File: Trajectories_together/170225_2Specimen_RawData_7.csv
"","V1","V2","V3"
"1","End date","2/25/2017",""
"2","Specimen label","1DG_2",""
"3","Maximum Load","0.09850","N"
"4","Time","Extension","Load"
"5","(s)","(mm)","(N)"
"6","0.00000","0.00000","-0.00076"
"82","0.45600","0.03827","-0.00022"
"158","0.91200","0.07611","-0.00023"
"234","1.36800","0.11408","0.00017"
"310","1.82400","0.15216","0.00030"
"386","2.28000","0.19013","0.00121"
"462","2.73600","0.22816","0.00096"
"538","3.19200","0.26618","0.00136"
"614","3.64800","0.30415","0.00132"
"690","4.10400","0.34212","0.00174"
"766","4.56000","0.38014","0.00160"
"842","5.01600","0.41811","0.00146"
"918","5.47200","0.45613","0.00175"
"994","5.92800","0.49422","0.00224"
"1070","6.38400","0.53219","0.00191"
"1146","6.84000","0.57003","0.00231"
"1222","7.29600","0.60806","0.00204"
"1298","7.75200","0.64609","0.00230"
"1374","8.20800","0.68417","0.00237"
"1450","8.66400","0.72214","0.00177"
"1526","9.12000","0.76016","0.00242"
"1602","9.57600","0.79813","0.00241"
"1678","10.03200","0.83604","0.00247"
"1754","10.48800","0.87406","0.00287"
"1830","10.94400","0.91215","0.00292"
"1906","11.40000","0.95018","0.00277"
"1982","11.85600","0.98814","0.00333"
"2058","12.31200","1.02617","0.00315"
"2134","12.76800","1.06413","0.00273"
"2210","13.22400","1.10210","0.00340"
"2286","13.68000","1.14019","0.00310"
"2362","14.13600","1.17815","0.00328"
"2438","14.59200","1.21612","0.00431"
"2514","15.04800","1.25415","0.00421"
"2590","15.50400","1.29211","0.00353"
"2666","15.96000","1.33008","0.00356"
"2742","16.41600","1.36810","0.00333"
"2818","16.87200","1.40613","0.00347"
"2894","17.32800","1.44416","0.00342"
"2970","17.78400","1.48206","0.00344"
"3046","18.24000","1.52009","0.00324"
"3122","18.69600","1.55812","0.00417"
"3198","19.15200","1.59614","0.00377"
"3274","19.60800","1.63417","0.00348"
"3350","20.06400","1.67213","0.00339"
"3426","20.52000","1.71016","0.00360"
"3502","20.97600","1.74819","0.00355"
"3578","21.43200","1.78615","0.00386"
"3654","21.88800","1.82412","0.00398"
"3730","22.34400","1.86209","0.00419"
"3806","22.80000","1.90011","0.00355"
"3882","23.25600","1.93814","0.00408"
"3958","23.71200","1.97616","0.00343"
"4034","24.16800","2.01413","0.00366"
"4110","24.62400","2.05210","0.00377"
"4186","25.08000","2.09006","0.00407"
"4262","25.53600","2.12815","0.00411"
"4338","25.99200","2.16617","0.00356"
"4414","26.44800","2.20414","0.00332"
"4490","26.90400","2.24217","0.00412"
"4566","27.36000","2.28013","0.00360"
"4642","27.81600","2.31810","0.00414"
"4718","28.27200","2.35607","0.00440"
"4794","28.72800","2.39415","0.00422"
"4870","29.18400","2.43212","0.00430"
"4946","29.64000","2.47014","0.00395"
"5022","30.09600","2.50811","0.00410"
"5098","30.55200","2.54608","0.00379"
"5174","31.00800","2.58404","0.00418"
"5250","31.46400","2.62213","0.00419"
"5326","31.92000","2.66016","0.00418"
"5402","32.37600","2.69818","0.00319"
"5478","32.83200","2.73615","0.00423"
"5554","33.28800","2.77417","0.00389"
"5630","33.74400","2.81208","0.00386"
"5706","34.20000","2.85011","0.00452"
"5782","34.65600","2.88813","0.00398"
"5858","35.11200","2.92622","0.00419"
"5934","35.56800","2.96413","0.00384"
"6010","36.02400","3.00215","0.00393"
"6086","36.48000","3.04012","0.00370"
"6162","36.93600","3.07808","0.00390"
"6238","37.39200","3.11611","0.00409"
"6314","37.84800","3.15408","0.00447"
"6390","38.30400","3.19216","0.00428"
"6466","38.76000","3.23013","0.00440"
"6542","39.21600","3.26822","0.00456"
"6618","39.67200","3.30612","0.00393"
"6694","40.12800","3.34409","0.00427"
"6770","40.58400","3.38211","0.00419"
"6846","41.04000","3.42014","0.00428"
"6922","41.49600","3.45817","0.00402"
"6998","41.95200","3.49619","0.00417"
"7074","42.40800","3.53410","0.00419"
"7150","42.86400","3.57207","0.00429"
"7226","43.32000","3.61009","0.00406"
"7302","43.77600","3.64812","0.00398"
"7378","44.23200","3.68620","0.00412"
"7454","44.68800","3.72417","0.00452"
"7530","45.14400","3.76214","0.00380"
"7606","45.60000","3.80010","0.00456"
"7682","46.05600","3.83807","0.00377"
"7758","46.51200","3.87610","0.00322"
"7834","46.96800","3.91418","0.00430"
"7910","47.42400","3.95215","0.00386"
"7986","47.88000","3.99017","0.00383"
"8062","48.33600","4.02820","0.00371"
"8138","48.79200","4.06605","0.00402"
"8214","49.24800","4.10413","0.00414"
"8290","49.70400","4.14216","0.00352"
"8366","50.16000","4.18013","0.00389"
"8442","50.61600","4.21815","0.00422"
"8518","51.07200","4.25612","0.00427"
"8594","51.52800","4.29408","0.00374"
"8670","51.98400","4.33211","0.00394"
"8746","52.44000","4.37014","0.00437"
"8822","52.89600","4.40816","0.00420"
"8898","53.35200","4.44613","0.00424"
"8974","53.80800","4.48416","0.00399"
"9050","54.26400","4.52212","0.00382"
"9126","54.72000","4.56015","0.00409"
"9202","55.17600","4.59811","0.00372"
"9278","55.63200","4.63608","0.00402"
"9354","56.08800","4.67417","0.00373"
"9430","56.54400","4.71213","0.00396"
"9506","57.00000","4.75022","0.00450"
"9582","57.45600","4.78813","0.00424"
"9658","57.91200","4.82609","0.00454"
"9734","58.36800","4.86412","0.00419"
"9810","58.82400","4.90214","0.00447"
"9886","59.28000","4.94017","0.00421"
"9962","59.73600","4.97814","0.00407"
"10038","60.19200","5.01610","0.00409"
"10114","60.64800","5.05407","0.00492"
"10190","61.10400","5.09215","0.00439"
"10266","61.56000","5.13012","0.00498"
"10342","62.01600","5.16815","0.00440"
"10418","62.47200","5.20617","0.00473"
"10494","62.92800","5.24420","0.00471"
"10570","63.38400","5.28211","0.00429"
"10646","63.84000","5.32013","0.00463"
"10722","64.29600","5.35810","0.00501"
"10798","64.75200","5.39618","0.00458"
"10874","65.20800","5.43415","0.00459"
"10950","65.66400","5.47218","0.00460"
"11026","66.12000","5.51014","0.00484"
"11102","66.57600","5.54805","0.00444"
"11178","67.03200","5.58608","0.00498"
"11254","67.48800","5.62416","0.00498"
"11330","67.94400","5.66213","0.00459"
"11406","68.40000","5.70010","0.00492"
"11482","68.85600","5.73818","0.00418"
"11558","69.31200","5.77615","0.00438"
"11634","69.76800","5.81411","0.00488"
"11710","70.22400","5.85214","0.00437"
"11786","70.68000","5.89017","0.00469"
"11862","71.13600","5.92813","0.00468"
"11938","71.59200","5.96610","0.00440"
"12014","72.04800","6.00412","0.00506"
"12090","72.50400","6.04209","0.00473"
"12166","72.96000","6.08012","0.00480"
"12242","73.41600","6.11808","0.00553"
"12318","73.87200","6.15617","0.00481"
"12394","74.32800","6.19414","0.00467"
"12470","74.78400","6.23216","0.00496"
"12546","75.24000","6.27019","0.00481"
"12622","75.69600","6.30809","0.00461"
"12698","76.15200","6.34612","0.00489"
"12774","76.60800","6.38415","0.00544"
"12850","77.06400","6.42211","0.00499"
"12926","77.52000","6.46014","0.00554"
"13002","77.97600","6.49817","0.00510"
"13078","78.43200","6.53613","0.00522"
"13154","78.88800","6.57404","0.00505"
"13230","79.34400","6.61212","0.00519"
"13306","79.80000","6.65015","0.00459"
"13382","80.25600","6.68818","0.00530"
"13458","80.71200","6.72620","0.00520"
"13534","81.16800","6.76411","0.00495"
"13610","81.62400","6.80208","0.00485"
"13686","82.08000","6.84010","0.00515"
"13762","82.53600","6.87813","0.00477"
"13838","82.99200","6.91615","0.00501"
"13914","83.44800","6.95418","0.00492"
"13990","83.90400","6.99209","0.00468"
"14066","84.36000","7.03005","0.00516"
"14142","84.81600","7.06808","0.00478"
"14218","85.27200","7.10611","0.00535"
"14294","85.72800","7.14419","0.00480"
"14370","86.18400","7.18216","0.00553"
"14446","86.64000","7.22012","0.00516"
"14522","87.09600","7.25809","0.00545"
"14598","87.55200","7.29606","0.00524"
"14674","88.00800","7.33414","0.00503"
"14750","88.46400","7.37211","0.00522"
"14826","88.92000","7.41014","0.00473"
"14902","89.37600","7.44810","0.00486"
"14978","89.83200","7.48619","0.00473"
"15054","90.28800","7.52409","0.00523"
"15130","90.74400","7.56212","0.00505"
"15206","91.20000","7.60015","0.00559"
"15282","91.65600","7.63811","0.00528"
"15358","92.11200","7.67614","0.00564"
"15434","92.56800","7.71417","0.00528"
"15510","93.02400","7.75219","0.00554"
"15586","93.48000","7.79010","0.00572"
"15662","93.93600","7.82806","0.00549"
"15738","94.39200","7.86609","0.00600"
"15814","94.84800","7.90412","0.00576"
"15890","95.30400","7.94220","0.00519"
"15966","95.76000","7.98023","0.00511"
"16042","96.21600","8.01814","0.00544"
"16118","96.67200","8.05610","0.00545"
"16194","97.12800","8.09413","0.00567"
"16270","97.58400","8.13209","0.00549"
"16346","98.04000","8.17018","0.00596"
"16422","98.49600","8.20821","0.00550"
"16498","98.95200","8.24611","0.00476"
"16574","99.40800","8.28408","0.00597"
"16650","99.86400","8.32205","0.00533"
"16726","100.32000","8.36013","0.00503"
"16802","100.77600","8.39816","0.00520"
"16878","101.23200","8.43612","0.00550"
"16954","101.68800","8.47421","0.00579"
"17030","102.14400","8.51206","0.00587"
"17106","102.60000","8.55002","0.00542"
"17182","103.05600","8.58811","0.00562"
"17258","103.51200","8.62619","0.00545"
"17334","103.96800","8.66416","0.00574"
"17410","104.42400","8.70213","0.00583"
"17486","104.88000","8.74009","0.00565"
"17562","105.33600","8.77812","0.00573"
"17638","105.79200","8.81609","0.00553"
"17714","106.24800","8.85417","0.00623"
"17790","106.70400","8.89214","0.00552"
"17866","107.16000","8.93011","0.00615"
"17942","107.61600","8.96813","0.00567"
"18018","108.07200","9.00616","0.00607"
"18094","108.52800","9.04412","0.00557"
"18170","108.98400","9.08209","0.00560"
"18246","109.44000","9.12012","0.00594"
"18322","109.89600","9.15814","0.00610"
"18398","110.35200","9.19617","0.00565"
"18474","110.80800","9.23413","0.00599"
"18550","111.26400","9.27216","0.00578"
"18626","111.72000","9.31007","0.00637"
"18702","112.17600","9.34809","0.00573"
"18778","112.63200","9.38612","0.00588"
"18854","113.08800","9.42415","0.00629"
"18930","113.54400","9.46217","0.00590"
"19006","114.00000","9.50014","0.00573"
"19082","114.45600","9.53811","0.00646"
"19158","114.91200","9.57613","0.00614"
"19234","115.36800","9.61410","0.00569"
"19310","115.82400","9.65212","0.00648"
"19386","116.28000","9.69021","0.00628"
"19462","116.73600","9.72818","0.00632"
"19538","117.19200","9.76614","0.00634"
"19614","117.64800","9.80405","0.00620"
"19690","118.10400","9.84213","0.00621"
"19766","118.56000","9.88016","0.00607"
"19842","119.01600","9.91819","0.00684"
"19918","119.47200","9.95615","0.00582"
"19994","119.92800","9.99412","0.00653"
"20070","120.38400","10.03209","0.00654"
"20146","120.84000","10.07011","0.00698"
"20222","121.29600","10.10814","0.00683"
"20298","121.75200","10.14616","0.00666"
"20374","122.20800","10.18413","0.00684"
"20450","122.66400","10.22216","0.00638"
"20526","123.12000","10.26006","0.00702"
"20602","123.57600","10.29809","0.00692"
"20678","124.03200","10.33612","0.00675"
"20754","124.48800","10.37414","0.00681"
"20830","124.94400","10.41217","0.00688"
"20906","125.40000","10.45013","0.00641"
"20982","125.85600","10.48816","0.00686"
"21058","126.31200","10.52613","0.00671"
"21134","126.76800","10.56415","0.00720"
"21210","127.22400","10.60212","0.00665"
"21286","127.68000","10.64015","0.00716"
"21362","128.13600","10.67811","0.00738"
"21438","128.59200","10.71614","0.00700"
"21514","129.04800","10.75416","0.00694"
"21590","129.50400","10.79213","0.00713"
"21666","129.96000","10.83016","0.00744"
"21742","130.41600","10.86812","0.00714"
"21818","130.87200","10.90615","0.00723"
"21894","131.32800","10.94418","0.00758"
"21970","131.78400","10.98220","0.00708"
"22046","132.24000","11.02011","0.00726"
"22122","132.69600","11.05807","0.00744"
"22198","133.15200","11.09610","0.00694"
"22274","133.60800","11.13419","0.00714"
"22350","134.06400","11.17215","0.00715"
"22426","134.52000","11.21018","0.00690"
"22502","134.97600","11.24815","0.00792"
"22578","135.43200","11.28605","0.00728"
"22654","135.88800","11.32414","0.00741"
"22730","136.34400","11.36216","0.00681"
"22806","136.80000","11.40019","0.00745"
"22882","137.25600","11.43816","0.00808"
"22958","137.71200","11.47612","0.00796"
"23034","138.16800","11.51409","0.00811"
"23110","138.62400","11.55206","0.00777"
"23186","139.08000","11.59014","0.00782"
"23262","139.53600","11.62817","0.00797"
"23338","139.99200","11.66613","0.00716"
"23414","140.44800","11.70416","0.00769"
"23490","140.90400","11.74213","0.00839"
"23566","141.36000","11.78009","0.00772"
"23642","141.81600","11.81812","0.00786"
"23718","142.27200","11.85620","0.00793"
"23794","142.72800","11.89417","0.00782"
"23870","143.18400","11.93208","0.00792"
"23946","143.64000","11.97016","0.00817"
"24022","144.09600","12.00813","0.00775"
"24098","144.55200","12.04610","0.00814"
"24174","145.00800","12.08412","0.00837"
"24250","145.46400","12.12215","0.00846"
"24326","145.92000","12.16018","0.00838"
"24402","146.37600","12.19814","0.00835"
"24478","146.83200","12.23617","0.00845"
"24554","147.28800","12.27413","0.00834"
"24630","147.74400","12.31210","0.00876"
"24706","148.20000","12.35013","0.00831"
"24782","148.65600","12.38815","0.00855"
"24858","149.11200","12.42618","0.00847"
"24934","149.56800","12.46415","0.00887"
"25010","150.02400","12.50211","0.00880"
"25086","150.48000","12.54008","0.00860"
"25162","150.93600","12.57810","0.00875"
"25238","151.39200","12.61613","0.00880"
"25314","151.84800","12.65416","0.00875"
"25390","152.30400","12.69218","0.00999"
"25466","152.76000","12.73015","0.00923"
"25542","153.21600","12.76812","0.00937"
"25618","153.67200","12.80608","0.00979"
"25694","154.12800","12.84411","0.00962"
"25770","154.58400","12.88213","0.00983"
"25846","155.04000","12.92016","0.01000"
"25922","155.49600","12.95813","0.00970"
"25998","155.95200","12.99609","0.00964"
"26074","156.40800","13.03406","0.00973"
"26150","156.86400","13.07215","0.01000"
"26226","157.32000","13.11017","0.00985"
"26302","157.77600","13.14820","0.00978"
"26378","158.23200","13.18610","0.00985"
"26454","158.68800","13.22413","0.00994"
"26530","159.14400","13.26210","0.01037"
"26606","159.60000","13.30012","0.01067"
"26682","160.05600","13.33815","0.01017"
"26758","160.51200","13.37611","0.01047"
"26834","160.96800","13.41414","0.01080"
"26910","161.42400","13.45217","0.01037"
"26986","161.88000","13.49013","0.01084"
"27062","162.33600","13.52810","0.01002"
"27138","162.79200","13.56612","0.01118"
"27214","163.24800","13.60415","0.01142"
"27290","163.70400","13.64218","0.01073"
"27366","164.16000","13.68008","0.01087"
"27442","164.61600","13.71817","0.01129"
"27518","165.07200","13.75614","0.01146"
"27594","165.52800","13.79410","0.01139"
"27670","165.98400","13.83213","0.01126"
"27746","166.44000","13.87016","0.01187"
"27822","166.89600","13.90812","0.01220"
"27898","167.35200","13.94621","0.01150"
"27974","167.80800","13.98417","0.01156"
"28050","168.26400","14.02208","0.01146"
"28126","168.72000","14.06011","0.01218"
"28202","169.17600","14.09807","0.01294"
"28278","169.63200","14.13616","0.01274"
"28354","170.08800","14.17412","0.01237"
"28430","170.54400","14.21221","0.01219"
"28506","171.00000","14.25012","0.01289"
"28582","171.45600","14.28808","0.01292"
"28658","171.91200","14.32605","0.01314"
"28734","172.36800","14.36420","0.01318"
"28810","172.82400","14.40222","0.01340"
"28886","173.28000","14.44013","0.01362"
"28962","173.73600","14.47815","0.01320"
"29038","174.19200","14.51606","0.01330"
"29114","174.64800","14.55415","0.01408"
"29190","175.10400","14.59211","0.01397"
"29266","175.56000","14.63014","0.01398"
"29342","176.01600","14.66811","0.01416"
"29418","176.47200","14.70613","0.01398"
"29494","176.92800","14.74410","0.01388"
"29570","177.38400","14.78207","0.01385"
"29646","177.84000","14.82009","0.01463"
"29722","178.29600","14.85818","0.01407"
"29798","178.75200","14.89614","0.01465"
"29874","179.20800","14.93417","0.01495"
"29950","179.66400","14.97214","0.01462"
"30026","180.12000","15.01016","0.01511"
"30102","180.57600","15.04813","0.01519"
"30178","181.03200","15.08609","0.01588"
"30254","181.48800","15.12418","0.01530"
"30330","181.94400","15.16215","0.01576"
"30406","182.40000","15.20017","0.01560"
"30482","182.85600","15.23814","0.01638"
"30558","183.31200","15.27611","0.01603"
"30634","183.76800","15.31407","0.01601"
"30710","184.22400","15.35210","0.01623"
"30786","184.68000","15.39013","0.01662"
"30862","185.13600","15.42815","0.01640"
"30938","185.59200","15.46618","0.01703"
"31014","186.04800","15.50414","0.01702"
"31090","186.50400","15.54205","0.01688"
"31166","186.96000","15.58014","0.01680"
"31242","187.41600","15.61816","0.01719"
"31318","187.87200","15.65619","0.01762"
"31394","188.32800","15.69421","0.01777"
"31470","188.78400","15.73206","0.01770"
"31546","189.24000","15.77009","0.01856"
"31622","189.69600","15.80811","0.01788"
"31698","190.15200","15.84614","0.01836"
"31774","190.60800","15.88416","0.01872"
"31850","191.06400","15.92213","0.01901"
"31926","191.52000","15.96010","0.01887"
"32002","191.97600","15.99806","0.01914"
"32078","192.43200","16.03609","0.01935"
"32154","192.88800","16.07412","0.01976"
"32230","193.34400","16.11214","0.01914"
"32306","193.80000","16.15017","0.01961"
"32382","194.25600","16.18814","0.01992"
"32458","194.71200","16.22616","0.02000"
"32534","195.16800","16.26407","0.02042"
"32610","195.62400","16.30209","0.02080"
"32686","196.08000","16.34018","0.02022"
"32762","196.53600","16.37815","0.02071"
"32838","196.99200","16.41611","0.02111"
"32914","197.44800","16.45414","0.02129"
"32990","197.90400","16.49211","0.02128"
"33066","198.36000","16.53007","0.02167"
"33142","198.81600","16.56810","0.02160"
"33218","199.27200","16.60612","0.02180"
"33294","199.72800","16.64415","0.02169"
"33370","200.18400","16.68218","0.02235"
"33446","200.64000","16.72014","0.02284"
"33522","201.09600","16.75811","0.02246"
"33598","201.55200","16.79613","0.02335"
"33674","202.00800","16.83410","0.02309"
"33750","202.46400","16.87219","0.02296"
"33826","202.92000","16.91015","0.02347"
"33902","203.37600","16.94824","0.02378"
"33978","203.83200","16.98615","0.02400"
"34054","204.28800","17.02405","0.02396"
"34130","204.74400","17.06208","0.02442"
"34206","205.20000","17.10011","0.02450"
"34282","205.65600","17.13819","0.02490"
"34358","206.11200","17.17616","0.02533"
"34434","206.56800","17.21412","0.02569"
"34510","207.02400","17.25209","0.02547"
"34586","207.48000","17.29012","0.02554"
"34662","207.93600","17.32814","0.02641"
"34738","208.39200","17.36617","0.02579"
"34814","208.84800","17.40420","0.02699"
"34890","209.30400","17.44216","0.02675"
"34966","209.76000","17.48013","0.02653"
"35042","210.21600","17.51809","0.02671"
"35118","210.67200","17.55612","0.02759"
"35194","211.12800","17.59421","0.02753"
"35270","211.58400","17.63217","0.02748"
"35346","212.04000","17.67020","0.02865"
"35422","212.49600","17.70811","0.02820"
"35498","212.95200","17.74607","0.02807"
"35574","213.40800","17.78410","0.02884"
"35650","213.86400","17.82212","0.02882"
"35726","214.32000","17.86015","0.02911"
"35802","214.77600","17.89812","0.02900"
"35878","215.23200","17.93614","0.02925"
"35954","215.68800","17.97411","0.02948"
"36030","216.14400","18.01213","0.02914"
"36106","216.60000","18.05010","0.02972"
"36182","217.05600","18.08813","0.02956"
"36258","217.51200","18.12615","0.02933"
"36334","217.96800","18.16412","0.02991"
"36410","218.42400","18.20215","0.03034"
"36486","218.88000","18.24017","0.03041"
"36562","219.33600","18.27808","0.03075"
"36638","219.79200","18.31610","0.03174"
"36714","220.24800","18.35413","0.03181"
"36790","220.70400","18.39216","0.03269"
"36866","221.16000","18.43018","0.03258"
"36942","221.61600","18.46809","0.03262"
"37018","222.07200","18.50606","0.03388"
"37094","222.52800","18.54414","0.03381"
"37170","222.98400","18.58211","0.03474"
"37246","223.44000","18.62020","0.03496"
"37322","223.89600","18.65816","0.03433"
"37398","224.35200","18.69613","0.03492"
"37474","224.80800","18.73409","0.03534"
"37550","225.26400","18.77206","0.03540"
"37626","225.72000","18.81015","0.03611"
"37702","226.17600","18.84811","0.03504"
"37778","226.63200","18.88614","0.03569"
"37854","227.08800","18.92416","0.03624"
"37930","227.54400","18.96213","0.03706"
"38006","228.00000","19.00010","0.03741"
"38082","228.45600","19.03812","0.03734"
"38158","228.91200","19.07615","0.03773"
"38234","229.36800","19.11412","0.03819"
"38310","229.82400","19.15214","0.03839"
"38386","230.28000","19.19017","0.03827"
"38462","230.73600","19.22813","0.03977"
"38538","231.19200","19.26610","0.03964"
"38614","231.64800","19.30413","0.03973"
"38690","232.10400","19.34215","0.04117"
"38766","232.56000","19.38012","0.04081"
"38842","233.01600","19.41815","0.04215"
"38918","233.47200","19.45611","0.04185"
"38994","233.92800","19.49408","0.04216"
"39070","234.38400","19.53210","0.04231"
"39146","234.84000","19.57013","0.04357"
"39222","235.29600","19.60816","0.04366"
"39298","235.75200","19.64612","0.04320"
"39374","236.20800","19.68415","0.04396"
"39450","236.66400","19.72217","0.04429"
"39526","237.12000","19.76014","0.04438"
"39602","237.57600","19.79811","0.04460"
"39678","238.03200","19.83614","0.04464"
"39754","238.48800","19.87416","0.04586"
"39830","238.94400","19.91219","0.04616"
"39906","239.40000","19.95015","0.04607"
"39982","239.85600","19.98812","0.04678"
"40058","240.31200","20.02603","0.04732"
"40134","240.76800","20.06411","0.04753"
"40210","241.22400","20.10214","0.04822"
"40286","241.68000","20.14016","0.04781"
"40362","242.13600","20.17813","0.04852"
"40438","242.59200","20.21616","0.04812"
"40514","243.04800","20.25406","0.04865"
"40590","243.50400","20.29215","0.04877"
"40666","243.96000","20.33012","0.04874"
"40742","244.41600","20.36814","0.04912"
"40818","244.87200","20.40617","0.04979"
"40894","245.32800","20.44413","0.05000"
"40970","245.78400","20.48216","0.05044"
"41046","246.24000","20.52013","0.05128"
"41122","246.69600","20.55809","0.05088"
"41198","247.15200","20.59618","0.05113"
"41274","247.60800","20.63414","0.05127"
"41350","248.06400","20.67217","0.05170"
"41426","248.52000","20.71008","0.05214"
"41502","248.97600","20.74804","0.05236"
"41578","249.43200","20.78613","0.05247"
"41654","249.88800","20.82416","0.05284"
"41730","250.34400","20.86218","0.05285"
"41806","250.80000","20.90009","0.05319"
"41882","251.25600","20.93817","0.05376"
"41958","251.71200","20.97608","0.05396"
"42034","252.16800","21.01410","0.05413"
"42110","252.62400","21.05213","0.05443"
"42186","253.08000","21.09010","0.05483"
"42262","253.53600","21.12813","0.05450"
"42338","253.99200","21.16615","0.05505"
"42414","254.44800","21.20418","0.05508"
"42490","254.90400","21.24209","0.05492"
"42566","255.36000","21.28011","0.05529"
"42642","255.81600","21.31814","0.05554"
"42718","256.27200","21.35610","0.05586"
"42794","256.72800","21.39413","0.05571"
"42870","257.18400","21.43216","0.05628"
"42946","257.64000","21.47012","0.05666"
"43022","258.09600","21.50809","0.05695"
"43098","258.55200","21.54611","0.05716"
"43174","259.00800","21.58414","0.05579"
"43250","259.46400","21.62211","0.05655"
"43326","259.92000","21.66019","0.05714"
"43402","260.37600","21.69816","0.05808"
"43478","260.83200","21.73606","0.05866"
"43554","261.28800","21.77409","0.05889"
"43630","261.74400","21.81212","0.06023"
"43706","262.20000","21.85014","0.06114"
"43782","262.65600","21.88811","0.06181"
"43858","263.11200","21.92620","0.06278"
"43934","263.56800","21.96411","0.06430"
"44010","264.02400","22.00207","0.06465"
"44086","264.48000","22.04009","0.06545"
"44162","264.93600","22.07818","0.06617"
"44238","265.39200","22.11615","0.06625"
"44314","265.84800","22.15412","0.06473"
"44390","266.30400","22.19214","0.06473"
"44466","266.76000","22.23011","0.06489"
"44542","267.21600","22.26807","0.06448"
"44618","267.67200","22.30616","0.06235"
"44694","268.12800","22.34419","0.06288"
"44770","268.58400","22.38215","0.06290"
"44846","269.04000","22.42012","0.06291"
"44922","269.49600","22.45815","0.06427"
"44998","269.95200","22.49611","0.06399"
"45074","270.40800","22.53408","0.06412"
"45150","270.86400","22.57210","0.06535"
"45226","271.32000","22.61013","0.06615"
"45302","271.77600","22.64816","0.06756"
"45378","272.23200","22.68618","0.06814"
"45454","272.68800","22.72415","0.06905"
"45530","273.14400","22.76205","0.06876"
"45606","273.60000","22.80014","0.06873"
"45682","274.05600","22.83817","0.06997"
"45758","274.51200","22.87619","0.07057"
"45834","274.96800","22.91416","0.06942"
"45910","275.42400","22.95213","0.06946"
"45986","275.88000","22.99009","0.06801"
"46062","276.33600","23.02812","0.06893"
"46138","276.79200","23.06608","0.06886"
"46214","277.24800","23.10411","0.06881"
"46290","277.70400","23.14214","0.06966"
"46366","278.16000","23.18016","0.07028"
"46442","278.61600","23.21807","0.07072"
"46518","279.07200","23.25610","0.07207"
"46594","279.52800","23.29412","0.07375"
"46670","279.98400","23.33215","0.07417"
"46746","280.44000","23.37017","0.07516"
"46822","280.89600","23.40820","0.07586"
"46898","281.35200","23.44617","0.07703"
"46974","281.80800","23.48407","0.07791"
"47050","282.26400","23.52210","0.07882"
"47126","282.72000","23.56012","0.07107"
"47202","283.17600","23.59815","0.06880"
"47278","283.63200","23.63612","0.06953"
"47354","284.08800","23.67420","0.07083"
"47430","284.54400","23.71211","0.07224"
"47506","285.00000","23.75008","0.07022"
"47582","285.45600","23.78810","0.07157"
"47658","285.91200","23.82613","0.07253"
"47734","286.36800","23.86410","0.07416"
"47810","286.82400","23.90212","0.07594"
"47886","287.28000","23.94015","0.07701"
"47962","287.73600","23.97811","0.07837"
"48038","288.19200","24.01614","0.07886"
"48114","288.64800","24.05411","0.08062"
"48190","289.10400","24.09219","0.08117"
"48266","289.56000","24.13010","0.08298"
"48342","290.01600","24.16818","0.08386"
"48418","290.47200","24.20615","0.08449"
"48494","290.92800","24.24406","0.08559"
"48570","291.38400","24.28209","0.08641"
"48646","291.84000","24.32011","0.08808"
"48722","292.29600","24.35814","0.08979"
"48798","292.75200","24.39616","0.09057"
"48874","293.20800","24.43413","0.09171"
"48950","293.66400","24.47216","0.09271"
"49026","294.12000","24.51006","0.09323"
"49102","294.57600","24.54815","0.09382"
"49178","295.03200","24.58617","0.09521"
"49254","295.48800","24.62414","0.09564"
"49330","295.94400","24.66222","0.09679"
"49406","296.40000","24.70013","0.09763"
"49482","296.85600","24.73810","0.09790"
"49558","297.31200","24.77607","0.05123"
"49634","297.76800","24.81415","0.04917"
"49710","298.22400","24.85218","0.04823"
"49786","298.68000","24.89014","0.05000"
"49862","299.13600","24.92811","0.05167"
"49938","299.59200","24.96608","0.05274"
"50014","300.04800","25.00410","0.05293"
"50090","300.50400","25.04213","0.05343"
"50166","300.96000","25.08015","0.05392"
"50242","301.41600","25.11818","0.04396"
"50318","301.87200","25.15615","0.04589"
"50394","302.32800","25.19411","0.04774"
"50470","302.78400","25.23208","0.04746"
"50546","303.24000","25.27011","0.04641"
"50622","303.69600","25.30819","0.04607"
"50698","304.15200","25.34616","0.04375"
"50774","304.60800","25.38418","0.04361"
"50850","305.06400","25.42215","0.04469"
"50926","305.52000","25.46012","0.04438"
"51002","305.97600","25.49809","0.04357"
"51078","306.43200","25.53611","0.04249"
"51154","306.88800","25.57414","0.04105"
"51230","307.34400","25.61210","0.04171"
"51306","307.80000","25.65019","0.04239"
"51382","308.25600","25.68809","0.04313"
"51458","308.71200","25.72612","0.04392"
"51534","309.16800","25.76403","0.04078"
"51610","309.62400","25.80211","0.04259"
"51686","310.08000","25.84014","0.04332"
"51762","310.53600","25.87817","0.04374"
"51838","310.99200","25.91613","0.04355"
"51914","311.44800","25.95416","0.04414"
"51990","311.90400","25.99207","0.04441"
"52066","312.36000","26.03015","0.04515"
"52142","312.81600","26.06812","0.04541"
"52218","313.27200","26.10614","0.04672"
"52294","313.72800","26.14417","0.04703"
"52370","314.18400","26.18214","0.04778"
"52446","314.64000","26.22010","0.04774"
"52522","315.09600","26.25807","0.04828"
"52598","315.55200","26.29610","0.04878"
"52674","316.00800","26.33412","0.04909"
"52750","316.46400","26.37215","0.04897"
"52826","316.92000","26.41017","0.03602"
"52902","317.37600","26.44808","0.03665"
"52978","317.83200","26.48605","0.03487"
"53054","318.28800","26.52407","0.03383"
"53130","318.74400","26.56216","0.03351"
"53206","319.20000","26.60018","0.03396"
"53282","319.65600","26.63815","0.03491"
"53358","320.11200","26.67612","0.03654"
"53434","320.56800","26.71408","0.03674"
"53510","321.02400","26.75217","0.03712"
"53586","321.48000","26.79014","0.03693"
"53662","321.93600","26.82810","0.03798"
"53738","322.39200","26.86613","0.03857"
"53814","322.84800","26.90415","0.03860"
"53890","323.30400","26.94212","0.03934"
"53966","323.76000","26.98003","0.03952"
"54042","324.21600","27.01811","0.04028"
"54118","324.67200","27.05614","0.04028"
"54194","325.12800","27.09417","0.03963"
"54270","325.58400","27.13213","0.03957"
"54346","326.04000","27.17010","0.04075"
"54422","326.49600","27.20812","0.04038"
"54498","326.95200","27.24609","0.04079"
"54574","327.40800","27.28412","0.04052"
"54650","327.86400","27.32214","0.04081"
"54726","328.32000","27.36011","0.03983"
"54802","328.77600","27.39820","0.03787"
"54878","329.23200","27.43616","0.03810"
"54954","329.68800","27.47413","0.03811"
"55030","330.14400","27.51215","0.03742"
"55106","330.60000","27.55006","0.03886"
"55182","331.05600","27.58815","0.03880"
"55258","331.51200","27.62611","0.03863"
"55334","331.96800","27.66420","0.03909"
"55410","332.42400","27.70211","0.03927"
"55486","332.88000","27.74007","0.03968"
"55562","333.33600","27.77810","0.03957"
"55638","333.79200","27.81612","0.04009"
"55714","334.24800","27.85415","0.04079"
"55790","334.70400","27.89212","0.04045"
"55866","335.16000","27.93014","0.04002"
"55942","335.61600","27.96811","0.03453"
"56018","336.07200","28.00608","0.03306"
"56094","336.52800","28.04416","0.03434"
"56170","336.98400","28.08213","0.03507"
"56246","337.44000","28.12015","0.03588"
"56322","337.89600","28.15812","0.03676"
"56398","338.35200","28.19609","0.03703"
"56474","338.80800","28.23411","0.03705"
"56550","339.26400","28.27208","0.03827"
"56626","339.72000","28.31017","0.03816"
"56702","340.17600","28.34813","0.03885"
"56778","340.63200","28.38616","0.03897"
"56854","341.08800","28.42412","0.03833"
"56930","341.54400","28.46209","0.03983"
"57006","342.00000","28.50012","0.04016"
"57082","342.45600","28.53814","0.04042"
"57158","342.91200","28.57617","0.04011"
"57234","343.36800","28.61413","0.04112"
"57310","343.82400","28.65210","0.04167"
"57386","344.28000","28.69013","0.04139"
"57462","344.73600","28.72810","0.04134"
"57538","345.19200","28.76612","0.04196"
"57614","345.64800","28.80415","0.04183"
"57690","346.10400","28.84211","0.04201"
"57766","346.56000","28.88014","0.04269"
"57842","347.01600","28.91816","0.04366"
"57918","347.47200","28.95613","0.04302"
"57994","347.92800","28.99410","0.04346"
"58070","348.38400","29.03212","0.04416"
"58146","348.84000","29.07015","0.04414"
"58222","349.29600","29.10818","0.04452"
"58298","349.75200","29.14620","0.04472"
"58374","350.20800","29.18411","0.04474"
"58450","350.66400","29.22207","0.04472"
"58526","351.12000","29.26010","0.04526"
"58602","351.57600","29.29813","0.04565"
"58678","352.03200","29.33615","0.04497"
"58754","352.48800","29.37412","0.04537"
"58830","352.94400","29.41215","0.04597"
"58906","353.40000","29.45011","0.04648"
"58982","353.85600","29.48808","0.04682"
"59058","354.31200","29.52610","0.04707"
"59134","354.76800","29.56419","0.04714"
"59210","355.22400","29.60216","0.04804"
"59286","355.68000","29.64018","0.04866"
"59362","356.13600","29.67815","0.04883"
"59438","356.59200","29.71605","0.04859"
"59514","357.04800","29.75408","0.04928"
"59590","357.50400","29.79217","0.04883"
"59666","357.96000","29.83019","0.04873"
"59742","358.41600","29.86816","0.03765"
"59818","358.87200","29.90619","0.03883"
"59894","359.32800","29.94409","0.04037"
"59970","359.78400","29.98206","0.04146"
"60046","360.24000","30.02015","0.04290"
"60122","360.69600","30.05811","0.04382"
"60198","361.15200","30.09614","0.04466"
"60274","361.60800","30.13411","0.04441"
"60350","362.06400","30.17213","0.03792"
"60426","362.52000","30.21010","0.03866"
"60502","362.97600","30.24806","0.03853"
"60578","363.43200","30.28615","0.03971"
"60654","363.88800","30.32418","0.03930"
"60730","364.34400","30.36214","0.04005"
"60806","364.80000","30.40017","0.03940"
"60882","365.25600","30.43814","0.03977"
"60958","365.71200","30.47610","0.03996"
"61034","366.16800","30.51407","0.04018"
"61110","366.62400","30.55215","0.03962"
"61186","367.08000","30.59012","0.04036"
"61262","367.53600","30.62815","0.04049"
"61338","367.99200","30.66617","0.04090"
"61414","368.44800","30.70408","0.04204"
"61490","368.90400","30.74210","0.04171"
"61566","369.36000","30.78007","0.04257"
"61642","369.81600","30.81816","0.04258"
"61718","370.27200","30.85618","0.04289"
"61794","370.72800","30.89415","0.04280"
"61870","371.18400","30.93212","0.04342"
"61946","371.64000","30.97008","0.04328"
"62022","372.09600","31.00811","0.04301"
"62098","372.55200","31.04613","0.04347"
"62174","373.00800","31.08416","0.04398"
"62250","373.46400","31.12218","0.04498"
"62326","373.92000","31.16009","0.04507"
"62402","374.37600","31.19812","0.04497"
"62478","374.83200","31.23608","0.03688"
"62554","375.28800","31.27417","0.03483"
"62630","375.74400","31.31214","0.03506"
"62706","376.20000","31.35016","0.03428"
"62782","376.65600","31.38819","0.03346"
"62858","377.11200","31.42609","0.03374"
"62934","377.56800","31.46412","0.03388"
"63010","378.02400","31.50215","0.03393"
"63086","378.48000","31.54017","0.03423"
"63162","378.93600","31.57820","0.03416"
"63238","379.39200","31.61611","0.03430"
"63314","379.84800","31.65413","0.03403"
"63390","380.30400","31.69210","0.03324"
"63466","380.76000","31.73013","0.03381"
"63542","381.21600","31.76809","0.03436"
"63618","381.67200","31.80612","0.03392"
"63694","382.12800","31.84408","0.03424"
"63770","382.58400","31.88217","0.03494"
"63846","383.04000","31.92014","0.03244"
"63922","383.49600","31.95810","0.03268"
"63998","383.95200","31.99613","0.03270"
"64074","384.40800","32.03410","0.03304"
"64150","384.86400","32.07218","0.03339"
"64226","385.32000","32.11021","0.03344"
"64302","385.77600","32.14817","0.03327"
"64378","386.23200","32.18614","0.03410"
"64454","386.68800","32.22411","0.03377"
"64530","387.14400","32.26207","0.03482"
"64606","387.60000","32.30016","0.03411"
"64682","388.05600","32.33812","0.03418"
"64758","388.51200","32.37615","0.03432"
"64834","388.96800","32.41412","0.03406"
"64910","389.42400","32.45208","0.03518"
"64986","389.88000","32.49011","0.03483"
"65062","390.33600","32.52814","0.03592"
"65138","390.79200","32.56616","0.03488"
"65214","391.24800","32.60419","0.03539"
"65290","391.70400","32.64215","0.03602"
"65366","392.16000","32.68012","0.03635"
"65442","392.61600","32.71809","0.03589"
"65518","393.07200","32.75611","0.03593"
"65594","393.52800","32.79420","0.03662"
"65670","393.98400","32.83216","0.03592"
"65746","394.44000","32.87019","0.03628"
"65822","394.89600","32.90804","0.03639"
"65898","395.35200","32.94606","0.03691"
"65974","395.80800","32.98409","0.03670"
"66050","396.26400","33.02212","0.03668"
"66126","396.72000","33.06015","0.03715"
"66202","397.17600","33.09811","0.03658"
"66278","397.63200","33.13614","0.03686"
"66354","398.08800","33.17410","0.03698"
"66430","398.54400","33.21213","0.03805"
"66506","399.00000","33.25009","0.03765"
"66582","399.45600","33.28818","0.03798"
"66658","399.91200","33.32615","0.03717"
"66734","400.36800","33.36417","0.03747"
"66810","400.82400","33.40220","0.03742"
"66886","401.28000","33.44011","0.03750"
"66962","401.73600","33.47807","0.03763"
"67038","402.19200","33.51616","0.03824"
"67114","402.64800","33.55413","0.03875"
"67190","403.10400","33.59215","0.03880"
"67266","403.56000","33.63012","0.03858"
"67342","404.01600","33.66808","0.03813"
"67418","404.47200","33.70605","0.03842"
"67494","404.92800","33.74408","0.03784"
"67570","405.38400","33.78210","0.03833"
"67646","405.84000","33.82013","0.03868"
"67722","406.29600","33.85815","0.03858"
"67798","406.75200","33.89612","0.03914"
"67874","407.20800","33.93415","0.03943"
"67950","407.66400","33.97211","0.03911"
"68026","408.12000","34.01008","0.03928"
"68102","408.57600","34.04816","0.03946"
"68178","409.03200","34.08613","0.03926"
"68254","409.48800","34.12416","0.03878"
"68330","409.94400","34.16212","0.03905"
"68406","410.40000","34.20003","0.03934"
"68482","410.85600","34.23806","0.03991"
"68558","411.31200","34.27614","0.03915"
"68634","411.76800","34.31417","0.03979"
"68710","412.22400","34.35213","0.03979"
"68786","412.68000","34.39010","0.03985"
"68862","413.13600","34.42813","0.04030"
"68938","413.59200","34.46609","0.03938"
"69014","414.04800","34.50418","0.03998"
"69090","414.50400","34.54221","0.03981"
"69166","414.96000","34.58017","0.03996"
"69242","415.41600","34.61814","0.04005"
"69318","415.87200","34.65611","0.03998"
"69394","416.32800","34.69413","0.03956"
"69470","416.78400","34.73210","0.04068"
"69546","417.24000","34.77012","0.04054"
"69622","417.69600","34.80815","0.04069"
"69698","418.15200","34.84612","0.04110"
"69774","418.60800","34.88420","0.04093"
"69850","419.06400","34.92211","0.04075"
"69926","419.52000","34.96008","0.04098"
"70002","419.97600","34.99810","0.04062"
"70078","420.43200","35.03613","0.04120"
"70154","420.88800","35.07415","0.04162"
"70230","421.34400","35.11218","0.04152"
"70306","421.80000","35.15015","0.04209"
"70382","422.25600","35.18811","0.04138"
"70458","422.71200","35.22608","0.04221"
"70534","423.16800","35.26410","0.04162"
"70610","423.62400","35.30213","0.04109"
"70686","424.08000","35.34016","0.04157"
"70762","424.53600","35.37812","0.04135"
"70838","424.99200","35.41609","0.04092"
"70914","425.44800","35.45406","0.04236"
"70990","425.90400","35.49208","0.04158"
"71066","426.36000","35.53017","0.04177"
"71142","426.81600","35.56814","0.04191"
"71218","427.27200","35.60616","0.04178"
"71294","427.72800","35.64413","0.04224"
"71370","428.18400","35.68209","0.04247"
"71446","428.64000","35.72006","0.04263"
"71522","429.09600","35.75814","0.04257"
"71598","429.55200","35.79617","0.04301"
"71674","430.00800","35.83414","0.04311"
"71750","430.46400","35.87217","0.04356"
"71826","430.92000","35.91007","0.04317"
"71902","431.37600","35.94810","0.04348"
"71978","431.83200","35.98606","0.04368"
"72054","432.28800","36.02415","0.04421"
"72130","432.74400","36.06212","0.04347"
"72206","433.20000","36.10014","0.04366"
"72282","433.65600","36.13811","0.04273"
"72358","434.11200","36.17613","0.04279"
"72434","434.56800","36.21416","0.04332"
"72510","435.02400","36.25212","0.04272"
"72586","435.48000","36.29015","0.04272"
"72662","435.93600","36.32812","0.04235"
"72738","436.39200","36.36615","0.04311"
"72814","436.84800","36.40417","0.04259"
"72890","437.30400","36.44208","0.04241"
"72966","437.76000","36.48011","0.04341"
"73042","438.21600","36.51813","0.04306"
"73118","438.67200","36.55616","0.04246"
"73194","439.12800","36.59418","0.04236"
"73270","439.58400","36.63209","0.04304"
"73346","440.04000","36.67012","0.04314"
"73422","440.49600","36.70808","0.04264"
"73498","440.95200","36.74617","0.04280"
"73574","441.40800","36.78413","0.04294"
"73650","441.86400","36.82216","0.04217"
"73726","442.32000","36.86019","0.04226"
"73802","442.77600","36.89816","0.04286"
"73878","443.23200","36.93612","0.04200"
"73954","443.68800","36.97409","0.04246"
"74030","444.14400","37.01211","0.04296"
"74106","444.60000","37.05014","0.04330"
"74182","445.05600","37.08816","0.04311"
"74258","445.51200","37.12619","0.04388"
"74334","445.96800","37.16410","0.04299"
"74410","446.42400","37.20206","0.04374"
"74486","446.88000","37.24009","0.04392"
"74562","447.33600","37.27818","0.04390"
"74638","447.79200","37.31614","0.04288"
"74714","448.24800","37.35417","0.04293"
"74790","448.70400","37.39207","0.04299"
"74866","449.16000","37.43004","0.04258"
"74942","449.61600","37.46813","0.04291"
"75018","450.07200","37.50615","0.04329"
"75094","450.52800","37.54412","0.04305"
"75170","450.98400","37.58215","0.04361"
"75246","451.44000","37.62011","0.04334"
"75322","451.89600","37.65814","0.04233"
"75398","452.35200","37.69604","0.04312"
"75474","452.80800","37.73413","0.04312"
"75550","453.26400","37.77216","0.04313"
"75626","453.72000","37.81018","0.04288"
"75702","454.17600","37.84815","0.04268"
"75778","454.63200","37.88618","0.04356"
"75854","455.08800","37.92414","0.04371"
"75930","455.54400","37.96205","0.04310"
"76006","456.00000","38.00014","0.04426"
"76082","456.45600","38.03816","0.04373"
"76158","456.91200","38.07613","0.04378"
"76234","457.36800","38.11415","0.04382"
"76310","457.82400","38.15212","0.04376"
"76386","458.28000","38.19009","0.04423"
"76462","458.73600","38.22812","0.04442"
"76538","459.19200","38.26608","0.04471"
"76614","459.64800","38.30410","0.04428"
"76690","460.10400","38.34219","0.04490"
"76766","460.56000","38.38010","0.04476"
"76842","461.01600","38.41812","0.04435"
"76918","461.47200","38.45609","0.04423"
"76994","461.92800","38.49406","0.04391"
"77070","462.38400","38.53214","0.04448"
"77146","462.84000","38.57023","0.04397"
"77222","463.29600","38.60819","0.04459"
"77298","463.75200","38.64610","0.04406"
"77374","464.20800","38.68407","0.04459"
"77450","464.66400","38.72210","0.04438"
"77526","465.12000","38.76012","0.04527"
"77602","465.57600","38.79815","0.04482"
"77678","466.03200","38.83611","0.04517"
"77754","466.48800","38.87414","0.04439"
"77830","466.94400","38.91211","0.04460"
"77906","467.40000","38.95013","0.04489"
"77982","467.85600","38.98816","0.04506"
"78058","468.31200","39.02612","0.04523"
"78134","468.76800","39.06415","0.04532"
"78210","469.22400","39.10212","0.04570"
"78286","469.68000","39.14014","0.04569"
"78362","470.13600","39.17810","0.04652"
"78438","470.59200","39.21613","0.04632"
"78514","471.04800","39.25416","0.04662"
"78590","471.50400","39.29213","0.04707"
"78666","471.96000","39.33015","0.04720"
"78742","472.41600","39.36812","0.04590"
"78818","472.87200","39.40614","0.04672"
"78894","473.32800","39.44405","0.04686"
"78970","473.78400","39.48214","0.04668"
"79046","474.24000","39.52016","0.04648"
"79122","474.69600","39.55813","0.04664"
"79198","475.15200","39.59615","0.04730"
"79274","475.60800","39.63412","0.04709"
"79350","476.06400","39.67215","0.04722"
"79426","476.52000","39.71011","0.04771"
"79502","476.97600","39.74809","0.04784"
"79578","477.43200","39.78610","0.04776"
"79654","477.88800","39.82413","0.04880"
"79730","478.34400","39.86216","0.04816"
"79806","478.80000","39.90013","0.04849"
"79882","479.25600","39.93809","0.04854"
"79958","479.71200","39.97606","0.04892"
"80034","480.16800","40.01414","0.04909"
"80110","480.62400","40.05217","0.04938"
"80186","481.08000","40.09014","0.04968"
"80262","481.53600","40.12811","0.04935"
"80338","481.99200","40.16607","0.04954"
"80414","482.44800","40.20410","0.05021"
"80490","482.90400","40.24212","0.05022"
"80566","483.36000","40.28015","0.05016"
"80642","483.81600","40.31811","0.05072"
"80718","484.27200","40.35614","0.05083"
"80794","484.72800","40.39411","0.05073"
"80870","485.18400","40.43207","0.05126"
"80946","485.64000","40.47010","0.05171"
"81022","486.09600","40.50812","0.05183"
"81098","486.55200","40.54615","0.05177"
"81174","487.00800","40.58412","0.05199"
"81250","487.46400","40.62215","0.05235"
"81326","487.92000","40.66011","0.05254"
"81402","488.37600","40.69807","0.05292"
"81478","488.83200","40.73616","0.04472"
"81554","489.28800","40.77412","0.04550"
"81630","489.74400","40.81216","0.04497"
"81706","490.20000","40.85012","0.04570"
"81782","490.65600","40.88815","0.04532"
"81858","491.11200","40.92611","0.04617"
"81934","491.56800","40.96414","0.04630"
"82010","492.02400","41.00211","0.04314"
"82086","492.48000","41.04013","0.03597"
"82162","492.93600","41.07810","0.03797"
"82238","493.39200","41.11613","0.03811"
"82314","493.84800","41.15415","0.03875"
"82390","494.30400","41.19212","0.03924"
"82466","494.76000","41.23008","0.03970"
"82542","495.21600","41.26817","0.03958"
"82618","495.67200","41.30613","0.03955"
"82694","496.12800","41.34416","0.04024"
"82770","496.58400","41.38213","0.04033"
"82846","497.04000","41.42009","0.04067"
"82922","497.49600","41.45806","0.04075"
"82998","497.95200","41.49615","0.04102"
"83074","498.40800","41.53418","0.04085"
"83150","498.86400","41.57214","0.04006"
"83226","499.32000","41.61016","0.04084"
"83302","499.77600","41.64808","0.04078"
"83378","500.23200","41.68610","0.04155"
"83454","500.68800","41.72412","0.04214"
"83530","501.14400","41.76215","0.04182"
"83606","501.60000","41.80012","0.04165"
"83682","502.05600","41.83814","0.04152"
"83758","502.51200","41.87611","0.04176"
"83834","502.96800","41.91408","0.04139"
"83910","503.42400","41.95216","0.04107"
"83986","503.88000","41.99013","0.04117"
"84062","504.33600","42.02815","0.04128"
"84138","504.79200","42.06612","0.04103"
"84214","505.24800","42.10415","0.04146"
"84290","505.70400","42.14212","0.04108"
"84366","506.16000","42.18008","0.04149"
"84442","506.61600","42.21811","0.04200"
"84518","507.07200","42.25613","0.04177"
"84594","507.52800","42.29416","0.04232"
"84670","507.98400","42.33213","0.04294"
"84746","508.44000","42.37009","0.04241"
"84822","508.89600","42.40812","0.04312"
"84898","509.35200","42.44608","0.04293"
"84974","509.80800","42.48417","0.04379"
"85050","510.26400","42.52214","0.04328"
"85126","510.72000","42.56016","0.04282"
"85202","511.17600","42.59819","0.04343"
"85278","511.63200","42.63610","0.04362"
"85354","512.08800","42.67406","0.04428"
"85430","512.54400","42.71209","0.04340"
"85506","513.00000","42.75011","0.04383"
"85582","513.45600","42.78814","0.04361"
"85658","513.91200","42.82616","0.04447"
"85734","514.36800","42.86413","0.04427"
"85810","514.82400","42.90204","0.04506"
"85886","515.28000","42.94006","0.04508"
"85962","515.73600","42.97809","0.04535"
"86038","516.19200","43.01617","0.04495"
"86114","516.64800","43.05420","0.04550"
"86190","517.10400","43.09211","0.04603"
"86266","517.56000","43.13014","0.04705"
"86342","518.01600","43.16805","0.04668"
"86418","518.47200","43.20613","0.04685"
"86494","518.92800","43.24416","0.04736"
"86570","519.38400","43.28218","0.04751"
"86646","519.84000","43.32015","0.04741"
"86722","520.29600","43.35811","0.04800"
"86798","520.75200","43.39608","0.04796"
"86874","521.20800","43.43405","0.04778"
"86950","521.66400","43.47213","0.04790"
"87026","522.12000","43.51016","0.04859"
"87102","522.57600","43.54813","0.04874"
"87178","523.03200","43.58615","0.04904"
"87254","523.48800","43.62412","0.04920"
"87330","523.94400","43.66208","0.04895"
"87406","524.40000","43.70005","0.04930"
"87482","524.85600","43.73813","0.04955"
"87558","525.31200","43.77616","0.04992"
"87634","525.76800","43.81413","0.04973"
"87710","526.22400","43.85215","0.05005"
"87786","526.68000","43.89012","0.05020"
"87862","527.13600","43.92815","0.05036"
"87938","527.59200","43.96611","0.05012"
"88014","528.04800","44.00414","0.05088"
"88090","528.50400","44.04210","0.05075"
"88166","528.96000","44.08014","0.05113"
"88242","529.41600","44.11816","0.05118"
"88318","529.87200","44.15607","0.05108"
"88394","530.32800","44.19409","0.05111"
"88470","530.78400","44.23206","0.05149"
"88546","531.24000","44.27014","0.05132"
"88622","531.69600","44.30817","0.05136"
"88698","532.15200","44.34620","0.05161"
"88774","532.60800","44.38410","0.05194"
"88850","533.06400","44.42207","0.05103"
"88926","533.52000","44.46009","0.05023"
"89002","533.97600","44.49818","0.05091"
"89078","534.43200","44.53615","0.05066"
"89154","534.88800","44.57418","0.05085"
"89230","535.34400","44.61208","0.05085"
"89306","535.80000","44.65005","0.05089"
"89382","536.25600","44.68813","0.05109"
"89458","536.71200","44.72610","0.05127"
"89534","537.16800","44.76412","0.05150"
"89610","537.62400","44.80215","0.05165"
"89686","538.08000","44.84012","0.05088"
"89762","538.53600","44.87814","0.04958"
"89838","538.99200","44.91605","0.05017"
"89914","539.44800","44.95414","0.05054"
"89990","539.90400","44.99216","0.05054"
"90066","540.36000","45.03012","0.05080"
"90142","540.81600","45.06816","0.05095"
"90218","541.27200","45.10612","0.05109"
"90294","541.72800","45.14409","0.05098"
"90370","542.18400","45.18211","0.05126"
"90446","542.64000","45.22014","0.05171"
"90522","543.09600","45.25816","0.05162"
"90598","543.55200","45.29607","0.05196"
"90674","544.00800","45.33416","0.05212"
"90750","544.46400","45.37212","0.05192"
"90826","544.92000","45.41009","0.05226"
"90902","545.37600","45.44812","0.05191"
"90978","545.83200","45.48615","0.05243"
"91054","546.28800","45.52417","0.05256"
"91130","546.74400","45.56213","0.05261"
"91206","547.20000","45.60017","0.05255"
"91282","547.65600","45.63813","0.05222"
"91358","548.11200","45.67604","0.05246"
"91434","548.56800","45.71412","0.05271"
"91510","549.02400","45.75215","0.05272"
"91586","549.48000","45.79017","0.05324"
"91662","549.93600","45.82814","0.05326"
"91738","550.39200","45.86610","0.05343"
"91814","550.84800","45.90408","0.05336"
"91890","551.30400","45.94210","0.05374"
"91966","551.76000","45.98013","0.05321"
"92042","552.21600","46.01815","0.05385"
"92118","552.67200","46.05618","0.05376"
"92194","553.12800","46.09414","0.05381"
"92270","553.58400","46.13211","0.05382"
"92346","554.04000","46.17014","0.05416"
"92422","554.49600","46.20810","0.05398"
"92498","554.95200","46.24619","0.05405"
"92574","555.40800","46.28415","0.05434"
"92650","555.86400","46.32218","0.05442"
"92726","556.32000","46.36009","0.05434"
"92750","556.46200","46.37193","0.05415"