File: Trajectories_together/170225_2Specimen_RawData_4.csv
"","V1","V2","V3"
"1","End date","2/25/2017",""
"2","Specimen label","1CT_3",""
"3","Maximum Load","0.09211","N"
"4","Time","Extension","Load"
"5","(s)","(mm)","(N)"
"6","0.00000","0.00000","-0.00026"
"38","0.19200","0.01321","0.00024"
"70","0.38400","0.03229","0.00006"
"102","0.57600","0.04819","0.00068"
"134","0.76800","0.06421","0.00033"
"166","0.96000","0.08024","0.00012"
"198","1.15200","0.09620","0.00070"
"230","1.34400","0.11222","0.00037"
"262","1.53600","0.12825","0.00070"
"294","1.72800","0.14415","0.00069"
"326","1.92000","0.16018","0.00118"
"358","2.11200","0.17626","0.00184"
"390","2.30400","0.19210","0.00120"
"422","2.49600","0.20825","0.00125"
"454","2.68800","0.22421","0.00154"
"486","2.88000","0.24017","0.00139"
"518","3.07200","0.25620","0.00148"
"550","3.26400","0.27228","0.00107"
"582","3.45600","0.28819","0.00188"
"614","3.64800","0.30421","0.00170"
"646","3.84000","0.32023","0.00164"
"678","4.03200","0.33620","0.00222"
"710","4.22400","0.35216","0.00202"
"742","4.41600","0.36824","0.00179"
"774","4.60800","0.38415","0.00190"
"806","4.80000","0.40023","0.00219"
"838","4.99200","0.41619","0.00194"
"870","5.18400","0.43222","0.00228"
"902","5.37600","0.44824","0.00218"
"934","5.56800","0.46421","0.00191"
"966","5.76000","0.48023","0.00233"
"998","5.95200","0.49619","0.00269"
"1030","6.14400","0.51216","0.00314"
"1062","6.33600","0.52824","0.00232"
"1094","6.52800","0.54420","0.00303"
"1126","6.72000","0.56023","0.00272"
"1158","6.91200","0.57625","0.00276"
"1190","7.10400","0.59222","0.00276"
"1222","7.29600","0.60824","0.00234"
"1254","7.48800","0.62420","0.00260"
"1286","7.68000","0.64017","0.00243"
"1318","7.87200","0.65625","0.00239"
"1350","8.06400","0.67221","0.00342"
"1382","8.25600","0.68812","0.00323"
"1414","8.44800","0.70426","0.00311"
"1446","8.64000","0.72022","0.00313"
"1478","8.83200","0.73613","0.00304"
"1510","9.02400","0.75221","0.00386"
"1542","9.21600","0.76818","0.00361"
"1574","9.40800","0.78420","0.00324"
"1606","9.60000","0.80028","0.00344"
"1638","9.79200","0.81619","0.00339"
"1670","9.98400","0.83221","0.00295"
"1702","10.17600","0.84823","0.00378"
"1734","10.36800","0.86420","0.00359"
"1766","10.56000","0.88022","0.00333"
"1798","10.75200","0.89625","0.00369"
"1830","10.94400","0.91215","0.00368"
"1862","11.13600","0.92823","0.00371"
"1894","11.32800","0.94426","0.00379"
"1926","11.52000","0.96016","0.00382"
"1958","11.71200","0.97624","0.00352"
"1990","11.90400","0.99221","0.00415"
"2022","12.09600","1.00817","0.00408"
"2054","12.28800","1.02425","0.00373"
"2086","12.48000","1.04022","0.00380"
"2118","12.67200","1.05618","0.00392"
"2150","12.86400","1.07221","0.00436"
"2182","13.05600","1.08817","0.00437"
"2214","13.24800","1.10419","0.00376"
"2246","13.44000","1.12022","0.00421"
"2278","13.63200","1.13618","0.00448"
"2310","13.82400","1.15226","0.00450"
"2342","14.01600","1.16823","0.00491"
"2374","14.20800","1.18419","0.00419"
"2406","14.40000","1.20022","0.00422"
"2438","14.59200","1.21618","0.00454"
"2470","14.78400","1.23220","0.00391"
"2502","14.97600","1.24817","0.00398"
"2534","15.16800","1.26419","0.00348"
"2566","15.36000","1.28021","0.00387"
"2598","15.55200","1.29624","0.00406"
"2630","15.74400","1.31220","0.00394"
"2662","15.93600","1.32822","0.00391"
"2694","16.12800","1.34425","0.00405"
"2726","16.32000","1.36015","0.00438"
"2758","16.51200","1.37624","0.00413"
"2790","16.70400","1.39220","0.00400"
"2822","16.89600","1.40816","0.00416"
"2854","17.08800","1.42419","0.00454"
"2886","17.28000","1.44015","0.00468"
"2918","17.47200","1.45623","0.00401"
"2950","17.66400","1.47220","0.00449"
"2982","17.85600","1.48822","0.00461"
"3014","18.04800","1.50419","0.00438"
"3046","18.24000","1.52027","0.00418"
"3078","18.43200","1.53617","0.00463"
"3110","18.62400","1.55220","0.00431"
"3142","18.81600","1.56822","0.00439"
"3174","19.00800","1.58412","0.00472"
"3206","19.20000","1.60027","0.00465"
"3238","19.39200","1.61623","0.00494"
"3270","19.58400","1.63213","0.00514"
"3302","19.77600","1.64828","0.00438"
"3334","19.96800","1.66418","0.00459"
"3366","20.16000","1.68015","0.00506"
"3398","20.35200","1.69629","0.00413"
"3430","20.54400","1.71219","0.00449"
"3462","20.73600","1.72816","0.00528"
"3494","20.92800","1.74424","0.00481"
"3526","21.12000","1.76020","0.00480"
"3558","21.31200","1.77623","0.00499"
"3590","21.50400","1.79219","0.00450"
"3622","21.69600","1.80816","0.00499"
"3654","21.88800","1.82418","0.00515"
"3686","22.08000","1.84020","0.00504"
"3718","22.27200","1.85623","0.00521"
"3750","22.46400","1.87225","0.00561"
"3782","22.65600","1.88827","0.00555"
"3814","22.84800","1.90418","0.00539"
"3846","23.04000","1.92020","0.00558"
"3878","23.23200","1.93622","0.00600"
"3910","23.42400","1.95225","0.00597"
"3942","23.61600","1.96821","0.00554"
"3974","23.80800","1.98418","0.00576"
"4006","24.00000","2.00026","0.00661"
"4038","24.19200","2.01628","0.00628"
"4070","24.38400","2.03219","0.00600"
"4102","24.57600","2.04827","0.00526"
"4134","24.76800","2.06423","0.00523"
"4166","24.96000","2.08014","0.00589"
"4198","25.15200","2.09622","0.00556"
"4230","25.34400","2.11219","0.00588"
"4262","25.53600","2.12815","0.00546"
"4294","25.72800","2.14423","0.00590"
"4326","25.92000","2.16020","0.00588"
"4358","26.11200","2.17616","0.00600"
"4390","26.30400","2.19218","0.00585"
"4422","26.49600","2.20815","0.00596"
"4454","26.68800","2.22423","0.00549"
"4486","26.88000","2.24025","0.00554"
"4518","27.07200","2.25616","0.00630"
"4550","27.26400","2.27224","0.00616"
"4582","27.45600","2.28821","0.00580"
"4614","27.64800","2.30417","0.00602"
"4646","27.84000","2.32025","0.00569"
"4678","28.03200","2.33622","0.00578"
"4710","28.22400","2.35224","0.00647"
"4742","28.41600","2.36826","0.00609"
"4774","28.60800","2.38417","0.00604"
"4806","28.80000","2.40025","0.00664"
"4838","28.99200","2.41621","0.00670"
"4870","29.18400","2.43224","0.00599"
"4902","29.37600","2.44820","0.00634"
"4934","29.56800","2.46423","0.00659"
"4966","29.76000","2.48019","0.00699"
"4998","29.95200","2.49621","0.00707"
"5030","30.14400","2.51218","0.00676"
"5062","30.33600","2.52814","0.00676"
"5094","30.52800","2.54428","0.00693"
"5126","30.72000","2.56019","0.00673"
"5158","30.91200","2.57621","0.00764"
"5190","31.10400","2.59224","0.00742"
"5222","31.29600","2.60820","0.00722"
"5254","31.48800","2.62422","0.00755"
"5286","31.68000","2.64025","0.00692"
"5318","31.87200","2.65621","0.00694"
"5350","32.06400","2.67223","0.00759"
"5382","32.25600","2.68826","0.00824"
"5414","32.44800","2.70410","0.00786"
"5446","32.64000","2.72024","0.00786"
"5478","32.83200","2.73627","0.00751"
"5510","33.02400","2.75211","0.00806"
"5542","33.21600","2.76826","0.00871"
"5574","33.40800","2.78422","0.00915"
"5606","33.60000","2.80018","0.00852"
"5638","33.79200","2.81621","0.00867"
"5670","33.98400","2.83223","0.00847"
"5702","34.17600","2.84813","0.00828"
"5734","34.36800","2.86422","0.00874"
"5766","34.56000","2.88018","0.00859"
"5798","34.75200","2.89620","0.00818"
"5830","34.94400","2.91223","0.00849"
"5862","35.13600","2.92819","0.00849"
"5894","35.32800","2.94428","0.00843"
"5926","35.52000","2.96024","0.00879"
"5958","35.71200","2.97620","0.00908"
"5990","35.90400","2.99223","0.00878"
"6022","36.09600","3.00825","0.00863"
"6054","36.28800","3.02421","0.00904"
"6086","36.48000","3.04018","0.00927"
"6118","36.67200","3.05620","0.00956"
"6150","36.86400","3.07223","0.00808"
"6182","37.05600","3.08825","0.00850"
"6214","37.24800","3.10421","0.00875"
"6246","37.44000","3.12018","0.00883"
"6278","37.63200","3.13620","0.00926"
"6310","37.82400","3.15222","0.00892"
"6342","38.01600","3.16819","0.00886"
"6374","38.20800","3.18421","0.00979"
"6406","38.40000","3.20017","0.00941"
"6438","38.59200","3.21626","0.00855"
"6470","38.78400","3.23222","0.00852"
"6502","38.97600","3.24813","0.00884"
"6534","39.16800","3.26421","0.00925"
"6566","39.36000","3.28017","0.00933"
"6598","39.55200","3.29620","0.00970"
"6630","39.74400","3.31222","0.00962"
"6662","39.93600","3.32812","0.00928"
"6694","40.12800","3.34421","0.00983"
"6726","40.32000","3.36023","0.00985"
"6758","40.51200","3.37614","0.00954"
"6790","40.70400","3.39228","0.01034"
"6822","40.89600","3.40818","0.01005"
"6854","41.08800","3.42415","0.01012"
"6886","41.28000","3.44029","0.01090"
"6918","41.47200","3.45625","0.01064"
"6950","41.66400","3.47216","0.01072"
"6982","41.85600","3.48830","0.01088"
"7014","42.04800","3.50420","0.01087"
"7046","42.24000","3.52017","0.00997"
"7078","42.43200","3.53625","0.01011"
"7110","42.62400","3.55222","0.01080"
"7142","42.81600","3.56824","0.01086"
"7174","43.00800","3.58426","0.01058"
"7206","43.20000","3.60017","0.01068"
"7238","43.39200","3.61619","0.01098"
"7270","43.58400","3.63227","0.01120"
"7302","43.77600","3.64818","0.01050"
"7334","43.96800","3.66420","0.01028"
"7366","44.16000","3.68028","0.01097"
"7398","44.35200","3.69619","0.01061"
"7430","44.54400","3.71221","0.01066"
"7462","44.73600","3.72824","0.01051"
"7494","44.92800","3.74420","0.01158"
"7526","45.12000","3.76022","0.01044"
"7558","45.31200","3.77619","0.01090"
"7590","45.50400","3.79221","0.01025"
"7622","45.69600","3.80817","0.00977"
"7654","45.88800","3.82420","0.00980"
"7686","46.08000","3.84022","0.00846"
"7718","46.27200","3.85625","0.00657"
"7750","46.46400","3.87215","0.00509"
"7782","46.65600","3.88823","0.00467"
"7814","46.84800","3.90420","0.00445"
"7846","47.04000","3.92022","0.00437"
"7878","47.23200","3.93618","0.00400"
"7910","47.42400","3.95215","0.00378"
"7942","47.61600","3.96823","0.00424"
"7974","47.80800","3.98420","0.00412"
"8006","48.00000","4.00016","0.00440"
"8038","48.19200","4.01624","0.00434"
"8070","48.38400","4.03221","0.00520"
"8102","48.57600","4.04817","0.00491"
"8134","48.76800","4.06425","0.00534"
"8166","48.96000","4.08022","0.00525"
"8198","49.15200","4.09618","0.00561"
"8230","49.34400","4.11226","0.00550"
"8262","49.53600","4.12817","0.00580"
"8294","49.72800","4.14413","0.00633"
"8326","49.92000","4.16022","0.00647"
"8358","50.11200","4.17624","0.00661"
"8390","50.30400","4.19220","0.00698"
"8422","50.49600","4.20823","0.00710"
"8454","50.68800","4.22419","0.00747"
"8486","50.88000","4.24021","0.00719"
"8518","51.07200","4.25624","0.00775"
"8550","51.26400","4.27220","0.00783"
"8582","51.45600","4.28823","0.00797"
"8614","51.64800","4.30425","0.00842"
"8646","51.84000","4.32015","0.00863"
"8678","52.03200","4.33618","0.00827"
"8710","52.22400","4.35226","0.00875"
"8742","52.41600","4.36816","0.00942"
"8774","52.60800","4.38425","0.00939"
"8806","52.80000","4.40021","0.00961"
"8838","52.99200","4.41617","0.01005"
"8870","53.18400","4.43220","0.00947"
"8902","53.37600","4.44816","0.00965"
"8934","53.56800","4.46419","0.01018"
"8966","53.76000","4.48027","0.01033"
"8998","53.95200","4.49617","0.01074"
"9030","54.14400","4.51220","0.01093"
"9062","54.33600","4.52822","0.01123"
"9094","54.52800","4.54418","0.01157"
"9126","54.72000","4.56021","0.01190"
"9158","54.91200","4.57623","0.01198"
"9190","55.10400","4.59213","0.01222"
"9222","55.29600","4.60816","0.01264"
"9254","55.48800","4.62418","0.01245"
"9286","55.68000","4.64021","0.01322"
"9318","55.87200","4.65617","0.01341"
"9350","56.06400","4.67219","0.01304"
"9382","56.25600","4.68822","0.01347"
"9414","56.44800","4.70424","0.01360"
"9446","56.64000","4.72020","0.01409"
"9478","56.83200","4.73623","0.01430"
"9510","57.02400","4.75219","0.01430"
"9542","57.21600","4.76816","0.01491"
"9574","57.40800","4.78424","0.01553"
"9606","57.60000","4.80020","0.01577"
"9638","57.79200","4.81617","0.01580"
"9670","57.98400","4.83225","0.01601"
"9702","58.17600","4.84827","0.01559"
"9734","58.36800","4.86418","0.01608"
"9766","58.56000","4.88020","0.01675"
"9798","58.75200","4.89616","0.01720"
"9830","58.94400","4.91225","0.01705"
"9862","59.13600","4.92821","0.01774"
"9894","59.32800","4.94418","0.01815"
"9926","59.52000","4.96026","0.01832"
"9958","59.71200","4.97622","0.01947"
"9990","59.90400","4.99219","0.01957"
"10022","60.09600","5.00827","0.01915"
"10054","60.28800","5.02423","0.02061"
"10086","60.48000","5.04020","0.02063"
"10118","60.67200","5.05628","0.02117"
"10150","60.86400","5.07219","0.02129"
"10182","61.05600","5.08815","0.02185"
"10214","61.24800","5.10423","0.02195"
"10246","61.44000","5.12020","0.02292"
"10278","61.63200","5.13622","0.02360"
"10310","61.82400","5.15224","0.02349"
"10342","62.01600","5.16821","0.02423"
"10374","62.20800","5.18423","0.02437"
"10406","62.40000","5.20025","0.02483"
"10438","62.59200","5.21616","0.02551"
"10470","62.78400","5.23224","0.02608"
"10502","62.97600","5.24821","0.02663"
"10534","63.16800","5.26417","0.02686"
"10566","63.36000","5.28019","0.02764"
"10598","63.55200","5.29622","0.02827"
"10630","63.74400","5.31218","0.02891"
"10662","63.93600","5.32820","0.02898"
"10694","64.12800","5.34423","0.02982"
"10726","64.32000","5.36019","0.03018"
"10758","64.51200","5.37621","0.03130"
"10790","64.70400","5.39218","0.03154"
"10822","64.89600","5.40826","0.03256"
"10854","65.08800","5.42423","0.03299"
"10886","65.28000","5.44019","0.03354"
"10918","65.47200","5.45621","0.03308"
"10950","65.66400","5.47218","0.03354"
"10982","65.85600","5.48814","0.03512"
"11014","66.04800","5.50422","0.03570"
"11046","66.24000","5.52019","0.03555"
"11078","66.43200","5.53621","0.03661"
"11110","66.62400","5.55218","0.03713"
"11142","66.81600","5.56820","0.03761"
"11174","67.00800","5.58416","0.03798"
"11206","67.20000","5.60025","0.03939"
"11238","67.39200","5.61621","0.03894"
"11270","67.58400","5.63223","0.03999"
"11302","67.77600","5.64820","0.03990"
"11334","67.96800","5.66416","0.04064"
"11366","68.16000","5.68030","0.04084"
"11398","68.35200","5.69621","0.04144"
"11430","68.54400","5.71217","0.04151"
"11462","68.73600","5.72826","0.04202"
"11494","68.92800","5.74416","0.04189"
"11526","69.12000","5.76018","0.04270"
"11558","69.31200","5.77621","0.04282"
"11590","69.50400","5.79217","0.04321"
"11622","69.69600","5.80819","0.04364"
"11654","69.88800","5.82422","0.04450"
"11686","70.08000","5.84012","0.04436"
"11718","70.27200","5.85621","0.04450"
"11750","70.46400","5.87223","0.04462"
"11782","70.65600","5.88819","0.04478"
"11814","70.84800","5.90422","0.04527"
"11846","71.04000","5.92024","0.04544"
"11878","71.23200","5.93614","0.04590"
"11910","71.42400","5.95223","0.04622"
"11942","71.61600","5.96819","0.04631"
"11974","71.80800","5.98416","0.04643"
"12006","72.00000","6.00030","0.04698"
"12038","72.19200","6.01620","0.04711"
"12070","72.38400","6.03217","0.04747"
"12102","72.57600","6.04825","0.04714"
"12134","72.76800","6.06421","0.04794"
"12166","72.96000","6.08018","0.04793"
"12198","73.15200","6.09620","0.04791"
"12230","73.34400","6.11216","0.04835"
"12262","73.53600","6.12825","0.04855"
"12294","73.72800","6.14421","0.04858"
"12326","73.92000","6.16017","0.04911"
"12358","74.11200","6.17620","0.04917"
"12390","74.30400","6.19228","0.04916"
"12422","74.49600","6.20819","0.04968"
"12454","74.68800","6.22421","0.04989"
"12486","74.88000","6.24023","0.04983"
"12518","75.07200","6.25620","0.05011"
"12550","75.26400","6.27222","0.05004"
"12582","75.45600","6.28819","0.04913"
"12614","75.64800","6.30421","0.04886"
"12646","75.84000","6.32023","0.04898"
"12678","76.03200","6.33614","0.04928"
"12710","76.22400","6.35222","0.04940"
"12742","76.41600","6.36818","0.04910"
"12774","76.60800","6.38421","0.04923"
"12806","76.80000","6.40023","0.04983"
"12838","76.99200","6.41619","0.04998"
"12870","77.18400","6.43222","0.05033"
"12902","77.37600","6.44818","0.05056"
"12934","77.56800","6.46415","0.05062"
"12966","77.76000","6.48023","0.05120"
"12998","77.95200","6.49619","0.05141"
"13030","78.14400","6.51222","0.05115"
"13062","78.33600","6.52824","0.05113"
"13094","78.52800","6.54420","0.05183"
"13126","78.72000","6.56017","0.05208"
"13158","78.91200","6.57619","0.05248"
"13190","79.10400","6.59222","0.05253"
"13222","79.29600","6.60818","0.05248"
"13254","79.48800","6.62420","0.05270"
"13286","79.68000","6.64017","0.05247"
"13318","79.87200","6.65619","0.05019"
"13350","80.06400","6.67227","0.04988"
"13382","80.25600","6.68818","0.04999"
"13414","80.44800","6.70420","0.05010"
"13446","80.64000","6.72022","0.05045"
"13478","80.83200","6.73619","0.05108"
"13510","81.02400","6.75221","0.05099"
"13542","81.21600","6.76824","0.05130"
"13574","81.40800","6.78420","0.05205"
"13606","81.60000","6.80022","0.05157"
"13638","81.79200","6.81619","0.05210"
"13670","81.98400","6.83215","0.05261"
"13702","82.17600","6.84823","0.05324"
"13734","82.36800","6.86420","0.05369"
"13766","82.56000","6.88016","0.05310"
"13798","82.75200","6.89618","0.04490"
"13830","82.94400","6.91215","0.04491"
"13862","83.13600","6.92823","0.04461"
"13894","83.32800","6.94426","0.04524"
"13926","83.52000","6.96016","0.04547"
"13958","83.71200","6.97618","0.04598"
"13990","83.90400","6.99221","0.04624"
"14022","84.09600","7.00817","0.04643"
"14054","84.28800","7.02419","0.04561"
"14086","84.48000","7.04028","0.04399"
"14118","84.67200","7.05618","0.04400"
"14150","84.86400","7.07227","0.04442"
"14182","85.05600","7.08823","0.04485"
"14214","85.24800","7.10413","0.04534"
"14246","85.44000","7.12022","0.04507"
"14278","85.63200","7.13618","0.04573"
"14310","85.82400","7.15220","0.04603"
"14342","86.01600","7.16823","0.04604"
"14374","86.20800","7.18419","0.04651"
"14406","86.40000","7.20021","0.04675"
"14438","86.59200","7.21624","0.04709"
"14470","86.78400","7.23214","0.04700"
"14502","86.97600","7.24817","0.04737"
"14534","87.16800","7.26425","0.04742"
"14566","87.36000","7.28021","0.04772"
"14598","87.55200","7.29624","0.04773"
"14630","87.74400","7.31220","0.04782"
"14662","87.93600","7.32822","0.04842"
"14694","88.12800","7.34419","0.04865"
"14726","88.32000","7.36021","0.04886"
"14758","88.51200","7.37624","0.04919"
"14790","88.70400","7.39220","0.04906"
"14822","88.89600","7.40822","0.04984"
"14854","89.08800","7.42419","0.04983"
"14886","89.28000","7.44021","0.05013"
"14918","89.47200","7.45617","0.05038"
"14950","89.66400","7.47226","0.05050"
"14982","89.85600","7.48822","0.05122"
"15014","90.04800","7.50418","0.05125"
"15046","90.24000","7.52027","0.04976"
"15078","90.43200","7.53623","0.04949"
"15110","90.62400","7.55220","0.04944"
"15142","90.81600","7.56828","0.04925"
"15174","91.00800","7.58418","0.04930"
"15206","91.20000","7.60021","0.04955"
"15238","91.39200","7.61623","0.04968"
"15270","91.58400","7.63219","0.04962"
"15302","91.77600","7.64822","0.04984"
"15334","91.96800","7.66424","0.04993"
"15366","92.16000","7.68021","0.05048"
"15398","92.35200","7.69623","0.05080"
"15430","92.54400","7.71225","0.05093"
"15462","92.73600","7.72816","0.05050"
"15494","92.92800","7.74424","0.05090"
"15526","93.12000","7.76026","0.05151"
"15558","93.31200","7.77611","0.05146"
"15590","93.50400","7.79225","0.05182"
"15622","93.69600","7.80821","0.05197"
"15654","93.88800","7.82412","0.05171"
"15686","94.08000","7.84026","0.05216"
"15718","94.27200","7.85622","0.05229"
"15750","94.46400","7.87219","0.05233"
"15782","94.65600","7.88827","0.05292"
"15814","94.84800","7.90418","0.05332"
"15846","95.04000","7.92014","0.05400"
"15878","95.23200","7.93628","0.05408"
"15910","95.42400","7.95213","0.05420"
"15942","95.61600","7.96821","0.05459"
"15974","95.80800","7.98423","0.05454"
"16006","96.00000","8.00020","0.05539"
"16038","96.19200","8.01616","0.05564"
"16070","96.38400","8.03219","0.05600"
"16102","96.57600","8.04821","0.05623"
"16134","96.76800","8.06417","0.05699"
"16166","96.96000","8.08020","0.05729"
"16198","97.15200","8.09622","0.05731"
"16230","97.34400","8.11218","0.05732"
"16262","97.53600","8.12821","0.05709"
"16294","97.72800","8.14423","0.05829"
"16326","97.92000","8.16020","0.05907"
"16358","98.11200","8.17616","0.05915"
"16390","98.30400","8.19218","0.05970"
"16422","98.49600","8.20821","0.06004"
"16454","98.68800","8.22417","0.06016"
"16486","98.88000","8.24025","0.06092"
"16518","99.07200","8.25616","0.06164"
"16550","99.26400","8.27218","0.06224"
"16582","99.45600","8.28820","0.06220"
"16614","99.64800","8.30417","0.06323"
"16646","99.84000","8.32019","0.06373"
"16678","100.03200","8.33622","0.06445"
"16710","100.22400","8.35218","0.06449"
"16742","100.41600","8.36826","0.06475"
"16774","100.60800","8.38423","0.06550"
"16806","100.80000","8.40019","0.06642"
"16838","100.99200","8.41627","0.06701"
"16870","101.18400","8.43218","0.06718"
"16902","101.37600","8.44814","0.06741"
"16934","101.56800","8.46422","0.06666"
"16966","101.76000","8.48025","0.06803"
"16998","101.95200","8.49615","0.06821"
"17030","102.14400","8.51224","0.06876"
"17062","102.33600","8.52820","0.06972"
"17094","102.52800","8.54422","0.06961"
"17126","102.72000","8.56031","0.07004"
"17158","102.91200","8.57615","0.07044"
"17190","103.10400","8.59217","0.07068"
"17222","103.29600","8.60826","0.07214"
"17254","103.48800","8.62416","0.07214"
"17286","103.68000","8.64019","0.07277"
"17318","103.87200","8.65621","0.07331"
"17350","104.06400","8.67211","0.07385"
"17382","104.25600","8.68820","0.07305"
"17414","104.44800","8.70422","0.07455"
"17446","104.64000","8.72018","0.07394"
"17478","104.83200","8.73627","0.06443"
"17510","105.02400","8.75223","0.05527"
"17542","105.21600","8.76819","0.05587"
"17574","105.40800","8.78422","0.05738"
"17606","105.60000","8.80024","0.05085"
"17638","105.79200","8.81621","0.04996"
"17670","105.98400","8.83223","0.04929"
"17702","106.17600","8.84819","0.04974"
"17734","106.36800","8.86422","0.05006"
"17766","106.56000","8.88024","0.05014"
"17798","106.75200","8.89614","0.05114"
"17830","106.94400","8.91223","0.05141"
"17862","107.13600","8.92819","0.05189"
"17894","107.32800","8.94416","0.05266"
"17926","107.52000","8.96024","0.05262"
"17958","107.71200","8.97620","0.05374"
"17990","107.90400","8.99223","0.05331"
"18022","108.09600","9.00819","0.05423"
"18054","108.28800","9.02421","0.05495"
"18086","108.48000","9.04018","0.05108"
"18118","108.67200","9.05620","0.05165"
"18150","108.86400","9.07216","0.05175"
"18182","109.05600","9.08825","0.05154"
"18214","109.24800","9.10421","0.05227"
"18246","109.44000","9.12018","0.05212"
"18278","109.63200","9.13626","0.05261"
"18310","109.82400","9.15216","0.05279"
"18342","110.01600","9.16819","0.05315"
"18374","110.20800","9.18421","0.05421"
"18406","110.40000","9.20017","0.05412"
"18438","110.59200","9.21626","0.05558"
"18470","110.78400","9.23222","0.05586"
"18502","110.97600","9.24819","0.05644"
"18534","111.16800","9.26421","0.05742"
"18566","111.36000","9.28023","0.05804"
"18598","111.55200","9.29620","0.05957"
"18630","111.74400","9.31222","0.06035"
"18662","111.93600","9.32818","0.06084"
"18694","112.12800","9.34415","0.06227"
"18726","112.32000","9.36023","0.06266"
"18758","112.51200","9.37619","0.06378"
"18790","112.70400","9.39216","0.06424"
"18822","112.89600","9.40824","0.06398"
"18854","113.08800","9.42421","0.06425"
"18886","113.28000","9.44017","0.06520"
"18918","113.47200","9.45625","0.06536"
"18950","113.66400","9.47222","0.06668"
"18982","113.85600","9.48818","0.06713"
"19014","114.04800","9.50426","0.06639"
"19046","114.24000","9.52017","0.06746"
"19078","114.43200","9.53625","0.06696"
"19110","114.62400","9.55222","0.06852"
"19142","114.81600","9.56818","0.06890"
"19174","115.00800","9.58420","0.07010"
"19206","115.20000","9.60023","0.07047"
"19238","115.39200","9.61619","0.07060"
"19270","115.58400","9.63221","0.07184"
"19302","115.77600","9.64824","0.07095"
"19334","115.96800","9.66420","0.05909"
"19366","116.16000","9.68022","0.05816"
"19398","116.35200","9.69619","0.05796"
"19430","116.54400","9.71215","0.05386"
"19462","116.73600","9.72824","0.05053"
"19494","116.92800","9.74420","0.04976"
"19526","117.12000","9.76022","0.04989"
"19558","117.31200","9.77625","0.04933"
"19590","117.50400","9.79221","0.04936"
"19622","117.69600","9.80829","0.04979"
"19654","117.88800","9.82420","0.04990"
"19686","118.08000","9.84016","0.05016"
"19718","118.27200","9.85624","0.05033"
"19750","118.46400","9.87221","0.05047"
"19782","118.65600","9.88817","0.05007"
"19814","118.84800","9.90420","0.04974"
"19846","119.04000","9.92016","0.04997"
"19878","119.23200","9.93624","0.04960"
"19910","119.42400","9.95221","0.05016"
"19942","119.61600","9.96817","0.05037"
"19974","119.80800","9.98425","0.05095"
"20006","120.00000","10.00022","0.05150"
"20038","120.19200","10.01618","0.05146"
"20070","120.38400","10.03226","0.05222"
"20102","120.57600","10.04817","0.05203"
"20134","120.76800","10.06419","0.05321"
"20166","120.96000","10.08028","0.05278"
"20198","121.15200","10.09618","0.05351"
"20230","121.34400","10.11220","0.05404"
"20262","121.53600","10.12823","0.05381"
"20294","121.72800","10.14419","0.05422"
"20326","121.92000","10.16022","0.05415"
"20358","122.11200","10.17618","0.05470"
"20390","122.30400","10.19220","0.05535"
"20422","122.49600","10.20823","0.05648"
"20454","122.68800","10.22425","0.05676"
"20486","122.88000","10.24009","0.05700"
"20518","123.07200","10.25624","0.05805"
"20550","123.26400","10.27220","0.05855"
"20582","123.45600","10.28816","0.05963"
"20614","123.64800","10.30425","0.05958"
"20646","123.84000","10.32021","0.06035"
"20678","124.03200","10.33618","0.06099"
"20710","124.22400","10.35220","0.06157"
"20742","124.41600","10.36822","0.06219"
"20774","124.60800","10.38419","0.06258"
"20806","124.80000","10.40021","0.06334"
"20838","124.99200","10.41617","0.06450"
"20870","125.18400","10.43220","0.06491"
"20902","125.37600","10.44822","0.06367"
"20934","125.56800","10.46418","0.06154"
"20966","125.76000","10.48021","0.06179"
"20998","125.95200","10.49623","0.06171"
"21030","126.14400","10.51220","0.06253"
"21062","126.33600","10.52822","0.06244"
"21094","126.52800","10.54418","0.06124"
"21126","126.72000","10.56021","0.06119"
"21158","126.91200","10.57617","0.06224"
"21190","127.10400","10.59219","0.06342"
"21222","127.29600","10.60822","0.06434"
"21254","127.48800","10.62424","0.06479"
"21286","127.68000","10.64020","0.06543"
"21318","127.87200","10.65623","0.06612"
"21350","128.06400","10.67225","0.06610"
"21382","128.25600","10.68816","0.05842"
"21414","128.44800","10.70430","0.05837"
"21446","128.64000","10.72020","0.06024"
"21478","128.83200","10.73623","0.06151"
"21510","129.02400","10.75219","0.06234"
"21542","129.21600","10.76816","0.06478"
"21574","129.40800","10.78424","0.06521"
"21606","129.60000","10.80020","0.06723"
"21638","129.79200","10.81617","0.06807"
"21670","129.98400","10.83219","0.06869"
"21702","130.17600","10.84821","0.07119"
"21734","130.36800","10.86418","0.07052"
"21766","130.56000","10.88020","0.07285"
"21798","130.75200","10.89622","0.07313"
"21830","130.94400","10.91219","0.07360"
"21862","131.13600","10.92821","0.07461"
"21894","131.32800","10.94423","0.07546"
"21926","131.52000","10.96014","0.07700"
"21958","131.71200","10.97622","0.07792"
"21990","131.90400","10.99225","0.07820"
"22022","132.09600","11.00821","0.07929"
"22054","132.28800","11.02429","0.07819"
"22086","132.48000","11.04020","0.07864"
"22118","132.67200","11.05622","0.07970"
"22150","132.86400","11.07224","0.08111"
"22182","133.05600","11.08821","0.08203"
"22214","133.24800","11.10423","0.08251"
"22246","133.44000","11.12020","0.08315"
"22278","133.63200","11.13616","0.08414"
"22310","133.82400","11.15218","0.08474"
"22342","134.01600","11.16821","0.08600"
"22374","134.20800","11.18417","0.08728"
"22406","134.40000","11.20025","0.08764"
"22438","134.59200","11.21622","0.08867"
"22470","134.78400","11.23218","0.08923"
"22502","134.97600","11.24821","0.08983"
"22534","135.16800","11.26423","0.09082"
"22566","135.36000","11.28025","0.09175"
"22598","135.55200","11.29622","0.09144"
"22630","135.74400","11.31218","0.02009"
"22662","135.93600","11.32826","0.00790"
"22694","136.12800","11.34423","0.02300"
"22726","136.32000","11.36019","0.01196"
"22758","136.51200","11.37621","0.01523"
"22790","136.70400","11.39224","0.01764"
"22822","136.89600","11.40814","0.01668"
"22854","137.08800","11.42423","0.01438"
"22886","137.28000","11.44025","0.02244"
"22918","137.47200","11.45621","0.01654"
"22950","137.66400","11.47224","0.01705"
"22982","137.85600","11.48820","0.02248"
"23014","138.04800","11.50416","0.01805"
"23046","138.24000","11.52025","0.02240"
"23078","138.43200","11.53621","0.02154"
"23110","138.62400","11.55223","0.02131"
"23142","138.81600","11.56826","0.02497"
"23174","139.00800","11.58416","0.02413"
"23206","139.20000","11.60025","0.02258"
"23238","139.39200","11.61627","0.02721"
"23270","139.58400","11.63217","0.02609"
"23302","139.77600","11.64820","0.02676"
"23334","139.96800","11.66422","0.02959"
"23366","140.16000","11.68024","0.02796"
"23398","140.35200","11.69621","0.03018"
"23430","140.54400","11.71217","0.03161"
"23462","140.73600","11.72826","0.03044"
"23494","140.92800","11.74422","0.03311"
"23526","141.12000","11.76018","0.03281"
"23558","141.31200","11.77621","0.03353"
"23590","141.50400","11.79223","0.03494"
"23622","141.69600","11.80819","0.03489"
"23654","141.88800","11.82428","0.03552"
"23686","142.08000","11.84018","0.03715"
"23718","142.27200","11.85614","0.03545"
"23750","142.46400","11.87223","0.03832"
"23782","142.65600","11.88819","0.03808"
"23814","142.84800","11.90416","0.03772"
"23846","143.04000","11.92018","0.03945"
"23878","143.23200","11.93620","0.03968"
"23910","143.42400","11.95223","0.03932"
"23942","143.61600","11.96825","0.04127"
"23974","143.80800","11.98421","0.04027"
"24006","144.00000","12.00024","0.04188"
"24038","144.19200","12.01626","0.04172"
"24070","144.38400","12.03211","0.04200"
"24102","144.57600","12.04825","0.04277"
"24134","144.76800","12.06427","0.04074"
"24166","144.96000","12.08012","0.04144"
"24198","145.15200","12.09626","0.04199"
"24230","145.34400","12.11228","0.04264"
"24262","145.53600","12.12813","0.04333"
"24294","145.72800","12.14427","0.04369"
"24326","145.92000","12.16023","0.04393"
"24358","146.11200","12.17614","0.04473"
"24390","146.30400","12.19222","0.04455"
"24422","146.49600","12.20813","0.04494"
"24454","146.68800","12.22421","0.04549"
"24486","146.88000","12.24023","0.04592"
"24518","147.07200","12.25614","0.04612"
"24550","147.26400","12.27222","0.04613"
"24582","147.45600","12.28824","0.04649"
"24614","147.64800","12.30415","0.04696"
"24646","147.84000","12.32017","0.04709"
"24678","148.03200","12.33619","0.04748"
"24710","148.22400","12.35222","0.04752"
"24742","148.41600","12.36818","0.04787"
"24774","148.60800","12.38421","0.04804"
"24806","148.80000","12.40023","0.04790"
"24838","148.99200","12.41619","0.04816"
"24870","149.18400","12.43222","0.04854"
"24902","149.37600","12.44818","0.04855"
"24934","149.56800","12.46420","0.04912"
"24966","149.76000","12.48023","0.04959"
"24998","149.95200","12.49619","0.04948"
"25030","150.14400","12.51222","0.05008"
"25062","150.33600","12.52818","0.05021"
"25094","150.52800","12.54420","0.05016"
"25126","150.72000","12.56017","0.04994"
"25158","150.91200","12.57619","0.05011"
"25190","151.10400","12.59221","0.05028"
"25222","151.29600","12.60818","0.05078"
"25254","151.48800","12.62420","0.05121"
"25286","151.68000","12.64023","0.05139"
"25318","151.87200","12.65613","0.05216"
"25350","152.06400","12.67227","0.05239"
"25382","152.25600","12.68824","0.05305"
"25414","152.44800","12.70414","0.05349"
"25446","152.64000","12.72028","0.05401"
"25478","152.83200","12.73619","0.05471"
"25510","153.02400","12.75209","0.05558"
"25542","153.21600","12.76829","0.05579"
"25574","153.40800","12.78426","0.05712"
"25606","153.60000","12.80016","0.05756"
"25638","153.79200","12.81625","0.05861"
"25670","153.98400","12.83221","0.05921"
"25702","154.17600","12.84817","0.05978"
"25734","154.36800","12.86426","0.06065"
"25766","154.56000","12.88016","0.06185"
"25798","154.75200","12.89618","0.06099"
"25830","154.94400","12.91221","0.06121"
"25862","155.13600","12.92817","0.06139"
"25894","155.32800","12.94420","0.06220"
"25926","155.52000","12.96028","0.06403"
"25958","155.71200","12.97612","0.06475"
"25990","155.90400","12.99221","0.06506"
"26022","156.09600","13.00823","0.06647"
"26054","156.28800","13.02419","0.06748"
"26086","156.48000","13.04022","0.06776"
"26118","156.67200","13.05624","0.06820"
"26150","156.86400","13.07220","0.05575"
"26182","157.05600","13.08817","0.05379"
"26214","157.24800","13.10419","0.05540"
"26246","157.44000","13.12022","0.05492"
"26278","157.63200","13.13618","0.05638"
"26310","157.82400","13.15220","0.05676"
"26342","158.01600","13.16823","0.05783"
"26374","158.20800","13.18425","0.05797"
"26406","158.40000","13.20021","0.05881"
"26438","158.59200","13.21630","0.05940"
"26470","158.78400","13.23220","0.06083"
"26502","158.97600","13.24822","0.06213"
"26534","159.16800","13.26425","0.06240"
"26566","159.36000","13.28021","0.06341"
"26598","159.55200","13.29618","0.06345"
"26630","159.74400","13.31220","0.06430"
"26662","159.93600","13.32816","0.06374"
"26694","160.12800","13.34419","0.06587"
"26726","160.32000","13.36027","0.06569"
"26758","160.51200","13.37617","0.06715"
"26790","160.70400","13.39226","0.06740"
"26822","160.89600","13.40822","0.06826"
"26854","161.08800","13.42419","0.06881"
"26886","161.28000","13.44027","0.07003"
"26918","161.47200","13.45617","0.07065"
"26950","161.66400","13.47220","0.07166"
"26982","161.85600","13.48828","0.07136"
"27014","162.04800","13.50412","0.07238"
"27046","162.24000","13.52021","0.06261"
"27078","162.43200","13.53623","0.05851"
"27110","162.62400","13.55225","0.05348"
"27142","162.81600","13.56822","0.05496"
"27174","163.00800","13.58424","0.05676"
"27206","163.20000","13.60015","0.05463"
"27238","163.39200","13.61623","0.05862"
"27270","163.58400","13.63219","0.05636"
"27302","163.77600","13.64816","0.05816"
"27334","163.96800","13.66424","0.05770"
"27366","164.16000","13.68020","0.05786"
"27398","164.35200","13.69611","0.05946"
"27430","164.54400","13.71219","0.05961"
"27462","164.73600","13.72822","0.06118"
"27494","164.92800","13.74412","0.06037"
"27526","165.12000","13.76026","0.06355"
"27558","165.31200","13.77623","0.06099"
"27590","165.50400","13.79219","0.06417"
"27622","165.69600","13.80821","0.06323"
"27654","165.88800","13.82418","0.06427"
"27686","166.08000","13.84020","0.06617"
"27718","166.27200","13.85623","0.06350"
"27750","166.46400","13.87219","0.06752"
"27782","166.65600","13.88821","0.06566"
"27814","166.84800","13.90424","0.06812"
"27846","167.04000","13.92020","0.06819"
"27878","167.23200","13.93622","0.06844"
"27910","167.42400","13.95225","0.07020"
"27942","167.61600","13.96821","0.07017"
"27974","167.80800","13.98423","0.07142"
"28006","168.00000","14.00020","0.07176"
"28038","168.19200","14.01616","0.07249"
"28070","168.38400","14.03219","0.07303"
"28102","168.57600","14.04821","0.07427"
"28134","168.76800","14.06417","0.01399"
"28166","168.96000","14.08020","0.01355"
"28198","169.15200","14.09622","0.01140"
"28230","169.34400","14.11224","0.01668"
"28262","169.53600","14.12821","0.01333"
"28294","169.72800","14.14423","0.01115"
"28326","169.92000","14.16020","0.01363"
"28358","170.11200","14.17616","0.01222"
"28390","170.30400","14.19218","0.01285"
"28422","170.49600","14.20821","0.01179"
"28454","170.68800","14.22417","0.01391"
"28486","170.88000","14.24025","0.01189"
"28518","171.07200","14.25628","0.01473"
"28550","171.26400","14.27218","0.01358"
"28582","171.45600","14.28826","0.01346"
"28614","171.64800","14.30423","0.01514"
"28646","171.84000","14.32013","0.01355"
"28678","172.03200","14.33622","0.01430"
"28710","172.22400","14.35224","0.01404"
"28742","172.41600","14.36814","0.01575"
"28774","172.60800","14.38423","0.01395"
"28806","172.80000","14.40019","0.01558"
"28838","172.99200","14.41615","0.01461"
"28870","173.18400","14.43224","0.01589"
"28902","173.37600","14.44814","0.01650"
"28934","173.56800","14.46422","0.01537"
"28966","173.76000","14.48025","0.01623"
"28998","173.95200","14.49615","0.01647"
"29030","174.14400","14.51224","0.01610"
"29062","174.33600","14.52826","0.01629"
"29094","174.52800","14.54410","0.01731"
"29126","174.72000","14.56025","0.01714"
"29158","174.91200","14.57621","0.01786"
"29190","175.10400","14.59211","0.01810"
"29222","175.29600","14.60820","0.01787"
"29254","175.48800","14.62422","0.01822"
"29286","175.68000","14.64019","0.01862"
"29318","175.87200","14.65621","0.01954"
"29350","176.06400","14.67217","0.01964"
"29382","176.25600","14.68820","0.01913"
"29414","176.44800","14.70422","0.01956"
"29446","176.64000","14.72024","0.02039"
"29478","176.83200","14.73615","0.01956"
"29510","177.02400","14.75223","0.02001"
"29542","177.21600","14.76820","0.02026"
"29574","177.40800","14.78422","0.02120"
"29606","177.60000","14.80024","0.02101"
"29638","177.79200","14.81614","0.02100"
"29670","177.98400","14.83223","0.02057"
"29702","178.17600","14.84825","0.02152"
"29734","178.36800","14.86416","0.02196"
"29766","178.56000","14.88018","0.02208"
"29798","178.75200","14.89620","0.02209"
"29830","178.94400","14.91223","0.02289"
"29862","179.13600","14.92825","0.02280"
"29894","179.32800","14.94422","0.02363"
"29926","179.52000","14.96024","0.02466"
"29958","179.71200","14.97626","0.02438"
"29990","179.90400","14.99217","0.02518"
"30022","180.09600","15.00825","0.02510"
"30054","180.28800","15.02421","0.02573"
"30086","180.48000","15.04024","0.02615"
"30118","180.67200","15.05620","0.02664"
"30150","180.86400","15.07217","0.02637"
"30182","181.05600","15.08819","0.02775"
"30214","181.24800","15.10421","0.02805"
"30246","181.44000","15.12018","0.02811"
"30278","181.63200","15.13626","0.02833"
"30310","181.82400","15.15228","0.02887"
"30342","182.01600","15.16819","0.02980"
"30374","182.20800","15.18427","0.02982"
"30406","182.40000","15.20029","0.02988"
"30438","182.59200","15.21614","0.03002"
"30470","182.78400","15.23222","0.03118"
"30502","182.97600","15.24825","0.03104"
"30534","183.16800","15.26415","0.03126"
"30566","183.36000","15.28017","0.03242"
"30598","183.55200","15.29626","0.03231"
"30630","183.74400","15.31216","0.03303"
"30662","183.93600","15.32824","0.03271"
"30694","184.12800","15.34421","0.03328"
"30726","184.32000","15.36023","0.03391"
"30758","184.51200","15.37626","0.03424"
"30790","184.70400","15.39222","0.03443"
"30822","184.89600","15.40818","0.03496"
"30854","185.08800","15.42421","0.03517"
"30886","185.28000","15.44017","0.03508"
"30918","185.47200","15.45619","0.03474"
"30950","185.66400","15.47222","0.03555"
"30982","185.85600","15.48812","0.03607"
"31014","186.04800","15.50420","0.03647"
"31046","186.24000","15.52023","0.03673"
"31078","186.43200","15.53613","0.03757"
"31110","186.62400","15.55222","0.03793"
"31142","186.81600","15.56818","0.03796"
"31174","187.00800","15.58420","0.03838"
"31206","187.20000","15.60023","0.03875"
"31238","187.39200","15.61613","0.03893"
"31270","187.58400","15.63221","0.03907"
"31302","187.77600","15.64824","0.04001"
"31334","187.96800","15.66420","0.04001"
"31366","188.16000","15.68022","0.04038"
"31398","188.35200","15.69625","0.04038"
"31430","188.54400","15.71215","0.04116"
"31462","188.73600","15.72823","0.04153"
"31494","188.92800","15.74420","0.04121"
"31526","189.12000","15.76022","0.04183"
"31558","189.31200","15.77619","0.04217"
"31590","189.50400","15.79221","0.04237"
"31622","189.69600","15.80823","0.04224"
"31654","189.88800","15.82420","0.04313"
"31686","190.08000","15.84022","0.04299"
"31718","190.27200","15.85618","0.04359"
"31750","190.46400","15.87221","0.04377"
"31782","190.65600","15.88817","0.04383"
"31814","190.84800","15.90420","0.04400"
"31846","191.04000","15.92022","0.04463"
"31878","191.23200","15.93612","0.04477"
"31910","191.42400","15.95221","0.04456"
"31942","191.61600","15.96823","0.04518"
"31974","191.80800","15.98419","0.04515"
"32006","192.00000","16.00022","0.04522"
"32038","192.19200","16.01624","0.04585"
"32070","192.38400","16.03220","0.04574"
"32102","192.57600","16.04823","0.04609"
"32134","192.76800","16.06419","0.04624"
"32166","192.96000","16.08022","0.04644"
"32198","193.15200","16.09624","0.04667"
"32230","193.34400","16.11214","0.04717"
"32262","193.53600","16.12823","0.04712"
"32294","193.72800","16.14419","0.04764"
"32326","193.92000","16.16009","0.04737"
"32358","194.11200","16.17630","0.04751"
"32390","194.30400","16.19220","0.04767"
"32422","194.49600","16.20816","0.04815"
"32454","194.68800","16.22425","0.04800"
"32486","194.88000","16.24021","0.04849"
"32518","195.07200","16.25624","0.04874"
"32550","195.26400","16.27226","0.04889"
"32582","195.45600","16.28810","0.04921"
"32614","195.64800","16.30425","0.04920"
"32646","195.84000","16.32021","0.04947"
"32678","196.03200","16.33617","0.05014"
"32710","196.22400","16.35226","0.04966"
"32742","196.41600","16.36822","0.05037"
"32774","196.60800","16.38412","0.05032"
"32806","196.80000","16.40027","0.05070"
"32838","196.99200","16.41629","0.05104"
"32870","197.18400","16.43214","0.05153"
"32902","197.37600","16.44822","0.05152"
"32934","197.56800","16.46424","0.05214"
"32966","197.76000","16.48015","0.05216"
"32998","197.95200","16.49623","0.05226"
"33030","198.14400","16.51220","0.05282"
"33062","198.33600","16.52816","0.05312"
"33094","198.52800","16.54424","0.05346"
"33126","198.72000","16.56015","0.05365"
"33158","198.91200","16.57617","0.05392"
"33190","199.10400","16.59219","0.05470"
"33222","199.29600","16.60822","0.05466"
"33254","199.48800","16.62424","0.05510"
"33286","199.68000","16.64021","0.05558"
"33318","199.87200","16.65617","0.05650"
"33350","200.06400","16.67219","0.05659"
"33382","200.25600","16.68815","0.05711"
"33414","200.44800","16.70418","0.05850"
"33446","200.64000","16.72020","0.05825"
"33478","200.83200","16.73617","0.05908"
"33510","201.02400","16.75225","0.05925"
"33542","201.21600","16.76821","0.05953"
"33574","201.40800","16.78418","0.06064"
"33606","201.60000","16.80026","0.06121"
"33638","201.79200","16.81623","0.06132"
"33670","201.98400","16.83219","0.06215"
"33702","202.17600","16.84827","0.06321"
"33734","202.36800","16.86418","0.06341"
"33766","202.56000","16.88020","0.06423"
"33798","202.75200","16.89622","0.06474"
"33830","202.94400","16.91219","0.06520"
"33862","203.13600","16.92821","0.06589"
"33894","203.32800","16.94423","0.06678"
"33926","203.52000","16.96014","0.06693"
"33958","203.71200","16.97622","0.06775"
"33990","203.90400","16.99224","0.06753"
"34022","204.09600","17.00821","0.06899"
"34054","204.28800","17.02423","0.06928"
"34086","204.48000","17.04026","0.06965"
"34118","204.67200","17.05616","0.07044"
"34150","204.86400","17.07224","0.07099"
"34182","205.05600","17.08821","0.07125"
"34214","205.24800","17.10411","0.07225"
"34246","205.44000","17.12025","0.07195"
"34278","205.63200","17.13622","0.07311"
"34310","205.82400","17.15212","0.07368"
"34342","206.01600","17.16826","0.07380"
"34374","206.20800","17.18417","0.07170"
"34406","206.40000","17.20013","0.07270"
"34438","206.59200","17.21628","0.07333"
"34470","206.78400","17.23218","0.07371"
"34502","206.97600","17.24820","0.07437"
"34534","207.16800","17.26429","0.07487"
"34566","207.36000","17.28019","0.07551"
"34598","207.55200","17.29622","0.07560"
"34630","207.74400","17.31224","0.07663"
"34662","207.93600","17.32820","0.07766"
"34694","208.12800","17.34417","0.07751"
"34726","208.32000","17.36019","0.07783"
"34758","208.51200","17.37621","0.01526"
"34790","208.70400","17.39218","0.01764"
"34822","208.89600","17.40820","0.02012"
"34854","209.08800","17.42416","0.00837"
"34886","209.28000","17.44025","0.01805"
"34918","209.47200","17.45621","0.01537"
"34950","209.66400","17.47223","0.01229"
"34982","209.85600","17.48820","0.01788"
"35014","210.04800","17.50422","0.01599"
"35046","210.24000","17.52019","0.01546"
"35078","210.43200","17.53615","0.01471"
"35110","210.62400","17.55218","0.01947"
"35142","210.81600","17.56826","0.01497"
"35174","211.00800","17.58416","0.01507"
"35206","211.20000","17.60018","0.02199"
"35238","211.39200","17.61621","0.01430"
"35270","211.58400","17.63217","0.01709"
"35302","211.77600","17.64814","0.02004"
"35334","211.96800","17.66422","0.01697"
"35366","212.16000","17.68018","0.01829"
"35398","212.35200","17.69627","0.01919"
"35430","212.54400","17.71223","0.01897"
"35462","212.73600","17.72813","0.01753"
"35494","212.92800","17.74428","0.02195"
"35526","213.12000","17.76018","0.01882"
"35558","213.31200","17.77614","0.01962"
"35590","213.50400","17.79223","0.02254"
"35622","213.69600","17.80819","0.01964"
"35654","213.88800","17.82421","0.02058"
"35686","214.08000","17.84030","0.02248"
"35718","214.27200","17.85620","0.02172"
"35750","214.46400","17.87217","0.02075"
"35782","214.65600","17.88825","0.02390"
"35814","214.84800","17.90421","0.02199"
"35846","215.04000","17.92024","0.02220"
"35878","215.23200","17.93626","0.02462"
"35910","215.42400","17.95217","0.02299"
"35942","215.61600","17.96819","0.02373"
"35974","215.80800","17.98421","0.02514"
"36006","216.00000","18.00018","0.02398"
"36038","216.19200","18.01620","0.02462"
"36070","216.38400","18.03222","0.02678"
"36102","216.57600","18.04813","0.02487"
"36134","216.76800","18.06427","0.02646"
"36166","216.96000","18.08018","0.02693"
"36198","217.15200","18.09620","0.02489"
"36230","217.34400","18.11222","0.02609"
"36262","217.53600","18.12819","0.02689"
"36294","217.72800","18.14421","0.02633"
"36326","217.92000","18.16023","0.02752"
"36358","218.11200","18.17620","0.02773"
"36390","218.30400","18.19222","0.02669"
"36422","218.49600","18.20824","0.02877"
"36454","218.68800","18.22415","0.02819"
"36486","218.88000","18.24017","0.02798"
"36518","219.07200","18.25620","0.02991"
"36550","219.26400","18.27216","0.02874"
"36582","219.45600","18.28818","0.02804"
"36614","219.64800","18.30421","0.03008"
"36646","219.84000","18.32017","0.02882"
"36678","220.03200","18.33619","0.02944"
"36710","220.22400","18.35222","0.03050"
"36742","220.41600","18.36824","0.02961"
"36774","220.60800","18.38426","0.03026"
"36806","220.80000","18.40023","0.03055"
"36838","220.99200","18.41625","0.03032"
"36870","221.18400","18.43222","0.03224"
"36902","221.37600","18.44818","0.03233"
"36934","221.56800","18.46426","0.03133"
"36966","221.76000","18.48017","0.03344"
"36998","221.95200","18.49625","0.03308"
"37030","222.14400","18.51221","0.03257"
"37062","222.33600","18.52818","0.03416"
"37094","222.52800","18.54420","0.03439"
"37126","222.72000","18.56022","0.03338"
"37158","222.91200","18.57613","0.03525"
"37190","223.10400","18.59221","0.03475"
"37222","223.29600","18.60824","0.03469"
"37254","223.48800","18.62414","0.03568"
"37286","223.68000","18.64022","0.03559"
"37318","223.87200","18.65625","0.03588"
"37350","224.06400","18.67215","0.03660"
"37382","224.25600","18.68824","0.03679"
"37414","224.44800","18.70420","0.03624"
"37446","224.64000","18.72016","0.03408"
"37478","224.83200","18.73625","0.03364"
"37510","225.02400","18.75221","0.03487"
"37542","225.21600","18.76823","0.03359"
"37574","225.40800","18.78426","0.03411"
"37606","225.60000","18.80016","0.03412"
"37638","225.79200","18.81618","0.03457"
"37670","225.98400","18.83227","0.03516"
"37702","226.17600","18.84811","0.03500"
"37734","226.36800","18.86419","0.03629"
"37766","226.56000","18.88028","0.03679"
"37798","226.75200","18.89612","0.03698"
"37830","226.94400","18.91221","0.03749"
"37862","227.13600","18.92823","0.03683"
"37894","227.32800","18.94419","0.03816"
"37926","227.52000","18.96022","0.03881"
"37958","227.71200","18.97624","0.03795"
"37990","227.90400","18.99220","0.03844"
"38022","228.09600","19.00823","0.03860"
"38054","228.28800","19.02419","0.03794"
"38086","228.48000","19.04028","0.03945"
"38118","228.67200","19.05618","0.03991"
"38150","228.86400","19.07214","0.03974"
"38182","229.05600","19.08823","0.04029"
"38214","229.24800","19.10425","0.04011"
"38246","229.44000","19.12016","0.04052"
"38278","229.63200","19.13624","0.04153"
"38310","229.82400","19.15226","0.00083"
"38342","230.01600","19.16823","0.00310"
"38374","230.20800","19.18419","0.00086"
"38406","230.40000","19.20021","0.00045"
"38438","230.59200","19.21624","0.00093"
"38470","230.78400","19.23220","0.00672"
"38502","230.97600","19.24816","-0.00059"
"38534","231.16800","19.26425","-0.00014"
"38566","231.36000","19.28021","0.00354"
"38598","231.55200","19.29618","0.00168"
"38630","231.74400","19.31226","0.00073"
"38662","231.93600","19.32822","0.00529"
"38694","232.12800","19.34419","0.00081"
"38726","232.32000","19.36021","0.00087"
"38758","232.51200","19.37617","0.00329"
"38790","232.70400","19.39220","0.00016"
"38822","232.89600","19.40822","0.00341"
"38854","233.08800","19.42418","0.00379"
"38886","233.28000","19.44021","-0.00046"
"38918","233.47200","19.45623","0.00300"
"38950","233.66400","19.47219","0.00315"
"38982","233.85600","19.48822","-0.00089"
"39014","234.04800","19.50424","0.00348"
"39046","234.24000","19.52015","0.00394"
"39078","234.43200","19.53629","0.00033"
"39110","234.62400","19.55219","0.00322"
"39142","234.81600","19.56816","0.00225"
"39174","235.00800","19.58430","0.00024"
"39206","235.20000","19.60020","0.00308"
"39238","235.39200","19.61617","0.00250"
"39252","235.47200","19.62287","0.00112"