File: Force_trajectories/161223_2/Specimen_RawData_7.csv
End date,"12/23/2016"
Specimen label,"21BG_65"
Maximum Load,"0.28197",N

Time,Extension,Load
(s),(mm),(N)
"0.00000","0.00006","0.00061"
"0.18000","0.01196","0.00087"
"0.36000","0.03007","0.00095"
"0.54000","0.04532","0.00147"
"0.72000","0.06021","0.00185"
"0.90000","0.07528","0.00246"
"1.08000","0.09028","0.00296"
"1.26000","0.10523","0.00274"
"1.44000","0.12024","0.00254"
"1.62000","0.13524","0.00282"
"1.80000","0.15025","0.00301"
"1.98000","0.16520","0.00346"
"2.16000","0.18021","0.00363"
"2.34000","0.19521","0.00371"
"2.52000","0.21016","0.00336"
"2.70000","0.22523","0.00392"
"2.88000","0.24023","0.00409"
"3.06000","0.25518","0.00402"
"3.24000","0.27025","0.00402"
"3.42000","0.28520","0.00395"
"3.60000","0.30020","0.00460"
"3.78000","0.31527","0.00495"
"3.96000","0.33022","0.00471"
"4.14000","0.34516","0.00437"
"4.32000","0.36017","0.00505"
"4.50000","0.37524","0.00491"
"4.68000","0.39025","0.00523"
"4.86000","0.40519","0.00515"
"5.04000","0.42020","0.00477"
"5.22000","0.43521","0.00530"
"5.40000","0.45022","0.00501"
"5.58000","0.46522","0.00530"
"5.76000","0.48023","0.00544"
"5.94000","0.49530","0.00548"
"6.12000","0.51018","0.00480"
"6.30000","0.52519","0.00551"
"6.48000","0.54026","0.00555"
"6.66000","0.55521","0.00599"
"6.84000","0.57021","0.00574"
"7.02000","0.58522","0.00592"
"7.20000","0.60017","0.00626"
"7.38000","0.61523","0.00636"
"7.56000","0.63024","0.00633"
"7.74000","0.64525","0.00661"
"7.92000","0.66020","0.00664"
"8.10000","0.67526","0.00619"
"8.28000","0.69021","0.00660"
"8.46000","0.70516","0.00668"
"8.64000","0.72028","0.00693"
"8.82000","0.73523","0.00660"
"9.00000","0.75024","0.00700"
"9.18000","0.76519","0.00645"
"9.36000","0.78019","0.00682"
"9.54000","0.79520","0.00689"
"9.72000","0.81021","0.00680"
"9.90000","0.82522","0.00707"
"10.08000","0.84022","0.00715"
"10.26000","0.85523","0.00697"
"10.44000","0.87018","0.00719"
"10.62000","0.88524","0.00741"
"10.80000","0.90025","0.00721"
"10.98000","0.91526","0.00765"
"11.16000","0.93021","0.00727"
"11.34000","0.94521","0.00721"
"11.52000","0.96022","0.00758"
"11.70000","0.97523","0.00748"
"11.88000","0.99029","0.00752"
"12.06000","1.00524","0.00751"
"12.24000","1.02025","0.00760"
"12.42000","1.03532","0.00810"
"12.60000","1.05020","0.00762"
"12.78000","1.06521","0.00822"
"12.96000","1.08022","0.00749"
"13.14000","1.09522","0.00768"
"13.32000","1.11023","0.00768"
"13.50000","1.12524","0.00818"
"13.68000","1.14025","0.00754"
"13.86000","1.15519","0.00829"
"14.04000","1.17020","0.00791"
"14.22000","1.18521","0.00820"
"14.40000","1.20022","0.00812"
"14.58000","1.21528","0.00794"
"14.76000","1.23017","0.00784"
"14.94000","1.24524","0.00823"
"15.12000","1.26024","0.00818"
"15.30000","1.27519","0.00818"
"15.48000","1.29026","0.00791"
"15.66000","1.30527","0.00820"
"15.84000","1.32021","0.00857"
"16.02000","1.33522","0.00856"
"16.20000","1.35029","0.00822"
"16.38000","1.36517","0.00863"
"16.56000","1.38024","0.00831"
"16.74000","1.39525","0.00893"
"16.92000","1.41020","0.00880"
"17.10000","1.42520","0.00857"
"17.28000","1.44027","0.00877"
"17.46000","1.45522","0.00861"
"17.64000","1.47022","0.00877"
"17.82000","1.48529","0.00886"
"18.00000","1.50018","0.00880"
"18.18000","1.51519","0.00883"
"18.36000","1.53025","0.00884"
"18.54000","1.54520","0.00947"
"18.72000","1.56021","0.00911"
"18.90000","1.57527","0.00939"
"19.08000","1.59022","0.00914"
"19.26000","1.60523","0.00948"
"19.44000","1.62024","0.00950"
"19.62000","1.63518","0.00913"
"19.80000","1.65025","0.00902"
"19.98000","1.66526","0.00912"
"20.16000","1.68027","0.00907"
"20.34000","1.69521","0.00905"
"20.52000","1.71022","0.00932"
"20.70000","1.72523","0.00912"
"20.88000","1.74023","0.00979"
"21.06000","1.75524","0.00974"
"21.24000","1.77019","0.00886"
"21.42000","1.78526","0.00967"
"21.60000","1.80026","0.00967"
"21.78000","1.81521","0.00985"
"21.96000","1.83022","0.00949"
"22.14000","1.84522","0.00991"
"22.32000","1.86023","0.00962"
"22.50000","1.87524","0.00899"
"22.68000","1.89025","0.00906"
"22.86000","1.90519","0.00916"
"23.04000","1.92026","0.00950"
"23.22000","1.93527","0.00928"
"23.40000","1.95022","0.00939"
"23.58000","1.96522","0.00938"
"23.76000","1.98023","0.00923"
"23.94000","1.99518","0.00939"
"24.12000","2.01024","0.00974"
"24.30000","2.02525","0.00974"
"24.48000","2.04020","0.01005"
"24.66000","2.05527","0.00967"
"24.84000","2.07021","0.00965"
"25.02000","2.08522","0.00979"
"25.20000","2.10029","0.01000"
"25.38000","2.11523","0.00968"
"25.56000","2.13018","0.00961"
"25.74000","2.14519","0.00971"
"25.92000","2.16026","0.00956"
"26.10000","2.17520","0.00965"
"26.28000","2.19021","0.00978"
"26.46000","2.20528","0.01007"
"26.64000","2.22016","0.01028"
"26.82000","2.23529","0.00971"
"27.00000","2.25024","0.01008"
"27.18000","2.26525","0.00993"
"27.36000","2.28025","0.01025"
"27.54000","2.29526","0.01020"
"27.72000","2.31021","0.00978"
"27.90000","2.32527","0.01039"
"28.08000","2.34028","0.01019"
"28.26000","2.35517","0.01014"
"28.44000","2.37024","0.00962"
"28.62000","2.38524","0.01037"
"28.80000","2.40019","0.01023"
"28.98000","2.41526","0.01041"
"29.16000","2.43021","0.01033"
"29.34000","2.44521","0.01000"
"29.52000","2.46022","0.01038"
"29.70000","2.47523","0.01042"
"29.88000","2.49017","0.01014"
"30.06000","2.50530","0.01029"
"30.24000","2.52019","0.01018"
"30.42000","2.53520","0.01041"
"30.60000","2.55026","0.01094"
"30.78000","2.56521","0.01083"
"30.96000","2.58016","0.01051"
"31.14000","2.59522","0.01057"
"31.32000","2.61023","0.01044"
"31.50000","2.62518","0.01063"
"31.68000","2.64025","0.01045"
"31.86000","2.65525","0.01054"
"32.04000","2.67020","0.01046"
"32.22000","2.68533","0.01028"
"32.40000","2.70021","0.01000"
"32.58000","2.71516","0.00989"
"32.76000","2.73029","0.00999"
"32.94000","2.74530","0.01021"
"33.12000","2.76012","0.00993"
"33.30000","2.77525","0.00977"
"33.48000","2.79026","0.00996"
"33.66000","2.80521","0.00990"
"33.84000","2.82027","0.00952"
"34.02000","2.83522","0.00990"
"34.20000","2.85023","0.00998"
"34.38000","2.86523","0.00963"
"34.56000","2.88024","0.00942"
"34.74000","2.89513","0.00911"
"34.92000","2.91026","0.00936"
"35.10000","2.92526","0.00934"
"35.28000","2.94021","0.00966"
"35.46000","2.95522","0.00929"
"35.64000","2.97028","0.00969"
"35.82000","2.98523","0.00957"
"36.00000","3.00024","0.01006"
"36.18000","3.01525","0.00975"
"36.36000","3.03025","0.00956"
"36.54000","3.04526","0.01018"
"36.72000","3.06021","0.00954"
"36.90000","3.07516","0.00962"
"37.08000","3.09028","0.00992"
"37.26000","3.10529","0.00992"
"37.44000","3.12018","0.01002"
"37.62000","3.13524","0.01030"
"37.80000","3.15025","0.00988"
"37.98000","3.16520","0.01031"
"38.16000","3.18027","0.01033"
"38.34000","3.19521","0.01014"
"38.52000","3.21016","0.00968"
"38.70000","3.22523","0.01004"
"38.88000","3.24023","0.01065"
"39.06000","3.25518","0.01042"
"39.24000","3.27025","0.01083"
"39.42000","3.28520","0.01123"
"39.60000","3.30014","0.01074"
"39.78000","3.31521","0.01026"
"39.96000","3.33028","0.01045"
"40.14000","3.34522","0.01091"
"40.32000","3.36023","0.01060"
"40.50000","3.37524","0.01062"
"40.68000","3.39025","0.01071"
"40.86000","3.40531","0.01050"
"41.04000","3.42020","0.01070"
"41.22000","3.43521","0.01072"
"41.40000","3.45027","0.01128"
"41.58000","3.46522","0.01062"
"41.76000","3.48017","0.01083"
"41.94000","3.49524","0.01108"
"42.12000","3.51024","0.01083"
"42.30000","3.52519","0.01077"
"42.48000","3.54026","0.01118"
"42.66000","3.55521","0.01138"
"42.84000","3.57021","0.01097"
"43.02000","3.58528","0.01097"
"43.20000","3.60023","0.01166"
"43.38000","3.61523","0.01097"
"43.56000","3.63024","0.01166"
"43.74000","3.64525","0.01155"
"43.92000","3.66020","0.01182"
"44.10000","3.67526","0.01164"
"44.28000","3.69021","0.01200"
"44.46000","3.70522","0.01163"
"44.64000","3.72022","0.01102"
"44.82000","3.73523","0.01115"
"45.00000","3.75024","0.01113"
"45.18000","3.76519","0.01156"
"45.36000","3.78019","0.01174"
"45.54000","3.79520","0.01131"
"45.72000","3.81027","0.01148"
"45.90000","3.82521","0.01168"
"46.08000","3.84016","0.01199"
"46.26000","3.85523","0.01198"
"46.44000","3.87024","0.01175"
"46.62000","3.88524","0.01164"
"46.80000","3.90025","0.01192"
"46.98000","3.91526","0.01220"
"47.16000","3.93021","0.01191"
"47.34000","3.94521","0.01234"
"47.52000","3.96016","0.01194"
"47.70000","3.97523","0.01155"
"47.88000","3.99023","0.01138"
"48.06000","4.00518","0.01101"
"48.24000","4.02019","0.01183"
"48.42000","4.03526","0.01155"
"48.60000","4.05026","0.01140"
"48.78000","4.06521","0.01265"
"48.96000","4.08022","0.01194"
"49.14000","4.09528","0.01198"
"49.32000","4.11023","0.01102"
"49.50000","4.12524","0.01153"
"49.68000","4.14019","0.01173"
"49.86000","4.15525","0.01169"
"50.04000","4.17026","0.01191"
"50.22000","4.18521","0.01200"
"50.40000","4.20021","0.01217"
"50.58000","4.21528","0.01218"
"50.76000","4.23023","0.01250"
"50.94000","4.24518","0.01267"
"51.12000","4.26024","0.01266"
"51.30000","4.27525","0.01241"
"51.48000","4.29020","0.01309"
"51.66000","4.30526","0.01273"
"51.84000","4.32021","0.01300"
"52.02000","4.33522","0.01275"
"52.20000","4.35017","0.01320"
"52.38000","4.36517","0.01324"
"52.56000","4.38018","0.01327"
"52.74000","4.39531","0.01342"
"52.92000","4.41026","0.01409"
"53.10000","4.42514","0.01426"
"53.28000","4.44027","0.01374"
"53.46000","4.45522","0.01371"
"53.64000","4.47016","0.01430"
"53.82000","4.48517","0.01429"
"54.00000","4.50024","0.01431"
"54.18000","4.51525","0.01431"
"54.36000","4.53025","0.01402"
"54.54000","4.54526","0.01461"
"54.72000","4.56021","0.01446"
"54.90000","4.57527","0.01482"
"55.08000","4.59022","0.01517"
"55.26000","4.60517","0.01496"
"55.44000","4.62024","0.01478"
"55.62000","4.63524","0.01535"
"55.80000","4.65025","0.01521"
"55.98000","4.66520","0.01574"
"56.16000","4.68021","0.01563"
"56.34000","4.69527","0.01622"
"56.52000","4.71022","0.01578"
"56.70000","4.72517","0.01590"
"56.88000","4.74023","0.01589"
"57.06000","4.75524","0.01597"
"57.24000","4.77019","0.01621"
"57.42000","4.78520","0.01526"
"57.60000","4.80026","0.01566"
"57.78000","4.81521","0.01627"
"57.96000","4.83022","0.01607"
"58.14000","4.84522","0.01642"
"58.32000","4.86023","0.01625"
"58.50000","4.87524","0.01601"
"58.68000","4.89025","0.01626"
"58.86000","4.90519","0.01637"
"59.04000","4.92026","0.01622"
"59.22000","4.93521","0.01661"
"59.40000","4.95027","0.01650"
"59.58000","4.96522","0.01651"
"59.76000","4.98023","0.01719"
"59.94000","4.99524","0.01714"
"60.12000","5.01018","0.01697"
"60.30000","5.02525","0.01706"
"60.48000","5.04026","0.01779"
"60.66000","5.05520","0.01793"
"60.84000","5.07021","0.01784"
"61.02000","5.08522","0.01824"
"61.20000","5.10029","0.01793"
"61.38000","5.11523","0.01810"
"61.56000","5.13018","0.01835"
"61.74000","5.14519","0.01833"
"61.92000","5.16026","0.01863"
"62.10000","5.17520","0.01881"
"62.28000","5.19021","0.01817"
"62.46000","5.20522","0.01895"
"62.64000","5.22022","0.01903"
"62.82000","5.23517","0.01945"
"63.00000","5.25024","0.01900"
"63.18000","5.26519","0.01916"
"63.36000","5.28019","0.02005"
"63.54000","5.29526","0.01977"
"63.72000","5.31021","0.01972"
"63.90000","5.32521","0.02022"
"64.08000","5.34028","0.02024"
"64.26000","5.35523","0.02025"
"64.44000","5.37024","0.02074"
"64.62000","5.38524","0.02037"
"64.80000","5.40025","0.02077"
"64.98000","5.41520","0.02077"
"65.16000","5.43020","0.02057"
"65.34000","5.44521","0.02042"
"65.52000","5.46022","0.02063"
"65.70000","5.47523","0.02038"
"65.88000","5.49017","0.02131"
"66.06000","5.50524","0.02072"
"66.24000","5.52025","0.02137"
"66.42000","5.53520","0.02105"
"66.60000","5.55020","0.02118"
"66.78000","5.56527","0.02089"
"66.96000","5.58016","0.02134"
"67.14000","5.59522","0.02134"
"67.32000","5.61029","0.02131"
"67.50000","5.62518","0.02091"
"67.68000","5.64025","0.02178"
"67.86000","5.65525","0.02135"
"68.04000","5.67020","0.02134"
"68.22000","5.68527","0.02187"
"68.40000","5.70027","0.02199"
"68.58000","5.71516","0.02173"
"68.76000","5.73023","0.02168"
"68.94000","5.74530","0.02157"
"69.12000","5.76018","0.02206"
"69.30000","5.77519","0.02216"
"69.48000","5.79026","0.02226"
"69.66000","5.80520","0.02253"
"69.84000","5.82021","0.02243"
"70.02000","5.83522","0.02310"
"70.20000","5.85023","0.02301"
"70.38000","5.86523","0.02287"
"70.56000","5.88030","0.02269"
"70.74000","5.89519","0.02289"
"70.92000","5.91020","0.02202"
"71.10000","5.92526","0.02271"
"71.28000","5.94021","0.02242"
"71.46000","5.95522","0.02274"
"71.64000","5.97022","0.02227"
"71.82000","5.98523","0.02213"
"72.00000","6.00024","0.02288"
"72.18000","6.01525","0.02265"
"72.36000","6.03025","0.02279"
"72.54000","6.04520","0.02287"
"72.72000","6.06027","0.02323"
"72.90000","6.07521","0.02301"
"73.08000","6.09022","0.02312"
"73.26000","6.10523","0.02311"
"73.44000","6.12024","0.02347"
"73.62000","6.13518","0.02351"
"73.80000","6.15025","0.02358"
"73.98000","6.16526","0.02381"
"74.16000","6.18020","0.02359"
"74.34000","6.19527","0.02371"
"74.52000","6.21022","0.02287"
"74.70000","6.22523","0.02308"
"74.88000","6.24029","0.02326"
"75.06000","6.25518","0.02323"
"75.24000","6.27025","0.02342"
"75.42000","6.28525","0.02316"
"75.60000","6.30014","0.02313"
"75.78000","6.31521","0.02369"
"75.96000","6.33028","0.02342"
"76.14000","6.34516","0.02273"
"76.32000","6.36023","0.02293"
"76.50000","6.37524","0.02343"
"76.68000","6.39019","0.02368"
"76.86000","6.40525","0.02366"
"77.04000","6.42026","0.02418"
"77.22000","6.43521","0.02383"
"77.40000","6.45021","0.02343"
"77.58000","6.46528","0.02407"
"77.76000","6.48017","0.02455"
"77.94000","6.49518","0.02323"
"78.12000","6.51024","0.02384"
"78.30000","6.52519","0.02365"
"78.48000","6.54026","0.02406"
"78.66000","6.55526","0.02393"
"78.84000","6.57021","0.02413"
"79.02000","6.58522","0.02460"
"79.20000","6.60023","0.02476"
"79.38000","6.61517","0.02458"
"79.56000","6.63024","0.02457"
"79.74000","6.64525","0.02524"
"79.92000","6.66019","0.02375"
"80.10000","6.67526","0.02392"
"80.28000","6.69021","0.02386"
"80.46000","6.70522","0.02427"
"80.64000","6.72022","0.02357"
"80.82000","6.73523","0.02372"
"81.00000","6.75024","0.02465"
"81.18000","6.76531","0.02465"
"81.36000","6.78025","0.02468"
"81.54000","6.79520","0.02488"
"81.72000","6.81027","0.02529"
"81.90000","6.82521","0.02554"
"82.08000","6.84016","0.02552"
"82.26000","6.85523","0.02585"
"82.44000","6.87024","0.02584"
"82.62000","6.88518","0.02662"
"82.80000","6.90025","0.02654"
"82.98000","6.91526","0.02623"
"83.16000","6.93026","0.02693"
"83.34000","6.94527","0.02712"
"83.52000","6.96022","0.02662"
"83.70000","6.97517","0.02675"
"83.88000","6.99029","0.02711"
"84.06000","7.00524","0.02705"
"84.24000","7.02013","0.02765"
"84.42000","7.03525","0.02719"
"84.60000","7.05026","0.02790"
"84.78000","7.06515","0.02773"
"84.96000","7.08022","0.02735"
"85.14000","7.09528","0.02824"
"85.32000","7.11017","0.02787"
"85.50000","7.12530","0.02858"
"85.68000","7.14025","0.02906"
"85.86000","7.15519","0.02851"
"86.04000","7.17026","0.02862"
"86.22000","7.18521","0.02890"
"86.40000","7.20015","0.02849"
"86.58000","7.21522","0.02874"
"86.76000","7.23029","0.02947"
"86.94000","7.24512","0.02964"
"87.12000","7.26024","0.02990"
"87.30000","7.27525","0.02965"
"87.48000","7.29020","0.02983"
"87.66000","7.30526","0.03015"
"87.84000","7.32027","0.03055"
"88.02000","7.33516","0.03074"
"88.20000","7.35023","0.03035"
"88.38000","7.36523","0.03071"
"88.56000","7.38018","0.03116"
"88.74000","7.39531","0.03133"
"88.92000","7.41025","0.03088"
"89.10000","7.42514","0.03123"
"89.28000","7.44021","0.03199"
"89.46000","7.45528","0.03135"
"89.64000","7.47022","0.03189"
"89.82000","7.48523","0.03227"
"90.00000","7.50024","0.03242"
"90.18000","7.51519","0.03295"
"90.36000","7.53025","0.03249"
"90.54000","7.54520","0.03328"
"90.72000","7.56015","0.03313"
"90.90000","7.57527","0.03382"
"91.08000","7.59022","0.03398"
"91.26000","7.60517","0.03421"
"91.44000","7.62024","0.03438"
"91.62000","7.63524","0.03467"
"91.80000","7.65019","0.03459"
"91.98000","7.66526","0.03518"
"92.16000","7.68026","0.03563"
"92.34000","7.69521","0.03555"
"92.52000","7.71028","0.03625"
"92.70000","7.72517","0.03697"
"92.88000","7.74017","0.03669"
"93.06000","7.75524","0.03692"
"93.24000","7.77025","0.03731"
"93.42000","7.78514","0.03742"
"93.60000","7.80026","0.03734"
"93.78000","7.81527","0.03832"
"93.96000","7.83016","0.03883"
"94.14000","7.84528","0.03915"
"94.32000","7.86023","0.03929"
"94.50000","7.87524","0.03957"
"94.68000","7.89024","0.04054"
"94.86000","7.90519","0.04063"
"95.04000","7.92020","0.04089"
"95.22000","7.93521","0.04125"
"95.40000","7.95021","0.04157"
"95.58000","7.96516","0.04203"
"95.76000","7.98023","0.04210"
"95.94000","7.99524","0.04293"
"96.12000","8.01018","0.04360"
"96.30000","8.02519","0.04413"
"96.48000","8.04026","0.04428"
"96.66000","8.05520","0.04459"
"96.84000","8.07021","0.04521"
"97.02000","8.08522","0.04603"
"97.20000","8.10023","0.04630"
"97.38000","8.11529","0.04682"
"97.56000","8.13018","0.04744"
"97.74000","8.14519","0.04749"
"97.92000","8.16031","0.04823"
"98.10000","8.17526","0.04831"
"98.28000","8.19021","0.04905"
"98.46000","8.20522","0.04919"
"98.64000","8.22028","0.04831"
"98.82000","8.23523","0.04833"
"99.00000","8.25024","0.04864"
"99.18000","8.26519","0.04944"
"99.36000","8.28019","0.04914"
"99.54000","8.29526","0.04982"
"99.72000","8.31015","0.05073"
"99.90000","8.32521","0.05084"
"100.08000","8.34028","0.05145"
"100.26000","8.35523","0.05181"
"100.44000","8.37018","0.05245"
"100.62000","8.38524","0.05298"
"100.80000","8.40025","0.05379"
"100.98000","8.41520","0.05433"
"101.16000","8.43020","0.05498"
"101.34000","8.44521","0.05555"
"101.52000","8.46022","0.05578"
"101.70000","8.47523","0.05648"
"101.88000","8.49023","0.05733"
"102.06000","8.50518","0.05667"
"102.24000","8.52025","0.05730"
"102.42000","8.53525","0.05829"
"102.60000","8.55014","0.05893"
"102.78000","8.56527","0.05967"
"102.96000","8.58028","0.06061"
"103.14000","8.59522","0.06172"
"103.32000","8.61029","0.06266"
"103.50000","8.62524","0.06388"
"103.68000","8.64019","0.06399"
"103.86000","8.65525","0.06496"
"104.04000","8.67020","0.06636"
"104.22000","8.68521","0.06689"
"104.40000","8.70027","0.06810"
"104.58000","8.71522","0.06821"
"104.76000","8.73017","0.06896"
"104.94000","8.74524","0.06995"
"105.12000","8.76024","0.07042"
"105.30000","8.77519","0.07114"
"105.48000","8.79020","0.07189"
"105.66000","8.80520","0.07276"
"105.84000","8.82021","0.07289"
"106.02000","8.83522","0.07413"
"106.20000","8.85023","0.07481"
"106.38000","8.86523","0.07484"
"106.56000","8.88024","0.07559"
"106.74000","8.89525","0.07562"
"106.92000","8.91020","0.07561"
"107.10000","8.92526","0.07652"
"107.28000","8.94021","0.07669"
"107.46000","8.95522","0.07719"
"107.64000","8.97022","0.07725"
"107.82000","8.98523","0.07822"
"108.00000","9.00018","0.07846"
"108.18000","9.01525","0.07924"
"108.36000","9.03019","0.07844"
"108.54000","9.04520","0.07883"
"108.72000","9.06021","0.07922"
"108.90000","9.07521","0.07956"
"109.08000","9.09022","0.07990"
"109.26000","9.10529","0.07958"
"109.44000","9.12024","0.08028"
"109.62000","9.13518","0.08036"
"109.80000","9.15019","0.07966"
"109.98000","9.16520","0.07697"
"110.16000","9.18021","0.07728"
"110.34000","9.19521","0.07744"
"110.52000","9.21016","0.07760"
"110.70000","9.22523","0.07797"
"110.88000","9.24023","0.07863"
"111.06000","9.25524","0.07976"
"111.24000","9.27025","0.08072"
"111.42000","9.28531","0.08204"
"111.60000","9.30020","0.08282"
"111.78000","9.31521","0.08345"
"111.96000","9.33022","0.08421"
"112.14000","9.34522","0.08568"
"112.32000","9.36023","0.08696"
"112.50000","9.37524","0.08813"
"112.68000","9.39019","0.08966"
"112.86000","9.40525","0.09072"
"113.04000","9.42026","0.09318"
"113.22000","9.43521","0.09386"
"113.40000","9.45021","0.09548"
"113.58000","9.46528","0.09618"
"113.76000","9.48023","0.09655"
"113.94000","9.49518","0.09732"
"114.12000","9.51024","0.06850"
"114.30000","9.52519","0.05336"
"114.48000","9.54020","0.05201"
"114.66000","9.55520","0.05255"
"114.84000","9.57021","0.04975"
"115.02000","9.58522","0.04736"
"115.20000","9.60023","0.05070"
"115.38000","9.61517","0.05140"
"115.56000","9.63024","0.05154"
"115.74000","9.64531","0.05447"
"115.92000","9.66019","0.05339"
"116.10000","9.67526","0.05430"
"116.28000","9.69021","0.04519"
"116.46000","9.70522","0.04273"
"116.64000","9.72022","0.04356"
"116.82000","9.73523","0.04213"
"117.00000","9.75018","0.04191"
"117.18000","9.76519","0.04330"
"117.36000","9.78025","0.04307"
"117.54000","9.79514","0.04416"
"117.72000","9.81027","0.04517"
"117.90000","9.82533","0.04504"
"118.08000","9.84016","0.04616"
"118.26000","9.85523","0.04683"
"118.44000","9.87024","0.04709"
"118.62000","9.88518","0.04884"
"118.80000","9.90025","0.04915"
"118.98000","9.91526","0.04973"
"119.16000","9.93020","0.05111"
"119.34000","9.94521","0.05054"
"119.52000","9.96028","0.05215"
"119.70000","9.97517","0.05259"
"119.88000","9.99023","0.05261"
"120.06000","10.00524","0.05420"
"120.24000","10.02019","0.05336"
"120.42000","10.03520","0.05410"
"120.60000","10.05026","0.05570"
"120.78000","10.06521","0.05490"
"120.96000","10.08016","0.05655"
"121.14000","10.09522","0.05695"
"121.32000","10.11023","0.05656"
"121.50000","10.12524","0.05906"
"121.68000","10.14024","0.05836"
"121.86000","10.15519","0.05982"
"122.04000","10.17020","0.06093"
"122.22000","10.18527","0.06057"
"122.40000","10.20015","0.06224"
"122.58000","10.21522","0.06192"
"122.76000","10.23023","0.06283"
"122.94000","10.24518","0.06401"
"123.12000","10.26018","0.06366"
"123.30000","10.27525","0.06565"
"123.48000","10.29026","0.06572"
"123.66000","10.30526","0.06675"
"123.84000","10.32027","0.06737"
"124.02000","10.33522","0.06770"
"124.20000","10.35023","0.06918"
"124.38000","10.36523","0.06916"
"124.56000","10.38024","0.07069"
"124.74000","10.39525","0.07173"
"124.92000","10.41025","0.07145"
"125.10000","10.42520","0.07189"
"125.28000","10.44021","0.07329"
"125.46000","10.45527","0.07358"
"125.64000","10.47022","0.07503"
"125.82000","10.48523","0.07519"
"126.00000","10.50030","0.07608"
"126.18000","10.51519","0.07694"
"126.36000","10.53031","0.07710"
"126.54000","10.54526","0.07828"
"126.72000","10.56015","0.07831"
"126.90000","10.57527","0.07971"
"127.08000","10.59028","0.08057"
"127.26000","10.60517","0.08116"
"127.44000","10.62024","0.08176"
"127.62000","10.63524","0.08243"
"127.80000","10.65019","0.08495"
"127.98000","10.66526","0.08489"
"128.16000","10.68026","0.08587"
"128.34000","10.69521","0.08699"
"128.52000","10.71028","0.08784"
"128.70000","10.72523","0.08963"
"128.88000","10.74017","0.09070"
"129.06000","10.75524","0.09072"
"129.24000","10.77025","0.09200"
"129.42000","10.78520","0.09341"
"129.60000","10.80020","0.09452"
"129.78000","10.81527","0.09497"
"129.96000","10.83016","0.09433"
"130.14000","10.84522","0.09473"
"130.32000","10.86023","0.09543"
"130.50000","10.87524","0.09586"
"130.68000","10.89019","0.09592"
"130.86000","10.90525","0.09697"
"131.04000","10.92020","0.09747"
"131.22000","10.93521","0.09631"
"131.40000","10.95021","0.09685"
"131.58000","10.96516","0.09669"
"131.76000","10.98023","0.09756"
"131.94000","10.99518","0.09767"
"132.12000","11.01018","0.09853"
"132.30000","11.02525","0.09923"
"132.48000","11.04020","0.09982"
"132.66000","11.05526","0.10099"
"132.84000","11.07021","0.10081"
"133.02000","11.08522","0.10116"
"133.20000","11.10017","0.10147"
"133.38000","11.11529","0.10228"
"133.56000","11.13024","0.10246"
"133.74000","11.14519","0.10300"
"133.92000","11.16025","0.10402"
"134.10000","11.17526","0.10400"
"134.28000","11.19021","0.10487"
"134.46000","11.20522","0.10581"
"134.64000","11.22022","0.10334"
"134.82000","11.23523","0.10411"
"135.00000","11.25030","0.10456"
"135.18000","11.26525","0.10547"
"135.36000","11.28019","0.10599"
"135.54000","11.29526","0.10665"
"135.72000","11.31021","0.10748"
"135.90000","11.32510","0.10772"
"136.08000","11.34028","0.10909"
"136.26000","11.35529","0.10971"
"136.44000","11.37012","0.11052"
"136.62000","11.38524","0.11094"
"136.80000","11.40025","0.11228"
"136.98000","11.41514","0.11254"
"137.16000","11.43026","0.11383"
"137.34000","11.44527","0.11455"
"137.52000","11.46022","0.11537"
"137.70000","11.47529","0.11682"
"137.88000","11.49023","0.11720"
"138.06000","11.50512","0.11844"
"138.24000","11.52031","0.11950"
"138.42000","11.53525","0.11988"
"138.60000","11.55014","0.12132"
"138.78000","11.56527","0.12203"
"138.96000","11.58028","0.12302"
"139.14000","11.59516","0.12431"
"139.32000","11.61023","0.12541"
"139.50000","11.62524","0.12613"
"139.68000","11.64019","0.12687"
"139.86000","11.65525","0.12776"
"140.04000","11.67026","0.12885"
"140.22000","11.68515","0.12955"
"140.40000","11.70027","0.13115"
"140.58000","11.71528","0.13247"
"140.76000","11.73023","0.13340"
"140.94000","11.74523","0.13474"
"141.12000","11.76024","0.13707"
"141.30000","11.77525","0.13877"
"141.48000","11.79020","0.14047"
"141.66000","11.80520","0.14271"
"141.84000","11.82021","0.14414"
"142.02000","11.83528","0.14586"
"142.20000","11.85022","0.14861"
"142.38000","11.86517","0.14978"
"142.56000","11.88030","0.15153"
"142.74000","11.89519","0.15230"
"142.92000","11.91019","0.15264"
"143.10000","11.92526","0.15437"
"143.28000","11.94027","0.15508"
"143.46000","11.95522","0.15592"
"143.64000","11.97022","0.15675"
"143.82000","11.98523","0.15760"
"144.00000","12.00024","0.15854"
"144.18000","12.01524","0.13650"
"144.36000","12.03019","0.13517"
"144.54000","12.04514","0.13429"
"144.72000","12.06021","0.13385"
"144.90000","12.07521","0.12541"
"145.08000","12.09016","0.05839"
"145.26000","12.10529","0.06658"
"145.44000","12.12030","0.05818"
"145.62000","12.13518","0.07141"
"145.80000","12.15025","0.06045"
"145.98000","12.16526","0.07028"
"146.16000","12.18020","0.07035"
"146.34000","12.19527","0.07033"
"146.52000","12.21022","0.07302"
"146.70000","12.22517","0.07192"
"146.88000","12.24023","0.07514"
"147.06000","12.25524","0.07580"
"147.24000","12.27019","0.07553"
"147.42000","12.28525","0.07427"
"147.60000","12.30020","0.07514"
"147.78000","12.31521","0.07563"
"147.96000","12.33022","0.07646"
"148.14000","12.34522","0.07615"
"148.32000","12.36017","0.07761"
"148.50000","12.37524","0.08012"
"148.68000","12.39019","0.08000"
"148.86000","12.40519","0.08440"
"149.04000","12.42026","0.08181"
"149.22000","12.43521","0.08130"
"149.40000","12.45015","0.08508"
"149.58000","12.46528","0.08321"
"149.76000","12.48023","0.08928"
"149.94000","12.49518","0.08770"
"150.12000","12.51024","0.09078"
"150.30000","12.52525","0.09437"
"150.48000","12.54026","0.09427"
"150.66000","12.55520","0.09846"
"150.84000","12.57021","0.09731"
"151.02000","12.58522","0.09947"
"151.20000","12.60029","0.10093"
"151.38000","12.61517","0.10132"
"151.56000","12.63024","0.10410"
"151.74000","12.64531","0.10334"
"151.92000","12.66019","0.10572"
"152.10000","12.67520","0.10565"
"152.28000","12.69021","0.10692"
"152.46000","12.70522","0.10892"
"152.64000","12.72022","0.10927"
"152.82000","12.73523","0.11183"
"153.00000","12.75024","0.11183"
"153.18000","12.76525","0.11465"
"153.36000","12.78019","0.11495"
"153.54000","12.79520","0.11713"
"153.72000","12.81021","0.11901"
"153.90000","12.82527","0.11960"
"154.08000","12.84022","0.12226"
"154.26000","12.85517","0.12243"
"154.44000","12.87030","0.12550"
"154.62000","12.88524","0.12554"
"154.80000","12.90019","0.12802"
"154.98000","12.91526","0.12952"
"155.16000","12.93020","0.13044"
"155.34000","12.94521","0.13463"
"155.52000","12.96022","0.13483"
"155.70000","12.97517","0.14018"
"155.88000","12.99017","0.14065"
"156.06000","13.00524","0.14557"
"156.24000","13.02025","0.14701"
"156.42000","13.03525","0.15007"
"156.60000","13.05026","0.15218"
"156.78000","13.06527","0.15405"
"156.96000","13.08022","0.15618"
"157.14000","13.09522","0.15688"
"157.32000","13.11023","0.16009"
"157.50000","13.12524","0.15992"
"157.68000","13.14024","0.16379"
"157.86000","13.15525","0.16393"
"158.04000","13.17026","0.16821"
"158.22000","13.18527","0.16925"
"158.40000","13.20021","0.17282"
"158.58000","13.21516","0.17425"
"158.76000","13.23029","0.17793"
"158.94000","13.24524","0.17870"
"159.12000","13.26018","0.18083"
"159.30000","13.27519","0.18230"
"159.48000","13.29020","0.18290"
"159.66000","13.30521","0.18506"
"159.84000","13.32021","0.18595"
"160.02000","13.33516","0.18840"
"160.20000","13.35017","0.18943"
"160.38000","13.36523","0.19233"
"160.56000","13.38018","0.19355"
"160.74000","13.39525","0.19606"
"160.92000","13.41031","0.19757"
"161.10000","13.42520","0.20049"
"161.28000","13.44021","0.20118"
"161.46000","13.45522","0.20388"
"161.64000","13.47022","0.20487"
"161.82000","13.48523","0.20750"
"162.00000","13.50024","0.20865"
"162.18000","13.51519","0.21080"
"162.36000","13.53025","0.21169"
"162.54000","13.54532","0.21402"
"162.72000","13.56021","0.21469"
"162.90000","13.57521","0.21654"
"163.08000","13.59028","0.21714"
"163.26000","13.60523","0.21863"
"163.44000","13.62024","0.21947"
"163.62000","13.63524","0.22155"
"163.80000","13.65019","0.22211"
"163.98000","13.66520","0.22439"
"164.16000","13.68026","0.22598"
"164.34000","13.69521","0.22811"
"164.52000","13.71022","0.22946"
"164.70000","13.72529","0.23072"
"164.88000","13.74017","0.23198"
"165.06000","13.75518","0.23285"
"165.24000","13.77031","0.23364"
"165.42000","13.78519","0.23508"
"165.60000","13.80020","0.23458"
"165.78000","13.81521","0.23634"
"165.96000","13.83022","0.23680"
"166.14000","13.84522","0.23861"
"166.32000","13.86023","0.23943"
"166.50000","13.87524","0.24029"
"166.68000","13.89018","0.23626"
"166.86000","13.90525","0.23719"
"167.04000","13.92020","0.23835"
"167.22000","13.93521","0.24056"
"167.40000","13.95021","0.24208"
"167.58000","13.96522","0.24455"
"167.76000","13.98023","0.24616"
"167.94000","13.99524","0.24952"
"168.12000","14.01018","0.25145"
"168.30000","14.02519","0.25380"
"168.48000","14.04026","0.25649"
"168.66000","14.05520","0.25900"
"168.84000","14.07027","0.26085"
"169.02000","14.08522","0.26409"
"169.20000","14.10023","0.26663"
"169.38000","14.11523","0.16416"
"169.56000","14.13024","0.16114"
"169.74000","14.14519","0.15983"
"169.92000","14.16020","0.16072"
"170.10000","14.17526","0.15980"
"170.28000","14.19021","0.14665"
"170.46000","14.20522","0.12564"
"170.64000","14.22022","0.12934"
"170.82000","14.23523","0.12950"
"171.00000","14.25024","0.13333"
"171.18000","14.26524","0.13541"
"171.36000","14.28013","0.13704"
"171.54000","14.29526","0.14040"
"171.72000","14.31027","0.14363"
"171.90000","14.32521","0.14562"
"172.08000","14.34022","0.14879"
"172.26000","14.35529","0.15005"
"172.44000","14.37018","0.15404"
"172.62000","14.38518","0.15529"
"172.80000","14.40025","0.15669"
"172.98000","14.41520","0.15839"
"173.16000","14.43020","0.15832"
"173.34000","14.44527","0.16147"
"173.52000","14.46022","0.16374"
"173.70000","14.47523","0.16700"
"173.88000","14.49023","0.16952"
"174.06000","14.50518","0.17270"
"174.24000","14.52019","0.17549"
"174.42000","14.53525","0.17803"
"174.60000","14.55014","0.18027"
"174.78000","14.56521","0.18190"
"174.96000","14.58022","0.18373"
"175.14000","14.59522","0.18516"
"175.32000","14.61023","0.18725"
"175.50000","14.62530","0.18844"
"175.68000","14.64025","0.18939"
"175.86000","14.65525","0.18989"
"176.04000","14.67026","0.19009"
"176.22000","14.68521","0.19063"
"176.40000","14.70021","0.19238"
"176.58000","14.71522","0.19274"
"176.76000","14.73023","0.19081"
"176.94000","14.74523","0.19253"
"177.12000","14.76024","0.18778"
"177.30000","14.77525","0.18881"
"177.48000","14.79026","0.19089"
"177.66000","14.80520","0.19319"
"177.84000","14.82015","0.19401"
"178.02000","14.83528","0.19660"
"178.20000","14.85023","0.19860"
"178.38000","14.86517","0.20073"
"178.56000","14.88024","0.20269"
"178.74000","14.89525","0.20505"
"178.92000","14.91013","0.20647"
"179.10000","14.92520","0.20916"
"179.28000","14.94027","0.21039"
"179.46000","14.95522","0.21183"
"179.64000","14.97028","0.21340"
"179.82000","14.98523","0.21515"
"180.00000","15.00018","0.21610"
"180.18000","15.01524","0.21749"
"180.36000","15.03025","0.21851"
"180.54000","15.04520","0.22012"
"180.72000","15.06021","0.22086"
"180.90000","15.07521","0.22289"
"181.08000","15.09022","0.22350"
"181.26000","15.10523","0.16414"
"181.44000","15.12024","0.16217"
"181.62000","15.13524","0.16170"
"181.80000","15.15025","0.16479"
"181.98000","15.16520","0.16388"
"182.16000","15.18020","0.16750"
"182.34000","15.19521","0.16963"
"182.52000","15.21022","0.17169"
"182.70000","15.22517","0.17462"
"182.88000","15.24023","0.17589"
"183.06000","15.25518","0.17792"
"183.24000","15.27013","0.17979"
"183.42000","15.28525","0.18090"
"183.60000","15.30026","0.18266"
"183.78000","15.31521","0.18369"
"183.96000","15.33028","0.18455"
"184.14000","15.34522","0.18665"
"184.32000","15.36017","0.18761"
"184.50000","15.37524","0.18931"
"184.68000","15.39025","0.19030"
"184.86000","15.40519","0.19270"
"185.04000","15.42026","0.19473"
"185.22000","15.43521","0.19633"
"185.40000","15.45015","0.19855"
"185.58000","15.46528","0.20085"
"185.76000","15.48023","0.20206"
"185.94000","15.49518","0.20415"
"186.12000","15.51024","0.20518"
"186.30000","15.52525","0.20670"
"186.48000","15.54020","0.20819"
"186.66000","15.55526","0.20947"
"186.84000","15.57021","0.21089"
"187.02000","15.58516","0.21151"
"187.20000","15.60029","0.21321"
"187.38000","15.61517","0.21477"
"187.56000","15.63012","0.21652"
"187.74000","15.64525","0.21715"
"187.92000","15.66025","0.21781"
"188.10000","15.67514","0.21840"
"188.28000","15.69027","0.21984"
"188.46000","15.70521","0.22105"
"188.64000","15.72016","0.22224"
"188.82000","15.73529","0.22390"
"189.00000","15.75024","0.22520"
"189.18000","15.76518","0.22626"
"189.36000","15.78025","0.22787"
"189.54000","15.79520","0.22988"
"189.72000","15.81015","0.23120"
"189.90000","15.82527","0.23290"
"190.08000","15.84028","0.23427"
"190.26000","15.85517","0.23576"
"190.44000","15.87023","0.23734"
"190.62000","15.88524","0.23849"
"190.80000","15.90019","0.24109"
"190.98000","15.91526","0.24287"
"191.16000","15.93020","0.24438"
"191.34000","15.94521","0.24649"
"191.52000","15.96022","0.24868"
"191.70000","15.97522","0.25079"
"191.88000","15.99011","0.25302"
"192.06000","16.00524","0.25448"
"192.24000","16.02025","0.25598"
"192.42000","16.03525","0.25755"
"192.60000","16.05026","0.25776"
"192.78000","16.06527","0.25417"
"192.96000","16.08022","0.25533"
"193.14000","16.09528","0.25717"
"193.32000","16.11023","0.25853"
"193.50000","16.12524","0.26068"
"193.68000","16.14024","0.26291"
"193.86000","16.15519","0.26502"
"194.04000","16.17014","0.26676"
"194.22000","16.18532","0.26949"
"194.40000","16.20021","0.27073"
"194.58000","16.21516","0.27329"
"194.76000","16.23023","0.27497"
"194.94000","16.24529","0.27731"
"195.12000","16.26018","0.27915"
"195.30000","16.27525","0.28111"
"195.48000","16.29026","0.28076"
"195.66000","16.30520","0.16211"
"195.84000","16.32021","0.15742"
"196.02000","16.33522","0.16130"
"196.20000","16.35016","0.15789"
"196.38000","16.36523","0.16483"
"196.56000","16.38024","0.16273"
"196.74000","16.39519","0.16701"
"196.92000","16.41025","0.17080"
"197.10000","16.42526","0.17065"
"197.28000","16.44015","0.17606"
"197.46000","16.45521","0.17835"
"197.64000","16.47022","0.18032"
"197.82000","16.48523","0.18261"
"198.00000","16.50024","0.18397"
"198.18000","16.51518","0.18501"
"198.36000","16.53019","0.18908"
"198.54000","16.54526","0.18845"
"198.72000","16.56021","0.19381"
"198.90000","16.57515","0.19339"
"199.08000","16.59028","0.19624"
"199.26000","16.60523","0.19789"
"199.44000","16.62017","0.20041"
"199.62000","16.63524","0.20161"
"199.80000","16.65025","0.20556"
"199.98000","16.66520","0.20509"
"200.16000","16.68020","0.20846"
"200.34000","16.69521","0.21043"
"200.52000","16.71022","0.21236"
"200.70000","16.72528","0.21417"
"200.88000","16.74023","0.21644"
"201.06000","16.75518","0.21727"
"201.24000","16.77024","0.21929"
"201.42000","16.78525","0.22057"
"201.60000","16.80020","0.22170"
"201.78000","16.81521","0.22331"
"201.96000","16.83027","0.22597"
"202.14000","16.84516","0.22735"
"202.32000","16.86023","0.23061"
"202.50000","16.87518","0.23195"
"202.68000","16.89025","0.23442"
"202.86000","16.90525","0.23558"
"203.04000","16.92014","0.23907"
"203.22000","16.93521","0.23964"
"203.40000","16.95027","0.24326"
"203.58000","16.96516","0.24463"
"203.76000","16.98023","0.24849"
"203.94000","16.99523","0.24944"
"204.12000","17.01018","0.25270"
"204.30000","17.02519","0.25392"
"204.48000","17.04026","0.25621"
"204.66000","17.05520","0.11121"
"204.84000","17.07027","0.11000"
"205.02000","17.08522","0.10834"
"205.20000","17.10022","0.11036"
"205.38000","17.11517","0.03947"
"205.56000","17.13024","0.02161"
"205.74000","17.14525","0.02400"
"205.92000","17.16019","0.02566"
"206.10000","17.17526","0.02526"
"206.28000","17.19027","0.02189"
"206.46000","17.20522","0.02303"
"206.64000","17.22022","0.02318"
"206.82000","17.23523","0.02189"
"207.00000","17.25024","0.02387"
"207.18000","17.26524","0.02373"
"207.36000","17.28019","0.02386"
"207.54000","17.29520","0.02430"
"207.72000","17.31026","0.02465"
"207.90000","17.32521","0.02409"
"208.08000","17.34016","0.02513"
"208.26000","17.35523","0.02595"
"208.44000","17.37024","0.02566"
"208.62000","17.38518","0.02707"
"208.80000","17.40019","0.02695"
"208.98000","17.41525","0.02726"
"209.16000","17.43020","0.02727"
"209.34000","17.44527","0.02861"
"209.52000","17.46028","0.02822"
"209.70000","17.47523","0.02893"
"209.88000","17.49023","0.02893"
"210.06000","17.50518","0.02987"
"210.24000","17.52019","0.02920"
"210.42000","17.53525","0.03050"
"210.60000","17.55026","0.03067"
"210.78000","17.56521","0.03086"
"210.96000","17.58022","0.03144"
"211.14000","17.59522","0.03174"
"211.32000","17.61017","0.03176"
"211.50000","17.62524","0.03251"
"211.68000","17.64018","0.03292"
"211.86000","17.65525","0.03319"
"212.04000","17.67020","0.03368"
"212.22000","17.68521","0.03404"
"212.40000","17.70021","0.03403"
"212.58000","17.71528","0.03474"
"212.76000","17.73023","0.03499"
"212.94000","17.74517","0.03579"
"213.12000","17.76024","0.03664"
"213.30000","17.77519","0.03649"
"213.48000","17.79020","0.03672"
"213.66000","17.80526","0.03724"
"213.84000","17.82021","0.03823"
"214.02000","17.83528","0.03862"
"214.20000","17.85028","0.03948"
"214.38000","17.86517","0.04003"
"214.56000","17.88024","0.04050"
"214.74000","17.89531","0.04177"
"214.92000","17.91019","0.04210"
"215.10000","17.92520","0.04318"
"215.28000","17.94027","0.04363"
"215.46000","17.95522","0.04407"
"215.64000","17.97022","0.04451"
"215.82000","17.98523","0.04393"
"216.00000","18.00018","0.04506"
"216.18000","18.01524","0.04596"
"216.36000","18.03025","0.04669"
"216.54000","18.04520","0.04736"
"216.72000","18.06021","0.04809"
"216.90000","18.07527","0.04837"
"217.08000","18.09022","0.04908"
"217.26000","18.10523","0.04991"
"217.44000","18.12024","0.05048"
"217.62000","18.13518","0.05104"
"217.80000","18.15019","0.05138"
"217.98000","18.16520","0.05221"
"218.16000","18.18020","0.05211"
"218.34000","18.19527","0.05322"
"218.52000","18.21022","0.05375"
"218.70000","18.22523","0.05478"
"218.88000","18.24023","0.05559"
"219.06000","18.25530","0.04767"
"219.24000","18.27019","0.04800"
"219.42000","18.28519","0.04763"
"219.60000","18.30020","0.04955"
"219.78000","18.31521","0.04969"
"219.96000","18.33022","0.05123"
"220.14000","18.34522","0.05135"
"220.32000","18.36023","0.05236"
"220.50000","18.37524","0.05385"
"220.68000","18.39024","0.05384"
"220.86000","18.40519","0.05391"
"221.04000","18.42026","0.05322"
"221.22000","18.43527","0.05310"
"221.40000","18.45021","0.05356"
"221.58000","18.46522","0.05513"
"221.76000","18.48023","0.05499"
"221.94000","18.49517","0.05675"
"222.12000","18.51024","0.05681"
"222.30000","18.52525","0.05781"
"222.48000","18.54020","0.05905"
"222.66000","18.55526","0.05955"
"222.84000","18.57027","0.05967"
"223.02000","18.58522","0.06185"
"223.20000","18.60028","0.06216"
"223.38000","18.61523","0.06409"
"223.56000","18.63018","0.06497"
"223.74000","18.64519","0.06349"
"223.92000","18.66025","0.06429"
"224.10000","18.67514","0.06469"
"224.28000","18.69021","0.06546"
"224.46000","18.70527","0.06609"
"224.64000","18.72016","0.06684"
"224.82000","18.73523","0.06812"
"225.00000","18.75030","0.06818"
"225.18000","18.76518","0.06851"
"225.36000","18.78025","0.06869"
"225.54000","18.79526","0.06901"
"225.72000","18.81015","0.07047"
"225.90000","18.82521","0.07097"
"226.08000","18.84028","0.07135"
"226.26000","18.85523","0.07152"
"226.44000","18.87024","0.07215"
"226.62000","18.88524","0.07271"
"226.80000","18.90025","0.06914"
"226.98000","18.91520","0.06944"
"227.16000","18.93020","0.06964"
"227.34000","18.94521","0.07132"
"227.52000","18.96022","0.07145"
"227.70000","18.97522","0.07178"
"227.88000","18.99017","0.07194"
"228.06000","19.00524","0.07289"
"228.24000","19.02025","0.07396"
"228.42000","19.03519","0.06599"
"228.60000","19.05026","0.06491"
"228.78000","19.06521","0.06564"
"228.96000","19.08022","0.06749"
"229.14000","19.09522","0.06825"
"229.32000","19.11023","0.06990"
"229.50000","19.12518","0.06941"
"229.68000","19.14024","0.06919"
"229.86000","19.15525","0.06720"
"230.04000","19.17020","0.06673"
"230.22000","19.18526","0.06653"
"230.40000","19.20021","0.06700"
"230.58000","19.21516","0.06736"
"230.76000","19.23023","0.06673"
"230.94000","19.24529","0.06686"
"231.12000","19.26018","0.06667"
"231.30000","19.27525","0.06700"
"231.48000","19.29025","0.06107"
"231.66000","19.30520","0.04737"
"231.84000","19.32027","0.04275"
"232.02000","19.33522","0.02129"
"232.20000","19.35023","0.00517"
"232.38000","19.36523","0.00759"
"232.56000","19.38024","0.00698"
"232.74000","19.39519","0.00511"
"232.92000","19.41019","0.00545"
"233.10000","19.42526","0.00524"
"233.28000","19.44021","0.00478"
"233.46000","19.45522","0.00551"
"233.64000","19.47022","0.00641"
"233.82000","19.48523","0.00613"
"234.00000","19.50024","0.00544"
"234.18000","19.51524","0.00503"
"234.36000","19.53019","0.00448"
"234.54000","19.54526","0.00530"
"234.72000","19.56027","0.00553"
"234.90000","19.57515","0.00615"
"235.08000","19.59022","0.00532"
"235.26000","19.60523","0.00507"
"235.44000","19.62017","0.00522"
"235.62000","19.63524","0.00507"
"235.80000","19.65025","0.00558"
"235.98000","19.66520","0.00584"
"236.16000","19.68026","0.00552"
"236.34000","19.69527","0.00478"
"236.52000","19.71022","0.00512"
"236.70000","19.72528","0.00542"
"236.88000","19.74023","0.00573"
"237.06000","19.75518","0.00630"
"237.24000","19.77025","0.00600"
"237.42000","19.78525","0.00530"
"237.60000","19.80020","0.00554"
"237.78000","19.81521","0.00538"
"237.96000","19.83022","0.00561"
"238.14000","19.84516","0.00598"
"238.32000","19.86023","0.00576"
"238.50000","19.87524","0.00567"
"238.68000","19.89018","0.00549"
"238.86000","19.90525","0.00494"
"239.04000","19.92020","0.00559"
"239.22000","19.93515","0.00629"
"239.40000","19.95027","0.00601"
"239.58000","19.96528","0.00548"
"239.76000","19.98017","0.00556"
"239.94000","19.99529","0.00558"
"240.12000","20.01024","0.00585"
"240.30000","20.02519","0.00631"
"240.48000","20.04025","0.00599"
"240.66000","20.05526","0.00569"
"240.84000","20.07021","0.00542"
"241.02000","20.08528","0.00604"
"241.20000","20.10023","0.00645"
"241.38000","20.11517","0.00652"
"241.56000","20.13024","0.00573"
"241.74000","20.14524","0.00602"
"241.92000","20.16019","0.00595"
"242.10000","20.17526","0.00616"
"242.28000","20.19027","0.00655"
"242.46000","20.20521","0.00645"
"242.64000","20.22022","0.00595"
"242.82000","20.23523","0.00609"
"243.00000","20.25023","0.00612"
"243.18000","20.26524","0.00643"
"243.36000","20.28025","0.00664"
"243.54000","20.29514","0.00661"
"243.72000","20.31027","0.00665"
"243.90000","20.32521","0.00658"
"244.08000","20.34016","0.00655"
"244.26000","20.35529","0.00642"
"244.44000","20.37029","0.00630"
"244.62000","20.38524","0.00654"
"244.80000","20.40025","0.00628"
"244.98000","20.41520","0.00664"
"245.16000","20.43020","0.00681"
"245.34000","20.44527","0.00674"
"245.52000","20.46022","0.00655"
"245.70000","20.47517","0.00653"
"245.88000","20.49029","0.00648"
"246.06000","20.50518","0.00629"
"246.24000","20.52019","0.00593"
"246.42000","20.53525","0.00580"
"246.60000","20.55026","0.00574"
"246.78000","20.56521","0.00540"
"246.96000","20.58022","0.00586"
"247.14000","20.59522","0.00601"
"247.32000","20.61023","0.00549"
"247.50000","20.62524","0.00579"
"247.68000","20.64024","0.00581"
"247.86000","20.65519","0.00585"
"248.04000","20.67026","0.00597"
"248.22000","20.68526","0.00566"
"248.40000","20.70015","0.00564"
"248.58000","20.71528","0.00584"
"248.76000","20.73023","0.00600"
"248.94000","20.74517","0.00594"
"249.12000","20.76024","0.00549"
"249.30000","20.77525","0.00610"
"249.48000","20.79020","0.00598"
"249.66000","20.80520","0.00555"
"249.84000","20.82021","0.00588"
"250.02000","20.83521","0.00566"
"250.20000","20.85028","0.00597"
"250.38000","20.86523","0.00575"
"250.56000","20.88012","0.00587"
"250.74000","20.89525","0.00601"
"250.92000","20.91025","0.00629"
"251.10000","20.92520","0.00580"
"251.28000","20.94021","0.00570"
"251.46000","20.95528","0.00618"
"251.64000","20.97022","0.00608"
"251.82000","20.98517","0.00579"
"252.00000","21.00018","0.00566"
"252.18000","21.01524","0.00567"
"252.36000","21.03025","0.00555"
"252.54000","21.04526","0.00601"
"252.72000","21.06020","0.00562"
"252.90000","21.07521","0.00594"
"253.08000","21.09022","0.00618"
"253.26000","21.10523","0.00631"
"253.44000","21.12024","0.00581"
"253.62000","21.13524","0.00604"
"253.80000","21.15025","0.00608"
"253.98000","21.16525","0.00557"
"254.16000","21.18020","0.00577"
"254.34000","21.19521","0.00589"
"254.52000","21.21022","0.00578"
"254.70000","21.22517","0.00548"
"254.88000","21.24023","0.00563"
"255.06000","21.25524","0.00579"
"255.24000","21.27019","0.00570"
"255.42000","21.28519","0.00580"
"255.60000","21.30020","0.00541"
"255.78000","21.31527","0.00548"
"255.96000","21.33021","0.00568"
"256.14000","21.34522","0.00564"
"256.32000","21.36017","0.00567"
"256.50000","21.37523","0.00571"
"256.68000","21.39024","0.00574"
"256.86000","21.40525","0.00568"
"257.04000","21.42020","0.00611"
"257.22000","21.43527","0.00600"
"257.40000","21.45021","0.00558"
"257.58000","21.46516","0.00619"
"257.76000","21.48023","0.00587"
"257.94000","21.49529","0.00577"
"258.12000","21.51018","0.00603"
"258.30000","21.52525","0.00564"
"258.48000","21.54020","0.00615"
"258.66000","21.55520","0.00589"
"258.84000","21.57021","0.00633"
"259.02000","21.58522","0.00625"
"259.20000","21.60022","0.00609"
"259.38000","21.61529","0.00619"
"259.56000","21.63018","0.00612"
"259.74000","21.64519","0.00585"
"259.92000","21.66025","0.00587"
"260.10000","21.67520","0.00597"
"260.28000","21.69021","0.00613"
"260.46000","21.70522","0.00551"
"260.64000","21.72022","0.00627"
"260.82000","21.73517","0.00619"
"261.00000","21.75024","0.00610"
"261.18000","21.76524","0.00621"
"261.36000","21.78019","0.00614"
"261.47400","21.78970","0.00618"