File: Force_trajectories/161223_2/Specimen_RawData_8.csv
End date,"12/23/2016"
Specimen label,"21BG_UNK"
Maximum Load,"0.01081",N

Time,Extension,Load
(s),(mm),(N)
"0.00000","-0.00006","0.00034"
"0.06600","0.00149","0.00053"
"0.13200","0.00646","0.00030"
"0.19800","0.01369","-0.00017"
"0.26400","0.02087","0.00068"
"0.33000","0.02738","0.00020"
"0.39600","0.03324","0.00010"
"0.46200","0.03874","0.00022"
"0.52800","0.04418","0.00057"
"0.59400","0.04969","0.00053"
"0.66000","0.05519","0.00018"
"0.72600","0.06075","0.00024"
"0.79200","0.06631","0.00067"
"0.85800","0.07175","0.00063"
"0.92400","0.07725","0.00035"
"0.99000","0.08269","0.00065"
"1.05600","0.08819","0.00059"
"1.12200","0.09369","0.00056"
"1.18800","0.09919","0.00027"
"1.25400","0.10469","0.00054"
"1.32000","0.11025","0.00044"
"1.38600","0.11575","0.00022"
"1.45200","0.12125","0.00038"
"1.51800","0.12669","0.00030"
"1.58400","0.13213","0.00059"
"1.65000","0.13764","0.00040"
"1.71600","0.14314","0.00019"
"1.78200","0.14870","0.00085"
"1.84800","0.15420","0.00076"
"1.91400","0.15976","0.00043"
"1.98000","0.16520","0.00042"
"2.04600","0.17076","0.00037"
"2.11200","0.17620","0.00050"
"2.17800","0.18170","0.00054"
"2.24400","0.18714","0.00054"
"2.31000","0.19270","0.00065"
"2.37600","0.19820","0.00080"
"2.44200","0.20370","0.00058"
"2.50800","0.20920","0.00071"
"2.57400","0.21470","0.00061"
"2.64000","0.22020","0.00084"
"2.70600","0.22571","0.00072"
"2.77200","0.23121","0.00071"
"2.83800","0.23665","0.00140"
"2.90400","0.24221","0.00029"
"2.97000","0.24771","0.00068"
"3.03600","0.25321","0.00044"
"3.10200","0.25877","0.00077"
"3.16800","0.26421","0.00050"
"3.23400","0.26965","0.00039"
"3.30000","0.27515","0.00045"
"3.36600","0.28071","0.00085"
"3.43200","0.28615","0.00085"
"3.49800","0.29165","0.00059"
"3.56400","0.29715","0.00070"
"3.63000","0.30271","0.00103"
"3.69600","0.30822","0.00086"
"3.76200","0.31372","0.00105"
"3.82800","0.31916","0.00045"
"3.89400","0.32466","0.00092"
"3.96000","0.33022","0.00089"
"4.02600","0.33572","0.00071"
"4.09200","0.34122","0.00086"
"4.15800","0.34672","0.00058"
"4.22400","0.35222","0.00128"
"4.29000","0.35772","0.00073"
"4.35600","0.36316","0.00089"
"4.42200","0.36866","0.00117"
"4.48800","0.37416","0.00054"
"4.55400","0.37972","0.00065"
"4.62000","0.38522","0.00079"
"4.68600","0.39072","0.00100"
"4.75200","0.39617","0.00069"
"4.81800","0.40167","0.00097"
"4.88400","0.40717","0.00066"
"4.95000","0.41261","0.00109"
"5.01600","0.41817","0.00072"
"5.08200","0.42373","0.00069"
"5.14800","0.42917","0.00091"
"5.21400","0.43473","0.00095"
"5.28000","0.44017","0.00090"
"5.34600","0.44573","0.00096"
"5.41200","0.45117","0.00085"
"5.47800","0.45667","0.00116"
"5.54400","0.46217","0.00082"
"5.61000","0.46773","0.00090"
"5.67600","0.47323","0.00068"
"5.74200","0.47868","0.00076"
"5.80800","0.48418","0.00084"
"5.87400","0.48968","0.00046"
"5.94000","0.49518","0.00103"
"6.00600","0.50062","0.00101"
"6.07200","0.50618","0.00082"
"6.13800","0.51168","0.00101"
"6.20400","0.51724","0.00089"
"6.27000","0.52268","0.00098"
"6.33600","0.52824","0.00065"
"6.40200","0.53368","0.00057"
"6.46800","0.53918","0.00037"
"6.53400","0.54468","0.00037"
"6.60000","0.55018","0.00066"
"6.66600","0.55568","0.00070"
"6.73200","0.56118","0.00077"
"6.79800","0.56669","0.00084"
"6.86400","0.57219","0.00092"
"6.93000","0.57769","0.00058"
"6.99600","0.58313","0.00024"
"7.06200","0.58869","0.00120"
"7.12800","0.59413","0.00125"
"7.19400","0.59969","0.00068"
"7.26000","0.60525","0.00088"
"7.32600","0.61069","0.00120"
"7.39200","0.61619","0.00106"
"7.45800","0.62169","0.00141"
"7.52400","0.62719","0.00100"
"7.59000","0.63263","0.00118"
"7.65600","0.63813","0.00103"
"7.72200","0.64369","0.00107"
"7.78800","0.64925","0.00079"
"7.85400","0.65470","0.00077"
"7.92000","0.66020","0.00087"
"7.98600","0.66570","0.00128"
"8.05200","0.67114","0.00108"
"8.11800","0.67664","0.00096"
"8.18400","0.68208","0.00096"
"8.25000","0.68770","0.00106"
"8.31600","0.69320","0.00117"
"8.38200","0.69870","0.00088"
"8.44800","0.70420","0.00109"
"8.51400","0.70976","0.00075"
"8.58000","0.71514","0.00083"
"8.64600","0.72070","0.00063"
"8.71200","0.72608","0.00104"
"8.77800","0.73170","0.00096"
"8.84400","0.73720","0.00099"
"8.91000","0.74277","0.00054"
"8.97600","0.74821","0.00074"
"9.04200","0.75371","0.00073"
"9.10800","0.75921","0.00104"
"9.17400","0.76465","0.00074"
"9.24000","0.77015","0.00083"
"9.30600","0.77565","0.00102"
"9.37200","0.78127","0.00073"
"9.43800","0.78671","0.00101"
"9.50400","0.79227","0.00083"
"9.57000","0.79771","0.00103"
"9.63600","0.80321","0.00134"
"9.70200","0.80865","0.00068"
"9.76800","0.81415","0.00087"
"9.83400","0.81965","0.00057"
"9.90000","0.82516","0.00101"
"9.96600","0.83072","0.00111"
"10.03200","0.83616","0.00098"
"10.09800","0.84172","0.00118"
"10.16400","0.84716","0.00103"
"10.23000","0.85272","0.00112"
"10.29600","0.85816","0.00109"
"10.36200","0.86372","0.00098"
"10.42800","0.86916","0.00099"
"10.49400","0.87472","0.00081"
"10.56000","0.88022","0.00059"
"10.62600","0.88572","0.00084"
"10.69200","0.89122","0.00090"
"10.75800","0.89660","0.00130"
"10.82400","0.90216","0.00121"
"10.89000","0.90761","0.00113"
"10.95600","0.91323","0.00084"
"11.02200","0.91873","0.00092"
"11.08800","0.92429","0.00088"
"11.15400","0.92973","0.00051"
"11.22000","0.93523","0.00110"
"11.28600","0.94073","0.00095"
"11.35200","0.94617","0.00066"
"11.41800","0.95167","0.00093"
"11.48400","0.95717","0.00081"
"11.55000","0.96267","0.00114"
"11.61600","0.96823","0.00071"
"11.68200","0.97373","0.00127"
"11.74800","0.97923","0.00114"
"11.81400","0.98467","0.00120"
"11.88000","0.99023","0.00156"
"11.94600","0.99568","0.00080"
"12.01200","1.00118","0.00132"
"12.07800","1.00668","0.00139"
"12.14400","1.01218","0.00119"
"12.21000","1.01774","0.00079"
"12.27600","1.02318","0.00100"
"12.34200","1.02868","0.00114"
"12.40800","1.03418","0.00111"
"12.47400","1.03962","0.00099"
"12.54000","1.04518","0.00081"
"12.60600","1.05068","0.00082"
"12.67200","1.05624","0.00090"
"12.73800","1.06168","0.00112"
"12.80400","1.06724","0.00124"
"12.87000","1.07268","0.00107"
"12.93600","1.07818","0.00120"
"13.00200","1.08363","0.00114"
"13.06800","1.08919","0.00102"
"13.13400","1.09475","0.00125"
"13.20000","1.10019","0.00159"
"13.26600","1.10575","0.00136"
"13.33200","1.11119","0.00185"
"13.39800","1.11675","0.00097"
"13.46400","1.12219","0.00113"
"13.53000","1.12769","0.00114"
"13.59600","1.13319","0.00166"
"13.66200","1.13875","0.00155"
"13.72800","1.14425","0.00161"
"13.79400","1.14975","0.00112"
"13.86000","1.15525","0.00169"
"13.92600","1.16069","0.00121"
"13.99200","1.16619","0.00172"
"14.05800","1.17170","0.00104"
"14.12400","1.17714","0.00156"
"14.19000","1.18270","0.00143"
"14.25600","1.18826","0.00142"
"14.32200","1.19370","0.00146"
"14.38800","1.19920","0.00143"
"14.45400","1.20470","0.00148"
"14.52000","1.21020","0.00189"
"14.58600","1.21564","0.00184"
"14.65200","1.22114","0.00160"
"14.71800","1.22670","0.00190"
"14.78400","1.23214","0.00179"
"14.85000","1.23770","0.00190"
"14.91600","1.24320","0.00176"
"14.98200","1.24870","0.00191"
"15.04800","1.25415","0.00168"
"15.11400","1.25971","0.00164"
"15.18000","1.26515","0.00148"
"15.24600","1.27071","0.00173"
"15.31200","1.27621","0.00170"
"15.37800","1.28171","0.00210"
"15.44400","1.28721","0.00200"
"15.51000","1.29271","0.00171"
"15.57600","1.29821","0.00164"
"15.64200","1.30365","0.00157"
"15.70800","1.30915","0.00157"
"15.77400","1.31465","0.00161"
"15.84000","1.32021","0.00150"
"15.90600","1.32571","0.00140"
"15.97200","1.33121","0.00152"
"16.03800","1.33671","0.00164"
"16.10400","1.34222","0.00162"
"16.17000","1.34766","0.00143"
"16.23600","1.35316","0.00193"
"16.30200","1.35866","0.00128"
"16.36800","1.36422","0.00172"
"16.43400","1.36972","0.00146"
"16.50000","1.37516","0.00171"
"16.56600","1.38072","0.00164"
"16.63200","1.38616","0.00222"
"16.69800","1.39166","0.00204"
"16.76400","1.39710","0.00201"
"16.83000","1.40272","0.00191"
"16.89600","1.40822","0.00181"
"16.96200","1.41378","0.00158"
"17.02800","1.41922","0.00167"
"17.09400","1.42472","0.00203"
"17.16000","1.43023","0.00173"
"17.22600","1.43567","0.00202"
"17.29200","1.44111","0.00207"
"17.35800","1.44661","0.00188"
"17.42400","1.45223","0.00166"
"17.49000","1.45773","0.00211"
"17.55600","1.46323","0.00238"
"17.62200","1.46867","0.00174"
"17.68800","1.47423","0.00189"
"17.75400","1.47967","0.00236"
"17.82000","1.48517","0.00203"
"17.88600","1.49061","0.00170"
"17.95200","1.49623","0.00183"
"18.01800","1.50173","0.00132"
"18.08400","1.50723","0.00223"
"18.15000","1.51274","0.00176"
"18.21600","1.51818","0.00176"
"18.28200","1.52374","0.00205"
"18.34800","1.52918","0.00159"
"18.41400","1.53468","0.00205"
"18.48000","1.54018","0.00220"
"18.54600","1.54574","0.00156"
"18.61200","1.55118","0.00170"
"18.67800","1.55674","0.00158"
"18.74400","1.56218","0.00193"
"18.81000","1.56768","0.00182"
"18.87600","1.57312","0.00206"
"18.94200","1.57862","0.00191"
"19.00800","1.58418","0.00232"
"19.07400","1.58968","0.00195"
"19.14000","1.59518","0.00217"
"19.20600","1.60075","0.00187"
"19.27200","1.60619","0.00189"
"19.33800","1.61169","0.00181"
"19.40400","1.61713","0.00157"
"19.47000","1.62263","0.00204"
"19.53600","1.62813","0.00158"
"19.60200","1.63369","0.00219"
"19.66800","1.63919","0.00224"
"19.73400","1.64469","0.00212"
"19.80000","1.65019","0.00205"
"19.86600","1.65569","0.00181"
"19.93200","1.66119","0.00176"
"19.99800","1.66663","0.00168"
"20.06400","1.67213","0.00196"
"20.13000","1.67763","0.00178"
"20.19600","1.68319","0.00196"
"20.26200","1.68876","0.00177"
"20.32800","1.69420","0.00187"
"20.39400","1.69970","0.00212"
"20.46000","1.70514","0.00177"
"20.52600","1.71064","0.00194"
"20.59200","1.71620","0.00178"
"20.65800","1.72170","0.00186"
"20.72400","1.72720","0.00219"
"20.79000","1.73264","0.00203"
"20.85600","1.73820","0.00237"
"20.92200","1.74370","0.00221"
"20.98800","1.74920","0.00219"
"21.05400","1.75464","0.00214"
"21.12000","1.76020","0.00144"
"21.18600","1.76564","0.00209"
"21.25200","1.77121","0.00198"
"21.31800","1.77671","0.00182"
"21.38400","1.78221","0.00217"
"21.45000","1.78771","0.00222"
"21.51600","1.79315","0.00236"
"21.58200","1.79871","0.00198"
"21.64800","1.80415","0.00182"
"21.71400","1.80971","0.00187"
"21.78000","1.81521","0.00174"
"21.84600","1.82077","0.00239"
"21.91200","1.82621","0.00203"
"21.97800","1.83171","0.00218"
"22.04400","1.83715","0.00196"
"22.11000","1.84265","0.00203"
"22.17600","1.84815","0.00256"
"22.24200","1.85365","0.00195"
"22.30800","1.85922","0.00241"
"22.37400","1.86466","0.00231"
"22.44000","1.87022","0.00231"
"22.50600","1.87566","0.00218"
"22.57200","1.88122","0.00240"
"22.63800","1.88666","0.00225"
"22.70400","1.89216","0.00255"
"22.77000","1.89766","0.00206"
"22.83600","1.90322","0.00215"
"22.90200","1.90872","0.00227"
"22.96800","1.91422","0.00228"
"23.03400","1.91966","0.00232"
"23.10000","1.92516","0.00216"
"23.16600","1.93060","0.00299"
"23.23200","1.93610","0.00210"
"23.29800","1.94167","0.00212"
"23.36400","1.94723","0.00247"
"23.43000","1.95273","0.00228"
"23.49600","1.95817","0.00226"
"23.56200","1.96367","0.00213"
"23.62800","1.96917","0.00237"
"23.69400","1.97467","0.00213"
"23.76000","1.98017","0.00251"
"23.82600","1.98567","0.00245"
"23.89200","1.99117","0.00259"
"23.95800","1.99667","0.00235"
"24.02400","2.00223","0.00198"
"24.09000","2.00767","0.00212"
"24.15600","2.01323","0.00236"
"24.22200","2.01867","0.00271"
"24.28800","2.02417","0.00203"
"24.35400","2.02962","0.00260"
"24.42000","2.03524","0.00197"
"24.48600","2.04074","0.00219"
"24.55200","2.04624","0.00244"
"24.61800","2.05174","0.00208"
"24.68400","2.05718","0.00235"
"24.75000","2.06268","0.00226"
"24.81600","2.06812","0.00214"
"24.88200","2.07368","0.00236"
"24.94800","2.07918","0.00262"
"25.01400","2.08474","0.00199"
"25.08000","2.09018","0.00206"
"25.14600","2.09568","0.00233"
"25.21200","2.10118","0.00259"
"25.27800","2.10668","0.00220"
"25.34400","2.11213","0.00196"
"25.41000","2.11763","0.00227"
"25.47600","2.12319","0.00236"
"25.54200","2.12869","0.00186"
"25.60800","2.13419","0.00223"
"25.67400","2.13969","0.00213"
"25.74000","2.14525","0.00201"
"25.80600","2.15063","0.00226"
"25.87200","2.15613","0.00171"
"25.93800","2.16157","0.00204"
"26.00400","2.16719","0.00247"
"26.07000","2.17275","0.00251"
"26.13600","2.17825","0.00216"
"26.20200","2.18369","0.00198"
"26.26800","2.18925","0.00208"
"26.33400","2.19475","0.00220"
"26.40000","2.20014","0.00253"
"26.46600","2.20564","0.00197"
"26.53200","2.21114","0.00242"
"26.59800","2.21676","0.00194"
"26.66400","2.22226","0.00226"
"26.73000","2.22776","0.00221"
"26.79600","2.23326","0.00249"
"26.86200","2.23876","0.00243"
"26.92800","2.24420","0.00195"
"26.99400","2.24964","0.00177"
"27.06000","2.25514","0.00174"
"27.12600","2.26070","0.00232"
"27.19200","2.26620","0.00274"
"27.25800","2.27170","0.00221"
"27.32400","2.27714","0.00249"
"27.39000","2.28264","0.00206"
"27.45600","2.28815","0.00261"
"27.52200","2.29365","0.00215"
"27.58800","2.29915","0.00205"
"27.65400","2.30465","0.00224"
"27.72000","2.31021","0.00269"
"27.78600","2.31571","0.00180"
"27.85200","2.32121","0.00259"
"27.91800","2.32671","0.00201"
"27.98400","2.33215","0.00261"
"28.05000","2.33765","0.00215"
"28.11600","2.34315","0.00249"
"28.18200","2.34871","0.00224"
"28.24800","2.35421","0.00218"
"28.31400","2.35971","0.00228"
"28.38000","2.36521","0.00249"
"28.44600","2.37071","0.00276"
"28.51200","2.37616","0.00248"
"28.57800","2.38172","0.00286"
"28.64400","2.38722","0.00235"
"28.71000","2.39266","0.00257"
"28.77600","2.39822","0.00262"
"28.84200","2.40366","0.00236"
"28.90800","2.40922","0.00240"
"28.97400","2.41466","0.00245"
"29.04000","2.42022","0.00255"
"29.10600","2.42566","0.00282"
"29.17200","2.43116","0.00252"
"29.23800","2.43666","0.00256"
"29.30400","2.44222","0.00279"
"29.37000","2.44766","0.00230"
"29.43600","2.45322","0.00281"
"29.50200","2.45872","0.00268"
"29.56800","2.46417","0.00233"
"29.63400","2.46967","0.00237"
"29.70000","2.47511","0.00249"
"29.76600","2.48067","0.00259"
"29.83200","2.48617","0.00236"
"29.89800","2.49173","0.00241"
"29.96400","2.49717","0.00272"
"30.03000","2.50273","0.00257"
"30.09600","2.50817","0.00252"
"30.16200","2.51367","0.00268"
"30.22800","2.51911","0.00257"
"30.29400","2.52467","0.00196"
"30.36000","2.53017","0.00249"
"30.42600","2.53567","0.00258"
"30.49200","2.54123","0.00254"
"30.55800","2.54668","0.00218"
"30.62400","2.55224","0.00255"
"30.69000","2.55768","0.00264"
"30.75600","2.56318","0.00274"
"30.82200","2.56868","0.00252"
"30.88800","2.57424","0.00249"
"30.95400","2.57974","0.00250"
"31.02000","2.58524","0.00273"
"31.08600","2.59074","0.00301"
"31.15200","2.59624","0.00288"
"31.21800","2.60168","0.00247"
"31.28400","2.60718","0.00233"
"31.35000","2.61268","0.00240"
"31.41600","2.61818","0.00262"
"31.48200","2.62374","0.00299"
"31.54800","2.62919","0.00296"
"31.61400","2.63469","0.00302"
"31.68000","2.64013","0.00255"
"31.74600","2.64575","0.00269"
"31.81200","2.65119","0.00274"
"31.87800","2.65669","0.00294"
"31.94400","2.66213","0.00252"
"32.01000","2.66769","0.00263"
"32.07600","2.67319","0.00256"
"32.14200","2.67875","0.00264"
"32.20800","2.68419","0.00266"
"32.27400","2.68963","0.00280"
"32.34000","2.69513","0.00266"
"32.40600","2.70063","0.00281"
"32.47200","2.70613","0.00284"
"32.53800","2.71169","0.00249"
"32.60400","2.71720","0.00249"
"32.67000","2.72276","0.00245"
"32.73600","2.72820","0.00275"
"32.80200","2.73370","0.00210"
"32.86800","2.73914","0.00283"
"32.93400","2.74464","0.00210"
"33.00000","2.75020","0.00241"
"33.06600","2.75570","0.00213"
"33.13200","2.76120","0.00280"
"33.19800","2.76670","0.00229"
"33.26400","2.77220","0.00257"
"33.33000","2.77770","0.00285"
"33.39600","2.78314","0.00220"
"33.46200","2.78870","0.00255"
"33.52800","2.79414","0.00252"
"33.59400","2.79970","0.00246"
"33.66000","2.80521","0.00251"
"33.72600","2.81071","0.00273"
"33.79200","2.81621","0.00258"
"33.85800","2.82165","0.00285"
"33.92400","2.82715","0.00270"
"33.99000","2.83259","0.00292"
"34.05600","2.83821","0.00269"
"34.12200","2.84365","0.00339"
"34.18800","2.84921","0.00297"
"34.25400","2.85465","0.00280"
"34.32000","2.86021","0.00287"
"34.38600","2.86565","0.00274"
"34.45200","2.87115","0.00234"
"34.51800","2.87665","0.00262"
"34.58400","2.88215","0.00268"
"34.65000","2.88771","0.00288"
"34.71600","2.89322","0.00294"
"34.78200","2.89872","0.00268"
"34.84800","2.90422","0.00278"
"34.91400","2.90972","0.00294"
"34.98000","2.91522","0.00275"
"35.04600","2.92066","0.00243"
"35.11200","2.92616","0.00293"
"35.17800","2.93172","0.00243"
"35.24400","2.93722","0.00268"
"35.31000","2.94272","0.00322"
"35.37600","2.94822","0.00318"
"35.44200","2.95366","0.00299"
"35.50800","2.95922","0.00285"
"35.57400","2.96466","0.00317"
"35.64000","2.97022","0.00262"
"35.70600","2.97567","0.00264"
"35.77200","2.98129","0.00258"
"35.83800","2.98667","0.00298"
"35.90400","2.99223","0.00289"
"35.97000","2.99773","0.00279"
"36.03600","3.00317","0.00271"
"36.10200","3.00867","0.00308"
"36.16800","3.01417","0.00347"
"36.23400","3.01967","0.00307"
"36.30000","3.02517","0.00304"
"36.36600","3.03073","0.00270"
"36.43200","3.03623","0.00267"
"36.49800","3.04173","0.00273"
"36.56400","3.04717","0.00270"
"36.63000","3.05267","0.00263"
"36.69600","3.05812","0.00298"
"36.76200","3.06368","0.00294"
"36.82800","3.06924","0.00291"
"36.89400","3.07474","0.00311"
"36.96000","3.08024","0.00276"
"37.02600","3.08574","0.00276"
"37.09200","3.09124","0.00257"
"37.15800","3.09668","0.00292"
"37.22400","3.10218","0.00299"
"37.29000","3.10762","0.00270"
"37.35600","3.11324","0.00185"
"37.42200","3.11868","0.00142"
"37.48800","3.12424","0.00159"
"37.55400","3.12968","0.00181"
"37.62000","3.13524","0.00177"
"37.68600","3.14068","0.00170"
"37.75200","3.14618","0.00167"
"37.81800","3.15169","0.00216"
"37.88400","3.15713","0.00188"
"37.95000","3.16269","0.00195"
"38.01600","3.16819","0.00221"
"38.08200","3.17375","0.00150"
"38.14800","3.17919","0.00234"
"38.21400","3.18469","0.00161"
"38.28000","3.19013","0.00124"
"38.34600","3.19569","0.00161"
"38.41200","3.20119","0.00111"
"38.47800","3.20675","0.00156"
"38.54400","3.21219","0.00156"
"38.61000","3.21769","0.00162"
"38.67600","3.22319","0.00198"
"38.74200","3.22869","0.00201"
"38.80800","3.23419","0.00173"
"38.87400","3.23964","0.00227"
"38.94000","3.24520","0.00201"
"39.00600","3.25070","0.00239"
"39.07200","3.25620","0.00203"
"39.13800","3.26164","0.00168"
"39.20400","3.26720","0.00144"
"39.27000","3.27270","0.00179"
"39.33600","3.27820","0.00141"
"39.40200","3.28364","0.00171"
"39.46800","3.28914","0.00190"
"39.53400","3.29470","0.00176"
"39.60000","3.30020","0.00188"
"39.66600","3.30570","0.00220"
"39.73200","3.31120","0.00174"
"39.79800","3.31670","0.00167"
"39.86400","3.32215","0.00217"
"39.93000","3.32765","0.00200"
"39.99600","3.33315","0.00137"
"40.06200","3.33871","0.00245"
"40.12800","3.34421","0.00201"
"40.19400","3.34971","0.00204"
"40.26000","3.35515","0.00190"
"40.32600","3.36065","0.00219"
"40.39200","3.36615","0.00200"
"40.45800","3.37165","0.00205"
"40.52400","3.37715","0.00240"
"40.59000","3.38271","0.00225"
"40.65600","3.38821","0.00277"
"40.72200","3.39371","0.00185"
"40.78800","3.39921","0.00202"
"40.85400","3.40465","0.00178"
"40.92000","3.41016","0.00224"
"40.98600","3.41566","0.00229"
"41.05200","3.42116","0.00175"
"41.11800","3.42666","0.00229"
"41.18400","3.43222","0.00186"
"41.25000","3.43772","0.00187"
"41.31600","3.44322","0.00221"
"41.38200","3.44872","0.00233"
"41.44800","3.45410","0.00245"
"41.51400","3.45966","0.00213"
"41.58000","3.46516","0.00206"
"41.64600","3.47078","0.00233"
"41.71200","3.47622","0.00230"
"41.77800","3.48172","0.00191"
"41.84400","3.48722","0.00233"
"41.91000","3.49273","0.00221"
"41.97600","3.49817","0.00247"
"42.04200","3.50361","0.00232"
"42.10800","3.50917","0.00231"
"42.17400","3.51473","0.00193"
"42.24000","3.52029","0.00237"
"42.30600","3.52573","0.00249"
"42.37200","3.53123","0.00223"
"42.43800","3.53667","0.00280"
"42.50400","3.54217","0.00240"
"42.57000","3.54767","0.00232"
"42.63600","3.55317","0.00181"
"42.70200","3.55867","0.00193"
"42.76800","3.56423","0.00218"
"42.83400","3.56973","0.00245"
"42.90000","3.57523","0.00252"
"42.96600","3.58074","0.00214"
"43.03200","3.58618","0.00213"
"43.09800","3.59168","0.00214"
"43.16400","3.59712","0.00209"
"43.23000","3.60268","0.00232"
"43.29600","3.60824","0.00232"
"43.36200","3.61374","0.00208"
"43.42800","3.61924","0.00224"
"43.49400","3.62474","0.00259"
"43.56000","3.63018","0.00223"
"43.62600","3.63562","0.00206"
"43.69200","3.64112","0.00249"
"43.75800","3.64662","0.00260"
"43.82400","3.65224","0.00237"
"43.89000","3.65768","0.00203"
"43.95600","3.66325","0.00220"
"44.02200","3.66875","0.00223"
"44.08800","3.67419","0.00222"
"44.15400","3.67969","0.00241"
"44.22000","3.68519","0.00218"
"44.28600","3.69069","0.00200"
"44.35200","3.69619","0.00200"
"44.41800","3.70175","0.00226"
"44.48400","3.70725","0.00201"
"44.55000","3.71275","0.00251"
"44.61600","3.71819","0.00231"
"44.68200","3.72369","0.00226"
"44.74800","3.72913","0.00218"
"44.81400","3.73469","0.00211"
"44.88000","3.74013","0.00249"
"44.94600","3.74575","0.00222"
"45.01200","3.75120","0.00271"
"45.07800","3.75676","0.00241"
"45.14400","3.76214","0.00254"
"45.21000","3.76764","0.00238"
"45.27600","3.77314","0.00190"
"45.34200","3.77864","0.00256"
"45.40800","3.78420","0.00242"
"45.47400","3.78970","0.00257"
"45.54000","3.79526","0.00248"
"45.60600","3.80070","0.00240"
"45.67200","3.80620","0.00242"
"45.73800","3.81164","0.00263"
"45.80400","3.81720","0.00256"
"45.87000","3.82264","0.00280"
"45.93600","3.82820","0.00202"
"46.00200","3.83371","0.00262"
"46.06800","3.83921","0.00252"
"46.13400","3.84477","0.00259"
"46.20000","3.85021","0.00253"
"46.26600","3.85565","0.00250"
"46.33200","3.86115","0.00279"
"46.39800","3.86671","0.00252"
"46.46400","3.87221","0.00204"
"46.53000","3.87771","0.00292"
"46.59600","3.88315","0.00266"
"46.66200","3.88877","0.00234"
"46.72800","3.89421","0.00327"
"46.79400","3.89965","0.00230"
"46.86000","3.90515","0.00256"
"46.92600","3.91059","0.00292"
"46.99200","3.91621","0.00221"
"47.05800","3.92172","0.00294"
"47.12400","3.92728","0.00294"
"47.19000","3.93266","0.00337"
"47.25600","3.93822","0.00254"
"47.32200","3.94372","0.00268"
"47.38800","3.94922","0.00281"
"47.45400","3.95466","0.00236"
"47.52000","3.96016","0.00296"
"47.58600","3.96572","0.00275"
"47.65200","3.97122","0.00262"
"47.71800","3.97672","0.00270"
"47.78400","3.98222","0.00251"
"47.85000","3.98766","0.00292"
"47.91600","3.99322","0.00333"
"47.98200","3.99860","0.00240"
"48.04800","4.00416","0.00239"
"48.11400","4.00967","0.00298"
"48.18000","4.01523","0.00255"
"48.24600","4.02073","0.00297"
"48.31200","4.02629","0.00305"
"48.37800","4.03173","0.00309"
"48.44400","4.03723","0.00238"
"48.51000","4.04267","0.00294"
"48.57600","4.04817","0.00323"
"48.64200","4.05373","0.00260"
"48.70800","4.05929","0.00280"
"48.77400","4.06467","0.00267"
"48.84000","4.07023","0.00311"
"48.90600","4.07567","0.00300"
"48.97200","4.08117","0.00310"
"49.03800","4.08667","0.00270"
"49.10400","4.09218","0.00296"
"49.17000","4.09768","0.00323"
"49.23600","4.10318","0.00280"
"49.30200","4.10868","0.00254"
"49.36800","4.11418","0.00274"
"49.43400","4.11968","0.00272"
"49.50000","4.12512","0.00311"
"49.56600","4.13068","0.00302"
"49.63200","4.13612","0.00265"
"49.69800","4.14174","0.00275"
"49.76400","4.14718","0.00294"
"49.83000","4.15274","0.00248"
"49.89600","4.15824","0.00272"
"49.96200","4.16374","0.00242"
"50.02800","4.16918","0.00262"
"50.09400","4.17468","0.00262"
"50.16000","4.18013","0.00271"
"50.22600","4.18569","0.00306"
"50.29200","4.19125","0.00298"
"50.35800","4.19669","0.00331"
"50.42400","4.20219","0.00280"
"50.49000","4.20769","0.00309"
"50.55600","4.21319","0.00291"
"50.62200","4.21863","0.00333"
"50.68800","4.22413","0.00330"
"50.75400","4.22969","0.00326"
"50.82000","4.23525","0.00294"
"50.88600","4.24069","0.00328"
"50.95200","4.24619","0.00283"
"51.01800","4.25169","0.00249"
"51.08400","4.25713","0.00301"
"51.15000","4.26269","0.00302"
"51.21600","4.26808","0.00308"
"51.28200","4.27370","0.00312"
"51.34800","4.27920","0.00282"
"51.41400","4.28470","0.00333"
"51.48000","4.29020","0.00315"
"51.54600","4.29570","0.00299"
"51.61200","4.30120","0.00249"
"51.67800","4.30670","0.00309"
"51.74400","4.31220","0.00304"
"51.81000","4.31764","0.00326"
"51.87600","4.32320","0.00352"
"51.94200","4.32870","0.00353"
"52.00800","4.33420","0.00346"
"52.07400","4.33970","0.00319"
"52.14000","4.34520","0.00329"
"52.20600","4.35065","0.00325"
"52.27200","4.35615","0.00321"
"52.33800","4.36165","0.00319"
"52.40400","4.36727","0.00351"
"52.47000","4.37277","0.00352"
"52.53600","4.37821","0.00287"
"52.60200","4.38371","0.00367"
"52.66800","4.38921","0.00329"
"52.73400","4.39465","0.00295"
"52.80000","4.40015","0.00317"
"52.86600","4.40565","0.00365"
"52.93200","4.41115","0.00307"
"52.99800","4.41671","0.00313"
"53.06400","4.42221","0.00305"
"53.13000","4.42771","0.00329"
"53.19600","4.43321","0.00374"
"53.26200","4.43866","0.00394"
"53.32800","4.44416","0.00354"
"53.39400","4.44960","0.00363"
"53.46000","4.45516","0.00328"
"53.52600","4.46066","0.00335"
"53.59200","4.46622","0.00366"
"53.65800","4.47172","0.00322"
"53.72400","4.47728","0.00366"
"53.79000","4.48266","0.00373"
"53.85600","4.48816","0.00312"
"53.92200","4.49360","0.00318"
"53.98800","4.49922","0.00345"
"54.05400","4.50472","0.00342"
"54.12000","4.51028","0.00309"
"54.18600","4.51572","0.00344"
"54.25200","4.52122","0.00332"
"54.31800","4.52667","0.00327"
"54.38400","4.53217","0.00331"
"54.45000","4.53773","0.00334"
"54.51600","4.54317","0.00302"
"54.58200","4.54867","0.00357"
"54.64800","4.55417","0.00344"
"54.71400","4.55979","0.00326"
"54.78000","4.56523","0.00367"
"54.84600","4.57073","0.00355"
"54.91200","4.57617","0.00349"
"54.97800","4.58167","0.00365"
"55.04400","4.58717","0.00362"
"55.11000","4.59267","0.00308"
"55.17600","4.59817","0.00332"
"55.24200","4.60367","0.00330"
"55.30800","4.60918","0.00364"
"55.37400","4.61468","0.00334"
"55.44000","4.62012","0.00345"
"55.50600","4.62562","0.00371"
"55.57200","4.63112","0.00375"
"55.63800","4.63668","0.00380"
"55.70400","4.64218","0.00397"
"55.77000","4.64768","0.00418"
"55.83600","4.65318","0.00394"
"55.90200","4.65868","0.00401"
"55.96800","4.66418","0.00372"
"56.03400","4.66962","0.00317"
"56.10000","4.67518","0.00370"
"56.16600","4.68068","0.00355"
"56.23200","4.68624","0.00371"
"56.29800","4.69174","0.00407"
"56.36400","4.69719","0.00360"
"56.43000","4.70275","0.00380"
"56.49600","4.70819","0.00402"
"56.56200","4.71369","0.00378"
"56.62800","4.71919","0.00388"
"56.69400","4.72469","0.00397"
"56.76000","4.73019","0.00389"
"56.82600","4.73569","0.00369"
"56.89200","4.74125","0.00416"
"56.95800","4.74669","0.00416"
"57.02400","4.75219","0.00355"
"57.09000","4.75763","0.00401"
"57.15600","4.76319","0.00428"
"57.22200","4.76863","0.00409"
"57.28800","4.77425","0.00427"
"57.35400","4.77970","0.00383"
"57.42000","4.78520","0.00444"
"57.48600","4.79070","0.00395"
"57.55200","4.79620","0.00416"
"57.61800","4.80164","0.00381"
"57.68400","4.80714","0.00391"
"57.75000","4.81270","0.00410"
"57.81600","4.81820","0.00407"
"57.88200","4.82376","0.00450"
"57.94800","4.82920","0.00457"
"58.01400","4.83470","0.00452"
"58.08000","4.84014","0.00445"
"58.14600","4.84564","0.00440"
"58.21200","4.85114","0.00404"
"58.27800","4.85664","0.00416"
"58.34400","4.86214","0.00440"
"58.41000","4.86770","0.00424"
"58.47600","4.87321","0.00422"
"58.54200","4.87871","0.00426"
"58.60800","4.88421","0.00403"
"58.67400","4.88965","0.00468"
"58.74000","4.89515","0.00457"
"58.80600","4.90065","0.00456"
"58.87200","4.90621","0.00465"
"58.93800","4.91171","0.00403"
"59.00400","4.91727","0.00378"
"59.07000","4.92271","0.00442"
"59.13600","4.92821","0.00440"
"59.20200","4.93365","0.00450"
"59.26800","4.93915","0.00417"
"59.33400","4.94465","0.00432"
"59.40000","4.95021","0.00436"
"59.46600","4.95572","0.00433"
"59.53200","4.96122","0.00474"
"59.59800","4.96672","0.00430"
"59.66400","4.97222","0.00419"
"59.73000","4.97766","0.00453"
"59.79600","4.98316","0.00417"
"59.86200","4.98866","0.00466"
"59.92800","4.99422","0.00400"
"59.99400","4.99972","0.00448"
"60.06000","5.00522","0.00422"
"60.12600","5.01072","0.00448"
"60.19200","5.01622","0.00416"
"60.25800","5.02166","0.00441"
"60.32400","5.02716","0.00459"
"60.39000","5.03260","0.00458"
"60.45600","5.03823","0.00452"
"60.52200","5.04373","0.00488"
"60.58800","5.04923","0.00472"
"60.65400","5.05473","0.00433"
"60.72000","5.06023","0.00438"
"60.78600","5.06573","0.00474"
"60.85200","5.07117","0.00450"
"60.91800","5.07661","0.00453"
"60.98400","5.08217","0.00453"
"61.05000","5.08773","0.00397"
"61.11600","5.09323","0.00482"
"61.18200","5.09873","0.00462"
"61.24800","5.10423","0.00414"
"61.31400","5.10973","0.00416"
"61.38000","5.11517","0.00456"
"61.44600","5.12067","0.00478"
"61.51200","5.12612","0.00437"
"61.57800","5.13168","0.00434"
"61.64400","5.13718","0.00424"
"61.71000","5.14268","0.00449"
"61.77600","5.14818","0.00454"
"61.84200","5.15362","0.00480"
"61.90800","5.15912","0.00479"
"61.97400","5.16462","0.00447"
"62.04000","5.17018","0.00411"
"62.10600","5.17568","0.00442"
"62.17200","5.18124","0.00418"
"62.23800","5.18668","0.00489"
"62.30400","5.19224","0.00439"
"62.37000","5.19768","0.00437"
"62.43600","5.20318","0.00469"
"62.50200","5.20868","0.00432"
"62.56800","5.21413","0.00444"
"62.63400","5.21969","0.00471"
"62.70000","5.22519","0.00443"
"62.76600","5.23075","0.00493"
"62.83200","5.23625","0.00487"
"62.89800","5.24169","0.00462"
"62.96400","5.24719","0.00494"
"63.03000","5.25269","0.00480"
"63.09600","5.25813","0.00476"
"63.16200","5.26363","0.00512"
"63.22800","5.26919","0.00486"
"63.29400","5.27469","0.00492"
"63.36000","5.28025","0.00486"
"63.42600","5.28569","0.00484"
"63.49200","5.29119","0.00533"
"63.55800","5.29670","0.00519"
"63.62400","5.30220","0.00483"
"63.69000","5.30770","0.00481"
"63.75600","5.31326","0.00500"
"63.82200","5.31870","0.00525"
"63.88800","5.32426","0.00518"
"63.95400","5.32970","0.00491"
"64.02000","5.33520","0.00471"
"64.08600","5.34064","0.00464"
"64.15200","5.34614","0.00478"
"64.21800","5.35164","0.00480"
"64.28400","5.35720","0.00490"
"64.35000","5.36270","0.00472"
"64.41600","5.36820","0.00514"
"64.48200","5.37376","0.00523"
"64.54800","5.37920","0.00466"
"64.61400","5.38471","0.00522"
"64.68000","5.39015","0.00530"
"64.74600","5.39571","0.00493"
"64.81200","5.40121","0.00509"
"64.87800","5.40671","0.00499"
"64.94400","5.41221","0.00486"
"65.01000","5.41771","0.00460"
"65.07600","5.42321","0.00508"
"65.14200","5.42871","0.00506"
"65.20800","5.43421","0.00468"
"65.27400","5.43965","0.00500"
"65.34000","5.44521","0.00520"
"65.40600","5.45065","0.00522"
"65.47200","5.45621","0.00511"
"65.53800","5.46171","0.00491"
"65.60400","5.46721","0.00498"
"65.67000","5.47266","0.00513"
"65.73600","5.47816","0.00493"
"65.80200","5.48366","0.00538"
"65.86800","5.48922","0.00513"
"65.93400","5.49472","0.00538"
"66.00000","5.50016","0.00527"
"66.06600","5.50572","0.00525"
"66.13200","5.51116","0.00518"
"66.19800","5.51666","0.00510"
"66.26400","5.52210","0.00523"
"66.33000","5.52772","0.00481"
"66.39600","5.53316","0.00516"
"66.46200","5.53872","0.00558"
"66.52800","5.54416","0.00532"
"66.59400","5.54966","0.00542"
"66.66000","5.55516","0.00540"
"66.72600","5.56061","0.00562"
"66.79200","5.56617","0.00482"
"66.85800","5.57167","0.00540"
"66.92400","5.57717","0.00516"
"66.99000","5.58267","0.00496"
"67.05600","5.58823","0.00536"
"67.12200","5.59367","0.00538"
"67.18800","5.59923","0.00509"
"67.25400","5.60467","0.00520"
"67.32000","5.61017","0.00581"
"67.38600","5.61567","0.00500"
"67.45200","5.62117","0.00495"
"67.51800","5.62673","0.00535"
"67.58400","5.63217","0.00498"
"67.65000","5.63773","0.00475"
"67.71600","5.64318","0.00518"
"67.78200","5.64868","0.00502"
"67.84800","5.65412","0.00494"
"67.91400","5.65968","0.00496"
"67.98000","5.66518","0.00468"
"68.04600","5.67074","0.00450"
"68.11200","5.67618","0.00482"
"68.17800","5.68168","0.00477"
"68.24400","5.68718","0.00507"
"68.31000","5.69268","0.00524"
"68.37600","5.69812","0.00468"
"68.44200","5.70362","0.00478"
"68.50800","5.70918","0.00475"
"68.57400","5.71468","0.00474"
"68.64000","5.72018","0.00479"
"68.70600","5.72574","0.00480"
"68.77200","5.73125","0.00462"
"68.83800","5.73675","0.00458"
"68.90400","5.74219","0.00455"
"68.97000","5.74763","0.00520"
"69.03600","5.75319","0.00458"
"69.10200","5.75869","0.00506"
"69.16800","5.76419","0.00484"
"69.23400","5.76969","0.00506"
"69.30000","5.77519","0.00505"
"69.36600","5.78075","0.00450"
"69.43200","5.78619","0.00511"
"69.49800","5.79163","0.00502"
"69.56400","5.79713","0.00542"
"69.63000","5.80275","0.00491"
"69.69600","5.80825","0.00484"
"69.76200","5.81376","0.00512"
"69.82800","5.81920","0.00530"
"69.89400","5.82470","0.00478"
"69.96000","5.83014","0.00498"
"70.02600","5.83564","0.00535"
"70.09200","5.84114","0.00488"
"70.15800","5.84664","0.00512"
"70.22400","5.85226","0.00525"
"70.29000","5.85770","0.00533"
"70.35600","5.86326","0.00516"
"70.42200","5.86864","0.00536"
"70.48800","5.87420","0.00508"
"70.55400","5.87964","0.00538"
"70.62000","5.88514","0.00501"
"70.68600","5.89064","0.00529"
"70.75200","5.89614","0.00532"
"70.81800","5.90165","0.00497"
"70.88400","5.90721","0.00509"
"70.95000","5.91265","0.00519"
"71.01600","5.91815","0.00550"
"71.08200","5.92365","0.00511"
"71.14800","5.92915","0.00572"
"71.21400","5.93465","0.00534"
"71.28000","5.94021","0.00523"
"71.34600","5.94571","0.00559"
"71.41200","5.95127","0.00521"
"71.47800","5.95671","0.00512"
"71.54400","5.96215","0.00574"
"71.61000","5.96765","0.00483"
"71.67600","5.97315","0.00546"
"71.74200","5.97865","0.00566"
"71.80800","5.98422","0.00563"
"71.87400","5.98972","0.00530"
"71.94000","5.99528","0.00547"
"72.00600","6.00072","0.00581"
"72.07200","6.00622","0.00536"
"72.13800","6.01172","0.00537"
"72.20400","6.01716","0.00546"
"72.27000","6.02266","0.00561"
"72.33600","6.02816","0.00514"
"72.40200","6.03372","0.00539"
"72.46800","6.03922","0.00554"
"72.53400","6.04472","0.00520"
"72.60000","6.05016","0.00565"
"72.66600","6.05566","0.00539"
"72.73200","6.06110","0.00511"
"72.79800","6.06666","0.00542"
"72.86400","6.07217","0.00535"
"72.93000","6.07773","0.00555"
"72.99600","6.08323","0.00541"
"73.06200","6.08873","0.00568"
"73.12800","6.09417","0.00524"
"73.19400","6.09973","0.00514"
"73.26000","6.10517","0.00592"
"73.32600","6.11061","0.00521"
"73.39200","6.11623","0.00574"
"73.45800","6.12167","0.00549"
"73.52400","6.12723","0.00544"
"73.59000","6.13267","0.00591"
"73.65600","6.13823","0.00528"
"73.72200","6.14367","0.00570"
"73.78800","6.14917","0.00548"
"73.85400","6.15468","0.00549"
"73.92000","6.16017","0.00585"
"73.98600","6.16574","0.00570"
"74.05200","6.17118","0.00580"
"74.11800","6.17674","0.00568"
"74.18400","6.18218","0.00563"
"74.25000","6.18774","0.00605"
"74.31600","6.19318","0.00581"
"74.38200","6.19874","0.00598"
"74.44800","6.20418","0.00572"
"74.51400","6.20974","0.00568"
"74.58000","6.21518","0.00574"
"74.64600","6.22074","0.00597"
"74.71200","6.22618","0.00594"
"74.77800","6.23168","0.00600"
"74.84400","6.23718","0.00601"
"74.91000","6.24262","0.00592"
"74.97600","6.24813","0.00583"
"75.04200","6.25369","0.00566"
"75.10800","6.25925","0.00588"
"75.17400","6.26469","0.00588"
"75.24000","6.27019","0.00586"
"75.30600","6.27563","0.00600"
"75.37200","6.28119","0.00599"
"75.43800","6.28663","0.00576"
"75.50400","6.29225","0.00593"
"75.57000","6.29769","0.00607"
"75.63600","6.30319","0.00618"
"75.70200","6.30869","0.00618"
"75.76800","6.31419","0.00590"
"75.83400","6.31969","0.00620"
"75.90000","6.32514","0.00565"
"75.96600","6.33064","0.00604"
"76.03200","6.33620","0.00594"
"76.09800","6.34170","0.00620"
"76.16400","6.34720","0.00595"
"76.23000","6.35270","0.00547"
"76.29600","6.35826","0.00592"
"76.36200","6.36370","0.00609"
"76.42800","6.36914","0.00579"
"76.49400","6.37464","0.00593"
"76.56000","6.38014","0.00628"
"76.62600","6.38570","0.00648"
"76.69200","6.39120","0.00637"
"76.75800","6.39670","0.00591"
"76.82400","6.40220","0.00588"
"76.89000","6.40770","0.00659"
"76.95600","6.41315","0.00612"
"77.02200","6.41865","0.00573"
"77.08800","6.42421","0.00616"
"77.15400","6.42965","0.00616"
"77.22000","6.43521","0.00602"
"77.28600","6.44071","0.00590"
"77.35200","6.44621","0.00625"
"77.41800","6.45171","0.00604"
"77.48400","6.45715","0.00598"
"77.55000","6.46265","0.00600"
"77.61600","6.46809","0.00671"
"77.68200","6.47371","0.00579"
"77.74800","6.47921","0.00570"
"77.81400","6.48477","0.00595"
"77.88000","6.49021","0.00648"
"77.94600","6.49577","0.00671"
"78.01200","6.50116","0.00601"
"78.07800","6.50666","0.00622"
"78.14400","6.51210","0.00654"
"78.21000","6.51766","0.00640"
"78.27600","6.52322","0.00639"
"78.34200","6.52872","0.00652"
"78.40800","6.53422","0.00647"
"78.47400","6.53966","0.00668"
"78.54000","6.54522","0.00655"
"78.60600","6.55066","0.00644"
"78.67200","6.55622","0.00684"
"78.73800","6.56166","0.00592"
"78.80400","6.56722","0.00638"
"78.87000","6.57272","0.00668"
"78.93600","6.57822","0.00673"
"79.00200","6.58372","0.00640"
"79.06800","6.58917","0.00635"
"79.13400","6.59461","0.00676"
"79.20000","6.60011","0.00621"
"79.26600","6.60567","0.00627"
"79.33200","6.61117","0.00665"
"79.39800","6.61673","0.00639"
"79.46400","6.62223","0.00667"
"79.53000","6.62773","0.00621"
"79.59600","6.63317","0.00712"
"79.66200","6.63867","0.00629"
"79.72800","6.64411","0.00650"
"79.79400","6.64967","0.00643"
"79.86000","6.65523","0.00648"
"79.92600","6.66073","0.00702"
"79.99200","6.66623","0.00663"
"80.05800","6.67173","0.00672"
"80.12400","6.67718","0.00699"
"80.19000","6.68268","0.00673"
"80.25600","6.68818","0.00722"
"80.32200","6.69368","0.00737"
"80.38800","6.69918","0.00689"
"80.45400","6.70474","0.00713"
"80.52000","6.71024","0.00679"
"80.58600","6.71574","0.00682"
"80.65200","6.72118","0.00688"
"80.71800","6.72674","0.00726"
"80.78400","6.73218","0.00714"
"80.85000","6.73774","0.00682"
"80.91600","6.74312","0.00720"
"80.98200","6.74874","0.00717"
"81.04800","6.75418","0.00721"
"81.11400","6.75974","0.00712"
"81.18000","6.76519","0.00668"
"81.24600","6.77069","0.00695"
"81.31200","6.77613","0.00709"
"81.37800","6.78163","0.00728"
"81.44400","6.78713","0.00723"
"81.51000","6.79269","0.00704"
"81.57600","6.79819","0.00666"
"81.64200","6.80369","0.00657"
"81.70800","6.80919","0.00708"
"81.77400","6.81469","0.00706"
"81.84000","6.82019","0.00749"
"81.90600","6.82563","0.00714"
"81.97200","6.83125","0.00670"
"82.03800","6.83669","0.00693"
"82.10400","6.84225","0.00666"
"82.17000","6.84770","0.00686"
"82.23600","6.85320","0.00684"
"82.30200","6.85876","0.00736"
"82.36800","6.86420","0.00727"
"82.43400","6.86970","0.00734"
"82.50000","6.87520","0.00718"
"82.56600","6.88076","0.00736"
"82.63200","6.88620","0.00742"
"82.69800","6.89176","0.00732"
"82.76400","6.89720","0.00757"
"82.83000","6.90276","0.00746"
"82.89600","6.90820","0.00754"
"82.96200","6.91364","0.00741"
"83.02800","6.91914","0.00751"
"83.09400","6.92470","0.00743"
"83.16000","6.93026","0.00768"
"83.22600","6.93565","0.00751"
"83.29200","6.94115","0.00753"
"83.35800","6.94659","0.00728"
"83.42400","6.95215","0.00729"
"83.49000","6.95765","0.00734"
"83.55600","6.96315","0.00789"
"83.62200","6.96865","0.00733"
"83.68800","6.97421","0.00715"
"83.75400","6.97971","0.00740"
"83.82000","6.98521","0.00804"
"83.88600","6.99065","0.00801"
"83.95200","6.99615","0.00783"
"84.01800","7.00165","0.00713"
"84.08400","7.00715","0.00790"
"84.15000","7.01265","0.00741"
"84.21600","7.01822","0.00795"
"84.28200","7.02366","0.00779"
"84.34800","7.02922","0.00774"
"84.41400","7.03466","0.00773"
"84.48000","7.04016","0.00799"
"84.54600","7.04560","0.00765"
"84.61200","7.05116","0.00796"
"84.67800","7.05672","0.00831"
"84.74400","7.06222","0.00805"
"84.81000","7.06772","0.00786"
"84.87600","7.07322","0.00773"
"84.94200","7.07866","0.00780"
"85.00800","7.08422","0.00797"
"85.07400","7.08960","0.00774"
"85.14000","7.09516","0.00821"
"85.20600","7.10072","0.00790"
"85.27200","7.10629","0.00773"
"85.33800","7.11167","0.00776"
"85.40400","7.11723","0.00816"
"85.47000","7.12267","0.00812"
"85.53600","7.12817","0.00807"
"85.60200","7.13367","0.00757"
"85.66800","7.13911","0.00779"
"85.73400","7.14467","0.00805"
"85.80000","7.15017","0.00798"
"85.86600","7.15573","0.00825"
"85.93200","7.16117","0.00761"
"85.99800","7.16673","0.00808"
"86.06400","7.17217","0.00815"
"86.13000","7.17767","0.00836"
"86.19600","7.18311","0.00816"
"86.26200","7.18867","0.00805"
"86.32800","7.19424","0.00843"
"86.39400","7.19974","0.00803"
"86.46000","7.20524","0.00831"
"86.52600","7.21068","0.00837"
"86.59200","7.21618","0.00775"
"86.65800","7.22168","0.00815"
"86.72400","7.22718","0.00817"
"86.79000","7.23262","0.00814"
"86.85600","7.23824","0.00755"
"86.92200","7.24374","0.00835"
"86.98800","7.24924","0.00843"
"87.05400","7.25474","0.00810"
"87.12000","7.26018","0.00831"
"87.18600","7.26568","0.00842"
"87.25200","7.27118","0.00838"
"87.31800","7.27668","0.00824"
"87.38400","7.28219","0.00852"
"87.45000","7.28769","0.00841"
"87.51600","7.29319","0.00822"
"87.58200","7.29869","0.00811"
"87.64800","7.30419","0.00791"
"87.71400","7.30969","0.00871"
"87.78000","7.31513","0.00840"
"87.84600","7.32069","0.00821"
"87.91200","7.32619","0.00826"
"87.97800","7.33169","0.00828"
"88.04400","7.33719","0.00831"
"88.11000","7.34275","0.00845"
"88.17600","7.34825","0.00817"
"88.24200","7.35369","0.00808"
"88.30800","7.35919","0.00846"
"88.37400","7.36470","0.00818"
"88.44000","7.37020","0.00801"
"88.50600","7.37570","0.00820"
"88.57200","7.38126","0.00842"
"88.63800","7.38670","0.00826"
"88.70400","7.39220","0.00851"
"88.77000","7.39764","0.00879"
"88.83600","7.40314","0.00873"
"88.90200","7.40864","0.00860"
"88.96800","7.41414","0.00858"
"89.03400","7.41970","0.00867"
"89.10000","7.42520","0.00864"
"89.16600","7.43076","0.00837"
"89.23200","7.43620","0.00879"
"89.29800","7.44170","0.00877"
"89.36400","7.44714","0.00928"
"89.43000","7.45265","0.00908"
"89.49600","7.45821","0.00889"
"89.56200","7.46371","0.00900"
"89.62800","7.46915","0.00932"
"89.69400","7.47465","0.00905"
"89.76000","7.48015","0.00848"
"89.82600","7.48565","0.00912"
"89.89200","7.49115","0.00911"
"89.95800","7.49659","0.00879"
"90.02400","7.50221","0.00865"
"90.09000","7.50771","0.00954"
"90.15600","7.51327","0.00869"
"90.22200","7.51871","0.00915"
"90.28800","7.52427","0.00906"
"90.35400","7.52972","0.00899"
"90.42000","7.53521","0.00924"
"90.48600","7.54066","0.00876"
"90.55200","7.54616","0.00883"
"90.61800","7.55166","0.00925"
"90.68400","7.55722","0.00906"
"90.75000","7.56272","0.00897"
"90.81600","7.56816","0.00886"
"90.88200","7.57372","0.00862"
"90.94800","7.57916","0.00927"
"91.01400","7.58466","0.00929"
"91.08000","7.59010","0.00922"
"91.14600","7.59566","0.00909"
"91.21200","7.60122","0.00903"
"91.27800","7.60666","0.00936"
"91.34400","7.61222","0.00891"
"91.41000","7.61772","0.00906"
"91.47600","7.62317","0.00923"
"91.54200","7.62867","0.00910"
"91.60800","7.63417","0.00904"
"91.67400","7.63967","0.00942"
"91.74000","7.64523","0.00898"
"91.80600","7.65073","0.00953"
"91.87200","7.65617","0.00953"
"91.93800","7.66173","0.00961"
"92.00400","7.66717","0.00936"
"92.07000","7.67267","0.00944"
"92.13600","7.67817","0.00910"
"92.20200","7.68367","0.00931"
"92.26800","7.68917","0.00963"
"92.33400","7.69467","0.00979"
"92.40000","7.70018","0.00943"
"92.46600","7.70568","0.00961"
"92.53200","7.71112","0.00983"
"92.59800","7.71668","0.00979"
"92.66400","7.72212","0.00945"
"92.73000","7.72774","0.00959"
"92.79600","7.73318","0.00960"
"92.86200","7.73874","0.00953"
"92.92800","7.74418","0.00970"
"92.99400","7.74974","0.00961"
"93.06000","7.75518","0.00942"
"93.12600","7.76068","0.00956"
"93.19200","7.76618","0.00939"
"93.25800","7.77168","0.00943"
"93.32400","7.77718","0.00942"
"93.39000","7.78268","0.00976"
"93.45600","7.78824","0.00959"
"93.52200","7.79369","0.00999"
"93.58800","7.79925","0.00972"
"93.65400","7.80469","0.00983"
"93.72000","7.81013","0.01008"
"93.78600","7.81569","0.00959"
"93.85200","7.82119","0.00984"
"93.91800","7.82675","0.00998"
"93.98400","7.83219","0.01012"
"94.05000","7.83769","0.00982"
"94.11600","7.84313","0.01030"
"94.18200","7.84869","0.00985"
"94.24800","7.85413","0.00979"
"94.31400","7.85969","0.01076"
"94.38000","7.86519","0.01026"
"94.44600","7.87075","-0.00071"
"94.51200","7.87619","0.00011"
"94.57800","7.88175","-0.00041"
"94.64400","7.88720","-0.00065"
"94.71000","7.89264","-0.00070"
"94.77600","7.89814","-0.00080"
"94.84200","7.90364","0.00081"
"94.90800","7.90920","0.00043"
"94.97400","7.91470","0.00087"
"95.04000","7.92026","0.00027"
"95.10600","7.92570","-0.00009"
"95.17200","7.93120","0.00003"
"95.23800","7.93664","-0.00061"
"95.30400","7.94214","-0.00046"
"95.37000","7.94764","-0.00012"
"95.43600","7.95320","0.00058"
"95.50200","7.95876","0.00079"
"95.56800","7.96420","0.00045"
"95.63400","7.96971","0.00002"
"95.70000","7.97521","-0.00023"
"95.76600","7.98071","-0.00049"
"95.83200","7.98615","-0.00046"
"95.89800","7.99165","0.00013"
"95.96400","7.99715","0.00065"
"96.03000","8.00271","0.00122"
"96.09600","8.00821","0.00084"
"96.16200","8.01371","0.00055"
"96.22800","8.01921","0.00015"
"96.29400","8.02465","-0.00018"
"96.36000","8.03015","-0.00028"
"96.42600","8.03559","-0.00035"
"96.49200","8.04115","0.00040"
"96.55800","8.04665","0.00037"
"96.62400","8.05221","0.00020"
"96.69000","8.05772","0.00014"
"96.75600","8.06328","0.00006"
"96.82200","8.06866","-0.00034"
"96.88800","8.07416","-0.00016"
"96.95400","8.07966","0.00005"
"97.02000","8.08516","0.00031"
"97.08600","8.09066","0.00043"
"97.15200","8.09622","0.00053"
"97.21800","8.10166","0.00057"
"97.28400","8.10722","0.00006"
"97.35000","8.11266","-0.00012"
"97.41600","8.11816","0.00005"
"97.48200","8.12366","0.00066"
"97.54800","8.12916","0.00094"
"97.61400","8.13466","0.00071"
"97.68000","8.14017","0.00112"
"97.74600","8.14573","0.00062"
"97.81200","8.15123","0.00019"
"97.87800","8.15667","-0.00003"
"97.94400","8.16217","-0.00019"
"98.01000","8.16767","0.00034"
"98.07600","8.17317","0.00053"
"98.14200","8.17867","0.00042"
"98.20800","8.18423","0.00052"
"98.27400","8.18967","0.00016"
"98.34000","8.19523","0.00014"
"98.40600","8.20067","-0.00028"
"98.47200","8.20617","0.00012"
"98.53800","8.21161","0.00045"
"98.60400","8.21717","0.00036"
"98.67000","8.22268","0.00041"
"98.71600","8.22650","0.00063"