File: Force_trajectories/161223_2/Specimen_RawData_4.csv
End date,"12/23/2016"
Specimen label,"21AT_UNK"
Maximum Load,"0.00834",N

Time,Extension,Load
(s),(mm),(N)
"0.00000","0.00000","0.00005"
"0.04800","0.00090","0.00006"
"0.09600","0.00395","-0.00010"
"0.14400","0.00843","0.00017"
"0.19200","0.01363","-0.00029"
"0.24000","0.01865","-0.00019"
"0.28800","0.02344","-0.00010"
"0.33600","0.02780","-0.00003"
"0.38400","0.03205","-0.00004"
"0.43200","0.03623","-0.00047"
"0.48000","0.04018","-0.00016"
"0.52800","0.04418","-0.00020"
"0.57600","0.04819","-0.00018"
"0.62400","0.05214","-0.00044"
"0.67200","0.05614","-0.00022"
"0.72000","0.06015","-0.00023"
"0.76800","0.06415","-0.00018"
"0.81600","0.06810","-0.00009"
"0.86400","0.07217","0.00006"
"0.91200","0.07611","-0.00044"
"0.96000","0.08012","-0.00004"
"1.00800","0.08418","-0.00045"
"1.05600","0.08813","-0.00010"
"1.10400","0.09214","-0.00016"
"1.15200","0.09614","0.00021"
"1.20000","0.10015","-0.00044"
"1.24800","0.10415","-0.00016"
"1.29600","0.10816","-0.00024"
"1.34400","0.11211","-0.00002"
"1.39200","0.11611","-0.00001"
"1.44000","0.12012","-0.00018"
"1.48800","0.12412","-0.00017"
"1.53600","0.12813","-0.00053"
"1.58400","0.13213","0.00014"
"1.63200","0.13614","-0.00018"
"1.68000","0.14009","-0.00005"
"1.72800","0.14415","-0.00035"
"1.77600","0.14810","0.00009"
"1.82400","0.15210","0.00000"
"1.87200","0.15611","-0.00055"
"1.92000","0.16006","-0.00013"
"1.96800","0.16406","0.00007"
"2.01600","0.16807","-0.00064"
"2.06400","0.17213","0.00018"
"2.11200","0.17608","-0.00010"
"2.16000","0.18015","-0.00007"
"2.20800","0.18409","-0.00015"
"2.25600","0.18810","-0.00021"
"2.30400","0.19216","-0.00055"
"2.35200","0.19617","0.00017"
"2.40000","0.20012","0.00011"
"2.44800","0.20412","0.00011"
"2.49600","0.20813","-0.00060"
"2.54400","0.21207","-0.00013"
"2.59200","0.21614","0.00015"
"2.64000","0.22015","-0.00015"
"2.68800","0.22415","-0.00005"
"2.73600","0.22816","-0.00027"
"2.78400","0.23216","-0.00034"
"2.83200","0.23617","-0.00025"
"2.88000","0.24017","-0.00014"
"2.92800","0.24412","0.00013"
"2.97600","0.24813","-0.00016"
"3.02400","0.25207","-0.00005"
"3.07200","0.25608","-0.00022"
"3.12000","0.26008","-0.00017"
"3.16800","0.26415","-0.00030"
"3.21600","0.26816","-0.00067"
"3.26400","0.27210","-0.00040"
"3.31200","0.27611","-0.00001"
"3.36000","0.28011","0.00006"
"3.40800","0.28412","-0.00014"
"3.45600","0.28813","-0.00024"
"3.50400","0.29213","-0.00026"
"3.55200","0.29608","-0.00053"
"3.60000","0.30008","0.00003"
"3.64800","0.30409","0.00023"
"3.69600","0.30810","-0.00014"
"3.74400","0.31216","-0.00070"
"3.79200","0.31617","-0.00040"
"3.84000","0.32011","-0.00020"
"3.88800","0.32418","-0.00010"
"3.93600","0.32812","0.00009"
"3.98400","0.33207","-0.00007"
"4.03200","0.33614","-0.00050"
"4.08000","0.34002","0.00019"
"4.12800","0.34403","-0.00016"
"4.17600","0.34815","-0.00038"
"4.22400","0.35210","-0.00010"
"4.27200","0.35611","-0.00004"
"4.32000","0.36017","-0.00025"
"4.36800","0.36412","-0.00032"
"4.41600","0.36812","0.00001"
"4.46400","0.37219","0.00036"
"4.51200","0.37614","-0.00036"
"4.56000","0.38008","0.00009"
"4.60800","0.38415","-0.00009"
"4.65600","0.38809","0.00000"
"4.70400","0.39204","-0.00027"
"4.75200","0.39617","0.00003"
"4.80000","0.40017","0.00003"
"4.84800","0.40418","-0.00016"
"4.89600","0.40818","0.00017"
"4.94400","0.41213","-0.00006"
"4.99200","0.41614","-0.00005"
"5.04000","0.42020","0.00004"
"5.08800","0.42415","0.00015"
"5.13600","0.42809","-0.00029"
"5.18400","0.43210","0.00007"
"5.23200","0.43605","0.00013"
"5.28000","0.44011","0.00017"
"5.32800","0.44418","-0.00057"
"5.37600","0.44818","-0.00027"
"5.42400","0.45219","0.00003"
"5.47200","0.45619","-0.00010"
"5.52000","0.46014","0.00011"
"5.56800","0.46409","0.00041"
"5.61600","0.46815","-0.00016"
"5.66400","0.47210","0.00021"
"5.71200","0.47610","0.00021"
"5.76000","0.48011","0.00024"
"5.80800","0.48406","-0.00015"
"5.85600","0.48806","0.00001"
"5.90400","0.49219","-0.00032"
"5.95200","0.49613","-0.00026"
"6.00000","0.50014","0.00001"
"6.04800","0.50421","0.00043"
"6.09600","0.50815","-0.00033"
"6.14400","0.51210","-0.00013"
"6.19200","0.51610","-0.00023"
"6.24000","0.52005","0.00001"
"6.28800","0.52406","0.00005"
"6.33600","0.52812","-0.00007"
"6.38400","0.53213","-0.00016"
"6.43200","0.53613","-0.00003"
"6.48000","0.54014","-0.00015"
"6.52800","0.54414","-0.00022"
"6.57600","0.54821","0.00031"
"6.62400","0.55216","0.00030"
"6.67200","0.55616","0.00028"
"6.72000","0.56011","0.00029"
"6.76800","0.56405","0.00014"
"6.81600","0.56806","0.00019"
"6.86400","0.57207","-0.00012"
"6.91200","0.57607","-0.00018"
"6.96000","0.58014","-0.00039"
"7.00800","0.58414","-0.00009"
"7.05600","0.58815","-0.00027"
"7.10400","0.59216","-0.00045"
"7.15200","0.59616","-0.00023"
"7.20000","0.60011","0.00045"
"7.24800","0.60411","-0.00027"
"7.29600","0.60812","-0.00012"
"7.34400","0.61207","-0.00018"
"7.39200","0.61607","-0.00029"
"7.44000","0.62008","-0.00005"
"7.48800","0.62414","-0.00032"
"7.53600","0.62815","0.00002"
"7.58400","0.63215","0.00024"
"7.63200","0.63622","-0.00004"
"7.68000","0.64017","-0.00010"
"7.72800","0.64411","-0.00009"
"7.77600","0.64818","-0.00029"
"7.82400","0.65206","-0.00006"
"7.87200","0.65607","-0.00011"
"7.92000","0.66014","-0.00033"
"7.96800","0.66408","-0.00002"
"8.01600","0.66809","0.00000"
"8.06400","0.67215","0.00027"
"8.11200","0.67610","-0.00032"
"8.16000","0.68011","-0.00027"
"8.20800","0.68417","-0.00045"
"8.25600","0.68812","0.00002"
"8.30400","0.69212","0.00020"
"8.35200","0.69613","0.00020"
"8.40000","0.70008","-0.00002"
"8.44800","0.70402","-0.00003"
"8.49600","0.70809","0.00001"
"8.54400","0.71209","0.00004"
"8.59200","0.71616","0.00042"
"8.64000","0.72022","0.00009"
"8.68800","0.72411","0.00004"
"8.73600","0.72812","0.00000"
"8.78400","0.73218","-0.00017"
"8.83200","0.73607","-0.00001"
"8.88000","0.74007","0.00021"
"8.92800","0.74414","0.00012"
"8.97600","0.74803","0.00005"
"9.02400","0.75203","-0.00012"
"9.07200","0.75610","-0.00022"
"9.12000","0.76010","-0.00017"
"9.16800","0.76417","-0.00015"
"9.21600","0.76818","-0.00017"
"9.26400","0.77212","-0.00033"
"9.31200","0.77613","0.00020"
"9.36000","0.78013","-0.00027"
"9.40800","0.78408","-0.00015"
"9.45600","0.78809","0.00008"
"9.50400","0.79215","-0.00009"
"9.55200","0.79610","-0.00018"
"9.60000","0.80010","0.00046"
"9.64800","0.80417","0.00009"
"9.69600","0.80812","-0.00045"
"9.74400","0.81212","-0.00033"
"9.79200","0.81619","0.00006"
"9.84000","0.82019","-0.00019"
"9.88800","0.82414","0.00010"
"9.93600","0.82814","0.00004"
"9.98400","0.83209","0.00036"
"10.03200","0.83610","0.00000"
"10.08000","0.84016","-0.00042"
"10.12800","0.84411","-0.00040"
"10.17600","0.84817","0.00006"
"10.22400","0.85218","-0.00027"
"10.27200","0.85613","0.00019"
"10.32000","0.86013","0.00002"
"10.36800","0.86414","-0.00013"
"10.41600","0.86814","-0.00025"
"10.46400","0.87209","0.00037"
"10.51200","0.87610","-0.00001"
"10.56000","0.88010","0.00013"
"10.60800","0.88411","-0.00023"
"10.65600","0.88811","-0.00003"
"10.70400","0.89218","-0.00010"
"10.75200","0.89619","0.00000"
"10.80000","0.90019","-0.00041"
"10.84800","0.90414","-0.00001"
"10.89600","0.90814","-0.00004"
"10.94400","0.91215","-0.00057"
"10.99200","0.91610","-0.00005"
"11.04000","0.92016","-0.00009"
"11.08800","0.92417","-0.00002"
"11.13600","0.92811","0.00011"
"11.18400","0.93212","-0.00033"
"11.23200","0.93612","-0.00001"
"11.28000","0.94013","0.00017"
"11.32800","0.94420","0.00017"
"11.37600","0.94814","0.00055"
"11.42400","0.95215","0.00008"
"11.47200","0.95615","0.00006"
"11.52000","0.96016","0.00032"
"11.56800","0.96411","0.00021"
"11.61600","0.96811","-0.00006"
"11.66400","0.97206","0.00013"
"11.71200","0.97606","0.00047"
"11.76000","0.98013","0.00020"
"11.80800","0.98414","0.00042"
"11.85600","0.98814","0.00014"
"11.90400","0.99215","-0.00006"
"11.95200","0.99615","0.00014"
"12.00000","1.00016","0.00031"
"12.04800","1.00417","-0.00018"
"12.09600","1.00811","0.00011"
"12.14400","1.01212","-0.00007"
"12.19200","1.01606","0.00010"
"12.24000","1.02013","-0.00008"
"12.28800","1.02413","0.00032"
"12.33600","1.02814","0.00021"
"12.38400","1.03215","0.00035"
"12.43200","1.03615","-0.00014"
"12.48000","1.04016","0.00063"
"12.52800","1.04410","0.00024"
"12.57600","1.04811","0.00011"
"12.62400","1.05212","0.00015"
"12.67200","1.05606","0.00002"
"12.72000","1.06007","0.00003"
"12.76800","1.06407","0.00011"
"12.81600","1.06814","0.00044"
"12.86400","1.07215","0.00027"
"12.91200","1.07615","0.00035"
"12.96000","1.08016","0.00016"
"13.00800","1.08410","0.00032"
"13.05600","1.08817","-0.00002"
"13.10400","1.09218","0.00013"
"13.15200","1.09612","-0.00003"
"13.20000","1.10013","0.00002"
"13.24800","1.10407","0.00002"
"13.29600","1.10802","0.00010"
"13.34400","1.11215","0.00019"
"13.39200","1.11615","0.00003"
"13.44000","1.12016","0.00020"
"13.48800","1.12416","0.00022"
"13.53600","1.12817","-0.00020"
"13.58400","1.13211","0.00044"
"13.63200","1.13618","0.00014"
"13.68000","1.14019","0.00018"
"13.72800","1.14407","0.00008"
"13.77600","1.14808","0.00025"
"13.82400","1.15202","0.00047"
"13.87200","1.15603","-0.00001"
"13.92000","1.16016","-0.00025"
"13.96800","1.16416","0.00020"
"14.01600","1.16817","0.00046"
"14.06400","1.17217","0.00008"
"14.11200","1.17618","-0.00016"
"14.16000","1.18019","-0.00011"
"14.20800","1.18413","-0.00015"
"14.25600","1.18814","0.00001"
"14.30400","1.19214","0.00017"
"14.35200","1.19609","-0.00018"
"14.40000","1.20010","-0.00001"
"14.44800","1.20410","0.00050"
"14.49600","1.20811","0.00043"
"14.54400","1.21217","-0.00029"
"14.59200","1.21618","0.00012"
"14.64000","1.22012","0.00025"
"14.68800","1.22413","-0.00019"
"14.73600","1.22814","0.00068"
"14.78400","1.23208","-0.00013"
"14.83200","1.23609","0.00030"
"14.88000","1.24003","-0.00029"
"14.92800","1.24410","0.00015"
"14.97600","1.24811","-0.00008"
"15.02400","1.25211","0.00005"
"15.07200","1.25618","0.00004"
"15.12000","1.26012","-0.00006"
"15.16800","1.26419","-0.00011"
"15.21600","1.26820","0.00002"
"15.26400","1.27214","0.00026"
"15.31200","1.27609","0.00000"
"15.36000","1.28009","0.00018"
"15.40800","1.28404","0.00028"
"15.45600","1.28805","0.00029"
"15.50400","1.29211","0.00044"
"15.55200","1.29612","-0.00006"
"15.60000","1.30012","0.00001"
"15.64800","1.30419","0.00024"
"15.69600","1.30814","-0.00030"
"15.74400","1.31214","0.00001"
"15.79200","1.31615","0.00023"
"15.84000","1.32015","0.00000"
"15.88800","1.32410","0.00042"
"15.93600","1.32810","0.00025"
"15.98400","1.33211","0.00033"
"16.03200","1.33606","0.00028"
"16.08000","1.34012","0.00016"
"16.12800","1.34413","0.00030"
"16.17600","1.34807","0.00040"
"16.22400","1.35214","0.00058"
"16.27200","1.35621","0.00033"
"16.32000","1.36015","0.00024"
"16.36800","1.36416","0.00043"
"16.41600","1.36816","0.00046"
"16.46400","1.37211","0.00058"
"16.51200","1.37612","0.00030"
"16.56000","1.38012","0.00017"
"16.60800","1.38407","0.00033"
"16.65600","1.38813","0.00038"
"16.70400","1.39214","0.00051"
"16.75200","1.39609","0.00051"
"16.80000","1.40015","0.00013"
"16.84800","1.40416","0.00007"
"16.89600","1.40810","0.00023"
"16.94400","1.41211","0.00019"
"16.99200","1.41606","0.00047"
"17.04000","1.42006","0.00049"
"17.08800","1.42413","0.00009"
"17.13600","1.42807","0.00017"
"17.18400","1.43214","0.00037"
"17.23200","1.43614","0.00051"
"17.28000","1.44009","0.00013"
"17.32800","1.44410","0.00013"
"17.37600","1.44816","0.00034"
"17.42400","1.45211","0.00013"
"17.47200","1.45611","0.00047"
"17.52000","1.46012","0.00045"
"17.56800","1.46407","0.00037"
"17.61600","1.46801","0.00074"
"17.66400","1.47214","0.00022"
"17.71200","1.47614","0.00046"
"17.76000","1.48015","0.00057"
"17.80800","1.48416","0.00009"
"17.85600","1.48816","0.00019"
"17.90400","1.49211","0.00044"
"17.95200","1.49617","0.00015"
"18.00000","1.50012","0.00031"
"18.04800","1.50413","0.00003"
"18.09600","1.50813","0.00037"
"18.14400","1.51214","0.00026"
"18.19200","1.51614","0.00020"
"18.24000","1.52015","0.00038"
"18.28800","1.52415","0.00038"
"18.33600","1.52816","0.00062"
"18.38400","1.53217","0.00021"
"18.43200","1.53617","0.00048"
"18.48000","1.54012","0.00046"
"18.52800","1.54412","0.00018"
"18.57600","1.54813","0.00040"
"18.62400","1.55214","0.00029"
"18.67200","1.55614","0.00034"
"18.72000","1.56015","0.00038"
"18.76800","1.56409","0.00043"
"18.81600","1.56816","0.00033"
"18.86400","1.57217","0.00067"
"18.91200","1.57611","0.00047"
"18.96000","1.58018","0.00031"
"19.00800","1.58412","-0.00004"
"19.05600","1.58807","0.00071"
"19.10400","1.59214","0.00020"
"19.15200","1.59608","-0.00014"
"19.20000","1.60003","0.00031"
"19.24800","1.60415","0.00051"
"19.29600","1.60810","0.00063"
"19.34400","1.61216","-0.00003"
"19.39200","1.61623","0.00013"
"19.44000","1.62018","0.00056"
"19.48800","1.62418","0.00030"
"19.53600","1.62813","0.00028"
"19.58400","1.63207","0.00067"
"19.63200","1.63608","0.00012"
"19.68000","1.64009","0.00025"
"19.72800","1.64409","0.00038"
"19.77600","1.64810","0.00070"
"19.82400","1.65210","0.00026"
"19.87200","1.65611","0.00035"
"19.92000","1.66012","0.00066"
"19.96800","1.66412","0.00050"
"20.01600","1.66819","0.00053"
"20.06400","1.67219","0.00045"
"20.11200","1.67614","0.00098"
"20.16000","1.68015","0.00051"
"20.20800","1.68409","0.00068"
"20.25600","1.68810","0.00039"
"20.30400","1.69210","0.00046"
"20.35200","1.69611","0.00049"
"20.40000","1.70018","0.00063"
"20.44800","1.70412","0.00075"
"20.49600","1.70813","0.00070"
"20.54400","1.71213","0.00069"
"20.59200","1.71614","0.00044"
"20.64000","1.72014","0.00052"
"20.68800","1.72415","0.00049"
"20.73600","1.72810","0.00012"
"20.78400","1.73204","0.00050"
"20.83200","1.73611","0.00084"
"20.88000","1.74005","0.00092"
"20.92800","1.74412","0.00038"
"20.97600","1.74819","0.00112"
"21.02400","1.75213","0.00098"
"21.07200","1.75608","0.00063"
"21.12000","1.76014","0.00047"
"21.16800","1.76415","0.00060"
"21.21600","1.76810","0.00058"
"21.26400","1.77210","0.00038"
"21.31200","1.77605","0.00043"
"21.36000","1.78005","0.00031"
"21.40800","1.78412","0.00054"
"21.45600","1.78813","0.00062"
"21.50400","1.79213","0.00079"
"21.55200","1.79620","0.00072"
"21.60000","1.80014","0.00081"
"21.64800","1.80415","0.00092"
"21.69600","1.80816","0.00057"
"21.74400","1.81210","0.00080"
"21.79200","1.81605","0.00050"
"21.84000","1.82005","0.00098"
"21.88800","1.82406","0.00072"
"21.93600","1.82807","0.00047"
"21.98400","1.83213","0.00077"
"22.03200","1.83614","0.00098"
"22.08000","1.84014","0.00064"
"22.12800","1.84409","0.00074"
"22.17600","1.84815","0.00101"
"22.22400","1.85210","0.00113"
"22.27200","1.85611","0.00065"
"22.32000","1.86011","0.00076"
"22.36800","1.86412","0.00083"
"22.41600","1.86806","0.00083"
"22.46400","1.87207","0.00096"
"22.51200","1.87608","0.00070"
"22.56000","1.88014","0.00043"
"22.60800","1.88415","0.00055"
"22.65600","1.88815","0.00089"
"22.70400","1.89222","0.00088"
"22.75200","1.89617","0.00073"
"22.80000","1.90011","0.00085"
"22.84800","1.90412","0.00083"
"22.89600","1.90812","0.00089"
"22.94400","1.91207","0.00058"
"22.99200","1.91614","0.00071"
"23.04000","1.92008","0.00095"
"23.08800","1.92409","0.00095"
"23.13600","1.92815","0.00075"
"23.18400","1.93210","0.00086"
"23.23200","1.93610","0.00054"
"23.28000","1.94017","0.00084"
"23.32800","1.94412","0.00097"
"23.37600","1.94812","0.00071"
"23.42400","1.95207","0.00116"
"23.47200","1.95607","0.00080"
"23.52000","1.96008","0.00092"
"23.56800","1.96415","0.00084"
"23.61600","1.96809","0.00076"
"23.66400","1.97216","0.00080"
"23.71200","1.97616","0.00066"
"23.76000","1.98017","0.00089"
"23.80800","1.98418","0.00057"
"23.85600","1.98818","0.00079"
"23.90400","1.99213","0.00082"
"23.95200","1.99613","0.00103"
"24.00000","2.00008","0.00079"
"24.04800","2.00403","0.00067"
"24.09600","2.00809","0.00051"
"24.14400","2.01216","0.00063"
"24.19200","2.01616","0.00104"
"24.24000","2.02017","0.00124"
"24.28800","2.02417","0.00099"
"24.33600","2.02812","0.00087"
"24.38400","2.03219","0.00058"
"24.43200","2.03619","0.00089"
"24.48000","2.04014","0.00086"
"24.52800","2.04414","0.00099"
"24.57600","2.04815","0.00122"
"24.62400","2.05210","0.00086"
"24.67200","2.05610","0.00069"
"24.72000","2.06017","0.00077"
"24.76800","2.06417","0.00086"
"24.81600","2.06818","0.00075"
"24.86400","2.07219","0.00066"
"24.91200","2.07613","0.00074"
"24.96000","2.08014","0.00095"
"25.00800","2.08414","0.00107"
"25.05600","2.08809","0.00066"
"25.10400","2.09210","0.00079"
"25.15200","2.09610","0.00115"
"25.20000","2.10005","0.00109"
"25.24800","2.10411","0.00095"
"25.29600","2.10812","0.00069"
"25.34400","2.11207","0.00058"
"25.39200","2.11613","0.00071"
"25.44000","2.12020","0.00141"
"25.48800","2.12414","0.00130"
"25.53600","2.12809","0.00089"
"25.58400","2.13209","0.00087"
"25.63200","2.13604","0.00077"
"25.68000","2.14011","0.00083"
"25.72800","2.14411","0.00126"
"25.77600","2.14812","0.00113"
"25.82400","2.15212","0.00095"
"25.87200","2.15619","0.00101"
"25.92000","2.16014","0.00080"
"25.96800","2.16414","0.00111"
"26.01600","2.16815","0.00126"
"26.06400","2.17209","0.00087"
"26.11200","2.17616","0.00114"
"26.16000","2.18011","0.00082"
"26.20800","2.18405","0.00099"
"26.25600","2.18812","0.00101"
"26.30400","2.19212","0.00048"
"26.35200","2.19613","0.00072"
"26.40000","2.20014","0.00087"
"26.44800","2.20414","0.00098"
"26.49600","2.20809","0.00132"
"26.54400","2.21215","0.00083"
"26.59200","2.21616","0.00096"
"26.64000","2.22010","0.00078"
"26.68800","2.22411","0.00077"
"26.73600","2.22812","0.00134"
"26.78400","2.23206","0.00097"
"26.83200","2.23613","0.00096"
"26.88000","2.24013","0.00076"
"26.92800","2.24414","0.00080"
"26.97600","2.24815","0.00139"
"27.02400","2.25215","0.00100"
"27.07200","2.25616","0.00081"
"27.12000","2.26010","0.00095"
"27.16800","2.26411","0.00160"
"27.21600","2.26812","0.00110"
"27.26400","2.27206","0.00096"
"27.31200","2.27607","0.00055"
"27.36000","2.28013","0.00150"
"27.40800","2.28414","0.00121"
"27.45600","2.28815","0.00122"
"27.50400","2.29209","0.00124"
"27.55200","2.29610","0.00121"
"27.60000","2.30004","0.00130"
"27.64800","2.30411","0.00117"
"27.69600","2.30806","0.00116"
"27.74400","2.31206","0.00062"
"27.79200","2.31607","0.00105"
"27.84000","2.32007","0.00110"
"27.88800","2.32408","0.00145"
"27.93600","2.32814","0.00101"
"27.98400","2.33215","0.00056"
"28.03200","2.33610","0.00119"
"28.08000","2.34016","0.00108"
"28.12800","2.34411","0.00108"
"28.17600","2.34811","0.00083"
"28.22400","2.35206","0.00110"
"28.27200","2.35613","0.00148"
"28.32000","2.36007","0.00087"
"28.36800","2.36408","0.00130"
"28.41600","2.36814","0.00114"
"28.46400","2.37209","0.00080"
"28.51200","2.37610","0.00097"
"28.56000","2.38016","0.00159"
"28.60800","2.38411","0.00097"
"28.65600","2.38811","0.00083"
"28.70400","2.39212","0.00120"
"28.75200","2.39607","0.00133"
"28.80000","2.40001","0.00117"
"28.84800","2.40408","0.00094"
"28.89600","2.40808","0.00154"
"28.94400","2.41209","0.00112"
"28.99200","2.41615","0.00136"
"29.04000","2.42010","0.00127"
"29.08800","2.42411","0.00096"
"29.13600","2.42817","0.00153"
"29.18400","2.43218","0.00111"
"29.23200","2.43612","0.00111"
"29.28000","2.44013","0.00119"
"29.32800","2.44408","0.00163"
"29.37600","2.44802","0.00112"
"29.42400","2.45209","0.00126"
"29.47200","2.45609","0.00154"
"29.52000","2.46016","0.00134"
"29.56800","2.46423","0.00108"
"29.61600","2.46817","0.00133"
"29.66400","2.47212","0.00168"
"29.71200","2.47612","0.00155"
"29.76000","2.48013","0.00143"
"29.80800","2.48414","0.00173"
"29.85600","2.48808","0.00146"
"29.90400","2.49209","0.00151"
"29.95200","2.49603","0.00142"
"30.00000","2.50010","0.00154"
"30.04800","2.50411","0.00124"
"30.09600","2.50811","0.00124"
"30.14400","2.51218","0.00122"
"30.19200","2.51612","0.00131"
"30.24000","2.52013","0.00161"
"30.28800","2.52413","0.00126"
"30.33600","2.52814","0.00138"
"30.38400","2.53209","0.00161"
"30.43200","2.53609","0.00145"
"30.48000","2.54010","0.00119"
"30.52800","2.54410","0.00161"
"30.57600","2.54817","0.00124"
"30.62400","2.55212","0.00132"
"30.67200","2.55612","0.00160"
"30.72000","2.56019","0.00150"
"30.76800","2.56419","0.00125"
"30.81600","2.56814","0.00134"
"30.86400","2.57215","0.00155"
"30.91200","2.57615","0.00168"
"30.96000","2.58010","0.00160"
"31.00800","2.58410","0.00150"
"31.05600","2.58811","0.00156"
"31.10400","2.59206","0.00184"
"31.15200","2.59612","0.00145"
"31.20000","2.60019","0.00136"
"31.24800","2.60413","0.00165"
"31.29600","2.60814","0.00158"
"31.34400","2.61214","0.00096"
"31.39200","2.61615","0.00149"
"31.44000","2.62010","0.00193"
"31.48800","2.62410","0.00169"
"31.53600","2.62811","0.00171"
"31.58400","2.63211","0.00132"
"31.63200","2.63612","0.00130"
"31.68000","2.64007","0.00142"
"31.72800","2.64407","0.00147"
"31.77600","2.64814","0.00185"
"31.82400","2.65214","0.00188"
"31.87200","2.65615","0.00165"
"31.92000","2.66010","0.00189"
"31.96800","2.66410","0.00200"
"32.01600","2.66811","0.00172"
"32.06400","2.67205","0.00182"
"32.11200","2.67606","0.00151"
"32.16000","2.68013","0.00158"
"32.20800","2.68413","0.00197"
"32.25600","2.68808","0.00171"
"32.30400","2.69220","0.00199"
"32.35200","2.69615","0.00164"
"32.40000","2.70016","0.00173"
"32.44800","2.70422","0.00170"
"32.49600","2.70811","0.00211"
"32.54400","2.71211","0.00166"
"32.59200","2.71612","0.00185"
"32.64000","2.72007","0.00157"
"32.68800","2.72407","0.00178"
"32.73600","2.72814","0.00168"
"32.78400","2.73214","0.00183"
"32.83200","2.73615","0.00212"
"32.88000","2.74021","0.00204"
"32.92800","2.74416","0.00199"
"32.97600","2.74817","0.00204"
"33.02400","2.75217","0.00176"
"33.07200","2.75612","0.00160"
"33.12000","2.76012","0.00173"
"33.16800","2.76413","0.00152"
"33.21600","2.76808","0.00168"
"33.26400","2.77208","0.00174"
"33.31200","2.77615","0.00187"
"33.36000","2.78009","0.00199"
"33.40800","2.78410","0.00176"
"33.45600","2.78817","0.00195"
"33.50400","2.79217","0.00175"
"33.55200","2.79612","0.00182"
"33.60000","2.80012","0.00167"
"33.64800","2.80407","0.00189"
"33.69600","2.80808","0.00184"
"33.74400","2.81214","0.00189"
"33.79200","2.81609","0.00198"
"33.84000","2.82015","0.00222"
"33.88800","2.82416","0.00161"
"33.93600","2.82810","0.00189"
"33.98400","2.83217","0.00202"
"34.03200","2.83618","0.00211"
"34.08000","2.84012","0.00201"
"34.12800","2.84413","0.00185"
"34.17600","2.84813","0.00172"
"34.22400","2.85208","0.00169"
"34.27200","2.85603","0.00185"
"34.32000","2.86015","0.00184"
"34.36800","2.86416","0.00188"
"34.41600","2.86816","0.00193"
"34.46400","2.87223","0.00222"
"34.51200","2.87612","0.00194"
"34.56000","2.88012","0.00204"
"34.60800","2.88413","0.00203"
"34.65600","2.88813","0.00173"
"34.70400","2.89208","0.00199"
"34.75200","2.89609","0.00188"
"34.80000","2.90003","0.00202"
"34.84800","2.90404","0.00203"
"34.89600","2.90810","0.00187"
"34.94400","2.91211","0.00241"
"34.99200","2.91617","0.00172"
"35.04000","2.92012","0.00247"
"35.08800","2.92419","0.00178"
"35.13600","2.92813","0.00197"
"35.18400","2.93208","0.00284"
"35.23200","2.93614","0.00204"
"35.28000","2.94015","0.00217"
"35.32800","2.94410","0.00225"
"35.37600","2.94810","0.00217"
"35.42400","2.95211","0.00211"
"35.47200","2.95611","0.00236"
"35.52000","2.96018","0.00224"
"35.56800","2.96413","0.00220"
"35.61600","2.96813","0.00247"
"35.66400","2.97214","0.00223"
"35.71200","2.97614","0.00259"
"35.76000","2.98015","0.00212"
"35.80800","2.98410","0.00243"
"35.85600","2.98810","0.00267"
"35.90400","2.99211","0.00239"
"35.95200","2.99611","0.00210"
"36.00000","3.00012","0.00227"
"36.04800","3.00418","0.00250"
"36.09600","3.00813","0.00246"
"36.14400","3.01208","0.00221"
"36.19200","3.01614","0.00271"
"36.24000","3.02009","0.00262"
"36.28800","3.02410","0.00240"
"36.33600","3.02816","0.00236"
"36.38400","3.03205","0.00216"
"36.43200","3.03605","0.00180"
"36.48000","3.04012","0.00209"
"36.52800","3.04406","0.00254"
"36.57600","3.04813","0.00215"
"36.62400","3.05220","0.00258"
"36.67200","3.05608","0.00234"
"36.72000","3.06015","0.00258"
"36.76800","3.06415","0.00238"
"36.81600","3.06804","0.00248"
"36.86400","3.07205","0.00285"
"36.91200","3.07611","0.00226"
"36.96000","3.08006","0.00226"
"37.00800","3.08412","0.00241"
"37.05600","3.08813","0.00226"
"37.10400","3.09214","0.00247"
"37.15200","3.09614","0.00246"
"37.20000","3.10015","0.00263"
"37.24800","3.10415","0.00302"
"37.29600","3.10816","0.00274"
"37.34400","3.11216","0.00245"
"37.39200","3.11611","0.00283"
"37.44000","3.12012","0.00264"
"37.48800","3.12412","0.00243"
"37.53600","3.12807","0.00248"
"37.58400","3.13213","0.00293"
"37.63200","3.13620","0.00221"
"37.68000","3.14015","0.00256"
"37.72800","3.14415","0.00243"
"37.77600","3.14816","0.00261"
"37.82400","3.15216","0.00251"
"37.87200","3.15617","0.00262"
"37.92000","3.16012","0.00250"
"37.96800","3.16412","0.00248"
"38.01600","3.16807","0.00267"
"38.06400","3.17207","0.00226"
"38.11200","3.17608","0.00244"
"38.16000","3.18009","0.00263"
"38.20800","3.18415","0.00265"
"38.25600","3.18810","0.00256"
"38.30400","3.19210","0.00243"
"38.35200","3.19611","0.00230"
"38.40000","3.20006","0.00267"
"38.44800","3.20406","0.00249"
"38.49600","3.20813","0.00263"
"38.54400","3.21207","0.00246"
"38.59200","3.21608","0.00302"
"38.64000","3.22014","0.00264"
"38.68800","3.22409","0.00267"
"38.73600","3.22816","0.00238"
"38.78400","3.23216","0.00239"
"38.83200","3.23617","0.00246"
"38.88000","3.24017","0.00257"
"38.92800","3.24412","0.00262"
"38.97600","3.24813","0.00314"
"39.02400","3.25213","0.00266"
"39.07200","3.25608","0.00255"
"39.12000","3.26008","0.00260"
"39.16800","3.26409","0.00273"
"39.21600","3.26810","0.00279"
"39.26400","3.27210","0.00307"
"39.31200","3.27611","0.00301"
"39.36000","3.28017","0.00279"
"39.40800","3.28418","0.00277"
"39.45600","3.28813","0.00294"
"39.50400","3.29213","0.00302"
"39.55200","3.29608","0.00280"
"39.60000","3.30008","0.00284"
"39.64800","3.30409","0.00272"
"39.69600","3.30804","0.00298"
"39.74400","3.31216","0.00298"
"39.79200","3.31623","0.00255"
"39.84000","3.32011","0.00282"
"39.88800","3.32418","0.00268"
"39.93600","3.32812","0.00255"
"39.98400","3.33213","0.00285"
"40.03200","3.33614","0.00277"
"40.08000","3.34014","0.00274"
"40.12800","3.34409","0.00270"
"40.17600","3.34809","0.00322"
"40.22400","3.35210","0.00271"
"40.27200","3.35611","0.00296"
"40.32000","3.36011","0.00282"
"40.36800","3.36412","0.00280"
"40.41600","3.36812","0.00276"
"40.46400","3.37213","0.00278"
"40.51200","3.37614","0.00343"
"40.56000","3.38014","0.00284"
"40.60800","3.38415","0.00351"
"40.65600","3.38809","0.00269"
"40.70400","3.39210","0.00292"
"40.75200","3.39611","0.00340"
"40.80000","3.40005","0.00265"
"40.84800","3.40412","0.00341"
"40.89600","3.40812","0.00271"
"40.94400","3.41213","0.00320"
"40.99200","3.41614","0.00293"
"41.04000","3.42020","0.00306"
"41.08800","3.42421","0.00272"
"41.13600","3.42809","0.00301"
"41.18400","3.43210","0.00288"
"41.23200","3.43604","0.00290"
"41.28000","3.44005","0.00313"
"41.32800","3.44412","0.00339"
"41.37600","3.44812","0.00339"
"41.42400","3.45213","0.00323"
"41.47200","3.45619","0.00292"
"41.52000","3.46014","0.00279"
"41.56800","3.46415","0.00319"
"41.61600","3.46815","0.00322"
"41.66400","3.47210","0.00331"
"41.71200","3.47610","0.00358"
"41.76000","3.48011","0.00306"
"41.80800","3.48412","0.00348"
"41.85600","3.48812","0.00318"
"41.90400","3.49213","0.00357"
"41.95200","3.49613","0.00343"
"42.00000","3.50014","0.00350"
"42.04800","3.50420","0.00308"
"42.09600","3.50821","0.00344"
"42.14400","3.51216","0.00307"
"42.19200","3.51616","0.00309"
"42.24000","3.52011","0.00361"
"42.28800","3.52411","0.00291"
"42.33600","3.52812","0.00309"
"42.38400","3.53213","0.00377"
"42.43200","3.53613","0.00375"
"42.48000","3.54014","0.00267"
"42.52800","3.54408","0.00334"
"42.57600","3.54809","0.00336"
"42.62400","3.55216","0.00334"
"42.67200","3.55610","0.00287"
"42.72000","3.56011","0.00333"
"42.76800","3.56411","0.00332"
"42.81600","3.56812","0.00348"
"42.86400","3.57207","0.00350"
"42.91200","3.57607","0.00295"
"42.96000","3.58008","0.00344"
"43.00800","3.58414","0.00355"
"43.05600","3.58809","0.00345"
"43.10400","3.59210","0.00325"
"43.15200","3.59616","0.00359"
"43.20000","3.60011","0.00310"
"43.24800","3.60411","0.00333"
"43.29600","3.60818","0.00347"
"43.34400","3.61213","0.00336"
"43.39200","3.61607","0.00312"
"43.44000","3.62008","0.00285"
"43.48800","3.62414","0.00337"
"43.53600","3.62815","0.00353"
"43.58400","3.63215","0.00319"
"43.63200","3.63616","0.00329"
"43.68000","3.64011","0.00383"
"43.72800","3.64411","0.00355"
"43.77600","3.64818","0.00386"
"43.82400","3.65212","0.00350"
"43.87200","3.65613","0.00355"
"43.92000","3.66014","0.00394"
"43.96800","3.66408","0.00354"
"44.01600","3.66809","0.00373"
"44.06400","3.67215","0.00361"
"44.11200","3.67610","0.00350"
"44.16000","3.68011","0.00391"
"44.20800","3.68417","0.00349"
"44.25600","3.68818","0.00391"
"44.30400","3.69212","0.00372"
"44.35200","3.69613","0.00376"
"44.40000","3.70014","0.00362"
"44.44800","3.70408","0.00397"
"44.49600","3.70809","0.00371"
"44.54400","3.71209","0.00361"
"44.59200","3.71610","0.00439"
"44.64000","3.72016","0.00388"
"44.68800","3.72417","0.00307"
"44.73600","3.72812","0.00389"
"44.78400","3.73212","0.00409"
"44.83200","3.73607","0.00369"
"44.88000","3.74007","0.00375"
"44.92800","3.74414","0.00397"
"44.97600","3.74809","0.00403"
"45.02400","3.75203","0.00383"
"45.07200","3.75616","0.00359"
"45.12000","3.76016","0.00420"
"45.16800","3.76411","0.00407"
"45.21600","3.76818","0.00376"
"45.26400","3.77212","0.00378"
"45.31200","3.77613","0.00420"
"45.36000","3.78019","0.00379"
"45.40800","3.78414","0.00364"
"45.45600","3.78809","0.00417"
"45.50400","3.79215","0.00368"
"45.55200","3.79610","0.00406"
"45.60000","3.80010","0.00409"
"45.64800","3.80417","0.00388"
"45.69600","3.80812","0.00366"
"45.74400","3.81212","0.00341"
"45.79200","3.81613","0.00376"
"45.84000","3.82013","0.00395"
"45.88800","3.82414","0.00394"
"45.93600","3.82814","0.00366"
"45.98400","3.83209","0.00375"
"46.03200","3.83604","0.00416"
"46.08000","3.84010","0.00408"
"46.12800","3.84405","0.00407"
"46.17600","3.84811","0.00401"
"46.22400","3.85218","0.00391"
"46.27200","3.85619","0.00408"
"46.32000","3.86013","0.00395"
"46.36800","3.86420","0.00387"
"46.41600","3.86814","0.00374"
"46.46400","3.87209","0.00330"
"46.51200","3.87616","0.00289"
"46.56000","3.88010","0.00272"
"46.60800","3.88411","0.00296"
"46.65600","3.88805","0.00306"
"46.70400","3.89212","0.00275"
"46.75200","3.89613","0.00279"
"46.80000","3.90013","0.00272"
"46.84800","3.90414","0.00292"
"46.89600","3.90814","0.00319"
"46.94400","3.91215","0.00289"
"46.99200","3.91615","0.00316"
"47.04000","3.92016","0.00313"
"47.08800","3.92411","0.00299"
"47.13600","3.92811","0.00266"
"47.18400","3.93206","0.00319"
"47.23200","3.93612","0.00305"
"47.28000","3.94013","0.00276"
"47.32800","3.94414","0.00285"
"47.37600","3.94814","0.00320"
"47.42400","3.95215","0.00334"
"47.47200","3.95615","0.00301"
"47.52000","3.96016","0.00291"
"47.56800","3.96411","0.00292"
"47.61600","3.96805","0.00303"
"47.66400","3.97212","0.00342"
"47.71200","3.97600","0.00342"
"47.76000","3.98007","0.00308"
"47.80800","3.98414","0.00322"
"47.85600","3.98814","0.00299"
"47.90400","3.99215","0.00359"
"47.95200","3.99615","0.00349"
"48.00000","4.00016","0.00333"
"48.04800","4.00416","0.00351"
"48.09600","4.00817","0.00330"
"48.14400","4.01218","0.00324"
"48.19200","4.01612","0.00323"
"48.24000","4.02007","0.00328"
"48.28800","4.02408","0.00353"
"48.33600","4.02808","0.00379"
"48.38400","4.03215","0.00337"
"48.43200","4.03615","0.00337"
"48.48000","4.04016","0.00325"
"48.52800","4.04416","0.00365"
"48.57600","4.04817","0.00350"
"48.62400","4.05212","0.00357"
"48.67200","4.05612","0.00353"
"48.72000","4.06013","0.00339"
"48.76800","4.06407","0.00342"
"48.81600","4.06808","0.00341"
"48.86400","4.07209","0.00367"
"48.91200","4.07609","0.00375"
"48.96000","4.08016","0.00332"
"49.00800","4.08416","0.00338"
"49.05600","4.08817","0.00328"
"49.10400","4.09218","0.00395"
"49.15200","4.09612","0.00366"
"49.20000","4.10007","0.00415"
"49.24800","4.10407","0.00372"
"49.29600","4.10808","0.00354"
"49.34400","4.11208","0.00391"
"49.39200","4.11615","0.00359"
"49.44000","4.12010","0.00384"
"49.48800","4.12410","0.00328"
"49.53600","4.12817","0.00382"
"49.58400","4.13211","0.00355"
"49.63200","4.13618","0.00390"
"49.68000","4.14019","0.00367"
"49.72800","4.14413","0.00376"
"49.77600","4.14808","0.00427"
"49.82400","4.15214","0.00357"
"49.87200","4.15609","0.00390"
"49.92000","4.16010","0.00393"
"49.96800","4.16410","0.00366"
"50.01600","4.16811","0.00385"
"50.06400","4.17217","0.00372"
"50.11200","4.17618","0.00395"
"50.16000","4.18018","0.00403"
"50.20800","4.18413","0.00384"
"50.25600","4.18814","0.00390"
"50.30400","4.19214","0.00363"
"50.35200","4.19615","0.00416"
"50.40000","4.20009","0.00419"
"50.44800","4.20410","0.00416"
"50.49600","4.20811","0.00364"
"50.54400","4.21211","0.00390"
"50.59200","4.21618","0.00394"
"50.64000","4.22012","0.00391"
"50.68800","4.22413","0.00385"
"50.73600","4.22814","0.00442"
"50.78400","4.23208","0.00406"
"50.83200","4.23609","0.00405"
"50.88000","4.24009","0.00429"
"50.92800","4.24404","0.00438"
"50.97600","4.24811","0.00402"
"51.02400","4.25211","0.00418"
"51.07200","4.25612","0.00378"
"51.12000","4.26018","0.00435"
"51.16800","4.26413","0.00413"
"51.21600","4.26814","0.00396"
"51.26400","4.27220","0.00402"
"51.31200","4.27615","0.00410"
"51.36000","4.28015","0.00415"
"51.40800","4.28416","0.00412"
"51.45600","4.28811","0.00414"
"51.50400","4.29211","0.00414"
"51.55200","4.29612","0.00413"
"51.60000","4.30012","0.00399"
"51.64800","4.30419","0.00396"
"51.69600","4.30819","0.00410"
"51.74400","4.31214","0.00431"
"51.79200","4.31615","0.00390"
"51.84000","4.32015","0.00390"
"51.88800","4.32410","0.00435"
"51.93600","4.32810","0.00439"
"51.98400","4.33211","0.00395"
"52.03200","4.33612","0.00480"
"52.08000","4.34012","0.00403"
"52.12800","4.34413","0.00444"
"52.17600","4.34813","0.00442"
"52.22400","4.35214","0.00423"
"52.27200","4.35615","0.00396"
"52.32000","4.36015","0.00429"
"52.36800","4.36416","0.00434"
"52.41600","4.36816","0.00429"
"52.46400","4.37211","0.00414"
"52.51200","4.37612","0.00414"
"52.56000","4.38012","0.00407"
"52.60800","4.38407","0.00441"
"52.65600","4.38813","0.00430"
"52.70400","4.39214","0.00440"
"52.75200","4.39609","0.00455"
"52.80000","4.40009","0.00440"
"52.84800","4.40416","0.00434"
"52.89600","4.40810","0.00466"
"52.94400","4.41211","0.00429"
"52.99200","4.41611","0.00407"
"53.04000","4.42006","0.00427"
"53.08800","4.42407","0.00455"
"53.13600","4.42813","0.00455"
"53.18400","4.43208","0.00436"
"53.23200","4.43614","0.00408"
"53.28000","4.44015","0.00460"
"53.32800","4.44410","0.00415"
"53.37600","4.44816","0.00483"
"53.42400","4.45217","0.00456"
"53.47200","4.45611","0.00461"
"53.52000","4.46012","0.00452"
"53.56800","4.46407","0.00502"
"53.61600","4.46807","0.00471"
"53.66400","4.47208","0.00452"
"53.71200","4.47614","0.00435"
"53.76000","4.48015","0.00494"
"53.80800","4.48421","0.00463"
"53.85600","4.48816","0.00472"
"53.90400","4.49211","0.00431"
"53.95200","4.49611","0.00468"
"54.00000","4.50012","0.00441"
"54.04800","4.50407","0.00489"
"54.09600","4.50807","0.00446"
"54.14400","4.51214","0.00495"
"54.19200","4.51602","0.00466"
"54.24000","4.52009","0.00416"
"54.28800","4.52409","0.00454"
"54.33600","4.52810","0.00489"
"54.38400","4.53217","0.00451"
"54.43200","4.53611","0.00495"
"54.48000","4.54012","0.00517"
"54.52800","4.54412","0.00487"
"54.57600","4.54813","0.00484"
"54.62400","4.55208","0.00482"
"54.67200","4.55608","0.00488"
"54.72000","4.56009","0.00457"
"54.76800","4.56409","0.00526"
"54.81600","4.56816","0.00507"
"54.86400","4.57217","0.00489"
"54.91200","4.57611","0.00512"
"54.96000","4.58018","0.00523"
"55.00800","4.58418","0.00492"
"55.05600","4.58813","0.00444"
"55.10400","4.59213","0.00532"
"55.15200","4.59608","0.00490"
"55.20000","4.60003","0.00534"
"55.24800","4.60409","0.00495"
"55.29600","4.60810","0.00508"
"55.34400","4.61216","0.00546"
"55.39200","4.61617","0.00477"
"55.44000","4.62018","0.00522"
"55.48800","4.62412","0.00502"
"55.53600","4.62813","0.00520"
"55.58400","4.63207","0.00478"
"55.63200","4.63614","0.00534"
"55.68000","4.64009","0.00490"
"55.72800","4.64409","0.00481"
"55.77600","4.64810","0.00509"
"55.82400","4.65210","0.00505"
"55.87200","4.65611","0.00544"
"55.92000","4.66018","0.00521"
"55.96800","4.66418","0.00532"
"56.01600","4.66813","0.00545"
"56.06400","4.67213","0.00506"
"56.11200","4.67614","0.00505"
"56.16000","4.68015","0.00481"
"56.20800","4.68415","0.00500"
"56.25600","4.68810","0.00512"
"56.30400","4.69204","0.00469"
"56.35200","4.69605","0.00544"
"56.40000","4.70011","0.00496"
"56.44800","4.70412","0.00548"
"56.49600","4.70813","0.00572"
"56.54400","4.71213","0.00558"
"56.59200","4.71614","0.00509"
"56.64000","4.72014","0.00567"
"56.68800","4.72415","0.00512"
"56.73600","4.72816","0.00513"
"56.78400","4.73210","0.00556"
"56.83200","4.73611","0.00554"
"56.88000","4.74005","0.00547"
"56.92800","4.74406","0.00535"
"56.97600","4.74819","0.00539"
"57.02400","4.75219","0.00540"
"57.07200","4.75614","0.00544"
"57.12000","4.76020","0.00557"
"57.16800","4.76415","0.00552"
"57.21600","4.76810","0.00582"
"57.26400","4.77216","0.00558"
"57.31200","4.77611","0.00510"
"57.36000","4.78005","0.00580"
"57.40800","4.78412","0.00560"
"57.45600","4.78807","0.00486"
"57.50400","4.79207","0.00540"
"57.55200","4.79620","0.00553"
"57.60000","4.80014","0.00542"
"57.64800","4.80415","0.00544"
"57.69600","4.80816","0.00545"
"57.74400","4.81210","0.00589"
"57.79200","4.81611","0.00539"
"57.84000","4.82011","0.00600"
"57.88800","4.82406","0.00593"
"57.93600","4.82806","0.00568"
"57.98400","4.83213","0.00562"
"58.03200","4.83608","0.00544"
"58.08000","4.84008","0.00550"
"58.12800","4.84415","0.00533"
"58.17600","4.84815","0.00588"
"58.22400","4.85216","0.00552"
"58.27200","4.85617","0.00577"
"58.32000","4.86011","0.00594"
"58.36800","4.86412","0.00557"
"58.41600","4.86806","0.00599"
"58.46400","4.87207","0.00561"
"58.51200","4.87608","0.00549"
"58.56000","4.88014","0.00562"
"58.60800","4.88415","0.00566"
"58.65600","4.88809","0.00585"
"58.70400","4.89216","0.00560"
"58.75200","4.89616","0.00579"
"58.80000","4.90017","0.00574"
"58.84800","4.90418","0.00557"
"58.89600","4.90812","0.00614"
"58.94400","4.91213","0.00612"
"58.99200","4.91613","0.00558"
"59.04000","4.92008","0.00562"
"59.08800","4.92409","0.00579"
"59.13600","4.92815","0.00585"
"59.18400","4.93216","0.00579"
"59.23200","4.93610","0.00592"
"59.28000","4.94017","0.00581"
"59.32800","4.94418","0.00570"
"59.37600","4.94812","0.00579"
"59.42400","4.95219","0.00567"
"59.47200","4.95613","0.00601"
"59.52000","4.96008","0.00617"
"59.56800","4.96409","0.00619"
"59.61600","4.96809","0.00610"
"59.66400","4.97210","0.00604"
"59.71200","4.97616","0.00540"
"59.76000","4.98017","0.00607"
"59.80800","4.98412","0.00606"
"59.85600","4.98812","0.00593"
"59.90400","4.99213","0.00607"
"59.95200","4.99607","0.00628"
"60.00000","5.00008","0.00625"
"60.04800","5.00409","0.00589"
"60.09600","5.00803","0.00627"
"60.14400","5.01210","0.00605"
"60.19200","5.01610","0.00600"
"60.24000","5.02011","0.00593"
"60.28800","5.02417","0.00617"
"60.33600","5.02812","0.00594"
"60.38400","5.03213","0.00624"
"60.43200","5.03613","0.00635"
"60.48000","5.04014","0.00595"
"60.52800","5.04414","0.00656"
"60.57600","5.04815","0.00608"
"60.62400","5.05210","0.00657"
"60.67200","5.05610","0.00633"
"60.72000","5.06017","0.00625"
"60.76800","5.06411","0.00591"
"60.81600","5.06812","0.00555"
"60.86400","5.07219","0.00611"
"60.91200","5.07613","0.00607"
"60.96000","5.08008","0.00586"
"61.00800","5.08414","0.00585"
"61.05600","5.08809","0.00626"
"61.10400","5.09209","0.00601"
"61.15200","5.09610","0.00540"
"61.20000","5.10011","0.00568"
"61.24800","5.10411","0.00598"
"61.29600","5.10818","0.00564"
"61.34400","5.11218","0.00572"
"61.39200","5.11613","0.00642"
"61.44000","5.12020","0.00620"
"61.48800","5.12414","0.00608"
"61.53600","5.12809","0.00597"
"61.58400","5.13215","0.00618"
"61.63200","5.13610","0.00530"
"61.68000","5.14005","0.00571"
"61.72800","5.14411","0.00616"
"61.77600","5.14812","0.00591"
"61.82400","5.15212","0.00613"
"61.87200","5.15619","0.00564"
"61.92000","5.16014","0.00587"
"61.96800","5.16414","0.00558"
"62.01600","5.16815","0.00596"
"62.06400","5.17209","0.00595"
"62.11200","5.17610","0.00574"
"62.16000","5.18011","0.00600"
"62.20800","5.18411","0.00583"
"62.25600","5.18806","0.00551"
"62.30400","5.19212","0.00616"
"62.35200","5.19607","0.00661"
"62.40000","5.20014","0.00632"
"62.44800","5.20420","0.00620"
"62.49600","5.20815","0.00595"
"62.54400","5.21215","0.00610"
"62.59200","5.21616","0.00582"
"62.64000","5.22010","0.00581"
"62.68800","5.22411","0.00614"
"62.73600","5.22812","0.00630"
"62.78400","5.23206","0.00645"
"62.83200","5.23613","0.00644"
"62.88000","5.24019","0.00636"
"62.92800","5.24414","0.00618"
"62.97600","5.24815","0.00576"
"63.02400","5.25221","0.00647"
"63.07200","5.25616","0.00634"
"63.12000","5.26016","0.00659"
"63.16800","5.26417","0.00610"
"63.21600","5.26812","0.00627"
"63.26400","5.27206","0.00630"
"63.31200","5.27607","0.00564"
"63.36000","5.28013","0.00637"
"63.40800","5.28414","0.00611"
"63.45600","5.28815","0.00579"
"63.50400","5.29215","0.00622"
"63.55200","5.29610","0.00598"
"63.60000","5.30010","0.00668"
"63.64800","5.30417","0.00661"
"63.69600","5.30812","0.00647"
"63.74400","5.31206","0.00657"
"63.79200","5.31613","0.00644"
"63.84000","5.32007","0.00623"
"63.88800","5.32408","0.00662"
"63.93600","5.32814","0.00700"
"63.98400","5.33215","0.00654"
"64.03200","5.33616","0.00676"
"64.08000","5.34016","0.00646"
"64.12800","5.34417","0.00667"
"64.17600","5.34817","0.00649"
"64.22400","5.35212","0.00580"
"64.27200","5.35613","0.00620"
"64.32000","5.36007","0.00643"
"64.36800","5.36408","0.00628"
"64.41600","5.36808","0.00603"
"64.46400","5.37215","0.00631"
"64.51200","5.37616","0.00631"
"64.56000","5.38016","0.00647"
"64.60800","5.38423","0.00651"
"64.65600","5.38811","0.00659"
"64.70400","5.39218","0.00675"
"64.75200","5.39618","0.00634"
"64.80000","5.40007","0.00621"
"64.84800","5.40408","0.00634"
"64.89600","5.40808","0.00636"
"64.94400","5.41203","0.00642"
"64.99200","5.41609","0.00683"
"65.04000","5.42016","0.00658"
"65.08800","5.42417","0.00652"
"65.13600","5.42817","0.00618"
"65.18400","5.43218","0.00667"
"65.23200","5.43612","0.00633"
"65.28000","5.44013","0.00624"
"65.32800","5.44420","0.00634"
"65.37600","5.44808","0.00641"
"65.42400","5.45209","0.00610"
"65.47200","5.45609","0.00668"
"65.52000","5.46004","0.00620"
"65.56800","5.46411","0.00680"
"65.61600","5.46817","0.00695"
"65.66400","5.47218","0.00703"
"65.71200","5.47618","0.00655"
"65.76000","5.48019","0.00679"
"65.80800","5.48414","0.00648"
"65.85600","5.48808","0.00654"
"65.90400","5.49209","0.00643"
"65.95200","5.49609","0.00628"
"66.00000","5.50004","0.00668"
"66.04800","5.50410","0.00728"
"66.09600","5.50811","0.00708"
"66.14400","5.51212","0.00720"
"66.19200","5.51618","0.00675"
"66.24000","5.52013","0.00726"
"66.28800","5.52413","0.00693"
"66.33600","5.52814","0.00672"
"66.38400","5.53209","0.00678"
"66.43200","5.53609","0.00714"
"66.48000","5.54010","0.00610"
"66.52800","5.54410","0.00689"
"66.57600","5.54811","0.00700"
"66.62400","5.55212","0.00693"
"66.67200","5.55612","0.00697"
"66.72000","5.56013","0.00644"
"66.76800","5.56413","0.00676"
"66.81600","5.56814","0.00738"
"66.86400","5.57221","0.00677"
"66.91200","5.57615","0.00722"
"66.96000","5.58010","0.00714"
"67.00800","5.58410","0.00646"
"67.05600","5.58811","0.00691"
"67.10400","5.59206","0.00718"
"67.15200","5.59606","0.00729"
"67.20000","5.60013","0.00668"
"67.24800","5.60413","0.00722"
"67.29600","5.60814","0.00724"
"67.34400","5.61214","0.00722"
"67.39200","5.61615","0.00676"
"67.44000","5.62016","0.00699"
"67.48800","5.62416","0.00735"
"67.53600","5.62811","0.00706"
"67.58400","5.63211","0.00705"
"67.63200","5.63606","0.00730"
"67.68000","5.64013","0.00718"
"67.72800","5.64413","0.00714"
"67.77600","5.64814","0.00729"
"67.82400","5.65214","0.00688"
"67.87200","5.65615","0.00753"
"67.92000","5.66016","0.00765"
"67.96800","5.66416","0.00748"
"68.01600","5.66817","0.00736"
"68.06400","5.67217","0.00712"
"68.11200","5.67612","0.00771"
"68.16000","5.68013","0.00738"
"68.20800","5.68413","0.00726"
"68.25600","5.68808","0.00725"
"68.30400","5.69214","0.00743"
"68.35200","5.69609","0.00741"
"68.40000","5.70010","0.00723"
"68.44800","5.70416","0.00749"
"68.49600","5.70817","0.00747"
"68.54400","5.71211","0.00762"
"68.59200","5.71612","0.00749"
"68.64000","5.72007","0.00759"
"68.68800","5.72407","0.00786"
"68.73600","5.72814","0.00741"
"68.78400","5.73208","0.00682"
"68.83200","5.73615","0.00781"
"68.88000","5.74015","0.00779"
"68.92800","5.74416","0.00802"
"68.97600","5.74817","0.00769"
"69.02400","5.75217","0.00808"
"69.07200","5.75612","0.00762"
"69.12000","5.76012","0.00743"
"69.16800","5.76413","0.00754"
"69.21600","5.76808","0.00787"
"69.26400","5.77208","0.00724"
"69.31200","5.77615","0.00780"
"69.36000","5.78015","0.00753"
"69.40800","5.78416","0.00729"
"69.45600","5.78817","0.00773"
"69.50400","5.79211","0.00808"
"69.55200","5.79612","0.00792"
"69.60000","5.80018","0.00794"
"69.64800","5.80419","0.00750"
"69.69600","5.80814","0.00760"
"69.74400","5.81214","0.00766"
"69.79200","5.81609","0.00800"
"69.84000","5.82009","0.00795"
"69.88800","5.82416","0.00785"
"69.93600","5.82816","0.00831"
"69.98400","5.83211","0.00783"
"70.03200","5.83618","0.00818"
"70.06000","5.83851","0.00778"