File: Force_trajectories/161223_2/Specimen_RawData_2.csv
End date,"12/23/2016"
Specimen label,"21AT_70"
Maximum Load,"0.31666",N

Time,Extension,Load
(s),(mm),(N)
"0.00000","0.00000","-0.00009"
"0.18000","0.01118","0.00034"
"0.36000","0.03001","-0.00012"
"0.54000","0.04514","0.00000"
"0.72000","0.06021","0.00031"
"0.90000","0.07522","0.00026"
"1.08000","0.09016","0.00028"
"1.26000","0.10517","0.00030"
"1.44000","0.12018","-0.00023"
"1.62000","0.13512","0.00043"
"1.80000","0.15013","0.00034"
"1.98000","0.16514","0.00031"
"2.16000","0.18015","0.00045"
"2.34000","0.19503","-0.00047"
"2.52000","0.21010","-0.00009"
"2.70000","0.22511","0.00003"
"2.88000","0.24017","0.00027"
"3.06000","0.25512","0.00024"
"3.24000","0.27013","0.00056"
"3.42000","0.28514","0.00008"
"3.60000","0.30008","0.00034"
"3.78000","0.31509","-0.00006"
"3.96000","0.33010","0.00000"
"4.14000","0.34511","0.00020"
"4.32000","0.36011","0.00093"
"4.50000","0.37512","0.00072"
"4.68000","0.39013","0.00038"
"4.86000","0.40513","0.00021"
"5.04000","0.42014","0.00037"
"5.22000","0.43515","0.00064"
"5.40000","0.45010","0.00002"
"5.58000","0.46516","0.00029"
"5.76000","0.48017","0.00024"
"5.94000","0.49512","0.00059"
"6.12000","0.51012","0.00037"
"6.30000","0.52519","0.00021"
"6.48000","0.54014","0.00027"
"6.66000","0.55515","0.00045"
"6.84000","0.57015","0.00047"
"7.02000","0.58510","0.00012"
"7.20000","0.60017","0.00048"
"7.38000","0.61517","0.00026"
"7.56000","0.63006","0.00060"
"7.74000","0.64513","0.00039"
"7.92000","0.66014","0.00057"
"8.10000","0.67508","0.00048"
"8.28000","0.69009","0.00055"
"8.46000","0.70522","0.00026"
"8.64000","0.72005","0.00045"
"8.82000","0.73511","0.00058"
"9.00000","0.75018","0.00032"
"9.18000","0.76513","0.00019"
"9.36000","0.78013","0.00043"
"9.54000","0.79514","0.00034"
"9.72000","0.81009","0.00010"
"9.90000","0.82516","0.00032"
"10.08000","0.84016","0.00096"
"10.26000","0.85505","-0.00001"
"10.44000","0.87012","0.00068"
"10.62000","0.88518","0.00054"
"10.80000","0.90007","0.00072"
"10.98000","0.91514","0.00044"
"11.16000","0.93015","0.00048"
"11.34000","0.94509","0.00051"
"11.52000","0.96016","0.00051"
"11.70000","0.97517","0.00076"
"11.88000","0.99011","0.00062"
"12.06000","1.00518","0.00043"
"12.24000","1.02013","0.00066"
"12.42000","1.03508","0.00073"
"12.60000","1.05014","0.00033"
"12.78000","1.06515","0.00041"
"12.96000","1.08010","0.00046"
"13.14000","1.09516","0.00066"
"13.32000","1.11017","0.00065"
"13.50000","1.12512","0.00062"
"13.68000","1.14019","0.00036"
"13.86000","1.15513","0.00066"
"14.04000","1.17008","0.00046"
"14.22000","1.18521","0.00078"
"14.40000","1.20016","0.00056"
"14.58000","1.21504","0.00074"
"14.76000","1.23011","0.00043"
"14.94000","1.24512","0.00056"
"15.12000","1.26006","0.00081"
"15.30000","1.27513","0.00069"
"15.48000","1.29014","0.00097"
"15.66000","1.30503","0.00099"
"15.84000","1.32015","0.00098"
"16.02000","1.33516","0.00028"
"16.20000","1.35011","0.00030"
"16.38000","1.36511","0.00075"
"16.56000","1.38012","0.00083"
"16.74000","1.39507","0.00084"
"16.92000","1.41014","0.00053"
"17.10000","1.42514","0.00040"
"17.28000","1.44009","0.00086"
"17.46000","1.45516","0.00066"
"17.64000","1.47016","0.00089"
"17.82000","1.48511","0.00077"
"18.00000","1.50012","0.00088"
"18.18000","1.51513","0.00095"
"18.36000","1.53007","0.00053"
"18.54000","1.54514","0.00088"
"18.72000","1.56015","0.00115"
"18.90000","1.57510","0.00094"
"19.08000","1.59016","0.00074"
"19.26000","1.60511","0.00096"
"19.44000","1.62006","0.00071"
"19.62000","1.63512","0.00087"
"19.80000","1.65013","0.00101"
"19.98000","1.66508","0.00082"
"20.16000","1.68015","0.00094"
"20.34000","1.69509","0.00030"
"20.52000","1.71010","0.00068"
"20.70000","1.72517","0.00082"
"20.88000","1.74011","0.00053"
"21.06000","1.75506","0.00103"
"21.24000","1.77019","0.00046"
"21.42000","1.78508","0.00091"
"21.60000","1.80008","0.00044"
"21.78000","1.81515","0.00053"
"21.96000","1.83016","0.00071"
"22.14000","1.84510","0.00100"
"22.32000","1.86011","0.00068"
"22.50000","1.87512","0.00075"
"22.68000","1.89013","0.00113"
"22.86000","1.90519","0.00071"
"23.04000","1.92008","0.00111"
"23.22000","1.93509","0.00042"
"23.40000","1.95022","0.00097"
"23.58000","1.96516","0.00084"
"23.76000","1.98005","0.00097"
"23.94000","1.99518","0.00089"
"24.12000","2.01012","0.00088"
"24.30000","2.02507","0.00078"
"24.48000","2.04020","0.00075"
"24.66000","2.05515","0.00089"
"24.84000","2.07009","0.00121"
"25.02000","2.08516","0.00103"
"25.20000","2.10011","0.00081"
"25.38000","2.11505","0.00089"
"25.56000","2.13018","0.00089"
"25.74000","2.14513","0.00093"
"25.92000","2.16008","0.00144"
"26.10000","2.17514","0.00104"
"26.28000","2.19015","0.00112"
"26.46000","2.20510","0.00123"
"26.64000","2.22016","0.00097"
"26.82000","2.23517","0.00069"
"27.00000","2.25012","0.00116"
"27.18000","2.26513","0.00174"
"27.36000","2.28013","0.00065"
"27.54000","2.29508","0.00108"
"27.72000","2.31015","0.00092"
"27.90000","2.32510","0.00131"
"28.08000","2.34010","0.00111"
"28.26000","2.35517","0.00095"
"28.44000","2.37018","0.00114"
"28.62000","2.38506","0.00120"
"28.80000","2.40013","0.00111"
"28.98000","2.41514","0.00111"
"29.16000","2.43015","0.00068"
"29.34000","2.44515","0.00130"
"29.52000","2.46010","0.00095"
"29.70000","2.47511","0.00087"
"29.88000","2.49017","0.00110"
"30.06000","2.50506","0.00113"
"30.24000","2.52013","0.00129"
"30.42000","2.53520","0.00118"
"30.60000","2.55014","0.00127"
"30.78000","2.56509","0.00148"
"30.96000","2.58010","0.00152"
"31.14000","2.59516","0.00164"
"31.32000","2.61005","0.00143"
"31.50000","2.62512","0.00127"
"31.68000","2.64013","0.00112"
"31.86000","2.65507","0.00123"
"32.04000","2.67014","0.00127"
"32.22000","2.68515","0.00133"
"32.40000","2.70010","0.00127"
"32.58000","2.71516","0.00175"
"32.76000","2.73017","0.00150"
"32.94000","2.74506","0.00123"
"33.12000","2.76012","0.00111"
"33.30000","2.77513","0.00156"
"33.48000","2.79008","0.00144"
"33.66000","2.80509","0.00190"
"33.84000","2.82009","0.00194"
"34.02000","2.83516","0.00181"
"34.20000","2.85011","0.00171"
"34.38000","2.86511","0.00171"
"34.56000","2.88012","0.00146"
"34.74000","2.89519","0.00175"
"34.92000","2.91014","0.00181"
"35.10000","2.92508","0.00135"
"35.28000","2.94015","0.00159"
"35.46000","2.95516","0.00188"
"35.64000","2.97010","0.00175"
"35.82000","2.98505","0.00163"
"36.00000","3.00012","0.00169"
"36.18000","3.01513","0.00120"
"36.36000","3.03013","0.00161"
"36.54000","3.04508","0.00153"
"36.72000","3.06009","0.00155"
"36.90000","3.07510","0.00175"
"37.08000","3.09010","0.00154"
"37.26000","3.10511","0.00144"
"37.44000","3.12018","0.00172"
"37.62000","3.13512","0.00148"
"37.80000","3.15013","0.00155"
"37.98000","3.16514","0.00168"
"38.16000","3.18015","0.00214"
"38.34000","3.19509","0.00204"
"38.52000","3.21010","0.00159"
"38.70000","3.22505","0.00169"
"38.88000","3.24017","0.00166"
"39.06000","3.25512","0.00151"
"39.24000","3.27007","0.00169"
"39.42000","3.28514","0.00208"
"39.60000","3.30014","0.00154"
"39.78000","3.31509","0.00150"
"39.96000","3.33016","0.00143"
"40.14000","3.34516","0.00148"
"40.32000","3.36011","0.00138"
"40.50000","3.37512","0.00180"
"40.68000","3.39013","0.00194"
"40.86000","3.40507","0.00179"
"41.04000","3.42014","0.00157"
"41.22000","3.43515","0.00160"
"41.40000","3.45010","0.00124"
"41.58000","3.46510","0.00123"
"41.76000","3.48017","0.00167"
"41.94000","3.49512","0.00195"
"42.12000","3.51012","0.00136"
"42.30000","3.52513","0.00187"
"42.48000","3.54014","0.00152"
"42.66000","3.55509","0.00158"
"42.84000","3.57009","0.00155"
"43.02000","3.58510","0.00176"
"43.20000","3.60011","0.00176"
"43.38000","3.61517","0.00191"
"43.56000","3.63012","0.00166"
"43.74000","3.64513","0.00180"
"43.92000","3.66020","0.00193"
"44.10000","3.67508","0.00154"
"44.28000","3.69009","0.00181"
"44.46000","3.70516","0.00161"
"44.64000","3.72010","0.00197"
"44.82000","3.73511","0.00220"
"45.00000","3.75012","0.00202"
"45.18000","3.76513","0.00190"
"45.36000","3.78013","0.00214"
"45.54000","3.79514","0.00187"
"45.72000","3.81009","0.00206"
"45.90000","3.82510","0.00217"
"46.08000","3.84016","0.00233"
"46.26000","3.85511","0.00200"
"46.44000","3.87012","0.00207"
"46.62000","3.88512","0.00218"
"46.80000","3.90013","0.00195"
"46.98000","3.91508","0.00220"
"47.16000","3.93015","0.00291"
"47.34000","3.94509","0.00241"
"47.52000","3.96010","0.00221"
"47.70000","3.97517","0.00218"
"47.88000","3.99011","0.00245"
"48.06000","4.00518","0.00223"
"48.24000","4.02013","0.00200"
"48.42000","4.03508","0.00203"
"48.60000","4.05014","0.00216"
"48.78000","4.06515","0.00225"
"48.96000","4.08010","0.00170"
"49.14000","4.09516","0.00230"
"49.32000","4.11017","0.00203"
"49.50000","4.12512","0.00213"
"49.68000","4.14013","0.00223"
"49.86000","4.15513","0.00238"
"50.04000","4.17008","0.00234"
"50.22000","4.18515","0.00189"
"50.40000","4.20015","0.00220"
"50.58000","4.21510","0.00254"
"50.76000","4.23011","0.00263"
"50.94000","4.24518","0.00256"
"51.12000","4.26012","0.00242"
"51.30000","4.27507","0.00248"
"51.48000","4.29014","0.00230"
"51.66000","4.30509","0.00234"
"51.84000","4.32015","0.00260"
"52.02000","4.33516","0.00250"
"52.20000","4.35011","0.00246"
"52.38000","4.36511","0.00247"
"52.56000","4.38018","0.00266"
"52.74000","4.39513","0.00275"
"52.92000","4.41014","0.00290"
"53.10000","4.42514","0.00268"
"53.28000","4.44009","0.00266"
"53.46000","4.45516","0.00240"
"53.64000","4.47010","0.00241"
"53.82000","4.48511","0.00290"
"54.00000","4.50018","0.00249"
"54.18000","4.51513","0.00276"
"54.36000","4.53013","0.00263"
"54.54000","4.54514","0.00249"
"54.72000","4.56015","0.00319"
"54.90000","4.57515","0.00303"
"55.08000","4.59016","0.00283"
"55.26000","4.60511","0.00344"
"55.44000","4.62006","0.00319"
"55.62000","4.63512","0.00296"
"55.80000","4.65013","0.00346"
"55.98000","4.66514","0.00313"
"56.16000","4.68015","0.00362"
"56.34000","4.69515","0.00333"
"56.52000","4.71010","0.00320"
"56.70000","4.72517","0.00320"
"56.88000","4.74017","0.00365"
"57.06000","4.75512","0.00361"
"57.24000","4.77019","0.00343"
"57.42000","4.78520","0.00340"
"57.60000","4.80008","0.00326"
"57.78000","4.81509","0.00335"
"57.96000","4.83016","0.00361"
"58.14000","4.84510","0.00363"
"58.32000","4.86017","0.00360"
"58.50000","4.87512","0.00376"
"58.68000","4.89013","0.00368"
"58.86000","4.90513","0.00388"
"59.04000","4.92014","0.00361"
"59.22000","4.93509","0.00382"
"59.40000","4.95015","0.00257"
"59.58000","4.96516","0.00269"
"59.76000","4.98005","0.00266"
"59.94000","4.99512","0.00271"
"60.12000","5.01012","0.00258"
"60.30000","5.02507","0.00243"
"60.48000","5.04014","0.00308"
"60.66000","5.05514","0.00326"
"60.84000","5.07009","0.00312"
"61.02000","5.08510","0.00285"
"61.20000","5.10017","0.00307"
"61.38000","5.11505","0.00324"
"61.56000","5.13018","0.00334"
"61.74000","5.14519","0.00351"
"61.92000","5.16008","0.00310"
"62.10000","5.17508","0.00369"
"62.28000","5.19015","0.00342"
"62.46000","5.20510","0.00331"
"62.64000","5.22016","0.00374"
"62.82000","5.23511","0.00342"
"63.00000","5.25012","0.00378"
"63.18000","5.26513","0.00343"
"63.36000","5.28013","0.00316"
"63.54000","5.29508","0.00322"
"63.72000","5.31015","0.00373"
"63.90000","5.32515","0.00364"
"64.08000","5.34004","0.00378"
"64.26000","5.35511","0.00324"
"64.44000","5.37012","0.00400"
"64.62000","5.38512","0.00387"
"64.80000","5.40007","0.00388"
"64.98000","5.41514","0.00375"
"65.16000","5.43015","0.00379"
"65.34000","5.44515","0.00387"
"65.52000","5.46016","0.00408"
"65.70000","5.47505","0.00370"
"65.88000","5.49017","0.00407"
"66.06000","5.50512","0.00403"
"66.24000","5.52007","0.00428"
"66.42000","5.53514","0.00278"
"66.60000","5.55020","0.00276"
"66.78000","5.56503","0.00312"
"66.96000","5.58016","0.00294"
"67.14000","5.59516","0.00279"
"67.32000","5.61005","0.00294"
"67.50000","5.62518","0.00335"
"67.68000","5.64013","0.00347"
"67.86000","5.65507","0.00364"
"68.04000","5.67014","0.00283"
"68.22000","5.68515","0.00360"
"68.40000","5.70010","0.00333"
"68.58000","5.71516","0.00329"
"68.76000","5.73017","0.00344"
"68.94000","5.74506","0.00335"
"69.12000","5.76012","0.00383"
"69.30000","5.77519","0.00399"
"69.48000","5.79014","0.00406"
"69.66000","5.80515","0.00339"
"69.84000","5.82009","0.00447"
"70.02000","5.83510","0.00349"
"70.20000","5.85017","0.00407"
"70.38000","5.86511","0.00395"
"70.56000","5.88000","0.00377"
"70.74000","5.89519","0.00403"
"70.92000","5.91014","0.00435"
"71.10000","5.92508","0.00410"
"71.28000","5.94015","0.00382"
"71.46000","5.95516","0.00455"
"71.64000","5.97010","0.00425"
"71.82000","5.98517","0.00444"
"72.00000","6.00012","0.00451"
"72.18000","6.01513","0.00488"
"72.36000","6.03019","0.00445"
"72.54000","6.04508","0.00426"
"72.72000","6.06009","0.00439"
"72.90000","6.07521","0.00503"
"73.08000","6.09010","0.00497"
"73.26000","6.10511","0.00469"
"73.44000","6.12018","0.00477"
"73.62000","6.13518","0.00410"
"73.80000","6.15007","0.00482"
"73.98000","6.16514","0.00432"
"74.16000","6.18014","0.00473"
"74.34000","6.19509","0.00465"
"74.52000","6.21016","0.00451"
"74.70000","6.22511","0.00392"
"74.88000","6.24005","0.00427"
"75.06000","6.25518","0.00413"
"75.24000","6.27013","0.00484"
"75.42000","6.28508","0.00464"
"75.60000","6.30020","0.00481"
"75.78000","6.31515","0.00454"
"75.96000","6.33010","0.00463"
"76.14000","6.34516","0.00494"
"76.32000","6.36017","0.00492"
"76.50000","6.37512","0.00500"
"76.68000","6.39013","0.00516"
"76.86000","6.40507","0.00495"
"77.04000","6.42008","0.00549"
"77.22000","6.43515","0.00544"
"77.40000","6.45015","0.00501"
"77.58000","6.46504","0.00532"
"77.76000","6.48017","0.00581"
"77.94000","6.49518","0.00569"
"78.12000","6.51006","0.00608"
"78.30000","6.52513","0.00607"
"78.48000","6.54014","0.00642"
"78.66000","6.55514","0.00595"
"78.84000","6.57009","0.00602"
"79.02000","6.58510","0.00592"
"79.20000","6.60011","0.00633"
"79.38000","6.61517","0.00644"
"79.56000","6.63012","0.00659"
"79.74000","6.64507","0.00626"
"79.92000","6.66014","0.00718"
"80.10000","6.67514","0.00667"
"80.28000","6.69003","0.00681"
"80.46000","6.70516","0.00724"
"80.64000","6.72016","0.00742"
"80.82000","6.73505","0.00745"
"81.00000","6.75018","0.00726"
"81.18000","6.76513","0.00742"
"81.36000","6.78007","0.00792"
"81.54000","6.79514","0.00797"
"81.72000","6.81009","0.00732"
"81.90000","6.82510","0.00718"
"82.08000","6.84016","0.00762"
"82.26000","6.85511","0.00759"
"82.44000","6.87012","0.00788"
"82.62000","6.88512","0.00782"
"82.80000","6.90019","0.00835"
"82.98000","6.91514","0.00768"
"83.16000","6.93015","0.00823"
"83.34000","6.94509","0.00912"
"83.52000","6.96010","0.00901"
"83.70000","6.97511","0.00883"
"83.88000","6.99011","0.00935"
"84.06000","7.00506","0.00929"
"84.24000","7.02019","0.00980"
"84.42000","7.03514","0.00952"
"84.60000","7.05008","0.00957"
"84.78000","7.06515","0.00978"
"84.96000","7.08016","0.01050"
"85.14000","7.09510","0.01024"
"85.32000","7.11011","0.01069"
"85.50000","7.12512","0.01097"
"85.68000","7.14013","0.01115"
"85.86000","7.15513","0.01090"
"86.04000","7.17008","0.01196"
"86.22000","7.18509","0.01194"
"86.40000","7.20021","0.01190"
"86.58000","7.21510","0.01254"
"86.76000","7.23011","0.01253"
"86.94000","7.24518","0.01311"
"87.12000","7.26018","0.01326"
"87.30000","7.27513","0.01346"
"87.48000","7.29014","0.01376"
"87.66000","7.30515","0.01385"
"87.84000","7.32015","0.01405"
"88.02000","7.33510","0.01486"
"88.20000","7.35011","0.01495"
"88.38000","7.36511","0.01544"
"88.56000","7.38012","0.01571"
"88.74000","7.39513","0.01602"
"88.92000","7.41014","0.01637"
"89.10000","7.42514","0.01579"
"89.28000","7.44015","0.01647"
"89.46000","7.45510","0.01657"
"89.64000","7.47010","0.01721"
"89.82000","7.48511","0.01772"
"90.00000","7.50012","0.01823"
"90.18000","7.51513","0.01857"
"90.36000","7.53001","0.01881"
"90.54000","7.54514","0.01943"
"90.72000","7.56015","0.01974"
"90.90000","7.57509","0.01987"
"91.08000","7.59010","0.02062"
"91.26000","7.60511","0.02097"
"91.44000","7.62012","0.02157"
"91.62000","7.63512","0.02107"
"91.80000","7.65013","0.02145"
"91.98000","7.66508","0.02242"
"92.16000","7.68015","0.02307"
"92.34000","7.69515","0.02316"
"92.52000","7.71010","0.02380"
"92.70000","7.72511","0.02405"
"92.88000","7.74017","0.01565"
"93.06000","7.75512","0.01653"
"93.24000","7.77013","0.01758"
"93.42000","7.78520","0.01915"
"93.60000","7.80008","0.01903"
"93.78000","7.81509","0.01900"
"93.96000","7.83016","0.01848"
"94.14000","7.84516","0.01839"
"94.32000","7.86005","0.01876"
"94.50000","7.87512","0.02033"
"94.68000","7.89013","0.02128"
"94.86000","7.90513","0.02242"
"95.04000","7.92014","0.02292"
"95.22000","7.93509","0.02236"
"95.40000","7.95009","0.02241"
"95.58000","7.96516","0.02294"
"95.76000","7.98005","0.02340"
"95.94000","7.99506","0.02512"
"96.12000","8.01012","0.02562"
"96.30000","8.02507","0.02631"
"96.48000","8.04014","0.02705"
"96.66000","8.05515","0.02521"
"96.84000","8.07009","0.02535"
"97.02000","8.08510","0.02698"
"97.20000","8.10011","0.02756"
"97.38000","8.11511","0.02899"
"97.56000","8.13012","0.02968"
"97.74000","8.14519","0.02901"
"97.92000","8.16008","0.02922"
"98.10000","8.17508","0.02779"
"98.28000","8.19015","0.02842"
"98.46000","8.20510","0.02923"
"98.64000","8.22016","0.03095"
"98.82000","8.23511","0.03157"
"99.00000","8.25012","0.03136"
"99.18000","8.26513","0.03231"
"99.36000","8.28013","0.01159"
"99.54000","8.29508","0.01400"
"99.72000","8.31015","0.01644"
"99.90000","8.32515","0.01960"
"100.08000","8.34010","0.02075"
"100.26000","8.35517","0.02000"
"100.44000","8.37012","0.01825"
"100.62000","8.38506","0.01759"
"100.80000","8.40013","0.01695"
"100.98000","8.41514","0.01866"
"101.16000","8.43014","0.02175"
"101.34000","8.44515","0.02393"
"101.52000","8.46016","0.02601"
"101.70000","8.47511","0.02597"
"101.88000","8.49011","0.02515"
"102.06000","8.50512","0.02469"
"102.24000","8.52013","0.02388"
"102.42000","8.53508","0.02510"
"102.60000","8.55020","0.02722"
"102.78000","8.56503","0.02938"
"102.96000","8.58010","0.03196"
"103.14000","8.59516","0.03271"
"103.32000","8.61017","0.03180"
"103.50000","8.62512","0.03174"
"103.68000","8.64019","0.03150"
"103.86000","8.65513","0.03300"
"104.04000","8.67014","0.03548"
"104.22000","8.68515","0.03792"
"104.40000","8.70009","0.04005"
"104.58000","8.71516","0.04039"
"104.76000","8.73017","0.04061"
"104.94000","8.74512","0.04048"
"105.12000","8.76012","0.04052"
"105.30000","8.77513","0.04231"
"105.48000","8.79014","0.04330"
"105.66000","8.80509","0.04529"
"105.84000","8.82015","0.04649"
"106.02000","8.83510","0.04742"
"106.20000","8.85017","0.04758"
"106.38000","8.86517","0.04819"
"106.56000","8.88006","0.04856"
"106.74000","8.89513","0.04952"
"106.92000","8.91020","0.05203"
"107.10000","8.92508","0.05322"
"107.28000","8.94009","0.04605"
"107.46000","8.95510","0.04730"
"107.64000","8.97010","0.04829"
"107.82000","8.98511","0.04907"
"108.00000","9.00012","0.04928"
"108.18000","9.01513","0.05004"
"108.36000","9.03013","0.05118"
"108.54000","9.04520","0.05286"
"108.72000","9.06009","0.05426"
"108.90000","9.07521","0.05587"
"109.08000","9.09010","0.05799"
"109.26000","9.10505","0.05891"
"109.44000","9.12018","0.05945"
"109.62000","9.13518","0.06147"
"109.80000","9.15007","0.06285"
"109.98000","9.16514","0.06428"
"110.16000","9.18014","0.06633"
"110.34000","9.19509","0.06765"
"110.52000","9.21016","0.06915"
"110.70000","9.22511","0.07027"
"110.88000","9.24011","0.07112"
"111.06000","9.25512","0.07215"
"111.24000","9.27013","0.07286"
"111.42000","9.28508","0.07434"
"111.60000","9.30008","0.07536"
"111.78000","9.31515","0.07730"
"111.96000","9.33010","0.07834"
"112.14000","9.34516","0.07990"
"112.32000","9.36011","0.08206"
"112.50000","9.37512","0.08331"
"112.68000","9.39013","0.08632"
"112.86000","9.40513","0.08825"
"113.04000","9.42008","0.09017"
"113.22000","9.43515","0.09152"
"113.40000","9.45015","0.09301"
"113.58000","9.46510","0.09482"
"113.76000","9.48011","0.09569"
"113.94000","9.49518","0.09673"
"114.12000","9.51012","0.09778"
"114.30000","9.52513","0.09880"
"114.48000","9.54014","0.10035"
"114.66000","9.55515","0.10144"
"114.84000","9.57021","0.10206"
"115.02000","9.58510","0.10319"
"115.20000","9.60011","0.10452"
"115.38000","9.61517","0.10544"
"115.56000","9.63012","0.10660"
"115.74000","9.64507","0.10814"
"115.92000","9.66014","0.10927"
"116.10000","9.67514","0.11111"
"116.28000","9.69009","0.11166"
"116.46000","9.70516","0.11363"
"116.64000","9.72016","0.11449"
"116.82000","9.73505","0.11642"
"117.00000","9.75012","0.11736"
"117.18000","9.76513","0.11899"
"117.36000","9.78007","0.12076"
"117.54000","9.79514","0.12204"
"117.72000","9.81015","0.12358"
"117.90000","9.82504","0.12504"
"118.08000","9.84016","0.12692"
"118.26000","9.85517","0.12851"
"118.44000","9.87006","0.13089"
"118.62000","9.88512","0.13332"
"118.80000","9.90013","0.13570"
"118.98000","9.91514","0.13966"
"119.16000","9.93014","0.14198"
"119.34000","9.94509","0.14526"
"119.52000","9.96010","0.14749"
"119.70000","9.97517","0.15005"
"119.88000","9.99011","0.15202"
"120.06000","10.00506","0.15347"
"120.24000","10.02013","0.15488"
"120.42000","10.03514","0.15689"
"120.60000","10.05008","0.15970"
"120.78000","10.06515","0.16128"
"120.96000","10.08016","0.16498"
"121.14000","10.09510","0.16723"
"121.32000","10.11017","0.16932"
"121.50000","10.12512","0.17258"
"121.68000","10.14012","0.17397"
"121.86000","10.15513","0.17617"
"122.04000","10.17014","0.17765"
"122.22000","10.18503","0.17892"
"122.40000","10.20015","0.18121"
"122.58000","10.21516","0.18300"
"122.76000","10.23011","0.18369"
"122.94000","10.24518","0.18476"
"123.12000","10.26018","0.18672"
"123.30000","10.27513","0.18862"
"123.48000","10.29014","0.19058"
"123.66000","10.30509","0.19225"
"123.84000","10.32009","0.19410"
"124.02000","10.33522","0.19591"
"124.20000","10.35005","0.19789"
"124.38000","10.36505","0.19982"
"124.56000","10.38012","0.20221"
"124.74000","10.39507","0.20451"
"124.92000","10.41007","0.20592"
"125.10000","10.42514","0.20766"
"125.28000","10.44009","0.20974"
"125.46000","10.45510","0.21152"
"125.64000","10.47010","0.21299"
"125.82000","10.48511","0.21444"
"126.00000","10.50012","0.21555"
"126.18000","10.51513","0.21691"
"126.36000","10.53007","0.21818"
"126.54000","10.54508","0.22068"
"126.72000","10.56021","0.22218"
"126.90000","10.57515","0.22482"
"127.08000","10.59004","0.22629"
"127.26000","10.60517","0.22814"
"127.44000","10.62018","0.23053"
"127.62000","10.63506","0.23203"
"127.80000","10.65013","0.23347"
"127.98000","10.66514","0.23635"
"128.16000","10.68014","0.23854"
"128.34000","10.69515","0.24096"
"128.52000","10.71016","0.24394"
"128.70000","10.72511","0.24621"
"128.88000","10.74017","0.24894"
"129.06000","10.75518","0.25108"
"129.24000","10.77013","0.25389"
"129.42000","10.78520","0.25541"
"129.60000","10.80014","0.25808"
"129.78000","10.81509","0.26039"
"129.96000","10.83016","0.26275"
"130.14000","10.84516","0.26518"
"130.32000","10.86011","0.26885"
"130.50000","10.87512","0.27040"
"130.68000","10.89012","0.27324"
"130.86000","10.90513","0.27523"
"131.04000","10.92020","0.27772"
"131.22000","10.93515","0.28014"
"131.40000","10.95009","0.28215"
"131.58000","10.96516","0.28559"
"131.76000","10.98011","0.28893"
"131.94000","10.99506","0.29310"
"132.12000","11.01012","0.29665"
"132.30000","11.02513","0.30022"
"132.48000","11.04008","0.30270"
"132.66000","11.05514","0.30504"
"132.84000","11.07009","0.30722"
"133.02000","11.08510","0.30881"
"133.20000","11.10011","0.31047"
"133.38000","11.11505","0.31272"
"133.56000","11.13012","0.31449"
"133.74000","11.14519","0.31602"
"133.92000","11.16014","0.31642"
"134.10000","11.17508","0.31493"
"134.28000","11.19015","0.31626"
"134.46000","11.20516","0.12876"
"134.64000","11.22010","0.11500"
"134.82000","11.23511","0.11248"
"135.00000","11.25006","0.11906"
"135.18000","11.26513","0.11519"
"135.36000","11.28013","0.11664"
"135.54000","11.29514","0.11236"
"135.72000","11.31009","0.11525"
"135.90000","11.32521","0.11527"
"136.08000","11.34016","0.11665"
"136.26000","11.35505","0.11821"
"136.44000","11.37017","0.12094"
"136.62000","11.38512","0.12279"
"136.80000","11.40013","0.12480"
"136.98000","11.41514","0.12230"
"137.16000","11.43014","0.12432"
"137.34000","11.44515","0.12630"
"137.52000","11.46016","0.12797"
"137.70000","11.47511","0.13356"
"137.88000","11.49011","0.13415"
"138.06000","11.50512","0.14063"
"138.24000","11.52013","0.14380"
"138.42000","11.53507","0.14286"
"138.60000","11.55014","0.14668"
"138.78000","11.56515","0.14480"
"138.96000","11.58010","0.14960"
"139.14000","11.59510","0.15075"
"139.32000","11.61011","0.15189"
"139.50000","11.62512","0.15678"
"139.68000","11.64013","0.15518"
"139.86000","11.65513","0.15994"
"140.04000","11.67014","0.15730"
"140.22000","11.68509","0.15991"
"140.40000","11.70015","0.16185"
"140.58000","11.71510","0.16296"
"140.76000","11.73017","0.09370"
"140.94000","11.74518","0.05356"
"141.12000","11.76006","0.06438"
"141.30000","11.77507","0.06933"
"141.48000","11.79008","0.05888"
"141.66000","11.80515","0.06961"
"141.84000","11.82015","0.06928"
"142.02000","11.83510","0.06260"
"142.20000","11.85011","0.07410"
"142.38000","11.86517","0.06723"
"142.56000","11.88012","0.07289"
"142.74000","11.89513","0.07423"
"142.92000","11.91014","0.07382"
"143.10000","11.92514","0.08215"
"143.28000","11.94009","0.07942"
"143.46000","11.95510","0.07888"
"143.64000","11.97010","0.08863"
"143.82000","11.98511","0.08045"
"144.00000","12.00012","0.08862"
"144.18000","12.01512","0.08849"
"144.36000","12.03013","0.08845"
"144.54000","12.04514","0.09568"
"144.72000","12.06009","0.09270"
"144.90000","12.07509","0.09773"
"145.08000","12.09022","0.09573"
"145.26000","12.10511","0.09595"
"145.44000","12.12012","0.09977"
"145.62000","12.13512","0.09794"
"145.80000","12.15007","0.09993"
"145.98000","12.16508","0.10136"
"146.16000","12.18014","0.10111"
"146.34000","12.19509","0.10567"
"146.52000","12.21010","0.10365"
"146.70000","12.22517","0.10744"
"146.88000","12.24011","0.10794"
"147.06000","12.25512","0.10813"
"147.24000","12.27019","0.11161"
"147.42000","12.28508","0.10988"
"147.60000","12.30008","0.11486"
"147.78000","12.31509","0.11363"
"147.96000","12.33010","0.11674"
"148.14000","12.34510","0.11884"
"148.32000","12.36011","0.11832"
"148.50000","12.37512","0.12272"
"148.68000","12.39012","0.12097"
"148.86000","12.40513","0.12500"
"149.04000","12.42008","0.12414"
"149.22000","12.43515","0.12634"
"149.40000","12.45015","0.03588"
"149.58000","12.46510","0.03088"
"149.76000","12.48011","0.03585"
"149.94000","12.49512","0.03149"
"150.12000","12.51012","0.04280"
"150.30000","12.52513","0.03442"
"150.48000","12.54014","0.04343"
"150.66000","12.55509","0.04008"
"150.84000","12.57009","0.04157"
"151.02000","12.58516","0.04360"
"151.20000","12.60011","0.04382"
"151.38000","12.61517","0.04585"
"151.56000","12.63018","0.04862"
"151.74000","12.64507","0.04902"
"151.92000","12.66013","0.05118"
"152.10000","12.67514","0.05233"
"152.28000","12.69015","0.05197"
"152.46000","12.70510","0.05689"
"152.64000","12.72016","0.05420"
"152.82000","12.73511","0.05876"
"153.00000","12.75012","0.05886"
"153.18000","12.76519","0.06137"
"153.36000","12.78013","0.06471"
"153.54000","12.79514","0.06450"
"153.72000","12.81015","0.06830"
"153.90000","12.82515","0.06943"
"154.08000","12.84010","0.06918"
"154.26000","12.85517","0.07221"
"154.44000","12.87012","0.07169"
"154.62000","12.88512","0.07420"
"154.80000","12.90019","0.07417"
"154.98000","12.91514","0.07559"
"155.16000","12.93014","0.07853"
"155.34000","12.94515","0.07914"
"155.52000","12.96010","0.08223"
"155.70000","12.97517","0.08367"
"155.88000","12.99017","0.08540"
"156.06000","13.00512","0.08767"
"156.24000","13.02013","0.08781"
"156.42000","13.03514","0.09107"
"156.60000","13.05008","0.09148"
"156.78000","13.06509","0.09337"
"156.96000","13.08016","0.09460"
"157.14000","13.09516","0.09544"
"157.32000","13.11017","0.09677"
"157.50000","13.12512","0.09723"
"157.68000","13.14012","0.09943"
"157.86000","13.15513","0.09947"
"158.04000","13.17014","0.10034"
"158.22000","13.18509","0.10178"
"158.40000","13.20015","0.10213"
"158.58000","13.21510","0.10357"
"158.76000","13.23011","0.10367"
"158.94000","13.24512","0.10563"
"159.12000","13.26018","0.10628"
"159.30000","13.27513","0.10821"
"159.48000","13.29014","0.10943"
"159.66000","13.30514","0.11066"
"159.84000","13.32009","0.11275"
"160.02000","13.33516","0.11394"
"160.20000","13.35011","0.11577"
"160.38000","13.36505","0.11628"
"160.56000","13.38012","0.11891"
"160.74000","13.39513","0.11987"
"160.92000","13.41013","0.12196"
"161.10000","13.42514","0.12308"
"161.28000","13.44015","0.12458"
"161.46000","13.45510","0.12577"
"161.64000","13.47016","0.12747"
"161.82000","13.48511","0.13038"
"162.00000","13.50012","0.13219"
"162.18000","13.51519","0.13632"
"162.36000","13.53019","0.13886"
"162.54000","13.54508","0.14229"
"162.72000","13.56015","0.14447"
"162.90000","13.57515","0.14754"
"163.08000","13.59004","0.14955"
"163.26000","13.60511","0.15174"
"163.44000","13.62018","0.15328"
"163.62000","13.63506","0.15462"
"163.80000","13.65013","0.15687"
"163.98000","13.66514","0.15886"
"164.16000","13.68008","0.16134"
"164.34000","13.69515","0.16325"
"164.52000","13.71016","0.16748"
"164.70000","13.72511","0.16930"
"164.88000","13.74011","0.17288"
"165.06000","13.75518","0.17449"
"165.24000","13.77007","0.17654"
"165.42000","13.78513","0.17795"
"165.60000","13.80014","0.17950"
"165.78000","13.81509","0.18077"
"165.96000","13.83016","0.18321"
"166.14000","13.84510","0.18487"
"166.32000","13.86011","0.18698"
"166.50000","13.87518","0.18859"
"166.68000","13.89013","0.16088"
"166.86000","13.90507","0.15718"
"167.04000","13.92020","0.16011"
"167.22000","13.93509","0.16079"
"167.40000","13.95009","0.16413"
"167.58000","13.96516","0.16711"
"167.76000","13.98011","0.16939"
"167.94000","13.99512","0.17218"
"168.12000","14.01012","0.17470"
"168.30000","14.02513","0.17710"
"168.48000","14.04008","0.17851"
"168.66000","14.05514","0.18096"
"168.84000","14.07015","0.18253"
"169.02000","14.08504","0.18473"
"169.20000","14.10017","0.18692"
"169.38000","14.11511","0.18882"
"169.56000","14.13006","0.19104"
"169.74000","14.14519","0.19328"
"169.92000","14.16020","0.19527"
"170.10000","14.17508","0.19757"
"170.28000","14.19015","0.19931"
"170.46000","14.20516","0.20163"
"170.64000","14.22010","0.20275"
"170.82000","14.23517","0.20474"
"171.00000","14.25012","0.20717"
"171.18000","14.26512","0.20875"
"171.36000","14.28013","0.20999"
"171.54000","14.29508","0.21177"
"171.72000","14.31003","0.21289"
"171.90000","14.32521","0.21463"
"172.08000","14.34016","0.21567"
"172.26000","14.35511","0.21699"
"172.44000","14.37012","0.21913"
"172.62000","14.38518","0.22101"
"172.80000","14.40013","0.22290"
"172.98000","14.41514","0.22493"
"173.16000","14.43015","0.22716"
"173.34000","14.44509","0.22850"
"173.52000","14.46010","0.23039"
"173.70000","14.47511","0.23197"
"173.88000","14.49005","0.23392"
"174.06000","14.50518","0.23595"
"174.24000","14.52013","0.23890"
"174.42000","14.53508","0.24026"
"174.60000","14.55014","0.24341"
"174.78000","14.56515","0.24302"
"174.96000","14.58010","0.20981"
"175.14000","14.59516","0.21182"
"175.32000","14.61011","0.21312"
"175.50000","14.62512","0.21455"
"175.68000","14.64019","0.21635"
"175.86000","14.65507","0.21728"
"176.04000","14.67008","0.21858"
"176.22000","14.68515","0.22036"
"176.40000","14.70009","0.22216"
"176.58000","14.71510","0.22432"
"176.76000","14.73011","0.22695"
"176.94000","14.74518","0.22902"
"177.12000","14.76012","0.23048"
"177.30000","14.77513","0.23235"
"177.48000","14.79014","0.23409"
"177.66000","14.80509","0.23612"
"177.84000","14.82015","0.23762"
"178.02000","14.83510","0.24021"
"178.20000","14.85005","0.24248"
"178.38000","14.86517","0.24533"
"178.56000","14.88012","0.24703"
"178.74000","14.89507","0.24992"
"178.92000","14.91020","0.25124"
"179.10000","14.92514","0.25277"
"179.28000","14.94009","0.25455"
"179.46000","14.95516","0.25713"
"179.64000","14.97016","0.25969"
"179.82000","14.98511","0.26109"
"180.00000","15.00012","0.26328"
"180.18000","15.01507","0.26618"
"180.36000","15.03007","0.26883"
"180.54000","15.04520","0.27065"
"180.72000","15.06015","0.09664"
"180.90000","15.07503","0.08819"
"181.08000","15.09016","0.06089"
"181.26000","15.10517","0.03426"
"181.44000","15.12012","0.02792"
"181.62000","15.13512","0.04802"
"181.80000","15.15013","0.04074"
"181.98000","15.16508","0.03052"
"182.16000","15.18014","0.04991"
"182.34000","15.19509","0.02494"
"182.52000","15.21010","0.04633"
"182.70000","15.22517","0.03408"
"182.88000","15.24011","0.03824"
"183.06000","15.25506","0.05004"
"183.24000","15.27019","0.03340"
"183.42000","15.28514","0.05094"
"183.60000","15.30008","0.04772"
"183.78000","15.31515","0.04934"
"183.96000","15.33016","0.05602"
"184.14000","15.34510","0.04152"
"184.32000","15.36011","0.05625"
"184.50000","15.37506","0.05373"
"184.68000","15.39013","0.04623"
"184.86000","15.40513","0.06207"
"185.04000","15.42008","0.05152"
"185.22000","15.43509","0.05706"
"185.40000","15.45015","0.06562"
"185.58000","15.46516","0.05463"
"185.76000","15.48011","0.06854"
"185.94000","15.49512","0.06888"
"186.12000","15.51018","0.06089"
"186.30000","15.52513","0.07282"
"186.48000","15.54014","0.07236"
"186.66000","15.55508","0.06706"
"186.84000","15.57015","0.07591"
"187.02000","15.58516","0.07489"
"187.20000","15.60011","0.07115"
"187.38000","15.61505","0.08089"
"187.56000","15.63018","0.07916"
"187.74000","15.64513","0.07567"
"187.92000","15.66007","0.08627"
"188.10000","15.67520","0.08617"
"188.28000","15.69015","0.08270"
"188.46000","15.70504","0.08810"
"188.64000","15.72010","0.09210"
"188.82000","15.73511","0.09156"
"189.00000","15.75012","0.09068"
"189.18000","15.76513","0.09541"
"189.36000","15.78013","0.09731"
"189.54000","15.79508","0.09441"
"189.72000","15.81015","0.09724"
"189.90000","15.82515","0.10254"
"190.08000","15.84010","0.09820"
"190.26000","15.85517","0.09938"
"190.44000","15.87011","0.10442"
"190.62000","15.88512","0.10200"
"190.80000","15.90007","0.10309"
"190.98000","15.91514","0.10432"
"191.16000","15.93014","0.10584"
"191.34000","15.94515","0.10885"
"191.52000","15.96010","0.10664"
"191.70000","15.97510","0.10839"
"191.88000","15.99017","0.11537"
"192.06000","16.00512","0.11223"
"192.24000","16.02007","0.11422"
"192.42000","16.03513","0.11680"
"192.60000","16.05014","0.11709"
"192.78000","16.06509","0.12170"
"192.96000","16.08016","0.11847"
"193.14000","16.09510","0.12092"
"193.32000","16.11011","0.12590"
"193.50000","16.12512","0.12440"
"193.68000","16.14012","0.12862"
"193.86000","16.15513","0.12748"
"194.04000","16.17014","0.12946"
"194.22000","16.18509","0.13850"
"194.40000","16.20009","0.13505"
"194.58000","16.21516","0.14052"
"194.76000","16.23011","0.14127"
"194.94000","16.24512","0.14285"
"195.12000","16.26012","0.15054"
"195.30000","16.27513","0.14813"
"195.48000","16.29014","0.15222"
"195.66000","16.30514","0.15236"
"195.84000","16.32009","0.15391"
"196.02000","16.33516","0.15850"
"196.20000","16.35011","0.15691"
"196.38000","16.36511","0.16239"
"196.56000","16.38012","0.16125"
"196.74000","16.39519","0.16362"
"196.92000","16.41014","0.16931"
"197.10000","16.42514","0.16897"
"197.28000","16.44015","0.17572"
"197.46000","16.45510","0.17316"
"197.64000","16.47010","0.17688"
"197.82000","16.48517","0.17822"
"198.00000","16.50012","0.17913"
"198.18000","16.51513","0.18289"
"198.36000","16.53013","0.18126"
"198.54000","16.54514","0.18538"
"198.72000","16.56009","0.18498"
"198.90000","16.57515","0.18799"
"199.08000","16.59016","0.19034"
"199.26000","16.60505","0.19110"
"199.44000","16.62012","0.19568"
"199.62000","16.63512","0.19515"
"199.80000","16.65013","0.19908"
"199.98000","16.66514","0.19915"
"200.16000","16.68014","0.20221"
"200.34000","16.69515","0.20321"
"200.52000","16.71016","0.20543"
"200.70000","16.72510","0.20776"
"200.88000","16.74017","0.20844"
"201.06000","16.75518","0.21187"
"201.24000","16.77013","0.21144"
"201.42000","16.78513","0.21373"
"201.60000","16.80014","0.21415"
"201.78000","16.81515","0.21610"
"201.96000","16.83010","0.21761"
"202.14000","16.84516","0.21876"
"202.32000","16.86011","0.22119"
"202.50000","16.87512","0.22217"
"202.68000","16.89018","0.22489"
"202.86000","16.90507","0.22584"
"203.04000","16.92014","0.22900"
"203.22000","16.93515","0.22893"
"203.40000","16.95009","0.23215"
"203.58000","16.96510","0.23250"
"203.76000","16.98017","0.23505"
"203.94000","16.99506","0.23613"
"204.12000","17.01012","0.23947"
"204.30000","17.02513","0.24025"
"204.48000","17.04008","0.24238"
"204.66000","17.05514","0.22079"
"204.84000","17.07015","0.22024"
"205.02000","17.08510","0.22189"
"205.20000","17.10011","0.22337"
"205.38000","17.11517","0.22548"
"205.56000","17.13012","0.22677"
"205.74000","17.14513","0.22954"
"205.92000","17.16014","0.23017"
"206.10000","17.17508","0.23241"
"206.28000","17.19009","0.23175"
"206.46000","17.20515","0.10286"
"206.64000","17.22010","0.10430"
"206.82000","17.23517","0.10343"
"207.00000","17.25012","0.11150"
"207.18000","17.26512","0.11105"
"207.36000","17.28013","0.11950"
"207.54000","17.29514","0.11751"
"207.72000","17.31009","0.12474"
"207.90000","17.32509","0.11969"
"208.08000","17.34016","0.12498"
"208.26000","17.35505","0.12513"
"208.44000","17.37011","0.12661"
"208.62000","17.38512","0.13783"
"208.80000","17.40013","0.13356"
"208.98000","17.41514","0.12876"
"209.16000","17.43008","0.12508"
"209.34000","17.44515","0.13041"
"209.52000","17.46016","0.13535"
"209.70000","17.47517","0.13690"
"209.88000","17.49011","0.14163"
"210.06000","17.50518","0.14468"
"210.24000","17.52013","0.14689"
"210.42000","17.53513","0.15041"
"210.60000","17.55014","0.15224"
"210.78000","17.56515","0.15510"
"210.96000","17.58015","0.15902"
"211.14000","17.59510","0.16222"
"211.32000","17.61017","0.16815"
"211.50000","17.62506","0.17086"
"211.68000","17.64018","0.17482"
"211.86000","17.65513","0.17649"
"212.04000","17.67008","0.17861"
"212.22000","17.68514","0.18026"
"212.40000","17.70015","0.18163"
"212.58000","17.71510","0.18395"
"212.76000","17.73017","0.18568"
"212.94000","17.74517","0.18960"
"213.12000","17.76012","0.19186"
"213.30000","17.77513","0.19534"
"213.48000","17.79014","0.19730"
"213.66000","17.80508","0.09780"
"213.84000","17.82015","0.10135"
"214.02000","17.83516","0.10445"
"214.20000","17.85011","0.10298"
"214.38000","17.86511","0.10423"
"214.56000","17.88012","0.10753"
"214.74000","17.89507","0.10791"
"214.92000","17.91007","0.11018"
"215.10000","17.92520","0.11090"
"215.28000","17.94009","0.11141"
"215.46000","17.95516","0.11530"
"215.64000","17.97010","0.11501"
"215.82000","17.98511","0.11629"
"216.00000","18.00012","0.12068"
"216.18000","18.01512","0.12034"
"216.36000","18.03007","0.12216"
"216.54000","18.04514","0.12498"
"216.72000","18.06009","0.12457"
"216.90000","18.07503","0.12788"
"217.08000","18.09016","0.12916"
"217.26000","18.10517","0.13007"
"217.44000","18.12012","0.13380"
"217.62000","18.13518","0.13408"
"217.80000","18.15013","0.13905"
"217.98000","18.16508","0.14001"
"218.16000","18.18014","0.14368"
"218.34000","18.19515","0.14720"
"218.52000","18.21010","0.14634"
"218.70000","18.22523","0.13132"
"218.88000","18.24011","0.13269"
"219.06000","18.25506","0.13564"
"219.24000","18.27013","0.13957"
"219.42000","18.28519","0.13788"
"219.60000","18.30008","0.14258"
"219.78000","18.31515","0.14412"
"219.96000","18.33022","0.14554"
"220.14000","18.34510","0.14923"
"220.32000","18.36017","0.14945"
"220.50000","18.37518","0.15150"
"220.68000","18.39006","0.15265"
"220.86000","18.40519","0.15332"
"221.04000","18.42014","0.15542"
"221.22000","18.43503","0.15651"
"221.40000","18.45015","0.15792"
"221.58000","18.46516","0.15931"
"221.76000","18.48011","0.15978"
"221.94000","18.49517","0.16266"
"222.12000","18.51018","0.16395"
"222.30000","18.52507","0.16695"
"222.48000","18.54020","0.16884"
"222.66000","18.55514","0.00110"
"222.84000","18.57009","0.05385"
"223.02000","18.58516","0.00327"
"223.20000","18.60017","0.00490"
"223.38000","18.61511","0.02449"
"223.56000","18.63018","0.01923"
"223.74000","18.64519","0.00672"
"223.92000","18.66007","0.01817"
"224.10000","18.67514","0.03174"
"224.28000","18.69015","0.00801"
"224.46000","18.70510","0.01125"
"224.64000","18.72010","0.03550"
"224.82000","18.73511","0.00906"
"225.00000","18.75012","0.02013"
"225.18000","18.76512","0.02740"
"225.36000","18.78013","0.01500"
"225.54000","18.79508","0.01698"
"225.72000","18.81015","0.02846"
"225.90000","18.82515","0.01354"
"226.08000","18.84010","0.02427"
"226.26000","18.85511","0.02303"
"226.44000","18.87012","0.02493"
"226.62000","18.88512","0.02478"
"226.80000","18.90013","0.02626"
"226.98000","18.91514","0.02071"
"227.16000","18.93008","0.03217"
"227.34000","18.94515","0.02384"
"227.52000","18.96010","0.02639"
"227.70000","18.97505","0.02575"
"227.88000","18.99017","0.03052"
"228.06000","19.00512","0.02702"
"228.24000","19.02007","0.02822"
"228.42000","19.03514","0.02923"
"228.60000","19.05020","0.03517"
"228.78000","19.06509","0.02803"
"228.96000","19.08010","0.03288"
"229.14000","19.09516","0.03217"
"229.32000","19.11011","0.03633"
"229.50000","19.12518","0.03397"
"229.68000","19.14018","0.03109"
"229.86000","19.15507","0.03989"
"230.04000","19.17020","0.03698"
"230.22000","19.18515","0.03494"
"230.40000","19.20004","0.04067"
"230.58000","19.21516","0.04026"
"230.76000","19.23017","0.03796"
"230.94000","19.24505","0.03996"
"231.12000","19.26018","0.04005"
"231.30000","19.27513","0.04520"
"231.48000","19.29014","0.03999"
"231.66000","19.30514","0.04129"
"231.84000","19.32009","0.04892"
"232.02000","19.33510","0.04289"
"232.20000","19.35017","0.04647"
"232.38000","19.36511","0.04901"
"232.56000","19.38006","0.04821"
"232.74000","19.39519","0.04909"
"232.92000","19.41013","0.04963"
"233.10000","19.42508","0.05448"
"233.28000","19.44015","0.05102"
"233.46000","19.45510","0.05191"
"233.64000","19.47010","0.05921"
"233.82000","19.48511","0.05459"
"234.00000","19.50012","0.05583"
"234.18000","19.51507","0.06170"
"234.36000","19.53013","0.06039"
"234.54000","19.54514","0.06065"
"234.72000","19.56009","0.06404"
"234.90000","19.57515","0.06712"
"235.08000","19.59016","0.06460"
"235.26000","19.60511","0.06741"
"235.44000","19.62012","0.07102"
"235.62000","19.63512","0.06799"
"235.80000","19.65013","0.07118"
"235.98000","19.66514","0.07273"
"236.16000","19.68008","0.07141"
"236.34000","19.69515","0.07419"
"236.52000","19.71016","0.07557"
"236.70000","19.72511","0.07541"
"236.88000","19.74011","0.07683"
"237.06000","19.75518","0.08017"
"237.24000","19.77013","0.07868"
"237.42000","19.78507","0.08039"
"237.60000","19.80014","0.08606"
"237.78000","19.81515","0.08277"
"237.96000","19.83016","0.08732"
"238.14000","19.84510","0.08917"
"238.32000","19.86011","0.08822"
"238.50000","19.87511","0.09064"
"238.68000","19.89012","0.09296"
"238.86000","19.90513","0.09287"
"239.04000","19.92008","0.09418"
"239.22000","19.93515","0.09593"
"239.40000","19.95015","0.09496"
"239.58000","19.96504","0.09714"
"239.76000","19.98017","0.09830"
"239.94000","19.99517","0.09751"
"240.12000","20.01006","0.09964"
"240.30000","20.02513","0.09986"
"240.48000","20.04008","0.10015"
"240.66000","20.05508","0.10172"
"240.84000","20.07015","0.10240"
"241.02000","20.08510","0.10280"
"241.20000","20.10010","0.10442"
"241.38000","20.11511","0.10465"
"241.56000","20.13012","0.10514"
"241.74000","20.14507","0.10717"
"241.92000","20.16014","0.10680"
"242.10000","20.17514","0.10881"
"242.28000","20.19009","0.10978"
"242.46000","20.20510","0.10974"
"242.64000","20.22010","0.05683"
"242.82000","20.23511","0.05887"
"243.00000","20.25018","0.05966"
"243.18000","20.26513","0.05531"
"243.36000","20.28013","0.04705"
"243.54000","20.29514","0.04817"
"243.72000","20.31009","0.04502"
"243.90000","20.32509","0.04537"
"244.08000","20.34016","0.04712"
"244.26000","20.35517","0.04824"
"244.44000","20.37011","0.04767"
"244.62000","20.38512","0.04776"
"244.80000","20.40013","0.05019"
"244.98000","20.41508","0.04945"
"245.16000","20.43014","0.04917"
"245.34000","20.44509","0.05136"
"245.52000","20.46016","0.05221"
"245.70000","20.47517","0.05130"
"245.88000","20.49005","0.05230"
"246.06000","20.50512","0.05388"
"246.24000","20.52013","0.05364"
"246.42000","20.53507","0.05428"
"246.60000","20.55014","0.05614"
"246.78000","20.56515","0.05678"
"246.96000","20.58010","0.05644"
"247.14000","20.59510","0.05752"
"247.32000","20.61011","0.05946"
"247.50000","20.62506","0.05836"
"247.68000","20.64018","0.05974"
"247.86000","20.65513","0.06173"
"248.04000","20.67008","0.06097"
"248.22000","20.68509","0.06164"
"248.40000","20.70021","0.06337"
"248.58000","20.71510","0.06366"
"248.76000","20.73011","0.06335"
"248.94000","20.74512","0.06554"
"249.12000","20.76012","0.06636"
"249.30000","20.77507","0.06553"
"249.48000","20.79014","0.06694"
"249.66000","20.80508","0.06815"
"249.84000","20.82015","0.06827"
"250.02000","20.83516","0.06879"
"250.20000","20.85011","0.07009"
"250.38000","20.86511","0.07069"
"250.56000","20.88012","0.07069"
"250.74000","20.89513","0.07152"
"250.92000","20.91007","0.07174"
"251.10000","20.92514","0.07206"
"251.28000","20.94009","0.07297"
"251.46000","20.95510","0.07363"
"251.64000","20.97010","0.07400"
"251.82000","20.98511","0.07424"
"252.00000","21.00011","0.07524"
"252.18000","21.01513","0.07489"
"252.36000","21.03013","0.07597"
"252.54000","21.04514","0.07684"
"252.72000","21.06015","0.07716"
"252.90000","21.07509","0.07806"
"253.08000","21.09010","0.07937"
"253.26000","21.10511","0.07932"
"253.44000","21.12011","0.07969"
"253.62000","21.13512","0.08141"
"253.80000","21.15013","0.08272"
"253.98000","21.16508","0.08227"
"254.16000","21.18008","0.08479"
"254.34000","21.19521","0.08443"
"254.52000","21.21010","0.08479"
"254.70000","21.22517","0.08706"
"254.88000","21.24017","0.08812"
"255.06000","21.25506","0.08851"
"255.24000","21.27012","0.08951"
"255.42000","21.28513","0.09043"
"255.60000","21.30014","0.09054"
"255.78000","21.31515","0.09159"
"255.96000","21.33016","0.08071"
"256.14000","21.34510","0.01862"
"256.32000","21.36017","0.03373"
"256.50000","21.37518","0.00997"
"256.68000","21.39013","0.01113"
"256.86000","21.40519","0.02252"
"257.04000","21.42020","0.02584"
"257.22000","21.43509","0.00889"
"257.40000","21.45009","0.00967"
"257.58000","21.46516","0.02437"
"257.76000","21.48011","0.01808"
"257.94000","21.49517","0.01331"
"258.12000","21.51018","0.01817"
"258.30000","21.52513","0.02666"
"258.48000","21.54013","0.01714"
"258.66000","21.55515","0.01341"
"258.84000","21.57009","0.02329"
"259.02000","21.58516","0.02142"
"259.20000","21.60016","0.01783"
"259.38000","21.61511","0.01923"
"259.56000","21.63012","0.02689"
"259.74000","21.64513","0.01945"
"259.92000","21.66007","0.01910"
"260.10000","21.67514","0.02466"
"260.28000","21.69015","0.02441"
"260.46000","21.70510","0.02126"
"260.64000","21.72004","0.02394"
"260.82000","21.73511","0.02787"
"261.00000","21.75012","0.02267"
"261.12800","21.76076","0.02399"