File: Force_trajectories/161223_2/Specimen_RawData_3.csv
End date,"12/23/2016"
Specimen label,"21AT_67"
Maximum Load,"0.37712",N

Time,Extension,Load
(s),(mm),(N)
"0.00000","0.00000","-0.00014"
"0.25200","0.01973","0.00004"
"0.50400","0.04221","0.00006"
"0.75600","0.06320","-0.00005"
"1.00800","0.08424","-0.00014"
"1.26000","0.10523","0.00031"
"1.51200","0.12628","-0.00013"
"1.76400","0.14714","0.00019"
"2.01600","0.16819","0.00005"
"2.26800","0.18911","0.00026"
"2.52000","0.21016","0.00025"
"2.77200","0.23109","0.00042"
"3.02400","0.25219","0.00038"
"3.27600","0.27318","0.00070"
"3.52800","0.29422","0.00010"
"3.78000","0.31515","0.00001"
"4.03200","0.33626","0.00053"
"4.28400","0.35724","0.00082"
"4.53600","0.37811","0.00023"
"4.78800","0.39915","0.00049"
"5.04000","0.42014","0.00006"
"5.29200","0.44125","0.00069"
"5.54400","0.46217","0.00051"
"5.79600","0.48322","0.00042"
"6.04800","0.50415","0.00084"
"6.30000","0.52525","0.00054"
"6.55200","0.54612","0.00062"
"6.80400","0.56716","0.00108"
"7.05600","0.58815","0.00066"
"7.30800","0.60926","0.00061"
"7.56000","0.63018","0.00090"
"7.81200","0.65117","0.00073"
"8.06400","0.67215","0.00092"
"8.31600","0.69320","0.00057"
"8.56800","0.71419","0.00088"
"8.82000","0.73517","0.00076"
"9.07200","0.75622","0.00086"
"9.32400","0.77720","0.00091"
"9.57600","0.79819","0.00122"
"9.82800","0.81912","0.00089"
"10.08000","0.84016","0.00093"
"10.33200","0.86121","0.00129"
"10.58400","0.88219","0.00075"
"10.83600","0.90318","0.00096"
"11.08800","0.92417","0.00126"
"11.34000","0.94515","0.00101"
"11.59200","0.96626","0.00099"
"11.84400","0.98718","0.00123"
"12.09600","1.00823","0.00094"
"12.34800","1.02928","0.00128"
"12.60000","1.05020","0.00120"
"12.85200","1.07119","0.00087"
"13.10400","1.09218","0.00105"
"13.35600","1.11316","0.00149"
"13.60800","1.13415","0.00139"
"13.86000","1.15519","0.00137"
"14.11200","1.17612","0.00124"
"14.36400","1.19723","0.00116"
"14.61600","1.21815","0.00161"
"14.86800","1.23914","0.00131"
"15.12000","1.26018","0.00128"
"15.37200","1.28123","0.00109"
"15.62400","1.30216","0.00158"
"15.87600","1.32320","0.00150"
"16.12800","1.34419","0.00144"
"16.38000","1.36517","0.00123"
"16.63200","1.38622","0.00094"
"16.88400","1.40715","0.00071"
"17.13600","1.42825","0.00100"
"17.38800","1.44918","0.00101"
"17.64000","1.47022","0.00113"
"17.89200","1.49115","0.00139"
"18.14400","1.51220","0.00108"
"18.39600","1.53318","0.00155"
"18.64800","1.55423","0.00116"
"18.90000","1.57516","0.00134"
"19.15200","1.59620","0.00138"
"19.40400","1.61719","0.00151"
"19.65600","1.63823","0.00131"
"19.90800","1.65916","0.00129"
"20.16000","1.68021","0.00178"
"20.41200","1.70119","0.00156"
"20.66400","1.72218","0.00172"
"20.91600","1.74322","0.00193"
"21.16800","1.76415","0.00135"
"21.42000","1.78526","0.00162"
"21.67200","1.80618","0.00192"
"21.92400","1.82717","0.00176"
"22.17600","1.84815","0.00209"
"22.42800","1.86926","0.00164"
"22.68000","1.89019","0.00171"
"22.93200","1.91123","0.00219"
"23.18400","1.93216","0.00196"
"23.43600","1.95320","0.00154"
"23.68800","1.97425","0.00223"
"23.94000","1.99518","0.00193"
"24.19200","2.01616","0.00171"
"24.44400","2.03715","0.00161"
"24.69600","2.05819","0.00188"
"24.94800","2.07918","0.00221"
"25.20000","2.10017","0.00179"
"25.45200","2.12115","0.00220"
"25.70400","2.14220","0.00184"
"25.95600","2.16313","0.00227"
"26.20800","2.18417","0.00230"
"26.46000","2.20516","0.00198"
"26.71200","2.22620","0.00253"
"26.96400","2.24719","0.00235"
"27.21600","2.26818","0.00207"
"27.46800","2.28910","0.00221"
"27.72000","2.31021","0.00232"
"27.97200","2.33125","0.00222"
"28.22400","2.35224","0.00252"
"28.47600","2.37317","0.00200"
"28.72800","2.39415","0.00252"
"28.98000","2.41526","0.00198"
"29.23200","2.43618","0.00209"
"29.48400","2.45723","0.00225"
"29.73600","2.47816","0.00226"
"29.98800","2.49920","0.00248"
"30.24000","2.52019","0.00230"
"30.49200","2.54117","0.00230"
"30.74400","2.56210","0.00282"
"30.99600","2.58327","0.00242"
"31.24800","2.60413","0.00290"
"31.50000","2.62518","0.00253"
"31.75200","2.64616","0.00312"
"32.00400","2.66721","0.00257"
"32.25600","2.68820","0.00255"
"32.50800","2.70918","0.00256"
"32.76000","2.73017","0.00266"
"33.01200","2.75122","0.00280"
"33.26400","2.77220","0.00304"
"33.51600","2.79313","0.00181"
"33.76800","2.81423","0.00227"
"34.02000","2.83516","0.00212"
"34.27200","2.85621","0.00229"
"34.52400","2.87713","0.00218"
"34.77600","2.89818","0.00211"
"35.02800","2.91916","0.00214"
"35.28000","2.94027","0.00284"
"35.53200","2.96114","0.00289"
"35.78400","2.98218","0.00240"
"36.03600","3.00323","0.00243"
"36.28800","3.02421","0.00259"
"36.54000","3.04520","0.00208"
"36.79200","3.06619","0.00240"
"37.04400","3.08717","0.00220"
"37.29600","3.10822","0.00245"
"37.54800","3.12926","0.00202"
"37.80000","3.15013","0.00193"
"38.05200","3.17124","0.00191"
"38.30400","3.19216","0.00220"
"38.55600","3.21321","0.00222"
"38.80800","3.23414","0.00242"
"39.06000","3.25518","0.00252"
"39.31200","3.27617","0.00232"
"39.56400","3.29715","0.00267"
"39.81600","3.31814","0.00197"
"40.06800","3.33919","0.00196"
"40.32000","3.36023","0.00214"
"40.57200","3.38122","0.00217"
"40.82400","3.40220","0.00203"
"41.07600","3.42313","0.00221"
"41.32800","3.44418","0.00240"
"41.58000","3.46516","0.00267"
"41.83200","3.48621","0.00248"
"42.08400","3.50713","0.00181"
"42.33600","3.52818","0.00250"
"42.58800","3.54923","0.00249"
"42.84000","3.57015","0.00197"
"43.09200","3.59114","0.00208"
"43.34400","3.61224","0.00265"
"43.59600","3.63317","0.00260"
"43.84800","3.65416","0.00214"
"44.10000","3.67520","0.00254"
"44.35200","3.69619","0.00241"
"44.60400","3.71723","0.00175"
"44.85600","3.73816","0.00232"
"45.10800","3.75921","0.00218"
"45.36000","3.78013","0.00258"
"45.61200","3.80118","0.00146"
"45.86400","3.82211","0.00188"
"46.11600","3.84315","0.00161"
"46.36800","3.86414","0.00252"
"46.62000","3.88524","0.00246"
"46.87200","3.90623","0.00267"
"47.12400","3.92722","0.00200"
"47.37600","3.94820","0.00241"
"47.62800","3.96925","0.00236"
"47.88000","3.99017","0.00253"
"48.13200","4.01116","0.00255"
"48.38400","4.03215","0.00255"
"48.63600","4.05319","0.00251"
"48.88800","4.07424","0.00284"
"49.14000","4.09516","0.00246"
"49.39200","4.11621","0.00244"
"49.64400","4.13714","0.00258"
"49.89600","4.15818","0.00226"
"50.14800","4.17911","0.00274"
"50.40000","4.20021","0.00226"
"50.65200","4.22120","0.00256"
"50.90400","4.24219","0.00227"
"51.15600","4.26317","0.00254"
"51.40800","4.28416","0.00227"
"51.66000","4.30521","0.00264"
"51.91200","4.32619","0.00273"
"52.16400","4.34718","0.00252"
"52.41600","4.36816","0.00236"
"52.66800","4.38921","0.00236"
"52.92000","4.41014","0.00239"
"53.17200","4.43118","0.00278"
"53.42400","4.45217","0.00246"
"53.67600","4.47321","0.00269"
"53.92800","4.49414","0.00284"
"54.18000","4.51519","0.00275"
"54.43200","4.53617","0.00283"
"54.68400","4.55722","0.00299"
"54.93600","4.57814","0.00266"
"55.18800","4.59925","0.00297"
"55.44000","4.62018","0.00246"
"55.69200","4.64122","0.00270"
"55.94400","4.66221","0.00114"
"56.19600","4.68313","0.00196"
"56.44800","4.70418","0.00222"
"56.70000","4.72517","0.00172"
"56.95200","4.74621","0.00153"
"57.20400","4.76714","0.00191"
"57.45600","4.78824","0.00205"
"57.70800","4.80917","0.00188"
"57.96000","4.83022","0.00199"
"58.21200","4.85114","0.00247"
"58.46400","4.87219","0.00236"
"58.71600","4.89318","0.00216"
"58.96800","4.91422","0.00250"
"59.22000","4.93521","0.00261"
"59.47200","4.95619","0.00281"
"59.72400","4.97718","0.00247"
"59.97600","4.99823","0.00291"
"60.22800","5.01915","0.00295"
"60.48000","5.04020","0.00305"
"60.73200","5.06118","0.00289"
"60.98400","5.08217","0.00346"
"61.23600","5.10322","0.00358"
"61.48800","5.12408","0.00370"
"61.74000","5.14519","0.00357"
"61.99200","5.16611","0.00284"
"62.24400","5.18716","0.00348"
"62.49600","5.20815","0.00317"
"62.74800","5.22925","0.00349"
"63.00000","5.25018","0.00349"
"63.25200","5.27122","0.00368"
"63.50400","5.29215","0.00361"
"63.75600","5.31320","0.00372"
"64.00800","5.33424","0.00374"
"64.26000","5.35523","0.00374"
"64.51200","5.37616","0.00398"
"64.76400","5.39714","0.00377"
"65.01600","5.41819","0.00368"
"65.26800","5.43917","0.00371"
"65.52000","5.46022","0.00379"
"65.77200","5.48109","0.00418"
"66.02400","5.50219","0.00416"
"66.27600","5.52318","0.00424"
"66.52800","5.54416","0.00423"
"66.78000","5.56521","0.00449"
"67.03200","5.58620","0.00449"
"67.28400","5.60718","0.00427"
"67.53600","5.62823","0.00456"
"67.78800","5.64921","0.00435"
"68.04000","5.67020","0.00449"
"68.29200","5.69125","0.00474"
"68.54400","5.71217","0.00469"
"68.79600","5.73316","0.00519"
"69.04800","5.75414","0.00524"
"69.30000","5.77519","0.00507"
"69.55200","5.79612","0.00505"
"69.80400","5.81722","0.00464"
"70.05600","5.83815","0.00467"
"70.30800","5.85920","0.00536"
"70.56000","5.88012","0.00524"
"70.81200","5.90117","0.00488"
"71.06400","5.92215","0.00502"
"71.31600","5.94326","0.00551"
"71.56800","5.96419","0.00487"
"71.82000","5.98517","0.00512"
"72.07200","6.00622","0.00556"
"72.32400","6.02720","0.00524"
"72.57600","6.04819","0.00532"
"72.82800","6.06912","0.00567"
"73.08000","6.09022","0.00574"
"73.33200","6.11121","0.00612"
"73.58400","6.13225","0.00592"
"73.83600","6.15312","0.00591"
"74.08800","6.17423","0.00595"
"74.34000","6.19515","0.00599"
"74.59200","6.21620","0.00623"
"74.84400","6.23718","0.00640"
"75.09600","6.25817","0.00696"
"75.34800","6.27916","0.00644"
"75.60000","6.30020","0.00600"
"75.85200","6.32119","0.00505"
"76.10400","6.34217","0.00606"
"76.35600","6.36322","0.00620"
"76.60800","6.38421","0.00478"
"76.86000","6.40519","0.00550"
"77.11200","6.42612","0.00530"
"77.36400","6.44717","0.00549"
"77.61600","6.46815","0.00567"
"77.86800","6.48920","0.00620"
"78.12000","6.51018","0.00671"
"78.37200","6.53117","0.00623"
"78.62400","6.55216","0.00638"
"78.87600","6.57320","0.00615"
"79.12800","6.59419","0.00662"
"79.38000","6.61523","0.00659"
"79.63200","6.63622","0.00652"
"79.88400","6.65721","0.00690"
"80.13600","6.67813","0.00606"
"80.38800","6.69918","0.00623"
"80.64000","6.72022","0.00581"
"80.89200","6.74115","0.00589"
"81.14400","6.76220","0.00578"
"81.39600","6.78312","0.00538"
"81.64800","6.80423","0.00566"
"81.90000","6.82516","0.00592"
"82.15200","6.84620","0.00532"
"82.40400","6.86719","0.00623"
"82.65600","6.88823","0.00623"
"82.90800","6.90916","0.00605"
"83.16000","6.93020","0.00582"
"83.41200","6.95119","0.00627"
"83.66400","6.97218","0.00666"
"83.91600","6.99316","0.00628"
"84.16800","7.01415","0.00677"
"84.42000","7.03519","0.00670"
"84.67200","7.05618","0.00665"
"84.92400","7.07723","0.00679"
"85.17600","7.09815","0.00692"
"85.42800","7.11920","0.00781"
"85.68000","7.14013","0.00741"
"85.93200","7.16123","0.00793"
"86.18400","7.18216","0.00778"
"86.43600","7.20320","0.00822"
"86.68800","7.22413","0.00812"
"86.94000","7.24524","0.00783"
"87.19200","7.26616","0.00849"
"87.44400","7.28721","0.00830"
"87.69600","7.30819","0.00848"
"87.94800","7.32924","0.00844"
"88.20000","7.35023","0.00881"
"88.45200","7.37115","0.00885"
"88.70400","7.39220","0.00926"
"88.95600","7.41319","0.00936"
"89.20800","7.43423","0.00945"
"89.46000","7.45516","0.00991"
"89.71200","7.47620","0.01033"
"89.96400","7.49719","0.01063"
"90.21600","7.51823","0.01064"
"90.46800","7.53922","0.01074"
"90.72000","7.56021","0.01065"
"90.97200","7.58113","0.01162"
"91.22400","7.60218","0.01196"
"91.47600","7.62317","0.01156"
"91.72800","7.64415","0.01162"
"91.98000","7.66526","0.01212"
"92.23200","7.68618","0.01275"
"92.48400","7.70717","0.01257"
"92.73600","7.72816","0.01296"
"92.98800","7.74920","0.01282"
"93.24000","7.77013","0.01305"
"93.49200","7.79117","0.01317"
"93.74400","7.81216","0.01377"
"93.99600","7.83321","0.01387"
"94.24800","7.85413","0.01456"
"94.50000","7.87518","0.01365"
"94.75200","7.89616","0.01311"
"95.00400","7.91721","0.01413"
"95.25600","7.93820","0.01414"
"95.50800","7.95918","0.01429"
"95.76000","7.98017","0.01473"
"96.01200","8.00115","0.01538"
"96.26400","8.02220","0.01602"
"96.51600","8.04319","0.01654"
"96.76800","8.06417","0.01662"
"97.02000","8.08522","0.01708"
"97.27200","8.10620","0.01751"
"97.52400","8.12713","0.01776"
"97.77600","8.14818","0.01846"
"98.02800","8.16910","0.01791"
"98.28000","8.19021","0.01887"
"98.53200","8.21119","0.01954"
"98.78400","8.23224","0.01946"
"99.03600","8.25317","0.02045"
"99.28800","8.27421","0.02085"
"99.54000","8.29514","0.02127"
"99.79200","8.31619","0.02167"
"100.04400","8.33717","0.02190"
"100.29600","8.35822","0.02217"
"100.54800","8.37920","0.02247"
"100.80000","8.40013","0.02308"
"101.05200","8.42124","0.02273"
"101.30400","8.44216","0.02248"
"101.55600","8.46321","0.02311"
"101.80800","8.48407","0.02334"
"102.06000","8.50518","0.02376"
"102.31200","8.52617","0.02401"
"102.56400","8.54721","0.02446"
"102.81600","8.56814","0.02532"
"103.06800","8.58924","0.02523"
"103.32000","8.61023","0.02591"
"103.57200","8.63122","0.02597"
"103.82400","8.65214","0.02656"
"104.07600","8.67313","0.02694"
"104.32800","8.69418","0.02781"
"104.58000","8.71522","0.02803"
"104.83200","8.73621","0.02838"
"105.08400","8.75719","0.02872"
"105.33600","8.77818","0.02955"
"105.58800","8.79911","0.02993"
"105.84000","8.82021","0.03100"
"106.09200","8.84114","0.03131"
"106.34400","8.86218","0.03132"
"106.59600","8.88317","0.03225"
"106.84800","8.90422","0.03280"
"107.10000","8.92514","0.03349"
"107.35200","8.94625","0.03425"
"107.60400","8.96723","0.03504"
"107.85600","8.98816","0.03574"
"108.10800","9.00915","0.03670"
"108.36000","9.03019","0.03761"
"108.61200","9.05124","0.03851"
"108.86400","9.07216","0.03923"
"109.11600","9.09321","0.04013"
"109.36800","9.11420","0.04054"
"109.62000","9.13524","0.04124"
"109.87200","9.15617","0.04243"
"110.12400","9.17715","0.03202"
"110.37600","9.19814","0.03226"
"110.62800","9.21925","0.03286"
"110.88000","9.24017","0.03378"
"111.13200","9.26122","0.03461"
"111.38400","9.28221","0.03461"
"111.63600","9.30319","0.03618"
"111.88800","9.32418","0.03698"
"112.14000","9.34516","0.03748"
"112.39200","9.36615","0.03800"
"112.64400","9.38720","0.03887"
"112.89600","9.40818","0.03925"
"113.14800","9.42911","0.03968"
"113.40000","9.45021","0.04047"
"113.65200","9.47114","0.04080"
"113.90400","9.49219","0.04190"
"114.15600","9.51317","0.04220"
"114.40800","9.53422","0.04290"
"114.66000","9.55520","0.04334"
"114.91200","9.57625","0.04408"
"115.16400","9.59718","0.04488"
"115.41600","9.61822","0.04544"
"115.66800","9.63921","0.04599"
"115.92000","9.66019","0.04664"
"116.17200","9.68118","0.04683"
"116.42400","9.70217","0.04736"
"116.67600","9.72321","0.04762"
"116.92800","9.74420","0.04832"
"117.18000","9.76519","0.04914"
"117.43200","9.78617","0.04988"
"117.68400","9.80722","0.04976"
"117.93600","9.82820","0.05028"
"118.18800","9.84919","0.05099"
"118.44000","9.87012","0.05137"
"118.69200","9.89116","0.05230"
"118.94400","9.91221","0.05285"
"119.19600","9.93319","0.05395"
"119.44800","9.95418","0.05453"
"119.70000","9.97517","0.05499"
"119.95200","9.99621","0.05570"
"120.20400","10.01714","0.05709"
"120.45600","10.03818","0.05764"
"120.70800","10.05917","0.05908"
"120.96000","10.08022","0.05997"
"121.21200","10.10114","0.05999"
"121.46400","10.12219","0.06126"
"121.71600","10.14318","0.06289"
"121.96800","10.16422","0.06365"
"122.22000","10.18515","0.06448"
"122.47200","10.20619","0.06528"
"122.72400","10.22718","0.06679"
"122.97600","10.24823","0.06735"
"123.22800","10.26915","0.06827"
"123.48000","10.29020","0.06899"
"123.73200","10.31118","0.06936"
"123.98400","10.33223","0.07003"
"124.23600","10.35322","0.07123"
"124.48800","10.37414","0.07110"
"124.74000","10.39519","0.07212"
"124.99200","10.41617","0.07233"
"125.24400","10.43722","0.07299"
"125.49600","10.45815","0.07336"
"125.74800","10.47919","0.07326"
"126.00000","10.50018","0.07416"
"126.25200","10.52122","0.07439"
"126.50400","10.54221","0.07499"
"126.75600","10.56326","0.07573"
"127.00800","10.58418","0.07377"
"127.26000","10.60517","0.01010"
"127.51200","10.62615","0.01258"
"127.76400","10.64720","0.01309"
"128.01600","10.66825","0.01125"
"128.26800","10.68923","0.01215"
"128.52000","10.71016","0.01306"
"128.77200","10.73114","0.01393"
"129.02400","10.75219","0.01457"
"129.27600","10.77318","0.01529"
"129.52800","10.79416","0.01411"
"129.78000","10.81515","0.01720"
"130.03200","10.83619","0.01635"
"130.28400","10.85718","0.01740"
"130.53600","10.87823","0.01767"
"130.78800","10.89921","0.01848"
"131.04000","10.92026","0.01829"
"131.29200","10.94125","0.02024"
"131.54400","10.96223","0.01998"
"131.79600","10.98316","0.02066"
"132.04800","11.00420","0.02141"
"132.30000","11.02525","0.02314"
"132.55200","11.04618","0.02229"
"132.80400","11.06716","0.02300"
"133.05600","11.08809","0.02361"
"133.30800","11.10925","0.02471"
"133.56000","11.13018","0.02505"
"133.81200","11.15117","0.02576"
"134.06400","11.17209","0.02568"
"134.31600","11.19320","0.02657"
"134.56800","11.21418","0.02724"
"134.82000","11.23523","0.02866"
"135.07200","11.25616","0.02885"
"135.32400","11.27714","0.02943"
"135.57600","11.29819","0.02950"
"135.82800","11.31917","0.02966"
"136.08000","11.34022","0.03129"
"136.33200","11.36121","0.03158"
"136.58400","11.38219","0.03316"
"136.83600","11.40312","0.03275"
"137.08800","11.42417","0.03430"
"137.34000","11.44515","0.03444"
"137.59200","11.46620","0.03696"
"137.84400","11.48712","0.03670"
"138.09600","11.50817","0.03895"
"138.34800","11.52915","0.03883"
"138.60000","11.55020","0.04056"
"138.85200","11.57113","0.04107"
"139.10400","11.59217","0.04245"
"139.35600","11.61322","0.04242"
"139.60800","11.63421","0.04377"
"139.86000","11.65519","0.04423"
"140.11200","11.67618","0.04529"
"140.36400","11.69716","0.04672"
"140.61600","11.71821","0.04671"
"140.86800","11.73920","0.04815"
"141.12000","11.76006","0.04750"
"141.37200","11.78117","0.04977"
"141.62400","11.80216","0.04943"
"141.87600","11.82320","0.05135"
"142.12800","11.84419","0.05167"
"142.38000","11.86523","0.05280"
"142.63200","11.88616","0.05391"
"142.88400","11.90721","0.05454"
"143.13600","11.92819","0.05586"
"143.38800","11.94924","0.05647"
"143.64000","11.97022","0.05825"
"143.89200","11.99121","0.05843"
"144.14400","12.01219","0.06011"
"144.39600","12.03318","0.06065"
"144.64800","12.05423","0.06245"
"144.90000","12.07515","0.06373"
"145.15200","12.09614","0.06471"
"145.40400","12.11713","0.06621"
"145.65600","12.13817","0.06745"
"145.90800","12.15922","0.06870"
"146.16000","12.18026","0.06934"
"146.41200","12.20119","0.07082"
"146.66400","12.22230","0.07130"
"146.91600","12.24322","0.07222"
"147.16800","12.26421","0.07289"
"147.42000","12.28520","0.07382"
"147.67200","12.30618","0.07497"
"147.92400","12.32723","0.07580"
"148.17600","12.34821","0.07715"
"148.42800","12.36920","0.07798"
"148.68000","12.39019","0.07943"
"148.93200","12.41123","0.08113"
"149.18400","12.43210","0.08217"
"149.43600","12.45320","0.08435"
"149.68800","12.47413","0.08522"
"149.94000","12.49523","0.08695"
"150.19200","12.51616","0.08902"
"150.44400","12.53721","0.09005"
"150.69600","12.55819","0.09166"
"150.94800","12.57924","0.09283"
"151.20000","12.60017","0.09337"
"151.45200","12.62115","0.09417"
"151.70400","12.64220","0.09521"
"151.95600","12.66318","0.09588"
"152.20800","12.68423","0.09641"
"152.46000","12.70516","0.09757"
"152.71200","12.72620","0.09821"
"152.96400","12.74719","0.09892"
"153.21600","12.76817","0.09985"
"153.46800","12.78910","0.10020"
"153.72000","12.81027","0.10155"
"153.97200","12.83119","0.10185"
"154.22400","12.85224","0.10328"
"154.47600","12.87316","0.10380"
"154.72800","12.89421","0.10444"
"154.98000","12.91520","0.10564"
"155.23200","12.93618","0.10674"
"155.48400","12.95717","0.08902"
"155.73600","12.97816","0.09023"
"155.98800","12.99914","0.08997"
"156.24000","13.02019","0.09162"
"156.49200","13.04117","0.09241"
"156.74400","13.06216","0.09322"
"156.99600","13.08327","0.09465"
"157.24800","13.10419","0.09536"
"157.50000","13.12518","0.09692"
"157.75200","13.14616","0.09773"
"158.00400","13.16721","0.09868"
"158.25600","13.18820","0.09960"
"158.50800","13.20924","0.10041"
"158.76000","13.23017","0.10163"
"159.01200","13.25121","0.10247"
"159.26400","13.27220","0.10276"
"159.51600","13.29319","0.10370"
"159.76800","13.31423","0.10385"
"160.02000","13.33516","0.10523"
"160.27200","13.35627","0.10698"
"160.52400","13.37713","0.10731"
"160.77600","13.39824","0.10918"
"161.02800","13.41916","0.11009"
"161.28000","13.44027","0.11097"
"161.53200","13.46113","0.11262"
"161.78400","13.48218","0.11378"
"162.03600","13.50311","0.11605"
"162.28800","13.52427","0.11681"
"162.54000","13.54520","0.11823"
"162.79200","13.56618","0.11998"
"163.04400","13.58717","0.12043"
"163.29600","13.60816","0.12178"
"163.54800","13.62920","0.12262"
"163.80000","13.65019","0.12440"
"164.05200","13.67118","0.12472"
"164.30400","13.69216","0.12619"
"164.55600","13.71321","0.12760"
"164.80800","13.73413","0.12987"
"165.06000","13.75518","0.13182"
"165.31200","13.77617","0.13453"
"165.56400","13.79721","0.13733"
"165.81600","13.81814","0.13875"
"166.06800","13.83918","0.14142"
"166.32000","13.86017","0.14427"
"166.57200","13.88122","0.14610"
"166.82400","13.90220","0.14740"
"167.07600","13.92319","0.14930"
"167.32800","13.94424","0.14978"
"167.58000","13.96522","0.15199"
"167.83200","13.98615","0.15294"
"168.08400","14.00713","0.15465"
"168.33600","14.02824","0.15629"
"168.58800","14.04916","0.15828"
"168.84000","14.07021","0.15967"
"169.09200","14.09114","0.16233"
"169.34400","14.11224","0.16414"
"169.59600","14.13317","0.16698"
"169.84800","14.15422","0.16919"
"170.10000","14.17514","0.17102"
"170.35200","14.19619","0.17332"
"170.60400","14.21711","0.17517"
"170.85600","14.23822","0.17706"
"171.10800","14.25920","0.17857"
"171.36000","14.28019","0.17995"
"171.61200","14.30124","0.18156"
"171.86400","14.32222","0.18306"
"172.11600","14.34321","0.18575"
"172.36800","14.36414","0.18671"
"172.62000","14.38518","0.18867"
"172.87200","14.40611","0.19056"
"173.12400","14.42716","0.19193"
"173.37600","14.44814","0.19256"
"173.62800","14.46925","0.18493"
"173.88000","14.49017","0.18578"
"174.13200","14.51116","0.18770"
"174.38400","14.53220","0.18898"
"174.63600","14.55325","0.19169"
"174.88800","14.57418","0.19396"
"175.14000","14.59516","0.19588"
"175.39200","14.61621","0.19807"
"175.64400","14.63726","0.19969"
"175.89600","14.65824","0.20176"
"176.14800","14.67917","0.20311"
"176.40000","14.70021","0.20491"
"176.65200","14.72120","0.20573"
"176.90400","14.74224","0.20787"
"177.15600","14.76311","0.20979"
"177.40800","14.78416","0.21103"
"177.66000","14.80520","0.21234"
"177.91200","14.82625","0.21332"
"178.16400","14.84718","0.21443"
"178.41600","14.86822","0.21513"
"178.66800","14.88915","0.21667"
"178.92000","14.91020","0.21825"
"179.17200","14.93118","0.22050"
"179.42400","14.95217","0.22189"
"179.67600","14.97321","0.22369"
"179.92800","14.99420","0.22545"
"180.18000","15.01518","0.22751"
"180.43200","15.03617","0.22901"
"180.68400","15.05722","0.23066"
"180.93600","15.07820","0.23235"
"181.18800","15.09919","0.23411"
"181.44000","15.12012","0.23634"
"181.69200","15.14116","0.23843"
"181.94400","15.16221","0.24082"
"182.19600","15.18319","0.24206"
"182.44800","15.20418","0.24382"
"182.70000","15.22523","0.22251"
"182.95200","15.24621","0.22228"
"183.20400","15.26726","0.22045"
"183.45600","15.28818","0.21921"
"183.70800","15.30917","0.21962"
"183.96000","15.33016","0.22071"
"184.21200","15.35120","0.22152"
"184.46400","15.37225","0.22358"
"184.71600","15.39312","0.22503"
"184.96800","15.41422","0.22666"
"185.22000","15.43515","0.22834"
"185.47200","15.45619","0.22975"
"185.72400","15.47712","0.23090"
"185.97600","15.49817","0.23072"
"186.22800","15.51915","0.22939"
"186.48000","15.54020","0.21723"
"186.73200","15.56118","0.09981"
"186.98400","15.58223","0.10291"
"187.23600","15.60322","0.10646"
"187.48800","15.62414","0.10879"
"187.74000","15.64519","0.10849"
"187.99200","15.66617","0.11096"
"188.24400","15.68722","0.10777"
"188.49600","15.70815","0.10828"
"188.74800","15.72919","0.11001"
"189.00000","15.75018","0.10000"
"189.25200","15.77122","0.10035"
"189.50400","15.79215","0.10044"
"189.75600","15.81319","0.10137"
"190.00800","15.83418","0.10524"
"190.26000","15.85523","0.10695"
"190.51200","15.87615","0.11118"
"190.76400","15.89720","0.11261"
"191.01600","15.91819","0.11450"
"191.26800","15.93917","0.11836"
"191.52000","15.96022","0.11862"
"191.77200","15.98120","0.11985"
"192.02400","16.00219","0.12081"
"192.27600","16.02318","0.12219"
"192.52800","16.04422","0.12572"
"192.78000","16.06509","0.12503"
"193.03200","16.08619","0.12669"
"193.28400","16.10718","0.13139"
"193.53600","16.12823","0.13289"
"193.78800","16.14915","0.13603"
"194.04000","16.17020","0.14162"
"194.29200","16.19118","0.14362"
"194.54400","16.21217","0.14760"
"194.79600","16.23316","0.14521"
"195.04800","16.25426","0.14508"
"195.30000","16.27519","0.14826"
"195.55200","16.29618","0.15074"
"195.80400","16.31722","0.15221"
"196.05600","16.33815","0.15425"
"196.30800","16.35925","0.15714"
"196.56000","16.38018","0.15885"
"196.81200","16.40123","0.16260"
"197.06400","16.42215","0.16532"
"197.31600","16.44320","0.16793"
"197.56800","16.46418","0.17234"
"197.82000","16.48517","0.17471"
"198.07200","16.50616","0.17606"
"198.32400","16.52726","0.17888"
"198.57600","16.54819","0.18061"
"198.82800","16.56918","0.18262"
"199.08000","16.59016","0.18568"
"199.33200","16.61115","0.18795"
"199.58400","16.63213","0.19026"
"199.83600","16.65318","0.19386"
"200.08800","16.67422","0.19533"
"200.34000","16.69515","0.19771"
"200.59200","16.71620","0.19881"
"200.84400","16.73712","0.20187"
"201.09600","16.75817","0.20413"
"201.34800","16.77909","0.20599"
"201.60000","16.80026","0.20835"
"201.85200","16.82119","0.21007"
"202.10400","16.84223","0.21189"
"202.35600","16.86322","0.21338"
"202.60800","16.88421","0.21534"
"202.86000","16.90519","0.21703"
"203.11200","16.92624","0.21870"
"203.36400","16.94722","0.22065"
"203.61600","16.96821","0.22288"
"203.86800","16.98919","0.22484"
"204.12000","17.01012","0.22624"
"204.37200","17.03123","0.22676"
"204.62400","17.05215","0.22796"
"204.87600","17.07320","0.22972"
"205.12800","17.09407","0.23102"
"205.38000","17.11517","0.23248"
"205.63200","17.13622","0.23503"
"205.88400","17.15726","0.23638"
"206.13600","17.17813","0.23916"
"206.38800","17.19924","0.24156"
"206.64000","17.22022","0.24403"
"206.89200","17.24121","0.24708"
"207.14400","17.26219","0.24958"
"207.39600","17.28318","0.25208"
"207.64800","17.30417","0.25398"
"207.90000","17.32521","0.25665"
"208.15200","17.34620","0.20704"
"208.40400","17.36719","0.20168"
"208.65600","17.38823","0.20554"
"208.90800","17.40916","0.20821"
"209.16000","17.43014","0.21111"
"209.41200","17.45113","0.21330"
"209.66400","17.47223","0.21539"
"209.91600","17.49316","0.21737"
"210.16800","17.51421","0.21993"
"210.42000","17.53513","0.22216"
"210.67200","17.55624","0.22422"
"210.92400","17.57722","0.22671"
"211.17600","17.59815","0.22784"
"211.42800","17.61920","0.22858"
"211.68000","17.64013","0.23029"
"211.93200","17.66123","0.23176"
"212.18400","17.68216","0.23333"
"212.43600","17.70326","0.23509"
"212.68800","17.72419","0.23895"
"212.94000","17.74529","0.24199"
"213.19200","17.76616","0.24587"
"213.44400","17.78715","0.24981"
"213.69600","17.80813","0.25200"
"213.94800","17.82924","0.25474"
"214.20000","17.85016","0.25639"
"214.45200","17.87121","0.23568"
"214.70400","17.89220","0.23134"
"214.95600","17.91318","0.23227"
"215.20800","17.93423","0.23412"
"215.46000","17.95516","0.23627"
"215.71200","17.97614","0.23960"
"215.96400","17.99719","0.24194"
"216.21600","18.01817","0.24382"
"216.46800","18.03916","0.24665"
"216.72000","18.06021","0.24871"
"216.97200","18.08113","0.25055"
"217.22400","18.10224","0.25231"
"217.47600","18.12317","0.25383"
"217.72800","18.14421","0.25654"
"217.98000","18.16514","0.25925"
"218.23200","18.18624","0.26142"
"218.48400","18.20717","0.26375"
"218.73600","18.22821","0.26760"
"218.98800","18.24920","0.26976"
"219.24000","18.27025","0.27133"
"219.49200","18.29117","0.27393"
"219.74400","18.31216","0.27568"
"219.99600","18.33320","0.27786"
"220.24800","18.35413","0.27930"
"220.50000","18.37524","0.28140"
"220.75200","18.39616","0.28367"
"221.00400","18.41727","0.28629"
"221.25600","18.43820","0.28948"
"221.50800","18.45918","0.29309"
"221.76000","18.48011","0.29591"
"222.01200","18.50115","0.29899"
"222.26400","18.52220","0.30148"
"222.51600","18.54319","0.30297"
"222.76800","18.56417","0.30488"
"223.02000","18.58516","0.30666"
"223.27200","18.60620","0.30793"
"223.52400","18.62719","0.30970"
"223.77600","18.64818","0.31127"
"224.02800","18.66916","0.31217"
"224.28000","18.69015","0.31349"
"224.53200","18.71113","0.31487"
"224.78400","18.73218","0.31610"
"225.03600","18.75317","0.31731"
"225.28800","18.77421","0.31885"
"225.54000","18.79520","0.32033"
"225.79200","18.81618","0.32142"
"226.04400","18.83711","0.32284"
"226.29600","18.85822","0.32412"
"226.54800","18.87914","0.32549"
"226.80000","18.90019","0.32695"
"227.05200","18.92118","0.32862"
"227.30400","18.94216","0.33003"
"227.55600","18.96321","0.33139"
"227.80800","18.98419","0.33214"
"228.06000","19.00524","0.33305"
"228.31200","19.02617","0.33497"
"228.56400","19.04721","0.33679"
"228.81600","19.06814","0.33828"
"229.06800","19.08918","0.34211"
"229.32000","19.11017","0.34459"
"229.57200","19.13122","0.34767"
"229.82400","19.15214","0.35029"
"230.07600","19.17319","0.35330"
"230.32800","19.19423","0.35488"
"230.58000","19.21522","0.35726"
"230.83200","19.23615","0.36002"
"231.08400","19.25719","0.36277"
"231.33600","19.27818","0.36425"
"231.58800","19.29916","0.36483"
"231.84000","19.32015","0.36726"
"232.09200","19.34114","0.37071"
"232.34400","19.36218","0.37355"
"232.59600","19.38317","0.37570"
"232.84800","19.40415","0.11839"
"233.10000","19.42514","0.06542"
"233.35200","19.44619","0.09317"
"233.60400","19.46717","0.07369"
"233.85600","19.48822","0.08860"
"234.10800","19.50915","0.07498"
"234.36000","19.53025","0.08725"
"234.61200","19.55124","0.07278"
"234.86400","19.57216","0.08925"
"235.11600","19.59315","0.07199"
"235.36800","19.61419","0.09650"
"235.62000","19.63518","0.08037"
"235.87200","19.65617","0.08717"
"236.12400","19.67715","0.07469"
"236.37600","19.69814","0.09199"
"236.62800","19.71925","0.08291"
"236.88000","19.74017","0.09347"
"237.13200","19.76116","0.08612"
"237.38400","19.78214","0.09213"
"237.63600","19.80325","0.08556"
"237.88800","19.82418","0.09465"
"238.14000","19.84522","0.09443"
"238.39200","19.86615","0.09650"
"238.64400","19.88719","0.09094"
"238.89600","19.90824","0.09695"
"239.14800","19.92917","0.09672"
"239.40000","19.95021","0.10126"
"239.65200","19.97120","0.09634"
"239.90400","19.99224","0.10146"
"240.15600","20.01317","0.09839"
"240.40800","20.03422","0.10521"
"240.66000","20.05514","0.10032"
"240.91200","20.07619","0.10740"
"241.16400","20.09718","0.10194"
"241.41600","20.11816","0.11167"
"241.66800","20.13915","0.10569"
"241.92000","20.16025","0.11289"
"242.17200","20.18112","0.10588"
"242.42400","20.20217","0.11326"
"242.67600","20.22315","0.10819"
"242.92800","20.24420","0.11467"
"243.18000","20.26518","0.10889"
"243.43200","20.28623","0.11245"
"243.68400","20.30722","0.11149"
"243.93600","20.32820","0.11281"
"244.18800","20.34925","0.11558"
"244.44000","20.37011","0.11395"
"244.69200","20.39122","0.12136"
"244.94400","20.41215","0.11654"
"245.19600","20.43319","0.12459"
"245.44800","20.45412","0.11845"
"245.70000","20.47517","0.12451"
"245.95200","20.49615","0.12064"
"246.20400","20.51720","0.12300"
"246.45600","20.53818","0.12270"
"246.70800","20.55923","0.12314"
"246.96000","20.58022","0.12963"
"247.21200","20.60120","0.12598"
"247.46400","20.62219","0.13632"
"247.71600","20.64317","0.12837"
"247.96800","20.66422","0.13592"
"248.22000","20.68514","0.13236"
"248.47200","20.70625","0.13420"
"248.72400","20.72718","0.14245"
"248.97600","20.74822","0.13771"
"249.22800","20.76921","0.14828"
"249.48000","20.79020","0.14199"
"249.73200","20.81118","0.14732"
"249.98400","20.83223","0.14741"
"250.23600","20.85321","0.14782"
"250.48800","20.87420","0.15380"
"250.74000","20.89519","0.14945"
"250.99200","20.91617","0.15261"
"251.24400","20.93722","0.15281"
"251.49600","20.95815","0.15350"
"251.74800","20.97919","0.15615"
"252.00000","21.00018","0.15455"
"252.25200","21.02122","0.15748"
"252.50400","21.04209","0.15703"
"252.75600","21.06319","0.15918"
"253.00800","21.08418","0.16218"
"253.26000","21.10529","0.16233"
"253.51200","21.12615","0.16783"
"253.76400","21.14720","0.16689"
"254.01600","21.16818","0.16856"
"254.26800","21.18923","0.17165"
"254.52000","21.21016","0.17196"
"254.77200","21.23114","0.17590"
"255.02400","21.25219","0.17591"
"255.27600","21.27324","0.17740"
"255.52800","21.29422","0.18048"
"255.78000","21.31515","0.17931"
"256.03200","21.33625","0.18137"
"256.28400","21.35712","0.18312"
"256.53600","21.37823","0.18370"
"256.78800","21.39915","0.18667"
"257.04000","21.42014","0.18735"
"257.29200","21.44118","0.18873"
"257.54400","21.46223","0.19216"
"257.79600","21.48315","0.19220"
"258.04800","21.50420","0.19509"
"258.30000","21.52519","0.19637"
"258.55200","21.54618","0.19721"
"258.80400","21.56716","0.19885"
"259.05600","21.58815","0.20025"
"259.30800","21.60919","0.20171"
"259.56000","21.63018","0.20387"
"259.81200","21.65122","0.20464"
"260.06400","21.67215","0.20547"
"260.31600","21.69320","0.20788"
"260.56800","21.71418","0.20851"
"260.82000","21.73517","0.21019"
"261.07200","21.75615","0.21138"
"261.32400","21.77720","0.21237"
"261.57600","21.79819","0.21375"
"261.82800","21.81923","0.21468"
"262.08000","21.84016","0.21550"
"262.33200","21.86121","0.20939"
"262.58400","21.88225","0.21060"
"262.83600","21.90312","0.21176"
"263.08800","21.92416","0.21238"
"263.34000","21.94515","0.21304"
"263.59200","21.96619","0.21381"
"263.84400","21.98718","0.21458"
"264.09600","22.00823","0.21516"
"264.34800","22.02915","0.21571"
"264.60000","22.05026","0.21635"
"264.85200","22.07113","0.21751"
"265.10400","22.09217","0.21904"
"265.35600","22.11316","0.21997"
"265.60800","22.13426","0.22146"
"265.86000","22.15519","0.22247"
"266.11200","22.17618","0.22449"
"266.36400","22.19716","0.22568"
"266.61600","22.21821","0.22720"
"266.86800","22.23919","0.22855"
"267.12000","22.26018","0.22958"
"267.37200","22.28123","0.23119"
"267.62400","22.30221","0.23282"
"267.87600","22.32314","0.23468"
"268.12800","22.34419","0.23633"
"268.38000","22.36517","0.23806"
"268.63200","22.38616","0.23989"
"268.88400","22.40720","0.24266"
"269.13600","22.42813","0.24393"
"269.38800","22.44918","0.24587"
"269.64000","22.47016","0.24851"
"269.89200","22.49127","0.25025"
"270.14400","22.51213","0.25206"
"270.39600","22.53324","0.25403"
"270.64800","22.55423","0.25602"
"270.90000","22.57521","0.25779"
"271.15200","22.59620","0.25972"
"271.40400","22.61719","0.26138"
"271.65600","22.63823","0.26345"
"271.90800","22.65916","0.26525"
"272.16000","22.68020","0.26801"
"272.41200","22.70113","0.27004"
"272.66400","22.72223","0.27210"
"272.91600","22.74316","0.27411"
"273.16800","22.76415","0.27582"
"273.42000","22.78519","0.27780"
"273.67200","22.80624","0.27925"
"273.92400","22.82717","0.28167"
"274.17600","22.84821","0.28284"
"274.42800","22.86920","0.28552"
"274.68000","22.89024","0.28828"
"274.93200","22.91123","0.29031"
"275.18400","22.93216","0.29401"
"275.43600","22.95320","0.29545"
"275.68800","22.97413","0.29780"
"275.94000","22.99517","0.29998"
"276.19200","23.01616","0.30166"
"276.44400","23.03721","0.30454"
"276.69600","23.05813","0.30530"
"276.94800","23.07918","0.30638"
"277.20000","23.10016","0.30770"
"277.45200","23.12121","0.30865"
"277.70400","23.14220","0.31029"
"277.95600","23.16324","0.31132"
"278.20800","23.18417","0.31280"
"278.46000","23.20522","0.31379"
"278.71200","23.22620","0.31461"
"278.96400","23.24719","0.31624"
"279.21600","23.26818","0.31763"
"279.46800","23.28916","0.31854"
"279.72000","23.31021","0.31947"
"279.97200","23.33119","0.32073"
"280.22400","23.35224","0.32139"
"280.47600","23.37310","0.32292"
"280.72800","23.39421","0.32363"
"280.98000","23.41520","0.32467"
"281.23200","23.43618","0.32569"
"281.48400","23.45717","0.32707"
"281.73600","23.47821","0.32770"
"281.98800","23.49920","0.32913"
"282.24000","23.52019","0.33004"
"282.49200","23.54117","0.05534"
"282.74400","23.56216","0.06659"
"282.99600","23.58320","0.08377"
"283.24800","23.60419","0.06350"
"283.50000","23.62518","0.09143"
"283.75200","23.64616","0.06489"
"284.00400","23.66721","0.07237"
"284.25600","23.68813","0.06371"
"284.50800","23.70918","0.08525"
"284.76000","23.73017","0.06495"
"285.01200","23.75121","0.08367"
"285.26400","23.77220","0.07639"
"285.51600","23.79324","0.07893"
"285.76800","23.81411","0.08068"
"286.02000","23.83516","0.08806"
"286.27200","23.85620","0.09684"
"286.52400","23.87719","0.08794"
"286.77600","23.89817","0.10460"
"287.02800","23.91916","0.08629"
"287.28000","23.94020","0.09879"
"287.53200","23.96119","0.08706"
"287.78400","23.98218","0.09904"
"288.03600","24.00316","0.09118"
"288.28800","24.02421","0.09544"
"288.54000","24.04514","0.09944"
"288.79200","24.06618","0.09221"
"289.04400","24.08711","0.10587"
"289.29600","24.10822","0.09738"
"289.54800","24.12920","0.11005"
"289.80000","24.15019","0.10309"
"290.05200","24.17117","0.10642"
"290.30400","24.19216","0.10693"
"290.55600","24.21321","0.10200"
"290.80800","24.23419","0.11195"
"291.06000","24.25518","0.10288"
"291.31200","24.27622","0.12208"
"291.56400","24.29721","0.10501"
"291.81600","24.31814","0.11630"
"292.06800","24.33924","0.11231"
"292.32000","24.36011","0.11194"
"292.57200","24.38121","0.12483"
"292.82400","24.40220","0.11532"
"293.07600","24.42319","0.12117"
"293.32800","24.44417","0.12430"
"293.58000","24.46522","0.11610"
"293.83200","24.48615","0.13128"
"294.08400","24.50719","0.11952"
"294.33600","24.52818","0.13629"
"294.58800","24.54922","0.12688"
"294.84000","24.57021","0.12702"
"295.09200","24.59120","0.14202"
"295.34400","24.61218","0.13039"
"295.59600","24.63317","0.13437"
"295.84800","24.65421","0.14658"
"296.10000","24.67514","0.13248"
"296.35200","24.69625","0.14984"
"296.60400","24.71711","0.14176"
"296.85600","24.73822","0.14274"
"297.10800","24.75915","0.15218"
"297.36000","24.78019","0.14577"
"297.61200","24.80118","0.15237"
"297.86400","24.82222","0.15338"
"298.11600","24.84315","0.15097"
"298.36800","24.86419","0.15628"
"298.62000","24.88518","0.15671"
"298.87200","24.90617","0.15347"
"299.12400","24.92715","0.16776"
"299.37600","24.94814","0.15678"
"299.62800","24.96919","0.15879"
"299.88000","24.99011","0.16677"
"300.13200","25.01122","0.16155"
"300.38400","25.03214","0.16360"
"300.63600","25.05319","0.17151"
"300.88800","25.07417","0.16561"
"301.14000","25.09516","0.16773"
"301.39200","25.11615","0.17423"
"301.64400","25.13725","0.16674"
"301.89600","25.15818","0.17581"
"302.14800","25.17916","0.17529"
"302.40000","25.20015","0.17227"
"302.65200","25.22120","0.17596"
"302.90400","25.24224","0.17691"
"303.15600","25.26317","0.17406"
"303.40800","25.28422","0.17854"
"303.66000","25.30514","0.18097"
"303.91200","25.32619","0.17589"
"304.16400","25.34711","0.18046"
"304.41600","25.36822","0.18189"
"304.66800","25.38915","-0.00313"
"304.92000","25.41025","0.04035"
"305.17200","25.43118","0.00927"
"305.42400","25.45223","0.02557"
"305.67600","25.47321","0.02128"
"305.92800","25.49426","0.01672"
"306.18000","25.51518","0.02640"
"306.43200","25.53617","0.01678"
"306.68400","25.55716","0.02722"
"306.93600","25.57820","0.02008"
"307.18800","25.59919","0.02461"
"307.44000","25.62017","0.02390"
"307.69200","25.64122","0.02279"
"307.94400","25.66215","0.02609"
"308.19600","25.68319","0.02279"
"308.44800","25.70412","0.02702"
"308.70000","25.72516","0.02502"
"308.95200","25.74615","0.02498"
"309.20400","25.76720","0.02783"
"309.45600","25.78812","0.02507"
"309.70800","25.80917","0.02934"
"309.96000","25.83021","0.02877"
"310.21200","25.85126","0.02764"
"310.46400","25.87219","0.03137"
"310.71600","25.89317","0.02971"
"310.96800","25.91422","0.03190"
"311.22000","25.93521","0.03442"
"311.47200","25.95619","0.03470"
"311.72400","25.97717","0.03606"
"311.97600","25.99822","0.03665"
"312.22800","26.01915","0.03672"
"312.48000","26.04020","0.03999"
"312.73200","26.06112","0.03908"
"312.98400","26.08217","0.03425"
"313.23600","26.10315","0.03657"
"313.48800","26.12420","0.03785"
"313.74000","26.14519","0.03838"
"313.99200","26.16623","0.04032"
"314.24400","26.18722","0.03960"
"314.49600","26.20814","0.04225"
"314.74800","26.22913","0.04233"
"315.00000","26.25018","0.04308"
"315.25200","26.27122","0.04391"
"315.50400","26.29215","0.04462"
"315.75600","26.31319","0.04614"
"316.00800","26.33418","0.04643"
"316.26000","26.35523","0.04786"
"316.51200","26.37615","0.04816"
"316.76400","26.39720","0.04900"
"317.01600","26.41812","0.04956"
"317.26800","26.43923","0.05061"
"317.52000","26.46021","0.05156"
"317.77200","26.48120","0.05278"
"318.02400","26.50219","0.05368"
"318.27600","26.52324","0.05375"
"318.52800","26.54422","0.05587"
"318.78000","26.56515","0.05662"
"319.03200","26.58613","0.05797"
"319.28400","26.60718","0.05903"
"319.53600","26.62823","0.06000"
"319.78800","26.64915","0.06212"
"320.04000","26.67020","0.06364"
"320.29200","26.69113","0.06532"
"320.54400","26.71217","0.06620"
"320.79600","26.73316","0.06714"
"321.04800","26.75420","0.06851"
"321.30000","26.77513","0.06942"
"321.55200","26.79623","0.07032"
"321.80400","26.81716","0.07119"
"322.05600","26.83821","0.07198"
"322.30800","26.85919","0.07301"
"322.56000","26.88024","0.07350"
"322.81200","26.90116","0.07390"
"323.06400","26.92215","0.07517"
"323.31600","26.94320","0.07611"
"323.56800","26.96418","0.07774"
"323.82000","26.98523","0.07936"
"324.07200","27.00610","0.08063"
"324.32400","27.02720","0.08220"
"324.57600","27.04813","0.08387"
"324.82800","27.06917","0.08541"
"325.08000","27.09016","0.08672"
"325.33200","27.11121","0.08857"
"325.58400","27.13219","0.08938"
"325.83600","27.15318","0.09196"
"326.08800","27.17417","0.09347"
"326.34000","27.19521","0.09373"
"326.59200","27.21626","0.09490"
"326.84400","27.23718","0.09611"
"327.09600","27.25817","0.09701"
"327.34800","27.27916","0.09761"
"327.60000","27.30020","0.09774"
"327.85200","27.32113","0.09894"
"328.10400","27.34223","0.09944"
"328.35600","27.36316","0.10040"
"328.60800","27.38420","0.10094"
"328.86000","27.40513","0.10195"
"329.11200","27.42618","0.10300"
"329.36400","27.44716","0.10383"
"329.61600","27.46827","0.10466"
"329.86800","27.48914","0.10532"
"330.12000","27.51018","0.10614"
"330.37200","27.53117","0.10704"
"330.62400","27.55221","0.10765"
"330.87600","27.57320","0.10891"
"331.12800","27.59418","0.10993"
"331.38000","27.61523","0.11146"
"331.63200","27.63616","0.11257"
"331.88400","27.65721","0.11334"
"332.13600","27.67813","0.11485"
"332.38800","27.69924","0.11625"
"332.64000","27.72016","0.11716"
"332.89200","27.74127","0.11847"
"333.14400","27.76213","0.11912"
"333.39600","27.78318","0.12064"
"333.64800","27.80417","0.12141"
"333.90000","27.82515","0.12309"
"334.15200","27.84614","0.12421"
"334.40400","27.86718","0.12520"
"334.65600","27.88823","0.12616"
"334.90800","27.90916","0.12814"
"335.16000","27.93014","0.12958"
"335.41200","27.95113","0.13169"
"335.66400","27.97218","0.13250"
"335.91600","27.99316","0.13514"
"336.16800","28.01421","0.13676"
"336.42000","28.03513","0.13965"
"336.67200","28.05618","0.14323"
"336.92400","28.07717","0.14493"
"337.17600","28.09821","0.14678"
"337.42800","28.11914","0.14890"
"337.68000","28.14025","0.15020"
"337.93200","28.16123","0.15116"
"338.18400","28.18221","0.15303"
"338.43600","28.20314","0.15334"
"338.68800","28.22413","0.15494"
"338.94000","28.24524","0.15679"
"339.19200","28.26622","0.15802"
"339.44400","28.28721","0.15929"
"339.69600","28.30813","0.16145"
"339.94800","28.32924","0.16325"
"340.20000","28.35016","0.16573"
"340.45200","28.37121","0.16843"
"340.70400","28.39214","0.17033"
"340.95600","28.41318","0.17234"
"341.20800","28.43417","0.17340"
"341.46000","28.45521","0.05565"
"341.71200","28.47620","0.05564"
"341.96400","28.49718","0.04896"
"342.21600","28.51823","0.06594"
"342.46800","28.53916","0.04693"
"342.72000","28.56021","0.01920"
"342.97200","28.58119","0.02592"
"343.22400","28.60224","0.02033"
"343.47600","28.62316","0.02612"
"343.72800","28.64421","0.03062"
"343.98000","28.66514","0.02422"
"344.23200","28.68624","0.03468"
"344.48400","28.70717","0.02479"
"344.73600","28.72821","0.03307"
"344.98800","28.74914","0.02789"
"345.24000","28.77025","0.03168"
"345.49200","28.79117","0.03231"
"345.74400","28.81222","0.03291"
"345.99600","28.83320","0.03595"
"346.24800","28.85425","0.03565"
"346.50000","28.87518","0.03740"
"346.75200","28.89616","0.03822"
"347.00400","28.91721","0.03848"
"347.25600","28.93819","0.03960"
"347.50800","28.95924","0.04044"
"347.76000","28.98011","0.04161"
"348.01200","29.00115","0.04312"
"348.26400","29.02214","0.04428"
"348.51600","29.04325","0.04461"
"348.76800","29.06417","0.04636"
"349.02000","29.08521","0.04649"
"349.27200","29.10614","0.04708"
"349.52400","29.12719","0.04896"
"349.77600","29.14818","0.04875"
"350.02800","29.16916","0.05134"
"350.28000","29.19027","0.05069"
"350.53200","29.21119","0.05279"
"350.78400","29.23218","0.05347"
"351.03600","29.25317","0.05388"
"351.28800","29.27421","0.05574"
"351.54000","29.29514","0.05569"
"351.79200","29.31618","0.06001"
"352.04400","29.33717","0.05689"
"352.29600","29.35822","0.06232"
"352.54800","29.37920","0.06049"
"352.80000","29.40013","0.06349"
"353.05200","29.42117","0.06484"
"353.30400","29.44222","0.06606"
"353.55600","29.46315","0.06740"
"353.80800","29.48419","0.06690"
"354.06000","29.50518","0.06929"
"354.31200","29.52617","-0.00021"
"354.56400","29.54721","-0.00194"
"354.81600","29.56814","-0.00185"
"355.06800","29.58918","-0.00086"
"355.32000","29.61023","-0.00133"
"355.57200","29.63122","-0.00145"
"355.82400","29.65208","-0.00115"
"356.07600","29.67319","-0.00178"
"356.32800","29.69411","-0.00192"
"356.58000","29.71522","-0.00095"
"356.83200","29.73615","-0.00107"
"357.08400","29.75725","-0.00159"
"357.33600","29.77818","-0.00171"
"357.58800","29.79928","-0.00169"
"357.84000","29.82015","-0.00129"
"358.09200","29.84114","-0.00142"
"358.34400","29.86218","-0.00113"
"358.59600","29.88323","-0.00123"
"358.84800","29.90421","-0.00158"
"359.10000","29.92514","-0.00145"
"359.35200","29.94625","-0.00136"
"359.60400","29.96717","-0.00132"
"359.85600","29.98822","-0.00184"
"360.10800","30.00908","-0.00178"
"360.36000","30.03019","-0.00115"
"360.61200","30.05118","-0.00123"
"360.86400","30.07222","-0.00084"
"361.11600","30.09321","-0.00092"
"361.36800","30.11426","-0.00187"
"361.62000","30.13524","-0.00174"
"361.87200","30.15623","-0.00103"
"362.12400","30.17715","-0.00111"
"362.37600","30.19820","-0.00117"
"362.62800","30.21918","-0.00191"
"362.88000","30.24023","-0.00149"
"363.13200","30.26122","-0.00128"
"363.38400","30.28214","-0.00150"
"363.63600","30.30319","-0.00129"
"363.88800","30.32418","-0.00142"
"364.14000","30.34522","-0.00141"
"364.39200","30.36615","-0.00109"
"364.64400","30.38719","-0.00130"
"364.89600","30.40812","-0.00132"
"365.14800","30.42923","-0.00174"
"365.40000","30.45015","-0.00169"
"365.65200","30.47120","-0.00102"
"365.90400","30.49218","-0.00085"
"366.15600","30.51317","-0.00081"
"366.40800","30.53415","-0.00133"
"366.66000","30.55520","-0.00135"
"366.91200","30.57625","-0.00131"
"367.16400","30.59718","-0.00095"
"367.41600","30.61822","-0.00111"
"367.66800","30.63914","-0.00137"
"367.92000","30.66025","-0.00163"
"368.17200","30.68118","-0.00168"
"368.42400","30.70217","-0.00109"
"368.67600","30.72315","-0.00149"
"368.92800","30.74426","-0.00078"
"369.18000","30.76518","-0.00172"
"369.43200","30.78623","-0.00143"
"369.68400","30.80722","-0.00123"
"369.93600","30.82820","-0.00093"
"370.18800","30.84919","-0.00134"
"370.44000","30.87017","-0.00159"
"370.62200","30.88536","-0.00139"