File: Force_trajectories/161223_2/Specimen_RawData_10.csv
End date,"12/23/2016"
Specimen label,"21DG_71"
Maximum Load,"0.74697",N

Time,Extension,Load
(s),(mm),(N)
"0.00000","0.00000","0.00016"
"0.31200","0.02559","0.00035"
"0.62400","0.05226","0.00052"
"0.93600","0.07820","0.00063"
"1.24800","0.10421","0.00096"
"1.56000","0.13016","0.00099"
"1.87200","0.15617","0.00090"
"2.18400","0.18224","0.00138"
"2.49600","0.20813","0.00156"
"2.80800","0.23426","0.00176"
"3.12000","0.26014","0.00164"
"3.43200","0.28615","0.00194"
"3.74400","0.31216","0.00189"
"4.05600","0.33817","0.00217"
"4.36800","0.36424","0.00224"
"4.68000","0.39019","0.00245"
"4.99200","0.41619","0.00296"
"5.30400","0.44214","0.00279"
"5.61600","0.46815","0.00270"
"5.92800","0.49422","0.00322"
"6.24000","0.52023","0.00308"
"6.55200","0.54618","0.00346"
"6.86400","0.57213","0.00351"
"7.17600","0.59819","0.00411"
"7.48800","0.62420","0.00403"
"7.80000","0.65015","0.00442"
"8.11200","0.67622","0.00412"
"8.42400","0.70217","0.00441"
"8.73600","0.72818","0.00464"
"9.04800","0.75419","0.00454"
"9.36000","0.78019","0.00483"
"9.67200","0.80626","0.00489"
"9.98400","0.83215","0.00525"
"10.29600","0.85822","0.00470"
"10.60800","0.88411","0.00530"
"10.92000","0.91018","0.00584"
"11.23200","0.93618","0.00590"
"11.54400","0.96219","0.00561"
"11.85600","0.98820","0.00586"
"12.16800","1.01415","0.00620"
"12.48000","1.04022","0.00646"
"12.79200","1.06617","0.00597"
"13.10400","1.09224","0.00697"
"13.41600","1.11824","0.00665"
"13.72800","1.14413","0.00618"
"14.04000","1.17014","0.00681"
"14.35200","1.19609","0.00716"
"14.66400","1.22222","0.00684"
"14.97600","1.24817","0.00736"
"15.28800","1.27417","0.00785"
"15.60000","1.30018","0.00728"
"15.91200","1.32619","0.00766"
"16.22400","1.35214","0.00788"
"16.53600","1.37815","0.00798"
"16.84800","1.40422","0.00887"
"17.16000","1.43023","0.00847"
"17.47200","1.45617","0.00843"
"17.78400","1.48224","0.00881"
"18.09600","1.50813","0.00886"
"18.40800","1.53420","0.00899"
"18.72000","1.56021","0.00929"
"19.03200","1.58622","0.00940"
"19.34400","1.61222","0.00947"
"19.65600","1.63811","0.00939"
"19.96800","1.66418","0.01010"
"20.28000","1.69013","0.00991"
"20.59200","1.71620","0.01026"
"20.90400","1.74215","0.01058"
"21.21600","1.76822","0.01077"
"21.52800","1.79416","0.01059"
"21.84000","1.82017","0.01091"
"22.15200","1.84630","0.01108"
"22.46400","1.87219","0.01166"
"22.77600","1.89820","0.01173"
"23.08800","1.92421","0.01149"
"23.40000","1.95022","0.01199"
"23.71200","1.97622","0.01195"
"24.02400","2.00217","0.01243"
"24.33600","2.02824","0.01238"
"24.64800","2.05413","0.01292"
"24.96000","2.08014","0.01246"
"25.27200","2.10621","0.01285"
"25.58400","2.13215","0.01340"
"25.89600","2.15822","0.01356"
"26.20800","2.18417","0.01333"
"26.52000","2.21024","0.01353"
"26.83200","2.23619","0.01335"
"27.14400","2.26220","0.01471"
"27.45600","2.28821","0.01401"
"27.76800","2.31415","0.01427"
"28.08000","2.34022","0.01426"
"28.39200","2.36617","-0.00390"
"28.70400","2.39218","-0.00426"
"29.01600","2.41819","-0.00378"
"29.32800","2.44420","-0.00372"
"29.64000","2.47026","-0.00375"
"29.95200","2.49615","-0.00390"
"30.26400","2.52222","-0.00368"
"30.57600","2.54817","-0.00361"
"30.88800","2.57418","-0.00352"
"31.20000","2.60025","-0.00299"
"31.51200","2.62620","-0.00343"
"31.82400","2.65220","-0.00325"
"32.13600","2.67815","-0.00359"
"32.44800","2.70422","-0.00336"
"32.76000","2.73023","-0.00307"
"33.07200","2.75624","-0.00318"
"33.38400","2.78225","-0.00342"
"33.69600","2.80814","-0.00306"
"34.00800","2.83420","-0.00284"
"34.32000","2.86015","-0.00360"
"34.63200","2.88622","-0.00349"
"34.94400","2.91223","-0.00382"
"35.25600","2.93812","-0.00338"
"35.56800","2.96419","-0.00348"
"35.88000","2.99013","-0.00310"
"36.19200","3.01620","-0.00308"
"36.50400","3.04221","-0.00337"
"36.81600","3.06822","-0.00303"
"37.12800","3.09423","-0.00332"
"37.44000","3.12012","-0.00316"
"37.75200","3.14618","-0.00229"
"38.06400","3.17213","-0.00289"
"38.37600","3.19820","-0.00306"
"38.68800","3.22415","-0.00325"
"39.00000","3.25022","-0.00323"
"39.31200","3.27623","-0.00308"
"39.62400","3.30218","-0.00265"
"39.93600","3.32818","-0.00338"
"40.24800","3.35419","-0.00343"
"40.56000","3.38020","-0.00367"
"40.87200","3.40621","-0.00349"
"41.18400","3.43216","-0.00301"
"41.49600","3.45817","-0.00332"
"41.80800","3.48418","-0.00317"
"42.12000","3.51018","-0.00328"
"42.43200","3.53619","-0.00287"
"42.74400","3.56214","-0.00313"
"43.05600","3.58821","-0.00341"
"43.36800","3.61416","-0.00304"
"43.68000","3.64017","-0.00295"
"43.99200","3.66612","-0.00315"
"44.30400","3.69224","-0.00303"
"44.61600","3.71819","-0.00327"
"44.92800","3.74414","-0.00338"
"45.24000","3.77027","-0.00349"
"45.55200","3.79616","-0.00362"
"45.86400","3.82223","-0.00377"
"46.17600","3.84811","-0.00340"
"46.48800","3.87418","-0.00333"
"46.80000","3.90019","-0.00303"
"47.11200","3.92614","-0.00303"
"47.42400","3.95227","-0.00339"
"47.73600","3.97816","-0.00352"
"48.04800","4.00422","-0.00325"
"48.36000","4.03011","-0.00348"
"48.67200","4.05618","-0.00341"
"48.98400","4.08219","-0.00279"
"49.29600","4.10814","-0.00321"
"49.60800","4.13421","-0.00386"
"49.92000","4.16016","-0.00327"
"50.23200","4.18616","-0.00300"
"50.54400","4.21223","-0.00301"
"50.85600","4.23818","-0.00306"
"51.16800","4.26419","-0.00338"
"51.48000","4.29014","-0.00304"
"51.79200","4.31627","-0.00260"
"52.10400","4.34221","-0.00306"
"52.41600","4.36822","-0.00297"
"52.72800","4.39429","-0.00302"
"53.04000","4.42018","-0.00298"
"53.35200","4.44619","-0.00263"
"53.66400","4.47214","-0.00283"
"53.97600","4.49821","-0.00307"
"54.28800","4.52421","-0.00345"
"54.60000","4.55022","-0.00285"
"54.91200","4.57623","-0.00321"
"55.22400","4.60218","-0.00301"
"55.53600","4.62825","-0.00296"
"55.84800","4.65420","-0.00306"
"56.16000","4.68026","-0.00284"
"56.47200","4.70621","-0.00268"
"56.78400","4.73216","-0.00303"
"57.09600","4.75817","-0.00280"
"57.40800","4.78412","-0.00291"
"57.72000","4.81019","-0.00289"
"58.03200","4.83620","-0.00277"
"58.34400","4.86220","-0.00307"
"58.65600","4.88821","-0.00242"
"58.96800","4.91422","-0.00265"
"59.28000","4.94023","-0.00232"
"59.59200","4.96618","-0.00232"
"59.90400","4.99219","-0.00239"
"60.21600","5.01819","-0.00273"
"60.52800","5.04420","-0.00297"
"60.84000","5.07021","-0.00261"
"61.15200","5.09610","-0.00259"
"61.46400","5.12223","-0.00298"
"61.77600","5.14818","-0.00276"
"62.08800","5.17419","-0.00283"
"62.40000","5.20019","-0.00275"
"62.71200","5.22614","-0.00280"
"63.02400","5.25221","-0.00293"
"63.33600","5.27816","-0.00263"
"63.64800","5.30423","-0.00265"
"63.96000","5.33012","-0.00254"
"64.27200","5.35619","-0.00260"
"64.58400","5.38219","-0.00427"
"64.89600","5.40820","-0.00394"
"65.20800","5.43427","-0.00354"
"65.52000","5.46022","-0.00385"
"65.83200","5.48617","-0.00399"
"66.14400","5.51218","-0.00346"
"66.45600","5.53818","-0.00401"
"66.76800","5.56419","-0.00400"
"67.08000","5.59014","-0.00375"
"67.39200","5.61621","-0.00398"
"67.70400","5.64216","-0.00324"
"68.01600","5.66817","-0.00319"
"68.32800","5.69424","-0.00310"
"68.64000","5.72018","-0.00315"
"68.95200","5.74619","-0.00302"
"69.26400","5.77214","-0.00298"
"69.57600","5.79821","-0.00361"
"69.88800","5.82416","-0.00348"
"70.20000","5.85017","-0.00323"
"70.51200","5.87624","-0.00367"
"70.82400","5.90218","-0.00319"
"71.13600","5.92819","-0.00350"
"71.44800","5.95414","-0.00348"
"71.76000","5.98021","-0.00350"
"72.07200","6.00616","-0.00430"
"72.38400","6.03217","-0.00404"
"72.69600","6.05817","-0.00371"
"73.00800","6.08412","-0.00391"
"73.32000","6.11019","-0.00403"
"73.63200","6.13614","-0.00369"
"73.94400","6.16221","-0.00370"
"74.25600","6.18822","-0.00329"
"74.56800","6.21417","-0.00372"
"74.88000","6.24017","-0.00365"
"75.19200","6.26612","-0.00324"
"75.50400","6.29219","-0.00375"
"75.81600","6.31820","-0.00359"
"76.12800","6.34421","-0.00376"
"76.44000","6.37022","-0.00352"
"76.75200","6.39616","-0.00394"
"77.06400","6.42217","-0.00419"
"77.37600","6.44818","-0.00429"
"77.68800","6.47425","-0.00365"
"78.00000","6.50026","-0.00369"
"78.31200","6.52615","-0.00378"
"78.62400","6.55222","-0.00399"
"78.93600","6.57810","-0.00360"
"79.24800","6.60423","-0.00408"
"79.56000","6.63018","-0.00362"
"79.87200","6.65619","-0.00373"
"80.18400","6.68226","-0.00384"
"80.49600","6.70821","-0.00370"
"80.80800","6.73421","-0.00393"
"81.12000","6.76016","-0.00365"
"81.43200","6.78623","-0.00342"
"81.74400","6.81224","-0.00387"
"82.05600","6.83819","-0.00352"
"82.36800","6.86420","-0.00361"
"82.68000","6.89015","-0.00325"
"82.99200","6.91621","-0.00356"
"83.30400","6.94216","-0.00342"
"83.61600","6.96817","-0.00310"
"83.92800","6.99424","-0.00368"
"84.24000","7.02019","-0.00351"
"84.55200","7.04620","-0.00349"
"84.86400","7.07221","-0.00347"
"85.17600","7.09821","-0.00296"
"85.48800","7.12416","-0.00293"
"85.80000","7.15017","-0.00285"
"86.11200","7.17618","-0.00280"
"86.42400","7.20219","-0.00356"
"86.73600","7.22820","-0.00299"
"87.04800","7.25415","-0.00299"
"87.36000","7.28021","-0.00293"
"87.67200","7.30622","-0.00324"
"87.98400","7.33217","-0.00327"
"88.29600","7.35824","-0.00262"
"88.60800","7.38419","-0.00333"
"88.92000","7.41025","-0.00311"
"89.23200","7.43614","-0.00261"
"89.54400","7.46215","-0.00263"
"89.85600","7.48816","-0.00297"
"90.16800","7.51417","-0.00318"
"90.48000","7.54024","-0.00264"
"90.79200","7.56619","-0.00296"
"91.10400","7.59220","-0.00235"
"91.41600","7.61814","-0.00270"
"91.72800","7.64415","-0.00296"
"92.04000","7.67022","-0.00291"
"92.35200","7.69617","-0.00280"
"92.66400","7.72218","-0.00319"
"92.97600","7.74819","-0.00279"
"93.28800","7.77425","-0.00288"
"93.60000","7.80020","-0.00283"
"93.91200","7.82621","-0.00240"
"94.22400","7.85222","-0.00309"
"94.53600","7.87817","-0.00293"
"94.84800","7.90424","-0.00301"
"95.16000","7.93024","-0.00266"
"95.47200","7.95619","-0.00261"
"95.78400","7.98226","-0.00252"
"96.09600","8.00815","-0.00246"
"96.40800","8.03416","-0.00224"
"96.72000","8.06011","-0.00282"
"97.03200","8.08618","-0.00247"
"97.34400","8.11224","-0.00262"
"97.65600","8.13819","-0.00324"
"97.96800","8.16420","-0.00297"
"98.28000","8.19015","-0.00377"
"98.59200","8.21622","-0.00319"
"98.90400","8.24217","-0.00303"
"99.21600","8.26823","-0.00281"
"99.52800","8.29418","-0.00300"
"99.84000","8.32013","-0.00244"
"100.15200","8.34620","-0.00295"
"100.46400","8.37215","-0.00290"
"100.77600","8.39816","-0.00289"
"101.08800","8.42417","-0.00317"
"101.40000","8.45017","-0.00315"
"101.71200","8.47624","-0.00282"
"102.02400","8.50213","-0.00234"
"102.33600","8.52814","-0.00275"
"102.64800","8.55415","-0.00268"
"102.96000","8.58016","-0.00229"
"103.27200","8.60616","-0.00237"
"103.58400","8.63217","-0.00297"
"103.89600","8.65818","-0.00275"
"104.20800","8.68413","-0.00192"
"104.52000","8.71020","-0.00280"
"104.83200","8.73621","-0.00285"
"105.14400","8.76222","-0.00232"
"105.45600","8.78822","-0.00241"
"105.76800","8.81417","-0.00222"
"106.08000","8.84024","-0.00216"
"106.39200","8.86619","-0.00253"
"106.70400","8.89220","-0.00263"
"107.01600","8.91815","-0.00259"
"107.32800","8.94416","-0.00211"
"107.64000","8.97022","-0.00259"
"107.95200","8.99617","-0.00211"
"108.26400","9.02224","-0.00222"
"108.57600","9.04819","-0.00192"
"108.88800","9.07420","-0.00173"
"109.20000","9.10021","-0.00189"
"109.51200","9.12615","-0.00184"
"109.82400","9.15222","-0.00151"
"110.13600","9.17823","-0.00183"
"110.44800","9.20424","-0.00153"
"110.76000","9.23019","-0.00134"
"111.07200","9.25614","-0.00125"
"111.38400","9.28221","-0.00130"
"111.69600","9.30821","-0.00197"
"112.00800","9.33422","-0.00139"
"112.32000","9.36017","-0.00138"
"112.63200","9.38624","-0.00111"
"112.94400","9.41219","-0.00124"
"113.25600","9.43820","-0.00107"
"113.56800","9.46426","-0.00121"
"113.88000","9.49015","-0.00077"
"114.19200","9.51622","-0.00111"
"114.50400","9.54211","-0.00073"
"114.81600","9.56818","-0.00111"
"115.12800","9.59419","-0.00070"
"115.44000","9.62014","-0.00039"
"115.75200","9.64620","-0.00073"
"116.06400","9.67215","-0.00040"
"116.37600","9.69822","-0.00040"
"116.68800","9.72417","-0.00039"
"117.00000","9.75018","-0.00035"
"117.31200","9.77625","-0.00012"
"117.62400","9.80219","-0.00058"
"117.93600","9.82820","0.00003"
"118.24800","9.85415","0.00034"
"118.56000","9.88022","-0.00005"
"118.87200","9.90623","-0.00002"
"119.18400","9.93224","0.00007"
"119.49600","9.95825","0.00031"
"119.80800","9.98413","0.00032"
"120.12000","10.01020","0.00092"
"120.43200","10.03615","0.00048"
"120.74400","10.06228","0.00091"
"121.05600","10.08823","0.00104"
"121.36800","10.11412","0.00066"
"121.68000","10.14019","0.00053"
"121.99200","10.16613","0.00131"
"122.30400","10.19226","0.00113"
"122.61600","10.21821","0.00162"
"122.92800","10.24422","0.00133"
"123.24000","10.27023","0.00189"
"123.55200","10.29618","0.00146"
"123.86400","10.32224","0.00166"
"124.17600","10.34813","0.00232"
"124.48800","10.37426","0.00209"
"124.80000","10.40021","0.00207"
"125.11200","10.42616","0.00125"
"125.42400","10.45217","0.00193"
"125.73600","10.47818","0.00144"
"126.04800","10.50424","0.00254"
"126.36000","10.53019","0.00196"
"126.67200","10.55620","0.00235"
"126.98400","10.58221","0.00224"
"127.29600","10.60816","0.00074"
"127.60800","10.63423","0.00134"
"127.92000","10.66018","0.00175"
"128.23200","10.68618","0.00126"
"128.54400","10.71213","0.00208"
"128.85600","10.73820","0.00154"
"129.16800","10.76421","0.00217"
"129.48000","10.79016","0.00220"
"129.79200","10.81623","0.00241"
"130.10400","10.84217","0.00197"
"130.41600","10.86818","0.00204"
"130.72800","10.89419","0.00252"
"131.04000","10.92014","0.00269"
"131.35200","10.94621","0.00276"
"131.66400","10.97210","0.00329"
"131.97600","10.99823","0.00350"
"132.28800","11.02411","0.00356"
"132.60000","11.05018","0.00427"
"132.91200","11.07619","0.00473"
"133.22400","11.10220","0.00453"
"133.53600","11.12827","0.00509"
"133.84800","11.15416","0.00521"
"134.16000","11.18016","0.00532"
"134.47200","11.20617","0.00626"
"134.78400","11.23218","0.00589"
"135.09600","11.25825","0.00649"
"135.40800","11.28414","0.00684"
"135.72000","11.31021","0.00713"
"136.03200","11.33615","0.00671"
"136.34400","11.36222","0.00713"
"136.65600","11.38823","0.00762"
"136.96800","11.41418","0.00706"
"137.28000","11.44019","0.00784"
"137.59200","11.46614","0.00874"
"137.90400","11.49221","0.00859"
"138.21600","11.51822","0.00866"
"138.52800","11.54422","0.00945"
"138.84000","11.57023","0.00964"
"139.15200","11.59612","0.01007"
"139.46400","11.62219","0.01078"
"139.77600","11.64814","0.01083"
"140.08800","11.67420","0.01157"
"140.40000","11.70021","0.01173"
"140.71200","11.72616","0.01195"
"141.02400","11.75217","0.01273"
"141.33600","11.77812","0.01268"
"141.64800","11.80419","0.01287"
"141.96000","11.83020","0.01373"
"142.27200","11.85626","0.01411"
"142.58400","11.88221","0.01423"
"142.89600","11.90816","0.01437"
"143.20800","11.93417","0.01488"
"143.52000","11.96012","0.01484"
"143.83200","11.98619","0.01576"
"144.14400","12.01219","0.01582"
"144.45600","12.03821","0.01669"
"144.76800","12.06427","0.01719"
"145.08000","12.09022","0.01744"
"145.39200","12.11617","0.01836"
"145.70400","12.14218","0.01917"
"146.01600","12.16819","0.01974"
"146.32800","12.19420","0.02027"
"146.64000","12.22014","0.02052"
"146.95200","12.24615","0.02097"
"147.26400","12.27216","0.02138"
"147.57600","12.29823","0.02255"
"147.88800","12.32418","0.02290"
"148.20000","12.35018","0.02292"
"148.51200","12.37625","0.02315"
"148.82400","12.40214","0.02419"
"149.13600","12.42821","0.02483"
"149.44800","12.45416","0.02480"
"149.76000","12.48023","0.02645"
"150.07200","12.50618","0.02768"
"150.38400","12.53213","0.02833"
"150.69600","12.55819","0.02979"
"151.00800","12.58420","0.03063"
"151.32000","12.61027","0.03273"
"151.63200","12.63616","0.03308"
"151.94400","12.66223","0.03409"
"152.25600","12.68824","0.03504"
"152.56800","12.71418","0.03611"
"152.88000","12.74025","0.03705"
"153.19200","12.76620","0.03787"
"153.50400","12.79221","0.03915"
"153.81600","12.81816","0.03927"
"154.12800","12.84411","0.03977"
"154.44000","12.87024","0.04077"
"154.75200","12.89618","0.04128"
"155.06400","12.92219","0.04256"
"155.37600","12.94814","0.04356"
"155.68800","12.97421","0.04483"
"156.00000","13.00016","0.04568"
"156.31200","13.02617","0.04701"
"156.62400","13.05223","0.04826"
"156.93600","13.07812","0.05018"
"157.24800","13.10419","0.05188"
"157.56000","13.13014","0.05129"
"157.87200","13.15621","0.05358"
"158.18400","13.18222","0.05457"
"158.49600","13.20811","0.05735"
"158.80800","13.23417","0.05875"
"159.12000","13.26012","0.06014"
"159.43200","13.28625","0.06143"
"159.74400","13.31220","0.06238"
"160.05600","13.33821","0.06317"
"160.36800","13.36422","0.06464"
"160.68000","13.39016","0.06560"
"160.99200","13.41617","0.06660"
"161.30400","13.44218","0.06801"
"161.61600","13.46819","0.06895"
"161.92800","13.49420","0.07049"
"162.24000","13.52015","0.07212"
"162.55200","13.54622","0.07393"
"162.86400","13.57210","0.07550"
"163.17600","13.59817","0.07780"
"163.48800","13.62418","0.07891"
"163.80000","13.65019","0.07984"
"164.11200","13.67620","0.08239"
"164.42400","13.70215","0.08286"
"164.73600","13.72816","0.08496"
"165.04800","13.75410","0.08565"
"165.36000","13.78023","0.08750"
"165.67200","13.80618","0.08830"
"165.98400","13.83219","0.08912"
"166.29600","13.85826","0.09017"
"166.60800","13.88415","0.09125"
"166.92000","13.91022","0.09199"
"167.23200","13.93616","0.09270"
"167.54400","13.96217","0.09399"
"167.85600","13.98818","0.09512"
"168.16800","14.01419","0.09513"
"168.48000","14.04020","0.09684"
"168.79200","14.06615","0.09772"
"169.10400","14.09221","0.09928"
"169.41600","14.11816","0.09987"
"169.72800","14.14417","0.10177"
"170.04000","14.17018","0.10304"
"170.35200","14.19619","0.10410"
"170.66400","14.22226","0.10606"
"170.97600","14.24821","0.10781"
"171.28800","14.27415","0.10887"
"171.60000","14.30016","0.11088"
"171.91200","14.32611","0.11204"
"172.22400","14.35218","0.11318"
"172.53600","14.37813","0.11436"
"172.84800","14.40420","0.11607"
"173.16000","14.43020","0.11750"
"173.47200","14.45621","0.11952"
"173.78400","14.48216","0.12086"
"174.09600","14.50817","0.12340"
"174.40800","14.53424","0.12605"
"174.72000","14.56019","0.12836"
"175.03200","14.58619","0.13144"
"175.34400","14.61214","0.13478"
"175.65600","14.63815","0.13712"
"175.96800","14.66422","0.13918"
"176.28000","14.69017","0.14151"
"176.59200","14.71624","0.14371"
"176.90400","14.74219","0.14482"
"177.21600","14.76820","0.14639"
"177.52800","14.79420","0.14868"
"177.84000","14.82021","0.15063"
"178.15200","14.84622","0.15263"
"178.46400","14.87217","0.15536"
"178.77600","14.89818","0.15861"
"179.08800","14.92413","0.16128"
"179.40000","14.95019","0.16409"
"179.71200","14.97620","0.16687"
"180.02400","15.00215","0.16822"
"180.33600","15.02816","0.17027"
"180.64800","15.05417","0.17184"
"180.96000","15.08024","0.17332"
"181.27200","15.10618","0.17499"
"181.58400","15.13225","0.17709"
"181.89600","15.15826","0.17866"
"182.20800","15.18415","0.18050"
"182.52000","15.21022","0.14450"
"182.83200","15.23611","0.12455"
"183.14400","15.26223","0.12220"
"183.45600","15.28824","0.11343"
"183.76800","15.31419","0.10863"
"184.08000","15.34020","0.10869"
"184.39200","15.36609","0.10398"
"184.70400","15.39222","0.10081"
"185.01600","15.41823","0.10136"
"185.32800","15.44423","0.10278"
"185.64000","15.47018","0.10398"
"185.95200","15.49619","0.10642"
"186.26400","15.52220","0.10804"
"186.57600","15.54809","0.10905"
"186.88800","15.57422","0.11061"
"187.20000","15.60017","0.11199"
"187.51200","15.62617","0.11333"
"187.82400","15.65224","0.11511"
"188.13600","15.67819","0.11649"
"188.44800","15.70420","0.11815"
"188.76000","15.73015","0.12006"
"189.07200","15.75622","0.12362"
"189.38400","15.78222","0.12647"
"189.69600","15.80817","0.13106"
"190.00800","15.83418","0.13394"
"190.32000","15.86013","0.13760"
"190.63200","15.88620","0.14034"
"190.94400","15.91215","0.14260"
"191.25600","15.93822","0.14509"
"191.56800","15.96422","0.14670"
"191.88000","15.99011","0.14887"
"192.19200","16.01624","0.15104"
"192.50400","16.04219","0.15392"
"192.81600","16.06820","0.15738"
"193.12800","16.09415","0.16037"
"193.44000","16.12016","0.16379"
"193.75200","16.14622","0.16623"
"194.06400","16.17217","0.16913"
"194.37600","16.19824","0.17124"
"194.68800","16.22419","0.17320"
"195.00000","16.25014","0.17545"
"195.31200","16.27621","0.17773"
"195.62400","16.30221","0.18018"
"195.93600","16.32822","0.18202"
"196.24800","16.35417","0.18301"
"196.56000","16.38024","0.18525"
"196.87200","16.40619","0.18825"
"197.18400","16.43214","0.19074"
"197.49600","16.45820","0.19350"
"197.80800","16.48421","0.19623"
"198.12000","16.51022","0.19896"
"198.43200","16.53611","0.20126"
"198.74400","16.56218","0.20350"
"199.05600","16.58819","0.20562"
"199.36800","16.61419","0.20773"
"199.68000","16.64021","0.20949"
"199.99200","16.66615","0.21116"
"200.30400","16.69222","0.21343"
"200.61600","16.71811","0.21553"
"200.92800","16.74418","0.21777"
"201.24000","16.77019","0.22005"
"201.55200","16.79613","0.22232"
"201.86400","16.82220","0.22416"
"202.17600","16.84809","0.22595"
"202.48800","16.87422","0.22850"
"202.80000","16.90017","0.23168"
"203.11200","16.92624","0.23530"
"203.42400","16.95219","0.23795"
"203.73600","16.97814","0.24029"
"204.04800","17.00420","0.24233"
"204.36000","17.03015","0.24509"
"204.67200","17.05622","0.24824"
"204.98400","17.08217","0.25017"
"205.29600","17.10818","0.25389"
"205.60800","17.13419","0.25753"
"205.92000","17.16007","0.26147"
"206.23200","17.18620","0.26526"
"206.54400","17.21221","0.26611"
"206.85600","17.23822","0.22054"
"207.16800","17.26423","0.22351"
"207.48000","17.29012","0.22602"
"207.79200","17.31618","0.22986"
"208.10400","17.34213","0.23486"
"208.41600","17.36826","0.23924"
"208.72800","17.39421","0.24274"
"209.04000","17.42022","0.24663"
"209.35200","17.44623","0.24965"
"209.66400","17.47212","0.25340"
"209.97600","17.49824","0.25896"
"210.28800","17.52419","0.26327"
"210.60000","17.55026","0.26679"
"210.91200","17.57621","0.27086"
"211.22400","17.60216","0.27454"
"211.53600","17.62823","0.27911"
"211.84800","17.65417","0.28540"
"212.16000","17.68024","0.28982"
"212.47200","17.70619","0.29464"
"212.78400","17.73220","0.29502"
"213.09600","17.75821","0.29811"
"213.40800","17.78416","0.30074"
"213.72000","17.81023","0.30329"
"214.03200","17.83617","0.30477"
"214.34400","17.86218","0.30796"
"214.65600","17.88819","0.31042"
"214.96800","17.91414","0.31330"
"215.28000","17.94021","0.31599"
"215.59200","17.96616","0.31833"
"215.90400","17.99216","0.32024"
"216.21600","18.01817","0.32290"
"216.52800","18.04418","0.32501"
"216.84000","18.07019","0.32804"
"217.15200","18.09620","0.33204"
"217.46400","18.12227","0.33470"
"217.77600","18.14816","0.34025"
"218.08800","18.17422","0.34434"
"218.40000","18.20011","0.34771"
"218.71200","18.22612","0.35098"
"219.02400","18.25225","0.35540"
"219.33600","18.27814","0.36003"
"219.64800","18.30421","0.36569"
"219.96000","18.33015","0.36999"
"220.27200","18.35622","0.37445"
"220.58400","18.38217","0.37659"
"220.89600","18.40818","0.37965"
"221.20800","18.43425","0.38392"
"221.52000","18.46014","0.38820"
"221.83200","18.48621","0.39311"
"222.14400","18.51221","0.39690"
"222.45600","18.53822","0.39889"
"222.76800","18.56423","0.40225"
"223.08000","18.59018","0.40513"
"223.39200","18.61619","0.40823"
"223.70400","18.64214","0.41145"
"224.01600","18.66821","0.41528"
"224.32800","18.69421","0.41971"
"224.64000","18.72016","0.42367"
"224.95200","18.74623","0.42307"
"225.26400","18.77212","0.42664"
"225.57600","18.79819","0.43062"
"225.88800","18.82414","0.43407"
"226.20000","18.85021","0.43893"
"226.51200","18.87621","0.44349"
"226.82400","18.90216","0.44781"
"227.13600","18.92817","0.45127"
"227.44800","18.95412","0.45416"
"227.76000","18.98025","0.45848"
"228.07200","19.00620","0.46357"
"228.38400","19.03220","0.46937"
"228.69600","19.05821","0.47442"
"229.00800","19.08410","0.47803"
"229.32000","19.11017","0.48203"
"229.63200","19.13612","0.48610"
"229.94400","19.16219","0.49233"
"230.25600","19.18814","0.49833"
"230.56800","19.21414","0.50451"
"230.88000","19.24021","0.50878"
"231.19200","19.26616","0.51212"
"231.50400","19.29217","0.51492"
"231.81600","19.31818","0.51728"
"232.12800","19.34419","0.52013"
"232.44000","19.37020","0.52388"
"232.75200","19.39614","0.52704"
"233.06400","19.42221","0.53223"
"233.37600","19.44816","0.53576"
"233.68800","19.47417","0.53999"
"234.00000","19.50018","0.54554"
"234.31200","19.52619","0.55025"
"234.62400","19.55219","0.55407"
"234.93600","19.57814","0.55814"
"235.24800","19.60427","0.55826"
"235.56000","19.63022","0.56375"
"235.87200","19.65623","0.57089"
"236.18400","19.68218","0.57716"
"236.49600","19.70812","0.58159"
"236.80800","19.73425","0.58642"
"237.12000","19.76020","0.59232"
"237.43200","19.78621","0.59608"
"237.74400","19.81216","0.60043"
"238.05600","19.83817","0.60446"
"238.36800","19.86418","0.60835"
"238.68000","19.89018","0.61194"
"238.99200","19.91625","0.61636"
"239.30400","19.94220","0.62076"
"239.61600","19.96821","0.62427"
"239.92800","19.99416","0.62830"
"240.24000","20.02017","0.63328"
"240.55200","20.04623","0.63926"
"240.86400","20.07218","0.64557"
"241.17600","20.09819","0.65316"
"241.48800","20.12414","0.65734"
"241.80000","20.15021","0.66206"
"242.11200","20.17622","0.49340"
"242.42400","20.20222","0.49526"
"242.73600","20.22824","0.30355"
"243.04800","20.25412","0.30899"
"243.36000","20.28019","0.31632"
"243.67200","20.30620","0.31797"
"243.98400","20.33221","0.32277"
"244.29600","20.35822","0.32541"
"244.60800","20.38410","0.33005"
"244.92000","20.41018","0.33934"
"245.23200","20.43618","0.34400"
"245.54400","20.46219","0.35226"
"245.85600","20.48820","0.35634"
"246.16800","20.51421","0.36842"
"246.48000","20.54022","0.37378"
"246.79200","20.56617","0.38093"
"247.10400","20.59217","0.38675"
"247.41600","20.61812","0.39721"
"247.72800","20.64425","0.40082"
"248.04000","20.67020","0.40658"
"248.35200","20.69615","0.41023"
"248.66400","20.72215","0.41642"
"248.97600","20.74817","0.42174"
"249.28800","20.77417","0.42754"
"249.60000","20.80018","0.43388"
"249.91200","20.82625","0.43936"
"250.22400","20.85220","0.44815"
"250.53600","20.87815","0.45073"
"250.84800","20.90421","0.45805"
"251.16000","20.93016","0.46638"
"251.47200","20.95623","0.47450"
"251.78400","20.98224","0.48049"
"252.09600","21.00819","0.48600"
"252.40800","21.03420","0.49325"
"252.72000","21.06015","0.50129"
"253.03200","21.08621","0.50877"
"253.34400","21.11216","0.51497"
"253.65600","21.13823","0.51902"
"253.96800","21.16418","0.52424"
"254.28000","21.19019","0.53019"
"254.59200","21.21620","0.53478"
"254.90400","21.24215","0.53916"
"255.21600","21.26821","0.54700"
"255.52800","21.29416","0.55392"
"255.84000","21.32017","0.55935"
"256.15200","21.34618","0.56727"
"256.46400","21.37225","0.57411"
"256.77600","21.39826","0.57967"
"257.08800","21.42420","0.58580"
"257.40000","21.45021","0.59358"
"257.71200","21.47616","0.59990"
"258.02400","21.50217","0.60404"
"258.33600","21.52818","0.60768"
"258.64800","21.55413","0.61414"
"258.96000","21.58019","0.61988"
"259.27200","21.60614","0.62366"
"259.58400","21.63215","0.62787"
"259.89600","21.65822","0.63336"
"260.20800","21.68417","0.64017"
"260.52000","21.71018","0.64829"
"260.83200","21.73613","0.65510"
"261.14400","21.76219","0.66107"
"261.45600","21.78814","0.66928"
"261.76800","21.81421","0.67897"
"262.08000","21.84022","0.68449"
"262.39200","21.86617","0.69080"
"262.70400","21.89224","0.70192"
"263.01600","21.91813","0.70844"
"263.32800","21.94419","0.71330"
"263.64000","21.97020","0.71951"
"263.95200","21.99621","0.72402"
"264.26400","22.02222","0.72902"
"264.57600","22.04817","0.73506"
"264.88800","22.07417","0.73521"
"265.20000","22.10012","0.73806"
"265.51200","22.12619","0.74318"
"265.82400","22.15220","0.74659"
"266.13600","22.17815","0.67978"
"266.44800","22.20422","0.68270"
"266.76000","22.23017","0.68695"
"267.07200","22.25624","0.47367"
"267.38400","22.28224","0.47961"
"267.69600","22.30819","0.48127"
"268.00800","22.33420","0.48956"
"268.32000","22.36015","0.49441"
"268.63200","22.38622","0.50053"
"268.94400","22.41217","0.50801"
"269.25600","22.43824","0.50927"
"269.56800","22.46424","0.51397"
"269.88000","22.49019","0.51568"
"270.19200","22.51620","0.51810"
"270.50400","22.54209","0.52400"
"270.81600","22.56828","0.18042"
"271.12800","22.59417","0.16997"
"271.44000","22.62017","0.16432"
"271.75200","22.64618","0.18283"
"272.06400","22.67213","0.22152"
"272.37600","22.69820","0.20929"
"272.68800","22.72421","0.19038"
"273.00000","22.75022","0.19912"
"273.31200","22.77617","0.20372"
"273.62400","22.80217","0.20898"
"273.93600","22.82824","0.23085"
"274.24800","22.85419","0.25954"
"274.56000","22.88020","0.25796"
"274.87200","22.90615","0.24115"
"275.18400","22.93216","0.23844"
"275.49600","22.95822","0.24534"
"275.80800","22.98411","0.25611"
"276.12000","23.01018","0.26380"
"276.43200","23.03619","0.26685"
"276.74400","23.06220","0.27062"
"277.05600","23.08815","0.28194"
"277.36800","23.11422","0.29646"
"277.68000","23.14022","0.30602"
"277.99200","23.16617","0.31555"
"278.30400","23.19224","0.32332"
"278.61600","23.21819","0.32865"
"278.92800","23.24420","0.33618"
"279.24000","23.27015","0.34486"
"279.55200","23.29616","0.35001"
"279.86400","23.32222","0.35529"
"280.17600","23.34817","0.36311"
"280.48800","23.37424","0.37075"
"280.80000","23.40019","0.37576"
"281.11200","23.42620","0.37941"
"281.42400","23.45220","0.38279"
"281.73600","23.47815","0.38731"
"282.04800","23.50422","0.39173"
"282.36000","23.53017","0.39391"
"282.67200","23.55618","0.39509"
"282.98400","23.58219","0.39678"
"283.29600","23.60814","0.39898"
"283.60800","23.63426","0.40221"
"283.92000","23.66015","0.40574"
"284.23200","23.68616","0.40936"
"284.54400","23.71217","0.41452"
"284.85600","23.73818","0.41932"
"285.16800","23.76418","0.42630"
"285.48000","23.79020","0.43382"
"285.79200","23.81621","0.44477"
"286.10400","23.84209","0.45361"
"286.41600","23.86822","0.46075"
"286.72800","23.89417","0.46164"
"287.04000","23.92024","0.46107"
"287.35200","23.94625","0.46500"
"287.66400","23.97213","0.47174"
"287.97600","23.99821","0.47724"
"288.28800","24.02409","0.48322"
"288.60000","24.05022","0.49671"
"288.91200","24.07617","0.50823"
"289.22400","24.10218","0.51022"
"289.53600","24.12819","0.50960"
"289.84800","24.15413","0.51243"
"290.16000","24.18020","0.51582"
"290.47200","24.20621","0.52045"
"290.78400","24.23222","0.53041"
"291.09600","24.25817","0.53670"
"291.40800","24.28418","0.53627"
"291.72000","24.31018","0.53797"
"292.03200","24.33613","0.54387"
"292.34400","24.36220","0.55154"
"292.65600","24.38821","0.56289"
"292.96800","24.41422","0.56864"
"293.28000","24.44023","0.56852"
"293.59200","24.46618","0.57471"
"293.90400","24.49218","0.58214"
"294.21600","24.51813","0.59613"
"294.52800","24.54420","0.60033"
"294.84000","24.57021","0.60052"
"295.15200","24.59616","0.60467"
"295.46400","24.62223","0.61136"
"295.77600","24.64818","0.61912"
"296.08800","24.67424","0.62023"
"296.40000","24.70013","0.62270"
"296.71200","24.72620","0.62977"
"297.02400","24.75221","0.64065"
"297.33600","24.77816","0.64365"
"297.64800","24.80423","0.64929"
"297.96000","24.83011","0.65699"
"298.27200","24.85618","0.66671"
"298.58400","24.88219","0.66777"
"298.89600","24.90814","0.67392"
"299.20800","24.93421","0.68518"
"299.52000","24.96022","0.68992"
"299.83200","24.98629","0.69145"
"300.14400","25.01217","0.69971"
"300.45600","25.03818","0.71041"
"300.76800","25.06419","0.71187"
"301.08000","25.09020","0.71568"
"301.39200","25.11627","0.72246"
"301.70400","25.14215","0.72452"
"302.01600","25.16822","0.72721"
"302.32800","25.19417","0.73380"
"302.64000","25.22018","0.39464"
"302.95200","25.24619","0.40403"
"303.26400","25.27214","0.41149"
"303.57600","25.29821","0.41281"
"303.88800","25.32409","0.41339"
"304.20000","25.35022","0.41558"
"304.51200","25.37617","0.42074"
"304.82400","25.40218","0.42815"
"305.13600","25.42825","0.43380"
"305.44800","25.45420","0.43788"
"305.76000","25.48021","0.44488"
"306.07200","25.50615","0.45049"
"306.38400","25.53216","0.45595"
"306.69600","25.55823","0.46311"
"307.00800","25.58418","0.47457"
"307.32000","25.61019","0.48138"
"307.63200","25.63614","0.48501"
"307.94400","25.66215","0.48532"
"308.25600","25.68815","0.49107"
"308.56800","25.71422","0.50051"
"308.88000","25.74029","0.50547"
"309.19200","25.76618","0.50946"
"309.50400","25.79219","0.51625"
"309.81600","25.81820","0.52144"
"310.12800","25.84421","0.52271"
"310.44000","25.87021","0.52537"
"310.75200","25.89616","0.53168"
"311.06400","25.92223","0.53414"
"311.37600","25.94812","0.54085"
"311.68800","25.97419","0.55006"
"312.00000","26.00020","0.55227"
"312.31200","26.02621","0.44319"
"312.62400","26.05227","0.43980"
"312.93600","26.07816","0.44661"
"313.24800","26.10417","0.44770"
"313.56000","26.13012","0.44949"
"313.87200","26.15625","0.45520"
"314.18400","26.18220","0.46401"
"314.49600","26.20820","0.47046"
"314.80800","26.23421","0.47572"
"315.12000","26.26016","0.48077"
"315.43200","26.28617","0.48300"
"315.74400","26.31218","0.48841"
"316.05600","26.33825","0.49551"
"316.36800","26.36414","0.50146"
"316.68000","26.39014","0.50872"
"316.99200","26.41621","0.51452"
"317.30400","26.44216","0.51737"
"317.61600","26.46817","0.52055"
"317.92800","26.49418","0.52506"
"318.24000","26.52013","0.52995"
"318.55200","26.54620","0.53382"
"318.86400","26.57214","0.53835"
"319.17600","26.59821","0.54403"
"319.48800","26.62416","0.54888"
"319.80000","26.65017","0.40854"
"320.11200","26.67618","0.40947"
"320.42400","26.70213","0.41092"
"320.73600","26.72819","0.41052"
"321.04800","26.75414","0.23515"
"321.36000","26.78021","0.22819"
"321.67200","26.80622","0.23020"
"321.98400","26.83217","0.23568"
"322.29600","26.85818","0.23911"
"322.60800","26.88418","0.24472"
"322.92000","26.91025","0.24906"
"323.23200","26.93620","0.25124"
"323.54400","26.96221","0.25645"
"323.85600","26.98816","0.26133"
"324.16800","27.01417","0.26500"
"324.48000","27.04023","0.26004"
"324.79200","27.06618","0.26290"
"325.10400","27.09219","0.26668"
"325.41600","27.11814","0.26874"
"325.72800","27.14421","0.27341"
"326.04000","27.17016","0.28056"
"326.35200","27.19617","0.28825"
"326.66400","27.22223","0.29370"
"326.97600","27.24818","0.29777"
"327.28800","27.27419","0.30138"
"327.60000","27.30014","0.30427"
"327.91200","27.32621","0.30753"
"328.22400","27.35222","0.31025"
"328.53600","27.37816","0.31278"
"328.84800","27.40423","0.31570"
"329.16000","27.43012","0.31811"
"329.47200","27.45619","0.32076"
"329.78400","27.48220","0.32333"
"330.09600","27.50821","0.32589"
"330.40800","27.53422","0.32949"
"330.72000","27.56016","0.33402"
"331.03200","27.58623","0.33882"
"331.34400","27.61212","0.34413"
"331.65600","27.63819","0.34886"
"331.96800","27.66420","0.35331"
"332.28000","27.69015","0.35878"
"332.59200","27.71616","0.36548"
"332.90400","27.74216","0.37051"
"333.21600","27.76818","0.37463"
"333.52800","27.79418","0.37793"
"333.84000","27.82025","0.38137"
"334.15200","27.84620","0.38591"
"334.46400","27.87221","0.39151"
"334.77600","27.89816","0.39110"
"335.08800","27.92410","0.24447"
"335.40000","27.95023","0.24081"
"335.71200","27.97618","0.24256"
"336.02400","28.00219","0.24732"
"336.33600","28.02820","0.25372"
"336.64800","28.05415","0.26262"
"336.96000","28.08021","0.27117"
"337.27200","28.10616","0.27870"
"337.58400","28.13223","0.28015"
"337.89600","28.15818","0.27846"
"338.20800","28.18419","0.27707"
"338.52000","28.21026","0.27740"
"338.83200","28.23615","0.28088"
"339.14400","28.26227","0.28525"
"339.45600","28.28822","0.29063"
"339.76800","28.31417","0.29565"
"340.08000","28.34018","0.29992"
"340.39200","28.36619","0.30306"
"340.70400","28.39226","0.30625"
"341.01600","28.41821","0.30929"
"341.32800","28.44421","0.31186"
"341.64000","28.47016","0.31336"
"341.95200","28.49617","0.31474"
"342.26400","28.52218","0.31594"
"342.57600","28.54819","0.31726"
"342.88800","28.57425","0.31901"
"343.20000","28.60014","0.32038"
"343.51200","28.62615","0.32302"
"343.82400","28.65216","0.32501"
"344.13600","28.67817","0.32765"
"344.44800","28.70424","0.32973"
"344.76000","28.73019","0.33234"
"345.07200","28.75620","0.33580"
"345.38400","28.78220","0.33860"
"345.69600","28.80815","0.34281"
"346.00800","28.83422","0.34622"
"346.32000","28.86011","0.34970"
"346.63200","28.88618","0.35339"
"346.94400","28.91213","0.35713"
"347.25600","28.93819","0.36257"
"347.56800","28.96414","0.36848"
"347.88000","28.99021","0.37085"
"348.19200","29.01628","0.37420"
"348.50400","29.04211","0.37645"
"348.81600","29.06824","0.37888"
"349.12800","29.09413","0.38136"
"349.44000","29.12019","0.38570"
"349.75200","29.14620","0.39014"
"350.06400","29.17215","0.39397"
"350.37600","29.19822","0.39819"
"350.68800","29.22411","0.40066"
"351.00000","29.25018","0.40350"
"351.31200","29.27618","0.40525"
"351.62400","29.30219","0.40813"
"351.93600","29.32826","0.41088"
"352.24800","29.35415","0.41394"
"352.56000","29.38016","0.41743"
"352.87200","29.40617","0.42045"
"353.18400","29.43224","0.42273"
"353.49600","29.45818","0.42489"
"353.80800","29.48413","0.42764"
"354.12000","29.51026","0.43102"
"354.43200","29.53615","0.35209"
"354.74400","29.56222","0.34378"
"355.05600","29.58817","0.34273"
"355.36800","29.61418","0.34242"
"355.68000","29.64024","0.34482"
"355.99200","29.66619","0.34688"
"356.30400","29.69220","0.34907"
"356.61600","29.71809","0.35215"
"356.92800","29.74422","0.35534"
"357.24000","29.77017","0.36044"
"357.55200","29.79623","0.36353"
"357.86400","29.82218","0.19655"
"358.17600","29.84813","0.19812"
"358.48800","29.87420","0.19918"
"358.80000","29.90015","0.20119"
"359.11200","29.92622","0.20179"
"359.42400","29.95223","0.20192"
"359.73600","29.97817","0.20328"
"360.04800","30.00418","0.20492"
"360.36000","30.03019","0.20648"
"360.67200","30.05620","0.20777"
"360.98400","30.08215","0.20867"
"361.29600","30.10816","0.20956"
"361.60800","30.13416","0.21021"
"361.92000","30.16017","0.21209"
"362.23200","30.18624","0.21424"
"362.54400","30.21219","0.21694"
"362.85600","30.23820","0.21823"
"363.16800","30.26421","0.21974"
"363.48000","30.29016","0.22115"
"363.79200","30.31623","0.22231"
"364.10400","30.34217","0.22426"
"364.41600","30.36824","0.22600"
"364.72800","30.39419","0.00641"
"365.04000","30.42020","0.00932"
"365.35200","30.44615","0.00735"
"365.66400","30.47216","0.00922"
"365.97600","30.49828","0.01047"
"366.28800","30.52417","0.00750"
"366.60000","30.55024","0.01160"
"366.91200","30.57619","0.00845"
"367.22400","30.60220","0.00670"
"367.53600","30.62820","0.01280"
"367.84800","30.65415","0.01073"
"368.16000","30.68022","0.00870"
"368.47200","30.70611","0.01434"
"368.78400","30.73218","0.00984"
"369.09600","30.75819","0.01123"
"369.40800","30.78420","0.01589"
"369.72000","30.81026","0.01121"
"370.03200","30.83621","0.01655"
"370.34400","30.86222","0.01835"
"370.65600","30.88817","0.01404"
"370.96800","30.91424","0.01657"
"371.28000","30.94025","0.01565"
"371.59200","30.96614","0.01277"
"371.90400","30.99221","0.01522"
"372.21600","31.01809","0.01526"
"372.52800","31.04422","0.01542"
"372.84000","31.07023","0.01719"
"373.15200","31.09624","0.01575"
"373.46400","31.12225","0.01163"
"373.77600","31.14814","0.01641"
"374.08800","31.17426","0.01494"
"374.40000","31.20015","0.01477"
"374.71200","31.22622","0.01713"
"375.02400","31.25217","0.01546"
"375.33600","31.27817","0.01569"
"375.64800","31.30418","0.01804"
"375.96000","31.33007","0.01711"
"376.27200","31.35620","0.01654"
"376.58400","31.38221","0.01938"
"376.89600","31.40822","0.01717"
"377.20800","31.43417","0.01763"
"377.52000","31.46018","0.01945"
"377.83200","31.48618","0.01862"
"378.14400","31.51213","0.01166"
"378.45600","31.53820","0.01856"
"378.76800","31.56421","0.02375"
"379.08000","31.59016","0.01467"
"379.39200","31.61623","0.01029"
"379.70400","31.64212","0.03683"
"380.01600","31.66824","0.01604"
"380.32800","31.69419","0.01280"
"380.64000","31.72026","0.02829"
"380.95200","31.74627","0.01453"
"381.26400","31.77216","0.01710"
"381.57600","31.79823","0.03267"
"381.88800","31.82412","0.01968"
"382.20000","31.85018","0.01707"
"382.51200","31.87613","0.03135"
"382.82400","31.90220","0.01753"
"383.13600","31.92821","0.01802"
"383.44800","31.95416","0.03134"
"383.76000","31.98022","0.02042"
"384.07200","32.00618","0.02203"
"384.38400","32.03218","0.03228"
"384.69600","32.05819","0.02792"
"385.00800","32.08414","0.02052"
"385.32000","32.11021","0.03374"
"385.63200","32.13616","0.02728"
"385.94400","32.16222","0.02251"
"386.25600","32.18818","0.03033"
"386.56800","32.21412","0.03239"
"386.88000","32.24019","0.02466"
"387.19200","32.26620","0.03061"
"387.50400","32.29221","0.03717"
"387.81600","32.31816","0.02827"
"388.12800","32.34422","0.03361"
"388.44000","32.37017","0.03827"
"388.75200","32.39612","0.03635"
"389.06400","32.42225","0.03281"
"389.37600","32.44814","0.04128"
"389.68800","32.47421","0.03916"
"390.00000","32.50016","0.03716"
"390.31200","32.52622","0.04275"
"390.62400","32.55217","0.04118"
"390.93600","32.57818","0.04106"
"391.24800","32.60425","0.04005"
"391.56000","32.63020","0.04241"
"391.87200","32.65620","0.03982"
"392.18400","32.68209","0.04219"
"392.49600","32.70823","0.04761"
"392.80800","32.73423","0.04529"
"393.12000","32.76018","0.04467"
"393.43200","32.78625","0.05029"
"393.74400","32.81214","0.05088"
"394.05600","32.83814","0.04829"
"394.36800","32.86421","0.05281"
"394.68000","32.89022","0.05696"
"394.99200","32.91623","0.05483"
"395.30400","32.94212","0.05763"
"395.61600","32.96819","0.06203"
"395.92800","32.99419","0.06167"
"396.24000","33.02021","0.06222"
"396.55200","33.04621","0.06541"
"396.86400","33.07216","0.06630"
"397.17600","33.09823","0.06689"
"397.48800","33.12412","0.06973"
"397.80000","33.15018","0.07179"
"398.11200","33.17619","0.07298"
"398.42400","33.20221","0.07743"
"398.73600","33.22821","0.08008"
"399.04800","33.25416","0.08168"
"399.36000","33.28023","0.08543"
"399.67200","33.30618","0.08691"
"399.98400","33.33225","0.08786"
"400.29600","33.35819","0.08923"
"400.60800","33.38414","0.09160"
"400.92000","33.41015","0.09286"
"401.23200","33.43616","0.09437"
"401.54400","33.46223","0.09646"
"401.85600","33.48824","0.09775"
"402.16800","33.51425","0.09946"
"402.48000","33.54019","0.10264"
"402.79200","33.56620","0.10431"
"403.10400","33.59221","0.10662"
"403.41600","33.61816","0.10905"
"403.72800","33.64423","0.11153"
"404.04000","33.67018","0.11295"
"404.35200","33.69613","0.11587"
"404.66400","33.72219","0.11843"
"404.97600","33.74814","0.11994"
"405.28800","33.77421","0.12477"
"405.60000","33.80022","0.13067"
"405.91200","33.82617","0.13318"
"406.22400","33.85218","0.13790"
"406.53600","33.87819","0.14255"
"406.84800","33.90419","0.14369"
"407.16000","33.93014","0.14694"
"407.47200","33.95621","0.15075"
"407.78400","33.98216","0.15164"
"408.09600","34.00817","0.15478"
"408.40800","34.03417","0.16251"
"408.72000","34.06018","0.16523"
"409.03200","34.08625","0.16594"
"409.34400","34.11220","0.17088"
"409.65600","34.13821","0.17373"
"409.96800","34.16416","0.17379"
"410.28000","34.19017","0.17651"
"410.59200","34.21617","0.18169"
"410.90400","34.24212","0.18349"
"411.21600","34.26819","0.18502"
"411.52800","34.29414","0.18940"
"411.84000","34.32021","0.19206"
"412.15200","34.34621","0.19389"
"412.46400","34.37217","0.19727"
"412.77600","34.39823","0.20023"
"413.08800","34.42418","0.20231"
"413.40000","34.45019","0.20413"
"413.71200","34.47620","0.20593"
"414.02400","34.50221","0.20818"
"414.33600","34.52821","0.20902"
"414.64800","34.55416","0.21136"
"414.96000","34.58023","0.21482"
"415.27200","34.60612","0.21678"
"415.58400","34.63219","0.21842"
"415.89600","34.65820","0.22104"
"416.20800","34.68421","0.22408"
"416.52000","34.71021","0.22633"
"416.83200","34.73610","0.22856"
"417.14400","34.76223","0.23134"
"417.45600","34.78812","0.23449"
"417.76800","34.81419","0.23725"
"418.08000","34.84014","0.23930"
"418.39200","34.86615","0.24214"
"418.70400","34.89215","0.24488"
"419.01600","34.91810","0.24705"
"419.32800","34.94423","0.24851"
"419.64000","34.97018","0.25202"
"419.95200","34.99625","0.25570"
"420.26400","35.02219","0.25908"
"420.57600","35.04815","0.26134"
"420.88800","35.07415","0.26425"
"421.20000","35.10016","0.26658"
"421.51200","35.12623","0.26880"
"421.82400","35.15218","0.27065"
"422.13600","35.17819","0.27331"
"422.44800","35.20420","0.27733"
"422.76000","35.23014","0.28181"
"423.07200","35.25621","0.28412"
"423.38400","35.28216","0.28702"
"423.69600","35.30823","0.28941"
"424.00800","35.33424","0.29369"
"424.32000","35.36013","0.29636"
"424.63200","35.38620","0.29837"
"424.94400","35.41220","0.30079"
"425.25600","35.43821","0.30244"
"425.56800","35.46410","0.30343"
"425.88000","35.49023","0.30538"
"426.19200","35.51624","0.08345"
"426.50400","35.54219","0.05701"
"426.81600","35.56826","0.00887"
"427.12800","35.59414","0.03854"
"427.44000","35.62021","0.07642"
"427.75200","35.64616","0.02628"
"428.06400","35.67217","0.02186"
"428.37600","35.69824","0.06942"
"428.68800","35.72419","0.06185"
"429.00000","35.75019","0.02627"
"429.31200","35.77620","0.04469"
"429.62400","35.80215","0.07748"
"429.93600","35.82822","0.04900"
"430.24800","35.85417","0.03606"
"430.56000","35.88024","0.06467"
"430.87200","35.90612","0.07105"
"431.18400","35.93225","0.04486"
"431.49600","35.95820","0.04904"
"431.80800","35.98421","0.07491"
"432.12000","36.01022","0.06659"
"432.43200","36.03617","0.05153"
"432.74400","36.06218","0.06553"
"433.05600","36.08812","0.08189"
"433.36800","36.11419","0.06537"
"433.68000","36.14021","0.06338"
"433.99200","36.16621","0.08124"
"434.30400","36.19222","0.08313"
"434.61600","36.21811","0.06825"
"434.92800","36.24424","0.07752"
"435.24000","36.27018","0.08925"
"435.55200","36.29619","0.08403"
"435.86400","36.32226","0.08101"
"436.17600","36.34815","0.09096"
"436.48800","36.37416","0.09250"
"436.80000","36.40017","0.08890"
"437.11200","36.42617","0.09237"
"437.42400","36.45219","0.09774"
"437.73600","36.47825","0.09501"
"438.04800","36.50426","0.09547"
"438.36000","36.53015","0.10145"
"438.67200","36.55622","0.10322"
"438.98400","36.58216","0.10064"
"439.29600","36.60817","0.10614"
"439.60800","36.63419","0.11059"
"439.92000","36.66013","0.10860"
"440.23200","36.68620","0.11211"
"440.54400","36.71209","0.11748"
"440.85600","36.73822","0.11691"
"441.16800","36.76423","0.11923"
"441.48000","36.79017","0.12598"
"441.79200","36.81624","0.12955"
"442.10400","36.84219","0.13217"
"442.41600","36.86820","0.13751"
"442.72800","36.89415","0.14235"
"443.04000","36.92022","0.14431"
"443.35200","36.94617","0.14541"
"443.66400","36.97217","0.14952"
"443.97600","36.99818","0.15415"
"444.28800","37.02413","0.15531"
"444.60000","37.05026","0.15824"
"444.91200","37.07621","0.16531"
"445.22400","37.10221","0.16734"
"445.53600","37.12817","0.16813"
"445.84800","37.15417","0.17234"
"446.16000","37.18018","0.17568"
"446.47200","37.20619","0.17526"
"446.78400","37.23220","0.17823"
"447.09600","37.25815","0.18515"
"447.40800","37.28410","0.18607"
"447.72000","37.31017","0.18630"
"448.03200","37.33617","0.19144"
"448.34400","37.36224","0.19535"
"448.65600","37.38819","0.19478"
"448.96800","37.41414","0.19656"
"449.28000","37.44015","0.20145"
"449.59200","37.46615","0.20327"
"449.90400","37.49222","0.20317"
"450.21600","37.51811","0.20540"
"450.52800","37.54424","0.20836"
"450.84000","37.57019","0.21013"
"451.15200","37.59614","0.21135"
"451.46400","37.62221","0.21466"
"451.77600","37.64815","0.21687"
"452.08800","37.67422","0.21823"
"452.40000","37.70017","0.22123"
"452.71200","37.72624","0.22359"
"453.02400","37.75219","0.22595"
"453.33600","37.77819","0.22675"
"453.64800","37.80426","0.22925"
"453.96000","37.83015","0.23405"
"454.27200","37.85622","0.23653"
"454.58400","37.88217","0.23781"
"454.89600","37.90818","0.24116"
"455.20800","37.93425","0.24486"
"455.52000","37.96019","0.24758"
"455.83200","37.98620","0.24915"
"456.14400","38.01215","0.25306"
"456.45600","38.03822","0.25727"
"456.76800","38.06417","0.26055"
"457.08000","38.09018","0.26277"
"457.39200","38.11625","0.26608"
"457.70400","38.14213","0.26906"
"458.01600","38.16820","0.27166"
"458.32800","38.19410","0.27385"
"458.64000","38.22022","0.27619"
"458.95200","38.24623","0.28059"
"459.26400","38.27224","0.28586"
"459.57600","38.29824","0.28948"
"459.88800","38.32413","0.29215"
"460.20000","38.35020","0.29540"
"460.51200","38.37615","0.29787"
"460.82400","38.40222","0.29970"
"461.13600","38.42823","-0.01304"
"461.44800","38.45412","-0.00612"
"461.76000","38.48013","-0.00550"
"462.07200","38.50608","-0.00741"
"462.38400","38.53220","-0.00709"
"462.69600","38.55821","-0.00663"
"463.00800","38.58422","-0.00625"
"463.32000","38.61023","-0.00664"
"463.52200","38.62703","-0.00788"