File: Force_trajectories/161223_2/Specimen_RawData_5.csv
End date,"12/23/2016"
Specimen label,"23BG_84"
Maximum Load,"1.42711",N

Time,Extension,Load
(s),(mm),(N)
"0.00000","0.00000","-0.00050"
"0.28800","0.02338","0.00029"
"0.57600","0.04825","0.00092"
"0.86400","0.07229","0.00169"
"1.15200","0.09620","0.00194"
"1.44000","0.12024","0.00195"
"1.72800","0.14421","0.00266"
"2.01600","0.16825","0.00331"
"2.30400","0.19222","0.00394"
"2.59200","0.21626","0.00423"
"2.88000","0.24023","0.00459"
"3.16800","0.26421","0.00491"
"3.45600","0.28825","0.00570"
"3.74400","0.31216","0.00562"
"4.03200","0.33626","0.00635"
"4.32000","0.36017","0.00668"
"4.60800","0.38427","0.00654"
"4.89600","0.40818","0.00737"
"5.18400","0.43222","0.00781"
"5.47200","0.45613","0.00827"
"5.76000","0.48023","0.00869"
"6.04800","0.50421","0.00944"
"6.33600","0.52824","0.00907"
"6.62400","0.55216","0.00941"
"6.91200","0.57619","0.00999"
"7.20000","0.60017","0.01034"
"7.48800","0.62420","0.01056"
"7.77600","0.64824","0.01069"
"8.06400","0.67221","0.01172"
"8.35200","0.69625","0.01184"
"8.64000","0.72022","0.01195"
"8.92800","0.74426","0.01264"
"9.21600","0.76818","0.01301"
"9.50400","0.79221","0.01358"
"9.79200","0.81619","0.01357"
"10.08000","0.84028","0.01370"
"10.36800","0.86420","0.01413"
"10.65600","0.88823","0.01451"
"10.94400","0.91221","0.01460"
"11.23200","0.93624","0.01495"
"11.52000","0.96022","0.01569"
"11.80800","0.98420","0.01503"
"12.09600","1.00829","0.01571"
"12.38400","1.03215","0.01572"
"12.67200","1.05624","0.01684"
"12.96000","1.08016","0.01704"
"13.24800","1.10425","0.01739"
"13.53600","1.12817","0.01759"
"13.82400","1.15220","0.01823"
"14.11200","1.17624","0.01765"
"14.40000","1.20022","0.01716"
"14.68800","1.22425","0.01781"
"14.97600","1.24829","0.01850"
"15.26400","1.27226","0.01819"
"15.55200","1.29630","0.01767"
"15.84000","1.32021","0.01780"
"16.12800","1.34419","0.01775"
"16.41600","1.36828","0.01825"
"16.70400","1.39220","0.01896"
"16.99200","1.41623","0.01909"
"17.28000","1.44021","0.01961"
"17.56800","1.46425","0.01966"
"17.85600","1.48816","0.01957"
"18.14400","1.51214","0.02033"
"18.43200","1.53617","0.02039"
"18.72000","1.56021","0.02060"
"19.00800","1.58418","0.02073"
"19.29600","1.60816","0.02066"
"19.58400","1.63225","0.02086"
"19.87200","1.65623","0.02140"
"20.16000","1.68027","0.02142"
"20.44800","1.70412","0.02187"
"20.73600","1.72822","0.02186"
"21.02400","1.75219","0.02229"
"21.31200","1.77629","0.02270"
"21.60000","1.80014","0.02246"
"21.88800","1.82424","0.02289"
"22.17600","1.84821","0.02325"
"22.46400","1.87225","0.02288"
"22.75200","1.89623","0.02369"
"23.04000","1.92026","0.02360"
"23.32800","1.94418","0.02370"
"23.61600","1.96821","0.02403"
"23.90400","1.99225","0.02430"
"24.19200","2.01616","0.02490"
"24.48000","2.04020","0.02529"
"24.76800","2.06417","0.02519"
"25.05600","2.08821","0.02556"
"25.34400","2.11213","0.02545"
"25.63200","2.13622","0.02580"
"25.92000","2.16020","0.02566"
"26.20800","2.18423","0.02633"
"26.49600","2.20821","0.02649"
"26.78400","2.23218","0.02688"
"27.07200","2.25616","0.02782"
"27.36000","2.28019","0.02758"
"27.64800","2.30423","0.02745"
"27.93600","2.32820","0.02826"
"28.22400","2.35224","0.02788"
"28.51200","2.37622","0.02787"
"28.80000","2.40019","0.02791"
"29.08800","2.42417","0.02826"
"29.37600","2.44826","0.02882"
"29.66400","2.47218","0.02945"
"29.95200","2.49627","0.02985"
"30.24000","2.52013","0.03003"
"30.52800","2.54422","0.03059"
"30.81600","2.56820","0.03092"
"31.10400","2.59224","0.03085"
"31.39200","2.61615","0.03147"
"31.68000","2.64019","0.03243"
"31.96800","2.66422","0.03296"
"32.25600","2.68820","0.03343"
"32.54400","2.71223","0.03392"
"32.83200","2.73615","0.03401"
"33.12000","2.76018","0.03480"
"33.40800","2.78416","0.03507"
"33.69600","2.80825","0.03570"
"33.98400","2.83217","0.03678"
"34.27200","2.85621","0.03682"
"34.56000","2.88018","0.03752"
"34.84800","2.90422","0.03761"
"35.13600","2.92813","0.03768"
"35.42400","2.95217","0.03842"
"35.71200","2.97620","0.03875"
"36.00000","3.00018","0.03941"
"36.28800","3.02421","0.04007"
"36.57600","3.04819","0.04037"
"36.86400","3.07223","0.04074"
"37.15200","3.09620","0.04094"
"37.44000","3.12024","0.04070"
"37.72800","3.14415","0.04032"
"38.01600","3.16819","0.04094"
"38.30400","3.19210","0.04122"
"38.59200","3.21626","0.04190"
"38.88000","3.24017","0.04214"
"39.16800","3.26421","0.04267"
"39.45600","3.28819","0.04310"
"39.74400","3.31216","0.04426"
"40.03200","3.33620","0.04420"
"40.32000","3.36017","0.04436"
"40.60800","3.38421","0.04505"
"40.89600","3.40824","0.04528"
"41.18400","3.43228","0.04599"
"41.47200","3.45619","0.04655"
"41.76000","3.48017","0.04695"
"42.04800","3.50415","0.04761"
"42.33600","3.52824","0.04801"
"42.62400","3.55216","0.04817"
"42.91200","3.57619","0.04858"
"43.20000","3.60023","0.04948"
"43.48800","3.62420","0.05023"
"43.77600","3.64818","0.05084"
"44.06400","3.67221","0.05157"
"44.35200","3.69625","0.05140"
"44.64000","3.72016","0.05286"
"44.92800","3.74420","0.05323"
"45.21600","3.76818","0.05386"
"45.50400","3.79221","0.05470"
"45.79200","3.81613","0.05506"
"46.08000","3.84022","0.05620"
"46.36800","3.86414","0.05667"
"46.65600","3.88823","0.05739"
"46.94400","3.91221","0.05795"
"47.23200","3.93624","0.05964"
"47.52000","3.96022","0.06081"
"47.80800","3.98420","0.06061"
"48.09600","4.00817","0.06192"
"48.38400","4.03221","0.06251"
"48.67200","4.05624","0.06311"
"48.96000","4.08016","0.06367"
"49.24800","4.10425","0.06412"
"49.53600","4.12817","0.06481"
"49.82400","4.15220","0.06579"
"50.11200","4.17618","0.06573"
"50.40000","4.20021","0.06660"
"50.68800","4.22419","0.06749"
"50.97600","4.24823","0.06746"
"51.26400","4.27220","0.06828"
"51.55200","4.29624","0.06874"
"51.84000","4.32021","0.06949"
"52.12800","4.34425","0.06997"
"52.41600","4.36828","0.07057"
"52.70400","4.39220","0.07116"
"52.99200","4.41629","0.07145"
"53.28000","4.44021","0.07200"
"53.56800","4.46430","0.07254"
"53.85600","4.48816","0.07365"
"54.14400","4.51220","0.07442"
"54.43200","4.53611","0.07538"
"54.72000","4.56027","0.07628"
"55.00800","4.58424","0.07791"
"55.29600","4.60828","0.07884"
"55.58400","4.63225","0.07998"
"55.87200","4.65629","0.08116"
"56.16000","4.68026","0.08204"
"56.44800","4.70424","0.08343"
"56.73600","4.72822","0.08442"
"57.02400","4.75219","0.08522"
"57.31200","4.77623","0.08643"
"57.60000","4.80020","0.08717"
"57.88800","4.82424","0.08795"
"58.17600","4.84815","0.08951"
"58.46400","4.87225","0.08979"
"58.75200","4.89622","0.09061"
"59.04000","4.92026","0.09133"
"59.32800","4.94418","0.09169"
"59.61600","4.96827","0.09259"
"59.90400","4.99225","0.09284"
"60.19200","5.01628","0.09354"
"60.48000","5.04026","0.09407"
"60.76800","5.06423","0.09444"
"61.05600","5.08827","0.09487"
"61.34400","5.11218","0.09547"
"61.63200","5.13622","0.09622"
"61.92000","5.16014","0.09692"
"62.20800","5.18417","0.09721"
"62.49600","5.20815","0.09835"
"62.78400","5.23224","0.09833"
"63.07200","5.25622","0.09907"
"63.36000","5.28019","0.10013"
"63.64800","5.30423","0.10074"
"63.93600","5.32826","0.10123"
"64.22400","5.35224","0.10180"
"64.51200","5.37621","0.10250"
"64.80000","5.40025","0.10326"
"65.08800","5.42423","0.10400"
"65.37600","5.44826","0.10482"
"65.66400","5.47218","0.10571"
"65.95200","5.49621","0.10642"
"66.24000","5.52019","0.10672"
"66.52800","5.54422","0.10734"
"66.81600","5.56814","0.10822"
"67.10400","5.59223","0.10907"
"67.39200","5.61621","0.11030"
"67.68000","5.64025","0.11026"
"67.96800","5.66422","0.11159"
"68.25600","5.68820","0.11247"
"68.54400","5.71217","0.10642"
"68.83200","5.73615","0.10637"
"69.12000","5.76024","0.10688"
"69.40800","5.78416","0.10794"
"69.69600","5.80819","0.10806"
"69.98400","5.83217","0.10928"
"70.27200","5.85621","0.11064"
"70.56000","5.88018","0.11114"
"70.84800","5.90422","0.11156"
"71.13600","5.92819","0.11375"
"71.42400","5.95223","0.11468"
"71.71200","5.97620","0.11538"
"72.00000","6.00018","0.11606"
"72.28800","6.02415","0.11706"
"72.57600","6.04819","0.11777"
"72.86400","6.07223","0.11850"
"73.15200","6.09614","0.11956"
"73.44000","6.12024","0.12063"
"73.72800","6.14421","0.12116"
"74.01600","6.16819","0.12245"
"74.30400","6.19216","0.12452"
"74.59200","6.21626","0.12551"
"74.88000","6.24017","0.12705"
"75.16800","6.26427","0.12917"
"75.45600","6.28819","0.13028"
"75.74400","6.31222","0.13182"
"76.03200","6.33620","0.13375"
"76.32000","6.36017","0.13638"
"76.60800","6.38421","0.13772"
"76.89600","6.40818","0.13982"
"77.18400","6.43222","0.14161"
"77.47200","6.45619","0.14351"
"77.76000","6.48023","0.14529"
"78.04800","6.50420","0.14599"
"78.33600","6.52818","0.14745"
"78.62400","6.55216","0.14897"
"78.91200","6.57619","0.14961"
"79.20000","6.60017","0.15093"
"79.48800","6.62420","0.15138"
"79.77600","6.64818","0.15306"
"80.06400","6.67221","0.15517"
"80.35200","6.69619","0.15543"
"80.64000","6.72016","0.15726"
"80.92800","6.74420","0.15839"
"81.21600","6.76818","0.16047"
"81.50400","6.79221","0.16200"
"81.79200","6.81619","0.16406"
"82.08000","6.84022","0.16581"
"82.36800","6.86420","0.16758"
"82.65600","6.88823","0.16911"
"82.94400","6.91215","0.17080"
"83.23200","6.93624","0.17249"
"83.52000","6.96016","0.17281"
"83.80800","6.98420","0.17415"
"84.09600","7.00817","0.17445"
"84.38400","7.03215","0.17639"
"84.67200","7.05618","0.17691"
"84.96000","7.08022","0.17805"
"85.24800","7.10425","0.17733"
"85.53600","7.12823","0.17855"
"85.82400","7.15226","0.17924"
"86.11200","7.17618","0.18060"
"86.40000","7.20021","0.18264"
"86.68800","7.22419","0.18325"
"86.97600","7.24823","0.18494"
"87.26400","7.27214","0.18651"
"87.55200","7.29618","0.18829"
"87.84000","7.32015","0.18995"
"88.12800","7.34419","0.19094"
"88.41600","7.36822","0.19305"
"88.70400","7.39220","0.19401"
"88.99200","7.41623","0.19522"
"89.28000","7.44021","0.19685"
"89.56800","7.46425","0.19809"
"89.85600","7.48816","0.19986"
"90.14400","7.51226","0.20104"
"90.43200","7.53617","0.20219"
"90.72000","7.56027","0.20341"
"91.00800","7.58418","0.20541"
"91.29600","7.60822","0.20614"
"91.58400","7.63219","0.20772"
"91.87200","7.65629","0.20861"
"92.16000","7.68021","0.20966"
"92.44800","7.70424","0.21069"
"92.73600","7.72822","0.21181"
"93.02400","7.75225","0.21265"
"93.31200","7.77623","0.21406"
"93.60000","7.80020","0.21554"
"93.88800","7.82424","0.21675"
"94.17600","7.84821","0.21837"
"94.46400","7.87225","0.21997"
"94.75200","7.89616","0.22132"
"95.04000","7.92032","0.22278"
"95.32800","7.94418","0.22432"
"95.61600","7.96827","0.22605"
"95.90400","7.99219","0.22773"
"96.19200","8.01622","0.22908"
"96.48000","8.04026","0.23007"
"96.76800","8.06423","0.23237"
"97.05600","8.08827","0.23377"
"97.34400","8.11224","0.23588"
"97.63200","8.13622","0.23797"
"97.92000","8.16013","0.24020"
"98.20800","8.18423","0.24252"
"98.49600","8.20815","0.24430"
"98.78400","8.23224","0.24628"
"99.07200","8.25616","0.24818"
"99.36000","8.28025","0.25023"
"99.64800","8.30417","0.25197"
"99.93600","8.32826","0.25402"
"100.22400","8.35224","0.25668"
"100.51200","8.37627","0.25886"
"100.80000","8.40019","0.26098"
"101.08800","8.42422","0.26399"
"101.37600","8.44826","0.26632"
"101.66400","8.47224","0.26808"
"101.95200","8.49621","0.27064"
"102.24000","8.52019","0.27242"
"102.52800","8.54428","0.27436"
"102.81600","8.56820","0.27637"
"103.10400","8.59223","0.27919"
"103.39200","8.61621","0.28189"
"103.68000","8.64025","0.28548"
"103.96800","8.66416","0.28897"
"104.25600","8.68820","0.29228"
"104.54400","8.71217","0.29603"
"104.83200","8.73615","0.29820"
"105.12000","8.76018","0.30063"
"105.40800","8.78416","0.30229"
"105.69600","8.80819","0.30369"
"105.98400","8.83217","0.30524"
"106.27200","8.85627","0.30727"
"106.56000","8.88018","0.30867"
"106.84800","8.90422","0.31027"
"107.13600","8.92819","0.31161"
"107.42400","8.95229","0.31354"
"107.71200","8.97614","0.31480"
"108.00000","9.00024","0.31628"
"108.28800","9.02421","0.31766"
"108.57600","9.04819","0.31920"
"108.86400","9.07216","0.32060"
"109.15200","9.09620","0.32279"
"109.44000","9.12024","0.32441"
"109.72800","9.14421","0.32597"
"110.01600","9.16825","0.32768"
"110.30400","9.19216","0.32869"
"110.59200","9.21620","0.33056"
"110.88000","9.24017","0.33169"
"111.16800","9.26421","0.33414"
"111.45600","9.28818","0.33691"
"111.74400","9.31222","0.33958"
"112.03200","9.33613","0.34230"
"112.32000","9.36023","0.34551"
"112.60800","9.38415","0.34820"
"112.89600","9.40818","0.34926"
"113.18400","9.43216","0.35143"
"113.47200","9.45619","0.35358"
"113.76000","9.48023","0.35560"
"114.04800","9.50414","0.35709"
"114.33600","9.52824","0.35863"
"114.62400","9.55216","0.36026"
"114.91200","9.57625","0.32474"
"115.20000","9.60017","0.32264"
"115.48800","9.62420","0.32380"
"115.77600","9.64812","0.32531"
"116.06400","9.67221","0.32626"
"116.35200","9.69619","0.32815"
"116.64000","9.72022","0.32925"
"116.92800","9.74420","0.33130"
"117.21600","9.76818","0.33316"
"117.50400","9.79215","0.33651"
"117.79200","9.81619","0.33919"
"118.08000","9.84022","0.34182"
"118.36800","9.86420","0.34552"
"118.65600","9.88823","0.34835"
"118.94400","9.91221","0.35111"
"119.23200","9.93624","0.35370"
"119.52000","9.96016","0.35678"
"119.80800","9.98419","0.36021"
"120.09600","10.00811","0.36316"
"120.38400","10.03221","0.36709"
"120.67200","10.05618","0.37071"
"120.96000","10.08022","0.37399"
"121.24800","10.10419","0.37698"
"121.53600","10.12817","0.37857"
"121.82400","10.15220","0.38059"
"122.11200","10.17618","0.38230"
"122.40000","10.20021","0.38463"
"122.68800","10.22419","0.38749"
"122.97600","10.24823","0.39065"
"123.26400","10.27220","0.39376"
"123.55200","10.29618","0.39614"
"123.84000","10.32009","0.39861"
"124.12800","10.34425","0.40091"
"124.41600","10.36816","0.40223"
"124.70400","10.39220","0.40489"
"124.99200","10.41617","0.40654"
"125.28000","10.44021","0.40850"
"125.56800","10.46418","0.40981"
"125.85600","10.48816","0.41167"
"126.14400","10.51220","0.41360"
"126.43200","10.53623","0.41629"
"126.72000","10.56021","0.41660"
"127.00800","10.58418","0.41829"
"127.29600","10.60822","0.42025"
"127.58400","10.63213","0.42311"
"127.87200","10.65623","0.42560"
"128.16000","10.68014","0.42895"
"128.44800","10.70424","0.43175"
"128.73600","10.72816","0.43495"
"129.02400","10.75225","0.43757"
"129.31200","10.77623","0.43987"
"129.60000","10.80026","0.44292"
"129.88800","10.82424","0.44520"
"130.17600","10.84815","0.44783"
"130.46400","10.87219","0.45104"
"130.75200","10.89616","0.45293"
"131.04000","10.92026","0.45537"
"131.32800","10.94418","0.45716"
"131.61600","10.96821","0.45896"
"131.90400","10.99219","0.46233"
"132.19200","11.01622","0.46590"
"132.48000","11.04020","0.46890"
"132.76800","11.06423","0.47348"
"133.05600","11.08821","0.47682"
"133.34400","11.11230","0.47946"
"133.63200","11.13622","0.48126"
"133.92000","11.16025","0.48361"
"134.20800","11.18423","0.48619"
"134.49600","11.20821","0.48963"
"134.78400","11.23224","0.49389"
"135.07200","11.25622","0.49785"
"135.36000","11.28025","0.50171"
"135.64800","11.30423","0.50537"
"135.93600","11.32826","0.50861"
"136.22400","11.35218","0.51206"
"136.51200","11.37627","0.51517"
"136.80000","11.40019","0.51728"
"137.08800","11.42423","0.51896"
"137.37600","11.44820","0.52088"
"137.66400","11.47224","0.52269"
"137.95200","11.49621","0.52476"
"138.24000","11.52025","0.52649"
"138.52800","11.54428","0.52987"
"138.81600","11.56820","0.53299"
"139.10400","11.59223","0.53574"
"139.39200","11.61621","0.53875"
"139.68000","11.64025","0.54129"
"139.96800","11.66416","0.54462"
"140.25600","11.68820","0.54884"
"140.54400","11.71217","0.55187"
"140.83200","11.73627","0.55502"
"141.12000","11.76024","0.55812"
"141.40800","11.78428","0.56105"
"141.69600","11.80819","0.56443"
"141.98400","11.83223","0.56898"
"142.27200","11.85620","0.57397"
"142.56000","11.88024","0.57806"
"142.84800","11.90428","0.58206"
"143.13600","11.92819","0.58541"
"143.42400","11.95223","0.58823"
"143.71200","11.97620","0.59117"
"144.00000","12.00024","0.59554"
"144.28800","12.02415","0.59934"
"144.57600","12.04825","0.60266"
"144.86400","12.07216","0.60580"
"145.15200","12.09626","0.60780"
"145.44000","12.12024","0.61001"
"145.72800","12.14421","0.61287"
"146.01600","12.16819","0.61589"
"146.30400","12.19222","0.61858"
"146.59200","12.21620","0.62187"
"146.88000","12.24023","0.62490"
"147.16800","12.26421","0.62734"
"147.45600","12.28819","0.62995"
"147.74400","12.31222","0.63251"
"148.03200","12.33619","0.63604"
"148.32000","12.36023","0.63946"
"148.60800","12.38421","0.64419"
"148.89600","12.40824","0.64916"
"149.18400","12.43216","0.65450"
"149.47200","12.45619","0.65900"
"149.76000","12.48023","0.66245"
"150.04800","12.50420","0.66611"
"150.33600","12.52824","0.66934"
"150.62400","12.55221","0.67393"
"150.91200","12.57625","0.67856"
"151.20000","12.60023","0.68419"
"151.48800","12.62420","0.68815"
"151.77600","12.64818","0.69090"
"152.06400","12.67221","0.69353"
"152.35200","12.69619","0.69727"
"152.64000","12.72022","0.70128"
"152.92800","12.74420","0.70633"
"153.21600","12.76824","0.71089"
"153.50400","12.79221","0.71382"
"153.79200","12.81619","0.71744"
"154.08000","12.84022","0.71996"
"154.36800","12.86420","0.72250"
"154.65600","12.88823","0.72484"
"154.94400","12.91221","0.72742"
"155.23200","12.93624","0.72996"
"155.52000","12.96022","0.73292"
"155.80800","12.98419","0.73602"
"156.09600","13.00817","0.71572"
"156.38400","13.03221","0.71830"
"156.67200","13.05612","0.72111"
"156.96000","13.08022","0.72359"
"157.24800","13.10419","0.72597"
"157.53600","13.12823","0.72854"
"157.82400","13.15220","0.73246"
"158.11200","13.17618","0.73522"
"158.40000","13.20021","0.73885"
"158.68800","13.22419","0.74217"
"158.97600","13.24822","0.74495"
"159.26400","13.27220","0.74909"
"159.55200","13.29624","0.75382"
"159.84000","13.32015","0.75895"
"160.12800","13.34425","0.76331"
"160.41600","13.36816","0.76722"
"160.70400","13.39226","0.77241"
"160.99200","13.41611","0.78014"
"161.28000","13.44027","0.78546"
"161.56800","13.46419","0.79011"
"161.85600","13.48822","0.79394"
"162.14400","13.51220","0.79851"
"162.43200","13.53623","0.80391"
"162.72000","13.56021","0.81051"
"163.00800","13.58418","0.81569"
"163.29600","13.60822","0.82132"
"163.58400","13.63219","0.82448"
"163.87200","13.65617","0.82812"
"164.16000","13.68015","0.83104"
"164.44800","13.70418","0.83314"
"164.73600","13.72816","0.83537"
"165.02400","13.75225","0.83782"
"165.31200","13.77617","0.84069"
"165.60000","13.80020","0.84407"
"165.88800","13.82418","0.84771"
"166.17600","13.84821","0.85116"
"166.46400","13.87225","0.85540"
"166.75200","13.89622","0.86161"
"167.04000","13.92020","0.86490"
"167.32800","13.94417","0.86782"
"167.61600","13.96821","0.87189"
"167.90400","13.99219","0.87673"
"168.19200","14.01622","0.88211"
"168.48000","14.04020","0.86719"
"168.76800","14.06423","0.85006"
"169.05600","14.08815","0.85227"
"169.34400","14.11224","0.82545"
"169.63200","14.13616","0.82719"
"169.92000","14.16026","0.82988"
"170.20800","14.18417","0.83209"
"170.49600","14.20821","0.83558"
"170.78400","14.23224","0.83832"
"171.07200","14.25622","0.84216"
"171.36000","14.28025","0.84471"
"171.64800","14.30423","0.84851"
"171.93600","14.32820","0.85214"
"172.22400","14.35218","0.85635"
"172.51200","14.37621","0.86227"
"172.80000","14.40019","0.86602"
"173.08800","14.42422","0.84105"
"173.37600","14.44820","0.83533"
"173.66400","14.47224","0.83908"
"173.95200","14.49621","0.84376"
"174.24000","14.52025","0.84815"
"174.52800","14.54422","0.85334"
"174.81600","14.56826","0.85906"
"175.10400","14.59229","0.86429"
"175.39200","14.61621","0.86860"
"175.68000","14.64025","0.87276"
"175.96800","14.66416","0.88035"
"176.25600","14.68826","0.88652"
"176.54400","14.71217","0.89053"
"176.83200","14.73627","0.84943"
"177.12000","14.76018","0.85160"
"177.40800","14.78428","0.85485"
"177.69600","14.80819","0.86007"
"177.98400","14.83223","0.86462"
"178.27200","14.85620","0.86777"
"178.56000","14.88024","0.86695"
"178.84800","14.90422","0.87094"
"179.13600","14.92825","0.87440"
"179.42400","14.95223","0.88061"
"179.71200","14.97614","0.88734"
"180.00000","15.00024","0.89181"
"180.28800","15.02421","0.89682"
"180.57600","15.04825","0.90247"
"180.86400","15.07222","0.90787"
"181.15200","15.09626","0.91296"
"181.44000","15.12024","0.91674"
"181.72800","15.14421","0.92174"
"182.01600","15.16819","0.92707"
"182.30400","15.19222","0.93195"
"182.59200","15.21620","0.93521"
"182.88000","15.24023","0.93823"
"183.16800","15.26421","0.94219"
"183.45600","15.28818","0.94734"
"183.74400","15.31222","0.95335"
"184.03200","15.33614","0.96180"
"184.32000","15.36029","0.96852"
"184.60800","15.38421","0.97393"
"184.89600","15.40830","0.97826"
"185.18400","15.43216","0.98380"
"185.47200","15.45625","0.99187"
"185.76000","15.48017","0.99784"
"186.04800","15.50426","1.00241"
"186.33600","15.52818","1.00647"
"186.62400","15.55222","1.01216"
"186.91200","15.57625","1.01669"
"187.20000","15.60023","1.02114"
"187.48800","15.62426","1.02362"
"187.77600","15.64824","1.02605"
"188.06400","15.67221","1.02871"
"188.35200","15.69613","1.03078"
"188.64000","15.72022","1.03265"
"188.92800","15.74420","1.03497"
"189.21600","15.76823","1.03842"
"189.50400","15.79221","1.04248"
"189.79200","15.81625","1.04514"
"190.08000","15.84016","1.04761"
"190.36800","15.86414","1.05278"
"190.65600","15.88817","1.06036"
"190.94400","15.91221","1.06720"
"191.23200","15.93618","1.05008"
"191.52000","15.96016","1.04316"
"191.80800","15.98425","1.04722"
"192.09600","16.00817","1.05178"
"192.38400","16.03220","1.00339"
"192.67200","16.05612","1.00467"
"192.96000","16.08022","1.00783"
"193.24800","16.10413","0.99035"
"193.53600","16.12823","0.99378"
"193.82400","16.15214","0.99972"
"194.11200","16.17624","1.00364"
"194.40000","16.20021","1.00920"
"194.68800","16.22419","1.01197"
"194.97600","16.24822","0.88823"
"195.26400","16.27220","0.88785"
"195.55200","16.29623","0.89115"
"195.84000","16.32015","0.89871"
"196.12800","16.34425","0.90230"
"196.41600","16.36816","0.90911"
"196.70400","16.39220","0.91646"
"196.99200","16.41611","0.92122"
"197.28000","16.44021","0.92792"
"197.56800","16.46418","0.93422"
"197.85600","16.48822","0.93136"
"198.14400","16.51213","0.93481"
"198.43200","16.53623","0.92005"
"198.72000","16.56021","0.92571"
"199.00800","16.58418","0.93273"
"199.29600","16.60822","0.93546"
"199.58400","16.63213","0.93866"
"199.87200","16.65617","0.94709"
"200.16000","16.68020","0.95138"
"200.44800","16.70424","0.96069"
"200.73600","16.72816","0.97172"
"201.02400","16.75219","0.97511"
"201.31200","16.77617","0.98136"
"201.60000","16.80020","0.98814"
"201.88800","16.82412","0.99580"
"202.17600","16.84821","1.00322"
"202.46400","16.87213","1.00582"
"202.75200","16.89622","1.00753"
"203.04000","16.92020","1.01223"
"203.32800","16.94417","1.01772"
"203.61600","16.96815","1.02299"
"203.90400","16.99219","1.02549"
"204.19200","17.01622","1.02961"
"204.48000","17.04020","1.03215"
"204.76800","17.06423","1.03592"
"205.05600","17.08815","1.04135"
"205.34400","17.11218","1.04434"
"205.63200","17.13610","1.05126"
"205.92000","17.16019","1.05633"
"206.20800","17.18417","1.06782"
"206.49600","17.20827","0.93819"
"206.78400","17.23224","0.93723"
"207.07200","17.25622","0.93760"
"207.36000","17.28019","0.94484"
"207.64800","17.30417","0.95199"
"207.93600","17.32820","0.95800"
"208.22400","17.35218","0.97278"
"208.51200","17.37621","0.97719"
"208.80000","17.40019","0.98466"
"209.08800","17.42422","0.99660"
"209.37600","17.44814","0.99551"
"209.66400","17.47218","1.00588"
"209.95200","17.49615","1.01257"
"210.24000","17.52025","1.02104"
"210.52800","17.54422","1.02630"
"210.81600","17.56826","1.02935"
"211.10400","17.59223","1.03706"
"211.39200","17.61621","1.03962"
"211.68000","17.64018","1.04722"
"211.96800","17.66416","1.05405"
"212.25600","17.68819","1.06606"
"212.54400","17.71223","1.07718"
"212.83200","17.73627","1.08203"
"213.12000","17.76018","1.09423"
"213.40800","17.78428","1.09837"
"213.69600","17.80819","1.10717"
"213.98400","17.83223","1.11345"
"214.27200","17.85614","1.12597"
"214.56000","17.88024","1.13042"
"214.84800","17.90421","1.13683"
"215.13600","17.92825","1.14150"
"215.42400","17.95223","1.14540"
"215.71200","17.97620","1.14821"
"216.00000","18.00024","1.15167"
"216.28800","18.02421","1.15593"
"216.57600","18.04831","1.16054"
"216.86400","18.07222","1.16645"
"217.15200","18.09626","1.17237"
"217.44000","18.12017","1.17790"
"217.72800","18.14427","1.18571"
"218.01600","18.16818","1.19432"
"218.30400","18.19222","1.20084"
"218.59200","18.21620","1.20690"
"218.88000","18.24029","1.21516"
"219.16800","18.26421","1.22186"
"219.45600","18.28824","1.23029"
"219.74400","18.31222","1.23538"
"220.03200","18.33619","1.24271"
"220.32000","18.36023","1.24599"
"220.60800","18.38420","1.25177"
"220.89600","18.40824","1.25591"
"221.18400","18.43222","1.26557"
"221.47200","18.45625","1.27258"
"221.76000","18.48023","1.28160"
"222.04800","18.50426","1.28613"
"222.33600","18.52818","1.29123"
"222.62400","18.55227","1.29944"
"222.91200","18.57619","1.30413"
"223.20000","18.60023","1.30913"
"223.48800","18.62420","1.31414"
"223.77600","18.64818","1.32235"
"224.06400","18.67227","1.32602"
"224.35200","18.69625","1.33155"
"224.64000","18.72028","1.33742"
"224.92800","18.74420","1.34273"
"225.21600","18.76823","1.34976"
"225.50400","18.79221","1.35382"
"225.79200","18.81624","1.35938"
"226.08000","18.84022","1.36843"
"226.36800","18.86419","1.37829"
"226.65600","18.88817","1.38801"
"226.94400","18.91221","1.39331"
"227.23200","18.93618","1.40241"
"227.52000","18.96022","1.41218"
"227.80800","18.98425","1.41904"
"228.09600","19.00823","1.42688"
"228.38400","19.03226","1.24785"
"228.67200","19.05618","1.25075"
"228.96000","19.08022","1.25099"
"229.24800","19.10413","1.26092"
"229.53600","19.12823","1.26454"
"229.82400","19.15214","1.27571"
"230.11200","19.17624","1.28275"
"230.40000","19.20021","1.28760"
"230.68800","19.22425","1.29636"
"230.97600","19.24816","1.30057"
"231.26400","19.27226","1.30815"
"231.55200","19.29623","1.31110"
"231.84000","19.32021","1.31910"
"232.12800","19.34425","1.32080"
"232.41600","19.36822","1.32482"
"232.70400","19.39226","1.32926"
"232.99200","19.41617","1.03858"
"233.28000","19.44021","0.92988"
"233.56800","19.46418","0.92555"
"233.85600","19.48822","0.93154"
"234.14400","19.51220","0.93085"
"234.43200","19.53623","0.93394"
"234.72000","19.56021","0.93815"
"235.00800","19.58424","0.93828"
"235.29600","19.60822","0.94289"
"235.58400","19.63219","0.95113"
"235.87200","19.65623","0.95422"
"236.16000","19.68020","0.96723"
"236.44800","19.70424","0.95605"
"236.73600","19.72821","0.96007"
"237.02400","19.75225","0.97077"
"237.31200","19.77617","0.97388"
"237.60000","19.80020","0.97864"
"237.88800","19.82418","0.98886"
"238.17600","19.84821","0.99083"
"238.46400","19.87219","1.00045"
"238.75200","19.89622","1.00395"
"239.04000","19.92020","1.01072"
"239.32800","19.94423","1.01895"
"239.61600","19.96821","1.02140"
"239.90400","19.99224","1.02690"
"240.19200","20.01622","1.03009"
"240.48000","20.04025","1.03326"
"240.76800","20.06423","1.03878"
"241.05600","20.08821","1.04125"
"241.34400","20.11218","1.04874"
"241.63200","20.13616","1.05295"
"241.92000","20.16019","1.06516"
"242.20800","20.18417","1.07301"
"242.49600","20.20820","1.07980"
"242.78400","20.23218","1.08875"
"243.07200","20.25621","1.09525"
"243.36000","20.28019","1.10389"
"243.64800","20.30423","1.10754"
"243.93600","20.32820","1.11539"
"244.22400","20.35217","1.12181"
"244.51200","20.37621","1.12970"
"244.80000","20.40019","0.85157"
"245.08800","20.42422","0.84033"
"245.37600","20.44820","0.48702"
"245.66400","20.47218","0.47828"
"245.95200","20.49615","0.47831"
"246.24000","20.52019","0.48549"
"246.52800","20.54416","0.48081"
"246.81600","20.56826","0.48377"
"247.10400","20.59211","0.49002"
"247.39200","20.61621","0.49274"
"247.68000","20.64018","0.49946"
"247.96800","20.66422","0.50427"
"248.25600","20.68819","0.51100"
"248.54400","20.71223","0.51463"
"248.83200","20.73621","0.52150"
"249.12000","20.76018","0.52398"
"249.40800","20.78422","0.53101"
"249.69600","20.80819","0.53767"
"249.98400","20.83223","0.54069"
"250.27200","20.85614","0.54218"
"250.56000","20.88018","0.54715"
"250.84800","20.90415","0.54776"
"251.13600","20.92819","0.55104"
"251.42400","20.95217","0.55703"
"251.71200","20.97626","0.56116"
"252.00000","21.00024","0.56144"
"252.28800","21.02421","0.55426"
"252.57600","21.04825","0.56456"
"252.86400","21.07216","0.56867"
"253.15200","21.09626","0.57683"
"253.44000","21.12017","0.57655"
"253.72800","21.14427","0.58166"
"254.01600","21.16818","0.58212"
"254.30400","21.19228","0.58693"
"254.59200","21.21620","0.59044"
"254.88000","21.24023","0.59763"
"255.16800","21.26414","0.60626"
"255.45600","21.28824","0.61239"
"255.74400","21.31216","0.61986"
"256.03200","21.33625","0.62356"
"256.32000","21.36023","0.62665"
"256.60800","21.38427","0.62876"
"256.89600","21.40824","0.63399"
"257.18400","21.43222","0.64139"
"257.47200","21.45631","0.65154"
"257.76000","21.48023","0.66207"
"258.04800","21.50426","0.66571"
"258.33600","21.52824","0.67034"
"258.62400","21.55227","0.67744"
"258.91200","21.57619","0.68687"
"259.20000","21.60022","0.69460"
"259.48800","21.62420","0.70316"
"259.77600","21.64824","0.70992"
"260.06400","21.67221","0.71439"
"260.35200","21.69625","0.71969"
"260.64000","21.72022","0.72523"
"260.92800","21.74420","0.73056"
"261.21600","21.76829","0.73371"
"261.50400","21.79221","0.73768"
"261.79200","21.81624","0.74241"
"262.08000","21.84016","0.75188"
"262.36800","21.86425","0.76201"
"262.65600","21.88817","0.76765"
"262.94400","21.91227","0.77641"
"263.23200","21.93618","0.78867"
"263.52000","21.96022","0.79620"
"263.80800","21.98419","0.80352"
"264.09600","22.00823","0.81178"
"264.38400","22.03221","0.82181"
"264.67200","22.05624","0.82868"
"264.96000","22.08022","0.83187"
"265.24800","22.10425","0.83527"
"265.53600","22.12823","0.84018"
"265.82400","22.15220","0.72606"
"266.11200","22.17630","0.72796"
"266.40000","22.20021","0.43846"
"266.68800","22.22419","0.43589"
"266.97600","22.24816","0.44098"
"267.26400","22.27220","0.43661"
"267.55200","22.29618","0.44966"
"267.84000","22.32021","0.44586"
"268.12800","22.34419","0.45035"
"268.41600","22.36816","0.38175"
"268.70400","22.39220","0.30533"
"268.99200","22.41617","0.31502"
"269.28000","22.44027","0.32030"
"269.56800","22.46424","0.31586"
"269.85600","22.48822","0.32049"
"270.14400","22.51213","0.33120"
"270.43200","22.53623","0.33085"
"270.72000","22.56015","0.33238"
"271.00800","22.58418","0.35031"
"271.29600","22.60816","0.35444"
"271.58400","22.63225","0.35468"
"271.87200","22.65617","0.36973"
"272.16000","22.68020","0.37490"
"272.44800","22.70418","0.37598"
"272.73600","22.72821","0.38451"
"273.02400","22.75225","0.38666"
"273.31200","22.77622","0.38908"
"273.60000","22.80020","0.40143"
"273.88800","22.82417","0.40155"
"274.17600","22.84821","0.40599"
"274.46400","22.87218","0.41201"
"274.75200","22.89622","0.41276"
"275.04000","22.92020","0.41988"
"275.32800","22.94417","0.42425"
"275.61600","22.96821","0.42920"
"275.90400","22.99225","0.43717"
"276.19200","23.01622","0.44102"
"276.48000","23.04020","0.44980"
"276.76800","23.06423","0.45400"
"277.05600","23.08821","0.45955"
"277.34400","23.11218","0.12380"
"277.63200","23.13616","0.13028"
"277.92000","23.16019","0.14636"
"278.20800","23.18417","0.14526"
"278.49600","23.20820","0.14458"
"278.78400","23.23218","0.16133"
"279.07200","23.25622","0.18775"
"279.36000","23.28013","0.17486"
"279.64800","23.30423","0.16897"
"279.93600","23.32814","0.17938"
"280.22400","23.35224","0.19889"
"280.51200","23.37621","0.19248"
"280.80000","23.40019","0.18673"
"281.08800","23.42422","0.19359"
"281.37600","23.44820","0.20763"
"281.66400","23.47223","0.21205"
"281.95200","23.49621","0.20925"
"282.24000","23.52019","0.21038"
"282.52800","23.54416","0.21665"
"282.81600","23.56820","0.13717"
"283.10400","23.59211","0.13472"
"283.39200","23.61621","0.12164"
"283.68000","23.64018","0.13355"
"283.96800","23.66422","0.15419"
"284.25600","23.68819","0.14818"
"284.54400","23.71223","0.14489"
"284.83200","23.73621","0.15383"
"285.12000","23.76018","0.17296"
"285.40800","23.78415","0.16745"
"285.69600","23.80813","0.16445"
"285.98400","23.83223","0.17421"
"286.27200","23.85614","0.18659"
"286.56000","23.88018","0.18618"
"286.84800","23.90415","0.18192"
"287.13600","23.92819","0.18556"
"287.42400","23.95211","0.19739"
"287.71200","23.97626","0.20432"
"288.00000","24.00018","0.20083"
"288.28800","24.02421","0.19902"
"288.57600","24.04819","0.20413"
"288.86400","24.07216","0.21104"
"289.15200","24.09620","0.21475"
"289.44000","24.12023","0.21256"
"289.72800","24.14415","0.21183"
"290.01600","24.16818","0.21502"
"290.30400","24.19222","0.22349"
"290.59200","24.21620","0.22842"
"290.88000","24.24023","0.22922"
"291.16800","24.26415","0.22786"
"291.45600","24.28824","0.22895"
"291.74400","24.31216","0.07520"
"292.03200","24.33625","0.08060"
"292.32000","24.36017","0.06229"
"292.60800","24.38420","0.08446"
"292.89600","24.40818","0.07044"
"293.18400","24.43221","0.07081"
"293.47200","24.45619","0.08982"
"293.76000","24.48017","0.07709"
"294.04800","24.50420","0.08792"
"294.33600","24.52818","0.09290"
"294.62400","24.55222","0.08961"
"294.91200","24.57619","0.09674"
"295.20000","24.60028","0.09840"
"295.48800","24.62414","0.09668"
"295.77600","24.64823","0.10282"
"296.06400","24.67221","0.10350"
"296.35200","24.69625","0.10427"
"296.64000","24.72022","0.11026"
"296.92800","24.74426","0.11067"
"297.21600","24.76823","0.11315"
"297.50400","24.79227","0.11923"
"297.79200","24.81624","0.11986"
"298.08000","24.84016","0.12319"
"298.36800","24.86432","0.12917"
"298.65600","24.88823","0.13286"
"298.94400","24.91226","0.13764"
"299.23200","24.93618","0.14377"
"299.52000","24.96022","0.14614"
"299.80800","24.98419","0.14929"
"300.09600","25.00829","0.15339"
"300.38400","25.03220","0.15703"
"300.67200","25.05624","0.09676"
"300.96000","25.08022","0.07192"
"301.24800","25.10425","0.09572"
"301.53600","25.12823","0.07940"
"301.82400","25.15226","0.08902"
"302.11200","25.17630","0.09400"
"302.40000","25.20021","0.08625"
"302.68800","25.22431","0.09983"
"302.97600","25.24822","0.09240"
"303.26400","25.27220","0.09642"
"303.55200","25.29617","0.10111"
"303.84000","25.32027","0.09592"
"304.12800","25.34425","0.10488"
"304.41600","25.36822","0.10244"
"304.70400","25.39219","0.10188"
"304.99200","25.41623","0.11008"
"305.28000","25.44021","0.10572"
"305.56800","25.46424","0.10978"
"305.85600","25.48828","0.11487"
"306.14400","25.51225","0.11125"
"306.43200","25.53629","0.11555"
"306.72000","25.56020","0.11828"
"307.00800","25.58424","0.11635"
"307.29600","25.60816","0.12048"
"307.58400","25.63219","0.12273"
"307.87200","25.65617","0.12228"
"308.16000","25.68026","0.12680"
"308.44800","25.70418","0.13052"
"308.73600","25.72821","0.13259"
"309.02400","25.75219","0.13714"
"309.31200","25.77622","0.13948"
"309.60000","25.80020","0.14115"
"309.88800","25.82423","0.14527"
"310.17600","25.84827","0.14727"
"310.46400","25.87225","0.14826"
"310.75200","25.89622","0.15090"
"311.04000","25.92020","0.15274"
"311.32800","25.94423","0.15501"
"311.61600","25.96815","0.15742"
"311.90400","25.99224","0.16157"
"312.19200","26.01616","0.16440"
"312.48000","26.04025","0.16718"
"312.76800","26.06423","0.16983"
"313.05600","26.08821","0.17242"
"313.34400","26.11218","0.17455"
"313.63200","26.13622","0.17565"
"313.92000","26.16025","0.17662"
"314.20800","26.18417","0.17653"
"314.49600","26.20827","0.04492"
"314.78400","26.23218","0.02924"
"315.07200","26.25622","0.04258"
"315.36000","26.28019","0.02972"
"315.64800","26.30423","0.04028"
"315.93600","26.32814","0.04598"
"316.22400","26.35224","0.04002"
"316.51200","26.37621","0.04842"
"316.80000","26.40025","0.04070"
"317.08800","26.42422","0.04137"
"317.37600","26.44826","0.04878"
"317.66400","26.47217","0.04126"
"317.95200","26.49621","0.04898"
"318.24000","26.52025","0.05128"
"318.52800","26.54422","0.04803"
"318.81600","26.56820","0.05357"
"319.10400","26.59217","0.04797"
"319.39200","26.61621","0.04832"
"319.68000","26.64018","0.05608"
"319.96800","26.66422","0.04892"
"320.25600","26.68819","0.05497"
"320.54400","26.71223","0.06120"
"320.83200","26.73620","0.05650"
"321.12000","26.76024","0.06487"
"321.40800","26.78422","0.06418"
"321.69600","26.80819","0.06265"
"321.98400","26.83223","0.06813"
"322.27200","26.85614","0.06743"
"322.56000","26.88024","0.06894"
"322.84800","26.90415","0.07212"
"323.13600","26.92825","0.07119"
"323.42400","26.95217","0.07410"
"323.71200","26.97620","0.07790"
"324.00000","27.00018","0.07785"
"324.28800","27.02427","0.08269"
"324.57600","27.04819","0.08613"
"324.86400","27.07222","0.08695"
"325.15200","27.09614","0.08990"
"325.44000","27.12023","0.09114"
"325.72800","27.14421","0.08410"
"326.01600","27.16819","0.08533"
"326.30400","27.19222","0.08835"
"326.59200","27.21620","0.09077"
"326.88000","27.24023","0.09259"
"327.16800","27.26421","0.09300"
"327.45600","27.28824","0.09279"
"327.74400","27.31222","0.09369"
"328.03200","27.33625","0.09548"
"328.32000","27.36017","0.09766"
"328.60800","27.38420","0.09922"
"328.89600","27.40812","0.10079"
"329.18400","27.43227","0.10292"
"329.47200","27.45619","0.10509"
"329.76000","27.48023","0.10069"
"330.04800","27.50420","0.10111"
"330.33600","27.52818","0.10323"
"330.62400","27.55221","0.10485"
"330.91200","27.57619","0.10794"
"331.20000","27.60023","0.11063"
"331.48800","27.62414","0.11073"
"331.77600","27.64824","0.11323"
"332.06400","27.67215","0.11560"
"332.35200","27.69618","0.11764"
"332.64000","27.72016","0.11931"
"332.92800","27.74426","0.11308"
"333.21600","27.76818","0.11684"
"333.50400","27.79221","0.11911"
"333.79200","27.81618","0.11973"
"334.08000","27.84022","0.12218"
"334.36800","27.86419","0.12513"
"334.65600","27.88817","0.12753"
"334.94400","27.91220","0.13134"
"335.23200","27.93618","0.13538"
"335.52000","27.96022","0.13881"
"335.80800","27.98419","0.14185"
"336.09600","28.00823","0.14477"
"336.38400","28.03214","0.14219"
"336.67200","28.05624","0.14581"
"336.96000","28.08021","0.14768"
"337.24800","28.10419","0.14925"
"337.53600","28.12817","0.15240"
"337.82400","28.15226","0.15379"
"338.11200","28.17624","0.15638"
"338.40000","28.20021","0.15984"
"338.68800","28.22425","0.16323"
"338.97600","28.24822","0.16663"
"339.26400","28.27226","0.17013"
"339.55200","28.29617","0.17164"
"339.84000","28.32021","0.17376"
"340.12800","28.34419","0.17569"
"340.41600","28.36828","0.17772"
"340.70400","28.39220","0.17711"
"340.99200","28.41623","0.17997"
"341.28000","28.44015","0.17886"
"341.56800","28.46424","0.17993"
"341.85600","28.48822","0.18275"
"342.14400","28.51225","0.18494"
"342.43200","28.53623","0.18774"
"342.72000","28.56026","0.19077"
"343.00800","28.58424","0.19270"
"343.29600","28.60822","0.19466"
"343.58400","28.63225","0.19672"
"343.87200","28.65623","0.19866"
"344.16000","28.68026","0.20090"
"344.44800","28.70418","0.20365"
"344.73600","28.72828","0.20513"
"345.02400","28.75219","0.20666"
"345.31200","28.77622","0.20866"
"345.60000","28.80020","0.20999"
"345.88800","28.82424","0.21096"
"346.17600","28.84821","0.20963"
"346.46400","28.87225","0.21106"
"346.75200","28.89628","0.21254"
"347.04000","28.92020","0.21434"
"347.32800","28.94429","0.21572"
"347.61600","28.96821","0.21839"
"347.90400","28.99218","0.22016"
"348.19200","29.01616","0.22171"
"348.48000","29.04020","0.22414"
"348.76800","29.06417","0.22552"
"349.05600","29.08821","0.22743"
"349.34400","29.11218","0.16794"
"349.63200","29.13622","0.06744"
"349.92000","29.16019","0.03825"
"350.20800","29.18423","0.05167"
"350.49600","29.20827","0.05380"
"350.78400","29.23218","0.02531"
"351.07200","29.25621","0.06860"
"351.36000","29.28019","0.03492"
"351.64800","29.30423","0.04516"
"351.93600","29.32820","0.06625"
"352.22400","29.35224","0.04079"
"352.51200","29.37615","0.06599"
"352.80000","29.40019","0.06139"
"353.08800","29.42416","0.05458"
"353.37600","29.44826","0.07295"
"353.66400","29.47218","0.06084"
"353.95200","29.49621","0.06559"
"354.24000","29.52019","0.07385"
"354.52800","29.54416","0.06554"
"354.81600","29.56820","0.07447"
"355.10400","29.59223","0.07935"
"355.39200","29.61627","0.07109"
"355.68000","29.64018","0.08390"
"355.96800","29.66422","0.08606"
"356.25600","29.68820","0.07765"
"356.54400","29.71223","0.08974"
"356.83200","29.73615","0.08926"
"357.12000","29.76024","0.08683"
"357.40800","29.78416","0.09324"
"357.69600","29.80825","0.09373"
"357.98400","29.83217","0.09315"
"358.27200","29.85620","0.09721"
"358.56000","29.88018","0.09726"
"358.84800","29.90421","0.09804"
"359.13600","29.92825","0.10139"
"359.42400","29.95217","0.10052"
"359.71200","29.97620","0.10070"
"360.00000","30.00024","0.10548"
"360.28800","30.02415","0.10579"
"360.57600","30.04813","0.10784"
"360.86400","30.07222","0.11126"
"361.15200","30.09614","0.11196"
"361.44000","30.12024","0.11317"
"361.72800","30.14415","0.11658"
"362.01600","30.16825","0.11859"
"362.30400","30.19222","0.12041"
"362.59200","30.21619","0.12298"
"362.88000","30.24017","0.12670"
"363.16800","30.26415","0.12863"
"363.45600","30.28818","0.13163"
"363.74400","30.31216","0.13594"
"364.03200","30.33619","0.13782"
"364.32000","30.36017","0.13962"
"364.60800","30.38420","0.14292"
"364.89600","30.40818","0.14586"
"365.18400","30.43221","0.14817"
"365.47200","30.45613","0.15056"
"365.76000","30.48023","0.15175"
"366.04800","30.50414","0.15568"
"366.33600","30.52818","0.15992"
"366.62400","30.55215","0.16443"
"366.91200","30.57619","0.16808"
"367.20000","30.60017","0.17152"
"367.48800","30.62414","0.17470"
"367.77600","30.64823","0.17757"
"368.06400","30.67221","0.17774"
"368.35200","30.69619","0.17976"
"368.64000","30.72016","0.18062"
"368.92800","30.74420","0.17541"
"369.21600","30.76818","0.17748"
"369.50400","30.79221","0.18174"
"369.79200","30.81612","0.18334"
"370.08000","30.84022","0.18726"
"370.36800","30.86420","0.19118"
"370.65600","30.88817","0.19311"
"370.94400","30.91221","0.19573"
"371.23200","30.93618","0.19992"
"371.52000","30.96022","0.20212"
"371.80800","30.98419","0.20372"
"372.09600","31.00823","0.20691"
"372.38400","31.03220","0.20953"
"372.67200","31.05624","0.21029"
"372.96000","31.08015","0.21193"
"373.24800","31.10419","0.21485"
"373.53600","31.12816","0.21730"
"373.82400","31.15226","0.21921"
"374.11200","31.17618","0.22223"
"374.40000","31.20021","0.22493"
"374.68800","31.22419","0.22699"
"374.97600","31.24822","0.22925"
"375.26400","31.27220","0.23263"
"375.55200","31.29617","0.23573"
"375.84000","31.32021","0.23873"
"376.12800","31.34418","0.24158"
"376.41600","31.36828","0.24496"
"376.70400","31.39219","0.24824"
"376.99200","31.41623","0.25084"
"377.28000","31.44015","0.25378"
"377.56800","31.46424","0.25675"
"377.85600","31.48822","0.26011"
"378.14400","31.51225","0.26426"
"378.43200","31.53623","0.26704"
"378.72000","31.56026","0.27050"
"379.00800","31.58424","0.27306"
"379.29600","31.60821","0.27601"
"379.58400","31.63225","0.27962"
"379.87200","31.65616","0.28440"
"380.16000","31.68026","0.28904"
"380.44800","31.70424","0.29365"
"380.73600","31.72821","0.29776"
"381.02400","31.75213","0.30081"
"381.31200","31.77622","0.30327"
"381.60000","31.80020","0.30585"
"381.88800","31.82423","0.30785"
"382.17600","31.84821","0.31033"
"382.46400","31.87231","0.31297"
"382.75200","31.89622","0.31502"
"383.04000","31.92025","0.31730"
"383.32800","31.94423","0.31974"
"383.61600","31.96827","0.32178"
"383.90400","31.99224","0.32399"
"384.19200","32.01616","0.32576"
"384.48000","32.04020","0.32471"
"384.76800","32.06417","0.32688"
"385.05600","32.08820","0.32643"
"385.34400","32.11218","0.21198"
"385.63200","32.13628","0.21148"
"385.92000","32.16019","0.21606"
"386.20800","32.18423","0.21793"
"386.49600","32.20820","0.21872"
"386.78400","32.23223","0.22467"
"387.07200","32.25621","0.22803"
"387.36000","32.28025","0.22756"
"387.64800","32.30422","0.23221"
"387.93600","32.32820","0.23837"
"388.22400","32.35229","0.24116"
"388.51200","32.37615","0.24361"
"388.80000","32.40025","0.24676"
"389.08800","32.42422","0.25192"
"389.37600","32.44826","0.25417"
"389.66400","32.47211","0.25828"
"389.95200","32.49627","0.26215"
"390.24000","32.52018","0.26643"
"390.52800","32.54422","0.26819"
"390.81600","32.56820","0.27127"
"391.10400","32.59223","0.27453"
"391.39200","32.61626","0.27768"
"391.68000","32.64024","0.28136"
"391.96800","32.66422","0.28583"
"392.25600","32.68819","0.15590"
"392.54400","32.71223","0.08143"
"392.83200","32.73615","0.02421"
"393.12000","32.76024","0.03035"
"393.40800","32.78416","0.00160"
"393.69600","32.80825","0.02627"
"393.98400","32.83223","0.03009"
"394.27200","32.85626","0.02113"
"394.56000","32.88018","0.03610"
"394.84800","32.90421","0.00882"
"395.13600","32.92819","0.02375"
"395.42400","32.95222","0.02083"
"395.71200","32.97620","0.01733"
"396.00000","33.00023","0.03680"
"396.28800","33.02427","0.01596"
"396.57600","33.04819","0.02534"
"396.86400","33.07228","0.02202"
"397.15200","33.09620","0.01673"
"397.44000","33.12024","0.02833"
"397.72800","33.14415","0.02162"
"398.01600","33.16824","0.02862"
"398.30400","33.19216","0.02456"
"398.59200","33.21625","0.02334"
"398.88000","33.24017","0.02609"
"399.16800","33.26421","0.02257"
"399.45600","33.28818","0.02441"
"399.74400","33.31216","0.02728"
"400.03200","33.33625","0.02662"
"400.32000","33.36017","0.02702"
"400.60800","33.38426","0.02949"
"400.89600","33.40818","0.02689"
"401.18400","33.43216","0.02999"
"401.47200","33.45613","0.02869"
"401.76000","33.48022","0.03095"
"402.04800","33.50414","0.02849"
"402.33600","33.52824","0.03176"
"402.62400","33.55215","0.03178"
"402.91200","33.57625","0.03237"
"403.20000","33.60016","0.03414"
"403.48800","33.62420","0.03427"
"403.77600","33.64817","0.03461"
"404.06400","33.67221","0.03689"
"404.35200","33.69619","0.03615"
"404.64000","33.72022","0.03867"
"404.92800","33.74420","0.03760"
"405.21600","33.76817","0.03940"
"405.50400","33.79221","0.04006"
"405.79200","33.81618","0.04125"
"406.08000","33.84022","0.04174"
"406.36800","33.86419","0.04206"
"406.65600","33.88823","0.04317"
"406.94400","33.91220","0.04446"
"407.23200","33.93618","0.04489"
"407.52000","33.96022","0.04578"
"407.80800","33.98419","0.04638"
"408.09600","34.00823","0.04745"
"408.38400","34.03220","0.04874"
"408.67200","34.05624","0.04930"
"408.96000","34.08015","0.05032"
"409.24800","34.10425","0.05183"
"409.53600","34.12816","0.05245"
"409.82400","34.15220","0.05411"
"410.11200","34.17611","0.05510"
"410.40000","34.20021","0.05753"
"410.68800","34.22419","0.05824"
"410.97600","34.24822","0.05958"
"411.26400","34.27220","0.06159"
"411.55200","34.29623","0.06208"
"411.84000","34.32021","0.06366"
"412.12800","34.34418","0.06401"
"412.41600","34.36822","0.06541"
"412.70400","34.39219","0.06647"
"412.99200","34.41623","0.06764"
"413.28000","34.44020","0.06815"
"413.56800","34.46424","0.06890"
"413.85600","34.48816","0.07017"
"414.14400","34.51219","0.07072"
"414.43200","34.53617","0.07191"
"414.72000","34.56026","0.07316"
"415.00800","34.58418","0.07432"
"415.29600","34.60822","0.07611"
"415.58400","34.63225","0.07804"
"415.87200","34.65623","0.08027"
"416.16000","34.68026","0.08220"
"416.44800","34.70417","0.08297"
"416.73600","34.72821","0.08527"
"417.02400","34.75219","0.08661"
"417.31200","34.77622","0.08866"
"417.60000","34.80014","0.08954"
"417.88800","34.82429","0.09087"
"418.17600","34.84815","0.09208"
"418.46400","34.87225","0.09270"
"418.75200","34.89622","0.09422"
"419.04000","34.92026","0.09477"
"419.32800","34.94423","0.09497"
"419.61600","34.96821","0.09567"
"419.90400","34.99218","0.09693"
"420.19200","35.01622","0.09772"
"420.48000","35.04019","0.09874"
"420.76800","35.06423","0.09944"
"421.05600","35.08820","0.10048"
"421.34400","35.11218","0.10194"
"421.63200","35.13622","0.10267"
"421.92000","35.16019","0.10381"
"422.20800","35.18429","0.10470"
"422.49600","35.20820","0.10613"
"422.78400","35.23224","0.10695"
"423.07200","35.25621","0.10829"
"423.36000","35.28025","0.10964"
"423.64800","35.30423","0.11054"
"423.93600","35.32826","0.11151"
"424.22400","35.35223","0.02614"
"424.51200","35.37621","-0.00719"
"424.80000","35.40025","-0.00345"
"425.08800","35.42416","-0.00261"
"425.37600","35.44826","-0.00284"
"425.66400","35.47217","-0.00282"
"425.95200","35.49627","-0.00279"
"426.24000","35.52018","-0.00174"
"426.52800","35.54428","-0.00208"
"426.81600","35.56820","-0.00279"
"427.10400","35.59229","-0.00320"
"427.39200","35.61621","-0.00276"
"427.68000","35.64024","-0.00297"
"427.96800","35.66416","-0.00279"
"428.25600","35.68819","-0.00331"
"428.50600","35.70900","-0.00348"