File: Force_trajectories/161221_1/Specimen_RawData_2.csv
End date,"12/21/2016"
Specimen label,"23DGG_81"
Maximum Load,"0.23561",N

Time,Extension,Load
(s),(mm),(N)
"0.00000","0.00000","0.00009"
"0.45600","0.03827","0.00007"
"0.91200","0.07623","0.00051"
"1.36800","0.11420","0.00057"
"1.82400","0.15222","0.00108"
"2.28000","0.19025","0.00090"
"2.73600","0.22822","0.00118"
"3.19200","0.26612","0.00120"
"3.64800","0.30415","0.00118"
"4.10400","0.34218","0.00111"
"4.56000","0.38020","0.00170"
"5.01600","0.41817","0.00157"
"5.47200","0.45619","0.00171"
"5.92800","0.49422","0.00176"
"6.38400","0.53219","0.00188"
"6.84000","0.57015","0.00224"
"7.29600","0.60818","0.00216"
"7.75200","0.64627","0.00225"
"8.20800","0.68423","0.00238"
"8.66400","0.72220","0.00221"
"9.12000","0.76016","0.00231"
"9.57600","0.79819","0.00264"
"10.03200","0.83622","0.00155"
"10.48800","0.87418","0.00155"
"10.94400","0.91221","0.00129"
"11.40000","0.95024","0.00164"
"11.85600","0.98820","0.00162"
"12.31200","1.02617","0.00168"
"12.76800","1.06419","0.00157"
"13.22400","1.10222","0.00174"
"13.68000","1.14025","0.00223"
"14.13600","1.17827","0.00189"
"14.59200","1.21624","0.00206"
"15.04800","1.25420","0.00174"
"15.50400","1.29217","0.00207"
"15.96000","1.33020","0.00218"
"16.41600","1.36822","0.00205"
"16.87200","1.40625","0.00221"
"17.32800","1.44422","0.00207"
"17.78400","1.48218","0.00193"
"18.24000","1.52015","0.00226"
"18.69600","1.55817","0.00227"
"19.15200","1.59620","0.00219"
"19.60800","1.63423","0.00217"
"20.06400","1.67225","0.00200"
"20.52000","1.71022","0.00228"
"20.97600","1.74819","0.00258"
"21.43200","1.78615","0.00222"
"21.88800","1.82424","0.00216"
"22.34400","1.86220","0.00259"
"22.80000","1.90023","0.00234"
"23.25600","1.93826","0.00206"
"23.71200","1.97622","0.00243"
"24.16800","2.01413","0.00225"
"24.62400","2.05216","0.00247"
"25.08000","2.09024","0.00224"
"25.53600","2.12821","0.00223"
"25.99200","2.16623","0.00264"
"26.44800","2.20420","0.00256"
"26.90400","2.24217","0.00216"
"27.36000","2.28013","0.00262"
"27.81600","2.31822","0.00241"
"28.27200","2.35619","0.00290"
"28.72800","2.39421","0.00272"
"29.18400","2.43224","0.00274"
"29.64000","2.47020","0.00249"
"30.09600","2.50817","0.00235"
"30.55200","2.54614","0.00282"
"31.00800","2.58422","0.00255"
"31.46400","2.62225","0.00238"
"31.92000","2.66016","0.00268"
"32.37600","2.69824","0.00282"
"32.83200","2.73621","0.00317"
"33.28800","2.77417","0.00277"
"33.74400","2.81214","0.00308"
"34.20000","2.85017","0.00274"
"34.65600","2.88825","0.00310"
"35.11200","2.92622","0.00312"
"35.56800","2.96425","0.00347"
"36.02400","3.00215","0.00320"
"36.48000","3.04018","0.00292"
"36.93600","3.07820","0.00337"
"37.39200","3.11623","0.00279"
"37.84800","3.15426","0.00299"
"38.30400","3.19222","0.00314"
"38.76000","3.23019","0.00307"
"39.21600","3.26816","0.00301"
"39.67200","3.30618","0.00341"
"40.12800","3.34421","0.00317"
"40.58400","3.38223","0.00307"
"41.04000","3.42026","0.00312"
"41.49600","3.45823","0.00359"
"41.95200","3.49619","0.00330"
"42.40800","3.53416","0.00324"
"42.86400","3.57219","0.00309"
"43.32000","3.61021","0.00362"
"43.77600","3.64824","0.00344"
"44.23200","3.68620","0.00379"
"44.68800","3.72417","0.00353"
"45.14400","3.76214","0.00352"
"45.60000","3.80016","0.00342"
"46.05600","3.83825","0.00314"
"46.51200","3.87622","0.00346"
"46.96800","3.91418","0.00380"
"47.42400","3.95221","0.00372"
"47.88000","3.99017","0.00360"
"48.33600","4.02820","0.00371"
"48.79200","4.06623","0.00353"
"49.24800","4.10413","0.00364"
"49.70400","4.14222","0.00363"
"50.16000","4.18024","0.00391"
"50.61600","4.21821","0.00350"
"51.07200","4.25624","0.00385"
"51.52800","4.29420","0.00347"
"51.98400","4.33217","0.00389"
"52.44000","4.37020","0.00383"
"52.89600","4.40822","0.00417"
"53.35200","4.44619","0.00396"
"53.80800","4.48416","0.00408"
"54.26400","4.52218","0.00403"
"54.72000","4.56015","0.00433"
"55.17600","4.59823","0.00405"
"55.63200","4.63620","0.00439"
"56.08800","4.67429","0.00428"
"56.54400","4.71213","0.00415"
"57.00000","4.75016","0.00411"
"57.45600","4.78819","0.00450"
"57.91200","4.82621","0.00445"
"58.36800","4.86424","0.00431"
"58.82400","4.90226","0.00471"
"59.28000","4.94023","0.00462"
"59.73600","4.97820","0.00420"
"60.19200","5.01616","0.00444"
"60.64800","5.05419","0.00446"
"61.10400","5.09221","0.00457"
"61.56000","5.13024","0.00428"
"62.01600","5.16821","0.00467"
"62.47200","5.20617","0.00473"
"62.92800","5.24414","0.00456"
"63.38400","5.28217","0.00477"
"63.84000","5.32025","0.00490"
"64.29600","5.35822","0.00488"
"64.75200","5.39618","0.00510"
"65.20800","5.43427","0.00518"
"65.66400","5.47224","0.00503"
"66.12000","5.51020","0.00529"
"66.57600","5.54817","0.00547"
"67.03200","5.58620","0.00547"
"67.48800","5.62422","0.00559"
"67.94400","5.66219","0.00560"
"68.40000","5.70021","0.00610"
"68.85600","5.73818","0.00573"
"69.31200","5.77615","0.00594"
"69.76800","5.81423","0.00593"
"70.22400","5.85220","0.00582"
"70.68000","5.89029","0.00656"
"71.13600","5.92819","0.00654"
"71.59200","5.96622","0.00654"
"72.04800","6.00418","0.00710"
"72.50400","6.04215","0.00678"
"72.96000","6.08024","0.00697"
"73.41600","6.11820","0.00740"
"73.87200","6.15623","0.00770"
"74.32800","6.19420","0.00791"
"74.78400","6.23216","0.00800"
"75.24000","6.27013","0.00797"
"75.69600","6.30815","0.00846"
"76.15200","6.34624","0.00874"
"76.60800","6.38427","0.00890"
"77.06400","6.42229","0.00907"
"77.52000","6.46020","0.00947"
"77.97600","6.49817","0.00939"
"78.43200","6.53619","0.00973"
"78.88800","6.57422","0.01028"
"79.34400","6.61224","0.01084"
"79.80000","6.65021","0.01078"
"80.25600","6.68818","0.01117"
"80.71200","6.72614","0.01135"
"81.16800","6.76417","0.01189"
"81.62400","6.80220","0.01240"
"82.08000","6.84016","0.01290"
"82.53600","6.87819","0.01318"
"82.99200","6.91621","0.01349"
"83.44800","6.95418","0.01438"
"83.90400","6.99215","0.01413"
"84.36000","7.03023","0.01510"
"84.81600","7.06820","0.01533"
"85.27200","7.10617","0.01500"
"85.72800","7.14425","0.01245"
"86.18400","7.18222","0.01364"
"86.64000","7.22018","0.01401"
"87.09600","7.25815","0.01445"
"87.55200","7.29618","0.01491"
"88.00800","7.33420","0.01541"
"88.46400","7.37223","0.01626"
"88.92000","7.41025","0.01692"
"89.37600","7.44822","0.01756"
"89.83200","7.48613","0.01828"
"90.28800","7.52415","0.01856"
"90.74400","7.56218","0.01903"
"91.20000","7.60021","0.01985"
"91.65600","7.63823","0.02012"
"92.11200","7.67626","0.02077"
"92.56800","7.71417","0.02123"
"93.02400","7.75219","0.02163"
"93.48000","7.79016","0.02282"
"93.93600","7.82824","0.02332"
"94.39200","7.86621","0.02392"
"94.84800","7.90424","0.02453"
"95.30400","7.94226","0.02558"
"95.76000","7.98017","0.02435"
"96.21600","8.01814","0.02556"
"96.67200","8.05616","0.02652"
"97.12800","8.09425","0.02714"
"97.58400","8.13221","0.02787"
"98.04000","8.17024","0.02836"
"98.49600","8.20821","0.02890"
"98.95200","8.24617","0.02922"
"99.40800","8.28420","0.02578"
"99.86400","8.32216","0.00604"
"100.32000","8.36019","0.00716"
"100.77600","8.39816","0.00617"
"101.23200","8.43618","0.00671"
"101.68800","8.47421","0.00699"
"102.14400","8.51224","0.00715"
"102.60000","8.55020","0.00691"
"103.05600","8.58823","0.00722"
"103.51200","8.62619","0.00756"
"103.96800","8.66422","0.00767"
"104.42400","8.70225","0.00773"
"104.88000","8.74021","0.00796"
"105.33600","8.77818","0.00832"
"105.79200","8.81621","0.00834"
"106.24800","8.85423","0.00818"
"106.70400","8.89220","0.00834"
"107.16000","8.93016","0.00895"
"107.61600","8.96819","0.00887"
"108.07200","9.00616","0.00837"
"108.52800","9.04418","0.00913"
"108.98400","9.08221","0.00933"
"109.44000","9.12018","0.00908"
"109.89600","9.15826","0.00913"
"110.35200","9.19623","0.00954"
"110.80800","9.23419","0.00967"
"111.26400","9.27216","0.00964"
"111.72000","9.31019","0.00955"
"112.17600","9.34827","0.00977"
"112.63200","9.38624","0.00988"
"113.08800","9.42421","0.01078"
"113.54400","9.46217","0.01082"
"114.00000","9.50014","0.01036"
"114.45600","9.53816","0.01076"
"114.91200","9.57619","0.01047"
"115.36800","9.61422","0.01112"
"115.82400","9.65224","0.01122"
"116.28000","9.69015","0.01128"
"116.73600","9.72812","0.01128"
"117.19200","9.76620","0.01156"
"117.64800","9.80423","0.01159"
"118.10400","9.84219","0.01164"
"118.56000","9.88022","0.01191"
"119.01600","9.91819","0.01222"
"119.47200","9.95621","0.01239"
"119.92800","9.99412","0.01228"
"120.38400","10.03221","0.01235"
"120.84000","10.07023","0.01278"
"121.29600","10.10820","0.01332"
"121.75200","10.14622","0.01339"
"122.20800","10.18419","0.01382"
"122.66400","10.22216","0.01373"
"123.12000","10.26018","0.01382"
"123.57600","10.29821","0.01432"
"124.03200","10.33624","0.01454"
"124.48800","10.37420","0.01484"
"124.94400","10.41223","0.01525"
"125.40000","10.45019","0.01525"
"125.85600","10.48816","0.01532"
"126.31200","10.52619","0.01596"
"126.76800","10.56415","0.01617"
"127.22400","10.60218","0.01625"
"127.68000","10.64020","0.01743"
"128.13600","10.67823","0.01765"
"128.59200","10.71620","0.01746"
"129.04800","10.75410","0.01805"
"129.50400","10.79219","0.01887"
"129.96000","10.83022","0.01928"
"130.41600","10.86824","0.01995"
"130.87200","10.90627","0.02049"
"131.32800","10.94418","0.02048"
"131.78400","10.98214","0.02190"
"132.24000","11.02017","0.02196"
"132.69600","11.05819","0.02226"
"133.15200","11.09628","0.02264"
"133.60800","11.13425","0.02274"
"134.06400","11.17221","0.02364"
"134.52000","11.21012","0.02278"
"134.97600","11.24815","0.02262"
"135.43200","11.28617","0.02140"
"135.88800","11.32420","0.02216"
"136.34400","11.36222","0.02260"
"136.80000","11.40019","0.02289"
"137.25600","11.43822","0.02409"
"137.71200","11.47612","0.02450"
"138.16800","11.51415","0.02538"
"138.62400","11.55223","0.02524"
"139.08000","11.59026","0.02562"
"139.53600","11.62823","0.02634"
"139.99200","11.66619","0.02726"
"140.44800","11.70422","0.02821"
"140.90400","11.74219","0.02875"
"141.36000","11.78015","0.02882"
"141.81600","11.81818","0.02965"
"142.27200","11.85620","0.03010"
"142.72800","11.89423","0.03048"
"143.18400","11.93220","0.03108"
"143.64000","11.97022","0.03180"
"144.09600","12.00819","0.03190"
"144.55200","12.04616","0.03243"
"145.00800","12.08424","0.03299"
"145.46400","12.12221","0.03351"
"145.92000","12.16029","0.03363"
"146.37600","12.19820","0.03440"
"146.83200","12.23617","0.03480"
"147.28800","12.27419","0.03558"
"147.74400","12.31216","0.03564"
"148.20000","12.35025","0.03640"
"148.65600","12.38821","0.03661"
"149.11200","12.42624","0.03682"
"149.56800","12.46420","0.03605"
"150.02400","12.50217","0.03665"
"150.48000","12.54020","0.03658"
"150.93600","12.57816","0.03663"
"151.39200","12.61619","0.03667"
"151.84800","12.65421","0.03670"
"152.30400","12.69212","0.03726"
"152.76000","12.73009","0.03784"
"153.21600","12.76817","0.03896"
"153.67200","12.80620","0.04067"
"154.12800","12.84423","0.04129"
"154.58400","12.88225","0.04278"
"155.04000","12.92022","0.04053"
"155.49600","12.95813","0.04158"
"155.95200","12.99615","0.04173"
"156.40800","13.03424","0.04251"
"156.86400","13.07220","0.04393"
"157.32000","13.11017","0.04506"
"157.77600","13.14820","0.04645"
"158.23200","13.18616","0.04779"
"158.68800","13.22413","0.04918"
"159.14400","13.26221","0.05064"
"159.60000","13.30018","0.03531"
"160.05600","13.33821","0.03673"
"160.51200","13.37617","0.03634"
"160.96800","13.41426","0.03743"
"161.42400","13.45223","0.03808"
"161.88000","13.49019","0.03854"
"162.33600","13.52822","0.03921"
"162.79200","13.56618","0.03968"
"163.24800","13.60421","0.03998"
"163.70400","13.64218","0.04017"
"164.16000","13.68020","0.04075"
"164.61600","13.71811","0.04130"
"165.07200","13.75614","0.04147"
"165.52800","13.79416","0.04243"
"165.98400","13.83225","0.04335"
"166.44000","13.87022","0.04442"
"166.89600","13.90818","0.04451"
"167.35200","13.94621","0.04509"
"167.80800","13.98417","0.04540"
"168.26400","14.02220","0.04617"
"168.72000","14.06023","0.04620"
"169.17600","14.09825","0.04707"
"169.63200","14.13622","0.04739"
"170.08800","14.17418","0.04796"
"170.54400","14.21215","0.04864"
"171.00000","14.25012","0.04982"
"171.45600","14.28820","0.04970"
"171.91200","14.32623","0.05018"
"172.36800","14.36420","0.05064"
"172.82400","14.40222","0.05066"
"173.28000","14.44013","0.05180"
"173.73600","14.47815","0.05278"
"174.19200","14.51618","0.05248"
"174.64800","14.55421","0.05343"
"175.10400","14.59223","0.05418"
"175.56000","14.63020","0.05493"
"176.01600","14.66817","0.05532"
"176.47200","14.70619","0.05560"
"176.92800","14.74416","0.05581"
"177.38400","14.78225","0.05685"
"177.84000","14.82021","0.05730"
"178.29600","14.85818","0.05871"
"178.75200","14.89620","0.05974"
"179.20800","14.93417","0.06051"
"179.66400","14.97214","0.06103"
"180.12000","15.01016","0.06164"
"180.57600","15.04813","0.06349"
"181.03200","15.08622","0.06454"
"181.48800","15.12424","0.06551"
"181.94400","15.16227","0.06563"
"182.40000","15.20017","0.06660"
"182.85600","15.23814","0.06747"
"183.31200","15.27617","0.06924"
"183.76800","15.31419","0.06945"
"184.22400","15.35228","0.07101"
"184.68000","15.39018","0.07148"
"185.13600","15.42821","0.07300"
"185.59200","15.46612","0.07373"
"186.04800","15.50414","0.07413"
"186.50400","15.54223","0.07489"
"186.96000","15.58020","0.07560"
"187.41600","15.61822","0.07603"
"187.87200","15.65625","0.06356"
"188.32800","15.69415","0.06212"
"188.78400","15.73212","0.06399"
"189.24000","15.77021","0.06506"
"189.69600","15.80829","0.06594"
"190.15200","15.84626","0.06785"
"190.60800","15.88429","0.06973"
"191.06400","15.92219","0.07043"
"191.52000","15.96016","0.07326"
"191.97600","15.99813","0.07356"
"192.43200","16.03621","0.07363"
"192.88800","16.07424","0.07437"
"193.34400","16.11220","0.07526"
"193.80000","16.15023","0.07588"
"194.25600","16.18819","0.07653"
"194.71200","16.22616","0.07745"
"195.16800","16.26419","0.07736"
"195.62400","16.30215","0.07795"
"196.08000","16.34018","0.07876"
"196.53600","16.37821","0.07972"
"196.99200","16.41623","0.07969"
"197.44800","16.45420","0.08075"
"197.90400","16.49211","0.08139"
"198.36000","16.53019","0.08237"
"198.81600","16.56822","0.08323"
"199.27200","16.60624","0.08395"
"199.72800","16.64421","0.08520"
"200.18400","16.68218","0.08745"
"200.64000","16.72014","0.08853"
"201.09600","16.75817","0.09004"
"201.55200","16.79620","0.09127"
"202.00800","16.83422","0.09215"
"202.46400","16.87225","0.09374"
"202.92000","16.91021","0.09419"
"203.37600","16.94818","0.09488"
"203.83200","16.98615","0.09644"
"204.28800","17.02417","0.09702"
"204.74400","17.06226","0.09813"
"205.20000","17.10022","0.09925"
"205.65600","17.13825","0.10055"
"206.11200","17.17622","0.10106"
"206.56800","17.21412","0.10200"
"207.02400","17.25221","0.10202"
"207.48000","17.29018","0.10282"
"207.93600","17.32820","0.10346"
"208.39200","17.36623","0.10311"
"208.84800","17.40420","0.10186"
"209.30400","17.44216","0.10312"
"209.76000","17.48019","0.10422"
"210.21600","17.51821","0.10502"
"210.67200","17.55624","0.10610"
"211.12800","17.59421","0.10735"
"211.58400","17.63223","0.10819"
"212.04000","17.67026","0.10945"
"212.49600","17.70823","0.10984"
"212.95200","17.74619","0.10431"
"213.40800","17.78416","0.10538"
"213.86400","17.82224","0.01640"
"214.32000","17.86021","0.01508"
"214.77600","17.89818","0.01327"
"215.23200","17.93620","0.01435"
"215.68800","17.97417","0.01747"
"216.14400","18.01219","0.01700"
"216.60000","18.05016","0.01700"
"217.05600","18.08819","0.01945"
"217.51200","18.12627","0.01998"
"217.96800","18.16424","0.02010"
"218.42400","18.20215","0.02192"
"218.88000","18.24023","0.02268"
"219.33600","18.27820","0.02343"
"219.79200","18.31623","0.02453"
"220.24800","18.35419","0.02553"
"220.70400","18.39222","0.02593"
"221.16000","18.43018","0.02684"
"221.61600","18.46815","0.02745"
"222.07200","18.50618","0.02805"
"222.52800","18.54420","0.02768"
"222.98400","18.58223","0.02937"
"223.44000","18.62020","0.02883"
"223.89600","18.65822","0.02948"
"224.35200","18.69613","0.03061"
"224.80800","18.73415","0.03163"
"225.26400","18.77224","0.03185"
"225.72000","18.81021","0.03202"
"226.17600","18.84823","0.03272"
"226.63200","18.88620","0.03311"
"227.08800","18.92416","0.03304"
"227.54400","18.96219","0.03271"
"228.00000","19.00016","0.03245"
"228.45600","19.03818","0.03274"
"228.91200","19.07621","0.03259"
"229.36800","19.11418","0.03324"
"229.82400","19.15220","0.03378"
"230.28000","19.19017","0.03403"
"230.73600","19.22819","0.03405"
"231.19200","19.26616","0.03361"
"231.64800","19.30425","0.03322"
"232.10400","19.34221","0.03325"
"232.56000","19.38024","0.03336"
"233.01600","19.41821","0.03405"
"233.47200","19.45611","0.03521"
"233.92800","19.49414","0.03592"
"234.38400","19.53216","0.03638"
"234.84000","19.57025","0.03776"
"235.29600","19.60822","0.03874"
"235.75200","19.64618","0.03933"
"236.20800","19.68415","0.04072"
"236.66400","19.72217","0.04132"
"237.12000","19.76020","0.04242"
"237.57600","19.79823","0.04306"
"238.03200","19.83625","0.04427"
"238.48800","19.87422","0.04469"
"238.94400","19.91219","0.04597"
"239.40000","19.95015","0.04647"
"239.85600","19.98818","0.04678"
"240.31200","20.02620","0.04812"
"240.76800","20.06423","0.04911"
"241.22400","20.10225","0.05008"
"241.68000","20.14022","0.05084"
"242.13600","20.17813","0.05212"
"242.59200","20.21616","0.05262"
"243.04800","20.25418","0.05308"
"243.50400","20.29221","0.05359"
"243.96000","20.33023","0.05484"
"244.41600","20.36820","0.05543"
"244.87200","20.40617","0.05612"
"245.32800","20.44413","0.05643"
"245.78400","20.48222","0.05650"
"246.24000","20.52024","0.05771"
"246.69600","20.55821","0.05879"
"247.15200","20.59618","0.06071"
"247.60800","20.63421","0.06091"
"248.06400","20.67217","0.06129"
"248.52000","20.71020","0.06134"
"248.97600","20.74817","0.06301"
"249.43200","20.78619","0.06459"
"249.88800","20.82422","0.06755"
"250.34400","20.86224","0.06990"
"250.80000","20.90021","0.07123"
"251.25600","20.93812","0.07350"
"251.71200","20.97620","0.07608"
"252.16800","21.01417","0.07735"
"252.62400","21.05219","0.07843"
"253.08000","21.09022","0.07906"
"253.53600","21.12825","0.08068"
"253.99200","21.16621","0.08219"
"254.44800","21.20418","0.08455"
"254.90400","21.24220","0.08581"
"255.36000","21.28023","0.08725"
"255.81600","21.31820","0.08854"
"256.27200","21.35628","0.09055"
"256.72800","21.39419","0.09130"
"257.18400","21.43216","0.09315"
"257.64000","21.47012","0.09545"
"258.09600","21.50815","0.09715"
"258.55200","21.54623","0.09953"
"259.00800","21.58420","0.10124"
"259.46400","21.62223","0.10303"
"259.92000","21.66013","0.10400"
"260.37600","21.69816","0.10546"
"260.83200","21.73619","0.10664"
"261.28800","21.77427","0.10648"
"261.74400","21.81224","0.10689"
"262.20000","21.85020","0.01727"
"262.65600","21.88817","0.01280"
"263.11200","21.92614","0.01088"
"263.56800","21.96422","0.01116"
"264.02400","22.00219","0.01392"
"264.48000","22.04022","0.01538"
"264.93600","22.07824","0.01422"
"265.39200","22.11621","0.01420"
"265.84800","22.15423","0.01648"
"266.30400","22.19220","0.01709"
"266.76000","22.23017","0.01692"
"267.21600","22.26819","0.01738"
"267.67200","22.30622","0.01843"
"268.12800","22.34419","0.01955"
"268.58400","22.38215","0.02025"
"269.04000","22.42018","0.02105"
"269.49600","22.45815","0.02183"
"269.95200","22.49617","0.02222"
"270.40800","22.53420","0.02308"
"270.86400","22.57216","0.02383"
"271.32000","22.61025","0.02400"
"271.77600","22.64816","0.02521"
"272.23200","22.68618","0.02554"
"272.68800","22.72421","0.02458"
"273.14400","22.76218","0.02481"
"273.60000","22.80020","0.02477"
"274.05600","22.83823","0.02537"
"274.51200","22.87625","0.02644"
"274.96800","22.91416","0.02417"
"275.42400","22.95213","0.02492"
"275.88000","22.99021","0.02559"
"276.33600","23.02824","0.02224"
"276.79200","23.06626","0.02355"
"277.24800","23.10423","0.02437"
"277.70400","23.14220","0.02486"
"278.16000","23.18010","0.02658"
"278.61600","23.21819","0.02670"
"279.07200","23.25622","0.02768"
"279.52800","23.29424","0.02904"
"279.98400","23.33221","0.02922"
"280.44000","23.37023","0.02955"
"280.89600","23.40820","0.02992"
"281.35200","23.44617","0.03103"
"281.80800","23.48419","0.02047"
"282.26400","23.52222","0.02466"
"282.72000","23.56025","0.02498"
"283.17600","23.59821","0.02558"
"283.63200","23.63618","0.02828"
"284.08800","23.67420","0.02838"
"284.54400","23.71217","0.02942"
"285.00000","23.75020","0.03034"
"285.45600","23.78822","0.03085"
"285.91200","23.82619","0.03089"
"286.36800","23.86427","0.03236"
"286.82400","23.90218","0.03285"
"287.28000","23.94015","0.03372"
"287.73600","23.97817","0.03515"
"288.19200","24.01620","0.03562"
"288.64800","24.05423","0.03500"
"289.10400","24.09225","0.03587"
"289.56000","24.13022","0.03717"
"290.01600","24.16818","0.03710"
"290.47200","24.20615","0.03851"
"290.92800","24.24412","0.03780"
"291.38400","24.28220","0.03771"
"291.84000","24.32023","0.03783"
"292.29600","24.35831","0.03786"
"292.75200","24.39616","0.03813"
"293.20800","24.43413","0.01901"
"293.66400","24.47216","0.02602"
"294.12000","24.51024","0.02713"
"294.57600","24.54827","0.02564"
"295.03200","24.58624","0.02826"
"295.48800","24.62420","0.03070"
"295.94400","24.66217","0.03119"
"296.40000","24.70019","0.03186"
"296.85600","24.73816","0.03386"
"297.31200","24.77625","0.03301"
"297.76800","24.81421","0.03389"
"298.22400","24.85224","0.03389"
"298.68000","24.89014","0.03363"
"299.13600","24.92817","0.03166"
"299.59200","24.96620","0.03070"
"300.04800","25.00416","0.03256"
"300.50400","25.04225","0.03278"
"300.96000","25.08022","0.03448"
"301.41600","25.11818","0.03552"
"301.87200","25.15621","0.03664"
"302.32800","25.19417","0.03735"
"302.78400","25.23220","0.03848"
"303.24000","25.27023","0.04030"
"303.69600","25.30819","0.04103"
"304.15200","25.34622","0.04252"
"304.60800","25.38418","0.04422"
"305.06400","25.42221","0.04500"
"305.52000","25.46012","0.04594"
"305.97600","25.49820","0.04703"
"306.43200","25.53617","0.04029"
"306.88800","25.57419","0.03536"
"307.34400","25.61228","0.03714"
"307.80000","25.65019","0.03890"
"308.25600","25.68815","0.03997"
"308.71200","25.72618","0.04245"
"309.16800","25.76421","0.04341"
"309.62400","25.80223","0.04364"
"310.08000","25.84026","0.04489"
"310.53600","25.87823","0.04571"
"310.99200","25.91613","0.04583"
"311.44800","25.95416","0.04514"
"311.90400","25.99219","0.04003"
"312.36000","26.03021","0.04182"
"312.81600","26.06824","0.04349"
"313.27200","26.10620","0.04478"
"313.72800","26.14423","0.04602"
"314.18400","26.18214","0.04666"
"314.64000","26.22022","0.04769"
"315.09600","26.25825","0.04828"
"315.55200","26.29621","0.04948"
"316.00800","26.33424","0.04886"
"316.46400","26.37221","0.04952"
"316.92000","26.41017","0.05022"
"317.37600","26.44820","0.05097"
"317.83200","26.48623","0.05157"
"318.28800","26.52419","0.05168"
"318.74400","26.56222","0.05116"
"319.20000","26.60018","0.04371"
"319.65600","26.63821","0.04493"
"320.11200","26.67618","0.04510"
"320.56800","26.71420","0.04677"
"321.02400","26.75217","0.04750"
"321.48000","26.79026","0.04847"
"321.93600","26.82816","0.04937"
"322.39200","26.86625","0.05034"
"322.84800","26.90421","0.05114"
"323.30400","26.94218","0.05146"
"323.76000","26.98021","0.05252"
"324.21600","27.01817","0.05349"
"324.67200","27.05620","0.05425"
"325.12800","27.09422","0.05525"
"325.58400","27.13219","0.05613"
"326.04000","27.17016","0.05678"
"326.49600","27.20818","0.05732"
"326.95200","27.24615","0.05823"
"327.40800","27.28424","0.05990"
"327.86400","27.32220","0.06094"
"328.32000","27.36023","0.06322"
"328.77600","27.39820","0.06365"
"329.23200","27.43616","0.06603"
"329.68800","27.47419","0.06706"
"330.14400","27.51221","0.06857"
"330.60000","27.55030","0.07009"
"331.05600","27.58821","0.07142"
"331.51200","27.62623","0.07211"
"331.96800","27.66414","0.07364"
"332.42400","27.70216","0.07530"
"332.88000","27.74019","0.07622"
"333.33600","27.77822","0.07760"
"333.79200","27.81618","0.07904"
"334.24800","27.85421","0.07970"
"334.70400","27.89218","0.08111"
"335.16000","27.93014","0.08212"
"335.61600","27.96817","0.08357"
"336.07200","28.00626","0.08511"
"336.52800","28.04422","0.08646"
"336.98400","28.08225","0.08740"
"337.44000","28.12015","0.08903"
"337.89600","28.15818","0.09030"
"338.35200","28.19614","0.09180"
"338.80800","28.23423","0.09355"
"339.26400","28.27226","0.09553"
"339.72000","28.31017","0.09738"
"340.17600","28.34819","0.09813"
"340.63200","28.38616","0.09202"
"341.08800","28.42418","0.07800"
"341.54400","28.46221","0.07888"
"342.00000","28.50018","0.08047"
"342.45600","28.53820","0.08282"
"342.91200","28.57623","0.08533"
"343.36800","28.61425","0.08703"
"343.82400","28.65216","0.08706"
"344.28000","28.69019","0.08646"
"344.73600","28.72821","0.08852"
"345.19200","28.76618","0.09027"
"345.64800","28.80426","0.09179"
"346.10400","28.84229","0.09433"
"346.56000","28.88020","0.09568"
"347.01600","28.91816","0.09549"
"347.47200","28.95619","0.09797"
"347.92800","28.99422","0.09968"
"348.38400","29.03225","0.10049"
"348.84000","29.07021","0.10164"
"349.29600","29.10818","0.10301"
"349.75200","29.14620","0.10327"
"350.20800","29.18417","0.10462"
"350.66400","29.22219","0.10550"
"351.12000","29.26022","0.10715"
"351.57600","29.29819","0.10811"
"352.03200","29.33621","0.10982"
"352.48800","29.37424","0.11132"
"352.94400","29.41215","0.11243"
"353.40000","29.45017","0.11361"
"353.85600","29.48826","0.11544"
"354.31200","29.52622","0.11717"
"354.76800","29.56419","0.11050"
"355.22400","29.60216","0.11371"
"355.68000","29.64018","0.11483"
"356.13600","29.67821","0.11782"
"356.59200","29.71618","0.11978"
"357.04800","29.75420","0.10592"
"357.50400","29.79223","0.11046"
"357.96000","29.83019","0.11196"
"358.41600","29.86822","0.11321"
"358.87200","29.90625","0.11491"
"359.32800","29.94415","0.11875"
"359.78400","29.98218","0.11993"
"360.24000","30.02020","0.12214"
"360.69600","30.05823","0.11927"
"361.15200","30.09626","0.12239"
"361.60800","30.13416","0.12396"
"362.06400","30.17219","0.12529"
"362.52000","30.21016","0.12696"
"362.97600","30.24818","0.12888"
"363.43200","30.28627","0.13013"
"363.88800","30.32424","0.13106"
"364.34400","30.36220","0.13235"
"364.80000","30.40017","0.13294"
"365.25600","30.43819","0.13330"
"365.71200","30.47622","0.13544"
"366.16800","30.51419","0.13633"
"366.62400","30.55221","0.13895"
"367.08000","30.59018","0.14062"
"367.53600","30.62820","0.14173"
"367.99200","30.66617","0.14254"
"368.44800","30.70420","0.14458"
"368.90400","30.74222","0.14631"
"369.36000","30.78019","0.14788"
"369.81600","30.81822","0.14993"
"370.27200","30.85618","0.15132"
"370.72800","30.89415","0.15139"
"371.18400","30.93217","0.15236"
"371.64000","30.97026","0.15466"
"372.09600","31.00823","0.15596"
"372.55200","31.04625","0.15699"
"373.00800","31.08422","0.15819"
"373.46400","31.12218","0.13491"
"373.92000","31.16021","0.13359"
"374.37600","31.19818","0.13846"
"374.83200","31.23621","0.13733"
"375.28800","31.27423","0.14120"
"375.74400","31.31220","0.14516"
"376.20000","31.35022","0.14695"
"376.65600","31.38819","0.14744"
"377.11200","31.42621","0.15066"
"377.56800","31.46418","0.15112"
"378.02400","31.50221","0.14961"
"378.48000","31.54023","0.15237"
"378.93600","31.57826","0.15366"
"379.39200","31.61623","0.15473"
"379.84800","31.65413","0.15475"
"380.30400","31.69216","0.15694"
"380.76000","31.73019","0.15800"
"381.21600","31.76821","0.15844"
"381.67200","31.80624","0.16031"
"382.12800","31.84420","0.16241"
"382.58400","31.88217","0.16383"
"383.04000","31.92014","0.16192"
"383.49600","31.95816","0.16121"
"383.95200","31.99625","0.16355"
"384.40800","32.03421","0.16248"
"384.86400","32.07224","0.16498"
"385.32000","32.11015","0.16628"
"385.77600","32.14817","0.16978"
"386.23200","32.18614","0.17265"
"386.68800","32.22423","0.17562"
"387.14400","32.26225","0.17879"
"387.60000","32.30022","0.18101"
"388.05600","32.33824","0.18295"
"388.51200","32.37615","0.18409"
"388.96800","32.41418","0.18512"
"389.42400","32.45220","0.18671"
"389.88000","32.49023","0.18734"
"390.33600","32.52819","0.18910"
"390.79200","32.56622","0.19080"
"391.24800","32.60419","0.19199"
"391.70400","32.64215","0.19301"
"392.16000","32.68018","0.19444"
"392.61600","32.71827","0.19656"
"393.07200","32.75623","0.19561"
"393.52800","32.79420","0.19926"
"393.98400","32.83223","0.19983"
"394.44000","32.87019","0.20103"
"394.89600","32.90816","0.20304"
"395.35200","32.94613","0.20466"
"395.80800","32.98421","0.20579"
"396.26400","33.02224","0.20723"
"396.72000","33.06026","0.20848"
"397.17600","33.09823","0.20991"
"397.63200","33.13620","0.21106"
"398.08800","33.17416","0.21246"
"398.54400","33.21219","0.21339"
"399.00000","33.25021","0.21477"
"399.45600","33.28824","0.21674"
"399.91200","33.32621","0.21751"
"400.36800","33.36423","0.21709"
"400.82400","33.40214","0.21966"
"401.28000","33.44017","0.22070"
"401.73600","33.47819","0.22209"
"402.19200","33.51622","0.21866"
"402.64800","33.55424","0.21989"
"403.10400","33.59221","0.22039"
"403.56000","33.63018","0.22173"
"404.01600","33.66814","0.22347"
"404.47200","33.70617","0.22605"
"404.92800","33.74420","0.22762"
"405.38400","33.78222","0.22919"
"405.84000","33.82025","0.23106"
"406.29600","33.85815","0.23206"
"406.75200","33.89618","0.23316"
"407.20800","33.93420","0.23421"
"407.66400","33.97223","0.23548"
"408.12000","34.01026","0.08952"
"408.57600","34.04823","0.09420"
"409.03200","34.08619","0.09523"
"409.48800","34.12416","0.03752"
"409.94400","34.16225","0.01087"
"410.40000","34.20021","0.00625"
"410.85600","34.23818","0.00550"
"411.31200","34.27620","0.00546"
"411.76800","34.31423","0.00629"
"412.22400","34.35225","0.00657"
"412.68000","34.39016","0.00660"
"413.13600","34.42813","0.00759"
"413.59200","34.46616","0.00761"
"414.04800","34.50424","0.00853"
"414.50400","34.54221","0.00748"
"414.96000","34.58023","0.00866"
"415.41600","34.61820","0.00841"
"415.87200","34.65617","0.00917"
"416.32800","34.69419","0.00960"
"416.78400","34.73222","0.00934"
"417.24000","34.77018","0.00959"
"417.69600","34.80827","0.00999"
"418.15200","34.84623","0.01045"
"418.60800","34.88414","0.01040"
"419.06400","34.92217","0.01098"
"419.52000","34.96014","0.01088"
"419.97600","34.99822","0.01128"
"420.43200","35.03625","0.01156"
"420.88800","35.07421","0.01147"
"421.34400","35.11218","0.01153"
"421.80000","35.15015","0.01183"
"422.25600","35.18817","0.01226"
"422.71200","35.22626","0.01220"
"423.16800","35.26423","0.01266"
"423.62400","35.30225","0.01299"
"424.08000","35.34016","0.01378"
"424.53600","35.37819","0.01384"
"424.99200","35.41621","0.01405"
"425.44800","35.45424","0.01458"
"425.90400","35.49226","0.01407"
"426.36000","35.53023","0.01445"
"426.81600","35.56820","0.01458"
"427.27200","35.60616","0.01535"
"427.72800","35.64419","0.01577"
"428.18400","35.68215","0.01575"
"428.64000","35.72018","0.01666"
"429.09600","35.75821","0.01623"
"429.55200","35.79623","0.01729"
"430.00800","35.83420","0.01727"
"430.46400","35.87217","0.01738"
"430.92000","35.91013","0.01817"
"431.37600","35.94816","0.01842"
"431.83200","35.98618","0.01900"
"432.28800","36.02421","0.01910"
"432.74400","36.06224","0.01905"
"433.20000","36.10020","0.01988"
"433.65600","36.13817","0.01985"
"434.11200","36.17619","0.02017"
"434.56800","36.21416","0.02005"
"435.02400","36.25219","0.02124"
"435.48000","36.29027","0.02113"
"435.93600","36.32824","0.02087"
"436.39200","36.36615","0.02220"
"436.84800","36.40417","0.02173"
"437.30400","36.44220","0.02143"
"437.76000","36.48022","0.02185"
"438.21600","36.51825","0.02141"
"438.67200","36.55628","0.02178"
"439.12800","36.59418","0.02195"
"439.58400","36.63215","0.02291"
"440.04000","36.67017","0.02366"
"440.49600","36.70820","0.02339"
"440.95200","36.74623","0.02347"
"441.40800","36.78419","0.02403"
"441.86400","36.82216","0.02390"
"442.32000","36.86013","0.02475"
"442.77600","36.89816","0.02573"
"443.23200","36.93624","0.02596"
"443.68800","36.97427","0.02618"
"444.14400","37.01217","0.02656"
"444.60000","37.05020","0.02764"
"445.05600","37.08823","0.02796"
"445.51200","37.12613","0.02801"
"445.96800","37.16422","0.02822"
"446.42400","37.20218","0.02872"
"446.88000","37.24021","0.02900"
"447.33600","37.27818","0.02964"
"447.79200","37.31614","0.02977"
"448.24800","37.35423","0.02999"
"448.70400","37.39220","0.02968"
"449.16000","37.43022","0.02979"
"449.61600","37.46819","0.02995"
"450.07200","37.50628","0.03038"
"450.52800","37.54424","0.03040"
"450.98400","37.58221","0.02784"
"451.44000","37.62023","0.02935"
"451.89600","37.65814","0.02942"
"452.35200","37.69622","0.03007"
"452.80800","37.73419","0.03089"
"453.26400","37.77222","0.03075"
"453.72000","37.81025","0.03141"
"454.17600","37.84821","0.03183"
"454.63200","37.88618","0.03207"
"455.08800","37.92414","0.03236"
"455.54400","37.96217","0.03322"
"456.00000","38.00026","0.03335"
"456.45600","38.03822","0.03395"
"456.91200","38.07619","0.03377"
"457.36800","38.11415","0.03379"
"457.82400","38.15218","0.03424"
"458.28000","38.19014","0.03452"
"458.73600","38.22823","0.03489"
"459.19200","38.26620","0.03539"
"459.64800","38.30423","0.03519"
"460.10400","38.34219","0.03536"
"460.56000","38.38010","0.03482"
"461.01600","38.41824","0.03424"
"461.47200","38.45621","0.03342"
"461.92800","38.49424","0.03382"
"462.38400","38.53220","0.03426"
"462.84000","38.57023","0.03425"
"463.29600","38.60819","0.03424"
"463.75200","38.64616","0.03448"
"464.20800","38.68419","0.03543"
"464.66400","38.72215","0.03572"
"465.12000","38.76024","0.03651"
"465.57600","38.79821","0.03697"
"466.03200","38.83624","0.03687"
"466.48800","38.87420","0.03767"
"466.94400","38.91217","0.03790"
"467.40000","38.95019","0.03568"
"467.85600","38.98822","0.03515"
"468.31200","39.02618","0.03536"
"468.76800","39.06421","0.03445"
"469.22400","39.10217","0.03298"
"469.68000","39.14014","0.03335"
"470.13600","39.17817","0.03396"
"470.59200","39.21619","0.03468"
"471.04800","39.25422","0.03475"
"471.50400","39.29224","0.03505"
"471.96000","39.33022","0.03474"
"472.41600","39.36818","0.03566"
"472.87200","39.40614","0.03619"
"473.32800","39.44417","0.03637"
"473.78400","39.48226","0.03674"
"474.24000","39.52022","0.03650"
"474.69600","39.55825","0.03754"
"475.15200","39.59615","0.03816"
"475.60800","39.63412","0.03846"
"476.06400","39.67215","0.03836"
"476.52000","39.71024","0.03892"
"476.97600","39.74826","0.03876"
"477.43200","39.78617","0.03899"
"477.88800","39.82420","0.03924"
"478.34400","39.86216","0.03933"
"478.80000","39.90019","0.03961"
"479.25600","39.93827","0.03960"
"479.71200","39.97618","0.04025"
"480.16800","40.01420","0.04058"
"480.62400","40.05223","0.03631"
"481.08000","40.09020","0.03585"
"481.53600","40.12816","0.03358"
"481.99200","40.16619","0.03346"
"482.44800","40.20421","0.03359"
"482.90400","40.24224","0.03423"
"483.36000","40.28015","0.03521"
"483.81600","40.31818","0.03575"
"484.27200","40.35620","0.03675"
"484.72800","40.39417","0.03796"
"485.18400","40.43219","0.03855"
"485.64000","40.47021","0.03749"
"486.09600","40.50819","0.03808"
"486.55200","40.54621","0.03786"
"487.00800","40.58418","0.03832"
"487.46400","40.62215","0.03873"
"487.92000","40.66017","0.03991"
"488.37600","40.69813","0.04134"
"488.83200","40.73622","0.04218"
"489.28800","40.77419","0.04327"
"489.74400","40.81222","0.04416"
"490.20000","40.85018","0.04471"
"490.65600","40.88815","0.04520"
"491.11200","40.92617","0.04566"
"491.56800","40.96426","0.04649"
"492.02400","41.00229","0.04699"
"492.48000","41.04025","0.04811"
"492.93600","41.07816","0.04875"
"493.39200","41.11613","0.04879"
"493.84800","41.15415","0.04873"
"494.30400","41.19218","0.04926"
"494.76000","41.23021","0.04961"
"495.21600","41.26817","0.05055"
"495.67200","41.30620","0.05123"
"496.12800","41.34416","0.05142"
"496.58400","41.38213","0.05206"
"497.04000","41.42016","0.05275"
"497.49600","41.45818","0.04892"
"497.95200","41.49621","0.04782"
"498.40800","41.53423","0.03759"
"498.86400","41.57220","0.03923"
"499.32000","41.61016","0.03900"
"499.77600","41.64819","0.03963"
"500.23200","41.68622","0.04085"
"500.68800","41.72424","0.04121"
"501.14400","41.76215","0.04140"
"501.60000","41.80018","0.04169"
"502.05600","41.83814","0.04214"
"502.51200","41.87617","0.03859"
"502.96800","41.91414","0.03961"
"503.42400","41.95222","0.04018"
"503.88000","41.99019","0.04203"
"504.33600","42.02821","0.04210"
"504.79200","42.06618","0.04159"
"505.24800","42.10420","0.04258"
"505.70400","42.14217","0.04385"
"506.16000","42.18014","0.04389"
"506.61600","42.21816","0.04486"
"507.07200","42.25625","0.04534"
"507.52800","42.29428","0.04599"
"507.98400","42.33219","0.04605"
"508.44000","42.37009","0.04742"
"508.89600","42.40818","0.04823"
"509.35200","42.44621","0.04882"
"509.80800","42.48423","0.04956"
"510.26400","42.52219","0.05057"
"510.72000","42.56022","0.05145"
"511.17600","42.59819","0.05222"
"511.63200","42.63615","0.05249"
"512.08800","42.67418","0.05317"
"512.54400","42.71221","0.05402"
"513.00000","42.75024","0.05465"
"513.45600","42.78826","0.05528"
"513.91200","42.82616","0.05655"
"514.36800","42.86413","0.05721"
"514.82400","42.90216","0.05832"
"515.28000","42.94019","0.06022"
"515.73600","42.97821","0.06161"
"516.19200","43.01617","0.06157"
"516.64800","43.05420","0.06197"
"517.10400","43.09217","0.06359"
"517.56000","43.13014","0.06509"
"518.01600","43.16822","0.06593"
"518.47200","43.20618","0.06082"
"518.92800","43.24422","0.06057"
"519.38400","43.28224","0.06191"
"519.84000","43.32021","0.06375"
"520.29600","43.35823","0.06448"
"520.75200","43.39614","0.06380"
"521.20800","43.43417","0.06544"
"521.66400","43.47219","0.06752"
"522.12000","43.51022","0.06702"
"522.57600","43.54818","0.06923"
"523.03200","43.58615","0.06900"
"523.48800","43.62418","0.07091"
"523.94400","43.66215","0.07299"
"524.40000","43.70017","0.07447"
"524.85600","43.73819","0.07505"
"525.31200","43.77622","0.07655"
"525.76800","43.81425","0.07694"
"526.22400","43.85215","0.07800"
"526.68000","43.89018","0.07907"
"527.13600","43.92821","0.07934"
"527.59200","43.96623","0.05778"
"528.04800","44.00426","0.04458"
"528.50400","44.04222","0.04586"
"528.96000","44.08014","0.04836"
"529.41600","44.11810","0.04976"
"529.87200","44.15619","0.05131"
"530.32800","44.19415","0.05313"
"530.78400","44.23218","0.05512"
"531.24000","44.27027","0.05687"
"531.69600","44.30817","0.05841"
"532.15200","44.34614","0.06105"
"532.60800","44.38416","0.05581"
"533.06400","44.42225","0.00164"
"533.52000","44.46022","0.00329"
"533.97600","44.49824","0.00217"
"534.43200","44.53620","0.00216"
"534.88800","44.57418","0.00310"
"535.34400","44.61214","0.00238"
"535.80000","44.65017","0.00230"
"536.25600","44.68819","0.00358"
"536.71200","44.72622","0.00229"
"537.16800","44.76419","0.00224"
"537.62400","44.80215","0.00269"
"538.08000","44.84018","0.00215"
"538.53600","44.87814","0.00257"
"538.99200","44.91617","0.00261"
"539.44800","44.95420","0.00247"
"539.90400","44.99216","0.00299"
"540.36000","45.03025","0.00264"
"540.81600","45.06821","0.00205"
"541.27200","45.10612","0.00291"
"541.72800","45.14421","0.00266"
"542.18400","45.18224","0.00242"
"542.64000","45.22020","0.00302"
"543.09600","45.25822","0.00235"
"543.55200","45.29619","0.00222"
"544.00800","45.33416","0.00293"
"544.46400","45.37212","0.00235"
"544.92000","45.41015","0.00243"
"545.37600","45.44823","0.00284"
"545.83200","45.48621","0.00214"
"546.28800","45.52422","0.00264"
"546.74400","45.56213","0.00271"
"547.20000","45.60017","0.00233"
"547.65600","45.63819","0.00278"
"548.11200","45.67622","0.00232"
"548.56800","45.71424","0.00213"
"549.02400","45.75221","0.00309"
"549.48000","45.79017","0.00255"
"549.93600","45.82814","0.00202"
"550.39200","45.86617","0.00273"
"550.84800","45.90419","0.00228"
"551.30400","45.94222","0.00247"
"551.76000","45.98018","0.00231"
"552.21600","46.01821","0.00217"
"552.67200","46.05618","0.00228"
"553.12800","46.09414","0.00240"
"553.58400","46.13217","0.00191"
"554.04000","46.17020","0.00284"
"554.49600","46.20822","0.00224"
"554.95200","46.24619","0.00255"
"555.40800","46.28421","0.00271"
"555.86400","46.32224","0.00257"
"556.32000","46.36020","0.00230"
"556.77600","46.39824","0.00277"
"557.23200","46.43620","0.00271"
"557.68800","46.47422","0.00259"
"558.14400","46.51225","0.00318"
"558.60000","46.55022","0.00270"
"559.05600","46.58813","0.00266"
"559.51200","46.62615","0.00226"
"559.96800","46.66418","0.00240"
"560.42400","46.70220","0.00265"
"560.88000","46.74023","0.00264"
"561.33600","46.77819","0.00208"
"561.79200","46.81616","0.00272"
"562.24800","46.85413","0.00223"
"562.70400","46.89221","0.00279"
"563.16000","46.93024","0.00239"
"563.61600","46.96827","0.00237"
"564.07200","47.00629","0.00261"
"564.52800","47.04420","0.00238"
"564.98400","47.08216","0.00259"
"565.44000","47.12019","0.00256"
"565.89600","47.15816","0.00337"
"566.35200","47.19618","0.00278"
"566.80800","47.23421","0.00304"
"567.26400","47.27224","0.00283"
"567.72000","47.31020","0.00275"
"568.17600","47.34811","0.00303"
"568.63200","47.38614","0.00292"
"569.08800","47.42422","0.00283"
"569.54400","47.46225","0.00337"
"570.00000","47.50021","0.00296"
"570.45600","47.53818","0.00256"
"570.91200","47.57620","0.00282"
"571.36800","47.61423","0.00293"
"571.82400","47.65220","0.00276"
"572.28000","47.69016","0.00324"
"572.73600","47.72819","0.00272"
"573.19200","47.76622","0.00264"
"573.64800","47.80418","0.00297"
"574.10400","47.84215","0.00263"
"574.56000","47.88017","0.00282"
"575.01600","47.91814","0.00264"
"575.47200","47.95623","0.00263"
"575.92800","47.99420","0.00332"
"576.38400","48.03222","0.00269"
"576.84000","48.07019","0.00291"
"577.29600","48.10815","0.00312"
"577.75200","48.14618","0.00279"
"578.20800","48.18421","0.00244"
"578.66400","48.22217","0.00298"
"579.12000","48.26020","0.00267"
"579.57600","48.29822","0.00304"
"580.03200","48.33619","0.00297"
"580.48800","48.37416","0.00314"
"580.94400","48.41212","0.00316"
"581.40000","48.45021","0.00279"
"581.85600","48.48823","0.00305"
"582.31200","48.52621","0.00287"
"582.76800","48.56417","0.00264"
"583.22400","48.60213","0.00308"
"583.68000","48.64016","0.00299"
"584.13600","48.67825","0.00329"
"584.59200","48.71621","0.00311"
"585.04800","48.75424","0.00310"
"585.50400","48.79221","0.00360"
"585.96000","48.83017","0.00296"
"586.41600","48.86819","0.00328"
"586.87200","48.90623","0.00330"
"587.32800","48.94425","0.00354"
"587.78400","48.98222","0.00347"
"588.24000","49.02018","0.00306"
"588.69600","49.05815","0.00378"
"589.15200","49.09618","0.00319"
"589.60800","49.13420","0.00360"
"590.06400","49.17223","0.00377"
"590.52000","49.21019","0.00384"
"590.97600","49.24816","0.00393"
"591.43200","49.28619","0.00337"
"591.88800","49.32415","0.00392"
"592.34400","49.36224","0.00380"
"592.80000","49.40020","0.00346"
"593.25600","49.43824","0.00365"
"593.71200","49.47620","0.00389"
"594.16800","49.51423","0.00365"
"594.62400","49.55219","0.00424"
"595.08000","49.59010","0.00411"
"595.53600","49.62818","0.00409"
"595.99200","49.66615","0.00467"
"596.44800","49.70424","0.00417"
"596.90400","49.74226","0.00456"
"597.36000","49.78023","0.00438"
"597.81600","49.81813","0.00450"
"598.27200","49.85616","0.00480"
"598.72800","49.89419","0.00447"
"599.18400","49.93221","0.00505"
"599.64000","49.97024","0.00515"
"600.09600","50.00826","0.00537"
"600.55200","50.04617","0.00534"
"601.00800","50.08414","0.00551"
"601.46400","50.12210","0.00546"
"601.92000","50.16019","0.00586"
"602.37600","50.19821","0.00565"
"602.83200","50.23618","0.00551"
"603.28800","50.27427","0.00584"
"603.74400","50.31211","0.00599"
"604.20000","50.35014","0.00606"
"604.65600","50.38816","0.00642"
"605.11200","50.42625","0.00646"
"605.56800","50.46422","0.00662"
"606.02400","50.50219","0.00679"
"606.48000","50.54015","0.00659"
"606.93600","50.57812","0.00691"
"607.39200","50.61620","0.00720"
"607.84800","50.65423","0.00719"
"608.30400","50.69226","0.00732"
"608.76000","50.73016","0.00707"
"609.21600","50.76819","0.00747"
"609.67200","50.80622","0.00631"
"610.12800","50.84412","0.00567"
"610.58400","50.88214","0.00588"
"611.04000","50.92023","0.00592"
"611.49600","50.95820","0.00592"
"611.95200","50.99622","0.00557"
"612.40800","51.03426","0.00574"
"612.86400","51.07222","0.00571"
"613.32000","51.11013","0.00571"
"613.77600","51.14816","0.00544"
"614.23200","51.18624","0.00454"
"614.68800","51.22420","0.00454"
"615.14400","51.26223","0.00381"
"615.60000","51.30019","0.00359"
"616.05600","51.33817","0.00315"
"616.51200","51.37619","0.00317"
"616.96800","51.41422","0.00297"
"617.42400","51.45218","0.00292"
"617.88000","51.49021","0.00300"
"618.33600","51.52818","0.00280"
"618.79200","51.56614","0.00330"
"619.24800","51.60411","0.00306"
"619.70400","51.64214","0.00284"
"620.16000","51.68028","0.00316"
"620.61600","51.71824","0.00322"
"621.07200","51.75628","0.00354"
"621.52800","51.79418","0.00317"
"621.98400","51.83214","0.00310"
"622.44000","51.87017","0.00298"
"622.89600","51.90820","0.00324"
"623.35200","51.94623","0.00317"
"623.80800","51.98419","0.00321"
"624.26400","52.02222","0.00288"
"624.72000","52.06012","0.00304"
"625.17600","52.09821","0.00319"
"625.63200","52.13618","0.00335"
"626.08800","52.17420","0.00279"
"626.54400","52.21216","0.00300"
"627.00000","52.25019","0.00309"
"627.45600","52.28822","0.00335"
"627.91200","52.32619","0.00320"
"628.36800","52.36415","0.00343"
"628.82400","52.40224","0.00325"
"629.28000","52.44020","0.00299"
"629.73600","52.47823","0.00258"
"630.19200","52.51620","0.00293"
"630.64800","52.55416","0.00284"
"631.10400","52.59213","0.00275"
"631.56000","52.63016","0.00317"
"632.01600","52.66818","0.00249"
"632.47200","52.70615","0.00277"
"632.92800","52.74423","0.00270"
"633.38400","52.78220","0.00279"
"633.84000","52.82016","0.00260"
"634.29600","52.85814","0.00253"
"634.75200","52.89616","0.00289"
"635.20800","52.93425","0.00295"
"635.66400","52.97227","0.00299"
"636.12000","53.01018","0.00268"
"636.57600","53.04821","0.00284"
"637.03200","53.08611","0.00282"
"637.48800","53.12413","0.00299"
"637.94400","53.16228","0.00248"
"638.40000","53.20019","0.00296"
"638.85600","53.23822","0.00305"
"639.31200","53.27618","0.00289"
"639.76800","53.31415","0.00310"
"640.22400","53.35217","0.00264"
"640.68000","53.39026","0.00282"
"641.13600","53.42823","0.00285"
"641.59200","53.46619","0.00294"
"642.04800","53.50422","0.00283"
"642.50400","53.54218","0.00303"
"642.96000","53.58015","0.00265"
"643.41600","53.61824","0.00297"
"643.87200","53.65614","0.00283"
"644.32800","53.69423","0.00302"
"644.78400","53.73219","0.00274"
"645.24000","53.77023","0.00267"
"645.69600","53.80819","0.00332"
"646.15200","53.84616","0.00307"
"646.60800","53.88424","0.00287"
"647.06400","53.92221","0.00295"
"647.52000","53.96017","0.00272"
"647.97600","53.99826","0.00238"
"648.43200","54.03616","0.00246"
"648.88800","54.07413","0.00251"
"649.34400","54.11222","0.00314"
"649.80000","54.15018","0.00291"
"650.25600","54.18821","0.00254"
"650.71200","54.22624","0.00293"
"651.16800","54.26420","0.00264"
"651.62400","54.30217","0.00282"
"652.08000","54.34019","0.00309"
"652.53600","54.37816","0.00284"
"652.99200","54.41619","0.00284"
"653.44800","54.45428","0.00323"
"653.90400","54.49224","0.00330"
"654.36000","54.53021","0.00303"
"654.81600","54.56817","0.00295"
"655.27200","54.60614","0.00309"
"655.72800","54.64417","0.00252"
"656.18400","54.68225","0.00299"
"656.64000","54.72021","0.00280"
"657.09600","54.75819","0.00288"
"657.55200","54.79615","0.00321"
"658.00800","54.83418","0.00341"
"658.46400","54.87220","0.00302"
"658.92000","54.91023","0.00307"
"659.37600","54.94820","0.00322"
"659.83200","54.98622","0.00311"
"660.28800","55.02425","0.00312"
"660.74400","55.06216","0.00330"
"661.20000","55.10018","0.00328"
"661.65600","55.13821","0.00322"
"662.11200","55.17624","0.00344"
"662.56800","55.21420","0.00310"
"663.02400","55.25222","0.00331"
"663.48000","55.29019","0.00345"
"663.93600","55.32816","0.00319"
"664.39200","55.36619","0.00316"
"664.84800","55.40415","0.00309"
"665.30400","55.44224","0.00342"
"665.76000","55.48021","0.00284"
"666.21600","55.51823","0.00306"
"666.67200","55.55619","0.00293"
"667.12800","55.59417","0.00276"
"667.58400","55.63225","0.00317"
"668.04000","55.67022","0.00265"
"668.49600","55.70818","0.00309"
"668.95200","55.74627","0.00347"
"669.40800","55.78423","0.00283"
"669.86400","55.82220","0.00289"
"670.32000","55.86017","0.00279"
"670.77600","55.89819","0.00291"
"671.23200","55.93622","0.00297"
"671.68800","55.97424","0.00278"
"672.14400","56.01221","0.00284"
"672.60000","56.05018","0.00277"
"673.05600","56.08820","0.00284"
"673.51200","56.12617","0.00251"
"673.96800","56.16426","0.00281"
"674.42400","56.20222","0.00263"
"674.88000","56.24025","0.00235"
"675.33600","56.27822","0.00242"
"675.79200","56.31606","0.00277"
"676.24800","56.35421","0.00240"
"676.70400","56.39223","0.00262"
"677.16000","56.43026","0.00242"
"677.22800","56.43582","0.00265"