File: Force_trajectories/161221_1/Specimen_RawData_9.csv
End date,"12/21/2016"
Specimen label,"24BG_95_run3"
Maximum Load,"0.04333",N

Time,Extension,Load
(s),(mm),(N)
"0.00000","18.84548","0.00640"
"0.48000","18.88584","0.00654"
"0.96000","18.92566","0.00634"
"1.44000","18.96566","0.00666"
"1.92000","19.00566","0.00662"
"2.40000","19.04566","0.00710"
"2.88000","19.08566","0.00693"
"3.36000","19.12572","0.00660"
"3.84000","19.16559","0.00684"
"4.32000","19.20560","0.00696"
"4.80000","19.24565","0.00727"
"5.28000","19.28565","0.00710"
"5.76000","19.32565","0.00733"
"6.24000","19.36571","0.00715"
"6.72000","19.40571","0.00707"
"7.20000","19.44571","0.00730"
"7.68000","19.48565","0.00729"
"8.16000","19.52559","0.00737"
"8.64000","19.56565","0.00746"
"9.12000","19.60565","0.00732"
"9.60000","19.64565","0.00740"
"10.08000","19.68570","0.00710"
"10.56000","19.72564","0.00734"
"11.04000","19.76564","0.00767"
"11.52000","19.80570","0.00769"
"12.00000","19.84564","0.00747"
"12.48000","19.88564","0.00746"
"12.96000","19.92564","0.00761"
"13.44000","19.96558","0.00740"
"13.92000","20.00564","0.00734"
"14.40000","20.04570","0.00766"
"14.88000","20.08570","0.00758"
"15.36000","20.12569","0.00769"
"15.84000","20.16570","0.00770"
"16.32000","20.20563","0.00747"
"16.80000","20.24563","0.00750"
"17.28000","20.28563","0.00773"
"17.76000","20.32557","0.00774"
"18.24000","20.36563","0.00750"
"18.72000","20.40569","0.00763"
"19.20000","20.44563","0.00768"
"19.68000","20.48569","0.00763"
"20.16000","20.52569","0.00767"
"20.64000","20.56569","0.00777"
"21.12000","20.60568","0.00773"
"21.60000","20.64569","0.00796"
"22.08000","20.68556","0.00781"
"22.56000","20.72562","0.00783"
"23.04000","20.76562","0.00765"
"23.52000","20.80568","0.00747"
"24.00000","20.84568","0.00776"
"24.48000","20.88568","0.00788"
"24.96000","20.92568","0.00766"
"25.44000","20.96562","0.00800"
"25.92000","21.00562","0.00761"
"26.40000","21.04562","0.00770"
"26.88000","21.08568","0.00742"
"27.36000","21.12561","0.00765"
"27.84000","21.16567","0.00787"
"28.32000","21.20567","0.00769"
"28.80000","21.24567","0.00770"
"29.28000","21.28561","0.00770"
"29.76000","21.32573","0.00788"
"30.24000","21.36567","0.00772"
"30.72000","21.40561","0.00777"
"31.20000","21.44561","0.00775"
"31.68000","21.48567","0.00769"
"32.16000","21.52561","0.00793"
"32.64000","21.56573","0.00775"
"33.12000","21.60566","0.00749"
"33.60000","21.64566","0.00768"
"34.08000","21.68566","0.00761"
"34.56000","21.72566","0.00782"
"35.04000","21.76560","0.00780"
"35.52000","21.80560","0.00779"
"36.00000","21.84566","0.00768"
"36.48000","21.88566","0.00772"
"36.96000","21.92566","0.00791"
"37.44000","21.96566","0.00805"
"37.92000","22.00566","0.00788"
"38.40000","22.04572","0.00806"
"38.88000","22.08560","0.00797"
"39.36000","22.12566","0.00769"
"39.84000","22.16559","0.00758"
"40.32000","22.20560","0.00794"
"40.80000","22.24565","0.00765"
"41.28000","22.28565","0.00787"
"41.76000","22.32565","0.00795"
"42.24000","22.36571","0.00794"
"42.72000","22.40565","0.00821"
"43.20000","22.44565","0.00789"
"43.68000","22.48565","0.00797"
"44.16000","22.52565","0.00764"
"44.64000","22.56558","0.00797"
"45.12000","22.60565","0.00757"
"45.60000","22.64565","0.00753"
"46.08000","22.68564","0.00766"
"46.56000","22.72570","0.00747"
"47.04000","22.76570","0.00731"
"47.52000","22.80570","0.00786"
"48.00000","22.84570","0.00750"
"48.48000","22.88564","0.00775"
"48.96000","22.92564","0.00711"
"49.44000","22.96558","0.00774"
"49.92000","23.00564","0.00727"
"50.40000","23.04570","0.00761"
"50.88000","23.08563","0.00747"
"51.36000","23.12564","0.00732"
"51.84000","23.16570","0.00751"
"52.32000","23.20564","0.00688"
"52.80000","23.24557","0.00755"
"53.28000","23.28563","0.00761"
"53.76000","23.32563","0.00759"
"54.24000","23.36563","0.00763"
"54.72000","23.40563","0.00765"
"55.20000","23.44569","0.00752"
"55.68000","23.48563","0.00775"
"56.16000","23.52568","0.00767"
"56.64000","23.56569","0.00768"
"57.12000","23.60563","0.00771"
"57.60000","23.64562","0.00758"
"58.08000","23.68562","0.00775"
"58.56000","23.72562","0.00794"
"59.04000","23.76568","0.00742"
"59.52000","23.80568","0.00757"
"60.00000","23.84568","0.00765"
"60.48000","23.88568","0.00749"
"60.96000","23.92562","0.00763"
"61.44000","23.96568","0.00763"
"61.92000","24.00568","0.00744"
"62.40000","24.04561","0.00789"
"62.88000","24.08562","0.00744"
"63.36000","24.12567","0.00767"
"63.84000","24.16567","0.00776"
"64.32000","24.20567","0.00743"
"64.80000","24.24573","0.00765"
"65.28000","24.28567","0.00754"
"65.76000","24.32567","0.00770"
"66.24000","24.36561","0.00750"
"66.72000","24.40561","0.00790"
"67.20000","24.44567","0.00754"
"67.68000","24.48567","0.00759"
"68.16000","24.52567","0.00764"
"68.64000","24.56573","0.00774"
"69.12000","24.60566","0.00734"
"69.60000","24.64566","0.00728"
"70.08000","24.68566","0.00750"
"70.56000","24.72560","0.00736"
"71.04000","24.76560","0.00785"
"71.52000","24.80560","0.00763"
"72.00000","24.84560","0.00750"
"72.48000","24.88566","0.00760"
"72.96000","24.92566","0.00772"
"73.44000","24.96566","0.00778"
"73.92000","25.00566","0.00765"
"74.40000","25.04572","0.00725"
"74.88000","25.08566","0.00737"
"75.36000","25.12559","0.00780"
"75.84000","25.16566","0.00727"
"76.32000","25.20559","0.00775"
"76.80000","25.24565","0.00750"
"77.28000","25.28565","0.00752"
"77.76000","25.32565","0.00746"
"78.24000","25.36571","0.00737"
"78.72000","25.40571","0.00772"
"79.20000","25.44571","0.00744"
"79.68000","25.48565","0.00739"
"80.16000","25.52565","0.00723"
"80.64000","25.56559","0.00737"
"81.12000","25.60571","0.00709"
"81.60000","25.64564","0.00748"
"82.08000","25.68564","0.00746"
"82.56000","25.72570","0.00751"
"83.04000","25.76570","0.00747"
"83.52000","25.80564","0.00758"
"84.00000","25.84564","0.00768"
"84.48000","25.88564","0.00759"
"84.96000","25.92564","0.00744"
"85.44000","25.96564","0.00714"
"85.92000","26.00564","0.00717"
"86.40000","26.04564","0.00738"
"86.88000","26.08564","0.00723"
"87.36000","26.12569","0.00762"
"87.84000","26.16563","0.00724"
"88.32000","26.20563","0.00741"
"88.80000","26.24563","0.00739"
"89.28000","26.28563","0.00762"
"89.76000","26.32569","0.00772"
"90.24000","26.36563","0.00779"
"90.72000","26.40569","0.00767"
"91.20000","26.44563","0.00752"
"91.68000","26.48569","0.00737"
"92.16000","26.52563","0.00774"
"92.64000","26.56562","0.00743"
"93.12000","26.60563","0.00735"
"93.60000","26.64568","0.00764"
"94.08000","26.68562","0.00740"
"94.56000","26.72568","0.00770"
"95.04000","26.76568","0.00741"
"95.52000","26.80562","0.00741"
"96.00000","26.84562","0.00716"
"96.48000","26.88568","0.00756"
"96.96000","26.92562","0.00763"
"97.44000","26.96562","0.00790"
"97.92000","27.00562","0.00766"
"98.40000","27.04556","0.00768"
"98.88000","27.08562","0.00766"
"99.36000","27.12573","0.00771"
"99.84000","27.16567","0.00749"
"100.32000","27.20567","0.00739"
"100.80000","27.24567","0.00772"
"101.28000","27.28561","0.00770"
"101.76000","27.32561","0.00781"
"102.24000","27.36567","0.00767"
"102.72000","27.40561","0.00760"
"103.20000","27.44567","0.00757"
"103.68000","27.48561","0.00745"
"104.16000","27.52567","0.00762"
"104.64000","27.56567","0.00744"
"105.12000","27.60572","0.00761"
"105.60000","27.64566","0.00763"
"106.08000","27.68567","0.00774"
"106.56000","27.72560","0.00797"
"107.04000","27.76560","0.00769"
"107.52000","27.80560","0.00771"
"108.00000","27.84566","0.00782"
"108.48000","27.88566","0.00780"
"108.96000","27.92572","0.00797"
"109.44000","27.96572","0.00821"
"109.92000","28.00560","0.00809"
"110.40000","28.04566","0.00780"
"110.88000","28.08560","0.00809"
"111.36000","28.12565","0.00815"
"111.84000","28.16560","0.00800"
"112.32000","28.20565","0.00817"
"112.80000","28.24565","0.00827"
"113.28000","28.28565","0.00811"
"113.76000","28.32565","0.00824"
"114.24000","28.36565","0.00825"
"114.72000","28.40565","0.00823"
"115.20000","28.44565","0.00820"
"115.68000","28.48559","0.00839"
"116.16000","28.52565","0.00828"
"116.64000","28.56565","0.00793"
"117.12000","28.60570","0.00799"
"117.60000","28.64570","0.00844"
"118.08000","28.68564","0.00807"
"118.56000","28.72570","0.00818"
"119.04000","28.76564","0.00784"
"119.52000","28.80564","0.00775"
"120.00000","28.84564","0.00815"
"120.48000","28.88564","0.00817"
"120.96000","28.92570","0.00837"
"121.44000","28.96564","0.00822"
"121.92000","29.00564","0.00817"
"122.40000","29.04564","0.00814"
"122.88000","29.08570","0.00832"
"123.36000","29.12564","0.00835"
"123.84000","29.16563","0.00818"
"124.32000","29.20563","0.00832"
"124.80000","29.24563","0.00863"
"125.28000","29.28563","0.00837"
"125.76000","29.32569","0.00844"
"126.24000","29.36569","0.00828"
"126.72000","29.40569","0.00823"
"127.20000","29.44569","0.00850"
"127.68000","29.48563","0.00868"
"128.16000","29.52563","0.00848"
"128.64000","29.56563","0.00840"
"129.12000","29.60563","0.00813"
"129.60000","29.64563","0.00879"
"130.08000","29.68568","0.00835"
"130.56000","29.72568","0.00871"
"131.04000","29.76562","0.00855"
"131.52000","29.80568","0.00866"
"132.00000","29.84568","0.00894"
"132.48000","29.88562","0.00875"
"132.96000","29.92562","0.00918"
"133.44000","29.96556","0.00862"
"133.92000","30.00562","0.00875"
"134.40000","30.04568","0.00874"
"134.88000","30.08568","0.00869"
"135.36000","30.12573","0.00888"
"135.84000","30.16561","0.00873"
"136.32000","30.20568","0.00889"
"136.80000","30.24561","0.00878"
"137.28000","30.28561","0.00891"
"137.76000","30.32555","0.00964"
"138.24000","30.36567","0.00940"
"138.72000","30.40561","0.00886"
"139.20000","30.44567","0.00899"
"139.68000","30.48567","0.00910"
"140.16000","30.52567","0.00871"
"140.64000","30.56566","0.00906"
"141.12000","30.60567","0.00922"
"141.60000","30.64566","0.00911"
"142.08000","30.68554","0.00924"
"142.56000","30.72566","0.00913"
"143.04000","30.76566","0.00921"
"143.52000","30.80566","0.00926"
"144.00000","30.84566","0.00910"
"144.48000","30.88566","0.00915"
"144.96000","30.92572","0.00919"
"145.44000","30.96566","0.00907"
"145.92000","31.00560","0.00927"
"146.40000","31.04560","0.00922"
"146.88000","31.08560","0.00951"
"147.36000","31.12566","0.00955"
"147.84000","31.16566","0.00933"
"148.32000","31.20565","0.00918"
"148.80000","31.24565","0.00946"
"149.28000","31.28565","0.00944"
"149.76000","31.32571","0.00921"
"150.24000","31.36565","0.00962"
"150.72000","31.40565","0.00948"
"151.20000","31.44559","0.00960"
"151.68000","31.48559","0.00957"
"152.16000","31.52571","0.00972"
"152.64000","31.56564","0.00967"
"153.12000","31.60570","0.00980"
"153.60000","31.64570","0.00967"
"154.08000","31.68564","0.00990"
"154.56000","31.72564","0.00997"
"155.04000","31.76564","0.00970"
"155.52000","31.80564","0.00968"
"156.00000","31.84564","0.00983"
"156.48000","31.88564","0.00972"
"156.96000","31.92564","0.00986"
"157.44000","31.96564","0.01000"
"157.92000","32.00570","0.01002"
"158.40000","32.04564","0.01015"
"158.88000","32.08569","0.00988"
"159.36000","32.12563","0.01044"
"159.84000","32.16557","0.01062"
"160.32000","32.20563","0.01052"
"160.80000","32.24563","0.01038"
"161.28000","32.28563","0.01044"
"161.76000","32.32569","0.01018"
"162.24000","32.36569","0.01008"
"162.72000","32.40562","0.01019"
"163.20000","32.44569","0.01033"
"163.68000","32.48569","0.01023"
"164.16000","32.52562","0.01091"
"164.64000","32.56556","0.01053"
"165.12000","32.60562","0.01045"
"165.60000","32.64562","0.01010"
"166.08000","32.68568","0.01068"
"166.56000","32.72568","0.01046"
"167.04000","32.76562","0.01070"
"167.52000","32.80574","0.01086"
"168.00000","32.84562","0.01137"
"168.48000","32.88562","0.01103"
"168.96000","32.92562","0.01122"
"169.44000","32.96561","0.01125"
"169.92000","33.00562","0.01137"
"170.40000","33.04573","0.01160"
"170.88000","33.08567","0.01148"
"171.36000","33.12567","0.01164"
"171.84000","33.16567","0.01152"
"172.32000","33.20567","0.01172"
"172.80000","33.24561","0.01170"
"173.28000","33.28561","0.01191"
"173.76000","33.32561","0.01214"
"174.24000","33.36561","0.01218"
"174.72000","33.40567","0.01260"
"175.20000","33.44567","0.01235"
"175.68000","33.48566","0.01297"
"176.16000","33.52572","0.01294"
"176.64000","33.56566","0.01250"
"177.12000","33.60566","0.01272"
"177.60000","33.64560","0.01311"
"178.08000","33.68560","0.01289"
"178.56000","33.72566","0.01313"
"179.04000","33.76566","0.01320"
"179.52000","33.80566","0.01338"
"180.00000","33.84566","0.01336"
"180.48000","33.88566","0.01387"
"180.96000","33.92566","0.01375"
"181.44000","33.96566","0.01371"
"181.92000","34.00566","0.01388"
"182.40000","34.04560","0.01421"
"182.88000","34.08566","0.01397"
"183.36000","34.12559","0.01418"
"183.84000","34.16565","0.01437"
"184.32000","34.20571","0.01484"
"184.80000","34.24565","0.01451"
"185.28000","34.28565","0.01427"
"185.76000","34.32565","0.01421"
"186.24000","34.36559","0.01457"
"186.72000","34.40565","0.01422"
"187.20000","34.44559","0.01491"
"187.68000","34.48565","0.01494"
"188.16000","34.52564","0.01468"
"188.64000","34.56570","0.01452"
"189.12000","34.60564","0.01507"
"189.60000","34.64564","0.01474"
"190.08000","34.68564","0.01495"
"190.56000","34.72558","0.01513"
"191.04000","34.76564","0.01478"
"191.52000","34.80564","0.01517"
"192.00000","34.84564","0.01526"
"192.48000","34.88570","0.01507"
"192.96000","34.92570","0.01562"
"193.44000","34.96570","0.01545"
"193.92000","35.00570","0.01545"
"194.40000","35.04570","0.01600"
"194.88000","35.08558","0.01565"
"195.36000","35.12563","0.01580"
"195.84000","35.16563","0.01584"
"196.32000","35.20563","0.01602"
"196.80000","35.24563","0.01630"
"197.28000","35.28569","0.01627"
"197.76000","35.32563","0.01664"
"198.24000","35.36569","0.01636"
"198.72000","35.40569","0.01682"
"199.20000","35.44563","0.01710"
"199.68000","35.48563","0.01665"
"200.16000","35.52562","0.01720"
"200.64000","35.56562","0.01706"
"201.12000","35.60563","0.01771"
"201.60000","35.64568","0.01783"
"202.08000","35.68568","0.01703"
"202.56000","35.72562","0.01771"
"203.04000","35.76568","0.01783"
"203.52000","35.80568","0.01720"
"204.00000","35.84568","0.01808"
"204.48000","35.88556","0.01799"
"204.96000","35.92562","0.01801"
"205.44000","35.96562","0.01808"
"205.92000","36.00568","0.01788"
"206.40000","36.04573","0.01774"
"206.88000","36.08567","0.01788"
"207.36000","36.12561","0.01781"
"207.84000","36.16567","0.01812"
"208.32000","36.20567","0.01826"
"208.80000","36.24561","0.01808"
"209.28000","36.28567","0.01786"
"209.76000","36.32567","0.01780"
"210.24000","36.36567","0.01826"
"210.72000","36.40567","0.01807"
"211.20000","36.44567","0.01806"
"211.68000","36.48566","0.01845"
"212.16000","36.52573","0.01787"
"212.64000","36.56567","0.01796"
"213.12000","36.60560","0.01786"
"213.60000","36.64560","0.01744"
"214.08000","36.68566","0.01766"
"214.56000","36.72566","0.01763"
"215.04000","36.76572","0.01814"
"215.52000","36.80560","0.01827"
"216.00000","36.84566","0.01828"
"216.48000","36.88566","0.01869"
"216.96000","36.92566","0.01875"
"217.44000","36.96566","0.01834"
"217.92000","37.00566","0.01891"
"218.40000","37.04559","0.01880"
"218.88000","37.08565","0.01907"
"219.36000","37.12566","0.01951"
"219.84000","37.16565","0.01901"
"220.32000","37.20565","0.01910"
"220.80000","37.24565","0.01929"
"221.28000","37.28565","0.01938"
"221.76000","37.32565","0.01977"
"222.24000","37.36565","0.01965"
"222.72000","37.40559","0.01975"
"223.20000","37.44564","0.01959"
"223.68000","37.48565","0.01977"
"224.16000","37.52565","0.02005"
"224.64000","37.56570","0.02008"
"225.12000","37.60564","0.02014"
"225.60000","37.64564","0.01981"
"226.08000","37.68564","0.01951"
"226.56000","37.72558","0.01982"
"227.04000","37.76564","0.01972"
"227.52000","37.80564","0.01935"
"228.00000","37.84558","0.01971"
"228.48000","37.88570","0.02021"
"228.96000","37.92564","0.01985"
"229.44000","37.96569","0.02025"
"229.92000","38.00563","0.02001"
"230.40000","38.04564","0.02011"
"230.88000","38.08557","0.02012"
"231.36000","38.12563","0.02036"
"231.84000","38.16563","0.02017"
"232.32000","38.20563","0.01980"
"232.80000","38.24563","0.02005"
"233.28000","38.28563","0.01940"
"233.76000","38.32563","0.02007"
"234.24000","38.36575","0.01999"
"234.72000","38.40563","0.01950"
"235.20000","38.44563","0.01899"
"235.68000","38.48563","0.01931"
"236.16000","38.52563","0.01914"
"236.64000","38.56562","0.01945"
"237.12000","38.60568","0.01922"
"237.60000","38.64568","0.01928"
"238.08000","38.68568","0.01929"
"238.56000","38.72568","0.01970"
"239.04000","38.76562","0.01994"
"239.52000","38.80562","0.01984"
"240.00000","38.84568","0.02033"
"240.48000","38.88568","0.02032"
"240.96000","38.92562","0.01984"
"241.44000","38.96568","0.01986"
"241.92000","39.00568","0.02020"
"242.40000","39.04567","0.01993"
"242.88000","39.08567","0.02026"
"243.36000","39.12561","0.02000"
"243.84000","39.16567","0.01978"
"244.32000","39.20561","0.01978"
"244.80000","39.24561","0.02005"
"245.28000","39.28567","0.02004"
"245.76000","39.32567","0.02031"
"246.24000","39.36567","0.02034"
"246.72000","39.40567","0.02033"
"247.20000","39.44566","0.02047"
"247.68000","39.48566","0.02014"
"248.16000","39.52560","0.02085"
"248.64000","39.56566","0.02036"
"249.12000","39.60560","0.02112"
"249.60000","39.64560","0.02095"
"250.08000","39.68566","0.02116"
"250.56000","39.72566","0.02138"
"251.04000","39.76566","0.02149"
"251.52000","39.80566","0.02138"
"252.00000","39.84566","0.02145"
"252.48000","39.88566","0.02032"
"252.96000","39.92560","0.02057"
"253.44000","39.96559","0.02095"
"253.92000","40.00565","0.02100"
"254.40000","40.04560","0.02109"
"254.88000","40.08566","0.02142"
"255.36000","40.12565","0.02105"
"255.84000","40.16565","0.02157"
"256.32000","40.20565","0.02166"
"256.80000","40.24565","0.02164"
"257.28000","40.28565","0.02199"
"257.76000","40.32565","0.02189"
"258.24000","40.36559","0.02247"
"258.72000","40.40565","0.02196"
"259.20000","40.44571","0.02233"
"259.68000","40.48564","0.02156"
"260.16000","40.52565","0.02171"
"260.64000","40.56570","0.02169"
"261.12000","40.60570","0.02101"
"261.60000","40.64564","0.02101"
"262.08000","40.68564","0.02082"
"262.56000","40.72558","0.02111"
"263.04000","40.76564","0.02086"
"263.52000","40.80570","0.02082"
"264.00000","40.84570","0.02048"
"264.48000","40.88570","0.02030"
"264.96000","40.92570","0.02013"
"265.44000","40.96569","0.02041"
"265.92000","41.00563","0.02039"
"266.40000","41.04564","0.02051"
"266.88000","41.08564","0.02045"
"267.36000","41.12563","0.02018"
"267.84000","41.16563","0.02056"
"268.32000","41.20569","0.02062"
"268.80000","41.24569","0.02126"
"269.28000","41.28569","0.02135"
"269.76000","41.32563","0.02105"
"270.24000","41.36568","0.02126"
"270.72000","41.40563","0.02161"
"271.20000","41.44557","0.02146"
"271.68000","41.48562","0.02123"
"272.16000","41.52568","0.02140"
"272.64000","41.56568","0.02104"
"273.12000","41.60569","0.02127"
"273.60000","41.64562","0.02119"
"274.08000","41.68568","0.02135"
"274.56000","41.72562","0.02160"
"275.04000","41.76556","0.02186"
"275.52000","41.80556","0.02155"
"276.00000","41.84562","0.02144"
"276.48000","41.88562","0.02158"
"276.96000","41.92567","0.02191"
"277.44000","41.96568","0.02097"
"277.92000","42.00567","0.02103"
"278.40000","42.04567","0.02206"
"278.88000","42.08573","0.02128"
"279.36000","42.12561","0.02184"
"279.84000","42.16561","0.02165"
"280.32000","42.20555","0.02077"
"280.80000","42.24567","0.02160"
"281.28000","42.28567","0.02088"
"281.76000","42.32567","0.02049"
"282.24000","42.36566","0.02083"
"282.72000","42.40567","0.02116"
"283.20000","42.44566","0.02060"
"283.68000","42.48560","0.02116"
"284.16000","42.52567","0.02090"
"284.64000","42.56560","0.02085"
"285.12000","42.60566","0.02054"
"285.60000","42.64572","0.02111"
"286.08000","42.68566","0.02096"
"286.56000","42.72565","0.02075"
"287.04000","42.76572","0.02064"
"287.52000","42.80566","0.02127"
"288.00000","42.84566","0.02059"
"288.48000","42.88560","0.02076"
"288.96000","42.92559","0.02089"
"289.44000","42.96560","0.02079"
"289.92000","43.00565","0.02090"
"290.40000","43.04565","0.02104"
"290.88000","43.08565","0.02112"
"291.36000","43.12571","0.02043"
"291.84000","43.16565","0.02069"
"292.32000","43.20565","0.02078"
"292.80000","43.24571","0.02027"
"293.28000","43.28559","0.02096"
"293.76000","43.32565","0.02089"
"294.24000","43.36565","0.02125"
"294.72000","43.40559","0.02042"
"295.20000","43.44564","0.02110"
"295.68000","43.48565","0.01985"
"296.16000","43.52570","0.01989"
"296.64000","43.56570","0.01987"
"297.12000","43.60564","0.02001"
"297.60000","43.64558","0.01986"
"298.08000","43.68564","0.01991"
"298.56000","43.72564","0.01983"
"299.04000","43.76564","0.02049"
"299.52000","43.80569","0.02077"
"300.00000","43.84570","0.01980"
"300.48000","43.88564","0.01935"
"300.96000","43.92564","0.01888"
"301.44000","43.96564","0.01874"
"301.92000","44.00563","0.01886"
"302.40000","44.04569","0.01890"
"302.88000","44.08563","0.01860"
"303.36000","44.12563","0.01856"
"303.84000","44.16569","0.01861"
"304.32000","44.20569","0.01826"
"304.80000","44.24563","0.01812"
"305.28000","44.28569","0.01817"
"305.76000","44.32563","0.01884"
"306.24000","44.36563","0.01925"
"306.72000","44.40557","0.01828"
"307.20000","44.44562","0.01882"
"307.68000","44.48563","0.01888"
"308.16000","44.52568","0.01893"
"308.64000","44.56569","0.01850"
"309.12000","44.60568","0.01914"
"309.60000","44.64562","0.01864"
"310.08000","44.68562","0.01850"
"310.56000","44.72562","0.01892"
"311.04000","44.76562","0.01889"
"311.52000","44.80561","0.01901"
"312.00000","44.84568","0.01941"
"312.48000","44.88562","0.01934"
"312.96000","44.92562","0.01936"
"313.44000","44.96567","0.01926"
"313.92000","45.00568","0.01887"
"314.40000","45.04567","0.01890"
"314.88000","45.08567","0.01896"
"315.36000","45.12556","0.01928"
"315.84000","45.16561","0.01878"
"316.32000","45.20561","0.01785"
"316.80000","45.24567","0.01834"
"317.28000","45.28567","0.01798"
"317.76000","45.32567","0.01783"
"318.24000","45.36567","0.01767"
"318.72000","45.40567","0.01805"
"319.20000","45.44567","0.01741"
"319.68000","45.48566","0.01754"
"320.16000","45.52560","0.01795"
"320.64000","45.56561","0.01748"
"321.12000","45.60560","0.01689"
"321.60000","45.64566","0.01741"
"322.08000","45.68566","0.01705"
"322.56000","45.72566","0.01748"
"323.04000","45.76566","0.01781"
"323.52000","45.80572","0.01768"
"324.00000","45.84560","0.01778"
"324.48000","45.88560","0.01792"
"324.96000","45.92560","0.01817"
"325.44000","45.96560","0.01834"
"325.92000","46.00565","0.01808"
"326.40000","46.04571","0.01862"
"326.88000","46.08566","0.01822"
"327.36000","46.12571","0.01831"
"327.84000","46.16565","0.01874"
"328.32000","46.20559","0.01910"
"328.80000","46.24559","0.01895"
"329.28000","46.28559","0.01899"
"329.76000","46.32565","0.01938"
"330.24000","46.36565","0.01939"
"330.72000","46.40565","0.01938"
"331.20000","46.44564","0.01908"
"331.68000","46.48570","0.01937"
"332.16000","46.52564","0.01959"
"332.64000","46.56564","0.01938"
"333.12000","46.60564","0.01890"
"333.60000","46.64558","0.01897"
"334.08000","46.68564","0.01830"
"334.56000","46.72570","0.01773"
"335.04000","46.76570","0.01813"
"335.52000","46.80563","0.01806"
"336.00000","46.84570","0.01926"
"336.48000","46.88564","0.01909"
"336.96000","46.92564","0.01856"
"337.44000","46.96563","0.01903"
"337.92000","47.00563","0.01876"
"338.40000","47.04563","0.01775"
"338.88000","47.08569","0.01732"
"339.36000","47.12563","0.01756"
"339.84000","47.16569","0.01740"
"340.32000","47.20569","0.01762"
"340.80000","47.24569","0.01733"
"341.28000","47.28569","0.01701"
"341.76000","47.32563","0.01721"
"342.24000","47.36557","0.01717"
"342.72000","47.40562","0.01699"
"343.20000","47.44563","0.01708"
"343.68000","47.48562","0.01708"
"344.16000","47.52568","0.01742"
"344.64000","47.56562","0.01742"
"345.12000","47.60568","0.01744"
"345.60000","47.64568","0.01714"
"346.08000","47.68562","0.01734"
"346.56000","47.72556","0.01703"
"347.04000","47.76562","0.01750"
"347.52000","47.80561","0.01750"
"348.00000","47.84562","0.01714"
"348.48000","47.88568","0.01739"
"348.96000","47.92567","0.01701"
"349.44000","47.96568","0.01694"
"349.92000","48.00567","0.01708"
"350.40000","48.04561","0.01732"
"350.88000","48.08561","0.01737"
"351.36000","48.12561","0.01734"
"351.84000","48.16561","0.01740"
"352.32000","48.20567","0.01809"
"352.80000","48.24567","0.01772"
"353.28000","48.28567","0.01730"
"353.76000","48.32573","0.01783"
"354.24000","48.36567","0.01728"
"354.72000","48.40560","0.01776"
"355.20000","48.44567","0.01706"
"355.68000","48.48560","0.01746"
"356.16000","48.52560","0.01759"
"356.64000","48.56566","0.01715"
"357.12000","48.60560","0.01721"
"357.60000","48.64566","0.01721"
"358.08000","48.68566","0.01741"
"358.56000","48.72572","0.01749"
"359.04000","48.76559","0.01735"
"359.52000","48.80566","0.01724"
"360.00000","48.84560","0.01694"
"360.48000","48.88560","0.01748"
"360.96000","48.92565","0.01757"
"361.44000","48.96566","0.01719"
"361.92000","49.00565","0.01737"
"362.40000","49.04565","0.01680"
"362.88000","49.08566","0.01653"
"363.36000","49.12565","0.01627"
"363.84000","49.16559","0.01627"
"364.32000","49.20559","0.01727"
"364.80000","49.24565","0.01681"
"365.28000","49.28565","0.01714"
"365.76000","49.32565","0.01752"
"366.24000","49.36570","0.01734"
"366.72000","49.40565","0.01773"
"367.20000","49.44565","0.01748"
"367.68000","49.48571","0.01765"
"368.16000","49.52565","0.01814"
"368.64000","49.56558","0.01794"
"369.12000","49.60564","0.01797"
"369.60000","49.64564","0.01821"
"370.08000","49.68564","0.01782"
"370.56000","49.72570","0.01830"
"371.04000","49.76564","0.01776"
"371.52000","49.80564","0.01830"
"372.00000","49.84570","0.01859"
"372.48000","49.88564","0.01838"
"372.96000","49.92563","0.01888"
"373.44000","49.96557","0.01940"
"373.92000","50.00563","0.01911"
"374.40000","50.04563","0.01897"
"374.88000","50.08569","0.01903"
"375.36000","50.12569","0.01912"
"375.84000","50.16569","0.01869"
"376.32000","50.20563","0.01818"
"376.80000","50.24563","0.01857"
"377.28000","50.28563","0.01892"
"377.76000","50.32563","0.01882"
"378.24000","50.36557","0.01855"
"378.72000","50.40563","0.01892"
"379.20000","50.44568","0.01863"
"379.68000","50.48569","0.01950"
"380.16000","50.52568","0.01922"
"380.64000","50.56568","0.01997"
"381.12000","50.60563","0.01964"
"381.60000","50.64562","0.01981"
"382.08000","50.68562","0.01992"
"382.56000","50.72556","0.01934"
"383.04000","50.76562","0.01922"
"383.52000","50.80568","0.01912"
"384.00000","50.84568","0.01906"
"384.48000","50.88573","0.01907"
"384.96000","50.92567","0.01929"
"385.44000","50.96562","0.02002"
"385.92000","51.00567","0.01911"
"386.40000","51.04561","0.01897"
"386.88000","51.08561","0.01861"
"387.36000","51.12561","0.01843"
"387.84000","51.16567","0.01884"
"388.32000","51.20567","0.01885"
"388.80000","51.24567","0.01863"
"389.28000","51.28566","0.01940"
"389.76000","51.32567","0.01957"
"390.24000","51.36567","0.01894"
"390.72000","51.40561","0.01949"
"391.20000","51.44566","0.01938"
"391.68000","51.48560","0.01910"
"392.16000","51.52567","0.02018"
"392.64000","51.56566","0.02024"
"393.12000","51.60566","0.02034"
"393.60000","51.64566","0.02031"
"394.08000","51.68566","0.02074"
"394.56000","51.72560","0.02084"
"395.04000","51.76560","0.02055"
"395.52000","51.80566","0.02098"
"396.00000","51.84565","0.02179"
"396.48000","51.88560","0.02162"
"396.96000","51.92572","0.02120"
"397.44000","51.96566","0.02253"
"397.92000","52.00565","0.02215"
"398.40000","52.04565","0.02179"
"398.88000","52.08565","0.02165"
"399.36000","52.12559","0.02222"
"399.84000","52.16565","0.02318"
"400.32000","52.20559","0.02214"
"400.80000","52.24559","0.02227"
"401.28000","52.28571","0.02220"
"401.76000","52.32571","0.02178"
"402.24000","52.36565","0.02208"
"402.72000","52.40565","0.02164"
"403.20000","52.44564","0.02172"
"403.68000","52.48565","0.02194"
"404.16000","52.52564","0.02110"
"404.64000","52.56558","0.02167"
"405.12000","52.60564","0.02109"
"405.60000","52.64564","0.02171"
"406.08000","52.68570","0.02085"
"406.56000","52.72564","0.02167"
"407.04000","52.76564","0.02236"
"407.52000","52.80569","0.02194"
"408.00000","52.84563","0.02225"
"408.48000","52.88564","0.02233"
"408.96000","52.92558","0.02268"
"409.44000","52.96564","0.02285"
"409.92000","53.00570","0.02283"
"410.40000","53.04564","0.02322"
"410.88000","53.08569","0.02388"
"411.36000","53.12569","0.02363"
"411.84000","53.16569","0.02353"
"412.32000","53.20569","0.02402"
"412.80000","53.24563","0.02354"
"413.28000","53.28556","0.02427"
"413.76000","53.32563","0.02386"
"414.24000","53.36563","0.02446"
"414.72000","53.40563","0.02463"
"415.20000","53.44557","0.02386"
"415.68000","53.48569","0.02445"
"416.16000","53.52568","0.02474"
"416.64000","53.56569","0.02470"
"417.12000","53.60563","0.02393"
"417.60000","53.64562","0.02367"
"418.08000","53.68562","0.02341"
"418.56000","53.72562","0.02328"
"419.04000","53.76568","0.02345"
"419.52000","53.80568","0.02275"
"420.00000","53.84562","0.02232"
"420.48000","53.88573","0.02058"
"420.96000","53.92568","0.02078"
"421.44000","53.96567","0.02043"
"421.92000","54.00568","0.02010"
"422.40000","54.04561","0.01972"
"422.88000","54.08567","0.02020"
"423.36000","54.12568","0.02023"
"423.84000","54.16561","0.02026"
"424.32000","54.20567","0.01967"
"424.80000","54.24567","0.01981"
"425.28000","54.28567","0.02018"
"425.76000","54.32566","0.02063"
"426.24000","54.36567","0.02039"
"426.72000","54.40561","0.02049"
"427.20000","54.44560","0.02080"
"427.68000","54.48567","0.02101"
"428.16000","54.52566","0.02089"
"428.64000","54.56572","0.02114"
"429.12000","54.60572","0.02075"
"429.60000","54.64560","0.02125"
"430.08000","54.68566","0.02137"
"430.56000","54.72560","0.02097"
"431.04000","54.76560","0.02129"
"431.52000","54.80566","0.02188"
"432.00000","54.84566","0.02183"
"432.48000","54.88560","0.02284"
"432.96000","54.92566","0.02348"
"433.44000","54.96565","0.02353"
"433.92000","55.00565","0.02368"
"434.40000","55.04571","0.02354"
"434.88000","55.08565","0.02409"
"435.36000","55.12560","0.02462"
"435.84000","55.16559","0.02491"
"436.32000","55.20565","0.02494"
"436.80000","55.24565","0.02546"
"437.28000","55.28571","0.02532"
"437.76000","55.32565","0.02609"
"438.24000","55.36564","0.02626"
"438.72000","55.40565","0.02661"
"439.20000","55.44565","0.02670"
"439.68000","55.48565","0.02727"
"440.16000","55.52564","0.02748"
"440.64000","55.56558","0.02807"
"441.12000","55.60564","0.02809"
"441.60000","55.64565","0.02798"
"442.08000","55.68564","0.02814"
"442.56000","55.72564","0.02920"
"443.04000","55.76575","0.02894"
"443.52000","55.80570","0.02939"
"444.00000","55.84564","0.02925"
"444.48000","55.88557","0.02936"
"444.96000","55.92564","0.02966"
"445.44000","55.96563","0.02991"
"445.92000","56.00570","0.02971"
"446.40000","56.04569","0.03018"
"446.88000","56.08569","0.03025"
"447.36000","56.12569","0.03070"
"447.84000","56.16563","0.03103"
"448.32000","56.20569","0.03093"
"448.80000","56.24563","0.03106"
"449.28000","56.28563","0.03144"
"449.76000","56.32568","0.03209"
"450.24000","56.36557","0.03177"
"450.72000","56.40568","0.03209"
"451.20000","56.44563","0.03165"
"451.68000","56.48568","0.03118"
"452.16000","56.52562","0.03082"
"452.64000","56.56568","0.03134"
"453.12000","56.60556","0.03108"
"453.60000","56.64563","0.03162"
"454.08000","56.68562","0.03140"
"454.56000","56.72562","0.03145"
"455.04000","56.76567","0.03214"
"455.52000","56.80568","0.03200"
"456.00000","56.84562","0.03198"
"456.48000","56.88567","0.03225"
"456.96000","56.92568","0.03200"
"457.44000","56.96561","0.03236"
"457.92000","57.00562","0.03227"
"458.40000","57.04561","0.03255"
"458.88000","57.08567","0.03264"
"459.36000","57.12561","0.03264"
"459.84000","57.16567","0.03266"
"460.32000","57.20561","0.03297"
"460.80000","57.24573","0.03304"
"461.28000","57.28567","0.03279"
"461.76000","57.32560","0.03346"
"462.24000","57.36567","0.03297"
"462.72000","57.40561","0.03366"
"463.20000","57.44567","0.03411"
"463.68000","57.48566","0.03375"
"464.16000","57.52572","0.03372"
"464.64000","57.56561","0.03336"
"465.12000","57.60572","0.03291"
"465.60000","57.64560","0.03302"
"466.08000","57.68560","0.03341"
"466.56000","57.72560","0.03293"
"467.04000","57.76566","0.03296"
"467.52000","57.80560","0.03285"
"468.00000","57.84571","0.03331"
"468.48000","57.88565","0.03235"
"468.96000","57.92566","0.03265"
"469.44000","57.96572","0.03247"
"469.92000","58.00566","0.03248"
"470.40000","58.04565","0.03329"
"470.88000","58.08559","0.03113"
"471.36000","58.12559","0.03147"
"471.84000","58.16565","0.03116"
"472.32000","58.20565","0.03089"
"472.80000","58.24565","0.03183"
"473.28000","58.28565","0.03181"
"473.76000","58.32565","0.03190"
"474.24000","58.36565","0.03241"
"474.72000","58.40564","0.03262"
"475.20000","58.44565","0.03310"
"475.68000","58.48559","0.03337"
"476.16000","58.52564","0.03398"
"476.64000","58.56564","0.03394"
"477.12000","58.60564","0.03425"
"477.60000","58.64570","0.03464"
"478.08000","58.68564","0.03468"
"478.56000","58.72570","0.03481"
"479.04000","58.76570","0.03431"
"479.52000","58.80558","0.03401"
"480.00000","58.84558","0.03473"
"480.48000","58.88564","0.03495"
"480.96000","58.92564","0.03534"
"481.44000","58.96564","0.03537"
"481.92000","59.00569","0.03524"
"482.40000","59.04563","0.03583"
"482.88000","59.08569","0.03600"
"483.36000","59.12569","0.03623"
"483.84000","59.16563","0.03700"
"484.32000","59.20557","0.03692"
"484.80000","59.24563","0.03729"
"485.28000","59.28563","0.03715"
"485.76000","59.32569","0.03662"
"486.24000","59.36568","0.03772"
"486.72000","59.40562","0.03762"
"487.20000","59.44569","0.03756"
"487.68000","59.48568","0.03777"
"488.16000","59.52562","0.03813"
"488.64000","59.56562","0.03760"
"489.12000","59.60562","0.03733"
"489.60000","59.64562","0.03740"
"490.08000","59.68568","0.03758"
"490.56000","59.72568","0.03732"
"491.04000","59.76568","0.03826"
"491.52000","59.80568","0.03836"
"492.00000","59.84568","0.03870"
"492.48000","59.88568","0.03830"
"492.96000","59.92567","0.03918"
"493.44000","59.96562","0.03927"
"493.92000","60.00562","0.03912"
"494.40000","60.04567","0.03940"
"494.88000","60.08567","0.03919"
"495.36000","60.12567","0.03994"
"495.84000","60.16567","0.03972"
"496.32000","60.20567","0.03963"
"496.80000","60.24561","0.03901"
"497.28000","60.28566","0.03915"
"497.76000","60.32561","0.03902"
"498.24000","60.36567","0.03928"
"498.72000","60.40566","0.03915"
"499.20000","60.44567","0.03931"
"499.68000","60.48566","0.03909"
"500.16000","60.52567","0.03986"
"500.64000","60.56572","0.04004"
"501.12000","60.60566","0.03946"
"501.60000","60.64560","0.03946"
"502.08000","60.68560","0.03973"
"502.56000","60.72561","0.04006"
"503.04000","60.76560","0.04076"
"503.52000","60.80566","0.04012"
"504.00000","60.84572","0.04003"
"504.48000","60.88572","0.04113"
"504.96000","60.92566","0.04112"
"505.44000","60.96572","0.04148"
"505.92000","61.00565","0.04172"
"506.40000","61.04559","0.04194"
"506.88000","61.08565","0.04190"
"507.36000","61.12559","0.04224"
"507.84000","61.16565","0.04263"
"508.32000","61.20565","0.04265"
"508.80000","61.24565","0.04280"
"509.28000","61.28564","0.04256"
"509.76000","61.32571","0.04294"
"510.24000","61.36565","0.04265"
"510.72000","61.40564","0.04107"
"511.20000","61.44564","0.03907"
"511.68000","61.48558","0.03844"
"512.16000","61.52565","0.03691"
"512.64000","61.56570","0.03481"
"513.12000","61.60570","0.03433"
"513.60000","61.64570","0.02922"
"514.08000","61.68570","0.01093"
"514.56000","61.72558","0.00673"
"515.04000","61.76564","0.00708"
"515.52000","61.80564","0.00771"
"516.00000","61.84563","0.00684"
"516.48000","61.88564","0.00777"
"516.96000","61.92564","0.00704"
"517.44000","61.96564","0.00747"
"517.92000","62.00569","0.00790"
"518.40000","62.04569","0.00745"
"518.88000","62.08563","0.00808"
"519.36000","62.12563","0.00753"
"519.84000","62.16563","0.00852"
"520.32000","62.20563","0.00786"
"520.80000","62.24563","0.00836"
"521.28000","62.28569","0.00794"
"521.76000","62.32563","0.00796"
"522.24000","62.36568","0.00818"
"522.72000","62.40562","0.00881"
"523.20000","62.44568","0.00826"
"523.68000","62.48563","0.00827"
"524.16000","62.52562","0.00873"
"524.64000","62.56562","0.00850"
"525.12000","62.60562","0.00856"
"525.60000","62.64561","0.00832"
"526.08000","62.68562","0.00842"
"526.56000","62.72568","0.00873"
"527.04000","62.76561","0.00806"
"527.52000","62.80568","0.00880"
"528.00000","62.84568","0.00864"
"528.48000","62.88561","0.00883"
"528.96000","62.92561","0.00830"
"529.44000","62.96561","0.00834"
"529.92000","63.00561","0.00876"
"530.40000","63.04567","0.00888"
"530.88000","63.08567","0.00895"
"531.36000","63.12567","0.00906"
"531.84000","63.16566","0.00856"
"532.32000","63.20567","0.00870"
"532.80000","63.24561","0.00858"
"533.28000","63.28560","0.00880"
"533.76000","63.32561","0.00860"
"534.24000","63.36560","0.00833"
"534.72000","63.40566","0.00841"
"535.20000","63.44566","0.00865"
"535.68000","63.48560","0.00814"
"536.16000","63.52572","0.00868"
"536.64000","63.56565","0.00806"
"537.12000","63.60566","0.00845"
"537.60000","63.64566","0.00795"
"538.08000","63.68554","0.00819"
"538.56000","63.72560","0.00831"
"539.04000","63.76565","0.00840"
"539.52000","63.80566","0.00841"
"540.00000","63.84566","0.00864"
"540.48000","63.88565","0.00837"
"540.96000","63.92571","0.00872"
"541.44000","63.96565","0.00808"
"541.92000","64.00565","0.00835"
"542.40000","64.04559","0.00877"
"542.88000","64.08565","0.00844"
"543.36000","64.12565","0.00852"
"543.84000","64.16564","0.00814"
"544.32000","64.20564","0.00846"
"544.80000","64.24565","0.00819"
"545.28000","64.28564","0.00869"
"545.76000","64.32571","0.00840"
"546.24000","64.36564","0.00870"
"546.72000","64.40559","0.00847"
"547.20000","64.44565","0.00860"
"547.68000","64.48564","0.00874"
"548.16000","64.52564","0.00867"
"548.64000","64.56570","0.00860"
"549.12000","64.60564","0.00887"
"549.60000","64.64564","0.00869"
"550.08000","64.68569","0.00856"
"550.56000","64.72564","0.00871"
"551.04000","64.76557","0.00879"
"551.52000","64.80563","0.00872"
"552.00000","64.84570","0.00864"
"552.48000","64.88563","0.00866"
"552.96000","64.92564","0.00865"
"553.44000","64.96563","0.00855"
"553.92000","65.00569","0.00836"
"554.40000","65.04569","0.00849"
"554.88000","65.08562","0.00847"
"555.36000","65.12563","0.00862"
"555.84000","65.16563","0.00885"
"556.32000","65.20563","0.00807"
"556.80000","65.24569","0.00862"
"557.28000","65.28568","0.00819"
"557.76000","65.32568","0.00871"
"558.24000","65.36568","0.00838"
"558.72000","65.40562","0.00821"
"559.20000","65.44563","0.00822"
"559.68000","65.48562","0.00834"
"560.16000","65.52556","0.00838"
"560.64000","65.56561","0.00860"
"561.12000","65.60562","0.00863"
"561.60000","65.64568","0.00846"
"562.08000","65.68568","0.00848"
"562.56000","65.72568","0.00854"
"563.04000","65.76567","0.00849"
"563.52000","65.80567","0.00872"
"564.00000","65.84567","0.00823"
"564.48000","65.88561","0.00813"
"564.96000","65.92561","0.00854"
"565.44000","65.96568","0.00807"
"565.92000","66.00561","0.00857"
"566.40000","66.04573","0.00863"
"566.88000","66.08566","0.00805"
"567.36000","66.12567","0.00816"
"567.84000","66.16567","0.00868"
"568.32000","66.20567","0.00829"
"568.80000","66.24561","0.00861"
"569.28000","66.28561","0.00852"
"569.76000","66.32567","0.00825"
"570.24000","66.36561","0.00827"
"570.72000","66.40566","0.00820"
"571.20000","66.44566","0.00826"
"571.68000","66.48560","0.00809"
"572.16000","66.52572","0.00851"
"572.64000","66.56567","0.00830"
"573.12000","66.60560","0.00823"
"573.60000","66.64566","0.00802"
"574.08000","66.68559","0.00789"
"574.56000","66.72565","0.00834"
"575.04000","66.76566","0.00809"
"575.52000","66.80566","0.00803"
"576.00000","66.84566","0.00826"
"576.48000","66.88565","0.00807"
"576.96000","66.92565","0.00814"
"577.44000","66.96559","0.00837"
"577.92000","67.00565","0.00831"
"578.40000","67.04559","0.00806"
"578.88000","67.08565","0.00830"
"579.36000","67.12565","0.00839"
"579.84000","67.16571","0.00858"
"580.32000","67.20564","0.00852"
"580.80000","67.24570","0.00808"
"581.28000","67.28564","0.00849"
"581.76000","67.32565","0.00843"
"582.24000","67.36559","0.00841"
"582.72000","67.40564","0.00830"
"583.20000","67.44564","0.00843"
"583.68000","67.48569","0.00847"
"584.16000","67.52570","0.00839"
"584.64000","67.56564","0.00824"
"585.12000","67.60564","0.00840"
"585.60000","67.64564","0.00860"
"586.08000","67.68569","0.00792"
"586.56000","67.72564","0.00849"
"587.04000","67.76564","0.00847"
"587.52000","67.80569","0.00836"
"588.00000","67.84563","0.00836"
"588.48000","67.88569","0.00795"
"588.96000","67.92569","0.00845"
"589.44000","67.96569","0.00820"
"589.92000","68.00569","0.00838"
"590.40000","68.04569","0.00833"
"590.88000","68.08556","0.00847"
"591.36000","68.12563","0.00857"
"591.84000","68.16563","0.00857"
"592.32000","68.20568","0.00819"
"592.80000","68.24563","0.00838"
"593.28000","68.28568","0.00880"
"593.76000","68.32562","0.00818"
"594.24000","68.36568","0.00871"
"594.72000","68.40562","0.00861"
"595.20000","68.44556","0.00886"
"595.68000","68.48562","0.00835"
"596.16000","68.52562","0.00875"
"596.64000","68.56562","0.00834"
"597.12000","68.60567","0.00816"
"597.60000","68.64568","0.00831"
"598.08000","68.68568","0.00858"
"598.56000","68.72568","0.00829"
"599.04000","68.76562","0.00836"
"599.52000","68.80555","0.00853"
"600.00000","68.84561","0.00841"
"600.48000","68.88561","0.00848"
"600.96000","68.92561","0.00841"
"601.44000","68.96568","0.00837"
"601.92000","69.00567","0.00841"
"602.40000","69.04561","0.00818"
"602.88000","69.08567","0.00891"
"603.36000","69.12566","0.00851"
"603.84000","69.16561","0.00836"
"604.32000","69.20560","0.00843"
"604.80000","69.24561","0.00839"
"605.28000","69.28560","0.00848"
"605.76000","69.32566","0.00857"
"606.24000","69.36566","0.00850"
"606.72000","69.40566","0.00839"
"607.20000","69.44572","0.00851"
"607.68000","69.48566","0.00850"
"608.16000","69.52566","0.00847"
"608.64000","69.56561","0.00840"
"609.12000","69.60566","0.00841"
"609.60000","69.64560","0.00874"
"610.08000","69.68566","0.00834"
"610.56000","69.72565","0.00837"
"611.04000","69.76566","0.00881"
"611.52000","69.80565","0.00840"
"612.00000","69.84566","0.00846"
"612.48000","69.88566","0.00886"
"612.96000","69.92565","0.00845"
"613.44000","69.96559","0.00838"
"613.92000","70.00565","0.00810"
"614.40000","70.04559","0.00835"
"614.88000","70.08566","0.00882"
"615.36000","70.12565","0.00831"
"615.84000","70.16565","0.00863"
"616.32000","70.20570","0.00833"
"616.80000","70.24564","0.00840"
"617.28000","70.28559","0.00813"
"617.76000","70.32558","0.00843"
"618.24000","70.36565","0.00863"
"618.72000","70.40564","0.00834"
"619.20000","70.44564","0.00867"
"619.68000","70.48570","0.00823"
"620.16000","70.52570","0.00840"
"620.64000","70.56570","0.00874"
"621.12000","70.60570","0.00822"
"621.60000","70.64564","0.00828"
"622.08000","70.68564","0.00858"
"622.56000","70.72563","0.00869"
"623.04000","70.76558","0.00833"
"623.52000","70.80563","0.00854"
"624.00000","70.84563","0.00870"
"624.48000","70.88570","0.00821"
"624.96000","70.92569","0.00862"
"625.44000","70.96569","0.00835"
"625.92000","71.00563","0.00865"
"626.40000","71.04563","0.00818"
"626.88000","71.08563","0.00898"
"627.36000","71.12563","0.00876"
"627.84000","71.16569","0.00860"
"628.32000","71.20574","0.00864"
"628.80000","71.24563","0.00880"
"629.28000","71.28563","0.00857"
"629.76000","71.32568","0.00889"
"630.24000","71.36568","0.00862"
"630.72000","71.40562","0.00896"
"631.20000","71.44563","0.00902"
"631.68000","71.48563","0.00893"
"632.16000","71.52562","0.00891"
"632.64000","71.56562","0.00901"
"633.12000","71.60567","0.00888"
"633.60000","71.64568","0.00870"
"634.08000","71.68568","0.00867"
"634.56000","71.72562","0.00896"
"635.04000","71.76568","0.00888"
"635.52000","71.80561","0.00899"
"636.00000","71.84567","0.00880"
"636.48000","71.88567","0.00897"
"636.96000","71.92561","0.00910"
"637.44000","71.96568","0.00872"
"637.92000","72.00567","0.00894"
"638.40000","72.04567","0.00878"
"638.88000","72.08573","0.00912"
"639.36000","72.12560","0.00881"
"639.84000","72.16561","0.00881"
"640.32000","72.20560","0.00880"
"640.80000","72.24567","0.00917"
"641.28000","72.28561","0.00915"
"641.76000","72.32566","0.00948"
"642.24000","72.36566","0.00934"
"642.72000","72.40566","0.00917"
"643.20000","72.44566","0.00937"
"643.68000","72.48560","0.00906"
"644.16000","72.52560","0.00912"
"644.64000","72.56566","0.00884"
"645.12000","72.60561","0.00905"
"645.60000","72.64566","0.00919"
"646.08000","72.68571","0.00896"
"646.56000","72.72565","0.00893"
"647.04000","72.76566","0.00929"
"647.52000","72.80572","0.00898"
"648.00000","72.84565","0.00909"
"648.48000","72.88566","0.00932"
"648.96000","72.92559","0.00903"
"649.44000","72.96559","0.00922"
"649.92000","73.00565","0.00877"
"650.40000","73.04565","0.00930"
"650.88000","73.08565","0.00913"
"651.36000","73.12570","0.00894"
"651.84000","73.16571","0.00923"
"652.32000","73.20565","0.00881"
"652.80000","73.24558","0.00901"
"653.28000","73.28564","0.00915"
"653.76000","73.32558","0.00765"
"654.24000","73.36565","0.00680"
"654.72000","73.40565","0.00672"
"655.20000","73.44564","0.00680"
"655.68000","73.48570","0.00676"
"656.16000","73.52570","0.00656"
"656.64000","73.56564","0.00703"
"657.12000","73.60564","0.00672"
"657.60000","73.64558","0.00654"
"658.08000","73.68558","0.00671"
"658.56000","73.72569","0.00686"
"659.04000","73.76569","0.00716"
"659.52000","73.80569","0.00685"
"660.00000","73.84570","0.00656"
"660.48000","73.88570","0.00678"
"660.96000","73.92563","0.00702"
"661.44000","73.96569","0.00682"
"661.92000","74.00563","0.00685"
"662.40000","74.04557","0.00668"
"662.88000","74.08563","0.00671"
"663.36000","74.12563","0.00689"
"663.84000","74.16563","0.00657"
"664.32000","74.20569","0.00682"
"664.80000","74.24562","0.00662"
"665.28000","74.28568","0.00661"
"665.76000","74.32562","0.00665"
"666.24000","74.36562","0.00685"
"666.72000","74.40562","0.00677"
"667.20000","74.44556","0.00666"
"667.68000","74.48562","0.00652"
"668.16000","74.52567","0.00687"
"668.64000","74.56568","0.00646"
"669.12000","74.60562","0.00652"
"669.60000","74.64568","0.00655"
"670.08000","74.68568","0.00645"
"670.56000","74.72562","0.00670"
"671.04000","74.76568","0.00656"
"671.52000","74.80562","0.00665"
"672.00000","74.84567","0.00679"
"672.48000","74.88567","0.00649"
"672.96000","74.92567","0.00682"
"673.44000","74.96567","0.00669"
"673.92000","75.00568","0.00668"
"674.40000","75.04567","0.00673"
"674.88000","75.08567","0.00682"
"675.36000","75.12566","0.00670"
"675.84000","75.16560","0.00645"
"676.32000","75.20561","0.00681"
"676.80000","75.24567","0.00652"
"677.28000","75.28567","0.00685"
"677.76000","75.32567","0.00659"
"678.24000","75.36566","0.00667"
"678.72000","75.40566","0.00685"
"679.20000","75.44566","0.00707"
"679.68000","75.48566","0.00656"
"680.16000","75.52554","0.00674"
"680.64000","75.56566","0.00674"
"681.12000","75.60566","0.00657"
"681.60000","75.64565","0.00639"
"682.08000","75.68566","0.00686"
"682.56000","75.72566","0.00663"
"683.04000","75.76566","0.00627"
"683.52000","75.80572","0.00680"
"684.00000","75.84565","0.00656"
"684.48000","75.88554","0.00676"
"684.96000","75.92566","0.00675"
"685.44000","75.96565","0.00662"
"685.92000","76.00565","0.00645"
"686.40000","76.04565","0.00684"
"686.88000","76.08565","0.00622"
"687.36000","76.12565","0.00673"
"687.84000","76.16565","0.00666"
"688.32000","76.20565","0.00662"
"688.80000","76.24558","0.00680"
"689.28000","76.28558","0.00649"
"689.76000","76.32565","0.00677"
"690.24000","76.36564","0.00637"
"690.72000","76.40565","0.00659"
"691.20000","76.44564","0.00662"
"691.68000","76.48570","0.00660"
"692.16000","76.52570","0.00658"
"692.64000","76.56564","0.00649"
"693.12000","76.60564","0.00655"
"693.60000","76.64564","0.00661"
"694.08000","76.68570","0.00655"
"694.56000","76.72564","0.00648"
"695.04000","76.76569","0.00677"
"695.52000","76.80563","0.00691"
"696.00000","76.84569","0.00649"
"696.48000","76.88564","0.00673"
"696.96000","76.92564","0.00636"
"697.44000","76.96563","0.00651"
"697.92000","77.00563","0.00666"
"698.40000","77.04562","0.00695"
"698.88000","77.08569","0.00694"
"699.36000","77.12563","0.00644"
"699.84000","77.16563","0.00680"
"700.32000","77.20569","0.00626"
"700.80000","77.24568","0.00637"
"701.28000","77.28568","0.00628"
"701.76000","77.32563","0.00659"
"702.24000","77.36562","0.00613"
"702.72000","77.40562","0.00661"
"703.20000","77.44568","0.00628"
"703.68000","77.48562","0.00624"
"704.16000","77.52568","0.00635"
"704.64000","77.56562","0.00661"
"705.12000","77.60568","0.00657"
"705.60000","77.64561","0.00623"
"706.08000","77.68562","0.00596"
"706.56000","77.72556","0.00640"
"707.04000","77.76562","0.00615"
"707.52000","77.80568","0.00610"
"708.00000","77.84561","0.00661"
"708.48000","77.88561","0.00634"
"708.96000","77.92567","0.00635"
"709.44000","77.96567","0.00601"
"709.92000","78.00567","0.00637"
"710.40000","78.04561","0.00636"
"710.88000","78.08555","0.00649"
"711.36000","78.12567","0.00621"
"711.84000","78.16566","0.00601"
"712.32000","78.20560","0.00667"
"712.80000","78.24573","0.00631"
"713.28000","78.28567","0.00635"
"713.74000","78.32399","0.00659"