File: Force_trajectories/161221_1/Specimen_RawData_10.csv
End date,"12/21/2016"
Specimen label,"24BG_96"
Maximum Load,"0.59025",N

Time,Extension,Load
(s),(mm),(N)
"0.00000","0.00000","-0.00033"
"0.45600","0.03833","-0.00050"
"0.91200","0.07629","0.00010"
"1.36800","0.11420","0.00024"
"1.82400","0.15216","0.00025"
"2.28000","0.19019","0.00028"
"2.73600","0.22816","0.00058"
"3.19200","0.26618","0.00081"
"3.64800","0.30421","0.00074"
"4.10400","0.34230","0.00123"
"4.56000","0.38020","0.00097"
"5.01600","0.41823","0.00106"
"5.47200","0.45619","0.00088"
"5.92800","0.49422","0.00101"
"6.38400","0.53225","0.00116"
"6.84000","0.57027","0.00113"
"7.29600","0.60824","0.00126"
"7.75200","0.64621","0.00149"
"8.20800","0.68411","0.00132"
"8.66400","0.72214","0.00166"
"9.12000","0.76022","0.00123"
"9.57600","0.79825","0.00123"
"10.03200","0.83622","0.00127"
"10.48800","0.87424","0.00141"
"10.94400","0.91215","0.00158"
"11.40000","0.95018","0.00168"
"11.85600","0.98826","0.00166"
"12.31200","1.02623","0.00161"
"12.76800","1.06425","0.00175"
"13.22400","1.10228","0.00190"
"13.68000","1.14019","0.00195"
"14.13600","1.17815","0.00178"
"14.59200","1.21618","0.00195"
"15.04800","1.25420","0.00185"
"15.50400","1.29223","0.00174"
"15.96000","1.33020","0.00215"
"16.41600","1.36822","0.00233"
"16.87200","1.40625","0.00209"
"17.32800","1.44416","0.00219"
"17.78400","1.48224","0.00195"
"18.24000","1.52021","0.00222"
"18.69600","1.55823","0.00243"
"19.15200","1.59626","0.00204"
"19.60800","1.63429","0.00240"
"20.06400","1.67219","0.00192"
"20.52000","1.71016","0.00186"
"20.97600","1.74819","0.00205"
"21.43200","1.78621","0.00220"
"21.88800","1.82424","0.00179"
"22.34400","1.86226","0.00191"
"22.80000","1.90017","0.00155"
"23.25600","1.93820","0.00174"
"23.71200","1.97616","0.00178"
"24.16800","2.01425","0.00154"
"24.62400","2.05222","0.00183"
"25.08000","2.09024","0.00203"
"25.53600","2.12821","0.00235"
"25.99200","2.16617","0.00187"
"26.44800","2.20420","0.00191"
"26.90400","2.24223","0.00206"
"27.36000","2.28031","0.00243"
"27.81600","2.31822","0.00229"
"28.27200","2.35625","0.00226"
"28.72800","2.39415","0.00240"
"29.18400","2.43212","0.00240"
"29.64000","2.47020","0.00217"
"30.09600","2.50823","0.00191"
"30.55200","2.54626","0.00222"
"31.00800","2.58422","0.00226"
"31.46400","2.62219","0.00232"
"31.92000","2.66022","0.00233"
"32.37600","2.69824","0.00232"
"32.83200","2.73621","0.00248"
"33.28800","2.77423","0.00249"
"33.74400","2.81226","0.00267"
"34.20000","2.85023","0.00232"
"34.65600","2.88825","0.00254"
"35.11200","2.92622","0.00260"
"35.56800","2.96419","0.00267"
"36.02400","3.00221","0.00237"
"36.48000","3.04024","0.00261"
"36.93600","3.07826","0.00305"
"37.39200","3.11623","0.00244"
"37.84800","3.15420","0.00274"
"38.30400","3.19216","0.00235"
"38.76000","3.23025","0.00306"
"39.21600","3.26822","0.00314"
"39.67200","3.30618","0.00270"
"40.12800","3.34427","0.00268"
"40.58400","3.38223","0.00302"
"41.04000","3.42020","0.00271"
"41.49600","3.45817","0.00276"
"41.95200","3.49619","0.00292"
"42.40800","3.53428","0.00298"
"42.86400","3.57225","0.00251"
"43.32000","3.61027","0.00320"
"43.77600","3.64818","0.00302"
"44.23200","3.68614","0.00300"
"44.68800","3.72417","0.00316"
"45.14400","3.76226","0.00309"
"45.60000","3.80022","0.00322"
"46.05600","3.83819","0.00321"
"46.51200","3.87622","0.00306"
"46.96800","3.91412","0.00325"
"47.42400","3.95221","0.00332"
"47.88000","3.99029","0.00337"
"48.33600","4.02826","0.00316"
"48.79200","4.06623","0.00320"
"49.24800","4.10419","0.00319"
"49.70400","4.14222","0.00340"
"50.16000","4.18018","0.00357"
"50.61600","4.21815","0.00329"
"51.07200","4.25624","0.00348"
"51.52800","4.29426","0.00331"
"51.98400","4.33223","0.00360"
"52.44000","4.37020","0.00388"
"52.89600","4.40822","0.00361"
"53.35200","4.44619","0.00400"
"53.80800","4.48421","0.00381"
"54.26400","4.52224","0.00395"
"54.72000","4.56021","0.00396"
"55.17600","4.59823","0.00398"
"55.63200","4.63626","0.00369"
"56.08800","4.67423","0.00396"
"56.54400","4.71219","0.00362"
"57.00000","4.75022","0.00324"
"57.45600","4.78824","0.00364"
"57.91200","4.82627","0.00334"
"58.36800","4.86424","0.00360"
"58.82400","4.90220","0.00396"
"59.28000","4.94017","0.00425"
"59.73600","4.97814","0.00373"
"60.19200","5.01622","0.00398"
"60.64800","5.05431","0.00418"
"61.10400","5.09221","0.00396"
"61.56000","5.13018","0.00418"
"62.01600","5.16815","0.00386"
"62.47200","5.20623","0.00404"
"62.92800","5.24426","0.00426"
"63.38400","5.28229","0.00459"
"63.84000","5.32025","0.00479"
"64.29600","5.35822","0.00484"
"64.75200","5.39618","0.00470"
"65.20800","5.43415","0.00502"
"65.66400","5.47224","0.00530"
"66.12000","5.51020","0.00485"
"66.57600","5.54829","0.00500"
"67.03200","5.58626","0.00530"
"67.48800","5.62422","0.00520"
"67.94400","5.66219","0.00483"
"68.40000","5.70021","0.00498"
"68.85600","5.73824","0.00500"
"69.31200","5.77621","0.00551"
"69.76800","5.81423","0.00564"
"70.22400","5.85226","0.00588"
"70.68000","5.89023","0.00565"
"71.13600","5.92825","0.00604"
"71.59200","5.96622","0.00617"
"72.04800","6.00424","0.00633"
"72.50400","6.04221","0.00686"
"72.96000","6.08024","0.00688"
"73.41600","6.11826","0.00766"
"73.87200","6.15617","0.00738"
"74.32800","6.19426","0.00777"
"74.78400","6.23216","0.00812"
"75.24000","6.27025","0.00802"
"75.69600","6.30827","0.00893"
"76.15200","6.34630","0.00901"
"76.60800","6.38421","0.00961"
"77.06400","6.42217","0.01012"
"77.52000","6.46014","0.01031"
"77.97600","6.49823","0.01078"
"78.43200","6.53625","0.01112"
"78.88800","6.57428","0.01177"
"79.34400","6.61218","0.01279"
"79.80000","6.65021","0.01288"
"80.25600","6.68818","0.01384"
"80.71200","6.72620","0.01448"
"81.16800","6.76423","0.01533"
"81.62400","6.80220","0.01666"
"82.08000","6.84028","0.01733"
"82.53600","6.87819","0.01779"
"82.99200","6.91615","0.01881"
"83.44800","6.95424","0.02028"
"83.90400","6.99227","0.02048"
"84.36000","7.03023","0.02214"
"84.81600","7.06820","0.02256"
"85.27200","7.10623","0.02430"
"85.72800","7.14419","0.02456"
"86.18400","7.18222","0.02505"
"86.64000","7.22024","0.02636"
"87.09600","7.25821","0.02770"
"87.55200","7.29624","0.02869"
"88.00800","7.33420","0.02977"
"88.46400","7.37223","0.03079"
"88.92000","7.41020","0.03147"
"89.37600","7.44822","0.03286"
"89.83200","7.48625","0.03389"
"90.28800","7.52421","0.03486"
"90.74400","7.56218","0.03641"
"91.20000","7.60027","0.03783"
"91.65600","7.63823","0.03813"
"92.11200","7.67620","0.02411"
"92.56800","7.71422","0.02467"
"93.02400","7.75219","0.02672"
"93.48000","7.79022","0.02611"
"93.93600","7.82830","0.02684"
"94.39200","7.86621","0.02798"
"94.84800","7.90418","0.02980"
"95.30400","7.94226","0.03108"
"95.76000","7.98023","0.03193"
"96.21600","8.01825","0.03299"
"96.67200","8.05628","0.01608"
"97.12800","8.09425","0.01724"
"97.58400","8.13215","0.02034"
"98.04000","8.17012","0.02299"
"98.49600","8.20821","0.02368"
"98.95200","8.24623","0.02409"
"99.40800","8.28426","0.02425"
"99.86400","8.32228","0.02754"
"100.32000","8.36019","0.02826"
"100.77600","8.39816","0.03045"
"101.23200","8.43618","0.03142"
"101.68800","8.47427","0.03324"
"102.14400","8.51224","0.03484"
"102.60000","8.55026","0.03677"
"103.05600","8.58823","0.03801"
"103.51200","8.62619","0.01016"
"103.96800","8.66422","0.01352"
"104.42400","8.70219","0.01243"
"104.88000","8.74027","0.01302"
"105.33600","8.77824","0.01476"
"105.79200","8.81621","0.01503"
"106.24800","8.85417","0.01606"
"106.70400","8.89220","0.01696"
"107.16000","8.93022","0.01803"
"107.61600","8.96825","0.01989"
"108.07200","9.00628","0.02065"
"108.52800","9.04418","0.02085"
"108.98400","9.08227","0.02284"
"109.44000","9.12024","0.02407"
"109.89600","9.15820","0.02462"
"110.35200","9.19623","0.02614"
"110.80800","9.23419","0.02737"
"111.26400","9.27222","0.02851"
"111.72000","9.31025","0.02959"
"112.17600","9.34827","0.03011"
"112.63200","9.38624","0.03123"
"113.08800","9.42421","0.03169"
"113.54400","9.46217","0.03284"
"114.00000","9.50026","0.03336"
"114.45600","9.53828","0.03458"
"114.91200","9.57625","0.03467"
"115.36800","9.61422","0.03576"
"115.82400","9.65218","0.03702"
"116.28000","9.69021","0.03768"
"116.73600","9.72824","0.03895"
"117.19200","9.76620","0.04043"
"117.64800","9.80423","0.04131"
"118.10400","9.84219","0.04197"
"118.56000","9.88016","0.04298"
"119.01600","9.91819","0.04384"
"119.47200","9.95621","0.04496"
"119.92800","9.99424","0.04596"
"120.38400","10.03226","0.04672"
"120.84000","10.07029","0.04843"
"121.29600","10.10820","0.04926"
"121.75200","10.14616","0.05004"
"122.20800","10.18425","0.05142"
"122.66400","10.22222","0.05220"
"123.12000","10.26030","0.05388"
"123.57600","10.29821","0.05466"
"124.03200","10.33624","0.05597"
"124.48800","10.37420","0.05767"
"124.94400","10.41223","0.05971"
"125.40000","10.45019","0.06124"
"125.85600","10.48822","0.06426"
"126.31200","10.52625","0.06661"
"126.76800","10.56421","0.06890"
"127.22400","10.60224","0.07075"
"127.68000","10.64027","0.07276"
"128.13600","10.67817","0.07450"
"128.59200","10.71626","0.07635"
"129.04800","10.75422","0.07788"
"129.50400","10.79225","0.07928"
"129.96000","10.83028","0.08043"
"130.41600","10.86818","0.08238"
"130.87200","10.90621","0.08383"
"131.32800","10.94423","0.08546"
"131.78400","10.98220","0.08685"
"132.24000","11.02029","0.08864"
"132.69600","11.05825","0.08992"
"133.15200","11.09622","0.09141"
"133.60800","11.13419","0.09374"
"134.06400","11.17215","0.09579"
"134.52000","11.21018","0.09837"
"134.97600","11.24826","0.10004"
"135.43200","11.28629","0.10107"
"135.88800","11.32426","0.10189"
"136.34400","11.36222","0.10328"
"136.80000","11.40013","0.10486"
"137.25600","11.43822","0.10715"
"137.71200","11.47630","0.10952"
"138.16800","11.51427","0.11182"
"138.62400","11.55229","0.11441"
"139.08000","11.59020","0.11726"
"139.53600","11.62817","0.11956"
"139.99200","11.66625","0.12236"
"140.44800","11.70428","0.12444"
"140.90400","11.74225","0.12631"
"141.36000","11.78021","0.12828"
"141.81600","11.81824","0.12967"
"142.27200","11.85620","0.13099"
"142.72800","11.89423","0.13262"
"143.18400","11.93220","0.13227"
"143.64000","11.97022","0.13425"
"144.09600","12.00825","0.13630"
"144.55200","12.04622","0.13808"
"145.00800","12.08424","0.14002"
"145.46400","12.12221","0.14275"
"145.92000","12.16018","0.14557"
"146.37600","12.19826","0.14850"
"146.83200","12.23623","0.15023"
"147.28800","12.27425","0.15239"
"147.74400","12.31222","0.15526"
"148.20000","12.35025","0.15702"
"148.65600","12.38821","0.15935"
"149.11200","12.42618","0.16294"
"149.56800","12.46420","0.16702"
"150.02400","12.50229","0.17225"
"150.48000","12.54026","0.17721"
"150.93600","12.57822","0.18140"
"151.39200","12.61619","0.18431"
"151.84800","12.65421","0.18725"
"152.30400","12.69218","0.19004"
"152.76000","12.73027","0.19265"
"153.21600","12.76829","0.19557"
"153.67200","12.80626","0.19845"
"154.12800","12.84423","0.18196"
"154.58400","12.88219","0.18373"
"155.04000","12.92016","0.18566"
"155.49600","12.95825","0.18965"
"155.95200","12.99627","0.19209"
"156.40800","13.03424","0.19433"
"156.86400","13.07220","0.19867"
"157.32000","13.11017","0.20123"
"157.77600","13.14820","0.19375"
"158.23200","13.18622","0.19566"
"158.68800","13.22425","0.20074"
"159.14400","13.26228","0.20333"
"159.60000","13.30024","0.20507"
"160.05600","13.33827","0.20800"
"160.51200","13.37617","0.21099"
"160.96800","13.41426","0.21429"
"161.42400","13.45223","0.21808"
"161.88000","13.49019","0.22179"
"162.33600","13.52822","0.22489"
"162.79200","13.56625","0.22841"
"163.24800","13.60421","0.23090"
"163.70400","13.64218","0.23428"
"164.16000","13.68020","0.23810"
"164.61600","13.71823","0.24176"
"165.07200","13.75626","0.24510"
"165.52800","13.79428","0.24899"
"165.98400","13.83225","0.25273"
"166.44000","13.87022","0.25701"
"166.89600","13.90824","0.26112"
"167.35200","13.94627","0.26669"
"167.80800","13.98423","0.27308"
"168.26400","14.02226","0.27852"
"168.72000","14.06029","0.28289"
"169.17600","14.09825","0.28696"
"169.63200","14.13616","0.29088"
"170.08800","14.17418","0.29508"
"170.54400","14.21227","0.29995"
"171.00000","14.25024","0.30484"
"171.45600","14.28826","0.30920"
"171.91200","14.32623","0.31153"
"172.36800","14.36420","0.31536"
"172.82400","14.40216","0.31844"
"173.28000","14.44019","0.32261"
"173.73600","14.47828","0.32697"
"174.19200","14.51624","0.32756"
"174.64800","14.55427","0.32605"
"175.10400","14.59223","0.33229"
"175.56000","14.63020","0.33792"
"176.01600","14.66823","0.34289"
"176.47200","14.70625","0.34774"
"176.92800","14.74428","0.35235"
"177.38400","14.78218","0.35685"
"177.84000","14.82021","0.36099"
"178.29600","14.85824","0.36570"
"178.75200","14.89620","0.37199"
"179.20800","14.93423","0.37959"
"179.66400","14.97220","0.38537"
"180.12000","15.01028","0.38867"
"180.57600","15.04825","0.39262"
"181.03200","15.08628","0.39832"
"181.48800","15.12418","0.40412"
"181.94400","15.16221","0.40974"
"182.40000","15.20023","0.41389"
"182.85600","15.23826","0.41722"
"183.31200","15.27623","0.42242"
"183.76800","15.31425","0.42706"
"184.22400","15.35222","0.43287"
"184.68000","15.39018","0.43842"
"185.13600","15.42821","0.44270"
"185.59200","15.46618","0.44811"
"186.04800","15.50426","0.45287"
"186.50400","15.54229","0.45707"
"186.96000","15.58026","0.46069"
"187.41600","15.61822","0.46644"
"187.87200","15.65619","0.47515"
"188.32800","15.69421","0.48388"
"188.78400","15.73230","0.48972"
"189.24000","15.77027","0.49437"
"189.69600","15.80823","0.49840"
"190.15200","15.84620","0.50417"
"190.60800","15.88416","0.51254"
"191.06400","15.92219","0.51821"
"191.52000","15.96028","0.52352"
"191.97600","15.99830","0.52931"
"192.43200","16.03621","0.53628"
"192.88800","16.07424","0.54234"
"193.34400","16.11220","0.54840"
"193.80000","16.15023","0.55390"
"194.25600","16.18826","0.55924"
"194.71200","16.22616","0.40319"
"195.16800","16.26425","0.40562"
"195.62400","16.30221","0.40983"
"196.08000","16.34024","0.41719"
"196.53600","16.37821","0.42145"
"196.99200","16.41617","0.43088"
"197.44800","16.45426","0.43731"
"197.90400","16.49228","0.44413"
"198.36000","16.53019","0.45174"
"198.81600","16.56822","0.45729"
"199.27200","16.60618","0.46322"
"199.72800","16.64421","0.47368"
"200.18400","16.68218","0.48481"
"200.64000","16.72026","0.49227"
"201.09600","16.75823","0.49756"
"201.55200","16.79631","0.50465"
"202.00800","16.83422","0.51382"
"202.46400","16.87213","0.52077"
"202.92000","16.91027","0.52540"
"203.37600","16.94824","0.53287"
"203.83200","16.98627","0.54130"
"204.28800","17.02429","0.54751"
"204.74400","17.06226","0.55501"
"205.20000","17.10022","0.56232"
"205.65600","17.13813","0.56800"
"206.11200","17.17622","0.57194"
"206.56800","17.21424","0.57990"
"207.02400","17.25227","0.58950"
"207.48000","17.29024","0.44755"
"207.93600","17.32814","0.44747"
"208.39200","17.36617","0.45230"
"208.84800","17.40420","0.45572"
"209.30400","17.44222","0.13425"
"209.76000","17.48025","0.09367"
"210.21600","17.51821","0.09254"
"210.67200","17.55624","0.09482"
"211.12800","17.59421","0.10483"
"211.58400","17.63217","0.11224"
"212.04000","17.67020","0.12191"
"212.49600","17.70823","0.12812"
"212.95200","17.74625","0.13177"
"213.40800","17.78422","0.13764"
"213.86400","17.82224","0.14367"
"214.32000","17.86021","0.15092"
"214.77600","17.89818","0.15621"
"215.23200","17.93626","0.16503"
"215.68800","17.97423","0.17900"
"216.14400","18.01225","0.19193"
"216.60000","18.05022","0.20656"
"217.05600","18.08825","0.21250"
"217.51200","18.12621","0.21099"
"217.96800","18.16418","0.20925"
"218.42400","18.20221","0.21249"
"218.88000","18.24023","0.22078"
"219.33600","18.27826","0.23241"
"219.79200","18.31623","0.24230"
"220.24800","18.35419","0.24196"
"220.70400","18.39216","0.24267"
"221.16000","18.43018","0.25004"
"221.61600","18.46827","0.26493"
"222.07200","18.50624","0.27629"
"222.52800","18.54426","0.27451"
"222.98400","18.58223","0.27976"
"223.44000","18.62020","0.13106"
"223.89600","18.65822","0.12871"
"224.35200","18.69625","0.13511"
"224.80800","18.73427","0.12474"
"225.26400","18.77224","0.13125"
"225.72000","18.81021","0.13507"
"226.17600","18.84817","0.14136"
"226.63200","18.88620","0.14412"
"227.08800","18.92422","0.15066"
"227.54400","18.96225","0.15624"
"228.00000","19.00022","0.16251"
"228.45600","19.03830","0.17170"
"228.91200","19.07621","0.17790"
"229.36800","19.11418","0.18243"
"229.82400","19.15226","0.18631"
"230.28000","19.19023","0.18876"
"230.73600","19.22819","0.19147"
"231.19200","19.26622","0.19522"
"231.64800","19.30425","0.20004"
"232.10400","19.34221","0.20482"
"232.56000","19.38024","0.20804"
"233.01600","19.41821","0.21165"
"233.47200","19.45623","0.21409"
"233.92800","19.49420","0.21681"
"234.38400","19.53222","0.22078"
"234.84000","19.57025","0.22549"
"235.29600","19.60822","0.23040"
"235.75200","19.64618","0.23398"
"236.20800","19.68421","0.23522"
"236.66400","19.72223","0.23894"
"237.12000","19.76026","0.24260"
"237.57600","19.79829","0.24201"
"238.03200","19.83619","0.24700"
"238.48800","19.87416","0.24809"
"238.94400","19.91219","0.25010"
"239.40000","19.95027","0.15375"
"239.85600","19.98824","0.15793"
"240.31200","20.02626","0.16866"
"240.76800","20.06423","0.17832"
"241.22400","20.10220","0.18450"
"241.68000","20.14016","0.18720"
"242.13600","20.17819","0.18845"
"242.59200","20.21628","0.18988"
"243.04800","20.25424","0.19128"
"243.50400","20.29227","0.19469"
"243.96000","20.33018","0.19921"
"244.41600","20.36814","0.20342"
"244.87200","20.40623","0.20588"
"245.32800","20.44425","0.20768"
"245.78400","20.48222","0.20856"
"246.24000","20.52024","0.21191"
"246.69600","20.55821","0.21611"
"247.15200","20.59618","0.22070"
"247.60800","20.63421","0.22416"
"248.06400","20.67223","0.22724"
"248.52000","20.71026","0.23062"
"248.97600","20.74822","0.23377"
"249.43200","20.78625","0.23652"
"249.88800","20.82422","0.23987"
"250.34400","20.86218","0.24415"
"250.80000","20.90021","0.24784"
"251.25600","20.93823","0.25160"
"251.71200","20.97626","0.25575"
"252.16800","21.01423","0.25990"
"252.62400","21.05219","0.26498"
"253.08000","21.09022","0.27010"
"253.53600","21.12819","0.27612"
"253.99200","21.16621","0.27995"
"254.44800","21.20424","0.28442"
"254.90400","21.24220","0.28823"
"255.36000","21.28029","0.29113"
"255.81600","21.31820","0.29340"
"256.27200","21.35616","0.24280"
"256.72800","21.39419","0.06909"
"257.18400","21.43216","0.06611"
"257.64000","21.47024","0.06936"
"258.09600","21.50827","0.07487"
"258.55200","21.54630","0.08036"
"259.00800","21.58414","0.08434"
"259.46400","21.62217","0.08951"
"259.92000","21.66025","0.09593"
"260.37600","21.69822","0.09951"
"260.83200","21.73631","0.10173"
"261.28800","21.77427","0.10368"
"261.74400","21.81218","0.10500"
"262.20000","21.85014","0.10748"
"262.65600","21.88817","0.11060"
"263.11200","21.92626","0.11372"
"263.56800","21.96422","0.11623"
"264.02400","22.00219","0.12020"
"264.48000","22.04022","0.12341"
"264.93600","22.07818","0.12657"
"265.39200","22.11615","0.12921"
"265.84800","22.15423","0.13144"
"266.30400","22.19232","0.13477"
"266.76000","22.23022","0.13876"
"267.21600","22.26826","0.14193"
"267.67200","22.30622","0.14537"
"268.12800","22.34419","0.14865"
"268.58400","22.38221","0.15230"
"269.04000","22.42024","0.15544"
"269.49600","22.45820","0.15820"
"269.95200","22.49617","0.16351"
"270.40800","22.53425","0.16931"
"270.86400","22.57228","0.17503"
"271.32000","22.61025","0.17966"
"271.77600","22.64822","0.18244"
"272.23200","22.68618","0.18561"
"272.68800","22.72427","0.18884"
"273.14400","22.76223","0.19141"
"273.60000","22.80026","0.19419"
"274.05600","22.83817","0.19693"
"274.51200","22.87613","0.19999"
"274.96800","22.91422","0.20374"
"275.42400","22.95224","0.20668"
"275.88000","22.99027","0.20998"
"276.33600","23.02830","0.21321"
"276.79200","23.06620","0.21631"
"277.24800","23.10417","0.22001"
"277.70400","23.14220","0.22315"
"278.16000","23.18022","0.22649"
"278.61600","23.21825","0.22941"
"279.07200","23.25628","0.23247"
"279.52800","23.29424","0.23436"
"279.98400","23.33215","0.23833"
"280.44000","23.37017","0.24247"
"280.89600","23.40820","0.24519"
"281.35200","23.44622","0.24743"
"281.80800","23.48425","0.15029"
"282.26400","23.52222","0.15004"
"282.72000","23.56025","0.15058"
"283.17600","23.59815","0.15405"
"283.63200","23.63624","0.15906"
"284.08800","23.67426","0.16341"
"284.54400","23.71223","0.16554"
"285.00000","23.75020","0.17138"
"285.45600","23.78816","0.17800"
"285.91200","23.82619","0.18112"
"286.36800","23.86421","0.18516"
"286.82400","23.90218","0.18872"
"287.28000","23.94020","0.19153"
"287.73600","23.97817","0.19450"
"288.19200","24.01626","0.19834"
"288.64800","24.05423","0.20026"
"289.10400","24.09219","0.20259"
"289.56000","24.13022","0.20380"
"290.01600","24.16818","0.20477"
"290.47200","24.20627","0.20618"
"290.92800","24.24424","0.20678"
"291.38400","24.28226","0.20883"
"291.84000","24.32023","0.21041"
"292.29600","24.35819","0.21259"
"292.75200","24.39616","0.21545"
"293.20800","24.43419","0.21873"
"293.66400","24.47227","0.22062"
"294.12000","24.51024","0.22267"
"294.57600","24.54821","0.22364"
"295.03200","24.58617","0.22532"
"295.48800","24.62420","0.22667"
"295.94400","24.66222","0.22892"
"296.40000","24.70019","0.23051"
"296.85600","24.73828","0.23253"
"297.31200","24.77625","0.23403"
"297.76800","24.81415","0.23527"
"298.22400","24.85212","0.23601"
"298.68000","24.89020","0.23724"
"299.13600","24.92829","0.23833"
"299.59200","24.96626","0.24107"
"300.04800","25.00428","0.24401"
"300.50400","25.04219","0.24607"
"300.96000","25.08015","0.24776"
"301.41600","25.11818","0.24937"
"301.87200","25.15627","0.25224"
"302.32800","25.19423","0.25490"
"302.78400","25.23220","0.25847"
"303.24000","25.27023","0.26155"
"303.69600","25.30819","0.26379"
"304.15200","25.34616","0.26538"
"304.60800","25.38418","0.26850"
"305.06400","25.42221","0.27201"
"305.52000","25.46024","0.27538"
"305.97600","25.49820","0.27851"
"306.43200","25.53623","0.28053"
"306.88800","25.57425","0.28170"
"307.34400","25.61222","0.28319"
"307.80000","25.65025","0.28469"
"308.25600","25.68821","0.28636"
"308.71200","25.72624","0.28840"
"309.16800","25.76427","0.28919"
"309.62400","25.80223","0.29135"
"310.08000","25.84014","0.29293"
"310.53600","25.87817","0.26733"
"310.99200","25.91619","0.27159"
"311.44800","25.95428","0.27854"
"311.90400","25.99224","0.28180"
"312.36000","26.03027","0.28458"
"312.81600","26.06817","0.28686"
"313.27200","26.10620","0.28979"
"313.72800","26.14423","0.29363"
"314.18400","26.18225","0.29624"
"314.64000","26.22028","0.29868"
"315.09600","26.25825","0.11731"
"315.55200","26.29621","0.11543"
"316.00800","26.33418","0.11187"
"316.46400","26.37221","0.10966"
"316.92000","26.41023","0.10673"
"317.37600","26.44826","0.10489"
"317.83200","26.48623","0.10402"
"318.28800","26.52425","0.00582"
"318.74400","26.56216","0.00307"
"319.20000","26.60018","0.00183"
"319.65600","26.63821","0.00228"
"320.11200","26.67624","0.00228"
"320.56800","26.71426","0.00221"
"321.02400","26.75223","0.00274"
"321.48000","26.79019","0.00193"
"321.93600","26.82822","0.00244"
"322.39200","26.86625","0.00236"
"322.84800","26.90427","0.00205"
"323.30400","26.94224","0.00239"
"323.76000","26.98021","0.00239"
"324.21600","27.01823","0.00146"
"324.67200","27.05620","0.00262"
"325.12800","27.09417","0.00234"
"325.58400","27.13219","0.00207"
"326.04000","27.17016","0.00258"
"326.49600","27.20824","0.00230"
"326.95200","27.24627","0.00284"
"327.40800","27.28424","0.00238"
"327.86400","27.32220","0.00198"
"328.32000","27.36017","0.00236"
"328.77600","27.39820","0.00242"
"329.23200","27.43622","0.00224"
"329.68800","27.47425","0.00217"
"330.14400","27.51221","0.00252"
"330.60000","27.55024","0.00205"
"331.05600","27.58815","0.00217"
"331.51200","27.62617","0.00198"
"331.96800","27.66426","0.00296"
"332.42400","27.70222","0.00235"
"332.88000","27.74025","0.00220"
"333.33600","27.77822","0.00243"
"333.79200","27.81618","0.00226"
"334.24800","27.85415","0.00223"
"334.70400","27.89218","0.00196"
"335.16000","27.93026","0.00252"
"335.61600","27.96829","0.00243"
"336.07200","28.00631","0.00213"
"336.52800","28.04422","0.00240"
"336.98400","28.08213","0.00201"
"337.44000","28.12021","0.00231"
"337.89600","28.15824","0.00189"
"338.35200","28.19627","0.00147"
"338.80800","28.23417","0.00196"
"339.26400","28.27220","0.00213"
"339.72000","28.31017","0.00224"
"340.17600","28.34819","0.00251"
"340.63200","28.38622","0.00215"
"341.08800","28.42418","0.00232"
"341.54400","28.46227","0.00252"
"342.00000","28.50024","0.00193"
"342.45600","28.53826","0.00232"
"342.91200","28.57623","0.00202"
"343.36800","28.61419","0.00255"
"343.82400","28.65222","0.00258"
"344.28000","28.69019","0.00235"
"344.73600","28.72828","0.00216"
"345.19200","28.76624","0.00249"
"345.64800","28.80420","0.00244"
"346.10400","28.84217","0.00210"
"346.56000","28.88020","0.00266"
"347.01600","28.91823","0.00277"
"347.47200","28.95625","0.00252"
"347.92800","28.99428","0.00239"
"348.38400","29.03218","0.00262"
"348.84000","29.07021","0.00272"
"349.29600","29.10824","0.00226"
"349.75200","29.14620","0.00247"
"350.20800","29.18423","0.00257"
"350.66400","29.22226","0.00254"
"351.12000","29.26022","0.00239"
"351.57600","29.29819","0.00260"
"352.03200","29.33615","0.00278"
"352.48800","29.37418","0.00283"
"352.94400","29.41227","0.00267"
"353.40000","29.45017","0.00292"
"353.85600","29.48826","0.00297"
"354.31200","29.52622","0.00326"
"354.76800","29.56419","0.00296"
"355.22400","29.60222","0.00296"
"355.68000","29.64024","0.00305"
"356.13600","29.67827","0.00317"
"356.59200","29.71623","0.00293"
"357.04800","29.75420","0.00286"
"357.50400","29.79223","0.00299"
"357.96000","29.83025","0.00293"
"358.41600","29.86822","0.00322"
"358.87200","29.90619","0.00296"
"359.32800","29.94422","0.00330"
"359.78400","29.98224","0.00399"
"360.24000","30.02020","0.00362"
"360.69600","30.05817","0.00331"
"361.15200","30.09614","0.00362"
"361.60800","30.13423","0.00372"
"362.06400","30.17225","0.00392"
"362.52000","30.21016","0.00351"
"362.97600","30.24824","0.00336"
"363.43200","30.28627","0.00350"
"363.88800","30.32418","0.00414"
"364.34400","30.36220","0.00414"
"364.80000","30.40023","0.00373"
"365.25600","30.43826","0.00407"
"365.71200","30.47628","0.00404"
"366.16800","30.51419","0.00456"
"366.62400","30.55215","0.00462"
"367.08000","30.59018","0.00393"
"367.53600","30.62815","0.00407"
"367.99200","30.66623","0.00466"
"368.44800","30.70420","0.00479"
"368.90400","30.74229","0.00492"
"369.36000","30.78019","0.00498"
"369.81600","30.81816","0.00462"
"370.27200","30.85618","0.00457"
"370.72800","30.89427","0.00503"
"371.18400","30.93230","0.00504"
"371.64000","30.97020","0.00531"
"372.09600","31.00823","0.00503"
"372.55200","31.04619","0.00506"
"373.00800","31.08422","0.00502"
"373.46400","31.12218","0.00529"
"373.92000","31.16021","0.00558"
"374.37600","31.19824","0.00578"
"374.83200","31.23621","0.00580"
"375.28800","31.27423","0.00552"
"375.74400","31.31220","0.00616"
"376.20000","31.35022","0.00607"
"376.65600","31.38825","0.00636"
"377.11200","31.42621","0.00613"
"377.56800","31.46424","0.00682"
"378.02400","31.50221","0.00632"
"378.48000","31.54023","0.00670"
"378.93600","31.57814","0.00660"
"379.39200","31.61623","0.00696"
"379.84800","31.65419","0.00711"
"380.30400","31.69222","0.00722"
"380.76000","31.73025","0.00699"
"381.21600","31.76821","0.00731"
"381.67200","31.80618","0.00754"
"382.12800","31.84414","0.00758"
"382.58400","31.88223","0.00733"
"383.04000","31.92019","0.00742"
"383.49600","31.95828","0.00760"
"383.95200","31.99625","0.00721"
"384.40800","32.03421","0.00755"
"384.86400","32.07218","0.00773"
"385.32000","32.11021","0.00773"
"385.77600","32.14824","0.00783"
"386.23200","32.18632","0.00776"
"386.68800","32.22423","0.00793"
"387.14400","32.26225","0.00795"
"387.60000","32.30010","0.00799"
"388.05600","32.33818","0.00825"
"388.51200","32.37621","0.00810"
"388.96800","32.41423","0.00857"
"389.42400","32.45220","0.00849"
"389.88000","32.49023","0.00804"
"390.33600","32.52819","0.00813"
"390.79200","32.56616","0.00853"
"391.24800","32.60425","0.00811"
"391.70400","32.64222","0.00758"
"392.16000","32.68024","0.00731"
"392.61600","32.71821","0.00726"
"393.07200","32.75623","0.00752"
"393.52800","32.79420","0.00712"
"393.98400","32.83223","0.00687"
"394.44000","32.87019","0.00687"
"394.89600","32.90822","0.00684"
"395.35200","32.94619","0.00695"
"395.80800","32.98427","0.00716"
"396.26400","33.02224","0.00689"
"396.72000","33.06015","0.00670"
"397.17600","33.09817","0.00657"
"397.63200","33.13620","0.00628"
"398.08800","33.17422","0.00640"
"398.54400","33.21225","0.00636"
"399.00000","33.25021","0.00650"
"399.45600","33.28818","0.00675"
"399.91200","33.32615","0.00694"
"400.36800","33.36417","0.00669"
"400.82400","33.40226","0.00646"
"401.28000","33.44022","0.00696"
"401.73600","33.47831","0.00757"
"402.19200","33.51622","0.00674"
"402.64800","33.55418","0.00708"
"403.10400","33.59221","0.00657"
"403.56000","33.63018","0.00650"
"404.01600","33.66827","0.00698"
"404.47200","33.70623","0.00708"
"404.92800","33.74426","0.00720"
"405.38400","33.78216","0.00718"
"405.84000","33.82013","0.00670"
"406.29600","33.85822","0.00705"
"406.75200","33.89624","0.00650"
"407.20800","33.93427","0.00650"
"407.66400","33.97223","0.00673"
"408.12000","34.01020","0.00656"
"408.57600","34.04816","0.00596"
"409.03200","34.08625","0.00618"
"409.48800","34.12428","0.00642"
"409.94400","34.16225","0.00667"
"410.40000","34.20027","0.00670"
"410.85600","34.23824","0.00692"
"411.31200","34.27620","0.00652"
"411.76800","34.31417","0.00636"
"412.22400","34.35213","0.00600"
"412.68000","34.39022","0.00591"
"413.13600","34.42825","0.00583"
"413.59200","34.46627","0.00620"
"414.04800","34.50418","0.00583"
"414.50400","34.54221","0.00615"
"414.96000","34.58023","0.00594"
"415.41600","34.61820","0.00580"
"415.87200","34.65623","0.00544"
"416.32800","34.69419","0.00572"
"416.78400","34.73228","0.00549"
"417.24000","34.77018","0.00557"
"417.69600","34.80815","0.00552"
"418.15200","34.84623","0.00568"
"418.60800","34.88414","0.00541"
"419.06400","34.92223","0.00549"
"419.52000","34.96025","0.00553"
"419.97600","34.99828","0.00493"
"420.43200","35.03619","0.00477"
"420.88800","35.07415","0.00458"
"421.34400","35.11224","0.00494"
"421.80000","35.15027","0.00474"
"422.25600","35.18829","0.00479"
"422.71200","35.22620","0.00473"
"423.16800","35.26416","0.00446"
"423.62400","35.30213","0.00446"
"424.08000","35.34016","0.00471"
"424.53600","35.37824","0.00451"
"424.99200","35.41621","0.00417"
"425.44800","35.45418","0.00442"
"425.90400","35.49226","0.00446"
"426.36000","35.53017","0.00477"
"426.81600","35.56820","0.00465"
"427.27200","35.60622","0.00449"
"427.72800","35.64425","0.00477"
"428.18400","35.68227","0.00438"
"428.64000","35.72024","0.00403"
"429.09600","35.75821","0.00424"
"429.55200","35.79617","0.00372"
"430.00800","35.83420","0.00385"
"430.46400","35.87222","0.00431"
"430.92000","35.91025","0.00409"
"431.37600","35.94822","0.00415"
"431.83200","35.98624","0.00382"
"432.28800","36.02421","0.00421"
"432.74400","36.06218","0.00435"
"433.20000","36.10020","0.00406"
"433.65600","36.13823","0.00395"
"434.11200","36.17619","0.00435"
"434.56800","36.21428","0.00415"
"435.02400","36.25225","0.00420"
"435.48000","36.29021","0.00416"
"435.93600","36.32818","0.00412"
"436.39200","36.36621","0.00420"
"436.84800","36.40423","0.00448"
"437.30400","36.44226","0.00459"
"437.76000","36.48029","0.00458"
"438.21600","36.51819","0.00470"
"438.67200","36.55622","0.00444"
"439.12800","36.59418","0.00460"
"439.58400","36.63221","0.00449"
"440.04000","36.67030","0.00434"
"440.49600","36.70826","0.00441"
"440.95200","36.74623","0.00440"
"441.40800","36.78419","0.00433"
"441.86400","36.82222","0.00400"
"442.32000","36.86019","0.00418"
"442.77600","36.89822","0.00436"
"443.23200","36.93624","0.00439"
"443.68800","36.97427","0.00407"
"444.14400","37.01217","0.00485"
"444.60000","37.05014","0.00420"
"445.05600","37.08823","0.00455"
"445.51200","37.12625","0.00427"
"445.96800","37.16428","0.00426"
"446.42400","37.20224","0.00455"
"446.88000","37.24021","0.00411"
"447.33600","37.27818","0.00422"
"447.79200","37.31620","0.00443"
"448.24800","37.35423","0.00431"
"448.70400","37.39225","0.00422"
"449.16000","37.43022","0.00445"
"449.61600","37.46825","0.00436"
"450.07200","37.50621","0.00433"
"450.52800","37.54424","0.00423"
"450.98400","37.58215","0.00398"
"451.44000","37.62023","0.00378"
"451.89600","37.65820","0.00408"
"452.35200","37.69622","0.00411"
"452.80800","37.73431","0.00405"
"453.26400","37.77222","0.00405"
"453.72000","37.81018","0.00382"
"454.17600","37.84821","0.00383"
"454.63200","37.88623","0.00381"
"455.08800","37.92420","0.00379"
"455.54400","37.96229","0.00345"
"456.00000","38.00026","0.00314"
"456.45600","38.03816","0.00358"
"456.91200","38.07619","0.00379"
"457.36800","38.11421","0.00383"
"457.82400","38.15224","0.00427"
"458.28000","38.19027","0.00363"
"458.73600","38.22823","0.00399"
"459.19200","38.26620","0.00368"
"459.64800","38.30416","0.00359"
"460.10400","38.34225","0.00358"
"460.56000","38.38028","0.00389"
"461.01600","38.41819","0.00370"
"461.47200","38.45627","0.00375"
"461.92800","38.49418","0.00370"
"462.38400","38.53214","0.00369"
"462.84000","38.57023","0.00369"
"463.29600","38.60825","0.00342"
"463.75200","38.64622","0.00342"
"464.20800","38.68425","0.00391"
"464.66400","38.72221","0.00367"
"465.12000","38.76018","0.00343"
"465.57600","38.79821","0.00352"
"466.03200","38.83624","0.00369"
"466.48800","38.87426","0.00381"
"466.94400","38.91228","0.00377"
"467.40000","38.95019","0.00357"
"467.85600","38.98822","0.00372"
"468.31200","39.02624","0.00372"
"468.76800","39.06421","0.00334"
"469.22400","39.10223","0.00366"
"469.68000","39.14026","0.00401"
"470.13600","39.17817","0.00403"
"470.59200","39.21625","0.00369"
"471.04800","39.25428","0.00365"
"471.50400","39.29219","0.00362"
"471.96000","39.33022","0.00400"
"472.41600","39.36818","0.00372"
"472.87200","39.40627","0.00378"
"473.32800","39.44423","0.00419"
"473.78400","39.48226","0.00391"
"474.24000","39.52016","0.00400"
"474.69600","39.55819","0.00383"
"475.15200","39.59621","0.00415"
"475.60800","39.63424","0.00377"
"476.06400","39.67227","0.00409"
"476.52000","39.71024","0.00416"
"476.97600","39.74820","0.00418"
"477.43200","39.78617","0.00417"
"477.88800","39.82420","0.00424"
"478.34400","39.86222","0.00396"
"478.80000","39.90025","0.00432"
"479.25600","39.93821","0.00419"
"479.71200","39.97624","0.00428"
"480.16800","40.01420","0.00403"
"480.62400","40.05217","0.00402"
"481.08000","40.09020","0.00440"
"481.53600","40.12828","0.00422"
"481.99200","40.16625","0.00445"
"482.44800","40.20427","0.00467"
"482.90400","40.24218","0.00460"
"483.36000","40.28021","0.00481"
"483.81600","40.31824","0.00472"
"484.27200","40.35620","0.00465"
"484.72800","40.39429","0.00513"
"485.18400","40.43219","0.00481"
"485.64000","40.47021","0.00430"
"486.09600","40.50819","0.00473"
"486.55200","40.54621","0.00461"
"487.00800","40.58424","0.00487"
"487.46400","40.62220","0.00448"
"487.92000","40.66023","0.00520"
"488.37600","40.69820","0.00486"
"488.83200","40.73628","0.00417"
"489.28800","40.77419","0.00499"
"489.74400","40.81216","0.00489"
"490.20000","40.85024","0.00502"
"490.65600","40.88821","0.00476"
"491.11200","40.92623","0.00527"
"491.56800","40.96426","0.00496"
"492.02400","41.00222","0.00475"
"492.48000","41.04013","0.00491"
"492.93600","41.07822","0.00495"
"493.39200","41.11625","0.00494"
"493.84800","41.15427","0.00472"
"494.30400","41.19229","0.00512"
"494.76000","41.23021","0.00467"
"495.21600","41.26817","0.00504"
"495.67200","41.30620","0.00461"
"496.12800","41.34423","0.00442"
"496.58400","41.38224","0.00488"
"497.04000","41.42022","0.00463"
"497.49600","41.45824","0.00481"
"497.95200","41.49627","0.00505"
"498.40800","41.53411","0.00475"
"498.86400","41.57220","0.00470"
"499.32000","41.61023","0.00463"
"499.77600","41.64825","0.00478"
"500.23200","41.68622","0.00513"
"500.68800","41.72419","0.00457"
"501.14400","41.76221","0.00483"
"501.60000","41.80024","0.00455"
"502.05600","41.83821","0.00495"
"502.51200","41.87623","0.00472"
"502.96800","41.91425","0.00484"
"503.42400","41.95222","0.00493"
"503.88000","41.99025","0.00482"
"504.33600","42.02827","0.00535"
"504.79200","42.06618","0.00548"
"505.24800","42.10420","0.00495"
"505.70400","42.14223","0.00537"
"506.16000","42.18026","0.00509"
"506.61600","42.21823","0.00511"
"507.07200","42.25625","0.00494"
"507.52800","42.29422","0.00508"
"507.98400","42.33219","0.00490"
"508.44000","42.37021","0.00512"
"508.89600","42.40824","0.00514"
"509.35200","42.44626","0.00545"
"509.80800","42.48423","0.00525"
"510.26400","42.52219","0.00522"
"510.72000","42.56022","0.00562"
"511.17600","42.59825","0.00456"
"511.63200","42.63621","0.00496"
"512.08800","42.67424","0.00464"
"512.54400","42.71221","0.00452"
"513.00000","42.75017","0.00460"
"513.45600","42.78820","0.00428"
"513.91200","42.82616","0.00449"
"514.36800","42.86425","0.00424"
"514.82400","42.90222","0.00457"
"515.28000","42.94024","0.00465"
"515.73600","42.97821","0.00491"
"516.19200","43.01617","0.00471"
"516.64800","43.05420","0.00442"
"517.10400","43.09229","0.00435"
"517.56000","43.13026","0.00421"
"518.01600","43.16822","0.00404"
"518.47200","43.20625","0.00436"
"518.92800","43.24422","0.00393"
"519.38400","43.28212","0.00427"
"519.84000","43.32027","0.00435"
"520.29600","43.35823","0.00420"
"520.75200","43.39620","0.00407"
"521.20800","43.43422","0.00425"
"521.66400","43.47219","0.00403"
"522.12000","43.51022","0.00399"
"522.57600","43.54824","0.00397"
"523.03200","43.58621","0.00429"
"523.48800","43.62423","0.00452"
"523.94400","43.66220","0.00445"
"524.40000","43.70023","0.00391"
"524.85600","43.73819","0.00414"
"525.31200","43.77610","0.00432"
"525.76800","43.81419","0.00432"
"526.22400","43.85221","0.00433"
"526.68000","43.89024","0.00410"
"527.13600","43.92827","0.00406"
"527.59200","43.96623","0.00408"
"528.04800","44.00420","0.00413"
"528.50400","44.04217","0.00398"
"528.96000","44.08019","0.00426"
"529.41600","44.11828","0.00427"
"529.87200","44.15624","0.00440"
"530.32800","44.19427","0.00449"
"530.78400","44.23218","0.00435"
"531.24000","44.27020","0.00458"
"531.69600","44.30817","0.00446"
"532.15200","44.34620","0.00422"
"532.60800","44.38428","0.00458"
"533.06400","44.42225","0.00456"
"533.52000","44.46027","0.00438"
"533.97600","44.49818","0.00436"
"534.43200","44.53615","0.00444"
"534.88800","44.57423","0.00463"
"535.34400","44.61226","0.00473"
"535.80000","44.65023","0.00434"
"536.25600","44.68825","0.00430"
"536.71200","44.72622","0.00471"
"537.16800","44.76419","0.00468"
"537.62400","44.80221","0.00476"
"538.08000","44.84030","0.00487"
"538.53600","44.87826","0.00482"
"538.99200","44.91623","0.00489"
"539.44800","44.95420","0.00494"
"539.90400","44.99222","0.00466"
"540.36000","45.03019","0.00470"
"540.81600","45.06821","0.00467"
"541.27200","45.10624","0.00478"
"541.72800","45.14421","0.00490"
"542.18400","45.18224","0.00461"
"542.64000","45.22020","0.00483"
"543.09600","45.25822","0.00520"
"543.55200","45.29619","0.00476"
"544.00800","45.33422","0.00474"
"544.46400","45.37225","0.00472"
"544.92000","45.41027","0.00495"
"545.37600","45.44823","0.00492"
"545.83200","45.48626","0.00505"
"546.28800","45.52417","0.00448"
"546.74400","45.56226","0.00518"
"547.20000","45.60022","0.00473"
"547.65600","45.63825","0.00494"
"548.11200","45.67627","0.00499"
"548.56800","45.71424","0.00492"
"549.02400","45.75221","0.00516"
"549.48000","45.79023","0.00480"
"549.93600","45.82820","0.00515"
"550.39200","45.86623","0.00477"
"550.84800","45.90425","0.00480"
"551.30400","45.94228","0.00488"
"551.76000","45.98018","0.00495"
"552.21600","46.01815","0.00507"
"552.67200","46.05618","0.00464"
"553.12800","46.09426","0.00493"
"553.58400","46.13229","0.00497"
"554.04000","46.17026","0.00502"
"554.49600","46.20822","0.00516"
"554.95200","46.24619","0.00512"
"555.40800","46.28421","0.00489"
"555.86400","46.32224","0.00509"
"556.32000","46.36020","0.00510"
"556.77600","46.39817","0.00510"
"557.23200","46.43620","0.00527"
"557.68800","46.47422","0.00500"
"558.14400","46.51219","0.00512"
"558.60000","46.55022","0.00516"
"559.05600","46.58824","0.00536"
"559.51200","46.62627","0.00531"
"559.96800","46.66424","0.00508"
"560.42400","46.70226","0.00539"
"560.88000","46.74023","0.00574"
"561.33600","46.77819","0.00580"
"561.79200","46.81622","0.00581"
"562.24800","46.85425","0.00591"
"562.70400","46.89221","0.00617"
"563.16000","46.93030","0.00594"
"563.61600","46.96820","0.00620"
"564.07200","47.00623","0.00641"
"564.52800","47.04420","0.00644"
"564.98400","47.08216","0.00670"
"565.44000","47.12025","0.00656"
"565.89600","47.15828","0.00690"
"566.35200","47.19624","0.00665"
"566.80800","47.23421","0.00716"
"567.26400","47.27218","0.00683"
"567.72000","47.31020","0.00693"
"568.17600","47.34829","0.00702"
"568.63200","47.38625","0.00771"
"569.08800","47.42428","0.00751"
"569.54400","47.46219","0.00767"
"570.00000","47.50021","0.00773"
"570.45600","47.53818","0.00791"
"570.91200","47.57626","0.00804"
"571.36800","47.61430","0.00797"
"571.82400","47.65220","0.00797"
"572.28000","47.69023","0.00835"
"572.73600","47.72819","0.00830"
"573.19200","47.76622","0.00877"
"573.64800","47.80424","0.00841"
"574.10400","47.84215","0.00870"
"574.56000","47.88023","0.00855"
"575.01600","47.91826","0.00861"
"575.47200","47.95623","0.00856"
"575.92800","47.99420","0.00813"
"576.38400","48.03216","0.00873"
"576.84000","48.07025","0.00877"
"577.29600","48.10821","0.00872"
"577.75200","48.14618","0.00872"
"578.20800","48.18421","0.00909"
"578.66400","48.22223","0.00923"
"579.12000","48.26020","0.00841"
"579.57600","48.29822","0.00906"
"580.03200","48.33619","0.00897"
"580.48800","48.37422","0.00908"
"580.94400","48.41230","0.00866"
"581.40000","48.45027","0.00906"
"581.85600","48.48817","0.00927"
"582.31200","48.52614","0.00921"
"582.76800","48.56417","0.00909"
"583.22400","48.60219","0.00910"
"583.68000","48.64028","0.00929"
"584.13600","48.67831","0.00924"
"584.59200","48.71621","0.00941"
"585.04800","48.75412","0.00912"
"585.50400","48.79221","0.00890"
"585.96000","48.83023","0.00858"
"586.41600","48.86826","0.00807"
"586.87200","48.90617","0.00744"
"587.32800","48.94425","0.00750"
"587.78400","48.98222","0.00800"
"588.24000","49.02018","0.00397"
"588.69600","49.05820","0.00567"
"589.15200","49.09629","0.00578"
"589.60800","49.13426","0.00480"
"590.06400","49.17223","0.00628"
"590.52000","49.21019","0.00521"
"590.97600","49.24816","0.00585"
"591.43200","49.28619","0.00624"
"591.88800","49.32421","0.00563"
"592.34400","49.36224","0.00659"
"592.80000","49.40020","0.00616"
"593.25600","49.43824","0.00584"
"593.71200","49.47625","0.00631"
"594.16800","49.51417","0.00648"
"594.62400","49.55225","0.00648"
"595.08000","49.59021","0.00628"
"595.53600","49.62824","0.00626"
"595.99200","49.66627","0.00627"
"596.44800","49.70424","0.00570"
"596.90400","49.74220","0.00511"
"597.36000","49.78016","0.00238"
"597.81600","49.81825","0.00219"
"598.27200","49.85622","0.00177"
"598.72800","49.89425","0.00207"
"599.18400","49.93227","0.00186"
"599.64000","49.97024","0.00144"
"600.09600","50.00821","0.00179"
"600.55200","50.04617","0.00174"
"601.00800","50.08420","0.00177"
"601.46400","50.12228","0.00152"
"601.92000","50.16025","0.00164"
"602.37600","50.19821","0.00137"
"602.83200","50.23612","0.00199"
"603.28800","50.27421","0.00206"
"603.74400","50.31217","0.00186"
"604.20000","50.35026","0.00182"
"604.65600","50.38828","0.00191"
"605.11200","50.42625","0.00158"
"605.56800","50.46422","0.00155"
"606.02400","50.50212","0.00190"
"606.48000","50.54021","0.00165"
"606.93600","50.57830","0.00195"
"607.39200","50.61626","0.00189"
"607.84800","50.65423","0.00159"
"608.30400","50.69220","0.00161"
"608.76000","50.73016","0.00151"
"609.21600","50.76819","0.00144"
"609.67200","50.80622","0.00161"
"610.12800","50.84418","0.00159"
"610.58400","50.88221","0.00189"
"611.04000","50.92023","0.00169"
"611.49600","50.95820","0.00197"
"611.95200","50.99622","0.00160"
"612.40800","51.03419","0.00165"
"612.86400","51.07222","0.00186"
"613.32000","51.11024","0.00160"
"613.77600","51.14821","0.00164"
"614.23200","51.18618","0.00171"
"614.68800","51.22420","0.00151"
"615.14400","51.26223","0.00161"
"615.60000","51.30019","0.00199"
"616.05600","51.33823","0.00151"
"616.51200","51.37625","0.00203"
"616.96800","51.41428","0.00201"
"617.42400","51.45224","0.00181"
"617.88000","51.49021","0.00198"
"618.33600","51.52818","0.00181"
"618.79200","51.56620","0.00150"
"619.24800","51.60429","0.00172"
"619.70400","51.64231","0.00197"
"620.16000","51.68028","0.00182"
"620.61600","51.71819","0.00171"
"621.07200","51.75615","0.00213"
"621.52800","51.79418","0.00168"
"621.98400","51.83227","0.00201"
"622.44000","51.87023","0.00197"
"622.89600","51.90826","0.00155"
"623.35200","51.94623","0.00121"
"623.80800","51.98419","0.00182"
"624.26400","52.02222","0.00202"
"624.72000","52.06024","0.00180"
"625.17600","52.09821","0.00166"
"625.63200","52.13623","0.00184"
"626.08800","52.17420","0.00203"
"626.54400","52.21222","0.00179"
"627.00000","52.25014","0.00179"
"627.45600","52.28822","0.00200"
"627.91200","52.32625","0.00166"
"628.36800","52.36427","0.00190"
"628.82400","52.40224","0.00195"
"629.28000","52.44020","0.00182"
"629.73600","52.47817","0.00189"
"630.19200","52.51620","0.00188"
"630.64800","52.55422","0.00178"
"631.10400","52.59225","0.00186"
"631.56000","52.63021","0.00156"
"632.01600","52.66824","0.00185"
"632.47200","52.70621","0.00169"
"632.92800","52.74417","0.00171"
"633.38400","52.78220","0.00169"
"633.84000","52.82016","0.00202"
"634.29600","52.85826","0.00179"
"634.75200","52.89622","0.00133"
"635.20800","52.93425","0.00174"
"635.66400","52.97221","0.00154"
"636.12000","53.01018","0.00163"
"636.57600","53.04821","0.00169"
"637.03200","53.08623","0.00162"
"637.48800","53.12426","0.00187"
"637.94400","53.16228","0.00174"
"638.40000","53.20019","0.00182"
"638.85600","53.23816","0.00198"
"639.31200","53.27618","0.00181"
"639.76800","53.31421","0.00169"
"640.22400","53.35223","0.00209"
"640.68000","53.39026","0.00185"
"641.13600","53.42823","0.00195"
"641.59200","53.46619","0.00159"
"642.04800","53.50416","0.00166"
"642.50400","53.54218","0.00189"
"642.96000","53.58021","0.00157"
"643.41600","53.61824","0.00193"
"643.87200","53.65627","0.00172"
"644.32800","53.69423","0.00151"
"644.78400","53.73214","0.00191"
"645.24000","53.77023","0.00175"
"645.69600","53.80831","0.00188"
"646.15200","53.84628","0.00202"
"646.60800","53.88424","0.00164"
"647.06400","53.92221","0.00162"
"647.52000","53.96017","0.00136"
"647.97600","53.99820","0.00157"
"648.43200","54.03623","0.00174"
"648.88800","54.07425","0.00160"
"649.34400","54.11216","0.00139"
"649.80000","54.15024","0.00129"
"650.25600","54.18821","0.00163"
"650.71200","54.22624","0.00153"
"651.16800","54.26414","0.00156"
"651.62400","54.30217","0.00140"
"652.08000","54.34019","0.00184"
"652.53600","54.37822","0.00153"
"652.99200","54.41625","0.00166"
"653.44800","54.45428","0.00161"
"653.90400","54.49212","0.00149"
"654.36000","54.53015","0.00171"
"654.81600","54.56823","0.00162"
"655.27200","54.60626","0.00143"
"655.72800","54.64423","0.00159"
"656.18400","54.68225","0.00172"
"656.64000","54.72021","0.00159"
"657.09600","54.75819","0.00177"
"657.55200","54.79621","0.00129"
"658.00800","54.83424","0.00178"
"658.46400","54.87226","0.00186"
"658.92000","54.91023","0.00150"
"659.37600","54.94825","0.00164"
"659.83200","54.98610","0.00189"
"660.28800","55.02419","0.00116"
"660.74400","55.06221","0.00157"
"661.20000","55.10024","0.00132"
"661.65600","55.13821","0.00154"
"662.11200","55.17624","0.00146"
"662.56800","55.21420","0.00146"
"663.02400","55.25216","0.00144"
"663.48000","55.29026","0.00176"
"663.93600","55.32828","0.00167"
"664.39200","55.36625","0.00138"
"664.84800","55.40427","0.00145"
"665.30400","55.44218","0.00144"
"665.76000","55.48026","0.00178"
"666.21600","55.51823","0.00144"
"666.67200","55.55619","0.00163"
"667.12800","55.59422","0.00166"
"667.58400","55.63219","0.00112"
"668.04000","55.67022","0.00161"
"668.49600","55.70818","0.00109"
"668.95200","55.74621","0.00116"
"669.40800","55.78417","0.00178"
"669.86400","55.82220","0.00157"
"670.32000","55.86023","0.00190"
"670.77600","55.89825","0.00153"
"671.23200","55.93628","0.00165"
"671.68800","55.97418","0.00131"
"672.14400","56.01221","0.00159"
"672.60000","56.05018","0.00173"
"673.05600","56.08826","0.00156"
"673.51200","56.12629","0.00166"
"673.96800","56.16426","0.00180"
"674.42400","56.20222","0.00133"
"674.88000","56.24013","0.00138"
"675.33600","56.27822","0.00157"
"675.79200","56.31618","0.00154"
"676.24800","56.35415","0.00141"
"676.70400","56.39223","0.00134"
"676.82600","56.40240","0.00150"