File: Force_trajectories/161221_1/Specimen_RawData_6.csv
End date,"12/21/2016"
Specimen label,"24BG_94"
Maximum Load,"0.28789",N

Time,Extension,Load
(s),(mm),(N)
"0.00000","-0.00006","-0.00020"
"0.36000","0.03001","0.00104"
"0.72000","0.06009","0.00204"
"1.08000","0.09022","0.00284"
"1.44000","0.12024","0.00328"
"1.80000","0.15019","0.00300"
"2.16000","0.18015","0.00384"
"2.52000","0.21022","0.00395"
"2.88000","0.24011","0.00455"
"3.24000","0.27013","0.00439"
"3.60000","0.30020","0.00447"
"3.96000","0.33010","0.00440"
"4.32000","0.36011","0.00456"
"4.68000","0.39019","0.00468"
"5.04000","0.42014","0.00500"
"5.40000","0.45016","0.00486"
"5.76000","0.48017","0.00491"
"6.12000","0.51012","0.00509"
"6.48000","0.54014","0.00516"
"6.84000","0.57021","0.00529"
"7.20000","0.60011","0.00527"
"7.56000","0.63018","0.00514"
"7.92000","0.66020","0.00536"
"8.28000","0.69009","0.00558"
"8.64000","0.72016","0.00538"
"9.00000","0.75018","0.00571"
"9.36000","0.78013","0.00564"
"9.72000","0.81015","0.00514"
"10.08000","0.84016","0.00578"
"10.44000","0.87018","0.00542"
"10.80000","0.90013","0.00587"
"11.16000","0.93015","0.00527"
"11.52000","0.96016","0.00587"
"11.88000","0.99011","0.00577"
"12.24000","1.02025","0.00562"
"12.60000","1.05014","0.00559"
"12.96000","1.08016","0.00577"
"13.32000","1.11017","0.00579"
"13.68000","1.14019","0.00554"
"14.04000","1.17014","0.00610"
"14.40000","1.20016","0.00600"
"14.76000","1.23017","0.00551"
"15.12000","1.26012","0.00595"
"15.48000","1.29014","0.00576"
"15.84000","1.32015","0.00560"
"16.20000","1.35011","0.00617"
"16.56000","1.38024","0.00563"
"16.92000","1.41014","0.00590"
"17.28000","1.44015","0.00555"
"17.64000","1.47016","0.00589"
"18.00000","1.50012","0.00594"
"18.36000","1.53019","0.00596"
"18.72000","1.56015","0.00581"
"19.08000","1.59016","0.00572"
"19.44000","1.62018","0.00564"
"19.80000","1.65013","0.00581"
"20.16000","1.68021","0.00594"
"20.52000","1.71016","0.00594"
"20.88000","1.74017","0.00589"
"21.24000","1.77013","0.00612"
"21.60000","1.80014","0.00582"
"21.96000","1.83022","0.00572"
"22.32000","1.86011","0.00598"
"22.68000","1.89013","0.00590"
"23.04000","1.92020","0.00617"
"23.40000","1.95016","0.00566"
"23.76000","1.98011","0.00581"
"24.12000","2.01018","0.00574"
"24.48000","2.04020","0.00591"
"24.84000","2.07015","0.00609"
"25.20000","2.10023","0.00612"
"25.56000","2.13012","0.00623"
"25.92000","2.16014","0.00568"
"26.28000","2.19015","0.00576"
"26.64000","2.22016","0.00587"
"27.00000","2.25018","0.00583"
"27.36000","2.28019","0.00599"
"27.72000","2.31015","0.00585"
"28.08000","2.34010","0.00577"
"28.44000","2.37018","0.00594"
"28.80000","2.40019","0.00596"
"29.16000","2.43015","0.00577"
"29.52000","2.46022","0.00605"
"29.88000","2.49017","0.00605"
"30.24000","2.52013","0.00589"
"30.60000","2.55020","0.00606"
"30.96000","2.58022","0.00636"
"31.32000","2.61011","0.00571"
"31.68000","2.64019","0.00599"
"32.04000","2.67020","0.00606"
"32.40000","2.70010","0.00581"
"32.76000","2.73023","0.00546"
"33.12000","2.76018","0.00553"
"33.48000","2.79014","0.00571"
"33.84000","2.82021","0.00542"
"34.20000","2.85017","0.00525"
"34.56000","2.88012","0.00520"
"34.92000","2.91020","0.00546"
"35.28000","2.94009","0.00526"
"35.64000","2.97010","0.00563"
"36.00000","3.00018","0.00535"
"36.36000","3.03019","0.00525"
"36.72000","3.06009","0.00536"
"37.08000","3.09016","0.00527"
"37.44000","3.12018","0.00536"
"37.80000","3.15013","0.00564"
"38.16000","3.18015","0.00584"
"38.52000","3.21022","0.00531"
"38.88000","3.24011","0.00534"
"39.24000","3.27019","0.00538"
"39.60000","3.30020","0.00564"
"39.96000","3.33010","0.00520"
"40.32000","3.36017","0.00512"
"40.68000","3.39025","0.00491"
"41.04000","3.42008","0.00497"
"41.40000","3.45016","0.00502"
"41.76000","3.48017","0.00505"
"42.12000","3.51018","0.00480"
"42.48000","3.54014","0.00506"
"42.84000","3.57015","0.00523"
"43.20000","3.60005","0.00541"
"43.56000","3.63018","0.00512"
"43.92000","3.66014","0.00553"
"44.28000","3.69015","0.00518"
"44.64000","3.72016","0.00517"
"45.00000","3.75024","0.00526"
"45.36000","3.78013","0.00517"
"45.72000","3.81015","0.00511"
"46.08000","3.84016","0.00528"
"46.44000","3.87012","0.00524"
"46.80000","3.90019","0.00494"
"47.16000","3.93021","0.00513"
"47.52000","3.96010","0.00507"
"47.88000","3.99011","0.00506"
"48.24000","4.02019","0.00517"
"48.60000","4.05008","0.00499"
"48.96000","4.08016","0.00549"
"49.32000","4.11017","0.00444"
"49.68000","4.14013","0.00510"
"50.04000","4.17014","0.00473"
"50.40000","4.20021","0.00495"
"50.76000","4.23017","0.00510"
"51.12000","4.26018","0.00498"
"51.48000","4.29014","0.00466"
"51.84000","4.32015","0.00502"
"52.20000","4.35017","0.00508"
"52.56000","4.38018","0.00507"
"52.92000","4.41014","0.00506"
"53.28000","4.44015","0.00508"
"53.64000","4.47016","0.00508"
"54.00000","4.50012","0.00524"
"54.36000","4.53013","0.00485"
"54.72000","4.56015","0.00519"
"55.08000","4.59016","0.00522"
"55.44000","4.62018","0.00513"
"55.80000","4.65013","0.00492"
"56.16000","4.68015","0.00500"
"56.52000","4.71010","0.00522"
"56.88000","4.74023","0.00496"
"57.24000","4.77013","0.00518"
"57.60000","4.80020","0.00508"
"57.96000","4.83016","0.00530"
"58.32000","4.86011","0.00496"
"58.68000","4.89013","0.00533"
"59.04000","4.92020","0.00515"
"59.40000","4.95010","0.00516"
"59.76000","4.98017","0.00488"
"60.12000","5.01018","0.00512"
"60.48000","5.04020","0.00493"
"60.84000","5.07009","0.00499"
"61.20000","5.10023","0.00539"
"61.56000","5.13012","0.00517"
"61.92000","5.16014","0.00524"
"62.28000","5.19015","0.00496"
"62.64000","5.22010","0.00511"
"63.00000","5.25012","0.00523"
"63.36000","5.28019","0.00512"
"63.72000","5.31015","0.00511"
"64.08000","5.34016","0.00510"
"64.44000","5.37012","0.00537"
"64.80000","5.40013","0.00523"
"65.16000","5.43015","0.00516"
"65.52000","5.46016","0.00558"
"65.88000","5.49011","0.00533"
"66.24000","5.52019","0.00532"
"66.60000","5.55020","0.00550"
"66.96000","5.58010","0.00525"
"67.32000","5.61011","0.00523"
"67.68000","5.64019","0.00545"
"68.04000","5.67014","0.00546"
"68.40000","5.70015","0.00557"
"68.76000","5.73017","0.00527"
"69.12000","5.76012","0.00519"
"69.48000","5.79014","0.00560"
"69.84000","5.82015","0.00558"
"70.20000","5.85017","0.00524"
"70.56000","5.88018","0.00487"
"70.92000","5.91020","0.00559"
"71.28000","5.94021","0.00515"
"71.64000","5.97016","0.00546"
"72.00000","6.00018","0.00529"
"72.36000","6.03019","0.00551"
"72.72000","6.06015","0.00552"
"73.08000","6.09022","0.00568"
"73.44000","6.12012","0.00561"
"73.80000","6.15013","0.00523"
"74.16000","6.18014","0.00557"
"74.52000","6.21022","0.00561"
"74.88000","6.24017","0.00539"
"75.24000","6.27019","0.00569"
"75.60000","6.30014","0.00569"
"75.96000","6.33016","0.00493"
"76.32000","6.36017","0.00522"
"76.68000","6.39019","0.00540"
"77.04000","6.42008","0.00509"
"77.40000","6.45021","0.00548"
"77.76000","6.48017","0.00542"
"78.12000","6.51018","0.00552"
"78.48000","6.54014","0.00521"
"78.84000","6.57015","0.00561"
"79.20000","6.60011","0.00551"
"79.56000","6.63018","0.00548"
"79.92000","6.66014","0.00551"
"80.28000","6.69015","0.00541"
"80.64000","6.72016","0.00555"
"81.00000","6.75024","0.00535"
"81.36000","6.78007","0.00542"
"81.72000","6.81015","0.00534"
"82.08000","6.84016","0.00542"
"82.44000","6.87012","0.00559"
"82.80000","6.90019","0.00521"
"83.16000","6.93015","0.00531"
"83.52000","6.96016","0.00532"
"83.88000","6.99017","0.00539"
"84.24000","7.02013","0.00541"
"84.60000","7.05008","0.00540"
"84.96000","7.08016","0.00520"
"85.32000","7.11017","0.00531"
"85.68000","7.14013","0.00556"
"86.04000","7.17020","0.00556"
"86.40000","7.20015","0.00547"
"86.76000","7.23011","0.00529"
"87.12000","7.26018","0.00544"
"87.48000","7.29020","0.00565"
"87.84000","7.32009","0.00551"
"88.20000","7.35017","0.00574"
"88.56000","7.38018","0.00575"
"88.92000","7.41014","0.00561"
"89.28000","7.44021","0.00544"
"89.64000","7.47022","0.00568"
"90.00000","7.50012","0.00556"
"90.36000","7.53019","0.00539"
"90.72000","7.56021","0.00543"
"91.08000","7.59010","0.00548"
"91.44000","7.62018","0.00528"
"91.80000","7.65019","0.00562"
"92.16000","7.68015","0.00526"
"92.52000","7.71016","0.00543"
"92.88000","7.74017","0.00568"
"93.24000","7.77007","0.00538"
"93.60000","7.80020","0.00533"
"93.96000","7.83022","0.00572"
"94.32000","7.86011","0.00552"
"94.68000","7.89019","0.00559"
"95.04000","7.92026","0.00569"
"95.40000","7.95009","0.00558"
"95.76000","7.98017","0.00560"
"96.12000","8.01024","0.00539"
"96.48000","8.04014","0.00546"
"96.84000","8.07009","0.00530"
"97.20000","8.10023","0.00575"
"97.56000","8.13012","0.00565"
"97.92000","8.16020","0.00574"
"98.28000","8.19021","0.00551"
"98.64000","8.22010","0.00557"
"99.00000","8.25012","0.00575"
"99.36000","8.28019","0.00533"
"99.72000","8.31009","0.00538"
"100.08000","8.34016","0.00540"
"100.44000","8.37018","0.00560"
"100.80000","8.40019","0.00546"
"101.16000","8.43014","0.00567"
"101.52000","8.46022","0.00576"
"101.88000","8.49011","0.00565"
"102.24000","8.52019","0.00539"
"102.60000","8.55014","0.00599"
"102.96000","8.58016","0.00583"
"103.32000","8.61017","0.00595"
"103.68000","8.64013","0.00561"
"104.04000","8.67014","0.00558"
"104.40000","8.70009","0.00594"
"104.76000","8.73017","0.00563"
"105.12000","8.76018","0.00536"
"105.48000","8.79008","0.00527"
"105.84000","8.82015","0.00559"
"106.20000","8.85017","0.00541"
"106.56000","8.88018","0.00561"
"106.92000","8.91014","0.00535"
"107.28000","8.94015","0.00549"
"107.64000","8.97016","0.00546"
"108.00000","9.00018","0.00541"
"108.36000","9.03013","0.00579"
"108.72000","9.06015","0.00592"
"109.08000","9.09016","0.00521"
"109.44000","9.12012","0.00590"
"109.80000","9.15013","0.00563"
"110.16000","9.18014","0.00568"
"110.52000","9.21010","0.00554"
"110.88000","9.24017","0.00568"
"111.24000","9.27019","0.00566"
"111.60000","9.30014","0.00573"
"111.96000","9.33010","0.00558"
"112.32000","9.36011","0.00569"
"112.68000","9.39019","0.00556"
"113.04000","9.42014","0.00572"
"113.40000","9.45021","0.00560"
"113.76000","9.48017","0.00602"
"114.12000","9.51018","0.00545"
"114.48000","9.54014","0.00588"
"114.84000","9.57015","0.00588"
"115.20000","9.60017","0.00607"
"115.56000","9.63018","0.00605"
"115.92000","9.66014","0.00583"
"116.28000","9.69015","0.00593"
"116.64000","9.72016","0.00620"
"117.00000","9.75018","0.00608"
"117.36000","9.78013","0.00593"
"117.72000","9.81021","0.00593"
"118.08000","9.84010","0.00616"
"118.44000","9.87012","0.00599"
"118.80000","9.90019","0.00605"
"119.16000","9.93009","0.00595"
"119.52000","9.96016","0.00628"
"119.88000","9.99023","0.00611"
"120.24000","10.02013","0.00581"
"120.60000","10.05014","0.00583"
"120.96000","10.08010","0.00611"
"121.32000","10.11017","0.00646"
"121.68000","10.14012","0.00605"
"122.04000","10.17020","0.00604"
"122.40000","10.20015","0.00602"
"122.76000","10.23011","0.00636"
"123.12000","10.26018","0.00624"
"123.48000","10.29014","0.00613"
"123.84000","10.32015","0.00634"
"124.20000","10.35023","0.00613"
"124.56000","10.38018","0.00602"
"124.92000","10.41014","0.00636"
"125.28000","10.44015","0.00601"
"125.64000","10.47016","0.00662"
"126.00000","10.50012","0.00585"
"126.36000","10.53019","0.00616"
"126.72000","10.56015","0.00632"
"127.08000","10.59010","0.00614"
"127.44000","10.62018","0.00582"
"127.80000","10.65019","0.00584"
"128.16000","10.68014","0.00619"
"128.52000","10.71022","0.00628"
"128.88000","10.74011","0.00636"
"129.24000","10.77013","0.00619"
"129.60000","10.80014","0.00599"
"129.96000","10.83016","0.00647"
"130.32000","10.86017","0.00662"
"130.68000","10.89019","0.00655"
"131.04000","10.92020","0.00637"
"131.40000","10.95015","0.00649"
"131.76000","10.98017","0.00651"
"132.12000","11.01018","0.00601"
"132.48000","11.04014","0.00651"
"132.84000","11.07015","0.00642"
"133.20000","11.10023","0.00654"
"133.56000","11.13006","0.00612"
"133.92000","11.16019","0.00648"
"134.28000","11.19021","0.00648"
"134.64000","11.22010","0.00656"
"135.00000","11.25018","0.00627"
"135.36000","11.28019","0.00670"
"135.72000","11.31009","0.00639"
"136.08000","11.34016","0.00645"
"136.44000","11.37017","0.00674"
"136.80000","11.40013","0.00675"
"137.16000","11.43014","0.00648"
"137.52000","11.46022","0.00670"
"137.88000","11.49005","0.00659"
"138.24000","11.52019","0.00639"
"138.60000","11.55014","0.00656"
"138.96000","11.58016","0.00641"
"139.32000","11.61017","0.00666"
"139.68000","11.64019","0.00712"
"140.04000","11.67014","0.00695"
"140.40000","11.70015","0.00654"
"140.76000","11.73017","0.00690"
"141.12000","11.76018","0.00644"
"141.48000","11.79020","0.00663"
"141.84000","11.82021","0.00684"
"142.20000","11.85011","0.00674"
"142.56000","11.88018","0.00672"
"142.92000","11.91019","0.00679"
"143.28000","11.94009","0.00683"
"143.64000","11.97016","0.00703"
"144.00000","12.00018","0.00681"
"144.36000","12.03007","0.00705"
"144.72000","12.06021","0.00669"
"145.08000","12.09016","0.00708"
"145.44000","12.12018","0.00691"
"145.80000","12.15013","0.00709"
"146.16000","12.18014","0.00704"
"146.52000","12.21004","0.00705"
"146.88000","12.24017","0.00693"
"147.24000","12.27019","0.00667"
"147.60000","12.30008","0.00718"
"147.96000","12.33016","0.00694"
"148.32000","12.36023","0.00713"
"148.68000","12.39012","0.00701"
"149.04000","12.42014","0.00709"
"149.40000","12.45015","0.00671"
"149.76000","12.48011","0.00707"
"150.12000","12.51012","0.00715"
"150.48000","12.54020","0.00739"
"150.84000","12.57009","0.00692"
"151.20000","12.60017","0.00694"
"151.56000","12.63018","0.00724"
"151.92000","12.66007","0.00745"
"152.28000","12.69021","0.00705"
"152.64000","12.72016","0.00761"
"153.00000","12.75012","0.00718"
"153.36000","12.78013","0.00752"
"153.72000","12.81021","0.00731"
"154.08000","12.84016","0.00729"
"154.44000","12.87017","0.00764"
"154.80000","12.90013","0.00761"
"155.16000","12.93008","0.00752"
"155.52000","12.96016","0.00777"
"155.88000","12.99017","0.00761"
"156.24000","13.02013","0.00748"
"156.60000","13.05020","0.00744"
"156.96000","13.08016","0.00763"
"157.32000","13.11017","0.00743"
"157.68000","13.14012","0.00755"
"158.04000","13.17020","0.00772"
"158.40000","13.20010","0.00753"
"158.76000","13.23017","0.00766"
"159.12000","13.26018","0.00747"
"159.48000","13.29014","0.00756"
"159.84000","13.32015","0.00776"
"160.20000","13.35023","0.00756"
"160.56000","13.38012","0.00764"
"160.92000","13.41019","0.00775"
"161.28000","13.44015","0.00768"
"161.64000","13.47016","0.00814"
"162.00000","13.50012","0.00747"
"162.36000","13.53019","0.00798"
"162.72000","13.56015","0.00760"
"163.08000","13.59016","0.00802"
"163.44000","13.62012","0.00777"
"163.80000","13.65013","0.00795"
"164.16000","13.68015","0.00767"
"164.52000","13.71016","0.00805"
"164.88000","13.74011","0.00764"
"165.24000","13.77019","0.00772"
"165.60000","13.80014","0.00801"
"165.96000","13.83016","0.00786"
"166.32000","13.86011","0.00770"
"166.68000","13.89018","0.00815"
"167.04000","13.92014","0.00743"
"167.40000","13.95015","0.00765"
"167.76000","13.98017","0.00806"
"168.12000","14.01012","0.00808"
"168.48000","14.04014","0.00793"
"168.84000","14.07015","0.00786"
"169.20000","14.10011","0.00794"
"169.56000","14.13018","0.00779"
"169.92000","14.16020","0.00792"
"170.28000","14.19009","0.00813"
"170.64000","14.22010","0.00806"
"171.00000","14.25018","0.00805"
"171.36000","14.28013","0.00805"
"171.72000","14.31021","0.00838"
"172.08000","14.34016","0.00797"
"172.44000","14.37012","0.00824"
"172.80000","14.40019","0.00827"
"173.16000","14.43015","0.00855"
"173.52000","14.46016","0.00818"
"173.88000","14.49017","0.00803"
"174.24000","14.52019","0.00824"
"174.60000","14.55014","0.00821"
"174.96000","14.58016","0.00835"
"175.32000","14.61017","0.00825"
"175.68000","14.64019","0.00842"
"176.04000","14.67014","0.00877"
"176.40000","14.70021","0.00896"
"176.76000","14.73017","0.00848"
"177.12000","14.76012","0.00887"
"177.48000","14.79014","0.00897"
"177.84000","14.82021","0.00860"
"178.20000","14.85017","0.00856"
"178.56000","14.88018","0.00861"
"178.92000","14.91013","0.00891"
"179.28000","14.94015","0.00881"
"179.64000","14.97022","0.00895"
"180.00000","15.00018","0.00902"
"180.36000","15.03013","0.00883"
"180.72000","15.06021","0.00940"
"181.08000","15.09016","0.00946"
"181.44000","15.12018","0.00939"
"181.80000","15.15013","0.00938"
"182.16000","15.18014","0.00922"
"182.52000","15.21010","0.00934"
"182.88000","15.24011","0.00884"
"183.24000","15.27013","0.00942"
"183.60000","15.30014","0.00978"
"183.96000","15.33022","0.00973"
"184.32000","15.36017","0.00981"
"184.68000","15.39013","0.00961"
"185.04000","15.42014","0.00969"
"185.40000","15.45015","0.00983"
"185.76000","15.48011","0.01019"
"186.12000","15.51018","0.00987"
"186.48000","15.54020","0.00974"
"186.84000","15.57015","0.00992"
"187.20000","15.60017","0.00949"
"187.56000","15.63018","0.00974"
"187.92000","15.66019","0.00985"
"188.28000","15.69015","0.00997"
"188.64000","15.72016","0.01002"
"189.00000","15.75012","0.01021"
"189.36000","15.78013","0.01001"
"189.72000","15.81021","0.01058"
"190.08000","15.84010","0.01023"
"190.44000","15.87011","0.01047"
"190.80000","15.90019","0.01059"
"191.16000","15.93014","0.01091"
"191.52000","15.96016","0.01069"
"191.88000","15.99017","0.01163"
"192.24000","16.02013","0.01076"
"192.60000","16.05020","0.01112"
"192.96000","16.08022","0.01148"
"193.32000","16.11011","0.01172"
"193.68000","16.14012","0.01092"
"194.04000","16.17020","0.01162"
"194.40000","16.20009","0.01166"
"194.76000","16.23017","0.01163"
"195.12000","16.26024","0.01233"
"195.48000","16.29014","0.01211"
"195.84000","16.32015","0.01227"
"196.20000","16.35016","0.01278"
"196.56000","16.38012","0.01240"
"196.92000","16.41014","0.01258"
"197.28000","16.44015","0.01264"
"197.64000","16.47016","0.01287"
"198.00000","16.50012","0.01245"
"198.36000","16.53025","0.01254"
"198.72000","16.56015","0.01295"
"199.08000","16.59016","0.01314"
"199.44000","16.62017","0.01348"
"199.80000","16.65013","0.01354"
"200.16000","16.68014","0.01301"
"200.52000","16.71016","0.01372"
"200.88000","16.74011","0.01356"
"201.24000","16.77019","0.01383"
"201.60000","16.80014","0.01417"
"201.96000","16.83016","0.01460"
"202.32000","16.86011","0.01437"
"202.68000","16.89018","0.01483"
"203.04000","16.92014","0.01517"
"203.40000","16.95021","0.01521"
"203.76000","16.98017","0.01565"
"204.12000","17.01012","0.01535"
"204.48000","17.04014","0.01476"
"204.84000","17.07015","0.01507"
"205.20000","17.10011","0.01546"
"205.56000","17.13018","0.01530"
"205.92000","17.16014","0.01541"
"206.28000","17.19015","0.01580"
"206.64000","17.22016","0.01621"
"207.00000","17.25018","0.01664"
"207.36000","17.28013","0.01666"
"207.72000","17.31021","0.01644"
"208.08000","17.34016","0.01725"
"208.44000","17.37011","0.01715"
"208.80000","17.40013","0.01732"
"209.16000","17.43014","0.01764"
"209.52000","17.46010","0.01776"
"209.88000","17.49017","0.01722"
"210.24000","17.52019","0.01756"
"210.60000","17.55014","0.01690"
"210.96000","17.58015","0.01761"
"211.32000","17.61017","0.01792"
"211.68000","17.64013","0.01822"
"212.04000","17.67014","0.01815"
"212.40000","17.70021","0.01894"
"212.76000","17.73011","0.01904"
"213.12000","17.76012","0.01897"
"213.48000","17.79014","0.01965"
"213.84000","17.82015","0.01983"
"214.20000","17.85011","0.02038"
"214.56000","17.88018","0.02086"
"214.92000","17.91013","0.02173"
"215.28000","17.94015","0.02172"
"215.64000","17.97016","0.02261"
"216.00000","18.00018","0.02274"
"216.36000","18.03013","0.02289"
"216.72000","18.06021","0.02304"
"217.08000","18.09016","0.02334"
"217.44000","18.12017","0.02431"
"217.80000","18.15019","0.02438"
"218.16000","18.18020","0.02469"
"218.52000","18.21016","0.02484"
"218.88000","18.24017","0.02513"
"219.24000","18.27013","0.02460"
"219.60000","18.30008","0.02490"
"219.96000","18.33022","0.02570"
"220.32000","18.36017","0.02614"
"220.68000","18.39013","0.02672"
"221.04000","18.42020","0.02772"
"221.40000","18.45009","0.02813"
"221.76000","18.48011","0.02843"
"222.12000","18.51012","0.02917"
"222.48000","18.54020","0.02966"
"222.84000","18.57015","0.03100"
"223.20000","18.60023","0.03004"
"223.56000","18.63012","0.03021"
"223.92000","18.66013","0.03153"
"224.28000","18.69015","0.03212"
"224.64000","18.72016","0.03296"
"225.00000","18.75018","0.03370"
"225.36000","18.78019","0.03416"
"225.72000","18.81015","0.03491"
"226.08000","18.84016","0.03556"
"226.44000","18.87017","0.03622"
"226.80000","18.90013","0.03693"
"227.16000","18.93014","0.03748"
"227.52000","18.96022","0.03815"
"227.88000","18.99017","0.03880"
"228.24000","19.02013","0.04001"
"228.60000","19.05020","0.04046"
"228.96000","19.08015","0.04198"
"229.32000","19.11011","0.04247"
"229.68000","19.14018","0.04344"
"230.04000","19.17014","0.04378"
"230.40000","19.20009","0.04502"
"230.76000","19.23023","0.04525"
"231.12000","19.26018","0.04629"
"231.48000","19.29014","0.04693"
"231.84000","19.32021","0.04834"
"232.20000","19.35017","0.04787"
"232.56000","19.38012","0.04827"
"232.92000","19.41019","0.04952"
"233.28000","19.44015","0.05002"
"233.64000","19.47016","0.05015"
"234.00000","19.50018","0.05088"
"234.36000","19.53019","0.05082"
"234.72000","19.56014","0.05084"
"235.08000","19.59016","0.05097"
"235.44000","19.62017","0.05116"
"235.80000","19.65019","0.05159"
"236.16000","19.68020","0.05195"
"236.52000","19.71016","0.05231"
"236.88000","19.74011","0.05260"
"237.24000","19.77025","0.05257"
"237.60000","19.80014","0.05341"
"237.96000","19.83016","0.05282"
"238.32000","19.86017","0.05300"
"238.68000","19.89018","0.05173"
"239.04000","19.92008","0.03943"
"239.40000","19.95021","0.03975"
"239.76000","19.98017","0.04057"
"240.12000","20.01012","0.04039"
"240.48000","20.04020","0.04113"
"240.84000","20.07015","0.04216"
"241.20000","20.10010","0.04290"
"241.56000","20.13024","0.04279"
"241.92000","20.16014","0.04286"
"242.28000","20.19021","0.04104"
"242.64000","20.22016","0.04099"
"243.00000","20.25018","0.04127"
"243.36000","20.28013","0.04174"
"243.72000","20.31021","0.04252"
"244.08000","20.34022","0.04116"
"244.44000","20.37011","0.04029"
"244.80000","20.40019","0.04053"
"245.16000","20.43020","0.03989"
"245.52000","20.46004","0.04023"
"245.88000","20.49023","0.04017"
"246.24000","20.52019","0.04129"
"246.60000","20.55008","0.04196"
"246.96000","20.58015","0.04198"
"247.32000","20.61023","0.04320"
"247.68000","20.64012","0.04355"
"248.04000","20.67020","0.04462"
"248.40000","20.70021","0.04553"
"248.76000","20.73011","0.04630"
"249.12000","20.76012","0.04607"
"249.48000","20.79020","0.04713"
"249.84000","20.82009","0.04774"
"250.20000","20.85016","0.04831"
"250.56000","20.88018","0.04788"
"250.92000","20.91007","0.04641"
"251.28000","20.94015","0.04643"
"251.64000","20.97016","0.04626"
"252.00000","21.00011","0.04544"
"252.36000","21.03013","0.04571"
"252.72000","21.06020","0.04290"
"253.08000","21.09010","0.04360"
"253.44000","21.12017","0.04412"
"253.80000","21.15019","0.04482"
"254.16000","21.18014","0.04538"
"254.52000","21.21016","0.04632"
"254.88000","21.24017","0.04681"
"255.24000","21.27007","0.04736"
"255.60000","21.30014","0.04679"
"255.96000","21.33021","0.04827"
"256.32000","21.36011","0.04808"
"256.68000","21.39018","0.04893"
"257.04000","21.42020","0.04929"
"257.40000","21.45015","0.04852"
"257.76000","21.48023","0.04931"
"258.12000","21.51012","0.04988"
"258.48000","21.54013","0.04800"
"258.84000","21.57015","0.04876"
"259.20000","21.60022","0.04863"
"259.56000","21.63012","0.04970"
"259.92000","21.66019","0.05083"
"260.28000","21.69015","0.05183"
"260.64000","21.72016","0.05240"
"261.00000","21.75012","0.05272"
"261.36000","21.78013","0.05270"
"261.72000","21.81014","0.05355"
"262.08000","21.84022","0.05359"
"262.44000","21.87012","0.05477"
"262.80000","21.90019","0.05553"
"263.16000","21.93014","0.05588"
"263.52000","21.96016","0.05671"
"263.88000","21.99011","0.05696"
"264.24000","22.02019","0.05705"
"264.60000","22.05014","0.05609"
"264.96000","22.08015","0.05596"
"265.32000","22.11011","0.05533"
"265.68000","22.14018","0.05625"
"266.04000","22.17014","0.05681"
"266.40000","22.20021","0.05798"
"266.76000","22.23011","0.05784"
"267.12000","22.26018","0.05863"
"267.48000","22.29014","0.05940"
"267.84000","22.32021","0.06032"
"268.20000","22.35011","0.06221"
"268.56000","22.38012","0.06295"
"268.92000","22.41019","0.06361"
"269.28000","22.44015","0.06370"
"269.64000","22.47016","0.06351"
"270.00000","22.50018","0.06079"
"270.36000","22.53013","0.06219"
"270.72000","22.56015","0.06464"
"271.08000","22.59016","0.06677"
"271.44000","22.62011","0.06494"
"271.80000","22.65013","0.06101"
"272.16000","22.68020","0.06267"
"272.52000","22.71016","0.06509"
"272.88000","22.74011","0.06574"
"273.24000","22.77019","0.06532"
"273.60000","22.80014","0.06629"
"273.96000","22.83015","0.06728"
"274.32000","22.86017","0.06841"
"274.68000","22.89018","0.07155"
"275.04000","22.92014","0.07353"
"275.40000","22.95015","0.07545"
"275.76000","22.98017","0.06406"
"276.12000","23.01018","0.05939"
"276.48000","23.04020","0.05941"
"276.84000","23.07015","0.05925"
"277.20000","23.10016","0.05971"
"277.56000","23.13012","0.06190"
"277.92000","23.16007","0.06353"
"278.28000","23.19015","0.06323"
"278.64000","23.22022","0.06302"
"279.00000","23.25018","0.06658"
"279.36000","23.28013","0.06960"
"279.72000","23.31021","0.07092"
"280.08000","23.34016","0.07178"
"280.44000","23.37017","0.07527"
"280.80000","23.40025","0.07772"
"281.16000","23.43020","0.07860"
"281.52000","23.46010","0.08032"
"281.88000","23.49023","0.08171"
"282.24000","23.52012","0.08241"
"282.60000","23.55014","0.08300"
"282.96000","23.58016","0.08514"
"283.32000","23.61017","0.08728"
"283.68000","23.64012","0.08829"
"284.04000","23.67020","0.08882"
"284.40000","23.70015","0.08982"
"284.76000","23.73011","0.09160"
"285.12000","23.76018","0.09406"
"285.48000","23.79013","0.09575"
"285.84000","23.82009","0.09765"
"286.20000","23.85016","0.09826"
"286.56000","23.88018","0.09926"
"286.92000","23.91013","0.10140"
"287.28000","23.94020","0.10162"
"287.64000","23.97022","0.10358"
"288.00000","24.00012","0.10578"
"288.36000","24.03019","0.10575"
"288.72000","24.06014","0.10806"
"289.08000","24.09010","0.10930"
"289.44000","24.12017","0.11229"
"289.80000","24.15019","0.11430"
"290.16000","24.18014","0.11749"
"290.52000","24.21016","0.12093"
"290.88000","24.24017","0.12387"
"291.24000","24.27018","0.12675"
"291.60000","24.30020","0.13004"
"291.96000","24.33015","0.13125"
"292.32000","24.36011","0.13363"
"292.68000","24.39018","0.13561"
"293.04000","24.42020","0.13770"
"293.40000","24.45015","0.13800"
"293.76000","24.48017","0.14005"
"294.12000","24.51012","0.14202"
"294.48000","24.54014","0.14393"
"294.84000","24.57015","0.14626"
"295.20000","24.60023","0.14914"
"295.56000","24.63012","0.15071"
"295.92000","24.66019","0.15277"
"296.28000","24.69021","0.15439"
"296.64000","24.72016","0.15437"
"297.00000","24.75018","0.15636"
"297.36000","24.78019","0.15772"
"297.72000","24.81009","0.15995"
"298.08000","24.84022","0.16254"
"298.44000","24.87023","0.16658"
"298.80000","24.90013","0.17031"
"299.16000","24.93014","0.17367"
"299.52000","24.96016","0.17824"
"299.88000","24.99011","0.18214"
"300.24000","25.02019","0.18550"
"300.60000","25.05014","0.18882"
"300.96000","25.08015","0.19077"
"301.32000","25.11017","0.19288"
"301.68000","25.14018","0.19531"
"302.04000","25.17008","0.19678"
"302.40000","25.20021","0.19807"
"302.76000","25.23017","0.19949"
"303.12000","25.26018","0.20204"
"303.48000","25.29008","0.20474"
"303.84000","25.32021","0.20738"
"304.20000","25.35011","0.20953"
"304.56000","25.38018","0.21183"
"304.92000","25.41019","0.21471"
"305.28000","25.44015","0.21664"
"305.64000","25.47016","0.21819"
"306.00000","25.50024","0.22150"
"306.36000","25.53007","0.22449"
"306.72000","25.56020","0.22725"
"307.08000","25.59016","0.22962"
"307.44000","25.62017","0.23113"
"307.80000","25.65013","0.23303"
"308.16000","25.68020","0.23504"
"308.52000","25.71010","0.23701"
"308.88000","25.74017","0.23891"
"309.24000","25.77013","0.24153"
"309.60000","25.80014","0.24566"
"309.96000","25.83015","0.24821"
"310.32000","25.86017","0.25168"
"310.68000","25.89013","0.25474"
"311.04000","25.92014","0.25706"
"311.40000","25.95015","0.26145"
"311.76000","25.98011","0.26579"
"312.12000","26.01012","0.26773"
"312.48000","26.04013","0.27304"
"312.84000","26.07015","0.27894"
"313.20000","26.10017","0.28305"
"313.56000","26.13018","0.27020"
"313.92000","26.16013","0.27058"
"314.28000","26.19015","0.27320"
"314.64000","26.22016","0.17119"
"315.00000","26.25012","0.16082"
"315.36000","26.28013","0.17137"
"315.72000","26.31021","0.16198"
"316.08000","26.34010","0.15925"
"316.44000","26.37012","0.16602"
"316.80000","26.40019","0.17233"
"317.16000","26.43014","0.16729"
"317.52000","26.46016","0.17599"
"317.88000","26.49017","0.18308"
"318.24000","26.52019","0.18249"
"318.60000","26.55020","0.18818"
"318.96000","26.58015","0.19137"
"319.32000","26.61011","0.19152"
"319.68000","26.64013","0.19632"
"320.04000","26.67014","0.19884"
"320.40000","26.70015","0.20090"
"320.76000","26.73017","0.20626"
"321.12000","26.76018","0.20800"
"321.48000","26.79014","0.21066"
"321.84000","26.82015","0.21329"
"322.20000","26.85023","0.21431"
"322.56000","26.88012","0.21748"
"322.92000","26.91013","0.21946"
"323.28000","26.94015","0.22210"
"323.64000","26.97016","0.22012"
"324.00000","27.00012","0.22271"
"324.36000","27.03019","0.22677"
"324.72000","27.06015","0.22826"
"325.08000","27.09016","0.23110"
"325.44000","27.12017","0.23346"
"325.80000","27.15013","0.23481"
"326.16000","27.18015","0.23675"
"326.52000","27.21022","0.23938"
"326.88000","27.24017","0.24307"
"327.24000","27.27013","0.24619"
"327.60000","27.30014","0.24866"
"327.96000","27.33015","0.25116"
"328.32000","27.36017","0.25283"
"328.68000","27.39018","0.25480"
"329.04000","27.42014","0.25757"
"329.40000","27.45015","0.25943"
"329.76000","27.48017","0.26346"
"330.12000","27.51012","0.26588"
"330.48000","27.54008","0.26849"
"330.84000","27.57015","0.27137"
"331.20000","27.60011","0.27375"
"331.56000","27.63012","0.27699"
"331.92000","27.66019","0.27915"
"332.28000","27.69015","0.28248"
"332.64000","27.72016","0.28424"
"333.00000","27.75018","0.28587"
"333.36000","27.78013","0.28620"
"333.72000","27.81015","0.28725"
"334.08000","27.84016","0.27664"
"334.44000","27.87012","0.04508"
"334.80000","27.90013","0.04897"
"335.16000","27.93020","0.05881"
"335.52000","27.96016","0.04611"
"335.88000","27.99011","0.08330"
"336.24000","28.02012","0.04570"
"336.60000","28.05014","0.04805"
"336.96000","28.08016","0.05017"
"337.32000","28.11017","0.04680"
"337.68000","28.14018","0.07711"
"338.04000","28.17008","0.05179"
"338.40000","28.20015","0.06236"
"338.76000","28.23017","0.05529"
"339.12000","28.26018","0.05378"
"339.48000","28.29020","0.07984"
"339.84000","28.32021","0.05815"
"340.20000","28.35010","0.06972"
"340.56000","28.38018","0.06939"
"340.92000","28.41019","0.06419"
"341.28000","28.44009","0.08464"
"341.64000","28.47016","0.07292"
"342.00000","28.50024","0.07544"
"342.36000","28.53013","0.08745"
"342.72000","28.56021","0.08020"
"343.08000","28.59016","0.08318"
"343.44000","28.62017","0.08992"
"343.80000","28.65019","0.08449"
"344.16000","28.68020","0.08810"
"344.52000","28.71010","0.09253"
"344.88000","28.74011","0.08841"
"345.24000","28.77013","0.09293"
"345.60000","28.80014","0.09711"
"345.96000","28.83015","0.09340"
"346.32000","28.86023","0.09740"
"346.68000","28.89013","0.10280"
"347.04000","28.92014","0.09922"
"347.40000","28.95015","0.10147"
"347.76000","28.98017","0.10732"
"348.12000","29.01012","0.10488"
"348.48000","29.04020","0.10494"
"348.84000","29.07009","0.10985"
"349.20000","29.10016","0.10989"
"349.56000","29.13018","0.10904"
"349.92000","29.16007","0.11263"
"350.28000","29.19015","0.11639"
"350.64000","29.22022","0.11522"
"351.00000","29.25011","0.11582"
"351.36000","29.28019","0.12021"
"351.72000","29.31020","0.12243"
"352.08000","29.34016","0.12123"
"352.44000","29.37017","0.12379"
"352.80000","29.40013","0.12694"
"353.16000","29.43008","0.03145"
"353.52000","29.46016","0.04285"
"353.88000","29.49017","0.04085"
"354.24000","29.52013","0.03874"
"354.60000","29.55014","0.04079"
"354.96000","29.58016","0.04608"
"355.32000","29.61011","0.03920"
"355.68000","29.64007","0.04289"
"356.04000","29.67020","0.04513"
"356.40000","29.70015","0.04329"
"356.76000","29.73017","0.04341"
"357.12000","29.76018","0.04619"
"357.48000","29.79014","0.04804"
"357.84000","29.82015","0.04562"
"358.20000","29.85023","0.04936"
"358.56000","29.88012","0.04923"
"358.92000","29.91019","0.04872"
"359.28000","29.94015","0.04989"
"359.64000","29.97010","0.05158"
"360.00000","30.00012","0.05249"
"360.36000","30.03019","0.05183"
"360.72000","30.06015","0.05300"
"361.08000","30.09022","0.05431"
"361.44000","30.12012","0.05296"
"361.80000","30.15013","0.05527"
"362.16000","30.18020","0.05495"
"362.52000","30.21016","0.05660"
"362.88000","30.24005","0.05733"
"363.24000","30.27019","0.05722"
"363.60000","30.30014","0.05948"
"363.96000","30.33015","0.05854"
"364.32000","30.36011","0.06051"
"364.68000","30.39018","0.06174"
"365.04000","30.42014","0.06155"
"365.40000","30.45021","0.06307"
"365.76000","30.48017","0.06315"
"366.12000","30.51012","0.06489"
"366.48000","30.54013","0.06626"
"366.84000","30.57021","0.06719"
"367.20000","30.60011","0.06915"
"367.56000","30.63018","0.06980"
"367.92000","30.66013","0.07137"
"368.28000","30.69015","0.07305"
"368.64000","30.72010","0.07433"
"369.00000","30.75024","0.07574"
"369.36000","30.78013","0.07670"
"369.72000","30.81014","0.07713"
"370.08000","30.84016","0.07830"
"370.44000","30.87011","0.07960"
"370.80000","30.90013","0.07994"
"371.16000","30.93015","0.07446"
"371.52000","30.96016","0.07274"
"371.88000","30.99017","0.07384"
"372.24000","31.02013","0.07740"
"372.60000","31.05014","0.07920"
"372.96000","31.08010","0.07969"
"373.32000","31.11017","0.08085"
"373.68000","31.14012","0.08208"
"374.04000","31.17014","0.08333"
"374.40000","31.20015","0.08368"
"374.76000","31.23017","0.08474"
"375.12000","31.26012","0.08572"
"375.48000","31.29019","0.08628"
"375.84000","31.32021","0.08687"
"376.20000","31.35016","0.08735"
"376.56000","31.38018","0.08854"
"376.92000","31.41013","0.08980"
"377.28000","31.44015","0.09013"
"377.64000","31.47022","0.09086"
"378.00000","31.50012","0.09194"
"378.36000","31.53013","0.09257"
"378.72000","31.56021","0.09312"
"379.08000","31.59016","0.09433"
"379.44000","31.62017","0.09585"
"379.80000","31.65013","0.09553"
"380.16000","31.68014","0.09671"
"380.52000","31.71016","0.09776"
"380.88000","31.74017","0.09828"
"381.24000","31.77019","0.09936"
"381.60000","31.80020","0.10065"
"381.96000","31.83015","0.10079"
"382.32000","31.86017","0.10226"
"382.68000","31.89012","0.09946"
"383.04000","31.92019","0.10082"
"383.40000","31.95015","0.10207"
"383.76000","31.98016","0.10275"
"384.12000","32.01018","0.10340"
"384.48000","32.04020","0.10389"
"384.84000","32.07021","0.10479"
"385.20000","32.10016","0.10531"
"385.56000","32.13018","0.10562"
"385.92000","32.16013","0.10599"
"386.28000","32.19021","0.10640"
"386.64000","32.22016","0.10718"
"387.00000","32.25011","0.10772"
"387.36000","32.28025","0.10844"
"387.72000","32.31014","0.10861"
"388.08000","32.34016","0.10928"
"388.44000","32.37017","0.11020"
"388.80000","32.40019","0.11071"
"389.16000","32.43014","0.11141"
"389.52000","32.46016","0.11210"
"389.88000","32.49017","0.11180"
"390.24000","32.52012","0.11180"
"390.60000","32.55020","0.11270"
"390.96000","32.58021","0.11347"
"391.32000","32.61011","0.11397"
"391.68000","32.64018","0.11496"
"392.04000","32.67014","0.11554"
"392.40000","32.70009","0.11622"
"392.76000","32.73017","0.11675"
"393.12000","32.76018","0.11763"
"393.48000","32.79013","0.11787"
"393.84000","32.82021","0.11864"
"394.20000","32.85016","0.11944"
"394.56000","32.88018","0.12030"
"394.92000","32.91019","0.12044"
"395.28000","32.94020","0.12068"
"395.64000","32.97016","0.12145"
"396.00000","33.00018","0.12229"
"396.36000","33.03019","0.12293"
"396.72000","33.06015","0.12377"
"397.08000","33.09016","0.12486"
"397.44000","33.12017","0.12571"
"397.80000","33.15012","0.12616"
"398.16000","33.18014","0.12735"
"398.52000","33.21016","0.12798"
"398.88000","33.24011","0.12841"
"399.24000","33.27018","0.12922"
"399.60000","33.30014","0.12948"
"399.96000","33.33015","0.12997"
"400.32000","33.36017","0.13059"
"400.68000","33.39018","0.13166"
"401.04000","33.42007","0.13213"
"401.40000","33.45021","0.13238"
"401.76000","33.48022","0.13318"
"402.12000","33.51018","0.13349"
"402.48000","33.54013","0.13420"
"402.84000","33.57021","0.13353"
"403.20000","33.60010","0.13368"
"403.56000","33.63018","0.13406"
"403.92000","33.66013","0.13451"
"404.28000","33.69015","0.13476"
"404.64000","33.72016","0.13519"
"405.00000","33.75024","0.13523"
"405.36000","33.78007","0.13582"
"405.72000","33.81014","0.13613"
"406.08000","33.84016","0.13687"
"406.44000","33.87011","0.13737"
"406.80000","33.90013","0.13701"
"407.16000","33.93020","0.13763"
"407.52000","33.96010","0.13790"
"407.88000","33.99023","0.13778"
"408.24000","34.02013","0.13809"
"408.60000","34.05014","0.13918"
"408.96000","34.08009","0.13993"
"409.32000","34.11016","0.13986"
"409.68000","34.14012","0.14055"
"410.04000","34.17020","0.14085"
"410.40000","34.20015","0.14215"
"410.76000","34.23016","0.14291"
"411.12000","34.26012","0.14379"
"411.48000","34.29020","0.14482"
"411.84000","34.32009","0.14544"
"412.20000","34.35016","0.00932"
"412.56000","34.38012","0.00679"
"412.92000","34.41013","0.00707"
"413.28000","34.44014","0.00588"
"413.64000","34.47010","0.00727"
"414.00000","34.50011","0.00563"
"414.36000","34.53013","0.00610"
"414.72000","34.56014","0.00667"
"415.08000","34.59016","0.00660"
"415.44000","34.62017","0.00576"
"415.80000","34.65013","0.00625"
"416.16000","34.68014","0.00713"
"416.52000","34.71016","0.00637"
"416.88000","34.74017","0.00584"
"417.24000","34.77012","0.00667"
"417.60000","34.80014","0.00633"
"417.96000","34.83015","0.00617"
"418.32000","34.86017","0.00663"
"418.68000","34.89018","0.00642"
"419.04000","34.92020","0.00586"
"419.40000","34.95009","0.00599"
"419.76000","34.98017","0.00652"
"420.12000","35.01012","0.00600"
"420.48000","35.04013","0.00623"
"420.84000","35.07015","0.00689"
"421.20000","35.10016","0.00607"
"421.56000","35.13018","0.00592"
"421.92000","35.16019","0.00649"
"422.28000","35.19015","0.00689"
"422.64000","35.22016","0.00595"
"423.00000","35.25011","0.00627"
"423.36000","35.28019","0.00671"
"423.72000","35.31014","0.00574"
"424.08000","35.34016","0.00634"
"424.44000","35.37011","0.00659"
"424.80000","35.40018","0.00634"
"425.16000","35.43014","0.00603"
"425.52000","35.46022","0.00610"
"425.88000","35.49017","0.00632"
"426.24000","35.52013","0.00611"
"426.60000","35.55020","0.00669"
"426.96000","35.58015","0.00680"
"427.32000","35.61011","0.00649"
"427.68000","35.64018","0.00650"
"428.04000","35.67007","0.00681"
"428.40000","35.70015","0.00627"
"428.76000","35.73016","0.00643"
"429.12000","35.76012","0.00632"
"429.48000","35.79013","0.00636"
"429.84000","35.82021","0.00588"
"430.20000","35.85016","0.00651"
"430.56000","35.88012","0.00639"
"430.92000","35.91019","0.00599"
"431.28000","35.94014","0.00624"
"431.64000","35.97016","0.00657"
"432.00000","36.00017","0.00650"
"432.36000","36.03013","0.00651"
"432.72000","36.06014","0.00653"
"433.08000","36.09016","0.00617"
"433.44000","36.12017","0.00655"
"433.80000","36.15013","0.00669"
"434.16000","36.18020","0.00641"
"434.52000","36.21016","0.00642"
"434.88000","36.24011","0.00674"
"435.24000","36.27024","0.00632"
"435.60000","36.30020","0.00634"
"435.96000","36.33015","0.00645"
"436.32000","36.36017","0.00632"
"436.68000","36.39012","0.00655"
"437.04000","36.42014","0.00651"
"437.40000","36.45021","0.00655"
"437.76000","36.48022","0.00669"
"438.12000","36.51018","0.00668"
"438.48000","36.54020","0.00644"
"438.84000","36.57015","0.00669"
"439.20000","36.60010","0.00653"
"439.56000","36.63018","0.00625"
"439.92000","36.66019","0.00650"
"440.28000","36.69020","0.00665"
"440.64000","36.72016","0.00667"
"441.00000","36.75024","0.00656"
"441.36000","36.78013","0.00657"
"441.72000","36.81015","0.00638"
"442.08000","36.84016","0.00658"
"442.44000","36.87011","0.00666"
"442.80000","36.90018","0.00695"
"443.16000","36.93020","0.00644"
"443.52000","36.96009","0.00671"
"443.88000","36.99017","0.00663"
"444.24000","37.02018","0.00673"
"444.60000","37.05014","0.00677"
"444.96000","37.08015","0.00686"
"445.32000","37.11017","0.00675"
"445.68000","37.14013","0.00666"
"446.04000","37.17020","0.00719"
"446.40000","37.20015","0.00659"
"446.76000","37.23016","0.00689"
"447.12000","37.26018","0.00680"
"447.48000","37.29019","0.00694"
"447.84000","37.32009","0.00693"
"448.20000","37.35022","0.00648"
"448.56000","37.38018","0.00683"
"448.92000","37.41013","0.00708"
"449.28000","37.44015","0.00699"
"449.64000","37.47016","0.00688"
"450.00000","37.50011","0.00695"
"450.36000","37.53013","0.00669"
"450.72000","37.56014","0.00686"
"451.08000","37.59010","0.00691"
"451.44000","37.62017","0.00681"
"451.80000","37.65019","0.00698"
"452.16000","37.68008","0.00707"
"452.52000","37.71016","0.00700"
"452.88000","37.74017","0.00719"
"453.24000","37.77007","0.00711"
"453.60000","37.80014","0.00746"
"453.96000","37.83021","0.00703"
"454.32000","37.86011","0.00723"
"454.68000","37.89018","0.00722"
"455.04000","37.92020","0.00736"
"455.40000","37.95015","0.00698"
"455.76000","37.98016","0.00742"
"456.12000","38.01018","0.00733"
"456.48000","38.04008","0.00742"
"456.84000","38.07015","0.00748"
"457.20000","38.10016","0.00704"
"457.56000","38.13018","0.00705"
"457.92000","38.16019","0.00747"
"458.28000","38.19020","0.00728"
"458.64000","38.22016","0.00753"
"459.00000","38.25018","0.00722"
"459.36000","38.28019","0.00758"
"459.72000","38.31009","0.00762"
"460.08000","38.34016","0.00756"
"460.44000","38.37017","0.00754"
"460.80000","38.40013","0.00746"
"461.16000","38.43020","0.00775"
"461.52000","38.46016","0.00748"
"461.88000","38.49005","0.00770"
"462.24000","38.52018","0.00735"
"462.60000","38.55020","0.00739"
"462.96000","38.58015","0.00764"
"463.32000","38.61017","0.00755"
"463.68000","38.64018","0.00754"
"464.04000","38.67008","0.00780"
"464.40000","38.70015","0.00769"
"464.76000","38.73010","0.00803"
"465.12000","38.76012","0.00783"
"465.48000","38.79019","0.00793"
"465.84000","38.82021","0.00825"
"466.20000","38.85010","0.00790"
"466.56000","38.88018","0.00773"
"466.92000","38.91013","0.00763"
"467.28000","38.94020","0.00815"
"467.64000","38.97010","0.00793"
"468.00000","39.00018","0.00797"
"468.36000","39.03013","0.00833"
"468.72000","39.06014","0.00844"
"469.08000","39.09010","0.00767"
"469.44000","39.12017","0.00800"
"469.80000","39.15012","0.00813"
"470.16000","39.18014","0.00787"
"470.52000","39.21016","0.00823"
"470.88000","39.24017","0.00791"
"471.24000","39.27018","0.00804"
"471.60000","39.30014","0.00809"
"471.96000","39.33015","0.00789"
"472.32000","39.36017","0.00761"
"472.68000","39.39012","0.00772"
"473.04000","39.42020","0.00744"
"473.40000","39.45015","0.00734"
"473.76000","39.48016","0.00722"
"474.12000","39.51012","0.00776"
"474.48000","39.54013","0.00771"
"474.84000","39.57009","0.00754"
"475.20000","39.60016","0.00779"
"475.56000","39.63018","0.00748"
"475.92000","39.66013","0.00748"
"476.28000","39.69014","0.00746"
"476.64000","39.72016","0.00772"
"477.00000","39.75018","0.00759"
"477.36000","39.78012","0.00802"
"477.72000","39.81014","0.00785"
"478.08000","39.84016","0.00787"
"478.44000","39.87011","0.00800"
"478.80000","39.90019","0.00814"
"479.16000","39.93020","0.00799"
"479.52000","39.96015","0.00794"
"479.88000","39.99017","0.00797"
"480.24000","40.02012","0.00811"
"480.60000","40.05013","0.00811"
"480.96000","40.08015","0.00813"
"481.32000","40.11017","0.00823"
"481.68000","40.14018","0.00830"
"482.04000","40.17020","0.00820"
"482.40000","40.20021","0.00839"
"482.76000","40.23016","0.00850"
"483.12000","40.26012","0.00841"
"483.48000","40.29013","0.00834"
"483.84000","40.32014","0.00811"
"484.20000","40.35016","0.00794"
"484.56000","40.38012","0.00811"
"484.92000","40.41019","0.00788"
"485.28000","40.44015","0.00809"
"485.64000","40.47016","0.00800"
"486.00000","40.50017","0.00820"
"486.36000","40.53019","0.00796"
"486.72000","40.56015","0.00788"
"487.08000","40.59016","0.00847"
"487.44000","40.62017","0.00854"
"487.80000","40.65018","0.00810"
"488.16000","40.68014","0.00834"
"488.52000","40.71021","0.00816"
"488.88000","40.74011","0.00823"
"489.24000","40.77012","0.00864"
"489.60000","40.80020","0.00826"
"489.96000","40.83015","0.00831"
"490.32000","40.86010","0.00838"
"490.68000","40.89018","0.00788"
"491.04000","40.92019","0.00812"
"491.40000","40.95015","0.00826"
"491.76000","40.98016","0.00813"
"492.12000","41.01023","0.00829"
"492.48000","41.04013","0.00829"
"492.84000","41.07015","0.00854"
"493.20000","41.10016","0.00801"
"493.56000","41.13012","0.00871"
"493.92000","41.16019","0.00851"
"494.28000","41.19020","0.00850"
"494.64000","41.22010","0.00830"
"495.00000","41.25011","0.00836"
"495.36000","41.28013","0.00835"
"495.72000","41.31014","0.00846"
"496.08000","41.34016","0.00843"
"496.44000","41.37017","0.00838"
"496.80000","41.40012","0.00839"
"497.16000","41.43014","0.00840"
"497.52000","41.46016","0.00912"
"497.88000","41.49011","0.00863"
"498.24000","41.52019","0.00870"
"498.60000","41.55020","0.00820"
"498.96000","41.58015","0.00880"
"499.32000","41.61016","0.00883"
"499.68000","41.64018","0.00845"
"500.04000","41.67008","0.00846"
"500.40000","41.70015","0.00843"
"500.76000","41.73016","0.00835"
"501.12000","41.76012","0.00825"
"501.48000","41.79013","0.00827"
"501.84000","41.82021","0.00819"
"502.20000","41.85010","0.00859"
"502.56000","41.88018","0.00851"
"502.92000","41.91019","0.00873"
"503.28000","41.94014","0.00843"
"503.64000","41.97016","0.00854"
"504.00000","42.00023","0.00836"
"504.36000","42.03007","0.00858"
"504.72000","42.06020","0.00873"
"505.08000","42.09021","0.00911"
"505.44000","42.12017","0.00893"
"505.80000","42.15013","0.00862"
"506.16000","42.18014","0.00882"
"506.52000","42.21015","0.00924"
"506.88000","42.24017","0.00908"
"507.24000","42.27018","0.00906"
"507.60000","42.30014","0.00923"
"507.96000","42.33015","0.00925"
"508.32000","42.36023","0.00915"
"508.68000","42.39006","0.00927"
"509.04000","42.42020","0.00953"
"509.40000","42.45015","0.00927"
"509.76000","42.48016","0.00932"
"510.12000","42.51011","0.00968"
"510.48000","42.54019","0.00941"
"510.84000","42.57009","0.00945"
"511.20000","42.60016","0.00894"
"511.56000","42.63018","0.00916"
"511.92000","42.66013","0.00893"
"512.28000","42.69015","0.00931"
"512.64000","42.72016","0.00908"
"513.00000","42.75006","0.00922"
"513.36000","42.78019","0.00891"
"513.72000","42.81020","0.00902"
"514.08000","42.84010","0.00896"
"514.44000","42.87017","0.00893"
"514.80000","42.90018","0.00912"
"515.16000","42.93008","0.00899"
"515.52000","42.96016","0.00851"
"515.88000","42.99017","0.00858"
"516.24000","43.02012","0.00894"
"516.60000","43.05014","0.00874"
"516.96000","43.08015","0.00872"
"517.32000","43.11011","0.00871"
"517.68000","43.14018","0.00853"
"518.04000","43.17020","0.00893"
"518.40000","43.20015","0.00915"
"518.76000","43.23016","0.00887"
"519.12000","43.26018","0.00895"
"519.48000","43.29013","0.00854"
"519.84000","43.32015","0.00885"
"520.20000","43.35016","0.00915"
"520.56000","43.38012","0.00897"
"520.92000","43.41013","0.00897"
"521.28000","43.44014","0.00913"
"521.64000","43.47015","0.00900"
"522.00000","43.50018","0.00859"
"522.36000","43.53024","0.00912"
"522.72000","43.56014","0.00904"
"523.08000","43.59016","0.00931"
"523.44000","43.62017","0.00913"
"523.80000","43.65019","0.00946"
"524.16000","43.68014","0.00937"
"524.52000","43.71021","0.00899"
"524.88000","43.74011","0.00924"
"525.24000","43.77018","0.00936"
"525.60000","43.80014","0.00927"
"525.96000","43.83015","0.00930"
"526.32000","43.86017","0.00957"
"526.68000","43.89018","0.00938"
"527.04000","43.92013","0.00936"
"527.40000","43.95015","0.00937"
"527.76000","43.98017","0.00902"
"528.12000","44.01018","0.00931"
"528.48000","44.04007","0.00944"
"528.84000","44.07021","0.00932"
"529.20000","44.10016","0.00948"
"529.56000","44.13012","0.00952"
"529.92000","44.16019","0.00976"
"530.28000","44.19020","0.00963"
"530.64000","44.22010","0.00982"
"531.00000","44.25018","0.01010"
"531.36000","44.28013","0.00985"
"531.72000","44.31015","0.00970"
"532.08000","44.34016","0.00984"
"532.44000","44.37017","0.00992"
"532.80000","44.40013","0.00967"
"533.16000","44.43020","0.00991"
"533.52000","44.46015","0.01037"
"533.88000","44.49010","0.00972"
"534.24000","44.52013","0.01012"
"534.60000","44.55014","0.00999"
"534.96000","44.58015","0.01015"
"535.32000","44.61017","0.01003"
"535.68000","44.64018","0.01014"
"536.04000","44.67020","0.01023"
"536.40000","44.70015","0.01039"
"536.76000","44.73016","0.01047"
"537.12000","44.76012","0.01037"
"537.48000","44.79019","0.01090"
"537.84000","44.82014","0.01035"
"538.13200","44.84442","0.01084"