File: Force_trajectories/161221_1/Specimen_RawData_4.csv
End date,"12/21/2016"
Specimen label,"23DG_88_run2"
Maximum Load,"0.01790",N

Time,Extension,Load
(s),(mm),(N)
"0.00000","28.99942","0.00161"
"0.45600","29.03774","0.00128"
"0.91200","29.07553","0.00117"
"1.36800","29.11350","0.00125"
"1.82400","29.15158","0.00139"
"2.28000","29.18955","0.00138"
"2.73600","29.22764","0.00108"
"3.19200","29.26560","0.00131"
"3.64800","29.30357","0.00141"
"4.10400","29.34153","0.00157"
"4.56000","29.37956","0.00096"
"5.01600","29.41759","0.00138"
"5.47200","29.45555","0.00153"
"5.92800","29.49358","0.00148"
"6.38400","29.53155","0.00128"
"6.84000","29.56957","0.00129"
"7.29600","29.60748","0.00157"
"7.75200","29.64556","0.00155"
"8.20800","29.68359","0.00153"
"8.66400","29.72156","0.00160"
"9.12000","29.75958","0.00135"
"9.57600","29.79755","0.00110"
"10.03200","29.83558","0.00119"
"10.48800","29.87354","0.00139"
"10.94400","29.91151","0.00157"
"11.40000","29.94959","0.00127"
"11.85600","29.98756","0.00160"
"12.31200","30.02559","0.00152"
"12.76800","30.06355","0.00169"
"13.22400","30.10152","0.00162"
"13.68000","30.13955","0.00137"
"14.13600","30.17757","0.00124"
"14.59200","30.21560","0.00167"
"15.04800","30.25356","0.00160"
"15.50400","30.29159","0.00150"
"15.96000","30.32956","0.00143"
"16.41600","30.36746","0.00161"
"16.87200","30.40555","0.00176"
"17.32800","30.44357","0.00130"
"17.78400","30.48160","0.00147"
"18.24000","30.51957","0.00146"
"18.69600","30.55753","0.00150"
"19.15200","30.59556","0.00155"
"19.60800","30.63353","0.00195"
"20.06400","30.67155","0.00176"
"20.52000","30.70964","0.00145"
"20.97600","30.74761","0.00171"
"21.43200","30.78557","0.00180"
"21.88800","30.82360","0.00161"
"22.34400","30.86151","0.00180"
"22.80000","30.89959","0.00213"
"23.25600","30.93762","0.00170"
"23.71200","30.97558","0.00187"
"24.16800","31.01361","0.00195"
"24.62400","31.05158","0.00170"
"25.08000","31.08954","0.00186"
"25.53600","31.12751","0.00167"
"25.99200","31.16553","0.00173"
"26.44800","31.20356","0.00212"
"26.90400","31.24159","0.00182"
"27.36000","31.27961","0.00192"
"27.81600","31.31752","0.00181"
"28.27200","31.35555","0.00161"
"28.72800","31.39351","0.00177"
"29.18400","31.43154","0.00200"
"29.64000","31.46956","0.00154"
"30.09600","31.50759","0.00199"
"30.55200","31.54561","0.00187"
"31.00800","31.58358","0.00191"
"31.46400","31.62155","0.00149"
"31.92000","31.65957","0.00163"
"32.37600","31.69760","0.00179"
"32.83200","31.73557","0.00208"
"33.28800","31.77359","0.00170"
"33.74400","31.81156","0.00202"
"34.20000","31.84947","0.00192"
"34.65600","31.88755","0.00206"
"35.11200","31.92552","0.00190"
"35.56800","31.96360","0.00174"
"36.02400","32.00163","0.00185"
"36.48000","32.03959","0.00188"
"36.93600","32.07756","0.00203"
"37.39200","32.11547","0.00210"
"37.84800","32.15355","0.00226"
"38.30400","32.19158","0.00171"
"38.76000","32.22961","0.00225"
"39.21600","32.26757","0.00223"
"39.67200","32.30554","0.00221"
"40.12800","32.34351","0.00226"
"40.58400","32.38147","0.00228"
"41.04000","32.41956","0.00196"
"41.49600","32.45758","0.00204"
"41.95200","32.49555","0.00190"
"42.40800","32.53358","0.00220"
"42.86400","32.57154","0.00231"
"43.32000","32.60957","0.00209"
"43.77600","32.64759","0.00195"
"44.23200","32.68562","0.00208"
"44.68800","32.72359","0.00218"
"45.14400","32.76155","0.00215"
"45.60000","32.79952","0.00200"
"46.05600","32.83755","0.00201"
"46.51200","32.87557","0.00196"
"46.96800","32.91354","0.00236"
"47.42400","32.95163","0.00218"
"47.88000","32.98953","0.00213"
"48.33600","33.02756","0.00189"
"48.79200","33.06558","0.00221"
"49.24800","33.10355","0.00200"
"49.70400","33.14152","0.00193"
"50.16000","33.17949","0.00202"
"50.61600","33.21763","0.00187"
"51.07200","33.25560","0.00219"
"51.52800","33.29362","0.00168"
"51.98400","33.33153","0.00198"
"52.44000","33.36956","0.00176"
"52.89600","33.40752","0.00206"
"53.35200","33.44561","0.00201"
"53.80800","33.48363","0.00175"
"54.26400","33.52160","0.00228"
"54.72000","33.55951","0.00187"
"55.17600","33.59753","0.00225"
"55.63200","33.63556","0.00180"
"56.08800","33.67358","0.00202"
"56.54400","33.71161","0.00181"
"57.00000","33.74958","0.00187"
"57.45600","33.78761","0.00225"
"57.91200","33.82551","0.00181"
"58.36800","33.86354","0.00186"
"58.82400","33.90156","0.00167"
"59.28000","33.93965","0.00188"
"59.73600","33.97755","0.00167"
"60.19200","34.01558","0.00191"
"60.64800","34.05355","0.00207"
"61.10400","34.09151","0.00207"
"61.56000","34.12960","0.00172"
"62.01600","34.16756","0.00220"
"62.47200","34.20565","0.00182"
"62.92800","34.24356","0.00188"
"63.38400","34.28159","0.00169"
"63.84000","34.31955","0.00239"
"64.29600","34.35758","0.00183"
"64.75200","34.39560","0.00199"
"65.20800","34.43357","0.00211"
"65.66400","34.47153","0.00202"
"66.12000","34.50956","0.00218"
"66.57600","34.54758","0.00199"
"67.03200","34.58556","0.00206"
"67.48800","34.62346","0.00229"
"67.94400","34.66154","0.00201"
"68.40000","34.69957","0.00189"
"68.85600","34.73760","0.00223"
"69.31200","34.77563","0.00219"
"69.76800","34.81353","0.00156"
"70.22400","34.85156","0.00218"
"70.68000","34.88958","0.00197"
"71.13600","34.92755","0.00213"
"71.59200","34.96558","0.00220"
"72.04800","35.00360","0.00223"
"72.50400","35.04157","0.00240"
"72.96000","35.07954","0.00216"
"73.41600","35.11756","0.00228"
"73.87200","35.15553","0.00222"
"74.32800","35.19361","0.00236"
"74.78400","35.23164","0.00226"
"75.24000","35.26961","0.00245"
"75.69600","35.30757","0.00224"
"76.15200","35.34548","0.00202"
"76.60800","35.38350","0.00222"
"77.06400","35.42159","0.00243"
"77.52000","35.45962","0.00231"
"77.97600","35.49759","0.00226"
"78.43200","35.53555","0.00244"
"78.88800","35.57352","0.00211"
"79.34400","35.61155","0.00230"
"79.80000","35.64963","0.00222"
"80.25600","35.68760","0.00241"
"80.71200","35.72556","0.00230"
"81.16800","35.76359","0.00248"
"81.62400","35.80155","0.00251"
"82.08000","35.83958","0.00247"
"82.53600","35.87754","0.00252"
"82.99200","35.91557","0.00206"
"83.44800","35.95360","0.00296"
"83.90400","35.99157","0.00265"
"84.36000","36.02959","0.00228"
"84.81600","36.06756","0.00251"
"85.27200","36.10553","0.00230"
"85.72800","36.14355","0.00269"
"86.18400","36.18158","0.00201"
"86.64000","36.21960","0.00270"
"87.09600","36.25757","0.00257"
"87.55200","36.29560","0.00245"
"88.00800","36.33350","0.00248"
"88.46400","36.37153","0.00262"
"88.92000","36.40955","0.00250"
"89.37600","36.44758","0.00285"
"89.83200","36.48560","0.00263"
"90.28800","36.52357","0.00273"
"90.74400","36.56154","0.00278"
"91.20000","36.59956","0.00302"
"91.65600","36.63753","0.00286"
"92.11200","36.67562","0.00218"
"92.56800","36.71365","0.00233"
"93.02400","36.75161","0.00273"
"93.48000","36.78952","0.00260"
"93.93600","36.82748","0.00272"
"94.39200","36.86551","0.00234"
"94.84800","36.90359","0.00255"
"95.30400","36.94162","0.00257"
"95.76000","36.97959","0.00290"
"96.21600","37.01756","0.00262"
"96.67200","37.05552","0.00287"
"97.12800","37.09355","0.00279"
"97.58400","37.13157","0.00264"
"98.04000","37.16960","0.00277"
"98.49600","37.20757","0.00256"
"98.95200","37.24559","0.00259"
"99.40800","37.28356","0.00281"
"99.86400","37.32152","0.00314"
"100.32000","37.35955","0.00294"
"100.77600","37.39758","0.00276"
"101.23200","37.43560","0.00245"
"101.68800","37.47357","0.00288"
"102.14400","37.51159","0.00267"
"102.60000","37.54956","0.00273"
"103.05600","37.58753","0.00266"
"103.51200","37.62555","0.00230"
"103.96800","37.66358","0.00285"
"104.42400","37.70161","0.00285"
"104.88000","37.73957","0.00293"
"105.33600","37.77760","0.00265"
"105.79200","37.81556","0.00294"
"106.24800","37.85353","0.00273"
"106.70400","37.89156","0.00281"
"107.16000","37.92958","0.00252"
"107.61600","37.96761","0.00230"
"108.07200","38.00558","0.00225"
"108.52800","38.04360","0.00253"
"108.98400","38.08151","0.00276"
"109.44000","38.11954","0.00253"
"109.89600","38.15756","0.00243"
"110.35200","38.19559","0.00232"
"110.80800","38.23361","0.00223"
"111.26400","38.27158","0.00205"
"111.72000","38.30954","0.00230"
"112.17600","38.34757","0.00257"
"112.63200","38.38554","0.00252"
"113.08800","38.42362","0.00258"
"113.54400","38.46159","0.00234"
"114.00000","38.49956","0.00230"
"114.45600","38.53753","0.00257"
"114.91200","38.57549","0.00251"
"115.36800","38.61357","0.00247"
"115.82400","38.65154","0.00259"
"116.28000","38.68963","0.00279"
"116.73600","38.72759","0.00264"
"117.19200","38.76556","0.00289"
"117.64800","38.80359","0.00268"
"118.10400","38.84155","0.00264"
"118.56000","38.87958","0.00280"
"119.01600","38.91755","0.00277"
"119.47200","38.95563","0.00252"
"119.92800","38.99360","0.00304"
"120.38400","39.03157","0.00256"
"120.84000","39.06953","0.00293"
"121.29600","39.10756","0.00265"
"121.75200","39.14558","0.00269"
"122.20800","39.18355","0.00250"
"122.66400","39.22157","0.00261"
"123.12000","39.25960","0.00275"
"123.57600","39.29757","0.00258"
"124.03200","39.33553","0.00259"
"124.48800","39.37356","0.00282"
"124.94400","39.41158","0.00263"
"125.40000","39.44955","0.00275"
"125.85600","39.48763","0.00303"
"126.31200","39.52555","0.00282"
"126.76800","39.56357","0.00281"
"127.22400","39.60159","0.00245"
"127.68000","39.63956","0.00268"
"128.13600","39.67759","0.00257"
"128.59200","39.71562","0.00253"
"129.04800","39.75364","0.00254"
"129.50400","39.79155","0.00254"
"129.96000","39.82946","0.00284"
"130.41600","39.86754","0.00256"
"130.87200","39.90557","0.00256"
"131.32800","39.94359","0.00251"
"131.78400","39.98149","0.00282"
"132.24000","40.01959","0.00325"
"132.69600","40.05749","0.00292"
"133.15200","40.09558","0.00319"
"133.60800","40.13360","0.00290"
"134.06400","40.17157","0.00320"
"134.52000","40.20954","0.00302"
"134.97600","40.24756","0.00325"
"135.43200","40.28553","0.00335"
"135.88800","40.32349","0.00322"
"136.34400","40.36152","0.00321"
"136.80000","40.39960","0.00335"
"137.25600","40.43758","0.00293"
"137.71200","40.47560","0.00324"
"138.16800","40.51357","0.00336"
"138.62400","40.55159","0.00341"
"139.08000","40.58956","0.00351"
"139.53600","40.62759","0.00321"
"139.99200","40.66561","0.00338"
"140.44800","40.70358","0.00356"
"140.90400","40.74160","0.00384"
"141.36000","40.77957","0.00370"
"141.81600","40.81754","0.00375"
"142.27200","40.85556","0.00374"
"142.72800","40.89352","0.00358"
"143.18400","40.93156","0.00399"
"143.64000","40.96959","0.00374"
"144.09600","41.00761","0.00355"
"144.55200","41.04558","0.00361"
"145.00800","41.08348","0.00393"
"145.46400","41.12156","0.00379"
"145.92000","41.15959","0.00381"
"146.37600","41.19762","0.00414"
"146.83200","41.23565","0.00418"
"147.28800","41.27355","0.00416"
"147.74400","41.31152","0.00424"
"148.20000","41.34954","0.00452"
"148.65600","41.38757","0.00392"
"149.11200","41.42560","0.00421"
"149.56800","41.46362","0.00440"
"150.02400","41.50159","0.00413"
"150.48000","41.53956","0.00466"
"150.93600","41.57752","0.00447"
"151.39200","41.61555","0.00480"
"151.84800","41.65357","0.00468"
"152.30400","41.69154","0.00473"
"152.76000","41.72963","0.00505"
"153.21600","41.76759","0.00454"
"153.67200","41.80556","0.00492"
"154.12800","41.84358","0.00499"
"154.58400","41.88161","0.00511"
"155.04000","41.91958","0.00530"
"155.49600","41.95761","0.00516"
"155.95200","41.99557","0.00519"
"156.40800","42.03360","0.00524"
"156.86400","42.07156","0.00526"
"157.32000","42.10958","0.00557"
"157.77600","42.14756","0.00550"
"158.23200","42.18552","0.00526"
"158.68800","42.22361","0.00551"
"159.14400","42.26157","0.00584"
"159.60000","42.29954","0.00557"
"160.05600","42.33757","0.00569"
"160.51200","42.37553","0.00588"
"160.96800","42.41362","0.00584"
"161.42400","42.45159","0.00572"
"161.88000","42.48961","0.00611"
"162.33600","42.52758","0.00616"
"162.79200","42.56548","0.00614"
"163.24800","42.60357","0.00637"
"163.70400","42.64154","0.00620"
"164.16000","42.67956","0.00616"
"164.61600","42.71759","0.00652"
"165.07200","42.75561","0.00676"
"165.52800","42.79352","0.00663"
"165.98400","42.83155","0.00709"
"166.44000","42.86958","0.00670"
"166.89600","42.90754","0.00704"
"167.35200","42.94556","0.00721"
"167.80800","42.98359","0.00716"
"168.26400","43.02156","0.00746"
"168.72000","43.05952","0.00739"
"169.17600","43.09755","0.00720"
"169.63200","43.13558","0.00723"
"170.08800","43.17360","0.00754"
"170.54400","43.21157","0.00774"
"171.00000","43.24960","0.00743"
"171.45600","43.28756","0.00785"
"171.91200","43.32553","0.00823"
"172.36800","43.36356","0.00848"
"172.82400","43.40158","0.00829"
"173.28000","43.43955","0.00767"
"173.73600","43.47757","0.00778"
"174.19200","43.51554","0.00712"
"174.64800","43.55357","0.00774"
"175.10400","43.59153","0.00776"
"175.56000","43.62956","0.00764"
"176.01600","43.66758","0.00800"
"176.47200","43.70555","0.00801"
"176.92800","43.74363","0.00839"
"177.38400","43.78160","0.00805"
"177.84000","43.81957","0.00816"
"178.29600","43.85754","0.00836"
"178.75200","43.89556","0.00835"
"179.20800","43.93359","0.00818"
"179.66400","43.97162","0.00793"
"180.12000","44.00952","0.00889"
"180.57600","44.04749","0.00847"
"181.03200","44.08551","0.00843"
"181.48800","44.12354","0.00855"
"181.94400","44.16162","0.00863"
"182.40000","44.19965","0.00883"
"182.85600","44.23756","0.00877"
"183.31200","44.27558","0.00833"
"183.76800","44.31355","0.00889"
"184.22400","44.35158","0.00846"
"184.68000","44.38961","0.00886"
"185.13600","44.42763","0.00897"
"185.59200","44.46560","0.00861"
"186.04800","44.50356","0.00872"
"186.50400","44.54147","0.00917"
"186.96000","44.57955","0.00866"
"187.41600","44.61758","0.00881"
"187.87200","44.65561","0.00927"
"188.32800","44.69357","0.00894"
"188.78400","44.73159","0.00892"
"189.24000","44.76957","0.00872"
"189.69600","44.80753","0.00898"
"190.15200","44.84556","0.00902"
"190.60800","44.88353","0.00933"
"191.06400","44.92161","0.00926"
"191.52000","44.95964","0.00971"
"191.97600","44.99754","0.00955"
"192.43200","45.03557","0.00977"
"192.88800","45.07354","0.00903"
"193.34400","45.11162","0.00867"
"193.80000","45.14959","0.00855"
"194.25600","45.18755","0.00634"
"194.71200","45.22558","0.00597"
"195.16800","45.26355","0.00597"
"195.62400","45.30157","0.00623"
"196.08000","45.33954","0.00647"
"196.53600","45.37757","0.00625"
"196.99200","45.41559","0.00686"
"197.44800","45.45356","0.00651"
"197.90400","45.49164","0.00693"
"198.36000","45.52949","0.00638"
"198.81600","45.56751","0.00686"
"199.27200","45.60555","0.00687"
"199.72800","45.64357","0.00751"
"200.18400","45.68159","0.00763"
"200.64000","45.71956","0.00703"
"201.09600","45.75753","0.00739"
"201.55200","45.79550","0.00751"
"202.00800","45.83352","0.00698"
"202.46400","45.87161","0.00711"
"202.92000","45.90957","0.00706"
"203.37600","45.94760","0.00730"
"203.83200","45.98557","0.00761"
"204.28800","46.02359","0.00753"
"204.74400","46.06150","0.00752"
"205.20000","46.09952","0.00800"
"205.65600","46.13761","0.00764"
"206.11200","46.17557","0.00741"
"206.56800","46.21360","0.00730"
"207.02400","46.25151","0.00733"
"207.48000","46.28953","0.00757"
"207.93600","46.32750","0.00766"
"208.39200","46.36559","0.00743"
"208.84800","46.40361","0.00733"
"209.30400","46.44152","0.00728"
"209.76000","46.47961","0.00749"
"210.21600","46.51757","0.00766"
"210.67200","46.55560","0.00780"
"211.12800","46.59357","0.00782"
"211.58400","46.63147","0.00770"
"212.04000","46.66962","0.00806"
"212.49600","46.70758","0.00879"
"212.95200","46.74561","0.00836"
"213.40800","46.78358","0.00823"
"213.86400","46.82154","0.00859"
"214.32000","46.85951","0.00925"
"214.77600","46.89760","0.00868"
"215.23200","46.93556","0.00943"
"215.68800","46.97359","0.00918"
"216.14400","47.01149","0.00924"
"216.60000","47.04958","0.00907"
"217.05600","47.08754","0.00913"
"217.51200","47.12558","0.00947"
"217.96800","47.16359","0.01005"
"218.42400","47.20163","0.01016"
"218.88000","47.23953","0.00948"
"219.33600","47.27750","0.00956"
"219.79200","47.31552","0.00946"
"220.24800","47.35355","0.00968"
"220.70400","47.39158","0.00944"
"221.16000","47.42960","0.01011"
"221.61600","47.46763","0.00981"
"222.07200","47.50554","0.00984"
"222.52800","47.54350","0.00957"
"222.98400","47.58153","0.01014"
"223.44000","47.61961","0.01078"
"223.89600","47.65758","0.01064"
"224.35200","47.69560","0.01104"
"224.80800","47.73351","0.01096"
"225.26400","47.77154","0.01106"
"225.72000","47.80951","0.01082"
"226.17600","47.84759","0.01125"
"226.63200","47.88556","0.01189"
"227.08800","47.92352","0.01167"
"227.54400","47.96161","0.01154"
"228.00000","47.99958","0.01183"
"228.45600","48.03754","0.01197"
"228.91200","48.07550","0.01190"
"229.36800","48.11359","0.01242"
"229.82400","48.15162","0.01198"
"230.28000","48.18953","0.01271"
"230.73600","48.22761","0.01215"
"231.19200","48.26558","0.01269"
"231.64800","48.30355","0.01274"
"232.10400","48.34157","0.01266"
"232.56000","48.37954","0.01257"
"233.01600","48.41756","0.01316"
"233.47200","48.45553","0.01293"
"233.92800","48.49356","0.01279"
"234.38400","48.53152","0.01309"
"234.84000","48.56948","0.01323"
"235.29600","48.60757","0.01328"
"235.75200","48.64555","0.01394"
"236.20800","48.68362","0.01409"
"236.66400","48.72160","0.01401"
"237.12000","48.75956","0.01416"
"237.57600","48.79747","0.01434"
"238.03200","48.83555","0.01429"
"238.48800","48.87358","0.01402"
"238.94400","48.91161","0.01520"
"239.40000","48.94963","0.01481"
"239.85600","48.98753","0.01499"
"240.31200","49.02551","0.01540"
"240.76800","49.06353","0.01541"
"241.22400","49.10156","0.01540"
"241.68000","49.13958","0.01585"
"242.13600","49.17755","0.01605"
"242.59200","49.21557","0.01639"
"243.04800","49.25354","0.01608"
"243.50400","49.29151","0.01663"
"243.96000","49.32953","0.01643"
"244.41600","49.36756","0.01656"
"244.87200","49.40559","0.01699"
"245.32800","49.44355","0.01718"
"245.78400","49.48158","0.01743"
"246.24000","49.51954","0.01742"
"246.69600","49.55758","0.01688"
"247.15200","49.59560","0.01677"
"247.60800","49.63357","0.01389"
"248.06400","49.67159","0.01218"
"248.52000","49.70956","0.01246"
"248.97600","49.74758","0.01087"
"249.43200","49.78555","0.00889"
"249.88800","49.82352","0.01032"
"250.34400","49.86154","0.01037"
"250.80000","49.89957","0.01030"
"251.25600","49.93759","0.01048"
"251.71200","49.97556","0.01023"
"252.16800","50.01353","0.00970"
"252.62400","50.05149","0.00990"
"253.08000","50.08952","0.01049"
"253.53600","50.12760","0.00956"
"253.99200","50.16563","0.01021"
"254.44800","50.20366","0.01016"
"254.90400","50.24150","0.01021"
"255.36000","50.27953","0.00980"
"255.81600","50.31750","0.01013"
"256.27200","50.35558","0.01009"
"256.72800","50.39361","0.00949"
"257.18400","50.43157","0.00981"
"257.64000","50.46960","0.00986"
"258.09600","50.50750","0.00987"
"258.55200","50.54554","0.00968"
"259.00800","50.58356","0.00926"
"259.46400","50.62159","0.00863"
"259.92000","50.65961","0.00815"
"260.37600","50.69758","0.00848"
"260.83200","50.73555","0.00831"
"261.28800","50.77351","0.00853"
"261.74400","50.81160","0.00856"
"262.20000","50.84956","0.00849"
"262.65600","50.88753","0.00852"
"263.11200","50.92556","0.00844"
"263.56800","50.96358","0.00838"
"264.02400","51.00155","0.00865"
"264.48000","51.03957","0.00866"
"264.93600","51.07754","0.00873"
"265.39200","51.11557","0.00886"
"265.84800","51.15359","0.00881"
"266.30400","51.19162","0.00860"
"266.76000","51.22959","0.00877"
"267.21600","51.26755","0.00887"
"267.67200","51.30552","0.00927"
"268.12800","51.34354","0.00898"
"268.58400","51.38157","0.00903"
"269.04000","51.41953","0.00881"
"269.49600","51.45757","0.00925"
"269.95200","51.49553","0.00893"
"270.40800","51.53350","0.00921"
"270.86400","51.57152","0.00925"
"271.32000","51.60955","0.00962"
"271.77600","51.64758","0.00932"
"272.23200","51.68560","0.00917"
"272.68800","51.72357","0.00895"
"273.14400","51.76153","0.00929"
"273.60000","51.79956","0.00947"
"274.05600","51.83752","0.00987"
"274.51200","51.87561","0.00977"
"274.96800","51.91364","0.00999"
"275.42400","51.95160","0.00979"
"275.88000","51.98951","0.00987"
"276.33600","52.02748","0.00959"
"276.79200","52.06551","0.00969"
"277.24800","52.10359","0.01000"
"277.70400","52.14162","0.01008"
"278.16000","52.17952","0.00999"
"278.61600","52.21755","0.00947"
"279.07200","52.25551","0.00909"
"279.52800","52.29354","0.00922"
"279.98400","52.33157","0.00955"
"280.44000","52.36959","0.00937"
"280.89600","52.40756","0.00973"
"281.35200","52.44553","0.00976"
"281.80800","52.48355","0.00971"
"282.26400","52.52152","0.00976"
"282.72000","52.55954","0.00974"
"283.17600","52.59757","0.00988"
"283.63200","52.63559","0.00957"
"284.08800","52.67356","0.00990"
"284.54400","52.71153","0.00990"
"285.00000","52.74955","0.00993"
"285.45600","52.78752","0.00786"
"285.91200","52.82555","0.00804"
"286.36800","52.86357","0.00829"
"286.82400","52.90154","0.00752"
"287.28000","52.93962","0.00787"
"287.73600","52.97760","0.00763"
"288.19200","53.01550","0.00749"
"288.64800","53.05353","0.00862"
"289.10400","53.09155","0.00797"
"289.56000","53.12958","0.00809"
"290.01600","53.16755","0.00789"
"290.47200","53.20563","0.00778"
"290.92800","53.24354","0.00872"
"291.38400","53.28151","0.00772"
"291.84000","53.31953","0.00849"
"292.29600","53.35761","0.00870"
"292.75200","53.39558","0.00858"
"293.20800","53.43361","0.00858"
"293.66400","53.47157","0.00875"
"294.12000","53.50948","0.00891"
"294.57600","53.54757","0.00919"
"295.03200","53.58566","0.00916"
"295.48800","53.62362","0.00947"
"295.94400","53.66158","0.00910"
"296.40000","53.69955","0.00965"
"296.85600","53.73752","0.00939"
"297.31200","53.77554","0.00847"
"297.76800","53.81351","0.00832"
"298.22400","53.85153","0.00846"
"298.68000","53.88956","0.00820"
"299.13600","53.92759","0.00858"
"299.59200","53.96556","0.00865"
"300.04800","54.00352","0.00824"
"300.50400","54.04155","0.00797"
"300.96000","54.07957","0.00829"
"301.41600","54.11760","0.00840"
"301.87200","54.15562","0.00856"
"302.32800","54.19359","0.00881"
"302.78400","54.23156","0.00830"
"303.24000","54.26953","0.00878"
"303.69600","54.30749","0.00810"
"304.15200","54.34552","0.00806"
"304.60800","54.38354","0.00862"
"305.06400","54.42157","0.00826"
"305.52000","54.45953","0.00749"
"305.97600","54.49757","0.00800"
"306.43200","54.53553","0.00737"
"306.88800","54.57349","0.00754"
"307.34400","54.61158","0.00813"
"307.80000","54.64960","0.00780"
"308.25600","54.68763","0.00762"
"308.71200","54.72554","0.00738"
"309.16800","54.76356","0.00741"
"309.62400","54.80154","0.00763"
"310.08000","54.83955","0.00777"
"310.53600","54.87759","0.00792"
"310.99200","54.91562","0.00775"
"311.44800","54.95358","0.00765"
"311.90400","54.99154","0.00793"
"312.36000","55.02951","0.00811"
"312.81600","55.06754","0.00779"
"313.27200","55.10556","0.00751"
"313.72800","55.14359","0.00787"
"314.18400","55.18155","0.00767"
"314.64000","55.21952","0.00719"
"315.09600","55.25749","0.00662"
"315.55200","55.29557","0.00641"
"316.00800","55.33360","0.00579"
"316.46400","55.37163","0.00617"
"316.92000","55.40960","0.00612"
"317.37600","55.44756","0.00622"
"317.83200","55.48559","0.00603"
"318.28800","55.52349","0.00650"
"318.74400","55.56158","0.00641"
"319.20000","55.59961","0.00638"
"319.65600","55.63757","0.00643"
"320.11200","55.67559","0.00628"
"320.56800","55.71356","0.00658"
"321.02400","55.75153","0.00675"
"321.48000","55.78950","0.00651"
"321.93600","55.82752","0.00668"
"322.39200","55.86555","0.00750"
"322.84800","55.90357","0.00706"
"323.30400","55.94160","0.00706"
"323.76000","55.97956","0.00747"
"324.21600","56.01753","0.00750"
"324.67200","56.05556","0.00774"
"325.12800","56.09352","0.00766"
"325.58400","56.13161","0.00780"
"326.04000","56.16957","0.00770"
"326.49600","56.20755","0.00730"
"326.95200","56.24551","0.00708"
"327.40800","56.28354","0.00669"
"327.86400","56.32151","0.00645"
"328.32000","56.35958","0.00691"
"328.77600","56.39762","0.00610"
"329.23200","56.43558","0.00626"
"329.68800","56.47355","0.00633"
"330.14400","56.51151","0.00638"
"330.60000","56.54960","0.00646"
"331.05600","56.58762","0.00584"
"331.51200","56.62559","0.00633"
"331.96800","56.66356","0.00584"
"332.42400","56.70153","0.00614"
"332.88000","56.73956","0.00549"
"333.33600","56.77752","0.00595"
"333.79200","56.81554","0.00588"
"334.24800","56.85357","0.00611"
"334.70400","56.89159","0.00593"
"335.16000","56.92956","0.00607"
"335.61600","56.96753","0.00597"
"336.07200","57.00555","0.00569"
"336.52800","57.04352","0.00618"
"336.98400","57.08155","0.00612"
"337.44000","57.11958","0.00643"
"337.89600","57.15754","0.00613"
"338.35200","57.19557","0.00614"
"338.80800","57.23359","0.00654"
"339.26400","57.27156","0.00587"
"339.72000","57.30953","0.00619"
"340.17600","57.34755","0.00540"
"340.63200","57.38552","0.00557"
"341.08800","57.42360","0.00552"
"341.54400","57.46157","0.00574"
"342.00000","57.49954","0.00547"
"342.45600","57.53750","0.00590"
"342.91200","57.57553","0.00583"
"343.36800","57.61361","0.00600"
"343.82400","57.65164","0.00605"
"344.28000","57.68960","0.00603"
"344.73600","57.72758","0.00574"
"345.19200","57.76548","0.00576"
"345.64800","57.80356","0.00635"
"346.10400","57.84159","0.00627"
"346.56000","57.87962","0.00641"
"347.01600","57.91753","0.00652"
"347.47200","57.95555","0.00600"
"347.92800","57.99352","0.00589"
"348.38400","58.03148","0.00512"
"348.84000","58.06957","0.00509"
"349.29600","58.10760","0.00516"
"349.75200","58.14556","0.00554"
"350.20800","58.18359","0.00532"
"350.66400","58.22156","0.00555"
"351.12000","58.25952","0.00607"
"351.57600","58.29755","0.00572"
"352.03200","58.33557","0.00553"
"352.48800","58.37360","0.00532"
"352.94400","58.41162","0.00511"
"353.40000","58.44953","0.00503"
"353.85600","58.48756","0.00539"
"354.31200","58.52552","0.00551"
"354.76800","58.56355","0.00557"
"355.22400","58.60157","0.00574"
"355.68000","58.63954","0.00556"
"356.13600","58.67757","0.00545"
"356.59200","58.71553","0.00590"
"357.04800","58.75350","0.00552"
"357.50400","58.79153","0.00560"
"357.96000","58.82956","0.00619"
"358.41600","58.86758","0.00595"
"358.87200","58.90561","0.00602"
"359.32800","58.94363","0.00610"
"359.78400","58.98154","0.00640"
"360.24000","59.01950","0.00572"
"360.69600","59.05759","0.00634"
"361.15200","59.09562","0.00604"
"361.60800","59.13364","0.00562"
"362.06400","59.17155","0.00638"
"362.52000","59.20952","0.00656"
"362.97600","59.24748","0.00611"
"363.43200","59.28551","0.00618"
"363.88800","59.32354","0.00629"
"364.34400","59.36162","0.00647"
"364.80000","59.39959","0.00617"
"365.25600","59.43755","0.00654"
"365.71200","59.47558","0.00655"
"366.16800","59.51349","0.00690"
"366.62400","59.55151","0.00657"
"367.08000","59.58960","0.00671"
"367.53600","59.62756","0.00665"
"367.99200","59.66559","0.00694"
"368.44800","59.70356","0.00666"
"368.90400","59.74147","0.00679"
"369.36000","59.77955","0.00680"
"369.81600","59.81758","0.00712"
"370.27200","59.85560","0.00661"
"370.72800","59.89357","0.00690"
"371.18400","59.93153","0.00705"
"371.64000","59.96956","0.00714"
"372.09600","60.00759","0.00710"
"372.55200","60.04561","0.00703"
"373.00800","60.08358","0.00656"
"373.46400","60.12160","0.00707"
"373.92000","60.15957","0.00720"
"374.37600","60.19760","0.00610"
"374.83200","60.23557","0.00632"
"375.28800","60.27353","0.00598"
"375.74400","60.31155","0.00636"
"376.20000","60.34958","0.00623"
"376.65600","60.38761","0.00656"
"377.11200","60.42558","0.00637"
"377.56800","60.46354","0.00574"
"378.02400","60.50151","0.00538"
"378.48000","60.53954","0.00602"
"378.93600","60.57756","0.00489"
"379.39200","60.61559","0.00485"
"379.84800","60.65361","0.00450"
"380.30400","60.69158","0.00492"
"380.76000","60.72955","0.00466"
"381.21600","60.76751","0.00517"
"381.67200","60.80554","0.00514"
"382.12800","60.84362","0.00497"
"382.58400","60.88159","0.00488"
"383.04000","60.91962","0.00529"
"383.49600","60.95752","0.00516"
"383.95200","60.99549","0.00538"
"384.40800","61.03357","0.00518"
"384.86400","61.07161","0.00527"
"385.32000","61.10957","0.00502"
"385.77600","61.14759","0.00508"
"386.23200","61.18556","0.00537"
"386.68800","61.22347","0.00511"
"387.14400","61.26149","0.00519"
"387.60000","61.29964","0.00511"
"388.05600","61.33761","0.00480"
"388.51200","61.37557","0.00525"
"388.96800","61.41360","0.00542"
"389.42400","61.45156","0.00514"
"389.88000","61.48959","0.00521"
"390.33600","61.52749","0.00532"
"390.79200","61.56558","0.00539"
"391.24800","61.60361","0.00560"
"391.70400","61.64158","0.00559"
"392.16000","61.67960","0.00578"
"392.61600","61.71757","0.00548"
"393.07200","61.75554","0.00562"
"393.52800","61.79356","0.00584"
"393.98400","61.83158","0.00606"
"394.44000","61.86961","0.00582"
"394.89600","61.90758","0.00548"
"395.35200","61.94560","0.00497"
"395.80800","61.98351","0.00532"
"396.26400","62.02148","0.00505"
"396.72000","62.05957","0.00495"
"397.17600","62.09759","0.00532"
"397.63200","62.13568","0.00556"
"398.08800","62.17359","0.00525"
"398.54400","62.21155","0.00561"
"399.00000","62.24952","0.00555"
"399.45600","62.28754","0.00580"
"399.91200","62.32557","0.00600"
"400.36800","62.36359","0.00606"
"400.82400","62.40156","0.00591"
"401.28000","62.43952","0.00573"
"401.73600","62.47750","0.00532"
"402.19200","62.51557","0.00477"
"402.64800","62.55360","0.00506"
"403.10400","62.59163","0.00542"
"403.56000","62.62960","0.00484"
"404.01600","62.66762","0.00560"
"404.47200","62.70552","0.00551"
"404.92800","62.74349","0.00542"
"405.38400","62.78152","0.00566"
"405.84000","62.81955","0.00558"
"406.29600","62.85763","0.00552"
"406.75200","62.89554","0.00566"
"407.20800","62.93356","0.00555"
"407.66400","62.97153","0.00621"
"408.12000","63.00956","0.00584"
"408.57600","63.04758","0.00593"
"409.03200","63.08561","0.00611"
"409.48800","63.12358","0.00630"
"409.94400","63.16161","0.00570"
"410.40000","63.19957","0.00546"
"410.85600","63.23753","0.00587"
"411.31200","63.27550","0.00558"
"411.76800","63.31359","0.00578"
"412.22400","63.35155","0.00552"
"412.68000","63.38958","0.00576"
"413.13600","63.42760","0.00588"
"413.59200","63.46552","0.00529"
"414.04800","63.50354","0.00574"
"414.50400","63.54156","0.00544"
"414.96000","63.57959","0.00543"
"415.41600","63.61762","0.00535"
"415.87200","63.65559","0.00581"
"416.32800","63.69355","0.00563"
"416.78400","63.73151","0.00509"
"417.24000","63.76948","0.00558"
"417.69600","63.80757","0.00533"
"418.15200","63.84554","0.00575"
"418.60800","63.88356","0.00541"
"419.06400","63.92159","0.00565"
"419.52000","63.95961","0.00568"
"419.97600","63.99752","0.00601"
"420.43200","64.03555","0.00605"
"420.88800","64.07363","0.00607"
"421.34400","64.11160","0.00616"
"421.80000","64.14963","0.00601"
"422.25600","64.18753","0.00602"
"422.71200","64.22549","0.00582"
"423.16800","64.26352","0.00605"
"423.62400","64.30161","0.00648"
"424.08000","64.33958","0.00649"
"424.53600","64.37754","0.00629"
"424.99200","64.41557","0.00667"
"425.44800","64.45354","0.00648"
"425.90400","64.49156","0.00684"
"426.36000","64.52953","0.00649"
"426.81600","64.56755","0.00654"
"427.27200","64.60558","0.00632"
"427.72800","64.64355","0.00660"
"428.18400","64.68157","0.00655"
"428.64000","64.71954","0.00654"
"429.09600","64.75751","0.00644"
"429.55200","64.79559","0.00424"
"430.00800","64.83356","0.00454"
"430.46400","64.87158","0.00371"
"430.92000","64.90955","0.00407"
"431.37600","64.94758","0.00384"
"431.83200","64.98554","0.00421"
"432.28800","65.02357","0.00427"
"432.74400","65.06159","0.00376"
"433.20000","65.09956","0.00418"
"433.65600","65.13765","0.00364"
"434.11200","65.17555","0.00373"
"434.56800","65.21358","0.00357"
"435.02400","65.25154","0.00363"
"435.48000","65.28951","0.00413"
"435.93600","65.32760","0.00385"
"436.39200","65.36562","0.00398"
"436.84800","65.40359","0.00387"
"437.30400","65.44156","0.00393"
"437.76000","65.47946","0.00411"
"438.21600","65.51756","0.00431"
"438.67200","65.55557","0.00416"
"439.12800","65.59360","0.00435"
"439.58400","65.63157","0.00429"
"440.04000","65.66954","0.00421"
"440.49600","65.70750","0.00410"
"440.95200","65.74558","0.00455"
"441.40800","65.78362","0.00463"
"441.86400","65.82158","0.00451"
"442.32000","65.85960","0.00460"
"442.77600","65.89757","0.00447"
"443.23200","65.93554","0.00497"
"443.68800","65.97356","0.00444"
"444.14400","66.01154","0.00486"
"444.60000","66.04955","0.00456"
"445.05600","66.08758","0.00457"
"445.51200","66.12555","0.00474"
"445.96800","66.16357","0.00480"
"446.42400","66.20154","0.00506"
"446.88000","66.23956","0.00448"
"447.33600","66.27753","0.00456"
"447.79200","66.31556","0.00465"
"448.24800","66.35359","0.00469"
"448.70400","66.39161","0.00469"
"449.16000","66.42958","0.00508"
"449.61600","66.46748","0.00479"
"450.07200","66.50558","0.00511"
"450.52800","66.54353","0.00482"
"450.98400","66.58157","0.00514"
"451.44000","66.61959","0.00504"
"451.89600","66.65762","0.00518"
"452.35200","66.69558","0.00487"
"452.80800","66.73349","0.00510"
"453.26400","66.77158","0.00517"
"453.72000","66.80960","0.00528"
"454.17600","66.84763","0.00475"
"454.63200","66.88559","0.00498"
"455.08800","66.92356","0.00504"
"455.54400","66.96146","0.00495"
"456.00000","66.99950","0.00540"
"456.45600","67.03764","0.00497"
"456.91200","67.07560","0.00492"
"457.36800","67.11357","0.00533"
"457.82400","67.15160","0.00515"
"458.28000","67.18950","0.00532"
"458.73600","67.22752","0.00565"
"459.19200","67.26556","0.00498"
"459.64800","67.30358","0.00505"
"460.10400","67.34155","0.00456"
"460.56000","67.37957","0.00482"
"461.01600","67.41754","0.00491"
"461.47200","67.45557","0.00487"
"461.92800","67.49354","0.00495"
"462.38400","67.53156","0.00551"
"462.84000","67.56958","0.00486"
"463.29600","67.60755","0.00508"
"463.75200","67.64558","0.00533"
"464.20800","67.68361","0.00501"
"464.66400","67.72151","0.00537"
"465.12000","67.75954","0.00519"
"465.57600","67.79756","0.00449"
"466.03200","67.83559","0.00434"
"466.48800","67.87361","0.00420"
"466.94400","67.91152","0.00464"
"467.40000","67.94955","0.00455"
"467.85600","67.98752","0.00471"
"468.31200","68.02554","0.00455"
"468.76800","68.06351","0.00465"
"469.22400","68.10159","0.00454"
"469.68000","68.13962","0.00451"
"470.13600","68.17753","0.00464"
"470.59200","68.21555","0.00490"
"471.04800","68.25352","0.00477"
"471.50400","68.29154","0.00485"
"471.96000","68.32964","0.00481"
"472.41600","68.36759","0.00442"
"472.87200","68.40556","0.00530"
"473.32800","68.44347","0.00491"
"473.78400","68.48156","0.00513"
"474.24000","68.51958","0.00470"
"474.69600","68.55760","0.00524"
"475.15200","68.59557","0.00464"
"475.60800","68.63354","0.00481"
"476.06400","68.67157","0.00483"
"476.52000","68.70947","0.00473"
"476.97600","68.74756","0.00499"
"477.43200","68.78558","0.00489"
"477.88800","68.82355","0.00448"
"478.34400","68.86157","0.00471"
"478.80000","68.89954","0.00528"
"479.25600","68.93757","0.00501"
"479.71200","68.97554","0.00472"
"480.16800","69.01357","0.00475"
"480.62400","69.05153","0.00529"
"481.08000","69.08955","0.00514"
"481.53600","69.12758","0.00473"
"481.99200","69.16561","0.00506"
"482.44800","69.20357","0.00511"
"482.90400","69.24154","0.00485"
"483.36000","69.27956","0.00488"
"483.81600","69.31766","0.00465"
"484.27200","69.35556","0.00509"
"484.72800","69.39359","0.00464"
"485.18400","69.43161","0.00469"
"485.64000","69.46952","0.00466"
"486.09600","69.50761","0.00473"
"486.55200","69.54557","0.00476"
"487.00800","69.58353","0.00483"
"487.46400","69.62157","0.00476"
"487.92000","69.65959","0.00474"
"488.37600","69.69749","0.00433"
"488.83200","69.73552","0.00463"
"489.28800","69.77349","0.00483"
"489.74400","69.81164","0.00506"
"490.20000","69.84960","0.00474"
"490.65600","69.88763","0.00500"
"491.11200","69.92553","0.00494"
"491.56800","69.96356","0.00496"
"492.02400","70.00153","0.00459"
"492.48000","70.03960","0.00534"
"492.93600","70.07764","0.00492"
"493.39200","70.11555","0.00484"
"493.84800","70.15357","0.00501"
"494.30400","70.19154","0.00464"
"494.76000","70.22950","0.00453"
"495.21600","70.26752","0.00478"
"495.67200","70.30556","0.00471"
"496.12800","70.34352","0.00507"
"496.58400","70.38155","0.00463"
"497.04000","70.41957","0.00471"
"497.49600","70.45754","0.00493"
"497.95200","70.49557","0.00524"
"498.40800","70.53359","0.00521"
"498.86400","70.57162","0.00496"
"499.32000","70.60964","0.00512"
"499.77600","70.64755","0.00496"
"500.23200","70.68558","0.00544"
"500.68800","70.72348","0.00554"
"501.14400","70.76157","0.00566"
"501.60000","70.79960","0.00547"
"502.05600","70.83750","0.00545"
"502.51200","70.87559","0.00538"
"502.96800","70.91355","0.00568"
"503.42400","70.95152","0.00530"
"503.88000","70.98955","0.00576"
"504.33600","71.02758","0.00569"
"504.79200","71.06560","0.00534"
"505.24800","71.10362","0.00557"
"505.70400","71.14159","0.00553"
"506.16000","71.17950","0.00572"
"506.61600","71.21752","0.00581"
"507.07200","71.25555","0.00563"
"507.52800","71.29358","0.00514"
"507.98400","71.33160","0.00555"
"508.44000","71.36964","0.00553"
"508.89600","71.40753","0.00563"
"509.35200","71.44550","0.00546"
"509.80800","71.48353","0.00540"
"510.26400","71.52161","0.00556"
"510.72000","71.55964","0.00556"
"511.17600","71.59760","0.00564"
"511.63200","71.63557","0.00566"
"512.08800","71.67355","0.00558"
"512.54400","71.71150","0.00533"
"513.00000","71.74959","0.00555"
"513.45600","71.78756","0.00601"
"513.91200","71.82558","0.00606"
"514.36800","71.86362","0.00605"
"514.82400","71.90157","0.00634"
"515.28000","71.93954","0.00620"
"515.73600","71.97751","0.00585"
"516.19200","72.01560","0.00605"
"516.64800","72.05356","0.00651"
"517.10400","72.09158","0.00615"
"517.56000","72.12955","0.00588"
"518.01600","72.16758","0.00626"
"518.47200","72.20554","0.00591"
"518.92800","72.24357","0.00596"
"519.38400","72.28154","0.00564"
"519.84000","72.31956","0.00586"
"520.29600","72.35760","0.00584"
"520.75200","72.39561","0.00625"
"521.20800","72.43359","0.00573"
"521.66400","72.47149","0.00597"
"522.12000","72.50958","0.00584"
"522.57600","72.54760","0.00581"
"523.03200","72.58557","0.00630"
"523.48800","72.62360","0.00634"
"523.94400","72.66156","0.00601"
"524.40000","72.69952","0.00567"
"524.85600","72.73750","0.00596"
"525.31200","72.77558","0.00613"
"525.76800","72.81361","0.00631"
"526.22400","72.85164","0.00611"
"526.68000","72.88960","0.00648"
"527.13600","72.92751","0.00617"
"527.59200","72.96553","0.00635"
"528.04800","73.00356","0.00683"
"528.50400","73.04158","0.00597"
"528.96000","73.07961","0.00600"
"529.41600","73.11758","0.00580"
"529.87200","73.15555","0.00587"
"530.32800","73.19351","0.00591"
"530.78400","73.23154","0.00617"
"531.24000","73.26956","0.00648"
"531.69600","73.30759","0.00589"
"532.15200","73.34550","0.00679"
"532.60800","73.38351","0.00626"
"533.06400","73.42155","0.00642"
"533.52000","73.45951","0.00638"
"533.97600","73.49760","0.00622"
"534.43200","73.53557","0.00616"
"534.88800","73.57359","0.00587"
"535.34400","73.61162","0.00624"
"535.80000","73.64958","0.00570"
"536.25600","73.68755","0.00652"
"536.71200","73.72552","0.00624"
"537.16800","73.76354","0.00622"
"537.62400","73.80157","0.00586"
"538.08000","73.83954","0.00634"
"538.53600","73.87762","0.00630"
"538.99200","73.91553","0.00631"
"539.44800","73.95355","0.00653"
"539.90400","73.99152","0.00637"
"540.36000","74.02955","0.00455"
"540.81600","74.06757","0.00388"
"541.27200","74.10560","0.00396"
"541.72800","74.14357","0.00514"
"542.18400","74.18147","0.00449"
"542.64000","74.21955","0.00462"
"543.09600","74.25758","0.00380"
"543.55200","74.29561","0.00437"
"544.00800","74.33364","0.00354"
"544.46400","74.37160","0.00415"
"544.92000","74.40951","0.00375"
"545.37600","74.44747","0.00406"
"545.83200","74.48557","0.00384"
"546.28800","74.52359","0.00417"
"546.74400","74.56155","0.00409"
"547.20000","74.59964","0.00437"
"547.65600","74.63755","0.00466"
"548.11200","74.67551","0.00441"
"548.56800","74.71354","0.00444"
"549.02400","74.75163","0.00437"
"549.48000","74.78959","0.00499"
"549.93600","74.82756","0.00469"
"550.39200","74.86559","0.00467"
"550.84800","74.90355","0.00483"
"551.30400","74.94151","0.00498"
"551.76000","74.97955","0.00512"
"552.21600","75.01757","0.00483"
"552.67200","75.05560","0.00517"
"553.12800","75.09356","0.00502"
"553.58400","75.13153","0.00518"
"554.04000","75.16956","0.00541"
"554.49600","75.20752","0.00561"
"554.95200","75.24554","0.00529"
"555.40800","75.28357","0.00548"
"555.86400","75.32154","0.00550"
"556.32000","75.35957","0.00543"
"556.77600","75.39759","0.00574"
"557.23200","75.43555","0.00554"
"557.68800","75.47346","0.00556"
"558.14400","75.51155","0.00582"
"558.60000","75.54958","0.00582"
"559.05600","75.58760","0.00595"
"559.51200","75.62557","0.00610"
"559.96800","75.66354","0.00573"
"560.42400","75.70151","0.00572"
"560.88000","75.73952","0.00586"
"561.33600","75.77755","0.00593"
"561.79200","75.81564","0.00641"
"562.24800","75.85361","0.00606"
"562.70400","75.89157","0.00601"
"563.16000","75.92953","0.00619"
"563.61600","75.96757","0.00617"
"564.07200","76.00559","0.00609"
"564.52800","76.04362","0.00633"
"564.98400","76.08158","0.00640"
"565.44000","76.11955","0.00641"
"565.89600","76.15752","0.00641"
"566.35200","76.19555","0.00688"
"566.80800","76.23357","0.00642"
"567.26400","76.27159","0.00630"
"567.72000","76.30956","0.00682"
"568.17600","76.34765","0.00664"
"568.63200","76.38555","0.00678"
"569.08800","76.42352","0.00700"
"569.54400","76.46155","0.00708"
"570.00000","76.49957","0.00671"
"570.45600","76.53754","0.00707"
"570.91200","76.57556","0.00726"
"571.36800","76.61359","0.00742"
"571.82400","76.65156","0.00734"
"572.28000","76.68958","0.00706"
"572.73600","76.72755","0.00745"
"573.19200","76.76552","0.00718"
"573.64800","76.80354","0.00703"
"574.10400","76.84157","0.00725"
"574.56000","76.87959","0.00761"
"575.01600","76.91756","0.00781"
"575.47200","76.95553","0.00738"
"575.92800","76.99355","0.00737"
"576.38400","77.03159","0.00768"
"576.84000","77.06960","0.00797"
"577.29600","77.10763","0.00779"
"577.75200","77.14554","0.00776"
"578.20800","77.18351","0.00765"
"578.66400","77.22153","0.00794"
"579.12000","77.25955","0.00781"
"579.57600","77.29758","0.00780"
"580.03200","77.33561","0.00753"
"580.48800","77.37351","0.00796"
"580.94400","77.41154","0.00809"
"581.40000","77.44951","0.00821"
"581.85600","77.48753","0.00843"
"582.31200","77.52562","0.00819"
"582.76800","77.56358","0.00836"
"583.22400","77.60161","0.00806"
"583.68000","77.63958","0.00834"
"584.13600","77.67749","0.00770"
"584.59200","77.71557","0.00809"
"585.04800","77.75359","0.00828"
"585.50400","77.79156","0.00788"
"585.96000","77.82959","0.00786"
"586.41600","77.86756","0.00773"
"586.87200","77.90552","0.00656"
"587.32800","77.94355","0.00642"
"587.78400","77.98158","0.00630"
"588.24000","78.01961","0.00638"
"588.69600","78.05756","0.00623"
"589.15200","78.09560","0.00650"
"589.60800","78.13356","0.00618"
"590.06400","78.17158","0.00665"
"590.52000","78.20956","0.00709"
"590.97600","78.24752","0.00684"
"591.43200","78.28555","0.00693"
"591.88800","78.32356","0.00700"
"592.34400","78.36160","0.00632"
"592.80000","78.39956","0.00583"
"593.25600","78.43752","0.00669"
"593.71200","78.47556","0.00647"
"594.16800","78.51352","0.00685"
"594.62400","78.55154","0.00632"
"595.08000","78.58962","0.00715"
"595.53600","78.62760","0.00653"
"595.99200","78.66551","0.00699"
"596.44800","78.70354","0.00687"
"596.90400","78.74150","0.00723"
"597.36000","78.77958","0.00724"
"597.81600","78.81761","0.00730"
"598.27200","78.85558","0.00706"
"598.72800","78.89349","0.00709"
"599.18400","78.93151","0.00761"
"599.64000","78.96953","0.00731"
"600.09600","79.00757","0.00745"
"600.55200","79.04565","0.00527"
"601.00800","79.08360","0.00258"
"601.46400","79.12158","0.00196"
"601.92000","79.15948","0.00172"
"602.37600","79.19752","0.00255"
"602.83200","79.23559","0.00170"
"603.28800","79.27357","0.00254"
"603.74400","79.31153","0.00228"
"604.20000","79.34956","0.00243"
"604.65600","79.38751","0.00163"
"605.11200","79.42554","0.00211"
"605.56800","79.46358","0.00237"
"606.02400","79.50161","0.00203"
"606.48000","79.53957","0.00239"
"606.93600","79.57754","0.00214"
"607.39200","79.61556","0.00268"
"607.84800","79.65353","0.00223"
"608.30400","79.69156","0.00226"
"608.76000","79.72952","0.00224"
"609.21600","79.76755","0.00228"
"609.67200","79.80552","0.00219"
"610.12800","79.84354","0.00234"
"610.58400","79.88163","0.00251"
"611.04000","79.91947","0.00266"
"611.49600","79.95755","0.00237"
"611.95200","79.99553","0.00256"
"612.40800","80.03362","0.00253"
"612.86400","80.07162","0.00257"
"613.32000","80.10954","0.00270"
"613.77600","80.14758","0.00264"
"614.23200","80.18547","0.00278"
"614.68800","80.22356","0.00237"
"615.14400","80.26159","0.00234"
"615.60000","80.29961","0.00281"
"616.05600","80.33765","0.00292"
"616.51200","80.37560","0.00281"
"616.96800","80.41351","0.00255"
"617.42400","80.45148","0.00285"
"617.88000","80.48956","0.00296"
"618.33600","80.52760","0.00268"
"618.79200","80.56556","0.00307"
"619.24800","80.60358","0.00284"
"619.70400","80.64149","0.00279"
"620.16000","80.67951","0.00305"
"620.61600","80.71754","0.00294"
"621.07200","80.75562","0.00281"
"621.52800","80.79354","0.00258"
"621.98400","80.83157","0.00291"
"622.44000","80.86953","0.00304"
"622.89600","80.90749","0.00278"
"623.35200","80.94557","0.00232"
"623.80800","80.98361","0.00261"
"624.26400","81.02164","0.00251"
"624.72000","81.05953","0.00272"
"625.17600","81.09756","0.00233"
"625.63200","81.13559","0.00284"
"626.08800","81.17356","0.00247"
"626.54400","81.21152","0.00251"
"627.00000","81.24955","0.00261"
"627.45600","81.28757","0.00287"
"627.91200","81.32561","0.00260"
"628.36800","81.36357","0.00266"
"628.82400","81.40154","0.00250"
"629.28000","81.43955","0.00243"
"629.73600","81.47753","0.00233"
"630.19200","81.51562","0.00274"
"630.64800","81.55358","0.00289"
"631.10400","81.59161","0.00284"
"631.56000","81.62958","0.00250"
"632.01600","81.66753","0.00268"
"632.47200","81.70557","0.00285"
"632.92800","81.74353","0.00261"
"633.38400","81.78156","0.00249"
"633.84000","81.81964","0.00244"
"634.29600","81.85755","0.00274"
"634.75200","81.89552","0.00261"
"635.20800","81.93354","0.00287"
"635.66400","81.97157","0.00268"
"636.12000","82.00959","0.00243"
"636.57600","82.04757","0.00296"
"637.03200","82.08565","0.00286"
"637.48800","82.12350","0.00284"
"637.94400","82.16146","0.00300"
"638.40000","82.19955","0.00256"
"638.85600","82.23763","0.00312"
"639.31200","82.27560","0.00272"
"639.76800","82.31357","0.00276"
"640.22400","82.35159","0.00286"
"640.68000","82.38950","0.00263"
"641.13600","82.42757","0.00233"
"641.59200","82.46555","0.00284"
"642.04800","82.50352","0.00275"
"642.50400","82.54155","0.00256"
"642.96000","82.57956","0.00288"
"643.41600","82.61760","0.00283"
"643.87200","82.65550","0.00293"
"644.32800","82.69353","0.00247"
"644.78400","82.73161","0.00309"
"645.24000","82.76963","0.00320"
"645.69600","82.80755","0.00309"
"646.15200","82.84557","0.00252"
"646.60800","82.88361","0.00286"
"647.06400","82.92151","0.00282"
"647.52000","82.95959","0.00282"
"647.97600","82.99756","0.00274"
"648.43200","83.03559","0.00320"
"648.88800","83.07361","0.00242"
"649.34400","83.11152","0.00284"
"649.80000","83.14948","0.00276"
"650.25600","83.18752","0.00280"
"650.71200","83.22552","0.00277"
"651.16800","83.26356","0.00260"
"651.62400","83.30159","0.00267"
"652.08000","83.33961","0.00248"
"652.53600","83.37759","0.00274"
"652.99200","83.41548","0.00257"
"653.44800","83.45351","0.00259"
"653.90400","83.49159","0.00271"
"654.36000","83.52962","0.00269"
"654.81600","83.56758","0.00285"
"655.27200","83.60550","0.00276"
"655.72800","83.64346","0.00291"
"656.18400","83.68156","0.00246"
"656.64000","83.71957","0.00298"
"657.09600","83.75754","0.00287"
"657.55200","83.79557","0.00330"
"658.00800","83.83360","0.00278"
"658.46400","83.87150","0.00310"
"658.92000","83.90952","0.00294"
"659.37600","83.94756","0.00321"
"659.83200","83.98558","0.00345"
"660.28800","84.02361","0.00296"
"660.74400","84.06156","0.00302"
"661.20000","84.09959","0.00318"
"661.65600","84.13756","0.00286"
"662.11200","84.17554","0.00289"
"662.56800","84.21355","0.00303"
"663.02400","84.25158","0.00280"
"663.48000","84.28954","0.00317"
"663.93600","84.32758","0.00320"
"664.39200","84.36554","0.00291"
"664.84800","84.40350","0.00328"
"665.30400","84.44147","0.00286"
"665.76000","84.47956","0.00347"
"666.21600","84.51753","0.00318"
"666.67200","84.55561","0.00361"
"667.12800","84.59358","0.00347"
"667.58400","84.63155","0.00353"
"668.04000","84.66952","0.00359"
"668.49600","84.70754","0.00353"
"668.95200","84.74562","0.00366"
"669.40800","84.78359","0.00363"
"669.86400","84.82162","0.00348"
"670.32000","84.85952","0.00348"
"670.77600","84.89749","0.00372"
"671.23200","84.93551","0.00370"
"671.68800","84.97360","0.00347"
"672.14400","85.01157","0.00363"
"672.60000","85.04954","0.00361"
"673.05600","85.08756","0.00384"
"673.51200","85.12553","0.00404"
"673.96800","85.16350","0.00372"
"674.42400","85.20158","0.00383"
"674.88000","85.23960","0.00359"
"675.02800","85.25186","0.00407"