File: Force_trajectories/161221_1/Specimen_RawData_3.csv
End date,"12/21/2016"
Specimen label,"23DG_88"
Maximum Load,"0.00944",N

Time,Extension,Load
(s),(mm),(N)
"0.00000","0.00000","0.00017"
"0.30600","0.02511","0.00056"
"0.61200","0.05124","0.00078"
"0.91800","0.07677","0.00074"
"1.22400","0.10218","0.00084"
"1.53000","0.12771","0.00115"
"1.83600","0.15324","0.00084"
"2.14200","0.17871","0.00143"
"2.44800","0.20424","0.00119"
"2.75400","0.22965","0.00097"
"3.06000","0.25524","0.00096"
"3.36600","0.28065","0.00140"
"3.67200","0.30624","0.00123"
"3.97800","0.33165","0.00129"
"4.28400","0.35712","0.00139"
"4.59000","0.38271","0.00148"
"4.89600","0.40818","0.00139"
"5.20200","0.43377","0.00137"
"5.50800","0.45918","0.00147"
"5.81400","0.48477","0.00164"
"6.12000","0.51012","0.00110"
"6.42600","0.53565","0.00149"
"6.73200","0.56118","0.00160"
"7.03800","0.58665","0.00139"
"7.34400","0.61219","0.00155"
"7.65000","0.63766","0.00140"
"7.95600","0.66325","0.00147"
"8.26200","0.68866","0.00146"
"8.56800","0.71413","0.00157"
"8.87400","0.73966","0.00161"
"9.18000","0.76513","0.00160"
"9.48600","0.79072","0.00131"
"9.79200","0.81619","0.00160"
"10.09800","0.84172","0.00155"
"10.40400","0.86719","0.00139"
"10.71000","0.89266","0.00169"
"11.01600","0.91819","0.00149"
"11.32200","0.94366","0.00127"
"11.62800","0.96919","0.00158"
"11.93400","0.99466","0.00174"
"12.24000","1.02025","0.00173"
"12.54600","1.04566","0.00177"
"12.85200","1.07119","0.00142"
"13.15800","1.09666","0.00164"
"13.46400","1.12213","0.00155"
"13.77000","1.14772","0.00160"
"14.07600","1.17319","0.00165"
"14.38200","1.19872","0.00118"
"14.68800","1.22419","0.00163"
"14.99400","1.24972","0.00151"
"15.30000","1.27519","0.00185"
"15.60600","1.30072","0.00179"
"15.91200","1.32619","0.00119"
"16.21800","1.35166","0.00193"
"16.52400","1.37725","0.00170"
"16.83000","1.40266","0.00194"
"17.13600","1.42819","0.00168"
"17.44200","1.45372","0.00162"
"17.74800","1.47913","0.00150"
"18.05400","1.50466","0.00150"
"18.36000","1.53013","0.00195"
"18.66600","1.55572","0.00164"
"18.97200","1.58113","0.00188"
"19.27800","1.60672","0.00193"
"19.58400","1.63219","0.00176"
"19.89000","1.65766","0.00185"
"20.19600","1.68325","0.00206"
"20.50200","1.70872","0.00144"
"20.80800","1.73420","0.00194"
"21.11400","1.75967","0.00185"
"21.42000","1.78526","0.00180"
"21.72600","1.81067","0.00191"
"22.03200","1.83614","0.00195"
"22.33800","1.86167","0.00148"
"22.64400","1.88720","0.00182"
"22.95000","1.91273","0.00211"
"23.25600","1.93814","0.00196"
"23.56200","1.96373","0.00166"
"23.86800","1.98920","0.00181"
"24.17400","2.01467","0.00168"
"24.48000","2.04014","0.00167"
"24.78600","2.06567","0.00136"
"25.09200","2.09120","0.00196"
"25.39800","2.11661","0.00163"
"25.70400","2.14220","0.00165"
"26.01000","2.16767","0.00208"
"26.31600","2.19320","0.00169"
"26.62200","2.21867","0.00153"
"26.92800","2.24420","0.00155"
"27.23400","2.26967","0.00170"
"27.54000","2.29514","0.00156"
"27.84600","2.32067","0.00176"
"28.15200","2.34614","0.00145"
"28.45800","2.37173","0.00186"
"28.76400","2.39720","0.00160"
"29.07000","2.42267","0.00167"
"29.37600","2.44820","0.00154"
"29.68200","2.47361","0.00170"
"29.98800","2.49920","0.00158"
"30.29400","2.52467","0.00165"
"30.60000","2.55020","0.00151"
"30.90600","2.57567","0.00156"
"31.21200","2.60120","0.00163"
"31.51800","2.62667","0.00165"
"31.82400","2.65214","0.00174"
"32.13000","2.67767","0.00168"
"32.43600","2.70308","0.00178"
"32.74200","2.72867","0.00159"
"33.04800","2.75420","0.00202"
"33.35400","2.77968","0.00147"
"33.66000","2.80521","0.00152"
"33.96600","2.83068","0.00144"
"34.27200","2.85615","0.00182"
"34.57800","2.88168","0.00160"
"34.88400","2.90721","0.00186"
"35.19000","2.93274","0.00162"
"35.49600","2.95821","0.00171"
"35.80200","2.98374","0.00183"
"36.10800","3.00915","0.00168"
"36.41400","3.03474","0.00189"
"36.72000","3.06015","0.00170"
"37.02600","3.08574","0.00206"
"37.33200","3.11121","0.00140"
"37.63800","3.13674","0.00188"
"37.94400","3.16221","0.00152"
"38.25000","3.18768","0.00175"
"38.55600","3.21315","0.00178"
"38.86200","3.23862","0.00170"
"39.16800","3.26421","0.00146"
"39.47400","3.28968","0.00165"
"39.78000","3.31521","0.00149"
"40.08600","3.34068","0.00185"
"40.39200","3.36621","0.00140"
"40.69800","3.39168","0.00159"
"41.00400","3.41715","0.00181"
"41.31000","3.44274","0.00170"
"41.61600","3.46815","0.00199"
"41.92200","3.49368","0.00155"
"42.22800","3.51921","0.00164"
"42.53400","3.54468","0.00197"
"42.84000","3.57021","0.00205"
"43.14600","3.59562","0.00184"
"43.45200","3.62121","0.00168"
"43.75800","3.64668","0.00191"
"44.06400","3.67215","0.00161"
"44.37000","3.69768","0.00191"
"44.67600","3.72315","0.00162"
"44.98200","3.74874","0.00167"
"45.28800","3.77415","0.00177"
"45.59400","3.79968","0.00170"
"45.90000","3.82515","0.00188"
"46.20600","3.85069","0.00239"
"46.51200","3.87622","0.00187"
"46.81800","3.90169","0.00182"
"47.12400","3.92722","0.00232"
"47.43000","3.95269","0.00184"
"47.73600","3.97822","0.00194"
"48.04200","4.00363","0.00211"
"48.34800","4.02922","0.00195"
"48.65400","4.05469","0.00190"
"48.96000","4.08022","0.00187"
"49.26600","4.10569","0.00134"
"49.57200","4.13116","0.00173"
"49.87800","4.15663","0.00188"
"50.18400","4.18216","0.00206"
"50.49000","4.20769","0.00202"
"50.79600","4.23316","0.00187"
"51.10200","4.25869","0.00170"
"51.40800","4.28416","0.00207"
"51.71400","4.30963","0.00122"
"52.02000","4.33516","0.00139"
"52.32600","4.36063","0.00189"
"52.63200","4.38622","0.00174"
"52.93800","4.41169","0.00218"
"53.24400","4.43722","0.00171"
"53.55000","4.46275","0.00197"
"53.85600","4.48816","0.00219"
"54.16200","4.51369","0.00198"
"54.46800","4.53910","0.00196"
"54.77400","4.56469","0.00200"
"55.08000","4.59016","0.00194"
"55.38600","4.61569","0.00155"
"55.69200","4.64122","0.00168"
"55.99800","4.66669","0.00158"
"56.30400","4.69222","0.00146"
"56.61000","4.71763","0.00206"
"56.91600","4.74328","0.00225"
"57.22200","4.76869","0.00173"
"57.52800","4.79416","0.00204"
"57.83400","4.81963","0.00218"
"58.14000","4.84516","0.00195"
"58.44600","4.87075","0.00216"
"58.75200","4.89616","0.00175"
"59.05800","4.92170","0.00202"
"59.36400","4.94723","0.00217"
"59.67000","4.97269","0.00232"
"59.97600","4.99817","0.00217"
"60.28200","5.02370","0.00182"
"60.58800","5.04923","0.00188"
"60.89400","5.07470","0.00217"
"61.20000","5.10017","0.00199"
"61.50600","5.12564","0.00209"
"61.81200","5.15117","0.00197"
"62.11800","5.17670","0.00190"
"62.42400","5.20217","0.00208"
"62.73000","5.22770","0.00213"
"63.03600","5.25317","0.00228"
"63.34200","5.27870","0.00217"
"63.64800","5.30411","0.00206"
"63.95400","5.32970","0.00189"
"64.26000","5.35517","0.00211"
"64.56600","5.38070","0.00215"
"64.87200","5.40617","0.00201"
"65.17800","5.43170","0.00216"
"65.48400","5.45723","0.00191"
"65.79000","5.48264","0.00193"
"66.09600","5.50817","0.00215"
"66.40200","5.53370","0.00238"
"66.70800","5.55917","0.00201"
"67.01400","5.58470","0.00240"
"67.32000","5.61023","0.00192"
"67.62600","5.63570","0.00199"
"67.93200","5.66117","0.00250"
"68.23800","5.68676","0.00232"
"68.54400","5.71217","0.00260"
"68.85000","5.73764","0.00206"
"69.15600","5.76323","0.00245"
"69.46200","5.78870","0.00196"
"69.76800","5.81423","0.00244"
"70.07400","5.83970","0.00237"
"70.38000","5.86523","0.00263"
"70.68600","5.89070","0.00235"
"70.99200","5.91611","0.00239"
"71.29800","5.94170","0.00262"
"71.60400","5.96717","0.00240"
"71.91000","5.99270","0.00267"
"72.21600","6.01812","0.00263"
"72.52200","6.04371","0.00264"
"72.82800","6.06918","0.00252"
"73.13400","6.09471","0.00254"
"73.44000","6.12018","0.00259"
"73.74600","6.14565","0.00270"
"74.05200","6.17124","0.00258"
"74.35800","6.19671","0.00267"
"74.66400","6.22224","0.00258"
"74.97000","6.24765","0.00231"
"75.27600","6.27318","0.00253"
"75.58200","6.29865","0.00265"
"75.88800","6.32418","0.00220"
"76.19400","6.34971","0.00247"
"76.50000","6.37518","0.00307"
"76.80600","6.40071","0.00287"
"77.11200","6.42618","0.00234"
"77.41800","6.45171","0.00277"
"77.72400","6.47718","0.00258"
"78.03000","6.50265","0.00257"
"78.33600","6.52818","0.00286"
"78.64200","6.55365","0.00245"
"78.94800","6.57918","0.00265"
"79.25400","6.60465","0.00290"
"79.56000","6.63018","0.00263"
"79.86600","6.65571","0.00270"
"80.17200","6.68118","0.00247"
"80.47800","6.70671","0.00280"
"80.78400","6.73218","0.00276"
"81.09000","6.75771","0.00273"
"81.39600","6.78318","0.00278"
"81.70200","6.80871","0.00260"
"82.00800","6.83418","0.00273"
"82.31400","6.85971","0.00235"
"82.62000","6.88524","0.00269"
"82.92600","6.91065","0.00262"
"83.23200","6.93618","0.00247"
"83.53800","6.96165","0.00278"
"83.84400","6.98718","0.00300"
"84.15000","7.01271","0.00287"
"84.45600","7.03818","0.00291"
"84.76200","7.06371","0.00293"
"85.06800","7.08919","0.00284"
"85.37400","7.11472","0.00289"
"85.68000","7.14019","0.00301"
"85.98600","7.16572","0.00321"
"86.29200","7.19119","0.00274"
"86.59800","7.21666","0.00306"
"86.90400","7.24219","0.00272"
"87.21000","7.26766","0.00300"
"87.51600","7.29319","0.00261"
"87.82200","7.31866","0.00286"
"88.12800","7.34419","0.00271"
"88.43400","7.36972","0.00308"
"88.74000","7.39525","0.00290"
"89.04600","7.42072","0.00285"
"89.35200","7.44613","0.00296"
"89.65800","7.47166","0.00310"
"89.96400","7.49713","0.00273"
"90.27000","7.52272","0.00312"
"90.57600","7.54819","0.00305"
"90.88200","7.57372","0.00300"
"91.18800","7.59919","0.00305"
"91.49400","7.62472","0.00274"
"91.80000","7.65019","0.00300"
"92.10600","7.67566","0.00273"
"92.41200","7.70119","0.00281"
"92.71800","7.72666","0.00251"
"93.02400","7.75219","0.00270"
"93.33000","7.77766","0.00298"
"93.63600","7.80313","0.00289"
"93.94200","7.82872","0.00285"
"94.24800","7.85413","0.00291"
"94.55400","7.87966","0.00284"
"94.86000","7.90513","0.00300"
"95.16600","7.93072","0.00280"
"95.47200","7.95619","0.00317"
"95.77800","7.98166","0.00317"
"96.08400","8.00719","0.00273"
"96.39000","8.03260","0.00291"
"96.69600","8.05819","0.00282"
"97.00200","8.08366","0.00277"
"97.30800","8.10925","0.00283"
"97.61400","8.13472","0.00285"
"97.92000","8.16020","0.00290"
"98.22600","8.18572","0.00269"
"98.53200","8.21114","0.00298"
"98.83800","8.23667","0.00290"
"99.14400","8.26214","0.00309"
"99.45000","8.28773","0.00268"
"99.75600","8.31320","0.00299"
"100.06200","8.33873","0.00339"
"100.36800","8.36420","0.00304"
"100.67400","8.38967","0.00281"
"100.98000","8.41520","0.00276"
"101.28600","8.44061","0.00301"
"101.59200","8.46620","0.00304"
"101.89800","8.49173","0.00279"
"102.20400","8.51720","0.00292"
"102.51000","8.54267","0.00302"
"102.81600","8.56820","0.00322"
"103.12200","8.59373","0.00283"
"103.42800","8.61914","0.00346"
"103.73400","8.64467","0.00329"
"104.04000","8.67020","0.00315"
"104.34600","8.69573","0.00283"
"104.65200","8.72120","0.00295"
"104.95800","8.74673","0.00296"
"105.26400","8.77220","0.00309"
"105.57000","8.79761","0.00294"
"105.87600","8.82320","0.00313"
"106.18200","8.84867","0.00302"
"106.48800","8.87426","0.00303"
"106.79400","8.89973","0.00288"
"107.10000","8.92520","0.00280"
"107.40600","8.95073","0.00311"
"107.71200","8.97614","0.00254"
"108.01800","9.00173","0.00308"
"108.32400","9.02714","0.00263"
"108.63000","9.05273","0.00276"
"108.93600","9.07814","0.00295"
"109.24200","9.10367","0.00272"
"109.54800","9.12920","0.00280"
"109.85400","9.15467","0.00290"
"110.16000","9.18014","0.00320"
"110.46600","9.20562","0.00312"
"110.77200","9.23120","0.00281"
"111.07800","9.25667","0.00324"
"111.38400","9.28221","0.00312"
"111.69000","9.30774","0.00268"
"111.99600","9.33315","0.00298"
"112.30200","9.35868","0.00300"
"112.60800","9.38415","0.00294"
"112.91400","9.40968","0.00296"
"113.22000","9.43521","0.00303"
"113.52600","9.46074","0.00296"
"113.83200","9.48621","0.00300"
"114.13800","9.51168","0.00301"
"114.44400","9.53721","0.00315"
"114.75000","9.56262","0.00303"
"115.05600","9.58821","0.00315"
"115.36200","9.61368","0.00322"
"115.66800","9.63921","0.00296"
"115.97400","9.66468","0.00296"
"116.28000","9.69015","0.00310"
"116.58600","9.71568","0.00316"
"116.89200","9.74115","0.00271"
"117.19800","9.76674","0.00329"
"117.50400","9.79215","0.00311"
"117.81000","9.81768","0.00298"
"118.11600","9.84321","0.00304"
"118.42200","9.86868","0.00336"
"118.72800","9.89421","0.00268"
"119.03400","9.91962","0.00308"
"119.34000","9.94521","0.00278"
"119.64600","9.97068","0.00325"
"119.95200","9.99621","0.00297"
"120.25800","10.02174","0.00299"
"120.56400","10.04721","0.00260"
"120.87000","10.07274","0.00285"
"121.17600","10.09815","0.00262"
"121.48200","10.12374","0.00249"
"121.78800","10.14915","0.00321"
"122.09400","10.17468","0.00306"
"122.40000","10.20021","0.00296"
"122.70600","10.22568","0.00312"
"123.01200","10.25127","0.00270"
"123.31800","10.27662","0.00273"
"123.62400","10.30221","0.00278"
"123.93000","10.32769","0.00309"
"124.23600","10.35322","0.00282"
"124.54200","10.37869","0.00265"
"124.84800","10.40416","0.00285"
"125.15400","10.42969","0.00279"
"125.46000","10.45516","0.00270"
"125.76600","10.48075","0.00332"
"126.07200","10.50616","0.00304"
"126.37800","10.53169","0.00324"
"126.68400","10.55716","0.00291"
"126.99000","10.58269","0.00287"
"127.29600","10.60822","0.00301"
"127.60200","10.63369","0.00264"
"127.90800","10.65922","0.00285"
"128.21400","10.68463","0.00277"
"128.52000","10.71022","0.00257"
"128.82600","10.73569","0.00261"
"129.13200","10.76116","0.00293"
"129.43800","10.78675","0.00307"
"129.74400","10.81216","0.00288"
"130.05000","10.83775","0.00258"
"130.35600","10.86316","0.00282"
"130.66200","10.88875","0.00301"
"130.96800","10.91422","0.00270"
"131.27400","10.93963","0.00261"
"131.58000","10.96522","0.00300"
"131.88600","10.99069","0.00282"
"132.19200","11.01628","0.00301"
"132.49800","11.04163","0.00271"
"132.80400","11.06722","0.00243"
"133.11000","11.09269","0.00219"
"133.41600","11.11816","0.00253"
"133.72200","11.14369","0.00227"
"134.02800","11.16916","0.00224"
"134.33400","11.19475","0.00215"
"134.64000","11.22016","0.00234"
"134.94600","11.24575","0.00262"
"135.25200","11.27116","0.00264"
"135.55800","11.29669","0.00255"
"135.86400","11.32222","0.00242"
"136.17000","11.34770","0.00235"
"136.47600","11.37322","0.00220"
"136.78200","11.39863","0.00240"
"137.08800","11.42423","0.00224"
"137.39400","11.44969","0.00222"
"137.70000","11.47517","0.00257"
"138.00600","11.50064","0.00201"
"138.31200","11.52617","0.00217"
"138.61800","11.55170","0.00209"
"138.92400","11.57717","0.00174"
"139.23000","11.60270","0.00244"
"139.53600","11.62817","0.00169"
"139.84200","11.65370","0.00202"
"140.14800","11.67917","0.00203"
"140.45400","11.70470","0.00201"
"140.76000","11.73023","0.00206"
"141.06600","11.75564","0.00178"
"141.37200","11.78123","0.00194"
"141.67800","11.80670","0.00201"
"141.98400","11.83217","0.00165"
"142.29000","11.85764","0.00134"
"142.59600","11.88317","0.00149"
"142.90200","11.90870","0.00127"
"143.20800","11.93417","0.00139"
"143.51400","11.95976","0.00138"
"143.82000","11.98523","0.00128"
"144.12600","12.01070","0.00157"
"144.43200","12.03617","0.00147"
"144.73800","12.06170","0.00157"
"145.04400","12.08723","0.00170"
"145.35000","12.11264","0.00163"
"145.65600","12.13823","0.00134"
"145.96200","12.16370","0.00149"
"146.26800","12.18923","0.00134"
"146.57400","12.21470","0.00134"
"146.88000","12.24017","0.00108"
"147.18600","12.26564","0.00150"
"147.49200","12.29111","0.00124"
"147.79800","12.31670","0.00106"
"148.10400","12.34217","0.00122"
"148.41000","12.36770","0.00158"
"148.71600","12.39318","0.00128"
"149.02200","12.41870","0.00133"
"149.32800","12.44423","0.00162"
"149.63400","12.46971","0.00150"
"149.94000","12.49523","0.00140"
"150.24600","12.52065","0.00172"
"150.55200","12.54624","0.00162"
"150.85800","12.57171","0.00142"
"151.16400","12.59724","0.00137"
"151.47000","12.62271","0.00165"
"151.77600","12.64818","0.00128"
"152.08200","12.67365","0.00186"
"152.38800","12.69912","0.00164"
"152.69400","12.72471","0.00167"
"153.00000","12.75018","0.00169"
"153.30600","12.77571","0.00135"
"153.61200","12.80118","0.00181"
"153.91800","12.82671","0.00148"
"154.22400","12.85218","0.00168"
"154.53000","12.87765","0.00124"
"154.83600","12.90318","0.00172"
"155.14200","12.92871","0.00172"
"155.44800","12.95418","0.00160"
"155.75400","12.97971","0.00064"
"156.06000","13.00518","0.00184"
"156.36600","13.03071","0.00166"
"156.67200","13.05612","0.00161"
"156.97800","13.08171","0.00095"
"157.28400","13.10712","0.00156"
"157.59000","13.13271","0.00108"
"157.89600","13.15818","0.00113"
"158.20200","13.18371","0.00124"
"158.50800","13.20924","0.00109"
"158.81400","13.23465","0.00130"
"159.12000","13.26018","0.00186"
"159.42600","13.28565","0.00156"
"159.73200","13.31124","0.00155"
"160.03800","13.33665","0.00176"
"160.34400","13.36218","0.00220"
"160.65000","13.38771","0.00128"
"160.95600","13.41318","0.00151"
"161.26200","13.43871","0.00173"
"161.56800","13.46412","0.00185"
"161.87400","13.48971","0.00167"
"162.18000","13.51525","0.00169"
"162.48600","13.54072","0.00134"
"162.79200","13.56625","0.00139"
"163.09800","13.59166","0.00167"
"163.40400","13.61719","0.00135"
"163.71000","13.64260","0.00165"
"164.01600","13.66825","0.00143"
"164.32200","13.69372","0.00126"
"164.62800","13.71925","0.00157"
"164.93400","13.74472","0.00177"
"165.24000","13.77019","0.00173"
"165.54600","13.79572","0.00183"
"165.85200","13.82113","0.00156"
"166.15800","13.84672","0.00187"
"166.46400","13.87219","0.00184"
"166.77000","13.89778","0.00152"
"167.07600","13.92325","0.00174"
"167.38200","13.94866","0.00192"
"167.68800","13.97419","0.00192"
"167.99400","13.99960","0.00203"
"168.30000","14.02519","0.00163"
"168.60600","14.05066","0.00186"
"168.91200","14.07619","0.00171"
"169.21800","14.10166","0.00133"
"169.52400","14.12719","0.00171"
"169.83000","14.15266","0.00180"
"170.13600","14.17813","0.00195"
"170.44200","14.20366","0.00157"
"170.74800","14.22913","0.00181"
"171.05400","14.25466","0.00174"
"171.36000","14.28019","0.00199"
"171.66600","14.30572","0.00212"
"171.97200","14.33125","0.00178"
"172.27800","14.35666","0.00189"
"172.58400","14.38219","0.00181"
"172.89000","14.40766","0.00223"
"173.19600","14.43319","0.00212"
"173.50200","14.45872","0.00203"
"173.80800","14.48425","0.00163"
"174.11400","14.50972","0.00236"
"174.42000","14.53513","0.00226"
"174.72600","14.56067","0.00194"
"175.03200","14.58614","0.00216"
"175.33800","14.61166","0.00179"
"175.64400","14.63720","0.00233"
"175.95000","14.66272","0.00202"
"176.25600","14.68820","0.00213"
"176.56200","14.71367","0.00200"
"176.86800","14.73920","0.00193"
"177.17400","14.76467","0.00202"
"177.48000","14.79020","0.00236"
"177.78600","14.81567","0.00189"
"178.09200","14.84120","0.00217"
"178.39800","14.86673","0.00209"
"178.70400","14.89214","0.00218"
"179.01000","14.91773","0.00206"
"179.31600","14.94314","0.00249"
"179.62200","14.96873","0.00194"
"179.92800","14.99414","0.00213"
"180.23400","15.01973","0.00190"
"180.54000","15.04520","0.00183"
"180.84600","15.07067","0.00199"
"181.15200","15.09614","0.00187"
"181.45800","15.12167","0.00199"
"181.76400","15.14720","0.00204"
"182.07000","15.17267","0.00226"
"182.37600","15.19820","0.00228"
"182.68200","15.22373","0.00192"
"182.98800","15.24914","0.00254"
"183.29400","15.27473","0.00195"
"183.60000","15.30014","0.00221"
"183.90600","15.32573","0.00208"
"184.21200","15.35114","0.00236"
"184.51800","15.37667","0.00196"
"184.82400","15.40220","0.00221"
"185.13000","15.42767","0.00203"
"185.43600","15.45320","0.00216"
"185.74200","15.47861","0.00249"
"186.04800","15.50420","0.00223"
"186.35400","15.52967","0.00242"
"186.66000","15.55520","0.00219"
"186.96600","15.58067","0.00230"
"187.27200","15.60620","0.00262"
"187.57800","15.63173","0.00254"
"187.88400","15.65714","0.00237"
"188.19000","15.68273","0.00212"
"188.49600","15.70820","0.00231"
"188.80200","15.73374","0.00215"
"189.10800","15.75915","0.00225"
"189.41400","15.78462","0.00241"
"189.72000","15.81021","0.00236"
"190.02600","15.83574","0.00252"
"190.33200","15.86121","0.00253"
"190.63800","15.88662","0.00253"
"190.94400","15.91221","0.00254"
"191.25000","15.93768","0.00237"
"191.55600","15.96315","0.00254"
"191.86200","15.98874","0.00213"
"192.16800","16.01415","0.00228"
"192.47400","16.03968","0.00256"
"192.78000","16.06509","0.00229"
"193.08600","16.09068","0.00257"
"193.39200","16.11615","0.00205"
"193.69800","16.14168","0.00250"
"194.00400","16.16721","0.00233"
"194.31000","16.19268","0.00253"
"194.61600","16.21827","0.00218"
"194.92200","16.24368","0.00199"
"195.22800","16.26921","0.00255"
"195.53400","16.29462","0.00255"
"195.84000","16.32015","0.00236"
"196.14600","16.34568","0.00244"
"196.45200","16.37121","0.00262"
"196.75800","16.39674","0.00256"
"197.06400","16.42215","0.00250"
"197.37000","16.44774","0.00233"
"197.67600","16.47321","0.00234"
"197.98200","16.49868","0.00244"
"198.28800","16.52421","0.00232"
"198.59400","16.54962","0.00279"
"198.90000","16.57521","0.00254"
"199.20600","16.60068","0.00251"
"199.51200","16.62627","0.00219"
"199.81800","16.65168","0.00221"
"200.12400","16.67715","0.00225"
"200.43000","16.70268","0.00225"
"200.73600","16.72816","0.00226"
"201.04200","16.75368","0.00248"
"201.34800","16.77909","0.00227"
"201.65400","16.80469","0.00231"
"201.96000","16.83016","0.00234"
"202.26600","16.85568","0.00251"
"202.57200","16.88116","0.00232"
"202.87800","16.90669","0.00252"
"203.18400","16.93221","0.00237"
"203.49000","16.95769","0.00272"
"203.79600","16.98322","0.00244"
"204.10200","17.00869","0.00236"
"204.40800","17.03422","0.00269"
"204.71400","17.05969","0.00247"
"205.02000","17.08516","0.00211"
"205.32600","17.11069","0.00231"
"205.63200","17.13616","0.00248"
"205.93800","17.16175","0.00260"
"206.24400","17.18716","0.00322"
"206.55000","17.21269","0.00256"
"206.85600","17.23816","0.00269"
"207.16200","17.26363","0.00266"
"207.46800","17.28916","0.00298"
"207.77400","17.31463","0.00272"
"208.08000","17.34022","0.00248"
"208.38600","17.36563","0.00282"
"208.69200","17.39122","0.00218"
"208.99800","17.41669","0.00272"
"209.30400","17.44222","0.00229"
"209.61000","17.46769","0.00218"
"209.91600","17.49316","0.00253"
"210.22200","17.51869","0.00298"
"210.52800","17.54416","0.00278"
"210.83400","17.56969","0.00229"
"211.14000","17.59516","0.00251"
"211.44600","17.62069","0.00307"
"211.75200","17.64622","0.00218"
"212.05800","17.67169","0.00277"
"212.36400","17.69716","0.00245"
"212.67000","17.72264","0.00264"
"212.97600","17.74822","0.00264"
"213.28200","17.77369","0.00279"
"213.58800","17.79917","0.00280"
"213.89400","17.82469","0.00243"
"214.20000","17.85022","0.00266"
"214.50600","17.87570","0.00233"
"214.81200","17.90117","0.00242"
"215.11800","17.92669","0.00280"
"215.42400","17.95217","0.00239"
"215.73000","17.97770","0.00245"
"216.03600","18.00317","0.00248"
"216.34200","18.02864","0.00265"
"216.64800","18.05423","0.00244"
"216.95400","18.07964","0.00230"
"217.26000","18.10523","0.00254"
"217.56600","18.13070","0.00255"
"217.87200","18.15623","0.00254"
"218.17800","18.18170","0.00240"
"218.48400","18.20717","0.00295"
"218.79000","18.23270","0.00258"
"219.09600","18.25811","0.00277"
"219.40200","18.28370","0.00261"
"219.70800","18.30917","0.00216"
"220.01400","18.33476","0.00258"
"220.32000","18.36017","0.00228"
"220.62600","18.38570","0.00254"
"220.93200","18.41117","0.00269"
"221.23800","18.43664","0.00262"
"221.54400","18.46217","0.00276"
"221.85000","18.48764","0.00271"
"222.15600","18.51317","0.00244"
"222.46200","18.53870","0.00234"
"222.76800","18.56417","0.00280"
"223.07400","18.58970","0.00291"
"223.38000","18.61517","0.00288"
"223.68600","18.64064","0.00275"
"223.99200","18.66611","0.00208"
"224.29800","18.69170","0.00252"
"224.60400","18.71717","0.00280"
"224.91000","18.74270","0.00231"
"225.21600","18.76823","0.00235"
"225.52200","18.79364","0.00233"
"225.82800","18.81917","0.00249"
"226.13400","18.84464","0.00229"
"226.44000","18.87024","0.00275"
"226.74600","18.89570","0.00259"
"227.05200","18.92124","0.00281"
"227.35800","18.94670","0.00257"
"227.66400","18.97212","0.00230"
"227.97000","18.99771","0.00290"
"228.27600","19.02312","0.00261"
"228.58200","19.04871","0.00264"
"228.88800","19.07418","0.00288"
"229.19400","19.09971","0.00245"
"229.50000","19.12518","0.00202"
"229.80600","19.15065","0.00217"
"230.11200","19.17618","0.00228"
"230.41800","19.20159","0.00246"
"230.72400","19.22718","0.00229"
"231.03000","19.25265","0.00184"
"231.33600","19.27824","0.00229"
"231.64200","19.30371","0.00251"
"231.94800","19.32918","0.00246"
"232.25400","19.35471","0.00216"
"232.56000","19.38018","0.00232"
"232.86600","19.40571","0.00200"
"233.17200","19.43118","0.00244"
"233.47800","19.45671","0.00217"
"233.78400","19.48224","0.00233"
"234.09000","19.50771","0.00225"
"234.39600","19.53324","0.00247"
"234.70200","19.55859","0.00232"
"235.00800","19.58418","0.00225"
"235.31400","19.60959","0.00235"
"235.62000","19.63524","0.00264"
"235.92600","19.66071","0.00252"
"236.23200","19.68624","0.00231"
"236.53800","19.71171","0.00242"
"236.84400","19.73712","0.00257"
"237.15000","19.76271","0.00227"
"237.45600","19.78812","0.00247"
"237.76200","19.81371","0.00256"
"238.06800","19.83918","0.00230"
"238.37400","19.86471","0.00242"
"238.68000","19.89024","0.00242"
"238.98600","19.91566","0.00277"
"239.29200","19.94118","0.00243"
"239.59800","19.96659","0.00235"
"239.90400","19.99218","0.00224"
"240.21000","20.01765","0.00233"
"240.51600","20.04325","0.00238"
"240.82200","20.06877","0.00235"
"241.12800","20.09412","0.00269"
"241.43400","20.11966","0.00271"
"241.74000","20.14519","0.00262"
"242.04600","20.17066","0.00257"
"242.35200","20.19619","0.00222"
"242.65800","20.22166","0.00278"
"242.96400","20.24725","0.00261"
"243.27000","20.27266","0.00230"
"243.57600","20.29819","0.00286"
"243.88200","20.32360","0.00279"
"244.18800","20.34919","0.00281"
"244.49400","20.37466","0.00227"
"244.80000","20.40019","0.00223"
"245.10600","20.42566","0.00239"
"245.41200","20.45113","0.00260"
"245.71800","20.47672","0.00251"
"246.02400","20.50213","0.00262"
"246.33000","20.52772","0.00307"
"246.63600","20.55313","0.00260"
"246.94200","20.57866","0.00242"
"247.24800","20.60419","0.00249"
"247.55400","20.62966","0.00211"
"247.86000","20.65525","0.00207"
"248.16600","20.68066","0.00246"
"248.47200","20.70619","0.00270"
"248.77800","20.73166","0.00271"
"249.08400","20.75719","0.00245"
"249.39000","20.78266","0.00266"
"249.69600","20.80819","0.00275"
"250.00200","20.83378","0.00266"
"250.30800","20.85913","0.00251"
"250.61400","20.88472","0.00248"
"250.92000","20.91019","0.00252"
"251.22600","20.93566","0.00263"
"251.53200","20.96119","0.00275"
"251.83800","20.98667","0.00341"
"252.14400","21.01225","0.00279"
"252.45000","21.03766","0.00295"
"252.75600","21.06319","0.00275"
"253.06200","21.08861","0.00277"
"253.36800","21.11420","0.00281"
"253.67400","21.13966","0.00241"
"253.98000","21.16520","0.00287"
"254.28600","21.19066","0.00239"
"254.59200","21.21620","0.00268"
"254.89800","21.24173","0.00249"
"255.20400","21.26714","0.00235"
"255.51000","21.29273","0.00286"
"255.81600","21.31814","0.00255"
"256.12200","21.34367","0.00267"
"256.42800","21.36920","0.00267"
"256.73400","21.39467","0.00234"
"257.04000","21.42020","0.00291"
"257.34600","21.44567","0.00296"
"257.65200","21.47120","0.00261"
"257.95800","21.49667","0.00277"
"258.26400","21.52220","0.00256"
"258.57000","21.54767","0.00256"
"258.87600","21.57320","0.00247"
"259.18200","21.59873","0.00251"
"259.48800","21.62420","0.00271"
"259.79400","21.64973","0.00313"
"260.10000","21.67520","0.00290"
"260.40600","21.70067","0.00306"
"260.71200","21.72620","0.00265"
"261.01800","21.75167","0.00275"
"261.32400","21.77726","0.00256"
"261.63000","21.80267","0.00282"
"261.93600","21.82820","0.00284"
"262.24200","21.85367","0.00270"
"262.54800","21.87920","0.00267"
"262.85400","21.90467","0.00303"
"263.16000","21.93014","0.00304"
"263.46600","21.95573","0.00299"
"263.77200","21.98120","0.00284"
"264.07800","22.00673","0.00290"
"264.38400","22.03214","0.00305"
"264.69000","22.05767","0.00292"
"264.99600","22.08320","0.00289"
"265.30200","22.10868","0.00260"
"265.60800","22.13420","0.00311"
"265.91400","22.15968","0.00287"
"266.22000","22.18521","0.00312"
"266.52600","22.21068","0.00255"
"266.83200","22.23615","0.00311"
"267.13800","22.26162","0.00337"
"267.44400","22.28715","0.00326"
"267.75000","22.31268","0.00322"
"268.05600","22.33815","0.00315"
"268.36200","22.36368","0.00289"
"268.66800","22.38914","0.00271"
"268.97400","22.41468","0.00293"
"269.28000","22.44015","0.00305"
"269.58600","22.46568","0.00270"
"269.89200","22.49121","0.00316"
"270.19800","22.51662","0.00326"
"270.50400","22.54221","0.00303"
"270.81000","22.56768","0.00287"
"271.11600","22.59321","0.00312"
"271.42200","22.61862","0.00317"
"271.72800","22.64415","0.00315"
"272.03400","22.66968","0.00334"
"272.34000","22.69515","0.00299"
"272.64600","22.72074","0.00329"
"272.95200","22.74621","0.00326"
"273.25800","22.77168","0.00313"
"273.56400","22.79715","0.00337"
"273.87000","22.82274","0.00328"
"274.17600","22.84821","0.00322"
"274.48200","22.87368","0.00321"
"274.78800","22.89915","0.00314"
"275.09400","22.92462","0.00334"
"275.40000","22.95021","0.00336"
"275.70600","22.97574","0.00328"
"276.01200","23.00121","0.00322"
"276.31800","23.02668","0.00322"
"276.62400","23.05215","0.00316"
"276.93000","23.07768","0.00313"
"277.23600","23.10315","0.00356"
"277.54200","23.12868","0.00344"
"277.84800","23.15415","0.00324"
"278.15400","23.17974","0.00356"
"278.46000","23.20522","0.00332"
"278.76600","23.23068","0.00314"
"279.07200","23.25622","0.00368"
"279.37800","23.28169","0.00347"
"279.68400","23.30721","0.00340"
"279.99000","23.33274","0.00310"
"280.29600","23.35822","0.00338"
"280.60200","23.38369","0.00353"
"280.90800","23.40916","0.00344"
"281.21400","23.43475","0.00346"
"281.52000","23.46016","0.00319"
"281.82600","23.48569","0.00400"
"282.13200","23.51116","0.00377"
"282.43800","23.53675","0.00311"
"282.74400","23.56216","0.00364"
"283.05000","23.58769","0.00340"
"283.35600","23.61316","0.00371"
"283.66200","23.63863","0.00368"
"283.96800","23.66416","0.00354"
"284.27400","23.68969","0.00389"
"284.58000","23.71522","0.00370"
"284.88600","23.74069","0.00353"
"285.19200","23.76622","0.00374"
"285.49800","23.79175","0.00342"
"285.80400","23.81710","0.00381"
"286.11000","23.84269","0.00357"
"286.41600","23.86810","0.00389"
"286.72200","23.89375","0.00406"
"287.02800","23.91922","0.00397"
"287.33400","23.94469","0.00392"
"287.64000","23.97022","0.00365"
"287.94600","23.99563","0.00384"
"288.25200","24.02116","0.00403"
"288.55800","24.04663","0.00370"
"288.86400","24.07222","0.00409"
"289.17000","24.09769","0.00394"
"289.47600","24.12322","0.00379"
"289.78200","24.14869","0.00384"
"290.08800","24.17422","0.00370"
"290.39400","24.19969","0.00376"
"290.70000","24.22511","0.00407"
"291.00600","24.25069","0.00401"
"291.31200","24.27622","0.00394"
"291.61800","24.30175","0.00399"
"291.92400","24.32723","0.00392"
"292.23000","24.35270","0.00417"
"292.53600","24.37817","0.00403"
"292.84200","24.40364","0.00363"
"293.14800","24.42922","0.00397"
"293.45400","24.45470","0.00395"
"293.76000","24.48022","0.00407"
"294.06600","24.50570","0.00401"
"294.37200","24.53117","0.00392"
"294.67800","24.55670","0.00390"
"294.98400","24.58217","0.00410"
"295.29000","24.60770","0.00410"
"295.59600","24.63317","0.00393"
"295.90200","24.65870","0.00422"
"296.20800","24.68423","0.00374"
"296.51400","24.70970","0.00397"
"296.82000","24.73523","0.00421"
"297.12600","24.76064","0.00411"
"297.43200","24.78617","0.00409"
"297.73800","24.81164","0.00404"
"298.04400","24.83723","0.00428"
"298.35000","24.86270","0.00396"
"298.65600","24.88823","0.00413"
"298.96200","24.91370","0.00435"
"299.26800","24.93911","0.00409"
"299.57400","24.96464","0.00410"
"299.88000","24.99011","0.00419"
"300.18600","25.01564","0.00409"
"300.49200","25.04117","0.00413"
"300.79800","25.06670","0.00408"
"301.10400","25.09223","0.00427"
"301.41000","25.11764","0.00442"
"301.71600","25.14323","0.00422"
"302.02200","25.16870","0.00414"
"302.32800","25.19417","0.00442"
"302.63400","25.21970","0.00381"
"302.94000","25.24523","0.00457"
"303.24600","25.27076","0.00398"
"303.55200","25.29617","0.00405"
"303.85800","25.32170","0.00440"
"304.16400","25.34711","0.00451"
"304.47000","25.37271","0.00446"
"304.77600","25.39817","0.00433"
"305.08200","25.42371","0.00400"
"305.38800","25.44917","0.00433"
"305.69400","25.47465","0.00436"
"306.00000","25.50018","0.00432"
"306.30600","25.52565","0.00435"
"306.61200","25.55118","0.00434"
"306.91800","25.57665","0.00413"
"307.22400","25.60218","0.00451"
"307.53000","25.62771","0.00477"
"307.83600","25.65318","0.00425"
"308.14200","25.67871","0.00432"
"308.44800","25.70418","0.00453"
"308.75400","25.72971","0.00431"
"309.06000","25.75512","0.00457"
"309.36600","25.78071","0.00430"
"309.67200","25.80624","0.00454"
"309.97800","25.83171","0.00460"
"310.28400","25.85724","0.00433"
"310.59000","25.88265","0.00488"
"310.89600","25.90818","0.00459"
"311.20200","25.93365","0.00448"
"311.50800","25.95918","0.00468"
"311.81400","25.98471","0.00491"
"312.12000","26.01018","0.00467"
"312.42600","26.03571","0.00463"
"312.73200","26.06118","0.00452"
"313.03800","26.08671","0.00485"
"313.34400","26.11212","0.00464"
"313.65000","26.13765","0.00464"
"313.95600","26.16318","0.00488"
"314.26200","26.18865","0.00485"
"314.56800","26.21424","0.00445"
"314.87400","26.23959","0.00491"
"315.18000","26.26518","0.00495"
"315.48600","26.29066","0.00454"
"315.79200","26.31618","0.00456"
"316.09800","26.34165","0.00476"
"316.40400","26.36719","0.00452"
"316.71000","26.39271","0.00509"
"317.01600","26.41818","0.00492"
"317.32200","26.44371","0.00497"
"317.62800","26.46918","0.00485"
"317.93400","26.49471","0.00493"
"318.24000","26.52019","0.00478"
"318.54600","26.54565","0.00469"
"318.85200","26.57125","0.00519"
"319.15800","26.59672","0.00500"
"319.46400","26.62219","0.00501"
"319.77000","26.64760","0.00558"
"320.07600","26.67319","0.00494"
"320.38200","26.69866","0.00483"
"320.68800","26.72413","0.00520"
"320.99400","26.74972","0.00532"
"321.30000","26.77519","0.00540"
"321.60600","26.80072","0.00513"
"321.91200","26.82613","0.00537"
"322.21800","26.85172","0.00433"
"322.52400","26.87719","0.00476"
"322.83000","26.90272","0.00392"
"323.13600","26.92819","0.00446"
"323.44200","26.95366","0.00425"
"323.74800","26.97925","0.00433"
"324.05400","27.00466","0.00416"
"324.36000","27.03025","0.00426"
"324.66600","27.05566","0.00408"
"324.97200","27.08119","0.00465"
"325.27800","27.10672","0.00443"
"325.58400","27.13219","0.00455"
"325.89000","27.15772","0.00427"
"326.19600","27.18319","0.00429"
"326.50200","27.20872","0.00427"
"326.80800","27.23419","0.00468"
"327.11400","27.25972","0.00447"
"327.42000","27.28519","0.00445"
"327.72600","27.31066","0.00420"
"328.03200","27.33619","0.00431"
"328.33800","27.36166","0.00438"
"328.64400","27.38725","0.00458"
"328.95000","27.41273","0.00436"
"329.25600","27.43813","0.00486"
"329.56200","27.46366","0.00473"
"329.86800","27.48920","0.00403"
"330.17400","27.51472","0.00458"
"330.48000","27.54014","0.00451"
"330.78600","27.56567","0.00471"
"331.09200","27.59114","0.00407"
"331.39800","27.61667","0.00459"
"331.70400","27.64214","0.00433"
"332.01000","27.66767","0.00452"
"332.31600","27.69320","0.00409"
"332.62200","27.71867","0.00459"
"332.92800","27.74426","0.00440"
"333.23400","27.76967","0.00397"
"333.54000","27.79526","0.00438"
"333.84600","27.82067","0.00460"
"334.15200","27.84620","0.00427"
"334.45800","27.87167","0.00423"
"334.76400","27.89720","0.00466"
"335.07000","27.92273","0.00451"
"335.37600","27.94820","0.00467"
"335.68200","27.97367","0.00487"
"335.98800","27.99914","0.00488"
"336.29400","28.02461","0.00452"
"336.60000","28.05020","0.00459"
"336.90600","28.07561","0.00465"
"337.21200","28.10120","0.00437"
"337.51800","28.12661","0.00473"
"337.82400","28.15220","0.00466"
"338.13000","28.17767","0.00496"
"338.43600","28.20320","0.00456"
"338.74200","28.22873","0.00479"
"339.04800","28.25414","0.00435"
"339.35400","28.27967","0.00495"
"339.66000","28.30514","0.00521"
"339.96600","28.33073","0.00478"
"340.27200","28.35620","0.00518"
"340.57800","28.38173","0.00503"
"340.88400","28.40720","0.00523"
"341.19000","28.43267","0.00524"
"341.49600","28.45820","0.00547"
"341.80200","28.48367","0.00521"
"342.10800","28.50920","0.00534"
"342.41400","28.53467","0.00537"
"342.72000","28.56021","0.00546"
"343.02600","28.58568","0.00492"
"343.33200","28.61121","0.00539"
"343.63800","28.63668","0.00535"
"343.94400","28.66215","0.00510"
"344.25000","28.68768","0.00485"
"344.55600","28.71315","0.00527"
"344.86200","28.73868","0.00510"
"345.16800","28.76415","0.00528"
"345.47400","28.78962","0.00553"
"345.78000","28.81521","0.00523"
"346.08600","28.84068","0.00515"
"346.39200","28.86621","0.00548"
"346.69800","28.89168","0.00554"
"347.00400","28.91721","0.00532"
"347.31000","28.94268","0.00526"
"347.61600","28.96821","0.00494"
"347.92200","28.99368","0.00544"
"348.22800","29.01915","0.00496"
"348.53400","29.04468","0.00516"
"348.84000","29.07009","0.00537"
"349.14600","29.09574","0.00528"
"349.45200","29.12115","0.00514"
"349.75800","29.14668","0.00537"
"350.06400","29.17221","0.00510"
"350.37000","29.19762","0.00524"
"350.67600","29.22315","0.00493"
"350.98200","29.24862","0.00505"
"351.28800","29.27421","0.00502"
"351.59400","29.29968","0.00512"
"351.90000","29.32521","0.00510"
"352.20600","29.35074","0.00533"
"352.51200","29.37621","0.00514"
"352.81800","29.40168","0.00512"
"353.12400","29.42715","0.00508"
"353.43000","29.45268","0.00487"
"353.73600","29.47821","0.00463"
"354.04200","29.50374","0.00521"
"354.34800","29.52921","0.00490"
"354.65400","29.55468","0.00494"
"354.96000","29.58021","0.00513"
"355.26600","29.60563","0.00512"
"355.57200","29.63122","0.00510"
"355.87800","29.65668","0.00534"
"356.18400","29.68222","0.00477"
"356.49000","29.70775","0.00525"
"356.79600","29.73315","0.00532"
"357.10200","29.75869","0.00526"
"357.40800","29.78410","0.00535"
"357.71400","29.80969","0.00512"
"358.02000","29.83516","0.00506"
"358.32600","29.86075","0.00528"
"358.63200","29.88616","0.00523"
"358.93800","29.91169","0.00538"
"359.24400","29.93722","0.00514"
"359.55000","29.96263","0.00500"
"359.85600","29.98816","0.00473"
"360.16200","30.01363","0.00485"
"360.46800","30.03922","0.00504"
"360.77400","30.06469","0.00488"
"361.08000","30.09022","0.00507"
"361.38600","30.11569","0.00490"
"361.69200","30.14116","0.00516"
"361.99800","30.16669","0.00486"
"362.30400","30.19216","0.00505"
"362.61000","30.21769","0.00537"
"362.91600","30.24322","0.00511"
"363.22200","30.26869","0.00520"
"363.52800","30.29422","0.00550"
"363.83400","30.31963","0.00499"
"364.14000","30.34516","0.00490"
"364.44600","30.37057","0.00529"
"364.75200","30.39616","0.00517"
"365.05800","30.42169","0.00546"
"365.36400","30.44722","0.00549"
"365.67000","30.47275","0.00502"
"365.97600","30.49810","0.00541"
"366.28200","30.52369","0.00551"
"366.58800","30.54917","0.00559"
"366.89400","30.57475","0.00495"
"367.20000","30.60017","0.00556"
"367.50600","30.62570","0.00547"
"367.81200","30.65122","0.00532"
"368.11800","30.67664","0.00540"
"368.42400","30.70222","0.00613"
"368.73000","30.72764","0.00556"
"369.03600","30.75323","0.00562"
"369.34200","30.77864","0.00598"
"369.64800","30.80422","0.00597"
"369.95400","30.82976","0.00580"
"370.26000","30.85511","0.00554"
"370.56600","30.88070","0.00555"
"370.87200","30.90617","0.00547"
"371.17800","30.93170","0.00568"
"371.48400","30.95717","0.00575"
"371.79000","30.98270","0.00565"
"372.09600","31.00823","0.00553"
"372.40200","31.03370","0.00613"
"372.70800","31.05923","0.00577"
"373.01400","31.08458","0.00571"
"373.32000","31.11023","0.00580"
"373.62600","31.13564","0.00623"
"373.93200","31.16117","0.00605"
"374.23800","31.18670","0.00638"
"374.54400","31.21217","0.00633"
"374.85000","31.23770","0.00621"
"375.15600","31.26317","0.00633"
"375.46200","31.28870","0.00605"
"375.76800","31.31417","0.00597"
"376.07400","31.33964","0.00581"
"376.38000","31.36517","0.00599"
"376.68600","31.39070","0.00598"
"376.99200","31.41623","0.00619"
"377.29800","31.44164","0.00615"
"377.60400","31.46723","0.00602"
"377.91000","31.49264","0.00598"
"378.21600","31.51823","0.00587"
"378.52200","31.54370","0.00639"
"378.82800","31.56917","0.00617"
"379.13400","31.59476","0.00617"
"379.44000","31.62011","0.00613"
"379.74600","31.64570","0.00611"
"380.05200","31.67117","0.00629"
"380.35800","31.69670","0.00644"
"380.66400","31.72217","0.00626"
"380.97000","31.74764","0.00655"
"381.27600","31.77317","0.00640"
"381.58200","31.79864","0.00664"
"381.88800","31.82417","0.00661"
"382.19400","31.84965","0.00653"
"382.50000","31.87517","0.00646"
"382.80600","31.90064","0.00621"
"383.11200","31.92612","0.00632"
"383.41800","31.95171","0.00653"
"383.72400","31.97718","0.00653"
"384.03000","32.00270","0.00693"
"384.33600","32.02818","0.00646"
"384.64200","32.05371","0.00644"
"384.94800","32.07917","0.00649"
"385.25400","32.10464","0.00641"
"385.56000","32.13018","0.00663"
"385.86600","32.15571","0.00675"
"386.17200","32.18124","0.00651"
"386.47800","32.20671","0.00687"
"386.78400","32.23223","0.00667"
"387.09000","32.25771","0.00633"
"387.39600","32.28318","0.00656"
"387.70200","32.30871","0.00641"
"388.00800","32.33418","0.00699"
"388.31400","32.35977","0.00631"
"388.62000","32.38518","0.00670"
"388.92600","32.41077","0.00653"
"389.23200","32.43618","0.00661"
"389.53800","32.46171","0.00664"
"389.84400","32.48718","0.00703"
"390.15000","32.51265","0.00693"
"390.45600","32.53824","0.00655"
"390.76200","32.56365","0.00673"
"391.06800","32.58918","0.00699"
"391.37400","32.61471","0.00686"
"391.68000","32.64024","0.00717"
"391.98600","32.66565","0.00683"
"392.29200","32.69112","0.00708"
"392.59800","32.71671","0.00677"
"392.90400","32.74218","0.00728"
"393.21000","32.76777","0.00700"
"393.51600","32.79318","0.00680"
"393.82200","32.81871","0.00685"
"394.12800","32.84418","0.00685"
"394.43400","32.86972","0.00676"
"394.74000","32.89518","0.00734"
"395.04600","32.92065","0.00666"
"395.35200","32.94619","0.00727"
"395.65800","32.97171","0.00643"
"395.96400","32.99718","0.00668"
"396.27000","33.02266","0.00696"
"396.57600","33.04813","0.00681"
"396.88200","33.07366","0.00687"
"397.18800","33.09912","0.00624"
"397.49400","33.12471","0.00674"
"397.80000","33.15012","0.00648"
"398.10600","33.17566","0.00639"
"398.41200","33.20119","0.00636"
"398.71800","33.22672","0.00607"
"399.02400","33.25219","0.00656"
"399.33000","33.27766","0.00635"
"399.63600","33.30318","0.00626"
"399.94200","33.32866","0.00648"
"400.24800","33.35419","0.00667"
"400.55400","33.37966","0.00623"
"400.86000","33.40519","0.00693"
"401.16600","33.43072","0.00651"
"401.47200","33.45613","0.00671"
"401.77800","33.48172","0.00701"
"402.08400","33.50719","0.00675"
"402.39000","33.53272","0.00679"
"402.69600","33.55813","0.00695"
"403.00200","33.58366","0.00685"
"403.30800","33.60919","0.00722"
"403.61400","33.63466","0.00666"
"403.92000","33.66019","0.00679"
"404.22600","33.68566","0.00691"
"404.53200","33.71125","0.00684"
"404.83800","33.73672","0.00696"
"405.14400","33.76219","0.00649"
"405.45000","33.78772","0.00631"
"405.75600","33.81313","0.00675"
"406.06200","33.83867","0.00642"
"406.36800","33.86413","0.00666"
"406.67400","33.88972","0.00681"
"406.98000","33.91519","0.00670"
"407.28600","33.94072","0.00641"
"407.59200","33.96619","0.00698"
"407.89800","33.99166","0.00607"
"408.20400","34.01725","0.00633"
"408.51000","34.04266","0.00663"
"408.81600","34.06819","0.00696"
"409.12200","34.09367","0.00695"
"409.42800","34.11926","0.00718"
"409.73400","34.14466","0.00675"
"410.04000","34.17014","0.00671"
"410.34600","34.19572","0.00705"
"410.65200","34.22113","0.00587"
"410.95800","34.24667","0.00652"
"411.26400","34.27214","0.00611"
"411.57000","34.29773","0.00522"
"411.87600","34.32320","0.00601"
"412.18200","34.34872","0.00562"
"412.48800","34.37420","0.00577"
"412.79400","34.39967","0.00521"
"413.10000","34.42520","0.00555"
"413.40600","34.45061","0.00547"
"413.71200","34.47620","0.00584"
"414.01800","34.50173","0.00580"
"414.32400","34.52720","0.00573"
"414.63000","34.55273","0.00515"
"414.93600","34.57814","0.00547"
"415.24200","34.60367","0.00501"
"415.54800","34.62908","0.00500"
"415.85400","34.65473","0.00514"
"416.16000","34.68020","0.00521"
"416.46600","34.70573","0.00478"
"416.77200","34.73126","0.00584"
"417.07800","34.75667","0.00549"
"417.38400","34.78220","0.00531"
"417.69000","34.80761","0.00524"
"417.99600","34.83320","0.00535"
"418.30200","34.85867","0.00530"
"418.60800","34.88420","0.00543"
"418.91400","34.90973","0.00516"
"419.22000","34.93520","0.00531"
"419.52600","34.96073","0.00532"
"419.83200","34.98615","0.00546"
"420.13800","35.01168","0.00536"
"420.44400","35.03714","0.00558"
"420.75000","35.06273","0.00537"
"421.05600","35.08826","0.00506"
"421.36200","35.11367","0.00589"
"421.66800","35.13921","0.00579"
"421.97400","35.16468","0.00534"
"422.28000","35.19020","0.00572"
"422.58600","35.21568","0.00547"
"422.89200","35.24121","0.00556"
"423.19800","35.26674","0.00602"
"423.50400","35.29215","0.00555"
"423.81000","35.31774","0.00553"
"424.11600","35.34315","0.00578"
"424.42200","35.36868","0.00585"
"424.72800","35.39415","0.00576"
"425.03400","35.41968","0.00599"
"425.34000","35.44521","0.00613"
"425.64600","35.47068","0.00567"
"425.95200","35.49621","0.00602"
"426.25800","35.52168","0.00548"
"426.56400","35.54715","0.00577"
"426.87000","35.57262","0.00629"
"427.17600","35.59821","0.00585"
"427.48200","35.62368","0.00594"
"427.78800","35.64921","0.00626"
"428.09400","35.67474","0.00611"
"428.40000","35.70009","0.00619"
"428.70600","35.72568","0.00610"
"429.01200","35.75115","0.00609"
"429.31800","35.77668","0.00645"
"429.62400","35.80215","0.00647"
"429.93000","35.82774","0.00610"
"430.23600","35.85327","0.00613"
"430.54200","35.87868","0.00602"
"430.84800","35.90421","0.00622"
"431.15400","35.92968","0.00639"
"431.46000","35.95521","0.00635"
"431.76600","35.98068","0.00640"
"432.07200","36.00621","0.00639"
"432.37800","36.03180","0.00621"
"432.68400","36.05716","0.00627"
"432.99000","36.08268","0.00664"
"433.29600","36.10810","0.00684"
"433.60200","36.13374","0.00665"
"433.90800","36.15915","0.00670"
"434.21400","36.18468","0.00655"
"434.52000","36.21022","0.00649"
"434.82600","36.23569","0.00677"
"435.13200","36.26122","0.00676"
"435.43800","36.28669","0.00721"
"435.74400","36.31221","0.00682"
"436.05000","36.33762","0.00654"
"436.35600","36.36316","0.00683"
"436.66200","36.38869","0.00706"
"436.96800","36.41416","0.00692"
"437.27400","36.43975","0.00681"
"437.58000","36.46516","0.00640"
"437.88600","36.49068","0.00702"
"438.19200","36.51610","0.00738"
"438.49800","36.54169","0.00711"
"438.80400","36.56722","0.00674"
"439.11000","36.59269","0.00714"
"439.41600","36.61822","0.00686"
"439.72200","36.64369","0.00734"
"440.02800","36.66922","0.00723"
"440.33400","36.69463","0.00748"
"440.64000","36.72016","0.00767"
"440.94600","36.74569","0.00712"
"441.25200","36.77116","0.00750"
"441.55800","36.79675","0.00764"
"441.86400","36.82216","0.00736"
"442.17000","36.84775","0.00703"
"442.47600","36.87310","0.00751"
"442.78200","36.89869","0.00765"
"443.08800","36.92416","0.00715"
"443.39400","36.94970","0.00768"
"443.70000","36.97522","0.00779"
"444.00600","37.00063","0.00776"
"444.31200","37.02617","0.00740"
"444.61800","37.05163","0.00749"
"444.92400","37.07722","0.00746"
"445.23000","37.10270","0.00768"
"445.53600","37.12817","0.00769"
"445.84200","37.15369","0.00781"
"446.14800","37.17923","0.00796"
"446.45400","37.20469","0.00779"
"446.76000","37.23016","0.00810"
"447.06600","37.25570","0.00834"
"447.37200","37.28117","0.00765"
"447.67800","37.30670","0.00795"
"447.98400","37.33223","0.00830"
"448.29000","37.35770","0.00835"
"448.59600","37.38322","0.00844"
"448.90200","37.40863","0.00829"
"449.20800","37.43423","0.00841"
"449.51400","37.45964","0.00830"
"449.82000","37.48517","0.00809"
"450.12600","37.51070","0.00845"
"450.43200","37.53617","0.00842"
"450.73800","37.56170","0.00876"
"451.04400","37.58711","0.00867"
"451.35000","37.61270","0.00838"
"451.65600","37.63817","0.00881"
"451.96200","37.66370","0.00860"
"452.26800","37.68917","0.00883"
"452.57400","37.71464","0.00911"
"452.88000","37.74023","0.00873"
"453.18600","37.76564","0.00858"
"453.49200","37.79123","0.00888"
"453.79800","37.81664","0.00872"
"454.10400","37.84217","0.00923"
"454.41000","37.86770","0.00900"
"454.71600","37.89323","0.00901"
"455.02200","37.91870","0.00883"
"455.32800","37.94417","0.00850"
"455.63400","37.96976","0.00876"
"455.94000","37.99517","0.00847"
"456.24600","38.02070","0.00862"
"456.55200","38.04617","0.00880"
"456.85800","38.07164","0.00831"
"457.16400","38.09717","0.00865"
"457.47000","38.12264","0.00900"
"457.60800","38.13418","0.00818"