File: Force_trajectories/161221_1/Specimen_RawData_8.csv
End date,"12/21/2016"
Specimen label,"24BG_95_run2"
Maximum Load,"0.01226",N

Time,Extension,Load
(s),(mm),(N)
"0.00000","7.50783","0.00789"
"0.09600","7.51082","0.00787"
"0.19200","7.51985","0.00808"
"0.28800","7.53067","0.00809"
"0.38400","7.53994","0.00796"
"0.48000","7.54807","0.00818"
"0.57600","7.55608","0.00820"
"0.67200","7.56403","0.00817"
"0.76800","7.57205","0.00809"
"0.86400","7.58000","0.00791"
"0.96000","7.58801","0.00801"
"1.05600","7.59602","0.00778"
"1.15200","7.60403","0.00782"
"1.24800","7.61204","0.00811"
"1.34400","7.62006","0.00857"
"1.44000","7.62795","0.00810"
"1.53600","7.63596","0.00797"
"1.63200","7.64403","0.00772"
"1.72800","7.65198","0.00839"
"1.82400","7.66000","0.00818"
"1.92000","7.66801","0.00789"
"2.01600","7.67596","0.00772"
"2.11200","7.68397","0.00852"
"2.20800","7.69204","0.00817"
"2.30400","7.70000","0.00803"
"2.40000","7.70801","0.00836"
"2.49600","7.71596","0.00802"
"2.59200","7.72397","0.00803"
"2.68800","7.73198","0.00807"
"2.78400","7.74005","0.00811"
"2.88000","7.74801","0.00806"
"2.97600","7.75602","0.00833"
"3.07200","7.76397","0.00796"
"3.16800","7.77192","0.00841"
"3.26400","7.77999","0.00806"
"3.36000","7.78806","0.00871"
"3.45600","7.79602","0.00831"
"3.55200","7.80397","0.00856"
"3.64800","7.81198","0.00815"
"3.74400","7.81993","0.00834"
"3.84000","7.82800","0.00829"
"3.93600","7.83608","0.00822"
"4.03200","7.84403","0.00826"
"4.12800","7.85198","0.00833"
"4.22400","7.85999","0.00820"
"4.32000","7.86794","0.00855"
"4.41600","7.87602","0.00829"
"4.51200","7.88403","0.00841"
"4.60800","7.89198","0.00826"
"4.70400","7.89993","0.00848"
"4.80000","7.90800","0.00836"
"4.89600","7.91596","0.00828"
"4.99200","7.92403","0.00805"
"5.08800","7.93204","0.00808"
"5.18400","7.93993","0.00847"
"5.28000","7.94794","0.00847"
"5.37600","7.95601","0.00825"
"5.47200","7.96397","0.00837"
"5.56800","7.97198","0.00827"
"5.66400","7.97999","0.00862"
"5.76000","7.98800","0.00806"
"5.85600","7.99595","0.00823"
"5.95200","8.00397","0.00854"
"6.04800","8.01198","0.00817"
"6.14400","8.01999","0.00840"
"6.24000","8.02800","0.00819"
"6.33600","8.03601","0.00828"
"6.43200","8.04396","0.00836"
"6.52800","8.05198","0.00813"
"6.62400","8.05999","0.00826"
"6.72000","8.06800","0.00842"
"6.81600","8.07595","0.00878"
"6.91200","8.08390","0.00849"
"7.00800","8.09198","0.00827"
"7.10400","8.10005","0.00812"
"7.20000","8.10800","0.00831"
"7.29600","8.11601","0.00836"
"7.39200","8.12402","0.00832"
"7.48800","8.13192","0.00825"
"7.58400","8.13999","0.00838"
"7.68000","8.14800","0.00839"
"7.77600","8.15595","0.00823"
"7.87200","8.16396","0.00808"
"7.96800","8.17197","0.00845"
"8.06400","8.17992","0.00829"
"8.16000","8.18800","0.00866"
"8.25600","8.19601","0.00782"
"8.35200","8.20396","0.00821"
"8.44800","8.21197","0.00840"
"8.54400","8.21998","0.00845"
"8.64000","8.22800","0.00866"
"8.73600","8.23601","0.00852"
"8.83200","8.24402","0.00870"
"8.92800","8.25197","0.00823"
"9.02400","8.25998","0.00810"
"9.12000","8.26800","0.00824"
"9.21600","8.27595","0.00807"
"9.31200","8.28396","0.00830"
"9.40800","8.29197","0.00810"
"9.50400","8.29992","0.00847"
"9.60000","8.30793","0.00814"
"9.69600","8.31601","0.00821"
"9.79200","8.32402","0.00830"
"9.88800","8.33203","0.00811"
"9.98400","8.34004","0.00781"
"10.08000","8.34793","0.00797"
"10.17600","8.35595","0.00851"
"10.27200","8.36402","0.00803"
"10.36800","8.37197","0.00830"
"10.46400","8.38004","0.00789"
"10.56000","8.38805","0.00820"
"10.65600","8.39594","0.00811"
"10.75200","8.40396","0.00807"
"10.84800","8.41209","0.00822"
"10.94400","8.41998","0.00822"
"11.04000","8.42799","0.00856"
"11.13600","8.43600","0.00804"
"11.23200","8.44390","0.00858"
"11.32800","8.45197","0.00805"
"11.42400","8.46004","0.00845"
"11.52000","8.46799","0.00824"
"11.61600","8.47600","0.00832"
"11.71200","8.48396","0.00799"
"11.80800","8.49197","0.00824"
"11.90400","8.49998","0.00821"
"12.00000","8.50799","0.00817"
"12.09600","8.51600","0.00801"
"12.19200","8.52395","0.00808"
"12.28800","8.53191","0.00854"
"12.38400","8.53998","0.00802"
"12.48000","8.54799","0.00797"
"12.57600","8.55600","0.00829"
"12.67200","8.56401","0.00810"
"12.76800","8.57197","0.00827"
"12.86400","8.57998","0.00828"
"12.96000","8.58793","0.00808"
"13.05600","8.59600","0.00819"
"13.15200","8.60401","0.00809"
"13.24800","8.61197","0.00836"
"13.34400","8.61992","0.00828"
"13.44000","8.62793","0.00819"
"13.53600","8.63600","0.00832"
"13.63200","8.64401","0.00844"
"13.72800","8.65196","0.00832"
"13.82400","8.65998","0.00816"
"13.92000","8.66799","0.00826"
"14.01600","8.67594","0.00832"
"14.11200","8.68401","0.00831"
"14.20800","8.69208","0.00801"
"14.30400","8.69998","0.00833"
"14.40000","8.70799","0.00835"
"14.49600","8.71594","0.00838"
"14.59200","8.72401","0.00864"
"14.68800","8.73202","0.00803"
"14.78400","8.73997","0.00843"
"14.88000","8.74799","0.00829"
"14.97600","8.75594","0.00847"
"15.07200","8.76395","0.00839"
"15.16800","8.77202","0.00790"
"15.26400","8.78003","0.00841"
"15.36000","8.78798","0.00833"
"15.45600","8.79600","0.00844"
"15.55200","8.80395","0.00810"
"15.64800","8.81196","0.00848"
"15.74400","8.82003","0.00843"
"15.84000","8.82798","0.00824"
"15.93600","8.83594","0.00819"
"16.03200","8.84401","0.00890"
"16.12800","8.85196","0.00823"
"16.22400","8.85997","0.00815"
"16.32000","8.86798","0.00808"
"16.41600","8.87599","0.00814"
"16.51200","8.88395","0.00828"
"16.60800","8.89196","0.00837"
"16.70400","8.89997","0.00875"
"16.80000","8.90798","0.00825"
"16.89600","8.91599","0.00829"
"16.99200","8.92401","0.00852"
"17.08800","8.93196","0.00850"
"17.18400","8.93997","0.00833"
"17.28000","8.94804","0.00854"
"17.37600","8.95599","0.00868"
"17.47200","8.96401","0.00840"
"17.56800","8.97196","0.00813"
"17.66400","8.97991","0.00858"
"17.76000","8.98798","0.00809"
"17.85600","8.99599","0.00844"
"17.95200","9.00400","0.00833"
"18.04800","9.01196","0.00846"
"18.14400","9.01997","0.00831"
"18.24000","9.02792","0.00834"
"18.33600","9.03593","0.00853"
"18.43200","9.04406","0.00855"
"18.52800","9.05202","0.00814"
"18.62400","9.05997","0.00873"
"18.72000","9.06798","0.00850"
"18.81600","9.07599","0.00874"
"18.91200","9.08400","0.00827"
"19.00800","9.09202","0.00858"
"19.10400","9.10003","0.00839"
"19.20000","9.10792","0.00825"
"19.29600","9.11593","0.00842"
"19.39200","9.12400","0.00862"
"19.48800","9.13201","0.00829"
"19.58400","9.13997","0.00848"
"19.68000","9.14798","0.00835"
"19.77600","9.15593","0.00808"
"19.87200","9.16400","0.00829"
"19.96800","9.17201","0.00841"
"20.06400","9.17997","0.00804"
"20.16000","9.18804","0.00801"
"20.25600","9.19599","0.00850"
"20.35200","9.20394","0.00828"
"20.44800","9.21201","0.00811"
"20.54400","9.22002","0.00823"
"20.64000","9.22798","0.00818"
"20.73600","9.23605","0.00848"
"20.83200","9.24394","0.00816"
"20.92800","9.25189","0.00811"
"21.02400","9.26002","0.00834"
"21.12000","9.26803","0.00810"
"21.21600","9.27605","0.00860"
"21.31200","9.28400","0.00810"
"21.40800","9.29201","0.00809"
"21.50400","9.29996","0.00798"
"21.60000","9.30797","0.00802"
"21.69600","9.31605","0.00828"
"21.79200","9.32400","0.00827"
"21.88800","9.33195","0.00822"
"21.98400","9.33996","0.00815"
"22.08000","9.34797","0.00835"
"22.17600","9.35604","0.00865"
"22.27200","9.36400","0.00828"
"22.36800","9.37201","0.00825"
"22.46400","9.37996","0.00831"
"22.56000","9.38791","0.00868"
"22.65600","9.39598","0.00843"
"22.75200","9.40406","0.00853"
"22.84800","9.41201","0.00855"
"22.94400","9.41996","0.00847"
"23.04000","9.42797","0.00832"
"23.13600","9.43592","0.00853"
"23.23200","9.44400","0.00854"
"23.32800","9.45207","0.00853"
"23.42400","9.45996","0.00859"
"23.52000","9.46803","0.00842"
"23.61600","9.47598","0.00837"
"23.71200","9.48394","0.00836"
"23.80800","9.49201","0.00865"
"23.90400","9.50002","0.00871"
"24.00000","9.50797","0.00829"
"24.09600","9.51592","0.00860"
"24.19200","9.52399","0.00847"
"24.28800","9.53195","0.00856"
"24.38400","9.53996","0.00808"
"24.48000","9.54803","0.00815"
"24.57600","9.55598","0.00845"
"24.67200","9.56393","0.00877"
"24.76800","9.57201","0.00845"
"24.86400","9.58002","0.00842"
"24.96000","9.58803","0.00852"
"25.05600","9.59604","0.00825"
"25.15200","9.60399","0.00839"
"25.24800","9.61194","0.00805"
"25.34400","9.62002","0.00848"
"25.44000","9.62803","0.00837"
"25.53600","9.63604","0.00885"
"25.63200","9.64399","0.00832"
"25.72800","9.65194","0.00813"
"25.82400","9.65996","0.00847"
"25.92000","9.66803","0.00834"
"26.01600","9.67598","0.00824"
"26.11200","9.68393","0.00838"
"26.20800","9.69200","0.00818"
"26.30400","9.69989","0.00863"
"26.40000","9.70797","0.00840"
"26.49600","9.71604","0.00844"
"26.59200","9.72399","0.00886"
"26.68800","9.73200","0.00862"
"26.78400","9.73995","0.00812"
"26.88000","9.74797","0.00846"
"26.97600","9.75604","0.00907"
"27.07200","9.76399","0.00850"
"27.16800","9.77200","0.00852"
"27.26400","9.77995","0.00846"
"27.36000","9.78790","0.00845"
"27.45600","9.79598","0.00847"
"27.55200","9.80399","0.00841"
"27.64800","9.81200","0.00882"
"27.74400","9.82001","0.00865"
"27.84000","9.82796","0.00868"
"27.93600","9.83598","0.00853"
"28.03200","9.84399","0.00826"
"28.12800","9.85200","0.00833"
"28.22400","9.86007","0.00871"
"28.32000","9.86796","0.00835"
"28.41600","9.87592","0.00858"
"28.51200","9.88399","0.00859"
"28.60800","9.89200","0.00864"
"28.70400","9.90001","0.00858"
"28.80000","9.90802","0.00823"
"28.89600","9.91597","0.00843"
"28.99200","9.92393","0.00883"
"29.08800","9.93200","0.00843"
"29.18400","9.94001","0.00841"
"29.28000","9.94802","0.00897"
"29.37600","9.95597","0.00844"
"29.47200","9.96399","0.00866"
"29.56800","9.97194","0.00848"
"29.66400","9.98001","0.00887"
"29.76000","9.98802","0.00873"
"29.85600","9.99597","0.00878"
"29.95200","10.00398","0.00853"
"30.04800","10.01200","0.00831"
"30.14400","10.01995","0.00890"
"30.24000","10.02802","0.00851"
"30.33600","10.03603","0.00868"
"30.43200","10.04398","0.00880"
"30.52800","10.05194","0.00868"
"30.62400","10.05995","0.00843"
"30.72000","10.06796","0.00884"
"30.81600","10.07597","0.00850"
"30.91200","10.08398","0.00831"
"31.00800","10.09193","0.00895"
"31.10400","10.09995","0.00867"
"31.20000","10.10796","0.00850"
"31.29600","10.11603","0.00858"
"31.39200","10.12398","0.00861"
"31.48800","10.13205","0.00859"
"31.58400","10.13995","0.00887"
"31.68000","10.14796","0.00855"
"31.77600","10.15603","0.00847"
"31.87200","10.16398","0.00847"
"31.96800","10.17199","0.00848"
"32.06400","10.18000","0.00831"
"32.16000","10.18796","0.00871"
"32.25600","10.19591","0.00851"
"32.35200","10.20398","0.00840"
"32.44800","10.21199","0.00877"
"32.54400","10.22000","0.00834"
"32.64000","10.22802","0.00838"
"32.73600","10.23591","0.00820"
"32.83200","10.24398","0.00882"
"32.92800","10.25205","0.00848"
"33.02400","10.26000","0.00890"
"33.12000","10.26802","0.00856"
"33.21600","10.27597","0.00846"
"33.31200","10.28392","0.00857"
"33.40800","10.29199","0.00858"
"33.50400","10.30000","0.00877"
"33.60000","10.30795","0.00854"
"33.69600","10.31597","0.00844"
"33.79200","10.32398","0.00883"
"33.88800","10.33193","0.00886"
"33.98400","10.34000","0.00903"
"34.08000","10.34801","0.00839"
"34.17600","10.35597","0.00890"
"34.27200","10.36398","0.00875"
"34.36800","10.37193","0.00877"
"34.46400","10.38000","0.00867"
"34.56000","10.38801","0.00844"
"34.65600","10.39596","0.00862"
"34.75200","10.40398","0.00855"
"34.84800","10.41199","0.00917"
"34.94400","10.41994","0.00923"
"35.04000","10.42801","0.00903"
"35.13600","10.43602","0.00850"
"35.23200","10.44398","0.00848"
"35.32800","10.45199","0.00886"
"35.42400","10.45994","0.00883"
"35.52000","10.46801","0.00861"
"35.61600","10.47596","0.00851"
"35.71200","10.48403","0.00879"
"35.80800","10.49199","0.00871"
"35.90400","10.49994","0.00873"
"36.00000","10.50795","0.00844"
"36.09600","10.51602","0.00883"
"36.19200","10.52397","0.00889"
"36.28800","10.53205","0.00878"
"36.38400","10.54000","0.00898"
"36.48000","10.54795","0.00869"
"36.57600","10.55596","0.00868"
"36.67200","10.56403","0.00880"
"36.76800","10.57198","0.00902"
"36.86400","10.58000","0.00866"
"36.96000","10.58795","0.00885"
"37.05600","10.59590","0.00885"
"37.15200","10.60397","0.00880"
"37.24800","10.61198","0.00899"
"37.34400","10.62000","0.00915"
"37.44000","10.62801","0.00856"
"37.53600","10.63596","0.00878"
"37.63200","10.64397","0.00909"
"37.72800","10.65198","0.00895"
"37.82400","10.66005","0.00898"
"37.92000","10.66801","0.00888"
"38.01600","10.67596","0.00892"
"38.11200","10.68397","0.00885"
"38.20800","10.69198","0.00916"
"38.30400","10.70005","0.00864"
"38.40000","10.70801","0.00879"
"38.49600","10.71596","0.00897"
"38.59200","10.72397","0.00882"
"38.68800","10.73198","0.00849"
"38.78400","10.73999","0.00915"
"38.88000","10.74800","0.00882"
"38.97600","10.75602","0.00856"
"39.07200","10.76397","0.00861"
"39.16800","10.77192","0.00916"
"39.26400","10.77999","0.00907"
"39.36000","10.78800","0.00902"
"39.45600","10.79596","0.00889"
"39.55200","10.80403","0.00899"
"39.64800","10.81198","0.00918"
"39.74400","10.81993","0.00896"
"39.84000","10.82800","0.00865"
"39.93600","10.83602","0.00869"
"40.03200","10.84403","0.00901"
"40.12800","10.85198","0.00854"
"40.22400","10.85999","0.00905"
"40.32000","10.86794","0.00936"
"40.41600","10.87601","0.00867"
"40.51200","10.88403","0.00875"
"40.60800","10.89198","0.00913"
"40.70400","10.89999","0.00875"
"40.80000","10.90800","0.00926"
"40.89600","10.91595","0.00893"
"40.99200","10.92403","0.00929"
"41.08800","10.93204","0.00875"
"41.18400","10.93999","0.00900"
"41.28000","10.94794","0.00901"
"41.37600","10.95589","0.00874"
"41.47200","10.96397","0.00898"
"41.56800","10.97204","0.00906"
"41.66400","10.97999","0.00893"
"41.76000","10.98800","0.00930"
"41.85600","10.99601","0.00931"
"41.95200","11.00396","0.00915"
"42.04800","11.01204","0.00910"
"42.14400","11.01999","0.00914"
"42.24000","11.02800","0.00892"
"42.33600","11.03601","0.00903"
"42.43200","11.04396","0.00884"
"42.52800","11.05198","0.00892"
"42.62400","11.06005","0.00925"
"42.72000","11.06800","0.00906"
"42.81600","11.07601","0.00894"
"42.91200","11.08402","0.00881"
"43.00800","11.09198","0.00917"
"43.10400","11.09999","0.00878"
"43.20000","11.10794","0.00900"
"43.29600","11.11595","0.00929"
"43.39200","11.12396","0.00916"
"43.48800","11.13191","0.00860"
"43.58400","11.13999","0.00932"
"43.68000","11.14800","0.00890"
"43.77600","11.15601","0.00882"
"43.87200","11.16396","0.00882"
"43.96800","11.17197","0.00903"
"44.06400","11.17993","0.00898"
"44.16000","11.18800","0.00880"
"44.25600","11.19601","0.00883"
"44.35200","11.20402","0.00878"
"44.44800","11.21197","0.00914"
"44.54400","11.21998","0.00888"
"44.64000","11.22800","0.00912"
"44.73600","11.23601","0.00894"
"44.83200","11.24396","0.00928"
"44.92800","11.25197","0.00891"
"45.02400","11.25992","0.00897"
"45.12000","11.26794","0.00918"
"45.21600","11.27595","0.00898"
"45.31200","11.28402","0.00911"
"45.40800","11.29203","0.00860"
"45.50400","11.29992","0.00916"
"45.60000","11.30799","0.00863"
"45.69600","11.31601","0.00890"
"45.79200","11.32396","0.00899"
"45.88800","11.33203","0.00895"
"45.98400","11.33998","0.00898"
"46.08000","11.34799","0.00857"
"46.17600","11.35595","0.00885"
"46.27200","11.36396","0.00878"
"46.36800","11.37203","0.00915"
"46.46400","11.38004","0.00880"
"46.56000","11.38799","0.00907"
"46.65600","11.39594","0.00908"
"46.75200","11.40396","0.00883"
"46.84800","11.41203","0.00897"
"46.94400","11.41998","0.00913"
"47.04000","11.42799","0.00908"
"47.13600","11.43606","0.00915"
"47.23200","11.44396","0.00898"
"47.32800","11.45197","0.00915"
"47.42400","11.45998","0.00904"
"47.52000","11.46799","0.00915"
"47.61600","11.47600","0.00889"
"47.71200","11.48401","0.00906"
"47.80800","11.49191","0.00925"
"47.90400","11.49992","0.00862"
"48.00000","11.50805","0.00898"
"48.09600","11.51600","0.00878"
"48.19200","11.52395","0.00920"
"48.28800","11.53197","0.00914"
"48.38400","11.53992","0.00922"
"48.48000","11.54799","0.00903"
"48.57600","11.55606","0.00938"
"48.67200","11.56401","0.00921"
"48.76800","11.57196","0.00904"
"48.86400","11.57998","0.00952"
"48.96000","11.58799","0.00895"
"49.05600","11.59600","0.00929"
"49.15200","11.60407","0.00862"
"49.24800","11.61196","0.00926"
"49.34400","11.61998","0.00898"
"49.44000","11.62799","0.00901"
"49.53600","11.63600","0.00945"
"49.63200","11.64401","0.00879"
"49.72800","11.65202","0.00935"
"49.82400","11.65998","0.00931"
"49.92000","11.66799","0.00915"
"50.01600","11.67594","0.00909"
"50.11200","11.68401","0.00882"
"50.20800","11.69196","0.00908"
"50.30400","11.69997","0.00901"
"50.40000","11.70799","0.00892"
"50.49600","11.71594","0.00889"
"50.59200","11.72401","0.00908"
"50.68800","11.73202","0.00935"
"50.78400","11.73997","0.00946"
"50.88000","11.74805","0.00931"
"50.97600","11.75600","0.00924"
"51.07200","11.76395","0.00905"
"51.16800","11.77202","0.00884"
"51.26400","11.77997","0.00917"
"51.36000","11.78798","0.00940"
"51.45600","11.79600","0.00917"
"51.55200","11.80395","0.00918"
"51.64800","11.81190","0.00921"
"51.74400","11.82003","0.00945"
"51.84000","11.82792","0.00935"
"51.93600","11.83594","0.00922"
"52.03200","11.84395","0.00917"
"52.12800","11.85190","0.00915"
"52.22400","11.85997","0.00919"
"52.32000","11.86804","0.00926"
"52.41600","11.87599","0.00872"
"52.51200","11.88395","0.00921"
"52.60800","11.89196","0.00925"
"52.70400","11.89991","0.00942"
"52.80000","11.90798","0.00914"
"52.89600","11.91599","0.00920"
"52.99200","11.92401","0.00911"
"53.08800","11.93196","0.00883"
"53.18400","11.93997","0.00881"
"53.28000","11.94798","0.00937"
"53.37600","11.95599","0.00930"
"53.47200","11.96400","0.00920"
"53.56800","11.97202","0.00899"
"53.66400","11.98003","0.00950"
"53.76000","11.98798","0.00912"
"53.85600","11.99599","0.00922"
"53.95200","12.00400","0.00890"
"54.04800","12.01202","0.00935"
"54.14400","12.01997","0.00930"
"54.24000","12.02792","0.00904"
"54.33600","12.03599","0.00934"
"54.43200","12.04400","0.00935"
"54.52800","12.05196","0.00887"
"54.62400","12.06003","0.00931"
"54.72000","12.06798","0.00920"
"54.81600","12.07587","0.00920"
"54.91200","12.08400","0.00928"
"55.00800","12.09201","0.00939"
"55.10400","12.10003","0.00924"
"55.20000","12.10804","0.00918"
"55.29600","12.11599","0.00930"
"55.39200","12.12394","0.00950"
"55.48800","12.13201","0.00915"
"55.58400","12.14003","0.00940"
"55.68000","12.14798","0.00942"
"55.77600","12.15599","0.00922"
"55.87200","12.16394","0.00960"
"55.96800","12.17195","0.00955"
"56.06400","12.18002","0.00904"
"56.16000","12.18804","0.00966"
"56.25600","12.19599","0.00930"
"56.35200","12.20388","0.00959"
"56.44800","12.21195","0.00960"
"56.54400","12.21996","0.00960"
"56.64000","12.22804","0.00953"
"56.73600","12.23605","0.00943"
"56.83200","12.24400","0.00953"
"56.92800","12.25201","0.00954"
"57.02400","12.25996","0.00964"
"57.12000","12.26798","0.00934"
"57.21600","12.27599","0.00940"
"57.31200","12.28400","0.00983"
"57.40800","12.29201","0.00922"
"57.50400","12.29996","0.00936"
"57.60000","12.30797","0.00940"
"57.69600","12.31599","0.00924"
"57.79200","12.32400","0.00941"
"57.88800","12.33201","0.00938"
"57.98400","12.33996","0.00981"
"58.08000","12.34797","0.00913"
"58.17600","12.35599","0.00917"
"58.27200","12.36400","0.00940"
"58.36800","12.37201","0.00920"
"58.46400","12.38002","0.00951"
"58.56000","12.38791","0.00948"
"58.65600","12.39599","0.00934"
"58.75200","12.40406","0.00923"
"58.84800","12.41195","0.00956"
"58.94400","12.42002","0.00968"
"59.04000","12.42797","0.00903"
"59.13600","12.43592","0.00902"
"59.23200","12.44400","0.00916"
"59.32800","12.45201","0.00950"
"59.42400","12.46002","0.00926"
"59.52000","12.46803","0.00969"
"59.61600","12.47598","0.00901"
"59.71200","12.48400","0.00940"
"59.80800","12.49201","0.00929"
"59.90400","12.50002","0.00918"
"60.00000","12.50797","0.00927"
"60.09600","12.51598","0.00961"
"60.19200","12.52399","0.00935"
"60.28800","12.53201","0.00960"
"60.38400","12.54002","0.00950"
"60.48000","12.54803","0.00950"
"60.57600","12.55592","0.00952"
"60.67200","12.56393","0.00956"
"60.76800","12.57201","0.00990"
"60.86400","12.57996","0.00939"
"60.96000","12.58797","0.00951"
"61.05600","12.59598","0.00968"
"61.15200","12.60393","0.00962"
"61.24800","12.61194","0.00933"
"61.34400","12.62002","0.00915"
"61.44000","12.62797","0.00930"
"61.53600","12.63604","0.00958"
"61.63200","12.64399","0.00925"
"61.72800","12.65194","0.00954"
"61.82400","12.65996","0.00962"
"61.92000","12.66803","0.00914"
"62.01600","12.67598","0.00922"
"62.11200","12.68405","0.00950"
"62.20800","12.69200","0.00939"
"62.30400","12.69990","0.00940"
"62.40000","12.70797","0.00943"
"62.49600","12.71604","0.00963"
"62.59200","12.72399","0.00947"
"62.68800","12.73194","0.00948"
"62.78400","12.73995","0.00946"
"62.88000","12.74791","0.00952"
"62.97600","12.75598","0.00984"
"63.07200","12.76399","0.00979"
"63.16800","12.77206","0.00969"
"63.26400","12.78001","0.00976"
"63.36000","12.78796","0.00945"
"63.45600","12.79598","0.00950"
"63.55200","12.80399","0.00945"
"63.64800","12.81200","0.00978"
"63.74400","12.82001","0.00940"
"63.84000","12.82796","0.00955"
"63.93600","12.83592","0.00979"
"64.03200","12.84393","0.00952"
"64.12800","12.85206","0.00964"
"64.22400","12.86001","0.00967"
"64.32000","12.86796","0.00942"
"64.41600","12.87597","0.00960"
"64.51200","12.88399","0.00953"
"64.60800","12.89194","0.00993"
"64.70400","12.90001","0.00971"
"64.80000","12.90802","0.00986"
"64.89600","12.91597","0.00957"
"64.99200","12.92393","0.01003"
"65.08800","12.93194","0.00976"
"65.18400","12.93995","0.00948"
"65.28000","12.94802","0.00950"
"65.37600","12.95597","0.00950"
"65.47200","12.96399","0.00985"
"65.56800","12.97194","0.00979"
"65.66400","12.97995","0.00980"
"65.76000","12.98802","0.00959"
"65.85600","12.99603","0.01000"
"65.95200","13.00398","0.00989"
"66.04800","13.01194","0.00929"
"66.14400","13.01995","0.00952"
"66.24000","13.02802","0.01004"
"66.33600","13.03597","0.00986"
"66.43200","13.04398","0.00947"
"66.52800","13.05206","0.01004"
"66.62400","13.05995","0.00976"
"66.72000","13.06796","0.00975"
"66.81600","13.07603","0.00941"
"66.91200","13.08398","0.00998"
"67.00800","13.09199","0.00979"
"67.10400","13.09995","0.01002"
"67.20000","13.10790","0.00958"
"67.29600","13.11597","0.00954"
"67.39200","13.12398","0.00968"
"67.48800","13.13199","0.00969"
"67.58400","13.13995","0.00953"
"67.68000","13.14796","0.00964"
"67.77600","13.15597","0.00962"
"67.87200","13.16398","0.00998"
"67.96800","13.17199","0.00986"
"68.06400","13.18000","0.00990"
"68.16000","13.18796","0.00963"
"68.25600","13.19597","0.00929"
"68.35200","13.20398","0.00954"
"68.44800","13.21199","0.00977"
"68.54400","13.22000","0.00981"
"68.64000","13.22802","0.00997"
"68.73600","13.23597","0.00971"
"68.83200","13.24398","0.00968"
"68.92800","13.25205","0.00995"
"69.02400","13.25994","0.00971"
"69.12000","13.26796","0.00974"
"69.21600","13.27597","0.00986"
"69.31200","13.28392","0.00979"
"69.40800","13.29193","0.00981"
"69.50400","13.30000","0.00996"
"69.60000","13.30801","0.00983"
"69.69600","13.31597","0.00962"
"69.79200","13.32398","0.00988"
"69.88800","13.33193","0.00961"
"69.98400","13.34000","0.00982"
"70.08000","13.34801","0.00993"
"70.17600","13.35602","0.00960"
"70.27200","13.36398","0.00960"
"70.36800","13.37193","0.00993"
"70.46400","13.37994","0.00950"
"70.56000","13.38801","0.00980"
"70.65600","13.39597","0.00996"
"70.75200","13.40404","0.00994"
"70.84800","13.41199","0.00981"
"70.94400","13.41988","0.00972"
"71.04000","13.42801","0.00992"
"71.13600","13.43602","0.00957"
"71.23200","13.44404","0.00969"
"71.32800","13.45199","0.00991"
"71.42400","13.45994","0.00982"
"71.52000","13.46795","0.00947"
"71.61600","13.47596","0.00949"
"71.71200","13.48403","0.00973"
"71.80800","13.49205","0.00992"
"71.90400","13.49994","0.00969"
"72.00000","13.50795","0.01002"
"72.09600","13.51602","0.00989"
"72.19200","13.52403","0.01001"
"72.28800","13.53199","0.01017"
"72.38400","13.54006","0.00970"
"72.48000","13.54795","0.00989"
"72.57600","13.55590","0.00975"
"72.67200","13.56403","0.00993"
"72.76800","13.57199","0.00989"
"72.86400","13.58000","0.00995"
"72.96000","13.58801","0.00996"
"73.05600","13.59596","0.01006"
"73.15200","13.60397","0.00993"
"73.24800","13.61204","0.00968"
"73.34400","13.62000","0.00971"
"73.44000","13.62801","0.01014"
"73.53600","13.63596","0.00974"
"73.63200","13.64391","0.01002"
"73.72800","13.65192","0.01002"
"73.82400","13.66000","0.00970"
"73.92000","13.66795","0.00980"
"74.01600","13.67596","0.00962"
"74.11200","13.68397","0.00964"
"74.20800","13.69192","0.01005"
"74.30400","13.70005","0.00974"
"74.40000","13.70801","0.00939"
"74.49600","13.71602","0.00976"
"74.59200","13.72403","0.00977"
"74.68800","13.73198","0.00976"
"74.78400","13.73999","0.00971"
"74.88000","13.74801","0.00959"
"74.97600","13.75602","0.00969"
"75.07200","13.76397","0.00982"
"75.16800","13.77198","0.00982"
"75.26400","13.77999","0.01023"
"75.36000","13.78795","0.00956"
"75.45600","13.79596","0.00980"
"75.55200","13.80403","0.01020"
"75.64800","13.81192","0.01011"
"75.74400","13.81993","0.00995"
"75.84000","13.82800","0.00983"
"75.93600","13.83602","0.00949"
"76.03200","13.84397","0.00995"
"76.12800","13.85204","0.00989"
"76.22400","13.85999","0.00997"
"76.32000","13.86794","0.00976"
"76.41600","13.87602","0.00965"
"76.51200","13.88403","0.00965"
"76.60800","13.89198","0.00997"
"76.70400","13.90005","0.00998"
"76.80000","13.90800","0.00994"
"76.89600","13.91595","0.00973"
"76.99200","13.92403","0.00985"
"77.08800","13.93198","0.00994"
"77.18400","13.93999","0.00996"
"77.28000","13.94800","0.00996"
"77.37600","13.95595","0.00980"
"77.47200","13.96397","0.00983"
"77.56800","13.97204","0.00946"
"77.66400","13.97993","0.00961"
"77.76000","13.98794","0.00953"
"77.85600","13.99601","0.00976"
"77.95200","14.00391","0.00947"
"78.04800","14.01198","0.00962"
"78.14400","14.01999","0.00968"
"78.24000","14.02800","0.00942"
"78.33600","14.03595","0.00969"
"78.43200","14.04391","0.00968"
"78.52800","14.05198","0.00991"
"78.62400","14.05999","0.00965"
"78.72000","14.06800","0.00977"
"78.81600","14.07595","0.00949"
"78.91200","14.08396","0.00997"
"79.00800","14.09192","0.00965"
"79.10400","14.09999","0.00971"
"79.20000","14.10800","0.00974"
"79.29600","14.11607","0.00967"
"79.39200","14.12396","0.00992"
"79.48800","14.13197","0.00986"
"79.58400","14.13999","0.00999"
"79.68000","14.14800","0.00995"
"79.77600","14.15601","0.00966"
"79.87200","14.16402","0.00972"
"79.96800","14.17197","0.00964"
"80.06400","14.17992","0.00990"
"80.16000","14.18800","0.00938"
"80.25600","14.19601","0.00986"
"80.35200","14.20396","0.00984"
"80.44800","14.21203","0.00942"
"80.54400","14.21992","0.00976"
"80.64000","14.22788","0.00977"
"80.73600","14.23601","0.00950"
"80.83200","14.24402","0.00968"
"80.92800","14.25203","0.00983"
"81.02400","14.26004","0.00990"
"81.12000","14.26794","0.00999"
"81.21600","14.27595","0.01021"
"81.31200","14.28402","0.00964"
"81.40800","14.29197","0.00968"
"81.50400","14.29998","0.00954"
"81.60000","14.30799","0.00981"
"81.69600","14.31595","0.00996"
"81.79200","14.32396","0.00994"
"81.88800","14.33203","0.01000"
"81.98400","14.33998","0.01022"
"82.08000","14.34799","0.00993"
"82.17600","14.35595","0.00994"
"82.27200","14.36390","0.00983"
"82.36800","14.37203","0.00956"
"82.46400","14.37998","0.01000"
"82.56000","14.38799","0.01000"
"82.65600","14.39600","0.00987"
"82.75200","14.40396","0.00970"
"82.84800","14.41197","0.00996"
"82.94400","14.41998","0.00979"
"83.04000","14.42799","0.00994"
"83.13600","14.43600","0.01004"
"83.23200","14.44396","0.00955"
"83.32800","14.45197","0.00997"
"83.42400","14.45998","0.00992"
"83.52000","14.46799","0.00959"
"83.61600","14.47600","0.00981"
"83.71200","14.48401","0.00990"
"83.80800","14.49197","0.00961"
"83.90400","14.49998","0.00956"
"84.00000","14.50799","0.00971"
"84.09600","14.51600","0.00974"
"84.19200","14.52401","0.01020"
"84.28800","14.53197","0.01020"
"84.38400","14.53986","0.00988"
"84.48000","14.54799","0.01020"
"84.57600","14.55606","0.01014"
"84.67200","14.56395","0.00986"
"84.76800","14.57202","0.00999"
"84.86400","14.58004","0.01000"
"84.96000","14.58793","0.01006"
"85.05600","14.59594","0.00993"
"85.15200","14.60407","0.00981"
"85.24800","14.61197","0.01017"
"85.34400","14.61998","0.00927"
"85.44000","14.62799","0.00981"
"85.53600","14.63594","0.00974"
"85.63200","14.64401","0.00976"
"85.72800","14.65196","0.01026"
"85.82400","14.66003","0.01005"
"85.92000","14.66799","0.01001"
"86.01600","14.67594","0.00937"
"86.11200","14.68401","0.00987"
"86.20800","14.69202","0.01011"
"86.30400","14.69998","0.01027"
"86.40000","14.70799","0.01011"
"86.49600","14.71594","0.01004"
"86.59200","14.72395","0.01008"
"86.68800","14.73196","0.00974"
"86.78400","14.73997","0.01005"
"86.88000","14.74799","0.00995"
"86.97600","14.75594","0.00968"
"87.07200","14.76395","0.01027"
"87.16800","14.77202","0.01038"
"87.26400","14.77997","0.00988"
"87.36000","14.78798","0.00994"
"87.45600","14.79606","0.00981"
"87.55200","14.80395","0.00977"
"87.64800","14.81196","0.00979"
"87.74400","14.81997","0.01007"
"87.84000","14.82798","0.00998"
"87.93600","14.83600","0.00977"
"88.03200","14.84401","0.00977"
"88.12800","14.85196","0.00969"
"88.22400","14.85997","0.00998"
"88.32000","14.86804","0.01014"
"88.41600","14.87594","0.01005"
"88.51200","14.88395","0.00995"
"88.60800","14.89196","0.00962"
"88.70400","14.89991","0.01012"
"88.80000","14.90792","0.01023"
"88.89600","14.91605","0.00966"
"88.99200","14.92401","0.00962"
"89.08800","14.93202","0.00997"
"89.18400","14.94003","0.00986"
"89.28000","14.94792","0.00973"
"89.37600","14.95599","0.01013"
"89.47200","14.96406","0.01014"
"89.56800","14.97202","0.00981"
"89.66400","14.97997","0.00995"
"89.76000","14.98792","0.00988"
"89.85600","14.99593","0.01018"
"89.95200","15.00406","0.00992"
"90.04800","15.01202","0.01010"
"90.14400","15.01997","0.01023"
"90.24000","15.02798","0.00986"
"90.33600","15.03599","0.01005"
"90.43200","15.04394","0.00991"
"90.52800","15.05202","0.01002"
"90.62400","15.06003","0.01008"
"90.72000","15.06792","0.00976"
"90.81600","15.07593","0.00994"
"90.91200","15.08400","0.01017"
"91.00800","15.09196","0.01011"
"91.10400","15.09997","0.00976"
"91.20000","15.10804","0.01028"
"91.29600","15.11599","0.01009"
"91.39200","15.12394","0.01010"
"91.48800","15.13195","0.00994"
"91.58400","15.13997","0.01017"
"91.68000","15.14804","0.00988"
"91.77600","15.15599","0.01003"
"91.87200","15.16394","0.00992"
"91.96800","15.17195","0.01006"
"92.06400","15.18003","0.00978"
"92.16000","15.18804","0.00962"
"92.25600","15.19605","0.01026"
"92.35200","15.20400","0.01020"
"92.44800","15.21195","0.01011"
"92.54400","15.21996","0.01051"
"92.64000","15.22804","0.00997"
"92.73600","15.23599","0.01032"
"92.83200","15.24400","0.01010"
"92.92800","15.25195","0.01012"
"93.02400","15.25990","0.01012"
"93.12000","15.26798","0.00967"
"93.21600","15.27605","0.00997"
"93.31200","15.28400","0.01000"
"93.40800","15.29201","0.00979"
"93.50400","15.29996","0.00997"
"93.60000","15.30797","0.00982"
"93.69600","15.31605","0.01027"
"93.79200","15.32400","0.00976"
"93.88800","15.33201","0.01006"
"93.98400","15.34002","0.01029"
"94.08000","15.34797","0.00988"
"94.17600","15.35599","0.01048"
"94.27200","15.36400","0.00997"
"94.36800","15.37201","0.00970"
"94.46400","15.38002","0.01011"
"94.56000","15.38797","0.00999"
"94.65600","15.39598","0.00988"
"94.75200","15.40400","0.01027"
"94.84800","15.41195","0.00990"
"94.94400","15.41996","0.01042"
"95.04000","15.42797","0.01008"
"95.13600","15.43592","0.01035"
"95.23200","15.44400","0.01034"
"95.32800","15.45201","0.01015"
"95.42400","15.45996","0.01024"
"95.52000","15.46797","0.01021"
"95.61600","15.47598","0.00980"
"95.71200","15.48394","0.01020"
"95.80800","15.49201","0.01017"
"95.90400","15.50002","0.01001"
"96.00000","15.50797","0.01037"
"96.09600","15.51598","0.01017"
"96.19200","15.52393","0.01042"
"96.28800","15.53195","0.01053"
"96.38400","15.54002","0.01038"
"96.48000","15.54803","0.01017"
"96.57600","15.55598","0.01029"
"96.67200","15.56399","0.00998"
"96.76800","15.57195","0.01042"
"96.86400","15.57996","0.01006"
"96.96000","15.58803","0.00994"
"97.05600","15.59604","0.01026"
"97.15200","15.60393","0.01012"
"97.24800","15.61195","0.01016"
"97.34400","15.61996","0.01033"
"97.44000","15.62797","0.01042"
"97.53600","15.63598","0.00997"
"97.63200","15.64405","0.01002"
"97.72800","15.65194","0.01031"
"97.82400","15.65995","0.01056"
"97.92000","15.66797","0.01008"
"98.01600","15.67604","0.01004"
"98.11200","15.68399","0.01044"
"98.20800","15.69200","0.00993"
"98.30400","15.69995","0.01012"
"98.40000","15.70791","0.01011"
"98.49600","15.71604","0.00995"
"98.59200","15.72399","0.01010"
"98.68800","15.73200","0.01043"
"98.78400","15.74001","0.01035"
"98.88000","15.74796","0.00998"
"98.97600","15.75598","0.00970"
"99.07200","15.76399","0.01033"
"99.16800","15.77200","0.01006"
"99.26400","15.78001","0.00987"
"99.36000","15.78796","0.01041"
"99.45600","15.79592","0.00994"
"99.55200","15.80399","0.01010"
"99.64800","15.81200","0.01034"
"99.74400","15.82001","0.01060"
"99.84000","15.82802","0.01046"
"99.93600","15.83603","0.01039"
"100.03200","15.84393","0.01005"
"100.12800","15.85200","0.01038"
"100.22400","15.86007","0.01058"
"100.32000","15.86802","0.01009"
"100.41600","15.87603","0.01031"
"100.51200","15.88399","0.01038"
"100.60800","15.89194","0.01027"
"100.70400","15.90001","0.01007"
"100.80000","15.90808","0.01043"
"100.89600","15.91597","0.01045"
"100.99200","15.92392","0.01018"
"101.08800","15.93200","0.01036"
"101.18400","15.93995","0.01041"
"101.28000","15.94796","0.01020"
"101.37600","15.95597","0.01046"
"101.47200","15.96398","0.01029"
"101.56800","15.97194","0.01059"
"101.66400","15.97995","0.01049"
"101.76000","15.98802","0.01046"
"101.85600","15.99597","0.01029"
"101.95200","16.00404","0.01051"
"102.04800","16.01200","0.01025"
"102.14400","16.01995","0.01059"
"102.24000","16.02802","0.01044"
"102.33600","16.03597","0.01065"
"102.43200","16.04398","0.01011"
"102.52800","16.05199","0.01074"
"102.62400","16.05995","0.01029"
"102.72000","16.06796","0.01070"
"102.81600","16.07597","0.01057"
"102.91200","16.08392","0.01023"
"103.00800","16.09205","0.01043"
"103.10400","16.10001","0.01037"
"103.20000","16.10796","0.01060"
"103.29600","16.11597","0.01010"
"103.39200","16.12398","0.01050"
"103.48800","16.13199","0.01043"
"103.58400","16.14001","0.01031"
"103.68000","16.14796","0.01080"
"103.77600","16.15591","0.01046"
"103.87200","16.16398","0.01039"
"103.96800","16.17205","0.01047"
"104.06400","16.17994","0.01017"
"104.16000","16.18796","0.01058"
"104.25600","16.19597","0.01064"
"104.35200","16.20392","0.01042"
"104.44800","16.21199","0.01051"
"104.54400","16.22000","0.01060"
"104.64000","16.22801","0.01084"
"104.73600","16.23597","0.01037"
"104.83200","16.24398","0.01054"
"104.92800","16.25199","0.01045"
"105.02400","16.26000","0.01053"
"105.12000","16.26801","0.01089"
"105.21600","16.27597","0.01087"
"105.31200","16.28392","0.01045"
"105.40800","16.29199","0.01062"
"105.50400","16.30000","0.01053"
"105.60000","16.30801","0.01090"
"105.69600","16.31597","0.01051"
"105.79200","16.32392","0.01046"
"105.88800","16.33193","0.01027"
"105.98400","16.34000","0.01062"
"106.08000","16.34801","0.01085"
"106.17600","16.35596","0.01058"
"106.27200","16.36404","0.01070"
"106.36800","16.37199","0.01059"
"106.46400","16.37994","0.01051"
"106.56000","16.38801","0.01082"
"106.65600","16.39602","0.01060"
"106.75200","16.40403","0.01052"
"106.84800","16.41199","0.01102"
"106.94400","16.41994","0.01072"
"107.04000","16.42795","0.01068"
"107.13600","16.43596","0.01103"
"107.23200","16.44403","0.01104"
"107.32800","16.45199","0.01054"
"107.42400","16.46000","0.01061"
"107.52000","16.46795","0.01055"
"107.61600","16.47596","0.01125"
"107.71200","16.48403","0.01069"
"107.80800","16.49199","0.01063"
"107.90400","16.50000","0.01086"
"108.00000","16.50801","0.01078"
"108.09600","16.51596","0.01031"
"108.19200","16.52397","0.01058"
"108.28800","16.53205","0.01102"
"108.38400","16.54006","0.01074"
"108.48000","16.54795","0.01060"
"108.57600","16.55596","0.01087"
"108.67200","16.56397","0.01064"
"108.76800","16.57198","0.01091"
"108.86400","16.58000","0.01073"
"108.96000","16.58801","0.01079"
"109.05600","16.59596","0.01075"
"109.15200","16.60397","0.01077"
"109.24800","16.61198","0.01071"
"109.34400","16.62000","0.01097"
"109.44000","16.62801","0.01113"
"109.53600","16.63602","0.01068"
"109.63200","16.64397","0.01122"
"109.72800","16.65198","0.01106"
"109.82400","16.65999","0.01044"
"109.92000","16.66795","0.01079"
"110.01600","16.67602","0.01087"
"110.11200","16.68397","0.01085"
"110.20800","16.69192","0.01083"
"110.30400","16.69993","0.01117"
"110.40000","16.70801","0.01047"
"110.49600","16.71602","0.01108"
"110.59200","16.72397","0.01097"
"110.68800","16.73198","0.01125"
"110.78400","16.73993","0.01087"
"110.88000","16.74800","0.01122"
"110.97600","16.75602","0.01105"
"111.07200","16.76403","0.01076"
"111.16800","16.77204","0.01097"
"111.26400","16.77999","0.01095"
"111.36000","16.78794","0.01085"
"111.45600","16.79607","0.01118"
"111.55200","16.80403","0.01095"
"111.64800","16.81198","0.01090"
"111.74400","16.81999","0.01144"
"111.84000","16.82794","0.01102"
"111.93600","16.83596","0.01098"
"112.03200","16.84403","0.01106"
"112.12800","16.85198","0.01093"
"112.22400","16.85993","0.01098"
"112.32000","16.86794","0.01114"
"112.41600","16.87595","0.01135"
"112.51200","16.88397","0.01161"
"112.60800","16.89204","0.01100"
"112.70400","16.90005","0.01088"
"112.80000","16.90794","0.01094"
"112.89600","16.91595","0.01093"
"112.99200","16.92402","0.01105"
"113.08800","16.93198","0.01114"
"113.18400","16.94005","0.01124"
"113.28000","16.94806","0.01104"
"113.37600","16.95595","0.01094"
"113.47200","16.96396","0.01129"
"113.56800","16.97203","0.01109"
"113.66400","16.97999","0.01099"
"113.76000","16.98794","0.01095"
"113.85600","16.99601","0.01113"
"113.95200","17.00396","0.01106"
"114.04800","17.01192","0.01077"
"114.14400","17.01999","0.01111"
"114.24000","17.02800","0.01144"
"114.33600","17.03595","0.01135"
"114.43200","17.04390","0.01104"
"114.52800","17.05191","0.01132"
"114.62400","17.05999","0.01144"
"114.72000","17.06806","0.01110"
"114.81600","17.07607","0.01095"
"114.91200","17.08402","0.01134"
"115.00800","17.09197","0.01150"
"115.10400","17.09993","0.01130"
"115.20000","17.10800","0.01119"
"115.29600","17.11601","0.01135"
"115.39200","17.12396","0.01140"
"115.48800","17.13197","0.01161"
"115.58400","17.13998","0.01127"
"115.68000","17.14794","0.01154"
"115.77600","17.15601","0.01169"
"115.87200","17.16402","0.01095"
"115.96800","17.17197","0.01140"
"116.06400","17.17999","0.01139"
"116.16000","17.18800","0.01118"
"116.25600","17.19595","0.01141"
"116.35200","17.20396","0.01124"
"116.44800","17.21197","0.01144"
"116.54400","17.21992","0.01139"
"116.64000","17.22793","0.01109"
"116.73600","17.23601","0.01140"
"116.83200","17.24396","0.01159"
"116.92800","17.25197","0.01142"
"117.02400","17.26004","0.01140"
"117.12000","17.26793","0.01171"
"117.21600","17.27595","0.01147"
"117.31200","17.28402","0.01116"
"117.40800","17.29203","0.01093"
"117.50400","17.29998","0.01155"
"117.60000","17.30805","0.01149"
"117.69600","17.31601","0.01142"
"117.79200","17.32396","0.01158"
"117.88800","17.33203","0.01124"
"117.98400","17.33998","0.01146"
"118.08000","17.34805","0.01165"
"118.17600","17.35600","0.01098"
"118.27200","17.36396","0.01128"
"118.36800","17.37197","0.01121"
"118.46400","17.37998","0.01170"
"118.56000","17.38799","0.01140"
"118.65600","17.39600","0.01112"
"118.75200","17.40396","0.01164"
"118.84800","17.41191","0.01171"
"118.94400","17.41998","0.01177"
"119.04000","17.42805","0.01167"
"119.13600","17.43600","0.01133"
"119.23200","17.44395","0.01160"
"119.32800","17.45203","0.01136"
"119.42400","17.45992","0.01154"
"119.52000","17.46799","0.01104"
"119.61600","17.47600","0.01160"
"119.71200","17.48395","0.01156"
"119.80800","17.49197","0.01157"
"119.90400","17.49992","0.01202"
"120.00000","17.50799","0.01138"
"120.09600","17.51600","0.01146"
"120.19200","17.52401","0.01166"
"120.28800","17.53197","0.01144"
"120.38400","17.53998","0.01135"
"120.48000","17.54799","0.01118"
"120.57600","17.55600","0.01147"
"120.67200","17.56401","0.01136"
"120.76800","17.57196","0.01144"
"120.86400","17.57998","0.01138"
"120.96000","17.58793","0.01143"
"121.05600","17.59594","0.01119"
"121.15200","17.60401","0.01136"
"121.24800","17.61196","0.01167"
"121.34400","17.61997","0.01150"
"121.44000","17.62793","0.01176"
"121.53600","17.63594","0.01134"
"121.63200","17.64395","0.01162"
"121.72800","17.65196","0.01162"
"121.82400","17.66003","0.01168"
"121.92000","17.66793","0.01181"
"122.01600","17.67594","0.01175"
"122.11200","17.68395","0.01162"
"122.20800","17.69196","0.01153"
"122.30400","17.70003","0.01153"
"122.40000","17.70804","0.01151"
"122.49600","17.71594","0.01148"
"122.59200","17.72395","0.01147"
"122.68800","17.73202","0.01164"
"122.78400","17.74003","0.01180"
"122.88000","17.74799","0.01192"
"122.97600","17.75600","0.01152"
"123.07200","17.76395","0.01126"
"123.16800","17.77196","0.01194"
"123.26400","17.77997","0.01164"
"123.36000","17.78804","0.01185"
"123.45600","17.79606","0.01144"
"123.55200","17.80395","0.01190"
"123.64800","17.81196","0.01150"
"123.74400","17.81997","0.01152"
"123.84000","17.82798","0.01215"
"123.93600","17.83605","0.01168"
"124.03200","17.84401","0.01159"
"124.12800","17.85196","0.01162"
"124.22400","17.85997","0.01170"
"124.32000","17.86798","0.01133"
"124.41600","17.87599","0.01147"
"124.51200","17.88401","0.01164"
"124.60800","17.89202","0.01174"
"124.70400","17.89997","0.01174"
"124.80000","17.90798","0.01154"
"124.89600","17.91599","0.01194"
"124.99200","17.92395","0.01161"
"125.08800","17.93202","0.01131"
"125.18400","17.93997","0.01127"
"125.28000","17.94792","0.01117"
"125.37600","17.95599","0.01114"
"125.47200","17.96406","0.01096"
"125.56800","17.97196","0.01112"
"125.66400","17.98003","0.01071"
"125.76000","17.98798","0.01073"
"125.85600","17.99593","0.01086"
"125.95200","18.00400","0.01107"
"126.04800","18.01201","0.01127"
"126.14400","18.02003","0.01102"
"126.24000","18.02798","0.01086"
"126.33600","18.03599","0.01112"
"126.43200","18.04394","0.01107"
"126.52800","18.05195","0.01105"
"126.62400","18.06003","0.01069"
"126.72000","18.06798","0.01092"
"126.81600","18.07593","0.01084"
"126.91200","18.08400","0.01061"
"127.00800","18.09196","0.01106"
"127.10400","18.09997","0.01115"
"127.20000","18.10798","0.01097"
"127.29600","18.11593","0.01062"
"127.39200","18.12394","0.01088"
"127.48800","18.13195","0.01078"
"127.58400","18.14003","0.01110"
"127.68000","18.14798","0.01085"
"127.77600","18.15599","0.01090"
"127.87200","18.16400","0.01086"
"127.96800","18.17195","0.01086"
"128.06400","18.17996","0.01079"
"128.16000","18.18797","0.01054"
"128.25600","18.19599","0.01113"
"128.35200","18.20400","0.01103"
"128.44800","18.21195","0.01080"
"128.54400","18.21990","0.01121"
"128.64000","18.22803","0.01102"
"128.73600","18.23599","0.01111"
"128.83200","18.24400","0.01111"
"128.92800","18.25201","0.01125"
"129.02400","18.25990","0.01103"
"129.12000","18.26797","0.01119"
"129.21600","18.27604","0.01104"
"129.31200","18.28394","0.01091"
"129.40800","18.29195","0.01095"
"129.50400","18.30002","0.01125"
"129.60000","18.30791","0.01131"
"129.69600","18.31593","0.01132"
"129.79200","18.32400","0.01142"
"129.88800","18.33201","0.01107"
"129.98400","18.33996","0.01109"
"130.08000","18.34791","0.01111"
"130.17600","18.35598","0.01099"
"130.27200","18.36399","0.01134"
"130.36800","18.37201","0.01108"
"130.46400","18.38002","0.01116"
"130.56000","18.38797","0.01112"
"130.65600","18.39598","0.01128"
"130.75200","18.40400","0.01076"
"130.84800","18.41201","0.01117"
"130.94400","18.42002","0.01119"
"131.04000","18.42797","0.01102"
"131.13600","18.43592","0.01124"
"131.23200","18.44399","0.01118"
"131.32800","18.45201","0.01118"
"131.42400","18.46002","0.01107"
"131.52000","18.46803","0.01094"
"131.61600","18.47592","0.01123"
"131.71200","18.48400","0.01104"
"131.80800","18.49201","0.01093"
"131.90400","18.49996","0.01100"
"132.00000","18.50803","0.01096"
"132.09600","18.51604","0.01078"
"132.19200","18.52393","0.01111"
"132.28800","18.53194","0.01114"
"132.38400","18.54002","0.01097"
"132.48000","18.54797","0.01110"
"132.57600","18.55598","0.01099"
"132.67200","18.56405","0.01098"
"132.76800","18.57195","0.01122"
"132.86400","18.57996","0.01082"
"132.96000","18.58803","0.01102"
"133.05600","18.59598","0.01106"
"133.15200","18.60399","0.01096"
"133.24800","18.61206","0.01091"
"133.34400","18.61996","0.01091"
"133.44000","18.62797","0.01090"
"133.53600","18.63604","0.01087"
"133.63200","18.64399","0.01095"
"133.72800","18.65194","0.01113"
"133.82400","18.65995","0.01114"
"133.92000","18.66791","0.01114"
"134.01600","18.67592","0.01088"
"134.11200","18.68399","0.01125"
"134.20800","18.69200","0.01109"
"134.30400","18.69995","0.01109"
"134.40000","18.70797","0.01099"
"134.49600","18.71592","0.01132"
"134.59200","18.72399","0.01095"
"134.68800","18.73206","0.01109"
"134.78400","18.74001","0.01085"
"134.88000","18.74802","0.01133"
"134.97600","18.75598","0.01078"
"135.07200","18.76399","0.01131"
"135.16800","18.77206","0.01132"
"135.26400","18.78001","0.01081"
"135.36000","18.78796","0.01112"
"135.45600","18.79598","0.01122"
"135.55200","18.80393","0.01092"
"135.64800","18.81200","0.01069"
"135.74400","18.82001","0.01117"
"135.84000","18.82802","0.01079"
"135.93600","18.83598","0.01104"
"135.97000","18.83879","0.01101"