File: Force_trajectories/170226_1/Specimen_RawData_9.csv
End date,"2/26/2017"
Specimen label,"6AT_47"
Maximum Load,"0.19279",N

Time,Extension,Load
(s),(mm),(N)
"0.00000","0.00000","0.00008"
"0.16200","0.00998","0.00017"
"0.32400","0.02679","-0.00019"
"0.48600","0.04090","0.00048"
"0.64800","0.05423","0.00027"
"0.81000","0.06774","-0.00020"
"0.97200","0.08125","0.00069"
"1.13400","0.09483","0.00019"
"1.29600","0.10822","0.00028"
"1.45800","0.12173","0.00031"
"1.62000","0.13524","-0.00008"
"1.78200","0.14870","0.00057"
"1.94400","0.16215","0.00075"
"2.10600","0.17572","-0.00015"
"2.26800","0.18929","0.00091"
"2.43000","0.20269","0.00070"
"2.59200","0.21620","0.00050"
"2.75400","0.22977","0.00014"
"2.91600","0.24316","0.00042"
"3.07800","0.25668","-0.00026"
"3.24000","0.27019","0.00019"
"3.40200","0.28370","0.00040"
"3.56400","0.29715","0.00066"
"3.72600","0.31073","0.00072"
"3.88800","0.32424","0.00074"
"4.05000","0.33763","0.00067"
"4.21200","0.35126","0.00086"
"4.37400","0.36472","0.00098"
"4.53600","0.37823","0.00034"
"4.69800","0.39168","0.00085"
"4.86000","0.40531","0.00014"
"5.02200","0.41877","0.00068"
"5.18400","0.43216","0.00083"
"5.34600","0.44573","0.00074"
"5.50800","0.45924","0.00037"
"5.67000","0.47270","0.00040"
"5.83200","0.48621","0.00049"
"5.99400","0.49972","0.00026"
"6.15600","0.51323","0.00052"
"6.31800","0.52669","0.00073"
"6.48000","0.54026","0.00061"
"6.64200","0.55371","0.00065"
"6.80400","0.56716","0.00013"
"6.96600","0.58074","0.00093"
"7.12800","0.59425","0.00074"
"7.29000","0.60770","0.00037"
"7.45200","0.62127","0.00051"
"7.61400","0.63473","0.00032"
"7.77600","0.64818","0.00085"
"7.93800","0.66169","0.00053"
"8.10000","0.67520","0.00033"
"8.26200","0.68866","0.00071"
"8.42400","0.70217","0.00049"
"8.58600","0.71580","0.00046"
"8.74800","0.72925","0.00039"
"8.91000","0.74271","0.00004"
"9.07200","0.75622","0.00048"
"9.23400","0.76973","0.00030"
"9.39600","0.78318","0.00043"
"9.55800","0.79670","0.00030"
"9.72000","0.81027","0.00045"
"9.88200","0.82372","0.00039"
"10.04400","0.83717","0.00084"
"10.20600","0.85075","0.00084"
"10.36800","0.86426","0.00033"
"10.53000","0.87765","0.00093"
"10.69200","0.89116","0.00063"
"10.85400","0.90474","0.00114"
"11.01600","0.91819","0.00101"
"11.17800","0.93176","0.00021"
"11.34000","0.94521","0.00085"
"11.50200","0.95873","0.00103"
"11.66400","0.97218","0.00065"
"11.82600","0.98575","0.00062"
"11.98800","0.99926","0.00108"
"12.15000","1.01272","0.00076"
"12.31200","1.02623","0.00146"
"12.47400","1.03980","0.00094"
"12.63600","1.05319","0.00096"
"12.79800","1.06671","0.00062"
"12.96000","1.08022","0.00058"
"13.12200","1.09373","0.00049"
"13.28400","1.10718","0.00067"
"13.44600","1.12075","0.00097"
"13.60800","1.13421","0.00092"
"13.77000","1.14772","0.00039"
"13.93200","1.16123","-0.00002"
"14.09400","1.17474","0.00055"
"14.25600","1.18820","0.00042"
"14.41800","1.20171","0.00069"
"14.58000","1.21522","0.00035"
"14.74200","1.22873","0.00078"
"14.90400","1.24225","0.00037"
"15.06600","1.25576","0.00077"
"15.22800","1.26921","0.00087"
"15.39000","1.28272","0.00118"
"15.55200","1.29624","0.00134"
"15.71400","1.30975","0.00081"
"15.87600","1.32314","0.00058"
"16.03800","1.33677","0.00066"
"16.20000","1.35029","0.00071"
"16.36200","1.36374","0.00098"
"16.52400","1.37719","0.00036"
"16.68600","1.39076","0.00103"
"16.84800","1.40422","0.00084"
"17.01000","1.41761","0.00129"
"17.17200","1.43124","0.00127"
"17.33400","1.44475","0.00058"
"17.49600","1.45821","0.00099"
"17.65800","1.47172","0.00080"
"17.82000","1.48523","0.00089"
"17.98200","1.49868","0.00088"
"18.14400","1.51214","0.00127"
"18.30600","1.52577","0.00080"
"18.46800","1.53922","0.00095"
"18.63000","1.55267","0.00104"
"18.79200","1.56619","0.00084"
"18.95400","1.57970","0.00115"
"19.11600","1.59321","0.00105"
"19.27800","1.60672","0.00080"
"19.44000","1.62024","0.00070"
"19.60200","1.63375","0.00079"
"19.76400","1.64720","-0.00023"
"19.92600","1.66077","0.00089"
"20.08800","1.67429","0.00084"
"20.25000","1.68768","0.00034"
"20.41200","1.70125","0.00014"
"20.57400","1.71476","0.00095"
"20.73600","1.72816","0.00072"
"20.89800","1.74173","0.00022"
"21.06000","1.75524","0.00064"
"21.22200","1.76875","0.00108"
"21.38400","1.78221","0.00055"
"21.54600","1.79572","0.00052"
"21.70800","1.80923","0.00034"
"21.87000","1.82268","0.00050"
"22.03200","1.83626","0.00054"
"22.19400","1.84971","0.00004"
"22.35600","1.86322","0.00069"
"22.51800","1.87673","0.00086"
"22.68000","1.89031","0.00081"
"22.84200","1.90370","0.00067"
"23.00400","1.91727","0.00045"
"23.16600","1.93072","0.00081"
"23.32800","1.94418","0.00090"
"23.49000","1.95763","0.00102"
"23.65200","1.97132","0.00087"
"23.81400","1.98477","0.00061"
"23.97600","1.99823","0.00061"
"24.13800","2.01174","0.00088"
"24.30000","2.02525","0.00092"
"24.46200","2.03870","0.00067"
"24.62400","2.05222","0.00118"
"24.78600","2.06573","0.00074"
"24.94800","2.07924","0.00093"
"25.11000","2.09269","0.00027"
"25.27200","2.10627","0.00076"
"25.43400","2.11972","0.00066"
"25.59600","2.13317","0.00101"
"25.75800","2.14674","0.00111"
"25.92000","2.16026","0.00038"
"26.08200","2.17371","0.00093"
"26.24400","2.18728","0.00104"
"26.40600","2.20073","0.00100"
"26.56800","2.21425","0.00125"
"26.73000","2.22770","0.00100"
"26.89200","2.24127","0.00094"
"27.05400","2.25472","0.00098"
"27.21600","2.26818","0.00099"
"27.37800","2.28169","0.00080"
"27.54000","2.29526","0.00085"
"27.70200","2.30871","0.00083"
"27.86400","2.32223","0.00109"
"28.02600","2.33568","0.00051"
"28.18800","2.34919","0.00080"
"28.35000","2.36264","0.00119"
"28.51200","2.37628","0.00165"
"28.67400","2.38979","0.00079"
"28.83600","2.40318","0.00153"
"28.99800","2.41675","0.00106"
"29.16000","2.43021","0.00129"
"29.32200","2.44372","0.00118"
"29.48400","2.45723","0.00101"
"29.64600","2.47068","0.00108"
"29.80800","2.48420","0.00171"
"29.97000","2.49771","0.00113"
"30.13200","2.51128","0.00149"
"30.29400","2.52473","0.00147"
"30.45600","2.53819","0.00201"
"30.61800","2.55176","0.00073"
"30.78000","2.56527","0.00140"
"30.94200","2.57872","0.00102"
"31.10400","2.59224","0.00119"
"31.26600","2.60575","0.00142"
"31.42800","2.61926","0.00124"
"31.59000","2.63271","0.00109"
"31.75200","2.64622","0.00131"
"31.91400","2.65968","0.00150"
"32.07600","2.67319","0.00151"
"32.23800","2.68676","0.00164"
"32.40000","2.70027","0.00210"
"32.56200","2.71373","0.00147"
"32.72400","2.72724","0.00155"
"32.88600","2.74075","0.00148"
"33.04800","2.75420","0.00180"
"33.21000","2.76772","0.00165"
"33.37200","2.78123","0.00166"
"33.53400","2.79474","0.00126"
"33.69600","2.80819","0.00211"
"33.85800","2.82177","0.00143"
"34.02000","2.83522","0.00159"
"34.18200","2.84867","0.00129"
"34.34400","2.86224","0.00181"
"34.50600","2.87576","0.00176"
"34.66800","2.88921","0.00215"
"34.83000","2.90272","0.00190"
"34.99200","2.91629","0.00167"
"35.15400","2.92981","0.00229"
"35.31600","2.94320","0.00197"
"35.47800","2.95677","0.00170"
"35.64000","2.97028","0.00210"
"35.80200","2.98368","0.00196"
"35.96400","2.99719","0.00212"
"36.12600","3.01070","0.00217"
"36.28800","3.02421","0.00221"
"36.45000","3.03773","0.00193"
"36.61200","3.05124","0.00160"
"36.77400","3.06475","0.00200"
"36.93600","3.07814","0.00268"
"37.09800","3.09178","0.00182"
"37.26000","3.10523","0.00234"
"37.42200","3.11874","0.00230"
"37.58400","3.13225","0.00296"
"37.74600","3.14577","0.00221"
"37.90800","3.15922","0.00191"
"38.07000","3.17273","0.00213"
"38.23200","3.18618","0.00231"
"38.39400","3.19976","0.00282"
"38.55600","3.21315","0.00262"
"38.71800","3.22678","0.00187"
"38.88000","3.24029","0.00220"
"39.04200","3.25375","0.00297"
"39.20400","3.26726","0.00284"
"39.36600","3.28071","0.00254"
"39.52800","3.29422","0.00272"
"39.69000","3.30774","0.00193"
"39.85200","3.32125","0.00249"
"40.01400","3.33476","0.00293"
"40.17600","3.34821","0.00281"
"40.33800","3.36179","0.00280"
"40.50000","3.37524","0.00298"
"40.66200","3.38869","0.00279"
"40.82400","3.40220","0.00291"
"40.98600","3.41572","0.00229"
"41.14800","3.42923","0.00273"
"41.31000","3.44274","0.00271"
"41.47200","3.45625","0.00327"
"41.63400","3.46965","0.00320"
"41.79600","3.48322","0.00374"
"41.95800","3.49673","0.00309"
"42.12000","3.51024","0.00353"
"42.28200","3.52370","0.00258"
"42.44400","3.53727","0.00265"
"42.60600","3.55078","0.00301"
"42.76800","3.56423","0.00253"
"42.93000","3.57775","0.00335"
"43.09200","3.59120","0.00311"
"43.25400","3.60471","0.00336"
"43.41600","3.61816","0.00342"
"43.57800","3.63174","0.00372"
"43.74000","3.64525","0.00433"
"43.90200","3.65870","0.00343"
"44.06400","3.67227","0.00366"
"44.22600","3.68573","0.00375"
"44.38800","3.69918","0.00375"
"44.55000","3.71269","0.00376"
"44.71200","3.72626","0.00377"
"44.87400","3.73972","0.00374"
"45.03600","3.75323","0.00435"
"45.19800","3.76680","0.00402"
"45.36000","3.78025","0.00389"
"45.52200","3.79371","0.00380"
"45.68400","3.80722","0.00366"
"45.84600","3.82079","0.00420"
"46.00800","3.83418","0.00426"
"46.17000","3.84770","0.00425"
"46.33200","3.86127","0.00432"
"46.49400","3.87472","0.00401"
"46.65600","3.88817","0.00421"
"46.81800","3.90169","0.00438"
"46.98000","3.91520","0.00460"
"47.14200","3.92865","0.00539"
"47.30400","3.94222","0.00449"
"47.46600","3.95574","0.00490"
"47.62800","3.96925","0.00484"
"47.79000","3.98270","0.00452"
"47.95200","3.99627","0.00447"
"48.11400","4.00973","0.00458"
"48.27600","4.02318","0.00496"
"48.43800","4.03669","0.00475"
"48.60000","4.05020","0.00495"
"48.76200","4.06366","0.00526"
"48.92400","4.07729","0.00436"
"49.08600","4.09074","0.00480"
"49.24800","4.10419","0.00492"
"49.41000","4.11770","0.00503"
"49.57200","4.13128","0.00454"
"49.73400","4.14467","0.00495"
"49.89600","4.15818","0.00521"
"50.05800","4.17175","0.00496"
"50.22000","4.18527","0.00505"
"50.38200","4.19872","0.00475"
"50.54400","4.21229","0.00483"
"50.70600","4.22574","0.00546"
"50.86800","4.23920","0.00507"
"51.03000","4.25277","0.00499"
"51.19200","4.26622","0.00494"
"51.35400","4.27973","0.00538"
"51.51600","4.29325","0.00503"
"51.67800","4.30676","0.00469"
"51.84000","4.32021","0.00514"
"52.00200","4.33366","0.00499"
"52.16400","4.34724","0.00546"
"52.32600","4.36075","0.00475"
"52.48800","4.37420","0.00537"
"52.65000","4.38777","0.00468"
"52.81200","4.40129","0.00494"
"52.97400","4.41468","0.00531"
"53.13600","4.42819","0.00434"
"53.29800","4.44170","0.00488"
"53.46000","4.45522","0.00488"
"53.62200","4.46867","0.00483"
"53.78400","4.48224","0.00512"
"53.94600","4.49575","0.00436"
"54.10800","4.50921","0.00462"
"54.27000","4.52272","0.00490"
"54.43200","4.53623","0.00475"
"54.59400","4.54968","0.00460"
"54.75600","4.56320","0.00416"
"54.91800","4.57671","0.00510"
"55.08000","4.59022","0.00468"
"55.24200","4.60367","0.00523"
"55.40400","4.61725","0.00447"
"55.56600","4.63076","0.00438"
"55.72800","4.64421","0.00474"
"55.89000","4.65772","0.00468"
"56.05200","4.67124","0.00453"
"56.21400","4.68475","0.00432"
"56.37600","4.69826","0.00456"
"56.53800","4.71177","0.00474"
"56.70000","4.72523","0.00403"
"56.86200","4.73868","0.00417"
"57.02400","4.75219","0.00437"
"57.18600","4.76570","0.00365"
"57.34800","4.77916","0.00397"
"57.51000","4.79273","0.00394"
"57.67200","4.80624","0.00440"
"57.83400","4.81969","0.00402"
"57.99600","4.83327","0.00424"
"58.15800","4.84672","0.00387"
"58.32000","4.86017","0.00411"
"58.48200","4.87368","0.00418"
"58.64400","4.88726","0.00380"
"58.80600","4.90077","0.00392"
"58.96800","4.91416","0.00369"
"59.13000","4.92779","0.00360"
"59.29200","4.94125","0.00395"
"59.45400","4.95470","0.00365"
"59.61600","4.96821","0.00470"
"59.77800","4.98172","0.00397"
"59.94000","4.99518","0.00403"
"60.10200","5.00875","0.00423"
"60.26400","5.02232","0.00416"
"60.42600","5.03577","0.00410"
"60.58800","5.04917","0.00375"
"60.75000","5.06274","0.00317"
"60.91200","5.07625","0.00367"
"61.07400","5.08970","0.00409"
"61.23600","5.10322","0.00354"
"61.39800","5.11679","0.00339"
"61.56000","5.13024","0.00362"
"61.72200","5.14369","0.00332"
"61.88400","5.15721","0.00380"
"62.04600","5.17072","0.00427"
"62.20800","5.18417","0.00381"
"62.37000","5.19774","0.00318"
"62.53200","5.21132","0.00357"
"62.69400","5.22471","0.00347"
"62.85600","5.23822","0.00307"
"63.01800","5.25173","0.00351"
"63.18000","5.26525","0.00363"
"63.34200","5.27870","0.00357"
"63.50400","5.29221","0.00331"
"63.66600","5.30572","0.00294"
"63.82800","5.31918","0.00384"
"63.99000","5.33281","0.00306"
"64.15200","5.34626","0.00347"
"64.31400","5.35971","0.00312"
"64.47600","5.37323","0.00346"
"64.63800","5.38668","0.00298"
"64.80000","5.40019","0.00308"
"64.96200","5.41364","0.00343"
"65.12400","5.42728","0.00295"
"65.28600","5.44079","0.00302"
"65.44800","5.45418","0.00325"
"65.61000","5.46769","0.00348"
"65.77200","5.48121","0.00302"
"65.93400","5.49466","0.00321"
"66.09600","5.50823","0.00350"
"66.25800","5.52174","0.00341"
"66.42000","5.53520","0.00355"
"66.58200","5.54871","0.00336"
"66.74400","5.56222","0.00342"
"66.90600","5.57573","0.00314"
"67.06800","5.58919","0.00330"
"67.23000","5.60270","0.00323"
"67.39200","5.61621","0.00359"
"67.55400","5.62966","0.00356"
"67.71600","5.64324","0.00312"
"67.87800","5.65675","0.00315"
"68.04000","5.67020","0.00293"
"68.20200","5.68371","0.00352"
"68.36400","5.69723","0.00329"
"68.52600","5.71074","0.00359"
"68.68800","5.72413","0.00316"
"68.85000","5.73776","0.00332"
"69.01200","5.75128","0.00311"
"69.17400","5.76473","0.00350"
"69.33600","5.77824","0.00335"
"69.49800","5.79175","0.00370"
"69.66000","5.80520","0.00306"
"69.82200","5.81866","0.00276"
"69.98400","5.83223","0.00364"
"70.14600","5.84574","0.00350"
"70.30800","5.85920","0.00334"
"70.47000","5.87277","0.00327"
"70.63200","5.88622","0.00330"
"70.79400","5.89973","0.00332"
"70.95600","5.91324","0.00288"
"71.11800","5.92676","0.00348"
"71.28000","5.94021","0.00325"
"71.44200","5.95372","0.00348"
"71.60400","5.96723","0.00315"
"71.76600","5.98075","0.00302"
"71.92800","5.99420","0.00322"
"72.09000","6.00771","0.00294"
"72.25200","6.02122","0.00284"
"72.41400","6.03468","0.00294"
"72.57600","6.04825","0.00315"
"72.73800","6.06176","0.00284"
"72.90000","6.07521","0.00231"
"73.06200","6.08873","0.00300"
"73.22400","6.10224","0.00325"
"73.38600","6.11569","0.00295"
"73.54800","6.12914","0.00328"
"73.71000","6.14278","0.00413"
"73.87200","6.15623","0.00282"
"74.03400","6.16968","0.00301"
"74.19600","6.18325","0.00291"
"74.35800","6.19671","0.00283"
"74.52000","6.21022","0.00295"
"74.68200","6.22367","0.00305"
"74.84400","6.23718","0.00363"
"75.00600","6.25070","0.00258"
"75.16800","6.26421","0.00272"
"75.33000","6.27778","0.00330"
"75.49200","6.29123","0.00326"
"75.65400","6.30469","0.00280"
"75.81600","6.31826","0.00288"
"75.97800","6.33177","0.00317"
"76.14000","6.34522","0.00293"
"76.30200","6.35874","0.00262"
"76.46400","6.37225","0.00216"
"76.62600","6.38576","0.00294"
"76.78800","6.39921","0.00329"
"76.95000","6.41273","0.00278"
"77.11200","6.42624","0.00277"
"77.27400","6.43963","0.00305"
"77.43600","6.45326","0.00268"
"77.59800","6.46678","0.00296"
"77.76000","6.48023","0.00206"
"77.92200","6.49374","0.00305"
"78.08400","6.50725","0.00314"
"78.24600","6.52071","0.00320"
"78.40800","6.53416","0.00310"
"78.57000","6.54773","0.00285"
"78.73200","6.56118","0.00242"
"78.89400","6.57470","0.00283"
"79.05600","6.58827","0.00323"
"79.21800","6.60172","0.00341"
"79.38000","6.61517","0.00329"
"79.54200","6.62875","0.00247"
"79.70400","6.64226","0.00309"
"79.86600","6.65571","0.00340"
"80.02800","6.66916","0.00324"
"80.19000","6.68280","0.00332"
"80.35200","6.69625","0.00264"
"80.51400","6.70970","0.00273"
"80.67600","6.72321","0.00303"
"80.83800","6.73673","0.00353"
"81.00000","6.75018","0.00293"
"81.16200","6.76369","0.00333"
"81.32400","6.77726","0.00335"
"81.48600","6.79072","0.00365"
"81.64800","6.80423","0.00324"
"81.81000","6.81774","0.00249"
"81.97200","6.83125","0.00239"
"82.13400","6.84471","0.00179"
"82.29600","6.85822","0.00228"
"82.45800","6.87167","0.00250"
"82.62000","6.88524","0.00261"
"82.78200","6.89876","0.00237"
"82.94400","6.91233","0.00295"
"83.10600","6.92572","0.00224"
"83.26800","6.93923","0.00285"
"83.43000","6.95275","0.00304"
"83.59200","6.96626","0.00263"
"83.75400","6.97965","0.00246"
"83.91600","6.99322","0.00254"
"84.07800","7.00674","0.00289"
"84.24000","7.02025","0.00220"
"84.40200","7.03370","0.00224"
"84.56400","7.04721","0.00218"
"84.72600","7.06067","0.00273"
"84.88800","7.07418","0.00269"
"85.05000","7.08769","0.00271"
"85.21200","7.10126","0.00279"
"85.37400","7.11472","0.00242"
"85.53600","7.12829","0.00309"
"85.69800","7.14174","0.00227"
"85.86000","7.15519","0.00278"
"86.02200","7.16876","0.00276"
"86.18400","7.18222","0.00248"
"86.34600","7.19573","0.00235"
"86.50800","7.20924","0.00248"
"86.67000","7.22281","0.00237"
"86.83200","7.23621","0.00219"
"86.99400","7.24966","0.00313"
"87.15600","7.26329","0.00254"
"87.31800","7.27674","0.00280"
"87.48000","7.29020","0.00282"
"87.64200","7.30371","0.00270"
"87.80400","7.31728","0.00242"
"87.96600","7.33074","0.00303"
"88.12800","7.34425","0.00254"
"88.29000","7.35770","0.00263"
"88.45200","7.37121","0.00276"
"88.61400","7.38467","0.00324"
"88.77600","7.39824","0.00267"
"88.93800","7.41175","0.00283"
"89.10000","7.42520","0.00241"
"89.26200","7.43871","0.00299"
"89.42400","7.45229","0.00273"
"89.58600","7.46568","0.00313"
"89.74800","7.47925","0.00314"
"89.91000","7.49270","0.00283"
"90.07200","7.50622","0.00294"
"90.23400","7.51967","0.00288"
"90.39600","7.53330","0.00255"
"90.55800","7.54675","0.00291"
"90.72000","7.56021","0.00324"
"90.88200","7.57378","0.00317"
"91.04400","7.58723","0.00329"
"91.20600","7.60068","0.00327"
"91.36800","7.61420","0.00311"
"91.53000","7.62771","0.00332"
"91.69200","7.64122","0.00286"
"91.85400","7.65474","0.00338"
"92.01600","7.66825","0.00297"
"92.17800","7.68170","0.00339"
"92.34000","7.69515","0.00320"
"92.50200","7.70866","0.00335"
"92.66400","7.72224","0.00308"
"92.82600","7.73569","0.00300"
"92.98800","7.74926","0.00293"
"93.15000","7.76271","0.00312"
"93.31200","7.77623","0.00417"
"93.47400","7.78968","0.00354"
"93.63600","7.80325","0.00303"
"93.79800","7.81676","0.00329"
"93.96000","7.83022","0.00337"
"94.12200","7.84379","0.00344"
"94.28400","7.85724","0.00264"
"94.44600","7.87069","0.00367"
"94.60800","7.88421","0.00414"
"94.77000","7.89772","0.00372"
"94.93200","7.91123","0.00320"
"95.09400","7.92468","0.00276"
"95.25600","7.93826","0.00347"
"95.41800","7.95177","0.00373"
"95.58000","7.96516","0.00390"
"95.74200","7.97879","0.00379"
"95.90400","7.99225","0.00355"
"96.06600","8.00570","0.00352"
"96.22800","8.01921","0.00367"
"96.39000","8.03278","0.00369"
"96.55200","8.04618","0.00428"
"96.71400","8.05969","0.00351"
"96.87600","8.07326","0.00314"
"97.03800","8.08671","0.00400"
"97.20000","8.10017","0.00364"
"97.36200","8.11374","0.00378"
"97.52400","8.12725","0.00405"
"97.68600","8.14070","0.00410"
"97.84800","8.15422","0.00430"
"98.01000","8.16779","0.00381"
"98.17200","8.18118","0.00380"
"98.33400","8.19469","0.00378"
"98.49600","8.20821","0.00332"
"98.65800","8.22172","0.00336"
"98.82000","8.23517","0.00402"
"98.98200","8.24874","0.00355"
"99.14400","8.26226","0.00407"
"99.30600","8.27571","0.00395"
"99.46800","8.28922","0.00407"
"99.63000","8.30273","0.00416"
"99.79200","8.31619","0.00349"
"99.95400","8.32970","0.00348"
"100.11600","8.34321","0.00404"
"100.27800","8.35672","0.00413"
"100.44000","8.37024","0.00430"
"100.60200","8.38381","0.00418"
"100.76400","8.39720","0.00417"
"100.92600","8.41065","0.00437"
"101.08800","8.42422","0.00332"
"101.25000","8.43774","0.00314"
"101.41200","8.45119","0.00294"
"101.57400","8.46476","0.00341"
"101.73600","8.47828","0.00337"
"101.89800","8.49173","0.00325"
"102.06000","8.50518","0.00358"
"102.22200","8.51875","0.00349"
"102.38400","8.53227","0.00342"
"102.54600","8.54566","0.00329"
"102.70800","8.55923","0.00312"
"102.87000","8.57274","0.00361"
"103.03200","8.58619","0.00309"
"103.19400","8.59971","0.00281"
"103.35600","8.61322","0.00392"
"103.51800","8.62673","0.00401"
"103.68000","8.64013","0.00398"
"103.84200","8.65376","0.00336"
"104.00400","8.66727","0.00317"
"104.16600","8.68066","0.00320"
"104.32800","8.69423","0.00367"
"104.49000","8.70775","0.00390"
"104.65200","8.72120","0.00401"
"104.81400","8.73471","0.00362"
"104.97600","8.74823","0.00369"
"105.13800","8.76168","0.00408"
"105.30000","8.77519","0.00392"
"105.46200","8.78876","0.00408"
"105.62400","8.80227","0.00395"
"105.78600","8.81573","0.00367"
"105.94800","8.82924","0.00369"
"106.11000","8.84275","0.00378"
"106.27200","8.85620","0.00394"
"106.43400","8.86972","0.00424"
"106.59600","8.88323","0.00418"
"106.75800","8.89674","0.00394"
"106.92000","8.91020","0.00393"
"107.08200","8.92371","0.00332"
"107.24400","8.93722","0.00384"
"107.40600","8.95067","0.00427"
"107.56800","8.96424","0.00417"
"107.73000","8.97770","0.00367"
"107.89200","8.99121","0.00418"
"108.05400","9.00472","0.00388"
"108.21600","9.01817","0.00417"
"108.37800","9.03169","0.00413"
"108.54000","9.04520","0.00403"
"108.70200","9.05871","0.00391"
"108.86400","9.07222","0.00442"
"109.02600","9.08568","0.00430"
"109.18800","9.09925","0.00420"
"109.35000","9.11276","0.00412"
"109.51200","9.12615","0.00479"
"109.67400","9.13973","0.00409"
"109.83600","9.15324","0.00417"
"109.99800","9.16669","0.00370"
"110.16000","9.18021","0.00428"
"110.32200","9.19372","0.00425"
"110.48400","9.20723","0.00434"
"110.64600","9.22068","0.00411"
"110.80800","9.23425","0.00425"
"110.97000","9.24771","0.00492"
"111.13200","9.26116","0.00460"
"111.29400","9.27473","0.00432"
"111.45600","9.28824","0.00452"
"111.61800","9.30170","0.00472"
"111.78000","9.31521","0.00439"
"111.94200","9.32872","0.00423"
"112.10400","9.34223","0.00496"
"112.26600","9.35569","0.00499"
"112.42800","9.36926","0.00484"
"112.59000","9.38277","0.00544"
"112.75200","9.39616","0.00452"
"112.91400","9.40974","0.00453"
"113.07600","9.42325","0.00488"
"113.23800","9.43676","0.00508"
"113.40000","9.45021","0.00520"
"113.56200","9.46373","0.00500"
"113.72400","9.47718","0.00436"
"113.88600","9.49063","0.00371"
"114.04800","9.50426","0.00393"
"114.21000","9.51778","0.00428"
"114.37200","9.53117","0.00397"
"114.53400","9.54474","0.00391"
"114.69600","9.55825","0.00426"
"114.85800","9.57171","0.00437"
"115.02000","9.58516","0.00411"
"115.18200","9.59873","0.00395"
"115.34400","9.61224","0.00395"
"115.50600","9.62570","0.00432"
"115.66800","9.63927","0.00422"
"115.83000","9.65278","0.00377"
"115.99200","9.66617","0.00456"
"116.15400","9.67975","0.00443"
"116.31600","9.69326","0.00412"
"116.47800","9.70671","0.00380"
"116.64000","9.72022","0.00455"
"116.80200","9.73380","0.00447"
"116.96400","9.74725","0.00482"
"117.12600","9.76070","0.00433"
"117.28800","9.77427","0.00452"
"117.45000","9.78773","0.00477"
"117.61200","9.80118","0.00448"
"117.77400","9.81475","0.00496"
"117.93600","9.82826","0.00409"
"118.09800","9.84166","0.00472"
"118.26000","9.85517","0.00512"
"118.42200","9.86874","0.00531"
"118.58400","9.88213","0.00480"
"118.74600","9.89565","0.00456"
"118.90800","9.90922","0.00465"
"119.07000","9.92273","0.00438"
"119.23200","9.93618","0.00473"
"119.39400","9.94976","0.00534"
"119.55600","9.96327","0.00482"
"119.71800","9.97672","0.00531"
"119.88000","9.99023","0.00492"
"120.04200","10.00375","0.00488"
"120.20400","10.01720","0.00486"
"120.36600","10.03071","0.00508"
"120.52800","10.04428","0.00412"
"120.69000","10.05774","0.00452"
"120.85200","10.07119","0.00440"
"121.01400","10.08476","0.00381"
"121.17600","10.09821","0.00449"
"121.33800","10.11172","0.00456"
"121.50000","10.12524","0.00384"
"121.66200","10.13881","0.00428"
"121.82400","10.15226","0.00411"
"121.98600","10.16572","0.00407"
"122.14800","10.17923","0.00486"
"122.31000","10.19268","0.00518"
"122.47200","10.20619","0.00455"
"122.63400","10.21971","0.00464"
"122.79600","10.23328","0.00436"
"122.95800","10.24673","0.00480"
"123.12000","10.26024","0.00453"
"123.28200","10.27376","0.00476"
"123.44400","10.28721","0.00509"
"123.60600","10.30072","0.00460"
"123.76800","10.31423","0.00494"
"123.93000","10.32774","0.00474"
"124.09200","10.34120","0.00488"
"124.25400","10.35477","0.00498"
"124.41600","10.36828","0.00472"
"124.57800","10.38168","0.00448"
"124.74000","10.39525","0.00528"
"124.90200","10.40876","0.00501"
"125.06400","10.42221","0.00486"
"125.22600","10.43567","0.00615"
"125.38800","10.44924","0.00586"
"125.55000","10.46275","0.00539"
"125.71200","10.47620","0.00585"
"125.87400","10.48972","0.00569"
"126.03600","10.50323","0.00618"
"126.19800","10.51668","0.00588"
"126.36000","10.53019","0.00641"
"126.52200","10.54370","0.00637"
"126.68400","10.55722","0.00661"
"126.84600","10.57073","0.00670"
"127.00800","10.58424","0.00547"
"127.17000","10.59769","0.00682"
"127.33200","10.61121","0.00653"
"127.49400","10.62472","0.00678"
"127.65600","10.63823","0.00650"
"127.81800","10.65169","0.00721"
"127.98000","10.66526","0.00755"
"128.14200","10.67877","0.00768"
"128.30400","10.69222","0.00782"
"128.46600","10.70568","0.00747"
"128.62800","10.71925","0.00779"
"128.79000","10.73270","0.00802"
"128.95200","10.74615","0.00866"
"129.11400","10.75978","0.00830"
"129.27600","10.77330","0.00841"
"129.43800","10.78669","0.00876"
"129.60000","10.80026","0.00926"
"129.76200","10.81377","0.00862"
"129.92400","10.82717","0.00881"
"130.08600","10.84068","0.00963"
"130.24800","10.85425","0.01014"
"130.41000","10.86776","0.00934"
"130.57200","10.88122","0.00956"
"130.73400","10.89473","0.01028"
"130.89600","10.90824","0.00988"
"131.05800","10.92169","0.01059"
"131.22000","10.93527","0.01104"
"131.38200","10.94872","0.01038"
"131.54400","10.96217","0.01168"
"131.70600","10.97568","0.01126"
"131.86800","10.98926","0.01138"
"132.03000","11.00277","0.01140"
"132.19200","11.01622","0.01217"
"132.35400","11.02973","0.01223"
"132.51600","11.04325","0.01272"
"132.67800","11.05670","0.01329"
"132.84000","11.07021","0.01340"
"133.00200","11.08378","0.01324"
"133.16400","11.09724","0.01346"
"133.32600","11.11075","0.01448"
"133.48800","11.12426","0.01418"
"133.65000","11.13771","0.01554"
"133.81200","11.15117","0.01541"
"133.97400","11.16474","0.01598"
"134.13600","11.17825","0.01582"
"134.29800","11.19170","0.01567"
"134.46000","11.20528","0.01647"
"134.62200","11.21873","0.01726"
"134.78400","11.23224","0.01792"
"134.94600","11.24575","0.01742"
"135.10800","11.25921","0.01802"
"135.27000","11.27272","0.01906"
"135.43200","11.28617","0.01875"
"135.59400","11.29980","0.01822"
"135.75600","11.31326","0.01833"
"135.91800","11.32671","0.01933"
"136.08000","11.34022","0.01992"
"136.24200","11.35373","0.02026"
"136.40400","11.36718","0.02035"
"136.56600","11.38070","0.02103"
"136.72800","11.39427","0.02150"
"136.89000","11.40778","0.02159"
"137.05200","11.42124","0.02241"
"137.21400","11.43475","0.02274"
"137.37600","11.44820","0.02301"
"137.53800","11.46165","0.02347"
"137.70000","11.47523","0.02401"
"137.86200","11.48874","0.02481"
"138.02400","11.50219","0.02396"
"138.18600","11.51576","0.02420"
"138.34800","11.52928","0.02494"
"138.51000","11.54273","0.02564"
"138.67200","11.55618","0.02645"
"138.83400","11.56975","0.02644"
"138.99600","11.58321","0.02688"
"139.15800","11.59666","0.02796"
"139.32000","11.61023","0.02861"
"139.48200","11.62380","0.02823"
"139.64400","11.63720","0.02894"
"139.80600","11.65071","0.02971"
"139.96800","11.66422","0.03033"
"140.13000","11.67767","0.03051"
"140.29200","11.69119","0.03146"
"140.45400","11.70476","0.03115"
"140.61600","11.71827","0.03142"
"140.77800","11.73172","0.03276"
"140.94000","11.74523","0.03305"
"141.10200","11.75875","0.03365"
"141.26400","11.77220","0.03451"
"141.42600","11.78571","0.03492"
"141.58800","11.79922","0.03549"
"141.75000","11.81274","0.03616"
"141.91200","11.82625","0.03602"
"142.07400","11.83976","0.03628"
"142.23600","11.85321","0.03709"
"142.39800","11.86667","0.03770"
"142.56000","11.88024","0.03780"
"142.72200","11.89375","0.03845"
"142.88400","11.90721","0.03866"
"143.04600","11.92072","0.03891"
"143.20800","11.93429","0.03970"
"143.37000","11.94774","0.04001"
"143.53200","11.96119","0.04040"
"143.69400","11.97471","0.04072"
"143.85600","11.98816","0.04115"
"144.01800","12.00167","0.04122"
"144.18000","12.01524","0.04208"
"144.34200","12.02870","0.04279"
"144.50400","12.04221","0.04291"
"144.66600","12.05572","0.04320"
"144.82800","12.06923","0.04328"
"144.99000","12.08269","0.04406"
"145.15200","12.09620","0.04420"
"145.31400","12.10971","0.04470"
"145.47600","12.12329","0.04499"
"145.63800","12.13674","0.04488"
"145.80000","12.15031","0.04518"
"145.96200","12.16376","0.04537"
"146.12400","12.17715","0.04576"
"146.28600","12.19073","0.04573"
"146.44800","12.20424","0.04601"
"146.61000","12.21769","0.04638"
"146.77200","12.23120","0.04648"
"146.93400","12.24478","0.04683"
"147.09600","12.25829","0.04683"
"147.25800","12.27162","0.04685"
"147.42000","12.28525","0.04530"
"147.58200","12.29871","0.04574"
"147.74400","12.31222","0.04617"
"147.90600","12.32567","0.04637"
"148.06800","12.33924","0.04672"
"148.23000","12.35270","0.04683"
"148.39200","12.36621","0.04732"
"148.55400","12.37972","0.04761"
"148.71600","12.39318","0.04772"
"148.87800","12.40663","0.04821"
"149.04000","12.42020","0.04869"
"149.20200","12.43377","0.04880"
"149.36400","12.44716","0.04924"
"149.52600","12.46080","0.04942"
"149.68800","12.47431","0.04964"
"149.85000","12.48770","0.05021"
"150.01200","12.50121","0.05013"
"150.17400","12.51467","0.05065"
"150.33600","12.52824","0.05128"
"150.49800","12.54169","0.05174"
"150.66000","12.55526","0.05129"
"150.82200","12.56872","0.05210"
"150.98400","12.58223","0.05234"
"151.14600","12.59574","0.05259"
"151.30800","12.60919","0.05341"
"151.47000","12.62271","0.05370"
"151.63200","12.63622","0.05490"
"151.79400","12.64979","0.05461"
"151.95600","12.66324","0.05561"
"152.11800","12.67670","0.05581"
"152.28000","12.69027","0.05669"
"152.44200","12.70372","0.05757"
"152.60400","12.71711","0.05790"
"152.76600","12.73075","0.05839"
"152.92800","12.74420","0.05932"
"153.09000","12.75771","0.05977"
"153.25200","12.77122","0.06023"
"153.41400","12.78474","0.06079"
"153.57600","12.79819","0.06188"
"153.73800","12.81170","0.06252"
"153.90000","12.82521","0.06311"
"154.06200","12.83873","0.06310"
"154.22400","12.85212","0.06349"
"154.38600","12.86581","0.06326"
"154.54800","12.87926","0.06370"
"154.71000","12.89272","0.06328"
"154.87200","12.90623","0.06469"
"155.03400","12.91974","0.06485"
"155.19600","12.93319","0.06586"
"155.35800","12.94671","0.01044"
"155.52000","12.96028","0.01125"
"155.68200","12.97373","0.01598"
"155.84400","12.98712","0.01423"
"156.00600","13.00076","0.01274"
"156.16800","13.01427","0.01415"
"156.33000","13.02772","0.01611"
"156.49200","13.04117","0.01575"
"156.65400","13.05475","0.01409"
"156.81600","13.06820","0.01596"
"156.97800","13.08171","0.01560"
"157.14000","13.09522","0.01704"
"157.30200","13.10874","0.01809"
"157.46400","13.12213","0.01727"
"157.62600","13.13576","0.01758"
"157.78800","13.14921","0.01973"
"157.95000","13.16273","0.01912"
"158.11200","13.17624","0.01882"
"158.27400","13.18981","0.02089"
"158.43600","13.20326","0.02110"
"158.59800","13.21666","0.02268"
"158.76000","13.23023","0.02216"
"158.92200","13.24368","0.02203"
"159.08400","13.25713","0.02318"
"159.24600","13.27076","0.02409"
"159.40800","13.28422","0.02289"
"159.57000","13.29767","0.02351"
"159.73200","13.31124","0.01896"
"159.89400","13.32476","0.01320"
"160.05600","13.33821","0.01326"
"160.21800","13.35172","0.01495"
"160.38000","13.36523","0.01416"
"160.54200","13.37875","0.01508"
"160.70400","13.39226","0.01599"
"160.86600","13.40577","0.01483"
"161.02800","13.41922","0.01596"
"161.19000","13.43268","0.01681"
"161.35200","13.44619","0.01400"
"161.51400","13.45976","0.01524"
"161.67600","13.47315","0.01591"
"161.83800","13.48672","0.01573"
"162.00000","13.50030","0.01464"
"162.16200","13.51375","0.01447"
"162.32400","13.52720","0.01282"
"162.48600","13.54077","0.01495"
"162.64800","13.55423","0.01518"
"162.81000","13.56768","0.01409"
"162.97200","13.58125","0.01523"
"163.13400","13.59477","0.01549"
"163.29600","13.60816","0.01521"
"163.45800","13.62173","0.01638"
"163.62000","13.63518","0.01597"
"163.78200","13.64869","0.01592"
"163.94400","13.66215","0.01699"
"164.10600","13.67578","0.01627"
"164.26800","13.68923","0.01150"
"164.43000","13.70268","0.01251"
"164.59200","13.71626","0.01236"
"164.75400","13.72977","0.01159"
"164.91600","13.74322","0.01209"
"165.07800","13.75673","0.01105"
"165.24000","13.77019","0.01154"
"165.40200","13.78370","0.01276"
"165.56400","13.79721","0.01195"
"165.72600","13.81078","0.01222"
"165.88800","13.82430","0.01231"
"166.05000","13.83769","0.01302"
"166.21200","13.85126","0.01197"
"166.37400","13.86472","0.01205"
"166.53600","13.87823","0.01249"
"166.69800","13.89174","0.01144"
"166.86000","13.90525","0.01285"
"167.02200","13.91877","0.01232"
"167.18400","13.93216","0.01223"
"167.34600","13.94573","0.01229"
"167.50800","13.95930","0.01174"
"167.67000","13.97263","0.01088"
"167.83200","13.98627","0.01123"
"167.99400","13.99972","0.01210"
"168.15600","14.01323","0.01141"
"168.31800","14.02680","0.01143"
"168.48000","14.04020","0.01125"
"168.64200","14.05371","0.01230"
"168.80400","14.06722","0.01142"
"168.96600","14.08074","0.01181"
"169.12800","14.09425","0.01217"
"169.29000","14.10770","0.01239"
"169.45200","14.12127","0.01232"
"169.61400","14.13472","0.01180"
"169.77600","14.14818","0.01156"
"169.93800","14.16169","0.01237"
"170.10000","14.17520","0.01258"
"170.26200","14.18865","0.01284"
"170.42400","14.20217","0.01248"
"170.58600","14.21574","0.01243"
"170.74800","14.22925","0.01272"
"170.91000","14.24264","0.01347"
"171.07200","14.25628","0.01275"
"171.23400","14.26979","0.01303"
"171.39600","14.28318","0.01345"
"171.55800","14.29675","0.01331"
"171.72000","14.31027","0.01320"
"171.88200","14.32372","0.01345"
"172.04400","14.33723","0.01305"
"172.20600","14.35074","0.01390"
"172.36800","14.36426","0.01450"
"172.53000","14.37765","0.01457"
"172.69200","14.39128","0.01421"
"172.85400","14.40473","0.01506"
"173.01600","14.41819","0.01430"
"173.17800","14.43176","0.01474"
"173.34000","14.44527","0.01525"
"173.50200","14.45872","0.01547"
"173.66400","14.47224","0.01572"
"173.82600","14.48569","0.01517"
"173.98800","14.49920","0.01574"
"174.15000","14.51265","0.01635"
"174.31200","14.52623","0.01641"
"174.47400","14.53974","0.01653"
"174.63600","14.55319","0.01627"
"174.79800","14.56670","0.01657"
"174.96000","14.58028","0.01654"
"175.12200","14.59373","0.01689"
"175.28400","14.60718","0.01721"
"175.44600","14.62069","0.01691"
"175.60800","14.63427","0.01710"
"175.77000","14.64778","0.01745"
"175.93200","14.66123","0.01760"
"176.09400","14.67474","0.01775"
"176.25600","14.68820","0.01788"
"176.41800","14.70177","0.01787"
"176.58000","14.71522","0.01862"
"176.74200","14.72873","0.01897"
"176.90400","14.74219","0.01891"
"177.06600","14.75576","0.01944"
"177.22800","14.76927","0.01943"
"177.39000","14.78266","0.02054"
"177.55200","14.79630","0.02012"
"177.71400","14.80969","0.01978"
"177.87600","14.82314","0.02044"
"178.03800","14.83671","0.02079"
"178.20000","14.85023","0.02040"
"178.36200","14.86374","0.02048"
"178.52400","14.87719","0.02098"
"178.68600","14.89070","0.02147"
"178.84800","14.90416","0.02182"
"179.01000","14.91767","0.02214"
"179.17200","14.93118","0.02164"
"179.33400","14.94475","0.02322"
"179.49600","14.95820","0.02309"
"179.65800","14.97178","0.02326"
"179.82000","14.98523","0.02346"
"179.98200","14.99868","0.02416"
"180.14400","15.01220","0.02330"
"180.30600","15.02577","0.01988"
"180.46800","15.03922","0.02091"
"180.63000","15.05267","0.02220"
"180.79200","15.06625","0.02138"
"180.95400","15.07982","0.02201"
"181.11600","15.09321","0.02305"
"181.27800","15.10672","0.02354"
"181.44000","15.12024","0.02424"
"181.60200","15.13369","0.02465"
"181.76400","15.14720","0.02495"
"181.92600","15.16077","0.02617"
"182.08800","15.17429","0.02560"
"182.25000","15.18774","0.02630"
"182.41200","15.20125","0.02657"
"182.57400","15.21476","0.02703"
"182.73600","15.22816","0.02700"
"182.89800","15.24167","0.02755"
"183.06000","15.25530","0.02602"
"183.22200","15.26869","0.02641"
"183.38400","15.28227","0.02688"
"183.54600","15.29578","0.02720"
"183.70800","15.30923","0.02719"
"183.87000","15.32274","0.02730"
"184.03200","15.33626","0.02822"
"184.19400","15.34977","0.02831"
"184.35600","15.36316","0.02864"
"184.51800","15.37673","0.02883"
"184.68000","15.39025","0.02880"
"184.84200","15.40370","0.02925"
"185.00400","15.41721","0.02921"
"185.16600","15.43072","0.02995"
"185.32800","15.44423","0.02957"
"185.49000","15.45763","0.02547"
"185.65200","15.47126","0.02680"
"185.81400","15.48477","0.02609"
"185.97600","15.49822","0.02701"
"186.13800","15.51174","0.02740"
"186.30000","15.52525","0.02695"
"186.46200","15.53870","0.02732"
"186.62400","15.55222","0.02772"
"186.78600","15.56573","0.02758"
"186.94800","15.57918","0.02647"
"187.11000","15.59275","0.02671"
"187.27200","15.60626","0.02756"
"187.43400","15.61972","0.02821"
"187.59600","15.63323","0.02827"
"187.75800","15.64674","0.02842"
"187.92000","15.66025","0.02893"
"188.08200","15.67371","0.02900"
"188.24400","15.68722","0.02993"
"188.40600","15.70073","0.03008"
"188.56800","15.71424","0.02997"
"188.73000","15.72770","0.02939"
"188.89200","15.74121","0.03022"
"189.05400","15.75472","0.03034"
"189.21600","15.76811","0.03054"
"189.37800","15.78174","0.03049"
"189.54000","15.79526","0.03126"
"189.70200","15.80871","0.03130"
"189.86400","15.82228","0.03092"
"190.02600","15.83574","0.03057"
"190.18800","15.84919","0.03046"
"190.35000","15.86270","0.02909"
"190.51200","15.87627","0.03032"
"190.67400","15.88973","0.03031"
"190.83600","15.90324","0.03118"
"190.99800","15.91681","0.03126"
"191.16000","15.93026","0.03093"
"191.32200","15.94366","0.03053"
"191.48400","15.95723","0.03282"
"191.64600","15.97080","0.03360"
"191.80800","15.98419","0.03449"
"191.97000","15.99771","0.03427"
"192.13200","16.01122","0.03485"
"192.29400","16.02473","0.03471"
"192.45600","16.03818","0.03565"
"192.61800","16.05176","0.03600"
"192.78000","16.06521","0.03645"
"192.94200","16.07866","0.03665"
"193.10400","16.09223","0.03021"
"193.26600","16.10575","0.02913"
"193.42800","16.11920","0.03159"
"193.59000","16.13271","0.03358"
"193.75200","16.14622","0.03295"
"193.91400","16.15973","0.03361"
"194.07600","16.17313","0.03495"
"194.23800","16.18676","0.03600"
"194.40000","16.20021","0.03529"
"194.56200","16.21372","0.03648"
"194.72400","16.22724","0.03756"
"194.88600","16.24075","0.03752"
"195.04800","16.25420","0.03780"
"195.21000","16.26772","0.03936"
"195.37200","16.28123","0.03952"
"195.53400","16.29468","0.03945"
"195.69600","16.30819","0.04009"
"195.85800","16.32177","0.04124"
"196.02000","16.33522","0.04113"
"196.18200","16.34873","0.04193"
"196.34400","16.36218","0.04246"
"196.50600","16.37569","0.04324"
"196.66800","16.38915","0.04328"
"196.83000","16.40272","0.04361"
"196.99200","16.41623","0.04466"
"197.15400","16.42974","0.04505"
"197.31600","16.44320","0.04501"
"197.47800","16.45677","0.04548"
"197.64000","16.47022","0.04629"
"197.80200","16.48362","0.04649"
"197.96400","16.49725","0.04711"
"198.12600","16.51076","0.04745"
"198.28800","16.52421","0.04821"
"198.45000","16.53778","0.04814"
"198.61200","16.55124","0.04867"
"198.77400","16.56475","0.04940"
"198.93600","16.57814","0.04981"
"199.09800","16.59177","0.05053"
"199.26000","16.60523","0.05127"
"199.42200","16.61868","0.05204"
"199.58400","16.63219","0.05228"
"199.74600","16.64571","0.05315"
"199.90800","16.65916","0.05394"
"200.07000","16.67267","0.05485"
"200.23200","16.68624","0.05543"
"200.39400","16.69969","0.05707"
"200.55600","16.71321","0.05799"
"200.71800","16.72678","0.05855"
"200.88000","16.74029","0.06011"
"201.04200","16.75368","0.06112"
"201.20400","16.76726","0.06223"
"201.36600","16.78077","0.06324"
"201.52800","16.79422","0.06436"
"201.69000","16.80767","0.06569"
"201.85200","16.82119","0.06696"
"202.01400","16.83470","0.06860"
"202.17600","16.84821","0.06998"
"202.33800","16.86178","0.07096"
"202.50000","16.87524","0.07267"
"202.66200","16.88863","0.07372"
"202.82400","16.90226","0.07554"
"202.98600","16.91571","0.07721"
"203.14800","16.92923","0.07845"
"203.31000","16.94274","0.07977"
"203.47200","16.95625","0.08106"
"203.63400","16.96971","0.08266"
"203.79600","16.98322","0.08467"
"203.95800","16.99679","0.08517"
"204.12000","17.01018","0.08637"
"204.28200","17.02363","0.08716"
"204.44400","17.03727","0.08821"
"204.60600","17.05078","0.09007"
"204.76800","17.06417","0.09065"
"204.93000","17.07768","0.09194"
"205.09200","17.09126","0.09233"
"205.25400","17.10471","0.09334"
"205.41600","17.11822","0.09426"
"205.57800","17.13173","0.09506"
"205.74000","17.14525","0.09610"
"205.90200","17.15870","0.09732"
"206.06400","17.17233","0.09842"
"206.22600","17.18578","0.09880"
"206.38800","17.19912","0.10022"
"206.55000","17.21275","0.10199"
"206.71200","17.22626","0.10321"
"206.87400","17.23965","0.10505"
"207.03600","17.25323","0.10612"
"207.19800","17.26674","0.10858"
"207.36000","17.28025","0.10991"
"207.52200","17.29364","0.11199"
"207.68400","17.30728","0.11370"
"207.84600","17.32073","0.11516"
"208.00800","17.33418","0.11723"
"208.17000","17.34769","0.11941"
"208.33200","17.36121","0.12097"
"208.49400","17.37472","0.12120"
"208.65600","17.38823","0.12398"
"208.81800","17.40174","0.12583"
"208.98000","17.41525","0.12700"
"209.14200","17.42865","0.12271"
"209.30400","17.44228","0.12486"
"209.46600","17.45573","0.12575"
"209.62800","17.46919","0.12776"
"209.79000","17.48276","0.12930"
"209.95200","17.49627","0.13025"
"210.11400","17.50972","0.13142"
"210.27600","17.52317","0.13210"
"210.43800","17.53669","0.13302"
"210.60000","17.55020","0.13429"
"210.76200","17.56365","0.13475"
"210.92400","17.57729","0.13519"
"211.08600","17.59074","0.13585"
"211.24800","17.60419","0.13662"
"211.41000","17.61776","0.13714"
"211.57200","17.63122","0.13791"
"211.73400","17.64473","0.13833"
"211.89600","17.65818","0.13880"
"212.05800","17.67175","0.13930"
"212.22000","17.68527","0.13992"
"212.38200","17.69872","0.14021"
"212.54400","17.71223","0.14069"
"212.70600","17.72568","0.14090"
"212.86800","17.73919","0.14141"
"213.03000","17.75271","0.14220"
"213.19200","17.76622","0.14303"
"213.35400","17.77973","0.14360"
"213.51600","17.79325","0.14428"
"213.67800","17.80676","0.14516"
"213.84000","17.82021","0.14655"
"214.00200","17.83372","0.14751"
"214.16400","17.84724","0.14852"
"214.32600","17.86069","0.14988"
"214.48800","17.87414","0.15163"
"214.65000","17.88777","0.15262"
"214.81200","17.90122","0.15506"
"214.97400","17.91468","0.15665"
"215.13600","17.92819","0.15841"
"215.29800","17.94170","0.16035"
"215.46000","17.95522","0.16232"
"215.62200","17.96867","0.16432"
"215.78400","17.98230","0.16736"
"215.94600","17.99575","0.16921"
"216.10800","18.00915","0.17189"
"216.27000","18.02278","0.17490"
"216.43200","18.03629","0.17633"
"216.59400","18.04974","0.17925"
"216.75600","18.06326","0.18169"
"216.91800","18.07677","0.18356"
"217.08000","18.09022","0.18658"
"217.24200","18.10373","0.18712"
"217.40400","18.11724","0.18872"
"217.56600","18.13076","0.18979"
"217.72800","18.14415","0.18899"
"217.89000","18.15772","0.19121"
"218.05200","18.17123","0.19261"
"218.21400","18.18469","0.08460"
"218.37600","18.19826","0.00656"
"218.53800","18.21177","0.04041"
"218.70000","18.22523","0.02398"
"218.86200","18.23874","0.03441"
"219.02400","18.25219","0.02297"
"219.18600","18.26570","0.03675"
"219.34800","18.27910","0.04362"
"219.51000","18.29279","0.00791"
"219.67200","18.30624","0.03308"
"219.83400","18.31975","0.01742"
"219.99600","18.33320","0.03995"
"220.15800","18.34678","0.01997"
"220.32000","18.36023","0.01246"
"220.48200","18.37368","0.03691"
"220.64400","18.38725","0.03085"
"220.80600","18.40071","0.03435"
"220.96800","18.41416","0.00731"
"221.13000","18.42779","0.03069"
"221.29200","18.44124","0.02262"
"221.45400","18.45470","0.03264"
"221.61600","18.46821","0.02334"
"221.77800","18.48172","0.02216"
"221.94000","18.49517","0.03510"
"222.10200","18.50875","0.01808"
"222.26400","18.52226","0.03236"
"222.42600","18.53577","0.01836"
"222.58800","18.54916","0.03332"
"222.75000","18.56274","0.01420"
"222.91200","18.57625","0.03468"
"223.07400","18.58970","0.03026"
"223.23600","18.60328","0.03136"
"223.39800","18.61679","0.02214"
"223.56000","18.63024","0.02483"
"223.72200","18.64375","0.03844"
"223.88400","18.65726","0.02572"
"224.04600","18.67072","0.02930"
"224.20800","18.68417","0.01739"
"224.37000","18.69774","0.04049"
"224.53200","18.71125","0.03166"
"224.69400","18.72471","0.02918"
"224.85600","18.73828","0.02420"
"225.01800","18.75179","0.03758"
"225.18000","18.76518","0.03908"
"225.34200","18.77870","0.02530"
"225.50400","18.79221","0.03276"
"225.66600","18.80572","0.03352"
"225.82800","18.81917","0.04198"
"225.99000","18.83275","0.02701"
"226.15200","18.84626","0.03613"
"226.31400","18.85965","0.03138"
"226.47600","18.87322","0.04350"
"226.63800","18.88680","0.03302"
"226.80000","18.90019","0.03859"
"226.96200","18.91370","0.03265"
"227.12400","18.92727","0.04478"
"227.28600","18.94079","0.03757"
"227.44800","18.95424","0.04051"
"227.61000","18.96769","0.03435"
"227.77200","18.98120","0.04476"
"227.93400","18.99466","0.04155"
"228.09600","19.00823","0.04143"
"228.25800","19.02174","0.03500"
"228.42000","19.03519","0.04578"
"228.58200","19.04871","0.04412"
"228.74400","19.06228","0.04223"
"228.90600","19.07573","0.03692"
"229.06800","19.08918","0.04701"
"229.23000","19.10270","0.04537"
"229.39200","19.11621","0.04305"
"229.55400","19.12972","0.03867"
"229.71600","19.14323","0.04803"
"229.87800","19.15675","0.04662"
"230.04000","19.17020","0.04380"
"230.20200","19.18377","0.04131"
"230.36400","19.19716","0.05022"
"230.52600","19.21068","0.04702"
"230.68800","19.22419","0.04439"
"230.85000","19.23776","0.04468"
"231.01200","19.25127","0.05285"
"231.17400","19.26467","0.04749"
"231.33600","19.27830","0.04480"
"231.49800","19.29181","0.04773"
"231.66000","19.30520","0.05439"
"231.82200","19.31878","0.04764"
"231.98400","19.33223","0.04607"
"232.14600","19.34574","0.05119"
"232.30800","19.35919","0.05615"
"232.47000","19.37276","0.04782"
"232.63200","19.38628","0.04776"
"232.79400","19.39961","0.05623"
"232.95600","19.41324","0.00233"
"233.11800","19.42676","0.00355"
"233.28000","19.44021","0.00283"
"233.44200","19.45372","-0.00034"
"233.60400","19.46729","-0.00081"
"233.76600","19.48075","-0.00057"
"233.92800","19.49420","-0.00038"
"234.09000","19.50777","0.00040"
"234.25200","19.52122","0.00093"
"234.41400","19.53468","0.00055"
"234.57600","19.54825","0.00003"
"234.73800","19.56176","0.00057"
"234.90000","19.57521","0.00005"
"235.06200","19.58872","0.00018"
"235.22400","19.60224","0.00068"
"235.38600","19.61569","0.00016"
"235.54800","19.62920","0.00068"
"235.71000","19.64271","0.00012"
"235.87200","19.65623","0.00053"
"236.03400","19.66968","0.00015"
"236.19600","19.68325","0.00082"
"236.35800","19.69676","0.00004"
"236.52000","19.71022","0.00067"
"236.68200","19.72373","0.00053"
"236.84400","19.73724","0.00115"
"236.85800","19.73844","0.00094"