File: Force_trajectories/170226_1/Specimen_RawData_1.csv
End date,"2/26/2017"
Specimen label,"1AT_2"
Maximum Load,"0.07470",N

Time,Extension,Load
(s),(mm),(N)
"0.00000","0.00000","0.00032"
"0.19200","0.01327","0.00043"
"0.38400","0.03217","0.00018"
"0.57600","0.04825","-0.00019"
"0.76800","0.06421","0.00000"
"0.96000","0.08018","0.00009"
"1.15200","0.09620","0.00057"
"1.34400","0.11228","0.00056"
"1.53600","0.12813","0.00063"
"1.72800","0.14421","0.00077"
"1.92000","0.16018","0.00004"
"2.11200","0.17608","0.00091"
"2.30400","0.19228","0.00041"
"2.49600","0.20813","0.00065"
"2.68800","0.22415","0.00005"
"2.88000","0.24023","0.00032"
"3.07200","0.25614","0.00130"
"3.26400","0.27216","0.00049"
"3.45600","0.28825","0.00034"
"3.64800","0.30415","0.00017"
"3.84000","0.32023","0.00060"
"4.03200","0.33620","0.00089"
"4.22400","0.35216","0.00084"
"4.41600","0.36818","0.00099"
"4.60800","0.38427","0.00091"
"4.80000","0.40011","0.00042"
"4.99200","0.41619","0.00037"
"5.18400","0.43222","0.00101"
"5.37600","0.44812","0.00064"
"5.56800","0.46421","0.00024"
"5.76000","0.48017","0.00045"
"5.95200","0.49613","0.00083"
"6.14400","0.51216","0.00051"
"6.33600","0.52818","0.00074"
"6.52800","0.54414","0.00095"
"6.72000","0.56023","0.00081"
"6.91200","0.57613","0.00068"
"7.10400","0.59222","0.00028"
"7.29600","0.60818","0.00079"
"7.48800","0.62414","0.00105"
"7.68000","0.64017","0.00078"
"7.87200","0.65619","0.00093"
"8.06400","0.67215","0.00116"
"8.25600","0.68818","0.00053"
"8.44800","0.70420","0.00128"
"8.64000","0.72016","0.00148"
"8.83200","0.73625","0.00077"
"9.02400","0.75215","0.00091"
"9.21600","0.76818","0.00029"
"9.40800","0.78420","0.00069"
"9.60000","0.80016","0.00043"
"9.79200","0.81625","0.00086"
"9.98400","0.83215","0.00091"
"10.17600","0.84817","0.00062"
"10.36800","0.86420","0.00088"
"10.56000","0.88016","0.00125"
"10.75200","0.89619","0.00109"
"10.94400","0.91227","0.00079"
"11.13600","0.92811","0.00045"
"11.32800","0.94420","0.00099"
"11.52000","0.96022","0.00079"
"11.71200","0.97612","0.00102"
"11.90400","0.99221","0.00124"
"12.09600","1.00817","0.00082"
"12.28800","1.02413","0.00057"
"12.48000","1.04016","0.00075"
"12.67200","1.05618","0.00074"
"12.86400","1.07209","0.00079"
"13.05600","1.08817","0.00087"
"13.24800","1.10419","0.00088"
"13.44000","1.12010","0.00148"
"13.63200","1.13624","0.00076"
"13.82400","1.15220","0.00087"
"14.01600","1.16811","0.00145"
"14.20800","1.18419","0.00074"
"14.40000","1.20016","0.00111"
"14.59200","1.21618","0.00101"
"14.78400","1.23220","0.00103"
"14.97600","1.24811","0.00082"
"15.16800","1.26413","0.00133"
"15.36000","1.28021","0.00089"
"15.55200","1.29612","0.00132"
"15.74400","1.31220","0.00129"
"15.93600","1.32822","0.00104"
"16.12800","1.34413","0.00083"
"16.32000","1.36015","0.00125"
"16.51200","1.37624","0.00118"
"16.70400","1.39214","0.00089"
"16.89600","1.40816","0.00051"
"17.08800","1.42419","0.00100"
"17.28000","1.44021","0.00110"
"17.47200","1.45617","0.00068"
"17.66400","1.47220","0.00076"
"17.85600","1.48816","0.00076"
"18.04800","1.50419","0.00109"
"18.24000","1.52015","0.00112"
"18.43200","1.53623","0.00120"
"18.62400","1.55220","0.00061"
"18.81600","1.56816","0.00093"
"19.00800","1.58424","0.00125"
"19.20000","1.60015","0.00107"
"19.39200","1.61617","0.00061"
"19.58400","1.63213","0.00013"
"19.77600","1.64816","0.00121"
"19.96800","1.66418","0.00099"
"20.16000","1.68015","0.00068"
"20.35200","1.69611","0.00101"
"20.54400","1.71219","0.00095"
"20.73600","1.72822","0.00117"
"20.92800","1.74412","0.00091"
"21.12000","1.76026","0.00099"
"21.31200","1.77617","0.00063"
"21.50400","1.79213","0.00102"
"21.69600","1.80821","0.00129"
"21.88800","1.82418","0.00084"
"22.08000","1.84014","0.00112"
"22.27200","1.85623","0.00082"
"22.46400","1.87219","0.00089"
"22.65600","1.88815","0.00096"
"22.84800","1.90424","0.00094"
"23.04000","1.92014","0.00157"
"23.23200","1.93616","0.00101"
"23.42400","1.95225","0.00142"
"23.61600","1.96809","0.00094"
"23.80800","1.98424","0.00115"
"24.00000","2.00020","0.00097"
"24.19200","2.01610","0.00135"
"24.38400","2.03219","0.00149"
"24.57600","2.04821","0.00056"
"24.76800","2.06417","0.00117"
"24.96000","2.08020","0.00141"
"25.15200","2.09616","0.00087"
"25.34400","2.11213","0.00135"
"25.53600","2.12821","0.00114"
"25.72800","2.14411","0.00125"
"25.92000","2.16020","0.00124"
"26.11200","2.17622","0.00144"
"26.30400","2.19218","0.00113"
"26.49600","2.20821","0.00107"
"26.68800","2.22423","0.00116"
"26.88000","2.24013","0.00102"
"27.07200","2.25616","0.00090"
"27.26400","2.27218","0.00115"
"27.45600","2.28821","0.00142"
"27.64800","2.30411","0.00098"
"27.84000","2.32019","0.00131"
"28.03200","2.33616","0.00110"
"28.22400","2.35218","0.00103"
"28.41600","2.36814","0.00188"
"28.60800","2.38417","0.00056"
"28.80000","2.40025","0.00145"
"28.99200","2.41621","0.00125"
"29.18400","2.43224","0.00140"
"29.37600","2.44820","0.00122"
"29.56800","2.46411","0.00112"
"29.76000","2.48019","0.00140"
"29.95200","2.49615","0.00142"
"30.14400","2.51218","0.00166"
"30.33600","2.52820","0.00096"
"30.52800","2.54416","0.00150"
"30.72000","2.56019","0.00131"
"30.91200","2.57621","0.00111"
"31.10400","2.59212","0.00136"
"31.29600","2.60820","0.00106"
"31.48800","2.62422","0.00133"
"31.68000","2.64013","0.00112"
"31.87200","2.65627","0.00153"
"32.06400","2.67223","0.00124"
"32.25600","2.68814","0.00152"
"32.44800","2.70422","0.00130"
"32.64000","2.72018","0.00104"
"32.83200","2.73615","0.00098"
"33.02400","2.75223","0.00116"
"33.21600","2.76814","0.00146"
"33.40800","2.78416","0.00144"
"33.60000","2.80018","0.00142"
"33.79200","2.81621","0.00093"
"33.98400","2.83223","0.00126"
"34.17600","2.84825","0.00093"
"34.36800","2.86416","0.00131"
"34.56000","2.88018","0.00127"
"34.75200","2.89626","0.00123"
"34.94400","2.91211","0.00117"
"35.13600","2.92819","0.00119"
"35.32800","2.94422","0.00139"
"35.52000","2.96012","0.00155"
"35.71200","2.97620","0.00186"
"35.90400","2.99217","0.00072"
"36.09600","3.00813","0.00130"
"36.28800","3.02415","0.00097"
"36.48000","3.04018","0.00175"
"36.67200","3.05620","0.00153"
"36.86400","3.07217","0.00106"
"37.05600","3.08819","0.00136"
"37.24800","3.10421","0.00127"
"37.44000","3.12024","0.00187"
"37.63200","3.13614","0.00143"
"37.82400","3.15222","0.00174"
"38.01600","3.16819","0.00150"
"38.20800","3.18415","0.00151"
"38.40000","3.20012","0.00159"
"38.59200","3.21614","0.00182"
"38.78400","3.23222","0.00162"
"38.97600","3.24819","0.00165"
"39.16800","3.26415","0.00157"
"39.36000","3.28023","0.00161"
"39.55200","3.29620","0.00144"
"39.74400","3.31216","0.00140"
"39.93600","3.32824","0.00140"
"40.12800","3.34415","0.00116"
"40.32000","3.36011","0.00128"
"40.51200","3.37620","0.00175"
"40.70400","3.39210","0.00212"
"40.89600","3.40818","0.00136"
"41.08800","3.42421","0.00195"
"41.28000","3.44017","0.00155"
"41.47200","3.45619","0.00200"
"41.66400","3.47222","0.00174"
"41.85600","3.48818","0.00136"
"42.04800","3.50420","0.00087"
"42.24000","3.52023","0.00169"
"42.43200","3.53607","0.00163"
"42.62400","3.55222","0.00170"
"42.81600","3.56824","0.00118"
"43.00800","3.58414","0.00162"
"43.20000","3.60023","0.00151"
"43.39200","3.61619","0.00171"
"43.58400","3.63209","0.00156"
"43.77600","3.64824","0.00123"
"43.96800","3.66414","0.00112"
"44.16000","3.68017","0.00177"
"44.35200","3.69625","0.00137"
"44.54400","3.71215","0.00179"
"44.73600","3.72818","0.00161"
"44.92800","3.74420","0.00126"
"45.12000","3.76016","0.00136"
"45.31200","3.77619","0.00184"
"45.50400","3.79221","0.00120"
"45.69600","3.80812","0.00166"
"45.88800","3.82414","0.00179"
"46.08000","3.84016","0.00141"
"46.27200","3.85613","0.00142"
"46.46400","3.87215","0.00193"
"46.65600","3.88823","0.00192"
"46.84800","3.90420","0.00194"
"47.04000","3.92016","0.00163"
"47.23200","3.93618","0.00145"
"47.42400","3.95221","0.00186"
"47.61600","3.96817","0.00176"
"47.80800","3.98414","0.00118"
"48.00000","4.00022","0.00149"
"48.19200","4.01624","0.00155"
"48.38400","4.03215","0.00223"
"48.57600","4.04823","0.00202"
"48.76800","4.06419","0.00183"
"48.96000","4.08016","0.00183"
"49.15200","4.09624","0.00179"
"49.34400","4.11220","0.00186"
"49.53600","4.12817","0.00172"
"49.72800","4.14419","0.00188"
"49.92000","4.16016","0.00188"
"50.11200","4.17618","0.00209"
"50.30400","4.19220","0.00191"
"50.49600","4.20817","0.00175"
"50.68800","4.22419","0.00229"
"50.88000","4.24015","0.00183"
"51.07200","4.25612","0.00206"
"51.26400","4.27220","0.00209"
"51.45600","4.28817","0.00175"
"51.64800","4.30413","0.00193"
"51.84000","4.32021","0.00203"
"52.03200","4.33618","0.00183"
"52.22400","4.35214","0.00196"
"52.41600","4.36822","0.00212"
"52.60800","4.38419","0.00172"
"52.80000","4.40021","0.00227"
"52.99200","4.41617","0.00230"
"53.18400","4.43220","0.00231"
"53.37600","4.44822","0.00160"
"53.56800","4.46419","0.00201"
"53.76000","4.48015","0.00196"
"53.95200","4.49623","0.00226"
"54.14400","4.51214","0.00175"
"54.33600","4.52816","0.00137"
"54.52800","4.54418","0.00221"
"54.72000","4.56015","0.00193"
"54.91200","4.57617","0.00220"
"55.10400","4.59219","0.00194"
"55.29600","4.60816","0.00176"
"55.48800","4.62418","0.00226"
"55.68000","4.64021","0.00201"
"55.87200","4.65611","0.00164"
"56.06400","4.67219","0.00211"
"56.25600","4.68822","0.00165"
"56.44800","4.70406","0.00236"
"56.64000","4.72020","0.00177"
"56.83200","4.73617","0.00191"
"57.02400","4.75213","0.00172"
"57.21600","4.76822","0.00232"
"57.40800","4.78424","0.00200"
"57.60000","4.80014","0.00164"
"57.79200","4.81617","0.00211"
"57.98400","4.83213","0.00139"
"58.17600","4.84815","0.00219"
"58.36800","4.86418","0.00172"
"58.56000","4.88014","0.00226"
"58.75200","4.89622","0.00144"
"58.94400","4.91219","0.00204"
"59.13600","4.92815","0.00204"
"59.32800","4.94418","0.00244"
"59.52000","4.96020","0.00185"
"59.71200","4.97622","0.00240"
"59.90400","4.99219","0.00211"
"60.09600","5.00815","0.00224"
"60.28800","5.02417","0.00237"
"60.48000","5.04020","0.00269"
"60.67200","5.05616","0.00230"
"60.86400","5.07219","0.00202"
"61.05600","5.08815","0.00208"
"61.24800","5.10417","0.00196"
"61.44000","5.12020","0.00216"
"61.63200","5.13622","0.00184"
"61.82400","5.15212","0.00195"
"62.01600","5.16821","0.00214"
"62.20800","5.18417","0.00207"
"62.40000","5.20014","0.00211"
"62.59200","5.21622","0.00273"
"62.78400","5.23212","0.00228"
"62.97600","5.24815","0.00229"
"63.16800","5.26417","0.00232"
"63.36000","5.28007","0.00195"
"63.55200","5.29616","0.00248"
"63.74400","5.31224","0.00256"
"63.93600","5.32808","0.00233"
"64.12800","5.34423","0.00259"
"64.32000","5.36019","0.00226"
"64.51200","5.37609","0.00183"
"64.70400","5.39218","0.00151"
"64.89600","5.40820","0.00126"
"65.08800","5.42411","0.00212"
"65.28000","5.44025","0.00206"
"65.47200","5.45621","0.00162"
"65.66400","5.47212","0.00181"
"65.85600","5.48820","0.00220"
"66.04800","5.50416","0.00221"
"66.24000","5.52019","0.00206"
"66.43200","5.53621","0.00215"
"66.62400","5.55218","0.00224"
"66.81600","5.56814","0.00227"
"67.00800","5.58422","0.00237"
"67.20000","5.60019","0.00262"
"67.39200","5.61621","0.00215"
"67.58400","5.63223","0.00227"
"67.77600","5.64814","0.00268"
"67.96800","5.66416","0.00227"
"68.16000","5.68019","0.00193"
"68.35200","5.69621","0.00206"
"68.54400","5.71217","0.00259"
"68.73600","5.72820","0.00246"
"68.92800","5.74416","0.00249"
"69.12000","5.76012","0.00189"
"69.31200","5.77621","0.00243"
"69.50400","5.79217","0.00230"
"69.69600","5.80819","0.00216"
"69.88800","5.82416","0.00240"
"70.08000","5.84018","0.00224"
"70.27200","5.85621","0.00260"
"70.46400","5.87217","0.00280"
"70.65600","5.88819","0.00299"
"70.84800","5.90416","0.00257"
"71.04000","5.92018","0.00249"
"71.23200","5.93614","0.00285"
"71.42400","5.95211","0.00214"
"71.61600","5.96819","0.00259"
"71.80800","5.98416","0.00255"
"72.00000","6.00012","0.00337"
"72.19200","6.01626","0.00295"
"72.38400","6.03217","0.00285"
"72.57600","6.04813","0.00288"
"72.76800","6.06427","0.00261"
"72.96000","6.08018","0.00327"
"73.15200","6.09608","0.00267"
"73.34400","6.11222","0.00226"
"73.53600","6.12819","0.00347"
"73.72800","6.14409","0.00257"
"73.92000","6.16017","0.00274"
"74.11200","6.17614","0.00286"
"74.30400","6.19216","0.00277"
"74.49600","6.20825","0.00305"
"74.68800","6.22415","0.00278"
"74.88000","6.24017","0.00286"
"75.07200","6.25626","0.00277"
"75.26400","6.27216","0.00252"
"75.45600","6.28819","0.00279"
"75.64800","6.30421","0.00347"
"75.84000","6.32011","0.00315"
"76.03200","6.33620","0.00309"
"76.22400","6.35222","0.00300"
"76.41600","6.36818","0.00303"
"76.60800","6.38415","0.00303"
"76.80000","6.40017","0.00307"
"76.99200","6.41613","0.00282"
"77.18400","6.43216","0.00300"
"77.37600","6.44812","0.00281"
"77.56800","6.46421","0.00346"
"77.76000","6.48017","0.00337"
"77.95200","6.49613","0.00273"
"78.14400","6.51222","0.00315"
"78.33600","6.52818","0.00280"
"78.52800","6.54414","0.00269"
"78.72000","6.56017","0.00274"
"78.91200","6.57619","0.00294"
"79.10400","6.59215","0.00366"
"79.29600","6.60818","0.00317"
"79.48800","6.62420","0.00315"
"79.68000","6.64023","0.00289"
"79.87200","6.65619","0.00313"
"80.06400","6.67215","0.00343"
"80.25600","6.68818","0.00270"
"80.44800","6.70420","0.00326"
"80.64000","6.72016","0.00360"
"80.83200","6.73625","0.00300"
"81.02400","6.75215","0.00368"
"81.21600","6.76818","0.00364"
"81.40800","6.78426","0.00334"
"81.60000","6.80022","0.00356"
"81.79200","6.81613","0.00257"
"81.98400","6.83221","0.00278"
"82.17600","6.84811","0.00293"
"82.36800","6.86420","0.00249"
"82.56000","6.88016","0.00309"
"82.75200","6.89618","0.00223"
"82.94400","6.91221","0.00237"
"83.13600","6.92817","0.00299"
"83.32800","6.94414","0.00287"
"83.52000","6.96022","0.00262"
"83.71200","6.97618","0.00243"
"83.90400","6.99209","0.00267"
"84.09600","7.00823","0.00281"
"84.28800","7.02413","0.00248"
"84.48000","7.04010","0.00306"
"84.67200","7.05624","0.00268"
"84.86400","7.07221","0.00257"
"85.05600","7.08817","0.00335"
"85.24800","7.10425","0.00254"
"85.44000","7.12016","0.00307"
"85.63200","7.13618","0.00228"
"85.82400","7.15226","0.00274"
"86.01600","7.16817","0.00273"
"86.20800","7.18419","0.00131"
"86.40000","7.20021","0.00194"
"86.59200","7.21612","0.00173"
"86.78400","7.23214","0.00113"
"86.97600","7.24817","0.00173"
"87.16800","7.26413","0.00179"
"87.36000","7.28015","0.00155"
"87.55200","7.29618","0.00205"
"87.74400","7.31214","0.00197"
"87.93600","7.32816","0.00151"
"88.12800","7.34419","0.00180"
"88.32000","7.36021","0.00252"
"88.51200","7.37617","0.00260"
"88.70400","7.39220","0.00214"
"88.89600","7.40816","0.00230"
"89.08800","7.42413","0.00211"
"89.28000","7.44009","0.00183"
"89.47200","7.45623","0.00245"
"89.66400","7.47220","0.00226"
"89.85600","7.48816","0.00213"
"90.04800","7.50418","0.00250"
"90.24000","7.52015","0.00245"
"90.43200","7.53617","0.00285"
"90.62400","7.55220","0.00279"
"90.81600","7.56816","0.00231"
"91.00800","7.58418","0.00249"
"91.20000","7.60021","0.00273"
"91.39200","7.61617","0.00223"
"91.58400","7.63219","0.00241"
"91.77600","7.64816","0.00231"
"91.96800","7.66412","0.00246"
"92.16000","7.68026","0.00287"
"92.35200","7.69617","0.00267"
"92.54400","7.71213","0.00305"
"92.73600","7.72816","0.00308"
"92.92800","7.74418","0.00303"
"93.12000","7.76020","0.00272"
"93.31200","7.77617","0.00287"
"93.50400","7.79213","0.00270"
"93.69600","7.80821","0.00251"
"93.88800","7.82424","0.00283"
"94.08000","7.84020","0.00306"
"94.27200","7.85622","0.00290"
"94.46400","7.87219","0.00278"
"94.65600","7.88815","0.00251"
"94.84800","7.90424","0.00340"
"95.04000","7.92020","0.00269"
"95.23200","7.93610","0.00334"
"95.42400","7.95225","0.00273"
"95.61600","7.96815","0.00274"
"95.80800","7.98417","0.00294"
"96.00000","8.00026","0.00323"
"96.19200","8.01616","0.00297"
"96.38400","8.03213","0.00270"
"96.57600","8.04821","0.00279"
"96.76800","8.06411","0.00337"
"96.96000","8.08014","0.00336"
"97.15200","8.09616","0.00272"
"97.34400","8.11212","0.00260"
"97.53600","8.12815","0.00256"
"97.72800","8.14423","0.00270"
"97.92000","8.16013","0.00269"
"98.11200","8.17622","0.00341"
"98.30400","8.19218","0.00319"
"98.49600","8.20815","0.00331"
"98.68800","8.22417","0.00290"
"98.88000","8.24019","0.00347"
"99.07200","8.25616","0.00303"
"99.26400","8.27218","0.00248"
"99.45600","8.28814","0.00256"
"99.64800","8.30423","0.00257"
"99.84000","8.32019","0.00273"
"100.03200","8.33616","0.00263"
"100.22400","8.35218","0.00273"
"100.41600","8.36814","0.00301"
"100.60800","8.38417","0.00290"
"100.80000","8.40019","0.00303"
"100.99200","8.41615","0.00325"
"101.18400","8.43218","0.00314"
"101.37600","8.44814","0.00360"
"101.56800","8.46416","0.00290"
"101.76000","8.48019","0.00301"
"101.95200","8.49621","0.00333"
"102.14400","8.51218","0.00307"
"102.33600","8.52820","0.00309"
"102.52800","8.54422","0.00362"
"102.72000","8.56013","0.00330"
"102.91200","8.57621","0.00332"
"103.10400","8.59217","0.00343"
"103.29600","8.60814","0.00347"
"103.48800","8.62422","0.00380"
"103.68000","8.64019","0.00368"
"103.87200","8.65615","0.00445"
"104.06400","8.67217","0.00421"
"104.25600","8.68814","0.00371"
"104.44800","8.70416","0.00390"
"104.64000","8.72018","0.00416"
"104.83200","8.73615","0.00438"
"105.02400","8.75217","0.00370"
"105.21600","8.76819","0.00412"
"105.40800","8.78410","0.00418"
"105.60000","8.80018","0.00444"
"105.79200","8.81615","0.00336"
"105.98400","8.83217","0.00407"
"106.17600","8.84819","0.00373"
"106.36800","8.86410","0.00389"
"106.56000","8.88018","0.00436"
"106.75200","8.89620","0.00394"
"106.94400","8.91217","0.00408"
"107.13600","8.92819","0.00491"
"107.32800","8.94416","0.00402"
"107.52000","8.96012","0.00477"
"107.71200","8.97614","0.00457"
"107.90400","8.99223","0.00436"
"108.09600","9.00813","0.00454"
"108.28800","9.02421","0.00449"
"108.48000","9.04024","0.00482"
"108.67200","9.05614","0.00449"
"108.86400","9.07216","0.00454"
"109.05600","9.08819","0.00468"
"109.24800","9.10415","0.00515"
"109.44000","9.12018","0.00456"
"109.63200","9.13614","0.00435"
"109.82400","9.15216","0.00394"
"110.01600","9.16819","0.00485"
"110.20800","9.18415","0.00513"
"110.40000","9.20017","0.00530"
"110.59200","9.21620","0.00519"
"110.78400","9.23216","0.00545"
"110.97600","9.24819","0.00555"
"111.16800","9.26421","0.00494"
"111.36000","9.28017","0.00511"
"111.55200","9.29620","0.00547"
"111.74400","9.31216","0.00536"
"111.93600","9.32818","0.00586"
"112.12800","9.34421","0.00567"
"112.32000","9.36017","0.00556"
"112.51200","9.37613","0.00607"
"112.70400","9.39222","0.00539"
"112.89600","9.40812","0.00577"
"113.08800","9.42421","0.00544"
"113.28000","9.44017","0.00587"
"113.47200","9.45613","0.00577"
"113.66400","9.47222","0.00572"
"113.85600","9.48818","0.00569"
"114.04800","9.50414","0.00603"
"114.24000","9.52023","0.00603"
"114.43200","9.53613","0.00565"
"114.62400","9.55210","0.00621"
"114.81600","9.56818","0.00613"
"115.00800","9.58414","0.00635"
"115.20000","9.60017","0.00676"
"115.39200","9.61625","0.00681"
"115.58400","9.63215","0.00637"
"115.77600","9.64824","0.00585"
"115.96800","9.66420","0.00573"
"116.16000","9.68017","0.00629"
"116.35200","9.69619","0.00576"
"116.54400","9.71221","0.00619"
"116.73600","9.72812","0.00593"
"116.92800","9.74420","0.00620"
"117.12000","9.76022","0.00600"
"117.31200","9.77607","0.00625"
"117.50400","9.79221","0.00609"
"117.69600","9.80817","0.00593"
"117.88800","9.82420","0.00590"
"118.08000","9.84022","0.00637"
"118.27200","9.85618","0.00602"
"118.46400","9.87215","0.00432"
"118.65600","9.88823","0.00451"
"118.84800","9.90414","0.00395"
"119.04000","9.92022","0.00473"
"119.23200","9.93618","0.00471"
"119.42400","9.95215","0.00485"
"119.61600","9.96817","0.00536"
"119.80800","9.98419","0.00521"
"120.00000","10.00016","0.00551"
"120.19200","10.01612","0.00508"
"120.38400","10.03215","0.00508"
"120.57600","10.04817","0.00455"
"120.76800","10.06413","0.00418"
"120.96000","10.08016","0.00312"
"121.15200","10.09618","0.00381"
"121.34400","10.11220","0.00440"
"121.53600","10.12817","0.00403"
"121.72800","10.14419","0.00372"
"121.92000","10.16015","0.00415"
"122.11200","10.17618","0.00439"
"122.30400","10.19220","0.00360"
"122.49600","10.20811","0.00422"
"122.68800","10.22413","0.00472"
"122.88000","10.24015","0.00472"
"123.07200","10.25618","0.00456"
"123.26400","10.27220","0.00500"
"123.45600","10.28822","0.00438"
"123.64800","10.30413","0.00433"
"123.84000","10.32021","0.00459"
"124.03200","10.33618","0.00487"
"124.22400","10.35214","0.00465"
"124.41600","10.36822","0.00459"
"124.60800","10.38419","0.00473"
"124.80000","10.40009","0.00451"
"124.99200","10.41623","0.00463"
"125.18400","10.43220","0.00504"
"125.37600","10.44816","0.00404"
"125.56800","10.46418","0.00462"
"125.76000","10.48021","0.00430"
"125.95200","10.49617","0.00448"
"126.14400","10.51226","0.00502"
"126.33600","10.52816","0.00435"
"126.52800","10.54418","0.00505"
"126.72000","10.56021","0.00418"
"126.91200","10.57611","0.00522"
"127.10400","10.59219","0.00503"
"127.29600","10.60822","0.00494"
"127.48800","10.62412","0.00495"
"127.68000","10.64020","0.00450"
"127.87200","10.65623","0.00494"
"128.06400","10.67213","0.00500"
"128.25600","10.68822","0.00535"
"128.44800","10.70418","0.00561"
"128.64000","10.72014","0.00529"
"128.83200","10.73617","0.00576"
"129.02400","10.75219","0.00587"
"129.21600","10.76816","0.00554"
"129.40800","10.78418","0.00561"
"129.60000","10.80014","0.00608"
"129.79200","10.81617","0.00561"
"129.98400","10.83219","0.00532"
"130.17600","10.84815","0.00596"
"130.36800","10.86418","0.00636"
"130.56000","10.88014","0.00633"
"130.75200","10.89616","0.00656"
"130.94400","10.91219","0.00664"
"131.13600","10.92815","0.00679"
"131.32800","10.94418","0.00676"
"131.52000","10.96020","0.00663"
"131.71200","10.97616","0.00676"
"131.90400","10.99219","0.00676"
"132.09600","11.00821","0.00701"
"132.28800","11.02417","0.00700"
"132.48000","11.04020","0.00697"
"132.67200","11.05616","0.00693"
"132.86400","11.07213","0.00739"
"133.05600","11.08827","0.00726"
"133.24800","11.10411","0.00781"
"133.44000","11.12014","0.00782"
"133.63200","11.13622","0.00808"
"133.82400","11.15218","0.00776"
"134.01600","11.16815","0.00782"
"134.20800","11.18417","0.00819"
"134.40000","11.20019","0.00833"
"134.59200","11.21622","0.00878"
"134.78400","11.23218","0.00820"
"134.97600","11.24815","0.00814"
"135.16800","11.26417","0.00864"
"135.36000","11.28019","0.00845"
"135.55200","11.29610","0.00969"
"135.74400","11.31218","0.00844"
"135.93600","11.32820","0.00799"
"136.12800","11.34411","0.00891"
"136.32000","11.36025","0.00803"
"136.51200","11.37615","0.00889"
"136.70400","11.39212","0.00923"
"136.89600","11.40820","0.00957"
"137.08800","11.42417","0.00964"
"137.28000","11.44013","0.00906"
"137.47200","11.45621","0.00923"
"137.66400","11.47212","0.01009"
"137.85600","11.48820","0.00987"
"138.04800","11.50416","0.00957"
"138.24000","11.52013","0.01004"
"138.43200","11.53621","0.00969"
"138.62400","11.55218","0.01042"
"138.81600","11.56814","0.00998"
"139.00800","11.58416","0.00979"
"139.20000","11.60019","0.01107"
"139.39200","11.61615","0.01096"
"139.58400","11.63217","0.01087"
"139.77600","11.64820","0.01117"
"139.96800","11.66416","0.01085"
"140.16000","11.68018","0.01149"
"140.35200","11.69615","0.01115"
"140.54400","11.71217","0.01174"
"140.73600","11.72820","0.01112"
"140.92800","11.74416","0.01144"
"141.12000","11.76024","0.01174"
"141.31200","11.77615","0.01225"
"141.50400","11.79217","0.01148"
"141.69600","11.80819","0.01191"
"141.88800","11.82416","0.01226"
"142.08000","11.84012","0.01197"
"142.27200","11.85614","0.01255"
"142.46400","11.87211","0.01236"
"142.65600","11.88825","0.01313"
"142.84800","11.90422","0.01253"
"143.04000","11.92018","0.01321"
"143.23200","11.93620","0.01333"
"143.42400","11.95223","0.01332"
"143.61600","11.96813","0.01356"
"143.80800","11.98421","0.01369"
"144.00000","12.00018","0.01395"
"144.19200","12.01614","0.01420"
"144.38400","12.03223","0.01434"
"144.57600","12.04819","0.01430"
"144.76800","12.06415","0.01451"
"144.96000","12.08024","0.01466"
"145.15200","12.09614","0.01539"
"145.34400","12.11216","0.01543"
"145.53600","12.12819","0.01573"
"145.72800","12.14421","0.01564"
"145.92000","12.16018","0.01553"
"146.11200","12.17620","0.01587"
"146.30400","12.19210","0.01658"
"146.49600","12.20819","0.01634"
"146.68800","12.22421","0.01670"
"146.88000","12.24011","0.01703"
"147.07200","12.25626","0.01726"
"147.26400","12.27216","0.01796"
"147.45600","12.28812","0.01797"
"147.64800","12.30421","0.01814"
"147.84000","12.32011","0.01793"
"148.03200","12.33614","0.01873"
"148.22400","12.35216","0.01937"
"148.41600","12.36818","0.01907"
"148.60800","12.38421","0.01864"
"148.80000","12.40023","0.01926"
"148.99200","12.41619","0.01913"
"149.18400","12.43216","0.01982"
"149.37600","12.44818","0.01949"
"149.56800","12.46415","0.01930"
"149.76000","12.48023","0.01961"
"149.95200","12.49619","0.01931"
"150.14400","12.51216","0.02030"
"150.33600","12.52818","0.02040"
"150.52800","12.54414","0.02049"
"150.72000","12.56017","0.02077"
"150.91200","12.57619","0.02146"
"151.10400","12.59215","0.02121"
"151.29600","12.60824","0.02175"
"151.48800","12.62420","0.02119"
"151.68000","12.64017","0.02253"
"151.87200","12.65625","0.02288"
"152.06400","12.67215","0.02249"
"152.25600","12.68818","0.02304"
"152.44800","12.70420","0.02297"
"152.64000","12.72010","0.02439"
"152.83200","12.73619","0.02372"
"153.02400","12.75215","0.02472"
"153.21600","12.76817","0.02427"
"153.40800","12.78414","0.02470"
"153.60000","12.80022","0.02506"
"153.79200","12.81619","0.02513"
"153.98400","12.83215","0.02516"
"154.17600","12.84823","0.02469"
"154.36800","12.86414","0.02494"
"154.56000","12.88022","0.02523"
"154.75200","12.89618","0.02497"
"154.94400","12.91209","0.02494"
"155.13600","12.92823","0.02509"
"155.32800","12.94420","0.02147"
"155.52000","12.96016","0.01810"
"155.71200","12.97624","0.01902"
"155.90400","12.99215","0.01877"
"156.09600","13.00817","0.01991"
"156.28800","13.02419","0.02108"
"156.48000","13.04016","0.02064"
"156.67200","13.05618","0.02078"
"156.86400","13.07220","0.02196"
"157.05600","13.08811","0.02312"
"157.24800","13.10413","0.02258"
"157.44000","13.12022","0.01875"
"157.63200","13.13612","0.01986"
"157.82400","13.15220","0.01959"
"158.01600","13.16823","0.02031"
"158.20800","13.18413","0.02035"
"158.40000","13.20015","0.02051"
"158.59200","13.21618","0.02133"
"158.78400","13.23220","0.02141"
"158.97600","13.24822","0.02284"
"159.16800","13.26419","0.02272"
"159.36000","13.28021","0.02237"
"159.55200","13.29618","0.02294"
"159.74400","13.31220","0.02338"
"159.93600","13.32822","0.02280"
"160.12800","13.34419","0.02191"
"160.32000","13.36009","0.02283"
"160.51200","13.37617","0.02373"
"160.70400","13.39220","0.02387"
"160.89600","13.40816","0.02491"
"161.08800","13.42419","0.02533"
"161.28000","13.44015","0.02458"
"161.47200","13.45617","0.02554"
"161.66400","13.47220","0.02569"
"161.85600","13.48816","0.02597"
"162.04800","13.50424","0.02671"
"162.24000","13.52021","0.02641"
"162.43200","13.53617","0.02749"
"162.62400","13.55220","0.02727"
"162.81600","13.56822","0.02772"
"163.00800","13.58412","0.02875"
"163.20000","13.60021","0.02858"
"163.39200","13.61617","0.02882"
"163.58400","13.63213","0.02897"
"163.77600","13.64816","0.02827"
"163.96800","13.66418","0.02905"
"164.16000","13.68020","0.02910"
"164.35200","13.69623","0.02937"
"164.54400","13.71219","0.02927"
"164.73600","13.72822","0.03020"
"164.92800","13.74418","0.03044"
"165.12000","13.76014","0.03052"
"165.31200","13.77623","0.03131"
"165.50400","13.79213","0.03187"
"165.69600","13.80809","0.03176"
"165.88800","13.82424","0.03219"
"166.08000","13.84020","0.03215"
"166.27200","13.85611","0.03148"
"166.46400","13.87219","0.03223"
"166.65600","13.88821","0.03143"
"166.84800","13.90418","0.03282"
"167.04000","13.92020","0.03296"
"167.23200","13.93616","0.03297"
"167.42400","13.95219","0.03244"
"167.61600","13.96821","0.03246"
"167.80800","13.98411","0.03257"
"168.00000","14.00020","0.03289"
"168.19200","14.01622","0.03344"
"168.38400","14.03213","0.03359"
"168.57600","14.04821","0.03362"
"168.76800","14.06423","0.03395"
"168.96000","14.08008","0.03402"
"169.15200","14.09622","0.01233"
"169.34400","14.11218","0.00323"
"169.53600","14.12815","0.00350"
"169.72800","14.14417","0.00308"
"169.92000","14.16014","0.00059"
"170.11200","14.17616","0.00207"
"170.30400","14.19224","0.00200"
"170.49600","14.20815","0.00107"
"170.68800","14.22417","0.00369"
"170.88000","14.24019","0.00245"
"171.07200","14.25616","0.00161"
"171.26400","14.27218","0.00212"
"171.45600","14.28820","0.00251"
"171.64800","14.30417","0.00347"
"171.84000","14.32019","0.00198"
"172.03200","14.33616","0.00203"
"172.22400","14.35218","0.00282"
"172.41600","14.36814","0.00131"
"172.60800","14.38417","0.00331"
"172.80000","14.40019","0.00363"
"172.99200","14.41615","0.00189"
"173.18400","14.43218","0.00242"
"173.37600","14.44814","0.00255"
"173.56800","14.46416","0.00269"
"173.76000","14.48013","0.00375"
"173.95200","14.49621","0.00275"
"174.14400","14.51218","0.00249"
"174.33600","14.52814","0.00256"
"174.52800","14.54422","0.00416"
"174.72000","14.56019","0.00380"
"174.91200","14.57621","0.00312"
"175.10400","14.59223","0.00325"
"175.29600","14.60814","0.00351"
"175.48800","14.62422","0.00342"
"175.68000","14.64019","0.00451"
"175.87200","14.65615","0.00368"
"176.06400","14.67223","0.00328"
"176.25600","14.68814","0.00351"
"176.44800","14.70410","0.00495"
"176.64000","14.72024","0.00384"
"176.83200","14.73621","0.00352"
"177.02400","14.75211","0.00409"
"177.21600","14.76825","0.00348"
"177.40800","14.78422","0.00306"
"177.60000","14.80012","0.00055"
"177.79200","14.81621","-0.00013"
"177.98400","14.83217","-0.00065"
"178.17600","14.84813","-0.00026"
"178.36800","14.86422","-0.00066"
"178.56000","14.88012","-0.00101"
"178.75200","14.89614","-0.00036"
"178.94400","14.91223","-0.00001"
"179.13600","14.92813","0.00005"
"179.32800","14.94422","-0.00063"
"179.52000","14.96024","-0.00011"
"179.71200","14.97620","-0.00014"
"179.90400","14.99217","-0.00013"
"180.09600","15.00825","-0.00015"
"180.28800","15.02415","0.00003"
"180.48000","15.04012","0.00004"
"180.67200","15.05614","-0.00009"
"180.86400","15.07217","0.00025"
"181.05600","15.08819","-0.00009"
"181.24800","15.10415","0.00030"
"181.44000","15.12018","0.00039"
"181.63200","15.13620","0.00031"
"181.82400","15.15216","0.00059"
"182.01600","15.16825","-0.00016"
"182.20800","15.18421","0.00077"
"182.40000","15.20017","0.00040"
"182.59200","15.21620","0.00035"
"182.78400","15.23210","0.00037"
"182.97600","15.24819","0.00026"
"183.16800","15.26421","0.00073"
"183.36000","15.28017","0.00047"
"183.55200","15.29620","0.00100"
"183.74400","15.31222","0.00057"
"183.93600","15.32812","0.00100"
"184.12800","15.34421","0.00027"
"184.32000","15.36017","0.00067"
"184.51200","15.37613","0.00076"
"184.70400","15.39228","0.00057"
"184.89600","15.40818","0.00033"
"185.08800","15.42408","0.00122"
"185.28000","15.44029","0.00044"
"185.47200","15.45613","0.00020"
"185.66400","15.47216","0.00083"
"185.85600","15.48818","0.00074"
"186.04800","15.50414","0.00144"
"186.24000","15.52017","0.00088"
"186.43200","15.53619","0.00038"
"186.62400","15.55216","0.00090"
"186.81600","15.56818","0.00057"
"187.00800","15.58420","0.00037"
"187.20000","15.60011","0.00106"
"187.39200","15.61619","0.00078"
"187.58400","15.63221","0.00114"
"187.77600","15.64812","0.00114"
"187.96800","15.66420","0.00068"
"188.16000","15.68022","0.00122"
"188.35200","15.69613","0.00117"
"188.54400","15.71221","0.00101"
"188.73600","15.72823","0.00106"
"188.92800","15.74414","0.00098"
"189.12000","15.76016","0.00110"
"189.31200","15.77613","0.00143"
"189.50400","15.79215","0.00125"
"189.69600","15.80823","0.00104"
"189.88800","15.82420","0.00080"
"190.08000","15.84022","0.00139"
"190.27200","15.85618","0.00127"
"190.46400","15.87221","0.00108"
"190.65600","15.88823","0.00140"
"190.84800","15.90420","0.00102"
"191.04000","15.92016","0.00170"
"191.23200","15.93618","0.00147"
"191.42400","15.95215","0.00121"
"191.61600","15.96817","0.00092"
"191.80800","15.98419","0.00120"
"192.00000","16.00016","0.00143"
"192.19200","16.01612","0.00142"
"192.38400","16.03214","0.00185"
"192.57600","16.04811","0.00182"
"192.76800","16.06419","0.00133"
"192.96000","16.08016","0.00104"
"193.15200","16.09618","0.00156"
"193.34400","16.11220","0.00148"
"193.53600","16.12811","0.00126"
"193.72800","16.14413","0.00114"
"193.92000","16.16015","0.00170"
"194.11200","16.17618","0.00107"
"194.30400","16.19220","0.00139"
"194.49600","16.20822","0.00131"
"194.68800","16.22413","0.00112"
"194.88000","16.24021","0.00172"
"195.07200","16.25624","0.00157"
"195.26400","16.27214","0.00156"
"195.45600","16.28816","0.00094"
"195.64800","16.30419","0.00156"
"195.84000","16.32015","0.00175"
"196.03200","16.33624","0.00132"
"196.22400","16.35214","0.00170"
"196.41600","16.36810","0.00167"
"196.60800","16.38424","0.00131"
"196.80000","16.40015","0.00136"
"196.99200","16.41611","0.00168"
"197.18400","16.43220","0.00168"
"197.37600","16.44816","0.00177"
"197.56800","16.46418","0.00158"
"197.76000","16.48021","0.00142"
"197.95200","16.49611","0.00172"
"198.14400","16.51220","0.00201"
"198.33600","16.52822","0.00141"
"198.52800","16.54412","0.00183"
"198.72000","16.56021","0.00186"
"198.91200","16.57611","0.00235"
"199.10400","16.59213","0.00189"
"199.29600","16.60816","0.00195"
"199.48800","16.62418","0.00195"
"199.68000","16.64014","0.00167"
"199.87200","16.65617","0.00164"
"200.06400","16.67219","0.00219"
"200.25600","16.68815","0.00174"
"200.44800","16.70418","0.00201"
"200.64000","16.72014","0.00183"
"200.83200","16.73623","0.00222"
"201.02400","16.75225","0.00220"
"201.21600","16.76815","0.00215"
"201.40800","16.78418","0.00199"
"201.60000","16.80020","0.00209"
"201.79200","16.81617","0.00188"
"201.98400","16.83219","0.00208"
"202.17600","16.84815","0.00249"
"202.36800","16.86418","0.00194"
"202.56000","16.88020","0.00231"
"202.75200","16.89616","0.00200"
"202.94400","16.91219","0.00231"
"203.13600","16.92821","0.00221"
"203.32800","16.94411","0.00195"
"203.52000","16.96026","0.00147"
"203.71200","16.97616","0.00237"
"203.90400","16.99213","0.00179"
"204.09600","17.00821","0.00187"
"204.28800","17.02411","0.00159"
"204.48000","17.04014","0.00179"
"204.67200","17.05616","0.00160"
"204.86400","17.07212","0.00188"
"205.05600","17.08821","0.00200"
"205.24800","17.10423","0.00203"
"205.44000","17.12013","0.00219"
"205.63200","17.13622","0.00234"
"205.82400","17.15224","0.00205"
"206.01600","17.16815","0.00212"
"206.20800","17.18417","0.00103"
"206.40000","17.20019","0.00225"
"206.59200","17.21610","0.00176"
"206.78400","17.23218","0.00230"
"206.97600","17.24814","0.00205"
"207.16800","17.26411","0.00171"
"207.36000","17.28025","0.00203"
"207.55200","17.29616","0.00273"
"207.74400","17.31218","0.00222"
"207.93600","17.32820","0.00211"
"208.12800","17.34417","0.00254"
"208.32000","17.36013","0.00220"
"208.51200","17.37621","0.00229"
"208.70400","17.39212","0.00237"
"208.89600","17.40820","0.00246"
"209.08800","17.42422","0.00207"
"209.28000","17.44013","0.00220"
"209.47200","17.45615","0.00187"
"209.66400","17.47223","0.00187"
"209.85600","17.48814","0.00221"
"210.04800","17.50416","0.00262"
"210.24000","17.52019","0.00254"
"210.43200","17.53615","0.00277"
"210.62400","17.55218","0.00242"
"210.81600","17.56814","0.00225"
"211.00800","17.58422","0.00224"
"211.20000","17.60018","0.00183"
"211.39200","17.61615","0.00255"
"211.58400","17.63223","0.00211"
"211.77600","17.64814","0.00207"
"211.96800","17.66410","0.00231"
"212.16000","17.68024","0.00244"
"212.35200","17.69615","0.00205"
"212.54400","17.71217","0.00236"
"212.73600","17.72820","0.00195"
"212.92800","17.74416","0.00236"
"213.12000","17.76018","0.00270"
"213.31200","17.77614","0.00216"
"213.50400","17.79217","0.00290"
"213.69600","17.80813","0.00221"
"213.88800","17.82416","0.00247"
"214.08000","17.84012","0.00258"
"214.27200","17.85614","0.00289"
"214.46400","17.87223","0.00240"
"214.65600","17.88813","0.00307"
"214.84800","17.90421","0.00302"
"215.04000","17.92018","0.00204"
"215.23200","17.93614","0.00232"
"215.42400","17.95223","0.00247"
"215.61600","17.96819","0.00269"
"215.80800","17.98421","0.00302"
"216.00000","18.00018","0.00229"
"216.19200","18.01620","0.00292"
"216.38400","18.03222","0.00272"
"216.57600","18.04825","0.00320"
"216.76800","18.06415","0.00266"
"216.96000","18.08018","0.00269"
"217.15200","18.09614","0.00295"
"217.34400","18.11210","0.00262"
"217.53600","18.12825","0.00266"
"217.72800","18.14415","0.00275"
"217.92000","18.16011","0.00274"
"218.11200","18.17620","0.00321"
"218.30400","18.19216","0.00242"
"218.49600","18.20819","0.00310"
"218.68800","18.22421","0.00354"
"218.88000","18.24011","0.00318"
"219.07200","18.25620","0.00327"
"219.26400","18.27216","0.00333"
"219.45600","18.28812","0.00349"
"219.64800","18.30421","0.00376"
"219.84000","18.32023","0.00349"
"220.03200","18.33613","0.00348"
"220.22400","18.35222","0.00333"
"220.41600","18.36824","0.00283"
"220.60800","18.38409","0.00354"
"220.80000","18.40017","0.00339"
"220.99200","18.41619","0.00390"
"221.18400","18.43210","0.00321"
"221.37600","18.44818","0.00339"
"221.56800","18.46420","0.00321"
"221.76000","18.48011","0.00366"
"221.95200","18.49619","0.00366"
"222.14400","18.51215","0.00336"
"222.33600","18.52818","0.00398"
"222.52800","18.54420","0.00335"
"222.72000","18.56017","0.00353"
"222.91200","18.57619","0.00427"
"223.10400","18.59215","0.00372"
"223.29600","18.60812","0.00451"
"223.48800","18.62420","0.00382"
"223.68000","18.64016","0.00441"
"223.87200","18.65613","0.00467"
"224.06400","18.67221","0.00449"
"224.25600","18.68818","0.00443"
"224.44800","18.70414","0.00418"
"224.64000","18.72016","0.00455"
"224.83200","18.73613","0.00397"
"225.02400","18.75221","0.00490"
"225.21600","18.76818","0.00434"
"225.40800","18.78414","0.00458"
"225.60000","18.80028","0.00456"
"225.79200","18.81618","0.00533"
"225.98400","18.83215","0.00516"
"226.17600","18.84823","0.00524"
"226.36800","18.86414","0.00475"
"226.56000","18.88016","0.00523"
"226.75200","18.89624","0.00520"
"226.94400","18.91215","0.00488"
"227.13600","18.92817","0.00529"
"227.32800","18.94419","0.00518"
"227.52000","18.96016","0.00588"
"227.71200","18.97618","0.00571"
"227.90400","18.99220","0.00589"
"228.09600","19.00811","0.00565"
"228.28800","19.02419","0.00616"
"228.48000","19.04022","0.00598"
"228.67200","19.05606","0.00639"
"228.86400","19.07220","0.00628"
"229.05600","19.08823","0.00659"
"229.24800","19.10407","0.00666"
"229.44000","19.12021","0.00696"
"229.63200","19.13612","0.00706"
"229.82400","19.15214","0.00742"
"230.01600","19.16823","0.00739"
"230.20800","19.18413","0.00779"
"230.40000","19.20015","0.00796"
"230.59200","19.21624","0.00789"
"230.78400","19.23214","0.00809"
"230.97600","19.24822","0.00780"
"231.16800","19.26419","0.00844"
"231.36000","19.28015","0.00791"
"231.55200","19.29618","0.00889"
"231.74400","19.31220","0.00823"
"231.93600","19.32816","0.00863"
"232.12800","19.34413","0.00891"
"232.32000","19.36021","0.00855"
"232.51200","19.37617","0.00871"
"232.70400","19.39220","0.00932"
"232.89600","19.40816","0.00873"
"233.08800","19.42418","0.00954"
"233.28000","19.44015","0.00910"
"233.47200","19.45617","0.00992"
"233.66400","19.47219","0.01016"
"233.85600","19.48816","0.00989"
"234.04800","19.50412","0.01037"
"234.24000","19.52027","0.01092"
"234.43200","19.53611","0.01105"
"234.62400","19.55219","0.01168"
"234.81600","19.56816","0.01202"
"235.00800","19.58412","0.01173"
"235.20000","19.60015","0.01219"
"235.39200","19.61617","0.01223"
"235.58400","19.63207","0.01272"
"235.77600","19.64822","0.01239"
"235.96800","19.66424","0.01305"
"236.16000","19.68014","0.01334"
"236.35200","19.69628","0.01304"
"236.54400","19.71213","0.01384"
"236.73600","19.72809","0.01398"
"236.92800","19.74424","0.01374"
"237.12000","19.76020","0.01418"
"237.31200","19.77611","0.01392"
"237.50400","19.79225","0.00541"
"237.69600","19.80815","0.00325"
"237.88800","19.82418","0.00215"
"238.08000","19.84026","0.00254"
"238.27200","19.85616","0.00235"
"238.46400","19.87219","0.00250"
"238.65600","19.88821","0.00319"
"238.84800","19.90417","0.00378"
"239.04000","19.92020","0.00278"
"239.23200","19.93622","0.00258"
"239.42400","19.95213","0.00260"
"239.61600","19.96821","0.00327"
"239.80800","19.98417","0.00323"
"240.00000","20.00014","0.00276"
"240.19200","20.01616","0.00299"
"240.38400","20.03218","0.00287"
"240.57600","20.04821","0.00291"
"240.76800","20.06417","0.00320"
"240.96000","20.08014","0.00374"
"241.15200","20.09616","0.00404"
"241.34400","20.11218","0.00411"
"241.53600","20.12815","0.00422"
"241.72800","20.14417","0.00398"
"241.92000","20.16019","0.00457"
"242.11200","20.17610","0.00438"
"242.30400","20.19218","0.00442"
"242.49600","20.20815","0.00441"
"242.68800","20.22411","0.00476"
"242.88000","20.24019","0.00446"
"243.07200","20.25616","0.00530"
"243.26400","20.27212","0.00520"
"243.45600","20.28820","0.00554"
"243.64800","20.30416","0.00557"
"243.84000","20.32019","0.00608"
"244.03200","20.33621","0.00600"
"244.22400","20.35217","0.00576"
"244.41600","20.36820","0.00493"
"244.60800","20.38423","0.00482"
"244.80000","20.40013","0.00441"
"244.99200","20.41621","0.00495"
"245.18400","20.43212","0.00606"
"245.37600","20.44814","0.00522"
"245.56800","20.46422","0.00544"
"245.76000","20.48013","0.00503"
"245.95200","20.49621","0.00498"
"246.14400","20.51223","0.00464"
"246.33600","20.52814","0.00470"
"246.52800","20.54422","0.00574"
"246.72000","20.56019","0.00583"
"246.91200","20.57615","0.00519"
"247.10400","20.59223","0.00551"
"247.29600","20.60820","0.00578"
"247.48800","20.62410","0.00620"
"247.68000","20.64018","0.00702"
"247.87200","20.65615","0.00693"
"248.06400","20.67211","0.00718"
"248.25600","20.68819","0.00744"
"248.44800","20.70416","0.00797"
"248.64000","20.72018","0.00817"
"248.83200","20.73627","0.00876"
"249.02400","20.75217","0.00923"
"249.21600","20.76819","0.00891"
"249.40800","20.78422","0.00885"
"249.60000","20.80012","0.01048"
"249.79200","20.81621","0.01002"
"249.98400","20.83217","0.00968"
"250.17600","20.84807","0.01042"
"250.36800","20.86421","0.01064"
"250.56000","20.88018","0.01089"
"250.75200","20.89614","0.01115"
"250.94400","20.91217","0.01187"
"251.13600","20.92825","0.01029"
"251.32800","20.94415","0.01022"
"251.52000","20.96018","0.01046"
"251.71200","20.97614","0.01110"
"251.90400","20.99223","0.01024"
"252.09600","21.00819","0.01023"
"252.28800","21.02415","0.01008"
"252.48000","21.04018","0.01076"
"252.67200","21.05620","0.01035"
"252.86400","21.07211","0.01117"
"253.05600","21.08819","0.01097"
"253.24800","21.10421","0.01058"
"253.44000","21.12017","0.01025"
"253.63200","21.13620","0.00854"
"253.82400","21.15216","0.00841"
"254.01600","21.16818","0.00949"
"254.20800","21.18415","0.01001"
"254.40000","21.20017","0.01022"
"254.59200","21.21620","0.01013"
"254.78400","21.23216","0.01134"
"254.97600","21.24813","0.01243"
"255.16800","21.26421","0.01216"
"255.36000","21.28017","0.01247"
"255.55200","21.29614","0.01345"
"255.74400","21.31216","0.01400"
"255.93600","21.32818","0.01492"
"256.12800","21.34414","0.01509"
"256.32000","21.36017","0.01623"
"256.51200","21.37619","0.01664"
"256.70400","21.39215","0.01784"
"256.89600","21.40824","0.01772"
"257.08800","21.42414","0.01842"
"257.28000","21.44017","0.01913"
"257.47200","21.45625","0.01961"
"257.66400","21.47210","0.02075"
"257.85600","21.48818","0.02118"
"258.04800","21.50420","0.02185"
"258.24000","21.52011","0.02262"
"258.43200","21.53625","0.02395"
"258.62400","21.55221","0.02400"
"258.81600","21.56812","0.02471"
"259.00800","21.58426","0.02573"
"259.20000","21.60022","0.02590"
"259.39200","21.61619","0.02644"
"259.58400","21.63221","0.02673"
"259.77600","21.64818","0.02783"
"259.96800","21.66420","0.02803"
"260.16000","21.68022","0.02867"
"260.35200","21.69619","0.02971"
"260.54400","21.71215","0.02974"
"260.73600","21.72817","0.03036"
"260.92800","21.74414","0.03081"
"261.12000","21.76016","0.03148"
"261.31200","21.77624","0.03196"
"261.50400","21.79215","0.03219"
"261.69600","21.80817","0.03296"
"261.88800","21.82420","0.03332"
"262.08000","21.84016","0.03348"
"262.27200","21.85618","0.03467"
"262.46400","21.87215","0.03371"
"262.65600","21.88817","0.03468"
"262.84800","21.90413","0.03495"
"263.04000","21.92016","0.03559"
"263.23200","21.93624","0.03616"
"263.42400","21.95221","0.03641"
"263.61600","21.96811","0.03655"
"263.80800","21.98425","0.03685"
"264.00000","22.00022","0.03724"
"264.19200","22.01618","0.03733"
"264.38400","22.03221","0.03738"
"264.57600","22.04817","0.03769"
"264.76800","22.06419","0.03787"
"264.96000","22.08015","0.03788"
"265.15200","22.09612","0.03821"
"265.34400","22.11220","0.03860"
"265.53600","22.12817","0.03813"
"265.72800","22.14413","0.03805"
"265.92000","22.16021","0.03837"
"266.11200","22.17624","0.03863"
"266.30400","22.19214","0.03905"
"266.49600","22.20823","0.03915"
"266.68800","22.22419","0.03933"
"266.88000","22.24015","0.03978"
"267.07200","22.25617","0.04028"
"267.26400","22.27220","0.04013"
"267.45600","22.28811","0.04067"
"267.64800","22.30412","0.04095"
"267.84000","22.32015","0.04129"
"268.03200","22.33617","0.04175"
"268.22400","22.35220","0.04185"
"268.41600","22.36816","0.04187"
"268.60800","22.38419","0.04249"
"268.80000","22.40021","0.04302"
"268.99200","22.41617","0.03687"
"269.18400","22.43220","0.03669"
"269.37600","22.44816","0.03766"
"269.56800","22.46412","0.03880"
"269.76000","22.48021","0.03849"
"269.95200","22.49617","0.03841"
"270.14400","22.51213","0.03910"
"270.33600","22.52822","0.03955"
"270.52800","22.54418","0.03948"
"270.72000","22.56015","0.04007"
"270.91200","22.57617","0.04070"
"271.10400","22.59213","0.04033"
"271.29600","22.60822","0.04076"
"271.48800","22.62424","0.04169"
"271.68000","22.64014","0.04125"
"271.87200","22.65623","0.04178"
"272.06400","22.67219","0.04250"
"272.25600","22.68810","0.04250"
"272.44800","22.70418","0.04278"
"272.64000","22.72020","0.04378"
"272.83200","22.73617","0.04396"
"273.02400","22.75219","0.04391"
"273.21600","22.76815","0.04519"
"273.40800","22.78418","0.04517"
"273.60000","22.80020","0.04516"
"273.79200","22.81616","0.04663"
"273.98400","22.83219","0.04667"
"274.17600","22.84821","0.04681"
"274.36800","22.86418","0.04804"
"274.56000","22.88020","0.04839"
"274.75200","22.89622","0.04885"
"274.94400","22.91213","0.04983"
"275.13600","22.92815","0.05068"
"275.32800","22.94417","0.05082"
"275.52000","22.96014","0.05239"
"275.71200","22.97616","0.05264"
"275.90400","22.99212","0.05265"
"276.09600","23.00821","0.05365"
"276.28800","23.02417","0.05454"
"276.48000","23.04020","0.05484"
"276.67200","23.05622","0.05573"
"276.86400","23.07224","0.05670"
"277.05600","23.08815","0.05720"
"277.24800","23.10429","0.05833"
"277.44000","23.12013","0.05894"
"277.63200","23.13610","0.05955"
"277.82400","23.15224","0.06073"
"278.01600","23.16809","0.06124"
"278.20800","23.18411","0.06108"
"278.40000","23.20019","0.06247"
"278.59200","23.21609","0.06257"
"278.78400","23.23218","0.06309"
"278.97600","23.24821","0.06453"
"279.16800","23.26417","0.06440"
"279.36000","23.28019","0.06540"
"279.55200","23.29622","0.06672"
"279.74400","23.31212","0.06680"
"279.93600","23.32820","0.06777"
"280.12800","23.34423","0.06891"
"280.32000","23.36013","0.06926"
"280.51200","23.37621","0.07046"
"280.70400","23.39218","0.06884"
"280.89600","23.40814","0.06921"
"281.08800","23.42416","0.07066"
"281.28000","23.44019","0.07098"
"281.47200","23.45615","0.07169"
"281.66400","23.47223","0.07254"
"281.85600","23.48814","0.07294"
"282.04800","23.50416","0.07363"
"282.24000","23.52024","0.02778"
"282.43200","23.53615","-0.00642"
"282.62400","23.55217","0.00860"
"282.81600","23.56820","0.00109"
"283.00800","23.58410","-0.00349"
"283.20000","23.60018","0.00092"
"283.39200","23.61621","0.00023"
"283.58400","23.63217","-0.00018"
"283.77600","23.64814","-0.00074"
"283.96800","23.66416","-0.00139"
"284.16000","23.68018","-0.00089"
"284.35200","23.69621","0.00027"
"284.54400","23.71217","0.00202"
"284.73600","23.72813","-0.00053"
"284.92800","23.74416","-0.00049"
"285.12000","23.76018","-0.00094"
"285.31200","23.77620","0.00168"
"285.50400","23.79217","0.00015"
"285.69600","23.80813","-0.00003"
"285.88800","23.82422","-0.00017"
"286.08000","23.84012","0.00107"
"286.26600","23.85566","0.00064"