File: Force_trajectories/170226_1/Specimen_RawData_10.csv
End date,"2/26/2017"
Specimen label,"2BG_13"
Maximum Load,"0.69358",N

Time,Extension,Load
(s),(mm),(N)
"0.00000","0.00000","-0.00393"
"0.31200","0.02565","-0.00300"
"0.62400","0.05220","-0.00137"
"0.93600","0.07826","-0.00018"
"1.24800","0.10415","0.00081"
"1.56000","0.13022","0.00146"
"1.87200","0.15617","0.00227"
"2.18400","0.18218","0.00281"
"2.49600","0.20819","0.00325"
"2.80800","0.23414","0.00414"
"3.12000","0.26026","0.00534"
"3.43200","0.28615","0.00510"
"3.74400","0.31222","0.00613"
"4.05600","0.33817","0.00704"
"4.36800","0.36418","0.00715"
"4.68000","0.39025","0.00706"
"4.99200","0.41614","0.00821"
"5.30400","0.44220","0.00901"
"5.61600","0.46815","0.00896"
"5.92800","0.49416","0.00988"
"6.24000","0.52017","0.01081"
"6.55200","0.54618","0.01142"
"6.86400","0.57225","0.01168"
"7.17600","0.59813","0.01258"
"7.48800","0.62420","0.01292"
"7.80000","0.65021","0.01328"
"8.11200","0.67616","0.01260"
"8.42400","0.70223","0.01322"
"8.73600","0.72812","0.01378"
"9.04800","0.75419","0.01456"
"9.36000","0.78013","0.01504"
"9.67200","0.80620","0.01548"
"9.98400","0.83221","0.01598"
"10.29600","0.85822","0.01635"
"10.60800","0.88423","0.01669"
"10.92000","0.91012","0.01738"
"11.23200","0.93618","0.01789"
"11.54400","0.96213","0.01842"
"11.85600","0.98826","0.01869"
"12.16800","1.01427","0.01910"
"12.48000","1.04016","0.01955"
"12.79200","1.06617","0.01985"
"13.10400","1.09212","0.02015"
"13.41600","1.11818","0.02114"
"13.72800","1.14419","0.02171"
"14.04000","1.17020","0.02146"
"14.35200","1.19621","0.02207"
"14.66400","1.22222","0.02242"
"14.97600","1.24817","0.02302"
"15.28800","1.27417","0.02272"
"15.60000","1.30018","0.02326"
"15.91200","1.32619","0.02412"
"16.22400","1.35214","0.02406"
"16.53600","1.37821","0.02397"
"16.84800","1.40416","0.02518"
"17.16000","1.43023","0.02519"
"17.47200","1.45623","0.02486"
"17.78400","1.48224","0.02605"
"18.09600","1.50819","0.02614"
"18.40800","1.53414","0.02626"
"18.72000","1.56021","0.02574"
"19.03200","1.58622","0.02655"
"19.34400","1.61228","0.02758"
"19.65600","1.63817","0.02726"
"19.96800","1.66418","0.02716"
"20.28000","1.69019","0.02808"
"20.59200","1.71620","0.02813"
"20.90400","1.74221","0.02819"
"21.21600","1.76822","0.02864"
"21.52800","1.79422","0.02881"
"21.84000","1.82023","0.02915"
"22.15200","1.84624","0.02898"
"22.46400","1.87225","0.02943"
"22.77600","1.89820","0.02941"
"23.08800","1.92421","0.03008"
"23.40000","1.95016","0.03050"
"23.71200","1.97616","0.03011"
"24.02400","2.00217","0.03058"
"24.33600","2.02818","0.03100"
"24.64800","2.05425","0.03069"
"24.96000","2.08014","0.03149"
"25.27200","2.10621","0.03127"
"25.58400","2.13221","0.03172"
"25.89600","2.15816","0.03141"
"26.20800","2.18423","0.03127"
"26.52000","2.21018","0.03169"
"26.83200","2.23625","0.03203"
"27.14400","2.26214","0.03189"
"27.45600","2.28821","0.03183"
"27.76800","2.31421","0.03244"
"28.08000","2.34016","0.03234"
"28.39200","2.36623","0.03273"
"28.70400","2.39212","0.03242"
"29.01600","2.41825","0.03342"
"29.32800","2.44420","0.03344"
"29.64000","2.47020","0.03307"
"29.95200","2.49621","0.03355"
"30.26400","2.52216","0.03376"
"30.57600","2.54817","0.03329"
"30.88800","2.57412","0.03261"
"31.20000","2.60019","0.03232"
"31.51200","2.62620","0.03251"
"31.82400","2.65220","0.03301"
"32.13600","2.67827","0.03291"
"32.44800","2.70416","0.03339"
"32.76000","2.73017","0.03324"
"33.07200","2.75618","0.03337"
"33.38400","2.78225","0.03395"
"33.69600","2.80825","0.03399"
"34.00800","2.83414","0.03414"
"34.32000","2.86021","0.03383"
"34.63200","2.88610","0.03428"
"34.94400","2.91223","0.03471"
"35.25600","2.93824","0.03448"
"35.56800","2.96425","0.03463"
"35.88000","2.99025","0.03495"
"36.19200","3.01614","0.03507"
"36.50400","3.04215","0.03534"
"36.81600","3.06816","0.03537"
"37.12800","3.09423","0.03543"
"37.44000","3.12018","0.03589"
"37.75200","3.14618","0.03547"
"38.06400","3.17219","0.00672"
"38.37600","3.19814","0.00628"
"38.68800","3.22421","0.00637"
"39.00000","3.25022","0.00625"
"39.31200","3.27623","0.00662"
"39.62400","3.30218","0.00630"
"39.93600","3.32818","0.00702"
"40.24800","3.35419","0.00501"
"40.56000","3.38020","0.00486"
"40.87200","3.40621","0.00570"
"41.18400","3.43216","0.00672"
"41.49600","3.45811","0.00773"
"41.80800","3.48418","0.00766"
"42.12000","3.51012","0.00848"
"42.43200","3.53625","0.00872"
"42.74400","3.56220","0.00911"
"43.05600","3.58821","0.00902"
"43.36800","3.61422","0.00927"
"43.68000","3.64017","0.00948"
"43.99200","3.66623","0.01019"
"44.30400","3.69218","0.01004"
"44.61600","3.71819","0.01125"
"44.92800","3.74414","0.01167"
"45.24000","3.77021","0.01125"
"45.55200","3.79622","0.01151"
"45.86400","3.82217","0.01177"
"46.17600","3.84823","0.01206"
"46.48800","3.87418","0.01304"
"46.80000","3.90019","0.01259"
"47.11200","3.92614","0.01234"
"47.42400","3.95215","0.01327"
"47.73600","3.97828","0.01359"
"48.04800","4.00422","0.01368"
"48.36000","4.03023","0.01413"
"48.67200","4.05618","0.01463"
"48.98400","4.08219","0.01539"
"49.29600","4.10820","0.01516"
"49.60800","4.13421","0.01553"
"49.92000","4.16022","0.01588"
"50.23200","4.18616","0.01619"
"50.54400","4.21229","0.01620"
"50.85600","4.23818","0.01682"
"51.16800","4.26419","0.01649"
"51.48000","4.29026","0.01621"
"51.79200","4.31615","0.01623"
"52.10400","4.34221","0.01701"
"52.41600","4.36816","0.01738"
"52.72800","4.39423","0.01738"
"53.04000","4.42018","0.01699"
"53.35200","4.44619","0.01776"
"53.66400","4.47226","0.01793"
"53.97600","4.49815","0.01765"
"54.28800","4.52421","0.01814"
"54.60000","4.55016","0.01826"
"54.91200","4.57623","0.01861"
"55.22400","4.60224","0.01866"
"55.53600","4.62819","0.01922"
"55.84800","4.65420","0.01854"
"56.16000","4.68009","0.01795"
"56.47200","4.70621","0.01870"
"56.78400","4.73216","0.01862"
"57.09600","4.75823","0.01827"
"57.40800","4.78418","0.01820"
"57.72000","4.81019","0.01920"
"58.03200","4.83626","0.01952"
"58.34400","4.86214","0.01983"
"58.65600","4.88821","0.01922"
"58.96800","4.91422","0.01970"
"59.28000","4.94017","0.01990"
"59.59200","4.96612","0.01995"
"59.90400","4.99213","0.01925"
"60.21600","5.01826","0.02013"
"60.52800","5.04420","0.02020"
"60.84000","5.07021","0.02009"
"61.15200","5.09622","0.01994"
"61.46400","5.12217","0.02061"
"61.77600","5.14824","0.02053"
"62.08800","5.17419","0.02050"
"62.40000","5.20025","0.02042"
"62.71200","5.22620","0.02032"
"63.02400","5.25215","0.02149"
"63.33600","5.27822","0.02122"
"63.64800","5.30417","0.02099"
"63.96000","5.33024","0.02110"
"64.27200","5.35619","0.02132"
"64.58400","5.38219","0.02079"
"64.89600","5.40820","0.02050"
"65.20800","5.43421","0.02164"
"65.52000","5.46022","0.02224"
"65.83200","5.48611","0.02180"
"66.14400","5.51224","0.02188"
"66.45600","5.53818","0.02204"
"66.76800","5.56413","0.02220"
"67.08000","5.59020","0.02221"
"67.39200","5.61615","0.02219"
"67.70400","5.64222","0.02208"
"68.01600","5.66817","0.02262"
"68.32800","5.69424","0.02315"
"68.64000","5.72018","0.02288"
"68.95200","5.74613","0.02322"
"69.26400","5.77220","0.02364"
"69.57600","5.79815","0.02289"
"69.88800","5.82422","0.02351"
"70.20000","5.85011","0.02396"
"70.51200","5.87617","0.02413"
"70.82400","5.90218","0.02384"
"71.13600","5.92819","0.02422"
"71.44800","5.95420","0.02460"
"71.76000","5.98015","0.02436"
"72.07200","6.00622","0.02472"
"72.38400","6.03217","0.02528"
"72.69600","6.05823","0.02510"
"73.00800","6.08424","0.02407"
"73.32000","6.11013","0.02442"
"73.63200","6.13620","0.02507"
"73.94400","6.16215","0.02542"
"74.25600","6.18816","0.02568"
"74.56800","6.21422","0.02554"
"74.88000","6.24017","0.02514"
"75.19200","6.26624","0.02556"
"75.50400","6.29219","0.02540"
"75.81600","6.31820","0.02533"
"76.12800","6.34421","0.02577"
"76.44000","6.37028","0.02572"
"76.75200","6.39622","0.02635"
"77.06400","6.42217","0.02639"
"77.37600","6.44824","0.02608"
"77.68800","6.47413","0.02629"
"78.00000","6.50026","0.02639"
"78.31200","6.52627","0.02655"
"78.62400","6.55222","0.02636"
"78.93600","6.57822","0.02708"
"79.24800","6.60417","0.02729"
"79.56000","6.63018","0.02726"
"79.87200","6.65619","0.02709"
"80.18400","6.68226","0.02753"
"80.49600","6.70815","0.02781"
"80.80800","6.73416","0.02725"
"81.12000","6.76022","0.02738"
"81.43200","6.78617","0.02741"
"81.74400","6.81224","0.02692"
"82.05600","6.83819","0.02737"
"82.36800","6.86420","0.02682"
"82.68000","6.89021","0.02765"
"82.99200","6.91615","0.02651"
"83.30400","6.94216","0.02684"
"83.61600","6.96823","0.02707"
"83.92800","6.99424","0.02765"
"84.24000","7.02019","0.02829"
"84.55200","7.04614","0.02799"
"84.86400","7.07221","0.02770"
"85.17600","7.09815","0.02807"
"85.48800","7.12422","0.02662"
"85.80000","7.15023","0.02707"
"86.11200","7.17618","0.02746"
"86.42400","7.20219","0.02644"
"86.73600","7.22820","0.02683"
"87.04800","7.25426","0.02479"
"87.36000","7.28015","0.02508"
"87.67200","7.30622","0.02568"
"87.98400","7.33217","0.02553"
"88.29600","7.35818","0.02637"
"88.60800","7.38419","0.02591"
"88.92000","7.41014","0.02626"
"89.23200","7.43620","0.02627"
"89.54400","7.46215","0.02670"
"89.85600","7.48822","0.02660"
"90.16800","7.51417","0.02617"
"90.48000","7.54018","0.02616"
"90.79200","7.56619","0.02658"
"91.10400","7.59220","0.02628"
"91.41600","7.61820","0.02664"
"91.72800","7.64415","0.02693"
"92.04000","7.67016","0.02716"
"92.35200","7.69623","0.02715"
"92.66400","7.72218","0.02681"
"92.97600","7.74819","0.02654"
"93.28800","7.77413","0.02683"
"93.60000","7.80020","0.02515"
"93.91200","7.82621","0.02517"
"94.22400","7.85222","0.02560"
"94.53600","7.87823","0.02613"
"94.84800","7.90412","0.02595"
"95.16000","7.93018","0.02703"
"95.47200","7.95613","0.02710"
"95.78400","7.98220","0.02602"
"96.09600","8.00821","0.02621"
"96.40800","8.03416","0.02664"
"96.72000","8.06017","0.02688"
"97.03200","8.08612","0.02698"
"97.34400","8.11218","0.02695"
"97.65600","8.13819","0.02625"
"97.96800","8.16420","0.02620"
"98.28000","8.19021","0.02580"
"98.59200","8.21622","0.02538"
"98.90400","8.24217","0.02625"
"99.21600","8.26812","0.02529"
"99.52800","8.29424","0.02532"
"99.84000","8.32025","0.02489"
"100.15200","8.34620","0.02511"
"100.46400","8.37221","0.02494"
"100.77600","8.39816","0.02563"
"101.08800","8.42417","0.02551"
"101.40000","8.45017","0.02556"
"101.71200","8.47618","0.02617"
"102.02400","8.50219","0.02476"
"102.33600","8.52814","0.02506"
"102.64800","8.55421","0.02521"
"102.96000","8.58016","0.02537"
"103.27200","8.60623","0.02577"
"103.58400","8.63217","0.02552"
"103.89600","8.65824","0.02586"
"104.20800","8.68425","0.02592"
"104.52000","8.71020","0.02625"
"104.83200","8.73621","0.02599"
"105.14400","8.76216","0.02634"
"105.45600","8.78822","0.02602"
"105.76800","8.81417","0.02693"
"106.08000","8.84018","0.02617"
"106.39200","8.86625","0.02665"
"106.70400","8.89220","0.02710"
"107.01600","8.91827","0.02650"
"107.32800","8.94416","0.02674"
"107.64000","8.97016","0.02679"
"107.95200","8.99623","0.02700"
"108.26400","9.02218","0.02652"
"108.57600","9.04825","0.02645"
"108.88800","9.07420","0.02717"
"109.20000","9.10021","0.02663"
"109.51200","9.12621","0.02656"
"109.82400","9.15222","0.02678"
"110.13600","9.17817","0.02675"
"110.44800","9.20418","0.02741"
"110.76000","9.23025","0.02718"
"111.07200","9.25620","0.02736"
"111.38400","9.28221","0.02746"
"111.69600","9.30821","0.02727"
"112.00800","9.33416","0.02764"
"112.32000","9.36029","0.02757"
"112.63200","9.38618","0.02779"
"112.94400","9.41225","0.02808"
"113.25600","9.43814","0.02833"
"113.56800","9.46414","0.02776"
"113.88000","9.49021","0.02856"
"114.19200","9.51622","0.02849"
"114.50400","9.54223","0.02854"
"114.81600","9.56812","0.02845"
"115.12800","9.59425","0.02834"
"115.44000","9.62014","0.02847"
"115.75200","9.64620","0.02891"
"116.06400","9.67221","0.02926"
"116.37600","9.69816","0.02884"
"116.68800","9.72417","0.02890"
"117.00000","9.75012","0.02924"
"117.31200","9.77619","0.02920"
"117.62400","9.80219","0.02924"
"117.93600","9.82820","0.02923"
"118.24800","9.85421","0.02911"
"118.56000","9.88010","0.02953"
"118.87200","9.90617","0.02909"
"119.18400","9.93218","0.02882"
"119.49600","9.95825","0.02861"
"119.80800","9.98425","0.02903"
"120.12000","10.01020","0.02929"
"120.43200","10.03615","0.02884"
"120.74400","10.06210","0.02882"
"121.05600","10.08823","0.02875"
"121.36800","10.11418","0.02893"
"121.68000","10.14024","0.02878"
"121.99200","10.16625","0.02874"
"122.30400","10.19220","0.02890"
"122.61600","10.21821","0.02943"
"122.92800","10.24416","0.02926"
"123.24000","10.27023","0.02988"
"123.55200","10.29618","0.03003"
"123.86400","10.32218","0.03010"
"124.17600","10.34819","0.03054"
"124.48800","10.37414","0.03027"
"124.80000","10.40027","0.03053"
"125.11200","10.42616","0.03051"
"125.42400","10.45217","0.03037"
"125.73600","10.47818","0.03108"
"126.04800","10.50418","0.03104"
"126.36000","10.53019","0.03104"
"126.67200","10.55614","0.03072"
"126.98400","10.58221","0.01336"
"127.29600","10.60822","0.01402"
"127.60800","10.63411","0.01471"
"127.92000","10.66023","0.01492"
"128.23200","10.68618","0.01605"
"128.54400","10.71225","0.01651"
"128.85600","10.73820","0.01668"
"129.16800","10.76415","0.01744"
"129.48000","10.79022","0.01761"
"129.79200","10.81617","0.01684"
"130.10400","10.84223","0.01773"
"130.41600","10.86812","0.01756"
"130.72800","10.89425","0.01867"
"131.04000","10.92014","0.01809"
"131.35200","10.94615","0.01835"
"131.66400","10.97222","0.01940"
"131.97600","10.99817","0.01907"
"132.28800","11.02423","0.01962"
"132.60000","11.05018","0.02023"
"132.91200","11.07619","0.02003"
"133.22400","11.10220","0.02073"
"133.53600","11.12815","0.01979"
"133.84800","11.15422","0.02105"
"134.16000","11.18016","0.01959"
"134.47200","11.20623","0.01896"
"134.78400","11.23218","0.01932"
"135.09600","11.25819","0.01986"
"135.40800","11.28420","0.02030"
"135.72000","11.31021","0.02030"
"136.03200","11.33622","0.02028"
"136.34400","11.36210","0.02147"
"136.65600","11.38823","0.02251"
"136.96800","11.41424","0.02176"
"137.28000","11.44025","0.02178"
"137.59200","11.46626","0.02235"
"137.90400","11.49215","0.02258"
"138.21600","11.51822","0.02335"
"138.52800","11.54416","0.02378"
"138.84000","11.57023","0.02344"
"139.15200","11.59624","0.02294"
"139.46400","11.62219","0.02393"
"139.77600","11.64820","0.02226"
"140.08800","11.67415","0.02330"
"140.40000","11.70021","0.02360"
"140.71200","11.72616","0.02380"
"141.02400","11.75223","0.02448"
"141.33600","11.77824","0.02479"
"141.64800","11.80419","0.02451"
"141.96000","11.83020","0.02535"
"142.27200","11.85609","0.02513"
"142.58400","11.88221","0.02544"
"142.89600","11.90822","0.02605"
"143.20800","11.93417","0.02629"
"143.52000","11.96024","0.02673"
"143.83200","11.98613","0.02650"
"144.14400","12.01219","0.02694"
"144.45600","12.03821","0.02708"
"144.76800","12.06421","0.02784"
"145.08000","12.09022","0.02746"
"145.39200","12.11617","0.02841"
"145.70400","12.14224","0.02825"
"146.01600","12.16813","0.02815"
"146.32800","12.19425","0.02882"
"146.64000","12.22020","0.02851"
"146.95200","12.24621","0.02879"
"147.26400","12.27222","0.02964"
"147.57600","12.29817","0.02922"
"147.88800","12.32424","0.02964"
"148.20000","12.35018","0.02995"
"148.51200","12.37619","0.03015"
"148.82400","12.40220","0.02953"
"149.13600","12.42815","0.02996"
"149.44800","12.45422","0.02954"
"149.76000","12.48017","0.02976"
"150.07200","12.50624","0.03006"
"150.38400","12.53218","0.03040"
"150.69600","12.55819","0.03054"
"151.00800","12.58420","0.02943"
"151.32000","12.61015","0.02967"
"151.63200","12.63622","0.03114"
"151.94400","12.66217","0.03090"
"152.25600","12.68818","0.03122"
"152.56800","12.71418","0.03166"
"152.88000","12.74013","0.03166"
"153.19200","12.76620","0.03185"
"153.50400","12.79215","0.03207"
"153.81600","12.81816","0.03238"
"154.12800","12.84417","0.03257"
"154.44000","12.87017","0.03245"
"154.75200","12.89618","0.03265"
"155.06400","12.92219","0.03272"
"155.37600","12.94826","0.03335"
"155.68800","12.97415","0.03329"
"156.00000","13.00022","0.03309"
"156.31200","13.02617","0.03296"
"156.62400","13.05217","0.03327"
"156.93600","13.07824","0.03390"
"157.24800","13.10419","0.03391"
"157.56000","13.13026","0.03410"
"157.87200","13.15609","0.03414"
"158.18400","13.18222","0.03432"
"158.49600","13.20823","0.03464"
"158.80800","13.23417","0.03458"
"159.12000","13.26018","0.03540"
"159.43200","13.28613","0.03548"
"159.74400","13.31220","0.03570"
"160.05600","13.33815","0.03587"
"160.36800","13.36422","0.03493"
"160.68000","13.39023","0.03533"
"160.99200","13.41617","0.03534"
"161.30400","13.44218","0.03597"
"161.61600","13.46813","0.03604"
"161.92800","13.49420","0.03585"
"162.24000","13.52021","0.03603"
"162.55200","13.54622","0.03669"
"162.86400","13.57222","0.03714"
"163.17600","13.59817","0.03759"
"163.48800","13.62412","0.03780"
"163.80000","13.65013","0.03798"
"164.11200","13.67626","0.03822"
"164.42400","13.70227","0.03848"
"164.73600","13.72822","0.03877"
"165.04800","13.75422","0.03893"
"165.36000","13.78017","0.03921"
"165.67200","13.80618","0.03744"
"165.98400","13.83219","0.03482"
"166.29600","13.85820","0.03487"
"166.60800","13.88421","0.03459"
"166.92000","13.91022","0.03535"
"167.23200","13.93622","0.03538"
"167.54400","13.96217","0.03532"
"167.85600","13.98824","0.03613"
"168.16800","14.01419","0.03662"
"168.48000","14.04020","0.03664"
"168.79200","14.06621","0.03673"
"169.10400","14.09215","0.03719"
"169.41600","14.11822","0.03718"
"169.72800","14.14417","0.03687"
"170.04000","14.17018","0.03718"
"170.35200","14.19625","0.03742"
"170.66400","14.22220","0.03778"
"170.97600","14.24821","0.03735"
"171.28800","14.27415","0.03774"
"171.60000","14.30022","0.03795"
"171.91200","14.32617","0.03851"
"172.22400","14.35218","0.03860"
"172.53600","14.37825","0.03883"
"172.84800","14.40420","0.03933"
"173.16000","14.43026","0.03944"
"173.47200","14.45609","0.03994"
"173.78400","14.48222","0.04039"
"174.09600","14.50817","0.03999"
"174.40800","14.53418","0.04121"
"174.72000","14.56025","0.04095"
"175.03200","14.58619","0.04150"
"175.34400","14.61220","0.04152"
"175.65600","14.63815","0.04201"
"175.96800","14.66422","0.04181"
"176.28000","14.69017","0.04204"
"176.59200","14.71618","0.04336"
"176.90400","14.74224","0.04312"
"177.21600","14.76814","0.04318"
"177.52800","14.79420","0.04369"
"177.84000","14.82021","0.04282"
"178.15200","14.84622","0.04272"
"178.46400","14.87229","0.03420"
"178.77600","14.89818","0.03419"
"179.08800","14.92418","0.03399"
"179.40000","14.95014","0.03396"
"179.71200","14.97620","0.03439"
"180.02400","15.00221","0.03479"
"180.33600","15.02822","0.03477"
"180.64800","15.05423","0.03464"
"180.96000","15.08012","0.03438"
"181.27200","15.10618","0.03466"
"181.58400","15.13219","0.03492"
"181.89600","15.15820","0.03539"
"182.20800","15.18421","0.03579"
"182.52000","15.21016","0.03587"
"182.83200","15.23617","0.03641"
"183.14400","15.26212","0.03669"
"183.45600","15.28818","0.03663"
"183.76800","15.31419","0.03706"
"184.08000","15.34026","0.03712"
"184.39200","15.36621","0.03745"
"184.70400","15.39216","0.03759"
"185.01600","15.41817","0.03756"
"185.32800","15.44417","0.03801"
"185.64000","15.47024","0.03800"
"185.95200","15.49619","0.03852"
"186.26400","15.52220","0.03898"
"186.57600","15.54821","0.03912"
"186.88800","15.57416","0.03961"
"187.20000","15.60017","0.03949"
"187.51200","15.62617","0.04024"
"187.82400","15.65218","0.04063"
"188.13600","15.67819","0.04082"
"188.44800","15.70414","0.04091"
"188.76000","15.73021","0.04148"
"189.07200","15.75616","0.04175"
"189.38400","15.78222","0.04170"
"189.69600","15.80817","0.04136"
"190.00800","15.83418","0.04170"
"190.32000","15.86025","0.04170"
"190.63200","15.88614","0.04196"
"190.94400","15.91221","0.04248"
"191.25600","15.93816","0.04304"
"191.56800","15.96422","0.04382"
"191.88000","15.99017","0.04419"
"192.19200","16.01618","0.04484"
"192.50400","16.04225","0.04493"
"192.81600","16.06820","0.04444"
"193.12800","16.09426","0.04432"
"193.44000","16.12021","0.04521"
"193.75200","16.14622","0.04617"
"194.06400","16.17223","0.04533"
"194.37600","16.19818","0.04631"
"194.68800","16.22425","0.04669"
"195.00000","16.25014","0.04797"
"195.31200","16.27621","0.04835"
"195.62400","16.30221","0.04878"
"195.93600","16.32816","0.04895"
"196.24800","16.35423","0.04998"
"196.56000","16.38018","0.05126"
"196.87200","16.40619","0.05159"
"197.18400","16.43220","0.05252"
"197.49600","16.45820","0.05377"
"197.80800","16.48421","0.05323"
"198.12000","16.51016","0.05454"
"198.43200","16.53623","0.05566"
"198.74400","16.56218","0.05671"
"199.05600","16.58825","0.05767"
"199.36800","16.61414","0.05852"
"199.68000","16.64021","0.05812"
"199.99200","16.66621","0.05925"
"200.30400","16.69216","0.06080"
"200.61600","16.71817","0.06171"
"200.92800","16.74412","0.06304"
"201.24000","16.77024","0.06352"
"201.55200","16.79620","0.06498"
"201.86400","16.82220","0.06578"
"202.17600","16.84821","0.06627"
"202.48800","16.87416","0.06706"
"202.80000","16.90023","0.06775"
"203.11200","16.92618","0.06899"
"203.42400","16.95225","0.06977"
"203.73600","16.97820","0.07086"
"204.04800","17.00420","0.07168"
"204.36000","17.03021","0.07290"
"204.67200","17.05610","0.07408"
"204.98400","17.08217","0.07462"
"205.29600","17.10824","0.07504"
"205.60800","17.13424","0.07611"
"205.92000","17.16025","0.07482"
"206.23200","17.18620","0.07566"
"206.54400","17.21221","0.07577"
"206.85600","17.23816","0.07757"
"207.16800","17.26423","0.07801"
"207.48000","17.29024","0.07915"
"207.79200","17.31618","0.07974"
"208.10400","17.34225","0.08050"
"208.41600","17.36814","0.08092"
"208.72800","17.39427","0.08154"
"209.04000","17.42022","0.08237"
"209.35200","17.44617","0.08305"
"209.66400","17.47218","0.08367"
"209.97600","17.49813","0.08474"
"210.28800","17.52419","0.08551"
"210.60000","17.55014","0.08639"
"210.91200","17.57627","0.08748"
"211.22400","17.60222","0.08872"
"211.53600","17.62823","0.08993"
"211.84800","17.65417","0.09110"
"212.16000","17.68018","0.09213"
"212.47200","17.70625","0.09360"
"212.78400","17.73220","0.09487"
"213.09600","17.75815","0.09628"
"213.40800","17.78422","0.09741"
"213.72000","17.81017","0.09919"
"214.03200","17.83623","0.10135"
"214.34400","17.86218","0.10331"
"214.65600","17.88825","0.10430"
"214.96800","17.91420","0.10593"
"215.28000","17.94021","0.10788"
"215.59200","17.96622","0.10955"
"215.90400","17.99216","0.11090"
"216.21600","18.01823","0.11251"
"216.52800","18.04412","0.11378"
"216.84000","18.07019","0.11477"
"217.15200","18.09614","0.11646"
"217.46400","18.12215","0.11730"
"217.77600","18.14822","0.11890"
"218.08800","18.17416","0.11934"
"218.40000","18.20023","0.12100"
"218.71200","18.22618","0.12105"
"219.02400","18.25219","0.12188"
"219.33600","18.27820","0.12211"
"219.64800","18.30415","0.11792"
"219.96000","18.33022","0.11865"
"220.27200","18.35616","0.11974"
"220.58400","18.38217","0.12045"
"220.89600","18.40812","0.12167"
"221.20800","18.43425","0.12208"
"221.52000","18.46026","0.12275"
"221.83200","18.48615","0.12272"
"222.14400","18.51221","0.12282"
"222.45600","18.53811","0.12341"
"222.76800","18.56423","0.12390"
"223.08000","18.59024","0.12480"
"223.39200","18.61619","0.12532"
"223.70400","18.64226","0.12630"
"224.01600","18.66814","0.12708"
"224.32800","18.69421","0.12705"
"224.64000","18.72016","0.12798"
"224.95200","18.74623","0.12862"
"225.26400","18.77224","0.12948"
"225.57600","18.79813","0.13002"
"225.88800","18.82420","0.13085"
"226.20000","18.85015","0.13208"
"226.51200","18.87621","0.13278"
"226.82400","18.90222","0.13423"
"227.13600","18.92823","0.13508"
"227.44800","18.95424","0.13651"
"227.76000","18.98019","0.13839"
"228.07200","19.00620","0.14024"
"228.38400","19.03214","0.14255"
"228.69600","19.05827","0.14442"
"229.00800","19.08422","0.14685"
"229.32000","19.11017","0.15004"
"229.63200","19.13624","0.15337"
"229.94400","19.16213","0.15585"
"230.25600","19.18820","0.15908"
"230.56800","19.21420","0.16262"
"230.88000","19.24015","0.16515"
"231.19200","19.26622","0.16891"
"231.50400","19.29217","0.17244"
"231.81600","19.31818","0.17689"
"232.12800","19.34419","0.17982"
"232.44000","19.37020","0.18307"
"232.75200","19.39620","0.18528"
"233.06400","19.42215","0.18716"
"233.37600","19.44822","0.18861"
"233.68800","19.47417","0.18944"
"234.00000","19.50024","0.19062"
"234.31200","19.52625","0.19276"
"234.62400","19.55225","0.19406"
"234.93600","19.57826","0.19618"
"235.24800","19.60415","0.19800"
"235.56000","19.63022","0.19986"
"235.87200","19.65617","0.20196"
"236.18400","19.68224","0.20477"
"236.49600","19.70819","0.20727"
"236.80800","19.73419","0.20995"
"237.12000","19.76026","0.21218"
"237.43200","19.78621","0.21424"
"237.74400","19.81222","0.21686"
"238.05600","19.83811","0.21910"
"238.36800","19.86418","0.22198"
"238.68000","19.89018","0.22360"
"238.99200","19.91619","0.22609"
"239.30400","19.94226","0.22718"
"239.61600","19.96821","0.22944"
"239.92800","19.99422","0.23084"
"240.24000","20.02022","0.23225"
"240.55200","20.04618","0.23333"
"240.86400","20.07224","0.23459"
"241.17600","20.09819","0.23532"
"241.48800","20.12426","0.23681"
"241.80000","20.15015","0.23790"
"242.11200","20.17622","0.23907"
"242.42400","20.20217","0.24047"
"242.73600","20.22817","0.24214"
"243.04800","20.25418","0.24367"
"243.36000","20.28013","0.24601"
"243.67200","20.30620","0.24814"
"243.98400","20.33215","0.25035"
"244.29600","20.35822","0.25252"
"244.60800","20.38423","0.22438"
"244.92000","20.41023","0.22526"
"245.23200","20.43618","0.22607"
"245.54400","20.46213","0.22720"
"245.85600","20.48814","0.22851"
"246.16800","20.51415","0.22932"
"246.48000","20.54022","0.23064"
"246.79200","20.56617","0.23133"
"247.10400","20.59217","0.23177"
"247.41600","20.61818","0.23290"
"247.72800","20.64413","0.23372"
"248.04000","20.67020","0.23451"
"248.35200","20.69615","0.23528"
"248.66400","20.72222","0.23603"
"248.97600","20.74822","0.23671"
"249.28800","20.77417","0.23731"
"249.60000","20.80018","0.23759"
"249.91200","20.82619","0.23854"
"250.22400","20.85226","0.23964"
"250.53600","20.87820","0.24066"
"250.84800","20.90415","0.24181"
"251.16000","20.93016","0.24290"
"251.47200","20.95617","0.24390"
"251.78400","20.98224","0.24556"
"252.09600","21.00819","0.24654"
"252.40800","21.03420","0.24857"
"252.72000","21.06020","0.25004"
"253.03200","21.08615","0.25178"
"253.34400","21.11222","0.25375"
"253.65600","21.13817","0.25521"
"253.96800","21.16424","0.25696"
"254.28000","21.19019","0.25911"
"254.59200","21.21620","0.26035"
"254.90400","21.24220","0.26318"
"255.21600","21.26815","0.26411"
"255.52800","21.29422","0.26595"
"255.84000","21.32017","0.26751"
"256.15200","21.34618","0.26961"
"256.46400","21.37219","0.27064"
"256.77600","21.39813","0.27284"
"257.08800","21.42426","0.27465"
"257.40000","21.45015","0.26687"
"257.71200","21.47622","0.26888"
"258.02400","21.50223","0.27051"
"258.33600","21.52812","0.27261"
"258.64800","21.55419","0.27416"
"258.96000","21.58019","0.27572"
"259.27200","21.60620","0.27756"
"259.58400","21.63215","0.27964"
"259.89600","21.65822","0.28131"
"260.20800","21.68417","0.28293"
"260.52000","21.71018","0.28456"
"260.83200","21.73625","0.28603"
"261.14400","21.76213","0.28803"
"261.45600","21.78820","0.28933"
"261.76800","21.81415","0.29246"
"262.08000","21.84022","0.29591"
"262.39200","21.86623","0.29859"
"262.70400","21.89218","0.30205"
"263.01600","21.91825","0.30562"
"263.32800","21.94413","0.30890"
"263.64000","21.97020","0.31133"
"263.95200","21.99615","0.31530"
"264.26400","22.02222","0.31812"
"264.57600","22.04829","0.32151"
"264.88800","22.07417","0.32411"
"265.20000","22.10018","0.32718"
"265.51200","22.12613","0.32959"
"265.82400","22.15220","0.33212"
"266.13600","22.17827","0.33376"
"266.44800","22.20422","0.33547"
"266.76000","22.23022","0.33726"
"267.07200","22.25617","0.33860"
"267.38400","22.28224","0.34015"
"267.69600","22.30819","0.34108"
"268.00800","22.33426","0.34151"
"268.32000","22.36027","0.34229"
"268.63200","22.38616","0.34263"
"268.94400","22.41217","0.34300"
"269.25600","22.43811","0.34331"
"269.56800","22.46424","0.34375"
"269.88000","22.49019","0.34413"
"270.19200","22.51620","0.34441"
"270.50400","22.54221","0.34544"
"270.81600","22.56816","0.34583"
"271.12800","22.59417","0.34588"
"271.44000","22.62017","0.34746"
"271.75200","22.64624","0.34640"
"272.06400","22.67219","0.34741"
"272.37600","22.69820","0.34854"
"272.68800","22.72427","0.34952"
"273.00000","22.75016","0.35065"
"273.31200","22.77622","0.35132"
"273.62400","22.80217","0.35307"
"273.93600","22.82812","0.35422"
"274.24800","22.85419","0.35601"
"274.56000","22.88014","0.35785"
"274.87200","22.90621","0.35985"
"275.18400","22.93216","0.36188"
"275.49600","22.95822","0.36491"
"275.80800","22.98417","0.36692"
"276.12000","23.01018","0.36926"
"276.43200","23.03625","0.37243"
"276.74400","23.06214","0.37331"
"277.05600","23.08821","0.37582"
"277.36800","23.11422","0.37883"
"277.68000","23.14022","0.38130"
"277.99200","23.16617","0.38337"
"278.30400","23.19218","0.38415"
"278.61600","23.21819","0.38658"
"278.92800","23.24414","0.38795"
"279.24000","23.27020","0.38897"
"279.55200","23.29616","0.39068"
"279.86400","23.32216","0.39157"
"280.17600","23.34823","0.39266"
"280.48800","23.37418","0.39409"
"280.80000","23.40019","0.39589"
"281.11200","23.42614","0.39703"
"281.42400","23.45220","0.39906"
"281.73600","23.47821","0.40069"
"282.04800","23.50416","0.40255"
"282.36000","23.53023","0.40508"
"282.67200","23.55618","0.40109"
"282.98400","23.58219","0.40181"
"283.29600","23.60814","0.40343"
"283.60800","23.63420","0.40567"
"283.92000","23.66021","0.40863"
"284.23200","23.68616","0.41198"
"284.54400","23.71223","0.41425"
"284.85600","23.73812","0.41673"
"285.16800","23.76418","0.41880"
"285.48000","23.79020","0.42079"
"285.79200","23.81621","0.42222"
"286.10400","23.84227","0.42434"
"286.41600","23.86816","0.42560"
"286.72800","23.89423","0.42717"
"287.04000","23.92012","0.42854"
"287.35200","23.94618","0.42989"
"287.66400","23.97220","0.43117"
"287.97600","23.99821","0.43279"
"288.28800","24.02421","0.43417"
"288.60000","24.05010","0.43581"
"288.91200","24.07617","0.43745"
"289.22400","24.10218","0.43882"
"289.53600","24.12819","0.44014"
"289.84800","24.15420","0.33375"
"290.16000","24.18020","0.33990"
"290.47200","24.20621","0.34230"
"290.78400","24.23210","0.34175"
"291.09600","24.25823","0.34328"
"291.40800","24.28418","0.34473"
"291.72000","24.31018","0.34453"
"292.03200","24.33625","0.34428"
"292.34400","24.36214","0.34526"
"292.65600","24.38821","0.34686"
"292.96800","24.41422","0.34688"
"293.28000","24.44029","0.34744"
"293.59200","24.46624","0.35103"
"293.90400","24.49218","0.35295"
"294.21600","24.51825","0.35296"
"294.52800","24.54414","0.35231"
"294.84000","24.57027","0.35356"
"295.15200","24.59616","0.35622"
"295.46400","24.62223","0.35766"
"295.77600","24.64823","0.35869"
"296.08800","24.67418","0.36216"
"296.40000","24.70019","0.36681"
"296.71200","24.72620","0.37095"
"297.02400","24.75221","0.37114"
"297.33600","24.77816","0.37185"
"297.64800","24.80416","0.37437"
"297.96000","24.83023","0.37614"
"298.27200","24.85618","0.37905"
"298.58400","24.88225","0.38008"
"298.89600","24.90820","0.38211"
"299.20800","24.93421","0.38375"
"299.52000","24.96022","0.38662"
"299.83200","24.98616","0.38832"
"300.14400","25.01223","0.38948"
"300.45600","25.03818","0.39028"
"300.76800","25.06425","0.39095"
"301.08000","25.09020","0.39229"
"301.39200","25.11615","0.39304"
"301.70400","25.14222","0.39423"
"302.01600","25.16816","0.39602"
"302.32800","25.19423","0.39628"
"302.64000","25.22012","0.39845"
"302.95200","25.24619","0.39919"
"303.26400","25.27220","0.40017"
"303.57600","25.29815","0.40072"
"303.88800","25.32427","0.40068"
"304.20000","25.35011","0.39774"
"304.51200","25.37623","0.39363"
"304.82400","25.40218","0.39170"
"305.13600","25.42819","0.39319"
"305.44800","25.45426","0.39446"
"305.76000","25.48015","0.39629"
"306.07200","25.50622","0.39948"
"306.38400","25.53210","0.40188"
"306.69600","25.55817","0.40488"
"307.00800","25.58418","0.40764"
"307.32000","25.61019","0.41007"
"307.63200","25.63626","0.41308"
"307.94400","25.66215","0.41495"
"308.25600","25.68821","0.41736"
"308.56800","25.71416","0.41907"
"308.88000","25.74023","0.42063"
"309.19200","25.76624","0.42199"
"309.50400","25.79219","0.42297"
"309.81600","25.81820","0.42442"
"310.12800","25.84409","0.42558"
"310.44000","25.87021","0.42673"
"310.75200","25.89622","0.42744"
"311.06400","25.92223","0.42853"
"311.37600","25.94818","0.42942"
"311.68800","25.97419","0.43010"
"312.00000","26.00020","0.43133"
"312.31200","26.02614","0.43266"
"312.62400","26.05221","0.43387"
"312.93600","26.07822","0.43523"
"313.24800","26.10423","0.43636"
"313.56000","26.13024","0.43768"
"313.87200","26.15619","0.43870"
"314.18400","26.18220","0.44030"
"314.49600","26.20820","0.44143"
"314.80800","26.23421","0.44304"
"315.12000","26.26022","0.44456"
"315.43200","26.28617","0.44610"
"315.74400","26.31218","0.44774"
"316.05600","26.33813","0.44921"
"316.36800","26.36420","0.45091"
"316.68000","26.39014","0.45311"
"316.99200","26.41615","0.45448"
"317.30400","26.44216","0.45713"
"317.61600","26.46811","0.45925"
"317.92800","26.49424","0.46151"
"318.24000","26.52019","0.46303"
"318.55200","26.54620","0.46528"
"318.86400","26.57220","0.46753"
"319.17600","26.59815","0.46921"
"319.48800","26.62422","0.47122"
"319.80000","26.65017","0.47392"
"320.11200","26.67624","0.47601"
"320.42400","26.70218","0.47765"
"320.73600","26.72819","0.47993"
"321.04800","26.75420","0.48192"
"321.36000","26.78015","0.48292"
"321.67200","26.80628","0.48467"
"321.98400","26.83217","0.48607"
"322.29600","26.85823","0.48783"
"322.60800","26.88418","0.48880"
"322.92000","26.91019","0.48972"
"323.23200","26.93626","0.49052"
"323.54400","26.96221","0.49144"
"323.85600","26.98822","0.49189"
"324.16800","27.01417","0.49261"
"324.48000","27.04023","0.49318"
"324.79200","27.06618","0.49409"
"325.10400","27.09219","0.49515"
"325.41600","27.11820","0.49669"
"325.72800","27.14421","0.49785"
"326.04000","27.17022","0.49902"
"326.35200","27.19617","0.50096"
"326.66400","27.22218","0.50298"
"326.97600","27.24825","0.50537"
"327.28800","27.27419","0.50594"
"327.60000","27.30020","0.50853"
"327.91200","27.32615","0.51129"
"328.22400","27.35222","0.51229"
"328.53600","27.37822","0.51434"
"328.84800","27.40423","0.51637"
"329.16000","27.43018","0.51745"
"329.47200","27.45619","0.52000"
"329.78400","27.48220","0.52264"
"330.09600","27.50815","0.52437"
"330.40800","27.53422","0.52557"
"330.72000","27.56023","0.52754"
"331.03200","27.58618","0.52955"
"331.34400","27.61218","0.53179"
"331.65600","27.63819","0.53319"
"331.96800","27.66420","0.53479"
"332.28000","27.69021","0.53583"
"332.59200","27.71622","0.53775"
"332.90400","27.74216","0.53960"
"333.21600","27.76818","0.54117"
"333.52800","27.79418","0.54192"
"333.84000","27.82013","0.54381"
"334.15200","27.84626","0.54443"
"334.46400","27.87221","0.54553"
"334.77600","27.89821","0.54575"
"335.08800","27.92422","0.54609"
"335.40000","27.95011","0.54701"
"335.71200","27.97618","0.54721"
"336.02400","28.00219","0.54600"
"336.33600","28.02826","0.54642"
"336.64800","28.05421","0.54636"
"336.96000","28.08021","0.54569"
"337.27200","28.10622","0.54559"
"337.58400","28.13217","0.54652"
"337.89600","28.15824","0.54714"
"338.20800","28.18419","0.54854"
"338.52000","28.21020","0.54967"
"338.83200","28.23621","0.55039"
"339.14400","28.26221","0.55161"
"339.45600","28.28822","0.55198"
"339.76800","28.31417","0.55275"
"340.08000","28.34018","0.55378"
"340.39200","28.36619","0.55436"
"340.70400","28.39220","0.55528"
"341.01600","28.41821","0.55592"
"341.32800","28.44415","0.55675"
"341.64000","28.47028","0.55787"
"341.95200","28.49617","0.55893"
"342.26400","28.52218","0.56053"
"342.57600","28.54819","0.56148"
"342.88800","28.57413","0.56324"
"343.20000","28.60020","0.56467"
"343.51200","28.62615","0.56624"
"343.82400","28.65222","0.56831"
"344.13600","28.67823","0.56975"
"344.44800","28.70418","0.57181"
"344.76000","28.73025","0.57412"
"345.07200","28.75613","0.57553"
"345.38400","28.78220","0.57794"
"345.69600","28.80809","0.58003"
"346.00800","28.83416","0.58195"
"346.32000","28.86017","0.58400"
"346.63200","28.88618","0.58619"
"346.94400","28.91225","0.58758"
"347.25600","28.93813","0.58845"
"347.56800","28.96420","0.59054"
"347.88000","28.99015","0.59090"
"348.19200","29.01622","0.59197"
"348.50400","29.04223","0.59351"
"348.81600","29.06818","0.59390"
"349.12800","29.09425","0.59519"
"349.44000","29.12013","0.59634"
"349.75200","29.14620","0.59715"
"350.06400","29.17221","0.59819"
"350.37600","29.19822","0.59923"
"350.68800","29.22423","0.60015"
"351.00000","29.25018","0.60120"
"351.31200","29.27618","0.60262"
"351.62400","29.30214","0.60392"
"351.93600","29.32820","0.60525"
"352.24800","29.35427","0.60710"
"352.56000","29.38016","0.60755"
"352.87200","29.40623","0.60970"
"353.18400","29.43211","0.61099"
"353.49600","29.45818","0.61277"
"353.80800","29.48419","0.61449"
"354.12000","29.51026","0.61592"
"354.43200","29.53621","0.61661"
"354.74400","29.56216","0.61856"
"355.05600","29.58817","0.62020"
"355.36800","29.61412","0.62200"
"355.68000","29.64024","0.62318"
"355.99200","29.66625","0.62489"
"356.30400","29.69220","0.62575"
"356.61600","29.71821","0.62707"
"356.92800","29.74416","0.62822"
"357.24000","29.77023","0.62869"
"357.55200","29.79623","0.62982"
"357.86400","29.82218","0.63024"
"358.17600","29.84819","0.63141"
"358.48800","29.87420","0.62878"
"358.80000","29.90021","0.62877"
"359.11200","29.92616","0.62661"
"359.42400","29.95223","0.62377"
"359.73600","29.97817","0.62166"
"360.04800","30.00418","0.62027"
"360.36000","30.03019","0.61918"
"360.67200","30.05614","0.62050"
"360.98400","30.08221","0.62286"
"361.29600","30.10816","0.62447"
"361.60800","30.13416","0.62716"
"361.92000","30.16023","0.62895"
"362.23200","30.18618","0.63117"
"362.54400","30.21225","0.63255"
"362.85600","30.23814","0.63481"
"363.16800","30.26421","0.63605"
"363.48000","30.29016","0.63719"
"363.79200","30.31623","0.63870"
"364.10400","30.34223","0.63942"
"364.41600","30.36818","0.64001"
"364.72800","30.39425","0.64104"
"365.04000","30.42020","0.64146"
"365.35200","30.44627","0.64182"
"365.66400","30.47221","0.64207"
"365.97600","30.49816","0.64238"
"366.28800","30.52429","0.64078"
"366.60000","30.55018","0.64104"
"366.91200","30.57619","0.64121"
"367.22400","30.60214","0.64176"
"367.53600","30.62820","0.64239"
"367.84800","30.65415","0.64281"
"368.16000","30.68016","0.64289"
"368.47200","30.70623","0.64335"
"368.78400","30.73218","0.64365"
"369.09600","30.75819","0.64385"
"369.40800","30.78420","0.64388"
"369.72000","30.81020","0.64422"
"370.03200","30.83628","0.64474"
"370.34400","30.86216","0.64487"
"370.65600","30.88823","0.64518"
"370.96800","30.91412","0.64592"
"371.28000","30.94019","0.64587"
"371.59200","30.96625","0.64630"
"371.90400","30.99221","0.64655"
"372.21600","31.01821","0.64687"
"372.52800","31.04416","0.64708"
"372.84000","31.07023","0.64727"
"373.15200","31.09618","0.64796"
"373.46400","31.12225","0.64764"
"373.77600","31.14820","0.64789"
"374.08800","31.17414","0.64837"
"374.40000","31.20015","0.64848"
"374.71200","31.22610","0.64895"
"375.02400","31.25217","0.64898"
"375.33600","31.27817","0.64879"
"375.64800","31.30424","0.64962"
"375.96000","31.33025","0.64982"
"376.27200","31.35620","0.65010"
"376.58400","31.38215","0.65055"
"376.89600","31.40816","0.65102"
"377.20800","31.43417","0.65110"
"377.52000","31.46018","0.65088"
"377.83200","31.48612","0.65107"
"378.14400","31.51219","0.65176"
"378.45600","31.53814","0.65204"
"378.76800","31.56421","0.65231"
"379.08000","31.59022","0.65271"
"379.39200","31.61623","0.65290"
"379.70400","31.64224","0.65350"
"380.01600","31.66818","0.65307"
"380.32800","31.69425","0.65300"
"380.64000","31.72020","0.65155"
"380.95200","31.74621","0.64970"
"381.26400","31.77216","0.64702"
"381.57600","31.79816","0.64483"
"381.88800","31.82423","0.64328"
"382.20000","31.85018","0.64199"
"382.51200","31.87625","0.64141"
"382.82400","31.90220","0.64087"
"383.13600","31.92821","0.64105"
"383.44800","31.95422","0.64125"
"383.76000","31.98016","0.64130"
"384.07200","32.00623","0.64184"
"384.38400","32.03218","0.64240"
"384.69600","32.05825","0.64271"
"385.00800","32.08420","0.64306"
"385.32000","32.11015","0.64397"
"385.63200","32.13616","0.64448"
"385.94400","32.16216","0.64488"
"386.25600","32.18823","0.64515"
"386.56800","32.21412","0.64532"
"386.88000","32.24025","0.64457"
"387.19200","32.26620","0.64354"
"387.50400","32.29214","0.63975"
"387.81600","32.31828","0.61792"
"388.12800","32.34416","0.59486"
"388.44000","32.37023","0.59423"
"388.75200","32.39618","0.59853"
"389.06400","32.42219","0.60345"
"389.37600","32.44820","0.60946"
"389.68800","32.47421","0.61753"
"390.00000","32.50021","0.62383"
"390.31200","32.52610","0.62939"
"390.62400","32.55217","0.63420"
"390.93600","32.57818","0.63740"
"391.24800","32.60425","0.64035"
"391.56000","32.63020","0.64189"
"391.87200","32.65614","0.64296"
"392.18400","32.68221","0.64397"
"392.49600","32.70823","0.64516"
"392.80800","32.73423","0.64631"
"393.12000","32.76024","0.64834"
"393.43200","32.78625","0.64944"
"393.74400","32.81220","0.65054"
"394.05600","32.83814","0.65299"
"394.36800","32.86421","0.65493"
"394.68000","32.89016","0.65699"
"394.99200","32.91623","0.65888"
"395.30400","32.94224","0.66170"
"395.61600","32.96819","0.66311"
"395.92800","32.99419","0.66438"
"396.24000","33.02014","0.66592"
"396.55200","33.04621","0.66727"
"396.86400","33.07222","0.66883"
"397.17600","33.09823","0.67053"
"397.48800","33.12424","0.67199"
"397.80000","33.15012","0.67275"
"398.11200","33.17619","0.67392"
"398.42400","33.20221","0.67473"
"398.73600","33.22827","0.67610"
"399.04800","33.25422","0.67689"
"399.36000","33.28017","0.67781"
"399.67200","33.30618","0.67859"
"399.98400","33.33219","0.67999"
"400.29600","33.35819","0.68230"
"400.60800","33.38420","0.68293"
"400.92000","33.41021","0.68333"
"401.23200","33.43622","0.68498"
"401.54400","33.46223","0.68660"
"401.85600","33.48824","0.68746"
"402.16800","33.51419","0.68782"
"402.48000","33.54019","0.68877"
"402.79200","33.56620","0.68998"
"403.10400","33.59215","0.69101"
"403.41600","33.61822","0.69170"
"403.72800","33.64417","0.69207"
"404.04000","33.67018","0.69221"
"404.35200","33.69619","0.69186"
"404.66400","33.72219","0.69338"
"404.97600","33.74820","0.69319"
"405.28800","33.77415","0.69317"
"405.60000","33.80022","0.69173"
"405.91200","33.82617","0.69133"
"406.22400","33.85223","0.68975"
"406.53600","33.87819","0.68642"
"406.84800","33.90419","0.68078"
"407.16000","33.93020","0.67374"
"407.47200","33.95615","0.66670"
"407.78400","33.98222","0.66112"
"408.09600","34.00817","0.65647"
"408.40800","34.03423","0.65256"
"408.72000","34.06018","0.64999"
"409.03200","34.08619","0.64715"
"409.34400","34.11226","0.64483"
"409.65600","34.13815","0.64348"
"409.96800","34.16422","0.64216"
"410.28000","34.19011","0.63974"
"410.59200","34.21617","0.63724"
"410.90400","34.24218","0.63531"
"411.21600","34.26819","0.63446"
"411.52800","34.29420","0.63505"
"411.84000","34.32015","0.63363"
"412.15200","34.34621","0.63340"
"412.46400","34.37217","0.63365"
"412.77600","34.39823","0.63418"
"413.08800","34.42424","0.63565"
"413.40000","34.45019","0.63511"
"413.71200","34.47620","0.63716"
"414.02400","34.50215","0.63831"
"414.33600","34.52821","0.63937"
"414.64800","34.55423","0.64058"
"414.96000","34.58023","0.64140"
"415.27200","34.60624","0.64196"
"415.58400","34.63213","0.64245"
"415.89600","34.65826","0.64302"
"416.20800","34.68415","0.64316"
"416.52000","34.71021","0.64357"
"416.83200","34.73616","0.64406"
"417.14400","34.76217","0.64426"
"417.45600","34.78818","0.64462"
"417.76800","34.81413","0.64523"
"418.08000","34.84019","0.64593"
"418.39200","34.86621","0.64594"
"418.70400","34.89222","0.64647"
"419.01600","34.91822","0.64715"
"419.32800","34.94417","0.64774"
"419.64000","34.97018","0.64814"
"419.95200","34.99619","0.64831"
"420.26400","35.02219","0.64822"
"420.57600","35.04821","0.64837"
"420.88800","35.07421","0.64949"
"421.20000","35.10022","0.64951"
"421.51200","35.12611","0.64965"
"421.82400","35.15224","0.64964"
"422.13600","35.17819","0.64984"
"422.44800","35.20420","0.65007"
"422.76000","35.23021","0.65008"
"423.07200","35.25615","0.65053"
"423.38400","35.28222","0.65089"
"423.69600","35.30817","0.65110"
"424.00800","35.33424","0.65154"
"424.32000","35.36019","0.65204"
"424.63200","35.38620","0.65244"
"424.94400","35.41220","0.65302"
"425.25600","35.43815","0.65319"
"425.56800","35.46428","0.65462"
"425.88000","35.49017","0.65508"
"426.19200","35.51624","0.65566"
"426.50400","35.54219","-0.01804"
"426.81600","35.56820","0.00300"
"427.12800","35.59426","0.00363"
"427.44000","35.62021","-0.00160"
"427.75200","35.64622","-0.00770"
"428.06400","35.67223","-0.00069"
"428.37600","35.69818","-0.00777"
"428.68800","35.72419","-0.00298"
"429.00000","35.75019","-0.00490"
"429.31200","35.77626","-0.00642"
"429.62400","35.80215","-0.00246"
"429.93600","35.82822","-0.00713"
"430.24800","35.85423","-0.00282"
"430.56000","35.88018","-0.00565"
"430.87200","35.90624","-0.00433"
"431.18400","35.93214","-0.00611"
"431.49600","35.95820","-0.00383"
"431.80800","35.98415","-0.00606"
"432.12000","36.01022","-0.00375"
"432.43200","36.03617","-0.00547"
"432.74400","36.06212","-0.00455"
"433.05600","36.08824","-0.00508"
"433.36800","36.11414","-0.00507"
"433.68000","36.14021","-0.00389"
"433.99200","36.16615","-0.00573"
"434.30400","36.19222","-0.00368"
"434.61600","36.21823","-0.00577"
"434.92800","36.24417","-0.00345"
"435.24000","36.27018","-0.00465"
"435.55200","36.29613","-0.00436"
"435.86400","36.32220","-0.00400"
"436.17600","36.34821","-0.00455"
"436.48800","36.37422","-0.00399"
"436.80000","36.40023","-0.00487"
"437.11200","36.42612","-0.00302"
"437.42400","36.45219","-0.00445"
"437.73600","36.47819","-0.00314"
"438.04800","36.50420","-0.00506"
"438.36000","36.53027","-0.00368"
"438.67200","36.55616","-0.00467"
"438.98400","36.58216","-0.00431"
"439.29600","36.60812","-0.00364"
"439.60800","36.63424","-0.00416"
"439.92000","36.66025","-0.00376"
"440.23200","36.68620","-0.00449"
"440.54400","36.71221","-0.00320"
"440.85600","36.73816","-0.00389"
"441.16800","36.76417","-0.00385"
"441.48000","36.79017","-0.00386"
"441.79200","36.81624","-0.00179"
"442.10400","36.84225","-0.00320"
"442.41600","36.86814","-0.00381"
"442.72800","36.89415","-0.00318"
"443.04000","36.92015","-0.00360"
"443.35200","36.94622","-0.00299"
"443.66400","36.97223","-0.00285"
"443.97600","36.99818","-0.00297"
"444.28800","37.02425","-0.00308"
"444.60000","37.05020","-0.00327"
"444.91200","37.07621","-0.00237"
"445.22400","37.10215","-0.00319"
"445.53600","37.12817","-0.00329"
"445.84800","37.15417","-0.00273"
"446.16000","37.18018","-0.00252"
"446.47200","37.20619","-0.00302"
"446.78400","37.23214","-0.00261"
"447.09600","37.25827","-0.00172"
"447.40800","37.28415","-0.00259"
"447.72000","37.31017","-0.00213"
"448.03200","37.33617","-0.00203"
"448.34400","37.36218","-0.00200"
"448.65600","37.38825","-0.00245"
"448.96800","37.41414","-0.00251"
"449.28000","37.44021","-0.00124"
"449.59200","37.46621","-0.00253"
"449.90400","37.49216","-0.00186"
"450.21600","37.51823","-0.00202"
"450.52800","37.54418","-0.00158"
"450.84000","37.57025","-0.00141"
"451.15200","37.59620","-0.00150"
"451.46400","37.62226","-0.00120"
"451.77600","37.64821","-0.00107"
"452.08800","37.67416","-0.00077"
"452.40000","37.70029","-0.00132"
"452.71200","37.72618","-0.00105"
"453.02400","37.75219","-0.00079"
"453.33600","37.77819","-0.00077"
"453.64800","37.80421","-0.00102"
"453.96000","37.83021","-0.00039"
"454.27200","37.85616","-0.00084"
"454.58400","37.88223","-0.00001"
"454.89600","37.90812","-0.00011"
"455.20800","37.93419","-0.00018"
"455.52000","37.96019","-0.00050"
"455.83200","37.98620","-0.00046"
"456.14400","38.01227","0.00013"
"456.45600","38.03816","-0.00011"
"456.76800","38.06423","0.00041"
"457.08000","38.09018","0.00003"
"457.39200","38.11619","-0.00003"
"457.70400","38.14219","0.00051"
"458.01600","38.16820","0.00097"
"458.32800","38.19421","0.00026"
"458.64000","38.22016","0.00127"
"458.95200","38.24623","0.00104"
"459.26400","38.27217","0.00088"
"459.57600","38.29819","0.00133"
"459.88800","38.32420","0.00165"
"460.20000","38.35014","0.00144"
"460.51200","38.37615","0.00205"
"460.82400","38.40216","0.00159"
"461.13600","38.42823","0.00206"
"461.44800","38.45417","0.00179"
"461.76000","38.48019","0.00204"
"462.07200","38.50620","0.00260"
"462.38400","38.53214","0.00250"
"462.69600","38.55815","0.00272"
"463.00800","38.58416","0.00246"
"463.32000","38.61023","0.00289"
"463.63200","38.63618","0.00354"
"463.94400","38.66219","0.00337"
"463.98400","38.66547","0.00341"