File: Force_trajectories/170226_1/Specimen_RawData_4.csv
End date,"2/26/2017"
Specimen label,"4BG_28"
Maximum Load,"0.04336",N

Time,Extension,Load
(s),(mm),(N)
"0.00000","0.00000","0.00016"
"0.13200","0.00676","0.00019"
"0.26400","0.02093","0.00028"
"0.39600","0.03330","0.00042"
"0.52800","0.04430","0.00089"
"0.66000","0.05525","0.00111"
"0.79200","0.06625","0.00131"
"0.92400","0.07725","0.00206"
"1.05600","0.08819","0.00157"
"1.18800","0.09925","0.00239"
"1.32000","0.11019","0.00255"
"1.45200","0.12119","0.00267"
"1.58400","0.13219","0.00284"
"1.71600","0.14320","0.00311"
"1.84800","0.15420","0.00284"
"1.98000","0.16514","0.00372"
"2.11200","0.17626","0.00358"
"2.24400","0.18726","0.00384"
"2.37600","0.19820","0.00414"
"2.50800","0.20920","0.00410"
"2.64000","0.22026","0.00374"
"2.77200","0.23121","0.00398"
"2.90400","0.24221","0.00400"
"3.03600","0.25315","0.00433"
"3.16800","0.26427","0.00443"
"3.30000","0.27521","0.00471"
"3.43200","0.28621","0.00473"
"3.56400","0.29709","0.00472"
"3.69600","0.30827","0.00526"
"3.82800","0.31928","0.00522"
"3.96000","0.33022","0.00463"
"4.09200","0.34116","0.00517"
"4.22400","0.35222","0.00490"
"4.35600","0.36322","0.00496"
"4.48800","0.37416","0.00585"
"4.62000","0.38516","0.00573"
"4.75200","0.39623","0.00574"
"4.88400","0.40723","0.00561"
"5.01600","0.41823","0.00540"
"5.14800","0.42917","0.00588"
"5.28000","0.44017","0.00600"
"5.41200","0.45123","0.00604"
"5.54400","0.46223","0.00669"
"5.67600","0.47317","0.00637"
"5.80800","0.48424","0.00641"
"5.94000","0.49524","0.00656"
"6.07200","0.50618","0.00650"
"6.20400","0.51712","0.00646"
"6.33600","0.52818","0.00637"
"6.46800","0.53918","0.00654"
"6.60000","0.55018","0.00711"
"6.73200","0.56112","0.00667"
"6.86400","0.57219","0.00645"
"6.99600","0.58325","0.00704"
"7.12800","0.59425","0.00687"
"7.26000","0.60525","0.00727"
"7.39200","0.61625","0.00685"
"7.52400","0.62725","0.00735"
"7.65600","0.63825","0.00775"
"7.78800","0.64919","0.00722"
"7.92000","0.66020","0.00708"
"8.05200","0.67120","0.00780"
"8.18400","0.68226","0.00771"
"8.31600","0.69320","0.00782"
"8.44800","0.70420","0.00776"
"8.58000","0.71526","0.00780"
"8.71200","0.72620","0.00812"
"8.84400","0.73720","0.00831"
"8.97600","0.74821","0.00827"
"9.10800","0.75927","0.00818"
"9.24000","0.77021","0.00813"
"9.37200","0.78115","0.00819"
"9.50400","0.79215","0.00819"
"9.63600","0.80321","0.00804"
"9.76800","0.81421","0.00847"
"9.90000","0.82522","0.00837"
"10.03200","0.83622","0.00807"
"10.16400","0.84728","0.00874"
"10.29600","0.85828","0.00857"
"10.42800","0.86922","0.00816"
"10.56000","0.88022","0.00846"
"10.69200","0.89128","0.00858"
"10.82400","0.90222","0.00851"
"10.95600","0.91317","0.00870"
"11.08800","0.92417","0.00914"
"11.22000","0.93523","0.00859"
"11.35200","0.94623","0.00960"
"11.48400","0.95723","0.00890"
"11.61600","0.96817","0.00899"
"11.74800","0.97923","0.00876"
"11.88000","0.99023","0.00902"
"12.01200","1.00124","0.00933"
"12.14400","1.01212","0.00926"
"12.27600","1.02324","0.00949"
"12.40800","1.03424","0.01024"
"12.54000","1.04518","0.00956"
"12.67200","1.05612","0.00949"
"12.80400","1.06718","0.00965"
"12.93600","1.07824","0.00905"
"13.06800","1.08919","0.00968"
"13.20000","1.10019","0.00897"
"13.33200","1.11119","0.00971"
"13.46400","1.12219","0.00955"
"13.59600","1.13325","0.00951"
"13.72800","1.14419","0.00953"
"13.86000","1.15525","0.00964"
"13.99200","1.16631","0.00969"
"14.12400","1.17726","0.00956"
"14.25600","1.18814","0.00995"
"14.38800","1.19920","0.00980"
"14.52000","1.21020","0.00965"
"14.65200","1.22120","0.01033"
"14.78400","1.23220","0.00979"
"14.91600","1.24320","0.01010"
"15.04800","1.25420","0.01039"
"15.18000","1.26527","0.01020"
"15.31200","1.27621","0.01041"
"15.44400","1.28721","0.01055"
"15.57600","1.29827","0.00983"
"15.70800","1.30921","0.00992"
"15.84000","1.32021","0.00993"
"15.97200","1.33121","0.01033"
"16.10400","1.34222","0.01027"
"16.23600","1.35322","0.01026"
"16.36800","1.36422","0.01055"
"16.50000","1.37516","0.01098"
"16.63200","1.38628","0.01053"
"16.76400","1.39722","0.01009"
"16.89600","1.40822","0.01101"
"17.02800","1.41922","0.01010"
"17.16000","1.43029","0.01046"
"17.29200","1.44123","0.00987"
"17.42400","1.45217","0.01091"
"17.55600","1.46317","0.01047"
"17.68800","1.47423","0.01107"
"17.82000","1.48523","0.01100"
"17.95200","1.49617","0.01086"
"18.08400","1.50717","0.01054"
"18.21600","1.51824","0.01030"
"18.34800","1.52924","0.01056"
"18.48000","1.54024","0.01106"
"18.61200","1.55124","0.01064"
"18.74400","1.56224","0.01069"
"18.87600","1.57324","0.01092"
"19.00800","1.58424","0.01076"
"19.14000","1.59513","0.01129"
"19.27200","1.60625","0.01098"
"19.40400","1.61719","0.01085"
"19.53600","1.62819","0.01118"
"19.66800","1.63919","0.01165"
"19.80000","1.65025","0.01098"
"19.93200","1.66125","0.01097"
"20.06400","1.67225","0.01124"
"20.19600","1.68314","0.01088"
"20.32800","1.69426","0.01075"
"20.46000","1.70526","0.01151"
"20.59200","1.71626","0.01135"
"20.72400","1.72720","0.01076"
"20.85600","1.73820","0.01103"
"20.98800","1.74920","0.01100"
"21.12000","1.76020","0.01123"
"21.25200","1.77121","0.01136"
"21.38400","1.78221","0.01118"
"21.51600","1.79321","0.01171"
"21.64800","1.80421","0.01101"
"21.78000","1.81515","0.01177"
"21.91200","1.82621","0.01161"
"22.04400","1.83727","0.01157"
"22.17600","1.84827","0.01124"
"22.30800","1.85922","0.01188"
"22.44000","1.87022","0.01159"
"22.57200","1.88128","0.01205"
"22.70400","1.89222","0.01153"
"22.83600","1.90322","0.01243"
"22.96800","1.91416","0.01196"
"23.10000","1.92522","0.01201"
"23.23200","1.93628","0.01222"
"23.36400","1.94723","0.01215"
"23.49600","1.95817","0.01182"
"23.62800","1.96923","0.01159"
"23.76000","1.98023","0.01193"
"23.89200","1.99123","0.01221"
"24.02400","2.00217","0.01205"
"24.15600","2.01323","0.01237"
"24.28800","2.02423","0.01241"
"24.42000","2.03518","0.01191"
"24.55200","2.04612","0.01259"
"24.68400","2.05724","0.01210"
"24.81600","2.06824","0.01202"
"24.94800","2.07924","0.01207"
"25.08000","2.09018","0.01226"
"25.21200","2.10124","0.01218"
"25.34400","2.11224","0.01265"
"25.47600","2.12325","0.01231"
"25.60800","2.13419","0.01294"
"25.74000","2.14525","0.01254"
"25.87200","2.15619","0.01262"
"26.00400","2.16719","0.01286"
"26.13600","2.17819","0.01273"
"26.26800","2.18919","0.01265"
"26.40000","2.20020","0.01262"
"26.53200","2.21120","0.01283"
"26.66400","2.22220","0.01254"
"26.79600","2.23320","0.01294"
"26.92800","2.24426","0.01261"
"27.06000","2.25520","0.01280"
"27.19200","2.26614","0.01279"
"27.32400","2.27720","0.01360"
"27.45600","2.28821","0.01354"
"27.58800","2.29921","0.01307"
"27.72000","2.31021","0.01277"
"27.85200","2.32127","0.01297"
"27.98400","2.33221","0.01271"
"28.11600","2.34321","0.01226"
"28.24800","2.35415","0.01278"
"28.38000","2.36521","0.01270"
"28.51200","2.37628","0.01292"
"28.64400","2.38722","0.01284"
"28.77600","2.39822","0.01296"
"28.90800","2.40922","0.01251"
"29.04000","2.42028","0.01335"
"29.17200","2.43122","0.01289"
"29.30400","2.44216","0.01296"
"29.43600","2.45316","0.01324"
"29.56800","2.46423","0.01348"
"29.70000","2.47523","0.01353"
"29.83200","2.48617","0.01298"
"29.96400","2.49723","0.01286"
"30.09600","2.50823","0.01327"
"30.22800","2.51929","0.01290"
"30.36000","2.53023","0.01272"
"30.49200","2.54123","0.01355"
"30.62400","2.55224","0.01297"
"30.75600","2.56330","0.01313"
"30.88800","2.57418","0.01296"
"31.02000","2.58518","0.01304"
"31.15200","2.59624","0.01325"
"31.28400","2.60724","0.01255"
"31.41600","2.61824","0.01302"
"31.54800","2.62919","0.01338"
"31.68000","2.64025","0.01319"
"31.81200","2.65125","0.01271"
"31.94400","2.66225","0.01363"
"32.07600","2.67319","0.01319"
"32.20800","2.68425","0.01356"
"32.34000","2.69525","0.01351"
"32.47200","2.70619","0.01308"
"32.60400","2.71714","0.01332"
"32.73600","2.72826","0.01348"
"32.86800","2.73926","0.01350"
"33.00000","2.75026","0.01361"
"33.13200","2.76120","0.01454"
"33.26400","2.77220","0.01353"
"33.39600","2.78320","0.01427"
"33.52800","2.79426","0.01394"
"33.66000","2.80521","0.01394"
"33.79200","2.81627","0.01356"
"33.92400","2.82727","0.01407"
"34.05600","2.83821","0.01400"
"34.18800","2.84915","0.01343"
"34.32000","2.86021","0.01370"
"34.45200","2.87121","0.01343"
"34.58400","2.88215","0.01402"
"34.71600","2.89316","0.01407"
"34.84800","2.90422","0.01368"
"34.98000","2.91522","0.01367"
"35.11200","2.92622","0.01432"
"35.24400","2.93722","0.01322"
"35.37600","2.94822","0.01394"
"35.50800","2.95922","0.01450"
"35.64000","2.97022","0.01415"
"35.77200","2.98117","0.01443"
"35.90400","2.99217","0.01431"
"36.03600","3.00323","0.01391"
"36.16800","3.01423","0.01459"
"36.30000","3.02517","0.01484"
"36.43200","3.03623","0.01381"
"36.56400","3.04723","0.01476"
"36.69600","3.05823","0.01472"
"36.82800","3.06924","0.01472"
"36.96000","3.08018","0.01486"
"37.09200","3.09124","0.01457"
"37.22400","3.10224","0.01402"
"37.35600","3.11318","0.01467"
"37.48800","3.12418","0.01473"
"37.62000","3.13524","0.01486"
"37.75200","3.14625","0.01478"
"37.88400","3.15719","0.01457"
"38.01600","3.16813","0.01535"
"38.14800","3.17925","0.01525"
"38.28000","3.19025","0.01473"
"38.41200","3.20125","0.01498"
"38.54400","3.21219","0.01476"
"38.67600","3.22325","0.01447"
"38.80800","3.23426","0.01498"
"38.94000","3.24520","0.01524"
"39.07200","3.25614","0.01489"
"39.20400","3.26714","0.01445"
"39.33600","3.27826","0.01510"
"39.46800","3.28920","0.01458"
"39.60000","3.30014","0.01460"
"39.73200","3.31120","0.01493"
"39.86400","3.32221","0.01496"
"39.99600","3.33321","0.01472"
"40.12800","3.34421","0.01537"
"40.26000","3.35521","0.01510"
"40.39200","3.36621","0.01496"
"40.52400","3.37721","0.01553"
"40.65600","3.38815","0.01520"
"40.78800","3.39921","0.01520"
"40.92000","3.41022","0.01489"
"41.05200","3.42128","0.01524"
"41.18400","3.43216","0.01507"
"41.31600","3.44322","0.01577"
"41.44800","3.45422","0.01574"
"41.58000","3.46522","0.01592"
"41.71200","3.47616","0.01625"
"41.84400","3.48722","0.01546"
"41.97600","3.49829","0.01576"
"42.10800","3.50923","0.01573"
"42.24000","3.52023","0.01641"
"42.37200","3.53117","0.01618"
"42.50400","3.54223","0.01546"
"42.63600","3.55323","0.01606"
"42.76800","3.56417","0.01651"
"42.90000","3.57518","0.01620"
"43.03200","3.58624","0.01569"
"43.16400","3.59724","0.01654"
"43.29600","3.60818","0.01587"
"43.42800","3.61924","0.01661"
"43.56000","3.63024","0.01643"
"43.69200","3.64124","0.01652"
"43.82400","3.65218","0.01616"
"43.95600","3.66319","0.01671"
"44.08800","3.67425","0.01639"
"44.22000","3.68525","0.01649"
"44.35200","3.69625","0.01681"
"44.48400","3.70719","0.01654"
"44.61600","3.71831","0.01684"
"44.74800","3.72925","0.01668"
"44.88000","3.74019","0.01683"
"45.01200","3.75120","0.01690"
"45.14400","3.76226","0.01682"
"45.27600","3.77326","0.01698"
"45.40800","3.78420","0.01712"
"45.54000","3.79514","0.01646"
"45.67200","3.80620","0.01702"
"45.80400","3.81726","0.01681"
"45.93600","3.82820","0.01691"
"46.06800","3.83915","0.01752"
"46.20000","3.85021","0.01743"
"46.33200","3.86121","0.01694"
"46.46400","3.87221","0.01694"
"46.59600","3.88315","0.01702"
"46.72800","3.89427","0.01741"
"46.86000","3.90527","0.01685"
"46.99200","3.91627","0.01654"
"47.12400","3.92716","0.01705"
"47.25600","3.93816","0.01680"
"47.38800","3.94922","0.01733"
"47.52000","3.96016","0.01639"
"47.65200","3.97116","0.01655"
"47.78400","3.98222","0.01706"
"47.91600","3.99322","0.01732"
"48.04800","4.00422","0.01671"
"48.18000","4.01517","0.01728"
"48.31200","4.02617","0.01673"
"48.44400","4.03723","0.01697"
"48.57600","4.04823","0.01740"
"48.70800","4.05917","0.01734"
"48.84000","4.07017","0.01754"
"48.97200","4.08117","0.01740"
"49.10400","4.09218","0.01735"
"49.23600","4.10312","0.01761"
"49.36800","4.11418","0.01780"
"49.50000","4.12524","0.01750"
"49.63200","4.13624","0.01777"
"49.76400","4.14718","0.01812"
"49.89600","4.15818","0.01781"
"50.02800","4.16924","0.01721"
"50.16000","4.18024","0.01750"
"50.29200","4.19125","0.01726"
"50.42400","4.20219","0.01794"
"50.55600","4.21325","0.01763"
"50.68800","4.22419","0.01753"
"50.82000","4.23519","0.01784"
"50.95200","4.24613","0.01800"
"51.08400","4.25719","0.01768"
"51.21600","4.26826","0.01765"
"51.34800","4.27920","0.01778"
"51.48000","4.29026","0.01743"
"51.61200","4.30126","0.01769"
"51.74400","4.31220","0.01809"
"51.87600","4.32320","0.01755"
"52.00800","4.33420","0.01759"
"52.14000","4.34520","0.01826"
"52.27200","4.35621","0.01776"
"52.40400","4.36715","0.01865"
"52.53600","4.37821","0.01752"
"52.66800","4.38921","0.01760"
"52.80000","4.40021","0.01793"
"52.93200","4.41121","0.01831"
"53.06400","4.42215","0.01830"
"53.19600","4.43327","0.01871"
"53.32800","4.44428","0.01926"
"53.46000","4.45528","0.01839"
"53.59200","4.46622","0.01820"
"53.72400","4.47728","0.01856"
"53.85600","4.48822","0.01866"
"53.98800","4.49922","0.01903"
"54.12000","4.51016","0.01860"
"54.25200","4.52122","0.01867"
"54.38400","4.53223","0.01897"
"54.51600","4.54329","0.01861"
"54.64800","4.55417","0.01868"
"54.78000","4.56523","0.01864"
"54.91200","4.57629","0.01868"
"55.04400","4.58729","0.01886"
"55.17600","4.59817","0.01934"
"55.30800","4.60924","0.01902"
"55.44000","4.62024","0.01850"
"55.57200","4.63124","0.01923"
"55.70400","4.64224","0.01926"
"55.83600","4.65324","0.01949"
"55.96800","4.66430","0.01922"
"56.10000","4.67524","0.01867"
"56.23200","4.68618","0.01943"
"56.36400","4.69719","0.01943"
"56.49600","4.70825","0.01947"
"56.62800","4.71931","0.01947"
"56.76000","4.73019","0.01891"
"56.89200","4.74125","0.01941"
"57.02400","4.75225","0.01914"
"57.15600","4.76325","0.01889"
"57.28800","4.77419","0.01976"
"57.42000","4.78520","0.01996"
"57.55200","4.79620","0.01976"
"57.68400","4.80720","0.02003"
"57.81600","4.81820","0.01971"
"57.94800","4.82920","0.02017"
"58.08000","4.84026","0.02031"
"58.21200","4.85126","0.01961"
"58.34400","4.86220","0.02001"
"58.47600","4.87321","0.02063"
"58.60800","4.88427","0.01961"
"58.74000","4.89521","0.02027"
"58.87200","4.90621","0.02039"
"59.00400","4.91715","0.01982"
"59.13600","4.92821","0.02037"
"59.26800","4.93927","0.02011"
"59.40000","4.95021","0.01988"
"59.53200","4.96122","0.01996"
"59.66400","4.97222","0.01877"
"59.79600","4.98322","0.01965"
"59.92800","4.99422","0.01968"
"60.06000","5.00522","0.01958"
"60.19200","5.01628","0.01912"
"60.32400","5.02722","0.01940"
"60.45600","5.03816","0.01909"
"60.58800","5.04911","0.01963"
"60.72000","5.06023","0.02018"
"60.85200","5.07123","0.02005"
"60.98400","5.08223","0.02036"
"61.11600","5.09317","0.01990"
"61.24800","5.10423","0.02002"
"61.38000","5.11523","0.01991"
"61.51200","5.12624","0.02008"
"61.64400","5.13718","0.02051"
"61.77600","5.14824","0.01994"
"61.90800","5.15924","0.02062"
"62.04000","5.17024","0.02055"
"62.17200","5.18118","0.01958"
"62.30400","5.19224","0.02037"
"62.43600","5.20318","0.02029"
"62.56800","5.21424","0.02019"
"62.70000","5.22513","0.02056"
"62.83200","5.23625","0.02002"
"62.96400","5.24725","0.02051"
"63.09600","5.25825","0.02032"
"63.22800","5.26919","0.02041"
"63.36000","5.28025","0.02082"
"63.49200","5.29125","0.02073"
"63.62400","5.30226","0.02124"
"63.75600","5.31320","0.02062"
"63.88800","5.32420","0.02088"
"64.02000","5.33526","0.02070"
"64.15200","5.34620","0.02145"
"64.28400","5.35720","0.02143"
"64.41600","5.36820","0.02151"
"64.54800","5.37926","0.02161"
"64.68000","5.39021","0.02150"
"64.81200","5.40115","0.02138"
"64.94400","5.41221","0.02128"
"65.07600","5.42321","0.02104"
"65.20800","5.43421","0.02113"
"65.34000","5.44515","0.02118"
"65.47200","5.45615","0.02152"
"65.60400","5.46721","0.02117"
"65.73600","5.47822","0.02181"
"65.86800","5.48922","0.02159"
"66.00000","5.50016","0.02174"
"66.13200","5.51122","0.02150"
"66.26400","5.52222","0.02167"
"66.39600","5.53328","0.02190"
"66.52800","5.54422","0.02182"
"66.66000","5.55528","0.02212"
"66.79200","5.56629","0.02188"
"66.92400","5.57723","0.02274"
"67.05600","5.58817","0.02224"
"67.18800","5.59923","0.02203"
"67.32000","5.61023","0.02198"
"67.45200","5.62123","0.02231"
"67.58400","5.63217","0.02212"
"67.71600","5.64324","0.02181"
"67.84800","5.65424","0.02258"
"67.98000","5.66524","0.02245"
"68.11200","5.67618","0.02168"
"68.24400","5.68724","0.02232"
"68.37600","5.69824","0.02236"
"68.50800","5.70924","0.02226"
"68.64000","5.72018","0.02181"
"68.77200","5.73125","0.02261"
"68.90400","5.74225","0.02236"
"69.03600","5.75325","0.02322"
"69.16800","5.76419","0.02271"
"69.30000","5.77519","0.02283"
"69.43200","5.78625","0.02301"
"69.56400","5.79719","0.02274"
"69.69600","5.80819","0.02301"
"69.82800","5.81920","0.02295"
"69.96000","5.83026","0.02258"
"70.09200","5.84126","0.02295"
"70.22400","5.85214","0.02260"
"70.35600","5.86320","0.02313"
"70.48800","5.87414","0.02310"
"70.62000","5.88520","0.02394"
"70.75200","5.89614","0.02361"
"70.88400","5.90721","0.02278"
"71.01600","5.91827","0.02371"
"71.14800","5.92921","0.02328"
"71.28000","5.94021","0.02280"
"71.41200","5.95121","0.02310"
"71.54400","5.96227","0.02301"
"71.67600","5.97327","0.02353"
"71.80800","5.98422","0.02333"
"71.94000","5.99522","0.02350"
"72.07200","6.00622","0.02353"
"72.20400","6.01722","0.02321"
"72.33600","6.02816","0.02330"
"72.46800","6.03916","0.02346"
"72.60000","6.05028","0.02341"
"72.73200","6.06122","0.02311"
"72.86400","6.07217","0.02369"
"72.99600","6.08323","0.02348"
"73.12800","6.09423","0.02361"
"73.26000","6.10523","0.02361"
"73.39200","6.11623","0.02349"
"73.52400","6.12723","0.02366"
"73.65600","6.13823","0.02343"
"73.78800","6.14923","0.02366"
"73.92000","6.16017","0.02306"
"74.05200","6.17118","0.02374"
"74.18400","6.18224","0.02314"
"74.31600","6.19324","0.02316"
"74.44800","6.20418","0.02334"
"74.58000","6.21518","0.02328"
"74.71200","6.22624","0.02352"
"74.84400","6.23724","0.02335"
"74.97600","6.24825","0.02377"
"75.10800","6.25919","0.02395"
"75.24000","6.27025","0.02355"
"75.37200","6.28125","0.02390"
"75.50400","6.29219","0.02385"
"75.63600","6.30313","0.02407"
"75.76800","6.31419","0.02371"
"75.90000","6.32519","0.02377"
"76.03200","6.33620","0.02369"
"76.16400","6.34720","0.02397"
"76.29600","6.35820","0.02347"
"76.42800","6.36926","0.02384"
"76.56000","6.38020","0.02309"
"76.69200","6.39120","0.02355"
"76.82400","6.40220","0.02352"
"76.95600","6.41320","0.02348"
"77.08800","6.42421","0.02342"
"77.22000","6.43521","0.02325"
"77.35200","6.44621","0.02309"
"77.48400","6.45721","0.02245"
"77.61600","6.46821","0.02340"
"77.74800","6.47921","0.02357"
"77.88000","6.49021","0.02390"
"78.01200","6.50121","0.02401"
"78.14400","6.51222","0.02408"
"78.27600","6.52322","0.02414"
"78.40800","6.53422","0.02439"
"78.54000","6.54522","0.02329"
"78.67200","6.55622","0.02398"
"78.80400","6.56716","0.02380"
"78.93600","6.57816","0.02383"
"79.06800","6.58923","0.02378"
"79.20000","6.60023","0.02405"
"79.33200","6.61123","0.02389"
"79.46400","6.62223","0.02398"
"79.59600","6.63329","0.02379"
"79.72800","6.64423","0.02387"
"79.86000","6.65523","0.02391"
"79.99200","6.66617","0.02396"
"80.12400","6.67724","0.02430"
"80.25600","6.68824","0.02413"
"80.38800","6.69924","0.02358"
"80.52000","6.71018","0.02386"
"80.65200","6.72124","0.02384"
"80.78400","6.73230","0.02358"
"80.91600","6.74318","0.02378"
"81.04800","6.75412","0.02403"
"81.18000","6.76531","0.02464"
"81.31200","6.77625","0.02464"
"81.44400","6.78725","0.02402"
"81.57600","6.79819","0.02386"
"81.70800","6.80925","0.02418"
"81.84000","6.82025","0.02446"
"81.97200","6.83119","0.02388"
"82.10400","6.84213","0.02370"
"82.23600","6.85320","0.02382"
"82.36800","6.86426","0.02416"
"82.50000","6.87520","0.02392"
"82.63200","6.88614","0.02512"
"82.76400","6.89726","0.02413"
"82.89600","6.90826","0.02394"
"83.02800","6.91926","0.02433"
"83.16000","6.93020","0.02422"
"83.29200","6.94121","0.02450"
"83.42400","6.95221","0.02395"
"83.55600","6.96321","0.02444"
"83.68800","6.97415","0.02495"
"83.82000","6.98521","0.02448"
"83.95200","6.99621","0.02499"
"84.08400","7.00727","0.02463"
"84.21600","7.01822","0.02512"
"84.34800","7.02922","0.02466"
"84.48000","7.04022","0.02537"
"84.61200","7.05122","0.02468"
"84.74400","7.06216","0.02516"
"84.87600","7.07322","0.02555"
"85.00800","7.08422","0.02533"
"85.14000","7.09522","0.02544"
"85.27200","7.10617","0.02579"
"85.40400","7.11717","0.02591"
"85.53600","7.12817","0.02473"
"85.66800","7.13923","0.02610"
"85.80000","7.15023","0.02555"
"85.93200","7.16117","0.02551"
"86.06400","7.17229","0.02527"
"86.19600","7.18323","0.02468"
"86.32800","7.19418","0.02593"
"86.46000","7.20524","0.02606"
"86.59200","7.21624","0.02556"
"86.72400","7.22724","0.02010"
"86.85600","7.23818","0.02121"
"86.98800","7.24918","0.01980"
"87.12000","7.26024","0.02128"
"87.25200","7.27124","0.02292"
"87.38400","7.28219","0.02298"
"87.51600","7.29319","0.02231"
"87.64800","7.30425","0.02223"
"87.78000","7.31525","0.02280"
"87.91200","7.32619","0.02281"
"88.04400","7.33719","0.02316"
"88.17600","7.34825","0.02367"
"88.30800","7.35919","0.02441"
"88.44000","7.37020","0.02445"
"88.57200","7.38114","0.02456"
"88.70400","7.39220","0.02476"
"88.83600","7.40320","0.02452"
"88.96800","7.41420","0.02496"
"89.10000","7.42514","0.02472"
"89.23200","7.43626","0.02547"
"89.36400","7.44727","0.02541"
"89.49600","7.45821","0.02573"
"89.62800","7.46915","0.02577"
"89.76000","7.48027","0.02579"
"89.89200","7.49127","0.02595"
"90.02400","7.50221","0.02618"
"90.15600","7.51315","0.02601"
"90.28800","7.52415","0.02672"
"90.42000","7.53521","0.02701"
"90.55200","7.54622","0.02666"
"90.68400","7.55716","0.02676"
"90.81600","7.56822","0.02722"
"90.94800","7.57922","0.02706"
"91.08000","7.59022","0.02713"
"91.21200","7.60122","0.02719"
"91.34400","7.61222","0.02701"
"91.47600","7.62323","0.02770"
"91.60800","7.63423","0.02736"
"91.74000","7.64523","0.02757"
"91.87200","7.65623","0.02802"
"92.00400","7.66723","0.02800"
"92.13600","7.67829","0.02778"
"92.26800","7.68917","0.02818"
"92.40000","7.70023","0.02825"
"92.53200","7.71124","0.02860"
"92.66400","7.72224","0.02825"
"92.79600","7.73324","0.02866"
"92.92800","7.74424","0.02830"
"93.06000","7.75524","0.02923"
"93.19200","7.76624","0.02951"
"93.32400","7.77718","0.02930"
"93.45600","7.78819","0.02896"
"93.58800","7.79919","0.02951"
"93.72000","7.81019","0.02953"
"93.85200","7.82119","0.02906"
"93.98400","7.83219","0.02917"
"94.11600","7.84319","0.02919"
"94.24800","7.85425","0.02976"
"94.38000","7.86525","0.03029"
"94.51200","7.87625","0.02993"
"94.64400","7.88731","0.02931"
"94.77600","7.89826","0.03014"
"94.90800","7.90920","0.03006"
"95.04000","7.92014","0.03079"
"95.17200","7.93126","0.02997"
"95.30400","7.94220","0.02991"
"95.43600","7.95320","0.03044"
"95.56800","7.96420","0.03040"
"95.70000","7.97521","0.03090"
"95.83200","7.98621","0.03113"
"95.96400","7.99721","0.03028"
"96.09600","8.00815","0.03098"
"96.22800","8.01927","0.03029"
"96.36000","8.03027","0.03064"
"96.49200","8.04127","0.03089"
"96.62400","8.05216","0.03038"
"96.75600","8.06328","0.03083"
"96.88800","8.07422","0.03139"
"97.02000","8.08522","0.03107"
"97.15200","8.09616","0.03128"
"97.28400","8.10722","0.03074"
"97.41600","8.11822","0.03039"
"97.54800","8.12922","0.03151"
"97.68000","8.14017","0.03112"
"97.81200","8.15123","0.03137"
"97.94400","8.16223","0.03100"
"98.07600","8.17329","0.03142"
"98.20800","8.18417","0.03155"
"98.34000","8.19517","0.03138"
"98.47200","8.20623","0.03110"
"98.60400","8.21717","0.02996"
"98.73600","8.22818","0.02974"
"98.86800","8.23918","0.02945"
"99.00000","8.25024","0.02995"
"99.13200","8.26124","0.02994"
"99.26400","8.27218","0.02928"
"99.39600","8.28324","0.02943"
"99.52800","8.29424","0.02941"
"99.66000","8.30524","0.02928"
"99.79200","8.31619","0.02921"
"99.92400","8.32719","0.02885"
"100.05600","8.33825","0.02854"
"100.18800","8.34925","0.02849"
"100.32000","8.36019","0.02797"
"100.45200","8.37113","0.02744"
"100.58400","8.38225","0.02669"
"100.71600","8.39325","0.02750"
"100.84800","8.40420","0.02655"
"100.98000","8.41520","0.02425"
"101.11200","8.42626","0.02133"
"101.24400","8.43726","0.02153"
"101.37600","8.44820","0.02267"
"101.50800","8.45914","0.02299"
"101.64000","8.47020","0.02406"
"101.77200","8.48120","0.02360"
"101.90400","8.49215","0.02439"
"102.03600","8.50315","0.02424"
"102.16800","8.51421","0.02383"
"102.30000","8.52521","0.02404"
"102.43200","8.53621","0.02408"
"102.56400","8.54721","0.01899"
"102.69600","8.55827","0.01793"
"102.82800","8.56927","0.01683"
"102.96000","8.58028","0.01598"
"103.09200","8.59122","0.01584"
"103.22400","8.60228","0.01524"
"103.35600","8.61322","0.01454"
"103.48800","8.62416","0.01438"
"103.62000","8.63516","0.01454"
"103.75200","8.64616","0.01440"
"103.88400","8.65723","0.01448"
"104.01600","8.66817","0.01391"
"104.14800","8.67917","0.01501"
"104.28000","8.69023","0.01531"
"104.41200","8.70129","0.01484"
"104.54400","8.71229","0.01562"
"104.67600","8.72317","0.01565"
"104.80800","8.73423","0.01536"
"104.94000","8.74524","0.01493"
"105.07200","8.75624","0.01539"
"105.20400","8.76718","0.01498"
"105.33600","8.77824","0.01512"
"105.46800","8.78924","0.01588"
"105.60000","8.80024","0.01547"
"105.73200","8.81118","0.01644"
"105.86400","8.82224","0.01612"
"105.99600","8.83331","0.01504"
"106.12800","8.84425","0.01473"
"106.26000","8.85519","0.01508"
"106.39200","8.86619","0.01554"
"106.52400","8.87725","0.01564"
"106.65600","8.88819","0.01611"
"106.78800","8.89919","0.01563"
"106.92000","8.91014","0.01577"
"107.05200","8.92126","0.01557"
"107.18400","8.93226","0.01553"
"107.31600","8.94320","0.01585"
"107.44800","8.95420","0.01590"
"107.58000","8.96526","0.01639"
"107.71200","8.97626","0.01566"
"107.84400","8.98720","0.01635"
"107.97600","8.99821","0.01603"
"108.10800","9.00921","0.01665"
"108.24000","9.02021","0.01624"
"108.37200","9.03121","0.01651"
"108.50400","9.04215","0.01630"
"108.63600","9.05327","0.01542"
"108.76800","9.06427","0.01615"
"108.90000","9.07521","0.01670"
"109.03200","9.08615","0.01642"
"109.16400","9.09722","0.01608"
"109.29600","9.10828","0.01705"
"109.42800","9.11928","0.01672"
"109.56000","9.13022","0.01702"
"109.69200","9.14122","0.01749"
"109.82400","9.15222","0.01648"
"109.95600","9.16316","0.01658"
"110.08800","9.17411","0.01714"
"110.22000","9.18523","0.01724"
"110.35200","9.19623","0.01685"
"110.48400","9.20723","0.01685"
"110.61600","9.21817","0.01712"
"110.74800","9.22923","0.01771"
"110.88000","9.24023","0.01754"
"111.01200","9.25123","0.01733"
"111.14400","9.26218","0.01781"
"111.27600","9.27324","0.01786"
"111.40800","9.28424","0.01833"
"111.54000","9.29518","0.01842"
"111.67200","9.30618","0.01799"
"111.80400","9.31718","0.01753"
"111.93600","9.32824","0.01799"
"112.06800","9.33918","0.01819"
"112.20000","9.35019","0.01799"
"112.33200","9.36119","0.01819"
"112.46400","9.37225","0.01784"
"112.59600","9.38319","0.01855"
"112.72800","9.39419","0.01813"
"112.86000","9.40519","0.01862"
"112.99200","9.41619","0.01861"
"113.12400","9.42720","0.01921"
"113.25600","9.43814","0.01891"
"113.38800","9.44920","0.01858"
"113.52000","9.46020","0.01846"
"113.65200","9.47126","0.01837"
"113.78400","9.48220","0.01908"
"113.91600","9.49320","0.01885"
"114.04800","9.50426","0.01938"
"114.18000","9.51521","0.01893"
"114.31200","9.52621","0.01885"
"114.44400","9.53721","0.01917"
"114.57600","9.54827","0.01870"
"114.70800","9.55927","0.01914"
"114.84000","9.57015","0.01885"
"114.97200","9.58115","0.02020"
"115.10400","9.59227","0.01917"
"115.23600","9.60328","0.01936"
"115.36800","9.61416","0.01975"
"115.50000","9.62516","0.01970"
"115.63200","9.63628","0.01980"
"115.76400","9.64722","0.01966"
"115.89600","9.65822","0.01963"
"116.02800","9.66922","0.01971"
"116.16000","9.68022","0.01984"
"116.29200","9.69123","0.01940"
"116.42400","9.70217","0.02033"
"116.55600","9.71311","0.02003"
"116.68800","9.72423","0.01990"
"116.82000","9.73523","0.01986"
"116.95200","9.74617","0.02077"
"117.08400","9.75717","0.02057"
"117.21600","9.76823","0.02049"
"117.34800","9.77924","0.02059"
"117.48000","9.79024","0.02053"
"117.61200","9.80124","0.02094"
"117.74400","9.81224","0.02085"
"117.87600","9.82324","0.02058"
"118.00800","9.83424","0.02124"
"118.14000","9.84518","0.02130"
"118.27200","9.85624","0.02114"
"118.40400","9.86719","0.02028"
"118.53600","9.87819","0.02128"
"118.66800","9.88913","0.02075"
"118.80000","9.90019","0.02099"
"118.93200","9.91125","0.02165"
"119.06400","9.92225","0.02101"
"119.19600","9.93319","0.02127"
"119.32800","9.94419","0.02178"
"119.46000","9.95526","0.02147"
"119.59200","9.96626","0.02142"
"119.72400","9.97720","0.02179"
"119.85600","9.98820","0.02122"
"119.98800","9.99920","0.02108"
"120.12000","10.01020","0.02186"
"120.25200","10.02120","0.02155"
"120.38400","10.03221","0.02195"
"120.51600","10.04327","0.02232"
"120.64800","10.05421","0.02212"
"120.78000","10.06521","0.02131"
"120.91200","10.07621","0.02190"
"121.04400","10.08727","0.02193"
"121.17600","10.09821","0.02225"
"121.30800","10.10915","0.02176"
"121.44000","10.12016","0.02223"
"121.57200","10.13122","0.02216"
"121.70400","10.14222","0.02198"
"121.83600","10.15322","0.02262"
"121.96800","10.16422","0.02214"
"122.10000","10.17528","0.02260"
"122.23200","10.18622","0.02201"
"122.36400","10.19722","0.02183"
"122.49600","10.20823","0.02297"
"122.62800","10.21929","0.02249"
"122.76000","10.23029","0.02256"
"122.89200","10.24117","0.02275"
"123.02400","10.25217","0.02263"
"123.15600","10.26323","0.02258"
"123.28800","10.27423","0.02281"
"123.42000","10.28517","0.02275"
"123.55200","10.29612","0.02281"
"123.68400","10.30724","0.02303"
"123.81600","10.31824","0.02329"
"123.94800","10.32924","0.02307"
"124.08000","10.34012","0.02276"
"124.21200","10.35124","0.02353"
"124.34400","10.36224","0.02292"
"124.47600","10.37324","0.02314"
"124.60800","10.38419","0.02335"
"124.74000","10.39519","0.02312"
"124.87200","10.40625","0.02338"
"125.00400","10.41719","0.02325"
"125.13600","10.42813","0.02375"
"125.26800","10.43919","0.02353"
"125.40000","10.45025","0.02330"
"125.53200","10.46119","0.02296"
"125.66400","10.47214","0.02402"
"125.79600","10.48320","0.02361"
"125.92800","10.49420","0.02404"
"126.06000","10.50526","0.02363"
"126.19200","10.51620","0.02291"
"126.32400","10.52720","0.02418"
"126.45600","10.53820","0.02390"
"126.58800","10.54920","0.02355"
"126.72000","10.56015","0.02400"
"126.85200","10.57121","0.02352"
"126.98400","10.58221","0.02371"
"127.11600","10.59327","0.02383"
"127.24800","10.60415","0.02329"
"127.38000","10.61521","0.02368"
"127.51200","10.62627","0.02340"
"127.64400","10.63728","0.02422"
"127.77600","10.64822","0.02363"
"127.90800","10.65916","0.02386"
"128.04000","10.67028","0.02429"
"128.17200","10.68122","0.02373"
"128.30400","10.69222","0.02415"
"128.43600","10.70322","0.02356"
"128.56800","10.71422","0.02317"
"128.70000","10.72523","0.02371"
"128.83200","10.73617","0.02367"
"128.96400","10.74717","0.02383"
"129.09600","10.75823","0.02279"
"129.22800","10.76923","0.02392"
"129.36000","10.78017","0.02384"
"129.49200","10.79117","0.02285"
"129.62400","10.80223","0.02327"
"129.75600","10.81318","0.02286"
"129.88800","10.82418","0.02355"
"130.02000","10.83518","0.02339"
"130.15200","10.84624","0.02341"
"130.28400","10.85724","0.02361"
"130.41600","10.86824","0.02386"
"130.54800","10.87912","0.02390"
"130.68000","10.89024","0.02367"
"130.81200","10.90125","0.02377"
"130.94400","10.91225","0.02319"
"131.07600","10.92319","0.02446"
"131.20800","10.93425","0.02408"
"131.34000","10.94525","0.02432"
"131.47200","10.95619","0.02353"
"131.60400","10.96713","0.02410"
"131.73600","10.97825","0.02436"
"131.86800","10.98920","0.02422"
"132.00000","11.00026","0.02486"
"132.13200","11.01114","0.02424"
"132.26400","11.02226","0.02248"
"132.39600","11.03320","0.02283"
"132.52800","11.04426","0.02254"
"132.66000","11.05514","0.02302"
"132.79200","11.06626","0.02384"
"132.92400","11.07727","0.02311"
"133.05600","11.08821","0.02379"
"133.18800","11.09921","0.02338"
"133.32000","11.11021","0.02296"
"133.45200","11.12127","0.02331"
"133.58400","11.13221","0.02299"
"133.71600","11.14322","0.02352"
"133.84800","11.15422","0.02322"
"133.98000","11.16522","0.02302"
"134.11200","11.17628","0.02286"
"134.24400","11.18716","0.02356"
"134.37600","11.19822","0.02404"
"134.50800","11.20922","0.02443"
"134.64000","11.22022","0.02367"
"134.77200","11.23116","0.02362"
"134.90400","11.24217","0.02343"
"135.03600","11.25323","0.02362"
"135.16800","11.26423","0.02356"
"135.30000","11.27517","0.02380"
"135.43200","11.28617","0.02375"
"135.56400","11.29723","0.02377"
"135.69600","11.30823","0.02384"
"135.82800","11.31923","0.02343"
"135.96000","11.33018","0.02375"
"136.09200","11.34124","0.02395"
"136.22400","11.35218","0.02416"
"136.35600","11.36318","0.02444"
"136.48800","11.37412","0.02399"
"136.62000","11.38524","0.02433"
"136.75200","11.39618","0.02405"
"136.88400","11.40718","0.02442"
"137.01600","11.41819","0.02441"
"137.14800","11.42925","0.02411"
"137.28000","11.44025","0.02497"
"137.41200","11.45119","0.02506"
"137.54400","11.46219","0.02506"
"137.67600","11.47325","0.02435"
"137.80800","11.48425","0.02503"
"137.94000","11.49519","0.02429"
"138.07200","11.50614","0.02481"
"138.20400","11.51726","0.02465"
"138.33600","11.52820","0.02468"
"138.46800","11.53920","0.02455"
"138.60000","11.55014","0.02484"
"138.73200","11.56120","0.02575"
"138.86400","11.57226","0.02487"
"138.99600","11.58327","0.02539"
"139.12800","11.59421","0.02541"
"139.26000","11.60527","0.02561"
"139.39200","11.61627","0.02524"
"139.52400","11.62721","0.02524"
"139.65600","11.63815","0.02524"
"139.78800","11.64921","0.02541"
"139.92000","11.66021","0.02562"
"140.05200","11.67116","0.02617"
"140.18400","11.68216","0.02579"
"140.31600","11.69322","0.02604"
"140.44800","11.70422","0.02612"
"140.58000","11.71528","0.02618"
"140.71200","11.72616","0.02595"
"140.84400","11.73722","0.02608"
"140.97600","11.74829","0.02539"
"141.10800","11.75922","0.02594"
"141.24000","11.77023","0.02638"
"141.37200","11.78123","0.02696"
"141.50400","11.79229","0.02616"
"141.63600","11.80323","0.02666"
"141.76800","11.81417","0.02686"
"141.90000","11.82517","0.02629"
"142.03200","11.83623","0.02641"
"142.16400","11.84724","0.02651"
"142.29600","11.85824","0.02691"
"142.42800","11.86924","0.02661"
"142.56000","11.88024","0.02695"
"142.69200","11.89130","0.02719"
"142.82400","11.90218","0.02729"
"142.95600","11.91318","0.02689"
"143.08800","11.92424","0.02706"
"143.22000","11.93525","0.02768"
"143.35200","11.94619","0.02779"
"143.48400","11.95719","0.02738"
"143.61600","11.96825","0.02757"
"143.74800","11.97925","0.02770"
"143.88000","11.99025","0.02710"
"144.01200","12.00119","0.02743"
"144.14400","12.01225","0.02769"
"144.27600","12.02326","0.02757"
"144.40800","12.03420","0.02831"
"144.54000","12.04514","0.02800"
"144.67200","12.05620","0.02803"
"144.80400","12.06726","0.02799"
"144.93600","12.07820","0.02844"
"145.06800","12.08920","0.02818"
"145.20000","12.10020","0.02818"
"145.33200","12.11121","0.02865"
"145.46400","12.12221","0.02852"
"145.59600","12.13321","0.02846"
"145.72800","12.14427","0.02837"
"145.86000","12.15527","0.02834"
"145.99200","12.16621","0.02919"
"146.12400","12.17715","0.02865"
"146.25600","12.18822","0.02893"
"146.38800","12.19922","0.02914"
"146.52000","12.21016","0.02850"
"146.65200","12.22116","0.02923"
"146.78400","12.23216","0.02937"
"146.91600","12.24322","0.02882"
"147.04800","12.25416","0.02920"
"147.18000","12.26523","0.02918"
"147.31200","12.27623","0.02955"
"147.44400","12.28729","0.02912"
"147.57600","12.29823","0.02940"
"147.70800","12.30917","0.02909"
"147.84000","12.32023","0.02972"
"147.97200","12.33123","0.02976"
"148.10400","12.34223","0.02938"
"148.23600","12.35317","0.02964"
"148.36800","12.36418","0.02974"
"148.50000","12.37524","0.02963"
"148.63200","12.38624","0.02972"
"148.76400","12.39718","0.03003"
"148.89600","12.40818","0.02957"
"149.02800","12.41924","0.02975"
"149.16000","12.43024","0.03012"
"149.29200","12.44112","0.02985"
"149.42400","12.45219","0.03022"
"149.55600","12.46325","0.03057"
"149.68800","12.47419","0.03058"
"149.82000","12.48519","0.03012"
"149.95200","12.49613","0.03052"
"150.08400","12.50725","0.03006"
"150.21600","12.51826","0.03038"
"150.34800","12.52919","0.03085"
"150.48000","12.54020","0.03090"
"150.61200","12.55126","0.03026"
"150.74400","12.56226","0.03094"
"150.87600","12.57320","0.03031"
"151.00800","12.58420","0.03013"
"151.14000","12.59520","0.03110"
"151.27200","12.60620","0.03080"
"151.40400","12.61721","0.03100"
"151.53600","12.62815","0.03101"
"151.66800","12.63927","0.03069"
"151.80000","12.65021","0.03076"
"151.93200","12.66127","0.03111"
"152.06400","12.67221","0.03167"
"152.19600","12.68327","0.03165"
"152.32800","12.69427","0.03118"
"152.46000","12.70522","0.03169"
"152.59200","12.71616","0.03141"
"152.72400","12.72722","0.03157"
"152.85600","12.73822","0.03173"
"152.98800","12.74922","0.03174"
"153.12000","12.76016","0.03141"
"153.25200","12.77122","0.03201"
"153.38400","12.78223","0.03141"
"153.51600","12.79323","0.03201"
"153.64800","12.80423","0.03183"
"153.78000","12.81523","0.03189"
"153.91200","12.82623","0.03077"
"154.04400","12.83723","0.03127"
"154.17600","12.84817","0.03150"
"154.30800","12.85917","0.03163"
"154.44000","12.87024","0.03176"
"154.57200","12.88124","0.03171"
"154.70400","12.89218","0.03198"
"154.83600","12.90318","0.03248"
"154.96800","12.91424","0.03198"
"155.10000","12.92518","0.03230"
"155.23200","12.93618","0.03206"
"155.36400","12.94718","0.03215"
"155.49600","12.95825","0.03238"
"155.62800","12.96925","0.03204"
"155.76000","12.98025","0.03214"
"155.89200","12.99125","0.03180"
"156.02400","13.00225","0.03277"
"156.15600","13.01319","0.03217"
"156.28800","13.02413","0.03264"
"156.42000","13.03520","0.03290"
"156.55200","13.04626","0.03295"
"156.68400","13.05726","0.03270"
"156.81600","13.06820","0.03290"
"156.94800","13.07920","0.03233"
"157.08000","13.09026","0.03270"
"157.21200","13.10126","0.03326"
"157.34400","13.11220","0.03286"
"157.47600","13.12321","0.03291"
"157.60800","13.13426","0.03255"
"157.74000","13.14527","0.03302"
"157.87200","13.15621","0.03347"
"158.00400","13.16715","0.03356"
"158.13600","13.17827","0.03357"
"158.26800","13.18927","0.03319"
"158.40000","13.20021","0.03298"
"158.53200","13.21115","0.03377"
"158.66400","13.22228","0.03366"
"158.79600","13.23328","0.03334"
"158.92800","13.24422","0.03377"
"159.06000","13.25522","0.03365"
"159.19200","13.26622","0.03403"
"159.32400","13.27722","0.03364"
"159.45600","13.28816","0.03356"
"159.58800","13.29910","0.03407"
"159.72000","13.31017","0.03354"
"159.85200","13.32117","0.03384"
"159.98400","13.33223","0.03366"
"160.11600","13.34317","0.03342"
"160.24800","13.35423","0.03365"
"160.38000","13.36523","0.03435"
"160.51200","13.37623","0.03458"
"160.64400","13.38724","0.03443"
"160.77600","13.39824","0.03391"
"160.90800","13.40924","0.03470"
"161.04000","13.42024","0.03476"
"161.17200","13.43118","0.03479"
"161.30400","13.44218","0.03515"
"161.43600","13.45324","0.03471"
"161.56800","13.46424","0.03208"
"161.70000","13.47519","0.03281"
"161.83200","13.48619","0.03255"
"161.96400","13.49725","0.03290"
"162.09600","13.50819","0.03316"
"162.22800","13.51919","0.03288"
"162.36000","13.53019","0.03278"
"162.49200","13.54119","0.03321"
"162.62400","13.55220","0.03334"
"162.75600","13.56320","0.03358"
"162.88800","13.57414","0.03342"
"163.02000","13.58526","0.03363"
"163.15200","13.59620","0.03281"
"163.28400","13.60720","0.03319"
"163.41600","13.61820","0.03327"
"163.54800","13.62926","0.03381"
"163.68000","13.64021","0.03323"
"163.81200","13.65121","0.03329"
"163.94400","13.66221","0.03303"
"164.07600","13.67321","0.03348"
"164.20800","13.68421","0.03462"
"164.34000","13.69515","0.03357"
"164.47200","13.70615","0.03368"
"164.60400","13.71721","0.03407"
"164.73600","13.72822","0.03335"
"164.86800","13.73922","0.03407"
"165.00000","13.75022","0.03390"
"165.13200","13.76128","0.03437"
"165.26400","13.77228","0.03382"
"165.39600","13.78322","0.03483"
"165.52800","13.79416","0.03410"
"165.66000","13.80528","0.03423"
"165.79200","13.81623","0.03513"
"165.92400","13.82723","0.03454"
"166.05600","13.83817","0.03504"
"166.18800","13.84923","0.03441"
"166.32000","13.86023","0.03408"
"166.45200","13.87123","0.03434"
"166.58400","13.88217","0.03446"
"166.71600","13.89323","0.03441"
"166.84800","13.90424","0.03431"
"166.98000","13.91524","0.03470"
"167.11200","13.92618","0.03495"
"167.24400","13.93724","0.03477"
"167.37600","13.94824","0.03535"
"167.50800","13.95924","0.03472"
"167.64000","13.97012","0.03540"
"167.77200","13.98118","0.03495"
"167.90400","13.99219","0.03559"
"168.03600","14.00319","0.03506"
"168.16800","14.01419","0.03420"
"168.30000","14.02519","0.03512"
"168.43200","14.03625","0.03516"
"168.56400","14.04725","0.03528"
"168.69600","14.05819","0.03565"
"168.82800","14.06926","0.03580"
"168.96000","14.08026","0.03604"
"169.09200","14.09126","0.03524"
"169.22400","14.10220","0.03578"
"169.35600","14.11320","0.03552"
"169.48800","14.12426","0.03585"
"169.62000","14.13526","0.03598"
"169.75200","14.14620","0.03632"
"169.88400","14.15721","0.03578"
"170.01600","14.16821","0.03642"
"170.14800","14.17927","0.03622"
"170.28000","14.19021","0.03657"
"170.41200","14.20121","0.03656"
"170.54400","14.21227","0.03679"
"170.67600","14.22321","0.03672"
"170.80800","14.23421","0.03622"
"170.94000","14.24516","0.03648"
"171.07200","14.25622","0.03636"
"171.20400","14.26722","0.03651"
"171.33600","14.27822","0.03688"
"171.46800","14.28916","0.03719"
"171.60000","14.30022","0.03699"
"171.73200","14.31122","0.03705"
"171.86400","14.32222","0.03696"
"171.99600","14.33323","0.03717"
"172.12800","14.34429","0.03751"
"172.26000","14.35523","0.03725"
"172.39200","14.36617","0.03773"
"172.52400","14.37717","0.03655"
"172.65600","14.38823","0.03678"
"172.78800","14.39917","0.03639"
"172.92000","14.41018","0.03685"
"173.05200","14.42118","0.03718"
"173.18400","14.43224","0.03717"
"173.31600","14.44324","0.03770"
"173.44800","14.45424","0.03730"
"173.58000","14.46518","0.03736"
"173.71200","14.47624","0.03717"
"173.84400","14.48724","0.03756"
"173.97600","14.49819","0.03740"
"174.10800","14.50913","0.03673"
"174.24000","14.52025","0.03739"
"174.37200","14.53119","0.03723"
"174.50400","14.54219","0.03688"
"174.63600","14.55313","0.03661"
"174.76800","14.56425","0.03724"
"174.90000","14.57519","0.03713"
"175.03200","14.58625","0.03699"
"175.16400","14.59720","0.03725"
"175.29600","14.60826","0.03748"
"175.42800","14.61926","0.03731"
"175.56000","14.63026","0.03736"
"175.69200","14.64120","0.03774"
"175.82400","14.65220","0.03773"
"175.95600","14.66326","0.03719"
"176.08800","14.67421","0.03814"
"176.22000","14.68521","0.03798"
"176.35200","14.69615","0.03809"
"176.48400","14.70721","0.03784"
"176.61600","14.71827","0.03793"
"176.74800","14.72915","0.03858"
"176.88000","14.74021","0.03815"
"177.01200","14.75121","0.03840"
"177.14400","14.76227","0.03793"
"177.27600","14.77322","0.03821"
"177.40800","14.78422","0.03823"
"177.54000","14.79522","0.03864"
"177.67200","14.80622","0.03885"
"177.80400","14.81722","0.03843"
"177.93600","14.82822","0.03903"
"178.06800","14.83922","0.03897"
"178.20000","14.85028","0.03892"
"178.33200","14.86117","0.03938"
"178.46400","14.87223","0.03900"
"178.59600","14.88329","0.03864"
"178.72800","14.89423","0.03913"
"178.86000","14.90523","0.03910"
"178.99200","14.91617","0.03809"
"179.12400","14.92723","0.03852"
"179.25600","14.93824","0.03838"
"179.38800","14.94918","0.03922"
"179.52000","14.96012","0.03930"
"179.65200","14.97124","0.03880"
"179.78400","14.98224","0.03927"
"179.91600","14.99318","0.03858"
"180.04800","15.00418","0.03954"
"180.18000","15.01518","0.03891"
"180.31200","15.02625","0.03825"
"180.44400","15.03725","0.03807"
"180.57600","15.04819","0.03787"
"180.70800","15.05919","0.03848"
"180.84000","15.07019","0.03843"
"180.97200","15.08113","0.03602"
"181.10400","15.09219","0.03579"
"181.23600","15.10325","0.03676"
"181.36800","15.11426","0.03705"
"181.50000","15.12520","0.03779"
"181.63200","15.13620","0.03739"
"181.76400","15.14720","0.03722"
"181.89600","15.15826","0.03771"
"182.02800","15.16926","0.03562"
"182.16000","15.18020","0.03483"
"182.29200","15.19121","0.03488"
"182.42400","15.20221","0.03595"
"182.55600","15.21321","0.03625"
"182.68800","15.22415","0.03579"
"182.82000","15.23521","0.03657"
"182.95200","15.24621","0.03659"
"183.08400","15.25721","0.03702"
"183.21600","15.26815","0.03698"
"183.34800","15.27921","0.03774"
"183.48000","15.29028","0.03760"
"183.61200","15.30128","0.03807"
"183.74400","15.31222","0.03822"
"183.87600","15.32322","0.03762"
"184.00800","15.33428","0.03891"
"184.14000","15.34522","0.03867"
"184.27200","15.35616","0.03856"
"184.40400","15.36717","0.03929"
"184.53600","15.37829","0.03958"
"184.66800","15.38923","0.03924"
"184.80000","15.40017","0.03914"
"184.93200","15.41117","0.03929"
"185.06400","15.42223","0.03893"
"185.19600","15.43323","0.03948"
"185.32800","15.44417","0.03970"
"185.46000","15.45518","0.03910"
"185.59200","15.46624","0.03822"
"185.72400","15.47724","0.03761"
"185.85600","15.48818","0.03858"
"185.98800","15.49912","0.03787"
"186.12000","15.51024","0.03758"
"186.25200","15.52124","0.03859"
"186.38400","15.53218","0.03847"
"186.51600","15.54319","0.03864"
"186.64800","15.55425","0.03907"
"186.78000","15.56525","0.03825"
"186.91200","15.57625","0.03661"
"187.04400","15.58719","0.03689"
"187.17600","15.59819","0.03794"
"187.30800","15.60919","0.03759"
"187.44000","15.62013","0.03819"
"187.57200","15.63114","0.03784"
"187.70400","15.64220","0.03780"
"187.83600","15.65320","0.03802"
"187.96800","15.66420","0.03855"
"188.10000","15.67514","0.03869"
"188.23200","15.68620","0.03893"
"188.36400","15.69726","0.03926"
"188.49600","15.70826","0.03904"
"188.62800","15.71920","0.03934"
"188.76000","15.73021","0.04005"
"188.89200","15.74127","0.03961"
"189.02400","15.75221","0.03961"
"189.15600","15.76321","0.04031"
"189.28800","15.77421","0.03996"
"189.42000","15.78521","0.04053"
"189.55200","15.79621","0.04069"
"189.68400","15.80722","0.04041"
"189.81600","15.81816","0.04062"
"189.94800","15.82928","0.04059"
"190.08000","15.84022","0.04066"
"190.21200","15.85116","0.03954"
"190.34400","15.86222","0.04000"
"190.47600","15.87322","0.04089"
"190.60800","15.88422","0.04050"
"190.74000","15.89517","0.04061"
"190.87200","15.90623","0.04068"
"191.00400","15.91723","0.04080"
"191.13600","15.92823","0.04067"
"191.26800","15.93917","0.04164"
"191.40000","15.95017","0.04171"
"191.53200","15.96123","0.04165"
"191.66400","15.97224","0.04122"
"191.79600","15.98318","0.04198"
"191.92800","15.99424","0.04208"
"192.06000","16.00530","0.04295"
"192.19200","16.01630","0.04265"
"192.32400","16.02718","0.04259"
"192.45600","16.03818","0.04307"
"192.58800","16.04924","0.04319"
"192.72000","16.06025","0.04276"
"192.82800","16.06921","0.04320"