File: Force_trajectories/170226_1/Specimen_RawData_8.csv
End date,"2/26/2017"
Specimen label,"6AT_44"
Maximum Load,"0.06217",N

Time,Extension,Load
(s),(mm),(N)
"0.00000","0.00000","0.00004"
"0.27600","0.02218","-0.00006"
"0.55200","0.04622","0.00100"
"0.82800","0.06918","0.00076"
"1.10400","0.09220","0.00171"
"1.38000","0.11521","0.00170"
"1.65600","0.13817","0.00209"
"1.93200","0.16113","0.00210"
"2.20800","0.18415","0.00237"
"2.48400","0.20717","0.00253"
"2.76000","0.23019","0.00217"
"3.03600","0.25321","0.00259"
"3.31200","0.27617","0.00273"
"3.58800","0.29919","0.00296"
"3.86400","0.32209","0.00272"
"4.14000","0.34522","0.00294"
"4.41600","0.36812","0.00295"
"4.69200","0.39120","0.00306"
"4.96800","0.41416","0.00278"
"5.24400","0.43724","0.00369"
"5.52000","0.46014","0.00354"
"5.79600","0.48316","0.00466"
"6.07200","0.50612","0.00418"
"6.34800","0.52920","0.00423"
"6.62400","0.55210","0.00424"
"6.90000","0.57518","0.00522"
"7.17600","0.59813","0.00442"
"7.45200","0.62115","0.00486"
"7.72800","0.64411","0.00497"
"8.00400","0.66719","0.00454"
"8.28000","0.69015","0.00466"
"8.55600","0.71317","0.00597"
"8.83200","0.73619","0.00565"
"9.10800","0.75921","0.00544"
"9.38400","0.78217","0.00571"
"9.66000","0.80519","0.00553"
"9.93600","0.82814","0.00556"
"10.21200","0.85122","0.00589"
"10.48800","0.87418","0.00583"
"10.76400","0.89720","0.00571"
"11.04000","0.92016","0.00623"
"11.31600","0.94318","0.00625"
"11.59200","0.96620","0.00605"
"11.86800","0.98922","0.00619"
"12.14400","1.01218","0.00672"
"12.42000","1.03520","0.00686"
"12.69600","1.05821","0.00690"
"12.97200","1.08117","0.00650"
"13.24800","1.10419","0.00693"
"13.52400","1.12715","0.00751"
"13.80000","1.15017","0.00783"
"14.07600","1.17319","0.00668"
"14.35200","1.19621","0.00762"
"14.62800","1.21917","0.00740"
"14.90400","1.24219","0.00780"
"15.18000","1.26515","0.00739"
"15.45600","1.28823","0.00758"
"15.73200","1.31118","0.00828"
"16.00800","1.33420","0.00800"
"16.28400","1.35716","0.00793"
"16.56000","1.38018","0.00746"
"16.83600","1.40314","0.00849"
"17.11200","1.42616","0.00868"
"17.38800","1.44906","0.00810"
"17.66400","1.47220","0.00836"
"17.94000","1.49510","0.00883"
"18.21600","1.51818","0.00915"
"18.49200","1.54114","0.00799"
"18.76800","1.56421","0.00833"
"19.04400","1.58717","0.00887"
"19.32000","1.61019","0.00875"
"19.59600","1.63315","0.00975"
"19.87200","1.65617","0.00879"
"20.14800","1.67913","0.01039"
"20.42400","1.70221","0.00940"
"20.70000","1.72517","0.00942"
"20.97600","1.74819","0.00836"
"21.25200","1.77115","0.00902"
"21.52800","1.79416","0.00880"
"21.80400","1.81718","0.00889"
"22.08000","1.84020","0.00891"
"22.35600","1.86316","0.00924"
"22.63200","1.88618","0.00944"
"22.90800","1.90920","0.00910"
"23.18400","1.93222","0.00931"
"23.46000","1.95524","0.00903"
"23.73600","1.97814","0.00914"
"24.01200","2.00122","0.00923"
"24.28800","2.02417","0.00947"
"24.56400","2.04713","0.00927"
"24.84000","2.07009","0.00930"
"25.11600","2.09317","0.00986"
"25.39200","2.11613","0.01016"
"25.66800","2.13921","0.00959"
"25.94400","2.16211","0.00957"
"26.22000","2.18519","0.01014"
"26.49600","2.20815","0.01011"
"26.77200","2.23123","0.00954"
"27.04800","2.25413","0.01023"
"27.32400","2.27720","0.00952"
"27.60000","2.30010","0.00974"
"27.87600","2.32318","0.00992"
"28.15200","2.34608","0.01029"
"28.42800","2.36916","0.00966"
"28.70400","2.39212","0.01010"
"28.98000","2.41520","0.01051"
"29.25600","2.43816","0.01056"
"29.53200","2.46124","0.00992"
"29.80800","2.48420","0.01024"
"30.08400","2.50721","0.00994"
"30.36000","2.53017","0.00961"
"30.63600","2.55319","0.00964"
"30.91200","2.57615","0.00948"
"31.18800","2.59917","0.01003"
"31.46400","2.62213","0.01025"
"31.74000","2.64521","0.01016"
"32.01600","2.66817","0.00980"
"32.29200","2.69113","0.01016"
"32.56800","2.71415","0.01047"
"32.84400","2.73716","0.00995"
"33.12000","2.76018","0.01051"
"33.39600","2.78320","0.00980"
"33.67200","2.80622","0.00996"
"33.94800","2.82924","0.00987"
"34.22400","2.85226","0.00913"
"34.50000","2.87516","0.00998"
"34.77600","2.89818","0.00983"
"35.05200","2.92120","0.01068"
"35.32800","2.94422","0.01089"
"35.60400","2.96712","0.01077"
"35.88000","2.99025","0.01079"
"36.15600","3.01315","0.01095"
"36.43200","3.03623","0.00935"
"36.70800","3.05913","0.00918"
"36.98400","3.08221","0.01024"
"37.26000","3.10517","0.01011"
"37.53600","3.12825","0.00973"
"37.81200","3.15115","0.01053"
"38.08800","3.17417","0.01076"
"38.36400","3.19713","0.01059"
"38.64000","3.22020","0.01100"
"38.91600","3.24316","0.01098"
"39.19200","3.26618","0.01127"
"39.46800","3.28914","0.01112"
"39.74400","3.31222","0.01129"
"40.02000","3.33512","0.01068"
"40.29600","3.35820","0.01167"
"40.57200","3.38116","0.01106"
"40.84800","3.40418","0.01019"
"41.12400","3.42720","0.01029"
"41.40000","3.45021","0.01085"
"41.67600","3.47317","0.01071"
"41.95200","3.49619","0.01044"
"42.22800","3.51915","0.01048"
"42.50400","3.54217","0.01111"
"42.78000","3.56519","0.01134"
"43.05600","3.58821","0.01110"
"43.33200","3.61117","0.01128"
"43.60800","3.63419","0.01171"
"43.88400","3.65721","0.01142"
"44.16000","3.68017","0.00960"
"44.43600","3.70318","0.01070"
"44.71200","3.72620","0.01036"
"44.98800","3.74922","0.01070"
"45.26400","3.77212","0.01054"
"45.54000","3.79520","0.01024"
"45.81600","3.81810","0.01085"
"46.09200","3.84118","0.01032"
"46.36800","3.86414","0.01132"
"46.64400","3.88722","0.01150"
"46.92000","3.91012","0.01159"
"47.19600","3.93319","0.01180"
"47.47200","3.95615","0.01149"
"47.74800","3.97917","0.01212"
"48.02400","4.00213","0.01197"
"48.30000","4.02515","0.01232"
"48.57600","4.04811","0.01207"
"48.85200","4.07119","0.01228"
"49.12800","4.09415","0.01264"
"49.40400","4.11717","0.01279"
"49.68000","4.14007","0.01300"
"49.95600","4.16315","0.01262"
"50.23200","4.18616","0.01250"
"50.50800","4.20918","0.01276"
"50.78400","4.23214","0.01286"
"51.06000","4.25522","0.01125"
"51.33600","4.27818","0.01094"
"51.61200","4.30120","0.01178"
"51.88800","4.32416","0.01220"
"52.16400","4.34724","0.01230"
"52.44000","4.37020","0.01312"
"52.71600","4.39322","0.01329"
"52.99200","4.41611","0.01340"
"53.26800","4.43919","0.01363"
"53.54400","4.46215","0.01355"
"53.82000","4.48517","0.01396"
"54.09600","4.50813","0.01430"
"54.37200","4.53121","0.01401"
"54.64800","4.55417","0.01465"
"54.92400","4.57719","0.01426"
"55.20000","4.60021","0.01425"
"55.47600","4.62323","0.01461"
"55.75200","4.64618","0.01423"
"56.02800","4.66914","0.01396"
"56.30400","4.69222","0.01429"
"56.58000","4.71518","0.01424"
"56.85600","4.73820","0.01441"
"57.13200","4.76116","0.01387"
"57.40800","4.78418","0.01446"
"57.68400","4.80714","0.01388"
"57.96000","4.83022","0.01441"
"58.23600","4.85312","0.01441"
"58.51200","4.87619","0.01464"
"58.78800","4.89915","0.01391"
"59.06400","4.92223","0.01408"
"59.34000","4.94513","0.01428"
"59.61600","4.96815","0.01446"
"59.89200","4.99111","0.01463"
"60.16800","5.01419","0.01418"
"60.44400","5.03709","0.01497"
"60.72000","5.06017","0.01487"
"60.99600","5.08307","0.01500"
"61.27200","5.10615","0.01434"
"61.54800","5.12911","0.01427"
"61.82400","5.15224","0.01458"
"62.10000","5.17520","0.01491"
"62.37600","5.19822","0.01544"
"62.65200","5.22118","0.01548"
"62.92800","5.24426","0.01590"
"63.20400","5.26716","0.01624"
"63.48000","5.29018","0.01531"
"63.75600","5.31320","0.01594"
"64.03200","5.33622","0.01693"
"64.30800","5.35912","0.01670"
"64.58400","5.38213","0.01725"
"64.86000","5.40515","0.01689"
"65.13600","5.42817","0.01717"
"65.41200","5.45119","0.01723"
"65.68800","5.47421","0.01772"
"65.96400","5.49717","0.01823"
"66.24000","5.52019","0.01751"
"66.51600","5.54321","0.01815"
"66.79200","5.56617","0.01869"
"67.06800","5.58919","0.01834"
"67.34400","5.61214","0.01898"
"67.62000","5.63516","0.01822"
"67.89600","5.65812","0.01841"
"68.17200","5.68120","0.01841"
"68.44800","5.70416","0.01854"
"68.72400","5.72718","0.01866"
"69.00000","5.75014","0.01916"
"69.27600","5.77322","0.01958"
"69.55200","5.79612","0.01904"
"69.82800","5.81926","0.01923"
"70.10400","5.84215","0.01930"
"70.38000","5.86517","0.01954"
"70.65600","5.88813","0.02028"
"70.93200","5.91115","0.02040"
"71.20800","5.93411","0.02053"
"71.48400","5.95719","0.02088"
"71.76000","5.98015","0.02060"
"72.03600","6.00323","0.02117"
"72.31200","6.02619","0.02178"
"72.58800","6.04921","0.02274"
"72.86400","6.07217","0.02243"
"73.14000","6.09518","0.02260"
"73.41600","6.11820","0.02265"
"73.69200","6.14122","0.02301"
"73.96800","6.16418","0.02258"
"74.24400","6.18714","0.02288"
"74.52000","6.21016","0.02247"
"74.79600","6.23318","0.02295"
"75.07200","6.25620","0.02400"
"75.34800","6.27922","0.02300"
"75.62400","6.30218","0.02292"
"75.90000","6.32514","0.02224"
"76.17600","6.34821","0.02312"
"76.45200","6.37117","0.02287"
"76.72800","6.39419","0.02412"
"77.00400","6.41721","0.02362"
"77.28000","6.44023","0.02375"
"77.55600","6.46313","0.02395"
"77.83200","6.48621","0.02433"
"78.10800","6.50911","0.02477"
"78.38400","6.53219","0.02410"
"78.66000","6.55514","0.02339"
"78.93600","6.57822","0.02364"
"79.21200","6.60118","0.02429"
"79.48800","6.62420","0.02473"
"79.76400","6.64716","0.02323"
"80.04000","6.67018","0.02380"
"80.31600","6.69308","0.02461"
"80.59200","6.71616","0.02541"
"80.86800","6.73918","0.02656"
"81.14400","6.76220","0.02703"
"81.42000","6.78516","0.02733"
"81.69600","6.80817","0.02766"
"81.97200","6.83107","0.02754"
"82.24800","6.85415","0.02700"
"82.52400","6.87711","0.02742"
"82.80000","6.90019","0.02574"
"83.07600","6.92315","0.02605"
"83.35200","6.94617","0.02560"
"83.62800","6.96913","0.02578"
"83.90400","6.99215","0.02570"
"84.18000","7.01517","0.02607"
"84.45600","7.03818","0.02666"
"84.73200","7.06120","0.02666"
"85.00800","7.08422","0.02705"
"85.28400","7.10718","0.02676"
"85.56000","7.13020","0.02621"
"85.83600","7.15316","0.02762"
"86.11200","7.17612","0.02810"
"86.38800","7.19920","0.02762"
"86.66400","7.22216","0.02746"
"86.94000","7.24518","0.02825"
"87.21600","7.26820","0.02738"
"87.49200","7.29121","0.02723"
"87.76800","7.31417","0.02632"
"88.04400","7.33719","0.02190"
"88.32000","7.36015","0.01998"
"88.59600","7.38317","0.01371"
"88.87200","7.40613","0.01424"
"89.14800","7.42915","0.01421"
"89.42400","7.45211","0.01500"
"89.70000","7.47519","0.01483"
"89.97600","7.49809","0.01184"
"90.25200","7.52116","0.01238"
"90.52800","7.54412","0.01247"
"90.80400","7.56720","0.01300"
"91.08000","7.59016","0.01314"
"91.35600","7.61318","0.01361"
"91.63200","7.63614","0.01348"
"91.90800","7.65922","0.01391"
"92.18400","7.68212","0.01431"
"92.46000","7.70520","0.01356"
"92.73600","7.72810","0.01426"
"93.01200","7.75117","0.01240"
"93.28800","7.77407","0.01181"
"93.56400","7.79715","0.01199"
"93.84000","7.82011","0.01269"
"94.11600","7.84319","0.01202"
"94.39200","7.86615","0.01263"
"94.66800","7.88917","0.01237"
"94.94400","7.91219","0.01292"
"95.22000","7.93521","0.01246"
"95.49600","7.95823","0.01238"
"95.77200","7.98118","0.01232"
"96.04800","8.00420","0.01176"
"96.32400","8.02716","0.01123"
"96.60000","8.05012","0.01115"
"96.87600","8.07314","0.01091"
"97.15200","8.09616","0.01078"
"97.42800","8.11912","0.01073"
"97.70400","8.14220","0.01145"
"97.98000","8.16516","0.01124"
"98.25600","8.18824","0.01100"
"98.53200","8.21119","0.01056"
"98.80800","8.23421","0.01028"
"99.08400","8.25717","0.01057"
"99.36000","8.28019","0.01035"
"99.63600","8.30315","0.01107"
"99.91200","8.32617","0.01115"
"100.18800","8.34919","0.01110"
"100.46400","8.37221","0.01176"
"100.74000","8.39517","0.01162"
"101.01600","8.41819","0.01170"
"101.29200","8.44115","0.01165"
"101.56800","8.46416","0.01241"
"101.84400","8.48712","0.01228"
"102.12000","8.51020","0.01313"
"102.39600","8.53316","0.01309"
"102.67200","8.55624","0.01294"
"102.94800","8.57914","0.01400"
"103.22400","8.60216","0.01352"
"103.50000","8.62512","0.01298"
"103.77600","8.64820","0.01366"
"104.05200","8.67116","0.01401"
"104.32800","8.69418","0.01405"
"104.60400","8.71713","0.01339"
"104.88000","8.74021","0.01329"
"105.15600","8.76317","0.01420"
"105.43200","8.78619","0.01371"
"105.70800","8.80921","0.01311"
"105.98400","8.83223","0.01382"
"106.26000","8.85519","0.01405"
"106.53600","8.87821","0.01421"
"106.81200","8.90117","0.01466"
"107.08800","8.92419","0.01473"
"107.36400","8.94715","0.01409"
"107.64000","8.97022","0.01310"
"107.91600","8.99318","0.01331"
"108.19200","9.01620","0.01336"
"108.46800","9.03916","0.01362"
"108.74400","9.06218","0.01390"
"109.02000","9.08520","0.01444"
"109.29600","9.10822","0.01446"
"109.57400","9.13142","0.01488"
"109.85000","9.15432","0.01519"
"110.12600","9.17739","0.01433"
"110.40200","9.20029","0.01445"
"110.67800","9.22337","0.01422"
"110.95400","9.24627","0.01458"
"111.23000","9.26935","0.01480"
"111.50600","9.29231","0.01538"
"111.78200","9.31533","0.01275"
"112.05800","9.33823","0.01386"
"112.33400","9.36137","0.01406"
"112.61000","9.38433","0.01357"
"112.88600","9.40740","0.01394"
"113.16200","9.43030","0.01332"
"113.43800","9.45338","0.01332"
"113.71400","9.47634","0.01396"
"113.99000","9.49936","0.01505"
"114.26600","9.52226","0.01501"
"114.54200","9.54534","0.01484"
"114.81800","9.56830","0.01539"
"115.09400","9.59138","0.01599"
"115.37000","9.61434","0.01586"
"115.64600","9.63741","0.01618"
"115.92200","9.66031","0.01619"
"116.19800","9.68339","0.01683"
"116.47400","9.70629","0.01674"
"116.75000","9.72931","0.01693"
"117.02600","9.75233","0.01724"
"117.30200","9.77535","0.01637"
"117.57800","9.79831","0.01723"
"117.85400","9.82133","0.01736"
"118.13000","9.84435","0.01840"
"118.40600","9.86731","0.01943"
"118.68200","9.89032","0.01833"
"118.95800","9.91328","0.01926"
"119.23400","9.93636","0.01925"
"119.51000","9.95932","0.01972"
"119.78600","9.98240","0.01921"
"120.06200","10.00530","0.01956"
"120.33800","10.02838","0.01716"
"120.61400","10.05134","0.01634"
"120.89000","10.07436","0.01752"
"121.16600","10.09732","0.01778"
"121.44200","10.12033","0.01782"
"121.71800","10.14329","0.01765"
"121.99400","10.16631","0.01825"
"122.27000","10.18927","0.01957"
"122.54600","10.21235","0.01974"
"122.82200","10.23531","0.01995"
"123.09800","10.25839","0.02039"
"123.37400","10.28129","0.01928"
"123.65000","10.30443","0.02002"
"123.92600","10.32733","0.02030"
"124.20200","10.35035","0.02114"
"124.47800","10.37330","0.02154"
"124.75400","10.39632","0.02158"
"125.03000","10.41928","0.02170"
"125.30600","10.44230","0.02148"
"125.58200","10.46526","0.02125"
"125.85800","10.48834","0.02143"
"126.13400","10.51130","0.02120"
"126.41000","10.53438","0.02102"
"126.68600","10.55728","0.01884"
"126.96200","10.58036","0.01906"
"127.23800","10.60337","0.01953"
"127.51400","10.62633","0.01883"
"127.79000","10.64935","0.01936"
"128.06600","10.67237","0.01936"
"128.34200","10.69533","0.02005"
"128.61800","10.71835","0.02057"
"128.89400","10.74137","0.02130"
"129.17000","10.76433","0.02097"
"129.44600","10.78735","0.02116"
"129.72200","10.81036","0.02199"
"129.99800","10.83339","0.02201"
"130.27400","10.85634","0.02214"
"130.55000","10.87942","0.02198"
"130.82600","10.90238","0.02380"
"131.10200","10.92540","0.02305"
"131.37800","10.94830","0.02396"
"131.65400","10.97138","0.02427"
"131.93000","10.99434","0.02412"
"132.20600","11.01736","0.02351"
"132.48200","11.04032","0.02332"
"132.75800","11.06334","0.02347"
"133.03400","11.08630","0.02384"
"133.31000","11.10931","0.02356"
"133.58600","11.13233","0.02341"
"133.86200","11.15535","0.02381"
"134.13800","11.17831","0.02437"
"134.41400","11.20139","0.02533"
"134.69000","11.22435","0.02549"
"134.96600","11.24737","0.02534"
"135.24200","11.27033","0.02612"
"135.51800","11.29335","0.02634"
"135.79400","11.31631","0.02646"
"136.07000","11.33938","0.02732"
"136.34600","11.36234","0.02663"
"136.62200","11.38536","0.01604"
"136.89800","11.40826","0.01499"
"137.17400","11.43134","0.01584"
"137.45000","11.45436","0.01690"
"137.72600","11.47732","0.01677"
"138.00200","11.50034","0.01761"
"138.27800","11.52342","0.01774"
"138.55400","11.54638","0.01929"
"138.83000","11.56939","0.01916"
"139.10600","11.59235","0.02047"
"139.38200","11.61537","0.02063"
"139.65800","11.63833","0.02059"
"139.93400","11.66135","0.02056"
"140.21000","11.68431","0.02161"
"140.48600","11.70733","0.02227"
"140.76200","11.73035","0.02265"
"141.03800","11.75337","0.02008"
"141.31400","11.77639","0.01851"
"141.59000","11.79941","0.02029"
"141.86600","11.82242","0.02011"
"142.14200","11.84532","0.02043"
"142.41800","11.86840","0.02111"
"142.69400","11.89136","0.02227"
"142.97000","11.91438","0.02186"
"143.24600","11.93734","0.02237"
"143.52200","11.96042","0.02198"
"143.79800","11.98338","0.02196"
"144.07400","12.00640","0.02238"
"144.35000","12.02930","0.02263"
"144.62600","12.05237","0.02320"
"144.90200","12.07527","0.02333"
"145.17800","12.09835","0.02273"
"145.45400","12.12131","0.02330"
"145.73000","12.14439","0.02277"
"146.00600","12.16735","0.02311"
"146.28200","12.19037","0.02331"
"146.55800","12.21327","0.02391"
"146.83400","12.23635","0.02404"
"147.11000","12.25931","0.02308"
"147.38600","12.28238","0.02271"
"147.66200","12.30528","0.02320"
"147.93800","12.32836","0.02377"
"148.21400","12.35132","0.02401"
"148.49000","12.37434","0.02333"
"148.76600","12.39736","0.02426"
"149.04200","12.42038","0.02307"
"149.31800","12.44334","0.02373"
"149.59400","12.46636","0.02433"
"149.87000","12.48938","0.02439"
"150.14600","12.51234","0.02266"
"150.42200","12.53529","0.02323"
"150.69800","12.55831","0.02366"
"150.97400","12.58133","0.02436"
"151.25000","12.60435","0.02415"
"151.52600","12.62737","0.00405"
"151.80200","12.65039","0.00401"
"152.07800","12.67335","0.00521"
"152.35400","12.69631","0.00440"
"152.63000","12.71939","0.00467"
"152.90600","12.74229","0.00403"
"153.18200","12.76536","0.00399"
"153.45800","12.78832","0.00444"
"153.73400","12.81134","0.00492"
"154.01000","12.83424","0.00491"
"154.28600","12.85732","0.00485"
"154.56200","12.88028","0.00549"
"154.83800","12.90330","0.00548"
"155.11400","12.92626","0.00529"
"155.39000","12.94934","0.00636"
"155.66600","12.97230","0.00585"
"155.94200","12.99538","0.00515"
"156.21800","13.01827","0.00576"
"156.49400","13.04135","0.00540"
"156.77000","13.06431","0.00649"
"157.04600","13.08739","0.00647"
"157.32200","13.11029","0.00603"
"157.59800","13.13337","0.00590"
"157.87400","13.15627","0.00610"
"158.15000","13.17935","0.00651"
"158.42600","13.20231","0.00568"
"158.70200","13.22539","0.00689"
"158.97800","13.24834","0.00685"
"159.25400","13.27136","0.00738"
"159.53000","13.29438","0.00763"
"159.80600","13.31734","0.00809"
"160.08200","13.34030","0.00778"
"160.35800","13.36332","0.00797"
"160.63400","13.38634","0.00777"
"160.91000","13.40930","0.00766"
"161.18600","13.43232","0.00821"
"161.46200","13.45528","0.00853"
"161.73800","13.47836","0.00896"
"162.01400","13.50131","0.00927"
"162.29000","13.52439","0.00917"
"162.56600","13.54729","0.00968"
"162.84200","13.57037","0.01024"
"163.11800","13.59333","0.01030"
"163.39400","13.61641","0.00991"
"163.67000","13.63931","0.01056"
"163.94600","13.66239","0.01062"
"164.22200","13.68535","0.01076"
"164.49800","13.70837","0.01066"
"164.77400","13.73126","0.01132"
"165.05000","13.75434","0.01152"
"165.32600","13.77730","0.01174"
"165.60200","13.80032","0.01204"
"165.87800","13.82334","0.01237"
"166.15400","13.84636","0.01312"
"166.43000","13.86926","0.01343"
"166.70600","13.89240","0.01354"
"166.98200","13.91536","0.01427"
"167.25800","13.93843","0.01355"
"167.53400","13.96134","0.01428"
"167.81000","13.98435","0.01404"
"168.08600","14.00725","0.01426"
"168.36200","14.03033","0.01472"
"168.63800","14.05329","0.01435"
"168.91400","14.07631","0.01460"
"169.19000","14.09933","0.01517"
"169.46600","14.12241","0.01526"
"169.74200","14.14531","0.01602"
"170.01800","14.16833","0.01603"
"170.29400","14.19134","0.01666"
"170.57000","14.21437","0.01662"
"170.84600","14.23738","0.01714"
"171.12200","14.26040","0.01807"
"171.39800","14.28342","0.01862"
"171.67400","14.30632","0.01807"
"171.95000","14.32934","0.01764"
"172.22600","14.35236","0.01839"
"172.50200","14.37538","0.01828"
"172.77800","14.39834","0.01835"
"173.05400","14.42136","0.01869"
"173.33000","14.44431","0.01891"
"173.60600","14.46739","0.01935"
"173.88200","14.49035","0.01926"
"174.15800","14.51343","0.01974"
"174.43400","14.53633","0.01947"
"174.71000","14.55941","0.01923"
"174.98600","14.58231","0.02007"
"175.26200","14.60533","0.02000"
"175.53800","14.62835","0.02055"
"175.81400","14.65137","0.02029"
"176.09000","14.67432","0.02097"
"176.36600","14.69734","0.02194"
"176.64200","14.72030","0.02154"
"176.91800","14.74338","0.02158"
"177.19400","14.76628","0.02244"
"177.47000","14.78936","0.02127"
"177.74600","14.81232","0.01911"
"178.02200","14.83540","0.01948"
"178.29800","14.85830","0.02024"
"178.57400","14.88132","0.02000"
"178.85000","14.90428","0.02021"
"179.12600","14.92735","0.01881"
"179.40200","14.95031","0.01920"
"179.67800","14.97333","0.01909"
"179.95400","14.99635","0.01934"
"180.23000","15.01937","0.01942"
"180.50600","15.04233","0.01977"
"180.78200","15.06535","0.01835"
"181.05800","15.08831","0.01794"
"181.33400","15.11139","0.01843"
"181.61000","15.13441","0.01726"
"181.88600","15.15742","0.01822"
"182.16200","15.18038","0.01751"
"182.43800","15.20334","0.01774"
"182.71400","15.22630","0.01736"
"182.99000","15.24932","0.01689"
"183.26600","15.27234","0.01735"
"183.54200","15.29536","0.01589"
"183.81800","15.31838","0.01616"
"184.09400","15.34134","0.01618"
"184.37000","15.36436","0.01678"
"184.64600","15.38732","0.01665"
"184.92200","15.41039","0.01573"
"185.19800","15.43329","0.01555"
"185.47400","15.45637","0.01509"
"185.75000","15.47933","0.01464"
"186.02600","15.50235","0.01312"
"186.30200","15.52531","0.01336"
"186.57800","15.54833","0.01247"
"186.85400","15.57129","0.01288"
"187.13000","15.59437","0.01257"
"187.40600","15.61732","0.01287"
"187.68200","15.64034","0.01320"
"187.95800","15.66330","0.01140"
"188.23400","15.68638","0.01163"
"188.51000","15.70928","0.01133"
"188.78600","15.73230","0.01106"
"189.06200","15.75526","0.01132"
"189.33800","15.77834","0.01150"
"189.61400","15.80130","0.01169"
"189.89000","15.82438","0.01175"
"190.16600","15.84727","0.01046"
"190.44200","15.87035","0.01160"
"190.71800","15.89325","0.01105"
"190.99400","15.91633","0.01109"
"191.27000","15.93929","0.01080"
"191.54600","15.96237","0.00986"
"191.82200","15.98533","0.00994"
"192.09800","16.00835","0.01026"
"192.37400","16.03137","0.01072"
"192.65000","16.05439","0.01004"
"192.92600","16.07734","0.01017"
"193.20200","16.10036","0.00967"
"193.47800","16.12332","0.01060"
"193.75400","16.14628","0.01046"
"194.03000","16.16936","0.01004"
"194.30600","16.19232","0.01021"
"194.58200","16.21534","0.01081"
"194.85800","16.23836","0.01092"
"195.13400","16.26138","0.01082"
"195.41000","16.28434","0.01097"
"195.68600","16.30742","0.01085"
"195.96200","16.33031","0.01047"
"196.23800","16.35339","0.01072"
"196.51400","16.37629","0.01130"
"196.79000","16.39937","0.01133"
"197.06600","16.42227","0.01168"
"197.34200","16.44535","0.01100"
"197.61800","16.46825","0.01063"
"197.89400","16.49133","0.01082"
"198.17000","16.51429","0.01106"
"198.44600","16.53731","0.01065"
"198.72200","16.56027","0.01098"
"198.99800","16.58340","0.01026"
"199.27400","16.60630","0.01070"
"199.55000","16.62938","0.01055"
"199.82600","16.65234","0.01089"
"200.10200","16.67542","0.01154"
"200.37800","16.69832","0.01127"
"200.65400","16.72134","0.01172"
"200.93000","16.74430","0.01189"
"201.20600","16.76732","0.01187"
"201.48200","16.79028","0.01191"
"201.75800","16.81341","0.01162"
"202.03400","16.83631","0.01153"
"202.31000","16.85933","0.01065"
"202.58600","16.88235","0.01130"
"202.86200","16.90537","0.01134"
"203.13800","16.92833","0.01177"
"203.41400","16.95135","0.01112"
"203.69000","16.97437","0.01170"
"203.96600","16.99733","0.01117"
"204.24200","17.02035","0.01217"
"204.51800","17.04331","0.01242"
"204.79400","17.06632","0.01184"
"205.07000","17.08928","0.01231"
"205.34600","17.11236","0.01195"
"205.62200","17.13538","0.01238"
"205.89800","17.15840","0.01286"
"206.17400","17.18136","0.01228"
"206.45000","17.20444","0.01203"
"206.72600","17.22734","0.01211"
"207.00200","17.25042","0.01028"
"207.27800","17.27332","0.01025"
"207.55400","17.29639","0.01017"
"207.83000","17.31929","0.01047"
"208.10600","17.34237","0.01068"
"208.38200","17.36527","0.01035"
"208.65800","17.38835","0.01121"
"208.93400","17.41125","0.01056"
"209.21000","17.43439","0.01102"
"209.48600","17.45729","0.01166"
"209.76200","17.48037","0.01129"
"210.03800","17.50333","0.01145"
"210.31400","17.52641","0.01122"
"210.59000","17.54936","0.01141"
"210.86600","17.57238","0.01238"
"211.14200","17.59528","0.01207"
"211.41800","17.61830","0.01140"
"211.69400","17.64126","0.01237"
"211.97000","17.66434","0.01172"
"212.24600","17.68736","0.01178"
"212.52200","17.71038","0.01236"
"212.79800","17.73334","0.01270"
"213.07400","17.75636","0.01277"
"213.35000","17.77938","0.01271"
"213.62600","17.80233","0.01330"
"213.90200","17.82529","0.01384"
"214.17800","17.84837","0.01319"
"214.45400","17.87139","0.01416"
"214.73000","17.89441","0.01364"
"215.00600","17.91737","0.01398"
"215.28200","17.94033","0.01383"
"215.55800","17.96335","0.01445"
"215.83400","17.98637","0.01398"
"216.11000","18.00938","0.01445"
"216.38600","18.03234","0.01520"
"216.66200","18.05536","0.01463"
"216.93800","18.07832","0.01515"
"217.21400","18.10134","0.01475"
"217.49000","18.12430","0.01412"
"217.76600","18.14738","0.01439"
"218.04200","18.17034","0.01463"
"218.31800","18.19342","0.01537"
"218.59400","18.21632","0.01510"
"218.87000","18.23934","0.01443"
"219.14600","18.26224","0.01494"
"219.42200","18.28531","0.01491"
"219.69800","18.30827","0.01578"
"219.97400","18.33135","0.01594"
"220.25000","18.35431","0.01578"
"220.52600","18.37739","0.01611"
"220.80200","18.40029","0.01663"
"221.07800","18.42337","0.01662"
"221.35400","18.44633","0.01603"
"221.63000","18.46935","0.01653"
"221.90600","18.49230","0.01565"
"222.18200","18.51532","0.01666"
"222.45800","18.53828","0.01675"
"222.73400","18.56136","0.01690"
"223.01000","18.58432","0.01728"
"223.28600","18.60734","0.01564"
"223.56200","18.63036","0.01587"
"223.83800","18.65332","0.01553"
"224.11400","18.67634","0.01508"
"224.39000","18.69942","0.01305"
"224.66600","18.72237","0.01217"
"224.94200","18.74533","0.01194"
"225.21800","18.76835","0.01229"
"225.49400","18.79137","0.01292"
"225.77000","18.81433","0.01205"
"226.04600","18.83729","0.01284"
"226.32200","18.86031","0.01272"
"226.59800","18.88327","0.01364"
"226.87400","18.90635","0.01324"
"227.15000","18.92931","0.01359"
"227.42600","18.95238","0.01268"
"227.70200","18.97534","0.01269"
"227.97800","18.99842","0.01299"
"228.25400","19.02132","0.01333"
"228.53000","19.04440","0.01324"
"228.80600","19.06730","0.01344"
"229.08200","19.09032","0.01312"
"229.35800","19.11328","0.01278"
"229.63400","19.13636","0.01300"
"229.91000","19.15932","0.01283"
"230.18600","19.18233","0.01241"
"230.46200","19.20529","0.01211"
"230.73800","19.22837","0.01321"
"231.01400","19.25133","0.01255"
"231.29000","19.27441","0.01188"
"231.56600","19.29731","0.01219"
"231.84200","19.32033","0.01206"
"232.11800","19.34335","0.01099"
"232.39400","19.36637","0.01088"
"232.67000","19.38927","0.01115"
"232.94600","19.41241","0.01069"
"233.22200","19.43530","0.01168"
"233.49800","19.45832","0.01144"
"233.77400","19.48128","0.01086"
"234.05000","19.50436","0.01037"
"234.32600","19.52732","0.01027"
"234.60200","19.55034","0.01002"
"234.87800","19.57330","0.01045"
"235.15400","19.59638","0.00985"
"235.43000","19.61934","0.00971"
"235.70600","19.64241","0.01000"
"235.98200","19.66537","0.01039"
"236.25800","19.68833","0.00953"
"236.53400","19.71135","0.01023"
"236.81000","19.73431","0.01033"
"237.08600","19.75733","0.00988"
"237.36200","19.78029","0.00979"
"237.63800","19.80337","0.01066"
"237.91400","19.82633","0.01005"
"238.19000","19.84941","0.01022"
"238.46600","19.87231","0.01035"
"238.74200","19.89544","0.00994"
"239.01800","19.91834","0.01054"
"239.29400","19.94142","0.01087"
"239.57000","19.96432","0.01017"
"239.84600","19.98740","0.01026"
"240.12200","20.01030","0.01030"
"240.39800","20.03338","0.01024"
"240.67400","20.05634","0.00956"
"240.95000","20.07936","0.01027"
"241.22600","20.10225","0.00967"
"241.50200","20.12534","0.01001"
"241.77800","20.14830","0.01029"
"242.05400","20.17137","0.01007"
"242.33000","20.19427","0.01039"
"242.60600","20.21735","0.01072"
"242.88200","20.24037","0.01041"
"243.15800","20.26339","0.01052"
"243.43400","20.28635","0.01059"
"243.71000","20.30943","0.01036"
"243.98600","20.33233","0.01073"
"244.26200","20.35535","0.01086"
"244.53800","20.37831","0.01076"
"244.81400","20.40138","0.00968"
"245.09000","20.42428","0.01011"
"245.36600","20.44730","0.01019"
"245.64200","20.47032","0.01072"
"245.91800","20.49334","0.01129"
"246.19400","20.51636","0.01102"
"246.47000","20.53938","0.01074"
"246.74600","20.56240","0.01066"
"247.02200","20.58536","0.01104"
"247.29800","20.60838","0.01111"
"247.57400","20.63127","0.01181"
"247.85000","20.65435","0.01127"
"248.12600","20.67731","0.01158"
"248.40200","20.70033","0.01186"
"248.67800","20.72329","0.01174"
"248.95400","20.74637","0.01196"
"249.23000","20.76933","0.01120"
"249.50600","20.79241","0.01117"
"249.78200","20.81531","0.01124"
"250.05800","20.83839","0.01132"
"250.33400","20.86135","0.01169"
"250.61000","20.88442","0.01157"
"250.88600","20.90732","0.01133"
"251.16200","20.93034","0.01151"
"251.43800","20.95330","0.01140"
"251.71400","20.97632","0.01189"
"251.99000","20.99928","0.01228"
"252.26600","21.02236","0.01187"
"252.54200","21.04526","0.01161"
"252.81800","21.06833","0.01189"
"253.09400","21.09129","0.01151"
"253.37000","21.11438","0.01162"
"253.64600","21.13733","0.01155"
"253.92200","21.16035","0.01127"
"254.19800","21.18331","0.01139"
"254.47400","21.20633","0.01098"
"254.75000","21.22929","0.01057"
"255.02600","21.25231","0.01120"
"255.30200","21.27527","0.01144"
"255.57800","21.29835","0.01129"
"255.85400","21.32131","0.01137"
"256.13000","21.34433","0.01086"
"256.40600","21.36735","0.01178"
"256.68200","21.39036","0.01127"
"256.95800","21.41332","0.01173"
"257.23400","21.43634","0.01201"
"257.51000","21.45936","0.01245"
"257.78600","21.48238","0.01268"
"258.06200","21.50540","0.01192"
"258.33800","21.52830","0.01169"
"258.61400","21.55137","0.01194"
"258.89000","21.57433","0.01178"
"259.16600","21.59735","0.01225"
"259.44200","21.62031","0.01174"
"259.71800","21.64339","0.01175"
"259.99400","21.66635","0.01219"
"260.27000","21.68937","0.01214"
"260.54600","21.71227","0.01295"
"260.82200","21.73535","0.01270"
"261.09800","21.75831","0.01250"
"261.37400","21.78133","0.01317"
"261.65000","21.80429","0.01306"
"261.92600","21.82737","0.01345"
"262.20200","21.85026","0.01306"
"262.47800","21.87328","0.01210"
"262.75400","21.89624","0.01267"
"263.03000","21.91932","0.01208"
"263.30600","21.94228","0.01246"
"263.58200","21.96536","0.01250"
"263.85800","21.98832","0.01233"
"264.13400","22.01140","0.01250"
"264.41000","22.03436","0.01316"
"264.68600","22.05732","0.01314"
"264.96200","22.08027","0.01329"
"265.23800","22.10335","0.01327"
"265.51400","22.12631","0.01349"
"265.79000","22.14933","0.01384"
"266.06600","22.17229","0.01366"
"266.34200","22.19537","0.01378"
"266.61800","22.21839","0.01351"
"266.89400","22.24135","0.01397"
"267.17000","22.26431","0.01334"
"267.44600","22.28739","0.01398"
"267.72200","22.31034","0.01405"
"267.99800","22.33342","0.01363"
"268.27400","22.35638","0.01477"
"268.55000","22.37934","0.01436"
"268.82600","22.40236","0.01531"
"269.10200","22.42532","0.01474"
"269.37800","22.44834","0.01466"
"269.65400","22.47130","0.01550"
"269.93000","22.49438","0.01488"
"270.20600","22.51733","0.01471"
"270.48200","22.54036","0.01454"
"270.75800","22.56338","0.01510"
"271.03400","22.58639","0.01512"
"271.31000","22.60929","0.01529"
"271.58600","22.63237","0.01540"
"271.86200","22.65533","0.01517"
"272.13800","22.67835","0.01547"
"272.41400","22.70137","0.01539"
"272.69000","22.72439","0.01608"
"272.96600","22.74735","0.01585"
"273.24200","22.77036","0.01557"
"273.51800","22.79326","0.01614"
"273.79400","22.81634","0.01634"
"274.07000","22.83930","0.01659"
"274.34600","22.86238","0.01707"
"274.62200","22.88528","0.01732"
"274.89800","22.90830","0.01782"
"275.17400","22.93132","0.01795"
"275.45000","22.95434","0.01804"
"275.72600","22.97736","0.01789"
"276.00200","23.00037","0.01807"
"276.27800","23.02333","0.01853"
"276.55400","23.04635","0.01766"
"276.83000","23.06931","0.01787"
"277.10600","23.09233","0.01707"
"277.38200","23.11529","0.01723"
"277.65800","23.13831","0.01800"
"277.93400","23.16133","0.01808"
"278.21000","23.18435","0.01754"
"278.48600","23.20737","0.01791"
"278.76200","23.23039","0.01836"
"279.03800","23.25340","0.01830"
"279.31400","23.27636","0.01793"
"279.59000","23.29932","0.01892"
"279.86600","23.32234","0.01917"
"280.14200","23.34536","0.01924"
"280.41800","23.36832","0.01987"
"280.69400","23.39134","0.01989"
"280.97000","23.41430","0.02012"
"281.24600","23.43738","0.02074"
"281.52200","23.46034","0.02063"
"281.79800","23.48335","0.02168"
"282.07400","23.50631","0.02159"
"282.35000","23.52939","0.02197"
"282.62600","23.55235","0.02239"
"282.90200","23.57537","0.02289"
"283.17800","23.59827","0.02318"
"283.45400","23.62135","0.02318"
"283.73000","23.64425","0.02328"
"284.00600","23.66733","0.02378"
"284.28200","23.69023","0.02408"
"284.55800","23.71337","0.02366"
"284.83400","23.73627","0.02457"
"285.11000","23.75940","0.02370"
"285.38600","23.78230","0.02437"
"285.66200","23.80538","0.02411"
"285.93800","23.82828","0.02329"
"286.21400","23.85136","0.02359"
"286.49000","23.87432","0.02344"
"286.76600","23.89740","0.02215"
"287.04200","23.92030","0.02067"
"287.31800","23.94338","0.02093"
"287.59400","23.96634","0.02153"
"287.87000","23.98935","0.02153"
"288.14600","24.01231","0.02106"
"288.42200","24.03533","0.02175"
"288.69800","24.05835","0.02226"
"288.97400","24.08131","0.02249"
"289.25000","24.10433","0.02232"
"289.52600","24.12729","0.02307"
"289.80200","24.15031","0.02302"
"290.07800","24.17339","0.02303"
"290.35400","24.19635","0.02377"
"290.63000","24.21931","0.02404"
"290.90600","24.24232","0.02349"
"291.18200","24.26528","0.02344"
"291.45800","24.28830","0.02469"
"291.73400","24.31132","0.02508"
"292.01000","24.33440","0.02539"
"292.28600","24.35730","0.02544"
"292.56200","24.38038","0.02582"
"292.83800","24.40334","0.02624"
"293.11400","24.42636","0.02544"
"293.39000","24.44931","0.02633"
"293.66600","24.47239","0.02602"
"293.94200","24.49529","0.02636"
"294.21800","24.51837","0.02643"
"294.49400","24.54127","0.02680"
"294.77000","24.56435","0.02630"
"295.04600","24.58731","0.02737"
"295.32200","24.61033","0.02727"
"295.59800","24.63329","0.02682"
"295.87400","24.65636","0.02715"
"296.15000","24.67933","0.02766"
"296.42600","24.70240","0.02768"
"296.70200","24.72536","0.02829"
"296.97800","24.74838","0.02905"
"297.25400","24.77128","0.02817"
"297.53000","24.79436","0.02941"
"297.80600","24.81732","0.03025"
"298.08200","24.84034","0.02991"
"298.35800","24.86330","0.03020"
"298.63400","24.88632","0.03086"
"298.91000","24.90928","0.03101"
"299.18600","24.93230","0.03101"
"299.46200","24.95538","0.03110"
"299.73800","24.97833","0.03044"
"300.01400","25.00135","0.03133"
"300.29000","25.02437","0.03128"
"300.56600","25.04739","0.03127"
"300.84200","25.07035","0.03053"
"301.11800","25.09337","0.03097"
"301.39400","25.11633","0.03146"
"301.67000","25.13935","0.03160"
"301.94600","25.16231","0.03239"
"302.22200","25.18538","0.03263"
"302.49800","25.20834","0.03249"
"302.77400","25.23142","0.03288"
"303.05000","25.25432","0.03318"
"303.32600","25.27740","0.03364"
"303.60200","25.30024","0.01465"
"303.87800","25.32338","0.01500"
"304.15400","25.34634","0.01564"
"304.43000","25.36942","0.01524"
"304.70600","25.39231","0.01643"
"304.98200","25.41534","0.01515"
"305.25800","25.43829","0.01706"
"305.53400","25.46132","0.01631"
"305.81000","25.48427","0.01665"
"306.08600","25.50729","0.01678"
"306.36200","25.53031","0.01677"
"306.63800","25.55333","0.01753"
"306.91400","25.57629","0.01709"
"307.19000","25.59937","0.01803"
"307.46600","25.62233","0.01715"
"307.74200","25.64535","0.01814"
"308.01800","25.66837","0.01771"
"308.29400","25.69132","0.01780"
"308.57000","25.71434","0.01784"
"308.84600","25.73736","0.01796"
"309.12200","25.76032","0.01845"
"309.39800","25.78334","0.01806"
"309.67400","25.80636","0.01900"
"309.95000","25.82932","0.01862"
"310.22600","25.85234","0.01942"
"310.50200","25.87535","0.01932"
"310.77800","25.89837","0.01986"
"311.05400","25.92139","0.02032"
"311.33000","25.94441","0.01994"
"311.60600","25.96737","0.02147"
"311.88200","25.99033","0.02032"
"312.15800","26.01335","0.02122"
"312.43400","26.03631","0.02171"
"312.71000","26.05933","0.02145"
"312.98600","26.08235","0.02220"
"313.26200","26.10531","0.02153"
"313.53800","26.12833","0.02075"
"313.81400","26.15134","0.02093"
"314.09000","26.17436","0.02103"
"314.36600","26.19732","0.02096"
"314.64200","26.22034","0.02125"
"314.91800","26.24336","0.02175"
"315.19400","26.26644","0.02118"
"315.47000","26.28934","0.02222"
"315.74600","26.31236","0.02156"
"316.02200","26.33532","0.02259"
"316.29800","26.35834","0.02243"
"316.57400","26.38129","0.02238"
"316.85000","26.40437","0.02240"
"317.12600","26.42727","0.02176"
"317.40200","26.45035","0.02213"
"317.67800","26.47331","0.02176"
"317.95400","26.49639","0.02206"
"318.23000","26.51929","0.02266"
"318.50600","26.54237","0.02289"
"318.78200","26.56533","0.02040"
"319.05800","26.58840","0.01647"
"319.33400","26.61137","0.01680"
"319.61000","26.63433","0.01664"
"319.88600","26.65728","0.01688"
"320.16200","26.68030","0.01780"
"320.43800","26.70332","0.01758"
"320.71400","26.72634","0.01905"
"320.99000","26.74930","0.01906"
"321.26600","26.77232","0.01932"
"321.54200","26.79540","0.01938"
"321.81800","26.81836","0.01944"
"322.09400","26.84138","0.02007"
"322.37000","26.86439","0.01997"
"322.64600","26.88735","0.02037"
"322.92200","26.91031","0.01981"
"323.19800","26.93333","0.02023"
"323.47400","26.95635","0.01943"
"323.75000","26.97937","0.01959"
"324.02600","27.00233","0.02031"
"324.30200","27.02535","0.01999"
"324.57800","27.04837","0.02048"
"324.85400","27.07139","0.02072"
"325.13000","27.09429","0.02011"
"325.40600","27.11736","0.02040"
"325.68200","27.14026","0.02053"
"325.95800","27.16334","0.02063"
"326.23400","27.18630","0.02024"
"326.51000","27.20932","0.02035"
"326.78600","27.23228","0.02087"
"327.06200","27.25530","0.02002"
"327.33800","27.27826","0.02061"
"327.61400","27.30134","0.02007"
"327.89000","27.32424","0.02006"
"328.16600","27.34737","0.02053"
"328.44200","27.37027","0.02001"
"328.71800","27.39335","0.02010"
"328.99400","27.41631","0.01928"
"329.27000","27.43933","0.01858"
"329.54600","27.46229","0.01875"
"329.82200","27.48537","0.01937"
"330.09800","27.50839","0.01744"
"330.37400","27.53135","0.01759"
"330.65000","27.55431","0.01737"
"330.92600","27.57738","0.01746"
"331.20200","27.60034","0.01731"
"331.47800","27.62330","0.01721"
"331.75400","27.64632","0.01769"
"332.03000","27.66934","0.01796"
"332.30600","27.69230","0.01779"
"332.58200","27.71538","0.01726"
"332.85800","27.73840","0.01817"
"333.13400","27.76136","0.01759"
"333.41000","27.78438","0.01810"
"333.68600","27.80728","0.01813"
"333.96200","27.83029","0.01794"
"334.23800","27.85325","0.01880"
"334.51400","27.87633","0.01795"
"334.79000","27.89935","0.01899"
"335.06600","27.92237","0.01899"
"335.34200","27.94533","0.01868"
"335.61800","27.96841","0.01939"
"335.89400","27.99131","0.01856"
"336.17000","28.01439","0.01899"
"336.44600","28.03735","0.01857"
"336.72200","28.06037","0.01841"
"336.99800","28.08332","0.01902"
"337.27400","28.10640","0.01850"
"337.55000","28.12924","0.01881"
"337.82600","28.15232","0.01900"
"338.10200","28.17528","0.01921"
"338.37800","28.19836","0.01931"
"338.65400","28.22132","0.01931"
"338.93000","28.24440","0.01987"
"339.20600","28.26730","0.01952"
"339.48200","28.29038","0.01931"
"339.75800","28.31333","0.01938"
"340.03400","28.33635","0.01962"
"340.31000","28.35937","0.01942"
"340.58600","28.38239","0.01995"
"340.86200","28.40535","0.01973"
"341.13800","28.42837","0.01915"
"341.41400","28.45133","0.01950"
"341.69000","28.47435","0.02025"
"341.96600","28.49731","0.01966"
"342.24200","28.52026","0.01951"
"342.51800","28.54334","0.02075"
"342.79400","28.56636","0.02014"
"343.07000","28.58932","0.02054"
"343.34600","28.61234","0.01994"
"343.62200","28.63542","0.02044"
"343.89800","28.65838","0.02026"
"344.17400","28.68140","0.02013"
"344.45000","28.70430","0.02060"
"344.72600","28.72738","0.02027"
"345.00200","28.75034","0.02090"
"345.27800","28.77342","0.02113"
"345.55400","28.79631","0.02083"
"345.83000","28.81939","0.02121"
"346.10600","28.84235","0.02127"
"346.38200","28.86537","0.02127"
"346.65800","28.88827","0.02188"
"346.93400","28.91135","0.02147"
"347.21000","28.93431","0.02163"
"347.48600","28.95739","0.02143"
"347.76200","28.98035","0.02170"
"348.03800","29.00342","0.02203"
"348.31400","29.02627","0.02212"
"348.59000","29.04928","0.02197"
"348.86600","29.07224","0.02159"
"349.14200","29.09532","0.02263"
"349.41800","29.11828","0.02241"
"349.69400","29.14136","0.02257"
"349.97000","29.16432","0.02324"
"350.24600","29.18740","0.02270"
"350.52200","29.21030","0.02327"
"350.79800","29.23331","0.02346"
"351.07400","29.25633","0.02303"
"351.35000","29.27935","0.02367"
"351.62600","29.30237","0.02331"
"351.90200","29.32533","0.02338"
"352.17800","29.34835","0.02438"
"352.45400","29.37137","0.02347"
"352.73000","29.39439","0.02389"
"353.00600","29.41729","0.02405"
"353.28200","29.44036","0.02406"
"353.55800","29.46339","0.02417"
"353.83400","29.48634","0.02467"
"354.11000","29.50937","0.02388"
"354.38600","29.53232","0.02424"
"354.66200","29.55534","0.02458"
"354.93800","29.57836","0.02508"
"355.21400","29.60132","0.02515"
"355.49000","29.62434","0.02528"
"355.76600","29.64730","0.02554"
"356.04200","29.67032","0.02584"
"356.31800","29.69328","0.02601"
"356.59400","29.71635","0.02618"
"356.87000","29.73931","0.02581"
"357.14600","29.76228","0.02571"
"357.42200","29.78529","0.02663"
"357.69800","29.80837","0.02603"
"357.97400","29.83133","0.02614"
"358.25000","29.85435","0.02661"
"358.52600","29.87731","0.02677"
"358.80200","29.90039","0.02611"
"359.07800","29.92329","0.02654"
"359.35400","29.94630","0.02680"
"359.63000","29.96926","0.02657"
"359.90600","29.99235","0.02670"
"360.18200","30.01530","0.02678"
"360.45800","30.03838","0.02715"
"360.73400","30.06128","0.02734"
"361.01000","30.08436","0.02701"
"361.28600","30.10732","0.02715"
"361.56200","30.13034","0.02792"
"361.83800","30.15330","0.02778"
"362.11400","30.17638","0.02780"
"362.39000","30.19934","0.02823"
"362.66600","30.22235","0.02804"
"362.94200","30.24532","0.02867"
"363.21800","30.26833","0.02861"
"363.49400","30.29129","0.02880"
"363.77000","30.31431","0.02892"
"364.04600","30.33733","0.02912"
"364.32200","30.36035","0.02923"
"364.59800","30.38337","0.02976"
"364.87400","30.40639","0.02973"
"365.15000","30.42934","0.02995"
"365.42600","30.45237","0.03012"
"365.70200","30.47532","0.03014"
"365.97800","30.49834","0.03087"
"366.25400","30.52136","0.03037"
"366.53000","30.54432","0.03026"
"366.80600","30.56740","0.03076"
"367.08200","30.59036","0.03057"
"367.35800","30.61338","0.03090"
"367.63400","30.63634","0.03156"
"367.91000","30.65936","0.03135"
"368.18600","30.68231","0.03177"
"368.46200","30.70539","0.03164"
"368.73800","30.72835","0.03191"
"369.01400","30.75137","0.03198"
"369.29000","30.77427","0.03228"
"369.56600","30.79735","0.03278"
"369.84200","30.82025","0.03243"
"370.11800","30.84333","0.03245"
"370.39400","30.86623","0.03297"
"370.67000","30.88937","0.03286"
"370.94600","30.91227","0.03275"
"371.22200","30.93541","0.03340"
"371.49800","30.95830","0.03369"
"371.77400","30.98138","0.03326"
"372.05000","31.00434","0.03419"
"372.32600","31.02736","0.03415"
"372.60200","31.05038","0.03463"
"372.87800","31.07340","0.03424"
"373.15400","31.09636","0.03460"
"373.43000","31.11938","0.03480"
"373.70600","31.14234","0.03489"
"373.98200","31.16535","0.03538"
"374.25800","31.18831","0.03594"
"374.53400","31.21133","0.03573"
"374.81000","31.23435","0.03637"
"375.08600","31.25737","0.03573"
"375.36200","31.28033","0.03648"
"375.63800","31.30335","0.03656"
"375.91400","31.32636","0.03710"
"376.19000","31.34932","0.03724"
"376.46600","31.37241","0.03739"
"376.74200","31.39536","0.03792"
"377.01800","31.41832","0.03777"
"377.29400","31.44128","0.03805"
"377.57000","31.46430","0.03822"
"377.84600","31.48726","0.03841"
"378.12200","31.51034","0.03819"
"378.39800","31.53330","0.03873"
"378.67400","31.55638","0.03884"
"378.95000","31.57933","0.03860"
"379.22600","31.60236","0.03905"
"379.50200","31.62531","0.03946"
"379.77800","31.64839","0.03971"
"380.05400","31.67129","0.04009"
"380.33000","31.69437","0.03994"
"380.60600","31.71727","0.04029"
"380.88200","31.74035","0.04046"
"381.15800","31.76325","0.04022"
"381.43400","31.78639","0.04072"
"381.71000","31.80929","0.04101"
"381.98600","31.83236","0.04126"
"382.26200","31.85533","0.04083"
"382.53800","31.87835","0.04133"
"382.81400","31.90130","0.04160"
"383.09000","31.92432","0.04156"
"383.36600","31.94734","0.04161"
"383.64200","31.97036","0.04232"
"383.91800","31.99338","0.04238"
"384.19400","32.01634","0.04256"
"384.47000","32.03936","0.04311"
"384.74600","32.06231","0.04249"
"385.02200","32.08533","0.04335"
"385.29800","32.10830","0.04327"
"385.57400","32.13131","0.04382"
"385.85000","32.15433","0.04392"
"386.12600","32.17735","0.04399"
"386.40200","32.20037","0.04414"
"386.67800","32.22339","0.04458"
"386.95400","32.24635","0.04424"
"387.23000","32.26942","0.04462"
"387.50600","32.29232","0.04492"
"387.78200","32.31540","0.04487"
"388.05800","32.33830","0.04511"
"388.33400","32.36139","0.04548"
"388.61000","32.38434","0.04565"
"388.88600","32.40736","0.04562"
"389.16200","32.43032","0.04600"
"389.43800","32.45334","0.04603"
"389.71400","32.47624","0.04655"
"389.99000","32.49932","0.04673"
"390.26600","32.52228","0.04684"
"390.54200","32.54535","0.04699"
"390.81800","32.56831","0.04700"
"391.09400","32.59140","0.04724"
"391.37000","32.61430","0.04771"
"391.64600","32.63731","0.04775"
"391.92200","32.66027","0.04790"
"392.19800","32.68335","0.04816"
"392.47400","32.70625","0.04852"
"392.75000","32.72933","0.04884"
"393.02600","32.75229","0.04864"
"393.30200","32.77536","0.04943"
"393.57800","32.79832","0.04940"
"393.85400","32.82134","0.04990"
"394.13000","32.84436","0.04977"
"394.40600","32.86732","0.05052"
"394.68200","32.89034","0.05041"
"394.95800","32.91336","0.05081"
"395.23400","32.93632","0.05156"
"395.51000","32.95934","0.05207"
"395.78600","32.98236","0.05227"
"396.06200","33.00532","0.05219"
"396.33800","33.02834","0.05330"
"396.61400","33.05135","0.05359"
"396.89000","33.07437","0.05396"
"397.16600","33.09739","0.05477"
"397.44200","33.12035","0.05505"
"397.71800","33.14331","0.05577"
"397.99400","33.16633","0.05637"
"398.27000","33.18935","0.05697"
"398.54600","33.21237","0.05744"
"398.82200","33.23532","0.05792"
"399.09800","33.25835","0.05873"
"399.37400","33.28130","0.05967"
"399.65000","33.30432","0.06020"
"399.92600","33.32734","0.06084"
"400.20200","33.35036","0.06210"
"400.47800","33.37332","-0.00260"
"400.75400","33.39634","0.00104"
"401.03000","33.41930","-0.00387"
"401.30600","33.44238","0.00041"
"401.58200","33.46534","-0.00043"
"401.85800","33.48835","0.00065"
"402.13400","33.51131","-0.00134"
"402.41000","33.53433","-0.00160"
"402.68600","33.55723","-0.00034"
"402.96200","33.58038","-0.00129"
"403.23800","33.60327","0.00144"
"403.51400","33.62641","-0.00072"
"403.79000","33.64931","-0.00069"
"404.06600","33.67233","-0.00070"
"404.34200","33.69535","-0.00102"
"404.61800","33.71836","-0.00069"
"404.89400","33.74139","-0.00169"
"405.17000","33.76440","-0.00008"
"405.44600","33.78736","0.00068"
"405.72200","33.81032","-0.00047"
"405.99800","33.83328","-0.00158"
"406.27400","33.85636","-0.00201"
"406.55000","33.87932","0.00007"
"406.82600","33.90234","-0.00060"
"407.10200","33.92536","0.00011"
"407.37800","33.94832","-0.00141"
"407.65400","33.97134","-0.00197"
"407.93000","33.99435","-0.00059"
"408.20600","34.01737","-0.00112"
"408.48200","34.04039","0.00038"
"408.75800","34.06342","-0.00108"
"408.81800","34.06832","-0.00206"