File: Force_trajectories/170226_1/Specimen_RawData_3.csv
End date,"2/26/2017"
Specimen label,"1AT_7"
Maximum Load,"0.00847",N

Time,Extension,Load
(s),(mm),(N)
"0.00000","0.00000","0.00081"
"0.15600","0.00909","0.00069"
"0.31200","0.02565","0.00049"
"0.46800","0.03928","0.00107"
"0.62400","0.05220","0.00080"
"0.78000","0.06517","0.00139"
"0.93600","0.07826","0.00135"
"1.09200","0.09124","0.00134"
"1.24800","0.10415","0.00155"
"1.40400","0.11719","0.00143"
"1.56000","0.13022","0.00119"
"1.71600","0.14314","0.00169"
"1.87200","0.15611","0.00147"
"2.02800","0.16920","0.00154"
"2.18400","0.18224","0.00129"
"2.34000","0.19515","0.00115"
"2.49600","0.20825","0.00166"
"2.65200","0.22122","0.00134"
"2.80800","0.23420","0.00171"
"2.96400","0.24717","0.00145"
"3.12000","0.26014","0.00143"
"3.27600","0.27324","0.00151"
"3.43200","0.28609","0.00126"
"3.58800","0.29919","0.00173"
"3.74400","0.31216","0.00135"
"3.90000","0.32520","0.00152"
"4.05600","0.33817","0.00219"
"4.21200","0.35126","0.00173"
"4.36800","0.36418","0.00156"
"4.52400","0.37715","0.00173"
"4.68000","0.39019","0.00209"
"4.83600","0.40322","0.00174"
"4.99200","0.41614","0.00151"
"5.14800","0.42917","0.00151"
"5.30400","0.44214","0.00213"
"5.46000","0.45512","0.00229"
"5.61600","0.46809","0.00215"
"5.77200","0.48119","0.00175"
"5.92800","0.49422","0.00179"
"6.08400","0.50719","0.00217"
"6.24000","0.52017","0.00163"
"6.39600","0.53314","0.00189"
"6.55200","0.54606","0.00154"
"6.70800","0.55915","0.00190"
"6.86400","0.57225","0.00176"
"7.02000","0.58522","0.00201"
"7.17600","0.59813","0.00201"
"7.33200","0.61123","0.00182"
"7.48800","0.62420","0.00226"
"7.64400","0.63718","0.00189"
"7.80000","0.65015","0.00191"
"7.95600","0.66325","0.00165"
"8.11200","0.67616","0.00214"
"8.26800","0.68913","0.00183"
"8.42400","0.70217","0.00198"
"8.58000","0.71526","0.00167"
"8.73600","0.72812","0.00167"
"8.89200","0.74115","0.00232"
"9.04800","0.75419","0.00210"
"9.20400","0.76716","0.00183"
"9.36000","0.78013","0.00227"
"9.51600","0.79323","0.00190"
"9.67200","0.80626","0.00156"
"9.82800","0.81918","0.00165"
"9.98400","0.83215","0.00189"
"10.14000","0.84518","0.00205"
"10.29600","0.85816","0.00178"
"10.45200","0.87113","0.00214"
"10.60800","0.88417","0.00221"
"10.76400","0.89720","0.00240"
"10.92000","0.91018","0.00222"
"11.07600","0.92315","0.00191"
"11.23200","0.93618","0.00241"
"11.38800","0.94916","0.00223"
"11.54400","0.96219","0.00194"
"11.70000","0.97517","0.00236"
"11.85600","0.98820","0.00198"
"12.01200","1.00112","0.00206"
"12.16800","1.01421","0.00185"
"12.32400","1.02718","0.00212"
"12.48000","1.04022","0.00215"
"12.63600","1.05313","0.00205"
"12.79200","1.06617","0.00209"
"12.94800","1.07914","0.00292"
"13.10400","1.09218","0.00183"
"13.26000","1.10521","0.00237"
"13.41600","1.11818","0.00263"
"13.57200","1.13116","0.00243"
"13.72800","1.14419","0.00226"
"13.88400","1.15717","0.00215"
"14.04000","1.17014","0.00285"
"14.19600","1.18312","0.00236"
"14.35200","1.19615","0.00242"
"14.50800","1.20918","0.00185"
"14.66400","1.22216","0.00189"
"14.82000","1.23519","0.00260"
"14.97600","1.24823","0.00216"
"15.13200","1.26120","0.00256"
"15.28800","1.27417","0.00185"
"15.44400","1.28721","0.00249"
"15.60000","1.30018","0.00281"
"15.75600","1.31316","0.00229"
"15.91200","1.32619","0.00244"
"16.06800","1.33917","0.00313"
"16.22400","1.35214","0.00250"
"16.38000","1.36511","0.00255"
"16.53600","1.37821","0.00244"
"16.69200","1.39124","0.00269"
"16.84800","1.40416","0.00283"
"17.00400","1.41719","0.00273"
"17.16000","1.43023","0.00250"
"17.31600","1.44314","0.00229"
"17.47200","1.45611","0.00227"
"17.62800","1.46921","0.00248"
"17.78400","1.48218","0.00232"
"17.94000","1.49510","0.00278"
"18.09600","1.50819","0.00299"
"18.25200","1.52123","0.00297"
"18.40800","1.53420","0.00298"
"18.56400","1.54717","0.00277"
"18.72000","1.56021","0.00269"
"18.87600","1.57318","0.00275"
"19.03200","1.58610","0.00267"
"19.18800","1.59919","0.00288"
"19.34400","1.61216","0.00284"
"19.50000","1.62514","0.00277"
"19.65600","1.63811","0.00269"
"19.81200","1.65115","0.00222"
"19.96800","1.66418","0.00284"
"20.12400","1.67716","0.00272"
"20.28000","1.69019","0.00319"
"20.43600","1.70322","0.00226"
"20.59200","1.71614","0.00322"
"20.74800","1.72917","0.00326"
"20.90400","1.74215","0.00279"
"21.06000","1.75518","0.00300"
"21.21600","1.76810","0.00333"
"21.37200","1.78119","0.00284"
"21.52800","1.79416","0.00295"
"21.68400","1.80714","0.00342"
"21.84000","1.82017","0.00285"
"21.99600","1.83321","0.00331"
"22.15200","1.84618","0.00305"
"22.30800","1.85916","0.00336"
"22.46400","1.87225","0.00331"
"22.62000","1.88516","0.00299"
"22.77600","1.89814","0.00342"
"22.93200","1.91117","0.00292"
"23.08800","1.92415","0.00283"
"23.24400","1.93712","0.00358"
"23.40000","1.95016","0.00327"
"23.55600","1.96319","0.00246"
"23.71200","1.97622","0.00296"
"23.86800","1.98908","0.00317"
"24.02400","2.00223","0.00323"
"24.18000","2.01521","0.00285"
"24.33600","2.02812","0.00274"
"24.49200","2.04115","0.00296"
"24.64800","2.05419","0.00246"
"24.80400","2.06716","0.00276"
"24.96000","2.08008","0.00366"
"25.11600","2.09317","0.00292"
"25.27200","2.10621","0.00282"
"25.42800","2.11918","0.00248"
"25.58400","2.13221","0.00305"
"25.74000","2.14525","0.00312"
"25.89600","2.15822","0.00329"
"26.05200","2.17108","0.00275"
"26.20800","2.18423","0.00263"
"26.36400","2.19721","0.00321"
"26.52000","2.21018","0.00274"
"26.67600","2.22315","0.00277"
"26.83200","2.23619","0.00273"
"26.98800","2.24916","0.00305"
"27.14400","2.26214","0.00318"
"27.30000","2.27517","0.00247"
"27.45600","2.28821","0.00306"
"27.61200","2.30112","0.00237"
"27.76800","2.31415","0.00330"
"27.92400","2.32719","0.00312"
"28.08000","2.34016","0.00305"
"28.23600","2.35314","0.00306"
"28.39200","2.36617","0.00328"
"28.54800","2.37914","0.00366"
"28.70400","2.39212","0.00310"
"28.86000","2.40521","0.00329"
"29.01600","2.41819","0.00360"
"29.17200","2.43116","0.00285"
"29.32800","2.44420","0.00353"
"29.48400","2.45723","0.00374"
"29.64000","2.47020","0.00275"
"29.79600","2.48312","0.00302"
"29.95200","2.49615","0.00331"
"30.10800","2.50919","0.00336"
"30.26400","2.52210","0.00352"
"30.42000","2.53514","0.00273"
"30.57600","2.54817","0.00290"
"30.73200","2.56114","0.00288"
"30.88800","2.57418","0.00281"
"31.04400","2.58721","0.00296"
"31.20000","2.60019","0.00279"
"31.35600","2.61310","0.00280"
"31.51200","2.62614","0.00305"
"31.66800","2.63917","0.00232"
"31.82400","2.65214","0.00275"
"31.98000","2.66512","0.00256"
"32.13600","2.67815","0.00296"
"32.29200","2.69113","0.00281"
"32.44800","2.70410","0.00266"
"32.60400","2.71720","0.00232"
"32.76000","2.73023","0.00277"
"32.91600","2.74320","0.00293"
"33.07200","2.75618","0.00252"
"33.22800","2.76927","0.00255"
"33.38400","2.78213","0.00281"
"33.54000","2.79510","0.00314"
"33.69600","2.80819","0.00281"
"33.85200","2.82117","0.00267"
"34.00800","2.83414","0.00189"
"34.16400","2.84712","0.00194"
"34.32000","2.86021","0.00255"
"34.47600","2.87325","0.00245"
"34.63200","2.88616","0.00221"
"34.78800","2.89919","0.00212"
"34.94400","2.91223","0.00218"
"35.10000","2.92514","0.00258"
"35.25600","2.93812","0.00267"
"35.41200","2.95121","0.00281"
"35.56800","2.96419","0.00246"
"35.72400","2.97716","0.00225"
"35.88000","2.99013","0.00230"
"36.03600","3.00317","0.00288"
"36.19200","3.01614","0.00240"
"36.34800","3.02918","0.00326"
"36.50400","3.04221","0.00274"
"36.66000","3.05519","0.00277"
"36.81600","3.06816","0.00230"
"36.97200","3.08119","0.00224"
"37.12800","3.09417","0.00255"
"37.28400","3.10714","0.00290"
"37.44000","3.12012","0.00250"
"37.59600","3.13309","0.00246"
"37.75200","3.14613","0.00256"
"37.90800","3.15910","0.00262"
"38.06400","3.17225","0.00202"
"38.22000","3.18523","0.00259"
"38.37600","3.19814","0.00252"
"38.53200","3.21118","0.00177"
"38.68800","3.22421","0.00226"
"38.84400","3.23718","0.00268"
"39.00000","3.25016","0.00215"
"39.15600","3.26319","0.00239"
"39.31200","3.27617","0.00217"
"39.46800","3.28914","0.00235"
"39.62400","3.30218","0.00241"
"39.78000","3.31521","0.00287"
"39.93600","3.32818","0.00258"
"40.09200","3.34122","0.00216"
"40.24800","3.35425","0.00259"
"40.40400","3.36717","0.00230"
"40.56000","3.38014","0.00214"
"40.71600","3.39318","0.00269"
"40.87200","3.40621","0.00170"
"41.02800","3.41918","0.00199"
"41.18400","3.43216","0.00234"
"41.34000","3.44519","0.00255"
"41.49600","3.45817","0.00235"
"41.65200","3.47120","0.00192"
"41.80800","3.48423","0.00230"
"41.96400","3.49721","0.00238"
"42.12000","3.51012","0.00205"
"42.27600","3.52322","0.00226"
"42.43200","3.53619","0.00203"
"42.58800","3.54917","0.00250"
"42.74400","3.56208","0.00262"
"42.90000","3.57523","0.00247"
"43.05600","3.58821","0.00272"
"43.21200","3.60112","0.00240"
"43.36800","3.61416","0.00237"
"43.52400","3.62725","0.00252"
"43.68000","3.64023","0.00219"
"43.83600","3.65314","0.00281"
"43.99200","3.66623","0.00287"
"44.14800","3.67915","0.00247"
"44.30400","3.69212","0.00289"
"44.46000","3.70522","0.00218"
"44.61600","3.71825","0.00280"
"44.77200","3.73111","0.00347"
"44.92800","3.74408","0.00279"
"45.08400","3.75717","0.00317"
"45.24000","3.77021","0.00284"
"45.39600","3.78318","0.00307"
"45.55200","3.79622","0.00277"
"45.70800","3.80919","0.00293"
"45.86400","3.82217","0.00284"
"46.02000","3.83514","0.00283"
"46.17600","3.84817","0.00232"
"46.33200","3.86115","0.00255"
"46.48800","3.87412","0.00348"
"46.64400","3.88716","0.00274"
"46.80000","3.90019","0.00296"
"46.95600","3.91317","0.00284"
"47.11200","3.92614","0.00272"
"47.26800","3.93923","0.00291"
"47.42400","3.95221","0.00235"
"47.58000","3.96512","0.00270"
"47.73600","3.97816","0.00264"
"47.89200","3.99119","0.00215"
"48.04800","4.00416","0.00275"
"48.20400","4.01720","0.00260"
"48.36000","4.03023","0.00304"
"48.51600","4.04321","0.00295"
"48.67200","4.05612","0.00251"
"48.82800","4.06922","0.00253"
"48.98400","4.08219","0.00293"
"49.14000","4.09516","0.00291"
"49.29600","4.10820","0.00232"
"49.45200","4.12117","0.00247"
"49.60800","4.13415","0.00304"
"49.76400","4.14712","0.00279"
"49.92000","4.16016","0.00266"
"50.07600","4.17319","0.00297"
"50.23200","4.18610","0.00283"
"50.38800","4.19920","0.00197"
"50.54400","4.21217","0.00267"
"50.70000","4.22515","0.00329"
"50.85600","4.23818","0.00246"
"51.01200","4.25121","0.00268"
"51.16800","4.26419","0.00246"
"51.32400","4.27710","0.00264"
"51.48000","4.29020","0.00244"
"51.63600","4.30323","0.00292"
"51.79200","4.31615","0.00312"
"51.94800","4.32912","0.00290"
"52.10400","4.34215","0.00277"
"52.26000","4.35513","0.00300"
"52.41600","4.36816","0.00231"
"52.57200","4.38120","0.00273"
"52.72800","4.39423","0.00336"
"52.88400","4.40715","0.00269"
"53.04000","4.42018","0.00289"
"53.19600","4.43315","0.00290"
"53.35200","4.44613","0.00271"
"53.50800","4.45910","0.00277"
"53.66400","4.47220","0.00381"
"53.82000","4.48517","0.00251"
"53.97600","4.49815","0.00297"
"54.13200","4.51118","0.00290"
"54.28800","4.52421","0.00249"
"54.44400","4.53719","0.00244"
"54.60000","4.55016","0.00324"
"54.75600","4.56320","0.00334"
"54.91200","4.57617","0.00224"
"55.06800","4.58909","0.00258"
"55.22400","4.60218","0.00266"
"55.38000","4.61515","0.00279"
"55.53600","4.62819","0.00361"
"55.69200","4.64110","0.00300"
"55.84800","4.65420","0.00290"
"56.00400","4.66717","0.00282"
"56.16000","4.68009","0.00272"
"56.31600","4.69318","0.00338"
"56.47200","4.70615","0.00300"
"56.62800","4.71919","0.00274"
"56.78400","4.73216","0.00322"
"56.94000","4.74520","0.00324"
"57.09600","4.75811","0.00317"
"57.25200","4.77108","0.00256"
"57.40800","4.78412","0.00324"
"57.56400","4.79715","0.00311"
"57.72000","4.81013","0.00295"
"57.87600","4.82316","0.00311"
"58.03200","4.83620","0.00290"
"58.18800","4.84923","0.00285"
"58.34400","4.86214","0.00289"
"58.50000","4.87524","0.00271"
"58.65600","4.88821","0.00282"
"58.81200","4.90113","0.00321"
"58.96800","4.91416","0.00317"
"59.12400","4.92714","0.00333"
"59.28000","4.94011","0.00295"
"59.43600","4.95308","0.00348"
"59.59200","4.96618","0.00300"
"59.74800","4.97921","0.00279"
"59.90400","4.99213","0.00247"
"60.06000","5.00516","0.00295"
"60.21600","5.01819","0.00256"
"60.37200","5.03117","0.00302"
"60.52800","5.04408","0.00258"
"60.68400","5.05724","0.00337"
"60.84000","5.07015","0.00223"
"60.99600","5.08313","0.00317"
"61.15200","5.09616","0.00240"
"61.30800","5.10919","0.00234"
"61.46400","5.12217","0.00322"
"61.62000","5.13514","0.00293"
"61.77600","5.14824","0.00298"
"61.93200","5.16121","0.00331"
"62.08800","5.17413","0.00339"
"62.24400","5.18716","0.00349"
"62.40000","5.20019","0.00218"
"62.55600","5.21311","0.00241"
"62.71200","5.22614","0.00275"
"62.86800","5.23918","0.00246"
"63.02400","5.25221","0.00260"
"63.18000","5.26519","0.00266"
"63.33600","5.27822","0.00307"
"63.49200","5.29119","0.00288"
"63.64800","5.30417","0.00264"
"63.80400","5.31714","0.00284"
"63.96000","5.33012","0.00253"
"64.11600","5.34315","0.00315"
"64.27200","5.35613","0.00254"
"64.42800","5.36916","0.00269"
"64.58400","5.38213","0.00253"
"64.74000","5.39517","0.00226"
"64.89600","5.40814","0.00279"
"65.05200","5.42118","0.00276"
"65.20800","5.43415","0.00228"
"65.36400","5.44719","0.00316"
"65.52000","5.46022","0.00248"
"65.67600","5.47313","0.00250"
"65.83200","5.48611","0.00269"
"65.98800","5.49920","0.00247"
"66.14400","5.51218","0.00252"
"66.30000","5.52515","0.00260"
"66.45600","5.53812","0.00282"
"66.61200","5.55122","0.00270"
"66.76800","5.56425","0.00308"
"66.92400","5.57711","0.00249"
"67.08000","5.59020","0.00258"
"67.23600","5.60324","0.00232"
"67.39200","5.61615","0.00244"
"67.54800","5.62918","0.00239"
"67.70400","5.64222","0.00233"
"67.86000","5.65519","0.00282"
"68.01600","5.66811","0.00250"
"68.17200","5.68120","0.00278"
"68.32800","5.69424","0.00260"
"68.48400","5.70721","0.00278"
"68.64000","5.72018","0.00268"
"68.79600","5.73322","0.00296"
"68.95200","5.74619","0.00232"
"69.10800","5.75911","0.00268"
"69.26400","5.77220","0.00290"
"69.42000","5.78518","0.00214"
"69.57600","5.79815","0.00284"
"69.73200","5.81112","0.00304"
"69.88800","5.82416","0.00289"
"70.04400","5.83713","0.00356"
"70.20000","5.85011","0.00318"
"70.35600","5.86320","0.00294"
"70.51200","5.87624","0.00300"
"70.66800","5.88915","0.00314"
"70.82400","5.90212","0.00314"
"70.98000","5.91522","0.00235"
"71.13600","5.92819","0.00267"
"71.29200","5.94117","0.00291"
"71.44800","5.95420","0.00313"
"71.60400","5.96723","0.00276"
"71.76000","5.98015","0.00335"
"71.91600","5.99318","0.00309"
"72.07200","6.00622","0.00249"
"72.22800","6.01919","0.00301"
"72.38400","6.03217","0.00314"
"72.54000","6.04520","0.00274"
"72.69600","6.05817","0.00315"
"72.85200","6.07115","0.00224"
"73.00800","6.08418","0.00321"
"73.16400","6.09716","0.00306"
"73.32000","6.11013","0.00353"
"73.47600","6.12317","0.00243"
"73.63200","6.13614","0.00328"
"73.78800","6.14917","0.00301"
"73.94400","6.16215","0.00309"
"74.10000","6.17524","0.00257"
"74.25600","6.18822","0.00313"
"74.41200","6.20113","0.00382"
"74.56800","6.21417","0.00289"
"74.72400","6.22720","0.00347"
"74.88000","6.24011","0.00290"
"75.03600","6.25315","0.00264"
"75.19200","6.26618","0.00320"
"75.34800","6.27916","0.00318"
"75.50400","6.29207","0.00344"
"75.66000","6.30517","0.00364"
"75.81600","6.31820","0.00321"
"75.97200","6.33117","0.00322"
"76.12800","6.34421","0.00281"
"76.28400","6.35724","0.00303"
"76.44000","6.37016","0.00364"
"76.59600","6.38313","0.00357"
"76.75200","6.39616","0.00312"
"76.90800","6.40920","0.00342"
"77.06400","6.42217","0.00277"
"77.22000","6.43515","0.00340"
"77.37600","6.44824","0.00322"
"77.53200","6.46122","0.00285"
"77.68800","6.47413","0.00326"
"77.84400","6.48722","0.00303"
"78.00000","6.50020","0.00335"
"78.15600","6.51317","0.00293"
"78.31200","6.52615","0.00296"
"78.46800","6.53918","0.00333"
"78.62400","6.55216","0.00334"
"78.78000","6.56513","0.00327"
"78.93600","6.57816","0.00286"
"79.09200","6.59120","0.00358"
"79.24800","6.60417","0.00350"
"79.40400","6.61721","0.00362"
"79.56000","6.63024","0.00372"
"79.71600","6.64316","0.00333"
"79.87200","6.65613","0.00346"
"80.02800","6.66916","0.00379"
"80.18400","6.68220","0.00336"
"80.34000","6.69517","0.00311"
"80.49600","6.70815","0.00360"
"80.65200","6.72118","0.00344"
"80.80800","6.73416","0.00305"
"80.96400","6.74713","0.00320"
"81.12000","6.76022","0.00322"
"81.27600","6.77320","0.00341"
"81.43200","6.78617","0.00289"
"81.58800","6.79921","0.00338"
"81.74400","6.81218","0.00322"
"81.90000","6.82516","0.00365"
"82.05600","6.83813","0.00317"
"82.21200","6.85116","0.00348"
"82.36800","6.86414","0.00318"
"82.52400","6.87711","0.00400"
"82.68000","6.89021","0.00319"
"82.83600","6.90318","0.00403"
"82.99200","6.91615","0.00319"
"83.14800","6.92913","0.00383"
"83.30400","6.94222","0.00353"
"83.46000","6.95514","0.00359"
"83.61600","6.96811","0.00404"
"83.77200","6.98115","0.00351"
"83.92800","6.99418","0.00388"
"84.08400","7.00709","0.00392"
"84.24000","7.02019","0.00433"
"84.39600","7.03316","0.00392"
"84.55200","7.04620","0.00388"
"84.70800","7.05911","0.00353"
"84.86400","7.07221","0.00376"
"85.02000","7.08518","0.00364"
"85.17600","7.09815","0.00443"
"85.33200","7.11119","0.00450"
"85.48800","7.12416","0.00335"
"85.64400","7.13714","0.00298"
"85.80000","7.15005","0.00371"
"85.95600","7.16320","0.00400"
"86.11200","7.17618","0.00438"
"86.26800","7.18915","0.00361"
"86.42400","7.20219","0.00448"
"86.58000","7.21528","0.00456"
"86.73600","7.22820","0.00399"
"86.89200","7.24117","0.00399"
"87.04800","7.25420","0.00378"
"87.20400","7.26718","0.00408"
"87.36000","7.28009","0.00379"
"87.51600","7.29313","0.00419"
"87.67200","7.30616","0.00422"
"87.82800","7.31914","0.00364"
"87.98400","7.33211","0.00409"
"88.14000","7.34520","0.00405"
"88.29600","7.35818","0.00402"
"88.45200","7.37109","0.00380"
"88.60800","7.38419","0.00363"
"88.76400","7.39722","0.00406"
"88.92000","7.41020","0.00394"
"89.07600","7.42317","0.00418"
"89.23200","7.43614","0.00391"
"89.38800","7.44918","0.00382"
"89.54400","7.46209","0.00395"
"89.70000","7.47519","0.00405"
"89.85600","7.48822","0.00390"
"90.01200","7.50119","0.00400"
"90.16800","7.51417","0.00365"
"90.32400","7.52720","0.00429"
"90.48000","7.54018","0.00429"
"90.63600","7.55315","0.00404"
"90.79200","7.56619","0.00464"
"90.94800","7.57922","0.00390"
"91.10400","7.59213","0.00354"
"91.26000","7.60511","0.00381"
"91.41600","7.61814","0.00402"
"91.57200","7.63112","0.00415"
"91.72800","7.64415","0.00433"
"91.88400","7.65725","0.00436"
"92.04000","7.67016","0.00420"
"92.19600","7.68313","0.00468"
"92.35200","7.69617","0.00406"
"92.50800","7.70920","0.00411"
"92.66400","7.72212","0.00439"
"92.82000","7.73515","0.00460"
"92.97600","7.74819","0.00448"
"93.13200","7.76116","0.00376"
"93.28800","7.77413","0.00390"
"93.44400","7.78723","0.00383"
"93.60000","7.80020","0.00411"
"93.75600","7.81318","0.00407"
"93.91200","7.82615","0.00401"
"94.06800","7.83919","0.00413"
"94.22400","7.85222","0.00339"
"94.38000","7.86507","0.00477"
"94.53600","7.87823","0.00384"
"94.69200","7.89120","0.00403"
"94.84800","7.90412","0.00396"
"95.00400","7.91715","0.00388"
"95.16000","7.93018","0.00428"
"95.31600","7.94316","0.00387"
"95.47200","7.95613","0.00422"
"95.62800","7.96917","0.00328"
"95.78400","7.98214","0.00398"
"95.94000","7.99512","0.00360"
"96.09600","8.00815","0.00399"
"96.25200","8.02118","0.00446"
"96.40800","8.03416","0.00413"
"96.56400","8.04713","0.00412"
"96.72000","8.06017","0.00401"
"96.87600","8.07320","0.00435"
"97.03200","8.08618","0.00488"
"97.18800","8.09921","0.00401"
"97.34400","8.11224","0.00409"
"97.50000","8.12516","0.00427"
"97.65600","8.13819","0.00415"
"97.81200","8.15117","0.00445"
"97.96800","8.16414","0.00420"
"98.12400","8.17706","0.00423"
"98.28000","8.19021","0.00467"
"98.43600","8.20318","0.00432"
"98.59200","8.21616","0.00394"
"98.74800","8.22913","0.00415"
"98.90400","8.24223","0.00392"
"99.06000","8.25520","0.00441"
"99.21600","8.26818","0.00398"
"99.37200","8.28121","0.00458"
"99.52800","8.29418","0.00373"
"99.68400","8.30716","0.00416"
"99.84000","8.32013","0.00355"
"99.99600","8.33317","0.00427"
"100.15200","8.34620","0.00370"
"100.30800","8.35917","0.00407"
"100.46400","8.37215","0.00425"
"100.62000","8.38518","0.00429"
"100.77600","8.39816","0.00450"
"100.93200","8.41119","0.00404"
"101.08800","8.42417","0.00433"
"101.24400","8.43720","0.00388"
"101.40000","8.45017","0.00479"
"101.55600","8.46321","0.00426"
"101.71200","8.47618","0.00407"
"101.86800","8.48916","0.00448"
"102.02400","8.50213","0.00408"
"102.18000","8.51517","0.00423"
"102.33600","8.52814","0.00414"
"102.49200","8.54117","0.00393"
"102.64800","8.55427","0.00450"
"102.80400","8.56724","0.00439"
"102.96000","8.58016","0.00473"
"103.11600","8.59319","0.00410"
"103.27200","8.60623","0.00453"
"103.42800","8.61914","0.00420"
"103.58400","8.63211","0.00487"
"103.74000","8.64521","0.00412"
"103.89600","8.65818","0.00409"
"104.05200","8.67110","0.00438"
"104.20800","8.68419","0.00470"
"104.36400","8.69722","0.00439"
"104.52000","8.71020","0.00509"
"104.67600","8.72317","0.00482"
"104.83200","8.73621","0.00394"
"104.98800","8.74918","0.00457"
"105.14400","8.76210","0.00544"
"105.30000","8.77519","0.00518"
"105.45600","8.78822","0.00436"
"105.61200","8.80114","0.00438"
"105.76800","8.81417","0.00438"
"105.92400","8.82721","0.00484"
"106.08000","8.84018","0.00517"
"106.23600","8.85316","0.00477"
"106.39200","8.86619","0.00412"
"106.54800","8.87922","0.00514"
"106.70400","8.89214","0.00496"
"106.86000","8.90517","0.00517"
"107.01600","8.91815","0.00537"
"107.17200","8.93118","0.00490"
"107.32800","8.94410","0.00524"
"107.48400","8.95719","0.00468"
"107.64000","8.97016","0.00449"
"107.79600","8.98314","0.00452"
"107.95200","8.99617","0.00466"
"108.10800","9.00921","0.00419"
"108.26400","9.02218","0.00398"
"108.42000","9.03516","0.00449"
"108.57600","9.04819","0.00467"
"108.73200","9.06116","0.00502"
"108.88800","9.07408","0.00501"
"109.04400","9.08723","0.00541"
"109.20000","9.10015","0.00493"
"109.35600","9.11318","0.00479"
"109.51200","9.12615","0.00491"
"109.66800","9.13925","0.00494"
"109.82400","9.15222","0.00536"
"109.98000","9.16514","0.00515"
"110.13600","9.17823","0.00449"
"110.29200","9.19121","0.00499"
"110.44800","9.20418","0.00534"
"110.60400","9.21715","0.00524"
"110.76000","9.23013","0.00400"
"110.91600","9.24316","0.00401"
"111.07200","9.25608","0.00385"
"111.22800","9.26917","0.00388"
"111.38400","9.28221","0.00387"
"111.54000","9.29512","0.00397"
"111.69600","9.30815","0.00456"
"111.85200","9.32119","0.00440"
"112.00800","9.33422","0.00467"
"112.16400","9.34708","0.00413"
"112.32000","9.36023","0.00425"
"112.47600","9.37315","0.00465"
"112.63200","9.38618","0.00389"
"112.78800","9.39915","0.00419"
"112.94400","9.41219","0.00480"
"113.10000","9.42516","0.00397"
"113.25600","9.43814","0.00408"
"113.41200","9.45117","0.00448"
"113.56800","9.46420","0.00440"
"113.72400","9.47712","0.00368"
"113.88000","9.49015","0.00394"
"114.03600","9.50319","0.00304"
"114.19200","9.51616","0.00316"
"114.34800","9.52914","0.00332"
"114.50400","9.54217","0.00363"
"114.66000","9.55515","0.00348"
"114.81600","9.56812","0.00349"
"114.97200","9.58121","0.00358"
"115.12800","9.59419","0.00326"
"115.28400","9.60716","0.00349"
"115.44000","9.62014","0.00344"
"115.59600","9.63317","0.00308"
"115.75200","9.64620","0.00268"
"115.90800","9.65912","0.00345"
"116.06400","9.67221","0.00374"
"116.22000","9.68513","0.00357"
"116.37600","9.69816","0.00359"
"116.53200","9.71113","0.00355"
"116.68800","9.72417","0.00374"
"116.84400","9.73714","0.00375"
"117.00000","9.75012","0.00410"
"117.15600","9.76321","0.00327"
"117.31200","9.77619","0.00386"
"117.46800","9.78916","0.00355"
"117.62400","9.80219","0.00361"
"117.78000","9.81517","0.00391"
"117.93600","9.82814","0.00334"
"118.09200","9.84112","0.00402"
"118.24800","9.85415","0.00438"
"118.40400","9.86719","0.00423"
"118.56000","9.88016","0.00383"
"118.71600","9.89319","0.00362"
"118.87200","9.90623","0.00363"
"119.02800","9.91914","0.00391"
"119.18400","9.93218","0.00432"
"119.34000","9.94521","0.00484"
"119.49600","9.95813","0.00371"
"119.65200","9.97110","0.00362"
"119.80800","9.98419","0.00460"
"119.96400","9.99717","0.00348"
"120.12000","10.01014","0.00393"
"120.27600","10.02318","0.00399"
"120.43200","10.03621","0.00397"
"120.58800","10.04919","0.00457"
"120.74400","10.06210","0.00393"
"120.90000","10.07519","0.00431"
"121.05600","10.08817","0.00388"
"121.21200","10.10114","0.00455"
"121.36800","10.11412","0.00399"
"121.52400","10.12721","0.00428"
"121.68000","10.14012","0.00409"
"121.83600","10.15310","0.00437"
"121.99200","10.16619","0.00429"
"122.14800","10.17923","0.00346"
"122.30400","10.19214","0.00421"
"122.46000","10.20524","0.00437"
"122.61600","10.21827","0.00446"
"122.77200","10.23118","0.00417"
"122.92800","10.24416","0.00401"
"123.08400","10.25719","0.00406"
"123.24000","10.27023","0.00408"
"123.39600","10.28314","0.00428"
"123.55200","10.29612","0.00383"
"123.70800","10.30915","0.00383"
"123.86400","10.32212","0.00388"
"124.02000","10.33516","0.00442"
"124.17600","10.34819","0.00416"
"124.33200","10.36117","0.00442"
"124.48800","10.37414","0.00367"
"124.64400","10.38718","0.00415"
"124.80000","10.40015","0.00441"
"124.95600","10.41318","0.00425"
"125.11200","10.42616","0.00477"
"125.26800","10.43919","0.00452"
"125.42400","10.45217","0.00427"
"125.58000","10.46514","0.00406"
"125.73600","10.47818","0.00386"
"125.89200","10.49121","0.00417"
"126.04800","10.50418","0.00456"
"126.20400","10.51716","0.00459"
"126.36000","10.53019","0.00465"
"126.51600","10.54311","0.00472"
"126.67200","10.55614","0.00426"
"126.82800","10.56918","0.00496"
"126.98400","10.58221","0.00457"
"127.14000","10.59512","0.00437"
"127.29600","10.60822","0.00455"
"127.45200","10.62119","0.00429"
"127.60800","10.63423","0.00403"
"127.76400","10.64714","0.00439"
"127.92000","10.66023","0.00447"
"128.07600","10.67321","0.00466"
"128.23200","10.68612","0.00448"
"128.38800","10.69916","0.00452"
"128.54400","10.71219","0.00401"
"128.70000","10.72517","0.00395"
"128.85600","10.73814","0.00468"
"129.01200","10.75117","0.00444"
"129.16800","10.76415","0.00458"
"129.32400","10.77712","0.00418"
"129.48000","10.79022","0.00442"
"129.63600","10.80325","0.00481"
"129.79200","10.81617","0.00445"
"129.94800","10.82920","0.00419"
"130.10400","10.84223","0.00447"
"130.26000","10.85521","0.00493"
"130.41600","10.86812","0.00457"
"130.57200","10.88116","0.00428"
"130.72800","10.89419","0.00412"
"130.88400","10.90717","0.00481"
"131.04000","10.92014","0.00489"
"131.19600","10.93323","0.00472"
"131.35200","10.94627","0.00440"
"131.50800","10.95918","0.00413"
"131.66400","10.97222","0.00472"
"131.82000","10.98519","0.00524"
"131.97600","10.99823","0.00470"
"132.13200","11.01120","0.00450"
"132.28800","11.02417","0.00451"
"132.44400","11.03721","0.00485"
"132.60000","11.05006","0.00525"
"132.75600","11.06316","0.00520"
"132.91200","11.07619","0.00540"
"133.06800","11.08922","0.00505"
"133.22400","11.10220","0.00455"
"133.38000","11.11517","0.00445"
"133.53600","11.12821","0.00532"
"133.69200","11.14112","0.00495"
"133.84800","11.15422","0.00460"
"134.00400","11.16719","0.00501"
"134.16000","11.18016","0.00474"
"134.31600","11.19314","0.00486"
"134.47200","11.20617","0.00505"
"134.62800","11.21915","0.00464"
"134.78400","11.23218","0.00514"
"134.94000","11.24522","0.00471"
"135.09600","11.25819","0.00482"
"135.25200","11.27116","0.00446"
"135.40800","11.28414","0.00464"
"135.56400","11.29717","0.00490"
"135.72000","11.31009","0.00522"
"135.87600","11.32318","0.00552"
"136.03200","11.33622","0.00505"
"136.18800","11.34919","0.00436"
"136.34400","11.36210","0.00539"
"136.50000","11.37520","0.00496"
"136.65600","11.38817","0.00476"
"136.81200","11.40115","0.00529"
"136.96800","11.41418","0.00542"
"137.12400","11.42722","0.00547"
"137.28000","11.44019","0.00481"
"137.43600","11.45316","0.00469"
"137.59200","11.46620","0.00490"
"137.74800","11.47923","0.00450"
"137.90400","11.49215","0.00503"
"138.06000","11.50512","0.00569"
"138.21600","11.51822","0.00567"
"138.37200","11.53119","0.00482"
"138.52800","11.54416","0.00534"
"138.68400","11.55720","0.00514"
"138.84000","11.57017","0.00549"
"138.99600","11.58309","0.00548"
"139.15200","11.59612","0.00473"
"139.30800","11.60915","0.00510"
"139.46400","11.62213","0.00551"
"139.62000","11.63510","0.00489"
"139.77600","11.64820","0.00541"
"139.93200","11.66123","0.00567"
"140.08800","11.67415","0.00566"
"140.24400","11.68718","0.00507"
"140.40000","11.70021","0.00508"
"140.55600","11.71319","0.00449"
"140.71200","11.72616","0.00558"
"140.86800","11.73914","0.00523"
"141.02400","11.75217","0.00545"
"141.18000","11.76509","0.00547"
"141.33600","11.77818","0.00596"
"141.49200","11.79121","0.00592"
"141.64800","11.80413","0.00580"
"141.80400","11.81716","0.00489"
"141.96000","11.83020","0.00552"
"142.11600","11.84323","0.00526"
"142.27200","11.85614","0.00613"
"142.42800","11.86924","0.00590"
"142.58400","11.88215","0.00555"
"142.74000","11.89519","0.00542"
"142.89600","11.90816","0.00551"
"143.05200","11.92114","0.00591"
"143.20800","11.93411","0.00541"
"143.36400","11.94709","0.00598"
"143.52000","11.96018","0.00533"
"143.67600","11.97321","0.00597"
"143.83200","11.98613","0.00579"
"143.98800","11.99922","0.00616"
"144.14400","12.01219","0.00600"
"144.30000","12.02517","0.00574"
"144.45600","12.03814","0.00629"
"144.61200","12.05118","0.00554"
"144.76800","12.06421","0.00615"
"144.92400","12.07713","0.00580"
"145.08000","12.09022","0.00608"
"145.23600","12.10319","0.00686"
"145.39200","12.11617","0.00666"
"145.54800","12.12914","0.00588"
"145.70400","12.14224","0.00569"
"145.86000","12.15521","0.00576"
"146.01600","12.16819","0.00620"
"146.17200","12.18116","0.00577"
"146.32800","12.19420","0.00564"
"146.48400","12.20711","0.00399"
"146.64000","12.22014","0.00619"
"146.79600","12.23318","0.00598"
"146.95200","12.24615","0.00692"
"147.10800","12.25913","0.00572"
"147.26400","12.27222","0.00414"
"147.42000","12.28520","0.00488"
"147.57600","12.29817","0.00666"
"147.73200","12.31114","0.00595"
"147.88800","12.32418","0.00571"
"148.04400","12.33721","0.00531"
"148.20000","12.35007","0.00582"
"148.35600","12.36316","0.00562"
"148.51200","12.37619","0.00604"
"148.66800","12.38917","0.00589"
"148.82400","12.40220","0.00608"
"148.98000","12.41518","0.00578"
"149.13600","12.42821","0.00596"
"149.29200","12.44112","0.00644"
"149.44800","12.45422","0.00645"
"149.60400","12.46719","0.00643"
"149.76000","12.48011","0.00682"
"149.91600","12.49314","0.00618"
"150.07200","12.50618","0.00591"
"150.22800","12.51915","0.00630"
"150.38400","12.53213","0.00636"
"150.54000","12.54522","0.00624"
"150.69600","12.55819","0.00658"
"150.85200","12.57123","0.00657"
"151.00800","12.58420","0.00630"
"151.16400","12.59724","0.00648"
"151.32000","12.61015","0.00618"
"151.47600","12.62313","0.00694"
"151.63200","12.63616","0.00693"
"151.78800","12.64913","0.00672"
"151.94400","12.66211","0.00712"
"152.10000","12.67514","0.00677"
"152.25600","12.68818","0.00700"
"152.41200","12.70109","0.00699"
"152.56800","12.71418","0.00715"
"152.72400","12.72722","0.00658"
"152.88000","12.74019","0.00726"
"153.03600","12.75311","0.00676"
"153.19200","12.76620","0.00773"
"153.34800","12.77918","0.00696"
"153.50400","12.79215","0.00622"
"153.66000","12.80512","0.00653"
"153.81600","12.81816","0.00642"
"153.97200","12.83113","0.00703"
"154.12800","12.84405","0.00635"
"154.28400","12.85720","0.00683"
"154.44000","12.87024","0.00603"
"154.59600","12.88321","0.00728"
"154.75200","12.89624","0.00690"
"154.90800","12.90922","0.00772"
"155.06400","12.92219","0.00727"
"155.22000","12.93511","0.00737"
"155.37600","12.94826","0.00710"
"155.53200","12.96117","0.00749"
"155.68800","12.97415","0.00541"
"155.84400","12.98712","0.00465"
"156.00000","13.00016","0.00559"
"156.15600","13.01313","0.00536"
"156.31200","13.02617","0.00583"
"156.46800","13.03920","0.00509"
"156.62400","13.05217","0.00461"
"156.78000","13.06515","0.00461"
"156.93600","13.07812","0.00468"
"157.09200","13.09122","0.00555"
"157.24800","13.10419","0.00500"
"157.40400","13.11717","0.00479"
"157.56000","13.13014","0.00501"
"157.71600","13.14317","0.00603"
"157.87200","13.15609","0.00600"
"158.02800","13.16924","0.00569"
"158.18400","13.18222","0.00557"
"158.34000","13.19519","0.00611"
"158.49600","13.20817","0.00590"
"158.65200","13.22120","0.00486"
"158.80800","13.23417","0.00572"
"158.96400","13.24709","0.00560"
"159.12000","13.26018","0.00575"
"159.27600","13.27316","0.00574"
"159.43200","13.28613","0.00636"
"159.58800","13.29917","0.00564"
"159.74400","13.31214","0.00585"
"159.90000","13.32517","0.00593"
"160.05600","13.33815","0.00640"
"160.21200","13.35118","0.00644"
"160.36800","13.36416","0.00590"
"160.52400","13.37713","0.00621"
"160.68000","13.39023","0.00627"
"160.83600","13.40320","0.00672"
"160.99200","13.41617","0.00674"
"161.14800","13.42915","0.00655"
"161.30400","13.44218","0.00636"
"161.46000","13.45516","0.00251"
"161.61600","13.46813","0.00260"
"161.77200","13.48123","0.00436"
"161.92800","13.49420","0.00311"
"162.08400","13.50711","0.00270"
"162.24000","13.52015","0.00229"
"162.39600","13.53318","0.00346"
"162.55200","13.54616","0.00404"
"162.70800","13.55907","0.00221"
"162.86400","13.57222","0.00278"
"163.02000","13.58520","0.00282"
"163.17600","13.59817","0.00290"
"163.33200","13.61115","0.00387"
"163.48800","13.62424","0.00272"
"163.64400","13.63722","0.00252"
"163.80000","13.65013","0.00282"
"163.95600","13.66322","0.00330"
"164.11200","13.67620","0.00314"
"164.26800","13.68917","0.00184"
"164.42400","13.70215","0.00371"
"164.58000","13.71524","0.00398"
"164.73600","13.72816","0.00310"
"164.89200","13.74107","0.00292"
"165.04800","13.75416","0.00222"
"165.20400","13.76726","0.00370"
"165.36000","13.78017","0.00380"
"165.51600","13.79321","0.00286"
"165.67200","13.80624","0.00269"
"165.82800","13.81921","0.00361"
"165.98400","13.83219","0.00313"
"166.14000","13.84522","0.00289"
"166.29600","13.85820","0.00325"
"166.45200","13.87117","0.00385"
"166.60800","13.88415","0.00331"
"166.76400","13.89718","0.00233"
"166.92000","13.91015","0.00343"
"167.07600","13.92313","0.00310"
"167.23200","13.93622","0.00414"
"167.38800","13.94920","0.00357"
"167.54400","13.96211","0.00319"
"167.70000","13.97515","0.00360"
"167.85600","13.98818","0.00330"
"168.01200","14.00115","0.00392"
"168.16800","14.01413","0.00400"
"168.32400","14.02722","0.00344"
"168.48000","14.04020","0.00353"
"168.63600","14.05317","0.00395"
"168.79200","14.06621","0.00397"
"168.94800","14.07918","0.00417"
"169.10400","14.09215","0.00477"
"169.26000","14.10513","0.00386"
"169.41600","14.11822","0.00417"
"169.57200","14.13114","0.00454"
"169.72800","14.14411","0.00413"
"169.88400","14.15721","0.00409"
"170.04000","14.17024","0.00429"
"170.19600","14.18315","0.00398"
"170.35200","14.19619","0.00426"
"170.50800","14.20922","0.00423"
"170.66400","14.22220","0.00497"
"170.82000","14.23517","0.00476"
"170.97600","14.24827","0.00409"
"171.13200","14.26118","0.00446"
"171.28800","14.27409","0.00498"
"171.44400","14.28719","0.00495"
"171.60000","14.30022","0.00490"
"171.75600","14.31314","0.00464"
"171.91200","14.32611","0.00445"
"172.06800","14.33920","0.00270"
"172.22400","14.35218","0.00368"
"172.38000","14.36515","0.00413"
"172.53600","14.37819","0.00311"
"172.69200","14.39122","0.00341"
"172.84800","14.40420","0.00397"
"173.00400","14.41717","0.00390"
"173.16000","14.43020","0.00341"
"173.31600","14.44318","0.00327"
"173.47200","14.45615","0.00447"
"173.62800","14.46919","0.00388"
"173.78400","14.48222","0.00306"
"173.94000","14.49514","0.00441"
"174.09600","14.50817","0.00368"
"174.25200","14.52120","0.00401"
"174.40800","14.53424","0.00371"
"174.56400","14.54715","0.00383"
"174.72000","14.56019","0.00378"
"174.87600","14.57316","0.00388"
"175.03200","14.58619","0.00376"
"175.18800","14.59911","0.00437"
"175.34400","14.61214","0.00437"
"175.50000","14.62518","0.00372"
"175.65600","14.63809","0.00413"
"175.81200","14.65119","0.00393"
"175.96800","14.66422","0.00399"
"176.12400","14.67719","0.00412"
"176.28000","14.69017","0.00431"
"176.43600","14.70320","0.00441"
"176.59200","14.71624","0.00379"
"176.74800","14.72915","0.00339"
"176.90400","14.74219","0.00321"
"177.06000","14.75516","0.00349"
"177.21600","14.76814","0.00347"
"177.37200","14.78117","0.00354"
"177.52800","14.79420","0.00381"
"177.68400","14.80712","0.00400"
"177.84000","14.82015","0.00370"
"177.99600","14.83325","0.00308"
"178.15200","14.84616","0.00357"
"178.30800","14.85913","0.00374"
"178.46400","14.87217","0.00369"
"178.62000","14.88520","0.00341"
"178.77600","14.89812","0.00386"
"178.93200","14.91115","0.00328"
"179.08800","14.92418","0.00431"
"179.24400","14.93716","0.00421"
"179.40000","14.95014","0.00392"
"179.55600","14.96323","0.00395"
"179.71200","14.97620","0.00370"
"179.86800","14.98912","0.00423"
"180.02400","15.00215","0.00397"
"180.18000","15.01518","0.00341"
"180.33600","15.02816","0.00335"
"180.49200","15.04107","0.00362"
"180.64800","15.05423","0.00365"
"180.80400","15.06720","0.00417"
"180.96000","15.08012","0.00312"
"181.11600","15.09315","0.00319"
"181.27200","15.10618","0.00410"
"181.42800","15.11916","0.00438"
"181.58400","15.13213","0.00390"
"181.74000","15.14517","0.00339"
"181.89600","15.15820","0.00398"
"182.05200","15.17111","0.00453"
"182.20800","15.18415","0.00386"
"182.36400","15.19718","0.00353"
"182.52000","15.21010","0.00409"
"182.67600","15.22307","0.00355"
"182.83200","15.23617","0.00384"
"182.98800","15.24920","0.00388"
"183.14400","15.26218","0.00352"
"183.30000","15.27521","0.00417"
"183.45600","15.28824","0.00408"
"183.61200","15.30116","0.00354"
"183.76800","15.31419","0.00387"
"183.92400","15.32717","0.00388"
"184.08000","15.34014","0.00382"
"184.23600","15.35306","0.00402"
"184.39200","15.36621","0.00390"
"184.54800","15.37918","0.00370"
"184.70400","15.39216","0.00377"
"184.86000","15.40513","0.00443"
"185.01600","15.41817","0.00414"
"185.17200","15.43114","0.00367"
"185.32800","15.44411","0.00464"
"185.48400","15.45721","0.00343"
"185.64000","15.47018","0.00385"
"185.79600","15.48316","0.00396"
"185.95200","15.49613","0.00385"
"186.10800","15.50917","0.00391"
"186.26400","15.52214","0.00390"
"186.42000","15.53517","0.00414"
"186.57600","15.54821","0.00364"
"186.73200","15.56124","0.00366"
"186.88800","15.57416","0.00380"
"187.04400","15.58719","0.00377"
"187.20000","15.60017","0.00390"
"187.35600","15.61314","0.00399"
"187.51200","15.62611","0.00350"
"187.66800","15.63921","0.00346"
"187.82400","15.65218","0.00418"
"187.98000","15.66516","0.00364"
"188.13600","15.67819","0.00336"
"188.29200","15.69116","0.00322"
"188.44800","15.70414","0.00378"
"188.60400","15.71717","0.00354"
"188.76000","15.73021","0.00363"
"188.91600","15.74318","0.00393"
"189.07200","15.75616","0.00380"
"189.22800","15.76919","0.00338"
"189.38400","15.78222","0.00351"
"189.54000","15.79514","0.00386"
"189.69600","15.80811","0.00418"
"189.85200","15.82115","0.00344"
"190.00800","15.83418","0.00423"
"190.16400","15.84710","0.00275"
"190.32000","15.86019","0.00356"
"190.47600","15.87322","0.00361"
"190.63200","15.88614","0.00412"
"190.78800","15.89911","0.00323"
"190.94400","15.91221","0.00400"
"191.10000","15.92518","0.00360"
"191.25600","15.93810","0.00378"
"191.41200","15.95119","0.00356"
"191.56800","15.96422","0.00351"
"191.72400","15.97714","0.00412"
"191.88000","15.99017","0.00390"
"192.03600","16.00321","0.00400"
"192.19200","16.01624","0.00420"
"192.34800","16.02921","0.00384"
"192.50400","16.04219","0.00354"
"192.66000","16.05516","0.00370"
"192.81600","16.06814","0.00340"
"192.97200","16.08117","0.00408"
"193.12800","16.09421","0.00428"
"193.28400","16.10718","0.00429"
"193.44000","16.12016","0.00440"
"193.59600","16.13319","0.00413"
"193.75200","16.14622","0.00456"
"193.90800","16.15920","0.00429"
"194.06400","16.17217","0.00446"
"194.22000","16.18521","0.00369"
"194.37600","16.19818","0.00452"
"194.53200","16.21115","0.00361"
"194.68800","16.22419","0.00427"
"194.84400","16.23710","0.00455"
"195.00000","16.25008","0.00394"
"195.15600","16.26317","0.00450"
"195.31200","16.27615","0.00444"
"195.46800","16.28912","0.00501"
"195.62400","16.30215","0.00412"
"195.78000","16.31519","0.00334"
"195.93600","16.32822","0.00352"
"196.09200","16.34114","0.00371"
"196.24800","16.35423","0.00399"
"196.40400","16.36720","0.00385"
"196.56000","16.38018","0.00362"
"196.71600","16.39321","0.00384"
"196.87200","16.40619","0.00334"
"197.02800","16.41916","0.00380"
"197.18400","16.43214","0.00415"
"197.34000","16.44523","0.00425"
"197.49600","16.45826","0.00414"
"197.65200","16.47112","0.00333"
"197.80800","16.48421","0.00432"
"197.96400","16.49719","0.00305"
"198.12000","16.51016","0.00331"
"198.27600","16.52314","0.00432"
"198.43200","16.53623","0.00353"
"198.58800","16.54914","0.00369"
"198.74400","16.56212","0.00406"
"198.90000","16.57515","0.00402"
"199.05600","16.58819","0.00393"
"199.21200","16.60116","0.00371"
"199.36800","16.61419","0.00413"
"199.52400","16.62723","0.00357"
"199.68000","16.64021","0.00394"
"199.83600","16.65318","0.00403"
"199.99200","16.66615","0.00417"
"200.14800","16.67919","0.00381"
"200.30400","16.69216","0.00387"
"200.46000","16.70514","0.00322"
"200.61600","16.71817","0.00357"
"200.77200","16.73114","0.00329"
"200.92800","16.74412","0.00399"
"201.08400","16.75721","0.00395"
"201.24000","16.77019","0.00402"
"201.39600","16.78316","0.00450"
"201.55200","16.79620","0.00391"
"201.70800","16.80917","0.00351"
"201.86400","16.82220","0.00444"
"202.02000","16.83518","0.00346"
"202.17600","16.84821","0.00382"
"202.33200","16.86119","0.00379"
"202.48800","16.87416","0.00383"
"202.64400","16.88720","0.00372"
"202.80000","16.90023","0.00371"
"202.95600","16.91320","0.00450"
"203.11200","16.92618","0.00401"
"203.26800","16.93921","0.00336"
"203.42400","16.95219","0.00356"
"203.58000","16.96510","0.00372"
"203.73600","16.97820","0.00402"
"203.89200","16.99117","0.00419"
"204.04800","17.00408","0.00359"
"204.20400","17.01712","0.00448"
"204.36000","17.03015","0.00336"
"204.51600","17.04319","0.00360"
"204.67200","17.05616","0.00334"
"204.82800","17.06919","0.00367"
"204.98400","17.08223","0.00400"
"205.14000","17.09514","0.00378"
"205.29600","17.10818","0.00389"
"205.45200","17.12115","0.00411"
"205.60800","17.13413","0.00423"
"205.76400","17.14710","0.00489"
"205.92000","17.16019","0.00420"
"206.07600","17.17323","0.00360"
"206.23200","17.18620","0.00408"
"206.38800","17.19918","0.00395"
"206.54400","17.21221","0.00447"
"206.70000","17.22524","0.00405"
"206.85600","17.23810","0.00437"
"207.01200","17.25125","0.00370"
"207.16800","17.26417","0.00435"
"207.32400","17.27714","0.00402"
"207.48000","17.29012","0.00366"
"207.63600","17.30315","0.00389"
"207.79200","17.31613","0.00381"
"207.94800","17.32910","0.00427"
"208.10400","17.34219","0.00390"
"208.26000","17.35523","0.00436"
"208.41600","17.36814","0.00356"
"208.57200","17.38118","0.00444"
"208.72800","17.39421","0.00403"
"208.88400","17.40718","0.00483"
"209.04000","17.42016","0.00427"
"209.19600","17.43313","0.00449"
"209.35200","17.44617","0.00400"
"209.50800","17.45914","0.00471"
"209.66400","17.47218","0.00402"
"209.82000","17.48521","0.00438"
"209.97600","17.49813","0.00438"
"210.13200","17.51116","0.00477"
"210.28800","17.52419","0.00462"
"210.44400","17.53717","0.00442"
"210.60000","17.55014","0.00382"
"210.75600","17.56312","0.00412"
"210.91200","17.57615","0.00410"
"211.06800","17.58912","0.00416"
"211.22400","17.60210","0.00465"
"211.38000","17.61513","0.00436"
"211.53600","17.62817","0.00384"
"211.69200","17.64114","0.00423"
"211.84800","17.65423","0.00504"
"212.00400","17.66721","0.00493"
"212.16000","17.68012","0.00467"
"212.31600","17.69316","0.00431"
"212.47200","17.70619","0.00417"
"212.62800","17.71917","0.00433"
"212.78400","17.73214","0.00485"
"212.94000","17.74517","0.00482"
"213.09600","17.75821","0.00458"
"213.25200","17.77112","0.00461"
"213.40800","17.78416","0.00437"
"213.56400","17.79713","0.00409"
"213.72000","17.81017","0.00481"
"213.87600","17.82314","0.00488"
"214.03200","17.83623","0.00524"
"214.18800","17.84921","0.00481"
"214.34400","17.86212","0.00475"
"214.50000","17.87516","0.00426"
"214.65600","17.88819","0.00485"
"214.81200","17.90111","0.00494"
"214.96800","17.91414","0.00506"
"215.12400","17.92723","0.00511"
"215.28000","17.94021","0.00428"
"215.43600","17.95312","0.00471"
"215.59200","17.96622","0.00415"
"215.74800","17.97925","0.00442"
"215.90400","17.99211","0.00445"
"216.06000","18.00514","0.00392"
"216.21600","18.01817","0.00485"
"216.37200","18.03115","0.00498"
"216.52800","18.04412","0.00454"
"216.68400","18.05716","0.00501"
"216.84000","18.07019","0.00481"
"216.99600","18.08316","0.00476"
"217.15200","18.09620","0.00472"
"217.30800","18.10917","0.00493"
"217.46400","18.12221","0.00527"
"217.62000","18.13512","0.00445"
"217.77600","18.14822","0.00486"
"217.93200","18.16125","0.00485"
"218.08800","18.17416","0.00465"
"218.24400","18.18714","0.00484"
"218.40000","18.20011","0.00465"
"218.55600","18.21315","0.00511"
"218.71200","18.22612","0.00505"
"218.86800","18.23922","0.00478"
"219.02400","18.25225","0.00462"
"219.18000","18.26516","0.00405"
"219.33600","18.27820","0.00505"
"219.49200","18.29117","0.00475"
"219.64800","18.30421","0.00491"
"219.80400","18.31718","0.00499"
"219.96000","18.33015","0.00483"
"220.11600","18.34319","0.00458"
"220.27200","18.35610","0.00364"
"220.42800","18.36920","0.00217"
"220.58400","18.38217","0.00170"
"220.74000","18.39515","0.00138"
"220.89600","18.40818","0.00203"
"221.05200","18.42121","0.00205"
"221.20800","18.43419","0.00186"
"221.36400","18.44710","0.00204"
"221.52000","18.46020","0.00174"
"221.67600","18.47317","0.00130"
"221.83200","18.48615","0.00146"
"221.98800","18.49918","0.00202"
"222.14400","18.51215","0.00207"
"222.30000","18.52519","0.00164"
"222.45600","18.53816","0.00193"
"222.61200","18.55126","0.00117"
"222.76800","18.56417","0.00167"
"222.92400","18.57714","0.00179"
"223.08000","18.59018","0.00175"
"223.23600","18.60316","0.00215"
"223.39200","18.61619","0.00160"
"223.54800","18.62904","0.00174"
"223.70400","18.64220","0.00185"
"223.86000","18.65517","0.00170"
"224.01600","18.66814","0.00116"
"224.17200","18.68118","0.00186"
"224.32800","18.69421","0.00142"
"224.48400","18.70719","0.00209"
"224.64000","18.72022","0.00174"
"224.79600","18.73320","0.00173"
"224.95200","18.74617","0.00170"
"225.10800","18.75915","0.00233"
"225.26400","18.77218","0.00162"
"225.42000","18.78521","0.00087"
"225.57600","18.79813","0.00212"
"225.73200","18.81116","0.00139"
"225.88800","18.82420","0.00222"
"225.97600","18.83155","0.00192"