File: Force_trajectories/170226_1/Specimen_RawData_5.csv
End date,"2/26/2017"
Specimen label,"4BG_28"
Maximum Load,"0.36069",N

Time,Extension,Load
(s),(mm),(N)
"0.00000","16.07627","0.02036"
"0.25800","16.09600","0.02082"
"0.51600","16.11950","0.02186"
"0.77400","16.14096","0.02287"
"1.03200","16.16243","0.02281"
"1.29000","16.18395","0.02354"
"1.54800","16.20535","0.02489"
"1.80600","16.22694","0.02495"
"2.06400","16.24840","0.02643"
"2.32200","16.26993","0.02698"
"2.58000","16.29145","0.02700"
"2.83800","16.31286","0.02722"
"3.09600","16.33438","0.02835"
"3.35400","16.35591","0.02872"
"3.61200","16.37743","0.02870"
"3.87000","16.39889","0.02938"
"4.12800","16.42036","0.02999"
"4.38600","16.44188","0.02976"
"4.64400","16.46347","0.03091"
"4.90200","16.48487","0.03115"
"5.16000","16.50639","0.03168"
"5.41800","16.52786","0.03241"
"5.67600","16.54939","0.03262"
"5.93400","16.57085","0.03317"
"6.19200","16.59243","0.03324"
"6.45000","16.61378","0.03385"
"6.70800","16.63536","0.03496"
"6.96600","16.65683","0.03472"
"7.22400","16.67841","0.03461"
"7.48200","16.69987","0.03548"
"7.74000","16.72140","0.03465"
"7.99800","16.74286","0.03652"
"8.25600","16.76439","0.03700"
"8.51400","16.78591","0.03729"
"8.77200","16.80737","0.03744"
"9.03000","16.82890","0.03525"
"9.28800","16.85043","0.03527"
"9.54600","16.87189","0.03695"
"9.80400","16.89341","0.03722"
"10.06200","16.91494","0.03841"
"10.32000","16.93634","0.03877"
"10.57800","16.95793","0.03955"
"10.83600","16.97933","0.03974"
"11.09400","17.00091","0.04030"
"11.35200","17.02238","0.04134"
"11.61000","17.04390","0.04101"
"11.86800","17.06531","0.04090"
"12.12600","17.08689","0.04189"
"12.38400","17.10836","0.04261"
"12.64200","17.12994","0.04256"
"12.90000","17.15134","0.04232"
"13.15800","17.17287","0.04226"
"13.41600","17.19433","0.04174"
"13.67400","17.21592","0.04305"
"13.93200","17.23738","0.04148"
"14.19000","17.25891","0.04247"
"14.44800","17.28031","0.04245"
"14.70600","17.30190","0.04275"
"14.96400","17.32342","0.04349"
"15.22200","17.34494","0.04357"
"15.48000","17.36641","0.04398"
"15.73800","17.38787","0.04313"
"15.99600","17.40940","0.04280"
"16.25400","17.43092","0.04376"
"16.51200","17.45244","0.04389"
"16.77000","17.47379","0.04460"
"17.02800","17.49543","0.04503"
"17.28600","17.51684","0.04513"
"17.54400","17.53842","0.04533"
"17.80200","17.55983","0.04593"
"18.06000","17.58135","0.04605"
"18.31800","17.60282","0.04585"
"18.57600","17.62440","0.04607"
"18.83400","17.64586","0.04666"
"19.09200","17.66745","0.04704"
"19.35000","17.68885","0.04721"
"19.60800","17.71038","0.04771"
"19.86600","17.73184","0.04775"
"20.12400","17.75337","0.04751"
"20.38200","17.77483","0.04802"
"20.64000","17.79641","0.04797"
"20.89800","17.81788","0.04863"
"21.15600","17.83940","0.04869"
"21.41400","17.86093","0.04869"
"21.67200","17.88239","0.04898"
"21.93000","17.90386","0.04896"
"22.18800","17.92532","0.04906"
"22.44600","17.94691","0.04935"
"22.70400","17.96843","0.04978"
"22.96200","17.98989","0.04994"
"23.22000","18.01130","0.05013"
"23.47800","18.03288","0.05040"
"23.73600","18.05435","0.05074"
"23.99400","18.07593","0.05075"
"24.25200","18.09734","0.05081"
"24.51000","18.11892","0.05087"
"24.76800","18.14032","0.05096"
"25.02600","18.16191","0.05106"
"25.28400","18.18337","0.05124"
"25.54200","18.20490","0.05148"
"25.80000","18.22636","0.05164"
"26.05800","18.24795","0.05089"
"26.31600","18.26941","0.05103"
"26.57400","18.29093","0.05149"
"26.83200","18.31240","0.05188"
"27.09000","18.33386","0.05200"
"27.34800","18.35533","0.05200"
"27.60600","18.37685","0.05223"
"27.86400","18.39844","0.05230"
"28.12200","18.41984","0.05227"
"28.38000","18.44142","0.05236"
"28.63800","18.46289","0.05201"
"28.89600","18.48441","0.05216"
"29.15400","18.50588","0.05186"
"29.41200","18.52740","0.05227"
"29.67000","18.54886","0.05255"
"29.92800","18.57039","0.05292"
"30.18600","18.59185","0.05267"
"30.44400","18.61344","0.05283"
"30.70200","18.63484","0.05299"
"30.96000","18.65637","0.05346"
"31.21800","18.67783","0.05430"
"31.47600","18.69942","0.05395"
"31.73400","18.72088","0.05463"
"31.99200","18.74240","0.05467"
"32.25000","18.76387","0.05487"
"32.50800","18.78545","0.05506"
"32.76600","18.80686","0.05551"
"33.02400","18.82844","0.05567"
"33.28200","18.84985","0.05624"
"33.54000","18.87137","0.05644"
"33.79800","18.89296","0.05619"
"34.05600","18.91442","0.05610"
"34.31400","18.93594","0.03611"
"34.57200","18.95735","0.03474"
"34.83000","18.97887","0.03724"
"35.08800","19.00034","0.03800"
"35.34600","19.02192","0.03973"
"35.60400","19.04338","0.03740"
"35.86200","19.06491","0.03977"
"36.12000","19.08632","0.03922"
"36.37800","19.10790","0.04197"
"36.63600","19.12936","0.04077"
"36.89400","19.15095","0.04251"
"37.15200","19.17235","0.04261"
"37.41000","19.19387","0.04392"
"37.66800","19.21534","0.04237"
"37.92600","19.23686","0.04384"
"38.18400","19.25839","0.04389"
"38.44200","19.27985","0.04515"
"38.70000","19.30132","0.04463"
"38.95800","19.32290","0.04582"
"39.21600","19.34443","0.04528"
"39.47400","19.36595","0.04595"
"39.73200","19.38736","0.04594"
"39.99000","19.40888","0.04707"
"40.24800","19.43034","0.04706"
"40.50600","19.45193","0.04760"
"40.76400","19.47345","0.04716"
"41.02200","19.49492","0.04758"
"41.28000","19.51644","0.04734"
"41.53800","19.53784","0.04789"
"41.79600","19.55943","0.04801"
"42.05400","19.58089","0.04548"
"42.31200","19.60242","0.04519"
"42.57000","19.62382","0.04631"
"42.82800","19.64540","0.04666"
"43.08600","19.66687","0.04680"
"43.34400","19.68845","0.04669"
"43.60200","19.70980","0.04710"
"43.86000","19.73138","0.04644"
"44.11800","19.75285","0.04683"
"44.37600","19.77443","0.04723"
"44.63400","19.79590","0.04751"
"44.89200","19.81742","0.04803"
"45.15000","19.83888","0.04793"
"45.40800","19.86041","0.04803"
"45.66600","19.88187","0.04857"
"45.92400","19.90340","0.04809"
"46.18200","19.92486","0.04854"
"46.44000","19.94639","0.04891"
"46.69800","19.96791","0.04885"
"46.95600","19.98944","0.04891"
"47.21400","20.01090","0.04927"
"47.47200","20.03236","0.04959"
"47.73000","20.05389","0.04976"
"47.98800","20.07535","0.04971"
"48.24600","20.09688","0.05001"
"48.50400","20.11834","0.04985"
"48.76200","20.13993","0.04995"
"49.02000","20.16133","0.04997"
"49.27800","20.18285","0.05039"
"49.53600","20.20432","0.05024"
"49.79400","20.22590","0.05050"
"50.05200","20.24731","0.05066"
"50.31000","20.26889","0.05065"
"50.56800","20.29035","0.05071"
"50.82600","20.31194","0.05107"
"51.08400","20.33334","0.05117"
"51.34200","20.35493","0.05142"
"51.60000","20.37633","0.05156"
"51.85800","20.39798","0.05159"
"52.11600","20.41938","0.05198"
"52.37400","20.44091","0.05216"
"52.63200","20.46237","0.05242"
"52.89000","20.48389","0.05282"
"53.14800","20.50542","0.05247"
"53.40600","20.52688","0.05254"
"53.66400","20.54840","0.05282"
"53.92200","20.56981","0.05295"
"54.18000","20.59139","0.05302"
"54.43800","20.61286","0.05345"
"54.69600","20.63444","0.05362"
"54.95400","20.65579","0.05389"
"55.21200","20.67737","0.05463"
"55.47000","20.69884","0.05473"
"55.72800","20.72042","0.05482"
"55.98600","20.74182","0.05470"
"56.24400","20.76335","0.05472"
"56.50200","20.78488","0.05521"
"56.76000","20.80640","0.05523"
"57.01800","20.82786","0.05574"
"57.27600","20.84945","0.05673"
"57.53400","20.87085","0.05644"
"57.79200","20.89238","0.05655"
"58.05000","20.91390","0.05698"
"58.30800","20.93537","0.05700"
"58.56600","20.95689","0.05679"
"58.82400","20.97841","0.05729"
"59.08200","20.99982","0.05785"
"59.34000","21.02134","0.05839"
"59.59800","21.04293","0.05828"
"59.85600","21.06439","0.05865"
"60.11400","21.08592","0.05895"
"60.37200","21.10732","0.05885"
"60.63000","21.12890","0.05918"
"60.88800","21.15037","0.06008"
"61.14600","21.17195","0.05916"
"61.40400","21.19336","0.05931"
"61.66200","21.21488","0.05898"
"61.92000","21.23635","0.06037"
"62.17800","21.25787","0.06052"
"62.43600","21.27939","0.06042"
"62.69400","21.30086","0.06068"
"62.95200","21.32238","0.06025"
"63.21000","21.34385","0.06103"
"63.46800","21.36531","0.06102"
"63.72600","21.38696","0.06130"
"63.98400","21.40836","0.06187"
"64.24200","21.42988","0.06268"
"64.50000","21.45135","0.06303"
"64.75800","21.47287","0.06307"
"65.01600","21.49446","0.06352"
"65.27400","21.51586","0.06340"
"65.53200","21.53733","0.06418"
"65.79000","21.55891","0.06453"
"66.04800","21.58037","0.06532"
"66.30600","21.60184","0.06532"
"66.56400","21.62336","0.06622"
"66.82200","21.64483","0.06655"
"67.08000","21.66641","0.06688"
"67.33800","21.68788","0.06683"
"67.59600","21.70940","0.06349"
"67.85400","21.73080","0.06553"
"68.11200","21.75239","0.06440"
"68.37000","21.77386","0.06617"
"68.62800","21.79538","0.06633"
"68.88600","21.81684","0.06615"
"69.14400","21.83843","0.06470"
"69.40200","21.85989","0.06600"
"69.66000","21.88141","0.06626"
"69.91800","21.90282","0.06694"
"70.17600","21.92440","0.06758"
"70.43400","21.94587","0.06806"
"70.69200","21.96739","0.06848"
"70.95000","21.98892","0.06863"
"71.20800","22.01038","0.06944"
"71.46600","22.03190","0.06838"
"71.72400","22.05337","0.06940"
"71.98200","22.07490","0.06854"
"72.24000","22.09636","0.06980"
"72.49800","22.11794","0.06997"
"72.75600","22.13941","0.07104"
"73.01400","22.16087","0.07045"
"73.27200","22.18239","0.07090"
"73.53000","22.20392","0.07153"
"73.78800","22.22538","0.07118"
"74.04600","22.24691","0.07063"
"74.30400","22.26831","0.07034"
"74.56200","22.28989","0.07141"
"74.82000","22.31136","0.07120"
"75.07800","22.33295","0.07136"
"75.33600","22.35435","0.07217"
"75.59400","22.37587","0.07293"
"75.85200","22.39734","0.07399"
"76.11000","22.41892","0.07465"
"76.36800","22.44039","0.07577"
"76.62600","22.46191","0.07630"
"76.88400","22.48332","0.07706"
"77.14200","22.50490","0.07730"
"77.40000","22.52642","0.07796"
"77.65800","22.54789","0.07813"
"77.91600","22.56941","0.07938"
"78.17400","22.59088","0.07984"
"78.43200","22.61234","0.08075"
"78.69000","22.63387","0.08135"
"78.94800","22.65545","0.08191"
"79.20600","22.67686","0.08272"
"79.46400","22.69838","0.08301"
"79.72200","22.71984","0.08430"
"79.98000","22.74143","0.08400"
"80.23800","22.76289","0.08389"
"80.49600","22.78442","0.08459"
"80.75400","22.80576","0.08457"
"81.01200","22.82741","0.08540"
"81.27000","22.84887","0.08609"
"81.52800","22.87039","0.08684"
"81.78600","22.89186","0.08718"
"82.04400","22.91338","0.08755"
"82.30200","22.93484","0.08771"
"82.56000","22.95643","0.08752"
"82.81800","22.97790","0.08694"
"83.07600","22.99942","0.08338"
"83.33400","23.02082","0.08417"
"83.59200","23.04241","0.08476"
"83.85000","23.06387","0.08598"
"84.10800","23.08546","0.08726"
"84.36600","23.10686","0.08781"
"84.62400","23.12839","0.08879"
"84.88200","23.14991","0.08925"
"85.14000","23.17137","0.08981"
"85.39800","23.19290","0.09028"
"85.65600","23.21436","0.09078"
"85.91400","23.23589","0.09178"
"86.17200","23.25729","0.09218"
"86.43000","23.27894","0.09333"
"86.68800","23.30034","0.09367"
"86.94600","23.32187","0.09355"
"87.20400","23.34333","0.09450"
"87.46200","23.36491","0.09491"
"87.72000","23.38632","0.09533"
"87.97800","23.40796","0.09574"
"88.23600","23.42937","0.09598"
"88.49400","23.45089","0.09633"
"88.75200","23.47241","0.09671"
"89.01000","23.49388","0.09707"
"89.26800","23.51534","0.09747"
"89.52600","23.53687","0.09774"
"89.78400","23.55833","0.09804"
"90.04200","23.57991","0.09845"
"90.30000","23.60144","0.09856"
"90.55800","23.62290","0.09924"
"90.81600","23.64437","0.09955"
"91.07400","23.66589","0.10025"
"91.33200","23.68736","0.10085"
"91.59000","23.70888","0.10190"
"91.84800","23.73041","0.10183"
"92.10600","23.75181","0.10168"
"92.36400","23.77339","0.10132"
"92.62200","23.79486","0.10241"
"92.88000","23.81639","0.10279"
"93.13800","23.83784","0.10318"
"93.39600","23.85937","0.10369"
"93.65400","23.88078","0.10461"
"93.91200","23.90236","0.10469"
"94.17000","23.92389","0.10578"
"94.42800","23.94541","0.10698"
"94.68600","23.96681","0.10764"
"94.94400","23.98840","0.10798"
"95.20200","24.00986","0.10862"
"95.46000","24.03139","0.11002"
"95.71800","24.05291","0.11109"
"95.97600","24.07437","0.11167"
"96.23400","24.09590","0.11269"
"96.49200","24.11736","0.11361"
"96.75000","24.13889","0.11443"
"97.00800","24.16035","0.11550"
"97.26600","24.18188","0.11652"
"97.52400","24.20334","0.11795"
"97.78200","24.22486","0.11881"
"98.04000","24.24639","0.11933"
"98.29800","24.26791","0.12042"
"98.55600","24.28932","0.12152"
"98.81400","24.31090","0.12191"
"99.07200","24.33231","0.12270"
"99.33000","24.35395","0.12381"
"99.58800","24.37536","0.12384"
"99.84600","24.39682","0.12454"
"100.10400","24.41834","0.12559"
"100.36200","24.43987","0.12611"
"100.62000","24.46133","0.12734"
"100.87800","24.48292","0.12841"
"101.13600","24.50432","0.12891"
"101.39400","24.52591","0.12971"
"101.65200","24.54737","0.12966"
"101.91000","24.56890","0.13045"
"102.16800","24.59036","0.13106"
"102.42600","24.61189","0.13180"
"102.68400","24.63341","0.13215"
"102.94200","24.65487","0.13365"
"103.20000","24.67645","0.13389"
"103.45800","24.69792","0.13454"
"103.71600","24.71939","0.13406"
"103.97400","24.74085","0.13519"
"104.23200","24.76243","0.13573"
"104.49000","24.78390","0.13608"
"104.74800","24.80542","0.13682"
"105.00600","24.82682","0.13710"
"105.26400","24.84841","0.13792"
"105.52200","24.86987","0.13814"
"105.78000","24.89140","0.13816"
"106.03800","24.91280","0.13862"
"106.29600","24.93439","0.13963"
"106.55400","24.95579","0.14050"
"106.81200","24.97738","0.14126"
"107.07000","24.99890","0.14163"
"107.32800","25.02036","0.14243"
"107.58600","25.04183","0.14233"
"107.84400","25.06335","0.14253"
"108.10200","25.08488","0.14273"
"108.36000","25.10640","0.14275"
"108.61800","25.12786","0.14304"
"108.87600","25.14939","0.14199"
"109.13400","25.17085","0.14130"
"109.39200","25.19238","0.14191"
"109.65000","25.21390","0.14223"
"109.90800","25.23537","0.14275"
"110.16600","25.25689","0.14292"
"110.42400","25.27836","0.14342"
"110.68200","25.29994","0.14348"
"110.94000","25.32141","0.14392"
"111.19800","25.34293","0.14438"
"111.45600","25.36427","0.14466"
"111.71400","25.38586","0.14524"
"111.97200","25.40732","0.14607"
"112.23000","25.42891","0.14565"
"112.48800","25.45037","0.14626"
"112.74600","25.47190","0.14674"
"113.00400","25.49330","0.14694"
"113.26200","25.51488","0.14749"
"113.52000","25.53635","0.14808"
"113.77800","25.55787","0.14870"
"114.03600","25.57934","0.14949"
"114.29400","25.60092","0.14999"
"114.55200","25.62239","0.15121"
"114.81000","25.64391","0.15160"
"115.06800","25.66532","0.15277"
"115.32600","25.68684","0.15304"
"115.58400","25.70836","0.15377"
"115.84200","25.72989","0.15437"
"116.10000","25.75141","0.15589"
"116.35800","25.77288","0.15665"
"116.61600","25.79440","0.15805"
"116.87400","25.81586","0.15868"
"117.13200","25.83739","0.16049"
"117.39000","25.85885","0.16156"
"117.64800","25.88038","0.16254"
"117.90600","25.90184","0.16352"
"118.16400","25.92337","0.16546"
"118.42200","25.94483","0.16638"
"118.68000","25.96641","0.16891"
"118.93800","25.98782","0.17006"
"119.19600","26.00934","0.17150"
"119.45400","26.03081","0.17333"
"119.71200","26.05245","0.17420"
"119.97000","26.07386","0.17552"
"120.22800","26.09538","0.17768"
"120.48600","26.11685","0.17883"
"120.74400","26.13843","0.18207"
"121.00200","26.15989","0.18326"
"121.26000","26.18142","0.18551"
"121.51800","26.20288","0.18702"
"121.77600","26.22441","0.18895"
"122.03400","26.24587","0.19010"
"122.29200","26.26740","0.19150"
"122.55000","26.28892","0.19405"
"122.80800","26.31038","0.19393"
"123.06600","26.33191","0.19485"
"123.32400","26.35337","0.19664"
"123.58200","26.37490","0.19821"
"123.84000","26.39636","0.19846"
"124.09800","26.41789","0.19937"
"124.35600","26.43929","0.20041"
"124.61400","26.46087","0.20166"
"124.87200","26.48234","0.20160"
"125.13000","26.50392","0.20226"
"125.38800","26.52539","0.20341"
"125.64600","26.54691","0.20361"
"125.90400","26.56838","0.20447"
"126.16200","26.58996","0.20504"
"126.42000","26.61137","0.20527"
"126.67800","26.63289","0.20598"
"126.93600","26.65436","0.20715"
"127.19400","26.67594","0.20789"
"127.45200","26.69740","0.20777"
"127.71000","26.71893","0.20941"
"127.96800","26.74033","0.21005"
"128.22600","26.76185","0.21005"
"128.48400","26.78338","0.21034"
"128.74200","26.80490","0.21042"
"129.00000","26.82643","0.21168"
"129.25800","26.84783","0.21239"
"129.51600","26.86936","0.21363"
"129.77400","26.89088","0.21471"
"130.03200","26.91241","0.21561"
"130.29000","26.93381","0.21626"
"130.54800","26.95539","0.21723"
"130.80600","26.97680","0.21862"
"131.06400","26.99844","0.21980"
"131.32200","27.01991","0.22082"
"131.58000","27.04143","0.22199"
"131.83800","27.06284","0.22329"
"132.09600","27.08436","0.22455"
"132.35400","27.10588","0.22585"
"132.61200","27.12747","0.22639"
"132.87000","27.14887","0.22744"
"133.12800","27.17039","0.22936"
"133.38600","27.19186","0.23022"
"133.64400","27.21338","0.23159"
"133.90200","27.23491","0.23189"
"134.16000","27.25637","0.23283"
"134.41800","27.27784","0.23402"
"134.67600","27.29936","0.23529"
"134.93400","27.32089","0.23629"
"135.19200","27.34241","0.23723"
"135.45000","27.36388","0.23853"
"135.70800","27.38534","0.23884"
"135.96600","27.40692","0.23999"
"136.22400","27.42839","0.23998"
"136.48200","27.44991","0.24051"
"136.74000","27.47132","0.24141"
"136.99800","27.49290","0.24225"
"137.25600","27.51431","0.24300"
"137.51400","27.53595","0.24322"
"137.77200","27.55735","0.24473"
"138.03000","27.57888","0.24491"
"138.28800","27.60040","0.24565"
"138.54600","27.62187","0.24623"
"138.80400","27.64333","0.24728"
"139.06200","27.66492","0.24758"
"139.32000","27.68632","0.24817"
"139.57800","27.70791","0.24879"
"139.83600","27.72937","0.24916"
"140.09400","27.75089","0.24987"
"140.35200","27.77242","0.25041"
"140.61000","27.79388","0.25095"
"140.86800","27.81535","0.25113"
"141.12600","27.83687","0.25183"
"141.38400","27.85839","0.25238"
"141.64200","27.87986","0.25291"
"141.90000","27.90138","0.25355"
"142.15800","27.92285","0.25349"
"142.41600","27.94437","0.25362"
"142.67400","27.96584","0.25428"
"142.93200","27.98736","0.25439"
"143.19000","28.00883","0.25568"
"143.44800","28.03035","0.25626"
"143.70600","28.05182","0.25738"
"143.96400","28.07346","0.25785"
"144.22200","28.09486","0.25875"
"144.48000","28.11639","0.25973"
"144.73800","28.13785","0.26009"
"144.99600","28.15938","0.26110"
"145.25400","28.18090","0.26163"
"145.51200","28.20242","0.26220"
"145.77000","28.22383","0.26211"
"146.02800","28.24541","0.26339"
"146.28600","28.26688","0.26534"
"146.54400","28.28846","0.26680"
"146.80200","28.30987","0.26836"
"147.06000","28.33139","0.26917"
"147.31800","28.35286","0.27047"
"147.57600","28.37432","0.27224"
"147.83400","28.39596","0.27330"
"148.09200","28.41737","0.27387"
"148.35000","28.43889","0.27453"
"148.60800","28.46036","0.27599"
"148.86600","28.48194","0.27708"
"149.12400","28.50341","0.27778"
"149.38200","28.52493","0.27917"
"149.64000","28.54633","0.28044"
"149.89800","28.56792","0.28128"
"150.15600","28.58932","0.28249"
"150.41400","28.61097","0.28372"
"150.67200","28.63237","0.28469"
"150.93000","28.65389","0.28599"
"151.18800","28.67536","0.28709"
"151.44600","28.69695","0.28798"
"151.70400","28.71835","0.18295"
"151.96200","28.73993","0.18673"
"152.22000","28.76134","0.18971"
"152.47800","28.78286","0.19079"
"152.73600","28.80438","0.19049"
"152.99400","28.82591","0.19198"
"153.25200","28.84737","0.19099"
"153.51000","28.86890","0.17525"
"153.76800","28.89036","0.17957"
"154.02600","28.91189","0.18328"
"154.28400","28.93347","0.18527"
"154.54200","28.95487","0.18936"
"154.80000","28.97640","0.19184"
"155.05800","28.99786","0.19505"
"155.31600","29.01939","0.19544"
"155.57400","29.04085","0.19693"
"155.83200","29.06238","0.19797"
"156.09000","29.08378","0.19783"
"156.34800","29.10537","0.19971"
"156.60600","29.12689","0.20090"
"156.86400","29.14841","0.20155"
"157.12200","29.16988","0.20203"
"157.38000","29.19140","0.20295"
"157.63800","29.21287","0.20339"
"157.89600","29.23439","0.20434"
"158.15400","29.25591","0.20490"
"158.41200","29.27738","0.20667"
"158.67000","29.29890","0.20644"
"158.92800","29.32037","0.20785"
"159.18600","29.34190","0.20850"
"159.44400","29.36342","0.20951"
"159.70200","29.38488","0.20881"
"159.96000","29.40635","0.20920"
"160.21800","29.42787","0.20982"
"160.47600","29.44940","0.21112"
"160.73400","29.47092","0.21217"
"160.99200","29.49238","0.21338"
"161.25000","29.51391","0.21203"
"161.50800","29.53537","0.21108"
"161.76600","29.55690","0.21181"
"162.02400","29.57836","0.21278"
"162.28200","29.59989","0.21394"
"162.54000","29.62129","0.21586"
"162.79800","29.64293","0.21667"
"163.05600","29.66434","0.21801"
"163.31400","29.68592","0.21989"
"163.57200","29.70733","0.22074"
"163.83000","29.72891","0.22200"
"164.08800","29.75038","0.22258"
"164.34600","29.77196","0.22455"
"164.60400","29.79342","0.22613"
"164.86200","29.81489","0.22653"
"165.12000","29.83635","0.22972"
"165.37800","29.85788","0.23041"
"165.63600","29.87940","0.10970"
"165.89400","29.90087","0.11175"
"166.15200","29.92233","0.11071"
"166.41000","29.94386","0.11216"
"166.66800","29.96538","0.11262"
"166.92600","29.98684","0.11156"
"167.18400","30.00843","0.11535"
"167.44200","30.02983","0.11423"
"167.70000","30.05136","0.11377"
"167.95800","30.07282","0.11511"
"168.21600","30.09440","0.11180"
"168.47400","30.11587","0.11341"
"168.73200","30.13739","0.11580"
"168.99000","30.15886","0.11757"
"169.24800","30.18044","0.12023"
"169.50600","30.20185","0.12206"
"169.76400","30.22349","0.12377"
"170.02200","30.24483","0.12468"
"170.28000","30.26642","0.12606"
"170.53800","30.28788","0.12597"
"170.79600","30.30941","0.12640"
"171.05400","30.33087","0.12796"
"171.31200","30.35240","0.12891"
"171.57000","30.37386","0.13009"
"171.82800","30.39544","0.13105"
"172.08600","30.41691","0.13064"
"172.34400","30.43843","0.13203"
"172.60200","30.45984","0.13280"
"172.86000","30.48136","0.13388"
"173.11800","30.50289","0.13495"
"173.37600","30.52435","0.13556"
"173.63400","30.54594","0.13641"
"173.89200","30.56734","0.13712"
"174.15000","30.58892","0.13703"
"174.40800","30.61033","0.13749"
"174.66600","30.63191","0.13819"
"174.92400","30.65338","0.13832"
"175.18200","30.67490","0.13864"
"175.44000","30.69631","0.10923"
"175.69800","30.71789","0.11184"
"175.95600","30.73942","0.11462"
"176.21400","30.76094","0.11741"
"176.47200","30.78240","0.11898"
"176.73000","30.80393","0.11887"
"176.98800","30.82539","0.12199"
"177.24600","30.84698","0.12023"
"177.50400","30.86838","0.12002"
"177.76200","30.88990","0.12179"
"178.02000","30.91137","0.12223"
"178.27800","30.93289","0.06411"
"178.53600","30.95436","0.05625"
"178.79400","30.97588","0.06039"
"179.05200","30.99735","0.05874"
"179.31000","31.01887","0.06141"
"179.56800","31.04033","0.06113"
"179.82600","31.06186","0.06372"
"180.08400","31.08344","0.06312"
"180.34200","31.10485","0.06604"
"180.60000","31.12643","0.06386"
"180.85800","31.14784","0.06844"
"181.11600","31.16942","0.06675"
"181.37400","31.19089","0.06995"
"181.63200","31.21241","0.06896"
"181.89000","31.23388","0.07038"
"182.14800","31.25540","0.07062"
"182.40600","31.27686","0.07296"
"182.66400","31.29844","0.07305"
"182.92200","31.31985","0.07493"
"183.18000","31.34137","0.07488"
"183.43800","31.36284","0.07634"
"183.69600","31.38442","0.07654"
"183.95400","31.40589","0.07690"
"184.21200","31.42741","0.07823"
"184.47000","31.44888","0.07883"
"184.72800","31.47034","0.07822"
"184.98600","31.49192","0.07811"
"185.24400","31.51339","0.07858"
"185.50200","31.53485","0.07847"
"185.76000","31.55638","0.07985"
"186.01800","31.57784","0.07961"
"186.27600","31.59937","0.08035"
"186.53400","31.62089","0.08071"
"186.79200","31.64230","0.08215"
"187.05000","31.66388","0.08293"
"187.30800","31.68534","0.08451"
"187.56600","31.70693","0.08466"
"187.82400","31.72833","0.08619"
"188.08200","31.74986","0.08731"
"188.34000","31.77132","0.08783"
"188.59800","31.79291","0.08956"
"188.85600","31.81437","0.09025"
"189.11400","31.83589","0.09051"
"189.37200","31.85736","0.09091"
"189.63000","31.87900","0.09183"
"189.88800","31.90035","0.09201"
"190.14600","31.92193","0.09313"
"190.40400","31.94334","0.09311"
"190.66200","31.96486","0.09351"
"190.92000","31.98638","0.09409"
"191.17800","32.00785","0.09468"
"191.43600","32.02937","0.09531"
"191.69400","32.05084","0.09549"
"191.95200","32.07242","0.09563"
"192.21000","32.09389","0.09601"
"192.46800","32.11541","0.09648"
"192.72600","32.13693","0.09683"
"192.98400","32.15840","0.09722"
"193.24200","32.17986","0.09763"
"193.50000","32.20139","0.09777"
"193.75800","32.22285","0.09783"
"194.01600","32.24437","0.09806"
"194.27400","32.26584","0.09825"
"194.53200","32.28736","0.09854"
"194.79000","32.30883","0.09881"
"195.04800","32.33035","0.09867"
"195.30600","32.35188","0.09859"
"195.56400","32.37340","0.09857"
"195.82200","32.39481","0.09936"
"196.08000","32.41645","0.09971"
"196.33800","32.43791","0.10001"
"196.59600","32.45944","0.10084"
"196.85400","32.48084","0.10080"
"197.11200","32.50243","0.10053"
"197.37000","32.52389","0.10041"
"197.62800","32.54541","0.10150"
"197.88600","32.56694","0.10213"
"198.14400","32.58834","0.10256"
"198.40200","32.60987","0.10360"
"198.66000","32.63133","0.10434"
"198.91800","32.65292","0.10505"
"199.17600","32.67432","0.10500"
"199.43400","32.69590","0.10636"
"199.69200","32.71731","0.10793"
"199.95000","32.73895","0.10789"
"200.20800","32.76036","0.10916"
"200.46600","32.78194","0.10941"
"200.72400","32.80329","0.11111"
"200.98200","32.82487","0.11203"
"201.24000","32.84634","0.11379"
"201.49800","32.86792","0.11460"
"201.75600","32.88939","0.11594"
"202.01400","32.91091","0.11838"
"202.27200","32.93237","0.11895"
"202.53000","32.95390","0.12084"
"202.78800","32.97536","0.12241"
"203.04600","32.99689","0.12303"
"203.30400","33.01835","0.12215"
"203.56200","33.03994","0.12231"
"203.82000","33.06134","0.12330"
"204.07800","33.08292","0.11336"
"204.33600","33.10439","0.11335"
"204.59400","33.12585","0.11489"
"204.85200","33.14738","0.11597"
"205.11000","33.16890","0.11793"
"205.36800","33.19036","0.11959"
"205.62600","33.21183","0.12165"
"205.88400","33.23341","0.12336"
"206.14200","33.25482","0.12411"
"206.40000","33.27640","0.12581"
"206.65800","33.29781","0.12717"
"206.91600","33.31939","0.12770"
"207.17400","33.34085","0.12794"
"207.43200","33.36238","0.12969"
"207.69000","33.38390","0.13114"
"207.94800","33.40543","0.13251"
"208.20600","33.42689","0.13335"
"208.46400","33.44836","0.13451"
"208.72200","33.46982","0.13515"
"208.98000","33.49141","0.13566"
"209.23800","33.51293","0.13626"
"209.49600","33.53433","0.13681"
"209.75400","33.55586","0.13738"
"210.01200","33.57738","0.13821"
"210.27000","33.59891","0.13850"
"210.52800","33.62037","0.13946"
"210.78600","33.64190","0.13995"
"211.04400","33.66336","0.14048"
"211.30200","33.68488","0.14073"
"211.56000","33.70635","0.14172"
"211.81800","33.72793","0.14192"
"212.07600","33.74934","0.14208"
"212.33400","33.77092","0.14270"
"212.59200","33.79232","0.14336"
"212.85000","33.81391","0.14347"
"213.10800","33.83537","0.14397"
"213.36600","33.85690","0.14426"
"213.62400","33.87830","0.14494"
"213.88200","33.89989","0.14505"
"214.14000","33.92135","0.14585"
"214.39800","33.94294","0.14682"
"214.65600","33.96434","0.14740"
"214.91400","33.98592","0.14799"
"215.17200","34.00733","0.14920"
"215.43000","34.02892","0.14971"
"215.68800","34.05038","0.15114"
"215.94600","34.07184","0.15289"
"216.20400","34.09336","0.15355"
"216.46200","34.11483","0.15441"
"216.72000","34.13641","0.15608"
"216.97800","34.15788","0.15807"
"217.23600","34.17934","0.16002"
"217.49400","34.20081","0.16190"
"217.75200","34.22239","0.16361"
"218.01000","34.24385","0.16671"
"218.26800","34.26544","0.15271"
"218.52600","34.28679","0.15354"
"218.78400","34.30843","0.15510"
"219.04200","34.32983","0.15676"
"219.30000","34.35136","0.15944"
"219.55800","34.37288","0.16282"
"219.81600","34.39441","0.16339"
"220.07400","34.41581","0.16533"
"220.33200","34.43740","0.16518"
"220.59000","34.45886","0.16798"
"220.84800","34.48045","0.17060"
"221.10600","34.50185","0.17299"
"221.36400","34.52337","0.17631"
"221.62200","34.54484","0.17830"
"221.88000","34.56642","0.18301"
"222.13800","34.58789","0.18608"
"222.39600","34.60935","0.18946"
"222.65400","34.63087","0.19151"
"222.91200","34.65240","0.19372"
"223.17000","34.67392","0.19233"
"223.42800","34.69539","0.19475"
"223.68600","34.71691","0.19676"
"223.94400","34.73832","0.19793"
"224.20200","34.75990","0.19974"
"224.46000","34.78143","0.20066"
"224.71800","34.80295","0.20184"
"224.97600","34.82429","0.20281"
"225.23400","34.84588","0.20355"
"225.49200","34.86734","0.20446"
"225.75000","34.88887","0.20537"
"226.00800","34.91039","0.20638"
"226.26600","34.93191","0.20747"
"226.52400","34.95332","0.20875"
"226.78200","34.97484","0.20986"
"227.04000","34.99637","0.21165"
"227.29800","35.01789","0.21304"
"227.55600","35.03942","0.21433"
"227.81400","35.06088","0.21592"
"228.07200","35.08234","0.21768"
"228.33000","35.10393","0.21814"
"228.58800","35.12539","0.21933"
"228.84600","35.14686","0.22068"
"229.10400","35.16832","0.22216"
"229.36200","35.18985","0.22270"
"229.62000","35.21143","0.22494"
"229.87800","35.23283","0.22674"
"230.13600","35.25436","0.22874"
"230.39400","35.27583","0.22949"
"230.65200","35.29741","0.23092"
"230.91000","35.31887","0.23237"
"231.16800","35.34040","0.23434"
"231.42600","35.36180","0.23632"
"231.68400","35.38338","0.23800"
"231.94200","35.40485","0.23893"
"232.20000","35.42643","0.24074"
"232.45800","35.44784","0.24141"
"232.71600","35.46936","0.24271"
"232.97400","35.49083","0.24378"
"233.23200","35.51241","0.24488"
"233.49000","35.53387","0.24567"
"233.74800","35.55540","0.24637"
"234.00600","35.57681","0.24658"
"234.26400","35.59839","0.24734"
"234.52200","35.61985","0.24783"
"234.78000","35.64138","0.24876"
"235.03800","35.66284","0.24890"
"235.29600","35.68436","0.24953"
"235.55400","35.70589","0.25013"
"235.81200","35.72742","0.25025"
"236.07000","35.74894","0.25119"
"236.32800","35.77034","0.25178"
"236.58600","35.79187","0.25257"
"236.84400","35.81333","0.25347"
"237.10200","35.83492","0.25449"
"237.36000","35.85638","0.25562"
"237.61800","35.87785","0.25665"
"237.87600","35.89931","0.25794"
"238.13400","35.92083","0.25882"
"238.39200","35.94242","0.25975"
"238.65000","35.96388","0.26117"
"238.90800","35.98535","0.26290"
"239.16600","36.00693","0.26434"
"239.42400","36.02834","0.26596"
"239.68200","36.04998","0.26727"
"239.94000","36.07138","0.26832"
"240.19800","36.09291","0.26837"
"240.45600","36.11437","0.26961"
"240.71400","36.13590","0.27047"
"240.97200","36.15742","0.27230"
"241.23000","36.17895","0.27394"
"241.48800","36.20035","0.27501"
"241.74600","36.22181","0.27581"
"242.00400","36.24340","0.27742"
"242.26200","36.26492","0.27787"
"242.52000","36.28645","0.27953"
"242.77800","36.30785","0.28034"
"243.03600","36.32944","0.28248"
"243.29400","36.35084","0.28364"
"243.55200","36.37248","0.28556"
"243.81000","36.39389","0.28624"
"244.06800","36.41535","0.28812"
"244.32600","36.43682","0.29022"
"244.58400","36.45840","0.29071"
"244.84200","36.47987","0.29258"
"245.10000","36.50145","0.29391"
"245.35800","36.52285","0.29527"
"245.61600","36.54438","0.29617"
"245.87400","36.56585","0.29736"
"246.13200","36.58743","0.29809"
"246.39000","36.60883","0.29909"
"246.64800","36.63041","0.29997"
"246.90600","36.65188","0.30150"
"247.16400","36.67340","0.30289"
"247.42200","36.69493","0.30484"
"247.68000","36.71639","0.30727"
"247.93800","36.73786","0.30875"
"248.19600","36.75938","0.31092"
"248.45400","36.78091","0.31435"
"248.71200","36.80243","0.31562"
"248.97000","36.82396","0.31790"
"249.22800","36.84530","0.32101"
"249.48600","36.86689","0.32255"
"249.74400","36.88829","0.32461"
"250.00200","36.90987","0.32636"
"250.26000","36.93134","0.32911"
"250.51800","36.95292","0.33181"
"250.77600","36.97433","0.33336"
"251.03400","36.99585","0.33533"
"251.29200","37.01731","0.33701"
"251.55000","37.03896","0.33963"
"251.80800","37.06036","0.34052"
"252.06600","37.08189","0.34373"
"252.32400","37.10335","0.34409"
"252.58200","37.12494","0.34685"
"252.84000","37.14634","0.34858"
"253.09800","37.16787","0.35037"
"253.35600","37.18939","0.35196"
"253.61400","37.21091","0.35336"
"253.87200","37.23244","0.35450"
"254.13000","37.25390","0.35534"
"254.38800","37.27542","0.35589"
"254.64600","37.29689","0.35640"
"254.90400","37.31836","0.35672"
"255.16200","37.33988","0.35689"
"255.42000","37.36140","0.35742"
"255.67800","37.38281","0.35767"
"255.93600","37.40439","0.35766"
"256.19400","37.42586","0.35795"
"256.45200","37.44738","0.35771"
"256.71000","37.46884","0.35809"
"256.96800","37.49037","0.35822"
"257.22600","37.51177","0.35849"
"257.48400","37.53342","0.35876"
"257.74200","37.55488","0.35869"
"258.00000","37.57641","0.35930"
"258.25800","37.59787","0.35948"
"258.51600","37.61939","0.35990"
"258.77400","37.64086","0.36019"
"259.03200","37.66244","0.07799"
"259.29000","37.68385","0.06629"
"259.54800","37.70537","0.05657"
"259.80600","37.72690","0.06818"
"260.06400","37.74842","0.04557"
"260.32200","37.76994","0.04973"
"260.58000","37.79135","0.05124"
"260.83800","37.81287","0.05183"
"261.09600","37.83434","0.06091"
"261.35400","37.85592","0.04865"
"261.61200","37.87739","0.05204"
"261.87000","37.89891","0.05141"
"262.12800","37.92031","0.05258"
"262.38600","37.94190","0.06590"
"262.64400","37.96336","0.05384"
"262.90200","37.98495","0.06224"
"263.16000","38.00636","0.05492"
"263.41800","38.02788","0.05523"
"263.67600","38.04934","0.06222"
"263.93400","38.07092","0.05624"
"264.19200","38.09239","0.06728"
"264.45000","38.11385","0.06275"
"264.70800","38.13532","0.06842"
"264.96600","38.15691","0.06639"
"265.22400","38.17836","0.07162"
"265.48200","38.19995","0.06740"
"265.74000","38.22136","0.07505"
"265.99800","38.24288","0.07047"
"266.25600","38.26440","0.07672"
"266.51400","38.28587","0.07695"
"266.77200","38.30745","0.07856"
"267.03000","38.32886","0.08179"
"267.28800","38.35044","0.08332"
"267.54600","38.37191","0.08428"
"267.80400","38.39337","0.08841"
"268.06200","38.41489","0.08439"
"268.32000","38.43642","0.08651"
"268.57800","38.45776","0.08963"
"268.83600","38.47941","0.09000"
"269.09400","38.50087","0.09238"
"269.35200","38.52246","0.09366"
"269.61000","38.54380","0.09399"
"269.86800","38.56533","0.09619"
"270.12600","38.58679","0.09669"
"270.38400","38.60843","0.09703"
"270.64200","38.62990","0.09849"
"270.90000","38.65142","0.09875"
"271.15800","38.67289","0.09908"
"271.41600","38.69441","0.09683"
"271.67400","38.71588","0.09632"
"271.93200","38.73746","0.09700"
"272.19000","38.75886","0.09706"
"272.44800","38.78033","0.09800"
"272.70600","38.80185","0.09842"
"272.96400","38.82338","0.09972"
"273.22200","38.84490","0.10087"
"273.48000","38.86637","0.10197"
"273.73800","38.88789","0.10333"
"273.99600","38.90936","0.10384"
"274.25400","38.93088","0.10710"
"274.51200","38.95234","0.10892"
"274.77000","38.97393","0.11099"
"275.02800","38.99539","0.11100"
"275.28600","39.01692","0.11373"
"275.54400","39.03832","0.11503"
"275.80200","39.05990","0.11655"
"276.06000","39.08131","0.11937"
"276.31800","39.10289","0.12160"
"276.57600","39.12436","0.12375"
"276.83400","39.14594","0.12584"
"277.09200","39.16734","0.12705"
"277.35000","39.18887","0.12829"
"277.60800","39.21033","0.12973"
"277.86600","39.23192","0.13092"
"278.12400","39.25338","0.13202"
"278.38200","39.27491","0.13417"
"278.64000","39.29638","0.13539"
"278.89800","39.31789","0.13654"
"279.15600","39.33942","0.13715"
"279.41400","39.36088","0.13749"
"279.67200","39.38241","0.13924"
"279.93000","39.40387","0.14007"
"280.18800","39.42540","0.14068"
"280.44600","39.44686","0.14127"
"280.70400","39.46838","0.14264"
"280.96200","39.48985","0.14313"
"281.22000","39.51138","0.14363"
"281.47800","39.53278","0.14425"
"281.73600","39.55436","0.14505"
"281.99400","39.57583","0.14579"
"282.25200","39.59741","0.14598"
"282.51000","39.61888","0.14809"
"282.76800","39.64046","0.14792"
"283.02600","39.66187","0.15015"
"283.28400","39.68345","0.15228"
"283.54200","39.70486","0.15444"
"283.80000","39.72638","0.15439"
"284.05800","39.74790","0.15594"
"284.31600","39.76942","0.15700"
"284.57400","39.79089","0.15960"
"284.83200","39.81236","0.16134"
"285.09000","39.83388","0.16266"
"285.34800","39.85540","0.16471"
"285.60600","39.87693","0.16586"
"285.86400","39.89839","0.16720"
"286.12200","39.91986","0.17093"
"286.38000","39.94132","0.17093"
"286.63800","39.96291","0.17506"
"286.89600","39.98437","0.17704"
"287.15400","40.00595","0.17688"
"287.41200","40.02730","0.17785"
"287.67000","40.04888","0.18079"
"287.92800","40.07034","0.18633"
"288.18600","40.09187","0.19124"
"288.44400","40.11333","0.19529"
"288.70200","40.13486","0.19773"
"288.96000","40.15632","0.20022"
"289.21800","40.17785","0.20177"
"289.47600","40.19937","0.20314"
"289.73400","40.22096","0.20411"
"289.99200","40.24236","0.20534"
"290.25000","40.26389","0.20700"
"290.50800","40.28541","0.20889"
"290.76600","40.30693","0.21003"
"291.02400","40.32840","0.20465"
"291.28200","40.34992","0.20415"
"291.54000","40.37133","0.20421"
"291.79800","40.39285","0.20553"
"292.05600","40.41444","0.20792"
"292.31400","40.43590","0.21029"
"292.57200","40.45742","0.21190"
"292.83000","40.47882","0.21303"
"293.08800","40.50041","0.18676"
"293.34600","40.52188","0.19451"
"293.60400","40.54340","0.19486"
"293.86200","40.56475","0.19819"
"294.12000","40.58639","0.20157"
"294.37800","40.60785","0.20434"
"294.63600","40.62938","0.20514"
"294.89400","40.65091","0.20566"
"295.15200","40.67242","0.20923"
"295.41000","40.69389","0.21042"
"295.66800","40.71542","0.21311"
"295.92600","40.73682","0.21595"
"296.18400","40.75840","0.21879"
"296.44200","40.77987","0.22279"
"296.70000","40.80140","0.22437"
"296.95800","40.82286","0.22623"
"297.21600","40.84444","0.22837"
"297.47400","40.86597","0.23159"
"297.73200","40.88737","0.23418"
"297.99000","40.90883","0.23623"
"298.24800","40.93036","0.23829"
"298.50600","40.95189","0.24071"
"298.76400","40.97341","0.24203"
"299.02200","40.99488","0.24395"
"299.28000","41.01640","0.24513"
"299.53800","41.03792","0.24607"
"299.79600","41.05933","0.24737"
"300.05400","41.08091","0.24869"
"300.31200","41.10232","0.24962"
"300.57000","41.12390","0.25052"
"300.82800","41.14530","0.25197"
"301.08600","41.16695","0.25261"
"301.34400","41.18835","0.25420"
"301.60200","41.20987","0.25539"
"301.86000","41.23134","0.25594"
"302.11800","41.25293","0.25784"
"302.37600","41.27433","0.25920"
"302.63400","41.29591","0.26116"
"302.89200","41.31731","0.26386"
"303.15000","41.33890","0.26570"
"303.40800","41.36043","0.26754"
"303.66600","41.38189","0.27019"
"303.92400","41.40342","0.27184"
"304.18200","41.42482","0.27423"
"304.44000","41.44640","0.27683"
"304.69800","41.46787","0.27903"
"304.95600","41.48939","0.28062"
"305.21400","41.51086","0.28308"
"305.47200","41.53238","0.28372"
"305.73000","41.55385","0.16130"
"305.98800","41.57543","0.15070"
"306.24600","41.59683","0.14914"
"306.50400","41.61835","0.14810"
"306.76200","41.63982","0.14921"
"307.02000","41.66141","0.15086"
"307.27800","41.68281","0.15260"
"307.53600","41.70440","0.15291"
"307.79400","41.72580","0.15435"
"308.05200","41.74738","0.15649"
"308.31000","41.76879","0.15737"
"308.56800","41.79043","0.15877"
"308.82600","41.81184","0.16073"
"309.08400","41.83342","0.16377"
"309.34200","41.85482","0.16384"
"309.60000","41.87640","0.16632"
"309.85800","41.89787","0.16714"
"310.11600","41.91940","0.16848"
"310.37400","41.94093","0.16962"
"310.63200","41.96239","0.17143"
"310.89000","41.98391","0.17564"
"311.14800","42.00537","0.17767"
"311.40600","42.02690","0.17976"
"311.66400","42.04836","0.18354"
"311.92200","42.06989","0.18661"
"312.18000","42.09135","0.18916"
"312.43800","42.11294","0.19107"
"312.69600","42.13440","0.19328"
"312.95400","42.15586","0.19532"
"313.21200","42.17727","0.19598"
"313.47000","42.19891","0.19761"
"313.72800","42.22032","0.19813"
"313.98600","42.24191","0.20016"
"314.24400","42.26337","0.20080"
"314.50200","42.28489","0.20214"
"314.76000","42.30635","0.20272"
"315.01800","42.32794","0.20358"
"315.27600","42.34940","0.20361"
"315.53400","42.37093","0.20400"
"315.79200","42.39233","0.20467"
"316.05000","42.41385","0.20518"
"316.30800","42.43538","0.20622"
"316.56600","42.45691","0.20698"
"316.82400","42.47837","0.20775"
"317.08200","42.49983","0.20871"
"317.34000","42.52136","0.20995"
"317.59800","42.54288","0.21129"
"317.85600","42.56441","0.21185"
"318.11400","42.58587","0.21239"
"318.37200","42.60740","0.21328"
"318.63000","42.62880","0.21361"
"318.88800","42.65039","0.21430"
"319.14600","42.67185","0.21656"
"319.40400","42.69337","0.21753"
"319.66200","42.71478","0.21844"
"319.92000","42.73636","0.21990"
"320.17800","42.75782","0.22155"
"320.43600","42.77941","0.22271"
"320.69400","42.80087","0.22333"
"320.95200","42.82240","0.22494"
"321.21000","42.84386","0.22617"
"321.46800","42.86539","0.22716"
"321.72600","42.88685","0.22793"
"321.98400","42.90838","0.22868"
"322.24200","42.92990","0.22939"
"322.50000","42.95143","0.23059"
"322.75800","42.97289","0.23219"
"323.01600","42.99442","0.23474"
"323.27400","43.01588","0.23541"
"323.53200","43.03734","0.23754"
"323.79000","43.05886","0.23774"
"324.04800","43.08039","0.23818"
"324.30600","43.10186","0.23853"
"324.56400","43.12332","0.23881"
"324.82200","43.14484","0.23937"
"325.08000","43.16631","0.23997"
"325.33800","43.18795","0.23971"
"325.59600","43.20936","0.24075"
"325.85400","43.23088","0.24163"
"326.11200","43.25235","0.24204"
"326.37000","43.27387","0.24260"
"326.62800","43.29533","0.24353"
"326.88600","43.31692","0.24396"
"327.14400","43.33832","0.24386"
"327.40200","43.35991","0.24372"
"327.66000","43.38137","0.00229"
"327.91800","43.40290","0.01710"
"328.17600","43.42436","0.01062"
"328.43400","43.44588","0.01062"
"328.69200","43.46735","0.00955"
"328.95000","43.48888","0.00993"
"329.20800","43.51046","0.01350"
"329.46600","43.53186","0.00857"
"329.72400","43.55338","0.01117"
"329.98200","43.57485","0.01031"
"330.24000","43.59637","0.01531"
"330.49800","43.61790","0.00845"
"330.75600","43.63936","0.00934"
"331.01400","43.66083","0.00976"
"331.27200","43.68235","0.01377"
"331.53000","43.70382","0.00911"
"331.78800","43.72540","0.00848"
"332.04600","43.74681","0.01028"
"332.30400","43.76833","0.01228"
"332.56200","43.78979","0.01078"
"332.82000","43.81138","0.00893"
"333.07800","43.83290","0.01020"
"333.33600","43.85442","0.01052"
"333.59400","43.87583","0.01260"
"333.85200","43.89741","0.00929"
"334.11000","43.91888","0.01014"
"334.36800","43.94046","0.00993"
"334.62600","43.96187","0.01178"
"334.88400","43.98339","0.01009"
"335.14200","44.00492","0.00996"
"335.40000","44.02638","0.01037"
"335.65800","44.04791","0.01121"
"335.91600","44.06937","0.01141"
"336.17400","44.09090","0.01050"
"336.43200","44.11236","0.01049"
"336.69000","44.13394","0.01029"
"336.94800","44.15540","0.01253"
"337.20600","44.17687","0.01056"
"337.46400","44.19828","0.01049"
"337.72200","44.21986","0.01029"
"337.98000","44.24138","0.01254"
"338.23800","44.26291","0.01062"
"338.49600","44.28437","0.01023"
"338.75400","44.30584","0.01025"
"339.01200","44.32736","0.01200"
"339.27000","44.34889","0.01170"
"339.52800","44.37035","0.01129"
"339.78600","44.39187","0.01018"
"340.04400","44.41334","0.01208"
"340.30200","44.43493","0.01239"
"340.56000","44.45644","0.01002"
"340.81800","44.47797","0.01092"
"341.07600","44.49932","0.01113"
"341.33400","44.52090","0.01299"
"341.59200","44.54230","0.01126"
"341.85000","44.56389","0.01074"
"342.10800","44.58541","0.01229"
"342.36600","44.60688","0.01285"
"342.62400","44.62835","0.01125"
"342.88200","44.64981","0.01117"
"343.14000","44.67139","0.01143"
"343.39800","44.69285","0.01256"
"343.65600","44.71438","0.01159"
"343.91400","44.73584","0.01092"
"344.17200","44.75737","0.01191"
"344.43000","44.77883","0.01317"
"344.68800","44.80042","0.01236"
"344.94600","44.82182","0.01163"
"345.20400","44.84335","0.01209"
"345.46200","44.86481","0.01335"
"345.72000","44.88646","0.01220"
"345.97800","44.90786","0.01183"
"346.23600","44.92939","0.01227"
"346.49400","44.95085","0.01267"
"346.75200","44.97243","0.01264"
"347.01000","44.99389","0.01213"
"347.26800","45.01542","0.01241"
"347.52600","45.03688","0.01372"
"347.78400","45.05841","0.01278"
"348.04200","45.07987","0.01231"
"348.30000","45.10140","0.01284"
"348.55800","45.12292","0.01372"
"348.81600","45.14433","0.01412"
"349.07400","45.16591","0.01339"
"349.33200","45.18738","0.01308"
"349.59000","45.20890","0.01370"
"349.84800","45.23037","0.01341"
"350.10600","45.25183","0.01297"
"350.36400","45.27329","0.01418"
"350.62200","45.29488","0.01488"
"350.88000","45.31634","0.01399"
"351.13800","45.33787","0.01378"
"351.39600","45.35933","0.01462"
"351.65400","45.38085","0.01524"
"351.91200","45.40231","0.01395"
"352.17000","45.42390","0.01434"
"352.42800","45.44537","0.01562"
"352.68600","45.46689","0.01530"
"352.94400","45.48836","0.01454"
"353.20200","45.50994","0.01561"
"353.46000","45.53140","0.01608"
"353.71800","45.55293","0.01599"
"353.97600","45.57433","0.01538"
"354.23400","45.59586","0.01610"
"354.49200","45.61738","0.01654"
"354.75000","45.63891","0.01593"
"355.00800","45.66043","0.01683"
"355.26600","45.68184","0.01671"
"355.52400","45.70342","0.01695"
"355.78200","45.72488","0.01674"
"356.04000","45.74641","0.01751"
"356.29800","45.76781","0.01783"
"356.55600","45.78940","0.01785"
"356.81400","45.81086","0.01774"
"357.07200","45.83238","0.01847"
"357.33000","45.85385","0.01880"
"357.58800","45.87537","0.01847"
"357.84600","45.89677","0.01835"
"358.10400","45.91836","0.01956"
"358.36200","45.93989","0.01985"
"358.62000","45.96141","0.01919"
"358.87800","45.98281","0.02023"
"359.13600","46.00439","0.02043"
"359.39400","46.02586","0.02083"
"359.65200","46.04745","0.02084"
"359.91000","46.06891","0.02092"
"360.16800","46.09044","0.02098"
"360.42600","46.11184","0.02106"
"360.68400","46.13337","0.02143"
"360.94200","46.15495","0.02195"
"361.20000","46.17641","0.02154"
"361.45800","46.19788","0.02198"
"361.71600","46.21935","0.02319"
"361.97400","46.24087","0.02284"
"362.23200","46.26239","0.02267"
"362.49000","46.28392","0.02395"
"362.74800","46.30532","0.02418"
"363.00600","46.32690","0.02400"
"363.26400","46.34831","0.02427"
"363.52200","46.36995","0.02451"
"363.78000","46.39136","0.02441"
"364.03800","46.41288","0.02453"
"364.29600","46.43435","0.02527"
"364.55400","46.45587","0.02495"
"364.81200","46.47734","0.02578"
"365.07000","46.49892","0.02593"
"365.32800","46.52038","0.02555"
"365.58600","46.54191","0.02636"
"365.84400","46.56337","0.02556"
"366.10200","46.58490","0.02591"
"366.36000","46.60642","0.02694"
"366.61800","46.62789","0.02726"
"366.87600","46.64935","0.02728"
"367.13400","46.67087","0.02672"
"367.39200","46.69240","0.02659"
"367.65000","46.71386","0.02651"
"367.90800","46.73539","0.02762"
"368.16600","46.75685","0.02692"
"368.42400","46.77844","0.02718"
"368.68200","46.79984","0.02721"
"368.94000","46.82142","0.02646"
"369.19800","46.84277","0.02749"
"369.45600","46.86441","0.02726"
"369.71400","46.88581","0.02761"
"369.97200","46.90740","0.02807"
"370.23000","46.92880","0.02854"
"370.48800","46.95045","0.02837"
"370.74600","46.97185","0.02871"
"371.00400","46.99338","0.02871"
"371.26200","47.01484","0.02847"
"371.52000","47.03643","0.02842"
"371.77800","47.05789","0.02900"
"372.03600","47.07941","0.02875"
"372.29400","47.10088","0.02970"
"372.55200","47.12240","0.02906"
"372.81000","47.14392","0.02952"
"373.06800","47.16539","0.03002"
"373.32600","47.18686","0.02979"
"373.58400","47.20839","0.02957"
"373.84200","47.22996","0.02992"
"374.10000","47.25137","0.03053"
"374.35800","47.27289","0.03074"
"374.61600","47.29430","0.03087"
"374.87400","47.31594","0.03091"
"375.13200","47.33741","0.03065"
"375.39000","47.35887","0.03039"
"375.64800","47.38027","0.03073"
"375.90600","47.40192","0.03103"
"376.16400","47.42339","0.03149"
"376.42200","47.44497","0.03110"
"376.68000","47.46637","0.03171"
"376.93800","47.48790","0.03156"
"377.19600","47.50936","0.03111"
"377.45400","47.53089","0.03257"
"377.71200","47.55235","0.03129"
"377.97000","47.57393","0.03215"
"378.22800","47.59534","0.03255"
"378.27200","47.59904","0.03255"