File: Force_trajectories/170226_1/Specimen_RawData_2.csv
End date,"2/26/2017"
Specimen label,"1AT_2.2"
Maximum Load,"0.00830",N

Time,Extension,Load
(s),(mm),(N)
"0.00000","0.00000","-0.00010"
"0.07800","0.00215","0.00010"
"0.15600","0.00891","-0.00002"
"0.23400","0.01764","-0.00031"
"0.31200","0.02565","-0.00021"
"0.39000","0.03270","0.00010"
"0.46800","0.03928","0.00022"
"0.54600","0.04574","0.00016"
"0.62400","0.05232","0.00000"
"0.70200","0.05877","0.00023"
"0.78000","0.06523","0.00016"
"0.85800","0.07175","0.00023"
"0.93600","0.07826","-0.00012"
"1.01400","0.08466","0.00001"
"1.09200","0.09124","0.00039"
"1.17000","0.09770","0.00008"
"1.24800","0.10427","0.00034"
"1.32600","0.11073","0.00044"
"1.40400","0.11725","0.00027"
"1.48200","0.12370","0.00021"
"1.56000","0.13016","0.00065"
"1.63800","0.13668","0.00054"
"1.71600","0.14320","0.00019"
"1.79400","0.14977","0.00011"
"1.87200","0.15623","0.00017"
"1.95000","0.16275","0.00016"
"2.02800","0.16920","0.00053"
"2.10600","0.17572","0.00007"
"2.18400","0.18224","0.00053"
"2.26200","0.18870","0.00058"
"2.34000","0.19521","0.00035"
"2.41800","0.20173","0.00030"
"2.49600","0.20825","0.00017"
"2.57400","0.21470","0.00047"
"2.65200","0.22116","0.00067"
"2.73000","0.22768","0.00044"
"2.80800","0.23420","0.00106"
"2.88600","0.24071","0.00073"
"2.96400","0.24723","0.00015"
"3.04200","0.25369","0.00046"
"3.12000","0.26020","0.00067"
"3.19800","0.26666","0.00056"
"3.27600","0.27318","0.00021"
"3.35400","0.27970","0.00000"
"3.43200","0.28621","0.00017"
"3.51000","0.29267","0.00074"
"3.58800","0.29919","0.00044"
"3.66600","0.30564","0.00017"
"3.74400","0.31216","0.00104"
"3.82200","0.31868","0.00068"
"3.90000","0.32520","0.00075"
"3.97800","0.33171","0.00098"
"4.05600","0.33823","0.00039"
"4.13400","0.34469","0.00049"
"4.21200","0.35120","0.00043"
"4.29000","0.35766","0.00069"
"4.36800","0.36424","0.00015"
"4.44600","0.37070","0.00072"
"4.52400","0.37727","0.00024"
"4.60200","0.38373","0.00009"
"4.68000","0.39019","0.00060"
"4.75800","0.39658","0.00022"
"4.83600","0.40322","0.00054"
"4.91400","0.40968","0.00038"
"4.99200","0.41625","0.00015"
"5.07000","0.42271","0.00044"
"5.14800","0.42929","0.00053"
"5.22600","0.43575","0.00038"
"5.30400","0.44214","0.00063"
"5.38200","0.44872","0.00090"
"5.46000","0.45524","0.00050"
"5.53800","0.46175","0.00075"
"5.61600","0.46821","0.00038"
"5.69400","0.47467","0.00092"
"5.77200","0.48119","0.00045"
"5.85000","0.48764","0.00056"
"5.92800","0.49416","0.00061"
"6.00600","0.50068","0.00033"
"6.08400","0.50725","0.00096"
"6.16200","0.51371","0.00040"
"6.24000","0.52023","0.00060"
"6.31800","0.52669","0.00033"
"6.39600","0.53320","0.00087"
"6.47400","0.53966","0.00025"
"6.55200","0.54624","0.00093"
"6.63000","0.55275","0.00072"
"6.70800","0.55927","0.00097"
"6.78600","0.56573","0.00046"
"6.86400","0.57219","0.00082"
"6.94200","0.57864","0.00079"
"7.02000","0.58522","0.00039"
"7.09800","0.59174","0.00088"
"7.17600","0.59825","0.00016"
"7.25400","0.60471","0.00038"
"7.33200","0.61123","0.00093"
"7.41000","0.61769","0.00075"
"7.48800","0.62420","0.00019"
"7.56600","0.63072","0.00096"
"7.64400","0.63718","0.00119"
"7.72200","0.64369","0.00050"
"7.80000","0.65021","0.00099"
"7.87800","0.65673","0.00068"
"7.95600","0.66319","0.00020"
"8.03400","0.66964","0.00063"
"8.11200","0.67622","0.00092"
"8.19000","0.68268","0.00047"
"8.26800","0.68925","0.00134"
"8.34600","0.69571","0.00104"
"8.42400","0.70223","0.00023"
"8.50200","0.70869","-0.00002"
"8.58000","0.71514","-0.00050"
"8.65800","0.72172","0.00001"
"8.73600","0.72818","0.00024"
"8.81400","0.73475","0.00012"
"8.89200","0.74121","0.00070"
"8.97000","0.74779","0.00012"
"9.04800","0.75419","0.00024"
"9.12600","0.76070","0.00033"
"9.20400","0.76716","0.00003"
"9.28200","0.77374","-0.00007"
"9.36000","0.78019","0.00048"
"9.43800","0.78677","0.00035"
"9.51600","0.79323","-0.00022"
"9.59400","0.79969","0.00033"
"9.67200","0.80620","-0.00036"
"9.75000","0.81272","0.00022"
"9.82800","0.81924","0.00015"
"9.90600","0.82569","-0.00012"
"9.98400","0.83227","0.00018"
"10.06200","0.83873","0.00010"
"10.14000","0.84518","0.00016"
"10.21800","0.85158","0.00044"
"10.29600","0.85828","-0.00022"
"10.37400","0.86480","0.00040"
"10.45200","0.87119","-0.00023"
"10.53000","0.87771","0.00004"
"10.60800","0.88423","0.00025"
"10.68600","0.89068","-0.00054"
"10.76400","0.89714","0.00064"
"10.84200","0.90366","0.00061"
"10.92000","0.91024","0.00017"
"10.99800","0.91669","0.00084"
"11.07600","0.92321","0.00044"
"11.15400","0.92967","0.00029"
"11.23200","0.93618","0.00020"
"11.31000","0.94264","0.00024"
"11.38800","0.94922","0.00047"
"11.46600","0.95574","0.00076"
"11.54400","0.96219","0.00003"
"11.62200","0.96871","-0.00010"
"11.70000","0.97523","0.00077"
"11.77800","0.98168","-0.00022"
"11.85600","0.98820","0.00034"
"11.93400","0.99472","-0.00040"
"12.01200","1.00124","0.00003"
"12.09000","1.00769","0.00020"
"12.16800","1.01421","0.00047"
"12.24600","1.02073","0.00017"
"12.32400","1.02718","0.00014"
"12.40200","1.03370","0.00037"
"12.48000","1.04022","0.00079"
"12.55800","1.04680","0.00014"
"12.63600","1.05319","0.00046"
"12.71400","1.05971","0.00051"
"12.79200","1.06617","0.00015"
"12.87000","1.07268","0.00009"
"12.94800","1.07920","0.00053"
"13.02600","1.08572","0.00056"
"13.10400","1.09224","0.00027"
"13.18200","1.09869","-0.00016"
"13.26000","1.10527","0.00008"
"13.33800","1.11167","0.00043"
"13.41600","1.11818","0.00051"
"13.49400","1.12470","0.00033"
"13.57200","1.13128","0.00023"
"13.65000","1.13768","0.00114"
"13.72800","1.14419","0.00043"
"13.80600","1.15071","0.00007"
"13.88400","1.15717","0.00033"
"13.96200","1.16368","0.00017"
"14.04000","1.17020","0.00013"
"14.11800","1.17678","0.00030"
"14.19600","1.18318","0.00061"
"14.27400","1.18975","0.00005"
"14.35200","1.19615","0.00066"
"14.43000","1.20273","0.00042"
"14.50800","1.20912","0.00016"
"14.58600","1.21570","0.00035"
"14.66400","1.22222","0.00012"
"14.74200","1.22873","0.00031"
"14.82000","1.23525","0.00047"
"14.89800","1.24171","0.00049"
"14.97600","1.24823","0.00039"
"15.05400","1.25468","0.00010"
"15.13200","1.26120","0.00071"
"15.21000","1.26778","0.00073"
"15.28800","1.27423","0.00008"
"15.36600","1.28075","0.00050"
"15.44400","1.28721","0.00032"
"15.52200","1.29367","0.00061"
"15.60000","1.30012","0.00075"
"15.67800","1.30670","0.00026"
"15.75600","1.31328","0.00038"
"15.83400","1.31973","0.00017"
"15.91200","1.32619","0.00037"
"15.99000","1.33277","0.00038"
"16.06800","1.33917","0.00062"
"16.14600","1.34568","0.00054"
"16.22400","1.35220","0.00075"
"16.30200","1.35872","0.00055"
"16.38000","1.36523","0.00054"
"16.45800","1.37169","0.00025"
"16.53600","1.37821","0.00006"
"16.61400","1.38467","0.00054"
"16.69200","1.39118","0.00016"
"16.77000","1.39764","-0.00012"
"16.84800","1.40422","0.00085"
"16.92600","1.41073","0.00066"
"17.00400","1.41725","0.00085"
"17.08200","1.42365","0.00017"
"17.16000","1.43017","0.00076"
"17.23800","1.43668","0.00029"
"17.31600","1.44326","0.00056"
"17.39400","1.44972","0.00032"
"17.47200","1.45623","0.00070"
"17.55000","1.46275","0.00064"
"17.62800","1.46921","0.00048"
"17.70600","1.47573","0.00015"
"17.78400","1.48224","0.00042"
"17.86200","1.48876","0.00065"
"17.94000","1.49522","0.00045"
"18.01800","1.50179","0.00059"
"18.09600","1.50819","0.00043"
"18.17400","1.51471","0.00065"
"18.25200","1.52117","0.00009"
"18.33000","1.52768","0.00064"
"18.40800","1.53420","0.00059"
"18.48600","1.54066","0.00022"
"18.56400","1.54723","0.00070"
"18.64200","1.55369","0.00053"
"18.72000","1.56015","0.00068"
"18.79800","1.56667","0.00051"
"18.87600","1.57318","0.00030"
"18.95400","1.57976","0.00031"
"19.03200","1.58622","0.00024"
"19.11000","1.59273","0.00016"
"19.18800","1.59919","0.00081"
"19.26600","1.60571","0.00011"
"19.34400","1.61216","0.00094"
"19.42200","1.61868","0.00085"
"19.50000","1.62520","0.00073"
"19.57800","1.63178","0.00053"
"19.65600","1.63823","0.00085"
"19.73400","1.64475","0.00032"
"19.81200","1.65121","0.00067"
"19.89000","1.65772","0.00005"
"19.96800","1.66418","0.00075"
"20.04600","1.67076","0.00063"
"20.12400","1.67722","0.00069"
"20.20200","1.68373","0.00039"
"20.28000","1.69019","0.00039"
"20.35800","1.69671","0.00047"
"20.43600","1.70316","0.00081"
"20.51400","1.70968","0.00051"
"20.59200","1.71626","0.00024"
"20.67000","1.72272","0.00051"
"20.74800","1.72923","0.00003"
"20.82600","1.73569","0.00093"
"20.90400","1.74221","0.00075"
"20.98200","1.74860","0.00067"
"21.06000","1.75524","0.00019"
"21.13800","1.76176","0.00061"
"21.21600","1.76822","0.00102"
"21.29400","1.77473","0.00041"
"21.37200","1.78119","0.00038"
"21.45000","1.78771","0.00043"
"21.52800","1.79416","0.00068"
"21.60600","1.80074","0.00085"
"21.68400","1.80720","0.00044"
"21.76200","1.81372","0.00011"
"21.84000","1.82023","0.00064"
"21.91800","1.82669","0.00060"
"21.99600","1.83315","0.00036"
"22.07400","1.83966","0.00055"
"22.15200","1.84624","0.00069"
"22.23000","1.85276","0.00048"
"22.30800","1.85928","0.00067"
"22.38600","1.86573","0.00051"
"22.46400","1.87219","0.00014"
"22.54200","1.87871","0.00074"
"22.62000","1.88516","0.00064"
"22.69800","1.89174","0.00072"
"22.77600","1.89826","0.00027"
"22.85400","1.90472","0.00030"
"22.93200","1.91123","0.00077"
"23.01000","1.91769","0.00073"
"23.08800","1.92421","0.00108"
"23.16600","1.93072","0.00052"
"23.24400","1.93724","0.00069"
"23.32200","1.94376","0.00057"
"23.40000","1.95022","0.00082"
"23.47800","1.95673","0.00042"
"23.55600","1.96319","0.00069"
"23.63400","1.96965","0.00032"
"23.71200","1.97616","0.00030"
"23.79000","1.98274","0.00066"
"23.86800","1.98926","0.00007"
"23.94600","1.99571","0.00046"
"24.02400","2.00223","0.00075"
"24.10200","2.00869","0.00084"
"24.18000","2.01515","0.00123"
"24.25800","2.02166","0.00020"
"24.33600","2.02824","0.00052"
"24.41400","2.03470","0.00041"
"24.49200","2.04121","-0.00006"
"24.57000","2.04767","0.00018"
"24.64800","2.05419","0.00091"
"24.72600","2.06065","0.00031"
"24.80400","2.06716","0.00016"
"24.88200","2.07374","0.00099"
"24.96000","2.08020","0.00022"
"25.03800","2.08677","0.00059"
"25.11600","2.09317","0.00060"
"25.19400","2.09969","0.00059"
"25.27200","2.10615","0.00056"
"25.35000","2.11272","0.00023"
"25.42800","2.11924","0.00048"
"25.50600","2.12570","0.00022"
"25.58400","2.13227","0.00061"
"25.66200","2.13867","0.00077"
"25.74000","2.14519","0.00040"
"25.81800","2.15165","0.00079"
"25.89600","2.15822","0.00079"
"25.97400","2.16468","0.00027"
"26.05200","2.17126","0.00064"
"26.13000","2.17771","0.00104"
"26.20800","2.18423","0.00067"
"26.28600","2.19069","0.00041"
"26.36400","2.19715","0.00082"
"26.44200","2.20366","0.00055"
"26.52000","2.21024","0.00036"
"26.59800","2.21670","0.00039"
"26.67600","2.22321","0.00058"
"26.75400","2.22973","0.00057"
"26.83200","2.23619","0.00014"
"26.91000","2.24265","0.00057"
"26.98800","2.24922","0.00052"
"27.06600","2.25574","0.00032"
"27.14400","2.26220","0.00055"
"27.22200","2.26877","0.00036"
"27.30000","2.27523","0.00086"
"27.37800","2.28169","0.00025"
"27.45600","2.28821","0.00094"
"27.53400","2.29472","0.00064"
"27.61200","2.30130","0.00076"
"27.69000","2.30776","0.00019"
"27.76800","2.31427","0.00013"
"27.84600","2.32073","0.00004"
"27.92400","2.32719","0.00094"
"28.00200","2.33371","0.00066"
"28.08000","2.34022","0.00038"
"28.15800","2.34674","0.00046"
"28.23600","2.35326","0.00069"
"28.31400","2.35971","0.00072"
"28.39200","2.36623","0.00073"
"28.47000","2.37269","0.00012"
"28.54800","2.37920","0.00073"
"28.62600","2.38572","0.00072"
"28.70400","2.39218","-0.00008"
"28.78200","2.39876","0.00088"
"28.86000","2.40521","0.00046"
"28.93800","2.41173","0.00104"
"29.01600","2.41813","0.00066"
"29.09400","2.42470","0.00034"
"29.17200","2.43122","0.00114"
"29.25000","2.43768","0.00068"
"29.32800","2.44420","0.00067"
"29.40600","2.45065","0.00010"
"29.48400","2.45717","0.00069"
"29.56200","2.46363","0.00080"
"29.64000","2.47020","0.00060"
"29.71800","2.47672","0.00044"
"29.79600","2.48324","0.00094"
"29.87400","2.48970","0.00021"
"29.95200","2.49621","0.00058"
"30.03000","2.50267","0.00121"
"30.10800","2.50919","0.00091"
"30.18600","2.51570","0.00040"
"30.26400","2.52222","0.00020"
"30.34200","2.52874","0.00044"
"30.42000","2.53526","0.00063"
"30.49800","2.54171","0.00028"
"30.57600","2.54817","0.00078"
"30.65400","2.55469","0.00069"
"30.73200","2.56120","0.00063"
"30.81000","2.56778","0.00089"
"30.88800","2.57424","0.00095"
"30.96600","2.58076","0.00051"
"31.04400","2.58721","0.00060"
"31.12200","2.59361","0.00070"
"31.20000","2.60019","0.00047"
"31.27800","2.60670","0.00032"
"31.35600","2.61328","0.00050"
"31.43400","2.61968","0.00090"
"31.51200","2.62620","0.00106"
"31.59000","2.63271","0.00068"
"31.66800","2.63917","0.00015"
"31.74600","2.64563","0.00089"
"31.82400","2.65220","0.00040"
"31.90200","2.65872","0.00089"
"31.98000","2.66524","-0.00007"
"32.05800","2.67176","0.00035"
"32.13600","2.67821","0.00049"
"32.21400","2.68467","0.00056"
"32.29200","2.69119","0.00129"
"32.37000","2.69770","0.00048"
"32.44800","2.70422","0.00046"
"32.52600","2.71074","0.00036"
"32.60400","2.71725","0.00032"
"32.68200","2.72371","0.00046"
"32.76000","2.73017","0.00089"
"32.83800","2.73663","0.00060"
"32.91600","2.74326","0.00074"
"32.99400","2.74978","-0.00003"
"33.07200","2.75630","0.00062"
"33.15000","2.76270","0.00050"
"33.22800","2.76927","0.00039"
"33.30600","2.77567","0.00010"
"33.38400","2.78219","0.00017"
"33.46200","2.78864","0.00034"
"33.54000","2.79528","0.00017"
"33.61800","2.80174","0.00095"
"33.69600","2.80819","0.00017"
"33.77400","2.81471","0.00063"
"33.85200","2.82117","-0.00007"
"33.93000","2.82769","0.00035"
"34.00800","2.83420","0.00036"
"34.08600","2.84072","0.00067"
"34.16400","2.84724","0.00054"
"34.24200","2.85375","0.00082"
"34.32000","2.86021","0.00022"
"34.39800","2.86667","0.00025"
"34.47600","2.87319","0.00073"
"34.55400","2.87970","0.00063"
"34.63200","2.88628","0.00058"
"34.71000","2.89274","0.00082"
"34.78800","2.89925","0.00057"
"34.86600","2.90571","0.00077"
"34.94400","2.91223","0.00061"
"35.02200","2.91869","0.00083"
"35.10000","2.92526","0.00087"
"35.17800","2.93172","0.00034"
"35.25600","2.93830","0.00044"
"35.33400","2.94469","0.00038"
"35.41200","2.95121","0.00041"
"35.49000","2.95767","0.00010"
"35.56800","2.96419","0.00074"
"35.64600","2.97070","0.00039"
"35.72400","2.97722","-0.00005"
"35.80200","2.98374","0.00082"
"35.88000","2.99025","0.00043"
"35.95800","2.99665","0.00016"
"36.03600","3.00311","0.00029"
"36.11400","3.00969","0.00040"
"36.19200","3.01620","0.00024"
"36.27000","3.02272","0.00013"
"36.34800","3.02924","0.00010"
"36.42600","3.03569","0.00052"
"36.50400","3.04221","0.00035"
"36.58200","3.04867","0.00094"
"36.66000","3.05519","0.00018"
"36.73800","3.06170","0.00081"
"36.81600","3.06822","0.00036"
"36.89400","3.07468","0.00081"
"36.97200","3.08119","0.00037"
"37.05000","3.08765","0.00042"
"37.12800","3.09417","0.00065"
"37.20600","3.10069","0.00053"
"37.28400","3.10726","0.00064"
"37.36200","3.11378","0.00084"
"37.44000","3.12024","0.00051"
"37.51800","3.12675","0.00113"
"37.59600","3.13321","0.00027"
"37.67400","3.13973","0.00014"
"37.75200","3.14625","0.00057"
"37.83000","3.15276","0.00027"
"37.90800","3.15922","0.00065"
"37.98600","3.16574","0.00118"
"38.06400","3.17219","0.00079"
"38.14200","3.17871","0.00053"
"38.22000","3.18523","0.00046"
"38.29800","3.19174","0.00040"
"38.37600","3.19826","0.00036"
"38.45400","3.20472","0.00033"
"38.53200","3.21124","0.00126"
"38.61000","3.21769","0.00130"
"38.68800","3.22421","0.00075"
"38.76600","3.23067","0.00051"
"38.84400","3.23724","0.00076"
"38.92200","3.24370","0.00102"
"39.00000","3.25022","0.00103"
"39.07800","3.25674","0.00036"
"39.15600","3.26319","0.00076"
"39.23400","3.26965","0.00038"
"39.31200","3.27623","0.00069"
"39.39000","3.28274","0.00050"
"39.46800","3.28926","0.00002"
"39.54600","3.29572","0.00006"
"39.62400","3.30224","0.00025"
"39.70200","3.30869","0.00129"
"39.78000","3.31515","0.00034"
"39.85800","3.32173","-0.00003"
"39.93600","3.32824","0.00082"
"40.01400","3.33476","0.00017"
"40.09200","3.34122","0.00047"
"40.17000","3.34774","0.00045"
"40.24800","3.35419","0.00031"
"40.32600","3.36065","0.00095"
"40.40400","3.36723","0.00095"
"40.48200","3.37374","0.00074"
"40.56000","3.38026","0.00026"
"40.63800","3.38672","0.00060"
"40.71600","3.39324","0.00088"
"40.79400","3.39969","0.00110"
"40.87200","3.40615","0.00092"
"40.95000","3.41273","-0.00001"
"41.02800","3.41924","0.00060"
"41.10600","3.42576","-0.00013"
"41.18400","3.43222","0.00057"
"41.26200","3.43874","0.00083"
"41.34000","3.44513","0.00062"
"41.41800","3.45165","0.00070"
"41.49600","3.45817","0.00067"
"41.57400","3.46474","0.00030"
"41.65200","3.47126","0.00044"
"41.73000","3.47772","0.00032"
"41.80800","3.48418","0.00049"
"41.88600","3.49063","0.00070"
"41.96400","3.49721","0.00065"
"42.04200","3.50367","0.00039"
"42.12000","3.51024","0.00070"
"42.19800","3.51670","0.00035"
"42.27600","3.52322","0.00007"
"42.35400","3.52968","-0.00003"
"42.43200","3.53613","0.00047"
"42.51000","3.54265","0.00059"
"42.58800","3.54923","0.00034"
"42.66600","3.55574","0.00069"
"42.74400","3.56220","0.00051"
"42.82200","3.56878","0.00018"
"42.90000","3.57518","0.00024"
"42.97800","3.58169","0.00078"
"43.05600","3.58815","0.00094"
"43.13400","3.59473","0.00037"
"43.21200","3.60124","0.00029"
"43.29000","3.60776","0.00036"
"43.36800","3.61422","0.00104"
"43.44600","3.62073","0.00027"
"43.52400","3.62719","0.00072"
"43.60200","3.63371","0.00027"
"43.68000","3.64023","0.00045"
"43.75800","3.64674","0.00087"
"43.83600","3.65320","0.00037"
"43.91400","3.65972","-0.00032"
"43.99200","3.66623","0.00085"
"44.07000","3.67269","0.00029"
"44.14800","3.67921","0.00085"
"44.22600","3.68567","0.00049"
"44.30400","3.69218","0.00032"
"44.38200","3.69870","0.00014"
"44.46000","3.70522","0.00045"
"44.53800","3.71173","-0.00006"
"44.61600","3.71813","0.00033"
"44.69400","3.72471","0.00024"
"44.77200","3.73123","0.00052"
"44.85000","3.73774","0.00044"
"44.92800","3.74420","0.00066"
"45.00600","3.75072","0.00072"
"45.08400","3.75717","0.00047"
"45.16200","3.76363","0.00047"
"45.24000","3.77021","0.00034"
"45.31800","3.77673","0.00063"
"45.39600","3.78330","0.00081"
"45.47400","3.78970","0.00015"
"45.55200","3.79628","0.00073"
"45.63000","3.80273","0.00013"
"45.70800","3.80919","0.00037"
"45.78600","3.81571","0.00058"
"45.86400","3.82223","0.00053"
"45.94200","3.82874","0.00076"
"46.02000","3.83526","0.00037"
"46.09800","3.84172","0.00043"
"46.17600","3.84823","0.00057"
"46.25400","3.85469","0.00036"
"46.33200","3.86115","0.00015"
"46.41000","3.86778","0.00060"
"46.48800","3.87424","0.00072"
"46.56600","3.88070","0.00043"
"46.64400","3.88716","0.00090"
"46.72200","3.89373","0.00044"
"46.80000","3.90013","0.00012"
"46.87800","3.90671","0.00033"
"46.95600","3.91322","0.00038"
"47.03400","3.91974","0.00095"
"47.11200","3.92620","-0.00014"
"47.19000","3.93272","0.00039"
"47.26800","3.93917","0.00031"
"47.34600","3.94569","0.00039"
"47.42400","3.95215","0.00034"
"47.50200","3.95872","0.00040"
"47.58000","3.96518","0.00008"
"47.65800","3.97170","-0.00001"
"47.73600","3.97816","0.00073"
"47.81400","3.98467","0.00064"
"47.89200","3.99119","0.00063"
"47.97000","3.99771","0.00027"
"48.04800","4.00422","0.00021"
"48.12600","4.01074","0.00058"
"48.20400","4.01726","0.00024"
"48.28200","4.02372","0.00025"
"48.36000","4.03017","0.00036"
"48.43800","4.03669","0.00038"
"48.51600","4.04321","0.00071"
"48.59400","4.04978","0.00060"
"48.67200","4.05618","0.00018"
"48.75000","4.06270","0.00020"
"48.82800","4.06916","0.00048"
"48.90600","4.07567","0.00072"
"48.98400","4.08219","0.00075"
"49.06200","4.08871","0.00053"
"49.14000","4.09528","0.00046"
"49.21800","4.10168","0.00071"
"49.29600","4.10826","0.00017"
"49.37400","4.11466","0.00067"
"49.45200","4.12117","0.00023"
"49.53000","4.12763","0.00045"
"49.60800","4.13421","0.00043"
"49.68600","4.14072","0.00043"
"49.76400","4.14724","0.00053"
"49.84200","4.15370","0.00079"
"49.92000","4.16016","0.00053"
"49.99800","4.16667","0.00024"
"50.07600","4.17313","0.00080"
"50.15400","4.17977","0.00044"
"50.23200","4.18622","0.00037"
"50.31000","4.19274","0.00050"
"50.38800","4.19920","0.00044"
"50.46600","4.20572","0.00040"
"50.54400","4.21223","0.00001"
"50.62200","4.21875","0.00054"
"50.70000","4.22521","0.00025"
"50.77800","4.23172","0.00023"
"50.85600","4.23824","0.00019"
"50.93400","4.24470","0.00008"
"51.01200","4.25121","0.00060"
"51.09000","4.25767","-0.00001"
"51.16800","4.26419","0.00002"
"51.24600","4.27071","0.00002"
"51.32400","4.27722","0.00012"
"51.40200","4.28374","0.00047"
"51.48000","4.29020","0.00011"
"51.55800","4.29666","0.00059"
"51.63600","4.30317","0.00013"
"51.71400","4.30969","0.00086"
"51.79200","4.31621","-0.00002"
"51.87000","4.32272","0.00038"
"51.94800","4.32924","0.00008"
"52.02600","4.33576","0.00067"
"52.10400","4.34215","0.00081"
"52.18200","4.34867","-0.00018"
"52.26000","4.35519","0.00087"
"52.33800","4.36171","0.00053"
"52.41600","4.36822","-0.00002"
"52.49400","4.37474","0.00066"
"52.57200","4.38126","0.00015"
"52.65000","4.38771","0.00031"
"52.72800","4.39423","-0.00034"
"52.80600","4.40075","0.00033"
"52.88400","4.40721","-0.00021"
"52.96200","4.41372","0.00001"
"53.04000","4.42024","0.00026"
"53.11800","4.42670","0.00040"
"53.19600","4.43321","0.00020"
"53.27400","4.43967","-0.00027"
"53.35200","4.44625","0.00015"
"53.43000","4.45277","0.00040"
"53.50800","4.45922","0.00045"
"53.58600","4.46574","0.00080"
"53.66400","4.47220","0.00050"
"53.74200","4.47871","0.00049"
"53.82000","4.48517","0.00046"
"53.89800","4.49169","-0.00005"
"53.97600","4.49821","0.00013"
"54.05400","4.50472","0.00027"
"54.13200","4.51118","0.00008"
"54.21000","4.51770","-0.00001"
"54.28800","4.52415","0.00060"
"54.36600","4.53061","0.00066"
"54.44400","4.53719","0.00014"
"54.52200","4.54371","0.00034"
"54.60000","4.55022","0.00012"
"54.67800","4.55668","0.00060"
"54.75600","4.56320","0.00022"
"54.83400","4.56965","0.00078"
"54.91200","4.57617","0.00026"
"54.99000","4.58269","0.00009"
"55.06800","4.58921","-0.00014"
"55.14600","4.59572","0.00041"
"55.22400","4.60218","0.00038"
"55.30200","4.60870","0.00029"
"55.38000","4.61515","0.00052"
"55.45800","4.62173","0.00067"
"55.53600","4.62819","0.00020"
"55.61400","4.63477","0.00056"
"55.69200","4.64122","0.00062"
"55.77000","4.64768","0.00031"
"55.84800","4.65414","0.00094"
"55.92600","4.66065","0.00040"
"56.00400","4.66723","-0.00032"
"56.08200","4.67375","0.00026"
"56.16000","4.68026","0.00001"
"56.23800","4.68672","0.00088"
"56.31600","4.69324","0.00017"
"56.39400","4.69970","0.00019"
"56.47200","4.70621","0.00031"
"56.55000","4.71267","0.00064"
"56.62800","4.71925","0.00056"
"56.70600","4.72570","0.00068"
"56.78400","4.73222","0.00071"
"56.86200","4.73868","0.00079"
"56.94000","4.74520","0.00000"
"57.01800","4.75165","0.00049"
"57.09600","4.75817","0.00100"
"57.17400","4.76481","0.00035"
"57.25200","4.77120","0.00042"
"57.33000","4.77772","0.00120"
"57.40800","4.78418","0.00083"
"57.48600","4.79070","0.00036"
"57.56400","4.79709","0.00045"
"57.64200","4.80367","0.00055"
"57.72000","4.81019","0.00013"
"57.79800","4.81670","0.00059"
"57.87600","4.82322","0.00058"
"57.95400","4.82968","0.00016"
"58.03200","4.83620","0.00060"
"58.11000","4.84265","0.00062"
"58.18800","4.84923","0.00079"
"58.26600","4.85569","0.00037"
"58.34400","4.86226","0.00008"
"58.42200","4.86872","0.00025"
"58.50000","4.87524","0.00060"
"58.57800","4.88170","0.00046"
"58.65600","4.88815","0.00071"
"58.73400","4.89473","0.00027"
"58.81200","4.90131","0.00071"
"58.89000","4.90776","0.00104"
"58.96800","4.91422","0.00018"
"59.04600","4.92074","0.00050"
"59.12400","4.92720","0.00004"
"59.20200","4.93371","0.00057"
"59.28000","4.94017","0.00019"
"59.35800","4.94675","0.00005"
"59.43600","4.95320","-0.00016"
"59.51400","4.95972","0.00062"
"59.59200","4.96618","0.00067"
"59.67000","4.97264","0.00018"
"59.74800","4.97921","0.00081"
"59.82600","4.98567","0.00065"
"59.90400","4.99225","0.00096"
"59.98200","4.99876","0.00063"
"60.06000","5.00528","0.00074"
"60.13800","5.01168","0.00041"
"60.21600","5.01814","0.00033"
"60.29400","5.02471","0.00026"
"60.37200","5.03123","0.00079"
"60.45000","5.03775","-0.00024"
"60.52800","5.04426","0.00054"
"60.60600","5.05072","0.00066"
"60.68400","5.05724","0.00032"
"60.76200","5.06369","0.00057"
"60.84000","5.07021","0.00034"
"60.91800","5.07673","0.00032"
"60.99600","5.08325","0.00031"
"61.07400","5.08976","0.00035"
"61.15200","5.09622","0.00071"
"61.23000","5.10268","0.00102"
"61.30800","5.10919","0.00033"
"61.38600","5.11571","-0.00003"
"61.46400","5.12223","0.00040"
"61.54200","5.12869","0.00004"
"61.62000","5.13526","0.00022"
"61.69800","5.14172","0.00029"
"61.77600","5.14818","-0.00028"
"61.85400","5.15464","-0.00015"
"61.93200","5.16121","0.00031"
"62.01000","5.16773","0.00001"
"62.08800","5.17425","0.00017"
"62.16600","5.18070","0.00038"
"62.24400","5.18722","0.00083"
"62.32200","5.19368","-0.00008"
"62.40000","5.20014","0.00080"
"62.47800","5.20671","-0.00015"
"62.55600","5.21323","0.00028"
"62.63400","5.21975","0.00016"
"62.71200","5.22620","0.00018"
"62.79000","5.23272","0.00004"
"62.86800","5.23918","-0.00012"
"62.94600","5.24564","0.00051"
"63.02400","5.25221","0.00055"
"63.10200","5.25873","0.00001"
"63.18000","5.26525","0.00038"
"63.25800","5.27176","0.00044"
"63.33600","5.27828","0.00034"
"63.41400","5.28468","0.00004"
"63.49200","5.29125","0.00047"
"63.57000","5.29771","0.00041"
"63.64800","5.30429","0.00059"
"63.72600","5.31069","0.00002"
"63.80400","5.31720","0.00032"
"63.88200","5.32366","0.00014"
"63.96000","5.33018","0.00039"
"64.03800","5.33663","0.00052"
"64.11600","5.34321","0.00044"
"64.19400","5.34973","0.00042"
"64.27200","5.35619","0.00044"
"64.35000","5.36270","0.00013"
"64.42800","5.36916","-0.00013"
"64.50600","5.37568","0.00045"
"64.58400","5.38213","0.00035"
"64.66200","5.38865","0.00004"
"64.74000","5.39517","0.00068"
"64.81800","5.40169","-0.00006"
"64.89600","5.40820","0.00053"
"64.97400","5.41466","0.00015"
"65.05200","5.42112","0.00009"
"65.13000","5.42763","-0.00017"
"65.20800","5.43427","0.00031"
"65.28600","5.44073","0.00034"
"65.36400","5.44730","0.00038"
"65.44200","5.45370","0.00029"
"65.52000","5.46022","-0.00004"
"65.59800","5.46668","-0.00005"
"65.67600","5.47319","0.00031"
"65.75400","5.47971","0.00023"
"65.83200","5.48623","0.00008"
"65.91000","5.49274","0.00013"
"65.98800","5.49920","-0.00030"
"66.06600","5.50572","0.00018"
"66.14400","5.51212","0.00002"
"66.22200","5.51875","0.00001"
"66.30000","5.52521","-0.00001"
"66.37800","5.53173","-0.00017"
"66.45600","5.53824","-0.00020"
"66.53400","5.54476","-0.00024"
"66.61200","5.55122","0.00042"
"66.69000","5.55768","-0.00038"
"66.76800","5.56419","0.00051"
"66.84600","5.57071","0.00021"
"66.92400","5.57723","0.00026"
"67.00200","5.58368","0.00020"
"67.08000","5.59026","0.00000"
"67.15800","5.59666","0.00019"
"67.23600","5.60312","0.00008"
"67.31400","5.60963","0.00075"
"67.39200","5.61627","0.00001"
"67.47000","5.62273","-0.00014"
"67.54800","5.62924","0.00042"
"67.62600","5.63570","0.00032"
"67.70400","5.64222","0.00036"
"67.78200","5.64868","0.00014"
"67.86000","5.65519","-0.00010"
"67.93800","5.66171","-0.00036"
"68.01600","5.66823","0.00086"
"68.09400","5.67474","-0.00014"
"68.17200","5.68120","0.00008"
"68.25000","5.68766","0.00040"
"68.32800","5.69418","0.00007"
"68.40600","5.70069","0.00013"
"68.48400","5.70721","0.00023"
"68.56200","5.71373","0.00021"
"68.64000","5.72024","0.00071"
"68.71800","5.72670","-0.00014"
"68.79600","5.73322","0.00045"
"68.87400","5.73962","0.00029"
"68.95200","5.74625","0.00045"
"69.03000","5.75271","0.00036"
"69.10800","5.75923","0.00056"
"69.18600","5.76568","0.00032"
"69.26400","5.77226","0.00042"
"69.34200","5.77872","0.00057"
"69.42000","5.78518","0.00058"
"69.49800","5.79169","0.00056"
"69.57600","5.79821","0.00040"
"69.65400","5.80479","0.00015"
"69.73200","5.81124","0.00030"
"69.81000","5.81770","0.00032"
"69.88800","5.82410","0.00011"
"69.96600","5.83074","0.00018"
"70.04400","5.83719","0.00057"
"70.12200","5.84371","0.00064"
"70.20000","5.85017","0.00009"
"70.27800","5.85668","0.00012"
"70.35600","5.86320","0.00009"
"70.43400","5.86966","0.00031"
"70.51200","5.87617","0.00002"
"70.59000","5.88275","0.00034"
"70.66800","5.88927","0.00037"
"70.74600","5.89573","-0.00008"
"70.82400","5.90224","0.00024"
"70.90200","5.90870","0.00011"
"70.98000","5.91522","0.00035"
"71.05800","5.92167","0.00036"
"71.13600","5.92819","0.00001"
"71.21400","5.93477","0.00003"
"71.29200","5.94123","0.00027"
"71.37000","5.94774","-0.00005"
"71.44800","5.95420","0.00012"
"71.52600","5.96066","0.00028"
"71.60400","5.96717","0.00040"
"71.68200","5.97369","0.00014"
"71.76000","5.98021","0.00052"
"71.83800","5.98679","0.00067"
"71.91600","5.99318","0.00001"
"71.99400","5.99970","0.00019"
"72.07200","6.00616","0.00025"
"72.15000","6.01273","0.00017"
"72.22800","6.01919","0.00025"
"72.30600","6.02577","0.00042"
"72.38400","6.03223","0.00022"
"72.46200","6.03868","0.00056"
"72.54000","6.04520","0.00010"
"72.61800","6.05160","0.00010"
"72.69600","6.05823","0.00012"
"72.77400","6.06469","0.00021"
"72.85200","6.07121","0.00019"
"72.93000","6.07767","0.00040"
"73.00800","6.08418","0.00017"
"73.08600","6.09070","0.00056"
"73.16400","6.09716","0.00073"
"73.24200","6.10373","0.00047"
"73.32000","6.11019","0.00053"
"73.39800","6.11677","0.00051"
"73.47600","6.12323","0.00039"
"73.55400","6.12974","-0.00019"
"73.63200","6.13614","0.00076"
"73.71000","6.14266","0.00026"
"73.78800","6.14917","0.00060"
"73.86600","6.15575","0.00057"
"73.94400","6.16221","0.00016"
"74.02200","6.16873","0.00015"
"74.10000","6.17524","0.00077"
"74.17800","6.18164","0.00054"
"74.25600","6.18822","0.00008"
"74.33400","6.19473","0.00048"
"74.41200","6.20131","0.00089"
"74.49000","6.20771","-0.00014"
"74.56800","6.21422","0.00050"
"74.64600","6.22068","0.00005"
"74.72400","6.22720","0.00055"
"74.80200","6.23366","0.00076"
"74.88000","6.24023","0.00020"
"74.95800","6.24675","0.00032"
"75.03600","6.25315","0.00027"
"75.11400","6.25973","0.00016"
"75.19200","6.26618","0.00038"
"75.27000","6.27270","0.00072"
"75.34800","6.27916","0.00044"
"75.42600","6.28573","0.00077"
"75.50400","6.29225","0.00092"
"75.58200","6.29871","0.00016"
"75.66000","6.30523","0.00107"
"75.73800","6.31174","-0.00001"
"75.81600","6.31820","-0.00008"
"75.89400","6.32472","0.00055"
"75.97200","6.33123","0.00058"
"76.05000","6.33781","0.00061"
"76.12800","6.34421","0.00066"
"76.20600","6.35073","0.00056"
"76.28400","6.35718","0.00047"
"76.36200","6.36364","0.00089"
"76.44000","6.37016","0.00099"
"76.51800","6.37667","0.00068"
"76.59600","6.38325","0.00040"
"76.67400","6.38977","0.00073"
"76.75200","6.39616","0.00066"
"76.83000","6.40268","0.00072"
"76.90800","6.40914","0.00047"
"76.98600","6.41572","-0.00012"
"77.06400","6.42217","0.00080"
"77.14200","6.42869","0.00062"
"77.22000","6.43521","0.00123"
"77.29800","6.44172","0.00014"
"77.37600","6.44818","0.00088"
"77.45400","6.45464","0.00056"
"77.53200","6.46122","0.00035"
"77.61000","6.46773","0.00038"
"77.68800","6.47425","0.00042"
"77.76600","6.48071","0.00046"
"77.84400","6.48728","0.00069"
"77.92200","6.49368","0.00042"
"78.00000","6.50020","0.00118"
"78.07800","6.50666","0.00009"
"78.15600","6.51323","0.00037"
"78.23400","6.51969","0.00120"
"78.31200","6.52627","0.00107"
"78.39000","6.53272","0.00036"
"78.46800","6.53924","0.00025"
"78.54600","6.54570","0.00062"
"78.62400","6.55222","0.00119"
"78.70200","6.55879","0.00061"
"78.78000","6.56519","0.00092"
"78.85800","6.57177","0.00059"
"78.93600","6.57816","0.00039"
"79.01400","6.58468","0.00149"
"79.09200","6.59114","0.00077"
"79.17000","6.59771","0.00037"
"79.24800","6.60423","0.00082"
"79.32600","6.61075","0.00098"
"79.40400","6.61721","0.00072"
"79.48200","6.62372","0.00059"
"79.56000","6.63018","0.00098"
"79.63800","6.63670","0.00071"
"79.71600","6.64321","0.00105"
"79.79400","6.64973","0.00124"
"79.87200","6.65619","0.00102"
"79.95000","6.66271","0.00067"
"80.02800","6.66916","0.00106"
"80.10600","6.67568","0.00089"
"80.18400","6.68214","0.00055"
"80.26200","6.68871","0.00115"
"80.34000","6.69523","0.00105"
"80.41800","6.70175","0.00076"
"80.49600","6.70821","0.00139"
"80.57400","6.71472","0.00095"
"80.65200","6.72118","0.00102"
"80.73000","6.72770","0.00132"
"80.80800","6.73421","0.00116"
"80.88600","6.74073","0.00148"
"80.96400","6.74719","0.00104"
"81.04200","6.75371","0.00105"
"81.12000","6.76016","0.00148"
"81.19800","6.76668","0.00139"
"81.27600","6.77320","0.00121"
"81.35400","6.77971","0.00120"
"81.43200","6.78629","0.00127"
"81.51000","6.79275","0.00098"
"81.58800","6.79921","0.00105"
"81.66600","6.80566","0.00164"
"81.74400","6.81218","0.00120"
"81.82200","6.81870","0.00096"
"81.90000","6.82521","0.00168"
"81.97800","6.83173","0.00151"
"82.05600","6.83825","0.00122"
"82.13400","6.84477","0.00165"
"82.21200","6.85116","0.00220"
"82.29000","6.85768","0.00161"
"82.36800","6.86420","0.00151"
"82.44600","6.87077","0.00147"
"82.52400","6.87717","0.00197"
"82.60200","6.88369","0.00146"
"82.68000","6.89021","0.00183"
"82.75800","6.89672","0.00121"
"82.83600","6.90312","0.00147"
"82.91400","6.90964","0.00158"
"82.99200","6.91621","0.00180"
"83.07000","6.92273","0.00170"
"83.14800","6.92925","0.00132"
"83.22600","6.93571","0.00167"
"83.30400","6.94216","0.00175"
"83.38200","6.94862","0.00175"
"83.46000","6.95520","0.00143"
"83.53800","6.96171","0.00164"
"83.61600","6.96823","0.00148"
"83.69400","6.97475","0.00215"
"83.77200","6.98121","0.00141"
"83.85000","6.98766","0.00174"
"83.92800","6.99418","0.00195"
"84.00600","7.00076","0.00193"
"84.08400","7.00721","0.00167"
"84.16200","7.01373","0.00188"
"84.24000","7.02019","0.00207"
"84.31800","7.02676","0.00246"
"84.39600","7.03316","0.00181"
"84.47400","7.03968","0.00185"
"84.55200","7.04620","0.00184"
"84.63000","7.05277","0.00214"
"84.70800","7.05923","0.00192"
"84.78600","7.06575","0.00215"
"84.86400","7.07221","0.00172"
"84.94200","7.07866","0.00180"
"85.02000","7.08518","0.00209"
"85.09800","7.09170","0.00161"
"85.17600","7.09827","0.00191"
"85.25400","7.10473","0.00236"
"85.33200","7.11125","0.00164"
"85.41000","7.11770","0.00205"
"85.48800","7.12416","0.00201"
"85.56600","7.13068","0.00227"
"85.64400","7.13720","0.00191"
"85.72200","7.14377","0.00127"
"85.80000","7.15023","0.00105"
"85.87800","7.15675","0.00098"
"85.95600","7.16314","0.00113"
"86.03400","7.16966","0.00141"
"86.11200","7.17612","0.00129"
"86.19000","7.18276","0.00138"
"86.26800","7.18921","0.00121"
"86.34600","7.19573","0.00058"
"86.42400","7.20225","0.00132"
"86.50200","7.20870","0.00130"
"86.58000","7.21522","0.00109"
"86.65800","7.22168","0.00073"
"86.73600","7.22826","0.00115"
"86.81400","7.23471","0.00192"
"86.89200","7.24123","0.00145"
"86.97000","7.24775","0.00156"
"87.04800","7.25420","0.00133"
"87.12600","7.26066","0.00184"
"87.20400","7.26718","0.00098"
"87.28200","7.27370","0.00164"
"87.36000","7.28021","0.00098"
"87.43800","7.28673","0.00158"
"87.51600","7.29325","0.00156"
"87.59400","7.29970","0.00210"
"87.67200","7.30616","0.00205"
"87.75000","7.31268","0.00172"
"87.82800","7.31920","0.00178"
"87.90600","7.32571","0.00207"
"87.98400","7.33223","0.00174"
"88.06200","7.33869","0.00155"
"88.14000","7.34520","0.00172"
"88.21800","7.35166","0.00204"
"88.29600","7.35818","0.00203"
"88.37400","7.36476","0.00194"
"88.45200","7.37127","0.00191"
"88.53000","7.37773","0.00187"
"88.60800","7.38425","0.00156"
"88.68600","7.39076","0.00193"
"88.76400","7.39722","0.00171"
"88.84200","7.40374","0.00183"
"88.92000","7.41025","0.00188"
"88.99800","7.41677","0.00154"
"89.07600","7.42323","0.00179"
"89.15400","7.42975","0.00232"
"89.23200","7.43620","0.00213"
"89.31000","7.44272","0.00218"
"89.38800","7.44918","0.00193"
"89.46600","7.45575","0.00186"
"89.54400","7.46221","0.00152"
"89.62200","7.46873","0.00197"
"89.70000","7.47513","0.00240"
"89.77800","7.48170","0.00282"
"89.85600","7.48816","0.00216"
"89.93400","7.49468","0.00266"
"90.01200","7.50125","0.00173"
"90.09000","7.50771","0.00227"
"90.16800","7.51423","0.00215"
"90.24600","7.52063","0.00214"
"90.32400","7.52720","0.00260"
"90.40200","7.53366","0.00201"
"90.48000","7.54024","0.00196"
"90.55800","7.54669","0.00245"
"90.63600","7.55321","0.00219"
"90.71400","7.55967","0.00280"
"90.79200","7.56613","0.00214"
"90.87000","7.57264","0.00271"
"90.94800","7.57922","0.00222"
"91.02600","7.58574","0.00182"
"91.10400","7.59225","0.00217"
"91.18200","7.59877","0.00247"
"91.26000","7.60529","0.00235"
"91.33800","7.61169","0.00242"
"91.41600","7.61820","0.00233"
"91.49400","7.62472","0.00223"
"91.57200","7.63124","0.00215"
"91.65000","7.63775","0.00222"
"91.72800","7.64421","0.00231"
"91.80600","7.65073","0.00226"
"91.88400","7.65719","0.00236"
"91.96200","7.66364","0.00227"
"92.04000","7.67022","0.00217"
"92.11800","7.67674","0.00227"
"92.19600","7.68331","0.00226"
"92.27400","7.68977","0.00223"
"92.35200","7.69629","0.00234"
"92.43000","7.70269","0.00278"
"92.50800","7.70920","0.00248"
"92.58600","7.71566","0.00278"
"92.66400","7.72224","0.00325"
"92.74200","7.72875","0.00258"
"92.82000","7.73527","0.00285"
"92.89800","7.74173","0.00268"
"92.97600","7.74819","0.00284"
"93.05400","7.75464","0.00245"
"93.13200","7.76116","0.00265"
"93.21000","7.76774","0.00241"
"93.28800","7.77419","0.00282"
"93.36600","7.78077","0.00203"
"93.44400","7.78717","0.00237"
"93.52200","7.79369","0.00265"
"93.60000","7.80020","0.00280"
"93.67800","7.80672","0.00183"
"93.75600","7.81324","0.00199"
"93.83400","7.81969","0.00251"
"93.91200","7.82627","0.00259"
"93.99000","7.83267","0.00200"
"94.06800","7.83919","0.00273"
"94.14600","7.84564","0.00277"
"94.22400","7.85222","0.00251"
"94.30200","7.85874","0.00253"
"94.38000","7.86525","0.00271"
"94.45800","7.87177","0.00295"
"94.53600","7.87823","0.00278"
"94.61400","7.88469","0.00261"
"94.69200","7.89114","0.00256"
"94.77000","7.89772","0.00293"
"94.84800","7.90424","0.00301"
"94.92600","7.91075","0.00276"
"95.00400","7.91727","0.00294"
"95.08200","7.92373","0.00321"
"95.16000","7.93018","0.00294"
"95.23800","7.93664","0.00294"
"95.31600","7.94316","0.00277"
"95.39400","7.94974","0.00310"
"95.47200","7.95619","0.00283"
"95.55000","7.96277","0.00295"
"95.62800","7.96923","0.00338"
"95.70600","7.97563","0.00268"
"95.78400","7.98220","0.00294"
"95.86200","7.98872","0.00327"
"95.94000","7.99524","0.00356"
"96.01800","8.00169","0.00282"
"96.09600","8.00821","0.00281"
"96.17400","8.01467","0.00282"
"96.25200","8.02112","0.00320"
"96.33000","8.02764","0.00324"
"96.40800","8.03422","0.00327"
"96.48600","8.04080","0.00271"
"96.56400","8.04725","0.00311"
"96.64200","8.05371","0.00306"
"96.72000","8.06023","0.00316"
"96.79800","8.06668","0.00362"
"96.87600","8.07314","0.00286"
"96.95400","8.07966","0.00292"
"97.03200","8.08624","0.00347"
"97.11000","8.09269","0.00270"
"97.18800","8.09921","0.00300"
"97.26600","8.10567","0.00270"
"97.34400","8.11218","0.00318"
"97.42200","8.11864","0.00346"
"97.50000","8.12528","0.00317"
"97.57800","8.13173","0.00368"
"97.65600","8.13825","0.00332"
"97.73400","8.14471","0.00336"
"97.81200","8.15123","0.00363"
"97.89000","8.15762","0.00307"
"97.96800","8.16420","0.00297"
"98.04600","8.17072","0.00286"
"98.12400","8.17723","0.00360"
"98.20200","8.18369","0.00329"
"98.28000","8.19015","0.00286"
"98.35800","8.19673","0.00324"
"98.43600","8.20318","0.00360"
"98.51400","8.20970","0.00376"
"98.59200","8.21616","0.00366"
"98.67000","8.22273","0.00311"
"98.74800","8.22925","0.00338"
"98.82600","8.23571","0.00338"
"98.90400","8.24217","0.00367"
"98.98200","8.24862","0.00320"
"99.06000","8.25520","0.00365"
"99.13800","8.26172","0.00358"
"99.21600","8.26823","0.00340"
"99.29400","8.27475","0.00340"
"99.37200","8.28127","0.00349"
"99.45000","8.28767","0.00327"
"99.52800","8.29424","0.00337"
"99.60600","8.30070","0.00362"
"99.68400","8.30728","0.00348"
"99.76200","8.31373","0.00361"
"99.84000","8.32025","0.00306"
"99.91800","8.32671","0.00386"
"99.99600","8.33323","0.00374"
"100.07400","8.33968","0.00397"
"100.15200","8.34620","0.00367"
"100.23000","8.35278","0.00319"
"100.30800","8.35923","0.00405"
"100.38600","8.36569","0.00345"
"100.46400","8.37215","0.00389"
"100.54200","8.37867","0.00375"
"100.62000","8.38512","0.00371"
"100.69800","8.39170","0.00405"
"100.77600","8.39822","0.00404"
"100.85400","8.40473","0.00367"
"100.93200","8.41125","0.00411"
"101.01000","8.41771","0.00437"
"101.08800","8.42422","0.00373"
"101.16600","8.43062","0.00399"
"101.24400","8.43726","0.00412"
"101.32200","8.44372","0.00419"
"101.40000","8.45029","0.00474"
"101.47800","8.45675","0.00395"
"101.55600","8.46321","0.00434"
"101.63400","8.46967","0.00404"
"101.71200","8.47612","0.00442"
"101.79000","8.48276","0.00405"
"101.86800","8.48928","0.00377"
"101.94600","8.49579","0.00393"
"102.02400","8.50219","0.00393"
"102.10200","8.50877","0.00435"
"102.18000","8.51517","0.00421"
"102.25800","8.52174","0.00441"
"102.33600","8.52820","0.00428"
"102.41400","8.53472","0.00396"
"102.49200","8.54123","0.00426"
"102.57000","8.54775","0.00465"
"102.64800","8.55421","0.00428"
"102.72600","8.56067","0.00458"
"102.80400","8.56718","0.00482"
"102.88200","8.57364","0.00462"
"102.96000","8.58022","0.00475"
"103.03800","8.58673","0.00454"
"103.11600","8.59325","0.00442"
"103.19400","8.59965","0.00466"
"103.27200","8.60616","0.00471"
"103.35000","8.61268","0.00490"
"103.42800","8.61920","0.00380"
"103.50600","8.62578","0.00480"
"103.58400","8.63223","0.00446"
"103.66200","8.63875","0.00440"
"103.74000","8.64521","0.00449"
"103.81800","8.65166","0.00485"
"103.89600","8.65818","0.00486"
"103.97400","8.66470","0.00453"
"104.05200","8.67122","0.00479"
"104.13000","8.67773","0.00443"
"104.20800","8.68425","0.00453"
"104.28600","8.69071","0.00472"
"104.36400","8.69717","0.00448"
"104.44200","8.70368","0.00449"
"104.52000","8.71020","0.00451"
"104.59800","8.71672","0.00537"
"104.67600","8.72323","0.00500"
"104.75400","8.72969","0.00493"
"104.83200","8.73621","0.00493"
"104.91000","8.74267","0.00500"
"104.98800","8.74924","0.00471"
"105.06600","8.75570","0.00515"
"105.14400","8.76222","0.00520"
"105.22200","8.76867","0.00478"
"105.30000","8.77519","0.00529"
"105.37800","8.78171","0.00500"
"105.45600","8.78817","0.00448"
"105.53400","8.79474","0.00464"
"105.61200","8.80120","0.00506"
"105.69000","8.80772","0.00484"
"105.76800","8.81417","0.00568"
"105.84600","8.82069","0.00562"
"105.92400","8.82715","0.00519"
"106.00200","8.83366","0.00551"
"106.08000","8.84018","0.00555"
"106.15800","8.84670","0.00535"
"106.23600","8.85328","0.00490"
"106.31400","8.85973","0.00547"
"106.39200","8.86625","0.00506"
"106.47000","8.87271","0.00516"
"106.54800","8.87922","0.00491"
"106.62600","8.88574","0.00535"
"106.70400","8.89232","0.00551"
"106.78200","8.89872","0.00533"
"106.86000","8.90523","0.00532"
"106.93800","8.91169","0.00566"
"107.01600","8.91815","0.00548"
"107.09400","8.92466","0.00547"
"107.17200","8.93124","0.00568"
"107.25000","8.93776","0.00548"
"107.32800","8.94421","0.00547"
"107.40600","8.95073","0.00561"
"107.48400","8.95713","0.00571"
"107.56200","8.96371","0.00583"
"107.64000","8.97016","0.00574"
"107.71800","8.97668","0.00607"
"107.79600","8.98320","0.00563"
"107.87400","8.98971","0.00577"
"107.95200","8.99623","0.00519"
"108.03000","9.00269","0.00625"
"108.10800","9.00915","0.00588"
"108.18600","9.01572","0.00557"
"108.26400","9.02224","0.00586"
"108.34200","9.02876","0.00569"
"108.42000","9.03521","0.00540"
"108.49800","9.04173","0.00629"
"108.57600","9.04819","0.00613"
"108.65400","9.05465","0.00583"
"108.73200","9.06122","0.00633"
"108.81000","9.06774","0.00641"
"108.88800","9.07420","0.00634"
"108.96600","9.08071","0.00616"
"109.04400","9.08723","0.00641"
"109.12200","9.09375","0.00611"
"109.20000","9.10015","0.00600"
"109.27800","9.10672","0.00673"
"109.35600","9.11324","0.00667"
"109.43400","9.11976","0.00669"
"109.51200","9.12621","0.00609"
"109.59000","9.13273","0.00626"
"109.66800","9.13919","0.00643"
"109.74600","9.14565","0.00628"
"109.82400","9.15222","0.00667"
"109.90200","9.15874","0.00638"
"109.98000","9.16526","0.00598"
"110.05800","9.17171","0.00703"
"110.13600","9.17829","0.00644"
"110.21400","9.18469","0.00688"
"110.29200","9.19115","0.00672"
"110.37000","9.19766","0.00743"
"110.44800","9.20424","0.00778"
"110.52600","9.21076","0.00734"
"110.60400","9.21721","0.00805"
"110.68200","9.22373","0.00773"
"110.76000","9.23019","0.00685"
"110.83800","9.23671","0.00766"
"110.91600","9.24316","0.00705"
"110.99400","9.24974","0.00757"
"111.07200","9.25620","0.00757"
"111.15000","9.26277","0.00768"
"111.22800","9.26917","0.00766"
"111.30600","9.27563","0.00792"
"111.38400","9.28215","0.00405"
"111.46200","9.28872","0.00150"
"111.54000","9.29524","0.00006"
"111.61800","9.30170","0.00063"
"111.69600","9.30827","0.00036"
"111.77400","9.31473","0.00096"
"111.85200","9.32119","0.00193"
"111.93000","9.32771","0.00191"
"112.00800","9.33416","0.00225"
"112.08600","9.34074","0.00105"
"112.16400","9.34720","0.00041"
"112.24200","9.35371","0.00108"
"112.32000","9.36023","0.00094"
"112.39800","9.36669","0.00134"
"112.47600","9.37321","0.00216"
"112.55400","9.37972","0.00249"
"112.63200","9.38624","0.00114"
"112.71000","9.39276","0.00175"
"112.78800","9.39921","0.00058"
"112.86600","9.40573","0.00135"
"112.94400","9.41213","0.00180"
"113.02200","9.41870","0.00229"
"113.10000","9.42522","0.00293"
"113.17800","9.43174","0.00303"
"113.25600","9.43820","0.00198"
"113.33400","9.44471","0.00160"
"113.41200","9.45117","0.00198"
"113.49000","9.45763","0.00129"
"113.56800","9.46420","0.00219"
"113.64600","9.47066","0.00324"
"113.72400","9.47724","0.00296"
"113.80200","9.48370","0.00231"
"113.88000","9.49027","0.00215"
"113.95800","9.49667","0.00100"
"114.03600","9.50319","0.00178"
"114.11400","9.50964","0.00287"
"114.19200","9.51622","0.00349"
"114.27000","9.52274","0.00398"
"114.34800","9.52920","0.00358"
"114.42600","9.53577","0.00259"