File: Force_trajectories/170226_1/Specimen_RawData_6.csv
End date,"2/26/2017"
Specimen label,"4BG_29"
Maximum Load,"0.86594",N

Time,Extension,Load
(s),(mm),(N)
"0.00000","0.00000","0.00017"
"0.31200","0.02535","0.00100"
"0.62400","0.05226","0.00075"
"0.93600","0.07820","0.00149"
"1.24800","0.10421","0.00156"
"1.56000","0.13022","0.00217"
"1.87200","0.15617","0.00225"
"2.18400","0.18218","0.00261"
"2.49600","0.20819","0.00300"
"2.80800","0.23420","0.00255"
"3.12000","0.26020","0.00306"
"3.43200","0.28615","0.00344"
"3.74400","0.31222","0.00412"
"4.05600","0.33811","0.00350"
"4.36800","0.36418","0.00319"
"4.68000","0.39019","0.00402"
"4.99200","0.41619","0.00355"
"5.30400","0.44214","0.00371"
"5.61600","0.46815","0.00416"
"5.92800","0.49422","0.00425"
"6.24000","0.52017","0.00473"
"6.55200","0.54618","0.00372"
"6.86400","0.57219","0.00492"
"7.17600","0.59813","0.00486"
"7.48800","0.62420","0.00462"
"7.80000","0.65015","0.00496"
"8.11200","0.67622","0.00489"
"8.42400","0.70211","0.00505"
"8.73600","0.72818","0.00516"
"9.04800","0.75419","0.00555"
"9.36000","0.78013","0.00520"
"9.67200","0.80620","0.00577"
"9.98400","0.83215","0.00543"
"10.29600","0.85822","0.00603"
"10.60800","0.88417","0.00543"
"10.92000","0.91012","0.00564"
"11.23200","0.93618","0.00523"
"11.54400","0.96219","0.00606"
"11.85600","0.98820","0.00605"
"12.16800","1.01415","0.00571"
"12.48000","1.04022","0.00625"
"12.79200","1.06611","0.00596"
"13.10400","1.09212","0.00589"
"13.41600","1.11818","0.00583"
"13.72800","1.14413","0.00664"
"14.04000","1.17020","0.00635"
"14.35200","1.19615","0.00638"
"14.66400","1.22216","0.00625"
"14.97600","1.24817","0.00664"
"15.28800","1.27417","0.00624"
"15.60000","1.30018","0.00641"
"15.91200","1.32613","0.00590"
"16.22400","1.35220","0.00650"
"16.53600","1.37815","0.00619"
"16.84800","1.40416","0.00639"
"17.16000","1.43023","0.00659"
"17.47200","1.45617","0.00633"
"17.78400","1.48218","0.00650"
"18.09600","1.50813","0.00632"
"18.40800","1.53420","0.00746"
"18.72000","1.56021","0.00668"
"19.03200","1.58622","0.00637"
"19.34400","1.61216","0.00699"
"19.65600","1.63811","0.00677"
"19.96800","1.66418","0.00731"
"20.28000","1.69013","0.00741"
"20.59200","1.71620","0.00633"
"20.90400","1.74221","0.00684"
"21.21600","1.76816","0.00675"
"21.52800","1.79416","0.00719"
"21.84000","1.82011","0.00745"
"22.15200","1.84618","0.00693"
"22.46400","1.87219","0.00678"
"22.77600","1.89820","0.00656"
"23.08800","1.92421","0.00668"
"23.40000","1.95016","0.00652"
"23.71200","1.97616","0.00685"
"24.02400","2.00211","0.00712"
"24.33600","2.02818","0.00726"
"24.64800","2.05419","0.00723"
"24.96000","2.08020","0.00764"
"25.27200","2.10621","0.00751"
"25.58400","2.13209","0.00712"
"25.89600","2.15822","0.00751"
"26.20800","2.18417","0.00763"
"26.52000","2.21012","0.00814"
"26.83200","2.23619","0.00757"
"27.14400","2.26208","0.00763"
"27.45600","2.28821","0.00730"
"27.76800","2.31415","0.00818"
"28.08000","2.34016","0.00774"
"28.39200","2.36617","0.00794"
"28.70400","2.39212","0.00823"
"29.01600","2.41819","0.00811"
"29.32800","2.44414","0.00797"
"29.64000","2.47020","0.00825"
"29.95200","2.49615","0.00826"
"30.26400","2.52222","0.00826"
"30.57600","2.54817","0.00853"
"30.88800","2.57412","0.00843"
"31.20000","2.60019","0.00864"
"31.51200","2.62614","0.00896"
"31.82400","2.65220","0.00848"
"32.13600","2.67815","0.00875"
"32.44800","2.70416","0.00923"
"32.76000","2.73023","0.00911"
"33.07200","2.75618","0.00976"
"33.38400","2.78225","0.00954"
"33.69600","2.80814","0.00950"
"34.00800","2.83414","0.00954"
"34.32000","2.86015","0.00993"
"34.63200","2.88616","0.00961"
"34.94400","2.91223","0.01033"
"35.25600","2.93812","0.01013"
"35.56800","2.96419","0.01015"
"35.88000","2.99013","0.01049"
"36.19200","3.01614","0.01107"
"36.50400","3.04221","0.01092"
"36.81600","3.06816","0.01082"
"37.12800","3.09423","0.01074"
"37.44000","3.12012","0.01139"
"37.75200","3.14618","0.01087"
"38.06400","3.17213","0.01113"
"38.37600","3.19820","0.01072"
"38.68800","3.22421","0.01140"
"39.00000","3.25016","0.01114"
"39.31200","3.27617","0.01179"
"39.62400","3.30206","0.01170"
"39.93600","3.32818","0.01168"
"40.24800","3.35419","0.01196"
"40.56000","3.38014","0.01127"
"40.87200","3.40621","0.01159"
"41.18400","3.43216","0.01191"
"41.49600","3.45817","0.01247"
"41.80800","3.48412","0.01218"
"42.12000","3.51018","0.01206"
"42.43200","3.53613","0.01236"
"42.74400","3.56214","0.01285"
"43.05600","3.58815","0.01241"
"43.36800","3.61410","0.01296"
"43.68000","3.64017","0.01281"
"43.99200","3.66617","0.01366"
"44.30400","3.69218","0.01275"
"44.61600","3.71825","0.01288"
"44.92800","3.74414","0.01312"
"45.24000","3.77015","0.01302"
"45.55200","3.79616","0.01419"
"45.86400","3.82223","0.01334"
"46.17600","3.84817","0.01389"
"46.48800","3.87418","0.01351"
"46.80000","3.90019","0.01360"
"47.11200","3.92614","0.01371"
"47.42400","3.95221","0.01351"
"47.73600","3.97816","0.01391"
"48.04800","4.00422","0.01376"
"48.36000","4.03023","0.01373"
"48.67200","4.05612","0.01427"
"48.98400","4.08219","0.01413"
"49.29600","4.10814","0.01419"
"49.60800","4.13421","0.01358"
"49.92000","4.16016","0.01331"
"50.23200","4.18610","0.01296"
"50.54400","4.21217","0.01329"
"50.85600","4.23818","0.01277"
"51.16800","4.26419","0.01193"
"51.48000","4.29020","0.01192"
"51.79200","4.31621","0.01217"
"52.10400","4.34221","0.01223"
"52.41600","4.36810","0.01202"
"52.72800","4.39417","0.01230"
"53.04000","4.42012","0.01290"
"53.35200","4.44619","0.01248"
"53.66400","4.47220","0.01280"
"53.97600","4.49815","0.01357"
"54.28800","4.52421","0.01327"
"54.60000","4.55016","0.01321"
"54.91200","4.57623","0.01404"
"55.22400","4.60206","0.01410"
"55.53600","4.62819","0.01410"
"55.84800","4.65420","0.01400"
"56.16000","4.68021","0.01369"
"56.47200","4.70621","0.01453"
"56.78400","4.73210","0.01382"
"57.09600","4.75817","0.01458"
"57.40800","4.78412","0.01498"
"57.72000","4.81013","0.01499"
"58.03200","4.83620","0.01581"
"58.34400","4.86220","0.01552"
"58.65600","4.88821","0.01582"
"58.96800","4.91410","0.01626"
"59.28000","4.94017","0.01604"
"59.59200","4.96612","0.01597"
"59.90400","4.99219","0.01573"
"60.21600","5.01826","0.01633"
"60.52800","5.04414","0.01595"
"60.84000","5.07021","0.01599"
"61.15200","5.09616","0.01643"
"61.46400","5.12223","0.01694"
"61.77600","5.14818","0.01630"
"62.08800","5.17419","0.01600"
"62.40000","5.20019","0.01579"
"62.71200","5.22608","0.01592"
"63.02400","5.25221","0.01609"
"63.33600","5.27816","0.01589"
"63.64800","5.30417","0.01550"
"63.96000","5.33018","0.01554"
"64.27200","5.35613","0.01557"
"64.58400","5.38213","0.01588"
"64.89600","5.40808","0.01611"
"65.20800","5.43421","0.01562"
"65.52000","5.46022","0.01492"
"65.83200","5.48623","0.01561"
"66.14400","5.51218","0.01401"
"66.45600","5.53812","0.01010"
"66.76800","5.56413","0.01258"
"67.08000","5.59014","0.01284"
"67.39200","5.61621","0.01293"
"67.70400","5.64216","0.01203"
"68.01600","5.66817","0.01336"
"68.32800","5.69418","0.01380"
"68.64000","5.72012","0.01376"
"68.95200","5.74619","0.01336"
"69.26400","5.77214","0.01374"
"69.57600","5.79815","0.01463"
"69.88800","5.82416","0.01533"
"70.20000","5.85011","0.01598"
"70.51200","5.87617","0.01482"
"70.82400","5.90218","0.01494"
"71.13600","5.92819","0.01569"
"71.44800","5.95414","0.01556"
"71.76000","5.98015","0.01613"
"72.07200","6.00622","0.01629"
"72.38400","6.03211","0.01667"
"72.69600","6.05817","0.01687"
"73.00800","6.08418","0.01672"
"73.32000","6.11019","0.01672"
"73.63200","6.13614","0.01685"
"73.94400","6.16215","0.01776"
"74.25600","6.18822","0.01738"
"74.56800","6.21417","0.01784"
"74.88000","6.24023","0.01788"
"75.19200","6.26618","0.01785"
"75.50400","6.29213","0.01755"
"75.81600","6.31820","0.01829"
"76.12800","6.34421","0.01805"
"76.44000","6.37022","0.01841"
"76.75200","6.39610","0.01907"
"77.06400","6.42217","0.01883"
"77.37600","6.44812","0.01883"
"77.68800","6.47413","0.01907"
"78.00000","6.50020","0.01900"
"78.31200","6.52615","0.01946"
"78.62400","6.55216","0.01961"
"78.93600","6.57816","0.01964"
"79.24800","6.60417","0.01928"
"79.56000","6.63024","0.01836"
"79.87200","6.65619","0.01935"
"80.18400","6.68220","0.01982"
"80.49600","6.70815","0.01964"
"80.80800","6.73421","0.01981"
"81.12000","6.76016","0.01953"
"81.43200","6.78623","0.01961"
"81.74400","6.81224","0.01989"
"82.05600","6.83813","0.01981"
"82.36800","6.86420","0.02027"
"82.68000","6.89015","0.02016"
"82.99200","6.91621","0.02075"
"83.30400","6.94216","0.02117"
"83.61600","6.96817","0.01980"
"83.92800","6.99418","0.02064"
"84.24000","7.02013","0.02093"
"84.55200","7.04620","0.01987"
"84.86400","7.07214","0.02080"
"85.17600","7.09821","0.02050"
"85.48800","7.12416","0.02084"
"85.80000","7.15017","0.02062"
"86.11200","7.17618","0.02138"
"86.42400","7.20207","0.02149"
"86.73600","7.22820","0.02120"
"87.04800","7.25420","0.02156"
"87.36000","7.28021","0.02159"
"87.67200","7.30622","0.02103"
"87.98400","7.33217","0.02181"
"88.29600","7.35818","0.02209"
"88.60800","7.38413","0.02228"
"88.92000","7.41020","0.02227"
"89.23200","7.43620","0.02259"
"89.54400","7.46215","0.02205"
"89.85600","7.48816","0.02199"
"90.16800","7.51411","0.02240"
"90.48000","7.54024","0.02292"
"90.79200","7.56619","0.02266"
"91.10400","7.59213","0.02275"
"91.41600","7.61820","0.02328"
"91.72800","7.64415","0.02341"
"92.04000","7.67022","0.02302"
"92.35200","7.69611","0.02339"
"92.66400","7.72224","0.02380"
"92.97600","7.74813","0.02370"
"93.28800","7.77413","0.02371"
"93.60000","7.80014","0.02373"
"93.91200","7.82615","0.02355"
"94.22400","7.85222","0.02382"
"94.53600","7.87817","0.02463"
"94.84800","7.90412","0.02403"
"95.16000","7.93018","0.02452"
"95.47200","7.95613","0.02432"
"95.78400","7.98220","0.02474"
"96.09600","8.00809","0.02499"
"96.40800","8.03422","0.02466"
"96.72000","8.06017","0.02537"
"97.03200","8.08618","0.02523"
"97.34400","8.11218","0.02514"
"97.65600","8.13813","0.02539"
"97.96800","8.16420","0.02560"
"98.28000","8.19009","0.02613"
"98.59200","8.21616","0.02669"
"98.90400","8.24217","0.02656"
"99.21600","8.26818","0.02518"
"99.52800","8.29418","0.02535"
"99.84000","8.32013","0.02569"
"100.15200","8.34620","0.02595"
"100.46400","8.37209","0.02592"
"100.77600","8.39816","0.02655"
"101.08800","8.42417","0.02693"
"101.40000","8.45011","0.02646"
"101.71200","8.47618","0.02669"
"102.02400","8.50207","0.02710"
"102.33600","8.52814","0.02638"
"102.64800","8.55415","0.02657"
"102.96000","8.58022","0.02678"
"103.27200","8.60623","0.02714"
"103.58400","8.63211","0.02700"
"103.89600","8.65818","0.02678"
"104.20800","8.68413","0.02726"
"104.52000","8.71020","0.02790"
"104.83200","8.73621","0.02777"
"105.14400","8.76216","0.02811"
"105.45600","8.78822","0.02828"
"105.76800","8.81411","0.02890"
"106.08000","8.84018","0.02985"
"106.39200","8.86619","0.02957"
"106.70400","8.89220","0.02961"
"107.01600","8.91821","0.03017"
"107.32800","8.94416","0.03055"
"107.64000","8.97016","0.03068"
"107.95200","8.99611","0.03042"
"108.26400","9.02224","0.03090"
"108.57600","9.04819","0.03204"
"108.88800","9.07420","0.03225"
"109.20000","9.10021","0.03161"
"109.51200","9.12615","0.03270"
"109.82400","9.15216","0.03298"
"110.13600","9.17817","0.03402"
"110.44800","9.20418","0.03470"
"110.76000","9.23019","0.03378"
"111.07200","9.25614","0.03502"
"111.38400","9.28215","0.03480"
"111.69600","9.30809","0.03592"
"112.00800","9.33416","0.03592"
"112.32000","9.36017","0.03677"
"112.63200","9.38612","0.03799"
"112.94400","9.41219","0.03771"
"113.25600","9.43808","0.03816"
"113.56800","9.46420","0.03868"
"113.88000","9.49015","0.03855"
"114.19200","9.51616","0.03945"
"114.50400","9.54217","0.04012"
"114.81600","9.56812","0.03999"
"115.12800","9.59425","0.04026"
"115.44000","9.62014","0.04032"
"115.75200","9.64620","0.04127"
"116.06400","9.67215","0.04179"
"116.37600","9.69816","0.04211"
"116.68800","9.72417","0.04244"
"117.00000","9.75012","0.04301"
"117.31200","9.77619","0.04332"
"117.62400","9.80219","0.04403"
"117.93600","9.82820","0.04447"
"118.24800","9.85415","0.04472"
"118.56000","9.88016","0.04543"
"118.87200","9.90623","0.04563"
"119.18400","9.93218","0.04613"
"119.49600","9.95819","0.04632"
"119.80800","9.98408","0.04723"
"120.12000","10.01020","0.04767"
"120.43200","10.03621","0.04748"
"120.74400","10.06216","0.04825"
"121.05600","10.08823","0.04860"
"121.36800","10.11418","0.04909"
"121.68000","10.14019","0.05010"
"121.99200","10.16613","0.05044"
"122.30400","10.19220","0.05062"
"122.61600","10.21821","0.05149"
"122.92800","10.24416","0.05112"
"123.24000","10.27023","0.05170"
"123.55200","10.29606","0.05240"
"123.86400","10.32218","0.05304"
"124.17600","10.34819","0.05340"
"124.48800","10.37420","0.05351"
"124.80000","10.40021","0.05362"
"125.11200","10.42610","0.05435"
"125.42400","10.45223","0.05498"
"125.73600","10.47812","0.05523"
"126.04800","10.50418","0.05502"
"126.36000","10.53019","0.05495"
"126.67200","10.55614","0.05562"
"126.98400","10.58215","0.05568"
"127.29600","10.60810","0.05646"
"127.60800","10.63417","0.05663"
"127.92000","10.66018","0.05692"
"128.23200","10.68618","0.05746"
"128.54400","10.71219","0.05759"
"128.85600","10.73814","0.05791"
"129.16800","10.76409","0.05845"
"129.48000","10.79010","0.05871"
"129.79200","10.81617","0.05875"
"130.10400","10.84217","0.05905"
"130.41600","10.86818","0.05948"
"130.72800","10.89419","0.06005"
"131.04000","10.92014","0.06013"
"131.35200","10.94621","0.06060"
"131.66400","10.97216","0.06122"
"131.97600","10.99823","0.06158"
"132.28800","11.02423","0.06191"
"132.60000","11.05018","0.06214"
"132.91200","11.07619","0.06269"
"133.22400","11.10208","0.06341"
"133.53600","11.12821","0.06409"
"133.84800","11.15416","0.06469"
"134.16000","11.18016","0.06517"
"134.47200","11.20617","0.06573"
"134.78400","11.23212","0.06633"
"135.09600","11.25825","0.06706"
"135.40800","11.28420","0.06724"
"135.72000","11.31015","0.06826"
"136.03200","11.33615","0.06887"
"136.34400","11.36210","0.06928"
"136.65600","11.38823","0.07117"
"136.96800","11.41412","0.07177"
"137.28000","11.44019","0.07252"
"137.59200","11.46614","0.07336"
"137.90400","11.49215","0.07405"
"138.21600","11.51816","0.07459"
"138.52800","11.54416","0.07481"
"138.84000","11.57023","0.07590"
"139.15200","11.59612","0.07704"
"139.46400","11.62219","0.07794"
"139.77600","11.64820","0.07850"
"140.08800","11.67415","0.08001"
"140.40000","11.70021","0.08038"
"140.71200","11.72616","0.08126"
"141.02400","11.75217","0.08271"
"141.33600","11.77812","0.08343"
"141.64800","11.80419","0.08448"
"141.96000","11.83014","0.08575"
"142.27200","11.85614","0.08623"
"142.58400","11.88221","0.08790"
"142.89600","11.90810","0.08943"
"143.20800","11.93417","0.09023"
"143.52000","11.96012","0.09093"
"143.83200","11.98619","0.09182"
"144.14400","12.01219","0.09289"
"144.45600","12.03814","0.09361"
"144.76800","12.06415","0.09443"
"145.08000","12.09016","0.09586"
"145.39200","12.11617","0.09614"
"145.70400","12.14218","0.09696"
"146.01600","12.16819","0.09768"
"146.32800","12.19425","0.09846"
"146.64000","12.22014","0.09968"
"146.95200","12.24615","0.09989"
"147.26400","12.27216","0.10063"
"147.57600","12.29823","0.10126"
"147.88800","12.32424","0.10261"
"148.20000","12.35018","0.10273"
"148.51200","12.37619","0.10325"
"148.82400","12.40214","0.10410"
"149.13600","12.42815","0.10462"
"149.44800","12.45416","0.10558"
"149.76000","12.48023","0.10629"
"150.07200","12.50624","0.10676"
"150.38400","12.53213","0.10793"
"150.69600","12.55819","0.10888"
"151.00800","12.58414","0.10995"
"151.32000","12.61021","0.11112"
"151.63200","12.63622","0.11244"
"151.94400","12.66217","0.11392"
"152.25600","12.68818","0.11523"
"152.56800","12.71413","0.11577"
"152.88000","12.74019","0.11739"
"153.19200","12.76614","0.11923"
"153.50400","12.79221","0.11995"
"153.81600","12.81822","0.12136"
"154.12800","12.84417","0.12310"
"154.44000","12.87017","0.12485"
"154.75200","12.89612","0.12592"
"155.06400","12.92219","0.12755"
"155.37600","12.94814","0.12874"
"155.68800","12.97415","0.13065"
"156.00000","13.00016","0.13174"
"156.31200","13.02611","0.13376"
"156.62400","13.05217","0.13481"
"156.93600","13.07812","0.13581"
"157.24800","13.10413","0.13775"
"157.56000","13.13014","0.13873"
"157.87200","13.15615","0.13946"
"158.18400","13.18222","0.14087"
"158.49600","13.20811","0.14112"
"158.80800","13.23417","0.14224"
"159.12000","13.26012","0.14327"
"159.43200","13.28613","0.14366"
"159.74400","13.31214","0.14425"
"160.05600","13.33815","0.14476"
"160.36800","13.36422","0.14564"
"160.68000","13.39016","0.14591"
"160.99200","13.41623","0.14659"
"161.30400","13.44218","0.14711"
"161.61600","13.46813","0.14808"
"161.92800","13.49420","0.14816"
"162.24000","13.52015","0.14856"
"162.55200","13.54616","0.14890"
"162.86400","13.57210","0.14945"
"163.17600","13.59811","0.14882"
"163.48800","13.62418","0.05210"
"163.80000","13.65019","0.05001"
"164.11200","13.67620","0.05109"
"164.42400","13.70209","0.05462"
"164.73600","13.72822","0.05400"
"165.04800","13.75416","0.05822"
"165.36000","13.78017","0.05707"
"165.67200","13.80618","0.05748"
"165.98400","13.83219","0.06217"
"166.29600","13.85820","0.05973"
"166.60800","13.88409","0.06029"
"166.92000","13.91015","0.06611"
"167.23200","13.93616","0.06245"
"167.54400","13.96217","0.06424"
"167.85600","13.98818","0.06917"
"168.16800","14.01413","0.06686"
"168.48000","14.04020","0.06893"
"168.79200","14.06615","0.07409"
"169.10400","14.09221","0.07160"
"169.41600","14.11816","0.07358"
"169.72800","14.14417","0.07882"
"170.04000","14.17018","0.07738"
"170.35200","14.19607","0.07949"
"170.66400","14.22214","0.08617"
"170.97600","14.24821","0.08436"
"171.28800","14.27421","0.08610"
"171.60000","14.30016","0.09156"
"171.91200","14.32611","0.09189"
"172.22400","14.35218","0.09242"
"172.53600","14.37813","0.09639"
"172.84800","14.40420","0.09884"
"173.16000","14.43020","0.09815"
"173.47200","14.45615","0.10099"
"173.78400","14.48222","0.10400"
"174.09600","14.50811","0.10376"
"174.40800","14.53424","0.10458"
"174.72000","14.56019","0.10819"
"175.03200","14.58619","0.10944"
"175.34400","14.61220","0.10955"
"175.65600","14.63815","0.11320"
"175.96800","14.66422","0.11818"
"176.28000","14.69011","0.11897"
"176.59200","14.71624","0.12085"
"176.90400","14.74213","0.12489"
"177.21600","14.76820","0.12953"
"177.52800","14.79420","0.13027"
"177.84000","14.82015","0.13164"
"178.15200","14.84622","0.13549"
"178.46400","14.87217","0.13849"
"178.77600","14.89824","0.13986"
"179.08800","14.92413","0.14066"
"179.40000","14.95014","0.14315"
"179.71200","14.97620","0.14480"
"180.02400","15.00215","0.14533"
"180.33600","15.02822","0.14579"
"180.64800","15.05417","0.14661"
"180.96000","15.08012","0.14786"
"181.27200","15.10618","0.14848"
"181.58400","15.13219","0.14919"
"181.89600","15.15820","0.14976"
"182.20800","15.18415","0.15140"
"182.52000","15.21022","0.15218"
"182.83200","15.23623","0.15330"
"183.14400","15.26212","0.15394"
"183.45600","15.28824","0.15569"
"183.76800","15.31413","0.15810"
"184.08000","15.34020","0.16033"
"184.39200","15.36609","0.16216"
"184.70400","15.39222","0.16445"
"185.01600","15.41817","0.16671"
"185.32800","15.44411","0.17078"
"185.64000","15.47018","0.17468"
"185.95200","15.49607","0.17762"
"186.26400","15.52220","0.18100"
"186.57600","15.54815","0.18410"
"186.88800","15.57422","0.18809"
"187.20000","15.60023","0.19290"
"187.51200","15.62611","0.19581"
"187.82400","15.65218","0.19997"
"188.13600","15.67807","0.20353"
"188.44800","15.70420","0.20630"
"188.76000","15.73021","0.20848"
"189.07200","15.75616","0.21029"
"189.38400","15.78222","0.21161"
"189.69600","15.80811","0.21342"
"190.00800","15.83418","0.21513"
"190.32000","15.86013","0.21724"
"190.63200","15.88620","0.21899"
"190.94400","15.91221","0.22149"
"191.25600","15.93816","0.22467"
"191.56800","15.96416","0.22678"
"191.88000","15.99005","0.23033"
"192.19200","16.01624","0.23312"
"192.50400","16.04219","0.23534"
"192.81600","16.06820","0.23897"
"193.12800","16.09421","0.24184"
"193.44000","16.12016","0.24520"
"193.75200","16.14616","0.24768"
"194.06400","16.17217","0.23283"
"194.37600","16.19818","0.15590"
"194.68800","16.22419","0.16173"
"195.00000","16.25014","0.16396"
"195.31200","16.27615","0.16512"
"195.62400","16.30209","0.17020"
"195.93600","16.32822","0.17725"
"196.24800","16.35417","0.18916"
"196.56000","16.38018","0.19821"
"196.87200","16.40619","0.19902"
"197.18400","16.43214","0.20278"
"197.49600","16.45820","0.20648"
"197.80800","16.48415","0.21005"
"198.12000","16.51016","0.21305"
"198.43200","16.53617","0.21579"
"198.74400","16.56212","0.21706"
"199.05600","16.58813","0.21895"
"199.36800","16.61408","0.21952"
"199.68000","16.64026","0.22251"
"199.99200","16.66615","0.22777"
"200.30400","16.69216","0.23232"
"200.61600","16.71817","0.23645"
"200.92800","16.74412","0.23939"
"201.24000","16.77024","0.24230"
"201.55200","16.79613","0.24381"
"201.86400","16.82220","0.24733"
"202.17600","16.84815","0.24997"
"202.48800","16.87416","0.25317"
"202.80000","16.90017","0.25514"
"203.11200","16.92618","0.25667"
"203.42400","16.95225","0.25794"
"203.73600","16.97814","0.25890"
"204.04800","17.00420","0.25999"
"204.36000","17.03015","0.26155"
"204.67200","17.05616","0.26331"
"204.98400","17.08223","0.26604"
"205.29600","17.10818","0.26913"
"205.60800","17.13419","0.27275"
"205.92000","17.16014","0.27598"
"206.23200","17.18614","0.28005"
"206.54400","17.21215","0.28442"
"206.85600","17.23816","0.28864"
"207.16800","17.26423","0.29173"
"207.48000","17.29012","0.29413"
"207.79200","17.31618","0.29747"
"208.10400","17.34213","0.30041"
"208.41600","17.36820","0.30268"
"208.72800","17.39427","0.30641"
"209.04000","17.42016","0.30861"
"209.35200","17.44623","0.31248"
"209.66400","17.47212","0.31712"
"209.97600","17.49818","0.32084"
"210.28800","17.52419","0.32707"
"210.60000","17.55020","0.33448"
"210.91200","17.57615","0.34013"
"211.22400","17.60210","0.34600"
"211.53600","17.62823","0.35226"
"211.84800","17.65417","0.35579"
"212.16000","17.68018","0.35914"
"212.47200","17.70619","0.36183"
"212.78400","17.73214","0.36327"
"213.09600","17.75815","0.36418"
"213.40800","17.78410","0.36504"
"213.72000","17.81017","0.36626"
"214.03200","17.83617","0.36707"
"214.34400","17.86218","0.36844"
"214.65600","17.88819","0.37050"
"214.96800","17.91414","0.37342"
"215.28000","17.94015","0.37639"
"215.59200","17.96616","0.38119"
"215.90400","17.99222","0.38675"
"216.21600","18.01817","0.39324"
"216.52800","18.04418","0.39926"
"216.84000","18.07019","0.40477"
"217.15200","18.09608","0.40984"
"217.46400","18.12221","0.41349"
"217.77600","18.14816","0.41800"
"218.08800","18.17416","0.42196"
"218.40000","18.20017","0.42644"
"218.71200","18.22612","0.43087"
"219.02400","18.25219","0.43537"
"219.33600","18.27814","0.43990"
"219.64800","18.30421","0.44395"
"219.96000","18.33015","0.44688"
"220.27200","18.35610","0.44975"
"220.58400","18.38217","0.45315"
"220.89600","18.40812","0.45576"
"221.20800","18.43419","0.45868"
"221.52000","18.46014","0.46131"
"221.83200","18.48615","0.46454"
"222.14400","18.51215","0.46903"
"222.45600","18.53816","0.47315"
"222.76800","18.56417","0.47716"
"223.08000","18.59018","0.48210"
"223.39200","18.61625","0.48735"
"223.70400","18.64214","0.49210"
"224.01600","18.66814","0.49782"
"224.32800","18.69421","0.50262"
"224.64000","18.72016","0.50738"
"224.95200","18.74617","0.51042"
"225.26400","18.77212","0.51291"
"225.57600","18.79819","0.51408"
"225.88800","18.82420","0.44522"
"226.20000","18.85015","0.44840"
"226.51200","18.87621","0.45097"
"226.82400","18.90210","0.45603"
"227.13600","18.92817","0.46042"
"227.44800","18.95412","0.46656"
"227.76000","18.98013","0.47413"
"228.07200","19.00614","0.48210"
"228.38400","19.03220","0.49109"
"228.69600","19.05815","0.49815"
"229.00800","19.08410","0.50379"
"229.32000","19.11023","0.50801"
"229.63200","19.13618","0.51138"
"229.94400","19.16219","0.51466"
"230.25600","19.18820","0.51982"
"230.56800","19.21414","0.52735"
"230.88000","19.24021","0.53611"
"231.19200","19.26610","0.54384"
"231.50400","19.29217","0.54902"
"231.81600","19.31818","0.55583"
"232.12800","19.34419","0.56188"
"232.44000","19.37020","0.56801"
"232.75200","19.39614","0.57088"
"233.06400","19.42215","0.57294"
"233.37600","19.44816","0.57442"
"233.68800","19.47423","0.57653"
"234.00000","19.50024","0.57893"
"234.31200","19.52612","0.58192"
"234.62400","19.55219","0.58505"
"234.93600","19.57808","0.58945"
"235.24800","19.60421","0.59626"
"235.56000","19.63022","0.60552"
"235.87200","19.65617","0.61195"
"236.18400","19.68218","0.61656"
"236.49600","19.70812","0.61941"
"236.80800","19.73419","0.62398"
"237.12000","19.76020","0.63059"
"237.43200","19.78621","0.63724"
"237.74400","19.81222","0.64300"
"238.05600","19.83822","0.64966"
"238.36800","19.86418","0.65513"
"238.68000","19.89012","0.65828"
"238.99200","19.91625","0.66139"
"239.30400","19.94220","0.66333"
"239.61600","19.96821","0.66516"
"239.92800","19.99422","0.66670"
"240.24000","20.02017","0.66856"
"240.55200","20.04618","0.67133"
"240.86400","20.07212","0.67589"
"241.17600","20.09819","0.68064"
"241.48800","20.12414","0.68642"
"241.80000","20.15015","0.69365"
"242.11200","20.17616","0.70074"
"242.42400","20.20210","0.70716"
"242.73600","20.22824","0.71373"
"243.04800","20.25412","0.71982"
"243.36000","20.28013","0.72377"
"243.67200","20.30614","0.72599"
"243.98400","20.33209","0.72969"
"244.29600","20.35822","0.73556"
"244.60800","20.38416","0.74154"
"244.92000","20.41023","0.74809"
"245.23200","20.43618","0.75317"
"245.54400","20.46219","0.46534"
"245.85600","20.48820","0.46322"
"246.16800","20.51415","0.46351"
"246.48000","20.54022","0.46746"
"246.79200","20.56610","0.47430"
"247.10400","20.59223","0.48270"
"247.41600","20.61818","0.49635"
"247.72800","20.64419","0.50572"
"248.04000","20.67026","0.50943"
"248.35200","20.69615","0.50889"
"248.66400","20.72215","0.51112"
"248.97600","20.74810","0.51325"
"249.28800","20.77417","0.51774"
"249.60000","20.80018","0.53075"
"249.91200","20.82613","0.54920"
"250.22400","20.85220","0.55859"
"250.53600","20.87809","0.55991"
"250.84800","20.90421","0.56138"
"251.16000","20.93016","0.56651"
"251.47200","20.95623","0.57144"
"251.78400","20.98224","0.57674"
"252.09600","21.00813","0.58094"
"252.40800","21.03420","0.58154"
"252.72000","21.06009","0.58326"
"253.03200","21.08621","0.59116"
"253.34400","21.11222","0.60518"
"253.65600","21.13817","0.61638"
"253.96800","21.16418","0.61744"
"254.28000","21.19013","0.61903"
"254.59200","21.21620","0.62428"
"254.90400","21.24215","0.63675"
"255.21600","21.26821","0.64626"
"255.52800","21.29416","0.64738"
"255.84000","21.32011","0.65128"
"256.15200","21.34612","0.65772"
"256.46400","21.37207","0.66311"
"256.77600","21.39813","0.66387"
"257.08800","21.42414","0.66442"
"257.40000","21.45015","0.66648"
"257.71200","21.47622","0.67108"
"258.02400","21.50211","0.67331"
"258.33600","21.52812","0.67496"
"258.64800","21.55419","0.68198"
"258.96000","21.58019","0.69201"
"259.27200","21.60614","0.69527"
"259.58400","21.63209","0.69969"
"259.89600","21.65816","0.70981"
"260.20800","21.68417","0.71791"
"260.52000","21.71024","0.72005"
"260.83200","21.73619","0.72314"
"261.14400","21.76219","0.72704"
"261.45600","21.78820","0.72948"
"261.76800","21.81415","0.73172"
"262.08000","21.84022","0.74079"
"262.39200","21.86611","0.75034"
"262.70400","21.89218","0.75277"
"263.01600","21.91818","0.75950"
"263.32800","21.94413","0.76584"
"263.64000","21.97020","0.76833"
"263.95200","21.99615","0.77060"
"264.26400","22.02222","0.77368"
"264.57600","22.04811","0.77516"
"264.88800","22.07417","0.77654"
"265.20000","22.10018","0.77954"
"265.51200","22.12619","0.78213"
"265.82400","22.15220","0.78341"
"266.13600","22.17815","0.78893"
"266.44800","22.20422","0.79292"
"266.76000","22.23017","0.79796"
"267.07200","22.25617","0.80704"
"267.38400","22.28224","0.81081"
"267.69600","22.30819","0.81480"
"268.00800","22.33420","0.81880"
"268.32000","22.36015","0.82085"
"268.63200","22.38616","0.81611"
"268.94400","22.41217","0.76933"
"269.25600","22.43818","0.77091"
"269.56800","22.46418","0.77181"
"269.88000","22.49007","0.77425"
"270.19200","22.51620","0.77642"
"270.50400","22.54215","0.77726"
"270.81600","22.56816","0.77934"
"271.12800","22.59417","0.78283"
"271.44000","22.62017","0.78481"
"271.75200","22.64618","0.78878"
"272.06400","22.67207","0.79676"
"272.37600","22.69820","0.80094"
"272.68800","22.72415","0.80727"
"273.00000","22.75022","0.81277"
"273.31200","22.77622","0.81516"
"273.62400","22.80211","0.81887"
"273.93600","22.82818","0.82295"
"274.24800","22.85413","0.82596"
"274.56000","22.88014","0.83164"
"274.87200","22.90621","0.83805"
"275.18400","22.93216","0.84466"
"275.49600","22.95822","0.85355"
"275.80800","22.98411","0.85871"
"276.12000","23.01018","0.86339"
"276.43200","23.03619","0.43919"
"276.74400","23.06220","0.43616"
"277.05600","23.08821","0.43655"
"277.36800","23.11416","0.43848"
"277.68000","23.14016","0.44123"
"277.99200","23.16611","0.44377"
"278.30400","23.19224","0.44525"
"278.61600","23.21819","0.44669"
"278.92800","23.24420","0.44749"
"279.24000","23.27020","0.44895"
"279.55200","23.29616","0.44901"
"279.86400","23.32216","0.45023"
"280.17600","23.34817","0.44957"
"280.48800","23.37418","0.44650"
"280.80000","23.40019","0.44878"
"281.11200","23.42614","0.45105"
"281.42400","23.45215","0.45423"
"281.73600","23.47815","0.45727"
"282.04800","23.50416","0.46042"
"282.36000","23.53017","0.46328"
"282.67200","23.55612","0.46579"
"282.98400","23.58219","0.46777"
"283.29600","23.60820","0.46904"
"283.60800","23.63420","0.34189"
"283.92000","23.66015","0.34652"
"284.23200","23.68616","0.35091"
"284.54400","23.71217","0.35339"
"284.85600","23.73812","0.35544"
"285.16800","23.76418","0.36025"
"285.48000","23.79013","0.36263"
"285.79200","23.81621","0.36377"
"286.10400","23.84215","0.36478"
"286.41600","23.86816","0.36520"
"286.72800","23.89417","0.36567"
"287.04000","23.92018","0.36650"
"287.35200","23.94625","0.36833"
"287.66400","23.97207","0.36987"
"287.97600","23.99821","0.37221"
"288.28800","24.02415","0.37475"
"288.60000","24.05016","0.37839"
"288.91200","24.07623","0.38110"
"289.22400","24.10218","0.38546"
"289.53600","24.12819","0.38805"
"289.84800","24.15413","0.39229"
"290.16000","24.18020","0.39480"
"290.47200","24.20615","0.39744"
"290.78400","24.23216","0.39979"
"291.09600","24.25823","0.40126"
"291.40800","24.28411","0.40357"
"291.72000","24.31018","0.40595"
"292.03200","24.33613","0.40724"
"292.34400","24.36214","0.40967"
"292.65600","24.38821","0.41117"
"292.96800","24.41416","0.41288"
"293.28000","24.44017","0.26882"
"293.59200","24.46612","0.26467"
"293.90400","24.49218","0.26493"
"294.21600","24.51819","0.26865"
"294.52800","24.54420","0.27285"
"294.84000","24.57021","0.27914"
"295.15200","24.59616","0.28274"
"295.46400","24.62217","0.28627"
"295.77600","24.64812","0.29074"
"296.08800","24.67418","0.29435"
"296.40000","24.70019","0.29699"
"296.71200","24.72620","0.29832"
"297.02400","24.75221","0.30003"
"297.33600","24.77810","0.30148"
"297.64800","24.80423","0.30288"
"297.96000","24.83018","0.30425"
"298.27200","24.85618","0.30491"
"298.58400","24.88219","0.30574"
"298.89600","24.90814","0.30746"
"299.20800","24.93415","0.30808"
"299.52000","24.96010","0.30925"
"299.83200","24.98623","0.31189"
"300.14400","25.01217","0.31524"
"300.45600","25.03812","0.31704"
"300.76800","25.06419","0.32062"
"301.08000","25.09014","0.32454"
"301.39200","25.11615","0.32767"
"301.70400","25.14215","0.33131"
"302.01600","25.16816","0.33535"
"302.32800","25.19417","0.33829"
"302.64000","25.22018","0.34166"
"302.95200","25.24619","0.34480"
"303.26400","25.27214","0.34648"
"303.57600","25.29821","0.34820"
"303.88800","25.32415","0.35129"
"304.20000","25.35016","0.35264"
"304.51200","25.37617","0.35430"
"304.82400","25.40218","0.35589"
"305.13600","25.42825","0.35747"
"305.44800","25.45414","0.35860"
"305.76000","25.48021","0.36071"
"306.07200","25.50615","0.36159"
"306.38400","25.53216","0.36247"
"306.69600","25.55817","0.36347"
"307.00800","25.58412","0.36392"
"307.32000","25.61025","0.36431"
"307.63200","25.63614","0.36459"
"307.94400","25.66215","0.36483"
"308.25600","25.68815","0.36521"
"308.56800","25.71416","0.36566"
"308.88000","25.74023","0.36562"
"309.19200","25.76618","0.36598"
"309.50400","25.79219","0.36680"
"309.81600","25.81814","0.36711"
"310.12800","25.84414","0.36796"
"310.44000","25.87016","0.36845"
"310.75200","25.89616","0.36977"
"311.06400","25.92217","0.37087"
"311.37600","25.94812","0.37225"
"311.68800","25.97419","0.37389"
"312.00000","26.00020","0.37525"
"312.31200","26.02614","0.37736"
"312.62400","26.05221","0.37947"
"312.93600","26.07810","0.38215"
"313.24800","26.10417","0.38445"
"313.56000","26.13012","0.38720"
"313.87200","26.15619","0.38937"
"314.18400","26.18214","0.39261"
"314.49600","26.20814","0.08704"
"314.80800","26.23415","0.03561"
"315.12000","26.26010","0.03026"
"315.43200","26.28617","0.03461"
"315.74400","26.31218","0.05376"
"316.05600","26.33819","0.03531"
"316.36800","26.36420","0.04618"
"316.68000","26.39009","0.03925"
"316.99200","26.41615","0.05449"
"317.30400","26.44210","0.04159"
"317.61600","26.46817","0.05142"
"317.92800","26.49418","0.04614"
"318.24000","26.52013","0.05211"
"318.55200","26.54620","0.04966"
"318.86400","26.57208","0.05285"
"319.17600","26.59821","0.05350"
"319.48800","26.62416","0.05219"
"319.80000","26.65023","0.05545"
"320.11200","26.67624","0.05249"
"320.42400","26.70213","0.05686"
"320.73600","26.72813","0.05494"
"321.04800","26.75408","0.05744"
"321.36000","26.78021","0.05570"
"321.67200","26.80622","0.05679"
"321.98400","26.83217","0.05754"
"322.29600","26.85823","0.05719"
"322.60800","26.88412","0.05833"
"322.92000","26.91019","0.05736"
"323.23200","26.93614","0.05919"
"323.54400","26.96221","0.05918"
"323.85600","26.98822","0.05983"
"324.16800","27.01411","0.06006"
"324.48000","27.04018","0.06007"
"324.79200","27.06612","0.06130"
"325.10400","27.09225","0.06206"
"325.41600","27.11820","0.06254"
"325.72800","27.14415","0.06281"
"326.04000","27.17016","0.06317"
"326.35200","27.19617","0.06357"
"326.66400","27.22223","0.06460"
"326.97600","27.24812","0.06549"
"327.28800","27.27413","0.06608"
"327.60000","27.30014","0.06685"
"327.91200","27.32609","0.06725"
"328.22400","27.35222","0.06788"
"328.53600","27.37816","0.06913"
"328.84800","27.40423","0.06981"
"329.16000","27.43012","0.07088"
"329.47200","27.45619","0.07189"
"329.78400","27.48220","0.07248"
"330.09600","27.50815","0.07321"
"330.40800","27.53428","0.07404"
"330.72000","27.56011","0.07472"
"331.03200","27.58623","0.07555"
"331.34400","27.61218","0.07690"
"331.65600","27.63813","0.07783"
"331.96800","27.66420","0.07909"
"332.28000","27.69015","0.07963"
"332.59200","27.71622","0.08070"
"332.90400","27.74211","0.08264"
"333.21600","27.76818","0.08413"
"333.52800","27.79418","0.08531"
"333.84000","27.82013","0.07889"
"334.15200","27.84626","0.05935"
"334.46400","27.87215","0.05280"
"334.77600","27.89821","0.05276"
"335.08800","27.92416","0.05181"
"335.40000","27.95017","0.05249"
"335.71200","27.97624","0.05260"
"336.02400","28.00213","0.05333"
"336.33600","28.02814","0.05325"
"336.64800","28.05409","0.05354"
"336.96000","28.08021","0.05432"
"337.27200","28.10622","0.05450"
"337.58400","28.13223","0.05437"
"337.89600","28.15824","0.05407"
"338.20800","28.18413","0.05342"
"338.52000","28.21020","0.05352"
"338.83200","28.23609","0.05315"
"339.14400","28.26216","0.05360"
"339.45600","28.28822","0.05386"
"339.76800","28.31417","0.05403"
"340.08000","28.34018","0.05391"
"340.39200","28.36607","0.05395"
"340.70400","28.39220","0.05468"
"341.01600","28.41821","0.05465"
"341.32800","28.44421","0.05469"
"341.64000","28.47016","0.05487"
"341.95200","28.49611","0.05558"
"342.26400","28.52218","0.05568"
"342.57600","28.54813","0.05515"
"342.88800","28.57420","0.05527"
"343.20000","28.60020","0.05566"
"343.51200","28.62615","0.05570"
"343.82400","28.65216","0.05591"
"344.13600","28.67811","0.05537"
"344.44800","28.70418","0.05599"
"344.76000","28.73019","0.05582"
"345.07200","28.75620","0.05579"
"345.38400","28.78220","0.05550"
"345.69600","28.80809","0.05573"
"346.00800","28.83416","0.05551"
"346.32000","28.86011","0.05445"
"346.63200","28.88618","0.05484"
"346.94400","28.91219","0.05493"
"347.25600","28.93819","0.05508"
"347.56800","28.96420","0.05472"
"347.88000","28.99015","0.05502"
"348.19200","29.01622","0.05503"
"348.50400","29.04217","0.05483"
"348.81600","29.06818","0.05490"
"349.12800","29.09413","0.05474"
"349.44000","29.12013","0.05540"
"349.75200","29.14620","0.05493"
"350.06400","29.17215","0.05495"
"350.37600","29.19822","0.05518"
"350.68800","29.22417","0.05562"
"351.00000","29.25011","0.05544"
"351.31200","29.27618","0.05596"
"351.62400","29.30214","0.05554"
"351.93600","29.32820","0.05580"
"352.24800","29.35415","0.05596"
"352.56000","29.38022","0.05561"
"352.87200","29.40617","0.05608"
"353.18400","29.43218","0.05581"
"353.49600","29.45818","0.05588"
"353.80800","29.48413","0.05606"
"354.12000","29.51020","0.05636"
"354.43200","29.53615","0.05655"
"354.74400","29.56216","0.05670"
"355.05600","29.58823","0.05643"
"355.36800","29.61412","0.05631"
"355.68000","29.64018","0.05666"
"355.99200","29.66613","0.05697"
"356.30400","29.69220","0.05718"
"356.61600","29.71809","0.05693"
"356.92800","29.74416","0.05708"
"357.24000","29.77023","0.05686"
"357.55200","29.79618","0.05708"
"357.86400","29.82218","0.05710"
"358.17600","29.84813","0.05725"
"358.48800","29.87420","0.05713"
"358.80000","29.90015","0.05773"
"359.11200","29.92622","0.05739"
"359.42400","29.95217","0.05767"
"359.73600","29.97812","0.05773"
"360.04800","30.00418","0.05724"
"360.36000","30.03013","0.05734"
"360.67200","30.05620","0.05763"
"360.98400","30.08221","0.05757"
"361.29600","30.10816","0.05778"
"361.60800","30.13416","0.05783"
"361.92000","30.16011","0.05779"
"362.23200","30.18618","0.05784"
"362.54400","30.21219","0.05778"
"362.85600","30.23820","0.05796"
"363.16800","30.26421","0.05809"
"363.48000","30.29016","0.05847"
"363.79200","30.31616","0.05838"
"364.10400","30.34211","0.05821"
"364.41600","30.36824","0.05790"
"364.72800","30.39419","0.05855"
"365.04000","30.42014","0.05852"
"365.35200","30.44621","0.05797"
"365.66400","30.47216","0.05832"
"365.97600","30.49822","0.05821"
"366.28800","30.52417","0.05845"
"366.60000","30.55018","0.05868"
"366.91200","30.57625","0.05848"
"367.22400","30.60214","0.05854"
"367.53600","30.62815","0.05839"
"367.84800","30.65415","0.05886"
"368.16000","30.68022","0.05873"
"368.47200","30.70617","0.05893"
"368.78400","30.73218","0.05927"
"369.09600","30.75819","0.05903"
"369.40800","30.78420","0.05917"
"369.72000","30.81026","0.05945"
"370.03200","30.83615","0.05959"
"370.34400","30.86210","0.05984"
"370.65600","30.88817","0.05988"
"370.96800","30.91412","0.06004"
"371.28000","30.94019","0.06014"
"371.59200","30.96608","0.05999"
"371.90400","30.99221","0.06079"
"372.21600","31.01815","0.06059"
"372.52800","31.04410","0.06025"
"372.84000","31.07017","0.05959"
"373.15200","31.09618","0.05990"
"373.46400","31.12225","0.06019"
"373.77600","31.14814","0.06058"
"374.08800","31.17414","0.06025"
"374.40000","31.20015","0.06098"
"374.71200","31.22616","0.06093"
"375.02400","31.25217","0.06086"
"375.33600","31.27811","0.06101"
"375.64800","31.30418","0.06111"
"375.96000","31.33014","0.06125"
"376.27200","31.35620","0.06164"
"376.58400","31.38221","0.06239"
"376.89600","31.40816","0.06203"
"377.20800","31.43423","0.06238"
"377.52000","31.46011","0.06252"
"377.83200","31.48618","0.06294"
"378.14400","31.51213","0.06366"
"378.45600","31.53820","0.06343"
"378.76800","31.56421","0.06340"
"379.08000","31.59010","0.06402"
"379.39200","31.61617","0.06343"
"379.70400","31.64212","0.06356"
"380.01600","31.66818","0.06398"
"380.32800","31.69419","0.06433"
"380.64000","31.72020","0.06395"
"380.95200","31.74621","0.06392"
"381.26400","31.77210","0.06369"
"381.57600","31.79816","0.06395"
"381.88800","31.82417","0.06418"
"382.20000","31.85018","0.06429"
"382.51200","31.87619","0.06474"
"382.82400","31.90214","0.06471"
"383.13600","31.92815","0.06493"
"383.44800","31.95410","0.06538"
"383.76000","31.98022","0.06534"
"384.07200","32.00618","0.06620"
"384.38400","32.03218","0.06620"
"384.69600","32.05819","0.06704"
"385.00800","32.08414","0.06767"
"385.32000","32.11015","0.06804"
"385.63200","32.13616","0.06819"
"385.94400","32.16222","0.06816"
"386.25600","32.18818","0.06786"
"386.56800","32.21418","0.06900"
"386.88000","32.24019","0.06901"
"387.19200","32.26614","0.06965"
"387.50400","32.29214","0.06994"
"387.81600","32.31816","0.07056"
"388.12800","32.34416","0.07122"
"388.44000","32.37017","0.07121"
"388.75200","32.39606","0.07085"
"389.06400","32.42219","0.07150"
"389.37600","32.44814","0.07245"
"389.68800","32.47421","0.07263"
"390.00000","32.50021","0.07355"
"390.31200","32.52616","0.07324"
"390.62400","32.55223","0.07386"
"390.93600","32.57812","0.07445"
"391.24800","32.60425","0.07373"
"391.56000","32.63014","0.07411"
"391.87200","32.65614","0.07453"
"392.18400","32.68216","0.07489"
"392.49600","32.70816","0.07457"
"392.80800","32.73423","0.07521"
"393.12000","32.76012","0.07559"
"393.43200","32.78625","0.07618"
"393.74400","32.81214","0.07606"
"394.05600","32.83814","0.07602"
"394.36800","32.86421","0.07650"
"394.68000","32.89016","0.07726"
"394.99200","32.91617","0.07759"
"395.30400","32.94212","0.07848"
"395.61600","32.96825","0.07807"
"395.92800","32.99414","0.07780"
"396.24000","33.02014","0.07800"
"396.55200","33.04621","0.07797"
"396.86400","33.07216","0.07820"
"397.17600","33.09817","0.07910"
"397.48800","33.12412","0.07995"
"397.80000","33.15012","0.08097"
"398.11200","33.17625","0.08094"
"398.42400","33.20214","0.08137"
"398.73600","33.22821","0.08225"
"399.04800","33.25410","0.08311"
"399.36000","33.28023","0.08331"
"399.67200","33.30618","0.08377"
"399.98400","33.33219","0.08470"
"400.29600","33.35825","0.08430"
"400.60800","33.38414","0.08550"
"400.92000","33.41015","0.08613"
"401.23200","33.43610","0.08677"
"401.54400","33.46217","0.08690"
"401.85600","33.48818","0.08704"
"402.16800","33.51419","0.08777"
"402.48000","33.54013","0.08926"
"402.79200","33.56608","0.08974"
"403.10400","33.59221","0.08997"
"403.41600","33.61816","0.09091"
"403.72800","33.64417","0.09037"
"404.04000","33.67023","0.09102"
"404.35200","33.69619","0.09162"
"404.66400","33.72213","0.09247"
"404.97600","33.74808","0.09310"
"405.28800","33.77421","0.09425"
"405.60000","33.80022","0.09490"
"405.91200","33.82617","0.09626"
"406.22400","33.85223","0.09725"
"406.53600","33.87812","0.09625"
"406.84800","33.90413","0.09737"
"407.16000","33.93014","0.09888"
"407.47200","33.95615","0.09927"
"407.78400","33.98216","0.09960"
"408.09600","34.00817","0.09960"
"408.40800","34.03417","0.10018"
"408.72000","34.06012","0.10090"
"409.03200","34.08619","0.10151"
"409.34400","34.11220","0.10170"
"409.65600","34.13815","0.10256"
"409.96800","34.16416","0.10368"
"410.28000","34.19011","0.10426"
"410.59200","34.21617","0.10490"
"410.90400","34.24212","0.10496"
"411.21600","34.26819","0.10376"
"411.52800","34.29420","0.10363"
"411.84000","34.32015","0.10416"
"412.15200","34.34621","0.10407"
"412.46400","34.37217","0.10472"
"412.77600","34.39817","0.10483"
"413.08800","34.42412","0.10613"
"413.40000","34.45013","0.10693"
"413.71200","34.47614","0.10729"
"414.02400","34.50215","0.10851"
"414.33600","34.52821","0.10996"
"414.64800","34.55410","0.11035"
"414.96000","34.58023","0.11104"
"415.27200","34.60618","0.10998"
"415.58400","34.63213","0.10914"
"415.89600","34.65820","0.10838"
"416.20800","34.68415","0.10796"
"416.52000","34.71021","0.10907"
"416.83200","34.73610","0.11036"
"417.14400","34.76217","0.11099"
"417.45600","34.78812","0.11280"
"417.76800","34.81413","0.11340"
"418.08000","34.84026","0.11534"
"418.39200","34.86615","0.11605"
"418.70400","34.89222","0.11831"
"419.01600","34.91816","0.11940"
"419.32800","34.94417","0.12031"
"419.64000","34.97018","0.12204"
"419.95200","34.99613","0.12291"
"420.26400","35.02219","0.12377"
"420.57600","35.04815","0.12487"
"420.88800","35.07415","0.12537"
"421.20000","35.10016","0.12657"
"421.51200","35.12617","0.12830"
"421.82400","35.15224","0.12778"
"422.13600","35.17813","0.12747"
"422.44800","35.20420","0.12823"
"422.76000","35.23014","0.12304"
"423.07200","35.25615","0.12449"
"423.38400","35.28222","0.12495"
"423.69600","35.30817","0.12662"
"424.00800","35.33418","0.12702"
"424.32000","35.36013","0.12806"
"424.63200","35.38620","0.13060"
"424.94400","35.41214","0.13303"
"425.25600","35.43821","0.13456"
"425.56800","35.46422","0.13703"
"425.88000","35.49011","0.13864"
"426.19200","35.51618","0.14048"
"426.50400","35.54213","0.14171"
"426.81600","35.56820","0.14296"
"427.12800","35.59420","0.14420"
"427.44000","35.62015","0.14457"
"427.75200","35.64616","0.14537"
"428.06400","35.67217","0.14572"
"428.37600","35.69818","0.14662"
"428.68800","35.72419","0.14733"
"429.00000","35.75026","0.14769"
"429.31200","35.77620","0.14808"
"429.62400","35.80215","0.14899"
"429.93600","35.82816","0.14932"
"430.24800","35.85411","0.15020"
"430.56000","35.88018","0.15090"
"430.87200","35.90619","0.15112"
"431.18400","35.93219","0.15204"
"431.49600","35.95820","0.15271"
"431.80800","35.98415","0.15280"
"432.12000","36.01016","0.15294"
"432.43200","36.03611","0.15372"
"432.74400","36.06218","0.15383"
"433.05600","36.08818","0.15337"
"433.36800","36.11414","0.15429"
"433.68000","36.14021","0.15559"
"433.99200","36.16615","0.15713"
"434.30400","36.19222","0.15833"
"434.61600","36.21817","0.15919"
"434.92800","36.24417","0.16124"
"435.24000","36.27018","0.16363"
"435.55200","36.29613","0.16614"
"435.86400","36.32214","0.16926"
"436.17600","36.34809","0.16944"
"436.48800","36.37422","0.17156"
"436.80000","36.40017","0.17219"
"437.11200","36.42617","0.17461"
"437.42400","36.45224","0.17580"
"437.73600","36.47819","0.17852"
"438.04800","36.50420","0.17946"
"438.36000","36.53009","0.17420"
"438.67200","36.55616","0.17499"
"438.98400","36.58216","0.17783"
"439.29600","36.60812","0.18050"
"439.60800","36.63419","0.18513"
"439.92000","36.66013","0.18879"
"440.23200","36.68614","0.19232"
"440.54400","36.71215","0.19410"
"440.85600","36.73816","0.19610"
"441.16800","36.76423","0.19918"
"441.48000","36.79017","0.19979"
"441.79200","36.81618","0.20148"
"442.10400","36.84207","0.20270"
"442.41600","36.86820","0.20299"
"442.72800","36.89415","0.20445"
"443.04000","36.92015","0.20683"
"443.35200","36.94617","0.20763"
"443.66400","36.97217","0.20874"
"443.97600","36.99818","0.21052"
"444.28800","37.02407","0.21193"
"444.60000","37.05020","0.21308"
"444.91200","37.07615","0.21381"
"445.22400","37.10215","0.21506"
"445.53600","37.12817","0.21601"
"445.84800","37.15405","0.21594"
"446.16000","37.18018","0.21610"
"446.47200","37.20619","0.21693"
"446.78400","37.23220","0.21745"
"447.09600","37.25821","0.21816"
"447.40800","37.28415","0.21958"
"447.72000","37.31017","0.22084"
"448.03200","37.33611","0.22240"
"448.34400","37.36218","0.22428"
"448.65600","37.38813","0.22645"
"448.96800","37.41414","0.22933"
"449.28000","37.44021","0.23166"
"449.59200","37.46609","0.23337"
"449.90400","37.49216","0.23531"
"450.21600","37.51817","0.23624"
"450.52800","37.54424","0.23208"
"450.84000","37.57019","0.23067"
"451.15200","37.59614","0.23323"
"451.46400","37.62221","0.23587"
"451.77600","37.64815","0.23783"
"452.08800","37.67416","0.23911"
"452.40000","37.70017","0.24079"
"452.71200","37.72618","0.24268"
"453.02400","37.75219","0.24490"
"453.33600","37.77814","-0.00037"
"453.64800","37.80421","0.00609"
"453.96000","37.83015","0.01106"
"454.27200","37.85622","0.01339"
"454.58400","37.88217","0.01255"
"454.89600","37.90818","0.01323"
"455.20800","37.93419","0.01257"
"455.52000","37.96019","0.01263"
"455.83200","37.98620","0.01483"
"456.14400","38.01215","0.01243"
"456.45600","38.03816","0.01155"
"456.76800","38.06417","0.01136"
"457.08000","38.09018","0.01334"
"457.39200","38.11625","0.01172"
"457.70400","38.14213","0.01274"
"458.01600","38.16820","0.01186"
"458.32800","38.19415","0.01274"
"458.64000","38.22016","0.01247"
"458.95200","38.24623","0.01180"
"459.26400","38.27217","0.01181"
"459.57600","38.29824","0.01187"
"459.88800","38.32413","0.01246"
"460.20000","38.35020","0.01267"
"460.51200","38.37615","0.01241"
"460.82400","38.40216","0.01177"
"461.13600","38.42817","0.01153"
"461.44800","38.45412","0.01209"
"461.76000","38.48019","0.01186"
"462.07200","38.50613","0.01169"
"462.38400","38.53220","0.01250"
"462.69600","38.55821","0.01200"
"463.00800","38.58416","0.01235"
"463.32000","38.61017","0.01161"
"463.63200","38.63612","0.01194"
"463.94400","38.66219","0.01249"
"464.25600","38.68819","0.01201"
"464.56800","38.71420","0.01130"
"464.88000","38.74027","0.01261"
"465.19200","38.76616","0.01253"
"465.27400","38.77298","0.01257"