File: Force_trajectories/161217/Specimen_RawData_5.csv
End date,"12/17/2016"
Specimen label,"15CG_17"
Maximum Load,"0.12803",N

Time,Extension,Load
(s),(mm),(N)
"0.00000","0.00000","-0.00020"
"0.28200","0.02218","0.00034"
"0.56400","0.04717","0.00144"
"0.84600","0.07067","0.00209"
"1.12800","0.09411","0.00257"
"1.41000","0.11767","0.00318"
"1.69200","0.14110","0.00326"
"1.97400","0.16466","0.00353"
"2.25600","0.18810","0.00383"
"2.53800","0.21160","0.00398"
"2.82000","0.23509","0.00418"
"3.10200","0.25871","0.00427"
"3.38400","0.28209","0.00479"
"3.66600","0.30564","0.00472"
"3.94800","0.32914","0.00476"
"4.23000","0.35270","0.00518"
"4.51200","0.37614","0.00497"
"4.79400","0.39963","0.00521"
"5.07600","0.42313","0.00532"
"5.35800","0.44663","0.00556"
"5.64000","0.47013","0.00564"
"5.92200","0.49362","0.00578"
"6.20400","0.51718","0.00570"
"6.48600","0.54062","0.00602"
"6.76800","0.56411","0.00610"
"7.05000","0.58755","0.00580"
"7.33200","0.61111","0.00635"
"7.61400","0.63461","0.00597"
"7.89600","0.65816","0.00639"
"8.17800","0.68160","0.00625"
"8.46000","0.70510","0.00666"
"8.74200","0.72854","0.00651"
"9.02400","0.75215","0.00675"
"9.30600","0.77559","0.00661"
"9.58800","0.79915","0.00661"
"9.87000","0.82258","0.00667"
"10.15200","0.84614","0.00698"
"10.43400","0.86964","0.00717"
"10.71600","0.89314","0.00726"
"10.99800","0.91657","0.00719"
"11.28000","0.94013","0.00748"
"11.56200","0.96363","0.00754"
"11.84400","0.98707","0.00748"
"12.12600","1.01068","0.00767"
"12.40800","1.03412","0.00746"
"12.69000","1.05768","0.00773"
"12.97200","1.08111","0.00759"
"13.25400","1.10467","0.00811"
"13.53600","1.12811","0.00787"
"13.81800","1.15167","0.00828"
"14.10000","1.17510","0.00791"
"14.38200","1.19860","0.00800"
"14.66400","1.22210","0.00853"
"14.94600","1.24560","0.00849"
"15.22800","1.26909","0.00889"
"15.51000","1.29259","0.00887"
"15.79200","1.31609","0.00913"
"16.07400","1.33964","0.00915"
"16.35600","1.36308","0.00927"
"16.63800","1.38664","0.00930"
"16.92000","1.41014","0.00962"
"17.20200","1.43363","0.00978"
"17.48400","1.45707","0.00922"
"17.76600","1.48057","0.00977"
"18.04800","1.50413","0.00986"
"18.33000","1.52762","0.00997"
"18.61200","1.55118","0.01009"
"18.89400","1.57462","0.01022"
"19.17600","1.59817","0.01061"
"19.45800","1.62155","0.01032"
"19.74000","1.64511","0.01085"
"20.02200","1.66855","0.01065"
"20.30400","1.69216","0.01056"
"20.58600","1.71554","0.01148"
"20.86800","1.73916","0.01106"
"21.15000","1.76260","0.01117"
"21.43200","1.78615","0.01134"
"21.71400","1.80965","0.01123"
"21.99600","1.83315","0.01100"
"22.27800","1.85658","0.01110"
"22.56000","1.88014","0.01148"
"22.84200","1.90358","0.01141"
"23.12400","1.92714","0.01145"
"23.40600","1.95063","0.01137"
"23.68800","1.97413","0.01148"
"23.97000","1.99763","0.01185"
"24.25200","2.02107","0.01197"
"24.53400","2.04462","0.01244"
"24.81600","2.06806","0.01215"
"25.09800","2.09162","0.01253"
"25.38000","2.11505","0.01259"
"25.66200","2.13861","0.01294"
"25.94400","2.16205","0.01287"
"26.22600","2.18567","0.01336"
"26.50800","2.20910","0.01342"
"26.79000","2.23266","0.01412"
"27.07200","2.25610","0.01403"
"27.35400","2.27966","0.01421"
"27.63600","2.30309","0.01408"
"27.91800","2.32659","0.01443"
"28.20000","2.35015","0.01495"
"28.48200","2.37370","0.01500"
"28.76400","2.39714","0.01522"
"29.04600","2.42070","0.01538"
"29.32800","2.44420","0.01541"
"29.61000","2.46763","0.01611"
"29.89200","2.49113","0.01616"
"30.17400","2.51457","0.01625"
"30.45600","2.53813","0.01640"
"30.73800","2.56162","0.01670"
"31.02000","2.58518","0.01742"
"31.30200","2.60862","0.01741"
"31.58400","2.63211","0.01710"
"31.86600","2.65561","0.01763"
"32.14800","2.67911","0.01795"
"32.43000","2.70255","0.01854"
"32.71200","2.72610","0.01785"
"32.99400","2.74954","0.01769"
"33.27600","2.77316","0.01799"
"33.55800","2.79666","0.01853"
"33.84000","2.82015","0.01831"
"34.12200","2.84359","0.01902"
"34.40400","2.86709","0.01939"
"34.68600","2.89058","0.01917"
"34.96800","2.91408","0.01966"
"35.25000","2.93764","0.02014"
"35.53200","2.96108","0.01990"
"35.81400","2.98463","0.02010"
"36.09600","3.00813","0.02073"
"36.37800","3.03169","0.02033"
"36.66000","3.05507","0.02108"
"36.94200","3.07868","0.02169"
"37.22400","3.10206","0.02162"
"37.50600","3.12562","0.02209"
"37.78800","3.14911","0.02177"
"38.07000","3.17267","0.02264"
"38.35200","3.19611","0.02272"
"38.63400","3.21967","0.02271"
"38.91600","3.24310","0.02265"
"39.19800","3.26666","0.02384"
"39.48000","3.29010","0.02351"
"39.76200","3.31366","0.02356"
"40.04400","3.33709","0.02344"
"40.32600","3.36065","0.02334"
"40.60800","3.38409","0.02370"
"40.89000","3.40758","0.02401"
"41.17200","3.43114","0.02456"
"41.45400","3.45464","0.02462"
"41.73600","3.47814","0.02515"
"42.01800","3.50163","0.02493"
"42.30000","3.52513","0.02417"
"42.58200","3.54857","0.02499"
"42.86400","3.57213","0.02475"
"43.14600","3.59556","0.02475"
"43.42800","3.61912","0.02550"
"43.71000","3.64256","0.02520"
"43.99200","3.66612","0.02549"
"44.27400","3.68961","0.02525"
"44.55600","3.71317","0.02557"
"44.83800","3.73661","0.02605"
"45.12000","3.76010","0.02615"
"45.40200","3.78360","0.02654"
"45.68400","3.80716","0.02621"
"45.96600","3.83066","0.02708"
"46.24800","3.85415","0.02683"
"46.53000","3.87765","0.02716"
"46.81200","3.90109","0.02658"
"47.09400","3.92458","0.02550"
"47.37600","3.94808","0.02614"
"47.65800","3.97164","0.02609"
"47.94000","3.99508","0.02618"
"48.22200","4.01863","0.02652"
"48.50400","4.04213","0.02607"
"48.78600","4.06563","0.02667"
"49.06800","4.08907","0.02694"
"49.35000","4.11262","0.02734"
"49.63200","4.13600","0.02772"
"49.91400","4.15956","0.02742"
"50.19600","4.18305","0.02718"
"50.47800","4.20667","0.02745"
"50.76000","4.23011","0.02793"
"51.04200","4.25367","0.02830"
"51.32400","4.27710","0.02863"
"51.60600","4.30060","0.02777"
"51.88800","4.32410","0.02874"
"52.17000","4.34766","0.02876"
"52.45200","4.37115","0.02967"
"52.73400","4.39465","0.02901"
"53.01600","4.41815","0.02982"
"53.29800","4.44165","0.02994"
"53.58000","4.46520","0.02976"
"53.86200","4.48864","0.02994"
"54.14400","4.51214","0.03065"
"54.42600","4.53563","0.02982"
"54.70800","4.55913","0.03009"
"54.99000","4.58257","0.03034"
"55.27200","4.60619","0.02919"
"55.55400","4.62956","0.02958"
"55.83600","4.65312","0.02892"
"56.11800","4.67656","0.02864"
"56.40000","4.70017","0.02852"
"56.68200","4.72355","0.02916"
"56.96400","4.74717","0.02970"
"57.24600","4.77061","0.03013"
"57.52800","4.79410","0.03008"
"57.81000","4.81760","0.03058"
"58.09200","4.84110","0.03104"
"58.37400","4.86466","0.03074"
"58.65600","4.88815","0.03076"
"58.93800","4.91165","0.03138"
"59.22000","4.93515","0.03131"
"59.50200","4.95864","0.03115"
"59.78400","4.98208","0.03114"
"60.06600","5.00564","0.03182"
"60.34800","5.02908","0.03227"
"60.63000","5.05263","0.02670"
"60.91200","5.07613","0.01987"
"61.19400","5.09963","0.01863"
"61.47600","5.12313","0.01854"
"61.75800","5.14668","0.01910"
"62.04000","5.17012","0.01954"
"62.32200","5.19362","0.01973"
"62.60400","5.21712","0.02009"
"62.88600","5.24067","0.02061"
"63.16800","5.26411","0.02074"
"63.45000","5.28767","0.02191"
"63.73200","5.31110","0.02136"
"64.01400","5.33460","0.02212"
"64.29600","5.35810","0.02173"
"64.57800","5.38160","0.02130"
"64.86000","5.40515","0.02152"
"65.14200","5.42859","0.01922"
"65.42400","5.45215","0.01858"
"65.70600","5.47559","0.01840"
"65.98800","5.49914","0.01816"
"66.27000","5.52258","0.01756"
"66.55200","5.54608","0.01774"
"66.83400","5.56957","0.01822"
"67.11600","5.59313","0.01805"
"67.39800","5.61657","0.01821"
"67.68000","5.64013","0.01819"
"67.96200","5.66362","0.01828"
"68.24400","5.68718","0.01880"
"68.52600","5.71062","0.01905"
"68.80800","5.73412","0.01858"
"69.09000","5.75761","0.01960"
"69.37200","5.78111","0.01954"
"69.65400","5.80467","0.02010"
"69.93600","5.82816","0.01972"
"70.21800","5.85166","0.02061"
"70.50000","5.87510","0.02075"
"70.78200","5.89872","0.02134"
"71.06400","5.92209","0.02162"
"71.34600","5.94565","0.02114"
"71.62800","5.96909","0.02171"
"71.91000","5.99265","0.02207"
"72.19200","6.01608","0.02221"
"72.47400","6.03964","0.02290"
"72.75600","6.06308","0.02239"
"73.03800","6.08663","0.02316"
"73.32000","6.11007","0.02356"
"73.60200","6.13363","0.02292"
"73.88400","6.15707","0.02385"
"74.16600","6.18062","0.02401"
"74.44800","6.20412","0.02417"
"74.73000","6.22762","0.02478"
"75.01200","6.25106","0.02454"
"75.29400","6.27461","0.02452"
"75.57600","6.29811","0.02519"
"75.85800","6.32161","0.02493"
"76.14000","6.34510","0.02572"
"76.42200","6.36860","0.02573"
"76.70400","6.39216","0.02594"
"76.98600","6.41566","0.02620"
"77.26800","6.43915","0.02648"
"77.55000","6.46259","0.02709"
"77.83200","6.48615","0.02785"
"78.11400","6.50964","0.02757"
"78.39600","6.53314","0.02770"
"78.67800","6.55658","0.02764"
"78.96000","6.58008","0.02803"
"79.24200","6.60351","0.02839"
"79.52400","6.62713","0.02860"
"79.80600","6.65057","0.02853"
"80.08800","6.67413","0.02711"
"80.37000","6.69762","0.02745"
"80.65200","6.72112","0.02749"
"80.93400","6.74456","0.02810"
"81.21600","6.76812","0.02770"
"81.49800","6.79155","0.02859"
"81.78000","6.81505","0.02861"
"82.06200","6.83861","0.02973"
"82.34400","6.86205","0.03000"
"82.62600","6.88566","0.03000"
"82.90800","6.90916","0.03076"
"83.19000","6.93266","0.03010"
"83.47200","6.95609","0.03051"
"83.75400","6.97959","0.03136"
"84.03600","7.00309","0.03183"
"84.31800","7.02665","0.03120"
"84.60000","7.05008","0.03252"
"84.88200","7.07364","0.03247"
"85.16400","7.09714","0.03319"
"85.44600","7.12063","0.03318"
"85.72800","7.14407","0.03346"
"86.01000","7.16763","0.03369"
"86.29200","7.19113","0.03454"
"86.57400","7.21456","0.03445"
"86.85600","7.23812","0.03496"
"87.13800","7.26162","0.03608"
"87.42000","7.28518","0.03573"
"87.70200","7.30867","0.03552"
"87.98400","7.33217","0.03611"
"88.26600","7.35555","0.03622"
"88.54800","7.37910","0.03666"
"88.83000","7.40254","0.03659"
"89.11200","7.42616","0.03670"
"89.39400","7.44960","0.03715"
"89.67600","7.47315","0.03816"
"89.95800","7.49659","0.03842"
"90.24000","7.52015","0.03766"
"90.52200","7.54359","0.03807"
"90.80400","7.56720","0.03867"
"91.08600","7.59058","0.03908"
"91.36800","7.61414","0.03903"
"91.65000","7.63758","0.03797"
"91.93200","7.66119","0.03876"
"92.21400","7.68463","0.03930"
"92.49600","7.70813","0.03898"
"92.77800","7.73162","0.03963"
"93.06000","7.75512","0.03811"
"93.34200","7.77856","0.03850"
"93.62400","7.80212","0.03916"
"93.90600","7.82567","0.03810"
"94.18800","7.84911","0.03926"
"94.47000","7.87261","0.03974"
"94.75200","7.89610","0.04038"
"95.03400","7.91966","0.04078"
"95.31600","7.94310","0.04034"
"95.59800","7.96666","0.03857"
"95.88000","7.99009","0.03891"
"96.16200","8.01365","0.03946"
"96.44400","8.03703","0.04039"
"96.72600","8.06059","0.04049"
"97.00800","8.08408","0.04121"
"97.29000","8.10764","0.04169"
"97.57200","8.13108","0.04204"
"97.85400","8.15463","0.04261"
"98.13600","8.17807","0.04288"
"98.41800","8.20163","0.04314"
"98.70000","8.22513","0.04355"
"98.98200","8.24862","0.04390"
"99.26400","8.27206","0.04450"
"99.54600","8.29562","0.04497"
"99.82800","8.31912","0.04551"
"100.11000","8.34261","0.04569"
"100.39200","8.36611","0.04626"
"100.67400","8.38955","0.04570"
"100.95600","8.41310","0.04600"
"101.23800","8.43654","0.04679"
"101.52000","8.46016","0.04629"
"101.80200","8.48360","0.04657"
"102.08400","8.50715","0.04672"
"102.36600","8.53059","0.04728"
"102.64800","8.55415","0.04738"
"102.93000","8.57765","0.04754"
"103.21200","8.60114","0.04789"
"103.49400","8.62464","0.04826"
"103.77600","8.64808","0.04850"
"104.05800","8.67158","0.04879"
"104.34000","8.69513","0.04855"
"104.62200","8.71863","0.04856"
"104.90400","8.74213","0.04866"
"105.18600","8.76562","0.04888"
"105.46800","8.78912","0.04937"
"105.75000","8.81262","0.04854"
"106.03200","8.83612","0.04891"
"106.31400","8.85967","0.04912"
"106.59600","8.88311","0.04939"
"106.87800","8.90661","0.04975"
"107.16000","8.93011","0.04982"
"107.44200","8.95366","0.04984"
"107.72400","8.97710","0.05037"
"108.00600","9.00066","0.05040"
"108.28800","9.02409","0.05110"
"108.57000","9.04765","0.05106"
"108.85200","9.07103","0.05129"
"109.13400","9.09471","0.05126"
"109.41600","9.11814","0.05196"
"109.69800","9.14164","0.05193"
"109.98000","9.16508","0.05192"
"110.26200","9.18863","0.05225"
"110.54400","9.21213","0.05259"
"110.82600","9.23563","0.05178"
"111.10800","9.25913","0.05187"
"111.39000","9.28262","0.05253"
"111.67200","9.30612","0.05261"
"111.95400","9.32962","0.05321"
"112.23600","9.35318","0.05279"
"112.51800","9.37661","0.05314"
"112.80000","9.40011","0.05353"
"113.08200","9.42361","0.05348"
"113.36400","9.44711","0.05373"
"113.64600","9.47054","0.05462"
"113.92800","9.49410","0.05459"
"114.21000","9.51754","0.05367"
"114.49200","9.54109","0.04973"
"114.77400","9.56453","0.05000"
"115.05600","9.58815","0.05023"
"115.33800","9.61159","0.05055"
"115.62000","9.63514","0.04982"
"115.90200","9.65858","0.05035"
"116.18400","9.68214","0.04955"
"116.46600","9.70557","0.05032"
"116.74800","9.72913","0.05017"
"117.03000","9.75263","0.05055"
"117.31200","9.77613","0.05082"
"117.59400","9.79962","0.05111"
"117.87600","9.82318","0.05151"
"118.15800","9.84668","0.05166"
"118.44000","9.87012","0.05208"
"118.72200","9.89367","0.05257"
"119.00400","9.91711","0.05270"
"119.28600","9.94067","0.05308"
"119.56800","9.96410","0.05372"
"119.85000","9.98766","0.05377"
"120.13200","10.01110","0.05445"
"120.41400","10.03466","0.05448"
"120.69600","10.05809","0.05425"
"120.97800","10.08165","0.05457"
"121.26000","10.10509","0.05465"
"121.54200","10.12865","0.05470"
"121.82400","10.15208","0.05490"
"122.10600","10.17558","0.05516"
"122.38800","10.19914","0.05433"
"122.67000","10.22264","0.05480"
"122.95200","10.24613","0.05491"
"123.23400","10.26963","0.05511"
"123.51600","10.29313","0.05592"
"123.79800","10.31656","0.05657"
"124.08000","10.34018","0.05669"
"124.36200","10.36356","0.05759"
"124.64400","10.38718","0.05786"
"124.92600","10.41055","0.05833"
"125.20800","10.43411","0.05922"
"125.49000","10.45761","0.05963"
"125.77200","10.48116","0.06005"
"126.05400","10.50460","0.05922"
"126.33600","10.52816","0.06046"
"126.61800","10.55160","0.05839"
"126.90000","10.57515","0.05876"
"127.18200","10.59859","0.05900"
"127.46400","10.62215","0.05936"
"127.74600","10.64565","0.05985"
"128.02800","10.66914","0.06009"
"128.31000","10.69264","0.06110"
"128.59200","10.71614","0.06150"
"128.87400","10.73964","0.06176"
"129.15600","10.76307","0.06253"
"129.43800","10.78663","0.06301"
"129.72000","10.81007","0.06435"
"130.00200","10.83362","0.06406"
"130.28400","10.85706","0.06478"
"130.56600","10.88062","0.06370"
"130.84800","10.90412","0.06421"
"131.13000","10.92761","0.06253"
"131.41200","10.95105","0.06236"
"131.69400","10.97461","0.06406"
"131.97600","10.99811","0.06566"
"132.25800","11.02166","0.06654"
"132.54000","11.04510","0.06727"
"132.82200","11.06866","0.06752"
"133.10400","11.09209","0.06829"
"133.38600","11.11565","0.01996"
"133.66800","11.13915","0.01973"
"133.95000","11.16265","0.02152"
"134.23200","11.18608","0.02022"
"134.51400","11.20958","0.02134"
"134.79600","11.23308","0.02200"
"135.07800","11.25664","0.01974"
"135.36000","11.28013","0.02271"
"135.64200","11.30363","0.02169"
"135.92400","11.32719","0.02219"
"136.20600","11.35062","0.02289"
"136.48800","11.37412","0.02391"
"136.77000","11.39762","0.02333"
"137.05200","11.42112","0.02422"
"137.33400","11.44455","0.02525"
"137.61600","11.46811","0.02441"
"137.89800","11.49155","0.02644"
"138.18000","11.51511","0.02498"
"138.46200","11.53860","0.02702"
"138.74400","11.56216","0.02642"
"139.02600","11.58560","0.02701"
"139.30800","11.60910","0.02722"
"139.59000","11.63259","0.02737"
"139.87200","11.65609","0.02873"
"140.15400","11.67965","0.02792"
"140.43600","11.70314","0.02983"
"140.71800","11.72664","0.02957"
"141.00000","11.75008","0.02996"
"141.28200","11.77364","0.03099"
"141.56400","11.79713","0.03096"
"141.84600","11.82069","0.03182"
"142.12800","11.84407","0.03040"
"142.41000","11.86762","0.03249"
"142.69200","11.89106","0.03211"
"142.97400","11.91468","0.03255"
"143.25600","11.93812","0.03264"
"143.53800","11.96161","0.03334"
"143.82000","11.98505","0.03453"
"144.10200","12.00861","0.03462"
"144.38400","12.03211","0.03373"
"144.66600","12.05560","0.03439"
"144.94800","12.07910","0.03450"
"145.23000","12.10260","0.03520"
"145.51200","12.12609","0.03513"
"145.79400","12.14959","0.03567"
"146.07600","12.17309","0.03570"
"146.35800","12.19659","0.03643"
"146.64000","12.22014","0.03572"
"146.92200","12.24358","0.03649"
"147.20400","12.26714","0.03626"
"147.48600","12.29058","0.03586"
"147.76800","12.31419","0.03647"
"148.05000","12.33763","0.03570"
"148.33200","12.36113","0.03666"
"148.61400","12.38456","0.03681"
"148.89600","12.40812","0.03691"
"149.17800","12.43156","0.03800"
"149.46000","12.45512","0.03811"
"149.74200","12.47855","0.03930"
"150.02400","12.50217","0.03992"
"150.30600","12.52561","0.03980"
"150.58800","12.54917","0.04008"
"150.87000","12.57260","0.04013"
"151.15200","12.59616","0.04195"
"151.43400","12.61960","0.04067"
"151.71600","12.64316","0.04057"
"151.99800","12.66659","0.04039"
"152.28000","12.69015","0.04174"
"152.56200","12.71365","0.04164"
"152.84400","12.73708","0.04151"
"153.12600","12.76064","0.04138"
"153.40800","12.78408","0.04178"
"153.69000","12.80764","0.04075"
"153.97200","12.83113","0.04110"
"154.25400","12.85463","0.04192"
"154.53600","12.87807","0.04236"
"154.81800","12.90163","0.04284"
"155.10000","12.92506","0.04305"
"155.38200","12.94862","0.04321"
"155.66400","12.97212","0.04346"
"155.94600","12.99562","0.04336"
"156.22800","13.01905","0.04327"
"156.51000","13.04267","0.04408"
"156.79200","13.06611","0.04416"
"157.07400","13.08960","0.04489"
"157.35600","13.11310","0.04387"
"157.63800","13.13666","0.04422"
"157.92000","13.16016","0.04475"
"158.20200","13.18365","0.04482"
"158.48400","13.20721","0.04510"
"158.76600","13.23059","0.04427"
"159.04800","13.25414","0.04502"
"159.33000","13.27758","0.04458"
"159.61200","13.30114","0.04513"
"159.89400","13.32458","0.04567"
"160.17600","13.34813","0.04557"
"160.45800","13.37157","0.04654"
"160.74000","13.39513","0.04601"
"161.02200","13.41857","0.04642"
"161.30400","13.44212","0.04627"
"161.58600","13.46556","0.04622"
"161.86800","13.48912","0.04695"
"162.15000","13.51255","0.04705"
"162.43200","13.53611","0.04738"
"162.71400","13.55961","0.04769"
"162.99600","13.58311","0.04812"
"163.27800","13.60660","0.04818"
"163.56000","13.63010","0.04820"
"163.84200","13.65360","0.04826"
"164.12400","13.67710","0.04833"
"164.40600","13.70059","0.04864"
"164.68800","13.72409","0.04882"
"164.97000","13.74765","0.04900"
"165.25200","13.77108","0.04933"
"165.53400","13.79464","0.04929"
"165.81600","13.81808","0.04795"
"166.09800","13.84164","0.04761"
"166.38000","13.86507","0.04793"
"166.66200","13.88863","0.04789"
"166.94400","13.91213","0.04807"
"167.22600","13.93569","0.04848"
"167.50800","13.95912","0.04869"
"167.79000","13.98262","0.04883"
"168.07200","14.00612","0.04842"
"168.35400","14.02967","0.04859"
"168.63600","14.05311","0.04889"
"168.91800","14.07667","0.04919"
"169.20000","14.10017","0.04930"
"169.48200","14.12360","0.04967"
"169.76400","14.14710","0.04961"
"170.04600","14.17060","0.04988"
"170.32800","14.19410","0.05005"
"170.61000","14.21759","0.05037"
"170.89200","14.24115","0.04883"
"171.17400","14.26459","0.04895"
"171.45600","14.28815","0.04940"
"171.73800","14.31164","0.04894"
"172.02000","14.33514","0.04940"
"172.30200","14.35864","0.04930"
"172.58400","14.38213","0.04967"
"172.86600","14.40557","0.04973"
"173.14800","14.42913","0.05017"
"173.43000","14.45263","0.05032"
"173.71200","14.47618","0.05015"
"173.99400","14.49962","0.05012"
"174.27600","14.52312","0.05023"
"174.55800","14.54661","0.05029"
"174.84000","14.57017","0.05058"
"175.12200","14.59367","0.05076"
"175.40400","14.61717","0.05061"
"175.68600","14.64066","0.05119"
"175.96800","14.66410","0.05099"
"176.25000","14.68760","0.05136"
"176.53200","14.71110","0.05127"
"176.81400","14.73465","0.05177"
"177.09600","14.75815","0.05137"
"177.37800","14.78165","0.05143"
"177.66000","14.80509","0.05104"
"177.94200","14.82858","0.05127"
"178.22400","14.85208","0.05106"
"178.50600","14.87564","0.05086"
"178.78800","14.89901","0.05041"
"179.07000","14.92263","0.05053"
"179.35200","14.94607","0.04991"
"179.63400","14.96962","0.05019"
"179.91600","14.99312","0.05016"
"180.19800","15.01668","0.05040"
"180.48000","15.04006","0.05036"
"180.76200","15.06355","0.04988"
"181.04400","15.08705","0.05035"
"181.32600","15.11061","0.05056"
"181.60800","15.13417","0.05045"
"181.89000","15.15760","0.05030"
"182.17200","15.18116","0.05045"
"182.45400","15.20460","0.05076"
"182.73600","15.22821","0.05083"
"183.01800","15.25165","0.05136"
"183.30000","15.27515","0.05149"
"183.58200","15.29859","0.05160"
"183.86400","15.32215","0.05187"
"184.14600","15.34558","0.05176"
"184.42800","15.36920","0.05180"
"184.71000","15.39258","0.05163"
"184.99200","15.41613","0.05083"
"185.27400","15.43957","0.05097"
"185.55600","15.46313","0.05110"
"185.83800","15.48657","0.05143"
"186.12000","15.51018","0.05135"
"186.40200","15.53362","0.05191"
"186.68400","15.55712","0.05185"
"186.96600","15.58062","0.05170"
"187.24800","15.60411","0.05238"
"187.53000","15.62767","0.05203"
"187.81200","15.65117","0.05093"
"188.09400","15.67460","0.05138"
"188.37600","15.69810","0.05142"
"188.65800","15.72160","0.05142"
"188.94000","15.74509","0.05170"
"189.22200","15.76865","0.05177"
"189.50400","15.79209","0.05249"
"189.78600","15.81565","0.05228"
"190.06800","15.83908","0.05279"
"190.35000","15.86264","0.05257"
"190.63200","15.88608","0.05259"
"190.91400","15.90964","0.05312"
"191.19600","15.93307","0.05308"
"191.47800","15.95663","0.05360"
"191.76000","15.98013","0.05384"
"192.04200","16.00368","0.05398"
"192.32400","16.02718","0.05351"
"192.60600","16.05068","0.05315"
"192.88800","16.07412","0.05343"
"193.17000","16.09761","0.05331"
"193.45200","16.12111","0.05352"
"193.73400","16.14461","0.05395"
"194.01600","16.16817","0.05342"
"194.29800","16.19160","0.05370"
"194.58000","16.21510","0.05383"
"194.86200","16.23860","0.05394"
"195.14400","16.26216","0.05412"
"195.42600","16.28559","0.05420"
"195.70800","16.30909","0.05440"
"195.99000","16.33253","0.05470"
"196.27200","16.35608","0.05495"
"196.55400","16.37958","0.05526"
"196.83600","16.40314","0.05556"
"197.11800","16.42658","0.05640"
"197.40000","16.45019","0.05667"
"197.68200","16.47357","0.05723"
"197.96400","16.49713","0.05733"
"198.24600","16.52062","0.05720"
"198.52800","16.54412","0.05748"
"198.81000","16.56762","0.05807"
"199.09200","16.59112","0.05858"
"199.37400","16.61461","0.05905"
"199.65600","16.63811","0.05960"
"199.93800","16.66173","0.06000"
"200.22000","16.68511","0.05988"
"200.50200","16.70866","0.06030"
"200.78400","16.73210","0.06019"
"201.06600","16.75566","0.06022"
"201.34800","16.77909","0.06162"
"201.63000","16.80265","0.06152"
"201.91200","16.82609","0.06201"
"202.19400","16.84965","0.06243"
"202.47600","16.87302","0.06148"
"202.75800","16.89664","0.06096"
"203.04000","16.92008","0.06151"
"203.32200","16.94364","0.06115"
"203.60400","16.96707","0.06264"
"203.88600","16.99063","0.06224"
"204.16800","17.01407","0.06105"
"204.45000","17.03762","0.06393"
"204.73200","17.06112","0.06255"
"205.01400","17.08462","0.06450"
"205.29600","17.10812","0.06452"
"205.57800","17.13161","0.06490"
"205.86000","17.15517","0.06588"
"206.14200","17.17861","0.06655"
"206.42400","17.20217","0.06757"
"206.70600","17.22560","0.06727"
"206.98800","17.24916","0.06848"
"207.27000","17.27260","0.06804"
"207.55200","17.29622","0.06873"
"207.83400","17.31959","0.06987"
"208.11600","17.34309","0.06848"
"208.39800","17.36653","0.06882"
"208.68000","17.39014","0.06939"
"208.96200","17.41358","0.06981"
"209.24400","17.43714","0.07087"
"209.52600","17.46064","0.07045"
"209.80800","17.48413","0.07012"
"210.09000","17.50757","0.07074"
"210.37200","17.53107","0.07282"
"210.65400","17.55463","0.07285"
"210.93600","17.57806","0.07449"
"211.21800","17.60156","0.07470"
"211.50000","17.62506","0.07506"
"211.78200","17.64867","0.07567"
"212.06400","17.67211","0.07624"
"212.34600","17.69567","0.07681"
"212.62800","17.71911","0.07713"
"212.91000","17.74260","0.07858"
"213.19200","17.76604","0.07938"
"213.47400","17.78960","0.07961"
"213.75600","17.81310","0.07962"
"214.03800","17.83659","0.08071"
"214.32000","17.86009","0.08152"
"214.60200","17.88365","0.08174"
"214.88400","17.90714","0.08265"
"215.16600","17.93064","0.08299"
"215.44800","17.95408","0.08361"
"215.73000","17.97758","0.08327"
"216.01200","18.00107","0.08390"
"216.29400","18.02457","0.08563"
"216.57600","18.04819","0.08570"
"216.85800","18.07162","0.08621"
"217.14000","18.09518","0.08719"
"217.42200","18.11856","0.08752"
"217.70400","18.14218","0.08789"
"217.98600","18.16562","0.08880"
"218.26800","18.18917","0.08892"
"218.55000","18.21261","0.08894"
"218.83200","18.23611","0.08973"
"219.11400","18.25960","0.09014"
"219.39600","18.28310","0.09090"
"219.67800","18.30654","0.09151"
"219.96000","18.33015","0.09117"
"220.24200","18.35365","0.09203"
"220.52400","18.37715","0.09152"
"220.80600","18.40059","0.09101"
"221.08800","18.42414","0.08989"
"221.37000","18.44758","0.09020"
"221.65200","18.47114","0.09029"
"221.93400","18.49458","0.09085"
"222.21600","18.51813","0.09072"
"222.49800","18.54157","0.09092"
"222.78000","18.56513","0.09174"
"223.06200","18.58869","0.09215"
"223.34400","18.61212","0.09300"
"223.62600","18.63562","0.09315"
"223.90800","18.65906","0.09373"
"224.19000","18.68268","0.09412"
"224.47200","18.70611","0.09389"
"224.75400","18.72967","0.09430"
"225.03600","18.75311","0.08781"
"225.31800","18.77666","0.08700"
"225.60000","18.80010","0.08826"
"225.88200","18.82360","0.08973"
"226.16400","18.84703","0.08210"
"226.44600","18.87065","0.08010"
"226.72800","18.89409","0.08158"
"227.01000","18.91765","0.08043"
"227.29200","18.94109","0.08177"
"227.57400","18.96464","0.08326"
"227.85600","18.98808","0.08243"
"228.13800","19.01158","0.08496"
"228.42000","19.03507","0.08464"
"228.70200","19.05857","0.07715"
"228.98400","19.08213","0.07675"
"229.26600","19.10563","0.07793"
"229.54800","19.12912","0.07750"
"229.83000","19.15256","0.07936"
"230.11200","19.17612","0.08020"
"230.39400","19.19956","0.07995"
"230.67600","19.22311","0.08226"
"230.95800","19.24655","0.08172"
"231.24000","19.27017","0.08109"
"231.52200","19.29360","0.08287"
"231.80400","19.31716","0.08221"
"232.08600","19.34060","0.08217"
"232.36800","19.36416","0.08281"
"232.65000","19.38759","0.08167"
"232.93200","19.41109","0.08233"
"233.21400","19.43465","0.08323"
"233.49600","19.45820","0.08018"
"233.77800","19.48164","0.08107"
"234.06000","19.50514","0.08229"
"234.34200","19.52864","0.08237"
"234.62400","19.55207","0.08240"
"234.90600","19.57563","0.08363"
"235.18800","19.59913","0.07893"
"235.47000","19.62268","0.07926"
"235.75200","19.64612","0.08178"
"236.03400","19.66962","0.08205"
"236.31600","19.69312","0.08088"
"236.59800","19.71661","0.08053"
"236.88000","19.74005","0.08056"
"237.16200","19.76361","0.08169"
"237.44400","19.78711","0.08320"
"237.72600","19.81066","0.07838"
"238.00800","19.83410","0.07863"
"238.29000","19.85766","0.07854"
"238.57200","19.88109","0.07827"
"238.85400","19.90459","0.07966"
"239.13600","19.92809","0.08015"
"239.41800","19.95165","0.07882"
"239.70000","19.97515","0.07986"
"239.98200","19.99864","0.07958"
"240.26400","20.02214","0.08003"
"240.54600","20.04564","0.08087"
"240.82800","20.06913","0.08134"
"241.11000","20.09263","0.08181"
"241.39200","20.11619","0.08148"
"241.67400","20.13956","0.08241"
"241.95600","20.16318","0.08239"
"242.23800","20.18662","0.08318"
"242.52000","20.21012","0.08349"
"242.80200","20.23355","0.08377"
"243.08400","20.25711","0.08517"
"243.36600","20.28055","0.08503"
"243.64800","20.30416","0.08485"
"243.93000","20.32754","0.08475"
"244.21200","20.35116","0.08568"
"244.49400","20.37460","0.08652"
"244.77600","20.39816","0.08704"
"245.05800","20.42159","0.08758"
"245.34000","20.44509","0.08811"
"245.62200","20.46859","0.08817"
"245.90400","20.49214","0.08800"
"246.18600","20.51564","0.08883"
"246.46800","20.53908","0.08875"
"246.75000","20.56264","0.08844"
"247.03200","20.58613","0.08959"
"247.31400","20.60963","0.09008"
"247.59600","20.63307","0.09024"
"247.87800","20.65663","0.08998"
"248.16000","20.68012","0.08926"
"248.44200","20.70362","0.08872"
"248.72400","20.72712","0.08795"
"249.00600","20.75068","0.08821"
"249.28800","20.77411","0.08870"
"249.57000","20.79761","0.08872"
"249.85200","20.82111","0.08891"
"250.13400","20.84466","0.08873"
"250.41600","20.86816","0.08912"
"250.69800","20.89166","0.08978"
"250.98000","20.91516","0.08997"
"251.26200","20.93865","0.08985"
"251.54400","20.96209","0.09009"
"251.82600","20.98559","0.08965"
"252.10800","21.00915","0.09017"
"252.39000","21.03264","0.09063"
"252.67200","21.05614","0.09110"
"252.95400","21.07958","0.09201"
"253.23600","21.10313","0.09249"
"253.51800","21.12657","0.09159"
"253.80000","21.15013","0.09203"
"254.08200","21.17351","0.09252"
"254.36400","21.19712","0.09286"
"254.64600","21.22056","0.09340"
"254.92800","21.24412","0.09339"
"255.21000","21.26761","0.09374"
"255.49200","21.29111","0.09338"
"255.77400","21.31461","0.09285"
"256.05600","21.33811","0.09245"
"256.33800","21.36160","0.09284"
"256.62000","21.38516","0.09333"
"256.90200","21.40866","0.09387"
"257.18400","21.43210","0.09426"
"257.46600","21.45559","0.09427"
"257.74800","21.47915","0.09421"
"258.03000","21.50265","0.09429"
"258.31200","21.52608","0.09519"
"258.59400","21.54964","0.09492"
"258.87600","21.57308","0.08203"
"259.15800","21.59664","0.08234"
"259.44000","21.62008","0.08201"
"259.72200","21.64363","0.08340"
"260.00400","21.66707","0.08257"
"260.28600","21.69063","0.08331"
"260.56800","21.71400","0.08426"
"260.85000","21.73762","0.08466"
"261.13200","21.76112","0.08484"
"261.41400","21.78468","0.08596"
"261.69600","21.80805","0.08619"
"261.97800","21.83167","0.08618"
"262.26000","21.85511","0.08726"
"262.54200","21.87860","0.08706"
"262.82400","21.90210","0.08746"
"263.10600","21.92566","0.08811"
"263.38800","21.94909","0.08826"
"263.67000","21.97265","0.08890"
"263.95200","21.99609","0.08942"
"264.23400","22.01959","0.08984"
"264.51600","22.04315","0.09040"
"264.79800","22.06664","0.09164"
"265.08000","22.09014","0.09186"
"265.36200","22.11364","0.09256"
"265.64400","22.13713","0.09275"
"265.92600","22.16063","0.09353"
"266.20800","22.18419","0.09384"
"266.49000","22.20757","0.09348"
"266.77200","22.23106","0.09395"
"267.05400","22.25456","0.09443"
"267.33600","22.27812","0.09452"
"267.61800","22.30156","0.09490"
"267.90000","22.32517","0.09567"
"268.18200","22.34861","0.09601"
"268.46400","22.37211","0.09661"
"268.74600","22.39566","0.09682"
"269.02800","22.41910","0.09673"
"269.31000","22.44266","0.09744"
"269.59200","22.46610","0.09793"
"269.87400","22.48959","0.09803"
"270.15600","22.51309","0.09792"
"270.43800","22.53665","0.09795"
"270.72000","22.56009","0.09797"
"271.00200","22.58364","0.09809"
"271.28400","22.60708","0.09841"
"271.56600","22.63064","0.09855"
"271.84800","22.65408","0.09898"
"272.13000","22.67769","0.09891"
"272.41200","22.70113","0.09914"
"272.69400","22.72463","0.09938"
"272.97600","22.74806","0.09948"
"273.25800","22.77168","0.09941"
"273.54000","22.79512","0.09921"
"273.82200","22.81867","0.09908"
"274.10400","22.84211","0.09828"
"274.38600","22.86561","0.09811"
"274.66800","22.88911","0.09683"
"274.95000","22.91261","0.09536"
"275.23200","22.93610","0.09580"
"275.51400","22.95960","0.09585"
"275.79600","22.98310","0.09638"
"276.07800","23.00659","0.09680"
"276.36000","23.03015","0.09715"
"276.64200","23.05365","0.09649"
"276.92400","23.07721","0.09697"
"277.20600","23.10058","0.09714"
"277.48800","23.12408","0.09783"
"277.77000","23.14758","0.09799"
"278.05200","23.17114","0.09824"
"278.33400","23.19457","0.09810"
"278.61600","23.21813","0.09773"
"278.89800","23.24157","0.09815"
"279.18000","23.26513","0.09830"
"279.46200","23.28856","0.09881"
"279.74400","23.31212","0.09877"
"280.02600","23.33562","0.09903"
"280.30800","23.35911","0.09917"
"280.59000","23.38261","0.09914"
"280.87200","23.40611","0.09950"
"281.15400","23.42961","0.09960"
"281.43600","23.45316","0.09974"
"281.71800","23.47666","0.10002"
"282.00000","23.50016","0.10008"
"282.28200","23.52365","0.10036"
"282.56400","23.54715","0.10052"
"282.84600","23.57065","0.10061"
"283.12800","23.59409","0.10060"
"283.41000","23.61758","0.10071"
"283.69200","23.64108","0.10108"
"283.97400","23.66464","0.10114"
"284.25600","23.68808","0.10163"
"284.53800","23.71163","0.10174"
"284.82000","23.73513","0.10195"
"285.10200","23.75863","0.10210"
"285.38400","23.78206","0.10226"
"285.66600","23.80562","0.10224"
"285.94800","23.82912","0.10270"
"286.23000","23.85262","0.10302"
"286.51200","23.87611","0.10322"
"286.79400","23.89967","0.10362"
"287.07600","23.92317","0.10361"
"287.35800","23.94666","0.10405"
"287.64000","23.97016","0.10464"
"287.92200","23.99360","0.10536"
"288.20400","24.01715","0.10585"
"288.48600","24.04059","0.10672"
"288.76800","24.06415","0.10701"
"289.05000","24.08759","0.10758"
"289.33200","24.11115","0.10846"
"289.61400","24.13458","0.10910"
"289.89600","24.15814","0.10637"
"290.17800","24.18158","0.10639"
"290.46000","24.20513","0.10699"
"290.74200","24.22857","0.10747"
"291.02400","24.25213","0.10828"
"291.30600","24.27563","0.10875"
"291.58800","24.29912","0.10924"
"291.87000","24.32262","0.11006"
"292.15200","24.34612","0.11027"
"292.43400","24.36962","0.11160"
"292.71600","24.39305","0.11208"
"292.99800","24.41661","0.11309"
"293.28000","24.44011","0.11304"
"293.56200","24.46367","0.11355"
"293.84400","24.48710","0.11383"
"294.12600","24.51066","0.11354"
"294.40800","24.53410","0.11059"
"294.69000","24.55759","0.11160"
"294.97200","24.58103","0.11280"
"295.25400","24.60465","0.11354"
"295.53600","24.62803","0.11298"
"295.81800","24.65164","0.09660"
"296.10000","24.67508","0.09684"
"296.38200","24.69870","0.09777"
"296.66400","24.72214","0.09867"
"296.94600","24.74563","0.09886"
"297.22800","24.76913","0.09873"
"297.51000","24.79263","0.09907"
"297.79200","24.81612","0.09917"
"298.07400","24.83968","0.09899"
"298.35600","24.86312","0.09960"
"298.63800","24.88667","0.10002"
"298.92000","24.91011","0.09997"
"299.20200","24.93361","0.10081"
"299.48400","24.95711","0.10061"
"299.76600","24.98060","0.10136"
"300.04800","25.00416","0.10163"
"300.33000","25.02760","0.10180"
"300.61200","25.05110","0.10202"
"300.89400","25.07459","0.10257"
"301.17600","25.09815","0.10329"
"301.45800","25.12159","0.10349"
"301.74000","25.14515","0.10402"
"302.02200","25.16858","0.10476"
"302.30400","25.19214","0.10484"
"302.58600","25.21558","0.10564"
"302.86800","25.23919","0.10641"
"303.15000","25.26263","0.10714"
"303.43200","25.28613","0.10751"
"303.71400","25.30963","0.10898"
"303.99600","25.33313","0.10993"
"304.27800","25.35662","0.11019"
"304.56000","25.38012","0.11242"
"304.84200","25.40362","0.11278"
"305.12400","25.42711","0.11286"
"305.40600","25.45055","0.11201"
"305.68800","25.47405","0.11212"
"305.97000","25.49767","0.11365"
"306.25200","25.52110","0.11313"
"306.53400","25.54466","0.11334"
"306.81600","25.56810","0.11471"
"307.09800","25.59159","0.11290"
"307.38000","25.61509","0.11480"
"307.66200","25.63865","0.11618"
"307.94400","25.66203","0.11784"
"308.22600","25.68558","0.12043"
"308.50800","25.70908","0.11535"
"308.79000","25.73264","0.11532"
"309.07200","25.75608","0.04885"
"309.35400","25.77963","0.04510"
"309.63600","25.80313","0.04567"
"309.91800","25.82657","0.04372"
"310.20000","25.85007","0.04488"
"310.48200","25.87356","0.04509"
"310.76400","25.89712","0.04575"
"311.04600","25.92062","0.04463"
"311.32800","25.94417","0.04749"
"311.61000","25.96761","0.04681"
"311.89200","25.99117","0.04682"
"312.17400","26.01461","0.04806"
"312.45600","26.03810","0.04844"
"312.73800","26.06160","0.04871"
"313.02000","26.08516","0.04909"
"313.30200","26.10853","0.04934"
"313.58400","26.13215","0.04935"
"313.86600","26.15559","0.04928"
"314.14800","26.17921","0.05037"
"314.43000","26.20258","0.05043"
"314.71200","26.22620","0.05080"
"314.99400","26.24958","0.05112"
"315.27600","26.27313","0.05197"
"315.55800","26.29657","0.05137"
"315.84000","26.32013","0.05261"
"316.12200","26.34363","0.05279"
"316.40400","26.36712","0.05249"
"316.68600","26.39062","0.05394"
"316.96800","26.41418","0.05383"
"317.25000","26.43762","0.05468"
"317.53200","26.46111","0.05509"
"317.81400","26.48461","0.05505"
"318.09600","26.50811","0.05645"
"318.37800","26.53161","0.05615"
"318.66000","26.55510","0.05754"
"318.94200","26.57860","0.05822"
"319.22400","26.60210","0.05802"
"319.50600","26.62566","0.06005"
"319.78800","26.64909","0.05997"
"320.07000","26.67265","0.06008"
"320.35200","26.69609","0.06164"
"320.63400","26.71964","0.06206"
"320.91600","26.74308","0.06274"
"321.19800","26.76664","0.06347"
"321.48000","26.79014","0.06372"
"321.76200","26.81363","0.06414"
"322.04400","26.83713","0.06444"
"322.32600","26.86063","0.06496"
"322.60800","26.88412","0.06601"
"322.89000","26.90756","0.06679"
"323.17200","26.93118","0.06714"
"323.45400","26.95456","0.06845"
"323.73600","26.97812","0.06891"
"324.01800","27.00161","0.06952"
"324.30000","27.02511","0.07013"
"324.58200","27.04861","0.07049"
"324.86400","27.07210","0.07122"
"325.14600","27.09554","0.07251"
"325.42800","27.11916","0.07311"
"325.71000","27.14260","0.07388"
"325.99200","27.16609","0.07487"
"326.27400","27.18959","0.07437"
"326.55600","27.21314","0.07488"
"326.83800","27.23658","0.07519"
"327.12000","27.26008","0.07569"
"327.40200","27.28364","0.07649"
"327.68400","27.30708","0.07701"
"327.96600","27.33063","0.07738"
"328.24800","27.35407","0.07866"
"328.53000","27.37763","0.07901"
"328.81200","27.40112","0.07969"
"329.09400","27.42474","0.08044"
"329.37600","27.44806","0.08078"
"329.65800","27.47168","0.08091"
"329.94000","27.49511","0.08239"
"330.22200","27.51867","0.08253"
"330.50400","27.54211","0.08248"
"330.78600","27.56567","0.08368"
"331.06800","27.58911","0.08397"
"331.35000","27.61266","0.08431"
"331.63200","27.63604","0.08514"
"331.91400","27.65966","0.08425"
"332.19600","27.68309","0.08359"
"332.47800","27.70665","0.08180"
"332.76000","27.73009","0.08092"
"333.04200","27.75364","0.08187"
"333.32400","27.77708","0.08178"
"333.60600","27.80064","0.08155"
"333.88800","27.82414","0.08202"
"334.17000","27.84757","0.08198"
"334.45200","27.87113","0.08100"
"334.73400","27.89463","0.03030"
"335.01600","27.91813","0.03720"
"335.29800","27.94162","0.04318"
"335.58000","27.96512","0.03562"
"335.86200","27.98862","0.04064"
"336.14400","28.01217","0.04227"
"336.42600","28.03561","0.04080"
"336.70800","28.05917","0.04177"
"336.99000","28.08255","0.04347"
"337.27200","28.10610","0.04297"
"337.55400","28.12960","0.04402"
"337.83600","28.15316","0.04513"
"338.11800","28.17665","0.04507"
"338.40000","28.20015","0.04593"
"338.68200","28.22365","0.04493"
"338.96400","28.24715","0.04519"
"339.24600","28.27064","0.04733"
"339.52800","28.29414","0.04645"
"339.81000","28.31758","0.04718"
"340.09200","28.34108","0.04820"
"340.37400","28.36457","0.04782"
"340.65600","28.38807","0.04763"
"340.93800","28.41163","0.04918"
"341.22000","28.43512","0.04875"
"341.50200","28.45862","0.04849"
"341.78400","28.48212","0.04925"
"342.06600","28.50556","0.04909"
"342.34800","28.52905","0.04957"
"342.63000","28.55261","0.04968"
"342.91200","28.57605","0.05002"
"343.19400","28.59961","0.04452"
"343.47600","28.62310","0.04367"
"343.75800","28.64666","0.04489"
"344.04000","28.67010","0.04501"
"344.32200","28.69359","0.04536"
"344.60400","28.71709","0.04576"
"344.88600","28.74059","0.04587"
"345.16800","28.76409","0.04605"
"345.45000","28.78765","0.04655"
"345.73200","28.81114","0.04662"
"346.01400","28.83464","0.04618"
"346.29600","28.85820","0.04710"
"346.57800","28.88157","0.04671"
"346.86000","28.90519","0.04722"
"347.14200","28.92857","0.04761"
"347.42400","28.95218","0.04743"
"347.70600","28.97556","0.04751"
"347.98800","28.99912","0.04744"
"348.27000","29.02256","0.04788"
"348.55200","29.04612","0.04785"
"348.83400","29.06955","0.04790"
"349.11600","29.09317","0.04770"
"349.39800","29.11661","0.04785"
"349.68000","29.14016","0.04773"
"349.96200","29.16354","0.04800"
"350.24400","29.18716","0.04830"
"350.52600","29.21060","0.04824"
"350.80800","29.23415","0.04828"
"351.09000","29.25765","0.04902"
"351.37200","29.28109","0.04905"
"351.65400","29.30453","0.04936"
"351.93600","29.32808","0.04952"
"352.21800","29.35164","0.04900"
"352.50000","29.37514","0.04971"
"352.78200","29.39863","0.04946"
"353.06400","29.42207","0.04954"
"353.34600","29.44563","0.05000"
"353.62800","29.46913","0.05027"
"353.91000","29.49262","0.05074"
"354.19200","29.51612","0.05090"
"354.47400","29.53968","0.05089"
"354.75600","29.56311","0.05125"
"355.03800","29.58661","0.05114"
"355.32000","29.61011","0.05135"
"355.60200","29.63367","0.05164"
"355.88400","29.65710","0.05182"
"356.16600","29.68060","0.05217"
"356.44800","29.70410","0.05236"
"356.73000","29.72759","0.05219"
"357.01200","29.75109","0.05262"
"357.29400","29.77459","0.05298"
"357.57600","29.79809","0.05280"
"357.85800","29.82158","0.05324"
"358.14000","29.84514","0.05284"
"358.42200","29.86864","0.05342"
"358.70400","29.89214","0.05398"
"358.98600","29.91557","0.05422"
"359.26800","29.93907","0.05412"
"359.55000","29.96257","0.05483"
"359.83200","29.98606","0.05506"
"360.11400","30.00956","0.05542"
"360.39600","30.03312","0.05588"
"360.67800","30.05662","0.05620"
"360.96000","30.08017","0.05629"
"361.24200","30.10361","0.05681"
"361.52400","30.12711","0.05759"
"361.80600","30.15061","0.05845"
"362.08800","30.17410","0.05904"
"362.37000","30.19760","0.05882"
"362.65200","30.22116","0.05901"
"362.93400","30.24465","0.05883"
"363.21600","30.26815","0.05876"
"363.49800","30.29165","0.05934"
"363.78000","30.31509","0.06029"
"364.06200","30.33864","0.06042"
"364.34400","30.36208","0.06141"
"364.62600","30.38564","0.06200"
"364.90800","30.40908","0.06237"
"365.19000","30.43263","0.06396"
"365.47200","30.45613","0.06442"
"365.75400","30.47963","0.06542"
"366.03600","30.50307","0.06503"
"366.31800","30.52662","0.06594"
"366.60000","30.55006","0.06711"
"366.88200","30.57362","0.06833"
"367.16400","30.59706","0.06852"
"367.44600","30.62067","0.06878"
"367.72800","30.64411","0.07005"
"368.01000","30.66761","0.07005"
"368.29200","30.69110","0.07092"
"368.57400","30.71460","0.07163"
"368.85600","30.73810","0.07235"
"369.13800","30.76166","0.01650"
"369.42000","30.78509","0.01907"
"369.70200","30.80859","0.00934"
"369.98400","30.83215","0.01042"
"370.26600","30.85559","0.01527"
"370.54800","30.87914","0.00980"
"370.83000","30.90264","0.01098"
"371.11200","30.92620","0.01333"
"371.39400","30.94957","0.00974"
"371.67600","30.97313","0.01235"
"371.95800","30.99657","0.01149"
"372.24000","31.02013","0.01063"
"372.52200","31.04356","0.01287"
"372.80400","31.06712","0.01012"
"373.08600","31.09056","0.01146"
"373.36800","31.11417","0.01114"
"373.65000","31.13761","0.01078"
"373.93200","31.16117","0.01212"
"374.21400","31.18461","0.01029"
"374.49600","31.20811","0.01214"
"374.77800","31.23160","0.01115"
"375.06000","31.25510","0.01167"
"375.34200","31.27865","0.01229"
"375.62400","31.30209","0.01095"
"375.90600","31.32565","0.01196"
"376.18800","31.34914","0.01106"
"376.47000","31.37264","0.01207"
"376.75200","31.39608","0.01150"
"377.03400","31.41958","0.01125"
"377.31600","31.44308","0.01167"
"377.59800","31.46663","0.01121"
"377.88000","31.49007","0.01161"
"378.16200","31.51363","0.01134"
"378.44400","31.53712","0.01192"
"378.72600","31.56062","0.01134"
"379.00800","31.58412","0.01118"
"379.29000","31.60768","0.01168"
"379.57200","31.63117","0.01155"
"379.85400","31.65467","0.01169"
"380.13600","31.67817","0.01151"
"380.41800","31.70160","0.01156"
"380.70000","31.72510","0.01133"
"380.98200","31.74860","0.01188"
"381.26400","31.77216","0.01177"
"381.54600","31.79560","0.01160"
"381.82800","31.81915","0.01195"
"382.11000","31.84253","0.01146"
"382.39200","31.86615","0.01186"
"382.67400","31.88958","0.01123"
"382.95600","31.91308","0.01170"
"383.23800","31.93652","0.01149"
"383.52000","31.96014","0.01210"
"383.80200","31.98357","0.01176"
"384.08400","32.00713","0.01194"
"384.36600","32.03057","0.01166"
"384.64800","32.05418","0.01174"
"384.93000","32.07762","0.01177"
"385.21200","32.10112","0.01177"
"385.49400","32.12461","0.01192"
"385.77600","32.14812","0.01185"
"386.05800","32.17167","0.01179"
"386.34000","32.19517","0.01202"
"386.62200","32.21861","0.01206"
"386.90400","32.24216","0.01206"
"387.18600","32.26566","0.01180"
"387.46800","32.28910","0.01171"
"387.75000","32.31260","0.01163"
"388.03200","32.33609","0.01223"
"388.31400","32.35965","0.01176"
"388.59600","32.38309","0.01157"
"388.87800","32.40664","0.01190"
"389.16000","32.43008","0.01165"
"389.44200","32.45364","0.01187"
"389.72400","32.47708","0.01169"
"390.00600","32.50057","0.01167"
"390.28800","32.52407","0.01132"
"390.57000","32.54769","0.01123"
"390.85200","32.57107","0.01154"
"391.13400","32.59462","0.01129"
"391.41600","32.61806","0.01124"
"391.69800","32.64162","0.01165"
"391.98000","32.66512","0.01105"
"392.26200","32.68861","0.01051"
"392.54400","32.71211","0.01096"
"392.82600","32.73560","0.01074"
"393.10800","32.75916","0.01051"
"393.39000","32.78260","0.01022"
"393.67200","32.80610","0.01074"
"393.95400","32.82959","0.01063"
"394.23600","32.85315","0.01073"
"394.51800","32.87659","0.01046"
"394.80000","32.90015","0.04137"
"395.08200","32.92358","0.01673"
"395.36400","32.94714","0.01485"
"395.64600","32.97064","0.00657"
"395.92800","32.99414","0.01040"
"396.21000","33.01757","0.00973"
"396.49200","33.04113","0.01047"
"396.77400","33.06462","0.00807"
"397.05600","33.08813","0.00839"
"397.33800","33.11162","0.00947"
"397.62000","33.13512","0.00805"
"397.90200","33.15862","0.00935"
"398.18400","33.18206","0.00843"
"398.46600","33.20561","0.00966"
"398.74800","33.22911","0.00955"
"399.03000","33.25261","0.00952"
"399.31200","33.27610","0.00992"
"399.59400","33.29966","0.00888"
"399.87600","33.32310","0.00915"
"400.15800","33.34666","0.00904"
"400.44000","33.37009","0.00928"
"400.72200","33.39365","0.00896"
"401.00400","33.41709","0.00898"
"401.28600","33.44065","0.01043"
"401.56800","33.46414","0.00888"
"401.85000","33.48764","0.00893"
"402.13200","33.51108","0.00911"
"402.41400","33.53463","0.01005"
"402.69600","33.55813","0.00948"
"402.97800","33.58163","0.00942"
"403.26000","33.60513","0.00870"
"403.54200","33.62862","0.00930"
"403.82400","33.65212","0.00995"
"404.10600","33.67562","0.00934"
"404.38800","33.69912","0.00930"
"404.67000","33.72261","0.00883"
"404.95200","33.74611","0.00970"
"405.23400","33.76955","0.00952"
"405.51600","33.79310","0.00991"
"405.79800","33.81660","0.00928"
"406.08000","33.84010","0.00935"
"406.36200","33.86360","0.00990"
"406.64400","33.88709","0.00934"
"406.92600","33.91053","0.00942"
"407.20800","33.93415","0.00919"
"407.49000","33.95753","0.00947"
"407.77200","33.98114","0.00993"
"408.05400","34.00452","0.00959"
"408.33600","34.02813","0.00991"
"408.61800","34.05164","0.00993"
"408.90000","34.07513","0.01012"
"409.18200","34.09863","0.00942"
"409.46400","34.12212","0.00958"
"409.74600","34.14562","0.00969"
"410.02800","34.16912","0.00970"
"410.31000","34.19262","0.00960"
"410.59200","34.21611","0.00951"
"410.87400","34.23961","0.00937"
"411.15600","34.26311","0.00960"
"411.43800","34.28667","0.00945"
"411.72000","34.31010","0.00973"
"412.00200","34.33366","0.00959"
"412.28400","34.35710","0.00948"
"412.56600","34.38066","0.00963"
"412.84800","34.40409","0.00969"
"413.13000","34.42765","0.00974"
"413.41200","34.45103","0.00979"
"413.69400","34.47464","0.00980"
"413.97600","34.49814","0.00957"
"414.25800","34.52164","0.00953"
"414.54000","34.54507","0.00961"
"414.82200","34.56863","0.00994"
"415.10400","34.59213","0.00981"
"415.38600","34.61557","0.00969"
"415.66800","34.63912","0.00975"
"415.95000","34.66262","0.00971"
"416.23200","34.68618","0.00966"
"416.51400","34.70962","0.00992"
"416.79600","34.73318","0.00979"
"417.07800","34.75661","0.00998"
"417.36000","34.78011","0.00960"
"417.42600","34.78567","0.00970"