File: Force_trajectories/161217/Specimen_RawData_8.csv
End date,"12/17/2016"
Specimen label,"15CG_Unk"
Maximum Load,"0.01489",N

Time,Extension,Load
(s),(mm),(N)
"0.00000","0.00006","-0.00059"
"0.07800","0.00227","0.00018"
"0.15600","0.00909","0.00032"
"0.23400","0.01770","0.00094"
"0.31200","0.02565","0.00111"
"0.39000","0.03276","0.00067"
"0.46800","0.03928","0.00157"
"0.54600","0.04574","0.00159"
"0.62400","0.05220","0.00161"
"0.70200","0.05871","0.00178"
"0.78000","0.06523","0.00223"
"0.85800","0.07175","0.00237"
"0.93600","0.07832","0.00249"
"1.01400","0.08478","0.00281"
"1.09200","0.09118","0.00266"
"1.17000","0.09770","0.00278"
"1.24800","0.10427","0.00276"
"1.32600","0.11073","0.00276"
"1.40400","0.11731","0.00290"
"1.48200","0.12376","0.00321"
"1.56000","0.13022","0.00304"
"1.63800","0.13674","0.00352"
"1.71600","0.14320","0.00332"
"1.79400","0.14971","0.00322"
"1.87200","0.15623","0.00342"
"1.95000","0.16275","0.00369"
"2.02800","0.16926","0.00364"
"2.10600","0.17572","0.00364"
"2.18400","0.18224","0.00377"
"2.26200","0.18870","0.00409"
"2.34000","0.19521","0.00380"
"2.41800","0.20173","0.00378"
"2.49600","0.20825","0.00397"
"2.57400","0.21476","0.00426"
"2.65200","0.22122","0.00407"
"2.73000","0.22768","0.00447"
"2.80800","0.23420","0.00438"
"2.88600","0.24071","0.00451"
"2.96400","0.24723","0.00475"
"3.04200","0.25369","0.00479"
"3.12000","0.26026","0.00477"
"3.19800","0.26672","0.00485"
"3.27600","0.27324","0.00448"
"3.35400","0.27964","0.00472"
"3.43200","0.28627","0.00466"
"3.51000","0.29273","0.00492"
"3.58800","0.29925","0.00490"
"3.66600","0.30570","0.00510"
"3.74400","0.31222","0.00526"
"3.82200","0.31874","0.00496"
"3.90000","0.32520","0.00517"
"3.97800","0.33171","0.00507"
"4.05600","0.33823","0.00523"
"4.13400","0.34481","0.00507"
"4.21200","0.35126","0.00520"
"4.29000","0.35772","0.00534"
"4.36800","0.36418","0.00547"
"4.44600","0.37070","0.00560"
"4.52400","0.37721","0.00548"
"4.60200","0.38379","0.00537"
"4.68000","0.39019","0.00547"
"4.75800","0.39670","0.00540"
"4.83600","0.40322","0.00550"
"4.91400","0.40968","0.00558"
"4.99200","0.41619","0.00563"
"5.07000","0.42271","0.00547"
"5.14800","0.42923","0.00584"
"5.22600","0.43569","0.00584"
"5.30400","0.44220","0.00580"
"5.38200","0.44866","0.00577"
"5.46000","0.45518","0.00597"
"5.53800","0.46169","0.00576"
"5.61600","0.46821","0.00582"
"5.69400","0.47473","0.00615"
"5.77200","0.48119","0.00601"
"5.85000","0.48776","0.00620"
"5.92800","0.49422","0.00607"
"6.00600","0.50068","0.00645"
"6.08400","0.50719","0.00645"
"6.16200","0.51377","0.00640"
"6.24000","0.52023","0.00623"
"6.31800","0.52675","0.00620"
"6.39600","0.53320","0.00639"
"6.47400","0.53972","0.00625"
"6.55200","0.54618","0.00670"
"6.63000","0.55269","0.00655"
"6.70800","0.55927","0.00630"
"6.78600","0.56573","0.00658"
"6.86400","0.57225","0.00637"
"6.94200","0.57870","0.00621"
"7.02000","0.58522","0.00652"
"7.09800","0.59162","0.00677"
"7.17600","0.59819","0.00708"
"7.25400","0.60471","0.00668"
"7.33200","0.61123","0.00693"
"7.41000","0.61775","0.00681"
"7.48800","0.62420","0.00670"
"7.56600","0.63072","0.00686"
"7.64400","0.63712","0.00677"
"7.72200","0.64375","0.00650"
"7.80000","0.65021","0.00696"
"7.87800","0.65673","0.00691"
"7.95600","0.66325","0.00698"
"8.03400","0.66976","0.00701"
"8.11200","0.67622","0.00689"
"8.19000","0.68262","0.00682"
"8.26800","0.68919","0.00679"
"8.34600","0.69577","0.00705"
"8.42400","0.70229","0.00711"
"8.50200","0.70875","0.00704"
"8.58000","0.71526","0.00712"
"8.65800","0.72166","0.00661"
"8.73600","0.72818","0.00732"
"8.81400","0.73463","0.00703"
"8.89200","0.74127","0.00699"
"8.97000","0.74773","0.00727"
"9.04800","0.75424","0.00728"
"9.12600","0.76070","0.00726"
"9.20400","0.76716","0.00724"
"9.28200","0.77368","0.00732"
"9.36000","0.78019","0.00691"
"9.43800","0.78671","0.00720"
"9.51600","0.79323","0.00740"
"9.59400","0.79974","0.00719"
"9.67200","0.80620","0.00728"
"9.75000","0.81266","0.00726"
"9.82800","0.81918","0.00746"
"9.90600","0.82563","0.00742"
"9.98400","0.83221","0.00741"
"10.06200","0.83873","0.00732"
"10.14000","0.84524","0.00702"
"10.21800","0.85170","0.00753"
"10.29600","0.85822","0.00754"
"10.37400","0.86468","0.00750"
"10.45200","0.87119","0.00730"
"10.53000","0.87771","0.00768"
"10.60800","0.88429","0.00761"
"10.68600","0.89068","0.00748"
"10.76400","0.89720","0.00741"
"10.84200","0.90366","0.00762"
"10.92000","0.91018","0.00761"
"10.99800","0.91675","0.00772"
"11.07600","0.92321","0.00766"
"11.15400","0.92973","0.00774"
"11.23200","0.93624","0.00772"
"11.31000","0.94270","0.00757"
"11.38800","0.94916","0.00798"
"11.46600","0.95568","0.00755"
"11.54400","0.96219","0.00773"
"11.62200","0.96871","0.00801"
"11.70000","0.97517","0.00807"
"11.77800","0.98168","0.00786"
"11.85600","0.98820","0.00775"
"11.93400","0.99466","0.00791"
"12.01200","1.00118","0.00770"
"12.09000","1.00769","0.00782"
"12.16800","1.01427","0.00750"
"12.24600","1.02073","0.00801"
"12.32400","1.02724","0.00810"
"12.40200","1.03370","0.00807"
"12.48000","1.04022","0.00822"
"12.55800","1.04668","0.00838"
"12.63600","1.05319","0.00793"
"12.71400","1.05971","0.00818"
"12.79200","1.06629","0.00826"
"12.87000","1.07274","0.00810"
"12.94800","1.07914","0.00793"
"13.02600","1.08572","0.00798"
"13.10400","1.09218","0.00842"
"13.18200","1.09875","0.00805"
"13.26000","1.10521","0.00804"
"13.33800","1.11173","0.00821"
"13.41600","1.11818","0.00824"
"13.49400","1.12464","0.00812"
"13.57200","1.13116","0.00807"
"13.65000","1.13774","0.00824"
"13.72800","1.14425","0.00837"
"13.80600","1.15077","0.00850"
"13.88400","1.15723","0.00818"
"13.96200","1.16368","0.00799"
"14.04000","1.17026","0.00809"
"14.11800","1.17672","0.00867"
"14.19600","1.18323","0.00806"
"14.27400","1.18975","0.00844"
"14.35200","1.19627","0.00845"
"14.43000","1.20273","0.00852"
"14.50800","1.20924","0.00804"
"14.58600","1.21570","0.00853"
"14.66400","1.22216","0.00835"
"14.74200","1.22873","0.00860"
"14.82000","1.23525","0.00852"
"14.89800","1.24177","0.00842"
"14.97600","1.24829","0.00865"
"15.05400","1.25474","0.00834"
"15.13200","1.26120","0.00876"
"15.21000","1.26772","0.00842"
"15.28800","1.27423","0.00856"
"15.36600","1.28075","0.00852"
"15.44400","1.28721","0.00838"
"15.52200","1.29373","0.00864"
"15.60000","1.30018","0.00852"
"15.67800","1.30664","0.00828"
"15.75600","1.31322","0.00879"
"15.83400","1.31973","0.00870"
"15.91200","1.32625","0.00879"
"15.99000","1.33271","0.00883"
"16.06800","1.33929","0.00896"
"16.14600","1.34568","0.00889"
"16.22400","1.35214","0.00877"
"16.30200","1.35866","0.00859"
"16.38000","1.36523","0.00887"
"16.45800","1.37175","0.00898"
"16.53600","1.37821","0.00914"
"16.61400","1.38479","0.00851"
"16.69200","1.39118","0.00874"
"16.77000","1.39770","0.00894"
"16.84800","1.40416","0.00856"
"16.92600","1.41079","0.00877"
"17.00400","1.41725","0.00930"
"17.08200","1.42371","0.00915"
"17.16000","1.43023","0.00885"
"17.23800","1.43674","0.00907"
"17.31600","1.44320","0.00901"
"17.39400","1.44972","0.00877"
"17.47200","1.45623","0.00944"
"17.55000","1.46275","0.00922"
"17.62800","1.46921","0.00902"
"17.70600","1.47573","0.00925"
"17.78400","1.48218","0.00902"
"17.86200","1.48864","0.00905"
"17.94000","1.49516","0.00932"
"18.01800","1.50167","0.00925"
"18.09600","1.50819","0.00916"
"18.17400","1.51477","0.00924"
"18.25200","1.52123","0.00928"
"18.33000","1.52768","0.00935"
"18.40800","1.53414","0.00927"
"18.48600","1.54072","0.00944"
"18.56400","1.54723","0.00911"
"18.64200","1.55375","0.00918"
"18.72000","1.56027","0.00958"
"18.79800","1.56673","0.00940"
"18.87600","1.57318","0.00924"
"18.95400","1.57970","0.00933"
"19.03200","1.58622","0.00937"
"19.11000","1.59273","0.00937"
"19.18800","1.59925","0.00938"
"19.26600","1.60577","0.00951"
"19.34400","1.61222","0.00932"
"19.42200","1.61868","0.00944"
"19.50000","1.62520","0.00937"
"19.57800","1.63166","0.00955"
"19.65600","1.63823","0.00980"
"19.73400","1.64469","0.00948"
"19.81200","1.65127","0.00966"
"19.89000","1.65766","0.00944"
"19.96800","1.66418","0.00964"
"20.04600","1.67070","0.00956"
"20.12400","1.67722","0.00963"
"20.20200","1.68379","0.00948"
"20.28000","1.69019","0.00974"
"20.35800","1.69671","0.00954"
"20.43600","1.70316","0.00962"
"20.51400","1.70968","0.00976"
"20.59200","1.71614","0.01006"
"20.67000","1.72272","0.00969"
"20.74800","1.72923","0.00939"
"20.82600","1.73569","0.00973"
"20.90400","1.74221","0.00927"
"20.98200","1.74872","0.01011"
"21.06000","1.75518","0.00946"
"21.13800","1.76170","0.00979"
"21.21600","1.76822","0.00958"
"21.29400","1.77473","0.00979"
"21.37200","1.78125","0.00982"
"21.45000","1.78771","0.00980"
"21.52800","1.79422","0.00974"
"21.60600","1.80068","0.00989"
"21.68400","1.80720","0.00986"
"21.76200","1.81372","0.00971"
"21.84000","1.82023","0.01000"
"21.91800","1.82675","0.00982"
"21.99600","1.83321","0.01016"
"22.07400","1.83972","0.00993"
"22.15200","1.84618","0.00992"
"22.23000","1.85276","0.01015"
"22.30800","1.85922","0.00990"
"22.38600","1.86573","0.00992"
"22.46400","1.87225","0.00979"
"22.54200","1.87871","0.01015"
"22.62000","1.88516","0.01017"
"22.69800","1.89168","0.01046"
"22.77600","1.89820","0.01008"
"22.85400","1.90472","0.01008"
"22.93200","1.91123","0.01031"
"23.01000","1.91775","0.01057"
"23.08800","1.92427","0.01030"
"23.16600","1.93066","0.01021"
"23.24400","1.93718","0.01030"
"23.32200","1.94370","0.00993"
"23.40000","1.95027","0.01029"
"23.47800","1.95673","0.01039"
"23.55600","1.96319","0.01025"
"23.63400","1.96977","0.01054"
"23.71200","1.97616","0.01028"
"23.79000","1.98268","0.01048"
"23.86800","1.98920","0.01073"
"23.94600","1.99577","0.01045"
"24.02400","2.00217","0.01049"
"24.10200","2.00875","0.01049"
"24.18000","2.01515","0.01078"
"24.25800","2.02166","0.01037"
"24.33600","2.02812","0.01046"
"24.41400","2.03470","0.01023"
"24.49200","2.04121","0.01059"
"24.57000","2.04773","0.01050"
"24.64800","2.05425","0.01046"
"24.72600","2.06071","0.01019"
"24.80400","2.06716","0.01056"
"24.88200","2.07362","0.01038"
"24.96000","2.08026","0.01044"
"25.03800","2.08677","0.01028"
"25.11600","2.09323","0.01052"
"25.19400","2.09975","0.01071"
"25.27200","2.10621","0.01074"
"25.35000","2.11272","0.01080"
"25.42800","2.11918","0.01044"
"25.50600","2.12570","0.01056"
"25.58400","2.13227","0.01057"
"25.66200","2.13873","0.01050"
"25.74000","2.14519","0.01057"
"25.81800","2.15171","0.01069"
"25.89600","2.15816","0.01058"
"25.97400","2.16468","0.01074"
"26.05200","2.17114","0.01034"
"26.13000","2.17771","0.01096"
"26.20800","2.18423","0.01084"
"26.28600","2.19075","0.01066"
"26.36400","2.19721","0.01044"
"26.44200","2.20366","0.01051"
"26.52000","2.21018","0.01125"
"26.59800","2.21670","0.01069"
"26.67600","2.22321","0.01106"
"26.75400","2.22973","0.01086"
"26.83200","2.23625","0.01065"
"26.91000","2.24265","0.01055"
"26.98800","2.24916","0.01108"
"27.06600","2.25568","0.01072"
"27.14400","2.26226","0.01083"
"27.22200","2.26877","0.01048"
"27.30000","2.27523","0.01110"
"27.37800","2.28175","0.01074"
"27.45600","2.28821","0.01102"
"27.53400","2.29472","0.01121"
"27.61200","2.30118","0.01121"
"27.69000","2.30776","0.01108"
"27.76800","2.31421","0.01108"
"27.84600","2.32073","0.01141"
"27.92400","2.32719","0.01131"
"28.00200","2.33371","0.01078"
"28.08000","2.34016","0.01096"
"28.15800","2.34668","0.01090"
"28.23600","2.35320","0.01129"
"28.31400","2.35971","0.01117"
"28.39200","2.36629","0.01134"
"28.47000","2.37269","0.01122"
"28.54800","2.37920","0.01097"
"28.62600","2.38566","0.01132"
"28.70400","2.39218","0.01134"
"28.78200","2.39870","0.01121"
"28.86000","2.40527","0.01118"
"28.93800","2.41173","0.01120"
"29.01600","2.41825","0.01132"
"29.09400","2.42470","0.01134"
"29.17200","2.43122","0.01141"
"29.25000","2.43774","0.01144"
"29.32800","2.44426","0.01162"
"29.40600","2.45071","0.01144"
"29.48400","2.45717","0.01173"
"29.56200","2.46375","0.01132"
"29.64000","2.47020","0.01161"
"29.71800","2.47672","0.01128"
"29.79600","2.48318","0.01109"
"29.87400","2.48970","0.01126"
"29.95200","2.49621","0.01165"
"30.03000","2.50273","0.01195"
"30.10800","2.50925","0.01128"
"30.18600","2.51570","0.01147"
"30.26400","2.52216","0.01170"
"30.34200","2.52874","0.01155"
"30.42000","2.53526","0.01205"
"30.49800","2.54171","0.01178"
"30.57600","2.54817","0.01182"
"30.65400","2.55463","0.01139"
"30.73200","2.56114","0.01175"
"30.81000","2.56766","0.01167"
"30.88800","2.57418","0.01168"
"30.96600","2.58076","0.01155"
"31.04400","2.58721","0.01184"
"31.12200","2.59373","0.01169"
"31.20000","2.60019","0.01170"
"31.27800","2.60670","0.01181"
"31.35600","2.61316","0.01161"
"31.43400","2.61968","0.01193"
"31.51200","2.62620","0.01151"
"31.59000","2.63271","0.01168"
"31.66800","2.63923","0.01165"
"31.74600","2.64569","0.01188"
"31.82400","2.65220","0.01128"
"31.90200","2.65866","0.01219"
"31.98000","2.66524","0.01229"
"32.05800","2.67170","0.01222"
"32.13600","2.67827","0.01179"
"32.21400","2.68473","0.01224"
"32.29200","2.69119","0.01240"
"32.37000","2.69764","0.01176"
"32.44800","2.70416","0.01227"
"32.52600","2.71074","0.01196"
"32.60400","2.71720","0.01167"
"32.68200","2.72371","0.01204"
"32.76000","2.73017","0.01167"
"32.83800","2.73669","0.01187"
"32.91600","2.74314","0.01208"
"32.99400","2.74972","0.01165"
"33.07200","2.75624","0.01198"
"33.15000","2.76275","0.01258"
"33.22800","2.76927","0.01233"
"33.30600","2.77573","0.01207"
"33.38400","2.78219","0.01217"
"33.46200","2.78864","0.01185"
"33.54000","2.79522","0.01187"
"33.61800","2.80174","0.01225"
"33.69600","2.80825","0.01194"
"33.77400","2.81471","0.01194"
"33.85200","2.82123","0.01226"
"33.93000","2.82769","0.01242"
"34.00800","2.83420","0.01262"
"34.08600","2.84066","0.01187"
"34.16400","2.84724","0.01250"
"34.24200","2.85369","0.01219"
"34.32000","2.86027","0.01229"
"34.39800","2.86673","0.01219"
"34.47600","2.87319","0.01226"
"34.55400","2.87970","0.01233"
"34.63200","2.88622","0.01219"
"34.71000","2.89268","0.01267"
"34.78800","2.89919","0.01219"
"34.86600","2.90571","0.01217"
"34.94400","2.91217","0.01239"
"35.02200","2.91869","0.01231"
"35.10000","2.92514","0.01225"
"35.17800","2.93172","0.01229"
"35.25600","2.93824","0.01256"
"35.33400","2.94469","0.01263"
"35.41200","2.95127","0.01265"
"35.49000","2.95767","0.01244"
"35.56800","2.96425","0.01270"
"35.64600","2.97064","0.01250"
"35.72400","2.97722","0.01265"
"35.80200","2.98374","0.01235"
"35.88000","2.99025","0.01299"
"35.95800","2.99671","0.01235"
"36.03600","3.00317","0.01264"
"36.11400","3.00969","0.01286"
"36.19200","3.01614","0.01226"
"36.27000","3.02272","0.01289"
"36.34800","3.02918","0.01258"
"36.42600","3.03575","0.01275"
"36.50400","3.04221","0.01314"
"36.58200","3.04873","0.01305"
"36.66000","3.05519","0.01280"
"36.73800","3.06170","0.01281"
"36.81600","3.06822","0.01296"
"36.89400","3.07468","0.01232"
"36.97200","3.08125","0.01290"
"37.05000","3.08771","0.01297"
"37.12800","3.09423","0.01303"
"37.20600","3.10063","0.01288"
"37.28400","3.10720","0.01340"
"37.36200","3.11372","0.01255"
"37.44000","3.12030","0.01307"
"37.51800","3.12669","0.01299"
"37.59600","3.13321","0.01324"
"37.67400","3.13973","0.01326"
"37.75200","3.14618","0.01299"
"37.83000","3.15264","0.01329"
"37.90800","3.15922","0.01294"
"37.98600","3.16574","0.01321"
"38.06400","3.17225","0.01313"
"38.14200","3.17871","0.01311"
"38.22000","3.18523","0.01312"
"38.29800","3.19168","0.01308"
"38.37600","3.19820","0.01280"
"38.45400","3.20472","0.01298"
"38.53200","3.21124","0.01316"
"38.61000","3.21769","0.01315"
"38.68800","3.22421","0.01322"
"38.76600","3.23067","0.01295"
"38.84400","3.23718","0.01320"
"38.92200","3.24370","0.01301"
"39.00000","3.25028","0.01317"
"39.07800","3.25668","0.01329"
"39.15600","3.26325","0.01334"
"39.23400","3.26971","0.01328"
"39.31200","3.27623","0.01314"
"39.39000","3.28268","0.01322"
"39.46800","3.28920","0.01366"
"39.54600","3.29572","0.01322"
"39.62400","3.30224","0.01330"
"39.70200","3.30875","0.01350"
"39.78000","3.31521","0.01326"
"39.85800","3.32173","0.01361"
"39.93600","3.32818","0.01340"
"40.01400","3.33476","0.01332"
"40.09200","3.34122","0.01364"
"40.17000","3.34774","0.01357"
"40.24800","3.35425","0.01337"
"40.32600","3.36077","0.01359"
"40.40400","3.36717","0.01342"
"40.48200","3.37368","0.01319"
"40.56000","3.38020","0.01326"
"40.63800","3.38678","0.01316"
"40.71600","3.39324","0.01370"
"40.79400","3.39975","0.01340"
"40.87200","3.40627","0.01354"
"40.95000","3.41267","0.01383"
"41.02800","3.41918","0.01355"
"41.10600","3.42570","0.01345"
"41.18400","3.43228","0.01395"
"41.26200","3.43874","0.01345"
"41.34000","3.44525","0.01384"
"41.41800","3.45171","0.01390"
"41.49600","3.45823","0.01386"
"41.57400","3.46468","0.01366"
"41.65200","3.47120","0.01363"
"41.73000","3.47778","0.01378"
"41.80800","3.48429","0.01345"
"41.88600","3.49075","0.01358"
"41.96400","3.49721","0.01319"
"42.04200","3.50367","0.01349"
"42.12000","3.51018","0.01351"
"42.19800","3.51670","0.01354"
"42.27600","3.52322","0.01383"
"42.35400","3.52973","0.01375"
"42.43200","3.53625","0.01429"
"42.51000","3.54271","0.01337"
"42.58800","3.54917","0.01412"
"42.66600","3.55562","0.01367"
"42.74400","3.56226","0.01374"
"42.82200","3.56872","0.01377"
"42.90000","3.57523","0.01371"
"42.97800","3.58169","0.01353"
"43.05600","3.58821","0.01398"
"43.13400","3.59467","0.01394"
"43.21200","3.60118","0.01399"
"43.29000","3.60770","0.01400"
"43.36800","3.61422","0.01386"
"43.44600","3.62073","0.01376"
"43.52400","3.62719","0.01422"
"43.60200","3.63371","0.01434"
"43.68000","3.64017","0.01399"
"43.75800","3.64668","0.01358"
"43.83600","3.65314","0.01399"
"43.91400","3.65972","0.01402"
"43.99200","3.66623","0.01380"
"44.07000","3.67269","0.01417"
"44.14800","3.67915","0.01398"
"44.22600","3.68561","0.01392"
"44.30400","3.69224","0.01405"
"44.38200","3.69870","0.01371"
"44.46000","3.70528","0.01364"
"44.53800","3.71173","0.01388"
"44.61600","3.71825","0.01388"
"44.69400","3.72471","0.01419"
"44.77200","3.73123","0.01389"
"44.85000","3.73768","0.01383"
"44.92800","3.74420","0.01398"
"45.00600","3.75072","0.01376"
"45.08400","3.75723","0.01401"
"45.16200","3.76369","0.01399"
"45.24000","3.77021","0.01401"
"45.31800","3.77673","0.01392"
"45.39600","3.78318","0.01390"
"45.47400","3.78970","0.01371"
"45.55200","3.79622","0.01387"
"45.63000","3.80273","0.01401"
"45.70800","3.80919","0.01387"
"45.78600","3.81565","0.01409"
"45.86400","3.82217","0.01391"
"45.94200","3.82868","0.01378"
"46.02000","3.83520","0.01409"
"46.09800","3.84172","0.01372"
"46.17600","3.84823","0.01371"
"46.25400","3.85475","0.01386"
"46.33200","3.86121","0.01387"
"46.41000","3.86767","0.01403"
"46.48800","3.87424","0.01396"
"46.56600","3.88076","0.01394"
"46.64400","3.88722","0.01401"
"46.72200","3.89373","0.01414"
"46.80000","3.90019","0.01376"
"46.87800","3.90671","0.01413"
"46.95600","3.91322","0.01394"
"47.03400","3.91974","0.01462"
"47.11200","3.92620","0.01434"
"47.19000","3.93278","0.01392"
"47.26800","3.93923","0.01393"
"47.34600","3.94569","0.01389"
"47.42400","3.95215","0.01384"
"47.50200","3.95866","0.01374"
"47.58000","3.96518","0.01404"
"47.65800","3.97176","0.01395"
"47.73600","3.97822","0.01387"
"47.81400","3.98467","0.01393"
"47.89200","3.99119","0.01399"
"47.97000","3.99765","0.01421"
"48.04800","4.00422","0.01397"
"48.12600","4.01068","0.01403"
"48.20400","4.01726","0.01434"
"48.28200","4.02372","0.01396"
"48.36000","4.03023","0.01420"
"48.43800","4.03669","0.01397"
"48.51600","4.04321","0.01394"
"48.59400","4.04966","0.01379"
"48.67200","4.05618","0.01376"
"48.75000","4.06270","0.01409"
"48.82800","4.06922","0.01398"
"48.90600","4.07573","0.01401"
"48.98400","4.08219","0.01419"
"49.06200","4.08871","0.01390"
"49.14000","4.09516","0.01401"
"49.21800","4.10174","0.01441"
"49.29600","4.10820","0.01401"
"49.37400","4.11478","0.01419"
"49.45200","4.12123","0.01435"
"49.53000","4.12769","0.01403"
"49.60800","4.13421","0.01374"
"49.68600","4.14072","0.01414"
"49.76400","4.14724","0.01424"
"49.84200","4.15376","0.01409"
"49.92000","4.16022","0.01427"
"49.99800","4.16673","0.01406"
"50.07600","4.17319","0.01439"
"50.15400","4.17965","0.01417"
"50.23200","4.18616","0.01424"
"50.31000","4.19274","0.01405"
"50.38800","4.19920","0.01424"
"50.46600","4.20577","0.01436"
"50.54400","4.21223","0.01390"
"50.62200","4.21869","0.01449"
"50.70000","4.22509","0.01396"
"50.77800","4.23172","0.01446"
"50.85600","4.23824","0.01433"
"50.93400","4.24476","0.01457"
"51.01200","4.25121","0.01422"
"51.09000","4.25773","0.01400"
"51.16800","4.26419","0.01444"
"51.24600","4.27065","0.01428"
"51.32400","4.27722","0.01415"
"51.40200","4.28374","0.01403"
"51.48000","4.29026","0.01407"
"51.55800","4.29671","0.01416"
"51.63600","4.30323","0.01396"
"51.71400","4.30969","0.01423"
"51.79200","4.31621","0.01408"
"51.87000","4.32266","0.01403"
"51.94800","4.32924","0.01426"
"52.02600","4.33570","0.01439"
"52.10400","4.34221","0.01417"
"52.18200","4.34873","0.01410"
"52.26000","4.35513","0.01423"
"52.33800","4.36171","0.01414"
"52.41600","4.36822","0.01453"
"52.49400","4.37474","0.01422"
"52.57200","4.38120","0.01381"
"52.65000","4.38777","0.01417"
"52.72800","4.39417","0.01416"
"52.80600","4.40075","0.01406"
"52.88400","4.40715","0.01437"
"52.96200","4.41366","0.01414"
"53.04000","4.42024","0.01414"
"53.11800","4.42670","0.01456"
"53.19600","4.43321","0.01436"
"53.27400","4.43967","0.01437"
"53.35200","4.44619","0.01421"
"53.43000","4.45265","0.01397"
"53.50800","4.45916","0.01402"
"53.58600","4.46574","0.01420"
"53.66400","4.47220","0.01408"
"53.74200","4.47871","0.01402"
"53.82000","4.48517","0.01473"
"53.89800","4.49163","0.01453"
"53.97600","4.49821","0.01416"
"54.05400","4.50472","0.01433"
"54.13200","4.51118","0.01413"
"54.21000","4.51776","0.01414"
"54.28800","4.52421","0.01414"
"54.36600","4.53073","0.01422"
"54.44400","4.53713","0.01424"
"54.52200","4.54371","0.01416"
"54.60000","4.55022","0.01412"
"54.67800","4.55674","0.01394"
"54.75600","4.56326","0.01418"
"54.83400","4.56971","0.01397"
"54.91200","4.57623","0.01422"
"54.99000","4.58269","0.01434"
"55.06800","4.58921","0.01424"
"55.14600","4.59572","0.01429"
"55.22400","4.60224","0.01412"
"55.30200","4.60876","0.01395"
"55.38000","4.61521","0.01420"
"55.45800","4.62173","0.01442"
"55.53600","4.62819","0.01451"
"55.61400","4.63471","0.01406"
"55.69200","4.64122","0.01431"
"55.77000","4.64774","0.01448"
"55.84800","4.65426","0.01419"
"55.92600","4.66071","0.01434"
"56.00400","4.66717","0.01410"
"56.08200","4.67369","0.01435"
"56.16000","4.68021","0.01464"
"56.23800","4.68678","0.01387"
"56.31600","4.69318","0.01428"
"56.39400","4.69976","0.01457"
"56.47200","4.70615","0.01382"
"56.55000","4.71267","0.01437"
"56.62800","4.71913","0.01441"
"56.70600","4.72570","0.01430"
"56.78400","4.73228","0.01452"
"56.86200","4.73874","0.01445"
"56.94000","4.74526","0.01442"
"57.01800","4.75171","0.01365"
"57.09600","4.75823","0.01412"
"57.17400","4.76469","0.01435"
"57.25200","4.77120","0.01375"
"57.33000","4.77772","0.01387"
"57.40800","4.78424","0.01424"
"57.48600","4.79070","0.01432"
"57.56400","4.79727","0.01436"
"57.64200","4.80373","0.01459"
"57.72000","4.81019","0.01433"
"57.79800","4.81676","0.01465"
"57.87600","4.82328","0.01468"
"57.95400","4.82974","0.01434"
"58.03200","4.83620","0.01413"
"58.11000","4.84271","0.01455"
"58.18800","4.84911","0.01471"
"58.26600","4.85569","0.01442"
"58.34400","4.86220","0.01416"
"58.42200","4.86872","0.01427"
"58.50000","4.87524","0.01440"
"58.57800","4.88170","0.01441"
"58.65600","4.88821","0.01422"
"58.73400","4.89467","0.01430"
"58.81200","4.90119","0.01417"
"58.89000","4.90770","0.01434"
"58.96800","4.91422","0.01489"
"59.04600","4.92074","0.01440"
"59.12400","4.92726","0.01436"
"59.20200","4.93371","0.01405"
"59.28000","4.94017","0.01432"
"59.35800","4.94669","0.01391"
"59.43600","4.95320","0.01424"
"59.51400","4.95972","0.01417"
"59.59200","4.96624","0.01432"
"59.67000","4.97276","0.01399"
"59.74800","4.97921","0.01440"
"59.82600","4.98567","0.01485"
"59.90400","4.99219","0.01432"
"59.98200","4.99876","0.01438"
"60.06000","5.00522","0.01412"
"60.13800","5.01174","0.01422"
"60.21600","5.01819","0.01424"
"60.29400","5.02465","0.01422"
"60.37200","5.03117","0.01457"
"60.45000","5.03763","0.01414"
"60.52800","5.04426","0.01402"
"60.60600","5.05072","0.01394"
"60.68400","5.05724","0.01479"
"60.76200","5.06369","0.01415"
"60.84000","5.07021","0.01383"
"60.91800","5.07667","0.01373"
"60.99600","5.08319","0.01348"
"61.07400","5.08970","0.01343"
"61.15200","5.09622","0.01348"
"61.23000","5.10274","0.01338"
"61.30800","5.10919","0.01342"
"61.38600","5.11565","0.01296"
"61.46400","5.12217","0.01327"
"61.54200","5.12869","0.01316"
"61.62000","5.13520","0.01328"
"61.69800","5.14172","0.01308"
"61.77600","5.14824","0.01320"
"61.85400","5.15469","0.01341"
"61.93200","5.16121","0.01332"
"62.01000","5.16767","0.01312"
"62.08800","5.17419","0.01352"
"62.16600","5.18076","0.01325"
"62.24400","5.18728","0.01367"
"62.32200","5.19374","0.01297"
"62.40000","5.20025","0.01317"
"62.47800","5.20671","0.01339"
"62.55600","5.21317","0.01315"
"62.63400","5.21969","0.01344"
"62.71200","5.22620","0.01341"
"62.79000","5.23266","0.01339"
"62.86800","5.23924","0.01294"
"62.94600","5.24564","0.01353"
"63.02400","5.25215","0.01334"
"63.10200","5.25867","0.01326"
"63.18000","5.26519","0.01304"
"63.25800","5.27176","0.01312"
"63.33600","5.27822","0.01336"
"63.41400","5.28474","0.01356"
"63.49200","5.29119","0.01320"
"63.57000","5.29771","0.01327"
"63.64800","5.30417","0.01336"
"63.72600","5.31075","0.01365"
"63.80400","5.31726","0.01306"
"63.88200","5.32372","0.01285"
"63.96000","5.33024","0.01344"
"64.03800","5.33669","0.01308"
"64.11600","5.34321","0.01317"
"64.19400","5.34967","0.01341"
"64.27200","5.35625","0.01331"
"64.35000","5.36270","0.01309"
"64.42800","5.36928","0.01324"
"64.50600","5.37568","0.01287"
"64.58400","5.38219","0.01351"
"64.66200","5.38871","0.01347"
"64.74000","5.39523","0.01299"
"64.81800","5.40175","0.01279"
"64.89600","5.40826","0.01317"
"64.97400","5.41472","0.01294"
"65.05200","5.42118","0.01291"
"65.13000","5.42769","0.01318"
"65.20800","5.43421","0.01332"
"65.28600","5.44067","0.01347"
"65.36400","5.44725","0.01304"
"65.44200","5.45370","0.01325"
"65.52000","5.46022","0.01325"
"65.59800","5.46668","0.01314"
"65.67600","5.47319","0.01276"
"65.75400","5.47965","0.01314"
"65.83200","5.48623","0.01308"
"65.91000","5.49268","0.01315"
"65.98800","5.49926","0.01303"
"66.06600","5.50572","0.01280"
"66.14400","5.51224","0.01306"
"66.22200","5.51863","0.01299"
"66.30000","5.52515","0.01258"
"66.37800","5.53173","0.01305"
"66.45600","5.53824","0.01316"
"66.53400","5.54470","0.01322"
"66.61200","5.55128","0.01305"
"66.69000","5.55774","0.01290"
"66.76800","5.56419","0.01324"
"66.84600","5.57065","0.01291"
"66.92400","5.57723","0.01304"
"67.00200","5.58374","0.01298"
"67.08000","5.59026","0.01319"
"67.15800","5.59678","0.01321"
"67.23600","5.60318","0.01283"
"67.31400","5.60969","0.01303"
"67.39200","5.61615","0.01302"
"67.47000","5.62273","0.01328"
"67.54800","5.62924","0.01293"
"67.62600","5.63570","0.01268"
"67.70400","5.64228","0.01293"
"67.78200","5.64868","0.01300"
"67.86000","5.65519","0.01309"
"67.93800","5.66165","0.01311"
"68.01600","5.66823","0.01297"
"68.09400","5.67474","0.01294"
"68.17200","5.68120","0.01307"
"68.25000","5.68772","0.01294"
"68.32800","5.69418","0.01309"
"68.40600","5.70069","0.01315"
"68.48400","5.70715","0.01297"
"68.56200","5.71373","0.01299"
"68.64000","5.72024","0.01290"
"68.71800","5.72676","0.01346"
"68.79600","5.73316","0.01361"
"68.87400","5.73968","0.01296"
"68.95200","5.74619","0.01293"
"69.03000","5.75265","0.01311"
"69.10800","5.75917","0.01313"
"69.18600","5.76568","0.01308"
"69.26400","5.77220","0.01285"
"69.34200","5.77866","0.01270"
"69.42000","5.78518","0.01295"
"69.49800","5.79163","0.01297"
"69.57600","5.79821","0.01337"
"69.65400","5.80467","0.01314"
"69.73200","5.81124","0.01313"
"69.81000","5.81770","0.01273"
"69.88800","5.82422","0.01300"
"69.96600","5.83068","0.01314"
"70.04400","5.83719","0.01304"
"70.12200","5.84371","0.01288"
"70.20000","5.85029","0.01307"
"70.27800","5.85674","0.01309"
"70.35600","5.86326","0.01291"
"70.43400","5.86972","0.01309"
"70.51200","5.87624","0.01287"
"70.59000","5.88269","0.01258"
"70.66800","5.88921","0.01317"
"70.74600","5.89573","0.01279"
"70.82400","5.90218","0.01312"
"70.90200","5.90876","0.01270"
"70.98000","5.91522","0.01280"
"71.05800","5.92173","0.01254"
"71.13600","5.92819","0.01268"
"71.21400","5.93471","0.01256"
"71.29200","5.94123","0.01262"
"71.37000","5.94768","0.01247"
"71.44800","5.95426","0.01297"
"71.52600","5.96072","0.01255"
"71.60400","5.96717","0.01271"
"71.68200","5.97363","0.01277"
"71.76000","5.98021","0.01287"
"71.83800","5.98673","0.01273"
"71.91600","5.99324","0.01308"
"71.99400","5.99976","0.01245"
"72.07200","6.00622","0.01257"
"72.15000","6.01273","0.01270"
"72.22800","6.01913","0.01291"
"72.30600","6.02577","0.01240"
"72.38400","6.03223","0.01261"
"72.46200","6.03874","0.01267"
"72.54000","6.04520","0.01251"
"72.61800","6.05172","0.01283"
"72.69600","6.05823","0.01271"
"72.77400","6.06469","0.01287"
"72.85200","6.07121","0.01284"
"72.93000","6.07773","0.01286"
"73.00800","6.08424","0.01290"
"73.08600","6.09070","0.01304"
"73.16400","6.09722","0.01290"
"73.24200","6.10367","0.01263"
"73.32000","6.11019","0.01298"
"73.39800","6.11671","0.01290"
"73.47600","6.12329","0.01286"
"73.55400","6.12968","0.01241"
"73.63200","6.13614","0.01229"
"73.71000","6.14266","0.01257"
"73.78800","6.14917","0.01232"
"73.86600","6.15569","0.01266"
"73.94400","6.16221","0.01240"
"74.02200","6.16879","0.01283"
"74.10000","6.17524","0.01266"
"74.17800","6.18170","0.01225"
"74.25600","6.18822","0.01276"
"74.33400","6.19467","0.01220"
"74.41200","6.20119","0.01313"
"74.49000","6.20771","0.01250"
"74.56800","6.21422","0.01247"
"74.64600","6.22074","0.01247"
"74.72400","6.22720","0.01258"
"74.80200","6.23366","0.01138"
"74.88000","6.24011","0.01114"
"74.95800","6.24669","0.01095"
"75.03600","6.25327","0.01106"
"75.11400","6.25973","0.01093"
"75.19200","6.26624","0.01092"
"75.27000","6.27270","0.01113"
"75.34800","6.27922","0.01152"
"75.42600","6.28567","0.01099"
"75.50400","6.29219","0.01120"
"75.58200","6.29877","0.01139"
"75.66000","6.30523","0.01088"
"75.73800","6.31174","0.01094"
"75.81600","6.31820","0.01131"
"75.89400","6.32472","0.01091"
"75.97200","6.33111","0.01135"
"76.05000","6.33769","0.01122"
"76.12800","6.34421","0.01083"
"76.20600","6.35073","0.01083"
"76.28400","6.35724","0.01108"
"76.36200","6.36376","0.01075"
"76.44000","6.37016","0.01095"
"76.51800","6.37661","0.01084"
"76.59600","6.38319","0.01101"
"76.67400","6.38971","0.01119"
"76.75200","6.39628","0.01129"
"76.83000","6.40268","0.01089"
"76.90800","6.40920","0.01100"
"76.98600","6.41566","0.01121"
"77.06400","6.42217","0.01090"
"77.14200","6.42863","0.01103"
"77.22000","6.43527","0.01106"
"77.29800","6.44172","0.01103"
"77.37600","6.44824","0.01127"
"77.45400","6.45476","0.01113"
"77.53200","6.46122","0.01135"
"77.61000","6.46773","0.01081"
"77.68800","6.47419","0.01076"
"77.76600","6.48077","0.01123"
"77.84400","6.48722","0.01110"
"77.92200","6.49374","0.01110"
"78.00000","6.50020","0.01134"
"78.07800","6.50672","0.01118"
"78.15600","6.51317","0.01122"
"78.23400","6.51969","0.01094"
"78.31200","6.52621","0.01113"
"78.39000","6.53278","0.01144"
"78.46800","6.53924","0.01097"
"78.54600","6.54570","0.01103"
"78.62400","6.55216","0.01140"
"78.70200","6.55867","0.01117"
"78.78000","6.56519","0.01077"
"78.85800","6.57171","0.01089"
"78.93600","6.57822","0.01113"
"79.01400","6.58474","0.01084"
"79.09200","6.59120","0.01104"
"79.17000","6.59771","0.01105"
"79.24800","6.60417","0.01099"
"79.32600","6.61075","0.01105"
"79.40400","6.61721","0.01147"
"79.48200","6.62378","0.01121"
"79.56000","6.63024","0.01072"
"79.63800","6.63670","0.01086"
"79.71600","6.64316","0.01080"
"79.79400","6.64967","0.01113"
"79.87200","6.65625","0.01112"
"79.95000","6.66271","0.01100"
"80.02800","6.66922","0.01079"
"80.10600","6.67574","0.01088"
"80.18400","6.68226","0.01124"
"80.26200","6.68866","0.01083"
"80.34000","6.69523","0.01107"
"80.41800","6.70175","0.01108"
"80.49600","6.70827","0.01103"
"80.57400","6.71466","0.01112"
"80.65200","6.72124","0.01081"
"80.73000","6.72770","0.01114"
"80.80800","6.73416","0.01114"
"80.88600","6.74067","0.01088"
"80.96400","6.74719","0.01092"
"81.04200","6.75377","0.01111"
"81.12000","6.76022","0.01114"
"81.19800","6.76674","0.01099"
"81.27600","6.77314","0.01099"
"81.35400","6.77971","0.01115"
"81.43200","6.78617","0.01109"
"81.51000","6.79275","0.01104"
"81.58800","6.79921","0.01118"
"81.66600","6.80572","0.01064"
"81.74400","6.81218","0.01116"
"81.82200","6.81870","0.01121"
"81.90000","6.82516","0.01127"
"81.97800","6.83173","0.01086"
"82.05600","6.83819","0.01139"
"82.13400","6.84471","0.01133"
"82.21200","6.85116","0.01106"
"82.29000","6.85768","0.01106"
"82.36800","6.86420","0.01111"
"82.44600","6.87066","0.01107"
"82.52400","6.87717","0.01114"
"82.60200","6.88369","0.01101"
"82.68000","6.89021","0.01103"
"82.75800","6.89672","0.01081"
"82.83600","6.90318","0.01078"
"82.91400","6.90970","0.01083"
"82.99200","6.91615","0.01122"
"83.07000","6.92273","0.01094"
"83.14800","6.92919","0.01114"
"83.22600","6.93571","0.01084"
"83.30400","6.94222","0.01099"
"83.38200","6.94874","0.01091"
"83.46000","6.95520","0.01069"
"83.53800","6.96171","0.01068"
"83.61600","6.96823","0.01081"
"83.69400","6.97475","0.01105"
"83.77200","6.98121","0.01100"
"83.85000","6.98772","0.01082"
"83.92800","6.99424","0.01066"
"84.00600","7.00064","0.01073"
"84.08400","7.00721","0.01074"
"84.16200","7.01367","0.01049"
"84.24000","7.02025","0.01117"
"84.31800","7.02671","0.01052"
"84.39600","7.03316","0.01084"
"84.47400","7.03968","0.01105"
"84.55200","7.04620","0.01065"
"84.63000","7.05271","0.01082"
"84.70800","7.05917","0.01059"
"84.78600","7.06581","0.01065"
"84.86400","7.07227","0.01086"
"84.94200","7.07878","0.01087"
"85.02000","7.08518","0.01101"
"85.09800","7.09170","0.01088"
"85.17600","7.09821","0.01074"
"85.25400","7.10473","0.01119"
"85.33200","7.11125","0.01057"
"85.41000","7.11776","0.01090"
"85.48800","7.12422","0.01071"
"85.56600","7.13068","0.01058"
"85.64400","7.13720","0.01068"
"85.72200","7.14365","0.01081"
"85.80000","7.15023","0.01098"
"85.87800","7.15675","0.01047"
"85.95600","7.16320","0.01111"
"86.03400","7.16966","0.01064"
"86.11200","7.17618","0.01095"
"86.19000","7.18264","0.01084"
"86.26800","7.18921","0.01087"
"86.34600","7.19567","0.01059"
"86.42400","7.20225","0.01102"
"86.50200","7.20876","0.01064"
"86.58000","7.21522","0.01070"
"86.65800","7.22174","0.01059"
"86.73600","7.22814","0.01093"
"86.81400","7.23471","0.01078"
"86.89200","7.24117","0.01098"
"86.97000","7.24775","0.01054"
"87.04800","7.25426","0.01085"
"87.12600","7.26066","0.01066"
"87.20400","7.26718","0.01068"
"87.28200","7.27364","0.01075"
"87.36000","7.28021","0.01085"
"87.43800","7.28673","0.01129"
"87.51600","7.29319","0.01085"
"87.59400","7.29976","0.01122"
"87.67200","7.30622","0.01089"
"87.75000","7.31268","0.01073"
"87.82800","7.31920","0.01129"
"87.90600","7.32571","0.01084"
"87.98400","7.33223","0.01096"
"88.06200","7.33875","0.01065"
"88.14000","7.34520","0.01077"
"88.21800","7.35172","0.01089"
"88.29600","7.35818","0.01056"
"88.37400","7.36470","0.01062"
"88.45200","7.37115","0.01066"
"88.53000","7.37773","0.01058"
"88.60800","7.38419","0.01069"
"88.68600","7.39076","0.01077"
"88.76400","7.39722","0.01074"
"88.84200","7.40368","0.01090"
"88.92000","7.41014","0.01110"
"88.99800","7.41671","0.01062"
"89.07600","7.42329","0.01083"
"89.15400","7.42969","0.01077"
"89.23200","7.43626","0.01099"
"89.31000","7.44272","0.01102"
"89.38800","7.44918","0.01080"
"89.46600","7.45564","0.01080"
"89.54400","7.46221","0.01090"
"89.62200","7.46873","0.01055"
"89.70000","7.47519","0.01081"
"89.77800","7.48170","0.01065"
"89.85600","7.48822","0.01068"
"89.93400","7.49468","0.01087"
"90.01200","7.50119","0.01053"
"90.09000","7.50771","0.01065"
"90.16800","7.51423","0.01009"
"90.24600","7.52075","0.00982"
"90.32400","7.52720","0.00850"
"90.40200","7.53372","0.00878"
"90.48000","7.54018","0.00802"
"90.55800","7.54669","0.00852"
"90.63600","7.55321","0.00815"
"90.71400","7.55973","0.00835"
"90.79200","7.56619","0.00871"
"90.87000","7.57270","0.00850"
"90.94800","7.57916","0.00946"
"91.02600","7.58568","0.01002"
"91.10400","7.59220","0.01007"
"91.18200","7.59877","0.01024"
"91.26000","7.60523","0.01029"
"91.33800","7.61169","0.00916"
"91.41600","7.61820","0.00914"
"91.49400","7.62466","0.00843"
"91.57200","7.63118","0.00812"
"91.65000","7.63769","0.00819"
"91.72800","7.64421","0.00850"
"91.80600","7.65073","0.00840"
"91.88400","7.65719","0.00856"
"91.96200","7.66370","0.00841"
"92.04000","7.67016","0.00843"
"92.11800","7.67668","0.00875"
"92.19600","7.68319","0.00871"
"92.27400","7.68977","0.00847"
"92.35200","7.69623","0.00856"
"92.43000","7.70275","0.00874"
"92.50800","7.70926","0.00854"
"92.58600","7.71572","0.00836"
"92.66400","7.72224","0.00834"
"92.74200","7.72869","0.00845"
"92.82000","7.73527","0.00841"
"92.89800","7.74173","0.00927"
"92.97600","7.74825","0.00873"
"93.05400","7.75470","0.00911"
"93.13200","7.76116","0.00938"
"93.21000","7.76768","0.00959"
"93.28800","7.77419","0.00940"
"93.36600","7.78071","0.00914"
"93.44400","7.78723","0.00937"
"93.52200","7.79375","0.00961"
"93.60000","7.80026","0.00958"
"93.67800","7.80672","0.00941"
"93.75600","7.81318","0.00878"
"93.83400","7.81969","0.00881"
"93.91200","7.82627","0.00912"
"93.99000","7.83273","0.00939"
"94.06800","7.83924","0.00940"
"94.14600","7.84576","0.00914"
"94.22400","7.85216","0.00915"
"94.30200","7.85862","0.00865"
"94.38000","7.86525","0.00874"
"94.45800","7.87171","0.00916"
"94.53600","7.87829","0.00903"
"94.61400","7.88474","0.00943"
"94.69200","7.89126","0.00932"
"94.77000","7.89772","0.00955"
"94.84800","7.90418","0.00923"
"94.92600","7.91069","0.00903"
"95.00400","7.91721","0.00947"
"95.08200","7.92373","0.00926"
"95.16000","7.93018","0.00928"
"95.23800","7.93664","0.00916"
"95.31600","7.94316","0.00942"
"95.39400","7.94968","0.00920"
"95.47200","7.95619","0.00896"
"95.55000","7.96271","0.00910"
"95.62800","7.96923","0.00914"
"95.70600","7.97574","0.00906"
"95.78400","7.98220","0.00928"
"95.86200","7.98872","0.00920"
"95.94000","7.99518","0.00908"
"96.01800","8.00169","0.00936"
"96.09600","8.00821","0.00928"
"96.17400","8.01473","0.00968"
"96.25200","8.02124","0.00959"
"96.33000","8.02770","0.00938"
"96.40800","8.03422","0.00940"
"96.48600","8.04062","0.00928"
"96.56400","8.04725","0.00935"
"96.64200","8.05371","0.00936"
"96.72000","8.06029","0.00902"
"96.79800","8.06668","0.00950"
"96.87600","8.07320","0.00926"
"96.95400","8.07966","0.00939"
"97.03200","8.08618","0.00932"
"97.11000","8.09275","0.00945"
"97.18800","8.09921","0.00944"
"97.26600","8.10579","0.00964"
"97.34400","8.11224","0.00929"
"97.42200","8.11870","0.00925"
"97.50000","8.12516","0.00962"
"97.57800","8.13168","0.00935"
"97.65600","8.13825","0.00973"
"97.73400","8.14471","0.00975"
"97.81200","8.15123","0.00969"
"97.89000","8.15774","0.00951"
"97.96800","8.16426","0.00917"
"98.04600","8.17066","0.00954"
"98.12400","8.17723","0.00943"
"98.20200","8.18369","0.00917"
"98.28000","8.19027","0.00924"
"98.35800","8.19673","0.00939"
"98.43600","8.20324","0.00920"
"98.51400","8.20970","0.00947"
"98.59200","8.21616","0.00930"
"98.67000","8.22268","0.00941"
"98.74800","8.22919","0.01048"
"98.82600","8.23571","0.01068"
"98.90400","8.24229","0.01148"
"98.98200","8.24874","0.01133"
"99.06000","8.25520","0.01176"
"99.13800","8.26166","0.01164"
"99.21600","8.26823","0.00974"
"99.29400","8.27475","0.01049"
"99.37200","8.28121","0.00864"
"99.45000","8.28773","0.00812"
"99.52800","8.29418","0.00838"
"99.60600","8.30070","0.00776"
"99.68400","8.30722","0.00799"
"99.76200","8.31373","0.00849"
"99.84000","8.32025","0.00824"
"99.91800","8.32671","0.00864"
"99.99600","8.33323","0.00851"
"100.07400","8.33968","0.00907"
"100.15200","8.34620","0.00890"
"100.23000","8.35266","0.00918"
"100.30800","8.35917","0.00873"
"100.38600","8.36569","0.00818"
"100.46400","8.37221","0.00838"
"100.54200","8.37873","0.00827"
"100.62000","8.38518","0.00853"
"100.69800","8.39170","0.00820"
"100.77600","8.39816","0.00862"
"100.85400","8.40473","0.00866"
"100.93200","8.41119","0.00879"
"101.01000","8.41777","0.00874"
"101.08800","8.42417","0.00888"
"101.16600","8.43068","0.00861"
"101.24400","8.43714","0.00863"
"101.32200","8.44372","0.00855"
"101.40000","8.45023","0.00832"
"101.47800","8.45675","0.00869"
"101.55600","8.46321","0.00875"
"101.63400","8.46967","0.00860"
"101.71200","8.47618","0.00866"
"101.79000","8.48264","0.00881"
"101.86800","8.48922","0.00869"
"101.94600","8.49573","0.00901"
"102.02400","8.50225","0.00867"
"102.10200","8.50871","0.00852"
"102.18000","8.51529","0.00874"
"102.25800","8.52168","0.00836"
"102.33600","8.52814","0.00881"
"102.41400","8.53472","0.00875"
"102.49200","8.54123","0.00867"
"102.57000","8.54775","0.00883"
"102.64800","8.55427","0.00854"
"102.72600","8.56073","0.00882"
"102.80400","8.56724","0.00895"
"102.88200","8.57364","0.00859"
"102.96000","8.58022","0.00870"
"103.03800","8.58673","0.00871"
"103.11600","8.59325","0.00865"
"103.19400","8.59977","0.00889"
"103.27200","8.60623","0.00921"
"103.35000","8.61274","0.00885"
"103.42800","8.61920","0.00877"
"103.50600","8.62572","0.00889"
"103.58400","8.63229","0.00902"
"103.66200","8.63875","0.00864"
"103.74000","8.64527","0.00902"
"103.81800","8.65166","0.00866"
"103.89600","8.65818","0.00891"
"103.97400","8.66464","0.00888"
"104.05200","8.67122","0.00908"
"104.13000","8.67773","0.00904"
"104.20800","8.68419","0.00877"
"104.28600","8.69077","0.00928"
"104.36400","8.69717","0.00897"
"104.44200","8.70368","0.00894"
"104.52000","8.71014","0.00897"
"104.59800","8.71678","0.00889"
"104.67600","8.72317","0.00890"
"104.75400","8.72975","0.00920"
"104.83200","8.73621","0.00893"
"104.91000","8.74272","0.00905"
"104.98800","8.74918","0.00887"
"105.06600","8.75570","0.00905"
"105.14400","8.76222","0.00933"
"105.22200","8.76873","0.00935"
"105.30000","8.77525","0.00876"
"105.37800","8.78177","0.00900"
"105.45600","8.78822","0.00886"
"105.53400","8.79468","0.00881"
"105.61200","8.80120","0.00899"
"105.69000","8.80772","0.00855"
"105.76800","8.81423","0.00917"
"105.84600","8.82069","0.00914"
"105.92400","8.82721","0.00874"
"106.00200","8.83366","0.00937"
"106.08000","8.84018","0.00950"
"106.15800","8.84670","0.00876"
"106.23600","8.85322","0.00908"
"106.31400","8.85973","0.00891"
"106.39200","8.86625","0.00880"
"106.47000","8.87271","0.00899"
"106.54800","8.87922","0.00921"
"106.62600","8.88568","0.00885"
"106.70400","8.89220","0.00874"
"106.78200","8.89872","0.00883"
"106.86000","8.90523","0.00879"
"106.93800","8.91175","0.00904"
"107.01600","8.91821","0.00860"
"107.09400","8.92472","0.00884"
"107.17200","8.93118","0.00871"
"107.25000","8.93764","0.00895"
"107.32800","8.94421","0.00889"
"107.40600","8.95067","0.00906"
"107.48400","8.95719","0.00892"
"107.56200","8.96371","0.00920"
"107.64000","8.97016","0.00900"
"107.71800","8.97668","0.00891"
"107.79600","8.98320","0.00898"
"107.87400","8.98977","0.00915"
"107.95200","8.99623","0.00903"
"108.03000","9.00275","0.00891"
"108.10800","9.00921","0.00914"
"108.18600","9.01572","0.00899"
"108.26400","9.02218","0.00915"
"108.34200","9.02870","0.00922"
"108.42000","9.03521","0.00936"
"108.49800","9.04173","0.00881"
"108.57600","9.04825","0.00901"
"108.65400","9.05465","0.00926"
"108.73200","9.06122","0.00932"
"108.81000","9.06768","0.00886"
"108.88800","9.07426","0.00924"
"108.96600","9.08071","0.00934"
"109.04400","9.08723","0.00952"
"109.12200","9.09375","0.00897"
"109.20000","9.10021","0.00926"
"109.27800","9.10666","0.00887"
"109.35600","9.11318","0.00940"
"109.43400","9.11970","0.00920"
"109.51200","9.12621","0.00927"
"109.59000","9.13273","0.00914"
"109.66800","9.13919","0.00896"
"109.74600","9.14577","0.00925"
"109.82400","9.15216","0.00933"
"109.90200","9.15868","0.00906"
"109.98000","9.16520","0.00939"
"110.05800","9.17177","0.00950"
"110.13600","9.17823","0.00932"
"110.21400","9.18475","0.00941"
"110.29200","9.19121","0.00917"
"110.37000","9.19766","0.00945"
"110.44800","9.20418","0.00909"
"110.52600","9.21070","0.00917"
"110.60400","9.21721","0.00904"
"110.68200","9.22373","0.00912"
"110.76000","9.23019","0.00928"
"110.83800","9.23671","0.00934"
"110.91600","9.24316","0.00932"
"110.99400","9.24968","0.00945"
"111.07200","9.25620","0.00950"
"111.15000","9.26271","0.00921"
"111.22800","9.26923","0.00947"
"111.30600","9.27569","0.00908"
"111.38400","9.28221","0.00940"
"111.46200","9.28866","0.00945"
"111.54000","9.29512","0.00918"
"111.61800","9.30170","0.00954"
"111.69600","9.30821","0.00937"
"111.77400","9.31473","0.00935"
"111.85200","9.32125","0.00908"
"111.93000","9.32771","0.00925"
"112.00800","9.33416","0.00944"
"112.08600","9.34068","0.00930"
"112.16400","9.34720","0.00926"
"112.24200","9.35371","0.00941"
"112.32000","9.36023","0.00921"
"112.39800","9.36669","0.00892"
"112.47600","9.37321","0.00945"
"112.55400","9.37966","0.00914"
"112.63200","9.38624","0.00951"
"112.71000","9.39264","0.00969"
"112.78800","9.39921","0.00951"
"112.86600","9.40573","0.00951"
"112.94400","9.41225","0.00931"
"113.02200","9.41870","0.00945"
"113.10000","9.42516","0.00962"
"113.11400","9.42630","0.00934"