File: Force_trajectories/161217/Specimen_RawData_3.csv
End date,"12/17/2016"
Specimen label,"6CT_43"
Maximum Load,"0.38913",N

Time,Extension,Load
(s),(mm),(N)
"0.00000","0.00000","-0.00001"
"0.18600","0.01160","0.00023"
"0.37200","0.03103","0.00127"
"0.55800","0.04676","0.00166"
"0.74400","0.06218","0.00202"
"0.93000","0.07767","0.00230"
"1.11600","0.09321","0.00256"
"1.30200","0.10870","0.00288"
"1.48800","0.12412","0.00317"
"1.67400","0.13973","0.00324"
"1.86000","0.15515","0.00309"
"2.04600","0.17064","0.00329"
"2.23200","0.18624","0.00336"
"2.41800","0.20167","0.00351"
"2.60400","0.21716","0.00409"
"2.79000","0.23270","0.00366"
"2.97600","0.24825","0.00396"
"3.16200","0.26361","0.00394"
"3.34800","0.27916","0.00409"
"3.53400","0.29470","0.00403"
"3.72000","0.31013","0.00410"
"3.90600","0.32567","0.00383"
"4.09200","0.34116","0.00421"
"4.27800","0.35664","0.00439"
"4.46400","0.37219","0.00429"
"4.65000","0.38768","0.00453"
"4.83600","0.40316","0.00457"
"5.02200","0.41865","0.00430"
"5.20800","0.43407","0.00444"
"5.39400","0.44962","0.00439"
"5.58000","0.46516","0.00436"
"5.76600","0.48059","0.00471"
"5.95200","0.49619","0.00434"
"6.13800","0.51168","0.00460"
"6.32400","0.52710","0.00486"
"6.51000","0.54271","0.00461"
"6.69600","0.55814","0.00498"
"6.88200","0.57362","0.00494"
"7.06800","0.58917","0.00483"
"7.25400","0.60465","0.00476"
"7.44000","0.62008","0.00465"
"7.62600","0.63562","0.00478"
"7.81200","0.65117","0.00502"
"7.99800","0.66659","0.00499"
"8.18400","0.68220","0.00507"
"8.37000","0.69768","0.00482"
"8.55600","0.71311","0.00496"
"8.74200","0.72871","0.00509"
"8.92800","0.74414","0.00524"
"9.11400","0.75969","0.00481"
"9.30000","0.77517","0.00506"
"9.48600","0.79066","0.00521"
"9.67200","0.80608","0.00532"
"9.85800","0.82169","0.00504"
"10.04400","0.83717","0.00520"
"10.23000","0.85266","0.00533"
"10.41600","0.86820","0.00514"
"10.60200","0.88369","0.00558"
"10.78800","0.89917","0.00525"
"10.97400","0.91466","0.00534"
"11.16000","0.93015","0.00524"
"11.34600","0.94563","0.00538"
"11.53200","0.96118","0.00544"
"11.71800","0.97660","0.00547"
"11.90400","0.99215","0.00558"
"12.09000","1.00769","0.00539"
"12.27600","1.02312","0.00569"
"12.46200","1.03866","0.00544"
"12.64800","1.05415","0.00554"
"12.83400","1.06963","0.00585"
"13.02000","1.08518","0.00540"
"13.20600","1.10067","0.00549"
"13.39200","1.11609","0.00543"
"13.57800","1.13170","0.00583"
"13.76400","1.14712","0.00590"
"13.95000","1.16261","0.00615"
"14.13600","1.17815","0.00561"
"14.32200","1.19364","0.00596"
"14.50800","1.20912","0.00621"
"14.69400","1.22467","0.00617"
"14.88000","1.24021","0.00588"
"15.06600","1.25564","0.00618"
"15.25200","1.27113","0.00586"
"15.43800","1.28667","0.00586"
"15.62400","1.30216","0.00598"
"15.81000","1.31770","0.00608"
"15.99600","1.33313","0.00622"
"16.18200","1.34861","0.00581"
"16.36800","1.36416","0.00580"
"16.55400","1.37964","0.00602"
"16.74000","1.39519","0.00635"
"16.92600","1.41067","0.00634"
"17.11200","1.42610","0.00646"
"17.29800","1.44170","0.00613"
"17.48400","1.45719","0.00629"
"17.67000","1.47262","0.00627"
"17.85600","1.48816","0.00628"
"18.04200","1.50365","0.00638"
"18.22800","1.51907","0.00630"
"18.41400","1.53462","0.00627"
"18.60000","1.55022","0.00647"
"18.78600","1.56559","0.00599"
"18.97200","1.58119","0.00662"
"19.15800","1.59668","0.00636"
"19.34400","1.61216","0.00647"
"19.53000","1.62771","0.00656"
"19.71600","1.64314","0.00649"
"19.90200","1.65862","0.00676"
"20.08800","1.67417","0.00661"
"20.27400","1.68965","0.00697"
"20.46000","1.70514","0.00661"
"20.64600","1.72062","0.00672"
"20.83200","1.73617","0.00669"
"21.01800","1.75165","0.00658"
"21.20400","1.76720","0.00664"
"21.39000","1.78262","0.00712"
"21.57600","1.79817","0.00676"
"21.76200","1.81372","0.00687"
"21.94800","1.82914","0.00697"
"22.13400","1.84463","0.00690"
"22.32000","1.86017","0.00708"
"22.50600","1.87560","0.00690"
"22.69200","1.89114","0.00684"
"22.87800","1.90669","0.00731"
"23.06400","1.92217","0.00711"
"23.25000","1.93766","0.00731"
"23.43600","1.95314","0.00720"
"23.62200","1.96863","0.00696"
"23.80800","1.98424","0.00723"
"23.99400","1.99966","0.00704"
"24.18000","2.01515","0.00751"
"24.36600","2.03069","0.00743"
"24.55200","2.04612","0.00721"
"24.73800","2.06160","0.00718"
"24.92400","2.07721","0.00740"
"25.11000","2.09263","0.00743"
"25.29600","2.10812","0.00757"
"25.48200","2.12372","0.00768"
"25.66800","2.13915","0.00779"
"25.85400","2.15458","0.00751"
"26.04000","2.17018","0.00759"
"26.22600","2.18567","0.00763"
"26.41200","2.20109","0.00766"
"26.59800","2.21670","0.00779"
"26.78400","2.23212","0.00806"
"26.97000","2.24761","0.00790"
"27.15600","2.26321","0.00756"
"27.34200","2.27864","0.00779"
"27.52800","2.29412","0.00770"
"27.71400","2.30973","0.00778"
"27.90000","2.32516","0.00793"
"28.08600","2.34064","0.00811"
"28.27200","2.35619","0.00834"
"28.45800","2.37155","0.00789"
"28.64400","2.38722","0.00791"
"28.83000","2.40270","0.00855"
"29.01600","2.41807","0.00817"
"29.20200","2.43367","0.00825"
"29.38800","2.44916","0.00831"
"29.57400","2.46458","0.00819"
"29.76000","2.48019","0.00817"
"29.94600","2.49567","0.00852"
"30.13200","2.51110","0.00850"
"30.31800","2.52665","0.00856"
"30.50400","2.54219","0.00796"
"30.69000","2.55762","0.00901"
"30.87600","2.57310","0.00880"
"31.06200","2.58859","0.00872"
"31.24800","2.60413","0.00835"
"31.43400","2.61968","0.00811"
"31.62000","2.63516","0.00872"
"31.80600","2.65071","0.00872"
"31.99200","2.66619","0.00773"
"32.17800","2.68162","0.00780"
"32.36400","2.69717","0.00762"
"32.55000","2.71265","0.00785"
"32.73600","2.72814","0.00824"
"32.92200","2.74368","0.00765"
"33.10800","2.75917","0.00804"
"33.29400","2.77459","0.00768"
"33.48000","2.79020","0.00815"
"33.66600","2.80574","0.00802"
"33.85200","2.82105","0.00825"
"34.03800","2.83671","0.00849"
"34.22400","2.85220","0.00820"
"34.41000","2.86763","0.00778"
"34.59600","2.88317","0.00820"
"34.78200","2.89866","0.00813"
"34.96800","2.91414","0.00819"
"35.15400","2.92975","0.00855"
"35.34000","2.94511","0.00831"
"35.52600","2.96060","0.00838"
"35.71200","2.97614","0.00863"
"35.89800","2.99163","0.00859"
"36.08400","3.00717","0.00895"
"36.27000","3.02266","0.00857"
"36.45600","3.03815","0.00858"
"36.64200","3.05363","0.00880"
"36.82800","3.06918","0.00868"
"37.01400","3.08472","0.00882"
"37.20000","3.10015","0.00895"
"37.38600","3.11569","0.00875"
"37.57200","3.13112","0.00882"
"37.75800","3.14666","0.00875"
"37.94400","3.16215","0.00890"
"38.13000","3.17763","0.00909"
"38.31600","3.19318","0.00899"
"38.50200","3.20866","0.00907"
"38.68800","3.22415","0.00903"
"38.87400","3.23970","0.00936"
"39.06000","3.25518","0.00962"
"39.24600","3.27067","0.00930"
"39.43200","3.28621","0.00925"
"39.61800","3.30158","0.00937"
"39.80400","3.31712","0.00937"
"39.99000","3.33273","0.00941"
"40.17600","3.34815","0.00935"
"40.36200","3.36364","0.00958"
"40.54800","3.37912","0.00980"
"40.73400","3.39461","0.00964"
"40.92000","3.41016","0.00957"
"41.10600","3.42570","0.00943"
"41.29200","3.44119","0.00966"
"41.47800","3.45661","0.00978"
"41.66400","3.47216","0.00979"
"41.85000","3.48764","0.00964"
"42.03600","3.50313","0.00996"
"42.22200","3.51867","0.01019"
"42.40800","3.53410","0.01000"
"42.59400","3.54964","0.01030"
"42.78000","3.56519","0.00968"
"42.96600","3.58068","0.00995"
"43.15200","3.59622","0.01013"
"43.33800","3.61165","0.01008"
"43.52400","3.62713","0.01000"
"43.71000","3.64268","0.01016"
"43.89600","3.65816","0.01078"
"44.08200","3.67359","0.01014"
"44.26800","3.68919","0.01046"
"44.45400","3.70468","0.01053"
"44.64000","3.72010","0.01055"
"44.82600","3.73571","0.01077"
"45.01200","3.75120","0.01020"
"45.19800","3.76662","0.01078"
"45.38400","3.78217","0.01015"
"45.57000","3.79771","0.01070"
"45.75600","3.81314","0.01096"
"45.94200","3.82862","0.01110"
"46.12800","3.84417","0.01123"
"46.31400","3.85965","0.01095"
"46.50000","3.87520","0.01102"
"46.68600","3.89068","0.01105"
"46.87200","3.90617","0.01073"
"47.05800","3.92165","0.01127"
"47.24400","3.93714","0.01127"
"47.43000","3.95269","0.01095"
"47.61600","3.96817","0.01081"
"47.80200","3.98366","0.01124"
"47.98800","3.99914","0.01138"
"48.17400","4.01463","0.01160"
"48.36000","4.03011","0.01143"
"48.54600","4.04566","0.01088"
"48.73200","4.06114","0.01119"
"48.91800","4.07663","0.01088"
"49.10400","4.09218","0.01134"
"49.29000","4.10766","0.01113"
"49.47600","4.12315","0.01134"
"49.66200","4.13869","0.01183"
"49.84800","4.15418","0.01102"
"50.03400","4.16966","0.01177"
"50.22000","4.18515","0.01170"
"50.40600","4.20063","0.01123"
"50.59200","4.21612","0.01173"
"50.77800","4.23166","0.01126"
"50.96400","4.24715","0.01181"
"51.15000","4.26264","0.01185"
"51.33600","4.27818","0.01155"
"51.52200","4.29361","0.01231"
"51.70800","4.30915","0.01218"
"51.89400","4.32470","0.01187"
"52.08000","4.34012","0.01212"
"52.26600","4.35567","0.01174"
"52.45200","4.37121","0.01167"
"52.63800","4.38664","0.01178"
"52.82400","4.40212","0.01201"
"53.01000","4.41773","0.01168"
"53.19600","4.43315","0.01212"
"53.38200","4.44864","0.01198"
"53.56800","4.46419","0.01201"
"53.75400","4.47967","0.01238"
"53.94000","4.49516","0.01209"
"54.12600","4.51070","0.01252"
"54.31200","4.52613","0.01258"
"54.49800","4.54161","0.01256"
"54.68400","4.55716","0.01249"
"54.87000","4.57258","0.01244"
"55.05600","4.58819","0.01270"
"55.24200","4.60367","0.01301"
"55.42800","4.61910","0.01333"
"55.61400","4.63471","0.01312"
"55.80000","4.65013","0.01261"
"55.98600","4.66568","0.01303"
"56.17200","4.68116","0.01329"
"56.35800","4.69665","0.01332"
"56.54400","4.71213","0.01319"
"56.73000","4.72768","0.01370"
"56.91600","4.74316","0.01382"
"57.10200","4.75865","0.01357"
"57.28800","4.77413","0.01361"
"57.47400","4.78962","0.01394"
"57.66000","4.80517","0.01396"
"57.84600","4.82065","0.01381"
"58.03200","4.83614","0.01433"
"58.21800","4.85168","0.01435"
"58.40400","4.86717","0.01419"
"58.59000","4.88259","0.01460"
"58.77600","4.89820","0.01469"
"58.96200","4.91362","0.01435"
"59.14800","4.92911","0.01480"
"59.33400","4.94471","0.01496"
"59.52000","4.96014","0.01498"
"59.70600","4.97563","0.01451"
"59.89200","4.99117","0.01510"
"60.07800","5.00666","0.01523"
"60.26400","5.02208","0.01515"
"60.45000","5.03769","0.01543"
"60.63600","5.05323","0.01531"
"60.82200","5.06866","0.01558"
"61.00800","5.08414","0.01540"
"61.19400","5.09963","0.01607"
"61.38000","5.11511","0.01593"
"61.56600","5.13066","0.01588"
"61.75200","5.14614","0.01593"
"61.93800","5.16169","0.01614"
"62.12400","5.17718","0.01638"
"62.31000","5.19260","0.01668"
"62.49600","5.20815","0.01640"
"62.68200","5.22369","0.01657"
"62.86800","5.23912","0.01659"
"63.05400","5.25466","0.01665"
"63.24000","5.27015","0.01641"
"63.42600","5.28563","0.01675"
"63.61200","5.30118","0.01706"
"63.79800","5.31666","0.01683"
"63.98400","5.33209","0.01704"
"64.17000","5.34764","0.01723"
"64.35600","5.36318","0.01690"
"64.54200","5.37867","0.01647"
"64.72800","5.39415","0.01660"
"64.91400","5.40964","0.01624"
"65.10000","5.42512","0.01679"
"65.28600","5.44067","0.01644"
"65.47200","5.45609","0.01684"
"65.65800","5.47170","0.01716"
"65.84400","5.48712","0.01718"
"66.03000","5.50261","0.01720"
"66.21600","5.51816","0.01735"
"66.40200","5.53370","0.01735"
"66.58800","5.54913","0.01746"
"66.77400","5.56467","0.01758"
"66.96000","5.58022","0.01803"
"67.14600","5.59564","0.01809"
"67.33200","5.61119","0.01803"
"67.51800","5.62667","0.01793"
"67.70400","5.64210","0.01834"
"67.89000","5.65764","0.01836"
"68.07600","5.67319","0.01914"
"68.26200","5.68862","0.01905"
"68.44800","5.70416","0.01887"
"68.63400","5.71965","0.01915"
"68.82000","5.73513","0.01946"
"69.00600","5.75068","0.01976"
"69.19200","5.76616","0.01962"
"69.37800","5.78165","0.01940"
"69.56400","5.79719","0.01926"
"69.75000","5.81262","0.01950"
"69.93600","5.82810","0.01983"
"70.12200","5.84371","0.01993"
"70.30800","5.85913","0.02080"
"70.49400","5.87462","0.02071"
"70.68000","5.89023","0.02001"
"70.86600","5.90565","0.02103"
"71.05200","5.92114","0.02118"
"71.23800","5.93662","0.02109"
"71.42400","5.95211","0.02178"
"71.61000","5.96765","0.02143"
"71.79600","5.98314","0.02216"
"71.98200","5.99868","0.02218"
"72.16800","6.01411","0.02249"
"72.35400","6.02965","0.02230"
"72.54000","6.04514","0.02266"
"72.72600","6.06063","0.02283"
"72.91200","6.07617","0.02290"
"73.09800","6.09166","0.02336"
"73.28400","6.10720","0.02317"
"73.47000","6.12269","0.02322"
"73.65600","6.13811","0.02386"
"73.84200","6.15372","0.02444"
"74.02800","6.16914","0.02398"
"74.21400","6.18457","0.02431"
"74.40000","6.20023","0.02463"
"74.58600","6.21566","0.02467"
"74.77200","6.23115","0.02546"
"74.95800","6.24669","0.02493"
"75.14400","6.26218","0.02518"
"75.33000","6.27766","0.02606"
"75.51600","6.29315","0.02578"
"75.70200","6.30869","0.02656"
"75.88800","6.32418","0.02636"
"76.07400","6.33960","0.02696"
"76.26000","6.35515","0.02600"
"76.44600","6.37063","0.02633"
"76.63200","6.38618","0.02681"
"76.81800","6.40167","0.02691"
"77.00400","6.41715","0.02691"
"77.19000","6.43270","0.02734"
"77.37600","6.44812","0.02770"
"77.56200","6.46367","0.02768"
"77.74800","6.47921","0.02804"
"77.93400","6.49464","0.02872"
"78.12000","6.51012","0.02849"
"78.30600","6.52573","0.02879"
"78.49200","6.54109","0.02939"
"78.67800","6.55664","0.02922"
"78.86400","6.57219","0.02979"
"79.05000","6.58761","0.03024"
"79.23600","6.60316","0.03077"
"79.42200","6.61870","0.03138"
"79.60800","6.63413","0.03125"
"79.79400","6.64967","0.03151"
"79.98000","6.66516","0.03191"
"80.16600","6.68058","0.03218"
"80.35200","6.69613","0.03209"
"80.53800","6.71161","0.03274"
"80.72400","6.72710","0.03312"
"80.91000","6.74265","0.03400"
"81.09600","6.75813","0.03423"
"81.28200","6.77368","0.03412"
"81.46800","6.78916","0.03393"
"81.65400","6.80465","0.03443"
"81.84000","6.82013","0.03407"
"82.02600","6.83568","0.03539"
"82.21200","6.85116","0.03494"
"82.39800","6.86665","0.03573"
"82.58400","6.88219","0.03591"
"82.77000","6.89762","0.03676"
"82.95600","6.91317","0.03713"
"83.14200","6.92871","0.03680"
"83.32800","6.94420","0.03684"
"83.51400","6.95962","0.03799"
"83.70000","6.97517","0.03788"
"83.88600","6.99059","0.03819"
"84.07200","7.00620","0.03861"
"84.25800","7.02168","0.03934"
"84.44400","7.03711","0.03955"
"84.63000","7.05271","0.03972"
"84.81600","7.06814","0.04014"
"85.00200","7.08362","0.04068"
"85.18800","7.09923","0.04039"
"85.37400","7.11460","0.04154"
"85.56000","7.13008","0.04121"
"85.74600","7.14569","0.04179"
"85.93200","7.16117","0.04205"
"86.11800","7.17660","0.04201"
"86.30400","7.19220","0.04253"
"86.49000","7.20763","0.04249"
"86.67600","7.22305","0.04289"
"86.86200","7.23866","0.04330"
"87.04800","7.25415","0.04354"
"87.23400","7.26963","0.04401"
"87.42000","7.28518","0.04380"
"87.60600","7.30066","0.04455"
"87.79200","7.31621","0.04429"
"87.97800","7.33169","0.04491"
"88.16400","7.34712","0.04484"
"88.35000","7.36266","0.04513"
"88.53600","7.37821","0.04564"
"88.72200","7.39363","0.04591"
"88.90800","7.40918","0.04567"
"89.09400","7.42466","0.04568"
"89.28000","7.44009","0.04617"
"89.46600","7.45570","0.04682"
"89.65200","7.47118","0.04678"
"89.83800","7.48661","0.04676"
"90.02400","7.50221","0.04694"
"90.21000","7.51770","0.04738"
"90.39600","7.53312","0.04790"
"90.58200","7.54867","0.04774"
"90.76800","7.56415","0.04783"
"90.95400","7.57958","0.04804"
"91.14000","7.59512","0.04836"
"91.32600","7.61067","0.04857"
"91.51200","7.62616","0.04870"
"91.69800","7.64164","0.04903"
"91.88400","7.65713","0.04941"
"92.07000","7.67261","0.04952"
"92.25600","7.68822","0.04969"
"92.44200","7.70358","0.04986"
"92.62800","7.71919","0.05035"
"92.81400","7.73473","0.05041"
"93.00000","7.75010","0.05071"
"93.18600","7.76570","0.05085"
"93.37200","7.78113","0.05148"
"93.55800","7.79662","0.05121"
"93.74400","7.81216","0.05155"
"93.93000","7.82771","0.05254"
"94.11600","7.84307","0.05291"
"94.30200","7.85868","0.05314"
"94.48800","7.87416","0.05363"
"94.67400","7.88959","0.05403"
"94.86000","7.90519","0.05406"
"95.04600","7.92068","0.05459"
"95.23200","7.93616","0.05543"
"95.41800","7.95171","0.05629"
"95.60400","7.96713","0.05650"
"95.79000","7.98262","0.05668"
"95.97600","7.99817","0.05731"
"96.16200","8.01365","0.05766"
"96.34800","8.02914","0.05775"
"96.53400","8.04468","0.05860"
"96.72000","8.06011","0.05933"
"96.90600","8.07559","0.05999"
"97.09200","8.09120","0.06041"
"97.27800","8.10662","0.06114"
"97.46400","8.12217","0.06128"
"97.65000","8.13771","0.06239"
"97.83600","8.15314","0.06239"
"98.02200","8.16868","0.06369"
"98.20800","8.18417","0.06383"
"98.39400","8.19966","0.06483"
"98.58000","8.21514","0.06555"
"98.76600","8.23063","0.06649"
"98.95200","8.24617","0.06592"
"99.13800","8.26166","0.05208"
"99.32400","8.27714","0.05067"
"99.51000","8.29263","0.05109"
"99.69600","8.30817","0.05107"
"99.88200","8.32366","0.05203"
"100.06800","8.33909","0.05213"
"100.25400","8.35469","0.05334"
"100.44000","8.37012","0.05378"
"100.62600","8.38560","0.05374"
"100.81200","8.40121","0.05482"
"100.99800","8.41669","0.05538"
"101.18400","8.43212","0.05701"
"101.37000","8.44766","0.05693"
"101.55600","8.46315","0.05789"
"101.74200","8.47863","0.05869"
"101.92800","8.49412","0.05979"
"102.11400","8.50966","0.05983"
"102.30000","8.52515","0.06061"
"102.48600","8.54070","0.06217"
"102.67200","8.55618","0.06230"
"102.85800","8.57167","0.06337"
"103.04400","8.58721","0.06477"
"103.23000","8.60264","0.06503"
"103.41600","8.61818","0.06607"
"103.60200","8.63367","0.06714"
"103.78800","8.64909","0.06803"
"103.97400","8.66470","0.06898"
"104.16000","8.68018","0.06958"
"104.34600","8.69555","0.07007"
"104.53200","8.71116","0.07150"
"104.71800","8.72670","0.07175"
"104.90400","8.74213","0.07223"
"105.09000","8.75767","0.07281"
"105.27600","8.77316","0.05477"
"105.46200","8.78864","0.05261"
"105.64800","8.80413","0.03578"
"105.83400","8.81967","0.03578"
"106.02000","8.83516","0.03838"
"106.20600","8.85058","0.03557"
"106.39200","8.86613","0.03791"
"106.57800","8.88167","0.03791"
"106.76400","8.89716","0.03821"
"106.95000","8.91265","0.03896"
"107.13600","8.92813","0.03900"
"107.32200","8.94368","0.03973"
"107.50800","8.95916","0.03970"
"107.69400","8.97465","0.04004"
"107.88000","8.99019","0.04013"
"108.06600","9.00562","0.04164"
"108.25200","9.02116","0.04047"
"108.43800","9.03665","0.04250"
"108.62400","9.05214","0.04169"
"108.81000","9.06768","0.04262"
"108.99600","9.08317","0.04320"
"109.18200","9.09865","0.04267"
"109.36800","9.11414","0.04397"
"109.55400","9.12968","0.04387"
"109.74000","9.14511","0.04425"
"109.92600","9.16065","0.04454"
"110.11200","9.17620","0.04481"
"110.29800","9.19168","0.04468"
"110.48400","9.20717","0.04547"
"110.67000","9.22265","0.04553"
"110.85600","9.23814","0.04565"
"111.04200","9.25363","0.04616"
"111.22800","9.26917","0.04647"
"111.41400","9.28460","0.04695"
"111.60000","9.30014","0.04664"
"111.78600","9.31563","0.04704"
"111.97200","9.33111","0.04736"
"112.15800","9.34672","0.04747"
"112.34400","9.36214","0.04818"
"112.53000","9.37763","0.04781"
"112.71600","9.39318","0.04853"
"112.90200","9.40860","0.04826"
"113.08800","9.42415","0.04864"
"113.27400","9.43969","0.04935"
"113.46000","9.45512","0.04914"
"113.64600","9.47066","0.05000"
"113.83200","9.48615","0.05006"
"114.01800","9.50163","0.05085"
"114.20400","9.51718","0.05086"
"114.39000","9.53266","0.05152"
"114.57600","9.54809","0.05136"
"114.76200","9.56369","0.05177"
"114.94800","9.57912","0.05225"
"115.13400","9.59455","0.05262"
"115.32000","9.61021","0.05312"
"115.50600","9.62564","0.05318"
"115.69200","9.64106","0.05459"
"115.87800","9.65673","0.05407"
"116.06400","9.67221","0.05575"
"116.25000","9.68764","0.05551"
"116.43600","9.70318","0.05563"
"116.62200","9.71867","0.05754"
"116.80800","9.73421","0.05678"
"116.99400","9.74964","0.05856"
"117.18000","9.76513","0.05905"
"117.36600","9.78067","0.06009"
"117.55200","9.79616","0.06159"
"117.73800","9.81164","0.06112"
"117.92400","9.82713","0.06351"
"118.11000","9.84267","0.06313"
"118.29600","9.85810","0.06444"
"118.48200","9.87370","0.06524"
"118.66800","9.88919","0.06557"
"118.85400","9.90456","0.06712"
"119.04000","9.92022","0.06719"
"119.22600","9.93565","0.06845"
"119.41200","9.95107","0.07000"
"119.59800","9.96667","0.06913"
"119.78400","9.98222","0.07112"
"119.97000","9.99759","0.07108"
"120.15600","10.01319","0.07239"
"120.34200","10.02868","0.07237"
"120.52800","10.04410","0.07369"
"120.71400","10.05971","0.07442"
"120.90000","10.07519","0.07457"
"121.08600","10.09062","0.06622"
"121.27200","10.10616","0.06413"
"121.45800","10.12165","0.06206"
"121.64400","10.13714","0.06223"
"121.83000","10.15262","0.06276"
"122.01600","10.16811","0.06421"
"122.20200","10.18365","0.06487"
"122.38800","10.19914","0.06570"
"122.57400","10.21462","0.06745"
"122.76000","10.23017","0.06699"
"122.94600","10.24565","0.06900"
"123.13200","10.26114","0.06939"
"123.31800","10.27668","0.07030"
"123.50400","10.29223","0.07171"
"123.69000","10.30760","0.07197"
"123.87600","10.32314","0.07351"
"124.06200","10.33869","0.07363"
"124.24800","10.35411","0.07479"
"124.43400","10.36972","0.07553"
"124.62000","10.38514","0.07562"
"124.80600","10.40063","0.07662"
"124.99200","10.41617","0.07699"
"125.17800","10.43166","0.07825"
"125.36400","10.44714","0.07902"
"125.55000","10.46269","0.07967"
"125.73600","10.47812","0.08064"
"125.92200","10.49366","0.08122"
"126.10800","10.50915","0.08248"
"126.29400","10.52463","0.08301"
"126.48000","10.54018","0.08373"
"126.66600","10.55566","0.08492"
"126.85200","10.57109","0.08506"
"127.03800","10.58663","0.08636"
"127.22400","10.60218","0.08672"
"127.41000","10.61767","0.08773"
"127.59600","10.63315","0.08840"
"127.78200","10.64870","0.08946"
"127.96800","10.66412","0.08985"
"128.15400","10.67967","0.08998"
"128.34000","10.69521","0.09072"
"128.52600","10.71058","0.09149"
"128.71200","10.72618","0.09233"
"128.89800","10.74167","0.09250"
"129.08400","10.75715","0.09295"
"129.27000","10.77270","0.09329"
"129.45600","10.78818","0.09337"
"129.64200","10.80361","0.09446"
"129.82800","10.81922","0.09456"
"130.01400","10.83464","0.09473"
"130.20000","10.85013","0.07662"
"130.38600","10.86567","0.07803"
"130.57200","10.88116","0.07673"
"130.75800","10.89658","0.07950"
"130.94400","10.91219","0.07934"
"131.13000","10.92767","0.08065"
"131.31600","10.94310","0.08182"
"131.50200","10.95864","0.08231"
"131.68800","10.97413","0.08440"
"131.87400","10.98962","0.08423"
"132.06000","11.00516","0.08567"
"132.24600","11.02065","0.08606"
"132.43200","11.03619","0.08641"
"132.61800","11.05168","0.08822"
"132.80400","11.06716","0.08808"
"132.99000","11.08265","0.08951"
"133.17600","11.09813","0.09044"
"133.36200","11.11368","0.09049"
"133.54800","11.12916","0.09157"
"133.73400","11.14471","0.09201"
"133.92000","11.16014","0.09273"
"134.10600","11.17574","0.09318"
"134.29200","11.19116","0.09362"
"134.47800","11.20659","0.09373"
"134.66400","11.22214","0.09460"
"134.85000","11.23762","0.09481"
"135.03600","11.25311","0.09513"
"135.22200","11.26865","0.09563"
"135.40800","11.28420","0.09580"
"135.59400","11.29968","0.09668"
"135.78000","11.31517","0.09622"
"135.96600","11.33066","0.09708"
"136.15200","11.34614","0.09691"
"136.33800","11.36168","0.09722"
"136.52400","11.37711","0.09784"
"136.71000","11.39266","0.09772"
"136.89600","11.40814","0.09864"
"137.08200","11.42363","0.09866"
"137.26800","11.43917","0.09905"
"137.45400","11.45472","0.09959"
"137.64000","11.47008","0.09968"
"137.82600","11.48569","0.10055"
"138.01200","11.50117","0.10101"
"138.19800","11.51660","0.10138"
"138.38400","11.53214","0.10196"
"138.57000","11.54769","0.10353"
"138.75600","11.56312","0.10345"
"138.94200","11.57866","0.10477"
"139.12800","11.59421","0.10518"
"139.31400","11.60963","0.10659"
"139.50000","11.62512","0.10803"
"139.68600","11.64066","0.10807"
"139.87200","11.65609","0.10960"
"140.05800","11.67169","0.11056"
"140.24400","11.68718","0.11216"
"140.43000","11.70267","0.11221"
"140.61600","11.71815","0.11512"
"140.80200","11.73363","0.11558"
"140.98800","11.74912","0.11764"
"141.17400","11.76467","0.11841"
"141.36000","11.78021","0.12031"
"141.54600","11.79564","0.12208"
"141.73200","11.81118","0.12301"
"141.91800","11.82661","0.12524"
"142.10400","11.84209","0.12597"
"142.29000","11.85770","0.12807"
"142.47600","11.87312","0.12875"
"142.66200","11.88861","0.13213"
"142.84800","11.90416","0.13232"
"143.03400","11.91964","0.13558"
"143.22000","11.93513","0.13596"
"143.40600","11.95067","0.13840"
"143.59200","11.96610","0.13989"
"143.77800","11.98164","0.14150"
"143.96400","11.99719","0.14350"
"144.15000","12.01267","0.14495"
"144.33600","12.02822","0.14644"
"144.52200","12.04364","0.14754"
"144.70800","12.05907","0.14944"
"144.89400","12.07468","0.15004"
"145.08000","12.09016","0.15189"
"145.26600","12.10559","0.15183"
"145.45200","12.12119","0.15278"
"145.63800","12.13668","0.15374"
"145.82400","12.15210","0.15445"
"146.01000","12.16771","0.15479"
"146.19600","12.18313","0.15560"
"146.38200","12.19862","0.15579"
"146.56800","12.21422","0.15635"
"146.75400","12.22971","0.15652"
"146.94000","12.24514","0.15711"
"147.12600","12.26068","0.15748"
"147.31200","12.27611","0.15823"
"147.49800","12.29159","0.15872"
"147.68400","12.30720","0.15941"
"147.87000","12.32262","0.16043"
"148.05600","12.33817","0.16067"
"148.24200","12.35365","0.16296"
"148.42800","12.36914","0.16358"
"148.61400","12.38468","0.16554"
"148.80000","12.40017","0.16566"
"148.98600","12.41566","0.16723"
"149.17200","12.43114","0.16776"
"149.35800","12.44669","0.16967"
"149.54400","12.46205","0.17077"
"149.73000","12.47766","0.17230"
"149.91600","12.49320","0.17340"
"150.10200","12.50857","0.17468"
"150.28800","12.52417","0.17534"
"150.47400","12.53966","0.17721"
"150.66000","12.55514","0.17760"
"150.84600","12.57063","0.17993"
"151.03200","12.58617","0.18048"
"151.21800","12.60160","0.18250"
"151.40400","12.61715","0.18309"
"151.59000","12.63263","0.18521"
"151.77600","12.64818","0.18601"
"151.96200","12.66366","0.18782"
"152.14800","12.67915","0.18876"
"152.33400","12.69463","0.18995"
"152.52000","12.71018","0.18057"
"152.70600","12.72566","0.18007"
"152.89200","12.74115","0.18023"
"153.07800","12.75669","0.18284"
"153.26400","12.77218","0.18330"
"153.45000","12.78772","0.18569"
"153.63600","12.80321","0.18594"
"153.82200","12.81858","0.18888"
"154.00800","12.83418","0.18901"
"154.19400","12.84973","0.19106"
"154.38000","12.86509","0.19215"
"154.56600","12.88070","0.19279"
"154.75200","12.89618","0.19418"
"154.93800","12.91161","0.19589"
"155.12400","12.92721","0.19605"
"155.31000","12.94264","0.19779"
"155.49600","12.95813","0.19817"
"155.68200","12.97367","0.19954"
"155.86800","12.98910","0.19968"
"156.05400","13.00464","0.20082"
"156.24000","13.02013","0.20157"
"156.42600","13.03567","0.20245"
"156.61200","13.05110","0.20257"
"156.79800","13.06664","0.20367"
"156.98400","13.08213","0.20415"
"157.17000","13.09761","0.20532"
"157.35600","13.11322","0.20566"
"157.54200","13.12858","0.20679"
"157.72800","13.14413","0.20685"
"157.91400","13.15962","0.20816"
"158.10000","13.17510","0.20752"
"158.28600","13.19059","0.20807"
"158.47200","13.20613","0.20936"
"158.65800","13.22162","0.21012"
"158.84400","13.23716","0.21157"
"159.03000","13.25265","0.21246"
"159.21600","13.26819","0.21463"
"159.40200","13.28368","0.21547"
"159.58800","13.29917","0.21762"
"159.77400","13.31465","0.21841"
"159.96000","13.33020","0.22077"
"160.14600","13.34568","0.22190"
"160.33200","13.36111","0.22397"
"160.51800","13.37665","0.22453"
"160.70400","13.39214","0.22677"
"160.89000","13.40762","0.22818"
"161.07600","13.42317","0.22959"
"161.26200","13.43865","0.23103"
"161.44800","13.45414","0.23242"
"161.63400","13.46969","0.23436"
"161.82000","13.48511","0.23566"
"162.00600","13.50066","0.23718"
"162.19200","13.51614","0.23925"
"162.37800","13.53169","0.24134"
"162.56400","13.54717","0.24206"
"162.75000","13.56266","0.24363"
"162.93600","13.57814","0.24450"
"163.12200","13.59369","0.24601"
"163.30800","13.60917","0.24688"
"163.49400","13.62460","0.24785"
"163.68000","13.64021","0.24802"
"163.86600","13.65569","0.24928"
"164.05200","13.67118","0.25011"
"164.23800","13.68666","0.25162"
"164.42400","13.70215","0.25209"
"164.61000","13.71763","0.25330"
"164.79600","13.73312","0.25478"
"164.98200","13.74872","0.25617"
"165.16800","13.76409","0.25803"
"165.35400","13.77969","0.25930"
"165.54000","13.79518","0.26225"
"165.72600","13.81067","0.26431"
"165.91200","13.82615","0.26757"
"166.09800","13.84170","0.27057"
"166.28400","13.85712","0.27247"
"166.47000","13.87261","0.27554"
"166.65600","13.88815","0.27811"
"166.84200","13.90364","0.28073"
"167.02800","13.91912","0.28279"
"167.21400","13.93461","0.28530"
"167.40000","13.95015","0.28673"
"167.58600","13.96564","0.28909"
"167.77200","13.98112","0.29166"
"167.95800","13.99667","0.29466"
"168.14400","14.01216","0.29803"
"168.33000","14.02770","0.29905"
"168.51600","14.04319","0.30182"
"168.70200","14.05867","0.30382"
"168.88800","14.07416","0.30526"
"169.07400","14.08964","0.30662"
"169.26000","14.10519","0.30759"
"169.44600","14.12061","0.30861"
"169.63200","14.13616","0.30917"
"169.81800","14.15164","0.30989"
"170.00400","14.16713","0.31001"
"170.19000","14.18267","0.31028"
"170.37600","14.19816","0.31058"
"170.56200","14.21365","0.31086"
"170.74800","14.22913","0.31119"
"170.93400","14.24462","0.31178"
"171.12000","14.26016","0.31248"
"171.30600","14.27571","0.31359"
"171.49200","14.29113","0.31484"
"171.67800","14.30662","0.31644"
"171.86400","14.32216","0.31743"
"172.05000","14.33771","0.32015"
"172.23600","14.35314","0.32078"
"172.42200","14.36874","0.32366"
"172.60800","14.38411","0.32542"
"172.79400","14.39959","0.32697"
"172.98000","14.41514","0.32954"
"173.16600","14.43062","0.33163"
"173.35200","14.44617","0.33435"
"173.53800","14.46165","0.33634"
"173.72400","14.47714","0.33908"
"173.91000","14.49274","0.34212"
"174.09600","14.50817","0.34395"
"174.28200","14.52365","0.34704"
"174.46800","14.53920","0.34949"
"174.65400","14.55469","0.35141"
"174.84000","14.57011","0.35394"
"175.02600","14.58572","0.35527"
"175.21200","14.60114","0.35686"
"175.39800","14.61657","0.23227"
"175.58400","14.63217","0.22834"
"175.77000","14.64766","0.22718"
"175.95600","14.66308","0.23053"
"176.14200","14.67863","0.23673"
"176.32800","14.69417","0.23403"
"176.51400","14.70960","0.23595"
"176.70000","14.72521","0.24226"
"176.88600","14.74069","0.24159"
"177.07200","14.75618","0.24194"
"177.25800","14.77166","0.24522"
"177.44400","14.78715","0.24748"
"177.63000","14.80263","0.24647"
"177.81600","14.81818","0.24805"
"178.00200","14.83366","0.25037"
"178.18800","14.84915","0.25101"
"178.37400","14.86463","0.25046"
"178.56000","14.88006","0.25314"
"178.74600","14.89573","0.25607"
"178.93200","14.91121","0.25594"
"179.11800","14.92658","0.25783"
"179.30400","14.94224","0.26169"
"179.49000","14.95761","0.26643"
"179.67600","14.97309","0.26465"
"179.86200","14.98870","0.26837"
"180.04800","15.00418","0.27247"
"180.23400","15.01961","0.27625"
"180.42000","15.03521","0.27608"
"180.60600","15.05070","0.27859"
"180.79200","15.06613","0.28344"
"180.97800","15.08167","0.28413"
"181.16400","15.09716","0.28614"
"181.35000","15.11264","0.28797"
"181.53600","15.12819","0.29227"
"181.72200","15.14361","0.29330"
"181.90800","15.15916","0.29388"
"182.09400","15.17464","0.29654"
"182.28000","15.19013","0.29919"
"182.46600","15.20568","0.30113"
"182.65200","15.22116","0.30071"
"182.83800","15.23659","0.30313"
"183.02400","15.25213","0.30492"
"183.21000","15.26768","0.30584"
"183.39600","15.28310","0.30654"
"183.58200","15.29865","0.30712"
"183.76800","15.31419","0.30823"
"183.95400","15.32962","0.30819"
"184.14000","15.34516","0.27648"
"184.32600","15.36065","0.22989"
"184.51200","15.37613","0.22882"
"184.69800","15.39168","0.23094"
"184.88400","15.40717","0.22983"
"185.07000","15.42265","0.23045"
"185.25600","15.43820","0.23253"
"185.44200","15.45362","0.23357"
"185.62800","15.46917","0.23311"
"185.81400","15.48465","0.23615"
"186.00000","15.50008","0.23629"
"186.18600","15.51562","0.23771"
"186.37200","15.53117","0.23854"
"186.55800","15.54659","0.24107"
"186.74400","15.56214","0.24041"
"186.93000","15.57768","0.24130"
"187.11600","15.59311","0.24426"
"187.30200","15.60865","0.24408"
"187.48800","15.62420","0.24504"
"187.67400","15.63963","0.24576"
"187.86000","15.65517","0.24595"
"188.04600","15.67072","0.06980"
"188.23200","15.68614","0.06664"
"188.41800","15.70169","0.08267"
"188.60400","15.71717","0.06918"
"188.79000","15.73266","0.08599"
"188.97600","15.74820","0.07618"
"189.16200","15.76369","0.08000"
"189.34800","15.77912","0.08785"
"189.53400","15.79472","0.07904"
"189.72000","15.81015","0.09043"
"189.90600","15.82563","0.08396"
"190.09200","15.84118","0.08850"
"190.27800","15.85666","0.09124"
"190.46400","15.87209","0.08660"
"190.65000","15.88769","0.09448"
"190.83600","15.90312","0.08913"
"191.02200","15.91860","0.09370"
"191.20800","15.93421","0.09343"
"191.39400","15.94969","0.09259"
"191.58000","15.96512","0.09585"
"191.76600","15.98067","0.09290"
"191.95200","15.99621","0.09672"
"192.13800","16.01164","0.09491"
"192.32400","16.02712","0.09591"
"192.51000","16.04261","0.09676"
"192.69600","16.05815","0.09584"
"192.88200","16.07364","0.09817"
"193.06800","16.08912","0.09611"
"193.25400","16.10467","0.09931"
"193.44000","16.12016","0.09730"
"193.62600","16.13564","0.09904"
"193.81200","16.15113","0.09914"
"193.99800","16.16667","0.09910"
"194.18400","16.18210","0.10159"
"194.37000","16.19770","0.09918"
"194.55600","16.21319","0.10380"
"194.74200","16.22861","0.09995"
"194.92800","16.24416","0.10545"
"195.11400","16.25970","0.10307"
"195.30000","16.27513","0.10604"
"195.48600","16.29062","0.10738"
"195.67200","16.30622","0.10717"
"195.85800","16.32159","0.11314"
"196.04400","16.33719","0.10887"
"196.23000","16.35268","0.11748"
"196.41600","16.36816","0.11160"
"196.60200","16.38371","0.11992"
"196.78800","16.39913","0.11614"
"196.97400","16.41462","0.12156"
"197.16000","16.43016","0.12208"
"197.34600","16.44565","0.12336"
"197.53200","16.46119","0.12762"
"197.71800","16.47668","0.12516"
"197.90400","16.49217","0.13314"
"198.09000","16.50765","0.12799"
"198.27600","16.52320","0.13824"
"198.46200","16.53862","0.13303"
"198.64800","16.55411","0.14222"
"198.83400","16.56965","0.13838"
"199.02000","16.58502","0.14607"
"199.20600","16.60062","0.14349"
"199.39200","16.61623","0.14774"
"199.57800","16.63165","0.14755"
"199.76400","16.64714","0.14976"
"199.95000","16.66269","0.15150"
"200.13600","16.67811","0.15196"
"200.32200","16.69371","0.15388"
"200.50800","16.70920","0.15375"
"200.69400","16.72463","0.15546"
"200.88000","16.74017","0.15481"
"201.06600","16.75566","0.15661"
"201.25200","16.77114","0.15598"
"201.43800","16.78663","0.15782"
"201.62400","16.80211","0.15708"
"201.81000","16.81766","0.15953"
"201.99600","16.83315","0.15831"
"202.18200","16.84863","0.16178"
"202.36800","16.86411","0.16051"
"202.55400","16.87972","0.16423"
"202.74000","16.89515","0.16322"
"202.92600","16.91063","0.16734"
"203.11200","16.92618","0.16616"
"203.29800","16.94160","0.16999"
"203.48400","16.95715","0.16977"
"203.67000","16.97263","0.17361"
"203.85600","16.98812","0.17264"
"204.04200","17.00366","0.17614"
"204.22800","17.01915","0.17616"
"204.41400","17.03464","0.17918"
"204.60000","17.05018","0.17920"
"204.78600","17.06567","0.18234"
"204.97200","17.08109","0.18291"
"205.15800","17.09676","0.18571"
"205.34400","17.11212","0.18594"
"205.53000","17.12761","0.18894"
"205.71600","17.14315","0.18971"
"205.90200","17.15870","0.19272"
"206.08800","17.17413","0.19282"
"206.27400","17.18973","0.19516"
"206.46000","17.20522","0.19567"
"206.64600","17.22058","0.19776"
"206.83200","17.23619","0.19818"
"207.01800","17.25167","0.20029"
"207.20400","17.26710","0.20031"
"207.39000","17.28270","0.20212"
"207.57600","17.29813","0.20240"
"207.76200","17.31361","0.20382"
"207.94800","17.32916","0.20431"
"208.13400","17.34459","0.20614"
"208.32000","17.36013","0.20627"
"208.50600","17.37568","0.20814"
"208.69200","17.39110","0.20823"
"208.87800","17.40671","0.21030"
"209.06400","17.42219","0.21087"
"209.25000","17.43762","0.21271"
"209.43600","17.45316","0.21326"
"209.62200","17.46865","0.21624"
"209.80800","17.48413","0.21613"
"209.99400","17.49968","0.21964"
"210.18000","17.51516","0.22013"
"210.36600","17.53059","0.22248"
"210.55200","17.54620","0.22347"
"210.73800","17.56168","0.22585"
"210.92400","17.57711","0.22744"
"211.11000","17.59265","0.22937"
"211.29600","17.60820","0.23063"
"211.48200","17.62362","0.23210"
"211.66800","17.63917","0.23446"
"211.85400","17.65459","0.23512"
"212.04000","17.67014","0.23773"
"212.22600","17.68568","0.23812"
"212.41200","17.70111","0.24159"
"212.59800","17.71671","0.24209"
"212.78400","17.73220","0.24440"
"212.97000","17.74763","0.24496"
"213.15600","17.76317","0.24644"
"213.34200","17.77866","0.24736"
"213.52800","17.79414","0.24826"
"213.71400","17.80969","0.24903"
"213.90000","17.82517","0.24974"
"214.08600","17.84060","0.25140"
"214.27200","17.85614","0.25185"
"214.45800","17.87169","0.25454"
"214.64400","17.88712","0.25505"
"214.83000","17.90266","0.25794"
"215.01600","17.91821","0.25908"
"215.20200","17.93363","0.26185"
"215.38800","17.94918","0.26476"
"215.57400","17.96460","0.26748"
"215.76000","17.98015","0.27053"
"215.94600","17.99563","0.27237"
"216.13200","18.01112","0.27627"
"216.31800","18.02660","0.27834"
"216.50400","18.04215","0.28154"
"216.69000","18.05763","0.28313"
"216.87600","18.07312","0.28614"
"217.06200","18.08867","0.28868"
"217.24800","18.10415","0.29106"
"217.43400","18.11964","0.29399"
"217.62000","18.13518","0.29575"
"217.80600","18.15067","0.29837"
"217.99200","18.16615","0.30056"
"218.17800","18.18170","0.30273"
"218.36400","18.19712","0.30351"
"218.55000","18.21267","0.30557"
"218.73600","18.22816","0.22407"
"218.92200","18.24364","0.22688"
"219.10800","18.25918","0.22612"
"219.29400","18.27461","0.22948"
"219.48000","18.29016","0.23446"
"219.66600","18.30564","0.23292"
"219.85200","18.32113","0.23685"
"220.03800","18.33661","0.24073"
"220.22400","18.35222","0.24250"
"220.41000","18.36758","0.24234"
"220.59600","18.38307","0.24675"
"220.78200","18.39867","0.24651"
"220.96800","18.41410","0.24805"
"221.15400","18.42964","0.23551"
"221.34000","18.44513","0.24177"
"221.52600","18.46062","0.23771"
"221.71200","18.47616","0.24211"
"221.89800","18.49165","0.24459"
"222.08400","18.50719","0.24383"
"222.27000","18.52262","0.24518"
"222.45600","18.53811","0.24672"
"222.64200","18.55365","0.24828"
"222.82800","18.56913","0.24760"
"223.01400","18.58462","0.25024"
"223.20000","18.60017","0.25008"
"223.38600","18.61565","0.25106"
"223.57200","18.63120","0.25059"
"223.75800","18.64662","0.25309"
"223.94400","18.66217","0.25334"
"224.13000","18.67765","0.25432"
"224.31600","18.69314","0.25769"
"224.50200","18.70862","0.25880"
"224.68800","18.72417","0.26120"
"224.87400","18.73959","0.26171"
"225.06000","18.75514","0.26773"
"225.24600","18.77069","0.26704"
"225.43200","18.78611","0.27093"
"225.61800","18.80165","0.27179"
"225.80400","18.81720","0.27549"
"225.99000","18.83263","0.27640"
"226.17600","18.84811","0.27857"
"226.36200","18.86366","0.28258"
"226.54800","18.87914","0.28284"
"226.73400","18.89463","0.28635"
"226.92000","18.91017","0.28739"
"227.10600","18.92566","0.29064"
"227.29200","18.94114","0.28470"
"227.47800","18.95663","0.28480"
"227.66400","18.97212","0.28928"
"227.85000","18.98766","0.28954"
"228.03600","19.00309","0.29253"
"228.22200","19.01863","0.29353"
"228.40800","19.03412","0.29726"
"228.59400","19.04966","0.29827"
"228.78000","19.06515","0.30036"
"228.96600","19.08063","0.30248"
"229.15200","19.09612","0.30335"
"229.33800","19.11160","0.30503"
"229.52400","19.12721","0.30490"
"229.71000","19.14264","0.30644"
"229.89600","19.15818","0.30727"
"230.08200","19.17373","0.30754"
"230.26800","19.18915","0.30849"
"230.45400","19.20470","0.30901"
"230.64000","19.22018","0.30947"
"230.82600","19.23567","0.30967"
"231.01200","19.25115","0.30993"
"231.19800","19.26658","0.31010"
"231.38400","19.28213","0.31045"
"231.57000","19.29773","0.31059"
"231.75600","19.31315","0.31084"
"231.94200","19.32864","0.31114"
"232.12800","19.34419","0.31143"
"232.31400","19.35967","0.31202"
"232.50000","19.37510","0.31229"
"232.68600","19.39070","0.31318"
"232.87200","19.40619","0.31397"
"233.05800","19.42167","0.31443"
"233.24400","19.43722","0.31633"
"233.43000","19.45264","0.31699"
"233.61600","19.46813","0.31820"
"233.80200","19.48368","0.32015"
"233.98800","19.49910","0.32125"
"234.17400","19.51465","0.32324"
"234.36000","19.53019","0.32379"
"234.54600","19.54568","0.32688"
"234.73200","19.56116","0.32842"
"234.91800","19.57665","0.33061"
"235.10400","19.59213","0.33272"
"235.29000","19.60768","0.33449"
"235.47600","19.62316","0.33774"
"235.66200","19.63859","0.33834"
"235.84800","19.65420","0.34172"
"236.03400","19.66968","0.34309"
"236.22000","19.68511","0.34586"
"236.40600","19.70071","0.34863"
"236.59200","19.71619","0.35026"
"236.77800","19.73162","0.35273"
"236.96400","19.74711","0.35406"
"237.15000","19.76265","0.35632"
"237.33600","19.77808","0.35753"
"237.52200","19.79362","0.35885"
"237.70800","19.80911","0.36056"
"237.89400","19.82466","0.36125"
"238.08000","19.84020","0.36277"
"238.26600","19.85563","0.36419"
"238.45200","19.87117","0.36542"
"238.63800","19.88665","0.36679"
"238.82400","19.90208","0.36812"
"239.01000","19.91775","0.37026"
"239.19600","19.93317","0.37217"
"239.38200","19.94860","0.37411"
"239.56800","19.96420","0.37557"
"239.75400","19.97969","0.37717"
"239.94000","19.99505","0.37845"
"240.12600","20.01066","0.38099"
"240.31200","20.02620","0.38171"
"240.49800","20.04163","0.38324"
"240.68400","20.05718","0.38502"
"240.87000","20.07272","0.38548"
"241.05600","20.08809","0.38642"
"241.24200","20.10369","0.38769"
"241.42800","20.11918","0.38866"
"241.61400","20.13460","0.32557"
"241.80000","20.15021","0.31430"
"241.98600","20.16563","0.31397"
"242.17200","20.18112","0.31342"
"242.35800","20.19666","0.31223"
"242.54400","20.21215","0.31473"
"242.73000","20.22770","0.31329"
"242.91600","20.24318","0.31517"
"243.10200","20.25861","0.31470"
"243.28800","20.27415","0.31630"
"243.47400","20.28976","0.31844"
"243.66000","20.30506","0.31729"
"243.84600","20.32061","0.32179"
"244.03200","20.33615","0.32123"
"244.21800","20.35158","0.32510"
"244.40400","20.36719","0.32637"
"244.59000","20.38267","0.32629"
"244.77600","20.39816","0.33065"
"244.96200","20.41364","0.32959"
"245.14800","20.42919","0.33429"
"245.33400","20.44461","0.33449"
"245.52000","20.46016","0.33710"
"245.70600","20.47564","0.34007"
"245.89200","20.49113","0.33942"
"246.07800","20.50667","0.34406"
"246.26400","20.52210","0.34366"
"246.45000","20.53765","0.34756"
"246.63600","20.55319","0.34998"
"246.82200","20.56861","0.35032"
"247.00800","20.58416","0.35441"
"247.19400","20.59970","0.35485"
"247.38000","20.61513","0.35732"
"247.56600","20.63062","0.35885"
"247.75200","20.64622","0.35939"
"247.93800","20.66159","0.36172"
"248.12400","20.67719","0.36180"
"248.31000","20.69268","0.36418"
"248.49600","20.70811","0.36475"
"248.68200","20.72365","0.36601"
"248.86800","20.73914","0.36862"
"249.05400","20.75462","0.36891"
"249.24000","20.77017","0.37195"
"249.42600","20.78571","0.37351"
"249.61200","20.80108","0.37521"
"249.79800","20.81668","0.37822"
"249.98400","20.83217","0.37853"
"250.17000","20.84759","0.38090"
"250.35600","20.86320","0.38186"
"250.54200","20.87862","0.26596"
"250.72800","20.89411","0.18115"
"250.91400","20.90966","0.20239"
"251.10000","20.92520","0.18604"
"251.28600","20.94057","0.20506"
"251.47200","20.95617","0.18596"
"251.65800","20.97166","0.20363"
"251.84400","20.98714","0.19869"
"252.03000","21.00269","0.19246"
"252.21600","21.01817","0.20674"
"252.40200","21.03360","0.19637"
"252.58800","21.04914","0.20586"
"252.77400","21.06463","0.19558"
"252.96000","21.08012","0.22673"
"253.14600","21.09566","0.19728"
"253.33200","21.11115","0.21816"
"253.51800","21.12663","0.20250"
"253.70400","21.14218","0.22567"
"253.89000","21.15766","0.20306"
"254.07600","21.17321","0.22288"
"254.26200","21.18869","0.21024"
"254.44800","21.20412","0.22534"
"254.63400","21.21967","0.21214"
"254.82000","21.23515","0.22410"
"255.00600","21.25064","0.22162"
"255.19200","21.26618","0.22927"
"255.37800","21.28167","0.22801"
"255.56400","21.29709","0.22927"
"255.75000","21.31264","0.23333"
"255.93600","21.32818","0.23427"
"256.12200","21.34361","0.24154"
"256.30800","21.35915","0.23877"
"256.49400","21.37470","0.24440"
"256.68000","21.39013","0.24079"
"256.86600","21.40567","0.24723"
"257.05200","21.42115","0.24501"
"257.23800","21.43664","0.24955"
"257.42400","21.45219","0.24768"
"257.61000","21.46761","0.25146"
"257.79600","21.48315","0.24935"
"257.98200","21.49864","0.25345"
"258.16800","21.51413","0.25225"
"258.35400","21.52967","0.25715"
"258.54000","21.54522","0.25529"
"258.72600","21.56064","0.26021"
"258.91200","21.57613","0.26162"
"259.09800","21.59167","0.26440"
"259.28400","21.60710","0.26899"
"259.47000","21.62259","0.26971"
"259.65600","21.63819","0.27678"
"259.84200","21.65361","0.27316"
"260.02800","21.66916","0.28455"
"260.21400","21.68471","0.27826"
"260.40000","21.70013","0.29138"
"260.58600","21.71568","0.28267"
"260.77200","21.73116","0.29847"
"260.95800","21.74665","0.28767"
"261.14400","21.76213","0.30306"
"261.33000","21.77768","0.29173"
"261.51600","21.79311","0.30596"
"261.70200","21.80871","0.29688"
"261.88800","21.82414","0.30796"
"262.07400","21.83962","0.30122"
"262.26000","21.85517","0.30914"
"262.44600","21.87065","0.30558"
"262.63200","21.88614","0.30961"
"262.81800","21.90168","0.30849"
"263.00400","21.91711","0.30996"
"263.19000","21.93259","0.30991"
"263.37600","21.94814","0.31038"
"263.56200","21.96362","0.31069"
"263.74800","21.97911","0.31058"
"263.93400","21.99466","0.31175"
"264.12000","22.01020","0.30858"
"264.30600","22.02563","0.30932"
"264.49200","22.04117","0.30594"
"264.67800","22.05660","0.30942"
"264.86400","22.07214","0.30647"
"265.05000","22.08769","0.30950"
"265.23600","22.10311","0.30755"
"265.42200","22.11872","0.30987"
"265.60800","22.13415","0.30876"
"265.79400","22.14957","0.31005"
"265.98000","22.16524","0.30958"
"266.16600","22.18066","0.31001"
"266.35200","22.19609","0.31005"
"266.53800","22.21169","0.31023"
"266.72400","22.22712","0.02357"
"266.91000","22.24260","0.01653"
"267.09600","22.25815","0.01499"
"267.28200","22.27369","0.00475"
"267.46800","22.28912","0.00398"
"267.65400","22.30466","0.01343"
"267.84000","22.32015","0.01040"
"268.02600","22.33563","0.00617"
"268.21200","22.35118","0.00778"
"268.39800","22.36666","0.01484"
"268.58400","22.38215","0.00400"
"268.77000","22.39770","0.00780"
"268.95600","22.41312","0.01211"
"269.14200","22.42867","0.00596"
"269.32800","22.44421","0.00716"
"269.51400","22.45958","0.01097"
"269.70000","22.47518","0.00743"
"269.88600","22.49067","0.00710"
"270.07200","22.50610","0.01017"
"270.25800","22.52170","0.00629"
"270.44400","22.53713","0.01011"
"270.63000","22.55261","0.00816"
"270.81600","22.56816","0.00735"
"271.00200","22.58370","0.00918"
"271.18800","22.59913","0.01008"
"271.37400","22.61468","0.00730"
"271.56000","22.63016","0.00884"
"271.74600","22.64565","0.00757"
"271.93200","22.66113","0.01069"
"272.11800","22.67662","0.00907"
"272.30400","22.69216","0.00802"
"272.49000","22.70765","0.00879"
"272.67600","22.72307","0.01009"
"272.86200","22.73868","0.00951"
"273.04800","22.75416","0.00913"
"273.23400","22.76959","0.00807"
"273.42000","22.78519","0.00982"
"273.60600","22.80068","0.00982"
"273.79200","22.81616","0.00838"
"273.97800","22.83165","0.00900"
"274.16400","22.84720","0.01002"
"274.35000","22.86268","0.00994"
"274.53600","22.87816","0.00924"
"274.72200","22.89371","0.00887"
"274.90800","22.90914","0.01047"
"275.09400","22.92462","0.00999"
"275.28000","22.94017","0.00889"
"275.46600","22.95560","0.00935"
"275.65200","22.97120","0.01006"
"275.83800","22.98662","0.01041"
"275.96000","22.99679","0.00977"