File: Force_trajectories/161217/Specimen_RawData_2.csv
End date,"12/17/2016"
Specimen label,"6CT_42"
Maximum Load,"0.30066",N

Time,Extension,Load
(s),(mm),(N)
"0.00000","0.00000","-0.00009"
"0.25200","0.01889","0.00062"
"0.50400","0.04227","0.00203"
"0.75600","0.06320","0.00265"
"1.00800","0.08412","0.00317"
"1.26000","0.10523","0.00360"
"1.51200","0.12616","0.00364"
"1.76400","0.14708","0.00400"
"2.01600","0.16819","0.00417"
"2.26800","0.18911","0.00425"
"2.52000","0.21016","0.00450"
"2.77200","0.23115","0.00421"
"3.02400","0.25219","0.00425"
"3.27600","0.27312","0.00445"
"3.52800","0.29422","0.00469"
"3.78000","0.31509","0.00449"
"4.03200","0.33620","0.00448"
"4.28400","0.35712","0.00475"
"4.53600","0.37823","0.00482"
"4.78800","0.39910","0.00452"
"5.04000","0.42014","0.00482"
"5.29200","0.44113","0.00475"
"5.54400","0.46217","0.00527"
"5.79600","0.48316","0.00484"
"6.04800","0.50415","0.00507"
"6.30000","0.52519","0.00525"
"6.55200","0.54612","0.00488"
"6.80400","0.56716","0.00510"
"7.05600","0.58809","0.00520"
"7.30800","0.60914","0.00548"
"7.56000","0.63012","0.00531"
"7.81200","0.65117","0.00520"
"8.06400","0.67209","0.00544"
"8.31600","0.69320","0.00505"
"8.56800","0.71413","0.00547"
"8.82000","0.73511","0.00532"
"9.07200","0.75610","0.00541"
"9.32400","0.77714","0.00567"
"9.57600","0.79819","0.00565"
"9.82800","0.81912","0.00560"
"10.08000","0.84016","0.00560"
"10.33200","0.86109","0.00541"
"10.58400","0.88219","0.00547"
"10.83600","0.90306","0.00564"
"11.08800","0.92417","0.00558"
"11.34000","0.94509","0.00550"
"11.59200","0.96614","0.00576"
"11.84400","0.98713","0.00583"
"12.09600","1.00817","0.00575"
"12.34800","1.02910","0.00549"
"12.60000","1.05020","0.00564"
"12.85200","1.07107","0.00556"
"13.10400","1.09212","0.00570"
"13.35600","1.11310","0.00605"
"13.60800","1.13415","0.00569"
"13.86000","1.15519","0.00590"
"14.11200","1.17618","0.00604"
"14.36400","1.19717","0.00601"
"14.61600","1.21809","0.00574"
"14.86800","1.23914","0.00578"
"15.12000","1.26006","0.00628"
"15.37200","1.28111","0.00603"
"15.62400","1.30210","0.00619"
"15.87600","1.32320","0.00583"
"16.12800","1.34407","0.00607"
"16.38000","1.36517","0.00593"
"16.63200","1.38610","0.00612"
"16.88400","1.40715","0.00618"
"17.13600","1.42813","0.00608"
"17.38800","1.44912","0.00619"
"17.64000","1.47016","0.00626"
"17.89200","1.49109","0.00607"
"18.14400","1.51214","0.00618"
"18.39600","1.53312","0.00643"
"18.64800","1.55417","0.00601"
"18.90000","1.57516","0.00607"
"19.15200","1.59614","0.00640"
"19.40400","1.61707","0.00632"
"19.65600","1.63811","0.00628"
"19.90800","1.65910","0.00647"
"20.16000","1.68015","0.00644"
"20.41200","1.70113","0.00632"
"20.66400","1.72218","0.00621"
"20.91600","1.74316","0.00627"
"21.16800","1.76415","0.00607"
"21.42000","1.78508","0.00637"
"21.67200","1.80606","0.00644"
"21.92400","1.82717","0.00639"
"22.17600","1.84815","0.00644"
"22.42800","1.86920","0.00637"
"22.68000","1.89007","0.00667"
"22.93200","1.91117","0.00643"
"23.18400","1.93210","0.00629"
"23.43600","1.95314","0.00636"
"23.68800","1.97413","0.00660"
"23.94000","1.99518","0.00666"
"24.19200","2.01616","0.00646"
"24.44400","2.03709","0.00674"
"24.69600","2.05808","0.00642"
"24.94800","2.07918","0.00660"
"25.20000","2.10017","0.00675"
"25.45200","2.12115","0.00683"
"25.70400","2.14214","0.00654"
"25.95600","2.16313","0.00682"
"26.20800","2.18417","0.00654"
"26.46000","2.20510","0.00679"
"26.71200","2.22614","0.00696"
"26.96400","2.24713","0.00629"
"27.21600","2.26818","0.00669"
"27.46800","2.28910","0.00666"
"27.72000","2.31015","0.00666"
"27.97200","2.33107","0.00649"
"28.22400","2.35218","0.00651"
"28.47600","2.37317","0.00666"
"28.72800","2.39415","0.00657"
"28.98000","2.41514","0.00679"
"29.23200","2.43618","0.00678"
"29.48400","2.45711","0.00701"
"29.73600","2.47810","0.00670"
"29.98800","2.49908","0.00684"
"30.24000","2.52013","0.00696"
"30.49200","2.54112","0.00693"
"30.74400","2.56210","0.00661"
"30.99600","2.58315","0.00707"
"31.24800","2.60407","0.00671"
"31.50000","2.62512","0.00696"
"31.75200","2.64611","0.00641"
"32.00400","2.66715","0.00695"
"32.25600","2.68814","0.00700"
"32.50800","2.70912","0.00695"
"32.76000","2.73011","0.00679"
"33.01200","2.75116","0.00714"
"33.26400","2.77220","0.00727"
"33.51600","2.79319","0.00715"
"33.76800","2.81411","0.00696"
"34.02000","2.83510","0.00708"
"34.27200","2.85615","0.00725"
"34.52400","2.87713","0.00725"
"34.77600","2.89818","0.00737"
"35.02800","2.91910","0.00717"
"35.28000","2.94015","0.00724"
"35.53200","2.96114","0.00736"
"35.78400","2.98212","0.00726"
"36.03600","3.00311","0.00708"
"36.28800","3.02415","0.00750"
"36.54000","3.04514","0.00716"
"36.79200","3.06613","0.00710"
"37.04400","3.08711","0.00732"
"37.29600","3.10810","0.00718"
"37.54800","3.12914","0.00725"
"37.80000","3.15013","0.00742"
"38.05200","3.17118","0.00730"
"38.30400","3.19216","0.00747"
"38.55600","3.21315","0.00731"
"38.80800","3.23408","0.00734"
"39.06000","3.25518","0.00728"
"39.31200","3.27617","0.00745"
"39.56400","3.29721","0.00759"
"39.81600","3.31808","0.00734"
"40.06800","3.33913","0.00736"
"40.32000","3.36005","0.00759"
"40.57200","3.38122","0.00756"
"40.82400","3.40208","0.00746"
"41.07600","3.42313","0.00763"
"41.32800","3.44418","0.00781"
"41.58000","3.46516","0.00733"
"41.83200","3.48615","0.00767"
"42.08400","3.50707","0.00753"
"42.33600","3.52818","0.00764"
"42.58800","3.54911","0.00747"
"42.84000","3.57015","0.00773"
"43.09200","3.59108","0.00726"
"43.34400","3.61213","0.00717"
"43.59600","3.63311","0.00727"
"43.84800","3.65422","0.00693"
"44.10000","3.67514","0.00737"
"44.35200","3.69619","0.00724"
"44.60400","3.71718","0.00718"
"44.85600","3.73816","0.00731"
"45.10800","3.75909","0.00700"
"45.36000","3.78013","0.00722"
"45.61200","3.80118","0.00715"
"45.86400","3.82217","0.00738"
"46.11600","3.84315","0.00744"
"46.36800","3.86414","0.00714"
"46.62000","3.88512","0.00747"
"46.87200","3.90611","0.00747"
"47.12400","3.92710","0.00746"
"47.37600","3.94808","0.00738"
"47.62800","3.96919","0.00776"
"47.88000","3.99011","0.00736"
"48.13200","4.01116","0.00727"
"48.38400","4.03209","0.00781"
"48.63600","4.05319","0.00737"
"48.88800","4.07418","0.00751"
"49.14000","4.09516","0.00768"
"49.39200","4.11609","0.00793"
"49.64400","4.13714","0.00784"
"49.89600","4.15818","0.00767"
"50.14800","4.17911","0.00752"
"50.40000","4.20015","0.00739"
"50.65200","4.22108","0.00756"
"50.90400","4.24219","0.00754"
"51.15600","4.26311","0.00750"
"51.40800","4.28410","0.00769"
"51.66000","4.30509","0.00748"
"51.91200","4.32619","0.00790"
"52.16400","4.34712","0.00781"
"52.41600","4.36816","0.00774"
"52.66800","4.38915","0.00777"
"52.92000","4.41014","0.00775"
"53.17200","4.43118","0.00803"
"53.42400","4.45211","0.00754"
"53.67600","4.47315","0.00792"
"53.92800","4.49414","0.00796"
"54.18000","4.51519","0.00778"
"54.43200","4.53611","0.00791"
"54.68400","4.55710","0.00837"
"54.93600","4.57814","0.00797"
"55.18800","4.59919","0.00797"
"55.44000","4.62012","0.00795"
"55.69200","4.64116","0.00830"
"55.94400","4.66209","0.00756"
"56.19600","4.68313","0.00805"
"56.44800","4.70406","0.00758"
"56.70000","4.72511","0.00815"
"56.95200","4.74609","0.00816"
"57.20400","4.76720","0.00766"
"57.45600","4.78813","0.00812"
"57.70800","4.80911","0.00816"
"57.96000","4.83010","0.00801"
"58.21200","4.85114","0.00792"
"58.46400","4.87219","0.00773"
"58.71600","4.89305","0.00788"
"58.96800","4.91422","0.00785"
"59.22000","4.93509","0.00769"
"59.47200","4.95613","0.00790"
"59.72400","4.97712","0.00804"
"59.97600","4.99817","0.00786"
"60.22800","5.01909","0.00798"
"60.48000","5.04014","0.00820"
"60.73200","5.06112","0.00821"
"60.98400","5.08211","0.00767"
"61.23600","5.10322","0.00804"
"61.48800","5.12414","0.00786"
"61.74000","5.14519","0.00764"
"61.99200","5.16611","0.00821"
"62.24400","5.18716","0.00775"
"62.49600","5.20809","0.00805"
"62.74800","5.22913","0.00723"
"63.00000","5.25006","0.00765"
"63.25200","5.27116","0.00766"
"63.50400","5.29215","0.00788"
"63.75600","5.31314","0.00752"
"64.00800","5.33412","0.00773"
"64.26000","5.35517","0.00796"
"64.51200","5.37616","0.00784"
"64.76400","5.39714","0.00814"
"65.01600","5.41813","0.00807"
"65.26800","5.43917","0.00827"
"65.52000","5.46022","0.00797"
"65.77200","5.48109","0.00825"
"66.02400","5.50213","0.00803"
"66.27600","5.52312","0.00819"
"66.52800","5.54416","0.00813"
"66.78000","5.56509","0.00832"
"67.03200","5.58620","0.00795"
"67.28400","5.60712","0.00785"
"67.53600","5.62817","0.00762"
"67.78800","5.64909","0.00784"
"68.04000","5.67020","0.00800"
"68.29200","5.69113","0.00785"
"68.54400","5.71217","0.00795"
"68.79600","5.73310","0.00799"
"69.04800","5.75409","0.00810"
"69.30000","5.77513","0.00823"
"69.55200","5.79618","0.00810"
"69.80400","5.81716","0.00813"
"70.05600","5.83815","0.00799"
"70.30800","5.85920","0.00805"
"70.56000","5.88012","0.00823"
"70.81200","5.90111","0.00819"
"71.06400","5.92209","0.00808"
"71.31600","5.94314","0.00799"
"71.56800","5.96413","0.00869"
"71.82000","5.98517","0.00810"
"72.07200","6.00616","0.00815"
"72.32400","6.02714","0.00789"
"72.57600","6.04813","0.00791"
"72.82800","6.06912","0.00790"
"73.08000","6.09010","0.00805"
"73.33200","6.11115","0.00858"
"73.58400","6.13219","0.00822"
"73.83600","6.15312","0.00802"
"74.08800","6.17411","0.00788"
"74.34000","6.19509","0.00840"
"74.59200","6.21620","0.00792"
"74.84400","6.23712","0.00815"
"75.09600","6.25817","0.00819"
"75.34800","6.27910","0.00805"
"75.60000","6.30014","0.00795"
"75.85200","6.32113","0.00798"
"76.10400","6.34217","0.00795"
"76.35600","6.36316","0.00776"
"76.60800","6.38415","0.00794"
"76.86000","6.40513","0.00820"
"77.11200","6.42612","0.00779"
"77.36400","6.44711","0.00776"
"77.61600","6.46815","0.00772"
"77.86800","6.48920","0.00826"
"78.12000","6.51006","0.00792"
"78.37200","6.53117","0.00766"
"78.62400","6.55210","0.00765"
"78.87600","6.57314","0.00789"
"79.12800","6.59407","0.00779"
"79.38000","6.61511","0.00769"
"79.63200","6.63610","0.00787"
"79.88400","6.65721","0.00770"
"80.13600","6.67813","0.00803"
"80.38800","6.69912","0.00777"
"80.64000","6.72016","0.00802"
"80.89200","6.74115","0.00782"
"81.14400","6.76214","0.00782"
"81.39600","6.78312","0.00778"
"81.64800","6.80411","0.00786"
"81.90000","6.82516","0.00770"
"82.15200","6.84614","0.00786"
"82.40400","6.86713","0.00802"
"82.65600","6.88817","0.00799"
"82.90800","6.90910","0.00798"
"83.16000","6.93015","0.00808"
"83.41200","6.95107","0.00803"
"83.66400","6.97212","0.00807"
"83.91600","6.99310","0.00783"
"84.16800","7.01415","0.00810"
"84.42000","7.03514","0.00833"
"84.67200","7.05618","0.00824"
"84.92400","7.07717","0.00809"
"85.17600","7.09815","0.00800"
"85.42800","7.11914","0.00820"
"85.68000","7.14007","0.00837"
"85.93200","7.16117","0.00819"
"86.18400","7.18210","0.00831"
"86.43600","7.20314","0.00826"
"86.68800","7.22407","0.00810"
"86.94000","7.24512","0.00848"
"87.19200","7.26610","0.00807"
"87.44400","7.28715","0.00795"
"87.69600","7.30814","0.00839"
"87.94800","7.32912","0.00849"
"88.20000","7.35005","0.00816"
"88.45200","7.37115","0.00834"
"88.70400","7.39214","0.00841"
"88.95600","7.41313","0.00853"
"89.20800","7.43417","0.00814"
"89.46000","7.45510","0.00825"
"89.71200","7.47614","0.00862"
"89.96400","7.49713","0.00874"
"90.21600","7.51818","0.00837"
"90.46800","7.53910","0.00847"
"90.72000","7.56015","0.00817"
"90.97200","7.58113","0.00828"
"91.22400","7.60218","0.00827"
"91.47600","7.62305","0.00791"
"91.72800","7.64415","0.00809"
"91.98000","7.66514","0.00779"
"92.23200","7.68618","0.00824"
"92.48400","7.70711","0.00813"
"92.73600","7.72816","0.00825"
"92.98800","7.74908","0.00791"
"93.24000","7.77019","0.00815"
"93.49200","7.79117","0.00774"
"93.74400","7.81204","0.00826"
"93.99600","7.83315","0.00808"
"94.24800","7.85413","0.00842"
"94.50000","7.87512","0.00823"
"94.75200","7.89604","0.00801"
"95.00400","7.91715","0.00839"
"95.25600","7.93814","0.00847"
"95.50800","7.95912","0.00854"
"95.76000","7.98011","0.00834"
"96.01200","8.00121","0.00839"
"96.26400","8.02214","0.00867"
"96.51600","8.04313","0.00830"
"96.76800","8.06411","0.00835"
"97.02000","8.08510","0.00852"
"97.27200","8.10614","0.00914"
"97.52400","8.12719","0.00827"
"97.77600","8.14812","0.00862"
"98.02800","8.16910","0.00872"
"98.28000","8.19015","0.00842"
"98.53200","8.21108","0.00874"
"98.78400","8.23212","0.00829"
"99.03600","8.25311","0.00853"
"99.28800","8.27415","0.00864"
"99.54000","8.29508","0.00863"
"99.79200","8.31613","0.00837"
"100.04400","8.33711","0.00798"
"100.29600","8.35816","0.00795"
"100.54800","8.37914","0.00822"
"100.80000","8.40019","0.00832"
"101.05200","8.42106","0.00810"
"101.30400","8.44210","0.00785"
"101.55600","8.46315","0.00784"
"101.80800","8.48413","0.00795"
"102.06000","8.50518","0.00807"
"102.31200","8.52605","0.00762"
"102.56400","8.54715","0.00787"
"102.81600","8.56814","0.00808"
"103.06800","8.58918","0.00780"
"103.32000","8.61011","0.00795"
"103.57200","8.63116","0.00801"
"103.82400","8.65208","0.00797"
"104.07600","8.67313","0.00820"
"104.32800","8.69411","0.00797"
"104.58000","8.71516","0.00790"
"104.83200","8.73615","0.00796"
"105.08400","8.75713","0.00803"
"105.33600","8.77812","0.00800"
"105.58800","8.79917","0.00822"
"105.84000","8.82015","0.00812"
"106.09200","8.84108","0.00808"
"106.34400","8.86212","0.00824"
"106.59600","8.88311","0.00810"
"106.84800","8.90416","0.00834"
"107.10000","8.92508","0.00830"
"107.35200","8.94613","0.00879"
"107.60400","8.96711","0.00843"
"107.85600","8.98816","0.00848"
"108.10800","9.00909","0.00870"
"108.36000","9.03013","0.00883"
"108.61200","9.05112","0.00855"
"108.86400","9.07216","0.00855"
"109.11600","9.09315","0.00872"
"109.36800","9.11408","0.00881"
"109.62000","9.13512","0.00848"
"109.87200","9.15611","0.00876"
"110.12400","9.17715","0.00877"
"110.37600","9.19808","0.00821"
"110.62800","9.21919","0.00818"
"110.88000","9.24011","0.00845"
"111.13200","9.26116","0.00866"
"111.38400","9.28215","0.00882"
"111.63600","9.30319","0.00877"
"111.88800","9.32412","0.00853"
"112.14000","9.34510","0.00887"
"112.39200","9.36609","0.00902"
"112.64400","9.38714","0.00890"
"112.89600","9.40818","0.00897"
"113.14800","9.42917","0.00879"
"113.40000","9.45015","0.00910"
"113.65200","9.47108","0.00906"
"113.90400","9.49213","0.00920"
"114.15600","9.51311","0.00950"
"114.40800","9.53410","0.00922"
"114.66000","9.55508","0.00963"
"114.91200","9.57613","0.00962"
"115.16400","9.59712","0.00948"
"115.41600","9.61816","0.00973"
"115.66800","9.63909","0.00980"
"115.92000","9.66019","0.00922"
"116.17200","9.68112","0.00929"
"116.42400","9.70217","0.00948"
"116.67600","9.72309","0.00946"
"116.92800","9.74408","0.00964"
"117.18000","9.76513","0.00952"
"117.43200","9.78611","0.00984"
"117.68400","9.80716","0.00962"
"117.93600","9.82814","0.00949"
"118.18800","9.84919","0.00985"
"118.44000","9.87012","0.00983"
"118.69200","9.89116","0.00979"
"118.94400","9.91209","0.00966"
"119.19600","9.93313","0.01014"
"119.44800","9.95412","0.01021"
"119.70000","9.97517","0.01030"
"119.95200","9.99609","0.01020"
"120.20400","10.01708","0.01043"
"120.45600","10.03812","0.01028"
"120.70800","10.05911","0.01053"
"120.96000","10.08016","0.01032"
"121.21200","10.10114","0.01070"
"121.46400","10.12213","0.01030"
"121.71600","10.14305","0.01052"
"121.96800","10.16422","0.01047"
"122.22000","10.18515","0.01073"
"122.47200","10.20613","0.01047"
"122.72400","10.22706","0.01106"
"122.97600","10.24811","0.01088"
"123.22800","10.26915","0.01095"
"123.48000","10.29020","0.01078"
"123.73200","10.31112","0.01142"
"123.98400","10.33217","0.01118"
"124.23600","10.35310","0.01133"
"124.48800","10.37414","0.01128"
"124.74000","10.39513","0.01137"
"124.99200","10.41611","0.01173"
"125.24400","10.43716","0.01182"
"125.49600","10.45815","0.01233"
"125.74800","10.47913","0.01200"
"126.00000","10.50012","0.01231"
"126.25200","10.52116","0.01182"
"126.50400","10.54209","0.01204"
"126.75600","10.56314","0.01221"
"127.00800","10.58406","0.01265"
"127.26000","10.60517","0.01263"
"127.51200","10.62609","0.01264"
"127.76400","10.64714","0.01277"
"128.01600","10.66813","0.01289"
"128.26800","10.68917","0.01289"
"128.52000","10.71016","0.01326"
"128.77200","10.73114","0.01330"
"129.02400","10.75213","0.01344"
"129.27600","10.77312","0.01317"
"129.52800","10.79416","0.01314"
"129.78000","10.81509","0.01337"
"130.03200","10.83613","0.01339"
"130.28400","10.85712","0.01307"
"130.53600","10.87817","0.01352"
"130.78800","10.89909","0.01359"
"131.04000","10.92014","0.01392"
"131.29200","10.94113","0.01380"
"131.54400","10.96217","0.01403"
"131.79600","10.98310","0.01379"
"132.04800","11.00414","0.01411"
"132.30000","11.02513","0.01421"
"132.55200","11.04618","0.01443"
"132.80400","11.06716","0.01414"
"133.05600","11.08809","0.01290"
"133.30800","11.10913","0.01283"
"133.56000","11.13018","0.01296"
"133.81200","11.15117","0.01292"
"134.06400","11.17209","0.01324"
"134.31600","11.19314","0.01318"
"134.56800","11.21412","0.01327"
"134.82000","11.23517","0.01379"
"135.07200","11.25610","0.01377"
"135.32400","11.27714","0.01361"
"135.57600","11.29807","0.01404"
"135.82800","11.31917","0.01380"
"136.08000","11.34010","0.01416"
"136.33200","11.36115","0.01423"
"136.58400","11.38219","0.01494"
"136.83600","11.40312","0.01474"
"137.08800","11.42417","0.01463"
"137.34000","11.44509","0.01475"
"137.59200","11.46614","0.01505"
"137.84400","11.48712","0.01505"
"138.09600","11.50817","0.01541"
"138.34800","11.52910","0.01497"
"138.60000","11.55014","0.01592"
"138.85200","11.57113","0.01577"
"139.10400","11.59211","0.01586"
"139.35600","11.61316","0.01617"
"139.60800","11.63415","0.01646"
"139.86000","11.65507","0.01674"
"140.11200","11.67612","0.01675"
"140.36400","11.69711","0.01687"
"140.61600","11.71815","0.01700"
"140.86800","11.73914","0.01769"
"141.12000","11.76012","0.01727"
"141.37200","11.78117","0.01775"
"141.62400","11.80210","0.01753"
"141.87600","11.82314","0.01800"
"142.12800","11.84407","0.01827"
"142.38000","11.86511","0.01842"
"142.63200","11.88610","0.01865"
"142.88400","11.90715","0.01866"
"143.13600","11.92807","0.01867"
"143.38800","11.94918","0.01954"
"143.64000","11.97010","0.01924"
"143.89200","11.99121","0.01949"
"144.14400","12.01214","0.01929"
"144.39600","12.03318","0.01973"
"144.64800","12.05417","0.02001"
"144.90000","12.07515","0.02077"
"145.15200","12.09614","0.02062"
"145.40400","12.11707","0.02035"
"145.65600","12.13817","0.02088"
"145.90800","12.15916","0.01950"
"146.16000","12.18020","0.01943"
"146.41200","12.20107","0.02015"
"146.66400","12.22212","0.01995"
"146.91600","12.24310","0.02055"
"147.16800","12.26415","0.02050"
"147.42000","12.28508","0.02055"
"147.67200","12.30612","0.02066"
"147.92400","12.32711","0.02118"
"148.17600","12.34815","0.02053"
"148.42800","12.36914","0.02151"
"148.68000","12.39019","0.02150"
"148.93200","12.41117","0.02172"
"149.18400","12.43216","0.02254"
"149.43600","12.45308","0.02246"
"149.68800","12.47407","0.02313"
"149.94000","12.49512","0.02291"
"150.19200","12.51616","0.02380"
"150.44400","12.53709","0.02372"
"150.69600","12.55807","0.02371"
"150.94800","12.57912","0.02323"
"151.20000","12.60011","0.02400"
"151.45200","12.62109","0.02387"
"151.70400","12.64208","0.02347"
"151.95600","12.66318","0.02509"
"152.20800","12.68417","0.02315"
"152.46000","12.70516","0.02339"
"152.71200","12.72614","0.02367"
"152.96400","12.74713","0.02408"
"153.21600","12.76817","0.02429"
"153.46800","12.78910","0.02477"
"153.72000","12.81015","0.02507"
"153.97200","12.83107","0.02543"
"154.22400","12.85218","0.02579"
"154.47600","12.87311","0.02615"
"154.72800","12.89415","0.02663"
"154.98000","12.91508","0.02729"
"155.23200","12.93618","0.02767"
"155.48400","12.95711","0.02762"
"155.73600","12.97816","0.02853"
"155.98800","12.99914","0.02887"
"156.24000","13.02013","0.02934"
"156.49200","13.04117","0.02927"
"156.74400","13.06216","0.03001"
"156.99600","13.08315","0.03019"
"157.24800","13.10413","0.03056"
"157.50000","13.12518","0.03156"
"157.75200","13.14604","0.02992"
"158.00400","13.16715","0.03070"
"158.25600","13.18814","0.03128"
"158.50800","13.20918","0.03171"
"158.76000","13.23011","0.03265"
"159.01200","13.25115","0.03284"
"159.26400","13.27208","0.03320"
"159.51600","13.29319","0.03459"
"159.76800","13.31405","0.03454"
"160.02000","13.33516","0.03454"
"160.27200","13.35614","0.03504"
"160.52400","13.37713","0.03597"
"160.77600","13.39818","0.03627"
"161.02800","13.41910","0.03672"
"161.28000","13.44015","0.03793"
"161.53200","13.46113","0.03726"
"161.78400","13.48218","0.03776"
"162.03600","13.50305","0.03912"
"162.28800","13.52415","0.03922"
"162.54000","13.54508","0.03925"
"162.79200","13.56618","0.04037"
"163.04400","13.58711","0.04075"
"163.29600","13.60816","0.04171"
"163.54800","13.62908","0.04110"
"163.80000","13.65013","0.04211"
"164.05200","13.67112","0.04241"
"164.30400","13.69210","0.04053"
"164.55600","13.71315","0.01853"
"164.80800","13.73413","0.02029"
"165.06000","13.75512","0.02161"
"165.31200","13.77611","0.01968"
"165.56400","13.79715","0.01980"
"165.81600","13.81808","0.01994"
"166.06800","13.83913","0.02110"
"166.32000","13.86011","0.02315"
"166.57200","13.88116","0.02344"
"166.82400","13.90214","0.02222"
"167.07600","13.92313","0.02194"
"167.32800","13.94412","0.02212"
"167.58000","13.96516","0.02417"
"167.83200","13.98609","0.02573"
"168.08400","14.00713","0.02558"
"168.33600","14.02806","0.02440"
"168.58800","14.04911","0.02468"
"168.84000","14.07015","0.02556"
"169.09200","14.09114","0.02668"
"169.34400","14.11218","0.02824"
"169.59600","14.13317","0.02766"
"169.84800","14.15416","0.02687"
"170.10000","14.17508","0.02758"
"170.35200","14.19613","0.02876"
"170.60400","14.21705","0.03018"
"170.85600","14.23816","0.02998"
"171.10800","14.25909","0.02920"
"171.36000","14.28019","0.03004"
"171.61200","14.30112","0.03097"
"171.86400","14.32216","0.03185"
"172.11600","14.34309","0.03336"
"172.36800","14.36414","0.03313"
"172.62000","14.38512","0.03197"
"172.87200","14.40617","0.03354"
"173.12400","14.42716","0.03505"
"173.37600","14.44814","0.03536"
"173.62800","14.46919","0.03585"
"173.88000","14.49011","0.03677"
"174.13200","14.51116","0.03667"
"174.38400","14.53209","0.03754"
"174.63600","14.55313","0.03919"
"174.88800","14.57412","0.03950"
"175.14000","14.59516","0.03962"
"175.39200","14.61615","0.04027"
"175.64400","14.63720","0.04080"
"175.89600","14.65812","0.04192"
"176.14800","14.67917","0.04198"
"176.40000","14.70009","0.04216"
"176.65200","14.72108","0.04235"
"176.90400","14.74213","0.04269"
"177.15600","14.76317","0.04367"
"177.40800","14.78416","0.04366"
"177.66000","14.80509","0.04362"
"177.91200","14.82613","0.03529"
"178.16400","14.84712","0.03563"
"178.41600","14.86810","0.03781"
"178.66800","14.88903","0.03670"
"178.92000","14.91020","0.03600"
"179.17200","14.93112","0.03866"
"179.42400","14.95217","0.03743"
"179.67600","14.97315","0.03911"
"179.92800","14.99420","0.04155"
"180.18000","15.01518","0.04059"
"180.43200","15.03611","0.03950"
"180.68400","15.05710","0.04138"
"180.93600","15.07814","0.04278"
"181.18800","15.09913","0.04270"
"181.44000","15.12012","0.04369"
"181.69200","15.14116","0.04319"
"181.94400","15.16209","0.04358"
"182.19600","15.18319","0.04469"
"182.44800","15.20406","0.04547"
"182.70000","15.22511","0.04565"
"182.95200","15.24609","0.04536"
"183.20400","15.26720","0.04569"
"183.45600","15.28813","0.04625"
"183.70800","15.30911","0.04648"
"183.96000","15.33016","0.01432"
"184.21200","15.35114","0.01425"
"184.46400","15.37213","0.01318"
"184.71600","15.39317","0.01831"
"184.96800","15.41416","0.01343"
"185.22000","15.43509","0.01490"
"185.47200","15.45613","0.01503"
"185.72400","15.47712","0.01370"
"185.97600","15.49817","0.01823"
"186.22800","15.51915","0.01581"
"186.48000","15.54014","0.01711"
"186.73200","15.56106","0.01773"
"186.98400","15.58211","0.01557"
"187.23600","15.60310","0.01732"
"187.48800","15.62420","0.01795"
"187.74000","15.64513","0.01799"
"187.99200","15.66617","0.01981"
"188.24400","15.68716","0.01886"
"188.49600","15.70815","0.01929"
"188.74800","15.72913","0.01932"
"189.00000","15.75012","0.01945"
"189.25200","15.77116","0.02057"
"189.50400","15.79215","0.02146"
"189.75600","15.81319","0.02176"
"190.00800","15.83406","0.02186"
"190.26000","15.85517","0.02151"
"190.51200","15.87615","0.02190"
"190.76400","15.89714","0.02234"
"191.01600","15.91807","0.02229"
"191.26800","15.93911","0.02336"
"191.52000","15.96016","0.02387"
"191.77200","15.98114","0.01629"
"192.02400","16.00213","0.01384"
"192.27600","16.02312","0.01492"
"192.52800","16.04410","0.01472"
"192.78000","16.06515","0.01547"
"193.03200","16.08619","0.01699"
"193.28400","16.10712","0.01645"
"193.53600","16.12811","0.01639"
"193.78800","16.14909","0.01725"
"194.04000","16.17014","0.01610"
"194.29200","16.19112","0.01876"
"194.54400","16.21217","0.01780"
"194.79600","16.23310","0.01796"
"195.04800","16.25414","0.01832"
"195.30000","16.27513","0.01782"
"195.55200","16.29623","0.01850"
"195.80400","16.31710","0.01877"
"196.05600","16.33815","0.01965"
"196.30800","16.35913","0.01983"
"196.56000","16.38012","0.02024"
"196.81200","16.40111","0.01976"
"197.06400","16.42209","0.02001"
"197.31600","16.44314","0.02052"
"197.56800","16.46412","0.01900"
"197.82000","16.48517","0.02049"
"198.07200","16.50610","0.01987"
"198.32400","16.52714","0.02061"
"198.57600","16.54807","0.02027"
"198.82800","16.56918","0.02005"
"199.08000","16.59010","0.01699"
"199.33200","16.61115","0.01586"
"199.58400","16.63213","0.01668"
"199.83600","16.65318","0.01735"
"200.08800","16.67410","0.01632"
"200.34000","16.69515","0.01746"
"200.59200","16.71614","0.01706"
"200.84400","16.73712","0.01701"
"201.09600","16.75811","0.01894"
"201.34800","16.77909","0.01882"
"201.60000","16.80014","0.01822"
"201.85200","16.82113","0.01874"
"202.10400","16.84211","0.01890"
"202.35600","16.86310","0.01870"
"202.60800","16.88415","0.02030"
"202.86000","16.90513","0.01991"
"203.11200","16.92612","0.01979"
"203.36400","16.94710","0.02017"
"203.61600","16.96815","0.01982"
"203.86800","16.98914","0.02059"
"204.12000","17.01012","0.02112"
"204.37200","17.03117","0.02105"
"204.62400","17.05215","0.02153"
"204.87600","17.07320","0.02141"
"205.12800","17.09413","0.02125"
"205.38000","17.11517","0.02190"
"205.63200","17.13610","0.02211"
"205.88400","17.15720","0.02268"
"206.13600","17.17813","0.02208"
"206.38800","17.19918","0.02245"
"206.64000","17.22004","0.02257"
"206.89200","17.24115","0.02316"
"207.14400","17.26213","0.02366"
"207.39600","17.28312","0.02447"
"207.64800","17.30411","0.02529"
"207.90000","17.32515","0.02543"
"208.15200","17.34614","0.02561"
"208.40400","17.36712","0.02493"
"208.65600","17.38811","0.02453"
"208.90800","17.40910","0.02505"
"209.16000","17.43014","0.02627"
"209.41200","17.45107","0.02675"
"209.66400","17.47212","0.02723"
"209.91600","17.49310","0.02743"
"210.16800","17.51421","0.02845"
"210.42000","17.53507","0.02864"
"210.67200","17.55612","0.02940"
"210.92400","17.57711","0.02959"
"211.17600","17.59815","0.03025"
"211.42800","17.61908","0.03127"
"211.68000","17.64013","0.03112"
"211.93200","17.66117","0.03182"
"212.18400","17.68216","0.03266"
"212.43600","17.70314","0.03331"
"212.68800","17.72413","0.03454"
"212.94000","17.74512","0.03473"
"213.19200","17.76610","0.03369"
"213.44400","17.78715","0.03503"
"213.69600","17.80807","0.03624"
"213.94800","17.82918","0.03672"
"214.20000","17.85011","0.03611"
"214.45200","17.87115","0.02944"
"214.70400","17.89214","0.03031"
"214.95600","17.91318","0.03188"
"215.20800","17.93411","0.03242"
"215.46000","17.95516","0.03330"
"215.71200","17.97608","0.03499"
"215.96400","17.99713","0.03530"
"216.21600","18.01817","0.02803"
"216.46800","18.03910","0.02534"
"216.72000","18.06015","0.02552"
"216.97200","18.08113","0.02487"
"217.22400","18.10218","0.02732"
"217.47600","18.12311","0.02446"
"217.72800","18.14415","0.02736"
"217.98000","18.16508","0.02694"
"218.23200","18.18618","0.02799"
"218.48400","18.20717","0.02873"
"218.73600","18.22816","0.02795"
"218.98800","18.24908","0.02886"
"219.24000","18.27019","0.02913"
"219.49200","18.29111","0.02959"
"219.74400","18.31216","0.03058"
"219.99600","18.33308","0.03134"
"220.24800","18.35413","0.03178"
"220.50000","18.37518","0.03241"
"220.75200","18.39616","0.03255"
"221.00400","18.41721","0.03339"
"221.25600","18.43814","0.03472"
"221.50800","18.45918","0.03443"
"221.76000","18.48005","0.03360"
"222.01200","18.50115","0.03373"
"222.26400","18.52208","0.03535"
"222.51600","18.54319","0.03538"
"222.76800","18.56411","0.03546"
"223.02000","18.58516","0.03810"
"223.27200","18.60608","0.03733"
"223.52400","18.62719","0.03730"
"223.77600","18.64812","0.03800"
"224.02800","18.66910","0.03790"
"224.28000","18.69015","0.03873"
"224.53200","18.71113","0.04008"
"224.78400","18.73218","0.04123"
"225.03600","18.75317","0.04145"
"225.28800","18.77415","0.04179"
"225.54000","18.79514","0.04280"
"225.79200","18.81612","0.04348"
"226.04400","18.83705","0.04358"
"226.29600","18.85816","0.04456"
"226.54800","18.87914","0.04481"
"226.80000","18.90019","0.04478"
"227.05200","18.92111","0.04532"
"227.30400","18.94216","0.04434"
"227.55600","18.96315","0.04518"
"227.80800","18.98419","0.04446"
"228.06000","19.00512","0.04518"
"228.31200","19.02611","0.04474"
"228.56400","19.04709","0.04253"
"228.81600","19.06814","0.04015"
"229.06800","19.08918","0.04221"
"229.32000","19.11011","0.04288"
"229.57200","19.13116","0.04134"
"229.82400","19.15208","0.04469"
"230.07600","19.17313","0.04254"
"230.32800","19.19406","0.04473"
"230.58000","19.21516","0.04466"
"230.83200","19.23615","0.04522"
"231.08400","19.25713","0.04612"
"231.33600","19.27812","0.04568"
"231.58800","19.29916","0.04647"
"231.84000","19.32015","0.04645"
"232.09200","19.34108","0.04685"
"232.34400","19.36212","0.04728"
"232.59600","19.38311","0.04729"
"232.84800","19.40415","0.04700"
"233.10000","19.42514","0.04831"
"233.35200","19.44619","0.04794"
"233.60400","19.46711","0.04852"
"233.85600","19.48822","0.04883"
"234.10800","19.50909","0.04901"
"234.36000","19.53013","0.04959"
"234.61200","19.55106","0.04963"
"234.86400","19.57216","0.05004"
"235.11600","19.59315","0.05088"
"235.36800","19.61414","0.05101"
"235.62000","19.63512","0.05125"
"235.87200","19.65617","0.05231"
"236.12400","19.67715","0.05260"
"236.37600","19.69814","0.05324"
"236.62800","19.71913","0.05375"
"236.88000","19.74011","0.05384"
"237.13200","19.76116","0.05461"
"237.38400","19.78209","0.05531"
"237.63600","19.80313","0.05586"
"237.88800","19.82412","0.05703"
"238.14000","19.84516","0.05760"
"238.39200","19.86609","0.05836"
"238.64400","19.88713","0.05792"
"238.89600","19.90812","0.05673"
"239.14800","19.92917","0.05575"
"239.40000","19.95009","0.05621"
"239.65200","19.97114","0.05805"
"239.90400","19.99213","0.05800"
"240.15600","20.01317","0.05860"
"240.40800","20.03410","0.05913"
"240.66000","20.05514","0.05992"
"240.91200","20.07619","0.06138"
"241.16400","20.09711","0.06127"
"241.41600","20.11816","0.06235"
"241.66800","20.13909","0.06370"
"241.92000","20.16014","0.06371"
"242.17200","20.18112","0.06536"
"242.42400","20.20210","0.06534"
"242.67600","20.22309","0.06636"
"242.92800","20.24414","0.06776"
"243.18000","20.26513","0.06854"
"243.43200","20.28617","0.06976"
"243.68400","20.30716","0.07058"
"243.93600","20.32814","0.07115"
"244.18800","20.34913","0.07181"
"244.44000","20.37011","0.07274"
"244.69200","20.39110","0.07353"
"244.94400","20.41209","0.07441"
"245.19600","20.43313","0.07531"
"245.44800","20.45412","0.07636"
"245.70000","20.47517","0.07693"
"245.95200","20.49615","0.07754"
"246.20400","20.51714","0.07872"
"246.45600","20.53806","0.07908"
"246.70800","20.55911","0.07970"
"246.96000","20.58010","0.08037"
"247.21200","20.60120","0.08079"
"247.46400","20.62213","0.08201"
"247.71600","20.64317","0.08297"
"247.96800","20.66416","0.08321"
"248.22000","20.68514","0.08441"
"248.47200","20.70619","0.08501"
"248.72400","20.72712","0.08560"
"248.97600","20.74817","0.08632"
"249.22800","20.76909","0.08746"
"249.48000","20.79014","0.08743"
"249.73200","20.81106","0.08870"
"249.98400","20.83217","0.08865"
"250.23600","20.85315","0.08923"
"250.48800","20.87420","0.08995"
"250.74000","20.89513","0.09006"
"250.99200","20.91611","0.09135"
"251.24400","20.93710","0.09160"
"251.49600","20.95815","0.09176"
"251.74800","20.97913","0.09194"
"252.00000","21.00018","0.09291"
"252.25200","21.02116","0.09317"
"252.50400","21.04215","0.09338"
"252.75600","21.06314","0.09377"
"253.00800","21.08412","0.09378"
"253.26000","21.10517","0.00527"
"253.51200","21.12609","0.02477"
"253.76400","21.14714","0.01520"
"254.01600","21.16807","0.01464"
"254.26800","21.18911","0.01485"
"254.52000","21.21016","0.01470"
"254.77200","21.23114","0.01963"
"255.02400","21.25207","0.00908"
"255.27600","21.27318","0.01977"
"255.52800","21.29410","0.01140"
"255.78000","21.31515","0.01246"
"256.03200","21.33607","0.01553"
"256.28400","21.35712","0.01198"
"256.53600","21.37823","0.01780"
"256.78800","21.39909","0.01257"
"257.04000","21.42014","0.01581"
"257.29200","21.44106","0.01674"
"257.54400","21.46217","0.01470"
"257.79600","21.48310","0.01726"
"258.04800","21.50414","0.01692"
"258.30000","21.52507","0.01822"
"258.55200","21.54618","0.01730"
"258.80400","21.56710","0.01921"
"259.05600","21.58815","0.01784"
"259.30800","21.60913","0.01851"
"259.56000","21.63018","0.01932"
"259.81200","21.65117","0.01786"
"260.06400","21.67209","0.01996"
"260.31600","21.69314","0.01798"
"260.56800","21.71412","0.01994"
"260.82000","21.73517","0.02079"
"261.07200","21.75615","0.01829"
"261.32400","21.77714","0.02230"
"261.57600","21.79813","0.02053"
"261.82800","21.81917","0.02075"
"262.08000","21.84010","0.02339"
"262.33200","21.86109","0.02079"
"262.58400","21.88207","0.02261"
"262.83600","21.90318","0.02342"
"263.08800","21.92410","0.02223"
"263.34000","21.94515","0.02432"
"263.59200","21.96614","0.02212"
"263.84400","21.98718","0.02361"
"264.09600","22.00817","0.02464"
"264.34800","22.02909","0.02320"
"264.60000","22.05014","0.02539"
"264.85200","22.07113","0.02502"
"265.10400","22.09217","0.02416"
"265.35600","22.11310","0.02634"
"265.60800","22.13415","0.02531"
"265.86000","22.15513","0.02678"
"266.11200","22.17618","0.02797"
"266.36400","22.19710","0.02676"
"266.61600","22.21815","0.02885"
"266.86800","22.23907","0.02920"
"267.12000","22.26018","0.02921"
"267.37200","22.28111","0.03013"
"267.62400","22.30215","0.03063"
"267.87600","22.32320","0.03148"
"268.12800","22.34413","0.03253"
"268.38000","22.36511","0.03371"
"268.63200","22.38610","0.03340"
"268.88400","22.40714","0.03379"
"269.13600","22.42807","0.03495"
"269.38800","22.44912","0.03483"
"269.64000","22.47010","0.03581"
"269.89200","22.49115","0.03711"
"270.14400","22.51213","0.03754"
"270.39600","22.53312","0.03755"
"270.64800","22.55411","0.03832"
"270.90000","22.57521","0.03840"
"271.15200","22.59614","0.03568"
"271.40400","22.61712","0.03568"
"271.65600","22.63805","0.03508"
"271.90800","22.65916","0.03535"
"272.16000","22.68014","0.03501"
"272.41200","22.70113","0.03775"
"272.66400","22.72218","0.03672"
"272.91600","22.74310","0.03864"
"273.16800","22.76415","0.03848"
"273.42000","22.78507","0.03989"
"273.67200","22.80612","0.04047"
"273.92400","22.82711","0.04106"
"274.17600","22.84821","0.04192"
"274.42800","22.86908","0.04243"
"274.68000","22.89012","0.04365"
"274.93200","22.91111","0.04363"
"275.18400","22.93216","0.04445"
"275.43600","22.95308","0.04455"
"275.68800","22.97413","0.04529"
"275.94000","22.99511","0.04574"
"276.19200","23.01616","0.04615"
"276.44400","23.03715","0.04662"
"276.69600","23.05813","0.04760"
"276.94800","23.07918","0.04775"
"277.20000","23.10016","0.04818"
"277.45200","23.12115","0.04843"
"277.70400","23.14208","0.04877"
"277.95600","23.16312","0.04951"
"278.20800","23.18411","0.04982"
"278.46000","23.20515","0.05050"
"278.71200","23.22608","0.05091"
"278.96400","23.24719","0.05137"
"279.21600","23.26811","0.05211"
"279.46800","23.28916","0.05242"
"279.72000","23.31008","0.05332"
"279.97200","23.33107","0.05414"
"280.22400","23.35212","0.05436"
"280.47600","23.37316","0.05507"
"280.72800","23.39415","0.05601"
"280.98000","23.41508","0.05678"
"281.23200","23.43618","0.05795"
"281.48400","23.45711","0.05937"
"281.73600","23.47815","0.06053"
"281.98800","23.49914","0.06186"
"282.24000","23.52019","0.06329"
"282.49200","23.54111","0.06451"
"282.74400","23.56210","0.06575"
"282.99600","23.58308","0.06755"
"283.24800","23.60419","0.06916"
"283.50000","23.62518","0.07074"
"283.75200","23.64616","0.07166"
"284.00400","23.66715","0.07317"
"284.25600","23.68813","0.07464"
"284.50800","23.70918","0.07536"
"284.76000","23.73011","0.07720"
"285.01200","23.75115","0.07757"
"285.26400","23.77214","0.07919"
"285.51600","23.79318","0.08000"
"285.76800","23.81411","0.08096"
"286.02000","23.83510","0.08215"
"286.27200","23.85608","0.08288"
"286.52400","23.87719","0.08433"
"286.77600","23.89812","0.08533"
"287.02800","23.91916","0.08639"
"287.28000","23.94015","0.08700"
"287.53200","23.96113","0.08845"
"287.78400","23.98212","0.08906"
"288.03600","24.00311","0.09025"
"288.28800","24.02409","0.09103"
"288.54000","24.04514","0.09102"
"288.79200","24.06618","0.09188"
"289.04400","24.08711","0.09291"
"289.29600","24.10816","0.09362"
"289.54800","24.12908","0.09461"
"289.80000","24.15013","0.09459"
"290.05200","24.17112","0.09532"
"290.30400","24.19216","0.09592"
"290.55600","24.21309","0.09613"
"290.80800","24.23419","0.09658"
"291.06000","24.25512","0.09653"
"291.31200","24.27616","0.09702"
"291.56400","24.29715","0.09758"
"291.81600","24.31820","0.09758"
"292.06800","24.33912","0.09773"
"292.32000","24.36005","0.09808"
"292.57200","24.38116","0.09824"
"292.82400","24.40214","0.09839"
"293.07600","24.42319","0.09830"
"293.32800","24.44411","0.09851"
"293.58000","24.46516","0.09890"
"293.83200","24.48615","0.09929"
"294.08400","24.50713","0.09948"
"294.33600","24.52806","0.09925"
"294.58800","24.54916","0.10019"
"294.84000","24.57015","0.09997"
"295.09200","24.59114","0.10057"
"295.34400","24.61212","0.10105"
"295.59600","24.63311","0.10163"
"295.84800","24.65416","0.10187"
"296.10000","24.67508","0.10214"
"296.35200","24.69613","0.10278"
"296.60400","24.71717","0.10349"
"296.85600","24.73816","0.10476"
"297.10800","24.75908","0.10481"
"297.36000","24.78019","0.10592"
"297.61200","24.80112","0.10645"
"297.86400","24.82216","0.10747"
"298.11600","24.84309","0.10773"
"298.36800","24.86413","0.10846"
"298.62000","24.88506","0.10992"
"298.87200","24.90623","0.11110"
"299.12400","24.92709","0.11167"
"299.37600","24.94814","0.11277"
"299.62800","24.96919","0.11303"
"299.88000","24.99017","0.11509"
"300.13200","25.01116","0.11651"
"300.38400","25.03208","0.11647"
"300.63600","25.05313","0.11800"
"300.88800","25.07405","0.11870"
"301.14000","25.09516","0.12002"
"301.39200","25.11609","0.12045"
"301.64400","25.13713","0.12165"
"301.89600","25.15806","0.12262"
"302.14800","25.17916","0.12307"
"302.40000","25.20009","0.12383"
"302.65200","25.22114","0.12447"
"302.90400","25.24212","0.12550"
"303.15600","25.26317","0.12641"
"303.40800","25.28410","0.12730"
"303.66000","25.30514","0.12813"
"303.91200","25.32613","0.12830"
"304.16400","25.34717","0.12937"
"304.41600","25.36816","0.12951"
"304.66800","25.38915","0.13083"
"304.92000","25.41013","0.13114"
"305.17200","25.43112","0.13157"
"305.42400","25.45210","0.13237"
"305.67600","25.47309","0.13263"
"305.92800","25.49414","0.13246"
"306.18000","25.51512","0.13398"
"306.43200","25.53611","0.13470"
"306.68400","25.55709","0.13438"
"306.93600","25.57814","0.13504"
"307.18800","25.59913","0.13674"
"307.44000","25.62017","0.13635"
"307.69200","25.64110","0.13796"
"307.94400","25.66215","0.13764"
"308.19600","25.68319","0.13924"
"308.44800","25.70412","0.13990"
"308.70000","25.72516","0.13981"
"308.95200","25.74609","0.14051"
"309.20400","25.76720","0.14078"
"309.45600","25.78812","0.14293"
"309.70800","25.80917","0.14231"
"309.96000","25.83009","0.14275"
"310.21200","25.85114","0.14436"
"310.46400","25.87213","0.14426"
"310.71600","25.89317","0.14536"
"310.96800","25.91410","0.14460"
"311.22000","25.93514","0.14595"
"311.47200","25.95619","0.14661"
"311.72400","25.97712","0.14720"
"311.97600","25.99816","0.14816"
"312.22800","26.01915","0.14877"
"312.48000","26.04013","0.14883"
"312.73200","26.06112","0.14998"
"312.98400","26.08217","0.15003"
"313.23600","26.10309","0.15066"
"313.48800","26.12420","0.15179"
"313.74000","26.14513","0.15253"
"313.99200","26.16617","0.15255"
"314.24400","26.18710","0.15302"
"314.49600","26.20820","0.15384"
"314.74800","26.22913","0.15427"
"315.00000","26.25012","0.15426"
"315.25200","26.27110","0.15464"
"315.50400","26.29215","0.15526"
"315.75600","26.31313","0.15557"
"316.00800","26.33412","0.15600"
"316.26000","26.35511","0.15630"
"316.51200","26.37615","0.15684"
"316.76400","26.39714","0.15694"
"317.01600","26.41806","0.15742"
"317.26800","26.43917","0.15744"
"317.52000","26.46010","0.15790"
"317.77200","26.48114","0.15822"
"318.02400","26.50213","0.15857"
"318.27600","26.52312","0.15847"
"318.52800","26.54404","0.15910"
"318.78000","26.56515","0.15931"
"319.03200","26.58607","0.15955"
"319.28400","26.60712","0.15979"
"319.53600","26.62817","0.15979"
"319.78800","26.64915","0.16062"
"320.04000","26.67014","0.16057"
"320.29200","26.69113","0.16092"
"320.54400","26.71217","0.16165"
"320.79600","26.73316","0.16213"
"321.04800","26.75414","0.16262"
"321.30000","26.77507","0.16319"
"321.55200","26.79612","0.16432"
"321.80400","26.81710","0.16600"
"322.05600","26.83815","0.16703"
"322.30800","26.85913","0.16962"
"322.56000","26.88018","0.17037"
"322.81200","26.90110","0.17207"
"323.06400","26.92209","0.17349"
"323.31600","26.94308","0.17468"
"323.56800","26.96418","0.17603"
"323.82000","26.98517","0.17805"
"324.07200","27.00610","0.17942"
"324.32400","27.02714","0.18045"
"324.57600","27.04813","0.18196"
"324.82800","27.06917","0.18331"
"325.08000","27.09004","0.18493"
"325.33200","27.11115","0.18655"
"325.58400","27.13213","0.18800"
"325.83600","27.15318","0.18911"
"326.08800","27.17404","0.19115"
"326.34000","27.19521","0.19209"
"326.59200","27.21614","0.19313"
"326.84400","27.23718","0.19438"
"327.09600","27.25811","0.19597"
"327.34800","27.27909","0.19688"
"327.60000","27.30014","0.19796"
"327.85200","27.32113","0.19852"
"328.10400","27.34217","0.19901"
"328.35600","27.36310","0.19965"
"328.60800","27.38414","0.20073"
"328.86000","27.40513","0.20153"
"329.11200","27.42612","0.20190"
"329.36400","27.44704","0.20249"
"329.61600","27.46815","0.20307"
"329.86800","27.48907","0.20402"
"330.12000","27.51018","0.20430"
"330.37200","27.53111","0.20443"
"330.62400","27.55215","0.20535"
"330.87600","27.57314","0.20596"
"331.12800","27.59413","0.20663"
"331.38000","27.61511","0.20707"
"331.63200","27.63616","0.20740"
"331.88400","27.65721","0.20769"
"332.13600","27.67813","0.20865"
"332.38800","27.69917","0.20945"
"332.64000","27.72010","0.20973"
"332.89200","27.74121","0.21074"
"333.14400","27.76213","0.21086"
"333.39600","27.78312","0.21134"
"333.64800","27.80410","0.21238"
"333.90000","27.82515","0.21328"
"334.15200","27.84614","0.21418"
"334.40400","27.86718","0.21476"
"334.65600","27.88811","0.21569"
"334.90800","27.90916","0.21643"
"335.16000","27.93020","0.21700"
"335.41200","27.95113","0.21831"
"335.66400","27.97211","0.21857"
"335.91600","27.99310","0.21969"
"336.16800","28.01421","0.22024"
"336.42000","28.03507","0.22106"
"336.67200","28.05612","0.22167"
"336.92400","28.07705","0.22219"
"337.17600","28.09815","0.22340"
"337.42800","28.11908","0.22378"
"337.68000","28.14012","0.22513"
"337.93200","28.16111","0.22549"
"338.18400","28.18216","0.22666"
"338.43600","28.20314","0.22704"
"338.68800","28.22413","0.22760"
"338.94000","28.24511","0.22864"
"339.19200","28.26610","0.22917"
"339.44400","28.28714","0.22993"
"339.69600","28.30813","0.23105"
"339.94800","28.32912","0.23156"
"340.20000","28.35016","0.23265"
"340.45200","28.37115","0.23352"
"340.70400","28.39214","0.23380"
"340.95600","28.41318","0.23461"
"341.20800","28.43411","0.23587"
"341.46000","28.45515","0.23648"
"341.71200","28.47608","0.23788"
"341.96400","28.49713","0.23871"
"342.21600","28.51811","0.23970"
"342.46800","28.53916","0.24101"
"342.72000","28.56014","0.24246"
"342.97200","28.58119","0.24288"
"343.22400","28.60217","0.24374"
"343.47600","28.62316","0.24421"
"343.72800","28.64415","0.24524"
"343.98000","28.66508","0.24615"
"344.23200","28.68612","0.24675"
"344.48400","28.70711","0.24752"
"344.73600","28.72815","0.24781"
"344.98800","28.74908","0.24861"
"345.24000","28.77013","0.24927"
"345.49200","28.79111","0.24957"
"345.74400","28.81216","0.25025"
"345.99600","28.83314","0.25084"
"346.24800","28.85413","0.25097"
"346.50000","28.87506","0.25153"
"346.75200","28.89616","0.25202"
"347.00400","28.91709","0.25258"
"347.25600","28.93813","0.25327"
"347.50800","28.95918","0.25399"
"347.76000","28.98011","0.25493"
"348.01200","29.00115","0.25536"
"348.26400","29.02214","0.25578"
"348.51600","29.04313","0.25589"
"348.76800","29.06411","0.25605"
"349.02000","29.08516","0.25694"
"349.27200","29.10614","0.25811"
"349.52400","29.12719","0.25903"
"349.77600","29.14806","0.26014"
"350.02800","29.16916","0.25979"
"350.28000","29.19015","0.26085"
"350.53200","29.21119","0.26154"
"350.78400","29.23212","0.26188"
"351.03600","29.25317","0.26265"
"351.28800","29.27409","0.26354"
"351.54000","29.29514","0.26428"
"351.79200","29.31618","0.26473"
"352.04400","29.33705","0.26575"
"352.29600","29.35816","0.26727"
"352.54800","29.37914","0.26788"
"352.80000","29.40019","0.26890"
"353.05200","29.42105","0.26962"
"353.30400","29.44216","0.27152"
"353.55600","29.46309","0.27192"
"353.80800","29.48413","0.27372"
"354.06000","29.50512","0.27507"
"354.31200","29.52617","0.27602"
"354.56400","29.54715","0.27739"
"354.81600","29.56814","0.27780"
"355.06800","29.58912","0.27822"
"355.32000","29.61011","0.27919"
"355.57200","29.63116","0.27867"
"355.82400","29.65214","0.27925"
"356.07600","29.67313","0.28016"
"356.32800","29.69405","0.28129"
"356.58000","29.71516","0.28185"
"356.83200","29.73609","0.28166"
"357.08400","29.75713","0.28324"
"357.33600","29.77812","0.28324"
"357.58800","29.79917","0.28393"
"357.84000","29.82009","0.28501"
"358.09200","29.84114","0.28572"
"358.34400","29.86206","0.28643"
"358.59600","29.88317","0.28134"
"358.84800","29.90415","0.27360"
"359.10000","29.92520","0.27052"
"359.35200","29.94607","0.27083"
"359.60400","29.96711","0.27338"
"359.85600","29.98816","0.27631"
"360.10800","30.00914","0.27809"
"360.36000","30.03013","0.28027"
"360.61200","30.05106","0.28169"
"360.86400","30.07216","0.28376"
"361.11600","30.09309","0.28587"
"361.36800","30.11414","0.28705"
"361.62000","30.13506","0.28902"
"361.87200","30.15617","0.28970"
"362.12400","30.17709","0.29144"
"362.37600","30.19814","0.29287"
"362.62800","30.21907","0.29424"
"362.88000","30.24011","0.29587"
"363.13200","30.26116","0.29725"
"363.38400","30.28214","0.29763"
"363.63600","30.30313","0.29925"
"363.88800","30.32418","0.29966"
"364.14000","30.34522","0.29970"
"364.39200","30.36609","0.30006"
"364.64400","30.38713","0.30007"
"364.89600","30.40806","0.30024"
"365.14800","30.42917","0.29935"
"365.40000","30.45015","0.29789"
"365.65200","30.47120","0.27510"
"365.90400","30.49212","0.00060"
"366.15600","30.51317","0.00723"
"366.40800","30.53410","0.00733"
"366.66000","30.55514","0.00730"
"366.91200","30.57613","0.00925"
"367.16400","30.59711","0.00687"
"367.41600","30.61816","0.00675"
"367.66800","30.63909","0.00642"
"367.92000","30.66013","0.00623"
"368.17200","30.68112","0.00738"
"368.42400","30.70217","0.00649"
"368.67600","30.72309","0.00673"
"368.92800","30.74414","0.00631"
"369.18000","30.76506","0.00630"
"369.43200","30.78617","0.00702"
"369.68400","30.80710","0.00674"
"369.93600","30.82820","0.00651"
"370.18800","30.84913","0.00655"
"370.44000","30.87017","0.00641"
"370.69200","30.89110","0.00690"
"370.94400","30.91215","0.00661"
"371.06400","30.92213","0.00646"