File: Force_trajectories/161217/Specimen_RawData_6.csv
End date,"12/17/2016"
Specimen label,"15CG_21"
Maximum Load,"0.00672",N

Time,Extension,Load
(s),(mm),(N)
"0.00000","0.00000","-0.00007"
"0.06600","0.00167","-0.00024"
"0.13200","0.00676","-0.00029"
"0.19800","0.01381","-0.00010"
"0.26400","0.02087","-0.00015"
"0.33000","0.02732","0.00010"
"0.39600","0.03318","0.00022"
"0.46200","0.03874","0.00023"
"0.52800","0.04424","0.00007"
"0.59400","0.04969","0.00064"
"0.66000","0.05519","0.00023"
"0.72600","0.06081","0.00065"
"0.79200","0.06619","0.00055"
"0.85800","0.07175","0.00028"
"0.92400","0.07719","0.00052"
"0.99000","0.08269","0.00038"
"1.05600","0.08813","0.00057"
"1.12200","0.09369","0.00059"
"1.18800","0.09919","0.00045"
"1.25400","0.10469","0.00064"
"1.32000","0.11019","0.00108"
"1.38600","0.11569","0.00104"
"1.45200","0.12119","0.00088"
"1.51800","0.12663","0.00084"
"1.58400","0.13213","0.00089"
"1.65000","0.13764","0.00058"
"1.71600","0.14314","0.00115"
"1.78200","0.14870","0.00074"
"1.84800","0.15420","0.00077"
"1.91400","0.15970","0.00085"
"1.98000","0.16520","0.00083"
"2.04600","0.17070","0.00097"
"2.11200","0.17614","0.00104"
"2.17800","0.18164","0.00114"
"2.24400","0.18720","0.00115"
"2.31000","0.19270","0.00094"
"2.37600","0.19820","0.00122"
"2.44200","0.20370","0.00123"
"2.50800","0.20920","0.00125"
"2.57400","0.21470","0.00101"
"2.64000","0.22015","0.00117"
"2.70600","0.22565","0.00123"
"2.77200","0.23115","0.00120"
"2.83800","0.23671","0.00092"
"2.90400","0.24221","0.00146"
"2.97000","0.24771","0.00133"
"3.03600","0.25321","0.00138"
"3.10200","0.25865","0.00142"
"3.16800","0.26415","0.00109"
"3.23400","0.26959","0.00133"
"3.30000","0.27521","0.00116"
"3.36600","0.28071","0.00135"
"3.43200","0.28621","0.00131"
"3.49800","0.29165","0.00136"
"3.56400","0.29721","0.00177"
"3.63000","0.30265","0.00167"
"3.69600","0.30816","0.00138"
"3.76200","0.31360","0.00169"
"3.82800","0.31916","0.00157"
"3.89400","0.32472","0.00141"
"3.96000","0.33022","0.00161"
"4.02600","0.33566","0.00181"
"4.09200","0.34122","0.00145"
"4.15800","0.34672","0.00177"
"4.22400","0.35216","0.00174"
"4.29000","0.35766","0.00132"
"4.35600","0.36310","0.00175"
"4.42200","0.36872","0.00146"
"4.48800","0.37422","0.00163"
"4.55400","0.37972","0.00168"
"4.62000","0.38516","0.00189"
"4.68600","0.39066","0.00170"
"4.75200","0.39617","0.00159"
"4.81800","0.40161","0.00152"
"4.88400","0.40717","0.00163"
"4.95000","0.41261","0.00193"
"5.01600","0.41823","0.00185"
"5.08200","0.42367","0.00188"
"5.14800","0.42923","0.00172"
"5.21400","0.43467","0.00181"
"5.28000","0.44017","0.00191"
"5.34600","0.44561","0.00169"
"5.41200","0.45111","0.00190"
"5.47800","0.45667","0.00188"
"5.54400","0.46217","0.00223"
"5.61000","0.46767","0.00180"
"5.67600","0.47323","0.00174"
"5.74200","0.47868","0.00210"
"5.80800","0.48418","0.00180"
"5.87400","0.48962","0.00186"
"5.94000","0.49512","0.00198"
"6.00600","0.50062","0.00176"
"6.07200","0.50618","0.00210"
"6.13800","0.51168","0.00188"
"6.20400","0.51718","0.00195"
"6.27000","0.52268","0.00190"
"6.33600","0.52818","0.00199"
"6.40200","0.53368","0.00173"
"6.46800","0.53912","0.00197"
"6.53400","0.54462","0.00202"
"6.60000","0.55018","0.00212"
"6.66600","0.55568","0.00205"
"6.73200","0.56124","0.00219"
"6.79800","0.56669","0.00222"
"6.86400","0.57219","0.00204"
"6.93000","0.57763","0.00220"
"6.99600","0.58313","0.00213"
"7.06200","0.58863","0.00224"
"7.12800","0.59419","0.00195"
"7.19400","0.59969","0.00198"
"7.26000","0.60519","0.00236"
"7.32600","0.61069","0.00222"
"7.39200","0.61619","0.00212"
"7.45800","0.62169","0.00192"
"7.52400","0.62707","0.00219"
"7.59000","0.63263","0.00238"
"7.65600","0.63813","0.00188"
"7.72200","0.64369","0.00241"
"7.78800","0.64913","0.00188"
"7.85400","0.65470","0.00204"
"7.92000","0.66014","0.00229"
"7.98600","0.66564","0.00195"
"8.05200","0.67114","0.00248"
"8.11800","0.67658","0.00246"
"8.18400","0.68214","0.00199"
"8.25000","0.68770","0.00228"
"8.31600","0.69320","0.00219"
"8.38200","0.69864","0.00186"
"8.44800","0.70420","0.00219"
"8.51400","0.70964","0.00216"
"8.58000","0.71514","0.00231"
"8.64600","0.72064","0.00231"
"8.71200","0.72620","0.00230"
"8.77800","0.73164","0.00257"
"8.84400","0.73715","0.00203"
"8.91000","0.74271","0.00239"
"8.97600","0.74821","0.00224"
"9.04200","0.75371","0.00252"
"9.10800","0.75915","0.00226"
"9.17400","0.76471","0.00227"
"9.24000","0.77015","0.00223"
"9.30600","0.77571","0.00242"
"9.37200","0.78115","0.00262"
"9.43800","0.78671","0.00243"
"9.50400","0.79215","0.00229"
"9.57000","0.79765","0.00251"
"9.63600","0.80309","0.00255"
"9.70200","0.80859","0.00261"
"9.76800","0.81415","0.00275"
"9.83400","0.81971","0.00232"
"9.90000","0.82516","0.00196"
"9.96600","0.83066","0.00262"
"10.03200","0.83622","0.00235"
"10.09800","0.84166","0.00277"
"10.16400","0.84722","0.00281"
"10.23000","0.85266","0.00255"
"10.29600","0.85816","0.00245"
"10.36200","0.86366","0.00233"
"10.42800","0.86922","0.00267"
"10.49400","0.87472","0.00248"
"10.56000","0.88022","0.00251"
"10.62600","0.88572","0.00234"
"10.69200","0.89110","0.00258"
"10.75800","0.89666","0.00274"
"10.82400","0.90216","0.00248"
"10.89000","0.90772","0.00236"
"10.95600","0.91317","0.00292"
"11.02200","0.91867","0.00231"
"11.08800","0.92423","0.00280"
"11.15400","0.92967","0.00259"
"11.22000","0.93517","0.00250"
"11.28600","0.94067","0.00287"
"11.35200","0.94617","0.00243"
"11.41800","0.95167","0.00261"
"11.48400","0.95723","0.00235"
"11.55000","0.96267","0.00261"
"11.61600","0.96817","0.00277"
"11.68200","0.97367","0.00277"
"11.74800","0.97917","0.00276"
"11.81400","0.98461","0.00248"
"11.88000","0.99017","0.00280"
"11.94600","0.99568","0.00251"
"12.01200","1.00124","0.00255"
"12.07800","1.00668","0.00254"
"12.14400","1.01218","0.00243"
"12.21000","1.01774","0.00257"
"12.27600","1.02312","0.00268"
"12.34200","1.02862","0.00223"
"12.40800","1.03412","0.00272"
"12.47400","1.03968","0.00267"
"12.54000","1.04518","0.00274"
"12.60600","1.05074","0.00271"
"12.67200","1.05618","0.00260"
"12.73800","1.06174","0.00282"
"12.80400","1.06718","0.00257"
"12.87000","1.07262","0.00294"
"12.93600","1.07807","0.00264"
"13.00200","1.08363","0.00277"
"13.06800","1.08925","0.00263"
"13.13400","1.09469","0.00281"
"13.20000","1.10019","0.00305"
"13.26600","1.10569","0.00270"
"13.33200","1.11119","0.00289"
"13.39800","1.11669","0.00299"
"13.46400","1.12213","0.00286"
"13.53000","1.12763","0.00276"
"13.59600","1.13313","0.00275"
"13.66200","1.13869","0.00246"
"13.72800","1.14419","0.00267"
"13.79400","1.14969","0.00284"
"13.86000","1.15513","0.00294"
"13.92600","1.16063","0.00313"
"13.99200","1.16614","0.00265"
"14.05800","1.17164","0.00275"
"14.12400","1.17714","0.00303"
"14.19000","1.18270","0.00291"
"14.25600","1.18820","0.00282"
"14.32200","1.19370","0.00277"
"14.38800","1.19914","0.00292"
"14.45400","1.20464","0.00289"
"14.52000","1.21008","0.00280"
"14.58600","1.21564","0.00303"
"14.65200","1.22120","0.00285"
"14.71800","1.22670","0.00291"
"14.78400","1.23220","0.00320"
"14.85000","1.23770","0.00335"
"14.91600","1.24320","0.00294"
"14.98200","1.24864","0.00281"
"15.04800","1.25415","0.00318"
"15.11400","1.25965","0.00286"
"15.18000","1.26521","0.00301"
"15.24600","1.27071","0.00290"
"15.31200","1.27615","0.00313"
"15.37800","1.28171","0.00331"
"15.44400","1.28721","0.00309"
"15.51000","1.29271","0.00289"
"15.57600","1.29815","0.00271"
"15.64200","1.30365","0.00305"
"15.70800","1.30915","0.00288"
"15.77400","1.31471","0.00321"
"15.84000","1.32015","0.00308"
"15.90600","1.32571","0.00312"
"15.97200","1.33115","0.00356"
"16.03800","1.33665","0.00333"
"16.10400","1.34216","0.00311"
"16.17000","1.34760","0.00312"
"16.23600","1.35316","0.00311"
"16.30200","1.35866","0.00328"
"16.36800","1.36422","0.00298"
"16.43400","1.36966","0.00337"
"16.50000","1.37522","0.00310"
"16.56600","1.38066","0.00297"
"16.63200","1.38622","0.00304"
"16.69800","1.39160","0.00308"
"16.76400","1.39716","0.00315"
"16.83000","1.40266","0.00272"
"16.89600","1.40822","0.00292"
"16.96200","1.41372","0.00345"
"17.02800","1.41922","0.00327"
"17.09400","1.42472","0.00293"
"17.16000","1.43017","0.00306"
"17.22600","1.43567","0.00312"
"17.29200","1.44117","0.00338"
"17.35800","1.44667","0.00317"
"17.42400","1.45223","0.00334"
"17.49000","1.45767","0.00296"
"17.55600","1.46317","0.00321"
"17.62200","1.46867","0.00331"
"17.68800","1.47417","0.00319"
"17.75400","1.47961","0.00331"
"17.82000","1.48517","0.00321"
"17.88600","1.49061","0.00324"
"17.95200","1.49617","0.00326"
"18.01800","1.50167","0.00322"
"18.08400","1.50717","0.00309"
"18.15000","1.51262","0.00323"
"18.21600","1.51818","0.00343"
"18.28200","1.52362","0.00326"
"18.34800","1.52918","0.00312"
"18.41400","1.53462","0.00368"
"18.48000","1.54024","0.00314"
"18.54600","1.54568","0.00356"
"18.61200","1.55118","0.00318"
"18.67800","1.55662","0.00367"
"18.74400","1.56212","0.00343"
"18.81000","1.56762","0.00345"
"18.87600","1.57312","0.00332"
"18.94200","1.57868","0.00330"
"19.00800","1.58418","0.00350"
"19.07400","1.58968","0.00327"
"19.14000","1.59524","0.00338"
"19.20600","1.60069","0.00331"
"19.27200","1.60613","0.00341"
"19.33800","1.61163","0.00342"
"19.40400","1.61713","0.00294"
"19.47000","1.62269","0.00365"
"19.53600","1.62819","0.00347"
"19.60200","1.63369","0.00339"
"19.66800","1.63919","0.00363"
"19.73400","1.64469","0.00328"
"19.80000","1.65019","0.00312"
"19.86600","1.65563","0.00364"
"19.93200","1.66119","0.00331"
"19.99800","1.66663","0.00346"
"20.06400","1.67219","0.00358"
"20.13000","1.67769","0.00339"
"20.19600","1.68319","0.00353"
"20.26200","1.68870","0.00349"
"20.32800","1.69414","0.00389"
"20.39400","1.69958","0.00307"
"20.46000","1.70508","0.00376"
"20.52600","1.71070","0.00345"
"20.59200","1.71620","0.00362"
"20.65800","1.72176","0.00349"
"20.72400","1.72720","0.00353"
"20.79000","1.73270","0.00327"
"20.85600","1.73814","0.00385"
"20.92200","1.74364","0.00319"
"20.98800","1.74908","0.00346"
"21.05400","1.75464","0.00347"
"21.12000","1.76020","0.00365"
"21.18600","1.76570","0.00375"
"21.25200","1.77121","0.00341"
"21.31800","1.77671","0.00334"
"21.38400","1.78221","0.00368"
"21.45000","1.78771","0.00376"
"21.51600","1.79315","0.00387"
"21.58200","1.79865","0.00357"
"21.64800","1.80421","0.00355"
"21.71400","1.80971","0.00346"
"21.78000","1.81521","0.00344"
"21.84600","1.82071","0.00378"
"21.91200","1.82615","0.00396"
"21.97800","1.83165","0.00359"
"22.04400","1.83715","0.00368"
"22.11000","1.84265","0.00355"
"22.17600","1.84809","0.00365"
"22.24200","1.85371","0.00380"
"22.30800","1.85916","0.00364"
"22.37400","1.86466","0.00364"
"22.44000","1.87016","0.00373"
"22.50600","1.87566","0.00362"
"22.57200","1.88110","0.00378"
"22.63800","1.88660","0.00370"
"22.70400","1.89216","0.00390"
"22.77000","1.89766","0.00401"
"22.83600","1.90316","0.00388"
"22.90200","1.90866","0.00367"
"22.96800","1.91416","0.00383"
"23.03400","1.91966","0.00367"
"23.10000","1.92510","0.00348"
"23.16600","1.93060","0.00391"
"23.23200","1.93616","0.00358"
"23.29800","1.94172","0.00391"
"23.36400","1.94723","0.00393"
"23.43000","1.95267","0.00360"
"23.49600","1.95823","0.00363"
"23.56200","1.96367","0.00377"
"23.62800","1.96917","0.00391"
"23.69400","1.97467","0.00381"
"23.76000","1.98011","0.00412"
"23.82600","1.98573","0.00394"
"23.89200","1.99117","0.00384"
"23.95800","1.99673","0.00381"
"24.02400","2.00217","0.00377"
"24.09000","2.00773","0.00393"
"24.15600","2.01317","0.00384"
"24.22200","2.01867","0.00400"
"24.28800","2.02411","0.00382"
"24.35400","2.02968","0.00378"
"24.42000","2.03518","0.00406"
"24.48600","2.04068","0.00369"
"24.55200","2.04624","0.00403"
"24.61800","2.05168","0.00372"
"24.68400","2.05718","0.00385"
"24.75000","2.06262","0.00374"
"24.81600","2.06818","0.00409"
"24.88200","2.07368","0.00356"
"24.94800","2.07924","0.00391"
"25.01400","2.08468","0.00415"
"25.08000","2.09018","0.00361"
"25.14600","2.09568","0.00419"
"25.21200","2.10118","0.00410"
"25.27800","2.10668","0.00366"
"25.34400","2.11213","0.00393"
"25.41000","2.11769","0.00404"
"25.47600","2.12319","0.00406"
"25.54200","2.12869","0.00401"
"25.60800","2.13413","0.00421"
"25.67400","2.13969","0.00373"
"25.74000","2.14513","0.00405"
"25.80600","2.15069","0.00405"
"25.87200","2.15613","0.00389"
"25.93800","2.16163","0.00349"
"26.00400","2.16719","0.00406"
"26.07000","2.17269","0.00394"
"26.13600","2.17819","0.00418"
"26.20200","2.18363","0.00402"
"26.26800","2.18919","0.00411"
"26.33400","2.19463","0.00425"
"26.40000","2.20014","0.00389"
"26.46600","2.20570","0.00406"
"26.53200","2.21120","0.00399"
"26.59800","2.21664","0.00393"
"26.66400","2.22214","0.00398"
"26.73000","2.22764","0.00440"
"26.79600","2.23314","0.00396"
"26.86200","2.23864","0.00400"
"26.92800","2.24408","0.00395"
"26.99400","2.24964","0.00415"
"27.06000","2.25514","0.00403"
"27.12600","2.26070","0.00382"
"27.19200","2.26614","0.00400"
"27.25800","2.27164","0.00402"
"27.32400","2.27708","0.00391"
"27.39000","2.28264","0.00428"
"27.45600","2.28815","0.00397"
"27.52200","2.29365","0.00443"
"27.58800","2.29915","0.00402"
"27.65400","2.30471","0.00378"
"27.72000","2.31015","0.00423"
"27.78600","2.31565","0.00417"
"27.85200","2.32115","0.00416"
"27.91800","2.32659","0.00429"
"27.98400","2.33215","0.00414"
"28.05000","2.33765","0.00406"
"28.11600","2.34321","0.00419"
"28.18200","2.34865","0.00462"
"28.24800","2.35421","0.00427"
"28.31400","2.35971","0.00460"
"28.38000","2.36521","0.00431"
"28.44600","2.37066","0.00405"
"28.51200","2.37610","0.00416"
"28.57800","2.38166","0.00421"
"28.64400","2.38716","0.00456"
"28.71000","2.39272","0.00420"
"28.77600","2.39816","0.00413"
"28.84200","2.40366","0.00451"
"28.90800","2.40916","0.00424"
"28.97400","2.41466","0.00439"
"29.04000","2.42010","0.00429"
"29.10600","2.42566","0.00465"
"29.17200","2.43116","0.00398"
"29.23800","2.43672","0.00429"
"29.30400","2.44216","0.00431"
"29.37000","2.44772","0.00450"
"29.43600","2.45322","0.00443"
"29.50200","2.45867","0.00452"
"29.56800","2.46417","0.00449"
"29.63400","2.46961","0.00431"
"29.70000","2.47517","0.00442"
"29.76600","2.48067","0.00456"
"29.83200","2.48623","0.00469"
"29.89800","2.49173","0.00415"
"29.96400","2.49717","0.00451"
"30.03000","2.50267","0.00446"
"30.09600","2.50811","0.00427"
"30.16200","2.51361","0.00423"
"30.22800","2.51917","0.00445"
"30.29400","2.52473","0.00413"
"30.36000","2.53017","0.00457"
"30.42600","2.53567","0.00455"
"30.49200","2.54117","0.00439"
"30.55800","2.54668","0.00468"
"30.62400","2.55218","0.00456"
"30.69000","2.55762","0.00465"
"30.75600","2.56318","0.00453"
"30.82200","2.56862","0.00456"
"30.88800","2.57418","0.00446"
"30.95400","2.57968","0.00471"
"31.02000","2.58518","0.00459"
"31.08600","2.59062","0.00464"
"31.15200","2.59612","0.00437"
"31.21800","2.60162","0.00453"
"31.28400","2.60718","0.00469"
"31.35000","2.61262","0.00438"
"31.41600","2.61824","0.00473"
"31.48200","2.62368","0.00447"
"31.54800","2.62924","0.00430"
"31.61400","2.63469","0.00460"
"31.68000","2.64013","0.00488"
"31.74600","2.64563","0.00436"
"31.81200","2.65113","0.00463"
"31.87800","2.65669","0.00452"
"31.94400","2.66219","0.00430"
"32.01000","2.66769","0.00484"
"32.07600","2.67319","0.00479"
"32.14200","2.67869","0.00456"
"32.20800","2.68413","0.00474"
"32.27400","2.68969","0.00459"
"32.34000","2.69513","0.00501"
"32.40600","2.70069","0.00458"
"32.47200","2.70619","0.00503"
"32.53800","2.71169","0.00462"
"32.60400","2.71725","0.00461"
"32.67000","2.72270","0.00475"
"32.73600","2.72814","0.00502"
"32.80200","2.73364","0.00444"
"32.86800","2.73914","0.00464"
"32.93400","2.74464","0.00487"
"33.00000","2.75014","0.00445"
"33.06600","2.75564","0.00474"
"33.13200","2.76120","0.00468"
"33.19800","2.76664","0.00467"
"33.26400","2.77214","0.00477"
"33.33000","2.77758","0.00462"
"33.39600","2.78314","0.00474"
"33.46200","2.78864","0.00518"
"33.52800","2.79420","0.00474"
"33.59400","2.79970","0.00505"
"33.66000","2.80515","0.00502"
"33.72600","2.81071","0.00493"
"33.79200","2.81615","0.00490"
"33.85800","2.82165","0.00478"
"33.92400","2.82709","0.00524"
"33.99000","2.83265","0.00490"
"34.05600","2.83821","0.00479"
"34.12200","2.84371","0.00492"
"34.18800","2.84921","0.00498"
"34.25400","2.85465","0.00515"
"34.32000","2.86015","0.00475"
"34.38600","2.86565","0.00474"
"34.45200","2.87115","0.00505"
"34.51800","2.87665","0.00516"
"34.58400","2.88215","0.00478"
"34.65000","2.88771","0.00490"
"34.71600","2.89316","0.00490"
"34.78200","2.89872","0.00476"
"34.84800","2.90422","0.00472"
"34.91400","2.90966","0.00508"
"34.98000","2.91516","0.00519"
"35.04600","2.92066","0.00515"
"35.11200","2.92616","0.00469"
"35.17800","2.93172","0.00509"
"35.24400","2.93716","0.00503"
"35.31000","2.94266","0.00482"
"35.37600","2.94810","0.00452"
"35.44200","2.95366","0.00499"
"35.50800","2.95910","0.00484"
"35.57400","2.96466","0.00496"
"35.64000","2.97016","0.00490"
"35.70600","2.97572","0.00504"
"35.77200","2.98117","0.00480"
"35.83800","2.98673","0.00504"
"35.90400","2.99217","0.00473"
"35.97000","2.99767","0.00561"
"36.03600","3.00317","0.00497"
"36.10200","3.00861","0.00495"
"36.16800","3.01417","0.00538"
"36.23400","3.01967","0.00530"
"36.30000","3.02523","0.00501"
"36.36600","3.03067","0.00508"
"36.43200","3.03623","0.00470"
"36.49800","3.04161","0.00470"
"36.56400","3.04717","0.00519"
"36.63000","3.05261","0.00517"
"36.69600","3.05817","0.00508"
"36.76200","3.06374","0.00529"
"36.82800","3.06918","0.00483"
"36.89400","3.07468","0.00524"
"36.96000","3.08018","0.00505"
"37.02600","3.08568","0.00547"
"37.09200","3.09112","0.00474"
"37.15800","3.09668","0.00486"
"37.22400","3.10218","0.00530"
"37.29000","3.10774","0.00516"
"37.35600","3.11318","0.00518"
"37.42200","3.11868","0.00527"
"37.48800","3.12412","0.00519"
"37.55400","3.12962","0.00544"
"37.62000","3.13518","0.00513"
"37.68600","3.14062","0.00554"
"37.75200","3.14618","0.00537"
"37.81800","3.15169","0.00534"
"37.88400","3.15719","0.00522"
"37.95000","3.16275","0.00548"
"38.01600","3.16819","0.00500"
"38.08200","3.17369","0.00547"
"38.14800","3.17919","0.00534"
"38.21400","3.18463","0.00511"
"38.28000","3.19013","0.00552"
"38.34600","3.19569","0.00546"
"38.41200","3.20119","0.00556"
"38.47800","3.20669","0.00556"
"38.54400","3.21219","0.00533"
"38.61000","3.21769","0.00534"
"38.67600","3.22313","0.00547"
"38.74200","3.22863","0.00521"
"38.80800","3.23414","0.00561"
"38.87400","3.23970","0.00586"
"38.94000","3.24520","0.00585"
"39.00600","3.25070","0.00538"
"39.07200","3.25620","0.00565"
"39.13800","3.26170","0.00540"
"39.20400","3.26714","0.00546"
"39.27000","3.27264","0.00533"
"39.33600","3.27814","0.00555"
"39.40200","3.28364","0.00547"
"39.46800","3.28920","0.00550"
"39.53400","3.29470","0.00524"
"39.60000","3.30020","0.00558"
"39.66600","3.30564","0.00526"
"39.73200","3.31114","0.00565"
"39.79800","3.31664","0.00568"
"39.86400","3.32215","0.00554"
"39.93000","3.32759","0.00551"
"39.99600","3.33315","0.00563"
"40.06200","3.33865","0.00581"
"40.12800","3.34421","0.00537"
"40.19400","3.34971","0.00558"
"40.26000","3.35509","0.00550"
"40.32600","3.36065","0.00547"
"40.39200","3.36609","0.00502"
"40.45800","3.37171","0.00567"
"40.52400","3.37721","0.00563"
"40.59000","3.38271","0.00520"
"40.65600","3.38821","0.00524"
"40.72200","3.39371","0.00549"
"40.78800","3.39915","0.00513"
"40.85400","3.40465","0.00573"
"40.92000","3.41016","0.00553"
"40.98600","3.41566","0.00518"
"41.05200","3.42116","0.00565"
"41.11800","3.42666","0.00554"
"41.18400","3.43222","0.00550"
"41.25000","3.43766","0.00544"
"41.31600","3.44322","0.00532"
"41.38200","3.44860","0.00566"
"41.44800","3.45416","0.00541"
"41.51400","3.45960","0.00541"
"41.58000","3.46516","0.00572"
"41.64600","3.47066","0.00530"
"41.71200","3.47616","0.00567"
"41.77800","3.48166","0.00548"
"41.84400","3.48716","0.00551"
"41.91000","3.49261","0.00563"
"41.97600","3.49811","0.00535"
"42.04200","3.50361","0.00573"
"42.10800","3.50917","0.00554"
"42.17400","3.51467","0.00579"
"42.24000","3.52017","0.00564"
"42.30600","3.52567","0.00560"
"42.37200","3.53123","0.00546"
"42.43800","3.53667","0.00547"
"42.50400","3.54211","0.00556"
"42.57000","3.54767","0.00555"
"42.63600","3.55317","0.00522"
"42.70200","3.55867","0.00564"
"42.76800","3.56417","0.00559"
"42.83400","3.56967","0.00570"
"42.90000","3.57523","0.00522"
"42.96600","3.58068","0.00576"
"43.03200","3.58618","0.00564"
"43.09800","3.59162","0.00538"
"43.16400","3.59718","0.00551"
"43.23000","3.60268","0.00547"
"43.29600","3.60818","0.00590"
"43.36200","3.61374","0.00584"
"43.42800","3.61918","0.00603"
"43.49400","3.62468","0.00562"
"43.56000","3.63012","0.00607"
"43.62600","3.63568","0.00539"
"43.69200","3.64112","0.00551"
"43.75800","3.64674","0.00597"
"43.82400","3.65218","0.00573"
"43.89000","3.65768","0.00588"
"43.95600","3.66313","0.00587"
"44.02200","3.66863","0.00543"
"44.08800","3.67413","0.00581"
"44.15400","3.67963","0.00570"
"44.22000","3.68519","0.00582"
"44.28600","3.69063","0.00603"
"44.35200","3.69619","0.00579"
"44.41800","3.70169","0.00601"
"44.48400","3.70719","0.00586"
"44.55000","3.71263","0.00573"
"44.61600","3.71819","0.00599"
"44.68200","3.72363","0.00619"
"44.74800","3.72919","0.00573"
"44.81400","3.73469","0.00561"
"44.88000","3.74019","0.00563"
"44.94600","3.74569","0.00588"
"45.01200","3.75120","0.00600"
"45.07800","3.75670","0.00599"
"45.14400","3.76214","0.00610"
"45.21000","3.76764","0.00580"
"45.27600","3.77314","0.00591"
"45.34200","3.77870","0.00602"
"45.40800","3.78420","0.00601"
"45.47400","3.78970","0.00576"
"45.54000","3.79520","0.00562"
"45.60600","3.80070","0.00562"
"45.67200","3.80620","0.00590"
"45.73800","3.81164","0.00576"
"45.80400","3.81714","0.00600"
"45.87000","3.82264","0.00561"
"45.93600","3.82820","0.00615"
"46.00200","3.83371","0.00594"
"46.06800","3.83915","0.00612"
"46.13400","3.84471","0.00595"
"46.20000","3.85015","0.00596"
"46.26600","3.85565","0.00595"
"46.33200","3.86115","0.00605"
"46.39800","3.86671","0.00570"
"46.46400","3.87221","0.00600"
"46.53000","3.87765","0.00615"
"46.59600","3.88321","0.00558"
"46.66200","3.88871","0.00576"
"46.72800","3.89415","0.00566"
"46.79400","3.89965","0.00585"
"46.86000","3.90509","0.00584"
"46.92600","3.91071","0.00580"
"46.99200","3.91621","0.00578"
"47.05800","3.92172","0.00580"
"47.12400","3.92722","0.00632"
"47.19000","3.93272","0.00605"
"47.25600","3.93816","0.00579"
"47.32200","3.94366","0.00594"
"47.38800","3.94916","0.00568"
"47.45400","3.95466","0.00587"
"47.52000","3.96022","0.00606"
"47.58600","3.96566","0.00585"
"47.65200","3.97116","0.00602"
"47.71800","3.97666","0.00603"
"47.78400","3.98216","0.00604"
"47.85000","3.98766","0.00582"
"47.91600","3.99316","0.00610"
"47.98200","3.99860","0.00609"
"48.04800","4.00416","0.00614"
"48.11400","4.00967","0.00634"
"48.18000","4.01523","0.00579"
"48.24600","4.02067","0.00580"
"48.31200","4.02617","0.00615"
"48.37800","4.03161","0.00603"
"48.44400","4.03711","0.00580"
"48.51000","4.04267","0.00601"
"48.57600","4.04817","0.00624"
"48.64200","4.05373","0.00586"
"48.70800","4.05917","0.00619"
"48.77400","4.06473","0.00631"
"48.84000","4.07017","0.00606"
"48.90600","4.07567","0.00608"
"48.97200","4.08111","0.00603"
"49.03800","4.08667","0.00596"
"49.10400","4.09211","0.00600"
"49.17000","4.09768","0.00598"
"49.23600","4.10318","0.00598"
"49.30200","4.10868","0.00615"
"49.36800","4.11418","0.00624"
"49.43400","4.11962","0.00604"
"49.50000","4.12512","0.00602"
"49.56600","4.13062","0.00625"
"49.63200","4.13612","0.00559"
"49.69800","4.14168","0.00598"
"49.76400","4.14718","0.00590"
"49.83000","4.15268","0.00602"
"49.89600","4.15812","0.00552"
"49.96200","4.16362","0.00610"
"50.02800","4.16912","0.00583"
"50.09400","4.17462","0.00583"
"50.16000","4.18018","0.00558"
"50.22600","4.18569","0.00568"
"50.29200","4.19113","0.00575"
"50.35800","4.19675","0.00609"
"50.42400","4.20219","0.00632"
"50.49000","4.20769","0.00627"
"50.55600","4.21313","0.00589"
"50.62200","4.21863","0.00583"
"50.68800","4.22413","0.00600"
"50.75400","4.22969","0.00622"
"50.82000","4.23519","0.00591"
"50.88600","4.24069","0.00600"
"50.95200","4.24619","0.00629"
"51.01800","4.25163","0.00586"
"51.08400","4.25713","0.00610"
"51.15000","4.26264","0.00612"
"51.21600","4.26814","0.00597"
"51.28200","4.27364","0.00599"
"51.34800","4.27920","0.00608"
"51.41400","4.28470","0.00618"
"51.48000","4.29020","0.00587"
"51.54600","4.29570","0.00618"
"51.61200","4.30114","0.00601"
"51.67800","4.30664","0.00595"
"51.74400","4.31214","0.00598"
"51.81000","4.31770","0.00616"
"51.87600","4.32314","0.00604"
"51.94200","4.32876","0.00574"
"52.00800","4.33420","0.00647"
"52.07400","4.33970","0.00619"
"52.14000","4.34514","0.00594"
"52.20600","4.35065","0.00655"
"52.27200","4.35615","0.00584"
"52.33800","4.36171","0.00633"
"52.40400","4.36715","0.00597"
"52.47000","4.37265","0.00585"
"52.53600","4.37815","0.00620"
"52.60200","4.38365","0.00634"
"52.66800","4.38915","0.00618"
"52.73400","4.39459","0.00640"
"52.80000","4.40021","0.00597"
"52.86600","4.40565","0.00596"
"52.93200","4.41121","0.00591"
"52.99800","4.41665","0.00566"
"53.06400","4.42221","0.00600"
"53.13000","4.42765","0.00637"
"53.19600","4.43315","0.00599"
"53.26200","4.43866","0.00604"
"53.32800","4.44416","0.00633"
"53.39400","4.44966","0.00627"
"53.46000","4.45522","0.00610"
"53.52600","4.46072","0.00660"
"53.59200","4.46616","0.00612"
"53.65800","4.47172","0.00608"
"53.72400","4.47722","0.00599"
"53.79000","4.48266","0.00590"
"53.85600","4.48816","0.00597"
"53.92200","4.49372","0.00568"
"53.98800","4.49922","0.00647"
"54.05400","4.50466","0.00588"
"54.12000","4.51022","0.00606"
"54.18600","4.51566","0.00606"
"54.25200","4.52116","0.00567"
"54.31800","4.52661","0.00632"
"54.38400","4.53217","0.00592"
"54.45000","4.53767","0.00623"
"54.51600","4.54323","0.00590"
"54.58200","4.54861","0.00582"
"54.64800","4.55417","0.00603"
"54.71400","4.55961","0.00632"
"54.78000","4.56517","0.00590"
"54.84600","4.57061","0.00589"
"54.91200","4.57611","0.00592"
"54.97800","4.58167","0.00603"
"55.04400","4.58717","0.00591"
"55.11000","4.59267","0.00606"
"55.17600","4.59817","0.00636"
"55.24200","4.60367","0.00581"
"55.30800","4.60918","0.00593"
"55.37400","4.61462","0.00569"
"55.44000","4.62012","0.00632"
"55.50600","4.62568","0.00601"
"55.57200","4.63118","0.00624"
"55.63800","4.63668","0.00616"
"55.70400","4.64218","0.00577"
"55.77000","4.64768","0.00571"
"55.83600","4.65318","0.00598"
"55.90200","4.65862","0.00584"
"55.96800","4.66412","0.00556"
"56.03400","4.66962","0.00599"
"56.10000","4.67518","0.00603"
"56.16600","4.68068","0.00594"
"56.23200","4.68618","0.00575"
"56.29800","4.69168","0.00582"
"56.36400","4.69719","0.00569"
"56.43000","4.70263","0.00580"
"56.49600","4.70813","0.00613"
"56.56200","4.71363","0.00584"
"56.62800","4.71913","0.00567"
"56.69400","4.72475","0.00589"
"56.76000","4.73019","0.00577"
"56.82600","4.73569","0.00593"
"56.89200","4.74113","0.00587"
"56.95800","4.74669","0.00605"
"57.02400","4.75213","0.00592"
"57.09000","4.75769","0.00574"
"57.15600","4.76313","0.00590"
"57.22200","4.76869","0.00589"
"57.28800","4.77419","0.00549"
"57.35400","4.77970","0.00578"
"57.42000","4.78520","0.00590"
"57.48600","4.79064","0.00576"
"57.55200","4.79614","0.00614"
"57.61800","4.80164","0.00563"
"57.68400","4.80720","0.00581"
"57.75000","4.81270","0.00560"
"57.81600","4.81820","0.00536"
"57.88200","4.82370","0.00585"
"57.94800","4.82920","0.00573"
"58.01400","4.83464","0.00559"
"58.08000","4.84014","0.00561"
"58.14600","4.84564","0.00566"
"58.21200","4.85114","0.00576"
"58.27800","4.85670","0.00560"
"58.34400","4.86214","0.00572"
"58.41000","4.86770","0.00581"
"58.47600","4.87315","0.00541"
"58.54200","4.87871","0.00552"
"58.60800","4.88415","0.00587"
"58.67400","4.88959","0.00570"
"58.74000","4.89515","0.00573"
"58.80600","4.90065","0.00580"
"58.87200","4.90615","0.00546"
"58.93800","4.91165","0.00573"
"59.00400","4.91721","0.00542"
"59.07000","4.92265","0.00554"
"59.13600","4.92809","0.00599"
"59.20200","4.93359","0.00570"
"59.26800","4.93915","0.00607"
"59.33400","4.94465","0.00552"
"59.40000","4.95021","0.00552"
"59.46600","4.95572","0.00589"
"59.53200","4.96122","0.00554"
"59.59800","4.96666","0.00585"
"59.66400","4.97222","0.00552"
"59.73000","4.97766","0.00586"
"59.79600","4.98316","0.00582"
"59.86200","4.98866","0.00590"
"59.92800","4.99416","0.00618"
"59.99400","4.99972","0.00598"
"60.06000","5.00516","0.00558"
"60.12600","5.01072","0.00592"
"60.19200","5.01616","0.00545"
"60.25800","5.02166","0.00584"
"60.32400","5.02710","0.00606"
"60.39000","5.03266","0.00600"
"60.45600","5.03816","0.00583"
"60.52200","5.04367","0.00576"
"60.58800","5.04917","0.00551"
"60.65400","5.05467","0.00552"
"60.72000","5.06017","0.00543"
"60.78600","5.06561","0.00582"
"60.85200","5.07117","0.00573"
"60.91800","5.07661","0.00574"
"60.98400","5.08223","0.00580"
"61.05000","5.08767","0.00598"
"61.11600","5.09323","0.00589"
"61.18200","5.09867","0.00561"
"61.24800","5.10417","0.00609"
"61.31400","5.10967","0.00553"
"61.38000","5.11511","0.00589"
"61.44600","5.12061","0.00598"
"61.51200","5.12618","0.00571"
"61.57800","5.13168","0.00580"
"61.64400","5.13718","0.00589"
"61.71000","5.14268","0.00575"
"61.77600","5.14812","0.00571"
"61.84200","5.15368","0.00564"
"61.90800","5.15912","0.00546"
"61.97400","5.16468","0.00584"
"62.04000","5.17018","0.00603"
"62.10600","5.17568","0.00562"
"62.17200","5.18118","0.00592"
"62.23800","5.18668","0.00596"
"62.30400","5.19212","0.00580"
"62.37000","5.19762","0.00593"
"62.43600","5.20312","0.00593"
"62.50200","5.20868","0.00555"
"62.56800","5.21419","0.00580"
"62.63400","5.21969","0.00594"
"62.70000","5.22519","0.00584"
"62.76600","5.23069","0.00588"
"62.83200","5.23619","0.00603"
"62.89800","5.24169","0.00546"
"62.96400","5.24713","0.00581"
"63.03000","5.25269","0.00592"
"63.09600","5.25819","0.00570"
"63.16200","5.26369","0.00625"
"63.22800","5.26919","0.00553"
"63.29400","5.27469","0.00567"
"63.36000","5.28013","0.00617"
"63.42600","5.28563","0.00585"
"63.49200","5.29113","0.00595"
"63.55800","5.29670","0.00585"
"63.62400","5.30214","0.00593"
"63.69000","5.30770","0.00594"
"63.75600","5.31314","0.00564"
"63.82200","5.31870","0.00554"
"63.88800","5.32414","0.00601"
"63.95400","5.32964","0.00580"
"64.02000","5.33514","0.00561"
"64.08600","5.34064","0.00601"
"64.15200","5.34620","0.00575"
"64.21800","5.35170","0.00602"
"64.28400","5.35720","0.00597"
"64.35000","5.36264","0.00612"
"64.41600","5.36820","0.00569"
"64.48200","5.37364","0.00593"
"64.54800","5.37915","0.00561"
"64.61400","5.38459","0.00575"
"64.68000","5.39015","0.00575"
"64.74600","5.39571","0.00603"
"64.81200","5.40121","0.00530"
"64.87800","5.40671","0.00593"
"64.94400","5.41215","0.00572"
"65.01000","5.41765","0.00558"
"65.07600","5.42315","0.00562"
"65.14200","5.42865","0.00554"
"65.20800","5.43409","0.00592"
"65.27400","5.43971","0.00599"
"65.34000","5.44515","0.00599"
"65.40600","5.45071","0.00558"
"65.47200","5.45615","0.00598"
"65.53800","5.46165","0.00569"
"65.60400","5.46710","0.00602"
"65.67000","5.47266","0.00544"
"65.73600","5.47816","0.00574"
"65.80200","5.48366","0.00544"
"65.86800","5.48922","0.00586"
"65.93400","5.49466","0.00561"
"66.00000","5.50022","0.00566"
"66.06600","5.50560","0.00602"
"66.13200","5.51116","0.00553"
"66.19800","5.51660","0.00572"
"66.26400","5.52216","0.00607"
"66.33000","5.52772","0.00584"
"66.39600","5.53316","0.00593"
"66.46200","5.53866","0.00548"
"66.52800","5.54416","0.00586"
"66.59400","5.54966","0.00573"
"66.66000","5.55516","0.00602"
"66.72600","5.56061","0.00603"
"66.79200","5.56617","0.00561"
"66.85800","5.57167","0.00503"
"66.92400","5.57723","0.00490"
"66.99000","5.58267","0.00562"
"67.05600","5.58823","0.00543"
"67.12200","5.59367","0.00529"
"67.18800","5.59917","0.00553"
"67.25400","5.60467","0.00556"
"67.32000","5.61017","0.00520"
"67.38600","5.61561","0.00526"
"67.45200","5.62117","0.00556"
"67.51800","5.62661","0.00546"
"67.58400","5.63223","0.00557"
"67.65000","5.63762","0.00544"
"67.71600","5.64318","0.00545"
"67.78200","5.64862","0.00504"
"67.84800","5.65418","0.00505"
"67.91400","5.65968","0.00541"
"67.98000","5.66524","0.00563"
"68.04600","5.67068","0.00537"
"68.11200","5.67618","0.00592"
"68.17800","5.68168","0.00543"
"68.24400","5.68718","0.00554"
"68.31000","5.69268","0.00523"
"68.37600","5.69812","0.00563"
"68.44200","5.70368","0.00522"
"68.50800","5.70918","0.00559"
"68.57400","5.71474","0.00559"
"68.64000","5.72018","0.00609"
"68.70600","5.72569","0.00564"
"68.77200","5.73118","0.00519"
"68.83800","5.73669","0.00544"
"68.90400","5.74219","0.00549"
"68.97000","5.74763","0.00536"
"69.03600","5.75319","0.00543"
"69.10200","5.75863","0.00566"
"69.16800","5.76419","0.00584"
"69.23400","5.76963","0.00585"
"69.30000","5.77519","0.00540"
"69.36600","5.78063","0.00556"
"69.43200","5.78613","0.00558"
"69.49800","5.79163","0.00579"
"69.56400","5.79719","0.00562"
"69.63000","5.80269","0.00550"
"69.69600","5.80819","0.00530"
"69.76200","5.81363","0.00546"
"69.82800","5.81914","0.00568"
"69.89400","5.82464","0.00538"
"69.96000","5.83014","0.00587"
"70.02600","5.83564","0.00591"
"70.09200","5.84114","0.00545"
"70.15800","5.84670","0.00587"
"70.22400","5.85220","0.00526"
"70.29000","5.85764","0.00547"
"70.35600","5.86314","0.00554"
"70.42200","5.86864","0.00559"
"70.48800","5.87414","0.00591"
"70.55400","5.87964","0.00556"
"70.62000","5.88514","0.00569"
"70.68600","5.89070","0.00612"
"70.75200","5.89614","0.00592"
"70.81800","5.90170","0.00542"
"70.88400","5.90715","0.00571"
"70.95000","5.91265","0.00595"
"71.01600","5.91809","0.00590"
"71.08200","5.92365","0.00541"
"71.14800","5.92921","0.00585"
"71.21400","5.93471","0.00589"
"71.28000","5.94021","0.00613"
"71.34600","5.94571","0.00557"
"71.41200","5.95115","0.00589"
"71.47800","5.95665","0.00551"
"71.54400","5.96209","0.00573"
"71.61000","5.96765","0.00575"
"71.67600","5.97315","0.00539"
"71.74200","5.97871","0.00556"
"71.80800","5.98416","0.00476"
"71.87400","5.98966","0.00553"
"71.94000","5.99516","0.00523"
"72.00600","6.00066","0.00549"
"72.07200","6.00610","0.00561"
"72.13800","6.01160","0.00529"
"72.20400","6.01716","0.00565"
"72.27000","6.02266","0.00530"
"72.33600","6.02816","0.00557"
"72.40200","6.03366","0.00516"
"72.46800","6.03922","0.00525"
"72.53400","6.04466","0.00555"
"72.60000","6.05016","0.00543"
"72.66600","6.05560","0.00550"
"72.73200","6.06116","0.00522"
"72.79800","6.06666","0.00508"
"72.86400","6.07223","0.00508"
"72.93000","6.07773","0.00564"
"72.99600","6.08317","0.00539"
"73.06200","6.08867","0.00553"
"73.12800","6.09417","0.00571"
"73.19400","6.09961","0.00531"
"73.26000","6.10511","0.00566"
"73.32600","6.11067","0.00526"
"73.39200","6.11617","0.00537"
"73.45800","6.12173","0.00511"
"73.52400","6.12717","0.00574"
"73.59000","6.13273","0.00533"
"73.65600","6.13817","0.00561"
"73.72200","6.14367","0.00532"
"73.78800","6.14917","0.00545"
"73.85400","6.15468","0.00549"
"73.92000","6.16024","0.00564"
"73.98600","6.16574","0.00535"
"74.05200","6.17118","0.00560"
"74.11800","6.17668","0.00544"
"74.18400","6.18218","0.00548"
"74.25000","6.18762","0.00547"
"74.31600","6.19318","0.00564"
"74.38200","6.19868","0.00505"
"74.44800","6.20418","0.00543"
"74.51400","6.20968","0.00563"
"74.58000","6.21518","0.00563"
"74.64600","6.22068","0.00538"
"74.71200","6.22612","0.00558"
"74.77800","6.23162","0.00558"
"74.84400","6.23712","0.00526"
"74.91000","6.24262","0.00569"
"74.97600","6.24813","0.00567"
"75.04200","6.25369","0.00557"
"75.10800","6.25919","0.00570"
"75.17400","6.26469","0.00582"
"75.24000","6.27013","0.00528"
"75.30600","6.27569","0.00533"
"75.37200","6.28113","0.00544"
"75.43800","6.28663","0.00522"
"75.50400","6.29219","0.00517"
"75.57000","6.29763","0.00565"
"75.63600","6.30319","0.00538"
"75.70200","6.30869","0.00525"
"75.76800","6.31419","0.00521"
"75.83400","6.31963","0.00528"
"75.90000","6.32519","0.00531"
"75.96600","6.33064","0.00559"
"76.03200","6.33620","0.00554"
"76.09800","6.34164","0.00574"
"76.16400","6.34720","0.00567"
"76.23000","6.35264","0.00532"
"76.29600","6.35820","0.00574"
"76.36200","6.36364","0.00530"
"76.42800","6.36908","0.00558"
"76.49400","6.37470","0.00550"
"76.56000","6.38020","0.00559"
"76.62600","6.38570","0.00553"
"76.69200","6.39114","0.00523"
"76.75800","6.39670","0.00560"
"76.82400","6.40214","0.00558"
"76.89000","6.40764","0.00533"
"76.95600","6.41315","0.00557"
"77.02200","6.41865","0.00524"
"77.08800","6.42409","0.00543"
"77.15400","6.42971","0.00537"
"77.22000","6.43521","0.00536"
"77.28600","6.44065","0.00557"
"77.35200","6.44621","0.00528"
"77.41800","6.45165","0.00515"
"77.48400","6.45715","0.00557"
"77.55000","6.46265","0.00548"
"77.61600","6.46821","0.00521"
"77.68200","6.47365","0.00506"
"77.74800","6.47915","0.00538"
"77.81400","6.48465","0.00554"
"77.88000","6.49015","0.00566"
"77.94600","6.49565","0.00544"
"78.01200","6.50116","0.00553"
"78.07800","6.50666","0.00547"
"78.14400","6.51216","0.00557"
"78.21000","6.51766","0.00546"
"78.27600","6.52316","0.00578"
"78.34200","6.52866","0.00526"
"78.40800","6.53416","0.00548"
"78.47400","6.53966","0.00564"
"78.54000","6.54516","0.00598"
"78.60600","6.55066","0.00519"
"78.67200","6.55616","0.00581"
"78.73800","6.56166","0.00563"
"78.80400","6.56716","0.00541"
"78.87000","6.57266","0.00565"
"78.93600","6.57816","0.00582"
"79.00200","6.58360","0.00533"
"79.06800","6.58917","0.00548"
"79.13400","6.59461","0.00554"
"79.20000","6.60017","0.00568"
"79.26600","6.60567","0.00526"
"79.33200","6.61117","0.00543"
"79.39800","6.61667","0.00560"
"79.46400","6.62223","0.00561"
"79.53000","6.62767","0.00507"
"79.59600","6.63317","0.00559"
"79.66200","6.63867","0.00573"
"79.72800","6.64417","0.00515"
"79.79400","6.64967","0.00556"
"79.86000","6.65517","0.00534"
"79.92600","6.66067","0.00549"
"79.99200","6.66617","0.00582"
"80.05800","6.67167","0.00558"
"80.12400","6.67712","0.00578"
"80.19000","6.68262","0.00565"
"80.25600","6.68812","0.00552"
"80.32200","6.69368","0.00561"
"80.38800","6.69918","0.00561"
"80.45400","6.70468","0.00568"
"80.52000","6.71018","0.00548"
"80.58600","6.71562","0.00565"
"80.65200","6.72112","0.00564"
"80.71800","6.72662","0.00548"
"80.78400","6.73218","0.00571"
"80.85000","6.73762","0.00538"
"80.91600","6.74324","0.00566"
"80.98200","6.74868","0.00537"
"81.04800","6.75424","0.00583"
"81.11400","6.75963","0.00579"
"81.18000","6.76513","0.00556"
"81.24600","6.77063","0.00558"
"81.31200","6.77613","0.00585"
"81.37800","6.78169","0.00557"
"81.44400","6.78719","0.00574"
"81.51000","6.79269","0.00572"
"81.57600","6.79819","0.00537"
"81.64200","6.80369","0.00561"
"81.70800","6.80913","0.00597"
"81.77400","6.81463","0.00579"
"81.84000","6.82013","0.00545"
"81.90600","6.82569","0.00549"
"81.97200","6.83119","0.00579"
"82.03800","6.83669","0.00557"
"82.10400","6.84219","0.00571"
"82.17000","6.84764","0.00550"
"82.23600","6.85320","0.00598"
"82.30200","6.85864","0.00566"
"82.36800","6.86420","0.00578"
"82.43400","6.86970","0.00579"
"82.50000","6.87520","0.00559"
"82.56600","6.88070","0.00578"
"82.63200","6.88626","0.00526"
"82.69800","6.89170","0.00545"
"82.76400","6.89720","0.00589"
"82.83000","6.90264","0.00589"
"82.89600","6.90814","0.00585"
"82.96200","6.91364","0.00586"
"83.02800","6.91914","0.00498"
"83.09400","6.92470","0.00569"
"83.16000","6.93020","0.00588"
"83.22600","6.93571","0.00575"
"83.29200","6.94115","0.00556"
"83.35800","6.94665","0.00549"
"83.42400","6.95209","0.00579"
"83.49000","6.95765","0.00560"
"83.55600","6.96315","0.00612"
"83.62200","6.96871","0.00576"
"83.68800","6.97415","0.00610"
"83.75400","6.97971","0.00556"
"83.82000","6.98521","0.00603"
"83.88600","6.99065","0.00579"
"83.95200","6.99615","0.00545"
"84.01800","7.00165","0.00580"
"84.08400","7.00721","0.00563"
"84.15000","7.01265","0.00555"
"84.21600","7.01822","0.00553"
"84.28200","7.02372","0.00578"
"84.34800","7.02916","0.00620"
"84.41400","7.03466","0.00584"
"84.48000","7.04016","0.00550"
"84.54600","7.04566","0.00559"
"84.61200","7.05116","0.00586"
"84.67800","7.05666","0.00558"
"84.74400","7.06210","0.00607"
"84.81000","7.06772","0.00586"
"84.87600","7.07316","0.00568"
"84.94200","7.07866","0.00571"
"85.00800","7.08410","0.00593"
"85.07400","7.08966","0.00603"
"85.14000","7.09516","0.00582"
"85.20600","7.10072","0.00582"
"85.27200","7.10617","0.00555"
"85.33800","7.11167","0.00583"
"85.40400","7.11723","0.00575"
"85.47000","7.12267","0.00464"
"85.53600","7.12811","0.00478"
"85.60200","7.13361","0.00455"
"85.66800","7.13917","0.00471"
"85.73400","7.14467","0.00468"
"85.80000","7.15017","0.00455"
"85.86600","7.15567","0.00509"
"85.93200","7.16117","0.00459"
"85.99800","7.16667","0.00460"
"86.06400","7.17211","0.00483"
"86.13000","7.17761","0.00492"
"86.19600","7.18317","0.00470"
"86.26200","7.18867","0.00493"
"86.32800","7.19418","0.00484"
"86.39400","7.19968","0.00505"
"86.46000","7.20518","0.00495"
"86.52600","7.21068","0.00475"
"86.59200","7.21612","0.00482"
"86.65800","7.22168","0.00484"
"86.72400","7.22712","0.00531"
"86.79000","7.23268","0.00483"
"86.85600","7.23818","0.00477"
"86.92200","7.24368","0.00492"
"86.98800","7.24918","0.00476"
"87.05400","7.25462","0.00511"
"87.12000","7.26012","0.00450"
"87.18600","7.26562","0.00484"
"87.25200","7.27118","0.00503"
"87.31800","7.27668","0.00471"
"87.38400","7.28219","0.00508"
"87.45000","7.28769","0.00494"
"87.51600","7.29313","0.00505"
"87.58200","7.29863","0.00503"
"87.64800","7.30413","0.00501"
"87.71400","7.30963","0.00485"
"87.78000","7.31513","0.00488"
"87.84600","7.32063","0.00497"
"87.91200","7.32613","0.00507"
"87.97800","7.33163","0.00466"
"88.04400","7.33719","0.00514"
"88.11000","7.34269","0.00501"
"88.17600","7.34813","0.00528"
"88.24200","7.35363","0.00530"
"88.30800","7.35914","0.00522"
"88.37400","7.36470","0.00490"
"88.44000","7.37020","0.00506"
"88.50600","7.37570","0.00483"
"88.57200","7.38120","0.00487"
"88.63800","7.38670","0.00476"
"88.70400","7.39220","0.00516"
"88.77000","7.39764","0.00534"
"88.83600","7.40320","0.00552"
"88.90200","7.40870","0.00504"
"88.96800","7.41426","0.00543"
"89.03400","7.41970","0.00517"
"89.10000","7.42526","0.00490"
"89.16600","7.43064","0.00516"
"89.23200","7.43614","0.00531"
"89.29800","7.44158","0.00515"
"89.36400","7.44714","0.00529"
"89.43000","7.45265","0.00537"
"89.49600","7.45821","0.00522"
"89.56200","7.46371","0.00516"
"89.62800","7.46921","0.00508"
"89.69400","7.47471","0.00512"
"89.76000","7.48015","0.00508"
"89.82600","7.48565","0.00519"
"89.89200","7.49115","0.00513"
"89.95800","7.49665","0.00522"
"90.02400","7.50221","0.00538"
"90.09000","7.50771","0.00509"
"90.15600","7.51315","0.00489"
"90.22200","7.51865","0.00521"
"90.28800","7.52421","0.00525"
"90.35400","7.52965","0.00547"
"90.42000","7.53510","0.00517"
"90.48600","7.54066","0.00551"
"90.55200","7.54622","0.00547"
"90.61800","7.55166","0.00551"
"90.68400","7.55722","0.00509"
"90.75000","7.56266","0.00517"
"90.81600","7.56822","0.00551"
"90.88200","7.57366","0.00510"
"90.94800","7.57916","0.00530"
"91.01400","7.58460","0.00495"
"91.08000","7.59010","0.00495"
"91.14600","7.59566","0.00528"
"91.21200","7.60116","0.00518"
"91.27800","7.60666","0.00536"
"91.34400","7.61216","0.00496"
"91.41000","7.61760","0.00524"
"91.47600","7.62311","0.00487"
"91.54200","7.62867","0.00487"
"91.60800","7.63417","0.00512"
"91.67400","7.63967","0.00516"
"91.74000","7.64517","0.00566"
"91.80600","7.65073","0.00547"
"91.87200","7.65617","0.00556"
"91.93800","7.66161","0.00528"
"92.00400","7.66717","0.00526"
"92.07000","7.67261","0.00514"
"92.13600","7.67817","0.00548"
"92.20200","7.68367","0.00527"
"92.26800","7.68923","0.00545"
"92.33400","7.69467","0.00535"
"92.40000","7.70023","0.00549"
"92.46600","7.70562","0.00533"
"92.53200","7.71112","0.00558"
"92.59800","7.71662","0.00549"
"92.66400","7.72212","0.00524"
"92.73000","7.72768","0.00538"
"92.79600","7.73318","0.00505"
"92.86200","7.73874","0.00555"
"92.92800","7.74412","0.00525"
"92.99400","7.74968","0.00554"
"93.06000","7.75512","0.00497"
"93.12600","7.76068","0.00518"
"93.19200","7.76612","0.00535"
"93.25800","7.77174","0.00551"
"93.32400","7.77712","0.00531"
"93.39000","7.78268","0.00545"
"93.45600","7.78819","0.00552"
"93.51400","7.79297","0.00540"