File: Force_trajectories/161217/Specimen_RawData_4.csv
End date,"12/17/2016"
Specimen label,"6CT_43_run2"
Maximum Load,"0.34031",N

Time,Extension,Load
(s),(mm),(N)
"0.00000","0.00000","0.00033"
"0.24000","0.01853","-0.00018"
"0.48000","0.04030","-0.00004"
"0.72000","0.06027","0.00011"
"0.96000","0.08024","-0.00002"
"1.20000","0.10027","-0.00001"
"1.44000","0.12030","0.00009"
"1.68000","0.14021","0.00010"
"1.92000","0.16024","-0.00012"
"2.16000","0.18015","0.00008"
"2.40000","0.20024","-0.00015"
"2.64000","0.22020","-0.00007"
"2.88000","0.24023","-0.00004"
"3.12000","0.26020","0.00019"
"3.36000","0.28023","-0.00008"
"3.60000","0.30020","-0.00006"
"3.84000","0.32023","-0.00018"
"4.08000","0.34026","-0.00026"
"4.32000","0.36017","-0.00001"
"4.56000","0.38020","-0.00001"
"4.80000","0.40017","-0.00017"
"5.04000","0.42020","0.00036"
"5.28000","0.44023","-0.00016"
"5.52000","0.46020","0.00019"
"5.76000","0.48023","0.00021"
"6.00000","0.50020","-0.00023"
"6.24000","0.52029","-0.00013"
"6.48000","0.54014","-0.00014"
"6.72000","0.56023","0.00002"
"6.96000","0.58020","0.00012"
"7.20000","0.60023","-0.00003"
"7.44000","0.62020","0.00014"
"7.68000","0.64023","0.00012"
"7.92000","0.66020","0.00031"
"8.16000","0.68017","-0.00007"
"8.40000","0.70020","0.00036"
"8.64000","0.72016","0.00010"
"8.88000","0.74019","0.00013"
"9.12000","0.76022","0.00020"
"9.36000","0.78025","-0.00025"
"9.60000","0.80022","0.00008"
"9.84000","0.82025","0.00002"
"10.08000","0.84022","0.00010"
"10.32000","0.86019","-0.00019"
"10.56000","0.88022","0.00016"
"10.80000","0.90013","0.00019"
"11.04000","0.92022","0.00016"
"11.28000","0.94025","0.00008"
"11.52000","0.96022","0.00005"
"11.76000","0.98019","-0.00009"
"12.00000","1.00028","0.00010"
"12.24000","1.02025","-0.00005"
"12.48000","1.04022","0.00002"
"12.72000","1.06025","0.00009"
"12.96000","1.08016","0.00040"
"13.20000","1.10025","0.00007"
"13.44000","1.12022","-0.00008"
"13.68000","1.14025","-0.00031"
"13.92000","1.16022","-0.00009"
"14.16000","1.18019","0.00033"
"14.40000","1.20022","0.00001"
"14.64000","1.22024","-0.00003"
"14.88000","1.24027","-0.00003"
"15.12000","1.26018","0.00033"
"15.36000","1.28015","0.00016"
"15.60000","1.30018","-0.00010"
"15.84000","1.32027","0.00003"
"16.08000","1.34018","-0.00011"
"16.32000","1.36027","0.00032"
"16.56000","1.38024","0.00000"
"16.80000","1.40021","0.00018"
"17.04000","1.42024","0.00019"
"17.28000","1.44015","0.00017"
"17.52000","1.46018","0.00030"
"17.76000","1.48021","0.00022"
"18.00000","1.50024","-0.00007"
"18.24000","1.52021","0.00019"
"18.48000","1.54024","-0.00010"
"18.72000","1.56021","-0.00008"
"18.96000","1.58024","0.00017"
"19.20000","1.60021","-0.00006"
"19.44000","1.62024","-0.00016"
"19.68000","1.64021","0.00009"
"19.92000","1.66018","0.00006"
"20.16000","1.68027","0.00009"
"20.40000","1.70024","-0.00007"
"20.64000","1.72026","-0.00008"
"20.88000","1.74023","0.00011"
"21.12000","1.76014","0.00015"
"21.36000","1.78023","0.00017"
"21.60000","1.80020","0.00017"
"21.84000","1.82029","0.00022"
"22.08000","1.84020","-0.00003"
"22.32000","1.86023","-0.00026"
"22.56000","1.88020","-0.00008"
"22.80000","1.90023","-0.00008"
"23.04000","1.92026","-0.00002"
"23.28000","1.94023","0.00003"
"23.52000","1.96026","0.00015"
"23.76000","1.98017","-0.00009"
"24.00000","2.00020","0.00030"
"24.24000","2.02017","-0.00014"
"24.48000","2.04026","-0.00027"
"24.72000","2.06017","-0.00016"
"24.96000","2.08020","-0.00008"
"25.20000","2.10023","-0.00002"
"25.44000","2.12020","0.00005"
"25.68000","2.14023","-0.00018"
"25.92000","2.16020","-0.00022"
"26.16000","2.18023","-0.00008"
"26.40000","2.20020","0.00001"
"26.64000","2.22028","0.00001"
"26.88000","2.24019","0.00007"
"27.12000","2.26022","0.00009"
"27.36000","2.28019","-0.00018"
"27.60000","2.30022","0.00003"
"27.84000","2.32019","0.00002"
"28.08000","2.34022","0.00021"
"28.32000","2.36019","0.00007"
"28.56000","2.38010","-0.00017"
"28.80000","2.40025","-0.00018"
"29.04000","2.42022","-0.00007"
"29.28000","2.44025","-0.00017"
"29.52000","2.46022","0.00005"
"29.76000","2.48019","-0.00012"
"30.00000","2.50022","-0.00011"
"30.24000","2.52019","-0.00009"
"30.48000","2.54022","-0.00014"
"30.72000","2.56013","-0.00021"
"30.96000","2.58028","-0.00021"
"31.20000","2.60019","0.00007"
"31.44000","2.62022","0.00006"
"31.68000","2.64025","-0.00006"
"31.92000","2.66022","-0.00018"
"32.16000","2.68019","-0.00002"
"32.40000","2.70016","-0.00036"
"32.64000","2.72024","-0.00010"
"32.88000","2.74015","0.00011"
"33.12000","2.76024","-0.00011"
"33.36000","2.78021","-0.00008"
"33.60000","2.80030","-0.00004"
"33.84000","2.82021","-0.00046"
"34.08000","2.84024","-0.00008"
"34.32000","2.86015","-0.00027"
"34.56000","2.88018","-0.00025"
"34.80000","2.90027","-0.00028"
"35.04000","2.92018","0.00007"
"35.28000","2.94027","-0.00009"
"35.52000","2.96018","0.00005"
"35.76000","2.98021","-0.00027"
"36.00000","3.00018","-0.00005"
"36.24000","3.02027","-0.00027"
"36.48000","3.04018","0.00022"
"36.72000","3.06021","-0.00008"
"36.96000","3.08024","-0.00012"
"37.20000","3.10015","0.00005"
"37.44000","3.12024","-0.00048"
"37.68000","3.14021","0.00013"
"37.92000","3.16024","0.00003"
"38.16000","3.18021","-0.00033"
"38.40000","3.20023","-0.00017"
"38.64000","3.22020","0.00005"
"38.88000","3.24023","-0.00010"
"39.12000","3.26020","-0.00019"
"39.36000","3.28017","-0.00009"
"39.60000","3.30026","0.00017"
"39.84000","3.32023","0.00007"
"40.08000","3.34020","0.00017"
"40.32000","3.36023","0.00015"
"40.56000","3.38026","-0.00028"
"40.80000","3.40023","-0.00005"
"41.04000","3.42020","-0.00013"
"41.28000","3.44023","-0.00021"
"41.52000","3.46020","-0.00002"
"41.76000","3.48017","0.00004"
"42.00000","3.50020","-0.00009"
"42.24000","3.52023","-0.00025"
"42.48000","3.54020","0.00009"
"42.72000","3.56023","0.00014"
"42.96000","3.58014","-0.00012"
"43.20000","3.60023","0.00002"
"43.44000","3.62020","0.00024"
"43.68000","3.64023","-0.00028"
"43.92000","3.66020","-0.00019"
"44.16000","3.68022","0.00001"
"44.40000","3.70025","-0.00043"
"44.64000","3.72016","-0.00003"
"44.88000","3.74025","-0.00015"
"45.12000","3.76016","-0.00010"
"45.36000","3.78025","-0.00005"
"45.60000","3.80028","-0.00047"
"45.84000","3.82025","-0.00007"
"46.08000","3.84022","-0.00018"
"46.32000","3.86019","-0.00022"
"46.56000","3.88022","-0.00029"
"46.80000","3.90019","-0.00031"
"47.04000","3.92022","0.00002"
"47.28000","3.94019","-0.00012"
"47.52000","3.96022","-0.00007"
"47.76000","3.98025","-0.00013"
"48.00000","4.00022","-0.00031"
"48.24000","4.02025","0.00010"
"48.48000","4.04016","-0.00003"
"48.72000","4.06025","-0.00004"
"48.96000","4.08016","-0.00033"
"49.20000","4.10019","-0.00028"
"49.44000","4.12022","0.00001"
"49.68000","4.14019","-0.00033"
"49.92000","4.16022","0.00003"
"50.16000","4.18018","-0.00005"
"50.40000","4.20021","0.00016"
"50.64000","4.22018","0.00001"
"50.88000","4.24021","0.00000"
"51.12000","4.26018","-0.00021"
"51.36000","4.28021","-0.00008"
"51.60000","4.30024","-0.00012"
"51.84000","4.32021","0.00006"
"52.08000","4.34018","0.00004"
"52.32000","4.36027","-0.00013"
"52.56000","4.38024","-0.00014"
"52.80000","4.40015","0.00002"
"53.04000","4.42024","-0.00028"
"53.28000","4.44015","-0.00017"
"53.52000","4.46018","0.00000"
"53.76000","4.48021","0.00010"
"54.00000","4.50024","-0.00001"
"54.24000","4.52021","0.00009"
"54.48000","4.54018","0.00001"
"54.72000","4.56021","-0.00019"
"54.96000","4.58018","-0.00002"
"55.20000","4.60027","-0.00021"
"55.44000","4.62018","-0.00052"
"55.68000","4.64021","-0.00003"
"55.92000","4.66018","-0.00010"
"56.16000","4.68021","-0.00031"
"56.40000","4.70017","-0.00016"
"56.64000","4.72026","0.00016"
"56.88000","4.74023","0.00027"
"57.12000","4.76020","-0.00011"
"57.36000","4.78029","-0.00005"
"57.60000","4.80020","0.00010"
"57.84000","4.82017","0.00000"
"58.08000","4.84014","0.00001"
"58.32000","4.86023","-0.00002"
"58.56000","4.88026","0.00004"
"58.80000","4.90023","-0.00015"
"59.04000","4.92026","-0.00021"
"59.28000","4.94017","-0.00039"
"59.52000","4.96026","0.00000"
"59.76000","4.98017","-0.00003"
"60.00000","5.00020","-0.00018"
"60.24000","5.02017","-0.00021"
"60.48000","5.04020","0.00001"
"60.72000","5.06017","0.00026"
"60.96000","5.08020","0.00014"
"61.20000","5.10029","0.00003"
"61.44000","5.12020","0.00016"
"61.68000","5.14029","0.00029"
"61.92000","5.16020","-0.00005"
"62.16000","5.18023","-0.00029"
"62.40000","5.20019","-0.00006"
"62.64000","5.22022","0.00020"
"62.88000","5.24019","-0.00007"
"63.12000","5.26022","0.00030"
"63.36000","5.28025","0.00017"
"63.60000","5.30022","0.00003"
"63.84000","5.32025","-0.00001"
"64.08000","5.34016","-0.00010"
"64.32000","5.36025","0.00014"
"64.56000","5.38016","0.00011"
"64.80000","5.40025","0.00000"
"65.04000","5.42016","0.00015"
"65.28000","5.44019","-0.00007"
"65.52000","5.46028","0.00005"
"65.76000","5.48019","0.00003"
"66.00000","5.50028","0.00011"
"66.24000","5.52019","0.00018"
"66.48000","5.54022","0.00026"
"66.72000","5.56013","-0.00002"
"66.96000","5.58028","-0.00003"
"67.20000","5.60019","0.00007"
"67.44000","5.62022","0.00021"
"67.68000","5.64025","0.00003"
"67.92000","5.66022","0.00015"
"68.16000","5.68024","0.00007"
"68.40000","5.70021","-0.00001"
"68.64000","5.72024","0.00013"
"68.88000","5.74015","0.00012"
"69.12000","5.76024","0.00006"
"69.36000","5.78021","0.00026"
"69.60000","5.80018","0.00002"
"69.84000","5.82021","0.00005"
"70.08000","5.84024","-0.00003"
"70.32000","5.86021","-0.00002"
"70.56000","5.88024","0.00003"
"70.80000","5.90021","0.00019"
"71.04000","5.92018","0.00012"
"71.28000","5.94021","-0.00001"
"71.52000","5.96018","0.00029"
"71.76000","5.98027","-0.00001"
"72.00000","6.00024","0.00031"
"72.24000","6.02021","0.00012"
"72.48000","6.04018","0.00012"
"72.72000","6.06015","0.00014"
"72.96000","6.08024","0.00014"
"73.20000","6.10015","0.00033"
"73.44000","6.12024","0.00005"
"73.68000","6.14021","0.00015"
"73.92000","6.16024","0.00043"
"74.16000","6.18020","-0.00009"
"74.40000","6.20023","0.00027"
"74.64000","6.22020","0.00025"
"74.88000","6.24017","-0.00003"
"75.12000","6.26026","0.00013"
"75.36000","6.28011","0.00002"
"75.60000","6.30020","0.00017"
"75.84000","6.32023","0.00010"
"76.08000","6.34020","0.00020"
"76.32000","6.36023","0.00025"
"76.56000","6.38026","0.00028"
"76.80000","6.40017","-0.00008"
"77.04000","6.42020","-0.00004"
"77.28000","6.44023","-0.00007"
"77.52000","6.46020","0.00043"
"77.76000","6.48023","0.00042"
"78.00000","6.50020","0.00019"
"78.24000","6.52023","0.00026"
"78.48000","6.54020","-0.00012"
"78.72000","6.56023","-0.00004"
"78.96000","6.58026","0.00018"
"79.20000","6.60023","0.00005"
"79.44000","6.62026","0.00056"
"79.68000","6.64017","0.00037"
"79.92000","6.66019","0.00037"
"80.16000","6.68022","0.00021"
"80.40000","6.70025","-0.00004"
"80.64000","6.72016","0.00030"
"80.88000","6.74025","0.00036"
"81.12000","6.76016","0.00038"
"81.36000","6.78019","0.00011"
"81.60000","6.80022","-0.00009"
"81.84000","6.82019","-0.00002"
"82.08000","6.84022","0.00027"
"82.32000","6.86019","0.00011"
"82.56000","6.88022","0.00005"
"82.80000","6.90025","0.00021"
"83.04000","6.92022","0.00049"
"83.28000","6.94019","0.00043"
"83.52000","6.96016","0.00036"
"83.76000","6.98025","0.00012"
"84.00000","7.00016","0.00036"
"84.24000","7.02025","0.00031"
"84.48000","7.04022","0.00028"
"84.72000","7.06025","0.00009"
"84.96000","7.08022","0.00035"
"85.20000","7.10025","0.00030"
"85.44000","7.12022","0.00060"
"85.68000","7.14019","0.00024"
"85.92000","7.16022","0.00030"
"86.16000","7.18018","0.00026"
"86.40000","7.20021","0.00034"
"86.64000","7.22018","-0.00001"
"86.88000","7.24021","0.00005"
"87.12000","7.26018","0.00040"
"87.36000","7.28021","0.00018"
"87.60000","7.30024","0.00033"
"87.84000","7.32021","0.00039"
"88.08000","7.34018","0.00039"
"88.32000","7.36021","0.00029"
"88.56000","7.38018","0.00038"
"88.80000","7.40015","0.00035"
"89.04000","7.42030","0.00008"
"89.28000","7.44015","0.00024"
"89.52000","7.46024","0.00022"
"89.76000","7.48021","0.00056"
"90.00000","7.50018","0.00021"
"90.24000","7.52021","0.00045"
"90.48000","7.54018","0.00041"
"90.72000","7.56027","0.00043"
"90.96000","7.58018","0.00030"
"91.20000","7.60027","0.00056"
"91.44000","7.62018","0.00021"
"91.68000","7.64021","0.00046"
"91.92000","7.66024","-0.00005"
"92.16000","7.68021","0.00060"
"92.40000","7.70023","0.00008"
"92.64000","7.72026","0.00030"
"92.88000","7.74023","0.00017"
"93.12000","7.76020","0.00061"
"93.36000","7.78023","0.00020"
"93.60000","7.80020","0.00037"
"93.84000","7.82023","0.00022"
"94.08000","7.84020","0.00006"
"94.32000","7.86023","0.00037"
"94.56000","7.88020","0.00021"
"94.80000","7.90017","0.00034"
"95.04000","7.92020","0.00018"
"95.28000","7.94017","0.00023"
"95.52000","7.96020","0.00033"
"95.76000","7.98017","0.00019"
"96.00000","8.00026","0.00009"
"96.24000","8.02023","0.00042"
"96.48000","8.04026","0.00036"
"96.72000","8.06017","0.00021"
"96.96000","8.08020","0.00034"
"97.20000","8.10023","0.00035"
"97.44000","8.12014","0.00054"
"97.68000","8.14023","0.00038"
"97.92000","8.16020","0.00024"
"98.16000","8.18028","0.00049"
"98.40000","8.20019","0.00043"
"98.64000","8.22022","0.00045"
"98.88000","8.24019","0.00033"
"99.12000","8.26016","0.00054"
"99.36000","8.28025","0.00015"
"99.60000","8.30016","0.00010"
"99.84000","8.32019","0.00041"
"100.08000","8.34022","0.00046"
"100.32000","8.36019","0.00035"
"100.56000","8.38016","0.00037"
"100.80000","8.40019","0.00049"
"101.04000","8.42016","0.00018"
"101.28000","8.44019","0.00050"
"101.52000","8.46028","0.00033"
"101.76000","8.48019","0.00016"
"102.00000","8.50022","0.00004"
"102.24000","8.52019","0.00047"
"102.48000","8.54022","0.00020"
"102.72000","8.56019","0.00017"
"102.96000","8.58022","0.00059"
"103.20000","8.60019","0.00005"
"103.44000","8.62022","0.00015"
"103.68000","8.64019","0.00019"
"103.92000","8.66016","0.00037"
"104.16000","8.68018","0.00054"
"104.40000","8.70015","0.00024"
"104.64000","8.72018","0.00015"
"104.88000","8.74021","0.00033"
"105.12000","8.76030","0.00042"
"105.36000","8.78021","0.00041"
"105.60000","8.80024","0.00008"
"105.84000","8.82027","0.00025"
"106.08000","8.84018","0.00025"
"106.32000","8.86021","0.00033"
"106.56000","8.88018","0.00040"
"106.80000","8.90027","0.00011"
"107.04000","8.92018","0.00020"
"107.28000","8.94021","0.00061"
"107.52000","8.96018","0.00036"
"107.76000","8.98021","0.00046"
"108.00000","9.00024","0.00028"
"108.24000","9.02015","0.00033"
"108.48000","9.04024","0.00036"
"108.72000","9.06015","0.00032"
"108.96000","9.08024","0.00032"
"109.20000","9.10015","0.00039"
"109.44000","9.12030","0.00032"
"109.68000","9.14021","0.00002"
"109.92000","9.16023","0.00046"
"110.16000","9.18026","0.00034"
"110.40000","9.20023","0.00054"
"110.64000","9.22020","0.00029"
"110.88000","9.24017","0.00044"
"111.12000","9.26026","0.00051"
"111.36000","9.28023","-0.00007"
"111.60000","9.30026","0.00045"
"111.84000","9.32023","0.00020"
"112.08000","9.34020","0.00035"
"112.32000","9.36023","0.00025"
"112.56000","9.38020","0.00055"
"112.80000","9.40023","0.00042"
"113.04000","9.42020","0.00028"
"113.28000","9.44023","0.00053"
"113.52000","9.46014","0.00032"
"113.76000","9.48029","0.00037"
"114.00000","9.50020","0.00073"
"114.24000","9.52023","0.00026"
"114.48000","9.54026","0.00042"
"114.72000","9.56023","0.00024"
"114.96000","9.58026","0.00030"
"115.20000","9.60017","0.00040"
"115.44000","9.62026","0.00043"
"115.68000","9.64023","0.00022"
"115.92000","9.66026","0.00025"
"116.16000","9.68022","0.00033"
"116.40000","9.70019","0.00045"
"116.64000","9.72022","0.00056"
"116.88000","9.74025","0.00047"
"117.12000","9.76022","0.00046"
"117.36000","9.78019","0.00015"
"117.60000","9.80022","0.00029"
"117.84000","9.82019","0.00078"
"118.08000","9.84022","0.00024"
"118.32000","9.86019","0.00032"
"118.56000","9.88022","0.00028"
"118.80000","9.90025","0.00051"
"119.04000","9.92022","0.00026"
"119.28000","9.94025","0.00013"
"119.52000","9.96016","0.00026"
"119.76000","9.98025","0.00039"
"120.00000","10.00016","0.00010"
"120.24000","10.02025","0.00064"
"120.48000","10.04022","0.00032"
"120.72000","10.06019","0.00059"
"120.96000","10.08016","0.00022"
"121.20000","10.10025","0.00044"
"121.44000","10.12022","0.00019"
"121.68000","10.14019","0.00032"
"121.92000","10.16022","0.00035"
"122.16000","10.18013","0.00039"
"122.40000","10.20021","0.00034"
"122.64000","10.22018","0.00042"
"122.88000","10.24021","0.00046"
"123.12000","10.26024","0.00049"
"123.36000","10.28027","0.00009"
"123.60000","10.30024","0.00044"
"123.84000","10.32015","0.00038"
"124.08000","10.34024","0.00056"
"124.32000","10.36021","0.00048"
"124.56000","10.38018","0.00061"
"124.80000","10.40015","0.00054"
"125.04000","10.42024","0.00063"
"125.28000","10.44021","0.00076"
"125.52000","10.46024","0.00045"
"125.76000","10.48027","0.00046"
"126.00000","10.50018","0.00059"
"126.24000","10.52027","0.00030"
"126.48000","10.54018","0.00049"
"126.72000","10.56021","0.00068"
"126.96000","10.58018","0.00094"
"127.20000","10.60027","0.00043"
"127.44000","10.62018","0.00092"
"127.68000","10.64020","0.00089"
"127.92000","10.66018","0.00079"
"128.16000","10.68020","0.00046"
"128.40000","10.70023","0.00096"
"128.64000","10.72020","0.00061"
"128.88000","10.74023","0.00066"
"129.12000","10.76020","0.00095"
"129.36000","10.78023","0.00080"
"129.60000","10.80014","0.00063"
"129.84000","10.82023","0.00090"
"130.08000","10.84026","0.00092"
"130.32000","10.86023","0.00117"
"130.56000","10.88026","0.00051"
"130.80000","10.90017","0.00065"
"131.04000","10.92020","0.00086"
"131.28000","10.94017","0.00093"
"131.52000","10.96026","0.00071"
"131.76000","10.98017","0.00057"
"132.00000","11.00026","0.00101"
"132.24000","11.02023","0.00082"
"132.48000","11.04020","0.00076"
"132.72000","11.06023","0.00093"
"132.96000","11.08020","0.00093"
"133.20000","11.10023","0.00080"
"133.44000","11.12014","0.00062"
"133.68000","11.14029","0.00086"
"133.92000","11.16019","0.00082"
"134.16000","11.18022","0.00056"
"134.40000","11.20019","0.00080"
"134.64000","11.22016","0.00097"
"134.88000","11.24025","0.00107"
"135.12000","11.26022","0.00106"
"135.36000","11.28019","0.00107"
"135.60000","11.30016","0.00106"
"135.84000","11.32025","0.00114"
"136.08000","11.34022","0.00106"
"136.32000","11.36025","0.00134"
"136.56000","11.38022","0.00098"
"136.80000","11.40019","0.00121"
"137.04000","11.42022","0.00093"
"137.28000","11.44025","0.00099"
"137.52000","11.46022","0.00099"
"137.76000","11.48019","0.00127"
"138.00000","11.50022","0.00103"
"138.24000","11.52013","0.00111"
"138.48000","11.54022","0.00102"
"138.72000","11.56019","0.00128"
"138.96000","11.58028","0.00125"
"139.20000","11.60019","0.00092"
"139.44000","11.62022","0.00111"
"139.68000","11.64025","0.00120"
"139.92000","11.66021","0.00131"
"140.16000","11.68024","0.00105"
"140.40000","11.70021","0.00122"
"140.64000","11.72024","0.00126"
"140.88000","11.74021","0.00120"
"141.12000","11.76024","0.00110"
"141.36000","11.78021","0.00094"
"141.60000","11.80024","0.00126"
"141.84000","11.82027","0.00162"
"142.08000","11.84012","0.00096"
"142.32000","11.86021","0.00103"
"142.56000","11.88018","0.00119"
"142.80000","11.90021","0.00117"
"143.04000","11.92018","0.00139"
"143.28000","11.94021","0.00106"
"143.52000","11.96024","0.00129"
"143.76000","11.98021","0.00132"
"144.00000","12.00024","0.00087"
"144.24000","12.02015","0.00106"
"144.48000","12.04018","0.00113"
"144.72000","12.06021","0.00116"
"144.96000","12.08024","0.00143"
"145.20000","12.10020","0.00080"
"145.44000","12.12024","0.00121"
"145.68000","12.14020","0.00092"
"145.92000","12.16018","0.00112"
"146.16000","12.18026","0.00147"
"146.40000","12.20017","0.00096"
"146.64000","12.22020","0.00114"
"146.88000","12.24023","0.00117"
"147.12000","12.26020","0.00091"
"147.36000","12.28023","0.00111"
"147.60000","12.30020","0.00080"
"147.84000","12.32023","0.00147"
"148.08000","12.34020","0.00091"
"148.32000","12.36023","0.00110"
"148.56000","12.38014","0.00101"
"148.80000","12.40017","0.00111"
"149.04000","12.42020","0.00138"
"149.28000","12.44023","0.00149"
"149.52000","12.46020","0.00142"
"149.76000","12.48023","0.00121"
"150.00000","12.50020","0.00137"
"150.24000","12.52017","0.00161"
"150.48000","12.54026","0.00118"
"150.72000","12.56017","0.00165"
"150.96000","12.58026","0.00143"
"151.20000","12.60017","0.00132"
"151.44000","12.62019","0.00104"
"151.68000","12.64023","0.00138"
"151.92000","12.66019","0.00136"
"152.16000","12.68022","0.00127"
"152.40000","12.70019","0.00149"
"152.64000","12.72022","0.00162"
"152.88000","12.74019","0.00151"
"153.12000","12.76016","0.00140"
"153.36000","12.78019","0.00180"
"153.60000","12.80022","0.00153"
"153.84000","12.82019","0.00152"
"154.08000","12.84022","0.00140"
"154.32000","12.86025","0.00145"
"154.56000","12.88022","0.00168"
"154.80000","12.90019","0.00152"
"155.04000","12.92016","0.00154"
"155.28000","12.94025","0.00178"
"155.52000","12.96022","0.00167"
"155.76000","12.98025","0.00165"
"156.00000","13.00016","0.00165"
"156.24000","13.02025","0.00169"
"156.48000","13.04022","0.00154"
"156.72000","13.06025","0.00169"
"156.96000","13.08022","0.00163"
"157.20000","13.10025","0.00180"
"157.44000","13.12022","0.00171"
"157.68000","13.14012","0.00189"
"157.92000","13.16027","0.00156"
"158.16000","13.18018","0.00165"
"158.40000","13.20027","0.00130"
"158.64000","13.22024","0.00171"
"158.88000","13.24021","0.00214"
"159.12000","13.26018","0.00186"
"159.36000","13.28021","0.00198"
"159.60000","13.30024","0.00185"
"159.84000","13.32015","0.00198"
"160.08000","13.34024","0.00147"
"160.32000","13.36021","0.00195"
"160.56000","13.38024","0.00170"
"160.80000","13.40027","0.00223"
"161.04000","13.42018","0.00191"
"161.28000","13.44021","0.00215"
"161.52000","13.46024","0.00209"
"161.76000","13.48021","0.00230"
"162.00000","13.50018","0.00219"
"162.24000","13.52027","0.00191"
"162.48000","13.54024","0.00222"
"162.72000","13.56027","0.00233"
"162.96000","13.58018","0.00205"
"163.20000","13.60021","0.00234"
"163.44000","13.62018","0.00241"
"163.68000","13.64021","0.00236"
"163.92000","13.66023","0.00218"
"164.16000","13.68020","0.00162"
"164.40000","13.70023","0.00280"
"164.64000","13.72014","0.00191"
"164.88000","13.74023","0.00179"
"165.12000","13.76020","0.00232"
"165.36000","13.78023","0.00168"
"165.60000","13.80020","0.00186"
"165.84000","13.82023","0.00220"
"166.08000","13.84026","0.00203"
"166.32000","13.86017","0.00197"
"166.56000","13.88026","0.00238"
"166.80000","13.90023","0.00178"
"167.04000","13.92026","0.00273"
"167.28000","13.94023","0.00206"
"167.52000","13.96020","0.00251"
"167.76000","13.98023","0.00272"
"168.00000","14.00020","0.00222"
"168.24000","14.02023","0.00273"
"168.48000","14.04014","0.00274"
"168.72000","14.06023","0.00226"
"168.96000","14.08020","0.00299"
"169.20000","14.10023","0.00252"
"169.44000","14.12020","0.00309"
"169.68000","14.14022","0.00303"
"169.92000","14.16020","0.00300"
"170.16000","14.18022","0.00328"
"170.40000","14.20019","0.00285"
"170.64000","14.22016","0.00324"
"170.88000","14.24019","0.00354"
"171.12000","14.26022","0.00355"
"171.36000","14.28019","0.00304"
"171.60000","14.30022","0.00323"
"171.84000","14.32025","0.00332"
"172.08000","14.34022","0.00390"
"172.32000","14.36019","0.00342"
"172.56000","14.38022","0.00388"
"172.80000","14.40019","0.00374"
"173.04000","14.42022","0.00400"
"173.28000","14.44019","0.00418"
"173.52000","14.46022","0.00400"
"173.76000","14.48019","0.00431"
"174.00000","14.50028","0.00433"
"174.24000","14.52019","0.00423"
"174.48000","14.54022","0.00431"
"174.72000","14.56025","0.00468"
"174.96000","14.58016","0.00447"
"175.20000","14.60031","0.00451"
"175.44000","14.62016","0.00498"
"175.68000","14.64025","0.00502"
"175.92000","14.66021","0.00493"
"176.16000","14.68018","0.00539"
"176.40000","14.70021","0.00546"
"176.64000","14.72018","0.00509"
"176.88000","14.74027","0.00545"
"177.12000","14.76018","0.00556"
"177.36000","14.78027","0.00612"
"177.60000","14.80018","0.00638"
"177.84000","14.82021","0.00645"
"178.08000","14.84018","0.00636"
"178.32000","14.86021","0.00677"
"178.56000","14.88018","0.00662"
"178.80000","14.90021","0.00698"
"179.04000","14.92024","0.00687"
"179.28000","14.94015","0.00729"
"179.52000","14.96024","0.00713"
"179.76000","14.98015","0.00730"
"180.00000","15.00024","0.00741"
"180.24000","15.02021","0.00784"
"180.48000","15.04024","0.00773"
"180.72000","15.06021","0.00800"
"180.96000","15.08018","0.00856"
"181.20000","15.10021","0.00858"
"181.44000","15.12024","0.00878"
"181.68000","15.14020","0.00921"
"181.92000","15.16018","0.00937"
"182.16000","15.18020","0.00964"
"182.40000","15.20017","0.00991"
"182.64000","15.22026","0.00952"
"182.88000","15.24017","0.00959"
"183.12000","15.26020","0.01032"
"183.36000","15.28023","0.01002"
"183.60000","15.30020","0.01163"
"183.84000","15.32029","0.01118"
"184.08000","15.34014","0.01090"
"184.32000","15.36029","0.01194"
"184.56000","15.38014","0.01376"
"184.80000","15.40023","0.01282"
"185.04000","15.42020","0.01038"
"185.28000","15.44017","0.01241"
"185.52000","15.46020","0.01332"
"185.76000","15.48023","0.01253"
"186.00000","15.50026","0.01360"
"186.24000","15.52023","0.01392"
"186.48000","15.54026","0.01412"
"186.72000","15.56017","0.01523"
"186.96000","15.58020","0.01508"
"187.20000","15.60017","0.01512"
"187.44000","15.62025","0.01611"
"187.68000","15.64022","0.01612"
"187.92000","15.66019","0.01718"
"188.16000","15.68016","0.01735"
"188.40000","15.70019","0.01742"
"188.64000","15.72022","0.01870"
"188.88000","15.74019","0.01893"
"189.12000","15.76022","0.01917"
"189.36000","15.78019","0.01982"
"189.60000","15.80022","0.01968"
"189.84000","15.82019","0.02130"
"190.08000","15.84022","0.02118"
"190.32000","15.86025","0.02155"
"190.56000","15.88016","0.02314"
"190.80000","15.90025","0.02343"
"191.04000","15.92016","0.02454"
"191.28000","15.94025","0.02383"
"191.52000","15.96016","0.02433"
"191.76000","15.98025","0.02580"
"192.00000","16.00022","0.02614"
"192.24000","16.02025","0.02685"
"192.48000","16.04021","0.02697"
"192.72000","16.06019","0.02757"
"192.96000","16.08022","0.02879"
"193.20000","16.10019","0.02922"
"193.44000","16.12021","0.03041"
"193.68000","16.14012","0.03071"
"193.92000","16.16021","0.03139"
"194.16000","16.18018","0.03168"
"194.40000","16.20015","0.03271"
"194.64000","16.22024","0.03339"
"194.88000","16.24021","0.03380"
"195.12000","16.26024","0.03501"
"195.36000","16.28015","0.03530"
"195.60000","16.30018","0.03516"
"195.84000","16.32021","0.03627"
"196.08000","16.34024","0.03696"
"196.32000","16.36021","0.03739"
"196.56000","16.38018","0.03794"
"196.80000","16.40021","0.03899"
"197.04000","16.42018","0.03922"
"197.28000","16.44027","0.03930"
"197.52000","16.46018","0.04018"
"197.76000","16.48021","0.04060"
"198.00000","16.50018","0.04118"
"198.24000","16.52027","0.04147"
"198.48000","16.54012","0.04206"
"198.72000","16.56021","0.04221"
"198.96000","16.58023","0.04218"
"199.20000","16.60020","0.04270"
"199.44000","16.62023","0.04316"
"199.68000","16.64021","0.04377"
"199.92000","16.66017","0.04408"
"200.16000","16.68014","0.04464"
"200.40000","16.70023","0.04528"
"200.64000","16.72020","0.04548"
"200.88000","16.74023","0.04621"
"201.12000","16.76026","0.04667"
"201.36000","16.78017","0.04786"
"201.60000","16.80020","0.04788"
"201.84000","16.82017","0.04863"
"202.08000","16.84020","0.04977"
"202.32000","16.86017","0.05063"
"202.56000","16.88020","0.05119"
"202.80000","16.90017","0.05182"
"203.04000","16.92020","0.05306"
"203.28000","16.94023","0.03274"
"203.52000","16.96020","0.03404"
"203.76000","16.98023","0.02994"
"204.00000","17.00020","0.03370"
"204.24000","17.02023","0.03517"
"204.48000","17.04020","0.03319"
"204.72000","17.06023","0.03731"
"204.96000","17.08019","0.03618"
"205.20000","17.10022","0.03655"
"205.44000","17.12025","0.03975"
"205.68000","17.14022","0.03727"
"205.92000","17.16019","0.04013"
"206.16000","17.18022","0.04009"
"206.40000","17.20019","0.04026"
"206.64000","17.22016","0.04215"
"206.88000","17.24025","0.04094"
"207.12000","17.26022","0.04295"
"207.36000","17.28019","0.04274"
"207.60000","17.30022","0.04315"
"207.84000","17.32025","0.04451"
"208.08000","17.34028","0.04405"
"208.32000","17.36019","0.04523"
"208.56000","17.38022","0.04510"
"208.80000","17.40013","0.04621"
"209.04000","17.42022","0.04738"
"209.28000","17.44019","0.04681"
"209.52000","17.46028","0.04904"
"209.76000","17.48025","0.04888"
"210.00000","17.50022","0.05055"
"210.24000","17.52019","0.05139"
"210.48000","17.54022","0.05188"
"210.72000","17.56025","0.05425"
"210.96000","17.58015","0.05370"
"211.20000","17.60018","0.05586"
"211.44000","17.62021","0.05569"
"211.68000","17.64024","0.05804"
"211.92000","17.66021","0.05854"
"212.16000","17.68018","0.05859"
"212.40000","17.70021","0.06123"
"212.64000","17.72018","0.06168"
"212.88000","17.74027","0.06311"
"213.12000","17.76012","0.06323"
"213.36000","17.78021","0.06544"
"213.60000","17.80024","0.06543"
"213.84000","17.82021","0.06695"
"214.08000","17.84024","0.06804"
"214.32000","17.86021","0.06849"
"214.56000","17.88018","0.06998"
"214.80000","17.90015","0.07062"
"215.04000","17.92024","0.07214"
"215.28000","17.94015","0.07243"
"215.52000","17.96024","0.07306"
"215.76000","17.98015","0.07444"
"216.00000","18.00024","0.07559"
"216.24000","18.02015","0.07661"
"216.48000","18.04024","0.07782"
"216.72000","18.06021","0.07880"
"216.96000","18.08018","0.07936"
"217.20000","18.10021","0.08008"
"217.44000","18.12012","0.08072"
"217.68000","18.14020","0.08194"
"217.92000","18.16023","0.08255"
"218.16000","18.18026","0.08322"
"218.40000","18.20017","0.08431"
"218.64000","18.22026","0.08471"
"218.88000","18.24017","0.08559"
"219.12000","18.26020","0.08629"
"219.36000","18.28023","0.08713"
"219.60000","18.30014","0.08747"
"219.84000","18.32029","0.08807"
"220.08000","18.34020","0.08862"
"220.32000","18.36023","0.08926"
"220.56000","18.38014","0.08964"
"220.80000","18.40023","0.09010"
"221.04000","18.42026","0.09045"
"221.28000","18.44023","0.09075"
"221.52000","18.46026","0.09139"
"221.76000","18.48017","0.09160"
"222.00000","18.50020","0.09211"
"222.24000","18.52017","0.09226"
"222.48000","18.54026","0.09278"
"222.72000","18.56017","0.09306"
"222.96000","18.58026","0.09337"
"223.20000","18.60023","0.09396"
"223.44000","18.62025","0.09406"
"223.68000","18.64022","0.09436"
"223.92000","18.66019","0.09553"
"224.16000","18.68022","0.09597"
"224.40000","18.70019","0.09653"
"224.64000","18.72028","0.09698"
"224.88000","18.74019","0.09820"
"225.12000","18.76028","0.09854"
"225.36000","18.78025","0.09970"
"225.60000","18.80022","0.10088"
"225.84000","18.82019","0.10196"
"226.08000","18.84022","0.10265"
"226.32000","18.86025","0.10477"
"226.56000","18.88016","0.10502"
"226.80000","18.90025","0.10692"
"227.04000","18.92016","0.10854"
"227.28000","18.94031","0.11056"
"227.52000","18.96022","0.11138"
"227.76000","18.98019","0.11323"
"228.00000","19.00022","0.11513"
"228.24000","19.02025","0.11640"
"228.48000","19.04028","0.11816"
"228.72000","19.06018","0.11920"
"228.96000","19.08022","0.12061"
"229.20000","19.10019","0.12293"
"229.44000","19.12021","0.12495"
"229.68000","19.14024","0.12641"
"229.92000","19.16021","0.12752"
"230.16000","19.18024","0.13022"
"230.40000","19.20021","0.13137"
"230.64000","19.22018","0.13435"
"230.88000","19.24015","0.13544"
"231.12000","19.26024","0.13744"
"231.36000","19.28021","0.13910"
"231.60000","19.30024","0.14068"
"231.84000","19.32021","0.14195"
"232.08000","19.34018","0.14396"
"232.32000","19.36021","0.14516"
"232.56000","19.38018","0.14632"
"232.80000","19.40021","0.14745"
"233.04000","19.42018","0.14820"
"233.28000","19.44021","0.14875"
"233.52000","19.46018","0.14937"
"233.76000","19.48021","0.15023"
"234.00000","19.50024","0.15060"
"234.24000","19.52027","0.15091"
"234.48000","19.54017","0.15180"
"234.72000","19.56021","0.15211"
"234.96000","19.58024","0.15245"
"235.20000","19.60020","0.15302"
"235.44000","19.62023","0.15374"
"235.68000","19.64020","0.15538"
"235.92000","19.66023","0.15543"
"236.16000","19.68020","0.15646"
"236.40000","19.70017","0.15722"
"236.64000","19.72020","0.15971"
"236.88000","19.74017","0.16012"
"237.12000","19.76026","0.16248"
"237.36000","19.78017","0.16245"
"237.60000","19.80026","0.16524"
"237.84000","19.82023","0.16572"
"238.08000","19.84020","0.16751"
"238.32000","19.86017","0.16890"
"238.56000","19.88026","0.16980"
"238.80000","19.90023","0.17214"
"239.04000","19.92020","0.17256"
"239.28000","19.94023","0.17533"
"239.52000","19.96013","0.17587"
"239.76000","19.98023","0.17814"
"240.00000","20.00020","0.17841"
"240.24000","20.02017","0.18043"
"240.48000","20.04020","0.18230"
"240.72000","20.06022","0.18363"
"240.96000","20.08019","0.18549"
"241.20000","20.10023","0.18666"
"241.44000","20.12025","0.18837"
"241.68000","20.14016","0.18944"
"241.92000","20.16019","0.19075"
"242.16000","20.18022","0.19164"
"242.40000","20.20019","0.19124"
"242.64000","20.22016","0.19382"
"242.88000","20.24025","0.19438"
"243.12000","20.26016","0.19604"
"243.36000","20.28025","0.19642"
"243.60000","20.30028","0.19746"
"243.84000","20.32019","0.19842"
"244.08000","20.34028","0.19906"
"244.32000","20.36013","0.19991"
"244.56000","20.38022","0.20086"
"244.80000","20.40019","0.20205"
"245.04000","20.42027","0.20242"
"245.28000","20.44019","0.20366"
"245.52000","20.46022","0.20448"
"245.76000","20.48025","0.20543"
"246.00000","20.50022","0.20730"
"246.24000","20.52024","0.20809"
"246.48000","20.54022","0.20943"
"246.72000","20.56025","0.21100"
"246.96000","20.58022","0.21285"
"247.20000","20.60024","0.21428"
"247.44000","20.62021","0.21563"
"247.68000","20.64018","0.21753"
"247.92000","20.66021","0.21843"
"248.16000","20.68024","0.21958"
"248.40000","20.70027","0.22129"
"248.64000","20.72018","0.22235"
"248.88000","20.74027","0.22391"
"249.12000","20.76018","0.22512"
"249.36000","20.78021","0.22686"
"249.60000","20.80018","0.22869"
"249.84000","20.82021","0.23007"
"250.08000","20.84018","0.23145"
"250.32000","20.86027","0.23194"
"250.56000","20.88024","0.23380"
"250.80000","20.90021","0.23542"
"251.04000","20.92024","0.23594"
"251.28000","20.94015","0.23753"
"251.52000","20.96024","0.23878"
"251.76000","20.98015","0.23992"
"252.00000","21.00024","0.24069"
"252.24000","21.02020","0.24195"
"252.48000","21.04024","0.24289"
"252.72000","21.06020","0.24361"
"252.96000","21.08017","0.24429"
"253.20000","21.10026","0.24551"
"253.44000","21.12017","0.24649"
"253.68000","21.14021","0.24704"
"253.92000","21.16017","0.24799"
"254.16000","21.18014","0.24916"
"254.40000","21.20017","0.25053"
"254.64000","21.22020","0.25262"
"254.88000","21.24023","0.25401"
"255.12000","21.26020","0.25614"
"255.36000","21.28023","0.25902"
"255.60000","21.30020","0.26097"
"255.84000","21.32023","0.26362"
"256.08000","21.34020","0.26526"
"256.32000","21.36023","0.26830"
"256.56000","21.38020","0.27002"
"256.80000","21.40029","0.27150"
"257.04000","21.42020","0.27455"
"257.28000","21.44017","0.27668"
"257.52000","21.46026","0.27822"
"257.76000","21.48017","0.28099"
"258.00000","21.50020","0.28310"
"258.24000","21.52017","0.28424"
"258.48000","21.54025","0.28611"
"258.72000","21.56017","0.28788"
"258.96000","21.58019","0.28995"
"259.20000","21.60022","0.29147"
"259.44000","21.62020","0.29341"
"259.68000","21.64022","0.29542"
"259.92000","21.66013","0.29617"
"260.16000","21.68022","0.29787"
"260.40000","21.70019","0.29911"
"260.64000","21.72028","0.30065"
"260.88000","21.74019","0.30155"
"261.12000","21.76022","0.30237"
"261.36000","21.78019","0.30315"
"261.60000","21.80016","0.30384"
"261.84000","21.82025","0.30425"
"262.08000","21.84022","0.30467"
"262.32000","21.86019","0.30493"
"262.56000","21.88016","0.30519"
"262.80000","21.90025","0.30545"
"263.04000","21.92016","0.30583"
"263.28000","21.94019","0.30587"
"263.52000","21.96028","0.30630"
"263.76000","21.98025","0.30682"
"264.00000","22.00028","0.30742"
"264.24000","22.02019","0.30824"
"264.48000","22.04022","0.30948"
"264.72000","22.06018","0.31084"
"264.96000","22.08027","0.31285"
"265.20000","22.10025","0.31460"
"265.44000","22.12021","0.31650"
"265.68000","22.14024","0.31913"
"265.92000","22.16015","0.32195"
"266.16000","22.18018","0.32416"
"266.40000","22.20021","0.32700"
"266.64000","22.22018","0.33015"
"266.88000","22.24015","0.33330"
"267.12000","22.26024","0.33670"
"267.36000","22.28015","0.33833"
"267.60000","22.30018","0.33948"
"267.84000","22.32027","0.17722"
"268.08000","22.34018","0.16957"
"268.32000","22.36021","0.16741"
"268.56000","22.38018","0.17062"
"268.80000","22.40021","0.17705"
"269.04000","22.42024","0.17688"
"269.28000","22.44027","0.17816"
"269.52000","22.46018","0.19331"
"269.76000","22.48021","0.18246"
"270.00000","22.50024","0.18824"
"270.24000","22.52021","0.18971"
"270.48000","22.54023","0.18614"
"270.72000","22.56021","0.18935"
"270.96000","22.58023","0.19413"
"271.20000","22.60015","0.19709"
"271.44000","22.62024","0.11678"
"271.68000","22.64020","0.11314"
"271.92000","22.66023","0.10635"
"272.16000","22.68020","0.11463"
"272.40000","22.70017","0.10366"
"272.64000","22.72026","0.11578"
"272.88000","22.74017","0.10988"
"273.12000","22.76020","0.11873"
"273.36000","22.78017","0.11667"
"273.60000","22.80026","0.11989"
"273.84000","22.82023","0.11709"
"274.08000","22.84026","0.11805"
"274.32000","22.86023","0.12376"
"274.56000","22.88020","0.11804"
"274.80000","22.90023","0.12921"
"275.04000","22.92020","0.12334"
"275.28000","22.94023","0.13251"
"275.52000","22.96014","0.12544"
"275.76000","22.98023","0.13632"
"276.00000","23.00020","0.12592"
"276.24000","23.02023","0.13521"
"276.48000","23.04020","0.13129"
"276.72000","23.06022","0.13862"
"276.96000","23.08026","0.13502"
"277.20000","23.10023","0.14280"
"277.44000","23.12025","0.13566"
"277.68000","23.14010","0.14467"
"277.92000","23.16019","0.13749"
"278.16000","23.18022","0.14575"
"278.40000","23.20025","0.14047"
"278.64000","23.22022","0.14674"
"278.88000","23.24025","0.14394"
"279.12000","23.26016","0.14805"
"279.36000","23.28019","0.14574"
"279.60000","23.30028","0.14844"
"279.84000","23.32013","0.14687"
"280.08000","23.34022","0.14936"
"280.32000","23.36019","0.14777"
"280.56000","23.38028","0.15038"
"280.80000","23.40025","0.14987"
"281.04000","23.42022","0.15081"
"281.28000","23.44019","0.15058"
"281.52000","23.46022","0.15083"
"281.76000","23.48025","0.06527"
"282.00000","23.50016","0.06829"
"282.24000","23.52024","0.06560"
"282.48000","23.54021","0.06853"
"282.72000","23.56025","0.06461"
"282.96000","23.58021","0.06706"
"283.20000","23.60024","0.06449"
"283.44000","23.62021","0.06471"
"283.68000","23.64018","0.06817"
"283.92000","23.66021","0.06444"
"284.16000","23.68018","0.07120"
"284.40000","23.70021","0.06788"
"284.64000","23.72018","0.07029"
"284.88000","23.74021","0.07005"
"285.12000","23.76018","0.01439"
"285.36000","23.78027","0.01858"
"285.60000","23.80024","0.00999"
"285.84000","23.82021","0.00787"
"286.08000","23.84024","0.01328"
"286.32000","23.86015","0.00810"
"286.56000","23.88024","0.00902"
"286.80000","23.90021","0.01377"
"287.04000","23.92024","0.00916"
"287.28000","23.94020","0.01241"
"287.52000","23.96024","0.01320"
"287.76000","23.98021","0.01006"
"288.00000","24.00018","0.01319"
"288.24000","24.02021","0.01207"
"288.48000","24.04017","0.01011"
"288.72000","24.06021","0.01371"
"288.96000","24.08017","0.01133"
"289.20000","24.10026","0.01281"
"289.44000","24.12017","0.01391"
"289.68000","24.14020","0.01181"
"289.92000","24.16023","0.01367"
"290.16000","24.18014","0.01302"
"290.40000","24.20023","0.01219"
"290.64000","24.22020","0.01446"
"290.88000","24.24017","0.01341"
"291.12000","24.26020","0.01324"
"291.36000","24.28023","0.01499"
"291.60000","24.30020","0.01345"
"291.84000","24.32023","0.01451"
"292.08000","24.34020","0.01490"
"292.32000","24.36017","0.01429"
"292.56000","24.38020","0.01555"
"292.80000","24.40023","0.01523"
"293.04000","24.42026","0.01494"
"293.28000","24.44017","0.01581"
"293.52000","24.46020","0.01481"
"293.76000","24.48017","0.01590"
"294.00000","24.50026","0.01639"
"294.24000","24.52022","0.01603"
"294.48000","24.54020","0.01660"
"294.72000","24.56022","0.01771"
"294.96000","24.58026","0.01650"
"295.20000","24.60023","0.01762"
"295.44000","24.62013","0.01745"
"295.68000","24.64022","0.01759"
"295.92000","24.66019","0.01842"
"296.16000","24.68022","0.01762"
"296.40000","24.70025","0.01840"
"296.64000","24.72016","0.01862"
"296.88000","24.74019","0.01889"
"297.12000","24.76022","0.01886"
"297.36000","24.78025","0.01878"
"297.60000","24.80022","0.01907"
"297.84000","24.82025","0.01956"
"298.08000","24.84022","0.01986"
"298.32000","24.86025","0.02003"
"298.56000","24.88028","0.02039"
"298.80000","24.90019","0.02016"
"299.04000","24.92022","0.02080"
"299.28000","24.94025","0.02114"
"299.52000","24.96022","0.02093"
"299.76000","24.98019","0.02127"
"300.00000","25.00022","0.02125"
"300.24000","25.02019","0.02177"
"300.48000","25.04022","0.02264"
"300.72000","25.06024","0.02244"
"300.96000","25.08022","0.02255"
"301.20000","25.10019","0.02305"
"301.44000","25.12021","0.02259"
"301.68000","25.14024","0.02286"
"301.92000","25.16015","0.02358"
"302.16000","25.18024","0.02377"
"302.40000","25.20015","0.02442"
"302.64000","25.22018","0.02389"
"302.88000","25.24021","0.02464"
"303.12000","25.26024","0.02483"
"303.36000","25.28021","0.02491"
"303.60000","25.30018","0.02584"
"303.84000","25.32021","0.02553"
"304.08000","25.34018","0.02644"
"304.32000","25.36027","0.02638"
"304.56000","25.38018","0.02622"
"304.80000","25.40021","0.02668"
"305.04000","25.42018","0.02739"
"305.28000","25.44015","0.02717"
"305.52000","25.46018","0.02699"
"305.76000","25.48021","0.02851"
"306.00000","25.50030","0.02774"
"306.24000","25.52015","0.02889"
"306.48000","25.54024","0.02974"
"306.72000","25.56020","0.02908"
"306.96000","25.58017","0.02925"
"307.20000","25.60020","0.02935"
"307.44000","25.62024","0.03012"
"307.68000","25.64021","0.02990"
"307.92000","25.66023","0.03057"
"308.16000","25.68026","0.03049"
"308.40000","25.70017","0.03090"
"308.64000","25.72020","0.03162"
"308.88000","25.74017","0.03153"
"309.12000","25.76026","0.03167"
"309.36000","25.78017","0.03249"
"309.60000","25.80032","0.03250"
"309.84000","25.82017","0.03327"
"310.08000","25.84014","0.03325"
"310.32000","25.86023","0.03291"
"310.56000","25.88020","0.03362"
"310.80000","25.90023","0.03385"
"311.04000","25.92020","0.03393"
"311.28000","25.94017","0.03435"
"311.52000","25.96020","0.03451"
"311.76000","25.98029","0.03498"
"312.00000","26.00014","0.03541"
"312.24000","26.02023","0.03556"
"312.48000","26.04020","0.03584"
"312.72000","26.06017","0.03622"
"312.96000","26.08025","0.03679"
"313.20000","26.10017","0.03707"
"313.44000","26.12025","0.03697"
"313.68000","26.14017","0.03653"
"313.92000","26.16025","0.03731"
"314.16000","26.18022","0.03731"
"314.40000","26.20019","0.03783"
"314.64000","26.22028","0.03812"
"314.88000","26.24019","0.03879"
"315.12000","26.26022","0.03894"
"315.36000","26.28019","0.03899"
"315.60000","26.30022","0.03976"
"315.84000","26.32013","0.03966"
"316.08000","26.34022","0.03973"
"316.32000","26.36019","0.04026"
"316.56000","26.38022","0.04028"
"316.80000","26.40025","0.04007"
"317.04000","26.42022","0.04106"
"317.28000","26.44025","0.04076"
"317.52000","26.46021","0.04124"
"317.76000","26.48025","0.04142"
"318.00000","26.50016","0.04125"
"318.24000","26.52025","0.04172"
"318.48000","26.54022","0.04174"
"318.72000","26.56018","0.04199"
"318.96000","26.58022","0.04211"
"319.20000","26.60024","0.04262"
"319.44000","26.62021","0.04218"
"319.68000","26.64018","0.04306"
"319.92000","26.66027","0.04327"
"320.16000","26.68018","0.04326"
"320.40000","26.70027","0.04369"
"320.64000","26.72018","0.04357"
"320.88000","26.74021","0.04377"
"321.12000","26.76024","0.04445"
"321.36000","26.78021","0.04430"
"321.60000","26.80018","0.04481"
"321.84000","26.82015","0.04496"
"322.08000","26.84030","0.04501"
"322.32000","26.86021","0.04558"
"322.56000","26.88024","0.04554"
"322.80000","26.90015","0.04635"
"323.04000","26.92024","0.04625"
"323.28000","26.94021","0.04609"
"323.52000","26.96024","0.04752"
"323.76000","26.98021","0.04726"
"324.00000","27.00018","0.04776"
"324.24000","27.02027","0.04793"
"324.48000","27.04018","0.04822"
"324.72000","27.06020","0.04980"
"324.96000","27.08023","0.04943"
"325.20000","27.10020","0.04956"
"325.44000","27.12023","0.05092"
"325.68000","27.14020","0.05004"
"325.92000","27.16017","0.05120"
"326.16000","27.18015","0.05122"
"326.40000","27.20023","0.05132"
"326.64000","27.22014","0.05274"
"326.88000","27.24017","0.05254"
"327.12000","27.26020","0.05338"
"327.36000","27.28023","0.05376"
"327.60000","27.30014","0.05394"
"327.84000","27.32023","0.05558"
"328.08000","27.34020","0.05498"
"328.32000","27.36017","0.05637"
"328.56000","27.38026","0.05739"
"328.80000","27.40017","0.05704"
"329.04000","27.42020","0.05858"
"329.28000","27.44017","0.05799"
"329.52000","27.46026","0.05922"
"329.76000","27.48023","0.06019"
"330.00000","27.50019","0.06015"
"330.24000","27.52023","0.06204"
"330.48000","27.54014","0.06204"
"330.72000","27.56023","0.06274"
"330.96000","27.58020","0.06353"
"331.20000","27.60023","0.06347"
"331.44000","27.62020","0.06508"
"331.68000","27.64022","0.06520"
"331.92000","27.66019","0.06534"
"332.16000","27.68016","0.06667"
"332.40000","27.70025","0.06679"
"332.64000","27.72016","0.06812"
"332.88000","27.74025","0.06779"
"333.12000","27.76016","0.06897"
"333.36000","27.78019","0.06975"
"333.60000","27.80016","0.07030"
"333.84000","27.82025","0.07083"
"334.08000","27.84022","0.07087"
"334.32000","27.86019","0.07138"
"334.56000","27.88028","0.07220"
"334.80000","27.90019","0.07279"
"335.04000","27.92022","0.07346"
"335.28000","27.94025","0.07437"
"335.52000","27.96022","0.07393"
"335.76000","27.98019","0.07483"
"336.00000","28.00028","0.07587"
"336.24000","28.02018","0.07624"
"336.48000","28.04021","0.07648"
"336.72000","28.06025","0.07697"
"336.96000","28.08021","0.07792"
"337.20000","28.10024","0.07852"
"337.44000","28.12015","0.07846"
"337.68000","28.14025","0.07919"
"337.92000","28.16015","0.07978"
"338.16000","28.18030","0.08047"
"338.40000","28.20015","0.08043"
"338.64000","28.22024","0.08094"
"338.88000","28.24027","0.08150"
"339.12000","28.26018","0.08230"
"339.36000","28.28021","0.08225"
"339.60000","28.30024","0.08277"
"339.84000","28.32021","0.08382"
"340.08000","28.34018","0.08382"
"340.32000","28.36027","0.08454"
"340.56000","28.38018","0.08470"
"340.80000","28.40027","0.08515"
"341.04000","28.42024","0.08537"
"341.28000","28.44021","0.08602"
"341.52000","28.46024","0.08619"
"341.76000","28.48021","0.08675"
"342.00000","28.50024","0.08696"
"342.24000","28.52015","0.08719"
"342.48000","28.54024","0.08723"
"342.72000","28.56021","0.08762"
"342.96000","28.58023","0.08793"
"343.20000","28.60020","0.08834"
"343.44000","28.62023","0.08847"
"343.68000","28.64020","0.08929"
"343.92000","28.66018","-0.00386"
"344.16000","28.68020","-0.00028"
"344.40000","28.70017","-0.00035"
"344.64000","28.72026","0.00080"
"344.88000","28.74017","0.00078"
"345.12000","28.76020","0.00022"
"345.36000","28.78017","-0.00026"
"345.60000","28.80026","-0.00039"
"345.84000","28.82023","-0.00030"
"346.08000","28.84020","-0.00034"
"346.32000","28.86023","-0.00035"
"346.56000","28.88014","-0.00071"
"346.80000","28.90023","-0.00046"
"347.04000","28.92020","-0.00059"
"347.28000","28.94023","-0.00051"
"347.52000","28.96020","-0.00015"
"347.76000","28.98022","-0.00036"
"348.00000","29.00019","-0.00026"
"348.24000","29.02016","-0.00055"
"348.48000","29.04026","-0.00030"
"348.72000","29.06017","-0.00055"
"348.96000","29.08019","-0.00018"
"349.20000","29.10016","-0.00013"
"349.44000","29.12019","-0.00004"
"349.68000","29.14016","-0.00071"
"349.92000","29.16025","-0.00051"
"350.16000","29.18022","-0.00048"
"350.40000","29.20019","-0.00025"
"350.64000","29.22028","-0.00035"
"350.88000","29.24013","-0.00027"
"351.12000","29.26022","-0.00074"
"351.16800","29.26423","-0.00047"