File: Force_trajectories/161217/Specimen_RawData_1.csv
End date,"12/17/2016"
Specimen label,"15AG_22"
Maximum Load,"0.00258",N

Time,Extension,Load
(s),(mm),(N)
"0.00000","0.00000","-0.00036"
"0.37200","0.03115","0.00000"
"0.74400","0.06218","0.00022"
"1.11600","0.09327","-0.00002"
"1.48800","0.12424","0.00016"
"1.86000","0.15515","0.00003"
"2.23200","0.18624","0.00003"
"2.60400","0.21722","0.00011"
"2.97600","0.24813","0.00011"
"3.34800","0.27916","0.00018"
"3.72000","0.31025","0.00031"
"4.09200","0.34116","0.00043"
"4.46400","0.37213","0.00031"
"4.83600","0.40322","0.00011"
"5.20800","0.43413","0.00049"
"5.58000","0.46516","0.00040"
"5.95200","0.49619","0.00021"
"6.32400","0.52722","0.00033"
"6.69600","0.55814","0.00005"
"7.06800","0.58917","0.00025"
"7.44000","0.62020","0.00023"
"7.81200","0.65111","0.00017"
"8.18400","0.68220","0.00024"
"8.55600","0.71323","0.00057"
"8.92800","0.74414","-0.00007"
"9.30000","0.77517","0.00022"
"9.67200","0.80614","0.00005"
"10.04400","0.83717","0.00022"
"10.41600","0.86814","0.00016"
"10.78800","0.89923","0.00011"
"11.16000","0.93027","0.00013"
"11.53200","0.96112","0.00011"
"11.90400","0.99221","0.00024"
"12.27600","1.02324","0.00050"
"12.64800","1.05409","0.00024"
"13.02000","1.08518","-0.00015"
"13.39200","1.11615","0.00067"
"13.76400","1.14718","0.00003"
"14.13600","1.17821","0.00041"
"14.50800","1.20918","0.00003"
"14.88000","1.24015","0.00019"
"15.25200","1.27113","0.00029"
"15.62400","1.30222","0.00033"
"15.99600","1.33319","0.00017"
"16.36800","1.36416","0.00016"
"16.74000","1.39519","0.00030"
"17.11200","1.42622","0.00039"
"17.48400","1.45719","0.00034"
"17.85600","1.48816","0.00019"
"18.22800","1.51919","0.00015"
"18.60000","1.55016","-0.00017"
"18.97200","1.58113","0.00026"
"19.34400","1.61222","0.00025"
"19.71600","1.64320","0.00058"
"20.08800","1.67411","0.00027"
"20.46000","1.70520","0.00027"
"20.83200","1.73623","0.00037"
"21.20400","1.76714","-0.00017"
"21.57600","1.79823","0.00032"
"21.94800","1.82926","0.00028"
"22.32000","1.86011","0.00037"
"22.69200","1.89114","0.00022"
"23.06400","1.92223","0.00021"
"23.43600","1.95314","-0.00003"
"23.80800","1.98424","0.00033"
"24.18000","2.01515","0.00005"
"24.55200","2.04618","0.00018"
"24.92400","2.07721","0.00030"
"25.29600","2.10818","0.00011"
"25.66800","2.13921","-0.00001"
"26.04000","2.17018","0.00029"
"26.41200","2.20115","0.00013"
"26.78400","2.23224","0.00037"
"27.15600","2.26315","0.00062"
"27.52800","2.29418","0.00013"
"27.90000","2.32516","0.00016"
"28.27200","2.35619","0.00037"
"28.64400","2.38716","0.00023"
"29.01600","2.41819","0.00024"
"29.38800","2.44922","0.00041"
"29.76000","2.48019","0.00032"
"30.13200","2.51122","0.00042"
"30.50400","2.54213","0.00019"
"30.87600","2.57310","0.00042"
"31.24800","2.60419","0.00032"
"31.62000","2.63522","0.00009"
"31.99200","2.66619","0.00007"
"32.36400","2.69723","0.00055"
"32.73600","2.72814","0.00043"
"33.10800","2.75917","0.00040"
"33.48000","2.79020","0.00018"
"33.85200","2.82117","0.00015"
"34.22400","2.85214","0.00009"
"34.59600","2.88317","0.00042"
"34.96800","2.91414","0.00000"
"35.34000","2.94517","0.00014"
"35.71200","2.97620","0.00036"
"36.08400","3.00717","0.00055"
"36.45600","3.03820","0.00033"
"36.82800","3.06912","0.00042"
"37.20000","3.10015","0.00037"
"37.57200","3.13124","0.00043"
"37.94400","3.16215","0.00062"
"38.31600","3.19318","0.00042"
"38.68800","3.22421","0.00039"
"39.06000","3.25518","0.00034"
"39.43200","3.28615","0.00023"
"39.80400","3.31718","0.00038"
"40.17600","3.34815","0.00024"
"40.54800","3.37912","0.00033"
"40.92000","3.41028","0.00014"
"41.29200","3.44119","0.00012"
"41.66400","3.47204","0.00026"
"42.03600","3.50325","0.00022"
"42.40800","3.53422","0.00045"
"42.78000","3.56519","0.00022"
"43.15200","3.59622","0.00039"
"43.52400","3.62719","0.00048"
"43.89600","3.65816","0.00039"
"44.26800","3.68913","0.00060"
"44.64000","3.72022","0.00030"
"45.01200","3.75120","0.00035"
"45.38400","3.78217","0.00034"
"45.75600","3.81320","0.00054"
"46.12800","3.84417","0.00025"
"46.50000","3.87514","0.00022"
"46.87200","3.90617","0.00028"
"47.24400","3.93726","0.00080"
"47.61600","3.96817","0.00045"
"47.98800","3.99914","0.00029"
"48.36000","4.03017","0.00042"
"48.73200","4.06114","0.00035"
"49.10400","4.09218","0.00032"
"49.47600","4.12321","0.00034"
"49.84800","4.15412","0.00045"
"50.22000","4.18515","0.00045"
"50.59200","4.21618","0.00014"
"50.96400","4.24721","0.00029"
"51.33600","4.27818","0.00024"
"51.70800","4.30921","0.00018"
"52.08000","4.34024","0.00028"
"52.45200","4.37109","0.00051"
"52.82400","4.40218","0.00030"
"53.19600","4.43321","0.00005"
"53.56800","4.46419","0.00037"
"53.94000","4.49516","0.00036"
"54.31200","4.52613","0.00022"
"54.68400","4.55716","0.00027"
"55.05600","4.58819","0.00048"
"55.42800","4.61922","0.00030"
"55.80000","4.65019","0.00042"
"56.17200","4.68116","0.00048"
"56.54400","4.71219","0.00044"
"56.91600","4.74322","0.00050"
"57.28800","4.77413","0.00031"
"57.66000","4.80522","0.00031"
"58.03200","4.83620","0.00044"
"58.40400","4.86717","0.00054"
"58.77600","4.89820","0.00054"
"59.14800","4.92917","0.00062"
"59.52000","4.96014","0.00038"
"59.89200","4.99117","0.00017"
"60.26400","5.02226","0.00069"
"60.63600","5.05317","0.00057"
"61.00800","5.08414","0.00032"
"61.38000","5.11523","0.00033"
"61.75200","5.14620","0.00065"
"62.12400","5.17718","0.00041"
"62.49600","5.20821","0.00016"
"62.86800","5.23918","0.00058"
"63.24000","5.27015","0.00045"
"63.61200","5.30118","0.00042"
"63.98400","5.33221","0.00032"
"64.35600","5.36312","0.00052"
"64.72800","5.39415","0.00050"
"65.10000","5.42524","0.00057"
"65.47200","5.45615","0.00021"
"65.84400","5.48712","0.00037"
"66.21600","5.51821","0.00050"
"66.58800","5.54919","0.00013"
"66.96000","5.58010","0.00057"
"67.33200","5.61119","0.00044"
"67.70400","5.64222","0.00020"
"68.07600","5.67313","0.00055"
"68.44800","5.70416","0.00031"
"68.82000","5.73519","0.00026"
"69.19200","5.76616","0.00021"
"69.56400","5.79719","0.00056"
"69.93600","5.82822","0.00044"
"70.30800","5.85920","0.00057"
"70.68000","5.89011","0.00027"
"71.05200","5.92120","0.00061"
"71.42400","5.95223","0.00032"
"71.79600","5.98314","0.00065"
"72.16800","6.01423","0.00083"
"72.54000","6.04520","0.00077"
"72.91200","6.07611","0.00069"
"73.28400","6.10720","0.00032"
"73.65600","6.13817","0.00029"
"74.02800","6.16920","0.00041"
"74.40000","6.20011","0.00075"
"74.77200","6.23120","0.00034"
"75.14400","6.26218","0.00064"
"75.51600","6.29315","0.00064"
"75.88800","6.32424","0.00032"
"76.26000","6.35521","0.00056"
"76.63200","6.38618","0.00035"
"77.00400","6.41715","0.00025"
"77.37600","6.44818","0.00042"
"77.74800","6.47915","0.00046"
"78.12000","6.51012","0.00064"
"78.49200","6.54121","0.00040"
"78.86400","6.57219","0.00050"
"79.23600","6.60316","0.00056"
"79.60800","6.63425","0.00040"
"79.98000","6.66516","0.00049"
"80.35200","6.69613","0.00044"
"80.72400","6.72716","0.00035"
"81.09600","6.75819","0.00054"
"81.46800","6.78916","0.00015"
"81.84000","6.82019","0.00062"
"82.21200","6.85122","0.00064"
"82.58400","6.88213","0.00040"
"82.95600","6.91322","0.00062"
"83.32800","6.94420","0.00049"
"83.70000","6.97511","0.00037"
"84.07200","7.00620","0.00053"
"84.44400","7.03717","0.00047"
"84.81600","7.06820","0.00036"
"85.18800","7.09917","0.00037"
"85.56000","7.13020","0.00042"
"85.93200","7.16123","0.00041"
"86.30400","7.19214","0.00035"
"86.67600","7.22317","0.00045"
"87.04800","7.25420","0.00060"
"87.42000","7.28512","0.00064"
"87.79200","7.31621","0.00011"
"88.16400","7.34718","0.00074"
"88.53600","7.37821","0.00074"
"88.90800","7.40912","0.00054"
"89.28000","7.44021","0.00054"
"89.65200","7.47118","0.00066"
"90.02400","7.50215","0.00067"
"90.39600","7.53318","0.00072"
"90.76800","7.56415","0.00048"
"91.14000","7.59512","0.00056"
"91.51200","7.62627","0.00055"
"91.88400","7.65719","0.00057"
"92.25600","7.68816","0.00075"
"92.62800","7.71913","0.00048"
"93.00000","7.75016","0.00086"
"93.37200","7.78119","0.00056"
"93.74400","7.81216","0.00052"
"94.11600","7.84319","0.00069"
"94.48800","7.87422","0.00083"
"94.86000","7.90519","0.00073"
"95.23200","7.93616","0.00095"
"95.60400","7.96725","0.00036"
"95.97600","7.99817","0.00055"
"96.34800","8.02920","0.00069"
"96.72000","8.06023","0.00059"
"97.09200","8.09114","0.00057"
"97.46400","8.12217","0.00074"
"97.83600","8.15326","0.00087"
"98.20800","8.18417","0.00057"
"98.58000","8.21520","0.00034"
"98.95200","8.24623","0.00054"
"99.32400","8.27714","0.00040"
"99.69600","8.30811","0.00054"
"100.06800","8.33920","0.00079"
"100.44000","8.37018","0.00067"
"100.81200","8.40115","0.00056"
"101.18400","8.43224","0.00110"
"101.55600","8.46327","0.00051"
"101.92800","8.49412","0.00078"
"102.30000","8.52521","0.00074"
"102.67200","8.55618","0.00064"
"103.04400","8.58715","0.00053"
"103.41600","8.61818","0.00063"
"103.78800","8.64921","0.00072"
"104.16000","8.68018","0.00074"
"104.53200","8.71116","0.00062"
"104.90400","8.74219","0.00098"
"105.27600","8.77322","0.00085"
"105.64800","8.80413","0.00069"
"106.02000","8.83516","0.00083"
"106.39200","8.86619","0.00054"
"106.76400","8.89710","0.00060"
"107.13600","8.92819","0.00088"
"107.50800","8.95922","0.00078"
"107.88000","8.99019","0.00089"
"108.25200","9.02116","0.00084"
"108.62400","9.05219","0.00077"
"108.99600","9.08317","0.00060"
"109.36800","9.11414","0.00067"
"109.74000","9.14523","0.00048"
"110.11200","9.17614","0.00070"
"110.48400","9.20711","0.00070"
"110.85600","9.23820","0.00087"
"111.22800","9.26917","0.00077"
"111.60000","9.30014","0.00071"
"111.97200","9.33117","0.00068"
"112.34400","9.36226","0.00059"
"112.71600","9.39312","0.00076"
"113.08800","9.42415","0.00073"
"113.46000","9.45524","0.00066"
"113.83200","9.48615","0.00117"
"114.20400","9.51724","0.00054"
"114.57600","9.54821","0.00072"
"114.94800","9.57918","0.00085"
"115.32000","9.61015","0.00060"
"115.69200","9.64118","0.00081"
"116.06400","9.67221","0.00071"
"116.43600","9.70312","0.00057"
"116.80800","9.73421","0.00076"
"117.18000","9.76519","0.00051"
"117.55200","9.79610","0.00084"
"117.92400","9.82725","0.00092"
"118.29600","9.85816","0.00077"
"118.66800","9.88913","0.00071"
"119.04000","9.92016","0.00098"
"119.41200","9.95119","0.00085"
"119.78400","9.98222","0.00075"
"120.15600","10.01319","0.00082"
"120.52800","10.04422","0.00077"
"120.90000","10.07519","0.00102"
"121.27200","10.10616","0.00076"
"121.64400","10.13720","0.00075"
"122.01600","10.16817","0.00084"
"122.38800","10.19914","0.00067"
"122.76000","10.23023","0.00073"
"123.13200","10.26120","0.00117"
"123.50400","10.29217","0.00092"
"123.87600","10.32320","0.00078"
"124.24800","10.35423","0.00103"
"124.62000","10.38514","0.00081"
"124.99200","10.41617","0.00046"
"125.36400","10.44720","0.00095"
"125.73600","10.47818","0.00092"
"126.10800","10.50915","0.00094"
"126.48000","10.54018","0.00088"
"126.85200","10.57115","0.00090"
"127.22400","10.60218","0.00075"
"127.59600","10.63321","0.00088"
"127.96800","10.66424","0.00098"
"128.34000","10.69515","0.00079"
"128.71200","10.72618","0.00079"
"129.08400","10.75721","0.00095"
"129.45600","10.78818","0.00120"
"129.82800","10.81916","0.00071"
"130.20000","10.85019","0.00109"
"130.57200","10.88116","0.00095"
"130.94400","10.91213","0.00106"
"131.31600","10.94316","0.00103"
"131.68800","10.97419","0.00095"
"132.06000","11.00516","0.00097"
"132.43200","11.03619","0.00095"
"132.80400","11.06722","0.00083"
"133.17600","11.09813","0.00074"
"133.54800","11.12922","0.00098"
"133.92000","11.16019","0.00077"
"134.29200","11.19116","0.00091"
"134.66400","11.22214","0.00099"
"135.03600","11.25323","0.00097"
"135.40800","11.28420","0.00109"
"135.78000","11.31517","0.00100"
"136.15200","11.34620","0.00083"
"136.52400","11.37717","0.00084"
"136.89600","11.40814","0.00083"
"137.26800","11.43917","0.00088"
"137.64000","11.47020","0.00113"
"138.01200","11.50117","0.00083"
"138.38400","11.53214","0.00096"
"138.75600","11.56318","0.00107"
"139.12800","11.59421","0.00105"
"139.50000","11.62518","0.00112"
"139.87200","11.65621","0.00090"
"140.24400","11.68718","0.00102"
"140.61600","11.71815","0.00104"
"140.98800","11.74918","0.00117"
"141.36000","11.78021","0.00083"
"141.73200","11.81118","0.00123"
"142.10400","11.84221","0.00096"
"142.47600","11.87325","0.00085"
"142.84800","11.90410","0.00082"
"143.22000","11.93519","0.00116"
"143.59200","11.96616","0.00101"
"143.96400","11.99713","0.00080"
"144.33600","12.02816","0.00115"
"144.70800","12.05913","0.00083"
"145.08000","12.09016","0.00095"
"145.45200","12.12119","0.00096"
"145.82400","12.15216","0.00106"
"146.19600","12.18319","0.00079"
"146.56800","12.21416","0.00118"
"146.94000","12.24520","0.00083"
"147.31200","12.27617","0.00096"
"147.68400","12.30720","0.00109"
"148.05600","12.33823","0.00101"
"148.42800","12.36920","0.00108"
"148.80000","12.40017","0.00118"
"149.17200","12.43114","0.00122"
"149.54400","12.46217","0.00108"
"149.91600","12.49314","0.00095"
"150.28800","12.52417","0.00103"
"150.66000","12.55520","0.00107"
"151.03200","12.58617","0.00101"
"151.40400","12.61715","0.00079"
"151.77600","12.64824","0.00095"
"152.14800","12.67921","0.00137"
"152.52000","12.71018","0.00083"
"152.89200","12.74121","0.00105"
"153.26400","12.77218","0.00091"
"153.63600","12.80315","0.00104"
"154.00800","12.83418","0.00101"
"154.38000","12.86521","0.00118"
"154.75200","12.89618","0.00143"
"155.12400","12.92715","0.00131"
"155.49600","12.95819","0.00117"
"155.86800","12.98916","0.00099"
"156.24000","13.02013","0.00107"
"156.61200","13.05116","0.00130"
"156.98400","13.08225","0.00116"
"157.35600","13.11316","0.00132"
"157.72800","13.14419","0.00129"
"158.10000","13.17528","0.00121"
"158.47200","13.20613","0.00084"
"158.84400","13.23722","0.00129"
"159.21600","13.26819","0.00106"
"159.58800","13.29917","0.00099"
"159.96000","13.33014","0.00124"
"160.33200","13.36123","0.00096"
"160.70400","13.39220","0.00101"
"161.07600","13.42317","0.00138"
"161.44800","13.45420","0.00135"
"161.82000","13.48517","0.00114"
"162.19200","13.51608","0.00091"
"162.56400","13.54723","0.00121"
"162.93600","13.57820","0.00125"
"163.30800","13.60917","0.00099"
"163.68000","13.64021","0.00112"
"164.05200","13.67118","0.00099"
"164.42400","13.70215","0.00114"
"164.79600","13.73312","0.00105"
"165.16800","13.76421","0.00103"
"165.54000","13.79524","0.00082"
"165.91200","13.82615","0.00086"
"166.28400","13.85718","0.00135"
"166.65600","13.88821","0.00119"
"167.02800","13.91918","0.00124"
"167.40000","13.95021","0.00102"
"167.77200","13.98124","0.00132"
"168.14400","14.01216","0.00117"
"168.51600","14.04319","0.00145"
"168.88800","14.07422","0.00095"
"169.26000","14.10513","0.00120"
"169.63200","14.13616","0.00114"
"170.00400","14.16719","0.00119"
"170.37600","14.19816","0.00088"
"170.74800","14.22913","0.00143"
"171.12000","14.26016","0.00140"
"171.49200","14.29119","0.00116"
"171.86400","14.32216","0.00131"
"172.23600","14.35320","0.00108"
"172.60800","14.38423","0.00110"
"172.98000","14.41514","0.00131"
"173.35200","14.44617","0.00112"
"173.72400","14.47720","0.00113"
"174.09600","14.50817","0.00118"
"174.46800","14.53920","0.00095"
"174.84000","14.57017","0.00102"
"175.21200","14.60120","0.00132"
"175.58400","14.63217","0.00125"
"175.95600","14.66326","0.00112"
"176.32800","14.69423","0.00122"
"176.70000","14.72515","0.00112"
"177.07200","14.75618","0.00104"
"177.44400","14.78715","0.00112"
"177.81600","14.81812","0.00114"
"178.18800","14.84921","0.00138"
"178.56000","14.88012","0.00104"
"178.93200","14.91121","0.00141"
"179.30400","14.94218","0.00137"
"179.67600","14.97315","0.00106"
"180.04800","15.00418","0.00120"
"180.42000","15.03516","0.00098"
"180.79200","15.06625","0.00120"
"181.16400","15.09722","0.00107"
"181.53600","15.12813","0.00124"
"181.90800","15.15922","0.00117"
"182.28000","15.19013","0.00135"
"182.65200","15.22116","0.00131"
"183.02400","15.25219","0.00122"
"183.39600","15.28322","0.00103"
"183.76800","15.31413","0.00125"
"184.14000","15.34516","0.00121"
"184.51200","15.37626","0.00111"
"184.88400","15.40717","0.00119"
"185.25600","15.43820","0.00140"
"185.62800","15.46923","0.00112"
"186.00000","15.50020","0.00134"
"186.37200","15.53117","0.00116"
"186.74400","15.56220","0.00108"
"187.11600","15.59317","0.00141"
"187.48800","15.62414","0.00116"
"187.86000","15.65517","0.00138"
"188.23200","15.68620","0.00147"
"188.60400","15.71717","0.00119"
"188.97600","15.74820","0.00135"
"189.34800","15.77917","0.00155"
"189.72000","15.81021","0.00128"
"190.09200","15.84118","0.00134"
"190.46400","15.87221","0.00146"
"190.83600","15.90318","0.00108"
"191.20800","15.93415","0.00111"
"191.58000","15.96524","0.00123"
"191.95200","15.99621","0.00125"
"192.32400","16.02712","0.00117"
"192.69600","16.05821","0.00117"
"193.06800","16.08924","0.00131"
"193.44000","16.12009","0.00109"
"193.81200","16.15119","0.00123"
"194.18400","16.18222","0.00118"
"194.55600","16.21319","0.00101"
"194.92800","16.24410","0.00089"
"195.30000","16.27519","0.00137"
"195.67200","16.30616","0.00118"
"196.04400","16.33719","0.00147"
"196.41600","16.36822","0.00135"
"196.78800","16.39919","0.00118"
"197.16000","16.43016","0.00132"
"197.53200","16.46119","0.00117"
"197.90400","16.49223","0.00133"
"198.27600","16.52320","0.00127"
"198.64800","16.55417","0.00124"
"199.02000","16.58520","0.00129"
"199.39200","16.61617","0.00110"
"199.76400","16.64714","0.00126"
"200.13600","16.67817","0.00131"
"200.50800","16.70920","0.00128"
"200.88000","16.74017","0.00110"
"201.25200","16.77120","0.00152"
"201.62400","16.80223","0.00155"
"201.99600","16.83315","0.00144"
"202.36800","16.86418","0.00150"
"202.74000","16.89521","0.00136"
"203.11200","16.92612","0.00142"
"203.48400","16.95721","0.00111"
"203.85600","16.98818","0.00118"
"204.22800","17.01921","0.00144"
"204.60000","17.05018","0.00141"
"204.97200","17.08115","0.00169"
"205.34400","17.11212","0.00161"
"205.71600","17.14321","0.00132"
"206.08800","17.17418","0.00139"
"206.46000","17.20522","0.00137"
"206.83200","17.23619","0.00149"
"207.20400","17.26716","0.00136"
"207.57600","17.29819","0.00134"
"207.94800","17.32916","0.00141"
"208.32000","17.36019","0.00149"
"208.69200","17.39116","0.00158"
"209.06400","17.42213","0.00137"
"209.43600","17.45310","0.00120"
"209.80800","17.48419","0.00174"
"210.18000","17.51522","0.00103"
"210.55200","17.54614","0.00149"
"210.92400","17.57722","0.00144"
"211.29600","17.60820","0.00129"
"211.66800","17.63917","0.00150"
"212.04000","17.67020","0.00151"
"212.41200","17.70117","0.00144"
"212.78400","17.73220","0.00154"
"213.15600","17.76317","0.00162"
"213.52800","17.79420","0.00157"
"213.90000","17.82511","0.00116"
"214.27200","17.85614","0.00150"
"214.64400","17.88723","0.00128"
"215.01600","17.91815","0.00148"
"215.38800","17.94918","0.00143"
"215.76000","17.98015","0.00152"
"216.13200","18.01118","0.00142"
"216.50400","18.04221","0.00165"
"216.87600","18.07324","0.00133"
"217.24800","18.10421","0.00132"
"217.62000","18.13512","0.00151"
"217.99200","18.16615","0.00139"
"218.36400","18.19724","0.00142"
"218.73600","18.22809","0.00157"
"219.10800","18.25918","0.00153"
"219.48000","18.29022","0.00114"
"219.85200","18.32119","0.00132"
"220.22400","18.35216","0.00133"
"220.59600","18.38319","0.00132"
"220.96800","18.41416","0.00150"
"221.34000","18.44519","0.00151"
"221.71200","18.47622","0.00157"
"222.08400","18.50719","0.00164"
"222.45600","18.53811","0.00145"
"222.82800","18.56925","0.00144"
"223.20000","18.60017","0.00152"
"223.57200","18.63114","0.00149"
"223.94400","18.66217","0.00147"
"224.31600","18.69320","0.00142"
"224.68800","18.72417","0.00168"
"225.06000","18.75514","0.00148"
"225.43200","18.78617","0.00147"
"225.80400","18.81720","0.00150"
"226.17600","18.84811","0.00157"
"226.54800","18.87920","0.00124"
"226.92000","18.91023","0.00170"
"227.29200","18.94114","0.00130"
"227.66400","18.97218","0.00154"
"228.03600","19.00321","0.00107"
"228.40800","19.03418","0.00167"
"228.78000","19.06515","0.00113"
"229.15200","19.09618","0.00143"
"229.52400","19.12715","0.00137"
"229.89600","19.15818","0.00181"
"230.26800","19.18927","0.00147"
"230.64000","19.22018","0.00130"
"231.01200","19.25115","0.00136"
"231.38400","19.28218","0.00153"
"231.75600","19.31315","0.00155"
"232.12800","19.34419","0.00178"
"232.50000","19.37522","0.00143"
"232.87200","19.40619","0.00154"
"233.24400","19.43710","0.00142"
"233.61600","19.46813","0.00163"
"233.98800","19.49922","0.00170"
"234.36000","19.53013","0.00163"
"234.73200","19.56116","0.00152"
"235.10400","19.59219","0.00166"
"235.47600","19.62322","0.00140"
"235.84800","19.65413","0.00163"
"236.22000","19.68523","0.00146"
"236.59200","19.71619","0.00145"
"236.96400","19.74717","0.00174"
"237.33600","19.77820","0.00159"
"237.70800","19.80917","0.00163"
"238.08000","19.84008","0.00160"
"238.45200","19.87123","0.00189"
"238.82400","19.90220","0.00179"
"239.19600","19.93317","0.00185"
"239.56800","19.96414","0.00158"
"239.94000","19.99517","0.00202"
"240.31200","20.02615","0.00153"
"240.68400","20.05718","0.00156"
"241.05600","20.08821","0.00184"
"241.42800","20.11918","0.00172"
"241.80000","20.15015","0.00174"
"242.17200","20.18124","0.00171"
"242.54400","20.21221","0.00164"
"242.91600","20.24318","0.00172"
"243.28800","20.27415","0.00184"
"243.66000","20.30518","0.00195"
"244.03200","20.33615","0.00142"
"244.40400","20.36719","0.00181"
"244.77600","20.39822","0.00181"
"245.14800","20.42913","0.00188"
"245.52000","20.46016","0.00153"
"245.89200","20.49113","0.00151"
"246.26400","20.52216","0.00163"
"246.63600","20.55319","0.00172"
"247.00800","20.58416","0.00172"
"247.38000","20.61519","0.00197"
"247.75200","20.64610","0.00168"
"248.12400","20.67719","0.00176"
"248.49600","20.70822","0.00178"
"248.86800","20.73914","0.00163"
"249.24000","20.77023","0.00196"
"249.61200","20.80120","0.00159"
"249.98400","20.83211","0.00165"
"250.35600","20.86314","0.00151"
"250.72800","20.89417","0.00210"
"251.10000","20.92520","0.00191"
"251.47200","20.95611","0.00167"
"251.84400","20.98720","0.00186"
"252.21600","21.01817","0.00174"
"252.58800","21.04908","0.00154"
"252.96000","21.08023","0.00195"
"253.33200","21.11121","0.00177"
"253.70400","21.14212","0.00167"
"254.07600","21.17321","0.00184"
"254.44800","21.20418","0.00155"
"254.82000","21.23521","0.00167"
"255.19200","21.26612","0.00170"
"255.56400","21.29721","0.00187"
"255.93600","21.32818","0.00177"
"256.30800","21.35909","0.00186"
"256.68000","21.39024","0.00191"
"257.05200","21.42121","0.00164"
"257.42400","21.45219","0.00166"
"257.79600","21.48322","0.00184"
"258.16800","21.51425","0.00188"
"258.54000","21.54516","0.00187"
"258.91200","21.57613","0.00181"
"259.28400","21.60722","0.00176"
"259.65600","21.63819","0.00162"
"260.02800","21.66916","0.00180"
"260.40000","21.70019","0.00191"
"260.77200","21.73122","0.00163"
"261.14400","21.76219","0.00192"
"261.51600","21.79323","0.00150"
"261.88800","21.82420","0.00203"
"262.26000","21.85517","0.00182"
"262.63200","21.88620","0.00181"
"263.00400","21.91723","0.00203"
"263.37600","21.94814","0.00174"
"263.74800","21.97923","0.00200"
"264.12000","22.01020","0.00182"
"264.49200","22.04111","0.00158"
"264.86400","22.07214","0.00168"
"265.23600","22.10317","0.00192"
"265.60800","22.13415","0.00185"
"265.98000","22.16518","0.00172"
"266.35200","22.19621","0.00160"
"266.72400","22.22718","0.00184"
"267.09600","22.25815","0.00209"
"267.46800","22.28918","0.00196"
"267.84000","22.32021","0.00143"
"268.21200","22.35118","0.00187"
"268.58400","22.38221","0.00177"
"268.95600","22.41324","0.00175"
"269.32800","22.44415","0.00213"
"269.70000","22.47512","0.00199"
"270.07200","22.50621","0.00184"
"270.44400","22.53719","0.00187"
"270.81600","22.56816","0.00204"
"271.18800","22.59919","0.00169"
"271.56000","22.63010","0.00198"
"271.93200","22.66107","0.00208"
"272.30400","22.69222","0.00192"
"272.67600","22.72319","0.00167"
"273.04800","22.75416","0.00201"
"273.42000","22.78519","0.00176"
"273.79200","22.81622","0.00168"
"274.16400","22.84714","0.00163"
"274.53600","22.87816","0.00211"
"274.90800","22.90926","0.00190"
"275.28000","22.94011","0.00163"
"275.65200","22.97120","0.00195"
"276.02400","23.00223","0.00205"
"276.39600","23.03320","0.00193"
"276.76800","23.06417","0.00173"
"277.14000","23.09520","0.00184"
"277.51200","23.12623","0.00192"
"277.88400","23.15708","0.00164"
"278.25600","23.18817","0.00176"
"278.62800","23.21926","0.00187"
"279.00000","23.25012","0.00207"
"279.37200","23.28121","0.00202"
"279.74400","23.31218","0.00197"
"280.11600","23.34315","0.00190"
"280.48800","23.37418","0.00182"
"280.86000","23.40521","0.00190"
"281.23200","23.43618","0.00206"
"281.60400","23.46715","0.00172"
"281.97600","23.49818","0.00214"
"282.34800","23.52916","0.00195"
"282.72000","23.56012","0.00202"
"283.09200","23.59122","0.00180"
"283.46400","23.62219","0.00184"
"283.83600","23.65316","0.00214"
"284.20800","23.68413","0.00216"
"284.58000","23.71522","0.00232"
"284.95200","23.74619","0.00173"
"285.32400","23.77716","0.00197"
"285.69600","23.80819","0.00184"
"286.06800","23.83916","0.00201"
"286.44000","23.87013","0.00184"
"286.81200","23.90122","0.00183"
"287.18400","23.93220","0.00218"
"287.55600","23.96311","0.00210"
"287.92800","23.99420","0.00199"
"288.30000","24.02523","0.00219"
"288.67200","24.05620","0.00197"
"289.04400","24.08717","0.00207"
"289.41600","24.11820","0.00207"
"289.78800","24.14911","0.00197"
"290.16000","24.18020","0.00188"
"290.53200","24.21123","0.00217"
"290.90400","24.24214","0.00216"
"291.27600","24.27317","0.00183"
"291.64800","24.30420","0.00203"
"292.02000","24.33518","0.00212"
"292.39200","24.36615","0.00186"
"292.76400","24.39718","0.00213"
"293.13600","24.42821","0.00225"
"293.50800","24.45918","0.00195"
"293.88000","24.49015","0.00182"
"294.25200","24.52124","0.00191"
"294.62400","24.55215","0.00194"
"294.99600","24.58318","0.00165"
"295.36800","24.61415","0.00172"
"295.74000","24.64513","0.00207"
"296.11200","24.67616","0.00194"
"296.48400","24.70725","0.00186"
"296.85600","24.73816","0.00195"
"297.22800","24.76913","0.00174"
"297.60000","24.80016","0.00200"
"297.97200","24.83113","0.00180"
"298.34400","24.86216","0.00226"
"298.71600","24.89319","0.00191"
"299.08800","24.92416","0.00215"
"299.46000","24.95520","0.00192"
"299.83200","24.98616","0.00196"
"300.20400","25.01720","0.00213"
"300.57600","25.04817","0.00194"
"300.94800","25.07920","0.00218"
"301.32000","25.11017","0.00201"
"301.69200","25.14120","0.00175"
"302.06400","25.17217","0.00195"
"302.43600","25.20320","0.00191"
"302.80800","25.23417","0.00198"
"303.18000","25.26514","0.00202"
"303.55200","25.29623","0.00183"
"303.92400","25.32721","0.00165"
"304.29600","25.35812","0.00196"
"304.66800","25.38921","0.00196"
"305.04000","25.42018","0.00191"
"305.41200","25.45109","0.00196"
"305.78400","25.48218","0.00192"
"306.15600","25.51321","0.00182"
"306.52800","25.54412","0.00177"
"306.90000","25.57515","0.00181"
"307.27200","25.60624","0.00175"
"307.64400","25.63715","0.00176"
"308.01600","25.66813","0.00192"
"308.38800","25.69921","0.00170"
"308.76000","25.73019","0.00172"
"309.13200","25.76116","0.00160"
"309.50400","25.79219","0.00174"
"309.87600","25.82316","0.00156"
"310.24800","25.85413","0.00192"
"310.62000","25.88516","0.00177"
"310.99200","25.91619","0.00167"
"311.36400","25.94722","0.00182"
"311.73600","25.97813","0.00182"
"312.10800","26.00922","0.00166"
"312.48000","26.04020","0.00132"
"312.85200","26.07117","0.00181"
"313.22400","26.10226","0.00168"
"313.59600","26.13323","0.00190"
"313.96800","26.16414","0.00201"
"314.34000","26.19517","0.00193"
"314.71200","26.22620","0.00194"
"315.08400","26.25717","0.00179"
"315.45600","26.28815","0.00186"
"315.82800","26.31923","0.00186"
"316.20000","26.35014","0.00170"
"316.57200","26.38112","0.00169"
"316.94400","26.41227","0.00149"
"317.31600","26.44318","0.00174"
"317.68800","26.47415","0.00177"
"318.06000","26.50518","0.00160"
"318.43200","26.53615","0.00160"
"318.80400","26.56718","0.00183"
"319.17600","26.59815","0.00183"
"319.54800","26.62924","0.00168"
"319.92000","26.66015","0.00192"
"320.29200","26.69118","0.00183"
"320.66400","26.72222","0.00194"
"321.03600","26.75319","0.00167"
"321.40800","26.78416","0.00206"
"321.78000","26.81525","0.00147"
"322.15200","26.84616","0.00147"
"322.52400","26.87713","0.00153"
"322.89600","26.90816","0.00186"
"323.26800","26.93925","0.00140"
"323.64000","26.97010","0.00166"
"324.01200","27.00119","0.00190"
"324.38400","27.03222","0.00142"
"324.75600","27.06314","0.00191"
"325.12800","27.09422","0.00142"
"325.50000","27.12520","0.00156"
"325.87200","27.15617","0.00165"
"326.24400","27.18720","0.00178"
"326.61600","27.21817","0.00179"
"326.98800","27.24920","0.00161"
"327.36000","27.28017","0.00145"
"327.73200","27.31120","0.00141"
"328.10400","27.34217","0.00169"
"328.47600","27.37314","0.00160"
"328.84800","27.40423","0.00181"
"329.22000","27.43521","0.00155"
"329.59200","27.46618","0.00194"
"329.96400","27.49715","0.00148"
"330.33600","27.52824","0.00143"
"330.70800","27.55921","0.00175"
"331.08000","27.59012","0.00161"
"331.45200","27.62127","0.00156"
"331.82400","27.65212","0.00172"
"332.19600","27.68315","0.00149"
"332.56800","27.71424","0.00151"
"332.94000","27.74521","0.00173"
"333.31200","27.77612","0.00178"
"333.68400","27.80721","0.00164"
"334.05600","27.83819","0.00141"
"334.42800","27.86910","0.00154"
"334.80000","27.90019","0.00142"
"335.17200","27.93122","0.00164"
"335.54400","27.96213","0.00162"
"335.91600","27.99316","0.00161"
"336.28800","28.02419","0.00167"
"336.66000","28.05516","0.00140"
"337.03200","28.08614","0.00175"
"337.40400","28.11722","0.00164"
"337.77600","28.14820","0.00148"
"338.14800","28.17911","0.00165"
"338.52000","28.21014","0.00146"
"338.89200","28.24123","0.00139"
"339.26400","28.27208","0.00158"
"339.63600","28.30317","0.00158"
"340.00800","28.33420","0.00194"
"340.38000","28.36517","0.00155"
"340.75200","28.39614","0.00196"
"341.12400","28.42723","0.00162"
"341.49600","28.45815","0.00173"
"341.86800","28.48912","0.00158"
"342.24000","28.52021","0.00147"
"342.61200","28.55118","0.00171"
"342.98400","28.58209","0.00150"
"343.35600","28.61324","0.00186"
"343.72800","28.64415","0.00163"
"344.10000","28.67512","0.00157"
"344.47200","28.70621","0.00157"
"344.84400","28.73718","0.00163"
"345.21600","28.76815","0.00163"
"345.58800","28.79912","0.00146"
"345.96000","28.83015","0.00167"
"346.33200","28.86119","0.00160"
"346.70400","28.89216","0.00151"
"347.07600","28.92319","0.00164"
"347.44800","28.95416","0.00134"
"347.82000","28.98519","0.00151"
"348.19200","29.01616","0.00148"
"348.56400","29.04725","0.00179"
"348.93600","29.07816","0.00160"
"349.30800","29.10919","0.00187"
"349.68000","29.14022","0.00172"
"350.05200","29.17113","0.00166"
"350.42400","29.20217","0.00151"
"350.79600","29.23319","0.00164"
"351.16800","29.26417","0.00156"
"351.54000","29.29514","0.00163"
"351.91200","29.32617","0.00157"
"352.28400","29.35720","0.00156"
"352.65600","29.38817","0.00189"
"353.02800","29.41920","0.00173"
"353.40000","29.45023","0.00159"
"353.77200","29.48114","0.00171"
"354.14400","29.51217","0.00168"
"354.51600","29.54314","0.00158"
"354.88800","29.57412","0.00152"
"355.26000","29.60527","0.00157"
"355.63200","29.63618","0.00170"
"356.00400","29.66715","0.00133"
"356.37600","29.69812","0.00163"
"356.74800","29.72921","0.00180"
"357.12000","29.76024","0.00167"
"357.49200","29.79115","0.00161"
"357.86400","29.82218","0.00166"
"358.23600","29.85315","0.00155"
"358.60800","29.88413","0.00158"
"358.98000","29.91521","0.00164"
"359.35200","29.94619","0.00149"
"359.72400","29.97721","0.00150"
"360.09600","30.00819","0.00163"
"360.46800","30.03916","0.00158"
"360.84000","30.07013","0.00155"
"361.21200","30.10116","0.00143"
"361.58400","30.13219","0.00162"
"361.95600","30.16316","0.00135"
"362.32800","30.19413","0.00154"
"362.70000","30.22523","0.00113"
"363.07200","30.25614","0.00131"
"363.44400","30.28717","0.00144"
"363.81600","30.31820","0.00140"
"364.18800","30.34923","0.00107"
"364.56000","30.38014","0.00154"
"364.93200","30.41117","0.00156"
"365.30400","30.44220","0.00160"
"365.67600","30.47317","0.00146"
"366.04800","30.50420","0.00174"
"366.42000","30.53523","0.00164"
"366.79200","30.56614","0.00159"
"367.16400","30.59711","0.00157"
"367.53600","30.62820","0.00173"
"367.90800","30.65924","0.00158"
"368.28200","30.69027","0.00146"
"368.65400","30.72136","0.00159"
"369.02600","30.75239","0.00155"
"369.39800","30.78330","0.00146"
"369.77000","30.81433","0.00134"
"370.14200","30.84536","0.00138"
"370.51400","30.87633","0.00161"
"370.88600","30.90730","0.00155"
"371.25800","30.93833","0.00160"
"371.63000","30.96936","0.00166"
"372.00200","31.00034","0.00155"
"372.37400","31.03131","0.00150"
"372.74600","31.06240","0.00163"
"373.11800","31.09331","0.00159"
"373.49000","31.12434","0.00151"
"373.86200","31.15537","0.00156"
"374.23400","31.18628","0.00136"
"374.60600","31.21737","0.00169"
"374.97800","31.24834","0.00159"
"375.35000","31.27937","0.00186"
"375.72200","31.31028","0.00139"
"376.09400","31.34137","0.00131"
"376.46600","31.37235","0.00138"
"376.83800","31.40337","0.00169"
"377.21000","31.43435","0.00171"
"377.58200","31.46538","0.00184"
"377.95400","31.49635","0.00144"
"378.32600","31.52732","0.00132"
"378.69800","31.55835","0.00176"
"379.07000","31.58932","0.00158"
"379.44200","31.62029","0.00174"
"379.81400","31.65138","0.00165"
"380.18600","31.68229","0.00138"
"380.55800","31.71333","0.00147"
"380.93000","31.74435","0.00145"
"381.30200","31.77533","0.00149"
"381.67400","31.80636","0.00160"
"382.04600","31.83733","0.00145"
"382.41800","31.86836","0.00152"
"382.79000","31.89933","0.00167"
"383.16200","31.93036","0.00152"
"383.53400","31.96139","0.00169"
"383.90600","31.99230","0.00149"
"384.27800","32.02339","0.00149"
"384.65000","32.05436","0.00163"
"385.02200","32.08533","0.00159"
"385.39400","32.11636","0.00158"
"385.76600","32.14734","0.00154"
"386.13800","32.17831","0.00163"
"386.51000","32.20934","0.00184"
"386.88200","32.24031","0.00175"
"387.25400","32.27134","0.00153"
"387.62600","32.30231","0.00142"
"387.99800","32.33334","0.00141"
"388.37000","32.36431","0.00154"
"388.74200","32.39534","0.00167"
"389.11400","32.42638","0.00138"
"389.48600","32.45734","0.00163"
"389.85800","32.48832","0.00146"
"390.23000","32.51929","0.00141"
"390.60200","32.55038","0.00167"
"390.97400","32.58135","0.00158"
"391.34600","32.61232","0.00180"
"391.71800","32.64341","0.00159"
"392.09000","32.67432","0.00130"
"392.46200","32.70529","0.00161"
"392.83400","32.73638","0.00152"
"393.20600","32.76736","0.00150"
"393.57800","32.79832","0.00155"
"393.95000","32.82936","0.00142"
"394.32200","32.86033","0.00146"
"394.69400","32.89130","0.00157"
"395.06600","32.92233","0.00143"
"395.43800","32.95342","0.00146"
"395.81000","32.98427","0.00172"
"396.18200","33.01536","0.00162"
"396.55400","33.04633","0.00165"
"396.92600","33.07736","0.00164"
"397.29800","33.10833","0.00165"
"397.67000","33.13936","0.00146"
"398.04200","33.17039","0.00175"
"398.41400","33.20131","0.00150"
"398.78600","33.23234","0.00123"
"399.15800","33.26337","0.00147"
"399.53000","33.29422","0.00132"
"399.90200","33.32543","0.00150"
"400.27400","33.35640","0.00172"
"400.64600","33.38731","0.00179"
"401.01800","33.41834","0.00162"
"401.39000","33.44938","0.00140"
"401.76200","33.48028","0.00147"
"402.13400","33.51131","0.00145"
"402.50600","33.54240","0.00150"
"402.87800","33.57338","0.00151"
"403.25000","33.60429","0.00157"
"403.62200","33.63538","0.00174"
"403.99400","33.66635","0.00148"
"404.36600","33.69732","0.00131"
"404.73800","33.72835","0.00140"
"405.11000","33.75938","0.00160"
"405.48200","33.79029","0.00149"
"405.85400","33.82127","0.00183"
"406.22600","33.85241","0.00113"
"406.59800","33.88333","0.00158"
"406.97000","33.91430","0.00146"
"407.34200","33.94539","0.00143"
"407.71400","33.97636","0.00157"
"408.08600","34.00733","0.00153"
"408.45800","34.03836","0.00129"
"408.83000","34.06939","0.00134"
"409.20200","34.10030","0.00150"
"409.57400","34.13133","0.00158"
"409.94600","34.16236","0.00170"
"410.31800","34.19328","0.00173"
"410.69000","34.22437","0.00186"
"411.06200","34.25540","0.00159"
"411.43400","34.28631","0.00154"
"411.80600","34.31734","0.00167"
"412.17800","34.34831","0.00167"
"412.55000","34.37934","0.00154"
"412.92200","34.41031","0.00166"
"413.29400","34.44140","0.00166"
"413.66600","34.47237","0.00169"
"414.03800","34.50328","0.00134"
"414.41000","34.53431","0.00147"
"414.78200","34.56535","0.00118"
"415.15400","34.59632","0.00150"
"415.52600","34.62741","0.00165"
"415.89800","34.65832","0.00157"
"416.27000","34.68935","0.00157"
"416.64200","34.72032","0.00144"
"417.01400","34.75135","0.00144"
"417.38600","34.78238","0.00145"
"417.75800","34.81329","0.00156"
"418.13000","34.84432","0.00140"
"418.50200","34.87535","0.00150"
"418.87400","34.90632","0.00167"
"419.24600","34.93742","0.00175"
"419.61800","34.96833","0.00155"
"419.99000","34.99936","0.00177"
"420.36200","35.03033","0.00158"
"420.73400","35.06136","0.00172"
"421.10600","35.09233","0.00135"
"421.47800","35.12336","0.00122"
"421.85000","35.15439","0.00150"
"422.22200","35.18536","0.00164"
"422.59400","35.21634","0.00126"
"422.96600","35.24736","0.00160"
"423.33800","35.27834","0.00129"
"423.71000","35.30931","0.00165"
"424.08200","35.34034","0.00160"
"424.45400","35.37143","0.00163"
"424.82600","35.40222","0.00149"
"425.19800","35.43337","0.00128"
"425.57000","35.46440","0.00161"
"425.94200","35.49531","0.00142"
"426.31400","35.52634","0.00147"
"426.68600","35.55737","0.00150"
"427.05800","35.58834","0.00157"
"427.43000","35.61932","0.00137"
"427.80200","35.65041","0.00162"
"428.17400","35.68138","0.00151"
"428.54600","35.71229","0.00164"
"428.91800","35.74332","0.00143"
"429.29000","35.77441","0.00139"
"429.66200","35.80526","0.00147"
"430.03400","35.83635","0.00155"
"430.40600","35.86738","0.00145"
"430.77800","35.89835","0.00144"
"431.15000","35.92932","0.00170"
"431.52200","35.96035","0.00134"
"431.89400","35.99139","0.00165"
"432.26600","36.02230","0.00163"
"432.63800","36.05339","0.00138"
"433.01000","36.08436","0.00173"
"433.38200","36.11533","0.00132"
"433.75400","36.14636","0.00187"
"434.12600","36.17739","0.00164"
"434.49800","36.20830","0.00140"
"434.87000","36.23933","0.00160"
"435.24200","36.27037","0.00164"
"435.61400","36.30133","0.00147"
"435.98600","36.33231","0.00140"
"436.35800","36.36340","0.00158"
"436.73000","36.39437","0.00153"
"437.10200","36.42528","0.00143"
"437.47400","36.45637","0.00118"
"437.84600","36.48734","0.00182"
"438.21800","36.51831","0.00126"
"438.59000","36.54934","0.00165"
"438.96200","36.58037","0.00161"
"439.33400","36.61129","0.00158"
"439.70600","36.64231","0.00163"
"440.07800","36.67340","0.00153"
"440.45000","36.70432","0.00151"
"440.82200","36.73535","0.00145"
"441.19400","36.76638","0.00169"
"441.56600","36.79735","0.00138"
"441.93800","36.82832","0.00168"
"442.31000","36.85935","0.00161"
"442.68200","36.89038","0.00138"
"443.05400","36.92135","0.00164"
"443.42600","36.95238","0.00160"
"443.79800","36.98335","0.00169"
"444.17000","37.01426","0.00157"
"444.54200","37.04536","0.00161"
"444.91400","37.07633","0.00162"
"445.28600","37.10730","0.00146"
"445.65800","37.13833","0.00164"
"446.03000","37.16930","0.00123"
"446.40200","37.20033","0.00161"
"446.77400","37.23136","0.00137"
"447.14600","37.26239","0.00147"
"447.51800","37.29336","0.00190"
"447.89000","37.32427","0.00165"
"448.26200","37.35536","0.00162"
"448.63400","37.38634","0.00149"
"449.00600","37.41737","0.00143"
"449.37800","37.44840","0.00148"
"449.75000","37.47937","0.00135"
"450.12200","37.51034","0.00161"
"450.49400","37.54131","0.00138"
"450.86600","37.57234","0.00146"
"451.23800","37.60331","0.00149"
"451.61000","37.63434","0.00174"
"451.98200","37.66537","0.00158"
"452.35400","37.69628","0.00172"
"452.72600","37.72731","0.00155"
"453.09800","37.75841","0.00173"
"453.47000","37.78938","0.00147"
"453.84200","37.82035","0.00147"
"454.21400","37.85132","0.00175"
"454.58600","37.88235","0.00170"
"454.95800","37.91326","0.00177"
"455.33000","37.94435","0.00158"
"455.70200","37.97544","0.00149"
"456.07400","38.00629","0.00160"
"456.44600","38.03738","0.00181"
"456.81800","38.06836","0.00156"
"457.19000","38.09933","0.00171"
"457.56200","38.13036","0.00188"
"457.93400","38.16138","0.00187"
"458.30600","38.19236","0.00169"
"458.67800","38.22327","0.00144"
"459.05000","38.25436","0.00150"
"459.42200","38.28539","0.00138"
"459.79400","38.31630","0.00136"
"460.16600","38.34739","0.00188"
"460.53800","38.37836","0.00143"
"460.91000","38.40933","0.00160"
"461.28200","38.44031","0.00144"
"461.65400","38.47134","0.00157"
"462.02600","38.50237","0.00166"
"462.39800","38.53334","0.00166"
"462.77000","38.56437","0.00142"
"463.14200","38.59534","0.00174"
"463.51400","38.62625","0.00165"
"463.88600","38.65740","0.00143"
"464.25800","38.68837","0.00166"
"464.63000","38.71935","0.00165"
"465.00200","38.75031","0.00158"
"465.37400","38.78140","0.00158"
"465.74600","38.81232","0.00171"
"466.11800","38.84335","0.00191"
"466.49000","38.87438","0.00152"
"466.86200","38.90535","0.00166"
"467.23400","38.93632","0.00185"
"467.60600","38.96735","0.00157"
"467.97800","38.99832","0.00156"
"468.35000","39.02935","0.00146"
"468.72200","39.06033","0.00155"
"469.09400","39.09135","0.00147"
"469.46600","39.12233","0.00135"
"469.83800","39.15335","0.00189"
"470.21000","39.18433","0.00151"
"470.58200","39.21535","0.00164"
"470.95400","39.24633","0.00166"
"471.32600","39.27736","0.00186"
"471.69800","39.30833","0.00190"
"472.07000","39.33936","0.00166"
"472.44200","39.37033","0.00182"
"472.81400","39.40130","0.00133"
"473.18600","39.43233","0.00153"
"473.55800","39.46336","0.00159"
"473.93000","39.49440","0.00169"
"474.30200","39.52531","0.00193"
"474.67400","39.55633","0.00192"
"475.04600","39.58736","0.00172"
"475.41800","39.61834","0.00166"
"475.79000","39.64937","0.00174"
"476.16200","39.68034","0.00169"
"476.53400","39.71131","0.00158"
"476.90600","39.74228","0.00171"
"477.27800","39.77338","0.00173"
"477.65000","39.80434","0.00146"
"478.02200","39.83537","0.00193"
"478.39400","39.86640","0.00151"
"478.76600","39.89732","0.00216"
"479.13800","39.92829","0.00186"
"479.51000","39.95938","0.00155"
"479.88200","39.99035","0.00184"
"480.25400","40.02132","0.00162"
"480.62600","40.05235","0.00190"
"480.99800","40.08332","0.00193"
"481.37000","40.11435","0.00153"
"481.74200","40.14538","0.00177"
"482.11400","40.17641","0.00172"
"482.48600","40.20732","0.00196"
"482.85800","40.23830","0.00174"
"483.23000","40.26933","0.00198"
"483.60200","40.30036","0.00189"
"483.97400","40.33133","0.00191"
"484.34600","40.36236","0.00178"
"484.71800","40.39339","0.00181"
"485.09000","40.42430","0.00162"
"485.46200","40.45533","0.00180"
"485.83400","40.48636","0.00153"
"486.20600","40.51727","0.00163"
"486.57800","40.54837","0.00168"
"486.95000","40.57940","0.00161"
"487.32200","40.61031","0.00145"
"487.69400","40.64134","0.00147"
"488.06600","40.67237","0.00172"
"488.43800","40.70334","0.00192"
"488.81000","40.73425","0.00179"
"489.18200","40.76534","0.00187"
"489.55400","40.79637","0.00152"
"489.92600","40.82728","0.00150"
"490.29800","40.85837","0.00170"
"490.67000","40.88934","0.00170"
"491.04200","40.92032","0.00191"
"491.41400","40.95134","0.00175"
"491.78600","40.98232","0.00176"
"492.15800","41.01340","0.00162"
"492.53000","41.04432","0.00176"
"492.90200","41.07535","0.00194"
"493.27400","41.10638","0.00189"
"493.64600","41.13729","0.00180"
"494.01800","41.16845","0.00164"
"494.39000","41.19941","0.00181"
"494.76200","41.23027","0.00178"
"495.13400","41.26136","0.00156"
"495.50600","41.29239","0.00161"
"495.87800","41.32336","0.00188"
"496.25000","41.35433","0.00209"
"496.62200","41.38536","0.00177"
"496.99400","41.41633","0.00154"
"497.36600","41.44736","0.00201"
"497.73800","41.47839","0.00140"
"498.11000","41.50937","0.00135"
"498.48200","41.54033","0.00156"
"498.85400","41.57137","0.00161"
"499.22600","41.60239","0.00174"
"499.59800","41.63331","0.00141"
"499.97000","41.66434","0.00196"
"500.34200","41.69543","0.00140"
"500.71400","41.72634","0.00179"
"501.08600","41.75731","0.00135"
"501.45800","41.78834","0.00167"
"501.83000","41.81931","0.00151"
"502.20200","41.85028","0.00160"
"502.57400","41.88137","0.00146"
"502.94600","41.91234","0.00151"
"503.31800","41.94331","0.00159"
"503.69000","41.97441","0.00145"
"504.06200","42.00537","0.00167"
"504.43400","42.03629","0.00136"
"504.80600","42.06738","0.00169"
"505.17800","42.09835","0.00152"
"505.55000","42.12931","0.00172"
"505.92200","42.16035","0.00164"
"506.29400","42.19132","0.00174"
"506.66600","42.22235","0.00162"
"507.03800","42.25332","0.00155"
"507.41000","42.28436","0.00169"
"507.78200","42.31533","0.00148"
"508.15400","42.34629","0.00157"
"508.52600","42.37732","0.00178"
"508.89800","42.40830","0.00161"
"509.27000","42.43933","0.00183"
"509.64200","42.47036","0.00191"
"510.01400","42.50139","0.00145"
"510.38600","42.53230","0.00142"
"510.75800","42.56334","0.00163"
"511.13000","42.59436","0.00141"
"511.50200","42.62534","0.00161"
"511.87400","42.65631","0.00151"
"512.24600","42.68740","0.00160"
"512.61800","42.71831","0.00146"
"512.99000","42.74928","0.00155"
"513.36200","42.78037","0.00148"
"513.73400","42.81134","0.00137"
"514.10600","42.84225","0.00130"
"514.47800","42.87340","0.00150"
"514.85000","42.90431","0.00122"
"515.22200","42.93528","0.00154"
"515.59400","42.96637","0.00146"
"515.96600","42.99741","0.00143"
"516.33800","43.02826","0.00141"
"516.71000","43.05935","0.00149"
"517.08200","43.09032","0.00139"
"517.45400","43.12128","0.00110"
"517.82600","43.15231","0.00144"
"518.19800","43.18335","0.00116"
"518.57000","43.21438","0.00149"
"518.94200","43.24529","0.00128"
"519.31400","43.27632","0.00160"
"519.68600","43.30735","0.00118"
"520.05800","43.33832","0.00123"
"520.43000","43.36942","0.00120"
"520.80200","43.40033","0.00130"
"521.17400","43.43136","0.00146"
"521.54600","43.46233","0.00134"
"521.91800","43.49336","0.00144"
"522.29000","43.52439","0.00121"
"522.66200","43.55530","0.00133"
"523.03400","43.58639","0.00122"
"523.40600","43.61736","0.00146"
"523.77800","43.64833","0.00140"
"524.15000","43.67936","0.00131"
"524.52200","43.71040","0.00121"
"524.89400","43.74136","0.00136"
"525.26600","43.77233","0.00153"
"525.63800","43.80336","0.00124"
"526.01000","43.83434","0.00131"
"526.38200","43.86531","0.00158"
"526.75400","43.89634","0.00164"
"527.12600","43.92731","0.00145"
"527.49800","43.95834","0.00140"
"527.87000","43.98937","0.00149"
"528.24200","44.02034","0.00115"
"528.61400","44.05132","0.00117"
"528.98600","44.08235","0.00138"
"529.35800","44.11338","0.00157"
"529.73000","44.14428","0.00101"
"530.10200","44.17532","0.00091"
"530.47400","44.20635","0.00146"
"530.84600","44.23732","0.00102"
"531.21800","44.26835","0.00110"
"531.59000","44.29938","0.00112"
"531.96200","44.33029","0.00125"
"532.33400","44.36132","0.00106"
"532.70600","44.39235","0.00101"
"533.07800","44.42333","0.00113"
"533.45000","44.45435","0.00112"
"533.82200","44.48539","0.00130"
"534.19400","44.51636","0.00098"
"534.56600","44.54733","0.00105"
"534.93800","44.57835","0.00113"
"535.31000","44.60933","0.00120"
"535.68200","44.64030","0.00131"
"536.05400","44.67139","0.00127"
"536.42600","44.70236","0.00099"
"536.79800","44.73333","0.00120"
"537.17000","44.76430","0.00099"
"537.54200","44.79539","0.00130"
"537.91400","44.82637","0.00101"
"538.28600","44.85734","0.00110"
"538.65800","44.88837","0.00108"
"539.03000","44.91933","0.00112"
"539.40200","44.95031","0.00120"
"539.77400","44.98140","0.00114"
"540.14600","45.01237","0.00134"
"540.51800","45.04334","0.00108"
"540.89000","45.07431","0.00119"
"541.26200","45.10540","0.00136"
"541.63400","45.13631","0.00128"
"542.00600","45.16734","0.00122"
"542.37800","45.19837","0.00122"
"542.75000","45.22935","0.00133"
"543.12200","45.26032","0.00117"
"543.49400","45.29141","0.00084"
"543.86600","45.32238","0.00106"
"544.23800","45.35329","0.00106"
"544.61000","45.38438","0.00103"
"544.98200","45.41541","0.00099"
"545.35400","45.44627","0.00114"
"545.72600","45.47736","0.00104"
"546.09800","45.50838","0.00095"
"546.47000","45.53930","0.00131"
"546.84200","45.57039","0.00099"
"547.21400","45.60130","0.00106"
"547.58600","45.63233","0.00118"
"547.95800","45.66330","0.00107"
"548.33000","45.69439","0.00119"
"548.70200","45.72536","0.00105"
"549.07400","45.75633","0.00094"
"549.44600","45.78736","0.00100"
"549.81800","45.81834","0.00097"
"550.19000","45.84930","0.00091"
"550.56200","45.88034","0.00113"
"550.93400","45.91137","0.00117"
"551.30600","45.94234","0.00098"
"551.67800","45.97331","0.00098"
"552.05000","46.00434","0.00090"
"552.42200","46.03531","0.00138"
"552.79400","46.06622","0.00103"
"553.16600","46.09743","0.00117"
"553.53800","46.12840","0.00090"
"553.91000","46.15926","0.00130"
"554.28200","46.19040","0.00091"
"554.65400","46.22137","0.00080"
"555.02600","46.25229","0.00093"
"555.39800","46.28332","0.00094"
"555.50000","46.29187","0.00117"