File: Force_trajectories/161217/Specimen_RawData_7.csv
End date,"12/17/2016"
Specimen label,"15CG_21_run2"
Maximum Load,"0.15933",N

Time,Extension,Load
(s),(mm),(N)
"0.00000","0.00000","-0.00016"
"0.45000","0.03779","0.00024"
"0.90000","0.07522","0.00059"
"1.35000","0.11270","0.00063"
"1.80000","0.15019","0.00077"
"2.25000","0.18774","0.00054"
"2.70000","0.22517","0.00105"
"3.15000","0.26266","0.00103"
"3.60000","0.30020","0.00124"
"4.05000","0.33769","0.00106"
"4.50000","0.37518","0.00136"
"4.95000","0.41261","0.00137"
"5.40000","0.45010","0.00152"
"5.85000","0.48764","0.00181"
"6.30000","0.52519","0.00152"
"6.75000","0.56268","0.00197"
"7.20000","0.60017","0.00176"
"7.65000","0.63766","0.00202"
"8.10000","0.67508","0.00243"
"8.55000","0.71263","0.00166"
"9.00000","0.75018","0.00220"
"9.45000","0.78767","0.00214"
"9.90000","0.82522","0.00201"
"10.35000","0.86264","0.00183"
"10.80000","0.90013","0.00222"
"11.25000","0.93762","0.00236"
"11.70000","0.97517","0.00248"
"12.15000","1.01266","0.00110"
"12.60000","1.05020","0.00074"
"13.05000","1.08763","0.00111"
"13.50000","1.12512","0.00036"
"13.95000","1.16261","0.00035"
"14.40000","1.20016","0.00057"
"14.85000","1.23764","0.00038"
"15.30000","1.27519","0.00053"
"15.75000","1.31268","0.00062"
"16.20000","1.35011","0.00068"
"16.65000","1.38766","0.00062"
"17.10000","1.42520","0.00090"
"17.55000","1.46269","0.00069"
"18.00000","1.50018","0.00101"
"18.45000","1.53767","0.00084"
"18.90000","1.57516","0.00075"
"19.35000","1.61264","0.00096"
"19.80000","1.65007","0.00147"
"20.25000","1.68768","0.00124"
"20.70000","1.72517","0.00118"
"21.15000","1.76271","0.00081"
"21.60000","1.80014","0.00122"
"22.05000","1.83763","0.00102"
"22.50000","1.87512","0.00157"
"22.95000","1.91267","0.00136"
"23.40000","1.95016","0.00160"
"23.85000","1.98764","0.00126"
"24.30000","2.02513","0.00135"
"24.75000","2.06262","0.00154"
"25.20000","2.10017","0.00120"
"25.65000","2.13766","0.00144"
"26.10000","2.17520","0.00144"
"26.55000","2.21269","0.00168"
"27.00000","2.25012","0.00141"
"27.45000","2.28761","0.00141"
"27.90000","2.32516","0.00163"
"28.35000","2.36264","0.00188"
"28.80000","2.40013","0.00214"
"29.25000","2.43768","0.00178"
"29.70000","2.47517","0.00179"
"30.15000","2.51266","0.00180"
"30.60000","2.55014","0.00153"
"31.05000","2.58769","0.00219"
"31.50000","2.62524","0.00207"
"31.95000","2.66273","0.00189"
"32.40000","2.70016","0.00199"
"32.85000","2.73758","0.00211"
"33.30000","2.77513","0.00191"
"33.75000","2.81268","0.00201"
"34.20000","2.85017","0.00213"
"34.65000","2.88766","0.00196"
"35.10000","2.92520","0.00179"
"35.55000","2.96269","0.00194"
"36.00000","3.00012","0.00218"
"36.45000","3.03767","0.00220"
"36.90000","3.07516","0.00205"
"37.35000","3.11264","0.00183"
"37.80000","3.15013","0.00252"
"38.25000","3.18762","0.00217"
"38.70000","3.22517","0.00229"
"39.15000","3.26271","0.00233"
"39.60000","3.30014","0.00210"
"40.05000","3.33769","0.00231"
"40.50000","3.37512","0.00200"
"40.95000","3.41261","0.00230"
"41.40000","3.45016","0.00239"
"41.85000","3.48764","0.00223"
"42.30000","3.52519","0.00248"
"42.75000","3.56268","0.00214"
"43.20000","3.60011","0.00268"
"43.65000","3.63760","0.00271"
"44.10000","3.67514","0.00261"
"44.55000","3.71269","0.00254"
"45.00000","3.75018","0.00225"
"45.45000","3.78767","0.00236"
"45.90000","3.82515","0.00233"
"46.35000","3.86258","0.00260"
"46.80000","3.90013","0.00241"
"47.25000","3.93768","0.00261"
"47.70000","3.97517","0.00279"
"48.15000","4.01271","0.00269"
"48.60000","4.05020","0.00306"
"49.05000","4.08763","0.00294"
"49.50000","4.12512","0.00246"
"49.95000","4.16267","0.00290"
"50.40000","4.20021","0.00283"
"50.85000","4.23764","0.00274"
"51.30000","4.27513","0.00271"
"51.75000","4.31262","0.00275"
"52.20000","4.35017","0.00283"
"52.65000","4.38765","0.00315"
"53.10000","4.42520","0.00303"
"53.55000","4.46269","0.00303"
"54.00000","4.50012","0.00271"
"54.45000","4.53767","0.00298"
"54.90000","4.57510","0.00268"
"55.35000","4.61264","0.00287"
"55.80000","4.65019","0.00310"
"56.25000","4.68768","0.00333"
"56.70000","4.72523","0.00317"
"57.15000","4.76265","0.00293"
"57.60000","4.80014","0.00330"
"58.05000","4.83763","0.00319"
"58.50000","4.87518","0.00269"
"58.95000","4.91273","0.00287"
"59.40000","4.95021","0.00287"
"59.85000","4.98758","0.00229"
"60.30000","5.02507","0.00177"
"60.75000","5.06262","0.00238"
"61.20000","5.10017","0.00152"
"61.65000","5.13771","0.00138"
"62.10000","5.17520","0.00150"
"62.55000","5.21263","0.00123"
"63.00000","5.25012","0.00152"
"63.45000","5.28761","0.00133"
"63.90000","5.32515","0.00158"
"64.35000","5.36264","0.00162"
"64.80000","5.40019","0.00169"
"65.25000","5.43768","0.00183"
"65.70000","5.47511","0.00125"
"66.15000","5.51265","0.00153"
"66.60000","5.55014","0.00164"
"67.05000","5.58769","0.00166"
"67.50000","5.62518","0.00159"
"67.95000","5.66267","0.00122"
"68.40000","5.70015","0.00126"
"68.85000","5.73758","0.00154"
"69.30000","5.77513","0.00135"
"69.75000","5.81268","0.00155"
"70.20000","5.85023","0.00143"
"70.65000","5.88765","0.00155"
"71.10000","5.92514","0.00166"
"71.55000","5.96263","0.00147"
"72.00000","6.00024","0.00139"
"72.45000","6.03767","0.00114"
"72.90000","6.07515","0.00126"
"73.35000","6.11264","0.00153"
"73.80000","6.15013","0.00044"
"74.25000","6.18762","0.00077"
"74.70000","6.22517","0.00125"
"75.15000","6.26271","0.00041"
"75.60000","6.30014","0.00027"
"76.05000","6.33769","0.00062"
"76.50000","6.37512","0.00055"
"76.95000","6.41261","0.00055"
"77.40000","6.45015","0.00077"
"77.85000","6.48764","0.00080"
"78.30000","6.52519","0.00103"
"78.75000","6.56268","0.00083"
"79.20000","6.60011","0.00119"
"79.65000","6.63759","0.00107"
"80.10000","6.67514","0.00063"
"80.55000","6.71263","0.00125"
"81.00000","6.75018","0.00113"
"81.45000","6.78767","0.00140"
"81.90000","6.82516","0.00136"
"82.35000","6.86258","0.00102"
"82.80000","6.90019","0.00127"
"83.25000","6.93768","0.00117"
"83.70000","6.97517","0.00121"
"84.15000","7.01265","0.00150"
"84.60000","7.05014","0.00128"
"85.05000","7.08763","0.00145"
"85.50000","7.12512","0.00134"
"85.95000","7.16267","0.00180"
"86.40000","7.20015","0.00175"
"86.85000","7.23764","0.00178"
"87.30000","7.27513","0.00137"
"87.75000","7.31268","0.00180"
"88.20000","7.35017","0.00195"
"88.65000","7.38765","0.00175"
"89.10000","7.42520","0.00201"
"89.55000","7.46269","0.00215"
"90.00000","7.50018","0.00226"
"90.45000","7.53761","0.00129"
"90.90000","7.57515","0.00125"
"91.35000","7.61270","0.00169"
"91.80000","7.65019","0.00170"
"92.25000","7.68774","0.00193"
"92.70000","7.72511","0.00168"
"93.15000","7.76259","0.00173"
"93.60000","7.80014","0.00198"
"94.05000","7.83763","0.00223"
"94.50000","7.87518","0.00180"
"94.95000","7.91267","0.00220"
"95.40000","7.95015","0.00238"
"95.85000","7.98764","0.00192"
"96.30000","8.02513","0.00217"
"96.75000","8.06262","0.00253"
"97.20000","8.10017","0.00255"
"97.65000","8.13771","0.00225"
"98.10000","8.17520","0.00248"
"98.55000","8.21263","0.00241"
"99.00000","8.25012","0.00270"
"99.45000","8.28761","0.00257"
"99.90000","8.32515","0.00210"
"100.35000","8.36264","0.00219"
"100.80000","8.40013","0.00223"
"101.25000","8.43762","0.00219"
"101.70000","8.47511","0.00199"
"102.15000","8.51265","0.00239"
"102.60000","8.55020","0.00281"
"103.05000","8.58763","0.00225"
"103.50000","8.62518","0.00451"
"103.95000","8.66261","0.00344"
"104.40000","8.70015","0.00280"
"104.85000","8.73770","0.00262"
"105.30000","8.77513","0.00252"
"105.75000","8.81268","0.00188"
"106.20000","8.85017","0.00193"
"106.65000","8.88765","0.00232"
"107.10000","8.92508","0.00302"
"107.55000","8.96263","0.00283"
"108.00000","9.00018","0.00289"
"108.45000","9.03773","0.00292"
"108.90000","9.07521","0.00344"
"109.35000","9.11264","0.00380"
"109.80000","9.15007","0.00332"
"110.25000","9.18762","0.00352"
"110.70000","9.22517","0.00392"
"111.15000","9.26271","0.00423"
"111.60000","9.30020","0.00395"
"112.05000","9.33763","0.00434"
"112.50000","9.37512","0.00416"
"112.95000","9.41261","0.00426"
"113.40000","9.45015","0.00401"
"113.85000","9.48764","0.00441"
"114.30000","9.52513","0.00498"
"114.75000","9.56268","0.00442"
"115.20000","9.60011","0.00516"
"115.65000","9.63765","0.00520"
"116.10000","9.67514","0.00521"
"116.55000","9.71269","0.00587"
"117.00000","9.75018","0.00511"
"117.45000","9.78767","0.00588"
"117.90000","9.82515","0.00562"
"118.35000","9.86264","0.00586"
"118.80000","9.90013","0.00598"
"119.25000","9.93768","0.00629"
"119.70000","9.97517","0.00623"
"120.15000","10.01265","0.00604"
"120.60000","10.05008","0.00636"
"121.05000","10.08769","0.00620"
"121.50000","10.12518","0.00702"
"121.95000","10.16267","0.00680"
"122.40000","10.20015","0.00665"
"122.85000","10.23770","0.00715"
"123.30000","10.27513","0.00743"
"123.75000","10.31262","0.00732"
"124.20000","10.35017","0.00800"
"124.65000","10.38765","0.00839"
"125.10000","10.42514","0.00849"
"125.55000","10.46269","0.00851"
"126.00000","10.50006","0.00882"
"126.45000","10.53767","0.00871"
"126.90000","10.57509","0.00804"
"127.35000","10.61270","0.00852"
"127.80000","10.65019","0.00893"
"128.25000","10.68768","0.00902"
"128.70000","10.72511","0.00937"
"129.15000","10.76259","0.00914"
"129.60000","10.80014","0.01015"
"130.05000","10.83763","0.00960"
"130.50000","10.87518","0.01030"
"130.95000","10.91267","0.01040"
"131.40000","10.95015","0.01107"
"131.85000","10.98764","0.01096"
"132.30000","11.02513","0.01128"
"132.75000","11.06268","0.01157"
"133.20000","11.10017","0.01149"
"133.65000","11.13771","0.01162"
"134.10000","11.17514","0.01224"
"134.55000","11.21257","0.01219"
"135.00000","11.25012","0.01260"
"135.45000","11.28767","0.01278"
"135.90000","11.32515","0.01285"
"136.35000","11.36264","0.01352"
"136.80000","11.40013","0.01350"
"137.25000","11.43762","0.01427"
"137.70000","11.47511","0.01403"
"138.15000","11.51265","0.01500"
"138.60000","11.55014","0.01540"
"139.05000","11.58775","0.01619"
"139.50000","11.62512","0.01582"
"139.95000","11.66261","0.01677"
"140.40000","11.70015","0.01679"
"140.85000","11.73770","0.01674"
"141.30000","11.77519","0.01768"
"141.75000","11.81268","0.01744"
"142.20000","11.85017","0.01762"
"142.65000","11.88765","0.01831"
"143.10000","11.92514","0.01829"
"143.55000","11.96263","0.01854"
"144.00000","12.00018","0.01906"
"144.45000","12.03773","0.01961"
"144.90000","12.07515","0.01973"
"145.35000","12.11264","0.02021"
"145.80000","12.15019","0.02027"
"146.25000","12.18774","0.02069"
"146.70000","12.22517","0.02192"
"147.15000","12.26271","0.02219"
"147.60000","12.30014","0.02198"
"148.05000","12.33763","0.02290"
"148.50000","12.37512","0.02189"
"148.95000","12.41261","0.02245"
"149.40000","12.45015","0.02341"
"149.85000","12.48770","0.02454"
"150.30000","12.52513","0.02505"
"150.75000","12.56262","0.02503"
"151.20000","12.60017","0.02574"
"151.65000","12.63765","0.02645"
"152.10000","12.67520","0.02559"
"152.55000","12.71263","0.02590"
"153.00000","12.75012","0.02663"
"153.45000","12.78767","0.02727"
"153.90000","12.82515","0.02812"
"154.35000","12.86270","0.02727"
"154.80000","12.90019","0.02634"
"155.25000","12.93768","0.02773"
"155.70000","12.97517","0.02836"
"156.15000","13.01259","0.02913"
"156.60000","13.05014","0.02777"
"157.05000","13.08763","0.02880"
"157.50000","13.12518","0.02944"
"157.95000","13.16267","0.02982"
"158.40000","13.20021","0.02771"
"158.85000","13.23764","0.02804"
"159.30000","13.27513","0.02924"
"159.75000","13.31262","0.03039"
"160.20000","13.35017","0.03039"
"160.65000","13.38771","0.03162"
"161.10000","13.42520","0.03151"
"161.55000","13.46263","0.03091"
"162.00000","13.50012","0.03168"
"162.45000","13.53767","0.03233"
"162.90000","13.57521","0.03191"
"163.35000","13.61264","0.03305"
"163.80000","13.65019","0.03348"
"164.25000","13.68768","0.03485"
"164.70000","13.72517","0.03460"
"165.15000","13.76259","0.03543"
"165.60000","13.80014","0.03321"
"166.05000","13.83763","0.03159"
"166.50000","13.87518","0.03055"
"166.95000","13.91267","0.03068"
"167.40000","13.95009","0.03202"
"167.85000","13.98764","0.03386"
"168.30000","14.02519","0.03460"
"168.75000","14.06268","0.03558"
"169.20000","14.10023","0.03535"
"169.65000","14.13759","0.03613"
"170.10000","14.17508","0.03536"
"170.55000","14.21263","0.03462"
"171.00000","14.25018","0.03554"
"171.45000","14.28773","0.03607"
"171.90000","14.32515","0.03721"
"172.35000","14.36264","0.03786"
"172.80000","14.40007","0.03856"
"173.25000","14.43762","0.03871"
"173.70000","14.47517","0.03928"
"174.15000","14.51265","0.03898"
"174.60000","14.55014","0.03895"
"175.05000","14.58763","0.03994"
"175.50000","14.62512","0.04034"
"175.95000","14.66261","0.04042"
"176.40000","14.70009","0.04090"
"176.85000","14.73770","0.04073"
"177.30000","14.77525","0.04111"
"177.75000","14.81268","0.04149"
"178.20000","14.85011","0.04194"
"178.65000","14.88765","0.04206"
"179.10000","14.92514","0.04297"
"179.55000","14.96269","0.04440"
"180.00000","15.00012","0.04460"
"180.45000","15.03767","0.04511"
"180.90000","15.07515","0.04590"
"181.35000","15.11264","0.04661"
"181.80000","15.15019","0.04779"
"182.25000","15.18768","0.03172"
"182.70000","15.22517","0.03068"
"183.15000","15.26265","0.03397"
"183.60000","15.30014","0.03596"
"184.05000","15.33763","0.03696"
"184.50000","15.37518","0.03828"
"184.95000","15.41267","0.03806"
"185.40000","15.45015","0.03780"
"185.85000","15.48770","0.03813"
"186.30000","15.52513","0.03909"
"186.75000","15.56262","0.03968"
"187.20000","15.60017","0.04068"
"187.65000","15.63765","0.04169"
"188.10000","15.67520","0.04253"
"188.55000","15.71263","0.04198"
"189.00000","15.75012","0.04093"
"189.45000","15.78755","0.04180"
"189.90000","15.82515","0.04256"
"190.35000","15.86270","0.04413"
"190.80000","15.90025","0.04455"
"191.25000","15.93768","0.04429"
"191.70000","15.97510","0.04438"
"192.15000","16.01265","0.04562"
"192.60000","16.05008","0.04653"
"193.05000","16.08763","0.04797"
"193.50000","16.12518","0.04895"
"193.95000","16.16273","0.05035"
"194.40000","16.20015","0.05066"
"194.85000","16.23758","0.05133"
"195.30000","16.27513","0.04935"
"195.75000","16.31262","0.05057"
"196.20000","16.35016","0.05232"
"196.65000","16.38765","0.05371"
"197.10000","16.42514","0.05481"
"197.55000","16.46263","0.05247"
"198.00000","16.50012","0.05385"
"198.45000","16.53766","0.05446"
"198.90000","16.57515","0.05200"
"199.35000","16.61264","0.04984"
"199.80000","16.65019","0.05269"
"200.25000","16.68762","0.05560"
"200.70000","16.72517","0.05752"
"201.15000","16.76271","0.05845"
"201.60000","16.80020","0.06015"
"202.05000","16.83769","0.06214"
"202.50000","16.87518","0.06472"
"202.95000","16.91261","0.06599"
"203.40000","16.95009","0.06735"
"203.85000","16.98770","0.06937"
"204.30000","17.02519","0.07092"
"204.75000","17.06268","0.07330"
"205.20000","17.10016","0.07392"
"205.65000","17.13765","0.07603"
"206.10000","17.17508","0.07566"
"206.55000","17.21263","0.07763"
"207.00000","17.25018","0.07913"
"207.45000","17.28773","0.07968"
"207.90000","17.32515","0.08051"
"208.35000","17.36264","0.08191"
"208.80000","17.40013","0.08341"
"209.25000","17.43762","0.08345"
"209.70000","17.47517","0.08500"
"210.15000","17.51265","0.08564"
"210.60000","17.55020","0.08630"
"211.05000","17.58763","0.08734"
"211.50000","17.62512","0.08786"
"211.95000","17.66266","0.08868"
"212.40000","17.70015","0.08933"
"212.85000","17.73770","0.09010"
"213.30000","17.77519","0.09063"
"213.75000","17.81268","0.09148"
"214.20000","17.85011","0.09191"
"214.65000","17.88759","0.09274"
"215.10000","17.92514","0.09257"
"215.55000","17.96263","0.09342"
"216.00000","18.00018","0.09513"
"216.45000","18.03761","0.09593"
"216.90000","18.07515","0.09816"
"217.35000","18.11264","0.09932"
"217.80000","18.15013","0.10069"
"218.25000","18.18768","0.10133"
"218.70000","18.22516","0.10159"
"219.15000","18.26265","0.10284"
"219.60000","18.30008","0.10461"
"220.05000","18.33763","0.10787"
"220.50000","18.37524","0.11121"
"220.95000","18.41272","0.11397"
"221.40000","18.45021","0.11737"
"221.85000","18.48764","0.12064"
"222.30000","18.52513","0.12272"
"222.75000","18.56262","0.12572"
"223.20000","18.60017","0.12990"
"223.65000","18.63771","0.13001"
"224.10000","18.67520","0.12194"
"224.55000","18.71269","0.11996"
"225.00000","18.75012","0.12488"
"225.45000","18.78766","0.12938"
"225.90000","18.82515","0.13209"
"226.35000","18.86270","0.13403"
"226.80000","18.90019","0.13671"
"227.25000","18.93768","0.13904"
"227.70000","18.97511","0.14165"
"228.15000","19.01259","0.14356"
"228.60000","19.05014","0.14404"
"229.05000","19.08763","0.14556"
"229.50000","19.12518","0.14708"
"229.95000","19.16266","0.14653"
"230.40000","19.20015","0.14740"
"230.85000","19.23764","0.14816"
"231.30000","19.27519","0.14929"
"231.75000","19.31274","0.15027"
"232.20000","19.35011","0.15136"
"232.65000","19.38765","0.15295"
"233.10000","19.42514","0.15355"
"233.55000","19.46263","0.15403"
"234.00000","19.50018","0.15458"
"234.45000","19.53766","0.15651"
"234.90000","19.57515","0.15812"
"235.35000","19.61270","0.15761"
"235.80000","19.65019","0.01054"
"236.25000","19.68762","-0.00063"
"236.70000","19.72516","-0.00098"
"237.15000","19.76271","0.00186"
"237.60000","19.80020","0.00381"
"238.05000","19.83769","0.00476"
"238.50000","19.87511","0.00136"
"238.95000","19.91261","0.00267"
"239.40000","19.95009","0.00116"
"239.85000","19.98770","0.00260"
"240.30000","20.02519","0.00222"
"240.75000","20.06268","0.00107"
"241.20000","20.10016","0.00213"
"241.65000","20.13759","0.00273"
"242.10000","20.17508","0.00515"
"242.55000","20.21269","0.00305"
"243.00000","20.25018","0.00240"
"243.45000","20.28766","0.00114"
"243.90000","20.32515","0.00235"
"244.35000","20.36264","0.00339"
"244.80000","20.40013","0.00326"
"245.25000","20.43761","0.00417"
"245.70000","20.47517","0.00268"
"246.15000","20.51265","0.00418"
"246.60000","20.55014","0.00312"
"247.05000","20.58763","0.00493"
"247.50000","20.62512","0.00370"
"247.95000","20.66267","0.00304"
"248.40000","20.70021","0.00296"
"248.85000","20.73764","0.00387"
"249.30000","20.77513","0.00471"
"249.75000","20.81262","0.00455"
"250.20000","20.85016","0.00529"
"250.65000","20.88765","0.00386"
"251.10000","20.92520","0.00549"
"251.55000","20.96269","0.00482"
"252.00000","21.00018","0.00620"
"252.45000","21.03761","0.00576"
"252.90000","21.07509","0.00565"
"253.35000","21.11270","0.00521"
"253.80000","21.15019","0.00573"
"254.25000","21.18768","0.00650"
"254.70000","21.22517","0.00740"
"255.15000","21.26259","0.00675"
"255.60000","21.30014","0.00709"
"256.05000","21.33763","0.00698"
"256.50000","21.37518","0.00827"
"256.95000","21.41273","0.00853"
"257.40000","21.45015","0.00898"
"257.85000","21.48764","0.00886"
"258.30000","21.52513","0.00958"
"258.75000","21.56262","0.00904"
"259.20000","21.60011","0.00987"
"259.65000","21.63765","0.01092"
"260.10000","21.67514","0.01116"
"260.55000","21.71263","0.01149"
"261.00000","21.75012","0.01081"
"261.45000","21.78760","0.01098"
"261.90000","21.82515","0.01237"
"262.35000","21.86264","0.01293"
"262.80000","21.90019","0.01287"
"263.25000","21.93768","0.01333"
"263.70000","21.97511","0.01298"
"264.15000","22.01265","0.01362"
"264.60000","22.05014","0.01416"
"265.05000","22.08763","0.01481"
"265.50000","22.12518","0.01552"
"265.95000","22.16261","0.01601"
"266.40000","22.20009","0.01551"
"266.85000","22.23764","0.01647"
"267.30000","22.27513","0.01606"
"267.75000","22.31262","0.01705"
"268.20000","22.35023","0.01841"
"268.65000","22.38765","0.01882"
"269.10000","22.42508","0.01909"
"269.55000","22.46263","0.01904"
"270.00000","22.50018","0.01962"
"270.45000","22.53766","0.01952"
"270.90000","22.57521","0.01994"
"271.35000","22.61264","0.02017"
"271.80000","22.65013","0.02152"
"272.25000","22.68762","0.02179"
"272.70000","22.72516","0.02097"
"273.15000","22.76265","0.02243"
"273.60000","22.80020","0.02227"
"274.05000","22.83769","0.02100"
"274.50000","22.87512","0.02095"
"274.95000","22.91266","0.01963"
"275.40000","22.95021","0.01921"
"275.85000","22.98764","0.01937"
"276.30000","23.02519","0.02024"
"276.75000","23.06268","0.02042"
"277.20000","23.10016","0.02056"
"277.65000","23.13765","0.02189"
"278.10000","23.17508","0.02222"
"278.55000","23.21269","0.02082"
"279.00000","23.25018","0.01661"
"279.45000","23.28766","0.01780"
"279.90000","23.32515","0.01805"
"280.35000","23.36264","0.01924"
"280.80000","23.40019","0.01987"
"281.25000","23.43768","0.02062"
"281.70000","23.47516","0.02084"
"282.15000","23.51265","0.01857"
"282.60000","23.55014","0.01981"
"283.05000","23.58763","0.02020"
"283.50000","23.62518","0.01957"
"283.95000","23.66266","0.01882"
"284.40000","23.70015","0.01768"
"284.85000","23.73764","0.01736"
"285.30000","23.77513","0.01579"
"285.75000","23.81262","0.01677"
"286.20000","23.85016","0.01721"
"286.65000","23.88771","0.01747"
"287.10000","23.92514","0.01545"
"287.55000","23.96269","0.01596"
"288.00000","24.00018","0.01417"
"288.45000","24.03760","0.01434"
"288.90000","24.07515","0.01265"
"289.35000","24.11270","0.01273"
"289.80000","24.15019","0.01238"
"290.25000","24.18768","0.01285"
"290.70000","24.22511","0.01179"
"291.15000","24.26259","0.01227"
"291.60000","24.30014","0.01199"
"292.05000","24.33769","0.01231"
"292.50000","24.37518","0.01249"
"292.95000","24.41272","0.01260"
"293.40000","24.45021","0.01204"
"293.85000","24.48770","0.01271"
"294.30000","24.52513","0.01251"
"294.75000","24.56262","0.01200"
"295.20000","24.60016","0.01301"
"295.65000","24.63765","0.01301"
"296.10000","24.67514","0.01308"
"296.55000","24.71263","0.01343"
"297.00000","24.75012","0.01330"
"297.45000","24.78766","0.01261"
"297.90000","24.82515","0.01355"
"298.35000","24.86270","0.01387"
"298.80000","24.90007","0.01369"
"299.25000","24.93761","0.01370"
"299.70000","24.97517","0.01409"
"300.15000","25.01265","0.01443"
"300.60000","25.05020","0.01496"
"301.05000","25.08763","0.01435"
"301.50000","25.12512","0.01459"
"301.95000","25.16260","0.01473"
"302.40000","25.20015","0.01550"
"302.85000","25.23770","0.01517"
"303.30000","25.27519","0.01553"
"303.75000","25.31268","0.01528"
"304.20000","25.35016","0.01565"
"304.65000","25.38759","0.01604"
"305.10000","25.42514","0.01602"
"305.55000","25.46263","0.01582"
"306.00000","25.50018","0.01627"
"306.45000","25.53772","0.01604"
"306.90000","25.57521","0.01621"
"307.35000","25.61264","0.01609"
"307.80000","25.65013","0.01624"
"308.25000","25.68762","0.01656"
"308.70000","25.72516","0.01672"
"309.15000","25.76265","0.01646"
"309.60000","25.80020","0.01649"
"310.05000","25.83763","0.01678"
"310.50000","25.87512","0.01717"
"310.95000","25.91266","0.01736"
"311.40000","25.95021","0.01723"
"311.85000","25.98770","0.01804"
"312.30000","26.02519","0.01805"
"312.75000","26.06268","0.01851"
"313.20000","26.10010","0.01800"
"313.65000","26.13765","0.01878"
"314.10000","26.17520","0.01848"
"314.55000","26.21263","0.01870"
"315.00000","26.25018","0.01887"
"315.45000","26.28766","0.01903"
"315.90000","26.32515","0.01955"
"316.35000","26.36264","0.02011"
"316.80000","26.40013","0.01997"
"317.25000","26.43768","0.01930"
"317.70000","26.47516","0.01976"
"318.15000","26.51265","0.01946"
"318.60000","26.55008","0.02103"
"319.05000","26.58769","0.02011"
"319.50000","26.62518","0.02005"
"319.95000","26.66272","0.02065"
"320.40000","26.70021","0.02032"
"320.85000","26.73764","0.02101"
"321.30000","26.77513","0.02172"
"321.75000","26.81256","0.02103"
"322.20000","26.85016","0.02123"
"322.65000","26.88765","0.02149"
"323.10000","26.92520","0.02161"
"323.55000","26.96269","0.02211"
"324.00000","27.00012","0.02196"
"324.45000","27.03766","0.02193"
"324.90000","27.07515","0.02272"
"325.35000","27.11264","0.02286"
"325.80000","27.15019","0.02390"
"326.25000","27.18768","0.02481"
"326.70000","27.22510","0.02589"
"327.15000","27.26259","0.02646"
"327.60000","27.30014","0.02718"
"328.05000","27.33769","0.02691"
"328.50000","27.37518","0.02860"
"328.95000","27.41266","0.02906"
"329.40000","27.45015","0.02941"
"329.85000","27.48764","0.02921"
"330.30000","27.52519","0.03085"
"330.75000","27.56268","0.03034"
"331.20000","27.60016","0.03128"
"331.65000","27.63765","0.03183"
"332.10000","27.67514","0.03214"
"332.55000","27.71263","0.02652"
"333.00000","27.75018","0.02594"
"333.45000","27.78766","0.02698"
"333.90000","27.82515","0.02711"
"334.35000","27.86270","0.02755"
"334.80000","27.90013","0.02806"
"335.25000","27.93762","0.02737"
"335.70000","27.97516","0.02787"
"336.15000","28.01265","0.02872"
"336.60000","28.05020","0.02983"
"337.05000","28.08763","0.02945"
"337.50000","28.12511","0.03047"
"337.95000","28.16261","0.03049"
"338.40000","28.20009","0.03120"
"338.85000","28.23770","0.03223"
"339.30000","28.27519","0.03224"
"339.75000","28.31268","0.03242"
"340.20000","28.35016","0.03316"
"340.65000","28.38759","0.03266"
"341.10000","28.42514","0.03313"
"341.55000","28.46269","0.03305"
"342.00000","28.50018","0.03249"
"342.45000","28.53772","0.03395"
"342.90000","28.57515","0.03420"
"343.35000","28.61264","0.03447"
"343.80000","28.65013","0.03477"
"344.25000","28.68768","0.03541"
"344.70000","28.72516","0.03497"
"345.15000","28.76265","0.03376"
"345.60000","28.80020","0.03447"
"346.05000","28.83763","0.03478"
"346.50000","28.87512","0.03581"
"346.95000","28.91266","0.03563"
"347.40000","28.95015","0.03567"
"347.85000","28.98764","0.03521"
"348.30000","29.02519","0.03585"
"348.75000","29.06256","0.03559"
"349.20000","29.10011","0.03606"
"349.65000","29.13771","0.03572"
"350.10000","29.17520","0.03636"
"350.55000","29.21269","0.03573"
"351.00000","29.25011","0.03578"
"351.45000","29.28760","0.03587"
"351.90000","29.32509","0.03475"
"352.35000","29.36264","0.03524"
"352.80000","29.40019","0.03623"
"353.25000","29.43768","0.03576"
"353.70000","29.47517","0.03660"
"354.15000","29.51265","0.03491"
"354.60000","29.55014","0.03545"
"355.05000","29.58763","0.03560"
"355.50000","29.62518","0.03702"
"355.95000","29.66273","0.03711"
"356.40000","29.70021","0.03733"
"356.85000","29.73764","0.03777"
"357.30000","29.77513","0.03810"
"357.75000","29.81268","0.03809"
"358.20000","29.85016","0.03869"
"358.65000","29.88765","0.03913"
"359.10000","29.92514","0.03915"
"359.55000","29.96269","0.03925"
"360.00000","30.00012","0.03970"
"360.45000","30.03767","0.04036"
"360.90000","30.07521","0.04076"
"361.35000","30.11264","0.04109"
"361.80000","30.15019","0.04111"
"362.25000","30.18768","0.04143"
"362.70000","30.22516","0.04230"
"363.15000","30.26265","0.04289"
"363.60000","30.30008","0.04293"
"364.05000","30.33769","0.04356"
"364.50000","30.37518","0.04448"
"364.95000","30.41266","0.04480"
"365.40000","30.45009","0.04504"
"365.85000","30.48764","0.04592"
"366.30000","30.52519","0.04659"
"366.75000","30.56274","0.04730"
"367.20000","30.60017","0.04847"
"367.65000","30.63765","0.04901"
"368.10000","30.67508","0.05028"
"368.55000","30.71263","0.05135"
"369.00000","30.75024","0.05246"
"369.45000","30.78766","0.05345"
"369.90000","30.82515","0.05487"
"370.35000","30.86264","0.05594"
"370.80000","30.90013","0.05603"
"371.25000","30.93762","0.05708"
"371.70000","30.97516","0.05751"
"372.15000","31.01265","0.05960"
"372.60000","31.05020","0.06168"
"373.05000","31.08763","0.06178"
"373.50000","31.12512","0.06340"
"373.95000","31.16260","0.06396"
"374.40000","31.20009","0.06384"
"374.85000","31.23764","0.06527"
"375.30000","31.27519","0.06645"
"375.75000","31.31267","0.06811"
"376.20000","31.35016","0.06858"
"376.65000","31.38765","0.06999"
"377.10000","31.42514","0.07143"
"377.55000","31.46269","0.07231"
"378.00000","31.50012","0.07301"
"378.45000","31.53766","0.07428"
"378.90000","31.57515","0.07506"
"379.35000","31.61270","0.07578"
"379.80000","31.65018","0.07750"
"380.25000","31.68767","0.07824"
"380.70000","31.72516","0.07937"
"381.15000","31.76271","0.07994"
"381.60000","31.80014","0.08095"
"382.05000","31.83763","0.08169"
"382.50000","31.87517","0.08343"
"382.95000","31.91266","0.08464"
"383.40000","31.95021","0.08533"
"383.85000","31.98770","0.08585"
"384.30000","32.02507","0.08603"
"384.75000","32.06268","0.08645"
"385.20000","32.10016","0.08660"
"385.65000","32.13771","0.08684"
"386.10000","32.17520","0.08775"
"386.55000","32.21268","0.08756"
"387.00000","32.25011","0.08690"
"387.45000","32.28760","0.08293"
"387.90000","32.32515","0.08236"
"388.35000","32.36264","0.08389"
"388.80000","32.40019","0.02744"
"389.25000","32.43768","0.00139"
"389.70000","32.47516","-0.00179"
"390.15000","32.51265","-0.00041"
"390.60000","32.55014","-0.00106"
"391.05000","32.58762","-0.00066"
"391.50000","32.62518","-0.00110"
"391.95000","32.66266","-0.00125"
"392.40000","32.70015","-0.00118"
"392.85000","32.73758","-0.00134"
"393.30000","32.77513","-0.00114"
"393.75000","32.81268","-0.00117"
"394.20000","32.85016","-0.00143"
"394.65000","32.88765","-0.00095"
"395.10000","32.92514","-0.00103"
"395.55000","32.96263","-0.00113"
"396.00000","33.00018","-0.00152"
"396.45000","33.03766","-0.00135"
"396.90000","33.07515","-0.00140"
"397.35000","33.11270","-0.00210"
"397.80000","33.15012","-0.00151"
"398.25000","33.18762","-0.00096"
"398.70000","33.22516","-0.00159"
"399.15000","33.26271","-0.00118"
"399.60000","33.30014","-0.00129"
"400.05000","33.33768","-0.00185"
"400.50000","33.37518","-0.00094"
"400.95000","33.41260","-0.00141"
"401.40000","33.45015","-0.00188"
"401.85000","33.48770","-0.00095"
"402.30000","33.52519","-0.00126"
"402.75000","33.56268","-0.00158"
"403.20000","33.60016","-0.00089"
"403.65000","33.63765","-0.00128"
"404.10000","33.67520","-0.00168"
"404.55000","33.71268","-0.00091"
"405.00000","33.75017","-0.00108"
"405.45000","33.78772","-0.00150"
"405.90000","33.82515","-0.00109"
"406.35000","33.86264","-0.00138"
"406.80000","33.90013","-0.00136"
"407.25000","33.93761","-0.00097"
"407.70000","33.97516","-0.00097"
"408.15000","34.01265","-0.00185"
"408.60000","34.05020","-0.00104"
"409.05000","34.08769","-0.00113"
"409.50000","34.12511","-0.00118"
"409.95000","34.16266","-0.00089"
"410.40000","34.20015","-0.00115"
"410.85000","34.23764","-0.00146"
"411.30000","34.27513","-0.00086"
"411.75000","34.31261","-0.00123"
"412.20000","34.35011","-0.00116"
"412.65000","34.38765","-0.00111"
"413.10000","34.42514","-0.00167"
"413.55000","34.46269","-0.00121"
"414.00000","34.50018","-0.00093"
"414.45000","34.53760","-0.00125"
"414.90000","34.57515","-0.00121"
"415.35000","34.61264","-0.00073"
"415.80000","34.65019","-0.00119"
"416.25000","34.68768","-0.00126"
"416.70000","34.72522","-0.00101"
"417.15000","34.76265","-0.00145"
"417.60000","34.80014","-0.00129"
"418.05000","34.83763","-0.00120"
"418.50000","34.87517","-0.00125"
"418.95000","34.91272","-0.00108"
"419.40000","34.95021","-0.00126"
"419.85000","34.98764","-0.00160"
"420.30000","35.02507","-0.00130"
"420.75000","35.06261","-0.00116"
"421.20000","35.10016","-0.00150"
"421.65000","35.13765","-0.00099"
"422.10000","35.17520","-0.00119"
"422.55000","35.21269","-0.00145"
"423.00000","35.25018","-0.00114"
"423.45000","35.28761","-0.00145"
"423.90000","35.32515","-0.00140"
"424.35000","35.36264","-0.00122"
"424.80000","35.40013","-0.00115"
"425.25000","35.43767","-0.00135"
"425.70000","35.47510","-0.00086"
"426.15000","35.51265","-0.00135"
"426.60000","35.55014","-0.00162"
"427.05000","35.58769","-0.00127"
"427.50000","35.62518","-0.00123"
"427.95000","35.66260","-0.00127"
"428.40000","35.70009","-0.00116"
"428.85000","35.73764","-0.00125"
"429.30000","35.77519","-0.00114"
"429.75000","35.81274","-0.00103"
"430.20000","35.85011","-0.00121"
"430.65000","35.88765","-0.00100"
"431.10000","35.92508","-0.00092"
"431.55000","35.96263","-0.00139"
"432.00000","36.00017","-0.00101"
"432.45000","36.03766","-0.00119"
"432.90000","36.07515","-0.00151"
"433.35000","36.11264","-0.00100"
"433.80000","36.15013","-0.00114"
"434.25000","36.18761","-0.00168"
"434.70000","36.22510","-0.00126"
"435.15000","36.26271","-0.00116"
"435.60000","36.30020","-0.00130"
"436.05000","36.33768","-0.00137"
"436.50000","36.37512","-0.00109"
"436.95000","36.41261","-0.00109"
"437.40000","36.45009","-0.00109"
"437.85000","36.48770","-0.00087"
"438.30000","36.52513","-0.00124"
"438.75000","36.56268","-0.00122"
"439.20000","36.60016","-0.00112"
"439.65000","36.63759","-0.00124"
"440.10000","36.67514","-0.00112"
"440.55000","36.71269","-0.00091"
"441.00000","36.75018","-0.00169"
"441.45000","36.78766","-0.00100"
"441.90000","36.82515","-0.00121"
"442.35000","36.86264","-0.00141"
"442.80000","36.90018","-0.00108"
"443.25000","36.93768","-0.00112"
"443.70000","36.97516","-0.00145"
"444.15000","37.01271","-0.00072"
"444.60000","37.05014","-0.00133"
"445.05000","37.08763","-0.00126"
"445.50000","37.12518","-0.00074"
"445.95000","37.16266","-0.00152"
"446.40000","37.20015","-0.00096"
"446.85000","37.23764","-0.00090"
"447.30000","37.27513","-0.00106"
"447.75000","37.31256","-0.00108"
"448.20000","37.35010","-0.00110"
"448.65000","37.38765","-0.00102"
"449.10000","37.42520","-0.00136"
"449.55000","37.46268","-0.00110"
"450.00000","37.50017","-0.00089"
"450.45000","37.53761","-0.00129"
"450.90000","37.57509","-0.00123"
"451.35000","37.61264","-0.00095"
"451.80000","37.65019","-0.00102"
"452.25000","37.68768","-0.00108"
"452.70000","37.72516","-0.00127"
"453.15000","37.76259","-0.00119"
"453.60000","37.80014","-0.00130"
"454.05000","37.83763","-0.00092"
"454.50000","37.87518","-0.00061"
"454.95000","37.91266","-0.00101"
"455.40000","37.95015","-0.00101"
"455.85000","37.98764","-0.00080"
"456.30000","38.02513","-0.00113"
"456.75000","38.06261","-0.00114"
"457.20000","38.10016","-0.00067"
"457.65000","38.13765","-0.00125"
"458.10000","38.17514","-0.00137"
"458.55000","38.21269","-0.00068"
"459.00000","38.25011","-0.00058"
"459.45000","38.28766","-0.00095"
"459.90000","38.32521","-0.00093"
"460.35000","38.36264","-0.00096"
"460.80000","38.40013","-0.00106"
"461.25000","38.43761","-0.00110"
"461.70000","38.47511","-0.00075"
"462.15000","38.51271","-0.00050"
"462.60000","38.55020","-0.00070"
"463.05000","38.58768","-0.00099"
"463.50000","38.62517","-0.00063"
"463.95000","38.66260","-0.00123"
"464.40000","38.70009","-0.00092"
"464.85000","38.73764","-0.00053"
"465.30000","38.77513","-0.00107"
"465.75000","38.81268","-0.00103"
"466.20000","38.85016","-0.00053"
"466.65000","38.88759","-0.00037"
"467.10000","38.92508","-0.00081"
"467.55000","38.96263","-0.00081"
"468.00000","39.00018","-0.00080"
"468.45000","39.03766","-0.00096"
"468.90000","39.07521","-0.00097"
"469.35000","39.11264","-0.00025"
"469.80000","39.15007","-0.00067"
"470.25000","39.18767","-0.00036"
"470.70000","39.22516","-0.00038"
"471.15000","39.26271","-0.00061"
"471.60000","39.30020","-0.00096"
"472.05000","39.33769","-0.00086"
"472.50000","39.37511","-0.00024"
"472.95000","39.41260","-0.00010"
"473.40000","39.45015","-0.00070"
"473.85000","39.48763","-0.00029"
"474.30000","39.52518","0.00012"
"474.75000","39.56268","-0.00053"
"475.20000","39.60016","-0.00041"
"475.65000","39.63765","-0.00009"
"476.10000","39.67514","-0.00005"
"476.55000","39.71268","-0.00040"
"477.00000","39.75018","0.00001"
"477.45000","39.78766","-0.00007"
"477.90000","39.82509","0.00018"
"478.35000","39.86264","-0.00067"
"478.80000","39.90025","0.00020"
"479.25000","39.93768","0.00030"
"479.70000","39.97516","-0.00064"
"480.15000","40.01259","-0.00003"
"480.60000","40.05013","0.00033"
"481.05000","40.08762","-0.00021"
"481.50000","40.12518","-0.00003"
"481.95000","40.16266","0.00036"
"482.40000","40.20015","0.00021"
"482.85000","40.23764","0.00028"
"483.30000","40.27512","0.00003"
"483.75000","40.31261","0.00005"
"484.20000","40.35016","0.00032"
"484.65000","40.38765","-0.00023"
"485.10000","40.42520","0.00017"
"485.55000","40.46269","0.00104"
"486.00000","40.50011","0.00054"
"486.45000","40.53760","0.00090"
"486.90000","40.57509","0.00083"
"487.35000","40.61263","0.00055"
"487.80000","40.65018","0.00089"
"488.25000","40.68768","0.00034"
"488.70000","40.72516","0.00060"
"489.15000","40.76259","0.00113"
"489.60000","40.80020","0.00031"
"490.05000","40.83775","0.00105"
"490.50000","40.87511","0.00100"
"490.95000","40.91266","0.00119"
"491.40000","40.95015","0.00163"
"491.85000","40.98770","0.00091"
"492.30000","41.02519","0.00148"
"492.75000","41.06261","0.00122"
"493.20000","41.10016","0.00104"
"493.65000","41.13771","0.00123"
"494.10000","41.17513","0.00096"
"494.55000","41.21257","0.00171"
"495.00000","41.25017","0.00135"
"495.45000","41.28772","0.00086"
"495.90000","41.32521","0.00148"
"496.35000","41.36270","0.00155"
"496.80000","41.40012","0.00135"
"497.25000","41.43755","0.00145"
"497.70000","41.47510","0.00157"
"498.15000","41.51271","0.00154"
"498.60000","41.55020","0.00161"
"499.05000","41.58763","0.00149"
"499.50000","41.62517","0.00153"
"499.95000","41.66261","0.00202"
"500.40000","41.70009","0.00180"
"500.85000","41.73764","0.00232"
"501.30000","41.77518","0.00174"
"501.75000","41.81267","0.00175"
"502.20000","41.85017","0.00217"
"502.65000","41.88765","0.00156"
"503.10000","41.92514","0.00223"
"503.55000","41.96262","0.00192"
"504.00000","42.00018","0.00126"
"504.45000","42.03766","0.00256"
"504.90000","42.07515","0.00128"
"505.35000","42.11264","0.00187"
"505.80000","42.15013","0.00180"
"506.25000","42.18768","0.00185"
"506.70000","42.22522","0.00210"
"507.15000","42.26265","0.00243"
"507.60000","42.30014","0.00171"
"508.05000","42.33763","0.00230"
"508.50000","42.37517","0.00200"
"508.95000","42.41266","0.00235"
"509.40000","42.45015","0.00251"
"509.85000","42.48764","0.00231"
"510.30000","42.52519","0.00260"
"510.75000","42.56261","0.00214"
"511.20000","42.60016","0.00197"
"511.65000","42.63771","0.00237"
"512.10000","42.67520","0.00188"
"512.55000","42.71269","0.00204"
"513.00000","42.75017","0.00194"
"513.45000","42.78761","0.00231"
"513.90000","42.82515","0.00275"
"514.35000","42.86264","0.00303"
"514.80000","42.90018","0.00237"
"515.25000","42.93768","0.00252"
"515.70000","42.97516","0.00279"
"516.15000","43.01265","0.00324"
"516.60000","43.05008","0.00324"
"517.05000","43.08762","0.00357"
"517.50000","43.12518","0.00352"
"517.95000","43.16266","0.00314"
"518.40000","43.20015","0.00378"
"518.85000","43.23770","0.00310"
"519.30000","43.27512","0.00344"
"519.75000","43.31261","0.00291"
"520.20000","43.35016","0.00227"
"520.65000","43.38765","0.00325"
"521.10000","43.42514","0.00375"
"521.55000","43.46268","0.00391"
"522.00000","43.50005","0.00323"
"522.45000","43.53766","0.00314"
"522.90000","43.57515","0.00399"
"523.35000","43.61264","0.00412"
"523.80000","43.65012","0.00331"
"524.25000","43.68768","0.00349"
"524.70000","43.72516","0.00367"
"525.15000","43.76265","0.00389"
"525.60000","43.80014","0.00364"
"526.05000","43.83768","0.00378"
"526.50000","43.87517","0.00346"
"526.95000","43.91261","0.00335"
"527.40000","43.95009","0.00370"
"527.85000","43.98764","0.00332"
"528.30000","44.02518","0.00410"
"528.75000","44.06261","0.00440"
"529.20000","44.10016","0.00451"
"529.65000","44.13765","0.00462"
"530.10000","44.17508","0.00563"
"530.55000","44.21262","0.00536"
"531.00000","44.25018","0.00571"
"531.45000","44.28766","0.00580"
"531.90000","44.32521","0.00576"
"532.35000","44.36264","0.00617"
"532.80000","44.40013","0.00619"
"533.25000","44.43768","0.00637"
"533.70000","44.47516","0.00636"
"534.15000","44.51265","0.00561"
"534.60000","44.55019","0.00663"
"535.05000","44.58763","0.00689"
"535.50000","44.62511","0.00718"
"535.95000","44.66260","0.00696"
"536.40000","44.70009","0.00751"
"536.85000","44.73770","0.00817"
"537.30000","44.77512","0.00870"
"537.75000","44.81268","0.00873"
"538.20000","44.85016","0.00895"
"538.65000","44.88765","0.00941"
"539.10000","44.92514","0.00955"
"539.55000","44.96268","0.00967"
"540.00000","45.00017","0.01018"
"540.45000","45.03767","0.01050"
"540.90000","45.07515","0.01064"
"541.35000","45.11264","0.01110"
"541.80000","45.15013","0.01162"
"542.25000","45.18768","0.01158"
"542.70000","45.22516","0.01177"
"543.15000","45.26271","0.01243"
"543.60000","45.30013","0.01297"
"544.05000","45.33762","0.01312"
"544.50000","45.37518","0.01375"
"544.95000","45.41266","0.01387"
"545.40000","45.45021","0.01429"
"545.85000","45.48770","0.01478"
"546.30000","45.52513","0.01528"
"546.75000","45.56261","0.01542"
"547.20000","45.60017","0.01586"
"547.65000","45.63771","0.01646"
"548.10000","45.67520","0.01651"
"548.55000","45.71269","0.01730"
"549.00000","45.75011","0.01717"
"549.45000","45.78760","0.01805"
"549.90000","45.82515","0.01889"
"550.35000","45.86264","0.01906"
"550.80000","45.90019","0.01883"
"551.25000","45.93773","0.01976"
"551.70000","45.97516","0.01083"
"552.15000","46.01265","0.00706"
"552.60000","46.05014","0.00930"
"553.05000","46.08762","0.01064"
"553.50000","46.12517","0.00993"
"553.95000","46.16266","0.01147"
"554.40000","46.20015","0.01178"
"554.85000","46.23764","0.00995"
"555.30000","46.27513","0.01136"
"555.75000","46.31268","0.01182"
"556.20000","46.35016","0.01122"
"556.65000","46.38771","0.01163"
"557.10000","46.42508","0.01150"
"557.55000","46.46262","0.01158"
"558.00000","46.50012","0.01199"
"558.45000","46.53766","0.01235"
"558.90000","46.57515","0.01270"
"559.35000","46.61264","0.01376"
"559.80000","46.65013","0.01260"
"560.25000","46.68761","0.01278"
"560.70000","46.72516","0.01332"
"561.15000","46.76265","0.01266"
"561.60000","46.80014","0.01377"
"562.05000","46.83769","0.01435"
"562.50000","46.87518","0.01385"
"562.95000","46.91260","0.01366"
"563.40000","46.95009","0.01455"
"563.85000","46.98764","0.01462"
"564.30000","47.02518","0.01551"
"564.75000","47.06267","0.01589"
"565.20000","47.10022","0.01620"
"565.65000","47.13759","0.01635"
"566.10000","47.17514","0.01662"
"566.55000","47.21262","0.01773"
"567.00000","47.25017","0.01774"
"567.45000","47.28766","0.01690"
"567.90000","47.32515","0.01855"
"568.35000","47.36264","0.01752"
"568.80000","47.40013","0.01775"
"569.25000","47.43768","0.01873"
"569.70000","47.47516","0.01912"
"570.15000","47.51265","0.01900"
"570.60000","47.55013","0.01934"
"571.05000","47.58768","0.01993"
"571.50000","47.62511","0.02085"
"571.95000","47.66266","0.02144"
"572.40000","47.70021","0.02180"
"572.85000","47.73764","0.02194"
"573.30000","47.77519","0.02220"
"573.75000","47.81261","0.02304"
"574.20000","47.85016","0.02171"
"574.65000","47.88765","0.02236"
"575.10000","47.92514","0.02256"
"575.55000","47.96268","0.02246"
"576.00000","48.00018","0.02420"
"576.45000","48.03766","0.02411"
"576.90000","48.07509","0.02418"
"577.35000","48.11264","0.02487"
"577.80000","48.15018","0.02425"
"578.25000","48.18767","0.02358"
"578.70000","48.22517","0.02354"
"579.15000","48.26265","0.02448"
"579.60000","48.30014","0.02372"
"580.05000","48.33756","0.02487"
"580.50000","48.37517","0.02541"
"580.95000","48.41266","0.02596"
"581.40000","48.45015","0.02524"
"581.85000","48.48770","0.02568"
"582.30000","48.52507","0.02652"
"582.75000","48.56268","0.02724"
"583.20000","48.60016","0.02775"
"583.65000","48.63771","0.02840"
"584.10000","48.67520","0.02923"
"584.55000","48.71262","0.02965"
"585.00000","48.75011","0.03054"
"585.45000","48.78760","0.03071"
"585.90000","48.82515","0.03166"
"586.35000","48.86269","0.02824"
"586.80000","48.90013","0.02654"
"587.25000","48.93767","0.02696"
"587.70000","48.97516","0.02726"
"588.15000","49.01265","0.02778"
"588.60000","49.05013","0.02899"
"589.05000","49.08768","0.02911"
"589.50000","49.12518","0.03002"
"589.95000","49.16266","0.03111"
"590.40000","49.20015","0.02768"
"590.85000","49.23764","0.02931"
"591.30000","49.27518","0.02981"
"591.75000","49.31267","0.03008"
"592.20000","49.35017","0.02989"
"592.65000","49.38765","0.03154"
"593.10000","49.42514","0.03261"
"593.55000","49.46256","0.03224"
"594.00000","49.50017","0.03311"
"594.45000","49.53760","0.03362"
"594.90000","49.57515","0.03428"
"595.35000","49.61263","0.03447"
"595.80000","49.65013","0.03448"
"596.25000","49.68755","0.03515"
"596.70000","49.72510","0.03603"
"597.15000","49.76271","0.03675"
"597.60000","49.80020","0.03678"
"598.05000","49.83768","0.03741"
"598.50000","49.87518","0.03795"
"598.95000","49.91260","0.03800"
"599.40000","49.95015","0.03863"
"599.85000","49.98764","0.03814"
"600.30000","50.02519","0.03764"
"600.75000","50.06267","0.03820"
"601.20000","50.10016","0.03865"
"601.65000","50.13759","0.03906"
"602.10000","50.17513","0.03948"
"602.55000","50.21262","0.03968"
"603.00000","50.25018","0.04002"
"603.45000","50.28766","0.04054"
"603.90000","50.32515","0.04097"
"604.35000","50.36264","0.04132"
"604.80000","50.40012","0.04195"
"605.25000","50.43761","0.04232"
"605.70000","50.47516","0.04187"
"606.15000","50.51271","0.04221"
"606.60000","50.55020","0.04299"
"607.05000","50.58762","0.04284"
"607.50000","50.62511","0.04346"
"607.95000","50.66272","0.04424"
"608.40000","50.70021","0.04476"
"608.85000","50.73769","0.04039"
"609.30000","50.77513","0.04158"
"609.75000","50.81262","0.04154"
"610.20000","50.85010","0.03908"
"610.65000","50.88771","0.04029"
"611.10000","50.92520","0.04062"
"611.55000","50.96268","0.04056"
"612.00000","51.00011","0.04118"
"612.45000","51.03760","0.04194"
"612.90000","51.07515","0.04203"
"613.35000","51.11264","0.04242"
"613.80000","51.15019","0.04306"
"614.25000","51.18773","0.04341"
"614.70000","51.22516","0.04373"
"615.15000","51.26265","0.04477"
"615.60000","51.30013","0.04449"
"616.05000","51.33763","0.04555"
"616.50000","51.37511","0.04643"
"616.95000","51.41266","0.04687"
"617.40000","51.45021","0.04600"
"617.85000","51.48770","0.04692"
"618.30000","51.52512","0.04739"
"618.75000","51.56268","0.04846"
"619.20000","51.60022","0.04900"
"619.65000","51.63765","0.05006"
"620.10000","51.67514","0.05125"
"620.55000","51.71269","0.05133"
"621.00000","51.75017","0.05228"
"621.45000","51.78766","0.05308"
"621.90000","51.82509","0.05388"
"622.35000","51.86269","0.05500"
"622.80000","51.90018","0.05570"
"623.25000","51.93767","0.05731"
"623.70000","51.97510","0.05794"
"624.15000","52.01265","0.05908"
"624.60000","52.05020","0.06005"
"625.05000","52.08768","0.06133"
"625.50000","52.12518","0.06202"
"625.95000","52.16260","0.06352"
"626.40000","52.20009","0.06452"
"626.85000","52.23764","0.06538"
"627.30000","52.27519","0.06679"
"627.75000","52.31273","0.06793"
"628.20000","52.35016","0.06885"
"628.65000","52.38765","0.06936"
"629.10000","52.42514","0.07042"
"629.55000","52.46256","0.07141"
"630.00000","52.50017","0.07247"
"630.45000","52.53766","0.07335"
"630.90000","52.57521","0.07427"
"631.35000","52.61270","0.07542"
"631.80000","52.65012","0.07636"
"632.25000","52.68768","0.07640"
"632.70000","52.72510","0.07739"
"633.15000","52.76265","0.07862"
"633.60000","52.80020","0.07949"
"634.05000","52.83769","0.08034"
"634.50000","52.87511","0.08085"
"634.95000","52.91261","0.08167"
"635.40000","52.95015","0.08279"
"635.85000","52.98769","0.08308"
"636.30000","53.02518","0.08389"
"636.75000","53.06267","0.08443"
"637.20000","53.10016","-0.00015"
"637.65000","53.13765","-0.00138"
"638.10000","53.17514","-0.00073"
"638.55000","53.21268","-0.00104"
"639.00000","53.25018","-0.00081"
"639.45000","53.28766","-0.00059"
"639.90000","53.32515","-0.00088"
"640.35000","53.36264","-0.00108"
"640.80000","53.40019","-0.00065"
"641.25000","53.43767","-0.00079"
"641.70000","53.47516","-0.00039"
"642.15000","53.51271","-0.00097"
"642.60000","53.55008","-0.00121"
"643.05000","53.58763","-0.00042"
"643.50000","53.62511","-0.00109"
"643.95000","53.66272","-0.00114"
"644.40000","53.70021","-0.00072"
"644.85000","53.73770","-0.00108"
"645.30000","53.77512","-0.00067"
"645.75000","53.81261","-0.00040"
"646.20000","53.85016","-0.00079"
"646.65000","53.88765","-0.00105"
"647.10000","53.92520","-0.00029"
"647.55000","53.96268","-0.00086"
"648.00000","54.00017","-0.00051"
"648.45000","54.03761","-0.00033"
"648.90000","54.07509","-0.00109"
"649.35000","54.11264","-0.00064"
"649.80000","54.15013","-0.00032"
"650.25000","54.18767","-0.00136"
"650.70000","54.22516","-0.00040"
"651.15000","54.26258","-0.00062"
"651.60000","54.30014","-0.00073"
"652.05000","54.33762","-0.00036"
"652.50000","54.37518","-0.00067"
"652.95000","54.41266","-0.00086"
"653.40000","54.45015","-0.00006"
"653.85000","54.48764","-0.00101"
"654.30000","54.52512","-0.00084"
"654.75000","54.56267","-0.00002"
"655.20000","54.60016","-0.00091"
"655.65000","54.63771","-0.00070"
"656.10000","54.67514","-0.00008"
"656.55000","54.71263","-0.00099"
"657.00000","54.75018","-0.00029"
"657.45000","54.78766","-0.00035"
"657.90000","54.82515","-0.00087"
"658.35000","54.86264","-0.00013"
"658.80000","54.90018","-0.00036"
"659.25000","54.93761","-0.00095"
"659.70000","54.97516","-0.00009"
"660.15000","55.01265","-0.00059"
"660.60000","55.05014","-0.00089"
"661.05000","55.08768","0.00027"
"661.50000","55.12517","-0.00058"
"661.95000","55.16261","-0.00088"
"662.40000","55.20015","0.00017"
"662.85000","55.23764","-0.00063"
"663.30000","55.27513","-0.00057"
"663.75000","55.31273","-0.00036"
"664.20000","55.35016","-0.00056"
"664.65000","55.38765","-0.00015"
"665.10000","55.42514","-0.00064"
"665.55000","55.46262","-0.00057"
"666.00000","55.50018","0.00004"
"666.45000","55.53766","-0.00042"
"666.90000","55.57521","-0.00063"
"667.35000","55.61264","0.00005"
"667.80000","55.65012","-0.00067"
"668.25000","55.68761","-0.00035"
"668.70000","55.72517","0.00025"
"669.15000","55.76265","-0.00066"
"669.60000","55.80014","-0.00003"
"670.05000","55.83763","-0.00028"
"670.50000","55.87511","-0.00035"
"670.95000","55.91266","-0.00012"
"671.40000","55.95015","-0.00037"
"671.85000","55.98763","-0.00009"
"672.30000","56.02518","0.00027"
"672.75000","56.06262","-0.00042"
"673.20000","56.10010","-0.00008"
"673.65000","56.13765","-0.00013"
"674.10000","56.17514","-0.00028"
"674.37600","56.19816","0.00003"