File: Force_trajectories/170122_2/Specimen_RawData_3.csv
End date,"1/22/2017"
Specimen label,"3CT_21"
Maximum Load,"0.29249",N

Time,Extension,Load
(s),(mm),(N)
"0.00000","0.00000","0.00063"
"0.22200","0.01596","0.00048"
"0.44400","0.03719","0.00074"
"0.66600","0.05566","0.00079"
"0.88800","0.07420","0.00067"
"1.11000","0.09267","0.00057"
"1.33200","0.11115","0.00070"
"1.55400","0.12962","0.00077"
"1.77600","0.14816","0.00135"
"1.99800","0.16663","0.00090"
"2.22000","0.18517","0.00083"
"2.44200","0.20370","0.00079"
"2.66400","0.22212","0.00101"
"2.88600","0.24059","0.00149"
"3.10800","0.25913","0.00094"
"3.33000","0.27766","0.00088"
"3.55200","0.29614","0.00142"
"3.77400","0.31461","0.00093"
"3.99600","0.33315","0.00136"
"4.21800","0.35156","0.00148"
"4.44000","0.37016","0.00119"
"4.66200","0.38863","0.00115"
"4.88400","0.40711","0.00083"
"5.10600","0.42564","0.00082"
"5.32800","0.44412","0.00138"
"5.55000","0.46265","0.00132"
"5.77200","0.48113","0.00138"
"5.99400","0.49966","0.00083"
"6.21600","0.51814","0.00129"
"6.43800","0.53655","0.00188"
"6.66000","0.55515","0.00100"
"6.88200","0.57362","0.00095"
"7.10400","0.59210","0.00125"
"7.32600","0.61063","0.00115"
"7.54800","0.62911","0.00107"
"7.77000","0.64764","0.00128"
"7.99200","0.66606","0.00149"
"8.21400","0.68465","0.00123"
"8.43600","0.70312","0.00136"
"8.65800","0.72160","0.00154"
"8.88000","0.74019","0.00182"
"9.10200","0.75861","0.00114"
"9.32400","0.77714","0.00146"
"9.54600","0.79562","0.00130"
"9.76800","0.81409","0.00167"
"9.99000","0.83263","0.00131"
"10.21200","0.85104","0.00158"
"10.43400","0.86970","0.00138"
"10.65600","0.88811","0.00109"
"10.87800","0.90665","0.00125"
"11.10000","0.92512","0.00147"
"11.32200","0.94360","0.00132"
"11.54400","0.96213","0.00167"
"11.76600","0.98061","0.00131"
"11.98800","0.99914","0.00134"
"12.21000","1.01756","0.00096"
"12.43200","1.03615","0.00111"
"12.65400","1.05463","0.00126"
"12.87600","1.07304","0.00118"
"13.09800","1.09164","0.00132"
"13.32000","1.11011","0.00131"
"13.54200","1.12865","0.00138"
"13.76400","1.14718","0.00111"
"13.98600","1.16560","0.00107"
"14.20800","1.18413","0.00068"
"14.43000","1.20255","0.00134"
"14.65200","1.22114","0.00115"
"14.87400","1.23968","0.00099"
"15.09600","1.25803","0.00094"
"15.31800","1.27669","0.00120"
"15.54000","1.29510","0.00118"
"15.76200","1.31364","0.00080"
"15.98400","1.33205","0.00106"
"16.20600","1.35065","0.00140"
"16.42800","1.36918","0.00128"
"16.65000","1.38760","0.00161"
"16.87200","1.40613","0.00177"
"17.09400","1.42461","0.00123"
"17.31600","1.44314","0.00153"
"17.53800","1.46167","0.00108"
"17.76000","1.48015","0.00129"
"17.98200","1.49862","0.00099"
"18.20400","1.51710","0.00129"
"18.42600","1.53563","0.00109"
"18.64800","1.55411","0.00183"
"18.87000","1.57258","0.00172"
"19.09200","1.59112","0.00173"
"19.31400","1.60959","0.00153"
"19.53600","1.62813","0.00137"
"19.75800","1.64666","0.00159"
"19.98000","1.66514","0.00113"
"20.20200","1.68367","0.00111"
"20.42400","1.70209","0.00164"
"20.64600","1.72062","0.00124"
"20.86800","1.73910","0.00164"
"21.09000","1.75763","0.00158"
"21.31200","1.77611","0.00161"
"21.53400","1.79458","0.00135"
"21.75600","1.81318","0.00100"
"21.97800","1.83159","0.00142"
"22.20000","1.85019","0.00124"
"22.42200","1.86860","0.00169"
"22.64400","1.88714","0.00174"
"22.86600","1.90561","0.00124"
"23.08800","1.92409","0.00169"
"23.31000","1.94268","0.00165"
"23.53200","1.96110","0.00133"
"23.75400","1.97963","0.00144"
"23.97600","1.99817","0.00151"
"24.19800","2.01664","0.00090"
"24.42000","2.03512","0.00126"
"24.64200","2.05359","0.00161"
"24.86400","2.07213","0.00148"
"25.08600","2.09066","0.00139"
"25.30800","2.10908","0.00097"
"25.53000","2.12767","0.00103"
"25.75200","2.14609","0.00161"
"25.97400","2.16462","0.00121"
"26.19600","2.18315","0.00152"
"26.41800","2.20163","0.00129"
"26.64000","2.22016","0.00141"
"26.86200","2.23858","0.00081"
"27.08400","2.25723","0.00129"
"27.30600","2.27559","0.00155"
"27.52800","2.29406","0.00126"
"27.75000","2.31260","0.00159"
"27.97200","2.33107","0.00098"
"28.19400","2.34961","0.00118"
"28.41600","2.36808","0.00226"
"28.63800","2.38662","0.00118"
"28.86000","2.40515","0.00141"
"29.08200","2.42357","0.00099"
"29.30400","2.44210","0.00187"
"29.52600","2.46064","0.00122"
"29.74800","2.47911","0.00125"
"29.97000","2.49765","0.00105"
"30.19200","2.51612","0.00158"
"30.41400","2.53466","0.00158"
"30.63600","2.55307","0.00168"
"30.85800","2.57167","0.00122"
"31.08000","2.59008","0.00142"
"31.30200","2.60862","0.00104"
"31.52400","2.62715","0.00136"
"31.74600","2.64557","0.00149"
"31.96800","2.66416","0.00119"
"32.19000","2.68258","0.00144"
"32.41200","2.70117","0.00108"
"32.63400","2.71959","0.00176"
"32.85600","2.73812","0.00175"
"33.07800","2.75666","0.00150"
"33.30000","2.77507","0.00177"
"33.52200","2.79361","0.00202"
"33.74400","2.81208","0.00169"
"33.96600","2.83062","0.00170"
"34.18800","2.84915","0.00108"
"34.41000","2.86763","0.00131"
"34.63200","2.88610","0.00160"
"34.85400","2.90464","0.00161"
"35.07600","2.92311","0.00153"
"35.29800","2.94170","0.00117"
"35.52000","2.96006","0.00125"
"35.74200","2.97860","0.00176"
"35.96400","2.99713","0.00111"
"36.18600","3.01566","0.00131"
"36.40800","3.03414","0.00190"
"36.63000","3.05261","0.00158"
"36.85200","3.07115","0.00112"
"37.07400","3.08956","0.00120"
"37.29600","3.10816","0.00182"
"37.51800","3.12657","0.00125"
"37.74000","3.14511","0.00135"
"37.96200","3.16358","0.00145"
"38.18400","3.18212","0.00140"
"38.40600","3.20065","0.00155"
"38.62800","3.21907","0.00172"
"38.85000","3.23766","0.00198"
"39.07200","3.25614","0.00186"
"39.29400","3.27467","0.00164"
"39.51600","3.29315","0.00137"
"39.73800","3.31162","0.00146"
"39.96000","3.33016","0.00121"
"40.18200","3.34863","0.00156"
"40.40400","3.36711","0.00179"
"40.62600","3.38564","0.00147"
"40.84800","3.40412","0.00155"
"41.07000","3.42265","0.00203"
"41.29200","3.44113","0.00094"
"41.51400","3.45960","0.00136"
"41.73600","3.47814","0.00136"
"41.95800","3.49655","0.00146"
"42.18000","3.51509","0.00187"
"42.40200","3.53356","0.00101"
"42.62400","3.55210","0.00159"
"42.84600","3.57063","0.00215"
"43.06800","3.58911","0.00165"
"43.29000","3.60770","0.00133"
"43.51200","3.62606","0.00142"
"43.73400","3.64471","0.00119"
"43.95600","3.66313","0.00154"
"44.17800","3.68160","0.00110"
"44.40000","3.70014","0.00219"
"44.62200","3.71861","0.00154"
"44.84400","3.73714","0.00195"
"45.06600","3.75562","0.00123"
"45.28800","3.77415","0.00165"
"45.51000","3.79269","0.00107"
"45.73200","3.81110","0.00182"
"45.95400","3.82964","0.00146"
"46.17600","3.84811","0.00174"
"46.39800","3.86665","0.00123"
"46.62000","3.88512","0.00170"
"46.84200","3.90354","0.00188"
"47.06400","3.92213","0.00121"
"47.28600","3.94061","0.00236"
"47.50800","3.95914","0.00142"
"47.73000","3.97768","0.00178"
"47.95200","3.99615","0.00166"
"48.17400","4.01463","0.00181"
"48.39600","4.03304","0.00161"
"48.61800","4.05170","0.00128"
"48.84000","4.07011","0.00223"
"49.06200","4.08865","0.00144"
"49.28400","4.10712","0.00173"
"49.50600","4.12560","0.00232"
"49.72800","4.14413","0.00214"
"49.95000","4.16261","0.00142"
"50.17200","4.18114","0.00210"
"50.39400","4.19962","0.00143"
"50.61600","4.21809","0.00160"
"50.83800","4.23663","0.00168"
"51.06000","4.25510","0.00116"
"51.28200","4.27364","0.00206"
"51.50400","4.29211","0.00152"
"51.72600","4.31059","0.00146"
"51.94800","4.32918","0.00198"
"52.17000","4.34760","0.00181"
"52.39200","4.36613","0.00156"
"52.61400","4.38461","0.00122"
"52.83600","4.40314","0.00213"
"53.05800","4.42162","0.00124"
"53.28000","4.44009","0.00176"
"53.50200","4.45862","0.00173"
"53.72400","4.47710","0.00183"
"53.94600","4.49563","0.00152"
"54.16800","4.51411","0.00246"
"54.39000","4.53259","0.00187"
"54.61200","4.55112","0.00138"
"54.83400","4.56959","0.00186"
"55.05600","4.58819","0.00142"
"55.27800","4.60654","0.00182"
"55.50000","4.62514","0.00153"
"55.72200","4.64367","0.00146"
"55.94400","4.66215","0.00214"
"56.16600","4.68062","0.00144"
"56.38800","4.69916","0.00183"
"56.61000","4.71763","0.00198"
"56.83200","4.73617","0.00194"
"57.05400","4.75458","0.00143"
"57.27600","4.77318","0.00198"
"57.49800","4.79159","0.00150"
"57.72000","4.81013","0.00153"
"57.94200","4.82866","0.00196"
"58.16400","4.84708","0.00168"
"58.38600","4.86567","0.00164"
"58.60800","4.88409","0.00209"
"58.83000","4.90268","0.00104"
"59.05200","4.92110","0.00162"
"59.27400","4.93957","0.00204"
"59.49600","4.95817","0.00116"
"59.71800","4.97658","0.00187"
"59.94000","4.99518","0.00246"
"60.16200","5.01359","0.00171"
"60.38400","5.03219","0.00179"
"60.60600","5.05066","0.00155"
"60.82800","5.06908","0.00165"
"61.05000","5.08761","0.00159"
"61.27200","5.10609","0.00188"
"61.49400","5.12468","0.00224"
"61.71600","5.14310","0.00200"
"61.93800","5.16163","0.00187"
"62.16000","5.18011","0.00192"
"62.38200","5.19864","0.00120"
"62.60400","5.21718","0.00160"
"62.82600","5.23565","0.00181"
"63.04800","5.25412","0.00167"
"63.27000","5.27260","0.00174"
"63.49200","5.29107","0.00193"
"63.71400","5.30967","0.00163"
"63.93600","5.32808","0.00190"
"64.15800","5.34662","0.00171"
"64.38000","5.36515","0.00096"
"64.60200","5.38363","0.00208"
"64.82400","5.40216","0.00165"
"65.04600","5.42058","0.00143"
"65.26800","5.43917","0.00225"
"65.49000","5.45759","0.00163"
"65.71200","5.47612","0.00223"
"65.93400","5.49466","0.00211"
"66.15600","5.51307","0.00186"
"66.37800","5.53167","0.00187"
"66.60000","5.55014","0.00203"
"66.82200","5.56862","0.00172"
"67.04400","5.58715","0.00167"
"67.26600","5.60563","0.00234"
"67.48800","5.62416","0.00138"
"67.71000","5.64264","0.00159"
"67.93200","5.66111","0.00204"
"68.15400","5.67965","0.00270"
"68.37600","5.69812","0.00222"
"68.59800","5.71666","0.00228"
"68.82000","5.73513","0.00189"
"69.04200","5.75367","0.00141"
"69.26400","5.77214","0.00227"
"69.48600","5.79062","0.00193"
"69.70800","5.80915","0.00175"
"69.93000","5.82757","0.00216"
"70.15200","5.84610","0.00171"
"70.37400","5.86464","0.00189"
"70.59600","5.88311","0.00205"
"70.81800","5.90165","0.00162"
"71.04000","5.92006","0.00156"
"71.26200","5.93866","0.00195"
"71.48400","5.95713","0.00192"
"71.70600","5.97566","0.00181"
"71.92800","5.99408","0.00197"
"72.15000","6.01261","0.00249"
"72.37200","6.03115","0.00154"
"72.59400","6.04956","0.00218"
"72.81600","6.06810","0.00200"
"73.03800","6.08663","0.00192"
"73.26000","6.10517","0.00243"
"73.48200","6.12364","0.00212"
"73.70400","6.14206","0.00213"
"73.92600","6.16065","0.00232"
"74.14800","6.17913","0.00191"
"74.37000","6.19766","0.00201"
"74.59200","6.21620","0.00232"
"74.81400","6.23455","0.00182"
"75.03600","6.25315","0.00162"
"75.25800","6.27156","0.00225"
"75.48000","6.29016","0.00215"
"75.70200","6.30863","0.00255"
"75.92400","6.32711","0.00166"
"76.14600","6.34564","0.00243"
"76.36800","6.36406","0.00196"
"76.59000","6.38265","0.00196"
"76.81200","6.40107","0.00197"
"77.03400","6.41966","0.00201"
"77.25600","6.43814","0.00152"
"77.47800","6.45661","0.00212"
"77.70000","6.47515","0.00205"
"77.92200","6.49362","0.00199"
"78.14400","6.51210","0.00283"
"78.36600","6.53063","0.00203"
"78.58800","6.54911","0.00191"
"78.81000","6.56758","0.00225"
"79.03200","6.58612","0.00243"
"79.25400","6.60465","0.00208"
"79.47600","6.62319","0.00216"
"79.69800","6.64160","0.00154"
"79.92000","6.66019","0.00189"
"80.14200","6.67861","0.00194"
"80.36400","6.69715","0.00200"
"80.58600","6.71562","0.00196"
"80.80800","6.73410","0.00184"
"81.03000","6.75263","0.00183"
"81.25200","6.77111","0.00214"
"81.47400","6.78964","0.00177"
"81.69600","6.80811","0.00215"
"81.91800","6.82665","0.00192"
"82.14000","6.84512","0.00216"
"82.36200","6.86360","0.00148"
"82.58400","6.88213","0.00221"
"82.80600","6.90055","0.00217"
"83.02800","6.91914","0.00213"
"83.25000","6.93762","0.00201"
"83.47200","6.95615","0.00197"
"83.69400","6.97463","0.00229"
"83.91600","6.99310","0.00265"
"84.13800","7.01164","0.00186"
"84.36000","7.03017","0.00233"
"84.58200","7.04859","0.00225"
"84.80400","7.06712","0.00207"
"85.02600","7.08554","0.00260"
"85.24800","7.10413","0.00221"
"85.47000","7.12261","0.00219"
"85.69200","7.14114","0.00213"
"85.91400","7.15968","0.00252"
"86.13600","7.17815","0.00230"
"86.35800","7.19669","0.00229"
"86.58000","7.21504","0.00247"
"86.80200","7.23364","0.00261"
"87.02400","7.25211","0.00166"
"87.24600","7.27059","0.00248"
"87.46800","7.28912","0.00233"
"87.69000","7.30754","0.00272"
"87.91200","7.32619","0.00211"
"88.13400","7.34461","0.00297"
"88.35600","7.36320","0.00176"
"88.57800","7.38168","0.00292"
"88.80000","7.40015","0.00211"
"89.02200","7.41863","0.00243"
"89.24400","7.43710","0.00210"
"89.46600","7.45564","0.00242"
"89.68800","7.47411","0.00216"
"89.91000","7.49259","0.00208"
"90.13200","7.51112","0.00223"
"90.35400","7.52959","0.00222"
"90.57600","7.54813","0.00195"
"90.79800","7.56666","0.00224"
"91.02000","7.58514","0.00238"
"91.24200","7.60361","0.00199"
"91.46400","7.62203","0.00243"
"91.68600","7.64062","0.00220"
"91.90800","7.65910","0.00255"
"92.13000","7.67769","0.00209"
"92.35200","7.69617","0.00263"
"92.57400","7.71452","0.00245"
"92.79600","7.73318","0.00308"
"93.01800","7.75165","0.00212"
"93.24000","7.77013","0.00217"
"93.46200","7.78860","0.00219"
"93.68400","7.80708","0.00259"
"93.90600","7.82567","0.00235"
"94.12800","7.84409","0.00226"
"94.35000","7.86268","0.00258"
"94.57200","7.88116","0.00240"
"94.79400","7.89963","0.00244"
"95.01600","7.91817","0.00267"
"95.23800","7.93658","0.00235"
"95.46000","7.95512","0.00258"
"95.68200","7.97359","0.00269"
"95.90400","7.99213","0.00311"
"96.12600","8.01066","0.00204"
"96.34800","8.02908","0.00276"
"96.57000","8.04761","0.00234"
"96.79200","8.06615","0.00256"
"97.01400","8.08468","0.00185"
"97.23600","8.10316","0.00246"
"97.45800","8.12163","0.00230"
"97.68000","8.14011","0.00180"
"97.90200","8.15858","0.00288"
"98.12400","8.17718","0.00274"
"98.34600","8.19559","0.00206"
"98.56800","8.21413","0.00218"
"98.79000","8.23266","0.00244"
"99.01200","8.25107","0.00214"
"99.23400","8.26967","0.00226"
"99.45600","8.28808","0.00220"
"99.67800","8.30668","0.00282"
"99.90000","8.32515","0.00257"
"100.12200","8.34363","0.00218"
"100.34400","8.36216","0.00258"
"100.56600","8.38058","0.00193"
"100.78800","8.39917","0.00201"
"101.01000","8.41765","0.00257"
"101.23200","8.43612","0.00203"
"101.45400","8.45466","0.00254"
"101.67600","8.47307","0.00248"
"101.89800","8.49161","0.00230"
"102.12000","8.51008","0.00275"
"102.34200","8.52862","0.00263"
"102.56400","8.54715","0.00205"
"102.78600","8.56557","0.00257"
"103.00800","8.58416","0.00283"
"103.23000","8.60258","0.00239"
"103.45200","8.62117","0.00239"
"103.67400","8.63965","0.00251"
"103.89600","8.65806","0.00270"
"104.11800","8.67666","0.00200"
"104.34000","8.69507","0.00208"
"104.56200","8.71367","0.00246"
"104.78400","8.73214","0.00256"
"105.00600","8.75062","0.00250"
"105.22800","8.76909","0.00246"
"105.45000","8.78763","0.00268"
"105.67200","8.80616","0.00262"
"105.89400","8.82458","0.00250"
"106.11600","8.84317","0.00206"
"106.33800","8.86159","0.00264"
"106.56000","8.88006","0.00200"
"106.78200","8.89866","0.00278"
"107.00400","8.91713","0.00219"
"107.22600","8.93561","0.00278"
"107.44800","8.95414","0.00245"
"107.67000","8.97262","0.00283"
"107.89200","8.99121","0.00274"
"108.11400","9.00957","0.00250"
"108.33600","9.02816","0.00170"
"108.55800","9.04657","0.00218"
"108.78000","9.06511","0.00195"
"109.00200","9.08364","0.00181"
"109.22400","9.10206","0.00242"
"109.44600","9.12071","0.00265"
"109.66800","9.13913","0.00211"
"109.89000","9.15766","0.00194"
"110.11200","9.17614","0.00197"
"110.33400","9.19461","0.00249"
"110.55600","9.21315","0.00230"
"110.77800","9.23156","0.00187"
"111.00000","9.25016","0.00285"
"111.22200","9.26863","0.00275"
"111.44400","9.28711","0.00208"
"111.66600","9.30564","0.00223"
"111.88800","9.32412","0.00223"
"112.11000","9.34259","0.00232"
"112.33200","9.36113","0.00282"
"112.55400","9.37960","0.00195"
"112.77600","9.39814","0.00244"
"112.99800","9.41649","0.00224"
"113.22000","9.43515","0.00242"
"113.44200","9.45362","0.00234"
"113.66400","9.47216","0.00215"
"113.88600","9.49063","0.00228"
"114.10800","9.50917","0.00250"
"114.33000","9.52764","0.00222"
"114.55200","9.54612","0.00238"
"114.77400","9.56471","0.00271"
"114.99600","9.58313","0.00223"
"115.21800","9.60160","0.00200"
"115.44000","9.62014","0.00254"
"115.66200","9.63855","0.00280"
"115.88400","9.65715","0.00239"
"116.10600","9.67562","0.00215"
"116.32800","9.69416","0.00212"
"116.55000","9.71263","0.00294"
"116.77200","9.73111","0.00247"
"116.99400","9.74958","0.00248"
"117.21600","9.76812","0.00248"
"117.43800","9.78665","0.00237"
"117.66000","9.80512","0.00233"
"117.88200","9.82354","0.00242"
"118.10400","9.84213","0.00248"
"118.32600","9.86061","0.00248"
"118.54800","9.87914","0.00209"
"118.77000","9.89768","0.00211"
"118.99200","9.91609","0.00274"
"119.21400","9.93469","0.00236"
"119.43600","9.95304","0.00275"
"119.65800","9.97164","0.00287"
"119.88000","9.99005","0.00255"
"120.10200","10.00865","0.00209"
"120.32400","10.02718","0.00214"
"120.54600","10.04566","0.00271"
"120.76800","10.06413","0.00275"
"120.99000","10.08261","0.00281"
"121.21200","10.10114","0.00262"
"121.43400","10.11962","0.00256"
"121.65600","10.13809","0.00309"
"121.87800","10.15663","0.00202"
"122.10000","10.17510","0.00245"
"122.32200","10.19364","0.00263"
"122.54400","10.21211","0.00226"
"122.76600","10.23065","0.00271"
"122.98800","10.24912","0.00234"
"123.21000","10.26760","0.00244"
"123.43200","10.28613","0.00251"
"123.65400","10.30461","0.00215"
"123.87600","10.32314","0.00237"
"124.09800","10.34168","0.00240"
"124.32000","10.36009","0.00215"
"124.54200","10.37863","0.00255"
"124.76400","10.39710","0.00257"
"124.98600","10.41570","0.00289"
"125.20800","10.43417","0.00296"
"125.43000","10.45265","0.00307"
"125.65200","10.47112","0.00261"
"125.87400","10.48959","0.00244"
"126.09600","10.50819","0.00246"
"126.31800","10.52660","0.00266"
"126.54000","10.54520","0.00243"
"126.76200","10.56367","0.00278"
"126.98400","10.58203","0.00269"
"127.20600","10.60063","0.00302"
"127.42800","10.61910","0.00213"
"127.65000","10.63763","0.00278"
"127.87200","10.65611","0.00248"
"128.09400","10.67464","0.00249"
"128.31600","10.69312","0.00301"
"128.53800","10.71165","0.00268"
"128.76000","10.73013","0.00316"
"128.98200","10.74866","0.00289"
"129.20400","10.76708","0.00321"
"129.42600","10.78567","0.00283"
"129.64800","10.80409","0.00239"
"129.87000","10.82262","0.00305"
"130.09200","10.84116","0.00332"
"130.31400","10.85963","0.00276"
"130.53600","10.87817","0.00282"
"130.75800","10.89658","0.00325"
"130.98000","10.91518","0.00288"
"131.20200","10.93365","0.00314"
"131.42400","10.95219","0.00302"
"131.64600","10.97060","0.00299"
"131.86800","10.98914","0.00284"
"132.09000","11.00761","0.00318"
"132.31200","11.02609","0.00337"
"132.53400","11.04468","0.00377"
"132.75600","11.06310","0.00338"
"132.97800","11.08163","0.00278"
"133.20000","11.10011","0.00270"
"133.42200","11.11858","0.00317"
"133.64400","11.13711","0.00310"
"133.86600","11.15559","0.00259"
"134.08800","11.17413","0.00331"
"134.31000","11.19260","0.00293"
"134.53200","11.21108","0.00330"
"134.75400","11.22967","0.00272"
"134.97600","11.24815","0.00296"
"135.19800","11.26668","0.00348"
"135.42000","11.28521","0.00331"
"135.64200","11.30357","0.00339"
"135.86400","11.32216","0.00314"
"136.08600","11.34058","0.00316"
"136.30800","11.35917","0.00347"
"136.53000","11.37759","0.00261"
"136.75200","11.39606","0.00312"
"136.97400","11.41466","0.00305"
"137.19600","11.43307","0.00359"
"137.41800","11.45167","0.00339"
"137.64000","11.47008","0.00304"
"137.86200","11.48868","0.00332"
"138.08400","11.50715","0.00256"
"138.30600","11.52563","0.00317"
"138.52800","11.54410","0.00290"
"138.75000","11.56258","0.00328"
"138.97200","11.58111","0.00369"
"139.19400","11.59965","0.00317"
"139.41600","11.61812","0.00347"
"139.63800","11.63666","0.00348"
"139.86000","11.65513","0.00371"
"140.08200","11.67361","0.00310"
"140.30400","11.69214","0.00303"
"140.52600","11.71062","0.00372"
"140.74800","11.72915","0.00287"
"140.97000","11.74757","0.00283"
"141.19200","11.76616","0.00359"
"141.41400","11.78464","0.00363"
"141.63600","11.80311","0.00320"
"141.85800","11.82165","0.00316"
"142.08000","11.84012","0.00315"
"142.30200","11.85860","0.00322"
"142.52400","11.87713","0.00301"
"142.74600","11.89567","0.00310"
"142.96800","11.91414","0.00313"
"143.19000","11.93267","0.00364"
"143.41200","11.95115","0.00341"
"143.63400","11.96957","0.00378"
"143.85600","11.98816","0.00335"
"144.07800","12.00663","0.00339"
"144.30000","12.02517","0.00296"
"144.52200","12.04364","0.00337"
"144.74400","12.06212","0.00389"
"144.96600","12.08060","0.00334"
"145.18800","12.09907","0.00354"
"145.41000","12.11760","0.00356"
"145.63200","12.13614","0.00376"
"145.85400","12.15456","0.00358"
"146.07600","12.17315","0.00361"
"146.29800","12.19162","0.00363"
"146.52000","12.21016","0.00393"
"146.74200","12.22863","0.00372"
"146.96400","12.24711","0.00384"
"147.18600","12.26570","0.00379"
"147.40800","12.28406","0.00360"
"147.63000","12.30271","0.00389"
"147.85200","12.32113","0.00344"
"148.07400","12.33966","0.00310"
"148.29600","12.35814","0.00379"
"148.51800","12.37661","0.00363"
"148.74000","12.39515","0.00327"
"148.96200","12.41362","0.00368"
"149.18400","12.43216","0.00413"
"149.40600","12.45057","0.00381"
"149.62800","12.46911","0.00368"
"149.85000","12.48764","0.00391"
"150.07200","12.50606","0.00372"
"150.29400","12.52465","0.00385"
"150.51600","12.54313","0.00352"
"150.73800","12.56166","0.00356"
"150.96000","12.58020","0.00318"
"151.18200","12.59861","0.00394"
"151.40400","12.61715","0.00386"
"151.62600","12.63562","0.00363"
"151.84800","12.65416","0.00357"
"152.07000","12.67269","0.00386"
"152.29200","12.69104","0.00379"
"152.51400","12.70970","0.00393"
"152.73600","12.72812","0.00381"
"152.95800","12.74665","0.00304"
"153.18000","12.76513","0.00420"
"153.40200","12.78360","0.00399"
"153.62400","12.80219","0.00410"
"153.84600","12.82061","0.00391"
"154.06800","12.83914","0.00358"
"154.29000","12.85762","0.00393"
"154.51200","12.87615","0.00361"
"154.73400","12.89463","0.00396"
"154.95600","12.91310","0.00365"
"155.17800","12.93164","0.00358"
"155.40000","12.95012","0.00425"
"155.62200","12.96865","0.00376"
"155.84400","12.98712","0.00434"
"156.06600","13.00560","0.00401"
"156.28800","13.02413","0.00446"
"156.51000","13.04261","0.00417"
"156.73200","13.06114","0.00380"
"156.95400","13.07968","0.00389"
"157.17600","13.09809","0.00442"
"157.39800","13.11663","0.00400"
"157.62000","13.13510","0.00402"
"157.84200","13.15364","0.00383"
"158.06400","13.17211","0.00408"
"158.28600","13.19065","0.00429"
"158.50800","13.20912","0.00368"
"158.73000","13.22760","0.00388"
"158.95200","13.24613","0.00336"
"159.17400","13.26461","0.00351"
"159.39600","13.28314","0.00337"
"159.61800","13.30162","0.00441"
"159.84000","13.32015","0.00376"
"160.06200","13.33863","0.00405"
"160.28400","13.35710","0.00367"
"160.50600","13.37564","0.00378"
"160.72800","13.39411","0.00404"
"160.95000","13.41265","0.00398"
"161.17200","13.43118","0.00422"
"161.39400","13.44960","0.00399"
"161.61600","13.46819","0.00427"
"161.83800","13.48660","0.00412"
"162.06000","13.50508","0.00391"
"162.28200","13.52367","0.00354"
"162.50400","13.54203","0.00402"
"162.72600","13.56063","0.00419"
"162.94800","13.57910","0.00382"
"163.17000","13.59764","0.00391"
"163.39200","13.61617","0.00430"
"163.61400","13.63465","0.00377"
"163.83600","13.65318","0.00446"
"164.05800","13.67159","0.00382"
"164.28000","13.69013","0.00381"
"164.50200","13.70860","0.00382"
"164.72400","13.72714","0.00365"
"164.94600","13.74561","0.00428"
"165.16800","13.76409","0.00454"
"165.39000","13.78262","0.00478"
"165.61200","13.80110","0.00426"
"165.83400","13.81963","0.00454"
"166.05600","13.83817","0.00407"
"166.27800","13.85664","0.00412"
"166.50000","13.87512","0.00422"
"166.72200","13.89359","0.00438"
"166.94400","13.91219","0.00504"
"167.16600","13.93066","0.00416"
"167.38800","13.94908","0.00373"
"167.61000","13.96761","0.00424"
"167.83200","13.98609","0.00406"
"168.05400","14.00462","0.00414"
"168.27600","14.02316","0.00466"
"168.49800","14.04163","0.00451"
"168.72000","14.06017","0.00416"
"168.94200","14.07852","0.00410"
"169.16400","14.09718","0.00428"
"169.38600","14.11565","0.00461"
"169.60800","14.13413","0.00428"
"169.83000","14.15266","0.00454"
"170.05200","14.17102","0.00484"
"170.27400","14.18967","0.00464"
"170.49600","14.20815","0.00452"
"170.71800","14.22662","0.00427"
"170.94000","14.24516","0.00463"
"171.16200","14.26357","0.00473"
"171.38400","14.28217","0.00487"
"171.60600","14.30058","0.00478"
"171.82800","14.31911","0.00479"
"172.05000","14.33765","0.00435"
"172.27200","14.35607","0.00431"
"172.49400","14.37466","0.00452"
"172.71600","14.39307","0.00494"
"172.93800","14.41161","0.00463"
"173.16000","14.43015","0.00437"
"173.38200","14.44862","0.00489"
"173.60400","14.46715","0.00477"
"173.82600","14.48557","0.00407"
"174.04800","14.50416","0.00434"
"174.27000","14.52264","0.00467"
"174.49200","14.54111","0.00463"
"174.71400","14.55959","0.00458"
"174.93600","14.57812","0.00423"
"175.15800","14.59666","0.00438"
"175.38000","14.61507","0.00436"
"175.60200","14.63367","0.00538"
"175.82400","14.65208","0.00451"
"176.04600","14.67062","0.00523"
"176.26800","14.68915","0.00544"
"176.49000","14.70757","0.00490"
"176.71200","14.72610","0.00504"
"176.93400","14.74458","0.00502"
"177.15600","14.76317","0.00446"
"177.37800","14.78159","0.00492"
"177.60000","14.80012","0.00580"
"177.82200","14.81860","0.00491"
"178.04400","14.83707","0.00463"
"178.26600","14.85567","0.00505"
"178.48800","14.87414","0.00564"
"178.71000","14.89262","0.00464"
"178.93200","14.91115","0.00518"
"179.15400","14.92957","0.00530"
"179.37600","14.94816","0.00556"
"179.59800","14.96663","0.00496"
"179.82000","14.98511","0.00506"
"180.04200","15.00364","0.00542"
"180.26400","15.02200","0.00526"
"180.48600","15.04066","0.00512"
"180.70800","15.05907","0.00531"
"180.93000","15.07767","0.00506"
"181.15200","15.09614","0.00531"
"181.37400","15.11462","0.00527"
"181.59600","15.13315","0.00507"
"181.81800","15.15157","0.00512"
"182.04000","15.17016","0.00525"
"182.26200","15.18863","0.00522"
"182.48400","15.20711","0.00609"
"182.70600","15.22564","0.00548"
"182.92800","15.24406","0.00567"
"183.15000","15.26259","0.00588"
"183.37200","15.28113","0.00582"
"183.59400","15.29966","0.00569"
"183.81600","15.31814","0.00584"
"184.03800","15.33655","0.00567"
"184.26000","15.35515","0.00615"
"184.48200","15.37362","0.00567"
"184.70400","15.39210","0.00600"
"184.92600","15.41069","0.00587"
"185.14800","15.42911","0.00583"
"185.37000","15.44764","0.00596"
"185.59200","15.46606","0.00574"
"185.81400","15.48465","0.00555"
"186.03600","15.50313","0.00558"
"186.25800","15.52160","0.00591"
"186.48000","15.54014","0.00550"
"186.70200","15.55855","0.00569"
"186.92400","15.57721","0.00553"
"187.14600","15.59562","0.00571"
"187.36800","15.61416","0.00541"
"187.59000","15.63263","0.00533"
"187.81200","15.65110","0.00606"
"188.03400","15.66964","0.00598"
"188.25600","15.68806","0.00548"
"188.47800","15.70659","0.00554"
"188.70000","15.72512","0.00647"
"188.92200","15.74360","0.00594"
"189.14400","15.76214","0.00574"
"189.36600","15.78061","0.00635"
"189.58800","15.79914","0.00647"
"189.81000","15.81768","0.00648"
"190.03200","15.83615","0.00562"
"190.25400","15.85463","0.00583"
"190.47600","15.87304","0.00617"
"190.69800","15.89164","0.00597"
"190.92000","15.91011","0.00616"
"191.14200","15.92865","0.00549"
"191.36400","15.94712","0.00596"
"191.58600","15.96560","0.00604"
"191.80800","15.98419","0.00603"
"192.03000","16.00261","0.00648"
"192.25200","16.02120","0.00624"
"192.47400","16.03962","0.00633"
"192.69600","16.05815","0.00634"
"192.91800","16.07663","0.00652"
"193.14000","16.09510","0.00652"
"193.36200","16.11364","0.00648"
"193.58400","16.13205","0.00642"
"193.80600","16.15065","0.00642"
"194.02800","16.16918","0.00671"
"194.25000","16.18760","0.00685"
"194.47200","16.20613","0.00639"
"194.69400","16.22461","0.00649"
"194.91600","16.24314","0.00702"
"195.13800","16.26168","0.00671"
"195.36000","16.28009","0.00667"
"195.58200","16.29869","0.00679"
"195.80400","16.31704","0.00718"
"196.02600","16.33570","0.00706"
"196.24800","16.35417","0.00692"
"196.47000","16.37259","0.00691"
"196.69200","16.39118","0.00710"
"196.91400","16.40954","0.00711"
"197.13600","16.42819","0.00694"
"197.35800","16.44661","0.00762"
"197.58000","16.46514","0.00703"
"197.80200","16.48362","0.00759"
"198.02400","16.50209","0.00725"
"198.24600","16.52062","0.00709"
"198.46800","16.53910","0.00736"
"198.69000","16.55763","0.00773"
"198.91200","16.57611","0.00759"
"199.13400","16.59459","0.00789"
"199.35600","16.61318","0.00750"
"199.57800","16.63159","0.00748"
"199.80000","16.65013","0.00774"
"200.02200","16.66860","0.00778"
"200.24400","16.68708","0.00781"
"200.46600","16.70561","0.00782"
"200.68800","16.72409","0.00795"
"200.91000","16.74262","0.00894"
"201.13200","16.76116","0.00799"
"201.35400","16.77963","0.00821"
"201.57600","16.79817","0.00797"
"201.79800","16.81658","0.00826"
"202.02000","16.83512","0.00805"
"202.24200","16.85359","0.00858"
"202.46400","16.87219","0.00802"
"202.68600","16.89066","0.00849"
"202.90800","16.90914","0.00889"
"203.13000","16.92767","0.00894"
"203.35200","16.94615","0.00881"
"203.57400","16.96462","0.00858"
"203.79600","16.98310","0.00910"
"204.01800","17.00163","0.00826"
"204.24000","17.02017","0.00841"
"204.46200","17.03858","0.00891"
"204.68400","17.05712","0.00923"
"204.90600","17.07559","0.00927"
"205.12800","17.09413","0.00901"
"205.35000","17.11266","0.00955"
"205.57200","17.13114","0.00899"
"205.79400","17.14961","0.00976"
"206.01600","17.16809","0.00934"
"206.23800","17.18662","0.00929"
"206.46000","17.20515","0.00996"
"206.68200","17.22363","0.00905"
"206.90400","17.24216","0.00939"
"207.12600","17.26064","0.00974"
"207.34800","17.27911","0.01004"
"207.57000","17.29765","0.00974"
"207.79200","17.31613","0.00982"
"208.01400","17.33466","0.01006"
"208.23600","17.35302","0.01001"
"208.45800","17.37167","0.00977"
"208.68000","17.39009","0.00969"
"208.90200","17.40862","0.01053"
"209.12400","17.42709","0.01018"
"209.34600","17.44563","0.01067"
"209.56800","17.46410","0.01010"
"209.79000","17.48258","0.01068"
"210.01200","17.50111","0.01093"
"210.23400","17.51965","0.01068"
"210.45600","17.53812","0.01119"
"210.67800","17.55666","0.01089"
"210.90000","17.57507","0.01147"
"211.12200","17.59367","0.01115"
"211.34400","17.61214","0.01161"
"211.56600","17.63062","0.01196"
"211.78800","17.64915","0.01174"
"212.01000","17.66757","0.01210"
"212.23200","17.68616","0.01142"
"212.45400","17.70458","0.01192"
"212.67600","17.72317","0.01191"
"212.89800","17.74165","0.01209"
"213.12000","17.76006","0.01262"
"213.34200","17.77866","0.01185"
"213.56400","17.79707","0.01254"
"213.78600","17.81567","0.01211"
"214.00800","17.83408","0.01220"
"214.23000","17.85262","0.01312"
"214.45200","17.87115","0.01304"
"214.67400","17.88957","0.01265"
"214.89600","17.90816","0.01300"
"215.11800","17.92664","0.01284"
"215.34000","17.94511","0.01377"
"215.56200","17.96365","0.01311"
"215.78400","17.98212","0.01364"
"216.00600","18.00060","0.01344"
"216.22800","18.01913","0.01414"
"216.45000","18.03761","0.01382"
"216.67200","18.05614","0.01362"
"216.89400","18.07462","0.01376"
"217.11600","18.09315","0.01415"
"217.33800","18.11162","0.01402"
"217.56000","18.13010","0.01407"
"217.78200","18.14863","0.01435"
"218.00400","18.16711","0.01485"
"218.22600","18.18564","0.01463"
"218.44800","18.20406","0.01472"
"218.67000","18.22265","0.01516"
"218.89200","18.24107","0.01545"
"219.11400","18.25960","0.01621"
"219.33600","18.27814","0.01600"
"219.55800","18.29655","0.01648"
"219.78000","18.31515","0.01616"
"220.00200","18.33356","0.01650"
"220.22400","18.35222","0.01645"
"220.44600","18.37063","0.01707"
"220.66800","18.38917","0.01687"
"220.89000","18.40764","0.01752"
"221.11200","18.42612","0.01738"
"221.33400","18.44465","0.01671"
"221.55600","18.46313","0.01738"
"221.77800","18.48166","0.01746"
"222.00000","18.50014","0.01760"
"222.22200","18.51861","0.01785"
"222.44400","18.53715","0.01782"
"222.66600","18.55562","0.01832"
"222.88800","18.57416","0.01842"
"223.11000","18.59269","0.01866"
"223.33200","18.61105","0.01921"
"223.55400","18.62964","0.01945"
"223.77600","18.64812","0.01983"
"223.99800","18.66665","0.01898"
"224.22000","18.68513","0.01960"
"224.44200","18.70360","0.01987"
"224.66400","18.72219","0.01994"
"224.88600","18.74055","0.02026"
"225.10800","18.75921","0.01961"
"225.33000","18.77762","0.02078"
"225.55200","18.79616","0.02082"
"225.77400","18.81463","0.02133"
"225.99600","18.83311","0.02106"
"226.21800","18.85164","0.02131"
"226.44000","18.87012","0.02164"
"226.66200","18.88865","0.02183"
"226.88400","18.90712","0.02232"
"227.10600","18.92566","0.02231"
"227.32800","18.94414","0.02302"
"227.55000","18.96261","0.02366"
"227.77200","18.98114","0.02277"
"227.99400","18.99968","0.02284"
"228.21600","19.01815","0.02347"
"228.43800","19.03663","0.02384"
"228.66000","19.05504","0.02376"
"228.88200","19.07364","0.02418"
"229.10400","19.09211","0.02438"
"229.32600","19.11065","0.02453"
"229.54800","19.12918","0.02492"
"229.77000","19.14754","0.02532"
"229.99200","19.16613","0.02482"
"230.21400","19.18461","0.02556"
"230.43600","19.20314","0.02561"
"230.65800","19.22162","0.02553"
"230.88000","19.24015","0.02693"
"231.10200","19.25863","0.02651"
"231.32400","19.27710","0.02680"
"231.54600","19.29564","0.02709"
"231.76800","19.31411","0.02702"
"231.99000","19.33265","0.02754"
"232.21200","19.35112","0.02779"
"232.43400","19.36966","0.02802"
"232.65600","19.38813","0.02821"
"232.87800","19.40667","0.02834"
"233.10000","19.42508","0.02877"
"233.32200","19.44368","0.02875"
"233.54400","19.46209","0.02923"
"233.76600","19.48068","0.02895"
"233.98800","19.49916","0.02943"
"234.21000","19.51764","0.03018"
"234.43200","19.53617","0.02994"
"234.65400","19.55458","0.03023"
"234.87600","19.57318","0.03088"
"235.09800","19.59166","0.03135"
"235.32000","19.61019","0.03131"
"235.54200","19.62860","0.03142"
"235.76400","19.64708","0.03183"
"235.98600","19.66561","0.03185"
"236.20800","19.68409","0.03170"
"236.43000","19.70268","0.03209"
"236.65200","19.72104","0.03241"
"236.87400","19.73969","0.03266"
"237.09600","19.75811","0.03247"
"237.31800","19.77664","0.03265"
"237.54000","19.79512","0.03302"
"237.76200","19.81359","0.03319"
"237.98400","19.83213","0.03341"
"238.20600","19.85060","0.03325"
"238.42800","19.86913","0.03352"
"238.65000","19.88767","0.03376"
"238.87200","19.90609","0.03431"
"239.09400","19.92468","0.03431"
"239.31600","19.94310","0.03471"
"239.53800","19.96163","0.03478"
"239.76000","19.98017","0.03478"
"239.98200","19.99858","0.03504"
"240.20400","20.01712","0.03556"
"240.42600","20.03559","0.03532"
"240.64800","20.05413","0.03551"
"240.87000","20.07266","0.03587"
"241.09200","20.09108","0.03591"
"241.31400","20.10967","0.03604"
"241.53600","20.12809","0.03611"
"241.75800","20.14662","0.03688"
"241.98000","20.16510","0.03687"
"242.20200","20.18363","0.03712"
"242.42400","20.20210","0.03717"
"242.64600","20.22058","0.03773"
"242.86800","20.23918","0.03819"
"243.09000","20.25759","0.03816"
"243.31200","20.27612","0.03896"
"243.53400","20.29466","0.03882"
"243.75600","20.31307","0.03890"
"243.97800","20.33161","0.03945"
"244.20000","20.35009","0.04012"
"244.42200","20.36862","0.04024"
"244.64400","20.38715","0.04126"
"244.86600","20.40557","0.04153"
"245.08800","20.42410","0.04214"
"245.31000","20.44258","0.04226"
"245.53200","20.46117","0.04378"
"245.75400","20.47965","0.04418"
"245.97600","20.49812","0.04521"
"246.19800","20.51666","0.04549"
"246.42000","20.53507","0.04542"
"246.64200","20.55367","0.04704"
"246.86400","20.57215","0.04743"
"247.08600","20.59062","0.04875"
"247.30800","20.60915","0.04882"
"247.53000","20.62757","0.04994"
"247.75200","20.64616","0.05118"
"247.97400","20.66458","0.05167"
"248.19600","20.68317","0.05261"
"248.41800","20.70165","0.05375"
"248.64000","20.72012","0.05423"
"248.86200","20.73866","0.05552"
"249.08400","20.75713","0.05609"
"249.30600","20.77561","0.05769"
"249.52800","20.79414","0.05791"
"249.75000","20.81262","0.05921"
"249.97200","20.83121","0.05999"
"250.19400","20.84957","0.06081"
"250.41600","20.86810","0.06161"
"250.63800","20.88658","0.06235"
"250.86000","20.90511","0.06370"
"251.08200","20.92359","0.06425"
"251.30400","20.94206","0.06467"
"251.52600","20.96066","0.06560"
"251.74800","20.97907","0.06663"
"251.97000","20.99761","0.06731"
"252.19200","21.01614","0.06792"
"252.41400","21.03461","0.06920"
"252.63600","21.05315","0.07010"
"252.85800","21.07157","0.07163"
"253.08000","21.09016","0.07210"
"253.30200","21.10858","0.07296"
"253.52400","21.12717","0.07473"
"253.74600","21.14564","0.07601"
"253.96800","21.16406","0.07705"
"254.19000","21.18259","0.07839"
"254.41200","21.20113","0.08018"
"254.63400","21.21967","0.08084"
"254.85600","21.23814","0.08162"
"255.07800","21.25661","0.08297"
"255.30000","21.27515","0.08359"
"255.52200","21.29362","0.08444"
"255.74400","21.31216","0.08509"
"255.96600","21.33069","0.08546"
"256.18800","21.34911","0.08599"
"256.41000","21.36764","0.08586"
"256.63200","21.38606","0.08636"
"256.85400","21.40465","0.08679"
"257.07600","21.42307","0.08705"
"257.29800","21.44160","0.08723"
"257.52000","21.46020","0.08741"
"257.74200","21.47855","0.08763"
"257.96400","21.49721","0.08782"
"258.18600","21.51562","0.08826"
"258.40800","21.53410","0.08937"
"258.63000","21.55263","0.09058"
"258.85200","21.57111","0.09104"
"259.07400","21.58964","0.09273"
"259.29600","21.60812","0.09509"
"259.51800","21.62665","0.09613"
"259.74000","21.64513","0.09863"
"259.96200","21.66360","0.10066"
"260.18400","21.68214","0.10281"
"260.40600","21.70061","0.10390"
"260.62800","21.71909","0.10557"
"260.85000","21.73762","0.10750"
"261.07200","21.75615","0.10957"
"261.29400","21.77463","0.11114"
"261.51600","21.79305","0.11332"
"261.73800","21.81164","0.11418"
"261.96000","21.83005","0.11572"
"262.18200","21.84865","0.11715"
"262.40400","21.86719","0.11855"
"262.62600","21.88560","0.11927"
"262.84800","21.90419","0.12081"
"263.07000","21.92255","0.12169"
"263.29200","21.94121","0.12251"
"263.51400","21.95962","0.12379"
"263.73600","21.97810","0.12483"
"263.95800","21.99663","0.12552"
"264.18000","22.01504","0.12654"
"264.40200","22.03364","0.12826"
"264.62400","22.05211","0.12906"
"264.84600","22.07065","0.12992"
"265.06800","22.08912","0.13162"
"265.29000","22.10760","0.13268"
"265.51200","22.12613","0.13375"
"265.73400","22.14461","0.13470"
"265.95600","22.16308","0.13547"
"266.17800","22.18162","0.13650"
"266.40000","22.20009","0.13738"
"266.62200","22.21863","0.13829"
"266.84400","22.23710","0.13963"
"267.06600","22.25564","0.14113"
"267.28800","22.27417","0.14307"
"267.51000","22.29259","0.14509"
"267.73200","22.31118","0.14719"
"267.95400","22.32954","0.14975"
"268.17600","22.34813","0.15283"
"268.39800","22.36661","0.15671"
"268.62000","22.38514","0.15989"
"268.84200","22.40362","0.16476"
"269.06400","22.42209","0.16917"
"269.28600","22.44069","0.17352"
"269.50800","22.45910","0.17840"
"269.73000","22.47770","0.18195"
"269.95200","22.49611","0.18478"
"270.17400","22.51459","0.18747"
"270.39600","22.53312","0.18868"
"270.61800","22.55160","0.19000"
"270.84000","22.57013","0.19092"
"271.06200","22.58861","0.19188"
"271.28400","22.60714","0.19308"
"271.50600","22.62567","0.19416"
"271.72800","22.64403","0.19671"
"271.95000","22.66262","0.19842"
"272.17200","22.68110","0.19624"
"272.39400","22.69963","0.19155"
"272.61600","22.71817","0.19262"
"272.83800","22.73659","0.19322"
"273.06000","22.75518","0.19415"
"273.28200","22.77360","0.19542"
"273.50400","22.79213","0.19836"
"273.72600","22.81060","0.19706"
"273.94800","22.82908","0.20147"
"274.17000","22.84767","0.20381"
"274.39200","22.86609","0.20727"
"274.61400","22.88468","0.20993"
"274.83600","22.90310","0.21299"
"275.05800","22.92163","0.21566"
"275.28000","22.94017","0.21825"
"275.50200","22.95858","0.22108"
"275.72400","22.97712","0.22428"
"275.94600","22.99565","0.22651"
"276.16800","23.01413","0.22812"
"276.39000","23.03266","0.23018"
"276.61200","23.05114","0.23158"
"276.83400","23.06961","0.23308"
"277.05600","23.08815","0.23407"
"277.27800","23.10662","0.23495"
"277.50000","23.12516","0.23577"
"277.72200","23.14357","0.23631"
"277.94400","23.16217","0.23698"
"278.16600","23.18058","0.23764"
"278.38800","23.19917","0.23821"
"278.61000","23.21759","0.23877"
"278.83200","23.23613","0.23978"
"279.05400","23.25460","0.24028"
"279.27600","23.27308","0.24138"
"279.49800","23.29161","0.24265"
"279.72000","23.31008","0.24426"
"279.94200","23.32868","0.24612"
"280.16400","23.34716","0.24835"
"280.38600","23.36563","0.25093"
"280.60800","23.38416","0.25418"
"280.83000","23.40258","0.25730"
"281.05200","23.42118","0.25975"
"281.27400","23.43965","0.26276"
"281.49600","23.45818","0.26529"
"281.71800","23.47666","0.26682"
"281.94000","23.49513","0.26936"
"282.16200","23.51361","0.27238"
"282.38400","23.53214","0.27579"
"282.60600","23.55062","0.27787"
"282.82800","23.56915","0.28064"
"283.05000","23.58757","0.28214"
"283.27200","23.60616","0.28371"
"283.49400","23.62458","0.28483"
"283.71600","23.64311","0.28581"
"283.93800","23.66171","0.28726"
"284.16000","23.68007","0.28899"
"284.38200","23.69872","0.29080"
"284.60400","23.71707","0.20715"
"284.82600","23.73561","0.19943"
"285.04800","23.75408","0.19632"
"285.27000","23.77262","0.19625"
"285.49200","23.79115","0.19883"
"285.71400","23.80963","0.19920"
"285.93600","23.82816","0.20162"
"286.15800","23.84658","0.20454"
"286.38000","23.86517","0.20708"
"286.60200","23.88365","0.20911"
"286.82400","23.90212","0.21286"
"287.04600","23.92066","0.21326"
"287.26800","23.93907","0.21680"
"287.49000","23.95761","0.21831"
"287.71200","23.97608","0.22028"
"287.93400","23.99462","0.22301"
"288.15600","24.01315","0.22532"
"288.37800","24.03162","0.22718"
"288.60000","24.05016","0.22962"
"288.82200","24.06863","0.23071"
"289.04400","24.08711","0.23191"
"289.26600","24.10565","0.23295"
"289.48800","24.12406","0.23359"
"289.71000","24.14266","0.23468"
"289.93200","24.16113","0.23534"
"290.15400","24.17960","0.23607"
"290.37600","24.19814","0.23637"
"290.59800","24.21655","0.23705"
"290.82000","24.23515","0.23748"
"291.04200","24.25357","0.23813"
"291.26400","24.27216","0.23864"
"291.48600","24.29057","0.23924"
"291.70800","24.30911","0.24011"
"291.93000","24.32764","0.24069"
"292.15200","24.34606","0.24136"
"292.37400","24.36465","0.24250"
"292.59600","24.38313","0.24372"
"292.81800","24.40160","0.24431"
"293.04000","24.42014","0.13751"
"293.26200","24.43861","0.13185"
"293.48400","24.45709","0.12868"
"293.70600","24.47562","0.13318"
"293.92800","24.49416","0.13076"
"294.15000","24.51269","0.13362"
"294.37200","24.53111","0.13170"
"294.59400","24.54964","0.13407"
"294.81600","24.56812","0.13307"
"295.03800","24.58665","0.13558"
"295.26000","24.60519","0.13417"
"295.48200","24.62360","0.13702"
"295.70400","24.64214","0.13607"
"295.92600","24.66055","0.13794"
"296.14800","24.67914","0.13829"
"296.37000","24.69762","0.13969"
"296.59200","24.71610","0.14211"
"296.81400","24.73463","0.14045"
"297.03600","24.75305","0.14923"
"297.25800","24.77164","0.14260"
"297.48000","24.79011","0.15767"
"297.70200","24.80871","0.14504"
"297.92400","24.82707","0.16294"
"298.14600","24.84566","0.15094"
"298.36800","24.86413","0.16701"
"298.59000","24.88261","0.15960"
"298.81200","24.90120","0.17117"
"299.03400","24.91968","0.16546"
"299.25600","24.93810","0.17774"
"299.47800","24.95663","0.16839"
"299.70000","24.97504","0.18515"
"299.92200","24.99364","0.17521"
"300.14400","25.01206","0.18812"
"300.36600","25.03065","0.18286"
"300.58800","25.04918","0.18988"
"300.81000","25.06754","0.18720"
"301.03200","25.08619","0.05467"
"301.25400","25.10461","0.08271"
"301.47600","25.12314","0.04963"
"301.69800","25.14162","0.08555"
"301.92000","25.16009","0.05193"
"302.14200","25.17863","0.07020"
"302.36400","25.19704","0.06588"
"302.58600","25.21570","0.06143"
"302.80800","25.23411","0.08758"
"303.03000","25.25265","0.05655"
"303.25200","25.27112","0.08200"
"303.47400","25.28960","0.06949"
"303.69600","25.30813","0.07787"
"303.91800","25.32661","0.07422"
"304.14000","25.34514","0.07627"
"304.36200","25.36362","0.08447"
"304.58400","25.38215","0.08126"
"304.80600","25.40063","0.08537"
"305.02800","25.41916","0.07194"
"305.25000","25.43764","0.08911"
"305.47200","25.45617","0.08095"
"305.69400","25.47459","0.08764"
"305.91600","25.49318","0.08375"
"306.13800","25.51154","0.08663"
"306.36000","25.53019","0.08838"
"306.58200","25.54861","0.08545"
"306.80400","25.56714","0.08775"
"307.02600","25.58568","0.08727"
"307.24800","25.60403","0.09003"
"307.47000","25.62269","0.08974"
"307.69200","25.64110","0.09130"
"307.91400","25.65963","0.08733"
"308.13600","25.67817","0.10255"
"308.35800","25.69658","0.08907"
"308.58000","25.71512","0.10619"
"308.80200","25.73359","0.08949"
"309.02400","25.75213","0.10122"
"309.24600","25.77061","0.09855"
"309.46800","25.78914","0.10287"
"309.69000","25.80762","0.10529"
"309.91200","25.82609","0.10436"
"310.13400","25.84462","0.10201"
"310.35600","25.86316","0.11139"
"310.57800","25.88157","0.10514"
"310.80000","25.90017","0.11749"
"311.02200","25.91852","0.10905"
"311.24400","25.93712","0.11577"
"311.46600","25.95565","0.11243"
"311.68800","25.97419","0.11585"
"311.91000","25.99266","0.11899"
"312.13200","26.01114","0.11887"
"312.35400","26.02967","0.12007"
"312.57600","26.04809","0.12029"
"312.79800","26.06668","0.11935"
"313.02000","26.08510","0.12332"
"313.24200","26.10357","0.12053"
"313.46400","26.12217","0.12619"
"313.68600","26.14058","0.12236"
"313.90800","26.15917","0.12713"
"314.13000","26.17759","0.12319"
"314.35200","26.19619","0.12648"
"314.57400","26.21466","0.12673"
"314.79600","26.23308","0.12752"
"315.01800","26.25161","0.13072"
"315.24000","26.27009","0.12911"
"315.46200","26.28862","0.13260"
"315.68400","26.30715","0.13000"
"315.90600","26.32563","0.13283"
"316.12800","26.34411","0.13246"
"316.35000","26.36258","0.13337"
"316.57200","26.38117","0.13455"
"316.79400","26.39965","0.13444"
"317.01600","26.41806","0.13640"
"317.23800","26.43666","0.13576"
"317.46000","26.45507","0.13817"
"317.68200","26.47367","0.13740"
"317.90400","26.49208","0.13939"
"318.12600","26.51062","0.13946"
"318.34800","26.52915","0.14078"
"318.57000","26.54757","0.14196"
"318.79200","26.56616","0.14316"
"319.01400","26.58464","0.14682"
"319.23600","26.60312","0.14661"
"319.45800","26.62165","0.15290"
"319.68000","26.64013","0.14969"
"319.90200","26.65866","0.15850"
"320.12400","26.67713","0.15284"
"320.34600","26.69567","0.16253"
"320.56800","26.71414","0.15708"
"320.79000","26.73262","0.16605"
"321.01200","26.75115","0.16471"
"321.23400","26.76957","0.16906"
"321.45600","26.78816","0.17372"
"321.67800","26.80664","0.17431"
"321.90000","26.82511","0.18100"
"322.12200","26.84365","0.17863"
"322.34400","26.86206","0.18365"
"322.56600","26.88066","0.18214"
"322.78800","26.89907","0.18702"
"323.01000","26.91767","0.18519"
"323.23200","26.93614","0.18897"
"323.45400","26.95462","0.18719"
"323.67600","26.97315","0.19043"
"323.89800","26.99157","0.18937"
"324.12000","27.01022","0.19114"
"324.34200","27.02864","0.19063"
"324.56400","27.04711","0.19254"
"324.78600","27.06565","0.19175"
"325.00800","27.08406","0.19177"
"325.23000","27.10266","0.01431"
"325.45200","27.12107","0.01650"
"325.67400","27.13961","0.00529"
"325.89600","27.15808","0.01079"
"326.11800","27.17662","0.01056"
"326.34000","27.19515","0.00808"
"326.56200","27.21362","0.00782"
"326.78400","27.23216","0.01671"
"327.00600","27.25064","0.00837"
"327.22800","27.26911","0.00615"
"327.45000","27.28770","0.01471"
"327.67200","27.30606","0.00885"
"327.89400","27.32459","0.00807"
"328.11600","27.34313","0.01241"
"328.33800","27.36166","0.00853"
"328.56000","27.38014","0.01018"
"328.78200","27.39855","0.01196"
"329.00400","27.41715","0.00799"
"329.22600","27.43556","0.01143"
"329.44800","27.45416","0.00994"
"329.67000","27.47257","0.01000"
"329.89200","27.49111","0.01279"
"330.11400","27.50958","0.00970"
"330.33600","27.52806","0.01186"
"330.55800","27.54665","0.01042"
"330.78000","27.56507","0.01180"
"331.00200","27.58360","0.01211"
"331.22400","27.60214","0.01113"
"331.44600","27.62061","0.01332"
"331.48200","27.62360","0.01377"