File: Force_trajectories/170122_2/Specimen_RawData_6.csv
End date,"1/22/2017"
Specimen label,"3CT_94"
Maximum Load,"1.27545",N

Time,Extension,Load
(s),(mm),(N)
"0.00000","37.82035","0.06402"
"0.20400","37.83434","0.06417"
"0.40800","37.85461","0.06429"
"0.61200","37.87159","0.06490"
"0.81600","37.88851","0.06511"
"1.02000","37.90555","0.06519"
"1.22400","37.92247","0.06522"
"1.42800","37.93951","0.06557"
"1.63200","37.95649","0.06556"
"1.83600","37.97347","0.06606"
"2.04000","37.99057","0.06624"
"2.24400","38.00749","0.06660"
"2.44800","38.02447","0.06674"
"2.65200","38.04151","0.06666"
"2.85600","38.05849","0.06678"
"3.06000","38.07553","0.06711"
"3.26400","38.09257","0.06750"
"3.46800","38.10943","0.06785"
"3.67200","38.12653","0.06811"
"3.87600","38.14345","0.06843"
"4.08000","38.16049","0.06879"
"4.28400","38.17753","0.06894"
"4.48800","38.19445","0.06954"
"4.69200","38.21149","0.07005"
"4.89600","38.22853","0.07018"
"5.10000","38.24545","0.07054"
"5.30400","38.26249","0.07059"
"5.50800","38.27953","0.07123"
"5.71200","38.29645","0.07143"
"5.91600","38.31355","0.07231"
"6.12000","38.33047","0.07288"
"6.32400","38.34751","0.07324"
"6.52800","38.36449","0.07380"
"6.73200","38.38147","0.07396"
"6.93600","38.39851","0.07446"
"7.14000","38.41549","0.07541"
"7.34400","38.43253","0.07614"
"7.54800","38.44952","0.07660"
"7.75200","38.46650","0.07679"
"7.95600","38.48359","0.07805"
"8.16000","38.50045","0.07808"
"8.36400","38.51756","0.07915"
"8.56800","38.53447","0.07964"
"8.77200","38.55145","0.08029"
"8.97600","38.56849","0.08075"
"9.18000","38.58553","0.08116"
"9.38400","38.60252","0.08174"
"9.58800","38.61950","0.08259"
"9.79200","38.63654","0.08352"
"9.99600","38.65345","0.08406"
"10.20000","38.67056","0.08470"
"10.40400","38.68742","0.08541"
"10.60800","38.70451","0.08594"
"10.81200","38.72149","0.08614"
"11.01600","38.73848","0.08729"
"11.22000","38.75552","0.08754"
"11.42400","38.77250","0.08874"
"11.62800","38.78948","0.08912"
"11.83200","38.80652","0.09020"
"12.03600","38.82350","0.09085"
"12.24000","38.84053","0.09053"
"12.44400","38.85752","0.09149"
"12.64800","38.87450","0.09238"
"12.85200","38.89148","0.09290"
"13.05600","38.90852","0.09329"
"13.26000","38.92556","0.09343"
"13.46400","38.94254","0.09413"
"13.66800","38.95946","0.09486"
"13.87200","38.97656","0.09548"
"14.07600","38.99354","0.09600"
"14.28000","39.01052","0.09662"
"14.48400","39.02750","0.09691"
"14.68800","39.04448","0.09833"
"14.89200","39.06152","0.09886"
"15.09600","39.07850","0.09840"
"15.30000","39.09542","0.09956"
"15.50400","39.11251","0.09987"
"15.70800","39.12950","0.10094"
"15.91200","39.14648","0.10175"
"16.11600","39.16351","0.10232"
"16.32000","39.18050","0.10364"
"16.52400","39.19754","0.10408"
"16.72800","39.21446","0.10454"
"16.93200","39.23144","0.10594"
"17.13600","39.24854","0.10598"
"17.34000","39.26540","0.10691"
"17.54400","39.28250","0.10864"
"17.74800","39.29954","0.10871"
"17.95200","39.31646","0.10940"
"18.15600","39.33350","0.11016"
"18.36000","39.35054","0.11122"
"18.56400","39.36746","0.11157"
"18.76800","39.38450","0.11267"
"18.97200","39.40148","0.11268"
"19.17600","39.41852","0.11401"
"19.38000","39.43550","0.11392"
"19.58400","39.45248","0.11481"
"19.78800","39.46952","0.11469"
"19.99200","39.48650","0.11512"
"20.19600","39.50348","0.11566"
"20.40000","39.52052","0.11569"
"20.60400","39.53751","0.11605"
"20.80800","39.55449","0.11633"
"21.01200","39.57153","0.11641"
"21.21600","39.58844","0.11655"
"21.42000","39.60554","0.11670"
"21.62400","39.62246","0.11673"
"21.82800","39.63950","0.11693"
"22.03200","39.65654","0.11728"
"22.23600","39.67353","0.11771"
"22.44000","39.69051","0.11796"
"22.64400","39.70754","0.11788"
"22.84800","39.72446","0.11851"
"23.05200","39.74150","0.11874"
"23.25600","39.75848","0.11940"
"23.46000","39.77546","0.11986"
"23.66400","39.79250","0.12059"
"23.86800","39.80949","0.12113"
"24.07200","39.82652","0.12202"
"24.27600","39.84351","0.12197"
"24.48000","39.86042","0.12411"
"24.68400","39.87747","0.12514"
"24.88800","39.89450","0.12683"
"25.09200","39.91149","0.12847"
"25.29600","39.92852","0.12936"
"25.50000","39.94545","0.13095"
"25.70400","39.96249","0.13210"
"25.90800","39.97947","0.13315"
"26.11200","39.99645","0.13431"
"26.31600","40.01349","0.13583"
"26.52000","40.03046","0.13652"
"26.72400","40.04757","0.13769"
"26.92800","40.06449","0.13944"
"27.13200","40.08141","0.14031"
"27.33600","40.09856","0.14095"
"27.54000","40.11549","0.14191"
"27.74400","40.13247","0.14292"
"27.94800","40.14951","0.14370"
"28.15200","40.16649","0.14459"
"28.35600","40.18353","0.14569"
"28.56000","40.20050","0.14656"
"28.76400","40.21743","0.14727"
"28.96800","40.23453","0.14809"
"29.17200","40.25157","0.14893"
"29.37600","40.26849","0.14951"
"29.58000","40.28553","0.14996"
"29.78400","40.30245","0.15084"
"29.98800","40.31943","0.15108"
"30.19200","40.33653","0.15177"
"30.39600","40.35339","0.15200"
"30.60000","40.37054","0.15262"
"30.80400","40.38747","0.15344"
"31.00800","40.40451","0.15364"
"31.21200","40.42155","0.15453"
"31.41600","40.43847","0.15544"
"31.62000","40.45551","0.15579"
"31.82400","40.47255","0.15677"
"32.02800","40.48947","0.15740"
"32.23200","40.50645","0.15803"
"32.43600","40.52349","0.15923"
"32.64000","40.54053","0.15949"
"32.84400","40.55751","0.16060"
"33.04800","40.57449","0.16129"
"33.25200","40.59148","0.16207"
"33.45600","40.60851","0.16290"
"33.66000","40.62543","0.16332"
"33.86400","40.64248","0.16407"
"34.06800","40.65945","0.16442"
"34.27200","40.67649","0.16507"
"34.47600","40.69353","0.16574"
"34.68000","40.71051","0.16641"
"34.88400","40.72750","0.16712"
"35.08800","40.74447","0.16764"
"35.29200","40.76152","0.16865"
"35.49600","40.77850","0.16989"
"35.70000","40.79547","0.17042"
"35.90400","40.81257","0.17164"
"36.10800","40.82949","0.17264"
"36.31200","40.84642","0.17389"
"36.51600","40.86351","0.17568"
"36.72000","40.88050","0.17750"
"36.92400","40.89754","0.17876"
"37.12800","40.91451","0.18108"
"37.33200","40.93144","0.18297"
"37.53600","40.94854","0.18263"
"37.74000","40.96551","0.18116"
"37.94400","40.98249","0.18566"
"38.14800","40.99947","0.18488"
"38.35200","41.01646","0.18971"
"38.55600","41.03350","0.18999"
"38.76000","41.05054","0.19490"
"38.96400","41.06746","0.19659"
"39.16800","41.08450","0.20176"
"39.37200","41.10154","0.20232"
"39.57600","41.11845","0.20732"
"39.78000","41.13555","0.20755"
"39.98400","41.15248","0.21122"
"40.18800","41.16952","0.21180"
"40.39200","41.18656","0.21413"
"40.59600","41.20342","0.21539"
"40.80000","41.22058","0.21654"
"41.00400","41.23750","0.21751"
"41.20800","41.25448","0.21838"
"41.41200","41.27152","0.21924"
"41.61600","41.28844","0.22006"
"41.82000","41.30548","0.22050"
"42.02400","41.32252","0.22155"
"42.22800","41.33950","0.22093"
"42.43200","41.35654","0.22197"
"42.63600","41.37346","0.22249"
"42.84000","41.39050","0.22393"
"43.04400","41.40754","0.22446"
"43.24800","41.42452","0.22630"
"43.45200","41.44150","0.22741"
"43.65600","41.45853","0.22975"
"43.86000","41.47546","0.23115"
"44.06400","41.49250","0.23395"
"44.26800","41.50948","0.23536"
"44.47200","41.52652","0.23838"
"44.67600","41.54350","0.24062"
"44.88000","41.56042","0.24221"
"45.08400","41.57758","0.24360"
"45.28800","41.59450","0.24559"
"45.49200","41.61142","0.24558"
"45.69600","41.62852","0.24825"
"45.90000","41.64545","0.24924"
"46.10400","41.66254","0.25193"
"46.30800","41.67952","0.25302"
"46.51200","41.69645","0.25491"
"46.71600","41.71354","0.25611"
"46.92000","41.73046","0.25877"
"47.12400","41.74744","0.25963"
"47.32800","41.76454","0.26111"
"47.53200","41.78152","0.26154"
"47.73600","41.79851","0.26284"
"47.94000","41.81554","0.26323"
"48.14400","41.83246","0.26436"
"48.34800","41.84945","0.26483"
"48.55200","41.86654","0.26553"
"48.75600","41.88346","0.26580"
"48.96000","41.90051","0.26630"
"49.16400","41.91742","0.26679"
"49.36800","41.93453","0.26712"
"49.57200","41.95150","0.26761"
"49.77600","41.96843","0.26823"
"49.98000","41.98553","0.26876"
"50.18400","42.00250","0.26906"
"50.38800","42.01949","0.26989"
"50.59200","42.03653","0.27054"
"50.79600","42.05345","0.27123"
"51.00000","42.07055","0.27231"
"51.20400","42.08747","0.27316"
"51.40800","42.10450","0.27372"
"51.61200","42.12149","0.27502"
"51.81600","42.13847","0.27626"
"52.02000","42.15545","0.27820"
"52.22400","42.17254","0.28003"
"52.42800","42.18947","0.28159"
"52.63200","42.20650","0.28404"
"52.83600","42.22354","0.28585"
"53.04000","42.24047","0.28908"
"53.24400","42.25751","0.29028"
"53.44800","42.27443","0.29221"
"53.65200","42.29153","0.29285"
"53.85600","42.30857","0.29576"
"54.06000","42.32543","0.29659"
"54.26400","42.34253","0.29952"
"54.46800","42.35951","0.30122"
"54.67200","42.37648","0.30368"
"54.87600","42.39353","0.30555"
"55.08000","42.41045","0.30779"
"55.28400","42.42755","0.30977"
"55.48800","42.44447","0.31080"
"55.69200","42.46145","0.31227"
"55.89600","42.47855","0.31346"
"56.10000","42.49547","0.31432"
"56.30400","42.51257","0.31487"
"56.50800","42.52949","0.31595"
"56.71200","42.54647","0.31726"
"56.91600","42.56351","0.31833"
"57.12000","42.58055","0.32080"
"57.32400","42.59747","0.32267"
"57.52800","42.61445","0.32557"
"57.73200","42.63149","0.32971"
"57.93600","42.64853","0.33373"
"58.14000","42.66551","0.33804"
"58.34400","42.68249","0.34175"
"58.54800","42.69954","0.34552"
"58.75200","42.71651","0.34853"
"58.95600","42.73343","0.35193"
"59.16000","42.75053","0.35537"
"59.36400","42.76751","0.35870"
"59.56800","42.78449","0.36085"
"59.77200","42.80147","0.36314"
"59.97600","42.81845","0.36536"
"60.18000","42.83549","0.36785"
"60.38400","42.85248","0.36911"
"60.58800","42.86951","0.37052"
"60.79200","42.88650","0.37183"
"60.99600","42.90342","0.37238"
"61.20000","42.92051","0.37340"
"61.40400","42.93750","0.37414"
"61.60800","42.95448","0.37450"
"61.81200","42.97152","0.37525"
"62.01600","42.98849","0.37540"
"62.22000","43.00548","0.37603"
"62.42400","43.02252","0.37638"
"62.62800","43.03949","0.37710"
"62.83200","43.05654","0.37805"
"63.03600","43.07352","0.37924"
"63.24000","43.09044","0.38045"
"63.44400","43.10748","0.38139"
"63.64800","43.12445","0.38248"
"63.85200","43.14150","0.38340"
"64.05600","43.15854","0.38477"
"64.26000","43.17540","0.38629"
"64.46400","43.19256","0.38750"
"64.66800","43.20948","0.38924"
"64.87200","43.22646","0.39094"
"65.07600","43.24356","0.39277"
"65.28000","43.26048","0.39470"
"65.48400","43.27752","0.39736"
"65.68800","43.29450","0.39963"
"65.89200","43.31148","0.40232"
"66.09600","43.32846","0.40717"
"66.30000","43.34550","0.40964"
"66.50400","43.36254","0.41373"
"66.70800","43.37952","0.41627"
"66.91200","43.39656","0.41868"
"67.11600","43.41354","0.41939"
"67.32000","43.43046","0.42098"
"67.52400","43.44750","0.42205"
"67.72800","43.46448","0.42346"
"67.93200","43.48152","0.42456"
"68.13600","43.49850","0.42615"
"68.34000","43.51548","0.42756"
"68.54400","43.53246","0.42969"
"68.74800","43.54950","0.43297"
"68.95200","43.56648","0.43488"
"69.15600","43.58346","0.43748"
"69.36000","43.60056","0.44026"
"69.56400","43.61749","0.44202"
"69.76800","43.63452","0.44482"
"69.97200","43.65150","0.44753"
"70.17600","43.66848","0.44956"
"70.38000","43.68552","0.45222"
"70.58400","43.70244","0.45410"
"70.78800","43.71948","0.45544"
"70.99200","43.73658","0.45753"
"71.19600","43.75350","0.45885"
"71.40000","43.77055","0.46011"
"71.60400","43.78753","0.46107"
"71.80800","43.80444","0.46202"
"72.01200","43.82154","0.46321"
"72.21600","43.83852","0.46391"
"72.42000","43.85544","0.46494"
"72.62400","43.87254","0.46599"
"72.82800","43.88946","0.46734"
"73.03200","43.90644","0.46924"
"73.23600","43.92354","0.47073"
"73.44000","43.94040","0.47334"
"73.64400","43.95757","0.47498"
"73.84800","43.97448","0.47677"
"74.05200","43.99147","0.47941"
"74.25600","44.00856","0.48127"
"74.46000","44.02542","0.48396"
"74.66400","44.04252","0.48611"
"74.86800","44.05951","0.48865"
"75.07200","44.07648","0.49244"
"75.27600","44.09347","0.49488"
"75.48000","44.11051","0.49800"
"75.68400","44.12748","0.50101"
"75.88800","44.14453","0.50435"
"76.09200","44.16151","0.50651"
"76.29600","44.17848","0.50833"
"76.50000","44.19553","0.51068"
"76.70400","44.21251","0.51281"
"76.90800","44.22948","0.51550"
"77.11200","44.24647","0.51791"
"77.31600","44.26351","0.51982"
"77.52000","44.28055","0.52151"
"77.72400","44.29747","0.52284"
"77.92800","44.31451","0.52321"
"78.13200","44.33155","0.52413"
"78.33600","44.34847","0.52496"
"78.54000","44.36551","0.52603"
"78.74400","44.38249","0.52751"
"78.94800","44.39953","0.52999"
"79.15200","44.41651","0.53433"
"79.35600","44.43343","0.53800"
"79.56000","44.45053","0.54224"
"79.76400","44.46745","0.54553"
"79.96800","44.48455","0.54926"
"80.17200","44.50153","0.55283"
"80.37600","44.51851","0.55583"
"80.58000","44.53549","0.55936"
"80.78400","44.55247","0.56203"
"80.98800","44.56945","0.56480"
"81.19200","44.58649","0.56765"
"81.39600","44.60347","0.56911"
"81.60000","44.62051","0.57138"
"81.80400","44.63755","0.57411"
"82.00800","44.65446","0.57617"
"82.21200","44.67151","0.57828"
"82.41600","44.68855","0.57977"
"82.62000","44.70547","0.58146"
"82.82400","44.72251","0.58283"
"83.02800","44.73943","0.58383"
"83.23200","44.75647","0.58495"
"83.43600","44.77351","0.58621"
"83.64000","44.79043","0.58691"
"83.84400","44.80759","0.58804"
"84.04800","44.82452","0.58895"
"84.25200","44.84149","0.59056"
"84.45600","44.85854","0.59208"
"84.66000","44.87545","0.59356"
"84.86400","44.89249","0.59625"
"85.06800","44.90947","0.59903"
"85.27200","44.92651","0.60199"
"85.47600","44.94349","0.60562"
"85.68000","44.96053","0.60973"
"85.88400","44.97752","0.61466"
"86.08800","44.99450","0.61971"
"86.29200","45.01147","0.62237"
"86.49600","45.02851","0.62514"
"86.70000","45.04549","0.62723"
"86.90400","45.06247","0.62872"
"87.10800","45.07951","0.63013"
"87.31200","45.09649","0.63285"
"87.51600","45.11353","0.63492"
"87.72000","45.13052","0.63927"
"87.92400","45.14743","0.64361"
"88.12800","45.16453","0.64747"
"88.33200","45.18151","0.65347"
"88.53600","45.19850","0.65819"
"88.74000","45.21553","0.66115"
"88.94400","45.23246","0.66411"
"89.14800","45.24955","0.66656"
"89.35200","45.26654","0.66900"
"89.55600","45.28346","0.67096"
"89.76000","45.30056","0.67239"
"89.96400","45.31748","0.67314"
"90.16800","45.33451","0.67399"
"90.37200","45.35150","0.67499"
"90.57600","45.36848","0.67519"
"90.78000","45.38551","0.67610"
"90.98400","45.40250","0.67671"
"91.18800","45.41948","0.67778"
"91.39200","45.43646","0.67910"
"91.59600","45.45350","0.68027"
"91.80000","45.47048","0.68187"
"92.00400","45.48751","0.68348"
"92.20800","45.50450","0.68519"
"92.41200","45.52154","0.68725"
"92.61600","45.53851","0.69038"
"92.82000","45.55544","0.69363"
"93.02400","45.57260","0.69753"
"93.22800","45.58946","0.70107"
"93.43200","45.60650","0.70516"
"93.63600","45.62348","0.70868"
"93.84000","45.64046","0.71148"
"94.04400","45.65756","0.71590"
"94.24800","45.67448","0.71997"
"94.45200","45.69152","0.72332"
"94.65600","45.70850","0.72737"
"94.86000","45.72548","0.73068"
"95.06400","45.74252","0.73293"
"95.26800","45.75950","0.73419"
"95.47200","45.77642","0.73516"
"95.67600","45.79352","0.73574"
"95.88000","45.81050","0.73671"
"96.08400","45.82748","0.73821"
"96.28800","45.84452","0.74205"
"96.49200","45.86150","0.74589"
"96.69600","45.87848","0.74956"
"96.90000","45.89552","0.75342"
"97.10400","45.91245","0.75762"
"97.30800","45.92954","0.76160"
"97.51200","45.94652","0.76606"
"97.71600","45.96344","0.76976"
"97.92000","45.98054","0.77311"
"98.12400","45.99746","0.77603"
"98.32800","46.01456","0.77762"
"98.53200","46.03148","0.78075"
"98.73600","46.04847","0.78277"
"98.94000","46.06551","0.78479"
"99.14400","46.08248","0.78651"
"99.34800","46.09952","0.78810"
"99.55200","46.11657","0.78908"
"99.75600","46.13348","0.79014"
"99.96000","46.15052","0.79081"
"100.16400","46.16750","0.79238"
"100.36800","46.18449","0.79369"
"100.57200","46.20147","0.79628"
"100.77600","46.21851","0.79825"
"100.98000","46.23549","0.80208"
"101.18400","46.25253","0.80427"
"101.38800","46.26945","0.80730"
"101.59200","46.28654","0.81043"
"101.79600","46.30352","0.81375"
"102.00000","46.32045","0.81848"
"102.20400","46.33755","0.82162"
"102.40800","46.35447","0.82427"
"102.61200","46.37151","0.82664"
"102.81600","46.38849","0.82797"
"103.02000","46.40546","0.82974"
"103.22400","46.42256","0.83247"
"103.42800","46.43949","0.83677"
"103.63200","46.45646","0.84024"
"103.83600","46.47351","0.84645"
"104.04000","46.49043","0.72239"
"104.24400","46.50753","0.72777"
"104.44800","46.52451","0.73024"
"104.65200","46.54149","0.72993"
"104.85600","46.55847","0.73099"
"105.06000","46.57551","0.73354"
"105.26400","46.59249","0.73492"
"105.46800","46.60953","0.73502"
"105.67200","46.62645","0.73510"
"105.87600","46.64355","0.73637"
"106.08000","46.66053","0.73937"
"106.28400","46.67745","0.74194"
"106.48800","46.69449","0.74541"
"106.69200","46.71147","0.75110"
"106.89600","46.72851","0.75787"
"107.10000","46.74554","0.76265"
"107.30400","46.76247","0.76584"
"107.50800","46.77951","0.77008"
"107.71200","46.79649","0.77583"
"107.91600","46.81347","0.77822"
"108.12000","46.83057","0.78010"
"108.32400","46.84743","0.78257"
"108.52800","46.86453","0.78519"
"108.73200","46.88151","0.78707"
"108.93600","46.89843","0.78785"
"109.14000","46.91553","0.78887"
"109.34400","46.93251","0.79035"
"109.54800","46.94949","0.79179"
"109.75200","46.96653","0.79267"
"109.95600","46.98351","0.79411"
"110.16000","47.00049","0.79596"
"110.36400","47.01747","0.79828"
"110.56800","47.03445","0.80134"
"110.77200","47.05149","0.80347"
"110.97600","47.06847","0.80576"
"111.18000","47.08551","0.80859"
"111.38400","47.10250","0.81130"
"111.58800","47.11948","0.81511"
"111.79200","47.13651","0.81757"
"111.99600","47.15350","0.82077"
"112.20000","47.17041","0.82349"
"112.40400","47.18751","0.82573"
"112.60800","47.20449","0.82811"
"112.81200","47.22153","0.83010"
"113.01600","47.23851","0.83317"
"113.22000","47.25544","0.83798"
"113.42400","47.27254","0.84299"
"113.62800","47.28945","0.84783"
"113.83200","47.30649","0.85318"
"114.03600","47.32354","0.85847"
"114.24000","47.34045","0.86366"
"114.44400","47.35749","0.86828"
"114.64800","47.37448","0.87175"
"114.85200","47.39146","0.87594"
"115.05600","47.40856","0.87979"
"115.26000","47.42553","0.88260"
"115.46400","47.44252","0.88486"
"115.66800","47.45950","0.88638"
"115.87200","47.47648","0.88729"
"116.07600","47.49346","0.88780"
"116.28000","47.51056","0.88820"
"116.48400","47.52748","0.88871"
"116.68800","47.54452","0.88958"
"116.89200","47.56150","0.89100"
"117.09600","47.57848","0.89328"
"117.30000","47.59552","0.89480"
"117.50400","47.61250","0.89646"
"117.70800","47.62954","0.89834"
"117.91200","47.64652","0.90091"
"118.11600","47.66344","0.90383"
"118.32000","47.68047","0.90708"
"118.52400","47.69752","0.91091"
"118.72800","47.71450","0.91478"
"118.93200","47.73154","0.91708"
"119.13600","47.74846","0.92072"
"119.34000","47.76550","0.92286"
"119.54400","47.78248","0.92736"
"119.74800","47.79946","0.93125"
"119.95200","47.81650","0.93401"
"120.15600","47.83348","0.79772"
"120.36000","47.85052","0.79413"
"120.56400","47.86750","0.79758"
"120.76800","47.88448","0.79927"
"120.97200","47.90152","0.79564"
"121.17600","47.91850","0.79505"
"121.38000","47.93542","0.79909"
"121.58400","47.95258","0.80434"
"121.78800","47.96950","0.80483"
"121.99200","47.98655","0.80239"
"122.19600","48.00352","0.80478"
"122.40000","48.02044","0.80941"
"122.60400","48.03754","0.81541"
"122.80800","48.05452","0.81700"
"123.01200","48.07150","0.81739"
"123.21600","48.08848","0.82160"
"123.42000","48.10546","0.82488"
"123.62400","48.12250","0.77878"
"123.82800","48.13948","0.78055"
"124.03200","48.15646","0.78132"
"124.23600","48.17356","0.78456"
"124.44000","48.19049","0.78729"
"124.64400","48.20746","0.78825"
"124.84800","48.22450","0.78902"
"125.05200","48.24149","0.79030"
"125.25600","48.25853","0.79313"
"125.46000","48.27556","0.79613"
"125.66400","48.29248","0.79837"
"125.86800","48.30953","0.80023"
"126.07200","48.32644","0.80336"
"126.27600","48.34348","0.80774"
"126.48000","48.36053","0.81208"
"126.68400","48.37744","0.81343"
"126.88800","48.39454","0.81683"
"127.09200","48.41153","0.82179"
"127.29600","48.42844","0.82476"
"127.50000","48.44548","0.82628"
"127.70400","48.46247","0.82817"
"127.90800","48.47951","0.83024"
"128.11200","48.49654","0.83476"
"128.31600","48.51347","0.84022"
"128.52000","48.53051","0.84580"
"128.72400","48.54749","0.84934"
"128.92800","48.56452","0.85476"
"129.13200","48.58151","0.86072"
"129.33600","48.59849","0.86577"
"129.54000","48.61547","0.74565"
"129.74400","48.63251","0.74876"
"129.94800","48.64943","0.74540"
"130.15200","48.66647","0.74380"
"130.35600","48.68351","0.75304"
"130.56000","48.70055","0.76201"
"130.76400","48.71753","0.76318"
"130.96800","48.73445","0.76358"
"131.17200","48.75155","0.76953"
"131.37600","48.76853","0.77590"
"131.58000","48.78545","0.77792"
"131.78400","48.80249","0.77839"
"131.98800","48.81947","0.78031"
"132.19200","48.83651","0.78396"
"132.39600","48.85355","0.78578"
"132.60000","48.87047","0.78627"
"132.80400","48.88757","0.78740"
"133.00800","48.90443","0.78947"
"133.21200","48.92147","0.79065"
"133.41600","48.93851","0.79170"
"133.62000","48.95549","0.79283"
"133.82400","48.97253","0.79495"
"134.02800","48.98951","0.79873"
"134.23200","49.00649","0.80146"
"134.43600","49.02347","0.80280"
"134.64000","49.04051","0.80609"
"134.84400","49.05749","0.81052"
"135.04800","49.07454","0.81505"
"135.25200","49.09145","0.81697"
"135.45600","49.10849","0.81978"
"135.66000","49.12553","0.82276"
"135.86400","49.14251","0.82546"
"136.06800","49.15949","0.82756"
"136.27200","49.17653","0.82876"
"136.47600","49.19351","0.83138"
"136.68000","49.21056","0.83627"
"136.88400","49.22748","0.84110"
"137.08800","49.24458","0.84514"
"137.29200","49.26149","0.84829"
"137.49600","49.27848","0.85394"
"137.70000","49.29551","0.85991"
"137.90400","49.31249","0.86566"
"138.10800","49.32948","0.86890"
"138.31200","49.34652","0.87305"
"138.51600","49.36349","0.87730"
"138.72000","49.38054","0.88146"
"138.92400","49.39752","0.88408"
"139.12800","49.41443","0.88567"
"139.33200","49.43153","0.88677"
"139.53600","49.44846","0.88758"
"139.74000","49.46549","0.88803"
"139.94400","49.48253","0.88843"
"140.14800","49.49945","0.88902"
"140.35200","49.51650","0.89004"
"140.55600","49.53354","0.89112"
"140.76000","49.55046","0.89291"
"140.96400","49.56756","0.89434"
"141.16800","49.58447","0.89657"
"141.37200","49.60151","0.89727"
"141.57600","49.61856","0.89928"
"141.78000","49.63548","0.90204"
"141.98400","49.65251","0.90460"
"142.18800","49.66944","0.90698"
"142.39200","49.68648","0.90934"
"142.59600","49.70352","0.91233"
"142.80000","49.72050","0.91577"
"143.00400","49.73754","0.91904"
"143.20800","49.75452","0.92224"
"143.41200","49.77150","0.92630"
"143.61600","49.78848","0.92926"
"143.82000","49.80545","0.93218"
"144.02400","49.82256","0.93534"
"144.22800","49.83954","0.93691"
"144.43200","49.85646","0.93870"
"144.63600","49.87350","0.93983"
"144.84000","49.89048","0.94159"
"145.04400","49.90746","0.94301"
"145.24800","49.92450","0.94514"
"145.45200","49.94148","0.94916"
"145.65600","49.95852","0.95358"
"145.86000","49.97550","0.95757"
"146.06400","49.99242","0.96105"
"146.26800","50.00958","0.96392"
"146.47200","50.02644","0.96672"
"146.67600","50.04348","0.96926"
"146.88000","50.06052","0.97175"
"147.08400","50.07744","0.97333"
"147.28800","50.09448","0.97476"
"147.49200","50.11153","0.97683"
"147.69600","50.12844","0.97763"
"147.90000","50.14554","0.97941"
"148.10400","50.16246","0.98164"
"148.30800","50.17950","0.98274"
"148.51200","50.19654","0.98549"
"148.71600","50.21346","0.98799"
"148.92000","50.23050","0.99018"
"149.12400","50.24748","0.99232"
"149.32800","50.26446","0.99425"
"149.53200","50.28151","0.99599"
"149.73600","50.29848","0.99749"
"149.94000","50.31546","1.00073"
"150.14400","50.33257","1.00397"
"150.34800","50.34942","1.00697"
"150.55200","50.36652","1.01095"
"150.75600","50.38350","1.01428"
"150.96000","50.40048","1.01705"
"151.16400","50.41752","1.02098"
"151.36800","50.43445","1.02462"
"151.57200","50.45149","1.02891"
"151.77600","50.46852","1.03291"
"151.98000","50.48551","1.03621"
"152.18400","50.50249","1.03871"
"152.38800","50.51946","1.04093"
"152.59200","50.53645","1.04307"
"152.79600","50.55349","1.04652"
"153.00000","50.57047","1.05014"
"153.20400","50.58751","1.05563"
"153.40800","50.60449","1.05987"
"153.61200","50.62146","1.06383"
"153.81600","50.63850","1.06700"
"154.02000","50.65555","1.07065"
"154.22400","50.67246","1.07338"
"154.42800","50.68950","1.07606"
"154.63200","50.70642","1.07829"
"154.83600","50.72347","1.08125"
"155.04000","50.74051","1.08338"
"155.24400","50.75743","1.08458"
"155.44800","50.77447","1.08614"
"155.65200","50.79145","1.08704"
"155.85600","50.80849","1.08803"
"156.06000","50.82553","1.08879"
"156.26400","50.84245","1.08975"
"156.46800","50.85954","1.09063"
"156.67200","50.87647","1.09166"
"156.87600","50.89351","1.09262"
"157.08000","50.91055","1.09441"
"157.28400","50.92747","1.09642"
"157.48800","50.94451","1.09874"
"157.69200","50.96149","1.10125"
"157.89600","50.97847","1.10360"
"158.10000","50.99551","1.10711"
"158.30400","51.01255","1.10980"
"158.50800","51.02947","1.11346"
"158.71200","51.04651","1.11695"
"158.91600","51.06343","1.11999"
"159.12000","51.08047","1.12607"
"159.32400","51.09751","1.13173"
"159.52800","51.11443","1.13754"
"159.73200","51.13153","1.14211"
"159.93600","51.14845","1.14581"
"160.14000","51.16549","1.14868"
"160.34400","51.18253","1.15183"
"160.54800","51.19952","1.15394"
"160.75200","51.21649","1.15614"
"160.95600","51.23353","0.98948"
"161.16000","51.25045","0.98410"
"161.36400","51.26749","0.98067"
"161.56800","51.28447","0.97931"
"161.77200","51.30151","0.98089"
"161.97600","51.31849","0.98593"
"162.18000","51.33554","0.98997"
"162.38400","51.35251","0.99153"
"162.58800","51.36950","0.99049"
"162.79200","51.38647","0.99128"
"162.99600","51.40345","0.99390"
"163.20000","51.42049","1.00029"
"163.40400","51.43753","1.00665"
"163.60800","51.45451","1.01012"
"163.81200","51.47149","1.01034"
"164.01600","51.48848","1.01228"
"164.22000","51.50551","1.01651"
"164.42400","51.52250","1.02312"
"164.62800","51.53954","1.03029"
"164.83200","51.55651","1.03405"
"165.03600","51.57355","1.03564"
"165.24000","51.59053","1.03715"
"165.44400","51.60745","1.03893"
"165.64800","51.62450","1.04199"
"165.85200","51.64148","1.04597"
"166.05600","51.65852","1.04965"
"166.26000","51.67550","1.05250"
"166.46400","51.69248","1.05445"
"166.66800","51.70952","1.05756"
"166.87200","51.72649","1.06170"
"167.07600","51.74348","1.06621"
"167.28000","51.76052","1.07098"
"167.48400","51.77750","1.07462"
"167.68800","51.79448","1.07761"
"167.89200","51.81158","1.07977"
"168.09600","51.82844","1.08160"
"168.30000","51.84554","1.08414"
"168.50400","51.86252","1.08618"
"168.70800","51.87944","1.08764"
"168.91200","51.89653","1.08878"
"169.11600","51.91346","1.08957"
"169.32000","51.93050","1.09028"
"169.52400","51.94754","1.09082"
"169.72800","51.96446","1.09198"
"169.93200","51.98156","1.09324"
"170.13600","51.99848","1.09481"
"170.34000","52.01546","1.09716"
"170.54400","52.03250","1.09951"
"170.74800","52.04942","1.10163"
"170.95200","52.06652","1.10466"
"171.15600","52.08356","1.10748"
"171.36000","52.10048","1.11040"
"171.56400","52.11752","1.11370"
"171.76800","52.13444","1.11734"
"171.97200","52.15148","1.12152"
"172.17600","52.16852","1.12745"
"172.38000","52.18550","1.13383"
"172.58400","52.20248","1.14037"
"172.78800","52.21946","1.14462"
"172.99200","52.23644","1.14845"
"173.19600","52.25349","1.15196"
"173.40000","52.27052","1.15487"
"173.60400","52.28756","1.15881"
"173.80800","52.30454","1.16281"
"174.01200","52.32146","1.16768"
"174.21600","52.33850","1.17088"
"174.42000","52.35554","1.17536"
"174.62400","52.37240","1.17907"
"174.82800","52.38956","1.18356"
"175.03200","52.40649","1.18790"
"175.23600","52.42352","1.19152"
"175.44000","52.44050","1.19448"
"175.64400","52.45749","0.97085"
"175.84800","52.47452","0.97605"
"176.05200","52.49150","0.98331"
"176.25600","52.50848","0.98484"
"176.46000","52.52552","0.97850"
"176.66400","52.54245","0.97569"
"176.86800","52.55954","0.97795"
"177.07200","52.57653","0.98505"
"177.27600","52.59350","0.99068"
"177.48000","52.61049","0.98824"
"177.68400","52.62753","0.98525"
"177.88800","52.64444","0.98619"
"178.09200","52.66149","0.99064"
"178.29600","52.67847","0.99615"
"178.50000","52.69551","0.99617"
"178.70400","52.71254","0.99399"
"178.90800","52.72947","0.99462"
"179.11200","52.74657","0.99892"
"179.31600","52.76348","1.00779"
"179.52000","52.78047","1.01326"
"179.72400","52.79750","1.01357"
"179.92800","52.81454","1.01246"
"180.13200","52.83153","1.01441"
"180.33600","52.84845","1.02054"
"180.54000","52.86549","1.02948"
"180.74400","52.88253","1.03279"
"180.94800","52.89945","1.03284"
"181.15200","52.91648","1.03304"
"181.35600","52.93353","1.03659"
"181.56000","52.95045","1.04067"
"181.76400","52.96755","1.04422"
"181.96800","52.98452","1.04646"
"182.17200","53.00151","1.04713"
"182.37600","53.01849","1.04872"
"182.58000","53.03547","1.05092"
"182.78400","53.05251","1.05685"
"182.98800","53.06955","1.06233"
"183.19200","53.08641","1.06562"
"183.39600","53.10351","1.06649"
"183.60000","53.12055","1.06792"
"183.80400","53.13754","1.07024"
"184.00800","53.15457","1.07443"
"184.21200","53.17149","1.07838"
"184.41600","53.18853","1.08093"
"184.62000","53.20551","1.08218"
"184.82400","53.22243","1.08292"
"185.02800","53.23953","1.08450"
"185.23200","53.25645","1.08606"
"185.43600","53.27349","1.08782"
"185.64000","53.29053","1.08890"
"185.84400","53.30751","1.08908"
"186.04800","53.32449","1.08955"
"186.25200","53.34153","1.09006"
"186.45600","53.35851","1.09059"
"186.66000","53.37549","1.09127"
"186.86400","53.39253","1.09237"
"187.06800","53.40951","1.09350"
"187.27200","53.42649","1.09433"
"187.47600","53.44347","1.09481"
"187.68000","53.46052","1.09677"
"187.88400","53.47755","1.09803"
"188.08800","53.49448","1.09998"
"188.29200","53.51152","1.10326"
"188.49600","53.52849","1.10504"
"188.70000","53.54554","1.10731"
"188.90400","53.56252","1.10935"
"189.10800","53.57949","1.11129"
"189.31200","53.59653","1.11471"
"189.51600","53.61345","1.11818"
"189.72000","53.63049","1.12203"
"189.92400","53.64753","1.12644"
"190.12800","53.66439","1.13072"
"190.33200","53.68155","1.13425"
"190.53600","53.69847","1.13794"
"190.74000","53.71545","1.14115"
"190.94400","53.73249","1.14568"
"191.14800","53.74948","1.14824"
"191.35200","53.76646","1.15019"
"191.55600","53.78350","1.15223"
"191.76000","53.80053","1.15322"
"191.96400","53.81752","1.15625"
"192.16800","53.83450","1.15912"
"192.37200","53.85147","1.16292"
"192.57600","53.86852","1.16758"
"192.78000","53.88550","1.17116"
"192.98400","53.90254","1.17522"
"193.18800","53.91952","1.17901"
"193.39200","53.93644","1.18228"
"193.59600","53.95354","1.18625"
"193.80000","53.97052","1.18990"
"194.00400","53.98743","1.19326"
"194.20800","54.00454","1.19627"
"194.41200","54.02146","1.19813"
"194.61600","54.03850","1.19953"
"194.82000","54.05554","1.20055"
"195.02400","54.07246","1.20157"
"195.22800","54.08950","1.20248"
"195.43200","54.10648","1.20393"
"195.63600","54.12352","1.20489"
"195.84000","54.14050","1.20572"
"196.04400","54.15748","1.20690"
"196.24800","54.17451","1.20809"
"196.45200","54.19150","1.20951"
"196.65600","54.20848","1.21174"
"196.86000","54.22558","1.21400"
"197.06400","54.24250","1.21659"
"197.26800","54.25948","1.21977"
"197.47200","54.27652","1.22327"
"197.67600","54.29350","1.22811"
"197.88000","54.31048","1.23251"
"198.08400","54.32752","1.23463"
"198.28800","54.34444","1.23705"
"198.49200","54.36154","1.13786"
"198.69600","54.37846","0.99038"
"198.90000","54.39550","0.98193"
"199.10400","54.41254","0.98052"
"199.30800","54.42946","0.98254"
"199.51200","54.44656","0.98522"
"199.71600","54.46348","0.98580"
"199.92000","54.48046","0.98654"
"200.12400","54.49750","0.98721"
"200.32800","54.51448","0.98978"
"200.53200","54.53147","0.99249"
"200.73600","54.54850","0.99611"
"200.94000","54.56543","0.99757"
"201.14400","54.58258","1.00028"
"201.34800","54.59956","1.00402"
"201.55200","54.61648","1.00998"
"201.75600","54.63353","1.01488"
"201.96000","54.65044","1.01937"
"202.16400","54.66748","1.02308"
"202.36800","54.68458","1.02750"
"202.57200","54.70145","1.03252"
"202.77600","54.71848","1.03699"
"202.98000","54.73547","1.04009"
"203.18400","54.75245","1.04268"
"203.38800","54.76955","1.04500"
"203.59200","54.78646","1.04694"
"203.79600","54.80350","1.04921"
"204.00000","54.82055","1.05281"
"204.20400","54.83746","1.05735"
"204.40800","54.85451","1.06199"
"204.61200","54.87148","1.06507"
"204.81600","54.88852","1.06814"
"205.02000","54.90551","1.07004"
"205.22400","54.92249","1.07251"
"205.42800","54.93952","1.07539"
"205.63200","54.95651","1.07931"
"205.83600","54.97349","1.08208"
"206.04000","54.99047","1.08456"
"206.24400","55.00751","1.08523"
"206.44800","55.02449","1.08704"
"206.65200","55.04153","1.08769"
"206.85600","55.05845","1.08888"
"207.06000","55.07549","1.08980"
"207.26400","55.09253","1.09061"
"207.46800","55.10945","1.09150"
"207.67200","55.12655","1.09233"
"207.87600","55.14353","1.09433"
"208.08000","55.16051","1.09684"
"208.28400","55.17755","1.09903"
"208.48800","55.19441","1.10214"
"208.69200","55.21151","1.10567"
"208.89600","55.22849","1.10875"
"209.10000","55.24553","1.11149"
"209.30400","55.26251","1.11447"
"209.50800","55.27949","1.11756"
"209.71200","55.29653","1.12129"
"209.91600","55.31351","1.12620"
"210.12000","55.33049","1.13067"
"210.32400","55.34753","1.13724"
"210.52800","55.36451","1.14243"
"210.73200","55.38149","1.14653"
"210.93600","55.39853","1.15010"
"211.14000","55.41552","1.15386"
"211.34400","55.43249","1.15676"
"211.54800","55.44953","1.16073"
"211.75200","55.46645","1.16407"
"211.95600","55.48349","1.16811"
"212.16000","55.50047","1.17276"
"212.36400","55.51751","1.17524"
"212.56800","55.53455","1.17899"
"212.77200","55.55141","1.18226"
"212.97600","55.56852","1.18658"
"213.18000","55.58549","1.18904"
"213.38400","55.60247","1.19182"
"213.58800","55.61951","1.19471"
"213.79200","55.63649","1.19651"
"213.99600","55.65353","1.19787"
"214.20000","55.67051","1.19923"
"214.40400","55.68750","1.20027"
"214.60800","55.70453","1.20129"
"214.81200","55.72145","1.20226"
"215.01600","55.73850","1.20301"
"215.22000","55.75547","1.20421"
"215.42400","55.77251","1.20490"
"215.62800","55.78950","1.20573"
"215.83200","55.80647","1.20638"
"216.03600","55.82346","1.20695"
"216.24000","55.84050","1.00703"
"216.44400","55.85753","0.99639"
"216.64800","55.87452","0.99121"
"216.85200","55.89150","0.99202"
"217.05600","55.90848","0.99618"
"217.26000","55.92551","0.99718"
"217.46400","55.94250","0.99505"
"217.66800","55.95948","0.99412"
"217.87200","55.97651","0.99572"
"218.07600","55.99350","1.00023"
"218.28000","56.01054","1.00355"
"218.48400","56.02752","1.00232"
"218.68800","56.04444","1.00062"
"218.89200","56.06160","1.00336"
"219.09600","56.07846","1.00864"
"219.30000","56.09550","1.01390"
"219.50400","56.11254","1.01423"
"219.70800","56.12946","1.01396"
"219.91200","56.14650","1.01536"
"220.11600","56.16354","1.02006"
"220.32000","56.18052","1.02608"
"220.52400","56.19750","1.02971"
"220.72800","56.21454","1.03011"
"220.93200","56.23146","1.03164"
"221.13600","56.24850","1.03373"
"221.34000","56.26542","1.03874"
"221.54400","56.28252","1.04109"
"221.74800","56.29950","1.04244"
"221.95200","56.31642","1.04283"
"222.15600","56.33358","1.04432"
"222.36000","56.35050","1.04667"
"222.56400","56.36748","1.05050"
"222.76800","56.38452","1.05410"
"222.97200","56.40150","1.05573"
"223.17600","56.41854","1.05755"
"223.38000","56.43546","1.06116"
"223.58400","56.45244","1.06462"
"223.78800","56.46948","1.06838"
"223.99200","56.48647","1.07007"
"224.19600","56.50351","1.07124"
"224.40000","56.52054","1.07252"
"224.60400","56.53746","1.07485"
"224.80800","56.55456","1.07828"
"225.01200","56.57154","1.08073"
"225.21600","56.58846","1.08239"
"225.42000","56.60550","1.08367"
"225.62400","56.62248","1.08494"
"225.82800","56.63946","1.08608"
"226.03200","56.65656","1.08771"
"226.23600","56.67342","1.08868"
"226.44000","56.69052","1.08945"
"226.64400","56.70750","1.08968"
"226.84800","56.72442","1.09019"
"227.05200","56.74158","1.09074"
"227.25600","56.75845","1.09185"
"227.46000","56.77548","1.09319"
"227.66400","56.79253","1.09392"
"227.86800","56.80945","1.09506"
"228.07200","56.82655","1.09579"
"228.27600","56.84346","1.09684"
"228.48000","56.86050","1.09820"
"228.68400","56.87754","1.09991"
"228.88800","56.89446","1.10150"
"229.09200","56.91150","1.10348"
"229.29600","56.92855","1.10576"
"229.50000","56.94547","1.10795"
"229.70400","56.96244","1.11111"
"229.90800","56.97949","1.11410"
"230.11200","56.99646","1.11672"
"230.31600","57.01350","1.11998"
"230.52000","57.03049","1.12420"
"230.72400","57.04753","1.12867"
"230.92800","57.06456","1.13483"
"231.13200","57.08149","1.13932"
"231.33600","57.09853","1.14420"
"231.54000","57.11551","1.14827"
"231.74400","57.13248","1.14983"
"231.94800","57.14953","1.15248"
"232.15200","57.16639","1.15524"
"232.35600","57.18354","1.15831"
"232.56000","57.20047","1.16260"
"232.76400","57.21751","1.16795"
"232.96800","57.23449","1.17216"
"233.17200","57.25147","1.17649"
"233.37600","57.26851","1.18056"
"233.58000","57.28555","1.18474"
"233.78400","57.30247","1.18798"
"233.98800","57.31951","1.19217"
"234.19200","57.33643","1.19506"
"234.39600","57.35347","1.19693"
"234.60000","57.37051","1.19853"
"234.80400","57.38749","1.19934"
"235.00800","57.40453","1.20088"
"235.21200","57.42151","1.20199"
"235.41600","57.43843","1.20310"
"235.62000","57.45553","1.20404"
"235.82400","57.47251","1.20519"
"236.02800","57.48949","1.20588"
"236.23200","57.50653","1.20668"
"236.43600","57.52345","1.20752"
"236.64000","57.54050","1.20852"
"236.84400","57.55753","1.20975"
"237.04800","57.57451","1.21110"
"237.25200","57.59155","1.21293"
"237.45600","57.60847","1.21523"
"237.66000","57.62551","1.21750"
"237.86400","57.64255","1.22109"
"238.06800","57.65941","1.22466"
"238.27200","57.67651","1.22885"
"238.47600","57.69350","1.23246"
"238.68000","57.71054","1.23618"
"238.88400","57.72751","1.23880"
"239.08800","57.74450","1.24030"
"239.29200","57.76147","1.24209"
"239.49600","57.77851","1.24302"
"239.70000","57.79544","1.24407"
"239.90400","57.81247","1.24613"
"240.10800","57.82951","1.24880"
"240.31200","57.84649","1.25264"
"240.51600","57.86354","1.25643"
"240.72000","57.88046","1.26162"
"240.92400","57.89749","1.26590"
"241.12800","57.91454","1.27009"
"241.33200","57.93145","1.27285"
"241.53600","57.94849","1.27538"
"241.74000","57.96548","1.06886"
"241.94400","57.98251","0.79552"
"242.14800","57.99950","0.80053"
"242.35200","58.01642","0.67159"
"242.55600","58.03358","0.65842"
"242.76000","58.05043","0.66674"
"242.96400","58.06748","0.68014"
"243.16800","58.08452","0.66717"
"243.37200","58.10143","0.67223"
"243.57600","58.11848","0.68055"
"243.78000","58.13552","0.66820"
"243.98400","58.15244","0.67155"
"244.18800","58.16954","0.68481"
"244.39200","58.18652","0.67433"
"244.59600","58.20350","0.67447"
"244.80000","58.22047","0.69026"
"245.00400","58.23752","0.67653"
"245.20800","58.25444","0.67620"
"245.41200","58.27153","0.68738"
"245.61600","58.28846","0.68267"
"245.82000","58.30550","0.67976"
"246.02400","58.32248","0.69076"
"246.22800","58.33952","0.69011"
"246.43200","58.35656","0.68373"
"246.63600","58.37348","0.68833"
"246.84000","58.39052","0.70495"
"247.04400","58.40750","0.69230"
"247.24800","58.42442","0.69567"
"247.45200","58.44152","0.71423"
"247.65600","58.45850","0.70323"
"247.86000","58.47554","0.70214"
"248.06400","58.49252","0.71839"
"248.26800","58.50950","0.72251"
"248.47200","58.52654","0.71393"
"248.67600","58.54352","0.72376"
"248.88000","58.56050","0.73398"
"249.08400","58.57748","0.72843"
"249.28800","58.59446","0.73093"
"249.49200","58.61150","0.73617"
"249.69600","58.62848","0.73523"
"249.90000","58.64546","0.73489"
"250.10400","58.66250","0.73651"
"250.30800","58.67954","0.74166"
"250.51200","58.69646","0.73748"
"250.71600","58.71356","0.74007"
"250.92000","58.73048","0.75100"
"251.12400","58.74746","0.74950"
"251.32800","58.76450","0.74515"
"251.53200","58.78143","0.75288"
"251.73600","58.79858","0.76113"
"251.94000","58.81550","0.75821"
"252.14400","58.83249","0.76054"
"252.34800","58.84953","0.77029"
"252.55200","58.86650","0.77211"
"252.75600","58.88354","0.76940"
"252.96000","58.90053","0.77290"
"253.16400","58.91751","0.77925"
"253.36800","58.93454","0.77813"
"253.57200","58.95147","0.77815"
"253.77600","58.96844","0.78199"
"253.98000","58.98554","0.78555"
"254.18400","59.00247","0.78465"
"254.38800","59.01950","0.78597"
"254.59200","59.03654","0.78835"
"254.79600","59.05347","0.78963"
"255.00000","59.07051","0.78903"
"255.20400","59.08749","0.78997"
"255.40800","59.10447","0.79246"
"255.61200","59.12157","0.79306"
"255.81600","59.13848","0.79318"
"256.02000","59.15553","0.79537"
"256.22400","59.17251","0.79904"
"256.42800","59.18942","0.80031"
"256.63200","59.20653","0.33694"
"256.83600","59.22345","0.36416"
"257.04000","59.24049","0.34402"
"257.24400","59.25753","0.36927"
"257.44800","59.27445","0.27522"
"257.65200","59.29155","0.30176"
"257.85600","59.30846","0.26984"
"258.06000","59.32551","0.29225"
"258.26400","59.34249","0.26942"
"258.46800","59.35947","0.28412"
"258.67200","59.37651","0.27139"
"258.87600","59.39349","0.27915"
"259.08000","59.41047","0.27621"
"259.28400","59.42745","0.27269"
"259.48800","59.44449","0.28279"
"259.69200","59.46152","0.27151"
"259.89600","59.47851","0.28507"
"260.10000","59.49543","0.27346"
"260.30400","59.51254","0.28831"
"260.50800","59.52957","0.27563"
"260.71200","59.54643","0.29142"
"260.91600","59.56353","0.27540"
"261.12000","59.58051","0.29066"
"261.32400","59.59749","0.27365"
"261.52800","59.61453","0.28848"
"261.73200","59.63145","0.27435"
"261.93600","59.64855","0.28623"
"262.14000","59.66547","0.27932"
"262.34400","59.68251","0.28239"
"262.54800","59.69949","0.29150"
"262.75200","59.71647","0.03909"
"262.95600","59.73357","0.06490"
"263.16000","59.75049","0.06493"
"263.36400","59.76748","0.04032"
"263.56800","59.78451","0.07309"
"263.77200","59.80149","0.04750"
"263.97600","59.81848","0.05438"
"264.18000","59.83546","0.05869"
"264.38400","59.85249","0.06047"
"264.58800","59.86948","0.05925"
"264.79200","59.88646","0.06459"
"264.99600","59.90343","0.05711"
"265.20000","59.92048","0.05696"
"265.40400","59.93752","0.06540"
"265.60800","59.95443","0.04604"
"265.81200","59.97153","0.06492"
"266.01600","59.98846","0.05672"
"266.22000","60.00556","0.06185"
"266.42400","60.02247","0.05823"
"266.62800","60.03946","0.06364"
"266.83200","60.05649","0.05398"
"267.03600","60.07347","0.06349"
"267.24000","60.09052","0.06083"
"267.44400","60.10749","0.05732"
"267.64800","60.12448","0.06375"
"267.85200","60.14151","0.05539"
"268.05600","60.15850","0.06339"
"268.26000","60.17548","0.05804"
"268.46400","60.19251","0.06277"
"268.66800","60.20944","0.05689"
"268.87200","60.22654","0.06357"
"269.07600","60.24352","0.05704"
"269.28000","60.26044","0.06284"
"269.48400","60.27754","0.05974"
"269.68800","60.29457","0.06042"
"269.89200","60.31144","0.06323"
"270.09600","60.32854","0.05824"
"270.30000","60.34546","0.06318"
"270.50400","60.36250","0.05909"
"270.70800","60.37954","0.06332"
"270.91200","60.39645","0.05884"
"271.11600","60.41356","0.06383"
"271.32000","60.43048","0.05781"
"271.52400","60.44752","0.06370"
"271.72800","60.46450","0.06056"
"271.93200","60.48148","0.06150"
"272.13600","60.49852","0.06255"
"272.34000","60.51550","0.06029"
"272.54400","60.53248","0.06353"
"272.74800","60.54946","0.05997"
"272.95200","60.56650","0.06329"
"273.15600","60.58348","0.06017"
"273.36000","60.60052","0.06432"
"273.56400","60.61750","0.05922"
"273.76800","60.63454","0.06418"
"273.97200","60.65152","0.06019"
"274.17600","60.66850","0.06331"
"274.38000","60.68554","0.06203"
"274.58400","60.70246","0.06245"
"274.78800","60.71951","0.06225"
"274.99200","60.73654","0.06233"
"275.19600","60.75346","0.06288"
"275.40000","60.77057","0.06098"
"275.60400","60.78748","0.06396"
"275.80800","60.80446","0.06069"
"276.01200","60.82150","0.06456"
"276.21600","60.83842","0.06062"
"276.42000","60.85546","0.06402"
"276.62400","60.87251","0.06178"
"276.82800","60.88942","0.06402"
"277.03200","60.90647","0.06200"
"277.23600","60.92350","0.06365"
"277.44000","60.94048","0.06250"
"277.64400","60.95752","0.06355"
"277.84800","60.97444","0.06334"
"278.05200","60.99154","0.06237"
"278.25600","61.00852","0.06378"
"278.46000","61.02544","0.06283"
"278.66400","61.04249","0.06436"
"278.86800","61.05952","0.06226"
"279.07200","61.07645","0.06489"
"279.27600","61.09355","0.06264"
"279.48000","61.11041","0.06469"
"279.68400","61.12751","0.06253"
"279.88800","61.14455","0.06482"
"280.09200","61.16146","0.06274"
"280.29600","61.17850","0.06458"
"280.50000","61.19549","0.06326"
"280.70400","61.21246","0.06414"
"280.90800","61.22956","0.06316"
"281.11200","61.24649","0.06411"
"281.31600","61.26352","0.06417"
"281.52000","61.28050","0.06339"
"281.72400","61.29749","0.06410"
"281.92800","61.31452","0.06387"
"282.13200","61.33151","0.06476"
"282.33600","61.34849","0.06341"
"282.54000","61.36553","0.06492"
"282.74400","61.38251","0.06377"
"282.94800","61.39949","0.06523"
"283.15200","61.41653","0.06361"
"283.35600","61.43344","0.06526"
"283.56000","61.45049","0.06381"
"283.76400","61.46747","0.06581"
"283.96800","61.48451","0.06404"
"284.17200","61.50149","0.06520"
"284.37600","61.51847","0.06415"
"284.58000","61.53551","0.06558"
"284.78400","61.55249","0.06455"
"284.98800","61.56953","0.06530"
"285.19200","61.58651","0.06432"
"285.39600","61.60343","0.06548"
"285.60000","61.62053","0.06502"
"285.80400","61.63751","0.06480"
"286.00800","61.65443","0.06517"
"286.21200","61.67153","0.06526"
"286.41600","61.68845","0.06571"
"286.62000","61.70549","0.06502"
"286.82400","61.72253","0.06553"
"287.02800","61.73951","0.06530"
"287.23200","61.75655","0.06602"
"287.43600","61.77347","0.06519"
"287.64000","61.79052","0.06606"
"287.84400","61.80749","0.06559"
"288.04800","61.82447","0.06608"
"288.25200","61.84145","0.06521"
"288.45600","61.85855","0.06642"
"288.66000","61.87542","0.06571"
"288.86400","61.89251","0.06665"
"289.06800","61.90949","0.06556"
"289.27200","61.92647","0.06657"
"289.47600","61.94351","0.06551"
"289.68000","61.96049","0.06728"
"289.88400","61.97747","0.06594"
"290.08800","61.99451","0.06659"
"290.29200","62.01144","0.06590"
"290.49600","62.02853","0.06731"
"290.70000","62.04546","0.06600"
"290.90400","62.06255","0.06685"
"291.10800","62.07954","0.06607"
"291.31200","62.09652","0.06749"
"291.51600","62.11350","0.06629"
"291.72000","62.13047","0.06706"
"291.92400","62.14745","0.06617"
"292.12800","62.16450","0.06814"
"292.33200","62.18147","0.06668"
"292.53600","62.19851","0.06750"
"292.74000","62.21550","0.06659"
"292.94400","62.23247","0.06804"
"293.14800","62.24952","0.06679"
"293.35200","62.26649","0.06763"
"293.55600","62.28348","0.06722"
"293.76000","62.30052","0.06837"
"293.96400","62.31749","0.06715"
"294.16800","62.33454","0.06819"
"294.37200","62.35152","0.06733"
"294.57600","62.36844","0.06920"
"294.78000","62.38560","0.06765"
"294.98400","62.40252","0.06849"
"295.18800","62.41949","0.06801"
"295.39200","62.43648","0.06945"
"295.59600","62.45346","0.06752"
"295.80000","62.47055","0.06874"
"296.00400","62.48748","0.06837"
"296.20800","62.50446","0.06984"
"296.41200","62.52150","0.06796"
"296.61600","62.53848","0.06933"
"296.82000","62.55552","0.06882"
"297.02400","62.57256","0.07084"
"297.22800","62.58941","0.06881"
"297.43200","62.60651","0.06948"
"297.63600","62.62349","0.06917"
"297.84000","62.64047","0.07074"
"298.04400","62.65751","0.06914"
"298.24800","62.67449","0.07011"
"298.45200","62.69148","0.06959"
"298.61800","62.70535","0.07145"