File: Force_trajectories/170122_2/Specimen_RawData_10.csv
End date,"1/22/2017"
Specimen label,"14BT_14"
Maximum Load,"0.55606",N

Time,Extension,Load
(s),(mm),(N)
"0.00000","0.00000","0.00004"
"0.25200","0.01901","0.00113"
"0.50400","0.04233","0.00114"
"0.75600","0.06314","0.00242"
"1.00800","0.08424","0.00154"
"1.26000","0.10517","0.00249"
"1.51200","0.12622","0.00250"
"1.76400","0.14720","0.00299"
"2.01600","0.16819","0.00277"
"2.26800","0.18917","0.00371"
"2.52000","0.21022","0.00357"
"2.77200","0.23121","0.00371"
"3.02400","0.25219","0.00401"
"3.27600","0.27324","0.00395"
"3.52800","0.29416","0.00464"
"3.78000","0.31521","0.00494"
"4.03200","0.33608","0.00464"
"4.28400","0.35724","0.00539"
"4.53600","0.37811","0.00458"
"4.78800","0.39921","0.00600"
"5.04000","0.42014","0.00532"
"5.29200","0.44119","0.00555"
"5.54400","0.46211","0.00580"
"5.79600","0.48322","0.00670"
"6.04800","0.50415","0.00636"
"6.30000","0.52519","0.00560"
"6.55200","0.54618","0.00675"
"6.80400","0.56716","0.00633"
"7.05600","0.58815","0.00764"
"7.30800","0.60920","0.00714"
"7.56000","0.63018","0.00731"
"7.81200","0.65117","0.00813"
"8.06400","0.67221","0.00835"
"8.31600","0.69314","0.00806"
"8.56800","0.71419","0.00831"
"8.82000","0.73517","0.00891"
"9.07200","0.75616","0.00911"
"9.32400","0.77714","0.00906"
"9.57600","0.79819","0.00843"
"9.82800","0.81918","0.00939"
"10.08000","0.84022","0.00961"
"10.33200","0.86115","0.00952"
"10.58400","0.88219","0.01023"
"10.83600","0.90318","0.01028"
"11.08800","0.92417","0.01014"
"11.34000","0.94515","0.01050"
"11.59200","0.96620","0.01036"
"11.84400","0.98718","0.01107"
"12.09600","1.00817","0.01042"
"12.34800","1.02922","0.01066"
"12.60000","1.05014","0.01143"
"12.85200","1.07119","0.01216"
"13.10400","1.09212","0.01196"
"13.35600","1.11322","0.01220"
"13.60800","1.13415","0.01200"
"13.86000","1.15525","0.01252"
"14.11200","1.17618","0.01272"
"14.36400","1.19717","0.01238"
"14.61600","1.21815","0.01297"
"14.86800","1.23914","0.01313"
"15.12000","1.26018","0.01396"
"15.37200","1.28111","0.01305"
"15.62400","1.30222","0.01378"
"15.87600","1.32314","0.01391"
"16.12800","1.34425","0.01347"
"16.38000","1.36505","0.01457"
"16.63200","1.38622","0.01473"
"16.88400","1.40715","0.01410"
"17.13600","1.42825","0.01477"
"17.38800","1.44918","0.01462"
"17.64000","1.47016","0.01537"
"17.89200","1.49115","0.01529"
"18.14400","1.51226","0.01505"
"18.39600","1.53318","0.01643"
"18.64800","1.55417","0.01555"
"18.90000","1.57510","0.01577"
"19.15200","1.59620","0.01608"
"19.40400","1.61719","0.01613"
"19.65600","1.63817","0.01580"
"19.90800","1.65922","0.01614"
"20.16000","1.68009","0.01644"
"20.41200","1.70125","0.01747"
"20.66400","1.72212","0.01715"
"20.91600","1.74316","0.01658"
"21.16800","1.76415","0.01741"
"21.42000","1.78520","0.01779"
"21.67200","1.80612","0.01736"
"21.92400","1.82723","0.01883"
"22.17600","1.84815","0.01845"
"22.42800","1.86914","0.01865"
"22.68000","1.89013","0.01819"
"22.93200","1.91117","0.01932"
"23.18400","1.93222","0.01862"
"23.43600","1.95314","0.01994"
"23.68800","1.97419","0.01914"
"23.94000","1.99518","0.01935"
"24.19200","2.01622","0.01935"
"24.44400","2.03715","0.01981"
"24.69600","2.05819","0.02061"
"24.94800","2.07912","0.01998"
"25.20000","2.10023","0.02076"
"25.45200","2.12121","0.02073"
"25.70400","2.14214","0.02054"
"25.95600","2.16313","0.02075"
"26.20800","2.18417","0.02125"
"26.46000","2.20522","0.02139"
"26.71200","2.22620","0.02164"
"26.96400","2.24713","0.02268"
"27.21600","2.26812","0.02204"
"27.46800","2.28916","0.02301"
"27.72000","2.31015","0.02267"
"27.97200","2.33119","0.02254"
"28.22400","2.35212","0.02319"
"28.47600","2.37323","0.02339"
"28.72800","2.39415","0.02286"
"28.98000","2.41520","0.02393"
"29.23200","2.43612","0.02340"
"29.48400","2.45723","0.02378"
"29.73600","2.47816","0.02383"
"29.98800","2.49920","0.02415"
"30.24000","2.52019","0.02437"
"30.49200","2.54117","0.02449"
"30.74400","2.56216","0.02465"
"30.99600","2.58315","0.02483"
"31.24800","2.60419","0.02517"
"31.50000","2.62518","0.02478"
"31.75200","2.64616","0.02531"
"32.00400","2.66715","0.02550"
"32.25600","2.68820","0.02599"
"32.50800","2.70918","0.02580"
"32.76000","2.73017","0.02568"
"33.01200","2.75116","0.02622"
"33.26400","2.77214","0.02678"
"33.51600","2.79319","0.02649"
"33.76800","2.81423","0.02729"
"34.02000","2.83516","0.02673"
"34.27200","2.85615","0.02694"
"34.52400","2.87719","0.02720"
"34.77600","2.89818","0.02730"
"35.02800","2.91922","0.02754"
"35.28000","2.94015","0.02763"
"35.53200","2.96120","0.02787"
"35.78400","2.98212","0.02851"
"36.03600","3.00317","0.02818"
"36.28800","3.02410","0.02887"
"36.54000","3.04514","0.02901"
"36.79200","3.06619","0.02967"
"37.04400","3.08717","0.02939"
"37.29600","3.10816","0.02907"
"37.54800","3.12920","0.02950"
"37.80000","3.15019","0.02974"
"38.05200","3.17118","0.03035"
"38.30400","3.19216","0.02999"
"38.55600","3.21315","0.03065"
"38.80800","3.23419","0.03083"
"39.06000","3.25518","0.03111"
"39.31200","3.27617","0.03098"
"39.56400","3.29721","0.03157"
"39.81600","3.31826","0.03172"
"40.06800","3.33913","0.03176"
"40.32000","3.36023","0.03174"
"40.57200","3.38110","0.03151"
"40.82400","3.40214","0.03114"
"41.07600","3.42313","0.03248"
"41.32800","3.44418","0.03192"
"41.58000","3.46516","0.03207"
"41.83200","3.48621","0.03250"
"42.08400","3.50719","0.03257"
"42.33600","3.52818","0.03317"
"42.58800","3.54923","0.03324"
"42.84000","3.57015","0.03354"
"43.09200","3.59120","0.03340"
"43.34400","3.61218","0.03426"
"43.59600","3.63323","0.03427"
"43.84800","3.65416","0.03419"
"44.10000","3.67520","0.03447"
"44.35200","3.69613","0.03527"
"44.60400","3.71718","0.03502"
"44.85600","3.73816","0.03529"
"45.10800","3.75921","0.03561"
"45.36000","3.78013","0.03615"
"45.61200","3.80118","0.03653"
"45.86400","3.82223","0.03668"
"46.11600","3.84321","0.03707"
"46.36800","3.86414","0.03713"
"46.62000","3.88518","0.03745"
"46.87200","3.90623","0.03793"
"47.12400","3.92716","0.03718"
"47.37600","3.94820","0.03849"
"47.62800","3.96913","0.03880"
"47.88000","3.99023","0.03908"
"48.13200","4.01116","0.03958"
"48.38400","4.03221","0.03982"
"48.63600","4.05313","0.03964"
"48.88800","4.07418","0.04048"
"49.14000","4.09516","0.04039"
"49.39200","4.11621","0.04056"
"49.64400","4.13714","0.04109"
"49.89600","4.15818","0.04171"
"50.14800","4.17923","0.04197"
"50.40000","4.20021","0.04187"
"50.65200","4.22120","0.04221"
"50.90400","4.24219","0.04309"
"51.15600","4.26323","0.04270"
"51.40800","4.28416","0.04370"
"51.66000","4.30515","0.04378"
"51.91200","4.32619","0.04382"
"52.16400","4.34724","0.04407"
"52.41600","4.36810","0.04493"
"52.66800","4.38921","0.04472"
"52.92000","4.41014","0.04549"
"53.17200","4.43124","0.04596"
"53.42400","4.45211","0.04580"
"53.67600","4.47315","0.04649"
"53.92800","4.49414","0.04682"
"54.18000","4.51519","0.04794"
"54.43200","4.53617","0.04758"
"54.68400","4.55722","0.04773"
"54.93600","4.57814","0.04849"
"55.18800","4.59919","0.04880"
"55.44000","4.62024","0.04863"
"55.69200","4.64110","0.04873"
"55.94400","4.66221","0.04951"
"56.19600","4.68313","0.04991"
"56.44800","4.70418","0.04991"
"56.70000","4.72517","0.05004"
"56.95200","4.74621","0.05060"
"57.20400","4.76714","0.05068"
"57.45600","4.78819","0.05179"
"57.70800","4.80911","0.05178"
"57.96000","4.83022","0.05123"
"58.21200","4.85114","0.05136"
"58.46400","4.87219","0.05216"
"58.71600","4.89318","0.05230"
"58.96800","4.91416","0.05237"
"59.22000","4.93521","0.05296"
"59.47200","4.95619","0.05358"
"59.72400","4.97718","0.05382"
"59.97600","4.99817","0.05370"
"60.22800","5.01921","0.05448"
"60.48000","5.04020","0.05416"
"60.73200","5.06118","0.05512"
"60.98400","5.08217","0.05528"
"61.23600","5.10322","0.05552"
"61.48800","5.12420","0.05544"
"61.74000","5.14519","0.05574"
"61.99200","5.16611","0.05600"
"62.24400","5.18716","0.05627"
"62.49600","5.20821","0.05634"
"62.74800","5.22925","0.05686"
"63.00000","5.25018","0.05693"
"63.25200","5.27116","0.05713"
"63.50400","5.29221","0.05756"
"63.75600","5.31314","0.05771"
"64.00800","5.33418","0.05763"
"64.26000","5.35511","0.05797"
"64.51200","5.37621","0.05826"
"64.76400","5.39720","0.05866"
"65.01600","5.41819","0.05879"
"65.26800","5.43911","0.05831"
"65.52000","5.46022","0.05853"
"65.77200","5.48115","0.05921"
"66.02400","5.50213","0.05929"
"66.27600","5.52312","0.05921"
"66.52800","5.54422","0.05957"
"66.78000","5.56527","0.05970"
"67.03200","5.58614","0.06010"
"67.28400","5.60718","0.01929"
"67.53600","5.62817","0.02369"
"67.78800","5.64921","0.02234"
"68.04000","5.67008","0.02253"
"68.29200","5.69119","0.02356"
"68.54400","5.71217","0.02339"
"68.79600","5.73322","0.02477"
"69.04800","5.75420","0.02378"
"69.30000","5.77519","0.02456"
"69.55200","5.79618","0.02354"
"69.80400","5.81722","0.02551"
"70.05600","5.83815","0.02439"
"70.30800","5.85913","0.02527"
"70.56000","5.88012","0.02481"
"70.81200","5.90123","0.02549"
"71.06400","5.92221","0.02578"
"71.31600","5.94320","0.02582"
"71.56800","5.96425","0.02596"
"71.82000","5.98517","0.02681"
"72.07200","6.00622","0.02668"
"72.32400","6.02708","0.02680"
"72.57600","6.04819","0.02754"
"72.82800","6.06918","0.02758"
"73.08000","6.09022","0.02783"
"73.33200","6.11115","0.02784"
"73.58400","6.13219","0.02833"
"73.83600","6.15318","0.02821"
"74.08800","6.17417","0.02892"
"74.34000","6.19515","0.02914"
"74.59200","6.21614","0.02927"
"74.84400","6.23718","0.02945"
"75.09600","6.25817","0.03005"
"75.34800","6.27922","0.03016"
"75.60000","6.30020","0.03044"
"75.85200","6.32125","0.03012"
"76.10400","6.34217","0.03063"
"76.35600","6.36316","0.03121"
"76.60800","6.38409","0.03141"
"76.86000","6.40519","0.03145"
"77.11200","6.42618","0.03137"
"77.36400","6.44717","0.03243"
"77.61600","6.46815","0.03276"
"77.86800","6.48926","0.03305"
"78.12000","6.51024","0.03329"
"78.37200","6.53117","0.03400"
"78.62400","6.55210","0.03361"
"78.87600","6.57314","0.03418"
"79.12800","6.59419","0.03391"
"79.38000","6.61517","0.03534"
"79.63200","6.63622","0.03517"
"79.88400","6.65715","0.03579"
"80.13600","6.67819","0.03586"
"80.38800","6.69912","0.03616"
"80.64000","6.72022","0.03659"
"80.89200","6.74115","0.03637"
"81.14400","6.76220","0.03512"
"81.39600","6.78318","0.03481"
"81.64800","6.80417","0.03589"
"81.90000","6.82516","0.03653"
"82.15200","6.84626","0.03681"
"82.40400","6.86719","0.03747"
"82.65600","6.88811","0.03752"
"82.90800","6.90916","0.03829"
"83.16000","6.93015","0.03850"
"83.41200","6.95125","0.03921"
"83.66400","6.97212","0.03945"
"83.91600","6.99316","0.03975"
"84.16800","7.01415","0.04022"
"84.42000","7.03519","0.04104"
"84.67200","7.05618","0.04063"
"84.92400","7.07717","0.04229"
"85.17600","7.09815","0.04222"
"85.42800","7.11920","0.04275"
"85.68000","7.14019","0.04344"
"85.93200","7.16123","0.04387"
"86.18400","7.18222","0.04397"
"86.43600","7.20320","0.04442"
"86.68800","7.22413","0.04496"
"86.94000","7.24518","0.04530"
"87.19200","7.26616","0.04584"
"87.44400","7.28715","0.04659"
"87.69600","7.30814","0.04662"
"87.94800","7.32912","0.04720"
"88.20000","7.35017","0.04814"
"88.45200","7.37109","0.04826"
"88.70400","7.39220","0.04922"
"88.95600","7.41319","0.04967"
"89.20800","7.43423","0.04993"
"89.46000","7.45516","0.05011"
"89.71200","7.47620","0.05059"
"89.96400","7.49713","0.05167"
"90.21600","7.51823","0.05112"
"90.46800","7.53922","0.05146"
"90.72000","7.56021","0.05268"
"90.97200","7.58119","0.05259"
"91.22400","7.60212","0.05333"
"91.47600","7.62323","0.05392"
"91.72800","7.64409","0.05324"
"91.98000","7.66526","0.05456"
"92.23200","7.68612","0.05448"
"92.48400","7.70717","0.05519"
"92.73600","7.72816","0.05542"
"92.98800","7.74920","0.05534"
"93.24000","7.77013","0.05592"
"93.49200","7.79123","0.05630"
"93.74400","7.81216","0.05658"
"93.99600","7.83315","0.05716"
"94.24800","7.85419","0.05691"
"94.50000","7.87518","0.05753"
"94.75200","7.89622","0.05796"
"95.00400","7.91715","0.05806"
"95.25600","7.93820","0.05810"
"95.50800","7.95918","0.05898"
"95.76000","7.98023","0.05883"
"96.01200","8.00109","0.05899"
"96.26400","8.02220","0.05931"
"96.51600","8.04319","0.05985"
"96.76800","8.06423","0.05970"
"97.02000","8.08510","0.06007"
"97.27200","8.10620","0.06030"
"97.52400","8.12713","0.06083"
"97.77600","8.14824","0.06081"
"98.02800","8.16916","0.06095"
"98.28000","8.19015","0.06140"
"98.53200","8.21126","0.06198"
"98.78400","8.23218","0.06187"
"99.03600","8.25323","0.06252"
"99.28800","8.27409","0.06247"
"99.54000","8.29520","0.06272"
"99.79200","8.31613","0.06368"
"100.04400","8.33723","0.06373"
"100.29600","8.35810","0.06410"
"100.54800","8.37920","0.06416"
"100.80000","8.40019","0.06528"
"101.05200","8.42124","0.06568"
"101.30400","8.44216","0.06568"
"101.55600","8.46321","0.06647"
"101.80800","8.48419","0.06724"
"102.06000","8.50518","0.06779"
"102.31200","8.52611","0.06818"
"102.56400","8.54715","0.06935"
"102.81600","8.56820","0.06974"
"103.06800","8.58918","0.07076"
"103.32000","8.61023","0.07108"
"103.57200","8.63116","0.07245"
"103.82400","8.65220","0.07329"
"104.07600","8.67313","0.07407"
"104.32800","8.69418","0.07527"
"104.58000","8.71510","0.07622"
"104.83200","8.73621","0.07710"
"105.08400","8.75719","0.07772"
"105.33600","8.77824","0.07882"
"105.58800","8.79917","0.07944"
"105.84000","8.82021","0.08036"
"106.09200","8.84120","0.08194"
"106.34400","8.86218","0.08289"
"106.59600","8.88317","0.08398"
"106.84800","8.90422","0.08486"
"107.10000","8.92520","0.08561"
"107.35200","8.94613","0.08543"
"107.60400","8.96723","0.08641"
"107.85600","8.98810","0.08658"
"108.10800","9.00921","0.08814"
"108.36000","9.03013","0.08897"
"108.61200","9.05118","0.08853"
"108.86400","9.07211","0.08912"
"109.11600","9.09321","0.09022"
"109.36800","9.11414","0.09076"
"109.62000","9.13518","0.09187"
"109.87200","9.15617","0.09208"
"110.12400","9.17722","0.09266"
"110.37600","9.19820","0.09409"
"110.62800","9.21913","0.09480"
"110.88000","9.24017","0.09560"
"111.13200","9.26116","0.09596"
"111.38400","9.28221","0.09694"
"111.63600","9.30313","0.09780"
"111.88800","9.32418","0.09933"
"112.14000","9.34516","0.10035"
"112.39200","9.36615","0.10138"
"112.64400","9.38714","0.10242"
"112.89600","9.40818","0.10388"
"113.14800","9.42911","0.10485"
"113.40000","9.45021","0.10584"
"113.65200","9.47114","0.10653"
"113.90400","9.49219","0.10760"
"114.15600","9.51317","0.10855"
"114.40800","9.53422","0.10948"
"114.66000","9.55515","0.10990"
"114.91200","9.57613","0.11011"
"115.16400","9.59718","0.11109"
"115.41600","9.61810","0.11150"
"115.66800","9.63921","0.11195"
"115.92000","9.66014","0.11205"
"116.17200","9.68124","0.11238"
"116.42400","9.70211","0.11285"
"116.67600","9.72321","0.11301"
"116.92800","9.74420","0.11372"
"117.18000","9.76519","0.11381"
"117.43200","9.78611","0.11452"
"117.68400","9.80716","0.11530"
"117.93600","9.82814","0.11572"
"118.18800","9.84919","0.11699"
"118.44000","9.87024","0.11772"
"118.69200","9.89116","0.11923"
"118.94400","9.91221","0.12086"
"119.19600","9.93319","0.12230"
"119.44800","9.95424","0.12418"
"119.70000","9.97511","0.12559"
"119.95200","9.99615","0.12735"
"120.20400","10.01714","0.12899"
"120.45600","10.03824","0.13004"
"120.70800","10.05917","0.13193"
"120.96000","10.08022","0.13364"
"121.21200","10.10114","0.13496"
"121.46400","10.12225","0.13665"
"121.71600","10.14318","0.13797"
"121.96800","10.16416","0.13856"
"122.22000","10.18515","0.13995"
"122.47200","10.20619","0.14120"
"122.72400","10.22724","0.14213"
"122.97600","10.24817","0.14340"
"123.22800","10.26921","0.14456"
"123.48000","10.29020","0.14583"
"123.73200","10.31118","0.14654"
"123.98400","10.33211","0.14712"
"124.23600","10.35322","0.14788"
"124.48800","10.37414","0.14894"
"124.74000","10.39519","0.14968"
"124.99200","10.41611","0.15069"
"125.24400","10.43722","0.15092"
"125.49600","10.45821","0.15207"
"125.74800","10.47919","0.15253"
"126.00000","10.50012","0.15381"
"126.25200","10.52110","0.15405"
"126.50400","10.54221","0.15528"
"126.75600","10.56320","0.15608"
"127.00800","10.58424","0.15670"
"127.26000","10.60517","0.15761"
"127.51200","10.62621","0.15854"
"127.76400","10.64714","0.15913"
"128.01600","10.66819","0.15974"
"128.26800","10.68911","0.16087"
"128.52000","10.71016","0.16158"
"128.77200","10.73114","0.16271"
"129.02400","10.75219","0.16337"
"129.27600","10.77318","0.16444"
"129.52800","10.79416","0.16495"
"129.78000","10.81521","0.16618"
"130.03200","10.83613","0.16679"
"130.28400","10.85712","0.16841"
"130.53600","10.87823","0.17058"
"130.78800","10.89921","0.17193"
"131.04000","10.92014","0.17346"
"131.29200","10.94119","0.17635"
"131.54400","10.96211","0.17824"
"131.79600","10.98322","0.18048"
"132.04800","11.00414","0.18378"
"132.30000","11.02519","0.18621"
"132.55200","11.04611","0.18945"
"132.80400","11.06722","0.19165"
"133.05600","11.08815","0.19479"
"133.30800","11.10919","0.19728"
"133.56000","11.13018","0.20021"
"133.81200","11.15117","0.20354"
"134.06400","11.17215","0.20587"
"134.31600","11.19314","0.20850"
"134.56800","11.21418","0.20940"
"134.82000","11.23517","0.21113"
"135.07200","11.25622","0.21295"
"135.32400","11.27714","0.21373"
"135.57600","11.29819","0.21507"
"135.82800","11.31917","0.21580"
"136.08000","11.34022","0.21660"
"136.33200","11.36115","0.21724"
"136.58400","11.38219","0.21838"
"136.83600","11.40318","0.21934"
"137.08800","11.42423","0.21989"
"137.34000","11.44515","0.14687"
"137.59200","11.46620","0.14930"
"137.84400","11.48718","0.15308"
"138.09600","11.50817","0.15717"
"138.34800","11.52915","0.15858"
"138.60000","11.55014","0.15782"
"138.85200","11.57119","0.15703"
"139.10400","11.59223","0.15811"
"139.35600","11.61316","0.15979"
"139.60800","11.63415","0.16219"
"139.86000","11.65519","0.16517"
"140.11200","11.67618","0.16663"
"140.36400","11.69716","0.16752"
"140.61600","11.71809","0.16780"
"140.86800","11.73920","0.16849"
"141.12000","11.76018","0.17117"
"141.37200","11.78123","0.17481"
"141.62400","11.80221","0.18086"
"141.87600","11.82320","0.18632"
"142.12800","11.84425","0.18915"
"142.38000","11.86517","0.19142"
"142.63200","11.88616","0.19484"
"142.88400","11.90708","0.19809"
"143.13600","11.92825","0.20022"
"143.38800","11.94912","0.20357"
"143.64000","11.97022","0.20649"
"143.89200","11.99109","0.20935"
"144.14400","12.01219","0.21228"
"144.39600","12.03318","0.21405"
"144.64800","12.05417","0.21455"
"144.90000","12.07521","0.21543"
"145.15200","12.09620","0.21616"
"145.40400","12.11713","0.21671"
"145.65600","12.13817","0.21772"
"145.90800","12.15916","0.21892"
"146.16000","12.18020","0.22023"
"146.41200","12.20119","0.22215"
"146.66400","12.22212","0.22435"
"146.91600","12.24316","0.22693"
"147.16800","12.26421","0.22910"
"147.42000","12.28520","0.23132"
"147.67200","12.30612","0.23388"
"147.92400","12.32723","0.23647"
"148.17600","12.34815","0.23894"
"148.42800","12.36926","0.24029"
"148.68000","12.39012","0.24266"
"148.93200","12.41123","0.24568"
"149.18400","12.43216","0.24761"
"149.43600","12.45320","0.24957"
"149.68800","12.47419","0.25125"
"149.94000","12.49518","0.25347"
"150.19200","12.51622","0.25518"
"150.44400","12.53721","0.25641"
"150.69600","12.55819","0.25780"
"150.94800","12.57906","0.25880"
"151.20000","12.60023","0.25975"
"151.45200","12.62115","0.26025"
"151.70400","12.64220","0.26056"
"151.95600","12.66312","0.26096"
"152.20800","12.68417","0.26171"
"152.46000","12.70516","0.26228"
"152.71200","12.72620","0.26287"
"152.96400","12.74719","0.26323"
"153.21600","12.76824","0.26369"
"153.46800","12.78922","0.26428"
"153.72000","12.81015","0.26483"
"153.97200","12.83113","0.26542"
"154.22400","12.85218","0.26619"
"154.47600","12.87323","0.26739"
"154.72800","12.89415","0.26781"
"154.98000","12.91520","0.26918"
"155.23200","12.93618","0.26902"
"155.48400","12.95723","0.27035"
"155.73600","12.97816","0.26968"
"155.98800","12.99914","0.27130"
"156.24000","13.02013","0.27259"
"156.49200","13.04117","0.27521"
"156.74400","13.06216","0.27725"
"156.99600","13.08321","0.27931"
"157.24800","13.10419","0.28159"
"157.50000","13.12518","0.28380"
"157.75200","13.14622","0.28623"
"158.00400","13.16721","0.28832"
"158.25600","13.18814","0.29030"
"158.50800","13.20918","0.29290"
"158.76000","13.23023","0.29364"
"159.01200","13.25115","0.29583"
"159.26400","13.27220","0.29904"
"159.51600","13.29313","0.30082"
"159.76800","13.31423","0.30292"
"160.02000","13.33516","0.30534"
"160.27200","13.35620","0.30733"
"160.52400","13.37719","0.30846"
"160.77600","13.39824","0.30966"
"161.02800","13.41916","0.31065"
"161.28000","13.44015","0.31202"
"161.53200","13.46113","0.31352"
"161.78400","13.48218","0.31483"
"162.03600","13.50317","0.31617"
"162.28800","13.52415","0.31912"
"162.54000","13.54520","0.32160"
"162.79200","13.56618","0.32473"
"163.04400","13.58717","0.32834"
"163.29600","13.60810","0.33383"
"163.54800","13.62914","0.33738"
"163.80000","13.65013","0.34088"
"164.05200","13.67118","0.34423"
"164.30400","13.69216","0.34831"
"164.55600","13.71321","0.35069"
"164.80800","13.73413","0.35432"
"165.06000","13.75518","0.35713"
"165.31200","13.77611","0.36005"
"165.56400","13.79721","0.36185"
"165.81600","13.81820","0.36420"
"166.06800","13.83918","0.36623"
"166.32000","13.86017","0.36766"
"166.57200","13.88116","0.36862"
"166.82400","13.90220","0.36940"
"167.07600","13.92319","0.37020"
"167.32800","13.94417","0.36866"
"167.58000","13.96510","0.21021"
"167.83200","13.98621","0.22729"
"168.08400","14.00713","0.22441"
"168.33600","14.02818","0.22695"
"168.58800","14.04916","0.22993"
"168.84000","14.07021","0.23214"
"169.09200","14.09120","0.23519"
"169.34400","14.11212","0.23994"
"169.59600","14.13317","0.24202"
"169.84800","14.15416","0.24485"
"170.10000","14.17520","0.24845"
"170.35200","14.19619","0.25187"
"170.60400","14.21717","0.25396"
"170.85600","14.23816","0.25603"
"171.10800","14.25920","0.25823"
"171.36000","14.28007","0.25956"
"171.61200","14.30112","0.25992"
"171.86400","14.32210","0.26113"
"172.11600","14.34315","0.26190"
"172.36800","14.36414","0.26258"
"172.62000","14.38518","0.26320"
"172.87200","14.40617","0.26409"
"173.12400","14.42727","0.26532"
"173.37600","14.44814","0.26599"
"173.62800","14.46925","0.26684"
"173.88000","14.49023","0.26814"
"174.13200","14.51116","0.27028"
"174.38400","14.53226","0.27144"
"174.63600","14.55313","0.27342"
"174.88800","14.57418","0.27545"
"175.14000","14.59522","0.28034"
"175.39200","14.61621","0.28155"
"175.64400","14.63708","0.28206"
"175.89600","14.65818","0.28467"
"176.14800","14.67911","0.28956"
"176.40000","14.70021","0.29234"
"176.65200","14.72114","0.29320"
"176.90400","14.74219","0.29642"
"177.15600","14.76317","0.30107"
"177.40800","14.78416","0.30359"
"177.66000","14.80514","0.30481"
"177.91200","14.82619","0.30743"
"178.16400","14.84718","0.30884"
"178.41600","14.86822","0.31094"
"178.66800","14.88921","0.31150"
"178.92000","14.91013","0.31269"
"179.17200","14.93124","0.31474"
"179.42400","14.95217","0.31756"
"179.67600","14.97315","0.32070"
"179.92800","14.99414","0.32295"
"180.18000","15.01518","0.16630"
"180.43200","15.03617","0.18480"
"180.68400","15.05722","0.21220"
"180.93600","15.07814","0.21348"
"181.18800","15.09919","0.20814"
"181.44000","15.12018","0.20562"
"181.69200","15.14116","0.20989"
"181.94400","15.16215","0.21592"
"182.19600","15.18319","0.22395"
"182.44800","15.20424","0.23622"
"182.70000","15.22517","0.23902"
"182.95200","15.24615","0.23768"
"183.20400","15.26714","0.23715"
"183.45600","15.28824","0.23821"
"183.70800","15.30911","0.24369"
"183.96000","15.33016","0.24802"
"184.21200","15.35114","0.25374"
"184.46400","15.37225","0.25845"
"184.71600","15.39312","0.26085"
"184.96800","15.41422","0.26198"
"185.22000","15.43521","0.26254"
"185.47200","15.45619","0.26364"
"185.72400","15.47718","0.26398"
"185.97600","15.49817","0.26443"
"186.22800","15.51915","0.26531"
"186.48000","15.54020","0.26522"
"186.73200","15.56118","0.26510"
"186.98400","15.58211","0.26629"
"187.23600","15.60316","0.26825"
"187.48800","15.62414","0.27140"
"187.74000","15.64525","0.27302"
"187.99200","15.66611","0.27812"
"188.24400","15.68716","0.28141"
"188.49600","15.70815","0.28720"
"188.74800","15.72919","0.29032"
"189.00000","15.75018","0.29299"
"189.25200","15.77122","0.29639"
"189.50400","15.79215","0.30138"
"189.75600","15.81319","0.30350"
"190.00800","15.83412","0.30645"
"190.26000","15.85517","0.30845"
"190.51200","15.87615","0.30919"
"190.76400","15.89720","0.31145"
"191.01600","15.91825","0.31234"
"191.26800","15.93917","0.31492"
"191.52000","15.96022","0.31900"
"191.77200","15.98120","0.32359"
"192.02400","16.00219","0.32821"
"192.27600","16.02312","0.33337"
"192.52800","16.04422","0.34031"
"192.78000","16.06515","0.34693"
"193.03200","16.08619","0.35305"
"193.28400","16.10718","0.35576"
"193.53600","16.12817","0.35898"
"193.78800","16.14921","0.36303"
"194.04000","16.17014","0.36548"
"194.29200","16.19118","0.36802"
"194.54400","16.21217","0.36917"
"194.79600","16.23322","0.37027"
"195.04800","16.25414","0.37096"
"195.30000","16.27519","0.37198"
"195.55200","16.29611","0.37292"
"195.80400","16.31722","0.37397"
"196.05600","16.33815","0.37547"
"196.30800","16.35913","0.37675"
"196.56000","16.38018","0.37807"
"196.81200","16.40117","0.38030"
"197.06400","16.42215","0.38238"
"197.31600","16.44320","0.38448"
"197.56800","16.46412","0.38654"
"197.82000","16.48517","0.38945"
"198.07200","16.50616","0.39265"
"198.32400","16.52720","0.39691"
"198.57600","16.54819","0.40173"
"198.82800","16.56911","0.40593"
"199.08000","16.59022","0.40905"
"199.33200","16.61115","0.41238"
"199.58400","16.63219","0.41500"
"199.83600","16.65318","0.41740"
"200.08800","16.67422","0.41878"
"200.34000","16.69515","0.42092"
"200.59200","16.71620","0.42287"
"200.84400","16.73712","0.42418"
"201.09600","16.75823","0.42723"
"201.34800","16.77915","0.43074"
"201.60000","16.80020","0.43444"
"201.85200","16.82119","0.43745"
"202.10400","16.84217","0.44093"
"202.35600","16.86316","0.44419"
"202.60800","16.88415","0.44620"
"202.86000","16.90519","0.44853"
"203.11200","16.92618","0.45103"
"203.36400","16.94722","0.45320"
"203.61600","16.96809","0.45449"
"203.86800","16.98919","0.45645"
"204.12000","17.01018","0.45766"
"204.37200","17.03117","0.42743"
"204.62400","17.05215","0.42598"
"204.87600","17.07320","0.42747"
"205.12800","17.09418","0.43133"
"205.38000","17.11517","0.43522"
"205.63200","17.13616","0.43946"
"205.88400","17.15720","0.44359"
"206.13600","17.17813","0.44724"
"206.38800","17.19912","0.45079"
"206.64000","17.22016","0.45210"
"206.89200","17.24109","0.45320"
"207.14400","17.26219","0.45490"
"207.39600","17.28318","0.45696"
"207.64800","17.30417","0.45902"
"207.90000","17.32515","0.46081"
"208.15200","17.34620","0.46280"
"208.40400","17.36712","0.46572"
"208.65600","17.38817","0.46846"
"208.90800","17.40916","0.47118"
"209.16000","17.43020","0.47315"
"209.41200","17.45119","0.47670"
"209.66400","17.47218","0.47984"
"209.91600","17.49316","0.48401"
"210.16800","17.51421","0.48670"
"210.42000","17.53525","0.49155"
"210.67200","17.55612","0.49484"
"210.92400","17.57717","0.49862"
"211.17600","17.59815","0.50077"
"211.42800","17.61926","0.50451"
"211.68000","17.64013","0.50744"
"211.93200","17.66117","0.51080"
"212.18400","17.68216","0.51286"
"212.43600","17.70320","0.51565"
"212.68800","17.72413","0.51768"
"212.94000","17.74517","0.51859"
"213.19200","17.76616","0.10909"
"213.44400","17.78715","0.11822"
"213.69600","17.80819","0.11450"
"213.94800","17.82918","0.12849"
"214.20000","17.85016","0.12978"
"214.45200","17.87121","0.11779"
"214.70400","17.89214","0.12958"
"214.95600","17.91306","0.13302"
"215.20800","17.93417","0.12721"
"215.46000","17.95522","0.13525"
"215.71200","17.97620","0.13770"
"215.96400","17.99713","0.13275"
"216.21600","18.01817","0.13768"
"216.46800","18.03916","0.14222"
"216.72000","18.06021","0.13835"
"216.97200","18.08113","0.14009"
"217.22400","18.10218","0.14485"
"217.47600","18.12317","0.14256"
"217.72800","18.14421","0.14243"
"217.98000","18.16520","0.14661"
"218.23200","18.18618","0.14691"
"218.48400","18.20723","0.14592"
"218.73600","18.22816","0.14774"
"218.98800","18.24920","0.14953"
"219.24000","18.27007","0.14861"
"219.49200","18.29117","0.14917"
"219.74400","18.31216","0.15106"
"219.99600","18.33320","0.15101"
"220.24800","18.35419","0.15116"
"220.50000","18.37524","0.15230"
"220.75200","18.39616","0.15358"
"221.00400","18.41715","0.15354"
"221.25600","18.43820","0.15404"
"221.50800","18.45912","0.15553"
"221.76000","18.48017","0.15631"
"222.01200","18.50115","0.15626"
"222.26400","18.52220","0.15680"
"222.51600","18.54319","0.15801"
"222.76800","18.56423","0.15836"
"223.02000","18.58510","0.15835"
"223.27200","18.60614","0.15944"
"223.52400","18.62713","0.16055"
"223.77600","18.64824","0.16099"
"224.02800","18.66916","0.16151"
"224.28000","18.69021","0.16260"
"224.53200","18.71113","0.16362"
"224.78400","18.73224","0.16426"
"225.03600","18.75317","0.16497"
"225.28800","18.77421","0.16587"
"225.54000","18.79514","0.16664"
"225.79200","18.81612","0.16863"
"226.04400","18.83717","0.16923"
"226.29600","18.85816","0.17037"
"226.54800","18.87920","0.17387"
"226.80000","18.90019","0.17447"
"227.05200","18.92118","0.17564"
"227.30400","18.94210","0.17822"
"227.55600","18.96315","0.17934"
"227.80800","18.98413","0.18191"
"228.06000","19.00524","0.18473"
"228.31200","19.02611","0.18392"
"228.56400","19.04721","0.18720"
"228.81600","19.06814","0.19111"
"229.06800","19.08918","0.19272"
"229.32000","19.11017","0.19596"
"229.57200","19.13116","0.19999"
"229.82400","19.15220","0.20319"
"230.07600","19.17319","0.20558"
"230.32800","19.19417","0.20835"
"230.58000","19.21516","0.21016"
"230.83200","19.23621","0.21231"
"231.08400","19.25719","0.21377"
"231.33600","19.27818","0.21431"
"231.58800","19.29910","0.21514"
"231.84000","19.32021","0.21627"
"232.09200","19.34120","0.21736"
"232.34400","19.36218","0.21819"
"232.59600","19.38317","0.21898"
"232.84800","19.40421","0.22120"
"233.10000","19.42520","0.22277"
"233.35200","19.44619","0.22409"
"233.60400","19.46717","0.22434"
"233.85600","19.48816","0.22672"
"234.10800","19.50920","0.22807"
"234.36000","19.53019","0.23208"
"234.61200","19.55124","0.23405"
"234.86400","19.57216","0.23538"
"235.11600","19.59321","0.23874"
"235.36800","19.61414","0.24026"
"235.62000","19.63518","0.24259"
"235.87200","19.65611","0.24507"
"236.12400","19.67727","0.24710"
"236.37600","19.69814","0.24878"
"236.62800","19.71925","0.25089"
"236.88000","19.74017","0.25269"
"237.13200","19.76122","0.25436"
"237.38400","19.78220","0.25579"
"237.63600","19.80313","0.25750"
"237.88800","19.82418","0.25833"
"238.14000","19.84516","0.25913"
"238.39200","19.86621","0.26035"
"238.64400","19.88707","0.26126"
"238.89600","19.90818","0.26175"
"239.14800","19.92917","0.26226"
"239.40000","19.95021","0.26271"
"239.65200","19.97114","0.26359"
"239.90400","19.99213","0.26412"
"240.15600","20.01311","0.26492"
"240.40800","20.03422","0.26566"
"240.66000","20.05514","0.26624"
"240.91200","20.07619","0.26761"
"241.16400","20.09718","0.26849"
"241.41600","20.11822","0.27013"
"241.66800","20.13921","0.27157"
"241.92000","20.16019","0.27389"
"242.17200","20.18118","0.27592"
"242.42400","20.20217","0.27920"
"242.67600","20.22315","0.28184"
"242.92800","20.24414","0.28455"
"243.18000","20.26518","0.28781"
"243.43200","20.28617","0.29023"
"243.68400","20.30716","0.29249"
"243.93600","20.32814","0.29497"
"244.18800","20.34919","0.29810"
"244.44000","20.37017","0.30074"
"244.69200","20.39122","0.30281"
"244.94400","20.41215","0.29785"
"245.19600","20.43319","0.16660"
"245.44800","20.45418","0.17812"
"245.70000","20.47517","0.17832"
"245.95200","20.49621","0.17955"
"246.20400","20.51720","0.19123"
"246.45600","20.53824","0.19129"
"246.70800","20.55917","0.19762"
"246.96000","20.58022","0.21049"
"247.21200","20.60114","0.20548"
"247.46400","20.62225","0.20987"
"247.71600","20.64317","0.21551"
"247.96800","20.66416","0.21600"
"248.22000","20.68514","0.21663"
"248.47200","20.70619","0.22023"
"248.72400","20.72718","0.22084"
"248.97600","20.74817","0.22207"
"249.22800","20.76915","0.22970"
"249.48000","20.79014","0.23221"
"249.73200","20.81118","0.23097"
"249.98400","20.83217","0.23759"
"250.23600","20.85321","0.24298"
"250.48800","20.87414","0.24239"
"250.74000","20.89519","0.24470"
"250.99200","20.91611","0.25099"
"251.24400","20.93716","0.25105"
"251.49600","20.95815","0.25231"
"251.74800","20.97919","0.25594"
"252.00000","21.00011","0.25744"
"252.25200","21.02116","0.25746"
"252.50400","21.04215","0.25917"
"252.75600","21.06326","0.26129"
"253.00800","21.08412","0.26137"
"253.26000","21.10517","0.26179"
"253.51200","21.12621","0.26274"
"253.76400","21.14714","0.26360"
"254.01600","21.16818","0.26346"
"254.26800","21.18911","0.26420"
"254.52000","21.21016","0.26589"
"254.77200","21.23120","0.26606"
"255.02400","21.25219","0.26647"
"255.27600","21.27311","0.26782"
"255.52800","21.29416","0.27016"
"255.78000","21.31515","0.27037"
"256.03200","21.33619","0.27132"
"256.28400","21.35712","0.27533"
"256.53600","21.37817","0.27831"
"256.78800","21.39921","0.27872"
"257.04000","21.42020","0.17449"
"257.29200","21.44118","0.15975"
"257.54400","21.46217","0.16301"
"257.79600","21.48315","0.16864"
"258.04800","21.50414","0.17107"
"258.30000","21.52513","0.16895"
"258.55200","21.54618","0.17028"
"258.80400","21.56722","0.17943"
"259.05600","21.58815","0.18893"
"259.30800","21.60913","0.18828"
"259.56000","21.63012","0.19072"
"259.81200","21.65122","0.19411"
"260.06400","21.67215","0.19967"
"260.31600","21.69314","0.20710"
"260.56800","21.71412","0.21055"
"260.82000","21.73523","0.21027"
"261.07200","21.75621","0.21136"
"261.32400","21.77720","0.21332"
"261.57600","21.79819","0.21411"
"261.82800","21.81917","0.21578"
"262.08000","21.84022","0.21676"
"262.33200","21.86115","0.21654"
"262.58400","21.88219","0.21786"
"262.83600","21.90312","0.21890"
"263.08800","21.92422","0.21942"
"263.34000","21.94515","0.22095"
"263.59200","21.96619","0.22333"
"263.84400","21.98706","0.22457"
"264.09600","22.00823","0.22611"
"264.34800","22.02915","0.22984"
"264.60000","22.05020","0.23120"
"264.85200","22.07119","0.23168"
"265.10400","22.09217","0.23578"
"265.35600","22.11316","0.23769"
"265.60800","22.13420","0.23850"
"265.86000","22.15519","0.24170"
"266.11200","22.17618","0.24371"
"266.36400","22.19722","0.24504"
"266.61600","22.21815","0.24664"
"266.86800","22.23919","0.24978"
"267.12000","22.26018","0.25103"
"267.37200","22.28123","0.25181"
"267.62400","22.30210","0.25394"
"267.87600","22.32320","0.25495"
"268.12800","22.34413","0.25622"
"268.38000","22.36523","0.25745"
"268.63200","22.38610","0.25852"
"268.88400","22.40714","0.25902"
"269.13600","22.42819","0.26006"
"269.38800","22.44923","0.26078"
"269.64000","22.47016","0.26144"
"269.89200","22.49115","0.26167"
"270.14400","22.51219","0.26213"
"270.39600","22.53312","0.26287"
"270.64800","22.55417","0.26344"
"270.90000","22.57509","0.26383"
"271.15200","22.59620","0.26470"
"271.40400","22.61719","0.26508"
"271.65600","22.63817","0.26548"
"271.90800","22.65916","0.26609"
"272.16000","22.68026","0.26706"
"272.41200","22.70119","0.26774"
"272.66400","22.72218","0.26828"
"272.91600","22.74316","0.26938"
"273.16800","22.76415","0.27103"
"273.42000","22.78519","0.27251"
"273.67200","22.80618","0.27402"
"273.92400","22.82717","0.27609"
"274.17600","22.84815","0.27849"
"274.42800","22.86920","0.28006"
"274.68000","22.89012","0.28156"
"274.93200","22.91123","0.28375"
"275.18400","22.93216","0.28618"
"275.43600","22.95320","0.28805"
"275.68800","22.97419","0.29030"
"275.94000","22.99517","0.29269"
"276.19200","23.01616","0.29466"
"276.44400","23.03727","0.29766"
"276.69600","23.05813","0.30036"
"276.94800","23.07918","0.30181"
"277.20000","23.10011","0.30393"
"277.45200","23.12121","0.30463"
"277.70400","23.14220","0.30588"
"277.95600","23.16318","0.30712"
"278.20800","23.18423","0.30748"
"278.46000","23.20510","0.30928"
"278.71200","23.22620","0.30940"
"278.96400","23.24707","0.31138"
"279.21600","23.26818","0.31225"
"279.46800","23.28916","0.31311"
"279.72000","23.31027","0.31451"
"279.97200","23.33113","0.31565"
"280.22400","23.35224","0.31805"
"280.47600","23.37316","0.32011"
"280.72800","23.39421","0.32168"
"280.98000","23.41514","0.32399"
"281.23200","23.43618","0.32372"
"281.48400","23.45717","0.32617"
"281.73600","23.47821","0.32979"
"281.98800","23.49920","0.33282"
"282.24000","23.52019","0.33624"
"282.49200","23.54123","0.33985"
"282.74400","23.56216","0.34176"
"282.99600","23.58315","0.32335"
"283.24800","23.60407","0.32694"
"283.50000","23.62518","0.33273"
"283.75200","23.64622","0.33796"
"284.00400","23.66721","0.34160"
"284.25600","23.68819","0.34599"
"284.50800","23.70918","0.34901"
"284.76000","23.73017","0.35193"
"285.01200","23.75115","0.35453"
"285.26400","23.77214","0.35608"
"285.51600","23.79312","0.35497"
"285.76800","23.81417","0.35649"
"286.02000","23.83516","0.35751"
"286.27200","23.85620","0.32275"
"286.52400","23.87713","0.32312"
"286.77600","23.89824","0.32477"
"287.02800","23.91910","0.03611"
"287.28000","23.94015","0.04821"
"287.53200","23.96113","0.05554"
"287.78400","23.98224","0.02552"
"288.03600","24.00316","0.02766"
"288.28800","24.02421","0.05528"
"288.54000","24.04520","0.03444"
"288.79200","24.06618","0.04979"
"289.04400","24.08717","0.03748"
"289.29600","24.10816","0.03476"
"289.54800","24.12920","0.05022"
"289.80000","24.15019","0.02933"
"290.05200","24.17117","0.05588"
"290.30400","24.19216","0.03143"
"290.55600","24.21321","0.05289"
"290.80800","24.23419","0.04316"
"291.06000","24.25524","0.04526"
"291.31200","24.27611","0.04757"
"291.56400","24.29715","0.04715"
"291.81600","24.31814","0.04713"
"292.06800","24.33924","0.04947"
"292.32000","24.36017","0.04650"
"292.57200","24.38121","0.05003"
"292.82400","24.40214","0.05273"
"293.07600","24.42319","0.04781"
"293.32800","24.44417","0.05406"
"293.58000","24.46522","0.04969"
"293.83200","24.48615","0.05445"
"294.08400","24.50713","0.05248"
"294.33600","24.52818","0.05460"
"294.58800","24.54910","0.05290"
"294.84000","24.57021","0.05667"
"295.09200","24.59114","0.05364"
"295.34400","24.61224","0.05688"
"295.59600","24.63311","0.05564"
"295.84800","24.65421","0.05773"
"296.10000","24.67514","0.05708"
"296.35200","24.69619","0.05879"
"296.60400","24.71711","0.05740"
"296.85600","24.73816","0.05955"
"297.10800","24.75920","0.05876"
"297.36000","24.78019","0.06016"
"297.61200","24.80118","0.06004"
"297.86400","24.82216","0.06098"
"298.11600","24.84321","0.06082"
"298.36800","24.86413","0.06165"
"298.62000","24.88518","0.06164"
"298.87200","24.90611","0.06232"
"299.12400","24.92721","0.06284"
"299.37600","24.94814","0.06328"
"299.62800","24.96919","0.06365"
"299.88000","24.99011","0.06458"
"300.13200","25.01122","0.06492"
"300.38400","25.03220","0.06545"
"300.63600","25.05319","0.06640"
"300.88800","25.07417","0.06653"
"301.14000","25.09516","0.06763"
"301.39200","25.11621","0.06827"
"301.64400","25.13720","0.06939"
"301.89600","25.15824","0.07011"
"302.14800","25.17916","0.07140"
"302.40000","25.20015","0.07171"
"302.65200","25.22114","0.07350"
"302.90400","25.24219","0.07392"
"303.15600","25.26317","0.07580"
"303.40800","25.28416","0.07721"
"303.66000","25.30514","0.07864"
"303.91200","25.32619","0.07936"
"304.16400","25.34717","0.08105"
"304.41600","25.36822","0.08133"
"304.66800","25.38915","0.08358"
"304.92000","25.41019","0.08497"
"305.17200","25.43118","0.08641"
"305.42400","25.45223","0.08725"
"305.67600","25.47321","0.08885"
"305.92800","25.49408","0.09008"
"306.18000","25.51518","0.09096"
"306.43200","25.53617","0.09263"
"306.68400","25.55716","0.09449"
"306.93600","25.57808","0.09592"
"307.18800","25.59919","0.09647"
"307.44000","25.62017","0.09867"
"307.69200","25.64122","0.09942"
"307.94400","25.66215","0.10217"
"308.19600","25.68319","0.10246"
"308.44800","25.70418","0.10527"
"308.70000","25.72516","0.10651"
"308.95200","25.74615","0.10778"
"309.20400","25.76720","0.10863"
"309.45600","25.78818","0.10925"
"309.70800","25.80917","0.11056"
"309.96000","25.83015","0.11119"
"310.21200","25.85114","0.11201"
"310.46400","25.87225","0.11267"
"310.71600","25.89311","0.11304"
"310.96800","25.91416","0.11354"
"311.22000","25.93508","0.11420"
"311.47200","25.95619","0.11577"
"311.72400","25.97717","0.11764"
"311.97600","25.99816","0.11914"
"312.22800","26.01915","0.11915"
"312.48000","26.04020","0.12035"
"312.73200","26.06118","0.12233"
"312.98400","26.08223","0.12415"
"313.23600","26.10315","0.12745"
"313.48800","26.12420","0.12814"
"313.74000","26.14524","0.13122"
"313.99200","26.16611","0.13137"
"314.24400","26.18722","0.13511"
"314.49600","26.20814","0.13562"
"314.74800","26.22919","0.13869"
"315.00000","26.25012","0.14002"
"315.25200","26.27116","0.14135"
"315.50400","26.29215","0.14292"
"315.75600","26.31319","0.14391"
"316.00800","26.33418","0.14539"
"316.26000","26.35517","0.14661"
"316.51200","26.37615","0.14835"
"316.76400","26.39720","0.14721"
"317.01600","26.41818","0.14877"
"317.26800","26.43917","0.15001"
"317.52000","26.46016","0.15083"
"317.77200","26.48114","0.15217"
"318.02400","26.50219","0.15324"
"318.27600","26.52317","0.15504"
"318.52800","26.54422","0.15580"
"318.78000","26.56515","0.15713"
"319.03200","26.58625","0.15809"
"319.28400","26.60712","0.15902"
"319.53600","26.62817","0.16045"
"319.78800","26.64915","0.16172"
"320.04000","26.67020","0.16304"
"320.29200","26.69113","0.16464"
"320.54400","26.71217","0.16629"
"320.79600","26.73316","0.16836"
"321.04800","26.75420","0.17028"
"321.30000","26.77519","0.17397"
"321.55200","26.79612","0.17733"
"321.80400","26.81716","0.18060"
"322.05600","26.83815","0.18425"
"322.30800","26.85925","0.18777"
"322.56000","26.88012","0.19434"
"322.81200","26.90116","0.19810"
"323.06400","26.92215","0.20209"
"323.31600","26.94320","0.20545"
"323.56800","26.96412","0.20884"
"323.82000","26.98523","0.21219"
"324.07200","27.00616","0.21293"
"324.32400","27.02720","0.21458"
"324.57600","27.04813","0.21604"
"324.82800","27.06917","0.21690"
"325.08000","27.09022","0.21886"
"325.33200","27.11115","0.22043"
"325.58400","27.13219","0.22301"
"325.83600","27.15318","0.22596"
"326.08800","27.17422","0.22846"
"326.34000","27.19509","0.23229"
"326.59200","27.21620","0.23459"
"326.84400","27.23712","0.23831"
"327.09600","27.25823","0.24077"
"327.34800","27.27916","0.24299"
"327.60000","27.30020","0.24559"
"327.85200","27.32119","0.24816"
"328.10400","27.34223","0.25125"
"328.35600","27.36316","0.25333"
"328.60800","27.38414","0.25555"
"328.86000","27.40513","0.25751"
"329.11200","27.42618","0.25849"
"329.36400","27.44716","0.25978"
"329.61600","27.46821","0.26072"
"329.86800","27.48920","0.26148"
"330.12000","27.51012","0.26237"
"330.37200","27.53123","0.26291"
"330.62400","27.55209","0.26368"
"330.87600","27.57320","0.26473"
"331.12800","27.59413","0.26560"
"331.38000","27.61523","0.26625"
"331.63200","27.63610","0.26769"
"331.88400","27.65721","0.26926"
"332.13600","27.67819","0.27030"
"332.38800","27.69917","0.27272"
"332.64000","27.72010","0.27550"
"332.89200","27.74115","0.27829"
"333.14400","27.76220","0.28157"
"333.39600","27.78318","0.28417"
"333.64800","27.80423","0.28719"
"333.90000","27.82515","0.28999"
"334.15200","27.84620","0.29319"
"334.40400","27.86718","0.29613"
"334.65600","27.88817","0.29911"
"334.90800","27.90910","0.30243"
"335.16000","27.93020","0.30480"
"335.41200","27.95119","0.30708"
"335.66400","27.97218","0.30882"
"335.91600","27.99316","0.31044"
"336.16800","28.01421","0.31256"
"336.42000","28.03519","0.31393"
"336.67200","28.05618","0.31659"
"336.92400","28.07710","0.31959"
"337.17600","28.09815","0.32378"
"337.42800","28.11920","0.32777"
"337.68000","28.14018","0.33356"
"337.93200","28.16123","0.33817"
"338.18400","28.18216","0.34269"
"338.43600","28.20320","0.34844"
"338.68800","28.22413","0.35166"
"338.94000","28.24524","0.35524"
"339.19200","28.26616","0.35873"
"339.44400","28.28721","0.36174"
"339.69600","28.30819","0.36371"
"339.94800","28.32918","0.36596"
"340.20000","28.35016","0.36725"
"340.45200","28.37121","0.36886"
"340.70400","28.39220","0.36984"
"340.95600","28.41318","0.37077"
"341.20800","28.43417","0.37163"
"341.46000","28.45515","0.37222"
"341.71200","28.47620","0.37309"
"341.96400","28.49713","0.37418"
"342.21600","28.51817","0.37557"
"342.46800","28.53916","0.37653"
"342.72000","28.56021","0.37811"
"342.97200","28.58113","0.37988"
"343.22400","28.60217","0.38145"
"343.47600","28.62316","0.38356"
"343.72800","28.64421","0.38675"
"343.98000","28.66514","0.38907"
"344.23200","28.68618","0.39187"
"344.48400","28.70717","0.39495"
"344.73600","28.72821","0.39867"
"344.98800","28.74914","0.40214"
"345.24000","28.77013","0.40639"
"345.49200","28.79117","0.41136"
"345.74400","28.81222","0.41341"
"345.99600","28.83320","0.41594"
"346.24800","28.85413","0.41762"
"346.50000","28.87524","0.41881"
"346.75200","28.89610","0.42043"
"347.00400","28.91721","0.42199"
"347.25600","28.93813","0.42444"
"347.50800","28.95918","0.42697"
"347.76000","28.98017","0.42952"
"348.01200","29.00121","0.43367"
"348.26400","29.02220","0.43701"
"348.51600","29.04318","0.43971"
"348.76800","29.06423","0.44182"
"349.02000","29.08521","0.44443"
"349.27200","29.10614","0.44709"
"349.52400","29.12713","0.44962"
"349.77600","29.14818","0.45181"
"350.02800","29.16916","0.45342"
"350.28000","29.19021","0.45530"
"350.53200","29.21114","0.45671"
"350.78400","29.23218","0.45800"
"351.03600","29.25317","0.45944"
"351.28800","29.27421","0.46104"
"351.54000","29.29514","0.46253"
"351.79200","29.31618","0.46392"
"352.04400","29.33717","0.46632"
"352.29600","29.35816","0.46848"
"352.54800","29.37914","0.47045"
"352.80000","29.40013","0.47322"
"353.05200","29.42117","0.47594"
"353.30400","29.44216","0.47777"
"353.55600","29.46321","0.48124"
"353.80800","29.48419","0.48402"
"354.06000","29.50518","0.48709"
"354.31200","29.52617","0.49087"
"354.56400","29.54721","0.49392"
"354.81600","29.56814","0.49745"
"355.06800","29.58924","0.50067"
"355.32000","29.61011","0.50373"
"355.57200","29.63116","0.50624"
"355.82400","29.65214","0.50887"
"356.07600","29.67325","0.51183"
"356.32800","29.69417","0.51324"
"356.58000","29.71522","0.51608"
"356.83200","29.73621","0.51782"
"357.08400","29.75719","0.51860"
"357.33600","29.77824","0.51974"
"357.58800","29.79910","0.52060"
"357.84000","29.82021","0.52111"
"358.09200","29.84114","0.52280"
"358.34400","29.86218","0.52469"
"358.59600","29.88311","0.52721"
"358.84800","29.90421","0.52935"
"359.10000","29.92514","0.53305"
"359.35200","29.94625","0.53637"
"359.60400","29.96717","0.54007"
"359.85600","29.98822","0.54251"
"360.10800","30.00921","0.54503"
"360.36000","30.03019","0.54838"
"360.61200","30.05112","0.55165"
"360.86400","30.07216","0.55441"
"361.11600","30.09321","0.55412"
"361.36800","30.11419","0.02874"
"361.62000","30.13518","0.01136"
"361.87200","30.15617","0.01489"
"362.12400","30.17721","0.00882"
"362.37600","30.19814","0.00674"
"362.62800","30.21918","0.00768"
"362.88000","30.24011","0.00930"
"363.13200","30.26122","0.00966"
"363.38400","30.28214","0.00801"
"363.63600","30.30319","0.00673"
"363.88800","30.32411","0.00823"
"364.14000","30.34522","0.00859"
"364.39200","30.36621","0.00951"
"364.64400","30.38719","0.00832"
"364.89600","30.40818","0.00731"
"365.14800","30.42923","0.00817"
"365.40000","30.45027","0.00919"
"365.65200","30.47114","0.00888"
"365.90400","30.49218","0.00832"
"366.15600","30.51311","0.00724"
"366.40800","30.53422","0.00795"
"366.66000","30.55514","0.00839"
"366.91200","30.57619","0.00896"
"367.16400","30.59711","0.00796"
"367.41600","30.61822","0.00710"
"367.66800","30.63914","0.00783"
"367.92000","30.66019","0.00946"
"368.17200","30.68118","0.00870"
"368.42400","30.70222","0.00799"
"368.67600","30.72321","0.00741"
"368.92800","30.74414","0.00850"
"369.18000","30.76518","0.00846"
"369.27800","30.77337","0.00886"