File: Force_trajectories/170122_2/Specimen_RawData_9.csv
End date,"1/22/2017"
Specimen label,"14BT_10"
Maximum Load,"0.08602",N

Time,Extension,Load
(s),(mm),(N)
"0.00000","0.00000","0.00011"
"0.33000","0.02738","0.00145"
"0.66000","0.05513","0.00156"
"0.99000","0.08269","0.00269"
"1.32000","0.11019","0.00304"
"1.65000","0.13770","0.00372"
"1.98000","0.16520","0.00432"
"2.31000","0.19264","0.00416"
"2.64000","0.22026","0.00446"
"2.97000","0.24765","0.00525"
"3.30000","0.27515","0.00463"
"3.63000","0.30265","0.00602"
"3.96000","0.33016","0.00602"
"4.29000","0.35772","0.00590"
"4.62000","0.38516","0.00560"
"4.95000","0.41273","0.00618"
"5.28000","0.44017","0.00631"
"5.61000","0.46767","0.00644"
"5.94000","0.49524","0.00661"
"6.27000","0.52268","0.00678"
"6.60000","0.55018","0.00723"
"6.93000","0.57775","0.00737"
"7.26000","0.60513","0.00707"
"7.59000","0.63269","0.00725"
"7.92000","0.66020","0.00796"
"8.25000","0.68764","0.00829"
"8.58000","0.71520","0.00769"
"8.91000","0.74265","0.00805"
"9.24000","0.77027","0.00796"
"9.57000","0.79771","0.00886"
"9.90000","0.82516","0.00870"
"10.23000","0.85272","0.00950"
"10.56000","0.88016","0.00914"
"10.89000","0.90766","0.00812"
"11.22000","0.93523","0.00949"
"11.55000","0.96261","0.00992"
"11.88000","0.99017","0.00912"
"12.21000","1.01768","0.00996"
"12.54000","1.04518","0.01018"
"12.87000","1.07268","0.01034"
"13.20000","1.10013","0.01021"
"13.53000","1.12775","0.00988"
"13.86000","1.15513","0.00995"
"14.19000","1.18264","0.01060"
"14.52000","1.21026","0.01052"
"14.85000","1.23764","0.01108"
"15.18000","1.26521","0.01144"
"15.51000","1.29271","0.01167"
"15.84000","1.32015","0.01056"
"16.17000","1.34772","0.01150"
"16.50000","1.37516","0.01249"
"16.83000","1.40272","0.01152"
"17.16000","1.43017","0.01192"
"17.49000","1.45767","0.01222"
"17.82000","1.48523","0.01164"
"18.15000","1.51274","0.01162"
"18.48000","1.54024","0.01317"
"18.81000","1.56774","0.01325"
"19.14000","1.59518","0.01332"
"19.47000","1.62269","0.01362"
"19.80000","1.65025","0.01344"
"20.13000","1.67763","0.01317"
"20.46000","1.70520","0.01312"
"20.79000","1.73264","0.01410"
"21.12000","1.76020","0.01371"
"21.45000","1.78777","0.01436"
"21.78000","1.81515","0.01437"
"22.11000","1.84271","0.01455"
"22.44000","1.87016","0.01493"
"22.77000","1.89766","0.01464"
"23.10000","1.92516","0.01487"
"23.43000","1.95267","0.01453"
"23.76000","1.98023","0.01513"
"24.09000","2.00767","0.01557"
"24.42000","2.03518","0.01498"
"24.75000","2.06274","0.01543"
"25.08000","2.09018","0.01524"
"25.41000","2.11769","0.01539"
"25.74000","2.14525","0.01565"
"26.07000","2.17269","0.01633"
"26.40000","2.20020","0.01635"
"26.73000","2.22770","0.01656"
"27.06000","2.25514","0.01639"
"27.39000","2.28270","0.01625"
"27.72000","2.31015","0.01646"
"28.05000","2.33771","0.01705"
"28.38000","2.36521","0.01652"
"28.71000","2.39266","0.01675"
"29.04000","2.42022","0.01679"
"29.37000","2.44766","0.01694"
"29.70000","2.47517","0.01741"
"30.03000","2.50273","0.01710"
"30.36000","2.53011","0.01795"
"30.69000","2.55768","0.01779"
"31.02000","2.58518","0.01437"
"31.35000","2.61268","0.01544"
"31.68000","2.64019","0.01546"
"32.01000","2.66757","0.01558"
"32.34000","2.69519","0.01579"
"32.67000","2.72270","0.01534"
"33.00000","2.75020","0.01550"
"33.33000","2.77776","0.01610"
"33.66000","2.80521","0.01645"
"33.99000","2.83265","0.01590"
"34.32000","2.86021","0.01637"
"34.65000","2.88766","0.01565"
"34.98000","2.91522","0.01617"
"35.31000","2.94272","0.01595"
"35.64000","2.97016","0.01700"
"35.97000","2.99773","0.01613"
"36.30000","3.02511","0.01622"
"36.63000","3.05273","0.01649"
"36.96000","3.08024","0.01648"
"37.29000","3.10768","0.01763"
"37.62000","3.13524","0.01703"
"37.95000","3.16269","0.01824"
"38.28000","3.19019","0.01859"
"38.61000","3.21769","0.01788"
"38.94000","3.24520","0.01835"
"39.27000","3.27270","0.01849"
"39.60000","3.30014","0.01909"
"39.93000","3.32771","0.01870"
"40.26000","3.35521","0.01914"
"40.59000","3.38259","0.01934"
"40.92000","3.41022","0.01911"
"41.25000","3.43772","0.02028"
"41.58000","3.46516","0.01966"
"41.91000","3.49267","0.01939"
"42.24000","3.52017","0.02016"
"42.57000","3.54767","0.02070"
"42.90000","3.57518","0.02098"
"43.23000","3.60262","0.02185"
"43.56000","3.63018","0.02249"
"43.89000","3.65768","0.02247"
"44.22000","3.68519","0.02278"
"44.55000","3.71275","0.02315"
"44.88000","3.74013","0.02375"
"45.21000","3.76770","0.02399"
"45.54000","3.79520","0.02427"
"45.87000","3.82264","0.02474"
"46.20000","3.85021","0.02500"
"46.53000","3.87771","0.02544"
"46.86000","3.90521","0.02584"
"47.19000","3.93272","0.02683"
"47.52000","3.96016","0.02739"
"47.85000","3.98772","0.02724"
"48.18000","4.01517","0.02744"
"48.51000","4.04273","0.02725"
"48.84000","4.07023","0.02761"
"49.17000","4.09762","0.02813"
"49.50000","4.12518","0.02858"
"49.83000","4.15268","0.02965"
"50.16000","4.18018","0.02983"
"50.49000","4.20769","0.03100"
"50.82000","4.23513","0.03150"
"51.15000","4.26269","0.03181"
"51.48000","4.29020","0.03317"
"51.81000","4.31764","0.03244"
"52.14000","4.34520","0.03250"
"52.47000","4.37265","0.03283"
"52.80000","4.40021","0.03290"
"53.13000","4.42771","0.03309"
"53.46000","4.45516","0.02546"
"53.79000","4.48272","0.02140"
"54.12000","4.51016","0.02236"
"54.45000","4.53773","0.02278"
"54.78000","4.56529","0.02247"
"55.11000","4.59267","0.02291"
"55.44000","4.62024","0.02365"
"55.77000","4.64762","0.02343"
"56.10000","4.67518","0.02425"
"56.43000","4.70269","0.02401"
"56.76000","4.73013","0.02390"
"57.09000","4.75769","0.02442"
"57.42000","4.78520","0.02496"
"57.75000","4.81264","0.02513"
"58.08000","4.84014","0.02520"
"58.41000","4.86765","0.02595"
"58.74000","4.89521","0.02601"
"59.07000","4.92271","0.02586"
"59.40000","4.95015","0.02655"
"59.73000","4.97772","0.02622"
"60.06000","5.00522","0.02724"
"60.39000","5.03266","0.02736"
"60.72000","5.06023","0.02675"
"61.05000","5.08767","0.02691"
"61.38000","5.11517","0.02653"
"61.71000","5.14268","0.02823"
"62.04000","5.17018","0.02786"
"62.37000","5.19768","0.02800"
"62.70000","5.22513","0.02889"
"63.03000","5.25275","0.02844"
"63.36000","5.28025","0.02834"
"63.69000","5.30770","0.02870"
"64.02000","5.33526","0.02907"
"64.35000","5.36264","0.02970"
"64.68000","5.39021","0.02928"
"65.01000","5.41771","0.02807"
"65.34000","5.44515","0.02883"
"65.67000","5.47271","0.02929"
"66.00000","5.50016","0.02982"
"66.33000","5.52772","0.02931"
"66.66000","5.55522","0.02950"
"66.99000","5.58261","0.02899"
"67.32000","5.61017","0.02926"
"67.65000","5.63767","0.02963"
"67.98000","5.66518","0.02981"
"68.31000","5.69268","0.03086"
"68.64000","5.72018","0.03117"
"68.97000","5.74763","0.03106"
"69.30000","5.77519","0.03167"
"69.63000","5.80269","0.03108"
"69.96000","5.83026","0.03148"
"70.29000","5.85770","0.03220"
"70.62000","5.88514","0.03230"
"70.95000","5.91277","0.03285"
"71.28000","5.94009","0.03308"
"71.61000","5.96771","0.03335"
"71.94000","5.99522","0.03413"
"72.27000","6.02266","0.03238"
"72.60000","6.05022","0.03332"
"72.93000","6.07767","0.03400"
"73.26000","6.10523","0.03374"
"73.59000","6.13273","0.03321"
"73.92000","6.16017","0.03475"
"74.25000","6.18774","0.03420"
"74.58000","6.21518","0.03473"
"74.91000","6.24268","0.03533"
"75.24000","6.27025","0.03582"
"75.57000","6.29763","0.03545"
"75.90000","6.32525","0.03614"
"76.23000","6.35270","0.03565"
"76.56000","6.38020","0.03611"
"76.89000","6.40770","0.03626"
"77.22000","6.43515","0.03737"
"77.55000","6.46271","0.03720"
"77.88000","6.49021","0.03805"
"78.21000","6.51766","0.03884"
"78.54000","6.54522","0.03821"
"78.87000","6.57266","0.03796"
"79.20000","6.60023","0.03822"
"79.53000","6.62773","0.03904"
"79.86000","6.65511","0.03894"
"80.19000","6.68268","0.03897"
"80.52000","6.71018","0.03909"
"80.85000","6.73768","0.04014"
"81.18000","6.76519","0.04064"
"81.51000","6.79263","0.04026"
"81.84000","6.82025","0.03963"
"82.17000","6.84770","0.04065"
"82.50000","6.87520","0.04083"
"82.83000","6.90276","0.04151"
"83.16000","6.93015","0.04167"
"83.49000","6.95777","0.04174"
"83.82000","6.98521","0.04289"
"84.15000","7.01271","0.04305"
"84.48000","7.04022","0.04368"
"84.81000","7.06766","0.04393"
"85.14000","7.09522","0.04467"
"85.47000","7.12273","0.04550"
"85.80000","7.15011","0.04561"
"86.13000","7.17773","0.04643"
"86.46000","7.20518","0.04619"
"86.79000","7.23262","0.04726"
"87.12000","7.26018","0.04727"
"87.45000","7.28763","0.04778"
"87.78000","7.31519","0.04725"
"88.11000","7.34269","0.04838"
"88.44000","7.37020","0.01423"
"88.77000","7.39776","0.01875"
"89.10000","7.42514","0.01626"
"89.43000","7.45271","0.01813"
"89.76000","7.48021","0.01859"
"90.09000","7.50765","0.01988"
"90.42000","7.53521","0.01911"
"90.75000","7.56266","0.01825"
"91.08000","7.59022","0.02118"
"91.41000","7.61766","0.02008"
"91.74000","7.64523","0.02049"
"92.07000","7.67273","0.02147"
"92.40000","7.70023","0.02174"
"92.73000","7.72768","0.02248"
"93.06000","7.75524","0.02146"
"93.39000","7.78262","0.02300"
"93.72000","7.81019","0.02314"
"94.05000","7.83775","0.02363"
"94.38000","7.86513","0.02379"
"94.71000","7.89270","0.02353"
"95.04000","7.92020","0.02501"
"95.37000","7.94770","0.02485"
"95.70000","7.97521","0.02491"
"96.03000","8.00265","0.02602"
"96.36000","8.03021","0.02605"
"96.69000","8.05772","0.02586"
"97.02000","8.08522","0.02648"
"97.35000","8.11272","0.02731"
"97.68000","8.14017","0.02723"
"98.01000","8.16767","0.02444"
"98.34000","8.19523","0.02411"
"98.67000","8.22268","0.02485"
"99.00000","8.25024","0.02464"
"99.33000","8.27768","0.02438"
"99.66000","8.30518","0.02519"
"99.99000","8.33269","0.02510"
"100.32000","8.36019","0.02551"
"100.65000","8.38769","0.02628"
"100.98000","8.41520","0.02565"
"101.31000","8.44270","0.02642"
"101.64000","8.47026","0.02731"
"101.97000","8.49771","0.02732"
"102.30000","8.52521","0.02718"
"102.63000","8.55265","0.02767"
"102.96000","8.58016","0.02776"
"103.29000","8.60766","0.02770"
"103.62000","8.63516","0.02781"
"103.95000","8.66273","0.02898"
"104.28000","8.69023","0.02935"
"104.61000","8.71767","0.02985"
"104.94000","8.74524","0.02946"
"105.27000","8.77268","0.02933"
"105.60000","8.80018","0.03017"
"105.93000","8.82775","0.02935"
"106.26000","8.85513","0.02889"
"106.59000","8.88269","0.02459"
"106.92000","8.91014","0.02331"
"107.25000","8.93764","0.02432"
"107.58000","8.96520","0.02474"
"107.91000","8.99265","0.02464"
"108.24000","9.02021","0.02558"
"108.57000","9.04771","0.02555"
"108.90000","9.07509","0.02587"
"109.23000","9.10272","0.02584"
"109.56000","9.13016","0.02564"
"109.89000","9.15766","0.02626"
"110.22000","9.18523","0.02573"
"110.55000","9.21267","0.02509"
"110.88000","9.24023","0.02532"
"111.21000","9.26768","0.02610"
"111.54000","9.29518","0.02625"
"111.87000","9.32274","0.02706"
"112.20000","9.35019","0.02687"
"112.53000","9.37769","0.02700"
"112.86000","9.40519","0.02810"
"113.19000","9.43264","0.02784"
"113.52000","9.46020","0.02845"
"113.85000","9.48770","0.02855"
"114.18000","9.51521","0.03000"
"114.51000","9.54271","0.02975"
"114.84000","9.57015","0.02960"
"115.17000","9.59772","0.02989"
"115.50000","9.62516","0.02980"
"115.83000","9.65266","0.03004"
"116.16000","9.68022","0.03065"
"116.49000","9.70761","0.03048"
"116.82000","9.73523","0.03043"
"117.15000","9.76267","0.03023"
"117.48000","9.79024","0.03044"
"117.81000","9.81768","0.03150"
"118.14000","9.84518","0.03181"
"118.47000","9.87269","0.03221"
"118.80000","9.90019","0.03285"
"119.13000","9.92769","0.03372"
"119.46000","9.95520","0.03310"
"119.79000","9.98264","0.03419"
"120.12000","10.01014","0.03481"
"120.45000","10.03777","0.03501"
"120.78000","10.06515","0.03595"
"121.11000","10.09271","0.03507"
"121.44000","10.12022","0.03555"
"121.77000","10.14766","0.03520"
"122.10000","10.17516","0.03662"
"122.43000","10.20267","0.03673"
"122.76000","10.23023","0.03660"
"123.09000","10.25773","0.03632"
"123.42000","10.28517","0.03753"
"123.75000","10.31274","0.03814"
"124.08000","10.34012","0.03813"
"124.41000","10.36768","0.03866"
"124.74000","10.39525","0.03879"
"125.07000","10.42263","0.03913"
"125.40000","10.45019","0.03948"
"125.73000","10.47770","0.03793"
"126.06000","10.50526","0.03862"
"126.39000","10.53264","0.03867"
"126.72000","10.56015","0.03916"
"127.05000","10.58771","0.03822"
"127.38000","10.61521","0.03814"
"127.71000","10.64266","0.03827"
"128.04000","10.67028","0.03923"
"128.37000","10.69766","0.03969"
"128.70000","10.72517","0.04010"
"129.03000","10.75273","0.03806"
"129.36000","10.78017","0.03501"
"129.69000","10.80768","0.03548"
"130.02000","10.83518","0.03612"
"130.35000","10.86268","0.03604"
"130.68000","10.89019","0.03660"
"131.01000","10.91763","0.03703"
"131.34000","10.94525","0.03812"
"131.67000","10.97269","0.03779"
"132.00000","11.00014","0.03650"
"132.33000","11.02770","0.03703"
"132.66000","11.05514","0.03758"
"132.99000","11.08271","0.03803"
"133.32000","11.11021","0.03881"
"133.65000","11.13771","0.04006"
"133.98000","11.16522","0.03915"
"134.31000","11.19266","0.03895"
"134.64000","11.22022","0.03904"
"134.97000","11.24767","0.03957"
"135.30000","11.27511","0.04009"
"135.63000","11.30267","0.04077"
"135.96000","11.33018","0.04105"
"136.29000","11.35774","0.04213"
"136.62000","11.38524","0.04183"
"136.95000","11.41269","0.04267"
"137.28000","11.44019","0.04254"
"137.61000","11.46769","0.04173"
"137.94000","11.49514","0.04025"
"138.27000","11.52270","0.04088"
"138.60000","11.55014","0.04155"
"138.93000","11.57771","0.04164"
"139.26000","11.60527","0.04269"
"139.59000","11.63265","0.04304"
"139.92000","11.66021","0.04343"
"140.25000","11.68766","0.04383"
"140.58000","11.71522","0.04393"
"140.91000","11.74272","0.04402"
"141.24000","11.77017","0.04459"
"141.57000","11.79767","0.04437"
"141.90000","11.82511","0.04486"
"142.23000","11.85268","0.04549"
"142.56000","11.88024","0.04588"
"142.89000","11.90768","0.04609"
"143.22000","11.93519","0.04689"
"143.55000","11.96269","0.04697"
"143.88000","11.99013","0.04648"
"144.21000","12.01770","0.04680"
"144.54000","12.04520","0.04744"
"144.87000","12.07270","0.04701"
"145.20000","12.10020","0.04701"
"145.53000","12.12765","0.04765"
"145.86000","12.15521","0.04852"
"146.19000","12.18271","0.04921"
"146.52000","12.21016","0.04896"
"146.85000","12.23772","0.04546"
"147.18000","12.26516","0.04285"
"147.51000","12.29267","0.04346"
"147.84000","12.32023","0.04403"
"148.17000","12.34768","0.04546"
"148.50000","12.37518","0.04610"
"148.83000","12.40268","0.04646"
"149.16000","12.43024","0.04725"
"149.49000","12.45775","0.04769"
"149.82000","12.48519","0.04839"
"150.15000","12.51275","0.04965"
"150.48000","12.54020","0.05024"
"150.81000","12.56764","0.05089"
"151.14000","12.59526","0.05143"
"151.47000","12.62265","0.05233"
"151.80000","12.65021","0.05297"
"152.13000","12.67771","0.05330"
"152.46000","12.70516","0.05371"
"152.79000","12.73272","0.05382"
"153.12000","12.76016","0.05417"
"153.45000","12.78772","0.05496"
"153.78000","12.81523","0.05556"
"154.11000","12.84261","0.05555"
"154.44000","12.87024","0.05581"
"154.77000","12.89768","0.05537"
"155.10000","12.92512","0.05604"
"155.43000","12.95269","0.05649"
"155.76000","12.98013","0.05721"
"156.09000","13.00769","0.05764"
"156.42000","13.03520","0.05759"
"156.75000","13.06264","0.05767"
"157.08000","13.09020","0.05777"
"157.41000","13.11765","0.05801"
"157.74000","13.14527","0.05809"
"158.07000","13.17271","0.05863"
"158.40000","13.20015","0.05706"
"158.73000","13.22772","0.05751"
"159.06000","13.25516","0.05762"
"159.39000","13.28272","0.05772"
"159.72000","13.31023","0.05851"
"160.05000","13.33773","0.05868"
"160.38000","13.36523","0.05909"
"160.71000","13.39268","0.05954"
"161.04000","13.42018","0.05985"
"161.37000","13.44768","0.06011"
"161.70000","13.47513","0.05972"
"162.03000","13.50269","0.05823"
"162.36000","13.53019","0.05637"
"162.69000","13.55770","0.05684"
"163.02000","13.58520","0.05740"
"163.35000","13.61270","0.05808"
"163.68000","13.64015","0.05919"
"164.01000","13.66771","0.05999"
"164.34000","13.69515","0.06111"
"164.67000","13.72271","0.06245"
"165.00000","13.75022","0.06335"
"165.33000","13.77772","0.06448"
"165.66000","13.80528","0.06541"
"165.99000","13.83261","0.06655"
"166.32000","13.86017","0.06638"
"166.65000","13.88773","0.06720"
"166.98000","13.91512","0.06778"
"167.31000","13.94268","0.06828"
"167.64000","13.97018","0.06992"
"167.97000","13.99775","0.07149"
"168.30000","14.02525","0.07251"
"168.63000","14.05263","0.07375"
"168.96000","14.08020","0.07474"
"169.29000","14.10764","0.07661"
"169.62000","14.13514","0.07790"
"169.95000","14.16277","0.07944"
"170.28000","14.19015","0.08043"
"170.61000","14.21765","0.08217"
"170.94000","14.24522","0.08316"
"171.27000","14.27272","0.08437"
"171.60000","14.30016","0.08555"
"171.93000","14.32767","0.08166"
"172.26000","14.35517","0.08043"
"172.59000","14.38273","0.07932"
"172.92000","14.41012","0.07835"
"173.25000","14.43774","0.07601"
"173.58000","14.46518","0.07536"
"173.91000","14.49262","0.07168"
"174.24000","14.52025","0.07087"
"174.57000","14.54763","0.06818"
"174.90000","14.57519","0.05599"
"175.23000","14.60270","0.05728"
"175.56000","14.63020","0.05765"
"175.89000","14.65770","0.05859"
"176.22000","14.68509","0.05994"
"176.55000","14.71271","0.06063"
"176.88000","14.74015","0.06207"
"177.21000","14.76766","0.06319"
"177.54000","14.79522","0.06353"
"177.87000","14.82266","0.06535"
"178.20000","14.85023","0.06605"
"178.53000","14.87773","0.06789"
"178.86000","14.90517","0.06884"
"179.19000","14.93268","0.06968"
"179.52000","14.96018","0.04508"
"179.85000","14.98768","0.04498"
"180.18000","15.01518","0.04440"
"180.51000","15.04263","0.02814"
"180.84000","15.07019","0.02894"
"181.17000","15.09769","0.02851"
"181.50000","15.12520","0.02929"
"181.83000","15.15270","0.03000"
"182.16000","15.18020","0.03108"
"182.49000","15.20765","0.03266"
"182.82000","15.23521","0.03283"
"183.15000","15.26271","0.03338"
"183.48000","15.29022","0.02621"
"183.81000","15.31760","0.02668"
"184.14000","15.34516","0.02406"
"184.47000","15.37273","0.02023"
"184.80000","15.40011","0.02031"
"185.13000","15.42773","0.02048"
"185.46000","15.45518","0.02071"
"185.79000","15.48268","0.02105"
"186.12000","15.51018","0.02152"
"186.45000","15.53769","0.02102"
"186.78000","15.56519","0.02155"
"187.11000","15.59269","0.02202"
"187.44000","15.62020","0.02193"
"187.77000","15.64764","0.02245"
"188.10000","15.67514","0.02285"
"188.43000","15.70270","0.02319"
"188.76000","15.73027","0.02325"
"189.09000","15.75765","0.02304"
"189.42000","15.78521","0.02324"
"189.75000","15.81266","0.02389"
"190.08000","15.84016","0.02437"
"190.41000","15.86766","0.02378"
"190.74000","15.89517","0.02429"
"191.07000","15.92273","0.02430"
"191.40000","15.95023","0.02459"
"191.73000","15.97768","0.02499"
"192.06000","16.00518","0.02477"
"192.39000","16.03262","0.02565"
"192.72000","16.06019","0.02587"
"193.05000","16.08769","0.02632"
"193.38000","16.11513","0.02600"
"193.71000","16.14270","0.02689"
"194.04000","16.17020","0.02732"
"194.37000","16.19770","0.02814"
"194.70000","16.22521","0.02844"
"195.03000","16.25265","0.02901"
"195.36000","16.28021","0.02904"
"195.69000","16.30771","0.02949"
"196.02000","16.33522","0.02966"
"196.35000","16.36278","0.03055"
"196.68000","16.39016","0.03134"
"197.01000","16.41767","0.03143"
"197.34000","16.44517","0.03268"
"197.67000","16.47267","0.03336"
"198.00000","16.50018","0.03338"
"198.33000","16.52768","0.03471"
"198.66000","16.55524","0.03513"
"198.99000","16.58269","0.03569"
"199.32000","16.61007","0.03662"
"199.65000","16.63769","0.03713"
"199.98000","16.66520","0.03880"
"200.31000","16.69264","0.03966"
"200.64000","16.72020","0.04025"
"200.97000","16.74765","0.04074"
"201.30000","16.77521","0.04014"
"201.63000","16.80265","0.04110"
"201.96000","16.83016","0.04114"
"202.29000","16.85766","0.04206"
"202.62000","16.88510","0.04342"
"202.95000","16.91278","0.04349"
"203.28000","16.94023","0.04453"
"203.61000","16.96767","0.04505"
"203.94000","16.99523","0.04631"
"204.27000","17.02268","0.04700"
"204.60000","17.05018","0.04790"
"204.93000","17.07768","0.04817"
"205.26000","17.10513","0.04895"
"205.59000","17.13269","0.04989"
"205.92000","17.16019","0.05058"
"206.25000","17.18770","0.05070"
"206.58000","17.21520","0.05187"
"206.91000","17.24264","0.05197"
"207.24000","17.27027","0.05290"
"207.57000","17.29771","0.05324"
"207.90000","17.32515","0.05366"
"208.23000","17.35271","0.05069"
"208.56000","17.38016","0.04836"
"208.89000","17.40772","0.04906"
"209.22000","17.43522","0.04968"
"209.55000","17.46267","0.04994"
"209.88000","17.49023","0.05174"
"210.21000","17.51768","0.05149"
"210.54000","17.54518","0.05174"
"210.87000","17.57268","0.04975"
"211.20000","17.60012","0.04895"
"211.53000","17.62769","0.04894"
"211.86000","17.65519","0.05000"
"212.19000","17.68269","0.05061"
"212.52000","17.71020","0.05118"
"212.85000","17.73770","0.05217"
"213.18000","17.76520","0.05294"
"213.51000","17.79271","0.05273"
"213.84000","17.82021","0.05339"
"214.17000","17.84771","0.05422"
"214.50000","17.87516","0.05449"
"214.83000","17.90266","0.05464"
"215.16000","17.93022","0.05510"
"215.49000","17.95767","0.05592"
"215.82000","17.98523","0.05622"
"216.15000","18.01273","0.05664"
"216.48000","18.04018","0.05717"
"216.81000","18.06768","0.05762"
"217.14000","18.09518","0.05850"
"217.47000","18.12275","0.05865"
"217.80000","18.15025","0.05896"
"218.13000","18.17763","0.03477"
"218.46000","18.20520","0.03498"
"218.79000","18.23270","0.03945"
"219.12000","18.26014","0.04075"
"219.45000","18.28777","0.04178"
"219.78000","18.31515","0.04561"
"220.11000","18.34271","0.04428"
"220.44000","18.37021","0.04536"
"220.77000","18.39772","0.04573"
"221.10000","18.42516","0.04627"
"221.43000","18.45260","0.04801"
"221.76000","18.48017","0.04856"
"222.09000","18.50773","0.04921"
"222.42000","18.53511","0.05056"
"222.75000","18.56274","0.05101"
"223.08000","18.59018","0.05137"
"223.41000","18.61762","0.05272"
"223.74000","18.64519","0.05265"
"224.07000","18.67263","0.05291"
"224.40000","18.70019","0.05337"
"224.73000","18.72770","0.05359"
"225.06000","18.75520","0.05432"
"225.39000","18.78270","0.05501"
"225.72000","18.81015","0.05517"
"226.05000","18.83777","0.05625"
"226.38000","18.86521","0.05644"
"226.71000","18.89265","0.05712"
"227.04000","18.92022","0.05800"
"227.37000","18.94772","0.05892"
"227.70000","18.97516","0.05962"
"228.03000","19.00267","0.06040"
"228.36000","19.03017","0.06080"
"228.69000","19.05767","0.06048"
"229.02000","19.08518","0.06151"
"229.35000","19.11268","0.06212"
"229.68000","19.14018","0.06332"
"230.01000","19.16763","0.06462"
"230.34000","19.19519","0.06610"
"230.67000","19.22269","0.06642"
"231.00000","19.25014","0.06644"
"231.33000","19.27770","0.06792"
"231.66000","19.30520","0.06888"
"231.99000","19.33265","0.07029"
"232.32000","19.36021","0.07024"
"232.65000","19.38771","0.07004"
"232.98000","19.41516","0.07083"
"233.31000","19.44266","0.07266"
"233.64000","19.47022","0.07422"
"233.97000","19.49773","0.07549"
"234.30000","19.52511","0.07687"
"234.63000","19.55273","0.07683"
"234.96000","19.58024","0.07629"
"235.29000","19.60768","0.07768"
"235.62000","19.63524","0.07982"
"235.95000","19.66269","0.08146"
"236.28000","19.69019","0.06952"
"236.61000","19.71769","0.05881"
"236.94000","19.74520","0.05859"
"237.27000","19.77270","0.05813"
"237.60000","19.80014","0.05938"
"237.93000","19.82771","0.06050"
"238.26000","19.85521","0.01097"
"238.59000","19.88271","0.02390"
"238.92000","19.91015","0.01050"
"239.25000","19.93772","0.01792"
"239.58000","19.96516","0.01246"
"239.91000","19.99266","0.01548"
"240.24000","20.02017","0.00882"
"240.57000","20.04767","0.01595"
"240.90000","20.07523","0.01087"
"241.23000","20.10267","0.01137"
"241.56000","20.13018","0.01435"
"241.89000","20.15762","0.01145"
"242.22000","20.18519","0.01275"
"242.55000","20.21275","0.01372"
"242.88000","20.24013","0.01467"
"243.21000","20.26769","0.01064"
"243.54000","20.29520","0.01649"
"243.87000","20.32276","0.01234"
"244.20000","20.35020","0.01265"
"244.53000","20.37765","0.01551"
"244.86000","20.40521","0.01191"
"245.19000","20.43266","0.01364"
"245.52000","20.46016","0.01519"
"245.85000","20.48772","0.01425"
"246.18000","20.51516","0.01375"
"246.51000","20.54273","0.01449"
"246.84000","20.57017","0.01375"
"247.17000","20.59767","0.01323"
"247.50000","20.62518","0.01574"
"247.83000","20.65262","0.01373"
"248.16000","20.68018","0.01407"
"248.49000","20.70774","0.01583"
"248.82000","20.73519","0.01369"
"249.15000","20.76269","0.01621"
"249.48000","20.79014","0.01549"
"249.81000","20.81770","0.01447"
"250.14000","20.84520","0.01624"
"250.47000","20.87264","0.01408"
"250.80000","20.90021","0.01593"
"251.13000","20.92771","0.01606"
"251.46000","20.95515","0.01570"
"251.79000","20.98272","0.01684"
"252.12000","21.01016","0.01595"
"252.45000","21.03772","0.01724"
"252.78000","21.06523","0.01648"
"253.11000","21.09267","0.01674"
"253.44000","21.12017","0.01615"
"253.77000","21.14768","0.01659"
"254.10000","21.17518","0.01698"
"254.43000","21.20274","0.01643"
"254.76000","21.23019","0.01684"
"255.09000","21.25769","0.01757"
"255.42000","21.28513","0.01739"
"255.75000","21.31269","0.01798"
"256.08000","21.34020","0.01773"
"256.41000","21.36764","0.01802"
"256.74000","21.39521","0.01807"
"257.07000","21.42271","0.01825"
"257.40000","21.45021","0.01814"
"257.73000","21.47772","0.01820"
"258.06000","21.50516","0.01917"
"258.39000","21.53266","0.01874"
"258.72000","21.56017","0.01875"
"259.05000","21.58767","0.01922"
"259.38000","21.61523","0.01939"
"259.71000","21.64267","0.01913"
"260.04000","21.67018","0.01957"
"260.37000","21.69768","0.01977"
"260.70000","21.72513","0.02003"
"261.03000","21.75269","0.02019"
"261.36000","21.78019","0.02001"
"261.69000","21.80769","0.02005"
"262.02000","21.83520","0.02098"
"262.35000","21.86270","0.02143"
"262.68000","21.89020","0.02128"
"263.01000","21.91771","0.02090"
"263.34000","21.94515","0.02169"
"263.67000","21.97271","0.02149"
"264.00000","22.00016","0.02245"
"264.33000","22.02766","0.02162"
"264.66000","22.05528","0.02208"
"264.99000","22.08267","0.02289"
"265.32000","22.11023","0.02309"
"265.65000","22.13767","0.02271"
"265.98000","22.16518","0.02329"
"266.31000","22.19268","0.02217"
"266.64000","22.22012","0.02213"
"266.97000","22.24768","0.02198"
"267.30000","22.27519","0.02294"
"267.63000","22.30263","0.02278"
"267.96000","22.33019","0.02352"
"268.29000","22.35770","0.02324"
"268.62000","22.38514","0.02323"
"268.95000","22.41270","0.02358"
"269.28000","22.44015","0.02409"
"269.61000","22.46777","0.02375"
"269.94000","22.49521","0.02404"
"270.27000","22.52272","0.02500"
"270.60000","22.55016","0.02398"
"270.93000","22.57760","0.02380"
"271.26000","22.60523","0.02384"
"271.59000","22.63267","0.02438"
"271.92000","22.66017","0.02469"
"272.25000","22.68774","0.02475"
"272.58000","22.71518","0.02506"
"272.91000","22.74268","0.02414"
"273.24000","22.77019","0.02504"
"273.57000","22.79763","0.02437"
"273.90000","22.82519","0.02456"
"274.23000","22.85270","0.02448"
"274.56000","22.88020","0.02465"
"274.89000","22.90776","0.02549"
"275.22000","22.93509","0.02545"
"275.55000","22.96271","0.02596"
"275.88000","22.99021","0.02599"
"276.21000","23.01766","0.02585"
"276.54000","23.04522","0.02615"
"276.87000","23.07266","0.02674"
"277.20000","23.10023","0.02618"
"277.53000","23.12773","0.02733"
"277.86000","23.15517","0.02686"
"278.19000","23.18274","0.02728"
"278.52000","23.21018","0.02581"
"278.85000","23.23774","0.02688"
"279.18000","23.26524","0.02690"
"279.51000","23.29263","0.02736"
"279.84000","23.32025","0.02728"
"280.17000","23.34764","0.02805"
"280.50000","23.37519","0.02822"
"280.83000","23.40270","0.02716"
"281.16000","23.43014","0.02814"
"281.49000","23.45771","0.02790"
"281.82000","23.48521","0.02813"
"282.15000","23.51271","0.02804"
"282.48000","23.54021","0.02819"
"282.81000","23.56766","0.02807"
"283.14000","23.59522","0.02893"
"283.47000","23.62272","0.02871"
"283.80000","23.65017","0.02886"
"284.13000","23.67767","0.02903"
"284.46000","23.70518","0.02975"
"284.79000","23.73268","0.02982"
"285.12000","23.76018","0.02939"
"285.45000","23.78768","0.03057"
"285.78000","23.81519","0.03081"
"286.11000","23.84269","0.03090"
"286.44000","23.87013","0.03141"
"286.77000","23.89770","0.03127"
"287.10000","23.92514","0.03079"
"287.43000","23.95264","0.03052"
"287.76000","23.98021","0.03130"
"288.09000","24.00765","0.03122"
"288.42000","24.03521","0.03127"
"288.75000","24.06266","0.03082"
"289.08000","24.09016","0.03063"
"289.41000","24.11766","0.03037"
"289.74000","24.14517","0.03188"
"290.07000","24.17273","0.03146"
"290.40000","24.20017","0.03207"
"290.73000","24.22768","0.03217"
"291.06000","24.25524","0.03228"
"291.39000","24.28268","0.03252"
"291.72000","24.31018","0.03306"
"292.05000","24.33775","0.03368"
"292.38000","24.36513","0.03339"
"292.71000","24.39270","0.03322"
"293.04000","24.42020","0.03362"
"293.37000","24.44770","0.03447"
"293.70000","24.47520","0.03449"
"294.03000","24.50265","0.03416"
"294.36000","24.53021","0.03466"
"294.69000","24.55765","0.03456"
"295.02000","24.58516","0.03452"
"295.35000","24.61278","0.03473"
"295.68000","24.64017","0.03385"
"296.01000","24.66767","0.03156"
"296.34000","24.69517","0.02588"
"296.67000","24.72261","0.02550"
"297.00000","24.75018","0.02506"
"297.33000","24.77762","0.02197"
"297.66000","24.80524","0.01846"
"297.99000","24.83275","0.01814"
"298.32000","24.86019","0.01923"
"298.65000","24.88775","0.02000"
"298.98000","24.91513","0.01988"
"299.31000","24.94270","0.01677"
"299.64000","24.97026","0.01040"
"299.97000","24.99770","0.01411"
"300.30000","25.02521","0.00934"
"300.63000","25.05265","0.01169"
"300.96000","25.08015","0.01064"
"301.29000","25.10772","0.01272"
"301.62000","25.13516","0.01065"
"301.95000","25.16266","0.01291"
"302.28000","25.19023","0.01117"
"302.61000","25.21761","0.01286"
"302.94000","25.24517","0.01237"
"303.27000","25.27268","0.01308"
"303.60000","25.30018","0.01314"
"303.93000","25.32774","0.01384"
"304.26000","25.35513","0.01212"
"304.59000","25.38275","0.01499"
"304.92000","25.41013","0.01420"
"305.25000","25.43770","0.01439"
"305.58000","25.46520","0.01504"
"305.91000","25.49264","0.01513"
"306.24000","25.52021","0.01580"
"306.57000","25.54771","0.01526"
"306.90000","25.57515","0.01577"
"307.23000","25.60266","0.01598"
"307.56000","25.63016","0.01643"
"307.89000","25.65772","0.01682"
"308.22000","25.68517","0.01633"
"308.55000","25.71267","0.01638"
"308.88000","25.74017","0.01678"
"309.21000","25.76768","0.01715"
"309.54000","25.79518","0.01786"
"309.87000","25.82268","0.01775"
"310.20000","25.85012","0.01761"
"310.53000","25.87775","0.01798"
"310.86000","25.90519","0.01857"
"311.19000","25.93269","0.01884"
"311.52000","25.96014","0.01892"
"311.85000","25.98764","0.01903"
"312.18000","26.01520","0.01927"
"312.51000","26.04271","0.02014"
"312.84000","26.07015","0.02017"
"313.17000","26.09771","0.02028"
"313.50000","26.12522","0.02001"
"313.83000","26.15266","0.02099"
"314.16000","26.18022","0.02137"
"314.49000","26.20761","0.02156"
"314.82000","26.23523","0.02197"
"315.15000","26.26267","0.02162"
"315.48000","26.29017","0.02154"
"315.81000","26.31768","0.02225"
"316.14000","26.34512","0.02164"
"316.47000","26.37275","0.02187"
"316.80000","26.40019","0.02209"
"317.13000","26.42769","0.02238"
"317.46000","26.45525","0.02262"
"317.79000","26.48264","0.02302"
"318.12000","26.51014","0.02308"
"318.45000","26.53770","0.02299"
"318.78000","26.56515","0.02337"
"319.11000","26.59271","0.02347"
"319.44000","26.62021","0.02433"
"319.77000","26.64772","0.02413"
"320.10000","26.67516","0.02351"
"320.43000","26.70260","0.02473"
"320.76000","26.73023","0.02476"
"321.09000","26.75773","0.02504"
"321.42000","26.78517","0.02538"
"321.75000","26.81280","0.02551"
"322.08000","26.84012","0.02644"
"322.41000","26.86768","0.02608"
"322.74000","26.89518","0.02632"
"323.07000","26.92269","0.02740"
"323.40000","26.95025","0.02643"
"323.73000","26.97764","0.02693"
"324.06000","27.00520","0.02644"
"324.39000","27.03264","0.02750"
"324.72000","27.06008","0.02690"
"325.05000","27.08771","0.02788"
"325.38000","27.11521","0.02704"
"325.71000","27.14265","0.02705"
"326.04000","27.17016","0.02746"
"326.37000","27.19766","0.02774"
"326.70000","27.22516","0.02767"
"327.03000","27.25267","0.02778"
"327.36000","27.28017","0.02789"
"327.69000","27.30767","0.02873"
"328.02000","27.33518","0.02894"
"328.35000","27.36268","0.02909"
"328.68000","27.39024","0.02954"
"329.01000","27.41763","0.02568"
"329.34000","27.44519","0.02495"
"329.67000","27.47269","0.02473"
"330.00000","27.50019","0.02557"
"330.33000","27.52770","0.02647"
"330.66000","27.55514","0.02676"
"330.99000","27.58270","0.02687"
"331.32000","27.61021","0.02744"
"331.65000","27.63765","0.02737"
"331.98000","27.66522","0.02746"
"332.31000","27.69266","0.02715"
"332.64000","27.72016","0.02716"
"332.97000","27.74772","0.02730"
"333.30000","27.77511","0.02792"
"333.63000","27.80273","0.02789"
"333.96000","27.83017","0.02790"
"334.29000","27.85774","0.02632"
"334.62000","27.88518","0.02450"
"334.95000","27.91269","0.02559"
"335.28000","27.94019","0.02504"
"335.61000","27.96769","0.02698"
"335.94000","27.99514","0.02655"
"336.27000","28.02276","0.02713"
"336.60000","28.05014","0.02741"
"336.93000","28.07770","0.02764"
"337.26000","28.10521","0.02762"
"337.59000","28.13265","0.02789"
"337.92000","28.16021","0.02896"
"338.25000","28.18772","0.02881"
"338.58000","28.21522","0.02898"
"338.91000","28.24272","0.02975"
"339.24000","28.27017","0.02942"
"339.57000","28.29773","0.02807"
"339.90000","28.32511","0.01761"
"340.23000","28.35267","0.01866"
"340.56000","28.38024","0.01752"
"340.89000","28.40762","0.01860"
"341.22000","28.43519","0.01990"
"341.55000","28.46269","0.01786"
"341.88000","28.49013","0.02121"
"342.21000","28.51769","0.01864"
"342.54000","28.54514","0.02052"
"342.87000","28.57270","0.02182"
"343.20000","28.60020","0.02147"
"343.53000","28.62765","0.02266"
"343.86000","28.65521","0.02298"
"344.19000","28.68265","0.02322"
"344.52000","28.71016","0.02375"
"344.85000","28.73772","0.02390"
"345.18000","28.76516","0.02495"
"345.51000","28.79273","0.02427"
"345.84000","28.82023","0.02544"
"346.17000","28.84767","0.02575"
"346.50000","28.87524","0.02616"
"346.83000","28.90262","0.02632"
"347.16000","28.93024","0.02627"
"347.49000","28.95774","0.02679"
"347.82000","28.98513","0.02704"
"348.15000","29.01275","0.02747"
"348.48000","29.04020","0.02866"
"348.81000","29.06770","0.02825"
"349.14000","29.09520","0.02891"
"349.47000","29.12264","0.02958"
"349.80000","29.15021","0.03013"
"350.13000","29.17771","0.03001"
"350.46000","29.20521","0.02994"
"350.79000","29.23272","0.03017"
"351.12000","29.26016","0.03105"
"351.45000","29.28773","0.03147"
"351.78000","29.31523","0.03129"
"352.11000","29.34267","0.03183"
"352.44000","29.37017","0.03196"
"352.77000","29.39768","0.03157"
"353.10000","29.42512","0.03194"
"353.43000","29.45268","0.03181"
"353.76000","29.48019","0.03219"
"354.09000","29.50769","0.03249"
"354.42000","29.53519","0.03277"
"354.75000","29.56269","0.02925"
"355.08000","29.59020","0.02882"
"355.41000","29.61764","0.02902"
"355.74000","29.64521","0.03032"
"356.07000","29.67271","0.03014"
"356.40000","29.70015","0.03092"
"356.73000","29.72771","0.03093"
"357.06000","29.75522","0.03146"
"357.39000","29.78272","0.03191"
"357.72000","29.81016","0.03176"
"358.05000","29.83767","0.03259"
"358.38000","29.86517","0.03225"
"358.71000","29.89268","0.03308"
"359.04000","29.92018","0.03320"
"359.37000","29.94774","0.03409"
"359.70000","29.97512","0.03418"
"360.03000","30.00269","0.03429"
"360.36000","30.03019","0.03433"
"360.69000","30.05763","0.03475"
"361.02000","30.08514","0.03552"
"361.35000","30.11264","0.03606"
"361.68000","30.14020","0.03690"
"362.01000","30.16771","0.03687"
"362.34000","30.19515","0.03710"
"362.67000","30.22271","0.03741"
"363.00000","30.25016","0.03789"
"363.33000","30.27766","0.03857"
"363.66000","30.30528","0.03985"
"363.99000","30.33261","0.04056"
"364.32000","30.36017","0.04146"
"364.65000","30.38773","0.04175"
"364.98000","30.41524","0.04267"
"365.31000","30.44268","0.04285"
"365.64000","30.47012","0.04377"
"365.97000","30.49768","0.04452"
"366.30000","30.52519","0.04568"
"366.63000","30.55269","0.04581"
"366.96000","30.58026","0.04426"
"367.29000","30.60770","0.04310"
"367.62000","30.63520","0.04425"
"367.95000","30.66276","0.04401"
"368.28000","30.69021","0.04559"
"368.61000","30.71771","0.04673"
"368.94000","30.74515","0.04719"
"369.27000","30.77272","0.04744"
"369.60000","30.80022","0.04812"
"369.93000","30.82766","0.04893"
"370.26000","30.85523","0.04845"
"370.59000","30.88273","0.04981"
"370.92000","30.91017","0.04962"
"371.25000","30.93768","0.04452"
"371.58000","30.96518","0.04250"
"371.91000","30.99268","0.04344"
"372.24000","31.02019","0.04336"
"372.57000","31.04763","0.04336"
"372.90000","31.07519","0.04392"
"373.23000","31.10263","0.04516"
"373.56000","31.13020","0.04577"
"373.89000","31.15770","0.04694"
"374.22000","31.18515","0.04732"
"374.55000","31.21271","0.04765"
"374.88000","31.24021","0.04370"
"375.21000","31.26765","0.04357"
"375.54000","31.29516","0.04455"
"375.87000","31.32266","0.04549"
"376.20000","31.35022","0.04580"
"376.53000","31.37767","0.04610"
"376.86000","31.40523","0.04622"
"377.19000","31.43273","0.04668"
"377.52000","31.46018","0.04815"
"377.85000","31.48768","0.04815"
"378.18000","31.51524","0.04850"
"378.51000","31.54263","0.04932"
"378.84000","31.57025","0.04930"
"379.17000","31.59769","0.04995"
"379.50000","31.62513","0.05024"
"379.83000","31.65270","0.04942"
"380.16000","31.68020","0.04965"
"380.49000","31.70770","0.04760"
"380.82000","31.73521","0.04851"
"381.15000","31.76265","0.04892"
"381.48000","31.79021","0.03781"
"381.81000","31.81766","0.04193"
"382.14000","31.84522","0.04034"
"382.47000","31.87272","0.04400"
"382.80000","31.90011","0.04236"
"383.13000","31.92773","0.04535"
"383.46000","31.95517","0.04407"
"383.79000","31.98268","0.04691"
"384.12000","32.01018","0.04595"
"384.45000","32.03768","0.04759"
"384.78000","32.06525","0.04529"
"385.11000","32.09269","0.04566"
"385.44000","32.12019","0.04254"
"385.77000","32.14769","0.03674"
"386.10000","32.17514","0.03118"
"386.43000","32.20270","0.02802"
"386.76000","32.23021","0.02791"
"387.09000","32.25765","0.02894"
"387.42000","32.28521","0.03037"
"387.75000","32.31271","0.03017"
"388.08000","32.34016","0.03059"
"388.41000","32.36766","0.03088"
"388.74000","32.39511","0.03210"
"389.07000","32.42273","0.03290"
"389.40000","32.45017","0.03221"
"389.73000","32.47767","0.03155"
"390.06000","32.50524","0.02905"
"390.39000","32.53262","0.02741"
"390.72000","32.56025","0.02696"
"391.05000","32.58762","0.02733"
"391.38000","32.61513","0.02836"
"391.71000","32.64269","0.02753"
"392.04000","32.67014","0.02813"
"392.37000","32.69776","0.02891"
"392.70000","32.72520","0.02848"
"393.03000","32.75264","0.02847"
"393.36000","32.78027","0.02797"
"393.69000","32.80771","0.02837"
"394.02000","32.83522","0.02895"
"394.35000","32.86272","0.02933"
"394.68000","32.89010","0.02857"
"395.01000","32.91772","0.01763"
"395.34000","32.94523","0.01735"
"395.67000","32.97267","0.01813"
"396.00000","33.00018","0.01847"
"396.33000","33.02762","0.01899"
"396.66000","33.05524","0.01883"
"396.99000","33.08274","0.01943"
"397.32000","33.11019","0.02009"
"397.65000","33.13769","0.02001"
"397.98000","33.16520","0.01977"
"398.31000","33.19270","0.01977"
"398.64000","33.22020","0.01911"
"398.97000","33.24764","0.02018"
"399.30000","33.27521","0.02012"
"399.63000","33.30265","0.02023"
"399.96000","33.33021","0.02102"
"400.29000","33.35772","0.02102"
"400.62000","33.38510","0.02130"
"400.95000","33.41272","0.02109"
"401.28000","33.44017","0.02160"
"401.61000","33.46761","0.02221"
"401.94000","33.49523","0.02200"
"402.27000","33.52262","0.02193"
"402.60000","33.55024","0.02220"
"402.93000","33.57768","0.02320"
"403.26000","33.60518","0.02335"
"403.59000","33.63275","0.02295"
"403.92000","33.66013","0.02360"
"404.25000","33.68769","0.02381"
"404.58000","33.71519","0.02381"
"404.91000","33.74264","0.02388"
"405.24000","33.77020","0.02395"
"405.57000","33.79771","0.02385"
"405.90000","33.82521","0.02439"
"406.23000","33.85271","0.02485"
"406.56000","33.88015","0.02418"
"406.89000","33.90772","0.02444"
"407.22000","33.93522","0.02517"
"407.55000","33.96267","0.02479"
"407.88000","33.99023","0.02482"
"408.21000","34.01767","0.02541"
"408.54000","34.04517","0.02531"
"408.87000","34.07274","0.02576"
"409.20000","34.10012","0.02600"
"409.53000","34.12769","0.02615"
"409.86000","34.15519","0.02619"
"410.19000","34.18269","0.02655"
"410.52000","34.21013","0.02720"
"410.85000","34.23764","0.02656"
"411.18000","34.26520","0.02659"
"411.51000","34.29271","0.02652"
"411.84000","34.32015","0.02653"
"412.17000","34.34771","0.02692"
"412.50000","34.37515","0.02765"
"412.83000","34.40266","0.02745"
"413.16000","34.43022","0.02770"
"413.49000","34.45766","0.02800"
"413.82000","34.48523","0.02745"
"414.15000","34.51267","0.02788"
"414.48000","34.54017","0.02829"
"414.81000","34.56768","0.02823"
"415.14000","34.59512","0.02879"
"415.47000","34.62268","0.02890"
"415.80000","34.65025","0.02936"
"416.13000","34.67763","0.02895"
"416.46000","34.70525","0.02976"
"416.79000","34.73264","0.02979"
"417.12000","34.76014","0.03003"
"417.45000","34.78770","0.02814"
"417.78000","34.81515","0.02855"
"418.11000","34.84271","0.02926"
"418.44000","34.87015","0.02895"
"418.77000","34.89772","0.02423"
"419.10000","34.92522","0.01810"
"419.43000","34.95260","0.01860"
"419.76000","34.98022","0.02143"
"420.09000","35.00767","0.01866"
"420.42000","35.03517","0.02314"
"420.75000","35.06273","0.01987"
"421.08000","35.09018","0.02374"
"421.41000","35.11762","0.02129"
"421.74000","35.14519","0.02375"
"422.07000","35.17269","0.02264"
"422.40000","35.20019","0.02405"
"422.73000","35.22770","0.02299"
"423.06000","35.25520","0.02387"
"423.39000","35.28276","0.02326"
"423.72000","35.31014","0.02389"
"424.05000","35.33770","0.02433"
"424.38000","35.36521","0.02411"
"424.71000","35.39265","0.02439"
"425.04000","35.42022","0.02435"
"425.37000","35.44766","0.02466"
"425.70000","35.47522","0.02295"
"426.03000","35.50267","0.02327"
"426.36000","35.53017","0.02293"
"426.69000","35.55767","0.02334"
"427.02000","35.58517","0.02334"
"427.35000","35.61268","0.02338"
"427.68000","35.64024","0.02359"
"428.01000","35.66763","0.02308"
"428.34000","35.69519","0.02397"
"428.67000","35.72269","0.02355"
"429.00000","35.75019","0.02425"
"429.33000","35.77770","0.02454"
"429.66000","35.80514","0.02424"
"429.99000","35.83264","0.02484"
"430.32000","35.86015","0.02488"
"430.65000","35.88765","0.02527"
"430.98000","35.91515","0.02578"
"431.31000","35.94272","0.02503"
"431.64000","35.97022","0.02493"
"431.97000","35.99778","0.02571"
"432.30000","36.02517","0.02498"
"432.63000","36.05267","0.02528"
"432.96000","36.08017","0.02572"
"433.29000","36.10768","0.02582"
"433.62000","36.13518","0.02572"
"433.95000","36.16268","0.02641"
"434.28000","36.19019","0.02614"
"434.61000","36.21769","0.02636"
"434.94000","36.24513","0.02656"
"435.27000","36.27270","0.02639"
"435.60000","36.30014","0.02561"
"435.93000","36.32770","0.02586"
"436.26000","36.35521","0.02510"
"436.59000","36.38265","0.02436"
"436.92000","36.41015","0.02330"
"437.25000","36.43765","0.02348"
"437.58000","36.46522","0.02333"
"437.91000","36.49272","0.02362"
"438.24000","36.52016","0.02387"
"438.57000","36.54767","0.02464"
"438.90000","36.57517","0.02463"
"439.23000","36.60261","0.02511"
"439.56000","36.63018","0.02533"
"439.89000","36.65768","0.02489"
"440.22000","36.68524","0.02140"
"440.55000","36.71275","0.02219"
"440.88000","36.74019","0.02221"
"441.21000","36.76769","0.02150"
"441.54000","36.79514","0.02263"
"441.87000","36.82270","0.01902"
"442.20000","36.85026","0.01959"
"442.53000","36.87765","0.01927"
"442.86000","36.90521","0.01912"
"443.19000","36.93265","0.01947"
"443.52000","36.96016","0.01931"
"443.85000","36.98772","0.02027"
"444.18000","37.01516","0.02024"
"444.51000","37.04272","0.01996"
"444.84000","37.07017","0.01991"
"445.17000","37.09767","0.02007"
"445.50000","37.12518","0.02006"
"445.83000","37.15262","0.02068"
"446.16000","37.18018","0.02051"
"446.49000","37.20774","0.02006"
"446.82000","37.23519","0.02100"
"447.15000","37.26269","0.02059"
"447.48000","37.29019","0.02042"
"447.81000","37.31770","0.02108"
"448.14000","37.34514","0.02122"
"448.47000","37.37265","0.02151"
"448.80000","37.40020","0.02225"
"449.13000","37.42765","0.02166"
"449.46000","37.45521","0.02214"
"449.79000","37.48272","0.02207"
"450.12000","37.51016","0.02249"
"450.45000","37.53772","0.02181"
"450.78000","37.56522","0.02244"
"451.11000","37.59267","0.02292"
"451.44000","37.62023","0.02253"
"451.77000","37.64767","0.02300"
"452.10000","37.67518","0.02315"
"452.43000","37.70268","0.02358"
"452.76000","37.73018","0.02364"
"453.09000","37.75775","0.02334"
"453.42000","37.78519","0.02191"
"453.75000","37.81269","0.02154"
"454.08000","37.84026","0.02249"
"454.41000","37.86764","0.02215"
"454.74000","37.89514","0.02276"
"455.07000","37.92271","0.02274"
"455.40000","37.95015","0.02432"
"455.73000","37.97771","0.01987"
"456.06000","38.00516","0.01790"
"456.39000","38.03266","0.01614"
"456.72000","38.06016","0.01348"
"457.05000","38.08767","0.01492"
"457.38000","38.11523","0.01560"
"457.71000","38.14267","0.01448"
"458.04000","38.17018","0.01446"
"458.37000","38.19774","0.01770"
"458.70000","38.22512","0.01327"
"459.03000","38.25275","0.01565"
"459.36000","38.28019","0.01669"
"459.69000","38.30769","0.01514"
"460.02000","38.33520","0.01608"
"460.35000","38.36264","0.01726"
"460.68000","38.39020","0.01585"
"461.01000","38.41771","0.01756"
"461.34000","38.44515","0.01734"
"461.67000","38.47277","0.01689"
"462.00000","38.50016","0.01794"
"462.33000","38.52766","0.01777"
"462.66000","38.55522","0.01724"
"462.99000","38.58260","0.01874"
"463.32000","38.61023","0.01774"
"463.65000","38.63767","0.01702"
"463.98000","38.66523","0.01872"
"464.31000","38.69273","0.01766"
"464.64000","38.72018","0.01839"
"464.97000","38.74774","0.01852"
"465.30000","38.77519","0.01822"
"465.63000","38.80263","0.01802"
"465.96000","38.83020","0.01935"
"466.29000","38.85764","0.01936"
"466.62000","38.88520","0.01984"
"466.95000","38.91270","0.01972"
"467.28000","38.94015","0.01947"
"467.61000","38.96771","0.02050"
"467.94000","38.99516","0.01938"
"468.27000","39.02271","0.02058"
"468.60000","39.05022","0.02041"
"468.93000","39.07760","0.02070"
"469.26000","39.10522","0.02019"
"469.59000","39.13272","0.01964"
"469.92000","39.16017","0.01982"
"470.25000","39.18767","0.01989"
"470.58000","39.21518","0.02041"
"470.91000","39.24274","0.01996"
"471.24000","39.27018","0.01996"
"471.57000","39.29768","0.01984"
"471.90000","39.32519","0.01979"
"472.23000","39.35263","0.02061"
"472.56000","39.38020","0.02026"
"472.89000","39.40776","0.02099"
"473.22000","39.43515","0.02114"
"473.55000","39.46265","0.02074"
"473.88000","39.49020","0.02071"
"474.21000","39.51765","0.02126"
"474.54000","39.54522","0.02100"
"474.87000","39.57266","0.02125"
"475.20000","39.60016","0.02111"
"475.53000","39.62767","0.02167"
"475.86000","39.65516","0.02207"
"476.19000","39.68273","0.02208"
"476.52000","39.71017","0.02230"
"476.85000","39.73767","0.02223"
"477.18000","39.76524","0.02337"
"477.51000","39.79262","0.02319"
"477.84000","39.82019","0.02314"
"478.17000","39.84769","0.02281"
"478.50000","39.87519","0.02284"
"478.83000","39.90270","0.02321"
"479.16000","39.93020","0.02345"
"479.49000","39.95771","0.02361"
"479.82000","39.98520","0.02313"
"480.15000","40.01271","0.02361"
"480.48000","40.04021","0.02349"
"480.81000","40.06766","0.02306"
"481.14000","40.09516","0.02349"
"481.47000","40.12272","0.02352"
"481.80000","40.15017","0.01844"
"482.13000","40.17773","0.01864"
"482.46000","40.20517","0.01712"
"482.79000","40.23267","0.01906"
"483.12000","40.26018","0.01840"
"483.45000","40.28762","0.01966"
"483.78000","40.31519","0.01880"
"484.11000","40.34269","0.01992"
"484.44000","40.37019","0.01912"
"484.77000","40.39775","0.02043"
"485.10000","40.42514","0.01950"
"485.43000","40.45270","0.02050"
"485.76000","40.48020","0.01979"
"486.09000","40.50765","0.02099"
"486.42000","40.53521","0.02037"
"486.75000","40.56266","0.02009"
"487.08000","40.59022","0.02085"
"487.41000","40.61772","0.02039"
"487.62400","40.63554","0.02023"