File: Force_trajectories/170122_2/Specimen_RawData_7.csv
End date,"1/22/2017"
Specimen label,"12CG_95"
Maximum Load,"0.02496",N

Time,Extension,Load
(s),(mm),(N)
"0.00000","0.00000","-0.00090"
"0.15600","0.00909","0.00027"
"0.31200","0.02571","0.00079"
"0.46800","0.03934","0.00173"
"0.62400","0.05220","0.00118"
"0.78000","0.06529","0.00324"
"0.93600","0.07826","0.00228"
"1.09200","0.09124","0.00220"
"1.24800","0.10421","0.00293"
"1.40400","0.11725","0.00327"
"1.56000","0.13022","0.00311"
"1.71600","0.14320","0.00348"
"1.87200","0.15623","0.00389"
"2.02800","0.16926","0.00365"
"2.18400","0.18224","0.00341"
"2.34000","0.19521","0.00332"
"2.49600","0.20825","0.00440"
"2.65200","0.22122","0.00423"
"2.80800","0.23420","0.00412"
"2.96400","0.24723","0.00440"
"3.12000","0.26026","0.00507"
"3.27600","0.27324","0.00446"
"3.43200","0.28627","0.00511"
"3.58800","0.29925","0.00451"
"3.74400","0.31222","0.00443"
"3.90000","0.32520","0.00499"
"4.05600","0.33829","0.00511"
"4.21200","0.35120","0.00480"
"4.36800","0.36424","0.00573"
"4.52400","0.37721","0.00484"
"4.68000","0.39025","0.00549"
"4.83600","0.40316","0.00555"
"4.99200","0.41619","0.00498"
"5.14800","0.42917","0.00623"
"5.30400","0.44220","0.00612"
"5.46000","0.45518","0.00582"
"5.61600","0.46827","0.00502"
"5.77200","0.48125","0.00570"
"5.92800","0.49422","0.00577"
"6.08400","0.50719","0.00633"
"6.24000","0.52023","0.00572"
"6.39600","0.53320","0.00561"
"6.55200","0.54618","0.00654"
"6.70800","0.55921","0.00649"
"6.86400","0.57219","0.00609"
"7.02000","0.58516","0.00652"
"7.17600","0.59819","0.00697"
"7.33200","0.61123","0.00619"
"7.48800","0.62420","0.00682"
"7.64400","0.63718","0.00637"
"7.80000","0.65021","0.00617"
"7.95600","0.66325","0.00624"
"8.11200","0.67616","0.00612"
"8.26800","0.68919","0.00687"
"8.42400","0.70223","0.00666"
"8.58000","0.71520","0.00649"
"8.73600","0.72812","0.00641"
"8.89200","0.74121","0.00663"
"9.04800","0.75424","0.00674"
"9.20400","0.76722","0.00687"
"9.36000","0.78025","0.00685"
"9.51600","0.79329","0.00681"
"9.67200","0.80620","0.00640"
"9.82800","0.81924","0.00668"
"9.98400","0.83221","0.00742"
"10.14000","0.84524","0.00651"
"10.29600","0.85816","0.00685"
"10.45200","0.87119","0.00729"
"10.60800","0.88423","0.00690"
"10.76400","0.89720","0.00707"
"10.92000","0.91018","0.00685"
"11.07600","0.92327","0.00718"
"11.23200","0.93618","0.00714"
"11.38800","0.94916","0.00673"
"11.54400","0.96225","0.00711"
"11.70000","0.97523","0.00765"
"11.85600","0.98820","0.00730"
"12.01200","1.00124","0.00748"
"12.16800","1.01421","0.00741"
"12.32400","1.02718","0.00813"
"12.48000","1.04016","0.00743"
"12.63600","1.05319","0.00695"
"12.79200","1.06623","0.00796"
"12.94800","1.07920","0.00739"
"13.10400","1.09224","0.00776"
"13.26000","1.10521","0.00730"
"13.41600","1.11818","0.00701"
"13.57200","1.13116","0.00763"
"13.72800","1.14425","0.00822"
"13.88400","1.15723","0.00815"
"14.04000","1.17020","0.00780"
"14.19600","1.18323","0.00807"
"14.35200","1.19627","0.00809"
"14.50800","1.20918","0.00774"
"14.66400","1.22222","0.00772"
"14.82000","1.23525","0.00839"
"14.97600","1.24823","0.00778"
"15.13200","1.26120","0.00789"
"15.28800","1.27423","0.00792"
"15.44400","1.28727","0.00779"
"15.60000","1.30018","0.00815"
"15.75600","1.31316","0.00826"
"15.91200","1.32625","0.00799"
"16.06800","1.33923","0.00804"
"16.22400","1.35214","0.00783"
"16.38000","1.36523","0.00849"
"16.53600","1.37827","0.00844"
"16.69200","1.39118","0.00873"
"16.84800","1.40416","0.00846"
"17.00400","1.41719","0.00837"
"17.16000","1.43017","0.00856"
"17.31600","1.44314","0.00778"
"17.47200","1.45623","0.00817"
"17.62800","1.46921","0.00858"
"17.78400","1.48218","0.00843"
"17.94000","1.49522","0.00861"
"18.09600","1.50825","0.00855"
"18.25200","1.52123","0.00819"
"18.40800","1.53426","0.00831"
"18.56400","1.54723","0.00871"
"18.72000","1.56027","0.00893"
"18.87600","1.57318","0.00891"
"19.03200","1.58622","0.00869"
"19.18800","1.59925","0.00843"
"19.34400","1.61222","0.00876"
"19.50000","1.62520","0.00895"
"19.65600","1.63823","0.00897"
"19.81200","1.65127","0.00864"
"19.96800","1.66418","0.00894"
"20.12400","1.67722","0.00843"
"20.28000","1.69025","0.00912"
"20.43600","1.70322","0.00948"
"20.59200","1.71620","0.00899"
"20.74800","1.72923","0.00902"
"20.90400","1.74221","0.00895"
"21.06000","1.75512","0.00888"
"21.21600","1.76822","0.00859"
"21.37200","1.78125","0.00932"
"21.52800","1.79416","0.00947"
"21.68400","1.80720","0.00857"
"21.84000","1.82023","0.00926"
"21.99600","1.83327","0.00974"
"22.15200","1.84618","0.00905"
"22.30800","1.85922","0.00933"
"22.46400","1.87225","0.00954"
"22.62000","1.88522","0.00972"
"22.77600","1.89826","0.00913"
"22.93200","1.91123","0.00917"
"23.08800","1.92421","0.00930"
"23.24400","1.93718","0.00932"
"23.40000","1.95022","0.00967"
"23.55600","1.96325","0.00917"
"23.71200","1.97622","0.00922"
"23.86800","1.98926","0.00903"
"24.02400","2.00223","0.00945"
"24.18000","2.01521","0.00914"
"24.33600","2.02818","0.00903"
"24.49200","2.04127","0.00996"
"24.64800","2.05425","0.00934"
"24.80400","2.06722","0.00970"
"24.96000","2.08020","0.00984"
"25.11600","2.09329","0.00974"
"25.27200","2.10621","0.00960"
"25.42800","2.11924","0.01049"
"25.58400","2.13227","0.00957"
"25.74000","2.14525","0.01003"
"25.89600","2.15816","0.00955"
"26.05200","2.17120","0.00953"
"26.20800","2.18423","0.01038"
"26.36400","2.19721","0.00985"
"26.52000","2.21018","0.01013"
"26.67600","2.22321","0.00984"
"26.83200","2.23625","0.01036"
"26.98800","2.24916","0.01004"
"27.14400","2.26220","0.00970"
"27.30000","2.27529","0.00997"
"27.45600","2.28821","0.00961"
"27.61200","2.30124","0.01038"
"27.76800","2.31421","0.00970"
"27.92400","2.32725","0.00977"
"28.08000","2.34022","0.00981"
"28.23600","2.35320","0.01018"
"28.39200","2.36623","0.01052"
"28.54800","2.37920","0.01001"
"28.70400","2.39224","0.01033"
"28.86000","2.40527","0.00960"
"29.01600","2.41825","0.01025"
"29.17200","2.43122","0.00999"
"29.32800","2.44426","0.01038"
"29.48400","2.45723","0.01017"
"29.64000","2.47014","0.01091"
"29.79600","2.48324","0.01031"
"29.95200","2.49621","0.01067"
"30.10800","2.50919","0.01059"
"30.26400","2.52216","0.01068"
"30.42000","2.53520","0.01096"
"30.57600","2.54823","0.01065"
"30.73200","2.56120","0.01070"
"30.88800","2.57424","0.01038"
"31.04400","2.58727","0.01108"
"31.20000","2.60019","0.01044"
"31.35600","2.61322","0.01086"
"31.51200","2.62620","0.01121"
"31.66800","2.63923","0.01058"
"31.82400","2.65214","0.01105"
"31.98000","2.66524","0.01100"
"32.13600","2.67827","0.01186"
"32.29200","2.69119","0.01119"
"32.44800","2.70422","0.01131"
"32.60400","2.71725","0.01075"
"32.76000","2.73029","0.01087"
"32.91600","2.74314","0.01082"
"33.07200","2.75630","0.01158"
"33.22800","2.76927","0.01107"
"33.38400","2.78219","0.01088"
"33.54000","2.79516","0.01138"
"33.69600","2.80819","0.01070"
"33.85200","2.82123","0.01116"
"34.00800","2.83414","0.01175"
"34.16400","2.84724","0.01125"
"34.32000","2.86027","0.01112"
"34.47600","2.87319","0.01146"
"34.63200","2.88622","0.01179"
"34.78800","2.89919","0.01185"
"34.94400","2.91217","0.01148"
"35.10000","2.92514","0.01183"
"35.25600","2.93818","0.01153"
"35.41200","2.95121","0.01166"
"35.56800","2.96419","0.01210"
"35.72400","2.97722","0.01133"
"35.88000","2.99025","0.01180"
"36.03600","3.00317","0.01157"
"36.19200","3.01620","0.01141"
"36.34800","3.02924","0.01170"
"36.50400","3.04221","0.01165"
"36.66000","3.05519","0.01174"
"36.81600","3.06822","0.01197"
"36.97200","3.08125","0.01192"
"37.12800","3.09417","0.01144"
"37.28400","3.10720","0.01198"
"37.44000","3.12018","0.01143"
"37.59600","3.13321","0.01180"
"37.75200","3.14618","0.01176"
"37.90800","3.15928","0.01187"
"38.06400","3.17225","0.01179"
"38.22000","3.18523","0.01229"
"38.37600","3.19820","0.01190"
"38.53200","3.21124","0.01166"
"38.68800","3.22415","0.01219"
"38.84400","3.23712","0.01212"
"39.00000","3.25022","0.01187"
"39.15600","3.26325","0.01289"
"39.31200","3.27617","0.01253"
"39.46800","3.28926","0.01215"
"39.62400","3.30224","0.01236"
"39.78000","3.31521","0.01230"
"39.93600","3.32818","0.01248"
"40.09200","3.34128","0.01236"
"40.24800","3.35425","0.01180"
"40.40400","3.36717","0.01217"
"40.56000","3.38020","0.01241"
"40.71600","3.39324","0.01240"
"40.87200","3.40615","0.01250"
"41.02800","3.41918","0.01243"
"41.18400","3.43222","0.01272"
"41.34000","3.44525","0.01294"
"41.49600","3.45823","0.01272"
"41.65200","3.47126","0.01217"
"41.80800","3.48429","0.01261"
"41.96400","3.49721","0.01227"
"42.12000","3.51018","0.01229"
"42.27600","3.52322","0.01274"
"42.43200","3.53619","0.01265"
"42.58800","3.54917","0.01273"
"42.74400","3.56220","0.01285"
"42.90000","3.57523","0.01296"
"43.05600","3.58815","0.01278"
"43.21200","3.60124","0.01270"
"43.36800","3.61422","0.01338"
"43.52400","3.62719","0.01277"
"43.68000","3.64017","0.01319"
"43.83600","3.65320","0.01325"
"43.99200","3.66623","0.01296"
"44.14800","3.67921","0.01274"
"44.30400","3.69218","0.01302"
"44.46000","3.70522","0.01336"
"44.61600","3.71819","0.01288"
"44.77200","3.73117","0.01276"
"44.92800","3.74426","0.01339"
"45.08400","3.75729","0.01284"
"45.24000","3.77021","0.01309"
"45.39600","3.78324","0.01263"
"45.55200","3.79622","0.01325"
"45.70800","3.80919","0.01282"
"45.86400","3.82217","0.01307"
"46.02000","3.83520","0.01341"
"46.17600","3.84823","0.01306"
"46.33200","3.86121","0.01345"
"46.48800","3.87424","0.01297"
"46.64400","3.88722","0.01303"
"46.80000","3.90019","0.01280"
"46.95600","3.91322","0.01357"
"47.11200","3.92626","0.01336"
"47.26800","3.93917","0.01350"
"47.42400","3.95221","0.01346"
"47.58000","3.96524","0.01396"
"47.73600","3.97828","0.01350"
"47.89200","3.99119","0.01353"
"48.04800","4.00422","0.01371"
"48.20400","4.01720","0.01366"
"48.36000","4.03023","0.01359"
"48.51600","4.04321","0.01376"
"48.67200","4.05630","0.01367"
"48.82800","4.06922","0.01391"
"48.98400","4.08219","0.01371"
"49.14000","4.09522","0.01347"
"49.29600","4.10820","0.01373"
"49.45200","4.12123","0.01413"
"49.60800","4.13415","0.01363"
"49.76400","4.14724","0.01352"
"49.92000","4.16022","0.01379"
"50.07600","4.17319","0.01327"
"50.23200","4.18622","0.01373"
"50.38800","4.19926","0.01402"
"50.54400","4.21223","0.01345"
"50.70000","4.22521","0.01466"
"50.85600","4.23824","0.01406"
"51.01200","4.25127","0.01347"
"51.16800","4.26419","0.01387"
"51.32400","4.27722","0.01413"
"51.48000","4.29020","0.01378"
"51.63600","4.30317","0.01419"
"51.79200","4.31621","0.01403"
"51.94800","4.32924","0.01429"
"52.10400","4.34227","0.01416"
"52.26000","4.35519","0.01390"
"52.41600","4.36822","0.01395"
"52.57200","4.38126","0.01416"
"52.72800","4.39417","0.01444"
"52.88400","4.40721","0.01411"
"53.04000","4.42018","0.01419"
"53.19600","4.43321","0.01387"
"53.35200","4.44613","0.01479"
"53.50800","4.45928","0.01420"
"53.66400","4.47220","0.01440"
"53.82000","4.48523","0.01401"
"53.97600","4.49821","0.01477"
"54.13200","4.51130","0.01404"
"54.28800","4.52427","0.01442"
"54.44400","4.53719","0.01413"
"54.60000","4.55022","0.01471"
"54.75600","4.56326","0.01475"
"54.91200","4.57623","0.01412"
"55.06800","4.58927","0.01482"
"55.22400","4.60224","0.01443"
"55.38000","4.61521","0.01414"
"55.53600","4.62819","0.01405"
"55.69200","4.64122","0.01450"
"55.84800","4.65420","0.01463"
"56.00400","4.66723","0.01484"
"56.16000","4.68021","0.01418"
"56.31600","4.69318","0.01451"
"56.47200","4.70621","0.01524"
"56.62800","4.71919","0.01472"
"56.78400","4.73222","0.01454"
"56.94000","4.74520","0.01479"
"57.09600","4.75817","0.01461"
"57.25200","4.77120","0.01491"
"57.40800","4.78424","0.01417"
"57.56400","4.79721","0.01453"
"57.72000","4.81025","0.01411"
"57.87600","4.82328","0.01492"
"58.03200","4.83626","0.01462"
"58.18800","4.84917","0.01456"
"58.34400","4.86220","0.01456"
"58.50000","4.87524","0.01517"
"58.65600","4.88815","0.01501"
"58.81200","4.90119","0.01515"
"58.96800","4.91422","0.01505"
"59.12400","4.92720","0.01403"
"59.28000","4.94017","0.01514"
"59.43600","4.95326","0.01456"
"59.59200","4.96624","0.01421"
"59.74800","4.97921","0.01417"
"59.90400","4.99219","0.01453"
"60.06000","5.00522","0.01456"
"60.21600","5.01819","0.01422"
"60.37200","5.03117","0.01414"
"60.52800","5.04420","0.01495"
"60.68400","5.05724","0.01468"
"60.84000","5.07021","0.01428"
"60.99600","5.08319","0.01420"
"61.15200","5.09628","0.01429"
"61.30800","5.10925","0.01470"
"61.46400","5.12223","0.01481"
"61.62000","5.13526","0.01446"
"61.77600","5.14824","0.01419"
"61.93200","5.16115","0.01447"
"62.08800","5.17425","0.01453"
"62.24400","5.18722","0.01466"
"62.40000","5.20025","0.01460"
"62.55600","5.21317","0.01436"
"62.71200","5.22626","0.01330"
"62.86800","5.23924","0.01391"
"63.02400","5.25215","0.01390"
"63.18000","5.26525","0.01374"
"63.33600","5.27828","0.01360"
"63.49200","5.29119","0.01384"
"63.64800","5.30417","0.01347"
"63.80400","5.31726","0.01352"
"63.96000","5.33018","0.01341"
"64.11600","5.34315","0.01360"
"64.27200","5.35625","0.01414"
"64.42800","5.36922","0.01385"
"64.58400","5.38219","0.01371"
"64.74000","5.39523","0.01366"
"64.89600","5.40820","0.01378"
"65.05200","5.42130","0.01362"
"65.20800","5.43415","0.01386"
"65.36400","5.44725","0.01339"
"65.52000","5.46022","0.01342"
"65.67600","5.47319","0.01324"
"65.83200","5.48623","0.01309"
"65.98800","5.49920","0.01412"
"66.14400","5.51218","0.01401"
"66.30000","5.52515","0.01328"
"66.45600","5.53824","0.01325"
"66.61200","5.55122","0.01380"
"66.76800","5.56419","0.01349"
"66.92400","5.57723","0.01405"
"67.08000","5.59020","0.01376"
"67.23600","5.60324","0.01365"
"67.39200","5.61615","0.01300"
"67.54800","5.62924","0.01361"
"67.70400","5.64222","0.01395"
"67.86000","5.65519","0.01336"
"68.01600","5.66823","0.01361"
"68.17200","5.68126","0.01352"
"68.32800","5.69418","0.01329"
"68.48400","5.70721","0.01357"
"68.64000","5.72024","0.01363"
"68.79600","5.73322","0.01408"
"68.95200","5.74619","0.01332"
"69.10800","5.75923","0.01357"
"69.26400","5.77226","0.01306"
"69.42000","5.78518","0.01313"
"69.57600","5.79815","0.01328"
"69.73200","5.81124","0.01282"
"69.88800","5.82422","0.01280"
"70.04400","5.83719","0.01362"
"70.20000","5.85029","0.01292"
"70.35600","5.86326","0.01371"
"70.51200","5.87624","0.01336"
"70.66800","5.88921","0.01298"
"70.82400","5.90224","0.01374"
"70.98000","5.91522","0.01378"
"71.13600","5.92819","0.01362"
"71.29200","5.94123","0.01294"
"71.44800","5.95420","0.01333"
"71.60400","5.96717","0.01338"
"71.76000","5.98021","0.01356"
"71.91600","5.99324","0.01328"
"72.07200","6.00622","0.01364"
"72.22800","6.01919","0.01385"
"72.38400","6.03223","0.01388"
"72.54000","6.04520","0.01348"
"72.69600","6.05817","0.01382"
"72.85200","6.07121","0.01368"
"73.00800","6.08424","0.01347"
"73.16400","6.09716","0.01353"
"73.32000","6.11013","0.01415"
"73.47600","6.12323","0.01370"
"73.63200","6.13626","0.01421"
"73.78800","6.14923","0.01375"
"73.94400","6.16227","0.01380"
"74.10000","6.17524","0.01412"
"74.25600","6.18816","0.01409"
"74.41200","6.20125","0.01371"
"74.56800","6.21422","0.01402"
"74.72400","6.22720","0.01338"
"74.88000","6.24011","0.01403"
"75.03600","6.25321","0.01369"
"75.19200","6.26624","0.01420"
"75.34800","6.27922","0.01395"
"75.50400","6.29225","0.01413"
"75.66000","6.30523","0.01406"
"75.81600","6.31820","0.01405"
"75.97200","6.33117","0.01443"
"76.12800","6.34427","0.01415"
"76.28400","6.35724","0.01398"
"76.44000","6.37022","0.01395"
"76.59600","6.38319","0.01461"
"76.75200","6.39622","0.01368"
"76.90800","6.40914","0.01370"
"77.06400","6.42217","0.01435"
"77.22000","6.43527","0.01422"
"77.37600","6.44830","0.01409"
"77.53200","6.46122","0.01410"
"77.68800","6.47425","0.01360"
"77.84400","6.48722","0.01410"
"78.00000","6.50020","0.01415"
"78.15600","6.51317","0.01402"
"78.31200","6.52621","0.01407"
"78.46800","6.53924","0.01402"
"78.62400","6.55216","0.01430"
"78.78000","6.56519","0.01358"
"78.93600","6.57822","0.01373"
"79.09200","6.59120","0.01415"
"79.24800","6.60417","0.01416"
"79.40400","6.61721","0.01397"
"79.56000","6.63018","0.01448"
"79.71600","6.64316","0.01436"
"79.87200","6.65625","0.01367"
"80.02800","6.66922","0.01414"
"80.18400","6.68220","0.01462"
"80.34000","6.69523","0.01364"
"80.49600","6.70827","0.01449"
"80.65200","6.72124","0.01405"
"80.80800","6.73421","0.01380"
"80.96400","6.74731","0.01408"
"81.12000","6.76022","0.01388"
"81.27600","6.77320","0.01324"
"81.43200","6.78617","0.01403"
"81.58800","6.79921","0.01405"
"81.74400","6.81212","0.01373"
"81.90000","6.82516","0.01436"
"82.05600","6.83819","0.01463"
"82.21200","6.85128","0.01450"
"82.36800","6.86420","0.01426"
"82.52400","6.87729","0.01444"
"82.68000","6.89027","0.01417"
"82.83600","6.90324","0.01451"
"82.99200","6.91621","0.01436"
"83.14800","6.92925","0.01464"
"83.30400","6.94222","0.01439"
"83.46000","6.95520","0.01415"
"83.61600","6.96823","0.01432"
"83.77200","6.98126","0.01431"
"83.92800","6.99418","0.01460"
"84.08400","7.00715","0.01492"
"84.24000","7.02025","0.01447"
"84.39600","7.03328","0.01436"
"84.55200","7.04620","0.01453"
"84.70800","7.05923","0.01455"
"84.86400","7.07227","0.01503"
"85.02000","7.08518","0.01456"
"85.17600","7.09821","0.01404"
"85.33200","7.11119","0.01402"
"85.48800","7.12416","0.01400"
"85.64400","7.13714","0.01457"
"85.80000","7.15017","0.01411"
"85.95600","7.16326","0.01428"
"86.11200","7.17618","0.01496"
"86.26800","7.18921","0.01474"
"86.42400","7.20225","0.01433"
"86.58000","7.21528","0.01443"
"86.73600","7.22820","0.01512"
"86.89200","7.24123","0.01454"
"87.04800","7.25426","0.01442"
"87.20400","7.26724","0.01443"
"87.36000","7.28021","0.01454"
"87.51600","7.29325","0.01528"
"87.67200","7.30622","0.01490"
"87.82800","7.31920","0.01493"
"87.98400","7.33229","0.01493"
"88.14000","7.34526","0.01493"
"88.29600","7.35824","0.01483"
"88.45200","7.37121","0.01447"
"88.60800","7.38419","0.01497"
"88.76400","7.39722","0.01507"
"88.92000","7.41020","0.01522"
"89.07600","7.42323","0.01476"
"89.23200","7.43626","0.01456"
"89.38800","7.44924","0.01479"
"89.54400","7.46221","0.01520"
"89.70000","7.47519","0.01493"
"89.85600","7.48822","0.01496"
"90.01200","7.50119","0.01465"
"90.16800","7.51423","0.01559"
"90.32400","7.52714","0.01567"
"90.48000","7.54018","0.01489"
"90.63600","7.55321","0.01537"
"90.79200","7.56625","0.01506"
"90.94800","7.57916","0.01533"
"91.10400","7.59225","0.01504"
"91.26000","7.60523","0.01527"
"91.41600","7.61820","0.01527"
"91.57200","7.63118","0.01515"
"91.72800","7.64427","0.01535"
"91.88400","7.65725","0.01551"
"92.04000","7.67016","0.01498"
"92.19600","7.68319","0.01559"
"92.35200","7.69623","0.01536"
"92.50800","7.70926","0.01604"
"92.66400","7.72218","0.01565"
"92.82000","7.73521","0.01533"
"92.97600","7.74825","0.01547"
"93.13200","7.76116","0.01522"
"93.28800","7.77425","0.01621"
"93.44400","7.78729","0.01521"
"93.60000","7.80026","0.01542"
"93.75600","7.81324","0.01522"
"93.91200","7.82627","0.01570"
"94.06800","7.83924","0.01564"
"94.22400","7.85216","0.01516"
"94.38000","7.86519","0.01543"
"94.53600","7.87823","0.01539"
"94.69200","7.89120","0.01529"
"94.84800","7.90424","0.01520"
"95.00400","7.91721","0.01516"
"95.16000","7.93024","0.01549"
"95.31600","7.94322","0.01520"
"95.47200","7.95619","0.01538"
"95.62800","7.96929","0.01566"
"95.78400","7.98220","0.01571"
"95.94000","7.99524","0.01534"
"96.09600","8.00821","0.01581"
"96.25200","8.02124","0.01586"
"96.40800","8.03416","0.01597"
"96.56400","8.04725","0.01600"
"96.72000","8.06023","0.01591"
"96.87600","8.07320","0.01598"
"97.03200","8.08618","0.01641"
"97.18800","8.09927","0.01604"
"97.34400","8.11224","0.01541"
"97.50000","8.12522","0.01579"
"97.65600","8.13825","0.01600"
"97.81200","8.15123","0.01552"
"97.96800","8.16420","0.01566"
"98.12400","8.17718","0.01620"
"98.28000","8.19021","0.01558"
"98.43600","8.20318","0.01576"
"98.59200","8.21616","0.01605"
"98.74800","8.22925","0.01610"
"98.90400","8.24223","0.01616"
"99.06000","8.25514","0.01613"
"99.21600","8.26818","0.01603"
"99.37200","8.28121","0.01631"
"99.52800","8.29418","0.01572"
"99.68400","8.30716","0.01623"
"99.84000","8.32019","0.01576"
"99.99600","8.33323","0.01619"
"100.15200","8.34614","0.01587"
"100.30800","8.35923","0.01676"
"100.46400","8.37227","0.01559"
"100.62000","8.38524","0.01629"
"100.77600","8.39822","0.01606"
"100.93200","8.41125","0.01596"
"101.08800","8.42422","0.01564"
"101.24400","8.43714","0.01557"
"101.40000","8.45017","0.01625"
"101.55600","8.46327","0.01607"
"101.71200","8.47618","0.01627"
"101.86800","8.48922","0.01641"
"102.02400","8.50225","0.01633"
"102.18000","8.51529","0.01572"
"102.33600","8.52820","0.01654"
"102.49200","8.54123","0.01589"
"102.64800","8.55421","0.01611"
"102.80400","8.56718","0.01593"
"102.96000","8.58016","0.01612"
"103.11600","8.59325","0.01635"
"103.27200","8.60623","0.01647"
"103.42800","8.61914","0.01600"
"103.58400","8.63223","0.01640"
"103.74000","8.64521","0.01632"
"103.89600","8.65818","0.01633"
"104.05200","8.67122","0.01640"
"104.20800","8.68425","0.01645"
"104.36400","8.69722","0.01610"
"104.52000","8.71020","0.01695"
"104.67600","8.72323","0.01632"
"104.83200","8.73621","0.01696"
"104.98800","8.74918","0.01656"
"105.14400","8.76222","0.01663"
"105.30000","8.77519","0.01684"
"105.45600","8.78822","0.01633"
"105.61200","8.80120","0.01658"
"105.76800","8.81423","0.01650"
"105.92400","8.82727","0.01617"
"106.08000","8.84024","0.01662"
"106.23600","8.85322","0.01558"
"106.39200","8.86625","0.01452"
"106.54800","8.87916","0.01506"
"106.70400","8.89220","0.01512"
"106.86000","8.90523","0.01549"
"107.01600","8.91821","0.01522"
"107.17200","8.93118","0.01516"
"107.32800","8.94421","0.01586"
"107.48400","8.95719","0.01602"
"107.64000","8.97022","0.01578"
"107.79600","8.98320","0.01491"
"107.95200","8.99623","0.01600"
"108.10800","9.00921","0.01620"
"108.26400","9.02218","0.01519"
"108.42000","9.03527","0.01604"
"108.57600","9.04825","0.01554"
"108.73200","9.06122","0.01564"
"108.88800","9.07420","0.01572"
"109.04400","9.08723","0.01624"
"109.20000","9.10021","0.01593"
"109.35600","9.11318","0.01588"
"109.51200","9.12627","0.01586"
"109.66800","9.13925","0.01583"
"109.82400","9.15216","0.01567"
"109.98000","9.16526","0.01610"
"110.13600","9.17823","0.01580"
"110.29200","9.19121","0.01621"
"110.44800","9.20418","0.01615"
"110.60400","9.21727","0.01620"
"110.76000","9.23019","0.01602"
"110.91600","9.24316","0.01604"
"111.07200","9.25620","0.01585"
"111.22800","9.26929","0.01596"
"111.38400","9.28221","0.01635"
"111.54000","9.29524","0.01633"
"111.69600","9.30821","0.01610"
"111.85200","9.32125","0.01666"
"112.00800","9.33416","0.01631"
"112.16400","9.34720","0.01669"
"112.32000","9.36029","0.01639"
"112.47600","9.37321","0.01609"
"112.63200","9.38618","0.01648"
"112.78800","9.39921","0.01709"
"112.94400","9.41225","0.01639"
"113.10000","9.42516","0.01592"
"113.25600","9.43826","0.01620"
"113.41200","9.45129","0.01586"
"113.56800","9.46420","0.01612"
"113.72400","9.47724","0.01610"
"113.88000","9.49021","0.01683"
"114.03600","9.50319","0.01635"
"114.19200","9.51616","0.01660"
"114.34800","9.52926","0.01605"
"114.50400","9.54223","0.01612"
"114.66000","9.55520","0.01702"
"114.81600","9.56824","0.01673"
"114.97200","9.58127","0.01617"
"115.12800","9.59425","0.01656"
"115.28400","9.60722","0.01646"
"115.44000","9.62020","0.01691"
"115.59600","9.63323","0.01594"
"115.75200","9.64620","0.01652"
"115.90800","9.65930","0.01586"
"116.06400","9.67227","0.01627"
"116.22000","9.68519","0.01669"
"116.37600","9.69822","0.01636"
"116.53200","9.71126","0.01627"
"116.68800","9.72429","0.01635"
"116.84400","9.73720","0.01640"
"117.00000","9.75024","0.01625"
"117.15600","9.76321","0.01676"
"117.31200","9.77619","0.01669"
"117.46800","9.78922","0.01641"
"117.62400","9.80219","0.01656"
"117.78000","9.81517","0.01678"
"117.93600","9.82814","0.01711"
"118.09200","9.84124","0.01654"
"118.24800","9.85427","0.01653"
"118.40400","9.86719","0.01691"
"118.56000","9.88022","0.01724"
"118.71600","9.89325","0.01646"
"118.87200","9.90629","0.01704"
"119.02800","9.91914","0.01658"
"119.18400","9.93224","0.01761"
"119.34000","9.94527","0.01687"
"119.49600","9.95825","0.01662"
"119.65200","9.97122","0.01714"
"119.80800","9.98425","0.01733"
"119.96400","9.99717","0.01703"
"120.12000","10.01014","0.01687"
"120.27600","10.02324","0.01747"
"120.43200","10.03627","0.01685"
"120.58800","10.04919","0.01704"
"120.74400","10.06222","0.01708"
"120.90000","10.07525","0.01646"
"121.05600","10.08823","0.01684"
"121.21200","10.10120","0.01672"
"121.36800","10.11418","0.01672"
"121.52400","10.12721","0.01764"
"121.68000","10.14012","0.01679"
"121.83600","10.15322","0.01591"
"121.99200","10.16625","0.01645"
"122.14800","10.17923","0.01585"
"122.30400","10.19220","0.01656"
"122.46000","10.20524","0.01624"
"122.61600","10.21821","0.01649"
"122.77200","10.23118","0.01658"
"122.92800","10.24422","0.01677"
"123.08400","10.25725","0.01646"
"123.24000","10.27023","0.01696"
"123.39600","10.28320","0.01637"
"123.55200","10.29624","0.01676"
"123.70800","10.30921","0.01631"
"123.86400","10.32218","0.01696"
"124.02000","10.33528","0.01644"
"124.17600","10.34825","0.01656"
"124.33200","10.36123","0.01634"
"124.48800","10.37420","0.01607"
"124.64400","10.38724","0.01652"
"124.80000","10.40021","0.01657"
"124.95600","10.41318","0.01665"
"125.11200","10.42622","0.01633"
"125.26800","10.43925","0.01664"
"125.42400","10.45217","0.01657"
"125.58000","10.46526","0.01600"
"125.73600","10.47824","0.01605"
"125.89200","10.49127","0.01713"
"126.04800","10.50418","0.01584"
"126.20400","10.51722","0.01666"
"126.36000","10.53025","0.01637"
"126.51600","10.54311","0.01603"
"126.67200","10.55620","0.01597"
"126.82800","10.56923","0.01696"
"126.98400","10.58215","0.01643"
"127.14000","10.59518","0.01641"
"127.29600","10.60822","0.01572"
"127.45200","10.62125","0.01638"
"127.60800","10.63417","0.01588"
"127.76400","10.64726","0.01628"
"127.92000","10.66023","0.01588"
"128.07600","10.67321","0.01600"
"128.23200","10.68618","0.01674"
"128.38800","10.69922","0.01614"
"128.54400","10.71219","0.01563"
"128.70000","10.72517","0.01665"
"128.85600","10.73820","0.01625"
"129.01200","10.75123","0.01557"
"129.16800","10.76421","0.01539"
"129.32400","10.77724","0.01468"
"129.48000","10.79028","0.01531"
"129.63600","10.80325","0.01579"
"129.79200","10.81617","0.01549"
"129.94800","10.82920","0.01529"
"130.10400","10.84223","0.01523"
"130.26000","10.85521","0.01573"
"130.41600","10.86818","0.01496"
"130.57200","10.88122","0.01527"
"130.72800","10.89425","0.01580"
"130.88400","10.90723","0.01594"
"131.04000","10.92026","0.01522"
"131.19600","10.93323","0.01570"
"131.35200","10.94621","0.01589"
"131.50800","10.95924","0.01556"
"131.66400","10.97222","0.01546"
"131.82000","10.98519","0.01602"
"131.97600","10.99817","0.01525"
"132.13200","11.01120","0.01544"
"132.28800","11.02423","0.01623"
"132.44400","11.03721","0.01561"
"132.60000","11.05024","0.01610"
"132.75600","11.06322","0.01581"
"132.91200","11.07613","0.01543"
"133.06800","11.08916","0.01581"
"133.22400","11.10220","0.01613"
"133.38000","11.11517","0.01543"
"133.53600","11.12815","0.01541"
"133.69200","11.14118","0.01563"
"133.84800","11.15422","0.01530"
"134.00400","11.16713","0.01586"
"134.16000","11.18022","0.01572"
"134.31600","11.19320","0.01575"
"134.47200","11.20623","0.01573"
"134.62800","11.21921","0.01579"
"134.78400","11.23230","0.01611"
"134.94000","11.24522","0.01556"
"135.09600","11.25819","0.01615"
"135.25200","11.27122","0.01579"
"135.40800","11.28420","0.01575"
"135.56400","11.29723","0.01592"
"135.72000","11.31015","0.01589"
"135.87600","11.32324","0.01562"
"136.03200","11.33622","0.01590"
"136.18800","11.34919","0.01576"
"136.34400","11.36222","0.01606"
"136.50000","11.37526","0.01562"
"136.65600","11.38823","0.01541"
"136.81200","11.40121","0.01543"
"136.96800","11.41424","0.01580"
"137.12400","11.42722","0.01624"
"137.28000","11.44013","0.01609"
"137.43600","11.45316","0.01642"
"137.59200","11.46626","0.01593"
"137.74800","11.47917","0.01585"
"137.90400","11.49221","0.01660"
"138.06000","11.50530","0.01608"
"138.21600","11.51827","0.01567"
"138.37200","11.53125","0.01614"
"138.52800","11.54422","0.01610"
"138.68400","11.55726","0.01571"
"138.84000","11.57017","0.01608"
"138.99600","11.58321","0.01630"
"139.15200","11.59618","0.01596"
"139.30800","11.60921","0.01665"
"139.46400","11.62213","0.01636"
"139.62000","11.63522","0.01622"
"139.77600","11.64820","0.01617"
"139.93200","11.66123","0.01620"
"140.08800","11.67420","0.01646"
"140.24400","11.68724","0.01629"
"140.40000","11.70021","0.01661"
"140.55600","11.71319","0.01592"
"140.71200","11.72628","0.01637"
"140.86800","11.73926","0.01641"
"141.02400","11.75223","0.01621"
"141.18000","11.76520","0.01661"
"141.33600","11.77818","0.01673"
"141.49200","11.79121","0.01657"
"141.64800","11.80419","0.01696"
"141.80400","11.81728","0.01650"
"141.96000","11.83026","0.01666"
"142.11600","11.84317","0.01624"
"142.27200","11.85620","0.01616"
"142.42800","11.86924","0.01633"
"142.58400","11.88221","0.01665"
"142.74000","11.89519","0.01707"
"142.89600","11.90822","0.01686"
"143.05200","11.92126","0.01663"
"143.20800","11.93417","0.01682"
"143.36400","11.94726","0.01641"
"143.52000","11.96024","0.01718"
"143.67600","11.97321","0.01606"
"143.83200","11.98625","0.01681"
"143.98800","11.99928","0.01632"
"144.14400","12.01225","0.01689"
"144.30000","12.02517","0.01704"
"144.45600","12.03826","0.01624"
"144.61200","12.05124","0.01675"
"144.76800","12.06421","0.01631"
"144.92400","12.07719","0.01748"
"145.08000","12.09022","0.01691"
"145.23600","12.10326","0.01700"
"145.39200","12.11617","0.01722"
"145.54800","12.12920","0.01719"
"145.70400","12.14224","0.01648"
"145.86000","12.15515","0.01669"
"146.01600","12.16813","0.01680"
"146.17200","12.18122","0.01690"
"146.32800","12.19420","0.01732"
"146.48400","12.20717","0.01692"
"146.64000","12.22020","0.01689"
"146.79600","12.23324","0.01716"
"146.95200","12.24621","0.01718"
"147.10800","12.25925","0.01729"
"147.26400","12.27228","0.01695"
"147.42000","12.28525","0.01755"
"147.57600","12.29823","0.01756"
"147.73200","12.31120","0.01714"
"147.88800","12.32424","0.01770"
"148.04400","12.33721","0.01734"
"148.20000","12.35025","0.01768"
"148.35600","12.36322","0.01754"
"148.51200","12.37625","0.01710"
"148.66800","12.38917","0.01703"
"148.82400","12.40226","0.01717"
"148.98000","12.41530","0.01701"
"149.13600","12.42821","0.01760"
"149.29200","12.44125","0.01705"
"149.44800","12.45428","0.01703"
"149.60400","12.46719","0.01706"
"149.76000","12.48017","0.01728"
"149.91600","12.49320","0.01794"
"150.07200","12.50618","0.01692"
"150.22800","12.51915","0.01767"
"150.38400","12.53224","0.01679"
"150.54000","12.54522","0.01709"
"150.69600","12.55819","0.01727"
"150.85200","12.57123","0.01752"
"151.00800","12.58420","0.01766"
"151.16400","12.59724","0.01774"
"151.32000","12.61015","0.01760"
"151.47600","12.62324","0.01752"
"151.63200","12.63622","0.01737"
"151.78800","12.64919","0.01737"
"151.94400","12.66223","0.01754"
"152.10000","12.67520","0.01736"
"152.25600","12.68818","0.01787"
"152.41200","12.70115","0.01754"
"152.56800","12.71424","0.01747"
"152.72400","12.72728","0.01731"
"152.88000","12.74019","0.01760"
"153.03600","12.75323","0.01769"
"153.19200","12.76626","0.01725"
"153.34800","12.77924","0.01762"
"153.50400","12.79215","0.01739"
"153.66000","12.80524","0.01814"
"153.81600","12.81822","0.01772"
"153.97200","12.83119","0.01748"
"154.12800","12.84423","0.01736"
"154.28400","12.85726","0.01799"
"154.44000","12.87017","0.01769"
"154.59600","12.88321","0.01767"
"154.75200","12.89624","0.01780"
"154.90800","12.90922","0.01767"
"155.06400","12.92219","0.01744"
"155.22000","12.93523","0.01733"
"155.37600","12.94826","0.01796"
"155.53200","12.96124","0.01753"
"155.68800","12.97421","0.01715"
"155.84400","12.98724","0.01787"
"156.00000","13.00022","0.01799"
"156.15600","13.01313","0.01743"
"156.31200","13.02623","0.01744"
"156.46800","13.03926","0.01779"
"156.62400","13.05217","0.01802"
"156.78000","13.06521","0.01792"
"156.93600","13.07824","0.01812"
"157.09200","13.09122","0.01817"
"157.24800","13.10419","0.01793"
"157.40400","13.11723","0.01821"
"157.56000","13.13020","0.01786"
"157.71600","13.14317","0.01757"
"157.87200","13.15621","0.01757"
"158.02800","13.16930","0.01833"
"158.18400","13.18222","0.01770"
"158.34000","13.19519","0.01813"
"158.49600","13.20823","0.01769"
"158.65200","13.22120","0.01778"
"158.80800","13.23417","0.01831"
"158.96400","13.24721","0.01796"
"159.12000","13.26024","0.01828"
"159.27600","13.27316","0.01769"
"159.43200","13.28619","0.01761"
"159.58800","13.29923","0.01795"
"159.74400","13.31226","0.01846"
"159.90000","13.32517","0.01846"
"160.05600","13.33821","0.01819"
"160.21200","13.35124","0.01852"
"160.36800","13.36416","0.01876"
"160.52400","13.37725","0.01882"
"160.68000","13.39023","0.01900"
"160.83600","13.40320","0.01859"
"160.99200","13.41617","0.01829"
"161.14800","13.42927","0.01826"
"161.30400","13.44224","0.01876"
"161.46000","13.45516","0.01844"
"161.61600","13.46825","0.01866"
"161.77200","13.48123","0.01853"
"161.92800","13.49426","0.01861"
"162.08400","13.50717","0.01885"
"162.24000","13.52027","0.01889"
"162.39600","13.53318","0.01912"
"162.55200","13.54616","0.01818"
"162.70800","13.55913","0.01841"
"162.86400","13.57222","0.01823"
"163.02000","13.58520","0.01878"
"163.17600","13.59817","0.01894"
"163.33200","13.61127","0.01877"
"163.48800","13.62424","0.01882"
"163.64400","13.63716","0.01876"
"163.80000","13.65019","0.01885"
"163.95600","13.66322","0.01858"
"164.11200","13.67620","0.01896"
"164.26800","13.68917","0.01871"
"164.42400","13.70221","0.01855"
"164.58000","13.71518","0.01893"
"164.73600","13.72816","0.01870"
"164.89200","13.74119","0.01864"
"165.04800","13.75422","0.01896"
"165.20400","13.76714","0.01851"
"165.36000","13.78017","0.01947"
"165.51600","13.79321","0.01858"
"165.67200","13.80618","0.01881"
"165.82800","13.81916","0.01987"
"165.98400","13.83219","0.01919"
"166.14000","13.84522","0.01972"
"166.29600","13.85820","0.01917"
"166.45200","13.87117","0.01937"
"166.60800","13.88426","0.01940"
"166.76400","13.89724","0.01954"
"166.92000","13.91022","0.01879"
"167.07600","13.92325","0.01934"
"167.23200","13.93622","0.01891"
"167.38800","13.94920","0.01928"
"167.54400","13.96223","0.01910"
"167.70000","13.97527","0.01913"
"167.85600","13.98818","0.01936"
"168.01200","14.00121","0.01982"
"168.16800","14.01425","0.01965"
"168.32400","14.02722","0.01903"
"168.48000","14.04020","0.01880"
"168.63600","14.05323","0.01913"
"168.79200","14.06621","0.01927"
"168.94800","14.07918","0.01975"
"169.10400","14.09221","0.01908"
"169.26000","14.10525","0.01943"
"169.41600","14.11822","0.01943"
"169.57200","14.13120","0.01921"
"169.72800","14.14423","0.01930"
"169.88400","14.15721","0.01903"
"170.04000","14.17018","0.01961"
"170.19600","14.18321","0.01963"
"170.35200","14.19625","0.01970"
"170.50800","14.20928","0.01971"
"170.66400","14.22220","0.01990"
"170.82000","14.23529","0.01951"
"170.97600","14.24827","0.01986"
"171.13200","14.26118","0.01931"
"171.28800","14.27415","0.01925"
"171.44400","14.28719","0.02013"
"171.60000","14.30016","0.01980"
"171.75600","14.31314","0.01975"
"171.91200","14.32623","0.01982"
"172.06800","14.33926","0.01900"
"172.22400","14.35218","0.01942"
"172.38000","14.36521","0.01935"
"172.53600","14.37825","0.01861"
"172.69200","14.39122","0.01980"
"172.84800","14.40420","0.01959"
"173.00400","14.41729","0.01935"
"173.16000","14.43026","0.01918"
"173.31600","14.44318","0.01930"
"173.47200","14.45615","0.01896"
"173.62800","14.46925","0.01938"
"173.78400","14.48222","0.01921"
"173.94000","14.49520","0.01977"
"174.09600","14.50829","0.01928"
"174.25200","14.52126","0.01962"
"174.40800","14.53418","0.02010"
"174.56400","14.54721","0.01986"
"174.72000","14.56025","0.01913"
"174.87600","14.57322","0.01960"
"175.03200","14.58619","0.01953"
"175.18800","14.59923","0.01935"
"175.34400","14.61220","0.01925"
"175.50000","14.62518","0.01939"
"175.65600","14.63827","0.01982"
"175.81200","14.65125","0.01990"
"175.96800","14.66422","0.01945"
"176.12400","14.67719","0.01994"
"176.28000","14.69023","0.01950"
"176.43600","14.70320","0.01984"
"176.59200","14.71618","0.02001"
"176.74800","14.72927","0.01929"
"176.90400","14.74224","0.02010"
"177.06000","14.75516","0.02009"
"177.21600","14.76820","0.01977"
"177.37200","14.78123","0.02017"
"177.52800","14.79426","0.01982"
"177.68400","14.80724","0.02001"
"177.84000","14.82027","0.01955"
"177.99600","14.83319","0.01944"
"178.15200","14.84616","0.01986"
"178.30800","14.85919","0.02031"
"178.46400","14.87217","0.01975"
"178.62000","14.88520","0.02016"
"178.77600","14.89812","0.02093"
"178.93200","14.91127","0.02017"
"179.08800","14.92424","0.02008"
"179.24400","14.93716","0.02027"
"179.40000","14.95025","0.02063"
"179.55600","14.96329","0.02032"
"179.71200","14.97620","0.01977"
"179.86800","14.98924","0.01988"
"180.02400","15.00227","0.02037"
"180.18000","15.01524","0.02032"
"180.33600","15.02822","0.02007"
"180.49200","15.04125","0.02026"
"180.64800","15.05429","0.02016"
"180.80400","15.06720","0.02061"
"180.96000","15.08024","0.01974"
"181.11600","15.09327","0.02073"
"181.27200","15.10624","0.01958"
"181.42800","15.11922","0.02010"
"181.58400","15.13219","0.01987"
"181.74000","15.14523","0.02020"
"181.89600","15.15820","0.02018"
"182.05200","15.17118","0.02056"
"182.20800","15.18421","0.02044"
"182.36400","15.19718","0.02034"
"182.52000","15.21016","0.02039"
"182.67600","15.22325","0.02049"
"182.83200","15.23623","0.01942"
"182.98800","15.24920","0.02048"
"183.14400","15.26218","0.02056"
"183.30000","15.27527","0.01971"
"183.45600","15.28818","0.02063"
"183.61200","15.30116","0.02074"
"183.76800","15.31425","0.02089"
"183.92400","15.32723","0.02079"
"184.08000","15.34020","0.02081"
"184.23600","15.35323","0.02071"
"184.39200","15.36621","0.02058"
"184.54800","15.37924","0.02036"
"184.70400","15.39222","0.02088"
"184.86000","15.40525","0.02056"
"185.01600","15.41823","0.02082"
"185.17200","15.43120","0.02051"
"185.32800","15.44423","0.02025"
"185.48400","15.45727","0.01988"
"185.64000","15.47024","0.02054"
"185.79600","15.48322","0.02025"
"185.95200","15.49619","0.02004"
"186.10800","15.50923","0.01950"
"186.26400","15.52214","0.02026"
"186.42000","15.53523","0.02079"
"186.57600","15.54827","0.02038"
"186.73200","15.56124","0.01992"
"186.88800","15.57422","0.02062"
"187.04400","15.58725","0.02063"
"187.20000","15.60023","0.02041"
"187.35600","15.61314","0.02082"
"187.51200","15.62623","0.02083"
"187.66800","15.63921","0.02029"
"187.82400","15.65218","0.02053"
"187.98000","15.66516","0.02092"
"188.13600","15.67825","0.02073"
"188.29200","15.69122","0.02025"
"188.44800","15.70420","0.02055"
"188.60400","15.71729","0.02028"
"188.76000","15.73027","0.02086"
"188.91600","15.74318","0.02016"
"189.07200","15.75616","0.02125"
"189.22800","15.76925","0.02037"
"189.38400","15.78216","0.02141"
"189.54000","15.79514","0.02077"
"189.69600","15.80823","0.02142"
"189.85200","15.82121","0.02059"
"190.00800","15.83418","0.02090"
"190.16400","15.84722","0.02103"
"190.32000","15.86025","0.02105"
"190.47600","15.87322","0.02064"
"190.63200","15.88620","0.02068"
"190.78800","15.89917","0.02072"
"190.94400","15.91221","0.02096"
"191.10000","15.92512","0.02041"
"191.25600","15.93822","0.01897"
"191.41200","15.95119","0.01941"
"191.56800","15.96422","0.02031"
"191.72400","15.97720","0.01927"
"191.88000","15.99023","0.01957"
"192.03600","16.00321","0.01930"
"192.19200","16.01618","0.01974"
"192.34800","16.02921","0.01996"
"192.50400","16.04225","0.01929"
"192.66000","16.05522","0.01960"
"192.81600","16.06820","0.01976"
"192.97200","16.08123","0.01977"
"193.12800","16.09421","0.01959"
"193.28400","16.10718","0.02008"
"193.44000","16.12021","0.02010"
"193.59600","16.13325","0.01971"
"193.75200","16.14622","0.01985"
"193.90800","16.15920","0.02021"
"194.06400","16.17223","0.02016"
"194.22000","16.18521","0.02020"
"194.37600","16.19818","0.02023"
"194.53200","16.21121","0.01973"
"194.68800","16.22425","0.02029"
"194.84400","16.23716","0.02022"
"195.00000","16.25020","0.02018"
"195.15600","16.26323","0.02112"
"195.31200","16.27621","0.02028"
"195.46800","16.28924","0.02007"
"195.62400","16.30227","0.01996"
"195.78000","16.31525","0.02032"
"195.93600","16.32816","0.02043"
"196.09200","16.34120","0.01976"
"196.24800","16.35417","0.01973"
"196.40400","16.36720","0.01995"
"196.56000","16.38012","0.02075"
"196.71600","16.39321","0.02030"
"196.87200","16.40619","0.02038"
"197.02800","16.41916","0.02000"
"197.18400","16.43220","0.01973"
"197.34000","16.44523","0.02040"
"197.49600","16.45815","0.02047"
"197.65200","16.47118","0.02022"
"197.80800","16.48421","0.02015"
"197.96400","16.49719","0.02039"
"198.12000","16.51016","0.02041"
"198.27600","16.52320","0.02047"
"198.43200","16.53623","0.02059"
"198.58800","16.54920","0.02067"
"198.74400","16.56218","0.02091"
"198.90000","16.57527","0.02087"
"199.05600","16.58825","0.02059"
"199.21200","16.60122","0.02155"
"199.36800","16.61425","0.02070"
"199.52400","16.62723","0.02068"
"199.68000","16.64021","0.02040"
"199.83600","16.65324","0.02079"
"199.99200","16.66621","0.02075"
"200.14800","16.67919","0.02115"
"200.30400","16.69216","0.02088"
"200.46000","16.70526","0.02060"
"200.61600","16.71823","0.02075"
"200.77200","16.73120","0.02073"
"200.92800","16.74424","0.02090"
"201.08400","16.75727","0.02076"
"201.24000","16.77019","0.02083"
"201.39600","16.78322","0.02092"
"201.55200","16.79626","0.02105"
"201.70800","16.80923","0.02107"
"201.86400","16.82214","0.02142"
"202.02000","16.83524","0.02082"
"202.17600","16.84821","0.02110"
"202.33200","16.86119","0.02090"
"202.48800","16.87422","0.02112"
"202.64400","16.88725","0.02169"
"202.80000","16.90029","0.02088"
"202.95600","16.91320","0.02150"
"203.11200","16.92624","0.02121"
"203.26800","16.93927","0.02083"
"203.42400","16.95219","0.02141"
"203.58000","16.96522","0.02138"
"203.73600","16.97820","0.02158"
"203.89200","16.99117","0.02166"
"204.04800","17.00414","0.02121"
"204.20400","17.01730","0.02135"
"204.36000","17.03027","0.02141"
"204.51600","17.04319","0.02132"
"204.67200","17.05622","0.02136"
"204.82800","17.06919","0.02166"
"204.98400","17.08223","0.02151"
"205.14000","17.09520","0.02175"
"205.29600","17.10830","0.02127"
"205.45200","17.12127","0.02136"
"205.60800","17.13419","0.02157"
"205.76400","17.14722","0.02201"
"205.92000","17.16025","0.02098"
"206.07600","17.17323","0.02110"
"206.23200","17.18620","0.02134"
"206.38800","17.19924","0.02081"
"206.54400","17.21227","0.02124"
"206.70000","17.22513","0.02085"
"206.85600","17.23822","0.02110"
"207.01200","17.25125","0.02116"
"207.16800","17.26417","0.02134"
"207.32400","17.27720","0.02162"
"207.48000","17.29024","0.02100"
"207.63600","17.30321","0.02179"
"207.79200","17.31618","0.02074"
"207.94800","17.32922","0.02156"
"208.10400","17.34225","0.02123"
"208.26000","17.35517","0.02183"
"208.41600","17.36820","0.02147"
"208.57200","17.38118","0.02164"
"208.72800","17.39421","0.02147"
"208.88400","17.40718","0.02152"
"209.04000","17.42022","0.02120"
"209.19600","17.43319","0.02152"
"209.35200","17.44617","0.02183"
"209.50800","17.45920","0.02133"
"209.66400","17.47223","0.02131"
"209.82000","17.48527","0.02086"
"209.97600","17.49824","0.02204"
"210.13200","17.51128","0.02147"
"210.28800","17.52419","0.02229"
"210.44400","17.53723","0.02198"
"210.60000","17.55020","0.02142"
"210.75600","17.56323","0.02102"
"210.91200","17.57621","0.02151"
"211.06800","17.58918","0.02132"
"211.22400","17.60222","0.02053"
"211.38000","17.61525","0.02172"
"211.53600","17.62823","0.02199"
"211.69200","17.64126","0.02108"
"211.84800","17.65423","0.02154"
"212.00400","17.66721","0.02180"
"212.16000","17.68018","0.02161"
"212.31600","17.69322","0.02147"
"212.47200","17.70625","0.02122"
"212.62800","17.71917","0.02167"
"212.78400","17.73226","0.02106"
"212.94000","17.74529","0.02256"
"213.09600","17.75821","0.02205"
"213.25200","17.77118","0.02185"
"213.40800","17.78428","0.02202"
"213.56400","17.79725","0.02216"
"213.72000","17.81017","0.02212"
"213.87600","17.82326","0.02248"
"214.03200","17.83623","0.02184"
"214.18800","17.84921","0.02162"
"214.34400","17.86218","0.02166"
"214.50000","17.87522","0.02158"
"214.65600","17.88819","0.02192"
"214.81200","17.90117","0.02197"
"214.96800","17.91426","0.02198"
"215.12400","17.92729","0.02205"
"215.28000","17.94021","0.02218"
"215.43600","17.95324","0.02183"
"215.59200","17.96622","0.02217"
"215.74800","17.97919","0.02215"
"215.90400","17.99216","0.02237"
"216.06000","18.00520","0.02232"
"216.21600","18.01823","0.02203"
"216.37200","18.03115","0.02246"
"216.52800","18.04418","0.02217"
"216.68400","18.05722","0.02261"
"216.84000","18.07019","0.02207"
"216.99600","18.08322","0.02308"
"217.15200","18.09626","0.02250"
"217.30800","18.10923","0.02279"
"217.46400","18.12215","0.02255"
"217.62000","18.13524","0.02260"
"217.77600","18.14822","0.02248"
"217.93200","18.16125","0.02282"
"218.08800","18.17422","0.02231"
"218.24400","18.18726","0.02272"
"218.40000","18.20023","0.02364"
"218.55600","18.21321","0.02250"
"218.71200","18.22624","0.02263"
"218.86800","18.23927","0.02268"
"219.02400","18.25225","0.02274"
"219.18000","18.26522","0.02275"
"219.33600","18.27826","0.02269"
"219.49200","18.29117","0.02288"
"219.64800","18.30415","0.02263"
"219.80400","18.31718","0.02288"
"219.96000","18.33022","0.02263"
"220.11600","18.34313","0.02310"
"220.27200","18.35622","0.02335"
"220.42800","18.36926","0.02295"
"220.58400","18.38223","0.02292"
"220.74000","18.39521","0.02328"
"220.89600","18.40830","0.02372"
"221.05200","18.42121","0.02338"
"221.20800","18.43413","0.02334"
"221.36400","18.44722","0.02287"
"221.52000","18.46020","0.02271"
"221.67600","18.47317","0.02344"
"221.83200","18.48615","0.02359"
"221.98800","18.49924","0.02393"
"222.14400","18.51221","0.02325"
"222.30000","18.52513","0.02301"
"222.45600","18.53828","0.02338"
"222.61200","18.55126","0.02343"
"222.76800","18.56423","0.02342"
"222.92400","18.57721","0.02298"
"223.08000","18.59024","0.02337"
"223.23600","18.60321","0.02353"
"223.39200","18.61613","0.02306"
"223.54800","18.62922","0.02354"
"223.70400","18.64226","0.02373"
"223.86000","18.65517","0.02354"
"224.01600","18.66821","0.02348"
"224.17200","18.68124","0.02369"
"224.32800","18.69421","0.02407"
"224.48400","18.70719","0.02345"
"224.64000","18.72022","0.02364"
"224.79600","18.73326","0.02331"
"224.95200","18.74617","0.02357"
"225.10800","18.75921","0.02375"
"225.26400","18.77224","0.02335"
"225.42000","18.78521","0.02373"
"225.57600","18.79813","0.02402"
"225.73200","18.81122","0.02378"
"225.88800","18.82420","0.02362"
"226.04400","18.83723","0.02337"
"226.20000","18.85021","0.02406"
"226.35600","18.86324","0.02372"
"226.51200","18.87615","0.02396"
"226.66800","18.88913","0.02403"
"226.82400","18.90222","0.02399"
"226.98000","18.91520","0.02389"
"227.13600","18.92817","0.02393"
"227.29200","18.94120","0.02460"
"227.44800","18.95418","0.02386"
"227.60400","18.96721","0.02428"
"227.76000","18.98019","0.02395"
"227.91600","18.99322","0.02465"
"228.07200","19.00620","0.02409"
"228.22800","19.01917","0.02439"
"228.38400","19.03220","0.02439"
"228.54000","19.04524","0.02433"
"228.69600","19.05815","0.02434"
"228.85200","19.07119","0.02376"
"229.00800","19.08422","0.02463"
"229.16400","19.09726","0.02428"
"229.32000","19.11017","0.02420"
"229.47600","19.12326","0.02458"
"229.63200","19.13624","0.02471"
"229.78800","19.14921","0.02424"
"229.94400","19.16219","0.02436"
"230.10000","19.17522","0.02334"
"230.25600","19.18820","0.02452"
"230.41200","19.20117","0.02391"
"230.56800","19.21420","0.02366"
"230.72400","19.22724","0.02383"
"230.88000","19.24015","0.02402"
"231.03400","19.25307","0.02367"