File: Force_trajectories/170122_2/Specimen_RawData_2.csv
End date,"1/22/2017"
Specimen label,"3CT_17_run2"
Maximum Load,"0.29793",N

Time,Extension,Load
(s),(mm),(N)
"0.00000","10.69796","0.03585"
"0.09600","10.70125","0.03665"
"0.19200","10.71064","0.03726"
"0.28800","10.72104","0.03734"
"0.38400","10.73007","0.03673"
"0.48000","10.73826","0.03698"
"0.57600","10.74615","0.03650"
"0.67200","10.75416","0.03732"
"0.76800","10.76206","0.03825"
"0.86400","10.77007","0.03849"
"0.96000","10.77814","0.03835"
"1.05600","10.78615","0.03841"
"1.15200","10.79410","0.03773"
"1.24800","10.80206","0.03811"
"1.34400","10.81007","0.03874"
"1.44000","10.81802","0.03919"
"1.53600","10.82609","0.03921"
"1.63200","10.83410","0.03881"
"1.72800","10.84206","0.03866"
"1.82400","10.85007","0.03908"
"1.92000","10.85802","0.03917"
"2.01600","10.86609","0.03987"
"2.11200","10.87410","0.04027"
"2.20800","10.88211","0.03976"
"2.30400","10.89007","0.03931"
"2.40000","10.89802","0.03954"
"2.49600","10.90609","0.03975"
"2.59200","10.91404","0.04076"
"2.68800","10.92211","0.04121"
"2.78400","10.93012","0.04070"
"2.88000","10.93808","0.04025"
"2.97600","10.94609","0.04027"
"3.07200","10.95410","0.04054"
"3.16800","10.96211","0.04141"
"3.26400","10.97012","0.04173"
"3.36000","10.97814","0.04159"
"3.45600","10.98609","0.04101"
"3.55200","10.99404","0.04100"
"3.64800","11.00211","0.04168"
"3.74400","11.01006","0.04230"
"3.84000","11.01813","0.04308"
"3.93600","11.02615","0.04282"
"4.03200","11.03410","0.04177"
"4.12800","11.04211","0.04235"
"4.22400","11.05012","0.04287"
"4.32000","11.05807","0.04393"
"4.41600","11.06609","0.04448"
"4.51200","11.07410","0.04397"
"4.60800","11.08199","0.04327"
"4.70400","11.09006","0.04339"
"4.80000","11.09813","0.04423"
"4.89600","11.10608","0.04488"
"4.99200","11.11410","0.04562"
"5.08800","11.12211","0.04506"
"5.18400","11.13006","0.04486"
"5.28000","11.13813","0.04507"
"5.37600","11.14608","0.04591"
"5.47200","11.15410","0.04683"
"5.56800","11.16211","0.04723"
"5.66400","11.17006","0.04710"
"5.76000","11.17807","0.04703"
"5.85600","11.18614","0.04694"
"5.95200","11.19410","0.04844"
"6.04800","11.20211","0.04910"
"6.14400","11.21006","0.04954"
"6.24000","11.21807","0.04897"
"6.33600","11.22608","0.04905"
"6.43200","11.23409","0.04918"
"6.52800","11.24211","0.05062"
"6.62400","11.25006","0.05139"
"6.72000","11.25807","0.05169"
"6.81600","11.26608","0.05116"
"6.91200","11.27409","0.05103"
"7.00800","11.28205","0.05195"
"7.10400","11.29012","0.05300"
"7.20000","11.29807","0.05367"
"7.29600","11.30602","0.05397"
"7.39200","11.31409","0.05355"
"7.48800","11.32211","0.05336"
"7.58400","11.33012","0.05483"
"7.68000","11.33813","0.05559"
"7.77600","11.34602","0.05625"
"7.87200","11.35403","0.05617"
"7.96800","11.36216","0.05603"
"8.06400","11.37012","0.05658"
"8.16000","11.37813","0.05734"
"8.25600","11.38614","0.05804"
"8.35200","11.39403","0.05894"
"8.44800","11.40210","0.05836"
"8.54400","11.41017","0.05813"
"8.64000","11.41813","0.05891"
"8.73600","11.42608","0.06034"
"8.83200","11.43409","0.06150"
"8.92800","11.44204","0.06130"
"9.02400","11.45011","0.06105"
"9.12000","11.45813","0.06129"
"9.21600","11.46614","0.06232"
"9.31200","11.47415","0.06300"
"9.40800","11.48210","0.06346"
"9.50400","11.49005","0.06352"
"9.60000","11.49813","0.06294"
"9.69600","11.50614","0.06421"
"9.79200","11.51409","0.06518"
"9.88800","11.52210","0.06556"
"9.98400","11.53005","0.06565"
"10.08000","11.53812","0.06567"
"10.17600","11.54614","0.06600"
"10.27200","11.55415","0.06655"
"10.36800","11.56210","0.06683"
"10.46400","11.57005","0.06789"
"10.56000","11.57812","0.06791"
"10.65600","11.58608","0.06820"
"10.75200","11.59409","0.06813"
"10.84800","11.60210","0.06920"
"10.94400","11.61005","0.06963"
"11.04000","11.61806","0.06994"
"11.13600","11.62602","0.06981"
"11.23200","11.63409","0.06998"
"11.32800","11.64210","0.07078"
"11.42400","11.65011","0.07142"
"11.52000","11.65806","0.07206"
"11.61600","11.66601","0.07192"
"11.71200","11.67415","0.07186"
"11.80800","11.68210","0.07225"
"11.90400","11.69011","0.07270"
"12.00000","11.69812","0.07357"
"12.09600","11.70607","0.07410"
"12.19200","11.71408","0.07445"
"12.28800","11.72210","0.07375"
"12.38400","11.73011","0.07542"
"12.48000","11.73812","0.07611"
"12.57600","11.74607","0.07649"
"12.67200","11.75408","0.07626"
"12.76800","11.76204","0.07693"
"12.86400","11.77005","0.07808"
"12.96000","11.77806","0.07760"
"13.05600","11.78607","0.07868"
"13.15200","11.79402","0.07971"
"13.24800","11.80204","0.07961"
"13.34400","11.81011","0.08025"
"13.44000","11.81812","0.08025"
"13.53600","11.82613","0.08127"
"13.63200","11.83414","0.08178"
"13.72800","11.84209","0.08221"
"13.82400","11.85011","0.08261"
"13.92000","11.85812","0.08302"
"14.01600","11.86613","0.08412"
"14.11200","11.87414","0.08436"
"14.20800","11.88209","0.08501"
"14.30400","11.89011","0.08506"
"14.40000","11.89812","0.08510"
"14.49600","11.90607","0.08599"
"14.59200","11.91414","0.08637"
"14.68800","11.92209","0.08702"
"14.78400","11.93005","0.08688"
"14.88000","11.93806","0.08710"
"14.97600","11.94613","0.08767"
"15.07200","11.95408","0.08836"
"15.16800","11.96209","0.08829"
"15.26400","11.97010","0.08830"
"15.36000","11.97800","0.08850"
"15.45600","11.98613","0.08877"
"15.55200","11.99414","0.08891"
"15.64800","12.00209","0.08949"
"15.74400","12.01010","0.08947"
"15.84000","12.01806","0.08959"
"15.93600","12.02607","0.08989"
"16.03200","12.03408","0.09010"
"16.12800","12.04215","0.09011"
"16.22400","12.05010","0.09025"
"16.32000","12.05811","0.09061"
"16.41600","12.06607","0.09043"
"16.51200","12.07408","0.09073"
"16.60800","12.08215","0.09073"
"16.70400","12.09016","0.09082"
"16.80000","12.09811","0.09084"
"16.89600","12.10607","0.09096"
"16.99200","12.11408","0.09112"
"17.08800","12.12209","0.09129"
"17.18400","12.13010","0.09123"
"17.28000","12.13811","0.09154"
"17.37600","12.14606","0.09153"
"17.47200","12.15402","0.09186"
"17.56800","12.16209","0.09219"
"17.66400","12.17010","0.09170"
"17.76000","12.17805","0.09183"
"17.85600","12.18612","0.09234"
"17.95200","12.19402","0.09237"
"18.04800","12.20203","0.09260"
"18.14400","12.21016","0.09247"
"18.24000","12.21811","0.09290"
"18.33600","12.22612","0.09333"
"18.43200","12.23413","0.09351"
"18.52800","12.24209","0.09367"
"18.62400","12.25004","0.09444"
"18.72000","12.25811","0.09475"
"18.81600","12.26612","0.09517"
"18.91200","12.27413","0.09555"
"19.00800","12.28215","0.09589"
"19.10400","12.29004","0.09683"
"19.20000","12.29805","0.09665"
"19.29600","12.30612","0.09745"
"19.39200","12.31407","0.09817"
"19.48800","12.32209","0.09857"
"19.58400","12.33004","0.09945"
"19.68000","12.33805","0.10052"
"19.77600","12.34606","0.10124"
"19.87200","12.35413","0.10104"
"19.96800","12.36208","0.10156"
"20.06400","12.37010","0.10272"
"20.16000","12.37811","0.10333"
"20.25600","12.38600","0.10388"
"20.35200","12.39407","0.10459"
"20.44800","12.40214","0.10486"
"20.54400","12.41015","0.10565"
"20.64000","12.41811","0.10609"
"20.73600","12.42606","0.10663"
"20.83200","12.43407","0.10753"
"20.92800","12.44214","0.10787"
"21.02400","12.45009","0.10868"
"21.12000","12.45811","0.10882"
"21.21600","12.46606","0.10919"
"21.31200","12.47407","0.11028"
"21.40800","12.48208","0.11031"
"21.50400","12.49009","0.11119"
"21.60000","12.49816","0.11216"
"21.69600","12.50612","0.11214"
"21.79200","12.51407","0.11289"
"21.88800","12.52214","0.11341"
"21.98400","12.53015","0.11400"
"22.08000","12.53810","0.11483"
"22.17600","12.54618","0.11524"
"22.27200","12.55413","0.11508"
"22.36800","12.56208","0.11584"
"22.46400","12.57009","0.11618"
"22.56000","12.57810","0.11690"
"22.65600","12.58612","0.11746"
"22.75200","12.59413","0.11730"
"22.84800","12.60208","0.11817"
"22.94400","12.61009","0.11883"
"23.04000","12.61810","0.11940"
"23.13600","12.62611","0.11925"
"23.23200","12.63413","0.12006"
"23.32800","12.64214","0.12073"
"23.42400","12.65003","0.12106"
"23.52000","12.65804","0.12135"
"23.61600","12.66617","0.12159"
"23.71200","12.67407","0.12199"
"23.80800","12.68208","0.12239"
"23.90400","12.69009","0.12268"
"24.00000","12.69804","0.12296"
"24.09600","12.70611","0.12336"
"24.19200","12.71413","0.12365"
"24.28800","12.72214","0.12397"
"24.38400","12.73009","0.12435"
"24.48000","12.73810","0.12467"
"24.57600","12.74611","0.12479"
"24.67200","12.75406","0.12498"
"24.76800","12.76214","0.12562"
"24.86400","12.77009","0.12548"
"24.96000","12.77810","0.12570"
"25.05600","12.78605","0.12599"
"25.15200","12.79412","0.12675"
"25.24800","12.80208","0.12638"
"25.34400","12.81015","0.12687"
"25.44000","12.81810","0.12701"
"25.53600","12.82599","0.12760"
"25.63200","12.83406","0.12738"
"25.72800","12.84213","0.12817"
"25.82400","12.85009","0.12844"
"25.92000","12.85810","0.12872"
"26.01600","12.86611","0.12881"
"26.11200","12.87400","0.12939"
"26.20800","12.88207","0.12924"
"26.30400","12.89015","0.12952"
"26.40000","12.89816","0.13014"
"26.49600","12.90611","0.12979"
"26.59200","12.91406","0.13022"
"26.68800","12.92207","0.13055"
"26.78400","12.93008","0.13086"
"26.88000","12.93816","0.13172"
"26.97600","12.94611","0.13193"
"27.07200","12.95412","0.13206"
"27.16800","12.96207","0.13260"
"27.26400","12.97003","0.13264"
"27.36000","12.97816","0.13302"
"27.45600","12.98617","0.13348"
"27.55200","12.99412","0.13394"
"27.64800","13.00207","0.13415"
"27.74400","13.01008","0.13462"
"27.84000","13.01803","0.13482"
"27.93600","13.02617","0.13496"
"28.03200","13.03412","0.13541"
"28.12800","13.04207","0.13543"
"28.22400","13.05008","0.13616"
"28.32000","13.05809","0.13610"
"28.41600","13.06611","0.13660"
"28.51200","13.07412","0.13680"
"28.60800","13.08213","0.13729"
"28.70400","13.09008","0.13808"
"28.80000","13.09803","0.13767"
"28.89600","13.10611","0.13830"
"28.99200","13.11412","0.13825"
"29.08800","13.12213","0.13883"
"29.18400","13.13014","0.13915"
"29.28000","13.13809","0.13896"
"29.37600","13.14610","0.13940"
"29.47200","13.15412","0.13933"
"29.56800","13.16207","0.13995"
"29.66400","13.17014","0.14007"
"29.76000","13.17809","0.14029"
"29.85600","13.18604","0.14037"
"29.95200","13.19406","0.14063"
"30.04800","13.20207","0.14075"
"30.14400","13.21008","0.14137"
"30.24000","13.21809","0.14156"
"30.33600","13.22604","0.14194"
"30.43200","13.23400","0.14205"
"30.52800","13.24207","0.14223"
"30.62400","13.25014","0.14265"
"30.72000","13.25815","0.14328"
"30.81600","13.26610","0.14339"
"30.91200","13.27411","0.14366"
"31.00800","13.28207","0.14411"
"31.10400","13.29014","0.14484"
"31.20000","13.29815","0.14488"
"31.29600","13.30610","0.14505"
"31.39200","13.31405","0.14596"
"31.48800","13.32207","0.14637"
"31.58400","13.33008","0.14714"
"31.68000","13.33815","0.14727"
"31.77600","13.34616","0.14713"
"31.87200","13.35411","0.14822"
"31.96800","13.36206","0.14917"
"32.06400","13.37008","0.14969"
"32.16000","13.37809","0.14995"
"32.25600","13.38610","0.15085"
"32.35200","13.39411","0.15190"
"32.44800","13.40206","0.15302"
"32.54400","13.41008","0.15264"
"32.64000","13.41809","0.15344"
"32.73600","13.42610","0.15340"
"32.83200","13.43411","0.15454"
"32.92800","13.44212","0.15519"
"33.02400","13.45008","0.15647"
"33.12000","13.45809","0.15701"
"33.21600","13.46616","0.15827"
"33.31200","13.47411","0.15813"
"33.40800","13.48212","0.15946"
"33.50400","13.49013","0.16091"
"33.60000","13.49809","0.16168"
"33.69600","13.50610","0.16269"
"33.79200","13.51411","0.16414"
"33.88800","13.52212","0.16502"
"33.98400","13.53013","0.16610"
"34.08000","13.53808","0.16693"
"34.17600","13.54604","0.16954"
"34.27200","13.55411","0.16932"
"34.36800","13.56212","0.17021"
"34.46400","13.57013","0.17158"
"34.56000","13.57808","0.17261"
"34.65600","13.58610","0.17424"
"34.75200","13.59405","0.17590"
"34.84800","13.60212","0.17662"
"34.94400","13.61019","0.17774"
"35.04000","13.61814","0.17816"
"35.13600","13.62609","0.17875"
"35.23200","13.63405","0.18044"
"35.32800","13.64206","0.18164"
"35.42400","13.65013","0.18236"
"35.52000","13.65814","0.18352"
"35.61600","13.66609","0.18442"
"35.71200","13.67405","0.18502"
"35.80800","13.68206","0.18596"
"35.90400","13.69007","0.18687"
"36.00000","13.69814","0.18743"
"36.09600","13.70615","0.18787"
"36.19200","13.71405","0.18912"
"36.28800","13.72206","0.18934"
"36.38400","13.73007","0.18977"
"36.48000","13.73808","0.19034"
"36.57600","13.74609","0.19028"
"36.67200","13.75416","0.19099"
"36.76800","13.76206","0.19148"
"36.86400","13.77007","0.19204"
"36.96000","13.77808","0.19177"
"37.05600","13.78609","0.19262"
"37.15200","13.79410","0.19298"
"37.24800","13.80212","0.19286"
"37.34400","13.81007","0.19316"
"37.44000","13.81802","0.19359"
"37.53600","13.82609","0.19389"
"37.63200","13.83410","0.19423"
"37.72800","13.84211","0.19442"
"37.82400","13.85013","0.19442"
"37.92000","13.85808","0.19468"
"38.01600","13.86609","0.19489"
"38.11200","13.87410","0.19507"
"38.20800","13.88211","0.19519"
"38.30400","13.89013","0.19548"
"38.40000","13.89808","0.19598"
"38.49600","13.90609","0.19599"
"38.59200","13.91404","0.19622"
"38.68800","13.92211","0.19669"
"38.78400","13.93013","0.19693"
"38.88000","13.93808","0.19682"
"38.97600","13.94603","0.19777"
"39.07200","13.95404","0.19751"
"39.16800","13.96211","0.19837"
"39.26400","13.97012","0.19837"
"39.36000","13.97814","0.19873"
"39.45600","13.98609","0.19932"
"39.55200","13.99410","0.19942"
"39.64800","14.00211","0.19948"
"39.74400","14.01012","0.20094"
"39.84000","14.01808","0.20144"
"39.93600","14.02615","0.20123"
"40.03200","14.03410","0.20196"
"40.12800","14.04211","0.20257"
"40.22400","14.05012","0.20305"
"40.32000","14.05813","0.20394"
"40.41600","14.06615","0.20348"
"40.51200","14.07410","0.20481"
"40.60800","14.08205","0.20581"
"40.70400","14.09006","0.20572"
"40.80000","14.09813","0.20634"
"40.89600","14.10609","0.20707"
"40.99200","14.11410","0.20826"
"41.08800","14.12211","0.20821"
"41.18400","14.13006","0.20871"
"41.28000","14.13807","0.20937"
"41.37600","14.14614","0.21058"
"41.47200","14.15416","0.21083"
"41.56800","14.16205","0.21168"
"41.66400","14.17006","0.21167"
"41.76000","14.17807","0.21277"
"41.85600","14.18608","0.21199"
"41.95200","14.19410","0.21384"
"42.04800","14.20217","0.21461"
"42.14400","14.21006","0.21457"
"42.24000","14.21807","0.21503"
"42.33600","14.22608","0.21541"
"42.43200","14.23415","0.21613"
"42.52800","14.24217","0.21639"
"42.62400","14.25012","0.21652"
"42.72000","14.25807","0.21721"
"42.81600","14.26608","0.21709"
"42.91200","14.27409","0.21764"
"43.00800","14.28217","0.21837"
"43.10400","14.29012","0.21857"
"43.20000","14.29807","0.21963"
"43.29600","14.30608","0.22000"
"43.39200","14.31409","0.22067"
"43.48800","14.32210","0.21995"
"43.58400","14.33012","0.22093"
"43.68000","14.33813","0.22137"
"43.77600","14.34608","0.22174"
"43.87200","14.35403","0.22159"
"43.96800","14.36210","0.22246"
"44.06400","14.37012","0.22221"
"44.16000","14.37813","0.22333"
"44.25600","14.38614","0.22346"
"44.35200","14.39403","0.22386"
"44.44800","14.40204","0.22393"
"44.54400","14.41012","0.22428"
"44.64000","14.41813","0.22487"
"44.73600","14.42614","0.22562"
"44.83200","14.43415","0.22643"
"44.92800","14.44204","0.22650"
"45.02400","14.45011","0.22716"
"45.12000","14.45813","0.22697"
"45.21600","14.46614","0.22805"
"45.31200","14.47415","0.22798"
"45.40800","14.48210","0.22900"
"45.50400","14.49005","0.22861"
"45.60000","14.49813","0.22907"
"45.69600","14.50614","0.22948"
"45.79200","14.51415","0.22976"
"45.88800","14.52210","0.23041"
"45.98400","14.53005","0.23069"
"46.08000","14.53806","0.23134"
"46.17600","14.54608","0.23120"
"46.27200","14.55415","0.23145"
"46.36800","14.56210","0.23167"
"46.46400","14.57005","0.23215"
"46.56000","14.57806","0.23208"
"46.65600","14.58608","0.23232"
"46.75200","14.59409","0.23297"
"46.84800","14.60216","0.23340"
"46.94400","14.61011","0.23322"
"47.04000","14.61806","0.23398"
"47.13600","14.62608","0.23411"
"47.23200","14.63409","0.23426"
"47.32800","14.64210","0.23426"
"47.42400","14.65017","0.23522"
"47.52000","14.65812","0.23530"
"47.61600","14.66607","0.23546"
"47.71200","14.67415","0.23561"
"47.80800","14.68216","0.23614"
"47.90400","14.69005","0.23650"
"48.00000","14.69812","0.23647"
"48.09600","14.70607","0.23652"
"48.19200","14.71403","0.23709"
"48.28800","14.72210","0.23714"
"48.38400","14.73011","0.23755"
"48.48000","14.73812","0.23732"
"48.57600","14.74613","0.23759"
"48.67200","14.75402","0.23774"
"48.76800","14.76204","0.23792"
"48.86400","14.77011","0.23811"
"48.96000","14.77806","0.23826"
"49.05600","14.78607","0.23847"
"49.15200","14.79408","0.23836"
"49.24800","14.80204","0.23851"
"49.34400","14.81011","0.23859"
"49.44000","14.81812","0.23875"
"49.53600","14.82613","0.23907"
"49.63200","14.83414","0.23916"
"49.72800","14.84209","0.23938"
"49.82400","14.85005","0.23940"
"49.92000","14.85812","0.23950"
"50.01600","14.86613","0.23947"
"50.11200","14.87414","0.23960"
"50.20800","14.88203","0.23976"
"50.30400","14.89011","0.23994"
"50.40000","14.89806","0.23992"
"50.49600","14.90607","0.24011"
"50.59200","14.91408","0.24011"
"50.68800","14.92209","0.24024"
"50.78400","14.93011","0.24013"
"50.88000","14.93806","0.24038"
"50.97600","14.94613","0.24050"
"51.07200","14.95414","0.24056"
"51.16800","14.96215","0.24077"
"51.26400","14.97010","0.24069"
"51.36000","14.97806","0.24075"
"51.45600","14.98607","0.24085"
"51.55200","14.99414","0.24090"
"51.64800","15.00209","0.24101"
"51.74400","15.01010","0.24109"
"51.84000","15.01805","0.24123"
"51.93600","15.02607","0.24147"
"52.03200","15.03408","0.24126"
"52.12800","15.04215","0.24129"
"52.22400","15.05010","0.24130"
"52.32000","15.05811","0.24131"
"52.41600","15.06607","0.24171"
"52.51200","15.07402","0.24158"
"52.60800","15.08209","0.24187"
"52.70400","15.09010","0.24200"
"52.80000","15.09811","0.24208"
"52.89600","15.10613","0.24216"
"52.99200","15.11408","0.24196"
"53.08800","15.12203","0.24217"
"53.18400","15.13016","0.24238"
"53.28000","15.13811","0.24250"
"53.37600","15.14612","0.24275"
"53.47200","15.15408","0.24256"
"53.56800","15.16203","0.24280"
"53.66400","15.17010","0.24320"
"53.76000","15.17811","0.24289"
"53.85600","15.18612","0.24323"
"53.95200","15.19408","0.24335"
"54.04800","15.20209","0.24338"
"54.14400","15.21010","0.24337"
"54.24000","15.21805","0.24353"
"54.33600","15.22612","0.24388"
"54.43200","15.23413","0.24406"
"54.52800","15.24209","0.24402"
"54.62400","15.25004","0.24427"
"54.72000","15.25811","0.24433"
"54.81600","15.26612","0.24461"
"54.91200","15.27407","0.24461"
"55.00800","15.28209","0.24488"
"55.10400","15.29010","0.24490"
"55.20000","15.29805","0.24498"
"55.29600","15.30606","0.24543"
"55.39200","15.31407","0.24524"
"55.48800","15.32215","0.24577"
"55.58400","15.33010","0.24561"
"55.68000","15.33805","0.24615"
"55.77600","15.34612","0.24634"
"55.87200","15.35413","0.24640"
"55.96800","15.36202","0.24666"
"56.06400","15.37016","0.24683"
"56.16000","15.37811","0.24722"
"56.25600","15.38600","0.24771"
"56.35200","15.39407","0.24768"
"56.44800","15.40214","0.24781"
"56.54400","15.41010","0.24831"
"56.64000","15.41811","0.24885"
"56.73600","15.42612","0.24915"
"56.83200","15.43407","0.24972"
"56.92800","15.44208","0.24974"
"57.02400","15.45009","0.25024"
"57.12000","15.45811","0.25033"
"57.21600","15.46606","0.25093"
"57.31200","15.47407","0.25152"
"57.40800","15.48208","0.25206"
"57.50400","15.49009","0.25245"
"57.60000","15.49817","0.25265"
"57.69600","15.50612","0.25285"
"57.79200","15.51407","0.25333"
"57.88800","15.52208","0.25431"
"57.98400","15.53009","0.25417"
"58.08000","15.53810","0.25528"
"58.17600","15.54612","0.25586"
"58.27200","15.55407","0.25673"
"58.36800","15.56208","0.25669"
"58.46400","15.57009","0.25774"
"58.56000","15.57810","0.25869"
"58.65600","15.58612","0.25917"
"58.75200","15.59407","0.25936"
"58.84800","15.60208","0.26010"
"58.94400","15.61009","0.25997"
"59.04000","15.61810","0.26144"
"59.13600","15.62611","0.26184"
"59.23200","15.63412","0.26269"
"59.32800","15.64214","0.26424"
"59.42400","15.65003","0.26414"
"59.52000","15.65804","0.26480"
"59.61600","15.66617","0.26563"
"59.71200","15.67406","0.26640"
"59.80800","15.68214","0.26743"
"59.90400","15.69015","0.26775"
"60.00000","15.69804","0.26814"
"60.09600","15.70605","0.26889"
"60.19200","15.71418","0.26911"
"60.28800","15.72208","0.27039"
"60.38400","15.73009","0.27109"
"60.48000","15.73810","0.27132"
"60.57600","15.74605","0.27204"
"60.67200","15.75406","0.27241"
"60.76800","15.76214","0.27394"
"60.86400","15.77015","0.27431"
"60.96000","15.77810","0.27503"
"61.05600","15.78605","0.27534"
"61.15200","15.79406","0.27612"
"61.24800","15.80213","0.27713"
"61.34400","15.81009","0.27768"
"61.44000","15.81810","0.27909"
"61.53600","15.82611","0.27956"
"61.63200","15.83400","0.27925"
"61.72800","15.84207","0.28047"
"61.82400","15.85015","0.28138"
"61.92000","15.85816","0.28213"
"62.01600","15.86611","0.28321"
"62.11200","15.87412","0.28329"
"62.20800","15.88207","0.28402"
"62.30400","15.89008","0.28436"
"62.40000","15.89816","0.28470"
"62.49600","15.90611","0.28559"
"62.59200","15.91406","0.28541"
"62.68800","15.92207","0.28609"
"62.78400","15.93008","0.28675"
"62.88000","15.93810","0.28647"
"62.97600","15.94611","0.28699"
"63.07200","15.95412","0.28743"
"63.16800","15.96207","0.28737"
"63.26400","15.97002","0.28773"
"63.36000","15.97809","0.28835"
"63.45600","15.98611","0.28835"
"63.55200","15.99412","0.28891"
"63.64800","16.00213","0.28912"
"63.74400","16.01008","0.28958"
"63.84000","16.01803","0.28965"
"63.93600","16.02611","0.28995"
"64.03200","16.03412","0.29043"
"64.12800","16.04213","0.29060"
"64.22400","16.05008","0.29119"
"64.32000","16.05803","0.29110"
"64.41600","16.06604","0.29212"
"64.51200","16.07412","0.29226"
"64.60800","16.08213","0.29214"
"64.70400","16.09008","0.29301"
"64.80000","16.09809","0.29335"
"64.89600","16.10604","0.29379"
"64.99200","16.11412","0.29448"
"65.08800","16.12213","0.29530"
"65.18400","16.13008","0.29549"
"65.28000","16.13809","0.29609"
"65.37600","16.14610","0.29690"
"65.47200","16.15405","0.29788"
"65.56800","16.16207","0.29715"
"65.66400","16.17014","0.29576"
"65.76000","16.17809","0.29511"
"65.85600","16.18604","0.29372"
"65.95200","16.19406","0.26121"
"66.04800","16.20207","0.00630"
"66.14400","16.21008","0.01807"
"66.24000","16.21815","0.02061"
"66.33600","16.22610","0.02427"
"66.43200","16.23411","0.01499"
"66.52800","16.24207","0.01045"
"66.62400","16.25008","0.02109"
"66.72000","16.25809","0.02864"
"66.81600","16.26610","0.02796"
"66.91200","16.27411","0.01952"
"67.00800","16.28206","0.01414"
"67.10400","16.29014","0.01900"
"67.20000","16.29815","0.02799"
"67.29600","16.30610","0.02912"
"67.39200","16.31411","0.02191"
"67.48800","16.32206","0.01506"
"67.58400","16.33008","0.01847"
"67.68000","16.33809","0.02717"
"67.77600","16.34610","0.02996"
"67.87200","16.35411","0.02383"
"67.96800","16.36212","0.01669"
"68.06400","16.37008","0.01822"
"68.16000","16.37809","0.02584"
"68.25600","16.38616","0.03097"
"68.35200","16.39411","0.02615"
"68.44800","16.40212","0.01982"
"68.54400","16.41007","0.01841"
"68.64000","16.41803","0.02513"
"68.73600","16.42610","0.03170"
"68.83200","16.43417","0.02821"
"68.92800","16.44212","0.02118"
"69.02400","16.45007","0.01903"
"69.12000","16.45808","0.02402"
"69.21600","16.46610","0.03063"
"69.31200","16.47411","0.02986"
"69.40800","16.48212","0.02293"
"69.50400","16.49013","0.02033"
"69.60000","16.49809","0.02456"
"69.69600","16.50598","0.03011"
"69.79200","16.51411","0.03103"
"69.88800","16.52212","0.02550"
"69.98400","16.53013","0.02071"
"70.08000","16.53814","0.02314"
"70.17600","16.54609","0.02991"
"70.27200","16.55405","0.03164"
"70.36800","16.56212","0.02693"
"70.46400","16.57013","0.02189"
"70.56000","16.57814","0.02326"
"70.65600","16.58610","0.02893"
"70.75200","16.59411","0.03161"
"70.84800","16.60206","0.02798"
"70.94400","16.61013","0.02271"
"71.04000","16.61814","0.02379"
"71.13600","16.62609","0.02893"
"71.23200","16.63411","0.03259"
"71.32800","16.64206","0.02949"
"71.42400","16.65007","0.02498"
"71.52000","16.65814","0.02396"
"71.61600","16.66609","0.02953"
"71.71200","16.67410","0.03296"
"71.80800","16.68206","0.03078"
"71.90400","16.69007","0.02674"
"72.00000","16.69814","0.02515"
"72.09600","16.70615","0.02948"
"72.19200","16.71410","0.03340"
"72.28800","16.72206","0.03207"
"72.38400","16.73007","0.02771"
"72.48000","16.73808","0.02686"
"72.57600","16.74609","0.03048"
"72.67200","16.75416","0.03355"
"72.76800","16.76212","0.03351"
"72.86400","16.77007","0.02893"
"72.96000","16.77808","0.02750"
"73.05600","16.78609","0.03087"
"73.15200","16.79410","0.03412"
"73.24800","16.80217","0.03357"
"73.34400","16.81007","0.02995"
"73.44000","16.81808","0.02831"
"73.53600","16.82609","0.03154"
"73.63200","16.83410","0.03494"
"73.72800","16.84211","0.03441"
"73.82400","16.85012","0.03139"
"73.92000","16.85808","0.02988"
"74.01600","16.86609","0.03239"
"74.11200","16.87410","0.03516"
"74.20800","16.88211","0.03484"
"74.30400","16.89012","0.03235"
"74.40000","16.89808","0.03092"
"74.49600","16.90609","0.03331"
"74.59200","16.91404","0.03564"
"74.68800","16.92211","0.03517"
"74.78400","16.93012","0.03267"
"74.88000","16.93808","0.03194"
"74.97600","16.94615","0.03425"
"75.07200","16.95404","0.03627"
"75.16800","16.96205","0.03601"
"75.26400","16.97018","0.03395"
"75.36000","16.97814","0.03321"
"75.45600","16.98609","0.03519"
"75.55200","16.99410","0.03642"
"75.64800","17.00205","0.03678"
"75.74400","17.01006","0.03453"
"75.84000","17.01819","0.03429"
"75.93600","17.02615","0.03568"
"76.03200","17.03410","0.03716"
"76.12800","17.04211","0.03674"
"76.22400","17.05012","0.03521"
"76.32000","17.05813","0.03522"
"76.41600","17.06614","0.03639"
"76.51200","17.07410","0.03753"
"76.60800","17.08205","0.03747"
"76.70400","17.09006","0.03581"
"76.80000","17.09813","0.03613"
"76.89600","17.10614","0.03717"
"76.99200","17.11410","0.03790"
"77.08800","17.12211","0.03702"
"77.18400","17.13006","0.03483"
"77.28000","17.13807","0.03531"
"77.37600","17.14608","0.03636"
"77.47200","17.15410","0.03741"
"77.56800","17.16211","0.03686"
"77.66400","17.17012","0.03603"
"77.76000","17.17807","0.03596"
"77.85600","17.18608","0.03712"
"77.95200","17.19415","0.03770"
"78.04800","17.20217","0.03716"
"78.14400","17.21012","0.03559"
"78.24000","17.21807","0.03635"
"78.33600","17.22602","0.03744"
"78.43200","17.23409","0.03819"
"78.52800","17.24211","0.03749"
"78.62400","17.25012","0.03674"
"78.72000","17.25813","0.03708"
"78.81600","17.26608","0.03822"
"78.91200","17.27403","0.03855"
"79.00800","17.28216","0.03768"
"79.10400","17.29012","0.03712"
"79.20000","17.29813","0.03781"
"79.29600","17.30608","0.03875"
"79.39200","17.31403","0.03854"
"79.48800","17.32204","0.03809"
"79.58400","17.33012","0.03751"
"79.68000","17.33807","0.03835"
"79.77600","17.34608","0.03909"
"79.87200","17.35403","0.03891"
"79.96800","17.36210","0.03861"
"80.06400","17.37005","0.03847"
"80.16000","17.37813","0.03870"
"80.25600","17.38614","0.03957"
"80.35200","17.39409","0.03892"
"80.44800","17.40204","0.03778"
"80.54400","17.41011","0.03718"
"80.64000","17.41813","0.03785"
"80.73600","17.42614","0.03651"
"80.83200","17.43409","0.03598"
"80.92800","17.44204","0.03547"
"81.02400","17.45005","0.03578"
"81.12000","17.45812","0.03656"
"81.21600","17.46608","0.03648"
"81.31200","17.47409","0.03657"
"81.40800","17.48210","0.03582"
"81.50400","17.49011","0.03634"
"81.60000","17.49806","0.03647"
"81.69600","17.50608","0.03695"
"81.79200","17.51403","0.03633"
"81.88800","17.52210","0.03549"
"81.98400","17.53005","0.03600"
"82.08000","17.53800","0.03686"
"82.17600","17.54614","0.03727"
"82.27200","17.55415","0.03727"
"82.36800","17.56210","0.03709"
"82.46400","17.57011","0.03747"
"82.56000","17.57812","0.03797"
"82.65600","17.58602","0.03820"
"82.75200","17.59409","0.03788"
"82.84800","17.60216","0.03771"
"82.94400","17.61011","0.03786"
"83.04000","17.61812","0.03841"
"83.13600","17.62613","0.03829"
"83.23200","17.63409","0.03795"
"83.32800","17.64216","0.03818"
"83.42400","17.65017","0.03880"
"83.52000","17.65812","0.03891"
"83.61600","17.66607","0.03927"
"83.71200","17.67409","0.03896"
"83.80800","17.68210","0.03882"
"83.90400","17.69017","0.03958"
"84.00000","17.69812","0.03953"
"84.09600","17.70607","0.03935"
"84.19200","17.71408","0.03930"
"84.28800","17.72210","0.03953"
"84.38400","17.73011","0.03975"
"84.48000","17.73812","0.04006"
"84.57600","17.74613","0.04037"
"84.67200","17.75402","0.03973"
"84.76800","17.76209","0.04007"
"84.86400","17.77011","0.04027"
"84.96000","17.77812","0.04007"
"85.05600","17.78613","0.03985"
"85.15200","17.79414","0.04010"
"85.24800","17.80203","0.04047"
"85.34400","17.81005","0.04056"
"85.44000","17.81812","0.04041"
"85.53600","17.82613","0.03984"
"85.63200","17.83414","0.04030"
"85.72800","17.84209","0.04037"
"85.82400","17.85004","0.04074"
"85.92000","17.85812","0.04107"
"86.01600","17.86613","0.04065"
"86.11200","17.87414","0.04090"
"86.20800","17.88209","0.04113"
"86.30400","17.89010","0.04137"
"86.40000","17.89806","0.04160"
"86.49600","17.90607","0.04103"
"86.59200","17.91414","0.04139"
"86.68800","17.92209","0.04201"
"86.78400","17.93010","0.04218"
"86.88000","17.93806","0.04157"
"86.97600","17.94607","0.04202"
"87.07200","17.95414","0.04243"
"87.16800","17.96215","0.04283"
"87.26400","17.97010","0.04289"
"87.36000","17.97812","0.04256"
"87.45600","17.98607","0.04307"
"87.55200","17.99408","0.04371"
"87.64800","18.00215","0.04419"
"87.74400","18.01016","0.04356"
"87.84000","18.01805","0.04409"
"87.93600","18.02607","0.04453"
"88.03200","18.03414","0.04511"
"88.12800","18.04209","0.04568"
"88.22400","18.05010","0.04517"
"88.32000","18.05817","0.04438"
"88.41600","18.06606","0.04375"
"88.51200","18.07402","0.04375"
"88.60800","18.08209","0.04351"
"88.70400","18.09010","0.04219"
"88.80000","18.09811","0.04202"
"88.89600","18.10612","0.04235"
"88.99200","18.11408","0.04199"
"89.08800","18.12209","0.04135"
"89.18400","18.13010","0.04094"
"89.28000","18.13811","0.04123"
"89.37600","18.14612","0.04101"
"89.47200","18.15408","0.04139"
"89.56800","18.16203","0.04166"
"89.66400","18.17010","0.04141"
"89.76000","18.17811","0.04149"
"89.85600","18.18612","0.04187"
"89.95200","18.19413","0.04212"
"90.04800","18.20209","0.04182"
"90.14400","18.21004","0.04201"
"90.24000","18.21811","0.04264"
"90.33600","18.22612","0.04291"
"90.43200","18.23413","0.04333"
"90.52800","18.24208","0.04368"
"90.62400","18.25010","0.04436"
"90.72000","18.25805","0.04498"
"90.81600","18.26612","0.04530"
"90.91200","18.27413","0.04580"
"91.00800","18.28208","0.04632"
"91.10400","18.29016","0.04672"
"91.20000","18.29805","0.04725"
"91.29600","18.30606","0.04701"
"91.39200","18.31413","0.04768"
"91.48800","18.32214","0.04842"
"91.58400","18.33010","0.04850"
"91.68000","18.33805","0.04885"
"91.77600","18.34606","0.04956"
"91.87200","18.35407","0.04961"
"91.96800","18.36214","0.05016"
"92.06400","18.37016","0.05057"
"92.16000","18.37811","0.05147"
"92.25600","18.38612","0.05207"
"92.35200","18.39413","0.05235"
"92.44800","18.40214","0.05233"
"92.54400","18.41009","0.05375"
"92.64000","18.41811","0.05412"
"92.73600","18.42606","0.05411"
"92.83200","18.43407","0.05430"
"92.92800","18.44208","0.05486"
"93.02400","18.45009","0.05545"
"93.12000","18.45811","0.05584"
"93.21600","18.46612","0.05648"
"93.31200","18.47407","0.05734"
"93.40800","18.48202","0.05826"
"93.50400","18.49009","0.05903"
"93.60000","18.49810","0.05920"
"93.69600","18.50611","0.05972"
"93.79200","18.51407","0.05998"
"93.88800","18.52208","0.06034"
"93.98400","18.53003","0.06089"
"94.08000","18.53816","0.06179"
"94.17600","18.54612","0.06212"
"94.27200","18.55413","0.06258"
"94.36800","18.56214","0.06253"
"94.46400","18.57003","0.06336"
"94.56000","18.57810","0.06437"
"94.65600","18.58611","0.06551"
"94.75200","18.59413","0.06597"
"94.84800","18.60208","0.06680"
"94.94400","18.61009","0.06741"
"95.04000","18.61804","0.06786"
"95.13600","18.62611","0.06809"
"95.23200","18.63412","0.06853"
"95.32800","18.64214","0.06914"
"95.42400","18.65009","0.07053"
"95.52000","18.65804","0.07018"
"95.61600","18.66611","0.07092"
"95.71200","18.67412","0.07152"
"95.80800","18.68214","0.07192"
"95.90400","18.69015","0.07205"
"96.00000","18.69804","0.07144"
"96.09600","18.70605","0.07248"
"96.19200","18.71412","0.07322"
"96.28800","18.72214","0.07405"
"96.38400","18.73009","0.07415"
"96.48000","18.73810","0.07436"
"96.57600","18.74605","0.07456"
"96.67200","18.75412","0.07587"
"96.76800","18.76213","0.07639"
"96.86400","18.77009","0.07715"
"96.96000","18.77810","0.07811"
"97.05600","18.78611","0.07895"
"97.15200","18.79400","0.08098"
"97.24800","18.80207","0.08135"
"97.34400","18.81015","0.08239"
"97.44000","18.81810","0.08390"
"97.53600","18.82611","0.08409"
"97.63200","18.83406","0.08516"
"97.72800","18.84201","0.08581"
"97.82400","18.85009","0.08598"
"97.92000","18.85816","0.08610"
"98.01600","18.86611","0.08673"
"98.11200","18.87412","0.08799"
"98.20800","18.88207","0.08823"
"98.30400","18.89009","0.08847"
"98.40000","18.89810","0.08947"
"98.49600","18.90611","0.08921"
"98.59200","18.91412","0.08980"
"98.68800","18.92207","0.09003"
"98.78400","18.93008","0.09000"
"98.88000","18.93810","0.09031"
"98.97600","18.94611","0.08786"
"99.07200","18.95412","0.08641"
"99.16800","18.96207","0.08596"
"99.26400","18.97008","0.08807"
"99.36000","18.97809","0.08997"
"99.45600","18.98611","0.08995"
"99.55200","18.99406","0.08946"
"99.64800","19.00213","0.08984"
"99.74400","19.01008","0.09086"
"99.84000","19.01803","0.09085"
"99.93600","19.02611","0.09067"
"100.03200","19.03406","0.09088"
"100.12800","19.04207","0.09114"
"100.22400","19.05008","0.09174"
"100.32000","19.05803","0.09180"
"100.41600","19.06605","0.09173"
"100.51200","19.07412","0.09209"
"100.60800","19.08213","0.09297"
"100.70400","19.09014","0.09349"
"100.80000","19.09815","0.09358"
"100.89600","19.10604","0.09425"
"100.99200","19.11406","0.09329"
"101.08800","19.12219","0.09348"
"101.18400","19.13008","0.09373"
"101.28000","19.13809","0.09457"
"101.37600","19.14610","0.09612"
"101.47200","19.15405","0.09619"
"101.56800","19.16213","0.09728"
"101.66400","19.17014","0.09834"
"101.76000","19.17809","0.09755"
"101.85600","19.18610","0.09765"
"101.95200","19.19411","0.09816"
"102.04800","19.20207","0.09959"
"102.14400","19.21014","0.10129"
"102.24000","19.21809","0.10201"
"102.33600","19.22610","0.09962"
"102.43200","19.23411","0.09943"
"102.52800","19.24207","0.09924"
"102.62400","19.25008","0.10600"
"102.72000","19.25815","0.10969"
"102.81600","19.26610","0.10253"
"102.91200","19.27411","0.09678"
"103.00800","19.28213","0.09915"
"103.10400","19.29008","0.11009"
"103.20000","19.29815","0.11230"
"103.29600","19.30610","0.10670"
"103.39200","19.31411","0.10238"
"103.48800","19.32206","0.10989"
"103.58400","19.33002","0.11559"
"103.68000","19.33809","0.11470"
"103.77600","19.34610","0.10996"
"103.87200","19.35411","0.11020"
"103.96800","19.36218","0.11709"
"104.06400","19.37008","0.12019"
"104.16000","19.37803","0.11732"
"104.25600","19.38616","0.11526"
"104.35200","19.39411","0.11843"
"104.44800","19.40206","0.12222"
"104.54400","19.41013","0.12206"
"104.64000","19.41809","0.11920"
"104.73600","19.42604","0.11981"
"104.83200","19.43417","0.12338"
"104.92800","19.44212","0.12445"
"105.02400","19.45013","0.12311"
"105.12000","19.45815","0.12197"
"105.21600","19.46610","0.12381"
"105.31200","19.47405","0.12599"
"105.40800","19.48218","0.12593"
"105.50400","19.49013","0.12526"
"105.60000","19.49808","0.12579"
"105.69600","19.50604","0.12756"
"105.79200","19.51405","0.12843"
"105.88800","19.52206","0.12741"
"105.98400","19.53007","0.12642"
"106.08000","19.53814","0.12490"
"106.17600","19.54609","0.06205"
"106.27200","19.55405","0.07023"
"106.36800","19.56206","0.07539"
"106.46400","19.57013","0.06118"
"106.56000","19.57808","0.05442"
"106.65600","19.58609","0.05935"
"106.75200","19.59405","0.06410"
"106.84800","19.60206","0.07829"
"106.94400","19.61007","0.06821"
"107.04000","19.61808","0.05876"
"107.13600","19.62615","0.05979"
"107.23200","19.63411","0.06371"
"107.32800","19.64206","0.07684"
"107.42400","19.65007","0.07556"
"107.52000","19.65814","0.06494"
"107.61600","19.66609","0.06391"
"107.71200","19.67410","0.06409"
"107.80800","19.68212","0.07316"
"107.90400","19.69007","0.07971"
"108.00000","19.69808","0.07004"
"108.09600","19.70609","0.06614"
"108.19200","19.71404","0.06758"
"108.28800","19.72211","0.07067"
"108.38400","19.73007","0.08160"
"108.48000","19.73802","0.07517"
"108.57600","19.74609","0.07031"
"108.67200","19.75416","0.07003"
"108.76800","19.76212","0.07186"
"108.86400","19.77013","0.08184"
"108.96000","19.77808","0.08227"
"109.05600","19.78609","0.07374"
"109.15200","19.79410","0.07240"
"109.24800","19.80211","0.07218"
"109.34400","19.81013","0.08240"
"109.44000","19.81808","0.08544"
"109.53600","19.82609","0.07874"
"109.63200","19.83410","0.07541"
"109.72800","19.84211","0.07454"
"109.82400","19.85013","0.08393"
"109.92000","19.85808","0.08751"
"110.01600","19.86609","0.08232"
"110.11200","19.87410","0.07803"
"110.20800","19.88211","0.07750"
"110.30400","19.89012","0.08485"
"110.40000","19.89808","0.08903"
"110.49600","19.90603","0.08597"
"110.59200","19.91410","0.08028"
"110.68800","19.92211","0.07920"
"110.78400","19.93006","0.08656"
"110.88000","19.93807","0.09017"
"110.97600","19.94615","0.08778"
"111.07200","19.95404","0.08229"
"111.16800","19.96205","0.08326"
"111.26400","19.97012","0.08833"
"111.36000","19.97807","0.09056"
"111.45600","19.98615","0.08929"
"111.55200","19.99410","0.08609"
"111.64800","20.00205","0.08599"
"111.74400","20.01006","0.08949"
"111.84000","20.01814","0.09135"
"111.93600","20.02608","0.09001"
"112.03200","20.03410","0.08813"
"112.12800","20.04211","0.08842"
"112.22400","20.05006","0.09052"
"112.32000","20.05807","0.09131"
"112.41600","20.06614","0.09077"
"112.51200","20.07410","0.08919"
"112.60800","20.08211","0.08855"
"112.70400","20.09006","0.09057"
"112.80000","20.09801","0.09144"
"112.89600","20.10614","0.09065"
"112.99200","20.11415","0.08972"
"113.08800","20.12211","0.08971"
"113.18400","20.13012","0.09090"
"113.28000","20.13807","0.09191"
"113.37600","20.14608","0.09126"
"113.47200","20.15416","0.09043"
"113.56800","20.16217","0.09056"
"113.66400","20.17012","0.09149"
"113.76000","20.17813","0.09266"
"113.85600","20.18608","0.09200"
"113.95200","20.19409","0.09119"
"114.04800","20.20217","0.09105"
"114.14400","20.21012","0.09204"
"114.24000","20.21807","0.09404"
"114.33600","20.22608","0.09207"
"114.43200","20.23409","0.09155"
"114.52800","20.24211","0.09182"
"114.62400","20.25012","0.09365"
"114.72000","20.25813","0.09553"
"114.81600","20.26608","0.09327"
"114.91200","20.27403","0.09256"
"115.00800","20.28210","0.09318"
"115.10400","20.29011","0.09537"
"115.20000","20.29813","0.09671"
"115.29600","20.30614","0.09462"
"115.39200","20.31409","0.09302"
"115.48800","20.32204","0.09431"
"115.58400","20.33012","0.09778"
"115.68000","20.33807","0.09846"
"115.77600","20.34614","0.09609"
"115.87200","20.35415","0.09460"
"115.96800","20.36210","0.09698"
"116.06400","20.37005","0.10057"
"116.16000","20.37812","0.10069"
"116.25600","20.38608","0.09691"
"116.35200","20.39409","0.09618"
"116.44800","20.40210","0.10045"
"116.54400","20.40999","0.10345"
"116.64000","20.41807","0.10186"
"116.73600","20.42614","0.09873"
"116.83200","20.43409","0.10060"
"116.92800","20.44204","0.10357"
"117.02400","20.45011","0.10591"
"117.12000","20.45807","0.10434"
"117.21600","20.46608","0.10301"
"117.31200","20.47409","0.10335"
"117.40800","20.48210","0.10682"
"117.50400","20.49005","0.10890"
"117.60000","20.49807","0.10664"
"117.69600","20.50608","0.10535"
"117.79200","20.51415","0.10785"
"117.88800","20.52210","0.10956"
"117.98400","20.53011","0.11022"
"118.08000","20.53812","0.10922"
"118.17600","20.54613","0.10856"
"118.27200","20.55415","0.10978"
"118.36800","20.56216","0.11208"
"118.46400","20.57011","0.11274"
"118.56000","20.57812","0.11138"
"118.65600","20.58607","0.11093"
"118.75200","20.59409","0.11225"
"118.84800","20.60210","0.11411"
"118.94400","20.61011","0.11384"
"119.04000","20.61812","0.11266"
"119.13600","20.62607","0.11332"
"119.23200","20.63408","0.11541"
"119.32800","20.64210","0.11646"
"119.42400","20.65011","0.11575"
"119.52000","20.65812","0.11557"
"119.61600","20.66607","0.11651"
"119.71200","20.67402","0.11777"
"119.80800","20.68210","0.11825"
"119.90400","20.69011","0.11779"
"120.00000","20.69812","0.11734"
"120.09600","20.70607","0.11868"
"120.19200","20.71408","0.11988"
"120.28800","20.72203","0.11992"
"120.38400","20.73005","0.11917"
"120.48000","20.73812","0.11954"
"120.57600","20.74613","0.12052"
"120.67200","20.75408","0.12119"
"120.76800","20.76203","0.12152"
"120.86400","20.77005","0.12094"
"120.96000","20.77812","0.12143"
"121.05600","20.78613","0.12225"
"121.15200","20.79414","0.12298"
"121.24800","20.80203","0.12252"
"121.34400","20.81005","0.12251"
"121.44000","20.81812","0.12330"
"121.53600","20.82613","0.12425"
"121.63200","20.83408","0.12428"
"121.72800","20.84209","0.12391"
"121.82400","20.85011","0.12415"
"121.92000","20.85806","0.12449"
"122.01600","20.86607","0.12508"
"122.11200","20.87414","0.12488"
"122.20800","20.88215","0.12510"
"122.30400","20.89010","0.12564"
"122.40000","20.89806","0.12575"
"122.49600","20.90613","0.12621"
"122.59200","20.91414","0.12622"
"122.68800","20.92209","0.12640"
"122.78400","20.93010","0.12658"
"122.88000","20.93812","0.12728"
"122.97600","20.94607","0.12740"
"123.07200","20.95408","0.12720"
"123.16800","20.96209","0.12755"
"123.26400","20.97010","0.12794"
"123.36000","20.97812","0.12796"
"123.45600","20.98607","0.12801"
"123.55200","20.99402","0.12821"
"123.64800","21.00215","0.12846"
"123.74400","21.01010","0.12893"
"123.84000","21.01811","0.12971"
"123.93600","21.02612","0.12899"
"124.03200","21.03408","0.12970"
"124.12800","21.04203","0.12960"
"124.22400","21.05010","0.13037"
"124.32000","21.05817","0.13051"
"124.41600","21.06613","0.13044"
"124.51200","21.07408","0.13077"
"124.60800","21.08209","0.13085"
"124.70400","21.09004","0.13117"
"124.80000","21.09811","0.13149"
"124.89600","21.10612","0.13139"
"124.99200","21.11407","0.13216"
"125.08800","21.12203","0.13211"
"125.18400","21.13010","0.13193"
"125.28000","21.13811","0.13216"
"125.37600","21.14612","0.13272"
"125.47200","21.15413","0.13305"
"125.56800","21.16209","0.13349"
"125.66400","21.17004","0.13404"
"125.76000","21.17805","0.13381"
"125.85600","21.18606","0.13435"
"125.95200","21.19407","0.13452"
"126.04800","21.20208","0.13460"
"126.14400","21.21004","0.13434"
"126.24000","21.21805","0.13501"
"126.33600","21.22612","0.13584"
"126.43200","21.23407","0.13597"
"126.52800","21.24215","0.13608"
"126.62400","21.25016","0.13636"
"126.72000","21.25805","0.13673"
"126.81600","21.26606","0.13673"
"126.91200","21.27413","0.13728"
"127.00800","21.28214","0.13708"
"127.10400","21.29010","0.13725"
"127.20000","21.29811","0.13800"
"127.29600","21.30606","0.13817"
"127.39200","21.31407","0.13825"
"127.48800","21.32214","0.13828"
"127.58400","21.33010","0.13857"
"127.68000","21.33805","0.13861"
"127.77600","21.34606","0.13901"
"127.87200","21.35407","0.13898"
"127.96800","21.36208","0.13928"
"128.06400","21.37015","0.13954"
"128.16000","21.37811","0.13965"
"128.25600","21.38606","0.13992"
"128.35200","21.39407","0.14008"
"128.44800","21.40208","0.14040"
"128.54400","21.41009","0.14044"
"128.64000","21.41817","0.14081"
"128.73600","21.42612","0.14100"
"128.83200","21.43407","0.14097"
"128.92800","21.44208","0.14121"
"129.02400","21.45015","0.14125"
"129.12000","21.45810","0.14173"
"129.21600","21.46612","0.14175"
"129.31200","21.47407","0.14238"
"129.40800","21.48202","0.14266"
"129.50400","21.49009","0.14270"
"129.60000","21.49810","0.14280"
"129.69600","21.50611","0.14339"
"129.79200","21.51413","0.14390"
"129.88800","21.52208","0.14368"
"129.98400","21.53003","0.14368"
"130.08000","21.53810","0.14458"
"130.17600","21.54611","0.14490"
"130.27200","21.55413","0.14508"
"130.36800","21.56214","0.14540"
"130.46400","21.57003","0.14561"
"130.56000","21.57804","0.14568"
"130.65600","21.58611","0.00536"
"130.75200","21.59413","0.00682"
"130.84800","21.60214","0.00474"
"130.94400","21.61009","0.00854"
"131.04000","21.61804","0.00219"
"131.13600","21.62611","0.00854"
"131.23200","21.63412","0.00683"
"131.32800","21.64214","0.00513"
"131.42400","21.65015","0.00667"
"131.52000","21.65810","0.00686"
"131.61600","21.66605","0.00697"
"131.71200","21.67406","0.00556"
"131.80800","21.68214","0.00625"
"131.90400","21.69015","0.00708"
"132.00000","21.69810","0.00603"
"132.09600","21.70611","0.00618"
"132.19200","21.71406","0.00711"
"132.28800","21.72213","0.00707"
"132.38400","21.73015","0.00706"
"132.48000","21.73810","0.00703"
"132.57600","21.74605","0.00607"
"132.67200","21.75406","0.00690"
"132.76800","21.76208","0.00692"
"132.86400","21.77009","0.00700"
"132.96000","21.77816","0.00704"
"133.05600","21.78611","0.00643"
"133.15200","21.79406","0.00614"
"133.24800","21.80207","0.00618"
"133.34400","21.81009","0.00625"
"133.44000","21.81810","0.00696"
"133.53600","21.82611","0.00731"
"133.63200","21.83406","0.00769"
"133.72800","21.84201","0.00701"
"133.82400","21.85008","0.00684"
"133.92000","21.85816","0.00753"
"134.01600","21.86611","0.00741"
"134.11200","21.87412","0.00695"
"134.20800","21.88207","0.00677"
"134.30400","21.89003","0.00626"
"134.40000","21.89810","0.00668"
"134.49600","21.90617","0.00634"
"134.59200","21.91412","0.00651"
"134.68800","21.92207","0.00649"
"134.78400","21.93008","0.00668"
"134.88000","21.93810","0.00736"
"134.97600","21.94611","0.00671"
"135.07200","21.95412","0.00692"
"135.16800","21.96213","0.00665"
"135.26400","21.97008","0.00676"
"135.36000","21.97810","0.00713"
"135.45600","21.98611","0.00678"
"135.55200","21.99418","0.00676"
"135.64800","22.00213","0.00642"
"135.74400","22.01008","0.00649"
"135.84000","22.01809","0.00678"
"135.93600","22.02604","0.00656"
"136.03200","22.03406","0.00656"
"136.12800","22.04213","0.00678"
"136.22400","22.05008","0.00716"
"136.32000","22.05803","0.00775"
"136.41600","22.06610","0.00639"
"136.51200","22.07412","0.00711"
"136.60800","22.08207","0.00666"
"136.70400","22.09014","0.00681"
"136.80000","22.09815","0.00713"
"136.89600","22.10604","0.00703"
"136.99200","22.11406","0.00698"
"137.08800","22.12213","0.00636"
"137.18400","22.13008","0.00619"
"137.28000","22.13809","0.00636"
"137.37600","22.14610","0.00693"
"137.47200","22.15405","0.00684"
"137.56800","22.16207","0.00660"
"137.66400","22.17014","0.00655"
"137.76000","22.17809","0.00689"
"137.85600","22.18610","0.00655"
"137.95200","22.19405","0.00695"
"138.04800","22.20201","0.00658"
"138.14400","22.21008","0.00718"
"138.24000","22.21815","0.00710"
"138.33600","22.22616","0.00637"
"138.43200","22.23411","0.00607"
"138.52800","22.24207","0.00622"
"138.62400","22.25002","0.00637"
"138.72000","22.25809","0.00673"
"138.81600","22.26610","0.00698"
"138.91200","22.27411","0.00643"
"139.00800","22.28213","0.00753"
"139.10400","22.29008","0.00726"
"139.20000","22.29803","0.00719"
"139.29600","22.30616","0.00674"
"139.39200","22.31417","0.00708"
"139.48800","22.32206","0.00696"
"139.58400","22.33008","0.00665"
"139.68000","22.33809","0.00706"
"139.77600","22.34604","0.00600"
"139.87200","22.35411","0.00568"
"139.96800","22.36212","0.00631"
"140.06400","22.37007","0.00681"
"140.16000","22.37803","0.00720"
"140.25600","22.38610","0.00671"
"140.35200","22.39405","0.00694"
"140.44800","22.40206","0.00687"
"140.54400","22.41013","0.00659"
"140.64000","22.41803","0.00748"
"140.73600","22.42604","0.00679"
"140.83200","22.43411","0.00722"
"140.92800","22.44212","0.00650"
"141.02400","22.45013","0.00580"
"141.12000","22.45815","0.00605"
"141.21600","22.46604","0.00615"
"141.31200","22.47411","0.00706"
"141.40800","22.48212","0.00680"
"141.50400","22.49007","0.00689"
"141.60000","22.49814","0.00735"
"141.69600","22.50616","0.00731"
"141.79200","22.51405","0.00769"
"141.88800","22.52206","0.00680"
"141.98400","22.53013","0.00706"
"142.08000","22.53808","0.00690"
"142.17600","22.54609","0.00674"
"142.27200","22.55404","0.00668"
"142.36800","22.56206","0.00627"
"142.46400","22.57007","0.00679"
"142.56000","22.57808","0.00670"
"142.65600","22.58609","0.00655"
"142.75200","22.59411","0.00669"
"142.84800","22.60206","0.00723"
"142.94400","22.61007","0.00720"
"143.04000","22.61808","0.00696"
"143.13600","22.62615","0.00713"
"143.23200","22.63410","0.00703"
"143.32800","22.64212","0.00667"
"143.42400","22.65013","0.00724"
"143.46600","22.65359","0.00693"