File: Force_trajectories/170122_2/Specimen_RawData_5.csv
End date,"1/22/2017"
Specimen label,"12CG_94"
Maximum Load,"0.94534",N

Time,Extension,Load
(s),(mm),(N)
"0.00000","0.00000","0.00067"
"0.34800","0.02894","0.00270"
"0.69600","0.05818","0.00477"
"1.04400","0.08711","0.00751"
"1.39200","0.11611","0.01006"
"1.74000","0.14517","0.01177"
"2.08800","0.17405","0.01420"
"2.43600","0.20316","0.01659"
"2.78400","0.23210","0.01866"
"3.13200","0.26110","0.02103"
"3.48000","0.29016","0.02216"
"3.82800","0.31910","0.02329"
"4.17600","0.34815","0.02506"
"4.52400","0.37715","0.02633"
"4.87200","0.40609","0.02758"
"5.22000","0.43509","0.02792"
"5.56800","0.46409","0.02978"
"5.91600","0.49314","0.03040"
"6.26400","0.52208","0.02892"
"6.61200","0.55114","0.02972"
"6.96000","0.58008","0.03059"
"7.30800","0.60914","0.03122"
"7.65600","0.63813","0.03183"
"8.00400","0.66707","0.03239"
"8.35200","0.69613","0.03257"
"8.70000","0.72519","0.03378"
"9.04800","0.75407","0.03334"
"9.39600","0.78312","0.03374"
"9.74400","0.81212","0.03429"
"10.09200","0.84106","0.03445"
"10.44000","0.87018","0.03491"
"10.78800","0.89917","0.03488"
"11.13600","0.92805","0.03581"
"11.48400","0.95717","0.03487"
"11.83200","0.98611","0.03565"
"12.18000","1.01517","0.03609"
"12.52800","1.04410","0.03663"
"12.87600","1.07310","0.03652"
"13.22400","1.10216","0.03680"
"13.57200","1.13110","0.03718"
"13.92000","1.16010","0.03723"
"14.26800","1.18915","0.03764"
"14.61600","1.21815","0.03801"
"14.96400","1.24715","0.03817"
"15.31200","1.27615","0.03776"
"15.66000","1.30515","0.03821"
"16.00800","1.33414","0.03890"
"16.35600","1.36314","0.03884"
"16.70400","1.39214","0.03929"
"17.05200","1.42108","0.03945"
"17.40000","1.45014","0.03934"
"17.74800","1.47913","0.03963"
"18.09600","1.50813","0.03971"
"18.44400","1.53713","0.03984"
"18.79200","1.56613","0.04037"
"19.14000","1.59513","0.04048"
"19.48800","1.62412","0.04108"
"19.83600","1.65312","0.04101"
"20.18400","1.68218","0.04116"
"20.53200","1.71118","0.04157"
"20.88000","1.74005","0.04175"
"21.22800","1.76917","0.04194"
"21.57600","1.79811","0.04241"
"21.92400","1.82711","0.04217"
"22.27200","1.85617","0.04305"
"22.62000","1.88510","0.04272"
"22.96800","1.91410","0.04301"
"23.31600","1.94310","0.04317"
"23.66400","1.97216","0.04349"
"24.01200","2.00110","0.04371"
"24.36000","2.03009","0.04435"
"24.70800","2.05915","0.04415"
"25.05600","2.08815","0.04470"
"25.40400","2.11715","0.04508"
"25.75200","2.14609","0.04491"
"26.10000","2.17514","0.04536"
"26.44800","2.20420","0.04423"
"26.79600","2.23308","0.04572"
"27.14400","2.26220","0.04552"
"27.49200","2.29114","0.04577"
"27.84000","2.32007","0.04591"
"28.18800","2.34913","0.04619"
"28.53600","2.37807","0.04650"
"28.88400","2.40713","0.04629"
"29.23200","2.43612","0.04687"
"29.58000","2.46512","0.04724"
"29.92800","2.49412","0.04767"
"30.27600","2.52318","0.04701"
"30.62400","2.55212","0.04702"
"30.97200","2.58111","0.04749"
"31.32000","2.61023","0.04761"
"31.66800","2.63911","0.04826"
"32.01600","2.66811","0.04747"
"32.36400","2.69711","0.04689"
"32.71200","2.72610","0.04808"
"33.06000","2.75516","0.04867"
"33.40800","2.78416","0.04832"
"33.75600","2.81310","0.04860"
"34.10400","2.84216","0.04860"
"34.45200","2.87115","0.04952"
"34.80000","2.90009","0.04949"
"35.14800","2.92915","0.05024"
"35.49600","2.95809","0.04985"
"35.84400","2.98708","0.05018"
"36.19200","3.01614","0.05058"
"36.54000","3.04508","0.05099"
"36.88800","3.07414","0.05085"
"37.23600","3.10320","0.05117"
"37.58400","3.13213","0.05129"
"37.93200","3.16113","0.05168"
"38.28000","3.19013","0.05158"
"38.62800","3.21913","0.05156"
"38.97600","3.24813","0.05206"
"39.32400","3.27712","0.05263"
"39.67200","3.30612","0.05277"
"40.02000","3.33512","0.05297"
"40.36800","3.36406","0.05287"
"40.71600","3.39312","0.05319"
"41.06400","3.42211","0.05351"
"41.41200","3.45111","0.05379"
"41.76000","3.48017","0.05412"
"42.10800","3.50917","0.05320"
"42.45600","3.53805","0.05383"
"42.80400","3.56716","0.05414"
"43.15200","3.59616","0.05443"
"43.50000","3.62510","0.05443"
"43.84800","3.65416","0.05505"
"44.19600","3.68315","0.05509"
"44.54400","3.71215","0.05557"
"44.89200","3.74115","0.05550"
"45.24000","3.77009","0.05623"
"45.58800","3.79909","0.05599"
"45.93600","3.82820","0.05597"
"46.28400","3.85714","0.05590"
"46.63200","3.88614","0.05645"
"46.98000","3.91514","0.05604"
"47.32800","3.94408","0.05569"
"47.67600","3.97313","0.05633"
"48.02400","4.00213","0.05627"
"48.37200","4.03107","0.05651"
"48.72000","4.06013","0.05680"
"49.06800","4.08913","0.05617"
"49.41600","4.11806","0.05608"
"49.76400","4.14712","0.05648"
"50.11200","4.17612","0.05690"
"50.46000","4.20512","0.05696"
"50.80800","4.23418","0.05696"
"51.15600","4.26311","0.05745"
"51.50400","4.29211","0.05788"
"51.85200","4.32117","0.05756"
"52.20000","4.35011","0.05768"
"52.54800","4.37916","0.05828"
"52.89600","4.40810","0.05816"
"53.24400","4.43716","0.05701"
"53.59200","4.46610","0.05718"
"53.94000","4.49516","0.05765"
"54.28800","4.52409","0.05765"
"54.63600","4.55315","0.05815"
"54.98400","4.58221","0.05797"
"55.33200","4.61103","0.05742"
"55.68000","4.64015","0.05817"
"56.02800","4.66914","0.05856"
"56.37600","4.69808","0.05877"
"56.72400","4.72714","0.05923"
"57.07200","4.75608","0.05943"
"57.42000","4.78508","0.05948"
"57.76800","4.81413","0.05988"
"58.11600","4.84313","0.05992"
"58.46400","4.87213","0.06040"
"58.81200","4.90113","0.06052"
"59.16000","4.93013","0.06080"
"59.50800","4.95912","0.06047"
"59.85600","4.98818","0.06063"
"60.20400","5.01706","0.06107"
"60.55200","5.04618","0.06161"
"60.90000","5.07517","0.06142"
"61.24800","5.10411","0.06116"
"61.59600","5.13317","0.06156"
"61.94400","5.16211","0.06167"
"62.29200","5.19111","0.06208"
"62.64000","5.22016","0.06235"
"62.98800","5.24910","0.06199"
"63.33600","5.27804","0.06210"
"63.68400","5.30710","0.06238"
"64.03200","5.33610","0.06261"
"64.38000","5.36509","0.06274"
"64.72800","5.39415","0.06274"
"65.07600","5.42309","0.06263"
"65.42400","5.45215","0.06235"
"65.77200","5.48115","0.06216"
"66.12000","5.51002","0.06257"
"66.46800","5.53914","0.06173"
"66.81600","5.56814","0.06151"
"67.16400","5.59714","0.06177"
"67.51200","5.62614","0.06177"
"67.86000","5.65519","0.06243"
"68.20800","5.68413","0.06269"
"68.55600","5.71313","0.06253"
"68.90400","5.74213","0.06279"
"69.25200","5.77112","0.06295"
"69.60000","5.80012","0.06298"
"69.94800","5.82912","0.06336"
"70.29600","5.85806","0.06319"
"70.64400","5.88712","0.06332"
"70.99200","5.91605","0.06348"
"71.34000","5.94517","0.06360"
"71.68800","5.97411","0.06360"
"72.03600","6.00311","0.06381"
"72.38400","6.03217","0.06388"
"72.73200","6.06116","0.06395"
"73.08000","6.09010","0.06407"
"73.42800","6.11916","0.06440"
"73.77600","6.14816","0.06437"
"74.12400","6.17710","0.06454"
"74.47200","6.20615","0.06455"
"74.82000","6.23509","0.06468"
"75.16800","6.26409","0.06478"
"75.51600","6.29315","0.06475"
"75.86400","6.32215","0.06531"
"76.21200","6.35114","0.06527"
"76.56000","6.38014","0.06538"
"76.90800","6.40908","0.06575"
"77.25600","6.43814","0.06566"
"77.60400","6.46713","0.06627"
"77.95200","6.49607","0.06641"
"78.30000","6.52513","0.06655"
"78.64800","6.55419","0.06650"
"78.99600","6.58301","0.06651"
"79.34400","6.61218","0.06664"
"79.69200","6.64118","0.06714"
"80.04000","6.67012","0.06713"
"80.38800","6.69918","0.06762"
"80.73600","6.72812","0.06725"
"81.08400","6.75711","0.06768"
"81.43200","6.78617","0.06819"
"81.78000","6.81511","0.06849"
"82.12800","6.84417","0.06823"
"82.47600","6.87317","0.06863"
"82.82400","6.90210","0.06879"
"83.17200","6.93104","0.06943"
"83.52000","6.96016","0.06908"
"83.86800","6.98910","0.06959"
"84.21600","7.01816","0.06955"
"84.56400","7.04715","0.06992"
"84.91200","7.07609","0.07008"
"85.26000","7.10515","0.07045"
"85.60800","7.13415","0.07057"
"85.95600","7.16314","0.07121"
"86.30400","7.19220","0.07196"
"86.65200","7.22114","0.07198"
"87.00000","7.25014","0.07226"
"87.34800","7.27914","0.07272"
"87.69600","7.30814","0.07266"
"88.04400","7.33713","0.07328"
"88.39200","7.36613","0.07368"
"88.74000","7.39513","0.07414"
"89.08800","7.42413","0.07505"
"89.43600","7.45312","0.07514"
"89.78400","7.48206","0.07490"
"90.13200","7.51112","0.07587"
"90.48000","7.54018","0.07603"
"90.82800","7.56918","0.07658"
"91.17600","7.59811","0.07655"
"91.52400","7.62711","0.07706"
"91.87200","7.65611","0.07810"
"92.22000","7.68517","0.07752"
"92.56800","7.71417","0.07825"
"92.91600","7.74310","0.07933"
"93.26400","7.77216","0.07971"
"93.61200","7.80110","0.07990"
"93.96000","7.83010","0.08111"
"94.30800","7.85915","0.08184"
"94.65600","7.88803","0.08206"
"95.00400","7.91721","0.08263"
"95.35200","7.94615","0.08322"
"95.70000","7.97509","0.08420"
"96.04800","8.00414","0.08424"
"96.39600","8.03308","0.08436"
"96.74400","8.06208","0.08457"
"97.09200","8.09114","0.08549"
"97.44000","8.12014","0.08616"
"97.78800","8.14913","0.08615"
"98.13600","8.17813","0.08703"
"98.48400","8.20713","0.08762"
"98.83200","8.23613","0.08825"
"99.18000","8.26519","0.08726"
"99.52800","8.29406","0.08692"
"99.87600","8.32318","0.08625"
"100.22400","8.35212","0.08684"
"100.57200","8.38106","0.08789"
"100.92000","8.41012","0.08790"
"101.26800","8.43911","0.08889"
"101.61600","8.46805","0.08848"
"101.96400","8.49717","0.08938"
"102.31200","8.52617","0.09014"
"102.66000","8.55505","0.09087"
"103.00800","8.58416","0.09124"
"103.35600","8.61316","0.09147"
"103.70400","8.64210","0.09234"
"104.05200","8.67122","0.09255"
"104.40000","8.70009","0.09336"
"104.74800","8.72909","0.09390"
"105.09600","8.75815","0.09434"
"105.44400","8.78709","0.09476"
"105.79200","8.81615","0.09507"
"106.14000","8.84514","0.09602"
"106.48800","8.87408","0.09633"
"106.83600","8.90314","0.09671"
"107.18400","8.93220","0.09698"
"107.53200","8.96108","0.09746"
"107.88000","8.99013","0.09799"
"108.22800","9.01913","0.09826"
"108.57600","9.04807","0.09954"
"108.92400","9.07713","0.09868"
"109.27200","9.10613","0.09955"
"109.62000","9.13512","0.10044"
"109.96800","9.16418","0.10056"
"110.31600","9.19312","0.10156"
"110.66400","9.22212","0.10165"
"111.01200","9.25111","0.10256"
"111.36000","9.28011","0.10406"
"111.70800","9.30917","0.10240"
"112.05600","9.33817","0.10327"
"112.40400","9.36705","0.10289"
"112.75200","9.39616","0.09781"
"113.10000","9.42516","0.09552"
"113.44800","9.45410","0.09543"
"113.79600","9.48316","0.09567"
"114.14400","9.51216","0.09513"
"114.49200","9.54109","0.09631"
"114.84000","9.57015","0.09633"
"115.18800","9.59909","0.09597"
"115.53600","9.62809","0.09682"
"115.88400","9.65715","0.09688"
"116.23200","9.68614","0.09784"
"116.58000","9.71514","0.09754"
"116.92800","9.74414","0.09827"
"117.27600","9.77314","0.09945"
"117.62400","9.80208","0.09937"
"117.97200","9.83119","0.09984"
"118.32000","9.86007","0.09946"
"118.66800","9.88919","0.10023"
"119.01600","9.91819","0.10039"
"119.36400","9.94707","0.10011"
"119.71200","9.97618","0.10116"
"120.06000","10.00512","0.10224"
"120.40800","10.03406","0.10277"
"120.75600","10.06318","0.10377"
"121.10400","10.09212","0.10482"
"121.45200","10.12111","0.10454"
"121.80000","10.15011","0.10623"
"122.14800","10.17911","0.10737"
"122.49600","10.20811","0.10787"
"122.84400","10.23716","0.10953"
"123.19200","10.26610","0.11035"
"123.54000","10.29516","0.11053"
"123.88800","10.32410","0.11091"
"124.23600","10.35304","0.11179"
"124.58400","10.38215","0.11240"
"124.93200","10.41115","0.11296"
"125.28000","10.44015","0.11339"
"125.62800","10.46915","0.11392"
"125.97600","10.49815","0.11440"
"126.32400","10.52708","0.11492"
"126.67200","10.55614","0.11508"
"127.02000","10.58514","0.11464"
"127.36800","10.61408","0.11495"
"127.71600","10.64319","0.11539"
"128.06400","10.67213","0.11569"
"128.41200","10.70113","0.11583"
"128.76000","10.73013","0.11608"
"129.10800","10.75907","0.11637"
"129.45600","10.78818","0.11645"
"129.80400","10.81718","0.11662"
"130.15200","10.84612","0.11669"
"130.50000","10.87512","0.11677"
"130.84800","10.90412","0.11706"
"131.19600","10.93311","0.11726"
"131.54400","10.96217","0.11739"
"131.89200","10.99117","0.11760"
"132.24000","11.02011","0.11796"
"132.58800","11.04917","0.11814"
"132.93600","11.07816","0.11870"
"133.28400","11.10716","0.11911"
"133.63200","11.13616","0.11939"
"133.98000","11.16516","0.11977"
"134.32800","11.19415","0.12092"
"134.67600","11.22309","0.12153"
"135.02400","11.25209","0.12276"
"135.37200","11.28109","0.12387"
"135.72000","11.31009","0.12454"
"136.06800","11.33909","0.12539"
"136.41600","11.36814","0.12646"
"136.76400","11.39720","0.12862"
"137.11200","11.42608","0.12991"
"137.46000","11.45514","0.13076"
"137.80800","11.48413","0.13212"
"138.15600","11.51313","0.13353"
"138.50400","11.54219","0.13453"
"138.85200","11.57107","0.13516"
"139.20000","11.60013","0.13667"
"139.54800","11.62912","0.13783"
"139.89600","11.65812","0.13896"
"140.24400","11.68712","0.14001"
"140.59200","11.71612","0.14127"
"140.94000","11.74512","0.14187"
"141.28800","11.77411","0.14262"
"141.63600","11.80311","0.14365"
"141.98400","11.83211","0.14468"
"142.33200","11.86117","0.14551"
"142.68000","11.89017","0.14607"
"143.02800","11.91910","0.14732"
"143.37600","11.94816","0.14767"
"143.72400","11.97710","0.14858"
"144.07200","12.00616","0.14892"
"144.42000","12.03515","0.14991"
"144.76800","12.06415","0.15044"
"145.11600","12.09309","0.15097"
"145.46400","12.12215","0.15137"
"145.81200","12.15115","0.15181"
"146.16000","12.18008","0.15166"
"146.50800","12.20920","0.15260"
"146.85600","12.23808","0.15293"
"147.20400","12.26714","0.15323"
"147.55200","12.29620","0.15389"
"147.90000","12.32507","0.15469"
"148.24800","12.35419","0.15556"
"148.59600","12.38313","0.15506"
"148.94400","12.41213","0.15598"
"149.29200","12.44118","0.15655"
"149.64000","12.47012","0.15717"
"149.98800","12.49912","0.15852"
"150.33600","12.52812","0.15909"
"150.68400","12.55712","0.15945"
"151.03200","12.58617","0.15985"
"151.38000","12.61511","0.16135"
"151.72800","12.64411","0.16172"
"152.07600","12.67311","0.16240"
"152.42400","12.70217","0.16298"
"152.77200","12.73110","0.16369"
"153.12000","12.76016","0.16412"
"153.46800","12.78916","0.16469"
"153.81600","12.81804","0.16526"
"154.16400","12.84710","0.16596"
"154.51200","12.87615","0.16644"
"154.86000","12.90509","0.16714"
"155.20800","12.93415","0.16712"
"155.55600","12.96315","0.16780"
"155.90400","12.99209","0.16830"
"156.25200","13.02114","0.16947"
"156.60000","13.05008","0.17062"
"156.94800","13.07914","0.17114"
"157.29600","13.10814","0.17226"
"157.64400","13.13714","0.17356"
"157.99200","13.16613","0.17447"
"158.34000","13.19513","0.17626"
"158.68800","13.22407","0.17830"
"159.03600","13.25313","0.17999"
"159.38400","13.28213","0.18152"
"159.73200","13.31112","0.18340"
"160.08000","13.34012","0.18481"
"160.42800","13.36918","0.18763"
"160.77600","13.39812","0.19016"
"161.12400","13.42712","0.19354"
"161.47200","13.45617","0.19667"
"161.82000","13.48511","0.19879"
"162.16800","13.51411","0.20157"
"162.51600","13.54317","0.20489"
"162.86400","13.57210","0.20739"
"163.21200","13.60116","0.21053"
"163.56000","13.63010","0.21189"
"163.90800","13.65916","0.21401"
"164.25600","13.68816","0.21473"
"164.60400","13.71709","0.21564"
"164.95200","13.74615","0.21691"
"165.30000","13.77515","0.21803"
"165.64800","13.80409","0.21893"
"165.99600","13.83315","0.21973"
"166.34400","13.86214","0.22028"
"166.69200","13.89108","0.22064"
"167.04000","13.92020","0.22133"
"167.38800","13.94914","0.22225"
"167.73600","13.97814","0.22330"
"168.08400","14.00713","0.22414"
"168.43200","14.03613","0.22581"
"168.78000","14.06519","0.22741"
"169.12800","14.09413","0.22994"
"169.47600","14.12313","0.23148"
"169.82400","14.15212","0.23291"
"170.17200","14.18112","0.23449"
"170.52000","14.21012","0.23690"
"170.86800","14.23912","0.23880"
"171.21600","14.26817","0.24051"
"171.56400","14.29705","0.24272"
"171.91200","14.32617","0.24427"
"172.26000","14.35517","0.24603"
"172.60800","14.38411","0.24841"
"172.95600","14.41317","0.24970"
"173.30400","14.44210","0.25109"
"173.65200","14.47110","0.25278"
"174.00000","14.50016","0.25457"
"174.34800","14.52910","0.25619"
"174.69600","14.55809","0.25761"
"175.04400","14.58709","0.25923"
"175.39200","14.61609","0.26040"
"175.74000","14.64515","0.26125"
"176.08800","14.67421","0.26272"
"176.43600","14.70308","0.26308"
"176.78400","14.73214","0.26388"
"177.13200","14.76114","0.26442"
"177.48000","14.79008","0.26493"
"177.82800","14.81907","0.26548"
"178.17600","14.84813","0.26582"
"178.52400","14.87713","0.26603"
"178.87200","14.90613","0.26640"
"179.22000","14.93513","0.26706"
"179.56800","14.96412","0.26737"
"179.91600","14.99312","0.26780"
"180.26400","15.02212","0.26833"
"180.61200","15.05112","0.26908"
"180.96000","15.08018","0.26953"
"181.30800","15.10905","0.27010"
"181.65600","15.13811","0.27110"
"182.00400","15.16717","0.27158"
"182.35200","15.19605","0.27304"
"182.70000","15.22517","0.27403"
"183.04800","15.25410","0.27548"
"183.39600","15.28310","0.27627"
"183.74400","15.31216","0.27765"
"184.09200","15.34110","0.27981"
"184.44000","15.37010","0.28196"
"184.78800","15.39915","0.28001"
"185.13600","15.42815","0.28274"
"185.48400","15.45715","0.28475"
"185.83200","15.48615","0.28674"
"186.18000","15.51509","0.28906"
"186.52800","15.54408","0.29222"
"186.87600","15.57314","0.29344"
"187.22400","15.60208","0.29598"
"187.57200","15.63120","0.29868"
"187.92000","15.66013","0.30046"
"188.26800","15.68913","0.30275"
"188.61600","15.71813","0.30539"
"188.96400","15.74713","0.30803"
"189.31200","15.77607","0.30990"
"189.66000","15.80512","0.31155"
"190.00800","15.83418","0.31274"
"190.35600","15.86312","0.31382"
"190.70400","15.89218","0.31485"
"191.05200","15.92112","0.31575"
"191.40000","15.95011","0.31683"
"191.74800","15.97917","0.31821"
"192.09600","16.00805","0.32017"
"192.44400","16.03717","0.32295"
"192.79200","16.06610","0.32664"
"193.14000","16.09510","0.32894"
"193.48800","16.12416","0.33329"
"193.83600","16.15316","0.33655"
"194.18400","16.18210","0.34139"
"194.53200","16.21115","0.33567"
"194.88000","16.24015","0.34098"
"195.22800","16.26909","0.34535"
"195.57600","16.29815","0.34886"
"195.92400","16.32709","0.35267"
"196.27200","16.35608","0.35541"
"196.62000","16.38520","0.35811"
"196.96800","16.41414","0.35924"
"197.31600","16.44314","0.36146"
"197.66400","16.47214","0.36346"
"198.01200","16.50113","0.36582"
"198.36000","16.53013","0.36072"
"198.70800","16.55919","0.36332"
"199.05600","16.58813","0.36595"
"199.40400","16.61712","0.36786"
"199.75200","16.64618","0.36045"
"200.10000","16.67506","0.36383"
"200.44800","16.70418","0.36098"
"200.79600","16.73318","0.36365"
"201.14400","16.76212","0.36591"
"201.49200","16.79117","0.36762"
"201.84000","16.82011","0.36986"
"202.18800","16.84911","0.37068"
"202.53600","16.87811","0.37212"
"202.88400","16.90710","0.37267"
"203.23200","16.93616","0.37370"
"203.58000","16.96510","0.37420"
"203.92800","16.99416","0.37460"
"204.27600","17.02310","0.37498"
"204.62400","17.05215","0.37555"
"204.97200","17.08109","0.37656"
"205.32000","17.11015","0.37718"
"205.66800","17.13915","0.37761"
"206.01600","17.16809","0.37866"
"206.36400","17.19714","0.37873"
"206.71200","17.22614","0.37991"
"207.06000","17.25508","0.38124"
"207.40800","17.28420","0.38197"
"207.75600","17.31314","0.38383"
"208.10400","17.34207","0.38490"
"208.45200","17.37113","0.38622"
"208.80000","17.40013","0.38835"
"209.14800","17.42913","0.39060"
"209.49600","17.45812","0.37851"
"209.84400","17.48712","0.37540"
"210.19200","17.51612","0.37621"
"210.54000","17.54518","0.37722"
"210.88800","17.57406","0.37834"
"211.23600","17.60317","0.38008"
"211.58400","17.63217","0.38109"
"211.93200","17.66111","0.38247"
"212.28000","17.69011","0.38450"
"212.62800","17.71911","0.38609"
"212.97600","17.74816","0.38823"
"213.32400","17.77716","0.38723"
"213.67200","17.80616","0.38978"
"214.02000","17.83510","0.39256"
"214.36800","17.86416","0.39595"
"214.71600","17.89315","0.39871"
"215.06400","17.92209","0.40312"
"215.41200","17.95115","0.40683"
"215.76000","17.98009","0.41005"
"216.10800","18.00915","0.41415"
"216.45600","18.03814","0.41729"
"216.80400","18.06708","0.41988"
"217.15200","18.09614","0.42116"
"217.50000","18.12514","0.42238"
"217.84800","18.15408","0.42366"
"218.19600","18.18313","0.42473"
"218.54400","18.21219","0.42579"
"218.89200","18.24107","0.42703"
"219.24000","18.27013","0.42587"
"219.58800","18.29913","0.37509"
"219.93600","18.32806","0.37536"
"220.28400","18.35718","0.37070"
"220.63200","18.38612","0.37333"
"220.98000","18.41512","0.37481"
"221.32800","18.44411","0.37620"
"221.67600","18.47311","0.37750"
"222.02400","18.50211","0.37920"
"222.37200","18.53111","0.38178"
"222.72000","18.56011","0.38408"
"223.06800","18.58916","0.38657"
"223.41600","18.61816","0.38939"
"223.76400","18.64710","0.39416"
"224.11200","18.67616","0.39968"
"224.46000","18.70516","0.40489"
"224.80800","18.73409","0.40442"
"225.15600","18.76321","0.41027"
"225.50400","18.79209","0.41506"
"225.85200","18.82109","0.41876"
"226.20000","18.85015","0.42139"
"226.54800","18.87914","0.40455"
"226.89600","18.90814","0.40374"
"227.24400","18.93714","0.40941"
"227.59200","18.96614","0.41413"
"227.94000","18.99513","0.41733"
"228.28800","19.02413","0.42041"
"228.63600","19.05313","0.42245"
"228.98400","19.08213","0.42352"
"229.33200","19.11119","0.42497"
"229.68000","19.14006","0.42765"
"230.02800","19.16918","0.42985"
"230.37600","19.19812","0.43287"
"230.72400","19.22712","0.43617"
"231.07200","19.25618","0.43882"
"231.42000","19.28511","0.44227"
"231.76800","19.31411","0.44577"
"232.11600","19.34317","0.44850"
"232.46400","19.37217","0.45100"
"232.81200","19.40111","0.45367"
"233.16000","19.43016","0.45545"
"233.50800","19.45910","0.45782"
"233.85600","19.48810","0.45965"
"234.20400","19.51710","0.46086"
"234.55200","19.54609","0.46184"
"234.90000","19.57515","0.46260"
"235.24800","19.60409","0.46372"
"235.59600","19.63303","0.46487"
"235.94400","19.66215","0.46601"
"236.29200","19.69109","0.46630"
"236.64000","19.72014","0.41097"
"236.98800","19.74914","0.41422"
"237.33600","19.77814","0.41848"
"237.68400","19.80707","0.42123"
"238.03200","19.83614","0.42332"
"238.38000","19.86513","0.42538"
"238.72800","19.89407","0.42851"
"239.07600","19.92313","0.43226"
"239.42400","19.95213","0.43764"
"239.77200","19.98112","0.44104"
"240.12000","20.01018","0.44513"
"240.46800","20.03906","0.44872"
"240.81600","20.06818","0.45218"
"241.16400","20.09718","0.45378"
"241.51200","20.12611","0.45653"
"241.86000","20.15517","0.45824"
"242.20800","20.18411","0.46033"
"242.55600","20.21311","0.46135"
"242.90400","20.24217","0.46266"
"243.25200","20.27116","0.46384"
"243.60000","20.30010","0.46511"
"243.94800","20.32916","0.46699"
"244.29600","20.35810","0.46984"
"244.64400","20.38715","0.47178"
"244.99200","20.41615","0.47214"
"245.34000","20.44503","0.47502"
"245.68800","20.47415","0.47759"
"246.03600","20.50321","0.48081"
"246.38400","20.53214","0.48243"
"246.73200","20.56114","0.48528"
"247.08000","20.59014","0.48910"
"247.42800","20.61908","0.49074"
"247.77600","20.64814","0.49176"
"248.12400","20.67719","0.49474"
"248.47200","20.70607","0.49850"
"248.82000","20.73519","0.50233"
"249.16800","20.76413","0.50449"
"249.51600","20.79306","0.50779"
"249.86400","20.82212","0.51067"
"250.21200","20.85112","0.51352"
"250.56000","20.88018","0.51536"
"250.90800","20.90911","0.51824"
"251.25600","20.93812","0.52042"
"251.60400","20.96711","0.52267"
"251.95200","20.99617","0.52342"
"252.30000","21.02511","0.52373"
"252.64800","21.05411","0.52474"
"252.99600","21.08316","0.52507"
"253.34400","21.11204","0.52669"
"253.69200","21.14116","0.52936"
"254.04000","21.17010","0.53180"
"254.38800","21.19910","0.53544"
"254.73600","21.22816","0.54131"
"255.08400","21.25715","0.54557"
"255.43200","21.28609","0.54917"
"255.78000","21.31515","0.55319"
"256.12800","21.34414","0.53515"
"256.47600","21.37308","0.53996"
"256.82400","21.40214","0.54520"
"257.17200","21.43114","0.54972"
"257.52000","21.46014","0.55389"
"257.86800","21.48919","0.55752"
"258.21600","21.51807","0.56127"
"258.56400","21.54713","0.56491"
"258.91200","21.57619","0.56737"
"259.26000","21.60513","0.56996"
"259.60800","21.63412","0.57221"
"259.95600","21.66312","0.57439"
"260.30400","21.69212","0.57615"
"260.65200","21.72118","0.57796"
"261.00000","21.75012","0.57940"
"261.34800","21.77911","0.58134"
"261.69600","21.80811","0.58322"
"262.04400","21.83717","0.58444"
"262.39200","21.86611","0.58591"
"262.74000","21.89517","0.58643"
"263.08800","21.92410","0.58715"
"263.43600","21.95316","0.58814"
"263.78400","21.98222","0.58967"
"264.13200","22.01104","0.59107"
"264.48000","22.04016","0.59343"
"264.82800","22.06915","0.59575"
"265.17600","22.09809","0.59830"
"265.52400","22.12709","0.60208"
"265.87200","22.15615","0.60800"
"266.22000","22.18515","0.61243"
"266.56800","22.21414","0.61678"
"266.91600","22.24308","0.62065"
"267.26400","22.27214","0.62291"
"267.61200","22.30114","0.62454"
"267.96000","22.33008","0.62516"
"268.30800","22.35913","0.32221"
"268.65600","22.38813","0.32327"
"269.00400","22.41707","0.34184"
"269.35200","22.44619","0.33359"
"269.70000","22.47512","0.35424"
"270.04800","22.50412","0.34576"
"270.39600","22.53312","0.36041"
"270.74400","22.56212","0.35699"
"271.09200","22.59106","0.36923"
"271.44000","22.62011","0.36817"
"271.78800","22.64917","0.37224"
"272.13600","22.67811","0.37244"
"272.48400","22.70711","0.37408"
"272.83200","22.73617","0.37554"
"273.18000","22.76510","0.37665"
"273.52800","22.79416","0.37720"
"273.87600","22.82310","0.37725"
"274.22400","22.85216","0.37921"
"274.57200","22.88115","0.38059"
"274.92000","22.91009","0.38149"
"275.26800","22.93915","0.35628"
"275.61600","22.96815","0.36004"
"275.96400","22.99709","0.36463"
"276.31200","23.02615","0.36798"
"276.66000","23.05514","0.37040"
"277.00800","23.08402","0.37179"
"277.35600","23.11314","0.37313"
"277.70400","23.14208","0.37405"
"278.05200","23.17114","0.37490"
"278.40000","23.20013","0.37574"
"278.74800","23.22913","0.37672"
"279.09600","23.25813","0.37783"
"279.44400","23.28713","0.37964"
"279.79200","23.31612","0.38116"
"280.14000","23.34518","0.38308"
"280.48800","23.37412","0.38478"
"280.83600","23.40312","0.38715"
"281.18400","23.43212","0.38999"
"281.53200","23.46117","0.39354"
"281.88000","23.49011","0.39910"
"282.22800","23.51917","0.40433"
"282.57600","23.54817","0.40948"
"282.92400","23.57710","0.41319"
"283.27200","23.60616","0.41700"
"283.62000","23.63510","0.41990"
"283.96800","23.66410","0.42207"
"284.31600","23.69316","0.42428"
"284.66400","23.72209","0.42626"
"285.01200","23.75115","0.42800"
"285.36000","23.78015","0.43169"
"285.70800","23.80915","0.43620"
"286.05600","23.83815","0.44142"
"286.40400","23.86714","0.44620"
"286.75200","23.89608","0.44829"
"287.10000","23.92514","0.45117"
"287.44800","23.95414","0.45405"
"287.79600","23.98308","0.45707"
"288.14400","24.01213","0.45988"
"288.49200","24.04113","0.46128"
"288.84000","24.07013","0.46246"
"289.18800","24.09913","0.46403"
"289.53600","24.12813","0.46584"
"289.88400","24.15713","0.46876"
"290.23200","24.18612","0.47085"
"290.58000","24.21518","0.47412"
"290.92800","24.24412","0.47753"
"291.27600","24.27312","0.48102"
"291.62400","24.30211","0.48454"
"291.97200","24.33111","0.48875"
"292.32000","24.36017","0.49334"
"292.66800","24.38905","0.49905"
"293.01600","24.41816","0.50356"
"293.36400","24.44716","0.50688"
"293.71200","24.47610","0.51087"
"294.06000","24.50516","0.51590"
"294.40800","24.53410","0.51891"
"294.75600","24.56310","0.52178"
"295.10400","24.59215","0.52368"
"295.45200","24.62115","0.52416"
"295.80000","24.65015","0.52565"
"296.14800","24.67914","0.52754"
"296.49600","24.70808","0.53189"
"296.84400","24.73714","0.53889"
"297.19200","24.76620","0.52939"
"297.54000","24.79508","0.53244"
"297.88800","24.82413","0.53875"
"298.23600","24.85319","0.54501"
"298.58400","24.88207","0.54989"
"298.93200","24.91113","0.55574"
"299.28000","24.94013","0.56146"
"299.62800","24.96906","0.56494"
"299.97600","24.99818","0.56825"
"300.32400","25.02718","0.57180"
"300.67200","25.05612","0.57429"
"301.02000","25.08512","0.57688"
"301.36800","25.11418","0.57923"
"301.71600","25.14311","0.58176"
"302.06400","25.17217","0.58368"
"302.41200","25.20111","0.58556"
"302.76000","25.23011","0.58672"
"303.10800","25.25916","0.58806"
"303.45600","25.28816","0.58998"
"303.80400","25.31716","0.59307"
"304.15200","25.34616","0.59564"
"304.50000","25.37510","0.58590"
"304.84800","25.40409","0.58776"
"305.19600","25.43321","0.58863"
"305.54400","25.46209","0.59098"
"305.89200","25.49115","0.59345"
"306.24000","25.52015","0.59588"
"306.58800","25.54914","0.59943"
"306.93600","25.57814","0.60472"
"307.28400","25.60708","0.61064"
"307.63200","25.63608","0.61710"
"307.98000","25.66514","0.62224"
"308.32800","25.69407","0.62583"
"308.67600","25.72313","0.62884"
"309.02400","25.75213","0.63187"
"309.37200","25.78113","0.63513"
"309.72000","25.81012","0.63982"
"310.06800","25.83918","0.64579"
"310.41600","25.86806","0.65152"
"310.76400","25.89712","0.65686"
"311.11200","25.92618","0.66072"
"311.46000","25.95506","0.66484"
"311.80800","25.98417","0.66889"
"312.15600","26.01311","0.67107"
"312.50400","26.04211","0.67289"
"312.85200","26.07117","0.67402"
"313.20000","26.10010","0.67500"
"313.54800","26.12910","0.67586"
"313.89600","26.15810","0.67651"
"314.24400","26.18710","0.67789"
"314.59200","26.21615","0.67972"
"314.94000","26.24516","0.68157"
"315.28800","26.27415","0.68335"
"315.63600","26.30309","0.68594"
"315.98400","26.33215","0.68873"
"316.33200","26.36115","0.69270"
"316.68000","26.39014","0.69754"
"317.02800","26.41920","0.70219"
"317.37600","26.44808","0.70581"
"317.72400","26.47714","0.71074"
"318.07200","26.50614","0.71463"
"318.42000","26.53513","0.71987"
"318.76800","26.56413","0.72576"
"319.11600","26.59313","0.73016"
"319.46400","26.62213","0.73295"
"319.81200","26.65112","0.73408"
"320.16000","26.68006","0.73533"
"320.50800","26.70912","0.73596"
"320.85600","26.73818","0.73802"
"321.20400","26.76712","0.74150"
"321.55200","26.79612","0.74686"
"321.90000","26.82511","0.75161"
"322.24800","26.85405","0.75781"
"322.59600","26.88317","0.76137"
"322.94400","26.91211","0.76675"
"323.29200","26.94110","0.77067"
"323.64000","26.97022","0.77480"
"323.98800","26.99910","0.77811"
"324.33600","27.02810","0.78072"
"324.68400","27.05710","0.78289"
"325.03200","27.08615","0.78562"
"325.38000","27.11509","0.78736"
"325.72800","27.14415","0.78880"
"326.07600","27.17315","0.79032"
"326.42400","27.20209","0.79199"
"326.77200","27.23114","0.79432"
"327.12000","27.26008","0.79793"
"327.46800","27.28914","0.80187"
"327.81600","27.31820","0.80538"
"328.16400","27.34708","0.80929"
"328.51200","27.37613","0.81439"
"328.86000","27.40513","0.81813"
"329.20800","27.43407","0.82200"
"329.55600","27.46313","0.82496"
"329.90400","27.49212","0.82701"
"330.25200","27.52112","0.82949"
"330.60000","27.55012","0.83293"
"330.94800","27.57912","0.83799"
"331.29600","27.60812","0.84343"
"331.64400","27.63711","0.85050"
"331.99200","27.66611","0.85802"
"332.34000","27.69517","0.86319"
"332.68800","27.72411","0.86894"
"333.03600","27.75305","0.87318"
"333.38400","27.78210","0.87911"
"333.73200","27.81110","0.88291"
"334.08000","27.84010","0.88554"
"334.42800","27.86916","0.88716"
"334.77600","27.89816","0.88808"
"335.12400","27.92710","0.88850"
"335.47200","27.95615","0.88923"
"335.82000","27.98515","0.89064"
"336.16800","28.01409","0.89277"
"336.51600","28.04320","0.89464"
"336.86400","28.07208","0.89687"
"337.21200","28.10114","0.89864"
"337.56000","28.13014","0.90180"
"337.90800","28.15908","0.90489"
"338.25600","28.18819","0.90916"
"338.60400","28.21713","0.91254"
"338.95200","28.24613","0.91651"
"339.30000","28.27519","0.92032"
"339.64800","28.30419","0.92527"
"339.99600","28.33307","0.93060"
"340.34400","28.36212","0.93411"
"340.69200","28.39112","0.93734"
"341.04000","28.42012","0.93893"
"341.38800","28.44911","0.94062"
"341.73600","28.47811","0.94275"
"342.08400","28.50711","0.94444"
"342.43200","28.53617","0.94395"
"342.78000","28.56517","0.33533"
"343.12800","28.59411","0.26793"
"343.47600","28.62310","0.26937"
"343.82400","28.65216","0.26873"
"344.17200","28.68116","0.27067"
"344.52000","28.71016","0.26914"
"344.86800","28.73910","0.27016"
"345.21600","28.76809","0.27032"
"345.56400","28.79715","0.27084"
"345.91200","28.82603","0.27101"
"346.26000","28.85521","0.27155"
"346.60800","28.88415","0.27354"
"346.95600","28.91308","0.27414"
"347.30400","28.94220","0.27567"
"347.65200","28.97114","0.27702"
"348.00000","29.00008","0.27928"
"348.34800","29.02919","0.27916"
"348.69600","29.05813","0.28119"
"349.04400","29.08713","0.28235"
"349.39200","29.11613","0.28609"
"349.74000","29.14512","0.28605"
"350.08800","29.17406","0.28905"
"350.43600","29.20318","0.27132"
"350.78400","29.23212","0.27221"
"351.13200","29.26118","0.27165"
"351.48000","29.29012","0.27278"
"351.82800","29.31906","0.27385"
"352.17600","29.34817","0.27600"
"352.52400","29.37711","0.27741"
"352.87200","29.40611","0.27991"
"353.22000","29.43517","0.28216"
"353.56800","29.46416","0.28458"
"353.91600","29.49310","0.28750"
"354.26400","29.52216","0.29097"
"354.61200","29.55110","0.29303"
"354.96000","29.58009","0.29368"
"355.30800","29.60921","0.29492"
"355.65600","29.63809","0.29751"
"356.00400","29.66715","0.29933"
"356.35200","29.69615","0.30265"
"356.70000","29.72509","0.30505"
"357.04800","29.75420","0.30822"
"357.39600","29.78314","0.31100"
"357.74400","29.81214","0.30348"
"358.09200","29.84114","0.30322"
"358.44000","29.87013","0.30481"
"358.78800","29.89907","0.30992"
"359.13600","29.92813","0.31092"
"359.48400","29.95713","0.31380"
"359.83200","29.98613","0.31309"
"360.18000","30.01512","0.31486"
"360.52800","30.04412","0.31455"
"360.87600","30.07312","0.31603"
"361.22400","30.10218","0.31668"
"361.57200","30.13106","0.31897"
"361.92000","30.16017","0.32050"
"362.26800","30.18917","0.32414"
"362.61600","30.21811","0.32770"
"362.96400","30.24711","0.31468"
"363.31200","30.27610","0.31458"
"363.66000","30.30511","0.31560"
"364.00800","30.33416","0.31757"
"364.35600","30.36316","0.31949"
"364.70400","30.39204","0.32221"
"365.05200","30.42115","0.32528"
"365.40000","30.45009","0.32872"
"365.74800","30.47909","0.33259"
"366.09600","30.50815","0.33794"
"366.44400","30.53709","0.34115"
"366.79200","30.56614","0.34434"
"367.14000","30.59514","0.34685"
"367.48800","30.62414","0.35106"
"367.83600","30.65308","0.35465"
"368.18400","30.68213","0.35869"
"368.53200","30.71107","0.36318"
"368.88000","30.74013","0.36693"
"369.22800","30.76919","0.36937"
"369.57600","30.79807","0.37093"
"369.92400","30.82719","0.37251"
"370.27200","30.85618","0.37287"
"370.62000","30.88506","0.37355"
"370.96800","30.91412","0.37397"
"371.31600","30.94312","0.37472"
"371.66400","30.97212","0.37546"
"372.01200","31.00117","0.37630"
"372.36000","31.03011","0.37737"
"372.70800","31.05917","0.37904"
"373.05600","31.08811","0.37938"
"373.40400","31.11711","0.38063"
"373.75200","31.14610","0.38160"
"374.10000","31.17516","0.38260"
"374.44800","31.20410","0.38436"
"374.79600","31.23316","0.38626"
"375.14400","31.26215","0.38854"
"375.49200","31.29109","0.39070"
"375.84000","31.32015","0.39106"
"376.18800","31.34908","0.39206"
"376.53600","31.37814","0.39417"
"376.88400","31.40714","0.39722"
"377.23200","31.43614","0.40147"
"377.58000","31.46514","0.40584"
"377.92800","31.49414","0.41115"
"378.27600","31.52313","0.41488"
"378.62400","31.55207","0.41691"
"378.97200","31.58119","0.41933"
"379.32000","31.61007","0.42131"
"379.66800","31.63913","0.42307"
"380.01600","31.66818","0.42509"
"380.36400","31.69706","0.42682"
"380.71200","31.72618","0.42798"
"381.06000","31.75517","0.43130"
"381.40800","31.78411","0.43489"
"381.75600","31.81311","0.43972"
"382.10400","31.84211","0.44296"
"382.45200","31.87111","0.44558"
"382.80000","31.90017","0.44855"
"383.14800","31.92916","0.45086"
"383.49600","31.95816","0.45444"
"383.84400","31.98716","0.45663"
"384.19200","32.01610","0.45817"
"384.54000","32.04510","0.45911"
"384.88800","32.07415","0.46046"
"385.23600","32.10309","0.46187"
"385.58400","32.13215","0.46276"
"385.93200","32.16109","0.46390"
"386.28000","32.19009","0.46495"
"386.62800","32.21915","0.46629"
"386.97600","32.24814","0.46916"
"387.32400","32.27708","0.47219"
"387.67200","32.30614","0.47419"
"388.02000","32.33514","0.47580"
"388.36800","32.36413","0.47921"
"388.71600","32.39313","0.48212"
"389.06400","32.42213","0.48459"
"389.41200","32.45113","0.48770"
"389.76000","32.48018","0.49107"
"390.10800","32.50912","0.49581"
"390.45600","32.53818","0.50037"
"390.80400","32.56706","0.50322"
"391.15200","32.59605","0.50563"
"391.50000","32.62518","0.50949"
"391.84800","32.65417","0.51249"
"392.19600","32.68305","0.51548"
"392.54400","32.71217","0.51837"
"392.89200","32.74123","0.52128"
"393.24000","32.77010","0.52307"
"393.58800","32.79916","0.52369"
"393.93600","32.82816","0.52469"
"394.28400","32.85704","0.52587"
"394.63200","32.88615","0.52799"
"394.98000","32.91509","0.52933"
"395.32800","32.94415","0.53412"
"395.67600","32.97315","0.54024"
"396.02400","33.00209","0.54380"
"396.37200","33.03115","0.54857"
"396.72000","33.06015","0.55339"
"397.06800","33.08914","0.55666"
"397.41600","33.11814","0.56031"
"397.76400","33.14714","0.56465"
"398.11200","33.17607","0.56792"
"398.46000","33.20513","0.57088"
"398.80800","33.23413","0.57271"
"399.15600","33.26307","0.57579"
"399.50400","33.29219","0.57803"
"399.85200","33.32113","0.57913"
"400.20000","33.35012","0.58136"
"400.54800","33.37912","0.54013"
"400.89600","33.40812","0.49066"
"401.24400","33.43712","0.48820"
"401.59200","33.46611","0.49054"
"401.94000","33.49517","0.49567"
"402.28800","33.52411","0.49858"
"402.63600","33.55311","0.50224"
"402.98400","33.58211","0.50727"
"403.33200","33.61110","0.51133"
"403.68000","33.64016","0.51429"
"404.02800","33.66904","0.51780"
"404.37600","33.69822","0.52155"
"404.72400","33.72715","0.52297"
"405.07200","33.75609","0.52406"
"405.42000","33.78515","0.52508"
"405.76800","33.81409","0.52707"
"406.11600","33.84309","0.53050"
"406.46400","33.87215","0.53441"
"406.81200","33.90114","0.53963"
"407.16000","33.93008","0.54725"
"407.50800","33.95914","0.55291"
"407.85600","33.98814","0.55753"
"408.20400","34.01707","0.56354"
"408.55200","34.04613","0.56726"
"408.90000","34.07507","0.57022"
"409.24800","34.10413","0.57307"
"409.59600","34.13313","0.57601"
"409.94400","34.16206","0.57825"
"410.29200","34.19112","0.58035"
"410.64000","34.22012","0.58197"
"410.98800","34.24912","0.58409"
"411.33600","34.27818","0.58556"
"411.68400","34.30717","0.58684"
"412.03200","34.33605","0.58801"
"412.38000","34.36511","0.58955"
"412.72800","34.39411","0.59190"
"413.07600","34.42311","0.59483"
"413.42400","34.45216","0.59880"
"413.77200","34.48104","0.60333"
"414.12000","34.51016","0.60915"
"414.46800","34.53915","0.61560"
"414.81600","34.56804","0.62232"
"415.16400","34.59716","0.62584"
"415.51200","34.62615","0.62803"
"415.86000","34.65515","0.63144"
"416.20800","34.68415","0.63391"
"416.55600","34.71309","0.63687"
"416.90400","34.74208","0.64111"
"417.25200","34.77114","0.64650"
"417.60000","34.80014","0.65311"
"417.94800","34.82914","0.65813"
"418.29600","34.85819","0.66205"
"418.64400","34.88707","0.66518"
"418.99200","34.91607","0.66841"
"419.34000","34.94513","0.67115"
"419.68800","34.97406","0.67297"
"420.03600","35.00312","0.67411"
"420.38400","35.03218","0.67483"
"420.73200","35.06106","0.67566"
"421.08000","35.09012","0.67668"
"421.42800","35.11917","0.67794"
"421.77600","35.14811","0.67949"
"422.12400","35.17711","0.68185"
"422.47200","35.20617","0.68335"
"422.82000","35.23511","0.68535"
"423.16800","35.26416","0.68878"
"423.51600","35.29310","0.69228"
"423.86400","35.32210","0.69727"
"424.21200","35.35116","0.70097"
"424.56000","35.38010","0.70572"
"424.90800","35.40916","0.70947"
"425.25600","35.43810","0.71441"
"425.60400","35.46715","0.71915"
"425.95200","35.49615","0.72365"
"426.30000","35.52515","0.72923"
"426.64800","35.55415","0.73236"
"426.99600","35.58314","0.73419"
"427.34400","35.61220","0.73534"
"427.69200","35.64108","0.73608"
"428.04000","35.67014","0.73831"
"428.38800","35.69913","0.46215"
"428.73600","35.72807","0.47033"
"429.08400","35.75719","0.46551"
"429.43200","35.78613","0.47110"
"429.78000","35.81513","0.46953"
"430.12800","35.84412","0.46456"
"430.47600","35.87312","0.48053"
"430.82400","35.90212","0.48892"
"431.17200","35.93112","0.47887"
"431.52000","35.96012","0.49408"
"431.86800","35.98917","0.49823"
"432.21600","36.01817","0.49338"
"432.56400","36.04711","0.51390"
"432.91200","36.07616","0.51695"
"433.26000","36.10510","0.51101"
"433.60800","36.13410","0.51919"
"433.95600","36.16316","0.52477"
"434.30400","36.19216","0.52543"
"434.65200","36.22116","0.52454"
"435.00000","36.25010","0.52941"
"435.34800","36.27909","0.53916"
"435.69600","36.30815","0.54631"
"436.04400","36.33715","0.54692"
"436.39200","36.36615","0.55582"
"436.74000","36.39508","0.56165"
"437.08800","36.42414","0.56657"
"437.43600","36.45314","0.56765"
"437.78400","36.48214","0.29345"
"438.13200","36.51120","0.31247"
"438.48000","36.54007","0.33124"
"438.82800","36.56919","0.31726"
"439.17600","36.59813","0.33431"
"439.52400","36.62707","0.35643"
"439.87200","36.65619","0.34567"
"440.22000","36.68512","0.36659"
"440.56800","36.71412","0.36654"
"440.91600","36.74318","0.36872"
"441.26400","36.77212","0.37451"
"441.61200","36.80111","0.37365"
"441.96000","36.83017","0.37699"
"442.30800","36.85911","0.37711"
"442.65600","36.88811","0.37921"
"443.00400","36.91717","0.38218"
"443.35200","36.94611","0.38390"
"443.70000","36.97516","0.38971"
"444.04800","37.00416","0.39187"
"444.39600","37.03310","0.39926"
"444.74400","37.06210","0.40141"
"445.09200","37.09116","0.41307"
"445.44000","37.12009","0.41548"
"445.78800","37.14909","0.42085"
"446.13600","37.17821","0.42262"
"446.48400","37.20708","0.42520"
"446.83200","37.23614","0.42788"
"447.18000","37.26514","0.43397"
"447.52800","37.29408","0.44029"
"447.87600","37.32314","0.44477"
"448.22400","37.35208","0.45068"
"448.57200","37.38113","0.45428"
"448.92000","37.41019","0.45833"
"449.26800","37.43907","0.46071"
"449.61600","37.46813","0.46262"
"449.96400","37.49712","0.46426"
"450.31200","37.52612","0.46536"
"450.66000","37.55512","0.46378"
"451.00800","37.58418","0.46414"
"451.35600","37.61312","0.46648"
"451.70400","37.64211","0.46881"
"452.05200","37.67111","0.47278"
"452.40000","37.70011","0.47518"
"452.74800","37.72917","0.47862"
"453.09600","37.75817","0.48367"
"453.44400","37.78711","0.48749"
"453.79200","37.81610","0.49277"
"454.14000","37.84510","0.49892"
"454.48800","37.87416","0.50433"
"454.83600","37.90310","0.50842"
"455.18400","37.93209","0.51241"
"455.53200","37.96109","0.51620"
"455.88000","37.99015","0.52066"
"456.22800","38.01909","0.52270"
"456.57600","38.04815","0.52395"
"456.92400","38.07714","0.52559"
"457.27200","38.10608","0.52819"
"457.62000","38.13520","0.53370"
"457.96800","38.16408","0.53997"
"458.31600","38.19308","0.54779"
"458.66400","38.22213","0.55346"
"459.01200","38.25107","0.54386"
"459.36000","38.28019","0.54904"
"459.70800","38.30907","0.55559"
"460.05600","38.33812","0.56274"
"460.40400","38.36712","0.56321"
"460.75200","38.39612","0.56748"
"461.10000","38.42512","0.57143"
"461.44800","38.45412","0.57355"
"461.79600","38.48323","0.57544"
"462.14400","38.51212","0.57927"
"462.49200","38.54117","0.58097"
"462.84000","38.57011","0.58392"
"463.18800","38.59911","0.58528"
"463.53600","38.62811","0.58660"
"463.88400","38.65716","0.58809"
"464.23200","38.68610","0.59002"
"464.58000","38.71516","0.59289"
"464.92800","38.74416","0.59600"
"465.27600","38.77309","0.60081"
"465.62400","38.80215","0.60886"
"465.97200","38.83109","0.61650"
"466.32000","38.86008","0.62045"
"466.66800","38.88921","0.62444"
"467.01600","38.91809","0.62890"
"467.36400","38.94720","0.63179"
"467.71200","38.97614","0.63535"
"468.06000","39.00508","0.62625"
"468.40800","39.03419","0.57209"
"468.75600","39.06313","0.57118"
"469.10400","39.09213","0.57225"
"469.45200","39.12113","0.57477"
"469.80000","39.15012","0.57750"
"470.14800","39.17912","0.57978"
"470.49600","39.20812","0.58222"
"470.84400","39.23712","0.58545"
"471.19200","39.26605","0.58669"
"471.54000","39.29518","0.58807"
"471.88800","39.32411","0.59009"
"472.23600","39.35312","0.59279"
"472.58400","39.38217","0.59523"
"472.93200","39.41105","0.59766"
"473.28000","39.44017","0.60304"
"473.62800","39.46916","0.61000"
"473.97600","39.49810","0.61715"
"474.32400","39.52716","0.62332"
"474.67200","39.55616","0.62746"
"475.02000","39.58509","0.63043"
"475.36800","39.61415","0.63417"
"475.71600","39.64315","0.64071"
"476.06400","39.67215","0.64649"
"476.41200","39.70121","0.50218"
"476.76000","39.73009","0.52182"
"477.10800","39.75914","0.36814"
"477.45600","39.78814","0.37139"
"477.80400","39.81708","0.37316"
"478.15200","39.84614","0.38198"
"478.50000","39.87513","0.37778"
"478.84800","39.90413","0.38843"
"479.19600","39.93307","0.39008"
"479.54400","39.96212","0.40085"
"479.89200","39.99107","0.41077"
"480.24000","40.02012","0.41600"
"480.58800","40.04918","0.42286"
"480.93600","40.07812","0.42426"
"481.28400","40.10712","0.42811"
"481.63200","40.13611","0.43098"
"481.98000","40.16512","0.43686"
"482.32800","40.19417","0.44262"
"482.67600","40.22311","0.44697"
"483.02400","40.25217","0.45063"
"483.37200","40.28110","0.45377"
"483.72000","40.31010","0.45754"
"484.06800","40.33910","0.46075"
"484.41600","40.36816","0.46259"
"484.76400","40.39709","0.46495"
"485.11200","40.42615","0.46762"
"485.46000","40.45515","0.47303"
"485.80800","40.48409","0.47707"
"486.15600","40.51315","0.48290"
"486.50400","40.54215","0.48849"
"486.85200","40.57114","0.49772"
"487.20000","40.60014","0.50498"
"487.54800","40.62914","0.51134"
"487.89600","40.65808","0.51512"
"488.24400","40.68708","0.52007"
"488.59200","40.71613","0.52318"
"488.94000","40.74513","0.52458"
"489.28800","40.77412","0.52675"
"489.63600","40.80313","0.53227"
"489.98400","40.83212","0.54093"
"490.33200","40.86119","0.55026"
"490.68000","40.89006","0.43463"
"491.02800","40.91918","0.44422"
"491.37600","40.94817","0.44172"
"491.72400","40.97712","0.44978"
"492.07200","41.00617","0.45084"
"492.42000","41.03511","0.45749"
"492.76800","41.06411","0.45919"
"493.11600","41.09316","0.46233"
"493.46400","41.12210","0.32519"
"493.81200","41.15110","0.32287"
"494.16000","41.18010","0.31911"
"494.50800","41.20910","0.32629"
"494.85600","41.23809","0.33980"
"495.20400","41.26716","0.33736"
"495.55200","41.29609","0.34988"
"495.90000","41.32515","0.35692"
"496.24800","41.35415","0.35667"
"496.59600","41.38309","0.36323"
"496.94400","41.41214","0.36521"
"497.29200","41.44114","0.36871"
"497.64000","41.47014","0.37187"
"497.98800","41.49914","0.37310"
"498.33600","41.52814","0.37419"
"498.68400","41.55707","0.37548"
"499.03200","41.58613","0.37644"
"499.38000","41.61513","0.37850"
"499.72800","41.64413","0.38026"
"500.07600","41.67319","0.38312"
"500.42400","41.70213","0.38685"
"500.77200","41.73112","0.39056"
"501.12000","41.76012","0.39634"
"501.46800","41.78906","0.40288"
"501.81600","41.81818","0.40997"
"502.16400","41.84711","0.41523"
"502.51200","41.87605","0.41958"
"502.86000","41.90517","0.42169"
"503.20800","41.93410","0.42392"
"503.55600","41.96310","0.42687"
"503.90400","41.99216","0.43178"
"504.25200","42.02116","0.43840"
"504.60000","42.05010","0.44464"
"504.94800","42.07916","0.44905"
"505.29600","42.10810","0.45276"
"505.64400","42.13709","0.45604"
"505.99200","42.16615","0.45939"
"506.34000","42.19509","0.46123"
"506.68800","42.22415","0.46294"
"507.03600","42.25309","0.46532"
"507.38400","42.28208","0.46686"
"507.73200","42.31114","0.46979"
"508.08000","42.34020","0.47392"
"508.42800","42.36907","0.47877"
"508.77600","42.39813","0.48267"
"509.12400","42.42713","0.48741"
"509.47200","42.45607","0.49229"
"509.82000","42.48519","0.49801"
"510.16800","42.51419","0.50198"
"510.51600","42.54312","0.50646"
"510.86400","42.57218","0.51086"
"511.21200","42.60106","0.51626"
"511.56000","42.63012","0.52041"
"511.90800","42.65918","0.52333"
"512.25600","42.68811","0.52450"
"512.60400","42.71717","0.52771"
"512.95200","42.74611","0.53272"
"513.30000","42.77510","0.53997"
"513.64800","42.80410","0.54801"
"513.99600","42.83316","0.55432"
"514.34400","42.86210","0.55892"
"514.69200","42.89116","0.56079"
"515.04000","42.92015","0.56315"
"515.33000","42.94425","0.56620"