File: Force_trajectories/170122_2/Specimen_RawData_4.csv
End date,"1/22/2017"
Specimen label,"3CT_24"
Maximum Load,"1.32302",N

Time,Extension,Load
(s),(mm),(N)
"0.00000","0.00000","0.00021"
"0.25800","0.02033","0.00124"
"0.51600","0.04329","0.00090"
"0.77400","0.06469","0.00183"
"1.03200","0.08622","0.00122"
"1.29000","0.10768","0.00173"
"1.54800","0.12921","0.00167"
"1.80600","0.15067","0.00207"
"2.06400","0.17225","0.00241"
"2.32200","0.19372","0.00286"
"2.58000","0.21518","0.00278"
"2.83800","0.23671","0.00356"
"3.09600","0.25817","0.00324"
"3.35400","0.27970","0.00385"
"3.61200","0.30122","0.00330"
"3.87000","0.32274","0.00356"
"4.12800","0.34415","0.00370"
"4.38600","0.36567","0.00422"
"4.64400","0.38714","0.00401"
"4.90200","0.40872","0.00484"
"5.16000","0.43019","0.00432"
"5.41800","0.45171","0.00469"
"5.67600","0.47311","0.00473"
"5.93400","0.49470","0.00460"
"6.19200","0.51616","0.00508"
"6.45000","0.53775","0.00448"
"6.70800","0.55915","0.00507"
"6.96600","0.58068","0.00519"
"7.22400","0.60214","0.00496"
"7.48200","0.62372","0.00553"
"7.74000","0.64519","0.00545"
"7.99800","0.66671","0.00555"
"8.25600","0.68818","0.00593"
"8.51400","0.70970","0.00495"
"8.77200","0.73123","0.00569"
"9.03000","0.75269","0.00561"
"9.28800","0.77415","0.00595"
"9.54600","0.79568","0.00572"
"9.80400","0.81720","0.00604"
"10.06200","0.83867","0.00555"
"10.32000","0.86025","0.00646"
"10.57800","0.88166","0.00651"
"10.83600","0.90324","0.00652"
"11.09400","0.92465","0.00578"
"11.35200","0.94623","0.00640"
"11.61000","0.96769","0.00635"
"11.86800","0.98922","0.00683"
"12.12600","1.01062","0.00655"
"12.38400","1.03221","0.00589"
"12.64200","1.05367","0.00643"
"12.90000","1.07520","0.00688"
"13.15800","1.09666","0.00661"
"13.41600","1.11824","0.00667"
"13.67400","1.13965","0.00688"
"13.93200","1.16123","0.00684"
"14.19000","1.18270","0.00704"
"14.44800","1.20416","0.00779"
"14.70600","1.22563","0.00736"
"14.96400","1.24721","0.00767"
"15.22200","1.26873","0.00769"
"15.48000","1.29020","0.00831"
"15.73800","1.31172","0.00777"
"15.99600","1.33319","0.00819"
"16.25400","1.35465","0.00871"
"16.51200","1.37618","0.00841"
"16.77000","1.39770","0.00833"
"17.02800","1.41916","0.00853"
"17.28600","1.44075","0.00825"
"17.54400","1.46209","0.00875"
"17.80200","1.48374","0.00873"
"18.06000","1.50514","0.00865"
"18.31800","1.52673","0.00937"
"18.57600","1.54813","0.00931"
"18.83400","1.56971","0.00902"
"19.09200","1.59118","0.00900"
"19.35000","1.61276","0.01010"
"19.60800","1.63417","0.01053"
"19.86600","1.65569","0.00986"
"20.12400","1.67716","0.01064"
"20.38200","1.69874","0.01007"
"20.64000","1.72020","0.01067"
"20.89800","1.74173","0.01115"
"21.15600","1.76325","0.01159"
"21.41400","1.78472","0.01147"
"21.67200","1.80624","0.01170"
"21.93000","1.82771","0.01140"
"22.18800","1.84923","0.01161"
"22.44600","1.87064","0.01216"
"22.70400","1.89216","0.01192"
"22.96200","1.91374","0.01207"
"23.22000","1.93527","0.01300"
"23.47800","1.95667","0.01212"
"23.73600","1.97820","0.01269"
"23.99400","1.99966","0.01307"
"24.25200","2.02125","0.01336"
"24.51000","2.04265","0.01329"
"24.76800","2.06417","0.01401"
"25.02600","2.08564","0.01439"
"25.28400","2.10716","0.01426"
"25.54200","2.12863","0.01453"
"25.80000","2.15027","0.01432"
"26.05800","2.17168","0.01515"
"26.31600","2.19326","0.01522"
"26.57400","2.21466","0.01529"
"26.83200","2.23625","0.01500"
"27.09000","2.25771","0.01167"
"27.34800","2.27918","0.00873"
"27.60600","2.30064","0.01061"
"27.86400","2.32217","0.01096"
"28.12200","2.34369","0.00940"
"28.38000","2.36515","0.00968"
"28.63800","2.38668","0.01023"
"28.89600","2.40820","0.01178"
"29.15400","2.42973","0.01158"
"29.41200","2.45119","0.01206"
"29.67000","2.47272","0.01221"
"29.92800","2.49418","0.01208"
"30.18600","2.51570","0.01259"
"30.44400","2.53717","0.01308"
"30.70200","2.55875","0.01339"
"30.96000","2.58016","0.01391"
"31.21800","2.60168","0.01357"
"31.47600","2.62309","0.01464"
"31.73400","2.64473","0.01512"
"31.99200","2.66619","0.01492"
"32.25000","2.68772","0.01522"
"32.50800","2.70912","0.01561"
"32.76600","2.73071","0.01665"
"33.02400","2.75217","0.01662"
"33.28200","2.77382","0.01679"
"33.54000","2.79516","0.01783"
"33.79800","2.81674","0.01796"
"34.05600","2.83821","0.01853"
"34.31400","2.85973","0.01877"
"34.57200","2.88126","0.01995"
"34.83000","2.90272","0.02004"
"35.08800","2.92419","0.02011"
"35.34600","2.94565","0.02108"
"35.60400","2.96724","0.02135"
"35.86200","2.98870","0.02182"
"36.12000","3.01022","0.02223"
"36.37800","3.03163","0.02271"
"36.63600","3.05321","0.02303"
"36.89400","3.07468","0.02358"
"37.15200","3.09626","0.02333"
"37.41000","3.11761","0.02428"
"37.66800","3.13919","0.02490"
"37.92600","3.16065","0.02487"
"38.18400","3.18218","0.02557"
"38.44200","3.20364","0.02548"
"38.70000","3.22523","0.02565"
"38.95800","3.24669","0.02616"
"39.21600","3.26822","0.02686"
"39.47400","3.28968","0.02743"
"39.73200","3.31126","0.02737"
"39.99000","3.33267","0.02744"
"40.24800","3.35419","0.01718"
"40.50600","3.37566","0.01917"
"40.76400","3.39724","0.02054"
"41.02200","3.41877","0.01919"
"41.28000","3.44017","0.02005"
"41.53800","3.46169","0.02221"
"41.79600","3.48316","0.02267"
"42.05400","3.50474","0.02259"
"42.31200","3.52621","0.02324"
"42.57000","3.54773","0.02431"
"42.82800","3.56908","0.02496"
"43.08600","3.59072","0.02506"
"43.34400","3.61218","0.02503"
"43.60200","3.63377","0.02606"
"43.86000","3.65517","0.02668"
"44.11800","3.67670","0.02659"
"44.37600","3.69816","0.02698"
"44.63400","3.71969","0.02813"
"44.89200","3.74115","0.02829"
"45.15000","3.76268","0.02820"
"45.40800","3.78420","0.02911"
"45.66600","3.80572","0.02901"
"45.92400","3.82725","0.02897"
"46.18200","3.84871","0.02929"
"46.44000","3.87018","0.03005"
"46.69800","3.89170","0.03024"
"46.95600","3.91322","0.03069"
"47.21400","3.93469","0.03097"
"47.47200","3.95621","0.03052"
"47.73000","3.97762","0.03088"
"47.98800","3.99920","0.03063"
"48.24600","4.02061","0.03119"
"48.50400","4.04219","0.03161"
"48.76200","4.06366","0.03190"
"49.02000","4.08518","0.03230"
"49.27800","4.10664","0.03236"
"49.53600","4.12817","0.03298"
"49.79400","4.14963","0.03284"
"50.05200","4.17122","0.03298"
"50.31000","4.19262","0.03385"
"50.56800","4.21421","0.03381"
"50.82600","4.23567","0.03411"
"51.08400","4.25725","0.03459"
"51.34200","4.27866","0.03502"
"51.60000","4.30024","0.03500"
"51.85800","4.32165","0.03548"
"52.11600","4.34323","0.03602"
"52.37400","4.36470","0.03670"
"52.63200","4.38616","0.03696"
"52.89000","4.40768","0.03731"
"53.14800","4.42921","0.03865"
"53.40600","4.45073","0.03916"
"53.66400","4.47220","0.03925"
"53.92200","4.49378","0.03980"
"54.18000","4.51519","0.04053"
"54.43800","4.53671","0.04167"
"54.69600","4.55817","0.04266"
"54.95400","4.57970","0.04354"
"55.21200","4.60116","0.04449"
"55.47000","4.62269","0.04545"
"55.72800","4.64415","0.04645"
"55.98600","4.66574","0.04754"
"56.24400","4.68720","0.04906"
"56.50200","4.70872","0.05004"
"56.76000","4.73019","0.05108"
"57.01800","4.75171","0.05238"
"57.27600","4.77318","0.05373"
"57.53400","4.79470","0.05448"
"57.79200","4.81617","0.05578"
"58.05000","4.83769","0.05637"
"58.30800","4.85916","0.05685"
"58.56600","4.88068","0.05823"
"58.82400","4.90226","0.05965"
"59.08200","4.92373","0.06056"
"59.34000","4.94513","0.06166"
"59.59800","4.96666","0.06263"
"59.85600","4.98818","0.06394"
"60.11400","5.00971","0.06474"
"60.37200","5.03123","0.06623"
"60.63000","5.05263","0.06724"
"60.88800","5.07422","0.06794"
"61.14600","5.09568","0.06966"
"61.40400","5.11727","0.07149"
"61.66200","5.13867","0.07250"
"61.92000","5.16026","0.07377"
"62.17800","5.18166","0.07576"
"62.43600","5.20318","0.07638"
"62.69400","5.22465","0.07740"
"62.95200","5.24623","0.07859"
"63.21000","5.26764","0.08015"
"63.46800","5.28916","0.08129"
"63.72600","5.31063","0.08177"
"63.98400","5.33227","0.08291"
"64.24200","5.35367","0.08342"
"64.50000","5.37520","0.08389"
"64.75800","5.39672","0.08434"
"65.01600","5.41819","0.08461"
"65.27400","5.43971","0.08505"
"65.53200","5.46124","0.08535"
"65.79000","5.48264","0.08559"
"66.04800","5.50422","0.08635"
"66.30600","5.52569","0.08666"
"66.56400","5.54715","0.08779"
"66.82200","5.56874","0.08857"
"67.08000","5.59014","0.08918"
"67.33800","5.61173","0.09079"
"67.59600","5.63319","0.09155"
"67.85400","5.65472","0.09404"
"68.11200","5.67612","0.09507"
"68.37000","5.69770","0.09735"
"68.62800","5.71911","0.09967"
"68.88600","5.74069","0.10101"
"69.14400","5.76216","0.10248"
"69.40200","5.78374","0.10491"
"69.66000","5.80520","0.10644"
"69.91800","5.82673","0.10847"
"70.17600","5.84813","0.10913"
"70.43400","5.86972","0.11113"
"70.69200","5.89118","0.11256"
"70.95000","5.91271","0.11353"
"71.20800","5.93423","0.11503"
"71.46600","5.95570","0.11626"
"71.72400","5.97722","0.11719"
"71.98200","5.99868","0.11841"
"72.24000","6.02021","0.11878"
"72.49800","6.04167","0.11997"
"72.75600","6.06320","0.12071"
"73.01400","6.08472","0.12135"
"73.27200","6.10619","0.12175"
"73.53000","6.12765","0.12303"
"73.78800","6.14923","0.12405"
"74.04600","6.17070","0.12480"
"74.30400","6.19222","0.12620"
"74.56200","6.21363","0.12705"
"74.82000","6.23521","0.12820"
"75.07800","6.25662","0.12953"
"75.33600","6.27826","0.13035"
"75.59400","6.29966","0.13090"
"75.85200","6.32119","0.13194"
"76.11000","6.34265","0.13305"
"76.36800","6.36424","0.13365"
"76.62600","6.38570","0.13443"
"76.88400","6.40723","0.13519"
"77.14200","6.42863","0.13636"
"77.40000","6.45021","0.13721"
"77.65800","6.47168","0.13873"
"77.91600","6.49320","0.14029"
"78.17400","6.51473","0.14165"
"78.43200","6.53619","0.14349"
"78.69000","6.55766","0.14597"
"78.94800","6.57918","0.14923"
"79.20600","6.60076","0.15140"
"79.46400","6.62223","0.15537"
"79.72200","6.64369","0.15880"
"79.98000","6.66516","0.16268"
"80.23800","6.68674","0.16682"
"80.49600","6.70821","0.17012"
"80.75400","6.72973","0.17395"
"81.01200","6.75113","0.17734"
"81.27000","6.77272","0.18092"
"81.52800","6.79418","0.18280"
"81.78600","6.81571","0.18495"
"82.04400","6.83717","0.18627"
"82.30200","6.85870","0.18756"
"82.56000","6.88016","0.18814"
"82.81800","6.90175","0.18867"
"83.07600","6.92321","0.18972"
"83.33400","6.94473","0.19061"
"83.59200","6.96614","0.19181"
"83.85000","6.98772","0.19374"
"84.10800","7.00919","0.19561"
"84.36600","7.03077","0.19916"
"84.62400","7.05218","0.20070"
"84.88200","7.07370","0.20338"
"85.14000","7.09522","0.20587"
"85.39800","7.11669","0.20876"
"85.65600","7.13821","0.21096"
"85.91400","7.15968","0.21328"
"86.17200","7.18120","0.21587"
"86.43000","7.20261","0.21844"
"86.68800","7.22425","0.22010"
"86.94600","7.24565","0.22203"
"87.20400","7.26718","0.22421"
"87.46200","7.28858","0.22628"
"87.72000","7.31017","0.22779"
"87.97800","7.33163","0.22899"
"88.23600","7.35328","0.23033"
"88.49400","7.37468","0.23147"
"88.75200","7.39620","0.23210"
"89.01000","7.41773","0.23315"
"89.26800","7.43919","0.23363"
"89.52600","7.46066","0.23413"
"89.78400","7.48218","0.23481"
"90.04200","7.50365","0.23526"
"90.30000","7.52523","0.23564"
"90.55800","7.54669","0.23606"
"90.81600","7.56816","0.23686"
"91.07400","7.58968","0.23756"
"91.33200","7.61121","0.23838"
"91.59000","7.63267","0.23957"
"91.84800","7.65420","0.24037"
"92.10600","7.67572","0.24173"
"92.36400","7.69719","0.24300"
"92.62200","7.71871","0.24536"
"92.88000","7.74017","0.24721"
"93.13800","7.76170","0.24932"
"93.39600","7.78316","0.25178"
"93.65400","7.80469","0.25512"
"93.91200","7.82609","0.25765"
"94.17000","7.84768","0.26018"
"94.42800","7.86914","0.26281"
"94.68600","7.89072","0.26526"
"94.94400","7.91213","0.26703"
"95.20200","7.93371","0.27011"
"95.46000","7.95518","0.27223"
"95.71800","7.97670","0.27525"
"95.97600","7.99817","0.27691"
"96.23400","8.01969","0.27915"
"96.49200","8.04115","0.28053"
"96.75000","8.06268","0.28156"
"97.00800","8.08420","0.27857"
"97.26600","8.10573","0.03612"
"97.52400","8.12725","0.03487"
"97.78200","8.14872","0.03573"
"98.04000","8.17024","0.03374"
"98.29800","8.19164","0.03546"
"98.55600","8.21317","0.03603"
"98.81400","8.23469","0.03681"
"99.07200","8.25622","0.03606"
"99.33000","8.27768","0.03703"
"99.58800","8.29921","0.03761"
"99.84600","8.32067","0.03747"
"100.10400","8.34213","0.03859"
"100.36200","8.36360","0.03922"
"100.62000","8.38518","0.04200"
"100.87800","8.40665","0.04074"
"101.13600","8.42823","0.04335"
"101.39400","8.44964","0.04304"
"101.65200","8.47122","0.04751"
"101.91000","8.49269","0.04705"
"102.16800","8.51421","0.04908"
"102.42600","8.53567","0.05098"
"102.68400","8.55720","0.05108"
"102.94200","8.57866","0.05481"
"103.20000","8.60019","0.05421"
"103.45800","8.62171","0.05770"
"103.71600","8.64323","0.05686"
"103.97400","8.66470","0.06002"
"104.23200","8.68616","0.06065"
"104.49000","8.70769","0.06116"
"104.74800","8.72921","0.06352"
"105.00600","8.75074","0.06391"
"105.26400","8.77214","0.06643"
"105.52200","8.79373","0.06628"
"105.78000","8.81519","0.06987"
"106.03800","8.83671","0.07050"
"106.29600","8.85812","0.07275"
"106.55400","8.87970","0.07501"
"106.81200","8.90111","0.07530"
"107.07000","8.92269","0.08001"
"107.32800","8.94421","0.07995"
"107.58600","8.96574","0.03436"
"107.84400","8.98714","0.03391"
"108.10200","9.00867","0.03612"
"108.36000","9.03019","0.03663"
"108.61800","9.05178","0.03897"
"108.87600","9.07318","0.03913"
"109.13400","9.09465","0.04095"
"109.39200","9.11617","0.04358"
"109.65000","9.13769","0.04082"
"109.90800","9.15922","0.04044"
"110.16600","9.18068","0.03912"
"110.42400","9.20221","0.04336"
"110.68200","9.22367","0.04100"
"110.94000","9.24520","0.04392"
"111.19800","9.26672","0.04272"
"111.45600","9.28818","0.04288"
"111.71400","9.30965","0.04385"
"111.97200","9.33117","0.04559"
"112.23000","9.35264","0.04213"
"112.48800","9.37422","0.04263"
"112.74600","9.39563","0.04737"
"113.00400","9.41721","0.04757"
"113.26200","9.43861","0.05159"
"113.52000","9.46020","0.05181"
"113.77800","9.48166","0.05676"
"114.03600","9.50319","0.05705"
"114.29400","9.52471","0.06013"
"114.55200","9.54624","0.06195"
"114.81000","9.56770","0.06219"
"115.06800","9.58922","0.06337"
"115.32600","9.61069","0.06083"
"115.58400","9.63215","0.06476"
"115.84200","9.65368","0.06542"
"116.10000","9.67514","0.06844"
"116.35800","9.69673","0.06710"
"116.61600","9.71819","0.06797"
"116.87400","9.73971","0.05431"
"117.13200","9.76118","0.05445"
"117.39000","9.78270","0.05888"
"117.64800","9.80417","0.05915"
"117.90600","9.82569","0.06331"
"118.16400","9.84716","0.06476"
"118.42200","9.86868","0.06768"
"118.68000","9.89014","0.06965"
"118.93800","9.91173","0.07249"
"119.19600","9.93313","0.07721"
"119.45400","9.95466","0.07889"
"119.71200","9.97612","0.08161"
"119.97000","9.99777","0.08251"
"120.22800","10.01917","0.08387"
"120.48600","10.04070","0.08473"
"120.74400","10.06216","0.08494"
"121.00200","10.08374","0.08617"
"121.26000","10.10521","0.08645"
"121.51800","10.12667","0.08712"
"121.77600","10.14820","0.08887"
"122.03400","10.16966","0.08888"
"122.29200","10.19118","0.09447"
"122.55000","10.21271","0.09696"
"122.80800","10.23423","0.09901"
"123.06600","10.25570","0.10370"
"123.32400","10.27722","0.10560"
"123.58200","10.29869","0.10974"
"123.84000","10.32021","0.11115"
"124.09800","10.34168","0.11380"
"124.35600","10.36320","0.11684"
"124.61400","10.38461","0.11806"
"124.87200","10.40625","0.11935"
"125.13000","10.42771","0.12096"
"125.38800","10.44924","0.12263"
"125.64600","10.47064","0.11007"
"125.90400","10.49217","0.11565"
"126.16200","10.51363","0.11773"
"126.42000","10.53522","0.11903"
"126.67800","10.55668","0.12031"
"126.93600","10.57820","0.12221"
"127.19400","10.59967","0.12395"
"127.45200","10.62125","0.12516"
"127.71000","10.64272","0.12675"
"127.96800","10.66424","0.12975"
"128.22600","10.68565","0.13120"
"128.48400","10.70723","0.13329"
"128.74200","10.72869","0.13541"
"129.00000","10.75022","0.13693"
"129.25800","10.77168","0.13793"
"129.51600","10.79321","0.14142"
"129.77400","10.81467","0.14394"
"130.03200","10.83613","0.14921"
"130.29000","10.85772","0.15528"
"130.54800","10.87918","0.16187"
"130.80600","10.90071","0.16993"
"131.06400","10.92211","0.17796"
"131.32200","10.94370","0.18015"
"131.58000","10.96516","0.18368"
"131.83800","10.98675","0.18649"
"132.09600","11.00815","0.18824"
"132.35400","11.02967","0.18975"
"132.61200","11.05114","0.19044"
"132.87000","11.07278","0.19360"
"133.12800","11.09419","0.19681"
"133.38600","11.11571","0.20202"
"133.64400","11.13718","0.20746"
"133.90200","11.15870","0.21238"
"134.16000","11.18022","0.21617"
"134.41800","11.20169","0.21997"
"134.67600","11.22315","0.22288"
"134.93400","11.24468","0.22649"
"135.19200","11.26620","0.22922"
"135.45000","11.28773","0.23169"
"135.70800","11.30919","0.23331"
"135.96600","11.33066","0.23247"
"136.22400","11.35224","0.23402"
"136.48200","11.37364","0.23540"
"136.74000","11.39517","0.23658"
"136.99800","11.41663","0.23785"
"137.25600","11.43822","0.23986"
"137.51400","11.45962","0.24305"
"137.77200","11.48127","0.24665"
"138.03000","11.50267","0.25165"
"138.28800","11.52419","0.25709"
"138.54600","11.54566","0.26275"
"138.80400","11.56718","0.26827"
"139.06200","11.58865","0.27309"
"139.32000","11.61023","0.27701"
"139.57800","11.63164","0.28092"
"139.83600","11.65322","0.28303"
"140.09400","11.67468","0.28516"
"140.35200","11.69621","0.28900"
"140.61000","11.71773","0.29583"
"140.86800","11.73920","0.30365"
"141.12600","11.76072","0.31403"
"141.38400","11.78219","0.32217"
"141.64200","11.80371","0.32931"
"141.90000","11.82517","0.33488"
"142.15800","11.84670","0.33861"
"142.41600","11.86822","0.34125"
"142.67400","11.88969","0.34264"
"142.93200","11.91121","0.34401"
"143.19000","11.93273","0.34532"
"143.44800","11.95414","0.34724"
"143.70600","11.97566","0.34937"
"143.96400","11.99713","0.35230"
"144.22200","12.01871","0.35575"
"144.48000","12.04018","0.36067"
"144.73800","12.06170","0.36608"
"144.99600","12.08317","0.37318"
"145.25400","12.10469","0.37873"
"145.51200","12.12621","0.38568"
"145.77000","12.14774","0.38917"
"146.02800","12.16920","0.39195"
"146.28600","12.19073","0.39365"
"146.54400","12.21219","0.39824"
"146.80200","12.23372","0.40416"
"147.06000","12.25524","0.41112"
"147.31800","12.27664","0.29071"
"147.57600","12.29817","0.29983"
"147.83400","12.31963","0.30625"
"148.09200","12.34128","0.31046"
"148.35000","12.36268","0.32212"
"148.60800","12.38421","0.32991"
"148.86600","12.40567","0.33576"
"149.12400","12.42725","0.34098"
"149.38200","12.44872","0.34251"
"149.64000","12.47018","0.34417"
"149.89800","12.49165","0.34674"
"150.15600","12.51323","0.34993"
"150.41400","12.53464","0.35440"
"150.67200","12.55622","0.36012"
"150.93000","12.57768","0.36795"
"151.18800","12.59921","0.37735"
"151.44600","12.62067","0.38619"
"151.70400","12.64220","0.39065"
"151.96200","12.66366","0.39459"
"152.22000","12.68525","0.40043"
"152.47800","12.70665","0.40682"
"152.73600","12.72818","0.41373"
"152.99400","12.74970","0.42045"
"153.25200","12.77122","0.42432"
"153.51000","12.79275","0.42810"
"153.76800","12.81421","0.43038"
"154.02600","12.83574","0.43275"
"154.28400","12.85720","0.43690"
"154.54200","12.87873","0.44238"
"154.80000","12.90019","0.44842"
"155.05800","12.92171","0.45486"
"155.31600","12.94318","0.46187"
"155.57400","12.96470","0.47091"
"155.83200","12.98617","0.47778"
"156.09000","13.00775","0.48342"
"156.34800","13.02910","0.48867"
"156.60600","13.05068","0.49153"
"156.86400","13.07220","0.49321"
"157.12200","13.09373","0.49648"
"157.38000","13.11519","0.49874"
"157.63800","13.13672","0.44413"
"157.89600","13.15818","0.42713"
"158.15400","13.17971","0.42855"
"158.41200","13.20123","0.42932"
"158.67000","13.22275","0.43172"
"158.92800","13.24422","0.43513"
"159.18600","13.26568","0.43042"
"159.44400","13.28721","0.43153"
"159.70200","13.30873","0.43410"
"159.96000","13.33020","0.43639"
"160.21800","13.35166","0.44396"
"160.47600","13.37319","0.45087"
"160.73400","13.39471","0.45684"
"160.99200","13.41623","0.46775"
"161.25000","13.43770","0.47674"
"161.50800","13.45922","0.48236"
"161.76600","13.48069","0.49003"
"162.02400","13.50221","0.49231"
"162.28200","13.52367","0.49501"
"162.54000","13.54520","0.50436"
"162.79800","13.56660","0.51455"
"163.05600","13.58825","0.52248"
"163.31400","13.60965","0.53102"
"163.57200","13.63124","0.53712"
"163.83000","13.65264","0.54159"
"164.08800","13.67423","0.54536"
"164.34600","13.69563","0.54933"
"164.60400","13.71727","0.47777"
"164.86200","13.73868","0.47010"
"165.12000","13.76020","0.48158"
"165.37800","13.78167","0.48510"
"165.63600","13.80319","0.48760"
"165.89400","13.82472","0.49218"
"166.15200","13.84624","0.49552"
"166.41000","13.86770","0.49842"
"166.66800","13.88917","0.51247"
"166.92600","13.91075","0.52611"
"167.18400","13.93216","0.53257"
"167.44200","13.95368","0.53882"
"167.70000","13.97515","0.54431"
"167.95800","13.99667","0.54842"
"168.21600","14.01814","0.55307"
"168.47400","14.03972","0.55549"
"168.73200","14.06118","0.55773"
"168.99000","14.08271","0.56289"
"169.24800","14.10417","0.57045"
"169.50600","14.12570","0.58062"
"169.76400","14.14716","0.59126"
"170.02200","14.16875","0.59609"
"170.28000","14.19015","0.60158"
"170.53800","14.21173","0.41393"
"170.79600","14.23320","0.42186"
"171.05400","14.25472","0.43044"
"171.31200","14.27619","0.44503"
"171.57000","14.29771","0.44909"
"171.82800","14.31911","0.45531"
"172.08600","14.34070","0.47665"
"172.34400","14.36222","0.49134"
"172.60200","14.38375","0.49397"
"172.86000","14.40515","0.50736"
"173.11800","14.42662","0.52692"
"173.37600","14.44820","0.53526"
"173.63400","14.46967","0.54333"
"173.89200","14.49125","0.55070"
"174.15000","14.51260","0.55397"
"174.40800","14.53424","0.55830"
"174.66600","14.55570","0.56648"
"174.92400","14.57723","0.57780"
"175.18200","14.59869","0.59172"
"175.44000","14.62021","0.59966"
"175.69800","14.64162","0.60455"
"175.95600","14.66320","0.62035"
"176.21400","14.68467","0.63045"
"176.47200","14.70625","0.63727"
"176.73000","14.72766","0.64165"
"176.98800","14.74918","0.64327"
"177.24600","14.77071","0.64539"
"177.50400","14.79229","0.64861"
"177.76200","14.81369","0.65277"
"178.02000","14.83522","0.65913"
"178.27800","14.85668","0.66644"
"178.53600","14.87821","0.67525"
"178.79400","14.89967","0.68347"
"179.05200","14.92120","0.69420"
"179.31000","14.94272","0.62619"
"179.56800","14.96418","0.63494"
"179.82600","14.98565","0.63966"
"180.08400","15.00717","0.64341"
"180.34200","15.02870","0.64683"
"180.60000","15.05010","0.65117"
"180.85800","15.07169","0.65779"
"181.11600","15.09315","0.66746"
"181.37400","15.11473","0.67808"
"181.63200","15.13620","0.68935"
"181.89000","15.15772","0.70084"
"182.14800","15.17913","0.70396"
"182.40600","15.20071","0.70856"
"182.66400","15.22218","0.72007"
"182.92200","15.24376","0.73195"
"183.18000","15.26517","0.74252"
"183.43800","15.28669","0.74900"
"183.69600","15.30815","0.75315"
"183.95400","15.32974","0.75611"
"184.21200","15.35120","0.75887"
"184.47000","15.37273","0.76304"
"184.72800","15.39419","0.76847"
"184.98600","15.41566","0.77447"
"185.24400","15.43724","0.78426"
"185.50200","15.45870","0.79062"
"185.76000","15.48017","0.79514"
"186.01800","15.50169","0.80012"
"186.27600","15.52316","0.76407"
"186.53400","15.54468","0.70876"
"186.79200","15.56621","0.70471"
"187.05000","15.58761","0.67366"
"187.30800","15.60919","0.68456"
"187.56600","15.63066","0.69713"
"187.82400","15.65224","0.70321"
"188.08200","15.67365","0.70879"
"188.34000","15.69517","0.72103"
"188.59800","15.71663","0.73543"
"188.85600","15.73822","0.74703"
"189.11400","15.75968","0.75418"
"189.37200","15.78121","0.75829"
"189.63000","15.80261","0.76507"
"189.88800","15.82426","0.77479"
"190.14600","15.84566","0.78562"
"190.40400","15.86718","0.79393"
"190.66200","15.88865","0.79971"
"190.92000","15.91017","0.81214"
"191.17800","15.93170","0.82580"
"191.43600","15.95316","0.84114"
"191.69400","15.97475","0.85206"
"191.95200","15.99621","0.85567"
"192.21000","16.01773","0.85676"
"192.46800","16.03920","0.85981"
"192.72600","16.06072","0.85994"
"192.98400","16.08219","0.86446"
"193.24200","16.10371","0.86908"
"193.50000","16.12518","0.87645"
"193.75800","16.14670","0.88500"
"194.01600","16.16817","0.89291"
"194.27400","16.18969","0.90193"
"194.53200","16.21115","0.90696"
"194.79000","16.23268","0.91086"
"195.04800","16.25414","0.91957"
"195.30600","16.27567","0.93040"
"195.56400","16.29719","0.93787"
"195.82200","16.31872","0.94304"
"196.08000","16.34018","0.94717"
"196.33800","16.36170","0.95263"
"196.59600","16.38323","0.95844"
"196.85400","16.40475","0.96337"
"197.11200","16.42616","0.97039"
"197.37000","16.44768","0.97972"
"197.62800","16.46921","0.98936"
"197.88600","16.49067","1.00054"
"198.14400","16.51220","1.00680"
"198.40200","16.53366","1.01190"
"198.66000","16.55518","1.01958"
"198.91800","16.57665","1.02940"
"199.17600","16.59823","1.03723"
"199.43400","16.61964","1.04461"
"199.69200","16.64122","1.05018"
"199.95000","16.66263","1.05484"
"200.20800","16.68421","1.05601"
"200.46600","16.70567","1.05810"
"200.72400","16.72726","1.06034"
"200.98200","16.74860","1.06448"
"201.24000","16.77019","1.06976"
"201.49800","16.79165","1.07715"
"201.75600","16.81324","1.08511"
"202.01400","16.83470","1.09599"
"202.27200","16.85622","1.10849"
"202.53000","16.87769","1.11842"
"202.78800","16.89921","1.12452"
"203.04600","16.92068","1.13645"
"203.30400","16.94220","1.14780"
"203.56200","16.96367","1.15731"
"203.82000","16.98519","1.16416"
"204.07800","17.00665","1.16772"
"204.33600","17.02818","1.17026"
"204.59400","17.04970","1.17271"
"204.85200","17.07117","1.17504"
"205.11000","17.09269","1.17880"
"205.36800","17.11422","1.18589"
"205.62600","17.13568","1.19662"
"205.88400","17.15714","1.20679"
"206.14200","17.17873","1.21224"
"206.40000","17.20013","1.21942"
"206.65800","17.22172","1.23193"
"206.91600","17.24312","1.24067"
"207.17400","17.26471","1.24937"
"207.43200","17.28617","1.25802"
"207.69000","17.30770","1.26568"
"207.94800","17.32916","1.27056"
"208.20600","17.35068","1.27332"
"208.46400","17.37215","1.27748"
"208.72200","17.39367","1.28780"
"208.98000","17.41514","1.29955"
"209.23800","17.43672","1.30903"
"209.49600","17.45824","1.31978"
"209.75400","17.47971","1.32247"
"210.01200","17.50117","1.23451"
"210.27000","17.52270","1.23729"
"210.52800","17.54416","1.14350"
"210.78600","17.56569","1.13981"
"211.04400","17.58715","1.14690"
"211.30200","17.60861","1.15260"
"211.56000","17.63020","1.16227"
"211.81800","17.65166","1.16762"
"212.07600","17.67325","1.16961"
"212.33400","17.69465","1.17262"
"212.59200","17.71624","1.17480"
"212.85000","17.73764","0.92880"
"213.10800","17.75922","0.93549"
"213.36600","17.78069","0.94126"
"213.62400","17.80221","0.94536"
"213.88200","17.82368","0.95473"
"214.14000","17.84520","0.96063"
"214.39800","17.86667","0.96887"
"214.65600","17.88819","0.94246"
"214.91400","17.90965","0.93829"
"215.17200","17.93124","0.63497"
"215.43000","17.95264","0.64157"
"215.68800","17.97423","0.64293"
"215.94600","17.99569","0.64533"
"216.20400","18.01716","0.64967"
"216.46200","18.03868","0.53983"
"216.72000","18.06015","0.53774"
"216.97800","18.08173","0.54414"
"217.23600","18.10319","0.55309"
"217.49400","18.12472","0.55532"
"217.75200","18.14612","0.55649"
"218.01000","18.16771","0.56362"
"218.26800","18.18917","0.58160"
"218.52600","18.21070","0.58918"
"218.78400","18.23210","0.59621"
"219.04200","18.25368","0.60926"
"219.30000","18.27515","0.58132"
"219.55800","18.29667","0.49000"
"219.81600","18.31820","0.49313"
"220.07400","18.33972","0.49957"
"220.33200","18.36119","0.51026"
"220.59000","18.38271","0.52270"
"220.84800","18.40417","0.53263"
"221.10600","18.42576","0.53900"
"221.36400","18.44716","0.54471"
"221.62200","18.46869","0.55008"
"221.88000","18.49015","0.55326"
"222.13800","18.51174","0.55567"
"222.39600","18.53320","0.55990"
"222.65400","18.55473","0.56426"
"222.91200","18.57619","0.57236"
"223.17000","18.59772","0.58676"
"223.42800","18.61924","0.59364"
"223.68600","18.64070","0.59802"
"223.94400","18.66217","0.60598"
"224.20200","18.68363","0.61592"
"224.46000","18.70522","0.62565"
"224.71800","18.72668","0.63405"
"224.97600","18.74826","0.63851"
"225.23400","18.76961","0.64215"
"225.49200","18.79119","0.64409"
"225.75000","18.81266","0.64535"
"226.00800","18.83418","0.64937"
"226.26600","18.85565","0.65333"
"226.52400","18.87717","0.65825"
"226.78200","18.89863","0.66702"
"227.04000","18.92016","0.67459"
"227.29800","18.94168","0.68234"
"227.55600","18.96327","0.69304"
"227.81400","18.98473","0.70029"
"228.07200","19.00620","0.70300"
"228.33000","19.02766","0.70473"
"228.58800","19.04924","0.71056"
"228.84600","19.07071","0.71816"
"229.10400","19.09217","0.72726"
"229.36200","19.11364","0.73487"
"229.62000","19.13516","0.74310"
"229.87800","19.15669","0.74818"
"230.13600","19.17821","0.75254"
"230.39400","19.19973","0.75604"
"230.65200","19.22114","0.75857"
"230.91000","19.24272","0.76193"
"231.16800","19.26419","0.76702"
"231.42600","19.28571","0.77387"
"231.68400","19.30712","0.78127"
"231.94200","19.32870","0.78941"
"232.20000","19.35011","0.79350"
"232.45800","19.37175","0.68000"
"232.71600","19.39315","0.65833"
"232.97400","19.41468","0.65776"
"233.23200","19.43614","0.66578"
"233.49000","19.45773","0.67654"
"233.74800","19.47919","0.68067"
"234.00600","19.50066","0.69547"
"234.26400","19.52212","0.70044"
"234.52200","19.54370","0.70360"
"234.78000","19.56517","0.70754"
"235.03800","19.58669","0.71402"
"235.29600","19.60822","0.72842"
"235.55400","19.62968","0.73435"
"235.81200","19.65121","0.74345"
"236.07000","19.67267","0.74872"
"236.32800","19.69425","0.75318"
"236.58600","19.71566","0.75652"
"236.84400","19.73718","0.75859"
"237.10200","19.75865","0.76264"
"237.36000","19.78023","0.76744"
"237.61800","19.80169","0.77518"
"237.87600","19.82322","0.78178"
"238.13400","19.84462","0.78895"
"238.39200","19.86621","0.79349"
"238.65000","19.88767","0.79689"
"238.90800","19.90920","0.80162"
"239.16600","19.93066","0.81089"
"239.42400","19.95218","0.82261"
"239.68200","19.97371","0.83262"
"239.94000","19.99524","0.84103"
"240.19800","20.01670","0.84942"
"240.45600","20.03822","0.85392"
"240.71400","20.05969","0.85570"
"240.97200","20.08121","0.85677"
"241.23000","20.10274","0.85834"
"241.48800","20.12426","0.86137"
"241.74600","20.14573","0.86480"
"242.00400","20.16713","0.86798"
"242.26200","20.18871","0.87324"
"242.52000","20.21018","0.87981"
"242.77800","20.23170","0.76707"
"243.03600","20.25317","0.75846"
"243.29400","20.27475","0.76085"
"243.55200","20.29615","0.76256"
"243.81000","20.31774","0.76860"
"244.06800","20.33920","0.77398"
"244.32600","20.36067","0.78012"
"244.58400","20.38213","0.78744"
"244.84200","20.40372","0.79119"
"245.10000","20.42518","0.79537"
"245.35800","20.44676","0.79781"
"245.61600","20.46817","0.80553"
"245.87400","20.48969","0.81317"
"246.13200","20.51116","0.82423"
"246.39000","20.53274","0.83229"
"246.64800","20.55421","0.84226"
"246.90600","20.57567","0.84914"
"247.16400","20.59713","0.85416"
"247.42200","20.61866","0.85560"
"247.68000","20.64018","0.85654"
"247.93800","20.66171","0.85749"
"248.19600","20.68323","0.85991"
"248.45400","20.70470","0.86257"
"248.71200","20.72622","0.86628"
"248.97000","20.74769","0.87104"
"249.22800","20.76921","0.87716"
"249.48600","20.79062","0.88407"
"249.74400","20.81220","0.89098"
"250.00200","20.83360","0.89859"
"250.26000","20.85518","0.90481"
"250.51800","20.87665","0.90795"
"250.77600","20.89824","0.91224"
"251.03400","20.91964","0.91881"
"251.29200","20.94122","0.92813"
"251.55000","20.96263","0.93572"
"251.80800","20.98421","0.93976"
"252.06600","21.00567","0.94384"
"252.32400","21.02720","0.94741"
"252.58200","21.04866","0.95166"
"252.84000","21.07025","0.95570"
"253.09800","21.09171","0.95939"
"253.35600","21.11318","0.96251"
"253.61400","21.13464","0.96746"
"253.87200","21.15617","0.97363"
"254.13000","21.17769","0.97898"
"254.38800","21.19921","0.98436"
"254.64600","21.22068","0.92650"
"254.90400","21.24220","0.87215"
"255.16200","21.26373","0.87418"
"255.42000","21.28519","0.87896"
"255.67800","21.30672","0.88443"
"255.93600","21.32818","0.89243"
"256.19400","21.34971","0.89983"
"256.45200","21.37117","0.90454"
"256.71000","21.39270","0.90817"
"256.96800","21.41416","0.91194"
"257.22600","21.43568","0.91944"
"257.48400","21.45709","0.92602"
"257.74200","21.47867","0.93350"
"258.00000","21.50014","0.93821"
"258.25800","21.52172","0.94201"
"258.51600","21.54319","0.01659"
"258.77400","21.56471","-0.00257"
"259.03200","21.58617","0.01289"
"259.29000","21.60776","0.01608"
"259.54800","21.62916","0.01202"
"259.80600","21.65069","0.04298"
"260.06400","21.67215","0.01682"
"260.32200","21.69374","0.00775"
"260.58000","21.71526","0.02711"
"260.83800","21.73672","0.00346"
"261.09600","21.75819","0.00703"
"261.35400","21.77965","0.02339"
"261.61200","21.80124","0.01033"
"261.87000","21.82270","0.00699"
"262.12800","21.84423","0.02419"
"262.38600","21.86563","0.00825"
"262.64400","21.88715","0.01034"
"262.90200","21.90868","0.02572"
"263.16000","21.93026","0.00951"
"263.41800","21.95167","0.01310"
"263.67600","21.97319","0.02457"
"263.93400","21.99466","0.01121"
"264.19200","22.01618","0.02389"
"264.45000","22.03765","0.01642"
"264.70800","22.05917","0.01277"
"264.96600","22.08057","0.02757"
"265.22400","22.10222","0.01529"
"265.48200","22.12368","0.02262"
"265.74000","22.14527","0.02395"
"265.99800","22.16667","0.01867"
"266.25600","22.18819","0.02826"
"266.51400","22.20966","0.02098"
"266.77200","22.23118","0.02607"
"267.03000","22.25271","0.02716"
"267.28800","22.27417","0.02448"
"267.54600","22.29570","0.03000"
"267.80400","22.31722","0.02619"
"268.06200","22.33875","0.02959"
"268.32000","22.36021","0.02867"
"268.57800","22.38173","0.02947"
"268.83600","22.40314","0.03114"
"269.09400","22.42472","0.02962"
"269.35200","22.44619","0.03181"
"269.61000","22.46771","0.03070"
"269.86800","22.48918","0.03225"
"270.12600","22.51070","0.03229"
"270.38400","22.53210","0.03263"
"270.64200","22.55375","0.03336"
"270.90000","22.57521","0.03314"
"271.15800","22.59674","0.03382"
"271.41600","22.61820","0.03386"
"271.67400","22.63972","0.03462"
"271.93200","22.66119","0.03508"
"272.19000","22.68277","0.03551"
"272.44800","22.70418","0.03621"
"272.70600","22.72564","0.03641"
"272.96400","22.74717","0.03764"
"273.22200","22.76869","0.03772"
"273.48000","22.79028","0.03943"
"273.73800","22.81168","0.04043"
"273.99600","22.83321","0.04098"
"274.25400","22.85467","0.04207"
"274.51200","22.87619","0.04288"
"274.77000","22.89766","0.04551"
"275.02800","22.91918","0.04635"
"275.28600","22.94065","0.04803"
"275.54400","22.96223","0.04922"
"275.80200","22.98363","0.05089"
"276.06000","23.00522","0.05241"
"276.31800","23.02662","0.05418"
"276.57600","23.04820","0.05629"
"276.83400","23.06967","0.05744"
"277.09200","23.09120","0.05922"
"277.35000","23.11266","0.05982"
"277.60800","23.13419","0.06158"
"277.86600","23.15565","0.06245"
"278.12400","23.17718","0.06455"
"278.38200","23.19870","0.06539"
"278.64000","23.22022","0.06686"
"278.89800","23.24169","0.06887"
"279.15600","23.26321","0.07005"
"279.41400","23.28468","0.07259"
"279.67200","23.30620","0.07467"
"279.93000","23.32772","0.07614"
"280.18800","23.34919","0.07798"
"280.44600","23.37071","0.07956"
"280.70400","23.39218","0.08133"
"280.96200","23.41376","0.08191"
"281.22000","23.43517","0.08315"
"281.47800","23.45669","0.08402"
"281.73600","23.47809","0.08478"
"281.99400","23.49968","0.09077"
"282.25200","23.52114","0.08305"
"282.51000","23.54273","0.08462"
"282.76800","23.56413","0.08540"
"283.02600","23.58572","0.08551"
"283.28400","23.60712","0.08994"
"283.54200","23.62876","0.08596"
"283.80000","23.65017","0.08736"
"284.05800","23.67169","0.09350"
"284.31600","23.69322","0.09227"
"284.57400","23.71474","0.10095"
"284.83200","23.73621","0.10015"
"285.09000","23.75767","0.10491"
"285.34800","23.77919","0.10023"
"285.60600","23.80066","0.10782"
"285.86400","23.82218","0.10981"
"286.12200","23.84371","0.11497"
"286.38000","23.86523","0.11215"
"286.63800","23.88664","0.11708"
"286.89600","23.90822","0.11701"
"287.15400","23.92968","0.11922"
"287.41200","23.95127","0.11999"
"287.67000","23.97267","0.12140"
"287.92800","23.99420","0.12364"
"288.18600","24.01566","0.12304"
"288.44400","24.03718","0.12566"
"288.70200","24.05871","0.12573"
"288.96000","24.08017","0.12938"
"289.21800","24.10164","0.13022"
"289.47600","24.12322","0.13106"
"289.73400","24.14463","0.13165"
"289.99200","24.16627","0.13285"
"290.25000","24.18768","0.13541"
"290.50800","24.20920","0.13544"
"290.76600","24.23072","0.13796"
"291.02400","24.25225","0.13825"
"291.28200","24.27371","0.14098"
"291.54000","24.29524","0.14408"
"291.79800","24.31664","0.14516"
"292.05600","24.33817","0.15073"
"292.31400","24.35969","0.15184"
"292.57200","24.38121","0.15858"
"292.83000","24.40268","0.16346"
"293.08800","24.42414","0.16747"
"293.34600","24.44567","0.17468"
"293.60400","24.46719","0.17687"
"293.86200","24.48872","0.18211"
"294.12000","24.51012","0.18458"
"294.37800","24.53171","0.18548"
"294.63600","24.55317","0.18772"
"294.89400","24.57470","0.18850"
"295.15200","24.59616","0.18977"
"295.41000","24.61768","0.19152"
"295.66800","24.63921","0.19304"
"295.92600","24.66073","0.19748"
"296.18400","24.68213","0.20043"
"296.44200","24.70372","0.20259"
"296.70000","24.72518","0.20779"
"296.95800","24.74671","0.20980"
"297.21600","24.76817","0.21302"
"297.47400","24.78976","0.21674"
"297.73200","24.81122","0.21830"
"297.99000","24.83269","0.22172"
"298.24800","24.85415","0.22444"
"298.50600","24.87561","0.22600"
"298.76400","24.89720","0.22857"
"299.02200","24.91872","0.23015"
"299.28000","24.94025","0.23131"
"299.53800","24.96171","0.23255"
"299.79600","24.98323","0.23319"
"300.05400","25.00464","0.23380"
"300.31200","25.02622","0.23477"
"300.57000","25.04763","0.23487"
"300.82800","25.06921","0.02631"
"301.08600","25.09062","0.03298"
"301.34400","25.11226","0.08002"
"301.60200","25.13367","0.03381"
"301.86000","25.15519","0.03598"
"302.11800","25.17665","0.05503"
"302.37600","25.19818","0.03264"
"302.63400","25.21964","0.04200"
"302.89200","25.24123","0.03072"
"303.15000","25.26263","0.05409"
"303.40800","25.28422","0.03285"
"303.66600","25.30574","0.03559"
"303.92400","25.32721","0.05497"
"304.18200","25.34873","0.03566"
"304.44000","25.37020","0.06307"
"304.69800","25.39166","0.03689"
"304.95600","25.41312","0.06288"
"305.21400","25.43477","0.04455"
"305.47200","25.45617","0.04962"
"305.73000","25.47763","0.06302"
"305.98800","25.49916","0.05017"
"306.24600","25.52074","0.07122"
"306.50400","25.54221","0.05308"
"306.76200","25.56373","0.07121"
"307.02000","25.58513","0.05909"
"307.27800","25.60672","0.06828"
"307.53600","25.62813","0.06577"
"307.79400","25.64971","0.06670"
"308.05200","25.67112","0.07642"
"308.31000","25.69270","0.06813"
"308.56800","25.71411","0.08284"
"308.82600","25.73575","0.07005"
"309.08400","25.75715","0.08450"
"309.34200","25.77874","0.07572"
"309.60000","25.80014","0.08606"
"309.85800","25.82172","0.08211"
"310.11600","25.84319","0.08773"
"310.37400","25.86471","0.08407"
"310.63200","25.88618","0.08983"
"310.89000","25.90764","0.08536"
"311.14800","25.92923","0.09322"
"311.40600","25.95069","0.08704"
"311.66400","25.97221","0.09853"
"311.92200","25.99368","0.09232"
"312.18000","26.01520","0.10312"
"312.43800","26.03667","0.09873"
"312.69600","26.05825","0.10873"
"312.95400","26.07966","0.10583"
"313.21200","26.10118","0.11396"
"313.47000","26.12259","0.11078"
"313.72800","26.14417","0.11789"
"313.98600","26.16569","0.11497"
"314.24400","26.18728","0.12056"
"314.50200","26.20868","0.11836"
"314.76000","26.23021","0.12399"
"315.01800","26.25167","0.12015"
"315.27600","26.27325","0.12702"
"315.53400","26.29466","0.12352"
"315.79200","26.31618","0.13045"
"316.05000","26.33759","0.12664"
"316.30800","26.35923","0.13257"
"316.56600","26.38070","0.13027"
"316.82400","26.40222","0.13388"
"317.08200","26.42374","0.13383"
"317.34000","26.44521","0.13612"
"317.59800","26.46667","0.13788"
"317.85600","26.48814","0.13834"
"318.11400","26.50978","0.14451"
"318.37200","26.53119","0.14144"
"318.63000","26.55271","0.15310"
"318.88800","26.57412","0.14716"
"319.14600","26.59570","0.16165"
"319.40400","26.61716","0.15742"
"319.66200","26.63869","0.16797"
"319.92000","26.66009","0.17278"
"320.17800","26.68168","0.17467"
"320.43600","26.70314","0.18408"
"320.69400","26.72473","0.18080"
"320.95200","26.74619","0.18768"
"321.21000","26.76765","0.18673"
"321.46800","26.78912","0.18926"
"321.72600","26.81070","0.19008"
"321.98400","26.83217","0.19044"
"322.24200","26.85369","0.19736"
"322.50000","26.87522","0.19558"
"322.75800","26.89668","0.20472"
"323.01600","26.91821","0.20416"
"323.27400","26.93973","0.20831"
"323.53200","26.96119","0.21354"
"323.79000","26.98266","0.21243"
"324.04800","27.00418","0.22042"
"324.30600","27.02571","0.21969"
"324.56400","27.04717","0.22417"
"324.82200","27.06863","0.22826"
"325.08000","27.09016","0.22780"
"325.33800","27.11162","0.23142"
"325.59600","27.13321","0.23187"
"325.85400","27.15467","0.23296"
"326.11200","27.17620","0.23431"
"326.37000","27.19760","0.23412"
"326.62800","27.21924","0.23548"
"326.88600","27.24065","0.23607"
"327.14400","27.26223","0.23642"
"327.40200","27.28364","0.23838"
"327.66000","27.30522","0.23868"
"327.91800","27.32669","0.23970"
"328.17600","27.34815","0.24282"
"328.43400","27.36962","0.24262"
"328.69200","27.39120","0.24746"
"328.95000","27.41266","0.25124"
"329.20800","27.43419","0.25181"
"329.46600","27.45571","0.25977"
"329.72400","27.47718","0.26270"
"329.98200","27.49870","0.26366"
"330.24000","27.52016","0.27004"
"330.49800","27.54169","0.27213"
"330.75600","27.56322","0.27383"
"331.01400","27.58474","0.27889"
"331.27200","27.60614","0.27988"
"331.53000","27.62767","0.28134"
"331.78800","27.64919","0.28429"
"332.04600","27.67072","0.28455"
"332.30400","27.69218","0.28643"
"332.56200","27.71370","0.29180"
"332.82000","27.73511","0.29284"
"333.07800","27.75669","0.29755"
"333.33600","27.77822","0.30770"
"333.59400","27.79974","0.31063"
"333.85200","27.82115","0.31474"
"334.11000","27.84267","0.32427"
"334.36800","27.86414","0.32586"
"334.62600","27.88578","0.32924"
"334.88400","27.90718","0.33429"
"335.14200","27.92871","0.33585"
"335.40000","27.95017","0.33680"
"335.65800","27.97176","0.33997"
"335.91600","27.99322","0.34127"
"336.17400","28.01469","0.34152"
"336.43200","28.03621","0.34270"
"336.69000","28.05761","0.34369"
"336.94800","28.07920","0.34422"
"337.20600","28.10066","0.34499"
"337.46400","28.12225","0.34651"
"337.72200","28.14359","0.34730"
"337.98000","28.16523","0.34766"
"338.23800","28.18670","0.35009"
"338.49600","28.20822","0.35172"
"338.75400","28.22963","0.35282"
"339.01200","28.25115","0.35499"
"339.27000","28.27262","0.35812"
"339.52800","28.29420","0.35957"
"339.78600","28.31567","0.36037"
"340.04400","28.33725","0.36418"
"340.30200","28.35872","0.36796"
"340.56000","28.38024","0.36916"
"340.81800","28.40170","0.37348"
"341.07600","28.42323","0.38006"
"341.33400","28.44463","0.38300"
"341.59200","28.46616","0.38518"
"341.85000","28.48768","0.38748"
"342.10800","28.50920","0.38994"
"342.36600","28.53073","0.39088"
"342.62400","28.55219","0.39133"
"342.88200","28.57372","0.39321"
"343.14000","28.59518","0.39479"
"343.39800","28.61671","0.39732"
"343.65600","28.63817","0.40054"
"343.91400","28.65976","0.40603"
"344.17200","28.68116","0.40853"
"344.43000","28.70268","0.41090"
"344.68800","28.72415","0.41415"
"344.94600","28.74573","0.41686"
"345.20400","28.76714","0.41959"
"345.46200","28.78866","0.42043"
"345.72000","28.81013","0.42291"
"345.97800","28.83171","0.42604"
"346.23600","28.85317","0.42789"
"346.49400","28.87470","0.42874"
"346.75200","28.89616","0.42990"
"347.01000","28.91769","0.43107"
"347.26800","28.93921","0.43209"
"347.52600","28.96068","0.43292"
"347.78400","28.98220","0.43411"
"348.04200","29.00372","0.43541"
"348.30000","29.02519","0.43881"
"348.55800","29.04671","0.43980"
"348.81600","29.06824","0.44120"
"349.07400","29.08970","0.44324"
"349.33200","29.11117","0.44598"
"349.59000","29.13263","0.44878"
"349.84800","29.15421","0.45023"
"350.10600","29.17568","0.45225"
"350.36400","29.19720","0.45587"
"350.62200","29.21861","0.45923"
"350.88000","29.24019","0.46190"
"351.13800","29.26165","0.46389"
"351.39600","29.28318","0.46682"
"351.65400","29.30464","0.47030"
"351.91200","29.32617","0.47337"
"352.17000","29.34763","0.47444"
"352.42800","29.36922","0.47705"
"352.68600","29.39068","0.22481"
"352.94400","29.41221","0.23141"
"353.20200","29.43367","0.23398"
"353.46000","29.45526","0.23242"
"353.71800","29.47666","0.23402"
"353.97600","29.49818","0.23329"
"354.23400","29.51965","0.23348"
"354.49200","29.54117","0.23566"
"354.75000","29.56269","0.23423"
"355.00800","29.58416","0.23604"
"355.26600","29.60575","0.23541"
"355.52400","29.62715","0.23470"
"355.78200","29.64873","0.23957"
"356.04000","29.67014","0.23555"
"356.29800","29.69172","0.23801"
"356.55600","29.71313","0.23792"
"356.81400","29.73471","0.23754"
"357.07200","29.75618","0.24235"
"357.33000","29.77770","0.23824"
"357.58800","29.79917","0.23978"
"357.84600","29.82075","0.24509"
"358.10400","29.84215","0.24055"
"358.36200","29.86368","0.24683"
"358.62000","29.88514","0.24398"
"358.87800","29.90672","0.24389"
"359.13600","29.92813","0.25335"
"359.39400","29.94971","0.24620"
"359.65200","29.97112","-0.00884"
"359.91000","29.99270","0.00816"
"360.16800","30.01423","0.00476"
"360.42600","30.03569","0.00412"
"360.68400","30.05715","0.00247"
"360.94200","30.07874","0.00112"
"361.20000","30.10021","0.00431"
"361.45800","30.12173","0.00379"
"361.71600","30.14325","0.00384"
"361.97400","30.16466","0.00150"
"362.23200","30.18618","0.00518"
"362.49000","30.20771","0.00357"
"362.74800","30.22923","0.00406"
"363.00600","30.25063","0.00142"
"363.26400","30.27222","0.00464"
"363.52200","30.29362","0.00379"
"363.78000","30.31521","0.00387"
"364.03800","30.33667","0.00162"
"364.29600","30.35820","0.00515"
"364.55400","30.37966","0.00419"
"364.81200","30.40118","0.00369"
"365.07000","30.42265","0.00154"
"365.32800","30.44429","0.00407"
"365.58600","30.46570","0.00448"
"365.84400","30.48716","0.00332"
"366.10200","30.50869","0.00273"
"366.36000","30.53021","0.00583"
"366.61800","30.55173","0.00451"
"366.87600","30.57320","0.00393"
"367.13400","30.59466","0.00314"
"367.39200","30.61619","0.00624"
"367.65000","30.63771","0.00440"
"367.90800","30.65918","0.00392"
"368.16600","30.68076","0.00413"
"368.42400","30.70217","0.00657"
"368.68200","30.72375","0.00402"
"368.94000","30.74515","0.00537"
"369.19800","30.76674","0.00538"
"369.45600","30.78814","0.00614"
"369.71400","30.80973","0.00484"
"369.97200","30.83113","0.00656"
"370.23000","30.85271","0.00554"
"370.48800","30.87418","0.00621"
"370.74600","30.89570","0.00592"
"371.00400","30.91717","0.00731"
"371.26200","30.93869","0.00585"
"371.52000","30.96010","0.00706"
"371.77800","30.98168","0.00761"
"372.03600","31.00321","0.00698"
"372.29400","31.02473","0.00720"
"372.55200","31.04619","0.00845"
"372.81000","31.06772","0.00752"
"373.06800","31.08924","0.00733"
"373.32600","31.11071","0.00881"
"373.58400","31.13217","0.00836"
"373.84200","31.15370","0.00857"
"374.10000","31.17522","0.00889"
"374.35800","31.19668","0.00989"
"374.61600","31.21815","0.00891"
"374.87400","31.23961","0.00908"
"375.13200","31.26119","0.00999"
"375.39000","31.28272","0.01021"
"375.64800","31.30418","0.01046"
"375.90600","31.32565","0.00970"
"376.16400","31.34723","0.01124"
"376.42200","31.36870","0.01051"
"376.68000","31.39022","0.01060"
"376.93800","31.41169","0.01048"
"377.19600","31.43315","0.01115"
"377.45400","31.45461","0.01175"
"377.71200","31.47620","0.01136"
"377.97000","31.49767","0.01266"
"378.22800","31.51925","0.01242"
"378.48600","31.54065","0.01219"
"378.74400","31.56223","0.01294"
"379.00200","31.58370","0.01304"
"379.26000","31.60522","0.01257"
"379.51800","31.62669","0.01353"
"379.77600","31.64821","0.01345"
"380.03400","31.66968","0.01386"
"380.29200","31.69114","0.01407"
"380.46600","31.70573","0.01469"