File: Force_trajectories/170122_2/Specimen_RawData_8.csv
End date,"1/22/2017"
Specimen label,"12CG_91"
Maximum Load,"0.23598",N

Time,Extension,Load
(s),(mm),(N)
"0.00000","0.00000","0.00375"
"0.50400","0.04233","0.00815"
"1.00800","0.08424","0.01180"
"1.51200","0.12634","0.01319"
"2.01600","0.16825","0.01433"
"2.52000","0.21028","0.01535"
"3.02400","0.25225","0.01788"
"3.52800","0.29422","0.02288"
"4.03200","0.33620","0.03194"
"4.53600","0.37817","0.04271"
"5.04000","0.42014","0.04898"
"5.54400","0.46217","0.05261"
"6.04800","0.50421","0.05580"
"6.55200","0.54624","0.05911"
"7.05600","0.58821","0.06279"
"7.56000","0.63024","0.06437"
"8.06400","0.67221","0.06599"
"8.56800","0.71425","0.06679"
"9.07200","0.75616","0.06823"
"9.57600","0.79825","0.06870"
"10.08000","0.84022","0.07041"
"10.58400","0.88219","0.07075"
"11.08800","0.92423","0.07204"
"11.59200","0.96620","0.07210"
"12.09600","1.00823","0.07283"
"12.60000","1.05020","0.07349"
"13.10400","1.09212","0.07434"
"13.60800","1.13415","0.07527"
"14.11200","1.17618","0.07546"
"14.61600","1.21821","0.07566"
"15.12000","1.26024","0.07634"
"15.62400","1.30222","0.07637"
"16.12800","1.34425","0.07734"
"16.63200","1.38622","0.07792"
"17.13600","1.42825","0.07808"
"17.64000","1.47022","0.07722"
"18.14400","1.51226","0.07760"
"18.64800","1.55423","0.07769"
"19.15200","1.59620","0.07819"
"19.65600","1.63823","0.07833"
"20.16000","1.68021","0.07845"
"20.66400","1.72218","0.07823"
"21.16800","1.76421","0.07974"
"21.67200","1.80618","0.07871"
"22.17600","1.84821","0.07893"
"22.68000","1.89025","0.07894"
"23.18400","1.93222","0.07940"
"23.68800","1.97425","0.07927"
"24.19200","2.01628","0.07956"
"24.69600","2.05825","0.07993"
"25.20000","2.10029","0.08063"
"25.70400","2.14214","0.08043"
"26.20800","2.18423","0.07948"
"26.71200","2.22620","0.07997"
"27.21600","2.26818","0.08009"
"27.72000","2.31021","0.07990"
"28.22400","2.35218","0.08027"
"28.72800","2.39409","0.07983"
"29.23200","2.43618","0.08072"
"29.73600","2.47816","0.08048"
"30.24000","2.52025","0.08071"
"30.74400","2.56216","0.08052"
"31.24800","2.60425","0.08077"
"31.75200","2.64622","0.08054"
"32.25600","2.68826","0.08139"
"32.76000","2.73023","0.08124"
"33.26400","2.77220","0.08101"
"33.76800","2.81423","0.08110"
"34.27200","2.85621","0.08111"
"34.77600","2.89824","0.08137"
"35.28000","2.94021","0.08143"
"35.78400","2.98218","0.08183"
"36.28800","3.02421","0.08221"
"36.79200","3.06619","0.08214"
"37.29600","3.10822","0.08277"
"37.80000","3.15019","0.08240"
"38.30400","3.19222","0.08300"
"38.80800","3.23426","0.08308"
"39.31200","3.27623","0.08235"
"39.81600","3.31826","0.08278"
"40.32000","3.36023","0.08297"
"40.82400","3.40226","0.08306"
"41.32800","3.44424","0.08269"
"41.83200","3.48627","0.08332"
"42.33600","3.52818","0.08383"
"42.84000","3.57021","0.08317"
"43.34400","3.61218","0.08320"
"43.84800","3.65422","0.08370"
"44.35200","3.69619","0.08398"
"44.85600","3.73816","0.08374"
"45.36000","3.78019","0.08357"
"45.86400","3.82223","0.08370"
"46.36800","3.86414","0.08401"
"46.87200","3.90623","0.08297"
"47.37600","3.94820","0.08347"
"47.88000","3.99023","0.08349"
"48.38400","4.03227","0.08381"
"48.88800","4.07424","0.08374"
"49.39200","4.11621","0.08440"
"49.89600","4.15830","0.08307"
"50.40000","4.20021","0.08309"
"50.90400","4.24219","0.08331"
"51.40800","4.28416","0.08305"
"51.91200","4.32619","0.08330"
"52.41600","4.36816","0.08354"
"52.92000","4.41020","0.08373"
"53.42400","4.45217","0.08416"
"53.92800","4.49420","0.08385"
"54.43200","4.53617","0.08462"
"54.93600","4.57814","0.08386"
"55.44000","4.62024","0.08459"
"55.94400","4.66227","0.08396"
"56.44800","4.70424","0.08434"
"56.95200","4.74621","0.08392"
"57.45600","4.78824","0.08427"
"57.96000","4.83022","0.08464"
"58.46400","4.87219","0.08511"
"58.96800","4.91416","0.08415"
"59.47200","4.95619","0.08486"
"59.97600","4.99823","0.08524"
"60.48000","5.04020","0.08540"
"60.98400","5.08217","0.08525"
"61.48800","5.12420","0.08475"
"61.99200","5.16617","0.08585"
"62.49600","5.20821","0.08516"
"63.00000","5.25018","0.08547"
"63.50400","5.29221","0.08567"
"64.00800","5.33424","0.08594"
"64.51200","5.37627","0.08598"
"65.01600","5.41819","0.08552"
"65.52000","5.46028","0.08609"
"66.02400","5.50225","0.08659"
"66.52800","5.54422","0.08632"
"67.03200","5.58620","0.08694"
"67.53600","5.62823","0.08622"
"68.04000","5.67020","0.08706"
"68.54400","5.71223","0.08650"
"69.04800","5.75420","0.08647"
"69.55200","5.79618","0.08756"
"70.05600","5.83821","0.08651"
"70.56000","5.88024","0.08691"
"71.06400","5.92227","0.08695"
"71.56800","5.96419","0.08656"
"72.07200","6.00622","0.08702"
"72.57600","6.04819","0.08724"
"73.08000","6.09022","0.08695"
"73.58400","6.13225","0.08720"
"74.08800","6.17423","0.08785"
"74.59200","6.21620","0.08791"
"75.09600","6.25823","0.08732"
"75.60000","6.30020","0.08817"
"76.10400","6.34217","0.08807"
"76.60800","6.38415","0.08851"
"77.11200","6.42618","0.08827"
"77.61600","6.46821","0.08883"
"78.12000","6.51024","0.08808"
"78.62400","6.55222","0.08877"
"79.12800","6.59425","0.08837"
"79.63200","6.63622","0.08865"
"80.13600","6.67825","0.08902"
"80.64000","6.72022","0.08909"
"81.14400","6.76226","0.08951"
"81.64800","6.80423","0.08945"
"82.15200","6.84626","0.08934"
"82.65600","6.88823","0.08912"
"83.16000","6.93020","0.08943"
"83.66400","6.97212","0.08948"
"84.16800","7.01421","0.09022"
"84.67200","7.05618","0.09021"
"85.17600","7.09821","0.09050"
"85.68000","7.14019","0.09101"
"86.18400","7.18228","0.09027"
"86.68800","7.22425","0.09105"
"87.19200","7.26622","0.09097"
"87.69600","7.30819","0.09030"
"88.20000","7.35029","0.09069"
"88.70400","7.39220","0.09063"
"89.20800","7.43429","0.09049"
"89.71200","7.47620","0.09098"
"90.21600","7.51823","0.09061"
"90.72000","7.56021","0.09074"
"91.22400","7.60224","0.09115"
"91.72800","7.64415","0.09194"
"92.23200","7.68612","0.09203"
"92.73600","7.72822","0.09201"
"93.24000","7.77019","0.09165"
"93.74400","7.81216","0.09191"
"94.24800","7.85419","0.09268"
"94.75200","7.89622","0.09217"
"95.25600","7.93826","0.09247"
"95.76000","7.98023","0.09265"
"96.26400","8.02220","0.09273"
"96.76800","8.06423","0.09303"
"97.27200","8.10626","0.09354"
"97.77600","8.14824","0.09298"
"98.28000","8.19021","0.09297"
"98.78400","8.23230","0.09324"
"99.28800","8.27421","0.09341"
"99.79200","8.31619","0.09263"
"100.29600","8.35816","0.09356"
"100.80000","8.40019","0.09414"
"101.30400","8.44222","0.09352"
"101.80800","8.48419","0.09457"
"102.31200","8.52617","0.09458"
"102.81600","8.56826","0.09402"
"103.32000","8.61023","0.09456"
"103.82400","8.65226","0.09477"
"104.32800","8.69423","0.09526"
"104.83200","8.73627","0.09495"
"105.33600","8.77824","0.09496"
"105.84000","8.82027","0.09599"
"106.34400","8.86218","0.09586"
"106.84800","8.90428","0.09531"
"107.35200","8.94625","0.09560"
"107.85600","8.98816","0.09538"
"108.36000","9.03013","0.09526"
"108.86400","9.07216","0.09572"
"109.36800","9.11420","0.09606"
"109.87200","9.15623","0.09604"
"110.37600","9.19820","0.09656"
"110.88000","9.24023","0.09653"
"111.38400","9.28226","0.09602"
"111.88800","9.32430","0.09552"
"112.39200","9.36621","0.09715"
"112.89600","9.40824","0.09176"
"113.40000","9.45021","0.08881"
"113.90400","9.49231","0.08759"
"114.40800","9.53422","0.08765"
"114.91200","9.57619","0.08776"
"115.41600","9.61816","0.08822"
"115.92000","9.66019","0.08887"
"116.42400","9.70217","0.08875"
"116.92800","9.74420","0.08893"
"117.43200","9.78623","0.08915"
"117.93600","9.82820","0.08930"
"118.44000","9.87024","0.08967"
"118.94400","9.91221","0.08954"
"119.44800","9.95430","0.08931"
"119.95200","9.99621","0.08990"
"120.45600","10.03824","0.08971"
"120.96000","10.08022","0.09022"
"121.46400","10.12225","0.09061"
"121.96800","10.16422","0.09022"
"122.47200","10.20625","0.09036"
"122.97600","10.24817","0.09096"
"123.48000","10.29020","0.09070"
"123.98400","10.33217","0.09107"
"124.48800","10.37414","0.09133"
"124.99200","10.41617","0.09096"
"125.49600","10.45821","0.09145"
"126.00000","10.50018","0.09135"
"126.50400","10.54227","0.09149"
"127.00800","10.58424","0.09149"
"127.51200","10.62627","0.09207"
"128.01600","10.66825","0.09251"
"128.52000","10.71022","0.09137"
"129.02400","10.75225","0.09208"
"129.52800","10.79422","0.09177"
"130.03200","10.83619","0.09204"
"130.53600","10.87817","0.09251"
"131.04000","10.92020","0.09234"
"131.54400","10.96217","0.09205"
"132.04800","11.00414","0.09274"
"132.55200","11.04624","0.09293"
"133.05600","11.08815","0.09319"
"133.56000","11.13018","0.09341"
"134.06400","11.17221","0.09308"
"134.56800","11.21424","0.09353"
"135.07200","11.25622","0.09309"
"135.57600","11.29825","0.09367"
"136.08000","11.34028","0.09366"
"136.58400","11.38219","0.09400"
"137.08800","11.42423","0.09393"
"137.59200","11.46626","0.09450"
"138.09600","11.50823","0.09391"
"138.60000","11.55020","0.09419"
"139.10400","11.59223","0.09390"
"139.60800","11.63421","0.09444"
"140.11200","11.67618","0.09470"
"140.61600","11.71815","0.09506"
"141.12000","11.76018","0.09472"
"141.62400","11.80221","0.09534"
"142.12800","11.84425","0.09497"
"142.63200","11.88622","0.09530"
"143.13600","11.92825","0.09505"
"143.64000","11.97022","0.09522"
"144.14400","12.01225","0.09555"
"144.64800","12.05423","0.09562"
"145.15200","12.09626","0.09533"
"145.65600","12.13823","0.09586"
"146.16000","12.18026","0.09591"
"146.66400","12.22218","0.09660"
"147.16800","12.26421","0.09536"
"147.67200","12.30618","0.09572"
"148.17600","12.34821","0.09526"
"148.68000","12.39019","0.09525"
"149.18400","12.43216","0.09555"
"149.68800","12.47419","0.09569"
"150.19200","12.51622","0.09594"
"150.69600","12.55819","0.09603"
"151.20000","12.60023","0.09525"
"151.70400","12.64226","0.09625"
"152.20800","12.68429","0.09599"
"152.71200","12.72620","0.09649"
"153.21600","12.76824","0.09628"
"153.72000","12.81021","0.09690"
"154.22400","12.85224","0.09596"
"154.72800","12.89421","0.09635"
"155.23200","12.93618","0.09728"
"155.73600","12.97810","0.09663"
"156.24000","13.02019","0.09702"
"156.74400","13.06222","0.09715"
"157.24800","13.10419","0.09661"
"157.75200","13.14622","0.09757"
"158.25600","13.18820","0.09788"
"158.76000","13.23023","0.09702"
"159.26400","13.27220","0.09745"
"159.76800","13.31423","0.09734"
"160.27200","13.35627","0.09700"
"160.77600","13.39824","0.09809"
"161.28000","13.44027","0.09801"
"161.78400","13.48224","0.09842"
"162.28800","13.52415","0.09772"
"162.79200","13.56618","0.09822"
"163.29600","13.60822","0.09858"
"163.80000","13.65019","0.09834"
"164.30400","13.69216","0.09828"
"164.80800","13.73419","0.09626"
"165.31200","13.77623","0.09671"
"165.81600","13.81826","0.09641"
"166.32000","13.86017","0.09707"
"166.82400","13.90226","0.09639"
"167.32800","13.94424","0.09729"
"167.83200","13.98627","0.09730"
"168.33600","14.02824","0.09722"
"168.84000","14.07027","0.09781"
"169.34400","14.11224","0.09782"
"169.84800","14.15422","0.09765"
"170.35200","14.19619","0.09725"
"170.85600","14.23822","0.09765"
"171.36000","14.28013","0.09762"
"171.86400","14.32222","0.09827"
"172.36800","14.36420","0.09822"
"172.87200","14.40623","0.09839"
"173.37600","14.44820","0.09876"
"173.88000","14.49023","0.09805"
"174.38400","14.53220","0.09853"
"174.88800","14.57424","0.09841"
"175.39200","14.61621","0.09811"
"175.89600","14.65824","0.09870"
"176.40000","14.70021","0.09894"
"176.90400","14.74224","0.09897"
"177.40800","14.78422","0.09915"
"177.91200","14.82625","0.09922"
"178.41600","14.86822","0.09819"
"178.92000","14.91013","0.09901"
"179.42400","14.95217","0.09927"
"179.92800","14.99414","0.09911"
"180.43200","15.03617","0.09939"
"180.93600","15.07820","0.09941"
"181.44000","15.12018","0.09980"
"181.94400","15.16221","0.09899"
"182.44800","15.20424","0.09968"
"182.95200","15.24621","0.09988"
"183.45600","15.28824","0.09982"
"183.96000","15.33022","0.09993"
"184.46400","15.37225","0.09979"
"184.96800","15.41422","0.10068"
"185.47200","15.45625","0.10044"
"185.97600","15.49822","0.10105"
"186.48000","15.54026","0.10051"
"186.98400","15.58211","0.10042"
"187.48800","15.62420","0.10039"
"187.99200","15.66617","0.10031"
"188.49600","15.70820","0.09993"
"189.00000","15.75024","0.10090"
"189.50400","15.79221","0.09966"
"190.00800","15.83418","0.10077"
"190.51200","15.87627","0.10026"
"191.01600","15.91819","0.10074"
"191.52000","15.96028","0.10077"
"192.02400","16.00219","0.10134"
"192.52800","16.04422","0.10101"
"193.03200","16.08625","0.10127"
"193.53600","16.12823","0.10141"
"194.04000","16.17020","0.10143"
"194.54400","16.21223","0.10132"
"195.04800","16.25414","0.10196"
"195.55200","16.29618","0.10159"
"196.05600","16.33821","0.10230"
"196.56000","16.38018","0.10170"
"197.06400","16.42215","0.10172"
"197.56800","16.46418","0.10265"
"198.07200","16.50622","0.10231"
"198.57600","16.54819","0.10271"
"199.08000","16.59022","0.10250"
"199.58400","16.63225","0.10277"
"200.08800","16.67422","0.10235"
"200.59200","16.71626","0.10219"
"201.09600","16.75823","0.10304"
"201.60000","16.80026","0.10307"
"202.10400","16.84223","0.10301"
"202.60800","16.88421","0.10326"
"203.11200","16.92618","0.10370"
"203.61600","16.96815","0.10322"
"204.12000","17.01018","0.10340"
"204.62400","17.05221","0.10312"
"205.12800","17.09425","0.10372"
"205.63200","17.13622","0.10388"
"206.13600","17.17825","0.10355"
"206.64000","17.22022","0.10405"
"207.14400","17.26225","0.10372"
"207.64800","17.30423","0.10413"
"208.15200","17.34620","0.10388"
"208.65600","17.38823","0.10434"
"209.16000","17.43026","0.10405"
"209.66400","17.47223","0.10447"
"210.16800","17.51421","0.10418"
"210.67200","17.55618","0.10436"
"211.17600","17.59821","0.10404"
"211.68000","17.64013","0.10463"
"212.18400","17.68216","0.10491"
"212.68800","17.72419","0.10463"
"213.19200","17.76622","0.10429"
"213.69600","17.80819","0.10506"
"214.20000","17.85022","0.10508"
"214.70400","17.89220","0.10506"
"215.20800","17.93429","0.10489"
"215.71200","17.97620","0.10529"
"216.21600","18.01823","0.10548"
"216.72000","18.06026","0.10511"
"217.22400","18.10224","0.10545"
"217.72800","18.14421","0.10578"
"218.23200","18.18624","0.10581"
"218.73600","18.22821","0.10546"
"219.24000","18.27019","0.10573"
"219.74400","18.31216","0.10561"
"220.24800","18.35419","0.10522"
"220.75200","18.39616","0.10617"
"221.25600","18.43820","0.10585"
"221.76000","18.48023","0.10628"
"222.26400","18.52220","0.10599"
"222.76800","18.56429","0.10551"
"223.27200","18.60620","0.10606"
"223.77600","18.64824","0.10583"
"224.28000","18.69021","0.10615"
"224.78400","18.73224","0.10602"
"225.28800","18.77421","0.10635"
"225.79200","18.81618","0.10642"
"226.29600","18.85822","0.10656"
"226.80000","18.90025","0.10680"
"227.30400","18.94216","0.10686"
"227.80800","18.98419","0.10725"
"228.31200","19.02617","0.10717"
"228.81600","19.06820","0.10731"
"229.32000","19.11023","0.10750"
"229.82400","19.15226","0.10780"
"230.32800","19.19423","0.10823"
"230.83200","19.23627","0.10812"
"231.33600","19.27824","0.10818"
"231.84000","19.32027","0.10859"
"232.34400","19.36218","0.10819"
"232.84800","19.40421","0.10833"
"233.35200","19.44625","0.10811"
"233.85600","19.48822","0.10843"
"234.36000","19.53025","0.10811"
"234.86400","19.57222","0.10885"
"235.36800","19.61414","0.10902"
"235.87200","19.65623","0.10851"
"236.37600","19.69820","0.10870"
"236.88000","19.74017","0.10891"
"237.38400","19.78220","0.10834"
"237.88800","19.82424","0.10880"
"238.39200","19.86621","0.10899"
"238.89600","19.90824","0.10918"
"239.40000","19.95027","0.10926"
"239.90400","19.99224","0.10913"
"240.40800","20.03422","0.10914"
"240.91200","20.07625","0.10861"
"241.41600","20.11822","0.10837"
"241.92000","20.16025","0.10833"
"242.42400","20.20222","0.10844"
"242.92800","20.24414","0.10872"
"243.43200","20.28617","0.10853"
"243.93600","20.32814","0.10885"
"244.44000","20.37017","0.10876"
"244.94400","20.41215","0.10915"
"245.44800","20.45424","0.10913"
"245.95200","20.49621","0.10924"
"246.45600","20.53824","0.10944"
"246.96000","20.58022","0.10962"
"247.46400","20.62230","0.10936"
"247.96800","20.66422","0.10960"
"248.47200","20.70625","0.10931"
"248.97600","20.74822","0.10934"
"249.48000","20.79020","0.10959"
"249.98400","20.83223","0.10990"
"250.48800","20.87426","0.11002"
"250.99200","20.91611","0.11040"
"251.49600","20.95826","0.11015"
"252.00000","21.00018","0.11045"
"252.50400","21.04221","0.10988"
"253.00800","21.08418","0.11058"
"253.51200","21.12621","0.11034"
"254.01600","21.16825","0.11031"
"254.52000","21.21028","0.11059"
"255.02400","21.25225","0.11033"
"255.52800","21.29422","0.11074"
"256.03200","21.33625","0.11091"
"256.53600","21.37829","0.11090"
"257.04000","21.42020","0.11104"
"257.54400","21.46217","0.11137"
"258.04800","21.50414","0.11137"
"258.55200","21.54623","0.11164"
"259.05600","21.58815","0.11155"
"259.56000","21.63018","0.11189"
"260.06400","21.67221","0.11171"
"260.56800","21.71418","0.11197"
"261.07200","21.75615","0.11216"
"261.57600","21.79819","0.11218"
"262.08000","21.84022","0.11257"
"262.58400","21.88225","0.11250"
"263.08800","21.92422","0.11273"
"263.59200","21.96619","0.11238"
"264.09600","22.00823","0.11258"
"264.60000","22.05026","0.11275"
"265.10400","22.09223","0.11225"
"265.60800","22.13420","0.11324"
"266.11200","22.17624","0.11276"
"266.61600","22.21821","0.11332"
"267.12000","22.26018","0.11326"
"267.62400","22.30215","0.11356"
"268.12800","22.34425","0.11370"
"268.63200","22.38622","0.11427"
"269.13600","22.42825","0.11416"
"269.64000","22.47016","0.11411"
"270.14400","22.51219","0.11479"
"270.64800","22.55423","0.11519"
"271.15200","22.59620","0.11506"
"271.65600","22.63817","0.11541"
"272.16000","22.68026","0.11571"
"272.66400","22.72223","0.11544"
"273.16800","22.76421","0.11592"
"273.67200","22.80618","0.11588"
"274.17600","22.84821","0.11596"
"274.68000","22.89012","0.11592"
"275.18400","22.93222","0.11607"
"275.68800","22.97413","0.11676"
"276.19200","23.01622","0.11597"
"276.69600","23.05819","0.11669"
"277.20000","23.10023","0.11721"
"277.70400","23.14220","0.11755"
"278.20800","23.18423","0.11760"
"278.71200","23.22620","0.11799"
"279.21600","23.26823","0.11808"
"279.72000","23.31021","0.11771"
"280.22400","23.35224","0.11721"
"280.72800","23.39421","0.11702"
"281.23200","23.43624","0.11798"
"281.73600","23.47821","0.11740"
"282.24000","23.52024","0.11810"
"282.74400","23.56222","0.11816"
"283.24800","23.60419","0.11791"
"283.75200","23.64622","0.11836"
"284.25600","23.68819","0.11819"
"284.76000","23.73017","0.11868"
"285.26400","23.77220","0.11870"
"285.76800","23.81417","0.11926"
"286.27200","23.85626","0.11991"
"286.77600","23.89824","0.11907"
"287.28000","23.94020","0.11944"
"287.78400","23.98224","0.11977"
"288.28800","24.02421","0.11956"
"288.79200","24.06631","0.12096"
"289.29600","24.10822","0.12094"
"289.80000","24.15019","0.12161"
"290.30400","24.19216","0.12191"
"290.80800","24.23419","0.12186"
"291.31200","24.27616","0.12272"
"291.81600","24.31820","0.12321"
"292.32000","24.36017","0.12350"
"292.82400","24.40220","0.12365"
"293.32800","24.44423","0.12362"
"293.83200","24.48620","0.12362"
"294.33600","24.52818","0.12437"
"294.84000","24.57027","0.12458"
"295.34400","24.61218","0.12528"
"295.84800","24.65421","0.12591"
"296.35200","24.69619","0.12500"
"296.85600","24.73828","0.12511"
"297.36000","24.78025","0.12565"
"297.86400","24.82222","0.12610"
"298.36800","24.86419","0.12650"
"298.87200","24.90617","0.12701"
"299.37600","24.94820","0.12683"
"299.88000","24.99011","0.12742"
"300.38400","25.03220","0.12799"
"300.88800","25.07424","0.12787"
"301.39200","25.11621","0.12824"
"301.89600","25.15824","0.12895"
"302.40000","25.20021","0.12875"
"302.90400","25.24224","0.12919"
"303.40800","25.28422","0.13009"
"303.91200","25.32625","0.13021"
"304.41600","25.36822","0.13035"
"304.92000","25.41025","0.13108"
"305.42400","25.45223","0.13187"
"305.92800","25.49420","0.13136"
"306.43200","25.53617","0.13235"
"306.93600","25.57814","0.13292"
"307.44000","25.62017","0.13309"
"307.94400","25.66220","0.13334"
"308.44800","25.70424","0.13394"
"308.95200","25.74621","0.13465"
"309.45600","25.78824","0.13474"
"309.96000","25.83021","0.13430"
"310.46400","25.87219","0.13552"
"310.96800","25.91422","0.13530"
"311.47200","25.95625","0.13603"
"311.97600","25.99822","0.13698"
"312.48000","26.04025","0.13729"
"312.98400","26.08217","0.13741"
"313.48800","26.12426","0.13800"
"313.99200","26.16623","0.13871"
"314.49600","26.20814","0.13923"
"315.00000","26.25012","0.13971"
"315.50400","26.29215","0.13983"
"316.00800","26.33418","0.13935"
"316.51200","26.37621","0.13981"
"317.01600","26.41818","0.14031"
"317.52000","26.46021","0.14114"
"318.02400","26.50225","0.13582"
"318.52800","26.54428","0.13616"
"319.03200","26.58619","0.13062"
"319.53600","26.62823","0.13026"
"320.04000","26.67026","0.13014"
"320.54400","26.71223","0.13014"
"321.04800","26.75420","0.12952"
"321.55200","26.79617","0.13023"
"322.05600","26.83821","0.12926"
"322.56000","26.88018","0.13099"
"323.06400","26.92215","0.13099"
"323.56800","26.96418","0.13109"
"324.07200","27.00621","0.13142"
"324.57600","27.04819","0.13203"
"325.08000","27.09022","0.13042"
"325.58400","27.13225","0.13042"
"326.08800","27.17422","0.13173"
"326.59200","27.21626","0.13165"
"327.09600","27.25829","0.13252"
"327.60000","27.30020","0.13242"
"328.10400","27.34229","0.13326"
"328.60800","27.38420","0.13314"
"329.11200","27.42624","0.13390"
"329.61600","27.46821","0.13463"
"330.12000","27.51018","0.13447"
"330.62400","27.55215","0.13562"
"331.12800","27.59418","0.13662"
"331.63200","27.63616","0.13759"
"332.13600","27.67819","0.13782"
"332.64000","27.72022","0.13858"
"333.14400","27.76225","0.13968"
"333.64800","27.80423","0.14085"
"334.15200","27.84626","0.14083"
"334.65600","27.88829","0.14103"
"335.16000","27.93020","0.14146"
"335.66400","27.97224","0.14254"
"336.16800","28.01421","0.14246"
"336.67200","28.05624","0.14364"
"337.17600","28.09821","0.14454"
"337.68000","28.14025","0.14533"
"338.18400","28.18221","0.14604"
"338.68800","28.22413","0.14602"
"339.19200","28.26622","0.14636"
"339.69600","28.30819","0.14732"
"340.20000","28.35022","0.14871"
"340.70400","28.39220","0.14942"
"341.20800","28.43423","0.15019"
"341.71200","28.47626","0.15100"
"342.21600","28.51823","0.15050"
"342.72000","28.56021","0.15030"
"343.22400","28.60224","0.15058"
"343.72800","28.64427","0.15105"
"344.23200","28.68618","0.15129"
"344.73600","28.72821","0.15220"
"345.24000","28.77018","0.15231"
"345.74400","28.81222","0.15375"
"346.24800","28.85419","0.15383"
"346.75200","28.89616","0.15510"
"347.25600","28.93813","0.15578"
"347.76000","28.98022","0.15689"
"348.26400","29.02220","0.15645"
"348.76800","29.06423","0.15723"
"349.27200","29.10620","0.15741"
"349.77600","29.14829","0.15806"
"350.28000","29.19027","0.15868"
"350.78400","29.23224","0.15864"
"351.28800","29.27421","0.15667"
"351.79200","29.31624","0.15639"
"352.29600","29.35822","0.15627"
"352.80000","29.40025","0.15751"
"353.30400","29.44216","0.15484"
"353.80800","29.48419","0.15705"
"354.31200","29.52622","0.15773"
"354.81600","29.56820","0.15842"
"355.32000","29.61017","0.15954"
"355.82400","29.65220","0.15972"
"356.32800","29.69417","0.15220"
"356.83200","29.73626","0.15382"
"357.33600","29.77824","0.15515"
"357.84000","29.82021","0.15641"
"358.34400","29.86224","0.15803"
"358.84800","29.90421","0.15866"
"359.35200","29.94625","0.15585"
"359.85600","29.98828","0.15519"
"360.36000","30.03019","0.15504"
"360.86400","30.07222","0.15668"
"361.36800","30.11419","0.15841"
"361.87200","30.15617","0.15907"
"362.37600","30.19814","0.15958"
"362.88000","30.24017","0.15938"
"363.38400","30.28221","0.16003"
"363.88800","30.32418","0.16092"
"364.39200","30.36621","0.16143"
"364.89600","30.40818","0.16225"
"365.40000","30.45021","0.16261"
"365.90400","30.49224","0.16219"
"366.40800","30.53422","0.16224"
"366.91200","30.57625","0.16266"
"367.41600","30.61828","0.16303"
"367.92000","30.66025","0.16338"
"368.42400","30.70222","0.16383"
"368.92800","30.74420","0.16468"
"369.43200","30.78623","0.16449"
"369.93600","30.82820","0.16466"
"370.44000","30.87023","0.16641"
"370.94400","30.91215","0.16681"
"371.44800","30.95418","0.16770"
"371.95200","30.99615","0.16867"
"372.45600","31.03824","0.17015"
"372.96000","31.08015","0.17238"
"373.46400","31.12218","0.17360"
"373.96800","31.16422","0.17509"
"374.47200","31.20625","0.17813"
"374.97600","31.24822","0.17994"
"375.48000","31.29025","0.18165"
"375.98400","31.33222","0.18415"
"376.48800","31.37426","0.18472"
"376.99200","31.41617","0.18711"
"377.49600","31.45820","0.18831"
"378.00000","31.50018","0.18981"
"378.50400","31.54221","0.19138"
"379.00800","31.58418","0.19225"
"379.51200","31.62615","0.19344"
"380.01600","31.66818","0.19415"
"380.52000","31.71021","0.19347"
"381.02400","31.75219","0.19512"
"381.52800","31.79416","0.19598"
"382.03200","31.83625","0.19738"
"382.53600","31.87823","0.19795"
"383.04000","31.92025","0.19863"
"383.54400","31.96223","0.19929"
"384.04800","32.00426","0.19653"
"384.55200","32.04623","0.19620"
"385.05600","32.08826","0.18790"
"385.56000","32.13018","0.19155"
"386.06400","32.17221","0.19278"
"386.56800","32.21418","0.19426"
"387.07200","32.25615","0.19535"
"387.57600","32.29813","0.19718"
"388.08000","32.34022","0.19794"
"388.58400","32.38219","0.19904"
"389.08800","32.42428","0.20043"
"389.59200","32.46626","0.20163"
"390.09600","32.50823","0.20322"
"390.60000","32.55025","0.20383"
"391.10400","32.59223","0.20543"
"391.60800","32.63420","0.20645"
"392.11200","32.67630","0.20692"
"392.61600","32.71821","0.20748"
"393.12000","32.76024","0.20841"
"393.62400","32.80215","0.20891"
"394.12800","32.84412","0.21030"
"394.63200","32.88615","0.21103"
"395.13600","32.92819","0.21216"
"395.64000","32.97022","0.21296"
"396.14400","33.01219","0.21318"
"396.64800","33.05416","0.21444"
"397.15200","33.09626","0.21566"
"397.65600","33.13823","0.21735"
"398.16000","33.18020","0.21910"
"398.66400","33.22223","0.22034"
"399.16800","33.26426","0.22237"
"399.67200","33.30624","0.22455"
"400.17600","33.34827","0.22750"
"400.68000","33.39024","0.23042"
"401.18400","33.43227","0.23375"
"401.68800","33.47419","0.23526"
"402.19200","33.51616","0.11307"
"402.69600","33.55819","0.11258"
"403.20000","33.60016","0.11425"
"403.70400","33.64220","0.11713"
"404.20800","33.68423","0.11612"
"404.71200","33.72620","0.11816"
"405.21600","33.76823","0.11751"
"405.72000","33.81026","0.11739"
"406.22400","33.85218","0.11743"
"406.72800","33.89421","0.11709"
"407.23200","33.93624","0.11873"
"407.73600","33.97821","0.11907"
"408.24000","34.02019","0.12024"
"408.74400","34.06228","0.12083"
"409.24800","34.10419","0.12163"
"409.75200","34.14622","0.12209"
"410.25600","34.18813","0.12323"
"410.76000","34.23016","0.12494"
"411.26400","34.27220","0.12566"
"411.76800","34.31417","0.12682"
"412.27200","34.35620","0.12773"
"412.77600","34.39823","0.12825"
"413.28000","34.44027","0.12939"
"413.78400","34.48224","0.13022"
"414.28800","34.52421","0.13128"
"414.79200","34.56624","0.13192"
"415.29600","34.60828","0.13302"
"415.80000","34.65031","0.13346"
"416.30400","34.69216","0.13378"
"416.80800","34.73425","0.13495"
"417.31200","34.77616","0.13547"
"417.81600","34.81820","0.13637"
"418.32000","34.86011","0.13583"
"418.82400","34.90220","0.13638"
"419.32800","34.94417","0.13758"
"419.83200","34.98621","0.13795"
"420.33600","35.02823","0.13815"
"420.84000","35.07027","0.13866"
"421.34400","35.11224","0.13957"
"421.84800","35.15427","0.14022"
"422.35200","35.19624","0.14047"
"422.85600","35.23816","0.14160"
"423.36000","35.28025","0.14187"
"423.86400","35.32222","0.14201"
"424.36800","35.36419","0.14199"
"424.87200","35.40622","0.14204"
"425.37600","35.44820","0.14292"
"425.88000","35.49017","0.14352"
"426.38400","35.53214","0.14413"
"426.88800","35.57418","0.14393"
"427.39200","35.61621","0.14463"
"427.89600","35.65818","0.14497"
"428.40000","35.70021","0.14498"
"428.90400","35.74218","0.14516"
"429.40800","35.78428","0.14632"
"429.91200","35.82625","0.14673"
"430.41600","35.86822","0.14747"
"430.92000","35.91019","0.14806"
"431.42400","35.95229","0.14908"
"431.92800","35.99419","0.14874"
"432.43200","36.03623","0.14933"
"432.93600","36.07820","0.15031"
"433.44000","36.12023","0.15097"
"433.94400","36.16220","0.15229"
"434.44800","36.20418","0.15207"
"434.95200","36.24615","0.15396"
"435.45600","36.28818","0.15510"
"435.96000","36.33021","0.15567"
"436.46400","36.37225","0.15612"
"436.96800","36.41422","0.15700"
"437.47200","36.45625","0.15818"
"437.97600","36.49822","0.15918"
"438.48000","36.54026","0.15949"
"438.98400","36.58216","0.15942"
"439.48800","36.62426","0.16022"
"439.99200","36.66623","0.16029"
"440.49600","36.70820","0.15966"
"441.00000","36.75024","0.16033"
"441.50400","36.79221","0.16074"
"442.00800","36.83418","0.16103"
"442.51200","36.87621","0.16166"
"443.01600","36.91818","0.16131"
"443.52000","36.96021","0.16182"
"444.02400","37.00219","0.16185"
"444.52800","37.04422","0.16229"
"445.03200","37.08625","0.16252"
"445.53600","37.12822","0.16283"
"446.04000","37.17020","0.16295"
"446.54400","37.21223","0.16297"
"447.04800","37.25420","0.16337"
"447.55200","37.29623","0.16352"
"448.05600","37.33820","0.16390"
"448.56000","37.38024","0.16397"
"449.06400","37.42221","0.16418"
"449.56800","37.46418","0.07745"
"450.07200","37.50621","0.08053"
"450.57600","37.54818","0.07651"
"451.08000","37.59016","0.08124"
"451.58400","37.63219","0.07828"
"452.08800","37.67422","0.08072"
"452.59200","37.71619","0.07888"
"453.09600","37.75823","0.08154"
"453.60000","37.80026","0.07929"
"454.10400","37.84229","0.08080"
"454.60800","37.88420","0.07965"
"455.11200","37.92624","0.08198"
"455.61600","37.96821","0.07972"
"456.12000","38.01024","0.08071"
"456.62400","38.05221","0.08086"
"457.12800","38.09425","0.08077"
"457.63200","38.13609","0.08212"
"458.13600","38.17819","0.08123"
"458.64000","38.22022","0.08209"
"459.14400","38.26219","0.08163"
"459.64800","38.30416","0.08200"
"460.15200","38.34620","0.08253"
"460.65600","38.38823","0.08234"
"461.16000","38.43020","0.08255"
"461.66400","38.47223","0.08275"
"462.16800","38.51426","0.08276"
"462.67200","38.55624","0.08348"
"463.17600","38.59827","0.08314"
"463.68000","38.64018","0.08332"
"464.18400","38.68222","0.08350"
"464.68800","38.72419","0.08372"
"465.19200","38.76622","0.08413"
"465.69600","38.80819","0.08389"
"466.20000","38.85016","0.08410"
"466.70400","38.89219","0.08415"
"467.20800","38.93417","0.08468"
"467.71200","38.97614","0.08366"
"468.21600","39.01823","0.08353"
"468.72000","39.06026","0.08391"
"469.22400","39.10223","0.08413"
"469.72800","39.14427","0.08481"
"470.23200","39.18624","0.08459"
"470.73600","39.22821","0.08511"
"471.24000","39.27024","0.08557"
"471.74400","39.31221","0.08503"
"472.24800","39.35419","0.08606"
"472.75200","39.39621","0.08594"
"473.25600","39.43819","0.08618"
"473.76000","39.48022","0.08654"
"474.26400","39.52213","0.08684"
"474.76800","39.56422","0.08701"
"475.27200","39.60620","0.08668"
"475.77600","39.64817","0.08736"
"476.28000","39.69014","0.08776"
"476.78400","39.73223","0.08705"
"477.28800","39.77421","0.08790"
"477.79200","39.81624","0.08764"
"478.29600","39.85822","0.08804"
"478.80000","39.90025","0.08825"
"479.30400","39.94228","0.08852"
"479.80800","39.98425","0.08811"
"480.31200","40.02616","0.08813"
"480.81600","40.06820","0.08785"
"481.32000","40.11017","0.08767"
"481.82400","40.15220","0.08781"
"482.32800","40.19417","0.08770"
"482.83200","40.23615","0.08608"
"483.33600","40.27818","0.08689"
"483.84000","40.32020","0.08658"
"484.34400","40.36224","0.08662"
"484.84800","40.40421","0.08633"
"485.35200","40.44624","0.08744"
"485.85600","40.48821","0.08547"
"486.36000","40.53019","0.08626"
"486.86400","40.57222","0.08688"
"487.36800","40.61425","0.08655"
"487.87200","40.65622","0.08711"
"488.37600","40.69820","0.08684"
"488.88000","40.74017","0.08718"
"489.38400","40.78220","0.08755"
"489.88800","40.82417","0.08764"
"490.39200","40.86621","0.08782"
"490.89600","40.90824","0.08770"
"491.40000","40.95021","0.08685"
"491.90400","40.99218","0.08731"
"492.40800","41.03421","0.08680"
"492.91200","41.07625","0.08694"
"493.41600","41.11822","0.08726"
"493.92000","41.16019","0.08724"
"494.42400","41.20229","0.08725"
"494.92800","41.24426","0.08732"
"495.43200","41.28622","0.08951"
"495.93600","41.32820","0.09057"
"496.44000","41.37023","0.08951"
"496.94400","41.41214","0.08980"
"497.44800","41.45424","0.08873"
"497.95200","41.49615","0.08850"
"498.45600","41.53818","0.08906"
"498.96000","41.58021","0.08862"
"499.46400","41.62218","0.08876"
"499.96800","41.66421","0.08865"
"500.47200","41.70625","0.08828"
"500.97600","41.74822","0.08848"
"501.48000","41.79020","0.08877"
"501.98400","41.83216","0.08801"
"502.48800","41.87420","0.08930"
"502.99200","41.91617","0.08876"
"503.49600","41.95826","0.08831"
"504.00000","42.00023","0.08898"
"504.50400","42.04221","0.08872"
"505.00800","42.08418","0.08817"
"505.51200","42.12615","0.08845"
"506.01600","42.16819","0.08852"
"506.52000","42.21015","0.08911"
"507.02400","42.25219","0.08910"
"507.52800","42.29422","0.08911"
"508.03200","42.33625","0.08941"
"508.53600","42.37828","0.08894"
"509.04000","42.42020","0.08931"
"509.54400","42.46223","0.08890"
"510.04800","42.50426","0.08901"
"510.55200","42.54623","0.08888"
"511.05600","42.58826","0.08927"
"511.56000","42.63023","0.08918"
"512.06400","42.67221","0.08986"
"512.56800","42.71418","0.08995"
"513.07200","42.75621","0.08972"
"513.57600","42.79812","0.08922"
"514.08000","42.84015","0.08950"
"514.58400","42.88219","0.08910"
"515.08800","42.92416","0.08947"
"515.59200","42.96619","0.08920"
"516.09600","43.00822","0.08900"
"516.60000","43.05020","0.08925"
"517.10400","43.09223","0.08841"
"517.60800","43.13420","0.08949"
"518.11200","43.17623","0.08919"
"518.61600","43.21821","0.08878"
"519.12000","43.26030","0.08931"
"519.62400","43.30221","0.08892"
"520.12800","43.34424","0.08876"
"520.63200","43.38622","0.08868"
"521.13600","43.42818","0.08888"
"521.64000","43.47010","0.08862"
"522.14400","43.51219","0.08879"
"522.64800","43.55416","0.08874"
"523.15200","43.59620","0.08941"
"523.65600","43.63823","0.08932"
"524.16000","43.68026","0.08900"
"524.66400","43.72223","0.08950"
"525.16800","43.76426","0.08957"
"525.67200","43.80618","0.08948"
"526.17600","43.84821","0.08895"
"526.68000","43.89024","0.08911"
"527.18400","43.93227","0.08863"
"527.68800","43.97424","0.08864"
"528.19200","44.01616","0.08865"
"528.69600","44.05819","0.08894"
"529.20000","44.10022","0.08871"
"529.70400","44.14214","0.08907"
"530.20800","44.18411","0.08900"
"530.71200","44.22620","0.08906"
"531.21600","44.26817","0.08907"
"531.72000","44.31026","0.08896"
"532.22400","44.35223","0.08932"
"532.72800","44.39421","0.08947"
"533.23200","44.43623","0.08952"
"533.73600","44.47827","0.08914"
"534.24000","44.52018","0.08904"
"534.74400","44.56227","0.08940"
"535.24800","44.60424","0.08909"
"535.75200","44.64622","0.08931"
"536.25600","44.68819","0.08907"
"536.76000","44.73016","0.08991"
"537.26400","44.77220","0.08965"
"537.76800","44.81423","0.08961"
"538.27200","44.85614","0.08975"
"538.77600","44.89817","0.09005"
"539.28000","44.94021","0.08970"
"539.78400","44.98224","0.09008"
"540.28800","45.02421","0.08972"
"540.79200","45.06624","0.09030"
"541.29600","45.10822","0.09086"
"541.80000","45.15024","0.09018"
"542.30400","45.19216","0.09086"
"542.80800","45.23419","0.09102"
"543.31200","45.27623","0.09127"
"543.81600","45.31820","0.09081"
"544.32000","45.36022","0.09041"
"544.82400","45.40220","0.09056"
"545.32800","45.44417","0.09069"
"545.83200","45.48621","0.09076"
"546.33600","45.52818","0.08986"
"546.84000","45.57021","0.09005"
"547.34400","45.61218","0.08959"
"547.84800","45.65421","0.09056"
"548.35200","45.69624","0.09042"
"548.85600","45.73822","0.09048"
"549.36000","45.78025","0.09080"
"549.86400","45.82222","0.09057"
"550.36800","45.86425","0.09073"
"550.87200","45.90616","0.09052"
"551.37600","45.94826","0.09093"
"551.88000","45.99023","0.09078"
"552.38400","46.03220","0.09132"
"552.88800","46.07412","0.09059"
"553.39200","46.11621","0.09099"
"553.89600","46.15818","0.09121"
"554.40000","46.20021","0.09048"
"554.90400","46.24218","0.09049"
"555.40800","46.28421","0.08512"
"555.91200","46.32624","0.08054"
"556.41600","46.36828","0.08444"
"556.92000","46.41025","0.08152"
"557.42400","46.45222","0.08096"
"557.92800","46.49420","0.08431"
"558.43200","46.53629","0.08107"
"558.93600","46.57820","0.08148"
"559.44000","46.62023","0.08358"
"559.94400","46.66220","0.08280"
"560.44800","46.70423","0.08232"
"560.95200","46.74615","0.08235"
"561.45600","46.78818","0.08438"
"561.96000","46.83015","0.08316"
"562.46400","46.87218","0.08285"
"562.96800","46.91422","0.08302"
"563.47200","46.95625","0.08379"
"563.97600","46.99822","0.08398"
"564.48000","47.04019","0.08428"
"564.98400","47.08223","0.08413"
"565.48800","47.12420","0.08434"
"565.99200","47.16623","0.08453"
"566.49600","47.20826","0.08453"
"567.00000","47.25023","0.08447"
"567.50400","47.29221","0.08533"
"568.00800","47.33418","0.08436"
"568.51200","47.37621","0.08525"
"569.01600","47.41818","0.08500"
"569.52000","47.46016","0.08503"
"570.02400","47.50218","0.08540"
"570.52800","47.54422","0.08591"
"571.03200","47.58619","0.08515"
"571.53600","47.62817","0.08590"
"572.04000","47.67025","0.08566"
"572.54400","47.71229","0.08596"
"573.04800","47.75426","0.08561"
"573.55200","47.79623","0.08600"
"574.05600","47.83826","0.08598"
"574.56000","47.88023","0.08612"
"575.06400","47.92226","0.08567"
"575.56800","47.96418","0.08604"
"576.07200","48.00627","0.08672"
"576.57600","48.04818","0.08621"
"577.08000","48.09022","0.08665"
"577.58400","48.13213","0.08673"
"578.08800","48.17422","0.08725"
"578.59200","48.21619","0.08689"
"579.09600","48.25822","0.08691"
"579.60000","48.30014","0.08692"
"580.10400","48.34217","0.08713"
"580.60800","48.38426","0.08699"
"581.11200","48.42624","0.08767"
"581.61600","48.46820","0.08698"
"582.12000","48.51024","0.08569"
"582.62400","48.55227","0.08619"
"583.12800","48.59424","0.08604"
"583.63200","48.63622","0.08644"
"584.13600","48.67818","0.08620"
"584.64000","48.72016","0.08645"
"585.14400","48.76219","0.08701"
"585.64800","48.80416","0.08755"
"586.15200","48.84619","0.08731"
"586.65600","48.88823","0.08764"
"587.16000","48.93020","0.08730"
"587.66400","48.97218","0.08688"
"588.16800","49.01420","0.08802"
"588.67200","49.05624","0.08766"
"589.17600","49.09821","0.08707"
"589.68000","49.14024","0.08755"
"590.18400","49.18221","0.08798"
"590.68800","49.22424","0.08816"
"591.19200","49.26622","0.08848"
"591.69600","49.30825","0.08829"
"592.20000","49.35022","0.08851"
"592.70400","49.39219","0.08821"
"593.20800","49.43416","0.08904"
"593.71200","49.47614","0.08910"
"594.21600","49.51817","0.08816"
"594.72000","49.56020","0.08879"
"595.22400","49.60224","0.08852"
"595.72800","49.64421","0.08748"
"596.23200","49.68618","0.08906"
"596.73600","49.72821","0.08861"
"597.24000","49.77024","0.08894"
"597.74400","49.81222","0.08975"
"598.24800","49.85419","0.08950"
"598.75200","49.89628","0.08964"
"599.25600","49.93819","0.08807"
"599.76000","49.98023","0.08874"
"600.26400","50.02214","0.08849"
"600.76800","50.06417","0.08876"
"601.27200","50.10620","0.08873"
"601.77600","50.14824","0.08895"
"602.28000","50.19020","0.08901"
"602.78400","50.23218","0.08989"
"603.28800","50.27421","0.08954"
"603.79200","50.31624","0.08948"
"604.29600","50.35822","0.08953"
"604.80000","50.40024","0.08997"
"605.30400","50.44222","0.08996"
"605.80800","50.48425","0.09009"
"606.31200","50.52622","0.08996"
"606.81600","50.56825","0.09062"
"607.32000","50.61023","0.09029"
"607.82400","50.65219","0.08953"
"608.32800","50.69417","0.08980"
"608.83200","50.73615","0.08982"
"609.33600","50.77817","0.09030"
"609.84000","50.82021","0.09081"
"610.34400","50.86218","0.09050"
"610.84800","50.90421","0.09080"
"611.35200","50.94624","0.09026"
"611.85600","50.98822","0.09050"
"612.36000","51.03025","0.09013"
"612.86400","51.07222","0.09045"
"613.36800","51.11425","0.09074"
"613.87200","51.15623","0.09124"
"614.37600","51.19826","0.09132"
"614.88000","51.24017","0.09132"
"615.38400","51.28226","0.09155"
"615.88800","51.32417","0.09140"
"616.39200","51.36615","0.09096"
"616.89600","51.40818","0.09120"
"617.40000","51.45021","0.09109"
"617.90400","51.49218","0.09157"
"618.40800","51.53421","0.09130"
"618.91200","51.57618","0.09151"
"619.41600","51.61827","0.09111"
"619.92000","51.66025","0.09194"
"620.42400","51.70228","0.09243"
"620.92800","51.74425","0.09171"
"621.43200","51.78623","0.09197"
"621.93600","51.82820","0.09197"
"622.44000","51.87029","0.09253"
"622.94400","51.91220","0.09256"
"623.44800","51.95417","0.09302"
"623.95200","51.99620","0.09271"
"624.45600","52.03824","0.09189"
"624.96000","52.08015","0.09282"
"625.46400","52.12218","0.09275"
"625.96800","52.16416","0.09275"
"626.47200","52.20618","0.09323"
"626.97600","52.24816","0.09325"
"627.48000","52.29019","0.09295"
"627.98400","52.33223","0.09248"
"628.48800","52.37426","0.09274"
"628.99200","52.41623","0.09240"
"629.49600","52.45820","0.09263"
"630.00000","52.50023","0.09318"
"630.50400","52.54226","0.09307"
"631.00800","52.58424","0.09336"
"631.51200","52.62615","0.09262"
"632.01600","52.66818","0.09187"
"632.52000","52.71016","0.09234"
"633.02400","52.75219","0.09234"
"633.52800","52.79422","0.09256"
"634.03200","52.83625","0.09338"
"634.53600","52.87816","0.09252"
"635.04000","52.92025","0.09217"
"635.54400","52.96223","0.09171"
"636.04800","53.00426","0.09265"
"636.55200","53.04623","0.09275"
"637.05600","53.08820","0.09318"
"637.56000","53.13023","0.09382"
"638.06400","53.17226","0.09375"
"638.56800","53.21424","0.09441"
"639.07200","53.25621","0.09390"
"639.57600","53.29818","0.09480"
"640.08000","53.34021","0.09420"
"640.58400","53.38219","0.09476"
"641.08800","53.42416","0.09482"
"641.59200","53.46619","0.09522"
"642.09600","53.50822","0.09490"
"642.60000","53.55019","0.09508"
"643.10400","53.59229","0.09479"
"643.60800","53.63420","0.09509"
"644.11200","53.67624","0.09521"
"644.61600","53.71827","0.09598"
"645.12000","53.76024","0.09581"
"645.62400","53.80227","0.09567"
"646.12800","53.84424","0.09674"
"646.63200","53.88621","0.09684"
"647.13600","53.92819","0.09718"
"647.64000","53.97022","0.09703"
"648.14400","54.01225","0.09741"
"648.64800","54.05416","0.09746"
"649.15200","54.09619","0.09773"
"649.65600","54.13817","0.09798"
"650.16000","54.18020","0.09737"
"650.66400","54.22223","0.09739"
"651.16800","54.26426","0.09779"
"651.67200","54.30624","0.09726"
"652.17600","54.34821","0.09712"
"652.68000","54.39024","0.09779"
"653.18400","54.43221","0.09813"
"653.68800","54.47425","0.09820"
"654.19200","54.51622","0.09882"
"654.69600","54.55825","0.09867"
"655.20000","54.60022","0.09863"
"655.70400","54.64226","0.09772"
"656.20800","54.68423","0.09803"
"656.71200","54.72620","0.09870"
"657.21600","54.76817","0.09682"
"657.72000","54.81020","0.09655"
"658.22400","54.85218","0.09701"
"658.72800","54.89427","0.09719"
"659.23200","54.93618","0.09736"
"659.73600","54.97828","0.09684"
"660.24000","55.02024","0.09819"
"660.74400","55.06227","0.09801"
"661.24800","55.10419","0.09840"
"661.75200","55.14622","0.09848"
"662.25600","55.18826","0.09810"
"662.76000","55.23022","0.09866"
"663.26400","55.27220","0.09921"
"663.76800","55.31423","0.09783"
"664.27200","55.35614","0.09286"
"664.77600","55.39817","0.09369"
"665.28000","55.44020","0.09398"
"665.78400","55.48218","0.09475"
"666.28800","55.52415","0.09486"
"666.79200","55.56618","0.09508"
"667.29600","55.60821","0.09477"
"667.80000","55.65018","0.09565"
"668.30400","55.69221","0.09570"
"668.80800","55.73425","0.09640"
"669.31200","55.77622","0.09621"
"669.81600","55.81826","0.09701"
"670.32000","55.86023","0.09662"
"670.82400","55.90220","0.09729"
"671.32800","55.94423","0.09759"
"671.83200","55.98620","0.09739"
"672.33600","56.02818","0.09727"
"672.84000","56.07014","0.09852"
"673.34400","56.11218","0.09763"
"673.84800","56.15421","0.09719"
"674.35200","56.19625","0.09799"
"674.85600","56.23816","0.09807"
"675.36000","56.28031","0.09815"
"675.86400","56.32222","0.09905"
"676.36800","56.36425","0.09896"
"676.87200","56.40622","0.10006"
"677.37600","56.44826","0.09997"
"677.88000","56.49023","0.10062"
"678.38400","56.53226","0.09999"
"678.88800","56.57417","0.10092"
"679.39200","56.61620","0.10144"
"679.89600","56.65818","0.10137"
"680.40000","56.70021","0.10265"
"680.90400","56.74218","0.10245"
"681.40800","56.78415","0.10289"
"681.91200","56.82619","0.10306"
"682.41600","56.86821","0.10324"
"682.92000","56.91013","0.10321"
"683.42400","56.95222","0.10346"
"683.92800","56.99426","0.10286"
"684.43200","57.03622","0.10315"
"684.93600","57.07820","0.10372"
"685.44000","57.12017","0.10378"
"685.94400","57.16220","0.10395"
"686.44800","57.20424","0.10375"
"686.95200","57.24614","0.10391"
"687.45600","57.28818","0.10425"
"687.96000","57.33015","0.10379"
"688.46400","57.37218","0.10426"
"688.96800","57.41415","0.10414"
"689.47200","57.45619","0.10426"
"689.97600","57.49821","0.10401"
"690.48000","57.54025","0.10495"
"690.98400","57.58222","0.10498"
"691.48800","57.62420","0.10492"
"691.99200","57.66623","0.10472"
"692.49600","57.70820","0.10480"
"693.00000","57.75023","0.10449"
"693.50400","57.79220","0.10413"
"694.00800","57.83424","0.10384"
"694.51200","57.87621","0.10358"
"695.01600","57.91824","0.10390"
"695.52000","57.96015","0.10460"
"696.02400","58.00219","0.10441"
"696.52800","58.04416","0.10422"
"697.03200","58.08619","0.10379"
"697.53600","58.12822","0.10459"
"698.04000","58.17013","0.10451"
"698.54400","58.21217","0.10528"
"699.04800","58.25426","0.10342"
"699.55200","58.29623","0.10197"
"700.05600","58.33826","0.10208"
"700.56000","58.38023","0.10151"
"701.06400","58.42227","0.10117"
"701.56800","58.46424","0.10126"
"702.07200","58.50627","0.10149"
"702.57600","58.54819","0.10220"
"703.08000","58.59021","0.10200"
"703.58400","58.63213","0.10196"
"704.08800","58.67416","0.10195"
"704.59200","58.71613","0.10176"
"705.09600","58.75817","0.10196"
"705.60000","58.80020","0.10314"
"706.10400","58.84217","0.10270"
"706.60800","58.88420","0.10215"
"707.11200","58.92623","0.10315"
"707.61600","58.96821","0.10321"
"708.12000","59.01024","0.10415"
"708.62400","59.05221","0.10387"
"709.12800","59.09424","0.10417"
"709.63200","59.13627","0.10389"
"710.13600","59.17825","0.10445"
"710.64000","59.22028","0.10467"
"711.14400","59.26220","0.10462"
"711.64800","59.30422","0.10471"
"712.15200","59.34613","0.10549"
"712.65600","59.38823","0.10526"
"713.16000","59.43020","0.10583"
"713.66400","59.47217","0.10580"
"714.16800","59.51420","0.10581"
"714.67200","59.55624","0.10598"
"715.17600","59.59821","0.10601"
"715.68000","59.64024","0.10131"
"716.18400","59.68221","0.10215"
"716.68800","59.72425","0.10128"
"717.19200","59.76621","0.10055"
"717.69600","59.80825","0.09731"
"718.20000","59.85022","0.09519"
"718.70400","59.89220","0.09478"
"719.20800","59.93417","0.09430"
"719.71200","59.97626","0.09410"
"720.21600","60.01811","0.09519"
"720.72000","60.06014","0.09583"
"721.22400","60.10218","0.09701"
"721.72800","60.14421","0.09688"
"722.23200","60.18618","0.09802"
"722.73600","60.22821","0.09757"
"723.24000","60.27024","0.09698"
"723.74400","60.31221","0.09766"
"724.24800","60.35419","0.09767"
"724.75200","60.39622","0.09768"
"725.25600","60.43825","0.09762"
"725.76000","60.48028","0.09777"
"726.26400","60.52226","0.09706"
"726.76800","60.56423","0.09653"
"727.27200","60.60620","0.09669"
"727.77600","60.64817","0.09603"
"728.28000","60.69014","0.09574"
"728.78400","60.73218","0.09293"
"729.28800","60.77421","0.09180"
"729.79200","60.81618","0.09228"
"730.29600","60.85821","0.09309"
"730.80000","60.90019","0.09341"
"731.30400","60.94221","0.09438"
"731.80800","60.98425","0.09387"
"732.31200","61.02622","0.09432"
"732.81600","61.06820","0.09446"
"733.32000","61.11023","0.09450"
"733.82400","61.15220","0.09459"
"734.32800","61.19417","0.09461"
"734.83200","61.23620","0.09481"
"735.33600","61.27823","0.09537"
"735.84000","61.32014","0.09508"
"736.34400","61.36218","0.09506"
"736.84800","61.40415","0.09519"
"737.35200","61.44619","0.09554"
"737.85600","61.48828","0.09627"
"738.36000","61.53025","0.09649"
"738.86400","61.57215","0.09629"
"739.36800","61.61431","0.09635"
"739.87200","61.65622","0.09608"
"740.37600","61.69826","0.09647"
"740.88000","61.74017","0.09761"
"741.38400","61.78226","0.09733"
"741.88800","61.82423","0.09753"
"742.39200","61.86620","0.09700"
"742.89600","61.90818","0.09755"
"743.40000","61.95021","0.09681"
"743.90400","61.99218","0.09708"
"744.40800","62.03421","0.09706"
"744.91200","62.07619","0.09623"
"745.41600","62.11816","0.08726"
"745.92000","62.16019","0.08585"
"746.42400","62.20228","0.08704"
"746.92800","62.24419","0.08781"
"747.43200","62.28622","0.08697"
"747.93600","62.32826","0.08629"
"748.44000","62.37023","0.08670"
"748.94400","62.41220","0.08807"
"749.44800","62.45417","0.08859"
"749.95200","62.49621","0.08885"
"750.45600","62.53823","0.08874"
"750.96000","62.58020","0.08833"
"751.20600","62.60072","0.08861"