File: Force_trajectories/170122_2/Specimen_RawData_1.csv
End date,"1/22/2017"
Specimen label,"3CT_17"
Maximum Load,"0.70951",N

Time,Extension,Load
(s),(mm),(N)
"0.00000","0.00000","0.00575"
"0.11400","0.00496","0.00542"
"0.22800","0.01716","0.00688"
"0.34200","0.02852","0.00750"
"0.45600","0.03827","0.00857"
"0.57000","0.04771","0.00932"
"0.68400","0.05722","0.00952"
"0.79800","0.06678","0.00995"
"0.91200","0.07623","0.01068"
"1.02600","0.08568","0.01073"
"1.14000","0.09524","0.01124"
"1.25400","0.10475","0.01124"
"1.36800","0.11426","0.01144"
"1.48200","0.12376","0.01191"
"1.59600","0.13321","0.01199"
"1.71000","0.14272","0.01222"
"1.82400","0.15216","0.01276"
"1.93800","0.16173","0.01296"
"2.05200","0.17124","0.01368"
"2.16600","0.18068","0.01360"
"2.28000","0.19019","0.01378"
"2.39400","0.19970","0.01346"
"2.50800","0.20926","0.01441"
"2.62200","0.21871","0.01405"
"2.73600","0.22822","0.01418"
"2.85000","0.23772","0.01409"
"2.96400","0.24717","0.01469"
"3.07800","0.25674","0.01442"
"3.19200","0.26618","0.01492"
"3.30600","0.27569","0.01462"
"3.42000","0.28520","0.01508"
"3.53400","0.29470","0.01562"
"3.64800","0.30421","0.01515"
"3.76200","0.31372","0.01509"
"3.87600","0.32322","0.01558"
"3.99000","0.33273","0.01551"
"4.10400","0.34218","0.01604"
"4.21800","0.35174","0.01608"
"4.33200","0.36119","0.01593"
"4.44600","0.37070","0.01598"
"4.56000","0.38026","0.01632"
"4.67400","0.38977","0.01679"
"4.78800","0.39921","0.01700"
"4.90200","0.40866","0.01671"
"5.01600","0.41817","0.01640"
"5.13000","0.42767","0.01714"
"5.24400","0.43724","0.01722"
"5.35800","0.44669","0.01724"
"5.47200","0.45619","0.01804"
"5.58600","0.46570","0.01732"
"5.70000","0.47521","0.01755"
"5.81400","0.48465","0.01755"
"5.92800","0.49416","0.01830"
"6.04200","0.50373","0.01824"
"6.15600","0.51323","0.01841"
"6.27000","0.52274","0.01853"
"6.38400","0.53219","0.01883"
"6.49800","0.54169","0.01871"
"6.61200","0.55120","0.01875"
"6.72600","0.56071","0.01893"
"6.84000","0.57021","0.01892"
"6.95400","0.57966","0.01930"
"7.06800","0.58917","0.02004"
"7.18200","0.59873","0.01942"
"7.29600","0.60818","0.01950"
"7.41000","0.61775","0.01935"
"7.52400","0.62719","0.01987"
"7.63800","0.63670","0.02013"
"7.75200","0.64627","0.01993"
"7.86600","0.65571","0.02068"
"7.98000","0.66516","0.02046"
"8.09400","0.67467","0.02085"
"8.20800","0.68417","0.02071"
"8.32200","0.69374","0.02076"
"8.43600","0.70324","0.02028"
"8.55000","0.71269","0.02075"
"8.66400","0.72220","0.02159"
"8.77800","0.73170","0.02151"
"8.89200","0.74121","0.02203"
"9.00600","0.75072","0.02142"
"9.12000","0.76016","0.02176"
"9.23400","0.76961","0.02185"
"9.34800","0.77930","0.02194"
"9.46200","0.78874","0.02173"
"9.57600","0.79819","0.02220"
"9.69000","0.80764","0.02276"
"9.80400","0.81720","0.02307"
"9.91800","0.82677","0.02278"
"10.03200","0.83622","0.02261"
"10.14600","0.84566","0.02312"
"10.26000","0.85517","0.02311"
"10.37400","0.86468","0.02327"
"10.48800","0.87424","0.02268"
"10.60200","0.88375","0.02380"
"10.71600","0.89314","0.02382"
"10.83000","0.90264","0.02357"
"10.94400","0.91221","0.02402"
"11.05800","0.92178","0.02326"
"11.17200","0.93122","0.02458"
"11.28600","0.94067","0.02494"
"11.40000","0.95018","0.02459"
"11.51400","0.95968","0.02430"
"11.62800","0.96925","0.02452"
"11.74200","0.97869","0.02529"
"11.85600","0.98820","0.02538"
"11.97000","0.99771","0.02452"
"12.08400","1.00727","0.02509"
"12.19800","1.01678","0.02516"
"12.31200","1.02623","0.02568"
"12.42600","1.03567","0.02567"
"12.54000","1.04518","0.02568"
"12.65400","1.05469","0.02593"
"12.76800","1.06419","0.02611"
"12.88200","1.07370","0.02645"
"12.99600","1.08315","0.02655"
"13.11000","1.09271","0.02638"
"13.22400","1.10222","0.02649"
"13.33800","1.11173","0.02658"
"13.45200","1.12117","0.02676"
"13.56600","1.13068","0.02699"
"13.68000","1.14019","0.02697"
"13.79400","1.14975","0.02760"
"13.90800","1.15920","0.02756"
"14.02200","1.16865","0.02754"
"14.13600","1.17815","0.02797"
"14.25000","1.18778","0.02776"
"14.36400","1.19723","0.02802"
"14.47800","1.20667","0.02798"
"14.59200","1.21612","0.02824"
"14.70600","1.22575","0.02838"
"14.82000","1.23525","0.02861"
"14.93400","1.24476","0.02814"
"15.04800","1.25415","0.02889"
"15.16200","1.26365","0.02867"
"15.27600","1.27322","0.02896"
"15.39000","1.28272","0.02933"
"15.50400","1.29223","0.02962"
"15.61800","1.30162","0.02929"
"15.73200","1.31118","0.03004"
"15.84600","1.32075","0.02950"
"15.96000","1.33026","0.02979"
"16.07400","1.33976","0.02997"
"16.18800","1.34915","0.02981"
"16.30200","1.35872","0.02986"
"16.41600","1.36822","0.02994"
"16.53000","1.37773","0.03081"
"16.64400","1.38718","0.03074"
"16.75800","1.39662","0.03113"
"16.87200","1.40619","0.03100"
"16.98600","1.41570","0.03136"
"17.10000","1.42526","0.03120"
"17.21400","1.43471","0.03094"
"17.32800","1.44416","0.03107"
"17.44200","1.45372","0.03171"
"17.55600","1.46323","0.03151"
"17.67000","1.47274","0.03165"
"17.78400","1.48218","0.03171"
"17.89800","1.49169","0.03177"
"18.01200","1.50126","0.03232"
"18.12600","1.51070","0.03192"
"18.24000","1.52021","0.03228"
"18.35400","1.52966","0.03241"
"18.46800","1.53916","0.03254"
"18.58200","1.54873","0.03257"
"18.69600","1.55823","0.03286"
"18.81000","1.56768","0.03297"
"18.92400","1.57719","0.03283"
"19.03800","1.58669","0.03304"
"19.15200","1.59620","0.03306"
"19.26600","1.60571","0.03336"
"19.38000","1.61521","0.03334"
"19.49400","1.62460","0.03364"
"19.60800","1.63417","0.03378"
"19.72200","1.64373","0.03353"
"19.83600","1.65318","0.03375"
"19.95000","1.66269","0.03396"
"20.06400","1.67219","0.03406"
"20.17800","1.68176","0.03448"
"20.29200","1.69127","0.03445"
"20.40600","1.70071","0.03429"
"20.52000","1.71016","0.03438"
"20.63400","1.71973","0.03459"
"20.74800","1.72923","0.03458"
"20.86200","1.73874","0.03463"
"20.97600","1.74825","0.03513"
"21.09000","1.75769","0.03484"
"21.20400","1.76720","0.03505"
"21.31800","1.77671","0.03497"
"21.43200","1.78621","0.03508"
"21.54600","1.79572","0.03527"
"21.66000","1.80523","0.03516"
"21.77400","1.81467","0.03547"
"21.88800","1.82424","0.03575"
"22.00200","1.83369","0.03588"
"22.11600","1.84319","0.03620"
"22.23000","1.85270","0.03627"
"22.34400","1.86215","0.03592"
"22.45800","1.87171","0.03610"
"22.57200","1.88122","0.03642"
"22.68600","1.89072","0.03630"
"22.80000","1.90023","0.03688"
"22.91400","1.90968","0.03644"
"23.02800","1.91918","0.03654"
"23.14200","1.92869","0.03665"
"23.25600","1.93820","0.03687"
"23.37000","1.94776","0.03699"
"23.48400","1.95721","0.03697"
"23.59800","1.96666","0.03725"
"23.71200","1.97616","0.03742"
"23.82600","1.98567","0.03702"
"23.94000","1.99518","0.03757"
"24.05400","2.00468","0.03762"
"24.16800","2.01419","0.03733"
"24.28200","2.02364","0.03767"
"24.39600","2.03320","0.03746"
"24.51000","2.04271","0.03774"
"24.62400","2.05222","0.03799"
"24.73800","2.06166","0.03809"
"24.85200","2.07123","0.03823"
"24.96600","2.08080","0.03824"
"25.08000","2.09018","0.03823"
"25.19400","2.09969","0.03805"
"25.30800","2.10914","0.03815"
"25.42200","2.11870","0.03876"
"25.53600","2.12821","0.03851"
"25.65000","2.13772","0.03843"
"25.76400","2.14722","0.03882"
"25.87800","2.15667","0.03872"
"25.99200","2.16623","0.03878"
"26.10600","2.17574","0.03862"
"26.22000","2.18525","0.03875"
"26.33400","2.19469","0.03870"
"26.44800","2.20414","0.03930"
"26.56200","2.21377","0.03910"
"26.67600","2.22327","0.03924"
"26.79000","2.23266","0.03904"
"26.90400","2.24217","0.03961"
"27.01800","2.25167","0.03949"
"27.13200","2.26130","0.03966"
"27.24600","2.27075","0.03969"
"27.36000","2.28019","0.03980"
"27.47400","2.28964","0.03984"
"27.58800","2.29921","0.03990"
"27.70200","2.30871","0.04016"
"27.81600","2.31822","0.04036"
"27.93000","2.32767","0.04033"
"28.04400","2.33717","0.04044"
"28.15800","2.34668","0.04015"
"28.27200","2.35625","0.04050"
"28.38600","2.36569","0.04070"
"28.50000","2.37514","0.04064"
"28.61400","2.38465","0.04081"
"28.72800","2.39421","0.04089"
"28.84200","2.40372","0.04053"
"28.95600","2.41317","0.04071"
"29.07000","2.42267","0.04087"
"29.18400","2.43218","0.04093"
"29.29800","2.44174","0.04107"
"29.41200","2.45125","0.04155"
"29.52600","2.46070","0.04142"
"29.64000","2.47020","0.02043"
"29.75400","2.47965","0.02166"
"29.86800","2.48922","0.01977"
"29.98200","2.49872","0.01935"
"30.09600","2.50823","0.02128"
"30.21000","2.51762","0.02158"
"30.32400","2.52724","0.02135"
"30.43800","2.53675","0.02145"
"30.55200","2.54626","0.02293"
"30.66600","2.55570","0.02262"
"30.78000","2.56515","0.02370"
"30.89400","2.57472","0.02401"
"31.00800","2.58428","0.02371"
"31.12200","2.59367","0.02323"
"31.23600","2.60318","0.02383"
"31.35000","2.61268","0.02429"
"31.46400","2.62225","0.02420"
"31.57800","2.63176","0.02420"
"31.69200","2.64120","0.02496"
"31.80600","2.65065","0.02584"
"31.92000","2.66016","0.02601"
"32.03400","2.66972","0.02552"
"32.14800","2.67923","0.02612"
"32.26200","2.68868","0.02647"
"32.37600","2.69812","0.02635"
"32.49000","2.70769","0.02657"
"32.60400","2.71725","0.02626"
"32.71800","2.72676","0.02742"
"32.83200","2.73615","0.02771"
"32.94600","2.74571","0.02807"
"33.06000","2.75522","0.02772"
"33.17400","2.76473","0.02781"
"33.28800","2.77423","0.02827"
"33.40200","2.78368","0.02832"
"33.51600","2.79325","0.02820"
"33.63000","2.80275","0.02840"
"33.74400","2.81226","0.02938"
"33.85800","2.82171","0.02930"
"33.97200","2.83115","0.02933"
"34.08600","2.84066","0.02929"
"34.20000","2.85023","0.03008"
"34.31400","2.85973","0.03014"
"34.42800","2.86918","0.03067"
"34.54200","2.87863","0.02997"
"34.65600","2.88819","0.03020"
"34.77000","2.89770","0.03060"
"34.88400","2.90727","0.03089"
"34.99800","2.91665","0.03077"
"35.11200","2.92610","0.03094"
"35.22600","2.93573","0.03158"
"35.34000","2.94523","0.03153"
"35.45400","2.95474","0.03201"
"35.56800","2.96419","0.03155"
"35.68200","2.97363","0.03193"
"35.79600","2.98320","0.03223"
"35.91000","2.99271","0.03225"
"36.02400","3.00215","0.03254"
"36.13800","3.01166","0.03216"
"36.25200","3.02117","0.03310"
"36.36600","3.03067","0.03324"
"36.48000","3.04024","0.03327"
"36.59400","3.04968","0.03303"
"36.70800","3.05913","0.03358"
"36.82200","3.06876","0.03383"
"36.93600","3.07820","0.03391"
"37.05000","3.08771","0.03374"
"37.16400","3.09716","0.03393"
"37.27800","3.10666","0.03448"
"37.39200","3.11623","0.03419"
"37.50600","3.12574","0.03424"
"37.62000","3.13524","0.03468"
"37.73400","3.14469","0.03470"
"37.84800","3.15420","0.03506"
"37.96200","3.16370","0.03476"
"38.07600","3.17327","0.03463"
"38.19000","3.18272","0.03549"
"38.30400","3.19216","0.03545"
"38.41800","3.20167","0.03504"
"38.53200","3.21118","0.03561"
"38.64600","3.22074","0.03593"
"38.76000","3.23019","0.03578"
"38.87400","3.23970","0.03604"
"38.98800","3.24920","0.03598"
"39.10200","3.25871","0.03602"
"39.21600","3.26822","0.03649"
"39.33000","3.27766","0.03681"
"39.44400","3.28717","0.03642"
"39.55800","3.29668","0.03630"
"39.67200","3.30624","0.03660"
"39.78600","3.31575","0.03690"
"39.90000","3.32520","0.03709"
"40.01400","3.33470","0.03686"
"40.12800","3.34421","0.03714"
"40.24200","3.35365","0.03737"
"40.35600","3.36322","0.03721"
"40.47000","3.37267","0.03745"
"40.58400","3.38223","0.03758"
"40.69800","3.39174","0.03788"
"40.81200","3.40119","0.03770"
"40.92600","3.41063","0.03780"
"41.04000","3.42020","0.03766"
"41.15400","3.42971","0.03831"
"41.26800","3.43921","0.03814"
"41.38200","3.44866","0.03848"
"41.49600","3.45817","0.03823"
"41.61000","3.46773","0.03876"
"41.72400","3.47718","0.03852"
"41.83800","3.48675","0.03868"
"41.95200","3.49619","0.03888"
"42.06600","3.50570","0.03921"
"42.18000","3.51527","0.03901"
"42.29400","3.52471","0.03892"
"42.40800","3.53422","0.03918"
"42.52200","3.54367","0.03941"
"42.63600","3.55323","0.03931"
"42.75000","3.56274","0.03943"
"42.86400","3.57219","0.03925"
"42.97800","3.58169","0.03921"
"43.09200","3.59114","0.03964"
"43.20600","3.60070","0.03987"
"43.32000","3.61027","0.03983"
"43.43400","3.61972","0.04018"
"43.54800","3.62916","0.03999"
"43.66200","3.63867","0.04022"
"43.77600","3.64824","0.04059"
"43.89000","3.65768","0.04042"
"44.00400","3.66719","0.04067"
"44.11800","3.67670","0.04100"
"44.23200","3.68620","0.04092"
"44.34600","3.69571","0.04063"
"44.46000","3.70522","0.04131"
"44.57400","3.71472","0.04155"
"44.68800","3.72423","0.04141"
"44.80200","3.73368","0.04134"
"44.91600","3.74318","0.04154"
"45.03000","3.75269","0.04226"
"45.14400","3.76220","0.04180"
"45.25800","3.77164","0.04191"
"45.37200","3.78121","0.04249"
"45.48600","3.79072","0.04284"
"45.60000","3.80022","0.04300"
"45.71400","3.80967","0.04239"
"45.82800","3.81918","0.04302"
"45.94200","3.82874","0.04326"
"46.05600","3.83819","0.04377"
"46.17000","3.84770","0.04457"
"46.28400","3.85720","0.04417"
"46.39800","3.86671","0.04462"
"46.51200","3.87622","0.04436"
"46.62600","3.88572","0.04483"
"46.74000","3.89517","0.04465"
"46.85400","3.90462","0.04574"
"46.96800","3.91418","0.04530"
"47.08200","3.92375","0.04567"
"47.19600","3.93319","0.04588"
"47.31000","3.94270","0.04639"
"47.42400","3.95215","0.04609"
"47.53800","3.96165","0.04630"
"47.65200","3.97128","0.04679"
"47.76600","3.98067","0.04755"
"47.88000","3.99017","0.04758"
"47.99400","3.99962","0.04798"
"48.10800","4.00925","0.04817"
"48.22200","4.01869","0.04826"
"48.33600","4.02820","0.04885"
"48.45000","4.03771","0.04900"
"48.56400","4.04715","0.04912"
"48.67800","4.05672","0.04986"
"48.79200","4.06617","0.05043"
"48.90600","4.07567","0.05050"
"49.02000","4.08518","0.05070"
"49.13400","4.09469","0.05093"
"49.24800","4.10419","0.05179"
"49.36200","4.11370","0.05207"
"49.47600","4.12315","0.05221"
"49.59000","4.13265","0.05220"
"49.70400","4.14216","0.05312"
"49.81800","4.15167","0.05311"
"49.93200","4.16123","0.05389"
"50.04600","4.17062","0.05413"
"50.16000","4.18013","0.05497"
"50.27400","4.18969","0.05485"
"50.38800","4.19926","0.05488"
"50.50200","4.20876","0.05563"
"50.61600","4.21815","0.05653"
"50.73000","4.22766","0.05699"
"50.84400","4.23728","0.05703"
"50.95800","4.24673","0.05694"
"51.07200","4.25618","0.05781"
"51.18600","4.26562","0.05784"
"51.30000","4.27519","0.05801"
"51.41400","4.28470","0.05877"
"51.52800","4.29426","0.05939"
"51.64200","4.30371","0.06011"
"51.75600","4.31316","0.05964"
"51.87000","4.32272","0.06018"
"51.98400","4.33223","0.06148"
"52.09800","4.34174","0.06190"
"52.21200","4.35118","0.06167"
"52.32600","4.36063","0.06238"
"52.44000","4.37026","0.06334"
"52.55400","4.37976","0.06339"
"52.66800","4.38921","0.06348"
"52.78200","4.39866","0.06442"
"52.89600","4.40822","0.06496"
"53.01000","4.41773","0.06493"
"53.12400","4.42724","0.06519"
"53.23800","4.43674","0.06566"
"53.35200","4.44613","0.06638"
"53.46600","4.45564","0.06632"
"53.58000","4.46520","0.06680"
"53.69400","4.47477","0.06719"
"53.80800","4.48416","0.06772"
"53.92200","4.49366","0.06797"
"54.03600","4.50323","0.06796"
"54.15000","4.51273","0.06877"
"54.26400","4.52224","0.06899"
"54.37800","4.53169","0.06926"
"54.49200","4.54119","0.06963"
"54.60600","4.55070","0.07033"
"54.72000","4.56027","0.07057"
"54.83400","4.56971","0.07078"
"54.94800","4.57922","0.07114"
"55.06200","4.58873","0.07189"
"55.17600","4.59817","0.07202"
"55.29000","4.60774","0.07233"
"55.40400","4.61719","0.07235"
"55.51800","4.62663","0.07333"
"55.63200","4.63620","0.07336"
"55.74600","4.64565","0.07401"
"55.86000","4.65521","0.07418"
"55.97400","4.66472","0.07459"
"56.08800","4.67417","0.07520"
"56.20200","4.68373","0.07534"
"56.31600","4.69324","0.07562"
"56.43000","4.70269","0.07644"
"56.54400","4.71219","0.07681"
"56.65800","4.72170","0.07708"
"56.77200","4.73121","0.07765"
"56.88600","4.74071","0.07810"
"57.00000","4.75022","0.07882"
"57.11400","4.75967","0.07893"
"57.22800","4.76917","0.07949"
"57.34200","4.77868","0.08036"
"57.45600","4.78819","0.08079"
"57.57000","4.79769","0.08155"
"57.68400","4.80720","0.08212"
"57.79800","4.81670","0.08301"
"57.91200","4.82621","0.08299"
"58.02600","4.83572","0.08403"
"58.14000","4.84516","0.08374"
"58.25400","4.85467","0.08456"
"58.36800","4.86418","0.08474"
"58.48200","4.87368","0.08547"
"58.59600","4.88319","0.08537"
"58.71000","4.89264","0.08622"
"58.82400","4.90220","0.08601"
"58.93800","4.91171","0.08643"
"59.05200","4.92122","0.08662"
"59.16600","4.93072","0.08776"
"59.28000","4.94023","0.08738"
"59.39400","4.94974","0.08793"
"59.50800","4.95918","0.08808"
"59.62200","4.96869","0.08792"
"59.73600","4.97814","0.08841"
"59.85000","4.98770","0.08863"
"59.96400","4.99727","0.08911"
"60.07800","5.00672","0.08949"
"60.19200","5.01622","0.08962"
"60.30600","5.02567","0.08984"
"60.42000","5.03524","0.09016"
"60.53400","5.04474","0.09028"
"60.64800","5.05419","0.09034"
"60.76200","5.06369","0.09038"
"60.87600","5.07314","0.09054"
"60.99000","5.08277","0.09059"
"61.10400","5.09227","0.09086"
"61.21800","5.10172","0.09085"
"61.33200","5.11117","0.09104"
"61.44600","5.12067","0.09105"
"61.56000","5.13018","0.09097"
"61.67400","5.13975","0.09120"
"61.78800","5.14919","0.09144"
"61.90200","5.15870","0.09138"
"62.01600","5.16815","0.09175"
"62.13000","5.17771","0.09162"
"62.24400","5.18722","0.09180"
"62.35800","5.19667","0.09187"
"62.47200","5.20617","0.09228"
"62.58600","5.21568","0.09255"
"62.70000","5.22525","0.09273"
"62.81400","5.23469","0.09288"
"62.92800","5.24420","0.09287"
"63.04200","5.25365","0.09337"
"63.15600","5.26321","0.09309"
"63.27000","5.27278","0.09350"
"63.38400","5.28223","0.09417"
"63.49800","5.29167","0.09447"
"63.61200","5.30118","0.09489"
"63.72600","5.31075","0.09537"
"63.84000","5.32019","0.09620"
"63.95400","5.32970","0.09626"
"64.06800","5.33921","0.09694"
"64.18200","5.34871","0.09750"
"64.29600","5.35828","0.09806"
"64.41000","5.36772","0.09820"
"64.52400","5.37717","0.09959"
"64.63800","5.38668","0.10037"
"64.75200","5.39618","0.10069"
"64.86600","5.40575","0.10189"
"64.98000","5.41520","0.10265"
"65.09400","5.42464","0.10297"
"65.20800","5.43421","0.10390"
"65.32200","5.44372","0.10458"
"65.43600","5.45322","0.10534"
"65.55000","5.46267","0.10585"
"65.66400","5.47218","0.10633"
"65.77800","5.48168","0.10751"
"65.89200","5.49125","0.10853"
"66.00600","5.50076","0.10842"
"66.12000","5.51020","0.10922"
"66.23400","5.51965","0.11007"
"66.34800","5.52922","0.11159"
"66.46200","5.53878","0.11132"
"66.57600","5.54823","0.11228"
"66.69000","5.55768","0.11316"
"66.80400","5.56712","0.11311"
"66.91800","5.57669","0.11359"
"67.03200","5.58626","0.11430"
"67.14600","5.59570","0.11516"
"67.26000","5.60515","0.11535"
"67.37400","5.61466","0.11601"
"67.48800","5.62422","0.11698"
"67.60200","5.63373","0.11748"
"67.71600","5.64324","0.11800"
"67.83000","5.65262","0.11847"
"67.94400","5.66219","0.11876"
"68.05800","5.67175","0.11962"
"68.17200","5.68120","0.11968"
"68.28600","5.69071","0.12011"
"68.40000","5.70015","0.12102"
"68.51400","5.70972","0.12126"
"68.62800","5.71923","0.12153"
"68.74200","5.72873","0.12219"
"68.85600","5.73818","0.12213"
"68.97000","5.74763","0.12253"
"69.08400","5.75725","0.12287"
"69.19800","5.76670","0.12360"
"69.31200","5.77621","0.12401"
"69.42600","5.78565","0.12412"
"69.54000","5.79522","0.12462"
"69.65400","5.80479","0.12480"
"69.76800","5.81423","0.12492"
"69.88200","5.82374","0.12519"
"69.99600","5.83319","0.12567"
"70.11000","5.84263","0.12599"
"70.22400","5.85226","0.12609"
"70.33800","5.86177","0.12642"
"70.45200","5.87121","0.12652"
"70.56600","5.88060","0.12666"
"70.68000","5.89017","0.12709"
"70.79400","5.89973","0.12741"
"70.90800","5.90924","0.12769"
"71.02200","5.91869","0.12782"
"71.13600","5.92813","0.12807"
"71.25000","5.93770","0.12848"
"71.36400","5.94726","0.12845"
"71.47800","5.95677","0.12933"
"71.59200","5.96616","0.12931"
"71.70600","5.97566","0.12959"
"71.82000","5.98523","0.12973"
"71.93400","5.99474","0.13023"
"72.04800","6.00424","0.13018"
"72.16200","6.01363","0.13091"
"72.27600","6.02320","0.13141"
"72.39000","6.03270","0.13182"
"72.50400","6.04227","0.13168"
"72.61800","6.05172","0.13234"
"72.73200","6.06116","0.13235"
"72.84600","6.07073","0.13330"
"72.96000","6.08024","0.13328"
"73.07400","6.08968","0.13349"
"73.18800","6.09919","0.13368"
"73.30200","6.10864","0.13392"
"73.41600","6.11820","0.13443"
"73.53000","6.12771","0.13491"
"73.64400","6.13722","0.13544"
"73.75800","6.14672","0.13556"
"73.87200","6.15623","0.13603"
"73.98600","6.16574","0.13625"
"74.10000","6.17518","0.13637"
"74.21400","6.18475","0.13718"
"74.32800","6.19420","0.13736"
"74.44200","6.20370","0.13742"
"74.55600","6.21321","0.13827"
"74.67000","6.22266","0.13826"
"74.78400","6.23222","0.13858"
"74.89800","6.24167","0.13870"
"75.01200","6.25117","0.13908"
"75.12600","6.26068","0.13944"
"75.24000","6.27013","0.13992"
"75.35400","6.27969","0.13993"
"75.46800","6.28920","0.14055"
"75.58200","6.29871","0.14044"
"75.69600","6.30821","0.14119"
"75.81000","6.31772","0.14145"
"75.92400","6.32723","0.14136"
"76.03800","6.33673","0.14192"
"76.15200","6.34618","0.14201"
"76.26600","6.35569","0.14260"
"76.38000","6.36519","0.14286"
"76.49400","6.37470","0.14299"
"76.60800","6.38421","0.14331"
"76.72200","6.39371","0.14364"
"76.83600","6.40322","0.14418"
"76.95000","6.41267","0.14451"
"77.06400","6.42217","0.14513"
"77.17800","6.43174","0.14553"
"77.29200","6.44125","0.14585"
"77.40600","6.45069","0.14610"
"77.52000","6.46014","0.14642"
"77.63400","6.46971","0.14704"
"77.74800","6.47921","0.14791"
"77.86200","6.48872","0.14843"
"77.97600","6.49823","0.14881"
"78.09000","6.50767","0.14934"
"78.20400","6.51724","0.15052"
"78.31800","6.52675","0.15020"
"78.43200","6.53625","0.15082"
"78.54600","6.54564","0.15225"
"78.66000","6.55520","0.15206"
"78.77400","6.56471","0.15316"
"78.88800","6.57422","0.15441"
"79.00200","6.58366","0.15524"
"79.11600","6.59311","0.15542"
"79.23000","6.60274","0.15639"
"79.34400","6.61224","0.15753"
"79.45800","6.62169","0.15830"
"79.57200","6.63120","0.15884"
"79.68600","6.64064","0.15993"
"79.80000","6.65021","0.16128"
"79.91400","6.65978","0.16230"
"80.02800","6.66922","0.16264"
"80.14200","6.67867","0.16502"
"80.25600","6.68818","0.16586"
"80.37000","6.69774","0.16803"
"80.48400","6.70725","0.16800"
"80.59800","6.71676","0.16968"
"80.71200","6.72620","0.17002"
"80.82600","6.73565","0.17165"
"80.94000","6.74522","0.17321"
"81.05400","6.75472","0.17451"
"81.16800","6.76423","0.17543"
"81.28200","6.77368","0.17827"
"81.39600","6.78318","0.17889"
"81.51000","6.79275","0.17913"
"81.62400","6.80220","0.18077"
"81.73800","6.81170","0.18171"
"81.85200","6.82115","0.18432"
"81.96600","6.83072","0.18452"
"82.08000","6.84028","0.18546"
"82.19400","6.84967","0.18582"
"82.30800","6.85923","0.18687"
"82.42200","6.86868","0.18675"
"82.53600","6.87819","0.18656"
"82.65000","6.88775","0.18755"
"82.76400","6.89720","0.18913"
"82.87800","6.90671","0.18964"
"82.99200","6.91621","0.19030"
"83.10600","6.92578","0.19107"
"83.22000","6.93517","0.19108"
"83.33400","6.94461","0.19154"
"83.44800","6.95418","0.19180"
"83.56200","6.96369","0.19261"
"83.67600","6.97325","0.19329"
"83.79000","6.98270","0.19346"
"83.90400","6.99215","0.19394"
"84.01800","7.00165","0.19407"
"84.13200","7.01122","0.19491"
"84.24600","7.02079","0.19496"
"84.36000","7.03023","0.19533"
"84.47400","7.03962","0.19640"
"84.58800","7.04919","0.19608"
"84.70200","7.05875","0.19602"
"84.81600","7.06826","0.19726"
"84.93000","7.07771","0.19766"
"85.04400","7.08721","0.19836"
"85.15800","7.09672","0.19879"
"85.27200","7.10623","0.20005"
"85.38600","7.11573","0.19998"
"85.50000","7.12518","0.20127"
"85.61400","7.13463","0.20164"
"85.72800","7.14419","0.20216"
"85.84200","7.15376","0.20339"
"85.95600","7.16326","0.20491"
"86.07000","7.17271","0.20606"
"86.18400","7.18216","0.20670"
"86.29800","7.19172","0.20805"
"86.41200","7.20123","0.20886"
"86.52600","7.21074","0.20959"
"86.64000","7.22012","0.21059"
"86.75400","7.22963","0.21146"
"86.86800","7.23926","0.21308"
"86.98200","7.24876","0.21298"
"87.09600","7.25821","0.21425"
"87.21000","7.26766","0.21490"
"87.32400","7.27716","0.21614"
"87.43800","7.28673","0.21668"
"87.55200","7.29624","0.21763"
"87.66600","7.30568","0.21876"
"87.78000","7.31513","0.21964"
"87.89400","7.32470","0.22076"
"88.00800","7.33420","0.22104"
"88.12200","7.34377","0.22236"
"88.23600","7.35322","0.22294"
"88.35000","7.36266","0.22416"
"88.46400","7.37223","0.22489"
"88.57800","7.38174","0.22584"
"88.69200","7.39124","0.22641"
"88.80600","7.40069","0.22718"
"88.92000","7.41020","0.22805"
"89.03400","7.41976","0.22932"
"89.14800","7.42927","0.22980"
"89.26200","7.43878","0.23025"
"89.37600","7.44816","0.23102"
"89.49000","7.45767","0.23182"
"89.60400","7.46717","0.23243"
"89.71800","7.47674","0.23348"
"89.83200","7.48619","0.23413"
"89.94600","7.49563","0.23424"
"90.06000","7.50526","0.23503"
"90.17400","7.51471","0.23560"
"90.28800","7.52421","0.23591"
"90.40200","7.53372","0.23666"
"90.51600","7.54317","0.23698"
"90.63000","7.55273","0.23707"
"90.74400","7.56224","0.23755"
"90.85800","7.57175","0.23796"
"90.97200","7.58119","0.23827"
"91.08600","7.59070","0.23855"
"91.20000","7.60021","0.23892"
"91.31400","7.60971","0.23918"
"91.42800","7.61928","0.23959"
"91.54200","7.62867","0.23973"
"91.65600","7.63823","0.23994"
"91.77000","7.64768","0.24013"
"91.88400","7.65719","0.24043"
"91.99800","7.66669","0.24047"
"92.11200","7.67614","0.24069"
"92.22600","7.68571","0.24096"
"92.34000","7.69521","0.24120"
"92.45400","7.70466","0.24136"
"92.56800","7.71417","0.24177"
"92.68200","7.72367","0.24199"
"92.79600","7.73318","0.24207"
"92.91000","7.74274","0.24232"
"93.02400","7.75219","0.24261"
"93.13800","7.76170","0.24306"
"93.25200","7.77120","0.24324"
"93.36600","7.78071","0.24354"
"93.48000","7.79022","0.24383"
"93.59400","7.79972","0.24426"
"93.70800","7.80917","0.24428"
"93.82200","7.81874","0.24481"
"93.93600","7.82824","0.24513"
"94.05000","7.83775","0.24525"
"94.16400","7.84720","0.24554"
"94.27800","7.85670","0.24583"
"94.39200","7.86621","0.24609"
"94.50600","7.87578","0.24688"
"94.62000","7.88522","0.24724"
"94.73400","7.89467","0.24780"
"94.84800","7.90424","0.24874"
"94.96200","7.91368","0.24963"
"95.07600","7.92319","0.25039"
"95.19000","7.93270","0.25105"
"95.30400","7.94214","0.25199"
"95.41800","7.95171","0.25265"
"95.53200","7.96122","0.25436"
"95.64600","7.97072","0.25529"
"95.76000","7.98017","0.25624"
"95.87400","7.98967","0.25772"
"95.98800","7.99918","0.25802"
"96.10200","8.00869","0.25982"
"96.21600","8.01820","0.26084"
"96.33000","8.02764","0.26211"
"96.44400","8.03721","0.26223"
"96.55800","8.04671","0.26428"
"96.67200","8.05622","0.26574"
"96.78600","8.06573","0.26661"
"96.90000","8.07517","0.26707"
"97.01400","8.08474","0.26822"
"97.12800","8.09419","0.26945"
"97.24200","8.10375","0.27057"
"97.35600","8.11320","0.27126"
"97.47000","8.12271","0.27292"
"97.58400","8.13221","0.27376"
"97.69800","8.14172","0.27431"
"97.81200","8.15129","0.27491"
"97.92600","8.16067","0.27525"
"98.04000","8.17018","0.27698"
"98.15400","8.17969","0.27812"
"98.26800","8.18919","0.27916"
"98.38200","8.19870","0.28038"
"98.49600","8.20815","0.28084"
"98.61000","8.21771","0.28261"
"98.72400","8.22722","0.28357"
"98.83800","8.23667","0.28443"
"98.95200","8.24623","0.28508"
"99.06600","8.25568","0.28603"
"99.18000","8.26524","0.28669"
"99.29400","8.27475","0.28735"
"99.40800","8.28420","0.28750"
"99.52200","8.29370","0.28850"
"99.63600","8.30315","0.28879"
"99.75000","8.31272","0.28913"
"99.86400","8.32222","0.28975"
"99.97800","8.33167","0.29065"
"100.09200","8.34118","0.29127"
"100.20600","8.35068","0.29125"
"100.32000","8.36025","0.29227"
"100.43400","8.36970","0.29330"
"100.54800","8.37914","0.29397"
"100.66200","8.38865","0.29508"
"100.77600","8.39822","0.29593"
"100.89000","8.40772","0.29751"
"101.00400","8.41723","0.30019"
"101.11800","8.42668","0.30078"
"101.23200","8.43618","0.30299"
"101.34600","8.44569","0.30462"
"101.46000","8.45520","0.30684"
"101.57400","8.46476","0.30983"
"101.68800","8.47421","0.31153"
"101.80200","8.48372","0.31411"
"101.91600","8.49322","0.31517"
"102.03000","8.50273","0.31754"
"102.14400","8.51224","0.31954"
"102.25800","8.52168","0.32102"
"102.37200","8.53119","0.32268"
"102.48600","8.54076","0.32442"
"102.60000","8.55026","0.32670"
"102.71400","8.55965","0.32818"
"102.82800","8.56910","0.32909"
"102.94200","8.57872","0.33103"
"103.05600","8.58823","0.33230"
"103.17000","8.59773","0.33367"
"103.28400","8.60718","0.33479"
"103.39800","8.61663","0.33650"
"103.51200","8.62625","0.33804"
"103.62600","8.63576","0.33883"
"103.74000","8.64527","0.34040"
"103.85400","8.65471","0.34105"
"103.96800","8.66416","0.34202"
"104.08200","8.67373","0.34294"
"104.19600","8.68323","0.34360"
"104.31000","8.69274","0.34444"
"104.42400","8.70219","0.34508"
"104.53800","8.71163","0.34584"
"104.65200","8.72126","0.34603"
"104.76600","8.73077","0.34701"
"104.88000","8.74015","0.34744"
"104.99400","8.74960","0.34771"
"105.10800","8.75917","0.34810"
"105.22200","8.76873","0.34849"
"105.33600","8.77824","0.34865"
"105.45000","8.78769","0.34916"
"105.56400","8.79719","0.34917"
"105.67800","8.80676","0.34963"
"105.79200","8.81621","0.34956"
"105.90600","8.82571","0.34969"
"106.02000","8.83516","0.35023"
"106.13400","8.84467","0.35036"
"106.24800","8.85423","0.35058"
"106.36200","8.86380","0.35139"
"106.47600","8.87324","0.35149"
"106.59000","8.88263","0.35162"
"106.70400","8.89220","0.35194"
"106.81800","8.90170","0.35232"
"106.93200","8.91127","0.35289"
"107.04600","8.92066","0.35320"
"107.16000","8.93011","0.35365"
"107.27400","8.93967","0.35478"
"107.38800","8.94924","0.35490"
"107.50200","8.95874","0.35558"
"107.61600","8.96819","0.35552"
"107.73000","8.97764","0.35612"
"107.84400","8.98720","0.35661"
"107.95800","8.99671","0.35721"
"108.07200","9.00622","0.35802"
"108.18600","9.01566","0.35821"
"108.30000","9.02517","0.35898"
"108.41400","9.03474","0.35944"
"108.52800","9.04424","0.36076"
"108.64200","9.05375","0.36109"
"108.75600","9.06314","0.36209"
"108.87000","9.07264","0.36261"
"108.98400","9.08221","0.36355"
"109.09800","9.09172","0.36426"
"109.21200","9.10116","0.36560"
"109.32600","9.11067","0.36671"
"109.44000","9.12024","0.36793"
"109.55400","9.12974","0.36885"
"109.66800","9.13925","0.36946"
"109.78200","9.14870","0.37017"
"109.89600","9.15820","0.37181"
"110.01000","9.16771","0.37283"
"110.12400","9.17722","0.37426"
"110.23800","9.18672","0.37622"
"110.35200","9.19617","0.37742"
"110.46600","9.20568","0.37850"
"110.58000","9.21518","0.38059"
"110.69400","9.22475","0.38225"
"110.80800","9.23419","0.38333"
"110.92200","9.24370","0.38433"
"111.03600","9.25321","0.38548"
"111.15000","9.26271","0.38598"
"111.26400","9.27222","0.38797"
"111.37800","9.28167","0.38914"
"111.49200","9.29117","0.38956"
"111.60600","9.30074","0.39087"
"111.72000","9.31019","0.39300"
"111.83400","9.31975","0.39377"
"111.94800","9.32920","0.39423"
"112.06200","9.33871","0.39504"
"112.17600","9.34827","0.39589"
"112.29000","9.35766","0.39640"
"112.40400","9.36723","0.39696"
"112.51800","9.37667","0.39741"
"112.63200","9.38618","0.39811"
"112.74600","9.39575","0.39832"
"112.86000","9.40525","0.39893"
"112.97400","9.41470","0.39966"
"113.08800","9.42415","0.40033"
"113.20200","9.43371","0.40105"
"113.31600","9.44322","0.40197"
"113.43000","9.45272","0.40271"
"113.54400","9.46217","0.40360"
"113.65800","9.47168","0.40507"
"113.77200","9.48118","0.40672"
"113.88600","9.49075","0.40862"
"114.00000","9.50020","0.40968"
"114.11400","9.50964","0.41033"
"114.22800","9.51921","0.41261"
"114.34200","9.52872","0.41370"
"114.45600","9.53822","0.41533"
"114.57000","9.54773","0.41633"
"114.68400","9.55718","0.41699"
"114.79800","9.56674","0.41818"
"114.91200","9.57619","0.41933"
"115.02600","9.58570","0.42131"
"115.14000","9.59520","0.42167"
"115.25400","9.60465","0.42267"
"115.36800","9.61422","0.42415"
"115.48200","9.62372","0.42443"
"115.59600","9.63317","0.42519"
"115.71000","9.64268","0.42686"
"115.82400","9.65218","0.42809"
"115.93800","9.66175","0.42805"
"116.05200","9.67120","0.42919"
"116.16600","9.68070","0.42991"
"116.28000","9.69015","0.43117"
"116.39400","9.69972","0.43168"
"116.50800","9.70922","0.43241"
"116.62200","9.71873","0.43310"
"116.73600","9.72818","0.43334"
"116.85000","9.73768","0.43400"
"116.96400","9.74719","0.43433"
"117.07800","9.75675","0.43513"
"117.19200","9.76620","0.43514"
"117.30600","9.77571","0.43575"
"117.42000","9.78521","0.43622"
"117.53400","9.79472","0.43688"
"117.64800","9.80423","0.43702"
"117.76200","9.81367","0.43738"
"117.87600","9.82318","0.43774"
"117.99000","9.83269","0.43825"
"118.10400","9.84225","0.43870"
"118.21800","9.85176","0.43899"
"118.33200","9.86115","0.44003"
"118.44600","9.87065","0.44057"
"118.56000","9.88022","0.44114"
"118.67400","9.88973","0.44167"
"118.78800","9.89923","0.44253"
"118.90200","9.90868","0.44303"
"119.01600","9.91819","0.44477"
"119.13000","9.92775","0.44480"
"119.24400","9.93726","0.44597"
"119.35800","9.94671","0.44728"
"119.47200","9.95615","0.44799"
"119.58600","9.96566","0.44867"
"119.70000","9.97529","0.44905"
"119.81400","9.98473","0.45044"
"119.92800","9.99418","0.45086"
"120.04200","10.00363","0.45219"
"120.15600","10.01319","0.23875"
"120.27000","10.02276","0.19781"
"120.38400","10.03226","0.20636"
"120.49800","10.04165","0.23328"
"120.61200","10.05110","0.20475"
"120.72600","10.06073","0.20045"
"120.84000","10.07023","0.23812"
"120.95400","10.07974","0.20603"
"121.06800","10.08924","0.20387"
"121.18200","10.09869","0.21345"
"121.29600","10.10826","0.23878"
"121.41000","10.11776","0.20593"
"121.52400","10.12721","0.20708"
"121.63800","10.13666","0.24525"
"121.75200","10.14616","0.21964"
"121.86600","10.15573","0.21711"
"121.98000","10.16524","0.23603"
"122.09400","10.17468","0.24130"
"122.20800","10.18413","0.22430"
"122.32200","10.19370","0.22804"
"122.43600","10.20326","0.25716"
"122.55000","10.21271","0.23020"
"122.66400","10.22216","0.23567"
"122.77800","10.23160","0.24967"
"122.89200","10.24123","0.24020"
"123.00600","10.25074","0.23948"
"123.12000","10.26024","0.24336"
"123.23400","10.26969","0.25756"
"123.34800","10.27914","0.24025"
"123.46200","10.28870","0.24197"
"123.57600","10.29827","0.27736"
"123.69000","10.30778","0.24202"
"123.80400","10.31716","0.24402"
"123.91800","10.32667","0.28066"
"124.03200","10.33618","0.24856"
"124.14600","10.34574","0.24751"
"124.26000","10.35519","0.27741"
"124.37400","10.36463","0.26754"
"124.48800","10.37420","0.25483"
"124.60200","10.38377","0.27343"
"124.71600","10.39321","0.28459"
"124.83000","10.40272","0.26429"
"124.94400","10.41217","0.27240"
"125.05800","10.42173","0.29675"
"125.17200","10.43118","0.26922"
"125.28600","10.44075","0.27649"
"125.40000","10.45019","0.31323"
"125.51400","10.45964","0.27874"
"125.62800","10.46921","0.28397"
"125.74200","10.47871","0.32259"
"125.85600","10.48828","0.28666"
"125.97000","10.49767","0.28808"
"126.08400","10.50723","0.33068"
"126.19800","10.51674","0.29208"
"126.31200","10.52619","0.29195"
"126.42600","10.53563","0.33468"
"126.54000","10.54514","0.30687"
"126.65400","10.55471","0.29996"
"126.76800","10.56421","0.33907"
"126.88200","10.57372","0.32512"
"126.99600","10.58322","0.31301"
"127.11000","10.59267","0.34336"
"127.22400","10.60224","0.33635"
"127.33800","10.61175","0.32501"
"127.45200","10.62119","0.34625"
"127.56600","10.63070","0.34364"
"127.68000","10.64020","0.33608"
"127.79400","10.64971","0.34877"
"127.90800","10.65928","0.34738"
"128.02200","10.66873","0.34290"
"128.13600","10.67817","0.35027"
"128.25000","10.68774","0.34941"
"128.36400","10.69719","0.34699"
"128.47800","10.70669","0.35264"
"128.59200","10.71620","0.35094"
"128.70600","10.72564","0.34899"
"128.82000","10.73521","0.35607"
"128.93400","10.74472","0.35204"
"129.04800","10.75422","0.35063"
"129.16200","10.76367","0.36032"
"129.27600","10.77318","0.35446"
"129.39000","10.78274","0.35273"
"129.50400","10.79225","0.36624"
"129.61800","10.80170","0.35649"
"129.73200","10.81114","0.35636"
"129.84600","10.82071","0.37498"
"129.96000","10.83022","0.35932"
"130.07400","10.83972","0.35995"
"130.18800","10.84917","0.38419"
"130.30200","10.85868","0.36272"
"130.41600","10.86818","0.36558"
"130.53000","10.87769","0.39135"
"130.64400","10.88720","0.36668"
"130.75800","10.89670","0.37408"
"130.87200","10.90621","0.39407"
"130.98600","10.91572","0.37422"
"131.10000","10.92522","0.38672"
"131.21400","10.93473","0.39568"
"131.32800","10.94418","0.38296"
"131.44200","10.95374","0.39545"
"131.55600","10.96319","0.39623"
"131.67000","10.97276","0.39122"
"131.78400","10.98220","0.40045"
"131.89800","10.99171","0.39742"
"132.01200","11.00121","0.39568"
"132.12600","11.01072","0.40869"
"132.24000","11.02023","0.39828"
"132.35400","11.02967","0.39923"
"132.46800","11.03918","0.41618"
"132.58200","11.04869","0.40043"
"132.69600","11.05819","0.40522"
"132.81000","11.06770","0.41973"
"132.92400","11.07715","0.40526"
"133.03800","11.08671","0.41629"
"133.15200","11.09628","0.42092"
"133.26600","11.10573","0.41170"
"133.38000","11.11517","0.42583"
"133.49400","11.12468","0.42078"
"133.60800","11.13419","0.41851"
"133.72200","11.14375","0.43264"
"133.83600","11.15320","0.42292"
"133.95000","11.16271","0.42497"
"134.06400","11.17215","0.43467"
"134.17800","11.18166","0.42614"
"134.29200","11.19123","0.43231"
"134.40600","11.20073","0.43485"
"134.52000","11.21018","0.43020"
"134.63400","11.21969","0.43636"
"134.74800","11.22925","0.43505"
"134.86200","11.23870","0.43368"
"134.97600","11.24815","0.43988"
"135.09000","11.25765","0.43526"
"135.20400","11.26722","0.43671"
"135.31800","11.27672","0.44156"
"135.43200","11.28617","0.43644"
"135.54600","11.29562","0.44010"
"135.66000","11.30512","0.44193"
"135.77400","11.31469","0.43830"
"135.88800","11.32426","0.44678"
"136.00200","11.33370","0.44172"
"136.11600","11.34315","0.44137"
"136.23000","11.35266","0.45135"
"136.34400","11.36228","0.44278"
"136.45800","11.37173","0.44775"
"136.57200","11.38124","0.45244"
"136.68600","11.39068","0.44652"
"136.80000","11.40019","0.45504"
"136.91400","11.40976","0.45161"
"137.02800","11.41920","0.45017"
"137.14200","11.42865","0.46184"
"137.25600","11.43816","0.45212"
"137.37000","11.44772","0.45660"
"137.48400","11.45723","0.46303"
"137.59800","11.46674","0.45605"
"137.71200","11.47624","0.46477"
"137.82600","11.48569","0.46189"
"137.94000","11.49519","0.46000"
"138.05400","11.50476","0.47342"
"138.16800","11.51421","0.46278"
"138.28200","11.52366","0.46815"
"138.39600","11.53316","0.47303"
"138.51000","11.54279","0.46441"
"138.62400","11.55223","0.47817"
"138.73800","11.56174","0.47579"
"138.85200","11.57113","0.47412"
"138.96600","11.58063","0.48467"
"139.08000","11.59020","0.47705"
"139.19400","11.59977","0.48263"
"139.30800","11.60921","0.48559"
"139.42200","11.61866","0.48059"
"139.53600","11.62811","0.48957"
"139.65000","11.63773","0.48501"
"139.76400","11.64724","0.48581"
"139.87800","11.65669","0.49322"
"139.99200","11.66613","0.48654"
"140.10600","11.67570","0.49212"
"140.22000","11.68527","0.49304"
"140.33400","11.69477","0.49050"
"140.44800","11.70416","0.49708"
"140.56200","11.71367","0.49317"
"140.67600","11.72317","0.49523"
"140.79000","11.73274","0.49780"
"140.90400","11.74225","0.49535"
"141.01800","11.75163","0.49848"
"141.13200","11.76114","0.49821"
"141.24600","11.77071","0.49740"
"141.36000","11.78021","0.50018"
"141.47400","11.78966","0.49801"
"141.58800","11.79917","0.50003"
"141.70200","11.80873","0.50098"
"141.81600","11.81818","0.49943"
"141.93000","11.82769","0.50454"
"142.04400","11.83719","0.50063"
"142.15800","11.84670","0.50278"
"142.27200","11.85620","0.50772"
"142.38600","11.86571","0.50246"
"142.50000","11.87528","0.51128"
"142.61400","11.88466","0.50707"
"142.72800","11.89417","0.50794"
"142.84200","11.90368","0.51847"
"142.95600","11.91324","0.50981"
"143.07000","11.92269","0.51893"
"143.18400","11.93214","0.51789"
"143.29800","11.94164","0.51572"
"143.41200","11.95121","0.52666"
"143.52600","11.96072","0.51933"
"143.64000","11.97022","0.52529"
"143.75400","11.97961","0.52761"
"143.86800","11.98918","0.52394"
"143.98200","11.99868","0.53247"
"144.09600","12.00825","0.52784"
"144.21000","12.01770","0.53108"
"144.32400","12.02720","0.53553"
"144.43800","12.03671","0.53120"
"144.55200","12.04622","0.53793"
"144.66600","12.05578","0.53562"
"144.78000","12.06517","0.53653"
"144.89400","12.07474","0.54177"
"145.00800","12.08424","0.53724"
"145.12200","12.09375","0.54255"
"145.23600","12.10319","0.54077"
"145.35000","12.11264","0.54085"
"145.46400","12.12221","0.54565"
"145.57800","12.13171","0.54273"
"145.69200","12.14122","0.54663"
"145.80600","12.15067","0.54623"
"145.92000","12.16012","0.54543"
"146.03400","12.16968","0.54925"
"146.14800","12.17919","0.54643"
"146.26200","12.18875","0.54889"
"146.37600","12.19820","0.54949"
"146.49000","12.20765","0.54915"
"146.60400","12.21721","0.55204"
"146.71800","12.22672","0.55065"
"146.83200","12.23623","0.55221"
"146.94600","12.24567","0.55336"
"147.06000","12.25518","0.55258"
"147.17400","12.26475","0.55607"
"147.28800","12.27419","0.55453"
"147.40200","12.28370","0.55628"
"147.51600","12.29321","0.55731"
"147.63000","12.30265","0.55617"
"147.74400","12.31222","0.55893"
"147.85800","12.32173","0.55759"
"147.97200","12.33111","0.55893"
"148.08600","12.34068","0.55998"
"148.20000","12.35018","0.55880"
"148.31400","12.35969","0.56090"
"148.42800","12.36920","0.55999"
"148.54200","12.37871","0.56092"
"148.65600","12.38821","0.56113"
"148.77000","12.39772","0.56083"
"148.88400","12.40722","0.56249"
"148.99800","12.41673","0.56174"
"149.11200","12.42618","0.56233"
"149.22600","12.43569","0.56307"
"149.34000","12.44519","0.56241"
"149.45400","12.45476","0.56505"
"149.56800","12.46415","0.56346"
"149.68200","12.47365","0.56506"
"149.79600","12.48322","0.56561"
"149.91000","12.49266","0.56536"
"150.02400","12.50217","0.56848"
"150.13800","12.51168","0.56691"
"150.25200","12.52124","0.56952"
"150.36600","12.53075","0.56978"
"150.48000","12.54020","0.57018"
"150.59400","12.54970","0.57465"
"150.70800","12.55921","0.57187"
"150.82200","12.56872","0.57648"
"150.93600","12.57822","0.57662"
"151.05000","12.58773","0.57648"
"151.16400","12.59724","0.58299"
"151.27800","12.60668","0.57976"
"151.39200","12.61625","0.58501"
"151.50600","12.62570","0.58460"
"151.62000","12.63520","0.58558"
"151.73400","12.64465","0.59155"
"151.84800","12.65421","0.58826"
"151.96200","12.66372","0.59520"
"152.07600","12.67317","0.59386"
"152.19000","12.68268","0.59487"
"152.30400","12.69218","0.59816"
"152.41800","12.70175","0.59569"
"152.53200","12.71131","0.59947"
"152.64600","12.72070","0.59795"
"152.76000","12.73015","0.60003"
"152.87400","12.73972","0.60090"
"152.98800","12.74922","0.60099"
"153.10200","12.75873","0.60317"
"153.21600","12.76824","0.60208"
"153.33000","12.77768","0.60411"
"153.44400","12.78719","0.60444"
"153.55800","12.79669","0.60426"
"153.67200","12.80620","0.60710"
"153.78600","12.81571","0.60612"
"153.90000","12.82515","0.60922"
"154.01400","12.83472","0.60905"
"154.12800","12.84429","0.61059"
"154.24200","12.85367","0.61407"
"154.35600","12.86318","0.61225"
"154.47000","12.87263","0.61869"
"154.58400","12.88219","0.61665"
"154.69800","12.89176","0.62010"
"154.81200","12.90127","0.62318"
"154.92600","12.91071","0.62224"
"155.04000","12.92016","0.62775"
"155.15400","12.92973","0.62575"
"155.26800","12.93923","0.63052"
"155.38200","12.94874","0.63131"
"155.49600","12.95819","0.63192"
"155.61000","12.96763","0.63496"
"155.72400","12.97726","0.63398"
"155.83800","12.98676","0.63775"
"155.95200","12.99621","0.63719"
"156.06600","13.00566","0.63856"
"156.18000","13.01517","0.64037"
"156.29400","13.02479","0.63987"
"156.40800","13.03424","0.64254"
"156.52200","13.04368","0.64180"
"156.63600","13.05313","0.64399"
"156.75000","13.06270","0.64383"
"156.86400","13.07220","0.64441"
"156.97800","13.08177","0.64625"
"157.09200","13.09122","0.64562"
"157.20600","13.10066","0.64693"
"157.32000","13.11023","0.64670"
"157.43400","13.11974","0.64786"
"157.54800","13.12924","0.64810"
"157.66200","13.13869","0.64802"
"157.77600","13.14820","0.64892"
"157.89000","13.15776","0.64856"
"158.00400","13.16727","0.64942"
"158.11800","13.17672","0.64933"
"158.23200","13.18616","0.64954"
"158.34600","13.19567","0.64989"
"158.46000","13.20524","0.64983"
"158.57400","13.21474","0.65054"
"158.68800","13.22419","0.65039"
"158.80200","13.23364","0.65120"
"158.91600","13.24320","0.65122"
"159.03000","13.25271","0.65144"
"159.14400","13.26221","0.65234"
"159.25800","13.27166","0.65212"
"159.37200","13.28111","0.65328"
"159.48600","13.29074","0.65313"
"159.60000","13.30024","0.65415"
"159.71400","13.30975","0.65438"
"159.82800","13.31913","0.65463"
"159.94200","13.32864","0.65616"
"160.05600","13.33821","0.65556"
"160.17000","13.34772","0.65668"
"160.28400","13.35722","0.65707"
"160.39800","13.36667","0.65840"
"160.51200","13.37617","0.65892"
"160.62600","13.38574","0.65934"
"160.74000","13.39525","0.66079"
"160.85400","13.40469","0.66049"
"160.96800","13.41414","0.66261"
"161.08200","13.42371","0.66193"
"161.19600","13.43321","0.66376"
"161.31000","13.44272","0.66435"
"161.42400","13.45223","0.66492"
"161.53800","13.46167","0.66737"
"161.65200","13.47118","0.66693"
"161.76600","13.48075","0.66992"
"161.88000","13.49025","0.66992"
"161.99400","13.49970","0.67190"
"162.10800","13.50921","0.67340"
"162.22200","13.51871","0.67433"
"162.33600","13.52822","0.67669"
"162.45000","13.53767","0.67669"
"162.56400","13.54711","0.67917"
"162.67800","13.55674","0.67950"
"162.79200","13.56625","0.68187"
"162.90600","13.57575","0.68252"
"163.02000","13.58520","0.68375"
"163.13400","13.59465","0.68519"
"163.24800","13.60421","0.68632"
"163.36200","13.61372","0.68822"
"163.47600","13.62322","0.68818"
"163.59000","13.63267","0.69126"
"163.70400","13.64218","0.69151"
"163.81800","13.65174","0.69325"
"163.93200","13.66119","0.69669"
"164.04600","13.67076","0.69618"
"164.16000","13.68020","0.69999"
"164.27400","13.68965","0.69933"
"164.38800","13.69922","0.70336"
"164.50200","13.70872","0.70293"
"164.61600","13.71817","0.70479"
"164.73000","13.72768","0.70581"
"164.84400","13.73718","0.70632"
"164.95800","13.74669","0.70715"
"165.07200","13.75620","0.70707"
"165.18600","13.76564","0.70808"
"165.30000","13.77521","0.70859"
"165.41400","13.78466","0.70897"
"165.52800","13.79422","0.70894"
"165.64200","13.80373","0.70935"
"165.67400","13.80636","0.70951"