File: Force_trajectories/161223_3/Specimen_RawData_2.csv
End date,"12/23/2016"
Specimen label,"21CT_65"
Maximum Load,"0.01464",N

Time,Extension,Load
(s),(mm),(N)
"0.00000","0.00000","0.00208"
"0.13800","0.00723","0.00194"
"0.27600","0.02206","0.00222"
"0.41400","0.03480","0.00236"
"0.55200","0.04628","0.00238"
"0.69000","0.05770","0.00292"
"0.82800","0.06918","0.00296"
"0.96600","0.08078","0.00316"
"1.10400","0.09226","0.00300"
"1.24200","0.10373","0.00279"
"1.38000","0.11515","0.00298"
"1.51800","0.12669","0.00330"
"1.65600","0.13823","0.00337"
"1.79400","0.14965","0.00289"
"1.93200","0.16119","0.00320"
"2.07000","0.17273","0.00273"
"2.20800","0.18421","0.00357"
"2.34600","0.19569","0.00352"
"2.48400","0.20717","0.00362"
"2.62200","0.21877","0.00324"
"2.76000","0.23025","0.00382"
"2.89800","0.24167","0.00383"
"3.03600","0.25315","0.00389"
"3.17400","0.26475","0.00384"
"3.31200","0.27623","0.00372"
"3.45000","0.28765","0.00381"
"3.58800","0.29919","0.00381"
"3.72600","0.31073","0.00362"
"3.86400","0.32227","0.00398"
"4.00200","0.33369","0.00403"
"4.14000","0.34522","0.00378"
"4.27800","0.35676","0.00424"
"4.41600","0.36824","0.00388"
"4.55400","0.37972","0.00430"
"4.69200","0.39120","0.00368"
"4.83000","0.40274","0.00398"
"4.96800","0.41422","0.00402"
"5.10600","0.42564","0.00398"
"5.24400","0.43718","0.00441"
"5.38200","0.44866","0.00434"
"5.52000","0.46014","0.00461"
"5.65800","0.47162","0.00431"
"5.79600","0.48316","0.00428"
"5.93400","0.49470","0.00434"
"6.07200","0.50618","0.00414"
"6.21000","0.51766","0.00415"
"6.34800","0.52920","0.00420"
"6.48600","0.54068","0.00426"
"6.62400","0.55222","0.00444"
"6.76200","0.56364","0.00445"
"6.90000","0.57524","0.00420"
"7.03800","0.58671","0.00434"
"7.17600","0.59819","0.00457"
"7.31400","0.60967","0.00435"
"7.45200","0.62121","0.00493"
"7.59000","0.63269","0.00439"
"7.72800","0.64417","0.00454"
"7.86600","0.65565","0.00452"
"8.00400","0.66725","0.00451"
"8.14200","0.67867","0.00456"
"8.28000","0.69021","0.00445"
"8.41800","0.70169","0.00484"
"8.55600","0.71323","0.00463"
"8.69400","0.72471","0.00473"
"8.83200","0.73613","0.00483"
"8.97000","0.74773","0.00475"
"9.10800","0.75921","0.00441"
"9.24600","0.77069","0.00452"
"9.38400","0.78217","0.00444"
"9.52200","0.79371","0.00475"
"9.66000","0.80525","0.00463"
"9.79800","0.81673","0.00537"
"9.93600","0.82820","0.00486"
"10.07400","0.83974","0.00476"
"10.21200","0.85122","0.00482"
"10.35000","0.86270","0.00433"
"10.48800","0.87418","0.00497"
"10.62600","0.88566","0.00472"
"10.76400","0.89726","0.00508"
"10.90200","0.90868","0.00462"
"11.04000","0.92016","0.00501"
"11.17800","0.93176","0.00510"
"11.31600","0.94324","0.00502"
"11.45400","0.95472","0.00481"
"11.59200","0.96620","0.00494"
"11.73000","0.97768","0.00505"
"11.86800","0.98928","0.00481"
"12.00600","1.00070","0.00506"
"12.14400","1.01218","0.00471"
"12.28200","1.02372","0.00470"
"12.42000","1.03520","0.00519"
"12.55800","1.04668","0.00549"
"12.69600","1.05816","0.00531"
"12.83400","1.06969","0.00507"
"12.97200","1.08117","0.00535"
"13.11000","1.09265","0.00521"
"13.24800","1.10413","0.00520"
"13.38600","1.11573","0.00527"
"13.52400","1.12721","0.00508"
"13.66200","1.13863","0.00541"
"13.80000","1.15017","0.00560"
"13.93800","1.16165","0.00553"
"14.07600","1.17319","0.00555"
"14.21400","1.18467","0.00529"
"14.35200","1.19621","0.00492"
"14.49000","1.20775","0.00526"
"14.62800","1.21923","0.00514"
"14.76600","1.23071","0.00541"
"14.90400","1.24219","0.00560"
"15.04200","1.25373","0.00541"
"15.18000","1.26521","0.00594"
"15.31800","1.27669","0.00538"
"15.45600","1.28823","0.00563"
"15.59400","1.29970","0.00606"
"15.73200","1.31124","0.00526"
"15.87000","1.32266","0.00547"
"16.00800","1.33420","0.00535"
"16.14600","1.34568","0.00549"
"16.28400","1.35716","0.00577"
"16.42200","1.36864","0.00582"
"16.56000","1.38018","0.00570"
"16.69800","1.39166","0.00583"
"16.83600","1.40314","0.00555"
"16.97400","1.41462","0.00559"
"17.11200","1.42622","0.00545"
"17.25000","1.43776","0.00569"
"17.38800","1.44918","0.00584"
"17.52600","1.46066","0.00575"
"17.66400","1.47226","0.00583"
"17.80200","1.48374","0.00622"
"17.94000","1.49522","0.00590"
"18.07800","1.50670","0.00585"
"18.21600","1.51824","0.00618"
"18.35400","1.52972","0.00556"
"18.49200","1.54119","0.00594"
"18.63000","1.55267","0.00598"
"18.76800","1.56427","0.00586"
"18.90600","1.57575","0.00607"
"19.04400","1.58717","0.00612"
"19.18200","1.59865","0.00612"
"19.32000","1.61019","0.00587"
"19.45800","1.62173","0.00635"
"19.59600","1.63315","0.00645"
"19.73400","1.64469","0.00644"
"19.87200","1.65623","0.00642"
"20.01000","1.66771","0.00609"
"20.14800","1.67913","0.00605"
"20.28600","1.69067","0.00642"
"20.42400","1.70221","0.00610"
"20.56200","1.71369","0.00618"
"20.70000","1.72517","0.00596"
"20.83800","1.73665","0.00633"
"20.97600","1.74819","0.00637"
"21.11400","1.75967","0.00619"
"21.25200","1.77115","0.00618"
"21.39000","1.78268","0.00618"
"21.52800","1.79422","0.00600"
"21.66600","1.80570","0.00583"
"21.80400","1.81718","0.00592"
"21.94200","1.82872","0.00586"
"22.08000","1.84032","0.00641"
"22.21800","1.85174","0.00623"
"22.35600","1.86322","0.00607"
"22.49400","1.87470","0.00572"
"22.63200","1.88624","0.00634"
"22.77000","1.89766","0.00603"
"22.90800","1.90914","0.00613"
"23.04600","1.92068","0.00636"
"23.18400","1.93222","0.00617"
"23.32200","1.94370","0.00604"
"23.46000","1.95518","0.00653"
"23.59800","1.96672","0.00652"
"23.73600","1.97820","0.00619"
"23.87400","1.98968","0.00639"
"24.01200","2.00116","0.00632"
"24.15000","2.01269","0.00639"
"24.28800","2.02423","0.00633"
"24.42600","2.03565","0.00619"
"24.56400","2.04713","0.00642"
"24.70200","2.05873","0.00616"
"24.84000","2.07021","0.00621"
"24.97800","2.08169","0.00642"
"25.11600","2.09323","0.00657"
"25.25400","2.10471","0.00637"
"25.39200","2.11625","0.00604"
"25.53000","2.12773","0.00621"
"25.66800","2.13921","0.00646"
"25.80600","2.15075","0.00656"
"25.94400","2.16223","0.00668"
"26.08200","2.17365","0.00701"
"26.22000","2.18525","0.00613"
"26.35800","2.19673","0.00651"
"26.49600","2.20821","0.00628"
"26.63400","2.21963","0.00638"
"26.77200","2.23123","0.00648"
"26.91000","2.24271","0.00624"
"27.04800","2.25418","0.00663"
"27.18600","2.26560","0.00642"
"27.32400","2.27720","0.00623"
"27.46200","2.28868","0.00635"
"27.60000","2.30016","0.00664"
"27.73800","2.31158","0.00647"
"27.87600","2.32324","0.00662"
"28.01400","2.33478","0.00670"
"28.15200","2.34620","0.00642"
"28.29000","2.35768","0.00701"
"28.42800","2.36928","0.00669"
"28.56600","2.38076","0.00656"
"28.70400","2.39218","0.00693"
"28.84200","2.40366","0.00682"
"28.98000","2.41526","0.00668"
"29.11800","2.42674","0.00691"
"29.25600","2.43816","0.00692"
"29.39400","2.44970","0.00697"
"29.53200","2.46130","0.00730"
"29.67000","2.47278","0.00682"
"29.80800","2.48420","0.00717"
"29.94600","2.49567","0.00736"
"30.08400","2.50721","0.00649"
"30.22200","2.51869","0.00699"
"30.36000","2.53023","0.00684"
"30.49800","2.54171","0.00727"
"30.63600","2.55325","0.00715"
"30.77400","2.56473","0.00728"
"30.91200","2.57615","0.00680"
"31.05000","2.58769","0.00710"
"31.18800","2.59917","0.00720"
"31.32600","2.61071","0.00712"
"31.46400","2.62213","0.00719"
"31.60200","2.63367","0.00691"
"31.74000","2.64521","0.00676"
"31.87800","2.65669","0.00713"
"32.01600","2.66817","0.00691"
"32.15400","2.67965","0.00721"
"32.29200","2.69125","0.00703"
"32.43000","2.70273","0.00701"
"32.56800","2.71415","0.00707"
"32.70600","2.72575","0.00690"
"32.84400","2.73728","0.00753"
"32.98200","2.74870","0.00727"
"33.12000","2.76018","0.00711"
"33.25800","2.77172","0.00723"
"33.39600","2.78326","0.00725"
"33.53400","2.79474","0.00746"
"33.67200","2.80616","0.00727"
"33.81000","2.81776","0.00706"
"33.94800","2.82918","0.00749"
"34.08600","2.84066","0.00742"
"34.22400","2.85214","0.00718"
"34.36200","2.86368","0.00712"
"34.50000","2.87522","0.00761"
"34.63800","2.88670","0.00727"
"34.77600","2.89818","0.00701"
"34.91400","2.90972","0.00738"
"35.05200","2.92120","0.00731"
"35.19000","2.93262","0.00740"
"35.32800","2.94422","0.00712"
"35.46600","2.95570","0.00749"
"35.60400","2.96718","0.00730"
"35.74200","2.97865","0.00733"
"35.88000","2.99019","0.00753"
"36.01800","3.00173","0.00718"
"36.15600","3.01321","0.00747"
"36.29400","3.02463","0.00749"
"36.43200","3.03623","0.00762"
"36.57000","3.04771","0.00759"
"36.70800","3.05925","0.00768"
"36.84600","3.07067","0.00744"
"36.98400","3.08227","0.00795"
"37.12200","3.09375","0.00821"
"37.26000","3.10523","0.00794"
"37.39800","3.11665","0.00769"
"37.53600","3.12819","0.00731"
"37.67400","3.13973","0.00765"
"37.81200","3.15121","0.00772"
"37.95000","3.16263","0.00814"
"38.08800","3.17417","0.00820"
"38.22600","3.18577","0.00718"
"38.36400","3.19719","0.00733"
"38.50200","3.20866","0.00823"
"38.64000","3.22020","0.00756"
"38.77800","3.23174","0.00766"
"38.91600","3.24316","0.00729"
"39.05400","3.25464","0.00741"
"39.19200","3.26618","0.00771"
"39.33000","3.27772","0.00754"
"39.46800","3.28920","0.00768"
"39.60600","3.30068","0.00711"
"39.74400","3.31228","0.00752"
"39.88200","3.32376","0.00776"
"40.02000","3.33518","0.00755"
"40.15800","3.34666","0.00769"
"40.29600","3.35826","0.00773"
"40.43400","3.36974","0.00778"
"40.57200","3.38122","0.00799"
"40.71000","3.39270","0.00786"
"40.84800","3.40424","0.00787"
"40.98600","3.41572","0.00825"
"41.12400","3.42720","0.00794"
"41.26200","3.43868","0.00805"
"41.40000","3.45021","0.00782"
"41.53800","3.46169","0.00779"
"41.67600","3.47317","0.00762"
"41.81400","3.48465","0.00780"
"41.95200","3.49619","0.00790"
"42.09000","3.50767","0.00750"
"42.22800","3.51915","0.00824"
"42.36600","3.53069","0.00765"
"42.50400","3.54223","0.00813"
"42.64200","3.55365","0.00783"
"42.78000","3.56513","0.00784"
"42.91800","3.57667","0.00838"
"43.05600","3.58821","0.00770"
"43.19400","3.59969","0.00790"
"43.33200","3.61117","0.00772"
"43.47000","3.62271","0.00808"
"43.60800","3.63419","0.00761"
"43.74600","3.64567","0.00774"
"43.88400","3.65715","0.00773"
"44.02200","3.66869","0.00762"
"44.16000","3.68022","0.00796"
"44.29800","3.69165","0.00769"
"44.43600","3.70318","0.00784"
"44.57400","3.71472","0.00791"
"44.71200","3.72626","0.00783"
"44.85000","3.73762","0.00799"
"44.98800","3.74916","0.00786"
"45.12600","3.76070","0.00788"
"45.26400","3.77218","0.00838"
"45.40200","3.78366","0.00754"
"45.54000","3.79514","0.00774"
"45.67800","3.80674","0.00795"
"45.81600","3.81822","0.00815"
"45.95400","3.82964","0.00803"
"46.09200","3.84118","0.00810"
"46.23000","3.85272","0.00784"
"46.36800","3.86420","0.00785"
"46.50600","3.87568","0.00831"
"46.64400","3.88716","0.00751"
"46.78200","3.89870","0.00810"
"46.92000","3.91024","0.00769"
"47.05800","3.92165","0.00789"
"47.19600","3.93319","0.00852"
"47.33400","3.94473","0.00781"
"47.47200","3.95621","0.00808"
"47.61000","3.96769","0.00770"
"47.74800","3.97923","0.00787"
"47.88600","3.99077","0.00790"
"48.02400","4.00219","0.00765"
"48.16200","4.01367","0.00786"
"48.30000","4.02515","0.00719"
"48.43800","4.03669","0.00733"
"48.57600","4.04817","0.00772"
"48.71400","4.05965","0.00734"
"48.85200","4.07119","0.00764"
"48.99000","4.08273","0.00729"
"49.12800","4.09421","0.00708"
"49.26600","4.10563","0.00747"
"49.40400","4.11723","0.00739"
"49.54200","4.12871","0.00690"
"49.68000","4.14019","0.00763"
"49.81800","4.15167","0.00757"
"49.95600","4.16320","0.00746"
"50.09400","4.17474","0.00770"
"50.23200","4.18616","0.00767"
"50.37000","4.19764","0.00755"
"50.50800","4.20930","0.00754"
"50.64600","4.22066","0.00731"
"50.78400","4.23220","0.00757"
"50.92200","4.24368","0.00737"
"51.06000","4.25522","0.00712"
"51.19800","4.26664","0.00749"
"51.33600","4.27812","0.00734"
"51.47400","4.28966","0.00727"
"51.61200","4.30120","0.00771"
"51.75000","4.31268","0.00750"
"51.88800","4.32416","0.00732"
"52.02600","4.33570","0.00768"
"52.16400","4.34724","0.00715"
"52.30200","4.35872","0.00745"
"52.44000","4.37014","0.00725"
"52.57800","4.38168","0.00746"
"52.71600","4.39316","0.00754"
"52.85400","4.40463","0.00729"
"52.99200","4.41611","0.00748"
"53.13000","4.42765","0.00751"
"53.26800","4.43919","0.00695"
"53.40600","4.45073","0.00810"
"53.54400","4.46215","0.00799"
"53.68200","4.47369","0.00766"
"53.82000","4.48523","0.00734"
"53.95800","4.49671","0.00741"
"54.09600","4.50813","0.00750"
"54.23400","4.51973","0.00766"
"54.37200","4.53127","0.00760"
"54.51000","4.54275","0.00781"
"54.64800","4.55423","0.00765"
"54.78600","4.56571","0.00786"
"54.92400","4.57725","0.00719"
"55.06200","4.58867","0.00716"
"55.20000","4.60015","0.00717"
"55.33800","4.61175","0.00715"
"55.47600","4.62323","0.00777"
"55.61400","4.63465","0.00763"
"55.75200","4.64618","0.00753"
"55.89000","4.65772","0.00720"
"56.02800","4.66920","0.00770"
"56.16600","4.68062","0.00755"
"56.30400","4.69216","0.00727"
"56.44200","4.70370","0.00734"
"56.58000","4.71524","0.00740"
"56.71800","4.72666","0.00743"
"56.85600","4.73820","0.00711"
"56.99400","4.74968","0.00771"
"57.13200","4.76122","0.00750"
"57.27000","4.77264","0.00747"
"57.40800","4.78418","0.00757"
"57.54600","4.79572","0.00753"
"57.68400","4.80726","0.00743"
"57.82200","4.81868","0.00740"
"57.96000","4.83022","0.00765"
"58.09800","4.84176","0.00755"
"58.23600","4.85324","0.00728"
"58.37400","4.86472","0.00743"
"58.51200","4.87619","0.00760"
"58.65000","4.88773","0.00758"
"58.78800","4.89921","0.00778"
"58.92600","4.91069","0.00775"
"59.06400","4.92223","0.00794"
"59.20200","4.93371","0.00746"
"59.34000","4.94519","0.00799"
"59.47800","4.95667","0.00769"
"59.61600","4.96821","0.00766"
"59.75400","4.97969","0.00749"
"59.89200","4.99117","0.00744"
"60.03000","5.00265","0.00706"
"60.16800","5.01419","0.00829"
"60.30600","5.02573","0.00757"
"60.44400","5.03721","0.00749"
"60.58200","5.04869","0.00782"
"60.72000","5.06023","0.00766"
"60.85800","5.07171","0.00777"
"60.99600","5.08319","0.00743"
"61.13400","5.09473","0.00765"
"61.27200","5.10627","0.00783"
"61.41000","5.11774","0.00833"
"61.54800","5.12922","0.00751"
"61.68600","5.14070","0.00768"
"61.82400","5.15230","0.00773"
"61.96200","5.16378","0.00748"
"62.10000","5.17520","0.00793"
"62.23800","5.18674","0.00738"
"62.37600","5.19822","0.00770"
"62.51400","5.20970","0.00762"
"62.65200","5.22118","0.00767"
"62.79000","5.23272","0.00799"
"62.92800","5.24420","0.00754"
"63.06600","5.25568","0.00819"
"63.20400","5.26716","0.00763"
"63.34200","5.27870","0.00768"
"63.48000","5.29024","0.00766"
"63.61800","5.30166","0.00787"
"63.75600","5.31314","0.00813"
"63.89400","5.32468","0.00774"
"64.03200","5.33622","0.00793"
"64.17000","5.34770","0.00778"
"64.30800","5.35918","0.00768"
"64.44600","5.37071","0.00778"
"64.58400","5.38219","0.00805"
"64.72200","5.39367","0.00769"
"64.86000","5.40515","0.00796"
"64.99800","5.41669","0.00784"
"65.13600","5.42829","0.00794"
"65.27400","5.43971","0.00829"
"65.41200","5.45125","0.00770"
"65.55000","5.46273","0.00776"
"65.68800","5.47427","0.00838"
"65.82600","5.48569","0.00832"
"65.96400","5.49717","0.00778"
"66.10200","5.50871","0.00803"
"66.24000","5.52019","0.00793"
"66.37800","5.53167","0.00766"
"66.51600","5.54315","0.00752"
"66.65400","5.55475","0.00799"
"66.79200","5.56623","0.00793"
"66.93000","5.57771","0.00831"
"67.06800","5.58919","0.00800"
"67.20600","5.60072","0.00812"
"67.34400","5.61220","0.00774"
"67.48200","5.62368","0.00783"
"67.62000","5.63516","0.00765"
"67.75800","5.64670","0.00814"
"67.89600","5.65818","0.00784"
"68.03400","5.66966","0.00788"
"68.17200","5.68120","0.00791"
"68.31000","5.69274","0.00786"
"68.44800","5.70422","0.00849"
"68.58600","5.71570","0.00772"
"68.72400","5.72724","0.00797"
"68.86200","5.73872","0.00723"
"69.00000","5.75026","0.00763"
"69.13800","5.76168","0.00760"
"69.27600","5.77328","0.00778"
"69.41400","5.78476","0.00762"
"69.55200","5.79624","0.00751"
"69.69000","5.80766","0.00772"
"69.82800","5.81920","0.00760"
"69.96600","5.83074","0.00774"
"70.10400","5.84215","0.00717"
"70.24200","5.85363","0.00723"
"70.38000","5.86517","0.00731"
"70.51800","5.87671","0.00715"
"70.65600","5.88819","0.00715"
"70.79400","5.89967","0.00769"
"70.93200","5.91121","0.00704"
"71.07000","5.92269","0.00705"
"71.20800","5.93417","0.00699"
"71.34600","5.94559","0.00748"
"71.48400","5.95725","0.00724"
"71.62200","5.96873","0.00725"
"71.76000","5.98021","0.00792"
"71.89800","5.99169","0.00738"
"72.03600","6.00323","0.00763"
"72.17400","6.01471","0.00706"
"72.31200","6.02613","0.00748"
"72.45000","6.03767","0.00768"
"72.58800","6.04921","0.00701"
"72.72600","6.06069","0.00727"
"72.86400","6.07217","0.00713"
"73.00200","6.08370","0.00739"
"73.14000","6.09524","0.00723"
"73.27800","6.10672","0.00680"
"73.41600","6.11820","0.00727"
"73.55400","6.12968","0.00740"
"73.69200","6.14122","0.00729"
"73.83000","6.15270","0.00713"
"73.96800","6.16412","0.00739"
"74.10600","6.17566","0.00737"
"74.24400","6.18720","0.00747"
"74.38200","6.19868","0.00732"
"74.52000","6.21016","0.00747"
"74.65800","6.22176","0.00747"
"74.79600","6.23324","0.00727"
"74.93400","6.24472","0.00771"
"75.07200","6.25620","0.00747"
"75.21000","6.26768","0.00739"
"75.34800","6.27922","0.00761"
"75.48600","6.29070","0.00710"
"75.62400","6.30218","0.00746"
"75.76200","6.31371","0.00718"
"75.90000","6.32525","0.00745"
"76.03800","6.33667","0.00770"
"76.17600","6.34815","0.00751"
"76.31400","6.35969","0.00721"
"76.45200","6.37123","0.00767"
"76.59000","6.38271","0.00763"
"76.72800","6.39419","0.00765"
"76.86600","6.40573","0.00786"
"77.00400","6.41721","0.00755"
"77.14200","6.42863","0.00769"
"77.28000","6.44017","0.00767"
"77.41800","6.45171","0.00789"
"77.55600","6.46319","0.00775"
"77.69400","6.47467","0.00793"
"77.83200","6.48621","0.00754"
"77.97000","6.49769","0.00802"
"78.10800","6.50923","0.00780"
"78.24600","6.52065","0.00767"
"78.38400","6.53219","0.00728"
"78.52200","6.54373","0.00770"
"78.66000","6.55514","0.00724"
"78.79800","6.56663","0.00781"
"78.93600","6.57816","0.00774"
"79.07400","6.58970","0.00730"
"79.21200","6.60124","0.00765"
"79.35000","6.61266","0.00769"
"79.48800","6.62420","0.00750"
"79.62600","6.63568","0.00761"
"79.76400","6.64722","0.00811"
"79.90200","6.65864","0.00776"
"80.04000","6.67018","0.00750"
"80.17800","6.68172","0.00754"
"80.31600","6.69320","0.00767"
"80.45400","6.70468","0.00833"
"80.59200","6.71622","0.00740"
"80.73000","6.72776","0.00751"
"80.86800","6.73918","0.00769"
"81.00600","6.75066","0.00744"
"81.14400","6.76220","0.00748"
"81.28200","6.77374","0.00757"
"81.42000","6.78516","0.00777"
"81.55800","6.79663","0.00729"
"81.69600","6.80823","0.00770"
"81.83400","6.81971","0.00792"
"81.97200","6.83119","0.00802"
"82.11000","6.84267","0.00764"
"82.24800","6.85421","0.00782"
"82.38600","6.86569","0.00774"
"82.52400","6.87717","0.00767"
"82.66200","6.88865","0.00750"
"82.80000","6.90025","0.00765"
"82.93800","6.91173","0.00780"
"83.07600","6.92315","0.00780"
"83.21400","6.93469","0.00769"
"83.35200","6.94623","0.00729"
"83.49000","6.95771","0.00760"
"83.62800","6.96919","0.00777"
"83.76600","6.98067","0.00747"
"83.90400","6.99221","0.00782"
"84.04200","7.00369","0.00773"
"84.18000","7.01517","0.00745"
"84.31800","7.02665","0.00782"
"84.45600","7.03818","0.00809"
"84.59400","7.04966","0.00753"
"84.73200","7.06114","0.00774"
"84.87000","7.07268","0.00769"
"85.00800","7.08422","0.00770"
"85.14600","7.09570","0.00790"
"85.28400","7.10718","0.00763"
"85.42200","7.11866","0.00755"
"85.56000","7.13020","0.00787"
"85.69800","7.14168","0.00791"
"85.83600","7.15316","0.00835"
"85.97400","7.16470","0.00778"
"86.11200","7.17624","0.00739"
"86.25000","7.18772","0.00778"
"86.38800","7.19920","0.00763"
"86.52600","7.21074","0.00774"
"86.66400","7.22216","0.00746"
"86.80200","7.23376","0.00753"
"86.94000","7.24518","0.00763"
"87.07800","7.25672","0.00739"
"87.21600","7.26826","0.00772"
"87.35400","7.27967","0.00731"
"87.49200","7.29115","0.00803"
"87.63000","7.30269","0.00776"
"87.76800","7.31423","0.00751"
"87.90600","7.32565","0.00756"
"88.04400","7.33719","0.00754"
"88.18200","7.34873","0.00745"
"88.32000","7.36021","0.00800"
"88.45800","7.37169","0.00780"
"88.59600","7.38311","0.00748"
"88.73400","7.39471","0.00784"
"88.87200","7.40619","0.00799"
"89.01000","7.41767","0.00783"
"89.14800","7.42915","0.00799"
"89.28600","7.44069","0.00773"
"89.42400","7.45223","0.00753"
"89.56200","7.46365","0.00822"
"89.70000","7.47519","0.00767"
"89.83800","7.48673","0.00808"
"89.97600","7.49827","0.00769"
"90.11400","7.50963","0.00796"
"90.25200","7.52122","0.00766"
"90.39000","7.53276","0.00789"
"90.52800","7.54424","0.00794"
"90.66600","7.55572","0.00782"
"90.80400","7.56726","0.00806"
"90.94200","7.57874","0.00805"
"91.08000","7.59022","0.00813"
"91.21800","7.60170","0.00757"
"91.35600","7.61318","0.00798"
"91.49400","7.62472","0.00780"
"91.63200","7.63620","0.00811"
"91.77000","7.64762","0.00782"
"91.90800","7.65916","0.00758"
"92.04600","7.67070","0.00738"
"92.18400","7.68218","0.00774"
"92.32200","7.69366","0.00784"
"92.46000","7.70520","0.00770"
"92.59800","7.71668","0.00751"
"92.73600","7.72822","0.00767"
"92.87400","7.73970","0.00803"
"93.01200","7.75124","0.00789"
"93.15000","7.76271","0.00799"
"93.28800","7.77419","0.00766"
"93.42600","7.78567","0.00756"
"93.56400","7.79727","0.00787"
"93.70200","7.80869","0.00813"
"93.84000","7.82017","0.00811"
"93.97800","7.83171","0.00792"
"94.11600","7.84325","0.00781"
"94.25400","7.85473","0.00765"
"94.39200","7.86621","0.00801"
"94.53000","7.87769","0.00788"
"94.66800","7.88923","0.00822"
"94.80600","7.90071","0.00813"
"94.94400","7.91219","0.00785"
"95.08200","7.92373","0.00778"
"95.22000","7.93521","0.00713"
"95.35800","7.94675","0.00722"
"95.49600","7.95817","0.00732"
"95.63400","7.96977","0.00770"
"95.77200","7.98124","0.00789"
"95.91000","7.99266","0.00757"
"96.04800","8.00414","0.00778"
"96.18600","8.01574","0.00759"
"96.32400","8.02722","0.00808"
"96.46200","8.03870","0.00766"
"96.60000","8.05018","0.00802"
"96.73800","8.06172","0.00794"
"96.87600","8.07326","0.00774"
"97.01400","8.08468","0.00813"
"97.15200","8.09616","0.00802"
"97.29000","8.10776","0.00770"
"97.42800","8.11924","0.00788"
"97.56600","8.13072","0.00817"
"97.70400","8.14220","0.00781"
"97.84200","8.15374","0.00811"
"97.98000","8.16528","0.00829"
"98.11800","8.17670","0.00782"
"98.25600","8.18818","0.00763"
"98.39400","8.19972","0.00812"
"98.53200","8.21126","0.00766"
"98.67000","8.22268","0.00774"
"98.80800","8.23421","0.00763"
"98.94600","8.24575","0.00739"
"99.08400","8.25723","0.00745"
"99.22200","8.26871","0.00767"
"99.36000","8.28019","0.00748"
"99.49800","8.29167","0.00839"
"99.63600","8.30321","0.00799"
"99.77400","8.31463","0.00784"
"99.91200","8.32617","0.00770"
"100.05000","8.33771","0.00801"
"100.18800","8.34925","0.00849"
"100.32600","8.36067","0.00788"
"100.46400","8.37221","0.00830"
"100.60200","8.38375","0.00796"
"100.74000","8.39523","0.00811"
"100.87800","8.40665","0.00818"
"101.01600","8.41819","0.00826"
"101.15400","8.42973","0.00818"
"101.29200","8.44121","0.00813"
"101.43000","8.45269","0.00812"
"101.56800","8.46422","0.00803"
"101.70600","8.47576","0.00811"
"101.84400","8.48724","0.00819"
"101.98200","8.49866","0.00844"
"102.12000","8.51026","0.00876"
"102.25800","8.52168","0.00837"
"102.39600","8.53316","0.00817"
"102.53400","8.54464","0.00834"
"102.67200","8.55618","0.00819"
"102.81000","8.56772","0.00865"
"102.94800","8.57914","0.00839"
"103.08600","8.59068","0.00841"
"103.22400","8.60222","0.00831"
"103.36200","8.61376","0.00848"
"103.50000","8.62518","0.00809"
"103.63800","8.63666","0.00829"
"103.77600","8.64826","0.00856"
"103.91400","8.65974","0.00866"
"104.05200","8.67116","0.00829"
"104.19000","8.68270","0.00823"
"104.32800","8.69423","0.00799"
"104.46600","8.70572","0.00840"
"104.60400","8.71719","0.00816"
"104.74200","8.72867","0.00782"
"104.88000","8.74027","0.00865"
"105.01800","8.75175","0.00820"
"105.15600","8.76317","0.00833"
"105.29400","8.77471","0.00809"
"105.43200","8.78625","0.00828"
"105.57000","8.79773","0.00840"
"105.70800","8.80915","0.00801"
"105.84600","8.82069","0.00838"
"105.98400","8.83223","0.00839"
"106.12200","8.84371","0.00773"
"106.26000","8.85513","0.00831"
"106.39800","8.86667","0.00833"
"106.53600","8.87821","0.00795"
"106.67400","8.88969","0.00803"
"106.81200","8.90111","0.00801"
"106.95000","8.91265","0.00782"
"107.08800","8.92425","0.00838"
"107.22600","8.93567","0.00809"
"107.36400","8.94708","0.00854"
"107.50200","8.95868","0.00780"
"107.64000","8.97022","0.00806"
"107.77800","8.98170","0.00837"
"107.91600","8.99318","0.00805"
"108.05400","9.00472","0.00822"
"108.19200","9.01626","0.00811"
"108.33000","9.02768","0.00812"
"108.46800","9.03922","0.00797"
"108.60600","9.05070","0.00797"
"108.74400","9.06224","0.00850"
"108.88200","9.07372","0.00823"
"109.02000","9.08520","0.00812"
"109.15800","9.09674","0.00809"
"109.29600","9.10822","0.00797"
"109.43400","9.11970","0.00823"
"109.57200","9.13112","0.00815"
"109.71000","9.14272","0.00811"
"109.84800","9.15420","0.00834"
"109.98600","9.16568","0.00812"
"110.12400","9.17715","0.00830"
"110.26200","9.18869","0.00840"
"110.40000","9.20017","0.00789"
"110.53800","9.21171","0.00812"
"110.67600","9.22319","0.00851"
"110.81400","9.23467","0.00825"
"110.95200","9.24615","0.00825"
"111.09000","9.25763","0.00841"
"111.22800","9.26917","0.00794"
"111.36600","9.28071","0.00869"
"111.50400","9.29225","0.00807"
"111.64200","9.30373","0.00833"
"111.78000","9.31521","0.00894"
"111.91800","9.32669","0.00850"
"112.05600","9.33823","0.00833"
"112.19400","9.34965","0.00877"
"112.33200","9.36125","0.00847"
"112.47000","9.37273","0.00834"
"112.60800","9.38427","0.00846"
"112.74600","9.39569","0.00834"
"112.88400","9.40722","0.00865"
"113.02200","9.41870","0.00880"
"113.16000","9.43019","0.00858"
"113.29800","9.44160","0.00863"
"113.43600","9.45320","0.00858"
"113.57400","9.46474","0.00871"
"113.71200","9.47616","0.00848"
"113.85000","9.48764","0.00845"
"113.98800","9.49924","0.00873"
"114.12600","9.51072","0.00854"
"114.26400","9.52220","0.00861"
"114.40200","9.53362","0.00853"
"114.54000","9.54528","0.00901"
"114.67800","9.55670","0.00873"
"114.81600","9.56818","0.00858"
"114.95400","9.57966","0.00842"
"115.09200","9.59126","0.00862"
"115.23000","9.60274","0.00880"
"115.36800","9.61416","0.00860"
"115.50600","9.62570","0.00893"
"115.64400","9.63718","0.00855"
"115.78200","9.64872","0.00880"
"115.92000","9.66014","0.00907"
"116.05800","9.67167","0.00865"
"116.19600","9.68321","0.00890"
"116.33400","9.69475","0.00873"
"116.47200","9.70617","0.00872"
"116.61000","9.71765","0.00904"
"116.74800","9.72919","0.00874"
"116.88600","9.74067","0.00890"
"117.02400","9.75209","0.00841"
"117.16200","9.76369","0.00853"
"117.30000","9.77517","0.00867"
"117.43800","9.78665","0.00844"
"117.57600","9.79813","0.00817"
"117.71400","9.80967","0.00878"
"117.85200","9.82121","0.00908"
"117.99000","9.83269","0.00860"
"118.12800","9.84417","0.00878"
"118.26600","9.85571","0.00891"
"118.40400","9.86719","0.00887"
"118.54200","9.87873","0.00877"
"118.68000","9.89020","0.00876"
"118.81800","9.90168","0.00895"
"118.95600","9.91323","0.00893"
"119.09400","9.92470","0.00868"
"119.23200","9.93624","0.00896"
"119.37000","9.94778","0.00862"
"119.50800","9.95920","0.00839"
"119.64600","9.97068","0.00845"
"119.78400","9.98216","0.00907"
"119.92200","9.99376","0.00878"
"120.06000","10.00518","0.00888"
"120.19800","10.01672","0.00865"
"120.33600","10.02820","0.00854"
"120.47400","10.03974","0.00821"
"120.61200","10.05122","0.00857"
"120.75000","10.06264","0.00880"
"120.88800","10.07418","0.00881"
"121.02600","10.08572","0.00843"
"121.16400","10.09726","0.00890"
"121.30200","10.10868","0.00866"
"121.44000","10.12022","0.00839"
"121.57800","10.13170","0.00821"
"121.71600","10.14323","0.00843"
"121.85400","10.15465","0.00813"
"121.99200","10.16619","0.00838"
"122.13000","10.17773","0.00892"
"122.26800","10.18921","0.00822"
"122.40600","10.20063","0.00816"
"122.54400","10.21223","0.00845"
"122.68200","10.22371","0.00836"
"122.82000","10.23525","0.00839"
"122.95800","10.24667","0.00913"
"123.09600","10.25827","0.00850"
"123.23400","10.26975","0.00868"
"123.37200","10.28123","0.00839"
"123.51000","10.29265","0.00854"
"123.64800","10.30419","0.00898"
"123.78600","10.31573","0.00842"
"123.92400","10.32721","0.00875"
"124.06200","10.33863","0.00890"
"124.20000","10.35023","0.00853"
"124.33800","10.36170","0.00855"
"124.47600","10.37318","0.00834"
"124.61400","10.38466","0.00897"
"124.75200","10.39620","0.00916"
"124.89000","10.40774","0.00862"
"125.02800","10.41916","0.00851"
"125.16600","10.43070","0.00906"
"125.30400","10.44224","0.00880"
"125.44200","10.45372","0.00896"
"125.58000","10.46520","0.00870"
"125.71800","10.47668","0.00872"
"125.85600","10.48822","0.00863"
"125.99400","10.49976","0.00890"
"126.13200","10.51112","0.00906"
"126.27000","10.52266","0.00902"
"126.40800","10.53426","0.00913"
"126.54600","10.54574","0.00888"
"126.68400","10.55722","0.00914"
"126.82200","10.56870","0.00925"
"126.96000","10.58024","0.00910"
"127.09800","10.59177","0.00901"
"127.23600","10.60320","0.00906"
"127.37400","10.61473","0.00923"
"127.51200","10.62627","0.00937"
"127.65000","10.63769","0.00871"
"127.78800","10.64917","0.00897"
"127.92600","10.66065","0.00894"
"128.06400","10.67219","0.00900"
"128.20200","10.68361","0.00919"
"128.34000","10.69515","0.00862"
"128.47800","10.70669","0.00881"
"128.61600","10.71823","0.00885"
"128.75400","10.72971","0.00932"
"128.89200","10.74119","0.00891"
"129.03000","10.75273","0.00896"
"129.16800","10.76427","0.00862"
"129.30600","10.77569","0.00877"
"129.44400","10.78717","0.00920"
"129.58200","10.79877","0.00862"
"129.72000","10.81019","0.00857"
"129.85800","10.82167","0.00950"
"129.99600","10.83321","0.00939"
"130.13400","10.84474","0.00880"
"130.27200","10.85622","0.00914"
"130.41000","10.86770","0.00890"
"130.54800","10.87918","0.00861"
"130.68600","10.89072","0.00902"
"130.82400","10.90226","0.00840"
"130.96200","10.91368","0.00888"
"131.10000","10.92516","0.00924"
"131.23800","10.93676","0.00882"
"131.37600","10.94824","0.00853"
"131.51400","10.95972","0.00915"
"131.65200","10.97120","0.00901"
"131.79000","10.98274","0.00888"
"131.92800","10.99422","0.00911"
"132.06600","11.00570","0.00894"
"132.20400","11.01718","0.00922"
"132.34200","11.02872","0.00895"
"132.48000","11.04020","0.00887"
"132.61800","11.05168","0.00892"
"132.75600","11.06322","0.00920"
"132.89400","11.07470","0.00922"
"133.03200","11.08624","0.00924"
"133.17000","11.09765","0.00914"
"133.30800","11.10925","0.00896"
"133.44600","11.12073","0.00877"
"133.58400","11.13227","0.00951"
"133.72200","11.14369","0.00931"
"133.86000","11.15523","0.00952"
"133.99800","11.16677","0.00853"
"134.13600","11.17825","0.00885"
"134.27400","11.18967","0.00881"
"134.41200","11.20121","0.00889"
"134.55000","11.21275","0.00932"
"134.68800","11.22417","0.00892"
"134.82600","11.23565","0.00853"
"134.96400","11.24719","0.00918"
"135.10200","11.25873","0.00886"
"135.24000","11.27015","0.00907"
"135.37800","11.28163","0.00915"
"135.51600","11.29317","0.00921"
"135.65400","11.30471","0.00943"
"135.79200","11.31618","0.00899"
"135.93000","11.32767","0.00899"
"136.06800","11.33921","0.00925"
"136.20600","11.35074","0.00923"
"136.34400","11.36216","0.00942"
"136.48200","11.37364","0.00928"
"136.62000","11.38524","0.00920"
"136.75800","11.39666","0.00960"
"136.89600","11.40814","0.00974"
"137.03400","11.41962","0.00911"
"137.17200","11.43122","0.00940"
"137.31000","11.44270","0.00957"
"137.44800","11.45418","0.00941"
"137.58600","11.46572","0.00956"
"137.72400","11.47726","0.00956"
"137.86200","11.48874","0.00919"
"138.00000","11.50016","0.00930"
"138.13800","11.51176","0.00924"
"138.27600","11.52324","0.00947"
"138.41400","11.53472","0.00949"
"138.55200","11.54614","0.00957"
"138.69000","11.55774","0.00967"
"138.82800","11.56921","0.00923"
"138.96600","11.58069","0.00966"
"139.10400","11.59211","0.00885"
"139.24200","11.60371","0.00919"
"139.38000","11.61525","0.00932"
"139.51800","11.62673","0.00915"
"139.65600","11.63815","0.00943"
"139.79400","11.64975","0.00948"
"139.93200","11.66129","0.00944"
"140.07000","11.67271","0.00946"
"140.20800","11.68419","0.00950"
"140.34600","11.69579","0.00944"
"140.48400","11.70721","0.00934"
"140.62200","11.71869","0.00934"
"140.76000","11.73017","0.00954"
"140.89800","11.74171","0.00938"
"141.03600","11.75325","0.00967"
"141.17400","11.76467","0.00999"
"141.31200","11.77621","0.00928"
"141.45000","11.78775","0.00971"
"141.58800","11.79928","0.00942"
"141.72600","11.81071","0.00947"
"141.86400","11.82218","0.00906"
"142.00200","11.83372","0.00965"
"142.14000","11.84520","0.00983"
"142.27800","11.85668","0.00938"
"142.41600","11.86816","0.00957"
"142.55400","11.87970","0.00946"
"142.69200","11.89124","0.00991"
"142.83000","11.90266","0.00944"
"142.96800","11.91420","0.00987"
"143.10600","11.92568","0.00949"
"143.24400","11.93716","0.00978"
"143.38200","11.94864","0.00910"
"143.52000","11.96018","0.00960"
"143.65800","11.97172","0.01003"
"143.79600","11.98320","0.01011"
"143.93400","11.99468","0.00970"
"144.07200","12.00622","0.00990"
"144.21000","12.01770","0.00994"
"144.34800","12.02918","0.01001"
"144.48600","12.04066","0.00949"
"144.62400","12.05213","0.00958"
"144.76200","12.06373","0.00983"
"144.90000","12.07521","0.01009"
"145.03800","12.08669","0.00984"
"145.17600","12.09823","0.00997"
"145.31400","12.10971","0.00981"
"145.45200","12.12119","0.00967"
"145.59000","12.13261","0.01013"
"145.72800","12.14421","0.00968"
"145.86600","12.15569","0.00993"
"146.00400","12.16711","0.00956"
"146.14200","12.17865","0.01025"
"146.28000","12.19019","0.00956"
"146.41800","12.20173","0.00975"
"146.55600","12.21315","0.01023"
"146.69400","12.22469","0.00991"
"146.83200","12.23623","0.01031"
"146.97000","12.24771","0.01009"
"147.10800","12.25919","0.01005"
"147.24600","12.27067","0.00988"
"147.38400","12.28221","0.00999"
"147.52200","12.29368","0.00998"
"147.66000","12.30516","0.01077"
"147.79800","12.31670","0.01001"
"147.93600","12.32824","0.00969"
"148.07400","12.33972","0.00990"
"148.21200","12.35114","0.01006"
"148.35000","12.36268","0.01011"
"148.48800","12.37422","0.00985"
"148.62600","12.38570","0.01010"
"148.76400","12.39718","0.01063"
"148.90200","12.40872","0.01028"
"149.04000","12.42026","0.01058"
"149.17800","12.43168","0.01022"
"149.31600","12.44316","0.01035"
"149.45400","12.45470","0.01042"
"149.59200","12.46624","0.00990"
"149.73000","12.47772","0.01058"
"149.86800","12.48920","0.01017"
"150.00600","12.50068","0.01012"
"150.14400","12.51222","0.01027"
"150.28200","12.52369","0.01076"
"150.42000","12.53512","0.01030"
"150.55800","12.54671","0.01010"
"150.69600","12.55825","0.01037"
"150.83400","12.56967","0.01069"
"150.97200","12.58121","0.01031"
"151.11000","12.59269","0.01015"
"151.24800","12.60429","0.01021"
"151.38600","12.61565","0.01068"
"151.52400","12.62719","0.01079"
"151.66200","12.63873","0.01065"
"151.80000","12.65021","0.01045"
"151.93800","12.66163","0.01077"
"152.07600","12.67317","0.01110"
"152.21400","12.68471","0.01077"
"152.35200","12.69619","0.01059"
"152.49000","12.70767","0.01073"
"152.62800","12.71921","0.01074"
"152.76600","12.73069","0.01079"
"152.90400","12.74217","0.01063"
"153.04200","12.75371","0.01070"
"153.18000","12.76519","0.01092"
"153.31800","12.77667","0.01062"
"153.45600","12.78820","0.01106"
"153.59400","12.79968","0.01130"
"153.73200","12.81110","0.01065"
"153.87000","12.82270","0.01095"
"154.00800","12.83418","0.01109"
"154.14600","12.84560","0.01076"
"154.28400","12.85720","0.01047"
"154.42200","12.86868","0.01061"
"154.56000","12.88022","0.01064"
"154.69800","12.89164","0.01107"
"154.83600","12.90318","0.01047"
"154.97400","12.91472","0.01105"
"155.11200","12.92626","0.01094"
"155.25000","12.93768","0.01101"
"155.38800","12.94922","0.01079"
"155.52600","12.96076","0.01110"
"155.66400","12.97224","0.01111"
"155.80200","12.98366","0.01098"
"155.94000","12.99526","0.01193"
"156.07800","13.00673","0.01116"
"156.21600","13.01821","0.01106"
"156.35400","13.02963","0.01128"
"156.49200","13.04117","0.01152"
"156.63000","13.05271","0.01157"
"156.76800","13.06413","0.01083"
"156.90600","13.07561","0.01137"
"157.04400","13.08721","0.01135"
"157.18200","13.09875","0.01148"
"157.32000","13.11023","0.01119"
"157.45800","13.12165","0.01120"
"157.59600","13.13325","0.01107"
"157.73400","13.14473","0.01106"
"157.87200","13.15621","0.01115"
"158.01000","13.16769","0.01139"
"158.14800","13.17923","0.01141"
"158.28600","13.19071","0.01134"
"158.42400","13.20213","0.01129"
"158.56200","13.21373","0.01155"
"158.70000","13.22526","0.01180"
"158.83800","13.23674","0.01126"
"158.97600","13.24822","0.01143"
"159.11400","13.25971","0.01122"
"159.25200","13.27124","0.01144"
"159.39000","13.28272","0.01099"
"159.52800","13.29420","0.01135"
"159.66600","13.30568","0.01123"
"159.80400","13.31722","0.01075"
"159.94200","13.32870","0.01123"
"160.08000","13.34018","0.01148"
"160.21800","13.35172","0.01105"
"160.35600","13.36320","0.01177"
"160.49400","13.37468","0.01146"
"160.63200","13.38616","0.01090"
"160.77000","13.39770","0.01135"
"160.90800","13.40918","0.01128"
"161.04600","13.42066","0.01162"
"161.18400","13.43214","0.01133"
"161.32200","13.44368","0.01144"
"161.46000","13.45522","0.01153"
"161.59800","13.46670","0.01123"
"161.73600","13.47818","0.01130"
"161.87400","13.48971","0.01118"
"162.01200","13.50119","0.01168"
"162.15000","13.51267","0.01175"
"162.28800","13.52421","0.01164"
"162.42600","13.53575","0.01187"
"162.56400","13.54723","0.01150"
"162.70200","13.55871","0.01122"
"162.84000","13.57019","0.01167"
"162.97800","13.58179","0.01177"
"163.11600","13.59321","0.01201"
"163.25400","13.60469","0.01210"
"163.39200","13.61623","0.01164"
"163.53000","13.62771","0.01109"
"163.66800","13.63919","0.01175"
"163.80600","13.65067","0.01170"
"163.94400","13.66221","0.01189"
"164.08200","13.67369","0.01173"
"164.22000","13.68517","0.01182"
"164.35800","13.69665","0.01183"
"164.49600","13.70825","0.01174"
"164.63400","13.71972","0.01218"
"164.77200","13.73120","0.01241"
"164.91000","13.74262","0.01179"
"165.04800","13.75416","0.01198"
"165.18600","13.76570","0.01206"
"165.32400","13.77724","0.01189"
"165.46200","13.78866","0.01183"
"165.60000","13.80020","0.01184"
"165.73800","13.81174","0.01232"
"165.87600","13.82322","0.01216"
"166.01400","13.83464","0.01229"
"166.15200","13.84624","0.01210"
"166.29000","13.85772","0.01220"
"166.42800","13.86926","0.01176"
"166.56600","13.88068","0.01211"
"166.70400","13.89222","0.01187"
"166.84200","13.90376","0.01232"
"166.98000","13.91518","0.01256"
"167.11800","13.92666","0.01197"
"167.25600","13.93820","0.01210"
"167.39400","13.94974","0.01215"
"167.53200","13.96115","0.01247"
"167.67000","13.97263","0.01244"
"167.80800","13.98423","0.01187"
"167.94600","13.99571","0.01246"
"168.08400","14.00719","0.01245"
"168.22200","14.01867","0.01250"
"168.36000","14.03021","0.01238"
"168.49800","14.04169","0.01273"
"168.63600","14.05317","0.01270"
"168.77400","14.06465","0.01229"
"168.91200","14.07625","0.01211"
"169.05000","14.08773","0.01276"
"169.18800","14.09915","0.01260"
"169.32600","14.11069","0.01234"
"169.46400","14.12223","0.01232"
"169.60200","14.13371","0.01271"
"169.74000","14.14519","0.01285"
"169.87800","14.15673","0.01274"
"170.01600","14.16827","0.01274"
"170.15400","14.17981","0.01302"
"170.29200","14.19123","0.01256"
"170.43000","14.20276","0.01285"
"170.56800","14.21424","0.01281"
"170.70600","14.22572","0.01265"
"170.84400","14.23720","0.01280"
"170.98200","14.24868","0.01279"
"171.12000","14.26022","0.01303"
"171.25800","14.27164","0.01255"
"171.39600","14.28312","0.01326"
"171.53400","14.29466","0.01271"
"171.67200","14.30620","0.01272"
"171.81000","14.31762","0.01271"
"171.94800","14.32916","0.01302"
"172.08600","14.34070","0.01282"
"172.22400","14.35224","0.01337"
"172.36200","14.36366","0.01281"
"172.50000","14.37514","0.01317"
"172.63800","14.38674","0.01296"
"172.77600","14.39822","0.01325"
"172.91400","14.40970","0.01322"
"173.05200","14.42118","0.01347"
"173.19000","14.43272","0.01342"
"173.32800","14.44425","0.01365"
"173.46600","14.45567","0.01375"
"173.60400","14.46721","0.01313"
"173.74200","14.47875","0.01355"
"173.88000","14.49023","0.01344"
"174.01800","14.50165","0.01336"
"174.15600","14.51319","0.01369"
"174.29400","14.52479","0.01343"
"174.43200","14.53621","0.01326"
"174.57000","14.54769","0.01304"
"174.70800","14.55917","0.01358"
"174.84600","14.57071","0.01350"
"174.98400","14.58219","0.01373"
"175.12200","14.59367","0.01374"
"175.26000","14.60521","0.01389"
"175.39800","14.61669","0.01362"
"175.53600","14.62823","0.01367"
"175.67400","14.63965","0.01366"
"175.81200","14.65119","0.01338"
"175.95000","14.66272","0.01371"
"176.08800","14.67421","0.01331"
"176.22600","14.68569","0.01320"
"176.36400","14.69728","0.01294"
"176.50200","14.70870","0.01340"
"176.64000","14.72024","0.01337"
"176.77800","14.73166","0.01355"
"176.91600","14.74320","0.01345"
"177.05400","14.75474","0.01362"
"177.19200","14.76622","0.01357"
"177.33000","14.77770","0.01353"
"177.46800","14.78924","0.01346"
"177.60600","14.80078","0.01368"
"177.74400","14.81220","0.01352"
"177.88200","14.82362","0.01401"
"178.02000","14.83522","0.01362"
"178.15800","14.84676","0.01299"
"178.29600","14.85824","0.01369"
"178.43400","14.86966","0.01377"
"178.57200","14.88120","0.01355"
"178.71000","14.89268","0.01354"
"178.84800","14.90422","0.01321"
"178.98600","14.91564","0.01328"
"179.12400","14.92723","0.01359"
"179.26200","14.93871","0.01378"
"179.40000","14.95019","0.01402"
"179.53800","14.96167","0.01384"
"179.67600","14.97321","0.01394"
"179.81400","14.98463","0.01405"
"179.95200","14.99617","0.01420"
"180.09000","15.00765","0.01393"
"180.22800","15.01919","0.01402"
"180.36600","15.03067","0.01391"
"180.50400","15.04215","0.01427"
"180.64200","15.05369","0.01383"
"180.78000","15.06523","0.01387"
"180.91800","15.07671","0.01428"
"181.05600","15.08813","0.01402"
"181.19400","15.09973","0.01383"
"181.33200","15.11127","0.01395"
"181.47000","15.12275","0.01386"
"181.60800","15.13417","0.01428"
"181.74600","15.14571","0.01382"
"181.88400","15.15719","0.01383"
"182.02200","15.16866","0.01409"
"182.16000","15.18014","0.01368"
"182.29800","15.19168","0.01378"
"182.43600","15.20322","0.01415"
"182.57400","15.21470","0.01332"
"182.71200","15.22612","0.01385"
"182.85000","15.23772","0.01398"
"182.98800","15.24926","0.01383"
"183.12600","15.26068","0.01394"
"183.26400","15.27216","0.01412"
"183.40200","15.28376","0.01395"
"183.54000","15.29524","0.01342"
"183.67800","15.30672","0.01334"
"183.81600","15.31820","0.01326"
"183.95400","15.32974","0.01331"
"184.09200","15.34122","0.01341"
"184.23000","15.35270","0.01372"
"184.36800","15.36418","0.01227"
"184.50600","15.37572","0.01238"
"184.64400","15.38726","0.01225"
"184.78200","15.39867","0.01241"
"184.92000","15.41021","0.01240"
"185.05800","15.42175","0.01246"
"185.19600","15.43323","0.01269"
"185.33400","15.44465","0.01273"
"185.47200","15.45613","0.01233"
"185.61000","15.46773","0.01266"
"185.74800","15.47921","0.01254"
"185.88600","15.49069","0.01287"
"186.02400","15.50217","0.01240"
"186.16200","15.51371","0.01259"
"186.30000","15.52519","0.01293"
"186.43800","15.53661","0.01251"
"186.57600","15.54821","0.01257"
"186.71400","15.55969","0.01307"
"186.85200","15.57123","0.01258"
"186.99000","15.58265","0.01272"
"187.12800","15.59419","0.01329"
"187.26600","15.60573","0.01282"
"187.40400","15.61721","0.01280"
"187.54200","15.62862","0.01257"
"187.68000","15.64022","0.01246"
"187.81800","15.65170","0.01286"
"187.95600","15.66324","0.01248"
"188.09400","15.67466","0.01277"
"188.23200","15.68620","0.01223"
"188.37000","15.69774","0.01250"
"188.50800","15.70922","0.01186"
"188.64600","15.72070","0.01270"
"188.78400","15.73218","0.01261"
"188.92200","15.74372","0.01244"
"189.06000","15.75514","0.01277"
"189.19800","15.76668","0.01275"
"189.33600","15.77822","0.01222"
"189.47400","15.78976","0.01314"
"189.61200","15.80118","0.01270"
"189.75000","15.81266","0.01236"
"189.88800","15.82420","0.01283"
"190.02600","15.83568","0.01300"
"190.16400","15.84716","0.01283"
"190.30200","15.85870","0.01294"
"190.44000","15.87023","0.01298"
"190.57800","15.88165","0.01301"
"190.71600","15.89313","0.01277"
"190.85400","15.90467","0.01336"
"190.99200","15.91627","0.01355"
"191.13000","15.92775","0.01264"
"191.26800","15.93917","0.01302"
"191.40600","15.95071","0.01299"
"191.54400","15.96225","0.01277"
"191.68200","15.97373","0.01294"
"191.82000","15.98515","0.01286"
"191.95800","15.99675","0.01293"
"192.09600","16.00823","0.01310"
"192.23400","16.01971","0.01351"
"192.37200","16.03113","0.01337"
"192.51000","16.04267","0.01335"
"192.64800","16.05421","0.01289"
"192.78600","16.06569","0.01314"
"192.92400","16.07717","0.01325"
"193.06200","16.08865","0.01318"
"193.20000","16.10024","0.01343"
"193.33800","16.11166","0.01331"
"193.47600","16.12314","0.01365"
"193.61400","16.13468","0.01364"
"193.75200","16.14622","0.01299"
"193.89000","16.15770","0.01298"
"194.02800","16.16918","0.01310"
"194.16600","16.18072","0.01344"
"194.30400","16.19226","0.01301"
"194.44200","16.20368","0.01324"
"194.58000","16.21522","0.01180"
"194.71800","16.22670","0.01302"
"194.85600","16.23824","0.01177"
"194.99400","16.24966","0.00942"
"195.13200","16.26126","0.00568"
"195.27000","16.27280","0.00552"
"195.40800","16.28422","0.00523"
"195.54600","16.29570","0.00552"
"195.68400","16.30718","0.00562"
"195.82200","16.31878","0.00484"
"195.96000","16.33020","0.00446"
"196.09800","16.34173","0.00470"
"196.23600","16.35321","0.00483"
"196.37400","16.36469","0.00556"
"196.51200","16.37623","0.00568"
"196.65000","16.38771","0.00497"
"196.78800","16.39919","0.00436"
"196.92600","16.41067","0.00472"
"197.06400","16.42215","0.00477"
"197.20200","16.43363","0.00487"
"197.34000","16.44523","0.00558"
"197.47800","16.45671","0.00509"
"197.61600","16.46819","0.00487"
"197.75400","16.47967","0.00461"
"197.89200","16.49121","0.00510"
"198.03000","16.50269","0.00545"
"198.16800","16.51423","0.00556"
"198.30600","16.52565","0.00544"
"198.44400","16.53725","0.00508"
"198.58200","16.54873","0.00489"
"198.72000","16.56027","0.00491"
"198.85800","16.57169","0.00545"
"198.99600","16.58328","0.00570"
"199.13400","16.59470","0.00581"
"199.27200","16.60618","0.00540"
"199.41000","16.61766","0.00578"
"199.54800","16.62926","0.00532"
"199.68600","16.64074","0.00541"
"199.82400","16.65222","0.00546"
"199.96200","16.66370","0.00573"
"200.10000","16.67524","0.00539"
"200.23800","16.68672","0.00544"
"200.37600","16.69814","0.00546"
"200.51400","16.70962","0.00556"
"200.58800","16.71590","0.00569"