File: Force_trajectories/161223_3/Specimen_RawData_1.csv
End date,"12/23/2016"
Specimen label,"21DG_67"
Maximum Load,"0.99029",N

Time,Extension,Load
(s),(mm),(N)
"0.00000","0.00006","-0.00037"
"0.33000","0.02738","-0.00019"
"0.66000","0.05525","-0.00035"
"0.99000","0.08275","0.00010"
"1.32000","0.11019","0.00007"
"1.65000","0.13770","0.00018"
"1.98000","0.16520","0.00029"
"2.31000","0.19276","-0.00016"
"2.64000","0.22026","0.00010"
"2.97000","0.24771","-0.00004"
"3.30000","0.27521","0.00012"
"3.63000","0.30271","0.00000"
"3.96000","0.33016","0.00003"
"4.29000","0.35778","0.00005"
"4.62000","0.38522","0.00007"
"4.95000","0.41273","0.00020"
"5.28000","0.44029","0.00046"
"5.61000","0.46773","-0.00001"
"5.94000","0.49524","0.00020"
"6.27000","0.52268","0.00016"
"6.60000","0.55024","0.00034"
"6.93000","0.57775","0.00031"
"7.26000","0.60519","0.00054"
"7.59000","0.63275","0.00024"
"7.92000","0.66020","0.00013"
"8.25000","0.68770","0.00062"
"8.58000","0.71520","0.00079"
"8.91000","0.74271","0.00047"
"9.24000","0.77027","0.00086"
"9.57000","0.79771","0.00043"
"9.90000","0.82527","0.00087"
"10.23000","0.85272","0.00048"
"10.56000","0.88022","0.00075"
"10.89000","0.90772","0.00055"
"11.22000","0.93523","0.00077"
"11.55000","0.96273","0.00034"
"11.88000","0.99029","0.00033"
"12.21000","1.01774","0.00053"
"12.54000","1.04518","0.00090"
"12.87000","1.07274","0.00077"
"13.20000","1.10025","0.00080"
"13.53000","1.12775","0.00041"
"13.86000","1.15519","0.00054"
"14.19000","1.18276","0.00046"
"14.52000","1.21026","0.00060"
"14.85000","1.23764","0.00052"
"15.18000","1.26527","0.00054"
"15.51000","1.29277","0.00109"
"15.84000","1.32021","0.00069"
"16.17000","1.34778","0.00057"
"16.50000","1.37522","0.00084"
"16.83000","1.40272","0.00096"
"17.16000","1.43023","0.00106"
"17.49000","1.45773","0.00088"
"17.82000","1.48523","0.00053"
"18.15000","1.51274","0.00112"
"18.48000","1.54024","0.00087"
"18.81000","1.56774","0.00123"
"19.14000","1.59518","0.00090"
"19.47000","1.62275","0.00095"
"19.80000","1.65025","0.00127"
"20.13000","1.67775","0.00079"
"20.46000","1.70520","0.00086"
"20.79000","1.73270","0.00128"
"21.12000","1.76026","0.00130"
"21.45000","1.78777","0.00088"
"21.78000","1.81521","0.00112"
"22.11000","1.84271","0.00112"
"22.44000","1.87022","0.00062"
"22.77000","1.89772","0.00090"
"23.10000","1.92528","0.00088"
"23.43000","1.95267","0.00092"
"23.76000","1.98029","0.00147"
"24.09000","2.00773","0.00112"
"24.42000","2.03524","0.00144"
"24.75000","2.06274","0.00109"
"25.08000","2.09018","0.00102"
"25.41000","2.11775","0.00054"
"25.74000","2.14519","0.00112"
"26.07000","2.17269","0.00157"
"26.40000","2.20025","0.00064"
"26.73000","2.22770","0.00115"
"27.06000","2.25526","0.00120"
"27.39000","2.28270","0.00123"
"27.72000","2.31021","0.00083"
"28.05000","2.33777","0.00165"
"28.38000","2.36521","0.00126"
"28.71000","2.39278","0.00131"
"29.04000","2.42028","0.00148"
"29.37000","2.44766","0.00117"
"29.70000","2.47523","0.00202"
"30.03000","2.50273","0.00126"
"30.36000","2.53017","0.00144"
"30.69000","2.55780","0.00176"
"31.02000","2.58518","0.00140"
"31.35000","2.61274","0.00170"
"31.68000","2.64025","0.00138"
"32.01000","2.66769","0.00146"
"32.34000","2.69525","0.00159"
"32.67000","2.72270","0.00144"
"33.00000","2.75026","0.00135"
"33.33000","2.77776","0.00149"
"33.66000","2.80521","0.00142"
"33.99000","2.83277","0.00165"
"34.32000","2.86021","0.00169"
"34.65000","2.88771","0.00129"
"34.98000","2.91528","0.00131"
"35.31000","2.94272","0.00193"
"35.64000","2.97028","0.00150"
"35.97000","2.99767","0.00174"
"36.30000","3.02523","0.00159"
"36.63000","3.05273","0.00120"
"36.96000","3.08018","0.00175"
"37.29000","3.10774","0.00163"
"37.62000","3.13524","0.00149"
"37.95000","3.16269","0.00148"
"38.28000","3.19025","0.00150"
"38.61000","3.21769","0.00186"
"38.94000","3.24520","0.00174"
"39.27000","3.27276","0.00190"
"39.60000","3.30014","0.00170"
"39.93000","3.32777","0.00144"
"40.26000","3.35521","0.00137"
"40.59000","3.38271","0.00193"
"40.92000","3.41028","0.00185"
"41.25000","3.43766","0.00163"
"41.58000","3.46522","0.00186"
"41.91000","3.49279","0.00160"
"42.24000","3.52023","0.00139"
"42.57000","3.54779","0.00189"
"42.90000","3.57523","0.00170"
"43.23000","3.60274","0.00194"
"43.56000","3.63024","0.00173"
"43.89000","3.65774","0.00194"
"44.22000","3.68525","0.00198"
"44.55000","3.71275","0.00197"
"44.88000","3.74025","0.00166"
"45.21000","3.76782","0.00194"
"45.54000","3.79520","0.00165"
"45.87000","3.82270","0.00196"
"46.20000","3.85027","0.00171"
"46.53000","3.87771","0.00161"
"46.86000","3.90527","0.00167"
"47.19000","3.93272","0.00203"
"47.52000","3.96022","0.00214"
"47.85000","3.98772","0.00193"
"48.18000","4.01523","0.00197"
"48.51000","4.04279","0.00200"
"48.84000","4.07023","0.00163"
"49.17000","4.09768","0.00223"
"49.50000","4.12530","0.00165"
"49.83000","4.15268","0.00199"
"50.16000","4.18024","0.00204"
"50.49000","4.20775","0.00196"
"50.82000","4.23525","0.00205"
"51.15000","4.26269","0.00252"
"51.48000","4.29020","0.00192"
"51.81000","4.31776","0.00159"
"52.14000","4.34526","0.00192"
"52.47000","4.37271","0.00191"
"52.80000","4.40033","0.00190"
"53.13000","4.42771","0.00181"
"53.46000","4.45522","0.00220"
"53.79000","4.48278","0.00249"
"54.12000","4.51016","0.00261"
"54.45000","4.53773","0.00206"
"54.78000","4.56523","0.00216"
"55.11000","4.59279","0.00218"
"55.44000","4.62024","0.00199"
"55.77000","4.64768","0.00187"
"56.10000","4.67524","0.00217"
"56.43000","4.70275","0.00215"
"56.76000","4.73019","0.00233"
"57.09000","4.75775","0.00228"
"57.42000","4.78520","0.00235"
"57.75000","4.81270","0.00226"
"58.08000","4.84026","0.00267"
"58.41000","4.86770","0.00277"
"58.74000","4.89521","0.00293"
"59.07000","4.92271","0.00277"
"59.40000","4.95027","0.00253"
"59.73000","4.97778","0.00274"
"60.06000","5.00516","0.00249"
"60.39000","5.03272","0.00260"
"60.72000","5.06023","0.00242"
"61.05000","5.08773","0.00266"
"61.38000","5.11529","0.00269"
"61.71000","5.14274","0.00252"
"62.04000","5.17024","0.00270"
"62.37000","5.19774","0.00296"
"62.70000","5.22525","0.00234"
"63.03000","5.25275","0.00244"
"63.36000","5.28019","0.00269"
"63.69000","5.30776","0.00249"
"64.02000","5.33526","0.00254"
"64.35000","5.36264","0.00245"
"64.68000","5.39021","0.00277"
"65.01000","5.41771","0.00306"
"65.34000","5.44521","0.00286"
"65.67000","5.47271","0.00282"
"66.00000","5.50022","0.00298"
"66.33000","5.52772","0.00286"
"66.66000","5.55522","0.00295"
"66.99000","5.58273","0.00309"
"67.32000","5.61023","0.00305"
"67.65000","5.63773","0.00319"
"67.98000","5.66524","0.00295"
"68.31000","5.69274","0.00326"
"68.64000","5.72018","0.00325"
"68.97000","5.74775","0.00301"
"69.30000","5.77525","0.00302"
"69.63000","5.80269","0.00372"
"69.96000","5.83020","0.00347"
"70.29000","5.85770","0.00350"
"70.62000","5.88526","0.00340"
"70.95000","5.91271","0.00334"
"71.28000","5.94021","0.00339"
"71.61000","5.96771","0.00321"
"71.94000","5.99522","0.00328"
"72.27000","6.02272","0.00394"
"72.60000","6.05028","0.00377"
"72.93000","6.07773","0.00371"
"73.26000","6.10523","0.00332"
"73.59000","6.13279","0.00318"
"73.92000","6.16024","0.00396"
"74.25000","6.18774","0.00375"
"74.58000","6.21518","0.00396"
"74.91000","6.24274","0.00391"
"75.24000","6.27025","0.00351"
"75.57000","6.29769","0.00376"
"75.90000","6.32531","0.00369"
"76.23000","6.35264","0.00348"
"76.56000","6.38026","0.00419"
"76.89000","6.40776","0.00389"
"77.22000","6.43515","0.00427"
"77.55000","6.46271","0.00390"
"77.88000","6.49021","0.00418"
"78.21000","6.51778","0.00401"
"78.54000","6.54528","0.00401"
"78.87000","6.57266","0.00378"
"79.20000","6.60029","0.00374"
"79.53000","6.62773","0.00377"
"79.86000","6.65523","0.00421"
"80.19000","6.68280","0.00369"
"80.52000","6.71024","0.00416"
"80.85000","6.73774","0.00400"
"81.18000","6.76525","0.00418"
"81.51000","6.79269","0.00399"
"81.84000","6.82025","0.00390"
"82.17000","6.84770","0.00380"
"82.50000","6.87526","0.00349"
"82.83000","6.90276","0.00373"
"83.16000","6.93020","0.00361"
"83.49000","6.95777","0.00337"
"83.82000","6.98521","0.00374"
"84.15000","7.01271","0.00352"
"84.48000","7.04028","0.00349"
"84.81000","7.06766","0.00390"
"85.14000","7.09522","0.00339"
"85.47000","7.12273","0.00399"
"85.80000","7.15023","0.00423"
"86.13000","7.17773","0.00409"
"86.46000","7.20518","0.00374"
"86.79000","7.23274","0.00382"
"87.12000","7.26024","0.00408"
"87.45000","7.28769","0.00415"
"87.78000","7.31525","0.00388"
"88.11000","7.34269","0.00343"
"88.44000","7.37026","0.00410"
"88.77000","7.39776","0.00410"
"89.10000","7.42520","0.00437"
"89.43000","7.45271","0.00363"
"89.76000","7.48021","0.00430"
"90.09000","7.50771","0.00391"
"90.42000","7.53521","0.00417"
"90.75000","7.56272","0.00414"
"91.08000","7.59022","0.00428"
"91.41000","7.61778","0.00422"
"91.74000","7.64523","0.00447"
"92.07000","7.67273","0.00445"
"92.40000","7.70023","0.00474"
"92.73000","7.72774","0.00452"
"93.06000","7.75524","0.00432"
"93.39000","7.78268","0.00414"
"93.72000","7.81025","0.00430"
"94.05000","7.83769","0.00467"
"94.38000","7.86519","0.00460"
"94.71000","7.89276","0.00472"
"95.04000","7.92014","0.00470"
"95.37000","7.94776","0.00483"
"95.70000","7.97521","0.00511"
"96.03000","8.00271","0.00481"
"96.36000","8.03027","0.00519"
"96.69000","8.05772","0.00494"
"97.02000","8.08528","0.00508"
"97.35000","8.11272","0.00465"
"97.68000","8.14023","0.00467"
"98.01000","8.16779","0.00458"
"98.34000","8.19523","0.00559"
"98.67000","8.22268","0.00559"
"99.00000","8.25030","0.00550"
"99.33000","8.27774","0.00545"
"99.66000","8.30524","0.00530"
"99.99000","8.33275","0.00532"
"100.32000","8.36019","0.00562"
"100.65000","8.38769","0.00557"
"100.98000","8.41514","0.00523"
"101.31000","8.44276","0.00513"
"101.64000","8.47026","0.00586"
"101.97000","8.49771","0.00548"
"102.30000","8.52533","0.00533"
"102.63000","8.55271","0.00552"
"102.96000","8.58016","0.00539"
"103.29000","8.60772","0.00508"
"103.62000","8.63516","0.00527"
"103.95000","8.66279","0.00579"
"104.28000","8.69017","0.00575"
"104.61000","8.71773","0.00559"
"104.94000","8.74524","0.00598"
"105.27000","8.77262","0.00577"
"105.60000","8.80024","0.00569"
"105.93000","8.82769","0.00587"
"106.26000","8.85525","0.00548"
"106.59000","8.88275","0.00587"
"106.92000","8.91025","0.00605"
"107.25000","8.93770","0.00624"
"107.58000","8.96520","0.00592"
"107.91000","8.99270","0.00586"
"108.24000","9.02021","0.00590"
"108.57000","9.04771","0.00586"
"108.90000","9.07527","0.00562"
"109.23000","9.10278","0.00586"
"109.56000","9.13016","0.00585"
"109.89000","9.15778","0.00591"
"110.22000","9.18523","0.00592"
"110.55000","9.21273","0.00641"
"110.88000","9.24029","0.00647"
"111.21000","9.26768","0.00634"
"111.54000","9.29524","0.00662"
"111.87000","9.32274","0.00682"
"112.20000","9.35025","0.00667"
"112.53000","9.37775","0.00677"
"112.86000","9.40519","0.00677"
"113.19000","9.43276","0.00664"
"113.52000","9.46026","0.00673"
"113.85000","9.48764","0.00733"
"114.18000","9.51521","0.00731"
"114.51000","9.54277","0.00691"
"114.84000","9.57027","0.00696"
"115.17000","9.59777","0.00656"
"115.50000","9.62522","0.00709"
"115.83000","9.65272","0.00724"
"116.16000","9.68022","0.00716"
"116.49000","9.70767","0.00725"
"116.82000","9.73523","0.00719"
"117.15000","9.76273","0.00706"
"117.48000","9.79024","0.00742"
"117.81000","9.81780","0.00820"
"118.14000","9.84512","0.00706"
"118.47000","9.87275","0.00726"
"118.80000","9.90025","0.00738"
"119.13000","9.92775","0.00798"
"119.46000","9.95526","0.00801"
"119.79000","9.98270","0.00792"
"120.12000","10.01026","0.00827"
"120.45000","10.03771","0.00787"
"120.78000","10.06521","0.00789"
"121.11000","10.09277","0.00839"
"121.44000","10.12016","0.00835"
"121.77000","10.14772","0.00828"
"122.10000","10.17522","0.00763"
"122.43000","10.20267","0.00818"
"122.76000","10.23023","0.00860"
"123.09000","10.25773","0.00844"
"123.42000","10.28529","0.00866"
"123.75000","10.31274","0.00837"
"124.08000","10.34018","0.00827"
"124.41000","10.36768","0.00845"
"124.74000","10.39519","0.00912"
"125.07000","10.42269","0.00903"
"125.40000","10.45025","0.00930"
"125.73000","10.47770","0.00916"
"126.06000","10.50526","0.00916"
"126.39000","10.53276","0.00895"
"126.72000","10.56021","0.00975"
"127.05000","10.58777","0.00862"
"127.38000","10.61521","0.00955"
"127.71000","10.64278","0.00905"
"128.04000","10.67028","0.00958"
"128.37000","10.69772","0.00974"
"128.70000","10.72529","0.00976"
"129.03000","10.75273","0.00926"
"129.36000","10.78023","0.00944"
"129.69000","10.80779","0.00946"
"130.02000","10.83524","0.00979"
"130.35000","10.86274","0.00962"
"130.68000","10.89024","0.01046"
"131.01000","10.91769","0.01038"
"131.34000","10.94525","0.00999"
"131.67000","10.97263","0.00982"
"132.00000","11.00020","0.00992"
"132.33000","11.02776","0.01006"
"132.66000","11.05520","0.00973"
"132.99000","11.08271","0.01021"
"133.32000","11.11021","0.01001"
"133.65000","11.13765","0.01091"
"133.98000","11.16522","0.01015"
"134.31000","11.19272","0.01064"
"134.64000","11.22028","0.01018"
"134.97000","11.24773","0.01062"
"135.30000","11.27523","0.01042"
"135.63000","11.30273","0.01110"
"135.96000","11.33018","0.01089"
"136.29000","11.35774","0.01084"
"136.62000","11.38530","0.01117"
"136.95000","11.41269","0.01097"
"137.28000","11.44025","0.01089"
"137.61000","11.46769","0.01094"
"137.94000","11.49525","0.01152"
"138.27000","11.52276","0.01146"
"138.60000","11.55026","0.01148"
"138.93000","11.57777","0.01134"
"139.26000","11.60521","0.01136"
"139.59000","11.63271","0.01128"
"139.92000","11.66021","0.01213"
"140.25000","11.68766","0.01150"
"140.58000","11.71522","0.01182"
"140.91000","11.74272","0.01194"
"141.24000","11.77023","0.01180"
"141.57000","11.79767","0.01224"
"141.90000","11.82523","0.01236"
"142.23000","11.85274","0.01233"
"142.56000","11.88024","0.01200"
"142.89000","11.90768","0.01218"
"143.22000","11.93531","0.01248"
"143.55000","11.96269","0.01289"
"143.88000","11.99019","0.01249"
"144.21000","12.01776","0.01241"
"144.54000","12.04514","0.01173"
"144.87000","12.07276","0.01209"
"145.20000","12.10027","0.01237"
"145.53000","12.12771","0.01222"
"145.86000","12.15521","0.01207"
"146.19000","12.18271","0.01239"
"146.52000","12.21028","0.01226"
"146.85000","12.23772","0.01226"
"147.18000","12.26523","0.01267"
"147.51000","12.29279","0.01262"
"147.84000","12.32023","0.01304"
"148.17000","12.34773","0.01331"
"148.50000","12.37530","0.01325"
"148.83000","12.40268","0.01362"
"149.16000","12.43024","0.01350"
"149.49000","12.45775","0.01320"
"149.82000","12.48519","0.01286"
"150.15000","12.51275","0.01294"
"150.48000","12.54014","0.01309"
"150.81000","12.56776","0.01295"
"151.14000","12.59520","0.01342"
"151.47000","12.62271","0.01348"
"151.80000","12.65027","0.01361"
"152.13000","12.67771","0.01373"
"152.46000","12.70522","0.01384"
"152.79000","12.73272","0.01432"
"153.12000","12.76016","0.01417"
"153.45000","12.78772","0.01352"
"153.78000","12.81523","0.01441"
"154.11000","12.84279","0.01451"
"154.44000","12.87024","0.01450"
"154.77000","12.89768","0.01436"
"155.10000","12.92524","0.01479"
"155.43000","12.95269","0.01464"
"155.76000","12.98019","0.01515"
"156.09000","13.00775","0.01486"
"156.42000","13.03520","0.01566"
"156.75000","13.06276","0.01509"
"157.08000","13.09020","0.01519"
"157.41000","13.11776","0.01500"
"157.74000","13.14521","0.01632"
"158.07000","13.17271","0.01559"
"158.40000","13.20027","0.01366"
"158.73000","13.22778","0.01465"
"159.06000","13.25516","0.01428"
"159.39000","13.28272","0.01428"
"159.72000","13.31029","0.01465"
"160.05000","13.33767","0.01437"
"160.38000","13.36523","0.01502"
"160.71000","13.39268","0.01475"
"161.04000","13.42024","0.01580"
"161.37000","13.44774","0.01509"
"161.70000","13.47519","0.01516"
"162.03000","13.50275","0.01534"
"162.36000","13.53013","0.01641"
"162.69000","13.55770","0.01572"
"163.02000","13.58526","0.01615"
"163.35000","13.61270","0.01600"
"163.68000","13.64021","0.01668"
"164.01000","13.66777","0.01647"
"164.34000","13.69521","0.01641"
"164.67000","13.72271","0.01676"
"165.00000","13.75022","0.01615"
"165.33000","13.77778","0.01671"
"165.66000","13.80522","0.01696"
"165.99000","13.83273","0.01749"
"166.32000","13.86023","0.01785"
"166.65000","13.88767","0.01756"
"166.98000","13.91518","0.01762"
"167.31000","13.94280","0.01731"
"167.64000","13.97018","0.01780"
"167.97000","13.99775","0.01836"
"168.30000","14.02519","0.01812"
"168.63000","14.05269","0.01823"
"168.96000","14.08026","0.01872"
"169.29000","14.10770","0.01863"
"169.62000","14.13526","0.01851"
"169.95000","14.16271","0.01938"
"170.28000","14.19021","0.01956"
"170.61000","14.21783","0.01883"
"170.94000","14.24516","0.01984"
"171.27000","14.27272","0.01956"
"171.60000","14.30022","0.01987"
"171.93000","14.32767","0.01895"
"172.26000","14.35529","0.01850"
"172.59000","14.38273","0.01877"
"172.92000","14.41029","0.01860"
"173.25000","14.43774","0.01869"
"173.58000","14.46518","0.01904"
"173.91000","14.49274","0.01934"
"174.24000","14.52025","0.01999"
"174.57000","14.54769","0.01988"
"174.90000","14.57531","0.02029"
"175.23000","14.60264","0.02038"
"175.56000","14.63026","0.02065"
"175.89000","14.65776","0.02045"
"176.22000","14.68521","0.02057"
"176.55000","14.71271","0.02089"
"176.88000","14.74021","0.02092"
"177.21000","14.76778","0.02129"
"177.54000","14.79528","0.02185"
"177.87000","14.82266","0.02193"
"178.20000","14.85028","0.02189"
"178.53000","14.87767","0.02224"
"178.86000","14.90517","0.02226"
"179.19000","14.93273","0.02265"
"179.52000","14.96018","0.02298"
"179.85000","14.98774","0.02314"
"180.18000","15.01524","0.02358"
"180.51000","15.04275","0.02315"
"180.84000","15.07025","0.02332"
"181.17000","15.09769","0.02358"
"181.50000","15.12526","0.02396"
"181.83000","15.15270","0.02396"
"182.16000","15.18020","0.02412"
"182.49000","15.20777","0.02432"
"182.82000","15.23527","0.02485"
"183.15000","15.26277","0.02502"
"183.48000","15.29028","0.02568"
"183.81000","15.31772","0.02576"
"184.14000","15.34528","0.02539"
"184.47000","15.37273","0.02609"
"184.80000","15.40017","0.02641"
"185.13000","15.42773","0.02611"
"185.46000","15.45524","0.02676"
"185.79000","15.48274","0.02668"
"186.12000","15.51030","0.02689"
"186.45000","15.53769","0.02704"
"186.78000","15.56519","0.02742"
"187.11000","15.59275","0.02779"
"187.44000","15.62025","0.02850"
"187.77000","15.64776","0.02843"
"188.10000","15.67520","0.02852"
"188.43000","15.70276","0.02908"
"188.76000","15.73021","0.02940"
"189.09000","15.75771","0.02973"
"189.42000","15.78527","0.02996"
"189.75000","15.81266","0.03028"
"190.08000","15.84022","0.03032"
"190.41000","15.86778","0.03073"
"190.74000","15.89517","0.03131"
"191.07000","15.92267","0.03153"
"191.40000","15.95017","0.03189"
"191.73000","15.97774","0.03202"
"192.06000","16.00524","0.03296"
"192.39000","16.03268","0.03328"
"192.72000","16.06031","0.03420"
"193.05000","16.08775","0.03406"
"193.38000","16.11519","0.03409"
"193.71000","16.14281","0.03440"
"194.04000","16.17020","0.03514"
"194.37000","16.19776","0.03543"
"194.70000","16.22527","0.03631"
"195.03000","16.25271","0.03627"
"195.36000","16.28021","0.03682"
"195.69000","16.30765","0.03750"
"196.02000","16.33528","0.03774"
"196.35000","16.36278","0.03782"
"196.68000","16.39022","0.03865"
"197.01000","16.41773","0.03945"
"197.34000","16.44517","0.03954"
"197.67000","16.47267","0.04021"
"198.00000","16.50024","0.04032"
"198.33000","16.52768","0.04030"
"198.66000","16.55524","0.04038"
"198.99000","16.58269","0.04123"
"199.32000","16.61025","0.04203"
"199.65000","16.63769","0.04221"
"199.98000","16.66514","0.04284"
"200.31000","16.69276","0.04280"
"200.64000","16.72026","0.04344"
"200.97000","16.74771","0.04403"
"201.30000","16.77527","0.04466"
"201.63000","16.80271","0.04527"
"201.96000","16.83022","0.04508"
"202.29000","16.85772","0.04539"
"202.62000","16.88522","0.04643"
"202.95000","16.91278","0.04637"
"203.28000","16.94023","0.04745"
"203.61000","16.96779","0.04760"
"203.94000","16.99523","0.04847"
"204.27000","17.02268","0.04844"
"204.60000","17.05024","0.04921"
"204.93000","17.07774","0.04946"
"205.26000","17.10519","0.05027"
"205.59000","17.13275","0.05029"
"205.92000","17.16019","0.05104"
"206.25000","17.18776","0.05181"
"206.58000","17.21520","0.05174"
"206.91000","17.24270","0.05255"
"207.24000","17.27027","0.05405"
"207.57000","17.29765","0.05431"
"207.90000","17.32521","0.05477"
"208.23000","17.35271","0.05548"
"208.56000","17.38016","0.05668"
"208.89000","17.40778","0.05677"
"209.22000","17.43522","0.05780"
"209.55000","17.46273","0.05841"
"209.88000","17.49023","0.05921"
"210.21000","17.51773","0.06098"
"210.54000","17.54518","0.06090"
"210.87000","17.57274","0.06173"
"211.20000","17.60024","0.06272"
"211.53000","17.62775","0.06316"
"211.86000","17.65525","0.06402"
"212.19000","17.68275","0.06522"
"212.52000","17.71026","0.06573"
"212.85000","17.73770","0.06679"
"213.18000","17.76526","0.06701"
"213.51000","17.79271","0.06810"
"213.84000","17.82021","0.06834"
"214.17000","17.84771","0.06892"
"214.50000","17.87522","0.06899"
"214.83000","17.90272","0.06981"
"215.16000","17.93022","0.07034"
"215.49000","17.95773","0.07071"
"215.82000","17.98523","0.07137"
"216.15000","18.01273","0.07230"
"216.48000","18.04024","0.07271"
"216.81000","18.06774","0.07309"
"217.14000","18.09518","0.07374"
"217.47000","18.12275","0.07412"
"217.80000","18.15019","0.07507"
"218.13000","18.17769","0.07611"
"218.46000","18.20526","0.07671"
"218.79000","18.23270","0.07736"
"219.12000","18.26026","0.07836"
"219.45000","18.28770","0.07941"
"219.78000","18.31521","0.08031"
"220.11000","18.34271","0.08169"
"220.44000","18.37021","0.08234"
"220.77000","18.39772","0.08357"
"221.10000","18.42522","0.08440"
"221.43000","18.45272","0.08596"
"221.76000","18.48029","0.08627"
"222.09000","18.50767","0.08746"
"222.42000","18.53529","0.08926"
"222.75000","18.56280","0.09009"
"223.08000","18.59018","0.09083"
"223.41000","18.61780","0.09166"
"223.74000","18.64519","0.09254"
"224.07000","18.67269","0.09360"
"224.40000","18.70031","0.09397"
"224.73000","18.72770","0.09454"
"225.06000","18.75526","0.09543"
"225.39000","18.78270","0.09567"
"225.72000","18.81021","0.09621"
"226.05000","18.83771","0.09696"
"226.38000","18.86515","0.09764"
"226.71000","18.89277","0.09801"
"227.04000","18.92028","0.09876"
"227.37000","18.94772","0.09963"
"227.70000","18.97522","0.10048"
"228.03000","19.00273","0.10087"
"228.36000","19.03017","0.10184"
"228.69000","19.05773","0.10238"
"229.02000","19.08518","0.10331"
"229.35000","19.11280","0.10359"
"229.68000","19.14018","0.10466"
"230.01000","19.16775","0.10551"
"230.34000","19.19525","0.10651"
"230.67000","19.22263","0.10724"
"231.00000","19.25026","0.10822"
"231.33000","19.27776","0.10970"
"231.66000","19.30520","0.10980"
"231.99000","19.33277","0.11158"
"232.32000","19.36021","0.11252"
"232.65000","19.38771","0.11331"
"232.98000","19.41522","0.11443"
"233.31000","19.44272","0.11527"
"233.64000","19.47028","0.11655"
"233.97000","19.49773","0.11760"
"234.30000","19.52523","0.11875"
"234.63000","19.55279","0.11945"
"234.96000","19.58017","0.12049"
"235.29000","19.60774","0.12128"
"235.62000","19.63524","0.12243"
"235.95000","19.66269","0.12344"
"236.28000","19.69019","0.12443"
"236.61000","19.71775","0.12582"
"236.94000","19.74520","0.12692"
"237.27000","19.77270","0.12841"
"237.60000","19.80020","0.12994"
"237.93000","19.82776","0.13140"
"238.26000","19.85521","0.13290"
"238.59000","19.88271","0.13493"
"238.92000","19.91027","0.13653"
"239.25000","19.93766","0.13913"
"239.58000","19.96528","0.14087"
"239.91000","19.99278","0.14267"
"240.24000","20.02022","0.14403"
"240.57000","20.04779","0.14624"
"240.90000","20.07523","0.14735"
"241.23000","20.10279","0.14935"
"241.56000","20.13024","0.15052"
"241.89000","20.15768","0.15135"
"242.22000","20.18525","0.15259"
"242.55000","20.21269","0.15306"
"242.88000","20.24019","0.15423"
"243.21000","20.26776","0.15612"
"243.54000","20.29520","0.15644"
"243.87000","20.32276","0.15895"
"244.20000","20.35026","0.16154"
"244.53000","20.37771","0.16366"
"244.86000","20.40521","0.16588"
"245.19000","20.43266","0.16752"
"245.52000","20.46022","0.16935"
"245.85000","20.48772","0.17172"
"246.18000","20.51516","0.12696"
"246.51000","20.54279","0.12308"
"246.84000","20.57017","0.12495"
"247.17000","20.59767","0.12708"
"247.50000","20.62530","0.12834"
"247.83000","20.65268","0.12957"
"248.16000","20.68024","0.13244"
"248.49000","20.70769","0.13606"
"248.82000","20.73525","0.13843"
"249.15000","20.76275","0.14041"
"249.48000","20.79020","0.14373"
"249.81000","20.81776","0.14680"
"250.14000","20.84526","0.14880"
"250.47000","20.87271","0.14955"
"250.80000","20.90027","0.15141"
"251.13000","20.92771","0.15350"
"251.46000","20.95522","0.15529"
"251.79000","20.98272","0.15698"
"252.12000","21.01022","0.15822"
"252.45000","21.03772","0.16030"
"252.78000","21.06517","0.16266"
"253.11000","21.09273","0.16524"
"253.44000","21.12024","0.16718"
"253.77000","21.14774","0.16964"
"254.10000","21.17524","0.17152"
"254.43000","21.20274","0.17395"
"254.76000","21.23013","0.17616"
"255.09000","21.25769","0.17682"
"255.42000","21.28519","0.17841"
"255.75000","21.31276","0.17953"
"256.08000","21.34026","0.18115"
"256.41000","21.36770","0.18282"
"256.74000","21.39527","0.18469"
"257.07000","21.42271","0.18584"
"257.40000","21.45021","0.18762"
"257.73000","21.47772","0.18908"
"258.06000","21.50516","0.19135"
"258.39000","21.53272","0.19305"
"258.72000","21.56023","0.19472"
"259.05000","21.58773","0.19631"
"259.38000","21.61523","0.19782"
"259.71000","21.64267","0.19959"
"260.04000","21.67024","0.20080"
"260.37000","21.69774","0.20275"
"260.70000","21.72524","0.20387"
"261.03000","21.75275","0.20555"
"261.36000","21.78019","0.20703"
"261.69000","21.80775","0.20878"
"262.02000","21.83532","0.20996"
"262.35000","21.86270","0.21123"
"262.68000","21.89026","0.21237"
"263.01000","21.91777","0.21325"
"263.34000","21.94521","0.21401"
"263.67000","21.97271","0.21513"
"264.00000","22.00016","0.21687"
"264.33000","22.02778","0.21811"
"264.66000","22.05522","0.21952"
"264.99000","22.08273","0.22126"
"265.32000","22.11029","0.22314"
"265.65000","22.13767","0.22426"
"265.98000","22.16524","0.22593"
"266.31000","22.19274","0.22745"
"266.64000","22.22024","0.22911"
"266.97000","22.24781","0.23095"
"267.30000","22.27519","0.23204"
"267.63000","22.30275","0.23361"
"267.96000","22.33019","0.23522"
"268.29000","22.35770","0.23712"
"268.62000","22.38526","0.23943"
"268.95000","22.41270","0.24120"
"269.28000","22.44027","0.24424"
"269.61000","22.46777","0.24620"
"269.94000","22.49521","0.24836"
"270.27000","22.52272","0.24927"
"270.60000","22.55022","0.25209"
"270.93000","22.57766","0.25302"
"271.26000","22.60523","0.25494"
"271.59000","22.63267","0.25688"
"271.92000","22.66023","0.25894"
"272.25000","22.68780","0.26164"
"272.58000","22.71518","0.26452"
"272.91000","22.74274","0.26654"
"273.24000","22.77024","0.25572"
"273.57000","22.79769","0.25389"
"273.90000","22.82525","0.25439"
"274.23000","22.85270","0.25604"
"274.56000","22.88026","0.25755"
"274.89000","22.90770","0.26046"
"275.22000","22.93521","0.26232"
"275.55000","22.96271","0.26528"
"275.88000","22.99015","0.26798"
"276.21000","23.01777","0.26967"
"276.54000","23.04522","0.27167"
"276.87000","23.07272","0.27281"
"277.20000","23.10023","0.27459"
"277.53000","23.12773","0.27681"
"277.86000","23.15523","0.27714"
"278.19000","23.18274","0.27552"
"278.52000","23.21018","0.24966"
"278.85000","23.23774","0.24816"
"279.18000","23.26518","0.24832"
"279.51000","23.29275","0.24978"
"279.84000","23.32025","0.24929"
"280.17000","23.34769","0.24924"
"280.50000","23.37519","0.25087"
"280.83000","23.40276","0.25093"
"281.16000","23.43014","0.25178"
"281.49000","23.45771","0.25396"
"281.82000","23.48521","0.25566"
"282.15000","23.51277","0.25803"
"282.48000","23.54028","0.25980"
"282.81000","23.56772","0.26192"
"283.14000","23.59522","0.26346"
"283.47000","23.62266","0.26632"
"283.80000","23.65023","0.26867"
"284.13000","23.67773","0.27063"
"284.46000","23.70518","0.27221"
"284.79000","23.73274","0.27391"
"285.12000","23.76024","0.27587"
"285.45000","23.78774","0.27793"
"285.78000","23.81519","0.27981"
"286.11000","23.84269","0.28194"
"286.44000","23.87025","0.28509"
"286.77000","23.89770","0.28756"
"287.10000","23.92520","0.29074"
"287.43000","23.95276","0.29437"
"287.76000","23.98021","0.29785"
"288.09000","24.00771","0.30121"
"288.42000","24.03527","0.30338"
"288.75000","24.06266","0.30558"
"289.08000","24.09022","0.30718"
"289.41000","24.11778","0.30881"
"289.74000","24.14523","0.30969"
"290.07000","24.17273","0.31244"
"290.40000","24.20017","0.31375"
"290.73000","24.22780","0.31538"
"291.06000","24.25524","0.31739"
"291.39000","24.28268","0.31887"
"291.72000","24.31030","0.32103"
"292.05000","24.33769","0.32221"
"292.38000","24.36519","0.32402"
"292.71000","24.39275","0.32586"
"293.04000","24.42020","0.32743"
"293.37000","24.44776","0.32932"
"293.70000","24.47527","0.33154"
"294.03000","24.50277","0.33274"
"294.36000","24.53021","0.33452"
"294.69000","24.55765","0.33599"
"295.02000","24.58528","0.33830"
"295.35000","24.61278","0.34130"
"295.68000","24.64022","0.34417"
"296.01000","24.66778","0.34695"
"296.34000","24.69517","0.34965"
"296.67000","24.72268","0.35280"
"297.00000","24.75023","0.35464"
"297.33000","24.77768","0.35671"
"297.66000","24.80524","0.25995"
"297.99000","24.83275","0.25752"
"298.32000","24.86025","0.25886"
"298.65000","24.88775","0.26167"
"298.98000","24.91513","0.26507"
"299.31000","24.94276","0.26714"
"299.64000","24.97020","0.26959"
"299.97000","24.99770","0.27292"
"300.30000","25.02527","0.27588"
"300.63000","25.05271","0.27789"
"300.96000","25.08022","0.28040"
"301.29000","25.10772","0.28520"
"301.62000","25.13522","0.29051"
"301.95000","25.16273","0.29371"
"302.28000","25.19017","0.29854"
"302.61000","25.21773","0.30289"
"302.94000","25.24517","0.30530"
"303.27000","25.27262","0.30727"
"303.60000","25.30024","0.30993"
"303.93000","25.32768","0.31184"
"304.26000","25.35519","0.31459"
"304.59000","25.38275","0.31741"
"304.92000","25.41019","0.32038"
"305.25000","25.43770","0.32261"
"305.58000","25.46520","0.32497"
"305.91000","25.49270","0.32728"
"306.24000","25.52021","0.32959"
"306.57000","25.54771","0.33138"
"306.90000","25.57527","0.33355"
"307.23000","25.60284","0.33666"
"307.56000","25.63016","0.33986"
"307.89000","25.65772","0.34377"
"308.22000","25.68522","0.34757"
"308.55000","25.71273","0.35120"
"308.88000","25.74023","0.35463"
"309.21000","25.76768","0.35792"
"309.54000","25.79530","0.36189"
"309.87000","25.82268","0.36547"
"310.20000","25.85018","0.37029"
"310.53000","25.87775","0.37462"
"310.86000","25.90519","0.37841"
"311.19000","25.93275","0.38057"
"311.52000","25.96025","0.38315"
"311.85000","25.98770","0.38565"
"312.18000","26.01520","0.38854"
"312.51000","26.04271","0.39255"
"312.84000","26.07021","0.39618"
"313.17000","26.09777","0.40028"
"313.50000","26.12522","0.21150"
"313.83000","26.15278","0.21285"
"314.16000","26.18028","0.21315"
"314.49000","26.20767","0.21211"
"314.82000","26.23523","0.21380"
"315.15000","26.26267","0.21546"
"315.48000","26.29023","0.22108"
"315.81000","26.31774","0.22887"
"316.14000","26.34518","0.23338"
"316.47000","26.37275","0.23616"
"316.80000","26.40019","0.23677"
"317.13000","26.42781","0.23746"
"317.46000","26.45525","0.24173"
"317.79000","26.48270","0.24924"
"318.12000","26.51026","0.25625"
"318.45000","26.53770","0.26330"
"318.78000","26.56521","0.26910"
"319.11000","26.59277","0.27220"
"319.44000","26.62021","0.27500"
"319.77000","26.64772","0.27651"
"320.10000","26.67522","0.27896"
"320.43000","26.70272","0.28498"
"320.76000","26.73023","0.29213"
"321.09000","26.75767","0.29888"
"321.42000","26.78523","0.30372"
"321.75000","26.81274","0.30799"
"322.08000","26.84018","0.31180"
"322.41000","26.86774","0.31455"
"322.74000","26.89524","0.31824"
"323.07000","26.92269","0.32161"
"323.40000","26.95025","0.32416"
"323.73000","26.97770","0.32723"
"324.06000","27.00526","0.33001"
"324.39000","27.03276","0.33211"
"324.72000","27.06020","0.33466"
"325.05000","27.08771","0.33885"
"325.38000","27.11515","0.34331"
"325.71000","27.14277","0.34888"
"326.04000","27.17028","0.35341"
"326.37000","27.19772","0.35780"
"326.70000","27.22528","0.36244"
"327.03000","27.25273","0.36745"
"327.36000","27.28017","0.37400"
"327.69000","27.30773","0.37887"
"328.02000","27.33524","0.38199"
"328.35000","27.36274","0.38487"
"328.68000","27.39018","0.38886"
"329.01000","27.41775","0.39458"
"329.34000","27.44525","0.40003"
"329.67000","27.47269","0.40373"
"330.00000","27.50019","0.40729"
"330.33000","27.52776","0.41012"
"330.66000","27.55520","0.41314"
"330.99000","27.58277","0.41641"
"331.32000","27.61027","0.41974"
"331.65000","27.63771","0.42338"
"331.98000","27.66522","0.42795"
"332.31000","27.69272","0.43247"
"332.64000","27.72022","0.43701"
"332.97000","27.74772","0.44024"
"333.30000","27.77523","0.44523"
"333.63000","27.80273","0.45092"
"333.96000","27.83017","0.45442"
"334.29000","27.85774","0.45748"
"334.62000","27.88524","0.46053"
"334.95000","27.91269","0.46439"
"335.28000","27.94019","0.46997"
"335.61000","27.96769","0.47609"
"335.94000","27.99525","0.48073"
"336.27000","28.02276","0.48380"
"336.60000","28.05020","0.48723"
"336.93000","28.07776","0.49155"
"337.26000","28.10521","0.49740"
"337.59000","28.13271","0.50309"
"337.92000","28.16027","0.50753"
"338.25000","28.18765","0.51227"
"338.58000","28.21522","0.51715"
"338.91000","28.24272","0.52032"
"339.24000","28.27022","0.52333"
"339.57000","28.29773","0.52612"
"339.90000","28.32517","0.52953"
"340.23000","28.35274","0.53370"
"340.56000","28.38024","0.53754"
"340.89000","28.40768","0.54098"
"341.22000","28.43524","0.54516"
"341.55000","28.46275","0.54976"
"341.88000","28.49019","0.55531"
"342.21000","28.51775","0.55960"
"342.54000","28.54520","0.56416"
"342.87000","28.57276","0.56947"
"343.20000","28.60020","0.57500"
"343.53000","28.62777","0.58145"
"343.86000","28.65521","0.58687"
"344.19000","28.68265","0.59119"
"344.52000","28.71028","0.59606"
"344.85000","28.73772","0.60142"
"345.18000","28.76522","0.60600"
"345.51000","28.79279","0.60995"
"345.84000","28.82023","0.61265"
"346.17000","28.84773","0.61649"
"346.50000","28.87524","0.62091"
"346.83000","28.90274","0.62467"
"347.16000","28.93024","0.62853"
"347.49000","28.95769","0.63231"
"347.82000","28.98525","0.63620"
"348.15000","29.01275","0.64032"
"348.48000","29.04020","0.64528"
"348.81000","29.06776","0.65141"
"349.14000","29.09520","0.65783"
"349.47000","29.12271","0.66251"
"349.80000","29.15021","0.66601"
"350.13000","29.17771","0.67051"
"350.46000","29.20521","0.67637"
"350.79000","29.23272","0.68403"
"351.12000","29.26022","0.68938"
"351.45000","29.28778","0.69402"
"351.78000","29.31517","0.69793"
"352.11000","29.34279","0.70358"
"352.44000","29.37029","0.70986"
"352.77000","29.39768","0.71521"
"353.10000","29.42530","0.71927"
"353.43000","29.45274","0.72257"
"353.76000","29.48019","0.72599"
"354.09000","29.50769","0.72880"
"354.42000","29.53519","0.73224"
"354.75000","29.56276","0.73584"
"355.08000","29.59020","0.74054"
"355.41000","29.61776","0.74481"
"355.74000","29.64526","0.74931"
"356.07000","29.67265","0.75456"
"356.40000","29.70021","0.75956"
"356.73000","29.72778","0.76460"
"357.06000","29.75516","0.77001"
"357.39000","29.78272","0.77660"
"357.72000","29.81022","0.78477"
"358.05000","29.83773","0.79128"
"358.38000","29.86523","0.79614"
"358.71000","29.89268","0.80042"
"359.04000","29.92024","0.80666"
"359.37000","29.94774","0.81398"
"359.70000","29.97519","0.81989"
"360.03000","30.00281","0.82526"
"360.36000","30.03013","0.82983"
"360.69000","30.05769","0.83406"
"361.02000","30.08526","0.83733"
"361.35000","30.11264","0.84010"
"361.68000","30.14026","0.84416"
"362.01000","30.16771","0.84803"
"362.34000","30.19521","0.85204"
"362.67000","30.22271","0.85655"
"363.00000","30.25016","0.86171"
"363.33000","30.27778","0.86691"
"363.66000","30.30516","0.87101"
"363.99000","30.33273","0.87523"
"364.32000","30.36029","0.88155"
"364.65000","30.38767","0.87802"
"364.98000","30.41524","0.88250"
"365.31000","30.44274","0.88778"
"365.64000","30.47018","0.89410"
"365.97000","30.49775","0.89872"
"366.30000","30.52519","0.61461"
"366.63000","30.55275","0.61161"
"366.96000","30.58026","0.60655"
"367.29000","30.60770","0.61235"
"367.62000","30.63526","0.61022"
"367.95000","30.66270","0.61301"
"368.28000","30.69021","0.61599"
"368.61000","30.71777","0.61765"
"368.94000","30.74515","0.62537"
"369.27000","30.77278","0.62647"
"369.60000","30.80022","0.63140"
"369.93000","30.82766","0.63552"
"370.26000","30.85523","0.63777"
"370.59000","30.88267","0.64833"
"370.92000","30.91023","0.65416"
"371.25000","30.93773","0.66067"
"371.58000","30.96518","0.66645"
"371.91000","30.99274","0.66940"
"372.24000","31.02025","0.58103"
"372.57000","31.04769","0.43938"
"372.90000","31.07525","0.44671"
"373.23000","31.10270","0.45450"
"373.56000","31.13026","0.46205"
"373.89000","31.15770","0.47095"
"374.22000","31.18526","0.48176"
"374.55000","31.21277","0.48712"
"374.88000","31.24021","0.49561"
"375.21000","31.26777","0.50025"
"375.54000","31.29528","0.50609"
"375.87000","31.32272","0.50917"
"376.20000","31.35022","0.51369"
"376.53000","31.37773","0.51826"
"376.86000","31.40517","0.52189"
"377.19000","31.43273","0.52548"
"377.52000","31.46018","0.53114"
"377.85000","31.48774","0.53745"
"378.18000","31.51518","0.54238"
"378.51000","31.54268","0.54522"
"378.84000","31.57025","0.54908"
"379.17000","31.59769","0.55397"
"379.50000","31.62519","0.55900"
"379.83000","31.65276","0.56404"
"380.16000","31.68026","0.57132"
"380.49000","31.70770","0.57828"
"380.82000","31.73521","0.58401"
"381.15000","31.76277","0.58652"
"381.48000","31.79021","0.58952"
"381.81000","31.81771","0.59321"
"382.14000","31.84528","0.60028"
"382.47000","31.87272","0.60730"
"382.80000","31.90017","0.61046"
"383.13000","31.92773","0.61326"
"383.46000","31.95523","0.61708"
"383.79000","31.98273","0.62072"
"384.12000","32.01024","0.62630"
"384.45000","32.03768","0.63050"
"384.78000","32.06525","0.63408"
"385.11000","32.09269","0.63653"
"385.44000","32.12025","0.64111"
"385.77000","32.14775","0.64631"
"386.10000","32.17520","0.65474"
"386.43000","32.20276","0.66088"
"386.76000","32.23021","0.66451"
"387.09000","32.25771","0.66955"
"387.42000","32.28527","0.67761"
"387.75000","32.31271","0.68541"
"388.08000","32.34028","0.69024"
"388.41000","32.36772","0.69420"
"388.74000","32.39523","0.69884"
"389.07000","32.42266","0.70561"
"389.40000","32.45011","0.71218"
"389.73000","32.47779","0.71611"
"390.06000","32.50524","0.71992"
"390.39000","32.53274","0.72440"
"390.72000","32.56025","0.72713"
"391.05000","32.58775","0.72950"
"391.38000","32.61519","0.73238"
"391.71000","32.64275","0.73678"
"392.04000","32.67020","0.74149"
"392.37000","32.69770","0.74486"
"392.70000","32.72520","0.75030"
"393.03000","32.75277","0.75688"
"393.36000","32.78027","0.76167"
"393.69000","32.80765","0.76638"
"394.02000","32.83527","0.77343"
"394.35000","32.86272","0.78022"
"394.68000","32.89016","0.78861"
"395.01000","32.91779","0.79440"
"395.34000","32.94523","0.79914"
"395.67000","32.97273","0.80530"
"396.00000","33.00023","0.81187"
"396.33000","33.02768","0.81936"
"396.66000","33.05524","0.82543"
"396.99000","33.08268","0.83031"
"397.32000","33.11024","0.83424"
"397.65000","33.13769","0.83782"
"397.98000","33.16520","0.84072"
"398.31000","33.19276","0.84475"
"398.64000","33.22020","0.84874"
"398.97000","33.24770","0.85378"
"399.30000","33.27521","0.85891"
"399.63000","33.30271","0.86488"
"399.96000","33.33021","0.86935"
"400.29000","33.35772","0.87402"
"400.62000","33.38522","0.88083"
"400.95000","33.41272","0.88899"
"401.28000","33.44017","0.89496"
"401.61000","33.46773","0.89958"
"401.94000","33.49529","0.90543"
"402.27000","33.52268","0.91130"
"402.60000","33.55030","0.91642"
"402.93000","33.57774","0.92112"
"403.26000","33.60524","0.92755"
"403.59000","33.63275","0.93222"
"403.92000","33.66019","0.93536"
"404.25000","33.68776","0.93807"
"404.58000","33.71519","0.55298"
"404.91000","33.74270","0.52411"
"405.24000","33.77026","0.54813"
"405.57000","33.79771","0.54680"
"405.90000","33.82527","0.55830"
"406.23000","33.85271","0.54533"
"406.56000","33.88015","0.55698"
"406.89000","33.90772","0.56015"
"407.22000","33.93522","0.57400"
"407.55000","33.96273","0.58436"
"407.88000","33.99023","0.59674"
"408.21000","34.01767","0.55602"
"408.54000","34.04523","0.55152"
"408.87000","34.07274","0.54957"
"409.20000","34.10018","0.55122"
"409.53000","34.12775","0.56039"
"409.86000","34.15519","0.56713"
"410.19000","34.18269","0.58144"
"410.52000","34.21031","0.58639"
"410.85000","34.23764","0.58911"
"411.18000","34.26526","0.58963"
"411.51000","34.29271","0.59555"
"411.84000","34.32027","0.60265"
"412.17000","34.34777","0.61001"
"412.50000","34.37515","0.61522"
"412.83000","34.40277","0.61626"
"413.16000","34.43016","0.62135"
"413.49000","34.45773","0.62423"
"413.82000","34.48523","0.63084"
"414.15000","34.51267","0.63560"
"414.48000","34.54023","0.64050"
"414.81000","34.56768","0.64194"
"415.14000","34.59518","0.64588"
"415.47000","34.62275","0.65491"
"415.80000","34.65019","0.66157"
"416.13000","34.67775","0.66552"
"416.46000","34.70525","0.66704"
"416.79000","34.73270","0.67214"
"417.12000","34.76026","0.68161"
"417.45000","34.78770","0.68954"
"417.78000","34.81515","0.69207"
"418.11000","34.84271","0.69462"
"418.44000","34.87015","0.69979"
"418.77000","34.89777","0.70866"
"419.10000","34.92522","0.71261"
"419.43000","34.95266","0.71584"
"419.76000","34.98022","0.72053"
"420.09000","35.00767","0.72513"
"420.42000","35.03529","0.72773"
"420.75000","35.06273","0.72978"
"421.08000","35.09018","0.73328"
"421.41000","35.11774","0.73804"
"421.74000","35.14524","0.74154"
"422.07000","35.17274","0.74479"
"422.40000","35.20025","0.74878"
"422.73000","35.22770","0.75591"
"423.06000","35.25526","0.75996"
"423.39000","35.28264","0.76432"
"423.72000","35.31020","0.77048"
"424.05000","35.33776","0.77620"
"424.38000","35.36515","0.78228"
"424.71000","35.39271","0.78967"
"425.04000","35.42022","0.79535"
"425.37000","35.44772","0.79860"
"425.70000","35.47516","0.80319"
"426.03000","35.50272","0.80985"
"426.36000","35.53023","0.81653"
"426.69000","35.55779","0.82162"
"427.02000","35.58517","0.82776"
"427.35000","35.61274","0.83211"
"427.68000","35.64024","0.83495"
"428.01000","35.66768","0.83771"
"428.34000","35.69525","0.84127"
"428.67000","35.72263","0.84372"
"429.00000","35.75026","0.84823"
"429.33000","35.77776","0.85225"
"429.66000","35.80520","0.85618"
"429.99000","35.83276","0.86110"
"430.32000","35.86021","0.86619"
"430.65000","35.88771","0.86971"
"430.98000","35.91521","0.87277"
"431.31000","35.94272","0.87645"
"431.64000","35.97028","0.88168"
"431.97000","35.99772","0.88826"
"432.30000","36.02523","0.89310"
"432.63000","36.05279","0.89759"
"432.96000","36.08023","0.90173"
"433.29000","36.10768","0.90627"
"433.62000","36.13524","0.91224"
"433.95000","36.16274","0.91635"
"434.28000","36.19025","0.92099"
"434.61000","36.21769","0.92125"
"434.94000","36.24525","0.92677"
"435.27000","36.27276","0.93186"
"435.60000","36.30020","0.93608"
"435.93000","36.32776","0.93883"
"436.26000","36.35521","0.94210"
"436.59000","36.38265","0.94602"
"436.92000","36.41027","0.95070"
"437.25000","36.43772","0.95629"
"437.58000","36.46527","0.96274"
"437.91000","36.49272","0.96901"
"438.24000","36.52023","0.97353"
"438.57000","36.54773","0.97755"
"438.90000","36.57511","0.98163"
"439.23000","36.60279","0.98774"
"439.56000","36.63023","0.37444"
"439.89000","36.65774","0.36389"
"440.22000","36.68524","0.15786"
"440.55000","36.71275","0.18012"
"440.88000","36.74019","0.16325"
"441.21000","36.76775","0.15408"
"441.54000","36.79520","0.18093"
"441.87000","36.82276","0.19271"
"442.20000","36.85020","0.17703"
"442.53000","36.87777","0.17953"
"442.86000","36.90527","0.19705"
"443.19000","36.93271","0.19092"
"443.52000","36.96021","0.18112"
"443.85000","36.98772","0.18741"
"444.18000","37.01522","0.20568"
"444.51000","37.04272","0.20088"
"444.84000","37.07023","0.19592"
"445.17000","37.09773","0.20292"
"445.50000","37.12523","0.21400"
"445.83000","37.15268","0.21271"
"446.16000","37.18024","0.20817"
"446.49000","37.20768","0.21117"
"446.82000","37.23525","0.21958"
"447.15000","37.26275","0.22137"
"447.48000","37.29019","0.21645"
"447.81000","37.31776","0.21717"
"448.14000","37.34520","0.22422"
"448.47000","37.37270","0.23048"
"448.80000","37.40020","0.08248"
"449.13000","37.42771","0.03279"
"449.46000","37.45521","0.03684"
"449.79000","37.48278","0.03652"
"450.12000","37.51022","0.02390"
"450.45000","37.53778","0.02313"
"450.78000","37.56522","0.02839"
"451.11000","37.59273","0.02337"
"451.44000","37.62023","0.04459"
"451.77000","37.64767","0.03265"
"452.10000","37.67524","0.04298"
"452.43000","37.70274","0.02801"
"452.76000","37.73018","0.02873"
"453.09000","37.75769","0.03088"
"453.42000","37.78519","0.02868"
"453.75000","37.81276","0.03643"
"454.08000","37.84020","0.04043"
"454.41000","37.86770","0.03942"
"454.74000","37.89526","0.03455"
"455.07000","37.92271","0.03766"
"455.40000","37.95027","0.03229"
"455.73000","37.97778","0.03496"
"456.06000","38.00522","0.03870"
"456.39000","38.03272","0.03562"
"456.72000","38.06022","0.04263"
"457.05000","38.08773","0.04297"
"457.38000","38.11523","0.04436"
"457.71000","38.14267","0.04052"
"458.04000","38.17030","0.04309"
"458.37000","38.19774","0.04104"
"458.70000","38.22524","0.04252"
"459.03000","38.25275","0.04352"
"459.36000","38.28019","0.04456"
"459.69000","38.30769","0.04638"
"460.02000","38.33525","0.04356"
"460.35000","38.36270","0.04890"
"460.68000","38.39026","0.04481"
"461.01000","38.41771","0.04911"
"461.34000","38.44527","0.04728"
"461.67000","38.47277","0.04994"
"462.00000","38.50016","0.04793"
"462.33000","38.52772","0.05017"
"462.66000","38.55522","0.04846"
"462.99000","38.58272","0.05114"
"463.32000","38.61023","0.05102"
"463.65000","38.63767","0.05073"
"463.98000","38.66529","0.05191"
"464.31000","38.69273","0.05436"
"464.64000","38.72024","0.05441"
"464.97000","38.74774","0.05414"
"465.30000","38.77519","0.05717"
"465.63000","38.80281","0.05687"
"465.96000","38.83025","0.06047"
"466.29000","38.85775","0.06350"
"466.62000","38.88526","0.04874"
"466.95000","38.91276","0.05798"
"467.28000","38.94020","0.05755"
"467.61000","38.96777","0.06585"
"467.94000","38.99521","0.05624"
"468.27000","39.02277","0.06718"
"468.60000","39.05022","0.06236"
"468.93000","39.07772","0.06912"
"469.26000","39.10522","0.06310"
"469.59000","39.13267","0.07025"
"469.92000","39.16023","0.06646"
"470.25000","39.18773","0.07146"
"470.58000","39.21524","0.06719"
"470.91000","39.24274","0.07259"
"471.24000","39.27024","0.06934"
"471.57000","39.29775","0.07404"
"471.90000","39.32525","0.07053"
"472.23000","39.35269","0.07482"
"472.56000","39.38025","0.07178"
"472.89000","39.40770","0.07616"
"473.22000","39.43520","0.07299"
"473.55000","39.46277","0.07609"
"473.88000","39.49015","0.07520"
"474.21000","39.51771","0.07762"
"474.54000","39.54522","0.07782"
"474.87000","39.57266","0.07763"
"475.20000","39.60022","0.08113"
"475.53000","39.62767","0.07949"
"475.86000","39.65523","0.08512"
"476.19000","39.68279","0.08039"
"476.52000","39.71024","0.08838"
"476.85000","39.73774","0.08299"
"477.18000","39.76518","0.09054"
"477.51000","39.79269","0.08541"
"477.84000","39.82025","0.09127"
"478.17000","39.84769","0.08840"
"478.50000","39.87525","0.09131"
"478.83000","39.90276","0.09158"
"479.16000","39.93020","0.09136"
"479.49000","39.95776","0.09398"
"479.82000","39.98520","0.09229"
"480.15000","40.01277","0.09585"
"480.48000","40.04021","0.09340"
"480.81000","40.06766","0.09662"
"481.14000","40.09528","0.09472"
"481.47000","40.12272","0.09717"
"481.80000","40.15017","0.09629"
"482.13000","40.17778","0.09688"
"482.46000","40.20517","0.09775"
"482.79000","40.23273","0.09719"
"483.12000","40.26024","-0.00319"
"483.45000","40.28768","0.00313"
"483.78000","40.31524","0.00142"
"484.11000","40.34269","0.00141"
"484.44000","40.37031","0.00116"
"484.77000","40.39775","0.00132"
"485.10000","40.42520","0.00089"
"485.43000","40.45282","0.00172"
"485.76000","40.48020","0.00109"
"486.09000","40.50771","0.00150"
"486.42000","40.53527","0.00093"
"486.75000","40.56271","0.00191"
"487.08000","40.59028","0.00120"
"487.41000","40.61772","0.00129"
"487.67000","40.63942","0.00124"