File: Force_trajectories/161221_2/Specimen_RawData_2.csv
End date,"12/21/2016"
Specimen label,"24T_90"
Maximum Load,"1.06486",N

Time,Extension,Load
(s),(mm),(N)
"0.00000","0.00000","0.00011"
"0.34200","0.02840","0.00071"
"0.68400","0.05710","0.00086"
"1.02600","0.08568","0.00096"
"1.36800","0.11414","0.00101"
"1.71000","0.14260","0.00096"
"2.05200","0.17118","0.00167"
"2.39400","0.19958","0.00129"
"2.73600","0.22822","0.00129"
"3.07800","0.25668","0.00148"
"3.42000","0.28508","0.00156"
"3.76200","0.31372","0.00156"
"4.10400","0.34212","0.00182"
"4.44600","0.37064","0.00157"
"4.78800","0.39915","0.00137"
"5.13000","0.42767","0.00179"
"5.47200","0.45613","0.00172"
"5.81400","0.48459","0.00139"
"6.15600","0.51305","0.00186"
"6.49800","0.54169","0.00179"
"6.84000","0.57015","0.00132"
"7.18200","0.59861","0.00181"
"7.52400","0.62713","0.00222"
"7.86600","0.65559","0.00207"
"8.20800","0.68411","0.00189"
"8.55000","0.71269","0.00182"
"8.89200","0.74115","0.00192"
"9.23400","0.76967","0.00194"
"9.57600","0.79813","0.00192"
"9.91800","0.82665","0.00196"
"10.26000","0.85517","0.00185"
"10.60200","0.88369","0.00224"
"10.94400","0.91209","0.00231"
"11.28600","0.94061","0.00202"
"11.62800","0.96913","0.00214"
"11.97000","0.99753","0.00233"
"12.31200","1.02617","0.00220"
"12.65400","1.05457","0.00179"
"12.99600","1.08315","0.00198"
"13.33800","1.11167","0.00234"
"13.68000","1.14013","0.00211"
"14.02200","1.16865","0.00215"
"14.36400","1.19723","0.00229"
"14.70600","1.22557","0.00220"
"15.04800","1.25415","0.00235"
"15.39000","1.28266","0.00110"
"15.73200","1.31112","0.00213"
"16.07400","1.33970","0.00212"
"16.41600","1.36810","0.00222"
"16.75800","1.39662","0.00255"
"17.10000","1.42514","0.00183"
"17.44200","1.45360","0.00219"
"17.78400","1.48212","0.00256"
"18.12600","1.51064","0.00261"
"18.46800","1.53910","0.00237"
"18.81000","1.56768","0.00228"
"19.15200","1.59620","0.00207"
"19.49400","1.62460","0.00227"
"19.83600","1.65312","0.00226"
"20.17800","1.68164","0.00261"
"20.52000","1.71010","0.00243"
"20.86200","1.73868","0.00262"
"21.20400","1.76708","0.00234"
"21.54600","1.79566","0.00218"
"21.88800","1.82412","0.00204"
"22.23000","1.85258","0.00228"
"22.57200","1.88116","0.00218"
"22.91400","1.90962","0.00208"
"23.25600","1.93814","0.00238"
"23.59800","1.96666","0.00173"
"23.94000","1.99512","0.00219"
"24.28200","2.02364","0.00216"
"24.62400","2.05216","0.00223"
"24.96600","2.08062","0.00215"
"25.30800","2.10914","0.00266"
"25.65000","2.13766","0.00244"
"25.99200","2.16606","0.00222"
"26.33400","2.19463","0.00250"
"26.67600","2.22315","0.00227"
"27.01800","2.25155","0.00266"
"27.36000","2.28013","0.00233"
"27.70200","2.30865","0.00216"
"28.04400","2.33711","0.00237"
"28.38600","2.36569","0.00272"
"28.72800","2.39415","0.00224"
"29.07000","2.42261","0.00250"
"29.41200","2.45119","0.00263"
"29.75400","2.47959","0.00258"
"30.09600","2.50817","0.00269"
"30.43800","2.53669","0.00249"
"30.78000","2.56515","0.00214"
"31.12200","2.59361","0.00233"
"31.46400","2.62213","0.00227"
"31.80600","2.65059","0.00259"
"32.14800","2.67917","0.00293"
"32.49000","2.70763","0.00239"
"32.83200","2.73615","0.00270"
"33.17400","2.76467","0.00266"
"33.51600","2.79313","0.00222"
"33.85800","2.82165","0.00239"
"34.20000","2.85011","0.00214"
"34.54200","2.87857","0.00247"
"34.88400","2.90721","0.00237"
"35.22600","2.93561","0.00239"
"35.56800","2.96413","0.00233"
"35.91000","2.99265","0.00224"
"36.25200","3.02105","0.00249"
"36.59400","3.04968","0.00223"
"36.93600","3.07820","0.00233"
"37.27800","3.10660","0.00236"
"37.62000","3.13518","0.00207"
"37.96200","3.16364","0.00243"
"38.30400","3.19210","0.00207"
"38.64600","3.22068","0.00233"
"38.98800","3.24908","0.00256"
"39.33000","3.27766","0.00211"
"39.67200","3.30612","0.00213"
"40.01400","3.33452","0.00253"
"40.35600","3.36316","0.00259"
"40.69800","3.39168","0.00213"
"41.04000","3.42008","0.00236"
"41.38200","3.44866","0.00248"
"41.72400","3.47712","0.00220"
"42.06600","3.50564","0.00193"
"42.40800","3.53410","0.00235"
"42.75000","3.56262","0.00237"
"43.09200","3.59120","0.00216"
"43.43400","3.61966","0.00220"
"43.77600","3.64812","0.00244"
"44.11800","3.67664","0.00231"
"44.46000","3.70516","0.00246"
"44.80200","3.73362","0.00253"
"45.14400","3.76214","0.00224"
"45.48600","3.79066","0.00229"
"45.82800","3.81912","0.00239"
"46.17000","3.84764","0.00227"
"46.51200","3.87610","0.00242"
"46.85400","3.90462","0.00226"
"47.19600","3.93314","0.00251"
"47.53800","3.96165","0.00245"
"47.88000","3.99017","0.00232"
"48.22200","4.01863","0.00259"
"48.56400","4.04709","0.00203"
"48.90600","4.07567","0.00240"
"49.24800","4.10413","0.00251"
"49.59000","4.13265","0.00230"
"49.93200","4.16117","0.00247"
"50.27400","4.18957","0.00263"
"50.61600","4.21809","0.00246"
"50.95800","4.24673","0.00240"
"51.30000","4.27507","0.00226"
"51.64200","4.30365","0.00252"
"51.98400","4.33217","0.00210"
"52.32600","4.36063","0.00201"
"52.66800","4.38915","0.00241"
"53.01000","4.41767","0.00228"
"53.35200","4.44607","0.00208"
"53.69400","4.47471","0.00221"
"54.03600","4.50311","0.00229"
"54.37800","4.53163","0.00217"
"54.72000","4.56015","0.00221"
"55.06200","4.58855","0.00232"
"55.40400","4.61719","0.00244"
"55.74600","4.64559","0.00243"
"56.08800","4.67417","0.00228"
"56.43000","4.70269","0.00253"
"56.77200","4.73115","0.00249"
"57.11400","4.75967","0.00259"
"57.45600","4.78819","0.00241"
"57.79800","4.81659","0.00245"
"58.14000","4.84516","0.00246"
"58.48200","4.87362","0.00214"
"58.82400","4.90208","0.00238"
"59.16600","4.93060","0.00221"
"59.50800","4.95912","0.00253"
"59.85000","4.98764","0.00248"
"60.19200","5.01616","0.00237"
"60.53400","5.04462","0.00248"
"60.87600","5.07314","0.00236"
"61.21800","5.10160","0.00238"
"61.56000","5.13012","0.00237"
"61.90200","5.15864","0.00226"
"62.24400","5.18716","0.00243"
"62.58600","5.21562","0.00245"
"62.92800","5.24414","0.00237"
"63.27000","5.27260","0.00227"
"63.61200","5.30112","0.00229"
"63.95400","5.32964","0.00231"
"64.29600","5.35810","0.00219"
"64.63800","5.38662","0.00216"
"64.98000","5.41514","0.00215"
"65.32200","5.44360","0.00234"
"65.66400","5.47212","0.00211"
"66.00600","5.50064","0.00232"
"66.34800","5.52910","0.00247"
"66.69000","5.55768","0.00266"
"67.03200","5.58620","0.00237"
"67.37400","5.61460","0.00247"
"67.71600","5.64312","0.00249"
"68.05800","5.67164","0.00250"
"68.40000","5.70004","0.00268"
"68.74200","5.72867","0.00239"
"69.08400","5.75713","0.00216"
"69.42600","5.78565","0.00232"
"69.76800","5.81417","0.00261"
"70.11000","5.84257","0.00261"
"70.45200","5.87115","0.00254"
"70.79400","5.89967","0.00259"
"71.13600","5.92807","0.00233"
"71.47800","5.95671","0.00229"
"71.82000","5.98511","0.00228"
"72.16200","6.01363","0.00226"
"72.50400","6.04215","0.00215"
"72.84600","6.07055","0.00226"
"73.18800","6.09919","0.00219"
"73.53000","6.12765","0.00191"
"73.87200","6.15611","0.00235"
"74.21400","6.18469","0.00248"
"74.55600","6.21315","0.00226"
"74.89800","6.24161","0.00211"
"75.24000","6.27013","0.00217"
"75.58200","6.29859","0.00194"
"75.92400","6.32717","0.00220"
"76.26600","6.35569","0.00250"
"76.60800","6.38409","0.00216"
"76.95000","6.41261","0.00176"
"77.29200","6.44119","0.00219"
"77.63400","6.46959","0.00257"
"77.97600","6.49817","0.00228"
"78.31800","6.52663","0.00243"
"78.66000","6.55514","0.00250"
"79.00200","6.58360","0.00233"
"79.34400","6.61212","0.00193"
"79.68600","6.64064","0.00216"
"80.02800","6.66916","0.00241"
"80.37000","6.69762","0.00216"
"80.71200","6.72614","0.00207"
"81.05400","6.75466","0.00219"
"81.39600","6.78312","0.00241"
"81.73800","6.81164","0.00216"
"82.08000","6.84010","0.00205"
"82.42200","6.86862","0.00187"
"82.76400","6.89714","0.00243"
"83.10600","6.92566","0.00225"
"83.44800","6.95412","0.00208"
"83.79000","6.98264","0.00211"
"84.13200","7.01110","0.00215"
"84.47400","7.03968","0.00237"
"84.81600","7.06814","0.00246"
"85.15800","7.09660","0.00207"
"85.50000","7.12512","0.00234"
"85.84200","7.15364","0.00248"
"86.18400","7.18210","0.00249"
"86.52600","7.21068","0.00236"
"86.86800","7.23914","0.00236"
"87.21000","7.26760","0.00263"
"87.55200","7.29618","0.00205"
"87.89400","7.32458","0.00249"
"88.23600","7.35316","0.00210"
"88.57800","7.38168","0.00218"
"88.92000","7.41008","0.00224"
"89.26200","7.43871","0.00254"
"89.60400","7.46706","0.00224"
"89.94600","7.49563","0.00223"
"90.28800","7.52415","0.00243"
"90.63000","7.55261","0.00253"
"90.97200","7.58113","0.00221"
"91.31400","7.60959","0.00239"
"91.65600","7.63805","0.00242"
"91.99800","7.66663","0.00250"
"92.34000","7.69515","0.00244"
"92.68200","7.72361","0.00222"
"93.02400","7.75213","0.00225"
"93.36600","7.78059","0.00272"
"93.70800","7.80911","0.00280"
"94.05000","7.83769","0.00246"
"94.39200","7.86609","0.00251"
"94.73400","7.89467","0.00237"
"95.07600","7.92313","0.00231"
"95.41800","7.95159","0.00255"
"95.76000","7.98017","0.00256"
"96.10200","8.00863","0.00244"
"96.44400","8.03715","0.00228"
"96.78600","8.06567","0.00247"
"97.12800","8.09413","0.00255"
"97.47000","8.12265","0.00239"
"97.81200","8.15117","0.00267"
"98.15400","8.17957","0.00230"
"98.49600","8.20815","0.00223"
"98.83800","8.23661","0.00215"
"99.18000","8.26513","0.00251"
"99.52200","8.29365","0.00205"
"99.86400","8.32216","0.00267"
"100.20600","8.35063","0.00251"
"100.54800","8.37908","0.00260"
"100.89000","8.40760","0.00268"
"101.23200","8.43612","0.00237"
"101.57400","8.46458","0.00217"
"101.91600","8.49310","0.00236"
"102.25800","8.52162","0.00213"
"102.60000","8.55020","0.00246"
"102.94200","8.57860","0.00236"
"103.28400","8.60718","0.00275"
"103.62600","8.63570","0.00269"
"103.96800","8.66404","0.00253"
"104.31000","8.69262","0.00274"
"104.65200","8.72114","0.00238"
"104.99400","8.74960","0.00237"
"105.33600","8.77812","0.00266"
"105.67800","8.80658","0.00281"
"106.02000","8.83516","0.00264"
"106.36200","8.86368","0.00261"
"106.70400","8.89208","0.00267"
"107.04600","8.92066","0.00259"
"107.38800","8.94918","0.00291"
"107.73000","8.97764","0.00275"
"108.07200","9.00616","0.00275"
"108.41400","9.03462","0.00280"
"108.75600","9.06308","0.00321"
"109.09800","9.09166","0.00237"
"109.44000","9.12012","0.00260"
"109.78200","9.14864","0.00268"
"110.12400","9.17715","0.00294"
"110.46600","9.20556","0.00263"
"110.80800","9.23413","0.00257"
"111.15000","9.26265","0.00315"
"111.49200","9.29111","0.00308"
"111.83400","9.31969","0.00243"
"112.17600","9.34809","0.00277"
"112.51800","9.37667","0.00271"
"112.86000","9.40513","0.00272"
"113.20200","9.43359","0.00282"
"113.54400","9.46211","0.00248"
"113.88600","9.49069","0.00300"
"114.22800","9.51909","0.00304"
"114.57000","9.54767","0.00270"
"114.91200","9.57607","0.00273"
"115.25400","9.60465","0.00268"
"115.59600","9.63311","0.00286"
"115.93800","9.66163","0.00284"
"116.28000","9.69015","0.00289"
"116.62200","9.71861","0.00279"
"116.96400","9.74707","0.00305"
"117.30600","9.77565","0.00278"
"117.64800","9.80411","0.00295"
"117.99000","9.83263","0.00290"
"118.33200","9.86115","0.00318"
"118.67400","9.88967","0.00280"
"119.01600","9.91813","0.00316"
"119.35800","9.94665","0.00323"
"119.70000","9.97511","0.00306"
"120.04200","10.00357","0.00343"
"120.38400","10.03215","0.00311"
"120.72600","10.06061","0.00309"
"121.06800","10.08918","0.00329"
"121.41000","10.11764","0.00326"
"121.75200","10.14604","0.00326"
"122.09400","10.17462","0.00312"
"122.43600","10.20314","0.00330"
"122.77800","10.23160","0.00305"
"123.12000","10.26018","0.00295"
"123.46200","10.28864","0.00331"
"123.80400","10.31710","0.00324"
"124.14600","10.34568","0.00307"
"124.48800","10.37408","0.00356"
"124.83000","10.40266","0.00333"
"125.17200","10.43112","0.00365"
"125.51400","10.45958","0.00357"
"125.85600","10.48816","0.00323"
"126.19800","10.51662","0.00371"
"126.54000","10.54514","0.00346"
"126.88200","10.57366","0.00391"
"127.22400","10.60206","0.00385"
"127.56600","10.63064","0.00389"
"127.90800","10.65922","0.00389"
"128.25000","10.68756","0.00395"
"128.59200","10.71614","0.00414"
"128.93400","10.74466","0.00396"
"129.27600","10.77312","0.00443"
"129.61800","10.80164","0.00418"
"129.96000","10.83010","0.00406"
"130.30200","10.85862","0.00418"
"130.64400","10.88720","0.00436"
"130.98600","10.91554","0.00450"
"131.32800","10.94418","0.00446"
"131.67000","10.97269","0.00454"
"132.01200","11.00109","0.00428"
"132.35400","11.02967","0.00422"
"132.69600","11.05807","0.00450"
"133.03800","11.08665","0.00505"
"133.38000","11.11517","0.00484"
"133.72200","11.14363","0.00508"
"134.06400","11.17215","0.00519"
"134.40600","11.20061","0.00525"
"134.74800","11.22907","0.00539"
"135.09000","11.25765","0.00515"
"135.43200","11.28611","0.00529"
"135.77400","11.31463","0.00566"
"136.11600","11.34315","0.00607"
"136.45800","11.37167","0.00601"
"136.80000","11.40007","0.00589"
"137.14200","11.42865","0.00656"
"137.48400","11.45711","0.00622"
"137.82600","11.48563","0.00667"
"138.16800","11.51415","0.00658"
"138.51000","11.54267","0.00684"
"138.85200","11.57113","0.00708"
"139.19400","11.59965","0.00746"
"139.53600","11.62811","0.00749"
"139.87800","11.65663","0.00773"
"140.22000","11.68521","0.00799"
"140.56200","11.71361","0.00825"
"140.90400","11.74219","0.00860"
"141.24600","11.77059","0.00860"
"141.58800","11.79917","0.00913"
"141.93000","11.82762","0.00945"
"142.27200","11.85609","0.00986"
"142.61400","11.88461","0.00993"
"142.95600","11.91318","0.01036"
"143.29800","11.94158","0.01051"
"143.64000","11.97016","0.01051"
"143.98200","11.99862","0.01118"
"144.32400","12.02714","0.01133"
"144.66600","12.05566","0.01192"
"145.00800","12.08412","0.01207"
"145.35000","12.11258","0.01281"
"145.69200","12.14116","0.01341"
"146.03400","12.16962","0.01382"
"146.37600","12.19820","0.01329"
"146.71800","12.22666","0.01424"
"147.06000","12.25506","0.01341"
"147.40200","12.28364","0.01528"
"147.74400","12.31216","0.01346"
"148.08600","12.34062","0.01291"
"148.42800","12.36914","0.01212"
"148.77000","12.39760","0.01453"
"149.11200","12.42618","0.01412"
"149.45400","12.45470","0.01468"
"149.79600","12.48304","0.01617"
"150.13800","12.51168","0.01599"
"150.48000","12.54014","0.01769"
"150.82200","12.56860","0.01753"
"151.16400","12.59718","0.01862"
"151.50600","12.62558","0.01934"
"151.84800","12.65410","0.02006"
"152.19000","12.68262","0.02018"
"152.53200","12.71114","0.02166"
"152.87400","12.73965","0.02134"
"153.21600","12.76817","0.00325"
"153.55800","12.79663","0.00299"
"153.90000","12.82509","0.00280"
"154.24200","12.85361","0.00323"
"154.58400","12.88207","0.00325"
"154.92600","12.91065","0.00288"
"155.26800","12.93917","0.00324"
"155.61000","12.96757","0.00317"
"155.95200","12.99615","0.00305"
"156.29400","13.02467","0.00336"
"156.63600","13.05313","0.00357"
"156.97800","13.08171","0.00325"
"157.32000","13.11005","0.00379"
"157.66200","13.13863","0.00332"
"158.00400","13.16721","0.00344"
"158.34600","13.19555","0.00380"
"158.68800","13.22413","0.00309"
"159.03000","13.25265","0.00373"
"159.37200","13.28111","0.00395"
"159.71400","13.30969","0.00373"
"160.05600","13.33809","0.00372"
"160.39800","13.36661","0.00397"
"160.74000","13.39519","0.00374"
"161.08200","13.42359","0.00406"
"161.42400","13.45211","0.00411"
"161.76600","13.48063","0.00432"
"162.10800","13.50915","0.00431"
"162.45000","13.53761","0.00422"
"162.79200","13.56612","0.00455"
"163.13400","13.59459","0.00450"
"163.47600","13.62322","0.00459"
"163.81800","13.65162","0.00487"
"164.16000","13.68015","0.00491"
"164.50200","13.70866","0.00516"
"164.84400","13.73706","0.00554"
"165.18600","13.76570","0.00532"
"165.52800","13.79416","0.00541"
"165.87000","13.82256","0.00594"
"166.21200","13.85114","0.00571"
"166.55400","13.87966","0.00614"
"166.89600","13.90812","0.00611"
"167.23800","13.93664","0.00646"
"167.58000","13.96510","0.00674"
"167.92200","13.99368","0.00672"
"168.26400","14.02214","0.00715"
"168.60600","14.05060","0.00707"
"168.94800","14.07912","0.00720"
"169.29000","14.10764","0.00783"
"169.63200","14.13616","0.00807"
"169.97400","14.16468","0.00835"
"170.31600","14.19314","0.00873"
"170.65800","14.22166","0.00880"
"171.00000","14.25012","0.00955"
"171.34200","14.27858","0.00954"
"171.68400","14.30710","0.00985"
"172.02600","14.33568","0.01009"
"172.36800","14.36414","0.00949"
"172.71000","14.39266","0.01018"
"173.05200","14.42118","0.01086"
"173.39400","14.44964","0.01157"
"173.73600","14.47815","0.01213"
"174.07800","14.50662","0.01201"
"174.42000","14.53513","0.01282"
"174.76200","14.56365","0.01299"
"175.10400","14.59211","0.01365"
"175.44600","14.62063","0.01399"
"175.78800","14.64915","0.01519"
"176.13000","14.67755","0.01542"
"176.47200","14.70613","0.01631"
"176.81400","14.73465","0.01678"
"177.15600","14.76311","0.01797"
"177.49800","14.79163","0.01838"
"177.84000","14.82009","0.01858"
"178.18200","14.84867","0.01931"
"178.52400","14.87713","0.02034"
"178.86600","14.90559","0.02134"
"179.20800","14.93411","0.01699"
"179.55000","14.96269","0.01856"
"179.89200","14.99103","0.01931"
"180.23400","15.01967","0.02069"
"180.57600","15.04813","0.02171"
"180.91800","15.07659","0.02237"
"181.26000","15.10517","0.02261"
"181.60200","15.13363","0.02337"
"181.94400","15.16209","0.02271"
"182.28600","15.19067","0.02362"
"182.62800","15.21907","0.02371"
"182.97000","15.24765","0.02301"
"183.31200","15.27623","0.02316"
"183.65400","15.30463","0.02355"
"183.99600","15.33321","0.02424"
"184.33800","15.36161","0.02413"
"184.68000","15.39013","0.02453"
"185.02200","15.41864","0.02491"
"185.36400","15.44710","0.02587"
"185.70600","15.47562","0.02698"
"186.04800","15.50414","0.02736"
"186.39000","15.53260","0.02755"
"186.73200","15.56118","0.02726"
"187.07400","15.58958","0.02887"
"187.41600","15.61810","0.02896"
"187.75800","15.64668","0.03004"
"188.10000","15.67514","0.03052"
"188.44200","15.70366","0.03197"
"188.78400","15.73212","0.03287"
"189.12600","15.76064","0.03378"
"189.46800","15.78916","0.03400"
"189.81000","15.81762","0.03448"
"190.15200","15.84614","0.03620"
"190.49400","15.87460","0.03677"
"190.83600","15.90312","0.03744"
"191.17800","15.93158","0.03827"
"191.52000","15.96016","0.03959"
"191.86200","15.98868","0.04034"
"192.20400","16.01708","0.04123"
"192.54600","16.04566","0.04188"
"192.88800","16.07412","0.04309"
"193.23000","16.10264","0.04382"
"193.57200","16.13116","0.04527"
"193.91400","16.15962","0.04637"
"194.25600","16.18814","0.04690"
"194.59800","16.21665","0.04834"
"194.94000","16.24512","0.04923"
"195.28200","16.27363","0.05061"
"195.62400","16.30215","0.05179"
"195.96600","16.33061","0.05341"
"196.30800","16.35919","0.05408"
"196.65000","16.38759","0.05526"
"196.99200","16.41605","0.05650"
"197.33400","16.44469","0.05787"
"197.67600","16.47309","0.06015"
"198.01800","16.50167","0.06180"
"198.36000","16.53013","0.06093"
"198.70200","16.55865","0.06123"
"199.04400","16.58717","0.06324"
"199.38600","16.61563","0.06582"
"199.72800","16.64409","0.05684"
"200.07000","16.67267","0.05710"
"200.41200","16.70107","0.06008"
"200.75400","16.72965","0.05746"
"201.09600","16.75817","0.05542"
"201.43800","16.78657","0.05628"
"201.78000","16.81521","0.05819"
"202.12200","16.84367","0.05173"
"202.46400","16.87213","0.05313"
"202.80600","16.90065","0.05417"
"203.14800","16.92911","0.05490"
"203.49000","16.95763","0.05591"
"203.83200","16.98615","0.05857"
"204.17400","17.01461","0.05907"
"204.51600","17.04319","0.06149"
"204.85800","17.07165","0.06272"
"205.20000","17.10011","0.06519"
"205.54200","17.12856","0.06810"
"205.88400","17.15714","0.06923"
"206.22600","17.18560","0.07069"
"206.56800","17.21418","0.07306"
"206.91000","17.24264","0.07462"
"207.25200","17.27116","0.07594"
"207.59400","17.29962","0.07738"
"207.93600","17.32814","0.07856"
"208.27800","17.35666","0.07967"
"208.62000","17.38518","0.08055"
"208.96200","17.41364","0.08150"
"209.30400","17.44216","0.08169"
"209.64600","17.47062","0.08269"
"209.98800","17.49908","0.08381"
"210.33000","17.52766","0.08049"
"210.67200","17.55618","0.07092"
"211.01400","17.58458","0.05135"
"211.35600","17.61316","0.05218"
"211.69800","17.64162","0.05457"
"212.04000","17.67014","0.05687"
"212.38200","17.69872","0.05958"
"212.72400","17.72712","0.06180"
"213.06600","17.75564","0.06436"
"213.40800","17.78416","0.06545"
"213.75000","17.81262","0.06624"
"214.09200","17.84114","0.06810"
"214.43400","17.86960","0.06987"
"214.77600","17.89806","0.06690"
"215.11800","17.92669","0.04828"
"215.46000","17.95510","0.05010"
"215.80200","17.98362","0.05223"
"216.14400","18.01219","0.05515"
"216.48600","18.04060","0.05659"
"216.82800","18.06923","0.05880"
"217.17000","18.09763","0.06293"
"217.51200","18.12609","0.06449"
"217.85400","18.15467","0.06723"
"218.19600","18.18313","0.06955"
"218.53800","18.21159","0.07170"
"218.88000","18.24017","0.07394"
"219.22200","18.26857","0.07489"
"219.56400","18.29715","0.07619"
"219.90600","18.32567","0.07792"
"220.24800","18.35407","0.07831"
"220.59000","18.38265","0.07895"
"220.93200","18.41111","0.07982"
"221.27400","18.43963","0.08084"
"221.61600","18.46815","0.08251"
"221.95800","18.49661","0.08348"
"222.30000","18.52519","0.08368"
"222.64200","18.55365","0.08507"
"222.98400","18.58205","0.08568"
"223.32600","18.61063","0.08591"
"223.66800","18.63915","0.08287"
"224.01000","18.66761","0.07995"
"224.35200","18.69613","0.08133"
"224.69400","18.72465","0.08159"
"225.03600","18.75311","0.08303"
"225.37800","18.78163","0.08204"
"225.72000","18.81015","0.05397"
"226.06200","18.83867","0.05572"
"226.40400","18.86713","0.05394"
"226.74600","18.89559","0.05487"
"227.08800","18.92416","0.05536"
"227.43000","18.95263","0.05437"
"227.77200","18.98114","0.05530"
"228.11400","19.00966","0.05624"
"228.45600","19.03812","0.05626"
"228.79800","19.06658","0.05641"
"229.14000","19.09510","0.05743"
"229.48200","19.12362","0.05698"
"229.82400","19.15214","0.05830"
"230.16600","19.18066","0.05916"
"230.50800","19.20912","0.05919"
"230.85000","19.23764","0.06096"
"231.19200","19.26616","0.06179"
"231.53400","19.29456","0.06185"
"231.87600","19.32314","0.06304"
"232.21800","19.35160","0.06379"
"232.56000","19.38012","0.06478"
"232.90200","19.40870","0.06464"
"233.24400","19.43716","0.06665"
"233.58600","19.46556","0.06646"
"233.92800","19.49420","0.06857"
"234.27000","19.52254","0.06835"
"234.61200","19.55112","0.06814"
"234.95400","19.57970","0.06945"
"235.29600","19.60810","0.07033"
"235.63800","19.63667","0.07056"
"235.98000","19.66508","0.07171"
"236.32200","19.69360","0.07209"
"236.66400","19.72217","0.07319"
"237.00600","19.75064","0.07285"
"237.34800","19.77915","0.07505"
"237.69000","19.80761","0.07490"
"238.03200","19.83601","0.07520"
"238.37400","19.86465","0.07626"
"238.71600","19.89317","0.07597"
"239.05800","19.92163","0.07651"
"239.40000","19.95015","0.07726"
"239.74200","19.97861","0.07780"
"240.08400","20.00713","0.07807"
"240.42600","20.03565","0.07834"
"240.76800","20.06411","0.07909"
"241.11000","20.09263","0.07898"
"241.45200","20.12115","0.07964"
"241.79400","20.14955","0.08059"
"242.13600","20.17813","0.08057"
"242.47800","20.20665","0.08060"
"242.82000","20.23505","0.08170"
"243.16200","20.26363","0.08207"
"243.50400","20.29215","0.08182"
"243.84600","20.32061","0.08266"
"244.18800","20.34907","0.08311"
"244.53000","20.37765","0.08316"
"244.87200","20.40611","0.08346"
"245.21400","20.43469","0.08389"
"245.55600","20.46315","0.08469"
"245.89800","20.49167","0.08481"
"246.24000","20.52013","0.08474"
"246.58200","20.54859","0.08527"
"246.92400","20.57716","0.08555"
"247.26600","20.60568","0.08578"
"247.60800","20.63414","0.08579"
"247.95000","20.66267","0.08653"
"248.29200","20.69112","0.08666"
"248.63400","20.71958","0.08685"
"248.97600","20.74817","0.08767"
"249.31800","20.77656","0.08764"
"249.66000","20.80514","0.08754"
"250.00200","20.83366","0.08810"
"250.34400","20.86212","0.08810"
"250.68600","20.89070","0.08851"
"251.02800","20.91916","0.08862"
"251.37000","20.94762","0.08907"
"251.71200","20.97620","0.08949"
"252.05400","21.00460","0.09016"
"252.39600","21.03312","0.09003"
"252.73800","21.06164","0.09034"
"253.08000","21.09004","0.09133"
"253.42200","21.11868","0.09173"
"253.76400","21.14714","0.09184"
"254.10600","21.17560","0.09268"
"254.44800","21.20418","0.09288"
"254.79000","21.23258","0.09364"
"255.13200","21.26116","0.09378"
"255.47400","21.28962","0.09445"
"255.81600","21.31808","0.09445"
"256.15800","21.34666","0.09379"
"256.50000","21.37518","0.09474"
"256.84200","21.40358","0.09512"
"257.18400","21.43210","0.09552"
"257.52600","21.46062","0.09602"
"257.86800","21.48913","0.09662"
"258.21000","21.51765","0.09704"
"258.55200","21.54611","0.09772"
"258.89400","21.57470","0.09806"
"259.23600","21.60315","0.09831"
"259.57800","21.63155","0.09879"
"259.92000","21.66019","0.10027"
"260.26200","21.68865","0.10016"
"260.60400","21.71711","0.10087"
"260.94600","21.74563","0.10122"
"261.28800","21.77409","0.10170"
"261.63000","21.80261","0.10213"
"261.97200","21.83113","0.10243"
"262.31400","21.85959","0.10274"
"262.65600","21.88811","0.10362"
"262.99800","21.91663","0.10415"
"263.34000","21.94509","0.10407"
"263.68200","21.97367","0.10474"
"264.02400","22.00213","0.10584"
"264.36600","22.03059","0.10587"
"264.70800","22.05911","0.10606"
"265.05000","22.08769","0.10637"
"265.39200","22.11609","0.10720"
"265.73400","22.14461","0.10763"
"266.07600","22.17313","0.10832"
"266.41800","22.20159","0.10919"
"266.76000","22.23017","0.10959"
"267.10200","22.25856","0.10980"
"267.44400","22.28715","0.10995"
"267.78600","22.31566","0.11053"
"268.12800","22.34407","0.11161"
"268.47000","22.37271","0.11193"
"268.81200","22.40117","0.11238"
"269.15400","22.42962","0.11347"
"269.49600","22.45820","0.11305"
"269.83800","22.48660","0.11414"
"270.18000","22.51506","0.11384"
"270.52200","22.54364","0.11466"
"270.86400","22.57210","0.11424"
"271.20600","22.60068","0.11382"
"271.54800","22.62914","0.11424"
"271.89000","22.65754","0.11407"
"272.23200","22.68618","0.11408"
"272.57400","22.71464","0.11462"
"272.91600","22.74310","0.11502"
"273.25800","22.77168","0.11554"
"273.60000","22.80008","0.11591"
"273.94200","22.82866","0.11651"
"274.28400","22.85718","0.11587"
"274.62600","22.88558","0.11747"
"274.96800","22.91410","0.11654"
"275.31000","22.94262","0.11649"
"275.65200","22.97108","0.11705"
"275.99400","22.99966","0.11561"
"276.33600","23.02818","-0.00028"
"276.67800","23.05664","0.00342"
"277.02000","23.08516","0.00364"
"277.36200","23.11356","0.00257"
"277.70400","23.14220","0.00278"
"278.04600","23.17066","0.00275"
"278.38800","23.19906","0.00300"
"278.73000","23.22763","0.00291"
"279.07200","23.25616","0.00268"
"279.41400","23.28461","0.00292"
"279.75600","23.31314","0.00277"
"280.09800","23.34160","0.00278"
"280.44000","23.37017","0.00284"
"280.78200","23.39857","0.00279"
"281.12400","23.42715","0.00291"
"281.46600","23.45567","0.00272"
"281.80800","23.48413","0.00274"
"282.15000","23.51259","0.00292"
"282.49200","23.54117","0.00270"
"282.83400","23.56963","0.00343"
"283.17600","23.59809","0.00309"
"283.51800","23.62667","0.00297"
"283.86000","23.65513","0.00322"
"284.20200","23.68359","0.00311"
"284.54400","23.71217","0.00293"
"284.88600","23.74063","0.00305"
"285.22800","23.76909","0.00291"
"285.57000","23.79773","0.00294"
"285.91200","23.82607","0.00289"
"286.25400","23.85465","0.00305"
"286.59600","23.88317","0.00283"
"286.93800","23.91163","0.00309"
"287.28000","23.94015","0.00285"
"287.62200","23.96861","0.00325"
"287.96400","23.99713","0.00336"
"288.30600","24.02571","0.00277"
"288.64800","24.05411","0.00315"
"288.99000","24.08262","0.00341"
"289.33200","24.11115","0.00316"
"289.67400","24.13955","0.00315"
"290.01600","24.16818","0.00333"
"290.35800","24.19665","0.00301"
"290.70000","24.22511","0.00301"
"291.04200","24.25368","0.00355"
"291.38400","24.28214","0.00307"
"291.72600","24.31060","0.00306"
"292.06800","24.33918","0.00304"
"292.41000","24.36758","0.00330"
"292.75200","24.39616","0.00274"
"293.09400","24.42462","0.00318"
"293.43600","24.45308","0.00308"
"293.77800","24.48166","0.00314"
"294.12000","24.51018","0.00308"
"294.46200","24.53858","0.00280"
"294.80400","24.56722","0.00310"
"295.14600","24.59556","0.00313"
"295.48800","24.62414","0.00281"
"295.83000","24.65260","0.00297"
"296.17200","24.68112","0.00321"
"296.51400","24.70964","0.00327"
"296.85600","24.73816","0.00300"
"297.19800","24.76662","0.00318"
"297.54000","24.79520","0.00321"
"297.88200","24.82366","0.00296"
"298.22400","24.85212","0.00292"
"298.56600","24.88064","0.00325"
"298.90800","24.90910","0.00311"
"299.25000","24.93761","0.00338"
"299.59200","24.96614","0.00314"
"299.93400","24.99459","0.00340"
"300.27600","25.02311","0.00327"
"300.61800","25.05164","0.00350"
"300.96000","25.08010","0.00324"
"301.30200","25.10867","0.00340"
"301.64400","25.13713","0.00354"
"301.98600","25.16559","0.00350"
"302.32800","25.19417","0.00352"
"302.67000","25.22264","0.00276"
"303.01200","25.25115","0.00334"
"303.35400","25.27967","0.00322"
"303.69600","25.30807","0.00309"
"304.03800","25.33665","0.00332"
"304.38000","25.36517","0.00343"
"304.72200","25.39363","0.00353"
"305.06400","25.42221","0.00321"
"305.40600","25.45067","0.00378"
"305.74800","25.47907","0.00352"
"306.09000","25.50771","0.00341"
"306.43200","25.53611","0.00365"
"306.77400","25.56463","0.00403"
"307.11600","25.59309","0.00374"
"307.45800","25.62161","0.00385"
"307.80000","25.65013","0.00401"
"308.14200","25.67865","0.00435"
"308.48400","25.70705","0.00392"
"308.82600","25.73563","0.00387"
"309.16800","25.76415","0.00378"
"309.51000","25.79261","0.00372"
"309.85200","25.82113","0.00373"
"310.19400","25.84958","0.00400"
"310.53600","25.87817","0.00373"
"310.87800","25.90668","0.00387"
"311.22000","25.93508","0.00332"
"311.56200","25.96373","0.00293"
"311.90400","25.99219","0.00284"
"312.24600","26.02058","0.00324"
"312.58800","26.04917","0.00370"
"312.93000","26.07763","0.00361"
"313.27200","26.10608","0.00345"
"313.61400","26.13461","0.00377"
"313.95600","26.16306","0.00387"
"314.29800","26.19164","0.00384"
"314.64000","26.22016","0.00399"
"314.98200","26.24862","0.00386"
"315.32400","26.27714","0.00409"
"315.66600","26.30566","0.00372"
"316.00800","26.33412","0.00383"
"316.35000","26.36264","0.00418"
"316.69200","26.39110","0.00401"
"317.03400","26.41962","0.00439"
"317.37600","26.44814","0.00384"
"317.71800","26.47666","0.00415"
"318.06000","26.50512","0.00431"
"318.40200","26.53364","0.00461"
"318.74400","26.56210","0.00408"
"319.08600","26.59062","0.00420"
"319.42800","26.61920","0.00428"
"319.77000","26.64760","0.00450"
"320.11200","26.67618","0.00414"
"320.45400","26.70464","0.00472"
"320.79600","26.73310","0.00466"
"321.13800","26.76167","0.00482"
"321.48000","26.79008","0.00424"
"321.82200","26.81860","0.00474"
"322.16400","26.84718","0.00488"
"322.50600","26.87558","0.00472"
"322.84800","26.90415","0.00508"
"323.19000","26.93268","0.00483"
"323.53200","26.96113","0.00473"
"323.87400","26.98965","0.00533"
"324.21600","27.01811","0.00453"
"324.55800","27.04663","0.00488"
"324.90000","27.07515","0.00467"
"325.24200","27.10361","0.00507"
"325.58400","27.13213","0.00507"
"325.92600","27.16065","0.00522"
"326.26800","27.18905","0.00515"
"326.61000","27.21763","0.00504"
"326.95200","27.24615","0.00537"
"327.29400","27.27461","0.00550"
"327.63600","27.30313","0.00539"
"327.97800","27.33165","0.00528"
"328.32000","27.36011","0.00574"
"328.66200","27.38869","0.00565"
"329.00400","27.41709","0.00558"
"329.34600","27.44567","0.00607"
"329.68800","27.47419","0.00542"
"330.03000","27.50259","0.00570"
"330.37200","27.53117","0.00595"
"330.71400","27.55963","0.00591"
"331.05600","27.58815","0.00586"
"331.39800","27.61667","0.00617"
"331.74000","27.64513","0.00618"
"332.08200","27.67371","0.00616"
"332.42400","27.70211","0.00579"
"332.76600","27.73057","0.00587"
"333.10800","27.75915","0.00606"
"333.45000","27.78766","0.00654"
"333.79200","27.81612","0.00560"
"334.13400","27.84464","0.00591"
"334.47600","27.87310","0.00614"
"334.81800","27.90162","0.00559"
"335.16000","27.93020","0.00557"
"335.50200","27.95860","0.00582"
"335.84400","27.98712","0.00627"
"336.18600","28.01564","0.00588"
"336.52800","28.04416","0.00574"
"336.87000","28.07262","0.00573"
"337.21200","28.10120","0.00526"
"337.55400","28.12960","0.00439"
"337.89600","28.15818","0.00276"
"338.23800","28.18664","0.00326"
"338.58000","28.21510","0.00299"
"338.92200","28.24362","0.00290"
"339.26400","28.27214","0.00318"
"339.60600","28.30066","0.00287"
"339.94800","28.32918","0.00313"
"340.29000","28.35758","0.00296"
"340.63200","28.38616","0.00348"
"340.97400","28.41462","0.00335"
"341.31600","28.44308","0.00330"
"341.65800","28.47166","0.00324"
"342.00000","28.50012","0.00334"
"342.34200","28.52857","0.00282"
"342.68400","28.55716","0.00269"
"343.02600","28.58562","0.00329"
"343.36800","28.61413","0.00290"
"343.71000","28.64266","0.00328"
"344.05200","28.67105","0.00342"
"344.39400","28.69963","0.00319"
"344.73600","28.72815","0.00358"
"345.07800","28.75656","0.00357"
"345.42000","28.78519","0.00371"
"345.76200","28.81365","0.00342"
"346.10400","28.84211","0.00345"
"346.44600","28.87069","0.00374"
"346.78800","28.89909","0.00399"
"347.13000","28.92767","0.00380"
"347.47200","28.95613","0.00389"
"347.81400","28.98453","0.00407"
"348.15600","29.01317","0.00339"
"348.49800","29.04163","0.00371"
"348.84000","29.07009","0.00320"
"349.18200","29.09867","0.00351"
"349.52400","29.12713","0.00390"
"349.86600","29.15565","0.00370"
"350.20800","29.18411","0.00365"
"350.55000","29.21263","0.00332"
"350.89200","29.24115","0.00359"
"351.23400","29.26967","0.00387"
"351.57600","29.29813","0.00357"
"351.91800","29.32659","0.00364"
"352.26000","29.35511","0.00361"
"352.60200","29.38363","0.00331"
"352.94400","29.41215","0.00366"
"353.28600","29.44067","0.00344"
"353.62800","29.46913","0.00346"
"353.97000","29.49758","0.00328"
"354.31200","29.52617","0.00333"
"354.65400","29.55463","0.00333"
"354.99600","29.58320","0.00309"
"355.33800","29.61154","0.00355"
"355.68000","29.64012","0.00339"
"356.02200","29.66864","0.00322"
"356.36400","29.69710","0.00372"
"356.70600","29.72568","0.00370"
"357.04800","29.75414","0.00354"
"357.39000","29.78260","0.00372"
"357.73200","29.81118","0.00355"
"358.07400","29.83964","0.00385"
"358.41600","29.86816","0.00382"
"358.75800","29.89668","0.00399"
"359.10000","29.92508","0.00368"
"359.44200","29.95360","0.00395"
"359.78400","29.98212","0.00366"
"360.12600","30.01064","0.00338"
"360.46800","30.03916","0.00378"
"360.81000","30.06762","0.00415"
"361.15200","30.09614","0.00369"
"361.49400","30.12466","0.00357"
"361.83600","30.15306","0.00390"
"362.17800","30.18164","0.00460"
"362.52000","30.21022","0.00405"
"362.86200","30.23856","0.00438"
"363.20400","30.26720","0.00438"
"363.54600","30.29565","0.00422"
"363.88800","30.32411","0.00447"
"364.23000","30.35264","0.00428"
"364.57200","30.38109","0.00434"
"364.91400","30.40961","0.00431"
"365.25600","30.43814","0.00459"
"365.59800","30.46660","0.00487"
"365.94000","30.49517","0.00500"
"366.28200","30.52363","0.00482"
"366.62400","30.55209","0.00462"
"366.96600","30.58067","0.00481"
"367.30800","30.60913","0.00492"
"367.65000","30.63765","0.00507"
"367.99200","30.66617","0.00534"
"368.33400","30.69463","0.00504"
"368.67600","30.72315","0.00537"
"369.01800","30.75167","0.00267"
"369.36000","30.78007","0.00263"
"369.70200","30.80859","0.00245"
"370.04400","30.83711","0.00253"
"370.38600","30.86563","0.00261"
"370.72800","30.89415","0.00283"
"371.07000","30.92267","0.00243"
"371.41200","30.95107","0.00267"
"371.75400","30.97965","0.00234"
"372.09600","31.00817","0.00227"
"372.43800","31.03663","0.00264"
"372.78000","31.06515","0.00231"
"373.12200","31.09361","0.00218"
"373.46400","31.12213","0.00205"
"373.80600","31.15065","0.00229"
"374.14800","31.17911","0.00246"
"374.49000","31.20762","0.00229"
"374.83200","31.23615","0.00223"
"375.17400","31.26466","0.00252"
"375.51600","31.29312","0.00234"
"375.85800","31.32164","0.00246"
"376.20000","31.35010","0.00230"
"376.54200","31.37868","0.00280"
"376.88400","31.40708","0.00260"
"377.22600","31.43560","0.00267"
"377.56800","31.46418","0.00226"
"377.91000","31.49258","0.00246"
"378.25200","31.52116","0.00207"
"378.59400","31.54962","0.00223"
"378.93600","31.57808","0.00235"
"379.27800","31.60666","0.00230"
"379.62000","31.63518","0.00223"
"379.96200","31.66364","0.00257"
"380.30400","31.69216","0.00269"
"380.64600","31.72056","0.00263"
"380.98800","31.74914","0.00249"
"381.33000","31.77766","0.00251"
"381.67200","31.80606","0.00250"
"382.01400","31.83470","0.00229"
"382.35600","31.86310","0.00258"
"382.69800","31.89162","0.00269"
"383.04000","31.92014","0.00261"
"383.38200","31.94860","0.00240"
"383.72400","31.97718","0.00247"
"384.06600","32.00563","0.00232"
"384.40800","32.03403","0.00260"
"384.75000","32.06261","0.00243"
"385.09200","32.09113","0.00259"
"385.43400","32.11959","0.00258"
"385.77600","32.14812","0.00257"
"386.11800","32.17663","0.00255"
"386.46000","32.20515","0.00240"
"386.80200","32.23367","0.00269"
"387.14400","32.26213","0.00273"
"387.48600","32.29065","0.00231"
"387.82800","32.31911","0.00259"
"388.17000","32.34757","0.00242"
"388.51200","32.37615","0.00242"
"388.85400","32.40461","0.00265"
"389.19600","32.43313","0.00297"
"389.53800","32.46165","0.00281"
"389.88000","32.49011","0.00262"
"390.22200","32.51863","0.00222"
"390.56400","32.54715","0.00253"
"390.90600","32.57561","0.00299"
"391.24800","32.60413","0.00267"
"391.59000","32.63265","0.00246"
"391.93200","32.66111","0.00270"
"392.27400","32.68969","0.00240"
"392.61600","32.71809","0.00270"
"392.95800","32.74655","0.00260"
"393.30000","32.77513","0.00246"
"393.64200","32.80365","0.00229"
"393.98400","32.83210","0.00231"
"394.32600","32.86063","0.00263"
"394.66800","32.88909","0.00241"
"395.01000","32.91760","0.00262"
"395.35200","32.94619","0.00209"
"395.69400","32.97464","0.00207"
"396.03600","33.00316","0.00193"
"396.37800","33.03168","0.00228"
"396.72000","33.06009","0.00234"
"397.06200","33.08866","0.00222"
"397.40400","33.11712","0.00197"
"397.74600","33.14558","0.00247"
"398.08800","33.17416","0.00255"
"398.43000","33.20256","0.00244"
"398.77200","33.23114","0.00215"
"399.11400","33.25966","0.00233"
"399.45600","33.28806","0.00224"
"399.79800","33.31664","0.00192"
"400.14000","33.34516","0.00199"
"400.48200","33.37362","0.00192"
"400.82400","33.40220","0.00265"
"401.16600","33.43060","0.00240"
"401.50800","33.45912","0.00235"
"401.85000","33.48764","0.00220"
"402.19200","33.51610","0.00267"
"402.53400","33.54468","0.00217"
"402.87600","33.57314","0.00233"
"403.21800","33.60160","0.00215"
"403.56000","33.63012","0.00251"
"403.90200","33.65864","0.00250"
"404.24400","33.68716","0.00216"
"404.58600","33.71562","0.00209"
"404.92800","33.74413","0.00232"
"405.27000","33.77259","0.00224"
"405.61200","33.80112","0.00204"
"405.95400","33.82963","0.00224"
"406.29600","33.85815","0.00222"
"406.63800","33.88667","0.00237"
"406.98000","33.91507","0.00230"
"407.32200","33.94365","0.00249"
"407.66400","33.97218","0.00176"
"408.00600","34.00057","0.00231"
"408.34800","34.02915","0.00231"
"408.69000","34.05767","0.00222"
"409.03200","34.08613","0.00219"
"409.37400","34.11465","0.00209"
"409.71600","34.14311","0.00205"
"410.05800","34.17163","0.00235"
"410.40000","34.20015","0.00204"
"410.74200","34.22861","0.00248"
"411.08400","34.25713","0.00220"
"411.42600","34.28565","0.00210"
"411.76800","34.31417","0.00230"
"412.11000","34.34263","0.00196"
"412.45200","34.37109","0.00228"
"412.79400","34.39961","0.00215"
"413.13600","34.42813","0.00200"
"413.47800","34.45659","0.00192"
"413.82000","34.48517","0.00249"
"414.16200","34.51369","0.00237"
"414.50400","34.54209","0.00202"
"414.84600","34.57067","0.00228"
"415.18800","34.59912","0.00233"
"415.53000","34.62765","0.00263"
"415.87200","34.65617","0.00221"
"416.21400","34.68462","0.00236"
"416.55600","34.71315","0.00228"
"416.89800","34.74166","0.00224"
"417.24000","34.77007","0.00255"
"417.58200","34.79865","0.00181"
"417.92400","34.82710","0.00219"
"418.26600","34.85562","0.00225"
"418.60800","34.88420","0.00231"
"418.95000","34.91260","0.00251"
"419.29200","34.94118","0.00204"
"419.63400","34.96964","0.00197"
"419.97600","34.99810","0.00198"
"420.31800","35.02668","0.00224"
"420.66000","35.05514","0.00242"
"421.00200","35.08360","0.00199"
"421.34400","35.11212","0.00221"
"421.68600","35.14064","0.00230"
"422.02800","35.16910","0.00207"
"422.37000","35.19768","0.00196"
"422.71200","35.22614","0.00206"
"423.05400","35.25460","0.00173"
"423.39600","35.28312","0.00181"
"423.73800","35.31164","0.00203"
"424.08000","35.34016","0.00196"
"424.42200","35.36868","0.00201"
"424.76400","35.39714","0.00168"
"425.10600","35.42566","0.00186"
"425.44800","35.45412","0.00232"
"425.79000","35.48264","0.00203"
"426.13200","35.51115","0.00206"
"426.47400","35.53962","0.00194"
"426.81600","35.56808","0.00237"
"427.15800","35.59660","0.00229"
"427.50000","35.62518","0.00200"
"427.84200","35.65364","0.00192"
"428.18400","35.68215","0.00193"
"428.52600","35.71056","0.00188"
"428.86800","35.73919","0.00217"
"429.21000","35.76771","0.00195"
"429.55200","35.79605","0.00251"
"429.89400","35.82463","0.00164"
"430.23600","35.85315","0.00184"
"430.57800","35.88161","0.00176"
"430.92000","35.91013","0.00183"
"431.26200","35.93859","0.00180"
"431.60400","35.96705","0.00207"
"431.94600","35.99569","0.00181"
"432.28800","36.02409","0.00211"
"432.63000","36.05261","0.00215"
"432.97200","36.08119","0.00202"
"433.31400","36.10959","0.00215"
"433.65600","36.13817","0.00187"
"433.99800","36.16663","0.00172"
"434.34000","36.19509","0.00210"
"434.68200","36.22367","0.00198"
"435.02400","36.25207","0.00195"
"435.36600","36.28065","0.00210"
"435.70800","36.30911","0.00188"
"436.05000","36.33757","0.00165"
"436.39200","36.36609","0.00163"
"436.73400","36.39467","0.00185"
"437.07600","36.42313","0.00178"
"437.41800","36.45171","0.00223"
"437.76000","36.48011","0.00179"
"438.10200","36.50863","0.00200"
"438.44400","36.53714","0.00167"
"438.78600","36.56561","0.00214"
"439.12800","36.59418","0.00200"
"439.47000","36.62264","0.00173"
"439.81200","36.65110","0.00166"
"440.15400","36.67968","0.00202"
"440.49600","36.70814","0.00202"
"440.83800","36.73660","0.00214"
"441.18000","36.76512","0.00179"
"441.52200","36.79364","0.00185"
"441.86400","36.82216","0.00187"
"442.20600","36.85068","0.00188"
"442.54800","36.87914","0.00160"
"442.89000","36.90760","0.00188"
"443.23200","36.93618","0.00192"
"443.57400","36.96458","0.00173"
"443.91600","36.99322","0.00189"
"444.25800","37.02162","0.00198"
"444.60000","37.05008","0.00222"
"444.94200","37.07866","0.00188"
"445.28400","37.10718","0.00197"
"445.62600","37.13564","0.00185"
"445.96800","37.16410","0.00173"
"446.31000","37.19262","0.00176"
"446.65200","37.22114","0.00190"
"446.99400","37.24972","0.00214"
"447.33600","37.27811","0.00210"
"447.67800","37.30664","0.00183"
"448.02000","37.33516","0.00216"
"448.36200","37.36356","0.00180"
"448.70400","37.39214","0.00181"
"449.04600","37.42059","0.00193"
"449.38800","37.44917","0.00190"
"449.73000","37.47770","0.00215"
"450.07200","37.50603","0.00222"
"450.41400","37.53461","0.00238"
"450.75600","37.56319","0.00221"
"451.09800","37.59153","0.00218"
"451.44000","37.62017","0.00217"
"451.78200","37.64863","0.00192"
"452.12400","37.67709","0.00207"
"452.46600","37.70567","0.00226"
"452.80800","37.73413","0.00249"
"453.15000","37.76259","0.00234"
"453.49200","37.79117","0.00246"
"453.83400","37.81951","0.00223"
"454.17600","37.84815","0.00235"
"454.51800","37.87667","0.00261"
"454.86000","37.90507","0.00240"
"455.20200","37.93365","0.00263"
"455.54400","37.96211","0.00266"
"455.88600","37.99063","0.00224"
"456.22800","38.01915","0.00252"
"456.57000","38.04761","0.00252"
"456.91200","38.07613","0.00218"
"457.25400","38.10464","0.00249"
"457.59600","38.13311","0.00273"
"457.93800","38.16169","0.00264"
"458.28000","38.19014","0.00292"
"458.62200","38.21861","0.00314"
"458.96400","38.24713","0.00303"
"459.30600","38.27564","0.00308"
"459.64800","38.30410","0.00326"
"459.99000","38.33263","0.00291"
"460.33200","38.36115","0.00310"
"460.67400","38.38966","0.00287"
"461.01600","38.41812","0.00299"
"461.35800","38.44658","0.00333"
"461.70000","38.47511","0.00300"
"462.04200","38.50362","0.00298"
"462.38400","38.53208","0.00354"
"462.72600","38.56060","0.00290"
"463.06800","38.58918","0.00301"
"463.41000","38.61764","0.00287"
"463.75200","38.64610","0.00314"
"464.09400","38.67462","0.00291"
"464.43600","38.70314","0.00310"
"464.77800","38.73166","0.00291"
"465.12000","38.76006","0.00296"
"465.46200","38.78864","0.00322"
"465.80400","38.81722","0.00317"
"466.14600","38.84556","0.00314"
"466.48800","38.87414","0.00295"
"466.83000","38.90266","0.00276"
"467.17200","38.93112","0.00316"
"467.51400","38.95970","0.00314"
"467.85600","38.98816","0.00299"
"468.19800","39.01662","0.00311"
"468.54000","39.04514","0.00316"
"468.88200","39.07360","0.00306"
"469.22400","39.10217","0.00315"
"469.56600","39.13063","0.00267"
"469.90800","39.15910","0.00282"
"470.25000","39.18767","0.00301"
"470.59200","39.21613","0.00287"
"470.93400","39.24459","0.00295"
"471.27600","39.27317","0.00317"
"471.61800","39.30157","0.00321"
"471.96000","39.33015","0.00290"
"472.30200","39.35867","0.00284"
"472.64400","39.38713","0.00292"
"472.98600","39.41565","0.00346"
"473.32800","39.44411","0.00276"
"473.67000","39.47263","0.00297"
"474.01200","39.50115","0.00309"
"474.35400","39.52961","0.00302"
"474.69600","39.55813","0.00277"
"475.03800","39.58665","0.00300"
"475.38000","39.61505","0.00303"
"475.72200","39.64368","0.00315"
"476.06400","39.67221","0.00282"
"476.40600","39.70061","0.00310"
"476.74800","39.72913","0.00274"
"477.09000","39.75764","-0.05321"
"477.43200","39.78610","-0.00032"
"477.77400","39.81469","0.06081"
"478.11600","39.84308","0.14883"
"478.45800","39.87167","0.03046"
"478.80000","39.90013","0.12066"
"479.14200","39.92865","0.36168"
"479.48400","39.95716","0.31528"
"479.82600","39.98563","0.31281"
"480.16800","40.01408","-0.00197"
"480.51000","40.04266","0.41352"
"480.85200","40.07118","0.96736"
"481.19400","40.09958","0.08897"
"481.53600","40.12811","-0.25693"
"481.87800","40.15662","-0.07140"
"482.22000","40.18514","-0.20569"
"482.56200","40.21366","-0.26588"
"482.90400","40.24212","-0.26835"
"483.24600","40.27058","0.04512"
"483.58800","40.29922","-0.22268"
"483.93000","40.32756","-0.26767"
"484.27200","40.35614","-0.26369"
"484.61400","40.38466","-0.24976"
"484.95600","40.41312","-0.17402"
"485.29800","40.44170","-0.11416"
"485.64000","40.47010","-0.02565"
"485.98200","40.49862","-0.00141"
"486.32400","40.52714","0.00166"
"486.66600","40.55560","0.00145"
"487.00800","40.58412","0.00076"
"487.35000","40.61263","-0.00171"
"487.69200","40.64104","0.00349"
"488.03400","40.66968","0.00062"
"488.37600","40.69813","0.00114"
"488.71800","40.72659","0.00088"
"489.06000","40.75518","0.00109"
"489.40200","40.78364","0.00013"
"489.74400","40.81216","0.00102"
"490.08600","40.84068","0.00111"
"490.42800","40.86908","0.00070"
"490.77000","40.89766","0.00073"
"491.11200","40.92617","0.00093"
"491.45400","40.95457","0.00123"
"491.79600","40.98315","0.00107"
"492.13800","41.01161","0.00130"
"492.48000","41.04013","0.00068"
"492.82200","41.06865","0.00107"
"493.16400","41.09711","0.00058"
"493.50600","41.12563","0.00101"
"493.84800","41.15415","0.00085"
"494.19000","41.18255","0.00075"
"494.53200","41.21113","0.00083"
"494.87400","41.23959","0.00111"
"495.21600","41.26811","0.00055"
"495.55800","41.29669","0.00079"
"495.90000","41.32515","0.00130"
"496.24200","41.35361","0.00102"
"496.58400","41.38219","0.00093"
"496.92600","41.41059","0.00085"
"497.26800","41.43911","0.00100"
"497.61000","41.46762","0.00059"
"497.95200","41.49615","0.00099"
"498.29400","41.52460","0.00120"
"498.63600","41.55312","0.00112"
"498.97800","41.58158","0.00092"
"499.32000","41.61016","0.00085"
"499.66200","41.63869","0.00088"
"500.00400","41.66709","0.00106"
"500.34600","41.69561","0.00101"
"500.68800","41.72412","0.00085"
"501.03000","41.75265","0.00106"
"501.37200","41.78117","0.00099"
"501.71400","41.80957","0.00096"
"502.05600","41.83814","0.00091"
"502.39800","41.86666","0.00071"
"502.74000","41.89507","0.00135"
"503.08200","41.92364","0.00087"
"503.42400","41.95216","0.00129"
"503.76600","41.98056","0.00086"
"504.10800","42.00914","0.00121"
"504.45000","42.03760","0.00096"
"504.79200","42.06612","0.00142"
"505.13400","42.09470","0.00129"
"505.47600","42.12310","0.00146"
"505.81800","42.15162","0.00111"
"506.16000","42.18014","0.00087"
"506.50200","42.20860","0.00090"
"506.81600","42.23479","0.00114"