File: Force_trajectories/161221_2/Specimen_RawData_1.csv
End date,"12/21/2016"
Specimen label,"24T_89"
Maximum Load,"0.18898",N

Time,Extension,Load
(s),(mm),(N)
"0.00000","0.00000","0.00015"
"0.36600","0.03061","0.00000"
"0.73200","0.06122","0.00039"
"1.09800","0.09178","0.00003"
"1.46400","0.12227","0.00025"
"1.83000","0.15270","-0.00010"
"2.19600","0.18325","0.00014"
"2.56200","0.21381","-0.00004"
"2.92800","0.24412","0.00030"
"3.29400","0.27479","0.00018"
"3.66000","0.30529","0.00023"
"4.02600","0.33566","0.00034"
"4.39200","0.36621","0.00033"
"4.75800","0.39676","0.00035"
"5.12400","0.42720","0.00062"
"5.49000","0.45769","0.00048"
"5.85600","0.48824","0.00040"
"6.22200","0.51867","0.00053"
"6.58800","0.54923","0.00024"
"6.95400","0.57972","0.00055"
"7.32000","0.61027","0.00032"
"7.68600","0.64070","0.00054"
"8.05200","0.67126","0.00038"
"8.41800","0.70175","0.00039"
"8.78400","0.73218","0.00043"
"9.15000","0.76279","0.00051"
"9.51600","0.79323","0.00063"
"9.88200","0.82366","0.00046"
"10.24800","0.85427","0.00052"
"10.61400","0.88477","0.00075"
"10.98000","0.91514","0.00058"
"11.34600","0.94575","0.00024"
"11.71200","0.97624","0.00079"
"12.07800","1.00668","0.00096"
"12.44400","1.03723","0.00077"
"12.81000","1.06772","0.00058"
"13.17600","1.09821","0.00078"
"13.54200","1.12877","0.00051"
"13.90800","1.15926","0.00066"
"14.27400","1.18969","0.00071"
"14.64000","1.22030","0.00046"
"15.00600","1.25074","0.00099"
"15.37200","1.28123","0.00059"
"15.73800","1.31172","0.00110"
"16.10400","1.34216","0.00063"
"16.47000","1.37271","0.00071"
"16.83600","1.40326","0.00071"
"17.20200","1.43369","0.00061"
"17.56800","1.46425","0.00046"
"17.93400","1.49474","0.00070"
"18.30000","1.52523","0.00057"
"18.66600","1.55572","0.00065"
"19.03200","1.58616","0.00092"
"19.39800","1.61671","0.00077"
"19.76400","1.64726","0.00098"
"20.13000","1.67769","0.00080"
"20.49600","1.70825","0.00097"
"20.86200","1.73874","0.00079"
"21.22800","1.76917","0.00092"
"21.59400","1.79967","0.00099"
"21.96000","1.83028","0.00085"
"22.32600","1.86065","0.00105"
"22.69200","1.89126","0.00096"
"23.05800","1.92176","0.00087"
"23.42400","1.95219","0.00113"
"23.79000","1.98274","0.00084"
"24.15600","2.01317","0.00133"
"24.52200","2.04367","0.00131"
"24.88800","2.07428","0.00137"
"25.25400","2.10471","0.00113"
"25.62000","2.13520","0.00133"
"25.98600","2.16570","0.00099"
"26.35200","2.19619","0.00096"
"26.71800","2.22674","0.00110"
"27.08400","2.25717","0.00109"
"27.45000","2.28779","0.00118"
"27.81600","2.31828","0.00128"
"28.18200","2.34865","0.00137"
"28.54800","2.37926","0.00131"
"28.91400","2.40970","0.00108"
"29.28000","2.44019","0.00103"
"29.64600","2.47074","0.00047"
"30.01200","2.50124","0.00128"
"30.37800","2.53167","0.00135"
"30.74400","2.56222","0.00125"
"31.11000","2.59277","0.00124"
"31.47600","2.62321","0.00121"
"31.84200","2.65376","0.00148"
"32.20800","2.68425","0.00137"
"32.57400","2.71468","0.00129"
"32.94000","2.74524","0.00138"
"33.30600","2.77573","0.00124"
"33.67200","2.80622","0.00142"
"34.03800","2.83671","0.00132"
"34.40400","2.86721","0.00148"
"34.77000","2.89776","0.00151"
"35.13600","2.92825","0.00139"
"35.50200","2.95874","0.00139"
"35.86800","2.98924","0.00115"
"36.23400","3.01967","0.00128"
"36.60000","3.05022","0.00158"
"36.96600","3.08072","0.00105"
"37.33200","3.11115","0.00145"
"37.69800","3.14176","0.00164"
"38.06400","3.17225","0.00116"
"38.43000","3.20269","0.00137"
"38.79600","3.23324","0.00131"
"39.16200","3.26379","0.00121"
"39.52800","3.29416","0.00155"
"39.89400","3.32478","0.00172"
"40.26000","3.35527","0.00155"
"40.62600","3.38570","0.00185"
"40.99200","3.41625","0.00136"
"41.35800","3.44675","0.00175"
"41.72400","3.47718","0.00192"
"42.09000","3.50773","0.00204"
"42.45600","3.53829","0.00177"
"42.82200","3.56872","0.00195"
"43.18800","3.59921","0.00159"
"43.55400","3.62970","0.00162"
"43.92000","3.66026","0.00187"
"44.28600","3.69069","0.00165"
"44.65200","3.72124","0.00156"
"45.01800","3.75173","0.00191"
"45.38400","3.78217","0.00187"
"45.75000","3.81278","0.00208"
"46.11600","3.84327","0.00222"
"46.48200","3.87370","0.00189"
"46.84800","3.90426","0.00196"
"47.21400","3.93481","0.00198"
"47.58000","3.96512","0.00170"
"47.94600","3.99573","0.00193"
"48.31200","4.02623","0.00204"
"48.67800","4.05672","0.00175"
"49.04400","4.08721","0.00206"
"49.41000","4.11776","0.00212"
"49.77600","4.14820","0.00199"
"50.14200","4.17869","0.00244"
"50.50800","4.20930","0.00195"
"50.87400","4.23968","0.00227"
"51.24000","4.27029","0.00235"
"51.60600","4.30072","0.00217"
"51.97200","4.33121","0.00209"
"52.33800","4.36171","0.00242"
"52.70400","4.39226","0.00212"
"53.07000","4.42275","0.00249"
"53.43600","4.45318","0.00232"
"53.80200","4.48380","0.00229"
"54.16800","4.51423","0.00246"
"54.53400","4.54466","0.00236"
"54.90000","4.57521","0.00259"
"55.26600","4.60577","0.00262"
"55.63200","4.63620","0.00235"
"55.99800","4.66669","0.00218"
"56.36400","4.69725","0.00220"
"56.73000","4.72768","0.00242"
"57.09600","4.75823","0.00227"
"57.46200","4.78872","0.00233"
"57.82800","4.81922","0.00236"
"58.19400","4.84971","0.00239"
"58.56000","4.88026","0.00256"
"58.92600","4.91069","0.00271"
"59.29200","4.94125","0.00216"
"59.65800","4.97174","0.00267"
"60.02400","5.00217","0.00241"
"60.39000","5.03272","0.00245"
"60.75600","5.06328","0.00276"
"61.12200","5.09371","0.00227"
"61.48800","5.12420","0.00275"
"61.85400","5.15481","0.00231"
"62.22000","5.18525","0.00266"
"62.58600","5.21568","0.00261"
"62.95200","5.24623","0.00265"
"63.31800","5.27673","0.00300"
"63.68400","5.30722","0.00283"
"64.05000","5.33771","0.00270"
"64.41600","5.36826","0.00297"
"64.78200","5.39864","0.00274"
"65.14800","5.42925","0.00297"
"65.51400","5.45974","0.00309"
"65.88000","5.49023","0.00279"
"66.24600","5.52073","0.00203"
"66.61200","5.55122","0.00206"
"66.97800","5.58165","0.00233"
"67.34400","5.61220","0.00222"
"67.71000","5.64276","0.00246"
"68.07600","5.67319","0.00215"
"68.44200","5.70374","0.00237"
"68.80800","5.73423","0.00167"
"69.17400","5.76467","0.00202"
"69.54000","5.79516","0.00142"
"69.90600","5.82571","0.00144"
"70.27200","5.85621","0.00196"
"70.63800","5.88676","0.00200"
"71.00400","5.91725","0.00197"
"71.37000","5.94768","0.00230"
"71.73600","5.97824","0.00202"
"72.10200","6.00873","0.00227"
"72.46800","6.03928","0.00191"
"72.83400","6.06965","0.00248"
"73.20000","6.10027","0.00207"
"73.56600","6.13070","0.00218"
"73.93200","6.16119","0.00233"
"74.29800","6.19174","0.00220"
"74.66400","6.22224","0.00227"
"75.03000","6.25273","0.00210"
"75.39600","6.28322","0.00230"
"75.76200","6.31377","0.00239"
"76.12800","6.34421","0.00217"
"76.49400","6.37476","0.00286"
"76.86000","6.40519","0.00258"
"77.22600","6.43569","0.00275"
"77.59200","6.46618","0.00266"
"77.95800","6.49673","0.00292"
"78.32400","6.52722","0.00302"
"78.69000","6.55772","0.00274"
"79.05600","6.58827","0.00293"
"79.42200","6.61870","0.00307"
"79.78800","6.64919","0.00301"
"80.15400","6.67975","0.00294"
"80.52000","6.71024","0.00307"
"80.88600","6.74067","0.00340"
"81.25200","6.77122","0.00302"
"81.61800","6.80172","0.00314"
"81.98400","6.83221","0.00335"
"82.35000","6.86276","0.00326"
"82.71600","6.89325","0.00390"
"83.08200","6.92369","0.00349"
"83.44800","6.95424","0.00360"
"83.81400","6.98473","0.00361"
"84.18000","7.01517","0.00372"
"84.54600","7.04572","0.00408"
"84.91200","7.07627","0.00339"
"85.27800","7.10670","0.00284"
"85.64400","7.13726","0.00314"
"86.01000","7.16775","0.00303"
"86.37600","7.19824","0.00304"
"86.74200","7.22873","0.00328"
"87.10800","7.25923","0.00313"
"87.47400","7.28972","0.00355"
"87.84000","7.32015","0.00359"
"88.20600","7.35071","0.00383"
"88.57200","7.38120","0.00388"
"88.93800","7.41169","0.00354"
"89.30400","7.44224","0.00398"
"89.67000","7.47273","0.00357"
"90.03600","7.50323","0.00401"
"90.40200","7.53378","0.00393"
"90.76800","7.56421","0.00395"
"91.13400","7.59465","0.00386"
"91.50000","7.62526","0.00382"
"91.86600","7.65575","0.00417"
"92.23200","7.68618","0.00408"
"92.59800","7.71674","0.00439"
"92.96400","7.74723","0.00410"
"93.33000","7.77766","0.00469"
"93.69600","7.80827","0.00475"
"94.06200","7.83871","0.00478"
"94.42800","7.86920","0.00465"
"94.79400","7.89969","0.00487"
"95.16000","7.93024","0.00474"
"95.52600","7.96074","0.00549"
"95.89200","7.99123","0.00500"
"96.25800","8.02172","0.00562"
"96.62400","8.05221","0.00518"
"96.99000","8.08271","0.00382"
"97.35600","8.11326","0.00407"
"97.72200","8.14375","0.00419"
"98.08800","8.17419","0.00398"
"98.45400","8.20480","0.00450"
"98.82000","8.23523","0.00447"
"99.18600","8.26566","0.00445"
"99.55200","8.29628","0.00449"
"99.91800","8.32677","0.00484"
"100.28400","8.35726","0.00463"
"100.65000","8.38769","0.00471"
"101.01600","8.41825","0.00476"
"101.38200","8.44862","0.00549"
"101.74800","8.47929","0.00532"
"102.11400","8.50978","0.00527"
"102.48000","8.54022","0.00556"
"102.84600","8.57071","0.00561"
"103.21200","8.60126","0.00594"
"103.57800","8.63169","0.00569"
"103.94400","8.66219","0.00603"
"104.31000","8.69280","0.00600"
"104.67600","8.72323","0.00635"
"105.04200","8.75373","0.00669"
"105.40800","8.78422","0.00692"
"105.77400","8.81471","0.00669"
"106.14000","8.84520","0.00655"
"106.50600","8.87582","0.00673"
"106.87200","8.90625","0.00664"
"107.23800","8.93674","0.00699"
"107.60400","8.96729","0.00708"
"107.97000","8.99773","0.00720"
"108.33600","9.02822","0.00717"
"108.70200","9.05877","0.00725"
"109.06800","9.08920","0.00736"
"109.43400","9.11970","0.00790"
"109.80000","9.15025","0.00742"
"110.16600","9.18074","0.00799"
"110.53200","9.21117","0.00816"
"110.89800","9.24173","0.00782"
"111.26400","9.27222","0.00826"
"111.63000","9.30271","0.00861"
"111.99600","9.33321","0.00904"
"112.36200","9.36376","0.00913"
"112.72800","9.39419","0.00869"
"113.09400","9.42474","0.00968"
"113.46000","9.45524","0.00941"
"113.82600","9.48573","0.00957"
"114.19200","9.51622","0.00833"
"114.55800","9.54677","0.00910"
"114.92400","9.57727","0.00881"
"115.29000","9.60770","0.00943"
"115.65600","9.63831","0.00851"
"116.02200","9.66869","0.00856"
"116.38800","9.69924","0.00893"
"116.75400","9.72973","0.00977"
"117.12000","9.76022","0.00990"
"117.48600","9.79072","0.01048"
"117.85200","9.82127","0.01037"
"118.21800","9.85170","0.01075"
"118.58400","9.88213","0.01109"
"118.95000","9.91281","0.01210"
"119.31600","9.94324","0.01127"
"119.68200","9.97373","0.01132"
"120.04800","10.00422","0.01217"
"120.41400","10.03478","0.01276"
"120.78000","10.06515","0.01334"
"121.14600","10.09576","0.01413"
"121.51200","10.12625","0.01347"
"121.87800","10.15669","0.01432"
"122.24400","10.18730","0.01423"
"122.61000","10.21773","0.01497"
"122.97600","10.24823","0.01479"
"123.34200","10.27872","0.01503"
"123.70800","10.30927","0.01581"
"124.07400","10.33970","0.01667"
"124.44000","10.37025","0.01761"
"124.80600","10.40075","0.01808"
"125.17200","10.43118","0.01853"
"125.53800","10.46173","0.01831"
"125.90400","10.49229","0.01930"
"126.27000","10.52272","0.01949"
"126.63600","10.55315","0.02063"
"127.00200","10.58376","0.02144"
"127.36800","10.61426","0.02204"
"127.73400","10.64469","0.02240"
"128.10000","10.67524","0.02287"
"128.46600","10.70573","0.02339"
"128.83200","10.73623","0.02421"
"129.19800","10.76672","0.02501"
"129.56400","10.79727","0.02545"
"129.93000","10.82771","0.02565"
"130.29600","10.85826","0.02489"
"130.66200","10.88875","0.02466"
"131.02800","10.91918","0.02591"
"131.39400","10.94974","0.02672"
"131.76000","10.98023","0.02711"
"132.12600","11.01072","0.02798"
"132.49200","11.04121","0.02871"
"132.85800","11.07177","0.02950"
"133.22400","11.10226","0.03044"
"133.59000","11.13269","0.03108"
"133.95600","11.16324","0.03188"
"134.32200","11.19374","0.03270"
"134.68800","11.22423","0.03419"
"135.05400","11.25478","0.03465"
"135.42000","11.28521","0.03564"
"135.78600","11.31565","0.03652"
"136.15200","11.34626","0.03680"
"136.51800","11.37675","0.03774"
"136.88400","11.40724","0.03919"
"137.25000","11.43774","0.03946"
"137.61600","11.46829","0.04014"
"137.98200","11.49866","0.04062"
"138.34800","11.52922","0.04177"
"138.71400","11.55977","0.04279"
"139.08000","11.59020","0.04366"
"139.44600","11.62075","0.04487"
"139.81200","11.65125","0.04571"
"140.17800","11.68174","0.04706"
"140.54400","11.71223","0.04768"
"140.91000","11.74272","0.04871"
"141.27600","11.77322","0.04969"
"141.64200","11.80371","0.05120"
"142.00800","11.83420","0.05202"
"142.37400","11.86469","0.05245"
"142.74000","11.89519","0.05375"
"143.10600","11.92574","0.05431"
"143.47200","11.95623","0.05456"
"143.83800","11.98667","0.05570"
"144.20400","12.01728","0.05761"
"144.57000","12.04771","0.05923"
"144.93600","12.07820","0.06291"
"145.30200","12.10870","0.06431"
"145.66800","12.13925","0.06620"
"146.03400","12.16968","0.06815"
"146.40000","12.20023","0.07015"
"146.76600","12.23073","0.07140"
"147.13200","12.26116","0.07237"
"147.49800","12.29177","0.07323"
"147.86400","12.32220","0.07434"
"148.23000","12.35270","0.07470"
"148.59600","12.38319","0.07642"
"148.96200","12.41374","0.07731"
"149.32800","12.44417","0.07845"
"149.69400","12.47473","0.07927"
"150.06000","12.50522","0.08053"
"150.42600","12.53571","0.08209"
"150.79200","12.56621","0.08323"
"151.15800","12.59670","0.08413"
"151.52400","12.62725","0.08502"
"151.89000","12.65768","0.08545"
"152.25600","12.68830","0.07778"
"152.62200","12.71873","0.07987"
"152.98800","12.74916","0.08198"
"153.35400","12.77971","0.08310"
"153.72000","12.81021","0.08484"
"154.08600","12.84070","0.08636"
"154.45200","12.87131","0.08785"
"154.81800","12.90180","0.08964"
"155.18400","12.93212","0.09215"
"155.55000","12.96273","0.09340"
"155.91600","12.99322","0.09449"
"156.28200","13.02372","0.09598"
"156.64800","13.05421","0.09705"
"157.01400","13.08476","0.09860"
"157.38000","13.11519","0.10000"
"157.74600","13.14574","0.09999"
"158.11200","13.17630","0.10174"
"158.47800","13.20667","0.10336"
"158.84400","13.23728","0.10495"
"159.21000","13.26772","0.10727"
"159.57600","13.29815","0.10971"
"159.94200","13.32870","0.11167"
"160.30800","13.35925","0.11446"
"160.67400","13.38969","0.11674"
"161.04000","13.42018","0.11891"
"161.40600","13.45073","0.11971"
"161.77200","13.48123","0.12271"
"162.13800","13.51172","0.12470"
"162.50400","13.54221","0.12617"
"162.87000","13.57276","0.12783"
"163.23600","13.60320","0.12917"
"163.60200","13.63375","0.13155"
"163.96800","13.66424","0.13352"
"164.33400","13.69473","0.13620"
"164.70000","13.72523","0.13867"
"165.06600","13.75578","0.14094"
"165.43200","13.78621","0.14324"
"165.79800","13.81676","0.14469"
"166.16400","13.84726","0.14666"
"166.53000","13.87763","0.14810"
"166.89600","13.90824","0.15007"
"167.26200","13.93873","0.15203"
"167.62800","13.96923","0.15413"
"167.99400","13.99972","0.15731"
"168.36000","14.03021","0.15956"
"168.72600","14.06070","0.16221"
"169.09200","14.09126","0.16719"
"169.45800","14.12175","0.17117"
"169.82400","14.15224","0.17511"
"170.19000","14.18273","0.17830"
"170.55600","14.21323","0.18082"
"170.92200","14.24372","0.18261"
"171.28800","14.27421","0.18509"
"171.65400","14.30477","0.18706"
"172.02000","14.33526","0.18881"
"172.38600","14.36569","0.16221"
"172.75200","14.39624","0.16115"
"173.11800","14.42674","0.01425"
"173.48400","14.45723","0.01483"
"173.85000","14.48772","0.01186"
"174.21600","14.51828","0.00939"
"174.58200","14.54865","0.01575"
"174.94800","14.57926","0.01089"
"175.31400","14.60975","0.01398"
"175.68000","14.64019","0.01673"
"176.04600","14.67080","0.01149"
"176.41200","14.70123","0.01610"
"176.77800","14.73172","0.01574"
"177.14400","14.76222","0.01785"
"177.51000","14.79271","0.02115"
"177.87600","14.82314","0.01881"
"178.24200","14.85375","0.01974"
"178.60800","14.88425","0.02386"
"178.97400","14.91474","0.02278"
"179.34000","14.94523","0.02274"
"179.70600","14.97572","0.02504"
"180.07200","15.00628","0.02689"
"180.43800","15.03671","0.02718"
"180.80400","15.06726","0.02829"
"181.17000","15.09769","0.02926"
"181.53600","15.12825","0.03037"
"181.90200","15.15874","0.03162"
"182.26800","15.18923","0.03245"
"182.63400","15.21967","0.03321"
"183.00000","15.25028","0.03484"
"183.36600","15.28077","0.03672"
"183.73200","15.31114","0.03699"
"184.09800","15.34176","0.03708"
"184.46400","15.37225","0.03863"
"184.83000","15.40268","0.03987"
"185.19600","15.43323","0.03940"
"185.56200","15.46373","0.04029"
"185.92800","15.49416","0.04160"
"186.29400","15.52477","0.04267"
"186.66000","15.55526","0.04327"
"187.02600","15.58570","0.04442"
"187.39200","15.61625","0.04553"
"187.75800","15.64674","0.04723"
"188.12400","15.67729","0.04845"
"188.49000","15.70773","0.04939"
"188.85600","15.73828","0.05060"
"189.22200","15.76871","0.05118"
"189.58800","15.79914","0.05270"
"189.95400","15.82976","0.05429"
"190.32000","15.86025","0.05457"
"190.68600","15.89068","0.05438"
"191.05200","15.92124","0.05670"
"191.41800","15.95179","0.05915"
"191.78400","15.98210","0.06141"
"192.15000","16.01277","0.06350"
"192.51600","16.04326","0.06675"
"192.88200","16.07364","0.06914"
"193.24800","16.10425","0.07204"
"193.61400","16.13474","0.07340"
"193.98000","16.16518","0.07470"
"194.34600","16.19573","0.07596"
"194.71200","16.22628","0.07732"
"195.07800","16.25665","0.07750"
"195.44400","16.28721","0.07950"
"195.81000","16.31770","0.08158"
"196.17600","16.34819","0.08264"
"196.54200","16.37868","0.08445"
"196.90800","16.40924","0.08621"
"197.27400","16.43973","0.08783"
"197.64000","16.47028","0.08990"
"198.00600","16.50072","0.09223"
"198.37200","16.53121","0.09395"
"198.73800","16.56170","0.09575"
"199.10400","16.59225","0.09754"
"199.47000","16.62275","0.09915"
"199.83600","16.65318","0.10098"
"200.20200","16.68367","0.10268"
"200.56800","16.71422","0.10496"
"200.93400","16.74466","0.10764"
"201.30000","16.77527","0.10977"
"201.66600","16.80576","0.11322"
"202.03200","16.83619","0.11466"
"202.39800","16.86669","0.11747"
"202.76400","16.89724","0.12025"
"203.13000","16.92767","0.12300"
"203.49600","16.95823","0.12535"
"203.86200","16.98872","0.12677"
"204.22800","17.01921","0.12864"
"204.59400","17.04970","0.12977"
"204.96000","17.08019","0.13248"
"205.32600","17.11075","0.13504"
"205.69200","17.14124","0.13785"
"206.05800","17.17179","0.14012"
"206.42400","17.20217","0.12716"
"206.79000","17.23272","0.12893"
"207.15600","17.26321","0.13088"
"207.52200","17.29376","0.13160"
"207.88800","17.32420","0.13332"
"208.25400","17.35475","0.13608"
"208.62000","17.38530","0.13790"
"208.98600","17.41562","0.13921"
"209.35200","17.44629","0.14189"
"209.71800","17.47678","0.14454"
"210.08400","17.50715","0.14689"
"210.45000","17.53777","0.14853"
"210.81600","17.56826","0.14477"
"211.18200","17.59869","0.14670"
"211.54800","17.62924","0.12712"
"211.91400","17.65979","0.12938"
"212.28000","17.69017","0.13157"
"212.64600","17.72078","0.13204"
"213.01200","17.75115","0.13427"
"213.37800","17.78171","0.11035"
"213.74400","17.81226","0.11391"
"214.11000","17.84275","0.11084"
"214.47600","17.87318","0.11363"
"214.84200","17.90374","0.11706"
"215.20800","17.93423","0.11844"
"215.57400","17.96472","0.12075"
"215.94000","17.99521","0.10157"
"216.30600","18.02571","0.10323"
"216.67200","18.05632","0.10456"
"217.03800","18.08663","0.10602"
"217.40400","18.11724","0.10858"
"217.77000","18.14774","0.11021"
"218.13600","18.17817","0.11473"
"218.50200","18.20872","0.11750"
"218.86800","18.23927","0.11884"
"219.23400","18.26971","0.08137"
"219.60000","18.30020","0.08344"
"219.96600","18.33075","0.08427"
"220.33200","18.36113","0.04651"
"220.69800","18.39174","0.04835"
"221.06400","18.42217","0.04979"
"221.43000","18.45272","0.05083"
"221.79600","18.48322","0.05264"
"222.16200","18.51371","0.05496"
"222.52800","18.54420","0.05832"
"222.89400","18.57469","0.06098"
"223.26000","18.60525","0.06256"
"223.62600","18.63568","0.06646"
"223.99200","18.66623","0.06748"
"224.35800","18.69673","0.01589"
"224.72400","18.72722","0.01657"
"225.09000","18.75765","0.01772"
"225.45600","18.78820","0.02186"
"225.82200","18.81870","0.02121"
"226.18800","18.84919","0.02057"
"226.55400","18.87974","0.02178"
"226.92000","18.91029","0.02366"
"227.28600","18.94073","0.02236"
"227.65200","18.97122","0.02431"
"228.01800","19.00177","0.02723"
"228.38400","19.03214","0.02766"
"228.75000","19.06276","0.02802"
"229.11600","19.09325","0.02969"
"229.48200","19.12368","0.03139"
"229.84800","19.15429","0.03220"
"230.21400","19.18467","0.03311"
"230.58000","19.21522","0.03388"
"230.94600","19.24571","0.03518"
"231.31200","19.27621","0.03633"
"231.67800","19.30670","0.03782"
"232.04400","19.33725","0.03918"
"232.41000","19.36768","0.04034"
"232.77600","19.39824","0.04165"
"233.14200","19.42867","0.04282"
"233.50800","19.45922","0.04378"
"233.87400","19.48977","0.04507"
"234.24000","19.52021","0.04662"
"234.60600","19.55076","0.04727"
"234.97200","19.58125","0.04879"
"235.33800","19.61168","0.04962"
"235.70400","19.64224","0.05114"
"236.07000","19.67279","0.05245"
"236.43600","19.70316","0.05403"
"236.80200","19.73372","0.05548"
"237.16800","19.76427","0.05715"
"237.53400","19.79470","0.05977"
"237.90000","19.82525","0.06068"
"238.26600","19.85574","0.06403"
"238.63200","19.88624","0.06574"
"238.99800","19.91673","0.06932"
"239.36400","19.94722","0.07092"
"239.73000","19.97772","0.07220"
"240.09600","20.00821","0.07396"
"240.46200","20.03870","0.07531"
"240.82800","20.06919","0.07585"
"241.19400","20.09968","0.07637"
"241.56000","20.13024","0.07852"
"241.92600","20.16073","0.07941"
"242.29200","20.19123","0.08098"
"242.65800","20.22178","0.08262"
"243.02400","20.25221","0.08425"
"243.39000","20.28270","0.08515"
"243.75600","20.31326","0.08673"
"244.12200","20.34369","0.08044"
"244.48800","20.37418","0.04544"
"244.85400","20.40473","0.04562"
"245.22000","20.43529","0.04665"
"245.58600","20.46566","0.04656"
"245.95200","20.49627","0.04738"
"246.31800","20.52676","0.05002"
"246.68400","20.55720","0.05166"
"247.05000","20.58775","0.05262"
"247.41600","20.61824","0.05364"
"247.78200","20.64867","0.05596"
"248.14800","20.67923","0.03471"
"248.51400","20.70978","0.03663"
"248.88000","20.74021","0.03661"
"249.24600","20.77076","0.03694"
"249.61200","20.80120","0.03893"
"249.97800","20.83175","0.03897"
"250.34400","20.86218","0.03725"
"250.71000","20.89273","0.03799"
"251.07600","20.92323","0.03990"
"251.44200","20.95372","0.04173"
"251.80800","20.98427","0.04311"
"252.17400","21.01471","0.04488"
"252.54000","21.04520","0.04643"
"252.90600","21.07569","0.04836"
"253.27200","21.10624","0.04966"
"253.63800","21.13667","0.05085"
"254.00400","21.16729","0.05293"
"254.37000","21.19772","0.05453"
"254.73600","21.22821","0.04855"
"255.10200","21.25877","0.03106"
"255.46800","21.28926","0.03434"
"255.83400","21.31969","0.03696"
"256.20000","21.35024","0.03945"
"256.56600","21.38080","0.04093"
"256.93200","21.41117","0.04230"
"257.29800","21.44172","0.04440"
"257.66400","21.47222","0.04646"
"258.03000","21.50271","0.03303"
"258.39600","21.53320","0.03611"
"258.76200","21.56369","0.03672"
"259.12800","21.59425","0.03864"
"259.49400","21.62468","0.04099"
"259.86000","21.65523","0.04205"
"260.22600","21.68572","0.04309"
"260.59200","21.71622","0.04491"
"260.95800","21.74677","0.04640"
"261.32400","21.77726","0.02606"
"261.69000","21.80769","0.02067"
"262.05600","21.83825","0.01903"
"262.42200","21.86874","0.02034"
"262.78800","21.89923","0.02190"
"263.15400","21.92978","0.02319"
"263.52000","21.96022","0.02432"
"263.88600","21.99071","0.02508"
"264.25200","22.02120","0.02555"
"264.61800","22.05176","0.02678"
"264.98400","22.08213","0.02809"
"265.35000","22.11274","0.02801"
"265.71600","22.14329","0.02859"
"266.08200","22.17373","0.02954"
"266.44800","22.20428","0.03084"
"266.81400","22.23471","0.02997"
"267.18000","22.26520","0.02695"
"267.54600","22.29570","0.02672"
"267.91200","22.32625","0.01175"
"268.27800","22.35674","0.01338"
"268.64400","22.38723","0.01497"
"269.01000","22.41773","0.01536"
"269.37600","22.44822","0.01688"
"269.74200","22.47871","0.01871"
"270.10800","22.50927","0.02046"
"270.47400","22.53976","0.02237"
"270.84000","22.57019","0.02194"
"271.20600","22.60074","0.02369"
"271.57200","22.63118","0.02462"
"271.93800","22.66167","0.02536"
"272.30400","22.69222","0.02573"
"272.67000","22.72271","0.02644"
"273.03600","22.75321","0.02758"
"273.40200","22.78376","0.02882"
"273.76800","22.81425","0.02988"
"274.13400","22.84468","0.02962"
"274.50000","22.87530","0.03009"
"274.86600","22.90573","0.03103"
"275.23200","22.93622","0.03228"
"275.59800","22.96671","0.03188"
"275.96400","22.99727","0.03325"
"276.33000","23.02770","0.03466"
"276.69600","23.05819","0.03658"
"277.06200","23.08875","0.03652"
"277.42800","23.11924","0.03813"
"277.79400","23.14967","0.03967"
"278.16000","23.18022","0.04119"
"278.52600","23.21078","0.04265"
"278.89200","23.24121","0.04363"
"279.25800","23.27176","0.04481"
"279.62400","23.30219","0.04647"
"279.99000","23.33269","0.04823"
"280.35600","23.36330","0.04929"
"280.72200","23.39373","0.05073"
"281.08800","23.42422","0.05163"
"281.45400","23.45477","0.05307"
"281.82000","23.48521","0.05464"
"282.18600","23.51564","0.05655"
"282.55200","23.54626","0.05926"
"282.91800","23.57675","0.06188"
"283.28400","23.60718","0.06472"
"283.65000","23.63773","0.06606"
"284.01600","23.66822","0.06805"
"284.38200","23.69866","0.06966"
"284.74800","23.72915","0.07153"
"285.11400","23.75976","0.07271"
"285.48000","23.79020","0.07438"
"285.84600","23.82075","0.07602"
"286.21200","23.85124","0.07711"
"286.57800","23.88173","0.07898"
"286.94400","23.91223","0.07983"
"287.31000","23.94278","0.08134"
"287.67600","23.97327","0.08265"
"288.04200","24.00370","0.08414"
"288.40800","24.03426","0.08598"
"288.77400","24.06469","0.08749"
"289.14000","24.09518","0.08812"
"289.50600","24.12573","0.09094"
"289.87200","24.15623","0.09297"
"290.23800","24.18666","0.09413"
"290.60400","24.21721","0.09608"
"290.97000","24.24771","0.09760"
"291.33600","24.27820","0.09904"
"291.70200","24.30875","0.10001"
"292.06800","24.33924","0.10117"
"292.43400","24.36968","0.10282"
"292.80000","24.40017","0.01879"
"293.16600","24.43078","0.01455"
"293.53200","24.46115","0.01987"
"293.89800","24.49176","0.01780"
"294.26400","24.52226","0.01805"
"294.63000","24.55269","0.01848"
"294.99600","24.58324","0.02036"
"295.36200","24.61374","0.02315"
"295.72800","24.64423","0.02282"
"296.09400","24.67472","0.02325"
"296.46000","24.70528","0.02603"
"296.82600","24.73571","0.02612"
"297.19200","24.76614","0.02976"
"297.55800","24.79675","0.02820"
"297.92400","24.82719","0.03143"
"298.29000","24.85774","0.03052"
"298.65600","24.88829","0.03397"
"299.02200","24.91872","0.03329"
"299.38800","24.94916","0.03353"
"299.75400","24.97977","0.03486"
"300.12000","25.01020","0.03505"
"300.48600","25.04069","0.03868"
"300.85200","25.07118","0.03719"
"301.21800","25.10174","0.03854"
"301.58400","25.13217","0.03839"
"301.95000","25.16273","0.03980"
"302.31600","25.19328","0.04197"
"302.68200","25.22365","0.04093"
"303.04800","25.25426","0.04242"
"303.41400","25.28470","0.04266"
"303.78000","25.31519","0.04385"
"304.14600","25.34574","0.04551"
"304.51200","25.37623","0.04464"
"304.87800","25.40672","0.04578"
"305.24400","25.43722","0.04667"
"305.61000","25.46777","0.04761"
"305.97600","25.49820","0.04866"
"306.34200","25.52870","0.04877"
"306.70800","25.55931","0.04918"
"307.07400","25.58974","0.05075"
"307.44000","25.62024","0.05115"
"307.80600","25.65073","0.05118"
"308.17200","25.68122","0.05189"
"308.53800","25.71171","0.05257"
"308.90400","25.74220","0.05284"
"309.27000","25.77276","0.04429"
"309.63600","25.80319","0.03411"
"310.00200","25.83368","0.03454"
"310.36800","25.86423","0.03539"
"310.73400","25.89467","0.03636"
"311.10000","25.92522","0.03507"
"311.46600","25.95572","0.03565"
"311.83200","25.98621","0.03495"
"312.19800","26.01670","0.03587"
"312.56400","26.04725","0.03699"
"312.93000","26.07774","0.03732"
"313.29600","26.10818","0.03807"
"313.66200","26.13879","0.03844"
"314.02800","26.16916","0.03937"
"314.39400","26.19971","0.04000"
"314.76000","26.23021","0.04002"
"315.12600","26.26076","0.04034"
"315.49200","26.29125","0.04073"
"315.85800","26.32174","0.04135"
"316.22400","26.35224","0.04180"
"316.59000","26.38267","0.04202"
"316.95600","26.41328","0.04265"
"317.32200","26.44378","0.04314"
"317.68800","26.47421","0.04372"
"318.05400","26.50470","0.04390"
"318.42000","26.53531","0.04420"
"318.78600","26.56569","0.04470"
"319.15200","26.59618","0.04567"
"319.51800","26.62673","0.04549"
"319.88400","26.65722","0.04583"
"320.25000","26.68777","0.04638"
"320.61600","26.71821","0.04669"
"320.98200","26.74870","0.04759"
"321.34800","26.77919","0.04746"
"321.71400","26.80981","0.04798"
"322.08000","26.84018","0.04779"
"322.44600","26.87073","0.04840"
"322.81200","26.90122","0.04889"
"323.17800","26.93172","0.04833"
"323.54400","26.96221","0.04880"
"323.91000","26.99276","0.04957"
"324.27600","27.02326","0.04999"
"324.64200","27.05369","0.05009"
"325.00800","27.08424","0.05085"
"325.37400","27.11473","0.05138"
"325.74000","27.14523","0.05170"
"326.10600","27.17572","0.05281"
"326.47200","27.20627","0.05253"
"326.83800","27.23670","0.05379"
"327.20400","27.26720","0.05434"
"327.57000","27.29775","0.05485"
"327.93600","27.32818","0.05622"
"328.30200","27.35879","0.05593"
"328.66800","27.38923","0.05782"
"329.03400","27.41972","0.05731"
"329.40000","27.45021","0.00067"
"329.76600","27.48077","-0.00075"
"330.13200","27.51120","0.00668"
"330.49800","27.54175","-0.00011"
"330.86400","27.57224","-0.00033"
"331.23000","27.60273","0.00324"
"331.59600","27.63323","0.00014"
"331.96200","27.66378","0.00028"
"332.32800","27.69421","0.00142"
"332.69400","27.72471","0.00033"
"333.06000","27.75526","0.00209"
"333.42600","27.78569","0.00066"
"333.79200","27.81618","0.00002"
"334.15800","27.84674","0.00426"
"334.52400","27.87723","0.00049"
"334.89000","27.90772","0.00186"
"335.25600","27.93827","0.00239"
"335.62200","27.96877","0.00110"
"335.98800","27.99914","0.00464"
"336.35400","28.02975","0.00186"
"336.72000","28.06019","0.00316"
"337.08600","28.09068","0.00333"
"337.45200","28.12123","0.00240"
"337.81800","28.15172","0.00497"
"338.18400","28.18221","0.00288"
"338.55000","28.21271","0.00513"
"338.91600","28.24326","0.00448"
"339.28200","28.27363","0.00499"
"339.64800","28.30424","0.00481"
"340.01400","28.33474","0.00375"
"340.38000","28.36517","0.00598"
"340.74600","28.39573","0.00501"
"341.11200","28.42628","0.00651"
"341.47800","28.45671","0.00582"
"341.84400","28.48714","0.00698"
"342.21000","28.51775","0.00719"
"342.57600","28.54825","0.00726"
"342.94200","28.57874","0.00781"
"343.30800","28.60923","0.00793"
"343.67400","28.63972","0.00886"
"344.04000","28.67022","0.00823"
"344.40600","28.70077","0.00973"
"344.77200","28.73126","0.00926"
"345.13800","28.76170","0.00967"
"345.50400","28.79225","0.00998"
"345.87000","28.82274","0.01113"
"346.23600","28.85317","0.01151"
"346.60200","28.88367","0.01207"
"346.96800","28.91428","0.01243"
"347.33400","28.94465","0.01269"
"347.70000","28.97526","0.01364"
"348.06600","29.00576","0.01381"
"348.43200","29.03619","0.01452"
"348.79800","29.06668","0.01223"
"349.16400","29.09723","0.01330"
"349.53000","29.12773","0.01289"
"349.89600","29.15822","0.01441"
"350.26200","29.18877","0.01387"
"350.62800","29.21920","0.01464"
"350.99400","29.24970","0.01522"
"351.36000","29.28019","0.01113"
"351.72600","29.31068","0.01081"
"352.09200","29.34124","0.00988"
"352.45800","29.37173","0.01084"
"352.82400","29.40222","0.00982"
"353.19000","29.43265","0.00948"
"353.55600","29.46326","0.01046"
"353.92200","29.49370","0.01100"
"354.28800","29.52425","0.01114"
"354.65400","29.55468","0.01113"
"355.02000","29.58524","0.01192"
"355.38600","29.61567","0.01230"
"355.75200","29.64622","0.01297"
"356.11800","29.67678","0.01008"
"356.48400","29.70715","0.01044"
"356.85000","29.73776","0.00956"
"357.21600","29.76819","0.01154"
"357.58200","29.79875","0.01119"
"357.94800","29.82918","0.01258"
"358.31400","29.85979","0.01244"
"358.68000","29.89017","0.01276"
"359.04600","29.92072","0.00806"
"359.41200","29.95127","0.00446"
"359.77800","29.98176","0.00321"
"360.14400","30.01225","0.00249"
"360.51000","30.04275","0.00132"
"360.87600","30.07318","0.00056"
"361.24200","30.10367","0.00059"
"361.60800","30.13423","0.00108"
"361.97400","30.16472","0.00020"
"362.34000","30.19521","0.00116"
"362.70600","30.22576","0.00081"
"363.07200","30.25626","0.00119"
"363.43800","30.28669","0.00073"
"363.80400","30.31724","0.00086"
"364.17000","30.34779","0.00091"
"364.53600","30.37817","0.00086"
"364.90200","30.40878","0.00144"
"365.26800","30.43921","0.00119"
"365.63400","30.46976","0.00095"
"366.00000","30.50020","0.00120"
"366.36600","30.53075","0.00120"
"366.73200","30.56118","0.00098"
"367.09800","30.59173","0.00126"
"367.46400","30.62222","0.00122"
"367.83000","30.65272","0.00127"
"368.19600","30.68321","0.00167"
"368.56200","30.71376","0.00138"
"368.92800","30.74420","0.00136"
"369.29400","30.77469","0.00106"
"369.66000","30.80524","0.00133"
"370.02600","30.83574","0.00136"
"370.39200","30.86617","0.00110"
"370.75800","30.89672","0.00109"
"371.12400","30.92721","0.00124"
"371.49000","30.95770","0.00148"
"371.85600","30.98826","0.00120"
"372.22200","31.01875","0.00160"
"372.58800","31.04912","0.00168"
"372.95400","31.07973","0.00146"
"373.32000","31.11023","0.00160"
"373.68600","31.14066","0.00149"
"374.05200","31.17122","0.00175"
"374.41800","31.20171","0.00196"
"374.78400","31.23220","0.00193"
"375.15000","31.26269","0.00212"
"375.51600","31.29330","0.00215"
"375.88200","31.32368","0.00221"
"376.24800","31.35423","0.00191"
"376.61400","31.38472","0.00174"
"376.98000","31.41521","0.00180"
"377.34600","31.44570","0.00159"
"377.71200","31.47626","0.00191"
"378.07800","31.50675","0.00200"
"378.44400","31.53724","0.00195"
"378.81000","31.56774","0.00240"
"379.17600","31.59823","0.00211"
"379.54200","31.62872","0.00195"
"379.90800","31.65928","0.00219"
"380.27400","31.68977","0.00202"
"380.64000","31.72020","0.00253"
"381.00600","31.75075","0.00207"
"381.37200","31.78124","0.00232"
"381.73800","31.81162","0.00201"
"382.10400","31.84229","0.00214"
"382.47000","31.87272","0.00239"
"382.83600","31.90322","0.00226"
"383.20200","31.93371","0.00266"
"383.56800","31.96420","0.00200"
"383.93400","31.99469","0.00151"
"384.30000","32.02525","0.00164"
"384.66600","32.05574","0.00127"
"385.03200","32.08617","0.00125"
"385.39800","32.11673","0.00111"
"385.76400","32.14722","0.00131"
"386.13000","32.17777","0.00132"
"386.49600","32.20820","0.00099"
"386.86200","32.23875","0.00124"
"387.22800","32.26925","0.00158"
"387.59400","32.29968","0.00132"
"387.96000","32.33023","0.00123"
"388.32600","32.36073","0.00125"
"388.69200","32.39116","0.00104"
"389.05800","32.42177","0.00132"
"389.42400","32.45226","0.00128"
"389.79000","32.48264","0.00121"
"390.15600","32.51331","0.00107"
"390.52200","32.54374","0.00146"
"390.88800","32.57417","0.00147"
"391.25400","32.60473","0.00147"
"391.62000","32.63528","0.00168"
"391.98600","32.66565","0.00137"
"392.35200","32.69627","0.00117"
"392.71800","32.72676","0.00142"
"393.08400","32.75719","0.00141"
"393.45000","32.78774","0.00128"
"393.81600","32.81818","0.00139"
"394.18200","32.84873","0.00149"
"394.54800","32.87916","0.00131"
"394.91400","32.90971","0.00123"
"395.28000","32.94020","0.00099"
"395.64600","32.97076","0.00118"
"396.01200","33.00125","0.00136"
"396.37800","33.03168","0.00155"
"396.74400","33.06223","0.00106"
"397.11000","33.09279","0.00147"
"397.47600","33.12328","0.00129"
"397.84200","33.15365","0.00104"
"398.20800","33.18427","0.00183"
"398.57400","33.21470","0.00134"
"398.94000","33.24519","0.00133"
"399.30600","33.27575","0.00162"
"399.67200","33.30624","0.00152"
"400.03800","33.33673","0.00117"
"400.40400","33.36723","0.00153"
"400.77000","33.39777","0.00131"
"401.13600","33.42821","0.00193"
"401.50200","33.45876","0.00157"
"401.86800","33.48925","0.00154"
"402.23400","33.51968","0.00158"
"402.60000","33.55018","0.00159"
"402.96600","33.58073","0.00169"
"403.33200","33.61122","0.00167"
"403.69800","33.64172","0.00180"
"404.06400","33.67227","0.00189"
"404.43000","33.70270","0.00155"
"404.79600","33.73319","0.00181"
"405.16200","33.76375","0.00161"
"405.52800","33.79424","0.00159"
"405.89400","33.82461","0.00147"
"406.26000","33.85529","0.00187"
"406.62600","33.88572","0.00206"
"406.99200","33.91621","0.00168"
"407.35800","33.94676","0.00199"
"407.72400","33.97726","0.00219"
"408.09000","34.00769","0.00233"
"408.45600","34.03824","0.00221"
"408.82200","34.06873","0.00181"
"409.18800","34.09911","0.00209"
"409.55400","34.12978","0.00251"
"409.92000","34.16027","0.00222"
"410.28600","34.19070","0.00219"
"410.65200","34.22126","0.00235"
"411.01800","34.25169","0.00222"
"411.38400","34.28224","0.00224"
"411.75000","34.31273","0.00197"
"412.11600","34.34323","0.00232"
"412.48200","34.37372","0.00250"
"412.84800","34.40421","0.00275"
"413.21400","34.43471","0.00253"
"413.58000","34.46520","0.00172"
"413.94600","34.49569","-0.00007"
"414.31200","34.52625","-0.00036"
"414.67800","34.55679","-0.00020"
"415.04400","34.58717","-0.00031"
"415.41000","34.61778","-0.00023"
"415.77600","34.64821","-0.00033"
"416.14200","34.67870","0.00034"
"416.50800","34.70926","-0.00031"
"416.87400","34.73981","0.00015"
"417.24000","34.77018","-0.00002"
"417.60600","34.80074","0.00011"
"417.97200","34.83123","0.00017"
"418.33800","34.86166","-0.00018"
"418.70400","34.89228","-0.00023"
"419.07000","34.92271","-0.00036"
"419.43600","34.95320","0.00028"
"419.80200","34.98375","0.00016"
"420.16800","35.01419","-0.00001"
"420.53400","35.04468","0.00020"
"420.90000","35.07523","-0.00036"
"421.26600","35.10572","0.00005"
"421.63200","35.13615","-0.00026"
"421.99800","35.16671","0.00018"
"422.36400","35.19720","0.00021"
"422.73000","35.22775","-0.00049"
"423.09600","35.25819","0.00051"
"423.46200","35.28874","-0.00020"
"423.82800","35.31923","-0.00001"
"424.19400","35.34966","0.00002"
"424.56000","35.38028","0.00010"
"424.92600","35.41071","0.00002"
"425.29200","35.44120","-0.00035"
"425.65800","35.47176","0.00023"
"426.02400","35.50225","0.00023"
"426.39000","35.53262","0.00011"
"426.75600","35.56329","0.00028"
"427.12200","35.59373","0.00001"
"427.48800","35.62416","-0.00013"
"427.85400","35.65471","0.00001"
"428.22000","35.68520","0.00014"
"428.58600","35.71564","0.00032"
"428.95200","35.74625","-0.00027"
"429.31800","35.77674","-0.00005"
"429.68400","35.80717","0.00002"
"430.05000","35.83778","0.00014"
"430.41600","35.86822","0.00027"
"430.78200","35.89877","0.00039"
"431.14800","35.92914","0.00020"
"431.51400","35.95976","-0.00017"
"431.88000","35.99025","0.00032"
"432.24600","36.02068","0.00008"
"432.61200","36.05124","-0.00010"
"432.97800","36.08173","0.00007"
"433.34400","36.11222","0.00023"
"433.71000","36.14277","0.00015"
"434.07600","36.17326","-0.00002"
"434.44200","36.20370","-0.00021"
"434.80800","36.23425","0.00005"
"435.17400","36.26474","-0.00020"
"435.54000","36.29517","0.00001"
"435.90600","36.32573","0.00028"
"436.27200","36.35622","0.00021"
"436.63800","36.38671","0.00050"
"437.00400","36.41727","0.00015"
"437.37000","36.44776","0.00011"
"437.73600","36.47813","-0.00008"
"438.10200","36.50874","0.00057"
"438.46800","36.53918","-0.00017"
"438.83400","36.56973","0.00051"
"439.20000","36.60022","0.00057"
"439.56600","36.63071","0.00013"
"439.93200","36.66127","0.00026"
"440.29800","36.69170","0.00049"
"440.66400","36.72226","0.00035"
"441.03000","36.75275","-0.00015"
"441.39600","36.78318","0.00014"
"441.76200","36.81373","-0.00004"
"442.12800","36.84428","0.00003"
"442.49400","36.87466","0.00040"
"442.86000","36.90521","0.00018"
"443.22600","36.93570","0.00002"
"443.59200","36.96619","0.00024"
"443.95800","36.99675","-0.00001"
"444.32400","37.02724","0.00006"
"444.69000","37.05767","0.00037"
"445.05600","37.08823","0.00040"
"445.42200","37.11872","0.00001"
"445.78800","37.14915","0.00003"
"446.15400","37.17970","0.00043"
"446.52000","37.21025","0.00033"
"446.88600","37.24069","0.00009"
"447.25200","37.27124","0.00002"
"447.61800","37.30173","0.00000"
"447.98400","37.33216","0.00025"
"448.35000","37.36272","0.00030"
"448.71600","37.39321","0.00028"
"449.08200","37.42370","0.00037"
"449.44800","37.45425","0.00022"
"449.81400","37.48475","0.00013"
"450.18000","37.51524","0.00047"
"450.54600","37.54567","0.00004"
"450.91200","37.57629","0.00036"
"451.27800","37.60672","0.00001"
"451.64400","37.63715","-0.00005"
"452.01000","37.66771","0.00016"
"452.37600","37.69826","0.00037"
"452.74200","37.72869","0.00028"
"453.10800","37.75924","0.00026"
"453.47400","37.78974","0.00014"
"453.84000","37.82017","0.00020"
"454.20600","37.85072","0.00020"
"454.57200","37.88133","0.00043"
"454.93800","37.91165","0.00012"
"455.30400","37.94226","0.00023"
"455.67000","37.97269","0.00049"
"456.03600","38.00319","0.00024"
"456.40200","38.03373","0.00030"
"456.76800","38.06423","0.00051"
"457.13400","38.09472","0.00048"
"457.50000","38.12521","0.00061"
"457.86600","38.15577","0.00052"
"458.23200","38.18620","0.00056"
"458.59800","38.21669","0.00026"
"458.96400","38.24725","0.00023"
"459.33000","38.27774","0.00061"
"459.69600","38.30817","0.00058"
"460.06200","38.33873","0.00049"
"460.42800","38.36922","0.00024"
"460.79400","38.39965","0.00022"
"461.16000","38.43026","0.00050"
"461.52600","38.46075","0.00041"
"461.89200","38.49118","0.00017"
"462.25800","38.52174","0.00041"
"462.62400","38.55229","0.00029"
"462.99000","38.58260","0.00027"
"463.35600","38.61328","0.00043"
"463.72200","38.64371","0.00032"
"464.08800","38.67414","0.00024"
"464.45400","38.70469","0.00062"
"464.82000","38.73525","0.00064"
"465.18600","38.76568","0.00032"
"465.55200","38.79623","0.00041"
"465.91800","38.82679","0.00038"
"466.28400","38.85716","0.00059"
"466.65000","38.88777","0.00022"
"467.01600","38.91821","0.00047"
"467.38200","38.94876","0.00057"
"467.74800","38.97925","0.00044"
"468.11400","39.00974","0.00042"
"468.48000","39.04023","0.00051"
"468.84600","39.07072","0.00049"
"469.21200","39.10128","0.00070"
"469.57800","39.13171","0.00039"
"469.94400","39.16220","0.00051"
"470.31000","39.19270","0.00064"
"470.67600","39.22325","0.00046"
"471.04200","39.25362","0.00052"
"471.40800","39.28423","0.00059"
"471.77400","39.31472","0.00066"
"472.14000","39.34521","0.00059"
"472.50600","39.37577","0.00048"
"472.87200","39.40620","0.00064"
"473.23800","39.43670","0.00074"
"473.60400","39.46719","0.00051"
"473.97000","39.49780","0.00014"
"474.33600","39.52818","0.00089"
"474.70200","39.55873","0.00066"
"475.06800","39.58922","0.00043"
"475.43400","39.61971","0.00066"
"475.80000","39.65020","0.00100"
"476.16600","39.68070","0.00058"
"476.53200","39.71119","0.00075"
"476.89800","39.74174","0.00048"
"477.26400","39.77224","0.00067"
"477.63000","39.80267","0.00069"
"477.99600","39.83322","0.00074"
"478.36200","39.86372","0.00026"
"478.72800","39.89427","0.00038"
"479.09400","39.92470","0.00040"
"479.46000","39.95525","0.00022"
"479.82600","39.98574","0.00044"
"480.19200","40.01618","0.00016"
"480.55800","40.04673","0.00036"
"480.92400","40.07722","0.00054"
"481.29000","40.10765","0.00073"
"481.65600","40.13821","0.00100"
"482.02200","40.16876","0.00036"
"482.38800","40.19913","0.00027"
"482.75400","40.22969","0.00041"
"483.12000","40.26024","0.00049"
"483.48600","40.29067","0.00041"
"483.85200","40.32128","0.00050"
"484.21800","40.35172","0.00048"
"484.58400","40.38221","0.00054"
"484.95000","40.41270","0.00053"
"485.31600","40.44326","0.00056"
"485.68200","40.47369","0.00011"
"486.04800","40.50418","0.00038"
"486.41400","40.53474","0.00008"
"486.78000","40.56523","0.00066"
"487.14600","40.59572","0.00029"
"487.51200","40.62621","0.00006"
"487.87800","40.65676","0.00032"
"488.24400","40.68719","0.00071"
"488.61000","40.71774","0.00039"
"488.97600","40.74818","0.00080"
"489.34200","40.77867","0.00072"
"489.70800","40.80922","0.00029"
"490.07400","40.83978","0.00020"
"490.44000","40.87021","0.00035"
"490.80600","40.90070","0.00074"
"491.17200","40.93126","0.00105"
"491.53800","40.96169","0.00076"
"491.90400","40.99218","0.00016"
"492.27000","41.02273","0.00049"
"492.63600","41.05322","0.00074"
"493.00200","41.08372","0.00029"
"493.36800","41.11421","0.00046"
"493.73400","41.14471","0.00024"
"494.10000","41.17519","0.00014"
"494.46600","41.20581","0.00048"
"494.83200","41.23618","0.00026"
"495.19800","41.26674","0.00050"
"495.56400","41.29723","0.00075"
"495.93000","41.32772","0.00066"
"496.29600","41.35822","0.00083"
"496.66200","41.38876","0.00109"
"497.02800","41.41926","0.00092"
"497.39400","41.44969","0.00131"
"497.76000","41.48024","0.00162"
"498.12600","41.51074","0.00139"
"498.49200","41.54123","0.00145"
"498.85800","41.57172","0.00177"
"499.22400","41.60228","0.00161"
"499.59000","41.63265","0.00147"
"499.95600","41.66320","0.00163"
"500.32200","41.69370","0.00208"
"500.68800","41.72419","0.00176"
"501.05400","41.75473","0.00228"
"501.42000","41.78523","0.00237"
"501.78600","41.81572","0.00233"
"502.15200","41.84621","0.00258"
"502.51800","41.87677","0.00268"
"502.88400","41.90720","0.00280"
"503.25000","41.93775","0.00307"
"503.61600","41.96825","0.00301"
"503.98200","41.99868","0.00324"
"504.34800","42.02923","0.00340"
"504.71400","42.05972","0.00342"
"505.08000","42.09021","0.00375"
"505.44600","42.12070","0.00347"
"505.81200","42.15126","0.00390"
"506.17800","42.18169","0.00400"
"506.54400","42.21219","0.00434"
"506.91000","42.24268","0.00467"
"507.27600","42.27324","0.00428"
"507.64200","42.30367","0.00453"
"508.00800","42.33422","0.00508"
"508.37400","42.36477","0.00511"
"508.74000","42.39520","0.00524"
"509.10600","42.42575","0.00525"
"509.47200","42.45625","0.00612"
"509.83800","42.48674","0.00599"
"510.20400","42.51717","0.00611"
"510.57000","42.54773","0.00626"
"510.93600","42.57816","0.00613"
"511.30200","42.60877","0.00674"
"511.66800","42.63927","0.00717"
"512.03400","42.66970","0.00745"
"512.40000","42.70025","0.00757"
"512.76600","42.73074","0.00764"
"513.13200","42.76118","0.00794"
"513.49800","42.79173","0.00871"
"513.86400","42.82228","0.00838"
"514.23000","42.85271","0.00891"
"514.59600","42.88320","0.00960"
"514.96200","42.91376","0.00938"
"515.32800","42.94419","0.01004"
"515.69400","42.97474","0.01041"
"516.06000","43.00523","0.01042"
"516.42600","43.03573","0.01107"
"516.79200","43.06616","0.01156"
"517.15800","43.09671","0.01173"
"517.52400","43.12720","0.01197"
"517.89000","43.15770","0.01271"
"518.25600","43.18825","0.01296"
"518.62200","43.21875","0.01295"
"518.98800","43.24918","0.01344"
"519.35400","43.27973","0.01404"
"519.72000","43.31028","0.01453"
"520.08600","43.34066","0.01453"
"520.45200","43.37121","0.01481"
"520.81800","43.40176","0.01531"
"521.18400","43.43219","0.01538"
"521.55000","43.46268","0.01588"
"521.91600","43.49323","0.01658"
"522.28200","43.52367","0.01749"
"522.64800","43.55423","0.01729"
"523.01400","43.58471","0.01735"
"523.38000","43.61521","0.01828"
"523.74600","43.64570","0.01853"
"524.11200","43.67625","0.01929"
"524.47800","43.70675","0.01973"
"524.84400","43.73718","0.01997"
"525.21000","43.76773","0.01179"
"525.57600","43.79822","0.01483"
"525.94200","43.82866","0.01024"
"526.30800","43.85921","0.01400"
"526.67400","43.88976","0.01062"
"527.04000","43.92020","0.01327"
"527.40600","43.95068","0.01257"
"527.77200","43.98130","0.01401"
"528.13800","44.01167","0.01454"
"528.50400","44.04222","0.01444"
"528.87000","44.07278","0.01520"
"529.23600","44.10321","0.01418"
"529.60200","44.13376","0.01562"
"529.96800","44.16426","0.01519"
"530.33400","44.19469","0.01605"
"530.70000","44.22518","0.01569"
"531.06600","44.25580","0.01602"
"531.43200","44.28617","0.01618"
"531.79800","44.31672","0.01733"
"532.16400","44.34721","0.01689"
"532.53000","44.37771","0.01709"
"532.89600","44.40820","0.01775"
"533.26200","44.43875","0.01773"
"533.62800","44.46924","0.01825"
"533.99400","44.49973","0.01836"
"534.36000","44.53022","0.01900"
"534.72600","44.56072","0.01886"
"535.09200","44.59121","-0.00230"
"535.45800","44.62170","0.00007"
"535.82400","44.65226","-0.00075"
"536.19000","44.68263","-0.00089"
"536.55600","44.71325","-0.00041"
"536.92200","44.74379","-0.00056"
"537.28800","44.77417","-0.00041"
"537.65400","44.80472","-0.00106"
"538.02000","44.83521","-0.00076"
"538.38600","44.86570","-0.00068"
"538.75200","44.89620","-0.00046"
"539.11800","44.92675","-0.00094"
"539.48400","44.95718","-0.00032"
"539.85000","44.98768","-0.00029"
"540.21600","45.01823","-0.00052"
"540.58200","45.04873","-0.00065"
"540.94800","45.07922","-0.00025"
"541.31400","45.10977","-0.00070"
"541.68000","45.14020","-0.00052"
"542.04600","45.17075","-0.00040"
"542.07200","45.17285","-0.00068"