File: Force_trajectories/161218_2/Specimen_RawData_3.csv
End date,"12/18/2016"
Specimen label,"16DG_27"
Maximum Load,"0.05222",N

Time,Extension,Load
(s),(mm),(N)
"0.00000","0.00000","0.00033"
"0.28800","0.02338","0.00103"
"0.57600","0.04825","0.00226"
"0.86400","0.07223","0.00298"
"1.15200","0.09626","0.00412"
"1.44000","0.12024","0.00435"
"1.72800","0.14427","0.00501"
"2.01600","0.16819","0.00518"
"2.30400","0.19222","0.00576"
"2.59200","0.21620","0.00578"
"2.88000","0.24017","0.00645"
"3.16800","0.26415","0.00677"
"3.45600","0.28825","0.00667"
"3.74400","0.31216","0.00770"
"4.03200","0.33626","0.00762"
"4.32000","0.36023","0.00773"
"4.60800","0.38427","0.00808"
"4.89600","0.40824","0.00851"
"5.18400","0.43222","0.00832"
"5.47200","0.45619","0.00868"
"5.76000","0.48017","0.00872"
"6.04800","0.50421","0.00888"
"6.33600","0.52818","0.00947"
"6.62400","0.55228","0.00916"
"6.91200","0.57619","0.00993"
"7.20000","0.60023","0.00970"
"7.48800","0.62414","0.01030"
"7.77600","0.64818","0.01028"
"8.06400","0.67215","0.01051"
"8.35200","0.69625","0.01054"
"8.64000","0.72022","0.01093"
"8.92800","0.74426","0.01100"
"9.21600","0.76824","0.01125"
"9.50400","0.79227","0.01099"
"9.79200","0.81625","0.01115"
"10.08000","0.84022","0.01141"
"10.36800","0.86426","0.01137"
"10.65600","0.88817","0.01145"
"10.94400","0.91221","0.01214"
"11.23200","0.93618","0.01167"
"11.52000","0.96022","0.01224"
"11.80800","0.98420","0.01188"
"12.09600","1.00823","0.01237"
"12.38400","1.03221","0.01236"
"12.67200","1.05618","0.01249"
"12.96000","1.08016","0.01186"
"13.24800","1.10419","0.01261"
"13.53600","1.12823","0.01269"
"13.82400","1.15220","0.01281"
"14.11200","1.17624","0.01317"
"14.40000","1.20016","0.01306"
"14.68800","1.22425","0.01282"
"14.97600","1.24817","0.01315"
"15.26400","1.27220","0.01368"
"15.55200","1.29612","0.01291"
"15.84000","1.32021","0.01358"
"16.12800","1.34419","0.01329"
"16.41600","1.36822","0.01351"
"16.70400","1.39220","0.01381"
"16.99200","1.41623","0.01376"
"17.28000","1.44021","0.01322"
"17.56800","1.46425","0.01450"
"17.85600","1.48822","0.01443"
"18.14400","1.51220","0.01391"
"18.43200","1.53617","0.01383"
"18.72000","1.56015","0.01428"
"19.00800","1.58424","0.01407"
"19.29600","1.60822","0.01436"
"19.58400","1.63219","0.01455"
"19.87200","1.65617","0.01436"
"20.16000","1.68021","0.01451"
"20.44800","1.70418","0.01456"
"20.73600","1.72816","0.01495"
"21.02400","1.75219","0.01450"
"21.31200","1.77617","0.01503"
"21.60000","1.80014","0.01466"
"21.88800","1.82418","0.01445"
"22.17600","1.84821","0.01514"
"22.46400","1.87213","0.01484"
"22.75200","1.89623","0.01522"
"23.04000","1.92014","0.01528"
"23.32800","1.94418","0.01522"
"23.61600","1.96815","0.01505"
"23.90400","1.99225","0.01537"
"24.19200","2.01616","0.01539"
"24.48000","2.04026","0.01554"
"24.76800","2.06417","0.01575"
"25.05600","2.08821","0.01554"
"25.34400","2.11219","0.01554"
"25.63200","2.13622","0.01550"
"25.92000","2.16020","0.01607"
"26.20800","2.18417","0.01610"
"26.49600","2.20821","0.01629"
"26.78400","2.23212","0.01589"
"27.07200","2.25616","0.01606"
"27.36000","2.28013","0.01627"
"27.64800","2.30417","0.01587"
"27.93600","2.32814","0.01629"
"28.22400","2.35224","0.01617"
"28.51200","2.37622","0.01595"
"28.80000","2.40025","0.01600"
"29.08800","2.42417","0.01578"
"29.37600","2.44820","0.01628"
"29.66400","2.47218","0.01618"
"29.95200","2.49615","0.01627"
"30.24000","2.52019","0.01646"
"30.52800","2.54416","0.01650"
"30.81600","2.56820","0.01682"
"31.10400","2.59218","0.01704"
"31.39200","2.61615","0.01649"
"31.68000","2.64013","0.01633"
"31.96800","2.66422","0.01677"
"32.25600","2.68814","0.01680"
"32.54400","2.71223","0.01689"
"32.83200","2.73615","0.01684"
"33.12000","2.76018","0.01682"
"33.40800","2.78416","0.01707"
"33.69600","2.80814","0.01697"
"33.98400","2.83217","0.01702"
"34.27200","2.85615","0.01745"
"34.56000","2.88018","0.01736"
"34.84800","2.90416","0.01706"
"35.13600","2.92819","0.01713"
"35.42400","2.95217","0.01711"
"35.71200","2.97620","0.01729"
"36.00000","3.00012","0.01756"
"36.28800","3.02421","0.01743"
"36.57600","3.04813","0.01718"
"36.86400","3.07217","0.01745"
"37.15200","3.09620","0.01739"
"37.44000","3.12018","0.01804"
"37.72800","3.14415","0.01778"
"38.01600","3.16819","0.01789"
"38.30400","3.19216","0.01761"
"38.59200","3.21614","0.01757"
"38.88000","3.24017","0.01772"
"39.16800","3.26415","0.01773"
"39.45600","3.28819","0.01781"
"39.74400","3.31216","0.01769"
"40.03200","3.33620","0.01782"
"40.32000","3.36011","0.01801"
"40.60800","3.38421","0.01821"
"40.89600","3.40812","0.01789"
"41.18400","3.43222","0.01739"
"41.47200","3.45619","0.01799"
"41.76000","3.48017","0.01794"
"42.04800","3.50415","0.01752"
"42.33600","3.52818","0.01798"
"42.62400","3.55222","0.01800"
"42.91200","3.57619","0.01767"
"43.20000","3.60023","0.01789"
"43.48800","3.62420","0.01795"
"43.77600","3.64818","0.01818"
"44.06400","3.67209","0.01790"
"44.35200","3.69619","0.01816"
"44.64000","3.72016","0.01817"
"44.92800","3.74420","0.01809"
"45.21600","3.76818","0.01850"
"45.50400","3.79221","0.01869"
"45.79200","3.81619","0.01870"
"46.08000","3.84022","0.01841"
"46.36800","3.86426","0.01863"
"46.65600","3.88817","0.01856"
"46.94400","3.91227","0.01837"
"47.23200","3.93618","0.01880"
"47.52000","3.96022","0.01871"
"47.80800","3.98420","0.01836"
"48.09600","4.00823","0.01880"
"48.38400","4.03221","0.01856"
"48.67200","4.05624","0.01867"
"48.96000","4.08016","0.01887"
"49.24800","4.10419","0.01912"
"49.53600","4.12823","0.01897"
"49.82400","4.15226","0.01953"
"50.11200","4.17624","0.01912"
"50.40000","4.20021","0.01958"
"50.68800","4.22425","0.01942"
"50.97600","4.24823","0.01989"
"51.26400","4.27220","0.01898"
"51.55200","4.29612","0.01907"
"51.84000","4.32021","0.01905"
"52.12800","4.34419","0.01923"
"52.41600","4.36822","0.01911"
"52.70400","4.39214","0.01942"
"52.99200","4.41623","0.01912"
"53.28000","4.44015","0.01937"
"53.56800","4.46419","0.01947"
"53.85600","4.48822","0.01967"
"54.14400","4.51220","0.01956"
"54.43200","4.53623","0.01934"
"54.72000","4.56021","0.01997"
"55.00800","4.58424","0.01940"
"55.29600","4.60816","0.01996"
"55.58400","4.63225","0.01978"
"55.87200","4.65617","0.01942"
"56.16000","4.68026","0.01949"
"56.44800","4.70412","0.01975"
"56.73600","4.72816","0.01958"
"57.02400","4.75213","0.01985"
"57.31200","4.77623","0.02018"
"57.60000","4.80020","0.01956"
"57.88800","4.82424","0.02033"
"58.17600","4.84821","0.01979"
"58.46400","4.87225","0.02027"
"58.75200","4.89622","0.02000"
"59.04000","4.92014","0.02025"
"59.32800","4.94418","0.02046"
"59.61600","4.96815","0.02001"
"59.90400","4.99219","0.02074"
"60.19200","5.01616","0.02022"
"60.48000","5.04020","0.02051"
"60.76800","5.06417","0.02054"
"61.05600","5.08827","0.02068"
"61.34400","5.11218","0.02061"
"61.63200","5.13622","0.02020"
"61.92000","5.16020","0.02048"
"62.20800","5.18423","0.02044"
"62.49600","5.20821","0.02084"
"62.78400","5.23218","0.02073"
"63.07200","5.25622","0.02108"
"63.36000","5.28019","0.02060"
"63.64800","5.30423","0.02066"
"63.93600","5.32814","0.02048"
"64.22400","5.35218","0.02094"
"64.51200","5.37616","0.02081"
"64.80000","5.40025","0.02088"
"65.08800","5.42417","0.02151"
"65.37600","5.44826","0.02117"
"65.66400","5.47218","0.02118"
"65.95200","5.49615","0.02117"
"66.24000","5.52013","0.02136"
"66.52800","5.54416","0.02126"
"66.81600","5.56820","0.02123"
"67.10400","5.59218","0.02122"
"67.39200","5.61621","0.02171"
"67.68000","5.64019","0.02183"
"67.96800","5.66422","0.02129"
"68.25600","5.68820","0.02160"
"68.54400","5.71223","0.02159"
"68.83200","5.73615","0.02149"
"69.12000","5.76024","0.02208"
"69.40800","5.78410","0.02175"
"69.69600","5.80819","0.02163"
"69.98400","5.83217","0.02159"
"70.27200","5.85621","0.02155"
"70.56000","5.88018","0.02172"
"70.84800","5.90416","0.02191"
"71.13600","5.92819","0.02192"
"71.42400","5.95211","0.02222"
"71.71200","5.97620","0.02173"
"72.00000","6.00018","0.02145"
"72.28800","6.02421","0.02151"
"72.57600","6.04819","0.02170"
"72.86400","6.07223","0.02174"
"73.15200","6.09614","0.02147"
"73.44000","6.12024","0.02167"
"73.72800","6.14415","0.02187"
"74.01600","6.16819","0.02173"
"74.30400","6.19216","0.02197"
"74.59200","6.21614","0.02230"
"74.88000","6.24017","0.02210"
"75.16800","6.26415","0.02191"
"75.45600","6.28819","0.02206"
"75.74400","6.31216","0.02201"
"76.03200","6.33626","0.02194"
"76.32000","6.36011","0.02190"
"76.60800","6.38421","0.02183"
"76.89600","6.40812","0.02175"
"77.18400","6.43222","0.02188"
"77.47200","6.45613","0.02169"
"77.76000","6.48023","0.02203"
"78.04800","6.50415","0.02192"
"78.33600","6.52818","0.02192"
"78.62400","6.55216","0.02186"
"78.91200","6.57619","0.02201"
"79.20000","6.60017","0.02187"
"79.48800","6.62420","0.02223"
"79.77600","6.64818","0.02215"
"80.06400","6.67215","0.02211"
"80.35200","6.69619","0.02200"
"80.64000","6.72016","0.02201"
"80.92800","6.74414","0.02208"
"81.21600","6.76812","0.02198"
"81.50400","6.79221","0.02247"
"81.79200","6.81619","0.02162"
"82.08000","6.84022","0.02224"
"82.36800","6.86420","0.02224"
"82.65600","6.88817","0.02217"
"82.94400","6.91221","0.02195"
"83.23200","6.93618","0.02178"
"83.52000","6.96022","0.02196"
"83.80800","6.98420","0.02194"
"84.09600","7.00823","0.02172"
"84.38400","7.03215","0.02194"
"84.67200","7.05624","0.02208"
"84.96000","7.08016","0.02198"
"85.24800","7.10425","0.02214"
"85.53600","7.12817","0.02195"
"85.82400","7.15220","0.02223"
"86.11200","7.17618","0.02219"
"86.40000","7.20021","0.02200"
"86.68800","7.22419","0.02171"
"86.97600","7.24823","0.02157"
"87.26400","7.27220","0.02164"
"87.55200","7.29618","0.02147"
"87.84000","7.32021","0.02191"
"88.12800","7.34419","0.02163"
"88.41600","7.36822","0.02188"
"88.70400","7.39220","0.02179"
"88.99200","7.41623","0.02200"
"89.28000","7.44015","0.02166"
"89.56800","7.46425","0.02204"
"89.85600","7.48822","0.02187"
"90.14400","7.51220","0.02166"
"90.43200","7.53623","0.02196"
"90.72000","7.56027","0.02164"
"91.00800","7.58424","0.02186"
"91.29600","7.60822","0.02175"
"91.58400","7.63225","0.02202"
"91.87200","7.65617","0.02166"
"92.16000","7.68026","0.02168"
"92.44800","7.70412","0.02183"
"92.73600","7.72822","0.02198"
"93.02400","7.75213","0.02211"
"93.31200","7.77623","0.02162"
"93.60000","7.80020","0.02214"
"93.88800","7.82424","0.02173"
"94.17600","7.84821","0.02200"
"94.46400","7.87225","0.02177"
"94.75200","7.89622","0.02201"
"95.04000","7.92026","0.02146"
"95.32800","7.94418","0.02229"
"95.61600","7.96821","0.02173"
"95.90400","7.99225","0.02201"
"96.19200","8.01616","0.02194"
"96.48000","8.04020","0.02182"
"96.76800","8.06417","0.02204"
"97.05600","8.08821","0.02217"
"97.34400","8.11218","0.02172"
"97.63200","8.13622","0.02192"
"97.92000","8.16020","0.02201"
"98.20800","8.18417","0.02216"
"98.49600","8.20815","0.02210"
"98.78400","8.23218","0.02208"
"99.07200","8.25616","0.02189"
"99.36000","8.28019","0.02204"
"99.64800","8.30423","0.02219"
"99.93600","8.32820","0.02230"
"100.22400","8.35224","0.02184"
"100.51200","8.37615","0.02169"
"100.80000","8.40019","0.02208"
"101.08800","8.42417","0.02217"
"101.37600","8.44820","0.02220"
"101.66400","8.47212","0.02184"
"101.95200","8.49621","0.02161"
"102.24000","8.52019","0.02147"
"102.52800","8.54422","0.02208"
"102.81600","8.56820","0.02252"
"103.10400","8.59217","0.02211"
"103.39200","8.61621","0.02185"
"103.68000","8.64019","0.02197"
"103.96800","8.66422","0.02153"
"104.25600","8.68820","0.02152"
"104.54400","8.71217","0.02211"
"104.83200","8.73615","0.02139"
"105.12000","8.76018","0.02148"
"105.40800","8.78416","0.02163"
"105.69600","8.80819","0.02142"
"105.98400","8.83223","0.02143"
"106.27200","8.85620","0.02133"
"106.56000","8.88018","0.02148"
"106.84800","8.90416","0.02132"
"107.13600","8.92813","0.02132"
"107.42400","8.95211","0.02195"
"107.71200","8.97614","0.02144"
"108.00000","9.00012","0.02128"
"108.28800","9.02421","0.02173"
"108.57600","9.04819","0.02170"
"108.86400","9.07222","0.02137"
"109.15200","9.09614","0.02142"
"109.44000","9.12018","0.02132"
"109.72800","9.14415","0.02151"
"110.01600","9.16825","0.02150"
"110.30400","9.19216","0.02145"
"110.59200","9.21620","0.02173"
"110.88000","9.24017","0.02158"
"111.16800","9.26415","0.02141"
"111.45600","9.28818","0.02145"
"111.74400","9.31216","0.02141"
"112.03200","9.33619","0.02138"
"112.32000","9.36017","0.02129"
"112.60800","9.38421","0.02136"
"112.89600","9.40812","0.02128"
"113.18400","9.43216","0.02145"
"113.47200","9.45613","0.02144"
"113.76000","9.48023","0.02133"
"114.04800","9.50414","0.02139"
"114.33600","9.52818","0.02112"
"114.62400","9.55216","0.02117"
"114.91200","9.57619","0.02150"
"115.20000","9.60017","0.02101"
"115.48800","9.62414","0.02130"
"115.77600","9.64818","0.02116"
"116.06400","9.67215","0.02139"
"116.35200","9.69619","0.02088"
"116.64000","9.72016","0.02099"
"116.92800","9.74420","0.02127"
"117.21600","9.76818","0.02094"
"117.50400","9.79221","0.02119"
"117.79200","9.81613","0.02104"
"118.08000","9.84022","0.02143"
"118.36800","9.86414","0.02094"
"118.65600","9.88823","0.02148"
"118.94400","9.91215","0.02137"
"119.23200","9.93618","0.02096"
"119.52000","9.96016","0.02072"
"119.80800","9.98419","0.02112"
"120.09600","10.00817","0.02126"
"120.38400","10.03215","0.02111"
"120.67200","10.05618","0.02109"
"120.96000","10.08016","0.02131"
"121.24800","10.10419","0.02135"
"121.53600","10.12817","0.02073"
"121.82400","10.15220","0.02084"
"122.11200","10.17618","0.02147"
"122.40000","10.20015","0.02152"
"122.68800","10.22413","0.02118"
"122.97600","10.24817","0.02097"
"123.26400","10.27220","0.02114"
"123.55200","10.29618","0.02123"
"123.84000","10.32021","0.02077"
"124.12800","10.34419","0.02113"
"124.41600","10.36822","0.02113"
"124.70400","10.39220","0.02073"
"124.99200","10.41617","0.02049"
"125.28000","10.44015","0.02109"
"125.56800","10.46418","0.02104"
"125.85600","10.48816","0.02099"
"126.14400","10.51226","0.02034"
"126.43200","10.53617","0.02073"
"126.72000","10.56027","0.02073"
"127.00800","10.58418","0.02098"
"127.29600","10.60822","0.02090"
"127.58400","10.63225","0.02080"
"127.87200","10.65623","0.02077"
"128.16000","10.68020","0.02075"
"128.44800","10.70418","0.02067"
"128.73600","10.72822","0.02083"
"129.02400","10.75219","0.02047"
"129.31200","10.77623","0.02072"
"129.60000","10.80020","0.02041"
"129.88800","10.82424","0.02087"
"130.17600","10.84815","0.02066"
"130.46400","10.87219","0.02039"
"130.75200","10.89616","0.02066"
"131.04000","10.92020","0.02067"
"131.32800","10.94418","0.02066"
"131.61600","10.96821","0.02055"
"131.90400","10.99225","0.02071"
"132.19200","11.01622","0.02053"
"132.48000","11.04026","0.02083"
"132.76800","11.06417","0.02033"
"133.05600","11.08821","0.02084"
"133.34400","11.11218","0.02082"
"133.63200","11.13622","0.02053"
"133.92000","11.16014","0.02025"
"134.20800","11.18423","0.02039"
"134.49600","11.20815","0.02054"
"134.78400","11.23224","0.02061"
"135.07200","11.25622","0.02071"
"135.36000","11.28025","0.02039"
"135.64800","11.30423","0.02063"
"135.93600","11.32826","0.02040"
"136.22400","11.35224","0.02090"
"136.51200","11.37621","0.02075"
"136.80000","11.40019","0.02064"
"137.08800","11.42417","0.02072"
"137.37600","11.44820","0.02061"
"137.66400","11.47212","0.02058"
"137.95200","11.49621","0.02110"
"138.24000","11.52019","0.02076"
"138.52800","11.54422","0.02064"
"138.81600","11.56820","0.02076"
"139.10400","11.59223","0.02092"
"139.39200","11.61615","0.02085"
"139.68000","11.64019","0.02094"
"139.96800","11.66422","0.02072"
"140.25600","11.68826","0.02084"
"140.54400","11.71223","0.02065"
"140.83200","11.73621","0.02054"
"141.12000","11.76024","0.02089"
"141.40800","11.78422","0.02063"
"141.69600","11.80819","0.02105"
"141.98400","11.83217","0.02094"
"142.27200","11.85620","0.02087"
"142.56000","11.88012","0.02099"
"142.84800","11.90422","0.02092"
"143.13600","11.92813","0.02067"
"143.42400","11.95223","0.02036"
"143.71200","11.97620","0.02058"
"144.00000","12.00018","0.02108"
"144.28800","12.02421","0.02104"
"144.57600","12.04819","0.02105"
"144.86400","12.07222","0.02040"
"145.15200","12.09620","0.02123"
"145.44000","12.12018","0.02073"
"145.72800","12.14415","0.02114"
"146.01600","12.16819","0.02090"
"146.30400","12.19216","0.02116"
"146.59200","12.21620","0.02088"
"146.88000","12.24017","0.02116"
"147.16800","12.26421","0.02053"
"147.45600","12.28812","0.02070"
"147.74400","12.31222","0.02063"
"148.03200","12.33619","0.02084"
"148.32000","12.36017","0.02091"
"148.60800","12.38421","0.02076"
"148.89600","12.40818","0.02086"
"149.18400","12.43222","0.02091"
"149.47200","12.45619","0.02069"
"149.76000","12.48023","0.02064"
"150.04800","12.50420","0.02145"
"150.33600","12.52824","0.02070"
"150.62400","12.55216","0.02085"
"150.91200","12.57619","0.02115"
"151.20000","12.60017","0.02105"
"151.48800","12.62420","0.02124"
"151.77600","12.64818","0.02108"
"152.06400","12.67221","0.02128"
"152.35200","12.69619","0.02088"
"152.64000","12.72016","0.02137"
"152.92800","12.74420","0.02090"
"153.21600","12.76817","0.02093"
"153.50400","12.79221","0.02119"
"153.79200","12.81619","0.02075"
"154.08000","12.84022","0.02113"
"154.36800","12.86414","0.02085"
"154.65600","12.88817","0.02077"
"154.94400","12.91215","0.02123"
"155.23200","12.93624","0.02076"
"155.52000","12.96016","0.02102"
"155.80800","12.98419","0.02097"
"156.09600","13.00817","0.02105"
"156.38400","13.03215","0.02086"
"156.67200","13.05618","0.02079"
"156.96000","13.08016","0.02087"
"157.24800","13.10425","0.02131"
"157.53600","13.12817","0.02096"
"157.82400","13.15220","0.02086"
"158.11200","13.17618","0.02098"
"158.40000","13.20015","0.02098"
"158.68800","13.22413","0.02139"
"158.97600","13.24822","0.02097"
"159.26400","13.27214","0.02059"
"159.55200","13.29624","0.02099"
"159.84000","13.32021","0.02123"
"160.12800","13.34419","0.02126"
"160.41600","13.36822","0.02133"
"160.70400","13.39214","0.02104"
"160.99200","13.41617","0.02126"
"161.28000","13.44021","0.02089"
"161.56800","13.46419","0.02111"
"161.85600","13.48816","0.02083"
"162.14400","13.51220","0.02094"
"162.43200","13.53611","0.02079"
"162.72000","13.56021","0.02134"
"163.00800","13.58412","0.02117"
"163.29600","13.60822","0.02136"
"163.58400","13.63213","0.02109"
"163.87200","13.65623","0.02106"
"164.16000","13.68015","0.02127"
"164.44800","13.70418","0.02079"
"164.73600","13.72822","0.02146"
"165.02400","13.75219","0.02112"
"165.31200","13.77617","0.02106"
"165.60000","13.80014","0.02134"
"165.88800","13.82424","0.02131"
"166.17600","13.84821","0.02130"
"166.46400","13.87219","0.02132"
"166.75200","13.89616","0.02120"
"167.04000","13.92020","0.02145"
"167.32800","13.94417","0.02134"
"167.61600","13.96821","0.02107"
"167.90400","13.99219","0.02152"
"168.19200","14.01622","0.02151"
"168.48000","14.04020","0.02129"
"168.76800","14.06423","0.02142"
"169.05600","14.08821","0.02136"
"169.34400","14.11218","0.02102"
"169.63200","14.13622","0.02159"
"169.92000","14.16020","0.02159"
"170.20800","14.18429","0.02182"
"170.49600","14.20815","0.02171"
"170.78400","14.23224","0.02128"
"171.07200","14.25616","0.02183"
"171.36000","14.28025","0.02125"
"171.64800","14.30417","0.02162"
"171.93600","14.32826","0.02142"
"172.22400","14.35218","0.02159"
"172.51200","14.37621","0.02164"
"172.80000","14.40019","0.02167"
"173.08800","14.42422","0.02142"
"173.37600","14.44820","0.02184"
"173.66400","14.47224","0.02146"
"173.95200","14.49621","0.02168"
"174.24000","14.52019","0.02149"
"174.52800","14.54422","0.02180"
"174.81600","14.56820","0.02164"
"175.10400","14.59223","0.02173"
"175.39200","14.61621","0.02134"
"175.68000","14.64025","0.02149"
"175.96800","14.66422","0.02156"
"176.25600","14.68820","0.02123"
"176.54400","14.71217","0.02183"
"176.83200","14.73621","0.02198"
"177.12000","14.76024","0.02149"
"177.40800","14.78422","0.02166"
"177.69600","14.80831","0.02126"
"177.98400","14.83217","0.02144"
"178.27200","14.85620","0.02141"
"178.56000","14.88012","0.02159"
"178.84800","14.90422","0.02157"
"179.13600","14.92813","0.02176"
"179.42400","14.95223","0.02178"
"179.71200","14.97614","0.02193"
"180.00000","15.00024","0.02212"
"180.28800","15.02415","0.02200"
"180.57600","15.04819","0.02178"
"180.86400","15.07217","0.02224"
"181.15200","15.09620","0.02205"
"181.44000","15.12024","0.02212"
"181.72800","15.14421","0.02233"
"182.01600","15.16819","0.02222"
"182.30400","15.19216","0.02205"
"182.59200","15.21620","0.02205"
"182.88000","15.24017","0.02228"
"183.16800","15.26421","0.02231"
"183.45600","15.28818","0.02214"
"183.74400","15.31222","0.02198"
"184.03200","15.33620","0.02186"
"184.32000","15.36017","0.02229"
"184.60800","15.38415","0.02255"
"184.89600","15.40812","0.02254"
"185.18400","15.43222","0.02219"
"185.47200","15.45619","0.02225"
"185.76000","15.48023","0.02251"
"186.04800","15.50414","0.02232"
"186.33600","15.52824","0.02234"
"186.62400","15.55210","0.02234"
"186.91200","15.57619","0.02241"
"187.20000","15.60011","0.02303"
"187.48800","15.62420","0.02276"
"187.77600","15.64812","0.02260"
"188.06400","15.67221","0.02238"
"188.35200","15.69613","0.02233"
"188.64000","15.72022","0.02223"
"188.92800","15.74414","0.02228"
"189.21600","15.76817","0.02232"
"189.50400","15.79227","0.02209"
"189.79200","15.81625","0.02263"
"190.08000","15.84022","0.02226"
"190.36800","15.86419","0.02258"
"190.65600","15.88817","0.02207"
"190.94400","15.91215","0.02257"
"191.23200","15.93618","0.02203"
"191.52000","15.96016","0.02218"
"191.80800","15.98419","0.02256"
"192.09600","16.00817","0.02265"
"192.38400","16.03220","0.02251"
"192.67200","16.05612","0.02214"
"192.96000","16.08016","0.02282"
"193.24800","16.10419","0.02282"
"193.53600","16.12817","0.02251"
"193.82400","16.15220","0.02293"
"194.11200","16.17618","0.02285"
"194.40000","16.20021","0.02254"
"194.68800","16.22413","0.02295"
"194.97600","16.24817","0.02275"
"195.26400","16.27208","0.02302"
"195.55200","16.29618","0.02233"
"195.84000","16.32015","0.02297"
"196.12800","16.34419","0.02256"
"196.41600","16.36816","0.02256"
"196.70400","16.39220","0.02310"
"196.99200","16.41617","0.02311"
"197.28000","16.44015","0.02293"
"197.56800","16.46418","0.02278"
"197.85600","16.48816","0.02304"
"198.14400","16.51220","0.02294"
"198.43200","16.53617","0.02248"
"198.72000","16.56015","0.02281"
"199.00800","16.58418","0.02277"
"199.29600","16.60816","0.02315"
"199.58400","16.63207","0.02320"
"199.87200","16.65617","0.02300"
"200.16000","16.68014","0.02308"
"200.44800","16.70418","0.02341"
"200.73600","16.72816","0.02340"
"201.02400","16.75219","0.02349"
"201.31200","16.77622","0.02270"
"201.60000","16.80020","0.02328"
"201.88800","16.82418","0.02333"
"202.17600","16.84815","0.02291"
"202.46400","16.87219","0.02320"
"202.75200","16.89616","0.02307"
"203.04000","16.92020","0.02350"
"203.32800","16.94417","0.02306"
"203.61600","16.96821","0.02371"
"203.90400","16.99213","0.02357"
"204.19200","17.01622","0.02338"
"204.48000","17.04020","0.02398"
"204.76800","17.06423","0.02330"
"205.05600","17.08821","0.02352"
"205.34400","17.11218","0.02369"
"205.63200","17.13616","0.02355"
"205.92000","17.16019","0.02368"
"206.20800","17.18417","0.02418"
"206.49600","17.20814","0.02356"
"206.78400","17.23224","0.02374"
"207.07200","17.25616","0.02394"
"207.36000","17.28019","0.02356"
"207.64800","17.30417","0.02372"
"207.93600","17.32820","0.02353"
"208.22400","17.35218","0.02357"
"208.51200","17.37621","0.02406"
"208.80000","17.40019","0.02409"
"209.08800","17.42422","0.02441"
"209.37600","17.44820","0.02385"
"209.66400","17.47223","0.02360"
"209.95200","17.49621","0.02401"
"210.24000","17.52013","0.02380"
"210.52800","17.54422","0.02372"
"210.81600","17.56820","0.02385"
"211.10400","17.59223","0.02424"
"211.39200","17.61615","0.02421"
"211.68000","17.64024","0.02393"
"211.96800","17.66416","0.02387"
"212.25600","17.68826","0.02400"
"212.54400","17.71217","0.02409"
"212.83200","17.73621","0.02390"
"213.12000","17.76018","0.02433"
"213.40800","17.78428","0.02403"
"213.69600","17.80825","0.02413"
"213.98400","17.83223","0.02422"
"214.27200","17.85620","0.02385"
"214.56000","17.88012","0.02435"
"214.84800","17.90421","0.02437"
"215.13600","17.92819","0.02451"
"215.42400","17.95223","0.02425"
"215.71200","17.97620","0.02433"
"216.00000","18.00024","0.02442"
"216.28800","18.02421","0.02431"
"216.57600","18.04825","0.02425"
"216.86400","18.07216","0.02479"
"217.15200","18.09626","0.02448"
"217.44000","18.12024","0.02459"
"217.72800","18.14421","0.02449"
"218.01600","18.16818","0.02466"
"218.30400","18.19216","0.02457"
"218.59200","18.21620","0.02453"
"218.88000","18.24017","0.02493"
"219.16800","18.26427","0.02459"
"219.45600","18.28818","0.02440"
"219.74400","18.31222","0.02465"
"220.03200","18.33613","0.02494"
"220.32000","18.36023","0.02473"
"220.60800","18.38420","0.02488"
"220.89600","18.40818","0.02472"
"221.18400","18.43222","0.02470"
"221.47200","18.45625","0.02453"
"221.76000","18.48023","0.02499"
"222.04800","18.50420","0.02532"
"222.33600","18.52824","0.02490"
"222.62400","18.55215","0.02515"
"222.91200","18.57625","0.02511"
"223.20000","18.60017","0.02525"
"223.48800","18.62420","0.02530"
"223.77600","18.64812","0.02521"
"224.06400","18.67221","0.02536"
"224.35200","18.69619","0.02491"
"224.64000","18.72022","0.02538"
"224.92800","18.74414","0.02560"
"225.21600","18.76823","0.02570"
"225.50400","18.79215","0.02554"
"225.79200","18.81624","0.02603"
"226.08000","18.84022","0.02605"
"226.36800","18.86419","0.02617"
"226.65600","18.88823","0.02579"
"226.94400","18.91221","0.02611"
"227.23200","18.93618","0.02598"
"227.52000","18.96016","0.02562"
"227.80800","18.98419","0.02605"
"228.09600","19.00817","0.02620"
"228.38400","19.03226","0.02620"
"228.67200","19.05618","0.02624"
"228.96000","19.08022","0.02629"
"229.24800","19.10413","0.02631"
"229.53600","19.12817","0.02600"
"229.82400","19.15220","0.02591"
"230.11200","19.17618","0.02604"
"230.40000","19.20021","0.02654"
"230.68800","19.22419","0.02673"
"230.97600","19.24822","0.02661"
"231.26400","19.27220","0.02640"
"231.55200","19.29618","0.02656"
"231.84000","19.32015","0.02659"
"232.12800","19.34419","0.02621"
"232.41600","19.36816","0.02692"
"232.70400","19.39220","0.02706"
"232.99200","19.41611","0.02673"
"233.28000","19.44021","0.02658"
"233.56800","19.46418","0.02652"
"233.85600","19.48828","0.02729"
"234.14400","19.51220","0.02706"
"234.43200","19.53617","0.02689"
"234.72000","19.56021","0.02690"
"235.00800","19.58424","0.02700"
"235.29600","19.60822","0.02726"
"235.58400","19.63219","0.02702"
"235.87200","19.65617","0.02683"
"236.16000","19.68014","0.02721"
"236.44800","19.70418","0.02747"
"236.73600","19.72815","0.02739"
"237.02400","19.75225","0.02749"
"237.31200","19.77623","0.02737"
"237.60000","19.80026","0.02749"
"237.88800","19.82418","0.02782"
"238.17600","19.84815","0.02746"
"238.46400","19.87219","0.02808"
"238.75200","19.89616","0.02839"
"239.04000","19.92020","0.02791"
"239.32800","19.94417","0.02795"
"239.61600","19.96815","0.02819"
"239.90400","19.99218","0.02861"
"240.19200","20.01616","0.02869"
"240.48000","20.04008","0.02875"
"240.76800","20.06417","0.02847"
"241.05600","20.08815","0.02934"
"241.34400","20.11224","0.02963"
"241.63200","20.13616","0.02922"
"241.92000","20.16019","0.02963"
"242.20800","20.18417","0.02984"
"242.49600","20.20820","0.03021"
"242.78400","20.23224","0.03039"
"243.07200","20.25621","0.03021"
"243.36000","20.28019","0.03046"
"243.64800","20.30416","0.03074"
"243.93600","20.32820","0.03088"
"244.22400","20.35212","0.03093"
"244.51200","20.37615","0.03150"
"244.80000","20.40013","0.03136"
"245.08800","20.42422","0.03166"
"245.37600","20.44820","0.03146"
"245.66400","20.47224","0.03143"
"245.95200","20.49615","0.03217"
"246.24000","20.52019","0.03189"
"246.52800","20.54422","0.03184"
"246.81600","20.56820","0.03216"
"247.10400","20.59217","0.03301"
"247.39200","20.61615","0.03315"
"247.68000","20.64018","0.03321"
"247.96800","20.66416","0.03358"
"248.25600","20.68819","0.03350"
"248.54400","20.71211","0.03404"
"248.83200","20.73621","0.03411"
"249.12000","20.76018","0.03454"
"249.40800","20.78428","0.03466"
"249.69600","20.80819","0.03473"
"249.98400","20.83223","0.03518"
"250.27200","20.85620","0.03535"
"250.56000","20.88018","0.03559"
"250.84800","20.90415","0.03542"
"251.13600","20.92819","0.03607"
"251.42400","20.95223","0.03560"
"251.71200","20.97620","0.03592"
"252.00000","21.00024","0.03630"
"252.28800","21.02421","0.03684"
"252.57600","21.04825","0.03750"
"252.86400","21.07216","0.03760"
"253.15200","21.09620","0.03855"
"253.44000","21.12017","0.03845"
"253.72800","21.14421","0.03932"
"254.01600","21.16818","0.03945"
"254.30400","21.19222","0.04008"
"254.59200","21.21620","0.04051"
"254.88000","21.24023","0.04061"
"255.16800","21.26421","0.04070"
"255.45600","21.28818","0.04137"
"255.74400","21.31228","0.04123"
"256.03200","21.33619","0.04214"
"256.32000","21.36023","0.04275"
"256.60800","21.38415","0.04264"
"256.89600","21.40824","0.04367"
"257.18400","21.43216","0.04374"
"257.47200","21.45625","0.04408"
"257.76000","21.48017","0.04455"
"258.04800","21.50420","0.04497"
"258.33600","21.52812","0.04542"
"258.62400","21.55221","0.04591"
"258.91200","21.57619","0.04639"
"259.20000","21.60022","0.04714"
"259.48800","21.62426","0.04737"
"259.77600","21.64818","0.04812"
"260.06400","21.67227","0.04827"
"260.35200","21.69625","0.04882"
"260.64000","21.72022","0.04912"
"260.92800","21.74420","0.04979"
"261.21600","21.76823","0.05056"
"261.50400","21.79221","0.05079"
"261.79200","21.81618","0.05087"
"262.08000","21.84016","0.05097"
"262.36800","21.86420","0.05171"
"262.65600","21.88823","0.05198"
"262.94400","21.91221","0.05137"
"263.23200","21.93618","0.03676"
"263.52000","21.96016","0.03643"
"263.80800","21.98419","0.03749"
"264.09600","22.00817","0.03590"
"264.38400","22.03221","0.03530"
"264.67200","22.05612","0.03413"
"264.96000","22.08022","0.03785"
"265.24800","22.10413","0.03775"
"265.53600","22.12823","0.03788"
"265.82400","22.15214","0.03579"
"266.11200","22.17618","0.03440"
"266.40000","22.20015","0.03365"
"266.68800","22.22419","0.03585"
"266.97600","22.24816","0.03530"
"267.26400","22.27220","0.03425"
"267.55200","22.29623","0.03571"
"267.84000","22.32021","0.03789"
"268.12800","22.34419","0.03828"
"268.41600","22.36816","0.03903"
"268.70400","22.39220","0.03952"
"268.99200","22.41617","0.03936"
"269.28000","22.44021","0.04018"
"269.56800","22.46418","0.04183"
"269.85600","22.48822","0.04291"
"270.14400","22.51219","0.04270"
"270.43200","22.53617","0.04288"
"270.72000","22.56015","0.04341"
"271.00800","22.58418","0.04456"
"271.29600","22.60822","0.04461"
"271.58400","22.63219","0.04535"
"271.87200","22.65623","0.04576"
"272.16000","22.68014","0.04654"
"272.44800","22.70418","0.04768"
"272.73600","22.72809","0.04820"
"273.02400","22.75219","0.04840"
"273.31200","22.77611","0.04889"
"273.60000","22.80020","0.04930"
"273.88800","22.82412","0.05065"
"274.17600","22.84821","0.05039"
"274.46400","22.87213","0.05084"
"274.75200","22.89622","0.05008"
"275.04000","22.92020","0.03725"
"275.32800","22.94423","0.02340"
"275.61600","22.96821","0.02454"
"275.90400","22.99218","0.02490"
"276.19200","23.01616","0.02475"
"276.48000","23.04020","0.02439"
"276.76800","23.06417","0.02411"
"277.05600","23.08809","0.02454"
"277.34400","23.11224","0.02439"
"277.63200","23.13616","0.02551"
"277.92000","23.16019","0.02512"
"278.20800","23.18411","0.02481"
"278.49600","23.20820","0.02459"
"278.78400","23.23218","0.02489"
"279.07200","23.25616","0.02489"
"279.36000","23.28019","0.02525"
"279.64800","23.30417","0.02490"
"279.93600","23.32820","0.02459"
"280.22400","23.35212","0.02525"
"280.51200","23.37615","0.02500"
"280.80000","23.40013","0.02541"
"281.08800","23.42422","0.02555"
"281.37600","23.44814","0.02531"
"281.66400","23.47223","0.02551"
"281.95200","23.49615","0.02520"
"282.24000","23.52019","0.02520"
"282.52800","23.54410","0.02567"
"282.81600","23.56820","0.02568"
"283.10400","23.59217","0.02534"
"283.39200","23.61615","0.02586"
"283.68000","23.64018","0.02596"
"283.96800","23.66416","0.02573"
"284.25600","23.68819","0.02578"
"284.54400","23.71217","0.02606"
"284.83200","23.73621","0.02595"
"285.12000","23.76018","0.02583"
"285.40800","23.78422","0.02653"
"285.69600","23.80807","0.02588"
"285.98400","23.83217","0.02662"
"286.27200","23.85614","0.02673"
"286.56000","23.88018","0.02656"
"286.84800","23.90415","0.02664"
"287.13600","23.92819","0.02704"
"287.42400","23.95216","0.02701"
"287.71200","23.97620","0.02698"
"288.00000","24.00018","0.02682"
"288.28800","24.02415","0.02705"
"288.57600","24.04819","0.02669"
"288.86400","24.07210","0.02736"
"289.15200","24.09620","0.02706"
"289.44000","24.12012","0.02665"
"289.72800","24.14421","0.02720"
"290.01600","24.16818","0.02718"
"290.30400","24.19222","0.02755"
"290.59200","24.21614","0.02715"
"290.88000","24.24023","0.02780"
"291.16800","24.26421","0.02730"
"291.45600","24.28824","0.02738"
"291.74400","24.31222","0.02748"
"292.03200","24.33619","0.02786"
"292.32000","24.36023","0.02748"
"292.60800","24.38414","0.02777"
"292.89600","24.40824","0.02801"
"293.18400","24.43216","0.02795"
"293.47200","24.45625","0.02777"
"293.76000","24.48017","0.02783"
"294.04800","24.50420","0.02778"
"294.33600","24.52818","0.02816"
"294.62400","24.55215","0.02799"
"294.91200","24.57619","0.02808"
"295.20000","24.60023","0.02859"
"295.48800","24.62420","0.02774"
"295.77600","24.64818","0.02831"
"296.06400","24.67221","0.02824"
"296.35200","24.69619","0.02780"
"296.64000","24.72028","0.02809"
"296.92800","24.74420","0.02813"
"297.21600","24.76823","0.02846"
"297.50400","24.79215","0.02800"
"297.79200","24.81624","0.02887"
"298.08000","24.84016","0.02825"
"298.36800","24.86419","0.02848"
"298.65600","24.88817","0.02846"
"298.94400","24.91226","0.02881"
"299.23200","24.93624","0.02876"
"299.52000","24.96022","0.02871"
"299.80800","24.98419","0.02830"
"300.09600","25.00823","0.02848"
"300.38400","25.03226","0.02919"
"300.67200","25.05612","0.02856"
"300.96000","25.08027","0.02906"
"301.24800","25.10419","0.02901"
"301.53600","25.12823","0.02858"
"301.82400","25.15214","0.02861"
"302.11200","25.17617","0.02857"
"302.40000","25.20015","0.02869"
"302.68800","25.22425","0.02853"
"302.97600","25.24817","0.02798"
"303.26400","25.27220","0.02750"
"303.55200","25.29617","0.02760"
"303.84000","25.32021","0.02735"
"304.12800","25.34418","0.02758"
"304.41600","25.36816","0.02733"
"304.70400","25.39219","0.02746"
"304.99200","25.41617","0.02717"
"305.28000","25.44021","0.02767"
"305.56800","25.46418","0.02744"
"305.85600","25.48822","0.02751"
"306.14400","25.51213","0.02782"
"306.43200","25.53623","0.02772"
"306.72000","25.56020","0.02816"
"307.00800","25.58418","0.02833"
"307.29600","25.60816","0.02785"
"307.58400","25.63225","0.02833"
"307.87200","25.65623","0.02799"
"308.16000","25.68020","0.02826"
"308.44800","25.70424","0.02817"
"308.73600","25.72816","0.02803"
"309.02400","25.75219","0.02848"
"309.31200","25.77610","0.02829"
"309.60000","25.80020","0.02839"
"309.88800","25.82411","0.02860"
"310.17600","25.84821","0.02862"
"310.46400","25.87219","0.02862"
"310.75200","25.89622","0.02880"
"311.04000","25.92020","0.02901"
"311.32800","25.94423","0.02917"
"311.61600","25.96821","0.02916"
"311.90400","25.99219","0.02943"
"312.19200","26.01622","0.02940"
"312.48000","26.04013","0.02895"
"312.76800","26.06423","0.02904"
"313.05600","26.08821","0.02940"
"313.34400","26.11218","0.02926"
"313.63200","26.13616","0.02943"
"313.92000","26.16019","0.02961"
"314.20800","26.18417","0.02988"
"314.49600","26.20820","0.02965"
"314.78400","26.23218","0.03000"
"315.07200","26.25622","0.03000"
"315.36000","26.28019","0.02988"
"315.64800","26.30423","0.03066"
"315.93600","26.32820","0.03053"
"316.22400","26.35218","0.03050"
"316.51200","26.37621","0.02998"
"316.80000","26.40013","0.03063"
"317.08800","26.42422","0.03082"
"317.37600","26.44820","0.03041"
"317.66400","26.47217","0.03087"
"317.95200","26.49615","0.03064"
"318.24000","26.52019","0.03110"
"318.52800","26.54410","0.03118"
"318.81600","26.56820","0.03075"
"319.10400","26.59217","0.03105"
"319.39200","26.61621","0.03092"
"319.68000","26.64013","0.03167"
"319.96800","26.66416","0.03141"
"320.25600","26.68819","0.03136"
"320.54400","26.71217","0.03168"
"320.83200","26.73620","0.03202"
"321.12000","26.76018","0.03170"
"321.40800","26.78422","0.03240"
"321.69600","26.80813","0.03263"
"321.98400","26.83217","0.03266"
"322.27200","26.85614","0.03234"
"322.56000","26.88018","0.03238"
"322.84800","26.90415","0.03253"
"323.13600","26.92825","0.03259"
"323.42400","26.95222","0.03263"
"323.71200","26.97620","0.03303"
"324.00000","27.00023","0.03371"
"324.28800","27.02415","0.03358"
"324.57600","27.04819","0.03357"
"324.86400","27.07216","0.03434"
"325.15200","27.09620","0.03409"
"325.44000","27.12017","0.03380"
"325.72800","27.14421","0.03402"
"326.01600","27.16819","0.03412"
"326.30400","27.19222","0.03440"
"326.59200","27.21614","0.03430"
"326.88000","27.24023","0.03427"
"327.16800","27.26415","0.03413"
"327.45600","27.28818","0.03416"
"327.74400","27.31216","0.03404"
"328.03200","27.33619","0.03499"
"328.32000","27.36023","0.03477"
"328.60800","27.38420","0.03449"
"328.89600","27.40824","0.03476"
"329.18400","27.43222","0.03558"
"329.47200","27.45625","0.03474"
"329.76000","27.48017","0.03486"
"330.04800","27.50420","0.03521"
"330.33600","27.52818","0.03573"
"330.62400","27.55221","0.03546"
"330.91200","27.57613","0.03617"
"331.20000","27.60023","0.03626"
"331.48800","27.62420","0.03604"
"331.77600","27.64824","0.03646"
"332.06400","27.67221","0.03647"
"332.35200","27.69625","0.03655"
"332.64000","27.72022","0.03618"
"332.92800","27.74420","0.03628"
"333.21600","27.76823","0.03686"
"333.50400","27.79221","0.03679"
"333.79200","27.81624","0.03655"
"334.08000","27.84016","0.03616"
"334.36800","27.86419","0.03640"
"334.65600","27.88811","0.03688"
"334.94400","27.91227","0.03670"
"335.23200","27.93618","0.03719"
"335.52000","27.96028","0.03748"
"335.80800","27.98419","0.03770"
"336.09600","28.00823","0.03788"
"336.38400","28.03220","0.03765"
"336.67200","28.05624","0.03779"
"336.96000","28.08021","0.03763"
"337.24800","28.10419","0.03768"
"337.53600","28.12823","0.03810"
"337.82400","28.15214","0.03813"
"338.11200","28.17618","0.03805"
"338.40000","28.20015","0.03786"
"338.68800","28.22425","0.03835"
"338.97600","28.24822","0.03828"
"339.26400","28.27220","0.03929"
"339.55200","28.29617","0.03776"
"339.84000","28.32021","0.03838"
"340.12800","28.34412","0.03858"
"340.41600","28.36822","0.02847"
"340.70400","28.39226","0.02911"
"340.99200","28.41623","0.02876"
"341.28000","28.44027","0.02830"
"341.56800","28.46418","0.02854"
"341.85600","28.48822","0.02940"
"342.14400","28.51213","0.02796"
"342.43200","28.53617","0.02862"
"342.72000","28.56014","0.02824"
"343.00800","28.58424","0.02931"
"343.29600","28.60815","0.02931"
"343.58400","28.63219","0.02856"
"343.87200","28.65617","0.02897"
"344.16000","28.68020","0.02909"
"344.44800","28.70418","0.02950"
"344.73600","28.72821","0.02965"
"345.02400","28.75219","0.03035"
"345.31200","28.77616","0.02946"
"345.60000","28.80020","0.02977"
"345.88800","28.82417","0.02954"
"346.17600","28.84821","0.03081"
"346.46400","28.87219","0.03040"
"346.75200","28.89622","0.03074"
"347.04000","28.92014","0.03028"
"347.32800","28.94423","0.03086"
"347.61600","28.96815","0.03022"
"347.90400","28.99218","0.03076"
"348.19200","29.01616","0.03091"
"348.48000","29.04014","0.03124"
"348.76800","29.06417","0.03083"
"349.05600","29.08821","0.03139"
"349.34400","29.11218","0.03056"
"349.63200","29.13616","0.03131"
"349.92000","29.16025","0.03206"
"350.20800","29.18417","0.03214"
"350.49600","29.20820","0.03165"
"350.78400","29.23212","0.03185"
"351.07200","29.25621","0.03184"
"351.36000","29.28019","0.03220"
"351.64800","29.30423","0.03244"
"351.93600","29.32814","0.03297"
"352.22400","29.35218","0.03182"
"352.51200","29.37615","0.03172"
"352.80000","29.40013","0.03177"
"353.08800","29.42422","0.03194"
"353.37600","29.44820","0.03286"
"353.66400","29.47223","0.03267"
"353.95200","29.49621","0.03232"
"354.24000","29.52019","0.03257"
"354.52800","29.54416","0.03250"
"354.81600","29.56820","0.03296"
"355.10400","29.59211","0.03265"
"355.39200","29.61621","0.03289"
"355.68000","29.64012","0.03238"
"355.96800","29.66416","0.03267"
"356.25600","29.68813","0.03326"
"356.54400","29.71217","0.03294"
"356.83200","29.73621","0.03299"
"357.12000","29.76012","0.03300"
"357.40800","29.78416","0.03266"
"357.69600","29.80813","0.03018"
"357.98400","29.83223","0.03032"
"358.27200","29.85614","0.02937"
"358.56000","29.88018","0.03092"
"358.84800","29.90415","0.03014"
"359.13600","29.92825","0.03091"
"359.42400","29.95217","0.03046"
"359.71200","29.97620","0.03136"
"360.00000","30.00012","0.03117"
"360.28800","30.02421","0.03219"
"360.57600","30.04819","0.03205"
"360.86400","30.07216","0.03183"
"361.15200","30.09614","0.03182"
"361.44000","30.12017","0.03215"
"361.72800","30.14421","0.03236"
"362.01600","30.16818","0.03202"
"362.30400","30.19222","0.03247"
"362.59200","30.21619","0.03239"
"362.88000","30.24017","0.03237"
"363.16800","30.26409","0.03249"
"363.45600","30.28818","0.03189"
"363.74400","30.31210","0.03266"
"364.03200","30.33619","0.03310"
"364.32000","30.36017","0.03237"
"364.60800","30.38420","0.03338"
"364.89600","30.40818","0.03290"
"365.18400","30.43216","0.03271"
"365.47200","30.45619","0.03263"
"365.76000","30.48011","0.03239"
"366.04800","30.50420","0.03222"
"366.33600","30.52818","0.03245"
"366.62400","30.55221","0.03320"
"366.91200","30.57613","0.03299"
"367.20000","30.60022","0.03273"
"367.48800","30.62414","0.03326"
"367.77600","30.64818","0.03347"
"368.06400","30.67215","0.03313"
"368.35200","30.69619","0.03358"
"368.64000","30.72016","0.03331"
"368.92800","30.74420","0.03334"
"369.21600","30.76818","0.03356"
"369.50400","30.79221","0.03419"
"369.79200","30.81618","0.03414"
"370.08000","30.84016","0.03388"
"370.36800","30.86420","0.03376"
"370.65600","30.88817","0.03343"
"370.94400","30.91221","0.03331"
"371.23200","30.93618","0.03248"
"371.52000","30.96022","0.03263"
"371.80800","30.98413","0.03253"
"372.09600","31.00817","0.03348"
"372.38400","31.03220","0.03362"
"372.67200","31.05618","0.03305"
"372.96000","31.08022","0.03202"
"373.24800","31.10425","0.03285"
"373.53600","31.12823","0.03352"
"373.82400","31.15220","0.03264"
"374.11200","31.17624","0.03345"
"374.40000","31.20015","0.03304"
"374.68800","31.22419","0.03399"
"374.97600","31.24822","0.03302"
"375.26400","31.27226","0.03396"
"375.55200","31.29617","0.03366"
"375.84000","31.32021","0.03414"
"376.12800","31.34412","0.03409"
"376.41600","31.36822","0.03420"
"376.70400","31.39219","0.03422"
"376.99200","31.41623","0.03455"
"377.28000","31.44021","0.03389"
"377.56800","31.46424","0.03407"
"377.85600","31.48822","0.03382"
"378.14400","31.51219","0.03455"
"378.43200","31.53617","0.03541"
"378.72000","31.56014","0.03473"
"379.00800","31.58430","0.03499"
"379.29600","31.60821","0.03507"
"379.58400","31.63219","0.03537"
"379.87200","31.65616","0.03541"
"380.16000","31.68026","0.03567"
"380.44800","31.70418","0.03581"
"380.73600","31.72821","0.03663"
"381.02400","31.75219","0.03557"
"381.31200","31.77622","0.03619"
"381.60000","31.80020","0.03637"
"381.88800","31.82423","0.03631"
"382.17600","31.84827","0.03631"
"382.46400","31.87219","0.03649"
"382.75200","31.89622","0.03591"
"383.04000","31.92019","0.03654"
"383.32800","31.94417","0.03707"
"383.61600","31.96815","0.03711"
"383.90400","31.99218","0.03733"
"384.19200","32.01616","0.03769"
"384.48000","32.04025","0.03765"
"384.76800","32.06417","0.03762"
"385.05600","32.08826","0.03832"
"385.34400","32.11224","0.03820"
"385.63200","32.13622","0.03782"
"385.92000","32.16025","0.03793"
"386.20800","32.18423","0.03758"
"386.49600","32.20820","0.03804"
"386.78400","32.23212","0.03884"
"387.07200","32.25621","0.03832"
"387.36000","32.28013","0.03781"
"387.64800","32.30422","0.03772"
"387.93600","32.32814","0.03795"
"388.22400","32.35223","0.03732"
"388.51200","32.37621","0.03797"
"388.80000","32.40025","0.03760"
"389.08800","32.42416","0.03883"
"389.37600","32.44820","0.03835"
"389.66400","32.47218","0.03830"
"389.95200","32.49621","0.03878"
"390.24000","32.52018","0.03847"
"390.52800","32.54416","0.03879"
"390.81600","32.56825","0.03946"
"391.10400","32.59217","0.03932"
"391.39200","32.61621","0.03948"
"391.68000","32.64018","0.03989"
"391.96800","32.66422","0.04014"
"392.25600","32.68813","0.04024"
"392.54400","32.71223","0.04072"
"392.83200","32.73621","0.04078"
"393.12000","32.76018","0.04100"
"393.40800","32.78416","0.04124"
"393.69600","32.80819","0.04122"
"393.98400","32.83223","0.04182"
"394.27200","32.85620","0.04127"
"394.56000","32.88023","0.04151"
"394.84800","32.90421","0.04167"
"395.13600","32.92825","0.04173"
"395.42400","32.95216","0.04158"
"395.71200","32.97620","0.04171"
"396.00000","33.00011","0.04112"
"396.28800","33.02421","0.04101"
"396.57600","33.04819","0.04190"
"396.86400","33.07222","0.04151"
"397.15200","33.09614","0.04215"
"397.44000","33.12017","0.04249"
"397.72800","33.14415","0.04238"
"398.01600","33.16818","0.04264"
"398.30400","33.19216","0.04219"
"398.59200","33.21619","0.04256"
"398.88000","33.24023","0.04178"
"399.16800","33.26421","0.04242"
"399.45600","33.28818","0.04228"
"399.74400","33.31216","0.04236"
"400.03200","33.33625","0.04183"
"400.32000","33.36017","0.04056"
"400.60800","33.38426","0.04156"
"400.89600","33.40818","0.04125"
"401.18400","33.43222","0.04185"
"401.47200","33.45613","0.04125"
"401.76000","33.48016","0.04127"
"402.04800","33.50420","0.04170"
"402.33600","33.52818","0.04172"
"402.62400","33.55221","0.04062"
"402.91200","33.57619","0.04101"
"403.20000","33.60022","0.04087"
"403.48800","33.62420","0.04066"
"403.77600","33.64817","0.04196"
"404.06400","33.67209","0.04213"
"404.35200","33.69619","0.04177"
"404.64000","33.72010","0.04181"
"404.92800","33.74420","0.04150"
"405.21600","33.76817","0.04274"
"405.50400","33.79221","0.04205"
"405.79200","33.81618","0.04270"
"406.08000","33.84016","0.04217"
"406.36800","33.86419","0.04289"
"406.65600","33.88817","0.04265"
"406.94400","33.91220","0.04324"
"407.23200","33.93618","0.04374"
"407.52000","33.96022","0.04317"
"407.80800","33.98413","0.04319"
"408.09600","34.00817","0.04284"
"408.38400","34.03214","0.04298"
"408.67200","34.05624","0.04279"
"408.96000","34.08015","0.04305"
"409.24800","34.10419","0.04359"
"409.53600","34.12822","0.04363"
"409.82400","34.15220","0.04361"
"410.11200","34.17624","0.04395"
"410.40000","34.20021","0.04337"
"410.68800","34.22425","0.04319"
"410.97600","34.24816","0.04374"
"411.26400","34.27226","0.04423"
"411.55200","34.29617","0.04427"
"411.84000","34.32021","0.04437"
"412.12800","34.34418","0.04445"
"412.41600","34.36822","0.04438"
"412.70400","34.39213","0.04398"
"412.99200","34.41623","0.04467"
"413.28000","34.44014","0.04446"
"413.56800","34.46418","0.04439"
"413.85600","34.48822","0.04404"
"414.14400","34.51219","0.04433"
"414.43200","34.53617","0.04396"
"414.72000","34.56020","0.04480"
"415.00800","34.58424","0.04434"
"415.29600","34.60822","0.04450"
"415.58400","34.63219","0.04449"
"415.87200","34.65617","0.04500"
"416.16000","34.68020","0.04535"
"416.44800","34.70417","0.04539"
"416.73600","34.72821","0.04501"
"417.02400","34.75219","0.04563"
"417.31200","34.77622","0.04538"
"417.60000","34.80020","0.04543"
"417.88800","34.82429","0.04574"
"418.17600","34.84827","0.04556"
"418.46400","34.87225","0.04525"
"418.75200","34.89628","0.04416"
"419.04000","34.92020","0.04464"
"419.32800","34.94423","0.04526"
"419.61600","34.96815","0.04516"
"419.90400","34.99224","0.04526"
"420.19200","35.01616","0.04584"
"420.48000","35.04025","0.04594"
"420.76800","35.06417","0.04548"
"421.05600","35.08826","0.04574"
"421.34400","35.11218","0.04663"
"421.63200","35.13628","0.04623"
"421.92000","35.16019","0.04545"
"422.20800","35.18423","0.04616"
"422.49600","35.20820","0.04611"
"422.78400","35.23224","0.04657"
"423.07200","35.25621","0.04664"
"423.36000","35.28013","0.04649"
"423.64800","35.30416","0.04674"
"423.93600","35.32814","0.04711"
"424.22400","35.35223","0.04649"
"424.51200","35.37615","0.04669"
"424.80000","35.40025","0.04687"
"425.08800","35.42416","0.04756"
"425.37600","35.44820","0.04735"
"425.66400","35.47223","0.04731"
"425.95200","35.49621","0.04727"
"426.24000","35.52024","0.04700"
"426.52800","35.54422","0.04752"
"426.81600","35.56826","0.03951"
"427.10400","35.59217","0.03894"
"427.39200","35.61621","0.03955"
"427.68000","35.64012","0.04036"
"427.96000","35.66356","0.04045"