File: Force_trajectories/161218_2/Specimen_RawData_2.csv
End date,"12/18/2016"
Specimen label,"16CT_28"
Maximum Load,"0.01260",N

Time,Extension,Load
(s),(mm),(N)
"0.00000","0.00000","-0.00002"
"0.25800","0.02033","0.00010"
"0.51600","0.04323","0.00015"
"0.77400","0.06475","0.00045"
"1.03200","0.08622","0.00044"
"1.29000","0.10780","0.00084"
"1.54800","0.12921","0.00071"
"1.80600","0.15067","0.00093"
"2.06400","0.17213","0.00069"
"2.32200","0.19372","0.00117"
"2.58000","0.21518","0.00120"
"2.83800","0.23671","0.00099"
"3.09600","0.25823","0.00054"
"3.35400","0.27976","0.00080"
"3.61200","0.30122","0.00100"
"3.87000","0.32274","0.00090"
"4.12800","0.34415","0.00140"
"4.38600","0.36567","0.00139"
"4.64400","0.38720","0.00118"
"4.90200","0.40872","0.00187"
"5.16000","0.43025","0.00152"
"5.41800","0.45171","0.00130"
"5.67600","0.47317","0.00159"
"5.93400","0.49464","0.00127"
"6.19200","0.51622","0.00137"
"6.45000","0.53769","0.00113"
"6.70800","0.55921","0.00147"
"6.96600","0.58068","0.00183"
"7.22400","0.60220","0.00169"
"7.48200","0.62366","0.00139"
"7.74000","0.64525","0.00125"
"7.99800","0.66659","0.00195"
"8.25600","0.68818","0.00188"
"8.51400","0.70964","0.00185"
"8.77200","0.73123","0.00178"
"9.03000","0.75269","0.00173"
"9.28800","0.77421","0.00189"
"9.54600","0.79568","0.00195"
"9.80400","0.81720","0.00203"
"10.06200","0.83873","0.00180"
"10.32000","0.86019","0.00175"
"10.57800","0.88166","0.00203"
"10.83600","0.90324","0.00209"
"11.09400","0.92470","0.00196"
"11.35200","0.94623","0.00221"
"11.61000","0.96775","0.00184"
"11.86800","0.98922","0.00176"
"12.12600","1.01074","0.00202"
"12.38400","1.03221","0.00236"
"12.64200","1.05373","0.00211"
"12.90000","1.07514","0.00207"
"13.15800","1.09672","0.00208"
"13.41600","1.11812","0.00231"
"13.67400","1.13971","0.00214"
"13.93200","1.16117","0.00208"
"14.19000","1.18270","0.00217"
"14.44800","1.20416","0.00238"
"14.70600","1.22575","0.00241"
"14.96400","1.24715","0.00244"
"15.22200","1.26873","0.00281"
"15.48000","1.29020","0.00277"
"15.73800","1.31172","0.00256"
"15.99600","1.33319","0.00248"
"16.25400","1.35471","0.00240"
"16.51200","1.37624","0.00255"
"16.77000","1.39770","0.00281"
"17.02800","1.41916","0.00272"
"17.28600","1.44069","0.00280"
"17.54400","1.46221","0.00299"
"17.80200","1.48374","0.00271"
"18.06000","1.50520","0.00276"
"18.31800","1.52667","0.00258"
"18.57600","1.54825","0.00307"
"18.83400","1.56971","0.00253"
"19.09200","1.59124","0.00250"
"19.35000","1.61264","0.00270"
"19.60800","1.63423","0.00293"
"19.86600","1.65563","0.00296"
"20.12400","1.67722","0.00256"
"20.38200","1.69862","0.00334"
"20.64000","1.72020","0.00299"
"20.89800","1.74161","0.00291"
"21.15600","1.76319","0.00313"
"21.41400","1.78460","0.00323"
"21.67200","1.80630","0.00308"
"21.93000","1.82765","0.00321"
"22.18800","1.84923","0.00292"
"22.44600","1.87069","0.00322"
"22.70400","1.89222","0.00311"
"22.96200","1.91374","0.00310"
"23.22000","1.93515","0.00334"
"23.47800","1.95667","0.00333"
"23.73600","1.97820","0.00334"
"23.99400","1.99972","0.00290"
"24.25200","2.02119","0.00309"
"24.51000","2.04271","0.00297"
"24.76800","2.06417","0.00325"
"25.02600","2.08570","0.00329"
"25.28400","2.10716","0.00309"
"25.54200","2.12875","0.00275"
"25.80000","2.15015","0.00317"
"26.05800","2.17174","0.00304"
"26.31600","2.19320","0.00331"
"26.57400","2.21472","0.00339"
"26.83200","2.23619","0.00369"
"27.09000","2.25771","0.00328"
"27.34800","2.27918","0.00281"
"27.60600","2.30070","0.00334"
"27.86400","2.32217","0.00355"
"28.12200","2.34375","0.00342"
"28.38000","2.36515","0.00326"
"28.63800","2.38668","0.00335"
"28.89600","2.40814","0.00330"
"29.15400","2.42973","0.00342"
"29.41200","2.45119","0.00337"
"29.67000","2.47272","0.00319"
"29.92800","2.49418","0.00362"
"30.18600","2.51570","0.00334"
"30.44400","2.53723","0.00329"
"30.70200","2.55869","0.00326"
"30.96000","2.58022","0.00358"
"31.21800","2.60168","0.00366"
"31.47600","2.62321","0.00338"
"31.73400","2.64467","0.00352"
"31.99200","2.66625","0.00347"
"32.25000","2.68766","0.00342"
"32.50800","2.70918","0.00349"
"32.76600","2.73065","0.00345"
"33.02400","2.75223","0.00364"
"33.28200","2.77370","0.00313"
"33.54000","2.79516","0.00310"
"33.79800","2.81668","0.00365"
"34.05600","2.83815","0.00352"
"34.31400","2.85967","0.00354"
"34.57200","2.88126","0.00380"
"34.83000","2.90266","0.00367"
"35.08800","2.92419","0.00372"
"35.34600","2.94571","0.00357"
"35.60400","2.96718","0.00371"
"35.86200","2.98870","0.00353"
"36.12000","3.01022","0.00368"
"36.37800","3.03169","0.00333"
"36.63600","3.05315","0.00365"
"36.89400","3.07474","0.00347"
"37.15200","3.09620","0.00329"
"37.41000","3.11773","0.00339"
"37.66800","3.13919","0.00336"
"37.92600","3.16071","0.00349"
"38.18400","3.18218","0.00370"
"38.44200","3.20370","0.00321"
"38.70000","3.22511","0.00342"
"38.95800","3.24675","0.00331"
"39.21600","3.26816","0.00340"
"39.47400","3.28974","0.00369"
"39.73200","3.31114","0.00349"
"39.99000","3.33273","0.00347"
"40.24800","3.35419","0.00309"
"40.50600","3.37566","0.00345"
"40.76400","3.39718","0.00378"
"41.02200","3.41871","0.00358"
"41.28000","3.44017","0.00325"
"41.53800","3.46169","0.00340"
"41.79600","3.48322","0.00352"
"42.05400","3.50468","0.00367"
"42.31200","3.52621","0.00378"
"42.57000","3.54767","0.00385"
"42.82800","3.56920","0.00348"
"43.08600","3.59066","0.00323"
"43.34400","3.61218","0.00372"
"43.60200","3.63365","0.00379"
"43.86000","3.65517","0.00374"
"44.11800","3.67664","0.00377"
"44.37600","3.69822","0.00343"
"44.63400","3.71969","0.00389"
"44.89200","3.74115","0.00382"
"45.15000","3.76262","0.00330"
"45.40800","3.78420","0.00370"
"45.66600","3.80566","0.00347"
"45.92400","3.82725","0.00372"
"46.18200","3.84865","0.00332"
"46.44000","3.87018","0.00357"
"46.69800","3.89170","0.00380"
"46.95600","3.91322","0.00343"
"47.21400","3.93469","0.00354"
"47.47200","3.95621","0.00363"
"47.73000","3.97762","0.00357"
"47.98800","3.99920","0.00358"
"48.24600","4.02073","0.00376"
"48.50400","4.04225","0.00368"
"48.76200","4.06372","0.00392"
"49.02000","4.08518","0.00340"
"49.27800","4.10670","0.00369"
"49.53600","4.12817","0.00390"
"49.79400","4.14975","0.00390"
"50.05200","4.17116","0.00399"
"50.31000","4.19274","0.00381"
"50.56800","4.21421","0.00363"
"50.82600","4.23573","0.00358"
"51.08400","4.25713","0.00377"
"51.34200","4.27866","0.00351"
"51.60000","4.30012","0.00395"
"51.85800","4.32171","0.00404"
"52.11600","4.34317","0.00373"
"52.37400","4.36476","0.00379"
"52.63200","4.38616","0.00364"
"52.89000","4.40768","0.00359"
"53.14800","4.42915","0.00367"
"53.40600","4.45073","0.00389"
"53.66400","4.47220","0.00408"
"53.92200","4.49372","0.00414"
"54.18000","4.51519","0.00395"
"54.43800","4.53671","0.00405"
"54.69600","4.55823","0.00408"
"54.95400","4.57970","0.00377"
"55.21200","4.60122","0.00395"
"55.47000","4.62269","0.00382"
"55.72800","4.64415","0.00394"
"55.98600","4.66568","0.00386"
"56.24400","4.68720","0.00375"
"56.50200","4.70866","0.00414"
"56.76000","4.73019","0.00397"
"57.01800","4.75159","0.00401"
"57.27600","4.77324","0.00374"
"57.53400","4.79470","0.00379"
"57.79200","4.81623","0.00381"
"58.05000","4.83763","0.00380"
"58.30800","4.85922","0.00409"
"58.56600","4.88068","0.00386"
"58.82400","4.90220","0.00376"
"59.08200","4.92367","0.00401"
"59.34000","4.94519","0.00365"
"59.59800","4.96666","0.00382"
"59.85600","4.98818","0.00384"
"60.11400","5.00964","0.00442"
"60.37200","5.03117","0.00394"
"60.63000","5.05263","0.00368"
"60.88800","5.07422","0.00406"
"61.14600","5.09574","0.00393"
"61.40400","5.11721","0.00393"
"61.66200","5.13867","0.00395"
"61.92000","5.16020","0.00393"
"62.17800","5.18166","0.00380"
"62.43600","5.20318","0.00404"
"62.69400","5.22471","0.00406"
"62.95200","5.24617","0.00382"
"63.21000","5.26770","0.00362"
"63.46800","5.28916","0.00388"
"63.72600","5.31069","0.00367"
"63.98400","5.33209","0.00391"
"64.24200","5.35373","0.00408"
"64.50000","5.37514","0.00403"
"64.75800","5.39672","0.00382"
"65.01600","5.41819","0.00407"
"65.27400","5.43971","0.00371"
"65.53200","5.46112","0.00380"
"65.79000","5.48270","0.00374"
"66.04800","5.50416","0.00409"
"66.30600","5.52569","0.00410"
"66.56400","5.54721","0.00382"
"66.82200","5.56868","0.00421"
"67.08000","5.59020","0.00379"
"67.33800","5.61173","0.00392"
"67.59600","5.63325","0.00416"
"67.85400","5.65472","0.00360"
"68.11200","5.67618","0.00363"
"68.37000","5.69764","0.00373"
"68.62800","5.71923","0.00383"
"68.88600","5.74069","0.00334"
"69.14400","5.76222","0.00393"
"69.40200","5.78362","0.00375"
"69.66000","5.80520","0.00408"
"69.91800","5.82667","0.00389"
"70.17600","5.84825","0.00411"
"70.43400","5.86966","0.00364"
"70.69200","5.89118","0.00313"
"70.95000","5.91265","0.00344"
"71.20800","5.93423","0.00321"
"71.46600","5.95564","0.00316"
"71.72400","5.97722","0.00338"
"71.98200","5.99868","0.00334"
"72.24000","6.02021","0.00327"
"72.49800","6.04167","0.00319"
"72.75600","6.06326","0.00313"
"73.01400","6.08466","0.00326"
"73.27200","6.10619","0.00322"
"73.53000","6.12771","0.00364"
"73.78800","6.14923","0.00343"
"74.04600","6.17070","0.00317"
"74.30400","6.19216","0.00308"
"74.56200","6.21369","0.00321"
"74.82000","6.23521","0.00333"
"75.07800","6.25674","0.00350"
"75.33600","6.27820","0.00378"
"75.59400","6.29972","0.00372"
"75.85200","6.32119","0.00343"
"76.11000","6.34271","0.00335"
"76.36800","6.36418","0.00306"
"76.62600","6.38576","0.00329"
"76.88400","6.40717","0.00309"
"77.14200","6.42869","0.00323"
"77.40000","6.45010","0.00340"
"77.65800","6.47174","0.00314"
"77.91600","6.49320","0.00345"
"78.17400","6.51473","0.00341"
"78.43200","6.53613","0.00363"
"78.69000","6.55772","0.00390"
"78.94800","6.57918","0.00357"
"79.20600","6.60070","0.00330"
"79.46400","6.62217","0.00314"
"79.72200","6.64369","0.00390"
"79.98000","6.66516","0.00375"
"80.23800","6.68668","0.00330"
"80.49600","6.70827","0.00328"
"80.75400","6.72967","0.00359"
"81.01200","6.75119","0.00356"
"81.27000","6.77266","0.00351"
"81.52800","6.79424","0.00423"
"81.78600","6.81571","0.00389"
"82.04400","6.83723","0.00338"
"82.30200","6.85864","0.00340"
"82.56000","6.88022","0.00332"
"82.81800","6.90163","0.00342"
"83.07600","6.92321","0.00388"
"83.33400","6.94467","0.00352"
"83.59200","6.96620","0.00339"
"83.85000","6.98766","0.00364"
"84.10800","7.00925","0.00375"
"84.36600","7.03065","0.00316"
"84.62400","7.05224","0.00386"
"84.88200","7.07370","0.00344"
"85.14000","7.09522","0.00326"
"85.39800","7.11669","0.00356"
"85.65600","7.13821","0.00376"
"85.91400","7.15968","0.00352"
"86.17200","7.18120","0.00312"
"86.43000","7.20273","0.00351"
"86.68800","7.22419","0.00311"
"86.94600","7.24565","0.00326"
"87.20400","7.26718","0.00351"
"87.46200","7.28870","0.00314"
"87.72000","7.31017","0.00340"
"87.97800","7.33169","0.00364"
"88.23600","7.35316","0.00346"
"88.49400","7.37468","0.00359"
"88.75200","7.39614","0.00397"
"89.01000","7.41767","0.00323"
"89.26800","7.43913","0.00313"
"89.52600","7.46072","0.00342"
"89.78400","7.48212","0.00349"
"90.04200","7.50371","0.00340"
"90.30000","7.52517","0.00318"
"90.55800","7.54675","0.00352"
"90.81600","7.56816","0.00334"
"91.07400","7.58974","0.00321"
"91.33200","7.61115","0.00310"
"91.59000","7.63273","0.00367"
"91.84800","7.65420","0.00342"
"92.10600","7.67566","0.00365"
"92.36400","7.69719","0.00369"
"92.62200","7.71871","0.00397"
"92.88000","7.74023","0.00326"
"93.13800","7.76170","0.00344"
"93.39600","7.78322","0.00370"
"93.65400","7.80463","0.00382"
"93.91200","7.82621","0.00361"
"94.17000","7.84768","0.00350"
"94.42800","7.86926","0.00351"
"94.68600","7.89066","0.00344"
"94.94400","7.91219","0.00356"
"95.20200","7.93365","0.00365"
"95.46000","7.95524","0.00361"
"95.71800","7.97670","0.00318"
"95.97600","7.99823","0.00346"
"96.23400","8.01963","0.00367"
"96.49200","8.04121","0.00348"
"96.75000","8.06268","0.00360"
"97.00800","8.08426","0.00322"
"97.26600","8.10567","0.00380"
"97.52400","8.12719","0.00316"
"97.78200","8.14865","0.00328"
"98.04000","8.17024","0.00341"
"98.29800","8.19170","0.00317"
"98.55600","8.21323","0.00321"
"98.81400","8.23463","0.00343"
"99.07200","8.25616","0.00290"
"99.33000","8.27774","0.00313"
"99.58800","8.29921","0.00303"
"99.84600","8.32073","0.00297"
"100.10400","8.34219","0.00315"
"100.36200","8.36372","0.00324"
"100.62000","8.38518","0.00367"
"100.87800","8.40677","0.00344"
"101.13600","8.42811","0.00344"
"101.39400","8.44970","0.00330"
"101.65200","8.47110","0.00337"
"101.91000","8.49274","0.00307"
"102.16800","8.51415","0.00358"
"102.42600","8.53567","0.00325"
"102.68400","8.55714","0.00350"
"102.94200","8.57872","0.00308"
"103.20000","8.60019","0.00354"
"103.45800","8.62171","0.00321"
"103.71600","8.64317","0.00356"
"103.97400","8.66470","0.00318"
"104.23200","8.68622","0.00335"
"104.49000","8.70769","0.00302"
"104.74800","8.72921","0.00331"
"105.00600","8.75068","0.00331"
"105.26400","8.77220","0.00358"
"105.52200","8.79366","0.00301"
"105.78000","8.81519","0.00352"
"106.03800","8.83671","0.00329"
"106.29600","8.85824","0.00318"
"106.55400","8.87964","0.00314"
"106.81200","8.90117","0.00346"
"107.07000","8.92269","0.00354"
"107.32800","8.94421","0.00335"
"107.58600","8.96562","0.00356"
"107.84400","8.98720","0.00349"
"108.10200","9.00867","0.00338"
"108.36000","9.03019","0.00348"
"108.61800","9.05166","0.00319"
"108.87600","9.07324","0.00340"
"109.13400","9.09465","0.00365"
"109.39200","9.11623","0.00329"
"109.65000","9.13769","0.00340"
"109.90800","9.15922","0.00340"
"110.16600","9.18062","0.00344"
"110.42400","9.20221","0.00311"
"110.68200","9.22367","0.00310"
"110.94000","9.24520","0.00327"
"111.19800","9.26672","0.00352"
"111.45600","9.28818","0.00337"
"111.71400","9.30977","0.00313"
"111.97200","9.33117","0.00367"
"112.23000","9.35270","0.00349"
"112.48800","9.37416","0.00330"
"112.74600","9.39569","0.00332"
"113.00400","9.41721","0.00329"
"113.26200","9.43873","0.00243"
"113.52000","9.46020","0.00295"
"113.77800","9.48172","0.00256"
"114.03600","9.50313","0.00309"
"114.29400","9.52465","0.00287"
"114.55200","9.54618","0.00258"
"114.81000","9.56776","0.00306"
"115.06800","9.58916","0.00302"
"115.32600","9.61069","0.00288"
"115.58400","9.63215","0.00300"
"115.84200","9.65374","0.00261"
"116.10000","9.67520","0.00264"
"116.35800","9.69673","0.00315"
"116.61600","9.71813","0.00303"
"116.87400","9.73971","0.00269"
"117.13200","9.76118","0.00281"
"117.39000","9.78270","0.00273"
"117.64800","9.80423","0.00282"
"117.90600","9.82569","0.00312"
"118.16400","9.84716","0.00304"
"118.42200","9.86868","0.00293"
"118.68000","9.89026","0.00315"
"118.93800","9.91167","0.00279"
"119.19600","9.93325","0.00274"
"119.45400","9.95472","0.00279"
"119.71200","9.97624","0.00349"
"119.97000","9.99771","0.00301"
"120.22800","10.01923","0.00296"
"120.48600","10.04064","0.00304"
"120.74400","10.06222","0.00305"
"121.00200","10.08368","0.00329"
"121.26000","10.10527","0.00311"
"121.51800","10.12667","0.00298"
"121.77600","10.14820","0.00289"
"122.03400","10.16966","0.00297"
"122.29200","10.19125","0.00316"
"122.55000","10.21271","0.00283"
"122.80800","10.23417","0.00279"
"123.06600","10.25564","0.00267"
"123.32400","10.27722","0.00249"
"123.58200","10.29869","0.00284"
"123.84000","10.32021","0.00313"
"124.09800","10.34168","0.00319"
"124.35600","10.36320","0.00318"
"124.61400","10.38472","0.00301"
"124.87200","10.40619","0.00324"
"125.13000","10.42771","0.00344"
"125.38800","10.44918","0.00286"
"125.64600","10.47070","0.00317"
"125.90400","10.49217","0.00288"
"126.16200","10.51369","0.00326"
"126.42000","10.53515","0.00310"
"126.67800","10.55674","0.00307"
"126.93600","10.57814","0.00295"
"127.19400","10.59973","0.00270"
"127.45200","10.62113","0.00297"
"127.71000","10.64278","0.00272"
"127.96800","10.66418","0.00262"
"128.22600","10.68571","0.00267"
"128.48400","10.70723","0.00239"
"128.74200","10.72875","0.00297"
"129.00000","10.75022","0.00269"
"129.25800","10.77168","0.00309"
"129.51600","10.79321","0.00270"
"129.77400","10.81473","0.00286"
"130.03200","10.83626","0.00237"
"130.29000","10.85772","0.00268"
"130.54800","10.87918","0.00283"
"130.80600","10.90071","0.00258"
"131.06400","10.92217","0.00285"
"131.32200","10.94370","0.00284"
"131.58000","10.96522","0.00280"
"131.83800","10.98669","0.00287"
"132.09600","11.00821","0.00279"
"132.35400","11.02967","0.00255"
"132.61200","11.05120","0.00279"
"132.87000","11.07266","0.00289"
"133.12800","11.09419","0.00307"
"133.38600","11.11559","0.00290"
"133.64400","11.13718","0.00307"
"133.90200","11.15870","0.00297"
"134.16000","11.18028","0.00258"
"134.41800","11.20169","0.00291"
"134.67600","11.22321","0.00283"
"134.93400","11.24468","0.00280"
"135.19200","11.26626","0.00319"
"135.45000","11.28767","0.00264"
"135.70800","11.30919","0.00278"
"135.96600","11.33071","0.00262"
"136.22400","11.35218","0.00298"
"136.48200","11.37370","0.00263"
"136.74000","11.39517","0.00293"
"136.99800","11.41669","0.00265"
"137.25600","11.43816","0.00286"
"137.51400","11.45974","0.00340"
"137.77200","11.48115","0.00264"
"138.03000","11.50273","0.00246"
"138.28800","11.52413","0.00283"
"138.54600","11.54572","0.00344"
"138.80400","11.56718","0.00273"
"139.06200","11.58871","0.00371"
"139.32000","11.61017","0.00389"
"139.57800","11.63170","0.00287"
"139.83600","11.65316","0.00298"
"140.09400","11.67468","0.00339"
"140.35200","11.69615","0.00298"
"140.61000","11.71773","0.00311"
"140.86800","11.73914","0.00316"
"141.12600","11.76072","0.00322"
"141.38400","11.78219","0.00311"
"141.64200","11.80377","0.00310"
"141.90000","11.82517","0.00313"
"142.15800","11.84670","0.00279"
"142.41600","11.86822","0.00308"
"142.67400","11.88975","0.00319"
"142.93200","11.91127","0.00319"
"143.19000","11.93267","0.00305"
"143.44800","11.95420","0.00322"
"143.70600","11.97566","0.00311"
"143.96400","11.99719","0.00325"
"144.22200","12.01865","0.00305"
"144.48000","12.04024","0.00299"
"144.73800","12.06164","0.00291"
"144.99600","12.08323","0.00305"
"145.25400","12.10469","0.00297"
"145.51200","12.12621","0.00341"
"145.77000","12.14768","0.00277"
"146.02800","12.16914","0.00288"
"146.28600","12.19067","0.00285"
"146.54400","12.21225","0.00266"
"146.80200","12.23366","0.00291"
"147.06000","12.25524","0.00303"
"147.31800","12.27670","0.00260"
"147.57600","12.29823","0.00276"
"147.83400","12.31969","0.00266"
"148.09200","12.34128","0.00302"
"148.35000","12.36268","0.00303"
"148.60800","12.38415","0.00307"
"148.86600","12.40567","0.00337"
"149.12400","12.42719","0.00294"
"149.38200","12.44872","0.00323"
"149.64000","12.47018","0.00283"
"149.89800","12.49165","0.00271"
"150.15600","12.51311","0.00290"
"150.41400","12.53470","0.00337"
"150.67200","12.55622","0.00290"
"150.93000","12.57774","0.00309"
"151.18800","12.59915","0.00276"
"151.44600","12.62073","0.00286"
"151.70400","12.64214","0.00297"
"151.96200","12.66378","0.00304"
"152.22000","12.68519","0.00328"
"152.47800","12.70665","0.00292"
"152.73600","12.72812","0.00298"
"152.99400","12.74970","0.00306"
"153.25200","12.77116","0.00270"
"153.51000","12.79275","0.00346"
"153.76800","12.81415","0.00315"
"154.02600","12.83574","0.00293"
"154.28400","12.85726","0.00346"
"154.54200","12.87873","0.00291"
"154.80000","12.90019","0.00318"
"155.05800","12.92171","0.00337"
"155.31600","12.94318","0.00311"
"155.57400","12.96464","0.00341"
"155.83200","12.98617","0.00314"
"156.09000","13.00763","0.00283"
"156.34800","13.02916","0.00310"
"156.60600","13.05068","0.00308"
"156.86400","13.07215","0.00340"
"157.12200","13.09367","0.00347"
"157.38000","13.11519","0.00327"
"157.63800","13.13666","0.00276"
"157.89600","13.15818","0.00313"
"158.15400","13.17971","0.00278"
"158.41200","13.20123","0.00311"
"158.67000","13.22263","0.00305"
"158.92800","13.24416","0.00296"
"159.18600","13.26562","0.00308"
"159.44400","13.28721","0.00318"
"159.70200","13.30867","0.00291"
"159.96000","13.33026","0.00318"
"160.21800","13.35166","0.00344"
"160.47600","13.37324","0.00326"
"160.73400","13.39471","0.00312"
"160.99200","13.41617","0.00325"
"161.25000","13.43770","0.00264"
"161.50800","13.45916","0.00365"
"161.76600","13.48069","0.00327"
"162.02400","13.50221","0.00314"
"162.28200","13.52374","0.00312"
"162.54000","13.54514","0.00309"
"162.79800","13.56672","0.00314"
"163.05600","13.58819","0.00332"
"163.31400","13.60971","0.00304"
"163.57200","13.63118","0.00368"
"163.83000","13.65264","0.00342"
"164.08800","13.67417","0.00302"
"164.34600","13.69575","0.00392"
"164.60400","13.71715","0.00313"
"164.86200","13.73874","0.00334"
"165.12000","13.76020","0.00359"
"165.37800","13.78167","0.00353"
"165.63600","13.80319","0.00360"
"165.89400","13.82472","0.00307"
"166.15200","13.84618","0.00350"
"166.41000","13.86770","0.00339"
"166.66800","13.88917","0.00314"
"166.92600","13.91075","0.00314"
"167.18400","13.93222","0.00314"
"167.44200","13.95374","0.00353"
"167.70000","13.97515","0.00297"
"167.95800","13.99667","0.00345"
"168.21600","14.01819","0.00309"
"168.47400","14.03966","0.00357"
"168.73200","14.06118","0.00347"
"168.99000","14.08265","0.00341"
"169.24800","14.10417","0.00317"
"169.50600","14.12564","0.00291"
"169.76400","14.14722","0.00332"
"170.02200","14.16862","0.00318"
"170.28000","14.19021","0.00338"
"170.53800","14.21161","0.00272"
"170.79600","14.23326","0.00328"
"171.05400","14.25472","0.00347"
"171.31200","14.27625","0.00305"
"171.57000","14.29765","0.00342"
"171.82800","14.31918","0.00306"
"172.08600","14.34070","0.00312"
"172.34400","14.36222","0.00328"
"172.60200","14.38369","0.00337"
"172.86000","14.40521","0.00306"
"173.11800","14.42668","0.00385"
"173.37600","14.44820","0.00324"
"173.63400","14.46972","0.00365"
"173.89200","14.49119","0.00337"
"174.15000","14.51265","0.00293"
"174.40800","14.53424","0.00308"
"174.66600","14.55570","0.00291"
"174.92400","14.57723","0.00348"
"175.18200","14.59869","0.00327"
"175.44000","14.62016","0.00328"
"175.69800","14.64174","0.00319"
"175.95600","14.66314","0.00331"
"176.21400","14.68467","0.00353"
"176.47200","14.70613","0.00325"
"176.73000","14.72766","0.00314"
"176.98800","14.74912","0.00327"
"177.24600","14.77071","0.00372"
"177.50400","14.79217","0.00330"
"177.76200","14.81369","0.00350"
"178.02000","14.83516","0.00359"
"178.27800","14.85674","0.00369"
"178.53600","14.87809","0.00338"
"178.79400","14.89979","0.00330"
"179.05200","14.92120","0.00332"
"179.31000","14.94272","0.00348"
"179.56800","14.96418","0.00343"
"179.82600","14.98571","0.00361"
"180.08400","15.00717","0.00345"
"180.34200","15.02870","0.00373"
"180.60000","15.05022","0.00328"
"180.85800","15.07169","0.00341"
"181.11600","15.09321","0.00334"
"181.37400","15.11468","0.00339"
"181.63200","15.13620","0.00342"
"181.89000","15.15766","0.00376"
"182.14800","15.17925","0.00352"
"182.40600","15.20071","0.00384"
"182.66400","15.22224","0.00358"
"182.92200","15.24364","0.00347"
"183.18000","15.26517","0.00387"
"183.43800","15.28669","0.00403"
"183.69600","15.30821","0.00377"
"183.95400","15.32962","0.00356"
"184.21200","15.35120","0.00386"
"184.47000","15.37261","0.00369"
"184.72800","15.39419","0.00378"
"184.98600","15.41566","0.00383"
"185.24400","15.43718","0.00345"
"185.50200","15.45870","0.00392"
"185.76000","15.48023","0.00379"
"186.01800","15.50169","0.00390"
"186.27600","15.52322","0.00429"
"186.53400","15.54474","0.00368"
"186.79200","15.56614","0.00368"
"187.05000","15.58767","0.00405"
"187.30800","15.60913","0.00375"
"187.56600","15.63072","0.00387"
"187.82400","15.65218","0.00369"
"188.08200","15.67371","0.00382"
"188.34000","15.69517","0.00395"
"188.59800","15.71669","0.00391"
"188.85600","15.73816","0.00393"
"189.11400","15.75968","0.00367"
"189.37200","15.78109","0.00352"
"189.63000","15.80273","0.00372"
"189.88800","15.82420","0.00372"
"190.14600","15.84578","0.00366"
"190.40400","15.86718","0.00415"
"190.66200","15.88871","0.00382"
"190.92000","15.91017","0.00382"
"191.17800","15.93176","0.00368"
"191.43600","15.95316","0.00386"
"191.69400","15.97469","0.00418"
"191.95200","15.99615","0.00363"
"192.21000","16.01768","0.00375"
"192.46800","16.03920","0.00368"
"192.72600","16.06072","0.00381"
"192.98400","16.08219","0.00369"
"193.24200","16.10371","0.00415"
"193.50000","16.12518","0.00380"
"193.75800","16.14664","0.00411"
"194.01600","16.16823","0.00401"
"194.27400","16.18969","0.00389"
"194.53200","16.21121","0.00418"
"194.79000","16.23262","0.00407"
"195.04800","16.25420","0.00411"
"195.30600","16.27573","0.00381"
"195.56400","16.29719","0.00414"
"195.82200","16.31860","0.00389"
"196.08000","16.34018","0.00387"
"196.33800","16.36164","0.00439"
"196.59600","16.38323","0.00397"
"196.85400","16.40469","0.00420"
"197.11200","16.42622","0.00458"
"197.37000","16.44774","0.00424"
"197.62800","16.46921","0.00431"
"197.88600","16.49073","0.00412"
"198.14400","16.51220","0.00409"
"198.40200","16.53372","0.00416"
"198.66000","16.55518","0.00420"
"198.91800","16.57671","0.00379"
"199.17600","16.59817","0.00408"
"199.43400","16.61970","0.00375"
"199.69200","16.64116","0.00457"
"199.95000","16.66263","0.00429"
"200.20800","16.68415","0.00416"
"200.46600","16.70567","0.00400"
"200.72400","16.72720","0.00448"
"200.98200","16.74872","0.00428"
"201.24000","16.77019","0.00413"
"201.49800","16.79177","0.00425"
"201.75600","16.81318","0.00409"
"202.01400","16.83470","0.00470"
"202.27200","16.85610","0.00390"
"202.53000","16.87769","0.00468"
"202.78800","16.89915","0.00437"
"203.04600","16.92080","0.00425"
"203.30400","16.94214","0.00450"
"203.56200","16.96367","0.00459"
"203.82000","16.98519","0.00446"
"204.07800","17.00671","0.00446"
"204.33600","17.02818","0.00431"
"204.59400","17.04970","0.00427"
"204.85200","17.07117","0.00454"
"205.11000","17.09269","0.00492"
"205.36800","17.11422","0.00475"
"205.62600","17.13574","0.00430"
"205.88400","17.15720","0.00469"
"206.14200","17.17867","0.00431"
"206.40000","17.20019","0.00488"
"206.65800","17.22172","0.00442"
"206.91600","17.24324","0.00432"
"207.17400","17.26464","0.00452"
"207.43200","17.28617","0.00448"
"207.69000","17.30764","0.00461"
"207.94800","17.32916","0.00467"
"208.20600","17.35068","0.00451"
"208.46400","17.37221","0.00435"
"208.72200","17.39367","0.00483"
"208.98000","17.41520","0.00459"
"209.23800","17.43666","0.00496"
"209.49600","17.45824","0.00439"
"209.75400","17.47965","0.00460"
"210.01200","17.50123","0.00497"
"210.27000","17.52270","0.00492"
"210.52800","17.54428","0.00477"
"210.78600","17.56569","0.00465"
"211.04400","17.58715","0.00420"
"211.30200","17.60868","0.00454"
"211.56000","17.63020","0.00454"
"211.81800","17.65172","0.00467"
"212.07600","17.67319","0.00488"
"212.33400","17.69465","0.00464"
"212.59200","17.71624","0.00483"
"212.85000","17.73770","0.00495"
"213.10800","17.75916","0.00498"
"213.36600","17.78075","0.00448"
"213.62400","17.80215","0.00440"
"213.88200","17.82374","0.00465"
"214.14000","17.84514","0.00455"
"214.39800","17.86673","0.00481"
"214.65600","17.88819","0.00506"
"214.91400","17.90965","0.00473"
"215.17200","17.93112","0.00498"
"215.43000","17.95264","0.00516"
"215.68800","17.97417","0.00492"
"215.94600","17.99575","0.00494"
"216.20400","18.01722","0.00528"
"216.46200","18.03874","0.00506"
"216.72000","18.06021","0.00482"
"216.97800","18.08173","0.00462"
"217.23600","18.10313","0.00513"
"217.49400","18.12472","0.00516"
"217.75200","18.14618","0.00499"
"218.01000","18.16771","0.00530"
"218.26800","18.18923","0.00513"
"218.52600","18.21076","0.00499"
"218.78400","18.23216","0.00475"
"219.04200","18.25368","0.00518"
"219.30000","18.27521","0.00498"
"219.55800","18.29667","0.00499"
"219.81600","18.31826","0.00510"
"220.07400","18.33966","0.00505"
"220.33200","18.36119","0.00546"
"220.59000","18.38259","0.00502"
"220.84800","18.40429","0.00519"
"221.10600","18.42564","0.00500"
"221.36400","18.44722","0.00562"
"221.62200","18.46863","0.00530"
"221.88000","18.49021","0.00487"
"222.13800","18.51168","0.00540"
"222.39600","18.53326","0.00491"
"222.65400","18.55466","0.00509"
"222.91200","18.57619","0.00500"
"223.17000","18.59765","0.00560"
"223.42800","18.61924","0.00535"
"223.68600","18.64070","0.00552"
"223.94400","18.66223","0.00546"
"224.20200","18.68369","0.00537"
"224.46000","18.70522","0.00552"
"224.71800","18.72674","0.00561"
"224.97600","18.74820","0.00546"
"225.23400","18.76973","0.00593"
"225.49200","18.79119","0.00574"
"225.75000","18.81272","0.00596"
"226.00800","18.83418","0.00519"
"226.26600","18.85571","0.00594"
"226.52400","18.87711","0.00540"
"226.78200","18.89869","0.00579"
"227.04000","18.92016","0.00572"
"227.29800","18.94174","0.00585"
"227.55600","18.96315","0.00531"
"227.81400","18.98467","0.00583"
"228.07200","19.00614","0.00583"
"228.33000","19.02772","0.00574"
"228.58800","19.04918","0.00568"
"228.84600","19.07077","0.00616"
"229.10400","19.09217","0.00595"
"229.36200","19.11376","0.00625"
"229.62000","19.13516","0.00554"
"229.87800","19.15669","0.00589"
"230.13600","19.17815","0.00617"
"230.39400","19.19967","0.00640"
"230.65200","19.22120","0.00631"
"230.91000","19.24272","0.00595"
"231.16800","19.26425","0.00626"
"231.42600","19.28565","0.00619"
"231.68400","19.30718","0.00678"
"231.94200","19.32864","0.00639"
"232.20000","19.35023","0.00616"
"232.45800","19.37169","0.00607"
"232.71600","19.39321","0.00658"
"232.97400","19.41468","0.00606"
"233.23200","19.43620","0.00624"
"233.49000","19.45767","0.00648"
"233.74800","19.47925","0.00651"
"234.00600","19.50066","0.00631"
"234.26400","19.52218","0.00625"
"234.52200","19.54364","0.00647"
"234.78000","19.56523","0.00672"
"235.03800","19.58669","0.00604"
"235.29600","19.60816","0.00652"
"235.55400","19.62968","0.00693"
"235.81200","19.65126","0.00710"
"236.07000","19.67273","0.00644"
"236.32800","19.69419","0.00682"
"236.58600","19.71566","0.00646"
"236.84400","19.73724","0.00689"
"237.10200","19.75871","0.00720"
"237.36000","19.78023","0.00706"
"237.61800","19.80175","0.00701"
"237.87600","19.82316","0.00678"
"238.13400","19.84474","0.00713"
"238.39200","19.86615","0.00763"
"238.65000","19.88773","0.00698"
"238.90800","19.90920","0.00724"
"239.16600","19.93072","0.00743"
"239.42400","19.95213","0.00747"
"239.68200","19.97371","0.00720"
"239.94000","19.99517","0.00762"
"240.19800","20.01670","0.00698"
"240.45600","20.03816","0.00722"
"240.71400","20.05963","0.00757"
"240.97200","20.08115","0.00738"
"241.23000","20.10274","0.00796"
"241.48800","20.12420","0.00730"
"241.74600","20.14573","0.00739"
"242.00400","20.16719","0.00727"
"242.26200","20.18871","0.00765"
"242.52000","20.21024","0.00796"
"242.77800","20.23170","0.00785"
"243.03600","20.25317","0.00771"
"243.29400","20.27469","0.00784"
"243.55200","20.29615","0.00825"
"243.81000","20.31774","0.00806"
"244.06800","20.33920","0.00808"
"244.32600","20.36067","0.00832"
"244.58400","20.38225","0.00839"
"244.84200","20.40366","0.00807"
"245.10000","20.42524","0.00760"
"245.35800","20.44665","0.00857"
"245.61600","20.46823","0.00866"
"245.87400","20.48964","0.00865"
"246.13200","20.51122","0.00818"
"246.39000","20.53268","0.00857"
"246.64800","20.55421","0.00867"
"246.90600","20.57561","0.00849"
"247.16400","20.59719","0.00829"
"247.42200","20.61866","0.00886"
"247.68000","20.64024","0.00839"
"247.93800","20.66171","0.00886"
"248.19600","20.68317","0.00925"
"248.45400","20.70470","0.00888"
"248.71200","20.72622","0.00907"
"248.97000","20.74775","0.00856"
"249.22800","20.76921","0.00894"
"249.48600","20.79067","0.00917"
"249.74400","20.81220","0.00911"
"250.00200","20.83372","0.00947"
"250.26000","20.85518","0.00935"
"250.51800","20.87671","0.00930"
"250.77600","20.89812","0.00956"
"251.03400","20.91970","0.00939"
"251.29200","20.94116","0.00947"
"251.55000","20.96269","0.01003"
"251.80800","20.98415","0.00933"
"252.06600","21.00574","0.00956"
"252.32400","21.02714","0.00961"
"252.58200","21.04866","0.00988"
"252.84000","21.07019","0.00981"
"253.09800","21.09171","0.00987"
"253.35600","21.11318","0.00991"
"253.61400","21.13476","0.01003"
"253.87200","21.15617","0.01003"
"254.13000","21.17775","0.00982"
"254.38800","21.19916","0.01001"
"254.64600","21.22068","0.01020"
"254.90400","21.24215","0.01009"
"255.16200","21.26373","0.01029"
"255.42000","21.28526","0.00955"
"255.67800","21.30672","0.01027"
"255.93600","21.32818","0.00991"
"256.19400","21.34965","0.00995"
"256.45200","21.37123","0.01002"
"256.71000","21.39270","0.00994"
"256.96800","21.41422","0.00937"
"257.22600","21.43568","0.00966"
"257.48400","21.45721","0.00884"
"257.74200","21.47867","0.00951"
"258.00000","21.50020","0.00955"
"258.25800","21.52160","0.00951"
"258.51600","21.54319","0.00949"
"258.77400","21.56465","0.00959"
"259.03200","21.58623","0.00951"
"259.29000","21.60770","0.00993"
"259.54800","21.62922","0.00983"
"259.80600","21.65069","0.00980"
"260.06400","21.67215","0.00932"
"260.32200","21.69368","0.00967"
"260.58000","21.71520","0.00961"
"260.83800","21.73666","0.00998"
"261.09600","21.75819","0.00983"
"261.35400","21.77971","0.01014"
"261.61200","21.80124","0.01006"
"261.87000","21.82270","0.01020"
"262.12800","21.84416","0.01030"
"262.38600","21.86563","0.01064"
"262.64400","21.88715","0.01045"
"262.90200","21.90874","0.01067"
"263.16000","21.93020","0.01052"
"263.41800","21.95173","0.01139"
"263.67600","21.97313","0.01041"
"263.93400","21.99471","0.01076"
"264.19200","22.01618","0.01056"
"264.45000","22.03777","0.01054"
"264.70800","22.05911","0.01105"
"264.96600","22.08069","0.01105"
"265.22400","22.10216","0.01087"
"265.48200","22.12368","0.01096"
"265.74000","22.14520","0.01120"
"265.99800","22.16667","0.01132"
"266.25600","22.18814","0.01154"
"266.51400","22.20972","0.01158"
"266.77200","22.23118","0.01124"
"267.03000","22.25277","0.01177"
"267.28800","22.27417","0.01161"
"267.54600","22.29570","0.01156"
"267.80400","22.31716","0.01198"
"268.06200","22.33875","0.01222"
"268.32000","22.36021","0.01224"
"268.57800","22.38167","0.01209"
"268.83600","22.40320","0.01181"
"269.09400","22.42466","0.01212"
"269.35200","22.44619","0.01205"
"269.61000","22.46771","0.00135"
"269.86800","22.48918","0.00279"
"270.12600","22.51064","0.00218"
"270.38400","22.53222","0.00227"
"270.64200","22.55363","0.00143"
"270.90000","22.57521","0.00187"
"271.15800","22.59662","0.00172"
"271.41600","22.61820","0.00197"
"271.67400","22.63961","0.00175"
"271.93200","22.66125","0.00161"
"272.19000","22.68266","0.00164"
"272.44800","22.70418","0.00230"
"272.70600","22.72570","0.00199"
"272.96400","22.74723","0.00186"
"273.22200","22.76863","0.00168"
"273.48000","22.79022","0.00203"
"273.73800","22.81168","0.00210"
"273.99600","22.83321","0.00200"
"274.25400","22.85473","0.00211"
"274.51200","22.87619","0.00152"
"274.77000","22.89766","0.00151"
"275.02800","22.91912","0.00223"
"275.28600","22.94071","0.00207"
"275.54400","22.96217","0.00196"
"275.80200","22.98375","0.00187"
"276.06000","23.00516","0.00217"
"276.31800","23.02668","0.00209"
"276.57600","23.04820","0.00199"
"276.83400","23.06973","0.00181"
"277.09200","23.09120","0.00169"
"277.35000","23.11272","0.00154"
"277.60800","23.13412","0.00217"
"277.86600","23.15571","0.00216"
"278.12400","23.17718","0.00196"
"278.38200","23.19870","0.00169"
"278.64000","23.22016","0.00119"
"278.89800","23.24169","0.00186"
"279.15600","23.26315","0.00231"
"279.41400","23.28473","0.00192"
"279.67200","23.30620","0.00206"
"279.93000","23.32772","0.00178"
"280.18800","23.34913","0.00205"
"280.44600","23.37071","0.00153"
"280.70400","23.39218","0.00194"
"280.96200","23.41370","0.00202"
"281.22000","23.43517","0.00190"
"281.47800","23.45663","0.00161"
"281.73600","23.47821","0.00171"
"281.99400","23.49968","0.00192"
"282.25200","23.52120","0.00210"
"282.51000","23.54267","0.00176"
"282.76800","23.56419","0.00185"
"283.02600","23.58566","0.00206"
"283.28400","23.60724","0.00211"
"283.54200","23.62870","0.00210"
"283.80000","23.65017","0.00181"
"284.05800","23.67163","0.00207"
"284.31600","23.69322","0.00217"
"284.57400","23.71468","0.00194"
"284.83200","23.73621","0.00178"
"285.09000","23.75767","0.00209"
"285.34800","23.77919","0.00202"
"285.60600","23.80066","0.00208"
"285.86400","23.82218","0.00208"
"286.12200","23.84365","0.00196"
"286.38000","23.86523","0.00200"
"286.63800","23.88670","0.00144"
"286.89600","23.90816","0.00224"
"287.15400","23.92968","0.00181"
"287.41200","23.95121","0.00198"
"287.67000","23.97267","0.00165"
"287.92800","23.99420","0.00183"
"288.18600","24.01566","0.00210"
"288.44400","24.03718","0.00209"
"288.70200","24.05871","0.00207"
"288.96000","24.08017","0.00201"
"289.21800","24.10176","0.00162"
"289.47600","24.12316","0.00195"
"289.73400","24.14469","0.00218"
"289.99200","24.16615","0.00217"
"290.25000","24.18768","0.00160"
"290.50800","24.20908","0.00172"
"290.76600","24.23067","0.00191"
"291.02400","24.25219","0.00229"
"291.28200","24.27371","0.00186"
"291.54000","24.29518","0.00196"
"291.79800","24.31670","0.00217"
"292.05600","24.33817","0.00188"
"292.31400","24.35969","0.00232"
"292.57200","24.38121","0.00214"
"292.83000","24.40268","0.00232"
"293.08800","24.42420","0.00151"
"293.34600","24.44567","0.00172"
"293.60400","24.46719","0.00202"
"293.86200","24.48866","0.00192"
"294.12000","24.51018","0.00213"
"294.37800","24.53164","0.00177"
"294.63600","24.55317","0.00190"
"294.89400","24.57470","0.00159"
"295.15200","24.59622","0.00204"
"295.41000","24.61762","0.00186"
"295.66800","24.63921","0.00188"
"295.92600","24.66061","0.00194"
"296.18400","24.68219","0.00140"
"296.44200","24.70366","0.00174"
"296.70000","24.72518","0.00182"
"296.95800","24.74665","0.00189"
"297.21600","24.76823","0.00185"
"297.47400","24.78970","0.00217"
"297.73200","24.81122","0.00163"
"297.99000","24.83263","0.00203"
"298.24800","24.85421","0.00175"
"298.50600","24.87568","0.00172"
"298.76400","24.89720","0.00213"
"299.02200","24.91866","0.00197"
"299.28000","24.94019","0.00151"
"299.53800","24.96165","0.00152"
"299.79600","24.98318","0.00183"
"300.05400","25.00470","0.00178"
"300.31200","25.02617","0.00196"
"300.57000","25.04769","0.00159"
"300.82800","25.06915","0.00236"
"301.08600","25.09074","0.00203"
"301.34400","25.11214","0.00165"
"301.60200","25.13373","0.00171"
"301.86000","25.15513","0.00193"
"302.11800","25.17671","0.00167"
"302.37600","25.19818","0.00186"
"302.63400","25.21976","0.00178"
"302.89200","25.24117","0.00177"
"303.15000","25.26263","0.00190"
"303.40800","25.28416","0.00210"
"303.66600","25.30574","0.00148"
"303.92400","25.32721","0.00193"
"304.18200","25.34873","0.00197"
"304.44000","25.37013","0.00235"
"304.69800","25.39178","0.00184"
"304.95600","25.41318","0.00172"
"305.21400","25.43471","0.00186"
"305.47200","25.45623","0.00193"
"305.73000","25.47770","0.00190"
"305.98800","25.49922","0.00169"
"306.24600","25.52074","0.00169"
"306.50400","25.54221","0.00187"
"306.76200","25.56367","0.00170"
"307.02000","25.58520","0.00168"
"307.27800","25.60666","0.00196"
"307.53600","25.62825","0.00172"
"307.79400","25.64971","0.00191"
"308.05200","25.67123","0.00173"
"308.31000","25.69264","0.00162"
"308.56800","25.71422","0.00223"
"308.82600","25.73563","0.00177"
"309.08400","25.75721","0.00179"
"309.34200","25.77868","0.00168"
"309.60000","25.80014","0.00200"
"309.85800","25.82166","0.00166"
"310.11600","25.84319","0.00177"
"310.37400","25.86471","0.00158"
"310.63200","25.88618","0.00193"
"310.89000","25.90770","0.00199"
"311.14800","25.92917","0.00166"
"311.40600","25.95069","0.00188"
"311.66400","25.97221","0.00169"
"311.92200","25.99362","0.00184"
"312.18000","26.01514","0.00188"
"312.43800","26.03667","0.00184"
"312.69600","26.05819","0.00193"
"312.95400","26.07972","0.00176"
"313.21200","26.10118","0.00186"
"313.47000","26.12270","0.00199"
"313.72800","26.14423","0.00200"
"313.98600","26.16569","0.00161"
"314.24400","26.18716","0.00174"
"314.50200","26.20874","0.00175"
"314.76000","26.23014","0.00185"
"315.01800","26.25173","0.00163"
"315.27600","26.27313","0.00151"
"315.53400","26.29472","0.00182"
"315.79200","26.31612","0.00178"
"316.05000","26.33771","0.00166"
"316.30800","26.35917","0.00183"
"316.56600","26.38070","0.00179"
"316.82400","26.40216","0.00243"
"317.08200","26.42369","0.00184"
"317.34000","26.44521","0.00201"
"317.59800","26.46673","0.00182"
"317.85600","26.48820","0.00205"
"318.11400","26.50966","0.00171"
"318.37200","26.53119","0.00188"
"318.63000","26.55265","0.00204"
"318.88800","26.57417","0.00193"
"319.14600","26.59570","0.00181"
"319.40400","26.61723","0.00190"
"319.66200","26.63863","0.00166"
"319.92000","26.66021","0.00176"
"320.17800","26.68168","0.00206"
"320.43600","26.70320","0.00165"
"320.69400","26.72466","0.00197"
"320.95200","26.74619","0.00191"
"321.21000","26.76765","0.00213"
"321.46800","26.78918","0.00184"
"321.72600","26.81064","0.00183"
"321.98400","26.83217","0.00196"
"322.24200","26.85369","0.00172"
"322.50000","26.87522","0.00202"
"322.75800","26.89668","0.00216"
"323.01600","26.91827","0.00188"
"323.27400","26.93967","0.00207"
"323.53200","26.96119","0.00186"
"323.79000","26.98266","0.00196"
"324.04800","27.00424","0.00222"
"324.30600","27.02571","0.00195"
"324.56400","27.04717","0.00198"
"324.82200","27.06870","0.00228"
"325.08000","27.09016","0.00215"
"325.33800","27.11168","0.00189"
"325.59600","27.13321","0.00176"
"325.85400","27.15473","0.00177"
"326.11200","27.17620","0.00181"
"326.37000","27.19772","0.00200"
"326.62800","27.21918","0.00207"
"326.88600","27.24077","0.00208"
"327.14400","27.26211","0.00183"
"327.40200","27.28370","0.00197"
"327.66000","27.30516","0.00191"
"327.91800","27.32669","0.00211"
"328.17600","27.34821","0.00201"
"328.43400","27.36974","0.00162"
"328.69200","27.39114","0.00180"
"328.95000","27.41273","0.00171"
"329.20800","27.43419","0.00205"
"329.46600","27.45571","0.00197"
"329.72400","27.47718","0.00182"
"329.98200","27.49870","0.00178"
"330.24000","27.52016","0.00166"
"330.49800","27.54169","0.00205"
"330.75600","27.56322","0.00203"
"331.01400","27.58474","0.00207"
"331.27200","27.60614","0.00198"
"331.53000","27.62767","0.00181"
"331.78800","27.64925","0.00197"
"332.04600","27.67072","0.00162"
"332.30400","27.69218","0.00193"
"332.56200","27.71365","0.00191"
"332.82000","27.73523","0.00191"
"333.07800","27.75669","0.00210"
"333.33600","27.77822","0.00191"
"333.59400","27.79962","0.00192"
"333.85200","27.82121","0.00202"
"334.11000","27.84261","0.00172"
"334.36800","27.86419","0.00189"
"334.62600","27.88572","0.00202"
"334.88400","27.90718","0.00174"
"335.14200","27.92865","0.00174"
"335.40000","27.95017","0.00217"
"335.65800","27.97164","0.00186"
"335.91600","27.99328","0.00212"
"336.17400","28.01469","0.00191"
"336.43200","28.03615","0.00149"
"336.69000","28.05767","0.00196"
"336.94800","28.07926","0.00183"
"337.20600","28.10072","0.00191"
"337.46400","28.12219","0.00155"
"337.72200","28.14371","0.00191"
"337.98000","28.16518","0.00176"
"338.23800","28.18670","0.00168"
"338.49600","28.20822","0.00180"
"338.75400","28.22975","0.00196"
"339.01200","28.25115","0.00188"
"339.27000","28.27274","0.00208"
"339.52800","28.29420","0.00207"
"339.78600","28.31573","0.00189"
"340.04400","28.33713","0.00186"
"340.30200","28.35872","0.00219"
"340.56000","28.38012","0.00208"
"340.81800","28.40176","0.00212"
"341.07600","28.42317","0.00215"
"341.33400","28.44475","0.00169"
"341.59200","28.46616","0.00186"
"341.85000","28.48774","0.00192"
"342.10800","28.50920","0.00163"
"342.36600","28.53073","0.00182"
"342.62400","28.55219","0.00157"
"342.88200","28.57372","0.00218"
"343.14000","28.59518","0.00196"
"343.39800","28.61671","0.00162"
"343.65600","28.63817","0.00202"
"343.91400","28.65964","0.00219"
"344.17200","28.68122","0.00192"
"344.43000","28.70268","0.00180"
"344.68800","28.72421","0.00193"
"344.94600","28.74567","0.00185"
"345.20400","28.76719","0.00162"
"345.46200","28.78872","0.00206"
"345.72000","28.81024","0.00167"
"345.97800","28.83171","0.00212"
"346.23600","28.85317","0.00198"
"346.49400","28.87464","0.00196"
"346.75200","28.89622","0.00232"
"347.01000","28.91769","0.00183"
"347.26800","28.93921","0.00174"
"347.52600","28.96062","0.00180"
"347.78400","28.98220","0.00205"
"348.04200","29.00366","0.00191"
"348.30000","29.02525","0.00210"
"348.55800","29.04671","0.00169"
"348.81600","29.06824","0.00209"
"349.07400","29.08964","0.00205"
"349.33200","29.11123","0.00198"
"349.59000","29.13275","0.00185"
"349.84800","29.15421","0.00189"
"350.10600","29.17568","0.00198"
"350.36400","29.19720","0.00192"
"350.62200","29.21873","0.00212"
"350.88000","29.24019","0.00177"
"351.13800","29.26171","0.00182"
"351.39600","29.28312","0.00212"
"351.65400","29.30470","0.00202"
"351.91200","29.32617","0.00195"
"352.17000","29.34775","0.00183"
"352.42800","29.36922","0.00193"
"352.68600","29.39068","0.00192"
"352.94400","29.41215","0.00208"
"353.20200","29.43367","0.00165"
"353.46000","29.45520","0.00187"
"353.71800","29.47672","0.00195"
"353.97600","29.49818","0.00173"
"354.23400","29.51971","0.00174"
"354.49200","29.54117","0.00222"
"354.75000","29.56276","0.00187"
"355.00800","29.58416","0.00197"
"355.26600","29.60568","0.00168"
"355.52400","29.62715","0.00236"
"355.78200","29.64867","0.00185"
"356.04000","29.67020","0.00159"
"356.29800","29.69172","0.00178"
"356.55600","29.71319","0.00165"
"356.81400","29.73471","0.00210"
"357.07200","29.75618","0.00204"
"357.33000","29.77770","0.00199"
"357.58800","29.79922","0.00153"
"357.84600","29.82069","0.00183"
"358.10400","29.84227","0.00164"
"358.36200","29.86368","0.00186"
"358.62000","29.88520","0.00216"
"358.87800","29.90667","0.00183"
"359.13600","29.92825","0.00202"
"359.39400","29.94959","0.00175"
"359.65200","29.97118","0.00203"
"359.91000","29.99264","0.00198"
"360.16800","30.01423","0.00177"
"360.42600","30.03569","0.00141"
"360.68400","30.05722","0.00206"
"360.94200","30.07868","0.00178"
"361.20000","30.10021","0.00179"
"361.45800","30.12167","0.00170"
"361.71600","30.14319","0.00174"
"361.97400","30.16466","0.00195"
"362.23200","30.18618","0.00196"
"362.49000","30.20771","0.00185"
"362.74800","30.22917","0.00192"
"363.00600","30.25069","0.00202"
"363.26400","30.27216","0.00197"
"363.52200","30.29368","0.00241"
"363.78000","30.31521","0.00194"
"364.03800","30.33673","0.00222"
"364.29600","30.35820","0.00183"
"364.55400","30.37972","0.00219"
"364.81200","30.40118","0.00189"
"365.07000","30.42271","0.00183"
"365.32800","30.44417","0.00207"
"365.58600","30.46570","0.00211"
"365.84400","30.48716","0.00185"
"366.10200","30.50869","0.00246"
"366.36000","30.53015","0.00177"
"366.61800","30.55173","0.00188"
"366.87600","30.57314","0.00130"
"367.13400","30.59472","0.00182"
"367.39200","30.61619","0.00167"
"367.65000","30.63771","0.00190"
"367.90800","30.65918","0.00201"
"368.16600","30.68064","0.00202"
"368.42400","30.70217","0.00203"
"368.68200","30.72375","0.00199"
"368.94000","30.74528","0.00210"
"369.19800","30.76668","0.00208"
"369.45600","30.78820","0.00219"
"369.71400","30.80967","0.00184"
"369.97200","30.83125","0.00219"
"370.23000","30.85266","0.00185"
"370.48800","30.87418","0.00190"
"370.74600","30.89564","0.00179"
"371.00400","30.91717","0.00187"
"371.26200","30.93869","0.00179"
"371.52000","30.96022","0.00218"
"371.77800","30.98168","0.00197"
"372.03600","31.00321","0.00202"
"372.29400","31.02467","0.00198"
"372.55200","31.04619","0.00204"
"372.81000","31.06772","0.00213"
"373.06800","31.08919","0.00184"
"373.32600","31.11065","0.00156"
"373.58400","31.13223","0.00218"
"373.84200","31.15370","0.00204"
"374.10000","31.17522","0.00214"
"374.35800","31.19668","0.00221"
"374.61600","31.21815","0.00183"
"374.87400","31.23967","0.00201"
"375.13200","31.26119","0.00201"
"375.39000","31.28272","0.00219"
"375.64800","31.30418","0.00197"
"375.90600","31.32571","0.00185"
"376.16400","31.34717","0.00209"
"376.42200","31.36870","0.00204"
"376.68000","31.39022","0.00169"
"376.93800","31.41169","0.00206"
"377.19600","31.43315","0.00188"
"377.45400","31.45473","0.00198"
"377.71200","31.47614","0.00207"
"377.97000","31.49772","0.00196"
"378.22800","31.51919","0.00205"
"378.48600","31.54065","0.00182"
"378.74400","31.56218","0.00199"
"379.00200","31.58370","0.00211"
"379.26000","31.60517","0.00176"
"379.51800","31.62669","0.00210"
"379.77600","31.64816","0.00205"
"380.03400","31.66973","0.00191"
"380.29200","31.69120","0.00223"
"380.55000","31.71273","0.00225"
"380.80800","31.73413","0.00200"
"381.06600","31.75566","0.00198"
"381.32400","31.77718","0.00185"
"381.58200","31.79864","0.00193"
"381.84000","31.82023","0.00212"
"382.09800","31.84169","0.00185"
"382.35600","31.86322","0.00211"
"382.61400","31.88468","0.00201"
"382.87200","31.90621","0.00218"
"383.13000","31.92761","0.00207"
"383.38800","31.94919","0.00218"
"383.64600","31.97060","0.00204"
"383.90400","31.99224","0.00220"
"384.16200","32.01365","0.00186"
"384.42000","32.03523","0.00209"
"384.67800","32.05664","0.00206"
"384.93600","32.07816","0.00202"
"385.19400","32.09962","0.00234"
"385.45200","32.12121","0.00217"
"385.71000","32.14267","0.00238"
"385.95800","32.16336","0.00214"