File: Force_trajectories/161218_2/Specimen_RawData_8.csv
End date,"12/18/2016"
Specimen label,"16BG_29"
Maximum Load,"0.30305",N

Time,Extension,Load
(s),(mm),(N)
"0.00000","-0.00006","0.00015"
"0.39600","0.03312","0.00043"
"0.79200","0.06613","0.00115"
"1.18800","0.09907","0.00116"
"1.58400","0.13213","0.00159"
"1.98000","0.16514","0.00180"
"2.37600","0.19814","0.00238"
"2.77200","0.23109","0.00306"
"3.16800","0.26415","0.00395"
"3.56400","0.29709","0.00434"
"3.96000","0.33010","0.00491"
"4.35600","0.36316","0.00536"
"4.75200","0.39617","0.00594"
"5.14800","0.42911","0.00689"
"5.54400","0.46205","0.00766"
"5.94000","0.49512","0.00772"
"6.33600","0.52812","0.00965"
"6.73200","0.56112","0.01071"
"7.12800","0.59413","0.01091"
"7.52400","0.62713","0.01209"
"7.92000","0.66014","0.01330"
"8.31600","0.69308","0.01504"
"8.71200","0.72608","0.01638"
"9.10800","0.75915","0.01722"
"9.50400","0.79215","0.01832"
"9.90000","0.82510","0.01951"
"10.29600","0.85810","0.02129"
"10.69200","0.89110","0.02297"
"11.08800","0.92411","0.02491"
"11.48400","0.95705","0.02681"
"11.88000","0.99011","0.02905"
"12.27600","1.02306","0.03102"
"12.67200","1.05606","0.03347"
"13.06800","1.08907","0.03719"
"13.46400","1.12213","0.04234"
"13.86000","1.15513","0.04776"
"14.25600","1.18814","0.05329"
"14.65200","1.22108","0.05827"
"15.04800","1.25415","0.06468"
"15.44400","1.28715","0.07199"
"15.84000","1.32003","0.07967"
"16.23600","1.35310","0.08772"
"16.63200","1.38616","0.10163"
"17.02800","1.41910","0.10975"
"17.42400","1.45211","0.11906"
"17.82000","1.48517","0.12775"
"18.21600","1.51812","0.12809"
"18.61200","1.55112","0.12865"
"19.00800","1.58412","0.12893"
"19.40400","1.61713","0.12877"
"19.80000","1.65019","0.12912"
"20.19600","1.68314","0.12872"
"20.59200","1.71608","0.12892"
"20.98800","1.74908","0.12873"
"21.38400","1.78215","0.12901"
"21.78000","1.81515","0.12928"
"22.17600","1.84809","0.12885"
"22.57200","1.88116","0.12937"
"22.96800","1.91410","0.12904"
"23.36400","1.94711","0.12895"
"23.76000","1.98011","0.12947"
"24.15600","2.01317","0.12939"
"24.55200","2.04618","0.12951"
"24.94800","2.07906","0.12928"
"25.34400","2.11207","0.12964"
"25.74000","2.14513","0.12948"
"26.13600","2.17813","0.12968"
"26.53200","2.21108","0.12949"
"26.92800","2.24414","0.12976"
"27.32400","2.27714","0.12989"
"27.72000","2.31009","0.12961"
"28.11600","2.34309","0.12998"
"28.51200","2.37616","0.12996"
"28.90800","2.40916","0.13022"
"29.30400","2.44210","0.13013"
"29.70000","2.47517","0.13017"
"30.09600","2.50811","0.13002"
"30.49200","2.54117","0.12992"
"30.88800","2.57406","0.13010"
"31.28400","2.60712","0.13002"
"31.68000","2.64013","0.13024"
"32.07600","2.67313","0.13010"
"32.47200","2.70607","0.13008"
"32.86800","2.73914","0.13033"
"33.26400","2.77214","0.12994"
"33.66000","2.80509","0.13009"
"34.05600","2.83809","0.13009"
"34.45200","2.87115","0.13053"
"34.84800","2.90416","0.13007"
"35.24400","2.93710","0.13030"
"35.64000","2.97004","0.13041"
"36.03600","3.00311","0.13076"
"36.43200","3.03611","0.13023"
"36.82800","3.06906","0.13059"
"37.22400","3.10212","0.12999"
"37.62000","3.13512","0.13067"
"38.01600","3.16813","0.13039"
"38.41200","3.20107","0.13003"
"38.80800","3.23408","0.13052"
"39.20400","3.26714","0.13041"
"39.60000","3.30014","0.13076"
"39.99600","3.33303","0.13033"
"40.39200","3.36609","0.13055"
"40.78800","3.39915","0.13100"
"41.18400","3.43216","0.13021"
"41.58000","3.46504","0.13019"
"41.97600","3.49811","0.12990"
"42.37200","3.53117","0.13057"
"42.76800","3.56411","0.13042"
"43.16400","3.59712","0.13031"
"43.56000","3.63018","0.13024"
"43.95600","3.66313","0.13046"
"44.35200","3.69613","0.13043"
"44.74800","3.72913","0.13078"
"45.14400","3.76214","0.13037"
"45.54000","3.79514","0.13050"
"45.93600","3.82808","0.13091"
"46.33200","3.86109","0.13024"
"46.72800","3.89409","0.13066"
"47.12400","3.92716","0.13050"
"47.52000","3.96004","0.13083"
"47.91600","3.99316","0.13075"
"48.31200","4.02611","0.13085"
"48.70800","4.05911","0.13107"
"49.10400","4.09211","0.13078"
"49.50000","4.12518","0.13064"
"49.89600","4.15818","0.13083"
"50.29200","4.19107","0.13082"
"50.68800","4.22407","0.13123"
"51.08400","4.25713","0.13088"
"51.48000","4.29014","0.13124"
"51.87600","4.32308","0.13051"
"52.27200","4.35609","0.13102"
"52.66800","4.38915","0.13096"
"53.06400","4.42209","0.13112"
"53.46000","4.45504","0.13134"
"53.85600","4.48810","0.13143"
"54.25200","4.52116","0.13167"
"54.64800","4.55411","0.13114"
"55.04400","4.58705","0.13113"
"55.44000","4.62012","0.13089"
"55.83600","4.65318","0.13168"
"56.23200","4.68612","0.13154"
"56.62800","4.71907","0.13167"
"57.02400","4.75213","0.13156"
"57.42000","4.78520","0.13180"
"57.81600","4.81808","0.13165"
"58.21200","4.85108","0.13153"
"58.60800","4.88415","0.13160"
"59.00400","4.91715","0.13168"
"59.40000","4.95010","0.13223"
"59.79600","4.98310","0.13171"
"60.19200","5.01616","0.13143"
"60.58800","5.04911","0.13181"
"60.98400","5.08211","0.13199"
"61.38000","5.11505","0.13215"
"61.77600","5.14812","0.13156"
"62.17200","5.18112","0.13176"
"62.56800","5.21413","0.13212"
"62.96400","5.24713","0.13162"
"63.36000","5.28013","0.13194"
"63.75600","5.31308","0.13195"
"64.15200","5.34608","0.13191"
"64.54800","5.37915","0.13204"
"64.94400","5.41215","0.13203"
"65.34000","5.44509","0.13213"
"65.73600","5.47810","0.13218"
"66.13200","5.51116","0.13193"
"66.52800","5.54416","0.13228"
"66.92400","5.57705","0.13255"
"67.32000","5.61011","0.13246"
"67.71600","5.64312","0.13255"
"68.11200","5.67612","0.13254"
"68.50800","5.70906","0.13301"
"68.90400","5.74219","0.13295"
"69.30000","5.77513","0.13295"
"69.69600","5.80807","0.13311"
"70.09200","5.84108","0.13264"
"70.48800","5.87414","0.13325"
"70.88400","5.90715","0.13333"
"71.28000","5.94009","0.13362"
"71.67600","5.97309","0.13336"
"72.07200","6.00610","0.13375"
"72.46800","6.03916","0.13364"
"72.86400","6.07211","0.13354"
"73.26000","6.10505","0.13374"
"73.65600","6.13817","0.13375"
"74.05200","6.17118","0.13403"
"74.44800","6.20400","0.13368"
"74.84400","6.23712","0.13395"
"75.24000","6.27019","0.13375"
"75.63600","6.30313","0.13380"
"76.03200","6.33608","0.13413"
"76.42800","6.36908","0.13383"
"76.82400","6.40208","0.13414"
"77.22000","6.43515","0.13429"
"77.61600","6.46815","0.13435"
"78.01200","6.50109","0.13433"
"78.40800","6.53410","0.13458"
"78.80400","6.56716","0.13390"
"79.20000","6.60011","0.13460"
"79.59600","6.63317","0.13471"
"79.99200","6.66617","0.13426"
"80.38800","6.69912","0.13433"
"80.78400","6.73218","0.13469"
"81.18000","6.76513","0.13466"
"81.57600","6.79813","0.13447"
"81.97200","6.83107","0.13507"
"82.36800","6.86414","0.13452"
"82.76400","6.89708","0.13454"
"83.16000","6.93009","0.13516"
"83.55600","6.96309","0.13493"
"83.95200","6.99615","0.13465"
"84.34800","7.02916","0.13458"
"84.74400","7.06204","0.13486"
"85.14000","7.09504","0.13495"
"85.53600","7.12817","0.13508"
"85.93200","7.16111","0.13552"
"86.32800","7.19406","0.13521"
"86.72400","7.22706","0.13507"
"87.12000","7.26012","0.13538"
"87.51600","7.29313","0.13623"
"87.91200","7.32607","0.13605"
"88.30800","7.35914","0.13623"
"88.70400","7.39220","0.13610"
"89.10000","7.42508","0.13631"
"89.49600","7.45803","0.13591"
"89.89200","7.49109","0.13614"
"90.28800","7.52415","0.13656"
"90.68400","7.55716","0.13677"
"91.08000","7.59010","0.13685"
"91.47600","7.62317","0.13652"
"91.87200","7.65617","0.13643"
"92.26800","7.68917","0.13724"
"92.66400","7.72212","0.13714"
"93.06000","7.75512","0.13655"
"93.45600","7.78813","0.13702"
"93.85200","7.82113","0.13740"
"94.24800","7.85407","0.13771"
"94.64400","7.88714","0.13766"
"95.04000","7.92014","0.13798"
"95.43600","7.95308","0.13792"
"95.83200","7.98615","0.13806"
"96.22800","8.01909","0.13821"
"96.62400","8.05210","0.13814"
"97.02000","8.08510","0.13835"
"97.41600","8.11816","0.13849"
"97.81200","8.15111","0.13859"
"98.20800","8.18411","0.13893"
"98.60400","8.21712","0.13886"
"99.00000","8.25012","0.13917"
"99.39600","8.28312","0.13895"
"99.79200","8.31613","0.13903"
"100.18800","8.34907","0.13938"
"100.58400","8.38213","0.13943"
"100.98000","8.41514","0.13950"
"101.37600","8.44802","0.13999"
"101.77200","8.48114","0.13953"
"102.16800","8.51421","0.14027"
"102.56400","8.54709","0.14024"
"102.96000","8.58004","0.14019"
"103.35600","8.61310","0.14071"
"103.75200","8.64616","0.14067"
"104.14800","8.67911","0.14148"
"104.54400","8.71205","0.14175"
"104.94000","8.74512","0.14109"
"105.33600","8.77818","0.14153"
"105.73200","8.81112","0.14177"
"106.12800","8.84413","0.14035"
"106.52400","8.87713","0.14009"
"106.92000","8.91014","0.14036"
"107.31600","8.94314","0.14079"
"107.71200","8.97608","0.14090"
"108.10800","9.00915","0.14122"
"108.50400","9.04215","0.14116"
"108.90000","9.07509","0.14201"
"109.29600","9.10810","0.14154"
"109.69200","9.14110","0.14235"
"110.08800","9.17417","0.14232"
"110.48400","9.20705","0.14231"
"110.88000","9.24011","0.14249"
"111.27600","9.27312","0.14263"
"111.67200","9.30612","0.14317"
"112.06800","9.33912","0.14330"
"112.46400","9.37213","0.14368"
"112.86000","9.40507","0.14379"
"113.25600","9.43808","0.14367"
"113.65200","9.47114","0.14423"
"114.04800","9.50408","0.14430"
"114.44400","9.53715","0.14426"
"114.84000","9.57009","0.14443"
"115.23600","9.60310","0.14495"
"115.63200","9.63610","0.14519"
"116.02800","9.66916","0.14466"
"116.42400","9.70211","0.14563"
"116.82000","9.73517","0.14589"
"117.21600","9.76812","0.14621"
"117.61200","9.80112","0.14482"
"118.00800","9.83400","0.14490"
"118.40400","9.86713","0.14598"
"118.80000","9.90013","0.14561"
"119.19600","9.93313","0.14615"
"119.59200","9.96614","0.14627"
"119.98800","9.99914","0.14604"
"120.38400","10.03215","0.14559"
"120.78000","10.06509","0.14605"
"121.17600","10.09809","0.14644"
"121.57200","10.13116","0.14647"
"121.96800","10.16416","0.14681"
"122.36400","10.19710","0.14692"
"122.76000","10.23005","0.14703"
"123.15600","10.26311","0.14745"
"123.55200","10.29612","0.14766"
"123.94800","10.32906","0.14839"
"124.34400","10.36206","0.14856"
"124.74000","10.39513","0.14867"
"125.13600","10.42813","0.14819"
"125.53200","10.46108","0.14877"
"125.92800","10.49408","0.14806"
"126.32400","10.52714","0.14910"
"126.72000","10.56015","0.14924"
"127.11600","10.59309","0.14944"
"127.51200","10.62609","0.14985"
"127.90800","10.65916","0.14941"
"128.30400","10.69210","0.14980"
"128.70000","10.72511","0.15031"
"129.09600","10.75817","0.15043"
"129.49200","10.79111","0.15086"
"129.88800","10.82412","0.15059"
"130.28400","10.85712","0.15108"
"130.68000","10.89012","0.15079"
"131.07600","10.92313","0.15155"
"131.47200","10.95607","0.15197"
"131.86800","10.98914","0.15166"
"132.26400","11.02208","0.15245"
"132.66000","11.05514","0.15179"
"133.05600","11.08809","0.15226"
"133.45200","11.12115","0.15291"
"133.84800","11.15410","0.15269"
"134.24400","11.18710","0.15221"
"134.64000","11.22010","0.15249"
"135.03600","11.25317","0.15290"
"135.43200","11.28611","0.15295"
"135.82800","11.31906","0.15311"
"136.22400","11.35212","0.15341"
"136.62000","11.38512","0.15417"
"137.01600","11.41813","0.15406"
"137.41200","11.45107","0.15376"
"137.80800","11.48413","0.15324"
"138.20400","11.51720","0.15383"
"138.60000","11.55014","0.15409"
"138.99600","11.58309","0.15405"
"139.39200","11.61615","0.15407"
"139.78800","11.64915","0.15488"
"140.18400","11.68210","0.15515"
"140.58000","11.71510","0.15561"
"140.97600","11.74810","0.15562"
"141.37200","11.78117","0.15583"
"141.76800","11.81411","0.15601"
"142.16400","11.84706","0.15584"
"142.56000","11.88012","0.15674"
"142.95600","11.91318","0.15663"
"143.35200","11.94613","0.15678"
"143.74800","11.97907","0.15657"
"144.14400","12.01219","0.15762"
"144.54000","12.04514","0.15741"
"144.93600","12.07814","0.15765"
"145.33200","12.11109","0.15779"
"145.72800","12.14409","0.15817"
"146.12400","12.17715","0.15831"
"146.52000","12.21010","0.15858"
"146.91600","12.24310","0.15909"
"147.31200","12.27611","0.15914"
"147.70800","12.30911","0.15925"
"148.10400","12.34212","0.15944"
"148.50000","12.37512","0.15975"
"148.89600","12.40812","0.15967"
"149.29200","12.44112","0.16049"
"149.68800","12.47413","0.16119"
"150.08400","12.50719","0.16130"
"150.48000","12.54008","0.16177"
"150.87600","12.57308","0.16177"
"151.27200","12.60614","0.16220"
"151.66800","12.63915","0.16260"
"152.06400","12.67215","0.16310"
"152.46000","12.70510","0.16347"
"152.85600","12.73816","0.16331"
"153.25200","12.77116","0.16395"
"153.64800","12.80411","0.16397"
"154.04400","12.83705","0.16484"
"154.44000","12.87017","0.16548"
"154.83600","12.90318","0.16543"
"155.23200","12.93606","0.16616"
"155.62800","12.96913","0.16630"
"156.02400","13.00213","0.16773"
"156.42000","13.03520","0.16790"
"156.81600","13.06808","0.16847"
"157.21200","13.10114","0.16834"
"157.60800","13.13415","0.16923"
"158.00400","13.16721","0.16924"
"158.40000","13.20003","0.16924"
"158.79600","13.23304","0.17041"
"159.19200","13.26610","0.17041"
"159.58800","13.29910","0.17107"
"159.98400","13.33205","0.17125"
"160.38000","13.36511","0.17183"
"160.77600","13.39812","0.17202"
"161.17200","13.43112","0.17237"
"161.56800","13.46407","0.17334"
"161.96400","13.49713","0.17390"
"162.36000","13.53013","0.17394"
"162.75600","13.56314","0.17506"
"163.15200","13.59614","0.17538"
"163.54800","13.62914","0.17533"
"163.94400","13.66215","0.17681"
"164.34000","13.69509","0.17630"
"164.73600","13.72816","0.17682"
"165.13200","13.76116","0.17748"
"165.52800","13.79416","0.17768"
"165.92400","13.82711","0.17888"
"166.32000","13.86017","0.17903"
"166.71600","13.89312","0.17981"
"167.11200","13.92606","0.18031"
"167.50800","13.95906","0.18115"
"167.90400","13.99219","0.18138"
"168.30000","14.02513","0.18160"
"168.69600","14.05813","0.18230"
"169.09200","14.09108","0.18243"
"169.48800","14.12414","0.18258"
"169.88400","14.15715","0.17129"
"170.28000","14.19009","0.17258"
"170.67600","14.22309","0.17340"
"171.07200","14.25616","0.17460"
"171.46800","14.28910","0.17569"
"171.86400","14.32205","0.17697"
"172.26000","14.35511","0.17757"
"172.65600","14.38811","0.17872"
"173.05200","14.42112","0.17944"
"173.44800","14.45406","0.18035"
"173.84400","14.48712","0.18157"
"174.24000","14.52013","0.18238"
"174.63600","14.55313","0.16980"
"175.03200","14.58608","0.15291"
"175.42800","14.61908","0.15438"
"175.82400","14.65214","0.15556"
"176.22000","14.68509","0.15668"
"176.61600","14.71809","0.15702"
"177.01200","14.75115","0.15791"
"177.40800","14.78416","0.15778"
"177.80400","14.81710","0.15851"
"178.20000","14.85011","0.15831"
"178.59600","14.88311","0.15913"
"178.99200","14.91617","0.16001"
"179.38800","14.94912","0.16056"
"179.78400","14.98206","0.16173"
"180.18000","15.01518","0.16261"
"180.57600","15.04813","0.16319"
"180.97200","15.08107","0.16425"
"181.36800","15.11414","0.16516"
"181.76400","15.14708","0.16559"
"182.16000","15.18008","0.16695"
"182.55600","15.21315","0.16703"
"182.95200","15.24615","0.16836"
"183.34800","15.27910","0.16973"
"183.74400","15.31210","0.16992"
"184.14000","15.34504","0.17016"
"184.53600","15.37811","0.17039"
"184.93200","15.41111","0.17183"
"185.32800","15.44406","0.17258"
"185.72400","15.47706","0.17300"
"186.12000","15.51012","0.17338"
"186.51600","15.54313","0.17398"
"186.91200","15.57601","0.17474"
"187.30800","15.60913","0.17533"
"187.70400","15.64214","0.17585"
"188.10000","15.67514","0.17654"
"188.49600","15.70809","0.17692"
"188.89200","15.74115","0.17789"
"189.28800","15.77415","0.17730"
"189.68400","15.80710","0.17861"
"190.08000","15.84010","0.17916"
"190.47600","15.87310","0.17955"
"190.87200","15.90617","0.17987"
"191.26800","15.93911","0.18137"
"191.66400","15.97212","0.18185"
"192.06000","16.00518","0.18097"
"192.45600","16.03818","0.18176"
"192.85200","16.07113","0.18234"
"193.24800","16.10407","0.18250"
"193.64400","16.13713","0.18253"
"194.04000","16.17014","0.18375"
"194.43600","16.20308","0.18215"
"194.83200","16.23609","0.18283"
"195.22800","16.26915","0.18351"
"195.62400","16.30209","0.18327"
"196.02000","16.33510","0.18415"
"196.41600","16.36810","0.18514"
"196.81200","16.40111","0.18543"
"197.20800","16.43411","0.18595"
"197.60400","16.46705","0.18690"
"198.00000","16.50012","0.18743"
"198.39600","16.53312","0.18856"
"198.79200","16.56613","0.18967"
"199.18800","16.59913","0.19028"
"199.58400","16.63213","0.19019"
"199.98000","16.66508","0.19101"
"200.37600","16.69808","0.19158"
"200.77200","16.73114","0.19324"
"201.16800","16.76415","0.19447"
"201.56400","16.79709","0.19519"
"201.96000","16.83010","0.19606"
"202.35600","16.86316","0.19726"
"202.75200","16.89616","0.19791"
"203.14800","16.92911","0.19848"
"203.54400","16.96205","0.20015"
"203.94000","16.99512","0.20105"
"204.33600","17.02818","0.20155"
"204.73200","17.06106","0.20256"
"205.12800","17.09413","0.19908"
"205.52400","17.12713","0.20008"
"205.92000","17.16019","0.20146"
"206.31600","17.19308","0.20227"
"206.71200","17.22608","0.20240"
"207.10800","17.25915","0.20353"
"207.50400","17.29209","0.20393"
"207.90000","17.32504","0.20423"
"208.29600","17.35816","0.20514"
"208.69200","17.39116","0.20547"
"209.08800","17.42410","0.20555"
"209.48400","17.45711","0.20614"
"209.88000","17.49011","0.20703"
"210.27600","17.52312","0.20736"
"210.67200","17.55612","0.20824"
"211.06800","17.58906","0.20856"
"211.46400","17.62213","0.20967"
"211.86000","17.65513","0.20995"
"212.25600","17.68808","0.21040"
"212.65200","17.72108","0.21152"
"213.04800","17.75414","0.21168"
"213.44400","17.78721","0.21232"
"213.84000","17.82009","0.21225"
"214.23600","17.85309","0.21307"
"214.63200","17.88616","0.21364"
"215.02800","17.91910","0.21358"
"215.42400","17.95211","0.17497"
"215.82000","17.98517","0.17604"
"216.21600","18.01811","0.14918"
"216.61200","18.05118","0.15282"
"217.00800","18.08406","0.15274"
"217.40400","18.11713","0.15345"
"217.80000","18.15013","0.15584"
"218.19600","18.18307","0.15594"
"218.59200","18.21608","0.15561"
"218.98800","18.24914","0.15639"
"219.38400","18.28214","0.15827"
"219.78000","18.31509","0.15863"
"220.17600","18.34809","0.15884"
"220.57200","18.38110","0.13462"
"220.96800","18.41416","0.13364"
"221.36400","18.44704","0.13524"
"221.76000","18.48017","0.13490"
"222.15600","18.51317","0.13595"
"222.55200","18.54612","0.13565"
"222.94800","18.57906","0.13598"
"223.34400","18.61206","0.13629"
"223.74000","18.64513","0.13669"
"224.13600","18.67813","0.13631"
"224.53200","18.71107","0.13710"
"224.92800","18.74408","0.13746"
"225.32400","18.77714","0.13709"
"225.72000","18.81009","0.13814"
"226.11600","18.84309","0.13806"
"226.51200","18.87615","0.13854"
"226.90800","18.90916","0.13860"
"227.30400","18.94210","0.13903"
"227.70000","18.97511","0.13928"
"228.09600","19.00811","0.13951"
"228.49200","19.04117","0.13987"
"228.88800","19.07412","0.13976"
"229.28400","19.10712","0.14049"
"229.68000","19.14013","0.14002"
"230.07600","19.17313","0.14057"
"230.47200","19.20607","0.14080"
"230.86800","19.23914","0.14113"
"231.26400","19.27214","0.14188"
"231.66000","19.30508","0.14179"
"232.05600","19.33809","0.14195"
"232.45200","19.37115","0.14166"
"232.84800","19.40409","0.14239"
"233.24400","19.43704","0.14213"
"233.64000","19.47004","0.14225"
"234.03600","19.50311","0.14209"
"234.43200","19.53611","0.14186"
"234.82800","19.56905","0.14260"
"235.22400","19.60212","0.14273"
"235.62000","19.63512","0.14328"
"236.01600","19.66813","0.14280"
"236.41200","19.70107","0.14303"
"236.80800","19.73413","0.14340"
"237.20400","19.76708","0.14476"
"237.60000","19.80014","0.14488"
"237.99600","19.83302","0.14544"
"238.39200","19.86615","0.14538"
"238.78800","19.89921","0.14546"
"239.18400","19.93209","0.14573"
"239.58000","19.96510","0.14594"
"239.97600","19.99816","0.14618"
"240.37200","20.03117","0.14667"
"240.76800","20.06405","0.14753"
"241.16400","20.09711","0.14766"
"241.56000","20.13018","0.14765"
"241.95600","20.16312","0.14863"
"242.35200","20.19607","0.14835"
"242.74800","20.22913","0.14912"
"243.14400","20.26208","0.14948"
"243.54000","20.29514","0.14915"
"243.93600","20.32808","0.14917"
"244.33200","20.36102","0.14902"
"244.72800","20.39415","0.14824"
"245.12400","20.42709","0.14905"
"245.52000","20.46004","0.14962"
"245.91600","20.49310","0.15069"
"246.31200","20.52611","0.15033"
"246.70800","20.55911","0.15136"
"247.10400","20.59211","0.15191"
"247.50000","20.62512","0.15316"
"247.89600","20.65812","0.15324"
"248.29200","20.69112","0.15349"
"248.68800","20.72407","0.15366"
"249.08400","20.75713","0.15453"
"249.48000","20.79014","0.15441"
"249.87600","20.82308","0.15514"
"250.27200","20.85614","0.15561"
"250.66800","20.88909","0.15551"
"251.06400","20.92215","0.15552"
"251.46000","20.95510","0.15595"
"251.85600","20.98816","0.15668"
"252.25200","21.02110","0.15703"
"252.64800","21.05417","0.15784"
"253.04400","21.08711","0.15800"
"253.44000","21.12011","0.15851"
"253.83600","21.15312","0.15886"
"254.23200","21.18606","0.15958"
"254.62800","21.21913","0.15994"
"255.02400","21.25213","0.16047"
"255.42000","21.28519","0.16118"
"255.81600","21.31808","0.16109"
"256.21200","21.35108","0.16200"
"256.60800","21.38415","0.16222"
"257.00400","21.41715","0.16241"
"257.40000","21.45003","0.16238"
"257.79600","21.48310","0.16252"
"258.19200","21.51616","0.16339"
"258.58800","21.54911","0.16331"
"258.98400","21.58205","0.16436"
"259.38000","21.61511","0.16271"
"259.77600","21.64812","0.16284"
"260.17200","21.68112","0.16358"
"260.56800","21.71412","0.16482"
"260.96400","21.74713","0.16483"
"261.36000","21.78013","0.16410"
"261.75600","21.81314","0.16477"
"262.15200","21.84614","0.16638"
"262.54800","21.87914","0.16637"
"262.94400","21.91215","0.16438"
"263.34000","21.94509","0.16545"
"263.73600","21.97810","0.16536"
"264.13200","22.01110","0.16612"
"264.52800","22.04416","0.16753"
"264.92400","22.07705","0.16796"
"265.32000","22.11017","0.16830"
"265.71600","22.14311","0.16940"
"266.11200","22.17612","0.17081"
"266.50800","22.20912","0.17049"
"266.90400","22.24212","0.16961"
"267.30000","22.27513","0.16958"
"267.69600","22.30807","0.16993"
"268.09200","22.34108","0.16998"
"268.48800","22.37414","0.17052"
"268.88400","22.40714","0.16908"
"269.28000","22.44009","0.17131"
"269.67600","22.47309","0.17117"
"270.07200","22.50616","0.17169"
"270.46800","22.53916","0.17245"
"270.86400","22.57204","0.17254"
"271.26000","22.60511","0.17398"
"271.65600","22.63817","0.17567"
"272.05200","22.67118","0.17623"
"272.44800","22.70406","0.17680"
"272.84400","22.73712","0.17742"
"273.24000","22.77013","0.17881"
"273.63600","22.80313","0.17951"
"274.03200","22.83607","0.18081"
"274.42800","22.86914","0.18172"
"274.82400","22.90214","0.18221"
"275.22000","22.93514","0.18316"
"275.61600","22.96809","0.18392"
"276.01200","23.00115","0.18417"
"276.40800","23.03410","0.18494"
"276.80400","23.06710","0.18464"
"277.20000","23.10011","0.18508"
"277.59600","23.13317","0.18634"
"277.99200","23.16617","0.18748"
"278.38800","23.19912","0.18848"
"278.78400","23.23206","0.18960"
"279.18000","23.26513","0.19105"
"279.57600","23.29813","0.19228"
"279.97200","23.33113","0.19374"
"280.36800","23.36414","0.19541"
"280.76400","23.39714","0.19716"
"281.16000","23.43008","0.19788"
"281.55600","23.46309","0.19941"
"281.95200","23.49609","0.20120"
"282.34800","23.52916","0.20269"
"282.74400","23.56210","0.20372"
"283.14000","23.59510","0.20434"
"283.53600","23.62817","0.20488"
"283.93200","23.66111","0.20200"
"284.32800","23.69406","0.20271"
"284.72400","23.72712","0.20344"
"285.12000","23.76012","0.20492"
"285.51600","23.79312","0.20563"
"285.91200","23.82607","0.20633"
"286.30800","23.85913","0.20730"
"286.70400","23.89214","0.20761"
"287.10000","23.92508","0.20883"
"287.49600","23.95809","0.20946"
"287.89200","23.99109","0.20925"
"288.28800","24.02415","0.20988"
"288.68400","24.05716","0.21100"
"289.08000","24.09010","0.21163"
"289.47600","24.12310","0.21271"
"289.87200","24.15617","0.21331"
"290.26800","24.18905","0.21157"
"290.66400","24.22205","0.21209"
"291.06000","24.25518","0.21316"
"291.45600","24.28812","0.21328"
"291.85200","24.32107","0.21387"
"292.24800","24.35407","0.21530"
"292.64400","24.38713","0.21573"
"293.04000","24.42014","0.21640"
"293.43600","24.45308","0.20965"
"293.83200","24.48609","0.21019"
"294.22800","24.51915","0.21105"
"294.62400","24.55209","0.21195"
"295.02000","24.58510","0.21177"
"295.41600","24.61810","0.21255"
"295.81200","24.65110","0.21332"
"296.20800","24.68411","0.21382"
"296.60400","24.71705","0.21422"
"297.00000","24.75012","0.21504"
"297.39600","24.78312","0.21494"
"297.79200","24.81612","0.21500"
"298.18800","24.84913","0.21596"
"298.58400","24.88213","0.21718"
"298.98000","24.91513","0.21735"
"299.37600","24.94808","0.21814"
"299.77200","24.98114","0.21800"
"300.16800","25.01415","0.21833"
"300.56400","25.04709","0.14520"
"300.96000","25.08003","0.14430"
"301.35600","25.11316","0.14480"
"301.75200","25.14610","0.14307"
"302.14800","25.17911","0.14679"
"302.54400","25.21205","0.14719"
"302.94000","25.24517","0.14751"
"303.33600","25.27812","0.14797"
"303.73200","25.31106","0.14886"
"304.12800","25.34406","0.15046"
"304.52400","25.37713","0.15139"
"304.92000","25.41019","0.15206"
"305.31600","25.44308","0.15236"
"305.71200","25.47614","0.15327"
"306.10800","25.50915","0.15362"
"306.50400","25.54215","0.15433"
"306.90000","25.57503","0.15257"
"307.29600","25.60810","0.15359"
"307.69200","25.64110","0.15452"
"308.08800","25.67416","0.15514"
"308.48400","25.70711","0.15552"
"308.88000","25.74011","0.15626"
"309.27600","25.77312","0.15685"
"309.67200","25.80606","0.15747"
"310.06800","25.83906","0.15808"
"310.46400","25.87213","0.15866"
"310.86000","25.90513","0.15885"
"311.25600","25.93814","0.15936"
"311.65200","25.97108","0.15977"
"312.04800","26.00414","0.16053"
"312.44400","26.03709","0.16007"
"312.84000","26.07015","0.16097"
"313.23600","26.10309","0.16275"
"313.63200","26.13616","0.16203"
"314.02800","26.16910","0.16250"
"314.42400","26.20211","0.16280"
"314.82000","26.23511","0.15458"
"315.21600","26.26811","0.15447"
"315.61200","26.30112","0.15082"
"316.00800","26.33406","0.15270"
"316.40400","26.36719","0.15357"
"316.80000","26.40013","0.15401"
"317.19600","26.43307","0.15491"
"317.59200","26.46608","0.15608"
"317.98800","26.49920","0.15693"
"318.38400","26.53214","0.15795"
"318.78000","26.56509","0.15851"
"319.17600","26.59815","0.15896"
"319.57200","26.63116","0.15954"
"319.96800","26.66410","0.16025"
"320.36400","26.69704","0.16056"
"320.76000","26.73010","0.16162"
"321.15600","26.76317","0.16252"
"321.55200","26.79612","0.16261"
"321.94800","26.82906","0.16364"
"322.34400","26.86206","0.16361"
"322.74000","26.89512","0.16400"
"323.13600","26.92813","0.16511"
"323.53200","26.96107","0.16595"
"323.92800","26.99414","0.16690"
"324.32400","27.02720","0.16762"
"324.72000","27.06008","0.16711"
"325.11600","27.09309","0.16785"
"325.51200","27.12615","0.16998"
"325.90800","27.15916","0.17048"
"326.30400","27.19210","0.17050"
"326.70000","27.22510","0.17153"
"327.09600","27.25811","0.17226"
"327.49200","27.29111","0.17293"
"327.88800","27.32412","0.17420"
"328.28400","27.35712","0.17290"
"328.68000","27.39012","0.17288"
"329.07600","27.42313","0.17345"
"329.47200","27.45613","0.17448"
"329.86800","27.48914","0.17520"
"330.26400","27.52214","0.17630"
"330.66000","27.55508","0.17760"
"331.05600","27.58815","0.17880"
"331.45200","27.62115","0.17846"
"331.84800","27.65409","0.17955"
"332.24400","27.68710","0.18036"
"332.64000","27.72010","0.18161"
"333.03600","27.75311","0.18247"
"333.43200","27.78611","0.18300"
"333.82800","27.81905","0.18339"
"334.22400","27.85212","0.18410"
"334.62000","27.88512","0.18443"
"335.01600","27.91807","0.18279"
"335.41200","27.95101","0.18377"
"335.80800","27.98413","0.18451"
"336.20400","28.01714","0.18557"
"336.60000","28.05008","0.18614"
"336.99600","28.08303","0.18723"
"337.39200","28.11609","0.18913"
"337.78800","28.14915","0.18972"
"338.18400","28.18210","0.19045"
"338.58000","28.21510","0.19255"
"338.97600","28.24810","0.19346"
"339.37200","28.28117","0.19526"
"339.76800","28.31411","0.19619"
"340.16400","28.34706","0.19779"
"340.56000","28.38012","0.19932"
"340.95600","28.41318","0.20102"
"341.35200","28.44607","0.20225"
"341.74800","28.47913","0.20381"
"342.14400","28.51213","0.20463"
"342.54000","28.54514","0.20553"
"342.93600","28.57808","0.20687"
"343.33200","28.61109","0.20774"
"343.72800","28.64415","0.20839"
"344.12400","28.67715","0.20964"
"344.52000","28.71010","0.21013"
"344.91600","28.74310","0.21098"
"345.31200","28.77611","0.21152"
"345.70800","28.80905","0.21260"
"346.10400","28.84211","0.21357"
"346.50000","28.87512","0.21468"
"346.89600","28.90812","0.21543"
"347.29200","28.94112","0.21669"
"347.68800","28.97413","0.21756"
"348.08400","29.00713","0.21865"
"348.48000","29.04008","0.21976"
"348.87600","29.07308","0.21964"
"349.27200","29.10614","0.22089"
"349.66800","29.13915","0.22223"
"350.06400","29.17215","0.22295"
"350.46000","29.20504","0.22427"
"350.85600","29.23816","0.22606"
"351.25200","29.27116","0.22715"
"351.64800","29.30411","0.22846"
"352.04400","29.33705","0.22971"
"352.44000","29.37017","0.23164"
"352.83600","29.40312","0.23233"
"353.23200","29.43606","0.23353"
"353.62800","29.46907","0.23500"
"354.02400","29.50213","0.23668"
"354.42000","29.53513","0.23819"
"354.81600","29.56808","0.24018"
"355.21200","29.60108","0.24101"
"355.60800","29.63414","0.24295"
"356.00400","29.66715","0.24543"
"356.40000","29.70003","0.24761"
"356.79600","29.73310","0.24980"
"357.19200","29.76610","0.25158"
"357.58800","29.79917","0.25414"
"357.98400","29.83205","0.25576"
"358.38000","29.86511","0.25764"
"358.77600","29.89812","0.25948"
"359.17200","29.93112","0.26042"
"359.56800","29.96407","0.26239"
"359.96400","29.99713","0.26346"
"360.36000","30.03013","0.26578"
"360.75600","30.06307","0.26722"
"361.15200","30.09608","0.26886"
"361.54800","30.12914","0.27008"
"361.94400","30.16215","0.27232"
"362.34000","30.19509","0.27427"
"362.73600","30.22810","0.27574"
"363.13200","30.26116","0.27757"
"363.52800","30.29410","0.27892"
"363.92400","30.32710","0.28028"
"364.32000","30.36017","0.28183"
"364.71600","30.39311","0.28410"
"365.11200","30.42606","0.28562"
"365.50800","30.45912","0.28663"
"365.90400","30.49212","0.28778"
"366.30000","30.52513","0.28977"
"366.69600","30.55813","0.29112"
"367.09200","30.59108","0.29199"
"367.48800","30.62420","0.29356"
"367.88400","30.65708","0.29483"
"368.28000","30.69003","0.29608"
"368.67600","30.72309","0.29811"
"369.07200","30.75616","0.29922"
"369.46800","30.78910","0.30039"
"369.86400","30.82204","0.30176"
"370.26000","30.85511","0.30305"
"370.65600","30.88817","0.28394"
"371.05200","30.92112","0.28358"
"371.44800","30.95406","0.28391"
"371.84400","30.98712","0.28417"
"372.24000","31.02019","0.28192"
"372.63600","31.05313","0.26255"
"373.03200","31.08607","0.26384"
"373.42800","31.11908","0.26631"
"373.82400","31.15214","0.26799"
"374.22000","31.18509","0.27011"
"374.61600","31.21809","0.26920"
"375.01200","31.25115","0.26816"
"375.40800","31.28421","0.26799"
"375.80400","31.31704","0.26746"
"376.20000","31.35010","0.26834"
"376.59600","31.38317","0.17473"
"376.99200","31.41617","0.18238"
"377.38800","31.44911","0.18298"
"377.78400","31.48212","0.18329"
"378.18000","31.51518","0.18342"
"378.57600","31.54806","0.18404"
"378.97200","31.58113","0.18422"
"379.36800","31.61413","0.18388"
"379.76400","31.64708","0.18419"
"380.16000","31.68014","0.18477"
"380.55600","31.71315","0.18563"
"380.95200","31.74609","0.18590"
"381.34800","31.77915","0.18599"
"381.74400","31.81210","0.18650"
"382.14000","31.84510","0.18658"
"382.53600","31.87810","0.18662"
"382.93200","31.91111","0.18746"
"383.32800","31.94411","0.18720"
"383.72400","31.97712","0.13772"
"384.12000","32.01012","0.13569"
"384.51600","32.04312","0.13668"
"384.91200","32.07607","0.13751"
"385.30800","32.10913","0.13707"
"385.70400","32.14214","0.13767"
"386.10000","32.17508","0.13667"
"386.49600","32.20802","0.13715"
"386.89200","32.24115","0.13732"
"387.28800","32.27415","0.13696"
"387.68400","32.30709","0.13785"
"388.08000","32.34010","0.13809"
"388.47600","32.37316","0.13773"
"388.87200","32.40617","0.13742"
"389.26800","32.43905","0.13786"
"389.66400","32.47211","0.13854"
"390.06000","32.50512","0.13807"
"390.45600","32.53818","0.13813"
"390.85200","32.57107","0.13822"
"391.24800","32.60407","0.13855"
"391.64400","32.63707","0.13864"
"392.04000","32.67020","0.13895"
"392.43600","32.70308","0.13859"
"392.83200","32.73608","0.13945"
"393.22800","32.76915","0.13872"
"393.62400","32.80209","0.13905"
"394.02000","32.83509","0.13963"
"394.41600","32.86810","0.14003"
"394.81200","32.90117","0.14007"
"395.20800","32.93411","0.14035"
"395.60400","32.96711","0.14033"
"396.00000","33.00011","0.14081"
"396.39600","33.03312","0.14007"
"396.79200","33.06612","0.14027"
"397.18800","33.09912","0.14063"
"397.58400","33.13213","0.14075"
"397.98000","33.16507","0.14114"
"398.37600","33.19808","0.14131"
"398.77200","33.23108","0.14142"
"399.16800","33.26408","0.14201"
"399.56400","33.29709","0.14242"
"399.96000","33.33009","0.14266"
"400.35600","33.36316","0.14208"
"400.75200","33.39610","0.14266"
"401.14800","33.42910","0.14287"
"401.54400","33.46211","0.14282"
"401.94000","33.49517","0.14305"
"402.33600","33.52818","0.14376"
"402.73200","33.56112","0.14297"
"403.12800","33.59412","0.14346"
"403.52400","33.62712","0.14370"
"403.92000","33.66013","0.14344"
"404.31600","33.69302","0.14292"
"404.71200","33.72608","0.14366"
"405.10800","33.75920","0.14377"
"405.50400","33.79209","0.14418"
"405.90000","33.82503","0.14368"
"406.29600","33.85809","0.14318"
"406.69200","33.89110","0.14279"
"407.08800","33.92410","0.14298"
"407.48400","33.95710","0.14335"
"407.88000","33.99011","0.14344"
"408.27600","34.02311","0.14321"
"408.67200","34.05618","0.14398"
"409.06800","34.08906","0.14397"
"409.46400","34.12212","0.14414"
"409.86000","34.15513","0.14456"
"410.25600","34.18807","0.14414"
"410.65200","34.22108","0.14482"
"411.04800","34.25408","0.14494"
"411.44400","34.28714","0.14552"
"411.84000","34.32009","0.14510"
"412.23600","34.35309","0.14487"
"412.63200","34.38609","0.14540"
"413.02800","34.41916","0.14654"
"413.42400","34.45210","0.14423"
"413.82000","34.48517","0.14408"
"414.21600","34.51811","0.14449"
"414.61200","34.55111","0.14499"
"415.00800","34.58412","0.14572"
"415.40400","34.61712","0.14452"
"415.80000","34.65013","0.14493"
"416.19600","34.68307","0.14515"
"416.59200","34.71607","0.14529"
"416.98800","34.74914","0.14509"
"417.38400","34.78214","0.14480"
"417.78000","34.81509","0.14485"
"418.17600","34.84809","0.14512"
"418.57200","34.88115","0.14487"
"418.96800","34.91410","0.14456"
"419.36400","34.94704","0.14475"
"419.76000","34.98011","0.14418"
"420.15600","35.01317","0.14325"
"420.55200","35.04611","0.14309"
"420.94800","35.07906","0.14388"
"421.34400","35.11212","0.14280"
"421.74000","35.14519","0.14372"
"422.13600","35.17807","0.14389"
"422.53200","35.21107","0.14415"
"422.92800","35.24414","0.14428"
"423.32400","35.27714","0.14450"
"423.72000","35.31008","0.14444"
"424.11600","35.34309","0.14507"
"424.51200","35.37609","0.14250"
"424.90800","35.40916","0.14334"
"425.30400","35.44204","0.14406"
"425.70000","35.47510","0.14421"
"426.09600","35.50817","0.14407"
"426.49200","35.54117","0.14332"
"426.88800","35.57405","0.14359"
"427.28400","35.60706","0.14399"
"427.68000","35.64012","0.14439"
"428.07600","35.67313","0.14378"
"428.47200","35.70607","0.14328"
"428.86800","35.73914","0.14348"
"429.26400","35.77208","0.14348"
"429.66000","35.80508","0.14395"
"430.05600","35.83809","0.14438"
"430.45200","35.87115","0.14430"
"430.84800","35.90416","0.14401"
"431.24400","35.93710","0.14423"
"431.64000","35.97010","0.14322"
"432.03600","36.00304","0.14340"
"432.43200","36.03611","0.14350"
"432.82800","36.06911","0.14363"
"433.22400","36.10218","0.14361"
"433.62000","36.13512","0.14379"
"434.01600","36.16806","0.14370"
"434.41200","36.20113","0.14364"
"434.80800","36.23413","0.14387"
"435.20400","36.26714","0.14427"
"435.60000","36.30008","0.14446"
"435.99600","36.33308","0.14453"
"436.39200","36.36615","0.14450"
"436.78800","36.39921","0.14493"
"437.18400","36.43209","0.14453"
"437.58000","36.46510","0.14444"
"437.97600","36.49816","0.14454"
"438.37200","36.53111","0.14476"
"438.76800","36.56411","0.14522"
"439.16400","36.59711","0.14520"
"439.56000","36.63018","0.14511"
"439.95600","36.66312","0.14551"
"440.35200","36.69606","0.14529"
"440.74800","36.72913","0.14521"
"441.14400","36.76213","0.14477"
"441.54000","36.79514","0.14511"
"441.93600","36.82808","0.14616"
"442.33200","36.86108","0.14563"
"442.72800","36.89408","0.14610"
"443.12400","36.92715","0.14607"
"443.52000","36.96009","0.14647"
"443.91600","36.99316","0.14659"
"444.31200","37.02617","0.14625"
"444.70800","37.05910","0.14671"
"445.10400","37.09211","0.14637"
"445.50000","37.12511","0.14642"
"445.89600","37.15818","0.14675"
"446.29200","37.19106","0.14694"
"446.68800","37.22406","0.14657"
"447.08400","37.25713","0.14655"
"447.48000","37.29013","0.14614"
"447.87600","37.32308","0.14700"
"448.27200","37.35614","0.14717"
"448.66800","37.38908","0.14728"
"449.06400","37.42209","0.14781"
"449.46000","37.45509","0.14771"
"449.85600","37.48816","0.14784"
"450.25200","37.52110","0.14791"
"450.64800","37.55410","0.14822"
"451.04400","37.58711","0.14791"
"451.44000","37.62011","0.14911"
"451.83600","37.65311","0.14863"
"452.23200","37.68612","0.14883"
"452.62800","37.71912","0.14892"
"453.02400","37.75213","0.14914"
"453.42000","37.78513","0.14929"
"453.81600","37.81802","0.14979"
"454.21200","37.85114","0.14951"
"454.60800","37.88420","0.15014"
"455.00400","37.91709","0.15050"
"455.40000","37.95003","0.15085"
"455.79600","37.98315","0.14986"
"456.19200","38.01616","0.15051"
"456.58800","38.04910","0.14974"
"456.98400","38.08211","0.14981"
"457.38000","38.11511","0.15060"
"457.77600","38.14817","0.15058"
"458.17200","38.18112","0.15084"
"458.56800","38.21412","0.15046"
"458.96400","38.24713","0.15140"
"459.36000","38.28013","0.15162"
"459.75600","38.31307","0.15190"
"460.15200","38.34608","0.15197"
"460.54800","38.37914","0.15245"
"460.94400","38.41215","0.15257"
"461.34000","38.44509","0.15358"
"461.73600","38.47809","0.15359"
"462.13200","38.51110","0.15354"
"462.52800","38.54416","0.15345"
"462.92400","38.57704","0.15433"
"463.32000","38.61011","0.15440"
"463.71600","38.64311","0.15416"
"464.11200","38.67612","0.15479"
"464.50800","38.70912","0.15456"
"464.90400","38.74212","0.15457"
"465.30000","38.77507","0.15511"
"465.69600","38.80807","0.15503"
"466.09200","38.84108","0.15543"
"466.48800","38.87414","0.15557"
"466.88400","38.90714","0.15586"
"467.28000","38.94009","0.15578"
"467.67600","38.97315","0.15306"
"468.07200","39.00610","0.15337"
"468.46800","39.03904","0.15418"
"468.86400","39.07210","0.15439"
"469.26000","39.10516","0.15493"
"469.65600","39.13811","0.15479"
"470.05200","39.17112","0.15471"
"470.44800","39.20406","0.15504"
"470.84400","39.23712","0.15505"
"471.24000","39.27013","0.15503"
"471.63600","39.30306","0.15495"
"472.03200","39.33607","0.15506"
"472.42800","39.36913","0.15538"
"472.82400","39.40214","0.15531"
"473.22000","39.43509","0.15441"
"473.61600","39.46809","0.15419"
"474.01200","39.50115","0.15473"
"474.40800","39.53416","0.15464"
"474.80400","39.56709","0.15455"
"475.20000","39.60016","0.15389"
"475.59600","39.63311","0.15417"
"475.99200","39.66611","0.15447"
"476.38800","39.69912","0.15439"
"476.78400","39.73206","0.15464"
"477.18000","39.76512","0.14608"
"477.57600","39.79813","0.14576"
"477.97200","39.83107","0.14649"
"478.36800","39.86413","0.14622"
"478.76400","39.89714","0.14655"
"479.16000","39.93008","0.14691"
"479.55600","39.96309","0.14823"
"479.95200","39.99615","0.14774"
"480.34800","40.02915","0.14768"
"480.74400","40.06209","0.14839"
"481.14000","40.09510","0.14830"
"481.53600","40.12816","0.14802"
"481.93200","40.16111","0.14917"
"482.32800","40.19405","0.14833"
"482.72400","40.22712","0.14875"
"483.12000","40.26006","0.14870"
"483.51600","40.29312","0.14880"
"483.91200","40.32612","0.14979"
"484.30800","40.35913","0.14910"
"484.70400","40.39207","0.14814"
"485.10000","40.42508","0.14878"
"485.49600","40.45808","0.14899"
"485.89200","40.49115","0.14893"
"486.28800","40.52409","0.14921"
"486.68400","40.55709","0.14920"
"487.08000","40.59010","0.14935"
"487.47600","40.62310","0.14945"
"487.87200","40.65617","0.14952"
"488.26800","40.68905","0.14993"
"488.66400","40.72211","0.14982"
"489.06000","40.75518","0.15019"
"489.45600","40.78818","0.15032"
"489.85200","40.82106","0.15037"
"490.24800","40.85413","0.15037"
"490.64400","40.88713","0.14931"
"491.04000","40.92014","0.15000"
"491.43600","40.95308","0.14825"
"491.83200","40.98614","0.14774"
"492.22800","41.01915","0.14798"
"492.62400","41.05215","0.14842"
"493.02000","41.08509","0.14816"
"493.41600","41.11810","0.14830"
"493.81200","41.15116","0.14884"
"494.20800","41.18411","0.14895"
"494.60400","41.21711","0.14870"
"495.00000","41.25011","0.14863"
"495.39600","41.28318","0.14923"
"495.79200","41.31606","0.14850"
"496.18800","41.34912","0.14913"
"496.58400","41.38213","0.14936"
"496.98000","41.41513","0.14938"
"497.37600","41.44808","0.14881"
"497.77200","41.48114","0.14948"
"498.16800","41.51415","0.14921"
"498.56400","41.54708","0.14886"
"498.96000","41.58009","0.14943"
"499.35600","41.61316","0.14923"
"499.75200","41.64610","0.14973"
"500.14800","41.67904","0.14911"
"500.54400","41.71211","0.14868"
"500.94000","41.74511","0.14900"
"501.33600","41.77812","0.14834"
"501.73200","41.81106","0.14819"
"502.12800","41.84412","0.14854"
"502.52400","41.87713","0.14751"
"502.92000","41.91013","0.14733"
"503.31600","41.94308","0.14748"
"503.71200","41.97608","0.14754"
"504.10800","42.00914","0.14769"
"504.50400","42.04214","0.14796"
"504.90000","42.07503","0.14750"
"505.29600","42.10815","0.14761"
"505.69200","42.14116","0.14778"
"506.08800","42.17410","0.14780"
"506.48400","42.20705","0.14717"
"506.88000","42.24010","0.14683"
"507.27600","42.27311","0.14691"
"507.67200","42.30611","0.14678"
"508.06800","42.33906","0.14674"
"508.46400","42.37218","0.14707"
"508.86000","42.40513","0.14653"
"509.25600","42.43808","0.14687"
"509.65200","42.47107","0.14674"
"510.04800","42.50414","0.14704"
"510.44400","42.53714","0.14657"
"510.84000","42.57009","0.14704"
"511.23600","42.60310","0.14685"
"511.63200","42.63615","0.14722"
"512.02800","42.66910","0.14701"
"512.42400","42.70211","0.14750"
"512.82000","42.73511","0.14809"
"513.21600","42.76811","0.14781"
"513.61200","42.80106","0.14754"
"514.00800","42.83412","0.14784"
"514.40400","42.86712","0.14785"
"514.80000","42.90018","0.14774"
"515.19600","42.93313","0.14847"
"515.59200","42.96613","0.14825"
"515.98800","42.99913","0.14821"
"516.38400","43.03214","0.14828"
"516.78000","43.06509","0.14917"
"517.17600","43.09815","0.14883"
"517.57200","43.13115","0.14884"
"517.96800","43.16410","0.14918"
"518.36400","43.19704","0.14975"
"518.76000","43.23010","0.14965"
"519.15600","43.26310","0.14969"
"519.55200","43.29611","0.14921"
"519.94800","43.32906","0.14905"
"520.34400","43.36212","0.14950"
"520.74000","43.39512","0.14970"
"521.13600","43.42806","0.14960"
"521.53200","43.46107","0.14912"
"521.92800","43.49414","0.14917"
"522.32400","43.52720","0.14915"
"522.72000","43.56009","0.14879"
"523.11600","43.59309","0.14880"
"523.51200","43.62615","0.14881"
"523.90800","43.65910","0.14933"
"524.30400","43.69204","0.14976"
"524.70000","43.72510","0.14881"
"525.09600","43.75816","0.14927"
"525.49200","43.79117","0.14927"
"525.88800","43.82405","0.14999"
"526.28400","43.85712","0.14924"
"526.68000","43.89012","0.14969"
"527.07600","43.92313","0.14991"
"527.47200","43.95613","0.14958"
"527.86800","43.98913","0.15012"
"528.26400","44.02214","0.15024"
"528.66000","44.05514","0.15029"
"529.05600","44.08809","0.14994"
"529.45200","44.12109","0.14994"
"529.84800","44.15415","0.14987"
"530.24400","44.18716","0.15017"
"530.64000","44.22010","0.14862"
"531.03600","44.25316","0.14885"
"531.43200","44.28617","0.14862"
"531.82800","44.31905","0.14890"
"532.22400","44.35212","0.14915"
"532.62000","44.38518","0.14857"
"533.01600","44.41806","0.14874"
"533.41200","44.45107","0.14935"
"533.80800","44.48419","0.14931"
"534.20400","44.51707","0.14971"
"534.60000","44.55008","0.14943"
"534.99600","44.58308","0.14998"
"535.39200","44.61609","0.15032"
"535.78800","44.64909","0.15006"
"536.18400","44.68209","0.14966"
"536.58000","44.71510","0.14982"
"536.97600","44.74816","0.15027"
"537.37200","44.78111","0.15047"
"537.76800","44.81405","0.15023"
"538.16400","44.84711","0.15006"
"538.56000","44.88012","0.14973"
"538.95600","44.91312","0.14960"
"539.35200","44.94607","0.14978"
"539.74800","44.97913","0.14969"
"540.14400","45.01213","0.14968"
"540.54000","45.04514","0.15005"
"540.93600","45.07808","0.15010"
"541.33200","45.11115","0.15004"
"541.72800","45.14415","0.14991"
"542.12400","45.17709","0.15040"
"542.52000","45.21009","0.15087"
"542.91600","45.24316","0.15040"
"543.31200","45.27617","0.15078"
"543.70800","45.30911","0.15065"
"544.10400","45.34211","0.15102"
"544.50000","45.37511","0.15038"
"544.89600","45.40812","0.15101"
"545.29200","45.44112","0.15076"
"545.68800","45.47406","0.15067"
"546.08400","45.50707","0.15085"
"546.48000","45.54008","0.15056"
"546.87600","45.57302","0.15100"
"547.27200","45.60614","0.15079"
"547.66800","45.63914","0.15069"
"548.06400","45.67215","0.15153"
"548.46000","45.70509","0.15142"
"548.85600","45.73809","0.15149"
"549.25200","45.77110","0.15176"
"549.64800","45.80410","0.15155"
"550.04400","45.83711","0.15171"
"550.44000","45.87017","0.15175"
"550.83600","45.90312","0.15181"
"551.23200","45.93612","0.15138"
"551.62800","45.96912","0.15103"
"552.02400","46.00212","0.15161"
"552.42000","46.03513","0.15117"
"552.81600","46.06808","0.15116"
"553.21200","46.10114","0.15134"
"553.60800","46.13414","0.15119"
"554.00400","46.16708","0.15120"
"554.40000","46.20009","0.15152"
"554.79600","46.23309","0.15155"
"555.19200","46.26610","0.15118"
"555.58800","46.29910","0.15081"
"555.98400","46.33211","0.15089"
"556.38000","46.36511","0.15119"
"556.77600","46.39817","0.15108"
"557.17200","46.43112","0.15172"
"557.56800","46.46406","0.15195"
"557.96400","46.49712","0.15172"
"558.36000","46.53019","0.15146"
"558.75600","46.56307","0.15159"
"559.15200","46.59608","0.15196"
"559.54800","46.62914","0.15138"
"559.94400","46.66209","0.15021"
"560.34000","46.69508","0.15012"
"560.73600","46.72815","0.15048"
"561.13200","46.76110","0.15111"
"561.52800","46.79416","0.15098"
"561.92400","46.82710","0.15113"
"562.32000","46.86011","0.15137"
"562.71600","46.89311","0.15153"
"563.11200","46.92611","0.15177"
"563.50800","46.95912","0.15144"
"563.90400","46.99212","0.15181"
"564.30000","47.02518","0.15210"
"564.69600","47.05807","0.15221"
"565.09200","47.09113","0.15242"
"565.48800","47.12414","0.15209"
"565.88400","47.15714","0.15218"
"566.28000","47.19002","0.15208"
"566.67600","47.22315","0.15248"
"567.07200","47.25615","0.15254"
"567.46800","47.28910","0.15217"
"567.86400","47.32204","0.15267"
"568.26000","47.35510","0.15290"
"568.65600","47.38817","0.15269"
"569.05200","47.42111","0.15317"
"569.44800","47.45412","0.15327"
"569.84400","47.48718","0.15337"
"570.24000","47.52012","0.15371"
"570.63600","47.55307","0.15372"
"571.03200","47.58613","0.15313"
"571.42800","47.61914","0.15286"
"571.82400","47.65214","0.15242"
"572.22000","47.68508","0.15327"
"572.61600","47.71809","0.15316"
"573.01200","47.75115","0.15412"
"573.40800","47.78415","0.15196"
"573.80400","47.81704","0.15244"
"574.20000","47.85010","0.15219"
"574.59600","47.88311","0.15194"
"574.99200","47.91617","0.15151"
"575.38800","47.94911","0.15134"
"575.78400","47.98212","0.15151"
"576.18000","48.01512","0.15136"
"576.57600","48.04812","0.15122"
"576.97200","48.08107","0.15130"
"577.36800","48.11407","0.15150"
"577.76400","48.14714","0.15174"
"578.16000","48.18008","0.15113"
"578.55600","48.21315","0.15145"
"578.95200","48.24609","0.15186"
"579.34800","48.27915","0.15201"
"579.74400","48.31210","0.15230"
"580.14000","48.34510","0.15191"
"580.53600","48.37811","0.15257"
"580.93200","48.41111","0.15196"
"581.32800","48.44405","0.15227"
"581.72400","48.47717","0.15205"
"582.12000","48.51012","0.15212"
"582.51600","48.54312","0.15217"
"582.91200","48.57600","0.15221"
"583.30800","48.60913","0.15270"
"583.70400","48.64214","0.15290"
"584.10000","48.67508","0.15200"
"584.49600","48.70808","0.15169"
"584.89200","48.74114","0.15203"
"585.28800","48.77415","0.15214"
"585.68400","48.80704","0.15243"
"586.08000","48.84010","0.15224"
"586.47600","48.87317","0.15186"
"586.87200","48.90610","0.15220"
"587.26800","48.93904","0.15254"
"587.66400","48.97218","0.15258"
"588.06000","49.00517","0.15300"
"588.45600","49.03812","0.15238"
"588.85200","49.07107","0.15291"
"588.91200","49.07608","0.15303"