File: Force_trajectories/161218_2/Specimen_RawData_4.csv
End date,"12/18/2016"
Specimen label,"16DG_31"
Maximum Load,"0.03697",N

Time,Extension,Load
(s),(mm),(N)
"0.00000","0.00000","0.00006"
"0.31800","0.02613","0.00030"
"0.63600","0.05315","0.00022"
"0.95400","0.07970","0.00053"
"1.27200","0.10619","0.00053"
"1.59000","0.13267","0.00047"
"1.90800","0.15910","0.00045"
"2.22600","0.18571","0.00052"
"2.54400","0.21219","0.00085"
"2.86200","0.23868","0.00082"
"3.18000","0.26523","0.00063"
"3.49800","0.29165","0.00104"
"3.81600","0.31820","0.00091"
"4.13400","0.34469","0.00048"
"4.45200","0.37117","0.00068"
"4.77000","0.39772","0.00069"
"5.08800","0.42415","0.00108"
"5.40600","0.45075","0.00086"
"5.72400","0.47718","0.00125"
"6.04200","0.50367","0.00092"
"6.36000","0.53009","0.00073"
"6.67800","0.55664","0.00043"
"6.99600","0.58325","0.00094"
"7.31400","0.60967","0.00130"
"7.63200","0.63622","0.00076"
"7.95000","0.66265","0.00068"
"8.26800","0.68913","0.00083"
"8.58600","0.71568","0.00118"
"8.90400","0.74211","0.00114"
"9.22200","0.76865","0.00114"
"9.54000","0.79514","0.00109"
"9.85800","0.82169","0.00065"
"10.17600","0.84823","0.00111"
"10.49400","0.87466","0.00090"
"10.81200","0.90115","0.00071"
"11.13000","0.92763","0.00028"
"11.44800","0.95424","0.00144"
"11.76600","0.98073","0.00100"
"12.08400","1.00715","0.00097"
"12.40200","1.03370","0.00038"
"12.72000","1.06013","0.00102"
"13.03800","1.08667","0.00068"
"13.35600","1.11316","0.00091"
"13.67400","1.13965","0.00066"
"13.99200","1.16619","0.00072"
"14.31000","1.19262","0.00103"
"14.62800","1.21917","0.00072"
"14.94600","1.24566","0.00103"
"15.26400","1.27214","0.00104"
"15.58200","1.29869","0.00063"
"15.90000","1.32518","0.00106"
"16.21800","1.35172","0.00102"
"16.53600","1.37815","0.00061"
"16.85400","1.40464","0.00110"
"17.17200","1.43124","0.00079"
"17.49000","1.45767","0.00035"
"17.80800","1.48422","0.00082"
"18.12600","1.51064","0.00070"
"18.44400","1.53719","0.00067"
"18.76200","1.56368","0.00107"
"19.08000","1.59016","0.00072"
"19.39800","1.61665","0.00067"
"19.71600","1.64314","0.00046"
"20.03400","1.66968","0.00066"
"20.35200","1.69623","0.00051"
"20.67000","1.72260","0.00075"
"20.98800","1.74914","0.00051"
"21.30600","1.77563","0.00062"
"21.62400","1.80218","0.00092"
"21.94200","1.82866","0.00069"
"22.26000","1.85515","0.00063"
"22.57800","1.88170","0.00049"
"22.89600","1.90812","0.00020"
"23.21400","1.93473","0.00059"
"23.53200","1.96110","0.00050"
"23.85000","1.98764","0.00045"
"24.16800","2.01419","0.00042"
"24.48600","2.04068","0.00049"
"24.80400","2.06722","0.00033"
"25.12200","2.09365","0.00088"
"25.44000","2.12014","0.00029"
"25.75800","2.14668","0.00056"
"26.07600","2.17317","0.00088"
"26.39400","2.19972","0.00071"
"26.71200","2.22614","0.00036"
"27.03000","2.25269","0.00064"
"27.34800","2.27924","0.00062"
"27.66600","2.30566","0.00064"
"27.98400","2.33221","0.00076"
"28.30200","2.35864","0.00068"
"28.62000","2.38518","0.00081"
"28.93800","2.41167","0.00055"
"29.25600","2.43816","0.00087"
"29.57400","2.46470","0.00045"
"29.89200","2.49113","0.00026"
"30.21000","2.51768","0.00062"
"30.52800","2.54422","0.00049"
"30.84600","2.57071","0.00058"
"31.16400","2.59720","0.00026"
"31.48200","2.62362","0.00042"
"31.80000","2.65017","0.00040"
"32.11800","2.67666","0.00070"
"32.43600","2.70320","0.00052"
"32.75400","2.72969","0.00060"
"33.07200","2.75618","0.00064"
"33.39000","2.78272","0.00094"
"33.70800","2.80921","0.00055"
"34.02600","2.83570","0.00051"
"34.34400","2.86218","0.00044"
"34.66200","2.88867","0.00044"
"34.98000","2.91522","0.00065"
"35.29800","2.94165","0.00059"
"35.61600","2.96819","0.00087"
"35.93400","2.99462","0.00055"
"36.25200","3.02117","0.00056"
"36.57000","3.04771","0.00009"
"36.88800","3.07414","0.00080"
"37.20600","3.10075","0.00034"
"37.52400","3.12717","0.00057"
"37.84200","3.15372","0.00061"
"38.16000","3.18027","0.00057"
"38.47800","3.20663","0.00039"
"38.79600","3.23318","0.00050"
"39.11400","3.25967","0.00078"
"39.43200","3.28621","0.00079"
"39.75000","3.31270","0.00065"
"40.06800","3.33913","0.00052"
"40.38600","3.36567","0.00038"
"40.70400","3.39216","0.00050"
"41.02200","3.41871","0.00032"
"41.34000","3.44519","0.00068"
"41.65800","3.47168","0.00041"
"41.97600","3.49817","0.00074"
"42.29400","3.52465","0.00052"
"42.61200","3.55120","0.00065"
"42.93000","3.57769","0.00081"
"43.24800","3.60411","0.00092"
"43.56600","3.63072","0.00073"
"43.88400","3.65715","0.00043"
"44.20200","3.68369","0.00055"
"44.52000","3.71018","0.00084"
"44.83800","3.73667","0.00022"
"45.15600","3.76321","0.00093"
"45.47400","3.78964","0.00065"
"45.79200","3.81619","0.00072"
"46.11000","3.84267","0.00072"
"46.42800","3.86916","0.00069"
"46.74600","3.89571","0.00077"
"47.06400","3.92213","0.00084"
"47.38200","3.94868","0.00094"
"47.70000","3.97511","0.00104"
"48.01800","4.00171","0.00043"
"48.33600","4.02820","0.00027"
"48.65400","4.05463","0.00088"
"48.97200","4.08117","0.00109"
"49.29000","4.10760","0.00066"
"49.60800","4.13421","0.00096"
"49.92600","4.16063","0.00070"
"50.24400","4.18718","0.00072"
"50.56200","4.21367","0.00081"
"50.88000","4.24015","0.00080"
"51.19800","4.26670","0.00101"
"51.51600","4.29319","0.00080"
"51.83400","4.31967","0.00044"
"52.15200","4.34616","0.00084"
"52.47000","4.37265","0.00071"
"52.78800","4.39919","0.00084"
"53.10600","4.42562","0.00117"
"53.42400","4.45211","0.00057"
"53.74200","4.47871","0.00069"
"54.06000","4.50514","0.00100"
"54.37800","4.53169","0.00113"
"54.69600","4.55812","0.00108"
"55.01400","4.58466","0.00100"
"55.33200","4.61121","0.00078"
"55.65000","4.63763","0.00090"
"55.96800","4.66418","0.00099"
"56.28600","4.69061","0.00062"
"56.60400","4.71715","0.00100"
"56.92200","4.74370","0.00047"
"57.24000","4.77019","0.00069"
"57.55800","4.79673","0.00107"
"57.87600","4.82316","0.00112"
"58.19400","4.84971","0.00082"
"58.51200","4.87619","0.00093"
"58.83000","4.90268","0.00028"
"59.14800","4.92917","0.00061"
"59.46600","4.95560","0.00080"
"59.78400","4.98220","0.00063"
"60.10200","5.00863","0.00054"
"60.42000","5.03517","0.00099"
"60.73800","5.06166","0.00046"
"61.05600","5.08815","0.00061"
"61.37400","5.11470","0.00095"
"61.69200","5.14112","0.00100"
"62.01000","5.16767","0.00068"
"62.32800","5.19416","0.00087"
"62.64600","5.22064","0.00094"
"62.96400","5.24719","0.00105"
"63.28200","5.27368","0.00068"
"63.60000","5.30016","0.00055"
"63.91800","5.32671","0.00102"
"64.23600","5.35314","0.00122"
"64.55400","5.37974","0.00114"
"64.87200","5.40611","0.00092"
"65.19000","5.43272","0.00087"
"65.50800","5.45914","0.00087"
"65.82600","5.48569","0.00117"
"66.14400","5.51224","0.00072"
"66.46200","5.53866","0.00073"
"66.78000","5.56521","0.00112"
"67.09800","5.59170","0.00053"
"67.41600","5.61824","0.00107"
"67.73400","5.64467","0.00096"
"68.05200","5.67116","0.00116"
"68.37000","5.69770","0.00147"
"68.68800","5.72413","0.00085"
"69.00600","5.75068","0.00115"
"69.32400","5.77716","0.00132"
"69.64200","5.80365","0.00114"
"69.96000","5.83020","0.00136"
"70.27800","5.85668","0.00127"
"70.59600","5.88317","0.00095"
"70.91400","5.90966","0.00094"
"71.23200","5.93614","0.00106"
"71.55000","5.96269","0.00087"
"71.86800","5.98918","0.00091"
"72.18600","6.01566","0.00102"
"72.50400","6.04215","0.00120"
"72.82200","6.06864","0.00112"
"73.14000","6.09518","0.00121"
"73.45800","6.12161","0.00110"
"73.77600","6.14816","0.00116"
"74.09400","6.17458","0.00126"
"74.41200","6.20119","0.00106"
"74.73000","6.22768","0.00123"
"75.04800","6.25411","0.00165"
"75.36600","6.28065","0.00125"
"75.68400","6.30708","0.00126"
"76.00200","6.33374","0.00099"
"76.32000","6.36023","0.00129"
"76.63800","6.38666","0.00156"
"76.95600","6.41315","0.00128"
"77.27400","6.43957","0.00114"
"77.59200","6.46618","0.00115"
"77.91000","6.49266","0.00147"
"78.22800","6.51921","0.00176"
"78.54600","6.54570","0.00160"
"78.86400","6.57212","0.00111"
"79.18200","6.59867","0.00141"
"79.50000","6.62516","0.00171"
"79.81800","6.65165","0.00174"
"80.13600","6.67819","0.00147"
"80.45400","6.70462","0.00171"
"80.77200","6.73123","0.00157"
"81.09000","6.75765","0.00167"
"81.40800","6.78414","0.00181"
"81.72600","6.81069","0.00138"
"82.04400","6.83717","0.00157"
"82.36200","6.86372","0.00175"
"82.68000","6.89015","0.00153"
"82.99800","6.91663","0.00163"
"83.31600","6.94318","0.00206"
"83.63400","6.96967","0.00151"
"83.95200","6.99615","0.00149"
"84.27000","7.02264","0.00160"
"84.58800","7.04919","0.00168"
"84.90600","7.07567","0.00150"
"85.22400","7.10216","0.00184"
"85.54200","7.12865","0.00183"
"85.86000","7.15513","0.00169"
"86.17800","7.18168","0.00182"
"86.49600","7.20817","0.00233"
"86.81400","7.23465","0.00200"
"87.13200","7.26120","0.00205"
"87.45000","7.28763","0.00220"
"87.76800","7.31417","0.00200"
"88.08600","7.34066","0.00200"
"88.40400","7.36715","0.00203"
"88.72200","7.39369","0.00208"
"89.04000","7.42012","0.00203"
"89.35800","7.44667","0.00211"
"89.67600","7.47315","0.00203"
"89.99400","7.49964","0.00219"
"90.31200","7.52619","0.00223"
"90.63000","7.55267","0.00224"
"90.94800","7.57922","0.00241"
"91.26600","7.60565","0.00247"
"91.58400","7.63219","0.00223"
"91.90200","7.65868","0.00271"
"92.22000","7.68517","0.00217"
"92.53800","7.71165","0.00255"
"92.85600","7.73808","0.00233"
"93.17400","7.76469","0.00223"
"93.49200","7.79117","0.00215"
"93.81000","7.81766","0.00216"
"94.12800","7.84421","0.00221"
"94.44600","7.87063","0.00240"
"94.76400","7.89712","0.00238"
"95.08200","7.92367","0.00219"
"95.40000","7.95021","0.00231"
"95.71800","7.97664","0.00210"
"96.03600","8.00319","0.00195"
"96.35400","8.02967","0.00215"
"96.67200","8.05616","0.00251"
"96.99000","8.08271","0.00259"
"97.30800","8.10919","0.00281"
"97.62600","8.13568","0.00251"
"97.94400","8.16217","0.00250"
"98.26200","8.18865","0.00291"
"98.58000","8.21520","0.00302"
"98.89800","8.24169","0.00291"
"99.21600","8.26812","0.00233"
"99.53400","8.29472","0.00287"
"99.85200","8.32115","0.00253"
"100.17000","8.34769","0.00325"
"100.48800","8.37412","0.00255"
"100.80600","8.40061","0.00279"
"101.12400","8.42716","0.00288"
"101.44200","8.45364","0.00302"
"101.76000","8.48025","0.00292"
"102.07800","8.50662","0.00347"
"102.39600","8.53316","0.00260"
"102.71400","8.55971","0.00339"
"103.03200","8.58614","0.00312"
"103.35000","8.61262","0.00285"
"103.66800","8.63911","0.00323"
"103.98600","8.66572","0.00312"
"104.30400","8.69220","0.00318"
"104.62200","8.71863","0.00319"
"104.94000","8.74518","0.00302"
"105.25800","8.77160","0.00302"
"105.57600","8.79815","0.00292"
"105.89400","8.82464","0.00296"
"106.21200","8.85112","0.00301"
"106.53000","8.87767","0.00314"
"106.84800","8.90416","0.00328"
"107.16600","8.93070","0.00344"
"107.48400","8.95719","0.00330"
"107.80200","8.98368","0.00350"
"108.12000","9.01016","0.00318"
"108.43800","9.03665","0.00335"
"108.75600","9.06320","0.00357"
"109.07400","9.08962","0.00339"
"109.39200","9.11617","0.00366"
"109.71000","9.14266","0.00337"
"110.02800","9.16914","0.00358"
"110.34600","9.19569","0.00376"
"110.66400","9.22212","0.00405"
"110.98200","9.24866","0.00399"
"111.30000","9.27521","0.00383"
"111.61800","9.30164","0.00408"
"111.93600","9.32818","0.00408"
"112.25400","9.35461","0.00416"
"112.57200","9.38122","0.00409"
"112.89000","9.40770","0.00425"
"113.20800","9.43419","0.00447"
"113.52600","9.46074","0.00426"
"113.84400","9.48710","0.00427"
"114.16200","9.51371","0.00434"
"114.48000","9.54020","0.00436"
"114.79800","9.56668","0.00440"
"115.11600","9.59317","0.00495"
"115.43400","9.61960","0.00435"
"115.75200","9.64620","0.00469"
"116.07000","9.67269","0.00449"
"116.38800","9.69918","0.00495"
"116.70600","9.72572","0.00460"
"117.02400","9.75215","0.00479"
"117.34200","9.77876","0.00468"
"117.66000","9.80518","0.00436"
"117.97800","9.83167","0.00485"
"118.29600","9.85816","0.00473"
"118.61400","9.88464","0.00473"
"118.93200","9.91119","0.00442"
"119.25000","9.93762","0.00477"
"119.56800","9.96417","0.00454"
"119.88600","9.99065","0.00437"
"120.20400","10.01720","0.00500"
"120.52200","10.04375","0.00482"
"120.84000","10.07011","0.00463"
"121.15800","10.09666","0.00462"
"121.47600","10.12315","0.00491"
"121.79400","10.14969","0.00500"
"122.11200","10.17618","0.00495"
"122.43000","10.20267","0.00506"
"122.74800","10.22915","0.00536"
"123.06600","10.25570","0.00503"
"123.38400","10.28218","0.00522"
"123.70200","10.30873","0.00529"
"124.02000","10.33510","0.00522"
"124.33800","10.36170","0.00568"
"124.65600","10.38813","0.00522"
"124.97400","10.41468","0.00592"
"125.29200","10.44123","0.00554"
"125.61000","10.46759","0.00554"
"125.92800","10.49420","0.00500"
"126.24600","10.52063","0.00567"
"126.56400","10.54717","0.00499"
"126.88200","10.57366","0.00482"
"127.20000","10.60015","0.00451"
"127.51800","10.62669","0.00402"
"127.83600","10.65312","0.00340"
"128.15400","10.67973","0.00334"
"128.47200","10.70615","0.00322"
"128.79000","10.73264","0.00299"
"129.10800","10.75925","0.00310"
"129.42600","10.78567","0.00344"
"129.74400","10.81222","0.00320"
"130.06200","10.83865","0.00302"
"130.38000","10.86519","0.00244"
"130.69800","10.89174","0.00284"
"131.01600","10.91817","0.00293"
"131.33400","10.94465","0.00280"
"131.65200","10.97114","0.00313"
"131.97000","10.99775","0.00283"
"132.28800","11.02423","0.00276"
"132.60600","11.05066","0.00343"
"132.92400","11.07715","0.00316"
"133.24200","11.10357","0.00319"
"133.56000","11.13018","0.00356"
"133.87800","11.15667","0.00316"
"134.19600","11.18315","0.00351"
"134.51400","11.20970","0.00377"
"134.83200","11.23613","0.00356"
"135.15000","11.26273","0.00381"
"135.46800","11.28910","0.00395"
"135.78600","11.31565","0.00379"
"136.10400","11.34219","0.00360"
"136.42200","11.36868","0.00384"
"136.74000","11.39523","0.00424"
"137.05800","11.42165","0.00419"
"137.37600","11.44820","0.00420"
"137.69400","11.47463","0.00418"
"138.01200","11.50111","0.00399"
"138.33000","11.52766","0.00444"
"138.64800","11.55415","0.00450"
"138.96600","11.58063","0.00445"
"139.28400","11.60718","0.00467"
"139.60200","11.63367","0.00430"
"139.92000","11.66016","0.00460"
"140.23800","11.68664","0.00465"
"140.55600","11.71319","0.00461"
"140.87400","11.73973","0.00466"
"141.19200","11.76616","0.00503"
"141.51000","11.79271","0.00492"
"141.82800","11.81907","0.00473"
"142.14600","11.84574","0.00509"
"142.46400","11.87223","0.00489"
"142.78200","11.89872","0.00492"
"143.10000","11.92520","0.00529"
"143.41800","11.95163","0.00540"
"143.73600","11.97823","0.00539"
"144.05400","12.00466","0.00541"
"144.37200","12.03115","0.00544"
"144.69000","12.05769","0.00562"
"145.00800","12.08418","0.00554"
"145.32600","12.11067","0.00597"
"145.64400","12.13715","0.00537"
"145.96200","12.16364","0.00573"
"146.28000","12.19013","0.00558"
"146.59800","12.21667","0.00594"
"146.91600","12.24316","0.00569"
"147.23400","12.26965","0.00606"
"147.55200","12.29620","0.00604"
"147.87000","12.32268","0.00603"
"148.18800","12.34917","0.00584"
"148.50600","12.37572","0.00647"
"148.82400","12.40214","0.00636"
"149.14200","12.42869","0.00601"
"149.46000","12.45518","0.00674"
"149.77800","12.48172","0.00692"
"150.09600","12.50821","0.00668"
"150.41400","12.53464","0.00632"
"150.73200","12.56118","0.00690"
"151.05000","12.58767","0.00660"
"151.36800","12.61422","0.00702"
"151.68600","12.64070","0.00716"
"152.00400","12.66713","0.00709"
"152.32200","12.69368","0.00696"
"152.64000","12.72016","0.00716"
"152.95800","12.74671","0.00745"
"153.27600","12.77320","0.00807"
"153.59400","12.79962","0.00800"
"153.91200","12.82617","0.00774"
"154.23000","12.85260","0.00805"
"154.54800","12.87920","0.00789"
"154.86600","12.90569","0.00772"
"155.18400","12.93218","0.00820"
"155.50200","12.95872","0.00779"
"155.82000","12.98515","0.00818"
"156.13800","13.01170","0.00831"
"156.45600","13.03813","0.00836"
"156.77400","13.06461","0.00795"
"157.09200","13.09116","0.00827"
"157.41000","13.11765","0.00805"
"157.72800","13.14419","0.00838"
"158.04600","13.17068","0.00820"
"158.36400","13.19716","0.00866"
"158.68200","13.22371","0.00866"
"159.00000","13.25014","0.00887"
"159.31800","13.27668","0.00912"
"159.63600","13.30311","0.00923"
"159.95400","13.32972","0.00909"
"160.27200","13.35620","0.00895"
"160.59000","13.38263","0.00958"
"160.90800","13.40918","0.00895"
"161.22600","13.43561","0.00965"
"161.54400","13.46221","0.00940"
"161.86200","13.48870","0.00935"
"162.18000","13.51519","0.00947"
"162.49800","13.54167","0.00991"
"162.81600","13.56816","0.00986"
"163.13400","13.59477","0.00961"
"163.45200","13.62113","0.00945"
"163.77000","13.64768","0.00942"
"164.08800","13.67417","0.00963"
"164.40600","13.70065","0.00950"
"164.72400","13.72720","0.00974"
"165.04200","13.75363","0.00991"
"165.36000","13.78011","0.01004"
"165.67800","13.80666","0.01042"
"165.99600","13.83315","0.01031"
"166.31400","13.85969","0.01023"
"166.63200","13.88618","0.01020"
"166.95000","13.91267","0.01051"
"167.26800","13.93921","0.01034"
"167.58600","13.96564","0.01038"
"167.90400","13.99219","0.01076"
"168.22200","14.01861","0.01005"
"168.54000","14.04516","0.01045"
"168.85800","14.07171","0.01029"
"169.17600","14.09819","0.01073"
"169.49400","14.12468","0.01116"
"169.81200","14.15111","0.01059"
"170.13000","14.17771","0.01099"
"170.44800","14.20420","0.01083"
"170.76600","14.23063","0.01088"
"171.08400","14.25717","0.01088"
"171.40200","14.28360","0.01106"
"171.72000","14.31021","0.01083"
"172.03800","14.33669","0.01016"
"172.35600","14.36318","0.01063"
"172.67400","14.38967","0.01095"
"172.99200","14.41615","0.00816"
"173.31000","14.44270","0.00944"
"173.62800","14.46919","0.00975"
"173.94600","14.49567","0.00998"
"174.26400","14.52216","0.01022"
"174.58200","14.54865","0.00991"
"174.90000","14.57519","0.01052"
"175.21800","14.60162","0.01080"
"175.53600","14.62817","0.01038"
"175.85400","14.65465","0.01056"
"176.17200","14.68114","0.01032"
"176.49000","14.70769","0.01055"
"176.80800","14.73411","0.01057"
"177.12600","14.76072","0.01070"
"177.44400","14.78715","0.01034"
"177.76200","14.81369","0.01057"
"178.08000","14.84024","0.01026"
"178.39800","14.86661","0.01135"
"178.71600","14.89322","0.01058"
"179.03400","14.91964","0.01056"
"179.35200","14.94619","0.00985"
"179.67000","14.97268","0.01027"
"179.98800","14.99916","0.01077"
"180.30600","15.02565","0.01031"
"180.62400","15.05219","0.01051"
"180.94200","15.07868","0.01095"
"181.26000","15.10517","0.01084"
"181.57800","15.13165","0.01055"
"181.89600","15.15820","0.01142"
"182.21400","15.18469","0.01105"
"182.53200","15.21117","0.01116"
"182.85000","15.23772","0.01150"
"183.16800","15.26415","0.01132"
"183.48600","15.29070","0.01142"
"183.80400","15.31712","0.01138"
"184.12200","15.34367","0.01148"
"184.44000","15.37016","0.01151"
"184.75800","15.39664","0.01086"
"185.07600","15.42319","0.01081"
"185.39400","15.44962","0.01096"
"185.71200","15.47616","0.01108"
"186.03000","15.50259","0.01146"
"186.34800","15.52919","0.01178"
"186.66600","15.55568","0.01172"
"186.98400","15.58211","0.01196"
"187.30200","15.60872","0.01191"
"187.62000","15.63514","0.01184"
"187.93800","15.66175","0.01222"
"188.25600","15.68818","0.01250"
"188.57400","15.71460","0.01228"
"188.89200","15.74115","0.01261"
"189.21000","15.76764","0.01283"
"189.52800","15.79418","0.01298"
"189.84600","15.82067","0.01299"
"190.16400","15.84716","0.01306"
"190.48200","15.87364","0.01296"
"190.80000","15.90013","0.01198"
"191.11800","15.92668","0.01275"
"191.43600","15.95316","0.01307"
"191.75400","15.97965","0.01249"
"192.07200","16.00620","0.01264"
"192.39000","16.03262","0.01272"
"192.70800","16.05917","0.01260"
"193.02600","16.08566","0.01290"
"193.34400","16.11214","0.01313"
"193.66200","16.13869","0.01329"
"193.98000","16.16512","0.01321"
"194.29800","16.19166","0.01301"
"194.61600","16.21815","0.01280"
"194.93400","16.24470","0.01281"
"195.25200","16.27118","0.01235"
"195.57000","16.29767","0.01263"
"195.88800","16.32416","0.01209"
"196.20600","16.35058","0.01186"
"196.52400","16.37719","0.01183"
"196.84200","16.40368","0.01197"
"197.16000","16.43016","0.01284"
"197.47800","16.45665","0.01230"
"197.79600","16.48308","0.01294"
"198.11400","16.50968","0.01206"
"198.43200","16.53617","0.01154"
"198.75000","16.56272","0.01118"
"199.06800","16.58920","0.01150"
"199.38600","16.61563","0.01141"
"199.70400","16.64224","0.01180"
"200.02200","16.66866","0.01139"
"200.34000","16.69515","0.01160"
"200.65800","16.72164","0.01197"
"200.97600","16.74813","0.01217"
"201.29400","16.77467","0.01206"
"201.61200","16.80110","0.01248"
"201.93000","16.82764","0.01215"
"202.24800","16.85419","0.01271"
"202.56600","16.88062","0.01254"
"202.88400","16.90722","0.01266"
"203.20200","16.93359","0.01300"
"203.52000","16.96020","0.01343"
"203.83800","16.98663","0.01341"
"204.15600","17.01317","0.01374"
"204.47400","17.03972","0.01402"
"204.79200","17.06609","0.01419"
"205.11000","17.09269","0.01411"
"205.42800","17.11918","0.01492"
"205.74600","17.14573","0.01466"
"206.06400","17.17215","0.01473"
"206.38200","17.19864","0.01428"
"206.70000","17.22519","0.01481"
"207.01800","17.25167","0.01470"
"207.33600","17.27816","0.01477"
"207.65400","17.30470","0.01475"
"207.97200","17.33113","0.01523"
"208.29000","17.35762","0.01476"
"208.60800","17.38417","0.01489"
"208.92600","17.41065","0.01503"
"209.24400","17.43714","0.01524"
"209.56200","17.46363","0.01535"
"209.88000","17.49017","0.01579"
"210.19800","17.51660","0.01568"
"210.51600","17.54321","0.01562"
"210.83400","17.56969","0.01595"
"211.15200","17.59612","0.01630"
"211.47000","17.62273","0.01626"
"211.78800","17.64915","0.01579"
"212.10600","17.67570","0.01611"
"212.42400","17.70213","0.01587"
"212.74200","17.72861","0.01645"
"213.06000","17.75522","0.01673"
"213.37800","17.78165","0.01676"
"213.69600","17.80819","0.01647"
"214.01400","17.83468","0.01637"
"214.33200","17.86117","0.01694"
"214.65000","17.88765","0.01416"
"214.96800","17.91414","0.01545"
"215.28600","17.94069","0.01573"
"215.60400","17.96711","0.01591"
"215.92200","17.99372","0.01494"
"216.24000","18.02021","0.01616"
"216.55800","18.04669","0.01592"
"216.87600","18.07312","0.01585"
"217.19400","18.09961","0.01614"
"217.51200","18.12615","0.01594"
"217.83000","18.15264","0.01670"
"218.14800","18.17913","0.01670"
"218.46600","18.20568","0.01684"
"218.78400","18.23216","0.01723"
"219.10200","18.25865","0.01716"
"219.42000","18.28519","0.01762"
"219.73800","18.31168","0.01751"
"220.05600","18.33817","0.01780"
"220.37400","18.36465","0.01830"
"220.69200","18.39120","0.01802"
"221.01000","18.41763","0.01774"
"221.32800","18.44418","0.01781"
"221.64600","18.47072","0.01863"
"221.96400","18.49715","0.01838"
"222.28200","18.52369","0.01843"
"222.60000","18.55012","0.01899"
"222.91800","18.57667","0.01850"
"223.23600","18.60316","0.01848"
"223.55400","18.62958","0.01813"
"223.87200","18.65619","0.01805"
"224.19000","18.68255","0.01665"
"224.50800","18.70916","0.01537"
"224.82600","18.73571","0.01532"
"225.14400","18.76213","0.01541"
"225.46200","18.78868","0.01562"
"225.78000","18.81511","0.01541"
"226.09800","18.84171","0.01587"
"226.41600","18.86814","0.01659"
"226.73400","18.89469","0.01679"
"227.05200","18.92124","0.01670"
"227.37000","18.94760","0.01678"
"227.68800","18.97421","0.01507"
"228.00600","19.00070","0.01571"
"228.32400","19.02718","0.01611"
"228.64200","19.05367","0.01608"
"228.96000","19.08015","0.01659"
"229.27800","19.10670","0.01722"
"229.59600","19.13313","0.01685"
"229.91400","19.15968","0.01749"
"230.23200","19.18616","0.01733"
"230.55000","19.21265","0.01622"
"230.86800","19.23914","0.01683"
"231.18600","19.26562","0.01680"
"231.50400","19.29217","0.01477"
"231.82200","19.31866","0.01539"
"232.14000","19.34520","0.01569"
"232.45800","19.37169","0.01637"
"232.77600","19.39812","0.01639"
"233.09400","19.42466","0.01624"
"233.41200","19.45115","0.01785"
"233.73000","19.47770","0.01743"
"234.04800","19.50418","0.01771"
"234.36600","19.53067","0.01796"
"234.68400","19.55722","0.01823"
"235.00200","19.58370","0.01884"
"235.32000","19.61019","0.01889"
"235.63800","19.63667","0.01793"
"235.95600","19.66310","0.01875"
"236.27400","19.68965","0.01966"
"236.59200","19.71619","0.01975"
"236.91000","19.74268","0.01975"
"237.22800","19.76923","0.02024"
"237.54600","19.79560","0.01929"
"237.86400","19.82220","0.01914"
"238.18200","19.84863","0.02050"
"238.50000","19.87518","0.01981"
"238.81800","19.90166","0.02032"
"239.13600","19.92815","0.01942"
"239.45400","19.95470","0.01982"
"239.77200","19.98112","0.01982"
"240.09000","20.00767","0.01914"
"240.40800","20.03410","0.01879"
"240.72600","20.06064","0.01948"
"241.04400","20.08719","0.01988"
"241.36200","20.11362","0.01958"
"241.68000","20.14022","0.01949"
"241.99800","20.16665","0.01982"
"242.31600","20.19320","0.01998"
"242.63400","20.21968","0.02013"
"242.95200","20.24611","0.02103"
"243.27000","20.27271","0.02022"
"243.58800","20.29914","0.02064"
"243.90600","20.32569","0.01991"
"244.22400","20.35224","0.02062"
"244.54200","20.37866","0.02086"
"244.86000","20.40515","0.02079"
"245.17800","20.43164","0.02093"
"245.49600","20.45824","0.01985"
"245.81400","20.48473","0.02044"
"246.13200","20.51116","0.02076"
"246.45000","20.53770","0.02056"
"246.76800","20.56413","0.02085"
"247.08600","20.59068","0.02096"
"247.40400","20.61716","0.02096"
"247.72200","20.64365","0.02105"
"248.04000","20.67020","0.02164"
"248.35800","20.69662","0.02071"
"248.67800","20.72335","0.02103"
"248.99600","20.74977","0.02135"
"249.31400","20.77633","0.02188"
"249.63200","20.80287","0.01889"
"249.95000","20.82930","0.01929"
"250.26800","20.85584","0.02038"
"250.58600","20.88227","0.02066"
"250.90400","20.90882","0.01914"
"251.22200","20.93537","0.01906"
"251.54000","20.96179","0.01859"
"251.85800","20.98834","0.01948"
"252.17600","21.01483","0.01784"
"252.49400","21.04137","0.01778"
"252.81200","21.06786","0.01838"
"253.13000","21.09428","0.01868"
"253.44800","21.12083","0.01891"
"253.76600","21.14726","0.01939"
"254.08400","21.17386","0.02011"
"254.40200","21.20035","0.02013"
"254.72000","21.22684","0.02082"
"255.03800","21.25339","0.02048"
"255.35600","21.27981","0.02087"
"255.67400","21.30636","0.02080"
"255.99200","21.33278","0.02048"
"256.31000","21.35933","0.02043"
"256.62800","21.38582","0.02024"
"256.94600","21.41231","0.01958"
"257.26400","21.43891","0.01969"
"257.58200","21.46528","0.01927"
"257.90000","21.49183","0.01973"
"258.21800","21.51837","0.01975"
"258.53600","21.54486","0.01964"
"258.85400","21.57135","0.02004"
"259.17200","21.59777","0.02034"
"259.49000","21.62438","0.02068"
"259.80800","21.65087","0.02101"
"260.12600","21.67735","0.02045"
"260.44400","21.70384","0.02103"
"260.76200","21.73027","0.02077"
"261.08000","21.75687","0.02049"
"261.39800","21.78336","0.02050"
"261.71600","21.80984","0.02149"
"262.03400","21.83633","0.02167"
"262.35200","21.86276","0.02150"
"262.67000","21.88937","0.02107"
"262.98800","21.91585","0.02121"
"263.30600","21.94234","0.02126"
"263.62400","21.96889","0.02210"
"263.94200","21.99531","0.02212"
"264.26000","22.02186","0.02253"
"264.57800","22.04835","0.02297"
"264.89600","22.07483","0.02359"
"265.21400","22.10132","0.02253"
"265.53200","22.12781","0.02325"
"265.85000","22.15442","0.02302"
"266.16800","22.18084","0.02283"
"266.48600","22.20739","0.02337"
"266.80400","22.23387","0.02214"
"267.12200","22.26036","0.02226"
"267.44000","22.28685","0.02182"
"267.75800","22.31333","0.02180"
"268.07600","22.33988","0.02230"
"268.39400","22.36631","0.02194"
"268.71200","22.39279","0.02049"
"269.03000","22.41940","0.02124"
"269.34800","22.44583","0.02149"
"269.66600","22.47237","0.02198"
"269.98400","22.49886","0.02199"
"270.30200","22.52535","0.02265"
"270.62000","22.55190","0.02239"
"270.93800","22.57826","0.02050"
"271.25600","22.60487","0.02089"
"271.57400","22.63129","0.02090"
"271.89200","22.65784","0.02101"
"272.21000","22.68439","0.01838"
"272.52800","22.71082","0.01792"
"272.84600","22.73736","0.01783"
"273.16400","22.76385","0.01715"
"273.48200","22.79039","0.01782"
"273.80000","22.81682","0.01874"
"274.11800","22.84331","0.01871"
"274.43600","22.86986","0.01825"
"274.75400","22.89628","0.01857"
"275.07200","22.92283","0.01923"
"275.39000","22.94932","0.01933"
"275.70800","22.97586","0.01913"
"276.02600","23.00235","0.01901"
"276.34400","23.02878","0.01988"
"276.66200","23.05538","0.01927"
"276.98000","23.08181","0.01938"
"277.29800","23.10829","0.01948"
"277.61600","23.13490","0.01951"
"277.93400","23.16133","0.01849"
"278.25200","23.18782","0.01893"
"278.57000","23.21430","0.01924"
"278.88800","23.24085","0.01899"
"279.20600","23.26740","0.01924"
"279.52400","23.29376","0.01898"
"279.84200","23.32037","0.01812"
"280.16000","23.34680","0.01876"
"280.47800","23.37340","0.01857"
"280.79600","23.39989","0.01883"
"281.11400","23.42632","0.01872"
"281.43200","23.45280","0.01882"
"281.75000","23.47923","0.01913"
"282.06800","23.50589","0.02009"
"282.38600","23.53232","0.02014"
"282.70400","23.55881","0.02036"
"283.02200","23.58530","0.01999"
"283.34000","23.61178","0.01978"
"283.65800","23.63839","0.01970"
"283.97600","23.66482","0.02015"
"284.29400","23.69130","0.02011"
"284.61200","23.71785","0.01990"
"284.93000","23.74434","0.01944"
"285.24800","23.77088","0.01887"
"285.56600","23.79731","0.01910"
"285.88400","23.82380","0.01943"
"286.20200","23.85034","0.02046"
"286.52000","23.87683","0.01985"
"286.83800","23.90332","0.01838"
"287.15600","23.92986","0.01909"
"287.47400","23.95635","0.01963"
"287.79200","23.98284","0.01991"
"288.11000","24.00933","0.01973"
"288.42800","24.03587","0.01920"
"288.74600","24.06224","0.01891"
"289.06400","24.08879","0.01919"
"289.38200","24.11533","0.02021"
"289.70000","24.14182","0.01920"
"290.01800","24.16836","0.01972"
"290.33600","24.19479","0.01960"
"290.65400","24.22134","0.01979"
"290.97200","24.24782","0.01809"
"291.29000","24.27431","0.01950"
"291.60800","24.30086","0.02009"
"291.92600","24.32728","0.01898"
"292.24400","24.35389","0.01819"
"292.56200","24.38038","0.01868"
"292.88000","24.40686","0.01945"
"293.19800","24.43335","0.01955"
"293.51600","24.45984","0.01927"
"293.83400","24.48639","0.01956"
"294.15200","24.51281","0.01933"
"294.47000","24.53930","0.01934"
"294.78800","24.56585","0.01929"
"295.10600","24.59227","0.01883"
"295.42400","24.61882","0.01991"
"295.74200","24.64531","0.01939"
"296.06000","24.67185","0.01949"
"296.37800","24.69834","0.01956"
"296.69600","24.72483","0.01968"
"297.01400","24.75137","0.02004"
"297.33200","24.77774","0.02033"
"297.65000","24.80434","0.01960"
"297.96800","24.83083","0.01937"
"298.28600","24.85738","0.01909"
"298.60400","24.88387","0.01969"
"298.92200","24.91035","0.01940"
"299.24000","24.93690","0.01936"
"299.55800","24.96333","0.01980"
"299.87600","24.98987","0.01922"
"300.19400","25.01636","0.01933"
"300.51200","25.04279","0.02004"
"300.83000","25.06933","0.01942"
"301.14800","25.09582","0.01948"
"301.46600","25.12237","0.02000"
"301.78400","25.14879","0.01993"
"302.10200","25.17528","0.02023"
"302.42000","25.20183","0.02030"
"302.73800","25.22831","0.02077"
"303.05600","25.25480","0.02062"
"303.37400","25.28129","0.02070"
"303.69200","25.30777","0.02078"
"304.01000","25.33432","0.02181"
"304.32800","25.36081","0.01779"
"304.64600","25.38735","0.01862"
"304.96400","25.41384","0.01892"
"305.28200","25.44027","0.01915"
"305.60000","25.46688","0.01986"
"305.91800","25.49336","0.01997"
"306.23600","25.51991","0.02049"
"306.55400","25.54627","0.02026"
"306.87200","25.57282","0.01836"
"307.19000","25.59937","0.01803"
"307.50800","25.62580","0.01874"
"307.82600","25.65234","0.01855"
"308.14400","25.67877","0.01891"
"308.46200","25.70538","0.01930"
"308.78000","25.73180","0.01930"
"309.09800","25.75829","0.01860"
"309.41600","25.78477","0.01933"
"309.73400","25.81126","0.01977"
"310.05200","25.83787","0.01934"
"310.37000","25.86430","0.01928"
"310.68800","25.89084","0.01991"
"311.00600","25.91739","0.02018"
"311.32400","25.94382","0.02083"
"311.64200","25.97036","0.02018"
"311.96000","25.99685","0.02053"
"312.27800","26.02328","0.02072"
"312.59600","26.04982","0.02030"
"312.91400","26.07631","0.02033"
"313.23200","26.10286","0.02020"
"313.55000","26.12928","0.02025"
"313.86800","26.15583","0.01956"
"314.18600","26.18237","0.02032"
"314.50400","26.20880","0.02056"
"314.82200","26.23535","0.02084"
"315.14000","26.26171","0.02117"
"315.45800","26.28832","0.02112"
"315.77600","26.31481","0.02175"
"316.09400","26.34130","0.02158"
"316.41200","26.36784","0.02130"
"316.73000","26.39427","0.02144"
"317.04800","26.42088","0.02148"
"317.36600","26.44736","0.02193"
"317.68400","26.47385","0.02207"
"318.00200","26.50034","0.02179"
"318.32000","26.52676","0.02258"
"318.63800","26.55331","0.02252"
"318.95600","26.57985","0.02245"
"319.27400","26.60634","0.02262"
"319.59200","26.63283","0.02229"
"319.91000","26.65932","0.02248"
"320.22800","26.68586","0.02226"
"320.54600","26.71235","0.02279"
"320.86400","26.73878","0.02293"
"321.18200","26.76532","0.02292"
"321.50000","26.79181","0.02312"
"321.81800","26.81836","0.02291"
"322.13600","26.84484","0.02355"
"322.45400","26.87133","0.02361"
"322.77200","26.89782","0.02325"
"323.09000","26.92430","0.02366"
"323.40800","26.95085","0.02324"
"323.72600","26.97734","0.02294"
"324.04400","27.00388","0.02353"
"324.36200","27.03031","0.02387"
"324.68000","27.05680","0.02452"
"324.99800","27.08335","0.02414"
"325.31600","27.10977","0.02480"
"325.63400","27.13638","0.02447"
"325.95200","27.16281","0.02436"
"326.27000","27.18935","0.02431"
"326.58800","27.21590","0.02489"
"326.90600","27.24232","0.02448"
"327.22400","27.26887","0.02471"
"327.54200","27.29530","0.02480"
"327.86000","27.32185","0.02498"
"328.17800","27.34839","0.02497"
"328.49600","27.37482","0.02474"
"328.81400","27.40136","0.02448"
"329.13200","27.42785","0.02291"
"329.45000","27.45434","0.02316"
"329.76800","27.48082","0.02194"
"330.08600","27.50725","0.02269"
"330.40400","27.53386","0.02325"
"330.72200","27.56035","0.02368"
"331.04000","27.58683","0.02399"
"331.35800","27.61338","0.02449"
"331.67600","27.63981","0.02440"
"331.99400","27.66635","0.02502"
"332.31200","27.69278","0.02483"
"332.63000","27.71938","0.02444"
"332.94800","27.74581","0.02470"
"333.26600","27.77230","0.02388"
"333.58400","27.79885","0.01699"
"333.90200","27.82527","0.01779"
"334.22000","27.85188","0.01850"
"334.53800","27.87825","0.01839"
"334.85600","27.90485","0.01874"
"335.17400","27.93134","0.01954"
"335.49200","27.95777","0.02028"
"335.81000","27.98437","0.01964"
"336.12800","28.01080","0.01990"
"336.44600","28.03735","0.02124"
"336.76400","28.06383","0.02160"
"337.08200","28.09032","0.02138"
"337.40000","28.11681","0.02238"
"337.71800","28.14329","0.02237"
"338.03600","28.16984","0.02273"
"338.35400","28.19633","0.02349"
"338.67200","28.22281","0.02341"
"338.99000","28.24936","0.02372"
"339.30800","28.27579","0.02389"
"339.62600","28.30233","0.02378"
"339.94400","28.32882","0.02443"
"340.26200","28.35531","0.02468"
"340.58000","28.38185","0.02427"
"340.89800","28.40828","0.02461"
"341.21600","28.43489","0.02481"
"341.53400","28.46131","0.02228"
"341.85200","28.48780","0.02232"
"342.17000","28.51435","0.02344"
"342.48800","28.54083","0.02337"
"342.80600","28.56738","0.02362"
"343.12400","28.59387","0.02368"
"343.44200","28.62035","0.02409"
"343.76000","28.64684","0.02438"
"344.07800","28.67333","0.02476"
"344.39600","28.69981","0.02470"
"344.71400","28.72630","0.02484"
"345.03200","28.75285","0.02548"
"345.35000","28.77939","0.02587"
"345.66800","28.80588","0.02539"
"345.98600","28.83231","0.02548"
"346.30400","28.85880","0.02439"
"346.62200","28.88534","0.02442"
"346.94000","28.91189","0.02515"
"347.25800","28.93837","0.02523"
"347.57600","28.96486","0.02495"
"347.89400","28.99129","0.02551"
"348.21200","29.01783","0.02558"
"348.53000","29.04432","0.02611"
"348.84800","29.07081","0.02648"
"349.16600","29.09736","0.02673"
"349.48400","29.12378","0.02695"
"349.80200","29.15039","0.02687"
"350.12000","29.17682","0.02695"
"350.43800","29.20336","0.02721"
"350.75600","29.22979","0.02719"
"351.07400","29.25627","0.02768"
"351.39200","29.28288","0.02765"
"351.71000","29.30931","0.02786"
"352.02800","29.33586","0.02796"
"352.34600","29.36234","0.02829"
"352.66400","29.38883","0.02858"
"352.98200","29.41538","0.02610"
"353.30000","29.44180","0.02665"
"353.61800","29.46835","0.02696"
"353.93600","29.49484","0.02724"
"354.25400","29.52138","0.02684"
"354.57200","29.54787","0.02742"
"354.89000","29.57430","0.02748"
"355.20800","29.60084","0.02749"
"355.52600","29.62733","0.02670"
"355.84400","29.65381","0.02495"
"356.16200","29.68036","0.02527"
"356.48000","29.70685","0.02578"
"356.79800","29.73334","0.02584"
"357.11600","29.75982","0.02669"
"357.43400","29.78637","0.02546"
"357.75200","29.81285","0.02620"
"358.07000","29.83928","0.02635"
"358.38800","29.86589","0.02703"
"358.70600","29.89232","0.02722"
"359.02400","29.91887","0.02654"
"359.34200","29.94535","0.02697"
"359.66000","29.97183","0.02734"
"359.97800","29.99838","0.02789"
"360.29600","30.02481","0.02772"
"360.61400","30.05136","0.02789"
"360.93200","30.07784","0.02740"
"361.25000","30.10433","0.02792"
"361.56800","30.13088","0.02761"
"361.88600","30.15736","0.02734"
"362.20400","30.18385","0.02734"
"362.52200","30.21033","0.02683"
"362.84000","30.23689","0.02710"
"363.15800","30.26337","0.02662"
"363.47600","30.28979","0.02690"
"363.79400","30.31634","0.02756"
"364.11200","30.34283","0.02762"
"364.43000","30.36938","0.02747"
"364.74800","30.39586","0.02301"
"365.06600","30.42229","0.02391"
"365.38400","30.44884","0.02385"
"365.70200","30.47526","0.02239"
"366.02000","30.50187","0.02381"
"366.33800","30.52835","0.02457"
"366.65600","30.55484","0.02500"
"366.97400","30.58139","0.02498"
"367.29200","30.60782","0.02569"
"367.61000","30.63436","0.02611"
"367.92800","30.66079","0.02661"
"368.24600","30.68734","0.02703"
"368.56400","30.71388","0.02717"
"368.88200","30.74031","0.02743"
"369.20000","30.76686","0.02765"
"369.51800","30.79329","0.02783"
"369.83600","30.81977","0.02792"
"370.15400","30.84632","0.02766"
"370.47200","30.87280","0.02850"
"370.79000","30.89935","0.02884"
"371.10800","30.92578","0.02828"
"371.42600","30.95232","0.02760"
"371.74400","30.97887","0.02702"
"372.06200","31.00536","0.02575"
"372.38000","31.03185","0.02640"
"372.69800","31.05833","0.02684"
"373.01600","31.08488","0.02706"
"373.33400","31.11136","0.02725"
"373.65200","31.13785","0.02804"
"373.97000","31.16428","0.02815"
"374.28800","31.19077","0.02864"
"374.60600","31.21737","0.02871"
"374.92400","31.24386","0.02938"
"375.24200","31.27034","0.02887"
"375.56000","31.29689","0.02918"
"375.87800","31.32326","0.02951"
"376.19600","31.34986","0.02890"
"376.51400","31.37635","0.02949"
"376.83200","31.40284","0.02950"
"377.15000","31.42938","0.02899"
"377.46800","31.45581","0.02924"
"377.78600","31.48242","0.02988"
"378.10400","31.50884","0.02945"
"378.42200","31.53533","0.03010"
"378.74000","31.56182","0.03017"
"379.05800","31.58836","0.03001"
"379.37600","31.61485","0.03106"
"379.69400","31.64134","0.03102"
"380.01200","31.66783","0.03094"
"380.33000","31.69431","0.02987"
"380.64800","31.72080","0.03036"
"380.96600","31.74734","0.03094"
"381.28400","31.77383","0.03068"
"381.60200","31.80032","0.03092"
"381.92000","31.82686","0.03044"
"382.23800","31.85335","0.03049"
"382.55600","31.87990","0.02969"
"382.87400","31.90633","0.02950"
"383.19200","31.93287","0.02660"
"383.51000","31.95936","0.02747"
"383.82800","31.98585","0.02721"
"384.14600","32.01239","0.02719"
"384.46400","32.03882","0.02837"
"384.78200","32.06536","0.02818"
"385.10000","32.09185","0.02848"
"385.41800","32.11840","0.02092"
"385.73600","32.14482","0.02258"
"386.05400","32.17131","0.02351"
"386.37200","32.19786","0.02325"
"386.69000","32.22429","0.02252"
"387.00800","32.25083","0.02440"
"387.32600","32.27738","0.02357"
"387.64400","32.30387","0.02369"
"387.96200","32.33035","0.02463"
"388.28000","32.35678","0.02488"
"388.59800","32.38338","0.02452"
"388.91600","32.40981","0.02464"
"389.23400","32.43630","0.02512"
"389.55200","32.46284","0.02520"
"389.87000","32.48933","0.02498"
"390.18800","32.51588","0.02506"
"390.50600","32.54231","0.02570"
"390.82400","32.56885","0.02587"
"391.14200","32.59540","0.02561"
"391.46000","32.62183","0.02594"
"391.77800","32.64837","0.02619"
"392.09600","32.67480","0.02646"
"392.41400","32.70135","0.02707"
"392.73200","32.72789","0.02658"
"393.05000","32.75432","0.02668"
"393.36800","32.78087","0.02702"
"393.68600","32.80729","0.02729"
"394.00400","32.83390","0.02704"
"394.32200","32.86039","0.02774"
"394.64000","32.88681","0.02733"
"394.95800","32.91336","0.02760"
"395.27600","32.93979","0.02751"
"395.59400","32.96634","0.02798"
"395.91200","32.99282","0.02815"
"396.23000","33.01937","0.02841"
"396.54800","33.04585","0.02855"
"396.86600","33.07234","0.02881"
"397.18400","33.09883","0.02851"
"397.50200","33.12532","0.02817"
"397.82000","33.15174","0.02869"
"398.13800","33.17835","0.02813"
"398.45600","33.20483","0.02875"
"398.77400","33.23132","0.02839"
"399.09200","33.25781","0.02851"
"399.41000","33.28436","0.02848"
"399.72800","33.31084","0.02876"
"400.04600","33.33733","0.02844"
"400.36400","33.36388","0.02920"
"400.68200","33.39030","0.02911"
"401.00000","33.41685","0.02857"
"401.31800","33.44334","0.02912"
"401.63600","33.46982","0.02873"
"401.95400","33.49631","0.02895"
"402.27200","33.52274","0.02840"
"402.59000","33.54940","0.02846"
"402.90800","33.57583","0.02866"
"403.22600","33.60232","0.02843"
"403.54400","33.62886","0.02869"
"403.86200","33.65529","0.02878"
"404.18000","33.68190","0.02869"
"404.49800","33.70832","0.02849"
"404.81600","33.73487","0.02924"
"405.13400","33.76136","0.02896"
"405.45200","33.78784","0.02877"
"405.77000","33.81439","0.02914"
"406.08800","33.84082","0.02883"
"406.40600","33.86730","0.02905"
"406.72400","33.89379","0.02947"
"407.04200","33.92034","0.02937"
"407.36000","33.94682","0.02904"
"407.67800","33.97331","0.02899"
"407.99600","33.99980","0.02846"
"408.31400","34.02634","0.02877"
"408.63200","34.05283","0.02863"
"408.95000","34.07938","0.02891"
"409.26800","34.10580","0.02934"
"409.58600","34.13235","0.02958"
"409.90400","34.15884","0.02906"
"410.22200","34.18538","0.02943"
"410.54000","34.21187","0.02885"
"410.85800","34.23830","0.02905"
"411.17600","34.26490","0.02834"
"411.49400","34.29133","0.02847"
"411.81200","34.31788","0.02855"
"412.13000","34.34436","0.02816"
"412.44800","34.37085","0.02851"
"412.76600","34.39734","0.02813"
"413.08400","34.42382","0.02862"
"413.40200","34.45037","0.02834"
"413.72000","34.47686","0.02860"
"414.03800","34.50328","0.02874"
"414.35600","34.52983","0.02874"
"414.67400","34.55632","0.02890"
"414.99200","34.58281","0.02880"
"415.31000","34.60935","0.02837"
"415.62800","34.63578","0.02836"
"415.94600","34.66238","0.02842"
"416.26400","34.68875","0.02882"
"416.58200","34.71536","0.02861"
"416.90000","34.74184","0.02910"
"417.21800","34.76833","0.02949"
"417.53600","34.79488","0.02944"
"417.85400","34.82130","0.02954"
"418.17200","34.84785","0.02928"
"418.49000","34.87428","0.02946"
"418.80800","34.90083","0.02949"
"419.12600","34.92737","0.02998"
"419.44400","34.95380","0.03012"
"419.76200","34.98035","0.02970"
"420.08000","35.00677","0.02990"
"420.39800","35.03338","0.03055"
"420.71600","35.05986","0.03050"
"421.03400","35.08635","0.03003"
"421.35200","35.11284","0.03055"
"421.67000","35.13927","0.03084"
"421.98800","35.16587","0.03090"
"422.30600","35.19236","0.03134"
"422.62400","35.21885","0.03111"
"422.94200","35.24533","0.03165"
"423.26000","35.27182","0.03195"
"423.57800","35.29831","0.03241"
"423.89600","35.32479","0.03232"
"424.21400","35.35134","0.03236"
"424.53200","35.37783","0.03273"
"424.85000","35.40425","0.03281"
"425.16800","35.43086","0.03347"
"425.48600","35.45729","0.03328"
"425.80400","35.48377","0.03351"
"426.12200","35.51038","0.03255"
"426.44000","35.53681","0.03272"
"426.75800","35.56341","0.03292"
"427.07600","35.58978","0.03260"
"427.39400","35.61633","0.03337"
"427.71200","35.64287","0.03350"
"428.03000","35.66930","0.03339"
"428.34800","35.69591","0.03339"
"428.66600","35.72234","0.03375"
"428.98400","35.74888","0.03342"
"429.30200","35.77537","0.03358"
"429.62000","35.80180","0.03436"
"429.93800","35.82834","0.03467"
"430.25600","35.85477","0.03496"
"430.57400","35.88137","0.03435"
"430.89200","35.90780","0.03464"
"431.21000","35.93429","0.03485"
"431.52800","35.96083","0.03495"
"431.84600","35.98732","0.03555"
"432.16400","36.01381","0.03559"
"432.48200","36.04029","0.03556"
"432.80000","36.06678","0.03581"
"433.11800","36.09333","0.03676"
"433.43600","36.11982","0.03651"
"433.75400","36.14636","0.03633"
"434.07200","36.17285","0.02946"
"434.39000","36.19928","0.02984"
"434.70800","36.22582","0.03040"
"435.02600","36.25231","0.03062"
"435.34400","36.27885","0.02926"
"435.66200","36.30528","0.03035"
"435.98000","36.33183","0.03223"
"436.29800","36.35831","0.03112"
"436.61600","36.38480","0.03192"
"436.93400","36.41135","0.03187"
"437.25200","36.43777","0.03337"
"437.57000","36.46438","0.03268"
"437.88800","36.49081","0.03305"
"438.20600","36.51736","0.03241"
"438.52400","36.54384","0.03313"
"438.84200","36.57027","0.03330"
"439.16000","36.59682","0.03337"
"439.47800","36.62336","0.03434"
"439.79600","36.64985","0.03435"
"440.11400","36.67633","0.03504"
"440.43200","36.70282","0.03510"
"440.75000","36.72931","0.03094"
"441.06800","36.75586","0.02688"
"441.38600","36.78234","0.02556"
"441.70400","36.80883","0.02532"
"442.02200","36.83532","0.02467"
"442.34000","36.86186","0.02568"
"442.65800","36.88835","0.02490"
"442.97600","36.91484","0.02527"
"443.29400","36.94132","0.02472"
"443.61200","36.96781","0.02421"
"443.93000","36.99436","0.02374"
"444.24800","37.02078","0.02412"
"444.56600","37.04733","0.02352"
"444.88400","37.07382","0.02376"
"445.20200","37.10030","0.02370"
"445.52000","37.12685","0.02401"
"445.83800","37.15334","0.02455"
"446.15600","37.17988","0.02468"
"446.47400","37.20631","0.02443"
"446.79200","37.23286","0.02493"
"447.11000","37.25940","0.02489"
"447.42800","37.28577","0.02511"
"447.74600","37.31232","0.02575"
"448.06400","37.33874","0.02581"
"448.38200","37.36535","0.02575"
"448.70000","37.39184","0.02590"
"449.01800","37.41832","0.02587"
"449.33600","37.44481","0.02591"
"449.65400","37.47130","0.02601"
"449.97200","37.49784","0.02603"
"450.29000","37.52433","0.02588"
"450.60800","37.55082","0.02589"
"450.92600","37.57730","0.02601"
"451.24400","37.60379","0.02604"
"451.56200","37.63034","0.02590"
"451.88000","37.65683","0.02593"
"452.19800","37.68331","0.02619"
"452.51600","37.70986","0.02651"
"452.83400","37.73628","0.02672"
"453.15200","37.76283","0.02703"
"453.47000","37.78926","0.02681"
"453.78800","37.81580","0.02673"
"454.10600","37.84235","0.02728"
"454.42400","37.86884","0.02793"
"454.74200","37.89532","0.02742"
"455.06000","37.92181","0.02771"
"455.37800","37.94836","0.02784"
"455.69600","37.97485","0.02844"
"456.01400","38.00133","0.02836"
"456.33200","38.02782","0.02884"
"456.65000","38.05430","0.02857"
"456.96800","38.08085","0.02861"
"457.28600","38.10734","0.02909"
"457.60400","38.13382","0.02904"
"457.92200","38.16037","0.02956"
"458.24000","38.18679","0.02941"
"458.55800","38.21341","0.02982"
"458.87600","38.23983","0.02939"
"459.19400","38.26632","0.03019"
"459.51200","38.29287","0.03033"
"459.83000","38.31929","0.03043"
"460.14800","38.34584","0.03004"
"460.46600","38.37226","0.03124"
"460.78400","38.39881","0.03052"
"461.10200","38.42536","0.03057"
"461.42000","38.45178","0.03065"
"461.73800","38.47839","0.03085"
"462.05600","38.50482","0.03134"
"462.37400","38.53130","0.03100"
"462.69200","38.55779","0.03061"
"463.01000","38.58434","0.03075"
"463.32800","38.61089","0.03106"
"463.64600","38.63731","0.03065"
"463.96400","38.66386","0.03059"
"464.28200","38.69034","0.03082"
"464.60000","38.71683","0.03029"
"464.91800","38.74338","0.03053"
"465.23600","38.76980","0.03045"
"465.55400","38.79635","0.03045"
"465.87200","38.82284","0.03084"
"466.19000","38.84939","0.03094"
"466.50800","38.87587","0.03084"
"466.82600","38.90230","0.03070"
"467.14400","38.92884","0.03107"
"467.46200","38.95533","0.03050"
"467.78000","38.98182","0.03111"
"468.09800","39.00837","0.03111"
"468.41600","39.03479","0.03109"
"468.73400","39.06140","0.03152"
"469.05200","39.08783","0.03144"
"469.37000","39.11437","0.03132"
"469.68800","39.14086","0.03204"
"470.00600","39.16729","0.03168"
"470.32400","39.19389","0.03216"
"470.64200","39.22032","0.03203"
"470.96000","39.24686","0.03167"
"471.27800","39.27329","0.03218"
"471.59600","39.29984","0.03177"
"471.91400","39.32639","0.03203"
"472.23200","39.35281","0.03231"
"472.55000","39.37941","0.03204"
"472.71200","39.39281","0.03214"