File: Force_trajectories/161218_2/Specimen_RawData_6.csv
End date,"12/18/2016"
Specimen label,"16DG_25"
Maximum Load,"0.05567",N

Time,Extension,Load
(s),(mm),(N)
"0.00000","0.00000","-0.00011"
"0.25200","0.01973","-0.00023"
"0.50400","0.04227","0.00039"
"0.75600","0.06332","0.00022"
"1.00800","0.08424","0.00027"
"1.26000","0.10523","0.00078"
"1.51200","0.12622","0.00066"
"1.76400","0.14720","0.00082"
"2.01600","0.16825","0.00108"
"2.26800","0.18917","0.00125"
"2.52000","0.21028","0.00125"
"2.77200","0.23121","0.00128"
"3.02400","0.25219","0.00150"
"3.27600","0.27318","0.00116"
"3.52800","0.29428","0.00159"
"3.78000","0.31521","0.00183"
"4.03200","0.33626","0.00155"
"4.28400","0.35718","0.00184"
"4.53600","0.37823","0.00175"
"4.78800","0.39921","0.00193"
"5.04000","0.42020","0.00212"
"5.29200","0.44119","0.00190"
"5.54400","0.46217","0.00172"
"5.79600","0.48322","0.00206"
"6.04800","0.50421","0.00213"
"6.30000","0.52525","0.00284"
"6.55200","0.54624","0.00252"
"6.80400","0.56728","0.00255"
"7.05600","0.58815","0.00223"
"7.30800","0.60920","0.00268"
"7.56000","0.63012","0.00233"
"7.81200","0.65129","0.00229"
"8.06400","0.67221","0.00247"
"8.31600","0.69326","0.00286"
"8.56800","0.71419","0.00260"
"8.82000","0.73523","0.00277"
"9.07200","0.75622","0.00246"
"9.32400","0.77720","0.00250"
"9.57600","0.79825","0.00266"
"9.82800","0.81924","0.00259"
"10.08000","0.84028","0.00286"
"10.33200","0.86115","0.00286"
"10.58400","0.88225","0.00309"
"10.83600","0.90318","0.00341"
"11.08800","0.92423","0.00318"
"11.34000","0.94515","0.00273"
"11.59200","0.96614","0.00345"
"11.84400","0.98718","0.00289"
"12.09600","1.00829","0.00349"
"12.34800","1.02922","0.00337"
"12.60000","1.05020","0.00333"
"12.85200","1.07119","0.00321"
"13.10400","1.09218","0.00331"
"13.35600","1.11322","0.00328"
"13.60800","1.13421","0.00351"
"13.86000","1.15519","0.00340"
"14.11200","1.17624","0.00388"
"14.36400","1.19723","0.00337"
"14.61600","1.21815","0.00357"
"14.86800","1.23926","0.00371"
"15.12000","1.26024","0.00345"
"15.37200","1.28117","0.00361"
"15.62400","1.30216","0.00370"
"15.87600","1.32326","0.00422"
"16.12800","1.34425","0.00412"
"16.38000","1.36523","0.00426"
"16.63200","1.38622","0.00347"
"16.88400","1.40721","0.00379"
"17.13600","1.42825","0.00409"
"17.38800","1.44924","0.00372"
"17.64000","1.47022","0.00438"
"17.89200","1.49115","0.00410"
"18.14400","1.51226","0.00437"
"18.39600","1.53312","0.00476"
"18.64800","1.55423","0.00432"
"18.90000","1.57516","0.00435"
"19.15200","1.59626","0.00411"
"19.40400","1.61719","0.00449"
"19.65600","1.63817","0.00405"
"19.90800","1.65916","0.00439"
"20.16000","1.68021","0.00428"
"20.41200","1.70119","0.00440"
"20.66400","1.72224","0.00457"
"20.91600","1.74322","0.00478"
"21.16800","1.76421","0.00457"
"21.42000","1.78526","0.00386"
"21.67200","1.80618","0.00418"
"21.92400","1.82723","0.00465"
"22.17600","1.84821","0.00501"
"22.42800","1.86920","0.00439"
"22.68000","1.89013","0.00471"
"22.93200","1.91117","0.00455"
"23.18400","1.93222","0.00428"
"23.43600","1.95326","0.00470"
"23.68800","1.97419","0.00491"
"23.94000","1.99524","0.00494"
"24.19200","2.01622","0.00477"
"24.44400","2.03721","0.00443"
"24.69600","2.05819","0.00513"
"24.94800","2.07924","0.00493"
"25.20000","2.10023","0.00497"
"25.45200","2.12127","0.00506"
"25.70400","2.14226","0.00484"
"25.95600","2.16319","0.00508"
"26.20800","2.18423","0.00465"
"26.46000","2.20522","0.00493"
"26.71200","2.22626","0.00487"
"26.96400","2.24713","0.00538"
"27.21600","2.26824","0.00508"
"27.46800","2.28922","0.00510"
"27.72000","2.31021","0.00535"
"27.97200","2.33119","0.00511"
"28.22400","2.35224","0.00526"
"28.47600","2.37317","0.00526"
"28.72800","2.39421","0.00537"
"28.98000","2.41520","0.00560"
"29.23200","2.43618","0.00522"
"29.48400","2.45723","0.00525"
"29.73600","2.47822","0.00479"
"29.98800","2.49926","0.00503"
"30.24000","2.52019","0.00549"
"30.49200","2.54129","0.00490"
"30.74400","2.56216","0.00498"
"30.99600","2.58315","0.00542"
"31.24800","2.60413","0.00534"
"31.50000","2.62530","0.00520"
"31.75200","2.64622","0.00522"
"32.00400","2.66721","0.00523"
"32.25600","2.68826","0.00590"
"32.50800","2.70930","0.00556"
"32.76000","2.73023","0.00570"
"33.01200","2.75122","0.00531"
"33.26400","2.77220","0.00594"
"33.51600","2.79319","0.00558"
"33.76800","2.81423","0.00577"
"34.02000","2.83516","0.00574"
"34.27200","2.85627","0.00591"
"34.52400","2.87713","0.00551"
"34.77600","2.89830","0.00558"
"35.02800","2.91916","0.00573"
"35.28000","2.94021","0.00616"
"35.53200","2.96120","0.00588"
"35.78400","2.98224","0.00595"
"36.03600","3.00317","0.00571"
"36.28800","3.02421","0.00578"
"36.54000","3.04520","0.00564"
"36.79200","3.06625","0.00458"
"37.04400","3.08717","0.00495"
"37.29600","3.10816","0.00530"
"37.54800","3.12926","0.00484"
"37.80000","3.15019","0.00516"
"38.05200","3.17124","0.00529"
"38.30400","3.19210","0.00496"
"38.55600","3.21321","0.00539"
"38.80800","3.23419","0.00545"
"39.06000","3.25524","0.00510"
"39.31200","3.27617","0.00480"
"39.56400","3.29727","0.00566"
"39.81600","3.31820","0.00555"
"40.06800","3.33925","0.00534"
"40.32000","3.36017","0.00556"
"40.57200","3.38122","0.00586"
"40.82400","3.40226","0.00537"
"41.07600","3.42325","0.00556"
"41.32800","3.44424","0.00540"
"41.58000","3.46522","0.00581"
"41.83200","3.48621","0.00527"
"42.08400","3.50719","0.00574"
"42.33600","3.52824","0.00548"
"42.58800","3.54911","0.00482"
"42.84000","3.57027","0.00497"
"43.09200","3.59120","0.00522"
"43.34400","3.61218","0.00469"
"43.59600","3.63317","0.00471"
"43.84800","3.65422","0.00499"
"44.10000","3.67520","0.00518"
"44.35200","3.69619","0.00520"
"44.60400","3.71718","0.00530"
"44.85600","3.73822","0.00562"
"45.10800","3.75927","0.00561"
"45.36000","3.78019","0.00529"
"45.61200","3.80124","0.00551"
"45.86400","3.82223","0.00565"
"46.11600","3.84327","0.00560"
"46.36800","3.86414","0.00569"
"46.62000","3.88524","0.00554"
"46.87200","3.90617","0.00569"
"47.12400","3.92728","0.00582"
"47.37600","3.94820","0.00548"
"47.62800","3.96919","0.00570"
"47.88000","3.99017","0.00609"
"48.13200","4.01128","0.00584"
"48.38400","4.03215","0.00585"
"48.63600","4.05319","0.00574"
"48.88800","4.07418","0.00589"
"49.14000","4.09516","0.00589"
"49.39200","4.11627","0.00605"
"49.64400","4.13720","0.00590"
"49.89600","4.15824","0.00536"
"50.14800","4.17923","0.00564"
"50.40000","4.20021","0.00539"
"50.65200","4.22114","0.00521"
"50.90400","4.24219","0.00563"
"51.15600","4.26317","0.00477"
"51.40800","4.28428","0.00512"
"51.66000","4.30521","0.00524"
"51.91200","4.32625","0.00488"
"52.16400","4.34724","0.00518"
"52.41600","4.36822","0.00572"
"52.66800","4.38921","0.00562"
"52.92000","4.41020","0.00547"
"53.17200","4.43124","0.00514"
"53.42400","4.45223","0.00518"
"53.67600","4.47321","0.00525"
"53.92800","4.49414","0.00533"
"54.18000","4.51525","0.00556"
"54.43200","4.53617","0.00590"
"54.68400","4.55722","0.00596"
"54.93600","4.57814","0.00549"
"55.18800","4.59925","0.00580"
"55.44000","4.62024","0.00564"
"55.69200","4.64122","0.00582"
"55.94400","4.66215","0.00564"
"56.19600","4.68325","0.00544"
"56.44800","4.70424","0.00546"
"56.70000","4.72523","0.00540"
"56.95200","4.74621","0.00552"
"57.20400","4.76720","0.00596"
"57.45600","4.78824","0.00599"
"57.70800","4.80917","0.00581"
"57.96000","4.83028","0.00528"
"58.21200","4.85120","0.00575"
"58.46400","4.87225","0.00571"
"58.71600","4.89312","0.00583"
"58.96800","4.91422","0.00581"
"59.22000","4.93521","0.00619"
"59.47200","4.95625","0.00577"
"59.72400","4.97718","0.00639"
"59.97600","4.99823","0.00609"
"60.22800","5.01921","0.00591"
"60.48000","5.04026","0.00601"
"60.73200","5.06118","0.00573"
"60.98400","5.08217","0.00553"
"61.23600","5.10322","0.00599"
"61.48800","5.12420","0.00603"
"61.74000","5.14525","0.00631"
"61.99200","5.16617","0.00603"
"62.24400","5.18722","0.00597"
"62.49600","5.20821","0.00602"
"62.74800","5.22925","0.00605"
"63.00000","5.25018","0.00631"
"63.25200","5.27116","0.00644"
"63.50400","5.29221","0.00639"
"63.75600","5.31326","0.00633"
"64.00800","5.33418","0.00619"
"64.26000","5.35523","0.00653"
"64.51200","5.37621","0.00677"
"64.76400","5.39720","0.00683"
"65.01600","5.41819","0.00652"
"65.26800","5.43917","0.00523"
"65.52000","5.46022","0.00444"
"65.77200","5.48121","0.00341"
"66.02400","5.50219","0.00285"
"66.27600","5.52318","0.00236"
"66.52800","5.54422","0.00270"
"66.78000","5.56515","0.00240"
"67.03200","5.58620","0.00269"
"67.28400","5.60718","0.00255"
"67.53600","5.62829","0.00259"
"67.78800","5.64921","0.00260"
"68.04000","5.67026","0.00269"
"68.29200","5.69119","0.00292"
"68.54400","5.71223","0.00308"
"68.79600","5.73328","0.00258"
"69.04800","5.75420","0.00285"
"69.30000","5.77519","0.00328"
"69.55200","5.79618","0.00345"
"69.80400","5.81722","0.00326"
"70.05600","5.83815","0.00315"
"70.30800","5.85925","0.00323"
"70.56000","5.88018","0.00335"
"70.81200","5.90129","0.00344"
"71.06400","5.92221","0.00332"
"71.31600","5.94320","0.00393"
"71.56800","5.96419","0.00361"
"71.82000","5.98523","0.00355"
"72.07200","6.00622","0.00359"
"72.32400","6.02720","0.00398"
"72.57600","6.04825","0.00424"
"72.82800","6.06924","0.00400"
"73.08000","6.09022","0.00416"
"73.33200","6.11121","0.00452"
"73.58400","6.13225","0.00431"
"73.83600","6.15318","0.00431"
"74.08800","6.17423","0.00461"
"74.34000","6.19515","0.00445"
"74.59200","6.21620","0.00432"
"74.84400","6.23718","0.00455"
"75.09600","6.25823","0.00477"
"75.34800","6.27916","0.00456"
"75.60000","6.30026","0.00487"
"75.85200","6.32119","0.00472"
"76.10400","6.34223","0.00504"
"76.35600","6.36316","0.00543"
"76.60800","6.38421","0.00550"
"76.86000","6.40525","0.00533"
"77.11200","6.42624","0.00583"
"77.36400","6.44723","0.00557"
"77.61600","6.46821","0.00581"
"77.86800","6.48926","0.00602"
"78.12000","6.51018","0.00591"
"78.37200","6.53123","0.00635"
"78.62400","6.55216","0.00644"
"78.87600","6.57320","0.00639"
"79.12800","6.59419","0.00663"
"79.38000","6.61523","0.00650"
"79.63200","6.63616","0.00642"
"79.88400","6.65721","0.00638"
"80.13600","6.67825","0.00634"
"80.38800","6.69924","0.00699"
"80.64000","6.72016","0.00678"
"80.89200","6.74121","0.00665"
"81.14400","6.76220","0.00658"
"81.39600","6.78318","0.00683"
"81.64800","6.80423","0.00710"
"81.90000","6.82516","0.00689"
"82.15200","6.84626","0.00732"
"82.40400","6.86719","0.00722"
"82.65600","6.88823","0.00735"
"82.90800","6.90922","0.00715"
"83.16000","6.93026","0.00759"
"83.41200","6.95125","0.00776"
"83.66400","6.97218","0.00793"
"83.91600","6.99316","0.00796"
"84.16800","7.01427","0.00789"
"84.42000","7.03525","0.00739"
"84.67200","7.05624","0.00776"
"84.92400","7.07723","0.00790"
"85.17600","7.09821","0.00799"
"85.42800","7.11926","0.00803"
"85.68000","7.14019","0.00822"
"85.93200","7.16123","0.00839"
"86.18400","7.18216","0.00802"
"86.43600","7.20326","0.00829"
"86.68800","7.22419","0.00839"
"86.94000","7.24518","0.00838"
"87.19200","7.26616","0.00867"
"87.44400","7.28727","0.00832"
"87.69600","7.30819","0.00806"
"87.94800","7.32924","0.00912"
"88.20000","7.35023","0.00852"
"88.45200","7.37121","0.00819"
"88.70400","7.39226","0.00824"
"88.95600","7.41319","0.00885"
"89.20800","7.43423","0.00914"
"89.46000","7.45522","0.00893"
"89.71200","7.47620","0.00946"
"89.96400","7.49713","0.00928"
"90.21600","7.51823","0.00879"
"90.46800","7.53922","0.00911"
"90.72000","7.56027","0.00897"
"90.97200","7.58119","0.00890"
"91.22400","7.60224","0.00938"
"91.47600","7.62323","0.00939"
"91.72800","7.64427","0.00813"
"91.98000","7.66514","0.00809"
"92.23200","7.68618","0.00841"
"92.48400","7.70717","0.00849"
"92.73600","7.72828","0.00858"
"92.98800","7.74926","0.00865"
"93.24000","7.77025","0.00849"
"93.49200","7.79123","0.00843"
"93.74400","7.81222","0.00878"
"93.99600","7.83321","0.00854"
"94.24800","7.85413","0.00846"
"94.50000","7.87524","0.00909"
"94.75200","7.89616","0.00847"
"95.00400","7.91721","0.00879"
"95.25600","7.93820","0.00906"
"95.50800","7.95924","0.00929"
"95.76000","7.98023","0.00734"
"96.01200","8.00121","0.00757"
"96.26400","8.02220","0.00723"
"96.51600","8.04319","0.00722"
"96.76800","8.06423","0.00700"
"97.02000","8.08516","0.00729"
"97.27200","8.10626","0.00763"
"97.52400","8.12719","0.00694"
"97.77600","8.14824","0.00762"
"98.02800","8.16916","0.00784"
"98.28000","8.19021","0.00796"
"98.53200","8.21119","0.00780"
"98.78400","8.23224","0.00771"
"99.03600","8.25317","0.00777"
"99.28800","8.27421","0.00798"
"99.54000","8.29520","0.00797"
"99.79200","8.31625","0.00815"
"100.04400","8.33717","0.00850"
"100.29600","8.35822","0.00857"
"100.54800","8.37920","0.00868"
"100.80000","8.40025","0.00868"
"101.05200","8.42124","0.00851"
"101.30400","8.44216","0.00843"
"101.55600","8.46321","0.00895"
"101.80800","8.48419","0.00822"
"102.06000","8.50524","0.00836"
"102.31200","8.52617","0.00865"
"102.56400","8.54721","0.00922"
"102.81600","8.56820","0.00786"
"103.06800","8.58930","0.00806"
"103.32000","8.61017","0.00791"
"103.57200","8.63128","0.00760"
"103.82400","8.65220","0.00784"
"104.07600","8.67325","0.00855"
"104.32800","8.69418","0.00829"
"104.58000","8.71516","0.00841"
"104.83200","8.73627","0.00877"
"105.08400","8.75725","0.00842"
"105.33600","8.77824","0.00857"
"105.58800","8.79917","0.00850"
"105.84000","8.82021","0.00892"
"106.09200","8.84120","0.00879"
"106.34400","8.86224","0.00836"
"106.59600","8.88317","0.00897"
"106.84800","8.90422","0.00913"
"107.10000","8.92520","0.00916"
"107.35200","8.94619","0.00912"
"107.60400","8.96717","0.00858"
"107.85600","8.98822","0.00887"
"108.10800","9.00927","0.00895"
"108.36000","9.03019","0.00941"
"108.61200","9.05124","0.00986"
"108.86400","9.07222","0.00943"
"109.11600","9.09327","0.00913"
"109.36800","9.11420","0.00809"
"109.62000","9.13524","0.00856"
"109.87200","9.15617","0.00841"
"110.12400","9.17722","0.00895"
"110.37600","9.19820","0.00844"
"110.62800","9.21919","0.00924"
"110.88000","9.24017","0.00906"
"111.13200","9.26128","0.00917"
"111.38400","9.28221","0.00908"
"111.63600","9.30325","0.00912"
"111.88800","9.32424","0.00973"
"112.14000","9.34528","0.00946"
"112.39200","9.36627","0.00922"
"112.64400","9.38714","0.00967"
"112.89600","9.40818","0.00981"
"113.14800","9.42923","0.00945"
"113.40000","9.45027","0.00981"
"113.65200","9.47120","0.01000"
"113.90400","9.49231","0.01014"
"114.15600","9.51317","0.00995"
"114.40800","9.53428","0.00934"
"114.66000","9.55515","0.00972"
"114.91200","9.57619","0.00952"
"115.16400","9.59718","0.00959"
"115.41600","9.61828","0.00985"
"115.66800","9.63915","0.00964"
"115.92000","9.66026","0.00991"
"116.17200","9.68124","0.01022"
"116.42400","9.70223","0.01009"
"116.67600","9.72321","0.01019"
"116.92800","9.74420","0.01033"
"117.18000","9.76525","0.01075"
"117.43200","9.78617","0.01092"
"117.68400","9.80722","0.01086"
"117.93600","9.82820","0.01113"
"118.18800","9.84925","0.01152"
"118.44000","9.87024","0.01113"
"118.69200","9.89122","0.01126"
"118.94400","9.91221","0.01140"
"119.19600","9.93325","0.01106"
"119.44800","9.95424","0.01098"
"119.70000","9.97522","0.01229"
"119.95200","9.99621","0.01155"
"120.20400","10.01726","0.01210"
"120.45600","10.03824","0.01177"
"120.70800","10.05923","0.01178"
"120.96000","10.08028","0.01218"
"121.21200","10.10120","0.01229"
"121.46400","10.12219","0.01240"
"121.71600","10.14318","0.01287"
"121.96800","10.16422","0.01184"
"122.22000","10.18515","0.01184"
"122.47200","10.20619","0.01207"
"122.72400","10.22718","0.01181"
"122.97600","10.24817","0.01207"
"123.22800","10.26921","0.01244"
"123.48000","10.29026","0.01165"
"123.73200","10.31118","0.01210"
"123.98400","10.33217","0.01227"
"124.23600","10.35322","0.01214"
"124.48800","10.37420","0.01237"
"124.74000","10.39525","0.01210"
"124.99200","10.41617","0.01259"
"125.24400","10.43728","0.01259"
"125.49600","10.45821","0.01244"
"125.74800","10.47925","0.01160"
"126.00000","10.50012","0.01151"
"126.25200","10.52122","0.01205"
"126.50400","10.54221","0.01158"
"126.75600","10.56326","0.01139"
"127.00800","10.58418","0.01171"
"127.26000","10.60523","0.01171"
"127.51200","10.62621","0.01177"
"127.76400","10.64726","0.01193"
"128.01600","10.66819","0.01185"
"128.26800","10.68923","0.01231"
"128.52000","10.71022","0.01259"
"128.77200","10.73127","0.01295"
"129.02400","10.75225","0.01204"
"129.27600","10.77318","0.01223"
"129.52800","10.79422","0.01215"
"129.78000","10.81521","0.01254"
"130.03200","10.83626","0.01276"
"130.28400","10.85712","0.01253"
"130.53600","10.87823","0.01269"
"130.78800","10.89915","0.01303"
"131.04000","10.92026","0.01272"
"131.29200","10.94119","0.01315"
"131.54400","10.96223","0.01302"
"131.79600","10.98328","0.01321"
"132.04800","11.00420","0.01377"
"132.30000","11.02519","0.01326"
"132.55200","11.04624","0.01334"
"132.80400","11.06722","0.01411"
"133.05600","11.08815","0.01380"
"133.30800","11.10919","0.01393"
"133.56000","11.13018","0.01372"
"133.81200","11.15129","0.01381"
"134.06400","11.17221","0.01385"
"134.31600","11.19326","0.01355"
"134.56800","11.21418","0.01404"
"134.82000","11.23523","0.01416"
"135.07200","11.25622","0.01427"
"135.32400","11.27720","0.01487"
"135.57600","11.29813","0.01441"
"135.82800","11.31923","0.01478"
"136.08000","11.34022","0.01523"
"136.33200","11.36127","0.01501"
"136.58400","11.38219","0.01531"
"136.83600","11.40318","0.01573"
"137.08800","11.42423","0.01571"
"137.34000","11.44515","0.01552"
"137.59200","11.46626","0.01538"
"137.84400","11.48718","0.01573"
"138.09600","11.50823","0.01601"
"138.34800","11.52922","0.01611"
"138.60000","11.55020","0.01605"
"138.85200","11.57119","0.01629"
"139.10400","11.59223","0.01605"
"139.35600","11.61322","0.01591"
"139.60800","11.63421","0.01674"
"139.86000","11.65519","0.01718"
"140.11200","11.67624","0.01732"
"140.36400","11.69722","0.01745"
"140.61600","11.71821","0.01767"
"140.86800","11.73920","0.01729"
"141.12000","11.76024","0.01679"
"141.37200","11.78123","0.01696"
"141.62400","11.80216","0.01715"
"141.87600","11.82326","0.01772"
"142.12800","11.84419","0.01727"
"142.38000","11.86523","0.01740"
"142.63200","11.88622","0.01765"
"142.88400","11.90721","0.01758"
"143.13600","11.92819","0.01804"
"143.38800","11.94924","0.01852"
"143.64000","11.97010","0.01768"
"143.89200","11.99127","0.01869"
"144.14400","12.01225","0.01894"
"144.39600","12.03324","0.01906"
"144.64800","12.05423","0.01919"
"144.90000","12.07521","0.01885"
"145.15200","12.09626","0.01879"
"145.40400","12.11719","0.01908"
"145.65600","12.13823","0.01963"
"145.90800","12.15916","0.02022"
"146.16000","12.18020","0.01964"
"146.41200","12.20119","0.02028"
"146.66400","12.22224","0.02008"
"146.91600","12.24316","0.02034"
"147.16800","12.26421","0.01991"
"147.42000","12.28520","0.01979"
"147.67200","12.30618","0.01983"
"147.92400","12.32717","0.02004"
"148.17600","12.34821","0.01999"
"148.42800","12.36926","0.02010"
"148.68000","12.39019","0.02017"
"148.93200","12.41123","0.02018"
"149.18400","12.43222","0.02046"
"149.43600","12.45326","0.02013"
"149.68800","12.47419","0.02044"
"149.94000","12.49523","0.02010"
"150.19200","12.51616","0.02068"
"150.44400","12.53727","0.02031"
"150.69600","12.55819","0.02058"
"150.94800","12.57924","0.02063"
"151.20000","12.60017","0.02033"
"151.45200","12.62127","0.02036"
"151.70400","12.64220","0.02028"
"151.95600","12.66318","0.01971"
"152.20800","12.68423","0.01993"
"152.46000","12.70522","0.01913"
"152.71200","12.72626","0.02012"
"152.96400","12.74719","0.02047"
"153.21600","12.76824","0.02058"
"153.46800","12.78916","0.02032"
"153.72000","12.81021","0.02033"
"153.97200","12.83113","0.02068"
"154.22400","12.85218","0.01961"
"154.47600","12.87316","0.01940"
"154.72800","12.89427","0.01936"
"154.98000","12.91520","0.01940"
"155.23200","12.93624","0.01969"
"155.48400","12.95723","0.01949"
"155.73600","12.97822","0.01944"
"155.98800","12.99920","0.02037"
"156.24000","13.02019","0.02046"
"156.49200","13.04123","0.02038"
"156.74400","13.06222","0.02055"
"156.99600","13.08327","0.02086"
"157.24800","13.10419","0.02075"
"157.50000","13.12524","0.02124"
"157.75200","13.14616","0.02161"
"158.00400","13.16721","0.02105"
"158.25600","13.18814","0.02066"
"158.50800","13.20918","0.02059"
"158.76000","13.23017","0.02061"
"159.01200","13.25121","0.02074"
"159.26400","13.27220","0.02120"
"159.51600","13.29325","0.02114"
"159.76800","13.31423","0.02096"
"160.02000","13.33522","0.02158"
"160.27200","13.35620","0.02127"
"160.52400","13.37719","0.02136"
"160.77600","13.39824","0.02192"
"161.02800","13.41922","0.02173"
"161.28000","13.44021","0.02139"
"161.53200","13.46120","0.02020"
"161.78400","13.48224","0.02075"
"162.03600","13.50317","0.02098"
"162.28800","13.52421","0.02121"
"162.54000","13.54514","0.02105"
"162.79200","13.56625","0.02084"
"163.04400","13.58717","0.02151"
"163.29600","13.60822","0.02195"
"163.54800","13.62920","0.02161"
"163.80000","13.65025","0.02154"
"164.05200","13.67124","0.02183"
"164.30400","13.69216","0.02211"
"164.55600","13.71321","0.02223"
"164.80800","13.73419","0.02208"
"165.06000","13.75524","0.02237"
"165.31200","13.77617","0.02210"
"165.56400","13.79721","0.02253"
"165.81600","13.81820","0.02222"
"166.06800","13.83924","0.02285"
"166.32000","13.86017","0.02253"
"166.57200","13.88122","0.02326"
"166.82400","13.90214","0.02298"
"167.07600","13.92325","0.02316"
"167.32800","13.94417","0.02310"
"167.58000","13.96522","0.02277"
"167.83200","13.98621","0.02287"
"168.08400","14.00725","0.02282"
"168.33600","14.02824","0.02266"
"168.58800","14.04916","0.02339"
"168.84000","14.07021","0.02302"
"169.09200","14.09120","0.02363"
"169.34400","14.11224","0.02382"
"169.59600","14.13317","0.02351"
"169.84800","14.15428","0.02362"
"170.10000","14.17514","0.02158"
"170.35200","14.19625","0.02195"
"170.60400","14.21717","0.02265"
"170.85600","14.23822","0.02259"
"171.10800","14.25920","0.02269"
"171.36000","14.28019","0.02296"
"171.61200","14.30118","0.02306"
"171.86400","14.32222","0.02321"
"172.11600","14.34327","0.02310"
"172.36800","14.36420","0.02227"
"172.62000","14.38518","0.02269"
"172.87200","14.40617","0.02335"
"173.12400","14.42727","0.02335"
"173.37600","14.44814","0.02369"
"173.62800","14.46919","0.02366"
"173.88000","14.49017","0.02275"
"174.13200","14.51122","0.02360"
"174.38400","14.53220","0.02323"
"174.63600","14.55325","0.02334"
"174.88800","14.57424","0.02390"
"175.14000","14.59522","0.02398"
"175.39200","14.61621","0.02372"
"175.64400","14.63720","0.02428"
"175.89600","14.65824","0.02381"
"176.14800","14.67923","0.02431"
"176.40000","14.70027","0.02374"
"176.65200","14.72120","0.02447"
"176.90400","14.74224","0.02468"
"177.15600","14.76317","0.02490"
"177.40800","14.78422","0.02506"
"177.66000","14.80514","0.02495"
"177.91200","14.82625","0.02528"
"178.16400","14.84718","0.02532"
"178.41600","14.86816","0.02518"
"178.66800","14.88915","0.02495"
"178.92000","14.91020","0.02495"
"179.17200","14.93118","0.02510"
"179.42400","14.95229","0.02554"
"179.67600","14.97321","0.02537"
"179.92800","14.99420","0.02556"
"180.18000","15.01524","0.02581"
"180.43200","15.03623","0.02552"
"180.68400","15.05722","0.02508"
"180.93600","15.07814","0.02546"
"181.18800","15.09925","0.02533"
"181.44000","15.12018","0.02551"
"181.69200","15.14122","0.02561"
"181.94400","15.16215","0.02572"
"182.19600","15.18325","0.02575"
"182.44800","15.20418","0.02599"
"182.70000","15.22528","0.02552"
"182.95200","15.24615","0.02518"
"183.20400","15.26720","0.02552"
"183.45600","15.28824","0.02600"
"183.70800","15.30923","0.02580"
"183.96000","15.33022","0.02545"
"184.21200","15.35120","0.02527"
"184.46400","15.37225","0.02522"
"184.71600","15.39317","0.02529"
"184.96800","15.41416","0.02501"
"185.22000","15.43515","0.02543"
"185.47200","15.45625","0.02556"
"185.72400","15.47718","0.02611"
"185.97600","15.49822","0.02596"
"186.22800","15.51915","0.02610"
"186.48000","15.54020","0.02606"
"186.73200","15.56118","0.02653"
"186.98400","15.58223","0.02661"
"187.23600","15.60322","0.02589"
"187.48800","15.62426","0.02614"
"187.74000","15.64525","0.02610"
"187.99200","15.66623","0.02605"
"188.24400","15.68716","0.02608"
"188.49600","15.70820","0.02613"
"188.74800","15.72925","0.02586"
"189.00000","15.75018","0.02625"
"189.25200","15.77122","0.02602"
"189.50400","15.79215","0.02621"
"189.75600","15.81326","0.02621"
"190.00800","15.83418","0.02635"
"190.26000","15.85523","0.02638"
"190.51200","15.87615","0.02614"
"190.76400","15.89726","0.02636"
"191.01600","15.91819","0.02683"
"191.26800","15.93923","0.02679"
"191.52000","15.96022","0.02680"
"191.77200","15.98120","0.02690"
"192.02400","16.00219","0.02696"
"192.27600","16.02318","0.02714"
"192.52800","16.04422","0.02715"
"192.78000","16.06527","0.02768"
"193.03200","16.08619","0.02756"
"193.28400","16.10718","0.02686"
"193.53600","16.12823","0.02744"
"193.78800","16.14915","0.02777"
"194.04000","16.17020","0.02825"
"194.29200","16.19118","0.02732"
"194.54400","16.21223","0.02701"
"194.79600","16.23316","0.02757"
"195.04800","16.25420","0.02710"
"195.30000","16.27513","0.02779"
"195.55200","16.29623","0.02654"
"195.80400","16.31722","0.02723"
"196.05600","16.33827","0.02763"
"196.30800","16.35919","0.02818"
"196.56000","16.38018","0.02787"
"196.81200","16.40123","0.02803"
"197.06400","16.42221","0.02812"
"197.31600","16.44320","0.02794"
"197.56800","16.46418","0.02833"
"197.82000","16.48523","0.02724"
"198.07200","16.50622","0.02761"
"198.32400","16.52726","0.02754"
"198.57600","16.54819","0.02753"
"198.82800","16.56923","0.02756"
"199.08000","16.59016","0.02775"
"199.33200","16.61121","0.02776"
"199.58400","16.63219","0.02644"
"199.83600","16.65318","0.02687"
"200.08800","16.67428","0.02586"
"200.34000","16.69515","0.02668"
"200.59200","16.71620","0.02661"
"200.84400","16.73718","0.02674"
"201.09600","16.75823","0.02761"
"201.34800","16.77915","0.02716"
"201.60000","16.80020","0.02753"
"201.85200","16.82119","0.02717"
"202.10400","16.84223","0.02795"
"202.35600","16.86316","0.02796"
"202.60800","16.88421","0.02803"
"202.86000","16.90519","0.02787"
"203.11200","16.92624","0.02824"
"203.36400","16.94716","0.02860"
"203.61600","16.96821","0.02883"
"203.86800","16.98919","0.02889"
"204.12000","17.01024","0.02906"
"204.37200","17.03123","0.02774"
"204.62400","17.05215","0.02781"
"204.87600","17.07320","0.02735"
"205.12800","17.09418","0.02772"
"205.38000","17.11523","0.02826"
"205.63200","17.13610","0.02848"
"205.88400","17.15720","0.02887"
"206.13600","17.17819","0.02901"
"206.38800","17.19924","0.02940"
"206.64000","17.22022","0.02963"
"206.89200","17.24127","0.02940"
"207.14400","17.26219","0.02980"
"207.39600","17.28324","0.02970"
"207.64800","17.30417","0.02968"
"207.90000","17.32515","0.02990"
"208.15200","17.34626","0.03052"
"208.40400","17.36724","0.03027"
"208.65600","17.38823","0.03067"
"208.90800","17.40916","0.03018"
"209.16000","17.43020","0.03034"
"209.41200","17.45119","0.03086"
"209.66400","17.47218","0.03065"
"209.91600","17.49316","0.03095"
"210.16800","17.51421","0.03087"
"210.42000","17.53519","0.03067"
"210.67200","17.55624","0.03081"
"210.92400","17.57722","0.03082"
"211.17600","17.59827","0.03091"
"211.42800","17.61926","0.03096"
"211.68000","17.64024","0.03096"
"211.93200","17.66117","0.03052"
"212.18400","17.68216","0.03139"
"212.43600","17.70320","0.03118"
"212.68800","17.72425","0.03148"
"212.94000","17.74523","0.03169"
"213.19200","17.76616","0.03194"
"213.44400","17.78727","0.03198"
"213.69600","17.80813","0.03096"
"213.94800","17.82924","0.03191"
"214.20000","17.85016","0.03217"
"214.45200","17.87121","0.03212"
"214.70400","17.89220","0.03225"
"214.95600","17.91324","0.03211"
"215.20800","17.93417","0.03262"
"215.46000","17.95527","0.03298"
"215.71200","17.97620","0.03213"
"215.96400","17.99719","0.03226"
"216.21600","18.01823","0.03209"
"216.46800","18.03922","0.03142"
"216.72000","18.06026","0.03168"
"216.97200","18.08113","0.03239"
"217.22400","18.10224","0.03263"
"217.47600","18.12322","0.03262"
"217.72800","18.14421","0.03283"
"217.98000","18.16520","0.03263"
"218.23200","18.18618","0.03273"
"218.48400","18.20717","0.03190"
"218.73600","18.22827","0.03253"
"218.98800","18.24920","0.03213"
"219.24000","18.27025","0.03169"
"219.49200","18.29123","0.03205"
"219.74400","18.31222","0.03191"
"219.99600","18.33320","0.03263"
"220.24800","18.35413","0.03273"
"220.50000","18.37518","0.03211"
"220.75200","18.39622","0.03284"
"221.00400","18.41721","0.03286"
"221.25600","18.43814","0.03270"
"221.50800","18.45924","0.03201"
"221.76000","18.48017","0.03312"
"222.01200","18.50121","0.03317"
"222.26400","18.52214","0.03398"
"222.51600","18.54325","0.03401"
"222.76800","18.56423","0.03421"
"223.02000","18.58528","0.03460"
"223.27200","18.60620","0.03381"
"223.52400","18.62725","0.03417"
"223.77600","18.64824","0.03419"
"224.02800","18.66922","0.03311"
"224.28000","18.69021","0.03348"
"224.53200","18.71119","0.03412"
"224.78400","18.73224","0.03357"
"225.03600","18.75317","0.03374"
"225.28800","18.77421","0.03405"
"225.54000","18.79520","0.03507"
"225.79200","18.81624","0.03410"
"226.04400","18.83717","0.03505"
"226.29600","18.85822","0.03492"
"226.54800","18.87914","0.03523"
"226.80000","18.90019","0.03583"
"227.05200","18.92124","0.03556"
"227.30400","18.94222","0.03534"
"227.55600","18.96327","0.03480"
"227.80800","18.98419","0.03501"
"228.06000","19.00524","0.03523"
"228.31200","19.02617","0.03539"
"228.56400","19.04721","0.03618"
"228.81600","19.06820","0.03551"
"229.06800","19.08924","0.03590"
"229.32000","19.11011","0.03589"
"229.57200","19.13122","0.03576"
"229.82400","19.15214","0.03443"
"230.07600","19.17319","0.03424"
"230.32800","19.19417","0.03418"
"230.58000","19.21522","0.03428"
"230.83200","19.23621","0.03487"
"231.08400","19.25725","0.03530"
"231.33600","19.27818","0.03477"
"231.58800","19.29922","0.03498"
"231.84000","19.32021","0.03470"
"232.09200","19.34126","0.03493"
"232.34400","19.36224","0.03583"
"232.59600","19.38317","0.03332"
"232.84800","19.40421","0.03346"
"233.10000","19.42520","0.03436"
"233.35200","19.44625","0.03457"
"233.60400","19.46717","0.03450"
"233.85600","19.48822","0.03460"
"234.10800","19.50920","0.03446"
"234.36000","19.53025","0.03472"
"234.61200","19.55118","0.03470"
"234.86400","19.57222","0.03485"
"235.11600","19.59315","0.03505"
"235.36800","19.61419","0.03491"
"235.62000","19.63518","0.03453"
"235.87200","19.65623","0.03440"
"236.12400","19.67727","0.03387"
"236.37600","19.69820","0.03417"
"236.62800","19.71918","0.03409"
"236.88000","19.74017","0.03390"
"237.13200","19.76122","0.03363"
"237.38400","19.78220","0.03408"
"237.63600","19.80319","0.01319"
"237.88800","19.82418","0.01198"
"238.14000","19.84522","0.01336"
"238.39200","19.86621","0.01276"
"238.64400","19.88719","0.01527"
"238.89600","19.90824","0.01451"
"239.14800","19.92922","0.01651"
"239.40000","19.95021","0.01577"
"239.65200","19.97126","0.01674"
"239.90400","19.99218","0.01703"
"240.15600","20.01323","0.01803"
"240.40800","20.03428","0.01784"
"240.66000","20.05514","0.01883"
"240.91200","20.07625","0.01945"
"241.16400","20.09711","0.01959"
"241.41600","20.11828","0.01979"
"241.66800","20.13915","0.02122"
"241.92000","20.16019","0.02113"
"242.17200","20.18112","0.02185"
"242.42400","20.20222","0.02153"
"242.67600","20.22321","0.02227"
"242.92800","20.24420","0.02181"
"243.18000","20.26524","0.02231"
"243.43200","20.28623","0.02154"
"243.68400","20.30722","0.02277"
"243.93600","20.32820","0.02209"
"244.18800","20.34925","0.02341"
"244.44000","20.37023","0.02246"
"244.69200","20.39122","0.02354"
"244.94400","20.41215","0.02310"
"245.19600","20.43319","0.02362"
"245.44800","20.45418","0.02386"
"245.70000","20.47522","0.02470"
"245.95200","20.49621","0.02474"
"246.20400","20.51726","0.02539"
"246.45600","20.53818","0.02452"
"246.70800","20.55923","0.02614"
"246.96000","20.58022","0.02530"
"247.21200","20.60120","0.02652"
"247.46400","20.62225","0.02616"
"247.71600","20.64323","0.02705"
"247.96800","20.66416","0.02715"
"248.22000","20.68521","0.02734"
"248.47200","20.70619","0.02695"
"248.72400","20.72724","0.02715"
"248.97600","20.74822","0.02749"
"249.22800","20.76909","0.02792"
"249.48000","20.79026","0.02746"
"249.73200","20.81118","0.02800"
"249.98400","20.83223","0.02818"
"250.23600","20.85321","0.02809"
"250.48800","20.87426","0.02878"
"250.74000","20.89519","0.02928"
"250.99200","20.91623","0.02872"
"251.24400","20.93722","0.02900"
"251.49600","20.95821","0.02896"
"251.74800","20.97925","0.02962"
"252.00000","21.00018","0.03001"
"252.25200","21.02122","0.02971"
"252.50400","21.04215","0.03023"
"252.75600","21.06326","0.03046"
"253.00800","21.08418","0.03091"
"253.26000","21.10523","0.03006"
"253.51200","21.12615","0.03111"
"253.76400","21.14726","0.03036"
"254.01600","21.16825","0.03016"
"254.26800","21.18929","0.03003"
"254.52000","21.21022","0.03099"
"254.77200","21.23126","0.03115"
"255.02400","21.25219","0.03137"
"255.27600","21.27318","0.03148"
"255.52800","21.29416","0.03156"
"255.78000","21.31521","0.03148"
"256.03200","21.33625","0.03173"
"256.28400","21.35724","0.03187"
"256.53600","21.37823","0.03284"
"256.78800","21.39921","0.03289"
"257.04000","21.42026","0.03271"
"257.29200","21.44112","0.03319"
"257.54400","21.46223","0.03271"
"257.79600","21.48315","0.03342"
"258.04800","21.50426","0.03293"
"258.30000","21.52519","0.03353"
"258.55200","21.54623","0.03407"
"258.80400","21.56722","0.03518"
"259.05600","21.58827","0.03484"
"259.30800","21.60925","0.03513"
"259.56000","21.63018","0.03565"
"259.81200","21.65122","0.03569"
"260.06400","21.67221","0.03609"
"260.31600","21.69326","0.03580"
"260.56800","21.71412","0.03566"
"260.82000","21.73523","0.03591"
"261.07200","21.75621","0.03649"
"261.32400","21.77720","0.03627"
"261.57600","21.79813","0.03705"
"261.82800","21.81923","0.03727"
"262.08000","21.84022","0.03795"
"262.33200","21.86121","0.03800"
"262.58400","21.88219","0.03788"
"262.83600","21.90324","0.03758"
"263.08800","21.92422","0.03816"
"263.34000","21.94521","0.03853"
"263.59200","21.96619","0.03856"
"263.84400","21.98718","0.03880"
"264.09600","22.00823","0.03928"
"264.34800","22.02921","0.03853"
"264.60000","22.05026","0.04009"
"264.85200","22.07119","0.03931"
"265.10400","22.09229","0.03880"
"265.35600","22.11316","0.03929"
"265.60800","22.13420","0.03950"
"265.86000","22.15519","0.04013"
"266.11200","22.17624","0.03972"
"266.36400","22.19722","0.04001"
"266.61600","22.21821","0.04033"
"266.86800","22.23919","0.04036"
"267.12000","22.26024","0.04057"
"267.37200","22.28123","0.04112"
"267.62400","22.30221","0.04102"
"267.87600","22.32320","0.04108"
"268.12800","22.34419","0.04056"
"268.38000","22.36529","0.04189"
"268.63200","22.38616","0.04099"
"268.88400","22.40720","0.04007"
"269.13600","22.42819","0.04090"
"269.38800","22.44930","0.04074"
"269.64000","22.47016","0.04098"
"269.89200","22.49115","0.04112"
"270.14400","22.51219","0.04174"
"270.39600","22.53330","0.04191"
"270.64800","22.55423","0.04224"
"270.90000","22.57521","0.04178"
"271.15200","22.59620","0.04273"
"271.40400","22.61719","0.04255"
"271.65600","22.63817","0.04290"
"271.90800","22.65922","0.04289"
"272.16000","22.68020","0.04321"
"272.41200","22.70119","0.04290"
"272.66400","22.72223","0.04335"
"272.91600","22.74316","0.04406"
"273.16800","22.76421","0.04418"
"273.42000","22.78519","0.04441"
"273.67200","22.80618","0.04407"
"273.92400","22.82717","0.04437"
"274.17600","22.84827","0.04414"
"274.42800","22.86920","0.04416"
"274.68000","22.89024","0.04390"
"274.93200","22.91123","0.04431"
"275.18400","22.93222","0.04475"
"275.43600","22.95320","0.04509"
"275.68800","22.97425","0.04511"
"275.94000","22.99517","0.04586"
"276.19200","23.01616","0.04529"
"276.44400","23.03721","0.04583"
"276.69600","23.05819","0.04563"
"276.94800","23.07924","0.04589"
"277.20000","23.10016","0.04592"
"277.45200","23.12127","0.04706"
"277.70400","23.14220","0.04661"
"277.95600","23.16318","0.04683"
"278.20800","23.18417","0.04649"
"278.46000","23.20522","0.04647"
"278.71200","23.22620","0.04766"
"278.96400","23.24719","0.04767"
"279.21600","23.26823","0.04806"
"279.46800","23.28922","0.04763"
"279.72000","23.31027","0.04775"
"279.97200","23.33119","0.04840"
"280.22400","23.35224","0.04876"
"280.47600","23.37316","0.04907"
"280.72800","23.39427","0.04934"
"280.98000","23.41514","0.04915"
"281.23200","23.43618","0.04913"
"281.48400","23.45717","0.04992"
"281.73600","23.47827","0.05007"
"281.98800","23.49914","0.05035"
"282.24000","23.52024","0.05063"
"282.49200","23.54117","0.05073"
"282.74400","23.56228","0.05095"
"282.99600","23.58320","0.05097"
"283.24800","23.60425","0.05074"
"283.50000","23.62523","0.05057"
"283.75200","23.64622","0.05058"
"284.00400","23.66721","0.05108"
"284.25600","23.68819","0.05099"
"284.50800","23.70924","0.05099"
"284.76000","23.73023","0.05113"
"285.01200","23.75121","0.05148"
"285.26400","23.77214","0.05073"
"285.51600","23.79318","0.05154"
"285.76800","23.81423","0.05105"
"286.02000","23.83528","0.05143"
"286.27200","23.85620","0.05146"
"286.52400","23.87725","0.05159"
"286.77600","23.89817","0.05176"
"287.02800","23.91922","0.05207"
"287.28000","23.94020","0.05224"
"287.53200","23.96119","0.05209"
"287.78400","23.98224","0.05235"
"288.03600","24.00323","0.05256"
"288.28800","24.02421","0.05277"
"288.54000","24.04514","0.05312"
"288.79200","24.06624","0.05291"
"289.04400","24.08717","0.05340"
"289.29600","24.10816","0.05334"
"289.54800","24.12914","0.05326"
"289.80000","24.15025","0.05372"
"290.05200","24.17123","0.05340"
"290.30400","24.19222","0.05304"
"290.55600","24.21321","0.05313"
"290.80800","24.23425","0.05322"
"291.06000","24.25524","0.05336"
"291.31200","24.27622","0.05357"
"291.56400","24.29721","0.05399"
"291.81600","24.31820","0.05403"
"292.06800","24.33924","0.05442"
"292.32000","24.36017","0.05459"
"292.57200","24.38121","0.05368"
"292.82400","24.40214","0.05330"
"293.07600","24.42324","0.05397"
"293.32800","24.44417","0.05402"
"293.58000","24.46522","0.05398"
"293.83200","24.48615","0.05381"
"294.08400","24.50725","0.05457"
"294.33600","24.52818","0.05419"
"294.58800","24.54922","0.05423"
"294.84000","24.57021","0.05442"
"295.09200","24.59126","0.05501"
"295.34400","24.61224","0.05515"
"295.59600","24.63317","0.05487"
"295.84800","24.65421","0.05347"
"296.10000","24.67520","0.05352"
"296.35200","24.69625","0.05360"
"296.60400","24.71711","0.05382"
"296.85600","24.73822","0.05322"
"297.10800","24.75920","0.05369"
"297.36000","24.78025","0.05361"
"297.61200","24.80118","0.05351"
"297.86400","24.82222","0.05342"
"298.11600","24.84321","0.05410"
"298.36800","24.86425","0.05344"
"298.62000","24.88518","0.05370"
"298.87200","24.90617","0.05406"
"299.12400","24.92721","0.05346"
"299.37600","24.94826","0.05347"
"299.62800","24.96924","0.05367"
"299.88000","24.99023","0.05424"
"300.13200","25.01122","0.05394"
"300.38400","25.03220","0.05449"
"300.63600","25.05325","0.05467"
"300.88800","25.07412","0.05501"
"301.14000","25.09522","0.05428"
"301.39200","25.11621","0.05473"
"301.64400","25.13725","0.05452"
"301.89600","25.15818","0.05451"
"302.14800","25.17923","0.05404"
"302.40000","25.20021","0.05438"
"302.65200","25.22120","0.05456"
"302.90400","25.24219","0.05479"
"303.15600","25.26323","0.05470"
"303.40800","25.28422","0.05539"
"303.66000","25.30520","0.05466"
"303.91200","25.32625","0.05506"
"304.16400","25.34717","0.05527"
"304.41600","25.36828","0.05501"
"304.66800","25.38915","0.05491"
"304.92000","25.41025","0.05449"
"305.17200","25.43118","0.05443"
"305.42400","25.45223","0.05384"
"305.67600","25.47321","0.05429"
"305.92800","25.49420","0.05449"
"306.18000","25.51518","0.05452"
"306.43200","25.53629","0.05405"
"306.68400","25.55721","0.05415"
"306.93600","25.57820","0.05384"
"307.18800","25.59919","0.05436"
"307.44000","25.62017","0.05350"
"307.69200","25.64122","0.05299"
"307.94400","25.66220","0.05329"
"308.19600","25.68325","0.05302"
"308.44800","25.70418","0.05310"
"308.70000","25.72523","0.05301"
"308.95200","25.74609","0.05117"
"309.20400","25.76720","0.05103"
"309.45600","25.78818","0.05125"
"309.70800","25.80923","0.05108"
"309.96000","25.83015","0.05097"
"310.21200","25.85126","0.05124"
"310.46400","25.87219","0.05205"
"310.71600","25.89323","0.04954"
"310.96800","25.91422","0.04979"
"311.22000","25.93527","0.05077"
"311.47200","25.95625","0.05071"
"311.72400","25.97717","0.05129"
"311.97600","25.99822","0.05076"
"312.22800","26.01915","0.05071"
"312.48000","26.04025","0.05141"
"312.73200","26.06118","0.05148"
"312.98400","26.08223","0.05147"
"313.23600","26.10315","0.05061"
"313.48800","26.12426","0.05059"
"313.74000","26.14519","0.05099"
"313.99200","26.16623","0.05056"
"314.24400","26.18716","0.04990"
"314.49600","26.20827","0.04911"
"314.74800","26.22919","0.04951"
"315.00000","26.25024","0.04868"
"315.25200","26.27122","0.04898"
"315.50400","26.29221","0.04928"
"315.75600","26.31325","0.04976"
"316.00800","26.33418","0.04951"
"316.26000","26.35523","0.04979"
"316.51200","26.37621","0.04839"
"316.76400","26.39726","0.04285"
"317.01600","26.41818","0.02952"
"317.26800","26.43917","0.02894"
"317.52000","26.46016","0.02744"
"317.77200","26.48126","0.02901"
"318.02400","26.50219","0.02851"
"318.27600","26.52324","0.02695"
"318.52800","26.54422","0.02731"
"318.78000","26.56527","0.02736"
"319.03200","26.58619","0.02845"
"319.28400","26.60718","0.02818"
"319.53600","26.62817","0.02818"
"319.78800","26.64915","0.02851"
"320.04000","26.67026","0.02834"
"320.29200","26.69118","0.02900"
"320.54400","26.71229","0.02892"
"320.79600","26.73322","0.02945"
"321.04800","26.75426","0.02978"
"321.30000","26.77519","0.03023"
"321.55200","26.79617","0.03048"
"321.80400","26.81716","0.03092"
"322.05600","26.83827","0.03048"
"322.30800","26.85919","0.03133"
"322.56000","26.88024","0.03123"
"322.81200","26.90122","0.03193"
"323.06400","26.92221","0.03176"
"323.31600","26.94320","0.03199"
"323.56800","26.96418","0.03259"
"323.82000","26.98523","0.03324"
"324.07200","27.00621","0.03387"
"324.32400","27.02720","0.03497"
"324.57600","27.04813","0.03461"
"324.82800","27.06917","0.03499"
"325.08000","27.09016","0.03578"
"325.33200","27.11121","0.03605"
"325.58400","27.13219","0.03646"
"325.83600","27.15324","0.03709"
"326.08800","27.17417","0.03750"
"326.34000","27.19527","0.03777"
"326.59200","27.21620","0.03777"
"326.84400","27.23724","0.03900"
"327.09600","27.25823","0.03840"
"327.34800","27.27927","0.03961"
"327.60000","27.30020","0.04025"
"327.85200","27.32119","0.04072"
"328.10400","27.34223","0.04117"
"328.35600","27.36316","0.04129"
"328.60800","27.38426","0.04107"
"328.86000","27.40519","0.04135"
"329.11200","27.42624","0.04151"
"329.36400","27.44722","0.04234"
"329.61600","27.46821","0.04248"
"329.86800","27.48914","0.04280"
"330.12000","27.51024","0.04344"
"330.37200","27.53123","0.04384"
"330.62400","27.55221","0.04409"
"330.87600","27.57320","0.04441"
"331.12800","27.59418","0.04462"
"331.38000","27.61523","0.04494"
"331.63200","27.63616","0.04579"
"331.88400","27.65726","0.04584"
"332.13600","27.67819","0.04617"
"332.38800","27.69924","0.04620"
"332.64000","27.72010","0.04670"
"332.89200","27.74121","0.04713"
"333.14400","27.76220","0.04760"
"333.39600","27.78324","0.04807"
"333.64800","27.80417","0.04862"
"333.90000","27.82521","0.04921"
"334.15200","27.84620","0.04890"
"334.40400","27.86730","0.03662"
"334.65600","27.88817","0.03755"
"334.90800","27.90922","0.03790"
"335.16000","27.93026","0.03880"
"335.41200","27.95125","0.03981"
"335.66400","27.97224","0.03945"
"335.91600","27.99322","0.04095"
"336.16800","28.01427","0.04105"
"336.42000","28.03519","0.04184"
"336.67200","28.05624","0.04189"
"336.92400","28.07717","0.04237"
"337.17600","28.09815","0.04274"
"337.42800","28.11914","0.04393"
"337.68000","28.14030","0.04475"
"337.93200","28.16117","0.04497"
"338.18400","28.18221","0.04551"
"338.43600","28.20326","0.04585"
"338.68800","28.22425","0.04705"
"338.94000","28.24517","0.04653"
"339.19200","28.26622","0.04640"
"339.44400","28.28721","0.04719"
"339.69600","28.30819","0.04722"
"339.94800","28.32918","0.04756"
"340.20000","28.35016","0.04874"
"340.45200","28.37127","0.04795"
"340.70400","28.39226","0.04875"
"340.95600","28.41324","0.04862"
"341.20800","28.43417","0.04931"
"341.46000","28.45521","0.04935"
"341.71200","28.47620","0.04972"
"341.96400","28.49718","0.05005"
"342.21600","28.51817","0.04933"
"342.46800","28.53922","0.04852"
"342.72000","28.56026","0.04884"
"342.97200","28.58125","0.04836"
"343.22400","28.60224","0.04861"
"343.47600","28.62316","0.04918"
"343.72800","28.64421","0.04958"
"343.98000","28.66520","0.05000"
"344.23200","28.68618","0.04931"
"344.48400","28.70717","0.04943"
"344.73600","28.72828","0.02165"
"344.98800","28.74920","0.02277"
"345.24000","28.77018","0.02129"
"345.49200","28.79111","0.00397"
"345.74400","28.81228","0.00146"
"345.99600","28.83320","0.00270"
"346.24800","28.85425","0.00576"
"346.50000","28.87524","0.00574"
"346.75200","28.89622","0.00257"
"347.00400","28.91721","0.00422"
"347.25600","28.93819","0.00593"
"347.50800","28.95924","0.00342"
"347.76000","28.98017","0.00337"
"348.01200","29.00121","0.00535"
"348.26400","29.02214","0.00439"
"348.51600","29.04325","0.00371"
"348.76800","29.06423","0.00516"
"349.02000","29.08521","0.00536"
"349.27200","29.10620","0.00394"
"349.52400","29.12725","0.00457"
"349.77600","29.14818","0.00521"
"350.02800","29.16922","0.00469"
"350.28000","29.19015","0.00426"
"350.53200","29.21119","0.00554"
"350.78400","29.23218","0.00466"
"351.03600","29.25322","0.00451"
"351.28800","29.27421","0.00511"
"351.54000","29.29526","0.00503"
"351.79200","29.31624","0.00473"
"352.04400","29.33723","0.00503"
"352.29600","29.35822","0.00482"
"352.54800","29.37914","0.00488"
"352.80000","29.40025","0.00514"
"353.05200","29.42117","0.00510"
"353.30400","29.44222","0.00475"
"353.55600","29.46321","0.00512"
"353.80800","29.48425","0.00550"
"354.06000","29.50524","0.00534"
"354.31200","29.52622","0.00545"
"354.56400","29.54721","0.00595"
"354.81600","29.56820","0.00544"
"355.06800","29.58924","0.00590"
"355.32000","29.61023","0.00571"
"355.57200","29.63128","0.00540"
"355.82400","29.65220","0.00573"
"356.07600","29.67325","0.00594"
"356.32800","29.69411","0.00574"
"356.58000","29.71522","0.00616"
"356.83200","29.73615","0.00578"
"357.08400","29.75725","0.00582"
"357.33600","29.77824","0.00592"
"357.58800","29.79917","0.00622"
"357.84000","29.82021","0.00615"
"358.09200","29.84126","0.00629"
"358.34400","29.86218","0.00614"
"358.59600","29.88317","0.00616"
"358.84800","29.90421","0.00592"
"359.10000","29.92520","0.00638"
"359.35200","29.94625","0.00622"
"359.60400","29.96717","0.00609"
"359.85600","29.98822","0.00635"
"360.10800","30.00921","0.00627"
"360.36000","30.03025","0.00642"
"360.61200","30.05118","0.00641"
"360.86400","30.07222","0.00636"
"361.11600","30.09321","0.00666"
"361.36800","30.11432","0.00644"
"361.62000","30.13512","0.00637"
"361.87200","30.15623","0.00675"
"362.12400","30.17721","0.00681"
"362.37600","30.19826","0.00684"
"362.62800","30.21918","0.00673"
"362.88000","30.24017","0.00704"
"363.13200","30.26122","0.00696"
"363.38400","30.28226","0.00688"
"363.63600","30.30325","0.00686"
"363.88800","30.32418","0.00678"
"364.14000","30.34522","0.00712"
"364.39200","30.36621","0.00755"
"364.64400","30.38725","0.00708"
"364.89600","30.40818","0.00728"
"365.14800","30.42917","0.00683"
"365.40000","30.45021","0.00710"
"365.65200","30.47126","0.00703"
"365.90400","30.49218","0.00708"
"366.15600","30.51323","0.00741"
"366.40800","30.53422","0.00709"
"366.66000","30.55520","0.00739"
"366.91200","30.57619","0.00777"
"367.16400","30.59718","0.00703"
"367.41600","30.61822","0.00747"
"367.66800","30.63921","0.00743"
"367.92000","30.66025","0.00721"
"368.17200","30.68118","0.00726"
"368.42400","30.70222","0.00776"
"368.67600","30.72315","0.00731"
"368.92800","30.74420","0.00763"
"369.18000","30.76512","0.00734"
"369.43200","30.78623","0.00759"
"369.68400","30.80722","0.00730"
"369.93600","30.82826","0.00758"
"370.18800","30.84919","0.00751"
"370.44000","30.87023","0.00791"
"370.69200","30.89128","0.00731"
"370.94400","30.91215","0.00755"
"371.19600","30.93319","0.00812"
"371.44800","30.95418","0.00783"
"371.70000","30.97528","0.00825"
"371.95200","30.99615","0.00786"
"372.20400","31.01726","0.00787"
"372.45600","31.03818","0.00781"
"372.70800","31.05929","0.00777"
"372.96000","31.08015","0.00790"
"373.21200","31.10120","0.00806"
"373.46400","31.12218","0.00799"
"373.71600","31.14329","0.00853"
"373.96800","31.16422","0.00837"
"374.22000","31.18526","0.00819"
"374.47200","31.20619","0.00840"
"374.56600","31.21408","0.00836"