File: Force_trajectories/161218_2/Specimen_RawData_7.csv
End date,"12/18/2016"
Specimen label,"16BG_30"
Maximum Load,"0.63762",N

Time,Extension,Load
(s),(mm),(N)
"0.00000","0.00000","0.00041"
"0.34200","0.02834","0.00562"
"0.68400","0.05716","0.00854"
"1.02600","0.08574","0.01081"
"1.36800","0.11414","0.01241"
"1.71000","0.14272","0.01339"
"2.05200","0.17118","0.01462"
"2.39400","0.19964","0.01576"
"2.73600","0.22822","0.01599"
"3.07800","0.25662","0.01652"
"3.42000","0.28520","0.01722"
"3.76200","0.31372","0.01742"
"4.10400","0.34212","0.01748"
"4.44600","0.37070","0.01762"
"4.78800","0.39921","0.01859"
"5.13000","0.42761","0.01882"
"5.47200","0.45613","0.01859"
"5.81400","0.48465","0.01889"
"6.15600","0.51311","0.01942"
"6.49800","0.54169","0.01941"
"6.84000","0.57021","0.01975"
"7.18200","0.59867","0.02050"
"7.52400","0.62719","0.02035"
"7.86600","0.65559","0.02042"
"8.20800","0.68423","0.01987"
"8.55000","0.71269","0.02073"
"8.89200","0.74109","0.02052"
"9.23400","0.76967","0.02099"
"9.57600","0.79813","0.02103"
"9.91800","0.82665","0.02094"
"10.26000","0.85517","0.02141"
"10.60200","0.88369","0.02150"
"10.94400","0.91215","0.02172"
"11.28600","0.94073","0.02188"
"11.62800","0.96913","0.02218"
"11.97000","0.99771","0.02224"
"12.31200","1.02617","0.02233"
"12.65400","1.05469","0.02252"
"12.99600","1.08315","0.02235"
"13.33800","1.11167","0.02291"
"13.68000","1.14013","0.02306"
"14.02200","1.16865","0.02327"
"14.36400","1.19717","0.02294"
"14.70600","1.22569","0.02302"
"15.04800","1.25420","0.02362"
"15.39000","1.28266","0.02341"
"15.73200","1.31118","0.02383"
"16.07400","1.33970","0.02390"
"16.41600","1.36810","0.02419"
"16.75800","1.39668","0.02423"
"17.10000","1.42520","0.02337"
"17.44200","1.45366","0.02336"
"17.78400","1.48218","0.02329"
"18.12600","1.51064","0.02321"
"18.46800","1.53916","0.02373"
"18.81000","1.56768","0.02287"
"19.15200","1.59614","0.02371"
"19.49400","1.62466","0.02364"
"19.83600","1.65318","0.02352"
"20.17800","1.68164","0.02396"
"20.52000","1.71016","0.02398"
"20.86200","1.73862","0.02374"
"21.20400","1.76714","0.02362"
"21.54600","1.79572","0.02371"
"21.88800","1.82418","0.02404"
"22.23000","1.85264","0.02418"
"22.57200","1.88122","0.02406"
"22.91400","1.90968","0.02407"
"23.25600","1.93820","0.02417"
"23.59800","1.96672","0.02436"
"23.94000","1.99518","0.02457"
"24.28200","2.02370","0.02496"
"24.62400","2.05216","0.02474"
"24.96600","2.08062","0.02511"
"25.30800","2.10920","0.02510"
"25.65000","2.13760","0.02532"
"25.99200","2.16617","0.02566"
"26.33400","2.19469","0.02552"
"26.67600","2.22309","0.02555"
"27.01800","2.25173","0.02540"
"27.36000","2.28019","0.02554"
"27.70200","2.30865","0.02592"
"28.04400","2.33723","0.02595"
"28.38600","2.36563","0.02604"
"28.72800","2.39415","0.02609"
"29.07000","2.42267","0.02651"
"29.41200","2.45113","0.02623"
"29.75400","2.47971","0.02661"
"30.09600","2.50823","0.02658"
"30.43800","2.53663","0.02643"
"30.78000","2.56515","0.02667"
"31.12200","2.59367","0.02690"
"31.46400","2.62213","0.02649"
"31.80600","2.65071","0.02670"
"32.14800","2.67917","0.02668"
"32.49000","2.70769","0.02687"
"32.83200","2.73615","0.02722"
"33.17400","2.76467","0.02685"
"33.51600","2.79319","0.02681"
"33.85800","2.82171","0.02722"
"34.20000","2.85011","0.02724"
"34.54200","2.87869","0.02775"
"34.88400","2.90721","0.02785"
"35.22600","2.93561","0.02785"
"35.56800","2.96419","0.02741"
"35.91000","2.99271","0.02747"
"36.25200","3.02117","0.02756"
"36.59400","3.04968","0.02836"
"36.93600","3.07814","0.02825"
"37.27800","3.10666","0.02812"
"37.62000","3.13524","0.02861"
"37.96200","3.16364","0.02838"
"38.30400","3.19216","0.02868"
"38.64600","3.22068","0.02854"
"38.98800","3.24914","0.02869"
"39.33000","3.27766","0.02895"
"39.67200","3.30612","0.02900"
"40.01400","3.33464","0.02916"
"40.35600","3.36322","0.02928"
"40.69800","3.39162","0.02906"
"41.04000","3.42014","0.02921"
"41.38200","3.44872","0.02986"
"41.72400","3.47712","0.02974"
"42.06600","3.50570","0.02952"
"42.40800","3.53416","0.02957"
"42.75000","3.56262","0.02984"
"43.09200","3.59120","0.02986"
"43.43400","3.61966","0.02999"
"43.77600","3.64812","0.02960"
"44.11800","3.67664","0.03042"
"44.46000","3.70510","0.03006"
"44.80200","3.73374","0.03043"
"45.14400","3.76220","0.03100"
"45.48600","3.79066","0.03027"
"45.82800","3.81918","0.03089"
"46.17000","3.84770","0.03071"
"46.51200","3.87616","0.03099"
"46.85400","3.90468","0.03068"
"47.19600","3.93314","0.03054"
"47.53800","3.96165","0.03114"
"47.88000","3.99017","0.03154"
"48.22200","4.01863","0.03111"
"48.56400","4.04715","0.03141"
"48.90600","4.07567","0.03136"
"49.24800","4.10419","0.03148"
"49.59000","4.13271","0.03160"
"49.93200","4.16117","0.03155"
"50.27400","4.18969","0.03168"
"50.61600","4.21821","0.03156"
"50.95800","4.24667","0.03172"
"51.30000","4.27519","0.03220"
"51.64200","4.30371","0.03222"
"51.98400","4.33217","0.03202"
"52.32600","4.36063","0.03204"
"52.66800","4.38915","0.03225"
"53.01000","4.41761","0.03245"
"53.35200","4.44619","0.03249"
"53.69400","4.47471","0.03269"
"54.03600","4.50311","0.03239"
"54.37800","4.53169","0.03298"
"54.72000","4.56015","0.03278"
"55.06200","4.58873","0.03295"
"55.40400","4.61719","0.03290"
"55.74600","4.64565","0.03299"
"56.08800","4.67417","0.03309"
"56.43000","4.70275","0.03311"
"56.77200","4.73115","0.03339"
"57.11400","4.75967","0.03288"
"57.45600","4.78819","0.03299"
"57.79800","4.81664","0.03294"
"58.14000","4.84522","0.03307"
"58.48200","4.87362","0.03313"
"58.82400","4.90214","0.03343"
"59.16600","4.93072","0.03347"
"59.50800","4.95906","0.03318"
"59.85000","4.98770","0.03358"
"60.19200","5.01622","0.03383"
"60.53400","5.04462","0.03386"
"60.87600","5.07320","0.03420"
"61.21800","5.10166","0.03426"
"61.56000","5.13012","0.03423"
"61.90200","5.15870","0.03403"
"62.24400","5.18716","0.03420"
"62.58600","5.21568","0.03436"
"62.92800","5.24414","0.03424"
"63.27000","5.27260","0.03453"
"63.61200","5.30118","0.03464"
"63.95400","5.32970","0.03481"
"64.29600","5.35816","0.03469"
"64.63800","5.38674","0.03463"
"64.98000","5.41514","0.03456"
"65.32200","5.44366","0.03502"
"65.66400","5.47218","0.03528"
"66.00600","5.50064","0.03537"
"66.34800","5.52922","0.03568"
"66.69000","5.55768","0.03521"
"67.03200","5.58614","0.03529"
"67.37400","5.61466","0.03549"
"67.71600","5.64318","0.03579"
"68.05800","5.67158","0.03543"
"68.40000","5.70021","0.03597"
"68.74200","5.72867","0.03532"
"69.08400","5.75713","0.03606"
"69.42600","5.78565","0.03603"
"69.76800","5.81417","0.03578"
"70.11000","5.84269","0.03561"
"70.45200","5.87115","0.03584"
"70.79400","5.89967","0.03581"
"71.13600","5.92819","0.03581"
"71.47800","5.95665","0.03639"
"71.82000","5.98511","0.03611"
"72.16200","6.01369","0.03649"
"72.50400","6.04215","0.03692"
"72.84600","6.07061","0.03715"
"73.18800","6.09919","0.03638"
"73.53000","6.12771","0.03664"
"73.87200","6.15617","0.03682"
"74.21400","6.18475","0.03653"
"74.55600","6.21315","0.03691"
"74.89800","6.24167","0.03696"
"75.24000","6.27019","0.03687"
"75.58200","6.29865","0.03699"
"75.92400","6.32717","0.03684"
"76.26600","6.35569","0.03735"
"76.60800","6.38415","0.03718"
"76.95000","6.41273","0.03717"
"77.29200","6.44107","0.03757"
"77.63400","6.46965","0.03720"
"77.97600","6.49817","0.03758"
"78.31800","6.52663","0.03752"
"78.66000","6.55520","0.03768"
"79.00200","6.58372","0.03765"
"79.34400","6.61218","0.03797"
"79.68600","6.64070","0.03806"
"80.02800","6.66910","0.03803"
"80.37000","6.69768","0.03806"
"80.71200","6.72620","0.03816"
"81.05400","6.75460","0.03827"
"81.39600","6.78318","0.03825"
"81.73800","6.81170","0.03827"
"82.08000","6.84010","0.03846"
"82.42200","6.86862","0.03807"
"82.76400","6.89714","0.03791"
"83.10600","6.92560","0.03851"
"83.44800","6.95418","0.03860"
"83.79000","6.98270","0.03860"
"84.13200","7.01122","0.03873"
"84.47400","7.03968","0.03894"
"84.81600","7.06814","0.03889"
"85.15800","7.09672","0.03908"
"85.50000","7.12518","0.03906"
"85.84200","7.15364","0.03935"
"86.18400","7.18216","0.03962"
"86.52600","7.21068","0.03922"
"86.86800","7.23914","0.03972"
"87.21000","7.26772","0.03975"
"87.55200","7.29618","0.03997"
"87.89400","7.32464","0.04003"
"88.23600","7.35316","0.03973"
"88.57800","7.38168","0.03976"
"88.92000","7.41020","0.03935"
"89.26200","7.43871","0.03907"
"89.60400","7.46712","0.03920"
"89.94600","7.49563","0.03926"
"90.28800","7.52415","0.03936"
"90.63000","7.55267","0.03951"
"90.97200","7.58119","0.03993"
"91.31400","7.60965","0.03981"
"91.65600","7.63811","0.04002"
"91.99800","7.66669","0.04027"
"92.34000","7.69515","0.04016"
"92.68200","7.72367","0.04038"
"93.02400","7.75225","0.04041"
"93.36600","7.78059","0.04017"
"93.70800","7.80923","0.04078"
"94.05000","7.83769","0.04022"
"94.39200","7.86615","0.04014"
"94.73400","7.89473","0.04101"
"95.07600","7.92319","0.04093"
"95.41800","7.95165","0.04139"
"95.76000","7.98017","0.04156"
"96.10200","8.00863","0.04155"
"96.44400","8.03715","0.04123"
"96.78600","8.06567","0.04176"
"97.12800","8.09413","0.04192"
"97.47000","8.12271","0.04169"
"97.81200","8.15117","0.04219"
"98.15400","8.17963","0.04225"
"98.49600","8.20815","0.04200"
"98.83800","8.23661","0.04247"
"99.18000","8.26519","0.04255"
"99.52200","8.29365","0.04240"
"99.86400","8.32210","0.04245"
"100.20600","8.35068","0.04315"
"100.54800","8.37920","0.04304"
"100.89000","8.40760","0.04383"
"101.23200","8.43618","0.04335"
"101.57400","8.46470","0.04372"
"101.91600","8.49316","0.04386"
"102.25800","8.52168","0.04406"
"102.60000","8.55014","0.04432"
"102.94200","8.57866","0.04430"
"103.28400","8.60718","0.04421"
"103.62600","8.63564","0.04388"
"103.96800","8.66416","0.04457"
"104.31000","8.69268","0.04484"
"104.65200","8.72114","0.04482"
"104.99400","8.74972","0.04497"
"105.33600","8.77818","0.04521"
"105.67800","8.80664","0.04521"
"106.02000","8.83516","0.04539"
"106.36200","8.86368","0.04394"
"106.70400","8.89220","0.04393"
"107.04600","8.92072","0.04430"
"107.38800","8.94918","0.04397"
"107.73000","8.97770","0.04432"
"108.07200","9.00616","0.04447"
"108.41400","9.03462","0.04455"
"108.75600","9.06314","0.04482"
"109.09800","9.09166","0.04494"
"109.44000","9.12012","0.04535"
"109.78200","9.14870","0.04573"
"110.12400","9.17715","0.04575"
"110.46600","9.20562","0.04598"
"110.80800","9.23425","0.04665"
"111.15000","9.26259","0.04667"
"111.49200","9.29117","0.04666"
"111.83400","9.31969","0.04679"
"112.17600","9.34815","0.04692"
"112.51800","9.37673","0.04726"
"112.86000","9.40513","0.04717"
"113.20200","9.43365","0.04744"
"113.54400","9.46223","0.04825"
"113.88600","9.49063","0.04801"
"114.22800","9.51921","0.04803"
"114.57000","9.54773","0.04862"
"114.91200","9.57607","0.04894"
"115.25400","9.60465","0.04861"
"115.59600","9.63317","0.04871"
"115.93800","9.66163","0.04880"
"116.28000","9.69021","0.04991"
"116.62200","9.71867","0.04958"
"116.96400","9.74719","0.04995"
"117.30600","9.77565","0.05032"
"117.64800","9.80417","0.05042"
"117.99000","9.83269","0.05016"
"118.33200","9.86121","0.05054"
"118.67400","9.88961","0.05130"
"119.01600","9.91819","0.05127"
"119.35800","9.94671","0.05151"
"119.70000","9.97511","0.05146"
"120.04200","10.00369","0.05174"
"120.38400","10.03215","0.05261"
"120.72600","10.06066","0.05273"
"121.06800","10.08913","0.05301"
"121.41000","10.11764","0.05291"
"121.75200","10.14616","0.05320"
"122.09400","10.17468","0.05333"
"122.43600","10.20314","0.05396"
"122.77800","10.23172","0.05362"
"123.12000","10.26018","0.05364"
"123.46200","10.28864","0.05438"
"123.80400","10.31716","0.05440"
"124.14600","10.34568","0.05430"
"124.48800","10.37420","0.05416"
"124.83000","10.40272","0.05432"
"125.17200","10.43118","0.05471"
"125.51400","10.45964","0.05463"
"125.85600","10.48822","0.05459"
"126.19800","10.51668","0.05559"
"126.54000","10.54520","0.05593"
"126.88200","10.57366","0.05565"
"127.22400","10.60218","0.05605"
"127.56600","10.63070","0.05645"
"127.90800","10.65916","0.05651"
"128.25000","10.68762","0.05706"
"128.59200","10.71620","0.05718"
"128.93400","10.74460","0.05707"
"129.27600","10.77312","0.05720"
"129.61800","10.80170","0.05765"
"129.96000","10.83010","0.05806"
"130.30200","10.85874","0.05774"
"130.64400","10.88713","0.05864"
"130.98600","10.91566","0.05860"
"131.32800","10.94423","0.05910"
"131.67000","10.97263","0.05937"
"132.01200","11.00115","0.05933"
"132.35400","11.02967","0.05961"
"132.69600","11.05813","0.06015"
"133.03800","11.08665","0.06011"
"133.38000","11.11523","0.06031"
"133.72200","11.14357","0.06105"
"134.06400","11.17215","0.06103"
"134.40600","11.20061","0.06179"
"134.74800","11.22913","0.06172"
"135.09000","11.25765","0.06228"
"135.43200","11.28617","0.06181"
"135.77400","11.31469","0.06286"
"136.11600","11.34321","0.06270"
"136.45800","11.37155","0.06309"
"136.80000","11.40019","0.06348"
"137.14200","11.42865","0.06375"
"137.48400","11.45717","0.06447"
"137.82600","11.48569","0.06461"
"138.16800","11.51415","0.06550"
"138.51000","11.54267","0.06557"
"138.85200","11.57119","0.06555"
"139.19400","11.59965","0.06600"
"139.53600","11.62817","0.06566"
"139.87800","11.65669","0.06649"
"140.22000","11.68515","0.06653"
"140.56200","11.71367","0.06749"
"140.90400","11.74219","0.06728"
"141.24600","11.77065","0.06761"
"141.58800","11.79917","0.06756"
"141.93000","11.82769","0.06814"
"142.27200","11.85614","0.06849"
"142.61400","11.88466","0.06843"
"142.95600","11.91318","0.06934"
"143.29800","11.94164","0.06967"
"143.64000","11.97016","0.06941"
"143.98200","11.99862","0.06985"
"144.32400","12.02720","0.07085"
"144.66600","12.05572","0.07048"
"145.00800","12.08412","0.07106"
"145.35000","12.11270","0.07169"
"145.69200","12.14122","0.07260"
"146.03400","12.16968","0.07291"
"146.37600","12.19820","0.07288"
"146.71800","12.22666","0.07335"
"147.06000","12.25512","0.07369"
"147.40200","12.28364","0.07438"
"147.74400","12.31216","0.07420"
"148.08600","12.34068","0.07523"
"148.42800","12.36914","0.07585"
"148.77000","12.39760","0.07583"
"149.11200","12.42618","0.07628"
"149.45400","12.45464","0.07648"
"149.79600","12.48310","0.07747"
"150.13800","12.51174","0.07807"
"150.48000","12.54014","0.07761"
"150.82200","12.56872","0.07847"
"151.16400","12.59724","0.07956"
"151.50600","12.62564","0.07981"
"151.84800","12.65416","0.07994"
"152.19000","12.68262","0.07951"
"152.53200","12.71114","0.08078"
"152.87400","12.73972","0.08080"
"153.21600","12.76824","0.08100"
"153.55800","12.79669","0.08149"
"153.90000","12.82515","0.08212"
"154.24200","12.85361","0.08291"
"154.58400","12.88225","0.08310"
"154.92600","12.91071","0.08334"
"155.26800","12.93911","0.08353"
"155.61000","12.96763","0.08411"
"155.95200","12.99615","0.08464"
"156.29400","13.02467","0.08500"
"156.63600","13.05319","0.08522"
"156.97800","13.08165","0.08541"
"157.32000","13.11017","0.08593"
"157.66200","13.13863","0.08682"
"158.00400","13.16715","0.08723"
"158.34600","13.19567","0.08758"
"158.68800","13.22419","0.08785"
"159.03000","13.25265","0.08841"
"159.37200","13.28123","0.08975"
"159.71400","13.30969","0.08991"
"160.05600","13.33815","0.09016"
"160.39800","13.36673","0.09061"
"160.74000","13.39519","0.09133"
"161.08200","13.42365","0.09188"
"161.42400","13.45217","0.09346"
"161.76600","13.48069","0.09350"
"162.10800","13.50915","0.09489"
"162.45000","13.53773","0.09418"
"162.79200","13.56607","0.09528"
"163.13400","13.59471","0.09575"
"163.47600","13.62316","0.09721"
"163.81800","13.65168","0.09716"
"164.16000","13.68015","0.09822"
"164.50200","13.70866","0.09884"
"164.84400","13.73712","0.09961"
"165.18600","13.76570","0.10088"
"165.52800","13.79416","0.10129"
"165.87000","13.82268","0.10221"
"166.21200","13.85120","0.10258"
"166.55400","13.87960","0.10264"
"166.89600","13.90818","0.10363"
"167.23800","13.93664","0.10377"
"167.58000","13.96516","0.10447"
"167.92200","13.99374","0.10495"
"168.26400","14.02214","0.10547"
"168.60600","14.05066","0.10585"
"168.94800","14.07924","0.10664"
"169.29000","14.10764","0.10720"
"169.63200","14.13622","0.10737"
"169.97400","14.16468","0.10783"
"170.31600","14.19314","0.10818"
"170.65800","14.22166","0.10873"
"171.00000","14.25018","0.10884"
"171.34200","14.27864","0.10879"
"171.68400","14.30722","0.10923"
"172.02600","14.33562","0.10970"
"172.36800","14.36414","0.11000"
"172.71000","14.39266","0.11061"
"173.05200","14.42112","0.11119"
"173.39400","14.44970","0.11181"
"173.73600","14.47815","0.11177"
"174.07800","14.50668","0.11262"
"174.42000","14.53519","0.11273"
"174.76200","14.56365","0.11317"
"175.10400","14.59211","0.11395"
"175.44600","14.62063","0.11440"
"175.78800","14.64915","0.11492"
"176.13000","14.67767","0.11494"
"176.47200","14.70619","0.11565"
"176.81400","14.73465","0.11567"
"177.15600","14.76317","0.11675"
"177.49800","14.79163","0.11693"
"177.84000","14.82015","0.11643"
"178.18200","14.84873","0.11702"
"178.52400","14.87719","0.11781"
"178.86600","14.90565","0.11837"
"179.20800","14.93417","0.11859"
"179.55000","14.96263","0.11951"
"179.89200","14.99115","0.11997"
"180.23400","15.01967","0.12034"
"180.57600","15.04813","0.12084"
"180.91800","15.07665","0.12152"
"181.26000","15.10517","0.12177"
"181.60200","15.13363","0.12239"
"181.94400","15.16221","0.12313"
"182.28600","15.19067","0.12340"
"182.62800","15.21913","0.12396"
"182.97000","15.24771","0.12445"
"183.31200","15.27617","0.12473"
"183.65400","15.30469","0.12530"
"183.99600","15.33315","0.12619"
"184.33800","15.36161","0.12637"
"184.68000","15.39018","0.12760"
"185.02200","15.41871","0.12837"
"185.36400","15.44710","0.12863"
"185.70600","15.47569","0.12966"
"186.04800","15.50420","0.13061"
"186.39000","15.53266","0.13101"
"186.73200","15.56118","0.13169"
"187.07400","15.58958","0.13333"
"187.41600","15.61816","0.13397"
"187.75800","15.64668","0.13482"
"188.10000","15.67508","0.13533"
"188.44200","15.70372","0.13589"
"188.78400","15.73218","0.13686"
"189.12600","15.76064","0.13814"
"189.46800","15.78922","0.13873"
"189.81000","15.81762","0.13838"
"190.15200","15.84614","0.13979"
"190.49400","15.87466","0.14015"
"190.83600","15.90312","0.14066"
"191.17800","15.93170","0.14190"
"191.52000","15.96022","0.14188"
"191.86200","15.98862","0.14370"
"192.20400","16.01720","0.14496"
"192.54600","16.04566","0.14483"
"192.88800","16.07412","0.14531"
"193.23000","16.10270","0.14725"
"193.57200","16.13116","0.14812"
"193.91400","16.15968","0.14864"
"194.25600","16.18814","0.14998"
"194.59800","16.21665","0.15138"
"194.94000","16.24512","0.15297"
"195.28200","16.27363","0.15428"
"195.62400","16.30215","0.15576"
"195.96600","16.33068","0.15669"
"196.30800","16.35925","0.15827"
"196.65000","16.38759","0.15946"
"196.99200","16.41617","0.15990"
"197.33400","16.44469","0.16151"
"197.67600","16.47315","0.16224"
"198.01800","16.50167","0.16329"
"198.36000","16.53013","0.16438"
"198.70200","16.55865","0.16472"
"199.04400","16.58717","0.16559"
"199.38600","16.61563","0.16718"
"199.72800","16.64415","0.16785"
"200.07000","16.67267","0.16910"
"200.41200","16.70113","0.16940"
"200.75400","16.72971","0.17002"
"201.09600","16.75811","0.17060"
"201.43800","16.78663","0.17249"
"201.78000","16.81527","0.17277"
"202.12200","16.84367","0.17367"
"202.46400","16.87213","0.17409"
"202.80600","16.90071","0.17526"
"203.14800","16.92911","0.17532"
"203.49000","16.95769","0.17699"
"203.83200","16.98615","0.17797"
"204.17400","17.01461","0.17879"
"204.51600","17.04313","0.17974"
"204.85800","17.07165","0.18078"
"205.20000","17.10016","0.18131"
"205.54200","17.12868","0.18191"
"205.88400","17.15709","0.18347"
"206.22600","17.18572","0.18450"
"206.56800","17.21418","0.18509"
"206.91000","17.24264","0.18523"
"207.25200","17.27122","0.18718"
"207.59400","17.29962","0.18776"
"207.93600","17.32814","0.18897"
"208.27800","17.35672","0.18912"
"208.62000","17.38518","0.19017"
"208.96200","17.41370","0.19040"
"209.30400","17.44216","0.19119"
"209.64600","17.47062","0.19282"
"209.98800","17.49920","0.19392"
"210.33000","17.52766","0.19487"
"210.67200","17.55618","0.19589"
"211.01400","17.58470","0.19694"
"211.35600","17.61316","0.19860"
"211.69800","17.64168","0.20053"
"212.04000","17.67020","0.20170"
"212.38200","17.69866","0.20287"
"212.72400","17.72712","0.20336"
"213.06600","17.75564","0.20094"
"213.40800","17.78416","0.20302"
"213.75000","17.81262","0.20436"
"214.09200","17.84120","0.20601"
"214.43400","17.86966","0.20683"
"214.77600","17.89818","0.20758"
"215.11800","17.92669","0.20893"
"215.46000","17.95516","0.21083"
"215.80200","17.98368","0.21185"
"216.14400","18.01213","0.21325"
"216.48600","18.04071","0.21428"
"216.82800","18.06923","0.21542"
"217.17000","18.09763","0.21639"
"217.51200","18.12621","0.21739"
"217.85400","18.15467","0.21809"
"218.19600","18.18307","0.21904"
"218.53800","18.21165","0.22022"
"218.88000","18.24011","0.22124"
"219.22200","18.26863","0.22222"
"219.56400","18.29721","0.22319"
"219.90600","18.32567","0.22379"
"220.24800","18.35413","0.22478"
"220.59000","18.38271","0.22553"
"220.93200","18.41111","0.22636"
"221.27400","18.43969","0.22736"
"221.61600","18.46821","0.22827"
"221.95800","18.49661","0.22772"
"222.30000","18.52519","0.22730"
"222.64200","18.55365","0.22820"
"222.98400","18.58211","0.22978"
"223.32600","18.61075","0.23069"
"223.66800","18.63909","0.23212"
"224.01000","18.66767","0.23346"
"224.35200","18.69625","0.23492"
"224.69400","18.72459","0.23567"
"225.03600","18.75323","0.23672"
"225.37800","18.78169","0.23800"
"225.72000","18.81015","0.23881"
"226.06200","18.83873","0.23940"
"226.40400","18.86713","0.24085"
"226.74600","18.89565","0.24113"
"227.08800","18.92416","0.24278"
"227.43000","18.95263","0.24354"
"227.77200","18.98114","0.24510"
"228.11400","19.00966","0.24681"
"228.45600","19.03812","0.24754"
"228.79800","19.06664","0.24928"
"229.14000","19.09516","0.25056"
"229.48200","19.12362","0.25226"
"229.82400","19.15220","0.25360"
"230.16600","19.18066","0.25545"
"230.50800","19.20918","0.25647"
"230.85000","19.23764","0.25772"
"231.19200","19.26616","0.25954"
"231.53400","19.29468","0.26079"
"231.87600","19.32320","0.26087"
"232.21800","19.35160","0.26229"
"232.56000","19.38018","0.26357"
"232.90200","19.40864","0.26441"
"233.24400","19.43710","0.26581"
"233.58600","19.46568","0.26797"
"233.92800","19.49420","0.26852"
"234.27000","19.52266","0.26822"
"234.61200","19.55118","0.26946"
"234.95400","19.57970","0.27195"
"235.29600","19.60816","0.27233"
"235.63800","19.63674","0.27487"
"235.98000","19.66514","0.27643"
"236.32200","19.69366","0.27786"
"236.66400","19.72217","0.27967"
"237.00600","19.75070","0.28078"
"237.34800","19.77921","0.28299"
"237.69000","19.80767","0.28436"
"238.03200","19.83614","0.28570"
"238.37400","19.86471","0.28696"
"238.71600","19.89311","0.28798"
"239.05800","19.92163","0.28983"
"239.40000","19.95021","0.29173"
"239.74200","19.97861","0.29356"
"240.08400","20.00719","0.29444"
"240.42600","20.03571","0.29688"
"240.76800","20.06417","0.30007"
"241.11000","20.09269","0.30320"
"241.45200","20.12109","0.30508"
"241.79400","20.14967","0.30794"
"242.13600","20.17819","0.30935"
"242.47800","20.20659","0.31149"
"242.82000","20.23523","0.31304"
"243.16200","20.26369","0.31514"
"243.50400","20.29209","0.31580"
"243.84600","20.32073","0.31690"
"244.18800","20.34919","0.31828"
"244.53000","20.37771","0.31942"
"244.87200","20.40617","0.32104"
"245.21400","20.43463","0.32229"
"245.55600","20.46321","0.32383"
"245.89800","20.49167","0.32465"
"246.24000","20.52013","0.32581"
"246.58200","20.54865","0.32774"
"246.92400","20.57716","0.32874"
"247.26600","20.60568","0.32992"
"247.60800","20.63414","0.33082"
"247.95000","20.66267","0.33194"
"248.29200","20.69112","0.33289"
"248.63400","20.71970","0.33396"
"248.97600","20.74817","0.33485"
"249.31800","20.77668","0.33649"
"249.66000","20.80520","0.33675"
"250.00200","20.83366","0.33812"
"250.34400","20.86218","0.33929"
"250.68600","20.89064","0.34066"
"251.02800","20.91910","0.34172"
"251.37000","20.94768","0.34324"
"251.71200","20.97620","0.34420"
"252.05400","21.00466","0.34489"
"252.39600","21.03318","0.34638"
"252.73800","21.06164","0.34809"
"253.08000","21.09016","0.35004"
"253.42200","21.11868","0.35200"
"253.76400","21.14714","0.35492"
"254.10600","21.17566","0.35692"
"254.44800","21.20418","0.35731"
"254.79000","21.23264","0.35937"
"255.13200","21.26116","0.36230"
"255.47400","21.28968","0.36442"
"255.81600","21.31814","0.36636"
"256.15800","21.34672","0.36775"
"256.50000","21.37512","0.36962"
"256.84200","21.40364","0.37208"
"257.18400","21.43222","0.37324"
"257.52600","21.46062","0.37575"
"257.86800","21.48919","0.37793"
"258.21000","21.51771","0.38023"
"258.55200","21.54611","0.38161"
"258.89400","21.57470","0.38309"
"259.23600","21.60315","0.38456"
"259.57800","21.63167","0.38690"
"259.92000","21.66019","0.38836"
"260.26200","21.68865","0.39060"
"260.60400","21.71717","0.39109"
"260.94600","21.74563","0.39310"
"261.28800","21.77409","0.39439"
"261.63000","21.80267","0.39589"
"261.97200","21.83119","0.39705"
"262.31400","21.85965","0.39910"
"262.65600","21.88817","0.40056"
"262.99800","21.91663","0.40292"
"263.34000","21.94515","0.40506"
"263.68200","21.97367","0.40700"
"264.02400","22.00213","0.40924"
"264.36600","22.03071","0.41124"
"264.70800","22.05917","0.41296"
"265.05000","22.08763","0.41386"
"265.39200","22.11621","0.41568"
"265.73400","22.14467","0.41691"
"266.07600","22.17319","0.41818"
"266.41800","22.20171","0.41975"
"266.76000","22.23017","0.42103"
"267.10200","22.25869","0.42227"
"267.44400","22.28715","0.42359"
"267.78600","22.31566","0.42495"
"268.12800","22.34419","0.42617"
"268.47000","22.37271","0.42744"
"268.81200","22.40117","0.42894"
"269.15400","22.42969","0.43072"
"269.49600","22.45815","0.43298"
"269.83800","22.48660","0.43488"
"270.18000","22.51512","0.43721"
"270.52200","22.54370","0.43922"
"270.86400","22.57216","0.44159"
"271.20600","22.60068","0.44403"
"271.54800","22.62914","0.44626"
"271.89000","22.65766","0.44801"
"272.23200","22.68624","0.45030"
"272.57400","22.71464","0.45224"
"272.91600","22.74316","0.45452"
"273.25800","22.77168","0.45695"
"273.60000","22.80014","0.45930"
"273.94200","22.82872","0.46155"
"274.28400","22.85718","0.46436"
"274.62600","22.88564","0.46653"
"274.96800","22.91422","0.46811"
"275.31000","22.94256","0.47011"
"275.65200","22.97114","0.47140"
"275.99400","22.99972","0.47327"
"276.33600","23.02812","0.47584"
"276.67800","23.05670","0.47709"
"277.02000","23.08516","0.47944"
"277.36200","23.11362","0.48179"
"277.70400","23.14226","0.48306"
"278.04600","23.17066","0.48517"
"278.38800","23.19917","0.48707"
"278.73000","23.22770","0.48925"
"279.07200","23.25610","0.49150"
"279.41400","23.28468","0.49312"
"279.75600","23.31314","0.49524"
"280.09800","23.34166","0.49656"
"280.44000","23.37017","0.49852"
"280.78200","23.39875","0.50052"
"281.12400","23.42715","0.50350"
"281.46600","23.45567","0.50661"
"281.80800","23.48413","0.50825"
"282.15000","23.51265","0.51208"
"282.49200","23.54117","0.51550"
"282.83400","23.56963","0.51859"
"283.17600","23.59821","0.52149"
"283.51800","23.62667","0.52482"
"283.86000","23.65513","0.52714"
"284.20200","23.68371","0.52898"
"284.54400","23.71217","0.53055"
"284.88600","23.74063","0.53262"
"285.22800","23.76921","0.53439"
"285.57000","23.79767","0.53654"
"285.91200","23.82619","0.53809"
"286.25400","23.85465","0.54014"
"286.59600","23.88317","0.54288"
"286.93800","23.91169","0.54511"
"287.28000","23.94015","0.54684"
"287.62200","23.96867","0.54919"
"287.96400","23.99719","0.55140"
"288.30600","24.02571","0.55351"
"288.64800","24.05417","0.55632"
"288.99000","24.08269","0.55801"
"289.33200","24.11115","0.56101"
"289.67400","24.13967","0.56389"
"290.01600","24.16818","0.56671"
"290.35800","24.19665","0.56910"
"290.70000","24.22516","0.57035"
"291.04200","24.25374","0.57158"
"291.38400","24.28209","0.57338"
"291.72600","24.31072","0.57531"
"292.06800","24.33918","0.57782"
"292.41000","24.36764","0.58027"
"292.75200","24.39622","0.52834"
"293.09400","24.42462","0.52771"
"293.43600","24.45320","0.52961"
"293.77800","24.48172","0.53051"
"294.12000","24.51012","0.53291"
"294.46200","24.53870","0.53343"
"294.80400","24.56716","0.53552"
"295.14600","24.59562","0.53724"
"295.48800","24.62420","0.53902"
"295.83000","24.65266","0.54088"
"296.17200","24.68118","0.54253"
"296.51400","24.70970","0.54524"
"296.85600","24.73810","0.54744"
"297.19800","24.76668","0.54994"
"297.54000","24.79520","0.55226"
"297.88200","24.82366","0.55423"
"298.22400","24.85218","0.55659"
"298.56600","24.88070","0.56091"
"298.90800","24.90910","0.56496"
"299.25000","24.93774","0.56851"
"299.59200","24.96614","0.57173"
"299.93400","24.99466","0.57490"
"300.27600","25.02311","0.57845"
"300.61800","25.05164","0.58118"
"300.96000","25.08022","0.58517"
"301.30200","25.10867","0.58944"
"301.64400","25.13713","0.59283"
"301.98600","25.16566","0.59543"
"302.32800","25.19411","0.59993"
"302.67000","25.22264","0.60275"
"303.01200","25.25121","0.60624"
"303.35400","25.27967","0.60892"
"303.69600","25.30813","0.61308"
"304.03800","25.33665","0.61529"
"304.38000","25.36517","0.61848"
"304.72200","25.39369","0.62093"
"305.06400","25.42221","0.62278"
"305.40600","25.45061","0.62531"
"305.74800","25.47919","0.62736"
"306.09000","25.50771","0.62895"
"306.43200","25.53617","0.63143"
"306.77400","25.56469","0.63331"
"307.11600","25.59321","0.63449"
"307.45800","25.62161","0.63656"
"307.80000","25.65019","0.63752"
"308.14200","25.67865","0.38017"
"308.48400","25.70717","0.38227"
"308.82600","25.73569","0.38147"
"309.16800","25.76415","0.38300"
"309.51000","25.79267","0.38425"
"309.85200","25.82125","0.38553"
"310.19400","25.84965","0.38690"
"310.53600","25.87817","0.38867"
"310.87800","25.90663","0.38926"
"311.22000","25.93514","0.05961"
"311.56200","25.96373","0.06282"
"311.90400","25.99212","0.06067"
"312.24600","26.02064","0.05590"
"312.58800","26.04922","0.06444"
"312.93000","26.07763","0.05775"
"313.27200","26.10614","0.05888"
"313.61400","26.13466","0.06467"
"313.95600","26.16312","0.06349"
"314.29800","26.19170","0.06157"
"314.64000","26.22010","0.06373"
"314.98200","26.24862","0.06881"
"315.32400","26.27714","0.06366"
"315.66600","26.30560","0.06617"
"316.00800","26.33418","0.07120"
"316.35000","26.36270","0.06670"
"316.69200","26.39110","0.06892"
"317.03400","26.41968","0.07235"
"317.37600","26.44820","0.07102"
"317.71800","26.47666","0.07201"
"318.06000","26.50518","0.07371"
"318.40200","26.53364","0.07684"
"318.74400","26.56222","0.07476"
"319.08600","26.59068","0.07580"
"319.42800","26.61914","0.07958"
"319.77000","26.64766","0.07833"
"320.11200","26.67618","0.07827"
"320.45400","26.70464","0.08067"
"320.79600","26.73322","0.08193"
"321.13800","26.76167","0.08096"
"321.48000","26.79014","0.08185"
"321.82200","26.81865","0.08379"
"322.16400","26.84718","0.08450"
"322.50600","26.87563","0.08390"
"322.84800","26.90409","0.08534"
"323.19000","26.93268","0.08774"
"323.53200","26.96113","0.08759"
"323.87400","26.98971","0.08749"
"324.21600","27.01817","0.08927"
"324.55800","27.04669","0.09235"
"324.90000","27.07521","0.09225"
"325.24200","27.10361","0.09192"
"325.58400","27.13219","0.09403"
"325.92600","27.16065","0.09578"
"326.26800","27.18917","0.09549"
"326.61000","27.21769","0.09549"
"326.95200","27.24609","0.09645"
"327.29400","27.27461","0.09813"
"327.63600","27.30319","0.09838"
"327.97800","27.33159","0.09850"
"328.32000","27.36023","0.10008"
"328.66200","27.38863","0.10229"
"329.00400","27.41715","0.10325"
"329.34600","27.44573","0.10296"
"329.68800","27.47413","0.10504"
"330.03000","27.50265","0.10612"
"330.37200","27.53123","0.10599"
"330.71400","27.55957","0.10637"
"331.05600","27.58821","0.10733"
"331.39800","27.61672","0.10870"
"331.74000","27.64513","0.10883"
"332.08200","27.67371","0.10844"
"332.42400","27.70216","0.10947"
"332.76600","27.73062","0.11023"
"333.10800","27.75920","0.11122"
"333.45000","27.78766","0.11156"
"333.79200","27.81618","0.11210"
"334.13400","27.84470","0.11285"
"334.47600","27.87310","0.11439"
"334.81800","27.90174","0.11425"
"335.16000","27.93020","0.11508"
"335.50200","27.95866","0.11573"
"335.84400","27.98718","0.11678"
"336.18600","28.01564","0.11764"
"336.52800","28.04416","0.11888"
"336.87000","28.07268","0.11916"
"337.21200","28.10114","0.11664"
"337.55400","28.12966","0.11114"
"337.89600","28.15818","0.11200"
"338.23800","28.18664","0.11293"
"338.58000","28.21522","0.11393"
"338.92200","28.24368","0.11476"
"339.26400","28.27220","0.11505"
"339.60600","28.30066","0.11583"
"339.94800","28.32918","0.11420"
"340.29000","28.35770","0.11404"
"340.63200","28.38616","0.11477"
"340.97400","28.41462","0.11535"
"341.31600","28.44314","0.11613"
"341.65800","28.47166","0.11577"
"342.00000","28.50012","0.11534"
"342.34200","28.52869","0.11482"
"342.68400","28.55722","0.11614"
"343.02600","28.58562","0.11681"
"343.36800","28.61413","0.11687"
"343.71000","28.64266","0.11693"
"344.05200","28.67112","0.11636"
"344.39400","28.69969","0.11743"
"344.73600","28.72815","0.11767"
"345.07800","28.75667","0.11841"
"345.42000","28.78513","0.11885"
"345.76200","28.81365","0.11980"
"346.10400","28.84217","0.11982"
"346.44600","28.87069","0.12105"
"346.78800","28.89915","0.12091"
"347.13000","28.92773","0.12242"
"347.47200","28.95619","0.12218"
"347.81400","28.98465","0.12223"
"348.15600","29.01323","0.12286"
"348.49800","29.04163","0.12287"
"348.84000","29.07015","0.12352"
"349.18200","29.09867","0.12491"
"349.52400","29.12713","0.12683"
"349.86600","29.15571","0.12796"
"350.20800","29.18417","0.12891"
"350.55000","29.21263","0.12967"
"350.89200","29.24121","0.13078"
"351.23400","29.26967","0.13226"
"351.57600","29.29813","0.13249"
"351.91800","29.32671","0.13357"
"352.26000","29.35511","0.13493"
"352.60200","29.38369","0.13664"
"352.94400","29.41227","0.13773"
"353.28600","29.44061","0.13883"
"353.62800","29.46919","0.14040"
"353.97000","29.49765","0.14105"
"354.31200","29.52610","0.14185"
"354.65400","29.55474","0.14438"
"354.99600","29.58315","0.14553"
"355.33800","29.61166","0.14716"
"355.68000","29.64012","0.14833"
"356.02200","29.66864","0.14869"
"356.36400","29.69716","0.15016"
"356.70600","29.72568","0.15094"
"357.04800","29.75414","0.15294"
"357.39000","29.78272","0.15460"
"357.73200","29.81118","0.15709"
"358.07400","29.83958","0.15827"
"358.41600","29.86816","0.15919"
"358.75800","29.89662","0.16050"
"359.10000","29.92514","0.16074"
"359.44200","29.95366","0.16200"
"359.78400","29.98218","0.16323"
"360.12600","30.01064","0.16458"
"360.46800","30.03922","0.16573"
"360.81000","30.06762","0.16742"
"361.15200","30.09620","0.16954"
"361.49400","30.12472","0.17103"
"361.83600","30.15318","0.17208"
"362.17800","30.18170","0.17385"
"362.52000","30.21016","0.17542"
"362.86200","30.23868","0.17721"
"363.20400","30.26720","0.17911"
"363.54600","30.29565","0.17829"
"363.88800","30.32418","0.17957"
"364.23000","30.35275","0.18177"
"364.57200","30.38109","0.18276"
"364.91400","30.40968","0.18412"
"365.25600","30.43814","0.18578"
"365.59800","30.46665","0.18676"
"365.94000","30.49517","0.18782"
"366.28200","30.52363","0.18905"
"366.62400","30.55215","0.18897"
"366.96600","30.58073","0.19013"
"367.30800","30.60913","0.19125"
"367.65000","30.63771","0.19311"
"367.99200","30.66617","0.19420"
"368.33400","30.69463","0.19608"
"368.67600","30.72315","0.19795"
"369.01800","30.75167","0.20017"
"369.36000","30.78013","0.20137"
"369.70200","30.80865","0.20343"
"370.04400","30.83717","0.20551"
"370.38600","30.86569","0.20652"
"370.72800","30.89421","0.20861"
"371.07000","30.92261","0.20879"
"371.41200","30.95119","0.21081"
"371.75400","30.97971","0.21237"
"372.09600","31.00817","0.21512"
"372.43800","31.03669","0.21529"
"372.78000","31.06515","0.21768"
"373.12200","31.09367","0.21917"
"373.46400","31.12218","0.22084"
"373.80600","31.15065","0.22157"
"374.14800","31.17917","0.22301"
"374.49000","31.20769","0.22403"
"374.83200","31.23621","0.22598"
"375.17400","31.26466","0.22696"
"375.51600","31.29318","0.22851"
"375.85800","31.32164","0.22981"
"376.20000","31.35022","0.23246"
"376.54200","31.37874","0.23381"
"376.88400","31.40714","0.23639"
"377.22600","31.43566","0.23520"
"377.56800","31.46412","0.23761"
"377.91000","31.49264","0.23912"
"378.25200","31.52116","0.23880"
"378.59400","31.54962","0.24094"
"378.93600","31.57820","0.24241"
"379.27800","31.60666","0.24416"
"379.62000","31.63512","0.24524"
"379.96200","31.66370","0.24736"
"380.30400","31.69222","0.24938"
"380.64600","31.72062","0.25144"
"380.98800","31.74920","0.25364"
"381.33000","31.77766","0.25568"
"381.67200","31.80618","0.25454"
"382.01400","31.83470","0.24995"
"382.35600","31.86310","0.25320"
"382.69800","31.89168","0.25484"
"383.04000","31.92019","0.25464"
"383.38200","31.94866","0.25501"
"383.72400","31.97718","0.25729"
"384.06600","32.00563","0.11784"
"384.40800","32.03410","0.11766"
"384.75000","32.06268","0.11704"
"385.09200","32.09113","0.11745"
"385.43400","32.11966","0.12019"
"385.77600","32.14824","0.12267"
"386.11800","32.17657","0.12332"
"386.46000","32.20521","0.12407"
"386.80200","32.23367","0.12666"
"387.14400","32.26213","0.12899"
"387.48600","32.29071","0.13082"
"387.82800","32.31911","0.13253"
"388.17000","32.34769","0.13440"
"388.51200","32.37615","0.13508"
"388.85400","32.40461","0.13582"
"389.19600","32.43319","0.13832"
"389.53800","32.46171","0.13939"
"389.88000","32.49017","0.13547"
"390.22200","32.51869","0.13310"
"390.56400","32.54721","0.13532"
"390.90600","32.57567","0.13591"
"391.24800","32.60419","0.12577"
"391.59000","32.63265","0.12438"
"391.93200","32.66117","0.12620"
"392.27400","32.68963","0.12809"
"392.61600","32.71815","0.13118"
"392.95800","32.74667","0.13263"
"393.30000","32.77518","0.13000"
"393.64200","32.80365","0.13113"
"393.98400","32.83216","0.13340"
"394.32600","32.86068","0.13272"
"394.66800","32.88914","0.12741"
"395.01000","32.91766","0.12088"
"395.35200","32.94619","0.12239"
"395.69400","32.97464","0.12166"
"396.03600","33.00316","0.12312"
"396.37800","33.03168","0.12599"
"396.72000","33.06015","0.12672"
"397.06200","33.08866","0.12601"
"397.40400","33.11712","0.12803"
"397.74600","33.14565","0.12980"
"398.08800","33.17416","0.13197"
"398.43000","33.20262","0.13243"
"398.77200","33.23120","0.13380"
"399.11400","33.25966","0.13599"
"399.45600","33.28812","0.13739"
"399.79800","33.31670","0.13950"
"400.14000","33.34516","0.14260"
"400.48200","33.37368","0.14498"
"400.82400","33.40226","0.14542"
"401.16600","33.43060","0.14851"
"401.50800","33.45918","0.15175"
"401.85000","33.48764","0.15397"
"402.19200","33.51616","0.15528"
"402.53400","33.54468","0.15804"
"402.87600","33.57314","0.15924"
"403.21800","33.60166","0.16102"
"403.56000","33.63018","0.16351"
"403.90200","33.65858","0.16502"
"404.24400","33.68721","0.16653"
"404.58600","33.71568","0.16854"
"404.92800","33.74413","0.17136"
"405.27000","33.77271","0.17369"
"405.61200","33.80117","0.17578"
"405.95400","33.82963","0.17757"
"406.29600","33.85815","0.17959"
"406.63800","33.88662","0.18228"
"406.98000","33.91519","0.18445"
"407.32200","33.94365","0.18660"
"407.66400","33.97211","0.18845"
"408.00600","34.00069","0.18958"
"408.34800","34.02921","0.19094"
"408.69000","34.05767","0.19379"
"409.03200","34.08619","0.19551"
"409.37400","34.11465","0.19496"
"409.71600","34.14311","0.19967"
"410.05800","34.17169","0.20291"
"410.40000","34.20015","0.20487"
"410.74200","34.22867","0.20810"
"411.08400","34.25719","0.21097"
"411.42600","34.28565","0.21300"
"411.76800","34.31417","0.21593"
"412.11000","34.34269","0.21792"
"412.45200","34.37115","0.22091"
"412.79400","34.39967","0.22270"
"413.13600","34.42819","0.22446"
"413.47800","34.45665","0.22659"
"413.82000","34.48523","0.22846"
"414.16200","34.51363","0.22924"
"414.50400","34.54215","0.23219"
"414.84600","34.57073","0.23473"
"415.18800","34.59912","0.23660"
"415.53000","34.62770","0.23927"
"415.87200","34.65623","0.24122"
"416.21400","34.68462","0.24345"
"416.55600","34.71315","0.24621"
"416.89800","34.74166","0.24852"
"417.24000","34.77012","0.25288"
"417.58200","34.79870","0.25683"
"417.92400","34.82716","0.25931"
"418.26600","34.85562","0.26198"
"418.60800","34.88426","0.26489"
"418.95000","34.91267","0.26763"
"419.29200","34.94118","0.27124"
"419.63400","34.96970","0.27454"
"419.97600","34.99810","0.27799"
"420.31800","35.02668","0.28102"
"420.66000","35.05520","0.28360"
"421.00200","35.08366","0.28683"
"421.34400","35.11218","0.28997"
"421.68600","35.14064","0.29444"
"422.02800","35.16916","0.29874"
"422.37000","35.19768","0.30244"
"422.71200","35.22608","0.30703"
"423.05400","35.25466","0.31172"
"423.39600","35.28324","0.31568"
"423.73800","35.31164","0.31811"
"424.08000","35.34022","0.32010"
"424.42200","35.36862","0.32159"
"424.76400","35.39720","0.32229"
"425.10600","35.42566","0.32330"
"425.44800","35.45412","0.32242"
"425.79000","35.48270","0.32643"
"426.13200","35.51122","0.32960"
"426.47400","35.53968","0.33238"
"426.81600","35.56814","0.33530"
"427.15800","35.59665","0.33749"
"427.50000","35.62518","0.34066"
"427.84200","35.65369","0.34165"
"428.18400","35.68215","0.34201"
"428.52600","35.71067","0.34281"
"428.86800","35.73914","0.27329"
"429.21000","35.76765","0.27228"
"429.55200","35.79617","0.27862"
"429.89400","35.82470","0.27777"
"430.23600","35.85309","0.28059"
"430.57800","35.88167","0.28209"
"430.92000","35.91013","0.28250"
"431.26200","35.93865","0.28334"
"431.60400","35.96717","0.28270"
"431.94600","35.99569","0.28557"
"432.28800","36.02415","0.28739"
"432.63000","36.05267","0.29070"
"432.97200","36.08113","0.29423"
"433.31400","36.10965","0.29795"
"433.65600","36.13823","0.29667"
"433.99800","36.16663","0.29907"
"434.34000","36.19521","0.30398"
"434.68200","36.22367","0.30858"
"435.02400","36.25212","0.31233"
"435.36600","36.28065","0.31599"
"435.70800","36.30917","0.28078"
"436.05000","36.33762","0.29038"
"436.39200","36.36621","0.29499"
"436.73400","36.39461","0.30088"
"437.07600","36.42318","0.30787"
"437.41800","36.45176","0.30900"
"437.76000","36.48011","0.31146"
"438.10200","36.50868","0.31515"
"438.44400","36.53714","0.31722"
"438.78600","36.56561","0.31914"
"439.12800","36.59424","0.32204"
"439.47000","36.62264","0.32402"
"439.81200","36.65117","0.32525"
"440.15400","36.67968","0.32721"
"440.49600","36.70808","0.32975"
"440.83800","36.73672","0.33232"
"441.18000","36.76518","0.33492"
"441.52200","36.79358","0.33684"
"441.86400","36.82216","0.33847"
"442.20600","36.85068","0.34066"
"442.54800","36.87914","0.34349"
"442.89000","36.90766","0.34476"
"443.23200","36.93612","0.34251"
"443.57400","36.96470","0.34521"
"443.91600","36.99322","0.34873"
"444.25800","37.02162","0.35406"
"444.60000","37.05020","0.35879"
"444.94200","37.07866","0.36346"
"445.28400","37.10712","0.36709"
"445.62600","37.13570","0.37068"
"445.96800","37.16416","0.37460"
"446.31000","37.19262","0.37883"
"446.65200","37.22114","0.38317"
"446.99400","37.24966","0.38643"
"447.33600","37.27818","0.38953"
"447.67800","37.30670","0.39222"
"448.02000","37.33516","0.39478"
"448.36200","37.36367","0.39690"
"448.70400","37.39220","0.40055"
"449.04600","37.42065","0.40287"
"449.38800","37.44917","0.40587"
"449.73000","37.47763","0.41066"
"450.07200","37.50615","0.41457"
"450.41400","37.53467","0.41795"
"450.75600","37.56319","0.42001"
"451.09800","37.59165","0.42277"
"451.44000","37.62023","0.41609"
"451.78200","37.64869","0.41334"
"452.12400","37.67715","0.36587"
"452.46600","37.70573","0.36931"
"452.80800","37.73413","0.37197"
"453.15000","37.76265","0.37522"
"453.49200","37.79117","0.37549"
"453.83400","37.81969","0.37565"
"454.17600","37.84821","0.37708"
"454.51800","37.87667","0.37927"
"454.86000","37.90513","0.38360"
"455.20200","37.93371","0.38773"
"455.54400","37.96211","0.39144"
"455.88600","37.99069","0.39329"
"456.22800","38.01921","0.39502"
"456.57000","38.04761","0.39647"
"456.91200","38.07625","0.39789"
"457.25400","38.10459","0.39990"
"457.59600","38.13317","0.40319"
"457.93800","38.16169","0.40776"
"458.28000","38.19014","0.41164"
"458.62200","38.21867","0.41479"
"458.96400","38.24719","0.41711"
"459.30600","38.27559","0.41876"
"459.64800","38.30416","0.42112"
"459.99000","38.33269","0.42350"
"460.33200","38.36115","0.42447"
"460.67400","38.38972","0.42651"
"461.01600","38.41812","0.42836"
"461.35800","38.44664","0.43040"
"461.70000","38.47516","0.43406"
"462.04200","38.50362","0.43767"
"462.38400","38.53220","0.43721"
"462.72600","38.56072","0.43974"
"463.06800","38.58912","0.44012"
"463.41000","38.61770","0.26458"
"463.75200","38.64616","0.25447"
"464.09400","38.67462","0.25107"
"464.43600","38.70314","0.24800"
"464.77800","38.73166","0.24834"
"465.12000","38.76012","0.24995"
"465.46200","38.78864","0.25379"
"465.80400","38.81716","0.25459"
"466.14600","38.84568","0.25636"
"466.48800","38.87420","0.25953"
"466.83000","38.90260","0.26211"
"467.17200","38.93124","0.26360"
"467.51400","38.95964","0.26566"
"467.85600","38.98810","0.26770"
"468.19800","39.01667","0.26992"
"468.54000","39.04520","0.27228"
"468.88200","39.07366","0.27516"
"469.22400","39.10217","0.27818"
"469.56600","39.13070","0.28100"
"469.90800","39.15910","0.28323"
"470.25000","39.18767","0.28578"
"470.59200","39.21613","0.28904"
"470.93400","39.24471","0.29153"
"471.27600","39.27317","0.29413"
"471.61800","39.30163","0.29714"
"471.96000","39.33015","0.30022"
"472.30200","39.35867","0.30261"
"472.64400","39.38713","0.30565"
"472.98600","39.41571","0.30913"
"473.32800","39.44411","0.22179"
"473.67000","39.47263","0.22406"
"474.01200","39.50121","0.22348"
"474.35400","39.52961","0.22223"
"474.69600","39.55819","0.22268"
"475.03800","39.58665","0.22386"
"475.38000","39.61511","0.22554"
"475.72200","39.64368","0.22694"
"476.06400","39.67215","0.22884"
"476.40600","39.70066","0.23172"
"476.74800","39.72919","0.23378"
"477.09000","39.75764","0.23504"
"477.43200","39.78623","0.23702"
"477.77400","39.81469","0.23837"
"478.11600","39.84314","0.23906"
"478.45800","39.87167","0.11362"
"478.80000","39.90019","0.12830"
"479.14200","39.92865","0.12097"
"479.48400","39.95716","0.13314"
"479.82600","39.98563","0.12214"
"480.16800","40.01420","0.12046"
"480.51000","40.04266","0.12677"
"480.85200","40.07113","0.13147"
"481.19400","40.09970","0.12428"
"481.53600","40.12816","0.12965"
"481.87800","40.15662","0.13046"
"482.22000","40.18520","0.12775"
"482.56200","40.21366","0.13016"
"482.90400","40.24218","0.13481"
"483.24600","40.27070","0.12811"
"483.58800","40.29916","0.13273"
"483.93000","40.32768","0.13697"
"484.27200","40.35614","0.13337"
"484.61400","40.38466","0.13388"
"484.95600","40.41318","0.14091"
"485.29800","40.44170","0.13753"
"485.64000","40.47016","0.13541"
"485.98200","40.49868","0.14174"
"486.32400","40.52714","0.14282"
"486.66600","40.55566","0.13936"
"487.00800","40.58418","0.14298"
"487.35000","40.61270","0.14664"
"487.69200","40.64116","0.14474"
"488.03400","40.66968","0.14554"
"488.37600","40.69807","0.15084"
"488.71800","40.72666","0.15041"
"489.06000","40.75524","0.14841"
"489.40200","40.78364","0.15247"
"489.74400","40.81222","0.15616"
"490.08600","40.84068","0.15371"
"490.42800","40.86914","0.15448"
"490.77000","40.89771","0.15784"
"491.11200","40.92611","0.15866"
"491.45400","40.95464","0.15749"
"491.79600","40.98315","0.15919"
"492.13800","41.01161","0.16203"
"492.48000","41.04019","0.16225"
"492.82200","41.06871","0.16118"
"493.16400","41.09711","0.16173"
"493.50600","41.12575","0.16439"
"493.84800","41.15415","0.16506"
"494.19000","41.18267","0.16488"
"494.53200","41.21119","0.16675"
"494.87400","41.23965","0.16910"
"495.21600","41.26817","0.16827"
"495.55800","41.29669","0.16884"
"495.90000","41.32509","0.17015"
"496.24200","41.35367","0.03304"
"496.58400","41.38219","0.03132"
"496.92600","41.41065","0.03101"
"497.26800","41.43923","0.02956"
"497.61000","41.46775","0.03111"
"497.95200","41.49615","0.03041"
"498.29400","41.52466","0.03160"
"498.63600","41.55312","0.03020"
"498.97800","41.58165","0.03094"
"499.32000","41.61023","0.03029"
"499.66200","41.63863","0.03302"
"500.00400","41.66721","0.03053"
"500.34600","41.69561","0.03106"
"500.68800","41.72412","0.03086"
"501.03000","41.75270","0.03010"
"501.37200","41.78111","0.03114"
"501.71400","41.80968","0.03046"
"502.05600","41.83814","0.03149"
"502.39800","41.86666","0.03050"
"502.74000","41.89518","0.03074"
"503.08200","41.92364","0.03040"
"503.42400","41.95210","0.03155"
"503.76600","41.98068","0.03109"
"504.10800","42.00920","0.03049"
"504.45000","42.03766","0.03020"
"504.79200","42.06618","0.03096"
"505.13400","42.09470","0.03090"
"505.47600","42.12316","0.03046"
"505.81800","42.15168","0.03156"
"506.16000","42.18014","0.03089"
"506.50200","42.20866","0.03103"
"506.84400","42.23718","0.03056"
"507.18600","42.26564","0.03215"
"507.52800","42.29416","0.03097"
"507.87000","42.32268","0.03088"
"508.21200","42.35114","0.03086"
"508.55400","42.37965","0.03083"
"508.66800","42.38911","0.03040"