File: Force_trajectories/161218_2/Specimen_RawData_5.csv
End date,"12/18/2016"
Specimen label,"16DG_31_run2"
Maximum Load,"0.05678",N

Time,Extension,Load
(s),(mm),(N)
"0.00000","39.39938","0.01421"
"0.19200","39.41146","0.01443"
"0.38400","39.43144","0.01467"
"0.57600","39.44758","0.01563"
"0.76800","39.46354","0.01528"
"0.96000","39.47957","0.01620"
"1.15200","39.49553","0.01671"
"1.34400","39.51155","0.01685"
"1.53600","39.52751","0.01753"
"1.72800","39.54360","0.01670"
"1.92000","39.55951","0.01778"
"2.11200","39.57547","0.01805"
"2.30400","39.59161","0.01887"
"2.49600","39.60746","0.01922"
"2.68800","39.62348","0.01945"
"2.88000","39.63950","0.01961"
"3.07200","39.65547","0.01937"
"3.26400","39.67149","0.01903"
"3.45600","39.68752","0.01958"
"3.64800","39.70348","0.01972"
"3.84000","39.71950","0.02027"
"4.03200","39.73553","0.02053"
"4.22400","39.75149","0.02040"
"4.41600","39.76757","0.02137"
"4.60800","39.78348","0.02128"
"4.80000","39.79950","0.02151"
"4.99200","39.81553","0.02211"
"5.18400","39.83155","0.02206"
"5.37600","39.84745","0.02209"
"5.56800","39.86353","0.02229"
"5.76000","39.87950","0.02141"
"5.95200","39.89546","0.02167"
"6.14400","39.91154","0.02133"
"6.33600","39.92751","0.02153"
"6.52800","39.94347","0.02040"
"6.72000","39.95955","0.02070"
"6.91200","39.97546","0.02110"
"7.10400","39.99142","0.02116"
"7.29600","40.00757","0.02095"
"7.48800","40.02341","0.02124"
"7.68000","40.03949","0.02078"
"7.87200","40.05558","0.02069"
"8.06400","40.07148","0.01887"
"8.25600","40.08751","0.01919"
"8.44800","40.10353","0.01953"
"8.64000","40.11950","0.01983"
"8.83200","40.13552","0.01878"
"9.02400","40.15154","0.02032"
"9.21600","40.16750","0.01977"
"9.40800","40.18347","0.01853"
"9.60000","40.19949","0.01831"
"9.79200","40.21552","0.01912"
"9.98400","40.23148","0.01891"
"10.17600","40.24750","0.01873"
"10.36800","40.26353","0.01893"
"10.56000","40.27949","0.01948"
"10.75200","40.29552","0.01975"
"10.94400","40.31154","0.01981"
"11.13600","40.32750","0.01962"
"11.32800","40.34352","0.02017"
"11.52000","40.35949","0.01983"
"11.71200","40.37545","0.02011"
"11.90400","40.39148","0.02073"
"12.09600","40.40750","0.01854"
"12.28800","40.42347","0.01927"
"12.48000","40.43948","0.01923"
"12.67200","40.45551","0.01848"
"12.86400","40.47147","0.01637"
"13.05600","40.48756","0.01703"
"13.24800","40.50346","0.01673"
"13.44000","40.51943","0.01646"
"13.63200","40.53557","0.01662"
"13.82400","40.55154","0.01752"
"14.01600","40.56744","0.01726"
"14.20800","40.58352","0.01581"
"14.40000","40.59948","0.01600"
"14.59200","40.61551","0.01573"
"14.78400","40.63153","0.01591"
"14.97600","40.64750","0.01595"
"15.16800","40.66346","0.01431"
"15.36000","40.67954","0.01473"
"15.55200","40.69545","0.01541"
"15.74400","40.71147","0.01585"
"15.93600","40.72750","0.01551"
"16.12800","40.74346","0.01572"
"16.32000","40.75948","0.01615"
"16.51200","40.77551","0.01628"
"16.70400","40.79147","0.01576"
"16.89600","40.80755","0.01615"
"17.08800","40.82352","0.01609"
"17.28000","40.83948","0.01670"
"17.47200","40.85550","0.01672"
"17.66400","40.87147","0.01687"
"17.85600","40.88749","0.01689"
"18.04800","40.90351","0.01731"
"18.24000","40.91948","0.01639"
"18.43200","40.93550","0.01698"
"18.62400","40.95152","0.01796"
"18.81600","40.96749","0.01803"
"19.00800","40.98351","0.01758"
"19.20000","40.99953","0.01811"
"19.39200","41.01550","0.01808"
"19.58400","41.03146","0.01872"
"19.77600","41.04749","0.01875"
"19.96800","41.06351","0.01852"
"20.16000","41.07954","0.01860"
"20.35200","41.09550","0.01912"
"20.54400","41.11146","0.01929"
"20.73600","41.12749","0.01952"
"20.92800","41.14345","0.02000"
"21.12000","41.15953","0.01964"
"21.31200","41.17549","0.01974"
"21.50400","41.19146","0.01994"
"21.69600","41.20755","0.02031"
"21.88800","41.22351","0.02054"
"22.08000","41.23953","0.02057"
"22.27200","41.25550","0.02097"
"22.46400","41.27145","0.02125"
"22.65600","41.28748","0.02126"
"22.84800","41.30351","0.02141"
"23.04000","41.31947","0.02163"
"23.23200","41.33555","0.02145"
"23.42400","41.35152","0.02142"
"23.61600","41.36748","0.02220"
"23.80800","41.38351","0.02233"
"24.00000","41.39953","0.02236"
"24.19200","41.41544","0.02236"
"24.38400","41.43151","0.02262"
"24.57600","41.44748","0.02269"
"24.76800","41.46345","0.02296"
"24.96000","41.47953","0.02298"
"25.15200","41.49549","0.02324"
"25.34400","41.51146","0.02326"
"25.53600","41.52754","0.02336"
"25.72800","41.54350","0.02325"
"25.92000","41.55946","0.02418"
"26.11200","41.57555","0.02359"
"26.30400","41.59145","0.02354"
"26.49600","41.60747","0.02423"
"26.68800","41.62350","0.02468"
"26.88000","41.63940","0.02408"
"27.07200","41.65549","0.02455"
"27.26400","41.67151","0.02415"
"27.45600","41.68747","0.02490"
"27.64800","41.70356","0.02467"
"27.84000","41.71952","0.02483"
"28.03200","41.73549","0.02529"
"28.22400","41.75151","0.02470"
"28.41600","41.76753","0.02532"
"28.60800","41.78349","0.02481"
"28.80000","41.79951","0.02556"
"28.99200","41.81542","0.02521"
"29.18400","41.83151","0.02532"
"29.37600","41.84753","0.02606"
"29.56800","41.86349","0.02569"
"29.76000","41.87952","0.02598"
"29.95200","41.89554","0.02562"
"30.14400","41.91151","0.02570"
"30.33600","41.92747","0.02583"
"30.52800","41.94349","0.02595"
"30.72000","41.95951","0.02646"
"30.91200","41.97548","0.02601"
"31.10400","41.99144","0.02622"
"31.29600","42.00753","0.02629"
"31.48800","42.02355","0.02658"
"31.68000","42.03946","0.02686"
"31.87200","42.05554","0.02657"
"32.06400","42.07150","0.02656"
"32.25600","42.08747","0.02654"
"32.44800","42.10355","0.02699"
"32.64000","42.11945","0.02696"
"32.83200","42.13548","0.02656"
"33.02400","42.15150","0.02677"
"33.21600","42.16746","0.02605"
"33.40800","42.18349","0.02651"
"33.60000","42.19952","0.02636"
"33.79200","42.21548","0.02651"
"33.98400","42.23149","0.02695"
"34.17600","42.24752","0.02717"
"34.36800","42.26349","0.02714"
"34.56000","42.27951","0.02736"
"34.75200","42.29554","0.02731"
"34.94400","42.31144","0.02717"
"35.13600","42.32758","0.02735"
"35.32800","42.34348","0.02734"
"35.52000","42.35945","0.02797"
"35.71200","42.37553","0.02737"
"35.90400","42.39150","0.02820"
"36.09600","42.40746","0.02804"
"36.28800","42.42355","0.02791"
"36.48000","42.43945","0.02731"
"36.67200","42.45547","0.02798"
"36.86400","42.47149","0.02766"
"37.05600","42.48746","0.02823"
"37.24800","42.50348","0.02812"
"37.44000","42.51950","0.02787"
"37.63200","42.53547","0.02815"
"37.82400","42.55149","0.02859"
"38.01600","42.56752","0.02829"
"38.20800","42.58348","0.02826"
"38.40000","42.59944","0.02822"
"38.59200","42.61553","0.02851"
"38.78400","42.63149","0.02875"
"38.97600","42.64751","0.02901"
"39.16800","42.66348","0.02887"
"39.36000","42.67950","0.02898"
"39.55200","42.69552","0.02877"
"39.74400","42.71149","0.02874"
"39.93600","42.72752","0.02832"
"40.12800","42.74354","0.02868"
"40.32000","42.75944","0.02898"
"40.51200","42.77559","0.02891"
"40.70400","42.79148","0.02864"
"40.89600","42.80745","0.02911"
"41.08800","42.82354","0.02904"
"41.28000","42.83950","0.02933"
"41.47200","42.85546","0.02912"
"41.66400","42.87148","0.02882"
"41.85600","42.88745","0.02864"
"42.04800","42.90353","0.02827"
"42.24000","42.91956","0.02839"
"42.43200","42.93546","0.02873"
"42.62400","42.95155","0.02886"
"42.81600","42.96757","0.02889"
"43.00800","42.98347","0.02945"
"43.20000","42.99950","0.02909"
"43.39200","43.01552","0.02907"
"43.58400","43.03143","0.02921"
"43.77600","43.04757","0.02962"
"43.96800","43.06347","0.03030"
"44.16000","43.07944","0.03018"
"44.35200","43.09552","0.03004"
"44.54400","43.11154","0.02973"
"44.73600","43.12750","0.03028"
"44.92800","43.14352","0.02985"
"45.12000","43.15949","0.03047"
"45.31200","43.17552","0.02997"
"45.50400","43.19154","0.03020"
"45.69600","43.20744","0.03028"
"45.88800","43.22353","0.03056"
"46.08000","43.23949","0.03063"
"46.27200","43.25546","0.03027"
"46.46400","43.27154","0.03048"
"46.65600","43.28751","0.03017"
"46.84800","43.30347","0.02993"
"47.04000","43.31948","0.03005"
"47.23200","43.33552","0.03046"
"47.42400","43.35148","0.03016"
"47.61600","43.36756","0.03093"
"47.80800","43.38346","0.03087"
"48.00000","43.39949","0.03052"
"48.19200","43.41551","0.03080"
"48.38400","43.43148","0.03106"
"48.57600","43.44756","0.03072"
"48.76800","43.46352","0.03107"
"48.96000","43.47943","0.03097"
"49.15200","43.49551","0.03109"
"49.34400","43.51154","0.03102"
"49.53600","43.52750","0.03161"
"49.72800","43.54346","0.03183"
"49.92000","43.55948","0.03110"
"50.11200","43.57545","0.03147"
"50.30400","43.59153","0.03150"
"50.49600","43.60749","0.03157"
"50.68800","43.62352","0.03137"
"50.88000","43.63955","0.03141"
"51.07200","43.65551","0.03175"
"51.26400","43.67147","0.03160"
"51.45600","43.68749","0.03108"
"51.64800","43.70352","0.03166"
"51.84000","43.71948","0.03116"
"52.03200","43.73551","0.03139"
"52.22400","43.75147","0.03184"
"52.41600","43.76749","0.03158"
"52.60800","43.78352","0.03149"
"52.80000","43.79954","0.03169"
"52.99200","43.81551","0.03179"
"53.18400","43.83153","0.03155"
"53.37600","43.84755","0.03193"
"53.56800","43.86357","0.03154"
"53.76000","43.87948","0.03171"
"53.95200","43.89556","0.03171"
"54.14400","43.91147","0.03183"
"54.33600","43.92743","0.03195"
"54.52800","43.94351","0.03175"
"54.72000","43.95948","0.03224"
"54.91200","43.97544","0.03174"
"55.10400","43.99152","0.03183"
"55.29600","44.00749","0.03240"
"55.48800","44.02351","0.02300"
"55.68000","44.03953","0.01980"
"55.87200","44.05550","0.02017"
"56.06400","44.07153","0.02032"
"56.25600","44.08749","0.01955"
"56.44800","44.10345","0.01944"
"56.64000","44.11953","0.02100"
"56.83200","44.13556","0.02061"
"57.02400","44.15140","0.02009"
"57.21600","44.16755","0.02146"
"57.40800","44.18351","0.02220"
"57.60000","44.19947","0.02250"
"57.79200","44.21555","0.02129"
"57.98400","44.23146","0.02135"
"58.17600","44.24743","0.02201"
"58.36800","44.26357","0.02300"
"58.56000","44.27941","0.02164"
"58.75200","44.29543","0.02249"
"58.94400","44.31152","0.02228"
"59.13600","44.32748","0.02286"
"59.32800","44.34351","0.02275"
"59.52000","44.35953","0.02202"
"59.71200","44.37543","0.02328"
"59.90400","44.39151","0.02383"
"60.09600","44.40754","0.02341"
"60.28800","44.42350","0.02392"
"60.48000","44.43947","0.02369"
"60.67200","44.45549","0.02372"
"60.86400","44.47146","0.02395"
"61.05600","44.48748","0.02411"
"61.24800","44.50350","0.02447"
"61.44000","44.51946","0.02493"
"61.63200","44.53549","0.02485"
"61.82400","44.55151","0.02432"
"62.01600","44.56753","0.02455"
"62.20800","44.58350","0.02444"
"62.40000","44.59946","0.02539"
"62.59200","44.61555","0.02517"
"62.78400","44.63145","0.02497"
"62.97600","44.64753","0.02567"
"63.16800","44.66350","0.02528"
"63.36000","44.67946","0.02478"
"63.55200","44.69555","0.02527"
"63.74400","44.71151","0.02558"
"63.93600","44.72747","0.02572"
"64.12800","44.74350","0.02583"
"64.32000","44.75952","0.02559"
"64.51200","44.77542","0.02526"
"64.70400","44.79157","0.02580"
"64.89600","44.80747","0.02482"
"65.08800","44.82344","0.02535"
"65.28000","44.83952","0.02563"
"65.47200","44.85548","0.02580"
"65.66400","44.87145","0.02540"
"65.85600","44.88753","0.02505"
"66.04800","44.90350","0.02576"
"66.24000","44.91946","0.02564"
"66.43200","44.93554","0.02593"
"66.62400","44.95151","0.02599"
"66.81600","44.96746","0.02639"
"67.00800","44.98355","0.02630"
"67.20000","44.99946","0.02605"
"67.39200","45.01548","0.02613"
"67.58400","45.03157","0.02609"
"67.77600","45.04747","0.02651"
"67.96800","45.06355","0.02658"
"68.16000","45.07951","0.02695"
"68.35200","45.09548","0.02623"
"68.54400","45.11150","0.02650"
"68.73600","45.12753","0.02641"
"68.92800","45.14349","0.02687"
"69.12000","45.15952","0.02708"
"69.31200","45.17548","0.02690"
"69.50400","45.19150","0.02716"
"69.69600","45.20752","0.02702"
"69.88800","45.22349","0.02646"
"70.08000","45.23945","0.02716"
"70.27200","45.25554","0.02700"
"70.46400","45.27150","0.02694"
"70.65600","45.28752","0.02715"
"70.84800","45.30348","0.02751"
"71.04000","45.31951","0.02688"
"71.23200","45.33553","0.02716"
"71.42400","45.35150","0.02761"
"71.61600","45.36746","0.02772"
"71.80800","45.38348","0.02782"
"72.00000","45.39951","0.02767"
"72.19200","45.41547","0.02761"
"72.38400","45.43150","0.02776"
"72.57600","45.44746","0.02747"
"72.76800","45.46354","0.02730"
"72.96000","45.47950","0.02735"
"73.15200","45.49541","0.02711"
"73.34400","45.51155","0.02740"
"73.53600","45.52752","0.02760"
"73.72800","45.54348","0.02766"
"73.92000","45.55950","0.02744"
"74.11200","45.57547","0.02609"
"74.30400","45.59149","0.02614"
"74.49600","45.60752","0.02647"
"74.68800","45.62348","0.02632"
"74.88000","45.63950","0.02625"
"75.07200","45.65552","0.02627"
"75.26400","45.67143","0.02660"
"75.45600","45.68752","0.02621"
"75.64800","45.70348","0.02673"
"75.84000","45.71944","0.02696"
"76.03200","45.73552","0.02670"
"76.22400","45.75149","0.02667"
"76.41600","45.76739","0.02667"
"76.60800","45.78354","0.02468"
"76.80000","45.79950","0.02503"
"76.99200","45.81546","0.02540"
"77.18400","45.83149","0.02559"
"77.37600","45.84751","0.02576"
"77.56800","45.86347","0.02552"
"77.76000","45.87956","0.02587"
"77.95200","45.89547","0.02565"
"78.14400","45.91149","0.02520"
"78.33600","45.92751","0.02583"
"78.52800","45.94348","0.02591"
"78.72000","45.95950","0.02579"
"78.91200","45.97552","0.02593"
"79.10400","45.99149","0.02616"
"79.29600","46.00751","0.02603"
"79.48800","46.02353","0.02590"
"79.68000","46.03943","0.02595"
"79.87200","46.05546","0.02591"
"80.06400","46.07148","0.02624"
"80.25600","46.08745","0.02640"
"80.44800","46.10353","0.02629"
"80.64000","46.11943","0.02649"
"80.83200","46.13552","0.02556"
"81.02400","46.15154","0.02379"
"81.21600","46.16745","0.02404"
"81.40800","46.18353","0.02458"
"81.60000","46.19949","0.02457"
"81.79200","46.21551","0.02450"
"81.98400","46.23154","0.02473"
"82.17600","46.24744","0.02431"
"82.36800","46.26353","0.02452"
"82.56000","46.27949","0.02486"
"82.75200","46.29545","0.02509"
"82.94400","46.31154","0.02477"
"83.13600","46.32756","0.02548"
"83.32800","46.34347","0.02505"
"83.52000","46.35955","0.02535"
"83.71200","46.37551","0.02485"
"83.90400","46.39147","0.02310"
"84.09600","46.40756","0.02384"
"84.28800","46.42352","0.02324"
"84.48000","46.43943","0.02341"
"84.67200","46.45546","0.02373"
"84.86400","46.47147","0.02360"
"85.05600","46.48750","0.02404"
"85.24800","46.50352","0.02397"
"85.44000","46.51949","0.02463"
"85.63200","46.53551","0.02459"
"85.82400","46.55153","0.02372"
"86.01600","46.56750","0.02441"
"86.20800","46.58352","0.02401"
"86.40000","46.59954","0.02391"
"86.59200","46.61538","0.02419"
"86.78400","46.63159","0.02436"
"86.97600","46.64756","0.02407"
"87.16800","46.66346","0.02459"
"87.36000","46.67955","0.02470"
"87.55200","46.69551","0.02434"
"87.74400","46.71141","0.02435"
"87.93600","46.72749","0.02464"
"88.12800","46.74352","0.02461"
"88.32000","46.75954","0.02447"
"88.51200","46.77551","0.02440"
"88.70400","46.79153","0.02417"
"88.89600","46.80750","0.02419"
"89.08800","46.82351","0.02423"
"89.28000","46.83948","0.02435"
"89.47200","46.85551","0.02383"
"89.66400","46.87153","0.02416"
"89.85600","46.88749","0.02462"
"90.04800","46.90351","0.02474"
"90.24000","46.91954","0.02476"
"90.43200","46.93550","0.02501"
"90.62400","46.95147","0.02437"
"90.81600","46.96749","0.02502"
"91.00800","46.98346","0.02430"
"91.20000","46.99953","0.02472"
"91.39200","47.01550","0.02472"
"91.58400","47.03152","0.02548"
"91.77600","47.04755","0.02455"
"91.96800","47.06345","0.02001"
"92.16000","47.07953","0.02113"
"92.35200","47.09550","0.02220"
"92.54400","47.11146","0.02178"
"92.73600","47.12754","0.02212"
"92.92800","47.14345","0.02300"
"93.12000","47.15947","0.02271"
"93.31200","47.17549","0.02301"
"93.50400","47.19146","0.02317"
"93.69600","47.20748","0.02379"
"93.88800","47.22351","0.02387"
"94.08000","47.23947","0.02402"
"94.27200","47.25549","0.02388"
"94.46400","47.27151","0.02383"
"94.65600","47.28748","0.02406"
"94.84800","47.30351","0.02405"
"95.04000","47.31947","0.02451"
"95.23200","47.33543","0.02440"
"95.42400","47.35151","0.02457"
"95.61600","47.36748","0.02483"
"95.80800","47.38350","0.02395"
"96.00000","47.39953","0.02448"
"96.19200","47.41555","0.02490"
"96.38400","47.43151","0.02524"
"96.57600","47.44754","0.02503"
"96.76800","47.46350","0.02464"
"96.96000","47.47947","0.02523"
"97.15200","47.49549","0.02558"
"97.34400","47.51146","0.02538"
"97.53600","47.52753","0.02565"
"97.72800","47.54350","0.02580"
"97.92000","47.55952","0.02574"
"98.11200","47.57549","0.02566"
"98.30400","47.59151","0.02572"
"98.49600","47.60748","0.02617"
"98.68800","47.62350","0.02592"
"98.88000","47.63952","0.02616"
"99.07200","47.65549","0.02622"
"99.26400","47.67151","0.02621"
"99.45600","47.68747","0.02631"
"99.64800","47.70350","0.02473"
"99.84000","47.71952","0.02497"
"100.03200","47.73548","0.02507"
"100.22400","47.75157","0.02455"
"100.41600","47.76754","0.02508"
"100.60800","47.78344","0.02546"
"100.80000","47.79951","0.02496"
"100.99200","47.81548","0.02539"
"101.18400","47.83145","0.02533"
"101.37600","47.84753","0.02589"
"101.56800","47.86349","0.02593"
"101.76000","47.87946","0.02541"
"101.95200","47.89554","0.02548"
"102.14400","47.91144","0.02541"
"102.33600","47.92746","0.02617"
"102.52800","47.94350","0.02606"
"102.72000","47.95952","0.02562"
"102.91200","47.97548","0.02628"
"103.10400","47.99150","0.02579"
"103.29600","48.00747","0.02585"
"103.48800","48.02349","0.02624"
"103.68000","48.03952","0.02664"
"103.87200","48.05548","0.02623"
"104.06400","48.07150","0.02668"
"104.25600","48.08746","0.02649"
"104.44800","48.10349","0.02616"
"104.64000","48.11951","0.02623"
"104.83200","48.13548","0.02704"
"105.02400","48.15150","0.02659"
"105.21600","48.16759","0.02716"
"105.40800","48.18349","0.02636"
"105.60000","48.19951","0.02605"
"105.79200","48.21548","0.02657"
"105.98400","48.23138","0.02608"
"106.17600","48.24758","0.02647"
"106.36800","48.26348","0.02631"
"106.56000","48.27945","0.02678"
"106.75200","48.29554","0.02669"
"106.94400","48.31150","0.02624"
"107.13600","48.32747","0.02667"
"107.32800","48.34354","0.02649"
"107.52000","48.35945","0.02666"
"107.71200","48.37553","0.02683"
"107.90400","48.39150","0.02687"
"108.09600","48.40746","0.02666"
"108.28800","48.42348","0.02701"
"108.48000","48.43957","0.02708"
"108.67200","48.45541","0.02709"
"108.86400","48.47155","0.02733"
"109.05600","48.48752","0.02742"
"109.24800","48.50348","0.02725"
"109.44000","48.51956","0.02772"
"109.63200","48.53547","0.02760"
"109.82400","48.55143","0.02766"
"110.01600","48.56752","0.02790"
"110.20800","48.58348","0.02760"
"110.40000","48.59950","0.02753"
"110.59200","48.61553","0.02753"
"110.78400","48.63143","0.02264"
"110.97600","48.64751","0.02342"
"111.16800","48.66354","0.02400"
"111.36000","48.67950","0.02429"
"111.55200","48.69552","0.02467"
"111.74400","48.71149","0.02478"
"111.93600","48.72745","0.02516"
"112.12800","48.74348","0.02543"
"112.32000","48.75950","0.02509"
"112.51200","48.77546","0.02516"
"112.70400","48.79149","0.02574"
"112.89600","48.80751","0.02599"
"113.08800","48.82347","0.02579"
"113.28000","48.83956","0.02602"
"113.47200","48.85546","0.02596"
"113.66400","48.87154","0.02612"
"113.85600","48.88750","0.02664"
"114.04800","48.90347","0.02629"
"114.24000","48.91956","0.02624"
"114.43200","48.93546","0.02566"
"114.62400","48.95149","0.02627"
"114.81600","48.96751","0.02610"
"115.00800","48.98341","0.02621"
"115.20000","48.99949","0.02635"
"115.39200","49.01552","0.02662"
"115.58400","49.03142","0.02683"
"115.77600","49.04751","0.02599"
"115.96800","49.06347","0.02666"
"116.16000","49.07949","0.02692"
"116.35200","49.09552","0.02702"
"116.54400","49.11148","0.02678"
"116.73600","49.12745","0.02708"
"116.92800","49.14353","0.02660"
"117.12000","49.15949","0.02720"
"117.31200","49.17545","0.02724"
"117.50400","49.19154","0.02733"
"117.69600","49.20750","0.02712"
"117.88800","49.22347","0.02745"
"118.08000","49.23955","0.02765"
"118.27200","49.25545","0.02761"
"118.46400","49.27142","0.02748"
"118.65600","49.28750","0.02791"
"118.84800","49.30341","0.02733"
"119.04000","49.31949","0.02739"
"119.23200","49.33557","0.02771"
"119.42400","49.35147","0.02775"
"119.61600","49.36750","0.02768"
"119.80800","49.38353","0.02773"
"120.00000","49.39943","0.02753"
"120.19200","49.41545","0.02799"
"120.38400","49.43153","0.02722"
"120.57600","49.44749","0.02744"
"120.76800","49.46347","0.02788"
"120.96000","49.47949","0.02718"
"121.15200","49.49551","0.02736"
"121.34400","49.51153","0.02782"
"121.53600","49.52750","0.02759"
"121.72800","49.54352","0.02813"
"121.92000","49.55948","0.02753"
"122.11200","49.57545","0.02716"
"122.30400","49.59153","0.02738"
"122.49600","49.60749","0.02724"
"122.68800","49.62352","0.02729"
"122.88000","49.63955","0.02757"
"123.07200","49.65545","0.02788"
"123.26400","49.67147","0.02819"
"123.45600","49.68749","0.02821"
"123.64800","49.70346","0.02800"
"123.84000","49.71954","0.02784"
"124.03200","49.73550","0.02807"
"124.22400","49.75147","0.02778"
"124.41600","49.76749","0.02792"
"124.60800","49.78351","0.02834"
"124.80000","49.79942","0.02808"
"124.99200","49.81557","0.02808"
"125.18400","49.83153","0.02821"
"125.37600","49.84749","0.02871"
"125.56800","49.86351","0.02828"
"125.76000","49.87947","0.02871"
"125.95200","49.89550","0.02856"
"126.14400","49.91153","0.02874"
"126.33600","49.92749","0.02822"
"126.52800","49.94352","0.02855"
"126.72000","49.95953","0.02820"
"126.91200","49.97544","0.02833"
"127.10400","49.99146","0.02864"
"127.29600","50.00755","0.02855"
"127.48800","50.02339","0.02871"
"127.68000","50.03953","0.02871"
"127.87200","50.05556","0.02888"
"128.06400","50.07146","0.02919"
"128.25600","50.08755","0.02900"
"128.44800","50.10351","0.02896"
"128.64000","50.11948","0.02902"
"128.83200","50.13550","0.02919"
"129.02400","50.15146","0.02861"
"129.21600","50.16748","0.02874"
"129.40800","50.18357","0.02891"
"129.60000","50.19947","0.02813"
"129.79200","50.21555","0.02840"
"129.98400","50.23152","0.02932"
"130.17600","50.24748","0.02910"
"130.36800","50.26351","0.02925"
"130.56000","50.27953","0.02896"
"130.75200","50.29543","0.02870"
"130.94400","50.31152","0.02882"
"131.13600","50.32754","0.02910"
"131.32800","50.34350","0.02942"
"131.52000","50.35947","0.02940"
"131.71200","50.37550","0.02927"
"131.90400","50.39146","0.02878"
"132.09600","50.40754","0.02948"
"132.28800","50.42344","0.02895"
"132.48000","50.43946","0.02917"
"132.67200","50.45555","0.02968"
"132.86400","50.47145","0.02822"
"133.05600","50.48754","0.02864"
"133.24800","50.50350","0.02794"
"133.44000","50.51946","0.02828"
"133.63200","50.53555","0.02842"
"133.82400","50.55145","0.02844"
"134.01600","50.56748","0.02902"
"134.20800","50.58350","0.02885"
"134.40000","50.59946","0.02914"
"134.59200","50.61549","0.02909"
"134.78400","50.63157","0.02888"
"134.97600","50.64748","0.02877"
"135.16800","50.66356","0.02936"
"135.36000","50.67952","0.02961"
"135.55200","50.69543","0.02958"
"135.74400","50.71151","0.02994"
"135.93600","50.72754","0.02995"
"136.12800","50.74344","0.02953"
"136.32000","50.75952","0.02993"
"136.51200","50.77548","0.02981"
"136.70400","50.79145","0.02992"
"136.89600","50.80753","0.02919"
"137.08800","50.82350","0.02966"
"137.28000","50.83952","0.02940"
"137.47200","50.85554","0.02964"
"137.66400","50.87150","0.02936"
"137.85600","50.88753","0.02976"
"138.04800","50.90356","0.02930"
"138.24000","50.91946","0.02942"
"138.43200","50.93554","0.02978"
"138.62400","50.95156","0.02941"
"138.81600","50.96741","0.02964"
"139.00800","50.98355","0.02971"
"139.20000","50.99952","0.02968"
"139.39200","51.01548","0.02979"
"139.58400","51.03151","0.02997"
"139.77600","51.04747","0.02950"
"139.96800","51.06349","0.02956"
"140.16000","51.07951","0.02965"
"140.35200","51.09548","0.02945"
"140.54400","51.11145","0.02930"
"140.73600","51.12752","0.02935"
"140.92800","51.14349","0.02922"
"141.12000","51.15951","0.02883"
"141.31200","51.17554","0.02891"
"141.50400","51.19144","0.02898"
"141.69600","51.20752","0.02914"
"141.88800","51.22355","0.02963"
"142.08000","51.23951","0.02962"
"142.27200","51.25547","0.02966"
"142.46400","51.27150","0.02948"
"142.65600","51.28753","0.02953"
"142.84800","51.30354","0.02978"
"143.04000","51.31951","0.02890"
"143.23200","51.33554","0.02888"
"143.42400","51.35149","0.02925"
"143.61600","51.36746","0.02918"
"143.80800","51.38354","0.02872"
"144.00000","51.39945","0.02862"
"144.19200","51.41547","0.02920"
"144.38400","51.43149","0.02912"
"144.57600","51.44746","0.02929"
"144.76800","51.46349","0.02796"
"144.96000","51.47951","0.02827"
"145.15200","51.49553","0.02826"
"145.34400","51.51143","0.02866"
"145.53600","51.52752","0.02853"
"145.72800","51.54348","0.02841"
"145.92000","51.55951","0.02857"
"146.11200","51.57553","0.02845"
"146.30400","51.59143","0.02841"
"146.49600","51.60751","0.02844"
"146.68800","51.62354","0.02822"
"146.88000","51.63945","0.02860"
"147.07200","51.65558","0.02876"
"147.26400","51.67149","0.02913"
"147.45600","51.68740","0.02832"
"147.64800","51.70353","0.02913"
"147.84000","51.71950","0.02896"
"148.03200","51.73547","0.02900"
"148.22400","51.75154","0.02901"
"148.41600","51.76745","0.02977"
"148.60800","51.78354","0.02928"
"148.80000","51.79950","0.02936"
"148.99200","51.81546","0.02951"
"149.18400","51.83149","0.02894"
"149.37600","51.84751","0.02963"
"149.56800","51.86347","0.03017"
"149.76000","51.87949","0.02871"
"149.95200","51.89552","0.02868"
"150.14400","51.91143","0.02842"
"150.33600","51.92751","0.02885"
"150.52800","51.94347","0.02889"
"150.72000","51.95950","0.02865"
"150.91200","51.97552","0.02834"
"151.10400","51.99149","0.02901"
"151.29600","52.00751","0.02837"
"151.48800","52.02353","0.02848"
"151.68000","52.03949","0.02849"
"151.87200","52.05552","0.02865"
"152.06400","52.07154","0.02833"
"152.25600","52.08745","0.02883"
"152.44800","52.10353","0.02870"
"152.64000","52.11949","0.02901"
"152.83200","52.13546","0.02917"
"153.02400","52.15154","0.02923"
"153.21600","52.16750","0.02922"
"153.40800","52.18347","0.02945"
"153.60000","52.19949","0.02934"
"153.79200","52.21551","0.02925"
"153.98400","52.23154","0.02961"
"154.17600","52.24750","0.02880"
"154.36800","52.26353","0.02875"
"154.56000","52.27949","0.02903"
"154.75200","52.29551","0.02926"
"154.94400","52.31148","0.02921"
"155.13600","52.32756","0.02929"
"155.32800","52.34346","0.02929"
"155.52000","52.35949","0.02946"
"155.71200","52.37551","0.02910"
"155.90400","52.39148","0.02798"
"156.09600","52.40750","0.02797"
"156.28800","52.42352","0.02775"
"156.48000","52.43949","0.02827"
"156.67200","52.45545","0.02864"
"156.86400","52.47148","0.02876"
"157.05600","52.48750","0.02894"
"157.24800","52.50352","0.02885"
"157.44000","52.51948","0.02898"
"157.63200","52.53545","0.02944"
"157.82400","52.55159","0.02921"
"158.01600","52.56750","0.02937"
"158.20800","52.58346","0.02907"
"158.40000","52.59954","0.02901"
"158.59200","52.61551","0.02900"
"158.78400","52.63147","0.02925"
"158.97600","52.64750","0.02930"
"159.16800","52.66346","0.02963"
"159.36000","52.67948","0.02909"
"159.55200","52.69557","0.02988"
"159.74400","52.71141","0.02997"
"159.93600","52.72749","0.02935"
"160.12800","52.74357","0.02944"
"160.32000","52.75942","0.02945"
"160.51200","52.77556","0.02959"
"160.70400","52.79153","0.03032"
"160.89600","52.80743","0.03050"
"161.08800","52.82352","0.02998"
"161.28000","52.83953","0.03056"
"161.47200","52.85544","0.03051"
"161.66400","52.87152","0.03050"
"161.85600","52.88749","0.03106"
"162.04800","52.90351","0.03153"
"162.24000","52.91954","0.03128"
"162.43200","52.93550","0.03159"
"162.62400","52.95158","0.03025"
"162.81600","52.96748","0.03064"
"163.00800","52.98352","0.03073"
"163.20000","52.99948","0.03158"
"163.39200","53.01550","0.03136"
"163.58400","53.03152","0.03121"
"163.77600","53.04749","0.03129"
"163.96800","53.06351","0.03142"
"164.16000","53.07953","0.03127"
"164.35200","53.09550","0.02910"
"164.54400","53.11147","0.02894"
"164.73600","53.12748","0.02902"
"164.92800","53.14351","0.02928"
"165.12000","53.15948","0.02941"
"165.31200","53.17550","0.02938"
"165.50400","53.19152","0.03015"
"165.69600","53.20743","0.02977"
"165.88800","53.22351","0.03027"
"166.08000","53.23947","0.03017"
"166.27200","53.25543","0.03042"
"166.46400","53.27152","0.03055"
"166.65600","53.28743","0.03069"
"166.84800","53.30345","0.03046"
"167.04000","53.31953","0.03049"
"167.23200","53.33543","0.03077"
"167.42400","53.35152","0.03067"
"167.61600","53.36754","0.03109"
"167.80800","53.38345","0.03136"
"168.00000","53.39952","0.03124"
"168.19200","53.41549","0.03152"
"168.38400","53.43146","0.03118"
"168.57600","53.44754","0.03198"
"168.76800","53.46356","0.03153"
"168.96000","53.47947","0.03153"
"169.15200","53.49555","0.03174"
"169.34400","53.51152","0.03186"
"169.53600","53.52747","0.03175"
"169.72800","53.54350","0.03139"
"169.92000","53.55947","0.03157"
"170.11200","53.57555","0.03162"
"170.30400","53.59157","0.03174"
"170.49600","53.60748","0.03133"
"170.68800","53.62350","0.03157"
"170.88000","53.63958","0.03223"
"171.07200","53.65549","0.03242"
"171.26400","53.67151","0.03187"
"171.45600","53.68753","0.03246"
"171.64800","53.70350","0.03135"
"171.84000","53.71946","0.03178"
"172.03200","53.73554","0.03213"
"172.22400","53.75151","0.03217"
"172.41600","53.76747","0.03178"
"172.60800","53.78350","0.03184"
"172.80000","53.79952","0.03217"
"172.99200","53.81548","0.03214"
"173.18400","53.83157","0.03227"
"173.37600","53.84753","0.03225"
"173.56800","53.86356","0.03222"
"173.76000","53.87946","0.03297"
"173.95200","53.89555","0.03311"
"174.14400","53.91151","0.03289"
"174.33600","53.92747","0.03253"
"174.52800","53.94349","0.03278"
"174.72000","53.95945","0.03322"
"174.91200","53.97548","0.03260"
"175.10400","53.99150","0.03261"
"175.29600","54.00747","0.03226"
"175.48800","54.02349","0.03305"
"175.68000","54.03951","0.03281"
"175.87200","54.05542","0.03127"
"176.06400","54.07156","0.03082"
"176.25600","54.08753","0.03117"
"176.44800","54.10343","0.03189"
"176.64000","54.11957","0.03218"
"176.83200","54.13548","0.03212"
"177.02400","54.15144","0.03203"
"177.21600","54.16753","0.03289"
"177.40800","54.18349","0.03258"
"177.60000","54.19946","0.03239"
"177.79200","54.21553","0.03257"
"177.98400","54.23150","0.03259"
"178.17600","54.24752","0.03290"
"178.36800","54.26355","0.03280"
"178.56000","54.27945","0.03232"
"178.75200","54.29547","0.03346"
"178.94400","54.31156","0.03316"
"179.13600","54.32746","0.03274"
"179.32800","54.34349","0.03341"
"179.52000","54.35951","0.03304"
"179.71200","54.37541","0.03389"
"179.90400","54.39156","0.03404"
"180.09600","54.40752","0.03401"
"180.28800","54.42348","0.03428"
"180.48000","54.43951","0.03362"
"180.67200","54.45547","0.03403"
"180.86400","54.47149","0.03388"
"181.05600","54.48751","0.03371"
"181.24800","54.50348","0.03382"
"181.44000","54.51951","0.03404"
"181.63200","54.53553","0.03367"
"181.82400","54.55149","0.03124"
"182.01600","54.56752","0.03109"
"182.20800","54.58354","0.03108"
"182.40000","54.59950","0.03109"
"182.59200","54.61547","0.03111"
"182.78400","54.63149","0.03151"
"182.97600","54.64751","0.03177"
"183.16800","54.66348","0.03150"
"183.36000","54.67950","0.03220"
"183.55200","54.69553","0.03196"
"183.74400","54.71149","0.03240"
"183.93600","54.72751","0.03264"
"184.12800","54.74353","0.03249"
"184.32000","54.75950","0.03259"
"184.51200","54.77546","0.03274"
"184.70400","54.79155","0.03280"
"184.89600","54.80751","0.03312"
"185.08800","54.82348","0.03278"
"185.28000","54.83955","0.03297"
"185.47200","54.85553","0.03340"
"185.66400","54.87148","0.03330"
"185.85600","54.88751","0.03339"
"186.04800","54.90347","0.03380"
"186.24000","54.91956","0.03413"
"186.43200","54.93552","0.03416"
"186.62400","54.95148","0.03366"
"186.81600","54.96751","0.03338"
"187.00800","54.98354","0.03337"
"187.20000","54.99950","0.03301"
"187.39200","55.01558","0.03352"
"187.58400","55.03154","0.03370"
"187.77600","55.04744","0.03404"
"187.96800","55.06359","0.03423"
"188.16000","55.07950","0.03387"
"188.35200","55.09546","0.03431"
"188.54400","55.11154","0.03406"
"188.73600","55.12750","0.03468"
"188.92800","55.14347","0.03427"
"189.12000","55.15955","0.03447"
"189.31200","55.17546","0.03471"
"189.50400","55.19148","0.03444"
"189.69600","55.20757","0.03506"
"189.88800","55.22346","0.03493"
"190.08000","55.23949","0.03537"
"190.27200","55.25552","0.03508"
"190.46400","55.27148","0.03511"
"190.65600","55.28750","0.03467"
"190.84800","55.30353","0.03397"
"191.04000","55.31949","0.03353"
"191.23200","55.33545","0.03435"
"191.42400","55.35154","0.03397"
"191.61600","55.36750","0.03343"
"191.80800","55.38346","0.03200"
"192.00000","55.39949","0.03096"
"192.19200","55.41552","0.03100"
"192.38400","55.43148","0.03148"
"192.57600","55.44750","0.03165"
"192.76800","55.46352","0.03199"
"192.96000","55.47948","0.03232"
"193.15200","55.49545","0.03291"
"193.34400","55.51154","0.03328"
"193.53600","55.52750","0.03271"
"193.72800","55.54352","0.03316"
"193.92000","55.55948","0.03350"
"194.11200","55.57550","0.03306"
"194.30400","55.59147","0.03371"
"194.49600","55.60756","0.03378"
"194.68800","55.62346","0.03397"
"194.88000","55.63948","0.03399"
"195.07200","55.65551","0.03383"
"195.26400","55.67147","0.03413"
"195.45600","55.68755","0.03436"
"195.64800","55.70352","0.03467"
"195.84000","55.71948","0.03494"
"196.03200","55.73556","0.03512"
"196.22400","55.75146","0.03563"
"196.41600","55.76743","0.03582"
"196.60800","55.78352","0.03551"
"196.80000","55.79948","0.03521"
"196.99200","55.81550","0.03595"
"197.18400","55.83147","0.03571"
"197.37600","55.84743","0.03612"
"197.56800","55.86351","0.03641"
"197.76000","55.87954","0.03645"
"197.95200","55.89550","0.03600"
"198.14400","55.91146","0.03692"
"198.33600","55.92755","0.03584"
"198.52800","55.94345","0.03599"
"198.72000","55.95954","0.03701"
"198.91200","55.97550","0.03663"
"199.10400","55.99141","0.03673"
"199.29600","56.00755","0.03704"
"199.48800","56.02345","0.03698"
"199.68000","56.03947","0.03758"
"199.87200","56.05556","0.03764"
"200.06400","56.07152","0.03799"
"200.25600","56.08749","0.03702"
"200.44800","56.10351","0.03738"
"200.64000","56.11947","0.03765"
"200.83200","56.13550","0.03721"
"201.02400","56.15152","0.03779"
"201.21600","56.16749","0.03785"
"201.40800","56.18351","0.03792"
"201.60000","56.19953","0.03836"
"201.79200","56.21550","0.03824"
"201.98400","56.23152","0.03937"
"202.17600","56.24748","0.03849"
"202.36800","56.26351","0.03909"
"202.56000","56.27947","0.03890"
"202.75200","56.29549","0.03925"
"202.94400","56.31152","0.03850"
"203.13600","56.32755","0.03921"
"203.32800","56.34345","0.03920"
"203.52000","56.35953","0.03971"
"203.71200","56.37549","0.03967"
"203.90400","56.39146","0.04030"
"204.09600","56.40754","0.03458"
"204.28800","56.42350","0.03408"
"204.48000","56.43947","0.03622"
"204.67200","56.45549","0.03655"
"204.86400","56.47145","0.03618"
"205.05600","56.48748","0.03737"
"205.24800","56.50351","0.03649"
"205.44000","56.51947","0.03790"
"205.63200","56.53555","0.03775"
"205.82400","56.55157","0.03771"
"206.01600","56.56747","0.03811"
"206.20800","56.58350","0.03820"
"206.40000","56.59958","0.03924"
"206.59200","56.61549","0.03851"
"206.78400","56.63157","0.03871"
"206.97600","56.64747","0.03960"
"207.16800","56.66343","0.03847"
"207.36000","56.67952","0.03872"
"207.55200","56.69549","0.03884"
"207.74400","56.71145","0.03846"
"207.93600","56.72753","0.03930"
"208.12800","56.74350","0.03740"
"208.32000","56.75946","0.03727"
"208.51200","56.77555","0.03723"
"208.70400","56.79151","0.03850"
"208.89600","56.80753","0.03817"
"209.08800","56.82349","0.03718"
"209.28000","56.83946","0.03697"
"209.47200","56.85555","0.03808"
"209.66400","56.87151","0.03746"
"209.85600","56.88747","0.03794"
"210.04800","56.90349","0.03807"
"210.24000","56.91946","0.03770"
"210.43200","56.93548","0.03849"
"210.62400","56.95151","0.03785"
"210.81600","56.96747","0.03813"
"211.00800","56.98349","0.03898"
"211.20000","56.99951","0.03854"
"211.39200","57.01548","0.03922"
"211.58400","57.03151","0.03953"
"211.77600","57.04753","0.03652"
"211.96800","57.06343","0.03690"
"212.16000","57.07951","0.03734"
"212.35200","57.09554","0.03831"
"212.54400","57.11144","0.03859"
"212.73600","57.12753","0.03906"
"212.92800","57.14355","0.03889"
"213.12000","57.15951","0.03950"
"213.31200","57.17554","0.03913"
"213.50400","57.19150","0.03709"
"213.69600","57.20746","0.03557"
"213.88800","57.22355","0.03685"
"214.08000","57.23951","0.03753"
"214.27200","57.25553","0.03702"
"214.46400","57.27150","0.03799"
"214.65600","57.28752","0.03789"
"214.84800","57.30349","0.03749"
"215.04000","57.31951","0.03799"
"215.23200","57.33547","0.03891"
"215.42400","57.35150","0.03910"
"215.61600","57.36746","0.03893"
"215.80800","57.38354","0.03973"
"216.00000","57.39951","0.03943"
"216.19200","57.41547","0.04010"
"216.38400","57.43150","0.04060"
"216.57600","57.44751","0.03998"
"216.76800","57.46348","0.04133"
"216.96000","57.47957","0.04128"
"217.15200","57.49553","0.04137"
"217.34400","57.51149","0.04105"
"217.53600","57.52752","0.04109"
"217.72800","57.54348","0.04119"
"217.92000","57.55944","0.04079"
"218.11200","57.57553","0.04142"
"218.30400","57.59143","0.04188"
"218.49600","57.60746","0.04194"
"218.68800","57.62354","0.04256"
"218.88000","57.63950","0.04269"
"219.07200","57.65546","0.04242"
"219.26400","57.67155","0.04321"
"219.45600","57.68752","0.04339"
"219.64800","57.70354","0.04124"
"219.84000","57.71956","0.04126"
"220.03200","57.73546","0.04140"
"220.22400","57.75149","0.04181"
"220.41600","57.76751","0.04223"
"220.60800","57.78342","0.04309"
"220.80000","57.79956","0.04271"
"220.99200","57.81552","0.04325"
"221.18400","57.83142","0.04366"
"221.37600","57.84751","0.04380"
"221.56800","57.86348","0.04448"
"221.76000","57.87950","0.04388"
"221.95200","57.89552","0.04380"
"222.14400","57.91148","0.04412"
"222.33600","57.92745","0.04420"
"222.52800","57.94353","0.04443"
"222.72000","57.95944","0.04247"
"222.91200","57.97552","0.04275"
"223.10400","57.99154","0.04299"
"223.29600","58.00750","0.04284"
"223.48800","58.02353","0.04385"
"223.68000","58.03950","0.04421"
"223.87200","58.05552","0.04404"
"224.06400","58.07142","0.04467"
"224.25600","58.08751","0.04505"
"224.44800","58.10353","0.04442"
"224.64000","58.11949","0.04322"
"224.83200","58.13546","0.04340"
"225.02400","58.15148","0.04330"
"225.21600","58.16750","0.04404"
"225.40800","58.18346","0.04436"
"225.60000","58.19949","0.04409"
"225.79200","58.21552","0.04421"
"225.98400","58.23148","0.04408"
"226.17600","58.24756","0.04420"
"226.36800","58.26347","0.04474"
"226.56000","58.27949","0.04474"
"226.75200","58.29551","0.04535"
"226.94400","58.31148","0.04574"
"227.13600","58.32750","0.04559"
"227.32800","58.34352","0.04548"
"227.52000","58.35943","0.04614"
"227.71200","58.37558","0.04597"
"227.90400","58.39154","0.04615"
"228.09600","58.40744","0.04642"
"228.28800","58.42352","0.04697"
"228.48000","58.43949","0.04681"
"228.67200","58.45545","0.04732"
"228.86400","58.47153","0.04689"
"229.05600","58.48750","0.04706"
"229.24800","58.50346","0.04736"
"229.44000","58.51954","0.04753"
"229.63200","58.53551","0.04772"
"229.82400","58.55147","0.04733"
"230.01600","58.56756","0.04800"
"230.20800","58.58346","0.04837"
"230.40000","58.59949","0.04786"
"230.59200","58.61551","0.04805"
"230.78400","58.63147","0.04850"
"230.97600","58.64749","0.04882"
"231.16800","58.66352","0.04908"
"231.36000","58.67942","0.04961"
"231.55200","58.69551","0.04832"
"231.74400","58.71153","0.04868"
"231.93600","58.72743","0.04905"
"232.12800","58.74352","0.04840"
"232.32000","58.75954","0.04884"
"232.51200","58.77545","0.04925"
"232.70400","58.79147","0.04957"
"232.89600","58.80749","0.04962"
"233.08800","58.82352","0.05008"
"233.28000","58.83948","0.05007"
"233.47200","58.85550","0.05032"
"233.66400","58.87152","0.05111"
"233.85600","58.88749","0.05117"
"234.04800","58.90351","0.05162"
"234.24000","58.91948","0.05180"
"234.43200","58.93550","0.05194"
"234.62400","58.95147","0.05172"
"234.81600","58.96749","0.05244"
"235.00800","58.98351","0.05250"
"235.20000","58.99954","0.05317"
"235.39200","59.01544","0.05174"
"235.58400","59.03146","0.05166"
"235.77600","59.04749","0.05144"
"235.96800","59.06351","0.05068"
"236.16000","59.07947","0.05105"
"236.35200","59.09555","0.05168"
"236.54400","59.11152","0.05160"
"236.73600","59.12743","0.05137"
"236.92800","59.14357","0.05146"
"237.12000","59.15947","0.05217"
"237.31200","59.17550","0.05186"
"237.50400","59.19152","0.05176"
"237.69600","59.20749","0.05238"
"237.88800","59.22351","0.05231"
"238.08000","59.23953","0.05243"
"238.27200","59.25549","0.05301"
"238.46400","59.27152","0.05281"
"238.65600","59.28754","0.05318"
"238.84800","59.30351","0.05291"
"239.04000","59.31953","0.05324"
"239.23200","59.33549","0.05344"
"239.42400","59.35140","0.05318"
"239.61600","59.36754","0.05379"
"239.80800","59.38350","0.05375"
"240.00000","59.39941","0.05295"
"240.19200","59.41555","0.05303"
"240.38400","59.43146","0.05307"
"240.57600","59.44748","0.05380"
"240.76800","59.46357","0.05337"
"240.96000","59.47953","0.05012"
"241.15200","59.49549","0.05017"
"241.34400","59.51157","0.05041"
"241.53600","59.52748","0.04933"
"241.72800","59.54350","0.05010"
"241.92000","59.55953","0.04860"
"242.11200","59.57549","0.04924"
"242.30400","59.59151","0.04927"
"242.49600","59.60753","0.04931"
"242.68800","59.62344","0.05009"
"242.88000","59.63952","0.05042"
"243.07200","59.65555","0.05056"
"243.26400","59.67146","0.05100"
"243.45600","59.68748","0.05106"
"243.64800","59.70350","0.05144"
"243.84000","59.71952","0.05132"
"244.03200","59.73555","0.05157"
"244.22400","59.75151","0.05210"
"244.41600","59.76748","0.05252"
"244.60800","59.78355","0.05244"
"244.80000","59.79952","0.05207"
"244.99200","59.81554","0.05193"
"245.18400","59.83151","0.05192"
"245.37600","59.84747","0.05126"
"245.56800","59.86349","0.05185"
"245.76000","59.87946","0.05195"
"245.95200","59.89548","0.05209"
"246.14400","59.91150","0.05303"
"246.33600","59.92747","0.05283"
"246.52800","59.94355","0.05364"
"246.72000","59.95951","0.05367"
"246.91200","59.97548","0.05381"
"247.10400","59.99156","0.05379"
"247.29600","60.00753","0.05411"
"247.48800","60.02343","0.05438"
"247.68000","60.03952","0.05435"
"247.87200","60.05548","0.05484"
"248.06400","60.07144","0.05431"
"248.25600","60.08752","0.05475"
"248.44800","60.10349","0.05474"
"248.64000","60.11945","0.05422"
"248.83200","60.13554","0.05498"
"249.02400","60.15150","0.05516"
"249.21600","60.16752","0.05563"
"249.40800","60.18349","0.05553"
"249.60000","60.19951","0.05585"
"249.79200","60.21548","0.05606"
"249.98400","60.23156","0.05653"
"250.17600","60.24741","0.05547"
"250.36800","60.26348","0.05522"
"250.56000","60.27951","0.05566"
"250.75200","60.29541","0.05590"
"250.94400","60.31155","0.05579"
"251.13600","60.32752","0.05633"
"251.32800","60.34348","0.05616"
"251.52000","60.35951","0.02901"
"251.71200","60.37553","0.02215"
"251.90400","60.39150","0.01993"
"252.09600","60.40752","0.01498"
"252.28800","60.42348","0.01568"
"252.48000","60.43951","0.02273"
"252.67200","60.45553","0.01739"
"252.86400","60.47150","0.01739"
"253.05600","60.48752","0.02363"
"253.24800","60.50354","0.01954"
"253.44000","60.51945","0.01799"
"253.63200","60.53553","0.02373"
"253.82400","60.55149","0.02086"
"254.01600","60.56752","0.01946"
"254.20800","60.58348","0.02406"
"254.40000","60.59950","0.02254"
"254.59200","60.61546","0.01997"
"254.78400","60.63149","0.02381"
"254.97600","60.64746","0.02242"
"255.16800","60.66354","0.02131"
"255.36000","60.67956","0.02405"
"255.55200","60.69547","0.02340"
"255.74400","60.71155","0.02182"
"255.93600","60.72745","0.02475"
"256.12800","60.74347","0.02416"
"256.32000","60.75950","0.02256"
"256.51200","60.77547","0.02532"
"256.70400","60.79155","0.02465"
"256.89600","60.80751","0.02328"
"257.08800","60.82348","0.02481"
"257.28000","60.83950","0.02463"
"257.47200","60.85552","0.02402"
"257.66400","60.87149","0.02468"
"257.85600","60.88751","0.02497"
"258.04800","60.90359","0.02518"
"258.24000","60.91950","0.02568"
"258.43200","60.93552","0.02563"
"258.62400","60.95148","0.02530"
"258.81600","60.96745","0.02611"
"259.00800","60.98353","0.02594"
"259.20000","60.99956","0.02601"
"259.39200","61.01546","0.02670"
"259.58400","61.03154","0.02628"
"259.77600","61.04745","0.02668"
"259.96800","61.06347","0.02689"
"260.16000","61.07956","0.02650"
"260.35200","61.09552","0.02655"
"260.54400","61.11148","0.02737"
"260.73600","61.12751","0.02699"
"260.92800","61.14341","0.02685"
"261.12000","61.15949","0.02739"
"261.31200","61.17552","0.02753"
"261.50400","61.19148","0.02757"
"261.69600","61.20751","0.02759"
"261.88800","61.22353","0.02775"
"262.08000","61.23943","0.02843"
"262.27200","61.25551","0.02833"
"262.46400","61.27148","0.02864"
"262.65600","61.28750","0.02838"
"262.84800","61.30353","0.02887"
"263.04000","61.31949","0.02801"
"263.23200","61.33551","0.02866"
"263.42400","61.35154","0.02856"
"263.61600","61.36750","0.02898"
"263.80800","61.38347","0.02898"
"264.00000","61.39954","0.02919"
"264.19200","61.41545","0.02875"
"264.38400","61.43153","0.02895"
"264.57600","61.44750","0.02855"
"264.76800","61.46346","0.02683"
"264.96000","61.47949","0.02666"
"265.15200","61.49551","0.02708"
"265.34400","61.51147","0.02741"
"265.53600","61.52756","0.02758"
"265.72800","61.54353","0.02730"
"265.92000","61.55955","0.02709"
"266.11200","61.57551","0.02759"
"266.30400","61.59147","0.02745"
"266.49600","61.60749","0.02744"
"266.68800","61.62352","0.02822"
"266.88000","61.63942","0.02804"
"267.07200","61.65551","0.02777"
"267.26400","61.67147","0.02851"
"267.45600","61.68749","0.02867"
"267.64800","61.70345","0.02873"
"267.84000","61.71949","0.02873"
"268.03200","61.73551","0.02885"
"268.22400","61.75153","0.02907"
"268.41600","61.76749","0.02987"
"268.60800","61.78352","0.02949"
"268.80000","61.79954","0.02963"
"268.99200","61.81544","0.02976"
"269.18400","61.83153","0.02972"
"269.37600","61.84749","0.03025"
"269.56800","61.86346","0.03026"
"269.76000","61.87954","0.03006"
"269.95200","61.89550","0.03038"
"270.14400","61.91146","0.03018"
"270.33600","61.92749","0.03031"
"270.52800","61.94351","0.03060"
"270.72000","61.95948","0.03088"
"270.91200","61.97550","0.03050"
"271.10400","61.99146","0.03046"
"271.29600","62.00749","0.03067"
"271.48800","62.02351","0.03097"
"271.68000","62.03942","0.03070"
"271.87200","62.05550","0.03071"
"272.06400","62.07158","0.03063"
"272.25600","62.08743","0.03103"
"272.44800","62.10351","0.03070"
"272.64000","62.11953","0.03067"
"272.83200","62.13538","0.03054"
"273.02400","62.15152","0.03064"
"273.21600","62.16755","0.03017"
"273.40800","62.18345","0.02951"
"273.60000","62.19953","0.02901"
"273.79200","62.21544","0.02943"
"273.98400","62.23146","0.02926"
"274.17600","62.24754","0.02904"
"274.36800","62.26344","0.02951"
"274.56000","62.27953","0.02924"
"274.75200","62.29550","0.03019"
"274.94400","62.31146","0.02970"
"275.13600","62.32754","0.03009"
"275.32800","62.34351","0.03011"
"275.52000","62.35947","0.02995"
"275.71200","62.37549","0.03023"
"275.90400","62.39146","0.03057"
"276.09600","62.40748","0.03031"
"276.28800","62.42350","0.03081"
"276.48000","62.43946","0.03031"
"276.67200","62.45549","0.03035"
"276.86400","62.47152","0.03072"
"277.05600","62.48748","0.03027"
"277.24800","62.50349","0.03022"
"277.44000","62.51952","0.03071"
"277.63200","62.53549","0.03042"
"277.82400","62.55157","0.03068"
"278.01600","62.56747","0.03080"
"278.20800","62.58344","0.03106"
"278.40000","62.59952","0.03103"
"278.59200","62.61548","0.03136"
"278.78400","62.63151","0.03093"
"278.97600","62.64753","0.03158"
"279.16800","62.66344","0.03125"
"279.36000","62.67952","0.03163"
"279.55200","62.69548","0.03204"
"279.74400","62.71145","0.03235"
"279.93600","62.72753","0.03216"
"280.12800","62.74349","0.03207"
"280.32000","62.75940","0.03178"
"280.51200","62.77554","0.03262"
"280.70400","62.79150","0.03263"
"280.89600","62.80741","0.03279"
"281.08800","62.82355","0.03262"
"281.28000","62.83952","0.03265"
"281.47200","62.85548","0.03308"
"281.66400","62.87156","0.03326"
"281.85600","62.88753","0.03355"
"282.04800","62.90349","0.03351"
"282.24000","62.91951","0.03398"
"282.43200","62.93548","0.03390"
"282.62400","62.95150","0.03396"
"282.81600","62.96753","0.03432"
"282.91800","62.97596","0.03395"