File: Force_trajectories/161218_2/Specimen_RawData_1.csv
End date,"12/18/2016"
Specimen label,"16CT_30"
Maximum Load,"0.20278",N

Time,Extension,Load
(s),(mm),(N)
"0.00000","0.00000","0.00013"
"0.34800","0.02900","-0.00002"
"0.69600","0.05824","0.00012"
"1.04400","0.08729","0.00011"
"1.39200","0.11623","0.00017"
"1.74000","0.14517","0.00015"
"2.08800","0.17429","0.00050"
"2.43600","0.20328","0.00010"
"2.78400","0.23222","0.00017"
"3.13200","0.26128","0.00057"
"3.48000","0.29022","0.00037"
"3.82800","0.31922","0.00010"
"4.17600","0.34821","-0.00016"
"4.52400","0.37721","-0.00004"
"4.87200","0.40621","0.00020"
"5.22000","0.43521","0.00020"
"5.56800","0.46421","0.00031"
"5.91600","0.49320","0.00039"
"6.26400","0.52226","0.00042"
"6.61200","0.55114","0.00029"
"6.96000","0.58026","0.00007"
"7.30800","0.60926","0.00034"
"7.65600","0.63819","0.00011"
"8.00400","0.66725","0.00018"
"8.35200","0.69619","0.00064"
"8.70000","0.72519","0.00019"
"9.04800","0.75424","0.00031"
"9.39600","0.78318","0.00013"
"9.74400","0.81218","0.00035"
"10.09200","0.84118","0.00085"
"10.44000","0.87024","0.00011"
"10.78800","0.89917","0.00047"
"11.13600","0.92829","0.00047"
"11.48400","0.95717","0.00017"
"11.83200","0.98623","0.00036"
"12.18000","1.01523","0.00045"
"12.52800","1.04416","0.00036"
"12.87600","1.07322","0.00061"
"13.22400","1.10216","0.00071"
"13.57200","1.13116","0.00032"
"13.92000","1.16028","0.00076"
"14.26800","1.18921","0.00055"
"14.61600","1.21815","0.00051"
"14.96400","1.24721","0.00035"
"15.31200","1.27627","0.00047"
"15.66000","1.30521","0.00090"
"16.00800","1.33426","0.00086"
"16.35600","1.36320","0.00023"
"16.70400","1.39220","0.00076"
"17.05200","1.42126","0.00075"
"17.40000","1.45014","0.00040"
"17.74800","1.47925","0.00057"
"18.09600","1.50825","0.00083"
"18.44400","1.53719","0.00076"
"18.79200","1.56625","0.00068"
"19.14000","1.59518","0.00087"
"19.48800","1.62418","0.00072"
"19.83600","1.65324","0.00125"
"20.18400","1.68224","0.00084"
"20.53200","1.71124","0.00087"
"20.88000","1.74023","0.00057"
"21.22800","1.76917","0.00040"
"21.57600","1.79817","0.00072"
"21.92400","1.82723","0.00042"
"22.27200","1.85623","0.00050"
"22.62000","1.88528","0.00077"
"22.96800","1.91422","0.00091"
"23.31600","1.94316","0.00061"
"23.66400","1.97222","0.00086"
"24.01200","2.00122","0.00092"
"24.36000","2.03015","0.00079"
"24.70800","2.05921","0.00078"
"25.05600","2.08821","0.00120"
"25.40400","2.11715","0.00147"
"25.75200","2.14626","0.00083"
"26.10000","2.17526","0.00101"
"26.44800","2.20420","0.00076"
"26.79600","2.23326","0.00101"
"27.14400","2.26220","0.00127"
"27.49200","2.29125","0.00130"
"27.84000","2.32025","0.00098"
"28.18800","2.34919","0.00091"
"28.53600","2.37825","0.00111"
"28.88400","2.40725","0.00103"
"29.23200","2.43618","0.00102"
"29.58000","2.46518","0.00112"
"29.92800","2.49424","0.00116"
"30.27600","2.52318","0.00092"
"30.62400","2.55224","0.00132"
"30.97200","2.58123","0.00145"
"31.32000","2.61011","0.00148"
"31.66800","2.63923","0.00094"
"32.01600","2.66823","0.00129"
"32.36400","2.69717","0.00148"
"32.71200","2.72628","0.00100"
"33.06000","2.75516","0.00172"
"33.40800","2.78422","0.00149"
"33.75600","2.81322","0.00129"
"34.10400","2.84222","0.00135"
"34.45200","2.87121","0.00152"
"34.80000","2.90027","0.00184"
"35.14800","2.92921","0.00117"
"35.49600","2.95827","0.00128"
"35.84400","2.98720","0.00112"
"36.19200","3.01614","0.00149"
"36.54000","3.04526","0.00126"
"36.88800","3.07420","0.00155"
"37.23600","3.10320","0.00154"
"37.58400","3.13225","0.00163"
"37.93200","3.16125","0.00152"
"38.28000","3.19025","0.00163"
"38.62800","3.21919","0.00144"
"38.97600","3.24825","0.00178"
"39.32400","3.27718","0.00110"
"39.67200","3.30618","0.00059"
"40.02000","3.33518","0.00120"
"40.36800","3.36418","0.00090"
"40.71600","3.39324","0.00107"
"41.06400","3.42217","0.00115"
"41.41200","3.45123","0.00102"
"41.76000","3.48029","0.00103"
"42.10800","3.50917","0.00107"
"42.45600","3.53822","0.00087"
"42.80400","3.56716","0.00151"
"43.15200","3.59622","0.00126"
"43.50000","3.62528","0.00145"
"43.84800","3.65422","0.00107"
"44.19600","3.68315","0.00152"
"44.54400","3.71221","0.00136"
"44.89200","3.74121","0.00165"
"45.24000","3.77021","0.00184"
"45.58800","3.79927","0.00143"
"45.93600","3.82820","0.00181"
"46.28400","3.85726","0.00143"
"46.63200","3.88626","0.00163"
"46.98000","3.91514","0.00146"
"47.32800","3.94426","0.00165"
"47.67600","3.97319","0.00146"
"48.02400","4.00219","0.00166"
"48.37200","4.03125","0.00189"
"48.72000","4.06025","0.00182"
"49.06800","4.08919","0.00171"
"49.41600","4.11824","0.00192"
"49.76400","4.14724","0.00202"
"50.11200","4.17624","0.00230"
"50.46000","4.20530","0.00199"
"50.80800","4.23418","0.00229"
"51.15600","4.26323","0.00179"
"51.50400","4.29223","0.00234"
"51.85200","4.32111","0.00227"
"52.20000","4.35023","0.00265"
"52.54800","4.37928","0.00274"
"52.89600","4.40816","0.00218"
"53.24400","4.43722","0.00255"
"53.59200","4.46628","0.00242"
"53.94000","4.49522","0.00217"
"54.28800","4.52421","0.00240"
"54.63600","4.55327","0.00260"
"54.98400","4.58215","0.00275"
"55.33200","4.61127","0.00294"
"55.68000","4.64021","0.00255"
"56.02800","4.66920","0.00302"
"56.37600","4.69820","0.00300"
"56.72400","4.72720","0.00310"
"57.07200","4.75620","0.00304"
"57.42000","4.78520","0.00321"
"57.76800","4.81419","0.00335"
"58.11600","4.84325","0.00327"
"58.46400","4.87225","0.00378"
"58.81200","4.90113","0.00390"
"59.16000","4.93018","0.00371"
"59.50800","4.95930","0.00364"
"59.85600","4.98818","0.00355"
"60.20400","5.01724","0.00401"
"60.55200","5.04624","0.00431"
"60.90000","5.07517","0.00402"
"61.24800","5.10429","0.00411"
"61.59600","5.13317","0.00437"
"61.94400","5.16217","0.00435"
"62.29200","5.19123","0.00429"
"62.64000","5.22022","0.00411"
"62.98800","5.24922","0.00435"
"63.33600","5.27822","0.00476"
"63.68400","5.30722","0.00468"
"64.03200","5.33622","0.00472"
"64.38000","5.36527","0.00518"
"64.72800","5.39415","0.00483"
"65.07600","5.42327","0.00504"
"65.42400","5.45227","0.00538"
"65.77200","5.48115","0.00551"
"66.12000","5.51026","0.00542"
"66.46800","5.53920","0.00561"
"66.81600","5.56820","0.00550"
"67.16400","5.59720","0.00566"
"67.51200","5.62619","0.00550"
"67.86000","5.65519","0.00647"
"68.20800","5.68425","0.00642"
"68.55600","5.71325","0.00592"
"68.90400","5.74219","0.00614"
"69.25200","5.77125","0.00596"
"69.60000","5.80024","0.00612"
"69.94800","5.82924","0.00624"
"70.29600","5.85824","0.00612"
"70.64400","5.88712","0.00620"
"70.99200","5.91623","0.00673"
"71.34000","5.94523","0.00667"
"71.68800","5.97423","0.00659"
"72.03600","6.00323","0.00673"
"72.38400","6.03223","0.00711"
"72.73200","6.06122","0.00708"
"73.08000","6.09022","0.00697"
"73.42800","6.11916","0.00740"
"73.77600","6.14822","0.00736"
"74.12400","6.17728","0.00765"
"74.47200","6.20621","0.00786"
"74.82000","6.23521","0.00789"
"75.16800","6.26427","0.00766"
"75.51600","6.29315","0.00788"
"75.86400","6.32226","0.00849"
"76.21200","6.35126","0.00808"
"76.56000","6.38020","0.00820"
"76.90800","6.40920","0.00858"
"77.25600","6.43820","0.00844"
"77.60400","6.46719","0.00908"
"77.95200","6.49625","0.00952"
"78.30000","6.52525","0.00934"
"78.64800","6.55419","0.00918"
"78.99600","6.58325","0.00957"
"79.34400","6.61218","0.00985"
"79.69200","6.64118","0.00983"
"80.04000","6.67024","0.00997"
"80.38800","6.69918","0.01014"
"80.73600","6.72824","0.01049"
"81.08400","6.75723","0.01061"
"81.43200","6.78617","0.01081"
"81.78000","6.81517","0.01167"
"82.12800","6.84423","0.01147"
"82.47600","6.87323","0.01157"
"82.82400","6.90222","0.01195"
"83.17200","6.93128","0.01210"
"83.52000","6.96016","0.01258"
"83.86800","6.98928","0.01279"
"84.21600","7.01822","0.01316"
"84.56400","7.04715","0.01410"
"84.91200","7.07627","0.01451"
"85.26000","7.10521","0.01530"
"85.60800","7.13421","0.01064"
"85.95600","7.16320","0.01022"
"86.30400","7.19220","0.01018"
"86.65200","7.22120","0.01067"
"87.00000","7.25020","0.01093"
"87.34800","7.27920","0.01174"
"87.69600","7.30819","0.01288"
"88.04400","7.33725","0.01231"
"88.39200","7.36613","0.01251"
"88.74000","7.39519","0.01295"
"89.08800","7.42425","0.01261"
"89.43600","7.45318","0.01316"
"89.78400","7.48224","0.01402"
"90.13200","7.51124","0.01460"
"90.48000","7.54018","0.01480"
"90.82800","7.56924","0.01535"
"91.17600","7.59823","0.01578"
"91.52400","7.62723","0.01657"
"91.87200","7.65623","0.01720"
"92.22000","7.68523","0.01753"
"92.56800","7.71422","0.01827"
"92.91600","7.74322","0.01883"
"93.26400","7.77210","0.01910"
"93.61200","7.80122","0.01976"
"93.96000","7.83022","0.02038"
"94.30800","7.85915","0.02108"
"94.65600","7.88827","0.02149"
"95.00400","7.91721","0.02197"
"95.35200","7.94621","0.02220"
"95.70000","7.97527","0.02287"
"96.04800","8.00420","0.02351"
"96.39600","8.03320","0.02326"
"96.74400","8.06220","0.02456"
"97.09200","8.09120","0.02496"
"97.44000","8.12020","0.02541"
"97.78800","8.14919","0.02578"
"98.13600","8.17819","0.02629"
"98.48400","8.20719","0.02661"
"98.83200","8.23625","0.02689"
"99.18000","8.26519","0.02681"
"99.52800","8.29424","0.02738"
"99.87600","8.32324","0.02844"
"100.22400","8.35212","0.02874"
"100.57200","8.38124","0.02922"
"100.92000","8.41024","0.02898"
"101.26800","8.43917","0.02981"
"101.61600","8.46829","0.02976"
"101.96400","8.49723","0.03003"
"102.31200","8.52623","0.03053"
"102.66000","8.55522","0.03088"
"103.00800","8.58422","0.03183"
"103.35600","8.61316","0.03204"
"103.70400","8.64228","0.03318"
"104.05200","8.67116","0.03418"
"104.40000","8.70021","0.03478"
"104.74800","8.72921","0.03597"
"105.09600","8.75815","0.03606"
"105.44400","8.78721","0.03650"
"105.79200","8.81621","0.03667"
"106.14000","8.84514","0.03782"
"106.48800","8.87420","0.03828"
"106.83600","8.90326","0.03890"
"107.18400","8.93220","0.03980"
"107.53200","8.96126","0.04052"
"107.88000","8.99019","0.04091"
"108.22800","9.01913","0.04085"
"108.57600","9.04825","0.04217"
"108.92400","9.07719","0.04258"
"109.27200","9.10618","0.04393"
"109.62000","9.13524","0.04463"
"109.96800","9.16418","0.04429"
"110.31600","9.19330","0.04544"
"110.66400","9.22224","0.04686"
"111.01200","9.25117","0.04728"
"111.36000","9.28023","0.04821"
"111.70800","9.30923","0.04892"
"112.05600","9.33817","0.04979"
"112.40400","9.36723","0.05055"
"112.75200","9.39622","0.05054"
"113.10000","9.42522","0.05149"
"113.44800","9.45422","0.05209"
"113.79600","9.48322","0.05249"
"114.14400","9.51222","0.05322"
"114.49200","9.54121","0.05495"
"114.84000","9.57021","0.05507"
"115.18800","9.59927","0.05526"
"115.53600","9.62821","0.05544"
"115.88400","9.65720","0.05620"
"116.23200","9.68614","0.05803"
"116.58000","9.71526","0.05896"
"116.92800","9.74420","0.05940"
"117.27600","9.77326","0.06088"
"117.62400","9.80231","0.06234"
"117.97200","9.83113","0.06346"
"118.32000","9.86025","0.06338"
"118.66800","9.88925","0.06486"
"119.01600","9.91813","0.06595"
"119.36400","9.94724","0.06741"
"119.71200","9.97618","0.06734"
"120.06000","10.00524","0.06932"
"120.40800","10.03424","0.07024"
"120.75600","10.06324","0.07095"
"121.10400","10.09223","0.07255"
"121.45200","10.12123","0.07389"
"121.80000","10.15023","0.07500"
"122.14800","10.17923","0.07545"
"122.49600","10.20828","0.07558"
"122.84400","10.23716","0.07660"
"123.19200","10.26622","0.07777"
"123.54000","10.29528","0.07852"
"123.88800","10.32416","0.07930"
"124.23600","10.35322","0.08019"
"124.58400","10.38221","0.08116"
"124.93200","10.41121","0.08175"
"125.28000","10.44021","0.08241"
"125.62800","10.46927","0.08314"
"125.97600","10.49820","0.08416"
"126.32400","10.52720","0.08474"
"126.67200","10.55620","0.08557"
"127.02000","10.58520","0.08685"
"127.36800","10.61426","0.08768"
"127.71600","10.64319","0.08878"
"128.06400","10.67219","0.08953"
"128.41200","10.70125","0.09035"
"128.76000","10.73019","0.09121"
"129.10800","10.75925","0.09213"
"129.45600","10.78824","0.09304"
"129.80400","10.81718","0.09367"
"130.15200","10.84624","0.09444"
"130.50000","10.87524","0.09558"
"130.84800","10.90418","0.09680"
"131.19600","10.93317","0.09822"
"131.54400","10.96223","0.09943"
"131.89200","10.99117","0.10041"
"132.24000","11.02023","0.10212"
"132.58800","11.04917","0.10221"
"132.93600","11.07822","0.10309"
"133.28400","11.10722","0.10487"
"133.63200","11.13616","0.10601"
"133.98000","11.16522","0.10702"
"134.32800","11.19427","0.10846"
"134.67600","11.22321","0.10980"
"135.02400","11.25221","0.11241"
"135.37200","11.28121","0.11341"
"135.72000","11.31021","0.11563"
"136.06800","11.33921","0.11767"
"136.41600","11.36826","0.12038"
"136.76400","11.39720","0.12269"
"137.11200","11.42626","0.12523"
"137.46000","11.45520","0.12619"
"137.80800","11.48419","0.12835"
"138.15600","11.51319","0.12979"
"138.50400","11.54219","0.13133"
"138.85200","11.57125","0.13273"
"139.20000","11.60019","0.13435"
"139.54800","11.62918","0.01829"
"139.89600","11.65818","0.02080"
"140.24400","11.68724","0.01598"
"140.59200","11.71624","0.01568"
"140.94000","11.74523","0.02172"
"141.28800","11.77423","0.02179"
"141.63600","11.80317","0.01988"
"141.98400","11.83223","0.02162"
"142.33200","11.86123","0.02523"
"142.68000","11.89017","0.02520"
"143.02800","11.91928","0.02427"
"143.37600","11.94822","0.02556"
"143.72400","11.97722","0.02748"
"144.07200","12.00622","0.02827"
"144.42000","12.03515","0.02802"
"144.76800","12.06427","0.02820"
"145.11600","12.09327","0.02947"
"145.46400","12.12215","0.03084"
"145.81200","12.15121","0.03126"
"146.16000","12.18020","0.03114"
"146.50800","12.20914","0.03199"
"146.85600","12.23826","0.03285"
"147.20400","12.26720","0.03449"
"147.55200","12.29620","0.03487"
"147.90000","12.32525","0.03539"
"148.24800","12.35419","0.03567"
"148.59600","12.38319","0.03667"
"148.94400","12.41225","0.03794"
"149.29200","12.44125","0.03946"
"149.64000","12.47018","0.03966"
"149.98800","12.49924","0.04056"
"150.33600","12.52824","0.04035"
"150.68400","12.55724","0.04126"
"151.03200","12.58623","0.04268"
"151.38000","12.61517","0.04274"
"151.72800","12.64423","0.04431"
"152.07600","12.67329","0.04442"
"152.42400","12.70211","0.04497"
"152.77200","12.73128","0.04559"
"153.12000","12.76028","0.04622"
"153.46800","12.78922","0.04736"
"153.81600","12.81822","0.04781"
"154.16400","12.84722","0.04928"
"154.51200","12.87621","0.04928"
"154.86000","12.90521","0.05013"
"155.20800","12.93421","0.05084"
"155.55600","12.96321","0.05171"
"155.90400","12.99227","0.05200"
"156.25200","13.02120","0.05336"
"156.60000","13.05020","0.05386"
"156.94800","13.07926","0.05410"
"157.29600","13.10814","0.05499"
"157.64400","13.13725","0.05526"
"157.99200","13.16625","0.05573"
"158.34000","13.19519","0.05581"
"158.68800","13.22425","0.05545"
"159.03600","13.25325","0.05679"
"159.38400","13.28219","0.05793"
"159.73200","13.31124","0.05839"
"160.08000","13.34024","0.05934"
"160.42800","13.36918","0.06041"
"160.77600","13.39824","0.06210"
"161.12400","13.42724","0.06288"
"161.47200","13.45617","0.06418"
"161.82000","13.48529","0.06540"
"162.16800","13.51417","0.06710"
"162.51600","13.54323","0.06753"
"162.86400","13.57222","0.06839"
"163.21200","13.60116","0.06907"
"163.56000","13.63028","0.07085"
"163.90800","13.65922","0.07210"
"164.25600","13.68822","0.07252"
"164.60400","13.71727","0.07339"
"164.95200","13.74621","0.07397"
"165.30000","13.77515","0.07462"
"165.64800","13.80421","0.07610"
"165.99600","13.83321","0.07649"
"166.34400","13.86226","0.07699"
"166.69200","13.89120","0.07788"
"167.04000","13.92020","0.07813"
"167.38800","13.94920","0.07871"
"167.73600","13.97819","0.07915"
"168.08400","14.00719","0.07929"
"168.43200","14.03631","0.07995"
"168.78000","14.06525","0.08059"
"169.12800","14.09419","0.08053"
"169.47600","14.12319","0.08142"
"169.82400","14.15224","0.08215"
"170.17200","14.18118","0.08290"
"170.52000","14.21024","0.08349"
"170.86800","14.23930","0.08388"
"171.21600","14.26817","0.08465"
"171.56400","14.29723","0.08540"
"171.91200","14.32617","0.08607"
"172.26000","14.35517","0.08670"
"172.60800","14.38423","0.08725"
"172.95600","14.41317","0.08756"
"173.30400","14.44222","0.08803"
"173.65200","14.47122","0.08860"
"174.00000","14.50016","0.08875"
"174.34800","14.52921","0.08930"
"174.69600","14.55827","0.09074"
"175.04400","14.58721","0.09173"
"175.39200","14.61621","0.09273"
"175.74000","14.64527","0.09274"
"176.08800","14.67415","0.09355"
"176.43600","14.70326","0.09464"
"176.78400","14.73220","0.09547"
"177.13200","14.76114","0.09582"
"177.48000","14.79026","0.09664"
"177.82800","14.81920","0.09825"
"178.17600","14.84819","0.09887"
"178.52400","14.87719","0.10022"
"178.87200","14.90619","0.10140"
"179.22000","14.93525","0.10283"
"179.56800","14.96424","0.10418"
"179.91600","14.99318","0.10539"
"180.26400","15.02218","0.10665"
"180.61200","15.05130","0.10818"
"180.96000","15.08018","0.11020"
"181.30800","15.10923","0.11262"
"181.65600","15.13823","0.11493"
"182.00400","15.16717","0.11667"
"182.35200","15.19629","0.11955"
"182.70000","15.22523","0.12007"
"183.04800","15.25422","0.12117"
"183.39600","15.28322","0.12278"
"183.74400","15.31222","0.12584"
"184.09200","15.34122","0.12786"
"184.44000","15.37022","0.13002"
"184.78800","15.39921","0.13022"
"185.13600","15.42815","0.13231"
"185.48400","15.45727","0.13332"
"185.83200","15.48621","0.13529"
"186.18000","15.51527","0.13674"
"186.52800","15.54426","0.13949"
"186.87600","15.57314","0.14036"
"187.22400","15.60220","0.14234"
"187.57200","15.63126","0.14235"
"187.92000","15.66019","0.14364"
"188.26800","15.68925","0.14529"
"188.61600","15.71819","0.14723"
"188.96400","15.74719","0.14860"
"189.31200","15.77625","0.14967"
"189.66000","15.80518","0.15007"
"190.00800","15.83418","0.15035"
"190.35600","15.86324","0.15176"
"190.70400","15.89218","0.15281"
"191.05200","15.92118","0.15478"
"191.40000","15.95023","0.14891"
"191.74800","15.97917","0.15117"
"192.09600","16.00829","0.15332"
"192.44400","16.03723","0.15418"
"192.79200","16.06623","0.15463"
"193.14000","16.09522","0.15149"
"193.48800","16.12422","0.15311"
"193.83600","16.15322","0.15500"
"194.18400","16.18228","0.15443"
"194.53200","16.21121","0.15602"
"194.88000","16.24021","0.15744"
"195.22800","16.26921","0.15802"
"195.57600","16.29821","0.15989"
"195.92400","16.32715","0.16087"
"196.27200","16.35626","0.16239"
"196.62000","16.38514","0.16407"
"196.96800","16.41426","0.16629"
"197.31600","16.44320","0.16764"
"197.66400","16.47214","0.17027"
"198.01200","16.50125","0.17180"
"198.36000","16.53025","0.17187"
"198.70800","16.55919","0.17453"
"199.05600","16.58825","0.17622"
"199.40400","16.61724","0.12071"
"199.75200","16.64612","0.12047"
"200.10000","16.67524","0.12477"
"200.44800","16.70424","0.12955"
"200.79600","16.73324","0.13323"
"201.14400","16.76229","0.13505"
"201.49200","16.79117","0.13498"
"201.84000","16.82023","0.13485"
"202.18800","16.84923","0.13509"
"202.53600","16.87823","0.13775"
"202.88400","16.90717","0.14017"
"203.23200","16.93622","0.14251"
"203.58000","16.96516","0.14433"
"203.92800","16.99416","0.14483"
"204.27600","17.02328","0.14514"
"204.62400","17.05215","0.14581"
"204.97200","17.08121","0.14554"
"205.32000","17.11027","0.14786"
"205.66800","17.13921","0.14890"
"206.01600","17.16826","0.14992"
"206.36400","17.19726","0.15060"
"206.71200","17.22620","0.15250"
"207.06000","17.25526","0.15421"
"207.40800","17.28420","0.15646"
"207.75600","17.31320","0.15823"
"208.10400","17.34219","0.15826"
"208.45200","17.37125","0.15821"
"208.80000","17.40019","0.15378"
"209.14800","17.42925","0.15434"
"209.49600","17.45812","0.15520"
"209.84400","17.48724","0.15754"
"210.19200","17.51624","0.15625"
"210.54000","17.54518","0.15784"
"210.88800","17.57424","0.15788"
"211.23600","17.60323","0.15949"
"211.58400","17.63217","0.16036"
"211.93200","17.66123","0.16149"
"212.28000","17.69023","0.16291"
"212.62800","17.71923","0.16449"
"212.97600","17.74822","0.16563"
"213.32400","17.77722","0.16697"
"213.67200","17.80622","0.16822"
"214.02000","17.83522","0.16826"
"214.36800","17.86422","0.16937"
"214.71600","17.89315","0.17005"
"215.06400","17.92227","0.17199"
"215.41200","17.95115","0.17403"
"215.76000","17.98021","0.17573"
"216.10800","18.00920","0.17780"
"216.45600","18.03820","0.17825"
"216.80400","18.06726","0.17975"
"217.15200","18.09620","0.18164"
"217.50000","18.12520","0.18288"
"217.84800","18.15425","0.18433"
"218.19600","18.18319","0.18631"
"218.54400","18.21219","0.18699"
"218.89200","18.24119","0.18840"
"219.24000","18.27019","0.18992"
"219.58800","18.29918","0.19072"
"219.93600","18.32824","0.18993"
"220.28400","18.35718","0.19027"
"220.63200","18.38624","0.19163"
"220.98000","18.41524","0.19243"
"221.32800","18.44411","0.18699"
"221.67600","18.47323","0.18698"
"222.02400","18.50229","0.18778"
"222.37200","18.53117","0.18975"
"222.72000","18.56022","0.19086"
"223.06800","18.58922","0.19211"
"223.41600","18.61816","0.19369"
"223.76400","18.64728","0.19558"
"224.11200","18.67622","0.19711"
"224.46000","18.70516","0.19841"
"224.80800","18.73427","0.19962"
"225.15600","18.76321","0.19964"
"225.50400","18.79221","0.20096"
"225.85200","18.82121","0.20211"
"226.20000","18.85021","0.08247"
"226.54800","18.87920","0.08137"
"226.89600","18.90820","0.08466"
"227.24400","18.93714","0.08804"
"227.59200","18.96620","0.08982"
"227.94000","18.99525","0.09148"
"228.28800","19.02419","0.09337"
"228.63600","19.05319","0.08749"
"228.98400","19.08225","0.07959"
"229.33200","19.11113","0.08033"
"229.68000","19.14024","0.07919"
"230.02800","19.16924","0.08154"
"230.37600","19.19818","0.08377"
"230.72400","19.22724","0.08507"
"231.07200","19.25618","0.08635"
"231.42000","19.28523","0.08722"
"231.76800","19.31423","0.08958"
"232.11600","19.34323","0.09177"
"232.46400","19.37223","0.09267"
"232.81200","19.40123","0.09375"
"233.16000","19.43022","0.09480"
"233.50800","19.45922","0.09683"
"233.85600","19.48822","0.09898"
"234.20400","19.51716","0.10053"
"234.55200","19.54622","0.10213"
"234.90000","19.57527","0.10488"
"235.24800","19.60421","0.10755"
"235.59600","19.63327","0.11007"
"235.94400","19.66220","0.11244"
"236.29200","19.69120","0.11470"
"236.64000","19.72020","0.11780"
"236.98800","19.74926","0.12223"
"237.33600","19.77820","0.12637"
"237.68400","19.80726","0.12963"
"238.03200","19.83619","0.13226"
"238.38000","19.86519","0.13404"
"238.72800","19.89425","0.13665"
"239.07600","19.92319","0.13883"
"239.42400","19.95225","0.14127"
"239.77200","19.98125","0.14377"
"240.12000","20.01018","0.14646"
"240.46800","20.03924","0.14823"
"240.81600","20.06818","0.15000"
"241.16400","20.09723","0.14862"
"241.51200","20.12623","0.15071"
"241.86000","20.15517","0.08574"
"242.20800","20.18423","0.03803"
"242.55600","20.21323","0.04588"
"242.90400","20.24222","0.03820"
"243.25200","20.27116","0.03315"
"243.60000","20.30028","0.03545"
"243.94800","20.32922","0.04451"
"244.29600","20.35822","0.04990"
"244.64400","20.38728","0.05302"
"244.99200","20.41615","0.05314"
"245.34000","20.44521","0.04650"
"245.68800","20.47421","0.04553"
"246.03600","20.50315","0.05038"
"246.38400","20.53226","0.05800"
"246.73200","20.56120","0.06056"
"247.08000","20.59020","0.05833"
"247.42800","20.61926","0.05551"
"247.77600","20.64820","0.05814"
"248.12400","20.67719","0.06899"
"248.47200","20.70625","0.06711"
"248.82000","20.73519","0.06724"
"249.16800","20.76419","0.06911"
"249.51600","20.79325","0.07364"
"249.86400","20.82218","0.07900"
"250.21200","20.85124","0.07559"
"250.56000","20.88024","0.07732"
"250.90800","20.90918","0.08271"
"251.25600","20.93823","0.08057"
"251.60400","20.96723","0.08130"
"251.95200","20.99623","0.08658"
"252.30000","21.02523","0.08409"
"252.64800","21.05429","0.08554"
"252.99600","21.08323","0.09080"
"253.34400","21.11222","0.08821"
"253.69200","21.14116","0.08959"
"254.04000","21.17016","0.09450"
"254.38800","21.19921","0.09286"
"254.73600","21.22821","0.09396"
"255.08400","21.25727","0.09902"
"255.43200","21.28627","0.09790"
"255.78000","21.31515","0.09819"
"256.12800","21.34426","0.10317"
"256.47600","21.37320","0.10457"
"256.82400","21.40214","0.10410"
"257.17200","21.43120","0.10612"
"257.52000","21.46026","0.11070"
"257.86800","21.48919","0.10960"
"258.21600","21.51825","0.11150"
"258.56400","21.54725","0.11738"
"258.91200","21.57619","0.11955"
"259.26000","21.60525","0.11936"
"259.60800","21.63424","0.12362"
"259.95600","21.66318","0.13018"
"260.30400","21.69218","0.13048"
"260.65200","21.72118","0.13131"
"261.00000","21.75024","0.13400"
"261.34800","21.77924","0.13804"
"261.69600","21.80817","0.13747"
"262.04400","21.83717","0.13415"
"262.39200","21.86623","0.13746"
"262.74000","21.89523","0.14057"
"263.08800","21.92422","0.14113"
"263.43600","21.95328","0.14320"
"263.78400","21.98216","0.14661"
"264.13200","22.01128","0.14889"
"264.48000","22.04022","0.14990"
"264.82800","22.06921","0.15169"
"265.17600","22.09821","0.15373"
"265.52400","22.12721","0.08713"
"265.87200","22.15627","0.05540"
"266.22000","22.18521","0.05844"
"266.56800","22.21420","0.06229"
"266.91600","22.24326","0.06658"
"267.26400","22.27220","0.06871"
"267.61200","22.30120","0.06804"
"267.96000","22.33019","0.07056"
"268.30800","22.35925","0.07418"
"268.65600","22.38819","0.07458"
"269.00400","22.41725","0.07634"
"269.35200","22.44619","0.07685"
"269.70000","22.47518","0.07810"
"270.04800","22.50424","0.08033"
"270.39600","22.53324","0.08000"
"270.74400","22.56218","0.08081"
"271.09200","22.59130","0.08302"
"271.44000","22.62024","0.08306"
"271.78800","22.64917","0.08399"
"272.13600","22.67823","0.08372"
"272.48400","22.70717","0.08354"
"272.83200","22.73623","0.08500"
"273.18000","22.76528","0.08724"
"273.52800","22.79410","0.08737"
"273.87600","22.82328","0.08891"
"274.22400","22.85222","0.09058"
"274.57200","22.88115","0.09102"
"274.92000","22.91021","0.09241"
"275.26800","22.93921","0.09408"
"275.61600","22.96821","0.09473"
"275.96400","22.99727","0.09595"
"276.31200","23.02621","0.09855"
"276.66000","23.05520","0.09951"
"277.00800","23.08420","0.10074"
"277.35600","23.11320","0.10305"
"277.70400","23.14220","0.10527"
"278.05200","23.17125","0.10674"
"278.40000","23.20019","0.10910"
"278.74800","23.22925","0.11201"
"279.09600","23.25825","0.11304"
"279.44400","23.28713","0.11497"
"279.79200","23.31618","0.11977"
"280.14000","23.34524","0.12247"
"280.48800","23.37418","0.12458"
"280.83600","23.40324","0.12733"
"281.18400","23.43229","0.13077"
"281.53200","23.46117","0.13306"
"281.88000","23.49023","0.13443"
"282.22800","23.51923","0.13679"
"282.57600","23.54823","0.13965"
"282.92400","23.57729","0.14191"
"283.27200","23.60616","0.14372"
"283.62000","23.63522","0.14510"
"283.96800","23.66422","0.14708"
"284.31600","23.69316","0.14170"
"284.66400","23.72228","0.14134"
"285.01200","23.75121","0.14501"
"285.36000","23.78021","0.14788"
"285.70800","23.80921","0.14932"
"286.05600","23.83821","0.15088"
"286.40400","23.86720","0.15328"
"286.75200","23.89620","0.15523"
"287.10000","23.92520","0.15671"
"287.44800","23.95420","0.15836"
"287.79600","23.98320","0.16047"
"288.14400","24.01220","0.16369"
"288.49200","24.04119","0.16622"
"288.84000","24.07025","0.16831"
"289.18800","24.09919","0.16980"
"289.53600","24.12825","0.17210"
"289.88400","24.15718","0.17467"
"290.23200","24.18618","0.17719"
"290.58000","24.21524","0.17875"
"290.92800","24.24424","0.18059"
"291.27600","24.27317","0.17828"
"291.62400","24.30223","0.16236"
"291.97200","24.33123","0.16475"
"292.32000","24.36011","0.16232"
"292.66800","24.38929","0.06327"
"293.01600","24.41823","0.05691"
"293.36400","24.44722","0.04922"
"293.71200","24.47628","0.04986"
"294.06000","24.50522","0.04847"
"294.40800","24.53422","0.04640"
"294.75600","24.56321","0.04665"
"295.10400","24.59221","0.04797"
"295.45200","24.62121","0.04915"
"295.80000","24.65021","0.05011"
"296.14800","24.67921","0.05064"
"296.49600","24.70815","0.05111"
"296.84400","24.73726","0.05168"
"297.19200","24.76614","0.05302"
"297.54000","24.79526","0.05339"
"297.88800","24.82425","0.05420"
"298.23600","24.85313","0.05543"
"298.58400","24.88225","0.05477"
"298.93200","24.91119","0.05552"
"299.28000","24.94019","0.05582"
"299.62800","24.96931","0.05748"
"299.97600","24.99824","0.05804"
"300.32400","25.02718","0.05916"
"300.67200","25.05624","0.05933"
"301.02000","25.08517","0.05961"
"301.36800","25.11418","0.05940"
"301.71600","25.14329","0.06009"
"302.06400","25.17217","0.06155"
"302.41200","25.20123","0.06228"
"302.76000","25.23023","0.06306"
"303.10800","25.25916","0.06412"
"303.45600","25.28816","0.06401"
"303.80400","25.31722","0.06612"
"304.15200","25.34622","0.06717"
"304.50000","25.37522","0.01511"
"304.84800","25.40421","0.01242"
"305.19600","25.43321","0.00915"
"305.54400","25.46221","0.01102"
"305.89200","25.49121","0.01408"
"306.24000","25.52021","0.01505"
"306.58800","25.54926","0.01309"
"306.93600","25.57820","0.01271"
"307.28400","25.60720","0.01315"
"307.63200","25.63626","0.01469"
"307.98000","25.66514","0.01547"
"308.32800","25.69425","0.01624"
"308.67600","25.72325","0.01622"
"309.02400","25.75219","0.01604"
"309.37200","25.78125","0.01642"
"309.72000","25.81025","0.01745"
"310.06800","25.83924","0.01801"
"310.41600","25.86824","0.01771"
"310.76400","25.89718","0.01776"
"311.11200","25.92618","0.01765"
"311.46000","25.95523","0.01897"
"311.80800","25.98417","0.01884"
"312.15600","26.01323","0.01912"
"312.50400","26.04223","0.01953"
"312.85200","26.07117","0.02033"
"313.20000","26.10022","0.02022"
"313.54800","26.12922","0.02069"
"313.89600","26.15816","0.02146"
"314.24400","26.18722","0.02158"
"314.59200","26.21622","0.02174"
"314.94000","26.24516","0.02158"
"315.28800","26.27421","0.02189"
"315.63600","26.30333","0.02175"
"315.98400","26.33215","0.02187"
"316.33200","26.36127","0.02228"
"316.68000","26.39026","0.02315"
"317.02800","26.41920","0.02259"
"317.37600","26.44826","0.02126"
"317.72400","26.47714","0.02173"
"318.07200","26.50620","0.02147"
"318.42000","26.53519","0.02136"
"318.76800","26.56419","0.02219"
"319.11600","26.59325","0.02254"
"319.46400","26.62219","0.02329"
"319.81200","26.65118","0.02351"
"320.16000","26.68024","0.02381"
"320.50800","26.70924","0.02447"
"320.85600","26.73818","0.02369"
"321.20400","26.76723","0.02345"
"321.55200","26.79629","0.02432"
"321.90000","26.82517","0.01995"
"322.24800","26.85423","0.01904"
"322.59600","26.88323","0.02018"
"322.94400","26.91223","0.02028"
"323.29200","26.94123","0.02085"
"323.64000","26.97022","0.02077"
"323.98800","26.99922","0.02119"
"324.33600","27.02822","0.02126"
"324.68400","27.05721","0.02220"
"325.03200","27.08621","0.02188"
"325.38000","27.11527","0.02211"
"325.72800","27.14415","0.02243"
"326.07600","27.17321","0.02225"
"326.42400","27.20226","0.02298"
"326.77200","27.23114","0.02354"
"327.12000","27.26026","0.02327"
"327.46800","27.28926","0.02289"
"327.81600","27.31820","0.02275"
"328.16400","27.34725","0.02328"
"328.51200","27.37619","0.02311"
"328.86000","27.40519","0.02324"
"329.20800","27.43419","0.02314"
"329.55600","27.46325","0.02309"
"329.90400","27.49224","0.02450"
"330.25200","27.52124","0.02452"
"330.60000","27.55018","0.02455"
"330.94800","27.57918","0.02494"
"331.29600","27.60824","0.02575"
"331.64400","27.63717","0.02524"
"331.99200","27.66623","0.02576"
"332.34000","27.69523","0.02642"
"332.68800","27.72417","0.02648"
"333.03600","27.75323","0.02618"
"333.38400","27.78222","0.02633"
"333.73200","27.81116","0.02659"
"334.08000","27.84022","0.02691"
"334.42800","27.86922","0.02730"
"334.77600","27.89816","0.02751"
"335.12400","27.92721","0.02798"
"335.47200","27.95621","0.02809"
"335.82000","27.98521","0.02877"
"336.16800","28.01421","0.02886"
"336.51600","28.04315","0.02889"
"336.86400","28.07226","0.02921"
"337.21200","28.10120","0.02943"
"337.56000","28.13014","0.03013"
"337.90800","28.15926","0.03011"
"338.25600","28.18819","0.03108"
"338.60400","28.21719","0.03097"
"338.95200","28.24625","0.03152"
"339.30000","28.27525","0.03166"
"339.64800","28.30419","0.03181"
"339.99600","28.33324","0.03201"
"340.34400","28.36224","0.03253"
"340.69200","28.39118","0.03272"
"341.04000","28.42024","0.03124"
"341.38800","28.44924","0.02997"
"341.73600","28.47823","0.02960"
"342.08400","28.50723","0.03108"
"342.43200","28.53617","0.03150"
"342.78000","28.56523","0.03152"
"343.12800","28.59429","0.03273"
"343.47600","28.62316","0.03345"
"343.82400","28.65222","0.03439"
"344.17200","28.68122","0.03438"
"344.52000","28.71016","0.03456"
"344.86800","28.73922","0.03489"
"345.21600","28.76821","0.03558"
"345.56400","28.79715","0.03561"
"345.91200","28.82627","0.03656"
"346.26000","28.85521","0.03717"
"346.60800","28.88421","0.03759"
"346.95600","28.91320","0.03841"
"347.30400","28.94226","0.03884"
"347.65200","28.97126","0.03952"
"348.00000","29.00019","0.04066"
"348.34800","29.02919","0.04107"
"348.69600","29.05819","0.04162"
"349.04400","29.08719","0.04206"
"349.39200","29.11619","0.04267"
"349.74000","29.14519","0.04314"
"350.08800","29.17430","0.04397"
"350.43600","29.20312","0.04397"
"350.78400","29.23224","0.04502"
"351.13200","29.26124","0.04549"
"351.48000","29.29018","0.04670"
"351.82800","29.31923","0.04752"
"352.17600","29.34817","0.04714"
"352.52400","29.37717","0.04811"
"352.87200","29.40623","0.04843"
"353.22000","29.43522","0.04875"
"353.56800","29.46422","0.04897"
"353.91600","29.49322","0.04993"
"354.26400","29.52222","0.05067"
"354.61200","29.55122","0.05097"
"354.96000","29.58027","0.05117"
"355.30800","29.60915","0.05098"
"355.65600","29.63821","0.03654"
"356.00400","29.66721","0.03466"
"356.35200","29.69615","0.03530"
"356.70000","29.72520","0.03788"
"357.04800","29.75420","0.03900"
"357.39600","29.78320","0.03940"
"357.74400","29.81226","0.03887"
"358.09200","29.84126","0.03987"
"358.44000","29.87020","0.04108"
"358.78800","29.89919","0.04172"
"359.13600","29.92825","0.04198"
"359.48400","29.95719","0.04230"
"359.83200","29.98624","0.04233"
"360.18000","30.01518","0.04255"
"360.52800","30.04424","0.04305"
"360.87600","30.07324","0.04334"
"361.22400","30.10212","0.04402"
"361.57200","30.13129","0.04464"
"361.92000","30.16023","0.04512"
"362.26800","30.18923","0.04557"
"362.61600","30.21823","0.04651"
"362.96400","30.24723","0.04467"
"363.31200","30.27617","0.04576"
"363.66000","30.30522","0.04571"
"364.00800","30.33416","0.04695"
"364.35600","30.36322","0.04628"
"364.70400","30.39228","0.04782"
"365.05200","30.42122","0.04864"
"365.40000","30.45021","0.04961"
"365.74800","30.47927","0.05018"
"366.09600","30.50821","0.05036"
"366.44400","30.53727","0.05090"
"366.79200","30.56626","0.05191"
"367.14000","30.59520","0.05256"
"367.48800","30.62426","0.05287"
"367.83600","30.65326","0.05357"
"368.18400","30.68213","0.05340"
"368.53200","30.71119","0.05435"
"368.88000","30.74025","0.05544"
"369.22800","30.76919","0.05577"
"369.57600","30.79825","0.05658"
"369.92400","30.82719","0.05639"
"370.27200","30.85618","0.05566"
"370.62000","30.88524","0.05611"
"370.96800","30.91418","0.05734"
"371.31600","30.94324","0.05748"
"371.66400","30.97218","0.05750"
"372.01200","31.00111","0.05874"
"372.36000","31.03023","0.05909"
"372.70800","31.05923","0.05987"
"373.05600","31.08823","0.06034"
"373.40400","31.11722","0.06118"
"373.75200","31.14628","0.06228"
"374.10000","31.17516","0.06329"
"374.44800","31.20422","0.06401"
"374.79600","31.23322","0.06496"
"375.14400","31.26215","0.06568"
"375.49200","31.29121","0.06716"
"375.84000","31.32027","0.06837"
"376.18800","31.34921","0.06918"
"376.53600","31.37820","0.07045"
"376.88400","31.40714","0.07132"
"377.23200","31.43620","0.07269"
"377.58000","31.46520","0.07233"
"377.92800","31.49420","0.07296"
"378.27600","31.52319","0.07373"
"378.62400","31.55225","0.07451"
"378.97200","31.58119","0.07580"
"379.32000","31.61025","0.07612"
"379.66800","31.63924","0.07706"
"380.01600","31.66818","0.07783"
"380.36400","31.69724","0.07815"
"380.71200","31.72624","0.07868"
"381.06000","31.75524","0.07880"
"381.40800","31.78424","0.07729"
"381.75600","31.81318","0.07002"
"382.10400","31.84223","0.06754"
"382.45200","31.87117","0.06609"
"382.80000","31.90023","0.06695"
"383.14800","31.92916","0.06856"
"383.49600","31.95822","0.06741"
"383.84400","31.98716","0.06985"
"384.19200","32.01622","0.07088"
"384.54000","32.04528","0.07146"
"384.88800","32.07415","0.07109"
"385.23600","32.10327","0.07102"
"385.58400","32.13221","0.07243"
"385.93200","32.16115","0.07301"
"386.28000","32.19027","0.07451"
"386.62800","32.21920","0.07512"
"386.97600","32.24820","0.07507"
"387.32400","32.27726","0.07512"
"387.67200","32.30626","0.07600"
"388.02000","32.33520","0.07635"
"388.36800","32.36419","0.07672"
"388.71600","32.39319","0.07718"
"389.06400","32.42225","0.07704"
"389.41200","32.45124","0.07809"
"389.76000","32.48013","0.07819"
"390.10800","32.50924","0.07821"
"390.45600","32.53824","0.07824"
"390.80400","32.56718","0.07888"
"391.15200","32.59624","0.07889"
"391.50000","32.62518","0.06625"
"391.84800","32.65423","0.06106"
"392.19600","32.68323","0.06055"
"392.54400","32.71223","0.06200"
"392.89200","32.74123","0.06298"
"393.24000","32.77023","0.06394"
"393.58800","32.79922","0.06572"
"393.93600","32.82816","0.06657"
"394.28400","32.85728","0.06881"
"394.63200","32.88610","0.06938"
"394.98000","32.91527","0.07014"
"395.32800","32.94421","0.07158"
"395.67600","32.97315","0.07270"
"396.02400","33.00221","0.07354"
"396.37200","33.03127","0.07446"
"396.72000","33.06020","0.07496"
"397.06800","33.08926","0.07587"
"397.41600","33.11826","0.07610"
"397.76400","33.14714","0.07654"
"398.11200","33.17619","0.07738"
"398.46000","33.20519","0.07738"
"398.80800","33.23419","0.07808"
"399.15600","33.26325","0.07866"
"399.50400","33.29219","0.07812"
"399.85200","33.32118","0.07893"
"400.20000","33.35024","0.07944"
"400.54800","33.37924","0.07981"
"400.89600","33.40824","0.08029"
"401.24400","33.43724","0.08087"
"401.59200","33.46618","0.08075"
"401.94000","33.49523","0.01576"
"402.28800","33.52423","-0.00048"
"402.63600","33.55311","0.00355"
"402.98400","33.58223","-0.00101"
"403.33200","33.61128","0.00577"
"403.68000","33.64022","-0.00039"
"404.02800","33.66922","0.00468"
"404.37600","33.69816","0.00128"
"404.72400","33.72715","0.00518"
"405.07200","33.75628","0.00086"
"405.42000","33.78515","0.00756"
"405.76800","33.81427","-0.00017"
"406.11600","33.84321","0.00551"
"406.46400","33.87221","0.00233"
"406.81200","33.90120","0.00051"
"407.16000","33.93020","0.00784"
"407.50800","33.95920","0.00060"
"407.85600","33.98820","0.00390"
"408.20400","34.01725","0.00392"
"408.55200","34.04619","0.00147"
"408.90000","34.07525","0.00572"
"409.24800","34.10425","0.00323"
"409.59600","34.13319","0.00296"
"409.94400","34.16225","0.00456"
"410.29200","34.19118","0.00268"
"410.64000","34.22018","0.00358"
"410.98800","34.24924","0.00478"
"411.33600","34.27824","0.00345"
"411.68400","34.30724","0.00422"
"412.03200","34.33623","0.00397"
"412.38000","34.36523","0.00430"
"412.72800","34.39417","0.00497"
"413.07600","34.42323","0.00304"
"413.42400","34.45216","0.00477"
"413.77200","34.48122","0.00477"
"414.12000","34.51022","0.00344"
"414.46800","34.53915","0.00556"
"414.81600","34.56828","0.00525"
"415.16400","34.59721","0.00436"
"415.51200","34.62621","0.00512"
"415.86000","34.65521","0.00456"
"416.20800","34.68421","0.00486"
"416.55600","34.71320","0.00534"
"416.90400","34.74220","0.00468"
"417.25200","34.77114","0.00564"
"417.60000","34.80014","0.00527"
"417.94800","34.82925","0.00438"
"418.29600","34.85819","0.00595"
"418.64400","34.88719","0.00608"
"418.99200","34.91625","0.00469"
"419.34000","34.94513","0.00603"
"419.68800","34.97425","0.00586"
"420.03600","35.00325","0.00531"
"420.38400","35.03218","0.00606"
"420.73200","35.06124","0.00588"
"421.08000","35.09018","0.00549"
"421.42800","35.11917","0.00638"
"421.77600","35.14823","0.00641"
"422.12400","35.17723","0.00616"
"422.47200","35.20617","0.00635"
"422.82000","35.23529","0.00671"
"423.16800","35.26416","0.00596"
"423.51600","35.29322","0.00714"
"423.86400","35.32228","0.00677"
"424.21200","35.35116","0.00615"
"424.56000","35.38022","0.00706"
"424.90800","35.40928","0.00728"
"425.25600","35.43815","0.00653"
"425.60400","35.46721","0.00757"
"425.95200","35.49621","0.00803"
"426.30000","35.52521","0.00715"
"426.64800","35.55426","0.00724"
"426.99600","35.58326","0.00801"
"427.34400","35.61220","0.00757"
"427.69200","35.64126","0.00834"
"428.04000","35.67020","0.00907"
"428.38800","35.69919","0.00825"
"428.73600","35.72825","0.00828"
"429.08400","35.75713","0.00890"
"429.43200","35.78625","0.00901"
"429.78000","35.81519","0.00875"
"430.12800","35.84418","0.00906"
"430.47600","35.87324","0.00939"
"430.82400","35.90224","0.00890"
"431.17200","35.93124","0.00971"
"431.52000","35.96024","0.01026"
"431.86800","35.98923","0.00963"
"432.21600","36.01817","0.00938"
"432.56400","36.04723","0.01035"
"432.91200","36.07623","0.01022"
"433.26000","36.10516","0.01033"
"433.60800","36.13428","0.01024"
"433.95600","36.16316","0.01087"
"434.30400","36.19222","0.01078"
"434.65200","36.22122","0.01075"
"435.00000","36.25021","0.01144"
"435.34800","36.27921","0.01167"
"435.69600","36.30821","0.01147"
"436.04400","36.33721","0.01115"
"436.39200","36.36626","0.01205"
"436.74000","36.39526","0.01205"
"437.08800","36.42414","0.01186"
"437.43600","36.45326","0.01317"
"437.78400","36.48225","0.01311"
"438.13200","36.51120","0.01328"
"438.48000","36.54026","0.01312"
"438.82800","36.56919","0.01286"
"439.17600","36.59819","0.01361"
"439.52400","36.62725","0.01400"
"439.87200","36.65619","0.01436"
"440.22000","36.68518","0.01470"
"440.56800","36.71418","0.01456"
"440.91600","36.74324","0.01534"
"441.26400","36.77224","0.01561"
"441.61200","36.80124","0.01551"
"441.96000","36.83023","0.01580"
"442.30800","36.85923","0.01615"
"442.65600","36.88829","0.01665"
"443.00400","36.91711","0.01173"
"443.35200","36.94622","0.01173"
"443.70000","36.97522","0.00751"
"444.04800","37.00416","0.00898"
"444.39600","37.03328","0.00975"
"444.74400","37.06227","0.00726"
"445.09200","37.09116","0.00956"
"445.44000","37.12027","0.00913"
"445.78800","37.14921","0.00835"
"446.13600","37.17821","0.00948"
"446.48400","37.20726","0.00950"
"446.83200","37.23620","0.00827"
"447.18000","37.26514","0.01004"
"447.52800","37.29426","0.01039"
"447.87600","37.32320","0.00943"
"448.22400","37.35226","0.00968"
"448.57200","37.38120","0.01006"
"448.92000","37.41019","0.00966"
"449.26800","37.43925","0.01064"
"449.61600","37.46825","0.01037"
"449.96400","37.49718","0.01019"
"450.31200","37.52618","0.01063"
"450.66000","37.55524","0.01016"
"451.00800","37.58418","0.01059"
"451.35600","37.61324","0.01109"
"451.70400","37.64217","0.01148"
"452.05200","37.67117","0.01069"
"452.40000","37.70029","0.01113"
"452.74800","37.72923","0.01153"
"453.09600","37.75823","0.01129"
"453.44400","37.78722","0.01194"
"453.79200","37.81616","0.01166"
"454.14000","37.84522","0.01180"
"454.48800","37.87422","0.01239"
"454.83600","37.90322","0.01264"
"455.18400","37.93221","0.01297"
"455.53200","37.96121","0.01310"
"455.88000","37.99015","0.01308"
"456.22800","38.01921","0.01358"
"456.57600","38.04826","0.01403"
"456.92400","38.07720","0.01394"
"457.27200","38.10620","0.01410"
"457.62000","38.13520","0.01456"
"457.96800","38.16420","0.01419"
"458.31600","38.19320","0.01453"
"458.66400","38.22213","0.01501"
"459.01200","38.25119","0.01534"
"459.36000","38.28019","0.01511"
"459.70800","38.30919","0.01540"
"460.05600","38.33812","0.01545"
"460.40400","38.36724","0.01569"
"460.75200","38.39618","0.01674"
"461.10000","38.42524","0.01705"
"461.44800","38.45424","0.01672"
"461.79600","38.48317","0.01695"
"462.14400","38.51223","0.01745"
"462.49200","38.54123","0.01752"
"462.84000","38.57017","0.01810"
"463.18800","38.59929","0.01797"
"463.53600","38.62817","0.01886"
"463.88400","38.65722","0.01841"
"464.23200","38.68616","0.01909"
"464.58000","38.71516","0.01922"
"464.92800","38.74421","0.01967"
"465.27600","38.77327","0.01927"
"465.62400","38.80221","0.01993"
"465.97200","38.83121","0.01977"
"466.32000","38.86021","0.01952"
"466.66800","38.88915","0.02046"
"467.01600","38.91826","0.02030"
"467.36400","38.94720","0.02048"
"467.71200","38.97620","0.02089"
"468.06000","39.00520","0.02040"
"468.40800","39.03426","0.02103"
"468.75600","39.06319","0.02134"
"469.10400","39.09219","0.02129"
"469.45200","39.12119","0.02193"
"469.80000","39.15018","0.02229"
"470.14800","39.17924","0.02153"
"470.49600","39.20818","0.02221"
"470.84400","39.23718","0.02274"
"471.19200","39.26624","0.02279"
"471.54000","39.29512","0.02322"
"471.88800","39.32423","0.02325"
"472.23600","39.35329","0.02376"
"472.58400","39.38217","0.02420"
"472.93200","39.41123","0.02411"
"473.28000","39.44017","0.02439"
"473.62800","39.46916","0.02495"
"473.97600","39.49828","0.02539"
"474.32400","39.52721","0.02527"
"474.67200","39.55616","0.02581"
"475.02000","39.58521","0.02643"
"475.36800","39.61427","0.02620"
"475.71600","39.64321","0.02673"
"476.06400","39.67221","0.02659"
"476.41200","39.70121","0.02720"
"476.76000","39.73021","0.02746"
"477.10800","39.75926","0.02767"
"477.45600","39.78814","0.02758"
"477.80400","39.81720","0.00171"
"478.15200","39.84626","0.00107"
"478.50000","39.87519","-0.00088"
"478.84800","39.90425","-0.00109"
"479.19600","39.93325","-0.00054"
"479.54400","39.96219","-0.00047"
"479.89200","39.99125","-0.00068"
"480.24000","40.02018","-0.00082"
"480.58800","40.04918","-0.00024"
"480.93600","40.07830","-0.00001"
"481.28400","40.10718","-0.00077"
"481.63200","40.13617","-0.00041"
"481.98000","40.16523","-0.00073"
"482.32800","40.19417","0.00031"
"482.67600","40.22329","-0.00042"
"483.02400","40.25223","-0.00092"
"483.37200","40.28116","-0.00068"
"483.72000","40.31022","-0.00042"
"484.06800","40.33922","-0.00063"
"484.41600","40.36816","-0.00054"
"484.76400","40.39722","-0.00035"
"485.11200","40.42621","-0.00040"
"485.46000","40.45522","-0.00092"
"485.80800","40.48427","-0.00033"
"486.15600","40.51321","-0.00006"
"486.50400","40.54221","-0.00074"
"486.85200","40.57121","-0.00080"
"487.20000","40.60020","-0.00045"
"487.54800","40.62920","0.00016"
"487.89600","40.65826","-0.00065"
"488.24400","40.68714","-0.00083"
"488.59200","40.71625","-0.00016"
"488.94000","40.74525","-0.00056"
"489.28800","40.77412","-0.00076"
"489.63600","40.80325","-0.00034"
"489.98400","40.83224","0.00027"
"490.33200","40.86119","-0.00041"
"490.68000","40.89024","-0.00081"
"491.02800","40.91924","-0.00065"
"491.37600","40.94817","0.00005"
"491.72400","40.97723","-0.00058"
"492.07200","41.00617","-0.00030"
"492.42000","41.03523","-0.00034"
"492.76800","41.06423","-0.00030"
"493.11600","41.09323","-0.00082"
"493.46400","41.12222","-0.00072"
"493.81200","41.15122","0.00004"
"494.16000","41.18022","-0.00031"
"494.50800","41.20922","-0.00001"
"494.85600","41.23828","-0.00069"
"495.20400","41.26716","0.00045"
"495.55200","41.29627","-0.00032"
"495.90000","41.32527","-0.00065"
"496.24800","41.35415","-0.00032"
"496.59600","41.38321","-0.00024"
"496.94400","41.41227","-0.00047"
"497.29200","41.44114","-0.00091"
"497.64000","41.47020","0.00001"
"497.98800","41.49920","-0.00073"
"498.33600","41.52819","-0.00067"
"498.68400","41.55719","-0.00021"
"499.03200","41.58625","0.00038"
"499.38000","41.61518","-0.00014"
"499.72800","41.64425","-0.00064"
"500.07600","41.67319","-0.00012"
"500.42400","41.70224","-0.00072"
"500.77200","41.73124","-0.00039"
"501.12000","41.76012","-0.00027"
"501.46800","41.78923","0.00096"
"501.81600","41.81823","-0.00036"
"502.16400","41.84717","-0.00038"
"502.51200","41.87623","0.00018"
"502.86000","41.90523","0.00010"
"503.20800","41.93416","-0.00038"
"503.55600","41.96322","-0.00055"
"503.90400","41.99222","0.00115"
"504.25200","42.02116","-0.00026"
"504.60000","42.05022","-0.00040"
"504.94800","42.07922","-0.00015"
"505.29600","42.10822","0.00028"
"505.64400","42.13727","-0.00059"
"505.99200","42.16615","-0.00063"
"506.34000","42.19521","0.00169"
"506.68800","42.22427","-0.00044"
"507.03600","42.25320","-0.00069"
"507.38400","42.28226","0.00081"
"507.73200","42.31120","0.00040"
"508.08000","42.34020","-0.00030"
"508.42800","42.36926","0.00024"
"508.77600","42.39825","0.00103"
"509.12400","42.42719","-0.00008"
"509.47200","42.45619","-0.00069"
"509.82000","42.48519","0.00148"
"510.16800","42.51424","-0.00011"
"510.51600","42.54324","-0.00036"
"510.86400","42.57218","0.00075"
"511.21200","42.60123","0.00044"
"511.56000","42.63023","-0.00024"
"511.90800","42.65918","-0.00002"
"512.25600","42.68823","0.00127"
"512.60400","42.71723","0.00009"
"512.95200","42.74622","-0.00012"
"513.30000","42.77522","0.00212"
"513.64800","42.80422","0.00041"
"513.99600","42.83323","0.00028"
"514.34400","42.86222","0.00186"
"514.69200","42.89122","0.00058"
"515.04000","42.92015","0.00027"
"515.38800","42.94928","0.00158"
"515.73600","42.97821","0.00037"
"516.05600","43.00488","0.00081"