File: Force_trajectories/170107_2/Specimen_RawData_2.csv
End date,"1/7/2017"
Specimen label,"17DG_39"
Maximum Load,"0.72575",N

Time,Extension,Load
(s),(mm),(N)
"0.00000","30.39048","0.00941"
"0.37200","30.42151","0.00946"
"0.74400","30.45272","0.00930"
"1.11600","30.48363","0.00962"
"1.48800","30.51467","0.00997"
"1.86000","30.54564","0.00982"
"2.23200","30.57667","0.00951"
"2.60400","30.60764","0.00989"
"2.97600","30.63867","0.00965"
"3.34800","30.66958","0.00998"
"3.72000","30.70061","0.00968"
"4.09200","30.73170","0.00975"
"4.46400","30.76261","0.00960"
"4.83600","30.79358","0.00993"
"5.20800","30.82467","0.00971"
"5.58000","30.85559","0.00900"
"5.95200","30.88661","0.01025"
"6.32400","30.91759","0.01004"
"6.69600","30.94862","0.01008"
"7.06800","30.97965","0.01030"
"7.44000","31.01062","0.01060"
"7.81200","31.04171","0.01036"
"8.18400","31.07256","0.01022"
"8.55600","31.10359","0.01010"
"8.92800","31.13468","0.01020"
"9.30000","31.16566","0.01016"
"9.67200","31.19662","0.01025"
"10.04400","31.22760","0.01092"
"10.41600","31.25862","0.01015"
"10.78800","31.28960","0.01036"
"11.16000","31.32069","0.00997"
"11.53200","31.35166","0.01036"
"11.90400","31.38257","0.01069"
"12.27600","31.41360","0.01088"
"12.64800","31.44457","0.01115"
"13.02000","31.47560","0.01141"
"13.39200","31.50663","0.01068"
"13.76400","31.53766","0.01077"
"14.13600","31.56870","0.01083"
"14.50800","31.59960","0.01099"
"14.88000","31.63063","0.01043"
"15.25200","31.66167","0.01069"
"15.62400","31.69252","0.01109"
"15.99600","31.72367","0.01048"
"16.36800","31.75470","0.01090"
"16.74000","31.78561","0.01092"
"17.11200","31.81658","0.01137"
"17.48400","31.84761","0.01103"
"17.85600","31.87864","0.01122"
"18.22800","31.90961","0.01104"
"18.60000","31.94064","0.01121"
"18.97200","31.97161","0.01120"
"19.34400","32.00259","0.01120"
"19.71600","32.03368","0.01138"
"20.08800","32.06465","0.01125"
"20.46000","32.09562","0.01120"
"20.83200","32.12659","0.01074"
"21.20400","32.15762","0.01215"
"21.57600","32.18865","0.01117"
"21.94800","32.21962","0.01133"
"22.32000","32.25065","0.01162"
"22.69200","32.28162","0.01191"
"23.06400","32.31260","0.01131"
"23.43600","32.34363","0.01131"
"23.80800","32.37466","0.01157"
"24.18000","32.40557","0.01219"
"24.55200","32.43666","0.01129"
"24.92400","32.46769","0.01207"
"25.29600","32.49860","0.01190"
"25.66800","32.52957","0.01175"
"26.04000","32.56066","0.01187"
"26.41200","32.59158","0.01181"
"26.78400","32.62260","0.01210"
"27.15600","32.65363","0.01173"
"27.52800","32.68460","0.01155"
"27.90000","32.71558","0.01223"
"28.27200","32.74667","0.01185"
"28.64400","32.77764","0.01197"
"29.01600","32.80861","0.01147"
"29.38800","32.83964","0.01237"
"29.76000","32.87067","0.01227"
"30.13200","32.90164","0.01236"
"30.50400","32.93261","0.01281"
"30.87600","32.96358","0.01209"
"31.24800","32.99461","0.01222"
"31.62000","33.02565","0.01295"
"31.99200","33.05667","0.01269"
"32.36400","33.08765","0.01260"
"32.73600","33.11856","0.01294"
"33.10800","33.14959","0.01259"
"33.48000","33.18068","0.01282"
"33.85200","33.21159","0.01276"
"34.22400","33.24268","0.01243"
"34.59600","33.27359","0.01281"
"34.96800","33.30457","0.01342"
"35.34000","33.33565","0.01344"
"35.71200","33.36668","0.01311"
"36.08400","33.39759","0.01295"
"36.45600","33.42863","0.01300"
"36.82800","33.45966","0.01307"
"37.20000","33.49063","0.01300"
"37.57200","33.52160","0.01366"
"37.94400","33.55269","0.01288"
"38.31600","33.58360","0.01316"
"38.68800","33.61457","0.01306"
"39.06000","33.64566","0.01329"
"39.43200","33.67663","0.01325"
"39.80400","33.70754","0.01302"
"40.17600","33.73864","0.01311"
"40.54800","33.76973","0.01363"
"40.92000","33.80052","0.01389"
"41.29200","33.83161","0.01378"
"41.66400","33.86270","0.01350"
"42.03600","33.89361","0.01367"
"42.40800","33.92464","0.01352"
"42.78000","33.95561","0.01364"
"43.15200","33.98658","0.01343"
"43.52400","34.01762","0.01281"
"43.89600","34.04864","0.01398"
"44.26800","34.07967","0.01332"
"44.64000","34.11059","0.01338"
"45.01200","34.14162","0.01390"
"45.38400","34.17271","0.01385"
"45.75600","34.20356","0.01359"
"46.12800","34.23465","0.01356"
"46.50000","34.26562","0.01385"
"46.87200","34.29659","0.01407"
"47.24400","34.32762","0.01434"
"47.61600","34.35859","0.01444"
"47.98800","34.38962","0.01438"
"48.36000","34.42059","0.01392"
"48.73200","34.45169","0.01415"
"49.10400","34.48266","0.01422"
"49.47600","34.51357","0.01426"
"49.84800","34.54466","0.01487"
"50.22000","34.57563","0.01434"
"50.59200","34.60654","0.01456"
"50.96400","34.63763","0.01457"
"51.33600","34.66860","0.01449"
"51.70800","34.69963","0.01462"
"52.08000","34.73060","0.01537"
"52.45200","34.76163","0.01422"
"52.82400","34.79266","0.01491"
"53.19600","34.82364","0.01530"
"53.56800","34.85466","0.01470"
"53.94000","34.88564","0.01480"
"54.31200","34.91661","0.01541"
"54.68400","34.94764","0.01876"
"55.05600","34.97867","0.01297"
"55.42800","35.00958","0.01139"
"55.80000","35.04062","0.01343"
"56.17200","35.07164","0.01515"
"56.54400","35.10255","0.01585"
"56.91600","35.13364","0.01521"
"57.28800","35.16468","0.01565"
"57.66000","35.19559","0.01466"
"58.03200","35.22662","0.01405"
"58.40400","35.25765","0.01511"
"58.77600","35.28862","0.01681"
"59.14800","35.31959","0.01773"
"59.52000","35.35062","0.01671"
"59.89200","35.38165","0.01538"
"60.26400","35.41262","0.01525"
"60.63600","35.44365","0.01209"
"61.00800","35.47462","0.00636"
"61.38000","35.50560","0.00631"
"61.75200","35.53662","0.00614"
"62.12400","35.56760","0.00653"
"62.49600","35.59863","0.00624"
"62.86800","35.62966","0.00643"
"63.24000","35.66063","0.00655"
"63.61200","35.69160","0.00600"
"63.98400","35.72263","0.00624"
"64.35600","35.75360","0.00577"
"64.72800","35.78463","0.00595"
"65.10000","35.81561","0.00632"
"65.47200","35.84663","0.00629"
"65.84400","35.87767","0.00608"
"66.21600","35.90858","0.00642"
"66.58800","35.93955","0.00663"
"66.96000","35.97064","0.00684"
"67.33200","36.00161","0.00663"
"67.70400","36.03264","0.00670"
"68.07600","36.06367","0.00634"
"68.44800","36.09459","0.00593"
"68.82000","36.12561","0.00632"
"69.19200","36.15664","0.00652"
"69.56400","36.18768","0.00610"
"69.93600","36.21859","0.00673"
"70.30800","36.24961","0.00640"
"70.68000","36.28071","0.00618"
"71.05200","36.31156","0.00649"
"71.42400","36.34259","0.00613"
"71.79600","36.37362","0.00601"
"72.16800","36.40459","0.00613"
"72.54000","36.43568","0.00601"
"72.91200","36.46666","0.00636"
"73.28400","36.49762","0.00595"
"73.65600","36.52859","0.00658"
"74.02800","36.55968","0.00643"
"74.40000","36.59066","0.00581"
"74.77200","36.62157","0.00607"
"75.14400","36.65266","0.00643"
"75.51600","36.68363","0.00654"
"75.88800","36.71460","0.00667"
"76.26000","36.74569","0.00687"
"76.63200","36.77666","0.00639"
"77.00400","36.80763","0.00636"
"77.37600","36.83860","0.00643"
"77.74800","36.86963","0.00672"
"78.12000","36.90067","0.00671"
"78.49200","36.93158","0.00657"
"78.86400","36.96267","0.00649"
"79.23600","36.99364","0.00628"
"79.60800","37.02461","0.00641"
"79.98000","37.05564","0.00599"
"80.35200","37.08667","0.00670"
"80.72400","37.11764","0.00683"
"81.09600","37.14861","0.00585"
"81.46800","37.17964","0.00697"
"81.84000","37.21061","0.00643"
"82.21200","37.24153","0.00674"
"82.58400","37.27268","0.00624"
"82.95600","37.30365","0.00647"
"83.32800","37.33462","0.00619"
"83.70000","37.36565","0.00630"
"84.07200","37.39662","0.00678"
"84.44400","37.42759","0.00678"
"84.81600","37.45862","0.00655"
"85.18800","37.48965","0.00651"
"85.56000","37.52062","0.00713"
"85.93200","37.55159","0.00672"
"86.30400","37.58268","0.00635"
"86.67600","37.61360","0.00671"
"87.04800","37.64462","0.00678"
"87.42000","37.67560","0.00659"
"87.79200","37.70663","0.00659"
"88.16400","37.73766","0.00653"
"88.53600","37.76863","0.00686"
"88.90800","37.79960","0.00663"
"89.28000","37.83057","0.00686"
"89.65200","37.86160","0.00691"
"90.02400","37.89269","0.00680"
"90.39600","37.92360","0.00657"
"90.76800","37.95464","0.00702"
"91.14000","37.98567","0.00670"
"91.51200","38.01657","0.00664"
"91.88400","38.04767","0.00637"
"92.25600","38.07864","0.00719"
"92.62800","38.10961","0.00704"
"93.00000","38.14058","0.00664"
"93.37200","38.17167","0.00682"
"93.74400","38.20264","0.00666"
"94.11600","38.23355","0.00623"
"94.48800","38.26464","0.00671"
"94.86000","38.29556","0.00635"
"95.23200","38.32659","0.00655"
"95.60400","38.35767","0.00625"
"95.97600","38.38865","0.00666"
"96.34800","38.41962","0.00641"
"96.72000","38.45065","0.00658"
"97.09200","38.48162","0.00619"
"97.46400","38.51259","0.00638"
"97.83600","38.54362","0.00654"
"98.20800","38.57471","0.00698"
"98.58000","38.60562","0.00617"
"98.95200","38.63660","0.00650"
"99.32400","38.66763","0.00651"
"99.69600","38.69865","0.00600"
"100.06800","38.72957","0.00671"
"100.44000","38.76066","0.00615"
"100.81200","38.79169","0.00635"
"101.18400","38.82254","0.00661"
"101.55600","38.85363","0.00649"
"101.92800","38.88472","0.00643"
"102.30000","38.91551","0.00671"
"102.67200","38.94666","0.00630"
"103.04400","38.97763","0.00601"
"103.41600","39.00861","0.00635"
"103.78800","39.03963","0.00637"
"104.16000","39.07066","0.00629"
"104.53200","39.10164","0.00625"
"104.90400","39.13255","0.00623"
"105.27600","39.16364","0.00678"
"105.64800","39.19467","0.00617"
"106.02000","39.22558","0.00684"
"106.39200","39.25667","0.00623"
"106.76400","39.28764","0.00623"
"107.13600","39.31861","0.00703"
"107.50800","39.34959","0.00663"
"107.88000","39.38061","0.00719"
"108.25200","39.41164","0.00671"
"108.62400","39.44256","0.00632"
"108.99600","39.47364","0.00630"
"109.36800","39.50468","0.00658"
"109.74000","39.53559","0.00685"
"110.11200","39.56668","0.00607"
"110.48400","39.59765","0.00664"
"110.85600","39.62856","0.00649"
"111.22800","39.65965","0.00642"
"111.60000","39.69068","0.00650"
"111.97200","39.72160","0.00696"
"112.34400","39.75256","0.00672"
"112.71600","39.78366","0.00707"
"113.08800","39.81456","0.00723"
"113.46000","39.84560","0.00713"
"113.83200","39.87663","0.00690"
"114.20400","39.90760","0.00675"
"114.57600","39.93863","0.00682"
"114.94800","39.96960","0.00717"
"115.32000","40.00063","0.00741"
"115.69200","40.03160","0.00740"
"116.06400","40.06263","0.00744"
"116.43600","40.09372","0.00744"
"116.80800","40.12458","0.00679"
"117.18000","40.15561","0.00687"
"117.55200","40.18664","0.00710"
"117.92400","40.21755","0.00712"
"118.29600","40.24863","0.00806"
"118.66800","40.27967","0.00757"
"119.04000","40.31064","0.00734"
"119.41200","40.34161","0.00681"
"119.78400","40.37264","0.00754"
"120.15600","40.40368","0.00697"
"120.52800","40.43452","0.00755"
"120.90000","40.46567","0.00772"
"121.27200","40.49665","0.00779"
"121.64400","40.52756","0.00802"
"122.01600","40.55865","0.00774"
"122.38800","40.58961","0.00801"
"122.76000","40.62065","0.00830"
"123.13200","40.65162","0.00771"
"123.50400","40.68265","0.00806"
"123.87600","40.71362","0.00795"
"124.24800","40.74459","0.00818"
"124.62000","40.77563","0.00875"
"124.99200","40.80665","0.00836"
"125.36400","40.83762","0.00870"
"125.73600","40.86866","0.00851"
"126.10800","40.89963","0.00878"
"126.48000","40.93060","0.00832"
"126.85200","40.96163","0.00847"
"127.22400","40.99266","0.00927"
"127.59600","41.02357","0.00884"
"127.96800","41.05460","0.00930"
"128.34000","41.08564","0.00997"
"128.71201","41.11666","0.00959"
"129.08400","41.14758","0.01004"
"129.45599","41.17867","0.01011"
"129.82800","41.20964","0.00982"
"130.20000","41.24061","0.01053"
"130.57201","41.27164","0.01011"
"130.94400","41.30261","0.01017"
"131.31599","41.33352","0.01022"
"131.68800","41.36461","0.01082"
"132.06000","41.39564","0.01064"
"132.43201","41.42661","0.01152"
"132.80400","41.45764","0.01154"
"133.17599","41.48861","0.01084"
"133.54800","41.51958","0.01172"
"133.92000","41.55062","0.01186"
"134.29201","41.58165","0.01250"
"134.66400","41.61268","0.01255"
"135.03600","41.64359","0.01259"
"135.40800","41.67462","0.01278"
"135.78000","41.70565","0.01314"
"136.15199","41.73662","0.01364"
"136.52400","41.76765","0.01378"
"136.89600","41.79862","0.01449"
"137.26801","41.82959","0.01404"
"137.64000","41.86063","0.01452"
"138.01199","41.89165","0.01466"
"138.38400","41.92263","0.01474"
"138.75600","41.95359","0.01512"
"139.12801","41.98469","0.01631"
"139.50000","42.01560","0.01538"
"139.87199","42.04657","0.01598"
"140.24400","42.07760","0.01616"
"140.61600","42.10863","0.01683"
"140.98801","42.13961","0.01657"
"141.36000","42.17064","0.01654"
"141.73199","42.20166","0.01711"
"142.10400","42.23263","0.01737"
"142.47600","42.26361","0.01801"
"142.84801","42.29470","0.01824"
"143.22000","42.32561","0.01821"
"143.59200","42.35664","0.01877"
"143.96400","42.38767","0.01894"
"144.33600","42.41864","0.01920"
"144.70799","42.44961","0.01986"
"145.08000","42.48064","0.01969"
"145.45200","42.51162","0.01997"
"145.82401","42.54258","0.02020"
"146.19600","42.57362","0.02031"
"146.56799","42.60471","0.02081"
"146.94000","42.63556","0.02083"
"147.31200","42.66665","0.02134"
"147.68401","42.69762","0.02156"
"148.05600","42.72859","0.02189"
"148.42799","42.75962","0.02222"
"148.80000","42.79065","0.02289"
"149.17200","42.82162","0.02294"
"149.54401","42.85265","0.02361"
"149.91600","42.88368","0.02359"
"150.28799","42.91465","0.02376"
"150.66000","42.94556","0.02397"
"151.03200","42.97666","0.02434"
"151.40401","43.00762","0.02541"
"151.77600","43.03860","0.02516"
"152.14799","43.06963","0.02538"
"152.52000","43.10060","0.02583"
"152.89200","43.13163","0.02592"
"153.26401","43.16260","0.02601"
"153.63600","43.19363","0.02605"
"154.00800","43.22466","0.02659"
"154.38000","43.25557","0.02712"
"154.75200","43.28667","0.02745"
"155.12399","43.31758","0.02771"
"155.49600","43.34860","0.02841"
"155.86800","43.37963","0.02816"
"156.24001","43.41061","0.02912"
"156.61200","43.44158","0.02934"
"156.98399","43.47261","0.02955"
"157.35600","43.50364","0.03013"
"157.72800","43.53461","0.03048"
"158.10001","43.56559","0.03083"
"158.47200","43.59667","0.03161"
"158.84399","43.62759","0.03176"
"159.21600","43.65862","0.03228"
"159.58800","43.68965","0.03250"
"159.96001","43.72062","0.03302"
"160.33200","43.75159","0.03364"
"160.70399","43.78268","0.03391"
"161.07600","43.81364","0.03508"
"161.44800","43.84456","0.03481"
"161.82001","43.87565","0.03589"
"162.19200","43.90668","0.03593"
"162.56400","43.93753","0.03623"
"162.93600","43.96862","0.03748"
"163.30800","43.99966","0.03794"
"163.67999","44.03062","0.03799"
"164.05200","44.06160","0.03860"
"164.42400","44.09269","0.03976"
"164.79601","44.12360","0.03935"
"165.16800","44.15456","0.04080"
"165.53999","44.18566","0.04081"
"165.91200","44.21663","0.04174"
"166.28400","44.24755","0.04174"
"166.65601","44.27863","0.04241"
"167.02800","44.30960","0.04326"
"167.39999","44.34057","0.04366"
"167.77200","44.37154","0.04380"
"168.14400","44.40263","0.04487"
"168.51601","44.43361","0.04627"
"168.88800","44.46452","0.04510"
"169.25999","44.49567","0.04559"
"169.63200","44.52664","0.04634"
"170.00400","44.55755","0.04598"
"170.37601","44.58864","0.04797"
"170.74800","44.61967","0.04770"
"171.12000","44.65059","0.04969"
"171.49200","44.68162","0.04930"
"171.86400","44.71265","0.05064"
"172.23599","44.74361","0.05168"
"172.60800","44.77464","0.05131"
"172.98000","44.80568","0.04849"
"173.35201","44.83659","0.05081"
"173.72400","44.86756","0.05137"
"174.09599","44.89865","0.05243"
"174.46800","44.92962","0.05630"
"174.84000","44.96066","0.04226"
"175.21201","44.99157","0.04632"
"175.58400","45.02265","0.04393"
"175.95599","45.05363","0.04564"
"176.32800","45.08466","0.04483"
"176.70000","45.11569","0.04683"
"177.07201","45.14654","0.04809"
"177.44400","45.17763","0.04696"
"177.81599","45.20866","0.04957"
"178.18800","45.23963","0.04866"
"178.56000","45.27060","0.05168"
"178.93201","45.30164","0.05138"
"179.30400","45.33266","0.05391"
"179.67599","45.36357","0.05478"
"180.04800","45.39466","0.05553"
"180.42000","45.42564","0.05769"
"180.79201","45.45655","0.05738"
"181.16400","45.48770","0.05942"
"181.53600","45.51867","0.06059"
"181.90800","45.54958","0.06153"
"182.28000","45.58061","0.06289"
"182.65199","45.61158","0.06350"
"183.02400","45.64267","0.06442"
"183.39600","45.67365","0.06522"
"183.76801","45.70461","0.06638"
"184.14000","45.73558","0.06754"
"184.51199","45.76661","0.06733"
"184.88400","45.79764","0.06870"
"185.25600","45.82867","0.06902"
"185.62801","45.85965","0.06974"
"186.00000","45.89068","0.07028"
"186.37199","45.92165","0.07090"
"186.74400","45.95262","0.06789"
"187.11600","45.98359","0.06770"
"187.48801","46.01468","0.06903"
"187.86000","46.04559","0.06988"
"188.23199","46.07663","0.06995"
"188.60400","46.10772","0.07128"
"188.97600","46.13863","0.07149"
"189.34801","46.16959","0.07212"
"189.72000","46.20063","0.07304"
"190.09200","46.23160","0.07286"
"190.46400","46.26263","0.07388"
"190.83600","46.29360","0.07424"
"191.20799","46.32469","0.07470"
"191.58000","46.35554","0.07530"
"191.95200","46.38663","0.07626"
"192.32401","46.41766","0.07626"
"192.69600","46.44858","0.07736"
"193.06799","46.47961","0.07790"
"193.44000","46.51064","0.07870"
"193.81200","46.54161","0.07933"
"194.18401","46.57258","0.08067"
"194.55600","46.60361","0.08138"
"194.92799","46.63470","0.08245"
"195.30000","46.66555","0.08373"
"195.67200","46.69664","0.08486"
"196.04401","46.72767","0.08614"
"196.41600","46.75853","0.08726"
"196.78799","46.78961","0.08870"
"197.16000","46.82071","0.08994"
"197.53200","46.85162","0.09267"
"197.90401","46.88259","0.09285"
"198.27600","46.91362","0.09483"
"198.64799","46.94465","0.09705"
"199.02000","46.97556","0.09887"
"199.39200","47.00665","0.10133"
"199.76401","47.03762","0.10415"
"200.13600","47.06860","0.09951"
"200.50800","47.09962","0.10268"
"200.88000","47.13066","0.10835"
"201.25200","47.16156","0.11342"
"201.62399","47.19265","0.11699"
"201.99600","47.22368","0.11608"
"202.36800","47.25460","0.11806"
"202.74001","47.28557","0.12200"
"203.11200","47.31666","0.12398"
"203.48399","47.34757","0.12575"
"203.85600","47.37860","0.12828"
"204.22800","47.40963","0.12850"
"204.60001","47.44061","0.13271"
"204.97200","47.47158","0.13654"
"205.34399","47.50261","0.13666"
"205.71600","47.53370","0.13907"
"206.08800","47.56460","0.14201"
"206.46001","47.59563","0.14475"
"206.83200","47.62667","0.14640"
"207.20399","47.65752","0.14865"
"207.57600","47.68867","0.15104"
"207.94800","47.71964","0.15225"
"208.32001","47.75061","0.15638"
"208.69200","47.78158","0.15962"
"209.06400","47.81261","0.16036"
"209.43600","47.84364","0.16262"
"209.80800","47.87462","0.16677"
"210.17999","47.90565","0.16851"
"210.55200","47.93668","0.16989"
"210.92400","47.96759","0.17250"
"211.29601","47.99862","0.17650"
"211.66800","48.02965","0.17796"
"212.03999","48.06056","0.17977"
"212.41200","48.09165","0.18186"
"212.78400","48.12262","0.18377"
"213.15601","48.15359","0.18491"
"213.52800","48.18462","0.18627"
"213.89999","48.21565","0.18871"
"214.27200","48.24662","0.19073"
"214.64400","48.27760","0.19315"
"215.01601","48.30869","0.19545"
"215.38800","48.33960","0.19832"
"215.75999","48.37057","0.20152"
"216.13200","48.40166","0.20426"
"216.50400","48.43263","0.20704"
"216.87601","48.46360","0.21044"
"217.24800","48.49463","0.21449"
"217.62000","48.52567","0.21915"
"217.99200","48.55657","0.22192"
"218.36400","48.58760","0.22459"
"218.73599","48.61869","0.22800"
"219.10800","48.64961","0.23204"
"219.48000","48.68064","0.23636"
"219.85201","48.71167","0.23966"
"220.22400","48.74258","0.24368"
"220.59599","48.77361","0.24784"
"220.96800","48.80464","0.25239"
"221.34000","48.83567","0.25815"
"221.71201","48.86658","0.26561"
"222.08400","48.89762","0.26971"
"222.45599","48.92865","0.27524"
"222.82800","48.95955","0.27920"
"223.20000","48.99065","0.28232"
"223.57201","49.02162","0.28584"
"223.94400","49.05259","0.28898"
"224.31599","49.08356","0.29119"
"224.68800","49.11465","0.29311"
"225.06000","49.14562","0.29457"
"225.43201","49.17659","0.29622"
"225.80400","49.20768","0.29824"
"226.17599","49.23865","0.30055"
"226.54800","49.26957","0.30315"
"226.92000","49.30066","0.30784"
"227.29201","49.33163","0.31338"
"227.66400","49.36259","0.31898"
"228.03600","49.39363","0.32402"
"228.40800","49.42460","0.32837"
"228.78000","49.45563","0.33310"
"229.15199","49.48660","0.33829"
"229.52400","49.51764","0.34290"
"229.89600","49.54860","0.34800"
"230.26801","49.57957","0.35219"
"230.64000","49.61066","0.35587"
"231.01199","49.64164","0.36019"
"231.38400","49.67261","0.36540"
"231.75600","49.70364","0.36964"
"232.12801","49.73467","0.37405"
"232.50000","49.76558","0.37712"
"232.87199","49.79667","0.38139"
"233.24400","49.82764","0.38427"
"233.61600","49.85862","0.38741"
"233.98801","49.88964","0.39012"
"234.36000","49.92061","0.39420"
"234.73199","49.95158","0.39873"
"235.10400","49.98262","0.40429"
"235.47600","50.01359","0.40936"
"235.84801","50.04462","0.41398"
"236.22000","50.07559","0.41895"
"236.59200","50.10668","0.42479"
"236.96400","50.13765","0.42881"
"237.33600","50.16862","0.43337"
"237.70799","50.19965","0.43647"
"238.08000","50.23062","0.44194"
"238.45200","50.26165","0.44811"
"238.82401","50.29263","0.45290"
"239.19600","50.32366","0.45778"
"239.56799","50.35462","0.46502"
"239.94000","50.38554","0.47170"
"240.31200","50.41669","0.47799"
"240.68401","50.44760","0.48430"
"241.05600","50.47857","0.48964"
"241.42799","50.50972","0.49343"
"241.80000","50.54063","0.49563"
"242.17200","50.57160","0.49866"
"242.54401","50.60263","0.27267"
"242.91600","50.63361","0.28125"
"243.28799","50.66464","0.28364"
"243.66000","50.69561","0.28419"
"244.03200","50.72664","0.28635"
"244.40401","50.75761","0.28767"
"244.77600","50.78864","0.28975"
"245.14799","50.81966","0.29056"
"245.52000","50.85058","0.29218"
"245.89200","50.88161","0.29326"
"246.26401","50.91264","0.29472"
"246.63600","50.94367","0.29618"
"247.00800","50.97458","0.29813"
"247.38000","51.00561","0.30030"
"247.75200","51.03671","0.30252"
"248.12399","51.06755","0.30557"
"248.49600","51.09865","0.30766"
"248.86800","51.12968","0.31076"
"249.24001","51.16058","0.31508"
"249.61200","51.19162","0.31943"
"249.98399","51.22265","0.32317"
"250.35600","51.25368","0.32714"
"250.72800","51.28459","0.33170"
"251.10001","51.31562","0.33556"
"251.47200","51.34665","0.34006"
"251.84399","51.37756","0.34411"
"252.21600","51.40865","0.34790"
"252.58800","51.43963","0.35038"
"252.96001","51.47060","0.35348"
"253.33200","51.50169","0.35639"
"253.70399","51.53260","0.35930"
"254.07600","51.56357","0.36220"
"254.44800","51.59460","0.36572"
"254.82001","51.62563","0.36927"
"255.19200","51.65666","0.37200"
"255.56400","51.68758","0.37401"
"255.93600","51.71861","0.37699"
"256.30801","51.74963","0.38018"
"256.67999","51.78061","0.38225"
"257.05200","51.81170","0.38476"
"257.42401","51.84267","0.38669"
"257.79599","51.87364","0.38912"
"258.16800","51.90461","0.39140"
"258.54001","51.93558","0.39425"
"258.91199","51.96661","0.39738"
"259.28400","51.99758","0.40116"
"259.65601","52.02867","0.40445"
"260.02802","52.05965","0.40819"
"260.39999","52.09055","0.41157"
"260.77200","52.12165","0.41491"
"261.14401","52.15268","0.41948"
"261.51599","52.18359","0.37722"
"261.88800","52.21462","0.37952"
"262.26001","52.24565","0.38349"
"262.63199","52.27662","0.38668"
"263.00400","52.30753","0.38809"
"263.37601","52.33868","0.38930"
"263.74799","52.36959","0.39178"
"264.12000","52.40062","0.39580"
"264.49200","52.43166","0.40097"
"264.86401","52.46263","0.40444"
"265.23599","52.49360","0.40695"
"265.60800","52.52469","0.41106"
"265.98001","52.55565","0.41623"
"266.35199","52.58657","0.42072"
"266.72400","52.61760","0.42349"
"267.09601","52.64863","0.42736"
"267.46799","52.67954","0.43085"
"267.84000","52.71063","0.43434"
"268.21201","52.74160","0.43802"
"268.58401","52.77258","0.44089"
"268.95599","52.80366","0.44559"
"269.32800","52.83464","0.44995"
"269.70001","52.86567","0.45255"
"270.07199","52.89664","0.45600"
"270.44400","52.92767","0.46125"
"270.81601","52.95864","0.46693"
"271.18799","52.98956","0.47044"
"271.56000","53.02064","0.47587"
"271.93201","53.05161","0.48121"
"272.30399","53.08258","0.48485"
"272.67599","53.11368","0.48823"
"273.04800","53.14464","0.49249"
"273.42001","53.17561","0.49495"
"273.79199","53.20659","0.49689"
"274.16400","53.23768","0.49952"
"274.53601","53.26865","0.50266"
"274.90799","53.29962","0.50546"
"275.28000","53.33071","0.50827"
"275.65201","53.36162","0.51223"
"276.02399","53.39259","0.51557"
"276.39600","53.42363","0.51897"
"276.76801","53.45465","0.52376"
"277.14001","53.48556","0.52805"
"277.51199","53.51659","0.53296"
"277.88400","53.54762","0.53699"
"278.25601","53.57860","0.54270"
"278.62799","53.60963","0.54740"
"279.00000","53.64066","0.55303"
"279.37201","53.67163","0.55759"
"279.74399","53.70260","0.56167"
"280.11600","53.73363","0.56585"
"280.48801","53.76460","0.56996"
"280.85999","53.79558","0.57479"
"281.23199","53.82666","0.57873"
"281.60400","53.85770","0.58239"
"281.97601","53.88855","0.58538"
"282.34799","53.91964","0.58858"
"282.72000","53.95067","0.59097"
"283.09201","53.98158","0.59356"
"283.46399","54.01267","0.59606"
"283.83600","54.04358","0.59797"
"284.20801","54.07461","0.60033"
"284.57999","54.10558","0.60354"
"284.95200","54.13667","0.60673"
"285.32401","54.16764","0.61066"
"285.69601","54.19862","0.61513"
"286.06799","54.22965","0.62072"
"286.44000","54.26062","0.62665"
"286.81201","54.29159","0.63212"
"287.18399","54.32267","0.63670"
"287.55600","54.35365","0.64008"
"287.92801","54.38462","0.64328"
"288.29999","54.41559","0.64732"
"288.67200","54.44662","0.65263"
"289.04401","54.47765","0.65727"
"289.41599","54.50856","0.66143"
"289.78799","54.53965","0.66508"
"290.16000","54.57062","0.66937"
"290.53201","54.60154","0.67385"
"290.90399","54.63269","0.67933"
"291.27600","54.66366","0.68394"
"291.64801","54.69463","0.68785"
"292.01999","54.72560","0.69172"
"292.39200","54.75663","0.69468"
"292.76401","54.78760","0.69749"
"293.13599","54.81863","0.69951"
"293.50800","54.84961","0.70126"
"293.88000","54.88064","0.70343"
"294.25201","54.91167","0.70562"
"294.62399","54.94263","0.70822"
"294.99600","54.97361","0.71074"
"295.36801","55.00464","0.71383"
"295.73999","55.03561","0.71733"
"296.11200","55.06664","0.72125"
"296.48401","55.09761","0.72531"
"296.85599","55.12858","0.59949"
"297.22800","55.15967","0.59927"
"297.60001","55.19064","0.59694"
"297.97198","55.22162","0.59957"
"298.34399","55.25264","0.60326"
"298.71600","55.28362","0.60089"
"299.08801","55.31459","0.21466"
"299.45999","55.34562","0.19692"
"299.83200","55.37664","0.19827"
"300.20401","55.40756","0.20750"
"300.57599","55.43865","0.20491"
"300.94800","55.46962","0.21637"
"301.32001","55.50059","0.20128"
"301.69199","55.53162","0.21862"
"302.06400","55.56265","0.20520"
"302.43600","55.59362","0.21751"
"302.80801","55.62466","0.21191"
"303.17999","55.65563","0.22538"
"303.55200","55.68666","0.21461"
"303.92401","55.71762","0.21718"
"304.29599","55.74866","0.21391"
"304.66800","55.77957","0.22713"
"305.04001","55.81060","0.22180"
"305.41199","55.84163","0.22573"
"305.78400","55.87260","0.21682"
"306.15601","55.90364","0.22960"
"306.52802","55.93466","0.22179"
"306.89999","55.96569","0.22475"
"307.27200","55.99661","0.22773"
"307.64401","56.02758","0.23663"
"308.01599","56.05867","0.22818"
"308.38800","56.08958","0.22945"
"308.76001","56.12067","0.22751"
"309.13199","56.15164","0.22966"
"309.50400","56.18261","0.23796"
"309.87601","56.21358","0.23229"
"310.24799","56.24467","0.23531"
"310.62000","56.27565","0.23066"
"310.99200","56.30655","0.24335"
"311.36401","56.33764","0.23340"
"311.73599","56.36861","0.23787"
"312.10800","56.39952","0.23541"
"312.48001","56.43068","0.24850"
"312.85199","56.46165","0.24714"
"313.22400","56.49262","0.23858"
"313.59601","56.52365","0.24160"
"313.96799","56.55462","0.24019"
"314.34000","56.58565","0.24985"
"314.71201","56.61657","0.24325"
"315.08401","56.64766","0.24629"
"315.45599","56.67869","0.24712"
"315.82800","56.70959","0.25358"
"316.20001","56.74063","0.25901"
"316.57199","56.77166","0.24715"
"316.94400","56.80257","0.25059"
"317.31601","56.83366","0.24911"
"317.68799","56.86463","0.25679"
"318.06000","56.89560","0.26084"
"318.43201","56.92657","0.25451"
"318.80399","56.95760","0.25938"
"319.17599","56.98864","0.25804"
"319.54800","57.01961","0.26937"
"319.92001","57.05070","0.26843"
"320.29199","57.08161","0.25962"
"320.66400","57.11258","0.26394"
"321.03601","57.14361","0.26072"
"321.40799","57.17464","0.27115"
"321.78000","57.20561","0.27452"
"322.15201","57.23658","0.26867"
"322.52399","57.26767","0.27026"
"322.89600","57.29858","0.27084"
"323.26801","57.32961","0.27568"
"323.64001","57.36070","0.27966"
"324.01199","57.39162","0.27554"
"324.38400","57.42259","0.27433"
"324.75601","57.45362","0.27493"
"325.12799","57.48458","0.27617"
"325.50000","57.51562","0.28094"
"325.87201","57.54665","0.28057"
"326.24399","57.57762","0.27799"
"326.61600","57.60859","0.27929"
"326.98801","57.63963","0.27915"
"327.35999","57.67066","0.28222"
"327.73199","57.70151","0.28523"
"328.10400","57.73265","0.28381"
"328.47601","57.76363","0.28239"
"328.84799","57.79460","0.28356"
"329.22000","57.82563","0.28359"
"329.59201","57.85666","0.28624"
"329.96399","57.88757","0.28817"
"330.33600","57.91860","0.28730"
"330.70801","57.94963","0.28616"
"331.07999","57.98066","0.28676"
"331.45200","58.01158","0.28761"
"331.82401","58.04266","0.28953"
"332.19601","58.07363","0.29110"
"332.56799","58.10460","0.29062"
"332.94000","58.13564","0.29018"
"333.31201","58.16666","0.29004"
"333.68399","58.19758","0.29080"
"334.05600","58.22861","0.29124"
"334.42801","58.25964","0.29295"
"334.79999","58.29061","0.29314"
"335.17200","58.32158","0.29197"
"335.54401","58.35261","0.29204"
"335.91599","58.38358","0.29246"
"336.28799","58.41462","0.29319"
"336.66000","58.44565","0.29393"
"337.03201","58.47662","0.29474"
"337.40399","58.50753","0.29415"
"337.77600","58.53867","0.29422"
"338.14801","58.56971","0.29390"
"338.51999","58.60056","0.29439"
"338.89200","58.63165","0.29527"
"339.26401","58.66262","0.29577"
"339.63599","58.69359","0.29612"
"340.00800","58.72462","0.29606"
"340.38000","58.75565","0.29569"
"340.75201","58.78663","0.29588"
"341.12399","58.81760","0.29617"
"341.49600","58.84869","0.29735"
"341.86801","58.87966","0.29767"
"342.23999","58.91057","0.29816"
"342.61200","58.94166","0.29783"
"342.98401","58.97263","0.29792"
"343.35599","59.00360","0.29808"
"343.72800","59.03463","0.29865"
"344.10001","59.06567","0.29980"
"344.47198","59.09663","0.30059"
"344.84399","59.12760","0.30097"
"345.21600","59.15863","0.30084"
"345.58801","59.18961","0.30048"
"345.95999","59.22057","0.30058"
"346.33200","59.25167","0.30104"
"346.70401","59.28264","0.30204"
"347.07599","59.31361","0.30273"
"347.44800","59.34464","0.30321"
"347.82001","59.37561","0.30350"
"348.19199","59.40665","0.30313"
"348.56400","59.43761","0.30281"
"348.93600","59.46858","0.30334"
"349.30801","59.49961","0.30481"
"349.67999","59.53059","0.30552"
"350.05200","59.56167","0.30619"
"350.42401","59.59265","0.30661"
"350.79599","59.62362","0.30693"
"351.16800","59.65465","0.30712"
"351.54001","59.68562","0.30766"
"351.91199","59.71659","0.30857"
"352.28400","59.74762","0.30993"
"352.65601","59.77865","0.30990"
"353.02802","59.80957","0.31126"
"353.39999","59.84060","0.31150"
"353.77200","59.87169","0.31251"
"354.14401","59.90259","0.31264"
"354.51599","59.93357","0.31336"
"354.88800","59.96466","0.31377"
"355.26001","59.99563","0.01646"
"355.63199","60.02660","0.01312"
"356.00400","60.05763","0.00998"
"356.37601","60.08867","0.01246"
"356.74799","60.11957","0.01298"
"357.12000","60.15060","0.00782"
"357.49200","60.18164","0.01381"
"357.86401","60.21261","0.00818"
"358.23599","60.24364","0.01229"
"358.60800","60.27467","0.01102"
"358.98001","60.30564","0.01114"
"359.35199","60.33661","0.01366"
"359.72400","60.36764","0.01008"
"360.09601","60.39867","0.01275"
"360.46799","60.42958","0.01336"
"360.84000","60.46067","0.01222"
"361.21201","60.49158","0.01243"
"361.58401","60.52256","0.01427"
"361.95599","60.55364","0.01110"
"362.32800","60.58462","0.01474"
"362.70001","60.61559","0.01384"
"363.07199","60.64661","0.01187"
"363.44400","60.67759","0.01498"
"363.81601","60.70861","0.01384"
"364.18799","60.73959","0.01339"
"364.56000","60.77068","0.01569"
"364.93201","60.80159","0.01360"
"365.30399","60.83256","0.01415"
"365.67599","60.86365","0.01595"
"366.04800","60.89468","0.01407"
"366.42001","60.92566","0.01575"
"366.79199","60.95663","0.01576"
"367.16400","60.98766","0.01445"
"367.53601","61.01857","0.01593"
"367.90799","61.04960","0.01636"
"368.28000","61.08069","0.01598"
"368.65201","61.11154","0.01639"
"369.02399","61.14263","0.01626"
"369.39600","61.17366","0.01605"
"369.76801","61.20457","0.01684"
"370.14001","61.23554","0.01679"
"370.51199","61.26664","0.01662"
"370.88400","61.29760","0.01699"
"371.25601","61.32858","0.01738"
"371.62799","61.35966","0.01682"
"372.00000","61.39064","0.01765"
"372.37201","61.42155","0.01781"
"372.74399","61.45264","0.01734"
"373.11600","61.48367","0.01849"
"373.48801","61.51458","0.01799"
"373.85999","61.54561","0.01793"
"374.23199","61.57664","0.01820"
"374.60400","61.60762","0.01861"
"374.97601","61.63858","0.01861"
"375.34799","61.66968","0.01895"
"375.72000","61.70065","0.01883"
"376.09201","61.73156","0.01909"
"376.46399","61.76265","0.01915"
"376.83600","61.79362","0.01936"
"377.20801","61.82453","0.01916"
"377.57999","61.85562","0.01899"
"377.95200","61.88665","0.01928"
"378.32401","61.91762","0.01924"
"378.69601","61.94860","0.01947"
"379.06799","61.97969","0.02049"
"379.44000","62.01059","0.02008"
"379.81201","62.04163","0.01989"
"380.18399","62.07266","0.02024"
"380.55600","62.10357","0.02106"
"380.92801","62.13460","0.02020"
"381.29999","62.16563","0.02087"
"381.67200","62.19666","0.02108"
"382.04401","62.22763","0.02088"
"382.41599","62.25860","0.02115"
"382.78799","62.28963","0.02139"
"383.16000","62.32055","0.02159"
"383.53201","62.35158","0.02165"
"383.90399","62.38267","0.02195"
"384.27600","62.41358","0.02171"
"384.64801","62.44461","0.02195"
"385.01999","62.47564","0.02210"
"385.39200","62.50661","0.02240"
"385.76401","62.53758","0.02201"
"386.13599","62.56867","0.02243"
"386.50800","62.59964","0.02270"
"386.88000","62.63061","0.02254"
"387.25201","62.66164","0.02301"
"387.62399","62.69261","0.02341"
"387.99600","62.72353","0.02316"
"388.36801","62.75468","0.02382"
"388.73999","62.78559","0.02419"
"389.11200","62.81661","0.02431"
"389.48401","62.84758","0.02400"
"389.85599","62.87862","0.02490"
"390.22800","62.90959","0.02510"
"390.60001","62.94062","0.02544"
"390.97198","62.97159","0.02502"
"391.34399","63.00262","0.02581"
"391.71600","63.03360","0.02550"
"392.08801","63.06468","0.02640"
"392.45999","63.09565","0.02619"
"392.83200","63.12656","0.02662"
"393.20401","63.15765","0.02695"
"393.57599","63.18863","0.02691"
"393.94800","63.21960","0.02688"
"394.32001","63.25063","0.02810"
"394.69199","63.28165","0.02788"
"395.06400","63.31263","0.02843"
"395.43600","63.34354","0.02809"
"395.80801","63.37463","0.02857"
"396.17999","63.40560","0.02865"
"396.55200","63.43658","0.02918"
"396.92401","63.46767","0.02957"
"397.29599","63.49864","0.02944"
"397.66800","63.52960","0.02967"
"398.04001","63.56063","0.03013"
"398.41199","63.59161","0.03127"
"398.78400","63.62258","0.03111"
"399.15601","63.65361","0.03210"
"399.52802","63.68464","0.03227"
"399.89999","63.71561","0.03256"
"400.27200","63.74658","0.03238"
"400.64401","63.77761","0.03338"
"401.01599","63.80864","0.03290"
"401.38800","63.83955","0.03384"
"401.76001","63.87065","0.03449"
"402.13199","63.90168","0.03439"
"402.50400","63.93259","0.03541"
"402.87601","63.96368","0.03562"
"403.24799","63.99464","0.03621"
"403.62000","64.02556","0.03642"
"403.99200","64.05665","0.03643"
"404.36401","64.08762","0.03738"
"404.73599","64.11865","0.03793"
"405.10800","64.14957","0.03796"
"405.48001","64.18066","0.03883"
"405.85199","64.21162","0.03902"
"406.22400","64.24259","0.03971"
"406.59601","64.27368","0.04035"
"406.96799","64.30460","0.04107"
"407.34000","64.33557","0.04121"
"407.71201","64.36666","0.04162"
"408.08401","64.39758","0.04213"
"408.45599","64.42860","0.04269"
"408.82800","64.45957","0.04279"
"409.20001","64.49066","0.04399"
"409.57199","64.52163","0.04429"
"409.94400","64.55260","0.04513"
"410.31601","64.58363","0.04511"
"410.68799","64.61467","0.04570"
"411.06000","64.64558","0.04604"
"411.43201","64.67667","0.04729"
"411.80399","64.70763","0.04833"
"412.17599","64.73861","0.04844"
"412.54800","64.76958","0.04915"
"412.92001","64.80074","0.05049"
"413.29199","64.83158","0.05115"
"413.66400","64.86262","0.05162"
"414.03601","64.89365","0.05256"
"414.40799","64.92455","0.05392"
"414.78000","64.95564","0.05430"
"415.15201","64.98662","0.05517"
"415.52399","65.01765","0.05561"
"415.89600","65.04862","0.05590"
"416.26801","65.07965","0.05805"
"416.64001","65.11069","0.05821"
"417.01199","65.14159","0.05904"
"417.38400","65.17262","0.05984"
"417.75601","65.20365","0.06077"
"418.12799","65.23457","0.06124"
"418.50000","65.26566","0.06202"
"418.87201","65.29663","0.06290"
"419.24399","65.32760","0.06375"
"419.61600","65.35863","0.06438"
"419.98801","65.38966","0.06498"
"420.35999","65.42062","0.06540"
"420.73199","65.45154","0.06595"
"421.10400","65.48269","0.06690"
"421.47601","65.51354","0.06747"
"421.84799","65.54458","0.06771"
"422.22000","65.57567","0.06852"
"422.59201","65.60663","0.06901"
"422.96399","65.63760","0.06963"
"423.33600","65.66863","0.06996"
"423.70801","65.69961","0.07037"
"424.07999","65.73064","0.07101"
"424.45200","65.76161","0.07157"
"424.82401","65.79264","0.07191"
"425.19601","65.82362","0.07239"
"425.56799","65.85458","0.07265"
"425.94000","65.88567","0.07272"
"426.31201","65.91658","0.07346"
"426.68399","65.94756","0.07373"
"427.05600","65.97865","0.07421"
"427.42801","66.00962","0.07474"
"427.79999","66.04059","0.07499"
"428.17200","66.07162","0.07545"
"428.54401","66.10265","0.07582"
"428.91599","66.13356","0.07633"
"429.28799","66.16459","0.07670"
"429.66000","66.19563","0.07700"
"430.03201","66.22659","0.07806"
"430.40399","66.25757","0.07829"
"430.77600","66.28866","0.07886"
"431.14801","66.31963","0.07928"
"431.51999","66.35059","0.07967"
"431.89200","66.38168","0.08022"
"432.26401","66.41266","0.08080"
"432.63599","66.44351","0.08167"
"433.00800","66.47472","0.08200"
"433.38000","66.50563","0.08200"
"433.75201","66.53654","0.08376"
"434.12399","66.56763","0.08453"
"434.49600","66.59860","0.08492"
"434.86801","66.62957","0.08629"
"435.23999","66.66055","0.08674"
"435.61200","66.69164","0.08709"
"435.98401","66.72261","0.08756"
"436.35599","66.75358","0.08925"
"436.72800","66.78467","0.09028"
"437.10001","66.81557","0.09070"
"437.47198","66.84661","0.09144"
"437.84399","66.87764","0.09281"
"438.21600","66.90868","0.09374"
"438.58801","66.93964","0.09470"
"438.95999","66.97056","0.09571"
"439.33200","67.00165","0.09778"
"439.70401","67.03262","0.09832"
"440.07599","67.06358","0.09916"
"440.44800","67.09467","0.10056"
"440.82001","67.12559","0.10187"
"441.19199","67.15656","0.10276"
"441.56400","67.18765","0.10500"
"441.93600","67.21862","0.10617"
"442.30801","67.24959","0.10726"
"442.67999","67.28062","0.10865"
"443.05200","67.31171","0.10878"
"443.42401","67.34257","0.10972"
"443.79599","67.37360","0.11148"
"444.16800","67.40462","0.11264"
"444.54001","67.43560","0.11396"
"444.91199","67.46663","0.11488"
"445.28400","67.49760","0.11659"
"445.65601","67.52863","0.11709"
"446.02802","67.55960","0.11831"
"446.39999","67.59063","0.11889"
"446.77200","67.62167","0.12039"
"447.14401","67.65257","0.12058"
"447.51599","67.68361","0.12193"
"447.88800","67.71463","0.12265"
"448.26001","67.74554","0.12406"
"448.63199","67.77670","0.12435"
"449.00400","67.80761","0.12584"
"449.37601","67.83864","0.12670"
"449.74799","67.86961","0.12771"
"450.12000","67.90058","0.12874"
"450.49200","67.93167","0.13008"
"450.86401","67.96258","0.13109"
"451.23599","67.99367","0.13176"
"451.60800","68.02458","0.13295"
"451.98001","68.05556","0.13363"
"452.35199","68.08665","0.13506"
"452.72400","68.11761","0.13649"
"453.09601","68.14859","0.13710"
"453.46799","68.17961","0.13832"
"453.84000","68.21065","0.13957"
"454.21201","68.24162","0.14062"
"454.58401","68.27259","0.14157"
"454.95599","68.30362","0.14259"
"455.32800","68.33466","0.14338"
"455.70001","68.36562","0.14428"
"456.07199","68.39666","0.14497"
"456.44400","68.42757","0.14625"
"456.81601","68.45860","0.14685"
"457.18799","68.48962","0.14768"
"457.56000","68.52060","0.14834"
"457.93201","68.55157","0.14973"
"458.30399","68.58260","0.15063"
"458.67599","68.61363","0.15181"
"459.04800","68.64460","0.15244"
"459.42001","68.67563","0.15388"
"459.79199","68.70667","0.15266"
"460.16400","68.73763","0.15281"
"460.53601","68.76861","0.15446"
"460.90799","68.79964","0.15535"
"461.28000","68.83067","0.15670"
"461.65201","68.86157","0.15851"
"462.02399","68.89261","0.15894"
"462.39600","68.92370","0.16076"
"462.76801","68.95455","0.16194"
"463.14001","68.98564","0.16245"
"463.51199","69.01667","0.16351"
"463.88400","69.04752","0.16497"
"464.25601","69.07861","0.16593"
"464.62799","69.10958","0.16665"
"465.00000","69.14061","0.16834"
"465.37201","69.17159","0.16962"
"465.74399","69.20261","0.17030"
"466.11600","69.23365","0.17167"
"466.48801","69.26462","0.17283"
"466.85999","69.29565","0.17390"
"467.23199","69.32662","0.17511"
"467.60400","69.35759","0.17556"
"467.97601","69.38862","0.17706"
"468.34799","69.41971","0.17887"
"468.72000","69.45062","0.17892"
"469.09201","69.48160","0.17996"
"469.46399","69.51263","0.18130"
"469.83600","69.54366","0.18199"
"470.20801","69.57456","0.18249"
"470.57999","69.60566","0.18363"
"470.95200","69.63663","0.18419"
"471.32401","69.66760","0.18433"
"471.69601","69.69869","0.18535"
"472.06799","69.72966","0.18606"
"472.44000","69.76057","0.18669"
"472.81201","69.79161","0.18781"
"473.18399","69.82263","0.18879"
"473.55600","69.85355","0.19003"
"473.92801","69.88464","0.19135"
"474.29999","69.91561","0.19305"
"474.67200","69.94664","0.19457"
"475.04401","69.97761","0.19588"
"475.41599","70.00864","0.19735"
"475.78799","70.03960","0.19883"
"476.16000","70.07064","0.19978"
"476.53201","70.10167","0.20150"
"476.90399","70.13264","0.20258"
"477.27600","70.16356","0.20391"
"477.64801","70.19459","0.20559"
"478.01999","70.22562","0.20765"
"478.39200","70.25659","0.20975"
"478.76401","70.28767","0.21179"
"479.13599","70.31859","0.21413"
"479.50800","70.34962","0.21574"
"479.88000","70.38059","0.21845"
"480.25201","70.41168","0.21983"
"480.62399","70.44266","0.22200"
"480.99600","70.47356","0.22302"
"481.36801","70.50471","0.22622"
"481.73999","70.53562","0.22759"
"482.11200","70.56660","0.23038"
"482.48401","70.59769","0.23209"
"482.85599","70.62860","0.23434"
"483.22800","70.65957","0.23740"
"483.60001","70.69066","0.23926"
"483.97198","70.72163","0.24127"
"484.34399","70.75260","0.24302"
"484.71600","70.78363","0.24621"
"485.08801","70.81466","0.24913"
"485.45999","70.84557","0.25167"
"485.83200","70.87660","0.25415"
"486.20401","70.90764","0.25908"
"486.57599","70.93861","0.26266"
"486.94800","70.96964","0.26569"
"487.32001","71.00066","0.26918"
"487.69199","71.03164","0.27237"
"488.06400","71.06255","0.27509"
"488.43600","71.09358","0.27713"
"488.80801","71.12467","0.27966"
"489.17999","71.15553","0.28134"
"489.55200","71.18668","0.28280"
"489.92401","71.21770","0.28449"
"490.29599","71.24855","0.28617"
"490.66800","71.27959","0.24917"
"491.04001","71.31068","0.24478"
"491.41199","71.34159","0.24856"
"491.78400","71.37262","0.25075"
"492.15601","71.40366","0.25091"
"492.52802","71.43468","0.25130"
"492.89999","71.46553","0.25525"
"493.27200","71.49668","0.26161"
"493.64401","71.52765","0.26380"
"494.01599","71.55862","0.26381"
"494.38800","71.58965","0.26494"
"494.76001","71.62063","0.26980"
"495.13199","71.65160","0.27152"
"495.50400","71.68256","0.27443"
"495.87601","71.71365","0.27771"
"496.24799","71.74463","0.27935"
"496.62000","71.77560","0.27893"
"496.99200","71.80663","0.27972"
"497.36401","71.83766","0.28122"
"497.73599","71.86858","0.28486"
"498.10800","71.89966","0.28686"
"498.48001","71.93063","0.28714"
"498.85199","71.96155","0.28761"
"499.22400","71.99264","0.28849"
"499.59601","72.02361","0.28992"
"499.96799","72.05458","0.29102"
"500.34000","72.08561","0.29207"
"500.71201","72.11665","0.29293"
"501.08401","72.14754","0.29411"
"501.45599","72.17858","0.29482"
"501.82800","72.20961","0.29470"
"502.20001","72.24065","0.29516"
"502.57199","72.27161","0.29635"
"502.94400","72.30265","0.29751"
"503.31601","72.33368","0.29909"
"503.68799","72.36452","0.30024"
"504.06000","72.39561","0.30060"
"504.43201","72.42664","0.30196"
"504.80399","72.45762","0.30345"
"505.17599","72.48865","0.30490"
"505.54800","72.51956","0.30548"
"505.92001","72.55065","0.30711"
"506.29199","72.58163","0.31033"
"506.66400","72.61265","0.31429"
"507.03601","72.64368","0.31715"
"507.40799","72.67459","0.31894"
"507.78000","72.70563","0.31964"
"508.15201","72.73666","0.32170"
"508.52399","72.76757","0.32352"
"508.89600","72.79866","0.32586"
"509.26801","72.82963","0.32684"
"509.64001","72.86060","0.32821"
"510.01199","72.89163","0.33007"
"510.38400","72.92266","0.33313"
"510.75601","72.95358","0.33698"
"511.12799","72.98460","0.33842"
"511.50000","73.01569","0.33973"
"511.87201","73.04667","0.34146"
"512.24402","73.07764","0.34239"
"512.61603","73.10867","0.34513"
"512.98798","73.13964","0.34695"
"513.35999","73.17061","0.34876"
"513.73199","73.20164","0.35019"
"514.10400","73.23261","0.35187"
"514.47601","73.26359","0.35250"
"514.84802","73.29461","0.35453"
"515.21997","73.32570","0.35632"
"515.59198","73.35661","0.35782"
"515.96399","73.38759","0.35906"
"516.33600","73.41862","0.36022"
"516.70801","73.44959","0.36184"
"517.08002","73.48062","0.36330"
"517.45203","73.51165","0.36499"
"517.82397","73.54268","0.36669"
"518.19598","73.57359","0.36759"
"518.56799","73.60462","0.36832"
"518.94000","73.63571","0.36890"
"519.31201","73.66656","0.37003"
"519.68402","73.69759","0.37217"
"520.05603","73.72863","0.37332"
"520.42798","73.75959","0.37460"
"520.79999","73.79063","0.37548"
"521.17200","73.82166","0.37588"
"521.54401","73.85263","0.37679"
"521.91602","73.88354","0.37796"
"522.28802","73.91463","0.37987"
"522.65997","73.94566","0.38085"
"523.03198","73.97658","0.38221"
"523.40399","74.00766","0.38291"
"523.77600","74.03864","0.38356"
"524.14801","74.06954","0.38406"
"524.52002","74.10064","0.38471"
"524.89203","74.13161","0.38593"
"525.26398","74.16258","0.38689"
"525.63599","74.19361","0.38734"
"526.00800","74.22464","0.38820"
"526.38000","74.25561","0.38927"
"526.75201","74.28658","0.39008"
"527.12402","74.31767","0.39043"
"527.49597","74.34870","0.39137"
"527.86798","74.37962","0.39314"
"528.23999","74.41064","0.39390"
"528.61200","74.44162","0.39568"
"528.98401","74.47259","0.39660"
"529.35602","74.50356","0.39827"
"529.72803","74.53465","0.39961"
"530.09998","74.56562","0.40119"
"530.47198","74.59659","0.40236"
"530.84399","74.62762","0.40387"
"531.21600","74.65865","0.40521"
"531.58801","74.68956","0.40706"
"531.96002","74.72065","0.40862"
"532.33197","74.75169","0.40991"
"532.70398","74.78259","0.41155"
"533.07599","74.81363","0.41253"
"533.44800","74.84466","0.41396"
"533.82001","74.87557","0.41583"
"534.19202","74.90660","0.41756"
"534.56403","74.93763","0.41932"
"534.93597","74.96860","0.42157"
"535.30798","74.99963","0.42348"
"535.67999","75.03060","0.42510"
"536.05200","75.06164","0.42608"
"536.42401","75.09261","0.42784"
"536.79602","75.12363","0.42943"
"537.16803","75.15467","0.32828"
"537.53998","75.18558","0.31872"
"537.91199","75.21661","0.32194"
"538.28400","75.24763","0.32182"
"538.65601","75.27861","0.31786"
"539.02802","75.30964","0.31536"
"539.40002","75.34061","0.31626"
"539.77197","75.37164","0.32078"
"540.14398","75.40261","0.32379"
"540.51599","75.43364","0.32198"
"540.88800","75.46461","0.32069"
"541.26001","75.49558","0.32120"
"541.63202","75.52668","0.32386"
"542.00403","75.55759","0.32612"
"542.37598","75.58862","0.32408"
"542.74799","75.61971","0.32318"
"543.12000","75.65062","0.32452"
"543.49200","75.68165","0.32817"
"543.86401","75.71256","0.33138"
"544.23602","75.74359","0.33078"
"544.60797","75.77457","0.32934"
"544.97998","75.80560","0.32879"
"545.35199","75.83669","0.33127"
"545.72400","75.86759","0.33444"
"546.09601","75.89863","0.33396"
"546.46802","75.92966","0.33276"
"546.84003","75.96063","0.33341"
"547.21198","75.99160","0.01389"
"547.58398","76.02263","0.01122"
"547.95599","76.05367","0.00953"
"548.32800","76.08458","0.00597"
"548.70001","76.11566","0.00611"
"549.07202","76.14669","0.00627"
"549.44397","76.17754","0.00828"
"549.81598","76.20863","0.00687"
"549.81799","76.20882","0.00692"