File: Force_trajectories/170107_2/Specimen_RawData_5.csv
End date,"1/7/2017"
Specimen label,"3AG_24"
Maximum Load,"0.03907",N

Time,Extension,Load
(s),(mm),(N)
"0.00000","0.00006","0.00018"
"0.21000","0.01519","0.00054"
"0.42000","0.03522","0.00135"
"0.63000","0.05273","0.00146"
"0.84000","0.07025","0.00164"
"1.05000","0.08771","0.00191"
"1.26000","0.10523","0.00173"
"1.47000","0.12263","0.00231"
"1.68000","0.14021","0.00215"
"1.89000","0.15772","0.00210"
"2.10000","0.17512","0.00229"
"2.31000","0.19270","0.00316"
"2.52000","0.21016","0.00281"
"2.73000","0.22774","0.00282"
"2.94000","0.24520","0.00321"
"3.15000","0.26266","0.00300"
"3.36000","0.28023","0.00317"
"3.57000","0.29757","0.00388"
"3.78000","0.31515","0.00360"
"3.99000","0.33273","0.00377"
"4.20000","0.35007","0.00428"
"4.41000","0.36771","0.00388"
"4.62000","0.38516","0.00383"
"4.83000","0.40262","0.00421"
"5.04000","0.42026","0.00410"
"5.25000","0.43760","0.00405"
"5.46000","0.45524","0.00435"
"5.67000","0.47270","0.00423"
"5.88000","0.49015","0.00472"
"6.09000","0.50767","0.00423"
"6.30000","0.52519","0.00475"
"6.51000","0.54265","0.00516"
"6.72000","0.56017","0.00453"
"6.93000","0.57763","0.00435"
"7.14000","0.59520","0.00464"
"7.35000","0.61266","0.00511"
"7.56000","0.63018","0.00467"
"7.77000","0.64770","0.00527"
"7.98000","0.66504","0.00500"
"8.19000","0.68274","0.00579"
"8.40000","0.70014","0.00540"
"8.61000","0.71771","0.00547"
"8.82000","0.73517","0.00554"
"9.03000","0.75269","0.00509"
"9.24000","0.77015","0.00563"
"9.45000","0.78767","0.00569"
"9.66000","0.80519","0.00519"
"9.87000","0.82270","0.00584"
"10.08000","0.84016","0.00576"
"10.29000","0.85768","0.00589"
"10.50000","0.87520","0.00593"
"10.71000","0.89260","0.00593"
"10.92000","0.91018","0.00634"
"11.13000","0.92763","0.00606"
"11.34000","0.94515","0.00573"
"11.55000","0.96267","0.00589"
"11.76000","0.98019","0.00670"
"11.97000","0.99771","0.00656"
"12.18000","1.01517","0.00632"
"12.39000","1.03262","0.00646"
"12.60000","1.05020","0.00648"
"12.81000","1.06760","0.00678"
"13.02000","1.08518","0.00657"
"13.23000","1.10264","0.00679"
"13.44000","1.12016","0.00723"
"13.65000","1.13768","0.00693"
"13.86000","1.15513","0.00691"
"14.07000","1.17271","0.00741"
"14.28000","1.19011","0.00720"
"14.49000","1.20763","0.00725"
"14.70000","1.22521","0.00737"
"14.91000","1.24267","0.00746"
"15.12000","1.26018","0.00758"
"15.33000","1.27770","0.00703"
"15.54000","1.29516","0.00732"
"15.75000","1.31268","0.00774"
"15.96000","1.33020","0.00743"
"16.17000","1.34772","0.00759"
"16.38000","1.36517","0.00719"
"16.59000","1.38257","0.00764"
"16.80000","1.40021","0.00746"
"17.01000","1.41761","0.00788"
"17.22000","1.43519","0.00758"
"17.43000","1.45271","0.00747"
"17.64000","1.47016","0.00775"
"17.85000","1.48768","0.00766"
"18.06000","1.50526","0.00839"
"18.27000","1.52266","0.00810"
"18.48000","1.54018","0.00788"
"18.69000","1.55764","0.00787"
"18.90000","1.57522","0.00799"
"19.11000","1.59267","0.00797"
"19.32000","1.61013","0.00807"
"19.53000","1.62771","0.00788"
"19.74000","1.64517","0.00747"
"19.95000","1.66269","0.00763"
"20.16000","1.68021","0.00797"
"20.37000","1.69766","0.00816"
"20.58000","1.71518","0.00832"
"20.79000","1.73264","0.00821"
"21.00000","1.75016","0.00822"
"21.21000","1.76774","0.00883"
"21.42000","1.78508","0.00837"
"21.63000","1.80271","0.00777"
"21.84000","1.82017","0.00883"
"22.05000","1.83763","0.00822"
"22.26000","1.85521","0.00843"
"22.47000","1.87267","0.00781"
"22.68000","1.89019","0.00811"
"22.89000","1.90770","0.00861"
"23.10000","1.92516","0.00775"
"23.31000","1.94268","0.00862"
"23.52000","1.96020","0.00876"
"23.73000","1.97766","0.00810"
"23.94000","1.99518","0.00860"
"24.15000","2.01264","0.00835"
"24.36000","2.03021","0.00867"
"24.57000","2.04767","0.00845"
"24.78000","2.06519","0.00892"
"24.99000","2.08265","0.00858"
"25.20000","2.10011","0.00811"
"25.41000","2.11769","0.00879"
"25.62000","2.13508","0.00888"
"25.83000","2.15272","0.00879"
"26.04000","2.17018","0.00846"
"26.25000","2.18764","0.00893"
"26.46000","2.20522","0.00846"
"26.67000","2.22268","0.00887"
"26.88000","2.24019","0.00914"
"27.09000","2.25771","0.00900"
"27.30000","2.27511","0.00901"
"27.51000","2.29269","0.00886"
"27.72000","2.31021","0.00869"
"27.93000","2.32761","0.00826"
"28.14000","2.34524","0.00906"
"28.35000","2.36264","0.00892"
"28.56000","2.38022","0.00833"
"28.77000","2.39768","0.00828"
"28.98000","2.41520","0.00874"
"29.19000","2.43266","0.00902"
"29.40000","2.45017","0.00947"
"29.61000","2.46763","0.00820"
"29.82000","2.48521","0.00900"
"30.03000","2.50267","0.00877"
"30.24000","2.52019","0.00878"
"30.45000","2.53771","0.00897"
"30.66000","2.55517","0.00951"
"30.87000","2.57274","0.00863"
"31.08000","2.59014","0.00900"
"31.29000","2.60766","0.00876"
"31.50000","2.62518","0.00877"
"31.71000","2.64264","0.00897"
"31.92000","2.66016","0.00883"
"32.13000","2.67761","0.00958"
"32.34000","2.69519","0.00930"
"32.55000","2.71265","0.00915"
"32.76000","2.73011","0.00901"
"32.97000","2.74769","0.00912"
"33.18000","2.76521","0.00910"
"33.39000","2.78266","0.00969"
"33.60000","2.80018","0.00911"
"33.81000","2.81758","0.00946"
"34.02000","2.83522","0.00953"
"34.23000","2.85268","0.00889"
"34.44000","2.87020","0.00892"
"34.65000","2.88771","0.00896"
"34.86000","2.90517","0.00884"
"35.07000","2.92269","0.01005"
"35.28000","2.94021","0.00923"
"35.49000","2.95767","0.00971"
"35.70000","2.97519","0.00972"
"35.91000","2.99265","0.00922"
"36.12000","3.01016","0.00944"
"36.33000","3.02768","0.00959"
"36.54000","3.04508","0.00919"
"36.75000","3.06272","0.00971"
"36.96000","3.08012","0.00945"
"37.17000","3.09776","0.00922"
"37.38000","3.11515","0.00904"
"37.59000","3.13267","0.00962"
"37.80000","3.15019","0.00932"
"38.01000","3.16765","0.00910"
"38.22000","3.18511","0.00884"
"38.43000","3.20275","0.00923"
"38.64000","3.22009","0.00928"
"38.85000","3.23766","0.00931"
"39.06000","3.25518","0.00965"
"39.27000","3.27264","0.00902"
"39.48000","3.29022","0.00973"
"39.69000","3.30768","0.00934"
"39.90000","3.32520","0.00965"
"40.11000","3.34265","0.00937"
"40.32000","3.36017","0.00926"
"40.53000","3.37763","0.00892"
"40.74000","3.39521","0.00931"
"40.95000","3.41273","0.00951"
"41.16000","3.43019","0.00944"
"41.37000","3.44764","0.00948"
"41.58000","3.46522","0.00866"
"41.79000","3.48262","0.00882"
"42.00000","3.50014","0.00921"
"42.21000","3.51766","0.00944"
"42.42000","3.53506","0.00922"
"42.63000","3.55269","0.00916"
"42.84000","3.57009","0.00943"
"43.05000","3.58761","0.00934"
"43.26000","3.60519","0.00961"
"43.47000","3.62259","0.00872"
"43.68000","3.64023","0.00875"
"43.89000","3.65768","0.00968"
"44.10000","3.67514","0.00906"
"44.31000","3.69272","0.00872"
"44.52000","3.71012","0.00906"
"44.73000","3.72770","0.00908"
"44.94000","3.74522","0.00944"
"45.15000","3.76262","0.00934"
"45.36000","3.78019","0.00985"
"45.57000","3.79765","0.00968"
"45.78000","3.81523","0.00926"
"45.99000","3.83269","0.00910"
"46.20000","3.85015","0.00986"
"46.41000","3.86767","0.00908"
"46.62000","3.88512","0.00929"
"46.83000","3.90264","0.00946"
"47.04000","3.92022","0.00941"
"47.25000","3.93768","0.00954"
"47.46000","3.95520","0.00893"
"47.67000","3.97266","0.00921"
"47.88000","3.99017","0.00915"
"48.09000","4.00775","0.00893"
"48.30000","4.02509","0.00975"
"48.51000","4.04273","0.00909"
"48.72000","4.06019","0.00922"
"48.93000","4.07765","0.00899"
"49.14000","4.09516","0.00942"
"49.35000","4.11268","0.00955"
"49.56000","4.13020","0.00917"
"49.77000","4.14766","0.00955"
"49.98000","4.16512","0.00937"
"50.19000","4.18270","0.00954"
"50.40000","4.20015","0.00931"
"50.61000","4.21767","0.00981"
"50.82000","4.23519","0.00900"
"51.03000","4.25259","0.00911"
"51.24000","4.27017","0.00925"
"51.45000","4.28763","0.00939"
"51.66000","4.30521","0.00928"
"51.87000","4.32266","0.00929"
"52.08000","4.34018","0.00970"
"52.29000","4.35770","0.00954"
"52.50000","4.37522","0.00894"
"52.71000","4.39268","0.00932"
"52.92000","4.41020","0.00924"
"53.13000","4.42759","0.00910"
"53.34000","4.44523","0.00952"
"53.55000","4.46275","0.01020"
"53.76000","4.48015","0.01002"
"53.97000","4.49773","0.00980"
"54.18000","4.51513","0.00859"
"54.39000","4.53270","0.00881"
"54.60000","4.55022","0.00831"
"54.81000","4.56762","0.00860"
"55.02000","4.58520","0.00855"
"55.23000","4.60266","0.00844"
"55.44000","4.62018","0.00851"
"55.65000","4.63769","0.00809"
"55.86000","4.65509","0.00832"
"56.07000","4.67273","0.00788"
"56.28000","4.69019","0.00843"
"56.49000","4.70765","0.00845"
"56.70000","4.72523","0.00826"
"56.91000","4.74263","0.00865"
"57.12000","4.76020","0.00874"
"57.33000","4.77760","0.00927"
"57.54000","4.79518","0.00778"
"57.75000","4.81264","0.00861"
"57.96000","4.83022","0.00844"
"58.17000","4.84768","0.00849"
"58.38000","4.86519","0.00849"
"58.59000","4.88265","0.00857"
"58.80000","4.90023","0.00833"
"59.01000","4.91769","0.00828"
"59.22000","4.93521","0.00867"
"59.43000","4.95267","0.00809"
"59.64000","4.97006","0.00812"
"59.85000","4.98770","0.00865"
"60.06000","5.00516","0.00849"
"60.27000","5.02268","0.00831"
"60.48000","5.04020","0.00910"
"60.69000","5.05760","0.00883"
"60.90000","5.07517","0.00850"
"61.11000","5.09269","0.00839"
"61.32000","5.11015","0.00831"
"61.53000","5.12767","0.00843"
"61.74000","5.14507","0.00884"
"61.95000","5.16271","0.00849"
"62.16000","5.18017","0.00890"
"62.37000","5.19762","0.00874"
"62.58000","5.21520","0.00861"
"62.79000","5.23266","0.00866"
"63.00000","5.25018","0.00892"
"63.21000","5.26770","0.00906"
"63.42000","5.28516","0.00856"
"63.63000","5.30267","0.00846"
"63.84000","5.32013","0.00877"
"64.05000","5.33765","0.00908"
"64.26000","5.35523","0.00861"
"64.47000","5.37263","0.00900"
"64.68000","5.39021","0.00845"
"64.89000","5.40766","0.00858"
"65.10000","5.42512","0.00901"
"65.31000","5.44270","0.00904"
"65.52000","5.46010","0.00875"
"65.73000","5.47768","0.00856"
"65.94000","5.49514","0.00854"
"66.15000","5.51265","0.00962"
"66.36000","5.53023","0.00847"
"66.57000","5.54769","0.00911"
"66.78000","5.56521","0.00851"
"66.99000","5.58267","0.00843"
"67.20000","5.60013","0.00897"
"67.41000","5.61771","0.00864"
"67.62000","5.63516","0.00882"
"67.83000","5.65268","0.00859"
"68.04000","5.67014","0.00887"
"68.25000","5.68760","0.00886"
"68.46000","5.70518","0.00873"
"68.67000","5.72264","0.00886"
"68.88000","5.74015","0.00866"
"69.09000","5.75767","0.00874"
"69.30000","5.77519","0.00870"
"69.51000","5.79271","0.00817"
"69.72000","5.81023","0.00827"
"69.93000","5.82769","0.00895"
"70.14000","5.84514","0.00830"
"70.35000","5.86260","0.00876"
"70.56000","5.88024","0.00818"
"70.77000","5.89770","0.00860"
"70.98000","5.91510","0.00877"
"71.19000","5.93274","0.00848"
"71.40000","5.95014","0.00869"
"71.61000","5.96771","0.00827"
"71.82000","5.98523","0.00872"
"72.03000","6.00263","0.00822"
"72.24000","6.02015","0.00845"
"72.45000","6.03761","0.00865"
"72.66000","6.05518","0.00845"
"72.87000","6.07276","0.00927"
"73.08000","6.09010","0.00853"
"73.29000","6.10768","0.00901"
"73.50000","6.12514","0.00865"
"73.71000","6.14266","0.00864"
"73.92000","6.16024","0.00850"
"74.13000","6.17763","0.00864"
"74.34000","6.19515","0.00884"
"74.55000","6.21267","0.00874"
"74.76000","6.23019","0.00889"
"74.97000","6.24765","0.00852"
"75.18000","6.26517","0.00908"
"75.39000","6.28268","0.00815"
"75.60000","6.30014","0.00919"
"75.81000","6.31766","0.00903"
"76.02000","6.33518","0.00857"
"76.23000","6.35264","0.00888"
"76.44000","6.37016","0.00876"
"76.65000","6.38767","0.00838"
"76.86000","6.40513","0.00825"
"77.07000","6.42271","0.00886"
"77.28000","6.44011","0.00935"
"77.49000","6.45769","0.00872"
"77.70000","6.47521","0.00922"
"77.91000","6.49266","0.00857"
"78.12000","6.51018","0.00854"
"78.33000","6.52770","0.00874"
"78.54000","6.54516","0.00902"
"78.75000","6.56268","0.00912"
"78.96000","6.58014","0.00885"
"79.17000","6.59771","0.00888"
"79.38000","6.61517","0.00932"
"79.59000","6.63263","0.00916"
"79.80000","6.65021","0.00886"
"80.01000","6.66767","0.00885"
"80.22000","6.68525","0.00910"
"80.43000","6.70265","0.00900"
"80.64000","6.72016","0.00916"
"80.85000","6.73768","0.00842"
"81.06000","6.75514","0.00869"
"81.27000","6.77260","0.00931"
"81.48000","6.79024","0.00897"
"81.69000","6.80758","0.00882"
"81.90000","6.82521","0.00895"
"82.11000","6.84267","0.00822"
"82.32000","6.86013","0.00834"
"82.53000","6.87771","0.00846"
"82.74000","6.89511","0.00852"
"82.95000","6.91263","0.00837"
"83.16000","6.93015","0.00855"
"83.37000","6.94760","0.00932"
"83.58000","6.96518","0.00904"
"83.79000","6.98264","0.00856"
"84.00000","7.00022","0.00928"
"84.21000","7.01774","0.00908"
"84.42000","7.03514","0.00949"
"84.63000","7.05271","0.00920"
"84.84000","7.07017","0.00887"
"85.05000","7.08769","0.00938"
"85.26000","7.10521","0.00951"
"85.47000","7.12261","0.00949"
"85.68000","7.14019","0.00910"
"85.89000","7.15764","0.00922"
"86.10000","7.17516","0.00926"
"86.31000","7.19268","0.00915"
"86.52000","7.21014","0.00902"
"86.73000","7.22772","0.00914"
"86.94000","7.24518","0.00933"
"87.15000","7.26264","0.00945"
"87.36000","7.28021","0.00959"
"87.57000","7.29761","0.00958"
"87.78000","7.31519","0.00924"
"87.99000","7.33271","0.00958"
"88.20000","7.35011","0.00976"
"88.41000","7.36769","0.00976"
"88.62000","7.38520","0.00908"
"88.83000","7.40272","0.00998"
"89.04000","7.42018","0.00925"
"89.25000","7.43764","0.00927"
"89.46000","7.45516","0.00938"
"89.67000","7.47268","0.01015"
"89.88000","7.49019","0.00983"
"90.09000","7.50771","0.00954"
"90.30000","7.52511","0.00959"
"90.51000","7.54269","0.01000"
"90.72000","7.56015","0.00991"
"90.93000","7.57767","0.00963"
"91.14000","7.59518","0.01002"
"91.35000","7.61264","0.01004"
"91.56000","7.63022","0.00974"
"91.77000","7.64768","0.00903"
"91.98000","7.66520","0.00973"
"92.19000","7.68266","0.00987"
"92.40000","7.70018","0.00985"
"92.61000","7.71769","0.00912"
"92.82000","7.73515","0.00911"
"93.03000","7.75261","0.00977"
"93.24000","7.77013","0.00941"
"93.45000","7.78765","0.00933"
"93.66000","7.80517","0.00938"
"93.87000","7.82268","0.00932"
"94.08000","7.84008","0.00928"
"94.29000","7.85772","0.01010"
"94.50000","7.87512","0.00973"
"94.71000","7.89270","0.00972"
"94.92000","7.91021","0.00988"
"95.13000","7.92767","0.00995"
"95.34000","7.94525","0.01002"
"95.55000","7.96271","0.01016"
"95.76000","7.98017","0.00978"
"95.97000","7.99769","0.00979"
"96.18000","8.01509","0.00980"
"96.39000","8.03272","0.00998"
"96.60000","8.05018","0.00979"
"96.81000","8.06764","0.01011"
"97.02000","8.08522","0.01030"
"97.23000","8.10262","0.00957"
"97.44000","8.12020","0.00914"
"97.65000","8.13765","0.00694"
"97.86000","8.15511","0.01028"
"98.07000","8.17269","0.00750"
"98.28000","8.19021","0.00965"
"98.49000","8.20767","0.00824"
"98.70000","8.22525","0.00979"
"98.91000","8.24264","0.00830"
"99.12000","8.26016","0.00951"
"99.33000","8.27768","0.00954"
"99.54000","8.29514","0.00970"
"99.75000","8.31272","0.00864"
"99.96000","8.33012","0.00999"
"100.17000","8.34769","0.00932"
"100.38000","8.36515","0.00948"
"100.59000","8.38261","0.01007"
"100.80000","8.40019","0.00886"
"101.01000","8.41771","0.00922"
"101.22000","8.43517","0.00907"
"101.43000","8.45269","0.00859"
"101.64000","8.47014","0.00929"
"101.85000","8.48772","0.00756"
"102.06000","8.50518","0.00870"
"102.27000","8.52264","0.00762"
"102.48000","8.54016","0.00833"
"102.69000","8.55768","0.00808"
"102.90000","8.57519","0.00832"
"103.11000","8.59265","0.00833"
"103.32000","8.61017","0.00774"
"103.53000","8.62769","0.00714"
"103.74000","8.64515","0.00615"
"103.95000","8.66273","0.00631"
"104.16000","8.68018","0.00683"
"104.37000","8.69764","0.00488"
"104.58000","8.71516","0.00553"
"104.79000","8.73262","0.00585"
"105.00000","8.75020","0.00574"
"105.21000","8.76772","0.00459"
"105.42000","8.78512","0.00577"
"105.63000","8.80269","0.00573"
"105.84000","8.82015","0.00477"
"106.05000","8.83773","0.00538"
"106.26000","8.85513","0.00551"
"106.47000","8.87265","0.00555"
"106.68000","8.89017","0.00558"
"106.89000","8.90768","0.00525"
"107.10000","8.92514","0.00555"
"107.31000","8.94272","0.00590"
"107.52000","8.96012","0.00521"
"107.73000","8.97770","0.00598"
"107.94000","8.99522","0.00651"
"108.15000","9.01267","0.00557"
"108.36000","9.03019","0.00591"
"108.57000","9.04765","0.00647"
"108.78000","9.06517","0.00489"
"108.99000","9.08263","0.00477"
"109.20000","9.10021","0.00578"
"109.41000","9.11766","0.00572"
"109.62000","9.13518","0.00619"
"109.83000","9.15270","0.00491"
"110.04000","9.17016","0.00432"
"110.25000","9.18762","0.00651"
"110.46000","9.20520","0.00482"
"110.67000","9.22265","0.00557"
"110.88000","9.24017","0.00677"
"111.09000","9.25763","0.00595"
"111.30000","9.27509","0.00627"
"111.51000","9.29273","0.00570"
"111.72000","9.31013","0.00588"
"111.93000","9.32765","0.00622"
"112.14000","9.34522","0.00581"
"112.35000","9.36262","0.00646"
"112.56000","9.38020","0.00563"
"112.77000","9.39772","0.00610"
"112.98000","9.41518","0.00642"
"113.19000","9.43270","0.00641"
"113.40000","9.45010","0.00616"
"113.61000","9.46767","0.00674"
"113.82000","9.48519","0.00640"
"114.03000","9.50259","0.00638"
"114.24000","9.52023","0.00695"
"114.45000","9.53763","0.00665"
"114.66000","9.55520","0.00715"
"114.87000","9.57266","0.00671"
"115.08000","9.59018","0.00723"
"115.29000","9.60770","0.00740"
"115.50000","9.62516","0.00706"
"115.71000","9.64268","0.00705"
"115.92000","9.66019","0.00755"
"116.13000","9.67765","0.00770"
"116.34000","9.69523","0.00687"
"116.55000","9.71269","0.00755"
"116.76000","9.73015","0.00775"
"116.97000","9.74773","0.00730"
"117.18000","9.76513","0.00733"
"117.39000","9.78270","0.00761"
"117.60000","9.80016","0.00776"
"117.81000","9.81768","0.00720"
"118.02000","9.83514","0.00764"
"118.23000","9.85266","0.00753"
"118.44000","9.87012","0.00755"
"118.65000","9.88769","0.00783"
"118.86000","9.90509","0.00767"
"119.07000","9.92267","0.00792"
"119.28000","9.94013","0.00828"
"119.49000","9.95771","0.00770"
"119.70000","9.97517","0.00764"
"119.91000","9.99262","0.00801"
"120.12000","10.01020","0.00811"
"120.33000","10.02760","0.00827"
"120.54000","10.04518","0.00757"
"120.75000","10.06270","0.00851"
"120.96000","10.08016","0.00771"
"121.17000","10.09768","0.00807"
"121.38000","10.11519","0.00839"
"121.59000","10.13265","0.00833"
"121.80000","10.15017","0.00802"
"122.01000","10.16763","0.00852"
"122.22000","10.18521","0.00792"
"122.43000","10.20267","0.00839"
"122.64000","10.22012","0.00773"
"122.85000","10.23770","0.00744"
"123.06000","10.25516","0.00808"
"123.27000","10.27268","0.00822"
"123.48000","10.29020","0.00842"
"123.69000","10.30766","0.00803"
"123.90000","10.32517","0.00753"
"124.11000","10.34269","0.00831"
"124.32000","10.36015","0.00874"
"124.53000","10.37773","0.00806"
"124.74000","10.39513","0.00834"
"124.95000","10.41271","0.00794"
"125.16000","10.43016","0.00805"
"125.37000","10.44768","0.00844"
"125.58000","10.46520","0.00832"
"125.79000","10.48260","0.00861"
"126.00000","10.50018","0.00879"
"126.21000","10.51764","0.00832"
"126.42000","10.53522","0.00927"
"126.63000","10.55267","0.00868"
"126.84000","10.57019","0.00893"
"127.05000","10.58771","0.00911"
"127.26000","10.60517","0.00881"
"127.47000","10.62269","0.00872"
"127.68000","10.64020","0.00946"
"127.89000","10.65766","0.00895"
"128.10001","10.67518","0.00853"
"128.31000","10.69270","0.00884"
"128.52000","10.71010","0.00883"
"128.73000","10.72768","0.00888"
"128.94000","10.74514","0.00947"
"129.14999","10.76265","0.00900"
"129.36000","10.78017","0.00933"
"129.57001","10.79763","0.00948"
"129.78000","10.81521","0.00955"
"129.99001","10.83273","0.00940"
"130.20000","10.85013","0.00943"
"130.41000","10.86770","0.00974"
"130.62000","10.88510","0.00931"
"130.83000","10.90268","0.00998"
"131.03999","10.92020","0.00930"
"131.25000","10.93760","0.00897"
"131.46001","10.95518","0.00958"
"131.67000","10.97263","0.01004"
"131.88000","10.99021","0.00994"
"132.09000","11.00767","0.00970"
"132.30000","11.02513","0.01008"
"132.50999","11.04271","0.00965"
"132.72000","11.06011","0.01010"
"132.92999","11.07769","0.01025"
"133.14000","11.09520","0.01024"
"133.35001","11.11266","0.01043"
"133.56000","11.13018","0.01009"
"133.77000","11.14770","0.01039"
"133.98000","11.16510","0.01059"
"134.19000","11.18274","0.01065"
"134.39999","11.20008","0.01098"
"134.61000","11.21771","0.01059"
"134.82001","11.23517","0.01095"
"135.03000","11.25269","0.00997"
"135.24001","11.27015","0.01106"
"135.45000","11.28773","0.01037"
"135.66000","11.30519","0.01051"
"135.87000","11.32270","0.01104"
"136.08000","11.34016","0.01112"
"136.28999","11.35768","0.01116"
"136.50000","11.37514","0.01122"
"136.71001","11.39266","0.01078"
"136.92000","11.41017","0.01121"
"137.13000","11.42757","0.01061"
"137.34000","11.44521","0.01108"
"137.55000","11.46261","0.01102"
"137.75999","11.48019","0.01099"
"137.97000","11.49765","0.01110"
"138.17999","11.51517","0.01083"
"138.39000","11.53268","0.00984"
"138.60001","11.55020","0.01033"
"138.81000","11.56766","0.01024"
"139.02000","11.58518","0.00984"
"139.23000","11.60264","0.01032"
"139.44000","11.62022","0.01024"
"139.64999","11.63773","0.01076"
"139.86000","11.65513","0.01010"
"140.07001","11.67265","0.01094"
"140.28000","11.69017","0.01034"
"140.49001","11.70769","0.01029"
"140.70000","11.72521","0.01070"
"140.91000","11.74266","0.01049"
"141.12000","11.76018","0.01113"
"141.33000","11.77770","0.01027"
"141.53999","11.79516","0.01070"
"141.75000","11.81274","0.00937"
"141.96001","11.83008","0.01041"
"142.17000","11.84771","0.00836"
"142.38000","11.86517","0.00784"
"142.59000","11.88263","0.00803"
"142.80000","11.90021","0.00799"
"143.00999","11.91761","0.00814"
"143.22000","11.93525","0.00841"
"143.42999","11.95265","0.00803"
"143.64000","11.97016","0.00840"
"143.85001","11.98768","0.00902"
"144.06000","12.00514","0.00877"
"144.27000","12.02272","0.00821"
"144.48000","12.04018","0.00875"
"144.69000","12.05764","0.00872"
"144.89999","12.07521","0.00867"
"145.11000","12.09267","0.00935"
"145.32001","12.11019","0.00886"
"145.53000","12.12771","0.00886"
"145.74001","12.14511","0.00883"
"145.95000","12.16275","0.00932"
"146.16000","12.18014","0.00876"
"146.37000","12.19766","0.00861"
"146.58000","12.21518","0.00867"
"146.78999","12.23264","0.00970"
"147.00000","12.25022","0.00963"
"147.21001","12.26768","0.00905"
"147.42000","12.28513","0.00926"
"147.63000","12.30271","0.00926"
"147.84000","12.32017","0.00909"
"148.05000","12.33769","0.00950"
"148.25999","12.35521","0.00927"
"148.47000","12.37267","0.00950"
"148.67999","12.39019","0.00885"
"148.89000","12.40764","0.00880"
"149.10001","12.42522","0.00939"
"149.31000","12.44268","0.00988"
"149.52000","12.46014","0.00964"
"149.73000","12.47766","0.00963"
"149.94000","12.49512","0.00963"
"150.14999","12.51263","0.00932"
"150.36000","12.53021","0.00998"
"150.57001","12.54761","0.00985"
"150.78000","12.56519","0.00971"
"150.99001","12.58271","0.00925"
"151.20000","12.60017","0.00979"
"151.41000","12.61768","0.00948"
"151.62000","12.63514","0.00982"
"151.83000","12.65266","0.00952"
"152.03999","12.67018","0.00938"
"152.25000","12.68764","0.00949"
"152.46001","12.70516","0.00978"
"152.67000","12.72267","0.00958"
"152.88000","12.74019","0.00942"
"153.09000","12.75771","0.00941"
"153.30000","12.77517","0.00928"
"153.50999","12.79269","0.00959"
"153.72000","12.81015","0.00911"
"153.92999","12.82766","0.00894"
"154.14000","12.84518","0.00936"
"154.35001","12.86258","0.00906"
"154.56000","12.88022","0.00950"
"154.77000","12.89762","0.00944"
"154.98000","12.91520","0.00896"
"155.19000","12.93272","0.00909"
"155.39999","12.95012","0.00950"
"155.61000","12.96769","0.00920"
"155.82001","12.98521","0.00917"
"156.03000","13.00267","0.00937"
"156.24001","13.02019","0.00936"
"156.45000","13.03759","0.00931"
"156.66000","13.05522","0.00915"
"156.87000","13.07268","0.00943"
"157.08000","13.09008","0.00922"
"157.28999","13.10772","0.00946"
"157.50000","13.12512","0.00968"
"157.71001","13.14270","0.00965"
"157.92000","13.16016","0.01009"
"158.13000","13.17767","0.00967"
"158.34000","13.19519","0.00973"
"158.55000","13.21265","0.00910"
"158.75999","13.23017","0.00966"
"158.97000","13.24775","0.01003"
"159.17999","13.26515","0.00970"
"159.39000","13.28272","0.00872"
"159.60001","13.30018","0.01071"
"159.81000","13.31764","0.00766"
"160.02000","13.33522","0.00892"
"160.23000","13.35262","0.01031"
"160.44000","13.37020","0.00831"
"160.64999","13.38765","0.00765"
"160.86000","13.40517","0.00901"
"161.07001","13.42269","0.00808"
"161.28000","13.44015","0.00913"
"161.49001","13.45767","0.00884"
"161.70000","13.47519","0.00885"
"161.91000","13.49258","0.00854"
"162.12000","13.51022","0.00908"
"162.33000","13.52768","0.00927"
"162.53999","13.54520","0.00865"
"162.75000","13.56266","0.00860"
"162.96001","13.58012","0.00923"
"163.17000","13.59770","0.00991"
"163.38000","13.61515","0.00932"
"163.59000","13.63267","0.00925"
"163.80000","13.65019","0.00955"
"164.00999","13.66765","0.01033"
"164.22000","13.68517","0.00983"
"164.42999","13.70268","0.00959"
"164.64000","13.72014","0.00962"
"164.85001","13.73766","0.00961"
"165.06000","13.75518","0.01009"
"165.27000","13.77270","0.01004"
"165.48000","13.79022","0.00996"
"165.69000","13.80762","0.00995"
"165.89999","13.82525","0.01006"
"166.11000","13.84265","0.01067"
"166.32001","13.86023","0.01047"
"166.53000","13.87763","0.01062"
"166.74001","13.89515","0.01061"
"166.95000","13.91267","0.01108"
"167.16000","13.93013","0.01047"
"167.37000","13.94758","0.01117"
"167.58000","13.96522","0.01064"
"167.78999","13.98256","0.01091"
"168.00000","14.00020","0.01099"
"168.21001","14.01766","0.01113"
"168.42000","14.03518","0.01145"
"168.63000","14.05269","0.01042"
"168.84000","14.07015","0.01116"
"169.05000","14.08767","0.01100"
"169.25999","14.10519","0.01157"
"169.47000","14.12271","0.01111"
"169.67999","14.14016","0.01127"
"169.89000","14.15768","0.01151"
"170.10001","14.17520","0.01200"
"170.31000","14.19266","0.01208"
"170.52000","14.21012","0.01160"
"170.73000","14.22770","0.01165"
"170.94000","14.24516","0.01120"
"171.14999","14.26267","0.01059"
"171.36000","14.28019","0.01126"
"171.57001","14.29759","0.01156"
"171.78000","14.31523","0.01140"
"171.99001","14.33263","0.01087"
"172.20000","14.35015","0.01118"
"172.41000","14.36772","0.01101"
"172.62000","14.38512","0.01158"
"172.83000","14.40270","0.01224"
"173.03999","14.42016","0.01129"
"173.25000","14.43762","0.01168"
"173.46001","14.45520","0.01222"
"173.67000","14.47259","0.01172"
"173.88000","14.49017","0.01181"
"174.09000","14.50769","0.01160"
"174.30000","14.52509","0.01203"
"174.50999","14.54267","0.01207"
"174.72000","14.56019","0.01180"
"174.92999","14.57770","0.01209"
"175.14000","14.59516","0.01190"
"175.35001","14.61262","0.01190"
"175.56000","14.63014","0.01223"
"175.77000","14.64766","0.01163"
"175.98000","14.66518","0.01201"
"176.19000","14.68270","0.01235"
"176.39999","14.70015","0.01293"
"176.61000","14.71767","0.01201"
"176.82001","14.73519","0.01186"
"177.03000","14.75265","0.01219"
"177.24001","14.77023","0.01214"
"177.45000","14.78757","0.01203"
"177.66000","14.80520","0.01224"
"177.87000","14.82266","0.01238"
"178.08000","14.84018","0.01210"
"178.28999","14.85764","0.01254"
"178.50000","14.87516","0.01285"
"178.71001","14.89268","0.01209"
"178.92000","14.91020","0.01241"
"179.13000","14.92765","0.01223"
"179.34000","14.94517","0.01244"
"179.55000","14.96263","0.01273"
"179.75999","14.98015","0.01280"
"179.97000","14.99767","0.01222"
"180.17999","15.01513","0.01293"
"180.39000","15.03264","0.01268"
"180.60001","15.05010","0.01295"
"180.81000","15.06768","0.01330"
"181.02000","15.08520","0.01316"
"181.23000","15.10266","0.01294"
"181.44000","15.12018","0.01253"
"181.64999","15.13769","0.01278"
"181.86000","15.15515","0.01294"
"182.07001","15.17267","0.01301"
"182.28000","15.19013","0.01310"
"182.49001","15.20771","0.01289"
"182.70000","15.22523","0.01332"
"182.91000","15.24263","0.01392"
"183.12000","15.26020","0.01365"
"183.33000","15.27766","0.01346"
"183.53999","15.29524","0.01340"
"183.75000","15.31270","0.01391"
"183.96001","15.33016","0.01367"
"184.17000","15.34774","0.01362"
"184.38000","15.36513","0.01372"
"184.59000","15.38265","0.01391"
"184.80000","15.40023","0.01384"
"185.00999","15.41757","0.01404"
"185.22000","15.43521","0.01449"
"185.42999","15.45266","0.01385"
"185.64000","15.47012","0.01408"
"185.85001","15.48770","0.01460"
"186.06000","15.50516","0.01409"
"186.27000","15.52274","0.01414"
"186.48000","15.54014","0.01442"
"186.69000","15.55766","0.01429"
"186.89999","15.57517","0.01398"
"187.11000","15.59269","0.01430"
"187.32001","15.61015","0.01447"
"187.53000","15.62773","0.01449"
"187.74001","15.64519","0.01486"
"187.95000","15.66271","0.01465"
"188.16000","15.68016","0.01471"
"188.37000","15.69768","0.01473"
"188.58000","15.71520","0.01532"
"188.78999","15.73260","0.01452"
"189.00000","15.75018","0.01520"
"189.21001","15.76764","0.01521"
"189.42000","15.78515","0.01517"
"189.63000","15.80273","0.01563"
"189.84000","15.82013","0.01508"
"190.05000","15.83771","0.01512"
"190.25999","15.85517","0.01479"
"190.47000","15.87263","0.01519"
"190.67999","15.89020","0.01539"
"190.89000","15.90760","0.01591"
"191.10001","15.92518","0.01534"
"191.31000","15.94270","0.01584"
"191.52000","15.96010","0.01585"
"191.73000","15.97774","0.01582"
"191.94000","15.99520","0.01548"
"192.14999","16.01271","0.01542"
"192.36000","16.03017","0.01533"
"192.57001","16.04769","0.01601"
"192.78000","16.06515","0.01609"
"192.99001","16.08267","0.01670"
"193.20000","16.10019","0.01596"
"193.41000","16.11764","0.01643"
"193.62000","16.13510","0.01629"
"193.83000","16.15268","0.01628"
"194.03999","16.17020","0.01632"
"194.25000","16.18766","0.01703"
"194.46001","16.20523","0.01667"
"194.67000","16.22263","0.01684"
"194.88000","16.24021","0.01700"
"195.09000","16.25767","0.01697"
"195.30000","16.27519","0.01728"
"195.50999","16.29271","0.01744"
"195.72000","16.31017","0.01726"
"195.92999","16.32768","0.01734"
"196.14000","16.34520","0.01735"
"196.35001","16.36266","0.01761"
"196.56000","16.38024","0.01750"
"196.77000","16.39764","0.01793"
"196.98000","16.41522","0.01765"
"197.19000","16.43267","0.01791"
"197.39999","16.45013","0.01811"
"197.61000","16.46771","0.01805"
"197.82001","16.48511","0.01830"
"198.03000","16.50269","0.01824"
"198.24001","16.52021","0.01869"
"198.45000","16.53766","0.01838"
"198.66000","16.55518","0.01872"
"198.87000","16.57270","0.01858"
"199.08000","16.59016","0.01882"
"199.28999","16.60768","0.01913"
"199.50000","16.62514","0.01853"
"199.71001","16.64272","0.01910"
"199.92000","16.66017","0.01956"
"200.13000","16.67763","0.01928"
"200.34000","16.69521","0.01885"
"200.55000","16.71261","0.01887"
"200.75999","16.73019","0.01887"
"200.97000","16.74771","0.01943"
"201.17999","16.76516","0.01879"
"201.39000","16.78268","0.01937"
"201.60001","16.80014","0.01923"
"201.81000","16.81766","0.01890"
"202.02000","16.83524","0.01875"
"202.23000","16.85264","0.01903"
"202.44000","16.87021","0.01953"
"202.64999","16.88767","0.01956"
"202.86000","16.90513","0.02006"
"203.07001","16.92271","0.01952"
"203.28000","16.94011","0.02022"
"203.49001","16.95769","0.01975"
"203.70000","16.97515","0.02063"
"203.91000","16.99266","0.02019"
"204.12000","17.01018","0.02079"
"204.33000","17.02770","0.02082"
"204.53999","17.04522","0.02071"
"204.75000","17.06268","0.02119"
"204.96001","17.08019","0.02126"
"205.17000","17.09771","0.02178"
"205.38000","17.11517","0.02152"
"205.59000","17.13269","0.02228"
"205.80000","17.15015","0.02176"
"206.00999","17.16761","0.02246"
"206.22000","17.18518","0.02230"
"206.42999","17.20258","0.02276"
"206.64000","17.22022","0.02252"
"206.85001","17.23768","0.02247"
"207.06000","17.25520","0.02244"
"207.27000","17.27266","0.02317"
"207.48000","17.29018","0.02306"
"207.69000","17.30770","0.02341"
"207.89999","17.32521","0.02414"
"208.11000","17.34261","0.02368"
"208.32001","17.36019","0.02402"
"208.53000","17.37765","0.02477"
"208.74001","17.39511","0.02461"
"208.95000","17.41269","0.02479"
"209.16000","17.43014","0.02526"
"209.37000","17.44772","0.02584"
"209.58000","17.46518","0.02593"
"209.78999","17.48270","0.02576"
"210.00000","17.50016","0.02647"
"210.21001","17.51768","0.02634"
"210.42000","17.53513","0.02691"
"210.63000","17.55271","0.02719"
"210.84000","17.57011","0.02775"
"211.05000","17.58769","0.02763"
"211.25999","17.60515","0.02770"
"211.47000","17.62267","0.02769"
"211.67999","17.64024","0.02818"
"211.89000","17.65764","0.02821"
"212.10001","17.67516","0.02887"
"212.31000","17.69268","0.02936"
"212.52000","17.71014","0.02972"
"212.73000","17.72766","0.02930"
"212.94000","17.74512","0.03026"
"213.14999","17.76269","0.03045"
"213.36000","17.78021","0.03080"
"213.57001","17.79767","0.03092"
"213.78000","17.81525","0.03128"
"213.99001","17.83265","0.02940"
"214.20000","17.85016","0.03070"
"214.41000","17.86768","0.03026"
"214.62000","17.88508","0.03093"
"214.83000","17.90266","0.03218"
"215.03999","17.92012","0.03216"
"215.25000","17.93770","0.03273"
"215.46001","17.95516","0.03309"
"215.67000","17.97261","0.03360"
"215.88000","17.99019","0.03419"
"216.09000","18.00771","0.03479"
"216.30000","18.02517","0.03541"
"216.50999","18.04269","0.03608"
"216.72000","18.06015","0.03613"
"216.92999","18.07772","0.03650"
"217.14000","18.09518","0.03735"
"217.35001","18.11258","0.03722"
"217.56000","18.13022","0.03830"
"217.77000","18.14768","0.03774"
"217.98000","18.16520","0.03865"
"218.19000","18.18265","0.03869"
"218.39999","18.20017","0.03834"
"218.61000","18.21769","0.01573"
"218.82001","18.23515","0.02374"
"219.03000","18.25267","0.01619"
"219.24001","18.27025","0.02126"
"219.45000","18.28765","0.01653"
"219.66000","18.30522","0.02120"
"219.87000","18.32268","0.01689"
"220.08000","18.34014","0.01760"
"220.28999","18.35772","0.01742"
"220.50000","18.37512","0.01442"
"220.71001","18.39269","0.01273"
"220.92000","18.41015","0.01254"
"221.13000","18.42767","0.01217"
"221.34000","18.44513","0.01288"
"221.55000","18.46265","0.01319"
"221.75999","18.48017","0.01262"
"221.97000","18.49768","0.01305"
"222.17999","18.51514","0.01259"
"222.39000","18.53266","0.01245"
"222.60001","18.55012","0.01252"
"222.81000","18.56770","0.01314"
"223.02000","18.58516","0.01246"
"223.23000","18.60262","0.01344"
"223.44000","18.62020","0.01215"
"223.64999","18.63759","0.01393"
"223.86000","18.65517","0.01352"
"224.07001","18.67269","0.01306"
"224.28000","18.69015","0.01359"
"224.49001","18.70767","0.01336"
"224.70000","18.72519","0.01341"
"224.91000","18.74264","0.01401"
"225.12000","18.76016","0.01377"
"225.33000","18.77762","0.01465"
"225.53999","18.79520","0.01429"
"225.75000","18.81272","0.01420"
"225.96001","18.83011","0.01413"
"226.17000","18.84769","0.01415"
"226.38000","18.86515","0.01446"
"226.59000","18.88273","0.01438"
"226.80000","18.90013","0.01485"
"227.00999","18.91765","0.01505"
"227.22000","18.93517","0.01455"
"227.42999","18.95268","0.01514"
"227.64000","18.97014","0.01524"
"227.85001","18.98772","0.01481"
"228.06000","19.00512","0.00933"
"228.27000","19.02270","0.01304"
"228.48000","19.04016","0.00887"
"228.69000","19.05762","0.01117"
"228.89999","19.07519","0.01126"
"229.11000","19.09265","0.01115"
"229.32001","19.11017","0.01111"
"229.53000","19.12769","0.01061"
"229.74001","19.14515","0.01164"
"229.95000","19.16266","0.01080"
"230.16000","19.18018","0.01131"
"230.37000","19.19770","0.01006"
"230.58000","19.21522","0.01118"
"230.78999","19.23262","0.01124"
"231.00000","19.25020","0.01167"
"231.21001","19.26766","0.01130"
"231.42000","19.28517","0.01052"
"231.63000","19.30269","0.01185"
"231.84000","19.32009","0.01160"
"232.05000","19.33773","0.01175"
"232.25999","19.35513","0.01108"
"232.47000","19.37271","0.01077"
"232.67999","19.39022","0.01170"
"232.89000","19.40762","0.01324"
"233.10001","19.42520","0.01169"
"233.31000","19.44266","0.01122"
"233.52000","19.46018","0.01165"
"233.73000","19.47770","0.01271"
"233.94000","19.49509","0.01253"
"234.14999","19.51267","0.01161"
"234.36000","19.53019","0.01211"
"234.57001","19.54765","0.01237"
"234.78000","19.56523","0.01279"
"234.99001","19.58263","0.01189"
"235.20000","19.60020","0.01214"
"235.41000","19.61766","0.01204"
"235.62000","19.63518","0.01292"
"235.83000","19.65270","0.01239"
"236.03999","19.67016","0.01209"
"236.25000","19.68762","0.01238"
"236.46001","19.70519","0.01319"
"236.67000","19.72259","0.01151"
"236.88000","19.74017","0.01115"
"237.09000","19.75769","0.01131"
"237.30000","19.77515","0.01167"
"237.50999","19.79273","0.01179"
"237.72000","19.81013","0.01183"
"237.92999","19.82771","0.01190"
"238.14000","19.84516","0.01196"
"238.35001","19.86268","0.01209"
"238.56000","19.88020","0.01196"
"238.77000","19.89766","0.01124"
"238.98000","19.91518","0.01194"
"239.19000","19.93270","0.01143"
"239.39999","19.95015","0.01126"
"239.61000","19.96773","0.00599"
"239.82001","19.98519","0.00813"
"240.03000","20.00271","0.00558"
"240.24001","20.02017","0.00532"
"240.45000","20.03757","0.00541"
"240.66000","20.05520","0.00580"
"240.87000","20.07266","0.00706"
"241.08000","20.09012","0.00511"
"241.28999","20.10770","0.00500"
"241.50000","20.12510","0.00488"
"241.71001","20.14267","0.00600"
"241.92000","20.16019","0.00628"
"242.13000","20.17765","0.00537"
"242.34000","20.19517","0.00490"
"242.55000","20.21263","0.00557"
"242.75999","20.23021","0.00590"
"242.97000","20.24773","0.00543"
"243.17999","20.26513","0.00494"
"243.39000","20.28276","0.00572"
"243.60001","20.30016","0.00514"
"243.81000","20.31774","0.00561"
"244.02000","20.33514","0.00574"
"244.23000","20.35266","0.00531"
"244.44000","20.37017","0.00535"
"244.64999","20.38763","0.00538"
"244.86000","20.40521","0.00570"
"245.07001","20.42273","0.00546"
"245.28000","20.44013","0.00548"
"245.49001","20.45771","0.00489"
"245.70000","20.47517","0.00552"
"245.91000","20.49262","0.00535"
"246.12000","20.51020","0.00550"
"246.33000","20.52760","0.00555"
"246.53999","20.54518","0.00579"
"246.75000","20.56264","0.00530"
"246.96001","20.58022","0.00562"
"247.17000","20.59767","0.00545"
"247.38000","20.61519","0.00515"
"247.59000","20.63265","0.00488"
"247.80000","20.65023","0.00533"
"248.00999","20.66763","0.00508"
"248.22000","20.68521","0.00556"
"248.42999","20.70266","0.00576"
"248.64000","20.72018","0.00509"
"248.85001","20.73770","0.00493"
"249.06000","20.75510","0.00461"
"249.27000","20.77268","0.00542"
"249.48000","20.79007","0.00498"
"249.69000","20.80771","0.00565"
"249.89999","20.82523","0.00494"
"250.11000","20.84263","0.00559"
"250.32001","20.86021","0.00513"
"250.53000","20.87773","0.00576"
"250.74001","20.89513","0.00531"
"250.95000","20.91270","0.00550"
"251.16000","20.93010","0.00479"
"251.37000","20.94768","0.00529"
"251.58000","20.96520","0.00486"
"251.78999","20.98266","0.00533"
"252.00000","21.00024","0.00509"
"252.21001","21.01763","0.00567"
"252.42000","21.03521","0.00485"
"252.63000","21.05267","0.00474"
"252.84000","21.07013","0.00492"
"253.05000","21.08765","0.00552"
"253.25999","21.10517","0.00536"
"253.47000","21.12263","0.00528"
"253.67999","21.14026","0.00514"
"253.89000","21.15760","0.00531"
"254.10001","21.17518","0.00534"
"254.31000","21.19264","0.00604"
"254.52000","21.21016","0.00542"
"254.73000","21.22767","0.00581"
"254.94000","21.24513","0.00549"
"255.14999","21.26271","0.00569"
"255.36000","21.28017","0.00566"
"255.57001","21.29769","0.00564"
"255.78000","21.31515","0.00530"
"255.99001","21.33267","0.00524"
"256.20001","21.35018","0.00557"
"256.41000","21.36770","0.00494"
"256.62000","21.38516","0.00538"
"256.82999","21.40268","0.00539"
"257.04001","21.42014","0.00534"
"257.25000","21.43766","0.00503"
"257.45999","21.45518","0.00534"
"257.67001","21.47257","0.00557"
"257.88000","21.49015","0.00542"
"258.09000","21.50767","0.00488"
"258.29999","21.52519","0.00487"
"258.51001","21.54265","0.00542"
"258.72000","21.56011","0.00522"
"258.92999","21.57768","0.00531"
"259.14001","21.59520","0.00530"
"259.35001","21.61266","0.00545"
"259.56000","21.63018","0.00552"
"259.76999","21.64758","0.00537"
"259.98001","21.66521","0.00521"
"260.19000","21.68267","0.00537"
"260.39999","21.70013","0.00560"
"260.60999","21.71771","0.00547"
"260.82001","21.73517","0.00558"
"261.03000","21.75269","0.00576"
"261.23999","21.77021","0.00560"
"261.45001","21.78767","0.00559"
"261.66000","21.80518","0.00623"
"261.87000","21.82258","0.00580"
"262.07999","21.84016","0.00607"
"262.29001","21.85774","0.00519"
"262.50000","21.87514","0.00565"
"262.70999","21.89271","0.00634"
"262.92001","21.91017","0.00622"
"263.13000","21.92763","0.00598"
"263.34000","21.94521","0.00641"
"263.54999","21.96261","0.00601"
"263.76001","21.98018","0.00610"
"263.97000","21.99765","0.00568"
"264.17999","22.01516","0.00626"
"264.39001","22.03268","0.00612"
"264.60001","22.05020","0.00636"
"264.81000","22.06766","0.00606"
"265.01999","22.08518","0.00641"
"265.23001","22.10263","0.00639"
"265.44000","22.12021","0.00621"
"265.64999","22.13767","0.00679"
"265.85999","22.15513","0.00649"
"266.07001","22.17265","0.00619"
"266.28000","22.19011","0.00578"
"266.48999","22.20769","0.00625"
"266.70001","22.22515","0.00701"
"266.91000","22.24266","0.00629"
"267.12000","22.26018","0.00675"
"267.32999","22.27764","0.00625"
"267.54001","22.29516","0.00673"
"267.75000","22.31268","0.00652"
"267.95999","22.33019","0.00669"
"268.17001","22.34771","0.00729"
"268.38000","22.36511","0.00660"
"268.59000","22.38269","0.00613"
"268.79999","22.40021","0.00658"
"269.01001","22.41767","0.00686"
"269.22000","22.43519","0.00641"
"269.42999","22.45271","0.00666"
"269.64001","22.47016","0.00662"
"269.85001","22.48768","0.00752"
"270.06000","22.50514","0.00677"
"270.26999","22.52266","0.00525"
"270.48001","22.54018","0.00546"
"270.69000","22.55770","0.00520"
"270.89999","22.57521","0.00436"
"271.10999","22.59261","0.00465"
"271.32001","22.61019","0.00517"
"271.53000","22.62765","0.00524"
"271.73999","22.64511","0.00434"
"271.95001","22.66268","0.00459"
"272.16000","22.68008","0.00461"
"272.37000","22.69766","0.00491"
"272.57999","22.71512","0.00473"
"272.79001","22.73264","0.00398"
"273.00000","22.75022","0.00458"
"273.20999","22.76767","0.00456"
"273.42001","22.78525","0.00465"
"273.63000","22.80271","0.00444"
"273.84000","22.82017","0.00417"
"274.04999","22.83775","0.00446"
"274.26001","22.85515","0.00541"
"274.47000","22.87267","0.00495"
"274.67999","22.89012","0.00453"
"274.89001","22.90758","0.00461"
"275.10001","22.92522","0.00496"
"275.31000","22.94262","0.00486"
"275.51999","22.96020","0.00405"
"275.73001","22.97771","0.00444"
"275.94000","22.99517","0.00424"
"276.14999","23.01269","0.00477"
"276.35999","23.03021","0.00457"
"276.57001","23.04767","0.00430"
"276.78000","23.06519","0.00473"
"276.98999","23.08265","0.00518"
"277.20001","23.10023","0.00497"
"277.41000","23.11768","0.00438"
"277.62000","23.13514","0.00443"
"277.82999","23.15266","0.00523"
"278.04001","23.17012","0.00443"
"278.25000","23.18770","0.00517"
"278.45999","23.20515","0.00507"
"278.67001","23.22267","0.00498"
"278.88000","23.24013","0.00509"
"279.09000","23.25765","0.00529"
"279.29999","23.27511","0.00553"
"279.51001","23.29275","0.00478"
"279.72000","23.31008","0.00512"
"279.92999","23.32772","0.00531"
"280.14001","23.34518","0.00558"
"280.35001","23.36264","0.00492"
"280.56000","23.38022","0.00465"
"280.76999","23.39768","0.00516"
"280.98001","23.41520","0.00469"
"281.19000","23.43271","0.00463"
"281.39999","23.45017","0.00445"
"281.60999","23.46769","0.00468"
"281.82001","23.48521","0.00453"
"282.03000","23.50273","0.00410"
"282.23999","23.52019","0.00423"
"282.45001","23.53764","0.00433"
"282.66000","23.55522","0.00540"
"282.87000","23.57268","0.00481"
"283.07999","23.59020","0.00466"
"283.29001","23.60766","0.00481"
"283.50000","23.62512","0.00452"
"283.70999","23.64269","0.00533"
"283.92001","23.66009","0.00468"
"284.13000","23.67767","0.00529"
"284.34000","23.69519","0.00487"
"284.54999","23.71259","0.00496"
"284.76001","23.73023","0.00508"
"284.97000","23.74768","0.00497"
"285.17999","23.76514","0.00458"
"285.39001","23.78272","0.00570"
"285.60001","23.80012","0.00488"
"285.81000","23.81770","0.00444"
"286.01999","23.83522","0.00420"
"286.23001","23.85262","0.00514"
"286.44000","23.87019","0.00492"
"286.64999","23.88765","0.00539"
"286.85999","23.90523","0.00541"
"287.07001","23.92263","0.00518"
"287.28000","23.94015","0.00504"
"287.48999","23.95767","0.00540"
"287.70001","23.97518","0.00480"
"287.91000","23.99264","0.00460"
"288.12000","24.01022","0.00485"
"288.32999","24.02762","0.00470"
"288.54001","24.04520","0.00445"
"288.75000","24.06266","0.00477"
"288.95999","24.08017","0.00488"
"289.17001","24.09769","0.00405"
"289.38000","24.11509","0.00447"
"289.59000","24.13267","0.00428"
"289.79999","24.15013","0.00462"
"290.01001","24.16765","0.00412"
"290.22000","24.18516","0.00463"
"290.42999","24.20268","0.00454"
"290.64001","24.22020","0.00454"
"290.85001","24.23772","0.00429"
"291.06000","24.25512","0.00430"
"291.26999","24.27270","0.00420"
"291.48001","24.29016","0.00427"
"291.69000","24.30768","0.00413"
"291.89999","24.32513","0.00445"
"292.10999","24.34259","0.00461"
"292.32001","24.36017","0.00446"
"292.53000","24.37763","0.00446"
"292.73999","24.39515","0.00434"
"292.95001","24.41272","0.00449"
"293.16000","24.43018","0.00470"
"293.37000","24.44764","0.00449"
"293.57999","24.46522","0.00416"
"293.79001","24.48268","0.00443"
"294.00000","24.50019","0.00402"
"294.20999","24.51765","0.00457"
"294.42001","24.53523","0.00479"
"294.63000","24.55269","0.00417"
"294.84000","24.57015","0.00472"
"295.04999","24.58773","0.00470"
"295.26001","24.60513","0.00449"
"295.47000","24.62271","0.00429"
"295.67999","24.64017","0.00396"
"295.89001","24.65768","0.00508"
"296.10001","24.67514","0.00463"
"296.31000","24.69266","0.00457"
"296.51999","24.71012","0.00461"
"296.73001","24.72770","0.00444"
"296.94000","24.74504","0.00497"
"297.14999","24.76273","0.00469"
"297.35999","24.78013","0.00423"
"297.57001","24.79765","0.00443"
"297.78000","24.81517","0.00518"
"297.98999","24.83263","0.00471"
"298.20001","24.85020","0.00473"
"298.41000","24.86766","0.00465"
"298.62000","24.88518","0.00481"
"298.82999","24.90264","0.00508"
"299.04001","24.92016","0.00514"
"299.25000","24.93767","0.00452"
"299.45999","24.95520","0.00519"
"299.67001","24.97265","0.00447"
"299.88000","24.99023","0.00444"
"300.09000","25.00763","0.00538"
"300.29999","25.02515","0.00470"
"300.51001","25.04267","0.00497"
"300.72000","25.06013","0.00517"
"300.92999","25.07770","0.00518"
"301.14001","25.09510","0.00536"
"301.35001","25.11268","0.00438"
"301.56000","25.13020","0.00477"
"301.76999","25.14760","0.00493"
"301.98001","25.16523","0.00414"
"302.19000","25.18269","0.00338"
"302.39999","25.20015","0.00348"
"302.60999","25.21773","0.00396"
"302.82001","25.23513","0.00402"
"303.03000","25.25271","0.00362"
"303.23999","25.27016","0.00346"
"303.45001","25.28762","0.00329"
"303.66000","25.30520","0.00308"
"303.87000","25.32266","0.00418"
"304.07999","25.34018","0.00343"
"304.29001","25.35764","0.00282"
"304.50000","25.37516","0.00354"
"304.70999","25.39268","0.00296"
"304.92001","25.41013","0.00337"
"305.13000","25.42765","0.00340"
"305.34000","25.44523","0.00311"
"305.54999","25.46263","0.00299"
"305.76001","25.48021","0.00322"
"305.97000","25.49767","0.00365"
"306.17999","25.51518","0.00362"
"306.39001","25.53270","0.00363"
"306.60001","25.55010","0.00341"
"306.81000","25.56768","0.00347"
"307.01999","25.58513","0.00349"
"307.23001","25.60266","0.00384"
"307.37000","25.61444","0.00368"