File: Force_trajectories/170107_2/Specimen_RawData_3.csv
End date,"1/7/2017"
Specimen label,"17DG_35"
Maximum Load,"0.39610",N

Time,Extension,Load
(s),(mm),(N)
"0.00000","-0.00006","-0.00077"
"0.37200","0.03103","-0.00051"
"0.74400","0.06218","0.00023"
"1.11600","0.09315","0.00003"
"1.48800","0.12418","0.00025"
"1.86000","0.15509","0.00025"
"2.23200","0.18618","0.00052"
"2.60400","0.21716","0.00042"
"2.97600","0.24807","0.00066"
"3.34800","0.27916","0.00091"
"3.72000","0.31019","0.00111"
"4.09200","0.34110","0.00168"
"4.46400","0.37213","0.00228"
"4.83600","0.40316","0.00186"
"5.20800","0.43407","0.00091"
"5.58000","0.46510","0.00135"
"5.95200","0.49619","0.00128"
"6.32400","0.52710","0.00162"
"6.69600","0.55808","0.00197"
"7.06800","0.58917","0.00217"
"7.44000","0.62014","0.00194"
"7.81200","0.65111","0.00218"
"8.18400","0.68214","0.00185"
"8.55600","0.71317","0.00204"
"8.92800","0.74408","0.00232"
"9.30000","0.77511","0.00288"
"9.67200","0.80614","0.00254"
"10.04400","0.83711","0.00311"
"10.41600","0.86814","0.00274"
"10.78800","0.89917","0.00263"
"11.16000","0.93015","0.00270"
"11.53200","0.96112","0.00302"
"11.90400","0.99215","0.00377"
"12.27600","1.02318","0.00305"
"12.64800","1.05409","0.00356"
"13.02000","1.08518","0.00336"
"13.39200","1.11609","0.00351"
"13.76400","1.14706","0.00344"
"14.13600","1.17821","0.00422"
"14.50800","1.20912","0.00416"
"14.88000","1.24009","0.00464"
"15.25200","1.27113","0.00452"
"15.62400","1.30216","0.00447"
"15.99600","1.33313","0.00482"
"16.36800","1.36410","0.00497"
"16.74000","1.39513","0.00524"
"17.11200","1.42616","0.00509"
"17.48400","1.45707","0.00534"
"17.85600","1.48816","0.00535"
"18.22800","1.51913","0.00595"
"18.60000","1.55010","0.00615"
"18.97200","1.58107","0.00605"
"19.34400","1.61216","0.00595"
"19.71600","1.64308","0.00631"
"20.08800","1.67411","0.00692"
"20.46000","1.70514","0.00568"
"20.83200","1.73611","0.00627"
"21.20400","1.76708","0.00639"
"21.57600","1.79817","0.00663"
"21.94800","1.82920","0.00658"
"22.32000","1.86011","0.00645"
"22.69200","1.89114","0.00668"
"23.06400","1.92217","0.00710"
"23.43600","1.95308","0.00675"
"23.80800","1.98418","0.00738"
"24.18000","2.01515","0.00746"
"24.55200","2.04612","0.00672"
"24.92400","2.07715","0.00716"
"25.29600","2.10812","0.00738"
"25.66800","2.13909","0.00740"
"26.04000","2.17012","0.00738"
"26.41200","2.20115","0.00721"
"26.78400","2.23212","0.00734"
"27.15600","2.26309","0.00746"
"27.52800","2.29412","0.00759"
"27.90000","2.32516","0.00763"
"28.27200","2.35613","0.00842"
"28.64400","2.38722","0.00761"
"29.01600","2.41813","0.00806"
"29.38800","2.44910","0.00838"
"29.76000","2.48013","0.00860"
"30.13200","2.51110","0.00807"
"30.50400","2.54213","0.00796"
"30.87600","2.57310","0.00810"
"31.24800","2.60413","0.00866"
"31.62000","2.63516","0.00831"
"31.99200","2.66607","0.00835"
"32.36400","2.69717","0.00818"
"32.73600","2.72814","0.00744"
"33.10800","2.75911","0.00816"
"33.48000","2.79014","0.00847"
"33.85200","2.82117","0.00807"
"34.22400","2.85208","0.00874"
"34.59600","2.88311","0.00859"
"34.96800","2.91420","0.00863"
"35.34000","2.94511","0.00811"
"35.71200","2.97614","0.00792"
"36.08400","3.00711","0.00811"
"36.45600","3.03809","0.00842"
"36.82800","3.06912","0.00846"
"37.20000","3.10015","0.00907"
"37.57200","3.13118","0.00842"
"37.94400","3.16209","0.00865"
"38.31600","3.19312","0.00879"
"38.68800","3.22421","0.00941"
"39.06000","3.25506","0.00872"
"39.43200","3.28615","0.00817"
"39.80400","3.31718","0.00935"
"40.17600","3.34809","0.00880"
"40.54800","3.37912","0.00861"
"40.92000","3.41022","0.00917"
"41.29200","3.44119","0.00872"
"41.66400","3.47210","0.00882"
"42.03600","3.50319","0.00896"
"42.40800","3.53416","0.00903"
"42.78000","3.56507","0.00935"
"43.15200","3.59616","0.00985"
"43.52400","3.62713","0.00961"
"43.89600","3.65810","0.00974"
"44.26800","3.68913","0.01016"
"44.64000","3.72016","0.01007"
"45.01200","3.75108","0.01005"
"45.38400","3.78211","0.00991"
"45.75600","3.81320","0.01007"
"46.12800","3.84417","0.01060"
"46.50000","3.87508","0.00978"
"46.87200","3.90617","0.01030"
"47.24400","3.93714","0.01027"
"47.61600","3.96811","0.01017"
"47.98800","3.99914","0.00973"
"48.36000","4.03017","0.01041"
"48.73200","4.06108","0.01039"
"49.10400","4.09211","0.01001"
"49.47600","4.12315","0.01026"
"49.84800","4.15412","0.01004"
"50.22000","4.18515","0.01022"
"50.59200","4.21618","0.01032"
"50.96400","4.24715","0.01007"
"51.33600","4.27806","0.01094"
"51.70800","4.30915","0.01069"
"52.08000","4.34012","0.01078"
"52.45200","4.37109","0.01117"
"52.82400","4.40218","0.01106"
"53.19600","4.43321","0.01118"
"53.56800","4.46407","0.01061"
"53.94000","4.49516","0.01134"
"54.31200","4.52619","0.01113"
"54.68400","4.55710","0.01092"
"55.05600","4.58819","0.01140"
"55.42800","4.61916","0.01048"
"55.80000","4.65013","0.00998"
"56.17200","4.68110","0.01020"
"56.54400","4.71219","0.01009"
"56.91600","4.74316","0.01081"
"57.28800","4.77407","0.01042"
"57.66000","4.80517","0.01070"
"58.03200","4.83614","0.01085"
"58.40400","4.86705","0.01055"
"58.77600","4.89814","0.01012"
"59.14800","4.92911","0.01013"
"59.52000","4.96014","0.01053"
"59.89200","4.99111","0.01089"
"60.26400","5.02214","0.01041"
"60.63600","5.05311","0.01098"
"61.00800","5.08408","0.01091"
"61.38000","5.11517","0.01083"
"61.75200","5.14609","0.01063"
"62.12400","5.17706","0.01101"
"62.49600","5.20815","0.01055"
"62.86800","5.23912","0.01095"
"63.24000","5.27009","0.01120"
"63.61200","5.30112","0.01149"
"63.98400","5.33215","0.01133"
"64.35600","5.36306","0.01146"
"64.72800","5.39409","0.01123"
"65.10000","5.42518","0.01116"
"65.47200","5.45609","0.01166"
"65.84400","5.48712","0.01135"
"66.21600","5.51816","0.01110"
"66.58800","5.54913","0.01111"
"66.96000","5.58016","0.01125"
"67.33200","5.61119","0.01157"
"67.70400","5.64210","0.01175"
"68.07600","5.67307","0.01137"
"68.44800","5.70416","0.01192"
"68.82000","5.73519","0.01180"
"69.19200","5.76610","0.01200"
"69.56400","5.79713","0.01222"
"69.93600","5.82810","0.01262"
"70.30800","5.85908","0.01223"
"70.68000","5.89011","0.01227"
"71.05200","5.92114","0.01201"
"71.42400","5.95217","0.01222"
"71.79600","5.98308","0.01265"
"72.16800","6.01417","0.01190"
"72.54000","6.04520","0.01278"
"72.91200","6.07605","0.01241"
"73.28400","6.10714","0.01289"
"73.65600","6.13817","0.01293"
"74.02800","6.16908","0.01126"
"74.40000","6.20017","0.01080"
"74.77200","6.23115","0.01175"
"75.14400","6.26218","0.01139"
"75.51600","6.29315","0.01146"
"75.88800","6.32412","0.01123"
"76.26000","6.35509","0.01154"
"76.63200","6.38612","0.01204"
"77.00400","6.41715","0.01150"
"77.37600","6.44812","0.01184"
"77.74800","6.47909","0.01194"
"78.12000","6.51012","0.01229"
"78.49200","6.54115","0.01223"
"78.86400","6.57212","0.01197"
"79.23600","6.60310","0.01158"
"79.60800","6.63419","0.01148"
"79.98000","6.66510","0.01173"
"80.35200","6.69607","0.01182"
"80.72400","6.72710","0.01130"
"81.09600","6.75819","0.01174"
"81.46800","6.78910","0.01148"
"81.84000","6.82019","0.01203"
"82.21200","6.85116","0.01221"
"82.58400","6.88213","0.01158"
"82.95600","6.91311","0.01196"
"83.32800","6.94414","0.01230"
"83.70000","6.97505","0.01212"
"84.07200","7.00614","0.01174"
"84.44400","7.03717","0.01245"
"84.81600","7.06814","0.01160"
"85.18800","7.09917","0.01260"
"85.56000","7.13014","0.01217"
"85.93200","7.16111","0.01266"
"86.30400","7.19214","0.01255"
"86.67600","7.22311","0.01255"
"87.04800","7.25415","0.01311"
"87.42000","7.28512","0.01247"
"87.79200","7.31615","0.01269"
"88.16400","7.34712","0.01353"
"88.53600","7.37809","0.01249"
"88.90800","7.40912","0.01244"
"89.28000","7.44015","0.01316"
"89.65200","7.47112","0.01260"
"90.02400","7.50209","0.01316"
"90.39600","7.53312","0.01296"
"90.76800","7.56415","0.01428"
"91.14000","7.59512","0.01379"
"91.51200","7.62621","0.01279"
"91.88400","7.65713","0.01320"
"92.25600","7.68810","0.01260"
"92.62800","7.71919","0.01308"
"93.00000","7.75010","0.01227"
"93.37200","7.78113","0.01296"
"93.74400","7.81216","0.01270"
"94.11600","7.84313","0.01270"
"94.48800","7.87410","0.01263"
"94.86000","7.90513","0.01343"
"95.23200","7.93616","0.01308"
"95.60400","7.96707","0.01350"
"95.97600","7.99811","0.01333"
"96.34800","8.02914","0.01299"
"96.72000","8.06011","0.01375"
"97.09200","8.09114","0.01375"
"97.46400","8.12217","0.01335"
"97.83600","8.15314","0.01353"
"98.20800","8.18405","0.01335"
"98.58000","8.21514","0.01232"
"98.95200","8.24623","0.01280"
"99.32400","8.27708","0.01224"
"99.69600","8.30811","0.01311"
"100.06800","8.33915","0.01346"
"100.44000","8.37012","0.01251"
"100.81200","8.40115","0.01261"
"101.18400","8.43218","0.01274"
"101.55600","8.46309","0.01315"
"101.92800","8.49412","0.01328"
"102.30000","8.52515","0.01286"
"102.67200","8.55618","0.01354"
"103.04400","8.58703","0.01284"
"103.41600","8.61818","0.01299"
"103.78800","8.64915","0.01366"
"104.16000","8.68013","0.01379"
"104.53200","8.71116","0.01372"
"104.90400","8.74213","0.01317"
"105.27600","8.77310","0.01329"
"105.64800","8.80407","0.01354"
"106.02000","8.83510","0.01372"
"106.39200","8.86619","0.01366"
"106.76400","8.89710","0.01426"
"107.13600","8.92819","0.01434"
"107.50800","8.95916","0.01436"
"107.88000","8.99007","0.01452"
"108.25200","9.02116","0.01462"
"108.62400","9.05214","0.01429"
"108.99600","9.08311","0.01437"
"109.36800","9.11414","0.01464"
"109.74000","9.14511","0.01501"
"110.11200","9.17608","0.01477"
"110.48400","9.20717","0.01504"
"110.85600","9.23820","0.01501"
"111.22800","9.26911","0.01554"
"111.60000","9.30014","0.01488"
"111.97200","9.33111","0.01553"
"112.34400","9.36214","0.01542"
"112.71600","9.39312","0.01527"
"113.08800","9.42415","0.01618"
"113.46000","9.45518","0.01574"
"113.83200","9.48603","0.01608"
"114.20400","9.51712","0.01566"
"114.57600","9.54815","0.01591"
"114.94800","9.57912","0.01579"
"115.32000","9.61015","0.01602"
"115.69200","9.64112","0.01576"
"116.06400","9.67215","0.01600"
"116.43600","9.70312","0.01661"
"116.80800","9.73415","0.01645"
"117.18000","9.76513","0.01654"
"117.55200","9.79616","0.01660"
"117.92400","9.82719","0.01681"
"118.29600","9.85816","0.01662"
"118.66800","9.88907","0.01664"
"119.04000","9.92022","0.01669"
"119.41200","9.95113","0.01609"
"119.78400","9.98210","0.01575"
"120.15600","10.01313","0.01603"
"120.52800","10.04416","0.01608"
"120.90000","10.07507","0.01544"
"121.27200","10.10611","0.01624"
"121.64400","10.13720","0.01653"
"122.01600","10.16811","0.01488"
"122.38800","10.19914","0.01537"
"122.76000","10.23017","0.01597"
"123.13200","10.26114","0.01532"
"123.50400","10.29211","0.01589"
"123.87600","10.32314","0.01590"
"124.24800","10.35417","0.01651"
"124.62000","10.38508","0.01576"
"124.99200","10.41617","0.01628"
"125.36400","10.44720","0.01647"
"125.73600","10.47806","0.01650"
"126.10800","10.50909","0.01688"
"126.48000","10.54012","0.01684"
"126.85200","10.57109","0.01681"
"127.22400","10.60212","0.01694"
"127.59600","10.63315","0.01738"
"127.96800","10.66418","0.01683"
"128.34000","10.69509","0.01769"
"128.71201","10.72618","0.01719"
"129.08400","10.75721","0.01746"
"129.45599","10.78806","0.01759"
"129.82800","10.81916","0.01737"
"130.20000","10.85019","0.01776"
"130.57201","10.88110","0.01770"
"130.94400","10.91213","0.01775"
"131.31599","10.94310","0.01809"
"131.68800","10.97413","0.01835"
"132.06000","11.00510","0.01829"
"132.43201","11.03619","0.01853"
"132.80400","11.06716","0.01843"
"133.17599","11.09807","0.01558"
"133.54800","11.12916","0.01651"
"133.92000","11.16019","0.01639"
"134.29201","11.19105","0.01612"
"134.66400","11.22214","0.01609"
"135.03600","11.25311","0.01710"
"135.40800","11.28414","0.01604"
"135.78000","11.31511","0.01629"
"136.15199","11.34614","0.01742"
"136.52400","11.37711","0.01738"
"136.89600","11.40808","0.01758"
"137.26801","11.43917","0.01762"
"137.64000","11.47014","0.01785"
"138.01199","11.50111","0.01796"
"138.38400","11.53209","0.01703"
"138.75600","11.56318","0.01809"
"139.12801","11.59415","0.01781"
"139.50000","11.62512","0.01808"
"139.87199","11.65615","0.01823"
"140.24400","11.68712","0.01841"
"140.61600","11.71809","0.01828"
"140.98801","11.74918","0.01832"
"141.36000","11.78015","0.01851"
"141.73199","11.81112","0.01923"
"142.10400","11.84215","0.01868"
"142.47600","11.87312","0.01905"
"142.84801","11.90410","0.01848"
"143.22000","11.93513","0.01958"
"143.59200","11.96616","0.01945"
"143.96400","11.99707","0.01956"
"144.33600","12.02816","0.01982"
"144.70799","12.05919","0.01970"
"145.08000","12.09010","0.02014"
"145.45200","12.12113","0.02009"
"145.82401","12.15216","0.01996"
"146.19600","12.18313","0.02015"
"146.56799","12.21410","0.02020"
"146.94000","12.24514","0.02021"
"147.31200","12.27617","0.02043"
"147.68401","12.30708","0.02051"
"148.05600","12.33811","0.02009"
"148.42799","12.36914","0.02044"
"148.80000","12.40011","0.02040"
"149.17200","12.43114","0.02049"
"149.54401","12.46223","0.02055"
"149.91600","12.49314","0.02114"
"150.28799","12.52411","0.02155"
"150.66000","12.55514","0.02126"
"151.03200","12.58617","0.02113"
"151.40401","12.61715","0.02144"
"151.77600","12.64818","0.02145"
"152.14799","12.67909","0.02147"
"152.52000","12.71006","0.02196"
"152.89200","12.74115","0.02169"
"153.26401","12.77212","0.02211"
"153.63600","12.80315","0.02179"
"154.00800","12.83412","0.02218"
"154.38000","12.86515","0.02236"
"154.75200","12.89612","0.02240"
"155.12399","12.92709","0.02169"
"155.49600","12.95819","0.02268"
"155.86800","12.98910","0.02274"
"156.24001","13.02013","0.02299"
"156.61200","13.05116","0.02302"
"156.98399","13.08213","0.02317"
"157.35600","13.11310","0.02350"
"157.72800","13.14413","0.02346"
"158.10001","13.17516","0.02344"
"158.47200","13.20607","0.02373"
"158.84399","13.23710","0.02411"
"159.21600","13.26819","0.02442"
"159.58800","13.29905","0.02464"
"159.96001","13.33020","0.02460"
"160.33200","13.36117","0.02442"
"160.70399","13.39214","0.02493"
"161.07600","13.42311","0.02517"
"161.44800","13.45414","0.02520"
"161.82001","13.48517","0.02514"
"162.19200","13.51608","0.02511"
"162.56400","13.54717","0.02551"
"162.93600","13.57814","0.02596"
"163.30800","13.60905","0.02530"
"163.67999","13.64015","0.02528"
"164.05200","13.67112","0.02535"
"164.42400","13.70215","0.02560"
"164.79601","13.73312","0.02588"
"165.16800","13.76415","0.02608"
"165.53999","13.79512","0.02631"
"165.91200","13.82609","0.02640"
"166.28400","13.85718","0.02620"
"166.65601","13.88815","0.02709"
"167.02800","13.91912","0.02682"
"167.39999","13.95021","0.02718"
"167.77200","13.98112","0.02719"
"168.14400","14.01210","0.02706"
"168.51601","14.04319","0.02754"
"168.88800","14.07416","0.02784"
"169.25999","14.10513","0.02794"
"169.63200","14.13610","0.02870"
"170.00400","14.16713","0.02885"
"170.37601","14.19810","0.02877"
"170.74800","14.22913","0.02884"
"171.12000","14.26016","0.02903"
"171.49200","14.29107","0.02885"
"171.86400","14.32216","0.02984"
"172.23599","14.35314","0.02970"
"172.60800","14.38411","0.03035"
"172.98000","14.41514","0.03059"
"173.35201","14.44617","0.03059"
"173.72400","14.47714","0.03056"
"174.09599","14.50811","0.03076"
"174.46800","14.53908","0.03036"
"174.84000","14.57017","0.03088"
"175.21201","14.60114","0.03040"
"175.58400","14.63217","0.03047"
"175.95599","14.66314","0.02940"
"176.32800","14.69411","0.02936"
"176.70000","14.72509","0.02975"
"177.07201","14.75618","0.03020"
"177.44400","14.78715","0.03027"
"177.81599","14.81812","0.03124"
"178.18800","14.84915","0.03133"
"178.56000","14.88012","0.03171"
"178.93201","14.91103","0.03201"
"179.30400","14.94218","0.03183"
"179.67599","14.97309","0.03121"
"180.04800","15.00412","0.03263"
"180.42000","15.03509","0.03313"
"180.79201","15.06619","0.03244"
"181.16400","15.09710","0.03328"
"181.53600","15.12813","0.03380"
"181.90800","15.15916","0.03449"
"182.28000","15.19013","0.03543"
"182.65199","15.22110","0.03536"
"183.02400","15.25219","0.03587"
"183.39600","15.28316","0.03590"
"183.76801","15.31413","0.03602"
"184.14000","15.34516","0.03676"
"184.51199","15.37619","0.03796"
"184.88400","15.40711","0.03777"
"185.25600","15.43814","0.03778"
"185.62801","15.46917","0.03851"
"186.00000","15.50008","0.03885"
"186.37199","15.53111","0.03927"
"186.74400","15.56214","0.04068"
"187.11600","15.59311","0.04065"
"187.48801","15.62408","0.04092"
"187.86000","15.65517","0.04186"
"188.23199","15.68614","0.04209"
"188.60400","15.71711","0.04213"
"188.97600","15.74814","0.04229"
"189.34801","15.77912","0.04293"
"189.72000","15.81009","0.04296"
"190.09200","15.84118","0.04321"
"190.46400","15.87215","0.04394"
"190.83600","15.90306","0.04189"
"191.20799","15.93409","0.04070"
"191.58000","15.96512","0.04163"
"191.95200","15.99615","0.04218"
"192.32401","16.02706","0.04255"
"192.69600","16.05815","0.04328"
"193.06799","16.08918","0.04383"
"193.44000","16.12009","0.04422"
"193.81200","16.15119","0.04516"
"194.18401","16.18216","0.04493"
"194.55600","16.21307","0.04626"
"194.92799","16.24410","0.04731"
"195.30000","16.27513","0.04789"
"195.67200","16.30616","0.04882"
"196.04401","16.33707","0.04959"
"196.41600","16.36816","0.04984"
"196.78799","16.39913","0.05109"
"197.16000","16.43010","0.05207"
"197.53200","16.46119","0.05282"
"197.90401","16.49217","0.05371"
"198.27600","16.52308","0.05430"
"198.64799","16.55411","0.05552"
"199.02000","16.58514","0.05577"
"199.39200","16.61611","0.05745"
"199.76401","16.64708","0.05770"
"200.13600","16.67817","0.05874"
"200.50800","16.70908","0.05927"
"200.88000","16.74017","0.06007"
"201.25200","16.77114","0.06134"
"201.62399","16.80211","0.06188"
"201.99600","16.83309","0.06190"
"202.36800","16.86418","0.06300"
"202.74001","16.89515","0.06363"
"203.11200","16.92612","0.06468"
"203.48399","16.95715","0.06539"
"203.85600","16.98818","0.06607"
"204.22800","17.01903","0.06686"
"204.60001","17.05012","0.06676"
"204.97200","17.08115","0.06794"
"205.34399","17.11206","0.06835"
"205.71600","17.14315","0.06915"
"206.08800","17.17413","0.07007"
"206.46001","17.20510","0.07003"
"206.83200","17.23613","0.07038"
"207.20399","17.26716","0.07081"
"207.57600","17.29819","0.07135"
"207.94800","17.32910","0.07206"
"208.32001","17.36013","0.07266"
"208.69200","17.39116","0.07328"
"209.06400","17.42207","0.07345"
"209.43600","17.45316","0.07391"
"209.80800","17.48419","0.07465"
"210.17999","17.51510","0.07493"
"210.55200","17.54614","0.07576"
"210.92400","17.57711","0.07645"
"211.29601","17.60814","0.07760"
"211.66800","17.63911","0.07827"
"212.03999","17.67020","0.07875"
"212.41200","17.70111","0.07980"
"212.78400","17.73208","0.08040"
"213.15601","17.76317","0.08086"
"213.52800","17.79420","0.08206"
"213.89999","17.82511","0.08251"
"214.27200","17.85614","0.08330"
"214.64400","17.88712","0.08414"
"215.01601","17.91809","0.08521"
"215.38800","17.94912","0.08639"
"215.75999","17.98021","0.08476"
"216.13200","18.01106","0.08661"
"216.50400","18.04215","0.08819"
"216.87601","18.07312","0.08950"
"217.24800","18.10409","0.09096"
"217.62000","18.13506","0.09275"
"217.99200","18.16615","0.09503"
"218.36400","18.19718","0.09635"
"218.73599","18.22809","0.09802"
"219.10800","18.25912","0.09971"
"219.48000","18.29022","0.10180"
"219.85201","18.32101","0.10345"
"220.22400","18.35216","0.10607"
"220.59599","18.38313","0.10876"
"220.96800","18.41416","0.10968"
"221.34000","18.44513","0.11162"
"221.71201","18.47622","0.11320"
"222.08400","18.50713","0.11579"
"222.45599","18.53811","0.11759"
"222.82800","18.56919","0.11957"
"223.20000","18.60011","0.12195"
"223.57201","18.63102","0.12323"
"223.94400","18.66217","0.12466"
"224.31599","18.69314","0.12725"
"224.68800","18.72411","0.12945"
"225.06000","18.75514","0.13116"
"225.43201","18.78617","0.13260"
"225.80400","18.81708","0.13447"
"226.17599","18.84805","0.13559"
"226.54800","18.87914","0.13728"
"226.92000","18.91011","0.13902"
"227.29201","18.94114","0.14054"
"227.66400","18.97218","0.14237"
"228.03600","19.00315","0.14342"
"228.40800","19.03412","0.14467"
"228.78000","19.06515","0.14617"
"229.15199","19.09618","0.14712"
"229.52400","19.12709","0.14902"
"229.89600","19.15812","0.14973"
"230.26801","19.18915","0.15178"
"230.64000","19.22006","0.15289"
"231.01199","19.25109","0.15446"
"231.38400","19.28213","0.15693"
"231.75600","19.31310","0.15861"
"232.12801","19.34413","0.16056"
"232.50000","19.37516","0.16245"
"232.87199","19.40613","0.16447"
"233.24400","19.43716","0.16594"
"233.61600","19.46813","0.16736"
"233.98801","19.49916","0.16892"
"234.36000","19.53007","0.17054"
"234.73199","19.56116","0.17250"
"235.10400","19.59213","0.17423"
"235.47600","19.62310","0.17598"
"235.84801","19.65413","0.17758"
"236.22000","19.68511","0.17889"
"236.59200","19.71614","0.17972"
"236.96400","19.74717","0.18132"
"237.33600","19.77814","0.18234"
"237.70799","19.80917","0.18322"
"238.08000","19.84008","0.18409"
"238.45200","19.87117","0.18492"
"238.82401","19.90214","0.18515"
"239.19600","19.93311","0.18598"
"239.56799","19.96420","0.18725"
"239.94000","19.99512","0.18856"
"240.31200","20.02615","0.18898"
"240.68401","20.05711","0.19109"
"241.05600","20.08815","0.19236"
"241.42799","20.11912","0.19374"
"241.80000","20.15009","0.19557"
"242.17200","20.18118","0.19736"
"242.54401","20.21215","0.19886"
"242.91600","20.24306","0.20059"
"243.28799","20.27415","0.20293"
"243.66000","20.30512","0.20591"
"244.03200","20.33610","0.20712"
"244.40401","20.36712","0.20716"
"244.77600","20.39822","0.20506"
"245.14799","20.42907","0.20666"
"245.52000","20.46016","0.19795"
"245.89200","20.49119","0.20004"
"246.26401","20.52210","0.20235"
"246.63600","20.55313","0.20630"
"247.00800","20.58416","0.20841"
"247.38000","20.61513","0.21028"
"247.75200","20.64610","0.21430"
"248.12399","20.67713","0.21783"
"248.49600","20.70811","0.22081"
"248.86800","20.73902","0.22279"
"249.24001","20.77017","0.22537"
"249.61200","20.80120","0.22827"
"249.98399","20.83211","0.23043"
"250.35600","20.86314","0.22565"
"250.72800","20.89411","0.22944"
"251.10001","20.92508","0.23176"
"251.47200","20.95611","0.23443"
"251.84399","20.98714","0.23769"
"252.21600","21.01817","0.24174"
"252.58800","21.04908","0.24317"
"252.96001","21.08012","0.24592"
"253.33200","21.11115","0.24909"
"253.70399","21.14212","0.25270"
"254.07600","21.17315","0.25518"
"254.44800","21.20418","0.25944"
"254.82001","21.23509","0.26360"
"255.19200","21.26612","0.26712"
"255.56400","21.29715","0.10792"
"255.93600","21.32812","0.09872"
"256.30801","21.35909","0.09407"
"256.67999","21.39018","0.09444"
"257.05200","21.42109","0.09937"
"257.42401","21.45213","0.10347"
"257.79599","21.48315","0.10706"
"258.16800","21.51413","0.10887"
"258.54001","21.54516","0.10806"
"258.91199","21.57613","0.10615"
"259.28400","21.60716","0.10899"
"259.65601","21.63813","0.11077"
"260.02802","21.66910","0.11356"
"260.39999","21.70019","0.11793"
"260.77200","21.73110","0.12144"
"261.14401","21.76208","0.12345"
"261.51599","21.79317","0.12483"
"261.88800","21.82414","0.12548"
"262.26001","21.85511","0.12664"
"262.63199","21.88614","0.12888"
"263.00400","21.91711","0.13027"
"263.37601","21.94808","0.13224"
"263.74799","21.97917","0.13435"
"264.12000","22.01014","0.13663"
"264.49200","22.04105","0.13766"
"264.86401","22.07220","0.13914"
"265.23599","22.10317","0.14051"
"265.60800","22.13408","0.14107"
"265.98001","22.16512","0.14210"
"266.35199","22.19609","0.14230"
"266.72400","22.22712","0.14398"
"267.09601","22.25815","0.14474"
"267.46799","22.28912","0.14632"
"267.84000","22.32015","0.14760"
"268.21201","22.35112","0.14939"
"268.58401","22.38215","0.15161"
"268.95599","22.41312","0.15415"
"269.32800","22.44409","0.15564"
"269.70001","22.47518","0.15619"
"270.07199","22.50616","0.15800"
"270.44400","22.53713","0.15977"
"270.81601","22.56810","0.16056"
"271.18799","22.59919","0.16193"
"271.56000","22.63010","0.16118"
"271.93201","22.66107","0.16118"
"272.30399","22.69222","0.16257"
"272.67599","22.72313","0.16438"
"273.04800","22.75410","0.16578"
"273.42001","22.78519","0.16688"
"273.79199","22.81616","0.16815"
"274.16400","22.84708","0.16940"
"274.53601","22.87816","0.17110"
"274.90799","22.90914","0.17298"
"275.28000","22.94011","0.17478"
"275.65201","22.97114","0.17645"
"276.02399","23.00217","0.17774"
"276.39600","23.03308","0.17915"
"276.76801","23.06411","0.17871"
"277.14001","23.09514","0.17974"
"277.51199","23.12611","0.18082"
"277.88400","23.15714","0.18188"
"278.25601","23.18817","0.18268"
"278.62799","23.21915","0.18337"
"279.00000","23.25012","0.18425"
"279.37201","23.28115","0.18509"
"279.74399","23.31218","0.18588"
"280.11600","23.34303","0.18649"
"280.48801","23.37418","0.18763"
"280.85999","23.40515","0.18868"
"281.23199","23.43606","0.18963"
"281.60400","23.46709","0.19091"
"281.97601","23.49818","0.19252"
"282.34799","23.52909","0.19446"
"282.72000","23.56012","0.19593"
"283.09201","23.59116","0.19755"
"283.46399","23.62213","0.19904"
"283.83600","23.65310","0.20039"
"284.20801","23.68419","0.20236"
"284.57999","23.71516","0.20381"
"284.95200","23.74613","0.20591"
"285.32401","23.77716","0.19945"
"285.69601","23.80813","0.20071"
"286.06799","23.83910","0.19963"
"286.44000","23.87008","0.19967"
"286.81201","23.90117","0.20007"
"287.18399","23.93214","0.20167"
"287.55600","23.96305","0.20268"
"287.92801","23.99414","0.20336"
"288.29999","24.02517","0.20290"
"288.67200","24.05614","0.20445"
"289.04401","24.08711","0.20603"
"289.41599","24.11814","0.20805"
"289.78799","24.14911","0.21088"
"290.16000","24.18014","0.21331"
"290.53201","24.21117","0.21564"
"290.90399","24.24208","0.21776"
"291.27600","24.27312","0.22051"
"291.64801","24.30415","0.22178"
"292.01999","24.33506","0.22394"
"292.39200","24.36615","0.22603"
"292.76401","24.39712","0.22813"
"293.13599","24.42815","0.23053"
"293.50800","24.45912","0.23298"
"293.88000","24.49015","0.23517"
"294.25201","24.52118","0.23757"
"294.62399","24.55203","0.23978"
"294.99600","24.58313","0.24237"
"295.36801","24.61415","0.24461"
"295.73999","24.64513","0.24710"
"296.11200","24.67616","0.25015"
"296.48401","24.70713","0.25299"
"296.85599","24.73816","0.25628"
"297.22800","24.76907","0.25949"
"297.60001","24.80016","0.26289"
"297.97198","24.83113","0.26629"
"298.34399","24.86210","0.26886"
"298.71600","24.89314","0.27186"
"299.08801","24.92410","0.27402"
"299.45999","24.95507","0.27657"
"299.83200","24.98616","0.27877"
"300.20401","25.01714","0.28070"
"300.57599","25.04811","0.28263"
"300.94800","25.07914","0.28485"
"301.32001","25.11017","0.28708"
"301.69199","25.14114","0.28859"
"302.06400","25.17211","0.29008"
"302.43600","25.20320","0.29115"
"302.80801","25.23411","0.29232"
"303.17999","25.26509","0.29309"
"303.55200","25.29617","0.29361"
"303.92401","25.32715","0.29469"
"304.29599","25.35812","0.29565"
"304.66800","25.38915","0.29670"
"305.04001","25.42018","0.29821"
"305.41199","25.45103","0.29942"
"305.78400","25.48218","0.30082"
"306.15601","25.51321","0.30288"
"306.52802","25.54406","0.30481"
"306.89999","25.57509","0.30675"
"307.27200","25.60612","0.30950"
"307.64401","25.63709","0.31251"
"308.01599","25.66813","0.31573"
"308.38800","25.69916","0.31944"
"308.76001","25.73013","0.32241"
"309.13199","25.76110","0.32494"
"309.50400","25.79213","0.32709"
"309.87601","25.82316","0.32872"
"310.24799","25.85407","0.33135"
"310.62000","25.88510","0.33327"
"310.99200","25.91613","0.33598"
"311.36401","25.94716","0.33892"
"311.73599","25.97813","0.34261"
"312.10800","26.00910","0.34550"
"312.48001","26.04013","0.34737"
"312.85199","26.07104","0.34975"
"313.22400","26.10214","0.35189"
"313.59601","26.13317","0.35417"
"313.96799","26.16408","0.35599"
"314.34000","26.19517","0.35887"
"314.71201","26.22620","0.36208"
"315.08401","26.25705","0.36480"
"315.45599","26.28815","0.36687"
"315.82800","26.31917","0.36949"
"316.20001","26.35014","0.37140"
"316.57199","26.38106","0.37365"
"316.94400","26.41221","0.37500"
"317.31601","26.44312","0.37721"
"317.68799","26.47409","0.37951"
"318.06000","26.50518","0.38129"
"318.43201","26.53615","0.38372"
"318.80399","26.56712","0.38509"
"319.17599","26.59809","0.38642"
"319.54800","26.62912","0.38792"
"319.92001","26.66009","0.38954"
"320.29199","26.69106","0.39137"
"320.66400","26.72222","0.39354"
"321.03601","26.75307","0.39495"
"321.40799","26.78416","0.37112"
"321.78000","26.81519","0.36916"
"322.15201","26.84616","0.17747"
"322.52399","26.87713","0.18082"
"322.89600","26.90816","0.18362"
"323.26801","26.93913","0.18551"
"323.64001","26.97010","0.18680"
"324.01199","27.00113","0.19002"
"324.38400","27.03216","0.19309"
"324.75601","27.06308","0.19593"
"325.12799","27.09417","0.19882"
"325.50000","27.12514","0.20166"
"325.87201","27.15605","0.20499"
"326.24399","27.18714","0.20820"
"326.61600","27.21811","0.21115"
"326.98801","27.24914","0.21406"
"327.35999","27.28011","0.21700"
"327.73199","27.31114","0.18222"
"328.10400","27.34211","0.04908"
"328.47601","27.37308","0.04915"
"328.84799","27.40417","0.05272"
"329.22000","27.43514","0.05698"
"329.59201","27.46612","0.05068"
"329.96399","27.49715","0.05416"
"330.33600","27.52818","0.06283"
"330.70801","27.55915","0.06291"
"331.07999","27.59012","0.06040"
"331.45200","27.62115","0.06098"
"331.82401","27.65212","0.06259"
"332.19601","27.68309","0.06707"
"332.56799","27.71418","0.06784"
"332.94000","27.74510","0.06768"
"333.31201","27.77612","0.06701"
"333.68399","27.80716","0.06792"
"334.05600","27.83813","0.07027"
"334.42801","27.86916","0.07217"
"334.79999","27.90013","0.07246"
"335.17200","27.93116","0.07202"
"335.54401","27.96207","0.07222"
"335.91599","27.99316","0.07343"
"336.28799","28.02419","0.07461"
"336.66000","28.05510","0.07615"
"337.03201","28.08619","0.07656"
"337.40399","28.11710","0.07671"
"337.77600","28.14808","0.07705"
"338.14801","28.17911","0.07768"
"338.51999","28.21014","0.07940"
"338.89200","28.24117","0.08144"
"339.26401","28.27208","0.08246"
"339.63599","28.30317","0.08327"
"340.00800","28.33420","0.08427"
"340.38000","28.36505","0.08540"
"340.75201","28.39614","0.08636"
"341.12399","28.42717","0.08809"
"341.49600","28.45815","0.08833"
"341.86801","28.48912","0.09111"
"342.23999","28.52015","0.09267"
"342.61200","28.55112","0.09383"
"342.98401","28.58215","0.09447"
"343.35599","28.61318","0.09393"
"343.72800","28.64415","0.09672"
"344.10001","28.67506","0.09862"
"344.47198","28.70615","0.10110"
"344.84399","28.73712","0.10390"
"345.21600","28.76815","0.10729"
"345.58801","28.79912","0.10901"
"345.95999","28.83015","0.11165"
"346.33200","28.86113","0.11312"
"346.70401","28.89210","0.11514"
"347.07599","28.92313","0.11651"
"347.44800","28.95416","0.11848"
"347.82001","28.98513","0.11969"
"348.19199","29.01616","0.12058"
"348.56400","29.04713","0.12338"
"348.93600","29.07810","0.12447"
"349.30801","29.10913","0.12603"
"349.67999","29.14016","0.12906"
"350.05200","29.17107","0.13056"
"350.42401","29.20210","0.13165"
"350.79599","29.23314","0.13395"
"351.16800","29.26411","0.13603"
"351.54001","29.29514","0.13738"
"351.91199","29.32617","0.13869"
"352.28400","29.35714","0.14007"
"352.65601","29.38811","0.14258"
"353.02802","29.41914","0.14367"
"353.39999","29.45005","0.14491"
"353.77200","29.48108","0.14654"
"354.14401","29.51217","0.14810"
"354.51599","29.54314","0.14983"
"354.88800","29.57412","0.15080"
"355.26001","29.60515","0.15256"
"355.63199","29.63612","0.15438"
"356.00400","29.66709","0.15593"
"356.37601","29.69818","0.15804"
"356.74799","29.72909","0.15990"
"357.12000","29.76012","0.16112"
"357.49200","29.79109","0.16357"
"357.86401","29.82218","0.16613"
"358.23599","29.85315","0.16719"
"358.60800","29.88413","0.16931"
"358.98001","29.91515","0.17064"
"359.35199","29.94613","0.17210"
"359.72400","29.97710","0.17431"
"360.09601","30.00819","0.17540"
"360.46799","30.03916","0.17661"
"360.84000","30.07013","0.17801"
"361.21201","30.10110","0.17957"
"361.58401","30.13213","0.18082"
"361.95599","30.16310","0.18203"
"362.32800","30.19413","0.18320"
"362.70001","30.22516","0.18423"
"363.07199","30.25607","0.18537"
"363.44400","30.28711","0.18638"
"363.81601","30.31814","0.18783"
"364.18799","30.34911","0.18949"
"364.56000","30.38008","0.19074"
"364.93201","30.41117","0.19201"
"365.30399","30.44220","0.19345"
"365.67599","30.47311","0.19515"
"366.04800","30.50414","0.19736"
"366.42001","30.53517","0.19885"
"366.79199","30.56602","0.19956"
"367.16400","30.59718","0.20141"
"367.53601","30.62820","0.20353"
"367.90799","30.65912","0.20506"
"368.28000","30.69009","0.20828"
"368.65201","30.72118","0.21135"
"369.02399","30.75215","0.21335"
"369.39600","30.78306","0.21528"
"369.76801","30.81415","0.21740"
"370.14001","30.84518","0.21952"
"370.51199","30.87609","0.22142"
"370.88400","30.90718","0.22306"
"371.25601","30.93810","0.22476"
"371.62799","30.96912","0.22750"
"372.00000","31.00010","0.22922"
"372.37201","31.03113","0.04691"
"372.74399","31.06216","0.03446"
"373.11600","31.09307","0.03752"
"373.48801","31.12422","0.03606"
"373.85999","31.15519","0.03431"
"374.23199","31.18610","0.03524"
"374.60400","31.21719","0.03985"
"374.97601","31.24816","0.03687"
"375.34799","31.27907","0.03669"
"375.72000","31.31010","0.03893"
"376.09201","31.34114","0.04155"
"376.46399","31.37210","0.03938"
"376.83600","31.40308","0.03976"
"377.20801","31.43417","0.04292"
"377.57999","31.46508","0.04355"
"377.95200","31.49611","0.04284"
"378.32401","31.52714","0.04320"
"378.69601","31.55817","0.04449"
"379.06799","31.58914","0.04528"
"379.44000","31.62011","0.04459"
"379.81201","31.65120","0.04512"
"380.18399","31.68212","0.04643"
"380.55600","31.71315","0.04658"
"380.92801","31.74417","0.04766"
"381.29999","31.77509","0.04774"
"381.67200","31.80612","0.04942"
"382.04401","31.83715","0.05050"
"382.41599","31.86812","0.04973"
"382.78799","31.89909","0.05006"
"383.16000","31.93018","0.05117"
"383.53201","31.96115","0.05194"
"383.90399","31.99212","0.05126"
"384.27600","32.02316","0.05172"
"384.64801","32.05413","0.05292"
"385.01999","32.08503","0.05344"
"385.39200","32.11618","0.05393"
"385.76401","32.14716","0.05367"
"386.13599","32.17807","0.05507"
"386.50800","32.20916","0.05582"
"386.88000","32.24007","0.05647"
"387.25201","32.27110","0.05645"
"387.62399","32.30213","0.05753"
"387.99600","32.33310","0.05809"
"388.36801","32.36413","0.05928"
"388.73999","32.39511","0.05894"
"389.11200","32.42613","0.05983"
"389.48401","32.45711","0.06023"
"389.85599","32.48814","0.06050"
"390.22800","32.51917","0.06019"
"390.60001","32.55020","0.06065"
"390.97198","32.58111","0.06082"
"391.34399","32.61214","0.06132"
"391.71600","32.64311","0.06154"
"392.08801","32.67408","0.06179"
"392.45999","32.70511","0.06220"
"392.83200","32.73621","0.06264"
"393.20401","32.76711","0.06239"
"393.57599","32.79808","0.06295"
"393.94800","32.82918","0.06280"
"394.32001","32.86015","0.06340"
"394.69199","32.89112","0.06377"
"395.06400","32.92215","0.06463"
"395.43600","32.95312","0.06472"
"395.80801","32.98403","0.06466"
"396.17999","33.01512","0.06565"
"396.55200","33.04615","0.06600"
"396.92401","33.07706","0.06614"
"397.29599","33.10815","0.06659"
"397.66800","33.13906","0.06709"
"398.04001","33.17010","0.06757"
"398.41199","33.20107","0.06788"
"398.78400","33.23215","0.06804"
"399.15601","33.26319","0.06691"
"399.52802","33.29410","0.06771"
"399.89999","33.32513","0.06784"
"400.27200","33.35616","0.06837"
"400.64401","33.38707","0.06643"
"401.01599","33.41816","0.06689"
"401.38800","33.44913","0.06735"
"401.76001","33.48010","0.06799"
"402.13199","33.51108","0.06823"
"402.50400","33.54217","0.06830"
"402.87601","33.57314","0.06877"
"403.24799","33.60411","0.06904"
"403.62000","33.63514","0.06916"
"403.99200","33.66611","0.06959"
"404.36401","33.69708","0.06904"
"404.73599","33.72817","0.06960"
"405.10800","33.75914","0.06989"
"405.48001","33.79018","0.07041"
"405.85199","33.82114","0.07064"
"406.22400","33.85218","0.07081"
"406.59601","33.88309","0.07126"
"406.96799","33.91406","0.07161"
"407.34000","33.94509","0.07179"
"407.71201","33.97612","0.07217"
"408.08401","34.00709","0.07242"
"408.45599","34.03818","0.07270"
"408.82800","34.06915","0.07296"
"409.20001","34.10012","0.07348"
"409.57199","34.13115","0.07390"
"409.94400","34.16219","0.07376"
"410.31601","34.19310","0.07394"
"410.68799","34.22412","0.07425"
"411.06000","34.25516","0.07460"
"411.43201","34.28607","0.07452"
"411.80399","34.31716","0.07492"
"412.17599","34.34813","0.07377"
"412.54800","34.37910","0.07422"
"412.92001","34.41013","0.07421"
"413.29199","34.44116","0.07460"
"413.66400","34.47213","0.07458"
"414.03601","34.50311","0.07500"
"414.40799","34.53419","0.07520"
"414.78000","34.56517","0.07551"
"415.15201","34.59608","0.07579"
"415.52399","34.62711","0.07636"
"415.89600","34.65814","0.07701"
"416.26801","34.68905","0.07693"
"416.64001","34.72014","0.07744"
"417.01199","34.75111","0.07757"
"417.38400","34.78214","0.07767"
"417.75601","34.81311","0.07853"
"418.12799","34.84415","0.07922"
"418.50000","34.87511","0.07896"
"418.87201","34.90615","0.07956"
"419.24399","34.93712","0.08024"
"419.61600","34.96815","0.08069"
"419.98801","34.99906","0.08144"
"420.35999","35.03015","0.08183"
"420.73199","35.06112","0.08280"
"421.10400","35.09209","0.08303"
"421.47601","35.12312","0.08399"
"421.84799","35.15415","0.08500"
"422.22000","35.18512","0.08523"
"422.59201","35.21615","0.08619"
"422.96399","35.24718","0.08457"
"423.33600","35.27816","0.08464"
"423.70801","35.30913","0.08516"
"424.07999","35.34016","0.08612"
"424.45200","35.37113","0.08551"
"424.82401","35.40210","0.08533"
"425.19601","35.43313","0.08645"
"425.56799","35.46416","0.08702"
"425.94000","35.49507","0.08782"
"426.31201","35.52617","0.08891"
"426.68399","35.55714","0.08957"
"427.05600","35.58810","0.08940"
"427.42801","35.61914","0.09065"
"427.79999","35.65011","0.09075"
"428.17200","35.68114","0.09208"
"428.54401","35.71211","0.08956"
"428.91599","35.74314","0.09088"
"429.28799","35.77417","0.09069"
"429.66000","35.80508","0.09069"
"430.03201","35.83617","0.09128"
"430.40399","35.86714","0.09181"
"430.77600","35.89812","0.09289"
"431.14801","35.92914","0.09349"
"431.51999","35.96017","0.09478"
"431.89200","35.99109","0.09502"
"432.26401","36.02212","0.09614"
"432.63599","36.05315","0.09797"
"433.00800","36.08412","0.09816"
"433.38000","36.11503","0.09885"
"433.75201","36.14618","0.10034"
"434.12399","36.17715","0.10197"
"434.49600","36.20807","0.10213"
"434.86801","36.23915","0.10243"
"435.23999","36.27018","0.10362"
"435.61200","36.30109","0.10090"
"435.98401","36.33213","0.10194"
"436.35599","36.36316","0.10375"
"436.72800","36.39413","0.10242"
"437.10001","36.42510","0.10339"
"437.47198","36.45619","0.10561"
"437.84399","36.48710","0.10622"
"438.21600","36.51807","0.10821"
"438.58801","36.54916","0.11001"
"438.95999","36.58014","0.11174"
"439.33200","36.61116","0.11346"
"439.70401","36.64214","0.11400"
"440.07599","36.67311","0.11556"
"440.44800","36.70408","0.11593"
"440.82001","36.73505","0.11711"
"441.19199","36.76614","0.11876"
"441.56400","36.79711","0.11926"
"441.93600","36.82814","0.11946"
"442.30801","36.85911","0.12091"
"442.67999","36.89014","0.12230"
"443.05200","36.92111","0.12264"
"443.42401","36.95214","0.12352"
"443.79599","36.98311","0.12447"
"444.16800","37.01409","0.12506"
"444.54001","37.04512","0.12624"
"444.91199","37.07615","0.12742"
"445.28400","37.10712","0.12908"
"445.65601","37.13821","0.13061"
"446.02802","37.16912","0.13073"
"446.39999","37.20009","0.13157"
"446.77200","37.23112","0.13232"
"447.14401","37.26215","0.13336"
"447.51599","37.29306","0.13491"
"447.88800","37.32415","0.13572"
"448.26001","37.35513","0.13654"
"448.63199","37.38616","0.13713"
"449.00400","37.41713","0.13631"
"449.37601","37.44816","0.13665"
"449.74799","37.47913","0.13668"
"450.12000","37.51010","0.13818"
"450.49200","37.54113","0.13913"
"450.86401","37.57216","0.14037"
"451.23599","37.60307","0.14121"
"451.60800","37.63416","0.14219"
"451.98001","37.66519","0.14323"
"452.35199","37.69611","0.14394"
"452.72400","37.72713","0.14404"
"453.09601","37.75817","0.14501"
"453.46799","37.78908","0.14480"
"453.84000","37.82005","0.14601"
"454.21201","37.85120","0.14666"
"454.58401","37.88211","0.14609"
"454.95599","37.91308","0.14606"
"455.32800","37.94417","0.14583"
"455.70001","37.97514","0.14117"
"456.07199","38.00605","0.14086"
"456.44400","38.03714","0.14113"
"456.81601","38.06818","0.14062"
"457.18799","38.09909","0.14028"
"457.56000","38.13012","0.14000"
"457.93201","38.16109","0.13990"
"458.30399","38.19212","0.14029"
"458.67599","38.22309","0.14170"
"459.04800","38.25418","0.13951"
"459.42001","38.28515","0.14101"
"459.79199","38.31606","0.14182"
"460.16400","38.34710","0.14211"
"460.53601","38.37818","0.14207"
"460.90799","38.40910","0.14374"
"461.28000","38.44019","0.14416"
"461.65201","38.47116","0.14427"
"462.02399","38.50213","0.14512"
"462.39600","38.53310","0.14553"
"462.76801","38.56413","0.14699"
"463.14001","38.59510","0.14855"
"463.51199","38.62607","0.14957"
"463.88400","38.65716","0.15039"
"464.25601","38.68813","0.15211"
"464.62799","38.71910","0.15058"
"465.00000","38.75013","0.15195"
"465.37201","38.78117","0.15258"
"465.74399","38.81214","0.15287"
"466.11600","38.84311","0.15313"
"466.48801","38.87420","0.15386"
"466.85999","38.90511","0.15548"
"467.23199","38.93608","0.15611"
"467.60400","38.96717","0.15741"
"467.97601","38.99814","0.15818"
"468.34799","39.02911","0.15886"
"468.72000","39.06014","0.15844"
"469.09201","39.09111","0.15891"
"469.46399","39.12209","0.16138"
"469.83600","39.15312","0.16260"
"470.20801","39.18415","0.16366"
"470.57999","39.21505","0.16431"
"470.95200","39.24615","0.16519"
"471.32401","39.27718","0.16585"
"471.69601","39.30803","0.16690"
"472.06799","39.33912","0.16759"
"472.44000","39.37009","0.16869"
"472.81201","39.40113","0.16947"
"473.18399","39.43215","0.16992"
"473.55600","39.46312","0.16990"
"473.92801","39.49415","0.17200"
"474.29999","39.52512","0.17325"
"474.67200","39.55616","0.17408"
"475.04401","39.58719","0.17415"
"475.41599","39.61810","0.17469"
"475.78799","39.64912","0.17522"
"476.16000","39.68016","0.17603"
"476.53201","39.71107","0.17089"
"476.90399","39.74216","0.16386"
"477.27600","39.77313","0.16422"
"477.64801","39.80410","0.15914"
"478.01999","39.83507","0.16069"
"478.39200","39.86617","0.16237"
"478.76401","39.89714","0.16404"
"479.13599","39.92811","0.16607"
"479.50800","39.95920","0.16730"
"479.88000","39.99017","0.16843"
"480.25201","40.02108","0.16933"
"480.62399","40.05217","0.17122"
"480.99600","40.08314","0.17254"
"481.36801","40.11411","0.17457"
"481.73999","40.14515","0.17574"
"482.11200","40.17617","0.17667"
"482.48401","40.20709","0.17809"
"482.85599","40.23811","0.17893"
"483.22800","40.26914","0.17953"
"483.60001","40.30017","0.18046"
"483.97198","40.33109","0.18119"
"484.34399","40.36212","0.18219"
"484.71600","40.39315","0.18303"
"485.08801","40.42412","0.18395"
"485.45999","40.45515","0.18427"
"485.83200","40.48618","0.18514"
"486.20401","40.51704","0.18556"
"486.57599","40.54813","0.17297"
"486.94800","40.57922","0.17392"
"487.32001","40.61007","0.17523"
"487.69199","40.64116","0.17704"
"488.06400","40.67213","0.17800"
"488.43600","40.70310","0.17959"
"488.80801","40.73407","0.18046"
"489.17999","40.76516","0.18146"
"489.55200","40.79613","0.18224"
"489.92401","40.82710","0.18309"
"490.29599","40.85819","0.18375"
"490.66800","40.88916","0.18459"
"491.04001","40.92007","0.18542"
"491.41199","40.95111","0.18605"
"491.78400","40.98207","0.18738"
"492.15601","41.01311","0.18833"
"492.52802","41.04408","0.18969"
"492.89999","41.07511","0.19076"
"493.27200","41.10614","0.19239"
"493.64401","41.13712","0.19374"
"494.01599","41.16814","0.19499"
"494.38800","41.19911","0.19592"
"494.76001","41.23008","0.19705"
"495.13199","41.26117","0.19794"
"495.50400","41.29214","0.19894"
"495.87601","41.32306","0.20008"
"496.24799","41.35409","0.20106"
"496.62000","41.38511","0.20109"
"496.99200","41.41609","0.20266"
"497.36401","41.44712","0.20402"
"497.73599","41.47815","0.20481"
"498.10800","41.50906","0.20691"
"498.48001","41.54009","0.20797"
"498.85199","41.57113","0.20955"
"499.22400","41.60216","0.21124"
"499.59601","41.63312","0.21316"
"499.96799","41.66410","0.21228"
"500.34000","41.69513","0.21522"
"500.71201","41.72610","0.21627"
"501.08401","41.75713","0.21890"
"501.45599","41.78816","0.22035"
"501.82800","41.81907","0.22164"
"502.20001","41.85017","0.22209"
"502.57199","41.88113","0.22339"
"502.94400","41.91216","0.22484"
"503.31601","41.94308","0.22596"
"503.68799","41.97416","0.22670"
"504.06000","42.00514","0.22870"
"504.43201","42.03611","0.23004"
"504.80399","42.06713","0.23183"
"505.17599","42.09817","0.23299"
"505.54800","42.12908","0.23312"
"505.92001","42.16017","0.23565"
"506.29199","42.19114","0.23662"
"506.66400","42.22211","0.23840"
"507.03601","42.25314","0.24064"
"507.40799","42.28411","0.24267"
"507.78000","42.31515","0.24366"
"508.15201","42.34612","0.24576"
"508.52399","42.37715","0.24726"
"508.89600","42.40812","0.24840"
"509.26801","42.43909","0.25038"
"509.64001","42.47018","0.25295"
"510.01199","42.50109","0.25438"
"510.38400","42.53212","0.25770"
"510.75601","42.56315","0.26016"
"511.12799","42.59418","0.26023"
"511.50000","42.62509","0.26201"
"511.87201","42.65612","0.26443"
"512.24402","42.68716","0.26757"
"512.61603","42.71813","0.26654"
"512.98798","42.74910","0.26959"
"513.35999","42.78019","0.27122"
"513.73199","42.81110","0.27013"
"514.10400","42.84213","0.27211"
"514.47601","42.87316","0.27612"
"514.84802","42.90413","0.27695"
"515.21997","42.93510","0.27829"
"515.59198","42.96619","0.27974"
"515.96399","42.99717","0.28051"
"516.33600","43.02802","0.28133"
"516.70801","43.05911","0.28376"
"517.08002","43.09014","0.28473"
"517.45203","43.12105","0.28066"
"517.82397","43.15220","0.28220"
"518.19598","43.18311","0.28290"
"518.56799","43.21408","0.28495"
"518.94000","43.24511","0.28574"
"519.31201","43.27614","0.28731"
"519.68402","43.30711","0.28680"
"520.05603","43.33815","0.28798"
"520.42798","43.36911","0.28913"
"520.79999","43.40015","0.28981"
"521.17200","43.43106","0.29071"
"521.54401","43.46215","0.29157"
"521.91602","43.49312","0.29217"
"522.28802","43.52415","0.29310"
"522.65997","43.55506","0.29375"
"523.03198","43.58615","0.29435"
"523.40399","43.61712","0.29480"
"523.77600","43.64809","0.29592"
"524.14801","43.67918","0.29554"
"524.52002","43.71016","0.29609"
"524.89203","43.74106","0.29772"
"525.26398","43.77209","0.29842"
"525.63599","43.80313","0.29914"
"526.00800","43.83410","0.30036"
"526.38000","43.86513","0.30142"
"526.75201","43.89616","0.30284"
"527.12402","43.92707","0.30420"
"527.49597","43.95810","0.30512"
"527.86798","43.98913","0.30741"
"528.23999","44.02010","0.30916"
"528.61200","44.05113","0.30965"
"528.98401","44.08210","0.31131"
"529.35602","44.11314","0.31409"
"529.72803","44.14417","0.31574"
"530.09998","44.17514","0.31864"
"530.47198","44.20617","0.32088"
"530.84399","44.23708","0.32294"
"531.21600","44.26817","0.32608"
"531.58801","44.29914","0.32736"
"531.96002","44.33005","0.32860"
"532.33197","44.36115","0.32992"
"532.70398","44.39212","0.33226"
"533.07599","44.42314","0.33336"
"533.44800","44.45417","0.33584"
"533.82001","44.48509","0.33804"
"534.19202","44.51618","0.33930"
"534.56403","44.54709","0.34137"
"534.93597","44.57812","0.32466"
"535.30798","44.60915","0.32578"
"535.67999","44.64006","0.18502"
"536.05200","44.67115","0.09607"
"536.42401","44.70213","0.08371"
"536.79602","44.73310","0.14337"
"537.16803","44.76412","0.08602"
"537.53998","44.79509","0.08769"
"537.91199","44.82612","0.11471"
"538.28400","44.85710","0.09322"
"538.65601","44.88819","0.08877"
"539.02802","44.91916","0.10937"
"539.40002","44.95013","0.10464"
"539.77197","44.98116","0.01175"
"540.14398","45.01213","0.02330"
"540.51599","45.04305","0.01249"
"540.88800","45.07413","0.01745"
"541.26001","45.10517","0.02003"
"541.63202","45.13607","0.01563"
"542.00403","45.16710","0.01539"
"542.37598","45.19820","0.01899"
"542.74799","45.22905","0.01884"
"543.12000","45.26008","0.01470"
"543.49200","45.29117","0.01683"
"543.86401","45.32214","0.01767"
"544.23602","45.35305","0.01929"
"544.60797","45.38414","0.01624"
"544.97998","45.41511","0.01536"
"545.35199","45.44609","0.02030"
"545.72400","45.47717","0.01832"
"546.09601","45.50821","0.01697"
"546.46802","45.53906","0.01818"
"546.84003","45.57021","0.01792"
"547.21198","45.60117","0.01996"
"547.58398","45.63203","0.01742"
"547.95599","45.66318","0.01734"
"548.32800","45.69415","0.02006"
"548.70001","45.72512","0.01880"
"549.07202","45.75610","0.01868"
"549.26398","45.77212","0.02000"