File: Force_trajectories/170107_2/Specimen_RawData_4.csv
End date,"1/7/2017"
Specimen label,"17DG_37"
Maximum Load,"1.09597",N

Time,Extension,Load
(s),(mm),(N)
"0.00000","0.00000","-0.00034"
"0.44400","0.03731","0.00116"
"0.88800","0.07426","0.00281"
"1.33200","0.11121","0.00296"
"1.77600","0.14816","0.00354"
"2.22000","0.18517","0.00440"
"2.66400","0.22218","0.00412"
"3.10800","0.25919","0.00489"
"3.55200","0.29620","0.00573"
"3.99600","0.33315","0.00612"
"4.44000","0.37010","0.00645"
"4.88400","0.40711","0.00695"
"5.32800","0.44418","0.00677"
"5.77200","0.48125","0.00702"
"6.21600","0.51826","0.00772"
"6.66000","0.55515","0.00776"
"7.10400","0.59216","0.00798"
"7.54800","0.62917","0.00881"
"7.99200","0.66623","0.00845"
"8.43600","0.70312","0.00833"
"8.88000","0.74019","0.00957"
"9.32400","0.77714","0.00972"
"9.76800","0.81415","0.00929"
"10.21200","0.85116","0.00914"
"10.65600","0.88823","0.00962"
"11.10000","0.92518","0.00952"
"11.54400","0.96219","0.00982"
"11.98800","0.99914","0.01058"
"12.43200","1.03615","0.01033"
"12.87600","1.07316","0.01014"
"13.32000","1.11017","0.01054"
"13.76400","1.14724","0.01079"
"14.20800","1.18413","0.01136"
"14.65200","1.22114","0.01154"
"15.09600","1.25815","0.01173"
"15.54000","1.29522","0.01118"
"15.98400","1.33223","0.01186"
"16.42800","1.36918","0.01217"
"16.87200","1.40619","0.01214"
"17.31600","1.44314","0.01246"
"17.76000","1.48015","0.01262"
"18.20400","1.51716","0.01241"
"18.64800","1.55417","0.01217"
"19.09200","1.59118","0.01296"
"19.53600","1.62813","0.01348"
"19.98000","1.66514","0.01323"
"20.42400","1.70221","0.01299"
"20.86800","1.73922","0.01415"
"21.31200","1.77623","0.01355"
"21.75600","1.81318","0.01377"
"22.20000","1.85013","0.01417"
"22.64400","1.88720","0.01440"
"23.08800","1.92421","0.01486"
"23.53200","1.96122","0.01440"
"23.97600","1.99817","0.01470"
"24.42000","2.03518","0.01448"
"24.86400","2.07219","0.01527"
"25.30800","2.10920","0.01514"
"25.75200","2.14621","0.01489"
"26.19600","2.18321","0.01583"
"26.64000","2.22016","0.01544"
"27.08400","2.25717","0.01543"
"27.52800","2.29412","0.01656"
"27.97200","2.33113","0.01645"
"28.41600","2.36820","0.01655"
"28.86000","2.40521","0.01630"
"29.30400","2.44222","0.01674"
"29.74800","2.47917","0.01706"
"30.19200","2.51612","0.01674"
"30.63600","2.55319","0.01690"
"31.08000","2.59020","0.01628"
"31.52400","2.62721","0.01689"
"31.96800","2.66416","0.01700"
"32.41200","2.70111","0.01754"
"32.85600","2.73812","0.01792"
"33.30000","2.77519","0.01813"
"33.74400","2.81220","0.01814"
"34.18800","2.84921","0.01800"
"34.63200","2.88616","0.01868"
"35.07600","2.92317","0.01814"
"35.52000","2.96018","0.01798"
"35.96400","2.99719","0.01891"
"36.40800","3.03420","0.01926"
"36.85200","3.07115","0.01921"
"37.29600","3.10810","0.01893"
"37.74000","3.14511","0.01953"
"38.18400","3.18224","0.02013"
"38.62800","3.21919","0.01997"
"39.07200","3.25626","0.01975"
"39.51600","3.29321","0.02005"
"39.96000","3.33016","0.02026"
"40.40400","3.36717","0.02046"
"40.84800","3.40418","0.02076"
"41.29200","3.44113","0.02099"
"41.73600","3.47820","0.02144"
"42.18000","3.51521","0.02165"
"42.62400","3.55216","0.02218"
"43.06800","3.58917","0.02229"
"43.51200","3.62618","0.02220"
"43.95600","3.66319","0.02201"
"44.40000","3.70019","0.02244"
"44.84400","3.73720","0.02269"
"45.28800","3.77415","0.02305"
"45.73200","3.81116","0.02294"
"46.17600","3.84823","0.02302"
"46.62000","3.88518","0.02378"
"47.06400","3.92219","0.02362"
"47.50800","3.95908","0.02380"
"47.95200","3.99615","0.02431"
"48.39600","4.03322","0.02424"
"48.84000","4.07023","0.02480"
"49.28400","4.10724","0.02453"
"49.72800","4.14413","0.02425"
"50.17200","4.18114","0.02480"
"50.61600","4.21815","0.02414"
"51.06000","4.25522","0.01981"
"51.50400","4.29217","0.01956"
"51.94800","4.32918","0.01921"
"52.39200","4.36613","0.01941"
"52.83600","4.40320","0.02034"
"53.28000","4.44021","0.02028"
"53.72400","4.47722","0.02128"
"54.16800","4.51417","0.01935"
"54.61200","4.55118","0.01962"
"55.05600","4.58813","0.02025"
"55.50000","4.62520","0.02078"
"55.94400","4.66215","0.02161"
"56.38800","4.69922","0.02188"
"56.83200","4.73623","0.02243"
"57.27600","4.77318","0.02292"
"57.72000","4.81013","0.02324"
"58.16400","4.84714","0.02314"
"58.60800","4.88421","0.02418"
"59.05200","4.92116","0.02486"
"59.49600","4.95817","0.02499"
"59.94000","4.99518","0.02485"
"60.38400","5.03213","0.02574"
"60.82800","5.06914","0.02601"
"61.27200","5.10615","0.02653"
"61.71600","5.14316","0.02707"
"62.16000","5.18017","0.02762"
"62.60400","5.21718","0.02838"
"63.04800","5.25418","0.02881"
"63.49200","5.29125","0.02906"
"63.93600","5.32820","0.02953"
"64.38000","5.36521","0.02986"
"64.82400","5.40216","0.03003"
"65.26800","5.43911","0.03121"
"65.71200","5.47612","0.03151"
"66.15600","5.51319","0.03174"
"66.60000","5.55020","0.03213"
"67.04400","5.58721","0.03226"
"67.48800","5.62422","0.03284"
"67.93200","5.66117","0.03352"
"68.37600","5.69824","0.03419"
"68.82000","5.73519","0.03439"
"69.26400","5.77220","0.03510"
"69.70800","5.80921","0.03515"
"70.15200","5.84616","0.03516"
"70.59600","5.88317","0.03571"
"71.04000","5.92012","0.03606"
"71.48400","5.95719","0.03678"
"71.92800","5.99420","0.03690"
"72.37200","6.03121","0.03703"
"72.81600","6.06816","0.03734"
"73.26000","6.10511","0.03744"
"73.70400","6.14218","0.03800"
"74.14800","6.17919","0.03787"
"74.59200","6.21620","0.03836"
"75.03600","6.25315","0.03767"
"75.48000","6.29010","0.03803"
"75.92400","6.32717","0.03663"
"76.36800","6.36424","0.03620"
"76.81200","6.40119","0.03725"
"77.25600","6.43820","0.03816"
"77.70000","6.47515","0.03802"
"78.14400","6.51222","0.03804"
"78.58800","6.54923","0.03837"
"79.03200","6.58618","0.03922"
"79.47600","6.62319","0.03896"
"79.92000","6.66019","0.03926"
"80.36400","6.69715","0.03685"
"80.80800","6.73410","0.03762"
"81.25200","6.77122","0.03718"
"81.69600","6.80817","0.03761"
"82.14000","6.84524","0.03770"
"82.58400","6.88219","0.03863"
"83.02800","6.91914","0.03898"
"83.47200","6.95615","0.03919"
"83.91600","6.99316","0.03952"
"84.36000","7.03017","0.03989"
"84.80400","7.06718","0.04027"
"85.24800","7.10419","0.04083"
"85.69200","7.14114","0.04121"
"86.13600","7.17821","0.04089"
"86.58000","7.21522","0.04082"
"87.02400","7.25217","0.04125"
"87.46800","7.28918","0.04200"
"87.91200","7.32619","0.04229"
"88.35600","7.36314","0.04212"
"88.80000","7.40015","0.04296"
"89.24400","7.43722","0.04260"
"89.68800","7.47417","0.04321"
"90.13200","7.51118","0.04265"
"90.57600","7.54813","0.04159"
"91.02000","7.58520","0.04110"
"91.46400","7.62221","0.04169"
"91.90800","7.65922","0.04174"
"92.35200","7.69617","0.04191"
"92.79600","7.73312","0.04229"
"93.24000","7.77013","0.04243"
"93.68400","7.80714","0.04263"
"94.12800","7.84421","0.04155"
"94.57200","7.88116","0.04197"
"95.01600","7.91817","0.04209"
"95.46000","7.95518","0.04043"
"95.90400","7.99219","0.04114"
"96.34800","8.02920","0.04103"
"96.79200","8.06621","0.04119"
"97.23600","8.10316","0.04014"
"97.68000","8.14017","0.04160"
"98.12400","8.17712","0.04063"
"98.56800","8.21418","0.04083"
"99.01200","8.25119","0.04140"
"99.45600","8.28820","0.04151"
"99.90000","8.32521","0.04198"
"100.34400","8.36222","0.04135"
"100.78800","8.39917","0.04116"
"101.23200","8.43612","0.04131"
"101.67600","8.47319","0.04153"
"102.12000","8.51020","0.04116"
"102.56400","8.54721","0.04210"
"103.00800","8.58416","0.04251"
"103.45200","8.62111","0.04259"
"103.89600","8.65818","0.04245"
"104.34000","8.69513","0.04297"
"104.78400","8.73220","0.04307"
"105.22800","8.76921","0.04296"
"105.67200","8.80622","0.04315"
"106.11600","8.84317","0.04355"
"106.56000","8.88024","0.04384"
"107.00400","8.91725","0.04292"
"107.44800","8.95414","0.04236"
"107.89200","8.99121","0.04256"
"108.33600","9.02810","0.04281"
"108.78000","9.06517","0.04365"
"109.22400","9.10218","0.04394"
"109.66800","9.13925","0.04425"
"110.11200","9.17620","0.04442"
"110.55600","9.21315","0.04442"
"111.00000","9.25016","0.04440"
"111.44400","9.28717","0.04423"
"111.88800","9.32418","0.04479"
"112.33200","9.36119","0.04519"
"112.77600","9.39820","0.04566"
"113.22000","9.43515","0.04626"
"113.66400","9.47216","0.04622"
"114.10800","9.50917","0.04615"
"114.55200","9.54624","0.04648"
"114.99600","9.58325","0.04449"
"115.44000","9.62020","0.04497"
"115.88400","9.65715","0.04575"
"116.32800","9.69416","0.04495"
"116.77200","9.73116","0.04482"
"117.21600","9.76818","0.04566"
"117.66000","9.80518","0.04364"
"118.10400","9.84213","0.06781"
"118.54800","9.87914","0.04429"
"118.99200","9.91615","0.04237"
"119.43600","9.95322","0.04304"
"119.88000","9.99023","0.01401"
"120.32400","10.02718","0.02918"
"120.76800","10.06413","0.06005"
"121.21200","10.10114","0.03669"
"121.65600","10.13821","0.03774"
"122.10000","10.17516","0.04076"
"122.54400","10.21217","0.04188"
"122.98800","10.24918","0.04207"
"123.43200","10.28613","0.04347"
"123.87600","10.32314","0.04360"
"124.32000","10.36021","0.04496"
"124.76400","10.39716","0.04594"
"125.20800","10.43417","0.04730"
"125.65200","10.47118","0.04863"
"126.09600","10.50813","0.04924"
"126.54000","10.54514","0.05031"
"126.98400","10.58221","0.05153"
"127.42800","10.61922","0.05233"
"127.87200","10.65617","0.05262"
"128.31599","10.69318","0.05295"
"128.75999","10.73019","0.05381"
"129.20399","10.76720","0.05329"
"129.64799","10.80421","0.05528"
"130.09200","10.84116","0.05558"
"130.53600","10.87823","0.05709"
"130.98000","10.91518","0.05790"
"131.42400","10.95213","0.05853"
"131.86800","10.98914","0.05926"
"132.31200","11.02621","0.06047"
"132.75600","11.06322","0.06175"
"133.20000","11.10023","0.06125"
"133.64400","11.13718","0.06211"
"134.08800","11.17419","0.06251"
"134.53200","11.21119","0.06407"
"134.97600","11.24821","0.06403"
"135.42000","11.28521","0.06465"
"135.86400","11.32211","0.06602"
"136.30800","11.35911","0.06605"
"136.75200","11.39612","0.06721"
"137.19600","11.43319","0.06792"
"137.64000","11.47020","0.06837"
"138.08400","11.50727","0.06939"
"138.52800","11.54416","0.06991"
"138.97200","11.58117","0.07026"
"139.41600","11.61818","0.07095"
"139.86000","11.65519","0.07160"
"140.30400","11.69220","0.07154"
"140.74800","11.72921","0.07215"
"141.19200","11.76616","0.07282"
"141.63600","11.80311","0.07307"
"142.08000","11.84018","0.07340"
"142.52400","11.87725","0.07347"
"142.96800","11.91420","0.07374"
"143.41200","11.95121","0.07442"
"143.85600","11.98816","0.07499"
"144.30000","12.02517","0.07539"
"144.74400","12.06218","0.07591"
"145.18800","12.09919","0.07613"
"145.63200","12.13620","0.07656"
"146.07600","12.17315","0.07680"
"146.52000","12.21010","0.07712"
"146.96400","12.24717","0.07774"
"147.40800","12.28418","0.07806"
"147.85201","12.32119","0.07898"
"148.29601","12.35820","0.07945"
"148.74001","12.39521","0.07993"
"149.18401","12.43216","0.08061"
"149.62801","12.46917","0.08125"
"150.07201","12.50618","0.08200"
"150.51601","12.54319","0.08182"
"150.96001","12.58020","0.08297"
"151.40401","12.61715","0.08314"
"151.84801","12.65416","0.08419"
"152.29201","12.69116","0.08527"
"152.73599","12.72824","0.08665"
"153.17999","12.76519","0.08728"
"153.62399","12.80219","0.08870"
"154.06799","12.83914","0.08949"
"154.51199","12.87615","0.09043"
"154.95599","12.91317","0.09161"
"155.39999","12.95017","0.09341"
"155.84399","12.98718","0.09468"
"156.28799","13.02413","0.09612"
"156.73199","13.06114","0.09756"
"157.17599","13.09821","0.09817"
"157.62000","13.13516","0.09888"
"158.06400","13.17223","0.10134"
"158.50800","13.20924","0.10345"
"158.95200","13.24613","0.10474"
"159.39600","13.28314","0.10794"
"159.84000","13.32015","0.10904"
"160.28400","13.35716","0.11164"
"160.72800","13.39423","0.11284"
"161.17200","13.43118","0.11503"
"161.61600","13.46819","0.11719"
"162.06000","13.50520","0.11980"
"162.50400","13.54221","0.11997"
"162.94800","13.57922","0.12224"
"163.39200","13.61617","0.12356"
"163.83600","13.65318","0.12562"
"164.28000","13.69013","0.12702"
"164.72400","13.72720","0.12941"
"165.16800","13.76421","0.13068"
"165.61200","13.80116","0.13222"
"166.05600","13.83823","0.13477"
"166.50000","13.87518","0.13570"
"166.94400","13.91213","0.13703"
"167.38800","13.94914","0.13815"
"167.83200","13.98621","0.13989"
"168.27600","14.02316","0.14101"
"168.72000","14.06023","0.14297"
"169.16400","14.09712","0.14479"
"169.60800","14.13413","0.14587"
"170.05200","14.17114","0.14553"
"170.49600","14.20827","0.14741"
"170.94000","14.24522","0.14892"
"171.38400","14.28217","0.15088"
"171.82800","14.31918","0.15101"
"172.27200","14.35612","0.15313"
"172.71600","14.39319","0.15516"
"173.16000","14.43015","0.15739"
"173.60400","14.46721","0.15898"
"174.04800","14.50416","0.16066"
"174.49200","14.54111","0.16290"
"174.93600","14.57812","0.16453"
"175.38000","14.61519","0.12431"
"175.82401","14.65220","0.12405"
"176.26801","14.68921","0.12683"
"176.71201","14.72616","0.10453"
"177.15601","14.76317","0.10596"
"177.60001","14.80018","0.10828"
"178.04401","14.83719","0.11064"
"178.48801","14.87420","0.11373"
"178.93201","14.91115","0.07915"
"179.37601","14.94810","0.08113"
"179.82001","14.98517","0.08130"
"180.26401","15.02218","0.08339"
"180.70799","15.05919","0.08401"
"181.15199","15.09620","0.08544"
"181.59599","15.13321","0.08643"
"182.03999","15.17016","0.08728"
"182.48399","15.20717","0.08966"
"182.92799","15.24418","0.09040"
"183.37199","15.28119","0.09184"
"183.81599","15.31820","0.08819"
"184.25999","15.35515","0.08937"
"184.70399","15.39216","0.09065"
"185.14799","15.42917","0.09158"
"185.59200","15.46624","0.09310"
"186.03600","15.50319","0.09442"
"186.48000","15.54026","0.09645"
"186.92400","15.57715","0.09761"
"187.36800","15.61410","0.09984"
"187.81200","15.65123","0.10097"
"188.25600","15.68824","0.10313"
"188.70000","15.72518","0.10552"
"189.14400","15.76219","0.10734"
"189.58800","15.79914","0.11015"
"190.03200","15.83615","0.11191"
"190.47600","15.87322","0.11595"
"190.92000","15.91017","0.11794"
"191.36400","15.94718","0.11949"
"191.80800","15.98419","0.12167"
"192.25200","16.02114","0.12377"
"192.69600","16.05815","0.12572"
"193.14000","16.09522","0.12752"
"193.58400","16.13217","0.12881"
"194.02800","16.16924","0.12992"
"194.47200","16.20619","0.13185"
"194.91600","16.24320","0.13305"
"195.36000","16.28021","0.13539"
"195.80400","16.31722","0.13707"
"196.24800","16.35417","0.13851"
"196.69200","16.39118","0.13976"
"197.13600","16.42813","0.14164"
"197.58000","16.46514","0.14339"
"198.02400","16.50215","0.14374"
"198.46800","16.53916","0.14509"
"198.91200","16.57623","0.14682"
"199.35600","16.61318","0.14874"
"199.80000","16.65013","0.14918"
"200.24400","16.68720","0.14969"
"200.68800","16.72415","0.15206"
"201.13200","16.76122","0.15313"
"201.57600","16.79817","0.15571"
"202.02000","16.83518","0.15699"
"202.46400","16.87207","0.15838"
"202.90800","16.90914","0.16057"
"203.35201","16.94621","0.16193"
"203.79601","16.98322","0.16411"
"204.24001","17.02023","0.16583"
"204.68401","17.05718","0.16768"
"205.12801","17.09413","0.16899"
"205.57201","17.13120","0.17093"
"206.01601","17.16821","0.17273"
"206.46001","17.20515","0.17388"
"206.90401","17.24216","0.17550"
"207.34801","17.27911","0.17582"
"207.79201","17.31613","0.17129"
"208.23599","17.35319","0.17431"
"208.67999","17.39021","0.17601"
"209.12399","17.42721","0.17688"
"209.56799","17.46416","0.17782"
"210.01199","17.50117","0.17905"
"210.45599","17.53812","0.18054"
"210.89999","17.57519","0.18069"
"211.34399","17.61220","0.18173"
"211.78799","17.64921","0.18290"
"212.23199","17.68616","0.18355"
"212.67599","17.72311","0.18519"
"213.12000","17.76018","0.18613"
"213.56400","17.79725","0.18717"
"214.00800","17.83426","0.18795"
"214.45200","17.87121","0.18879"
"214.89600","17.90816","0.19009"
"215.34000","17.94511","0.19165"
"215.78400","17.98218","0.19306"
"216.22800","18.01925","0.19416"
"216.67200","18.05620","0.19602"
"217.11600","18.09321","0.19768"
"217.56000","18.13010","0.19944"
"218.00400","18.16717","0.20106"
"218.44800","18.20430","0.20216"
"218.89200","18.24119","0.20385"
"219.33600","18.27826","0.20542"
"219.78000","18.31515","0.20839"
"220.22400","18.35216","0.20977"
"220.66800","18.38917","0.21125"
"221.11200","18.42618","0.21318"
"221.55600","18.46319","0.21590"
"222.00000","18.50014","0.21791"
"222.44400","18.53715","0.21974"
"222.88800","18.57416","0.22176"
"223.33200","18.61123","0.22421"
"223.77600","18.64824","0.22571"
"224.22000","18.68519","0.22746"
"224.66400","18.72219","0.22913"
"225.10800","18.75915","0.23114"
"225.55200","18.79616","0.23268"
"225.99600","18.83316","0.23547"
"226.44000","18.87017","0.23742"
"226.88400","18.90718","0.23979"
"227.32800","18.94419","0.24167"
"227.77200","18.98114","0.24510"
"228.21600","19.01815","0.24768"
"228.66000","19.05522","0.25077"
"229.10400","19.09217","0.25315"
"229.54800","19.12924","0.25721"
"229.99200","19.16613","0.26056"
"230.43600","19.20308","0.26482"
"230.88000","19.24015","0.26855"
"231.32401","19.27722","0.27165"
"231.76801","19.31417","0.27521"
"232.21201","19.35118","0.27770"
"232.65601","19.38819","0.28003"
"233.10001","19.42514","0.28219"
"233.54401","19.46215","0.28371"
"233.98801","19.49922","0.28597"
"234.43201","19.53617","0.28783"
"234.87601","19.57318","0.28902"
"235.32001","19.61013","0.29070"
"235.76401","19.64714","0.29150"
"236.20799","19.68421","0.29274"
"236.65199","19.72116","0.29331"
"237.09599","19.75817","0.29431"
"237.53999","19.79518","0.29545"
"237.98399","19.83213","0.29596"
"238.42799","19.86913","0.29734"
"238.87199","19.90621","0.29813"
"239.31599","19.94321","0.29920"
"239.75999","19.98017","0.30082"
"240.20399","20.01712","0.30192"
"240.64799","20.05413","0.30362"
"241.09200","20.09114","0.30576"
"241.53600","20.12821","0.30811"
"241.98000","20.16528","0.31046"
"242.42400","20.20222","0.31252"
"242.86800","20.23918","0.31658"
"243.31200","20.27612","0.31986"
"243.75600","20.31314","0.32331"
"244.20000","20.35020","0.32574"
"244.64400","20.38721","0.32910"
"245.08800","20.42422","0.33183"
"245.53200","20.46111","0.33523"
"245.97600","20.49812","0.33848"
"246.42000","20.53525","0.34174"
"246.86400","20.57226","0.34377"
"247.30800","20.60921","0.34633"
"247.75200","20.64616","0.34917"
"248.19600","20.68317","0.35175"
"248.64000","20.72018","0.35379"
"249.08400","20.75719","0.35573"
"249.52800","20.79414","0.35690"
"249.97200","20.83115","0.35893"
"250.41600","20.86816","0.36156"
"250.86000","20.90517","0.36256"
"251.30400","20.94218","0.36453"
"251.74800","20.97919","0.36713"
"252.19200","21.01620","0.36957"
"252.63600","21.05321","0.37155"
"253.08000","21.09016","0.37413"
"253.52400","21.12711","0.37639"
"253.96800","21.16412","0.37893"
"254.41200","21.20119","0.38057"
"254.85600","21.23820","0.38297"
"255.30000","21.27515","0.38472"
"255.74400","21.31216","0.38672"
"256.18799","21.34917","0.38824"
"256.63199","21.38624","0.38966"
"257.07599","21.42325","0.39219"
"257.51999","21.46020","0.39471"
"257.96399","21.49714","0.39710"
"258.40799","21.53410","0.40086"
"258.85199","21.57117","0.40307"
"259.29599","21.60818","0.40622"
"259.73999","21.64519","0.40954"
"260.18399","21.68220","0.41296"
"260.62799","21.71915","0.41638"
"261.07199","21.75615","0.42008"
"261.51599","21.79323","0.42363"
"261.95999","21.83023","0.42767"
"262.40399","21.86719","0.42972"
"262.84799","21.90419","0.42846"
"263.29199","21.94108","0.42998"
"263.73599","21.97815","0.43265"
"264.17999","22.01516","0.43467"
"264.62399","22.05223","0.43725"
"265.06799","22.08918","0.43993"
"265.51199","22.12613","0.44251"
"265.95599","22.16314","0.44529"
"266.39999","22.20015","0.44335"
"266.84399","22.23722","0.44659"
"267.28799","22.27417","0.44907"
"267.73199","22.31124","0.45301"
"268.17599","22.34819","0.45660"
"268.62000","22.38514","0.46021"
"269.06400","22.42215","0.46330"
"269.50800","22.45916","0.46841"
"269.95200","22.49617","0.47280"
"270.39600","22.53324","0.47709"
"270.84000","22.57019","0.48075"
"271.28400","22.60714","0.48458"
"271.72800","22.64421","0.48836"
"272.17200","22.68116","0.49204"
"272.61600","22.71823","0.49495"
"273.06000","22.75518","0.49688"
"273.50400","22.79213","0.49884"
"273.94800","22.82914","0.50044"
"274.39200","22.86621","0.50195"
"274.83600","22.90322","0.50389"
"275.28000","22.94023","0.50606"
"275.72400","22.97718","0.50800"
"276.16800","23.01419","0.51092"
"276.61200","23.05120","0.51451"
"277.05600","23.08821","0.51713"
"277.50000","23.12516","0.52126"
"277.94400","23.16217","0.52518"
"278.38800","23.19912","0.52949"
"278.83200","23.23613","0.53408"
"279.27600","23.27319","0.53788"
"279.72000","23.31021","0.54118"
"280.16400","23.34722","0.54404"
"280.60800","23.38422","0.52440"
"281.05200","23.42112","0.53018"
"281.49600","23.45818","0.53543"
"281.94000","23.49513","0.53936"
"282.38400","23.53220","0.54516"
"282.82800","23.56915","0.54951"
"283.27200","23.60616","0.55334"
"283.71600","23.64311","0.55781"
"284.16000","23.68018","0.56231"
"284.60400","23.71719","0.56709"
"285.04800","23.75420","0.57236"
"285.49200","23.79127","0.57625"
"285.93600","23.82816","0.57975"
"286.38000","23.86511","0.58360"
"286.82401","23.90212","0.58623"
"287.26801","23.93919","0.58805"
"287.71201","23.97620","0.59082"
"288.15601","24.01321","0.59281"
"288.60001","24.05016","0.59471"
"289.04401","24.08717","0.59640"
"289.48801","24.12424","0.59831"
"289.93201","24.16125","0.60031"
"290.37601","24.19820","0.60257"
"290.82001","24.23515","0.60596"
"291.26401","24.27210","0.60999"
"291.70801","24.30917","0.61379"
"292.15201","24.34624","0.60201"
"292.59601","24.38319","0.60393"
"293.04001","24.42020","0.60608"
"293.48401","24.45721","0.60869"
"293.92801","24.49416","0.61332"
"294.37201","24.53117","0.61817"
"294.81601","24.56812","0.62143"
"295.26001","24.60519","0.62479"
"295.70401","24.64214","0.63121"
"296.14801","24.67914","0.63759"
"296.59201","24.71616","0.64133"
"297.03601","24.75317","0.64602"
"297.48001","24.79024","0.64974"
"297.92401","24.82724","0.65417"
"298.36801","24.86419","0.65767"
"298.81201","24.90120","0.66154"
"299.25601","24.93815","0.66611"
"299.70001","24.97522","0.66973"
"300.14401","25.01223","0.67549"
"300.58801","25.04918","0.67755"
"301.03201","25.08613","0.68282"
"301.47601","25.12308","0.68752"
"301.92001","25.16021","0.69129"
"302.36401","25.19716","0.69485"
"302.80801","25.23423","0.69810"
"303.25201","25.27124","0.70024"
"303.69601","25.30813","0.70217"
"304.14001","25.34514","0.70404"
"304.58401","25.38221","0.70651"
"305.02802","25.41922","0.70835"
"305.47198","25.45623","0.71100"
"305.91599","25.49324","0.71409"
"306.35999","25.53013","0.71738"
"306.80399","25.56714","0.72119"
"307.24799","25.60421","0.72450"
"307.69199","25.64122","0.72966"
"308.13599","25.67823","0.73496"
"308.57999","25.71524","0.73959"
"309.02399","25.75213","0.74383"
"309.46799","25.78914","0.73817"
"309.91199","25.82621","0.74191"
"310.35599","25.86316","0.74396"
"310.79999","25.90023","0.74815"
"311.24399","25.93718","0.54117"
"311.68799","25.97413","0.53482"
"312.13199","26.01114","0.53644"
"312.57599","26.04821","0.53943"
"313.01999","26.08516","0.55011"
"313.46399","26.12223","0.55912"
"313.90799","26.15917","0.56347"
"314.35199","26.19613","0.56880"
"314.79599","26.23320","0.56922"
"315.23999","26.27021","0.57442"
"315.68399","26.30722","0.58267"
"316.12799","26.34411","0.58510"
"316.57199","26.38112","0.58733"
"317.01599","26.41818","0.59011"
"317.45999","26.45520","0.59181"
"317.90399","26.49226","0.59333"
"318.34799","26.52921","0.59339"
"318.79199","26.56616","0.59268"
"319.23599","26.60312","0.59411"
"319.67999","26.64013","0.59601"
"320.12399","26.67719","0.59827"
"320.56799","26.71420","0.59969"
"321.01199","26.75121","0.60073"
"321.45599","26.78816","0.60252"
"321.89999","26.82517","0.60492"
"322.34399","26.86218","0.60723"
"322.78799","26.89919","0.61086"
"323.23199","26.93620","0.61667"
"323.67599","26.97321","0.62083"
"324.12000","27.01010","0.62568"
"324.56400","27.04717","0.55978"
"325.00800","27.08418","0.55794"
"325.45200","27.12119","0.56292"
"325.89600","27.15820","0.56896"
"326.34000","27.19515","0.57231"
"326.78400","27.23210","0.57983"
"327.22800","27.26917","0.58328"
"327.67200","27.30618","0.58498"
"328.11600","27.34319","0.58907"
"328.56000","27.38020","0.59202"
"329.00400","27.41715","0.59406"
"329.44800","27.45410","0.59649"
"329.89200","27.49117","0.59935"
"330.33600","27.52818","0.60134"
"330.78000","27.56519","0.60381"
"331.22400","27.60220","0.60830"
"331.66800","27.63921","0.61225"
"332.11200","27.67610","0.61617"
"332.55600","27.71317","0.62208"
"333.00000","27.75018","0.62918"
"333.44400","27.78718","0.63285"
"333.88800","27.82420","0.63717"
"334.33200","27.86108","0.64026"
"334.77600","27.89816","0.64235"
"335.22000","27.93517","0.64450"
"335.66400","27.97224","0.64604"
"336.10800","28.00924","0.64788"
"336.55200","28.04619","0.64937"
"336.99600","28.08315","0.65078"
"337.44000","28.12015","0.65195"
"337.88400","28.15716","0.65504"
"338.32800","28.19417","0.65862"
"338.77200","28.23118","0.66226"
"339.21600","28.26814","0.66554"
"339.66000","28.30508","0.67013"
"340.10400","28.34215","0.67409"
"340.54800","28.37922","0.67803"
"340.99200","28.41623","0.68306"
"341.43600","28.45318","0.68721"
"341.88000","28.49013","0.69199"
"342.32401","28.52714","0.69573"
"342.76801","28.56415","0.69854"
"343.21201","28.60122","0.70061"
"343.65601","28.63817","0.70230"
"344.10001","28.67518","0.70419"
"344.54401","28.71207","0.70638"
"344.98801","28.74920","0.70862"
"345.43201","28.78615","0.71141"
"345.87601","28.82316","0.71490"
"346.32001","28.86029","0.71904"
"346.76401","28.89718","0.72359"
"347.20801","28.93413","0.72815"
"347.65201","28.97114","0.73255"
"348.09601","29.00821","0.73761"
"348.54001","29.04516","0.74253"
"348.98401","29.08217","0.74777"
"349.42801","29.11918","0.75219"
"349.87201","29.15613","0.75800"
"350.31601","29.19326","0.76336"
"350.76001","29.23021","0.76900"
"351.20401","29.26722","0.77541"
"351.64801","29.30417","0.78220"
"352.09201","29.34118","0.78786"
"352.53601","29.37813","0.79286"
"352.98001","29.41519","0.79780"
"353.42401","29.45221","0.80157"
"353.86801","29.48916","0.80447"
"354.31201","29.52617","0.80637"
"354.75601","29.56311","0.80881"
"355.20001","29.60018","0.81006"
"355.64401","29.63725","0.81196"
"356.08801","29.67420","0.81420"
"356.53201","29.71121","0.81744"
"356.97601","29.74816","0.82142"
"357.42001","29.78511","0.82393"
"357.86401","29.82212","0.82696"
"358.30801","29.85919","0.83093"
"358.75201","29.89620","0.83553"
"359.19601","29.93315","0.83910"
"359.64001","29.97016","0.84395"
"360.08401","30.00717","0.84837"
"360.52802","30.04418","0.85184"
"360.97198","30.08125","0.85567"
"361.41599","30.11820","0.86023"
"361.85999","30.15515","0.86580"
"362.30399","30.19216","0.87050"
"362.74799","30.22917","0.87768"
"363.19199","30.26618","0.88314"
"363.63599","30.30319","0.88783"
"364.07999","30.34020","0.89216"
"364.52399","30.37721","0.89630"
"364.96799","30.41410","0.89989"
"365.41199","30.45117","0.90400"
"365.85599","30.48818","0.90754"
"366.29999","30.52519","0.91084"
"366.74399","30.56220","0.91438"
"367.18799","30.59909","0.91946"
"367.63199","30.63616","0.92497"
"368.07599","30.67317","0.93051"
"368.51999","30.71024","0.93595"
"368.96399","30.74719","0.94324"
"369.40799","30.78420","0.94937"
"369.85199","30.82115","0.95522"
"370.29599","30.85816","0.96118"
"370.73999","30.89516","0.96524"
"371.18399","30.93217","0.97189"
"371.62799","30.96918","0.97702"
"372.07199","31.00614","0.98156"
"372.51599","31.04314","0.98756"
"372.95999","31.08015","0.99279"
"373.40399","31.11716","0.99643"
"373.84799","31.15417","0.99968"
"374.29199","31.19124","1.00221"
"374.73599","31.22819","1.00419"
"375.17999","31.26514","1.00596"
"375.62399","31.30215","1.00779"
"376.06799","31.33922","1.01059"
"376.51199","31.37617","1.01451"
"376.95599","31.41318","1.01716"
"377.39999","31.45013","1.02079"
"377.84399","31.48714","1.02579"
"378.28799","31.52421","1.03064"
"378.73199","31.56122","1.03733"
"379.17599","31.59823","1.04340"
"379.62000","31.63518","1.04890"
"380.06400","31.67213","1.05407"
"380.50800","31.70920","1.05884"
"380.95200","31.74615","1.06527"
"381.39600","31.78322","1.07080"
"381.84000","31.82017","1.07766"
"382.28400","31.85724","1.08379"
"382.72800","31.89413","0.93748"
"383.17200","31.93114","0.90941"
"383.61600","31.96821","0.90477"
"384.06000","32.00528","0.90116"
"384.50400","32.04223","0.87749"
"384.94800","32.07917","0.85777"
"385.39200","32.11613","0.85484"
"385.83600","32.15314","0.84981"
"386.28000","32.19014","0.85332"
"386.72400","32.22715","0.85690"
"387.16800","32.26423","0.86117"
"387.61200","32.30118","0.86848"
"388.05600","32.33818","0.87263"
"388.50000","32.37519","0.88172"
"388.94400","32.41220","0.88805"
"389.38800","32.44921","0.89256"
"389.83200","32.48616","0.89535"
"390.27600","32.52311","0.89506"
"390.72000","32.56012","0.88627"
"391.16400","32.59719","0.87878"
"391.60800","32.63414","0.87563"
"392.05200","32.67121","0.88009"
"392.49600","32.70816","0.88472"
"392.94000","32.74511","0.88997"
"393.38400","32.78218","0.89384"
"393.82800","32.81919","0.89866"
"394.27200","32.85620","0.90344"
"394.71600","32.89321","0.90709"
"395.16000","32.93016","0.91160"
"395.60400","32.96717","0.91604"
"396.04800","33.00418","0.92186"
"396.49200","33.04119","0.92860"
"396.93600","33.07820","0.93642"
"397.38000","33.11521","0.94408"
"397.82401","33.15216","0.95070"
"398.26801","33.18911","0.95647"
"398.71201","33.22618","0.96298"
"399.15601","33.26319","0.96859"
"399.60001","33.30020","0.97429"
"400.04401","33.33715","0.97854"
"400.48801","33.37410","0.98428"
"400.93201","33.41117","0.98991"
"401.37601","33.44824","0.99389"
"401.82001","33.48525","0.99743"
"402.26401","33.52214","1.00038"
"402.70801","33.55915","1.00232"
"403.15201","33.59616","1.00396"
"403.59601","33.63316","1.00529"
"404.04001","33.67023","1.00700"
"404.48401","33.70713","1.00877"
"404.92801","33.74420","1.01125"
"405.37201","33.78109","1.01439"
"405.81601","33.81816","1.01703"
"406.26001","33.85517","1.01362"
"406.70401","33.89217","1.01353"
"407.14801","33.92924","1.01548"
"407.59201","33.96619","1.01414"
"408.03601","34.00314","1.01251"
"408.48001","34.04015","0.97788"
"408.92401","34.07716","0.94364"
"409.36801","34.11417","0.93712"
"409.81201","34.15124","0.93972"
"410.25601","34.18819","0.94308"
"410.70001","34.22514","0.94854"
"411.14401","34.26215","0.95352"
"411.58801","34.29922","0.95663"
"412.03201","34.33623","0.96239"
"412.47601","34.37318","0.96796"
"412.92001","34.41013","0.97367"
"413.36401","34.44714","0.97900"
"413.80801","34.48415","0.98474"
"414.25201","34.52122","0.99045"
"414.69601","34.55817","0.99489"
"415.14001","34.59518","0.99874"
"415.58401","34.63213","1.00111"
"416.02802","34.66920","1.00322"
"416.47198","34.70621","1.00447"
"416.91599","34.74316","1.00521"
"417.35999","34.78023","1.00610"
"417.80399","34.81718","1.00775"
"418.24799","34.85413","1.00958"
"418.69199","34.89114","1.01232"
"419.13599","34.92821","1.01508"
"419.57999","34.96516","1.01780"
"420.02399","35.00217","1.01875"
"420.46799","35.03918","1.01411"
"420.91199","35.07619","0.99674"
"421.35599","35.11320","0.99657"
"421.79999","35.15021","0.99731"
"422.24399","35.18721","0.99855"
"422.68799","35.22417","0.99984"
"423.13199","35.26118","1.00170"
"423.57599","35.29819","1.00358"
"424.01999","35.33514","1.00542"
"424.46399","35.37215","1.00720"
"424.90799","35.40921","1.00950"
"425.35199","35.44622","1.01288"
"425.79599","35.48317","1.01626"
"426.23999","35.52018","1.01987"
"426.68399","35.55719","1.02517"
"427.12799","35.59420","1.03136"
"427.57199","35.63121","1.03999"
"428.01599","35.66811","1.04747"
"428.45999","35.70511","1.05320"
"428.90399","35.74212","1.05765"
"429.34799","35.77919","1.06225"
"429.79199","35.81620","0.66762"
"430.23599","35.85321","0.67709"
"430.67999","35.89010","0.68498"
"431.12399","35.92711","0.69504"
"431.56799","35.96418","0.70314"
"432.01199","36.00119","0.70589"
"432.45599","36.03820","0.71024"
"432.89999","36.07515","0.71739"
"433.34399","36.11216","0.72624"
"433.78799","36.14911","0.73527"
"434.23199","36.18618","0.74186"
"434.67599","36.22319","0.74782"
"435.12000","36.26020","0.75777"
"435.56400","36.29721","0.79165"
"436.00800","36.33416","0.79980"
"436.45200","36.37117","0.79144"
"436.89600","36.40818","0.79856"
"437.34000","36.44519","0.80423"
"437.78400","36.48220","0.80844"
"438.22800","36.51915","0.81145"
"438.67200","36.55616","0.81616"
"439.11600","36.59317","0.82186"
"439.56000","36.63018","0.82749"
"440.00400","36.66725","0.83426"
"440.44800","36.70420","0.71696"
"440.89200","36.74115","0.71444"
"441.33600","36.77810","0.72021"
"441.78000","36.81517","0.72972"
"442.22400","36.85224","0.73917"
"442.66800","36.88918","0.74543"
"443.11200","36.92619","0.75322"
"443.55600","36.96309","0.76465"
"444.00000","37.00015","0.76423"
"444.44400","37.03722","0.77235"
"444.88800","37.07423","0.78302"
"445.33200","37.11124","0.79317"
"445.77600","37.14813","0.79952"
"446.22000","37.18514","0.80466"
"446.66400","37.22221","0.80828"
"447.10800","37.25916","0.81156"
"447.55200","37.29617","0.81731"
"447.99600","37.33318","0.82218"
"448.44000","37.37013","0.82588"
"448.88400","37.40714","0.83526"
"449.32800","37.44421","0.84388"
"449.77200","37.48116","0.84494"
"450.21600","37.51817","0.85061"
"450.66000","37.55518","0.85732"
"451.10400","37.59213","0.86405"
"451.54800","37.62914","0.87088"
"451.99200","37.66615","0.87938"
"452.43600","37.70316","0.88711"
"452.88000","37.74023","0.89219"
"453.32401","37.77718","0.89782"
"453.76801","37.81413","0.90126"
"454.21201","37.85114","0.90457"
"454.65601","37.88821","0.90655"
"455.10001","37.92522","0.90745"
"455.54401","37.96223","0.91111"
"455.98801","37.99912","0.91591"
"456.43201","38.03613","0.92108"
"456.87601","38.07314","0.92752"
"457.32001","38.11021","0.93926"
"457.76401","38.14722","0.93353"
"458.20801","38.18423","0.94785"
"458.65201","38.22118","0.95673"
"459.09601","38.25813","0.95776"
"459.54001","38.29519","0.96470"
"459.98401","38.33221","0.97831"
"460.42801","38.36916","0.97337"
"460.87201","38.40617","0.97623"
"461.31601","38.44312","0.98066"
"461.76001","38.48019","0.98851"
"462.20401","38.51714","0.99175"
"462.64801","38.55414","0.99587"
"463.09201","38.59121","1.00029"
"463.53601","38.62822","1.00476"
"463.98001","38.66518","1.00827"
"464.42401","38.70218","1.00645"
"464.86801","38.73919","1.00905"
"465.31201","38.77620","1.01331"
"465.75601","38.81321","1.01743"
"466.20001","38.85010","1.02180"
"466.64401","38.88717","1.02830"
"467.08801","38.92418","1.03613"
"467.53201","38.96119","1.04305"
"467.97601","38.99820","1.05538"
"468.42001","39.03521","1.09555"
"468.86401","39.07215","1.05680"
"469.30801","39.10911","1.06852"
"469.75201","39.14618","1.06523"
"470.19601","39.18325","1.07121"
"470.64001","39.22020","1.07712"
"471.08401","39.25721","1.00633"
"471.52802","39.29410","1.00323"
"471.97198","39.33117","1.00529"
"472.41599","39.36824","1.00781"
"472.85999","39.40519","0.75987"
"473.30399","39.44220","0.76663"
"473.74799","39.47921","0.76999"
"474.19199","39.51616","0.77726"
"474.63599","39.55317","0.78397"
"475.07999","39.59017","0.79129"
"475.52399","39.62713","0.79978"
"475.96799","39.66414","0.80323"
"476.41199","39.70115","0.80815"
"476.85599","39.73810","0.81670"
"477.29999","39.77523","0.81953"
"477.74399","39.81224","0.82681"
"478.18799","39.84925","0.82612"
"478.63199","39.88613","0.83074"
"479.07599","39.92308","0.83879"
"479.51999","39.96015","0.84149"
"479.96399","39.99716","0.84463"
"480.40799","40.03423","0.85178"
"480.85199","40.07118","0.86136"
"481.29599","40.10813","0.86471"
"481.73999","40.14515","0.86999"
"482.18399","40.18216","0.87729"
"482.62799","40.21917","0.72206"
"483.07199","40.25617","0.63340"
"483.51599","40.29318","0.64110"
"483.95999","40.33014","0.63336"
"484.40399","40.36714","0.63433"
"484.84799","40.40415","0.64192"
"485.29199","40.44116","0.64089"
"485.73599","40.47817","0.64468"
"486.17999","40.51518","0.65626"
"486.62399","40.55213","0.65638"
"487.06799","40.58914","0.65777"
"487.51199","40.62621","0.66532"
"487.95599","40.66322","0.67057"
"488.39999","40.70017","0.67257"
"488.84399","40.73718","0.67908"
"489.28799","40.77412","0.68814"
"489.73199","40.81114","0.68806"
"490.17599","40.84821","0.69066"
"490.62000","40.88516","0.69803"
"491.06400","40.92223","0.69852"
"491.50800","40.95918","0.69959"
"491.95200","40.99613","0.70141"
"492.39600","41.03320","0.70495"
"492.84000","41.07021","0.70758"
"493.28400","41.10716","0.70912"
"493.72800","41.14416","0.71138"
"494.17200","41.18111","0.71816"
"494.61600","41.21812","0.72123"
"495.06000","41.25513","0.72416"
"495.50400","41.29220","0.72589"
"495.94800","41.32921","0.73165"
"496.39200","41.36622","0.74408"
"496.83600","41.40318","0.76376"
"497.28000","41.44019","0.75644"
"497.72400","41.47720","0.75859"
"498.16800","41.51421","0.75483"
"498.61200","41.55115","0.76210"
"499.05600","41.58817","0.77099"
"499.50000","41.62511","0.76550"
"499.94400","41.66218","0.76435"
"500.38800","41.69913","0.77494"
"500.83200","41.73620","0.78012"
"501.27600","41.77321","0.77450"
"501.72000","41.81010","0.78306"
"502.16400","41.84717","0.78797"
"502.60800","41.88412","0.80052"
"503.05200","41.92119","0.80050"
"503.49600","41.95820","0.80927"
"503.94000","41.99521","0.81146"
"504.38400","42.03210","0.80397"
"504.82800","42.06911","0.80602"
"505.27200","42.10618","0.80915"
"505.71600","42.14325","0.81119"
"506.16000","42.18020","0.81207"
"506.60400","42.21721","0.81381"
"507.04800","42.25410","0.81416"
"507.49200","42.29117","0.81846"
"507.93600","42.32818","0.81914"
"508.38000","42.36519","0.82218"
"508.82401","42.40220","0.82578"
"509.26801","42.43914","0.82868"
"509.71201","42.47615","0.83132"
"510.15601","42.51316","0.83469"
"510.60001","42.55017","0.83782"
"511.04401","42.58719","0.84043"
"511.48801","42.62420","0.84774"
"511.93201","42.66115","0.85020"
"512.37598","42.69809","0.85919"
"512.82001","42.73517","0.83010"
"513.26398","42.77218","0.83579"
"513.70801","42.80919","0.84183"
"514.15198","42.84620","0.85532"
"514.59601","42.88314","0.85493"
"515.03998","42.92015","0.85140"
"515.48401","42.95723","0.85472"
"515.92798","42.99417","0.86310"
"516.37201","43.03119","0.85959"
"516.81598","43.06820","0.86327"
"517.26001","43.10514","0.86635"
"517.70398","43.14209","0.87004"
"518.14801","43.17916","0.87510"
"518.59198","43.21624","0.88042"
"519.03601","43.25318","0.88679"
"519.47998","43.29019","0.88581"
"519.92401","43.32714","0.89560"
"520.36798","43.36421","0.89311"
"520.81201","43.40116","0.89596"
"521.25598","43.43818","0.89886"
"521.70001","43.47519","0.90165"
"522.14398","43.51207","0.90275"
"522.58801","43.54914","0.90548"
"523.03198","43.58615","0.90822"
"523.47601","43.62322","0.90904"
"523.91998","43.66017","0.91854"
"524.36401","43.69718","0.91480"
"524.80798","43.73419","0.91719"
"525.25201","43.77114","0.92073"
"525.69598","43.80821","0.92511"
"526.14001","43.84516","0.92998"
"526.58398","43.88217","0.93428"
"527.02802","43.91912","0.93772"
"527.47198","43.95619","0.94339"
"527.91602","43.99320","0.94885"
"528.35999","44.03021","0.95262"
"528.80402","44.06722","0.95575"
"529.24799","44.10423","0.95928"
"529.69202","44.14117","0.96219"
"530.13599","44.17813","0.96668"
"530.58002","44.21519","0.96728"
"531.02399","44.25220","0.98085"
"531.46802","44.28922","0.97603"
"531.91199","44.32617","0.97172"
"532.35602","44.36312","0.97279"
"532.79999","44.40013","0.97088"
"533.24402","44.43719","0.97433"
"533.68799","44.47415","0.97408"
"534.13202","44.51122","0.98320"
"534.57599","44.54816","0.98171"
"535.02002","44.58512","0.98444"
"535.46399","44.62218","0.98766"
"535.90802","44.65919","0.98911"
"536.35199","44.69614","0.99210"
"536.79602","44.73322","0.99170"
"537.23999","44.77016","0.94149"
"537.68402","44.80711","0.93484"
"538.12799","44.84412","0.93145"
"538.57202","44.88126","0.93067"
"539.01599","44.91820","0.93259"
"539.46002","44.95515","0.93626"
"539.90399","44.99216","0.93835"
"540.34802","45.02917","0.94321"
"540.79199","45.06618","0.94658"
"541.23602","45.10319","0.94966"
"541.67999","45.14014","0.95338"
"542.12402","45.17721","0.95368"
"542.56799","45.21410","0.95567"
"543.01202","45.25117","0.95931"
"543.45599","45.28818","0.96090"
"543.90002","45.32525","0.96395"
"544.34399","45.36226","0.96653"
"544.78802","45.39915","0.96930"
"545.23199","45.43610","0.97244"
"545.67603","45.47317","0.97497"
"546.12000","45.51018","0.97660"
"546.56403","45.54719","0.97856"
"547.00800","45.58420","0.98044"
"547.45203","45.62115","0.98188"
"547.89600","45.65816","0.99079"
"548.34003","45.69516","0.99628"
"548.78400","45.73218","1.00732"
"549.22803","45.76925","1.00127"
"549.67200","45.80620","0.98829"
"550.11603","45.84315","0.99198"
"550.56000","45.88021","0.99562"
"551.00403","45.91722","0.99799"
"551.44800","45.95417","1.00082"
"551.89203","45.99118","1.00187"
"552.33600","46.02814","1.00233"
"552.78003","46.06521","1.00384"
"553.22400","46.10215","1.00476"
"553.66803","46.13923","1.00608"
"554.11200","46.17617","1.00732"
"554.55603","46.21318","1.00974"
"555.00000","46.25019","1.01197"
"555.44397","46.28709","1.01263"
"555.88800","46.32416","1.01570"
"556.33197","46.36116","1.01779"
"556.77600","46.39817","1.01953"
"557.21997","46.43518","1.02761"
"557.66400","46.47219","1.02626"
"558.10797","46.50914","1.03123"
"558.55200","46.54622","1.03352"
"558.99597","46.58323","1.03730"
"559.44000","46.62011","1.03830"
"559.88397","46.65718","1.04313"
"560.32800","46.69413","1.04695"
"560.77197","46.73114","1.04844"
"561.21600","46.76815","1.05055"
"561.65997","46.80516","1.05258"
"562.10400","46.84217","1.05518"
"562.54797","46.87918","1.05799"
"562.99200","46.91619","1.06000"
"563.43597","46.95320","1.06307"
"563.88000","46.99021","1.06609"
"564.32397","47.02721","1.06887"
"564.76801","47.06417","1.07157"
"565.21198","47.10112","1.07470"
"565.65601","47.13813","1.07800"
"566.09998","47.17514","1.08048"
"566.54401","47.21220","1.08315"
"566.98798","47.24922","1.08532"
"567.43201","47.28617","1.08715"
"567.87598","47.32318","1.08867"
"568.32001","47.36019","1.09057"
"568.76398","47.39720","1.09108"
"569.20801","47.43414","1.09271"
"569.65198","47.47122","1.08597"
"570.09601","47.50816","0.69695"
"570.53998","47.54512","0.70248"
"570.98401","47.58213","0.70669"
"571.42798","47.61919","0.71092"
"571.87201","47.65614","0.71327"
"572.31598","47.69321","0.71880"
"572.76001","47.73022","0.72531"
"573.20398","47.76711","0.72891"
"573.64801","47.80418","0.73121"
"574.09198","47.84119","0.73241"
"574.53601","47.87814","0.73712"
"574.97998","47.91515","0.74126"
"575.42401","47.95216","0.38047"
"575.86798","47.98917","0.40192"
"576.31201","48.02618","0.38919"
"576.75598","48.06319","0.38955"
"577.20001","48.10020","0.40972"
"577.64398","48.13715","0.40020"
"578.08801","48.17416","0.40869"
"578.53198","48.21117","0.41440"
"578.97601","48.24818","0.41267"
"579.41998","48.28519","0.43126"
"579.86401","48.32214","0.42512"
"580.30798","48.35921","0.43056"
"580.75201","48.39616","0.43321"
"581.19598","48.43317","0.43564"
"581.64001","48.47024","0.44672"
"582.08398","48.50719","0.44024"
"582.52802","48.54420","0.45270"
"582.97198","48.58115","0.45039"
"583.41602","48.61816","0.45544"
"583.85999","48.65517","0.46078"
"584.30402","48.69217","0.46488"
"584.74799","48.72918","0.47650"
"585.19202","48.76620","0.47495"
"585.63599","48.80315","0.48725"
"586.08002","48.84021","0.48631"
"586.52399","48.87722","0.49499"
"586.96802","48.91418","0.49284"
"587.41199","48.95124","0.49846"
"587.85602","48.98813","0.49804"
"588.29999","49.02515","0.50324"
"588.74402","49.06215","0.50266"
"589.18799","49.09916","0.50784"
"589.63202","49.13617","0.50784"
"590.07599","49.17318","0.51464"
"590.52002","49.21019","0.51539"
"590.96399","49.24715","0.52489"
"591.40802","49.28421","0.52271"
"591.85199","49.32116","0.52979"
"592.29602","49.35823","0.53098"
"592.73999","49.39524","0.53781"
"593.18402","49.43214","0.53934"
"593.62799","49.46914","0.54415"
"594.07202","49.50615","0.54807"
"594.51599","49.54322","0.55113"
"594.96002","49.58023","0.55592"
"595.40399","49.61718","0.55785"
"595.84802","49.65413","0.56289"
"596.29199","49.69114","0.56386"
"596.73602","49.72815","0.56874"
"597.17999","49.76522","0.57061"
"597.62402","49.80217","0.57478"
"598.06799","49.83918","0.57736"
"598.51202","49.87607","0.57598"
"598.95599","49.91314","0.57944"
"599.40002","49.95021","0.58090"
"599.84399","49.98722","0.58291"
"600.28802","50.02417","0.58458"
"600.73199","50.06118","0.58583"
"601.17603","50.09813","0.58719"
"601.62000","50.13520","0.58811"
"602.06403","50.17226","0.59063"
"602.50800","50.20916","0.59142"
"602.95203","50.24616","0.59276"
"603.39600","50.28312","0.59403"
"603.84003","50.32013","0.59515"
"604.28400","50.35719","0.59630"
"604.72803","50.39420","0.59754"
"605.17200","50.43121","0.59815"
"605.61603","50.46822","0.59816"
"606.06000","50.50518","0.59975"
"606.50403","50.54219","0.60029"
"606.94800","50.57914","0.60151"
"607.39203","50.61620","0.60264"
"607.83600","50.65322","0.60422"
"608.28003","50.69017","0.60569"
"608.72400","50.72712","0.60780"
"609.16803","50.76418","0.60956"
"609.61200","50.80125","0.61242"
"610.05603","50.83820","0.61395"
"610.50000","50.87521","0.61562"
"610.94397","50.91216","0.61862"
"611.38800","50.94912","0.62065"
"611.83197","50.98619","0.62323"
"612.27600","51.02319","0.62557"
"612.71997","51.06020","0.62739"
"613.16400","51.09715","0.62851"
"613.60797","51.13416","0.62998"
"614.05200","51.17117","0.63293"
"614.49597","51.20824","0.63423"
"614.94000","51.24525","0.63542"
"615.38397","51.28220","0.63792"
"615.82800","51.31915","0.63858"
"616.27197","51.35610","0.64045"
"616.71600","51.39317","0.64199"
"617.15997","51.43018","0.64350"
"617.60400","51.46719","0.64506"
"618.04797","51.50420","0.64730"
"618.49200","51.54115","0.64842"
"618.93597","51.57816","0.65009"
"619.38000","51.61517","0.65184"
"619.82397","51.65218","0.65192"
"620.26801","51.68919","0.65398"
"620.71198","51.72620","0.65567"
"621.15601","51.76315","0.65668"
"621.59998","51.80009","0.65891"
"622.04401","51.83717","0.66009"
"622.48798","51.87418","0.66134"
"622.93201","51.91118","0.66239"
"623.37598","51.94820","0.65709"
"623.82001","51.98515","0.65786"
"624.26398","52.02209","0.65573"
"624.70801","52.05922","0.65667"
"625.15198","52.09617","0.65778"
"625.59601","52.13324","0.65878"
"626.03998","52.17014","0.65967"
"626.48401","52.20708","0.65698"
"626.92798","52.24416","0.65772"
"627.37201","52.28123","0.66005"
"627.81598","52.31817","0.66276"
"628.26001","52.35519","0.66390"
"628.70398","52.39213","0.66502"
"629.14801","52.42914","0.66767"
"629.59198","52.46615","0.66949"
"630.03601","52.50322","0.67103"
"630.47998","52.54017","0.67498"
"630.92401","52.57712","0.67697"
"631.36798","52.61413","0.68042"
"631.81201","52.65115","0.68407"
"632.25598","52.68821","0.68606"
"632.70001","52.72522","0.68743"
"633.14398","52.76223","0.68958"
"633.58801","52.79924","0.69192"
"634.03198","52.83613","0.69352"
"634.47601","52.87314","0.69517"
"634.91998","52.91015","0.69607"
"635.36401","52.94716","0.69674"
"635.80798","52.98423","0.69769"
"636.25201","53.02118","0.69794"
"636.69598","53.05813","0.69852"
"637.14001","53.09520","0.69907"
"637.58398","53.13221","0.69869"
"638.02802","53.16922","0.38304"
"638.47198","53.20617","0.38848"
"638.91602","53.24311","0.38548"
"639.35999","53.28012","0.38945"
"639.80402","53.31720","0.38910"
"640.24799","53.35426","0.39092"
"640.69202","53.39122","0.39045"
"641.13599","53.42823","0.40385"
"641.58002","53.46505","0.40287"
"642.02399","53.50219","0.40682"
"642.46802","53.53920","0.41351"
"642.91199","53.57627","0.41337"
"643.35602","53.61322","0.42078"
"643.79999","53.65016","0.42155"
"644.24402","53.68718","0.42358"
"644.68799","53.72412","0.43115"
"645.13202","53.76119","0.43002"
"645.57599","53.79815","0.43432"
"646.02002","53.83521","0.43634"
"646.46399","53.87217","0.43784"
"646.90802","53.90918","0.44304"
"647.35199","53.94619","0.44334"
"647.79602","53.98313","0.44751"
"648.23999","54.02014","0.45071"
"648.68402","54.05715","0.45406"
"649.12799","54.09416","0.45747"
"649.57202","54.13117","0.45870"
"650.01599","54.16813","0.46416"
"650.46002","54.20519","0.46745"
"650.90399","54.24220","0.47332"
"651.34802","54.27921","0.47752"
"651.79199","54.31610","0.48285"
"652.23602","54.35317","0.48617"
"652.67999","54.39024","0.49015"
"653.12402","54.42719","0.49321"
"653.56799","54.46420","0.49521"
"654.01202","54.50114","0.49761"
"654.45599","54.53810","0.49900"
"654.90002","54.57517","0.50212"
"655.34399","54.61218","0.50418"
"655.78802","54.64919","0.50771"
"656.23199","54.68620","0.50885"
"656.67603","54.72315","0.51250"
"657.12000","54.76016","0.51435"
"657.56403","54.79723","0.51733"
"658.00800","54.83418","0.51794"
"658.45203","54.87119","0.52051"
"658.89600","54.90820","0.52391"
"659.34003","54.94514","0.52786"
"659.78400","54.98215","0.52929"
"660.22803","55.01917","0.52946"
"660.67200","55.05618","0.44679"
"661.11603","55.09319","0.40940"
"661.56000","55.13020","0.41178"
"662.00403","55.16714","0.41429"
"662.44800","55.20415","0.41466"
"662.89203","55.24117","0.41963"
"663.33600","55.27818","0.42268"
"663.78003","55.31518","0.42541"
"664.22400","55.35213","0.43044"
"664.66803","55.38914","0.43244"
"665.11200","55.42616","0.43493"
"665.31000","55.44271","0.43614"