File: Force_trajectories/170107_2/Specimen_RawData_6.csv
End date,"1/7/2017"
Specimen label,"3AG_19"
Maximum Load,"0.51913",N

Time,Extension,Load
(s),(mm),(N)
"0.00000","0.00000","-0.00025"
"0.19800","0.01381","0.00023"
"0.39600","0.03318","0.00082"
"0.59400","0.04969","0.00135"
"0.79200","0.06625","0.00224"
"0.99000","0.08275","0.00258"
"1.18800","0.09919","0.00288"
"1.38600","0.11569","0.00348"
"1.58400","0.13219","0.00395"
"1.78200","0.14876","0.00419"
"1.98000","0.16520","0.00482"
"2.17800","0.18170","0.00472"
"2.37600","0.19820","0.00521"
"2.57400","0.21470","0.00566"
"2.77200","0.23115","0.00562"
"2.97000","0.24771","0.00592"
"3.16800","0.26421","0.00595"
"3.36600","0.28065","0.00627"
"3.56400","0.29721","0.00675"
"3.76200","0.31366","0.00735"
"3.96000","0.33016","0.00745"
"4.15800","0.34672","0.00721"
"4.35600","0.36310","0.00743"
"4.55400","0.37972","0.00777"
"4.75200","0.39623","0.00766"
"4.95000","0.41261","0.00903"
"5.14800","0.42923","0.00883"
"5.34600","0.44567","0.00878"
"5.54400","0.46217","0.00962"
"5.74200","0.47873","0.00945"
"5.94000","0.49512","0.00969"
"6.13800","0.51168","0.01012"
"6.33600","0.52818","0.00979"
"6.53400","0.54456","0.01048"
"6.73200","0.56124","0.01075"
"6.93000","0.57769","0.01046"
"7.12800","0.59413","0.01095"
"7.32600","0.61075","0.01109"
"7.52400","0.62713","0.01138"
"7.72200","0.64375","0.01130"
"7.92000","0.66020","0.01155"
"8.11800","0.67658","0.01120"
"8.31600","0.69326","0.01154"
"8.51400","0.70970","0.01125"
"8.71200","0.72614","0.01180"
"8.91000","0.74271","0.01130"
"9.10800","0.75915","0.01172"
"9.30600","0.77565","0.01204"
"9.50400","0.79221","0.01221"
"9.70200","0.80865","0.01238"
"9.90000","0.82522","0.01211"
"10.09800","0.84166","0.01290"
"10.29600","0.85810","0.01307"
"10.49400","0.87472","0.01241"
"10.69200","0.89116","0.01259"
"10.89000","0.90772","0.01351"
"11.08800","0.92423","0.01316"
"11.28600","0.94067","0.01313"
"11.48400","0.95723","0.01319"
"11.68200","0.97373","0.01315"
"11.88000","0.99011","0.01312"
"12.07800","1.00674","0.01344"
"12.27600","1.02312","0.01378"
"12.47400","1.03968","0.01402"
"12.67200","1.05618","0.01380"
"12.87000","1.07262","0.01371"
"13.06800","1.08919","0.01386"
"13.26600","1.10575","0.01423"
"13.46400","1.12213","0.01435"
"13.66200","1.13869","0.01400"
"13.86000","1.15519","0.01413"
"14.05800","1.17170","0.01439"
"14.25600","1.18820","0.01438"
"14.45400","1.20464","0.01453"
"14.65200","1.22114","0.01478"
"14.85000","1.23770","0.01472"
"15.04800","1.25415","0.01451"
"15.24600","1.27071","0.01439"
"15.44400","1.28721","0.01453"
"15.64200","1.30365","0.01511"
"15.84000","1.32021","0.01513"
"16.03800","1.33671","0.01499"
"16.23600","1.35316","0.01475"
"16.43400","1.36966","0.01469"
"16.63200","1.38616","0.01530"
"16.83000","1.40266","0.01549"
"17.02800","1.41922","0.01460"
"17.22600","1.43567","0.01543"
"17.42400","1.45223","0.01496"
"17.62200","1.46867","0.01525"
"17.82000","1.48517","0.01555"
"18.01800","1.50167","0.01527"
"18.21600","1.51824","0.01531"
"18.41400","1.53468","0.01527"
"18.61200","1.55118","0.01566"
"18.81000","1.56768","0.01540"
"19.00800","1.58418","0.01597"
"19.20600","1.60075","0.01573"
"19.40400","1.61713","0.01538"
"19.60200","1.63369","0.01598"
"19.80000","1.65025","0.01609"
"19.99800","1.66663","0.01555"
"20.19600","1.68319","0.01599"
"20.39400","1.69970","0.01592"
"20.59200","1.71620","0.01596"
"20.79000","1.73270","0.01654"
"20.98800","1.74914","0.01691"
"21.18600","1.76570","0.01690"
"21.38400","1.78221","0.01574"
"21.58200","1.79865","0.01560"
"21.78000","1.81521","0.01600"
"21.97800","1.83171","0.01601"
"22.17600","1.84809","0.01607"
"22.37400","1.86472","0.01618"
"22.57200","1.88116","0.01634"
"22.77000","1.89766","0.01644"
"22.96800","1.91422","0.01632"
"23.16600","1.93060","0.01676"
"23.36400","1.94723","0.01655"
"23.56200","1.96373","0.01664"
"23.76000","1.98011","0.01678"
"23.95800","1.99673","0.01728"
"24.15600","2.01317","0.01706"
"24.35400","2.02968","0.01717"
"24.55200","2.04624","0.01684"
"24.75000","2.06268","0.01770"
"24.94800","2.07918","0.01740"
"25.14600","2.09574","0.01706"
"25.34400","2.11207","0.01707"
"25.54200","2.12875","0.01697"
"25.74000","2.14519","0.01750"
"25.93800","2.16163","0.01748"
"26.13600","2.17819","0.01694"
"26.33400","2.19469","0.01714"
"26.53200","2.21120","0.01745"
"26.73000","2.22770","0.01860"
"26.92800","2.24420","0.01728"
"27.12600","2.26076","0.01775"
"27.32400","2.27714","0.01725"
"27.52200","2.29365","0.01810"
"27.72000","2.31021","0.01810"
"27.91800","2.32659","0.01788"
"28.11600","2.34321","0.01766"
"28.31400","2.35971","0.01776"
"28.51200","2.37616","0.01782"
"28.71000","2.39272","0.01788"
"28.90800","2.40922","0.01846"
"29.10600","2.42566","0.01785"
"29.30400","2.44222","0.01865"
"29.50200","2.45867","0.01842"
"29.70000","2.47517","0.01804"
"29.89800","2.49167","0.01808"
"30.09600","2.50817","0.01817"
"30.29400","2.52467","0.01826"
"30.49200","2.54123","0.01779"
"30.69000","2.55768","0.01781"
"30.88800","2.57424","0.01747"
"31.08600","2.59068","0.01745"
"31.28400","2.60718","0.01785"
"31.48200","2.62368","0.01752"
"31.68000","2.64019","0.01779"
"31.87800","2.65669","0.01775"
"32.07600","2.67313","0.01795"
"32.27400","2.68969","0.01779"
"32.47200","2.70619","0.01793"
"32.67000","2.72270","0.01830"
"32.86800","2.73920","0.01749"
"33.06600","2.75570","0.01793"
"33.26400","2.77220","0.01799"
"33.46200","2.78870","0.01778"
"33.66000","2.80515","0.01785"
"33.85800","2.82165","0.01808"
"34.05600","2.83821","0.01798"
"34.25400","2.85471","0.01773"
"34.45200","2.87115","0.01806"
"34.65000","2.88771","0.01793"
"34.84800","2.90422","0.01794"
"35.04600","2.92066","0.01773"
"35.24400","2.93716","0.01790"
"35.44200","2.95372","0.01799"
"35.64000","2.97016","0.01768"
"35.83800","2.98667","0.01816"
"36.03600","3.00317","0.01785"
"36.23400","3.01967","0.01805"
"36.43200","3.03623","0.01820"
"36.63000","3.05267","0.01822"
"36.82800","3.06918","0.01786"
"37.02600","3.08574","0.01812"
"37.22400","3.10218","0.01765"
"37.42200","3.11868","0.01795"
"37.62000","3.13518","0.01788"
"37.81800","3.15169","0.01771"
"38.01600","3.16819","0.01799"
"38.21400","3.18469","0.01796"
"38.41200","3.20119","0.01753"
"38.61000","3.21769","0.01748"
"38.80800","3.23414","0.01756"
"39.00600","3.25076","0.01735"
"39.20400","3.26714","0.01747"
"39.40200","3.28364","0.01731"
"39.60000","3.30026","0.01719"
"39.79800","3.31664","0.01746"
"39.99600","3.33321","0.01741"
"40.19400","3.34971","0.01738"
"40.39200","3.36615","0.01734"
"40.59000","3.38271","0.01714"
"40.78800","3.39921","0.01771"
"40.98600","3.41566","0.01716"
"41.18400","3.43222","0.01768"
"41.38200","3.44866","0.01701"
"41.58000","3.46522","0.01766"
"41.77800","3.48172","0.01751"
"41.97600","3.49817","0.01735"
"42.17400","3.51467","0.01778"
"42.37200","3.53123","0.01771"
"42.57000","3.54761","0.01793"
"42.76800","3.56423","0.01788"
"42.96600","3.58068","0.01775"
"43.16400","3.59718","0.01791"
"43.36200","3.61374","0.01806"
"43.56000","3.63012","0.01789"
"43.75800","3.64668","0.01772"
"43.95600","3.66319","0.01866"
"44.15400","3.67963","0.01827"
"44.35200","3.69625","0.01796"
"44.55000","3.71269","0.01826"
"44.74800","3.72913","0.01816"
"44.94600","3.74569","0.01708"
"45.14400","3.76214","0.01732"
"45.34200","3.77864","0.01669"
"45.54000","3.79520","0.01723"
"45.73800","3.81164","0.01712"
"45.93600","3.82820","0.01736"
"46.13400","3.84471","0.01711"
"46.33200","3.86115","0.01747"
"46.53000","3.87771","0.01723"
"46.72800","3.89415","0.01782"
"46.92600","3.91071","0.01750"
"47.12400","3.92722","0.01698"
"47.32200","3.94366","0.01778"
"47.52000","3.96022","0.01709"
"47.71800","3.97672","0.01765"
"47.91600","3.99316","0.01750"
"48.11400","4.00973","0.01753"
"48.31200","4.02617","0.01766"
"48.51000","4.04267","0.01779"
"48.70800","4.05917","0.01808"
"48.90600","4.07567","0.01750"
"49.10400","4.09218","0.01773"
"49.30200","4.10874","0.01723"
"49.50000","4.12512","0.01596"
"49.69800","4.14168","0.01640"
"49.89600","4.15824","0.01603"
"50.09400","4.17468","0.01549"
"50.29200","4.19119","0.01563"
"50.49000","4.20775","0.01518"
"50.68800","4.22419","0.01596"
"50.88600","4.24069","0.01549"
"51.08400","4.25719","0.01557"
"51.28200","4.27370","0.01547"
"51.48000","4.29020","0.01625"
"51.67800","4.30664","0.01598"
"51.87600","4.32320","0.01630"
"52.07400","4.33970","0.01569"
"52.27200","4.35615","0.01644"
"52.47000","4.37271","0.01565"
"52.66800","4.38921","0.01612"
"52.86600","4.40565","0.01625"
"53.06400","4.42221","0.01659"
"53.26200","4.43866","0.01612"
"53.46000","4.45522","0.01598"
"53.65800","4.47172","0.01655"
"53.85600","4.48816","0.01587"
"54.05400","4.50472","0.01643"
"54.25200","4.52122","0.01626"
"54.45000","4.53767","0.01672"
"54.64800","4.55423","0.01667"
"54.84600","4.57067","0.01673"
"55.04400","4.58717","0.01650"
"55.24200","4.60367","0.01645"
"55.44000","4.62012","0.01682"
"55.63800","4.63674","0.01703"
"55.83600","4.65324","0.01627"
"56.03400","4.66962","0.01613"
"56.23200","4.68624","0.01658"
"56.43000","4.70269","0.01626"
"56.62800","4.71913","0.01637"
"56.82600","4.73575","0.01667"
"57.02400","4.75219","0.01664"
"57.22200","4.76869","0.01623"
"57.42000","4.78520","0.01660"
"57.61800","4.80164","0.01630"
"57.81600","4.81820","0.01680"
"58.01400","4.83470","0.01734"
"58.21200","4.85114","0.01693"
"58.41000","4.86770","0.01707"
"58.60800","4.88415","0.01715"
"58.80600","4.90071","0.01719"
"59.00400","4.91721","0.01756"
"59.20200","4.93365","0.01664"
"59.40000","4.95021","0.01669"
"59.59800","4.96672","0.01770"
"59.79600","4.98310","0.01699"
"59.99400","4.99972","0.01675"
"60.19200","5.01616","0.01711"
"60.39000","5.03266","0.01684"
"60.58800","5.04923","0.01709"
"60.78600","5.06567","0.01684"
"60.98400","5.08223","0.01719"
"61.18200","5.09873","0.01725"
"61.38000","5.11517","0.01747"
"61.57800","5.13174","0.01729"
"61.77600","5.14812","0.01725"
"61.97400","5.16468","0.01736"
"62.17200","5.18118","0.01776"
"62.37000","5.19768","0.01762"
"62.56800","5.21419","0.01710"
"62.76600","5.23075","0.01741"
"62.96400","5.24713","0.01746"
"63.16200","5.26375","0.01770"
"63.36000","5.28019","0.01707"
"63.55800","5.29670","0.01747"
"63.75600","5.31320","0.01752"
"63.95400","5.32964","0.01783"
"64.15200","5.34620","0.01798"
"64.35000","5.36270","0.01735"
"64.54800","5.37915","0.01750"
"64.74600","5.39571","0.01795"
"64.94400","5.41221","0.01791"
"65.14200","5.42865","0.01748"
"65.34000","5.44521","0.01773"
"65.53800","5.46165","0.01793"
"65.73600","5.47816","0.01729"
"65.93400","5.49466","0.01805"
"66.13200","5.51116","0.01790"
"66.33000","5.52766","0.01746"
"66.52800","5.54422","0.01839"
"66.72600","5.56067","0.01839"
"66.92400","5.57723","0.01839"
"67.12200","5.59373","0.01827"
"67.32000","5.61017","0.01894"
"67.51800","5.62667","0.01870"
"67.71600","5.64324","0.01784"
"67.91400","5.65962","0.01836"
"68.11200","5.67618","0.01822"
"68.31000","5.69268","0.01899"
"68.50800","5.70918","0.01838"
"68.70600","5.72569","0.01847"
"68.90400","5.74219","0.01823"
"69.10200","5.75869","0.01883"
"69.30000","5.77525","0.01859"
"69.49800","5.79163","0.01868"
"69.69600","5.80819","0.01884"
"69.89400","5.82470","0.01911"
"70.09200","5.84120","0.01855"
"70.29000","5.85764","0.01935"
"70.48800","5.87414","0.01900"
"70.68600","5.89070","0.01950"
"70.88400","5.90721","0.01890"
"71.08200","5.92365","0.01929"
"71.28000","5.94021","0.01873"
"71.47800","5.95665","0.01860"
"71.67600","5.97315","0.01921"
"71.87400","5.98972","0.01899"
"72.07200","6.00616","0.01917"
"72.27000","6.02272","0.01929"
"72.46800","6.03916","0.01942"
"72.66600","6.05560","0.01972"
"72.86400","6.07223","0.01944"
"73.06200","6.08873","0.01891"
"73.26000","6.10511","0.01939"
"73.45800","6.12173","0.01947"
"73.65600","6.13817","0.01946"
"73.85400","6.15468","0.01946"
"74.05200","6.17118","0.01902"
"74.25000","6.18768","0.01922"
"74.44800","6.20418","0.01959"
"74.64600","6.22068","0.01948"
"74.84400","6.23712","0.01985"
"75.04200","6.25375","0.02012"
"75.24000","6.27019","0.01985"
"75.43800","6.28663","0.01990"
"75.63600","6.30319","0.01966"
"75.83400","6.31963","0.02043"
"76.03200","6.33620","0.02020"
"76.23000","6.35276","0.02042"
"76.42800","6.36914","0.01995"
"76.62600","6.38570","0.02014"
"76.82400","6.40214","0.02035"
"77.02200","6.41859","0.01958"
"77.22000","6.43521","0.01934"
"77.41800","6.45165","0.01993"
"77.61600","6.46815","0.02033"
"77.81400","6.48471","0.02039"
"78.01200","6.50116","0.01996"
"78.21000","6.51766","0.02030"
"78.40800","6.53422","0.02066"
"78.60600","6.55066","0.02013"
"78.80400","6.56722","0.02024"
"79.00200","6.58366","0.02079"
"79.20000","6.60023","0.02043"
"79.39800","6.61667","0.02048"
"79.59600","6.63317","0.01966"
"79.79400","6.64973","0.02057"
"79.99200","6.66623","0.02045"
"80.19000","6.68268","0.02063"
"80.38800","6.69924","0.02048"
"80.58600","6.71568","0.02042"
"80.78400","6.73218","0.02087"
"80.98200","6.74868","0.02067"
"81.18000","6.76513","0.02055"
"81.37800","6.78169","0.02101"
"81.57600","6.79825","0.02113"
"81.77400","6.81469","0.02067"
"81.97200","6.83119","0.02083"
"82.17000","6.84770","0.02134"
"82.36800","6.86414","0.02039"
"82.56600","6.88070","0.02095"
"82.76400","6.89720","0.02091"
"82.96200","6.91370","0.02124"
"83.16000","6.93015","0.02105"
"83.35800","6.94665","0.02137"
"83.55600","6.96315","0.02155"
"83.75400","6.97971","0.02109"
"83.95200","6.99615","0.02089"
"84.15000","7.01271","0.02140"
"84.34800","7.02922","0.02124"
"84.54600","7.04566","0.02102"
"84.74400","7.06216","0.02119"
"84.94200","7.07872","0.02132"
"85.14000","7.09516","0.02120"
"85.33800","7.11167","0.02120"
"85.53600","7.12811","0.02119"
"85.73400","7.14473","0.02134"
"85.93200","7.16123","0.02155"
"86.13000","7.17767","0.02159"
"86.32800","7.19424","0.02214"
"86.52600","7.21074","0.02180"
"86.72400","7.22718","0.02196"
"86.92200","7.24368","0.02203"
"87.12000","7.26018","0.02193"
"87.31800","7.27663","0.02183"
"87.51600","7.29319","0.02140"
"87.71400","7.30963","0.02161"
"87.91200","7.32619","0.02169"
"88.11000","7.34275","0.02156"
"88.30800","7.35914","0.02165"
"88.50600","7.37570","0.02137"
"88.70400","7.39220","0.02201"
"88.90200","7.40864","0.02176"
"89.10000","7.42526","0.02191"
"89.29800","7.44170","0.02192"
"89.49600","7.45821","0.02155"
"89.69400","7.47471","0.02169"
"89.89200","7.49115","0.02186"
"90.09000","7.50771","0.02192"
"90.28800","7.52421","0.02226"
"90.48600","7.54060","0.02202"
"90.68400","7.55728","0.02214"
"90.88200","7.57366","0.02214"
"91.08000","7.59016","0.02220"
"91.27800","7.60672","0.02259"
"91.47600","7.62317","0.02202"
"91.67400","7.63973","0.02252"
"91.87200","7.65617","0.02238"
"92.07000","7.67261","0.02257"
"92.26800","7.68923","0.02241"
"92.46600","7.70568","0.02239"
"92.66400","7.72212","0.02262"
"92.86200","7.73874","0.02239"
"93.06000","7.75518","0.02244"
"93.25800","7.77168","0.02243"
"93.45600","7.78824","0.02320"
"93.65400","7.80463","0.02255"
"93.85200","7.82119","0.02274"
"94.05000","7.83769","0.02285"
"94.24800","7.85413","0.02260"
"94.44600","7.87075","0.02256"
"94.64400","7.88720","0.02282"
"94.84200","7.90370","0.02259"
"95.04000","7.92020","0.02294"
"95.23800","7.93664","0.02271"
"95.43600","7.95320","0.02288"
"95.63400","7.96971","0.02312"
"95.83200","7.98615","0.02314"
"96.03000","8.00271","0.02300"
"96.22800","8.01909","0.02338"
"96.42600","8.03571","0.02350"
"96.62400","8.05216","0.02360"
"96.82200","8.06866","0.02305"
"97.02000","8.08516","0.02311"
"97.21800","8.10166","0.02321"
"97.41600","8.11816","0.02334"
"97.61400","8.13472","0.02343"
"97.81200","8.15117","0.02324"
"98.01000","8.16767","0.02314"
"98.20800","8.18417","0.02361"
"98.40600","8.20067","0.02354"
"98.60400","8.21717","0.02342"
"98.80200","8.23374","0.02332"
"99.00000","8.25018","0.02346"
"99.19800","8.26674","0.02317"
"99.39600","8.28324","0.02357"
"99.59400","8.29962","0.02365"
"99.79200","8.31625","0.02378"
"99.99000","8.33269","0.02425"
"100.18800","8.34913","0.02406"
"100.38600","8.36569","0.02380"
"100.58400","8.38219","0.02402"
"100.78200","8.39863","0.02375"
"100.98000","8.41526","0.02418"
"101.17800","8.43164","0.02416"
"101.37600","8.44820","0.02385"
"101.57400","8.46470","0.02417"
"101.77200","8.48114","0.02414"
"101.97000","8.49765","0.02511"
"102.16800","8.51421","0.02434"
"102.36600","8.53059","0.02493"
"102.56400","8.54715","0.02474"
"102.76200","8.56359","0.02428"
"102.96000","8.58016","0.02461"
"103.15800","8.59672","0.02510"
"103.35600","8.61316","0.02501"
"103.55400","8.62972","0.02472"
"103.75200","8.64622","0.02507"
"103.95000","8.66267","0.02531"
"104.14800","8.67923","0.02581"
"104.34600","8.69573","0.02532"
"104.54400","8.71217","0.02533"
"104.74200","8.72867","0.02542"
"104.94000","8.74518","0.02553"
"105.13800","8.76168","0.02579"
"105.33600","8.77818","0.02533"
"105.53400","8.79462","0.02573"
"105.73200","8.81124","0.02593"
"105.93000","8.82769","0.02615"
"106.12800","8.84419","0.02584"
"106.32600","8.86069","0.02643"
"106.52400","8.87719","0.02615"
"106.72200","8.89369","0.02645"
"106.92000","8.91020","0.02700"
"107.11800","8.92664","0.02681"
"107.31600","8.94326","0.02619"
"107.51400","8.95970","0.02645"
"107.71200","8.97614","0.02690"
"107.91000","8.99276","0.02665"
"108.10800","9.00915","0.02728"
"108.30600","9.02565","0.02679"
"108.50400","9.04221","0.02719"
"108.70200","9.05865","0.02709"
"108.90000","9.07521","0.02766"
"109.09800","9.09172","0.02761"
"109.29600","9.10816","0.02792"
"109.49400","9.12472","0.02784"
"109.69200","9.14116","0.02829"
"109.89000","9.15766","0.02839"
"110.08800","9.17423","0.02824"
"110.28600","9.19067","0.02868"
"110.48400","9.20717","0.02848"
"110.68200","9.22373","0.02835"
"110.88000","9.24011","0.02868"
"111.07800","9.25667","0.02833"
"111.27600","9.27318","0.02849"
"111.47400","9.28968","0.02870"
"111.67200","9.30618","0.02861"
"111.87000","9.32268","0.02865"
"112.06800","9.33924","0.02822"
"112.26600","9.35569","0.02882"
"112.46400","9.37219","0.02940"
"112.66200","9.38869","0.02908"
"112.86000","9.40519","0.02904"
"113.05800","9.42163","0.02979"
"113.25600","9.43820","0.02941"
"113.45400","9.45464","0.02982"
"113.65200","9.47114","0.03007"
"113.85000","9.48770","0.03033"
"114.04800","9.50414","0.03067"
"114.24600","9.52065","0.03058"
"114.44400","9.53721","0.03110"
"114.64200","9.55365","0.03149"
"114.84000","9.57021","0.03140"
"115.03800","9.58665","0.03167"
"115.23600","9.60316","0.03206"
"115.43400","9.61966","0.03259"
"115.63200","9.63616","0.03200"
"115.83000","9.65266","0.03239"
"116.02800","9.66916","0.03222"
"116.22600","9.68567","0.03247"
"116.42400","9.70223","0.03275"
"116.62200","9.71867","0.03369"
"116.82000","9.73511","0.03352"
"117.01800","9.75173","0.03381"
"117.21600","9.76823","0.03426"
"117.41400","9.78468","0.03494"
"117.61200","9.80124","0.03447"
"117.81000","9.81768","0.03501"
"118.00800","9.83418","0.03530"
"118.20600","9.85074","0.03571"
"118.40400","9.86713","0.03536"
"118.60200","9.88369","0.03560"
"118.80000","9.90025","0.03664"
"118.99800","9.91663","0.03687"
"119.19600","9.93319","0.03737"
"119.39400","9.94970","0.03721"
"119.59200","9.96614","0.03761"
"119.79000","9.98270","0.03763"
"119.98800","9.99914","0.03834"
"120.18600","10.01570","0.03809"
"120.38400","10.03221","0.03898"
"120.58200","10.04865","0.03896"
"120.78000","10.06521","0.03911"
"120.97800","10.08171","0.03967"
"121.17600","10.09809","0.03978"
"121.37400","10.11465","0.03947"
"121.57200","10.13116","0.03984"
"121.77000","10.14766","0.04030"
"121.96800","10.16416","0.04052"
"122.16600","10.18072","0.04070"
"122.36400","10.19716","0.04112"
"122.56200","10.21373","0.04178"
"122.76000","10.23011","0.04174"
"122.95800","10.24673","0.04194"
"123.15600","10.26317","0.04238"
"123.35400","10.27967","0.04232"
"123.55200","10.29618","0.04276"
"123.75000","10.31268","0.04284"
"123.94800","10.32924","0.04285"
"124.14600","10.34568","0.04361"
"124.34400","10.36212","0.04397"
"124.54200","10.37874","0.04421"
"124.74000","10.39519","0.04469"
"124.93800","10.41163","0.04463"
"125.13600","10.42825","0.04494"
"125.33400","10.44463","0.04558"
"125.53200","10.46119","0.04614"
"125.73000","10.47770","0.04645"
"125.92800","10.49414","0.04602"
"126.12600","10.51070","0.04702"
"126.32400","10.52720","0.04735"
"126.52200","10.54364","0.04746"
"126.72000","10.56021","0.04737"
"126.91800","10.57665","0.04825"
"127.11600","10.59315","0.04875"
"127.31400","10.60971","0.04937"
"127.51200","10.62615","0.04922"
"127.71000","10.64272","0.04968"
"127.90800","10.65922","0.05064"
"128.10600","10.67566","0.05097"
"128.30400","10.69216","0.05122"
"128.50200","10.70866","0.05163"
"128.70000","10.72517","0.05226"
"128.89799","10.74167","0.05244"
"129.09599","10.75817","0.05331"
"129.29401","10.77467","0.05411"
"129.49200","10.79123","0.05328"
"129.69000","10.80768","0.05413"
"129.88800","10.82424","0.05442"
"130.08600","10.84068","0.05517"
"130.28400","10.85718","0.05545"
"130.48199","10.87374","0.05616"
"130.67999","10.89019","0.05704"
"130.87801","10.90669","0.05695"
"131.07600","10.92319","0.05776"
"131.27400","10.93969","0.05865"
"131.47200","10.95619","0.05776"
"131.67000","10.97269","0.05797"
"131.86800","10.98914","0.05863"
"132.06599","11.00570","0.05959"
"132.26401","11.02220","0.06116"
"132.46201","11.03870","0.06133"
"132.66000","11.05520","0.06251"
"132.85800","11.07165","0.06159"
"133.05600","11.08821","0.06289"
"133.25400","11.10471","0.06300"
"133.45200","11.12115","0.06338"
"133.64999","11.13771","0.06419"
"133.84801","11.15422","0.06480"
"134.04601","11.17060","0.06483"
"134.24400","11.18716","0.06551"
"134.44200","11.20366","0.06652"
"134.64000","11.22016","0.06661"
"134.83800","11.23672","0.06687"
"135.03600","11.25311","0.06760"
"135.23399","11.26967","0.06800"
"135.43201","11.28623","0.06850"
"135.63000","11.30267","0.06848"
"135.82800","11.31917","0.06907"
"136.02600","11.33574","0.06954"
"136.22400","11.35212","0.06974"
"136.42200","11.36868","0.06946"
"136.62000","11.38518","0.06996"
"136.81799","11.40168","0.07055"
"137.01601","11.41825","0.07107"
"137.21400","11.43469","0.07113"
"137.41200","11.45125","0.07138"
"137.61000","11.46769","0.07173"
"137.80800","11.48413","0.07056"
"138.00600","11.50070","0.07092"
"138.20399","11.51720","0.07099"
"138.40199","11.53364","0.07154"
"138.60001","11.55020","0.07182"
"138.79800","11.56664","0.07217"
"138.99600","11.58315","0.07260"
"139.19400","11.59971","0.07317"
"139.39200","11.61609","0.07305"
"139.59000","11.63271","0.07313"
"139.78799","11.64915","0.07381"
"139.98599","11.66565","0.07388"
"140.18401","11.68222","0.07416"
"140.38200","11.69866","0.07452"
"140.58000","11.71516","0.07478"
"140.77800","11.73172","0.07535"
"140.97600","11.74810","0.07519"
"141.17400","11.76473","0.07544"
"141.37199","11.78117","0.07565"
"141.57001","11.79761","0.07557"
"141.76801","11.81423","0.07551"
"141.96600","11.83074","0.07572"
"142.16400","11.84712","0.07573"
"142.36200","11.86368","0.07536"
"142.56000","11.88018","0.07446"
"142.75800","11.89668","0.07216"
"142.95599","11.91318","0.07158"
"143.15401","11.92963","0.07134"
"143.35201","11.94625","0.07164"
"143.55000","11.96263","0.07182"
"143.74800","11.97913","0.07257"
"143.94600","11.99569","0.07188"
"144.14400","12.01214","0.07196"
"144.34200","12.02870","0.07255"
"144.53999","12.04520","0.07249"
"144.73801","12.06164","0.07283"
"144.93600","12.07820","0.07326"
"145.13400","12.09470","0.07357"
"145.33200","12.11115","0.07344"
"145.53000","12.12771","0.07412"
"145.72800","12.14415","0.07467"
"145.92599","12.16065","0.07501"
"146.12399","12.17721","0.07508"
"146.32201","12.19366","0.07556"
"146.52000","12.21016","0.07558"
"146.71800","12.22672","0.07606"
"146.91600","12.24316","0.07619"
"147.11400","12.25972","0.07625"
"147.31200","12.27617","0.07665"
"147.50999","12.29267","0.07704"
"147.70799","12.30923","0.07343"
"147.90601","12.32567","0.07444"
"148.10400","12.34217","0.07041"
"148.30200","12.35868","0.07184"
"148.50000","12.37518","0.07221"
"148.69800","12.39168","0.07284"
"148.89600","12.40824","0.07322"
"149.09399","12.42468","0.07393"
"149.29201","12.44125","0.07421"
"149.49001","12.45769","0.07504"
"149.68800","12.47419","0.07535"
"149.88600","12.49069","0.07544"
"150.08400","12.50713","0.07578"
"150.28200","12.52369","0.07638"
"150.48000","12.54026","0.07685"
"150.67799","12.55664","0.07726"
"150.87601","12.57320","0.07739"
"151.07401","12.58970","0.07768"
"151.27200","12.60614","0.07788"
"151.47000","12.62271","0.07902"
"151.66800","12.63915","0.07913"
"151.86600","12.65565","0.07926"
"152.06400","12.67215","0.07877"
"152.26199","12.68865","0.07942"
"152.46001","12.70516","0.07968"
"152.65800","12.72172","0.07968"
"152.85600","12.73810","0.08046"
"153.05400","12.75472","0.08102"
"153.25200","12.77122","0.08140"
"153.45000","12.78767","0.08162"
"153.64799","12.80417","0.08222"
"153.84599","12.82067","0.08283"
"154.04401","12.83717","0.08347"
"154.24200","12.85367","0.08403"
"154.44000","12.87017","0.08450"
"154.63800","12.88668","0.08495"
"154.83600","12.90324","0.08578"
"155.03400","12.91962","0.08657"
"155.23199","12.93624","0.08750"
"155.42999","12.95269","0.08776"
"155.62801","12.96913","0.08843"
"155.82600","12.98575","0.08917"
"156.02400","13.00219","0.08983"
"156.22200","13.01869","0.09087"
"156.42000","13.03520","0.09133"
"156.61800","13.05164","0.09197"
"156.81599","13.06820","0.09309"
"157.01401","13.08464","0.09345"
"157.21201","13.10114","0.09425"
"157.41000","13.11770","0.09506"
"157.60800","13.13415","0.09726"
"157.80600","13.15071","0.09657"
"158.00400","13.16721","0.09775"
"158.20200","13.18365","0.09884"
"158.39999","13.20021","0.09993"
"158.59801","13.21666","0.10127"
"158.79601","13.23310","0.10105"
"158.99400","13.24972","0.10348"
"159.19200","13.26622","0.10471"
"159.39000","13.28266","0.10530"
"159.58800","13.29923","0.07401"
"159.78600","13.31561","0.07009"
"159.98399","13.33223","0.06844"
"160.18201","13.34867","0.07019"
"160.38000","13.36517","0.06968"
"160.57800","13.38174","0.07133"
"160.77600","13.39818","0.07189"
"160.97400","13.41468","0.07322"
"161.17200","13.43118","0.07376"
"161.37000","13.44762","0.07446"
"161.56799","13.46419","0.07514"
"161.76601","13.48069","0.07543"
"161.96400","13.49713","0.07630"
"162.16200","13.51369","0.07653"
"162.36000","13.53025","0.07726"
"162.55800","13.54669","0.07797"
"162.75600","13.56320","0.07813"
"162.95399","13.57970","0.07871"
"163.15199","13.59614","0.07913"
"163.35001","13.61270","0.07994"
"163.54800","13.62920","0.08092"
"163.74600","13.64565","0.08146"
"163.94400","13.66215","0.08240"
"164.14200","13.67865","0.08281"
"164.34000","13.69521","0.08384"
"164.53799","13.71165","0.08489"
"164.73599","13.72816","0.08538"
"164.93401","13.74466","0.08643"
"165.13200","13.76116","0.08717"
"165.33000","13.77766","0.08852"
"165.52800","13.79422","0.08998"
"165.72600","13.81067","0.09071"
"165.92400","13.82723","0.09173"
"166.12199","13.84373","0.09303"
"166.32001","13.86017","0.09403"
"166.51801","13.87667","0.09537"
"166.71600","13.89317","0.09642"
"166.91400","13.90968","0.09753"
"167.11200","13.92618","0.09877"
"167.31000","13.94268","0.10000"
"167.50800","13.95918","0.10185"
"167.70599","13.97568","0.10276"
"167.90401","13.99219","0.10374"
"168.10201","14.00869","0.10567"
"168.30000","14.02525","0.10648"
"168.49800","14.04163","0.10503"
"168.69600","14.05819","0.10712"
"168.89400","14.07470","0.10796"
"169.09200","14.09114","0.11043"
"169.28999","14.10770","0.11222"
"169.48801","14.12414","0.11355"
"169.68600","14.14064","0.11605"
"169.88400","14.15721","0.11634"
"170.08200","14.17359","0.11862"
"170.28000","14.19021","0.12060"
"170.47800","14.20671","0.12128"
"170.67599","14.22315","0.12262"
"170.87399","14.23972","0.12424"
"171.07201","14.25616","0.12584"
"171.27000","14.27272","0.12625"
"171.46800","14.28922","0.12763"
"171.66600","14.30566","0.12874"
"171.86400","14.32222","0.13026"
"172.06200","14.33873","0.13168"
"172.25999","14.35511","0.13324"
"172.45799","14.37173","0.13378"
"172.65601","14.38817","0.12827"
"172.85400","14.40467","0.12625"
"173.05200","14.42124","0.12597"
"173.25000","14.43768","0.12767"
"173.44800","14.45418","0.12850"
"173.64600","14.47068","0.12996"
"173.84399","14.48712","0.13170"
"174.04201","14.50375","0.13367"
"174.24001","14.52019","0.13474"
"174.43800","14.53663","0.13641"
"174.63600","14.55313","0.13793"
"174.83400","14.56969","0.13907"
"175.03200","14.58619","0.13907"
"175.23000","14.60270","0.14044"
"175.42799","14.61920","0.14243"
"175.62601","14.63576","0.14358"
"175.82401","14.65220","0.14457"
"176.02200","14.66859","0.14597"
"176.22000","14.68521","0.14638"
"176.41800","14.70165","0.14755"
"176.61600","14.71821","0.14925"
"176.81400","14.73471","0.14953"
"177.01199","14.75115","0.15049"
"177.21001","14.76772","0.15149"
"177.40800","14.78422","0.15234"
"177.60600","14.80066","0.15342"
"177.80400","14.81722","0.15385"
"178.00200","14.83366","0.15437"
"178.20000","14.85017","0.15549"
"178.39799","14.86667","0.15674"
"178.59599","14.88317","0.15792"
"178.79401","14.89967","0.15905"
"178.99200","14.91623","0.16123"
"179.19000","14.93268","0.16291"
"179.38800","14.94918","0.16372"
"179.58600","14.96568","0.16490"
"179.78400","14.98212","0.16611"
"179.98199","14.99868","0.16666"
"180.17999","15.01518","0.16764"
"180.37801","15.03169","0.16793"
"180.57600","15.04819","0.16860"
"180.77400","15.06469","0.16958"
"180.97200","15.08113","0.16916"
"181.17000","15.09769","0.17062"
"181.36800","15.11420","0.17178"
"181.56599","15.13070","0.14902"
"181.76401","15.14720","0.15141"
"181.96201","15.16370","0.15174"
"182.16000","15.18020","0.15317"
"182.35800","15.19665","0.15365"
"182.55600","15.21315","0.15591"
"182.75400","15.22971","0.15522"
"182.95200","15.24615","0.15763"
"183.14999","15.26265","0.15783"
"183.34801","15.27921","0.16016"
"183.54601","15.29566","0.16019"
"183.74400","15.31216","0.16284"
"183.94200","15.32872","0.16261"
"184.14000","15.34516","0.16463"
"184.33800","15.36166","0.15505"
"184.53600","15.37817","0.15684"
"184.73399","15.39467","0.15810"
"184.93201","15.41123","0.16060"
"185.13000","15.42761","0.16177"
"185.32800","15.44417","0.16293"
"185.52600","15.46074","0.15374"
"185.72400","15.47712","0.15511"
"185.92200","15.49374","0.15622"
"186.12000","15.51018","0.15729"
"186.31799","15.52668","0.15935"
"186.51601","15.54325","0.14929"
"186.71400","15.55963","0.14924"
"186.91200","15.57613","0.15023"
"187.11000","15.59269","0.15272"
"187.30800","15.60907","0.15457"
"187.50600","15.62570","0.15780"
"187.70399","15.64220","0.15756"
"187.90199","15.65864","0.16093"
"188.10001","15.67520","0.16251"
"188.29800","15.69170","0.16516"
"188.49600","15.70815","0.16609"
"188.69400","15.72477","0.16882"
"188.89200","15.74115","0.16905"
"189.09000","15.75771","0.17161"
"189.28799","15.77421","0.17283"
"189.48599","15.79060","0.17464"
"189.68401","15.80722","0.17542"
"189.88200","15.82372","0.17756"
"190.08000","15.84022","0.17864"
"190.27800","15.85672","0.18023"
"190.47600","15.87322","0.18099"
"190.67400","15.88966","0.18212"
"190.87199","15.90617","0.18225"
"191.07001","15.92261","0.18377"
"191.26801","15.93923","0.18430"
"191.46600","15.95561","0.18497"
"191.66400","15.97217","0.18582"
"191.86200","15.98868","0.18617"
"192.06000","16.00518","0.18669"
"192.25800","16.02168","0.18618"
"192.45599","16.03818","0.16247"
"192.65401","16.05462","0.15085"
"192.85201","16.07125","0.15287"
"193.05000","16.08769","0.15444"
"193.24800","16.10413","0.15590"
"193.44600","16.12075","0.15794"
"193.64400","16.13713","0.15968"
"193.84200","16.15370","0.16213"
"194.03999","16.17020","0.16319"
"194.23801","16.18670","0.16490"
"194.43600","16.20320","0.16618"
"194.63400","16.21970","0.16766"
"194.83200","16.23615","0.16918"
"195.03000","16.25271","0.17033"
"195.22800","16.26915","0.17129"
"195.42599","16.28565","0.17291"
"195.62399","16.30221","0.17317"
"195.82201","16.31866","0.17414"
"196.02000","16.33522","0.17548"
"196.21800","16.35172","0.17656"
"196.41600","16.36816","0.17754"
"196.61400","16.38472","0.17790"
"196.81200","16.40117","0.17870"
"197.00999","16.41767","0.17967"
"197.20799","16.43417","0.18079"
"197.40601","16.45067","0.18166"
"197.60400","16.46717","0.18273"
"197.80200","16.48368","0.18351"
"198.00000","16.50018","0.18405"
"198.19800","16.51668","0.18439"
"198.39600","16.53318","0.18565"
"198.59399","16.54968","0.18592"
"198.79201","16.56624","0.18625"
"198.99001","16.58269","0.18694"
"199.18800","16.59919","0.18772"
"199.38600","16.61569","0.18820"
"199.58400","16.63219","0.18906"
"199.78200","16.64869","0.18922"
"199.98000","16.66520","0.18849"
"200.17799","16.68170","0.18468"
"200.37601","16.69820","0.18588"
"200.57401","16.71470","0.18626"
"200.77200","16.73120","0.18718"
"200.97000","16.74771","0.18748"
"201.16800","16.76421","0.18814"
"201.36600","16.78065","0.18886"
"201.56400","16.79721","0.18978"
"201.76199","16.81365","0.19057"
"201.96001","16.83022","0.19083"
"202.15800","16.84672","0.19100"
"202.35600","16.86310","0.19100"
"202.55400","16.87972","0.19228"
"202.75200","16.89622","0.19179"
"202.95000","16.91266","0.19233"
"203.14799","16.92923","0.19249"
"203.34599","16.94567","0.19272"
"203.54401","16.96217","0.19182"
"203.74200","16.97873","0.18896"
"203.94000","16.99517","0.18901"
"204.13800","17.01168","0.19009"
"204.33600","17.02824","0.19081"
"204.53400","17.04462","0.18911"
"204.73199","17.06118","0.07830"
"204.92999","17.07768","0.07445"
"205.12801","17.09413","0.07762"
"205.32600","17.11069","0.07725"
"205.52400","17.12713","0.07717"
"205.72200","17.14369","0.08104"
"205.92000","17.16019","0.07703"
"206.11800","17.17658","0.08294"
"206.31599","17.19326","0.07789"
"206.51401","17.20970","0.08282"
"206.71201","17.22614","0.08081"
"206.91000","17.24270","0.08238"
"207.10800","17.25920","0.08517"
"207.30600","17.27571","0.08208"
"207.50400","17.29221","0.08862"
"207.70200","17.30865","0.08368"
"207.89999","17.32521","0.09099"
"208.09801","17.34165","0.08574"
"208.29601","17.35810","0.09214"
"208.49400","17.37472","0.08911"
"208.69200","17.39116","0.09245"
"208.89000","17.40766","0.09287"
"209.08800","17.42422","0.09340"
"209.28600","17.44067","0.09677"
"209.48399","17.45723","0.09437"
"209.68201","17.47373","0.10024"
"209.88000","17.49011","0.09561"
"210.07800","17.50679","0.10376"
"210.27600","17.52312","0.09884"
"210.47400","17.53962","0.10675"
"210.67200","17.55618","0.10278"
"210.87000","17.57268","0.10873"
"211.06799","17.58912","0.10659"
"211.26601","17.60568","0.11109"
"211.46400","17.62213","0.11265"
"211.66200","17.63875","0.11350"
"211.86000","17.65519","0.11802"
"212.05800","17.67163","0.11631"
"212.25600","17.68819","0.12191"
"212.45399","17.70464","0.11851"
"212.65199","17.72114","0.12524"
"212.85001","17.73764","0.12260"
"213.04800","17.75414","0.12800"
"213.24600","17.77070","0.12560"
"213.44400","17.78721","0.13009"
"213.64200","17.80365","0.12886"
"213.84000","17.82015","0.13240"
"214.03799","17.83665","0.13169"
"214.23599","17.85321","0.13456"
"214.43401","17.86966","0.13408"
"214.63200","17.88622","0.13765"
"214.83000","17.90266","0.13812"
"215.02800","17.91922","0.13998"
"215.22600","17.93566","0.14105"
"215.42400","17.95217","0.14159"
"215.62199","17.96867","0.14291"
"215.82001","17.98517","0.14427"
"216.01801","18.00173","0.14025"
"216.21600","18.01817","0.14103"
"216.41400","18.03468","0.14400"
"216.61200","18.05118","0.14456"
"216.81000","18.06768","0.14754"
"217.00800","18.08424","0.14800"
"217.20599","18.10068","0.14939"
"217.40401","18.11719","0.14955"
"217.60201","18.13369","0.15226"
"217.80000","18.15025","0.15242"
"217.99800","18.16663","0.15448"
"218.19600","18.18313","0.15526"
"218.39400","18.19970","0.15787"
"218.59200","18.21620","0.15803"
"218.78999","18.23270","0.16089"
"218.98801","18.24914","0.16173"
"219.18600","18.26570","0.16485"
"219.38400","18.28226","0.16491"
"219.58200","18.29859","0.16715"
"219.78000","18.31521","0.16728"
"219.97800","18.33171","0.17034"
"220.17599","18.34815","0.17112"
"220.37399","18.36471","0.17243"
"220.57201","18.38116","0.17349"
"220.77000","18.39760","0.17536"
"220.96800","18.41422","0.17556"
"221.16600","18.43060","0.17799"
"221.36400","18.44722","0.17900"
"221.56200","18.46373","0.18085"
"221.75999","18.48017","0.18173"
"221.95799","18.49673","0.18263"
"222.15601","18.51317","0.18358"
"222.35400","18.52967","0.18437"
"222.55200","18.54618","0.18521"
"222.75000","18.56268","0.18609"
"222.94800","18.57918","0.13273"
"223.14600","18.59568","0.11998"
"223.34399","18.61206","0.12730"
"223.54201","18.62868","0.12722"
"223.74001","18.64519","0.13050"
"223.93800","18.66163","0.12666"
"224.13600","18.67819","0.13511"
"224.33400","18.69469","0.13217"
"224.53200","18.71119","0.13613"
"224.73000","18.72775","0.13656"
"224.92799","18.74414","0.13900"
"225.12601","18.76076","0.14038"
"225.32401","18.77720","0.14331"
"225.52200","18.79358","0.14502"
"225.72000","18.81021","0.14708"
"225.91800","18.82665","0.14946"
"226.11600","18.84315","0.14987"
"226.31400","18.85971","0.15284"
"226.51199","18.87615","0.15364"
"226.71001","18.89272","0.15604"
"226.90800","18.90922","0.15748"
"227.10600","18.92560","0.16135"
"227.30400","18.94228","0.16241"
"227.50200","18.95866","0.16517"
"227.70000","18.97511","0.16722"
"227.89799","18.99173","0.16956"
"228.09599","19.00817","0.17027"
"228.29401","19.02473","0.17307"
"228.49200","19.04123","0.17430"
"228.69000","19.05767","0.17617"
"228.88800","19.07424","0.17800"
"229.08600","19.09068","0.17930"
"229.28400","19.10712","0.18074"
"229.48199","19.12374","0.18239"
"229.67999","19.14013","0.18382"
"229.87801","19.15669","0.18428"
"230.07600","19.17319","0.18562"
"230.27400","19.18963","0.18640"
"230.47200","19.20619","0.18748"
"230.67000","19.22269","0.18790"
"230.86800","19.23914","0.18876"
"231.06599","19.25570","0.18955"
"231.26401","19.27220","0.19108"
"231.46201","19.28864","0.19174"
"231.66000","19.30520","0.19335"
"231.85800","19.32164","0.19429"
"232.05600","19.33815","0.19636"
"232.25400","19.35471","0.19698"
"232.45200","19.37121","0.19962"
"232.64999","19.38765","0.20051"
"232.84801","19.40415","0.20239"
"233.04601","19.42066","0.20347"
"233.24400","19.43716","0.20470"
"233.44200","19.45372","0.20395"
"233.64000","19.47016","0.17071"
"233.83800","19.48666","0.15558"
"234.03600","19.50317","0.16434"
"234.23399","19.51967","0.16295"
"234.43201","19.53623","0.16301"
"234.63000","19.55267","0.17012"
"234.82800","19.56923","0.16636"
"235.02600","19.58573","0.17131"
"235.22400","19.60212","0.17259"
"235.42200","19.61868","0.17210"
"235.62000","19.63518","0.17937"
"235.81799","19.65168","0.17610"
"236.01601","19.66818","0.17997"
"236.21400","19.68463","0.18202"
"236.41200","19.70119","0.18207"
"236.61000","19.71775","0.18453"
"236.80800","19.73413","0.18486"
"237.00600","19.75076","0.18540"
"237.20399","19.76719","0.18790"
"237.40199","19.78358","0.18730"
"237.60001","19.80026","0.18883"
"237.79800","19.81664","0.19045"
"237.99600","19.83315","0.19037"
"238.19400","19.84971","0.19267"
"238.39200","19.86609","0.19413"
"238.59000","19.88265","0.19480"
"238.78799","19.89921","0.19739"
"238.98599","19.91560","0.19874"
"239.18401","19.93221","0.19984"
"239.38200","19.94872","0.20268"
"239.58000","19.96522","0.20292"
"239.77800","19.98172","0.20449"
"239.97600","19.99816","0.20639"
"240.17400","20.01466","0.20787"
"240.37199","20.03123","0.20938"
"240.57001","20.04761","0.21189"
"240.76801","20.06423","0.21376"
"240.96600","20.08068","0.21605"
"241.16400","20.09711","0.21851"
"241.36200","20.11374","0.22004"
"241.56000","20.13018","0.22162"
"241.75800","20.14668","0.22395"
"241.95599","20.16324","0.22484"
"242.15401","20.17969","0.22523"
"242.35201","20.19624","0.22795"
"242.55000","20.21263","0.22923"
"242.74800","20.22913","0.23099"
"242.94600","20.24569","0.23298"
"243.14400","20.26213","0.23456"
"243.34200","20.27869","0.23627"
"243.53999","20.29520","0.23839"
"243.73801","20.31164","0.24005"
"243.93600","20.32826","0.24216"
"244.13400","20.34470","0.24404"
"244.33200","20.36109","0.24676"
"244.53000","20.37777","0.24870"
"244.72800","20.39415","0.25042"
"244.92599","20.41065","0.25327"
"245.12399","20.42721","0.25575"
"245.32201","20.44366","0.25831"
"245.52000","20.46022","0.26192"
"245.71800","20.47672","0.26402"
"245.91600","20.49316","0.26806"
"246.11400","20.50972","0.26941"
"246.31200","20.52617","0.27233"
"246.50999","20.54267","0.27549"
"246.70799","20.55917","0.27577"
"246.90601","20.57567","0.27767"
"247.10400","20.59217","0.27917"
"247.30200","20.60873","0.28160"
"247.50000","20.62518","0.28297"
"247.69800","20.64168","0.28439"
"247.89600","20.65818","0.28431"
"248.09399","20.67468","0.28557"
"248.29201","20.69118","0.28722"
"248.49001","20.70769","0.28894"
"248.68800","20.72419","0.29023"
"248.88600","20.74069","0.29207"
"249.08400","20.75719","0.29291"
"249.28200","20.77369","0.29415"
"249.48000","20.79020","0.29491"
"249.67799","20.80664","0.29574"
"249.87601","20.82314","0.29619"
"250.07401","20.83970","0.29739"
"250.27200","20.85614","0.29794"
"250.47000","20.87271","0.29841"
"250.66800","20.88921","0.29928"
"250.86600","20.90565","0.29986"
"251.06400","20.92221","0.30109"
"251.26199","20.93865","0.30225"
"251.46001","20.95515","0.30381"
"251.65800","20.97166","0.30489"
"251.85600","20.98816","0.30674"
"252.05400","21.00466","0.30905"
"252.25200","21.02122","0.31156"
"252.45000","21.03766","0.31307"
"252.64799","21.05423","0.31562"
"252.84599","21.07073","0.31953"
"253.04401","21.08717","0.32220"
"253.24200","21.10367","0.31628"
"253.44000","21.12017","0.31984"
"253.63800","21.13667","0.32296"
"253.83600","21.15324","0.32527"
"254.03400","21.16962","0.32887"
"254.23199","21.18624","0.33081"
"254.42999","21.20268","0.33359"
"254.62801","21.21913","0.33634"
"254.82600","21.23575","0.33875"
"255.02400","21.25219","0.34022"
"255.22200","21.26869","0.34287"
"255.42000","21.28526","0.34547"
"255.61800","21.30164","0.34734"
"255.81599","21.31814","0.35073"
"256.01401","21.33470","0.35254"
"256.21201","21.35114","0.35417"
"256.41000","21.36770","0.35599"
"256.60800","21.38420","0.35722"
"256.80600","21.40065","0.35922"
"257.00400","21.41721","0.36052"
"257.20200","21.43365","0.36261"
"257.39999","21.45021","0.36488"
"257.59799","21.46671","0.36721"
"257.79599","21.48310","0.36813"
"257.99399","21.49978","0.36985"
"258.19199","21.51622","0.37140"
"258.39001","21.53266","0.37329"
"258.58801","21.54922","0.37561"
"258.78601","21.56573","0.37676"
"258.98401","21.58217","0.37861"
"259.18201","21.59873","0.38013"
"259.38000","21.61517","0.38097"
"259.57800","21.63173","0.38277"
"259.77600","21.64818","0.38221"
"259.97400","21.66462","0.37921"
"260.17200","21.68118","0.38064"
"260.37000","21.69768","0.37963"
"260.56799","21.71418","0.37691"
"260.76599","21.73068","0.37835"
"260.96399","21.74713","0.37935"
"261.16199","21.76375","0.38136"
"261.35999","21.78019","0.38246"
"261.55801","21.79663","0.38374"
"261.75601","21.81325","0.38529"
"261.95401","21.82964","0.38668"
"262.15201","21.84620","0.38763"
"262.35001","21.86270","0.38856"
"262.54800","21.87920","0.38932"
"262.74600","21.89570","0.39024"
"262.94400","21.91221","0.39095"
"263.14200","21.92865","0.39170"
"263.34000","21.94521","0.39301"
"263.53799","21.96165","0.39438"
"263.73599","21.97815","0.39594"
"263.93399","21.99471","0.39774"
"264.13199","22.01116","0.39890"
"264.32999","22.02766","0.40049"
"264.52802","22.04422","0.40115"
"264.72601","22.06067","0.40040"
"264.92401","22.07717","0.39804"
"265.12201","22.09373","0.40041"
"265.32001","22.11017","0.40129"
"265.51801","22.12667","0.40291"
"265.71600","22.14317","0.40532"
"265.91400","22.15968","0.40724"
"266.11200","22.17612","0.40880"
"266.31000","22.19268","0.41105"
"266.50800","22.20918","0.41297"
"266.70599","22.22568","0.41456"
"266.90399","22.24218","0.41658"
"267.10199","22.25869","0.41917"
"267.29999","22.27519","0.42037"
"267.49799","22.29163","0.42336"
"267.69601","22.30819","0.42574"
"267.89401","22.32463","0.42697"
"268.09201","22.34120","0.42927"
"268.29001","22.35770","0.43030"
"268.48801","22.37414","0.43208"
"268.68600","22.39070","0.43383"
"268.88400","22.40720","0.43555"
"269.08200","22.42365","0.43705"
"269.28000","22.44015","0.43859"
"269.47800","22.45671","0.44087"
"269.67599","22.47315","0.44198"
"269.87399","22.48965","0.44455"
"270.07199","22.50616","0.44573"
"270.26999","22.52272","0.44804"
"270.46799","22.53922","0.45051"
"270.66599","22.55566","0.45180"
"270.86401","22.57222","0.45388"
"271.06201","22.58878","0.45564"
"271.26001","22.60511","0.45842"
"271.45801","22.62173","0.45916"
"271.65601","22.63817","0.46183"
"271.85400","22.65467","0.46386"
"272.05200","22.67123","0.46687"
"272.25000","22.68768","0.47068"
"272.44800","22.70418","0.47371"
"272.64600","22.72074","0.47745"
"272.84399","22.73712","0.47944"
"273.04199","22.75368","0.47347"
"273.23999","22.77024","0.47535"
"273.43799","22.78663","0.47761"
"273.63599","22.80325","0.48139"
"273.83401","22.81963","0.48378"
"274.03201","22.83613","0.48613"
"274.23001","22.85270","0.48891"
"274.42801","22.86914","0.49185"
"274.62601","22.88570","0.49366"
"274.82401","22.90220","0.49542"
"275.02200","22.91858","0.48917"
"275.22000","22.93521","0.49007"
"275.41800","22.95171","0.49148"
"275.61600","22.96815","0.49315"
"275.81400","22.98471","0.49463"
"276.01199","23.00121","0.49593"
"276.20999","23.01771","0.49731"
"276.40799","23.03422","0.49818"
"276.60599","23.05066","0.49926"
"276.80399","23.06722","0.50020"
"277.00201","23.08366","0.50127"
"277.20001","23.10016","0.50255"
"277.39801","23.11673","0.50384"
"277.59601","23.13311","0.50509"
"277.79401","23.14973","0.50682"
"277.99200","23.16623","0.50846"
"278.19000","23.18261","0.51002"
"278.38800","23.19924","0.51069"
"278.58600","23.21568","0.51218"
"278.78400","23.23212","0.51381"
"278.98199","23.24868","0.51557"
"279.17999","23.26518","0.51759"
"279.37799","23.28163","0.38059"
"279.57599","23.29819","0.33619"
"279.77399","23.31469","0.03717"
"279.97198","23.33119","0.02660"
"280.17001","23.34769","0.02781"
"280.36801","23.36414","0.04153"
"280.56601","23.38076","0.01814"
"280.76401","23.39720","0.02138"
"280.96201","23.41364","0.03927"
"281.16000","23.43014","0.01562"
"281.35800","23.44664","0.02664"
"281.55600","23.46314","0.03244"
"281.75400","23.47971","0.01772"
"281.95200","23.49615","0.02880"
"282.14999","23.51271","0.02730"
"282.34799","23.52921","0.02035"
"282.54599","23.54566","0.03163"
"282.74399","23.56222","0.02510"
"282.94199","23.57872","0.02400"
"283.14001","23.59516","0.03125"
"283.33801","23.61166","0.02373"
"283.53601","23.62817","0.02753"
"283.73401","23.64467","0.02859"
"283.93201","23.66123","0.02450"
"284.13000","23.67773","0.03010"
"284.32800","23.69423","0.02713"
"284.52600","23.71067","0.02711"
"284.72400","23.72712","0.03003"
"284.92200","23.74368","0.02618"
"285.12000","23.76024","0.02943"
"285.31799","23.77662","0.02859"
"285.51599","23.79318","0.02774"
"285.71399","23.80969","0.03096"
"285.91199","23.82619","0.02782"
"286.10999","23.84269","0.03019"
"286.30801","23.85919","0.03006"
"286.50601","23.87569","0.02847"
"286.70401","23.89220","0.03093"
"286.90201","23.90870","0.02970"
"287.10001","23.92520","0.03052"
"287.29800","23.94164","0.03179"
"287.49600","23.95820","0.02958"
"287.69400","23.97470","0.03220"
"287.89200","23.99115","0.03145"
"288.09000","24.00771","0.03116"
"288.28799","24.02421","0.03245"
"288.48599","24.04066","0.03129"
"288.68399","24.05722","0.03302"
"288.88199","24.07366","0.03259"
"289.03799","24.08663","0.03270"