File: Force_trajectories/170107_2/Specimen_RawData_7.csv
End date,"1/7/2017"
Specimen label,"3AG_22"
Maximum Load,"0.73679",N

Time,Extension,Load
(s),(mm),(N)
"0.00000","0.00000","0.00005"
"0.31800","0.02619","0.00160"
"0.63600","0.05327","0.00393"
"0.95400","0.07970","0.00495"
"1.27200","0.10625","0.00653"
"1.59000","0.13267","0.00842"
"1.90800","0.15922","0.01014"
"2.22600","0.18565","0.01120"
"2.54400","0.21213","0.01263"
"2.86200","0.23868","0.01344"
"3.18000","0.26511","0.01436"
"3.49800","0.29171","0.01650"
"3.81600","0.31814","0.01698"
"4.13400","0.34469","0.01761"
"4.45200","0.37123","0.01852"
"4.77000","0.39760","0.01964"
"5.08800","0.42421","0.02016"
"5.40600","0.45063","0.02109"
"5.72400","0.47718","0.02136"
"6.04200","0.50373","0.02214"
"6.36000","0.53015","0.02304"
"6.67800","0.55664","0.02310"
"6.99600","0.58313","0.02394"
"7.31400","0.60967","0.02434"
"7.63200","0.63616","0.02486"
"7.95000","0.66265","0.02427"
"8.26800","0.68913","0.02504"
"8.58600","0.71562","0.02105"
"8.90400","0.74217","0.02072"
"9.22200","0.76865","0.01934"
"9.54000","0.79514","0.01982"
"9.85800","0.82169","0.02020"
"10.17600","0.84811","0.02127"
"10.49400","0.87472","0.02235"
"10.81200","0.90115","0.02296"
"11.13000","0.92763","0.02367"
"11.44800","0.95418","0.02429"
"11.76600","0.98067","0.02445"
"12.08400","1.00721","0.02448"
"12.40200","1.03364","0.02482"
"12.72000","1.06019","0.02496"
"13.03800","1.08667","0.02448"
"13.35600","1.11316","0.02524"
"13.67400","1.13965","0.02507"
"13.99200","1.16614","0.02547"
"14.31000","1.19268","0.02536"
"14.62800","1.21917","0.02490"
"14.94600","1.24566","0.02507"
"15.26400","1.27220","0.02568"
"15.58200","1.29857","0.02541"
"15.90000","1.32518","0.02616"
"16.21800","1.35166","0.02684"
"16.53600","1.37821","0.02679"
"16.85400","1.40476","0.02752"
"17.17200","1.43112","0.02826"
"17.49000","1.45773","0.02880"
"17.80800","1.48416","0.02882"
"18.12600","1.51070","0.02932"
"18.44400","1.53719","0.02992"
"18.76200","1.56368","0.03015"
"19.08000","1.59022","0.03061"
"19.39800","1.61665","0.03085"
"19.71600","1.64320","0.03114"
"20.03400","1.66968","0.03153"
"20.35200","1.69617","0.03165"
"20.67000","1.72266","0.03207"
"20.98800","1.74914","0.03205"
"21.30600","1.77569","0.03264"
"21.62400","1.80218","0.03320"
"21.94200","1.82866","0.03383"
"22.26000","1.85521","0.03432"
"22.57800","1.88164","0.03474"
"22.89600","1.90818","0.03512"
"23.21400","1.93467","0.03569"
"23.53200","1.96122","0.03643"
"23.85000","1.98770","0.03741"
"24.16800","2.01413","0.03782"
"24.48600","2.04074","0.03877"
"24.80400","2.06716","0.03933"
"25.12200","2.09371","0.04042"
"25.44000","2.12020","0.04156"
"25.75800","2.14662","0.04197"
"26.07600","2.17317","0.04359"
"26.39400","2.19966","0.04370"
"26.71200","2.22626","0.04485"
"27.03000","2.25275","0.04623"
"27.34800","2.27912","0.04675"
"27.66600","2.30572","0.04835"
"27.98400","2.33215","0.04904"
"28.30200","2.35864","0.05032"
"28.62000","2.38518","0.05163"
"28.93800","2.41161","0.05330"
"29.25600","2.43822","0.05429"
"29.57400","2.46464","0.05540"
"29.89200","2.49119","0.05656"
"30.21000","2.51762","0.05810"
"30.52800","2.54416","0.05940"
"30.84600","2.57071","0.06155"
"31.16400","2.59714","0.06345"
"31.48200","2.62368","0.06534"
"31.80000","2.65017","0.06735"
"32.11800","2.67672","0.06884"
"32.43600","2.70326","0.07041"
"32.75400","2.72963","0.07237"
"33.07200","2.75618","0.07409"
"33.39000","2.78266","0.07478"
"33.70800","2.80921","0.07642"
"34.02600","2.83570","0.07741"
"34.34400","2.86218","0.07898"
"34.66200","2.88861","0.07971"
"34.98000","2.91510","0.08118"
"35.29800","2.94170","0.08240"
"35.61600","2.96819","0.08397"
"35.93400","2.99468","0.08539"
"36.25200","3.02122","0.08617"
"36.57000","3.04765","0.08709"
"36.88800","3.07420","0.08937"
"37.20600","3.10069","0.09008"
"37.52400","3.12717","0.09182"
"37.84200","3.15372","0.09275"
"38.16000","3.18015","0.09459"
"38.47800","3.20669","0.09595"
"38.79600","3.23312","0.09726"
"39.11400","3.25967","0.09806"
"39.43200","3.28621","0.09896"
"39.75000","3.31270","0.10057"
"40.06800","3.33919","0.10106"
"40.38600","3.36561","0.10228"
"40.70400","3.39216","0.10311"
"41.02200","3.41871","0.10390"
"41.34000","3.44513","0.10559"
"41.65800","3.47168","0.10647"
"41.97600","3.49811","0.10767"
"42.29400","3.52471","0.10851"
"42.61200","3.55126","0.11050"
"42.93000","3.57769","0.11228"
"43.24800","3.60417","0.11306"
"43.56600","3.63060","0.11487"
"43.88400","3.65721","0.11625"
"44.20200","3.68369","0.11718"
"44.52000","3.71018","0.10453"
"44.83800","3.73673","0.10563"
"45.15600","3.76315","0.10693"
"45.47400","3.78970","0.10866"
"45.79200","3.81619","0.11035"
"46.11000","3.84267","0.11125"
"46.42800","3.86916","0.11253"
"46.74600","3.89565","0.11517"
"47.06400","3.92225","0.11761"
"47.38200","3.94868","0.11856"
"47.70000","3.97517","0.12042"
"48.01800","4.00171","0.12112"
"48.33600","4.02820","0.12171"
"48.65400","4.05469","0.12359"
"48.97200","4.08117","0.12555"
"49.29000","4.10772","0.12714"
"49.60800","4.13421","0.12772"
"49.92600","4.16069","0.12923"
"50.24400","4.18718","0.13035"
"50.56200","4.21361","0.13220"
"50.88000","4.24021","0.13383"
"51.19800","4.26670","0.13461"
"51.51600","4.29325","0.13445"
"51.83400","4.31973","0.13546"
"52.15200","4.34616","0.13619"
"52.47000","4.37271","0.13707"
"52.78800","4.39913","0.13597"
"53.10600","4.42568","0.13742"
"53.42400","4.45223","0.12197"
"53.74200","4.47865","0.12337"
"54.06000","4.50520","0.12454"
"54.37800","4.53163","0.12520"
"54.69600","4.55823","0.12691"
"55.01400","4.58472","0.12818"
"55.33200","4.61115","0.12931"
"55.65000","4.63775","0.13040"
"55.96800","4.66418","0.13104"
"56.28600","4.69067","0.13290"
"56.60400","4.71722","0.13428"
"56.92200","4.74364","0.13598"
"57.24000","4.77025","0.13649"
"57.55800","4.79667","0.13677"
"57.87600","4.82322","0.12715"
"58.19400","4.84965","0.12968"
"58.51200","4.87614","0.13222"
"58.83000","4.90274","0.13397"
"59.14800","4.92917","0.13554"
"59.46600","4.95572","0.13619"
"59.78400","4.98214","0.13658"
"60.10200","5.00869","0.13643"
"60.42000","5.03524","0.13751"
"60.73800","5.06160","0.13872"
"61.05600","5.08815","0.13936"
"61.37400","5.11464","0.13973"
"61.69200","5.14124","0.14057"
"62.01000","5.16773","0.14083"
"62.32800","5.19416","0.14158"
"62.64600","5.22070","0.14224"
"62.96400","5.24713","0.14348"
"63.28200","5.27374","0.14531"
"63.60000","5.30016","0.14575"
"63.91800","5.32665","0.14302"
"64.23600","5.35320","0.14319"
"64.55400","5.37962","0.14396"
"64.87200","5.40623","0.14504"
"65.19000","5.43266","0.14588"
"65.50800","5.45920","0.14683"
"65.82600","5.48569","0.14828"
"66.14400","5.51212","0.15017"
"66.46200","5.53872","0.15112"
"66.78000","5.56515","0.15162"
"67.09800","5.59164","0.15335"
"67.41600","5.61824","0.15456"
"67.73400","5.64473","0.15698"
"68.05200","5.67122","0.15835"
"68.37000","5.69764","0.16062"
"68.68800","5.72419","0.16080"
"69.00600","5.75074","0.16176"
"69.32400","5.77716","0.16354"
"69.64200","5.80371","0.16548"
"69.96000","5.83014","0.16755"
"70.27800","5.85668","0.16978"
"70.59600","5.88323","0.17212"
"70.91400","5.90966","0.16092"
"71.23200","5.93620","0.16144"
"71.55000","5.96263","0.16286"
"71.86800","5.98924","0.16470"
"72.18600","6.01566","0.16619"
"72.50400","6.04215","0.16872"
"72.82200","6.06864","0.16973"
"73.14000","6.09512","0.17133"
"73.45800","6.12167","0.17231"
"73.77600","6.14816","0.17406"
"74.09400","6.17464","0.17613"
"74.41200","6.20119","0.17732"
"74.73000","6.22768","0.17896"
"75.04800","6.25422","0.18093"
"75.36600","6.28065","0.18204"
"75.68400","6.30720","0.18349"
"76.00200","6.33368","0.17350"
"76.32000","6.36017","0.15652"
"76.63800","6.38672","0.15703"
"76.95600","6.41315","0.13964"
"77.27400","6.43969","0.13947"
"77.59200","6.46624","0.13997"
"77.91000","6.49266","0.14028"
"78.22800","6.51921","0.14061"
"78.54600","6.54558","0.14075"
"78.86400","6.57219","0.14132"
"79.18200","6.59867","0.14132"
"79.50000","6.62516","0.14258"
"79.81800","6.65171","0.14344"
"80.13600","6.67813","0.14445"
"80.45400","6.70468","0.14524"
"80.77200","6.73117","0.09970"
"81.09000","6.75771","0.10143"
"81.40800","6.78420","0.10234"
"81.72600","6.81063","0.10527"
"82.04400","6.83717","0.10769"
"82.36200","6.86372","0.10899"
"82.68000","6.89021","0.11078"
"82.99800","6.91669","0.11163"
"83.31600","6.94318","0.11435"
"83.63400","6.96973","0.11808"
"83.95200","6.99615","0.11948"
"84.27000","7.02264","0.12156"
"84.58800","7.04919","0.12289"
"84.90600","7.07567","0.12523"
"85.22400","7.10216","0.12793"
"85.54200","7.12865","0.13041"
"85.86000","7.15519","0.13262"
"86.17800","7.18168","0.13337"
"86.49600","7.20817","0.13460"
"86.81400","7.23471","0.13598"
"87.13200","7.26114","0.13694"
"87.45000","7.28775","0.13870"
"87.76800","7.31411","0.13965"
"88.08600","7.34072","0.14045"
"88.40400","7.36721","0.14103"
"88.72200","7.39363","0.14187"
"89.04000","7.42024","0.14289"
"89.35800","7.44667","0.14402"
"89.67600","7.47321","0.14531"
"89.99400","7.49970","0.14663"
"90.31200","7.52619","0.14743"
"90.63000","7.55267","0.14857"
"90.94800","7.57910","0.14948"
"91.26600","7.60571","0.15164"
"91.58400","7.63213","0.15285"
"91.90200","7.65862","0.15455"
"92.22000","7.68517","0.15646"
"92.53800","7.71165","0.15780"
"92.85600","7.73814","0.15801"
"93.17400","7.76469","0.15901"
"93.49200","7.79111","0.16081"
"93.81000","7.81772","0.16218"
"94.12800","7.84415","0.16348"
"94.44600","7.87069","0.16493"
"94.76400","7.89712","0.16694"
"95.08200","7.92361","0.16908"
"95.40000","7.95021","0.17197"
"95.71800","7.97664","0.17367"
"96.03600","8.00325","0.17591"
"96.35400","8.02961","0.17652"
"96.67200","8.05616","0.17804"
"96.99000","8.08271","0.17891"
"97.30800","8.10919","0.18119"
"97.62600","8.13568","0.18308"
"97.94400","8.16211","0.18557"
"98.26200","8.18871","0.18757"
"98.58000","8.21520","0.19046"
"98.89800","8.24163","0.19255"
"99.21600","8.26812","0.19447"
"99.53400","8.29454","0.19582"
"99.85200","8.32121","0.19742"
"100.17000","8.34769","0.19824"
"100.48800","8.37418","0.20077"
"100.80600","8.40073","0.20302"
"101.12400","8.42716","0.20421"
"101.44200","8.45370","0.20711"
"101.76000","8.48019","0.19656"
"102.07800","8.50668","0.19861"
"102.39600","8.53316","0.19984"
"102.71400","8.55965","0.20179"
"103.03200","8.58626","0.20400"
"103.35000","8.61268","0.20644"
"103.66800","8.63917","0.21032"
"103.98600","8.66566","0.21231"
"104.30400","8.69214","0.21629"
"104.62200","8.71869","0.21376"
"104.94000","8.74506","0.21043"
"105.25800","8.77166","0.21391"
"105.57600","8.79815","0.21823"
"105.89400","8.82464","0.22090"
"106.21200","8.85118","0.22417"
"106.53000","8.87761","0.22504"
"106.84800","8.90422","0.22766"
"107.16600","8.93064","0.23092"
"107.48400","8.95719","0.23127"
"107.80200","8.98368","0.23327"
"108.12000","9.01010","0.23526"
"108.43800","9.03671","0.23711"
"108.75600","9.06320","0.23891"
"109.07400","9.08968","0.24037"
"109.39200","9.11617","0.24149"
"109.71000","9.14266","0.24315"
"110.02800","9.16920","0.24417"
"110.34600","9.19569","0.24539"
"110.66400","9.22218","0.24540"
"110.98200","9.24866","0.24695"
"111.30000","9.27515","0.24708"
"111.61800","9.30170","0.24811"
"111.93600","9.32812","0.24881"
"112.25400","9.35467","0.24975"
"112.57200","9.38116","0.25014"
"112.89000","9.40764","0.25143"
"113.20800","9.43419","0.25208"
"113.52600","9.46062","0.25250"
"113.84400","9.48722","0.25302"
"114.16200","9.51365","0.25435"
"114.48000","9.54014","0.25549"
"114.79800","9.56668","0.25675"
"115.11600","9.59311","0.25788"
"115.43400","9.61972","0.26003"
"115.75200","9.64614","0.26148"
"116.07000","9.67269","0.26261"
"116.38800","9.69924","0.26540"
"116.70600","9.72561","0.26648"
"117.02400","9.75221","0.27019"
"117.34200","9.77864","0.27320"
"117.66000","9.80518","0.27602"
"117.97800","9.83167","0.27846"
"118.29600","9.85816","0.28077"
"118.61400","9.88470","0.28305"
"118.93200","9.91113","0.28555"
"119.25000","9.93768","0.29012"
"119.56800","9.96417","0.29431"
"119.88600","9.99059","0.29726"
"120.20400","10.01720","0.29944"
"120.52200","10.04363","0.30143"
"120.84000","10.07017","0.30328"
"121.15800","10.09666","0.30618"
"121.47600","10.12321","0.30765"
"121.79400","10.14969","0.30933"
"122.11200","10.17612","0.29129"
"122.43000","10.20272","0.29410"
"122.74800","10.22915","0.29646"
"123.06600","10.25564","0.29885"
"123.38400","10.28224","0.30268"
"123.70200","10.30867","0.30536"
"124.02000","10.33522","0.30710"
"124.33800","10.36165","0.30922"
"124.65600","10.38819","0.31086"
"124.97400","10.41468","0.31216"
"125.29200","10.44116","0.31396"
"125.61000","10.46771","0.31583"
"125.92800","10.49408","0.31784"
"126.24600","10.52069","0.31975"
"126.56400","10.54717","0.32270"
"126.88200","10.57366","0.32420"
"127.20000","10.60021","0.32760"
"127.51800","10.62657","0.32899"
"127.83600","10.65318","0.33065"
"128.15401","10.67967","0.33298"
"128.47200","10.70609","0.33483"
"128.78999","10.73270","0.33672"
"129.10800","10.75913","0.33833"
"129.42599","10.78573","0.34028"
"129.74400","10.81216","0.34163"
"130.06200","10.83871","0.34302"
"130.38000","10.86519","0.34440"
"130.69800","10.89162","0.34571"
"131.01601","10.91823","0.34804"
"131.33400","10.94465","0.34973"
"131.65199","10.97114","0.35228"
"131.97000","10.99769","0.35463"
"132.28799","11.02417","0.35776"
"132.60600","11.05066","0.35968"
"132.92400","11.07715","0.36061"
"133.24200","11.10369","0.36312"
"133.56000","11.13018","0.36583"
"133.87801","11.15667","0.36833"
"134.19600","11.18321","0.37310"
"134.51401","11.20964","0.37696"
"134.83200","11.23613","0.38043"
"135.14999","11.26267","0.38371"
"135.46800","11.28922","0.38547"
"135.78600","11.31571","0.36270"
"136.10400","11.34213","0.36271"
"136.42200","11.36868","0.36423"
"136.74001","11.39517","0.36573"
"137.05800","11.42171","0.36851"
"137.37601","11.44820","0.37057"
"137.69400","11.47463","0.37276"
"138.01199","11.50117","0.37517"
"138.33000","11.52766","0.37828"
"138.64799","11.55421","0.38112"
"138.96600","11.58069","0.38450"
"139.28400","11.60712","0.38612"
"139.60201","11.63373","0.38818"
"139.92000","11.66016","0.39044"
"140.23801","11.68670","0.39271"
"140.55600","11.71313","0.39469"
"140.87399","11.73961","0.39165"
"141.19200","11.76622","0.39452"
"141.50999","11.79265","0.39672"
"141.82800","11.81919","0.39913"
"142.14600","11.84568","0.40153"
"142.46400","11.87217","0.40401"
"142.78200","11.89872","0.40745"
"143.10001","11.92514","0.40965"
"143.41800","11.95163","0.41251"
"143.73599","11.97818","0.41536"
"144.05400","12.00472","0.41856"
"144.37199","12.03121","0.42269"
"144.69000","12.05764","0.42582"
"145.00800","12.08418","0.43343"
"145.32600","12.11067","0.43768"
"145.64400","12.13721","0.44140"
"145.96201","12.16376","0.44409"
"146.28000","12.19019","0.44607"
"146.59801","12.21667","0.44776"
"146.91600","12.24316","0.44953"
"147.23399","12.26971","0.45112"
"147.55200","12.29620","0.45247"
"147.87000","12.32268","0.45359"
"148.18800","12.34923","0.45664"
"148.50600","12.37566","0.45881"
"148.82401","12.40220","0.46053"
"149.14200","12.42869","0.46278"
"149.46001","12.45518","0.46455"
"149.77800","12.48166","0.42250"
"150.09599","12.50815","0.42202"
"150.41400","12.53470","0.42691"
"150.73199","12.56118","0.43099"
"151.05000","12.58767","0.43743"
"151.36800","12.61422","0.44055"
"151.68600","12.64070","0.44446"
"152.00400","12.66719","0.44777"
"152.32201","12.69368","0.45015"
"152.64000","12.72016","0.45187"
"152.95799","12.74671","0.45317"
"153.27600","12.77314","0.45516"
"153.59399","12.79968","0.45673"
"153.91200","12.82611","0.45857"
"154.23000","12.85272","0.34974"
"154.54800","12.87926","0.34763"
"154.86600","12.90563","0.35036"
"155.18401","12.93218","0.35451"
"155.50200","12.95860","0.35696"
"155.82001","12.98521","0.36219"
"156.13800","13.01170","0.36393"
"156.45599","13.03818","0.36829"
"156.77400","13.06473","0.37135"
"157.09200","13.09116","0.37799"
"157.41000","13.11770","0.37948"
"157.72800","13.14413","0.38423"
"158.04601","13.17068","0.38575"
"158.36400","13.19716","0.38907"
"158.68201","13.22365","0.39081"
"159.00000","13.25020","0.39381"
"159.31799","13.27663","0.39487"
"159.63600","13.30317","0.39766"
"159.95399","13.32966","0.39879"
"160.27200","13.35614","0.40375"
"160.59000","13.38269","0.40682"
"160.90800","13.40918","0.41234"
"161.22600","13.43573","0.41544"
"161.54401","13.46215","0.41990"
"161.86200","13.48870","0.42153"
"162.17999","13.51519","0.42504"
"162.49800","13.54161","0.42966"
"162.81599","13.56816","0.43411"
"163.13400","13.59471","0.43880"
"163.45200","13.62119","0.44126"
"163.77000","13.64768","0.44350"
"164.08800","13.67411","0.44480"
"164.40601","13.70071","0.44737"
"164.72400","13.72720","0.44923"
"165.04201","13.75369","0.45075"
"165.36000","13.78023","0.45226"
"165.67799","13.80660","0.45317"
"165.99600","13.83321","0.45401"
"166.31400","13.85969","0.45568"
"166.63200","13.88618","0.45704"
"166.95000","13.91273","0.45932"
"167.26801","13.93915","0.46085"
"167.58600","13.96576","0.46272"
"167.90401","13.99219","0.46451"
"168.22200","14.01873","0.46627"
"168.53999","14.04516","0.46917"
"168.85800","14.07165","0.47160"
"169.17599","14.09819","0.47428"
"169.49400","14.12468","0.47971"
"169.81200","14.15123","0.48360"
"170.13000","14.17771","0.48688"
"170.44800","14.20414","0.48941"
"170.76601","14.23069","0.49373"
"171.08400","14.25717","0.49703"
"171.40199","14.28366","0.48477"
"171.72000","14.31021","0.42487"
"172.03799","14.33669","0.42034"
"172.35600","14.36324","0.41902"
"172.67400","14.38961","0.41780"
"172.99200","14.41621","0.41911"
"173.31000","14.44264","0.42276"
"173.62801","14.46919","0.39631"
"173.94600","14.49573","0.39661"
"174.26401","14.52216","0.39685"
"174.58200","14.54871","0.39829"
"174.89999","14.57513","0.40062"
"175.21800","14.60174","0.40340"
"175.53600","14.62817","0.40753"
"175.85400","14.65465","0.41022"
"176.17200","14.68114","0.41428"
"176.49001","14.70763","0.41754"
"176.80800","14.73417","0.42073"
"177.12601","14.76066","0.42453"
"177.44400","14.78715","0.42797"
"177.76199","14.81369","0.43146"
"178.08000","14.84012","0.43486"
"178.39799","14.86673","0.43850"
"178.71600","14.89315","0.44085"
"179.03400","14.91964","0.44341"
"179.35201","14.94619","0.44644"
"179.67000","14.97268","0.44860"
"179.98801","14.99922","0.45040"
"180.30600","15.02565","0.45177"
"180.62399","15.05219","0.45325"
"180.94200","15.07874","0.45431"
"181.25999","15.10517","0.45591"
"181.57800","15.13171","0.45738"
"181.89600","15.15808","0.45967"
"182.21400","15.18469","0.46067"
"182.53200","15.21124","0.46221"
"182.85001","15.23766","0.46358"
"183.16800","15.26421","0.46512"
"183.48599","15.29058","0.46700"
"183.80400","15.31724","0.47037"
"184.12199","15.34373","0.47213"
"184.44000","15.37016","0.47433"
"184.75800","15.39664","0.47821"
"185.07600","15.42313","0.48018"
"185.39400","15.44967","0.48451"
"185.71201","15.47616","0.48835"
"186.03000","15.50271","0.49043"
"186.34801","15.52919","0.49143"
"186.66600","15.55568","0.49477"
"186.98399","15.58223","0.49950"
"187.30200","15.60865","0.50243"
"187.62000","15.63514","0.50450"
"187.93800","15.66163","0.50581"
"188.25600","15.68818","0.50833"
"188.57401","15.71466","0.50968"
"188.89200","15.74109","0.51233"
"189.21001","15.76770","0.51333"
"189.52800","15.79418","0.51571"
"189.84599","15.82067","0.51811"
"190.16400","15.84722","0.52077"
"190.48199","15.87358","0.52391"
"190.80000","15.90019","0.52676"
"191.11800","15.92668","0.52985"
"191.43600","15.95322","0.53287"
"191.75400","15.97971","0.53529"
"192.07201","16.00608","0.53679"
"192.39000","16.03274","0.53827"
"192.70799","16.05917","0.54031"
"193.02600","16.08572","0.54150"
"193.34399","16.11220","0.54303"
"193.66200","16.13863","0.54474"
"193.98000","16.16518","0.54617"
"194.29800","16.19166","0.54758"
"194.61600","16.21815","0.54904"
"194.93401","16.24470","0.55022"
"195.25200","16.27118","0.55081"
"195.57001","16.29773","0.55266"
"195.88800","16.32416","0.55310"
"196.20599","16.35064","0.55423"
"196.52400","16.37713","0.55524"
"196.84200","16.40362","0.55635"
"197.16000","16.43022","0.55766"
"197.47800","16.45665","0.55885"
"197.79601","16.48320","0.56055"
"198.11400","16.50968","0.56198"
"198.43201","16.53617","0.56388"
"198.75000","16.56266","0.56637"
"199.06799","16.58914","0.56849"
"199.38600","16.61569","0.57158"
"199.70399","16.64218","0.57440"
"200.02200","16.66872","0.57736"
"200.34000","16.69527","0.57524"
"200.65800","16.72164","0.57814"
"200.97600","16.74818","0.57978"
"201.29401","16.77467","0.58407"
"201.61200","16.80122","0.53523"
"201.92999","16.82770","0.50976"
"202.24800","16.85419","0.51028"
"202.56599","16.88068","0.51055"
"202.88400","16.90710","0.51062"
"203.20200","16.93371","0.50615"
"203.52000","16.96020","0.31880"
"203.83800","16.98668","0.31916"
"204.15601","17.01317","0.31882"
"204.47400","17.03966","0.31937"
"204.79201","17.06614","0.32076"
"205.11000","17.09263","0.32138"
"205.42799","17.11918","0.32265"
"205.74600","17.14573","0.32333"
"206.06400","17.17209","0.32493"
"206.38200","17.19870","0.32634"
"206.70000","17.22519","0.32765"
"207.01801","17.25167","0.32820"
"207.33600","17.27822","0.32944"
"207.65401","17.30465","0.33066"
"207.97200","17.33119","0.33240"
"208.28999","17.35762","0.33470"
"208.60800","17.38417","0.33695"
"208.92599","17.41071","0.33934"
"209.24400","17.43708","0.34139"
"209.56200","17.46369","0.34375"
"209.88000","17.49011","0.34633"
"210.19800","17.51672","0.34933"
"210.51601","17.54321","0.35200"
"210.83400","17.56969","0.35429"
"211.15199","17.59612","0.35622"
"211.47000","17.62255","0.35830"
"211.78799","17.64921","0.36017"
"212.10600","17.67570","0.36313"
"212.42400","17.70219","0.36464"
"212.74200","17.72867","0.36770"
"213.06000","17.75516","0.37135"
"213.37801","17.78171","0.37509"
"213.69600","17.80813","0.37938"
"214.01401","17.83468","0.38221"
"214.33200","17.86117","0.38450"
"214.64999","17.88759","0.38582"
"214.96800","17.91426","0.38742"
"215.28600","17.94069","0.38898"
"215.60400","17.96717","0.39042"
"215.92200","17.99372","0.14247"
"216.24001","18.02021","0.11623"
"216.55800","18.04675","0.10586"
"216.87601","18.07312","0.10880"
"217.19400","18.09967","0.12390"
"217.51199","18.12615","0.13749"
"217.83000","18.15264","0.12764"
"218.14799","18.17919","0.12358"
"218.46600","18.20568","0.12535"
"218.78400","18.23222","0.13507"
"219.10201","18.25871","0.14303"
"219.42000","18.28519","0.13928"
"219.73801","18.31168","0.13586"
"220.05600","18.33805","0.13658"
"220.37399","18.36465","0.13973"
"220.69200","18.39114","0.14817"
"221.00999","18.41769","0.15162"
"221.32800","18.44418","0.14627"
"221.64600","18.47066","0.14458"
"221.96400","18.49721","0.14623"
"222.28200","18.52364","0.15104"
"222.60001","18.55018","0.15897"
"222.91800","18.57673","0.16393"
"223.23599","18.60316","0.16139"
"223.55400","18.62970","0.15864"
"223.87199","18.65619","0.15989"
"224.19000","18.68261","0.16295"
"224.50800","18.70916","0.16849"
"224.82600","18.73565","0.17054"
"225.14400","18.76225","0.17602"
"225.46201","18.78862","0.17528"
"225.78000","18.81517","0.17473"
"226.09801","18.84166","0.17474"
"226.41600","18.86814","0.17722"
"226.73399","18.89469","0.18046"
"227.05200","18.92111","0.18552"
"227.37000","18.94772","0.16951"
"227.68800","18.97415","0.17187"
"228.00600","19.00070","0.17265"
"228.32401","19.02718","0.17347"
"228.64200","19.05361","0.17543"
"228.96001","19.08015","0.17851"
"229.27800","19.10664","0.18266"
"229.59599","19.13319","0.18772"
"229.91400","19.15968","0.19136"
"230.23199","19.18616","0.19410"
"230.55000","19.21265","0.19544"
"230.86800","19.23920","0.19708"
"231.18600","19.26568","0.20003"
"231.50400","19.29223","0.20241"
"231.82201","19.31860","0.20683"
"232.14000","19.34520","0.21127"
"232.45799","19.37163","0.21781"
"232.77600","19.39817","0.22291"
"233.09399","19.42466","0.22675"
"233.41200","19.45121","0.22970"
"233.73000","19.47770","0.23240"
"234.04800","19.50412","0.23370"
"234.36600","19.53067","0.23588"
"234.68401","19.55716","0.23804"
"235.00200","19.58364","0.24033"
"235.32001","19.61025","0.24225"
"235.63800","19.63667","0.24435"
"235.95599","19.66322","0.24633"
"236.27400","19.68965","0.24799"
"236.59200","19.71619","0.24954"
"236.91000","19.74274","0.25038"
"237.22800","19.76911","0.25171"
"237.54601","19.79565","0.25288"
"237.86400","19.82214","0.25372"
"238.18201","19.84869","0.25503"
"238.50000","19.87518","0.25674"
"238.81799","19.90166","0.25778"
"239.13600","19.92815","0.25964"
"239.45399","19.95457","0.25814"
"239.77200","19.98118","0.26010"
"240.09000","20.00767","0.26281"
"240.40800","20.03416","0.26734"
"240.72600","20.06064","0.27115"
"241.04401","20.08713","0.27528"
"241.36200","20.11368","0.27765"
"241.67999","20.14016","0.28014"
"241.99800","20.16665","0.28285"
"242.31599","20.19326","0.28557"
"242.63400","20.21962","0.28950"
"242.95200","20.24617","0.29261"
"243.27000","20.27260","0.29596"
"243.58800","20.29914","0.29954"
"243.90601","20.32569","0.30188"
"244.22400","20.35217","0.30545"
"244.54201","20.37872","0.30762"
"244.86000","20.40515","0.30975"
"245.17799","20.43170","0.31052"
"245.49600","20.45818","0.30449"
"245.81400","20.48467","0.30627"
"246.13200","20.51122","0.30791"
"246.45000","20.53765","0.30993"
"246.76801","20.56419","0.31174"
"247.08600","20.59068","0.31393"
"247.40401","20.61716","0.31656"
"247.72200","20.64365","0.31885"
"248.03999","20.67014","0.32052"
"248.35800","20.69674","0.32235"
"248.67599","20.72323","0.32452"
"248.99400","20.74966","0.32581"
"249.31200","20.77621","0.32816"
"249.63000","20.80263","0.33058"
"249.94800","20.82918","0.33217"
"250.26601","20.85561","0.33367"
"250.58400","20.88215","0.33553"
"250.90199","20.90870","0.33581"
"251.22000","20.93513","0.33720"
"251.53799","20.96173","0.33870"
"251.85600","20.98816","0.33984"
"252.17400","21.01464","0.34091"
"252.49200","21.04113","0.34184"
"252.81000","21.06762","0.34282"
"253.12801","21.09422","0.34429"
"253.44600","21.12065","0.34564"
"253.76401","21.14720","0.34714"
"254.08200","21.17369","0.34921"
"254.39999","21.20017","0.35136"
"254.71800","21.22672","0.35362"
"255.03600","21.25315","0.35552"
"255.35400","21.27969","0.35825"
"255.67200","21.30618","0.36009"
"255.99001","21.33273","0.35824"
"256.30801","21.35921","0.36142"
"256.62601","21.38564","0.36426"
"256.94400","21.41219","0.36760"
"257.26199","21.43867","0.37080"
"257.57999","21.46516","0.37428"
"257.89801","21.49170","0.37744"
"258.21600","21.51813","0.38008"
"258.53400","21.54468","0.38218"
"258.85199","21.57117","0.38441"
"259.17001","21.59771","0.38598"
"259.48801","21.62420","0.38777"
"259.80600","21.65063","0.39002"
"260.12399","21.67723","0.39190"
"260.44199","21.70366","0.39358"
"260.76001","21.73015","0.39638"
"261.07800","21.75669","0.39760"
"261.39600","21.78318","0.40125"
"261.71399","21.80973","0.40360"
"262.03201","21.83615","0.40589"
"262.35001","21.86276","0.40795"
"262.66800","21.88913","0.41024"
"262.98599","21.91567","0.41228"
"263.30399","21.94222","0.41461"
"263.62201","21.96865","0.41683"
"263.94000","21.99519","0.41947"
"264.25800","22.02162","0.42267"
"264.57599","22.04817","0.42573"
"264.89401","22.07471","0.42949"
"265.21201","22.10114","0.43252"
"265.53000","22.12769","0.40595"
"265.84799","22.15412","0.39100"
"266.16599","22.18072","0.39243"
"266.48401","22.20721","0.39380"
"266.80200","22.23369","0.39533"
"267.12000","22.26018","0.39747"
"267.43799","22.28661","0.39923"
"267.75601","22.31322","0.40190"
"268.07401","22.33970","0.40390"
"268.39200","22.36613","0.40627"
"268.70999","22.39268","0.40815"
"269.02802","22.41910","0.41074"
"269.34601","22.44571","0.41272"
"269.66400","22.47214","0.41601"
"269.98199","22.49862","0.41907"
"270.29999","22.52517","0.42146"
"270.61801","22.55165","0.42551"
"270.93600","22.57820","0.42884"
"271.25400","22.60469","0.43165"
"271.57199","22.63118","0.43438"
"271.89001","22.65772","0.43806"
"272.20801","22.68415","0.44000"
"272.52600","22.71069","0.44004"
"272.84399","22.73712","0.44270"
"273.16199","22.76361","0.44463"
"273.48001","22.79015","0.44558"
"273.79800","22.81664","0.44744"
"274.11600","22.84319","0.44867"
"274.43399","22.86962","0.45029"
"274.75201","22.89622","0.44484"
"275.07001","22.92271","0.44750"
"275.38800","22.94914","0.44874"
"275.70599","22.97568","0.45076"
"276.02399","23.00205","0.45203"
"276.34201","23.02872","0.45214"
"276.66000","23.05520","0.45323"
"276.97800","23.08169","0.45460"
"277.29599","23.10824","0.45647"
"277.61401","23.13466","0.45764"
"277.93201","23.16121","0.45907"
"278.25000","23.18770","0.46141"
"278.56799","23.21418","0.46283"
"278.88599","23.24067","0.46450"
"279.20401","23.26716","0.46602"
"279.52200","23.29376","0.46783"
"279.84000","23.32019","0.47016"
"280.15799","23.34668","0.47204"
"280.47601","23.37316","0.47507"
"280.79401","23.39965","0.47724"
"281.11200","23.42620","0.48002"
"281.42999","23.45262","0.48356"
"281.74799","23.47917","0.48482"
"282.06601","23.50566","0.48794"
"282.38400","23.53214","0.48998"
"282.70200","23.55869","0.49185"
"283.01999","23.58518","0.49376"
"283.33801","23.61166","0.49550"
"283.65601","23.63815","0.49849"
"283.97400","23.66470","0.50140"
"284.29199","23.69118","0.50457"
"284.60999","23.71761","0.50663"
"284.92801","23.74422","0.50953"
"285.24600","23.77065","0.51198"
"285.56400","23.79725","0.51474"
"285.88199","23.82368","0.51538"
"286.20001","23.85016","0.51704"
"286.51801","23.87671","0.52021"
"286.83600","23.90314","0.52296"
"287.15399","23.92974","0.52488"
"287.47198","23.95617","0.52755"
"287.79001","23.98260","0.53026"
"288.10800","24.00914","0.53190"
"288.42599","24.03563","0.53403"
"288.74399","24.06218","0.53629"
"289.06201","24.08867","0.53770"
"289.38000","24.11515","0.53885"
"289.69800","24.14176","0.53927"
"290.01599","24.16818","0.54151"
"290.33401","24.19467","0.54295"
"290.65201","24.22116","0.54411"
"290.97000","24.24764","0.54559"
"291.28799","24.27425","0.54684"
"291.60599","24.30062","0.54799"
"291.92401","24.32723","0.54936"
"292.24200","24.35365","0.55094"
"292.56000","24.38020","0.55254"
"292.87799","24.40674","0.55434"
"293.19601","24.43311","0.55594"
"293.51401","24.45966","0.55703"
"293.83200","24.48609","0.55830"
"294.14999","24.51269","0.55967"
"294.46799","24.53918","0.56120"
"294.78601","24.56566","0.56369"
"295.10400","24.59215","0.56594"
"295.42200","24.61864","0.56841"
"295.73999","24.64519","0.57052"
"296.05801","24.67173","0.57090"
"296.37601","24.69816","0.57232"
"296.69400","24.72465","0.57266"
"297.01199","24.75113","0.57685"
"297.32999","24.77774","0.57977"
"297.64801","24.80416","0.58241"
"297.96600","24.83065","0.58543"
"298.28400","24.85720","0.58840"
"298.60199","24.88369","0.59093"
"298.92001","24.91023","0.59280"
"299.23801","24.93666","0.59512"
"299.55600","24.96315","0.59727"
"299.87399","24.98969","0.60117"
"300.19199","25.01624","0.60383"
"300.51001","25.04273","0.60636"
"300.82800","25.06915","0.60956"
"301.14600","25.09564","0.61229"
"301.46399","25.12225","0.61448"
"301.78201","25.14861","0.61710"
"302.10001","25.17516","0.61931"
"302.41800","25.20159","0.62078"
"302.73599","25.22820","0.62353"
"303.05399","25.25468","0.62584"
"303.37201","25.28117","0.62911"
"303.69000","25.30771","0.63170"
"304.00800","25.33408","0.63431"
"304.32599","25.36075","0.63685"
"304.64401","25.38717","0.63948"
"304.96201","25.41366","0.64227"
"305.28000","25.44015","0.64486"
"305.59799","25.46663","0.64667"
"305.91599","25.49318","0.64861"
"306.23401","25.51967","0.65055"
"306.55200","25.54622","0.65205"
"306.87000","25.57270","0.65352"
"307.18799","25.59913","0.65498"
"307.50601","25.62568","0.65620"
"307.82401","25.65216","0.65732"
"308.14200","25.67865","0.65881"
"308.45999","25.70514","0.65942"
"308.77802","25.73162","0.66150"
"309.09601","25.75823","0.66335"
"309.41400","25.78460","0.66472"
"309.73199","25.81120","0.66661"
"310.04999","25.83769","0.66813"
"310.36801","25.86418","0.66763"
"310.68600","25.89072","0.66529"
"311.00400","25.91715","0.65500"
"311.32199","25.94370","0.65640"
"311.64001","25.97018","0.65738"
"311.95801","25.99673","0.65901"
"312.27600","26.02322","0.66036"
"312.59399","26.04964","0.65849"
"312.91199","26.07625","0.65950"
"313.23001","26.10268","0.66094"
"313.54800","26.12916","0.66219"
"313.86600","26.15565","0.66363"
"314.18399","26.18214","0.66490"
"314.50201","26.20868","0.66621"
"314.82001","26.23511","0.66749"
"315.13800","26.26171","0.66934"
"315.45599","26.28820","0.67133"
"315.77399","26.31463","0.67303"
"316.09201","26.34124","0.67518"
"316.41000","26.36761","0.67779"
"316.72800","26.39415","0.68050"
"317.04599","26.42070","0.67987"
"317.36401","26.44712","0.67981"
"317.68201","26.47373","0.68227"
"318.00000","26.50016","0.60571"
"318.31799","26.52670","0.60762"
"318.63599","26.55319","0.60767"
"318.95401","26.57968","0.61148"
"319.27200","26.60622","0.61329"
"319.59000","26.63265","0.61754"
"319.90799","26.65920","0.62264"
"320.22601","26.68568","0.62515"
"320.54401","26.71217","0.63089"
"320.86200","26.73872","0.63767"
"321.17999","26.76508","0.64121"
"321.49799","26.79169","0.64495"
"321.81601","26.81812","0.64919"
"322.13400","26.84467","0.65191"
"322.45200","26.87121","0.65373"
"322.76999","26.89764","0.65494"
"323.08801","26.92418","0.65629"
"323.40601","26.95061","0.64207"
"323.72400","26.97722","0.62628"
"324.04199","27.00371","0.63040"
"324.35999","27.03019","0.63621"
"324.67801","27.05662","0.64035"
"324.99600","27.08317","0.64410"
"325.31400","27.10971","0.64633"
"325.63199","27.13620","0.64924"
"325.95001","27.16262","0.65213"
"326.26801","27.18917","0.65369"
"326.58600","27.21560","0.65530"
"326.90399","27.24221","0.65726"
"327.22198","27.26869","0.65900"
"327.54001","27.29518","0.65995"
"327.85800","27.32173","0.66210"
"328.17599","27.34815","0.66385"
"328.49399","27.37470","0.66540"
"328.81201","27.40112","0.66666"
"329.13000","27.42767","0.66919"
"329.44800","27.45416","0.67153"
"329.76599","27.48071","0.67344"
"330.08401","27.50719","0.67544"
"330.40201","27.53362","0.66574"
"330.72000","27.56016","0.66804"
"331.03799","27.58671","0.66891"
"331.35599","27.61320","0.67146"
"331.67401","27.63969","0.67420"
"331.99200","27.66605","0.67532"
"332.31000","27.69272","0.67742"
"332.62799","27.71921","0.67983"
"332.94601","27.74563","0.68239"
"333.26401","27.77218","0.68494"
"333.58200","27.79867","0.68788"
"333.89999","27.82521","0.69006"
"334.21799","27.85164","0.69334"
"334.53601","27.87813","0.69539"
"334.85400","27.90467","0.69773"
"335.17200","27.93110","0.70044"
"335.48999","27.95771","0.70284"
"335.80801","27.98413","0.70434"
"336.12601","28.01068","0.70589"
"336.44400","28.03717","0.70685"
"336.76199","28.06365","0.70902"
"337.07999","28.09020","0.71112"
"337.39801","28.11663","0.71326"
"337.71600","28.14317","0.71564"
"338.03400","28.16966","0.71632"
"338.35199","28.19614","0.71863"
"338.67001","28.22269","0.72141"
"338.98801","28.24912","0.72307"
"339.30600","28.27573","0.72583"
"339.62399","28.30221","0.72739"
"339.94199","28.32870","0.72943"
"340.26001","28.35519","0.72998"
"340.57800","28.38161","0.73190"
"340.89600","28.40822","0.73466"
"341.21399","28.43465","0.73480"
"341.53201","28.46126","0.72146"
"341.85001","28.48768","0.72269"
"342.16800","28.51417","0.72422"
"342.48599","28.54065","0.72700"
"342.80399","28.56720","0.72889"
"343.12201","28.59369","0.73179"
"343.44000","28.62023","0.73414"
"343.75800","28.64666","0.73622"
"344.07599","28.67321","0.60560"
"344.39401","28.69963","0.56856"
"344.71201","28.72618","0.56753"
"345.03000","28.75267","0.57245"
"345.34799","28.77915","0.57489"
"345.66599","28.80576","0.57775"
"345.98401","28.83213","0.58225"
"346.30200","28.85867","0.58719"
"346.62000","28.88516","0.59244"
"346.93799","28.91165","0.59393"
"347.25601","28.93813","0.59705"
"347.57401","28.96462","0.60044"
"347.89200","28.99117","0.60413"
"348.20999","29.01765","0.60618"
"348.52802","29.04420","0.60850"
"348.84601","29.07069","0.61184"
"349.16400","29.09712","0.61505"
"349.48199","29.12366","0.61722"
"349.79999","29.15009","0.61930"
"350.11801","29.17669","0.62116"
"350.43600","29.20324","0.62290"
"350.75400","29.22967","0.62601"
"351.07199","29.25621","0.62676"
"351.39001","29.28264","0.62748"
"351.70801","29.30925","0.62989"
"352.02600","29.33567","0.63176"
"352.34399","29.36216","0.63276"
"352.66199","29.38865","0.63389"
"352.98001","29.41513","0.63547"
"353.29800","29.44168","0.63716"
"353.61600","29.46817","0.63761"
"353.93399","29.49465","0.63875"
"354.25201","29.52120","0.64062"
"354.57001","29.54763","0.64169"
"354.88800","29.57418","0.64207"
"355.20599","29.60066","0.64302"
"355.52399","29.62709","0.64420"
"355.84201","29.65369","0.64464"
"356.16000","29.68012","0.64470"
"356.47800","29.70673","0.64572"
"356.79599","29.73315","0.64712"
"357.11401","29.75964","0.64768"
"357.43201","29.78619","0.64879"
"357.75000","29.81261","0.64920"
"358.06799","29.83916","0.65019"
"358.38599","29.86559","0.65123"
"358.70401","29.89219","0.65205"
"359.02200","29.91868","0.65311"
"359.34000","29.94517","0.65398"
"359.65799","29.97165","0.65472"
"359.97601","29.99809","0.65544"
"360.29401","30.02469","0.65624"
"360.61200","30.05112","0.65642"
"360.92999","30.07766","0.65688"
"361.24799","30.10421","0.65753"
"361.56601","30.13064","0.65810"
"361.88400","30.15718","0.65866"
"362.20200","30.18367","0.65874"
"362.51999","30.21022","0.65975"
"362.83801","30.23670","0.66044"
"363.15601","30.26319","0.66144"
"363.47400","30.28974","0.66182"
"363.79199","30.31616","0.66228"
"364.10999","30.34265","0.66320"
"364.42801","30.36920","0.66408"
"364.74600","30.39562","0.66519"
"365.06400","30.42223","0.66634"
"365.38199","30.44866","0.66666"
"365.70001","30.47520","0.66748"
"366.01801","30.50169","0.66893"
"366.33600","30.52818","0.66942"
"366.65399","30.55472","0.67063"
"366.97198","30.58115","0.67159"
"367.29001","30.60770","0.67238"
"367.60800","30.63418","0.67372"
"367.92599","30.66067","0.67558"
"368.24399","30.68722","0.67740"
"368.56201","30.71364","0.67863"
"368.88000","30.74013","0.68007"
"369.19800","30.76668","0.68159"
"369.51599","30.79322","0.68378"
"369.83401","30.81971","0.68530"
"370.15201","30.84608","0.68676"
"370.47000","30.87268","0.68754"
"370.78799","30.89917","0.68952"
"371.10599","30.92572","0.69071"
"371.42401","30.95221","0.69244"
"371.74200","30.97869","0.69335"
"372.06000","31.00524","0.69464"
"372.37799","31.03167","0.69694"
"372.69601","31.05815","0.69825"
"373.01401","31.08464","0.69923"
"373.33200","31.11113","0.69988"
"373.64999","31.13773","0.70215"
"373.96799","31.16416","0.70300"
"374.28601","31.19070","0.70460"
"374.60400","31.21713","0.70639"
"374.92200","31.24368","0.70785"
"375.23999","31.27023","0.70893"
"375.55801","31.29659","0.71167"
"375.87601","31.32320","0.71339"
"376.19400","31.34962","0.71496"
"376.51199","31.37623","0.71697"
"376.82999","31.40272","0.71748"
"377.14801","31.42915","0.71826"
"377.46600","31.45569","0.72051"
"377.78400","31.48218","0.72153"
"378.10199","31.50872","0.72288"
"378.42001","31.53521","0.72469"
"378.73801","31.56164","0.72657"
"379.05600","31.58819","0.72814"
"379.37399","31.61461","0.73041"
"379.69199","31.64122","0.58614"
"380.01001","31.66771","0.57894"
"380.32800","31.69413","0.57614"
"380.64600","31.72068","0.58907"
"380.96399","31.74717","0.58173"
"381.28201","31.77371","0.58758"
"381.60001","31.80014","0.59701"
"381.91800","31.82663","0.59285"
"382.23599","31.85323","0.56563"
"382.55399","31.87966","0.57444"
"382.87201","31.90621","0.57732"
"383.19000","31.93263","0.52073"
"383.50800","31.95918","0.52165"
"383.82599","31.98573","0.52112"
"384.14401","32.01221","0.52150"
"384.46201","32.03870","0.52587"
"384.78000","32.06513","0.53484"
"385.09799","32.09167","0.53953"
"385.41599","32.11822","0.54234"
"385.73401","32.14465","0.54448"
"386.05200","32.17113","0.54522"
"386.37000","32.19762","0.54516"
"386.68799","32.22417","0.54701"
"387.00601","32.25071","0.54956"
"387.32401","32.27714","0.55259"
"387.64200","32.30369","0.55444"
"387.95999","32.33012","0.55427"
"388.27802","32.35672","0.55470"
"388.59601","32.38321","0.55540"
"388.91400","32.40969","0.55828"
"389.23199","32.43618","0.56222"
"389.54999","32.46267","0.56522"
"389.86801","32.48927","0.56559"
"390.18600","32.51570","0.56543"
"390.50400","32.54219","0.56656"
"390.82199","32.56868","0.57055"
"391.14001","32.59516","0.57559"
"391.45801","32.62171","0.57844"
"391.77600","32.64814","0.57934"
"392.09399","32.67468","0.58027"
"392.41199","32.70123","0.58247"
"392.73001","32.72765","0.58563"
"393.04800","32.75420","0.58965"
"393.36600","32.78063","0.59072"
"393.68399","32.80717","0.59045"
"394.00201","32.83366","0.59188"
"394.32001","32.86021","0.59370"
"394.63800","32.88670","0.59603"
"394.95599","32.91312","0.59774"
"395.27399","32.93973","0.59843"
"395.59201","32.96622","0.59829"
"395.91000","32.99270","0.60044"
"396.22800","33.01919","0.60162"
"396.54599","33.04568","0.60346"
"396.86401","33.07222","0.60431"
"397.18201","33.09871","0.60379"
"397.50000","33.12519","0.60393"
"397.81799","33.15168","0.60547"
"398.13599","33.17811","0.60725"
"398.45401","33.20472","0.60811"
"398.77200","33.23114","0.60918"
"399.09000","33.25769","0.61002"
"399.40799","33.28418","0.61199"
"399.72601","33.31066","0.61330"
"400.04401","33.33721","0.61473"
"400.36200","33.36364","0.61614"
"400.67999","33.39018","0.61664"
"400.99799","33.41667","0.61748"
"401.31601","33.44316","0.61985"
"401.63400","33.46970","0.62225"
"401.95200","33.49619","0.62267"
"402.26999","33.52268","0.62358"
"402.58801","33.54916","0.62577"
"402.90601","33.57565","0.62793"
"403.22400","33.60220","0.62973"
"403.54199","33.62868","0.63068"
"403.85999","33.65517","0.63256"
"404.17801","33.68166","0.63372"
"404.49600","33.70820","0.63514"
"404.81400","33.73475","0.63697"
"405.13199","33.76112","0.63862"
"405.45001","33.78766","0.64007"
"405.76801","33.81415","0.64125"
"406.08600","33.84076","0.64278"
"406.40399","33.86724","0.64400"
"406.72198","33.89367","0.64460"
"407.04001","33.92022","0.64570"
"407.35800","33.94664","0.64614"
"407.67599","33.97319","0.64814"
"407.99399","33.99968","0.64858"
"408.31201","34.02617","0.64968"
"408.63000","34.05265","0.65105"
"408.94800","34.07914","0.65204"
"409.26599","34.10574","0.65127"
"409.58401","34.13217","0.65179"
"409.90201","34.15866","0.65226"
"410.22000","34.18520","0.65304"
"410.53799","34.21169","0.65338"
"410.85599","34.23824","0.65403"
"411.17401","34.26466","0.65423"
"411.49200","34.29115","0.65458"
"411.81000","34.31770","0.65511"
"412.12799","34.34418","0.65548"
"412.44601","34.37073","0.65627"
"412.76401","34.39710","0.65650"
"413.08200","34.42371","0.65698"
"413.39999","34.45025","0.65747"
"413.71799","34.47668","0.65814"
"414.03601","34.50317","0.65861"
"414.35400","34.52959","0.65925"
"414.67200","34.55620","0.65963"
"414.98999","34.58274","0.35899"
"415.30801","34.60917","0.35585"
"415.62601","34.63572","0.35685"
"415.94400","34.66209","0.36821"
"416.26199","34.68869","0.38747"
"416.57999","34.71518","0.40257"
"416.89801","34.74166","0.40347"
"417.21600","34.76815","0.39426"
"417.53400","34.79464","0.38714"
"417.85199","34.82119","0.38507"
"418.17001","34.84767","0.38630"
"418.48801","34.87416","0.38841"
"418.80600","34.90065","0.39079"
"419.12399","34.92713","0.39475"
"419.44199","34.95368","0.40339"
"419.76001","34.98017","0.41466"
"420.07800","35.00665","0.42765"
"420.39600","35.03320","0.43389"
"420.71399","35.05969","0.43163"
"421.03201","35.08624","0.42482"
"421.35001","35.11266","0.41853"
"421.66800","35.13915","0.41438"
"421.98599","35.16570","0.41260"
"422.30399","35.19218","0.41122"
"422.62201","35.21873","0.41170"
"422.94000","35.24509","0.41327"
"423.25800","35.27170","0.41564"
"423.57599","35.29819","0.42107"
"423.89401","35.32467","0.42666"
"424.21201","35.35116","0.43421"
"424.53000","35.37758","0.43840"
"424.84799","35.40419","0.44038"
"425.16599","35.43068","0.43986"
"425.48401","35.45723","0.43800"
"425.80200","35.48372","0.43532"
"426.12000","35.51014","0.43328"
"426.43799","35.53669","0.43131"
"426.75601","35.56318","0.43157"
"427.07401","35.58972","0.43145"
"427.39200","35.61621","0.43237"
"427.70999","35.64270","0.43387"
"428.02802","35.66924","0.43644"
"428.34601","35.69567","0.43937"
"428.66400","35.72215","0.44278"
"428.98199","35.74870","0.44642"
"429.29999","35.77512","0.44807"
"429.61801","35.80173","0.44935"
"429.93600","35.82816","0.45024"
"430.25400","35.85471","0.45073"
"430.57199","35.88120","0.45058"
"430.89001","35.90768","0.45139"
"431.20801","35.93423","0.45152"
"431.52600","35.96059","0.44933"
"431.84399","35.98720","0.44910"
"432.16199","36.01363","0.45254"
"432.48001","36.04017","0.45131"
"432.79800","36.06666","0.44945"
"433.11600","36.09315","0.44597"
"433.43399","36.11970","0.44470"
"433.75201","36.14612","0.44679"
"434.07001","36.17273","0.44385"
"434.38800","36.19915","0.45189"
"434.70599","36.22564","0.45311"
"435.02399","36.25219","0.45323"
"435.34201","36.27861","0.45556"
"435.66000","36.30522","0.45398"
"435.97800","36.33165","0.45132"
"436.29599","36.35819","0.45371"
"436.61401","36.38468","0.45518"
"436.93201","36.41111","0.45554"
"437.25000","36.43765","0.45573"
"437.56799","36.46414","0.45691"
"437.88599","36.49063","0.45776"
"438.20401","36.51717","0.45954"
"438.52200","36.54366","0.46023"
"438.84000","36.57021","0.45983"
"439.15799","36.59663","0.45986"
"439.47601","36.62312","0.46107"
"439.79401","36.64973","0.46172"
"440.11200","36.67616","0.46258"
"440.42999","36.70270","0.46290"
"440.74799","36.72907","0.46343"
"441.06601","36.75567","0.46394"
"441.38400","36.78222","0.46517"
"441.70200","36.80865","0.46531"
"442.01999","36.83519","0.46637"
"442.33801","36.86156","0.46696"
"442.65601","36.88823","0.46798"
"442.97400","36.91465","0.46927"
"443.29199","36.94114","0.46960"
"443.60999","36.96769","0.47071"
"443.92801","36.99411","0.47175"
"444.24600","37.02066","0.47321"
"444.56400","37.04721","0.47475"
"444.88199","37.07369","0.47521"
"445.20001","37.10018","0.47616"
"445.51801","37.12661","0.47714"
"445.83600","37.15321","0.47800"
"446.15399","37.17970","0.47987"
"446.47198","37.20613","0.48032"
"446.79001","37.23267","0.48094"
"447.10800","37.25910","0.48069"
"447.42599","37.28571","0.48272"
"447.74399","37.31219","0.48316"
"448.06201","37.33874","0.48405"
"448.38000","37.36517","0.48499"
"448.69800","37.39165","0.48553"
"449.01599","37.41820","0.48662"
"449.33401","37.44463","0.48701"
"449.65201","37.47118","0.48749"
"449.97000","37.49760","0.48861"
"450.28799","37.52415","0.48971"
"450.60599","37.55069","0.49066"
"450.92401","37.57712","0.49163"
"451.24200","37.60373","0.49245"
"451.56000","37.63016","0.49337"
"451.87799","37.65664","0.49506"
"452.19601","37.68319","0.49568"
"452.51401","37.70962","0.49676"
"452.83200","37.73622","0.49678"
"453.14999","37.76271","0.49840"
"453.46799","37.78920","0.49918"
"453.78601","37.81568","0.49929"
"454.10400","37.84211","0.50054"
"454.42200","37.86872","0.50087"
"454.73999","37.89520","0.49862"
"455.05801","37.92169","0.49619"
"455.37601","37.94818","-0.00848"
"455.69400","37.97466","-0.02716"
"456.01199","38.00121","-0.02162"
"456.32999","38.02769","-0.03018"
"456.64801","38.05418","-0.02484"
"456.96600","38.08073","-0.02913"
"457.28400","38.10715","-0.02156"
"457.60199","38.13370","-0.02831"
"457.92001","38.16007","-0.02388"
"458.23801","38.18668","-0.02541"
"458.55600","38.21310","-0.02438"
"458.87399","38.23965","-0.02458"
"459.19199","38.26620","-0.02545"
"459.51001","38.29263","-0.02331"
"459.82800","38.31917","-0.02579"
"460.14600","38.34560","-0.02327"
"460.46399","38.37220","-0.02473"
"460.78201","38.39869","-0.02485"
"461.10001","38.42512","-0.02360"
"461.41800","38.45173","-0.02506"
"461.73801","38.47833","-0.02331"
"462.05600","38.50488","-0.02390"
"462.37399","38.53137","-0.02447"
"462.69199","38.55779","-0.02382"
"463.01001","38.58434","-0.02466"
"463.32800","38.61082","-0.02341"
"463.64600","38.63737","-0.02363"
"463.96399","38.66386","-0.02367"
"464.28201","38.69028","-0.02302"
"464.60001","38.71683","-0.02392"
"464.91800","38.74326","-0.02301"
"465.23599","38.76986","-0.02370"
"465.55399","38.79635","-0.02346"
"465.87201","38.82278","-0.02213"
"466.19000","38.84939","-0.02354"
"466.50800","38.87581","-0.02277"
"466.82599","38.90236","-0.02291"
"467.14401","38.92878","-0.02266"
"467.46201","38.95527","-0.02239"
"467.78000","38.98188","-0.02337"
"468.09799","39.00830","-0.02256"
"468.41599","39.03485","-0.02194"
"468.73401","39.06134","-0.02285"
"469.05200","39.08783","-0.02222"
"469.37000","39.11437","-0.02244"
"469.68799","39.14080","-0.02227"
"470.00601","39.16734","-0.02205"
"470.32401","39.19377","-0.02215"
"470.64200","39.22038","-0.02208"
"470.95999","39.24686","-0.02209"
"471.27802","39.27335","-0.02239"
"471.59601","39.29984","-0.02210"
"471.91400","39.32627","-0.02156"
"472.23199","39.35281","-0.02169"
"472.54999","39.37930","-0.02209"
"472.86801","39.40578","-0.02212"
"473.18600","39.43233","-0.02194"
"473.50400","39.45876","-0.02166"
"473.82199","39.48536","-0.02196"
"474.14001","39.51185","-0.02152"
"474.45801","39.53833","-0.02157"
"474.77600","39.56488","-0.02127"
"475.09399","39.59131","-0.02181"
"475.41199","39.61786","-0.02166"
"475.73001","39.64434","-0.02127"
"476.04800","39.67083","-0.02126"
"476.34399","39.69552","-0.02148"