File: Force_trajectories/170107_2/Specimen_RawData_1.csv
End date,"1/7/2017"
Specimen label,"17DG_39"
Maximum Load,"1.63142",N

Time,Extension,Load
(s),(mm),(N)
"0.00000","0.00000","0.00025"
"0.34200","0.02828","0.00025"
"0.68400","0.05716","0.00059"
"1.02600","0.08562","0.00073"
"1.36800","0.11414","0.00114"
"1.71000","0.14266","0.00120"
"2.05200","0.17106","0.00159"
"2.39400","0.19964","0.00179"
"2.73600","0.22822","0.00154"
"3.07800","0.25656","0.00168"
"3.42000","0.28514","0.00188"
"3.76200","0.31360","0.00221"
"4.10400","0.34206","0.00202"
"4.44600","0.37064","0.00259"
"4.78800","0.39910","0.00261"
"5.13000","0.42755","0.00270"
"5.47200","0.45607","0.00329"
"5.81400","0.48453","0.00319"
"6.15600","0.51311","0.00321"
"6.49800","0.54163","0.00373"
"6.84000","0.57009","0.00357"
"7.18200","0.59861","0.00358"
"7.52400","0.62713","0.00364"
"7.86600","0.65559","0.00314"
"8.20800","0.68411","0.00331"
"8.55000","0.71263","0.00381"
"8.89200","0.74109","0.00410"
"9.23400","0.76961","0.00419"
"9.57600","0.79807","0.00436"
"9.91800","0.82665","0.00347"
"10.26000","0.85517","0.00339"
"10.60200","0.88363","0.00346"
"10.94400","0.91215","0.00341"
"11.28600","0.94061","0.00409"
"11.62800","0.96907","0.00400"
"11.97000","0.99759","0.00387"
"12.31200","1.02611","0.00469"
"12.65400","1.05457","0.00462"
"12.99600","1.08309","0.00454"
"13.33800","1.11161","0.00494"
"13.68000","1.14013","0.00434"
"14.02200","1.16865","0.00484"
"14.36400","1.19711","0.00530"
"14.70600","1.22557","0.00501"
"15.04800","1.25415","0.00592"
"15.39000","1.28261","0.00564"
"15.73200","1.31112","0.00569"
"16.07400","1.33958","0.00606"
"16.41600","1.36810","0.00611"
"16.75800","1.39662","0.00682"
"17.10000","1.42508","0.00682"
"17.44200","1.45360","0.00672"
"17.78400","1.48218","0.00695"
"18.12600","1.51052","0.00713"
"18.46800","1.53916","0.00764"
"18.81000","1.56762","0.00753"
"19.15200","1.59608","0.00812"
"19.49400","1.62466","0.00853"
"19.83600","1.65312","0.00847"
"20.17800","1.68158","0.00842"
"20.52000","1.71010","0.00907"
"20.86200","1.73862","0.00873"
"21.20400","1.76720","0.00907"
"21.54600","1.79560","0.00890"
"21.88800","1.82412","0.00963"
"22.23000","1.85270","0.00968"
"22.57200","1.88110","0.01023"
"22.91400","1.90962","0.01023"
"23.25600","1.93814","0.01052"
"23.59800","1.96654","0.01110"
"23.94000","1.99512","0.01127"
"24.28200","2.02364","0.01158"
"24.62400","2.05210","0.01173"
"24.96600","2.08062","0.01223"
"25.30800","2.10908","0.01274"
"25.65000","2.13760","0.01249"
"25.99200","2.16612","0.01274"
"26.33400","2.19463","0.01341"
"26.67600","2.22309","0.01383"
"27.01800","2.25161","0.01369"
"27.36000","2.28007","0.01442"
"27.70200","2.30865","0.01424"
"28.04400","2.33717","0.01461"
"28.38600","2.36557","0.01533"
"28.72800","2.39415","0.01520"
"29.07000","2.42261","0.01495"
"29.41200","2.45107","0.01528"
"29.75400","2.47965","0.01579"
"30.09600","2.50811","0.01640"
"30.43800","2.53657","0.01634"
"30.78000","2.56509","0.01687"
"31.12200","2.59361","0.01692"
"31.46400","2.62213","0.01769"
"31.80600","2.65065","0.01751"
"32.14800","2.67905","0.01788"
"32.49000","2.70763","0.01810"
"32.83200","2.73615","0.01840"
"33.17400","2.76455","0.01894"
"33.51600","2.79307","0.01880"
"33.85800","2.82159","0.01898"
"34.20000","2.85011","0.01956"
"34.54200","2.87863","0.01978"
"34.88400","2.90709","0.01970"
"35.22600","2.93561","0.02015"
"35.56800","2.96419","0.02084"
"35.91000","2.99259","0.02009"
"36.25200","3.02111","0.02076"
"36.59400","3.04968","0.02118"
"36.93600","3.07808","0.02122"
"37.27800","3.10666","0.02163"
"37.62000","3.13506","0.02237"
"37.96200","3.16358","0.02190"
"38.30400","3.19216","0.02238"
"38.64600","3.22056","0.02261"
"38.98800","3.24914","0.02259"
"39.33000","3.27766","0.02301"
"39.67200","3.30606","0.02319"
"40.01400","3.33464","0.02361"
"40.35600","3.36310","0.02373"
"40.69800","3.39156","0.02420"
"41.04000","3.42014","0.02448"
"41.38200","3.44860","0.02491"
"41.72400","3.47712","0.02559"
"42.06600","3.50564","0.02559"
"42.40800","3.53404","0.02565"
"42.75000","3.56268","0.02541"
"43.09200","3.59114","0.02598"
"43.43400","3.61954","0.02651"
"43.77600","3.64812","0.02677"
"44.11800","3.67658","0.02727"
"44.46000","3.70510","0.02767"
"44.80200","3.73362","0.02785"
"45.14400","3.76214","0.02832"
"45.48600","3.79060","0.02885"
"45.82800","3.81912","0.02857"
"46.17000","3.84758","0.02919"
"46.51200","3.87616","0.02978"
"46.85400","3.90462","0.02994"
"47.19600","3.93314","0.03049"
"47.53800","3.96165","0.03109"
"47.88000","3.99011","0.03128"
"48.22200","4.01857","0.03121"
"48.56400","4.04715","0.03175"
"48.90600","4.07561","0.03232"
"49.24800","4.10413","0.03273"
"49.59000","4.13265","0.03326"
"49.93200","4.16111","0.03339"
"50.27400","4.18957","0.03398"
"50.61600","4.21815","0.03399"
"50.95800","4.24655","0.03401"
"51.30000","4.27513","0.03476"
"51.64200","4.30365","0.03503"
"51.98400","4.33211","0.03450"
"52.32600","4.36063","0.03475"
"52.66800","4.38909","0.03572"
"53.01000","4.41761","0.03534"
"53.35200","4.44619","0.03569"
"53.69400","4.47459","0.03697"
"54.03600","4.50311","0.03683"
"54.37800","4.53169","0.03699"
"54.72000","4.56003","0.03776"
"55.06200","4.58867","0.03831"
"55.40400","4.61713","0.03874"
"55.74600","4.64559","0.03702"
"56.08800","4.67417","0.03639"
"56.43000","4.70263","0.03722"
"56.77200","4.73115","0.03796"
"57.11400","4.75967","0.03835"
"57.45600","4.78807","0.03869"
"57.79800","4.81659","0.03954"
"58.14000","4.84510","0.03923"
"58.48200","4.87356","0.03882"
"58.82400","4.90214","0.03932"
"59.16600","4.93060","0.03992"
"59.50800","4.95906","0.04045"
"59.85000","4.98764","0.04073"
"60.19200","5.01610","0.04115"
"60.53400","5.04462","0.04165"
"60.87600","5.07314","0.04178"
"61.21800","5.10154","0.04247"
"61.56000","5.13018","0.04270"
"61.90200","5.15864","0.04333"
"62.24400","5.18704","0.04366"
"62.58600","5.21562","0.04385"
"62.92800","5.24408","0.04415"
"63.27000","5.27260","0.04447"
"63.61200","5.30106","0.04552"
"63.95400","5.32964","0.04518"
"64.29600","5.35816","0.04565"
"64.63800","5.38662","0.04620"
"64.98000","5.41514","0.04632"
"65.32200","5.44366","0.04701"
"65.66400","5.47212","0.04758"
"66.00600","5.50058","0.04797"
"66.34800","5.52910","0.04865"
"66.69000","5.55762","0.04888"
"67.03200","5.58614","0.04871"
"67.37400","5.61460","0.04902"
"67.71600","5.64312","0.04992"
"68.05800","5.67158","0.05129"
"68.40000","5.70010","0.05158"
"68.74200","5.72861","0.05198"
"69.08400","5.75713","0.05336"
"69.42600","5.78565","0.05394"
"69.76800","5.81411","0.05445"
"70.11000","5.84263","0.05503"
"70.45200","5.87115","0.05529"
"70.79400","5.89955","0.05615"
"71.13600","5.92819","0.05562"
"71.47800","5.95665","0.05647"
"71.82000","5.98505","0.05752"
"72.16200","6.01363","0.05800"
"72.50400","6.04203","0.05895"
"72.84600","6.07061","0.05885"
"73.18800","6.09907","0.06007"
"73.53000","6.12759","0.06050"
"73.87200","6.15611","0.06155"
"74.21400","6.18457","0.06207"
"74.55600","6.21309","0.06160"
"74.89800","6.24167","0.06242"
"75.24000","6.27007","0.06211"
"75.58200","6.29865","0.06208"
"75.92400","6.32711","0.06303"
"76.26600","6.35551","0.06345"
"76.60800","6.38415","0.06404"
"76.95000","6.41261","0.06394"
"77.29200","6.44107","0.06524"
"77.63400","6.46965","0.06531"
"77.97600","6.49811","0.06598"
"78.31800","6.52663","0.06693"
"78.66000","6.55514","0.06684"
"79.00200","6.58354","0.06768"
"79.34400","6.61218","0.06841"
"79.68600","6.64064","0.06818"
"80.02800","6.66904","0.06823"
"80.37000","6.69762","0.06937"
"80.71200","6.72614","0.06977"
"81.05400","6.75460","0.07020"
"81.39600","6.78312","0.07022"
"81.73800","6.81158","0.07049"
"82.08000","6.84010","0.07085"
"82.42200","6.86856","0.07132"
"82.76400","6.89708","0.07218"
"83.10600","6.92560","0.07212"
"83.44800","6.95412","0.07252"
"83.79000","6.98258","0.07274"
"84.13200","7.01116","0.07298"
"84.47400","7.03962","0.07312"
"84.81600","7.06808","0.07346"
"85.15800","7.09666","0.07396"
"85.50000","7.12512","0.07378"
"85.84200","7.15358","0.07411"
"86.18400","7.18210","0.07465"
"86.52600","7.21062","0.07475"
"86.86800","7.23908","0.07506"
"87.21000","7.26766","0.07514"
"87.55200","7.29606","0.07521"
"87.89400","7.32464","0.07568"
"88.23600","7.35316","0.07589"
"88.57800","7.38162","0.07628"
"88.92000","7.41014","0.07656"
"89.26200","7.43859","0.07713"
"89.60400","7.46706","0.07753"
"89.94600","7.49563","0.07745"
"90.28800","7.52409","0.07828"
"90.63000","7.55261","0.07850"
"90.97200","7.58113","0.07888"
"91.31400","7.60953","0.07927"
"91.65600","7.63811","0.07960"
"91.99800","7.66663","0.08000"
"92.34000","7.69515","0.08065"
"92.68200","7.72367","0.08068"
"93.02400","7.75207","0.08055"
"93.36600","7.78059","0.08003"
"93.70800","7.80917","0.08078"
"94.05000","7.83757","0.08145"
"94.39200","7.86615","0.08226"
"94.73400","7.89467","0.08257"
"95.07600","7.92307","0.08309"
"95.41800","7.95165","0.08372"
"95.76000","7.98011","0.08461"
"96.10200","8.00857","0.08483"
"96.44400","8.03709","0.08556"
"96.78600","8.06561","0.08652"
"97.12800","8.09413","0.08686"
"97.47000","8.12259","0.08778"
"97.81200","8.15105","0.08875"
"98.15400","8.17963","0.08903"
"98.49600","8.20815","0.08978"
"98.83800","8.23661","0.09021"
"99.18000","8.26513","0.09078"
"99.52200","8.29358","0.09217"
"99.86400","8.32210","0.09242"
"100.20600","8.35063","0.09259"
"100.54800","8.37908","0.09407"
"100.89000","8.40766","0.09455"
"101.23200","8.43612","0.09535"
"101.57400","8.46458","0.09685"
"101.91600","8.49304","0.09789"
"102.25800","8.52162","0.09904"
"102.60000","8.55014","0.09947"
"102.94200","8.57860","0.10105"
"103.28400","8.60718","0.10215"
"103.62600","8.63558","0.10364"
"103.96800","8.66410","0.10445"
"104.31000","8.69262","0.10527"
"104.65200","8.72114","0.10669"
"104.99400","8.74966","0.10682"
"105.33600","8.77806","0.10817"
"105.67800","8.80664","0.11032"
"106.02000","8.83510","0.11066"
"106.36200","8.86356","0.11267"
"106.70400","8.89214","0.11313"
"107.04600","8.92066","0.11485"
"107.38800","8.94906","0.11704"
"107.73000","8.97770","0.11670"
"108.07200","9.00610","0.11692"
"108.41400","9.03462","0.11835"
"108.75600","9.06320","0.11941"
"109.09800","9.09154","0.12072"
"109.44000","9.12012","0.12146"
"109.78200","9.14864","0.12265"
"110.12400","9.17710","0.12377"
"110.46600","9.20562","0.12465"
"110.80800","9.23407","0.12624"
"111.15000","9.26254","0.12696"
"111.49200","9.29117","0.12832"
"111.83400","9.31957","0.12848"
"112.17600","9.34815","0.12957"
"112.51800","9.37667","0.13092"
"112.86000","9.40507","0.13243"
"113.20200","9.43365","0.13350"
"113.54400","9.46217","0.13400"
"113.88600","9.49057","0.13480"
"114.22800","9.51915","0.13627"
"114.57000","9.54761","0.13724"
"114.91200","9.57607","0.13854"
"115.25400","9.60459","0.13897"
"115.59600","9.63305","0.13996"
"115.93800","9.66163","0.14038"
"116.28000","9.69009","0.14186"
"116.62200","9.71861","0.14310"
"116.96400","9.74713","0.14358"
"117.30600","9.77565","0.14431"
"117.64800","9.80411","0.14544"
"117.99000","9.83263","0.14649"
"118.33200","9.86115","0.14669"
"118.67400","9.88961","0.14740"
"119.01600","9.91813","0.14835"
"119.35800","9.94665","0.14986"
"119.70000","9.97511","0.15042"
"120.04200","10.00363","0.15116"
"120.38400","10.03209","0.15232"
"120.72600","10.06066","0.15359"
"121.06800","10.08913","0.15412"
"121.41000","10.11759","0.15578"
"121.75200","10.14610","0.15674"
"122.09400","10.17462","0.15805"
"122.43600","10.20314","0.15886"
"122.77800","10.23160","0.16001"
"123.12000","10.26012","0.16211"
"123.46200","10.28858","0.16237"
"123.80400","10.31716","0.16329"
"124.14600","10.34562","0.16336"
"124.48800","10.37414","0.16461"
"124.83000","10.40260","0.16546"
"125.17200","10.43106","0.16692"
"125.51400","10.45964","0.16769"
"125.85600","10.48810","0.16881"
"126.19800","10.51662","0.16961"
"126.54000","10.54514","0.17056"
"126.88200","10.57354","0.17229"
"127.22400","10.60212","0.17321"
"127.56600","10.63064","0.17422"
"127.90800","10.65904","0.17573"
"128.25000","10.68768","0.17613"
"128.59200","10.71614","0.17685"
"128.93401","10.74460","0.17821"
"129.27600","10.77318","0.17907"
"129.61800","10.80164","0.17954"
"129.96001","10.83010","0.18044"
"130.30200","10.85862","0.18085"
"130.64400","10.88708","0.18139"
"130.98599","10.91572","0.18246"
"131.32800","10.94418","0.18316"
"131.67000","10.97257","0.18350"
"132.01199","11.00115","0.18412"
"132.35400","11.02955","0.18491"
"132.69600","11.05807","0.18534"
"133.03799","11.08659","0.18576"
"133.38000","11.11505","0.18620"
"133.72200","11.14363","0.18694"
"134.06400","11.17209","0.18792"
"134.40601","11.20055","0.18837"
"134.74800","11.22913","0.18898"
"135.09000","11.25759","0.18996"
"135.43201","11.28611","0.19076"
"135.77400","11.31463","0.19221"
"136.11600","11.34309","0.19302"
"136.45799","11.37161","0.19404"
"136.80000","11.40013","0.19528"
"137.14200","11.42859","0.19588"
"137.48399","11.45711","0.19761"
"137.82600","11.48563","0.19805"
"138.16800","11.51403","0.19911"
"138.50999","11.54267","0.20059"
"138.85201","11.57113","0.20196"
"139.19400","11.59959","0.20254"
"139.53600","11.62811","0.20400"
"139.87801","11.65663","0.20524"
"140.22000","11.68509","0.20674"
"140.56200","11.71361","0.20792"
"140.90401","11.74213","0.20883"
"141.24600","11.77059","0.21125"
"141.58800","11.79911","0.21289"
"141.92999","11.82757","0.21363"
"142.27200","11.85614","0.21626"
"142.61400","11.88461","0.21786"
"142.95599","11.91306","0.21928"
"143.29800","11.94164","0.22035"
"143.64000","11.97016","0.22138"
"143.98199","11.99862","0.22266"
"144.32401","12.02714","0.22386"
"144.66600","12.05554","0.22416"
"145.00800","12.08406","0.22610"
"145.35001","12.11270","0.22745"
"145.69200","12.14110","0.22913"
"146.03400","12.16962","0.23021"
"146.37601","12.19814","0.23149"
"146.71800","12.22654","0.23331"
"147.06000","12.25512","0.23437"
"147.40199","12.28358","0.23661"
"147.74400","12.31204","0.23766"
"148.08600","12.34068","0.23835"
"148.42799","12.36908","0.24066"
"148.77000","12.39766","0.24196"
"149.11200","12.42612","0.24136"
"149.45399","12.45458","0.24259"
"149.79601","12.48316","0.24462"
"150.13800","12.51162","0.24567"
"150.48000","12.54008","0.24721"
"150.82201","12.56866","0.24849"
"151.16400","12.59712","0.25114"
"151.50600","12.62564","0.25393"
"151.84801","12.65410","0.25666"
"152.19000","12.68262","0.25976"
"152.53200","12.71114","0.26213"
"152.87399","12.73965","0.26502"
"153.21600","12.76805","0.26806"
"153.55800","12.79663","0.27061"
"153.89999","12.82509","0.27319"
"154.24200","12.85361","0.27525"
"154.58400","12.88213","0.27667"
"154.92599","12.91059","0.27878"
"155.26801","12.93911","0.27989"
"155.61000","12.96757","0.28224"
"155.95200","12.99609","0.28356"
"156.29401","13.02461","0.28457"
"156.63600","13.05313","0.28566"
"156.97800","13.08159","0.28704"
"157.32001","13.11011","0.28787"
"157.66200","13.13863","0.28943"
"158.00400","13.16709","0.29043"
"158.34599","13.19567","0.29124"
"158.68800","13.22413","0.29191"
"159.03000","13.25259","0.29274"
"159.37199","13.28111","0.29324"
"159.71400","13.30963","0.29402"
"160.05600","13.33809","0.29512"
"160.39799","13.36667","0.29539"
"160.74001","13.39507","0.29651"
"161.08200","13.42365","0.29738"
"161.42400","13.45217","0.29827"
"161.76601","13.48057","0.29949"
"162.10800","13.50909","0.30080"
"162.45000","13.53761","0.30166"
"162.79201","13.56607","0.30352"
"163.13400","13.59465","0.30501"
"163.47600","13.62305","0.30665"
"163.81799","13.65162","0.30964"
"164.16000","13.68020","0.31289"
"164.50200","13.70854","0.31554"
"164.84399","13.73712","0.31795"
"165.18600","13.76558","0.32094"
"165.52800","13.79410","0.32364"
"165.87000","13.82268","0.32581"
"166.21201","13.85108","0.32829"
"166.55400","13.87960","0.33030"
"166.89600","13.90812","0.33295"
"167.23801","13.93652","0.33585"
"167.58000","13.96516","0.33796"
"167.92200","13.99362","0.33989"
"168.26401","14.02202","0.34261"
"168.60600","14.05066","0.34549"
"168.94800","14.07912","0.34724"
"169.28999","14.10764","0.34956"
"169.63200","14.13610","0.35163"
"169.97400","14.16462","0.35287"
"170.31599","14.19308","0.35465"
"170.65800","14.22160","0.35653"
"171.00000","14.25006","0.35869"
"171.34200","14.27864","0.36088"
"171.68401","14.30710","0.36354"
"172.02600","14.33562","0.36527"
"172.36800","14.36414","0.36755"
"172.71001","14.39266","0.37023"
"173.05200","14.42112","0.37203"
"173.39400","14.44964","0.37361"
"173.73599","14.47810","0.37522"
"174.07800","14.50662","0.37704"
"174.42000","14.53519","0.37862"
"174.76199","14.56365","0.38043"
"175.10400","14.59211","0.38227"
"175.44600","14.62063","0.38368"
"175.78799","14.64909","0.38491"
"176.13000","14.67761","0.38607"
"176.47200","14.70613","0.38790"
"176.81400","14.73459","0.38973"
"177.15601","14.76311","0.39191"
"177.49800","14.79157","0.39354"
"177.84000","14.82009","0.39661"
"178.18201","14.84861","0.39804"
"178.52400","14.87707","0.40140"
"178.86600","14.90559","0.40372"
"179.20799","14.93417","0.40662"
"179.55000","14.96263","0.40938"
"179.89200","14.99115","0.41228"
"180.23399","15.01961","0.41449"
"180.57600","15.04807","0.41719"
"180.91800","15.07665","0.41982"
"181.25999","15.10511","0.42288"
"181.60201","15.13363","0.42615"
"181.94400","15.16215","0.42843"
"182.28600","15.19055","0.42954"
"182.62801","15.21913","0.43190"
"182.97000","15.24765","0.43341"
"183.31200","15.27611","0.43590"
"183.65401","15.30463","0.43735"
"183.99600","15.33309","0.43989"
"184.33800","15.36161","0.44187"
"184.67999","15.39013","0.44462"
"185.02200","15.41859","0.44678"
"185.36400","15.44716","0.44994"
"185.70599","15.47562","0.45303"
"186.04800","15.50402","0.45562"
"186.39000","15.53266","0.45759"
"186.73199","15.56112","0.46135"
"187.07401","15.58964","0.46451"
"187.41600","15.61816","0.46812"
"187.75800","15.64662","0.47225"
"188.10001","15.67508","0.47499"
"188.44200","15.70360","0.47876"
"188.78400","15.73206","0.48270"
"189.12601","15.76064","0.48565"
"189.46800","15.78916","0.48866"
"189.81000","15.81756","0.49089"
"190.15199","15.84614","0.49299"
"190.49400","15.87466","0.49493"
"190.83600","15.90306","0.49624"
"191.17799","15.93164","0.49778"
"191.52000","15.96010","0.49972"
"191.86200","15.98862","0.50133"
"192.20399","16.01714","0.50361"
"192.54601","16.04560","0.50599"
"192.88800","16.07412","0.50897"
"193.23000","16.10264","0.51079"
"193.57201","16.13110","0.51353"
"193.91400","16.15968","0.51601"
"194.25600","16.18814","0.51953"
"194.59801","16.21659","0.52212"
"194.94000","16.24512","0.52577"
"195.28200","16.27357","0.52866"
"195.62399","16.30203","0.53206"
"195.96600","16.33061","0.53440"
"196.30800","16.35913","0.51136"
"196.64999","16.38759","0.51080"
"196.99200","16.41617","0.51523"
"197.33400","16.44457","0.52078"
"197.67599","16.47315","0.52593"
"198.01801","16.50167","0.52981"
"198.36000","16.53007","0.53547"
"198.70200","16.55859","0.54033"
"199.04401","16.58711","0.54459"
"199.38600","16.61557","0.54748"
"199.72800","16.64421","0.55119"
"200.07001","16.67255","0.55561"
"200.41200","16.70113","0.55963"
"200.75400","16.72965","0.56363"
"201.09599","16.75805","0.56834"
"201.43800","16.78663","0.57284"
"201.78000","16.81515","0.57560"
"202.12199","16.84361","0.57910"
"202.46400","16.87213","0.58130"
"202.80600","16.90065","0.58367"
"203.14799","16.92911","0.58560"
"203.49001","16.95763","0.58778"
"203.83200","16.98603","0.59071"
"204.17400","17.01461","0.59283"
"204.51601","17.04313","0.59436"
"204.85800","17.07159","0.59692"
"205.20000","17.10011","0.59842"
"205.54201","17.12862","0.60130"
"205.88400","17.15709","0.60446"
"206.22600","17.18560","0.60737"
"206.56799","17.21412","0.61146"
"206.91000","17.24264","0.61603"
"207.25200","17.27110","0.62043"
"207.59399","17.29956","0.62494"
"207.93600","17.32814","0.63142"
"208.27800","17.35666","0.63606"
"208.62000","17.38506","0.63958"
"208.96201","17.41364","0.64331"
"209.30400","17.44204","0.64627"
"209.64600","17.47056","0.64958"
"209.98801","17.49914","0.65335"
"210.33000","17.52760","0.65697"
"210.67200","17.55612","0.66047"
"211.01401","17.58458","0.66404"
"211.35600","17.61310","0.66681"
"211.69800","17.64162","0.67101"
"212.03999","17.67014","0.67539"
"212.38200","17.69860","0.67967"
"212.72400","17.72712","0.68373"
"213.06599","17.75570","0.68720"
"213.40800","17.78410","0.69110"
"213.75000","17.81262","0.69426"
"214.09200","17.84114","0.69638"
"214.43401","17.86954","0.59489"
"214.77600","17.89812","0.59456"
"215.11800","17.92657","0.59610"
"215.46001","17.95516","0.59816"
"215.80200","17.98368","0.60055"
"216.14400","18.01208","0.60408"
"216.48599","18.04066","0.60784"
"216.82800","18.06911","0.61247"
"217.17000","18.09757","0.61758"
"217.51199","18.12621","0.62368"
"217.85400","18.15461","0.63048"
"218.19600","18.18313","0.63503"
"218.53799","18.21165","0.63844"
"218.88000","18.23999","0.64088"
"219.22200","18.26863","0.64454"
"219.56400","18.29709","0.64854"
"219.90601","18.32555","0.65265"
"220.24800","18.35419","0.65705"
"220.59000","18.38259","0.66115"
"220.93201","18.41111","0.66537"
"221.27400","18.43963","0.66904"
"221.61600","18.46809","0.67370"
"221.95799","18.49661","0.67773"
"222.30000","18.52519","0.68161"
"222.64200","18.55353","0.68615"
"222.98399","18.58211","0.69049"
"223.32600","18.61063","0.69329"
"223.66800","18.63909","0.69599"
"224.00999","18.66761","0.69804"
"224.35201","18.69607","0.70004"
"224.69400","18.72465","0.70158"
"225.03600","18.75311","0.70377"
"225.37801","18.78157","0.70582"
"225.72000","18.81015","0.70823"
"226.06200","18.83867","0.71090"
"226.40401","18.86713","0.71336"
"226.74600","18.89565","0.71593"
"227.08800","18.92410","0.71878"
"227.42999","18.95257","0.72236"
"227.77200","18.98114","0.72622"
"228.11400","19.00960","0.73106"
"228.45599","19.03812","0.73533"
"228.79800","19.06658","0.69296"
"229.14000","19.09510","0.69704"
"229.48199","19.12362","0.69957"
"229.82401","19.15214","0.70210"
"230.16600","19.18060","0.70469"
"230.50800","19.20912","0.70806"
"230.85001","19.23764","0.71149"
"231.19200","19.26610","0.71465"
"231.53400","19.29462","0.71837"
"231.87601","19.32314","0.72348"
"232.21800","19.35154","0.72832"
"232.56000","19.38012","0.73298"
"232.90199","19.40858","0.73655"
"233.24400","19.43710","0.74050"
"233.58600","19.46568","0.74527"
"233.92799","19.49402","0.75079"
"234.27000","19.52260","0.75585"
"234.61200","19.55112","0.76059"
"234.95399","19.57964","0.76608"
"235.29601","19.60816","0.77191"
"235.63800","19.63662","0.77349"
"235.98000","19.66508","0.77561"
"236.32201","19.69366","0.69608"
"236.66400","19.72211","0.70053"
"237.00600","19.75064","0.70256"
"237.34801","19.77915","0.70519"
"237.69000","19.80750","0.70796"
"238.03200","19.83614","0.71155"
"238.37399","19.86459","0.71551"
"238.71600","19.89311","0.72035"
"239.05800","19.92163","0.72726"
"239.39999","19.95009","0.73298"
"239.74200","19.97861","0.73844"
"240.08400","20.00713","0.74140"
"240.42599","20.03559","0.71791"
"240.76801","20.06423","0.72008"
"241.11000","20.09263","0.72630"
"241.45200","20.12103","0.73143"
"241.79401","20.14961","0.73583"
"242.13600","20.17813","0.74005"
"242.47800","20.20659","0.74275"
"242.82001","20.23517","0.74836"
"243.16200","20.26357","0.75131"
"243.50400","20.29215","0.75511"
"243.84599","20.32061","0.75968"
"244.18800","20.34907","0.76512"
"244.53000","20.37765","0.77033"
"244.87199","20.40611","0.77458"
"245.21400","20.43463","0.78023"
"245.55600","20.46315","0.78523"
"245.89799","20.49161","0.78910"
"246.24001","20.52007","0.79311"
"246.58200","20.54865","0.79673"
"246.92400","20.57711","0.79848"
"247.26601","20.60563","0.80225"
"247.60800","20.63414","0.80473"
"247.95000","20.66260","0.80719"
"248.29201","20.69112","0.80896"
"248.63400","20.71964","0.81010"
"248.97600","20.74810","0.81243"
"249.31799","20.77662","0.81249"
"249.66000","20.80514","0.81611"
"250.00200","20.83360","0.81966"
"250.34399","20.86212","0.82335"
"250.68600","20.89064","0.82646"
"251.02800","20.91910","0.83033"
"251.37000","20.94768","0.83454"
"251.71201","20.97602","0.83868"
"252.05400","21.00460","0.84257"
"252.39600","21.03318","0.84642"
"252.73801","21.06152","0.85062"
"253.08000","21.09016","0.85538"
"253.42200","21.11862","0.85996"
"253.76401","21.14708","0.86372"
"254.10600","21.17566","0.86843"
"254.44800","21.20406","0.87287"
"254.78999","21.23258","0.87729"
"255.13200","21.26110","0.87917"
"255.47400","21.28956","0.87352"
"255.81599","21.31814","0.87780"
"256.15799","21.34666","0.88403"
"256.50000","21.37506","0.88742"
"256.84201","21.40369","0.89177"
"257.18399","21.43210","0.89489"
"257.52600","21.46056","0.89830"
"257.86801","21.48913","0.90086"
"258.20999","21.51760","0.90403"
"258.55200","21.54618","0.90718"
"258.89401","21.57463","0.91076"
"259.23599","21.60303","0.91439"
"259.57800","21.63161","0.91914"
"259.92001","21.66013","0.92419"
"260.26199","21.68859","0.92917"
"260.60400","21.71711","0.73162"
"260.94601","21.74557","0.73590"
"261.28799","21.77409","0.73800"
"261.63000","21.80261","0.74443"
"261.97198","21.83107","0.74816"
"262.31400","21.85959","0.75514"
"262.65601","21.88811","0.76108"
"262.99799","21.91657","0.75725"
"263.34000","21.94515","0.76132"
"263.68201","21.97361","0.76627"
"264.02399","22.00207","0.77382"
"264.36600","22.03065","0.75702"
"264.70801","22.05911","0.76171"
"265.04999","22.08763","0.76510"
"265.39200","22.11609","0.77165"
"265.73401","22.14461","0.77578"
"266.07599","22.17307","0.78286"
"266.41800","22.20165","0.41254"
"266.76001","22.23005","0.41858"
"267.10199","22.25869","0.42219"
"267.44400","22.28715","0.42711"
"267.78601","22.31555","0.42827"
"268.12799","22.34413","0.43075"
"268.47000","22.37264","0.43026"
"268.81201","22.40110","0.43212"
"269.15399","22.42969","0.43574"
"269.49600","22.45808","0.43849"
"269.83801","22.48660","0.44324"
"270.17999","22.51512","0.44712"
"270.52200","22.54358","0.44929"
"270.86401","22.57210","0.45438"
"271.20599","22.60062","0.45704"
"271.54800","22.62908","0.46182"
"271.89001","22.65766","0.46803"
"272.23199","22.68606","0.47134"
"272.57401","22.71464","0.47657"
"272.91599","22.74316","0.48171"
"273.25800","22.77156","0.48535"
"273.60001","22.80008","0.48946"
"273.94199","22.82866","0.49286"
"274.28400","22.85706","0.49460"
"274.62601","22.88558","0.49662"
"274.96799","22.91416","0.49949"
"275.31000","22.94256","0.50102"
"275.65201","22.97120","0.50339"
"275.99399","22.99960","0.50669"
"276.33600","23.02812","0.51000"
"276.67801","23.05664","0.51292"
"277.01999","23.08504","0.51611"
"277.36200","23.11368","0.51921"
"277.70401","23.14214","0.52304"
"278.04599","23.17060","0.52855"
"278.38800","23.19912","0.53383"
"278.73001","23.22763","0.53832"
"279.07199","23.25610","0.54385"
"279.41400","23.28468","0.54959"
"279.75601","23.31307","0.55386"
"280.09799","23.34160","0.55890"
"280.44000","23.37005","0.56264"
"280.78201","23.39857","0.56719"
"281.12399","23.42715","0.57257"
"281.46600","23.45561","0.57750"
"281.80801","23.48407","0.58069"
"282.14999","23.51265","0.58298"
"282.49200","23.54111","0.58557"
"282.83401","23.56957","0.58899"
"283.17599","23.59809","0.59029"
"283.51801","23.62667","0.59263"
"283.85999","23.65513","0.59488"
"284.20200","23.68365","0.59662"
"284.54401","23.71211","0.59859"
"284.88599","23.74057","0.60134"
"285.22800","23.76915","0.60443"
"285.57001","23.79761","0.60865"
"285.91199","23.82613","0.61408"
"286.25400","23.85465","0.61964"
"286.59601","23.88311","0.62481"
"286.93799","23.91163","0.63087"
"287.28000","23.94009","0.63568"
"287.62201","23.96855","0.63951"
"287.96399","23.99713","0.64386"
"288.30600","24.02559","0.64737"
"288.64801","24.05411","0.65115"
"288.98999","24.08262","0.65606"
"289.33200","24.11103","0.65948"
"289.67401","24.13960","0.66281"
"290.01599","24.16813","0.66758"
"290.35800","24.19658","0.67242"
"290.70001","24.22516","0.67781"
"291.04199","24.25357","0.68172"
"291.38400","24.28209","0.68473"
"291.72601","24.31060","0.68645"
"292.06799","24.33912","0.68754"
"292.41000","24.36764","0.68999"
"292.75201","24.39616","0.69389"
"293.09399","24.42456","0.69745"
"293.43600","24.45314","0.69999"
"293.77802","24.48160","0.70165"
"294.12000","24.51012","0.70355"
"294.46201","24.53864","0.70631"
"294.80399","24.56704","0.70908"
"295.14600","24.59562","0.71175"
"295.48801","24.62414","0.71482"
"295.82999","24.65254","0.71789"
"296.17200","24.68112","0.72283"
"296.51401","24.70958","0.72741"
"296.85599","24.73810","0.73300"
"297.19800","24.76668","0.73653"
"297.54001","24.79514","0.74075"
"297.88199","24.82360","0.74604"
"298.22400","24.85212","0.75105"
"298.56601","24.88058","0.75696"
"298.90799","24.90910","0.76192"
"299.25000","24.93761","0.76758"
"299.59201","24.96608","0.77363"
"299.93399","24.99459","0.78059"
"300.27600","25.02311","0.78734"
"300.61801","25.05157","0.79321"
"300.95999","25.08015","0.79752"
"301.30200","25.10862","0.80129"
"301.64401","25.13708","0.80490"
"301.98599","25.16559","0.80752"
"302.32800","25.19411","0.80929"
"302.67001","25.22264","0.81131"
"303.01199","25.25115","0.81450"
"303.35400","25.27955","0.81801"
"303.69601","25.30813","0.82129"
"304.03799","25.33665","0.82502"
"304.38000","25.36511","0.82961"
"304.72198","25.39369","0.83401"
"305.06400","25.42215","0.83892"
"305.40601","25.45055","0.84229"
"305.74799","25.47907","0.84539"
"306.09000","25.50759","0.85081"
"306.43201","25.53605","0.85650"
"306.77399","25.56463","0.86284"
"307.11600","25.59309","0.86769"
"307.45801","25.62161","0.86592"
"307.79999","25.65013","0.87188"
"308.14200","25.67859","0.87650"
"308.48401","25.70711","0.88234"
"308.82599","25.73557","0.88762"
"309.16800","25.76409","0.89196"
"309.51001","25.79267","0.89594"
"309.85199","25.82107","0.89948"
"310.19400","25.84965","0.90348"
"310.53601","25.87811","0.90726"
"310.87799","25.90656","0.91040"
"311.22000","25.93514","0.91390"
"311.56201","25.96367","0.91848"
"311.90399","25.99207","0.92235"
"312.24600","26.02064","0.92767"
"312.58801","26.04910","0.93192"
"312.92999","26.07763","0.93727"
"313.27200","26.10614","0.94396"
"313.61401","26.13454","0.95070"
"313.95599","26.16318","0.95625"
"314.29800","26.19164","0.96211"
"314.64001","26.22010","0.96857"
"314.98199","26.24862","0.97270"
"315.32401","26.27708","0.97682"
"315.66599","26.30566","0.98247"
"316.00800","26.33412","0.98729"
"316.35001","26.36258","0.99211"
"316.69199","26.39116","0.99616"
"317.03400","26.41962","0.99897"
"317.37601","26.44808","1.00167"
"317.71799","26.47660","1.00347"
"318.06000","26.50512","1.00458"
"318.40201","26.53358","1.00686"
"318.74399","26.56216","1.00906"
"319.08600","26.59062","1.01265"
"319.42801","26.61908","1.01621"
"319.76999","26.64766","1.02112"
"320.11200","26.67612","1.02643"
"320.45401","26.70464","1.03438"
"320.79599","26.73310","1.04324"
"321.13800","26.76162","1.04974"
"321.48001","26.79008","1.05431"
"321.82199","26.81865","1.05968"
"322.16400","26.84711","1.06525"
"322.50601","26.87569","1.06009"
"322.84799","26.90409","1.06273"
"323.19000","26.93255","1.06387"
"323.53201","26.96113","0.90220"
"323.87399","26.98959","0.90585"
"324.21600","27.01811","0.90964"
"324.55801","27.04663","0.91388"
"324.89999","27.07509","0.91951"
"325.24200","27.10361","0.92659"
"325.58401","27.13219","0.93406"
"325.92599","27.16053","0.94394"
"326.26801","27.18911","0.95023"
"326.60999","27.21763","0.95862"
"326.95200","27.24609","0.96559"
"327.29401","27.27467","0.97239"
"327.63599","27.30313","0.97735"
"327.97800","27.33159","0.98334"
"328.32001","27.36011","0.99050"
"328.66199","27.38857","0.99585"
"329.00400","27.41715","0.99958"
"329.34601","27.44567","1.00230"
"329.68799","27.47407","1.00444"
"330.03000","27.50265","1.00705"
"330.37201","27.53111","1.01085"
"330.71399","27.55957","1.01564"
"331.05600","27.58815","1.02074"
"331.39801","27.61654","1.02549"
"331.73999","27.64507","1.03352"
"332.08200","27.67365","1.04316"
"332.42401","27.70205","1.04959"
"332.76599","27.73069","1.05677"
"333.10800","27.75915","1.06267"
"333.45001","27.78760","1.07018"
"333.79199","27.81612","1.07795"
"334.13400","27.84459","1.08450"
"334.47601","27.87310","1.09537"
"334.81799","27.90162","1.10199"
"335.16000","27.93014","1.10742"
"335.50201","27.95860","1.11226"
"335.84399","27.98712","1.11636"
"336.18600","28.01558","1.11726"
"336.52802","28.04410","1.11985"
"336.87000","28.07262","1.12146"
"337.21201","28.10108","1.12327"
"337.55399","28.12960","1.12600"
"337.89600","28.15812","1.08055"
"338.23801","28.18664","1.08148"
"338.57999","28.21510","1.08671"
"338.92200","28.24362","1.09368"
"339.26401","28.27214","1.10058"
"339.60599","28.30066","1.10737"
"339.94800","28.32906","1.11198"
"340.29001","28.35764","1.11653"
"340.63199","28.38616","1.11914"
"340.97400","28.41456","1.12109"
"341.31601","28.44308","1.12319"
"341.65799","28.47160","1.12639"
"342.00000","28.50006","1.13093"
"342.34201","28.52864","1.13747"
"342.68399","28.55710","1.14339"
"343.02600","28.58562","1.15003"
"343.36801","28.61413","1.15823"
"343.70999","28.64260","1.16557"
"344.05200","28.67112","1.17146"
"344.39401","28.69963","1.17904"
"344.73599","28.72810","1.18887"
"345.07800","28.75661","1.19773"
"345.42001","28.78513","1.17959"
"345.76199","28.81359","1.18528"
"346.10400","28.84217","1.19442"
"346.44601","28.87057","1.20171"
"346.78799","28.89915","1.20711"
"347.13000","28.92767","1.21153"
"347.47198","28.95607","1.21479"
"347.81400","28.98471","1.21922"
"348.15601","29.01311","1.22356"
"348.49799","29.04157","1.22952"
"348.84000","29.07009","1.23628"
"349.18201","29.09855","1.24413"
"349.52399","29.12713","1.25319"
"349.86600","29.15565","1.25984"
"350.20801","29.18405","1.26518"
"350.54999","29.21263","1.26971"
"350.89200","29.24115","1.23976"
"351.23401","29.26961","1.24825"
"351.57599","29.29807","1.25660"
"351.91800","29.32659","1.26163"
"352.26001","29.35511","1.26814"
"352.60199","29.38363","1.27139"
"352.94400","29.41215","1.27604"
"353.28601","29.44067","1.28042"
"353.62799","29.46907","1.28749"
"353.97000","29.49758","1.29453"
"354.31201","29.52610","1.30021"
"354.65399","29.55468","1.30588"
"354.99600","29.58309","1.31225"
"355.33801","29.61166","1.31847"
"355.67999","29.64012","1.32518"
"356.02200","29.66858","1.33154"
"356.36401","29.69716","1.33967"
"356.70599","29.72562","1.34993"
"357.04800","29.75408","1.35776"
"357.39001","29.78260","1.36604"
"357.73199","29.81112","1.37278"
"358.07401","29.83958","1.38167"
"358.41599","29.86816","1.39010"
"358.75800","29.89662","1.39904"
"359.10001","29.92508","1.40815"
"359.44199","29.95366","1.41415"
"359.78400","29.98212","1.41835"
"360.12601","30.01064","1.42078"
"360.46799","30.03910","1.42220"
"360.81000","30.06756","1.42335"
"361.15201","30.09620","1.42545"
"361.49399","30.12460","1.42892"
"361.83600","30.15312","1.43366"
"362.17801","30.18170","1.44096"
"362.51999","30.21004","1.45049"
"362.86200","30.23868","1.45963"
"363.20401","30.26714","1.46819"
"363.54599","30.29560","1.47631"
"363.88800","30.32411","1.48277"
"364.23001","30.35258","1.48973"
"364.57199","30.38104","1.49969"
"364.91400","30.40961","1.50797"
"365.25601","30.43808","1.51331"
"365.59799","30.46665","1.51797"
"365.94000","30.49512","1.52296"
"366.28201","30.52358","1.52876"
"366.62399","30.55215","1.53462"
"366.96600","30.58061","1.53997"
"367.30801","30.60913","1.54522"
"367.64999","30.63759","1.54909"
"367.99200","30.66611","1.55441"
"368.33401","30.69463","1.56148"
"368.67599","30.72315","1.56750"
"369.01801","30.75155","1.57253"
"369.35999","30.78013","1.57688"
"369.70200","30.80859","1.58109"
"370.04401","30.83705","1.58439"
"370.38599","30.86563","1.58995"
"370.72800","30.89415","1.59821"
"371.07001","30.92261","1.60591"
"371.41199","30.95113","1.61250"
"371.75400","30.97959","1.61787"
"372.09601","31.00811","1.62318"
"372.43799","31.03663","1.62770"
"372.78000","31.06509","1.63092"
"373.12201","31.09367","0.99846"
"373.46399","31.12213","1.00649"
"373.80600","31.15059","1.00151"
"374.14801","31.17917","0.88886"
"374.48999","31.20762","0.84372"
"374.83200","31.23608","0.79567"
"375.17401","31.26460","0.79782"
"375.51599","31.29306","0.79977"
"375.85800","31.32164","0.80172"
"376.20001","31.35016","0.79646"
"376.54199","31.37862","0.80477"
"376.88400","31.40714","0.80601"
"377.22601","31.43566","0.80879"
"377.56799","31.46406","0.81544"
"377.91000","31.49264","0.81331"
"378.25201","31.52110","0.81824"
"378.59399","31.54956","0.81742"
"378.93600","31.57814","0.81948"
"379.27802","31.60660","0.82833"
"379.62000","31.63512","0.82811"
"379.96201","31.66364","0.84088"
"380.30399","31.69204","0.84268"
"380.64600","31.72062","0.84955"
"380.98801","31.74914","0.85744"
"381.32999","31.77760","0.85868"
"381.67200","31.80618","0.86896"
"382.01401","31.83464","0.86657"
"382.35599","31.86304","0.87712"
"382.69800","31.89168","0.87816"
"383.04001","31.92007","0.88658"
"383.38199","31.94866","0.89200"
"383.72400","31.97712","0.89574"
"384.06601","32.00557","0.90268"
"384.40799","32.03416","0.90445"
"384.75000","32.06261","0.91173"
"385.09201","32.09107","0.91264"
"385.43399","32.11966","0.92387"
"385.77600","32.14812","0.92579"
"386.11801","32.17657","0.94014"
"386.45999","32.20509","0.94159"
"386.80200","32.23362","0.95348"
"387.14401","32.26213","0.95516"
"387.48599","32.29065","0.96527"
"387.82800","32.31905","0.96841"
"388.17001","32.34763","0.97690"
"388.51199","32.37615","0.97870"
"388.85400","32.40461","0.98824"
"389.19601","32.43313","0.99105"
"389.53799","32.46159","0.99742"
"389.88000","32.49011","0.99910"
"390.22198","32.51863","1.00357"
"390.56400","32.54709","1.00426"
"390.90601","32.57561","1.00821"
"391.24799","32.60413","1.01006"
"391.59000","32.63259","1.01622"
"391.93201","32.66117","1.01933"
"392.27399","32.68963","1.02782"
"392.61600","32.71803","1.03564"
"392.95801","32.74667","1.04538"
"393.29999","32.77513","1.05328"
"393.64200","32.80359","1.05932"
"393.98401","32.83210","1.07086"
"394.32599","32.86063","1.07555"
"394.66800","32.88909","1.08853"
"395.01001","32.91760","1.09255"
"395.35199","32.94606","1.10105"
"395.69400","32.97459","1.10600"
"396.03601","33.00316","1.11026"
"396.37799","33.03162","1.11743"
"396.72000","33.06015","0.60960"
"397.06201","33.08860","0.41546"
"397.40399","33.11706","0.42226"
"397.74600","33.14565","0.42820"
"398.08801","33.17404","0.42787"
"398.42999","33.20262","0.43678"
"398.77200","33.23114","0.43366"
"399.11401","33.25954","0.44512"
"399.45599","33.28818","0.44254"
"399.79800","33.31664","0.45252"
"400.14001","33.34510","0.45399"
"400.48199","33.37362","0.46499"
"400.82401","33.40208","0.46979"
"401.16599","33.43060","0.47555"
"401.50800","33.45918","0.47539"
"401.85001","33.48758","0.48076"
"402.19199","33.51616","0.48529"
"402.53400","33.54462","0.49040"
"402.87601","33.57307","0.49401"
"403.21799","33.60160","0.49833"
"403.56000","33.63012","0.50052"
"403.90201","33.65858","0.50380"
"404.24399","33.68710","0.50334"
"404.58600","33.71562","0.50885"
"404.92801","33.74413","0.50941"
"405.26999","33.77259","0.51716"
"405.61200","33.80106","0.52197"
"405.95401","33.82963","0.52964"
"406.29599","33.85809","0.53063"
"406.63800","33.88662","0.53464"
"406.98001","33.91513","0.54029"
"407.32199","33.94359","0.54571"
"407.66400","33.97211","0.55449"
"408.00601","34.00063","0.55682"
"408.34799","34.02909","0.55940"
"408.69000","34.05761","0.56402"
"409.03201","34.08613","0.56856"
"409.37399","34.11459","0.57711"
"409.71600","34.14311","0.57941"
"410.05801","34.17169","0.58037"
"410.39999","34.20009","0.44747"
"410.74200","34.22861","0.45211"
"411.08401","34.25713","0.45318"
"411.42599","34.28559","0.46109"
"411.76801","34.31417","0.46337"
"412.10999","34.34263","0.47213"
"412.45200","34.37103","0.47421"
"412.79401","34.39961","0.48233"
"413.13599","34.42813","0.48366"
"413.47800","34.45665","0.48988"
"413.82001","34.48517","0.49225"
"414.16199","34.51357","0.49544"
"414.50400","34.54215","0.49777"
"414.84601","34.57061","0.50014"
"415.18799","34.59907","0.50146"
"415.53000","34.62765","0.50436"
"415.87201","34.65611","0.50768"
"416.21399","34.68457","0.50979"
"416.55600","34.71315","0.51377"
"416.89801","34.74154","0.51683"
"417.23999","34.77012","0.52333"
"417.58200","34.79865","0.52589"
"417.92401","34.82710","0.53041"
"418.26599","34.85562","0.53456"
"418.60800","34.88414","0.53941"
"418.95001","34.91260","0.54609"
"419.29199","34.94112","0.55011"
"419.63400","34.96964","0.55494"
"419.97601","34.99810","0.55858"
"420.31799","35.02668","0.56336"
"420.66000","35.05502","0.56889"
"421.00201","35.08360","0.57435"
"421.34399","35.11212","0.57969"
"421.68600","35.14058","0.58202"
"422.02802","35.16916","0.58446"
"422.37000","35.19762","0.58764"
"422.71201","35.22614","0.59014"
"423.05399","35.25466","0.59337"
"423.39600","35.28306","0.59549"
"423.73801","35.31164","0.59709"
"424.07999","35.34016","0.59996"
"424.42200","35.36856","0.60350"
"424.76401","35.39714","0.60703"
"425.10599","35.42559","0.61186"
"425.44800","35.45406","0.61687"
"425.79001","35.48264","0.62330"
"426.13199","35.51110","0.63065"
"426.47400","35.53962","0.63542"
"426.81601","35.56808","0.63935"
"427.15799","35.59660","0.64400"
"427.50000","35.62511","0.64888"
"427.84201","35.65364","0.65345"
"428.18399","35.68209","0.65783"
"428.52600","35.71061","0.66299"
"428.86801","35.73907","0.66735"
"429.20999","35.76759","0.67240"
"429.55200","35.79611","0.67739"
"429.89401","35.82463","0.68323"
"430.23599","35.85309","0.68806"
"430.57800","35.88161","0.69185"
"430.92001","35.91013","0.69540"
"431.26199","35.93859","0.69772"
"431.60400","35.96717","0.70025"
"431.94601","35.99551","0.70211"
"432.28799","36.02415","0.70534"
"432.63000","36.05261","0.70866"
"432.97198","36.08107","0.71202"
"433.31400","36.10965","0.71498"
"433.65601","36.13811","0.71920"
"433.99799","36.16657","0.72372"
"434.34000","36.19515","0.72927"
"434.68201","36.22355","0.73741"
"435.02399","36.25212","0.74366"
"435.36600","36.28065","0.74785"
"435.70801","36.30905","0.75289"
"436.04999","36.33762","0.75848"
"436.39200","36.36615","0.76384"
"436.73401","36.39461","0.76987"
"437.07599","36.42318","0.77900"
"437.41800","36.45158","0.78440"
"437.76001","36.48011","0.79070"
"438.10199","36.50863","0.79541"
"438.44400","36.53709","0.79874"
"438.78601","36.56567","0.80309"
"439.12799","36.59418","0.80667"
"439.47000","36.62252","0.80803"
"439.81201","36.65117","0.81045"
"440.15399","36.67962","0.81326"
"440.49600","36.70808","0.81701"
"440.83801","36.73660","0.82048"
"441.17999","36.76506","0.82469"
"441.52200","36.79358","0.82933"
"441.86401","36.82210","0.83510"
"442.20599","36.85056","0.83960"
"442.54800","36.87914","0.84412"
"442.89001","36.90766","0.84825"
"443.23199","36.93612","0.85247"
"443.57401","36.96464","0.85779"
"443.91599","36.99310","0.86289"
"444.25800","37.02156","0.86780"
"444.60001","37.05014","0.87482"
"444.94199","37.07860","0.88052"
"445.28400","37.10718","0.88700"
"445.62601","37.13564","0.89176"
"445.96799","37.16410","0.89616"
"446.31000","37.19256","0.90003"
"446.65201","37.22108","0.90331"
"446.99399","37.24960","0.90720"
"447.33600","37.27811","0.91057"
"447.67801","37.30664","0.91528"
"448.01999","37.33509","0.92037"
"448.36200","37.36361","0.92678"
"448.70401","37.39214","0.93397"
"449.04599","37.42059","0.94249"
"449.38800","37.44917","0.94882"
"449.73001","37.47757","0.95462"
"450.07199","37.50609","0.96030"
"450.41400","37.53461","0.96644"
"450.75601","37.56308","0.97272"
"451.09799","37.59165","0.97748"
"451.44000","37.62011","0.98361"
"451.78201","37.64863","0.98960"
"452.12399","37.67715","0.99458"
"452.46600","37.70555","0.99836"
"452.80801","37.73407","1.00096"
"453.14999","37.76265","1.00317"
"453.49200","37.79105","1.00555"
"453.83401","37.81957","1.00841"
"454.17599","37.84815","1.01255"
"454.51801","37.87661","1.01631"
"454.85999","37.90513","1.02053"
"455.20200","37.93359","1.02605"
"455.54401","37.96211","1.03432"
"455.88599","37.99063","1.04185"
"456.22800","38.01909","1.04547"
"456.57001","38.04767","1.05034"
"456.91199","38.07613","1.05613"
"457.25400","38.10453","1.06202"
"457.59601","38.13317","1.06732"
"457.93799","38.16163","1.07508"
"458.28000","38.19003","1.08378"
"458.62201","38.21867","1.09267"
"458.96399","38.24706","1.10083"
"459.30600","38.27559","1.10751"
"459.64801","38.30416","1.11291"
"459.98999","38.33256","1.11691"
"460.33200","38.36115","1.11947"
"460.67401","38.38960","1.12119"
"461.01599","38.41806","1.12302"
"461.35800","38.44670","1.12606"
"461.70001","38.47511","1.12910"
"462.04199","38.50362","1.13352"
"462.38400","38.53214","1.13867"
"462.72601","38.56060","1.14393"
"463.06799","38.58906","1.14981"
"463.41000","38.61758","1.15631"
"463.75201","38.64610","1.16329"
"464.09399","38.67462","1.16940"
"464.43600","38.70314","1.17536"
"464.77802","38.73154","1.18291"
"465.12000","38.76018","1.19403"
"465.46201","38.78864","1.20132"
"465.80399","38.81710","1.20736"
"466.14600","38.84562","1.21132"
"466.48801","38.87414","1.21522"
"466.82999","38.90260","1.21433"
"467.17200","38.93112","1.21789"
"467.51401","38.95958","1.22251"
"467.85599","38.98810","1.22824"
"468.19800","39.01662","1.23426"
"468.54001","39.04508","1.24176"
"468.88199","39.07366","1.25010"
"469.22400","39.10212","1.25895"
"469.56601","39.13058","1.26311"
"469.90799","39.15910","1.26645"
"470.25000","39.18761","1.27007"
"470.59201","39.21608","1.27470"
"470.93399","39.24471","1.27965"
"471.27600","39.27305","1.28592"
"471.61801","39.30163","1.29433"
"471.95999","39.33015","1.30081"
"472.30200","39.35855","1.30522"
"472.64401","39.38713","1.31081"
"472.98599","39.41565","1.31633"
"473.32800","39.44405","1.32140"
"473.67001","39.47269","1.32614"
"474.01199","39.50115","1.33132"
"474.35400","39.52961","1.33889"
"474.69601","39.55813","1.34644"
"475.03799","39.58653","1.35432"
"475.38000","39.61517","1.31430"
"475.72198","39.64368","1.31937"
"476.06400","39.67209","1.32347"
"476.40601","39.70061","1.32779"
"476.74799","39.72907","1.33348"
"477.09000","39.75759","1.34246"
"477.43201","39.78610","1.35152"
"477.77399","39.81456","1.35986"
"478.11600","39.84314","1.36640"
"478.45801","39.87160","1.37242"
"478.79999","39.90006","1.37854"
"479.14200","39.92859","1.38677"
"479.48401","39.95711","1.39469"
"479.82599","39.98563","1.40204"
"480.16800","40.01414","1.40956"
"480.51001","40.04261","1.41309"
"480.85199","40.07113","1.41764"
"481.19400","40.09964","1.42052"
"481.53601","40.12811","1.42214"
"481.87799","40.15662","1.42233"
"482.22000","40.18508","1.42327"
"482.56201","40.21360","1.42499"
"482.90399","40.24212","1.42794"
"483.24600","40.27064","1.43203"
"483.58801","40.29904","1.43803"
"483.92999","40.32763","1.44611"
"484.27200","40.35614","1.45414"
"484.61401","40.38454","1.46090"
"484.95599","40.41312","1.46875"
"485.29800","40.44158","1.47609"
"485.64001","40.47010","1.48197"
"485.98199","40.49868","1.48847"
"486.32401","40.52708","1.49542"
"486.66599","40.55560","1.50423"
"487.00800","40.58412","1.51035"
"487.35001","40.61252","1.22880"
"487.69199","40.64116","1.23209"
"488.03400","40.66962","0.61394"
"488.37601","40.69813","0.62634"
"488.71799","40.72666","0.62420"
"489.06000","40.75512","0.60843"
"489.40201","40.78358","0.61920"
"489.74399","40.81210","0.62132"
"490.08600","40.84055","0.63877"
"490.42801","40.86914","0.67478"
"490.76999","40.89766","0.66444"
"491.11200","40.92599","0.65205"
"491.45401","40.95464","0.66286"
"491.79599","40.98310","0.67002"
"492.13800","41.01155","0.69852"
"492.48001","41.04019","0.69803"
"492.82199","41.06853","0.69019"
"493.16400","41.09711","0.69610"
"493.50601","41.12563","0.70198"
"493.84799","41.15409","0.72277"
"494.19000","41.18267","0.71373"
"494.53201","41.21113","0.71206"
"494.87399","41.23959","0.71632"
"495.21600","41.26817","0.74337"
"495.55801","41.29663","0.74672"
"495.89999","41.32509","0.74028"
"496.24200","41.35361","0.75063"
"496.58401","41.38207","0.77794"
"496.92599","41.41059","0.77746"
"497.26801","41.43911","0.77066"
"497.60999","41.46757","0.78272"
"497.95200","41.49609","0.80520"
"498.29401","41.52460","0.80045"
"498.63599","41.55312","0.80259"
"498.97800","41.58165","0.80942"
"499.32001","41.61016","0.81733"
"499.66199","41.63863","0.81268"
"500.00400","41.66709","0.81719"
"500.34601","41.69561","0.83680"
"500.68799","41.72412","0.82816"
"501.03000","41.75265","0.83337"
"501.37201","41.78104","0.84982"
"501.71399","41.80957","0.84821"
"502.05600","41.83814","0.85025"
"502.39801","41.86660","0.86605"
"502.73999","41.89512","0.87007"
"503.08200","41.92364","0.86992"
"503.42401","41.95205","0.88717"
"503.76599","41.98063","0.89122"
"504.10800","42.00908","0.89113"
"504.45001","42.03760","0.90330"
"504.79199","42.06612","0.90487"
"505.13400","42.09458","0.90695"
"505.47601","42.12310","0.92069"
"505.81799","42.15162","0.91912"
"506.16000","42.18014","0.92499"
"506.50201","42.20866","0.94565"
"506.84399","42.23712","0.93719"
"507.18600","42.26558","0.94908"
"507.52802","42.29416","0.95994"
"507.87000","42.32256","0.96004"
"508.21201","42.35114","0.97507"
"508.55399","42.37965","0.97566"
"508.89600","42.40806","0.98185"
"509.11200","42.42618","0.98514"