File: Force_trajectories/170107_2/Specimen_RawData_8.csv
End date,"1/7/2017"
Specimen label,"20CG_58"
Maximum Load,"0.70788",N

Time,Extension,Load
(s),(mm),(N)
"0.00000","0.00000","-0.00020"
"0.32400","0.02673","0.00039"
"0.64800","0.05423","0.00111"
"0.97200","0.08119","0.00182"
"1.29600","0.10822","0.00207"
"1.62000","0.13524","0.00265"
"1.94400","0.16221","0.00298"
"2.26800","0.18923","0.00308"
"2.59200","0.21620","0.00304"
"2.91600","0.24322","0.00397"
"3.24000","0.27025","0.00333"
"3.56400","0.29721","0.00374"
"3.88800","0.32424","0.00430"
"4.21200","0.35114","0.00385"
"4.53600","0.37823","0.00399"
"4.86000","0.40525","0.00408"
"5.18400","0.43222","0.00458"
"5.50800","0.45924","0.00431"
"5.83200","0.48621","0.00490"
"6.15600","0.51323","0.00436"
"6.48000","0.54026","0.00463"
"6.80400","0.56722","0.00500"
"7.12800","0.59425","0.00561"
"7.45200","0.62121","0.00537"
"7.77600","0.64824","0.00422"
"8.10000","0.67526","0.00514"
"8.42400","0.70223","0.00453"
"8.74800","0.72925","0.00549"
"9.07200","0.75616","0.00537"
"9.39600","0.78318","0.00552"
"9.72000","0.81027","0.00497"
"10.04400","0.83717","0.00577"
"10.36800","0.86426","0.00517"
"10.69200","0.89122","0.00602"
"11.01600","0.91825","0.00557"
"11.34000","0.94533","0.00543"
"11.66400","0.97218","0.00508"
"11.98800","0.99926","0.00552"
"12.31200","1.02629","0.00519"
"12.63600","1.05325","0.00608"
"12.96000","1.08028","0.00566"
"13.28400","1.10718","0.00602"
"13.60800","1.13427","0.00631"
"13.93200","1.16117","0.00618"
"14.25600","1.18826","0.00604"
"14.58000","1.21522","0.00631"
"14.90400","1.24219","0.00646"
"15.22800","1.26927","0.00646"
"15.55200","1.29618","0.00639"
"15.87600","1.32320","0.00626"
"16.20000","1.35029","0.00696"
"16.52400","1.37713","0.00717"
"16.84800","1.40422","0.00690"
"17.17200","1.43118","0.00677"
"17.49600","1.45827","0.00689"
"17.82000","1.48523","0.00705"
"18.14400","1.51214","0.00685"
"18.46800","1.53928","0.00726"
"18.79200","1.56625","0.00705"
"19.11600","1.59321","0.00681"
"19.44000","1.62024","0.00695"
"19.76400","1.64720","0.00743"
"20.08800","1.67423","0.00701"
"20.41200","1.70119","0.00733"
"20.73600","1.72816","0.00774"
"21.06000","1.75524","0.00737"
"21.38400","1.78221","0.00729"
"21.70800","1.80929","0.00649"
"22.03200","1.83620","0.00688"
"22.35600","1.86316","0.00722"
"22.68000","1.89025","0.00655"
"23.00400","1.91721","0.00615"
"23.32800","1.94424","0.00634"
"23.65200","1.97126","0.00662"
"23.97600","1.99823","0.00664"
"24.30000","2.02525","0.00663"
"24.62400","2.05216","0.00694"
"24.94800","2.07924","0.00689"
"25.27200","2.10621","0.00762"
"25.59600","2.13323","0.00691"
"25.92000","2.16020","0.00704"
"26.24400","2.18728","0.00674"
"26.56800","2.21425","0.00660"
"26.89200","2.24121","0.00658"
"27.21600","2.26824","0.00759"
"27.54000","2.29526","0.00700"
"27.86400","2.32217","0.00736"
"28.18800","2.34919","0.00754"
"28.51200","2.37628","0.00770"
"28.83600","2.40324","0.00781"
"29.16000","2.43021","0.00815"
"29.48400","2.45723","0.00798"
"29.80800","2.48426","0.00818"
"30.13200","2.51128","0.00830"
"30.45600","2.53825","0.00816"
"30.78000","2.56521","0.00821"
"31.10400","2.59218","0.00810"
"31.42800","2.61926","0.00771"
"31.75200","2.64622","0.00769"
"32.07600","2.67319","0.00887"
"32.40000","2.70027","0.00791"
"32.72400","2.72724","0.00855"
"33.04800","2.75426","0.00851"
"33.37200","2.78117","0.00844"
"33.69600","2.80819","0.00839"
"34.02000","2.83528","0.00868"
"34.34400","2.86218","0.00875"
"34.66800","2.88927","0.00859"
"34.99200","2.91617","0.00896"
"35.31600","2.94314","0.00902"
"35.64000","2.97022","0.00885"
"35.96400","2.99719","0.00821"
"36.28800","3.02427","0.00774"
"36.61200","3.05124","0.00739"
"36.93600","3.07820","0.00733"
"37.26000","3.10523","0.00801"
"37.58400","3.13219","0.00764"
"37.90800","3.15922","0.00838"
"38.23200","3.18624","0.00804"
"38.55600","3.21321","0.00848"
"38.88000","3.24023","0.00869"
"39.20400","3.26720","0.00871"
"39.52800","3.29422","0.00881"
"39.85200","3.32125","0.00892"
"40.17600","3.34821","0.00899"
"40.50000","3.37524","0.00898"
"40.82400","3.40214","0.00937"
"41.14800","3.42923","0.00930"
"41.47200","3.45631","0.00892"
"41.79600","3.48316","0.00959"
"42.12000","3.51024","0.00835"
"42.44400","3.53721","0.00888"
"42.76800","3.56423","0.00790"
"43.09200","3.59126","0.00895"
"43.41600","3.61816","0.00849"
"43.74000","3.64525","0.00915"
"44.06400","3.67221","0.00926"
"44.38800","3.69924","0.00886"
"44.71200","3.72620","0.00905"
"45.03600","3.75317","0.00910"
"45.36000","3.78025","0.00945"
"45.68400","3.80722","0.00927"
"46.00800","3.83418","0.00928"
"46.33200","3.86127","0.00924"
"46.65600","3.88823","0.00962"
"46.98000","3.91526","0.00923"
"47.30400","3.94222","0.00945"
"47.62800","3.96925","0.00940"
"47.95200","3.99627","0.00960"
"48.27600","4.02312","0.00980"
"48.60000","4.05026","0.01002"
"48.92400","4.07729","0.01034"
"49.24800","4.10425","0.01021"
"49.57200","4.13128","0.01048"
"49.89600","4.15818","0.01040"
"50.22000","4.18521","0.00988"
"50.54400","4.21217","0.00962"
"50.86800","4.23920","0.00969"
"51.19200","4.26628","0.01031"
"51.51600","4.29319","0.01031"
"51.84000","4.32027","0.01060"
"52.16400","4.34718","0.01022"
"52.48800","4.37420","0.01063"
"52.81200","4.40129","0.01096"
"53.13600","4.42813","0.01101"
"53.46000","4.45522","0.01105"
"53.78400","4.48224","0.01133"
"54.10800","4.50921","0.01179"
"54.43200","4.53623","0.01143"
"54.75600","4.56314","0.01168"
"55.08000","4.59028","0.01176"
"55.40400","4.61719","0.01192"
"55.72800","4.64421","0.01188"
"56.05200","4.67124","0.01258"
"56.37600","4.69820","0.01240"
"56.70000","4.72529","0.01221"
"57.02400","4.75225","0.01234"
"57.34800","4.77916","0.01292"
"57.67200","4.80624","0.01227"
"57.99600","4.83315","0.01243"
"58.32000","4.86023","0.01281"
"58.64400","4.88720","0.01272"
"58.96800","4.91416","0.01312"
"59.29200","4.94125","0.01258"
"59.61600","4.96815","0.01320"
"59.94000","4.99524","0.01308"
"60.26400","5.02226","0.01332"
"60.58800","5.04923","0.01345"
"60.91200","5.07619","0.01338"
"61.23600","5.10316","0.01355"
"61.56000","5.13024","0.01338"
"61.88400","5.15721","0.01334"
"62.20800","5.18423","0.01343"
"62.53200","5.21126","0.01389"
"62.85600","5.23822","0.01411"
"63.18000","5.26519","0.01341"
"63.50400","5.29221","0.01362"
"63.82800","5.31924","0.01385"
"64.15200","5.34626","0.01427"
"64.47600","5.37323","0.01414"
"64.80000","5.40019","0.01431"
"65.12400","5.42728","0.01416"
"65.44800","5.45418","0.01492"
"65.77200","5.48127","0.01482"
"66.09600","5.50817","0.01488"
"66.42000","5.53525","0.01528"
"66.74400","5.56228","0.01498"
"67.06800","5.58919","0.01540"
"67.39200","5.61621","0.01503"
"67.71600","5.64324","0.01578"
"68.04000","5.67026","0.01577"
"68.36400","5.69723","0.01570"
"68.68800","5.72419","0.01592"
"69.01200","5.75128","0.01535"
"69.33600","5.77824","0.01544"
"69.66000","5.80520","0.01586"
"69.98400","5.83229","0.01566"
"70.30800","5.85920","0.01561"
"70.63200","5.88622","0.01634"
"70.95600","5.91319","0.01671"
"71.28000","5.94021","0.01615"
"71.60400","5.96729","0.01643"
"71.92800","5.99420","0.01617"
"72.25200","6.02122","0.01692"
"72.57600","6.04825","0.01724"
"72.90000","6.07527","0.01695"
"73.22400","6.10224","0.01744"
"73.54800","6.12914","0.01718"
"73.87200","6.15623","0.01819"
"74.19600","6.18325","0.01789"
"74.52000","6.21022","0.01714"
"74.84400","6.23724","0.01774"
"75.16800","6.26415","0.01800"
"75.49200","6.29123","0.01867"
"75.81600","6.31820","0.01783"
"76.14000","6.34516","0.01834"
"76.46400","6.37225","0.01919"
"76.78800","6.39915","0.01879"
"77.11200","6.42624","0.01944"
"77.43600","6.45320","0.01938"
"77.76000","6.48023","0.01983"
"78.08400","6.50719","0.02001"
"78.40800","6.53416","0.02060"
"78.73200","6.56124","0.02082"
"79.05600","6.58821","0.02026"
"79.38000","6.61523","0.02039"
"79.70400","6.64220","0.02010"
"80.02800","6.66916","0.02011"
"80.35200","6.69625","0.02058"
"80.67600","6.72327","0.01990"
"81.00000","6.75018","0.01962"
"81.32400","6.77726","0.02010"
"81.64800","6.80417","0.02066"
"81.97200","6.83125","0.02029"
"82.29600","6.85822","0.02114"
"82.62000","6.88518","0.02097"
"82.94400","6.91227","0.02124"
"83.26800","6.93911","0.02138"
"83.59200","6.96626","0.02018"
"83.91600","6.99322","0.02122"
"84.24000","7.02025","0.02136"
"84.56400","7.04721","0.02098"
"84.88800","7.07418","0.02157"
"85.21200","7.10132","0.02185"
"85.53600","7.12817","0.02229"
"85.86000","7.15519","0.02014"
"86.18400","7.18222","0.02095"
"86.50800","7.20918","0.02193"
"86.83200","7.23627","0.02134"
"87.15600","7.26323","0.02166"
"87.48000","7.29020","0.02156"
"87.80400","7.31722","0.02212"
"88.12800","7.34419","0.02267"
"88.45200","7.37121","0.02271"
"88.77600","7.39818","0.02287"
"89.10000","7.42520","0.02311"
"89.42400","7.45223","0.02457"
"89.74800","7.47919","0.02433"
"90.07200","7.50622","0.02450"
"90.39600","7.53324","0.02499"
"90.72000","7.56015","0.02492"
"91.04400","7.58717","0.02607"
"91.36800","7.61420","0.02618"
"91.69200","7.64122","0.02605"
"92.01600","7.66825","0.02650"
"92.34000","7.69515","0.02684"
"92.66400","7.72224","0.02662"
"92.98800","7.74920","0.02437"
"93.31200","7.77623","0.02358"
"93.63600","7.80319","0.02350"
"93.96000","7.83016","0.02402"
"94.28400","7.85724","0.02440"
"94.60800","7.88421","0.02527"
"94.93200","7.91123","0.02527"
"95.25600","7.93826","0.02650"
"95.58000","7.96516","0.02694"
"95.90400","7.99225","0.02690"
"96.22800","8.01915","0.02783"
"96.55200","8.04630","0.02749"
"96.87600","8.07326","0.02781"
"97.20000","8.10023","0.02795"
"97.52400","8.12719","0.02788"
"97.84800","8.15422","0.02813"
"98.17200","8.18118","0.02868"
"98.49600","8.20821","0.02819"
"98.82000","8.23517","0.02882"
"99.14400","8.26226","0.02944"
"99.46800","8.28922","0.03024"
"99.79200","8.31625","0.03016"
"100.11600","8.34327","0.02784"
"100.44000","8.37018","0.02821"
"100.76400","8.39720","0.02854"
"101.08800","8.42411","0.02956"
"101.41200","8.45119","0.02988"
"101.73600","8.47822","0.03087"
"102.06000","8.50518","0.03123"
"102.38400","8.53227","0.03113"
"102.70800","8.55923","0.03207"
"103.03200","8.58626","0.03243"
"103.35600","8.61328","0.03320"
"103.68000","8.64019","0.03313"
"104.00400","8.66727","0.03381"
"104.32800","8.69423","0.03433"
"104.65200","8.72126","0.03435"
"104.97600","8.74828","0.03521"
"105.30000","8.77525","0.03565"
"105.62400","8.80227","0.03537"
"105.94800","8.82918","0.03660"
"106.27200","8.85620","0.03691"
"106.59600","8.88329","0.03715"
"106.92000","8.91020","0.03816"
"107.24400","8.93728","0.03834"
"107.56800","8.96424","0.03878"
"107.89200","8.99127","0.03913"
"108.21600","9.01824","0.03988"
"108.54000","9.04514","0.04034"
"108.86400","9.07222","0.04103"
"109.18800","9.09925","0.04179"
"109.51200","9.12621","0.04300"
"109.83600","9.15324","0.04304"
"110.16000","9.18021","0.04301"
"110.48400","9.20729","0.04379"
"110.80800","9.23425","0.04432"
"111.13200","9.26122","0.04550"
"111.45600","9.28818","0.04577"
"111.78000","9.31521","0.04638"
"112.10400","9.34223","0.04739"
"112.42800","9.36920","0.04794"
"112.75200","9.39622","0.04853"
"113.07600","9.42331","0.04903"
"113.40000","9.45015","0.05026"
"113.72400","9.47718","0.05111"
"114.04800","9.50420","0.05189"
"114.37200","9.53123","0.05116"
"114.69600","9.55825","0.05114"
"115.02000","9.58516","0.05193"
"115.34400","9.61224","0.05265"
"115.66800","9.63927","0.05343"
"115.99200","9.66623","0.05440"
"116.31600","9.69320","0.05514"
"116.64000","9.72016","0.05598"
"116.96400","9.74725","0.05622"
"117.28800","9.77421","0.05726"
"117.61200","9.80118","0.05797"
"117.93600","9.82826","0.05855"
"118.26000","9.85517","0.05882"
"118.58400","9.88225","0.05943"
"118.90800","9.90922","0.06022"
"119.23200","9.93618","0.06068"
"119.55600","9.96327","0.06095"
"119.88000","9.99017","0.06135"
"120.20400","10.01726","0.06200"
"120.52800","10.04422","0.06265"
"120.85200","10.07119","0.06291"
"121.17600","10.09815","0.06339"
"121.50000","10.12518","0.06407"
"121.82400","10.15226","0.06431"
"122.14800","10.17923","0.06477"
"122.47200","10.20625","0.06544"
"122.79600","10.23328","0.06549"
"123.12000","10.26018","0.06605"
"123.44400","10.28721","0.06655"
"123.76800","10.31423","0.06705"
"124.09200","10.34120","0.06824"
"124.41600","10.36822","0.06818"
"124.74000","10.39519","0.06895"
"125.06400","10.42227","0.06944"
"125.38800","10.44930","0.06988"
"125.71200","10.47620","0.07013"
"126.03600","10.50323","0.07127"
"126.36000","10.53019","0.07177"
"126.68400","10.55728","0.07284"
"127.00800","10.58424","0.07426"
"127.33200","10.61121","0.07486"
"127.65600","10.63829","0.07569"
"127.98000","10.66520","0.07660"
"128.30400","10.69222","0.07623"
"128.62801","10.71919","0.07660"
"128.95200","10.74621","0.07859"
"129.27600","10.77330","0.07989"
"129.60001","10.80020","0.08155"
"129.92400","10.82723","0.08286"
"130.24800","10.85425","0.08391"
"130.57201","10.88122","0.08503"
"130.89600","10.90824","0.08661"
"131.22000","10.93521","0.08890"
"131.54401","10.96223","0.09074"
"131.86800","10.98926","0.09258"
"132.19200","11.01616","0.09468"
"132.51601","11.04319","0.09683"
"132.84000","11.07021","0.09718"
"133.16400","11.09724","0.10012"
"133.48801","11.12426","0.10207"
"133.81200","11.15111","0.10407"
"134.13600","11.17825","0.10599"
"134.46001","11.20522","0.10774"
"134.78400","11.23224","0.10886"
"135.10800","11.25927","0.11122"
"135.43201","11.28617","0.11211"
"135.75600","11.31326","0.11424"
"136.08000","11.34022","0.11487"
"136.40401","11.36718","0.11626"
"136.72800","11.39427","0.11767"
"137.05200","11.42118","0.11960"
"137.37601","11.44826","0.12104"
"137.70000","11.47517","0.12102"
"138.02400","11.50225","0.12142"
"138.34801","11.52928","0.11401"
"138.67200","11.55612","0.08034"
"138.99600","11.58327","0.08436"
"139.32001","11.61017","0.08836"
"139.64400","11.63720","0.09304"
"139.96800","11.66422","0.09858"
"140.29201","11.69119","0.10390"
"140.61600","11.71827","0.10844"
"140.94000","11.74518","0.11234"
"141.26401","11.77220","0.11525"
"141.58800","11.79922","0.11856"
"141.91200","11.82619","0.12266"
"142.23599","11.85321","0.12499"
"142.56000","11.88024","0.12760"
"142.88400","11.90721","0.12953"
"143.20799","11.93423","0.13184"
"143.53200","11.96119","0.13426"
"143.85600","11.98822","0.13580"
"144.17999","12.01518","0.13658"
"144.50400","12.04221","0.13795"
"144.82800","12.06923","0.13994"
"145.15199","12.09614","0.14128"
"145.47600","12.12329","0.14292"
"145.80000","12.15025","0.14513"
"146.12399","12.17721","0.14683"
"146.44800","12.20424","0.14873"
"146.77200","12.23114","0.15058"
"147.09599","12.25829","0.15306"
"147.42000","12.28525","0.15460"
"147.74400","12.31222","0.15597"
"148.06799","12.33924","0.15741"
"148.39200","12.36621","0.15962"
"148.71600","12.39323","0.16088"
"149.03999","12.42026","0.16281"
"149.36400","12.44722","0.16465"
"149.68800","12.47425","0.16623"
"150.01199","12.50115","0.16761"
"150.33600","12.52824","0.16929"
"150.66000","12.55526","0.17012"
"150.98399","12.58217","0.17118"
"151.30800","12.60925","0.17244"
"151.63200","12.63622","0.17331"
"151.95599","12.66324","0.17420"
"152.28000","12.69021","0.17493"
"152.60400","12.71717","0.17604"
"152.92799","12.74426","0.17682"
"153.25200","12.77122","0.17791"
"153.57600","12.79825","0.17887"
"153.89999","12.82521","0.18047"
"154.22400","12.85224","0.18161"
"154.54800","12.87920","0.18292"
"154.87199","12.90617","0.18453"
"155.19600","12.93325","0.18641"
"155.52000","12.96028","0.18804"
"155.84399","12.98718","0.18945"
"156.16800","13.01421","0.19051"
"156.49200","13.04117","0.19200"
"156.81599","13.06820","0.19360"
"157.14000","13.09528","0.19522"
"157.46400","13.12219","0.19710"
"157.78799","13.14921","0.19954"
"158.11200","13.17624","0.20124"
"158.43600","13.20320","0.20410"
"158.75999","13.23023","0.20612"
"159.08400","13.25719","0.20861"
"159.40800","13.28428","0.21004"
"159.73199","13.31118","0.21194"
"160.05600","13.33821","0.21223"
"160.38000","13.36523","0.21404"
"160.70399","13.39226","0.21593"
"161.02800","13.41928","0.21786"
"161.35201","13.44619","0.21985"
"161.67599","13.47327","0.22183"
"162.00000","13.50030","0.22429"
"162.32401","13.52720","0.22586"
"162.64799","13.55423","0.22795"
"162.97200","13.58119","0.22970"
"163.29601","13.60822","0.23291"
"163.62000","13.63524","0.23417"
"163.94400","13.66221","0.23778"
"164.26801","13.68923","0.23893"
"164.59200","13.71626","0.24134"
"164.91600","13.74322","0.24425"
"165.24001","13.77025","0.24713"
"165.56400","13.79721","0.24877"
"165.88800","13.82424","0.25175"
"166.21201","13.85120","0.25392"
"166.53600","13.87817","0.25586"
"166.86000","13.90525","0.25812"
"167.18401","13.93222","0.26125"
"167.50800","13.95924","0.26317"
"167.83200","13.98621","0.26493"
"168.15601","14.01323","0.26683"
"168.48000","14.04032","0.26805"
"168.80400","14.06716","0.27046"
"169.12801","14.09425","0.27289"
"169.45200","14.12127","0.27447"
"169.77600","14.14824","0.27590"
"170.10001","14.17526","0.27697"
"170.42400","14.20217","0.27802"
"170.74800","14.22925","0.27957"
"171.07201","14.25622","0.28036"
"171.39600","14.28324","0.28111"
"171.72000","14.31021","0.28181"
"172.04401","14.33723","0.28274"
"172.36800","14.36426","0.28327"
"172.69200","14.39122","0.28381"
"173.01601","14.41819","0.28447"
"173.34000","14.44527","0.28553"
"173.66400","14.47218","0.28615"
"173.98801","14.49920","0.28704"
"174.31200","14.52629","0.28763"
"174.63600","14.55325","0.28887"
"174.96001","14.58022","0.28953"
"175.28400","14.60712","0.29061"
"175.60800","14.63421","0.29202"
"175.93201","14.66123","0.29317"
"176.25600","14.68820","0.29528"
"176.58000","14.71522","0.29592"
"176.90401","14.74219","0.29926"
"177.22800","14.76921","0.30014"
"177.55200","14.79624","0.30338"
"177.87601","14.82320","0.30539"
"178.20000","14.85028","0.30722"
"178.52400","14.87713","0.31007"
"178.84801","14.90428","0.31187"
"179.17200","14.93124","0.31359"
"179.49600","14.95820","0.31694"
"179.82001","14.98523","0.31905"
"180.14400","15.01214","0.32082"
"180.46800","15.03922","0.32402"
"180.79201","15.06619","0.32625"
"181.11600","15.09321","0.32929"
"181.44000","15.12018","0.33225"
"181.76401","15.14714","0.33479"
"182.08800","15.17422","0.33788"
"182.41200","15.20119","0.34008"
"182.73599","15.22821","0.34224"
"183.06000","15.25524","0.34402"
"183.38400","15.28220","0.34537"
"183.70799","15.30923","0.34773"
"184.03200","15.33620","0.34990"
"184.35600","15.36316","0.35224"
"184.67999","15.39025","0.35413"
"185.00400","15.41721","0.35647"
"185.32800","15.44423","0.35868"
"185.65199","15.47126","0.35969"
"185.97600","15.49817","0.36205"
"186.30000","15.52519","0.36317"
"186.62399","15.55216","0.36484"
"186.94800","15.57924","0.36588"
"187.27200","15.60626","0.36744"
"187.59599","15.63317","0.36884"
"187.92000","15.66019","0.36984"
"188.24400","15.68716","0.37137"
"188.56799","15.71424","0.37361"
"188.89200","15.74127","0.37486"
"189.21600","15.76823","0.37652"
"189.53999","15.79526","0.37747"
"189.86400","15.82216","0.37891"
"190.18800","15.84925","0.38025"
"190.51199","15.87621","0.38172"
"190.83600","15.90324","0.38320"
"191.16000","15.93020","0.38556"
"191.48399","15.95717","0.38705"
"191.80800","15.98419","0.38934"
"192.13200","16.01122","0.39156"
"192.45599","16.03818","0.39224"
"192.78000","16.06521","0.39521"
"193.10400","16.09217","0.39758"
"193.42799","16.11920","0.40010"
"193.75200","16.14628","0.40286"
"194.07600","16.17313","0.40507"
"194.39999","16.20021","0.40772"
"194.72400","16.22718","0.41035"
"195.04800","16.25420","0.41257"
"195.37199","16.28123","0.41485"
"195.69600","16.30819","0.41656"
"196.02000","16.33522","0.41845"
"196.34399","16.36218","0.42051"
"196.66800","16.38915","0.42144"
"196.99200","16.41629","0.42333"
"197.31599","16.44320","0.42503"
"197.64000","16.47028","0.42680"
"197.96400","16.49719","0.42834"
"198.28799","16.52421","0.43115"
"198.61200","16.55124","0.43272"
"198.93600","16.57814","0.43548"
"199.25999","16.60523","0.43797"
"199.58400","16.63219","0.44038"
"199.90800","16.65922","0.44296"
"200.23199","16.68630","0.44608"
"200.55600","16.71321","0.44854"
"200.88000","16.74023","0.45128"
"201.20399","16.76720","0.45446"
"201.52800","16.79416","0.45847"
"201.85201","16.82125","0.46276"
"202.17599","16.84821","0.46625"
"202.50000","16.87524","0.47010"
"202.82401","16.90220","0.47452"
"203.14799","16.92917","0.47787"
"203.47200","16.95625","0.48081"
"203.79601","16.98322","0.48319"
"204.12000","17.01024","0.48523"
"204.44400","17.03727","0.48692"
"204.76801","17.06423","0.48855"
"205.09200","17.09126","0.49038"
"205.41600","17.11816","0.49274"
"205.74001","17.14525","0.49411"
"206.06400","17.17227","0.49616"
"206.38800","17.19918","0.49835"
"206.71201","17.22620","0.50080"
"207.03600","17.25323","0.50102"
"207.36000","17.28025","0.50320"
"207.68401","17.30722","0.50616"
"208.00800","17.33424","0.51036"
"208.33200","17.36127","0.51351"
"208.65601","17.38823","0.51728"
"208.98000","17.41525","0.52055"
"209.30400","17.44222","0.52516"
"209.62801","17.46919","0.52874"
"209.95200","17.49621","0.53270"
"210.27600","17.52317","0.53683"
"210.60001","17.55026","0.54031"
"210.92400","17.57729","0.54348"
"211.24800","17.60419","0.54711"
"211.57201","17.63122","0.54994"
"211.89600","17.65818","0.55309"
"212.22000","17.68527","0.55688"
"212.54401","17.71223","0.55984"
"212.86800","17.73926","0.56264"
"213.19200","17.76628","0.56629"
"213.51601","17.79325","0.56859"
"213.84000","17.82021","0.56996"
"214.16400","17.84724","0.57240"
"214.48801","17.87420","0.57458"
"214.81200","17.90129","0.57630"
"215.13600","17.92819","0.57804"
"215.46001","17.95527","0.57977"
"215.78400","17.98224","0.58098"
"216.10800","18.00920","0.58296"
"216.43201","18.03617","0.58440"
"216.75600","18.06314","0.58579"
"217.08000","18.09022","0.58733"
"217.40401","18.11724","0.58858"
"217.72800","18.14421","0.59081"
"218.05200","18.17123","0.59284"
"218.37601","18.19820","0.59528"
"218.70000","18.22523","0.59773"
"219.02400","18.25225","0.60091"
"219.34801","18.27921","0.60464"
"219.67200","18.30630","0.61029"
"219.99600","18.33320","0.61595"
"220.32001","18.36023","0.62117"
"220.64400","18.38725","0.62473"
"220.96800","18.41416","0.62806"
"221.29201","18.44124","0.63144"
"221.61600","18.46815","0.63456"
"221.94000","18.49523","0.63837"
"222.26401","18.52232","0.64251"
"222.58800","18.54922","0.64625"
"222.91200","18.57625","0.65009"
"223.23599","18.60321","0.65373"
"223.56000","18.63024","0.65614"
"223.88400","18.65720","0.65953"
"224.20799","18.68423","0.66336"
"224.53200","18.71125","0.66757"
"224.85600","18.73822","0.67142"
"225.17999","18.76518","0.67473"
"225.50400","18.79221","0.67783"
"225.82800","18.81923","0.68067"
"226.15199","18.84626","0.68311"
"226.47600","18.87317","0.68534"
"226.80000","18.90019","0.68764"
"227.12399","18.92727","0.68964"
"227.44800","18.95424","0.69118"
"227.77200","18.98126","0.69341"
"228.09599","19.00823","0.69570"
"228.42000","19.03519","0.69737"
"228.74400","19.06228","0.69932"
"229.06799","19.08918","0.70099"
"229.39200","19.11621","0.70301"
"229.71600","19.14323","0.70415"
"230.03999","19.17026","0.70580"
"230.36400","19.19728","0.70750"
"230.68800","19.22419","0.70696"
"231.01199","19.25127","-0.00570"
"231.33600","19.27818","-0.00276"
"231.66000","19.30514","-0.00299"
"231.98399","19.33223","0.00039"
"232.30800","19.35919","0.00187"
"232.63200","19.38628","-0.00025"
"232.95599","19.41318","-0.00090"
"233.28000","19.44021","0.00040"
"233.60400","19.46729","0.00040"
"233.92799","19.49420","0.00063"
"234.25200","19.52122","-0.00023"
"234.57600","19.54819","0.00011"
"234.89999","19.57521","0.00038"
"235.22400","19.60224","-0.00013"
"235.54800","19.62914","-0.00076"
"235.87199","19.65623","0.00064"
"236.19600","19.68319","0.00039"
"236.52000","19.71022","0.00016"
"236.84399","19.73724","0.00019"
"237.16800","19.76415","-0.00023"
"237.49200","19.79123","0.00013"
"237.81599","19.81820","0.00003"
"238.14000","19.84522","0.00045"
"238.46400","19.87231","0.00056"
"238.78799","19.89915","0.00075"
"239.11200","19.92624","0.00021"
"239.43600","19.95320","0.00050"
"239.75999","19.98017","0.00027"
"240.08400","20.00725","0.00032"
"240.40800","20.03422","0.00031"
"240.73199","20.06124","-0.00008"
"241.05600","20.08827","0.00037"
"241.38000","20.11517","0.00071"
"241.70399","20.14220","0.00071"
"242.02800","20.16910","0.00126"
"242.35201","20.19631","0.00161"
"242.67599","20.22321","0.00082"
"243.00000","20.25018","0.00153"
"243.32401","20.27720","0.00119"
"243.64799","20.30423","0.00162"
"243.97200","20.33119","0.00143"
"244.29601","20.35822","0.00183"
"244.62000","20.38518","0.00158"
"244.94400","20.41226","0.00144"
"245.26801","20.43917","0.00155"
"245.59200","20.46620","0.00169"
"245.91600","20.49328","0.00154"
"246.24001","20.52019","0.00164"
"246.56400","20.54721","0.00211"
"246.88800","20.57417","0.00185"
"247.21201","20.60126","0.00163"
"247.53600","20.62828","0.00216"
"247.86000","20.65519","0.00264"
"248.18401","20.68222","0.00241"
"248.50800","20.70924","0.00222"
"248.83200","20.73627","0.00275"
"249.15601","20.76323","0.00216"
"249.48000","20.79020","0.00255"
"249.80400","20.81728","0.00253"
"250.12801","20.84425","0.00217"
"250.45200","20.87121","0.00260"
"250.77600","20.89824","0.00285"
"251.10001","20.92526","0.00264"
"251.42400","20.95223","0.00292"
"251.74800","20.97919","0.00290"
"252.07201","21.00616","0.00304"
"252.39600","21.03330","0.00317"
"252.72000","21.06015","0.00290"
"253.04401","21.08723","0.00338"
"253.36800","21.11420","0.00300"
"253.69200","21.14128","0.00312"
"254.01601","21.16825","0.00267"
"254.34000","21.19515","0.00295"
"254.66400","21.22223","0.00260"
"254.98801","21.24920","0.00260"
"255.31200","21.27622","0.00268"
"255.63600","21.30325","0.00295"
"255.96001","21.33021","0.00289"
"256.28400","21.35730","0.00269"
"256.60800","21.38420","0.00250"
"256.93201","21.41117","0.00273"
"257.25601","21.43826","0.00289"
"257.57999","21.46522","0.00332"
"257.90399","21.49224","0.00264"
"258.22800","21.51915","0.00227"
"258.55200","21.54623","0.00220"
"258.87601","21.57326","0.00287"
"259.20001","21.60016","0.00271"
"259.52399","21.62725","0.00243"
"259.84799","21.65421","0.00310"
"260.17200","21.68124","0.00299"
"260.49600","21.70821","0.00283"
"260.82001","21.73517","0.00195"
"261.14401","21.76225","0.00290"
"261.46799","21.78922","0.00289"
"261.79199","21.81618","0.00298"
"262.11600","21.84321","0.00282"
"262.44000","21.87018","0.00193"
"262.76401","21.89726","0.00323"
"263.08801","21.92422","0.00321"
"263.41199","21.95119","0.00309"
"263.73599","21.97827","0.00318"
"264.06000","22.00518","0.00329"
"264.38400","22.03226","0.00307"
"264.70801","22.05923","0.00257"
"265.03201","22.08625","0.00342"
"265.35599","22.11322","0.00284"
"265.67999","22.14018","0.00312"
"266.00400","22.16727","0.00300"
"266.32800","22.19429","0.00282"
"266.65201","22.22120","0.00285"
"266.97601","22.24822","0.00267"
"267.29999","22.27519","0.00267"
"267.62399","22.30227","0.00331"
"267.94800","22.32918","0.00299"
"268.27200","22.35620","0.00332"
"268.59601","22.38323","0.00281"
"268.92001","22.41019","0.00320"
"269.24399","22.43722","0.00271"
"269.56799","22.46418","0.00201"
"269.89200","22.49115","0.00310"
"270.21600","22.51823","0.00267"
"270.54001","22.54520","0.00315"
"270.86401","22.57222","0.00323"
"271.18799","22.59925","0.00363"
"271.51199","22.62621","0.00309"
"271.83600","22.65324","0.00350"
"272.16000","22.68014","0.00315"
"272.48401","22.70723","0.00282"
"272.80801","22.73425","0.00339"
"273.13199","22.76116","0.00308"
"273.45599","22.78824","0.00331"
"273.78000","22.81521","0.00302"
"274.10400","22.84223","0.00329"
"274.42801","22.86920","0.00320"
"274.75201","22.89622","0.00314"
"275.07599","22.92331","0.00322"
"275.39999","22.95015","0.00305"
"275.72400","22.97724","0.00384"
"276.04800","23.00426","0.00374"
"276.37201","23.03117","0.00367"
"276.69601","23.05825","0.00384"
"277.01999","23.08516","0.00428"
"277.34399","23.11224","0.00366"
"277.66800","23.13921","0.00386"
"277.99200","23.16623","0.00400"
"278.31601","23.19320","0.00446"
"278.64001","23.22022","0.00456"
"278.96399","23.24725","0.00362"
"279.28799","23.27421","0.00429"
"279.61200","23.30118","0.00427"
"279.93600","23.32826","0.00447"
"280.26001","23.35517","0.00413"
"280.58401","23.38219","0.00371"
"280.90799","23.40922","0.00411"
"281.23199","23.43618","0.00482"
"281.55600","23.46327","0.00430"
"281.88000","23.49017","0.00477"
"282.20401","23.51720","0.00508"
"282.52802","23.54422","0.00457"
"282.85199","23.57119","0.00444"
"283.17599","23.59821","0.00505"
"283.50000","23.62523","0.00436"
"283.82401","23.65226","0.00443"
"284.14801","23.67923","0.00429"
"284.47198","23.70619","0.00500"
"284.79599","23.73322","0.00473"
"285.12000","23.76018","0.00487"
"285.44400","23.78726","0.00426"
"285.76801","23.81423","0.00445"
"286.09201","23.84120","0.00498"
"286.41599","23.86828","0.00509"
"286.73999","23.89519","0.00515"
"287.06400","23.92215","0.00509"
"287.38800","23.94924","0.00553"
"287.71201","23.97620","0.00495"
"288.03601","24.00328","0.00499"
"288.35999","24.03019","0.00508"
"288.68399","24.05722","0.00546"
"289.00800","24.08424","0.00533"
"289.33200","24.11121","0.00507"
"289.65601","24.13829","0.00537"
"289.98001","24.16525","0.00557"
"290.30399","24.19222","0.00536"
"290.62799","24.21925","0.00559"
"290.95200","24.24615","0.00551"
"291.27600","24.27329","0.00561"
"291.60001","24.30020","0.00546"
"291.92401","24.32723","0.00517"
"292.24799","24.35425","0.00533"
"292.57199","24.38116","0.00425"
"292.89600","24.40824","0.00465"
"293.22000","24.43520","0.00499"
"293.54401","24.46223","0.00492"
"293.86801","24.48926","0.00481"
"294.19199","24.51622","0.00500"
"294.51599","24.54318","0.00490"
"294.84000","24.57027","0.00519"
"295.16400","24.59723","0.00535"
"295.48801","24.62420","0.00541"
"295.81201","24.65117","0.00488"
"296.13599","24.67825","0.00516"
"296.45999","24.70521","0.00525"
"296.78400","24.73224","0.00552"
"297.10800","24.75926","0.00514"
"297.43201","24.78617","0.00547"
"297.75601","24.81326","0.00541"
"298.07999","24.84022","0.00518"
"298.40399","24.86718","0.00569"
"298.72800","24.89427","0.00518"
"299.05200","24.92118","0.00540"
"299.37601","24.94826","0.00589"
"299.70001","24.97517","0.00612"
"300.02399","25.00219","0.00558"
"300.34799","25.02921","0.00550"
"300.67200","25.05618","0.00608"
"300.99600","25.08326","0.00558"
"301.32001","25.11023","0.00633"
"301.64401","25.13720","0.00659"
"301.96799","25.16422","0.00609"
"302.29199","25.19118","0.00575"
"302.61600","25.21827","0.00605"
"302.94000","25.24523","0.00634"
"303.26401","25.27214","0.00615"
"303.58801","25.29922","0.00645"
"303.91199","25.32625","0.00693"
"304.23599","25.35327","0.00649"
"304.56000","25.38030","0.00637"
"304.88400","25.40720","0.00676"
"305.20801","25.43429","0.00607"
"305.53201","25.46113","0.00687"
"305.85599","25.48822","0.00686"
"306.17999","25.51524","0.00645"
"306.50400","25.54221","0.00665"
"306.82800","25.56923","0.00683"
"307.15201","25.59614","0.00686"
"307.47601","25.62328","0.00677"
"307.79999","25.65025","0.00694"
"308.12399","25.67721","0.00695"
"308.44800","25.70430","0.00691"
"308.77200","25.73120","0.00720"
"309.09601","25.75829","0.00712"
"309.42001","25.78525","0.00735"
"309.74399","25.81222","0.00714"
"310.06799","25.83924","0.00706"
"310.39200","25.86621","0.00729"
"310.71600","25.89323","0.00738"
"311.04001","25.92026","0.00719"
"311.36401","25.94722","0.00717"
"311.68799","25.97425","0.00737"
"312.01199","26.00121","0.00749"
"312.33600","26.02824","0.00735"
"312.66000","26.05526","0.00755"
"312.98401","26.08217","0.00695"
"313.30801","26.10925","0.00742"
"313.63199","26.13622","0.00741"
"313.95599","26.16324","0.00727"
"314.28000","26.19027","0.00775"
"314.60400","26.21717","0.00767"
"314.92801","26.24420","0.00803"
"315.25201","26.27122","0.00752"
"315.57599","26.29825","0.00727"
"315.89999","26.32527","0.00789"
"316.22400","26.35218","0.00754"
"316.54800","26.37932","0.00777"
"316.87201","26.40617","0.00782"
"317.19601","26.43319","0.00798"
"317.51999","26.46021","0.00769"
"317.84399","26.48718","0.00736"
"318.16800","26.51421","0.00759"
"318.49200","26.54117","0.00817"
"318.81601","26.56826","0.00776"
"319.14001","26.59522","0.00791"
"319.46399","26.62219","0.00823"
"319.78799","26.64921","0.00763"
"320.11200","26.67624","0.00754"
"320.43600","26.70326","0.00805"
"320.76001","26.73023","0.00758"
"321.08401","26.75719","0.00758"
"321.40799","26.78422","0.00748"
"321.73199","26.81118","0.00759"
"322.05600","26.83821","0.00804"
"322.38000","26.86523","0.00747"
"322.70401","26.89220","0.00785"
"323.02802","26.91928","0.00806"
"323.35199","26.94619","0.00798"
"323.67599","26.97315","0.00841"
"324.00000","27.00030","0.00847"
"324.32401","27.02714","0.00840"
"324.64801","27.05422","0.00823"
"324.97198","27.08119","0.00883"
"325.29599","27.10822","0.00835"
"325.62000","27.13524","0.00840"
"325.94400","27.16215","0.00845"
"326.26801","27.18929","0.00868"
"326.59201","27.21626","0.00862"
"326.91599","27.24322","0.00918"
"327.23999","27.27019","0.00871"
"327.56400","27.29721","0.00894"
"327.88800","27.32424","0.00893"
"328.21201","27.35126","0.00935"
"328.53601","27.37822","0.00935"
"328.85999","27.40525","0.00898"
"329.18399","27.43216","0.00924"
"329.50800","27.45924","0.00937"
"329.83200","27.48621","0.00892"
"330.15601","27.51323","0.00940"
"330.48001","27.54025","0.00926"
"330.80399","27.56716","0.00968"
"331.12799","27.59425","0.01002"
"331.45200","27.62127","0.00988"
"331.77600","27.64824","0.01009"
"332.10001","27.67526","0.00990"
"332.42401","27.70216","0.00960"
"332.74799","27.72925","0.01041"
"333.07199","27.75622","0.00989"
"333.39600","27.78318","0.01012"
"333.72000","27.81026","0.01041"
"334.04401","27.83723","0.01034"
"334.36801","27.86426","0.00960"
"334.69199","27.89122","0.00995"
"335.01599","27.91818","0.01016"
"335.34000","27.94527","0.01027"
"335.66400","27.97218","0.01073"
"335.98801","27.99920","0.01015"
"336.31201","28.02622","0.01019"
"336.63599","28.05319","0.01043"
"336.95999","28.08021","0.01044"
"337.28400","28.10718","0.01041"
"337.60800","28.13427","0.01060"
"337.93201","28.16123","0.01071"
"338.25601","28.18819","0.01048"
"338.57999","28.21522","0.01059"
"338.90399","28.24219","0.01095"
"339.22800","28.26927","0.01084"
"339.55200","28.29623","0.01091"
"339.87601","28.32314","0.01101"
"340.20001","28.35028","0.01095"
"340.52399","28.37719","0.01111"
"340.84799","28.40428","0.01107"
"341.17200","28.43124","0.01170"
"341.49600","28.45820","0.01123"
"341.82001","28.48523","0.01106"
"342.14401","28.51220","0.01139"
"342.46799","28.53922","0.01134"
"342.79199","28.56631","0.01167"
"343.11600","28.59315","0.01160"
"343.44000","28.62023","0.01184"
"343.76401","28.64714","0.01177"
"344.08801","28.67422","0.01192"
"344.41199","28.70125","0.01142"
"344.73599","28.72821","0.01249"
"345.06000","28.75524","0.01196"
"345.38400","28.78220","0.01236"
"345.70801","28.80923","0.01230"
"346.03201","28.83619","0.01216"
"346.35599","28.86316","0.01216"
"346.67999","28.89030","0.01224"
"347.00400","28.91721","0.01267"
"347.32800","28.94417","0.01287"
"347.65201","28.97126","0.01299"
"347.97601","28.99822","0.01246"
"348.29999","29.02525","0.01315"
"348.62399","29.05222","0.01281"
"348.94800","29.07924","0.01323"
"349.27200","29.10633","0.01305"
"349.59601","29.13317","0.01295"
"349.92001","29.16025","0.01296"
"350.24399","29.18722","0.01353"
"350.56799","29.21424","0.01357"
"350.89200","29.24127","0.01341"
"351.21600","29.26817","0.01357"
"351.54001","29.29526","0.01344"
"351.86401","29.32222","0.01351"
"352.18799","29.34925","0.01345"
"352.51199","29.37621","0.01347"
"352.83600","29.40324","0.01361"
"353.16000","29.43026","0.01396"
"353.48401","29.45717","0.01366"
"353.80801","29.48419","0.01374"
"354.13199","29.51128","0.01391"
"354.45599","29.53818","0.01422"
"354.78000","29.56521","0.01436"
"355.10400","29.59223","0.01445"
"355.42801","29.61926","0.01427"
"355.75201","29.64628","0.01445"
"356.07599","29.67319","0.01447"
"356.39999","29.70021","0.01464"
"356.72400","29.72724","0.01438"
"357.04800","29.75414","0.01423"
"357.37201","29.78123","0.01461"
"357.69601","29.80819","0.01417"
"358.01999","29.83528","0.01440"
"358.34399","29.86218","0.01523"
"358.66800","29.88915","0.01433"
"358.99200","29.91623","0.01409"
"359.31601","29.94320","0.01472"
"359.64001","29.97022","0.01491"
"359.96399","29.99719","0.01520"
"360.28799","30.02421","0.01514"
"360.61200","30.05124","0.01493"
"360.93600","30.07814","0.01531"
"361.26001","30.10523","0.01555"
"361.58401","30.13225","0.01548"
"361.90799","30.15922","0.01584"
"362.23199","30.18618","0.01652"
"362.55600","30.21315","0.01621"
"362.88000","30.24029","0.01622"
"363.20401","30.26726","0.01682"
"363.52802","30.29422","0.01633"
"363.85199","30.32118","0.01631"
"364.17599","30.34821","0.01612"
"364.50000","30.37518","0.01615"
"364.82401","30.40220","0.01591"
"365.14801","30.42923","0.01589"
"365.47198","30.45619","0.01255"
"365.79599","30.48322","0.01134"
"366.12000","30.51024","0.01018"
"366.44400","30.53727","0.01077"
"366.76801","30.56417","0.01035"
"367.09201","30.59126","0.01095"
"367.41599","30.61816","0.01007"
"367.73999","30.64525","0.01103"
"368.06400","30.67227","0.01037"
"368.38800","30.69918","0.01017"
"368.71201","30.72620","0.01074"
"369.03601","30.75317","0.01096"
"369.35999","30.78025","0.01071"
"369.68399","30.80722","0.01074"
"370.00800","30.83418","0.01044"
"370.33200","30.86126","0.01054"
"370.65601","30.88823","0.01070"
"370.98001","30.91525","0.01126"
"371.30399","30.94228","0.01097"
"371.62799","30.96924","0.01127"
"371.95200","30.99621","0.01129"
"372.27600","31.02317","0.01115"
"372.60001","31.05026","0.01094"
"372.92401","31.07723","0.01081"
"373.24799","31.10419","0.01104"
"373.57199","31.13122","0.01120"
"373.89600","31.15818","0.01115"
"374.22000","31.18526","0.01164"
"374.54401","31.21223","0.01097"
"374.86801","31.23914","0.01128"
"375.19199","31.26622","0.01099"
"375.51599","31.29324","0.01143"
"375.84000","31.32021","0.01133"
"376.16400","31.34723","0.01177"
"376.48801","31.37414","0.01166"
"376.81201","31.40128","0.01181"
"377.13599","31.42819","0.01204"
"377.45999","31.45521","0.01171"
"377.78400","31.48224","0.01151"
"378.10800","31.50914","0.01216"
"378.43201","31.53629","0.01157"
"378.75601","31.56319","0.01181"
"379.07999","31.59022","0.01193"
"379.40399","31.61724","0.01183"
"379.72800","31.64415","0.01209"
"380.05200","31.67123","0.01183"
"380.37601","31.69820","0.01219"
"380.70001","31.72522","0.01231"
"381.02399","31.75231","0.01226"
"381.34799","31.77915","0.01225"
"381.67200","31.80624","0.01223"
"381.99600","31.83320","0.01221"
"382.32001","31.86023","0.01240"
"382.64401","31.88719","0.01286"
"382.96799","31.91416","0.01247"
"383.29199","31.94124","0.01233"
"383.61600","31.96821","0.01261"
"383.94000","31.99523","0.01286"
"384.26401","32.02225","0.01273"
"384.58801","32.04916","0.01260"
"384.91199","32.07619","0.01276"
"385.23599","32.10321","0.01328"
"385.56000","32.13024","0.01295"
"385.88400","32.15726","0.01297"
"386.20801","32.18417","0.01252"
"386.53201","32.21125","0.01287"
"386.85599","32.23822","0.01309"
"387.17999","32.26524","0.01270"
"387.50400","32.29221","0.01271"
"387.82800","32.31917","0.01285"
"388.15201","32.34626","0.01264"
"388.47601","32.37322","0.01254"
"388.79999","32.40025","0.01247"
"389.12399","32.42727","0.01270"
"389.44800","32.45418","0.01269"
"389.77200","32.48126","0.01267"
"390.09601","32.50816","0.01298"
"390.42001","32.53519","0.01310"
"390.74399","32.56227","0.01270"
"391.06799","32.58918","0.01352"
"391.39200","32.61626","0.01323"
"391.71600","32.64329","0.01297"
"392.04001","32.67020","0.01405"
"392.36401","32.69722","0.01292"
"392.68799","32.72413","0.01334"
"393.01199","32.75127","0.01317"
"393.33600","32.77824","0.01378"
"393.66000","32.80526","0.01341"
"393.98401","32.83229","0.01358"
"394.30801","32.85919","0.01361"
"394.63199","32.88622","0.01382"
"394.95599","32.91318","0.01367"
"395.28000","32.94015","0.01403"
"395.60400","32.96729","0.01379"
"395.92801","32.99419","0.01374"
"396.25201","33.02122","0.01421"
"396.57599","33.04819","0.01388"
"396.89999","33.07521","0.01382"
"397.22400","33.10224","0.01429"
"397.54800","33.12920","0.01401"
"397.87201","33.15616","0.01346"
"398.19601","33.18325","0.01375"
"398.51999","33.21021","0.01441"
"398.84399","33.23718","0.01394"
"399.16800","33.26421","0.01391"
"399.49200","33.29123","0.01420"
"399.81601","33.31820","0.01416"
"400.14001","33.34516","0.01456"
"400.46399","33.37225","0.01473"
"400.78799","33.39921","0.01408"
"401.11200","33.42624","0.01450"
"401.43600","33.45326","0.01460"
"401.76001","33.48016","0.01454"
"402.08401","33.50725","0.01513"
"402.40799","33.53410","0.01490"
"402.73199","33.56124","0.01525"
"403.05600","33.58826","0.01504"
"403.38000","33.61517","0.01503"
"403.70401","33.64220","0.01563"
"404.02802","33.66916","0.01522"
"404.35199","33.69630","0.01513"
"404.67599","33.72327","0.01564"
"405.00000","33.75024","0.01517"
"405.32401","33.77720","0.01523"
"405.64801","33.80422","0.01551"
"405.97198","33.83125","0.01578"
"406.29599","33.85827","0.01588"
"406.62000","33.88524","0.01617"
"406.94400","33.91226","0.01581"
"407.26801","33.93917","0.01627"
"407.59201","33.96614","0.01606"
"407.91599","33.99322","0.01651"
"408.23999","34.02024","0.01631"
"408.56400","34.04727","0.01645"
"408.88800","34.07423","0.01652"
"409.21201","34.10126","0.01640"
"409.53601","34.12828","0.01672"
"409.85999","34.15519","0.01654"
"410.18399","34.18221","0.01716"
"410.50800","34.20924","0.01666"
"410.83200","34.23620","0.01617"
"411.15601","34.26329","0.01764"
"411.48001","34.29020","0.01714"
"411.80399","34.31728","0.01691"
"412.12799","34.34425","0.01690"
"412.45200","34.37121","0.01698"
"412.77600","34.39823","0.01721"
"413.10001","34.42520","0.01695"
"413.42401","34.45228","0.01744"
"413.74799","34.47919","0.01748"
"414.07199","34.50621","0.01753"
"414.39600","34.53330","0.01792"
"414.72000","34.56020","0.01798"
"415.04401","34.58723","0.01847"
"415.36801","34.61419","0.01794"
"415.69199","34.64122","0.01798"
"416.01599","34.66824","0.01832"
"416.34000","34.69515","0.01854"
"416.66400","34.72223","0.01847"
"416.98801","34.74926","0.01865"
"417.31201","34.77622","0.01849"
"417.63599","34.80319","0.01917"
"417.95999","34.83015","0.01898"
"418.28400","34.85724","0.01840"
"418.60800","34.88420","0.01862"
"418.93201","34.91117","0.01863"
"419.25601","34.93831","0.01854"
"419.57999","34.96516","0.01899"
"419.90399","34.99224","0.01931"
"420.22800","35.01921","0.01946"
"420.55200","35.04623","0.01981"
"420.87601","35.07326","0.01989"
"421.20001","35.10010","0.01975"
"421.52399","35.12725","0.02001"
"421.84799","35.15421","0.01993"
"422.17200","35.18118","0.02045"
"422.49600","35.20826","0.01988"
"422.82001","35.23517","0.01995"
"423.14401","35.26225","0.02041"
"423.46799","35.28922","0.02083"
"423.79199","35.31618","0.02045"
"424.11600","35.34321","0.02017"
"424.44000","35.37023","0.02089"
"424.76401","35.39720","0.02018"
"425.08801","35.42422","0.02040"
"425.41199","35.45119","0.02065"
"425.73599","35.47821","0.02125"
"426.06000","35.50518","0.02154"
"426.38400","35.53226","0.02168"
"426.70801","35.55928","0.02144"
"427.03201","35.58625","0.02167"
"427.35599","35.61322","0.02174"
"427.67999","35.64012","0.02189"
"428.00400","35.66727","0.02255"
"428.32800","35.69423","0.02221"
"428.65201","35.72120","0.02213"
"428.97601","35.74822","0.02235"
"429.29999","35.77519","0.02249"
"429.62399","35.80227","0.02290"
"429.94800","35.82924","0.02297"
"430.27200","35.85620","0.02340"
"430.59601","35.88329","0.02270"
"430.92001","35.91019","0.02317"
"431.24399","35.93722","0.02313"
"431.56799","35.96424","0.02337"
"431.89200","35.99121","0.02346"
"432.21600","36.01829","0.02345"
"432.54001","36.04514","0.02368"
"432.86401","36.07222","0.02406"
"433.18799","36.09925","0.02373"
"433.51199","36.12615","0.02320"
"433.83600","36.15324","0.02366"
"434.16000","36.18020","0.02379"
"434.48401","36.20728","0.02407"
"434.80801","36.23425","0.02445"
"435.13199","36.26122","0.02425"
"435.45599","36.28824","0.02433"
"435.78000","36.31520","0.02432"
"436.10400","36.34229","0.02476"
"436.42801","36.36926","0.02460"
"436.75201","36.39616","0.02457"
"437.07599","36.42331","0.02446"
"437.39999","36.45021","0.02488"
"437.72400","36.47723","0.02396"
"438.04800","36.50420","0.02220"
"438.37201","36.53117","0.01995"
"438.69601","36.55825","0.01763"
"439.01999","36.58522","0.01727"
"439.34399","36.61224","0.01638"
"439.66800","36.63927","0.01679"
"439.99200","36.66617","0.01415"
"440.31601","36.69320","0.01297"
"440.64001","36.72022","0.01289"
"440.96399","36.74724","0.01270"
"441.28799","36.77427","0.01371"
"441.61200","36.80124","0.01241"
"441.93600","36.82826","0.01207"
"442.26001","36.85522","0.01180"
"442.58401","36.88219","0.01232"
"442.90799","36.90921","0.01193"
"443.23199","36.93618","0.01203"
"443.55600","36.96321","0.01184"
"443.88000","36.99017","0.01137"
"444.20401","37.01720","0.01130"
"444.52802","37.04428","0.01132"
"444.85199","37.07118","0.01179"
"445.17599","37.09827","0.01153"
"445.50000","37.12518","0.01176"
"445.82401","37.15220","0.01152"
"446.14801","37.17923","0.01196"
"446.47198","37.20613","0.01156"
"446.79599","37.23327","0.01190"
"447.12000","37.26024","0.01165"
"447.44400","37.28720","0.01216"
"447.76801","37.31423","0.01217"
"448.09201","37.34120","0.01231"
"448.41599","37.36828","0.01240"
"448.73999","37.39518","0.01227"
"449.06400","37.42221","0.01247"
"449.38800","37.44929","0.01218"
"449.71201","37.47620","0.01249"
"450.03601","37.50322","0.01240"
"450.35999","37.53019","0.01260"
"450.68399","37.55716","0.01227"
"451.00800","37.58424","0.01214"
"451.33200","37.61121","0.01283"
"451.65601","37.63823","0.01292"
"451.98001","37.66526","0.01234"
"452.30399","37.69222","0.01256"
"452.62799","37.71924","0.01301"
"452.95200","37.74615","0.01320"
"453.27600","37.77323","0.01272"
"453.60001","37.80020","0.01313"
"453.92401","37.82716","0.01297"
"454.24799","37.85425","0.01327"
"454.57199","37.88121","0.01379"
"454.89600","37.90824","0.01365"
"455.22000","37.93520","0.01346"
"455.54401","37.96217","0.01354"
"455.86801","37.98932","0.01377"
"456.19199","38.01616","0.01338"
"456.51599","38.04324","0.01362"
"456.84000","38.07021","0.01423"
"457.16400","38.09723","0.01375"
"457.48801","38.12426","0.01374"
"457.81201","38.15117","0.01395"
"458.13599","38.17819","0.01384"
"458.45999","38.20515","0.01406"
"458.78400","38.23218","0.01457"
"459.10800","38.25920","0.01431"
"459.43201","38.28617","0.01413"
"459.75601","38.31325","0.01461"
"460.07999","38.34028","0.01481"
"460.40399","38.36718","0.01454"
"460.72800","38.39421","0.01509"
"461.05200","38.42123","0.01499"
"461.37601","38.44820","0.01456"
"461.70001","38.47522","0.01469"
"462.02399","38.50219","0.01495"
"462.34799","38.52927","0.01534"
"462.67200","38.55618","0.01563"
"462.99600","38.58320","0.01564"
"463.32001","38.61023","0.01567"
"463.64401","38.63719","0.01534"
"463.96799","38.66422","0.01543"
"464.29199","38.69118","0.01578"
"464.61600","38.71827","0.01551"
"464.94000","38.74523","0.01570"
"465.26401","38.77219","0.01575"
"465.58801","38.79922","0.01591"
"465.91199","38.82619","0.01621"
"466.23599","38.85321","0.01628"
"466.56000","38.88024","0.01648"
"466.88400","38.90720","0.01657"
"467.20801","38.93429","0.01689"
"467.53201","38.96119","0.01708"
"467.85599","38.98822","0.01681"
"468.17999","39.01524","0.01679"
"468.50400","39.04227","0.01714"
"468.82800","39.06923","0.01720"
"469.15201","39.09620","0.01741"
"469.47601","39.12322","0.01747"
"469.79999","39.15031","0.01725"
"470.12399","39.17715","0.01734"
"470.44800","39.20423","0.01814"
"470.77200","39.23120","0.01829"
"471.09601","39.25829","0.01791"
"471.42001","39.28525","0.01800"
"471.74399","39.31215","0.01816"
"472.06799","39.33930","0.01794"
"472.39200","39.36626","0.01838"
"472.71600","39.39317","0.01779"
"473.04001","39.42025","0.01785"
"473.36401","39.44722","0.01780"
"473.68799","39.47424","0.01838"
"474.01199","39.50121","0.01763"
"474.33600","39.52824","0.01747"
"474.66000","39.55526","0.01786"
"474.98401","39.58216","0.01737"
"475.30801","39.60925","0.01794"
"475.63199","39.63622","0.01812"
"475.95599","39.66324","0.01832"
"476.28000","39.69027","0.01893"
"476.60400","39.71711","0.01872"
"476.92801","39.74419","0.01839"
"477.25201","39.77122","0.01881"
"477.57599","39.79824","0.01871"
"477.89999","39.82527","0.01918"
"478.22400","39.85217","0.01947"
"478.54800","39.87920","0.01938"
"478.87201","39.90623","0.01975"
"479.19601","39.93319","0.01965"
"479.51999","39.96022","0.02050"
"479.84399","39.98717","0.01644"
"480.16800","40.01427","0.01606"
"480.49200","40.04117","0.01229"
"480.81601","40.06820","0.01430"
"481.14001","40.09522","0.01316"
"481.46399","40.12218","0.01416"
"481.78799","40.14921","0.01347"
"482.11200","40.17617","0.01420"
"482.43600","40.20326","0.01403"
"482.76001","40.23029","0.01454"
"483.08401","40.25713","0.01390"
"483.40799","40.28428","0.01415"
"483.73199","40.31124","0.01390"
"484.05600","40.33820","0.01370"
"484.38000","40.36523","0.01384"
"484.56601","40.38071","0.01450"