File: Force_trajectories/161218/Specimen_RawData_5.csv
End date,"12/18/2016"
Specimen label,"16AT_Unk"
Maximum Load,"0.14730",N

Time,Extension,Load
(s),(mm),(N)
"0.00000","0.00000","-0.00013"
"0.41400","0.03480","-0.00022"
"0.82800","0.06924","0.00001"
"1.24200","0.10373","-0.00025"
"1.65600","0.13829","0.00021"
"2.07000","0.17273","0.00015"
"2.48400","0.20723","0.00030"
"2.89800","0.24161","-0.00017"
"3.31200","0.27623","-0.00003"
"3.72600","0.31073","0.00017"
"4.14000","0.34528","0.00002"
"4.55400","0.37972","0.00003"
"4.96800","0.41416","0.00015"
"5.38200","0.44872","0.00017"
"5.79600","0.48322","-0.00001"
"6.21000","0.51772","0.00008"
"6.62400","0.55216","0.00006"
"7.03800","0.58671","0.00008"
"7.45200","0.62121","0.00006"
"7.86600","0.65571","0.00009"
"8.28000","0.69021","0.00025"
"8.69400","0.72471","0.00019"
"9.10800","0.75921","0.00023"
"9.52200","0.79371","-0.00005"
"9.93600","0.82820","0.00027"
"10.35000","0.86270","0.00021"
"10.76400","0.89726","0.00005"
"11.17800","0.93176","0.00020"
"11.59200","0.96620","0.00014"
"12.00600","1.00070","0.00037"
"12.42000","1.03532","0.00062"
"12.83400","1.06975","0.00015"
"13.24800","1.10419","0.00007"
"13.66200","1.13863","0.00003"
"14.07600","1.17319","0.00027"
"14.49000","1.20775","0.00013"
"14.90400","1.24225","0.00017"
"15.31800","1.27669","0.00080"
"15.73200","1.31124","0.00023"
"16.14600","1.34574","0.00014"
"16.56000","1.38024","0.00051"
"16.97400","1.41474","0.00038"
"17.38800","1.44924","0.00060"
"17.80200","1.48368","0.00005"
"18.21600","1.51824","0.00029"
"18.63000","1.55273","-0.00011"
"19.04400","1.58717","0.00056"
"19.45800","1.62179","0.00048"
"19.87200","1.65623","0.00043"
"20.28600","1.69073","0.00031"
"20.70000","1.72517","0.00032"
"21.11400","1.75973","0.00013"
"21.52800","1.79422","0.00036"
"21.94200","1.82872","0.00080"
"22.35600","1.86322","0.00053"
"22.77000","1.89772","0.00025"
"23.18400","1.93228","0.00024"
"23.59800","1.96678","0.00080"
"24.01200","2.00116","0.00012"
"24.42600","2.03565","0.00040"
"24.84000","2.07021","0.00078"
"25.25400","2.10471","0.00107"
"25.66800","2.13921","0.00037"
"26.08200","2.17371","0.00033"
"26.49600","2.20815","0.00033"
"26.91000","2.24271","0.00047"
"27.32400","2.27726","0.00061"
"27.73800","2.31170","0.00006"
"28.15200","2.34614","0.00020"
"28.56600","2.38070","0.00022"
"28.98000","2.41520","0.00009"
"29.39400","2.44970","0.00030"
"29.80800","2.48420","0.00019"
"30.22200","2.51869","-0.00015"
"30.63600","2.55325","0.00041"
"31.05000","2.58775","0.00024"
"31.46400","2.62219","-0.00002"
"31.87800","2.65669","0.00013"
"32.29200","2.69125","0.00045"
"32.70600","2.72569","-0.00028"
"33.12000","2.76024","0.00005"
"33.53400","2.79468","0.00033"
"33.94800","2.82918","0.00023"
"34.36200","2.86374","0.00026"
"34.77600","2.89824","0.00001"
"35.19000","2.93268","0.00030"
"35.60400","2.96718","0.00014"
"36.02000","3.00191","0.00013"
"36.43400","3.03641","0.00023"
"36.84800","3.07085","0.00024"
"37.26200","3.10541","0.00055"
"37.67600","3.13991","0.00012"
"38.09000","3.17441","0.00007"
"38.50400","3.20890","0.00025"
"38.91800","3.24334","0.00039"
"39.33200","3.27784","0.00029"
"39.74600","3.31240","0.00014"
"40.16000","3.34690","0.00006"
"40.57400","3.38140","0.00010"
"40.98800","3.41590","0.00021"
"41.40200","3.45039","0.00009"
"41.81600","3.48489","0.00016"
"42.23000","3.51933","0.00015"
"42.64400","3.55389","0.00019"
"43.05800","3.58845","0.00023"
"43.47200","3.62289","0.00022"
"43.88600","3.65739","0.00028"
"44.30000","3.69188","-0.00001"
"44.71400","3.72644","0.00031"
"45.12800","3.76094","0.00045"
"45.54200","3.79538","-0.00005"
"45.95600","3.82982","0.00034"
"46.37000","3.86432","0.00011"
"46.78400","3.89894","0.00014"
"47.19800","3.93343","0.00013"
"47.61200","3.96781","0.00029"
"48.02600","4.00231","-0.00028"
"48.44000","4.03693","-0.00039"
"48.85400","4.07143","0.00014"
"49.26800","4.10587","-0.00020"
"49.68200","4.14037","0.00028"
"50.09600","4.17486","-0.00005"
"50.51000","4.20942","-0.00012"
"50.92400","4.24386","-0.00005"
"51.33800","4.27836","0.00011"
"51.75200","4.31292","-0.00029"
"52.16600","4.34742","-0.00010"
"52.58000","4.38192","-0.00012"
"52.99400","4.41635","-0.00022"
"53.40800","4.45085","-0.00001"
"53.82200","4.48541","0.00003"
"54.23600","4.51991","-0.00009"
"54.65000","4.55435","-0.00028"
"55.06400","4.58885","-0.00014"
"55.47800","4.62346","-0.00017"
"55.89200","4.65790","-0.00003"
"56.30600","4.69234","0.00002"
"56.72000","4.72684","-0.00004"
"57.13400","4.76140","0.00005"
"57.54800","4.79590","0.00009"
"57.96200","4.83040","0.00006"
"58.37600","4.86484","0.00030"
"58.79000","4.89933","0.00028"
"59.20400","4.93389","0.00020"
"59.61800","4.96845","0.00017"
"60.03200","5.00289","-0.00018"
"60.44600","5.03739","0.00053"
"60.86000","5.07189","0.00015"
"61.27400","5.10638","0.00066"
"61.68800","5.14088","0.00061"
"62.10200","5.17532","0.00051"
"62.51600","5.20988","0.00028"
"62.93000","5.24438","-0.00003"
"63.34400","5.27894","0.00056"
"63.75800","5.31338","0.00017"
"64.17200","5.34782","0.00049"
"64.58600","5.38237","0.00032"
"65.00000","5.41687","0.00046"
"65.41400","5.45137","-0.00002"
"65.82800","5.48587","0.00011"
"66.24200","5.52043","0.00056"
"66.65600","5.55493","0.00056"
"67.07000","5.58937","0.00043"
"67.48400","5.62380","0.00051"
"67.89800","5.65836","0.00012"
"68.31200","5.69286","-0.00005"
"68.72600","5.72736","0.00044"
"69.14000","5.76186","-0.00004"
"69.55400","5.79636","0.00068"
"69.96800","5.83085","0.00032"
"70.38200","5.86541","0.00047"
"70.79600","5.89991","0.00043"
"71.21000","5.93429","0.00042"
"71.62400","5.96885","0.00058"
"72.03800","6.00335","0.00028"
"72.45200","6.03791","0.00053"
"72.86600","6.07234","0.00037"
"73.28000","6.10690","0.00107"
"73.69400","6.14146","0.00075"
"74.10800","6.17590","0.00079"
"74.52200","6.21034","0.00057"
"74.93600","6.24484","0.00062"
"75.35000","6.27940","0.00081"
"75.76400","6.31383","0.00120"
"76.17800","6.34839","0.00070"
"76.59200","6.38289","0.00106"
"77.00600","6.41745","0.00093"
"77.42000","6.45189","0.00131"
"77.83400","6.48639","0.00140"
"78.24800","6.52083","0.00115"
"78.66200","6.55532","0.00146"
"79.07600","6.58994","0.00149"
"79.49000","6.62444","0.00131"
"79.90400","6.65888","0.00118"
"80.31800","6.69338","0.00167"
"80.73200","6.72794","0.00163"
"81.14600","6.76244","0.00157"
"81.56000","6.79687","0.00172"
"81.97400","6.83131","0.00223"
"82.38800","6.86587","0.00201"
"82.80200","6.90037","0.00240"
"83.21600","6.93487","0.00219"
"83.63000","6.96937","0.00249"
"84.04400","7.00393","0.00254"
"84.45800","7.03842","0.00240"
"84.87200","7.07292","0.00279"
"85.28600","7.10736","0.00272"
"85.70000","7.14186","0.00262"
"86.11400","7.17642","0.00304"
"86.52800","7.21092","0.00339"
"86.94200","7.24542","0.00327"
"87.35600","7.27985","0.00275"
"87.77000","7.31441","0.00305"
"88.18400","7.34891","0.00345"
"88.59800","7.38341","0.00345"
"89.01200","7.41785","0.00357"
"89.42600","7.45241","0.00325"
"89.84000","7.48691","0.00403"
"90.25400","7.52140","0.00347"
"90.66800","7.55584","0.00438"
"91.08200","7.59034","0.00394"
"91.49600","7.62490","0.00442"
"91.91000","7.65946","0.00472"
"92.32400","7.69384","0.00411"
"92.73800","7.72834","0.00426"
"93.15200","7.76289","0.00494"
"93.56600","7.79739","0.00476"
"93.98000","7.83189","0.00494"
"94.39400","7.86639","0.00492"
"94.80800","7.90089","0.00544"
"95.22200","7.93545","0.00503"
"95.63600","7.96994","0.00529"
"96.05000","8.00438","0.00495"
"96.46400","8.03882","0.00527"
"96.87800","8.07338","0.00590"
"97.29200","8.10788","0.00582"
"97.70600","8.14238","0.00557"
"98.12000","8.17682","0.00640"
"98.53400","8.21138","0.00640"
"98.94800","8.24593","0.00704"
"99.36200","8.28037","0.00634"
"99.77600","8.31481","0.00717"
"100.19000","8.34931","0.00702"
"100.60400","8.38387","0.00708"
"101.01800","8.41843","0.00678"
"101.43200","8.45286","0.00683"
"101.84600","8.48736","0.00696"
"102.26000","8.52192","0.00681"
"102.67400","8.55642","0.00739"
"103.08800","8.59086","0.00818"
"103.50200","8.62536","0.00812"
"103.91600","8.65986","0.00803"
"104.33000","8.69441","0.00831"
"104.74400","8.72885","0.00846"
"105.15800","8.76335","0.00858"
"105.57200","8.79791","0.00901"
"105.98600","8.83241","0.00882"
"106.40000","8.86691","0.00883"
"106.81400","8.90135","0.00886"
"107.22800","8.93584","0.00913"
"107.64200","8.97040","0.00961"
"108.05600","9.00484","0.01002"
"108.47000","9.03934","0.00936"
"108.88400","9.07384","0.01007"
"109.29800","9.10840","0.00986"
"109.71200","9.14290","0.01023"
"110.12600","9.17739","0.01001"
"110.54000","9.21177","0.00992"
"110.95400","9.24633","0.00973"
"111.36800","9.28089","0.00983"
"111.78200","9.31545","0.01029"
"112.19600","9.34983","0.01039"
"112.61000","9.38439","0.00997"
"113.02400","9.41888","0.01001"
"113.43800","9.45344","0.01024"
"113.85200","9.48788","0.01028"
"114.26600","9.52238","0.01008"
"114.68000","9.55688","0.01057"
"115.09400","9.59138","0.01054"
"115.50800","9.62594","0.01103"
"115.92200","9.66031","0.01163"
"116.33600","9.69487","0.01119"
"116.75000","9.72943","0.01184"
"117.16400","9.76393","0.01214"
"117.57800","9.79837","0.01212"
"117.99200","9.83287","0.01265"
"118.40600","9.86736","0.01410"
"118.82000","9.90186","0.01290"
"119.23400","9.93642","0.01280"
"119.64800","9.97086","0.01293"
"120.06200","10.00542","0.01277"
"120.47600","10.03992","0.01351"
"120.89000","10.07442","0.01409"
"121.30400","10.10880","0.01388"
"121.71800","10.14335","0.01367"
"122.13200","10.17791","0.01330"
"122.54600","10.21241","0.01096"
"122.96000","10.24685","0.01144"
"123.37400","10.28135","0.01185"
"123.78800","10.31591","0.01206"
"124.20200","10.35046","0.01199"
"124.61600","10.38490","0.01222"
"125.03000","10.41934","0.01297"
"125.44400","10.45384","0.01332"
"125.85800","10.48840","0.01353"
"126.27200","10.52290","0.01453"
"126.68600","10.55734","0.01477"
"127.10000","10.59190","0.01488"
"127.51400","10.62645","0.01502"
"127.92800","10.66095","0.01534"
"128.34200","10.69539","0.01545"
"128.75600","10.72983","0.01592"
"129.17000","10.76439","0.01539"
"129.58400","10.79889","0.01671"
"129.99800","10.83339","0.01657"
"130.41200","10.86788","0.01737"
"130.82600","10.90238","0.01765"
"131.24000","10.93688","0.01672"
"131.65400","10.97144","0.01729"
"132.06800","11.00582","0.01809"
"132.48200","11.04038","0.01756"
"132.89600","11.07487","0.01767"
"133.31000","11.10943","0.01803"
"133.72400","11.14387","0.01807"
"134.13800","11.17831","0.01814"
"134.55200","11.21293","0.01847"
"134.96600","11.24737","0.01937"
"135.38000","11.28187","0.01919"
"135.79400","11.31631","0.01926"
"136.20800","11.35086","0.02044"
"136.62200","11.38536","0.02105"
"137.03600","11.41986","0.02032"
"137.45000","11.45436","0.02179"
"137.86400","11.48892","0.02162"
"138.27800","11.52342","0.02227"
"138.69200","11.55791","0.02292"
"139.10600","11.59235","0.02234"
"139.52000","11.62685","0.02186"
"139.93400","11.66141","0.02258"
"140.34800","11.69591","0.02219"
"140.76200","11.73041","0.02222"
"141.17600","11.76485","0.01836"
"141.59000","11.79941","0.01882"
"142.00400","11.83390","0.01942"
"142.41800","11.86840","0.02040"
"142.83200","11.90284","0.01943"
"143.24600","11.93734","0.01943"
"143.66000","11.97190","0.02014"
"144.07400","12.00640","0.02078"
"144.48800","12.04083","0.02287"
"144.90200","12.07533","0.02308"
"145.31600","12.10995","0.02358"
"145.73000","12.14439","0.02385"
"146.14400","12.17889","0.02384"
"146.55800","12.21339","0.02367"
"146.97200","12.24789","0.02508"
"147.38600","12.28238","0.02532"
"147.80000","12.31688","0.02644"
"148.21400","12.35138","0.02652"
"148.62800","12.38588","0.02766"
"149.04200","12.42044","0.02861"
"149.45600","12.45494","0.02880"
"149.87000","12.48938","0.02851"
"150.28400","12.52387","0.02928"
"150.69800","12.55837","0.02882"
"151.11200","12.59287","0.02878"
"151.52600","12.62737","0.03018"
"151.94000","12.66181","0.02957"
"152.35400","12.69643","0.03024"
"152.76800","12.73093","0.03088"
"153.18200","12.76536","0.03219"
"153.59600","12.79980","0.03164"
"154.01000","12.83436","0.03218"
"154.42400","12.86886","0.03214"
"154.83800","12.90342","0.03143"
"155.25200","12.93786","0.03095"
"155.66600","12.97235","0.03205"
"156.08000","13.00686","0.03183"
"156.49400","13.04141","0.03277"
"156.90800","13.07591","0.03391"
"157.32200","13.11029","0.03229"
"157.73600","13.14491","0.03318"
"158.15000","13.17941","0.03338"
"158.56400","13.21390","0.03451"
"158.97800","13.24834","0.03577"
"159.39200","13.28284","0.03728"
"159.80600","13.31740","0.03692"
"160.22000","13.35190","0.03315"
"160.63400","13.38634","0.03267"
"161.04800","13.42084","0.03333"
"161.46200","13.45539","0.03137"
"161.87600","13.48983","0.03199"
"162.29000","13.52439","0.03252"
"162.70400","13.55883","0.03312"
"163.11800","13.59339","0.03386"
"163.53200","13.62789","0.03447"
"163.94600","13.66245","0.03528"
"164.36000","13.69683","0.03675"
"164.77400","13.73133","0.03689"
"165.18800","13.76594","0.03668"
"165.60200","13.80038","0.03763"
"166.01600","13.83488","0.03817"
"166.43000","13.86938","0.03949"
"166.84400","13.90388","0.04021"
"167.25800","13.93837","0.04030"
"167.67200","13.97293","0.04167"
"168.08600","14.00731","0.04245"
"168.50000","14.04187","0.04324"
"168.91400","14.07643","0.04428"
"169.32800","14.11087","0.04475"
"169.74200","14.14537","0.04295"
"170.15600","14.17987","0.04324"
"170.57000","14.21442","0.04023"
"170.98400","14.24886","0.04028"
"171.39800","14.28336","0.04114"
"171.81200","14.31786","0.04157"
"172.22600","14.35242","0.04156"
"172.64000","14.38692","0.04174"
"173.05400","14.42141","0.04277"
"173.46800","14.45585","0.04320"
"173.88200","14.49041","0.04425"
"174.29600","14.52491","0.04467"
"174.71000","14.55941","0.04595"
"175.12400","14.59385","0.04689"
"175.53800","14.62835","0.04674"
"175.95200","14.66291","0.04821"
"176.36600","14.69746","0.04835"
"176.78000","14.73184","0.04872"
"177.19400","14.76628","0.05057"
"177.60800","14.80096","0.05196"
"178.02200","14.83546","0.05305"
"178.43600","14.86990","0.05395"
"178.85000","14.90434","0.05461"
"179.26400","14.93889","0.05487"
"179.67800","14.97339","0.05593"
"180.09200","15.00789","0.05551"
"180.50600","15.04239","0.05681"
"180.92000","15.07689","0.05880"
"181.33400","15.11145","0.06104"
"181.74800","15.14595","0.06275"
"182.16200","15.18038","0.06552"
"182.57600","15.21482","0.06393"
"182.99000","15.24938","0.06687"
"183.40400","15.28388","0.06938"
"183.81800","15.31838","0.07021"
"184.23200","15.35282","0.07066"
"184.64600","15.38743","0.07332"
"185.06000","15.42193","0.07495"
"185.47400","15.45643","0.07580"
"185.88800","15.49081","0.07615"
"186.30200","15.52537","0.07706"
"186.71600","15.55993","0.07791"
"187.13000","15.59437","0.07872"
"187.54400","15.62880","0.07966"
"187.95800","15.66330","0.08017"
"188.37200","15.69792","0.08150"
"188.78600","15.73242","0.08209"
"189.20000","15.76692","0.08354"
"189.61400","15.80136","0.08485"
"190.02800","15.83586","0.08465"
"190.44200","15.87041","0.08588"
"190.85600","15.90485","0.08562"
"191.27000","15.93935","0.08759"
"191.68400","15.97385","0.08902"
"192.09800","16.00841","0.09000"
"192.51200","16.04297","0.09135"
"192.92600","16.07740","0.09283"
"193.34000","16.11184","0.09391"
"193.75400","16.14634","0.09555"
"194.16800","16.18090","0.09729"
"194.58200","16.21534","0.09811"
"194.99600","16.24984","0.09985"
"195.41000","16.28440","0.10321"
"195.82400","16.31890","0.10531"
"196.23800","16.35339","0.10664"
"196.65200","16.38783","0.10941"
"197.06600","16.42239","0.11172"
"197.48000","16.45689","0.11340"
"197.89400","16.49139","0.11649"
"198.30800","16.52583","0.12041"
"198.72200","16.56033","0.12346"
"199.13600","16.59482","0.12708"
"199.55000","16.62938","0.13017"
"199.96400","16.66394","0.12824"
"200.37800","16.69832","0.13146"
"200.79200","16.73282","0.13470"
"201.20600","16.76738","0.13602"
"201.62000","16.80187","0.13917"
"202.03400","16.83631","0.14130"
"202.44800","16.87087","0.14372"
"202.86200","16.90537","0.14557"
"203.27600","16.93987","0.00200"
"203.69000","16.97443","-0.00221"
"204.10400","17.00887","-0.00045"
"204.51800","17.04342","-0.00145"
"204.93200","17.07786","-0.00053"
"205.34600","17.11236","-0.00129"
"205.76000","17.14686","-0.00069"
"206.17400","17.18136","-0.00071"
"206.58800","17.21592","-0.00110"
"207.00200","17.25042","-0.00076"
"207.41600","17.28485","-0.00090"
"207.83000","17.31929","-0.00089"
"208.24400","17.35391","-0.00115"
"208.65800","17.38841","-0.00087"
"209.07200","17.42291","-0.00099"
"209.48600","17.45735","-0.00074"
"209.90000","17.49191","-0.00071"
"210.31400","17.52641","-0.00108"
"210.72800","17.56090","-0.00081"
"211.14200","17.59534","-0.00098"
"211.55600","17.62984","-0.00065"
"211.97000","17.66440","-0.00135"
"212.38400","17.69890","-0.00102"
"212.79800","17.73334","-0.00080"
"213.21200","17.76784","-0.00095"
"213.62600","17.80239","-0.00099"
"214.04000","17.83695","-0.00063"
"214.45400","17.87139","-0.00066"
"214.86800","17.90589","-0.00070"
"215.28200","17.94039","-0.00054"
"215.69600","17.97489","-0.00090"
"216.11000","18.00938","-0.00091"
"216.52400","18.04388","-0.00080"
"216.93800","18.07838","-0.00098"
"217.35200","18.11294","-0.00089"
"217.76600","18.14744","-0.00071"
"218.18000","18.18188","-0.00130"
"218.59400","18.21638","-0.00054"
"219.00800","18.25088","-0.00095"
"219.42200","18.28543","-0.00103"
"219.83600","18.31987","-0.00104"
"220.25000","18.35437","-0.00060"
"220.66400","18.38887","-0.00122"
"221.07800","18.42343","-0.00088"
"221.49200","18.45793","-0.00075"
"221.90600","18.49230","-0.00050"
"222.32000","18.52686","-0.00059"
"222.73400","18.56136","-0.00053"
"223.14800","18.59586","-0.00068"
"223.56200","18.63036","-0.00080"
"223.97600","18.66486","-0.00097"
"224.39000","18.69942","-0.00038"
"224.80400","18.73397","-0.00100"
"225.21800","18.76841","-0.00057"
"225.63200","18.80285","-0.00067"
"226.04600","18.83735","-0.00073"
"226.46000","18.87185","-0.00080"
"226.87400","18.90641","-0.00073"
"227.28800","18.94085","-0.00063"
"227.70200","18.97540","-0.00112"
"228.11600","19.00990","-0.00033"
"228.53000","19.04446","-0.00099"
"228.94400","19.07884","-0.00049"
"229.35800","19.11334","-0.00042"
"229.77200","19.14790","-0.00054"
"230.18600","19.18240","-0.00071"
"230.60000","19.21683","-0.00029"
"231.01400","19.25133","-0.00047"
"231.42800","19.28589","-0.00036"
"231.84200","19.32039","-0.00064"
"232.25600","19.35495","-0.00049"
"232.67000","19.38939","-0.00075"
"233.08400","19.42383","-0.00052"
"233.49800","19.45838","-0.00041"
"233.91200","19.49288","-0.00047"
"234.32600","19.52738","-0.00040"
"234.74000","19.56188","-0.00054"
"235.15400","19.59638","-0.00041"
"235.56800","19.63087","-0.00072"
"235.98200","19.66537","-0.00031"
"236.39600","19.69987","-0.00035"
"236.81000","19.73437","-0.00006"
"237.22400","19.76887","-0.00055"
"237.63800","19.80337","-0.00032"
"238.05200","19.83781","-0.00042"
"238.46600","19.87237","-0.00019"
"238.88000","19.90693","-0.00031"
"239.29400","19.94136","-0.00040"
"239.70800","19.97586","-0.00035"
"240.12200","20.01036","-0.00012"
"240.53600","20.04486","-0.00063"
"240.95000","20.07942","-0.00041"
"241.36400","20.11386","-0.00036"
"241.77800","20.14836","-0.00048"
"242.19200","20.18285","-0.00012"
"242.60600","20.21741","-0.00020"
"243.02000","20.25191","-0.00050"
"243.43400","20.28629","-0.00022"
"243.84800","20.32085","-0.00017"
"244.26200","20.35541","0.00004"
"244.67600","20.38990","-0.00037"
"245.09000","20.42434","-0.00021"
"245.50400","20.45884","-0.00042"
"245.91800","20.49340","-0.00056"
"246.33200","20.52790","-0.00037"
"246.74600","20.56240","-0.00033"
"247.16000","20.59684","-0.00019"
"247.57400","20.63140","-0.00014"
"247.98800","20.66589","-0.00058"
"248.40200","20.70039","-0.00047"
"248.81600","20.73483","-0.00007"
"249.23000","20.76933","-0.00067"
"249.64400","20.80389","-0.00023"
"250.05800","20.83845","0.00001"
"250.47200","20.87288","-0.00027"
"250.88600","20.90732","-0.00022"
"251.30000","20.94188","-0.00030"
"251.71400","20.97638","-0.00037"
"252.12800","21.01094","-0.00017"
"252.54200","21.04538","-0.00015"
"252.95600","21.07994","0.00016"
"253.37000","21.11444","-0.00025"
"253.78400","21.14893","0.00008"
"254.19800","21.18337","0.00028"
"254.61200","21.21787","0.00039"
"255.02600","21.25243","0.00042"
"255.44000","21.28687","-0.00005"
"255.85400","21.32137","0.00061"
"256.26800","21.35586","0.00028"
"256.68200","21.39042","0.00005"
"257.09600","21.42492","0.00050"
"257.51000","21.45942","-0.00039"
"257.92400","21.49392","-0.00049"
"258.33800","21.52836","-0.00025"
"258.75200","21.56285","-0.00047"
"259.16600","21.59742","-0.00071"
"259.58000","21.63191","-0.00021"
"259.99400","21.66641","-0.00047"
"260.40800","21.70091","-0.00063"
"260.82200","21.73547","-0.00005"
"261.23600","21.76985","-0.00052"
"261.65000","21.80435","-0.00020"
"262.06400","21.83890","-0.00014"
"262.47800","21.87340","-0.00012"
"262.89200","21.90784","-0.00031"
"263.30600","21.94234","0.00021"
"263.72000","21.97690","-0.00004"
"264.13400","22.01140","-0.00030"
"264.54800","22.04589","0.00012"
"264.96200","22.08034","0.00001"
"265.37600","22.11489","-0.00002"
"265.79000","22.14939","0.00003"
"266.20400","22.18389","0.00008"
"266.61800","22.21833","-0.00015"
"267.03200","22.25289","-0.00041"
"267.44600","22.28739","0.00042"
"267.86000","22.32189","0.00044"
"268.27400","22.35638","0.00020"
"268.68800","22.39088","0.00031"
"269.10200","22.42538","0.00041"
"269.51600","22.45988","0.00029"
"269.93000","22.49438","0.00012"
"270.34400","22.52882","0.00018"
"270.75800","22.56343","0.00044"
"271.17200","22.59787","0.00020"
"271.58600","22.63237","0.00053"
"272.00000","22.66687","0.00069"
"272.41400","22.70137","0.00052"
"272.82800","22.73593","0.00038"
"273.24200","22.77036","0.00069"
"273.65600","22.80486","0.00067"
"274.07000","22.83936","0.00072"
"274.48400","22.87392","0.00093"
"274.89800","22.90842","0.00085"
"275.31200","22.94286","0.00033"
"275.72600","22.97736","0.00065"
"276.14000","23.01186","0.00088"
"276.55400","23.04641","0.00070"
"276.96800","23.08085","0.00091"
"277.38200","23.11535","0.00105"
"277.79600","23.14985","0.00077"
"278.21000","23.18441","0.00065"
"278.62400","23.21897","0.00092"
"279.03800","23.25340","0.00161"
"279.45200","23.28784","0.00072"
"279.86600","23.32240","0.00138"
"280.28000","23.35690","0.00143"
"280.69400","23.39140","0.00153"
"281.10800","23.42584","0.00120"
"281.52200","23.46040","0.00135"
"281.93600","23.49489","0.00122"
"282.35000","23.52939","0.00154"
"282.76400","23.56389","0.00160"
"283.17800","23.59839","0.00149"
"283.59200","23.63289","0.00153"
"284.00600","23.66739","0.00194"
"284.42000","23.70189","0.00212"
"284.83400","23.73632","0.00164"
"285.24800","23.77088","0.00216"
"285.66200","23.80544","0.00217"
"286.07600","23.83988","0.00248"
"286.49000","23.87438","0.00255"
"286.90400","23.90888","0.00238"
"287.31800","23.94338","0.00213"
"287.73200","23.97787","0.00277"
"288.14600","24.01231","0.00254"
"288.56000","24.04687","0.00256"
"288.97400","24.08143","0.00284"
"289.38800","24.11587","0.00245"
"289.80200","24.15037","0.00208"
"290.21600","24.18487","0.00190"
"290.63000","24.21943","0.00231"
"291.04400","24.25386","0.00243"
"291.45800","24.28836","0.00295"
"291.87200","24.32280","0.00222"
"292.28600","24.35736","0.00262"
"292.70000","24.39192","0.00300"
"293.11400","24.42648","0.00290"
"293.52800","24.46085","0.00290"
"293.94200","24.49535","0.00270"
"294.35600","24.52991","0.00337"
"294.77000","24.56435","0.00322"
"295.18400","24.59891","0.00373"
"295.59800","24.63335","0.00349"
"296.01200","24.66791","0.00367"
"296.42600","24.70240","0.00352"
"296.84000","24.73690","0.00362"
"297.25400","24.77134","0.00385"
"297.66800","24.80584","0.00374"
"298.08200","24.84040","0.00418"
"298.49600","24.87490","0.00374"
"298.91000","24.90934","0.00383"
"299.32400","24.94384","0.00385"
"299.73800","24.97839","0.00421"
"300.15200","25.01289","0.00425"
"300.56600","25.04739","0.00392"
"300.98000","25.08189","0.00404"
"301.39400","25.11639","0.00431"
"301.80800","25.15089","0.00449"
"302.22200","25.18538","0.00397"
"302.63600","25.21982","0.00426"
"303.05000","25.25438","0.00454"
"303.46400","25.28894","0.00404"
"303.87800","25.32344","0.00429"
"304.29200","25.35788","0.00384"
"304.70600","25.39238","0.00400"
"305.12000","25.42688","0.00366"
"305.53400","25.46137","0.00430"
"305.94800","25.49587","0.00457"
"306.36200","25.53031","0.00466"
"306.77600","25.56487","0.00448"
"307.19000","25.59943","0.00470"
"307.60400","25.63386","0.00516"
"308.01800","25.66837","0.00499"
"308.43200","25.70286","0.00495"
"308.84600","25.73742","0.00446"
"309.26000","25.77186","0.00394"
"309.67400","25.80630","0.00400"
"310.08800","25.84080","0.00357"
"310.50200","25.87535","0.00302"
"310.91600","25.90992","0.00358"
"311.33000","25.94441","0.00350"
"311.74400","25.97885","0.00350"
"312.15800","26.01341","0.00370"
"312.57200","26.04785","0.00371"
"312.98600","26.08241","0.00439"
"313.40000","26.11685","0.00386"
"313.81400","26.15134","0.00453"
"314.22800","26.18590","0.00430"
"314.64200","26.22046","0.00459"
"315.05600","26.25484","0.00438"
"315.47000","26.28934","0.00435"
"315.88400","26.32390","0.00487"
"316.29800","26.35839","0.00461"
"316.71200","26.39283","0.00438"
"317.12600","26.42733","0.00486"
"317.54000","26.46189","0.00525"
"317.95400","26.49639","0.00526"
"318.36800","26.53095","0.00501"
"318.78200","26.56539","0.00450"
"319.19600","26.59989","0.00493"
"319.61000","26.63438","0.00532"
"320.02400","26.66888","0.00520"
"320.43800","26.70338","0.00555"
"320.85200","26.73788","0.00566"
"321.26600","26.77238","0.00563"
"321.68000","26.80694","0.00502"
"322.09400","26.84138","0.00521"
"322.50800","26.87587","0.00530"
"322.92200","26.91037","0.00529"
"323.33600","26.94487","0.00554"
"323.75000","26.97937","0.00562"
"324.16400","27.01381","0.00557"
"324.57800","27.04843","0.00552"
"324.99200","27.08293","0.00571"
"325.40600","27.11742","0.00541"
"325.82000","27.15192","0.00543"
"326.23400","27.18642","0.00604"
"326.64800","27.22086","0.00584"
"327.06200","27.25536","0.00616"
"327.47600","27.28986","0.00633"
"327.89000","27.32435","0.00607"
"328.30400","27.35885","0.00600"
"328.71800","27.39341","0.00622"
"329.13200","27.42791","0.00628"
"329.54600","27.46235","0.00675"
"329.96000","27.49685","0.00672"
"330.37400","27.53141","0.00708"
"330.78800","27.56590","0.00710"
"331.20200","27.60034","0.00696"
"331.61600","27.63484","0.00738"
"332.03000","27.66940","0.00744"
"332.44400","27.70390","0.00781"
"332.85800","27.73834","0.00819"
"333.27200","27.77290","0.00826"
"333.68600","27.80739","0.00818"
"334.10000","27.84189","0.00848"
"334.51400","27.87639","0.00866"
"334.92800","27.91083","0.00895"
"335.34200","27.94533","0.00240"
"335.75600","27.97989","-0.00056"
"336.17000","28.01439","0.00004"
"336.58400","28.04888","-0.00058"
"336.99800","28.08338","0.00013"
"337.41200","28.11794","-0.00037"
"337.82600","28.15238","0.00018"
"338.24000","28.18682","-0.00015"
"338.65400","28.22132","-0.00012"
"339.06800","28.25588","0.00023"
"339.48200","28.29038","-0.00033"
"339.89600","28.32493","0.00026"
"340.31000","28.35937","0.00015"
"340.72400","28.39387","0.00045"
"341.13800","28.42843","0.00054"
"341.55200","28.46293","0.00079"
"341.96600","28.49736","0.00058"
"342.38000","28.53187","0.00062"
"342.79400","28.56642","0.00045"
"343.20800","28.60092","0.00031"
"343.62200","28.63536","0.00112"
"344.03600","28.66986","0.00087"
"344.45000","28.70442","0.00110"
"344.86400","28.73886","0.00059"
"345.27800","28.77342","0.00119"
"345.69200","28.80785","0.00110"
"346.10600","28.84235","0.00102"
"346.52000","28.87691","0.00112"
"346.93400","28.91147","0.00121"
"347.34800","28.94591","0.00141"
"347.76200","28.98035","0.00176"
"348.17600","29.01491","0.00165"
"348.59000","29.04940","0.00177"
"349.00400","29.08390","0.00161"
"349.41800","29.11834","0.00173"
"349.83200","29.15290","0.00162"
"350.24600","29.18740","0.00204"
"350.66000","29.22189","0.00206"
"351.07400","29.25640","0.00215"
"351.48800","29.29089","0.00212"
"351.90200","29.32539","0.00203"
"352.31600","29.35989","0.00238"
"352.73000","29.39433","0.00203"
"353.14400","29.42889","0.00168"
"353.55800","29.46339","0.00133"
"353.97200","29.49788","0.00177"
"354.38600","29.53238","0.00000"
"354.80000","29.56688","-0.00034"
"355.21400","29.60144","-0.00051"
"355.62800","29.63588","-0.00005"
"356.04200","29.67038","-0.00042"
"356.45600","29.70481","-0.00013"
"356.87000","29.73937","-0.00026"
"357.28400","29.77387","0.00004"
"357.69800","29.80843","-0.00049"
"358.11200","29.84287","0.00015"
"358.52600","29.87737","0.00013"
"358.94000","29.91193","0.00000"
"359.35400","29.94637","-0.00004"
"359.76800","29.98086","0.00016"
"360.18200","30.01530","0.00017"
"360.59600","30.04986","0.00006"
"361.01000","30.08436","0.00032"
"361.42400","30.11892","0.00022"
"361.83800","30.15342","0.00053"
"362.25200","30.18785","0.00040"
"362.66600","30.22241","0.00006"
"363.08000","30.25691","0.00023"
"363.49400","30.29135","0.00067"
"363.90800","30.32585","0.00032"
"364.32200","30.36041","0.00063"
"364.73600","30.39491","0.00053"
"365.15000","30.42940","0.00053"
"365.56400","30.46384","0.00028"
"365.97800","30.49840","0.00003"
"366.39200","30.53284","0.00032"
"366.80600","30.56734","0.00022"
"367.22000","30.60184","0.00051"
"367.63400","30.63640","0.00063"
"368.04800","30.67096","0.00073"
"368.46200","30.70539","0.00057"
"368.87600","30.73983","0.00038"
"369.29000","30.77439","0.00070"
"369.70400","30.80889","0.00070"
"370.11800","30.84339","0.00055"
"370.53200","30.87789","0.00052"
"370.94600","30.91233","0.00041"
"371.36000","30.94683","0.00073"
"371.77400","30.98138","0.00094"
"372.18800","31.01588","0.00083"
"372.60200","31.05032","0.00084"
"373.01600","31.08488","0.00049"
"373.43000","31.11938","0.00081"
"373.84400","31.15388","0.00088"
"374.25800","31.18831","0.00130"
"374.67200","31.22287","0.00109"
"375.08600","31.25737","0.00127"
"375.50000","31.29187","0.00151"
"375.91400","31.32636","0.00114"
"376.32800","31.36086","0.00129"
"376.74200","31.39542","0.00139"
"377.15600","31.42992","0.00178"
"377.57000","31.46442","0.00167"
"377.98400","31.49886","0.00187"
"378.39800","31.53336","0.00146"
"378.81200","31.56786","0.00181"
"379.22600","31.60242","0.00209"
"379.64000","31.63685","0.00203"
"380.05400","31.67135","0.00173"
"380.46800","31.70591","0.00189"
"380.88200","31.74041","0.00216"
"381.29600","31.77491","0.00185"
"381.71000","31.80935","0.00218"
"382.12400","31.84385","0.00225"
"382.53800","31.87846","0.00251"
"382.95200","31.91290","0.00270"
"383.36600","31.94740","0.00261"
"383.78000","31.98190","0.00240"
"384.19400","32.01640","0.00269"
"384.60800","32.05090","0.00224"
"385.02200","32.08533","0.00220"
"385.43600","32.11989","0.00228"
"385.85000","32.15445","0.00272"
"386.26400","32.18889","0.00224"
"386.67800","32.22339","0.00274"
"387.09200","32.25789","0.00264"
"387.50600","32.29239","0.00235"
"387.92000","32.32689","0.00260"
"388.33400","32.36132","0.00256"
"388.74800","32.39582","0.00210"
"389.16200","32.43038","0.00218"
"389.57600","32.46494","0.00249"
"389.99000","32.49944","0.00262"
"390.40400","32.53388","0.00257"
"390.81800","32.56837","0.00231"
"391.23200","32.60293","0.00253"
"391.64600","32.63743","0.00236"
"392.06000","32.67181","0.00285"
"392.47400","32.70631","0.00291"
"392.88800","32.74093","0.00233"
"393.30200","32.77542","0.00244"
"393.71600","32.80993","0.00228"
"394.13000","32.84443","0.00261"
"394.54400","32.87886","0.00243"
"394.95800","32.91342","0.00249"
"395.37200","32.94792","0.00238"
"395.78600","32.98236","0.00263"
"396.20000","33.01686","0.00235"
"396.61400","33.05141","0.00248"
"397.02800","33.08591","0.00256"
"397.44200","33.12041","0.00220"
"397.85600","33.15485","0.00183"
"398.27000","33.18941","0.00220"
"398.68400","33.22391","0.00189"
"399.09800","33.25840","0.00208"
"399.51200","33.29279","0.00180"
"399.92600","33.32734","0.00156"
"400.34000","33.36190","0.00224"
"400.75400","33.39640","0.00191"
"401.16800","33.43084","0.00189"
"401.58200","33.46540","0.00219"
"401.99600","33.49990","0.00225"
"402.41000","33.53439","0.00200"
"402.82400","33.56883","0.00156"
"403.23800","33.60327","0.00170"
"403.65200","33.63789","0.00191"
"404.06600","33.67239","0.00195"
"404.48000","33.70689","0.00214"
"404.89400","33.74139","0.00189"
"405.30800","33.77589","0.00242"
"405.72200","33.81044","0.00240"
"406.13600","33.84488","0.00220"
"406.55000","33.87938","0.00239"
"406.96400","33.91382","0.00203"
"407.37800","33.94838","0.00228"
"407.79200","33.98294","0.00191"
"408.20600","34.01737","0.00222"
"408.62000","34.05182","0.00246"
"409.03400","34.08637","0.00220"
"409.44800","34.12087","0.00207"
"409.86200","34.15537","0.00191"
"410.27600","34.18980","0.00212"
"410.69000","34.22437","0.00200"
"411.10400","34.25892","0.00169"
"411.51800","34.29336","0.00181"
"411.93200","34.32786","0.00179"
"412.34600","34.36236","0.00153"
"412.76000","34.39692","0.00206"
"413.17400","34.43142","0.00209"
"413.58800","34.46586","0.00217"
"414.00200","34.50035","0.00180"
"414.41600","34.53485","0.00167"
"414.83000","34.56941","0.00156"
"415.24400","34.60391","0.00180"
"415.65800","34.63835","0.00184"
"416.07200","34.67284","0.00182"
"416.48600","34.70741","0.00209"
"416.90000","34.74191","0.00211"
"417.31400","34.77628","0.00163"
"417.72800","34.81090","0.00190"
"418.14200","34.84540","0.00254"
"418.55600","34.87990","0.00220"
"418.97000","34.91440","0.00214"
"419.38400","34.94890","0.00256"
"419.79800","34.98339","0.00247"
"420.21200","35.01789","0.00194"
"420.62600","35.05239","0.00245"
"421.04000","35.08683","0.00220"
"421.45400","35.12139","0.00255"
"421.86800","35.15588","0.00198"
"422.28200","35.19038","0.00252"
"422.69600","35.22488","0.00232"
"423.11000","35.25938","0.00232"
"423.52400","35.29394","0.00243"
"423.93800","35.32838","0.00279"
"424.35200","35.36288","0.00249"
"424.76600","35.39732","0.00267"
"425.18000","35.43188","0.00272"
"425.59400","35.46643","0.00265"
"426.00800","35.50093","0.00217"
"426.42200","35.53537","0.00160"
"426.83600","35.56987","0.00201"
"427.25000","35.60443","0.00158"
"427.66400","35.63892","0.00152"
"428.07800","35.67331","0.00142"
"428.49200","35.70781","0.00133"
"428.90600","35.74242","0.00181"
"429.32000","35.77686","0.00157"
"429.73400","35.81136","0.00189"
"430.14800","35.84586","0.00144"
"430.56200","35.88042","0.00156"
"430.97600","35.91492","0.00187"
"431.39000","35.94935","0.00187"
"431.80400","35.98385","0.00211"
"432.21800","36.01835","0.00186"
"432.63200","36.05291","0.00215"
"433.04600","36.08741","0.00148"
"433.46000","36.12185","0.00166"
"433.87400","36.15641","0.00178"
"434.28800","36.19096","0.00169"
"434.70200","36.22540","0.00160"
"435.11600","36.25984","0.00184"
"435.53000","36.29428","0.00186"
"435.94400","36.32884","0.00213"
"436.35800","36.36340","0.00182"
"436.77200","36.39789","0.00248"
"437.18600","36.43233","0.00200"
"437.60000","36.46689","0.00213"
"438.01400","36.50139","0.00212"
"438.42800","36.53589","0.00220"
"438.84200","36.57039","0.00234"
"439.25600","36.60482","0.00269"
"439.67000","36.63939","0.00256"
"440.08400","36.67389","0.00256"
"440.49800","36.70838","0.00244"
"440.91200","36.74282","0.00235"
"441.32600","36.77738","0.00234"
"441.74000","36.81188","0.00237"
"442.15400","36.84638","0.00279"
"442.56800","36.88081","0.00245"
"442.98200","36.91537","0.00243"
"443.39600","36.94993","0.00232"
"443.81000","36.98443","0.00230"
"444.22400","37.01887","0.00266"
"444.63800","37.05337","0.00248"
"445.05200","37.08792","0.00230"
"445.46600","37.12236","0.00175"
"445.88000","37.15686","0.00244"
"446.29400","37.19130","0.00148"
"446.70800","37.22586","0.00150"
"447.12200","37.26042","0.00244"
"447.53600","37.29492","0.00206"
"447.95000","37.32936","0.00206"
"448.36400","37.36385","0.00231"
"448.77800","37.39841","0.00199"
"449.19200","37.43291","0.00153"
"449.60600","37.46741","0.00139"
"450.02000","37.50185","0.00154"
"450.43400","37.53641","0.00183"
"450.84800","37.57090","0.00203"
"451.26200","37.60540","0.00160"
"451.67600","37.63984","0.00237"
"452.09000","37.67440","0.00219"
"452.50400","37.70890","0.00201"
"452.91800","37.74334","0.00198"
"453.33200","37.77784","0.00256"
"453.74600","37.81240","0.00205"
"454.16000","37.84695","0.00273"
"454.57400","37.88133","0.00226"
"454.98800","37.91589","0.00220"
"455.40200","37.95039","0.00235"
"455.81600","37.98489","0.00243"
"456.23000","38.01939","0.00242"
"456.64400","38.05389","0.00225"
"457.05800","38.08833","0.00261"
"457.47200","38.12288","0.00251"
"457.88600","38.15744","0.00247"
"458.30000","38.19188","0.00247"
"458.71400","38.22638","0.00269"
"459.12800","38.26088","0.00310"
"459.54200","38.29544","0.00260"
"459.95600","38.32993","0.00238"
"460.37000","38.36432","0.00217"
"460.78400","38.39881","0.00205"
"461.19800","38.43337","0.00156"
"461.61200","38.46793","0.00118"
"462.02600","38.50237","0.00078"
"462.44000","38.53687","0.00069"
"462.85400","38.57143","0.00053"
"463.26800","38.60592","0.00052"
"463.68200","38.64042","0.00084"
"464.09600","38.67486","0.00039"
"464.51000","38.70936","0.00090"
"464.92400","38.74392","0.00070"
"465.33800","38.77842","0.00106"
"465.75200","38.81285","0.00054"
"466.16600","38.84735","0.00081"
"466.58000","38.88191","0.00092"
"466.99400","38.91641","0.00064"
"467.40800","38.95091","0.00086"
"467.82200","38.98529","0.00081"
"468.23600","39.01984","0.00139"
"468.65000","39.05441","0.00078"
"469.06400","39.08896","0.00107"
"469.47800","39.12340","0.00102"
"469.89200","39.15790","0.00069"
"470.30600","39.19246","0.00104"
"470.72000","39.22690","0.00090"
"471.13400","39.26133","0.00087"
"471.54800","39.29583","0.00080"
"471.96200","39.33039","0.00103"
"472.37600","39.36483","0.00088"
"472.79000","39.39938","0.00090"
"473.20400","39.43383","0.00103"
"473.61800","39.46838","0.00067"
"474.03200","39.50288","0.00086"
"474.44600","39.53738","0.00097"
"474.86000","39.57182","0.00077"
"475.27400","39.60632","0.00101"
"475.68800","39.64088","0.00147"
"476.10200","39.67538","0.00103"
"476.51600","39.70988","0.00091"
"476.93000","39.74437","0.00096"
"477.34400","39.77893","0.00118"
"477.75800","39.81343","0.00084"
"478.17200","39.84787","0.00124"
"478.58600","39.88231","0.00101"
"479.00000","39.91687","0.00081"
"479.41400","39.95142","0.00086"
"479.82800","39.98587","0.00118"
"480.24200","40.02037","0.00105"
"480.65600","40.05492","0.00130"
"481.07000","40.08942","0.00102"
"481.48400","40.12392","0.00104"
"481.89800","40.15835","0.00123"
"482.31200","40.19286","0.00159"
"482.72600","40.22735","0.00132"
"483.14000","40.26185","0.00155"
"483.55400","40.29635","0.00149"
"483.96800","40.33085","0.00143"
"484.38200","40.36541","0.00099"
"484.79600","40.39991","0.00104"
"485.21000","40.43441","0.00164"
"485.62400","40.46884","0.00159"
"486.03800","40.50341","0.00146"
"486.45200","40.53790","0.00159"
"486.86600","40.57246","0.00146"
"487.28000","40.60690","0.00164"
"487.69400","40.64134","0.00155"
"488.10800","40.67596","0.00140"
"488.52200","40.71039","0.00140"
"488.93600","40.74489","0.00187"
"489.35000","40.77934","0.00131"
"489.76400","40.81389","0.00127"
"490.17800","40.84839","0.00199"
"490.59200","40.88288","0.00173"
"491.00600","40.91738","0.00156"
"491.42000","40.95189","0.00130"
"491.83400","40.98638","0.00128"
"492.24800","41.02094","0.00186"
"492.66200","41.05538","0.00173"
"493.07600","41.08982","0.00170"
"493.49000","41.12438","0.00158"
"493.90400","41.15894","0.00171"
"494.31800","41.19337","0.00179"
"494.73200","41.22781","0.00183"
"495.14600","41.26237","0.00187"
"495.56000","41.29693","0.00189"
"495.97400","41.33137","0.00186"
"496.38800","41.36581","0.00179"
"496.80200","41.40031","0.00181"
"497.21600","41.43492","0.00184"
"497.63000","41.46936","0.00239"
"498.04400","41.50386","0.00191"
"498.45800","41.53836","0.00192"
"498.87200","41.57286","0.00176"
"499.28600","41.60742","0.00217"
"499.70000","41.64191","0.00188"
"500.11400","41.67629","0.00220"
"500.52800","41.71085","0.00196"
"500.94200","41.74541","0.00223"
"501.35600","41.77991","0.00225"
"501.77000","41.81435","0.00243"
"502.18400","41.84890","0.00254"
"502.59800","41.88340","0.00206"
"503.01200","41.91790","0.00276"
"503.42600","41.95234","0.00244"
"503.84000","41.98684","0.00208"
"504.25400","42.02134","0.00238"
"504.66800","42.05590","0.00131"
"505.08200","42.09040","0.00130"
"505.49600","42.12484","0.00096"
"505.91000","42.15939","0.00128"
"506.32400","42.19389","0.00142"
"506.73800","42.22839","0.00137"
"507.15200","42.26283","0.00128"
"507.56600","42.29733","0.00176"
"507.98000","42.33189","0.00128"
"508.39400","42.36639","0.00141"
"508.80800","42.40083","0.00090"
"509.22200","42.43532","0.00150"
"509.63600","42.46994","0.00072"
"510.05000","42.50438","0.00125"
"510.46400","42.53888","0.00034"
"510.87800","42.57332","0.00054"
"511.29200","42.60788","0.00086"
"511.70600","42.64237","0.00043"
"512.12000","42.67693","0.00047"
"512.53400","42.71137","0.00069"
"512.94800","42.74586","0.00098"
"513.36200","42.78043","0.00037"
"513.77600","42.81493","0.00056"
"514.19000","42.84937","0.00109"
"514.60400","42.88387","0.00099"
"515.01800","42.91842","0.00098"
"515.43200","42.95286","0.00074"
"515.84600","42.98742","0.00069"
"516.26000","43.02192","0.00076"
"516.67400","43.05642","0.00093"
"517.08800","43.09092","0.00081"
"517.50200","43.12535","0.00087"
"517.91600","43.15985","0.00124"
"518.33000","43.19435","0.00109"
"518.74400","43.22897","0.00061"
"519.15800","43.26340","0.00117"
"519.57200","43.29784","0.00102"
"519.98600","43.33234","0.00090"
"520.40000","43.36697","0.00107"
"520.81400","43.40140","0.00072"
"521.22800","43.43590","0.00061"
"521.64200","43.47034","0.00114"
"522.05600","43.50489","0.00084"
"522.47000","43.53946","0.00061"
"522.88400","43.57389","0.00067"
"523.29800","43.60839","0.00109"
"523.71200","43.64289","0.00063"
"524.12600","43.67745","0.00082"
"524.54000","43.71189","0.00076"
"524.95400","43.74633","0.00084"
"525.36800","43.78083","0.00065"
"525.78200","43.81538","0.00078"
"526.19600","43.84995","0.00112"
"526.61000","43.88438","0.00065"
"527.02400","43.91882","0.00092"
"527.43800","43.95338","0.00088"
"527.85200","43.98793","0.00067"
"528.26600","44.02243","0.00061"
"528.68000","44.05681","0.00065"
"529.09400","44.09137","0.00082"
"529.50800","44.12587","0.00079"
"529.92200","44.16043","0.00085"
"530.33600","44.19481","0.00092"
"530.75000","44.22931","0.00102"
"531.16400","44.26392","0.00113"
"531.57800","44.29842","0.00076"
"531.99200","44.33286","0.00119"
"532.40600","44.36730","0.00086"
"532.82000","44.40186","0.00135"
"533.23400","44.43642","0.00113"
"533.64800","44.47092","0.00129"
"534.06200","44.50536","0.00114"
"534.47600","44.53985","0.00181"
"534.89000","44.57435","0.00134"
"535.30400","44.60885","0.00112"
"535.71800","44.64341","0.00133"
"536.13200","44.67785","0.00075"
"536.54600","44.71235","0.00125"
"536.96000","44.74691","0.00092"
"537.37400","44.78140","0.00086"
"537.78800","44.81578","0.00155"
"538.20200","44.85040","0.00138"
"538.61600","44.88490","0.00087"
"539.03000","44.91940","0.00106"
"539.44400","44.95378","0.00105"
"539.85800","44.98834","0.00126"
"540.27200","45.02289","0.00139"
"540.68600","45.05739","0.00123"
"541.10000","45.09189","0.00124"
"541.51400","45.12633","0.00092"
"541.92800","45.16095","0.00134"
"542.34200","45.19545","0.00114"
"542.75600","45.22989","0.00114"
"543.17000","45.26432","0.00163"
"543.58400","45.29882","0.00144"
"543.99800","45.33338","0.00112"
"544.41200","45.36794","0.00123"
"544.82600","45.40238","0.00048"
"545.24000","45.43681","0.00107"
"545.65400","45.47144","0.00115"
"546.06800","45.50593","0.00108"
"546.48200","45.54037","0.00102"
"546.89600","45.57487","0.00069"
"547.31000","45.60937","0.00122"
"547.72400","45.64387","0.00092"
"548.13800","45.67836","0.00125"
"548.55200","45.71287","0.00089"
"548.96600","45.74736","0.00118"
"549.38000","45.78192","0.00094"
"549.79400","45.81642","0.00143"
"550.20800","45.85086","0.00089"
"550.62200","45.88541","0.00059"
"551.03600","45.91992","0.00145"
"551.45000","45.95436","0.00103"
"551.86400","45.98885","0.00125"
"552.27800","46.02335","0.00060"
"552.69200","46.05791","0.00100"
"553.10600","46.09241","0.00103"
"553.52000","46.12691","0.00105"
"553.93400","46.16129","0.00072"
"554.34800","46.19590","0.00121"
"554.76200","46.23046","0.00099"
"555.17600","46.26496","0.00078"
"555.59000","46.29934","0.00144"
"556.00400","46.33384","0.00084"
"556.41800","46.36846","0.00046"
"556.83200","46.40289","0.00070"
"557.24600","46.43733","0.00041"
"557.66000","46.47183","0.00074"
"558.07400","46.50639","0.00052"
"558.48800","46.54089","0.00055"
"558.90200","46.57539","0.00036"
"559.31600","46.60989","0.00057"
"559.73000","46.64438","0.00055"
"560.14400","46.67894","0.00039"
"560.55800","46.71339","0.00066"
"560.97200","46.74782","0.00010"
"561.38600","46.78232","0.00063"
"561.80000","46.81688","0.00109"
"562.21400","46.85143","0.00056"
"562.62800","46.88588","0.00064"
"563.04200","46.92031","0.00090"
"563.45600","46.95493","0.00083"
"563.87000","46.98943","0.00086"
"564.28400","47.02387","0.00075"
"564.69800","47.05831","0.00050"
"565.11200","47.09281","0.00051"
"565.52600","47.12736","0.00068"
"565.94000","47.16192","0.00112"
"566.35400","47.19637","0.00093"
"566.76800","47.23092","0.00141"
"567.18200","47.26542","0.00080"
"567.59600","47.29992","0.00057"
"568.01000","47.33442","0.00084"
"568.42400","47.36880","0.00101"
"568.83800","47.40335","0.00094"
"569.25200","47.43785","0.00081"
"569.66600","47.47235","0.00095"
"570.08000","47.50685","0.00062"
"570.49400","47.54141","0.00061"
"570.90800","47.57585","0.00091"
"571.32200","47.61040","0.00023"
"571.73600","47.64484","0.00090"
"572.15000","47.67934","0.00047"
"572.56400","47.71384","0.00061"
"572.97800","47.74834","0.00045"
"573.39200","47.78284","0.00069"
"573.80600","47.81734","0.00048"
"574.22000","47.85196","0.00035"
"574.63400","47.88639","0.00037"
"575.04800","47.92083","0.00037"
"575.46200","47.95527","0.00097"
"575.87600","47.98983","0.00075"
"576.29000","48.02439","0.00065"
"576.70400","48.05894","0.00058"
"577.11800","48.09339","0.00038"
"577.53200","48.12788","0.00057"
"577.94600","48.16238","0.00063"
"578.36000","48.19694","0.00104"
"578.77400","48.23138","0.00090"
"579.18800","48.26582","0.00070"
"579.60200","48.30038","0.00009"
"580.01600","48.33488","0.00032"
"580.43000","48.36943","0.00047"
"580.84400","48.40382","0.00049"
"581.25800","48.43837","0.00063"
"581.67200","48.47293","0.00082"
"582.08600","48.50743","0.00069"
"582.50000","48.54187","0.00078"
"582.91400","48.57637","0.00048"
"583.32800","48.61092","0.00082"
"583.74200","48.64536","0.00066"
"584.15600","48.67986","0.00082"
"584.57000","48.71436","0.00077"
"584.98400","48.74892","0.00095"
"585.39800","48.78348","0.00056"
"585.81200","48.81792","0.00071"
"586.22600","48.85229","0.00029"
"586.64000","48.88686","0.00075"
"587.05400","48.92141","0.00072"
"587.46800","48.95591","0.00090"
"587.88200","48.99035","0.00078"
"588.29600","49.02484","0.00072"
"588.71000","49.05941","0.00070"
"589.12400","49.09396","0.00098"
"589.53800","49.12834","0.00108"
"589.95200","49.16290","0.00106"
"590.36600","49.19734","0.00084"
"590.78000","49.23190","0.00076"
"591.19400","49.26633","0.00107"
"591.60800","49.30083","0.00123"
"592.02200","49.33540","0.00111"
"592.43600","49.36989","0.00143"
"592.85000","49.40445","0.00080"
"593.26400","49.43888","0.00077"
"593.67800","49.47333","0.00129"
"594.09200","49.50788","0.00117"
"594.50600","49.54238","0.00082"
"594.92000","49.57689","0.00067"
"595.33400","49.61138","0.00083"
"595.74800","49.64594","0.00077"
"596.16200","49.68038","0.00101"
"596.57600","49.71494","0.00082"
"596.99000","49.74931","0.00113"
"597.40400","49.78381","0.00112"
"597.81800","49.81844","0.00116"
"598.23200","49.85293","0.00149"
"598.64600","49.88737","0.00135"
"599.06000","49.92187","0.00126"
"599.47400","49.95642","0.00094"
"599.88800","49.99092","0.00129"
"600.30200","50.02536","0.00082"
"600.71600","50.05986","0.00095"
"601.13000","50.09436","0.00111"
"601.54400","50.12886","0.00170"
"601.95800","50.16342","0.00069"
"602.37200","50.19786","0.00105"
"602.78600","50.23241","0.00120"
"603.20000","50.26691","0.00135"
"603.61400","50.30141","0.00096"
"604.02800","50.33585","0.00092"
"604.44200","50.37035","0.00120"
"604.85600","50.40485","0.00122"
"605.27000","50.43935","0.00110"
"605.68400","50.47390","0.00161"
"606.09800","50.50834","0.00134"
"606.51200","50.54291","0.00119"
"606.92600","50.57746","0.00110"
"607.34000","50.61184","0.00100"
"607.75400","50.64634","0.00139"
"608.16800","50.68090","0.00141"
"608.58200","50.71539","0.00143"
"608.99600","50.74984","0.00134"
"609.41000","50.78439","0.00120"
"609.82400","50.81883","0.00111"
"610.23800","50.85339","0.00166"
"610.65200","50.88795","0.00082"
"611.06600","50.92239","0.00118"
"611.48000","50.95683","0.00140"
"611.89400","50.99138","0.00134"
"612.30800","51.02588","0.00117"
"612.72200","51.06038","0.00148"
"613.13600","51.09482","0.00153"
"613.55000","51.12938","0.00162"
"613.96400","51.16388","0.00123"
"614.37800","51.19843","0.00150"
"614.38200","51.19879","0.00153"