File: Force_trajectories/161218/Specimen_RawData_4.csv
End date,"12/18/2016"
Specimen label,"16AT_26_run2"
Maximum Load,"0.19149",N

Time,Extension,Load
(s),(mm),(N)
"0.00000","0.00000","-0.00028"
"0.25800","0.01973","0.00018"
"0.51600","0.04323","0.00017"
"0.77400","0.06469","0.00054"
"1.03200","0.08616","0.00046"
"1.29000","0.10768","0.00075"
"1.54800","0.12915","0.00070"
"1.80600","0.15061","0.00083"
"2.06400","0.17213","0.00103"
"2.32200","0.19366","0.00081"
"2.58000","0.21518","0.00117"
"2.83800","0.23665","0.00113"
"3.09600","0.25817","0.00152"
"3.35400","0.27964","0.00129"
"3.61200","0.30116","0.00118"
"3.87000","0.32262","0.00121"
"4.12800","0.34415","0.00145"
"4.38600","0.36561","0.00168"
"4.64400","0.38714","0.00186"
"4.90200","0.40860","0.00190"
"5.16000","0.43019","0.00190"
"5.41800","0.45159","0.00143"
"5.67600","0.47311","0.00127"
"5.93400","0.49458","0.00187"
"6.19200","0.51616","0.00131"
"6.45000","0.53763","0.00127"
"6.70800","0.55915","0.00147"
"6.96600","0.58062","0.00158"
"7.22400","0.60220","0.00149"
"7.48200","0.62366","0.00161"
"7.74000","0.64513","0.00188"
"7.99800","0.66665","0.00206"
"8.25600","0.68812","0.00166"
"8.51400","0.70964","0.00217"
"8.77200","0.73117","0.00190"
"9.03000","0.75269","0.00162"
"9.28800","0.77410","0.00194"
"9.54600","0.79568","0.00223"
"9.80400","0.81708","0.00197"
"10.06200","0.83867","0.00206"
"10.32000","0.86013","0.00209"
"10.57800","0.88166","0.00256"
"10.83600","0.90306","0.00223"
"11.09400","0.92465","0.00210"
"11.35200","0.94611","0.00258"
"11.61000","0.96763","0.00278"
"11.86800","0.98910","0.00260"
"12.12600","1.01062","0.00231"
"12.38400","1.03209","0.00237"
"12.64200","1.05367","0.00258"
"12.90000","1.07514","0.00293"
"13.15800","1.09666","0.00278"
"13.41600","1.11812","0.00252"
"13.67400","1.13965","0.00297"
"13.93200","1.16117","0.00263"
"14.19000","1.18270","0.00288"
"14.44800","1.20410","0.00299"
"14.70600","1.22563","0.00294"
"14.96400","1.24715","0.00279"
"15.22200","1.26867","0.00355"
"15.48000","1.29014","0.00329"
"15.73800","1.31160","0.00309"
"15.99600","1.33313","0.00289"
"16.25400","1.35459","0.00350"
"16.51200","1.37618","0.00363"
"16.77000","1.39764","0.00327"
"17.02800","1.41916","0.00344"
"17.28600","1.44057","0.00330"
"17.54400","1.46215","0.00332"
"17.80200","1.48362","0.00319"
"18.06000","1.50514","0.00387"
"18.31800","1.52661","0.00408"
"18.57600","1.54813","0.00370"
"18.83400","1.56959","0.00362"
"19.09200","1.59118","0.00401"
"19.35000","1.61264","0.00389"
"19.60800","1.63417","0.00417"
"19.86600","1.65563","0.00397"
"20.12400","1.67710","0.00425"
"20.38200","1.69862","0.00432"
"20.64000","1.72014","0.00379"
"20.89800","1.74161","0.00428"
"21.15600","1.76313","0.00436"
"21.41400","1.78460","0.00427"
"21.67200","1.80612","0.00409"
"21.93000","1.82765","0.00441"
"22.18800","1.84911","0.00434"
"22.44600","1.87064","0.00431"
"22.70400","1.89210","0.00381"
"22.96200","1.91368","0.00431"
"23.22000","1.93509","0.00386"
"23.47800","1.95667","0.00410"
"23.73600","1.97808","0.00453"
"23.99400","1.99972","0.00420"
"24.25200","2.02113","0.00423"
"24.51000","2.04265","0.00427"
"24.76800","2.06411","0.00452"
"25.02600","2.08564","0.00414"
"25.28400","2.10710","0.00460"
"25.54200","2.12869","0.00460"
"25.80000","2.15009","0.00467"
"26.05800","2.17162","0.00437"
"26.31600","2.19308","0.00462"
"26.57400","2.21466","0.00458"
"26.83200","2.23619","0.00438"
"27.09000","2.25765","0.00449"
"27.34800","2.27912","0.00437"
"27.60600","2.30064","0.00448"
"27.86400","2.32217","0.00433"
"28.12200","2.34363","0.00490"
"28.38000","2.36515","0.00458"
"28.63800","2.38662","0.00438"
"28.89600","2.40814","0.00456"
"29.15400","2.42961","0.00496"
"29.41200","2.45113","0.00478"
"29.67000","2.47260","0.00529"
"29.92800","2.49412","0.00496"
"30.18600","2.51558","0.00506"
"30.44400","2.53717","0.00523"
"30.70200","2.55863","0.00507"
"30.96000","2.58010","0.00511"
"31.21800","2.60156","0.00559"
"31.47600","2.62315","0.00464"
"31.73400","2.64461","0.00486"
"31.99200","2.66619","0.00502"
"32.25000","2.68766","0.00523"
"32.50800","2.70918","0.00533"
"32.76600","2.73065","0.00512"
"33.02400","2.75223","0.00521"
"33.28200","2.77370","0.00553"
"33.54000","2.79510","0.00546"
"33.79800","2.81662","0.00543"
"34.05600","2.83809","0.00601"
"34.31400","2.85967","0.00616"
"34.57200","2.88114","0.00560"
"34.83000","2.90266","0.00582"
"35.08800","2.92413","0.00595"
"35.34600","2.94565","0.00611"
"35.60400","2.96712","0.00616"
"35.86200","2.98864","0.00609"
"36.12000","3.01010","0.00638"
"36.37800","3.03169","0.00637"
"36.63600","3.05309","0.00665"
"36.89400","3.07468","0.00690"
"37.15200","3.09614","0.00609"
"37.41000","3.11767","0.00669"
"37.66800","3.13913","0.00649"
"37.92600","3.16065","0.00713"
"38.18400","3.18212","0.00667"
"38.44200","3.20364","0.00700"
"38.70000","3.22511","0.00674"
"38.95800","3.24663","0.00733"
"39.21600","3.26816","0.00740"
"39.47400","3.28968","0.00727"
"39.73200","3.31114","0.00706"
"39.99000","3.33261","0.00670"
"40.24800","3.35419","0.00692"
"40.50600","3.37560","0.00684"
"40.76400","3.39718","0.00646"
"41.02200","3.41865","0.00671"
"41.28000","3.44017","0.00704"
"41.53800","3.46157","0.00682"
"41.79600","3.48316","0.00714"
"42.05400","3.50462","0.00724"
"42.31200","3.52621","0.00718"
"42.57000","3.54755","0.00679"
"42.82800","3.56914","0.00716"
"43.08600","3.59060","0.00712"
"43.34400","3.61218","0.00715"
"43.60200","3.63359","0.00739"
"43.86000","3.65517","0.00699"
"44.11800","3.67658","0.00749"
"44.37600","3.69816","0.00748"
"44.63400","3.71963","0.00759"
"44.89200","3.74115","0.00721"
"45.15000","3.76262","0.00821"
"45.40800","3.78414","0.00727"
"45.66600","3.80566","0.00757"
"45.92400","3.82713","0.00791"
"46.18200","3.84865","0.00780"
"46.44000","3.87012","0.00818"
"46.69800","3.89164","0.00730"
"46.95600","3.91317","0.00759"
"47.21400","3.93469","0.00762"
"47.47200","3.95615","0.00776"
"47.73000","3.97768","0.00782"
"47.98800","3.99914","0.00770"
"48.24600","4.02067","0.00790"
"48.50400","4.04213","0.00823"
"48.76200","4.06366","0.00801"
"49.02000","4.08506","0.00853"
"49.27800","4.10664","0.00858"
"49.53600","4.12811","0.00810"
"49.79400","4.14969","0.00807"
"50.05200","4.17110","0.00761"
"50.31000","4.19268","0.00863"
"50.56800","4.21409","0.00784"
"50.82600","4.23573","0.00804"
"51.08400","4.25713","0.00798"
"51.34200","4.27860","0.00842"
"51.60000","4.30012","0.00860"
"51.85800","4.32165","0.00885"
"52.11600","4.34317","0.00850"
"52.37400","4.36464","0.00862"
"52.63200","4.38616","0.00925"
"52.89000","4.40756","0.00899"
"53.14800","4.42915","0.00913"
"53.40600","4.45061","0.00905"
"53.66400","4.47214","0.00938"
"53.92200","4.49360","0.00935"
"54.18000","4.51513","0.00922"
"54.43800","4.53659","0.00936"
"54.69600","4.55817","0.00931"
"54.95400","4.57964","0.00929"
"55.21200","4.60116","0.00978"
"55.47000","4.62263","0.00913"
"55.72800","4.64415","0.01004"
"55.98600","4.66562","0.00975"
"56.24400","4.68720","0.00968"
"56.50200","4.70860","0.00998"
"56.76000","4.73013","0.01021"
"57.01800","4.75159","0.01005"
"57.27600","4.77318","0.01006"
"57.53400","4.79464","0.01014"
"57.79200","4.81617","0.01019"
"58.05000","4.83763","0.01010"
"58.30800","4.85916","0.01024"
"58.56600","4.88068","0.01037"
"58.82400","4.90214","0.01055"
"59.08200","4.92361","0.01019"
"59.34000","4.94507","0.01085"
"59.59800","4.96666","0.01050"
"59.85600","4.98812","0.01089"
"60.11400","5.00964","0.01137"
"60.37200","5.03105","0.01094"
"60.63000","5.05269","0.01096"
"60.88800","5.07410","0.01090"
"61.14600","5.09568","0.01052"
"61.40400","5.11709","0.01090"
"61.66200","5.13861","0.01069"
"61.92000","5.16008","0.01054"
"62.17800","5.18166","0.01126"
"62.43600","5.20312","0.01105"
"62.69400","5.22471","0.01166"
"62.95200","5.24611","0.01144"
"63.21000","5.26764","0.01138"
"63.46800","5.28910","0.01123"
"63.72600","5.31069","0.01124"
"63.98400","5.33215","0.01178"
"64.24200","5.35361","0.01163"
"64.50000","5.37514","0.01127"
"64.75800","5.39660","0.01193"
"65.01600","5.41813","0.01198"
"65.27400","5.43965","0.01202"
"65.53200","5.46112","0.01215"
"65.79000","5.48264","0.01226"
"66.04800","5.50410","0.01176"
"66.30600","5.52563","0.01242"
"66.56400","5.54715","0.01194"
"66.82200","5.56856","0.01259"
"67.08000","5.59014","0.01313"
"67.33800","5.61161","0.01278"
"67.59600","5.63319","0.01254"
"67.85400","5.65465","0.01252"
"68.11200","5.67618","0.01276"
"68.37000","5.69764","0.01277"
"68.62800","5.71917","0.01304"
"68.88600","5.74063","0.01261"
"69.14400","5.76216","0.01299"
"69.40200","5.78356","0.01164"
"69.66000","5.80515","0.00300"
"69.91800","5.82661","0.00035"
"70.17600","5.84813","0.00089"
"70.43400","5.86966","0.00072"
"70.69200","5.89112","0.00142"
"70.95000","5.91265","0.00068"
"71.20800","5.93411","0.00126"
"71.46600","5.95570","0.00098"
"71.72400","5.97710","0.00127"
"71.98200","5.99862","0.00128"
"72.24000","6.02015","0.00138"
"72.49800","6.04161","0.00114"
"72.75600","6.06314","0.00151"
"73.01400","6.08466","0.00129"
"73.27200","6.10607","0.00088"
"73.53000","6.12765","0.00120"
"73.78800","6.14911","0.00114"
"74.04600","6.17064","0.00105"
"74.30400","6.19204","0.00139"
"74.56200","6.21363","0.00125"
"74.82000","6.23509","0.00167"
"75.07800","6.25668","0.00097"
"75.33600","6.27814","0.00111"
"75.59400","6.29966","0.00098"
"75.85200","6.32107","0.00156"
"76.11000","6.34271","0.00124"
"76.36800","6.36412","0.00099"
"76.62600","6.38564","0.00116"
"76.88400","6.40711","0.00130"
"77.14200","6.42857","0.00151"
"77.40000","6.45015","0.00118"
"77.65800","6.47162","0.00137"
"77.91600","6.49314","0.00133"
"78.17400","6.51461","0.00113"
"78.43200","6.53613","0.00105"
"78.69000","6.55760","0.00138"
"78.94800","6.57918","0.00155"
"79.20600","6.60065","0.00122"
"79.46400","6.62211","0.00148"
"79.72200","6.64357","0.00136"
"79.98000","6.66516","0.00165"
"80.23800","6.68662","0.00164"
"80.49600","6.70815","0.00164"
"80.75400","6.72961","0.00101"
"81.01200","6.75113","0.00159"
"81.27000","6.77260","0.00159"
"81.52800","6.79412","0.00140"
"81.78600","6.81559","0.00116"
"82.04400","6.83711","0.00122"
"82.30200","6.85858","0.00124"
"82.56000","6.88016","0.00117"
"82.81800","6.90169","0.00150"
"83.07600","6.92321","0.00109"
"83.33400","6.94461","0.00119"
"83.59200","6.96614","0.00134"
"83.85000","6.98766","0.00113"
"84.10800","7.00913","0.00144"
"84.36600","7.03065","0.00111"
"84.62400","7.05212","0.00133"
"84.88200","7.07364","0.00156"
"85.14000","7.09510","0.00101"
"85.39800","7.11663","0.00162"
"85.65600","7.13809","0.00157"
"85.91400","7.15968","0.00138"
"86.17200","7.18108","0.00117"
"86.43000","7.20267","0.00132"
"86.68800","7.22413","0.00151"
"86.94600","7.24565","0.00119"
"87.20400","7.26706","0.00139"
"87.46200","7.28858","0.00150"
"87.72000","7.31011","0.00148"
"87.97800","7.33169","0.00129"
"88.23600","7.35316","0.00150"
"88.49400","7.37462","0.00137"
"88.75200","7.39614","0.00119"
"89.01000","7.41761","0.00142"
"89.26800","7.43913","0.00142"
"89.52600","7.46066","0.00172"
"89.78400","7.48212","0.00160"
"90.04200","7.50365","0.00183"
"90.30000","7.52511","0.00166"
"90.55800","7.54669","0.00189"
"90.81600","7.56816","0.00140"
"91.07400","7.58962","0.00194"
"91.33200","7.61115","0.00152"
"91.59000","7.63261","0.00176"
"91.84800","7.65414","0.00190"
"92.10600","7.67560","0.00154"
"92.36400","7.69712","0.00192"
"92.62200","7.71853","0.00166"
"92.88000","7.74017","0.00205"
"93.13800","7.76158","0.00174"
"93.39600","7.78316","0.00211"
"93.65400","7.80463","0.00193"
"93.91200","7.82615","0.00184"
"94.17000","7.84762","0.00211"
"94.42800","7.86914","0.00165"
"94.68600","7.89060","0.00200"
"94.94400","7.91213","0.00183"
"95.20200","7.93359","0.00187"
"95.46000","7.95518","0.00185"
"95.71800","7.97670","0.00175"
"95.97600","7.99811","0.00193"
"96.23400","8.01957","0.00218"
"96.49200","8.04109","0.00181"
"96.75000","8.06262","0.00178"
"97.00800","8.08408","0.00188"
"97.26600","8.10567","0.00215"
"97.52400","8.12713","0.00176"
"97.78200","8.14865","0.00172"
"98.04000","8.17012","0.00138"
"98.29800","8.19170","0.00189"
"98.55600","8.21311","0.00137"
"98.81400","8.23463","0.00143"
"99.07200","8.25610","0.00178"
"99.33000","8.27768","0.00133"
"99.58800","8.29915","0.00174"
"99.84600","8.32061","0.00178"
"100.10400","8.34207","0.00155"
"100.36200","8.36366","0.00196"
"100.62000","8.38512","0.00196"
"100.87800","8.40665","0.00179"
"101.13600","8.42811","0.00175"
"101.39400","8.44970","0.00164"
"101.65200","8.47110","0.00164"
"101.91000","8.49269","0.00209"
"102.16800","8.51415","0.00162"
"102.42600","8.53561","0.00157"
"102.68400","8.55714","0.00205"
"102.94200","8.57860","0.00217"
"103.20000","8.60019","0.00168"
"103.45800","8.62165","0.00174"
"103.71600","8.64317","0.00158"
"103.97400","8.66458","0.00157"
"104.23200","8.68616","0.00200"
"104.49000","8.70763","0.00238"
"104.74800","8.72915","0.00208"
"105.00600","8.75056","0.00208"
"105.26400","8.77214","0.00183"
"105.52200","8.79355","0.00211"
"105.78000","8.81513","0.00225"
"106.03800","8.83665","0.00187"
"106.29600","8.85818","0.00208"
"106.55400","8.87964","0.00221"
"106.81200","8.90117","0.00190"
"107.07000","8.92263","0.00200"
"107.32800","8.94416","0.00197"
"107.58600","8.96556","0.00195"
"107.84400","8.98714","0.00162"
"108.10200","9.00861","0.00116"
"108.36000","9.03013","0.00122"
"108.61800","9.05166","0.00140"
"108.87600","9.07318","0.00149"
"109.13400","9.09459","0.00153"
"109.39200","9.11611","0.00154"
"109.65000","9.13769","0.00162"
"109.90800","9.15916","0.00167"
"110.16600","9.18062","0.00174"
"110.42400","9.20209","0.00182"
"110.68200","9.22367","0.00173"
"110.94000","9.24514","0.00199"
"111.19800","9.26672","0.00168"
"111.45600","9.28806","0.00221"
"111.71400","9.30965","0.00199"
"111.97200","9.33111","0.00202"
"112.23000","9.35264","0.00181"
"112.48800","9.37410","0.00180"
"112.74600","9.39563","0.00229"
"113.00400","9.41709","0.00242"
"113.26200","9.43861","0.00208"
"113.52000","9.46014","0.00237"
"113.77800","9.48166","0.00224"
"114.03600","9.50313","0.00226"
"114.29400","9.52465","0.00176"
"114.55200","9.54612","0.00165"
"114.81000","9.56770","0.00188"
"115.06800","9.58916","0.00164"
"115.32600","9.61063","0.00179"
"115.58400","9.63209","0.00214"
"115.84200","9.65356","0.00196"
"116.10000","9.67514","0.00206"
"116.35800","9.69661","0.00220"
"116.61600","9.71819","0.00170"
"116.87400","9.73960","0.00230"
"117.13200","9.76118","0.00244"
"117.39000","9.78258","0.00220"
"117.64800","9.80417","0.00243"
"117.90600","9.82557","0.00251"
"118.16400","9.84716","0.00215"
"118.42200","9.86862","0.00217"
"118.68000","9.89020","0.00249"
"118.93800","9.91161","0.00231"
"119.19600","9.93313","0.00249"
"119.45400","9.95460","0.00239"
"119.71200","9.97618","0.00291"
"119.97000","9.99759","0.00242"
"120.22800","10.01911","0.00227"
"120.48600","10.04058","0.00248"
"120.74400","10.06216","0.00247"
"121.00200","10.08362","0.00263"
"121.26000","10.10509","0.00256"
"121.51800","10.12661","0.00262"
"121.77600","10.14814","0.00248"
"122.03400","10.16966","0.00260"
"122.29200","10.19113","0.00254"
"122.55000","10.21265","0.00272"
"122.80800","10.23411","0.00282"
"123.06600","10.25564","0.00267"
"123.32400","10.27710","0.00292"
"123.58200","10.29869","0.00309"
"123.84000","10.32015","0.00293"
"124.09800","10.34168","0.00362"
"124.35600","10.36308","0.00318"
"124.61400","10.38461","0.00289"
"124.87200","10.40613","0.00312"
"125.13000","10.42765","0.00316"
"125.38800","10.44912","0.00288"
"125.64600","10.47070","0.00338"
"125.90400","10.49211","0.00336"
"126.16200","10.51369","0.00318"
"126.42000","10.53515","0.00250"
"126.67800","10.55662","0.00300"
"126.93600","10.57808","0.00318"
"127.19400","10.59967","0.00316"
"127.45200","10.62119","0.00314"
"127.71000","10.64266","0.00315"
"127.96800","10.66412","0.00318"
"128.22600","10.68559","0.00387"
"128.48400","10.70717","0.00383"
"128.74200","10.72863","0.00353"
"129.00000","10.75016","0.00370"
"129.25800","10.77162","0.00308"
"129.51600","10.79321","0.00355"
"129.77400","10.81461","0.00336"
"130.03200","10.83619","0.00317"
"130.29000","10.85760","0.00315"
"130.54800","10.87912","0.00351"
"130.80600","10.90053","0.00313"
"131.06400","10.92211","0.00304"
"131.32200","10.94364","0.00337"
"131.58000","10.96522","0.00383"
"131.83800","10.98663","0.00366"
"132.09600","11.00815","0.00365"
"132.35400","11.02962","0.00344"
"132.61200","11.05120","0.00353"
"132.87000","11.07260","0.00337"
"133.12800","11.09413","0.00392"
"133.38600","11.11559","0.00366"
"133.64400","11.13711","0.00415"
"133.90200","11.15870","0.00410"
"134.16000","11.18016","0.00379"
"134.41800","11.20163","0.00381"
"134.67600","11.22315","0.00371"
"134.93400","11.24462","0.00395"
"135.19200","11.26614","0.00382"
"135.45000","11.28767","0.00441"
"135.70800","11.30907","0.00414"
"135.96600","11.33066","0.00436"
"136.22400","11.35206","0.00416"
"136.48200","11.37364","0.00469"
"136.74000","11.39511","0.00462"
"136.99800","11.41669","0.00476"
"137.25600","11.43810","0.00487"
"137.51400","11.45962","0.00479"
"137.77200","11.48108","0.00462"
"138.03000","11.50267","0.00502"
"138.28800","11.52413","0.00457"
"138.54600","11.54566","0.00511"
"138.80400","11.56712","0.00475"
"139.06200","11.58865","0.00574"
"139.32000","11.61011","0.00548"
"139.57800","11.63158","0.00567"
"139.83600","11.65310","0.00436"
"140.09400","11.67462","0.00482"
"140.35200","11.69615","0.00510"
"140.61000","11.71767","0.00501"
"140.86800","11.73914","0.00529"
"141.12600","11.76066","0.00486"
"141.38400","11.78219","0.00561"
"141.64200","11.80365","0.00556"
"141.90000","11.82517","0.00551"
"142.15800","11.84658","0.00531"
"142.41600","11.86816","0.00569"
"142.67400","11.88957","0.00555"
"142.93200","11.91115","0.00583"
"143.19000","11.93262","0.00594"
"143.44800","11.95414","0.00570"
"143.70600","11.97554","0.00534"
"143.96400","11.99719","0.00606"
"144.22200","12.01859","0.00615"
"144.48000","12.04018","0.00630"
"144.73800","12.06164","0.00640"
"144.99600","12.08317","0.00638"
"145.25400","12.10463","0.00642"
"145.51200","12.12621","0.00678"
"145.77000","12.14762","0.00699"
"146.02800","12.16908","0.00646"
"146.28600","12.19067","0.00661"
"146.54400","12.21219","0.00660"
"146.80200","12.23372","0.00599"
"147.06000","12.25512","0.00590"
"147.31800","12.27664","0.00597"
"147.57600","12.29811","0.00600"
"147.83400","12.31969","0.00622"
"148.09200","12.34116","0.00632"
"148.35000","12.36262","0.00620"
"148.60800","12.38403","0.00662"
"148.86600","12.40561","0.00658"
"149.12400","12.42707","0.00656"
"149.38200","12.44866","0.00664"
"149.64000","12.47012","0.00670"
"149.89800","12.49165","0.00676"
"150.15600","12.51311","0.00694"
"150.41400","12.53464","0.00738"
"150.67200","12.55610","0.00747"
"150.93000","12.57768","0.00744"
"151.18800","12.59909","0.00749"
"151.44600","12.62067","0.00654"
"151.70400","12.64214","0.00698"
"151.96200","12.66372","0.00623"
"152.22000","12.68513","0.00476"
"152.47800","12.70665","0.00481"
"152.73600","12.72812","0.00445"
"152.99400","12.74964","0.00419"
"153.25200","12.77116","0.00458"
"153.51000","12.79263","0.00474"
"153.76800","12.81415","0.00473"
"154.02600","12.83562","0.00472"
"154.28400","12.85720","0.00518"
"154.54200","12.87866","0.00503"
"154.80000","12.90019","0.00532"
"155.05800","12.92153","0.00560"
"155.31600","12.94318","0.00552"
"155.57400","12.96464","0.00525"
"155.83200","12.98617","0.00506"
"156.09000","13.00757","0.00557"
"156.34800","13.02910","0.00522"
"156.60600","13.05056","0.00529"
"156.86400","13.07220","0.00523"
"157.12200","13.09367","0.00502"
"157.38000","13.11519","0.00550"
"157.63800","13.13666","0.00513"
"157.89600","13.15818","0.00565"
"158.15400","13.17965","0.00546"
"158.41200","13.20117","0.00599"
"158.67000","13.22263","0.00582"
"158.92800","13.24410","0.00568"
"159.18600","13.26562","0.00562"
"159.44400","13.28715","0.00577"
"159.70200","13.30873","0.00601"
"159.96000","13.33014","0.00635"
"160.21800","13.35166","0.00628"
"160.47600","13.37313","0.00639"
"160.73400","13.39471","0.00592"
"160.99200","13.41611","0.00601"
"161.25000","13.43764","0.00631"
"161.50800","13.45910","0.00598"
"161.76600","13.48063","0.00533"
"162.02400","13.50209","0.00543"
"162.28200","13.52374","0.00560"
"162.54000","13.54508","0.00535"
"162.79800","13.56660","0.00569"
"163.05600","13.58807","0.00552"
"163.31400","13.60965","0.00623"
"163.57200","13.63112","0.00603"
"163.83000","13.65264","0.00424"
"164.08800","13.67411","0.00487"
"164.34600","13.69563","0.00523"
"164.60400","13.71715","0.00498"
"164.86200","13.73862","0.00485"
"165.12000","13.76014","0.00526"
"165.37800","13.78167","0.00566"
"165.63600","13.80313","0.00501"
"165.89400","13.82460","0.00552"
"166.15200","13.84618","0.00568"
"166.41000","13.86764","0.00524"
"166.66800","13.88917","0.00557"
"166.92600","13.91063","0.00589"
"167.18400","13.93216","0.00515"
"167.44200","13.95362","0.00551"
"167.70000","13.97515","0.00530"
"167.95800","13.99661","0.00520"
"168.21600","14.01814","0.00564"
"168.47400","14.03960","0.00574"
"168.73200","14.06118","0.00612"
"168.99000","14.08259","0.00604"
"169.24800","14.10417","0.00611"
"169.50600","14.12558","0.00565"
"169.76400","14.14716","0.00524"
"170.02200","14.16862","0.00552"
"170.28000","14.19015","0.00514"
"170.53800","14.21167","0.00513"
"170.79600","14.23320","0.00511"
"171.05400","14.25466","0.00573"
"171.31200","14.27613","0.00553"
"171.57000","14.29765","0.00574"
"171.82800","14.31911","0.00598"
"172.08600","14.34064","0.00580"
"172.34400","14.36216","0.00557"
"172.60200","14.38369","0.00601"
"172.86000","14.40509","0.00584"
"173.11800","14.42668","0.00635"
"173.37600","14.44814","0.00584"
"173.63400","14.46967","0.00655"
"173.89200","14.49107","0.00608"
"174.15000","14.51260","0.00590"
"174.40800","14.53412","0.00550"
"174.66600","14.55564","0.00574"
"174.92400","14.57711","0.00589"
"175.18200","14.59863","0.00613"
"175.44000","14.62010","0.00634"
"175.69800","14.64162","0.00653"
"175.95600","14.66308","0.00656"
"176.21400","14.68467","0.00630"
"176.47200","14.70607","0.00653"
"176.73000","14.72760","0.00646"
"176.98800","14.74918","0.00654"
"177.24600","14.77065","0.00704"
"177.50400","14.79217","0.00707"
"177.76200","14.81369","0.00679"
"178.02000","14.83516","0.00712"
"178.27800","14.85662","0.00714"
"178.53600","14.87815","0.00713"
"178.79400","14.89961","0.00692"
"179.05200","14.92120","0.00686"
"179.31000","14.94254","0.00743"
"179.56800","14.96418","0.00717"
"179.82600","14.98565","0.00709"
"180.08400","15.00717","0.00721"
"180.34200","15.02858","0.00705"
"180.60000","15.05016","0.00738"
"180.85800","15.07157","0.00720"
"181.11600","15.09315","0.00736"
"181.37400","15.11462","0.00770"
"181.63200","15.13614","0.00820"
"181.89000","15.15760","0.00728"
"182.14800","15.17913","0.00755"
"182.40600","15.20053","0.00812"
"182.66400","15.22218","0.00822"
"182.92200","15.24364","0.00812"
"183.18000","15.26517","0.00830"
"183.43800","15.28663","0.00805"
"183.69600","15.30821","0.00849"
"183.95400","15.32968","0.00875"
"184.21200","15.35114","0.00858"
"184.47000","15.37261","0.00886"
"184.72800","15.39407","0.00901"
"184.98600","15.41566","0.00867"
"185.24400","15.43718","0.00874"
"185.50200","15.45864","0.00844"
"185.76000","15.48017","0.00879"
"186.01800","15.50169","0.00883"
"186.27600","15.52310","0.00895"
"186.53400","15.54462","0.00879"
"186.79200","15.56603","0.00926"
"187.05000","15.58761","0.00998"
"187.30800","15.60907","0.00978"
"187.56600","15.63072","0.00947"
"187.82400","15.65212","0.00971"
"188.08200","15.67365","0.00987"
"188.34000","15.69511","0.01015"
"188.59800","15.71663","0.00986"
"188.85600","15.73810","0.01006"
"189.11400","15.75962","0.00975"
"189.37200","15.78109","0.01029"
"189.63000","15.80267","0.01008"
"189.88800","15.82414","0.00154"
"190.14600","15.84560","0.00112"
"190.40400","15.86713","0.00068"
"190.66200","15.88865","0.00159"
"190.92000","15.91011","0.00107"
"191.17800","15.93164","0.00120"
"191.43600","15.95316","0.00200"
"191.69400","15.97463","0.00124"
"191.95200","15.99615","0.00201"
"192.21000","16.01762","0.00135"
"192.46800","16.03920","0.00164"
"192.72600","16.06060","0.00228"
"192.98400","16.08213","0.00256"
"193.24200","16.10353","0.00238"
"193.50000","16.12512","0.00235"
"193.75800","16.14658","0.00245"
"194.01600","16.16811","0.00260"
"194.27400","16.18957","0.00240"
"194.53200","16.21109","0.00334"
"194.79000","16.23256","0.00308"
"195.04800","16.25420","0.00299"
"195.30600","16.27561","0.00302"
"195.56400","16.29719","0.00312"
"195.82200","16.31860","0.00347"
"196.08000","16.34018","0.00350"
"196.33800","16.36164","0.00320"
"196.59600","16.38317","0.00345"
"196.85400","16.40463","0.00347"
"197.11200","16.42610","0.00411"
"197.37000","16.44762","0.00385"
"197.62800","16.46909","0.00394"
"197.88600","16.49067","0.00420"
"198.14400","16.51213","0.00421"
"198.40200","16.53366","0.00461"
"198.66000","16.55506","0.00447"
"198.91800","16.57665","0.00432"
"199.17600","16.59811","0.00458"
"199.43400","16.61964","0.00460"
"199.69200","16.64104","0.00467"
"199.95000","16.66263","0.00491"
"200.20800","16.68409","0.00462"
"200.46600","16.70567","0.00512"
"200.72400","16.72714","0.00529"
"200.98200","16.74866","0.00537"
"201.24000","16.77013","0.00530"
"201.49800","16.79171","0.00554"
"201.75600","16.81306","0.00578"
"202.01400","16.83464","0.00591"
"202.27200","16.85604","0.00638"
"202.53000","16.87769","0.00627"
"202.78800","16.89915","0.00706"
"203.04600","16.92068","0.00643"
"203.30400","16.94214","0.00654"
"203.56200","16.96360","0.00712"
"203.82000","16.98513","0.00696"
"204.07800","17.00660","0.00709"
"204.33600","17.02818","0.00708"
"204.59400","17.04958","0.00732"
"204.85200","17.07117","0.00719"
"205.11000","17.09257","0.00717"
"205.36800","17.11415","0.00747"
"205.62600","17.13562","0.00807"
"205.88400","17.15714","0.00809"
"206.14200","17.17855","0.00806"
"206.40000","17.20013","0.00846"
"206.65800","17.22160","0.00831"
"206.91600","17.24318","0.00895"
"207.17400","17.26459","0.00885"
"207.43200","17.28611","0.00854"
"207.69000","17.30758","0.00912"
"207.94800","17.32916","0.00924"
"208.20600","17.35062","0.00971"
"208.46400","17.37215","0.00997"
"208.72200","17.39361","0.00959"
"208.98000","17.41514","0.00928"
"209.23800","17.43666","0.00932"
"209.49600","17.45812","0.00963"
"209.75400","17.47959","0.01006"
"210.01200","17.50111","0.00974"
"210.27000","17.52264","0.01089"
"210.52800","17.54410","0.01072"
"210.78600","17.56563","0.01046"
"211.04400","17.58715","0.01058"
"211.30200","17.60868","0.01071"
"211.56000","17.63008","0.01090"
"211.81800","17.65166","0.01119"
"212.07600","17.67313","0.01114"
"212.33400","17.69459","0.01197"
"212.59200","17.71606","0.01170"
"212.85000","17.73764","0.01224"
"213.10800","17.75911","0.01237"
"213.36600","17.78069","0.01263"
"213.62400","17.80210","0.01336"
"213.88200","17.82368","0.01290"
"214.14000","17.84514","0.01394"
"214.39800","17.86667","0.01381"
"214.65600","17.88807","0.01408"
"214.91400","17.90960","0.01460"
"215.17200","17.93112","0.01530"
"215.43000","17.95264","0.01519"
"215.68800","17.97417","0.01569"
"215.94600","17.99563","0.01573"
"216.20400","18.01716","0.01610"
"216.46200","18.03862","0.01661"
"216.72000","18.06015","0.01676"
"216.97800","18.08161","0.01662"
"217.23600","18.10313","0.01661"
"217.49400","18.12460","0.01614"
"217.75200","18.14612","0.01498"
"218.01000","18.16759","0.01742"
"218.26800","18.18917","0.01748"
"218.52600","18.21058","0.01863"
"218.78400","18.23216","0.01534"
"219.04200","18.25356","0.01550"
"219.30000","18.27515","0.01718"
"219.55800","18.29661","0.01710"
"219.81600","18.31814","0.01793"
"220.07400","18.33960","0.01012"
"220.33200","18.36113","0.01191"
"220.59000","18.38259","0.01127"
"220.84800","18.40417","0.01214"
"221.10600","18.42564","0.01234"
"221.36400","18.44716","0.01307"
"221.62200","18.46863","0.01347"
"221.88000","18.49015","0.01382"
"222.13800","18.51162","0.01474"
"222.39600","18.53314","0.01380"
"222.65400","18.55466","0.01578"
"222.91200","18.57607","0.01582"
"223.17000","18.59765","0.01644"
"223.42800","18.61912","0.01735"
"223.68600","18.64070","0.01751"
"223.94400","18.66205","0.01833"
"224.20200","18.68363","0.01940"
"224.46000","18.70516","0.02015"
"224.71800","18.72668","0.02089"
"224.97600","18.74809","0.02166"
"225.23400","18.76955","0.02208"
"225.49200","18.79113","0.02286"
"225.75000","18.81266","0.02312"
"226.00800","18.83412","0.02432"
"226.26600","18.85565","0.02492"
"226.52400","18.87717","0.02528"
"226.78200","18.89869","0.02649"
"227.04000","18.92016","0.02653"
"227.29800","18.94168","0.02755"
"227.55600","18.96309","0.02774"
"227.81400","18.98461","0.02847"
"228.07200","19.00607","0.02913"
"228.33000","19.02766","0.02978"
"228.58800","19.04918","0.03030"
"228.84600","19.07065","0.03088"
"229.10400","19.09211","0.03166"
"229.36200","19.11358","0.03211"
"229.62000","19.13510","0.03334"
"229.87800","19.15663","0.03363"
"230.13600","19.17815","0.03453"
"230.39400","19.19962","0.03554"
"230.65200","19.22114","0.03704"
"230.91000","19.24260","0.03704"
"231.16800","19.26419","0.03824"
"231.42600","19.28559","0.03946"
"231.68400","19.30712","0.03966"
"231.94200","19.32858","0.04057"
"232.20000","19.35017","0.04120"
"232.45800","19.37163","0.04217"
"232.71600","19.39315","0.04216"
"232.97400","19.41462","0.04299"
"233.23200","19.43614","0.04366"
"233.49000","19.45767","0.04481"
"233.74800","19.47913","0.04493"
"234.00600","19.50066","0.04674"
"234.26400","19.52212","0.04699"
"234.52200","19.54364","0.04803"
"234.78000","19.56517","0.04896"
"235.03800","19.58663","0.04987"
"235.29600","19.60810","0.05003"
"235.55400","19.62962","0.05211"
"235.81200","19.65108","0.05294"
"236.07000","19.67261","0.05389"
"236.32800","19.69407","0.05502"
"236.58600","19.71566","0.05574"
"236.84400","19.73706","0.05710"
"237.10200","19.75865","0.05835"
"237.36000","19.78005","0.05890"
"237.61800","19.80163","0.06061"
"237.87600","19.82310","0.06171"
"238.13400","19.84462","0.06292"
"238.39200","19.86609","0.06514"
"238.65000","19.88767","0.06574"
"238.90800","19.90914","0.06714"
"239.16600","19.93066","0.06915"
"239.42400","19.95213","0.07075"
"239.68200","19.97371","0.07203"
"239.94000","19.99512","0.07236"
"240.19800","20.01664","0.07375"
"240.45600","20.03810","0.07509"
"240.71400","20.05963","0.07611"
"240.97200","20.08115","0.07715"
"241.23000","20.10262","0.07771"
"241.48800","20.12420","0.07850"
"241.74600","20.14561","0.07923"
"242.00400","20.16719","0.08002"
"242.26200","20.18859","0.08015"
"242.52000","20.21018","0.08149"
"242.77800","20.23158","0.08202"
"243.03600","20.25317","0.08309"
"243.29400","20.27463","0.08351"
"243.55200","20.29615","0.08405"
"243.81000","20.31762","0.08525"
"244.06800","20.33920","0.08571"
"244.32600","20.36061","0.08562"
"244.58400","20.38213","0.08624"
"244.84200","20.40360","0.08705"
"245.10000","20.42518","0.08793"
"245.35800","20.44658","0.08826"
"245.61600","20.46811","0.08900"
"245.87400","20.48957","0.08935"
"246.13200","20.51116","0.09002"
"246.39000","20.53268","0.09106"
"246.64800","20.55415","0.09166"
"246.90600","20.57561","0.09207"
"247.16400","20.59719","0.09269"
"247.42200","20.61866","0.09351"
"247.68000","20.64018","0.09382"
"247.93800","20.66165","0.09472"
"248.19600","20.68305","0.09562"
"248.45400","20.70464","0.09628"
"248.71200","20.72610","0.09768"
"248.97000","20.74769","0.09813"
"249.22800","20.76909","0.09921"
"249.48600","20.79067","0.10084"
"249.74400","20.81208","0.10123"
"250.00200","20.83366","0.10170"
"250.26000","20.85513","0.10323"
"250.51800","20.87665","0.10421"
"250.77600","20.89812","0.10500"
"251.03400","20.91964","0.10647"
"251.29200","20.94105","0.10756"
"251.55000","20.96269","0.10868"
"251.80800","20.98415","0.11018"
"252.06600","21.00562","0.11170"
"252.32400","21.02714","0.11211"
"252.58200","21.04866","0.11273"
"252.84000","21.07013","0.11457"
"253.09800","21.09159","0.11621"
"253.35600","21.11306","0.11842"
"253.61400","21.13464","0.11447"
"253.87200","21.15617","0.11608"
"254.13000","21.17763","0.11806"
"254.38800","21.19916","0.12037"
"254.64600","21.22062","0.12195"
"254.90400","21.24215","0.12387"
"255.16200","21.26361","0.12587"
"255.42000","21.28519","0.12769"
"255.67800","21.30654","0.12911"
"255.93600","21.32812","0.13127"
"256.19400","21.34958","0.13158"
"256.45200","21.37117","0.13335"
"256.71000","21.39264","0.13342"
"256.96800","21.41416","0.13537"
"257.22600","21.43556","0.13648"
"257.48400","21.45715","0.13832"
"257.74200","21.47861","0.13930"
"258.00000","21.50014","0.14005"
"258.25800","21.52160","0.14155"
"258.51600","21.54313","0.14297"
"258.77400","21.56465","0.14374"
"259.03200","21.58611","0.14453"
"259.29000","21.60770","0.14569"
"259.54800","21.62916","0.14690"
"259.80600","21.65063","0.14757"
"260.06400","21.67209","0.14812"
"260.32200","21.69368","0.14906"
"260.58000","21.71514","0.14954"
"260.83800","21.73660","0.15052"
"261.09600","21.75807","0.15126"
"261.35400","21.77965","0.15223"
"261.61200","21.80112","0.15275"
"261.87000","21.82264","0.15340"
"262.12800","21.84411","0.15489"
"262.38600","21.86569","0.15600"
"262.64400","21.88715","0.15646"
"262.90200","21.90868","0.15746"
"263.16000","21.93008","0.15800"
"263.41800","21.95161","0.15908"
"263.67600","21.97307","0.15969"
"263.93400","21.99466","0.16084"
"264.19200","22.01612","0.16128"
"264.45000","22.03770","0.16260"
"264.70800","22.05911","0.16336"
"264.96600","22.08069","0.16402"
"265.22400","22.10216","0.16538"
"265.48200","22.12368","0.16606"
"265.74000","22.14515","0.16638"
"265.99800","22.16661","0.16753"
"266.25600","22.18814","0.16918"
"266.51400","22.20960","0.17045"
"266.77200","22.23118","0.17121"
"267.03000","22.25265","0.17208"
"267.28800","22.27411","0.17163"
"267.54600","22.29558","0.17303"
"267.80400","22.31716","0.17412"
"268.06200","22.33862","0.17555"
"268.32000","22.36015","0.17679"
"268.57800","22.38156","0.17801"
"268.83600","22.40314","0.17935"
"269.09400","22.42460","0.18080"
"269.35200","22.44619","0.18171"
"269.61000","22.46765","0.18304"
"269.86800","22.48918","0.18442"
"270.12600","22.51064","0.18562"
"270.38400","22.53217","0.18684"
"270.64200","22.55363","0.18751"
"270.90000","22.57515","0.18876"
"271.15800","22.59662","0.18983"
"271.41600","22.61814","0.18990"
"271.67400","22.63961","0.19055"
"271.93200","22.66119","0.19112"
"272.19000","22.68266","-0.01645"
"272.44800","22.70412","0.01086"
"272.70600","22.72564","0.00358"
"272.96400","22.74717","0.00292"
"273.22200","22.76869","0.00527"
"273.48000","22.79010","0.00482"
"273.73800","22.81162","0.00287"
"273.99600","22.83308","0.00476"
"274.25400","22.85467","0.00455"
"274.51200","22.87613","0.00369"
"274.77000","22.89766","0.00434"
"275.02800","22.91906","0.00570"
"275.28600","22.94065","0.00379"
"275.54400","22.96217","0.00518"
"275.80200","22.98369","0.00519"
"276.06000","23.00510","0.00459"
"276.31800","23.02662","0.00569"
"276.57600","23.04809","0.00546"
"276.83400","23.06967","0.00455"
"277.09200","23.09114","0.00619"
"277.35000","23.11266","0.00568"
"277.60800","23.13412","0.00540"
"277.86600","23.15565","0.00621"
"278.12400","23.17718","0.00547"
"278.38200","23.19864","0.00574"
"278.64000","23.22010","0.00687"
"278.89800","23.24163","0.00632"
"279.15600","23.26315","0.00671"
"279.41400","23.28461","0.00714"
"279.67200","23.30614","0.00569"
"279.93000","23.32760","0.00713"
"280.18800","23.34919","0.00693"
"280.44600","23.37059","0.00750"
"280.70400","23.39218","0.00745"
"280.96200","23.41364","0.00756"
"281.22000","23.43517","0.00797"
"281.47800","23.45657","0.00790"
"281.73600","23.47815","0.00752"
"281.99400","23.49962","0.00805"
"282.25200","23.52120","0.00749"
"282.51000","23.54260","0.00780"
"282.76800","23.56419","0.00722"
"283.02600","23.58560","0.00777"
"283.28400","23.60712","0.00753"
"283.54200","23.62864","0.00723"
"283.80000","23.65011","0.00704"
"284.05800","23.67157","0.00760"
"284.31600","23.69310","0.00753"
"284.57400","23.71468","0.00427"
"284.83200","23.73615","0.00374"
"285.09000","23.75767","0.00296"
"285.34800","23.77913","0.00346"
"285.60600","23.80066","0.00399"
"285.86400","23.82218","0.00323"
"286.12200","23.84365","0.00332"
"286.38000","23.86505","0.00407"
"286.63800","23.88664","0.00402"
"286.89600","23.90810","0.00325"
"287.15400","23.92963","0.00438"
"287.41200","23.95115","0.00399"
"287.67000","23.97261","0.00341"
"287.92800","23.99408","0.00382"
"288.18600","24.01560","0.00404"
"288.44400","24.03713","0.00442"
"288.70200","24.05865","0.00408"
"288.96000","24.08006","0.00484"
"289.21800","24.10164","0.00445"
"289.47600","24.12310","0.00461"
"289.73400","24.14475","0.00451"
"289.99200","24.16615","0.00437"
"290.25000","24.18762","0.00451"
"290.50800","24.20914","0.00434"
"290.76600","24.23067","0.00475"
"291.02400","24.25213","0.00454"
"291.28200","24.27365","0.00434"
"291.54000","24.29512","0.00418"
"291.79800","24.31658","0.00484"
"292.05600","24.33811","0.00503"
"292.31400","24.35963","0.00510"
"292.57200","24.38121","0.00481"
"292.83000","24.40256","0.00471"
"293.08800","24.42414","0.00497"
"293.34600","24.44561","0.00451"
"293.60400","24.46719","0.00522"
"293.86200","24.48860","0.00493"
"294.12000","24.51012","0.00500"
"294.37800","24.53159","0.00500"
"294.63600","24.55311","0.00517"
"294.89400","24.57463","0.00470"
"295.15200","24.59616","0.00476"
"295.41000","24.61762","0.00533"
"295.66800","24.63915","0.00502"
"295.92600","24.66061","0.00502"
"296.18400","24.68219","0.00546"
"296.44200","24.70360","0.00517"
"296.70000","24.72512","0.00531"
"296.95800","24.74659","0.00558"
"297.21600","24.76811","0.00507"
"297.47400","24.78970","0.00511"
"297.73200","24.81116","0.00487"
"297.99000","24.83263","0.00544"
"298.24800","24.85415","0.00551"
"298.50600","24.87568","0.00552"
"298.76400","24.89708","0.00548"
"299.02200","24.91866","0.00549"
"299.28000","24.94007","0.00306"
"299.53800","24.96165","0.00350"
"299.79600","24.98306","0.00299"
"300.05400","25.00470","0.00334"
"300.31200","25.02611","0.00311"
"300.57000","25.04763","0.00400"
"300.82800","25.06903","0.00331"
"301.08600","25.09068","0.00353"
"301.34400","25.11214","0.00337"
"301.60200","25.13367","0.00414"
"301.86000","25.15507","0.00351"
"302.11800","25.17665","0.00332"
"302.37600","25.19812","0.00329"
"302.63400","25.21964","0.00347"
"302.89200","25.24111","0.00331"
"303.15000","25.26263","0.00410"
"303.40800","25.28416","0.00366"
"303.66600","25.30562","0.00407"
"303.92400","25.32715","0.00372"
"304.18200","25.34861","0.00380"
"304.44000","25.37013","0.00335"
"304.69800","25.39160","0.00417"
"304.95600","25.41312","0.00401"
"305.21400","25.43465","0.00421"
"305.47200","25.45617","0.00379"
"305.73000","25.47763","0.00393"
"305.98800","25.49916","0.00363"
"306.24600","25.52057","0.00380"
"306.50400","25.54215","0.00405"
"306.76200","25.56355","0.00424"
"307.02000","25.58513","0.00417"
"307.27800","25.60660","0.00431"
"307.53600","25.62819","0.00438"
"307.79400","25.64959","0.00449"
"308.05200","25.67117","0.00352"
"308.31000","25.69258","0.00390"
"308.56800","25.71422","0.00337"
"308.82600","25.73563","0.00379"
"309.08400","25.75715","0.00398"
"309.34200","25.77862","0.00350"
"309.60000","25.80008","0.00380"
"309.85800","25.82161","0.00375"
"310.11600","25.84313","0.00417"
"310.37400","25.86471","0.00382"
"310.63200","25.88612","0.00419"
"310.89000","25.90764","0.00398"
"311.14800","25.92911","0.00403"
"311.40600","25.95069","0.00430"
"311.66400","25.97209","0.00396"
"311.92200","25.99368","0.00423"
"312.18000","26.01508","0.00438"
"312.43800","26.03661","0.00444"
"312.69600","26.05813","0.00433"
"312.95400","26.07972","0.00445"
"313.21200","26.10112","0.00440"
"313.47000","26.12265","0.00453"
"313.72800","26.14411","0.00437"
"313.98600","26.16563","0.00488"
"314.24400","26.18716","0.00436"
"314.50200","26.20862","0.00490"
"314.76000","26.23009","0.00430"
"315.01800","26.25167","0.00488"
"315.27600","26.27313","0.00440"
"315.53400","26.29466","0.00484"
"315.79200","26.31612","0.00515"
"316.05000","26.33765","0.00462"
"316.30800","26.35917","0.00465"
"316.56600","26.38064","0.00494"
"316.82400","26.40216","0.00528"
"317.08200","26.42357","0.00470"
"317.34000","26.44515","0.00473"
"317.59800","26.46661","0.00506"
"317.85600","26.48820","0.00482"
"318.11400","26.50960","0.00497"
"318.37200","26.53113","0.00492"
"318.63000","26.55259","0.00488"
"318.88800","26.57412","0.00436"
"319.14600","26.59558","0.00520"
"319.40400","26.61711","0.00480"
"319.66200","26.63857","0.00504"
"319.92000","26.66009","0.00528"
"320.17800","26.68156","0.00497"
"320.43600","26.70320","0.00521"
"320.69400","26.72466","0.00488"
"320.95200","26.74613","0.00486"
"321.21000","26.76765","0.00540"
"321.46800","26.78918","0.00484"
"321.72600","26.81064","0.00523"
"321.98400","26.83217","0.00491"
"322.24200","26.85357","0.00479"
"322.50000","26.87510","0.00532"
"322.75800","26.89662","0.00508"
"323.01600","26.91808","0.00523"
"323.27400","26.93967","0.00516"
"323.53200","26.96113","0.00474"
"323.79000","26.98266","0.00505"
"324.04800","27.00412","0.00509"
"324.30600","27.02565","0.00486"
"324.56400","27.04711","0.00479"
"324.82200","27.06863","0.00501"
"325.08000","27.09004","0.00526"
"325.33800","27.11168","0.00523"
"325.59600","27.13309","0.00505"
"325.85400","27.15467","0.00543"
"326.11200","27.17608","0.00543"
"326.37000","27.19766","0.00500"
"326.62800","27.21912","0.00513"
"326.88600","27.24065","0.00504"
"327.14400","27.26211","0.00545"
"327.40200","27.28358","0.00509"
"327.66000","27.30510","0.00550"
"327.91800","27.32663","0.00556"
"328.17600","27.34815","0.00539"
"328.43400","27.36962","0.00537"
"328.69200","27.39108","0.00577"
"328.95000","27.41266","0.00575"
"329.20800","27.43419","0.00591"
"329.46600","27.45560","0.00551"
"329.72400","27.47712","0.00569"
"329.98200","27.49858","0.00576"
"330.24000","27.52016","0.00602"
"330.49800","27.54163","0.00575"
"330.75600","27.56315","0.00558"
"331.01400","27.58456","0.00626"
"331.27200","27.60614","0.00557"
"331.53000","27.62761","0.00619"
"331.78800","27.64913","0.00584"
"332.04600","27.67060","0.00577"
"332.30400","27.69218","0.00584"
"332.56200","27.71358","0.00548"
"332.82000","27.73517","0.00550"
"333.07800","27.75664","0.00560"
"333.33600","27.77822","0.00565"
"333.59400","27.79962","0.00544"
"333.85200","27.82115","0.00583"
"334.11000","27.84261","0.00557"
"334.36800","27.86419","0.00509"
"334.62600","27.88566","0.00545"
"334.88400","27.90713","0.00566"
"335.14200","27.92859","0.00573"
"335.40000","27.95005","0.00532"
"335.65800","27.97170","0.00532"
"335.91600","27.99316","0.00538"
"336.17400","28.01469","0.00543"
"336.43200","28.03615","0.00579"
"336.69000","28.05767","0.00535"
"336.94800","28.07914","0.00543"
"337.20600","28.10066","0.00549"
"337.46400","28.12207","0.00581"
"337.72200","28.14359","0.00571"
"337.98000","28.16506","0.00504"
"338.23800","28.18664","0.00527"
"338.49600","28.20810","0.00476"
"338.75400","28.22963","0.00453"
"339.01200","28.25109","0.00501"
"339.27000","28.27268","0.00503"
"339.52800","28.29408","0.00467"
"339.78600","28.31567","0.00485"
"340.04400","28.33707","0.00499"
"340.30200","28.35865","0.00462"
"340.56000","28.38012","0.00473"
"340.81800","28.40170","0.00423"
"341.07600","28.42317","0.00443"
"341.33400","28.44463","0.00489"
"341.59200","28.46610","0.00533"
"341.85000","28.48762","0.00464"
"342.10800","28.50914","0.00517"
"342.36600","28.53061","0.00415"
"342.62400","28.55213","0.00477"
"342.88200","28.57354","0.00502"
"343.14000","28.59512","0.00495"
"343.39800","28.61665","0.00476"
"343.65600","28.63817","0.00463"
"343.91400","28.65957","0.00449"
"344.17200","28.68116","0.00432"
"344.43000","28.70262","0.00422"
"344.68800","28.72421","0.00440"
"344.94600","28.74567","0.00454"
"345.20400","28.76714","0.00456"
"345.46200","28.78860","0.00492"
"345.72000","28.81013","0.00444"
"345.97800","28.83165","0.00456"
"346.23600","28.85317","0.00469"
"346.49400","28.87464","0.00449"
"346.75200","28.89610","0.00447"
"347.01000","28.91763","0.00493"
"347.26800","28.93909","0.00484"
"347.52600","28.96062","0.00404"
"347.78400","28.98214","0.00480"
"348.04200","29.00360","0.00408"
"348.30000","29.02513","0.00484"
"348.55800","29.04665","0.00428"
"348.81600","29.06812","0.00502"
"349.07400","29.08964","0.00405"
"349.33200","29.11110","0.00492"
"349.59000","29.13269","0.00436"
"349.84800","29.15409","0.00470"
"350.10600","29.17562","0.00466"
"350.36400","29.19702","0.00481"
"350.62200","29.21861","0.00487"
"350.88000","29.24007","0.00494"
"351.13800","29.26165","0.00449"
"351.39600","29.28312","0.00493"
"351.65400","29.30470","0.00414"
"351.91200","29.32611","0.00506"
"352.17000","29.34769","0.00451"
"352.42800","29.36916","0.00504"
"352.68600","29.39062","0.00466"
"352.94400","29.41209","0.00473"
"353.20200","29.43367","0.00449"
"353.46000","29.45514","0.00514"
"353.71800","29.47666","0.00471"
"353.97600","29.49818","0.00528"
"354.23400","29.51959","0.00495"
"354.49200","29.54117","0.00475"
"354.75000","29.56264","0.00435"
"355.00800","29.58410","0.00499"
"355.26600","29.60556","0.00522"
"355.52400","29.62715","0.00499"
"355.78200","29.64855","0.00460"
"356.04000","29.67014","0.00475"
"356.29800","29.69166","0.00496"
"356.55600","29.71313","0.00499"
"356.81400","29.73459","0.00502"
"357.07200","29.75611","0.00527"
"357.33000","29.77764","0.00504"
"357.58800","29.79922","0.00506"
"357.84600","29.82063","0.00523"
"358.10400","29.84215","0.00519"
"358.36200","29.86362","0.00534"
"358.62000","29.88520","0.00546"
"358.87800","29.90660","0.00554"
"359.13600","29.92813","0.00501"
"359.39400","29.94966","0.00558"
"359.65200","29.97118","0.00583"
"359.91000","29.99270","0.00534"
"360.16800","30.01417","0.00574"
"360.42600","30.03563","0.00567"
"360.68400","30.05709","0.00562"
"360.94200","30.07862","0.00568"
"361.20000","30.10015","0.00619"
"361.45800","30.12167","0.00603"
"361.71600","30.14307","0.00626"
"361.97400","30.16466","0.00606"
"362.23200","30.18612","0.00604"
"362.49000","30.20771","0.00622"
"362.74800","30.22911","0.00615"
"363.00600","30.25063","0.00642"
"363.26400","30.27204","0.00642"
"363.52200","30.29362","0.00687"
"363.78000","30.31515","0.00666"
"364.03800","30.33667","0.00661"
"364.29600","30.35814","0.00661"
"364.55400","30.37966","0.00651"
"364.81200","30.40112","0.00677"
"365.07000","30.42271","0.00651"
"365.32800","30.44411","0.00683"
"365.58600","30.46564","0.00693"
"365.84400","30.48704","0.00653"
"366.10200","30.50863","0.00612"
"366.36000","30.53015","0.00687"
"366.61800","30.55162","0.00627"
"366.87600","30.57314","0.00678"
"367.13400","30.59466","0.00663"
"367.39200","30.61613","0.00632"
"367.65000","30.63765","0.00661"
"367.90800","30.65918","0.00720"
"368.16600","30.68058","0.00687"
"368.42400","30.70222","0.00697"
"368.68200","30.72357","0.00684"
"368.94000","30.74515","0.00752"
"369.19800","30.76662","0.00701"
"369.45600","30.78814","0.00694"
"369.71400","30.80960","0.00678"
"369.97200","30.83113","0.00669"
"370.23000","30.85260","0.00679"
"370.48800","30.87418","0.00675"
"370.74600","30.89558","0.00674"
"371.00400","30.91717","0.00656"
"371.26200","30.93857","0.00702"
"371.52000","30.96016","0.00646"
"371.77800","30.98162","0.00612"
"372.03600","31.00315","0.00635"
"372.29400","31.02467","0.00679"
"372.55200","31.04608","0.00717"
"372.81000","31.06766","0.00710"
"373.06800","31.08912","0.00678"
"373.32600","31.11065","0.00721"
"373.58400","31.13211","0.00678"
"373.84200","31.15364","0.00681"
"374.10000","31.17510","0.00696"
"374.35800","31.19668","0.00704"
"374.61600","31.21809","0.00726"
"374.87400","31.23967","0.00712"
"375.13200","31.26114","0.00663"
"375.39000","31.28266","0.00696"
"375.64800","31.30407","0.00680"
"375.90600","31.32565","0.00732"
"376.16400","31.34711","0.00709"
"376.42200","31.36864","0.00729"
"376.68000","31.39016","0.00707"
"376.93800","31.41169","0.00757"
"377.19600","31.43309","0.00722"
"377.45400","31.45468","0.00728"
"377.71200","31.47614","0.00748"
"377.97000","31.49767","0.00758"
"378.22800","31.51907","0.00723"
"378.48600","31.54059","0.00777"
"378.74400","31.56212","0.00799"
"379.00200","31.58364","0.00804"
"379.26000","31.60522","0.00761"
"379.51800","31.62663","0.00835"
"379.77600","31.64816","0.00800"
"380.03400","31.66962","0.00773"
"380.29200","31.69120","0.00803"
"380.55000","31.71267","0.00803"
"380.80800","31.73413","0.00840"
"381.06600","31.75554","0.00870"
"381.32400","31.77718","0.00828"
"381.58200","31.79864","0.00838"
"381.84000","31.82023","0.00851"
"382.09800","31.84157","0.00842"
"382.35600","31.86310","0.00865"
"382.61400","31.88456","0.00867"
"382.87200","31.90615","0.00882"
"382.91800","31.90997","0.00860"