File: Force_trajectories/161218/Specimen_RawData_3.csv
End date,"12/18/2016"
Specimen label,"16AT_26"
Maximum Load,"0.01147",N

Time,Extension,Load
(s),(mm),(N)
"0.00000","0.82868","0.01088"
"0.00600","0.82868","0.01084"
"0.01200","0.82868","0.01075"
"0.01800","0.82880","0.01067"
"0.02400","0.82892","0.01061"
"0.03000","0.82898","0.01060"
"0.03600","0.82916","0.01051"
"0.04200","0.82928","0.01044"
"0.04800","0.82952","0.01047"
"0.05400","0.82976","0.01044"
"0.06000","0.83000","0.01042"
"0.06600","0.83030","0.01043"
"0.07200","0.83060","0.01046"
"0.07800","0.83095","0.01043"
"0.08400","0.83131","0.01044"
"0.09000","0.83173","0.01050"
"0.09600","0.83215","0.01061"
"0.10200","0.83263","0.01067"
"0.10800","0.83311","0.01066"
"0.11400","0.83365","0.01068"
"0.12000","0.83412","0.01073"
"0.12600","0.83472","0.01076"
"0.13200","0.83526","0.01085"
"0.13800","0.83592","0.01079"
"0.14400","0.83652","0.01069"
"0.15000","0.83711","0.01066"
"0.15600","0.83777","0.01062"
"0.16200","0.83843","0.01065"
"0.16800","0.83909","0.01059"
"0.17400","0.83980","0.01045"
"0.18000","0.84046","0.01037"
"0.18600","0.84112","0.01033"
"0.19200","0.84178","0.01033"
"0.19800","0.84243","0.01042"
"0.20400","0.84309","0.01045"
"0.21000","0.84375","0.01046"
"0.21600","0.84441","0.01046"
"0.22200","0.84507","0.01041"
"0.22800","0.84572","0.01039"
"0.23400","0.84638","0.01036"
"0.24000","0.84698","0.01032"
"0.24600","0.84764","0.01037"
"0.25200","0.84829","0.01045"
"0.25800","0.84889","0.01047"
"0.26400","0.84949","0.01044"
"0.27000","0.85015","0.01036"
"0.27600","0.85075","0.01041"
"0.28200","0.85134","0.01049"
"0.28800","0.85200","0.01050"
"0.29400","0.85254","0.01045"
"0.30000","0.85320","0.01042"
"0.30600","0.85373","0.01040"
"0.31200","0.85433","0.01045"
"0.31800","0.85487","0.01045"
"0.32400","0.85547","0.01039"
"0.33000","0.85601","0.01039"
"0.33600","0.85654","0.01036"
"0.34200","0.85708","0.01035"
"0.34800","0.85762","0.01045"
"0.35400","0.85822","0.01057"
"0.36000","0.85876","0.01067"
"0.36600","0.85930","0.01086"
"0.37200","0.85983","0.01099"
"0.37800","0.86037","0.01116"
"0.38400","0.86091","0.01126"
"0.39000","0.86139","0.01122"
"0.39600","0.86193","0.01130"
"0.40200","0.86246","0.01141"
"0.40800","0.86300","0.01145"
"0.41400","0.86354","0.01145"
"0.42000","0.86402","0.01139"
"0.42600","0.86456","0.01133"
"0.43200","0.86503","0.01134"
"0.43800","0.86551","0.01122"
"0.44400","0.86605","0.01114"
"0.45000","0.86653","0.01110"
"0.45600","0.86701","0.01093"
"0.46200","0.86755","0.01077"
"0.46800","0.86802","0.01067"
"0.47400","0.86850","0.01057"
"0.48000","0.86904","0.01054"
"0.48600","0.86952","0.01059"
"0.49200","0.87000","0.01069"
"0.49800","0.87048","0.01078"
"0.50400","0.87101","0.01075"
"0.51000","0.87149","0.01069"
"0.51600","0.87197","0.01072"
"0.52200","0.87251","0.01068"
"0.52800","0.87299","0.01064"
"0.53400","0.87353","0.01069"
"0.54000","0.87400","0.01075"
"0.54600","0.87448","0.01087"
"0.55200","0.87502","0.01096"
"0.55800","0.87550","0.01096"
"0.56400","0.87598","0.01097"
"0.57000","0.87651","0.01091"
"0.57600","0.87699","0.01088"
"0.58200","0.87747","0.01089"
"0.58800","0.87795","0.01084"
"0.59400","0.87843","0.01082"
"0.60000","0.87897","0.01092"
"0.60600","0.87944","0.01096"
"0.61200","0.87998","0.01097"
"0.61800","0.88046","0.01094"
"0.62400","0.88094","0.01087"
"0.63000","0.88142","0.01089"
"0.63600","0.88196","0.01092"
"0.64200","0.88243","0.01091"
"0.64800","0.88291","0.01094"
"0.65400","0.88345","0.01089"
"0.66000","0.88393","0.01099"
"0.66600","0.88441","0.01111"
"0.67200","0.88489","0.01112"
"0.67800","0.88542","0.01110"
"0.68400","0.88590","0.01108"
"0.69000","0.88644","0.01097"
"0.69600","0.88692","0.01096"
"0.70200","0.88740","0.01091"
"0.70800","0.88793","0.01088"
"0.71400","0.88841","0.01096"
"0.72000","0.88889","0.01102"
"0.72600","0.88937","0.01110"
"0.73200","0.88991","0.01124"
"0.73800","0.89039","0.01122"
"0.74400","0.89086","0.01116"
"0.75000","0.89134","0.01115"
"0.75600","0.89188","0.01112"
"0.76200","0.89236","0.01118"
"0.76800","0.89284","0.01122"
"0.77400","0.89338","0.01121"
"0.78000","0.89385","0.01120"
"0.78600","0.89439","0.01110"
"0.79200","0.89487","0.01097"
"0.79800","0.89535","0.01094"
"0.80400","0.89583","0.01091"
"0.81000","0.89636","0.01087"
"0.81600","0.89684","0.01084"
"0.82200","0.89732","0.01078"
"0.82800","0.89786","0.01075"
"0.83400","0.89834","0.01070"
"0.84000","0.89888","0.01066"
"0.84600","0.89941","0.01067"
"0.85200","0.89989","0.01075"
"0.85800","0.90043","0.01079"
"0.86400","0.90091","0.01084"
"0.87000","0.90145","0.01088"
"0.87600","0.90193","0.01090"
"0.88200","0.90240","0.01102"
"0.88800","0.90294","0.01102"
"0.89400","0.90342","0.01102"
"0.90000","0.90390","0.01115"
"0.90600","0.90444","0.01119"
"0.91200","0.90491","0.01122"
"0.91800","0.90539","0.01123"
"0.92400","0.90593","0.01118"
"0.93000","0.90641","0.01115"
"0.93600","0.90689","0.01108"
"0.94200","0.90743","0.01098"
"0.94800","0.90790","0.01100"
"0.95400","0.90844","0.01092"
"0.96000","0.90892","0.01085"
"0.96600","0.90940","0.01081"
"0.97200","0.90994","0.01069"
"0.97800","0.91042","0.01060"
"0.98400","0.91095","0.01063"
"0.99000","0.91149","0.01062"
"0.99600","0.91197","0.01063"
"1.00200","0.91251","0.01079"
"1.00800","0.91299","0.01088"
"1.01400","0.91346","0.01092"
"1.02000","0.91400","0.01088"
"1.02600","0.91448","0.01088"
"1.03200","0.91496","0.01101"
"1.03800","0.91544","0.01102"
"1.04400","0.91592","0.01094"
"1.05000","0.91645","0.01090"
"1.05600","0.91693","0.01085"
"1.06200","0.91741","0.01090"
"1.06800","0.91795","0.01098"
"1.07400","0.91843","0.01102"
"1.08000","0.91891","0.01109"
"1.08600","0.91944","0.01105"
"1.09200","0.91992","0.01105"
"1.09800","0.92046","0.01112"
"1.10400","0.92094","0.01105"
"1.11000","0.92142","0.01100"
"1.11600","0.92195","0.01102"
"1.12200","0.92243","0.01102"
"1.12800","0.92297","0.01100"
"1.13400","0.92345","0.01114"
"1.14000","0.92399","0.01124"
"1.14600","0.92447","0.01127"
"1.15200","0.92500","0.01113"
"1.15800","0.92548","0.01107"
"1.16400","0.92602","0.01112"
"1.17000","0.92650","0.01114"
"1.17600","0.92698","0.01113"
"1.18200","0.92746","0.01108"
"1.18800","0.92793","0.01101"
"1.19400","0.92847","0.01091"
"1.20000","0.92895","0.01077"
"1.20600","0.92943","0.01060"
"1.21200","0.92991","0.01050"
"1.21800","0.93044","0.01048"
"1.22400","0.93092","0.01051"
"1.23000","0.93140","0.01065"
"1.23600","0.93194","0.01075"
"1.24200","0.93242","0.01087"
"1.24800","0.93290","0.01103"
"1.25400","0.93343","0.01104"
"1.26000","0.93391","0.01100"
"1.26600","0.93439","0.01100"
"1.27200","0.93493","0.01103"
"1.27800","0.93541","0.01106"
"1.28400","0.93595","0.01108"
"1.29000","0.93642","0.01118"
"1.29600","0.93696","0.01132"
"1.30200","0.93744","0.01139"
"1.30800","0.93792","0.01137"
"1.31400","0.93840","0.01140"
"1.32000","0.93888","0.01143"
"1.32600","0.93941","0.01136"
"1.33200","0.93989","0.01131"
"1.33800","0.94037","0.01124"
"1.34400","0.94085","0.01121"
"1.35000","0.94139","0.01124"
"1.35600","0.94186","0.01129"
"1.36200","0.94234","0.01133"
"1.36800","0.94282","0.01136"
"1.37400","0.94336","0.01135"
"1.38000","0.94384","0.01141"
"1.38600","0.94438","0.01145"
"1.39200","0.94485","0.01147"
"1.39800","0.94539","0.01141"
"1.40400","0.94587","0.01128"
"1.41000","0.94641","0.01113"
"1.41600","0.94689","0.01109"
"1.42200","0.94743","0.01117"
"1.42800","0.94796","0.01118"
"1.43400","0.94844","0.01116"
"1.44000","0.94898","0.01103"
"1.44600","0.94946","0.01094"
"1.45200","0.95000","0.01086"
"1.45800","0.95047","0.01078"
"1.46400","0.95095","0.01085"
"1.47000","0.95149","0.01093"
"1.47600","0.95197","0.01097"
"1.48200","0.95245","0.01105"
"1.48800","0.95293","0.01101"
"1.49400","0.95346","0.01102"
"1.50000","0.95394","0.01108"
"1.50600","0.95448","0.01113"
"1.51200","0.95496","0.01119"
"1.51800","0.95544","0.01125"
"1.52400","0.95592","0.01132"
"1.53000","0.95645","0.01136"
"1.53600","0.95693","0.01135"
"1.54200","0.95741","0.01133"
"1.54800","0.95795","0.01131"
"1.55400","0.95843","0.01125"
"1.56000","0.95896","0.01119"
"1.56600","0.95950","0.01121"
"1.57200","0.95998","0.01118"
"1.57800","0.96046","0.01117"
"1.58400","0.96100","0.01123"
"1.59000","0.96148","0.01129"
"1.59600","0.96195","0.01133"
"1.60200","0.96243","0.01126"
"1.60800","0.96297","0.01121"
"1.61400","0.96345","0.01125"
"1.62000","0.96393","0.01133"
"1.62600","0.96441","0.01139"
"1.63200","0.96494","0.01145"
"1.63800","0.96542","0.01142"
"1.64400","0.96596","0.01130"
"1.65000","0.96644","0.01126"
"1.65600","0.96692","0.01108"
"1.66200","0.96745","0.01089"
"1.66800","0.96793","0.01076"
"1.67400","0.96841","0.01066"
"1.68000","0.96895","0.01059"
"1.68600","0.96943","0.01055"
"1.69200","0.96997","0.01053"
"1.69800","0.97044","0.01063"
"1.70400","0.97098","0.01069"
"1.71000","0.97146","0.01080"
"1.71600","0.97200","0.01094"
"1.72200","0.97248","0.01103"
"1.72800","0.97296","0.01106"
"1.73400","0.97349","0.01111"
"1.74000","0.97397","0.01111"
"1.74600","0.97445","0.01111"
"1.75200","0.97493","0.01101"
"1.75800","0.97547","0.01091"
"1.76400","0.97594","0.01094"
"1.77000","0.97642","0.01092"
"1.77600","0.97690","0.01082"
"1.78200","0.97744","0.01078"
"1.78800","0.97792","0.01075"
"1.79400","0.97840","0.01072"
"1.80000","0.97893","0.01073"
"1.80600","0.97941","0.01073"
"1.81200","0.97989","0.01071"
"1.81800","0.98043","0.01064"
"1.82400","0.98091","0.01056"
"1.83000","0.98139","0.01060"
"1.83600","0.98192","0.01063"
"1.84200","0.98240","0.01063"
"1.84800","0.98288","0.01068"
"1.85400","0.98342","0.01071"
"1.86000","0.98390","0.01064"
"1.86600","0.98437","0.01061"
"1.87200","0.98491","0.01069"
"1.87800","0.98539","0.01074"
"1.88400","0.98587","0.01070"
"1.89000","0.98635","0.01058"
"1.89600","0.98683","0.01062"
"1.90200","0.98736","0.01065"
"1.90800","0.98784","0.01065"
"1.91400","0.98832","0.01073"
"1.92000","0.98886","0.01080"
"1.92600","0.98934","0.01077"
"1.93200","0.98982","0.01080"
"1.93800","0.99035","0.01083"
"1.94400","0.99083","0.01077"
"1.95000","0.99137","0.01071"
"1.95600","0.99185","0.01064"
"1.96200","0.99239","0.01066"
"1.96800","0.99292","0.01062"
"1.97400","0.99340","0.01058"
"1.98000","0.99394","0.01061"
"1.98600","0.99442","0.01065"
"1.99200","0.99496","0.01064"
"1.99800","0.99544","0.01063"
"2.00400","0.99597","0.01068"
"2.01000","0.99645","0.01080"
"2.01600","0.99699","0.01094"
"2.02200","0.99747","0.01095"
"2.02800","0.99795","0.01091"
"2.03400","0.99849","0.01087"
"2.04000","0.99896","0.01082"
"2.04600","0.99950","0.01080"
"2.05200","0.99998","0.01071"
"2.05800","1.00046","0.01063"
"2.06400","1.00100","0.01070"
"2.07000","1.00147","0.01078"
"2.07600","1.00195","0.01074"
"2.08200","1.00249","0.01074"
"2.08800","1.00297","0.01077"
"2.09400","1.00345","0.01084"
"2.10000","1.00393","0.01098"
"2.10600","1.00446","0.01102"
"2.11200","1.00494","0.01104"
"2.11800","1.00542","0.01105"
"2.12400","1.00596","0.01099"
"2.13000","1.00644","0.01089"
"2.13600","1.00698","0.01075"
"2.14200","1.00745","0.01060"
"2.14800","1.00799","0.01051"
"2.15400","1.00847","0.01039"
"2.16000","1.00895","0.01034"
"2.16600","1.00949","0.01040"
"2.17200","1.00996","0.01046"
"2.17800","1.01044","0.01051"
"2.18400","1.01092","0.01060"
"2.19000","1.01146","0.01067"
"2.19600","1.01194","0.01072"
"2.20200","1.01242","0.01078"
"2.20800","1.01295","0.01076"
"2.21400","1.01343","0.01077"
"2.22000","1.01391","0.01073"
"2.22600","1.01445","0.01068"
"2.23200","1.01493","0.01066"
"2.23800","1.01541","0.01061"
"2.24400","1.01588","0.01059"
"2.25000","1.01642","0.01061"
"2.25600","1.01690","0.01059"
"2.26200","1.01738","0.01063"
"2.26800","1.01792","0.01069"
"2.27400","1.01840","0.01070"
"2.28000","1.01893","0.01073"
"2.28600","1.01947","0.01072"
"2.29200","1.01995","0.01071"
"2.29800","1.02043","0.01078"
"2.30400","1.02097","0.01083"
"2.31000","1.02144","0.01079"
"2.31600","1.02192","0.01084"
"2.32200","1.02246","0.01091"
"2.32800","1.02294","0.01091"
"2.33400","1.02342","0.01093"
"2.34000","1.02390","0.01088"
"2.34600","1.02443","0.01088"
"2.35200","1.02491","0.01082"
"2.35800","1.02539","0.01072"
"2.36400","1.02587","0.01073"
"2.37000","1.02641","0.01075"
"2.37600","1.02689","0.01076"
"2.38200","1.02736","0.01079"
"2.38800","1.02790","0.01080"
"2.39400","1.02838","0.01077"
"2.40000","1.02886","0.01075"
"2.40600","1.02940","0.01072"
"2.41200","1.02987","0.01079"
"2.41800","1.03041","0.01087"
"2.42400","1.03089","0.01083"
"2.43000","1.03143","0.01087"
"2.43600","1.03191","0.01092"
"2.44200","1.03239","0.01094"
"2.44800","1.03292","0.01099"
"2.45400","1.03340","0.01102"
"2.46000","1.03394","0.01096"
"2.46600","1.03442","0.01092"
"2.47200","1.03490","0.01089"
"2.47800","1.03544","0.01081"
"2.48400","1.03591","0.01077"
"2.49000","1.03639","0.01070"
"2.49600","1.03687","0.01069"
"2.50200","1.03735","0.01070"
"2.50800","1.03789","0.01069"
"2.51400","1.03836","0.01077"
"2.52000","1.03884","0.01091"
"2.52600","1.03938","0.01096"
"2.53200","1.03986","0.01099"
"2.53800","1.04034","0.01099"
"2.54400","1.04088","0.01090"
"2.55000","1.04135","0.01080"
"2.55600","1.04189","0.01070"
"2.56200","1.04237","0.01062"
"2.56800","1.04291","0.01062"
"2.57400","1.04345","0.01059"
"2.58000","1.04393","0.01064"
"2.58600","1.04446","0.01062"
"2.59200","1.04494","0.01053"
"2.59800","1.04548","0.01053"
"2.60400","1.04596","0.01063"
"2.61000","1.04650","0.01078"
"2.61600","1.04697","0.01090"
"2.62200","1.04745","0.01092"
"2.62800","1.04793","0.01089"
"2.63400","1.04847","0.01087"
"2.64000","1.04895","0.01082"
"2.64600","1.04943","0.01081"
"2.65200","1.04990","0.01087"
"2.65800","1.05044","0.01090"
"2.66400","1.05092","0.01097"
"2.67000","1.05140","0.01100"
"2.67600","1.05194","0.01100"
"2.68200","1.05242","0.01099"
"2.68800","1.05295","0.01096"
"2.69400","1.05343","0.01098"
"2.70000","1.05397","0.01105"
"2.70600","1.05445","0.01104"
"2.71200","1.05499","0.01098"
"2.71800","1.05546","0.01094"
"2.72400","1.05600","0.01088"
"2.73000","1.05648","0.01089"
"2.73600","1.05696","0.01076"
"2.74200","1.05750","0.01061"
"2.74800","1.05798","0.01061"
"2.75400","1.05845","0.01057"
"2.76000","1.05899","0.01057"
"2.76600","1.05947","0.01070"
"2.77200","1.05995","0.01088"
"2.77800","1.06043","0.01097"
"2.78400","1.06091","0.01096"
"2.79000","1.06144","0.01091"
"2.79600","1.06192","0.01094"
"2.80200","1.06240","0.01097"
"2.80800","1.06288","0.01095"
"2.81400","1.06342","0.01107"
"2.82000","1.06389","0.01109"
"2.82600","1.06437","0.01103"
"2.83200","1.06485","0.01104"
"2.83800","1.06539","0.01096"
"2.84400","1.06587","0.01088"
"2.85000","1.06641","0.01086"
"2.85600","1.06688","0.01082"
"2.86200","1.06736","0.01080"
"2.86800","1.06790","0.01079"
"2.87400","1.06838","0.01074"
"2.88000","1.06886","0.01073"
"2.88600","1.06934","0.01073"
"2.89200","1.06987","0.01072"
"2.89800","1.07035","0.01079"
"2.90400","1.07083","0.01080"
"2.91000","1.07131","0.01074"
"2.91600","1.07185","0.01067"
"2.92200","1.07233","0.01065"
"2.92800","1.07280","0.01076"
"2.93400","1.07334","0.01086"
"2.94000","1.07382","0.01086"
"2.94600","1.07436","0.01090"
"2.95200","1.07484","0.01094"
"2.95800","1.07537","0.01095"
"2.96400","1.07585","0.01103"
"2.97000","1.07633","0.01111"
"2.97600","1.07687","0.01108"
"2.98200","1.07735","0.01108"
"2.98800","1.07783","0.01108"
"2.99400","1.07836","0.01115"
"3.00000","1.07884","0.01132"
"3.00600","1.07938","0.01137"
"3.01200","1.07992","0.01134"
"3.01800","1.08040","0.01129"
"3.02400","1.08094","0.01117"
"3.03000","1.08141","0.01111"
"3.03600","1.08189","0.01103"
"3.04200","1.08243","0.01102"
"3.04800","1.08291","0.01112"
"3.05400","1.08339","0.01119"
"3.06000","1.08386","0.01114"
"3.06600","1.08434","0.01111"
"3.07200","1.08488","0.01107"
"3.07800","1.08536","0.01098"
"3.08400","1.08590","0.01084"
"3.09000","1.08638","0.01074"
"3.09600","1.08691","0.01084"
"3.10200","1.08739","0.01096"
"3.10800","1.08793","0.01104"
"3.11400","1.08841","0.01118"
"3.12000","1.08889","0.01129"
"3.12600","1.08943","0.01134"
"3.13200","1.08990","0.01144"
"3.13800","1.09038","0.01145"
"3.14400","1.09092","0.01140"
"3.15000","1.09140","0.01133"
"3.15600","1.09194","0.01120"
"3.16200","1.09241","0.01109"
"3.16800","1.09289","0.01104"
"3.17400","1.09343","0.01096"
"3.18000","1.09391","0.01091"
"3.18600","1.09445","0.01086"
"3.19200","1.09493","0.01087"
"3.19800","1.09540","0.01100"
"3.20400","1.09594","0.01109"
"3.21000","1.09642","0.01108"
"3.21600","1.09696","0.01116"
"3.22200","1.09744","0.01119"
"3.22800","1.09792","0.01122"
"3.23400","1.09845","0.01129"
"3.24000","1.09893","0.01129"
"3.24600","1.09947","0.01121"
"3.25200","1.09995","0.01103"
"3.25800","1.10049","0.01085"
"3.26400","1.10096","0.01077"
"3.27000","1.10144","0.01072"
"3.27600","1.10198","0.01065"
"3.28200","1.10246","0.01067"
"3.28800","1.10294","0.01069"
"3.29400","1.10348","0.01076"
"3.30000","1.10395","0.01090"
"3.30600","1.10443","0.01102"
"3.31200","1.10497","0.01107"
"3.31800","1.10545","0.01112"
"3.32400","1.10593","0.01122"
"3.33000","1.10647","0.01135"
"3.33600","1.10694","0.01142"
"3.34200","1.10742","0.01133"
"3.34800","1.10796","0.01131"
"3.35400","1.10844","0.01123"
"3.36000","1.10892","0.01111"
"3.36400","1.10928","0.01107"