File: Force_trajectories/161218/Specimen_RawData_9.csv
End date,"12/18/2016"
Specimen label,"16CT_29_run2"
Maximum Load,"0.16028",N

Time,Extension,Load
(s),(mm),(N)
"0.00000","10.26192","0.01566"
"0.16800","10.27130","0.01642"
"0.33600","10.28960","0.01871"
"0.50400","10.30413","0.01992"
"0.67200","10.31806","0.02085"
"0.84000","10.33211","0.02149"
"1.00800","10.34610","0.02262"
"1.17600","10.36009","0.02356"
"1.34400","10.37408","0.02422"
"1.51200","10.38801","0.02520"
"1.68000","10.40200","0.02565"
"1.84800","10.41611","0.02694"
"2.01600","10.43005","0.02716"
"2.18400","10.44404","0.02842"
"2.35200","10.45803","0.02865"
"2.52000","10.47208","0.02865"
"2.68800","10.48601","0.02968"
"2.85600","10.50006","0.03103"
"3.02400","10.51405","0.03150"
"3.19200","10.52804","0.03250"
"3.36000","10.54203","0.03305"
"3.52800","10.55608","0.03383"
"3.69600","10.57001","0.03468"
"3.86400","10.58400","0.03601"
"4.03200","10.59805","0.03610"
"4.20000","10.61204","0.03678"
"4.36800","10.62603","0.03830"
"4.53600","10.64009","0.03890"
"4.70400","10.65402","0.03985"
"4.87200","10.66801","0.03993"
"5.04000","10.68206","0.04130"
"5.20800","10.69605","0.04203"
"5.37600","10.70998","0.04251"
"5.54400","10.72403","0.04345"
"5.71200","10.73808","0.04425"
"5.88000","10.75201","0.04465"
"6.04800","10.76600","0.04536"
"6.21600","10.77999","0.04564"
"6.38400","10.79398","0.04624"
"6.55200","10.80797","0.04709"
"6.72000","10.82208","0.04782"
"6.88800","10.83608","0.04833"
"7.05600","10.85001","0.04903"
"7.22400","10.86406","0.04944"
"7.39200","10.87805","0.04974"
"7.56000","10.89198","0.05073"
"7.72800","10.90603","0.05101"
"7.89600","10.92008","0.05211"
"8.06400","10.93395","0.05255"
"8.23200","10.94806","0.05317"
"8.40000","10.96199","0.05315"
"8.56800","10.97598","0.05332"
"8.73600","10.99003","0.05406"
"8.90400","11.00402","0.05343"
"9.07200","11.01807","0.05342"
"9.24000","11.03201","0.05393"
"9.40800","11.04606","0.05421"
"9.57600","11.06005","0.05449"
"9.74400","11.07404","0.05470"
"9.91200","11.08809","0.04952"
"10.08000","11.10202","0.04997"
"10.24800","11.11601","0.05026"
"10.41600","11.13006","0.04936"
"10.58400","11.14405","0.05092"
"10.75200","11.15804","0.05103"
"10.92000","11.17203","0.05099"
"11.08800","11.18602","0.05111"
"11.25600","11.19995","0.05132"
"11.42400","11.21407","0.05257"
"11.59200","11.22806","0.05278"
"11.76000","11.24205","0.05302"
"11.92800","11.25604","0.05426"
"12.09600","11.27003","0.05364"
"12.26400","11.28402","0.05458"
"12.43200","11.29795","0.05536"
"12.60000","11.31206","0.05565"
"12.76800","11.32605","0.05647"
"12.93600","11.33998","0.05695"
"13.10400","11.35403","0.05748"
"13.27200","11.36808","0.05740"
"13.44000","11.38195","0.05799"
"13.60800","11.39606","0.05909"
"13.77600","11.41012","0.06025"
"13.94400","11.42399","0.06076"
"14.11200","11.43804","0.06087"
"14.28000","11.45203","0.06228"
"14.44800","11.46602","0.06309"
"14.61600","11.48001","0.06378"
"14.78400","11.49406","0.06509"
"14.95200","11.50805","0.06575"
"15.12000","11.52204","0.06738"
"15.28800","11.53609","0.06770"
"15.45600","11.55008","0.06824"
"15.62400","11.56401","0.06930"
"15.79200","11.57800","0.07041"
"15.96000","11.59205","0.07124"
"16.12800","11.60598","0.07306"
"16.29600","11.62004","0.07300"
"16.46400","11.63409","0.07374"
"16.63200","11.64802","0.07417"
"16.80000","11.66201","0.07501"
"16.96800","11.67606","0.07637"
"17.13600","11.69005","0.07655"
"17.30400","11.70398","0.07692"
"17.47200","11.71803","0.07773"
"17.64000","11.73208","0.07763"
"17.80800","11.74601","0.07879"
"17.97600","11.76006","0.07918"
"18.14400","11.77399","0.07942"
"18.31200","11.78798","0.07996"
"18.48000","11.80210","0.08038"
"18.64800","11.81608","0.08068"
"18.81600","11.83002","0.08134"
"18.98400","11.84401","0.08199"
"19.15200","11.85806","0.08238"
"19.32000","11.87199","0.08309"
"19.48800","11.88604","0.08315"
"19.65600","11.90003","0.08410"
"19.82400","11.91402","0.08442"
"19.99200","11.92801","0.08516"
"20.16000","11.94200","0.08583"
"20.32800","11.95605","0.08605"
"20.49600","11.96998","0.08671"
"20.66400","11.98409","0.08722"
"20.83200","11.99802","0.08815"
"21.00000","12.01202","0.08785"
"21.16800","12.02607","0.08885"
"21.33600","12.04006","0.08966"
"21.50400","12.05405","0.08963"
"21.67200","12.06804","0.09038"
"21.84000","12.08209","0.09060"
"22.00800","12.09602","0.09085"
"22.17600","12.11001","0.07639"
"22.34400","12.12406","0.07766"
"22.51200","12.13805","0.07815"
"22.68000","12.15204","0.07915"
"22.84800","12.16609","0.07926"
"23.01600","12.18002","0.07996"
"23.18400","12.19396","0.08040"
"23.35200","12.20800","0.08097"
"23.52000","12.22206","0.08216"
"23.68800","12.23599","0.08298"
"23.85600","12.25004","0.08317"
"24.02400","12.26403","0.08444"
"24.19200","12.27802","0.08480"
"24.36000","12.29201","0.08538"
"24.52800","12.30606","0.08697"
"24.69600","12.32005","0.08761"
"24.86400","12.33404","0.08760"
"25.03200","12.34803","0.08851"
"25.20000","12.36202","0.08888"
"25.36800","12.37601","0.08989"
"25.53600","12.39007","0.09050"
"25.70400","12.40406","0.09180"
"25.87200","12.41793","0.09242"
"26.04000","12.43204","0.09297"
"26.20800","12.44603","0.09400"
"26.37600","12.46002","0.09419"
"26.54400","12.47407","0.09500"
"26.71200","12.48806","0.09602"
"26.88000","12.50205","0.09704"
"27.04800","12.51604","0.09786"
"27.21600","12.53003","0.09878"
"27.38400","12.54402","0.09963"
"27.55200","12.55807","0.09986"
"27.72000","12.57206","0.10109"
"27.88800","12.58606","0.10186"
"28.05600","12.59999","0.10266"
"28.22400","12.61404","0.10366"
"28.39200","12.62809","0.10485"
"28.56000","12.64196","0.10572"
"28.72800","12.65607","0.10614"
"28.89600","12.67006","0.10749"
"29.06400","12.68399","0.10811"
"29.23200","12.69810","0.10870"
"29.40000","12.71209","0.10911"
"29.56800","12.72602","0.10987"
"29.73600","12.74001","0.11084"
"29.90400","12.75400","0.11199"
"30.07200","12.76799","0.11379"
"30.24000","12.78199","0.11490"
"30.40800","12.79610","0.11605"
"30.57600","12.81009","0.11763"
"30.74400","12.82396","0.11798"
"30.91200","12.83807","0.11995"
"31.08000","12.85200","0.12080"
"31.24800","12.86599","0.12187"
"31.41600","12.88010","0.12353"
"31.58400","12.89409","0.12407"
"31.75200","12.90796","0.12433"
"31.92000","12.92201","0.12537"
"32.08800","12.93606","0.12620"
"32.25600","12.94999","0.12791"
"32.42400","12.96399","0.12876"
"32.59200","12.97804","0.12991"
"32.76000","12.99203","0.13081"
"32.92800","13.00602","0.13217"
"33.09600","13.02001","0.13247"
"33.26400","13.03406","0.13307"
"33.43200","13.04799","0.13379"
"33.60000","13.06204","0.13419"
"33.76800","13.07603","0.13492"
"33.93600","13.08990","0.13549"
"34.10400","13.10401","0.13608"
"34.27200","13.11806","0.13747"
"34.44000","13.13205","0.13833"
"34.60800","13.14604","0.13904"
"34.77600","13.16004","0.13930"
"34.94400","13.17403","0.14076"
"35.11200","13.18808","0.14149"
"35.28000","13.20207","0.14243"
"35.44800","13.21606","0.14322"
"35.61600","13.23005","0.14377"
"35.78400","13.24404","0.14430"
"35.95200","13.25797","0.14607"
"36.12000","13.27196","0.14627"
"36.28800","13.28607","0.14622"
"36.45600","13.30000","0.14741"
"36.62400","13.31405","0.14777"
"36.79200","13.32798","0.14820"
"36.96000","13.34203","0.14886"
"37.12800","13.35602","0.14961"
"37.29600","13.37008","0.15022"
"37.46400","13.38407","0.15109"
"37.63200","13.39800","0.15132"
"37.80000","13.41205","0.15223"
"37.96800","13.42604","0.15325"
"38.13600","13.44003","0.15373"
"38.30400","13.45408","0.15492"
"38.47200","13.46807","0.15560"
"38.64000","13.48206","0.15648"
"38.80800","13.49593","0.15759"
"38.97600","13.51004","0.15824"
"39.14400","13.52409","0.15907"
"39.31200","13.53802","0.15957"
"39.48000","13.55208","0.15928"
"39.64800","13.56607","0.00939"
"39.81600","13.58006","0.00087"
"39.98400","13.59405","0.00175"
"40.15200","13.60810","0.01045"
"40.32000","13.62203","0.00167"
"40.48800","13.63602","0.00380"
"40.65600","13.65007","0.00323"
"40.82400","13.66400","0.00574"
"40.99200","13.67799","0.00270"
"41.16000","13.69204","0.00650"
"41.32800","13.70603","0.00391"
"41.49600","13.72002","0.00631"
"41.66400","13.73401","0.00408"
"41.83200","13.74801","0.00371"
"42.00000","13.76200","0.00319"
"42.16800","13.77605","0.00468"
"42.33600","13.79010","0.00390"
"42.50400","13.80397","0.00471"
"42.67200","13.81802","0.00524"
"42.84000","13.83201","0.00732"
"43.00800","13.84600","0.00726"
"43.17600","13.86005","0.00717"
"43.34400","13.87404","0.00597"
"43.51200","13.88809","0.00763"
"43.68000","13.90202","0.00553"
"43.84800","13.91607","0.00637"
"44.01600","13.93001","0.00676"
"44.18400","13.94405","0.00708"
"44.35200","13.95811","0.00747"
"44.52000","13.97204","0.00894"
"44.68800","13.98597","0.00985"
"44.85600","14.00002","0.00927"
"45.02400","14.01407","0.01025"
"45.19200","14.02800","0.00942"
"45.36000","14.04205","0.00905"
"45.52800","14.05604","0.00949"
"45.69600","14.07003","0.00992"
"45.86400","14.08402","0.00987"
"46.03200","14.09807","0.01171"
"46.20000","14.11206","0.01344"
"46.36800","14.12599","0.01293"
"46.53600","14.13999","0.01442"
"46.70400","14.15404","0.01440"
"46.87200","14.16797","0.01294"
"47.04000","14.18208","0.01461"
"47.20800","14.19613","0.01426"
"47.37600","14.20994","0.01402"
"47.54400","14.22405","0.01499"
"47.71200","14.23810","0.01689"
"47.88000","14.25203","0.01681"
"48.04800","14.26608","0.01778"
"48.21600","14.28007","0.01890"
"48.38400","14.29400","0.01773"
"48.55200","14.30799","0.01831"
"48.72000","14.32199","0.01967"
"48.88800","14.33604","0.01795"
"49.05600","14.35003","0.01849"
"49.22400","14.36402","0.02078"
"49.39200","14.37801","0.02011"
"49.56000","14.39194","0.02179"
"49.72800","14.40605","0.02383"
"49.89600","14.42004","0.02285"
"50.06400","14.43403","0.02336"
"50.23200","14.44808","0.02423"
"50.40000","14.46207","0.02295"
"50.56800","14.47600","0.02382"
"50.73600","14.48999","0.02510"
"50.90400","14.50410","0.02478"
"51.07200","14.51803","0.02622"
"51.24000","14.53203","0.02768"
"51.40800","14.54608","0.02695"
"51.57600","14.56001","0.02817"
"51.74400","14.57394","0.02871"
"51.91200","14.58805","0.02773"
"52.08000","14.60204","0.02859"
"52.24800","14.61603","0.02945"
"52.41600","14.63002","0.02935"
"52.58400","14.64407","0.03042"
"52.75200","14.65800","0.03101"
"52.92000","14.67205","0.03153"
"53.08800","14.68604","0.03266"
"53.25600","14.70003","0.03266"
"53.42400","14.71403","0.03208"
"53.59200","14.72808","0.03311"
"53.76000","14.74201","0.03314"
"53.92800","14.75606","0.03357"
"54.09600","14.77005","0.03583"
"54.26400","14.78398","0.03511"
"54.43200","14.79803","0.03605"
"54.60000","14.81202","0.03805"
"54.76800","14.82601","0.03697"
"54.93600","14.84000","0.03759"
"55.10400","14.85411","0.03942"
"55.27200","14.86804","0.03815"
"55.44000","14.88197","0.03918"
"55.60800","14.89602","0.04030"
"55.77600","14.91008","0.04029"
"55.94400","14.92401","0.04136"
"56.11200","14.93806","0.04230"
"56.28000","14.95211","0.04184"
"56.44800","14.96598","0.04296"
"56.61600","14.97997","0.04296"
"56.78400","14.99408","0.04240"
"56.95200","15.00801","0.04364"
"57.12000","15.02200","0.04428"
"57.28800","15.03605","0.04437"
"57.45600","15.05004","0.04568"
"57.62400","15.06397","0.04574"
"57.79200","15.07802","0.04602"
"57.96000","15.09207","0.04714"
"58.12800","15.10601","0.04691"
"58.29600","15.12006","0.04684"
"58.46400","15.13405","0.04861"
"58.63200","15.14798","0.04803"
"58.80000","15.16203","0.04898"
"58.96800","15.17608","0.03969"
"59.13600","15.19001","0.03229"
"59.30400","15.20400","0.03329"
"59.47200","15.21799","0.03441"
"59.64000","15.23198","0.03425"
"59.80800","15.24597","0.03635"
"59.97600","15.26014","0.03593"
"60.14400","15.27401","0.03653"
"60.31200","15.28800","0.03779"
"60.48000","15.30205","0.03781"
"60.64800","15.31605","0.03983"
"60.81600","15.33004","0.03915"
"60.98400","15.34403","0.04005"
"61.15200","15.35808","0.04056"
"61.32000","15.37201","0.04102"
"61.48800","15.38600","0.04082"
"61.65600","15.40005","0.04224"
"61.82400","15.41404","0.04252"
"61.99200","15.42803","0.02612"
"62.16000","15.44202","0.00354"
"62.32800","15.45595","0.00469"
"62.49600","15.47000","0.00477"
"62.66400","15.48406","0.00536"
"62.83200","15.49811","0.00600"
"63.00000","15.51204","0.00605"
"63.16800","15.52609","0.00639"
"63.33600","15.54008","0.00714"
"63.50400","15.55401","0.00719"
"63.67200","15.56806","0.00702"
"63.84000","15.58205","0.00748"
"64.00800","15.59604","0.00778"
"64.17600","15.61003","0.00808"
"64.34400","15.62408","0.00869"
"64.51200","15.63801","0.00889"
"64.68000","15.65200","0.00901"
"64.84800","15.66605","0.01027"
"65.01600","15.68004","0.00958"
"65.18400","15.69398","0.01025"
"65.35200","15.70809","0.01092"
"65.52000","15.72202","0.01104"
"65.68800","15.73601","0.01069"
"65.85600","15.75006","0.01138"
"66.02400","15.76405","0.01198"
"66.19200","15.77798","0.01213"
"66.36000","15.79197","0.01286"
"66.52800","15.80608","0.01422"
"66.69600","15.82001","0.01322"
"66.86400","15.83406","0.01444"
"67.03200","15.84805","0.01459"
"67.20000","15.86204","0.01527"
"67.36800","15.87603","0.01576"
"67.53600","15.89002","0.01689"
"67.70400","15.90407","0.01707"
"67.87200","15.91807","0.01740"
"68.04000","15.93206","0.01831"
"68.20800","15.94611","0.01841"
"68.37600","15.95998","0.01931"
"68.54400","15.97403","0.01986"
"68.71200","15.98802","0.02003"
"68.88000","16.00201","0.02003"
"69.04800","16.01600","0.02198"
"69.21600","16.02999","0.02195"
"69.38400","16.04398","0.02245"
"69.55200","16.05803","0.02303"
"69.72000","16.07208","0.02302"
"69.88800","16.08601","0.02340"
"70.05600","16.10001","0.02398"
"70.22400","16.11406","0.02342"
"70.39200","16.12799","0.02441"
"70.56000","16.14198","0.02462"
"70.72800","16.15609","0.02467"
"70.89600","16.17002","0.02514"
"71.06400","16.18401","0.02535"
"71.23200","16.19806","0.02563"
"71.40000","16.21205","0.02626"
"71.56800","16.22598","0.02684"
"71.73600","16.24003","0.02699"
"71.90400","16.25402","0.02703"
"72.07200","16.26801","0.02814"
"72.24000","16.28206","0.02815"
"72.40800","16.29600","0.02905"
"72.57600","16.30999","0.02950"
"72.74400","16.32404","0.02935"
"72.91200","16.33803","0.03033"
"73.08000","16.35202","0.03059"
"73.24800","16.36595","0.03042"
"73.41600","16.38006","0.03118"
"73.58400","16.39405","0.01050"
"73.75200","16.40798","0.00902"
"73.92000","16.42203","0.00955"
"74.08800","16.43608","0.01066"
"74.25600","16.45001","0.01038"
"74.42400","16.46400","0.01086"
"74.59200","16.47811","0.01127"
"74.76000","16.49199","0.01156"
"74.92800","16.50604","0.01183"
"75.09600","16.52003","0.01243"
"75.26400","16.53402","0.01286"
"75.43200","16.54801","0.01280"
"75.60000","16.56206","0.01412"
"75.76800","16.57605","0.01469"
"75.93600","16.58998","0.01430"
"76.10400","16.60409","0.01532"
"76.27200","16.61808","0.01593"
"76.44000","16.63201","0.01508"
"76.60800","16.64606","0.01646"
"76.77600","16.66005","0.01666"
"76.94400","16.67399","0.01673"
"77.11200","16.68804","0.01794"
"77.28000","16.70203","0.01889"
"77.44800","16.71602","0.01839"
"77.61600","16.73001","0.01926"
"77.78400","16.74406","0.01954"
"77.95200","16.75805","0.02008"
"78.12000","16.77198","0.02055"
"78.28800","16.78597","0.02142"
"78.45600","16.80008","0.02148"
"78.62400","16.81407","0.02189"
"78.79200","16.82806","0.02236"
"78.96000","16.84205","0.02303"
"79.12800","16.85599","0.02372"
"79.29600","16.87004","0.02416"
"79.46400","16.88403","0.02403"
"79.63200","16.89802","0.02339"
"79.80000","16.91201","0.02409"
"79.96800","16.92606","0.02453"
"80.13600","16.94005","0.02439"
"80.30400","16.95404","0.02539"
"80.47200","16.96803","0.02562"
"80.64000","16.98208","0.02582"
"80.80800","16.99601","0.02668"
"80.97600","17.01000","0.02624"
"81.14400","17.02399","0.02739"
"81.31200","17.03792","0.02776"
"81.48000","17.05203","0.02801"
"81.64800","17.06603","0.02789"
"81.81600","17.07996","0.02905"
"81.98400","17.09407","0.02871"
"82.15200","17.10806","0.02972"
"82.32000","17.12199","0.03013"
"82.48800","17.13610","0.03058"
"82.65600","17.15009","0.03089"
"82.82400","17.16402","0.03173"
"82.99200","17.17795","0.03171"
"83.16000","17.19206","0.03245"
"83.32800","17.20605","0.03276"
"83.49600","17.22004","0.03377"
"83.66400","17.23403","0.03264"
"83.83200","17.24803","0.03412"
"84.00000","17.26202","0.03470"
"84.16800","17.27601","0.03492"
"84.33600","17.29006","0.03516"
"84.50400","17.30405","0.03623"
"84.67200","17.31804","0.03624"
"84.84000","17.33203","0.03731"
"85.00800","17.34602","0.03745"
"85.17600","17.36001","0.03700"
"85.34400","17.37406","0.03813"
"85.51200","17.38799","0.03888"
"85.68000","17.40198","0.03904"
"85.84800","17.41603","0.03976"
"86.01600","17.43003","0.04052"
"86.18400","17.44402","0.04101"
"86.35200","17.45807","0.04154"
"86.52000","17.47212","0.04223"
"86.68800","17.48605","0.04242"
"86.85600","17.50010","0.04335"
"87.02400","17.51403","0.04368"
"87.19200","17.52802","0.04419"
"87.36000","17.54207","0.04496"
"87.52800","17.55600","0.04509"
"87.69600","17.56999","0.04555"
"87.86400","17.58398","0.04624"
"88.03200","17.59803","0.04689"
"88.20000","17.61202","0.04783"
"88.36800","17.62607","0.04806"
"88.53600","17.64013","0.04813"
"88.70400","17.65406","0.04890"
"88.87200","17.66805","0.04995"
"89.04000","17.68204","0.05011"
"89.20800","17.69603","0.05156"
"89.37600","17.70996","0.05163"
"89.54400","17.72407","0.05224"
"89.71200","17.73806","0.05251"
"89.88000","17.75199","0.05325"
"90.04800","17.76604","0.05358"
"90.21600","17.78009","0.05438"
"90.38400","17.79402","0.05483"
"90.55200","17.80807","0.05529"
"90.72000","17.82207","0.05575"
"90.88800","17.83599","0.05632"
"91.05600","17.84999","0.05639"
"91.22400","17.86410","0.05695"
"91.39200","17.87809","0.05767"
"91.56000","17.89202","0.05801"
"91.72800","17.90607","0.05863"
"91.89600","17.92000","0.06024"
"92.06400","17.93393","0.06005"
"92.23200","17.94804","0.06111"
"92.40000","17.96209","0.06129"
"92.56800","17.97602","0.06191"
"92.73600","17.99007","0.06208"
"92.90400","18.00406","0.06311"
"93.07200","18.01799","0.06341"
"93.24000","18.03204","0.06447"
"93.40800","18.04610","0.06528"
"93.57600","18.06003","0.06587"
"93.74400","18.07402","0.06713"
"93.91200","18.08801","0.06733"
"94.08000","18.10200","0.06899"
"94.24800","18.11599","0.06963"
"94.41600","18.13010","0.07058"
"94.58400","18.14403","0.07211"
"94.75200","18.15802","0.07324"
"94.92000","18.17207","0.07360"
"95.08800","18.18600","0.07420"
"95.25600","18.20005","0.07473"
"95.42400","18.21404","0.07572"
"95.59200","18.22809","0.07571"
"95.76000","18.24203","0.07672"
"95.92800","18.25602","0.07688"
"96.09600","18.27001","0.07768"
"96.26400","18.28406","0.07777"
"96.43200","18.29799","0.07854"
"96.60000","18.31204","0.07922"
"96.76800","18.32603","0.07970"
"96.93600","18.34002","0.08012"
"97.10400","18.35407","0.08068"
"97.27200","18.36800","0.08109"
"97.44000","18.38199","0.08126"
"97.60800","18.39604","0.08196"
"97.77600","18.41003","0.08284"
"97.94400","18.42397","0.08293"
"98.11200","18.43807","0.08334"
"98.28000","18.45201","0.08392"
"98.44800","18.46600","0.08411"
"98.61600","18.48005","0.00726"
"98.78400","18.49404","0.00361"
"98.95200","18.50797","0.00296"
"99.12000","18.52202","0.00738"
"99.28800","18.53607","0.00495"
"99.45600","18.55000","0.00255"
"99.62400","18.56393","0.01014"
"99.79200","18.57804","0.01876"
"99.96000","18.59197","0.00531"
"100.12800","18.60602","0.00709"
"100.29600","18.62002","0.01316"
"100.46400","18.63407","0.01656"
"100.63200","18.64800","0.00559"
"100.80000","18.66205","0.00784"
"100.96800","18.67610","0.01661"
"101.13600","18.69003","0.01066"
"101.30400","18.70408","0.00849"
"101.47200","18.71807","0.01006"
"101.64000","18.73200","0.01813"
"101.80800","18.74599","0.01072"
"101.97600","18.76004","0.01024"
"102.14400","18.77403","0.01771"
"102.31200","18.78802","0.01578"
"102.48000","18.80202","0.01199"
"102.64800","18.81601","0.01320"
"102.81600","18.82994","0.01982"
"102.98400","18.84405","0.01436"
"103.15200","18.85810","0.01497"
"103.32000","18.87203","0.01981"
"103.48800","18.88602","0.01886"
"103.65600","18.90001","0.01639"
"103.82400","18.91400","0.01845"
"103.99200","18.92799","0.00853"
"104.16000","18.94204","0.00474"
"104.32800","18.95603","-0.00159"
"104.49600","18.97002","0.00029"
"104.66400","18.98407","0.00029"
"104.83200","18.99800","-0.00112"
"105.00000","19.01193","-0.00037"
"105.16800","19.02605","0.00089"
"105.33600","19.04004","-0.00048"
"105.50400","19.05403","-0.00092"
"105.67200","19.06802","0.00087"
"105.84000","19.08207","-0.00049"
"106.00800","19.09600","-0.00111"
"106.17600","19.11005","-0.00015"
"106.34400","19.12410","0.00027"
"106.51200","19.13803","-0.00059"
"106.68000","19.15202","-0.00021"
"106.84800","19.16601","-0.00004"
"107.01600","19.18000","0.00026"
"107.18400","19.19406","-0.00037"
"107.35200","19.20805","-0.00043"
"107.52000","19.22204","0.00047"
"107.68800","19.23597","0.00006"
"107.85600","19.25008","-0.00044"
"108.02400","19.26407","0.00035"
"108.19200","19.27800","0.00023"
"108.36000","19.29211","-0.00046"
"108.52800","19.30610","0.00045"
"108.69600","19.31997","0.00020"
"108.86400","19.33402","0.00025"
"109.03200","19.34807","0.00003"
"109.20000","19.36200","0.00034"
"109.36800","19.37600","0.00077"
"109.53600","19.39005","-0.00029"
"109.70400","19.40404","0.00007"
"109.87200","19.41803","0.00046"
"110.04000","19.43202","0.00059"
"110.20800","19.44601","0.00022"
"110.37600","19.46000","0.00021"
"110.54400","19.47405","0.00014"
"110.71200","19.48804","0.00008"
"110.88000","19.50197","0.00005"
"111.04800","19.51608","0.00093"
"111.21600","19.53007","0.00056"
"111.38400","19.54394","0.00038"
"111.55200","19.55805","0.00058"
"111.72000","19.57204","0.00013"
"111.88800","19.58603","0.00007"
"112.05600","19.60003","0.00064"
"112.22400","19.61402","0.00093"
"112.39200","19.62801","0.00068"
"112.56000","19.64199","0.00046"
"112.72800","19.65605","0.00084"
"112.89600","19.67004","0.00006"
"113.06400","19.68403","0.00004"
"113.23200","19.69808","0.00065"
"113.40000","19.71201","0.00070"
"113.56800","19.72600","0.00046"
"113.73600","19.74005","0.00012"
"113.90400","19.75404","0.00066"
"114.07200","19.76803","0.00016"
"114.24000","19.78203","0.00032"
"114.40800","19.79607","0.00042"
"114.57600","19.81001","0.00094"
"114.74400","19.82406","0.00105"
"114.91200","19.83805","0.00093"
"115.08000","19.85204","0.00042"
"115.24800","19.86603","0.00022"
"115.41600","19.88002","0.00057"
"115.58400","19.89401","0.00060"
"115.75200","19.90794","0.00097"
"115.92000","19.92211","0.00106"
"116.08800","19.93604","0.00078"
"116.25600","19.94997","0.00064"
"116.42400","19.96408","0.00016"
"116.59200","19.97801","0.00102"
"116.76000","19.99200","0.00110"
"116.92800","20.00606","0.00091"
"117.09600","20.02011","0.00079"
"117.26400","20.03403","0.00104"
"117.43200","20.04803","0.00089"
"117.60000","20.06208","0.00077"
"117.76800","20.07601","0.00085"
"117.93600","20.09000","0.00123"
"118.10400","20.10405","0.00092"
"118.27200","20.11804","0.00110"
"118.44000","20.13197","0.00054"
"118.60800","20.14602","0.00066"
"118.77600","20.16007","0.00075"
"118.94400","20.17400","0.00127"
"119.11200","20.18806","0.00114"
"119.28000","20.20210","0.00127"
"119.44800","20.21598","0.00099"
"119.61600","20.23003","0.00076"
"119.78400","20.24402","0.00084"
"119.95200","20.25801","0.00120"
"120.12000","20.27200","0.00149"
"120.28800","20.28605","0.00112"
"120.45600","20.30004","0.00144"
"120.62400","20.31397","0.00101"
"120.79200","20.32808","0.00083"
"120.96000","20.34207","0.00108"
"121.12800","20.35600","0.00145"
"121.29600","20.37000","0.00149"
"121.46400","20.38404","0.00145"
"121.63200","20.39798","0.00135"
"121.80000","20.41203","0.00081"
"121.96800","20.42602","0.00151"
"122.13600","20.44001","0.00159"
"122.30400","20.45406","0.00156"
"122.47200","20.46805","0.00205"
"122.64000","20.48198","0.00129"
"122.80800","20.49603","0.00105"
"122.97600","20.51002","0.00124"
"123.14400","20.52401","0.00147"
"123.31200","20.53800","0.00186"
"123.48000","20.55199","0.00169"
"123.64800","20.56604","0.00167"
"123.81600","20.57998","0.00109"
"123.98400","20.59409","0.00131"
"124.15200","20.60802","0.00183"
"124.32000","20.62201","0.00223"
"124.48800","20.63606","0.00217"
"124.65600","20.65005","0.00188"
"124.82400","20.66404","0.00143"
"124.99200","20.67803","0.00160"
"125.16000","20.69202","0.00214"
"125.32800","20.70601","0.00270"
"125.49600","20.72000","0.00254"
"125.66400","20.73405","0.00209"
"125.83200","20.74804","0.00192"
"126.00000","20.76198","0.00224"
"126.16800","20.77603","0.00291"
"126.33600","20.79002","0.00306"
"126.50400","20.80395","0.00231"
"126.67200","20.81806","0.00205"
"126.84000","20.83211","0.00179"
"127.00800","20.84598","0.00252"
"127.17600","20.86003","0.00372"
"127.34400","20.87408","0.00335"
"127.51200","20.88801","0.00282"
"127.68000","20.90200","0.00226"
"127.84800","20.91605","0.00259"
"128.01600","20.93004","0.00399"
"128.18400","20.94398","0.00383"
"128.35200","20.95796","0.00366"
"128.52000","20.97202","0.00313"
"128.68800","20.98601","0.00368"
"128.85600","21.00006","0.00466"
"129.02400","21.01405","0.00486"
"129.19200","21.02804","0.00446"
"129.36000","21.04209","0.00380"
"129.52800","21.05602","0.00475"
"129.69600","21.07001","0.00566"
"129.86400","21.08406","0.00573"
"130.03200","21.09805","0.00521"
"130.20000","21.11204","0.00509"
"130.36800","21.12603","0.00582"
"130.53600","21.14002","0.00672"
"130.70400","21.15402","0.00628"
"130.87200","21.16800","0.00625"
"131.04000","21.18206","0.00620"
"131.20800","21.19599","0.00674"
"131.37600","21.20998","0.00724"
"131.54400","21.22409","0.00771"
"131.71200","21.23808","0.00745"
"131.88000","21.25201","0.00706"
"132.04800","21.26612","0.00801"
"132.21600","21.28005","0.00785"
"132.38400","21.29398","0.00796"
"132.55200","21.30803","0.00866"
"132.72000","21.32203","0.00858"
"132.88800","21.33596","0.00840"
"133.05600","21.35000","0.00897"
"133.22400","21.36406","0.00845"
"133.39200","21.37805","0.00871"
"133.56000","21.39204","0.00907"
"133.72800","21.40609","0.00943"
"133.89600","21.42008","0.00980"
"134.06400","21.43395","0.00973"
"134.23200","21.44806","0.00992"
"134.40000","21.46205","0.00989"
"134.56800","21.47598","0.01009"
"134.73600","21.49003","0.01037"
"134.90400","21.50402","0.01022"
"135.07200","21.51795","0.01012"
"135.24000","21.53200","0.01110"
"135.40800","21.54606","0.01086"
"135.57600","21.56005","0.01069"
"135.74400","21.57404","0.01096"
"135.91200","21.58803","0.01153"
"136.08000","21.60202","0.01189"
"136.24800","21.61595","0.01200"
"136.41600","21.63000","0.01197"
"136.58400","21.64405","0.01237"
"136.75200","21.65798","0.01268"
"136.92000","21.67203","0.01323"
"137.08800","21.68608","0.01323"
"137.25600","21.69995","0.01401"
"137.42400","21.71406","0.01362"
"137.59200","21.72806","0.01400"
"137.76000","21.74204","0.01394"
"137.92800","21.75603","0.01445"
"138.09600","21.77003","0.01488"
"138.26400","21.78402","0.01527"
"138.43200","21.79801","0.01550"
"138.60000","21.81200","0.01612"
"138.76800","21.82599","0.01569"
"138.93600","21.83998","0.01647"
"139.10400","21.85403","0.01611"
"139.27200","21.86796","0.01658"
"139.44000","21.88201","0.01701"
"139.60800","21.89612","0.01752"
"139.77600","21.91006","0.01712"
"139.94400","21.92404","0.01767"
"140.11200","21.93803","0.01776"
"140.28000","21.95209","0.00396"
"140.44800","21.96596","0.00454"
"140.61600","21.98001","0.00545"
"140.78400","21.99406","0.00385"
"140.95200","22.00799","0.00338"
"141.12000","22.02204","0.00369"
"141.28800","22.03603","0.00201"
"141.45600","22.05002","0.00274"
"141.62400","22.06407","0.00275"
"141.79200","22.07806","0.00306"
"141.96000","22.09205","0.00324"
"142.12800","22.10598","0.00257"
"142.29600","22.12010","0.00304"
"142.46400","22.13408","0.00226"
"142.63200","22.14802","0.00282"
"142.80000","22.16207","0.00287"
"142.96800","22.17606","0.00306"
"143.13600","22.18999","0.00299"
"143.30400","22.20404","0.00291"
"143.47200","22.21809","0.00299"
"143.64000","22.23202","0.00290"
"143.80800","22.24601","0.00336"
"143.97600","22.26006","0.00279"
"144.14400","22.27399","0.00292"
"144.31200","22.28804","0.00324"
"144.48000","22.30203","0.00305"
"144.64800","22.31602","0.00296"
"144.81600","22.33002","0.00336"
"144.98400","22.34407","0.00325"
"145.15200","22.35806","0.00309"
"145.32000","22.37199","0.00342"
"145.48800","22.38604","0.00322"
"145.65600","22.40003","0.00324"
"145.82400","22.41396","0.00336"
"145.99200","22.42807","0.00361"
"146.16000","22.44206","0.00323"
"146.32800","22.45605","0.00350"
"146.49600","22.47004","0.00398"
"146.66400","22.48403","0.00343"
"146.83200","22.49802","0.00334"
"147.00000","22.51196","0.00335"
"147.16800","22.52600","0.00339"
"147.33600","22.54006","0.00375"
"147.50400","22.55404","0.00369"
"147.67200","22.56810","0.00354"
"147.84000","22.58197","0.00380"
"148.00800","22.59596","0.00340"
"148.17600","22.61001","0.00327"
"148.34400","22.62406","0.00376"
"148.51200","22.63799","0.00370"
"148.68000","22.65204","0.00409"
"148.84800","22.66609","0.00407"
"149.01600","22.67996","0.00353"
"149.18400","22.69401","0.00425"
"149.35200","22.70807","0.00422"
"149.52000","22.72206","0.00426"
"149.68800","22.73604","0.00381"
"149.85600","22.75010","0.00446"
"150.02400","22.76403","0.00403"
"150.19200","22.77796","0.00433"
"150.36000","22.79207","0.00399"
"150.52800","22.80606","0.00404"
"150.69600","22.82005","0.00411"
"150.86400","22.83404","0.00420"
"151.03200","22.84803","0.00441"
"151.20000","22.86196","0.00426"
"151.36800","22.87607","0.00438"
"151.53600","22.89006","0.00400"
"151.70400","22.90400","0.00450"
"151.87200","22.91799","0.00460"
"152.04000","22.93204","0.00493"
"152.20800","22.94603","0.00446"
"152.37600","22.96002","0.00494"
"152.54400","22.97407","0.00485"
"152.71200","22.98806","0.00430"
"152.88000","23.00193","0.00462"
"153.04800","23.01604","0.00501"
"153.21600","23.03003","0.00452"
"153.38400","23.04402","0.00498"
"153.55200","23.05801","0.00491"
"153.72000","23.07206","0.00532"
"153.88800","23.08599","0.00477"
"154.05600","23.10004","0.00502"
"154.22400","23.11404","0.00503"
"154.39200","23.12803","0.00524"
"154.56000","23.14202","0.00531"
"154.72800","23.15601","0.00520"
"154.89600","23.17000","0.00559"
"155.06400","23.18399","0.00514"
"155.23200","23.19810","0.00511"
"155.40000","23.21209","0.00519"
"155.56800","23.22602","0.00507"
"155.73600","23.24007","0.00538"
"155.90400","23.25400","0.00543"
"156.07200","23.26799","0.00553"
"156.24000","23.28204","0.00558"
"156.40800","23.29604","0.00553"
"156.57600","23.30997","0.00557"
"156.74400","23.32402","0.00588"
"156.91200","23.33801","0.00566"
"157.08000","23.35200","0.00593"
"157.24800","23.36599","0.00590"
"157.41600","23.38004","0.00580"
"157.58400","23.39403","0.00553"
"157.75200","23.40802","0.00585"
"157.92000","23.42207","0.00623"
"158.08800","23.43606","0.00614"
"158.25600","23.45000","0.00586"
"158.42400","23.46410","0.00617"
"158.59200","23.47803","0.00600"
"158.76000","23.49196","0.00658"
"158.92800","23.50602","0.00603"
"159.09600","23.52007","0.00652"
"159.26400","23.53406","0.00645"
"159.43200","23.54805","0.00637"
"159.60000","23.56204","0.00661"
"159.76800","23.57603","0.00666"
"159.93600","23.59002","0.00624"
"160.10400","23.60407","0.00639"
"160.27200","23.61806","0.00629"
"160.44000","23.63199","0.00636"
"160.60800","23.64604","0.00682"
"160.77600","23.66003","0.00615"
"160.94400","23.67396","0.00706"
"161.11200","23.68808","0.00660"
"161.28000","23.70207","0.00686"
"161.44800","23.71600","0.00628"
"161.61600","23.73005","0.00667"
"161.78400","23.74404","0.00665"
"161.95200","23.75803","0.00681"
"162.12000","23.77202","0.00729"
"162.28800","23.78613","0.00678"
"162.45600","23.80000","0.00728"
"162.62400","23.81399","0.00708"
"162.79200","23.82798","0.00727"
"162.96000","23.84203","0.00738"
"163.12800","23.85602","0.00731"
"163.29600","23.87008","0.00734"
"163.46400","23.88407","0.00782"
"163.63200","23.89800","0.00730"
"163.80000","23.91205","0.00748"
"163.96800","23.92604","0.00748"
"164.13600","23.94003","0.00786"
"164.30400","23.95402","0.00797"
"164.47200","23.96807","0.00787"
"164.64000","23.98200","0.00742"
"164.80800","23.99599","0.00785"
"164.97600","24.01004","0.00776"
"165.14400","24.02403","0.00802"
"165.31200","24.03802","0.00801"
"165.48000","24.05207","0.00794"
"165.64800","24.06601","0.00774"
"165.81600","24.08006","0.00820"
"165.98400","24.09405","0.00777"
"166.15200","24.10810","0.00831"
"166.32000","24.12203","0.00841"
"166.48800","24.13602","0.00855"
"166.65600","24.15001","0.00865"
"166.82400","24.16394","0.00820"
"166.99200","24.17805","0.00832"
"167.16000","24.19204","0.00869"
"167.32800","24.20603","0.00877"
"167.49600","24.22002","0.00856"
"167.66400","24.23401","0.00829"
"167.83200","24.24800","0.00788"
"168.00000","24.26205","0.00884"
"168.16800","24.27611","0.00908"
"168.33600","24.29009","0.00918"
"168.50400","24.30396","0.00908"
"168.67200","24.31808","0.00937"
"168.84000","24.33207","0.00937"
"169.00800","24.34600","0.00907"
"169.17600","24.36005","0.00945"
"169.34400","24.37404","0.00936"
"169.51200","24.38797","0.01000"
"169.68000","24.40202","0.00977"
"169.84800","24.41607","0.00944"
"170.01600","24.43000","0.00954"
"170.18400","24.44405","0.00968"
"170.35200","24.45804","0.01019"
"170.52000","24.47204","0.01029"
"170.68800","24.48602","0.00995"
"170.85600","24.50002","0.01029"
"171.02400","24.51407","0.01041"
"171.19200","24.52800","0.00991"
"171.36000","24.54205","0.00996"
"171.52800","24.55604","0.01035"
"171.69600","24.56997","0.00967"
"171.86400","24.58408","0.01084"
"172.03200","24.59807","0.01052"
"172.20000","24.61200","0.01046"
"172.36800","24.62605","0.01102"
"172.53600","24.64004","0.01054"
"172.70400","24.65404","0.01061"
"172.87200","24.66802","0.01096"
"173.04000","24.68208","0.01109"
"173.20800","24.69601","0.01092"
"173.37600","24.71000","0.01108"
"173.54400","24.72405","0.01161"
"173.71200","24.73798","0.01173"
"173.88000","24.75203","0.01146"
"174.04800","24.76608","0.01179"
"174.21600","24.78001","0.01174"
"174.38400","24.79400","0.01168"
"174.55200","24.80805","0.01193"
"174.72000","24.82204","0.01188"
"174.88800","24.83597","0.01201"
"175.05600","24.85009","0.01241"
"175.22400","24.86401","0.01183"
"175.39200","24.87801","0.01225"
"175.56000","24.89200","0.01223"
"175.72800","24.90605","0.01257"
"175.89600","24.92004","0.01260"
"176.06400","24.93409","0.01292"
"176.23200","24.94808","0.01299"
"176.40000","24.96201","0.01241"
"176.56800","24.97600","0.01346"
"176.73600","24.99005","0.01335"
"176.90400","25.00404","0.01401"
"177.07200","25.01797","0.01320"
"177.24000","25.03208","0.01360"
"177.40800","25.04607","0.01363"
"177.57600","25.06001","0.01352"
"177.74400","25.07400","0.01384"
"177.91200","25.08805","0.01339"
"178.08000","25.10198","0.01382"
"178.24800","25.11603","0.01340"
"178.41600","25.13008","0.01415"
"178.58400","25.14407","0.01393"
"178.75200","25.15800","0.01440"
"178.92000","25.17205","0.01430"
"179.08800","25.18604","0.01402"
"179.25600","25.19997","0.01469"
"179.42400","25.21402","0.01429"
"179.59200","25.22802","0.01498"
"179.76000","25.24201","0.01427"
"179.92800","25.25605","0.01482"
"180.09600","25.27011","0.01518"
"180.26400","25.28398","0.01490"
"180.43200","25.29803","0.01574"
"180.60000","25.31208","0.01548"
"180.76800","25.32601","0.01516"
"180.93600","25.34006","0.01540"
"181.10400","25.35405","0.01610"
"181.27200","25.36804","0.01645"
"181.44000","25.38197","0.01648"
"181.60800","25.39602","0.01640"
"181.77600","25.41002","0.01624"
"181.94400","25.42401","0.01649"
"182.11200","25.43805","0.01679"
"182.28000","25.45204","0.01683"
"182.44800","25.46604","0.01682"
"182.61600","25.48003","0.01704"
"182.78400","25.49408","0.01711"
"182.95200","25.50807","0.01726"
"183.12000","25.52200","0.01704"
"183.28800","25.53605","0.01757"
"183.45600","25.54998","0.01772"
"183.62400","25.56403","0.01799"
"183.79200","25.57808","0.01814"
"183.96000","25.59207","0.01786"
"184.12800","25.60600","0.01792"
"184.29600","25.62005","0.01835"
"184.46400","25.63405","0.01913"
"184.63200","25.64798","0.01935"
"184.80000","25.66209","0.01997"
"184.96800","25.67608","0.01971"
"185.13600","25.69001","0.01991"
"185.30400","25.70406","0.02011"
"185.47200","25.71805","0.02025"
"185.64000","25.73198","0.02051"
"185.80800","25.74603","0.02068"
"185.97600","25.76002","0.02074"
"186.14400","25.77401","0.02126"
"186.31200","25.78800","0.02144"
"186.48000","25.80205","0.02147"
"186.64800","25.81598","0.02129"
"186.81600","25.83004","0.02241"
"186.98400","25.84402","0.02179"
"187.15200","25.85802","0.02174"
"187.32000","25.87195","0.02203"
"187.48800","25.88606","0.02231"
"187.65600","25.90005","0.02234"
"187.82400","25.91404","0.02255"
"187.99200","25.92803","0.02276"
"188.16000","25.94208","0.02312"
"188.32800","25.95601","0.02305"
"188.49600","25.97000","0.02409"
"188.66400","25.98405","0.02391"
"188.83200","25.99804","0.02351"
"189.00000","26.01204","0.02406"
"189.16800","26.02602","0.02432"
"189.33600","26.04002","0.02478"
"189.50400","26.05401","0.02472"
"189.67200","26.06806","0.02517"
"189.84000","26.08199","0.02498"
"190.00800","26.09598","0.02499"
"190.17600","26.11009","0.02533"
"190.34400","26.12408","0.02544"
"190.51200","26.13801","0.02511"
"190.68000","26.15206","0.02600"
"190.84800","26.16605","0.02520"
"191.01600","26.18004","0.02519"
"191.18400","26.19397","0.02515"
"191.35200","26.20802","0.02572"
"191.52000","26.22202","0.02596"
"191.68800","26.23606","0.02512"
"191.85600","26.25006","0.02658"
"192.02400","26.26399","0.02637"
"192.19200","26.27798","0.02631"
"192.36000","26.29203","0.02657"
"192.52800","26.30608","0.02714"
"192.69600","26.32001","0.02712"
"192.86400","26.33412","0.02663"
"193.03200","26.34805","0.02724"
"193.20000","26.36198","0.02749"
"193.36800","26.37603","0.02684"
"193.53600","26.39009","0.02776"
"193.70400","26.40408","0.02745"
"193.87200","26.41801","0.02781"
"194.04000","26.43206","0.02820"
"194.20800","26.44599","0.02712"
"194.37600","26.45998","0.02810"
"194.54400","26.47409","0.02642"
"194.71200","26.48808","0.02604"
"194.88000","26.50201","0.02651"
"195.04800","26.51606","0.02350"
"195.21600","26.52999","0.02743"
"195.38400","26.54398","0.02486"
"195.55200","26.55803","0.02724"
"195.72000","26.57214","0.02624"
"195.88800","26.58595","0.02598"
"196.05600","26.60006","0.02755"
"196.22400","26.61406","0.02627"
"196.39200","26.62799","0.02808"
"196.56000","26.64204","0.02754"
"196.72800","26.65609","0.02776"
"196.89600","26.67002","0.02794"
"197.06400","26.68401","0.02798"
"197.23200","26.69806","0.02875"
"197.40000","26.71205","0.02098"
"197.56800","26.72598","0.02820"
"197.73600","26.74003","0.01871"
"197.90400","26.75408","0.01994"
"198.07200","26.76801","0.01658"
"198.24000","26.78206","0.02006"
"198.40800","26.79605","0.01275"
"198.57600","26.81005","0.01963"
"198.74400","26.82404","0.01454"
"198.91200","26.83809","0.01789"
"199.08000","26.85202","0.01858"
"199.24800","26.86601","0.01499"
"199.41600","26.88000","0.02013"
"199.58400","26.89399","0.01560"
"199.75200","26.90804","0.01814"
"199.92000","26.92203","0.01818"
"200.08800","26.93602","0.01578"
"200.25600","26.94995","0.01987"
"200.42400","26.96406","0.01675"
"200.59200","26.97812","0.01874"
"200.76000","26.99204","0.01871"
"200.92800","27.00610","0.01719"
"201.09600","27.02009","0.02056"
"201.26400","27.03402","0.01732"
"201.43200","27.04807","0.02054"
"201.60000","27.06206","0.01844"
"201.76800","27.07599","0.01892"
"201.93600","27.09004","0.01928"
"202.10400","27.10403","0.01760"
"202.27200","27.11802","0.01935"
"202.44000","27.13201","0.01862"
"202.60800","27.14606","0.01924"
"202.77600","27.16005","0.02022"
"202.94400","27.17398","0.01874"
"203.11200","27.18810","0.01991"
"203.28000","27.20202","0.01870"
"203.44800","27.21602","0.02067"
"203.61600","27.23013","0.02018"
"203.78400","27.24406","0.02051"
"203.95200","27.25793","0.02051"
"204.12000","27.27204","0.01985"
"204.28800","27.28609","0.02162"
"204.45600","27.30002","0.02113"
"204.62400","27.31401","0.02129"
"204.79200","27.32800","0.02129"
"204.96000","27.34199","0.02141"
"205.12800","27.35598","0.02168"
"205.29600","27.37003","0.02144"
"205.46400","27.38402","0.02186"
"205.63200","27.39802","0.02174"
"205.80000","27.41201","0.02253"
"205.96800","27.42606","0.02265"
"206.13600","27.43999","0.02180"
"206.30400","27.45410","0.02245"
"206.47200","27.46809","0.02278"
"206.64000","27.48202","0.02288"
"206.80800","27.49601","0.02296"
"206.97600","27.51006","0.02240"
"207.14400","27.52399","0.02295"
"207.31200","27.53804","0.02246"
"207.48000","27.55203","0.02303"
"207.64800","27.56602","0.02307"
"207.81600","27.58002","0.02314"
"207.98400","27.59401","0.02321"
"208.15200","27.60794","0.02330"
"208.32000","27.62199","0.02323"
"208.48800","27.63610","0.02342"
"208.65600","27.65003","0.02416"
"208.82400","27.66402","0.02356"
"208.99200","27.67801","0.02401"
"209.16000","27.69200","0.02369"
"209.32800","27.70599","0.02310"
"209.49600","27.72004","0.02393"
"209.66400","27.73409","0.02316"
"209.83200","27.74802","0.02377"
"210.00000","27.76207","0.02304"
"210.16800","27.77601","0.02345"
"210.33600","27.79000","0.02348"
"210.50400","27.80399","0.02396"
"210.67200","27.81804","0.02400"
"210.84000","27.83209","0.02369"
"211.00800","27.84602","0.02413"
"211.17600","27.86007","0.02423"
"211.34400","27.87412","0.02422"
"211.51200","27.88799","0.02453"
"211.68000","27.90210","0.02393"
"211.84800","27.91603","0.02491"
"212.01600","27.93003","0.02479"
"212.18400","27.94402","0.02483"
"212.35200","27.95806","0.02453"
"212.52000","27.97199","0.02426"
"212.68800","27.98598","0.02504"
"212.85600","28.00004","0.02442"
"213.02400","28.01403","0.02417"
"213.19200","28.02802","0.02538"
"213.36000","28.04207","0.02433"
"213.52800","28.05606","0.02539"
"213.69600","28.06999","0.02546"
"213.86400","28.08404","0.02508"
"214.03200","28.09803","0.02546"
"214.20000","28.11202","0.02500"
"214.36800","28.12607","0.02601"
"214.53600","28.14006","0.02581"
"214.70400","28.15399","0.02577"
"214.87200","28.16805","0.02634"
"215.04000","28.18210","0.02570"
"215.20800","28.19603","0.02619"
"215.37600","28.21008","0.02634"
"215.54400","28.22407","0.02650"
"215.71200","28.23800","0.02640"
"215.88000","28.25199","0.02650"
"216.04800","28.26604","0.02613"
"216.21600","28.28009","0.02619"
"216.38400","28.29408","0.02682"
"216.55200","28.30807","0.02683"
"216.72000","28.32200","0.02700"
"216.88800","28.33599","0.02704"
"217.05600","28.35005","0.02721"
"217.22400","28.36403","0.02660"
"217.39200","28.37803","0.02684"
"217.56000","28.39202","0.02635"
"217.72800","28.40601","0.02741"
"217.89600","28.41994","0.02689"
"218.06400","28.43405","0.02709"
"218.23200","28.44804","0.02797"
"218.40000","28.46203","0.02768"
"218.56800","28.47602","0.02796"
"218.73600","28.49007","0.02846"
"218.90400","28.50400","0.02869"
"219.07200","28.51799","0.02928"
"219.24000","28.53210","0.02891"
"219.40800","28.54609","0.02953"
"219.57600","28.55997","0.02939"
"219.74400","28.57408","0.02998"
"219.91200","28.58801","0.02935"
"220.08000","28.60200","0.02935"
"220.24800","28.61605","0.02997"
"220.41600","28.63010","0.02994"
"220.58400","28.64403","0.03017"
"220.75200","28.65796","0.03037"
"220.92000","28.67201","0.03063"
"221.08800","28.68600","0.03034"
"221.25600","28.70005","0.03131"
"221.42400","28.71404","0.03110"
"221.59200","28.72803","0.03115"
"221.76000","28.74196","0.03206"
"221.92800","28.75602","0.03141"
"222.09600","28.77007","0.03206"
"222.26400","28.78400","0.03176"
"222.43200","28.79805","0.03191"
"222.60000","28.81210","0.03196"
"222.76800","28.82603","0.03204"
"222.93600","28.84002","0.03250"
"223.10400","28.85407","0.03305"
"223.27200","28.86806","0.03264"
"223.44000","28.88199","0.03242"
"223.60800","28.89604","0.03293"
"223.77600","28.91003","0.03216"
"223.94400","28.92396","0.03214"
"224.11200","28.93807","0.03180"
"224.28000","28.95206","0.03229"
"224.44800","28.96606","0.03249"
"224.61600","28.98005","0.03242"
"224.78400","28.99404","0.03244"
"224.95200","29.00803","0.03272"
"225.12000","29.02208","0.03354"
"225.28800","29.03601","0.03243"
"225.45600","29.05000","0.03356"
"225.62400","29.06399","0.03330"
"225.79200","29.07804","0.03325"
"225.96000","29.09197","0.03381"
"226.12800","29.10602","0.03291"
"226.29600","29.12001","0.03370"
"226.46400","29.13400","0.03387"
"226.63200","29.14806","0.03419"
"226.80000","29.16205","0.03437"
"226.96800","29.17604","0.03474"
"227.13600","29.19003","0.03406"
"227.30400","29.20408","0.03484"
"227.47200","29.21801","0.03501"
"227.64000","29.23194","0.03546"
"227.80800","29.24605","0.03519"
"227.97600","29.26004","0.03568"
"228.14400","29.27403","0.03584"
"228.31200","29.28802","0.03619"
"228.48000","29.30207","0.03660"
"228.64800","29.31600","0.02076"
"228.81600","29.32999","-0.00117"
"228.98400","29.34405","0.00225"
"229.15200","29.35810","0.00176"
"229.32000","29.37203","-0.00069"
"229.48800","29.38602","-0.00134"
"229.65600","29.40007","-0.00074"
"229.82400","29.41394","-0.00121"
"229.99200","29.42805","-0.00106"
"230.16000","29.44204","-0.00038"
"230.32800","29.45597","-0.00051"
"230.49600","29.47002","-0.00003"
"230.66400","29.48401","-0.00121"
"230.83200","29.49800","-0.00106"
"231.00000","29.51205","-0.00062"
"231.16800","29.52610","-0.00085"
"231.33600","29.54004","-0.00085"
"231.50400","29.55403","-0.00082"
"231.67200","29.56802","0.00030"
"231.84000","29.58201","-0.00068"
"232.00800","29.59606","-0.00110"
"232.17600","29.61011","-0.00087"
"232.34400","29.62410","-0.00077"
"232.51200","29.63797","-0.00071"
"232.68000","29.65202","-0.00088"
"232.84800","29.66601","-0.00030"
"233.01600","29.68000","-0.00057"
"233.18400","29.69405","-0.00053"
"233.35200","29.70804","-0.00083"
"233.52000","29.72203","-0.00063"
"233.68800","29.73603","-0.00106"
"233.85600","29.75002","-0.00080"
"234.02400","29.76401","-0.00068"
"234.19200","29.77800","-0.00016"
"234.36000","29.79205","-0.00078"
"234.52800","29.80598","-0.00104"
"234.69600","29.81997","-0.00062"
"234.86400","29.83402","-0.00071"
"235.03200","29.84807","-0.00121"
"235.20000","29.86206","-0.00126"
"235.36800","29.87611","-0.00054"
"235.53600","29.89004","-0.00107"
"235.70400","29.90398","-0.00067"
"235.87200","29.91809","-0.00125"
"236.04000","29.93207","-0.00085"
"236.20800","29.94601","-0.00091"
"236.37600","29.96000","-0.00089"
"236.54400","29.97405","-0.00077"
"236.71200","29.98798","-0.00068"
"236.88000","30.00203","-0.00095"
"237.04800","30.01608","-0.00084"
"237.21600","30.03007","-0.00087"
"237.38400","30.04394","-0.00062"
"237.55200","30.05811","-0.00056"
"237.72000","30.07199","-0.00106"
"237.88800","30.08598","-0.00093"
"238.05600","30.10008","-0.00086"
"238.22400","30.11407","-0.00089"
"238.39200","30.12801","-0.00089"
"238.56000","30.14200","-0.00060"
"238.72800","30.15605","-0.00051"
"238.89600","30.16998","-0.00089"
"239.06400","30.18403","-0.00066"
"239.23200","30.19808","-0.00081"
"239.40000","30.21201","-0.00064"
"239.56800","30.22600","-0.00101"
"239.73600","30.24005","-0.00078"
"239.90400","30.25404","-0.00105"
"240.07200","30.26803","-0.00091"
"240.24000","30.28202","-0.00081"
"240.40800","30.29607","-0.00068"
"240.57600","30.30995","-0.00085"
"240.74400","30.32406","-0.00101"
"240.91200","30.33805","-0.00096"
"241.08000","30.35198","-0.00101"
"241.24800","30.36603","-0.00074"
"241.41600","30.38002","-0.00061"
"241.58400","30.39401","-0.00096"
"241.75200","30.40806","-0.00055"
"241.92000","30.42205","-0.00074"
"242.08800","30.43604","-0.00111"
"242.25600","30.44997","-0.00105"
"242.42400","30.46403","-0.00084"
"242.59200","30.47802","-0.00068"
"242.76000","30.49200","-0.00079"
"242.92800","30.50606","-0.00033"
"243.09600","30.52005","-0.00053"
"243.26400","30.53404","-0.00083"
"243.35800","30.54187","-0.00103"