File: Force_trajectories/161218/Specimen_RawData_8.csv
End date,"12/18/2016"
Specimen label,"16CT_29"
Maximum Load,"0.02810",N

Time,Extension,Load
(s),(mm),(N)
"0.00000","0.00000","-0.00022"
"0.08400","0.00263","-0.00009"
"0.16800","0.01052","-0.00001"
"0.25200","0.01973","-0.00036"
"0.33600","0.02792","-0.00020"
"0.42000","0.03528","0.00012"
"0.50400","0.04221","0.00004"
"0.58800","0.04933","-0.00013"
"0.67200","0.05626","-0.00015"
"0.75600","0.06326","-0.00015"
"0.84000","0.07025","-0.00008"
"0.92400","0.07719","-0.00005"
"1.00800","0.08418","0.00013"
"1.09200","0.09118","0.00026"
"1.17600","0.09829","-0.00039"
"1.26000","0.10523","0.00022"
"1.34400","0.11222","-0.00004"
"1.42800","0.11928","0.00033"
"1.51200","0.12622","0.00002"
"1.59600","0.13321","-0.00007"
"1.68000","0.14021","0.00007"
"1.76400","0.14726","0.00023"
"1.84800","0.15426","0.00008"
"1.93200","0.16131","0.00016"
"2.01600","0.16819","0.00003"
"2.10000","0.17512","0.00030"
"2.18400","0.18218","-0.00033"
"2.26800","0.18923","0.00009"
"2.35200","0.19623","0.00017"
"2.43600","0.20322","0.00013"
"2.52000","0.21022","0.00026"
"2.60400","0.21722","0.00016"
"2.68800","0.22415","0.00003"
"2.77200","0.23121","0.00002"
"2.85600","0.23826","-0.00006"
"2.94000","0.24520","-0.00025"
"3.02400","0.25219","0.00015"
"3.10800","0.25925","0.00031"
"3.19200","0.26618","0.00052"
"3.27600","0.27318","0.00038"
"3.36000","0.28023","-0.00010"
"3.44400","0.28723","0.00011"
"3.52800","0.29422","0.00015"
"3.61200","0.30116","0.00030"
"3.69600","0.30816","0.00005"
"3.78000","0.31515","0.00004"
"3.86400","0.32221","-0.00025"
"3.94800","0.32920","0.00020"
"4.03200","0.33620","0.00049"
"4.11600","0.34313","0.00002"
"4.20000","0.35019","0.00009"
"4.28400","0.35712","0.00051"
"4.36800","0.36418","0.00051"
"4.45200","0.37123","0.00007"
"4.53600","0.37817","0.00019"
"4.62000","0.38516","0.00031"
"4.70400","0.39216","0.00002"
"4.78800","0.39915","0.00049"
"4.87200","0.40621","0.00016"
"4.95600","0.41321","0.00020"
"5.04000","0.42026","-0.00003"
"5.12400","0.42720","0.00029"
"5.20800","0.43419","-0.00022"
"5.29200","0.44119","0.00021"
"5.37600","0.44818","-0.00014"
"5.46000","0.45518","0.00020"
"5.54400","0.46223","0.00003"
"5.62800","0.46923","0.00027"
"5.71200","0.47622","0.00042"
"5.79600","0.48316","0.00039"
"5.88000","0.49015","0.00002"
"5.96400","0.49721","-0.00019"
"6.04800","0.50426","0.00030"
"6.13200","0.51120","-0.00013"
"6.21600","0.51820","-0.00007"
"6.30000","0.52519","0.00075"
"6.38400","0.53213","0.00029"
"6.46800","0.53918","0.00017"
"6.55200","0.54618","0.00005"
"6.63600","0.55323","0.00006"
"6.72000","0.56023","0.00034"
"6.80400","0.56722","0.00024"
"6.88800","0.57416","0.00003"
"6.97200","0.58115","0.00013"
"7.05600","0.58821","0.00010"
"7.14000","0.59520","0.00025"
"7.22400","0.60226","-0.00024"
"7.30800","0.60920","0.00049"
"7.39200","0.61619","0.00010"
"7.47600","0.62319","0.00025"
"7.56000","0.63012","0.00011"
"7.64400","0.63724","-0.00010"
"7.72800","0.64423","0.00035"
"7.81200","0.65123","0.00021"
"7.89600","0.65822","0.00021"
"7.98000","0.66516","0.00029"
"8.06400","0.67221","0.00039"
"8.14800","0.67915","0.00020"
"8.23200","0.68620","0.00033"
"8.31600","0.69326","0.00036"
"8.40000","0.70020","0.00040"
"8.48400","0.70719","0.00044"
"8.56800","0.71413","0.00033"
"8.65200","0.72118","0.00022"
"8.73600","0.72818","-0.00028"
"8.82000","0.73517","0.00012"
"8.90400","0.74223","0.00011"
"8.98800","0.74916","0.00032"
"9.07200","0.75616","-0.00008"
"9.15600","0.76315","0.00023"
"9.24000","0.77015","-0.00010"
"9.32400","0.77720","-0.00013"
"9.40800","0.78420","-0.00016"
"9.49200","0.79119","0.00002"
"9.57600","0.79819","0.00012"
"9.66000","0.80519","0.00013"
"9.74400","0.81218","-0.00008"
"9.82800","0.81924","0.00009"
"9.91200","0.82623","0.00026"
"9.99600","0.83323","0.00033"
"10.08000","0.84016","-0.00013"
"10.16400","0.84716","0.00027"
"10.24800","0.85415","0.00011"
"10.33200","0.86121","-0.00005"
"10.41600","0.86820","0.00018"
"10.50000","0.87526","0.00024"
"10.58400","0.88219","0.00019"
"10.66800","0.88913","0.00024"
"10.75200","0.89613","0.00029"
"10.83600","0.90318","0.00022"
"10.92000","0.91024","0.00025"
"11.00400","0.91723","-0.00014"
"11.08800","0.92417","0.00024"
"11.17200","0.93116","0.00019"
"11.25600","0.93816","-0.00017"
"11.34000","0.94521","-0.00010"
"11.42400","0.95221","0.00002"
"11.50800","0.95926","0.00036"
"11.59200","0.96620","0.00037"
"11.67600","0.97319","0.00028"
"11.76000","0.98019","0.00013"
"11.84400","0.98718","0.00010"
"11.92800","0.99424","0.00000"
"12.01200","1.00124","0.00005"
"12.09600","1.00823","0.00022"
"12.18000","1.01523","-0.00013"
"12.26400","1.02222","0.00036"
"12.34800","1.02922","0.00035"
"12.43200","1.03621","0.00039"
"12.51600","1.04327","0.00006"
"12.60000","1.05020","0.00005"
"12.68400","1.05720","0.00017"
"12.76800","1.06419","-0.00002"
"12.85200","1.07113","-0.00006"
"12.93600","1.07818","0.00027"
"13.02000","1.08518","0.00036"
"13.10400","1.09218","-0.00035"
"13.18800","1.09917","0.00000"
"13.27200","1.10617","0.00011"
"13.35600","1.11316","0.00022"
"13.44000","1.12016","0.00041"
"13.52400","1.12721","0.00013"
"13.60800","1.13421","-0.00007"
"13.69200","1.14120","0.00008"
"13.77600","1.14826","0.00013"
"13.86000","1.15519","0.00023"
"13.94400","1.16219","0.00051"
"14.02800","1.16918","0.00016"
"14.11200","1.17624","0.00033"
"14.19600","1.18323","0.00018"
"14.28000","1.19023","0.00031"
"14.36400","1.19723","0.00026"
"14.44800","1.20416","-0.00009"
"14.53200","1.21122","0.00037"
"14.61600","1.21821","0.00030"
"14.70000","1.22527","0.00020"
"14.78400","1.23226","0.00015"
"14.86800","1.23920","0.00033"
"14.95200","1.24619","0.00023"
"15.03600","1.25313","0.00046"
"15.12000","1.26018","-0.00006"
"15.20400","1.26724","0.00045"
"15.28800","1.27423","0.00027"
"15.37200","1.28123","0.00041"
"15.45600","1.28817","-0.00007"
"15.54000","1.29522","0.00054"
"15.62400","1.30222","0.00019"
"15.70800","1.30921","0.00029"
"15.79200","1.31627","0.00022"
"15.87600","1.32320","0.00014"
"15.96000","1.33020","0.00041"
"16.04400","1.33713","0.00020"
"16.12800","1.34413","0.00033"
"16.21200","1.35124","0.00038"
"16.29600","1.35824","-0.00047"
"16.38000","1.36529","0.00037"
"16.46400","1.37223","0.00040"
"16.54800","1.37917","0.00033"
"16.63200","1.38616","0.00012"
"16.71600","1.39316","0.00025"
"16.80000","1.40021","0.00065"
"16.88400","1.40721","-0.00001"
"16.96800","1.41420","0.00011"
"17.05200","1.42120","0.00046"
"17.13600","1.42819","0.00003"
"17.22000","1.43519","0.00027"
"17.30400","1.44218","0.00009"
"17.38800","1.44924","0.00023"
"17.47200","1.45623","0.00005"
"17.55600","1.46323","-0.00008"
"17.64000","1.47016","0.00022"
"17.72400","1.47710","0.00011"
"17.80800","1.48422","0.00061"
"17.89200","1.49121","-0.00002"
"17.97600","1.49827","0.00031"
"18.06000","1.50520","0.00024"
"18.14400","1.51220","0.00017"
"18.22800","1.51919","0.00046"
"18.31200","1.52619","0.00009"
"18.39600","1.53318","0.00024"
"18.48000","1.54024","0.00069"
"18.56400","1.54723","0.00060"
"18.64800","1.55423","-0.00013"
"18.73200","1.56122","0.00031"
"18.81600","1.56816","0.00046"
"18.90000","1.57522","0.00014"
"18.98400","1.58221","0.00028"
"19.06800","1.58921","0.00022"
"19.15200","1.59620","0.00017"
"19.23600","1.60320","0.00027"
"19.32000","1.61019","0.00037"
"19.40400","1.61719","0.00009"
"19.48800","1.62424","0.00006"
"19.57200","1.63118","0.00018"
"19.65600","1.63823","0.00021"
"19.74000","1.64523","0.00003"
"19.82400","1.65222","0.00011"
"19.90800","1.65916","0.00026"
"19.99200","1.66621","0.00010"
"20.07600","1.67327","0.00047"
"20.16000","1.68021","0.00025"
"20.24400","1.68726","0.00057"
"20.32800","1.69420","0.00021"
"20.41200","1.70125","0.00015"
"20.49600","1.70819","0.00017"
"20.58000","1.71524","0.00007"
"20.66400","1.72224","0.00013"
"20.74800","1.72923","0.00019"
"20.83200","1.73623","0.00032"
"20.91600","1.74316","0.00049"
"21.00000","1.75016","0.00074"
"21.08400","1.75721","0.00010"
"21.16800","1.76421","0.00017"
"21.25200","1.77121","0.00031"
"21.33600","1.77820","0.00016"
"21.42000","1.78514","0.00040"
"21.50400","1.79213","0.00052"
"21.58800","1.79919","0.00076"
"21.67200","1.80624","0.00026"
"21.75600","1.81318","-0.00013"
"21.84000","1.82023","0.00046"
"21.92400","1.82717","0.00017"
"22.00800","1.83422","0.00021"
"22.09200","1.84122","0.00020"
"22.17600","1.84821","0.00001"
"22.26000","1.85521","-0.00024"
"22.34400","1.86220","0.00005"
"22.42800","1.86920","-0.00007"
"22.51200","1.87614","0.00007"
"22.59600","1.88319","0.00025"
"22.68000","1.89019","0.00056"
"22.76400","1.89724","0.00015"
"22.84800","1.90424","0.00033"
"22.93200","1.91117","0.00094"
"23.01600","1.91817","0.00041"
"23.10000","1.92516","0.00034"
"23.18400","1.93216","0.00024"
"23.26800","1.93927","0.00050"
"23.35200","1.94621","0.00036"
"23.43600","1.95320","0.00027"
"23.52000","1.96020","0.00032"
"23.60400","1.96714","-0.00002"
"23.68800","1.97419","0.00025"
"23.77200","1.98119","0.00084"
"23.85600","1.98824","0.00039"
"23.94000","1.99524","0.00021"
"24.02400","2.00217","0.00035"
"24.10800","2.00923","0.00066"
"24.19200","2.01610","0.00028"
"24.27600","2.02328","0.00069"
"24.36000","2.03021","-0.00009"
"24.44400","2.03721","0.00014"
"24.52800","2.04426","0.00059"
"24.61200","2.05120","0.00046"
"24.69600","2.05819","0.00002"
"24.78000","2.06519","0.00078"
"24.86400","2.07225","0.00022"
"24.94800","2.07924","0.00044"
"25.03200","2.08624","0.00014"
"25.11600","2.09323","0.00030"
"25.20000","2.10017","0.00045"
"25.28400","2.10722","0.00083"
"25.36800","2.11416","0.00061"
"25.45200","2.12121","0.00023"
"25.53600","2.12827","0.00013"
"25.62000","2.13520","0.00058"
"25.70400","2.14214","0.00045"
"25.78800","2.14913","0.00052"
"25.87200","2.15619","0.00060"
"25.95600","2.16319","0.00046"
"26.04000","2.17024","0.00035"
"26.12400","2.17724","0.00051"
"26.20800","2.18423","0.00065"
"26.29200","2.19117","0.00068"
"26.37600","2.19816","0.00046"
"26.46000","2.20522","0.00035"
"26.54400","2.21221","0.00057"
"26.62800","2.21927","0.00033"
"26.71200","2.22620","0.00059"
"26.79600","2.23320","0.00077"
"26.88000","2.24013","0.00085"
"26.96400","2.24719","0.00042"
"27.04800","2.25424","0.00060"
"27.13200","2.26130","0.00049"
"27.21600","2.26818","0.00044"
"27.30000","2.27517","0.00047"
"27.38400","2.28217","0.00060"
"27.46800","2.28916","0.00049"
"27.55200","2.29628","0.00047"
"27.63600","2.30315","0.00059"
"27.72000","2.31027","0.00058"
"27.80400","2.31720","0.00055"
"27.88800","2.32420","0.00021"
"27.97200","2.33119","0.00042"
"28.05600","2.33819","0.00070"
"28.14000","2.34530","0.00018"
"28.22400","2.35218","0.00058"
"28.30800","2.35924","0.00047"
"28.39200","2.36617","0.00047"
"28.47600","2.37317","0.00070"
"28.56000","2.38022","0.00054"
"28.64400","2.38722","0.00066"
"28.72800","2.39421","0.00055"
"28.81200","2.40121","0.00052"
"28.89600","2.40814","0.00070"
"28.98000","2.41514","0.00047"
"29.06400","2.42213","0.00027"
"29.14800","2.42919","0.00093"
"29.23200","2.43618","0.00055"
"29.31600","2.44324","0.00050"
"29.40000","2.45017","0.00060"
"29.48400","2.45717","0.00054"
"29.56800","2.46417","0.00030"
"29.65200","2.47116","0.00051"
"29.73600","2.47822","0.00096"
"29.82000","2.48521","0.00048"
"29.90400","2.49221","0.00092"
"29.98800","2.49920","0.00033"
"30.07200","2.50614","0.00048"
"30.15600","2.51319","0.00024"
"30.24000","2.52025","0.00075"
"30.32400","2.52724","0.00084"
"30.40800","2.53424","0.00078"
"30.49200","2.54117","0.00087"
"30.57600","2.54823","0.00116"
"30.66000","2.55517","0.00041"
"30.74400","2.56222","0.00084"
"30.82800","2.56922","0.00091"
"30.91200","2.57621","0.00059"
"30.99600","2.58327","0.00049"
"31.08000","2.59020","0.00039"
"31.16400","2.59720","0.00101"
"31.24800","2.60419","0.00089"
"31.33200","2.61125","0.00049"
"31.41600","2.61824","0.00033"
"31.50000","2.62524","0.00033"
"31.58400","2.63223","0.00088"
"31.66800","2.63917","0.00068"
"31.75200","2.64616","0.00074"
"31.83600","2.65322","0.00068"
"31.92000","2.66022","0.00079"
"32.00400","2.66721","0.00076"
"32.08800","2.67415","0.00052"
"32.17200","2.68114","0.00039"
"32.25600","2.68808","0.00067"
"32.34000","2.69519","0.00080"
"32.42400","2.70225","0.00047"
"32.50800","2.70918","0.00073"
"32.59200","2.71630","0.00092"
"32.67600","2.72317","0.00035"
"32.76000","2.73017","0.00035"
"32.84400","2.73722","0.00036"
"32.92800","2.74422","0.00051"
"33.01200","2.75128","0.00032"
"33.09600","2.75821","0.00073"
"33.18000","2.76527","0.00045"
"33.26400","2.77214","0.00065"
"33.34800","2.77914","0.00031"
"33.43200","2.78619","0.00024"
"33.51600","2.79325","0.00042"
"33.60000","2.80024","0.00058"
"33.68400","2.80724","0.00056"
"33.76800","2.81417","0.00075"
"33.85200","2.82117","0.00013"
"33.93600","2.82816","0.00045"
"34.02000","2.83522","0.00056"
"34.10400","2.84227","0.00083"
"34.18800","2.84921","0.00066"
"34.27200","2.85621","0.00064"
"34.35600","2.86314","0.00054"
"34.44000","2.87020","0.00062"
"34.52400","2.87719","0.00072"
"34.60800","2.88425","0.00079"
"34.69200","2.89124","0.00056"
"34.77600","2.89818","0.00058"
"34.86000","2.90517","0.00041"
"34.94400","2.91211","0.00049"
"35.02800","2.91922","0.00059"
"35.11200","2.92622","0.00094"
"35.19600","2.93321","0.00080"
"35.28000","2.94021","0.00051"
"35.36400","2.94721","0.00085"
"35.44800","2.95420","0.00055"
"35.53200","2.96120","0.00091"
"35.61600","2.96825","0.00079"
"35.70000","2.97519","0.00063"
"35.78400","2.98224","0.00105"
"35.86800","2.98924","0.00039"
"35.95200","2.99623","0.00002"
"36.03600","3.00317","0.00032"
"36.12000","3.01016","0.00054"
"36.20400","3.01722","0.00057"
"36.28800","3.02421","0.00053"
"36.37200","3.03121","0.00091"
"36.45600","3.03820","0.00058"
"36.54000","3.04514","0.00046"
"36.62400","3.05220","0.00056"
"36.70800","3.05919","0.00064"
"36.79200","3.06619","0.00094"
"36.87600","3.07324","0.00051"
"36.96000","3.08018","0.00031"
"37.04400","3.08723","0.00059"
"37.12800","3.09411","0.00088"
"37.21200","3.10122","0.00102"
"37.29600","3.10822","0.00075"
"37.38000","3.11521","0.00089"
"37.46400","3.12221","0.00100"
"37.54800","3.12920","0.00069"
"37.63200","3.13620","0.00108"
"37.71600","3.14320","0.00095"
"37.80000","3.15025","0.00062"
"37.88400","3.15725","0.00066"
"37.96800","3.16424","0.00108"
"38.05200","3.17124","0.00094"
"38.13600","3.17817","0.00113"
"38.22000","3.18523","0.00073"
"38.30400","3.19222","0.00092"
"38.38800","3.19922","0.00087"
"38.47200","3.20621","0.00092"
"38.55600","3.21315","0.00114"
"38.64000","3.22020","0.00052"
"38.72400","3.22714","0.00087"
"38.80800","3.23419","0.00101"
"38.89200","3.24131","0.00087"
"38.97600","3.24825","0.00068"
"39.06000","3.25518","0.00085"
"39.14400","3.26218","0.00069"
"39.22800","3.26917","0.00103"
"39.31200","3.27617","0.00092"
"39.39600","3.28322","0.00108"
"39.48000","3.29022","0.00073"
"39.56400","3.29721","0.00080"
"39.64800","3.30421","0.00096"
"39.73200","3.31114","0.00069"
"39.81600","3.31820","0.00131"
"39.90000","3.32525","0.00110"
"39.98400","3.33219","0.00121"
"40.06800","3.33919","0.00111"
"40.15200","3.34618","0.00105"
"40.23600","3.35318","0.00090"
"40.32000","3.36017","0.00075"
"40.40400","3.36717","0.00081"
"40.48800","3.37428","0.00119"
"40.57200","3.38122","0.00131"
"40.65600","3.38821","0.00074"
"40.74000","3.39521","0.00097"
"40.82400","3.40214","0.00079"
"40.90800","3.40920","0.00087"
"40.99200","3.41619","0.00092"
"41.07600","3.42325","0.00144"
"41.16000","3.43024","0.00142"
"41.24400","3.43718","0.00095"
"41.32800","3.44418","0.00116"
"41.41200","3.45111","0.00112"
"41.49600","3.45823","0.00124"
"41.58000","3.46522","0.00105"
"41.66400","3.47216","0.00147"
"41.74800","3.47915","0.00145"
"41.83200","3.48621","0.00110"
"41.91600","3.49314","0.00114"
"42.00000","3.50014","0.00015"
"42.08400","3.50725","0.00071"
"42.16800","3.51425","0.00078"
"42.25200","3.52124","0.00120"
"42.33600","3.52824","0.00131"
"42.42000","3.53518","0.00092"
"42.50400","3.54223","0.00095"
"42.58800","3.54917","0.00126"
"42.67200","3.55622","0.00094"
"42.75600","3.56322","0.00112"
"42.84000","3.57021","0.00059"
"42.92400","3.57715","0.00129"
"43.00800","3.58414","0.00089"
"43.09200","3.59120","0.00097"
"43.17600","3.59825","0.00093"
"43.26000","3.60525","0.00140"
"43.34400","3.61224","0.00103"
"43.42800","3.61918","0.00115"
"43.51200","3.62618","0.00113"
"43.59600","3.63311","0.00120"
"43.68000","3.64029","0.00128"
"43.76400","3.64728","0.00117"
"43.84800","3.65422","0.00100"
"43.93200","3.66127","0.00129"
"44.01600","3.66815","0.00103"
"44.10000","3.67514","0.00132"
"44.18400","3.68220","0.00147"
"44.26800","3.68925","0.00085"
"44.35200","3.69625","0.00134"
"44.43600","3.70318","0.00141"
"44.52000","3.71024","0.00113"
"44.60400","3.71718","0.00117"
"44.68800","3.72417","0.00146"
"44.77200","3.73123","0.00135"
"44.85600","3.73816","0.00119"
"44.94000","3.74522","0.00145"
"45.02400","3.75215","0.00113"
"45.10800","3.75921","0.00149"
"45.19200","3.76620","0.00107"
"45.27600","3.77320","0.00138"
"45.36000","3.78025","0.00149"
"45.44400","3.78725","0.00101"
"45.52800","3.79424","0.00137"
"45.61200","3.80124","0.00145"
"45.69600","3.80817","0.00154"
"45.78000","3.81523","0.00158"
"45.86400","3.82223","0.00115"
"45.94800","3.82922","0.00151"
"46.03200","3.83622","0.00137"
"46.11600","3.84321","0.00191"
"46.20000","3.85021","0.00141"
"46.28400","3.85714","0.00164"
"46.36800","3.86420","0.00155"
"46.45200","3.87119","0.00130"
"46.53600","3.87819","0.00114"
"46.62000","3.88518","0.00095"
"46.70400","3.89212","0.00077"
"46.78800","3.89917","0.00109"
"46.87200","3.90617","0.00129"
"46.95600","3.91322","0.00087"
"47.04000","3.92016","0.00112"
"47.12400","3.92716","0.00111"
"47.20800","3.93415","0.00095"
"47.29200","3.94115","0.00123"
"47.37600","3.94814","0.00126"
"47.46000","3.95520","0.00082"
"47.54400","3.96219","0.00097"
"47.62800","3.96919","0.00124"
"47.71200","3.97618","0.00083"
"47.79600","3.98318","0.00104"
"47.88000","3.99017","0.00085"
"47.96400","3.99717","0.00114"
"48.04800","4.00416","0.00123"
"48.13200","4.01122","0.00089"
"48.21600","4.01822","0.00139"
"48.30000","4.02515","0.00123"
"48.38400","4.03221","0.00104"
"48.46800","4.03920","0.00127"
"48.55200","4.04626","0.00089"
"48.63600","4.05325","0.00097"
"48.72000","4.06025","0.00113"
"48.80400","4.06724","0.00104"
"48.88800","4.07412","0.00107"
"48.97200","4.08117","0.00138"
"49.05600","4.08823","0.00080"
"49.14000","4.09522","0.00115"
"49.22400","4.10222","0.00131"
"49.30800","4.10921","0.00148"
"49.39200","4.11615","0.00144"
"49.47600","4.12309","0.00084"
"49.56000","4.13020","0.00126"
"49.64400","4.13726","0.00145"
"49.72800","4.14419","0.00116"
"49.81200","4.15125","0.00115"
"49.89600","4.15818","0.00132"
"49.98000","4.16518","0.00122"
"50.06400","4.17217","0.00097"
"50.14800","4.17923","0.00125"
"50.23200","4.18628","0.00108"
"50.31600","4.19322","0.00135"
"50.40000","4.20021","0.00126"
"50.48400","4.20715","0.00097"
"50.56800","4.21421","0.00139"
"50.65200","4.22120","0.00127"
"50.73600","4.22826","0.00129"
"50.82000","4.23525","0.00163"
"50.90400","4.24219","0.00144"
"50.98800","4.24918","0.00132"
"51.07200","4.25618","0.00143"
"51.15600","4.26317","0.00138"
"51.24000","4.27017","0.00153"
"51.32400","4.27716","0.00159"
"51.40800","4.28422","0.00170"
"51.49200","4.29115","0.00105"
"51.57600","4.29815","0.00134"
"51.66000","4.30521","0.00154"
"51.74400","4.31220","0.00137"
"51.82800","4.31926","0.00152"
"51.91200","4.32619","0.00139"
"51.99600","4.33319","0.00153"
"52.08000","4.34018","0.00144"
"52.16400","4.34712","0.00173"
"52.24800","4.35423","0.00125"
"52.33200","4.36123","0.00179"
"52.41600","4.36822","0.00154"
"52.50000","4.37522","0.00145"
"52.58400","4.38221","0.00158"
"52.66800","4.38921","0.00132"
"52.75200","4.39614","0.00126"
"52.83600","4.40320","0.00159"
"52.92000","4.41020","0.00142"
"53.00400","4.41725","0.00163"
"53.08800","4.42425","0.00125"
"53.17200","4.43118","0.00198"
"53.25600","4.43818","0.00137"
"53.34000","4.44517","0.00113"
"53.42400","4.45217","0.00136"
"53.50800","4.45922","0.00142"
"53.59200","4.46622","0.00179"
"53.67600","4.47321","0.00153"
"53.76000","4.48009","0.00131"
"53.84400","4.48726","0.00172"
"53.92800","4.49420","0.00180"
"54.01200","4.50119","0.00202"
"54.09600","4.50825","0.00155"
"54.18000","4.51519","0.00199"
"54.26400","4.52218","0.00181"
"54.34800","4.52912","0.00182"
"54.43200","4.53617","0.00162"
"54.51600","4.54323","0.00209"
"54.60000","4.55022","0.00197"
"54.68400","4.55716","0.00147"
"54.76800","4.56421","0.00190"
"54.85200","4.57115","0.00169"
"54.93600","4.57820","0.00164"
"55.02000","4.58526","0.00184"
"55.10400","4.59219","0.00178"
"55.18800","4.59925","0.00173"
"55.27200","4.60619","0.00165"
"55.35600","4.61318","0.00200"
"55.44000","4.62018","0.00192"
"55.52400","4.62723","0.00192"
"55.60800","4.63417","0.00178"
"55.69200","4.64122","0.00195"
"55.77600","4.64816","0.00211"
"55.86000","4.65521","0.00183"
"55.94400","4.66215","0.00191"
"56.02800","4.66920","0.00171"
"56.11200","4.67626","0.00189"
"56.19600","4.68319","0.00136"
"56.28000","4.69019","0.00144"
"56.36400","4.69713","0.00151"
"56.44800","4.70418","0.00142"
"56.53200","4.71124","0.00164"
"56.61600","4.71823","0.00141"
"56.70000","4.72523","0.00150"
"56.78400","4.73222","0.00172"
"56.86800","4.73922","0.00173"
"56.95200","4.74615","0.00175"
"57.03600","4.75315","0.00153"
"57.12000","4.76026","0.00151"
"57.20400","4.76720","0.00157"
"57.28800","4.77419","0.00184"
"57.37200","4.78119","0.00135"
"57.45600","4.78819","0.00159"
"57.54000","4.79518","0.00150"
"57.62400","4.80218","0.00192"
"57.70800","4.80923","0.00195"
"57.79200","4.81617","0.00192"
"57.87600","4.82322","0.00144"
"57.96000","4.83022","0.00131"
"58.04400","4.83715","0.00156"
"58.12800","4.84421","0.00137"
"58.21200","4.85120","0.00175"
"58.29600","4.85826","0.00160"
"58.38000","4.86525","0.00140"
"58.46400","4.87219","0.00123"
"58.54800","4.87918","0.00150"
"58.63200","4.88618","0.00151"
"58.71600","4.89318","0.00211"
"58.80000","4.90023","0.00159"
"58.88400","4.90723","0.00146"
"58.96800","4.91422","0.00181"
"59.05200","4.92122","0.00175"
"59.13600","4.92815","0.00151"
"59.22000","4.93515","0.00176"
"59.30400","4.94226","0.00189"
"59.38800","4.94920","0.00161"
"59.47200","4.95619","0.00187"
"59.55600","4.96325","0.00201"
"59.64000","4.97018","0.00169"
"59.72400","4.97718","0.00204"
"59.80800","4.98418","0.00178"
"59.89200","4.99123","0.00150"
"59.97600","4.99823","0.00190"
"60.06000","5.00516","0.00199"
"60.14400","5.01222","0.00146"
"60.22800","5.01915","0.00179"
"60.31200","5.02615","0.00187"
"60.39600","5.03320","0.00163"
"60.48000","5.04020","0.00183"
"60.56400","5.04725","0.00199"
"60.64800","5.05419","0.00163"
"60.73200","5.06112","0.00194"
"60.81600","5.06818","0.00149"
"60.90000","5.07523","0.00239"
"60.98400","5.08223","0.00178"
"61.06800","5.08923","0.00182"
"61.15200","5.09622","0.00198"
"61.23600","5.10316","0.00219"
"61.32000","5.11021","0.00229"
"61.40400","5.11721","0.00228"
"61.48800","5.12420","0.00219"
"61.57200","5.13126","0.00179"
"61.65600","5.13819","0.00193"
"61.74000","5.14519","0.00203"
"61.82400","5.15218","0.00201"
"61.90800","5.15918","0.00214"
"61.99200","5.16617","0.00158"
"62.07600","5.17317","0.00120"
"62.16000","5.18023","0.00112"
"62.24400","5.18716","0.00122"
"62.32800","5.19416","0.00132"
"62.41200","5.20115","0.00111"
"62.49600","5.20821","0.00124"
"62.58000","5.21520","0.00125"
"62.66400","5.22220","0.00105"
"62.74800","5.22919","0.00106"
"62.83200","5.23619","0.00115"
"62.91600","5.24318","0.00146"
"63.00000","5.25018","0.00153"
"63.08400","5.25723","0.00164"
"63.16800","5.26423","0.00130"
"63.25200","5.27122","0.00116"
"63.33600","5.27822","0.00116"
"63.42000","5.28522","0.00174"
"63.50400","5.29215","0.00177"
"63.58800","5.29921","0.00158"
"63.67200","5.30620","0.00145"
"63.75600","5.31326","0.00176"
"63.84000","5.32019","0.00154"
"63.92400","5.32719","0.00132"
"64.00800","5.33418","0.00159"
"64.09200","5.34112","0.00124"
"64.17600","5.34823","0.00186"
"64.26000","5.35517","0.00169"
"64.34400","5.36222","0.00185"
"64.42800","5.36922","0.00146"
"64.51200","5.37616","0.00164"
"64.59600","5.38321","0.00221"
"64.68000","5.39021","0.00171"
"64.76400","5.39720","0.00170"
"64.84800","5.40426","0.00171"
"64.93200","5.41119","0.00173"
"65.01600","5.41819","0.00216"
"65.10000","5.42512","0.00173"
"65.18400","5.43224","0.00182"
"65.26800","5.43923","0.00165"
"65.35200","5.44623","0.00199"
"65.43600","5.45322","0.00224"
"65.52000","5.46016","0.00204"
"65.60400","5.46715","0.00170"
"65.68800","5.47421","0.00220"
"65.77200","5.48127","0.00198"
"65.85600","5.48820","0.00187"
"65.94000","5.49520","0.00222"
"66.02400","5.50219","0.00244"
"66.10800","5.50919","0.00206"
"66.19200","5.51618","0.00191"
"66.27600","5.52318","0.00184"
"66.36000","5.53023","0.00174"
"66.44400","5.53723","0.00200"
"66.52800","5.54422","0.00175"
"66.61200","5.55116","0.00221"
"66.69600","5.55815","0.00188"
"66.78000","5.56521","0.00231"
"66.86400","5.57227","0.00185"
"66.94800","5.57920","0.00190"
"67.03200","5.58626","0.00184"
"67.11600","5.59313","0.00194"
"67.20000","5.60013","0.00184"
"67.28400","5.60718","0.00229"
"67.36800","5.61424","0.00205"
"67.45200","5.62129","0.00236"
"67.53600","5.62823","0.00221"
"67.62000","5.63522","0.00165"
"67.70400","5.64216","0.00220"
"67.78800","5.64915","0.00175"
"67.87200","5.65621","0.00240"
"67.95600","5.66321","0.00206"
"68.04000","5.67020","0.00207"
"68.12400","5.67720","0.00188"
"68.20800","5.68419","0.00210"
"68.29200","5.69119","0.00165"
"68.37600","5.69818","0.00178"
"68.46000","5.70524","0.00168"
"68.54400","5.71223","0.00212"
"68.62800","5.71923","0.00199"
"68.71200","5.72616","0.00194"
"68.79600","5.73310","0.00183"
"68.88000","5.74021","0.00212"
"68.96400","5.74721","0.00165"
"69.04800","5.75426","0.00234"
"69.13200","5.76126","0.00191"
"69.21600","5.76820","0.00221"
"69.30000","5.77519","0.00216"
"69.38400","5.78213","0.00195"
"69.46800","5.78918","0.00234"
"69.55200","5.79624","0.00236"
"69.63600","5.80323","0.00235"
"69.72000","5.81023","0.00210"
"69.80400","5.81716","0.00215"
"69.88800","5.82416","0.00207"
"69.97200","5.83115","0.00216"
"70.05600","5.83815","0.00260"
"70.14000","5.84520","0.00204"
"70.22400","5.85226","0.00233"
"70.30800","5.85920","0.00193"
"70.39200","5.86619","0.00255"
"70.47600","5.87313","0.00249"
"70.56000","5.88018","0.00238"
"70.64400","5.88718","0.00220"
"70.72800","5.89423","0.00258"
"70.81200","5.90117","0.00191"
"70.89600","5.90822","0.00263"
"70.98000","5.91510","0.00260"
"71.06400","5.92221","0.00291"
"71.14800","5.92927","0.00225"
"71.23200","5.93620","0.00239"
"71.31600","5.94326","0.00259"
"71.40000","5.95019","0.00238"
"71.48400","5.95719","0.00272"
"71.56800","5.96419","0.00213"
"71.65200","5.97118","0.00281"
"71.73600","5.97824","0.00237"
"71.82000","5.98523","0.00250"
"71.90400","5.99223","0.00290"
"71.98800","5.99922","0.00265"
"72.07200","6.00616","0.00254"
"72.15600","6.01321","0.00222"
"72.24000","6.02021","0.00262"
"72.32400","6.02726","0.00250"
"72.40800","6.03420","0.00235"
"72.49200","6.04119","0.00233"
"72.57600","6.04813","0.00255"
"72.66000","6.05518","0.00205"
"72.74400","6.06224","0.00253"
"72.82800","6.06918","0.00240"
"72.91200","6.07623","0.00225"
"72.99600","6.08317","0.00245"
"73.08000","6.09016","0.00245"
"73.16400","6.09716","0.00263"
"73.24800","6.10421","0.00224"
"73.33200","6.11127","0.00238"
"73.41600","6.11820","0.00286"
"73.50000","6.12520","0.00249"
"73.58400","6.13213","0.00297"
"73.66800","6.13919","0.00195"
"73.75200","6.14618","0.00230"
"73.83600","6.15318","0.00201"
"73.92000","6.16024","0.00193"
"74.00400","6.16717","0.00222"
"74.08800","6.17423","0.00195"
"74.17200","6.18116","0.00188"
"74.25600","6.18822","0.00194"
"74.34000","6.19521","0.00228"
"74.42400","6.20221","0.00214"
"74.50800","6.20926","0.00159"
"74.59200","6.21620","0.00197"
"74.67600","6.22313","0.00177"
"74.76000","6.23019","0.00215"
"74.84400","6.23718","0.00192"
"74.92800","6.24430","0.00223"
"75.01200","6.25117","0.00244"
"75.09600","6.25817","0.00215"
"75.18000","6.26517","0.00189"
"75.26400","6.27216","0.00201"
"75.34800","6.27916","0.00234"
"75.43200","6.28621","0.00211"
"75.51600","6.29321","0.00243"
"75.60000","6.30026","0.00259"
"75.68400","6.30726","0.00254"
"75.76800","6.31413","0.00255"
"75.85200","6.32119","0.00273"
"75.93600","6.32824","0.00206"
"76.02000","6.33524","0.00207"
"76.10400","6.34223","0.00119"
"76.18800","6.34923","0.00208"
"76.27200","6.35617","0.00158"
"76.35600","6.36316","0.00192"
"76.44000","6.37016","0.00187"
"76.52400","6.37727","0.00233"
"76.60800","6.38421","0.00194"
"76.69200","6.39120","0.00217"
"76.77600","6.39826","0.00243"
"76.86000","6.40513","0.00182"
"76.94400","6.41219","0.00232"
"77.02800","6.41918","0.00208"
"77.11200","6.42624","0.00219"
"77.19600","6.43323","0.00211"
"77.28000","6.44017","0.00195"
"77.36400","6.44723","0.00209"
"77.44800","6.45416","0.00191"
"77.53200","6.46116","0.00238"
"77.61600","6.46821","0.00237"
"77.70000","6.47521","0.00225"
"77.78400","6.48220","0.00240"
"77.86800","6.48920","0.00247"
"77.95200","6.49613","0.00239"
"78.03600","6.50319","0.00247"
"78.12000","6.51018","0.00264"
"78.20400","6.51724","0.00262"
"78.28800","6.52423","0.00258"
"78.37200","6.53123","0.00218"
"78.45600","6.53816","0.00232"
"78.54000","6.54516","0.00243"
"78.62400","6.55222","0.00272"
"78.70800","6.55921","0.00224"
"78.79200","6.56627","0.00257"
"78.87600","6.57320","0.00223"
"78.96000","6.58020","0.00239"
"79.04400","6.58713","0.00250"
"79.12800","6.59419","0.00261"
"79.21200","6.60118","0.00288"
"79.29600","6.60818","0.00281"
"79.38000","6.61523","0.00260"
"79.46400","6.62217","0.00262"
"79.54800","6.62916","0.00252"
"79.63200","6.63616","0.00296"
"79.71600","6.64321","0.00302"
"79.80000","6.65021","0.00274"
"79.88400","6.65721","0.00288"
"79.96800","6.66420","0.00266"
"80.05200","6.67120","0.00271"
"80.13600","6.67813","0.00270"
"80.22000","6.68519","0.00311"
"80.30400","6.69218","0.00284"
"80.38800","6.69924","0.00308"
"80.47200","6.70617","0.00275"
"80.55600","6.71317","0.00237"
"80.64000","6.72016","0.00209"
"80.72400","6.72716","0.00193"
"80.80800","6.73427","0.00205"
"80.89200","6.74121","0.00224"
"80.97600","6.74821","0.00215"
"81.06000","6.75520","0.00180"
"81.14400","6.76220","0.00209"
"81.22800","6.76919","0.00230"
"81.31200","6.77619","0.00223"
"81.39600","6.78330","0.00293"
"81.48000","6.79024","0.00258"
"81.56400","6.79723","0.00258"
"81.64800","6.80423","0.00265"
"81.73200","6.81116","0.00226"
"81.81600","6.81822","0.00230"
"81.90000","6.82521","0.00261"
"81.98400","6.83221","0.00257"
"82.06800","6.83921","0.00291"
"82.15200","6.84614","0.00267"
"82.23600","6.85320","0.00272"
"82.32000","6.86013","0.00306"
"82.40400","6.86725","0.00294"
"82.48800","6.87418","0.00308"
"82.57200","6.88124","0.00259"
"82.65600","6.88823","0.00272"
"82.74000","6.89517","0.00271"
"82.82400","6.90210","0.00269"
"82.90800","6.90922","0.00296"
"82.99200","6.91621","0.00285"
"83.07600","6.92321","0.00274"
"83.16000","6.93026","0.00294"
"83.24400","6.93720","0.00302"
"83.32800","6.94420","0.00286"
"83.41200","6.95119","0.00302"
"83.49600","6.95825","0.00379"
"83.58000","6.96524","0.00330"
"83.66400","6.97224","0.00350"
"83.74800","6.97917","0.00282"
"83.83200","6.98617","0.00302"
"83.91600","6.99316","0.00252"
"84.00000","7.00022","0.00274"
"84.08400","7.00727","0.00333"
"84.16800","7.01421","0.00286"
"84.25200","7.02126","0.00336"
"84.33600","7.02814","0.00329"
"84.42000","7.03514","0.00336"
"84.50400","7.04219","0.00327"
"84.58800","7.04925","0.00369"
"84.67200","7.05624","0.00366"
"84.75600","7.06318","0.00358"
"84.84000","7.07023","0.00331"
"84.92400","7.07717","0.00343"
"85.00800","7.08410","0.00376"
"85.09200","7.09122","0.00363"
"85.17600","7.09821","0.00404"
"85.26000","7.10527","0.00387"
"85.34400","7.11214","0.00385"
"85.42800","7.11914","0.00408"
"85.51200","7.12614","0.00438"
"85.59600","7.13313","0.00370"
"85.68000","7.14019","0.00418"
"85.76400","7.14718","0.00463"
"85.84800","7.15424","0.00412"
"85.93200","7.16117","0.00489"
"86.01600","7.16817","0.00481"
"86.10000","7.17522","0.00448"
"86.18400","7.18216","0.00445"
"86.26800","7.18921","0.00467"
"86.35200","7.19621","0.00479"
"86.43600","7.20320","0.00538"
"86.52000","7.21020","0.00480"
"86.60400","7.21714","0.00508"
"86.68800","7.22425","0.00522"
"86.77200","7.23125","0.00496"
"86.85600","7.23824","0.00536"
"86.94000","7.24524","0.00506"
"87.02400","7.25223","0.00542"
"87.10800","7.25917","0.00543"
"87.19200","7.26622","0.00558"
"87.27600","7.27322","0.00556"
"87.36000","7.28021","0.00551"
"87.44400","7.28727","0.00543"
"87.52800","7.29426","0.00599"
"87.61200","7.30120","0.00616"
"87.69600","7.30819","0.00590"
"87.78000","7.31519","0.00607"
"87.86400","7.32218","0.00605"
"87.94800","7.32924","0.00587"
"88.03200","7.33624","0.00622"
"88.11600","7.34323","0.00652"
"88.20000","7.35011","0.00660"
"88.28400","7.35722","0.00676"
"88.36800","7.36422","0.00680"
"88.45200","7.37121","0.00662"
"88.53600","7.37827","0.00672"
"88.62000","7.38520","0.00717"
"88.70400","7.39220","0.00692"
"88.78800","7.39913","0.00730"
"88.87200","7.40625","0.00697"
"88.95600","7.41324","0.00735"
"89.04000","7.42018","0.00764"
"89.12400","7.42724","0.00741"
"89.20800","7.43417","0.00720"
"89.29200","7.44117","0.00745"
"89.37600","7.44816","0.00759"
"89.46000","7.45522","0.00768"
"89.54400","7.46227","0.00798"
"89.62800","7.46915","0.00810"
"89.71200","7.47620","0.00823"
"89.79600","7.48314","0.00842"
"89.88000","7.49013","0.00860"
"89.96400","7.49725","0.00782"
"90.04800","7.50418","0.00855"
"90.13200","7.51124","0.00845"
"90.21600","7.51818","0.00896"
"90.30000","7.52517","0.00894"
"90.38400","7.53217","0.00841"
"90.46800","7.53916","0.00870"
"90.55200","7.54628","0.00900"
"90.63600","7.55321","0.00922"
"90.72000","7.56021","0.00894"
"90.80400","7.56720","0.00820"
"90.88800","7.57420","0.00775"
"90.97200","7.58119","0.00267"
"91.05600","7.58825","0.00038"
"91.14000","7.59518","0.00214"
"91.22400","7.60224","0.00186"
"91.30800","7.60918","0.00152"
"91.39200","7.61617","0.00069"
"91.47600","7.62323","0.00028"
"91.56000","7.63022","0.00072"
"91.64400","7.63722","0.00086"
"91.72800","7.64427","0.00142"
"91.81200","7.65121","0.00121"
"91.89600","7.65814","0.00072"
"91.98000","7.66520","0.00042"
"92.06400","7.67219","0.00156"
"92.14800","7.67931","0.00240"
"92.23200","7.68618","0.00125"
"92.31600","7.69318","0.00065"
"92.40000","7.70018","0.00040"
"92.48400","7.70717","0.00092"
"92.56800","7.71417","0.00193"
"92.65200","7.72116","0.00170"
"92.73600","7.72822","0.00068"
"92.82000","7.73521","0.00078"
"92.90400","7.74221","0.00176"
"92.98800","7.74920","0.00195"
"93.07200","7.75608","0.00127"
"93.15600","7.76325","0.00126"
"93.24000","7.77025","0.00113"
"93.32400","7.77724","0.00146"
"93.40800","7.78424","0.00209"
"93.49200","7.79117","0.00134"
"93.57600","7.79817","0.00143"
"93.66000","7.80517","0.00100"
"93.74400","7.81228","0.00210"
"93.82800","7.81921","0.00204"
"93.91200","7.82621","0.00195"
"93.99600","7.83321","0.00117"
"94.08000","7.84014","0.00152"
"94.16400","7.84720","0.00216"
"94.24800","7.85419","0.00245"
"94.33200","7.86125","0.00168"
"94.41600","7.86824","0.00100"
"94.50000","7.87524","0.00163"
"94.58400","7.88217","0.00197"
"94.66800","7.88917","0.00184"
"94.75200","7.89616","0.00166"
"94.83600","7.90322","0.00104"
"94.92000","7.91027","0.00147"
"95.00400","7.91721","0.00194"
"95.08800","7.92421","0.00183"
"95.17200","7.93114","0.00182"
"95.25600","7.93820","0.00161"
"95.34000","7.94519","0.00170"
"95.42400","7.95225","0.00198"
"95.50800","7.95924","0.00174"
"95.59200","7.96624","0.00192"
"95.67600","7.97317","0.00152"
"95.76000","7.98017","0.00237"
"95.84400","7.98722","0.00230"
"95.92800","7.99422","0.00165"
"96.01200","8.00127","0.00181"
"96.09600","8.00821","0.00160"
"96.18000","8.01521","0.00187"
"96.26400","8.02214","0.00172"
"96.34800","8.02920","0.00174"
"96.43200","8.03619","0.00182"
"96.51600","8.04319","0.00177"
"96.60000","8.05024","0.00214"
"96.68400","8.05718","0.00179"
"96.76800","8.06417","0.00222"
"96.85200","8.07117","0.00126"
"96.93600","8.07822","0.00190"
"97.02000","8.08528","0.00181"
"97.10400","8.09221","0.00213"
"97.18800","8.09921","0.00168"
"97.27200","8.10620","0.00200"
"97.35600","8.11320","0.00239"
"97.44000","8.12020","0.00221"
"97.52400","8.12719","0.00231"
"97.60800","8.13425","0.00175"
"97.69200","8.14118","0.00218"
"97.77600","8.14818","0.00235"
"97.86000","8.15517","0.00243"
"97.94400","8.16217","0.00188"
"98.02800","8.16922","0.00229"
"98.11200","8.17616","0.00231"
"98.19600","8.18315","0.00212"
"98.28000","8.19015","0.00222"
"98.36400","8.19720","0.00249"
"98.44800","8.20414","0.00206"
"98.53200","8.21119","0.00198"
"98.61600","8.21825","0.00227"
"98.70000","8.22519","0.00260"
"98.78400","8.23218","0.00242"
"98.86800","8.23918","0.00211"
"98.95200","8.24617","0.00207"
"99.03600","8.25317","0.00226"
"99.12000","8.26016","0.00254"
"99.20400","8.26722","0.00217"
"99.28800","8.27421","0.00278"
"99.37200","8.28115","0.00245"
"99.45600","8.28820","0.00248"
"99.54000","8.29514","0.00238"
"99.62400","8.30219","0.00304"
"99.70800","8.30919","0.00217"
"99.79200","8.31625","0.00260"
"99.87600","8.32324","0.00256"
"99.96000","8.33018","0.00250"
"100.04400","8.33717","0.00263"
"100.12800","8.34417","0.00284"
"100.21200","8.35122","0.00268"
"100.29600","8.35822","0.00278"
"100.38000","8.36521","0.00274"
"100.46400","8.37221","0.00303"
"100.54800","8.37914","0.00263"
"100.63200","8.38620","0.00306"
"100.71600","8.39325","0.00318"
"100.80000","8.40019","0.00279"
"100.88400","8.40725","0.00299"
"100.96800","8.41418","0.00314"
"101.05200","8.42118","0.00337"
"101.13600","8.42811","0.00322"
"101.22000","8.43517","0.00345"
"101.30400","8.44222","0.00327"
"101.38800","8.44922","0.00272"
"101.47200","8.45627","0.00294"
"101.55600","8.46315","0.00325"
"101.64000","8.47020","0.00291"
"101.72400","8.47720","0.00293"
"101.80800","8.48419","0.00352"
"101.89200","8.49125","0.00287"
"101.97600","8.49825","0.00292"
"102.06000","8.50524","0.00304"
"102.14400","8.51218","0.00323"
"102.22800","8.51911","0.00313"
"102.31200","8.52623","0.00356"
"102.39600","8.53328","0.00330"
"102.48000","8.54022","0.00323"
"102.56400","8.54721","0.00327"
"102.64800","8.55421","0.00364"
"102.73200","8.56120","0.00368"
"102.81600","8.56820","0.00395"
"102.90000","8.57519","0.00366"
"102.98400","8.58219","0.00373"
"103.06800","8.58924","0.00349"
"103.15200","8.59618","0.00368"
"103.23600","8.60318","0.00377"
"103.32000","8.61023","0.00373"
"103.40400","8.61717","0.00360"
"103.48800","8.62422","0.00362"
"103.57200","8.63122","0.00424"
"103.65600","8.63821","0.00350"
"103.74000","8.64515","0.00375"
"103.82400","8.65214","0.00358"
"103.90800","8.65920","0.00353"
"103.99200","8.66619","0.00417"
"104.07600","8.67319","0.00410"
"104.16000","8.68024","0.00434"
"104.24400","8.68718","0.00367"
"104.32800","8.69418","0.00423"
"104.41200","8.70117","0.00453"
"104.49600","8.70817","0.00449"
"104.58000","8.71522","0.00435"
"104.66400","8.72228","0.00451"
"104.74800","8.72921","0.00477"
"104.83200","8.73615","0.00476"
"104.91600","8.74320","0.00488"
"105.00000","8.75020","0.00448"
"105.08400","8.75719","0.00438"
"105.16800","8.76419","0.00472"
"105.25200","8.77118","0.00416"
"105.33600","8.77818","0.00501"
"105.42000","8.78512","0.00492"
"105.50400","8.79217","0.00533"
"105.58800","8.79922","0.00506"
"105.67200","8.80616","0.00499"
"105.75600","8.81322","0.00564"
"105.84000","8.82021","0.00533"
"105.92400","8.82715","0.00518"
"106.00800","8.83414","0.00569"
"106.09200","8.84120","0.00511"
"106.17600","8.84819","0.00521"
"106.26000","8.85519","0.00562"
"106.34400","8.86218","0.00594"
"106.42800","8.86918","0.00624"
"106.51200","8.87617","0.00585"
"106.59600","8.88317","0.00636"
"106.68000","8.89023","0.00624"
"106.76400","8.89722","0.00607"
"106.84800","8.90422","0.00652"
"106.93200","8.91121","0.00650"
"107.01600","8.91815","0.00658"
"107.10000","8.92514","0.00700"
"107.18400","8.93220","0.00671"
"107.26800","8.93919","0.00667"
"107.35200","8.94619","0.00721"
"107.43600","8.95312","0.00698"
"107.52000","8.96018","0.00712"
"107.60400","8.96717","0.00733"
"107.68800","8.97423","0.00728"
"107.77200","8.98123","0.00722"
"107.85600","8.98822","0.00760"
"107.94000","8.99522","0.00771"
"108.02400","9.00215","0.00750"
"108.10800","9.00915","0.00768"
"108.19200","9.01620","0.00759"
"108.27600","9.02320","0.00782"
"108.36000","9.03019","0.00790"
"108.44400","9.03719","0.00806"
"108.52800","9.04418","0.00752"
"108.61200","9.05118","0.00736"
"108.69600","9.05811","0.00729"
"108.78000","9.06523","0.00740"
"108.86400","9.07222","0.00745"
"108.94800","9.07922","0.00727"
"109.03200","9.08622","0.00733"
"109.11600","9.09321","0.00743"
"109.20000","9.10021","0.00734"
"109.28400","9.10720","0.00760"
"109.36800","9.11426","0.00793"
"109.45200","9.12119","0.00787"
"109.53600","9.12825","0.00815"
"109.62000","9.13518","0.00825"
"109.70400","9.14212","0.00815"
"109.78800","9.14923","0.00863"
"109.87200","9.15623","0.00872"
"109.95600","9.16322","0.00903"
"110.04000","9.17022","0.00877"
"110.12400","9.17722","0.00917"
"110.20800","9.18421","0.00905"
"110.29200","9.19115","0.00930"
"110.37600","9.19820","0.00934"
"110.46000","9.20520","0.00944"
"110.54400","9.21219","0.00914"
"110.62800","9.21925","0.00970"
"110.71200","9.22618","0.00960"
"110.79600","9.23318","0.01031"
"110.88000","9.24017","0.00989"
"110.96400","9.24723","0.01064"
"111.04800","9.25422","0.01074"
"111.13200","9.26122","0.01078"
"111.21600","9.26822","0.01110"
"111.30000","9.27521","0.01110"
"111.38400","9.28215","0.01120"
"111.46800","9.28914","0.01105"
"111.55200","9.29620","0.01167"
"111.63600","9.30325","0.01112"
"111.72000","9.31019","0.01158"
"111.80400","9.31712","0.01218"
"111.88800","9.32412","0.01185"
"111.97200","9.33117","0.01226"
"112.05600","9.33817","0.01249"
"112.14000","9.34522","0.01258"
"112.22400","9.35222","0.01327"
"112.30800","9.35921","0.01337"
"112.39200","9.36621","0.01319"
"112.47600","9.37315","0.01354"
"112.56000","9.38020","0.01328"
"112.64400","9.38726","0.01384"
"112.72800","9.39419","0.01436"
"112.81200","9.40125","0.01414"
"112.89600","9.40818","0.01448"
"112.98000","9.41518","0.01476"
"113.06400","9.42217","0.01452"
"113.14800","9.42923","0.01480"
"113.23200","9.43628","0.01495"
"113.31600","9.44316","0.01455"
"113.40000","9.45015","0.01456"
"113.48400","9.45709","0.01513"
"113.56800","9.46414","0.01528"
"113.65200","9.47126","0.01549"
"113.73600","9.47820","0.01569"
"113.82000","9.48525","0.01578"
"113.90400","9.49219","0.01566"
"113.98800","9.49918","0.01649"
"114.07200","9.50612","0.01600"
"114.15600","9.51323","0.01619"
"114.24000","9.52029","0.01717"
"114.32400","9.52722","0.01642"
"114.40800","9.53422","0.01706"
"114.49200","9.54121","0.01755"
"114.57600","9.54821","0.01712"
"114.66000","9.55520","0.01755"
"114.74400","9.56226","0.01834"
"114.82800","9.56925","0.01785"
"114.91200","9.57619","0.01826"
"114.99600","9.58325","0.01832"
"115.08000","9.59018","0.01900"
"115.16400","9.59718","0.01905"
"115.24800","9.60417","0.01935"
"115.33200","9.61117","0.01940"
"115.41600","9.61822","0.01841"
"115.50000","9.62516","0.01106"
"115.58400","9.63221","0.01108"
"115.66800","9.63915","0.01187"
"115.75200","9.64620","0.01000"
"115.83600","9.65320","0.01058"
"115.92000","9.66019","0.01083"
"116.00400","9.66719","0.01142"
"116.08800","9.67419","0.01187"
"116.17200","9.68112","0.01024"
"116.25600","9.68824","0.01040"
"116.34000","9.69517","0.01206"
"116.42400","9.70223","0.01186"
"116.50800","9.70922","0.01251"
"116.59200","9.71616","0.01344"
"116.67600","9.72321","0.01326"
"116.76000","9.73015","0.01294"
"116.84400","9.73720","0.01274"
"116.92800","9.74420","0.01303"
"117.01200","9.75119","0.01452"
"117.09600","9.75825","0.01508"
"117.18000","9.76519","0.01504"
"117.26400","9.77218","0.01489"
"117.34800","9.77918","0.01418"
"117.43200","9.78623","0.01423"
"117.51600","9.79323","0.01504"
"117.60000","9.80022","0.01520"
"117.68400","9.80722","0.01647"
"117.76800","9.81415","0.01607"
"117.85200","9.82121","0.01616"
"117.93600","9.82826","0.01564"
"118.02000","9.83526","0.01642"
"118.10400","9.84219","0.01664"
"118.18800","9.84919","0.01775"
"118.27200","9.85618","0.01880"
"118.35600","9.86312","0.01829"
"118.44000","9.87024","0.01773"
"118.52400","9.87723","0.01847"
"118.60800","9.88417","0.01862"
"118.69200","9.89128","0.01948"
"118.77600","9.89816","0.01997"
"118.86000","9.90509","0.01945"
"118.94400","9.91221","0.01889"
"119.02800","9.91926","0.01938"
"119.11200","9.92620","0.01948"
"119.19600","9.93325","0.01997"
"119.28000","9.94025","0.02066"
"119.36400","9.94718","0.02109"
"119.44800","9.95418","0.02063"
"119.53200","9.96124","0.02053"
"119.61600","9.96829","0.02130"
"119.70000","9.97522","0.02155"
"119.78400","9.98222","0.02211"
"119.86800","9.98922","0.02179"
"119.95200","9.99615","0.02174"
"120.03600","10.00315","0.02155"
"120.12000","10.01026","0.02191"
"120.20400","10.01720","0.02188"
"120.28800","10.02425","0.02166"
"120.37200","10.03119","0.02229"
"120.45600","10.03818","0.02196"
"120.54000","10.04518","0.02201"
"120.62400","10.05218","0.02183"
"120.70800","10.05923","0.02244"
"120.79200","10.06623","0.02266"
"120.87600","10.07322","0.02368"
"120.96000","10.08016","0.02301"
"121.04400","10.08709","0.02322"
"121.12800","10.09427","0.02326"
"121.21200","10.10120","0.02391"
"121.29600","10.10820","0.02406"
"121.38000","10.11525","0.02464"
"121.46400","10.12219","0.02431"
"121.54800","10.12918","0.02452"
"121.63200","10.13612","0.02461"
"121.71600","10.14323","0.02492"
"121.80000","10.15023","0.02524"
"121.88400","10.15723","0.02527"
"121.96800","10.16422","0.02562"
"122.05200","10.17122","0.02504"
"122.13600","10.17821","0.02502"
"122.22000","10.18521","0.02554"
"122.30400","10.19226","0.02631"
"122.38800","10.19926","0.02613"
"122.47200","10.20619","0.02669"
"122.55600","10.21319","0.02704"
"122.64000","10.22012","0.02690"
"122.72400","10.22718","0.02712"
"122.80800","10.23423","0.02717"
"122.89200","10.24123","0.02786"
"122.97600","10.24823","0.02800"
"123.06000","10.25522","0.02804"
"123.06800","10.25588","0.02791"