File: Force_trajectories/161218/Specimen_RawData_2.csv
End date,"12/18/2016"
Specimen label,"16AT_32"
Maximum Load,"0.01616",N

Time,Extension,Load
(s),(mm),(N)
"0.00000","0.00000","0.00084"
"0.34800","0.02894","0.00176"
"0.69600","0.05824","0.00379"
"1.04400","0.08717","0.00434"
"1.39200","0.11623","0.00541"
"1.74000","0.14523","0.00574"
"2.08800","0.17417","0.00604"
"2.43600","0.20322","0.00661"
"2.78400","0.23222","0.00672"
"3.13200","0.26116","0.00706"
"3.48000","0.29028","0.00704"
"3.82800","0.31916","0.00778"
"4.17600","0.34815","0.00760"
"4.52400","0.37721","0.00820"
"4.87200","0.40609","0.00804"
"5.22000","0.43521","0.00812"
"5.56800","0.46421","0.00842"
"5.91600","0.49314","0.00839"
"6.26400","0.52220","0.00819"
"6.61200","0.55120","0.00800"
"6.96000","0.58020","0.00853"
"7.30800","0.60920","0.00823"
"7.65600","0.63819","0.00821"
"8.00400","0.66713","0.00853"
"8.35200","0.69613","0.00835"
"8.70000","0.72519","0.00849"
"9.04800","0.75413","0.00885"
"9.39600","0.78318","0.00863"
"9.74400","0.81218","0.00905"
"10.09200","0.84124","0.00866"
"10.44000","0.87018","0.00879"
"10.78800","0.89912","0.00899"
"11.13600","0.92823","0.00920"
"11.48400","0.95723","0.00917"
"11.83200","0.98617","0.00964"
"12.18000","1.01517","0.00923"
"12.52800","1.04422","0.00929"
"12.87600","1.07310","0.00942"
"13.22400","1.10222","0.00966"
"13.57200","1.13116","0.00951"
"13.92000","1.16016","0.00967"
"14.26800","1.18927","0.00965"
"14.61600","1.21815","0.00962"
"14.96400","1.24715","0.01000"
"15.31200","1.27615","0.01009"
"15.66000","1.30509","0.00997"
"16.00800","1.33420","0.00971"
"16.35600","1.36320","0.00999"
"16.70400","1.39220","0.01003"
"17.05200","1.42120","0.01006"
"17.40000","1.45020","0.00998"
"17.74800","1.47919","0.01002"
"18.09600","1.50819","0.01006"
"18.44400","1.53719","0.01038"
"18.79200","1.56613","0.01038"
"19.14000","1.59518","0.01001"
"19.48800","1.62418","0.01018"
"19.83600","1.65318","0.01032"
"20.18400","1.68218","0.01024"
"20.53200","1.71112","0.00999"
"20.88000","1.74017","0.01046"
"21.22800","1.76923","0.01050"
"21.57600","1.79817","0.01049"
"21.92400","1.82717","0.01041"
"22.27200","1.85623","0.01085"
"22.62000","1.88516","0.01056"
"22.96800","1.91416","0.01082"
"23.31600","1.94322","0.01078"
"23.66400","1.97210","0.01060"
"24.01200","2.00122","0.01043"
"24.36000","2.03021","0.01075"
"24.70800","2.05921","0.01112"
"25.05600","2.08821","0.01078"
"25.40400","2.11721","0.01074"
"25.75200","2.14621","0.01102"
"26.10000","2.17520","0.01107"
"26.44800","2.20420","0.01092"
"26.79600","2.23314","0.01086"
"27.14400","2.26220","0.01075"
"27.49200","2.29114","0.01084"
"27.84000","2.32013","0.01055"
"28.18800","2.34925","0.01135"
"28.53600","2.37813","0.01123"
"28.88400","2.40719","0.01095"
"29.23200","2.43624","0.01131"
"29.58000","2.46512","0.01065"
"29.92800","2.49418","0.01086"
"30.27600","2.52318","0.01125"
"30.62400","2.55218","0.01107"
"30.97200","2.58123","0.01110"
"31.32000","2.61023","0.01101"
"31.66800","2.63917","0.01106"
"32.01600","2.66817","0.01119"
"32.36400","2.69717","0.01153"
"32.71200","2.72616","0.01108"
"33.06000","2.75516","0.01144"
"33.40800","2.78416","0.01120"
"33.75600","2.81316","0.01164"
"34.10400","2.84216","0.01125"
"34.45200","2.87109","0.01146"
"34.80000","2.90021","0.01155"
"35.14800","2.92915","0.01153"
"35.49600","2.95821","0.01163"
"35.84400","2.98720","0.01172"
"36.19200","3.01620","0.01143"
"36.54000","3.04514","0.01169"
"36.88800","3.07420","0.01156"
"37.23600","3.10320","0.01143"
"37.58400","3.13213","0.01151"
"37.93200","3.16119","0.01188"
"38.28000","3.19019","0.01201"
"38.62800","3.21919","0.01188"
"38.97600","3.24819","0.01175"
"39.32400","3.27712","0.01193"
"39.67200","3.30618","0.01199"
"40.02000","3.33518","0.01228"
"40.36800","3.36418","0.01255"
"40.71600","3.39318","0.01194"
"41.06400","3.42223","0.01238"
"41.41200","3.45117","0.01216"
"41.76000","3.48023","0.01211"
"42.10800","3.50917","0.01243"
"42.45600","3.53817","0.01253"
"42.80400","3.56722","0.01206"
"43.15200","3.59616","0.01233"
"43.50000","3.62516","0.01219"
"43.84800","3.65422","0.01237"
"44.19600","3.68315","0.01214"
"44.54400","3.71221","0.01257"
"44.89200","3.74115","0.01257"
"45.24000","3.77015","0.01245"
"45.58800","3.79921","0.01238"
"45.93600","3.82820","0.01246"
"46.28400","3.85714","0.01270"
"46.63200","3.88620","0.01248"
"46.98000","3.91520","0.01248"
"47.32800","3.94414","0.01275"
"47.67600","3.97325","0.01266"
"48.02400","4.00219","0.01258"
"48.37200","4.03113","0.01262"
"48.72000","4.06025","0.01256"
"49.06800","4.08919","0.01243"
"49.41600","4.11812","0.01300"
"49.76400","4.14718","0.01305"
"50.11200","4.17618","0.01266"
"50.46000","4.20518","0.01268"
"50.80800","4.23418","0.01307"
"51.15600","4.26317","0.01258"
"51.50400","4.29211","0.01312"
"51.85200","4.32123","0.01283"
"52.20000","4.35017","0.01288"
"52.54800","4.37922","0.01293"
"52.89600","4.40822","0.01298"
"53.24400","4.43716","0.01315"
"53.59200","4.46622","0.01298"
"53.94000","4.49522","0.01317"
"54.28800","4.52421","0.01309"
"54.63600","4.55321","0.01320"
"54.98400","4.58215","0.01199"
"55.33200","4.61121","0.01115"
"55.68000","4.64021","0.01149"
"56.02800","4.66920","0.01142"
"56.37600","4.69814","0.01176"
"56.72400","4.72720","0.01187"
"57.07200","4.75614","0.01151"
"57.42000","4.78520","0.01188"
"57.76800","4.81419","0.01179"
"58.11600","4.84313","0.01160"
"58.46400","4.87225","0.01189"
"58.81200","4.90119","0.01189"
"59.16000","4.93018","0.01188"
"59.50800","4.95924","0.01177"
"59.85600","4.98818","0.01202"
"60.20400","5.01718","0.01174"
"60.55200","5.04618","0.01206"
"60.90000","5.07517","0.01224"
"61.24800","5.10417","0.01191"
"61.59600","5.13323","0.01232"
"61.94400","5.16217","0.01215"
"62.29200","5.19117","0.01249"
"62.64000","5.22022","0.01210"
"62.98800","5.24916","0.01196"
"63.33600","5.27822","0.01230"
"63.68400","5.30722","0.01219"
"64.03200","5.33616","0.01236"
"64.38000","5.36515","0.01271"
"64.72800","5.39415","0.01219"
"65.07600","5.42315","0.01255"
"65.42400","5.45221","0.01221"
"65.77200","5.48121","0.01249"
"66.12000","5.51020","0.01233"
"66.46800","5.53920","0.01273"
"66.81600","5.56814","0.01219"
"67.16400","5.59720","0.01243"
"67.51200","5.62619","0.01281"
"67.86000","5.65513","0.01229"
"68.20800","5.68425","0.01240"
"68.55600","5.71319","0.01317"
"68.90400","5.74213","0.01248"
"69.25200","5.77112","0.01315"
"69.60000","5.80018","0.01286"
"69.94800","5.82912","0.01284"
"70.29600","5.85824","0.01272"
"70.64400","5.88718","0.01231"
"70.99200","5.91617","0.01259"
"71.34000","5.94523","0.01282"
"71.68800","5.97423","0.01265"
"72.03600","6.00317","0.01297"
"72.38400","6.03223","0.01277"
"72.73200","6.06110","0.01275"
"73.08000","6.09016","0.01257"
"73.42800","6.11916","0.01288"
"73.77600","6.14816","0.01280"
"74.12400","6.17722","0.01302"
"74.47200","6.20621","0.01278"
"74.82000","6.23515","0.01327"
"75.16800","6.26421","0.01288"
"75.51600","6.29321","0.01308"
"75.86400","6.32215","0.01266"
"76.21200","6.35114","0.01338"
"76.56000","6.38020","0.01280"
"76.90800","6.40914","0.01270"
"77.25600","6.43820","0.01301"
"77.60400","6.46719","0.01299"
"77.95200","6.49619","0.01286"
"78.30000","6.52519","0.01263"
"78.64800","6.55419","0.01286"
"78.99600","6.58319","0.01302"
"79.34400","6.61218","0.01316"
"79.69200","6.64118","0.01306"
"80.04000","6.67018","0.01323"
"80.38800","6.69924","0.01302"
"80.73600","6.72812","0.01330"
"81.08400","6.75717","0.01330"
"81.43200","6.78623","0.01309"
"81.78000","6.81517","0.01314"
"82.12800","6.84423","0.01300"
"82.47600","6.87317","0.01290"
"82.82400","6.90216","0.01315"
"83.17200","6.93122","0.01309"
"83.52000","6.96016","0.01326"
"83.86800","6.98922","0.01331"
"84.21600","7.01816","0.01321"
"84.56400","7.04715","0.01339"
"84.91200","7.07615","0.01326"
"85.26000","7.10515","0.01317"
"85.60800","7.13415","0.01344"
"85.95600","7.16320","0.01331"
"86.30400","7.19220","0.01314"
"86.65200","7.22114","0.01313"
"87.00000","7.25026","0.01357"
"87.34800","7.27926","0.01338"
"87.69600","7.30814","0.01276"
"88.04400","7.33719","0.01330"
"88.39200","7.36619","0.01337"
"88.74000","7.39519","0.01324"
"89.08800","7.42425","0.01374"
"89.43600","7.45318","0.01327"
"89.78400","7.48218","0.01355"
"90.13200","7.51118","0.01374"
"90.48000","7.54018","0.01323"
"90.82800","7.56918","0.01335"
"91.17600","7.59817","0.01367"
"91.52400","7.62717","0.01358"
"91.87200","7.65617","0.01371"
"92.22000","7.68517","0.01340"
"92.56800","7.71411","0.01371"
"92.91600","7.74322","0.01320"
"93.26400","7.77216","0.01386"
"93.61200","7.80116","0.01395"
"93.96000","7.83022","0.01360"
"94.30800","7.85921","0.01325"
"94.65600","7.88815","0.01403"
"95.00400","7.91721","0.01334"
"95.35200","7.94615","0.01336"
"95.70000","7.97515","0.01357"
"96.04800","8.00426","0.01370"
"96.39600","8.03314","0.01374"
"96.74400","8.06220","0.01361"
"97.09200","8.09120","0.01389"
"97.44000","8.12014","0.01363"
"97.78800","8.14925","0.01367"
"98.13600","8.17819","0.01366"
"98.48400","8.20719","0.01374"
"98.83200","8.23619","0.01360"
"99.18000","8.26519","0.01367"
"99.52800","8.29412","0.01359"
"99.87600","8.32318","0.01387"
"100.22400","8.35218","0.01343"
"100.57200","8.38112","0.01384"
"100.92000","8.41024","0.01386"
"101.26800","8.43917","0.01349"
"101.61600","8.46817","0.01389"
"101.96400","8.49723","0.01356"
"102.31200","8.52617","0.01347"
"102.66000","8.55516","0.01374"
"103.00800","8.58422","0.01378"
"103.35600","8.61316","0.01379"
"103.70400","8.64216","0.01390"
"104.05200","8.67116","0.01345"
"104.40000","8.70015","0.01332"
"104.74800","8.72915","0.01364"
"105.09600","8.75827","0.01370"
"105.44400","8.78715","0.01387"
"105.79200","8.81621","0.01425"
"106.14000","8.84520","0.01418"
"106.48800","8.87420","0.01433"
"106.83600","8.90320","0.01389"
"107.18400","8.93214","0.01430"
"107.53200","8.96119","0.01423"
"107.88000","8.99019","0.01369"
"108.22800","9.01919","0.01429"
"108.57600","9.04819","0.01440"
"108.92400","9.07719","0.01427"
"109.27200","9.10618","0.01456"
"109.62000","9.13518","0.01411"
"109.96800","9.16424","0.01412"
"110.31600","9.19318","0.01424"
"110.66400","9.22218","0.01423"
"111.01200","9.25123","0.01401"
"111.36000","9.28017","0.01436"
"111.70800","9.30923","0.01416"
"112.05600","9.33817","0.01439"
"112.40400","9.36717","0.01430"
"112.75200","9.39622","0.01454"
"113.10000","9.42516","0.01443"
"113.44800","9.45422","0.01449"
"113.79600","9.48322","0.01432"
"114.14400","9.51216","0.01433"
"114.49200","9.54121","0.01456"
"114.84000","9.57021","0.01449"
"115.18800","9.59909","0.01423"
"115.53600","9.62821","0.01441"
"115.88400","9.65720","0.01434"
"116.23200","9.68614","0.01450"
"116.58000","9.71526","0.01434"
"116.92800","9.74420","0.01486"
"117.27600","9.77320","0.01460"
"117.62400","9.80219","0.01457"
"117.97200","9.83119","0.01444"
"118.32000","9.86013","0.01441"
"118.66800","9.88919","0.01444"
"119.01600","9.91819","0.01489"
"119.36400","9.94718","0.01422"
"119.71200","9.97624","0.01456"
"120.06000","10.00512","0.01460"
"120.40800","10.03418","0.01460"
"120.75600","10.06324","0.01483"
"121.10400","10.09212","0.01484"
"121.45200","10.12123","0.01480"
"121.80000","10.15023","0.01429"
"122.14800","10.17917","0.01477"
"122.49600","10.20817","0.01458"
"122.84400","10.23722","0.01469"
"123.19200","10.26616","0.01427"
"123.54000","10.29522","0.01441"
"123.88800","10.32422","0.01450"
"124.23600","10.35316","0.01455"
"124.58400","10.38221","0.01470"
"124.93200","10.41115","0.01450"
"125.28000","10.44015","0.01465"
"125.62800","10.46921","0.01440"
"125.97600","10.49815","0.01501"
"126.32400","10.52720","0.01478"
"126.67200","10.55614","0.01467"
"127.02000","10.58514","0.01476"
"127.36800","10.61420","0.01466"
"127.71600","10.64319","0.01525"
"128.06400","10.67219","0.01481"
"128.41200","10.70119","0.01484"
"128.76000","10.73025","0.01504"
"129.10800","10.75913","0.01507"
"129.45600","10.78818","0.01508"
"129.80400","10.81718","0.01471"
"130.15200","10.84612","0.01476"
"130.50000","10.87524","0.01478"
"130.84800","10.90418","0.01503"
"131.19600","10.93317","0.01509"
"131.54400","10.96217","0.01467"
"131.89200","10.99117","0.01501"
"132.24000","11.02023","0.01539"
"132.58800","11.04917","0.01485"
"132.93600","11.07816","0.01463"
"133.28400","11.10716","0.01486"
"133.63200","11.13616","0.01487"
"133.98000","11.16510","0.01490"
"134.32800","11.19421","0.01452"
"134.67600","11.22321","0.01528"
"135.02400","11.25221","0.01530"
"135.37200","11.28121","0.01523"
"135.72000","11.31015","0.01536"
"136.06800","11.33921","0.01558"
"136.41600","11.36820","0.01532"
"136.76400","11.39714","0.01523"
"137.11200","11.42620","0.01544"
"137.46000","11.45520","0.01535"
"137.80800","11.48419","0.01511"
"138.15600","11.51319","0.01543"
"138.50400","11.54219","0.01582"
"138.85200","11.57113","0.01559"
"139.20000","11.60019","0.01564"
"139.54800","11.62924","0.01576"
"139.89600","11.65812","0.01566"
"140.24400","11.68724","0.01523"
"140.59200","11.71624","0.01538"
"140.94000","11.74518","0.01553"
"141.28800","11.77423","0.01564"
"141.63600","11.80311","0.01573"
"141.98400","11.83217","0.01587"
"142.33200","11.86123","0.01546"
"142.68000","11.89017","0.01546"
"143.02800","11.91916","0.01530"
"143.37600","11.94816","0.01512"
"143.72400","11.97716","0.01513"
"144.07200","12.00616","0.01533"
"144.42000","12.03522","0.01555"
"144.76800","12.06409","0.01535"
"145.11600","12.09327","0.01570"
"145.46400","12.12221","0.01584"
"145.81200","12.15115","0.01536"
"146.16000","12.18020","0.01490"
"146.50800","12.20920","0.01527"
"146.85600","12.23814","0.01492"
"147.20400","12.26720","0.01502"
"147.55200","12.29620","0.01523"
"147.90000","12.32513","0.01517"
"148.24800","12.35419","0.01508"
"148.59600","12.38319","0.01516"
"148.94400","12.41219","0.01560"
"149.29200","12.44125","0.01546"
"149.64000","12.47012","0.01543"
"149.98800","12.49924","0.01506"
"150.33600","12.52824","0.01517"
"150.68400","12.55712","0.01425"
"151.03200","12.58623","0.01407"
"151.38000","12.61517","0.01432"
"151.72800","12.64417","0.01418"
"152.07600","12.67323","0.01472"
"152.42400","12.70217","0.01427"
"152.77200","12.73117","0.01441"
"153.12000","12.76016","0.01419"
"153.46800","12.78922","0.01472"
"153.81600","12.81822","0.01413"
"154.16400","12.84722","0.01439"
"154.51200","12.87621","0.01429"
"154.86000","12.90521","0.01498"
"155.20800","12.93421","0.01455"
"155.55600","12.96315","0.01448"
"155.90400","12.99221","0.01466"
"156.25200","13.02120","0.01444"
"156.60000","13.05020","0.01446"
"156.94800","13.07920","0.01425"
"157.29600","13.10820","0.01413"
"157.64400","13.13714","0.01431"
"157.99200","13.16619","0.01453"
"158.34000","13.19519","0.01459"
"158.68800","13.22419","0.01478"
"159.03600","13.25319","0.01426"
"159.38400","13.28219","0.01410"
"159.73200","13.31112","0.01444"
"160.08000","13.34024","0.01413"
"160.42800","13.36918","0.01395"
"160.77600","13.39824","0.01408"
"161.12400","13.42718","0.01388"
"161.47200","13.45617","0.01405"
"161.82000","13.48517","0.01429"
"162.16800","13.51417","0.01409"
"162.51600","13.54317","0.01410"
"162.86400","13.57216","0.01440"
"163.21200","13.60122","0.01440"
"163.56000","13.63016","0.01432"
"163.90800","13.65922","0.01494"
"164.25600","13.68816","0.01453"
"164.60400","13.71709","0.01430"
"164.95200","13.74627","0.01444"
"165.30000","13.77521","0.01455"
"165.64800","13.80415","0.01437"
"165.99600","13.83321","0.01458"
"166.34400","13.86220","0.01431"
"166.69200","13.89120","0.01450"
"167.04000","13.92020","0.01463"
"167.38800","13.94920","0.01453"
"167.73600","13.97819","0.01451"
"168.08400","14.00719","0.01457"
"168.43200","14.03613","0.01445"
"168.78000","14.06519","0.01479"
"169.12800","14.09419","0.01435"
"169.47600","14.12313","0.01508"
"169.82400","14.15218","0.01436"
"170.17200","14.18118","0.01439"
"170.52000","14.21024","0.01474"
"170.86800","14.23924","0.01448"
"171.21600","14.26817","0.01461"
"171.56400","14.29717","0.01466"
"171.91200","14.32617","0.01472"
"172.26000","14.35517","0.01501"
"172.60800","14.38411","0.01496"
"172.95600","14.41322","0.01495"
"173.30400","14.44216","0.01463"
"173.65200","14.47116","0.01459"
"174.00000","14.50022","0.01415"
"174.34800","14.52910","0.01358"
"174.69600","14.55821","0.01393"
"175.04400","14.58721","0.01378"
"175.39200","14.61615","0.01333"
"175.74000","14.64521","0.01298"
"176.08800","14.67415","0.01342"
"176.43600","14.70314","0.01317"
"176.78400","14.73220","0.01295"
"177.13200","14.76120","0.01338"
"177.48000","14.79014","0.01269"
"177.82800","14.81920","0.01269"
"178.17600","14.84819","0.01274"
"178.52400","14.87719","0.01287"
"178.87200","14.90619","0.01284"
"179.22000","14.93513","0.01297"
"179.56800","14.96424","0.01292"
"179.91600","14.99318","0.01286"
"180.26400","15.02212","0.01293"
"180.61200","15.05118","0.01292"
"180.96000","15.08018","0.01309"
"181.30800","15.10917","0.01275"
"181.65600","15.13817","0.01286"
"182.00400","15.16723","0.01282"
"182.35200","15.19617","0.01283"
"182.70000","15.22517","0.01307"
"183.04800","15.25416","0.01283"
"183.39600","15.28316","0.01274"
"183.74400","15.31222","0.01284"
"184.09200","15.34116","0.01327"
"184.44000","15.37022","0.01317"
"184.78800","15.39921","0.01323"
"185.13600","15.42815","0.01278"
"185.48400","15.45721","0.01307"
"185.83200","15.48621","0.01297"
"186.18000","15.51515","0.01342"
"186.52800","15.54426","0.01201"
"186.87600","15.57320","0.01339"
"187.22400","15.60214","0.01315"
"187.57200","15.63120","0.01350"
"187.92000","15.66019","0.01345"
"188.26800","15.68919","0.01345"
"188.61600","15.71825","0.01382"
"188.96400","15.74719","0.01369"
"189.31200","15.77619","0.01372"
"189.66000","15.80518","0.01312"
"190.00800","15.83418","0.01205"
"190.35600","15.86324","0.01114"
"190.70400","15.89218","0.01165"
"191.05200","15.92118","0.01110"
"191.40000","15.95017","0.01150"
"191.74800","15.97917","0.01192"
"192.09600","16.00811","0.01159"
"192.44400","16.03723","0.01179"
"192.79200","16.06623","0.01150"
"193.14000","16.09516","0.01139"
"193.48800","16.12422","0.01150"
"193.83600","16.15316","0.01146"
"194.18400","16.18216","0.01168"
"194.53200","16.21121","0.01147"
"194.88000","16.24015","0.01137"
"195.22800","16.26921","0.01175"
"195.57600","16.29815","0.01194"
"195.92400","16.32715","0.01140"
"196.27200","16.35620","0.01201"
"196.62000","16.38526","0.01169"
"196.96800","16.41414","0.01183"
"197.31600","16.44320","0.01163"
"197.66400","16.47226","0.01147"
"198.01200","16.50119","0.01172"
"198.36000","16.53019","0.01169"
"198.70800","16.55919","0.01162"
"199.05600","16.58813","0.01161"
"199.40400","16.61724","0.01200"
"199.75200","16.64624","0.01181"
"200.10000","16.67518","0.01147"
"200.44800","16.70418","0.01178"
"200.79600","16.73324","0.01153"
"201.14400","16.76217","0.01174"
"201.49200","16.79123","0.01186"
"201.84000","16.82017","0.01193"
"202.18800","16.84917","0.01178"
"202.53600","16.87823","0.01156"
"202.88400","16.90710","0.01174"
"203.23200","16.93622","0.01160"
"203.58000","16.96522","0.01178"
"203.92800","16.99416","0.01175"
"204.27600","17.02321","0.01173"
"204.62400","17.05215","0.01169"
"204.97200","17.08121","0.01171"
"205.32000","17.11021","0.01176"
"205.66800","17.13921","0.01207"
"206.01600","17.16821","0.01217"
"206.36400","17.19714","0.01230"
"206.71200","17.22614","0.01218"
"207.06000","17.25514","0.01205"
"207.40800","17.28420","0.01216"
"207.75600","17.31320","0.01214"
"208.10400","17.34219","0.01164"
"208.45200","17.37119","0.01221"
"208.80000","17.40013","0.01180"
"209.14800","17.42925","0.01228"
"209.49600","17.45824","0.01205"
"209.84400","17.48718","0.01198"
"210.19200","17.51618","0.01222"
"210.54000","17.54518","0.01195"
"210.88800","17.57412","0.01241"
"211.23600","17.60323","0.01233"
"211.58400","17.63223","0.01209"
"211.93200","17.66117","0.01216"
"212.28000","17.69029","0.01245"
"212.62800","17.71917","0.01245"
"212.97600","17.74816","0.01241"
"213.32400","17.77722","0.01239"
"213.67200","17.80616","0.01216"
"214.02000","17.83522","0.01197"
"214.36800","17.86422","0.01231"
"214.71600","17.89315","0.01236"
"215.06400","17.92221","0.01256"
"215.41200","17.95115","0.01239"
"215.76000","17.98015","0.01237"
"216.10800","18.00920","0.01226"
"216.45600","18.03820","0.01263"
"216.80400","18.06714","0.01255"
"217.15200","18.09620","0.01244"
"217.50000","18.12514","0.01246"
"217.84800","18.15413","0.01222"
"218.19600","18.18319","0.01254"
"218.54400","18.21213","0.01257"
"218.89200","18.24119","0.01267"
"219.24000","18.27019","0.01248"
"219.58800","18.29918","0.01272"
"219.93600","18.32818","0.01270"
"220.28400","18.35718","0.01284"
"220.63200","18.38618","0.01249"
"220.98000","18.41517","0.01284"
"221.32800","18.44423","0.01239"
"221.67600","18.47311","0.01260"
"222.02400","18.50223","0.01309"
"222.37200","18.53123","0.01326"
"222.72000","18.56017","0.01265"
"223.06800","18.58922","0.01302"
"223.41600","18.61816","0.01318"
"223.76400","18.64716","0.01294"
"224.11200","18.67622","0.01306"
"224.46000","18.70516","0.01307"
"224.80800","18.73415","0.01269"
"225.15600","18.76315","0.01328"
"225.50400","18.79215","0.01289"
"225.85200","18.82115","0.01298"
"226.20000","18.85021","0.01277"
"226.54800","18.87914","0.01286"
"226.89600","18.90820","0.01329"
"227.24400","18.93720","0.01291"
"227.59200","18.96614","0.01321"
"227.94000","18.99519","0.01295"
"228.28800","19.02419","0.01308"
"228.63600","19.05319","0.01309"
"228.98400","19.08219","0.01316"
"229.33200","19.11119","0.01305"
"229.68000","19.14013","0.01337"
"230.02800","19.16912","0.01206"
"230.37600","19.19818","0.01193"
"230.72400","19.22718","0.01221"
"231.07200","19.25624","0.01194"
"231.42000","19.28517","0.01250"
"231.76800","19.31417","0.01182"
"232.11600","19.34323","0.01196"
"232.46400","19.37211","0.01199"
"232.81200","19.40123","0.01203"
"233.16000","19.43016","0.01093"
"233.50800","19.45916","0.01155"
"233.85600","19.48822","0.01113"
"234.20400","19.51722","0.01170"
"234.55200","19.54615","0.01146"
"234.90000","19.57521","0.01126"
"235.24800","19.60421","0.01151"
"235.59600","19.63321","0.01173"
"235.94400","19.66220","0.01177"
"236.29200","19.69114","0.01156"
"236.64000","19.72014","0.01148"
"236.98800","19.74920","0.01173"
"237.33600","19.77808","0.01155"
"237.68400","19.80726","0.01136"
"238.03200","19.83619","0.01120"
"238.38000","19.86513","0.01146"
"238.72800","19.89419","0.01135"
"239.07600","19.92319","0.01116"
"239.42400","19.95218","0.01150"
"239.77200","19.98125","0.01145"
"240.12000","20.01024","0.01160"
"240.46800","20.03918","0.01120"
"240.81600","20.06818","0.01160"
"241.16400","20.09718","0.01174"
"241.51200","20.12617","0.01136"
"241.86000","20.15523","0.01141"
"242.20800","20.18417","0.01177"
"242.55600","20.21323","0.01127"
"242.90400","20.24217","0.01139"
"243.25200","20.27116","0.01126"
"243.60000","20.30022","0.01131"
"243.94800","20.32922","0.01119"
"244.29600","20.35815","0.01128"
"244.64400","20.38721","0.01158"
"244.99200","20.41615","0.01128"
"245.34000","20.44515","0.01131"
"245.68800","20.47421","0.01147"
"246.03600","20.50321","0.01159"
"246.38400","20.53214","0.01134"
"246.73200","20.56120","0.01163"
"247.08000","20.59020","0.01165"
"247.42800","20.61920","0.01111"
"247.77600","20.64820","0.01171"
"248.12400","20.67713","0.01166"
"248.47200","20.70619","0.01182"
"248.82000","20.73519","0.01108"
"249.16800","20.76419","0.01158"
"249.51600","20.79313","0.01162"
"249.86400","20.82224","0.01142"
"250.21200","20.85118","0.01148"
"250.56000","20.88018","0.01163"
"250.90800","20.90918","0.01169"
"251.25600","20.93812","0.01147"
"251.60400","20.96723","0.01160"
"251.95200","20.99617","0.01166"
"252.30000","21.02517","0.01160"
"252.64800","21.05423","0.01146"
"252.99600","21.08316","0.01164"
"253.34400","21.11216","0.01172"
"253.69200","21.14116","0.01143"
"254.04000","21.17022","0.01190"
"254.38800","21.19916","0.01142"
"254.73600","21.22821","0.01128"
"255.08400","21.25715","0.01153"
"255.43200","21.28621","0.01144"
"255.78000","21.31521","0.01132"
"256.12800","21.34409","0.01110"
"256.47600","21.37320","0.01151"
"256.82400","21.40220","0.01158"
"257.17200","21.43120","0.01157"
"257.52000","21.46020","0.01153"
"257.86800","21.48913","0.01143"
"258.21600","21.51819","0.01166"
"258.56400","21.54719","0.01148"
"258.91200","21.57619","0.01133"
"259.26000","21.60513","0.01156"
"259.60800","21.63419","0.01153"
"259.95600","21.66318","0.01128"
"260.30400","21.69218","0.01109"
"260.65200","21.72124","0.01163"
"261.00000","21.75012","0.01163"
"261.34800","21.77924","0.01133"
"261.69600","21.80823","0.01154"
"262.04400","21.83711","0.01130"
"262.39200","21.86623","0.01110"
"262.74000","21.89517","0.01152"
"263.08800","21.92416","0.01153"
"263.43600","21.95322","0.01152"
"263.78400","21.98216","0.01116"
"264.13200","22.01116","0.01166"
"264.48000","22.04016","0.01178"
"264.82800","22.06915","0.01182"
"265.17600","22.09815","0.01181"
"265.52400","22.12721","0.01176"
"265.87200","22.15615","0.01167"
"266.22000","22.18521","0.01144"
"266.56800","22.21420","0.01162"
"266.91600","22.24314","0.01162"
"267.26400","22.27220","0.01141"
"267.61200","22.30120","0.01145"
"267.96000","22.33014","0.01130"
"268.30800","22.35925","0.01143"
"268.65600","22.38819","0.01166"
"269.00400","22.41713","0.01161"
"269.35200","22.44619","0.01209"
"269.70000","22.47518","0.01156"
"270.04800","22.50418","0.01155"
"270.39600","22.53324","0.01151"
"270.74400","22.56212","0.01147"
"271.09200","22.59118","0.01189"
"271.44000","22.62017","0.01161"
"271.78800","22.64917","0.01148"
"272.13600","22.67817","0.01169"
"272.48400","22.70717","0.01113"
"272.83200","22.73617","0.01155"
"273.18000","22.76522","0.01138"
"273.52800","22.79422","0.01145"
"273.87600","22.82316","0.01158"
"274.22400","22.85216","0.01156"
"274.57200","22.88122","0.01156"
"274.92000","22.91015","0.01195"
"275.26800","22.93921","0.01166"
"275.61600","22.96821","0.01178"
"275.96400","22.99715","0.01167"
"276.31200","23.02621","0.01151"
"276.66000","23.05514","0.01148"
"277.00800","23.08414","0.01163"
"277.35600","23.11320","0.01156"
"277.70400","23.14220","0.01148"
"278.05200","23.17120","0.01159"
"278.40000","23.20019","0.01170"
"278.74800","23.22913","0.01176"
"279.09600","23.25819","0.01128"
"279.44400","23.28718","0.01190"
"279.79200","23.31618","0.01172"
"280.14000","23.34524","0.01159"
"280.48800","23.37418","0.01198"
"280.83600","23.40318","0.01197"
"281.18400","23.43218","0.01192"
"281.53200","23.46111","0.01161"
"281.88000","23.49017","0.01162"
"282.22800","23.51917","0.01181"
"282.57600","23.54817","0.01161"
"282.92400","23.57722","0.01164"
"283.27200","23.60622","0.01164"
"283.62000","23.63516","0.01192"
"283.96800","23.66410","0.01161"
"284.31600","23.69328","0.01185"
"284.66400","23.72215","0.01178"
"285.01200","23.75121","0.01188"
"285.36000","23.78021","0.01169"
"285.70800","23.80915","0.01201"
"286.05600","23.83821","0.01167"
"286.40400","23.86720","0.01174"
"286.75200","23.89614","0.01169"
"287.10000","23.92520","0.01199"
"287.44800","23.95414","0.01174"
"287.79600","23.98320","0.01199"
"288.14400","24.01220","0.01177"
"288.49200","24.04119","0.01193"
"288.84000","24.07019","0.01192"
"289.18800","24.09925","0.01166"
"289.53600","24.12813","0.01185"
"289.88400","24.15718","0.01158"
"290.23200","24.18618","0.01151"
"290.58000","24.21512","0.01177"
"290.92800","24.24424","0.01167"
"291.27600","24.27324","0.01190"
"291.62400","24.30217","0.01196"
"291.97200","24.33117","0.01169"
"292.32000","24.36017","0.01189"
"292.66800","24.38917","0.01150"
"293.01600","24.41823","0.01169"
"293.36400","24.44722","0.01148"
"293.71200","24.47610","0.01159"
"294.06000","24.50522","0.01158"
"294.40800","24.53416","0.01147"
"294.75600","24.56316","0.01168"
"295.10400","24.59221","0.01159"
"295.45200","24.62115","0.01200"
"295.80000","24.65021","0.01122"
"296.14800","24.67921","0.01200"
"296.49600","24.70815","0.01155"
"296.84400","24.73720","0.01169"
"297.19200","24.76620","0.01178"
"297.54000","24.79514","0.01117"
"297.88800","24.82420","0.01164"
"298.23600","24.85319","0.01142"
"298.58400","24.88213","0.01132"
"298.93200","24.91119","0.01121"
"299.28000","24.94019","0.01142"
"299.62800","24.96919","0.01124"
"299.97600","24.99818","0.01134"
"300.32400","25.02718","0.01157"
"300.67200","25.05618","0.01151"
"301.02000","25.08517","0.01151"
"301.36800","25.11411","0.01149"
"301.71600","25.14318","0.01144"
"302.06400","25.17217","0.01156"
"302.41200","25.20117","0.01153"
"302.76000","25.23023","0.01121"
"303.10800","25.25922","0.01147"
"303.45600","25.28816","0.01125"
"303.80400","25.31722","0.01138"
"304.15200","25.34616","0.01130"
"304.50000","25.37516","0.01165"
"304.84800","25.40421","0.01149"
"305.19600","25.43315","0.01161"
"305.54400","25.46215","0.01129"
"305.89200","25.49121","0.01128"
"306.24000","25.52015","0.01127"
"306.58800","25.54921","0.01154"
"306.93600","25.57814","0.01186"
"307.28400","25.60720","0.01175"
"307.63200","25.63620","0.01157"
"307.98000","25.66519","0.01154"
"308.32800","25.69413","0.01124"
"308.67600","25.72319","0.01127"
"309.02400","25.75219","0.01140"
"309.37200","25.78119","0.01104"
"309.72000","25.81025","0.01124"
"310.06800","25.83918","0.01115"
"310.41600","25.86812","0.01137"
"310.76400","25.89718","0.01152"
"311.11200","25.92618","0.01134"
"311.46000","25.95518","0.01136"
"311.80800","25.98423","0.01157"
"312.15600","26.01317","0.01129"
"312.50400","26.04217","0.01120"
"312.85200","26.07122","0.01136"
"313.20000","26.10017","0.01102"
"313.54800","26.12922","0.01161"
"313.89600","26.15822","0.01165"
"314.24400","26.18710","0.01124"
"314.59200","26.21627","0.01176"
"314.94000","26.24516","0.01162"
"315.28800","26.27415","0.01154"
"315.63600","26.30321","0.01151"
"315.98400","26.33221","0.01140"
"316.33200","26.36121","0.01163"
"316.68000","26.39014","0.01144"
"317.02800","26.41920","0.01130"
"317.37600","26.44820","0.01176"
"317.72400","26.47714","0.01161"
"318.07200","26.50620","0.01171"
"318.42000","26.53513","0.01154"
"318.76800","26.56425","0.01148"
"319.11600","26.59319","0.01132"
"319.46400","26.62219","0.01136"
"319.81200","26.65125","0.01144"
"320.16000","26.68012","0.01141"
"320.50800","26.70918","0.01157"
"320.85600","26.73818","0.01149"
"321.20400","26.76718","0.01184"
"321.55200","26.79623","0.01154"
"321.90000","26.82523","0.01162"
"322.24800","26.85417","0.01178"
"322.59600","26.88323","0.01170"
"322.94400","26.91217","0.01144"
"323.29200","26.94117","0.01168"
"323.64000","26.97022","0.01164"
"323.98800","26.99916","0.01175"
"324.33600","27.02822","0.01183"
"324.68400","27.05716","0.01154"
"325.03200","27.08609","0.01177"
"325.38000","27.11521","0.01141"
"325.72800","27.14415","0.01177"
"326.07600","27.17321","0.01208"
"326.42400","27.20220","0.01160"
"326.77200","27.23120","0.01190"
"327.12000","27.26020","0.01231"
"327.46800","27.28920","0.01146"
"327.81600","27.31820","0.01178"
"328.16400","27.34713","0.01140"
"328.51200","27.37619","0.01144"
"328.86000","27.40519","0.01201"
"329.20800","27.43419","0.01151"
"329.55600","27.46325","0.01148"
"329.90400","27.49212","0.01175"
"330.25200","27.52124","0.01168"
"330.60000","27.55018","0.01176"
"330.94800","27.57918","0.01235"
"331.29600","27.60818","0.01191"
"331.64400","27.63717","0.01191"
"331.99200","27.66617","0.01210"
"332.34000","27.69517","0.01205"
"332.68800","27.72417","0.01199"
"333.03600","27.75317","0.01244"
"333.38400","27.78222","0.01197"
"333.73200","27.81116","0.01213"
"334.08000","27.84016","0.01196"
"334.42800","27.86916","0.01217"
"334.77600","27.89816","0.01215"
"335.12400","27.92721","0.01199"
"335.47200","27.95621","0.01190"
"335.82000","27.98515","0.01081"
"336.16800","28.01414","0.01085"
"336.51600","28.04320","0.01036"
"336.86400","28.07214","0.01071"
"337.21200","28.10120","0.01038"
"337.56000","28.13026","0.01055"
"337.90800","28.15908","0.01060"
"338.25600","28.18819","0.01079"
"338.60400","28.21719","0.01057"
"338.95200","28.24613","0.01071"
"339.30000","28.27525","0.01079"
"339.64800","28.30419","0.01043"
"339.99600","28.33318","0.01053"
"340.34400","28.36224","0.01074"
"340.69200","28.39118","0.01059"
"341.04000","28.42018","0.01067"
"341.38800","28.44918","0.01077"
"341.73600","28.47818","0.01081"
"342.08400","28.50717","0.01049"
"342.43200","28.53629","0.01046"
"342.78000","28.56511","0.01047"
"343.12800","28.59422","0.01036"
"343.47600","28.62322","0.01060"
"343.82400","28.65216","0.01082"
"344.17200","28.68116","0.01072"
"344.52000","28.71016","0.01069"
"344.86800","28.73922","0.01050"
"345.21600","28.76821","0.01048"
"345.56400","28.79721","0.01080"
"345.91200","28.82621","0.01066"
"346.26000","28.85515","0.01066"
"346.60800","28.88421","0.01065"
"346.95600","28.91314","0.01080"
"347.30400","28.94220","0.01061"
"347.65200","28.97114","0.01060"
"348.00000","29.00019","0.01072"
"348.34800","29.02919","0.01039"
"348.69600","29.05807","0.01060"
"349.04400","29.08725","0.01088"
"349.39200","29.11625","0.01073"
"349.74000","29.14519","0.01069"
"350.08800","29.17424","0.01049"
"350.43600","29.20318","0.01071"
"350.78400","29.23212","0.01078"
"351.13200","29.26118","0.01063"
"351.48000","29.29018","0.01081"
"351.82800","29.31923","0.01087"
"352.17600","29.34823","0.01048"
"352.52400","29.37717","0.01069"
"352.87200","29.40617","0.01061"
"353.22000","29.43517","0.01064"
"353.56800","29.46410","0.01068"
"353.91600","29.49322","0.01038"
"354.26400","29.52222","0.01055"
"354.61200","29.55116","0.01055"
"354.96000","29.58021","0.01047"
"355.30800","29.60921","0.01060"
"355.65600","29.63815","0.01069"
"356.00400","29.66721","0.01034"
"356.35200","29.69621","0.01074"
"356.70000","29.72520","0.01033"
"357.04800","29.75420","0.01057"
"357.39600","29.78314","0.01090"
"357.74400","29.81214","0.01133"
"358.09200","29.84126","0.01036"
"358.44000","29.87013","0.01071"
"358.78800","29.89919","0.01110"
"359.13600","29.92813","0.01078"
"359.48400","29.95713","0.01051"
"359.83200","29.98618","0.01073"
"360.18000","30.01518","0.01113"
"360.52800","30.04418","0.01102"
"360.87600","30.07324","0.01052"
"361.22400","30.10218","0.01080"
"361.57200","30.13112","0.01033"
"361.92000","30.16017","0.01072"
"362.26800","30.18917","0.01033"
"362.61600","30.21817","0.01095"
"362.96400","30.24723","0.01080"
"363.31200","30.27623","0.01055"
"363.66000","30.30516","0.01057"
"364.00800","30.33416","0.01072"
"364.35600","30.36316","0.01047"
"364.70400","30.39221","0.01077"
"365.05200","30.42122","0.01064"
"365.40000","30.45021","0.01057"
"365.74800","30.47915","0.01067"
"366.09600","30.50821","0.01044"
"366.44400","30.53709","0.01064"
"366.79200","30.56620","0.01091"
"367.14000","30.59520","0.01048"
"367.48800","30.62414","0.01037"
"367.83600","30.65326","0.01067"
"368.18400","30.68220","0.01032"
"368.53200","30.71113","0.01118"
"368.88000","30.74019","0.01084"
"369.22800","30.76913","0.01046"
"369.57600","30.79825","0.01048"
"369.92400","30.82719","0.01052"
"370.27200","30.85618","0.01065"
"370.62000","30.88512","0.01067"
"370.96800","30.91424","0.01076"
"371.31600","30.94318","0.01074"
"371.66400","30.97223","0.01082"
"372.01200","31.00123","0.01050"
"372.36000","31.03017","0.01060"
"372.70800","31.05917","0.01063"
"373.05600","31.08823","0.01061"
"373.40400","31.11716","0.01080"
"373.75200","31.14622","0.01051"
"374.10000","31.17516","0.01061"
"374.44800","31.20416","0.01098"
"374.79600","31.23316","0.01052"
"375.14400","31.26221","0.01059"
"375.49200","31.29115","0.01094"
"375.84000","31.32021","0.01080"
"376.18800","31.34914","0.01036"
"376.53600","31.37820","0.01079"
"376.88400","31.40720","0.01054"
"377.23200","31.43608","0.01030"
"377.58000","31.46520","0.01084"
"377.92800","31.49420","0.01086"
"378.27600","31.52319","0.01077"
"378.62400","31.55219","0.01063"
"378.97200","31.58119","0.01084"
"379.32000","31.61019","0.01045"
"379.66800","31.63924","0.01087"
"380.01600","31.66818","0.01059"
"380.36400","31.69718","0.01099"
"380.71200","31.72618","0.01072"
"381.06000","31.75517","0.01038"
"381.40800","31.78411","0.01091"
"381.75600","31.81323","0.01074"
"382.10400","31.84211","0.01071"
"382.45200","31.87123","0.01054"
"382.80000","31.90017","0.01100"
"383.14800","31.92911","0.01047"
"383.49600","31.95822","0.01073"
"383.84400","31.98722","0.01070"
"384.19200","32.01616","0.01068"
"384.54000","32.04528","0.01091"
"384.88800","32.07421","0.01076"
"385.23600","32.10315","0.01053"
"385.58400","32.13215","0.01063"
"385.93200","32.16115","0.01055"
"386.28000","32.19014","0.01050"
"386.62800","32.21920","0.01046"
"386.97600","32.24814","0.01083"
"387.32400","32.27714","0.01081"
"387.67200","32.30620","0.01081"
"388.02000","32.33520","0.01071"
"388.36800","32.36419","0.01073"
"388.71600","32.39319","0.01087"
"389.06400","32.42213","0.01065"
"389.41200","32.45119","0.01061"
"389.76000","32.48018","0.01073"
"390.10800","32.50918","0.01083"
"390.45600","32.53818","0.01070"
"390.80400","32.56724","0.01076"
"391.15200","32.59618","0.01094"
"391.50000","32.62524","0.01084"
"391.84800","32.65411","0.01048"
"392.19600","32.68317","0.01102"
"392.54400","32.71223","0.01071"
"392.89200","32.74117","0.01091"
"393.24000","32.77016","0.01057"
"393.58800","32.79922","0.01082"
"393.93600","32.82816","0.01080"
"394.28400","32.85716","0.01068"
"394.63200","32.88622","0.01101"
"394.98000","32.91521","0.01061"
"395.32800","32.94415","0.01080"
"395.67600","32.97321","0.01075"
"396.02400","33.00215","0.01074"
"396.37200","33.03121","0.01082"
"396.72000","33.06020","0.01070"
"397.06800","33.08914","0.01058"
"397.41600","33.11820","0.01074"
"397.76400","33.14714","0.01056"
"398.11200","33.17619","0.01081"
"398.46000","33.20519","0.01082"
"398.80800","33.23419","0.01086"
"399.15600","33.26319","0.01111"
"399.50400","33.29219","0.01048"
"399.85200","33.32113","0.01047"
"400.20000","33.35012","0.01089"
"400.54800","33.37918","0.01077"
"400.89600","33.40818","0.01112"
"401.24400","33.43724","0.01052"
"401.59200","33.46618","0.01099"
"401.94000","33.49511","0.01122"
"402.28800","33.52423","0.01082"
"402.63600","33.55317","0.01098"
"402.98400","33.58223","0.01086"
"403.33200","33.61122","0.01103"
"403.68000","33.64016","0.01092"
"404.02800","33.66916","0.01090"
"404.37600","33.69816","0.01099"
"404.72400","33.72715","0.01049"
"405.07200","33.75609","0.01071"
"405.42000","33.78527","0.01067"
"405.76800","33.81415","0.01073"
"406.11600","33.84321","0.01096"
"406.46400","33.87221","0.01077"
"406.81200","33.90108","0.01045"
"407.16000","33.93026","0.01082"
"407.50800","33.95920","0.01083"
"407.85600","33.98814","0.01054"
"408.20400","34.01719","0.01089"
"408.55200","34.04619","0.01098"
"408.90000","34.07513","0.01080"
"409.24800","34.10419","0.01057"
"409.59600","34.13319","0.01066"
"409.94400","34.16219","0.01052"
"410.29200","34.19124","0.01025"
"410.64000","34.22018","0.01049"
"410.98800","34.24918","0.01093"
"411.33600","34.27824","0.01074"
"411.68400","34.30711","0.01104"
"412.03200","34.33623","0.01081"
"412.38000","34.36523","0.01102"
"412.72800","34.39417","0.01081"
"413.07600","34.42316","0.01085"
"413.42400","34.45216","0.01082"
"413.77200","34.48116","0.01063"
"414.12000","34.51022","0.01104"
"414.46800","34.53922","0.01066"
"414.81600","34.56816","0.01080"
"415.16400","34.59721","0.01078"
"415.51200","34.62621","0.01099"
"415.86000","34.65515","0.01048"
"416.20800","34.68421","0.01094"
"416.55600","34.71315","0.01066"
"416.90400","34.74220","0.01066"
"417.25200","34.77114","0.01059"
"417.60000","34.80014","0.01056"
"417.94800","34.82920","0.01099"
"418.29600","34.85819","0.01087"
"418.64400","34.88719","0.01057"
"418.99200","34.91619","0.01039"
"419.34000","34.94519","0.01083"
"419.68800","34.97413","0.01051"
"420.03600","35.00319","0.01129"
"420.38400","35.03218","0.01059"
"420.73200","35.06118","0.01080"
"421.08000","35.09024","0.01017"
"421.42800","35.11917","0.01078"
"421.77600","35.14817","0.01089"
"422.12400","35.17717","0.01078"
"422.47200","35.20617","0.01082"
"422.82000","35.23517","0.01055"
"423.16800","35.26416","0.01075"
"423.51600","35.29316","0.01073"
"423.86400","35.32216","0.01104"
"424.21200","35.35122","0.01091"
"424.56000","35.38010","0.01067"
"424.90800","35.40921","0.01091"
"425.25600","35.43821","0.01087"
"425.60400","35.46715","0.01111"
"425.95200","35.49621","0.01075"
"426.30000","35.52515","0.01054"
"426.64800","35.55420","0.01090"
"426.99600","35.58320","0.01095"
"427.34400","35.61220","0.01066"
"427.69200","35.64114","0.01090"
"428.04000","35.67014","0.01061"
"428.38800","35.69919","0.01102"
"428.73600","35.72820","0.01072"
"429.08400","35.75719","0.01100"
"429.43200","35.78619","0.01064"
"429.78000","35.81519","0.01085"
"430.12800","35.84425","0.01081"
"430.47600","35.87312","0.01056"
"430.82400","35.90218","0.01089"
"431.17200","35.93118","0.01033"
"431.52000","35.96012","0.01087"
"431.86800","35.98923","0.01045"
"432.21600","36.01817","0.01040"
"432.56400","36.04717","0.01080"
"432.91200","36.07623","0.01089"
"433.26000","36.10516","0.01059"
"433.60800","36.13416","0.01057"
"433.95600","36.16322","0.01083"
"434.30400","36.19216","0.01052"
"434.65200","36.22116","0.01068"
"435.00000","36.25021","0.01083"
"435.34800","36.27909","0.01062"
"435.69600","36.30821","0.01059"
"436.04400","36.33715","0.01054"
"436.39200","36.36615","0.01086"
"436.74000","36.39520","0.01068"
"437.08800","36.42420","0.01057"
"437.43600","36.45314","0.01092"
"437.78400","36.48220","0.01071"
"438.13200","36.51120","0.01043"
"438.48000","36.54020","0.01114"
"438.82800","36.56919","0.01077"
"439.17600","36.59819","0.01067"
"439.52400","36.62713","0.01097"
"439.87200","36.65625","0.01124"
"440.22000","36.68518","0.01072"
"440.56800","36.71418","0.01097"
"440.91600","36.74324","0.01039"
"441.26400","36.77212","0.01112"
"441.61200","36.80124","0.01089"
"441.96000","36.83023","0.01074"
"442.30800","36.85911","0.01078"
"442.65600","36.88823","0.01063"
"443.00400","36.91717","0.01084"
"443.35200","36.94611","0.01105"
"443.70000","36.97522","0.01081"
"444.04800","37.00416","0.01103"
"444.39600","37.03316","0.01081"
"444.74400","37.06222","0.01074"
"445.09200","37.09116","0.01109"
"445.44000","37.12021","0.01059"
"445.78800","37.14921","0.01080"
"446.13600","37.17815","0.01084"
"446.48400","37.20721","0.01070"
"446.83200","37.23614","0.01088"
"447.18000","37.26520","0.01073"
"447.52800","37.29420","0.01049"
"447.87600","37.32320","0.01054"
"448.22400","37.35220","0.01079"
"448.57200","37.38120","0.01084"
"448.92000","37.41019","0.01061"
"449.26800","37.43913","0.01115"
"449.61600","37.46819","0.01104"
"449.96400","37.49718","0.01051"
"450.31200","37.52618","0.01082"
"450.66000","37.55518","0.01090"
"451.00800","37.58412","0.01037"
"451.35600","37.61324","0.01084"
"451.70400","37.64217","0.01068"
"452.05200","37.67117","0.01018"
"452.40000","37.70017","0.01079"
"452.74800","37.72923","0.01083"
"453.09600","37.75817","0.01069"
"453.44400","37.78717","0.01072"
"453.79200","37.81622","0.01092"
"454.14000","37.84516","0.01074"
"454.48800","37.87422","0.01050"
"454.83600","37.90322","0.01050"
"455.18400","37.93216","0.01061"
"455.53200","37.96121","0.01085"
"455.88000","37.99015","0.01062"
"456.22800","38.01915","0.01103"
"456.57600","38.04820","0.01075"
"456.92400","38.07720","0.01099"
"457.27200","38.10614","0.01087"
"457.62000","38.13520","0.01088"
"457.96800","38.16414","0.01108"
"458.31600","38.19320","0.01071"
"458.66400","38.22225","0.01093"
"459.01200","38.25113","0.01105"
"459.36000","38.28025","0.01083"
"459.70800","38.30919","0.01039"
"460.05600","38.33812","0.01077"
"460.40400","38.36724","0.01077"
"460.75200","38.39618","0.01055"
"461.10000","38.42518","0.01059"
"461.44800","38.45424","0.01050"
"461.79600","38.48317","0.01047"
"462.14400","38.51217","0.01046"
"462.49200","38.54117","0.01052"
"462.84000","38.57017","0.01083"
"463.18800","38.59917","0.01065"
"463.53600","38.62822","0.01035"
"463.88400","38.65716","0.01042"
"464.23200","38.68616","0.01039"
"464.58000","38.71528","0.01059"
"464.92800","38.74416","0.01071"
"465.27600","38.77315","0.01070"
"465.62400","38.80221","0.01081"
"465.97200","38.83115","0.01082"
"466.32000","38.86021","0.01056"
"466.66800","38.88921","0.01055"
"467.01600","38.91814","0.01061"
"467.36400","38.94720","0.01058"
"467.71200","38.97620","0.01074"
"468.06000","39.00514","0.01099"
"468.40800","39.03419","0.01077"
"468.75600","39.06319","0.01054"
"469.10400","39.09219","0.01039"
"469.45200","39.12119","0.01064"
"469.80000","39.15018","0.01090"
"470.14800","39.17924","0.01066"
"470.49600","39.20818","0.01075"
"470.84400","39.23712","0.01067"
"471.19200","39.26618","0.01094"
"471.54000","39.29524","0.01102"
"471.88800","39.32417","0.01075"
"472.23600","39.35317","0.01081"
"472.58400","39.38223","0.01103"
"472.93200","39.41117","0.01086"
"473.28000","39.44017","0.01107"
"473.62800","39.46916","0.01080"
"473.97600","39.49810","0.01080"
"474.32400","39.52721","0.01085"
"474.67200","39.55616","0.01079"
"475.02000","39.58521","0.01082"
"475.36800","39.61421","0.01088"
"475.71600","39.64315","0.01101"
"476.06400","39.67221","0.01090"
"476.41200","39.70121","0.01078"
"476.76000","39.73015","0.01119"
"477.10800","39.75920","0.01105"
"477.45600","39.78820","0.01078"
"477.80400","39.81713","0.01084"
"478.15200","39.84626","0.01075"
"478.50000","39.87519","0.01072"
"478.84800","39.90419","0.01101"
"479.19600","39.93325","0.01100"
"479.54400","39.96219","0.01096"
"479.89200","39.99118","0.01095"
"480.24000","40.02012","0.01061"
"480.58800","40.04918","0.01059"
"480.93600","40.07818","0.01100"
"481.28400","40.10718","0.01055"
"481.63200","40.13624","0.01062"
"481.98000","40.16517","0.01062"
"482.32800","40.19423","0.01053"
"482.67600","40.22317","0.01082"
"483.02400","40.25223","0.01060"
"483.37200","40.28122","0.01060"
"483.72000","40.31010","0.01085"
"484.06800","40.33922","0.01077"
"484.41600","40.36822","0.01067"
"484.76400","40.39716","0.01092"
"485.11200","40.42621","0.01092"
"485.46000","40.45515","0.01062"
"485.80800","40.48421","0.01083"
"486.15600","40.51321","0.01065"
"486.50400","40.54215","0.01065"
"486.85200","40.57114","0.01047"
"487.20000","40.60020","0.01040"
"487.54800","40.62914","0.01066"
"487.89600","40.65820","0.01064"
"488.24400","40.68725","0.01068"
"488.59200","40.71613","0.01050"
"488.94000","40.74519","0.01067"
"489.28800","40.77419","0.01084"
"489.63600","40.80318","0.01068"
"489.98400","40.83218","0.01063"
"490.33200","40.86119","0.01070"
"490.68000","40.89018","0.01056"
"491.02800","40.91918","0.01083"
"491.37600","40.94824","0.01086"
"491.72400","40.97712","0.01081"
"492.07200","41.00617","0.01068"
"492.42000","41.03517","0.01044"
"492.76800","41.06417","0.01053"
"493.11600","41.09323","0.01082"
"493.46400","41.12210","0.01070"
"493.81200","41.15122","0.01062"
"494.16000","41.18022","0.01077"
"494.50800","41.20916","0.01065"
"494.85600","41.23822","0.01058"
"495.20400","41.26716","0.01090"
"495.55200","41.29615","0.01099"
"495.90000","41.32521","0.01070"
"496.24800","41.35415","0.01086"
"496.59600","41.38315","0.01071"
"496.94400","41.41220","0.01097"
"497.29200","41.44114","0.01079"
"497.64000","41.47014","0.01068"
"497.98800","41.49914","0.01059"
"498.33600","41.52814","0.01036"
"498.68400","41.55725","0.01089"
"499.03200","41.58619","0.01080"
"499.38000","41.61513","0.01048"
"499.72800","41.64413","0.01095"
"500.07600","41.67319","0.01105"
"500.42400","41.70219","0.01083"
"500.77200","41.73118","0.01115"
"501.12000","41.76018","0.01073"
"501.46800","41.78917","0.01048"
"501.81600","41.81823","0.01068"
"502.16400","41.84717","0.01076"
"502.51200","41.87617","0.01073"
"502.86000","41.90523","0.01038"
"503.20800","41.93416","0.01066"
"503.55600","41.96317","0.01082"
"503.90400","41.99216","0.01063"
"504.25200","42.02110","0.01047"
"504.60000","42.05022","0.01089"
"504.94800","42.07916","0.01084"
"505.29600","42.10815","0.01051"
"505.64400","42.13721","0.01090"
"505.99200","42.16621","0.01091"
"506.34000","42.19515","0.01074"
"506.68800","42.22415","0.01055"
"507.03600","42.25314","0.01057"
"507.38400","42.28214","0.01064"
"507.73200","42.31120","0.01049"
"508.08000","42.34014","0.01091"
"508.42800","42.36919","0.01075"
"508.77600","42.39819","0.01046"
"509.12400","42.42719","0.01042"
"509.47200","42.45619","0.01063"
"509.82000","42.48519","0.01068"
"510.16800","42.51419","0.01071"
"510.51600","42.54318","0.01049"
"510.86400","42.57218","0.01062"
"511.21200","42.60112","0.01055"
"511.56000","42.63018","0.01039"
"511.90800","42.65923","0.01092"
"512.25600","42.68811","0.01062"
"512.60400","42.71723","0.01091"
"512.95200","42.74616","0.01061"
"513.30000","42.77517","0.01069"
"513.64800","42.80422","0.01070"
"513.99600","42.83316","0.01084"
"514.34400","42.86216","0.01074"
"514.69200","42.89116","0.01042"
"515.04000","42.92015","0.01075"
"515.38800","42.94915","0.01069"
"515.73600","42.97821","0.01060"
"516.08400","43.00721","0.01064"
"516.43200","43.03615","0.01053"
"516.78000","43.06520","0.01070"
"517.12800","43.09414","0.01051"
"517.47600","43.12320","0.01035"
"517.82400","43.15220","0.01065"
"518.06200","43.17205","0.01067"