File: Force_trajectories/161218/Specimen_RawData_6.csv
End date,"12/18/2016"
Specimen label,"17AT_40"
Maximum Load,"0.55607",N

Time,Extension,Load
(s),(mm),(N)
"0.00000","0.00000","-0.00016"
"0.37200","0.03103","0.00021"
"0.74400","0.06212","0.00061"
"1.11600","0.09315","0.00070"
"1.48800","0.12418","0.00080"
"1.86000","0.15515","0.00108"
"2.23200","0.18612","0.00158"
"2.60400","0.21716","0.00182"
"2.97600","0.24819","0.00210"
"3.34800","0.27910","0.00232"
"3.72000","0.31019","0.00242"
"4.09200","0.34116","0.00271"
"4.46400","0.37207","0.00293"
"4.83600","0.40316","0.00348"
"5.20800","0.43413","0.00362"
"5.58000","0.46510","0.00344"
"5.95200","0.49607","0.00368"
"6.32400","0.52716","0.00428"
"6.69600","0.55814","0.00464"
"7.06800","0.58917","0.00426"
"7.44000","0.62014","0.00518"
"7.81200","0.65111","0.00515"
"8.18400","0.68208","0.00522"
"8.55600","0.71317","0.00596"
"8.92800","0.74414","0.00605"
"9.30000","0.77511","0.00604"
"9.67200","0.80608","0.00651"
"10.04400","0.83711","0.00633"
"10.41600","0.86808","0.00702"
"10.78800","0.89912","0.00746"
"11.16000","0.93015","0.00792"
"11.53200","0.96112","0.00815"
"11.90400","0.99209","0.00798"
"12.27600","1.02312","0.00885"
"12.64800","1.05415","0.00874"
"13.02000","1.08512","0.00946"
"13.39200","1.11609","0.01008"
"13.76400","1.14718","0.01022"
"14.13600","1.17809","0.01054"
"14.50800","1.20912","0.01087"
"14.88000","1.24015","0.01119"
"15.25200","1.27113","0.01155"
"15.62400","1.30216","0.01229"
"15.99600","1.33313","0.01253"
"16.36800","1.36410","0.01315"
"16.74000","1.39513","0.01310"
"17.11200","1.42616","0.01415"
"17.48400","1.45713","0.01410"
"17.85600","1.48810","0.01542"
"18.22800","1.51913","0.01575"
"18.60000","1.55016","0.01662"
"18.97200","1.58113","0.01666"
"19.34400","1.61216","0.01727"
"19.71600","1.64314","0.01785"
"20.08800","1.67411","0.01828"
"20.46000","1.70508","0.01892"
"20.83200","1.73611","0.01918"
"21.20400","1.76720","0.01961"
"21.57600","1.79811","0.01958"
"21.94800","1.82914","0.02033"
"22.32000","1.86011","0.02118"
"22.69200","1.89108","0.01964"
"23.06400","1.92217","0.01994"
"23.43600","1.95314","0.02105"
"23.80800","1.98412","0.02182"
"24.18000","2.01515","0.02140"
"24.55200","2.04612","0.02225"
"24.92400","2.07715","0.02243"
"25.29600","2.10812","0.02256"
"25.66800","2.13915","0.02308"
"26.04000","2.17012","0.02354"
"26.41200","2.20115","0.02342"
"26.78400","2.23218","0.02379"
"27.15600","2.26309","0.02382"
"27.52800","2.29412","0.02422"
"27.90000","2.32516","0.02455"
"28.27200","2.35619","0.02494"
"28.64400","2.38710","0.02506"
"29.01600","2.41813","0.02528"
"29.38800","2.44922","0.02563"
"29.76000","2.48007","0.02617"
"30.13200","2.51110","0.02608"
"30.50400","2.54213","0.02700"
"30.87600","2.57310","0.02698"
"31.24800","2.60413","0.02756"
"31.62000","2.63516","0.02856"
"31.99200","2.66613","0.02776"
"32.36400","2.69711","0.02855"
"32.73600","2.72814","0.02932"
"33.10800","2.75917","0.02912"
"33.48000","2.79008","0.02962"
"33.85200","2.82117","0.02895"
"34.22400","2.85214","0.03069"
"34.59600","2.88311","0.02941"
"34.96800","2.91414","0.03011"
"35.34000","2.94511","0.03047"
"35.71200","2.97608","0.03131"
"36.08400","3.00705","0.03153"
"36.45600","3.03815","0.03182"
"36.82800","3.06918","0.03161"
"37.20000","3.10009","0.03239"
"37.57200","3.13112","0.03300"
"37.94400","3.16215","0.03299"
"38.31600","3.19312","0.03411"
"38.68800","3.22415","0.03427"
"39.06000","3.25518","0.03380"
"39.43200","3.28609","0.03424"
"39.80400","3.31712","0.03492"
"40.17600","3.34815","0.03586"
"40.54800","3.37912","0.03636"
"40.92000","3.41010","0.03655"
"41.29200","3.44119","0.03665"
"41.66400","3.47210","0.03735"
"42.03600","3.50307","0.03776"
"42.40800","3.53410","0.03828"
"42.78000","3.56513","0.03893"
"43.15200","3.59610","0.03908"
"43.52400","3.62713","0.03952"
"43.89600","3.65822","0.04031"
"44.26800","3.68907","0.04073"
"44.64000","3.72010","0.04075"
"45.01200","3.75120","0.04163"
"45.38400","3.78211","0.04198"
"45.75600","3.81314","0.04221"
"46.12800","3.84411","0.04314"
"46.50000","3.87514","0.04339"
"46.87200","3.90611","0.04260"
"47.24400","3.93720","0.04342"
"47.61600","3.96817","0.04401"
"47.98800","3.99908","0.04482"
"48.36000","4.03011","0.04558"
"48.73200","4.06108","0.04628"
"49.10400","4.09206","0.04582"
"49.47600","4.12315","0.04661"
"49.84800","4.15412","0.04797"
"50.22000","4.18509","0.04802"
"50.59200","4.21612","0.04795"
"50.96400","4.24715","0.04918"
"51.33600","4.27812","0.04945"
"51.70800","4.30915","0.05063"
"52.08000","4.34018","0.05128"
"52.45200","4.37109","0.05185"
"52.82400","4.40206","0.05190"
"53.19600","4.43315","0.05238"
"53.56800","4.46413","0.05319"
"53.94000","4.49510","0.05420"
"54.31200","4.52613","0.05478"
"54.68400","4.55716","0.05593"
"55.05600","4.58807","0.05707"
"55.42800","4.61910","0.05793"
"55.80000","4.65019","0.05925"
"56.17200","4.68110","0.06100"
"56.54400","4.71213","0.06161"
"56.91600","4.74316","0.06273"
"57.28800","4.77413","0.06379"
"57.66000","4.80517","0.06492"
"58.03200","4.83614","0.05017"
"58.40400","4.86717","0.05067"
"58.77600","4.89808","0.05142"
"59.14800","4.92911","0.05170"
"59.52000","4.96020","0.05275"
"59.89200","4.99111","0.05305"
"60.26400","5.02214","0.05449"
"60.63600","5.05311","0.05556"
"61.00800","5.08408","0.05707"
"61.38000","5.11511","0.05849"
"61.75200","5.14614","0.05925"
"62.12400","5.17712","0.06024"
"62.49600","5.20809","0.06178"
"62.86800","5.23918","0.06354"
"63.24000","5.27021","0.06456"
"63.61200","5.30106","0.06615"
"63.98400","5.33215","0.06739"
"64.35600","5.36318","0.06875"
"64.72800","5.39403","0.06987"
"65.10000","5.42512","0.07132"
"65.47200","5.45615","0.07196"
"65.84400","5.48712","0.07307"
"66.21600","5.51810","0.07382"
"66.58800","5.54913","0.07451"
"66.96000","5.58010","0.07491"
"67.33200","5.61113","0.07557"
"67.70400","5.64216","0.07653"
"68.07600","5.67313","0.07650"
"68.44800","5.70410","0.07802"
"68.82000","5.73513","0.07821"
"69.19200","5.76616","0.07924"
"69.56400","5.79713","0.07972"
"69.93600","5.82810","0.08046"
"70.30800","5.85913","0.08180"
"70.68000","5.89011","0.08251"
"71.05200","5.92108","0.08305"
"71.42400","5.95211","0.08373"
"71.79600","5.98314","0.08441"
"72.16800","6.01411","0.08563"
"72.54000","6.04514","0.07994"
"72.91200","6.07617","0.08020"
"73.28400","6.10714","0.08066"
"73.65600","6.13811","0.06832"
"74.02800","6.16914","0.07029"
"74.40000","6.20005","0.07146"
"74.77200","6.23115","0.07214"
"75.14400","6.26212","0.07312"
"75.51600","6.29315","0.07402"
"75.88800","6.32412","0.07467"
"76.26000","6.35509","0.07527"
"76.63200","6.38612","0.07366"
"77.00400","6.41715","0.07439"
"77.37600","6.44812","0.07498"
"77.74800","6.47915","0.07539"
"78.12000","6.51006","0.07631"
"78.49200","6.54109","0.07686"
"78.86400","6.57212","0.07777"
"79.23600","6.60310","0.07847"
"79.60800","6.63413","0.07939"
"79.98000","6.66516","0.08002"
"80.35200","6.69613","0.08087"
"80.72400","6.72710","0.08123"
"81.09600","6.75813","0.08228"
"81.46800","6.78916","0.08319"
"81.84000","6.82007","0.08341"
"82.21200","6.85116","0.08437"
"82.58400","6.88213","0.06427"
"82.95600","6.91311","0.06315"
"83.32800","6.94414","0.06567"
"83.70000","6.97511","0.06766"
"84.07200","7.00614","0.06938"
"84.44400","7.03711","0.07003"
"84.81600","7.06814","0.07156"
"85.18800","7.09911","0.07257"
"85.56000","7.13014","0.07304"
"85.93200","7.16117","0.07401"
"86.30400","7.19208","0.07519"
"86.67600","7.22311","0.07591"
"87.04800","7.25415","0.07673"
"87.42000","7.28512","0.07668"
"87.79200","7.31615","0.07764"
"88.16400","7.34718","0.07850"
"88.53600","7.37815","0.07917"
"88.90800","7.40906","0.07974"
"89.28000","7.44009","0.08047"
"89.65200","7.47118","0.08147"
"90.02400","7.50203","0.08213"
"90.39600","7.53312","0.08317"
"90.76800","7.56415","0.08362"
"91.14000","7.59512","0.08442"
"91.51200","7.62610","0.08534"
"91.88400","7.65719","0.08619"
"92.25600","7.68810","0.08676"
"92.62800","7.71913","0.08721"
"93.00000","7.75016","0.08747"
"93.37200","7.78113","0.08848"
"93.74400","7.81204","0.06914"
"94.11600","7.84319","0.07295"
"94.48800","7.87416","0.07354"
"94.86000","7.90513","0.07443"
"95.23200","7.93616","0.07545"
"95.60400","7.96713","0.07567"
"95.97600","7.99811","0.07668"
"96.34800","8.02908","0.07726"
"96.72000","8.06011","0.07804"
"97.09200","8.09114","0.07902"
"97.46400","8.12211","0.07906"
"97.83600","8.15320","0.07974"
"98.20800","8.18417","0.08110"
"98.58000","8.21508","0.08159"
"98.95200","8.24617","0.08181"
"99.32400","8.27714","0.08301"
"99.69600","8.30811","0.08356"
"100.06800","8.33909","0.08407"
"100.44000","8.37012","0.08459"
"100.81200","8.40109","0.05099"
"101.18400","8.43212","0.05173"
"101.55600","8.46321","0.05444"
"101.92800","8.49412","0.05652"
"102.30000","8.52509","0.05647"
"102.67200","8.55612","0.05634"
"103.04400","8.58715","0.05729"
"103.41600","8.61812","0.05998"
"103.78800","8.64915","0.06179"
"104.16000","8.68018","0.06231"
"104.53200","8.71110","0.06226"
"104.90400","8.74207","0.06426"
"105.27600","8.77316","0.06612"
"105.64800","8.80413","0.06824"
"106.02000","8.83516","0.06812"
"106.39200","8.86613","0.06839"
"106.76400","8.89710","0.06982"
"107.13600","8.92807","0.07093"
"107.50800","8.95916","0.07197"
"107.88000","8.99013","0.07303"
"108.25200","9.02110","0.07257"
"108.62400","9.05214","0.07380"
"108.99600","9.08311","0.07484"
"109.36800","9.11402","0.07548"
"109.74000","9.14517","0.07577"
"110.11200","9.17614","0.07620"
"110.48400","9.20711","0.07731"
"110.85600","9.23814","0.07772"
"111.22800","9.26911","0.07812"
"111.60000","9.30008","0.07873"
"111.97200","9.33111","0.07951"
"112.34400","9.36214","0.07990"
"112.71600","9.39312","0.08061"
"113.08800","9.42409","0.08104"
"113.46000","9.45518","0.08189"
"113.83200","9.48609","0.08260"
"114.20400","9.51712","0.08290"
"114.57600","9.54815","0.08336"
"114.94800","9.57912","0.08477"
"115.32000","9.61009","0.08504"
"115.69200","9.64112","0.08546"
"116.06400","9.67215","0.08611"
"116.43600","9.70306","0.08744"
"116.80800","9.73409","0.08790"
"117.18000","9.76513","0.08853"
"117.55200","9.79610","0.08920"
"117.92400","9.82713","0.08994"
"118.29600","9.85816","0.09017"
"118.66800","9.88913","0.09128"
"119.04000","9.92004","0.09228"
"119.41200","9.95119","0.09385"
"119.78400","9.98222","0.09434"
"120.15600","10.01307","0.09499"
"120.52800","10.04416","0.09688"
"120.90000","10.07519","0.09734"
"121.27200","10.10611","0.09840"
"121.64400","10.13714","0.09968"
"122.01600","10.16811","0.10116"
"122.38800","10.19914","0.10171"
"122.76000","10.23011","0.10369"
"123.13200","10.26120","0.10507"
"123.50400","10.29217","0.10630"
"123.87600","10.32308","0.10741"
"124.24800","10.35417","0.10949"
"124.62000","10.38514","0.11113"
"124.99200","10.41605","0.11288"
"125.36400","10.44714","0.11506"
"125.73600","10.47812","0.11613"
"126.10800","10.50915","0.11829"
"126.48000","10.54012","0.11969"
"126.85200","10.57115","0.12171"
"127.22400","10.60212","0.12368"
"127.59600","10.63309","0.12531"
"127.96800","10.66418","0.12671"
"128.34000","10.69515","0.12792"
"128.71200","10.72612","0.12947"
"129.08400","10.75709","0.13059"
"129.45600","10.78818","0.13161"
"129.82800","10.81916","0.13300"
"130.20000","10.85007","0.13482"
"130.57200","10.88116","0.13623"
"130.94400","10.91213","0.13737"
"131.31600","10.94310","0.13888"
"131.68800","10.97419","0.14046"
"132.06000","11.00510","0.14123"
"132.43200","11.03607","0.14264"
"132.80400","11.06716","0.14425"
"133.17600","11.09813","0.14516"
"133.54800","11.12910","0.14655"
"133.92000","11.16014","0.14753"
"134.29200","11.19116","0.14943"
"134.66400","11.22208","0.15084"
"135.03600","11.25317","0.15199"
"135.40800","11.28420","0.15364"
"135.78000","11.31511","0.15417"
"136.15200","11.34614","0.15578"
"136.52400","11.37717","0.15713"
"136.89600","11.40814","0.15788"
"137.26800","11.43911","0.15908"
"137.64000","11.47014","0.16150"
"138.01200","11.50117","0.16254"
"138.38400","11.53209","0.16468"
"138.75600","11.56312","0.16669"
"139.12800","11.59415","0.16815"
"139.50000","11.62512","0.17051"
"139.87200","11.65615","0.17170"
"140.24400","11.68718","0.17305"
"140.61600","11.71815","0.17475"
"140.98800","11.74912","0.17657"
"141.36000","11.78015","0.17760"
"141.73200","11.81118","0.17930"
"142.10400","11.84209","0.18021"
"142.47600","11.87319","0.18228"
"142.84800","11.90410","0.18407"
"143.22000","11.93507","0.18455"
"143.59200","11.96616","0.18637"
"143.96400","11.99713","0.18778"
"144.33600","12.02810","0.18891"
"144.70800","12.05913","0.19025"
"145.08000","12.09016","0.19154"
"145.45200","12.12107","0.19265"
"145.82400","12.15210","0.19369"
"146.19600","12.18319","0.19486"
"146.56800","12.21410","0.19674"
"146.94000","12.24514","0.19800"
"147.31200","12.27617","0.19987"
"147.68400","12.30714","0.20153"
"148.05600","12.33811","0.20359"
"148.42800","12.36914","0.20556"
"148.80000","12.40017","0.20704"
"149.17200","12.43108","0.20913"
"149.54400","12.46211","0.21030"
"149.91600","12.49320","0.21208"
"150.28800","12.52405","0.21420"
"150.66000","12.55520","0.21667"
"151.03200","12.58617","0.21877"
"151.40400","12.61709","0.22121"
"151.77600","12.64812","0.22320"
"152.14800","12.67915","0.22585"
"152.52000","12.71012","0.22761"
"152.89200","12.74109","0.22936"
"153.26400","12.77218","0.23074"
"153.63600","12.80315","0.23314"
"154.00800","12.83406","0.23549"
"154.38000","12.86515","0.23763"
"154.75200","12.89612","0.23940"
"155.12400","12.92715","0.24170"
"155.49600","12.95813","0.24384"
"155.86800","12.98916","0.24598"
"156.24000","13.02013","0.24833"
"156.61200","13.05110","0.25043"
"156.98400","13.08213","0.25315"
"157.35600","13.11316","0.25499"
"157.72800","13.14407","0.25697"
"158.10000","13.17516","0.25904"
"158.47200","13.20613","0.26147"
"158.84400","13.23704","0.26454"
"159.21600","13.26819","0.26813"
"159.58800","13.29917","0.27154"
"159.96000","13.33014","0.27525"
"160.33200","13.36111","0.27692"
"160.70400","13.39214","0.27828"
"161.07600","13.42305","0.28054"
"161.44800","13.45414","0.28149"
"161.82000","13.48517","0.28358"
"162.19200","13.51608","0.28418"
"162.56400","13.54711","0.28604"
"162.93600","13.57814","0.28763"
"163.30800","13.60911","0.28937"
"163.68000","13.64009","0.29088"
"164.05200","13.67118","0.29311"
"164.42400","13.70215","0.29467"
"164.79600","13.73312","0.29613"
"165.16800","13.76409","0.29716"
"165.54000","13.79518","0.29825"
"165.91200","13.82609","0.29945"
"166.28400","13.85718","0.30088"
"166.65600","13.88815","0.30145"
"167.02800","13.91912","0.30295"
"167.40000","13.95009","0.30481"
"167.77200","13.98118","0.30704"
"168.14400","14.01216","0.30877"
"168.51600","14.04313","0.31045"
"168.88800","14.07416","0.31223"
"169.26000","14.10513","0.31440"
"169.63200","14.13610","0.31592"
"170.00400","14.16719","0.31795"
"170.37600","14.19810","0.32177"
"170.74800","14.22913","0.32432"
"171.12000","14.26010","0.32775"
"171.49200","14.29113","0.16020"
"171.86400","14.32210","0.15488"
"172.23600","14.35314","0.15789"
"172.60800","14.38417","0.15747"
"172.98000","14.41514","0.15677"
"173.35200","14.44611","0.16049"
"173.72400","14.47714","0.15848"
"174.09600","14.50811","0.16080"
"174.46800","14.53914","0.16214"
"174.84000","14.57011","0.16155"
"175.21200","14.60114","0.16506"
"175.58400","14.63211","0.16460"
"175.95600","14.66314","0.16642"
"176.32800","14.69417","0.16770"
"176.70000","14.72509","0.16745"
"177.07200","14.75612","0.17100"
"177.44400","14.78715","0.16979"
"177.81600","14.81806","0.17273"
"178.18800","14.84909","0.17293"
"178.56000","14.88018","0.17366"
"178.93200","14.91115","0.17546"
"179.30400","14.94212","0.17508"
"179.67600","14.97315","0.17752"
"180.04800","15.00412","0.17751"
"180.42000","15.03509","0.17907"
"180.79200","15.06613","0.17932"
"181.16400","15.09716","0.18044"
"181.53600","15.12807","0.18274"
"181.90800","15.15910","0.18205"
"182.28000","15.19013","0.18460"
"182.65200","15.22116","0.18451"
"183.02400","15.25207","0.18590"
"183.39600","15.28316","0.18635"
"183.76800","15.31413","0.18747"
"184.14000","15.34510","0.18850"
"184.51200","15.37619","0.18866"
"184.88400","15.40717","0.19049"
"185.25600","15.43808","0.19016"
"185.62800","15.46911","0.19194"
"186.00000","15.50014","0.19212"
"186.37200","15.53117","0.19362"
"186.74400","15.56208","0.19363"
"187.11600","15.59317","0.19448"
"187.48800","15.62414","0.19550"
"187.86000","15.65511","0.19686"
"188.23200","15.68620","0.19821"
"188.60400","15.71711","0.19927"
"188.97600","15.74808","0.20120"
"189.34800","15.77912","0.20194"
"189.72000","15.81015","0.20315"
"190.09200","15.84112","0.20369"
"190.46400","15.87209","0.20572"
"190.83600","15.90318","0.20625"
"191.20800","15.93409","0.20764"
"191.58000","15.96512","0.20847"
"191.95200","15.99615","0.20987"
"192.32400","16.02712","0.21074"
"192.69600","16.05809","0.21236"
"193.06800","16.08912","0.21338"
"193.44000","16.12016","0.21564"
"193.81200","16.15113","0.21707"
"194.18400","16.18210","0.21952"
"194.55600","16.21319","0.22192"
"194.92800","16.24404","0.22391"
"195.30000","16.27513","0.22558"
"195.67200","16.30616","0.22787"
"196.04400","16.33707","0.22905"
"196.41600","16.36816","0.23120"
"196.78800","16.39913","0.23201"
"197.16000","16.43010","0.23375"
"197.53200","16.46113","0.23532"
"197.90400","16.49217","0.23609"
"198.27600","16.52320","0.23761"
"198.64800","16.55411","0.23880"
"199.02000","16.58508","0.24084"
"199.39200","16.61611","0.24221"
"199.76400","16.64708","0.24339"
"200.13600","16.67817","0.24485"
"200.50800","16.70914","0.24638"
"200.88000","16.74005","0.24858"
"201.25200","16.77114","0.25040"
"201.62400","16.80211","0.25170"
"201.99600","16.83315","0.25273"
"202.36800","16.86411","0.25473"
"202.74000","16.89521","0.25518"
"203.11200","16.92612","0.25704"
"203.48400","16.95703","0.25836"
"203.85600","16.98818","0.26150"
"204.22800","17.01915","0.26392"
"204.60000","17.05006","0.26857"
"204.97200","17.08115","0.27185"
"205.34400","17.11212","0.27512"
"205.71600","17.14309","0.27726"
"206.08800","17.17413","0.27999"
"206.46000","17.20515","0.28202"
"206.83200","17.23607","0.28454"
"207.20400","17.26716","0.28628"
"207.57600","17.29813","0.28897"
"207.94800","17.32910","0.29047"
"208.32000","17.36007","0.29240"
"208.69200","17.39116","0.29335"
"209.06400","17.42213","0.29443"
"209.43600","17.45304","0.29595"
"209.80800","17.48407","0.29715"
"210.18000","17.51522","0.29816"
"210.55200","17.54608","0.29938"
"210.92400","17.57717","0.30027"
"211.29600","17.60814","0.30089"
"211.66800","17.63911","0.30149"
"212.04000","17.67008","0.30292"
"212.41200","17.70117","0.30466"
"212.78400","17.73214","0.30586"
"213.15600","17.76305","0.30732"
"213.52800","17.79414","0.30878"
"213.90000","17.82511","0.31010"
"214.27200","17.85602","0.31226"
"214.64400","17.88717","0.31166"
"215.01600","17.91815","0.30802"
"215.38800","17.94906","0.30921"
"215.76000","17.98015","0.31131"
"216.13200","18.01118","0.31363"
"216.50400","18.04209","0.31583"
"216.87600","18.07306","0.31960"
"217.24800","18.10415","0.32264"
"217.62000","18.13512","0.32520"
"217.99200","18.16609","0.32816"
"218.36400","18.19718","0.33072"
"218.73600","18.22809","0.33266"
"219.10800","18.25912","0.33514"
"219.48000","18.29016","0.33641"
"219.85200","18.32119","0.33802"
"220.22400","18.35210","0.34001"
"220.59600","18.38307","0.34289"
"220.96800","18.41416","0.34595"
"221.34000","18.44513","0.34815"
"221.71200","18.47610","0.35058"
"222.08400","18.50713","0.35258"
"222.45600","18.53811","0.35481"
"222.82800","18.56907","0.35773"
"223.20000","18.60011","0.36024"
"223.57200","18.63114","0.36102"
"223.94400","18.66211","0.36315"
"224.31600","18.69314","0.36502"
"224.68800","18.72417","0.36673"
"225.06000","18.75508","0.36840"
"225.43200","18.78617","0.37151"
"225.80400","18.81714","0.37465"
"226.17600","18.84811","0.37693"
"226.54800","18.87914","0.37933"
"226.92000","18.91011","0.38167"
"227.29200","18.94114","0.38415"
"227.66400","18.97212","0.38641"
"228.03600","19.00315","0.38739"
"228.40800","19.03418","0.38885"
"228.78000","19.06515","0.39054"
"229.15200","19.09612","0.39012"
"229.52400","19.12715","0.39166"
"229.89600","19.15806","0.39299"
"230.26800","19.18915","0.39444"
"230.64000","19.22012","0.39581"
"231.01200","19.25115","0.39802"
"231.38400","19.28213","0.40005"
"231.75600","19.31310","0.40271"
"232.12800","19.34413","0.40578"
"232.50000","19.37510","0.40886"
"232.87200","19.40619","0.41085"
"233.24400","19.43710","0.41336"
"233.61600","19.46807","0.41585"
"233.98800","19.49916","0.41678"
"234.36000","19.53013","0.41859"
"234.73200","19.56110","0.42162"
"235.10400","19.59213","0.42520"
"235.47600","19.62316","0.42852"
"235.84800","19.65408","0.40410"
"236.22000","19.68511","0.40722"
"236.59200","19.71614","0.41031"
"236.96400","19.74711","0.41230"
"237.33600","19.77814","0.41674"
"237.70800","19.80917","0.42015"
"238.08000","19.84008","0.42147"
"238.45200","19.87111","0.42487"
"238.82400","19.90214","0.42469"
"239.19600","19.93317","0.42756"
"239.56800","19.96408","0.43083"
"239.94000","19.99512","0.43357"
"240.31200","20.02615","0.43635"
"240.68400","20.05711","0.43811"
"241.05600","20.08815","0.44041"
"241.42800","20.11918","0.44326"
"241.80000","20.15009","0.44329"
"242.17200","20.18112","0.44511"
"242.54400","20.21215","0.44615"
"242.91600","20.24312","0.44713"
"243.28800","20.27409","0.44838"
"243.66000","20.30512","0.45017"
"244.03200","20.33615","0.42203"
"244.40400","20.36712","0.42490"
"244.77600","20.39816","0.42761"
"245.14800","20.42913","0.43001"
"245.52000","20.46004","0.43139"
"245.89200","20.49113","0.42300"
"246.26400","20.52210","0.42697"
"246.63600","20.55313","0.42549"
"247.00800","20.58410","0.42922"
"247.38000","20.61513","0.43442"
"247.75200","20.64610","0.43518"
"248.12400","20.67713","0.43698"
"248.49600","20.70816","0.43955"
"248.86800","20.73914","0.44222"
"249.24000","20.77011","0.44313"
"249.61200","20.80114","0.44673"
"249.98400","20.83217","0.44816"
"250.35600","20.86308","0.44896"
"250.72800","20.89405","0.45232"
"251.10000","20.92520","0.45569"
"251.47200","20.95611","0.45665"
"251.84400","20.98708","0.46058"
"252.21600","21.01811","0.46412"
"252.58800","21.04914","0.46514"
"252.96000","21.08012","0.46966"
"253.33200","21.11115","0.47552"
"253.70400","21.14212","0.47702"
"254.07600","21.17309","0.46340"
"254.44800","21.20412","0.09591"
"254.82000","21.23515","0.09142"
"255.19200","21.26606","0.11512"
"255.56400","21.29715","0.10606"
"255.93600","21.32818","0.09147"
"256.30800","21.35915","0.09521"
"256.68000","21.39013","0.09790"
"257.05200","21.42109","0.12885"
"257.42400","21.45213","0.14013"
"257.79600","21.48315","0.12599"
"258.16800","21.51413","0.11335"
"258.54000","21.54516","0.11654"
"258.91200","21.57607","0.13090"
"259.28400","21.60710","0.14692"
"259.65600","21.63813","0.15511"
"260.02800","21.66910","0.15243"
"260.40000","21.70019","0.14707"
"260.77200","21.73116","0.14367"
"261.14400","21.76213","0.14778"
"261.51600","21.79311","0.15360"
"261.88800","21.82414","0.16024"
"262.26000","21.85517","0.17425"
"262.63200","21.88608","0.18094"
"263.00400","21.91717","0.18150"
"263.37600","21.94808","0.18063"
"263.74800","21.97911","0.17860"
"264.12000","22.01020","0.17914"
"264.49200","22.04117","0.18236"
"264.86400","22.07208","0.18161"
"265.23600","22.10317","0.18567"
"265.60800","22.13415","0.18961"
"265.98000","22.16506","0.19266"
"266.35200","22.19615","0.19841"
"266.72400","22.22718","0.19644"
"267.09600","22.25809","0.20133"
"267.46800","22.28912","0.20444"
"267.84000","22.32009","0.20659"
"268.21200","22.35112","0.19497"
"268.58400","22.38209","0.19526"
"268.95600","22.41318","0.19649"
"269.32800","22.44415","0.19717"
"269.70000","22.47507","0.19980"
"270.07200","22.50616","0.20296"
"270.44400","22.53719","0.20577"
"270.81600","22.56804","0.20936"
"271.18800","22.59919","0.21274"
"271.56000","22.63016","0.21633"
"271.93200","22.66107","0.22050"
"272.30400","22.69210","0.22086"
"272.67600","22.72319","0.22400"
"273.04800","22.75410","0.22733"
"273.42000","22.78507","0.23125"
"273.79200","22.81616","0.23352"
"274.16400","22.84714","0.23762"
"274.53600","22.87811","0.24107"
"274.90800","22.90914","0.24408"
"275.28000","22.94011","0.24803"
"275.65200","22.97108","0.25159"
"276.02400","23.00211","0.25421"
"276.39600","23.03314","0.25826"
"276.76800","23.06411","0.26215"
"277.14000","23.09508","0.26788"
"277.51200","23.12617","0.27443"
"277.88400","23.15714","0.27943"
"278.25600","23.18806","0.28345"
"278.62800","23.21915","0.28728"
"279.00000","23.25012","0.29060"
"279.37200","23.28109","0.29407"
"279.74400","23.31212","0.29694"
"280.11600","23.34315","0.29899"
"280.48800","23.37406","0.30113"
"280.86000","23.40515","0.30325"
"281.23200","23.43612","0.30484"
"281.60400","23.46709","0.30724"
"281.97600","23.49812","0.30955"
"282.34800","23.52916","0.31265"
"282.72000","23.56007","0.31569"
"283.09200","23.59110","0.31933"
"283.46400","23.62213","0.32447"
"283.83600","23.65316","0.32937"
"284.20800","23.68413","0.33563"
"284.58000","23.71516","0.34033"
"284.95200","23.74619","0.34523"
"285.32400","23.77704","0.34974"
"285.69600","23.80807","0.35275"
"286.06800","23.83910","0.35516"
"286.44000","23.87013","0.35817"
"286.81200","23.90117","0.35987"
"287.18400","23.93214","0.36176"
"287.55600","23.96317","0.36400"
"287.92800","23.99408","0.36821"
"288.30000","24.02517","0.37269"
"288.67200","24.05614","0.37586"
"289.04400","24.08711","0.37945"
"289.41600","24.11814","0.38184"
"289.78800","24.14911","0.38468"
"290.16000","24.18014","0.38838"
"290.53200","24.21117","0.39100"
"290.90400","24.24214","0.39339"
"291.27600","24.27312","0.39690"
"291.64800","24.30415","0.40023"
"292.02000","24.33518","0.40440"
"292.39200","24.36609","0.39442"
"292.76400","24.39712","0.39778"
"293.13600","24.42815","0.40176"
"293.50800","24.45912","0.40452"
"293.88000","24.49009","0.41054"
"294.25200","24.52118","0.41656"
"294.62400","24.55209","0.42095"
"294.99600","24.58313","0.42539"
"295.36800","24.61409","0.43012"
"295.74000","24.64519","0.43485"
"296.11200","24.67610","0.43916"
"296.48400","24.70713","0.44264"
"296.85600","24.73816","0.44561"
"297.22800","24.76907","0.44680"
"297.60000","24.80010","0.44737"
"297.97200","24.83113","0.44934"
"298.34400","24.86210","0.45104"
"298.71600","24.89314","0.45277"
"299.08800","24.92416","0.45528"
"299.46000","24.95513","0.45798"
"299.83200","24.98611","0.46131"
"300.20400","25.01714","0.46602"
"300.57600","25.04817","0.47125"
"300.94800","25.07908","0.47880"
"301.32000","25.11011","0.48544"
"301.69200","25.14114","0.49087"
"302.06400","25.17211","0.49590"
"302.43600","25.20314","0.49963"
"302.80800","25.23411","0.50246"
"303.18000","25.26514","0.50551"
"303.55200","25.29605","0.50891"
"303.92400","25.32715","0.51195"
"304.29600","25.35818","0.51488"
"304.66800","25.38909","0.51922"
"305.04000","25.42012","0.42003"
"305.41200","25.45115","0.41850"
"305.78400","25.48206","0.42246"
"306.15600","25.51315","0.42950"
"306.52800","25.54412","0.43921"
"306.90000","25.57509","0.44639"
"307.27200","25.60606","0.44743"
"307.64400","25.63715","0.45133"
"308.01600","25.66813","0.46017"
"308.38800","25.69910","0.46918"
"308.76000","25.73019","0.47589"
"309.13200","25.76116","0.48292"
"309.50400","25.79207","0.49529"
"309.87600","25.82310","0.49127"
"310.24800","25.85413","0.49328"
"310.62000","25.88510","0.49602"
"310.99200","25.91607","0.48850"
"311.36400","25.94716","0.35769"
"311.73600","25.97807","0.28089"
"312.10800","26.00916","0.01531"
"312.48000","26.04020","0.02193"
"312.85200","26.07117","0.02590"
"313.22400","26.10208","0.01672"
"313.59600","26.13317","0.02670"
"313.96800","26.16414","0.01869"
"314.34000","26.19511","0.02019"
"314.71200","26.22614","0.03038"
"315.08400","26.25717","0.02166"
"315.45600","26.28802","0.02564"
"315.82800","26.31917","0.03063"
"316.20000","26.35014","0.02357"
"316.57200","26.38106","0.02600"
"316.94400","26.41208","0.03010"
"317.31600","26.44312","0.02668"
"317.68800","26.47415","0.02781"
"318.06000","26.50512","0.03058"
"318.43200","26.53615","0.02877"
"318.80400","26.56712","0.03178"
"319.17600","26.59809","0.03423"
"319.54800","26.62912","0.03253"
"319.92000","26.66015","0.03390"
"320.29200","26.69113","0.03776"
"320.66400","26.72215","0.03715"
"321.03600","26.75313","0.03636"
"321.40800","26.78416","0.03709"
"321.78000","26.81513","0.03877"
"322.15200","26.84616","0.03784"
"322.52400","26.87713","0.03876"
"322.89600","26.90810","0.04031"
"323.26800","26.93919","0.04149"
"323.64000","26.97004","0.04199"
"324.01200","27.00107","0.04260"
"324.38400","27.03216","0.04403"
"324.75600","27.06314","0.04622"
"325.12800","27.09411","0.04702"
"325.50000","27.12514","0.04767"
"325.87200","27.15617","0.04903"
"326.24400","27.18708","0.05071"
"326.61600","27.21811","0.05222"
"326.98800","27.24920","0.05280"
"327.36000","27.28011","0.05348"
"327.73200","27.31114","0.05600"
"328.10400","27.34217","0.05771"
"328.47600","27.37308","0.05851"
"328.84800","27.40411","0.06018"
"329.22000","27.43514","0.06319"
"329.59200","27.46618","0.06346"
"329.96400","27.49709","0.06512"
"330.33600","27.52812","0.06788"
"330.70800","27.55921","0.07042"
"331.08000","27.59006","0.07180"
"331.45200","27.62115","0.07294"
"331.82400","27.65212","0.07411"
"332.19600","27.68309","0.07535"
"332.56800","27.71412","0.07522"
"332.94000","27.74510","0.07531"
"333.31200","27.77612","0.07562"
"333.68400","27.80709","0.07685"
"334.05600","27.83819","0.07781"
"334.42800","27.86916","0.07992"
"334.80000","27.90007","0.08098"
"335.17200","27.93116","0.08168"
"335.54400","27.96213","0.08334"
"335.91600","27.99310","0.08413"
"336.28800","28.02413","0.08551"
"336.66000","28.05516","0.08721"
"337.03200","28.08607","0.08800"
"337.40400","28.11710","0.08942"
"337.77600","28.14813","0.09065"
"338.14800","28.17917","0.09222"
"338.52000","28.21008","0.09372"
"338.89200","28.24117","0.09551"
"339.26400","28.27214","0.09818"
"339.63600","28.30311","0.10088"
"340.00800","28.33414","0.10405"
"340.38000","28.36517","0.10607"
"340.75200","28.39614","0.10945"
"341.12400","28.42711","0.11405"
"341.49600","28.45815","0.11729"
"341.86800","28.48912","0.12155"
"342.24000","28.52009","0.12591"
"342.61200","28.55118","0.12893"
"342.98400","28.58209","0.13170"
"343.35600","28.61312","0.13456"
"343.72800","28.64409","0.13760"
"344.10000","28.67506","0.14130"
"344.47200","28.70609","0.14307"
"344.84400","28.73712","0.13524"
"345.21600","28.76815","0.13832"
"345.58800","28.79906","0.14282"
"345.96000","28.83010","0.14584"
"346.33200","28.86113","0.14830"
"346.70400","28.89210","0.15166"
"347.07600","28.92313","0.15555"
"347.44800","28.95410","0.15751"
"347.82000","28.98513","0.15994"
"348.19200","29.01610","0.16450"
"348.56400","29.04719","0.16929"
"348.93600","29.07816","0.17175"
"349.30800","29.10907","0.17494"
"349.68000","29.14016","0.17735"
"350.05200","29.17113","0.18071"
"350.42400","29.20205","0.18410"
"350.79600","29.23314","0.18702"
"351.16800","29.26411","0.18977"
"351.54000","29.29514","0.19225"
"351.91200","29.32611","0.19437"
"352.28400","29.35708","0.19732"
"352.65600","29.38811","0.20039"
"353.02800","29.41914","0.20417"
"353.40000","29.45017","0.20699"
"353.77200","29.48108","0.21087"
"354.14400","29.51205","0.21421"
"354.51600","29.54314","0.21765"
"354.88800","29.57412","0.22254"
"355.26000","29.60509","0.22613"
"355.63200","29.63612","0.22897"
"356.00400","29.66715","0.23131"
"356.37600","29.69812","0.23471"
"356.74800","29.72915","0.23785"
"357.12000","29.76012","0.24139"
"357.49200","29.79103","0.24410"
"357.86400","29.82212","0.24832"
"358.23600","29.85315","0.25229"
"358.60800","29.88406","0.25664"
"358.98000","29.91515","0.26224"
"359.35200","29.94613","0.26866"
"359.72400","29.97716","0.27567"
"360.09600","30.00801","0.28076"
"360.46800","30.03916","0.28500"
"360.84000","30.07019","0.28859"
"361.21200","30.10110","0.29211"
"361.58400","30.13213","0.29506"
"361.95600","30.16310","0.29749"
"362.32800","30.19413","0.29917"
"362.70000","30.22511","0.30059"
"363.07200","30.25614","0.30254"
"363.44400","30.28717","0.30517"
"363.81600","30.31808","0.30845"
"364.18800","30.34917","0.31128"
"364.56000","30.38014","0.31539"
"364.93200","30.41111","0.32080"
"365.30400","30.44220","0.32589"
"365.67600","30.47317","0.33152"
"366.04800","30.50408","0.33520"
"366.42000","30.53511","0.33871"
"366.79200","30.56614","0.34495"
"367.16400","30.59711","0.34907"
"367.53600","30.62809","0.35233"
"367.90800","30.65918","0.35463"
"368.28000","30.69009","0.35839"
"368.65200","30.72112","0.36111"
"369.02400","30.75221","0.36427"
"369.39600","30.78312","0.36751"
"369.76800","30.81409","0.37112"
"370.14000","30.84512","0.37615"
"370.51200","30.87615","0.37987"
"370.88400","30.90712","0.38359"
"371.25600","30.93810","0.38733"
"371.62800","30.96918","0.39044"
"372.00000","31.00010","0.39390"
"372.37200","31.03113","0.39663"
"372.74400","31.06216","0.40082"
"373.11600","31.09307","0.40501"
"373.48800","31.12410","0.41124"
"373.86000","31.15513","0.41545"
"374.23200","31.18616","0.42058"
"374.60400","31.21707","0.42567"
"374.97600","31.24816","0.42986"
"375.34800","31.27913","0.43446"
"375.72000","31.31004","0.43888"
"376.09200","31.34114","0.44246"
"376.46400","31.37216","0.44568"
"376.83600","31.40308","0.44816"
"377.20800","31.43417","0.45122"
"377.58000","31.46508","0.45484"
"377.95200","31.49611","0.45926"
"378.32400","31.52714","0.46454"
"378.69600","31.55811","0.47023"
"379.06800","31.58914","0.47656"
"379.44000","31.62011","0.48288"
"379.81200","31.65114","0.48915"
"380.18400","31.68212","0.49413"
"380.55600","31.71308","0.49880"
"380.92800","31.74417","0.50202"
"381.30000","31.77515","0.50506"
"381.67200","31.80612","0.50825"
"382.04400","31.83709","0.51162"
"382.41600","31.86812","0.51480"
"382.78800","31.89909","0.51802"
"383.16000","31.93012","0.52174"
"383.53200","31.96115","0.48616"
"383.90400","31.99206","0.21623"
"384.27600","32.02309","0.21261"
"384.64800","32.05418","0.20971"
"385.02000","32.08516","0.21558"
"385.39200","32.11613","0.21804"
"385.76400","32.14716","0.22472"
"386.13600","32.17813","0.23124"
"386.50800","32.20904","0.23428"
"386.88000","32.24013","0.24325"
"387.25200","32.27116","0.24531"
"387.62400","32.30207","0.25438"
"387.99600","32.33316","0.25790"
"388.36800","32.36407","0.27205"
"388.74000","32.39511","0.27452"
"389.11200","32.42613","0.28321"
"389.48400","32.45723","0.28716"
"389.85600","32.48814","0.29186"
"390.22800","32.51905","0.29323"
"390.60000","32.55014","0.29754"
"390.97200","32.58111","0.29930"
"391.34400","32.61208","0.30193"
"391.71600","32.64317","0.30340"
"392.08800","32.67414","0.30769"
"392.46000","32.70511","0.30945"
"392.83200","32.73615","0.31296"
"393.20400","32.76711","0.31718"
"393.57600","32.79815","0.32360"
"393.94800","32.82912","0.33016"
"394.32000","32.86015","0.33596"
"394.69200","32.89112","0.34224"
"395.06400","32.92209","0.34861"
"395.43600","32.95318","0.35456"
"395.80800","32.98415","0.35913"
"396.18000","33.01512","0.36391"
"396.55200","33.04609","0.36814"
"396.92400","33.07713","0.37402"
"397.29600","33.10809","0.37985"
"397.66800","33.13906","0.38386"
"398.04000","33.17010","0.38646"
"398.41200","33.20107","0.39108"
"398.78400","33.23210","0.39507"
"399.15600","33.26319","0.39952"
"399.52800","33.29410","0.40504"
"399.90000","33.32513","0.40973"
"400.27200","33.35616","0.41441"
"400.64400","33.38719","0.41937"
"401.01600","33.41810","0.34953"
"401.38800","33.44913","0.35037"
"401.76000","33.48016","0.35617"
"402.13200","33.51108","0.35644"
"402.50400","33.54211","0.36315"
"402.87600","33.57314","0.37037"
"403.24800","33.60411","0.37610"
"403.62000","33.63514","0.38400"
"403.99200","33.66611","0.38759"
"404.36400","33.69714","0.38985"
"404.73600","33.72811","0.39302"
"405.10800","33.75914","0.39608"
"405.48000","33.79018","0.39975"
"405.85200","33.82108","0.40816"
"406.22400","33.85212","0.41563"
"406.59600","33.88315","0.41311"
"406.96800","33.91406","0.41704"
"407.34000","33.94515","0.39726"
"407.71200","33.97618","0.39971"
"408.08400","34.00715","0.40573"
"408.45600","34.03806","0.41168"
"408.82800","34.06915","0.41760"
"409.20000","34.10018","0.42324"
"409.57200","34.13110","0.42879"
"409.94400","34.16212","0.43370"
"410.31600","34.19310","0.43843"
"410.68800","34.22407","0.44289"
"411.06000","34.25516","0.44614"
"411.43200","34.28613","0.44937"
"411.80400","34.31710","0.45222"
"412.17600","34.34807","0.45675"
"412.54800","34.37916","0.46132"
"412.92000","34.41013","0.46693"
"413.29200","34.44110","0.44906"
"413.66400","34.47213","0.45177"
"414.03600","34.50311","0.45545"
"414.40800","34.53413","0.46007"
"414.78000","34.56517","0.46025"
"415.15200","34.59614","0.46273"
"415.52400","34.62704","0.46278"
"415.89600","34.65814","0.45877"
"416.26800","34.68917","0.46242"
"416.64000","34.72008","0.46617"
"417.01200","34.75111","0.47026"
"417.38400","34.78214","0.47544"
"417.75600","34.81311","0.48384"
"418.12800","34.84409","0.49059"
"418.50000","34.87511","0.49418"
"418.87200","34.90609","0.49891"
"419.24400","34.93712","0.50246"
"419.61600","34.96815","0.50532"
"419.98800","34.99918","0.50802"
"420.36000","35.03009","0.51094"
"420.73200","35.06118","0.46476"
"421.10400","35.09215","0.45247"
"421.47600","35.12312","0.45424"
"421.84800","35.15415","0.45956"
"422.22000","35.18512","0.37999"
"422.59200","35.21609","0.37598"
"422.96400","35.24707","0.37638"
"423.33600","35.27816","0.37883"
"423.70800","35.30913","0.37833"
"424.08000","35.34004","0.38429"
"424.45200","35.37119","0.38766"
"424.82400","35.40216","0.38937"
"425.19600","35.43307","0.39164"
"425.56800","35.46416","0.38957"
"425.94000","35.49513","0.39042"
"426.31200","35.52604","0.39325"
"426.68400","35.55714","0.39604"
"427.05600","35.58817","0.36551"
"427.42800","35.61914","0.36739"
"427.80000","35.65011","0.37202"
"428.17200","35.68119","0.37612"
"428.54400","35.71211","0.37396"
"428.91600","35.74308","0.37502"
"429.28800","35.77411","0.37859"
"429.66000","35.80514","0.38205"
"430.03200","35.83617","0.38469"
"430.40400","35.86714","0.38825"
"430.77600","35.89812","0.39118"
"431.14800","35.92908","0.39395"
"431.52000","35.96006","0.39667"
"431.89200","35.99115","0.39978"
"432.26400","36.02212","0.40431"
"432.63600","36.05315","0.40906"
"433.00800","36.08412","0.41346"
"433.38000","36.11509","0.41698"
"433.75200","36.14612","0.42087"
"434.12400","36.17715","0.42500"
"434.49600","36.20812","0.42843"
"434.86800","36.23909","0.43045"
"435.24000","36.27012","0.43602"
"435.61200","36.30116","0.43927"
"435.98400","36.33207","0.44143"
"436.35600","36.36316","0.44482"
"436.72800","36.39413","0.44752"
"437.10000","36.42510","0.45040"
"437.47200","36.45613","0.45361"
"437.84400","36.48710","0.45743"
"438.21600","36.51807","0.46113"
"438.58800","36.54916","0.46513"
"438.96000","36.58014","0.47020"
"439.33200","36.61110","0.47645"
"439.70400","36.64214","0.48257"
"440.07600","36.67316","0.48914"
"440.44800","36.70414","0.49386"
"440.82000","36.73511","0.49767"
"441.19200","36.76614","0.50078"
"441.56400","36.79717","0.50188"
"441.93600","36.82808","0.50363"
"442.30800","36.85917","0.50575"
"442.68000","36.89014","0.50753"
"443.05200","36.92111","0.50969"
"443.42400","36.95214","0.51264"
"443.79600","36.98317","0.51468"
"444.16800","37.01409","0.51250"
"444.54000","37.04506","0.51290"
"444.91200","37.07615","0.51284"
"445.28400","37.10712","0.51442"
"445.65600","37.13815","0.51530"
"446.02800","37.16918","0.51768"
"446.40000","37.20015","0.51977"
"446.77200","37.23106","0.51387"
"447.14400","37.26209","0.51666"
"447.51600","37.29313","0.51999"
"447.88800","37.32409","0.52336"
"448.26000","37.35513","0.52697"
"448.63200","37.38610","0.53039"
"449.00400","37.41713","0.53324"
"449.37600","37.44810","0.53734"
"449.74800","37.47913","0.53991"
"450.12000","37.51016","0.54278"
"450.49200","37.54107","0.54635"
"450.86400","37.57210","0.54969"
"451.23600","37.60313","0.55331"
"451.60800","37.63411","0.55550"
"451.98000","37.66519","0.51740"
"452.35200","37.69616","0.51699"
"452.72400","37.72713","0.52158"
"453.09600","37.75811","0.52772"
"453.46800","37.78913","0.52704"
"453.84000","37.82011","0.36160"
"454.21200","37.85108","0.35296"
"454.58400","37.88217","0.35871"
"454.95600","37.91308","0.35882"
"455.32800","37.94405","0.36144"
"455.70000","37.97514","0.36698"
"456.07200","38.00611","0.36787"
"456.44400","38.03714","0.37615"
"456.81600","38.06812","0.38007"
"457.18800","38.09915","0.38326"
"457.56000","38.13012","0.39015"
"457.93200","38.16109","0.39280"
"458.30400","38.19218","0.39593"
"458.67600","38.22315","0.40020"
"459.04800","38.25406","0.40160"
"459.42000","38.28515","0.40292"
"459.79200","38.31612","0.40599"
"460.16400","38.34710","0.40776"
"460.53600","38.37812","0.41212"
"460.90800","38.40915","0.39463"
"461.28000","38.44007","0.34233"
"461.65200","38.47110","0.34381"
"462.02400","38.50219","0.34771"
"462.39600","38.53304","0.35021"
"462.76800","38.56413","0.35385"
"463.14000","38.59516","0.35862"
"463.51200","38.62613","0.36093"
"463.88400","38.65716","0.36420"
"464.25600","38.68813","0.36845"
"464.62800","38.71916","0.37212"
"465.00000","38.75008","0.37582"
"465.37200","38.78111","0.37802"
"465.74400","38.81220","0.37837"
"466.11600","38.84311","0.37974"
"466.48800","38.87408","0.38187"
"466.86000","38.90517","0.38470"
"467.23200","38.93608","0.38710"
"467.60400","38.96717","0.38954"
"467.97600","38.99814","0.39243"
"468.34800","39.02917","0.39548"
"468.72000","39.06008","0.39802"
"469.09200","39.09117","0.40126"
"469.46400","39.12215","0.40445"
"469.83600","39.15312","0.40747"
"470.20800","39.18415","0.41103"
"470.58000","39.21512","0.41416"
"470.95200","39.24609","0.41741"
"471.32400","39.27718","0.42063"
"471.69600","39.30809","0.42512"
"472.06800","39.33912","0.42978"
"472.44000","39.37009","0.43419"
"472.81200","39.40118","0.43728"
"473.18400","39.43209","0.43974"
"473.55600","39.46307","0.44177"
"473.92800","39.49415","0.44459"
"474.30000","39.52512","0.44621"
"474.67200","39.55610","0.44878"
"475.04400","39.58713","0.45174"
"475.41600","39.61816","0.45468"
"475.78800","39.64907","0.45732"
"476.16000","39.68010","0.46094"
"476.53200","39.71119","0.46284"
"476.90400","39.74205","0.35526"
"477.27600","39.77313","0.35384"
"477.64800","39.80416","0.35537"
"478.02000","39.83507","0.35548"
"478.39200","39.86610","0.35895"
"478.76400","39.89714","0.36084"
"479.13600","39.92805","0.36391"
"479.50800","39.95908","0.36619"
"479.88000","39.99017","0.36884"
"480.25200","40.02114","0.37325"
"480.62400","40.05211","0.37472"
"480.99600","40.08320","0.37697"
"481.36800","40.11417","0.37886"
"481.74000","40.14508","0.38052"
"482.11200","40.17612","0.38306"
"482.48400","40.20715","0.38479"
"482.85600","40.23811","0.38712"
"483.22800","40.26909","0.39008"
"483.60000","40.30012","0.39236"
"483.97200","40.33109","0.39554"
"484.34400","40.36212","0.39885"
"484.71600","40.39315","0.40176"
"485.08800","40.42412","0.40485"
"485.46000","40.45503","0.40762"
"485.83200","40.48618","0.41007"
"486.20400","40.51721","0.22310"
"486.57600","40.54807","0.08651"
"486.94800","40.57909","0.07659"
"487.32000","40.61019","0.07498"
"487.69200","40.64109","0.07886"
"488.06400","40.67213","0.07189"
"488.43600","40.70316","0.07168"
"488.80800","40.73407","0.07562"
"489.18000","40.76504","0.07133"
"489.55200","40.79613","0.07451"
"489.92400","40.82716","0.08161"
"490.29600","40.85813","0.08079"
"490.66800","40.88911","0.08038"
"491.04000","40.92014","0.08652"
"491.41200","40.95111","0.08837"
"491.78400","40.98214","0.08484"
"492.15600","41.01317","0.08663"
"492.52800","41.04408","0.09119"
"492.90000","41.07511","0.09137"
"493.27200","41.10614","0.09098"
"493.64400","41.13712","0.09526"
"494.01600","41.16814","0.09875"
"494.38800","41.19917","0.09772"
"494.76000","41.23014","0.09734"
"495.13200","41.26112","0.10274"
"495.50400","41.29214","0.10590"
"495.87600","41.32318","0.10507"
"496.24800","41.35409","0.10818"
"496.62000","41.38518","0.11432"
"496.99200","41.41615","0.11593"
"497.36400","41.44706","0.11820"
"497.73600","41.47815","0.12227"
"498.10800","41.50906","0.12688"
"498.48000","41.54009","0.12732"
"498.85200","41.57113","0.12917"
"499.22400","41.60216","0.13257"
"499.59600","41.63312","0.13628"
"499.96800","41.66410","0.13704"
"500.34000","41.69513","0.13907"
"500.71200","41.72610","0.14217"
"501.08400","41.75707","0.09986"
"501.45600","41.78816","0.09282"
"501.82800","41.81919","0.09783"
"502.20000","41.85010","0.09670"
"502.57200","41.88113","0.09743"
"502.94400","41.91211","0.10567"
"503.31600","41.94308","0.11090"
"503.68800","41.97411","0.10799"
"504.06000","42.00520","0.10944"
"504.43200","42.03611","0.11740"
"504.80400","42.06708","0.12057"
"505.17600","42.09817","0.11973"
"505.54800","42.12914","0.12356"
"505.92000","42.16011","0.12822"
"506.29200","42.19114","0.12910"
"506.66400","42.22217","0.12860"
"507.03600","42.25303","0.13219"
"507.40800","42.28411","0.13578"
"507.78000","42.31515","0.13600"
"508.15200","42.34605","0.13681"
"508.52400","42.37715","0.13958"
"508.89600","42.40812","0.14199"
"509.26800","42.43909","0.14249"
"509.64000","42.47012","0.14402"
"510.01200","42.50115","0.14558"
"510.38400","42.53212","0.14765"
"510.75600","42.56309","0.14829"
"511.12800","42.59412","0.06143"
"511.50000","42.62515","0.04087"
"511.87200","42.65607","0.07977"
"512.24400","42.68716","0.03886"
"512.61600","42.71813","0.06133"
"512.98800","42.74910","0.04225"
"513.36000","42.78013","0.04009"
"513.73200","42.81110","0.06651"
"514.10400","42.84213","0.03937"
"514.47600","42.87310","0.06479"
"514.84800","42.90419","0.04605"
"515.22000","42.93510","0.04421"
"515.59200","42.96608","0.06331"
"515.96400","42.99711","0.04376"
"516.33600","43.02813","0.06165"
"516.70800","43.05911","0.05349"
"517.08000","43.09014","0.04851"
"517.45200","43.12117","0.06836"
"517.82400","43.15214","0.04974"
"518.19600","43.18311","0.05775"
"518.56800","43.21414","0.06503"
"518.94000","43.24511","0.05287"
"519.31200","43.27614","0.06960"
"519.68400","43.30711","0.06314"
"520.05600","43.33815","0.06059"
"520.42800","43.36911","0.07371"
"520.80000","43.40008","0.06366"
"521.17200","43.43118","0.06922"
"521.54400","43.46209","0.07483"
"521.91600","43.49312","0.06840"
"522.28800","43.52421","0.07421"
"522.66000","43.55506","0.07500"
"523.03200","43.58615","0.07170"
"523.40400","43.61712","0.07765"
"523.77600","43.64809","0.07654"
"524.14800","43.67913","0.07490"
"524.52000","43.71010","0.07931"
"524.89200","43.74118","0.07830"
"525.26400","43.77216","0.07800"
"525.63600","43.80313","0.08184"
"526.00800","43.83416","0.08024"
"526.38000","43.86507","0.08078"
"526.75200","43.89610","0.08291"
"527.12400","43.92713","0.08218"
"527.49600","43.95810","0.08369"
"527.86800","43.98913","0.08505"
"528.24000","44.02010","0.08447"
"528.61200","44.05113","0.08544"
"528.98400","44.08210","0.08642"
"529.35600","44.11314","0.08621"
"529.72800","44.14417","0.08760"
"530.10000","44.17508","0.08822"
"530.47200","44.20617","0.08819"
"530.84400","44.23714","0.08781"
"531.21600","44.26805","0.08776"
"531.58800","44.29914","0.08747"
"531.96000","44.33011","0.08734"
"532.33200","44.36115","0.08681"
"532.70400","44.39212","0.08606"
"533.07600","44.42314","0.08643"
"533.44800","44.45406","0.08587"
"533.82000","44.48509","0.08465"
"534.19200","44.51618","0.08508"
"534.56400","44.54715","0.08487"
"534.93600","44.57806","0.08500"
"535.30800","44.60915","0.08484"
"535.68000","44.64012","0.08507"
"536.05200","44.67109","0.08536"
"536.42400","44.70218","0.08456"
"536.79600","44.73322","0.08432"
"537.16800","44.76400","0.08350"
"537.54000","44.79515","0.08375"
"537.91200","44.82619","0.08371"
"538.28400","44.85704","0.08440"
"538.65600","44.88813","0.08467"
"539.02800","44.91916","0.08479"
"539.40000","44.95007","0.08533"
"539.77200","44.98110","0.08621"
"540.14400","45.01213","0.08679"
"540.51600","45.04310","0.08712"
"540.88800","45.07407","0.08806"
"541.26000","45.10517","0.08877"
"541.63200","45.13614","0.08886"
"542.00400","45.16705","0.09011"
"542.37600","45.19814","0.09067"
"542.74800","45.22917","0.09190"
"543.12000","45.26014","0.09254"
"543.49200","45.29111","0.09389"
"543.86400","45.32208","0.09431"
"544.23600","45.35311","0.09533"
"544.60800","45.38408","0.09673"
"544.98000","45.41511","0.09762"
"545.35200","45.44614","0.09219"
"545.72400","45.47699","0.09294"
"546.09600","45.50821","0.09461"
"546.46800","45.53918","0.09535"
"546.84000","45.57009","0.09635"
"547.21200","45.60112","0.09830"
"547.58400","45.63214","0.09892"
"547.95600","45.66312","0.09995"
"548.32800","45.69409","0.10165"
"548.70000","45.72512","0.10296"
"549.07200","45.75610","0.10436"
"549.44400","45.78712","0.10549"
"549.81600","45.81815","0.10688"
"550.18800","45.84912","0.10812"
"550.56000","45.88010","0.10943"
"550.93200","45.91113","0.11114"
"551.30400","45.94210","0.11218"
"551.67600","45.97313","0.11445"
"552.04800","46.00410","0.11523"
"552.42000","46.03513","0.11650"
"552.79200","46.06604","0.11926"
"553.16400","46.09713","0.12007"
"553.53600","46.12811","-0.00414"
"553.82200","46.15190","-0.00514"