File: Force_trajectories/161218/Specimen_RawData_7.csv
End date,"12/18/2016"
Specimen label,"17AT_35"
Maximum Load,"0.28481",N

Time,Extension,Load
(s),(mm),(N)
"0.00000","0.00000","-0.00166"
"0.30600","0.02511","-0.00022"
"0.61200","0.05118","0.00091"
"0.91800","0.07665","0.00166"
"1.22400","0.10218","0.00230"
"1.53000","0.12765","0.00298"
"1.83600","0.15318","0.00356"
"2.14200","0.17865","0.00365"
"2.44800","0.20418","0.00422"
"2.75400","0.22965","0.00475"
"3.06000","0.25512","0.00502"
"3.36600","0.28065","0.00502"
"3.67200","0.30612","0.00503"
"3.97800","0.33171","0.00582"
"4.28400","0.35712","0.00568"
"4.59000","0.38265","0.00567"
"4.89600","0.40812","0.00583"
"5.20200","0.43365","0.00543"
"5.50800","0.45918","0.00616"
"5.81400","0.48459","0.00659"
"6.12000","0.51012","0.00637"
"6.42600","0.53565","0.00655"
"6.73200","0.56118","0.00668"
"7.03800","0.58665","0.00690"
"7.34400","0.61213","0.00644"
"7.65000","0.63766","0.00697"
"7.95600","0.66313","0.00676"
"8.26200","0.68866","0.00694"
"8.56800","0.71407","0.00719"
"8.87400","0.73966","0.00746"
"9.18000","0.76507","0.00768"
"9.48600","0.79060","0.00759"
"9.79200","0.81613","0.00737"
"10.09800","0.84160","0.00787"
"10.40400","0.86713","0.00755"
"10.71000","0.89260","0.00782"
"11.01600","0.91813","0.00815"
"11.32200","0.94360","0.00820"
"11.62800","0.96913","0.00819"
"11.93400","0.99466","0.00801"
"12.24000","1.02019","0.00844"
"12.54600","1.04572","0.00825"
"12.85200","1.07107","0.00841"
"13.15800","1.09666","0.00832"
"13.46400","1.12213","0.00894"
"13.77000","1.14760","0.00871"
"14.07600","1.17313","0.00820"
"14.38200","1.19860","0.00870"
"14.68800","1.22419","0.00875"
"14.99400","1.24960","0.00883"
"15.30000","1.27513","0.00900"
"15.60600","1.30060","0.00874"
"15.91200","1.32613","0.00884"
"16.21800","1.35166","0.00917"
"16.52400","1.37713","0.00927"
"16.83000","1.40266","0.00902"
"17.13600","1.42819","0.00893"
"17.44200","1.45366","0.00921"
"17.74800","1.47913","0.00916"
"18.05400","1.50466","0.00948"
"18.36000","1.53013","0.00943"
"18.66600","1.55560","0.00960"
"18.97200","1.58113","0.00971"
"19.27800","1.60660","0.00944"
"19.58400","1.63219","0.00945"
"19.89000","1.65761","0.00980"
"20.19600","1.68314","0.00936"
"20.50200","1.70861","0.00970"
"20.80800","1.73414","0.00956"
"21.11400","1.75967","0.00934"
"21.42000","1.78514","0.00963"
"21.72600","1.81067","0.00958"
"22.03200","1.83614","0.00961"
"22.33800","1.86167","0.00940"
"22.64400","1.88714","0.00984"
"22.95000","1.91267","0.01018"
"23.25600","1.93814","0.00968"
"23.56200","1.96361","0.00980"
"23.86800","1.98920","0.00988"
"24.17400","2.01461","0.00963"
"24.48000","2.04020","0.01002"
"24.78600","2.06561","0.01008"
"25.09200","2.09114","0.01016"
"25.39800","2.11667","0.00987"
"25.70400","2.14208","0.00988"
"26.01000","2.16767","0.00994"
"26.31600","2.19314","0.00966"
"26.62200","2.21867","0.00988"
"26.92800","2.24414","0.00998"
"27.23400","2.26961","0.01017"
"27.54000","2.29514","0.00996"
"27.84600","2.32061","0.01000"
"28.15200","2.34614","0.00985"
"28.45800","2.37161","0.00999"
"28.76400","2.39714","0.01031"
"29.07000","2.42267","0.01007"
"29.37600","2.44814","0.01035"
"29.68200","2.47367","0.00984"
"29.98800","2.49908","0.01030"
"30.29400","2.52467","0.00981"
"30.60000","2.55008","0.01021"
"30.90600","2.57567","0.00994"
"31.21200","2.60108","0.01037"
"31.51800","2.62667","0.01044"
"31.82400","2.65214","0.01054"
"32.13000","2.67761","0.01027"
"32.43600","2.70314","0.01015"
"32.74200","2.72861","0.01051"
"33.04800","2.75414","0.01015"
"33.35400","2.77962","0.01000"
"33.66000","2.80515","0.01041"
"33.96600","2.83068","0.01039"
"34.27200","2.85615","0.01039"
"34.57800","2.88174","0.01040"
"34.88400","2.90715","0.01011"
"35.19000","2.93262","0.01054"
"35.49600","2.95815","0.01015"
"35.80200","2.98362","0.01030"
"36.10800","3.00909","0.01013"
"36.41400","3.03462","0.01046"
"36.72000","3.06015","0.01095"
"37.02600","3.08556","0.01058"
"37.33200","3.11115","0.01039"
"37.63800","3.13662","0.01071"
"37.94400","3.16221","0.01078"
"38.25000","3.18762","0.01077"
"38.55600","3.21315","0.01056"
"38.86200","3.23868","0.01062"
"39.16800","3.26409","0.01079"
"39.47400","3.28962","0.01039"
"39.78000","3.31509","0.01039"
"40.08600","3.34068","0.01058"
"40.39200","3.36615","0.01087"
"40.69800","3.39168","0.01042"
"41.00400","3.41715","0.01080"
"41.31000","3.44262","0.01101"
"41.61600","3.46815","0.01064"
"41.92200","3.49356","0.01083"
"42.22800","3.51915","0.01086"
"42.53400","3.54462","0.01063"
"42.84000","3.57015","0.01061"
"43.14600","3.59562","0.01074"
"43.45200","3.62109","0.01075"
"43.75800","3.64662","0.01070"
"44.06400","3.67209","0.01087"
"44.37000","3.69762","0.01058"
"44.67600","3.72315","0.01094"
"44.98200","3.74868","0.01112"
"45.28800","3.77415","0.01099"
"45.59400","3.79957","0.01078"
"45.90000","3.82510","0.01108"
"46.20600","3.85057","0.01095"
"46.51200","3.87616","0.01118"
"46.81800","3.90163","0.01104"
"47.12400","3.92716","0.01102"
"47.43000","3.95269","0.01116"
"47.73600","3.97810","0.01124"
"48.04200","4.00363","0.01115"
"48.34800","4.02910","0.01107"
"48.65400","4.05463","0.01115"
"48.96000","4.08010","0.01158"
"49.26600","4.10569","0.01151"
"49.57200","4.13116","0.01097"
"49.87800","4.15663","0.01076"
"50.18400","4.18210","0.01128"
"50.49000","4.20757","0.01088"
"50.79600","4.23310","0.01113"
"51.10200","4.25857","0.01114"
"51.40800","4.28416","0.01142"
"51.71400","4.30963","0.01121"
"52.02000","4.33516","0.01100"
"52.32600","4.36069","0.01133"
"52.63200","4.38610","0.01126"
"52.93800","4.41163","0.01157"
"53.24400","4.43710","0.01118"
"53.55000","4.46269","0.01150"
"53.85600","4.48816","0.01169"
"54.16200","4.51369","0.01131"
"54.46800","4.53916","0.01134"
"54.77400","4.56463","0.01159"
"55.08000","4.59016","0.01136"
"55.38600","4.61563","0.01186"
"55.69200","4.64116","0.01141"
"55.99800","4.66663","0.01184"
"56.30400","4.69216","0.01151"
"56.61000","4.71763","0.01149"
"56.91600","4.74310","0.01159"
"57.22200","4.76863","0.01193"
"57.52800","4.79404","0.01214"
"57.83400","4.81963","0.01190"
"58.14000","4.84510","0.01181"
"58.44600","4.87064","0.01195"
"58.75200","4.89616","0.01191"
"59.05800","4.92158","0.01192"
"59.36400","4.94711","0.01191"
"59.67000","4.97258","0.01201"
"59.97600","4.99817","0.01168"
"60.28200","5.02364","0.01222"
"60.58800","5.04917","0.01205"
"60.89400","5.07464","0.01235"
"61.20000","5.10011","0.01244"
"61.50600","5.12564","0.01221"
"61.81200","5.15111","0.01245"
"62.11800","5.17664","0.01190"
"62.42400","5.20211","0.01208"
"62.73000","5.22764","0.01245"
"63.03600","5.25317","0.01234"
"63.34200","5.27864","0.01212"
"63.64800","5.30417","0.01251"
"63.95400","5.32958","0.01232"
"64.26000","5.35517","0.01229"
"64.56600","5.38058","0.01217"
"64.87200","5.40611","0.01230"
"65.17800","5.43164","0.01205"
"65.48400","5.45711","0.01252"
"65.79000","5.48270","0.01246"
"66.09600","5.50811","0.01234"
"66.40200","5.53364","0.01236"
"66.70800","5.55911","0.01248"
"67.01400","5.58464","0.01236"
"67.32000","5.61011","0.01280"
"67.62600","5.63564","0.01245"
"67.93200","5.66123","0.01259"
"68.23800","5.68664","0.01270"
"68.54400","5.71217","0.01269"
"68.85000","5.73764","0.01283"
"69.15600","5.76317","0.01285"
"69.46200","5.78864","0.01283"
"69.76800","5.81411","0.01258"
"70.07400","5.83970","0.01333"
"70.38000","5.86517","0.01311"
"70.68600","5.89064","0.01308"
"70.99200","5.91611","0.01302"
"71.29800","5.94164","0.01308"
"71.60400","5.96717","0.01336"
"71.91000","5.99265","0.01311"
"72.21600","6.01817","0.01350"
"72.52200","6.04359","0.01332"
"72.82800","6.06918","0.01286"
"73.13400","6.09459","0.01348"
"73.44000","6.12012","0.01362"
"73.74600","6.14559","0.01341"
"74.05200","6.17112","0.01323"
"74.35800","6.19665","0.01360"
"74.66400","6.22212","0.01365"
"74.97000","6.24765","0.01326"
"75.27600","6.27312","0.01341"
"75.58200","6.29871","0.01368"
"75.88800","6.32412","0.01334"
"76.19400","6.34965","0.01353"
"76.50000","6.37512","0.01355"
"76.80600","6.40065","0.01355"
"77.11200","6.42618","0.01326"
"77.41800","6.45165","0.01327"
"77.72400","6.47718","0.01357"
"78.03000","6.50265","0.01301"
"78.33600","6.52812","0.01325"
"78.64200","6.55365","0.01291"
"78.94800","6.57912","0.01335"
"79.25400","6.60471","0.01332"
"79.56000","6.63006","0.01349"
"79.86600","6.65565","0.01352"
"80.17200","6.68112","0.01351"
"80.47800","6.70665","0.01329"
"80.78400","6.73212","0.01356"
"81.09000","6.75759","0.01365"
"81.39600","6.78318","0.01358"
"81.70200","6.80865","0.01377"
"82.00800","6.83424","0.01370"
"82.31400","6.85959","0.01385"
"82.62000","6.88512","0.01369"
"82.92600","6.91059","0.01380"
"83.23200","6.93612","0.01375"
"83.53800","6.96165","0.01402"
"83.84400","6.98712","0.01343"
"84.15000","7.01265","0.01397"
"84.45600","7.03813","0.01382"
"84.76200","7.06366","0.01419"
"85.06800","7.08913","0.01415"
"85.37400","7.11466","0.01438"
"85.68000","7.14013","0.01393"
"85.98600","7.16566","0.01451"
"86.29200","7.19119","0.01389"
"86.59800","7.21660","0.01449"
"86.90400","7.24213","0.01423"
"87.21000","7.26760","0.01391"
"87.51600","7.29313","0.01411"
"87.82200","7.31866","0.01406"
"88.12800","7.34407","0.01454"
"88.43400","7.36966","0.01478"
"88.74000","7.39513","0.01455"
"89.04600","7.42066","0.01431"
"89.35200","7.44613","0.01455"
"89.65800","7.47160","0.01448"
"89.96400","7.49719","0.01480"
"90.27000","7.52260","0.01490"
"90.57600","7.54813","0.01472"
"90.88200","7.57366","0.01465"
"91.18800","7.59919","0.01496"
"91.49400","7.62460","0.01459"
"91.80000","7.65013","0.01514"
"92.10600","7.67566","0.01491"
"92.41200","7.70107","0.01487"
"92.71800","7.72666","0.01449"
"93.02400","7.75207","0.01493"
"93.33000","7.77772","0.01482"
"93.63600","7.80319","0.01530"
"93.94200","7.82866","0.01518"
"94.24800","7.85407","0.01519"
"94.55400","7.87960","0.01506"
"94.86000","7.90513","0.01471"
"95.16600","7.93060","0.01518"
"95.47200","7.95613","0.01524"
"95.77800","7.98160","0.01528"
"96.08400","8.00713","0.01506"
"96.39000","8.03266","0.01444"
"96.69600","8.05813","0.01485"
"97.00200","8.08366","0.01449"
"97.30800","8.10907","0.01413"
"97.61400","8.13466","0.01447"
"97.92000","8.16013","0.01501"
"98.22600","8.18567","0.01471"
"98.53200","8.21114","0.01442"
"98.83800","8.23661","0.01470"
"99.14400","8.26220","0.01476"
"99.45000","8.28755","0.01463"
"99.75600","8.31314","0.01488"
"100.06200","8.33861","0.01429"
"100.36800","8.36420","0.01425"
"100.67400","8.38961","0.01468"
"100.98000","8.41514","0.01436"
"101.28600","8.44067","0.01411"
"101.59200","8.46608","0.01425"
"101.89800","8.49161","0.01325"
"102.20400","8.51708","0.01322"
"102.51000","8.54267","0.01368"
"102.81600","8.56814","0.01385"
"103.12200","8.59367","0.01396"
"103.42800","8.61920","0.01352"
"103.73400","8.64461","0.01399"
"104.04000","8.67014","0.01387"
"104.34600","8.69555","0.01376"
"104.65200","8.72114","0.01389"
"104.95800","8.74661","0.01392"
"105.26400","8.77214","0.01380"
"105.57000","8.79767","0.01382"
"105.87600","8.82308","0.01436"
"106.18200","8.84861","0.01389"
"106.48800","8.87408","0.01396"
"106.79400","8.89967","0.01386"
"107.10000","8.92514","0.01400"
"107.40600","8.95067","0.01366"
"107.71200","8.97614","0.01383"
"108.01800","9.00167","0.01407"
"108.32400","9.02720","0.01393"
"108.63000","9.05261","0.01357"
"108.93600","9.07820","0.01278"
"109.24200","9.10361","0.01254"
"109.54800","9.12920","0.01260"
"109.85400","9.15467","0.01267"
"110.16000","9.18009","0.01265"
"110.46600","9.20562","0.01270"
"110.77200","9.23108","0.01265"
"111.07800","9.25667","0.01309"
"111.38400","9.28215","0.01313"
"111.69000","9.30768","0.01304"
"111.99600","9.33315","0.01319"
"112.30200","9.35862","0.01291"
"112.60800","9.38415","0.01295"
"112.91400","9.40956","0.01294"
"113.22000","9.43515","0.01307"
"113.52600","9.46062","0.01285"
"113.83200","9.48615","0.01272"
"114.13800","9.51168","0.01302"
"114.44400","9.53709","0.01293"
"114.75000","9.56268","0.01300"
"115.05600","9.58809","0.01292"
"115.36200","9.61362","0.01325"
"115.66800","9.63909","0.01345"
"115.97400","9.66468","0.01318"
"116.28000","9.69015","0.01326"
"116.58600","9.71562","0.01383"
"116.89200","9.74121","0.01338"
"117.19800","9.76662","0.01367"
"117.50400","9.79215","0.01346"
"117.81000","9.81756","0.01338"
"118.11600","9.84315","0.01393"
"118.42200","9.86862","0.01372"
"118.72800","9.89415","0.01435"
"119.03400","9.91968","0.01399"
"119.34000","9.94509","0.01388"
"119.64600","9.97062","0.01401"
"119.95200","9.99609","0.01427"
"120.25800","10.02162","0.01432"
"120.56400","10.04709","0.01388"
"120.87000","10.07268","0.01397"
"121.17600","10.09821","0.01378"
"121.48200","10.12362","0.01395"
"121.78800","10.14915","0.01402"
"122.09400","10.17462","0.01401"
"122.40000","10.20015","0.01400"
"122.70600","10.22563","0.01395"
"123.01200","10.25115","0.01404"
"123.31800","10.27668","0.01464"
"123.62400","10.30210","0.01444"
"123.93000","10.32763","0.01424"
"124.23600","10.35310","0.01456"
"124.54200","10.37869","0.01448"
"124.84800","10.40409","0.01434"
"125.15400","10.42963","0.01511"
"125.46000","10.45516","0.01452"
"125.76600","10.48063","0.01476"
"126.07200","10.50616","0.01525"
"126.37800","10.53157","0.01499"
"126.68400","10.55716","0.01541"
"126.99000","10.58257","0.01507"
"127.29600","10.60816","0.01510"
"127.60200","10.63363","0.01589"
"127.90800","10.65910","0.01517"
"128.21400","10.68469","0.01541"
"128.52000","10.71010","0.01557"
"128.82600","10.73563","0.01546"
"129.13200","10.76116","0.01542"
"129.43800","10.78669","0.01580"
"129.74400","10.81216","0.01589"
"130.05000","10.83763","0.01580"
"130.35600","10.86322","0.01562"
"130.66200","10.88863","0.01567"
"130.96800","10.91416","0.01592"
"131.27400","10.93963","0.01572"
"131.58000","10.96522","0.01622"
"131.88600","10.99069","0.01596"
"132.19200","11.01610","0.01640"
"132.49800","11.04169","0.01653"
"132.80400","11.06710","0.01609"
"133.11000","11.09269","0.01592"
"133.41600","11.11810","0.01604"
"133.72200","11.14363","0.01684"
"134.02800","11.16910","0.01641"
"134.33400","11.19463","0.01660"
"134.64000","11.22016","0.01679"
"134.94600","11.24563","0.01723"
"135.25200","11.27116","0.01712"
"135.55800","11.29663","0.01706"
"135.86400","11.32222","0.01747"
"136.17000","11.34764","0.01727"
"136.47600","11.37311","0.01777"
"136.78200","11.39869","0.01759"
"137.08800","11.42417","0.01791"
"137.39400","11.44969","0.01804"
"137.70000","11.47511","0.01839"
"138.00600","11.50064","0.01807"
"138.31200","11.52611","0.01853"
"138.61800","11.55158","0.01852"
"138.92400","11.57711","0.01926"
"139.23000","11.60258","0.01910"
"139.53600","11.62817","0.01923"
"139.84200","11.65364","0.01920"
"140.14800","11.67917","0.01896"
"140.45400","11.70464","0.01912"
"140.76000","11.73011","0.01998"
"141.06600","11.75564","0.01925"
"141.37200","11.78111","0.01975"
"141.67800","11.80670","0.01988"
"141.98400","11.83211","0.02000"
"142.29000","11.85764","0.02032"
"142.59600","11.88311","0.02036"
"142.90200","11.90864","0.02048"
"143.20800","11.93405","0.02003"
"143.51400","11.95958","0.02070"
"143.82000","11.98517","0.02029"
"144.12600","12.01064","0.02089"
"144.43200","12.03617","0.02060"
"144.73800","12.06164","0.02086"
"145.04400","12.08717","0.02137"
"145.35000","12.11264","0.02150"
"145.65600","12.13811","0.02053"
"145.96200","12.16364","0.02060"
"146.26800","12.18917","0.02129"
"146.57400","12.21470","0.01860"
"146.88000","12.24011","0.01830"
"147.18600","12.26564","0.01593"
"147.49200","12.29111","0.01656"
"147.79800","12.31658","0.01698"
"148.10400","12.34212","0.01645"
"148.41000","12.36758","0.01621"
"148.71600","12.39318","0.01698"
"149.02200","12.41859","0.01727"
"149.32800","12.44417","0.01779"
"149.63400","12.46965","0.01760"
"149.94000","12.49512","0.01804"
"150.24600","12.52065","0.01828"
"150.55200","12.54612","0.01833"
"150.85800","12.57171","0.01871"
"151.16400","12.59712","0.01875"
"151.47000","12.62271","0.01931"
"151.77600","12.64812","0.01891"
"152.08200","12.67365","0.01957"
"152.38800","12.69918","0.01995"
"152.69400","12.72459","0.01933"
"153.00000","12.75018","0.02001"
"153.30600","12.77559","0.02007"
"153.61200","12.80112","0.02017"
"153.91800","12.82659","0.02015"
"154.22400","12.85212","0.01971"
"154.53000","12.87765","0.01994"
"154.83600","12.90312","0.02019"
"155.14200","12.92865","0.02057"
"155.44800","12.95412","0.02052"
"155.75400","12.97965","0.02115"
"156.06000","13.00512","0.02112"
"156.36600","13.03059","0.02147"
"156.67200","13.05612","0.02186"
"156.97800","13.08159","0.02158"
"157.28400","13.10712","0.02237"
"157.59000","13.13259","0.02177"
"157.89600","13.15818","0.02143"
"158.20200","13.18365","0.02196"
"158.50800","13.20918","0.02113"
"158.81400","13.23465","0.02194"
"159.12000","13.26012","0.02208"
"159.42600","13.28565","0.02258"
"159.73200","13.31112","0.02252"
"160.03800","13.33665","0.02240"
"160.34400","13.36212","0.02301"
"160.65000","13.38765","0.02337"
"160.95600","13.41312","0.02296"
"161.26200","13.43859","0.02374"
"161.56800","13.46412","0.02421"
"161.87400","13.48959","0.02362"
"162.18000","13.51513","0.02388"
"162.48600","13.54060","0.02361"
"162.79200","13.56618","0.02448"
"163.09800","13.59166","0.02400"
"163.40400","13.61719","0.02409"
"163.71000","13.64272","0.02428"
"164.01600","13.66813","0.02423"
"164.32200","13.69366","0.02429"
"164.62800","13.71913","0.02476"
"164.93400","13.74466","0.02545"
"165.24000","13.77013","0.02539"
"165.54600","13.79560","0.02580"
"165.85200","13.82119","0.02453"
"166.15800","13.84660","0.02451"
"166.46400","13.87213","0.02480"
"166.77000","13.89760","0.02502"
"167.07600","13.92319","0.02564"
"167.38200","13.94866","0.02554"
"167.68800","13.97419","0.02575"
"167.99400","13.99966","0.02643"
"168.30000","14.02513","0.02620"
"168.60600","14.05060","0.02696"
"168.91200","14.07607","0.02741"
"169.21800","14.10166","0.02722"
"169.52400","14.12713","0.02784"
"169.83000","14.15272","0.02814"
"170.13600","14.17819","0.02861"
"170.44200","14.20360","0.02831"
"170.74800","14.22913","0.02890"
"171.05400","14.25454","0.02881"
"171.36000","14.28013","0.03004"
"171.66600","14.30560","0.02899"
"171.97200","14.33113","0.02916"
"172.27800","14.35666","0.02968"
"172.58400","14.38213","0.03026"
"172.89000","14.40766","0.03010"
"173.19600","14.43313","0.03049"
"173.50200","14.45866","0.03091"
"173.80800","14.48413","0.03122"
"174.11400","14.50966","0.03216"
"174.42000","14.53519","0.03206"
"174.72600","14.56060","0.03294"
"175.03200","14.58614","0.03282"
"175.33800","14.61155","0.03295"
"175.64400","14.63714","0.03306"
"175.95000","14.66261","0.03321"
"176.25600","14.68820","0.03360"
"176.56200","14.71367","0.03338"
"176.86800","14.73914","0.03377"
"177.17400","14.76467","0.03357"
"177.48000","14.79008","0.03456"
"177.78600","14.81567","0.03488"
"178.09200","14.84108","0.03264"
"178.39800","14.86667","0.03418"
"178.70400","14.89214","0.03525"
"179.01000","14.91761","0.03587"
"179.31600","14.94314","0.03475"
"179.62200","14.96855","0.03502"
"179.92800","14.99414","0.03575"
"180.23400","15.01961","0.03631"
"180.54000","15.04514","0.03649"
"180.84600","15.07061","0.03705"
"181.15200","15.09620","0.03765"
"181.45800","15.12173","0.03811"
"181.76400","15.14714","0.03827"
"182.07000","15.17261","0.03812"
"182.37600","15.19808","0.03792"
"182.68200","15.22367","0.03842"
"182.98800","15.24914","0.03837"
"183.29400","15.27467","0.03918"
"183.60000","15.30020","0.03963"
"183.90600","15.32561","0.03979"
"184.21200","15.35114","0.04052"
"184.51800","15.37661","0.04063"
"184.82400","15.40214","0.04158"
"185.13000","15.42761","0.04159"
"185.43600","15.45314","0.04228"
"185.74200","15.47867","0.04339"
"186.04800","15.50414","0.04286"
"186.35400","15.52961","0.04358"
"186.66000","15.55508","0.04397"
"186.96600","15.58067","0.02548"
"187.27200","15.60608","0.02587"
"187.57800","15.63167","0.02401"
"187.88400","15.65714","0.02345"
"188.19000","15.68262","0.02356"
"188.49600","15.70815","0.02367"
"188.80200","15.73361","0.02376"
"189.10800","15.75915","0.02431"
"189.41400","15.78462","0.02458"
"189.72000","15.81015","0.02350"
"190.02600","15.83568","0.02379"
"190.33200","15.86115","0.02415"
"190.63800","15.88668","0.02433"
"190.94400","15.91215","0.02383"
"191.25000","15.93768","0.02376"
"191.55600","15.96309","0.02435"
"191.86200","15.98862","0.02504"
"192.16800","16.01415","0.02545"
"192.47400","16.03962","0.02379"
"192.78000","16.06521","0.02359"
"193.08600","16.09062","0.02338"
"193.39200","16.11615","0.02416"
"193.69800","16.14162","0.02446"
"194.00400","16.16715","0.02579"
"194.31000","16.19262","0.02549"
"194.61600","16.21809","0.02591"
"194.92200","16.24368","0.02704"
"195.22800","16.26915","0.02756"
"195.53400","16.29468","0.02822"
"195.84000","16.32009","0.02901"
"196.14600","16.34568","0.02962"
"196.45200","16.37115","0.02987"
"196.75800","16.39662","0.03078"
"197.06400","16.42215","0.03070"
"197.37000","16.44762","0.03141"
"197.67600","16.47315","0.03147"
"197.98200","16.49862","0.03154"
"198.28800","16.52415","0.03244"
"198.59400","16.54962","0.03202"
"198.90000","16.57509","0.03250"
"199.20600","16.60068","0.03286"
"199.51200","16.62615","0.03376"
"199.81800","16.65168","0.03409"
"200.12400","16.67710","0.03415"
"200.43000","16.70268","0.03535"
"200.73600","16.72816","0.03495"
"201.04200","16.75363","0.03601"
"201.34800","16.77915","0.03606"
"201.65400","16.80463","0.03617"
"201.96000","16.83016","0.03511"
"202.26600","16.85557","0.03534"
"202.57200","16.88116","0.03550"
"202.87800","16.90657","0.03514"
"203.18400","16.93210","0.03531"
"203.49000","16.95763","0.03614"
"203.79600","16.98310","0.03670"
"204.10200","17.00869","0.03697"
"204.40800","17.03416","0.03537"
"204.71400","17.05969","0.03452"
"205.02000","17.08510","0.03523"
"205.32600","17.11063","0.03558"
"205.63200","17.13610","0.03583"
"205.93800","17.16163","0.03658"
"206.24400","17.18722","0.03662"
"206.55000","17.21263","0.03700"
"206.85600","17.23816","0.03755"
"207.16200","17.26357","0.03802"
"207.46800","17.28910","0.03827"
"207.77400","17.31463","0.03580"
"208.08000","17.34010","0.03246"
"208.38600","17.36569","0.03214"
"208.69200","17.39110","0.03198"
"208.99800","17.41663","0.03245"
"209.30400","17.44210","0.03409"
"209.61000","17.46763","0.03241"
"209.91600","17.49310","0.03351"
"210.22200","17.51857","0.03446"
"210.52800","17.54416","0.03417"
"210.83400","17.56963","0.03478"
"211.14000","17.59522","0.03575"
"211.44600","17.62063","0.03554"
"211.75200","17.64616","0.03637"
"212.05800","17.67157","0.03676"
"212.36400","17.69710","0.03756"
"212.67000","17.72264","0.03711"
"212.97600","17.74810","0.03688"
"213.28200","17.77363","0.03775"
"213.58800","17.79910","0.03772"
"213.89400","17.82469","0.03698"
"214.20000","17.85011","0.03827"
"214.50600","17.87564","0.03849"
"214.81200","17.90117","0.03939"
"215.11800","17.92664","0.03999"
"215.42400","17.95217","0.04016"
"215.73000","17.97764","0.04138"
"216.03600","18.00311","0.04144"
"216.34200","18.02858","0.04314"
"216.64800","18.05411","0.04398"
"216.95400","18.07970","0.04352"
"217.26000","18.10505","0.04446"
"217.56600","18.13064","0.04500"
"217.87200","18.15611","0.04556"
"218.17800","18.18164","0.04494"
"218.48400","18.20711","0.04527"
"218.79000","18.23270","0.04618"
"219.09600","18.25817","0.04719"
"219.40200","18.28364","0.04797"
"219.70800","18.30911","0.04844"
"220.01400","18.33464","0.04575"
"220.32000","18.36017","0.04469"
"220.62600","18.38564","0.04583"
"220.93200","18.41111","0.04648"
"221.23800","18.43664","0.04665"
"221.54400","18.46211","0.04432"
"221.85000","18.48764","0.04469"
"222.15600","18.51311","0.04493"
"222.46200","18.53870","0.04577"
"222.76800","18.56417","0.04323"
"223.07400","18.58970","0.04320"
"223.38000","18.61511","0.04409"
"223.68600","18.64058","0.04452"
"223.99200","18.66611","0.04490"
"224.29800","18.69164","0.04436"
"224.60400","18.71717","0.04619"
"224.91000","18.74258","0.04652"
"225.21600","18.76818","0.04799"
"225.52200","18.79364","0.04840"
"225.82800","18.81911","0.04637"
"226.13400","18.84464","0.04812"
"226.44000","18.87012","0.04946"
"226.74600","18.89565","0.05026"
"227.05200","18.92111","0.04948"
"227.35800","18.94670","0.05017"
"227.66400","18.97218","0.05053"
"227.97000","18.99764","0.05109"
"228.27600","19.02324","0.05271"
"228.58200","19.04859","0.05131"
"228.88800","19.07412","0.04974"
"229.19400","19.09959","0.04911"
"229.50000","19.12524","0.04658"
"229.80600","19.15059","0.04702"
"230.11200","19.17612","0.04368"
"230.41800","19.20165","0.04238"
"230.72400","19.22712","0.04357"
"231.03000","19.25259","0.04445"
"231.33600","19.27806","0.04551"
"231.64200","19.30365","0.04710"
"231.94800","19.32912","0.04756"
"232.25400","19.35465","0.04802"
"232.56000","19.38018","0.04900"
"232.86600","19.40565","0.04963"
"233.17200","19.43112","0.05007"
"233.47800","19.45659","0.05118"
"233.78400","19.48212","0.05170"
"234.09000","19.50765","0.05205"
"234.39600","19.53318","0.05246"
"234.70200","19.55871","0.05256"
"235.00800","19.58412","0.05167"
"235.31400","19.60965","0.05294"
"235.62000","19.63506","0.05355"
"235.92600","19.66065","0.04963"
"236.23200","19.68618","0.05050"
"236.53800","19.71171","0.05198"
"236.84400","19.73718","0.05207"
"237.15000","19.76259","0.05256"
"237.45600","19.78818","0.05339"
"237.76200","19.81359","0.05491"
"238.06800","19.83918","0.05582"
"238.37400","19.86459","0.05568"
"238.68000","19.89018","0.05602"
"238.98600","19.91566","0.05771"
"239.29200","19.94113","0.05698"
"239.59800","19.96659","0.05708"
"239.90400","19.99207","0.05695"
"240.21000","20.01765","0.05546"
"240.51600","20.04313","0.05561"
"240.82200","20.06866","0.05648"
"241.12800","20.09412","0.05630"
"241.43400","20.11960","0.05789"
"241.74000","20.14519","0.05336"
"242.04600","20.17060","0.05243"
"242.35200","20.19613","0.05304"
"242.65800","20.22160","0.05538"
"242.96400","20.24713","0.05582"
"243.27000","20.27266","0.05676"
"243.57600","20.29813","0.05706"
"243.88200","20.32372","0.05702"
"244.18800","20.34907","0.05812"
"244.49400","20.37466","0.05770"
"244.80000","20.40007","0.05727"
"245.10600","20.42566","0.05691"
"245.41200","20.45113","0.05771"
"245.71800","20.47666","0.05929"
"246.02400","20.50219","0.05954"
"246.33000","20.52760","0.05869"
"246.63600","20.55313","0.05855"
"246.94200","20.57854","0.05520"
"247.24800","20.60413","0.05535"
"247.55400","20.62960","0.05632"
"247.86000","20.65513","0.05702"
"248.16600","20.68066","0.05622"
"248.47200","20.70607","0.05522"
"248.77800","20.73166","0.05583"
"249.08400","20.75713","0.05588"
"249.39000","20.78266","0.05784"
"249.69600","20.80813","0.05800"
"250.00200","20.83366","0.05831"
"250.30800","20.85919","0.05819"
"250.61400","20.88466","0.05945"
"250.92000","20.91013","0.05986"
"251.22600","20.93560","0.05354"
"251.53200","20.96113","0.05302"
"251.83800","20.98660","0.05422"
"252.14400","21.01213","0.05485"
"252.45000","21.03766","0.05499"
"252.75600","21.06307","0.05727"
"253.06200","21.08867","0.05851"
"253.36800","21.11407","0.05859"
"253.67400","21.13966","0.05914"
"253.98000","21.16508","0.05421"
"254.28600","21.19066","0.04895"
"254.59200","21.21614","0.04918"
"254.89800","21.24161","0.04751"
"255.20400","21.26720","0.04939"
"255.51000","21.29255","0.04925"
"255.81600","21.31814","0.04738"
"256.12200","21.34355","0.04070"
"256.42800","21.36914","0.03676"
"256.73400","21.39461","0.03136"
"257.04000","21.42014","0.03212"
"257.34600","21.44573","0.02984"
"257.65200","21.47114","0.02828"
"257.95800","21.49661","0.03028"
"258.26400","21.52208","0.03047"
"258.57000","21.54761","0.03132"
"258.87600","21.57314","0.03296"
"259.18200","21.59861","0.03416"
"259.48800","21.62420","0.03526"
"259.79400","21.64967","0.03560"
"260.10000","21.67520","0.03632"
"260.40600","21.70061","0.03721"
"260.71200","21.72620","0.03781"
"261.01800","21.75167","0.03889"
"261.32400","21.77714","0.03939"
"261.63000","21.80267","0.03998"
"261.93600","21.82814","0.04015"
"262.24200","21.85367","0.04069"
"262.54800","21.87908","0.04171"
"262.85400","21.90467","0.04189"
"263.16000","21.93008","0.04130"
"263.46600","21.95561","0.04233"
"263.77200","21.98114","0.04278"
"264.07800","22.00661","0.04388"
"264.38400","22.03214","0.04476"
"264.69000","22.05761","0.04617"
"264.99600","22.08320","0.04623"
"265.30200","22.10861","0.04713"
"265.60800","22.13415","0.04738"
"265.91400","22.15968","0.04825"
"266.22000","22.18515","0.04874"
"266.52600","22.21068","0.04911"
"266.83200","22.23609","0.04973"
"267.13800","22.26162","0.05030"
"267.44400","22.28709","0.05061"
"267.75000","22.31262","0.05103"
"268.05600","22.33809","0.05146"
"268.36200","22.36362","0.05162"
"268.66800","22.38914","0.05249"
"268.97400","22.41462","0.05339"
"269.28000","22.44021","0.04903"
"269.58600","22.46562","0.04804"
"269.89200","22.49115","0.05015"
"270.19800","22.51668","0.05036"
"270.50400","22.54215","0.05017"
"270.81000","22.56768","0.05113"
"271.11600","22.59309","0.05204"
"271.42200","22.61868","0.05010"
"271.72800","22.64415","0.05073"
"272.03400","22.66962","0.05148"
"272.34000","22.69509","0.05224"
"272.64600","22.72062","0.05365"
"272.95200","22.74615","0.05445"
"273.25800","22.77162","0.05535"
"273.56400","22.79715","0.05622"
"273.87000","22.82262","0.05720"
"274.17600","22.84815","0.05750"
"274.48200","22.87362","0.05700"
"274.78800","22.89909","0.05668"
"275.09400","22.92462","0.05703"
"275.40000","22.95015","0.05806"
"275.70600","22.97568","0.05897"
"276.01200","23.00109","0.05993"
"276.31800","23.02662","0.06085"
"276.62400","23.05215","0.06161"
"276.93000","23.07756","0.06239"
"277.23600","23.10315","0.06317"
"277.54200","23.12863","0.06364"
"277.84800","23.15415","0.06419"
"278.15400","23.17962","0.06271"
"278.46000","23.20515","0.06347"
"278.76600","23.23062","0.06446"
"279.07200","23.25616","0.06257"
"279.37800","23.28169","0.05800"
"279.68400","23.30716","0.05951"
"279.99000","23.33269","0.06120"
"280.29600","23.35810","0.06170"
"280.60200","23.38369","0.06177"
"280.90800","23.40910","0.06227"
"281.21400","23.43468","0.05991"
"281.52000","23.46016","0.05986"
"281.82600","23.48563","0.05743"
"282.13200","23.51116","0.05816"
"282.43800","23.53663","0.06059"
"282.74400","23.56216","0.06150"
"283.05000","23.58763","0.06293"
"283.35600","23.61316","0.06359"
"283.66200","23.63863","0.06448"
"283.96800","23.66410","0.06497"
"284.27400","23.68963","0.06577"
"284.58000","23.71510","0.06511"
"284.88600","23.74063","0.06536"
"285.19200","23.76610","0.06435"
"285.49800","23.79163","0.06527"
"285.80400","23.81716","0.06595"
"286.11000","23.84257","0.05899"
"286.41600","23.86810","0.05916"
"286.72200","23.89357","0.06129"
"287.02800","23.91916","0.06145"
"287.33400","23.94463","0.06294"
"287.64000","23.97016","0.06452"
"287.94600","23.99569","0.06600"
"288.25200","24.02116","0.06777"
"288.55800","24.04669","0.06786"
"288.86400","24.07210","0.06966"
"289.17000","24.09769","0.07091"
"289.47600","24.12310","0.07287"
"289.78200","24.14869","0.07382"
"290.08800","24.17416","0.07470"
"290.39400","24.19963","0.07400"
"290.70000","24.22516","0.07505"
"291.00600","24.25063","0.07593"
"291.31200","24.27611","0.07619"
"291.61800","24.30163","0.07431"
"291.92400","24.32717","0.07557"
"292.23000","24.35263","0.05738"
"292.53600","24.37817","0.05120"
"292.84200","24.40370","0.05452"
"293.14800","24.42917","0.05461"
"293.45400","24.45464","0.05327"
"293.76000","24.48011","0.05596"
"294.06600","24.50564","0.05787"
"294.37200","24.53111","0.05903"
"294.67800","24.55664","0.05897"
"294.98400","24.58217","0.06078"
"295.29000","24.60764","0.06297"
"295.59600","24.63311","0.06105"
"295.90200","24.65858","0.06186"
"296.20800","24.68417","0.06376"
"296.51400","24.70964","0.06075"
"296.82000","24.73511","0.06191"
"297.12600","24.76064","0.06249"
"297.43200","24.78611","0.06302"
"297.73800","24.81164","0.06500"
"298.04400","24.83705","0.06489"
"298.35000","24.86264","0.06628"
"298.65600","24.88817","0.06694"
"298.96200","24.91370","0.06865"
"299.26800","24.93917","0.07041"
"299.57400","24.96464","0.07143"
"299.88000","24.99011","0.07181"
"300.18600","25.01558","0.07329"
"300.49200","25.04117","0.07522"
"300.79800","25.06658","0.07653"
"301.10400","25.09217","0.07878"
"301.41000","25.11764","0.08036"
"301.71600","25.14311","0.08112"
"302.02200","25.16864","0.08208"
"302.32800","25.19411","0.08246"
"302.63400","25.21964","0.08382"
"302.94000","25.24512","0.08429"
"303.24600","25.27070","0.08522"
"303.55200","25.29617","0.08637"
"303.85800","25.32165","0.08695"
"304.16400","25.34717","0.08748"
"304.47000","25.37259","0.08841"
"304.77600","25.39812","0.08881"
"305.08200","25.42359","0.08897"
"305.38800","25.44917","0.08955"
"305.69400","25.47465","0.08980"
"306.00000","25.50011","0.09003"
"306.30600","25.52565","0.09088"
"306.61200","25.55112","0.09084"
"306.91800","25.57665","0.09189"
"307.22400","25.60206","0.09168"
"307.53000","25.62765","0.09203"
"307.83600","25.65318","0.07373"
"308.14200","25.67865","0.06995"
"308.44800","25.70418","0.07603"
"308.75400","25.72965","0.07788"
"309.06000","25.75512","0.07661"
"309.36600","25.78059","0.07678"
"309.67200","25.80618","0.08002"
"309.97800","25.83159","0.08342"
"310.28400","25.85712","0.08307"
"310.59000","25.88271","0.08224"
"310.89600","25.90812","0.08462"
"311.20200","25.93365","0.08665"
"311.50800","25.95906","0.08759"
"311.81400","25.98465","0.08765"
"312.12000","26.01012","0.08833"
"312.42600","26.03565","0.08940"
"312.73200","26.06124","0.09033"
"313.03800","26.08665","0.09111"
"313.34400","26.11218","0.09140"
"313.65000","26.13765","0.09267"
"313.95600","26.16324","0.09309"
"314.26200","26.18859","0.09385"
"314.56800","26.21412","0.09490"
"314.87400","26.23965","0.09441"
"315.18000","26.26512","0.09551"
"315.48600","26.29066","0.09662"
"315.79200","26.31606","0.09735"
"316.09800","26.34165","0.09810"
"316.40400","26.36712","0.09926"
"316.71000","26.39266","0.10013"
"317.01600","26.41818","0.09972"
"317.32200","26.44360","0.10003"
"317.62800","26.46913","0.10066"
"317.93400","26.49460","0.10162"
"318.24000","26.52013","0.09774"
"318.54600","26.54560","0.09448"
"318.85200","26.57113","0.09534"
"319.15800","26.59666","0.09595"
"319.46400","26.62213","0.09735"
"319.77000","26.64766","0.09830"
"320.07600","26.67313","0.09953"
"320.38200","26.69866","0.09990"
"320.68800","26.72413","0.10077"
"320.99400","26.74966","0.10095"
"321.30000","26.77513","0.09939"
"321.60600","26.80066","0.09723"
"321.91200","26.82619","0.09725"
"322.21800","26.85160","0.09790"
"322.52400","26.87713","0.09871"
"322.83000","26.90260","0.09977"
"323.13600","26.92813","0.10047"
"323.44200","26.95360","0.10101"
"323.74800","26.97913","0.10194"
"324.05400","27.00466","0.10281"
"324.36000","27.03013","0.10364"
"324.66600","27.05566","0.10368"
"324.97200","27.08107","0.10325"
"325.27800","27.10666","0.10382"
"325.58400","27.13213","0.10484"
"325.89000","27.15760","0.10544"
"326.19600","27.18319","0.10564"
"326.50200","27.20866","0.10611"
"326.80800","27.23413","0.10663"
"327.11400","27.25960","0.10792"
"327.42000","27.28519","0.10903"
"327.72600","27.31060","0.11064"
"328.03200","27.33607","0.11159"
"328.33800","27.36166","0.11253"
"328.64400","27.38713","0.11399"
"328.95000","27.41266","0.11387"
"329.25600","27.43808","0.11453"
"329.56200","27.46372","0.11327"
"329.86800","27.48914","0.11020"
"330.17400","27.51467","0.11128"
"330.48000","27.54014","0.11134"
"330.78600","27.56561","0.11322"
"331.09200","27.59119","0.11467"
"331.39800","27.61661","0.11457"
"331.70400","27.64220","0.11529"
"332.01000","27.66761","0.11427"
"332.31600","27.69314","0.10020"
"332.62200","27.71861","0.10004"
"332.92800","27.74408","0.10178"
"333.23400","27.76967","0.10367"
"333.54000","27.79514","0.10323"
"333.84600","27.82067","0.10426"
"334.15200","27.84608","0.10602"
"334.45800","27.87167","0.10697"
"334.76400","27.89714","0.10932"
"335.07000","27.92261","0.10935"
"335.37600","27.94814","0.11031"
"335.68200","27.97367","0.11116"
"335.98800","27.99920","0.11299"
"336.29400","28.02467","0.11428"
"336.60000","28.05014","0.11441"
"336.90600","28.07561","0.11580"
"337.21200","28.10108","0.11715"
"337.51800","28.12661","0.11829"
"337.82400","28.15208","0.11955"
"338.13000","28.17761","0.12105"
"338.43600","28.20308","0.12177"
"338.74200","28.22867","0.12420"
"339.04800","28.25414","0.12572"
"339.35400","28.27961","0.12748"
"339.66000","28.30514","0.12880"
"339.96600","28.33061","0.13111"
"340.27200","28.35620","0.13166"
"340.57800","28.38161","0.11591"
"340.88400","28.40714","0.11794"
"341.19000","28.43262","0.11862"
"341.49600","28.45815","0.12060"
"341.80200","28.48367","0.12268"
"342.10800","28.50914","0.12655"
"342.41400","28.53461","0.12902"
"342.72000","28.56014","0.13008"
"343.02600","28.58574","0.12817"
"343.33200","28.61109","0.10564"
"343.63800","28.63668","0.10649"
"343.94400","28.66215","0.10635"
"344.25000","28.68761","0.10630"
"344.55600","28.71315","0.10788"
"344.86200","28.73862","0.10910"
"345.16800","28.76415","0.11111"
"345.47400","28.78962","0.11144"
"345.78000","28.81509","0.11212"
"346.08600","28.84068","0.11439"
"346.39200","28.86609","0.11631"
"346.69800","28.89162","0.11795"
"347.00400","28.91709","0.11941"
"347.31000","28.94262","0.12066"
"347.61600","28.96809","0.12338"
"347.92200","28.99368","0.12578"
"348.22800","29.01915","0.12840"
"348.53400","29.04462","0.12926"
"348.84000","29.07015","0.11316"
"349.14600","29.09562","0.11571"
"349.45200","29.12115","0.11701"
"349.75800","29.14662","0.11859"
"350.06400","29.17215","0.12006"
"350.37000","29.19762","0.12395"
"350.67600","29.22309","0.12801"
"350.98200","29.24862","0.13085"
"351.28800","29.27409","0.13169"
"351.59400","29.29968","0.13390"
"351.90000","29.32515","0.13658"
"352.20600","29.35068","0.13994"
"352.51200","29.37609","0.14232"
"352.81800","29.40157","0.14344"
"353.12400","29.42715","0.14482"
"353.43000","29.45262","0.14633"
"353.73600","29.47816","0.14827"
"354.04200","29.50356","0.14946"
"354.34800","29.52916","0.15182"
"354.65400","29.55463","0.15306"
"354.96000","29.58016","0.15420"
"355.26600","29.60568","0.15437"
"355.57200","29.63110","0.15455"
"355.87800","29.65663","0.14560"
"356.18400","29.68210","0.14789"
"356.49000","29.70769","0.15128"
"356.79600","29.73315","0.15275"
"357.10200","29.75863","0.15343"
"357.40800","29.78422","0.15451"
"357.71400","29.80963","0.15617"
"358.02000","29.83516","0.15807"
"358.32600","29.86057","0.15956"
"358.63200","29.88622","0.16058"
"358.93800","29.91163","0.16148"
"359.24400","29.93716","0.16239"
"359.55000","29.96263","0.16351"
"359.85600","29.98810","0.16453"
"360.16200","30.01357","0.16578"
"360.46800","30.03904","0.16626"
"360.77400","30.06463","0.16806"
"361.08000","30.09016","0.16942"
"361.38600","30.11563","0.16979"
"361.69200","30.14116","0.17058"
"361.99800","30.16663","0.17142"
"362.30400","30.19216","0.17270"
"362.61000","30.21757","0.17393"
"362.91600","30.24316","0.17485"
"363.22200","30.26863","0.17661"
"363.52800","30.29416","0.17763"
"363.83400","30.31969","0.17854"
"364.14000","30.34510","0.17920"
"364.44600","30.37063","0.18085"
"364.75200","30.39604","0.17454"
"365.05800","30.42163","0.17549"
"365.36400","30.44711","0.17751"
"365.67000","30.47269","0.17940"
"365.97600","30.49816","0.17987"
"366.28200","30.52363","0.17860"
"366.58800","30.54917","0.17461"
"366.89400","30.57463","0.16651"
"367.20000","30.60017","0.16792"
"367.50600","30.62557","0.16897"
"367.81200","30.65117","0.16971"
"368.11800","30.67664","0.16797"
"368.42400","30.70217","0.16800"
"368.73000","30.72764","0.16869"
"369.03600","30.75311","0.16472"
"369.34200","30.77864","0.16255"
"369.64800","30.80411","0.14732"
"369.95400","30.82964","0.14552"
"370.26000","30.85511","0.13458"
"370.56600","30.88064","0.13341"
"370.87200","30.90617","0.13318"
"371.17800","30.93158","0.12839"
"371.48400","30.95711","0.12603"
"371.79000","30.98258","0.12785"
"372.09600","31.00817","0.12926"
"372.40200","31.03364","0.12848"
"372.70800","31.05917","0.12813"
"373.01400","31.08470","0.12934"
"373.32000","31.11011","0.12883"
"373.62600","31.13564","0.12974"
"373.93200","31.16111","0.12989"
"374.23800","31.18670","0.12969"
"374.54400","31.21217","0.12303"
"374.85000","31.23764","0.12462"
"375.15600","31.26323","0.12579"
"375.46200","31.28864","0.12886"
"375.76800","31.31411","0.13057"
"376.07400","31.33958","0.13224"
"376.38000","31.36517","0.13479"
"376.68600","31.39064","0.13796"
"376.99200","31.41617","0.14004"
"377.29800","31.44170","0.14196"
"377.60400","31.46711","0.14408"
"377.91000","31.49264","0.14585"
"378.21600","31.51811","0.14761"
"378.52200","31.54364","0.14986"
"378.82800","31.56911","0.15186"
"379.13400","31.59464","0.15283"
"379.44000","31.62017","0.15432"
"379.74600","31.64564","0.15558"
"380.05200","31.67117","0.15703"
"380.35800","31.69658","0.15835"
"380.66400","31.72217","0.15927"
"380.97000","31.74764","0.16091"
"381.27600","31.77317","0.16206"
"381.58200","31.79864","0.16332"
"381.88800","31.82412","0.16536"
"382.19400","31.84965","0.16664"
"382.50000","31.87506","0.16717"
"382.80600","31.90064","0.16852"
"383.11200","31.92605","0.16971"
"383.41800","31.95164","0.17082"
"383.72400","31.97712","0.17233"
"384.03000","32.00259","0.17275"
"384.33600","32.02818","0.17449"
"384.64200","32.05365","0.17584"
"384.94800","32.07917","0.17676"
"385.25400","32.10458","0.17835"
"385.56000","32.13018","0.18017"
"385.86600","32.15565","0.18087"
"386.17200","32.18112","0.18254"
"386.47800","32.20665","0.18374"
"386.78400","32.23212","0.18470"
"387.09000","32.25765","0.18551"
"387.39600","32.28312","0.18760"
"387.70200","32.30865","0.18863"
"388.00800","32.33412","0.18992"
"388.31400","32.35959","0.19169"
"388.62000","32.38512","0.19250"
"388.92600","32.41065","0.19365"
"389.23200","32.43618","0.19370"
"389.53800","32.46159","0.19362"
"389.84400","32.48718","0.19307"
"390.15000","32.51265","0.19282"
"390.45600","32.53812","0.19469"
"390.76200","32.56365","0.19627"
"391.06800","32.58912","0.19735"
"391.37400","32.61465","0.19800"
"391.68000","32.64006","0.18262"
"391.98600","32.66565","0.18135"
"392.29200","32.69112","0.18432"
"392.59800","32.71659","0.18665"
"392.90400","32.74212","0.18803"
"393.21000","32.76765","0.18854"
"393.51600","32.79318","0.18926"
"393.82200","32.81859","0.19089"
"394.12800","32.84418","0.19216"
"394.43400","32.86959","0.19151"
"394.74000","32.89513","0.18956"
"395.04600","32.92065","0.18911"
"395.35200","32.94613","0.18709"
"395.65800","32.97165","0.18769"
"395.96400","32.99712","0.18868"
"396.27000","33.02266","0.18977"
"396.57600","33.04813","0.18980"
"396.88200","33.07360","0.19130"
"397.18800","33.09912","0.19151"
"397.49400","33.12460","0.19303"
"397.80000","33.15012","0.19416"
"398.10600","33.17566","0.19486"
"398.41200","33.20119","0.19611"
"398.71800","33.22666","0.19678"
"399.02400","33.25213","0.19788"
"399.33000","33.27766","0.19889"
"399.63600","33.30313","0.20020"
"399.94200","33.32866","0.20121"
"400.24800","33.35413","0.20192"
"400.55400","33.37972","0.20251"
"400.86000","33.40513","0.20378"
"401.16600","33.43066","0.20425"
"401.47200","33.45607","0.20520"
"401.77800","33.48160","0.20556"
"402.08400","33.50713","0.20643"
"402.39000","33.53260","0.20715"
"402.69600","33.55813","0.20745"
"403.00200","33.58360","0.20806"
"403.30800","33.60919","0.20903"
"403.61400","33.63466","0.20873"
"403.92000","33.66013","0.20867"
"404.22600","33.68566","0.20913"
"404.53200","33.71113","0.21001"
"404.83800","33.73666","0.21070"
"405.14400","33.76213","0.21106"
"405.45000","33.78766","0.21206"
"405.75600","33.81313","0.21240"
"406.06200","33.83860","0.21312"
"406.36800","33.86413","0.21376"
"406.67400","33.88960","0.21515"
"406.98000","33.91513","0.21569"
"407.28600","33.94061","0.21726"
"407.59200","33.96619","0.21810"
"407.89800","33.99160","0.21856"
"408.20400","34.01714","0.21968"
"408.51000","34.04266","0.22038"
"408.81600","34.06813","0.22211"
"409.12200","34.09367","0.22192"
"409.42800","34.11908","0.21312"
"409.73400","34.14473","0.20880"
"410.04000","34.17014","0.20869"
"410.34600","34.19566","0.20952"
"410.65200","34.22113","0.21052"
"410.95800","34.24667","0.21189"
"411.26400","34.27214","0.21336"
"411.57000","34.29755","0.21520"
"411.87600","34.32314","0.21654"
"412.18200","34.34861","0.21723"
"412.48800","34.37414","0.21740"
"412.79400","34.39967","0.21840"
"413.10000","34.42514","0.21985"
"413.40600","34.45061","0.22113"
"413.71200","34.47608","0.22217"
"414.01800","34.50167","0.22171"
"414.32400","34.52708","0.22045"
"414.63000","34.55261","0.22133"
"414.93600","34.57814","0.22246"
"415.24200","34.60361","0.22360"
"415.54800","34.62914","0.22490"
"415.85400","34.65461","0.22650"
"416.16000","34.68014","0.22782"
"416.46600","34.70561","0.22898"
"416.77200","34.73120","0.23088"
"417.07800","34.75667","0.23277"
"417.38400","34.78214","0.23463"
"417.69000","34.80767","0.23613"
"417.99600","34.83315","0.23745"
"418.30200","34.85867","0.23895"
"418.60800","34.88408","0.24010"
"418.91400","34.90967","0.24124"
"419.22000","34.93514","0.24234"
"419.52600","34.96067","0.24359"
"419.83200","34.98615","0.24445"
"420.13800","35.01162","0.24537"
"420.44400","35.03709","0.24630"
"420.75000","35.06255","0.24766"
"421.05600","35.08814","0.24847"
"421.36200","35.11361","0.25019"
"421.66800","35.13915","0.25136"
"421.97400","35.16468","0.25196"
"422.28000","35.19009","0.25329"
"422.58600","35.21568","0.25416"
"422.89200","35.24109","0.25533"
"423.19800","35.26667","0.25648"
"423.50400","35.29215","0.25774"
"423.81000","35.31768","0.25887"
"424.11600","35.34315","0.26015"
"424.42200","35.36862","0.26105"
"424.72800","35.39409","0.26269"
"425.03400","35.41956","0.26397"
"425.34000","35.44515","0.26634"
"425.64600","35.47062","0.26614"
"425.95200","35.49615","0.26723"
"426.25800","35.52168","0.26729"
"426.56400","35.54709","0.26843"
"426.87000","35.57262","0.26941"
"427.17600","35.59809","0.27054"
"427.48200","35.62368","0.27208"
"427.78800","35.64909","0.27378"
"428.09400","35.67468","0.27499"
"428.40000","35.70015","0.27690"
"428.70600","35.72568","0.27859"
"429.01200","35.75109","0.28038"
"429.31800","35.77656","0.28330"
"429.62400","35.80215","0.28476"
"429.93000","35.82756","0.01709"
"430.23600","35.85315","0.01991"
"430.54200","35.87868","0.00996"
"430.84800","35.90416","0.00916"
"431.15400","35.92968","0.01217"
"431.46000","35.95509","0.00984"
"431.76600","35.98068","0.00946"
"432.07200","36.00609","0.01160"
"432.37800","36.03162","0.01247"
"432.68400","36.05722","0.00918"
"432.99000","36.08268","0.01286"
"433.29600","36.10815","0.00941"
"433.60200","36.13356","0.01309"
"433.90800","36.15915","0.01049"
"434.21400","36.18456","0.01078"
"434.52000","36.21016","0.00982"
"434.82600","36.23563","0.01297"
"435.13200","36.26110","0.01066"
"435.43800","36.28662","0.00961"
"435.74400","36.31210","0.01190"
"436.05000","36.33762","0.01012"
"436.35600","36.36304","0.01051"
"436.66200","36.38869","0.01032"
"436.96800","36.41410","0.01288"
"437.27400","36.43963","0.00976"
"437.58000","36.46516","0.01278"
"437.88600","36.49057","0.01017"
"438.19200","36.51616","0.01241"
"438.49800","36.54157","0.01007"
"438.80400","36.56716","0.01064"
"439.11000","36.59263","0.01123"
"439.41600","36.61810","0.01143"
"439.72200","36.64369","0.01114"
"440.02800","36.66916","0.01060"
"440.33400","36.69463","0.01288"
"440.64000","36.72010","0.01010"
"440.94600","36.74569","0.01197"
"441.25200","36.77110","0.01054"
"441.55800","36.79663","0.01361"
"441.86400","36.82216","0.01095"
"442.17000","36.84763","0.01135"
"442.47600","36.87316","0.01243"
"442.78200","36.89863","0.01117"
"443.08800","36.92422","0.01291"
"443.39400","36.94957","0.01072"
"443.70000","36.97516","0.01405"
"444.00600","37.00063","0.01123"
"444.31200","37.02617","0.01297"
"444.61800","37.05163","0.01244"
"444.92400","37.07710","0.01235"
"445.23000","37.10270","0.01258"
"445.53600","37.12811","0.01218"
"445.84200","37.15364","0.01474"
"446.14800","37.17910","0.01210"
"446.45400","37.20464","0.01379"
"446.76000","37.23016","0.01324"
"447.06600","37.25557","0.01371"
"447.37200","37.28117","0.01389"
"447.67800","37.30658","0.01301"
"447.98400","37.33211","0.01577"
"448.29000","37.35764","0.01335"
"448.59600","37.38311","0.01414"
"448.90200","37.40870","0.01492"
"449.20800","37.43417","0.01428"
"449.51400","37.45964","0.01530"
"449.82000","37.48511","0.01478"
"450.12600","37.51064","0.01544"
"450.43200","37.53611","0.01551"
"450.73800","37.56164","0.01512"
"451.04400","37.58717","0.01696"
"451.35000","37.61264","0.01527"
"451.65600","37.63817","0.01592"
"451.83200","37.65282","0.01598"