File: Force_trajectories/161114/Specimen_RawData_1.csv
End date,"11/14/2016"
Specimen label,"20AG60"
Maximum Load,"0.05133",N

Time,Extension,Load
(s),(mm),(N)
"0.00000","0.00000","-0.00363"
"0.14400","0.00819","-0.00187"
"0.28800","0.02338","-0.00152"
"0.43200","0.03617","-0.00093"
"0.57600","0.04825","-0.00067"
"0.72000","0.06021","-0.00074"
"0.86400","0.07217","0.00156"
"1.00800","0.08418","0.00118"
"1.15200","0.09620","0.00098"
"1.29600","0.10816","0.00192"
"1.44000","0.12012","0.00250"
"1.58400","0.13213","0.00272"
"1.72800","0.14415","0.00342"
"1.87200","0.15617","0.00281"
"2.01600","0.16807","0.00363"
"2.16000","0.18021","0.00391"
"2.30400","0.19216","0.00432"
"2.44800","0.20412","0.00466"
"2.59200","0.21608","0.00431"
"2.73600","0.22816","0.00519"
"2.88000","0.24017","0.00539"
"3.02400","0.25213","0.00588"
"3.16800","0.26409","0.00556"
"3.31200","0.27617","0.00462"
"3.45600","0.28813","0.00625"
"3.60000","0.30008","0.00611"
"3.74400","0.31216","0.00688"
"3.88800","0.32418","0.00637"
"4.03200","0.33620","0.00662"
"4.17600","0.34809","0.00623"
"4.32000","0.36011","0.00647"
"4.46400","0.37213","0.00717"
"4.60800","0.38409","0.00723"
"4.75200","0.39605","0.00770"
"4.89600","0.40812","0.00730"
"5.04000","0.42020","0.00755"
"5.18400","0.43210","0.00806"
"5.32800","0.44412","0.00821"
"5.47200","0.45613","0.00829"
"5.61600","0.46815","0.00782"
"5.76000","0.48011","0.00874"
"5.90400","0.49207","0.00841"
"6.04800","0.50415","0.00905"
"6.19200","0.51616","0.00950"
"6.33600","0.52812","0.00845"
"6.48000","0.54014","0.00908"
"6.62400","0.55216","0.00863"
"6.76800","0.56411","0.00869"
"6.91200","0.57607","0.00873"
"7.05600","0.58815","0.00864"
"7.20000","0.60017","0.00940"
"7.34400","0.61219","0.00943"
"7.48800","0.62414","0.00939"
"7.63200","0.63616","0.00992"
"7.77600","0.64818","0.00997"
"7.92000","0.66014","0.00911"
"8.06400","0.67215","0.00976"
"8.20800","0.68417","0.00994"
"8.35200","0.69619","0.00983"
"8.49600","0.70815","0.00992"
"8.64000","0.72016","0.01059"
"8.78400","0.73218","0.00958"
"8.92800","0.74414","0.01077"
"9.07200","0.75610","0.01006"
"9.21600","0.76818","0.01029"
"9.36000","0.78013","0.01030"
"9.50400","0.79215","0.01040"
"9.64800","0.80417","0.01016"
"9.79200","0.81613","0.01071"
"9.93600","0.82814","0.01046"
"10.08000","0.84004","0.00995"
"10.22400","0.85218","0.01092"
"10.36800","0.86414","0.01042"
"10.51200","0.87616","0.01146"
"10.65600","0.88805","0.01110"
"10.80000","0.90019","0.01128"
"10.94400","0.91221","0.01091"
"11.08800","0.92411","0.01136"
"11.23200","0.93612","0.01148"
"11.37600","0.94820","0.01145"
"11.52000","0.96022","0.01167"
"11.66400","0.97212","0.01178"
"11.80800","0.98414","0.01125"
"11.95200","0.99615","0.01167"
"12.09600","1.00823","0.01217"
"12.24000","1.02013","0.01193"
"12.38400","1.03221","0.01253"
"12.52800","1.04422","0.01248"
"12.67200","1.05612","0.01232"
"12.81600","1.06808","0.01272"
"12.96000","1.08016","0.01283"
"13.10400","1.09218","0.01223"
"13.24800","1.10413","0.01239"
"13.39200","1.11615","0.01178"
"13.53600","1.12817","0.01230"
"13.68000","1.14019","0.01217"
"13.82400","1.15214","0.01266"
"13.96800","1.16416","0.01230"
"14.11200","1.17618","0.01208"
"14.25600","1.18814","0.01297"
"14.40000","1.20010","0.01320"
"14.54400","1.21211","0.01317"
"14.68800","1.22413","0.01371"
"14.83200","1.23615","0.01370"
"14.97600","1.24811","0.01280"
"15.12000","1.26012","0.01278"
"15.26400","1.27220","0.01348"
"15.40800","1.28416","0.01341"
"15.55200","1.29612","0.01377"
"15.69600","1.30820","0.01395"
"15.84000","1.32015","0.01434"
"15.98400","1.33211","0.01356"
"16.12800","1.34413","0.01358"
"16.27200","1.35615","0.01361"
"16.41600","1.36816","0.01350"
"16.56000","1.38012","0.01351"
"16.70400","1.39214","0.01341"
"16.84800","1.40422","0.01344"
"16.99200","1.41617","0.01380"
"17.13600","1.42807","0.01351"
"17.28000","1.44021","0.01395"
"17.42400","1.45217","0.01446"
"17.56800","1.46413","0.01336"
"17.71200","1.47614","0.01415"
"17.85600","1.48816","0.01366"
"18.00000","1.50012","0.01491"
"18.14400","1.51208","0.01359"
"18.28800","1.52409","0.01463"
"18.43200","1.53611","0.01392"
"18.57600","1.54813","0.01466"
"18.72000","1.56009","0.01447"
"18.86400","1.57217","0.01416"
"19.00800","1.58418","0.01437"
"19.15200","1.59614","0.01443"
"19.29600","1.60810","0.01451"
"19.44000","1.62018","0.01432"
"19.58400","1.63213","0.01361"
"19.72800","1.64409","0.01439"
"19.87200","1.65611","0.01479"
"20.01600","1.66819","0.01458"
"20.16000","1.68021","0.01456"
"20.30400","1.69210","0.01473"
"20.44800","1.70412","0.01506"
"20.59200","1.71620","0.01541"
"20.73600","1.72810","0.01482"
"20.88000","1.74005","0.01541"
"21.02400","1.75219","0.01494"
"21.16800","1.76421","0.01494"
"21.31200","1.77617","0.01431"
"21.45600","1.78813","0.01485"
"21.60000","1.80020","0.01520"
"21.74400","1.81216","0.01542"
"21.88800","1.82412","0.01534"
"22.03200","1.83608","0.01466"
"22.17600","1.84815","0.01567"
"22.32000","1.86011","0.01481"
"22.46400","1.87207","0.01519"
"22.60800","1.88409","0.01558"
"22.75200","1.89611","0.01481"
"22.89600","1.90812","0.01527"
"23.04000","1.92008","0.01558"
"23.18400","1.93210","0.01523"
"23.32800","1.94418","0.01585"
"23.47200","1.95613","0.01502"
"23.61600","1.96809","0.01491"
"23.76000","1.98011","0.01488"
"23.90400","1.99213","0.01535"
"24.04800","2.00403","0.01539"
"24.19200","2.01610","0.01530"
"24.33600","2.02818","0.01531"
"24.48000","2.04014","0.01527"
"24.62400","2.05210","0.01475"
"24.76800","2.06411","0.01464"
"24.91200","2.07613","0.01467"
"25.05600","2.08815","0.01580"
"25.20000","2.10011","0.01577"
"25.34400","2.11213","0.01532"
"25.48800","2.12414","0.01602"
"25.63200","2.13610","0.01573"
"25.77600","2.14812","0.01526"
"25.92000","2.16020","0.01547"
"26.06400","2.17215","0.01541"
"26.20800","2.18411","0.01546"
"26.35200","2.19607","0.01546"
"26.49600","2.20815","0.01567"
"26.64000","2.22010","0.01577"
"26.78400","2.23212","0.01528"
"26.92800","2.24414","0.01529"
"27.07200","2.25616","0.01558"
"27.21600","2.26812","0.01573"
"27.36000","2.28013","0.01502"
"27.50400","2.29215","0.01636"
"27.64800","2.30417","0.01595"
"27.79200","2.31613","0.01534"
"27.93600","2.32814","0.01677"
"28.08000","2.34016","0.01609"
"28.22400","2.35212","0.01618"
"28.36800","2.36408","0.01635"
"28.51200","2.37610","0.01537"
"28.65600","2.38817","0.01604"
"28.80000","2.40013","0.01694"
"28.94400","2.41203","0.01608"
"29.08800","2.42411","0.01648"
"29.23200","2.43618","0.01568"
"29.37600","2.44814","0.01662"
"29.52000","2.46010","0.01638"
"29.66400","2.47224","0.01636"
"29.80800","2.48420","0.01635"
"29.95200","2.49609","0.01608"
"30.09600","2.50811","0.01584"
"30.24000","2.52013","0.01645"
"30.38400","2.53209","0.01596"
"30.52800","2.54404","0.01626"
"30.67200","2.55606","0.01636"
"30.81600","2.56814","0.01632"
"30.96000","2.58010","0.01667"
"31.10400","2.59212","0.01650"
"31.24800","2.60413","0.01616"
"31.39200","2.61615","0.01655"
"31.53600","2.62811","0.01677"
"31.68000","2.64013","0.01676"
"31.82400","2.65214","0.01648"
"31.96800","2.66422","0.01676"
"32.11200","2.67612","0.01756"
"32.25600","2.68814","0.01640"
"32.40000","2.70010","0.01774"
"32.54400","2.71211","0.01664"
"32.68800","2.72407","0.01734"
"32.83200","2.73615","0.01710"
"32.97600","2.74811","0.01702"
"33.12000","2.76012","0.01634"
"33.26400","2.77208","0.01706"
"33.40800","2.78416","0.01714"
"33.55200","2.79612","0.01696"
"33.69600","2.80814","0.01714"
"33.84000","2.82009","0.01673"
"33.98400","2.83217","0.01628"
"34.12800","2.84413","0.01710"
"34.27200","2.85609","0.01715"
"34.41600","2.86810","0.01643"
"34.56000","2.88012","0.01726"
"34.70400","2.89208","0.01628"
"34.84800","2.90404","0.01718"
"34.99200","2.91617","0.01692"
"35.13600","2.92813","0.01581"
"35.28000","2.94009","0.01676"
"35.42400","2.95211","0.01704"
"35.56800","2.96413","0.01714"
"35.71200","2.97614","0.01740"
"35.85600","2.98810","0.01636"
"36.00000","3.00012","0.01752"
"36.14400","3.01214","0.01745"
"36.28800","3.02415","0.01634"
"36.43200","3.03611","0.01609"
"36.57600","3.04813","0.01722"
"36.72000","3.06015","0.01643"
"36.86400","3.07211","0.01779"
"37.00800","3.08406","0.01711"
"37.15200","3.09614","0.01666"
"37.29600","3.10816","0.01729"
"37.44000","3.12012","0.01749"
"37.58400","3.13207","0.01635"
"37.72800","3.14415","0.01714"
"37.87200","3.15617","0.01594"
"38.01600","3.16813","0.01691"
"38.16000","3.18009","0.01701"
"38.30400","3.19216","0.01680"
"38.44800","3.20412","0.01706"
"38.59200","3.21608","0.01695"
"38.73600","3.22810","0.01700"
"38.88000","3.24017","0.01699"
"39.02400","3.25213","0.01699"
"39.16800","3.26409","0.01754"
"39.31200","3.27617","0.01761"
"39.45600","3.28819","0.01757"
"39.60000","3.30008","0.01756"
"39.74400","3.31204","0.01693"
"39.88800","3.32418","0.01681"
"40.03200","3.33614","0.01706"
"40.17600","3.34809","0.01719"
"40.32000","3.36005","0.01621"
"40.46400","3.37213","0.01743"
"40.60800","3.38415","0.01746"
"40.75200","3.39605","0.01590"
"40.89600","3.40812","0.01681"
"41.04000","3.42014","0.01712"
"41.18400","3.43210","0.01670"
"41.32800","3.44406","0.01702"
"41.47200","3.45613","0.01678"
"41.61600","3.46815","0.01689"
"41.76000","3.48011","0.01644"
"41.90400","3.49207","0.01700"
"42.04800","3.50415","0.01715"
"42.19200","3.51616","0.01705"
"42.33600","3.52812","0.01708"
"42.48000","3.54014","0.01674"
"42.62400","3.55216","0.01741"
"42.76800","3.56411","0.01647"
"42.91200","3.57613","0.01718"
"43.05600","3.58815","0.01692"
"43.20000","3.60017","0.01739"
"43.34400","3.61213","0.01742"
"43.48800","3.62408","0.01685"
"43.63200","3.63616","0.01672"
"43.77600","3.64812","0.01705"
"43.92000","3.66008","0.01703"
"44.06400","3.67209","0.01563"
"44.20800","3.68411","0.01654"
"44.35200","3.69613","0.01710"
"44.49600","3.70809","0.01680"
"44.64000","3.72010","0.01677"
"44.78400","3.73212","0.01700"
"44.92800","3.74414","0.01651"
"45.07200","3.75604","0.01700"
"45.21600","3.76818","0.01663"
"45.36000","3.78013","0.01653"
"45.50400","3.79215","0.01727"
"45.64800","3.80405","0.01733"
"45.79200","3.81613","0.01674"
"45.93600","3.82814","0.01698"
"46.08000","3.84010","0.01694"
"46.22400","3.85206","0.01670"
"46.36800","3.86414","0.01684"
"46.51200","3.87616","0.01708"
"46.65600","3.88811","0.01638"
"46.80000","3.90013","0.01737"
"46.94400","3.91215","0.01762"
"47.08800","3.92417","0.01716"
"47.23200","3.93612","0.01690"
"47.37600","3.94814","0.01663"
"47.52000","3.96016","0.01708"
"47.66400","3.97206","0.01686"
"47.80800","3.98408","0.01786"
"47.95200","3.99609","0.01667"
"48.09600","4.00817","0.01705"
"48.24000","4.02007","0.01669"
"48.38400","4.03215","0.01573"
"48.52800","4.04422","0.01609"
"48.67200","4.05618","0.01582"
"48.81600","4.06814","0.01550"
"48.96000","4.08016","0.01595"
"49.10400","4.09218","0.01552"
"49.24800","4.10419","0.01631"
"49.39200","4.11609","0.01566"
"49.53600","4.12817","0.01554"
"49.68000","4.14019","0.01592"
"49.82400","4.15214","0.01567"
"49.96800","4.16410","0.01536"
"50.11200","4.17618","0.01493"
"50.25600","4.18814","0.01543"
"50.40000","4.20015","0.01583"
"50.54400","4.21211","0.01603"
"50.68800","4.22413","0.01517"
"50.83200","4.23615","0.01542"
"50.97600","4.24811","0.01603"
"51.12000","4.26012","0.01492"
"51.26400","4.27214","0.01605"
"51.40800","4.28416","0.01574"
"51.55200","4.29612","0.01568"
"51.69600","4.30819","0.01590"
"51.84000","4.32021","0.01562"
"51.98400","4.33217","0.01565"
"52.12800","4.34413","0.01571"
"52.27200","4.35621","0.01597"
"52.41600","4.36816","0.01640"
"52.56000","4.38012","0.01547"
"52.70400","4.39214","0.01614"
"52.84800","4.40416","0.01659"
"52.99200","4.41617","0.01536"
"53.13600","4.42813","0.01576"
"53.28000","4.44015","0.01554"
"53.42400","4.45217","0.01554"
"53.56800","4.46419","0.01683"
"53.71200","4.47614","0.01629"
"53.85600","4.48816","0.01531"
"54.00000","4.50018","0.01580"
"54.14400","4.51208","0.01594"
"54.28800","4.52409","0.01471"
"54.43200","4.53611","0.01574"
"54.57600","4.54813","0.01470"
"54.72000","4.56009","0.01618"
"54.86400","4.57217","0.01472"
"55.00800","4.58418","0.01515"
"55.15200","4.59620","0.01558"
"55.29600","4.60810","0.01548"
"55.44000","4.62012","0.01550"
"55.58400","4.63219","0.01551"
"55.72800","4.64415","0.01667"
"55.87200","4.65611","0.01611"
"56.01600","4.66819","0.01630"
"56.16000","4.68015","0.01531"
"56.30400","4.69210","0.01559"
"56.44800","4.70412","0.01554"
"56.59200","4.71620","0.01571"
"56.73600","4.72816","0.01511"
"56.88000","4.74011","0.01555"
"57.02400","4.75219","0.01636"
"57.16800","4.76421","0.01556"
"57.31200","4.77617","0.01582"
"57.45600","4.78813","0.01532"
"57.60000","4.80014","0.01605"
"57.74400","4.81216","0.01561"
"57.88800","4.82418","0.01611"
"58.03200","4.83608","0.01537"
"58.17600","4.84815","0.01627"
"58.32000","4.86017","0.01613"
"58.46400","4.87213","0.01564"
"58.60800","4.88415","0.01648"
"58.75200","4.89616","0.01530"
"58.89600","4.90818","0.01640"
"59.04000","4.92014","0.01594"
"59.18400","4.93216","0.01537"
"59.32800","4.94418","0.01635"
"59.47200","4.95613","0.01574"
"59.61600","4.96809","0.01561"
"59.76000","4.98011","0.01604"
"59.90400","4.99219","0.01643"
"60.04800","5.00414","0.01515"
"60.19200","5.01610","0.01524"
"60.33600","5.02818","0.01567"
"60.48000","5.04014","0.01579"
"60.62400","5.05210","0.01606"
"60.76800","5.06411","0.01570"
"60.91200","5.07613","0.01603"
"61.05600","5.08809","0.01554"
"61.20000","5.10017","0.01592"
"61.34400","5.11212","0.01569"
"61.48800","5.12414","0.01540"
"61.63200","5.13610","0.01617"
"61.77600","5.14812","0.01639"
"61.92000","5.16014","0.01592"
"62.06400","5.17215","0.01595"
"62.20800","5.18411","0.01567"
"62.35200","5.19613","0.01567"
"62.49600","5.20815","0.01661"
"62.64000","5.22016","0.01610"
"62.78400","5.23212","0.01560"
"62.92800","5.24414","0.01585"
"63.07200","5.25616","0.01568"
"63.21600","5.26818","0.01590"
"63.36000","5.28013","0.01557"
"63.50400","5.29215","0.01643"
"63.64800","5.30417","0.01567"
"63.79200","5.31613","0.01587"
"63.93600","5.32808","0.01624"
"64.08000","5.34016","0.01626"
"64.22400","5.35218","0.01580"
"64.36800","5.36414","0.01599"
"64.51200","5.37616","0.01640"
"64.65600","5.38817","0.01603"
"64.80000","5.40019","0.01555"
"64.94400","5.41209","0.01625"
"65.08800","5.42411","0.01635"
"65.23200","5.43612","0.01549"
"65.37600","5.44814","0.01501"
"65.52000","5.46010","0.01624"
"65.66400","5.47212","0.01542"
"65.80800","5.48414","0.01669"
"65.95200","5.49615","0.01621"
"66.09600","5.50811","0.01613"
"66.24000","5.52013","0.01620"
"66.38400","5.53221","0.01632"
"66.52800","5.54410","0.01592"
"66.67200","5.55612","0.01535"
"66.81600","5.56808","0.01567"
"66.96000","5.58010","0.01568"
"67.10400","5.59206","0.01677"
"67.24800","5.60413","0.01565"
"67.39200","5.61615","0.01621"
"67.53600","5.62817","0.01597"
"67.68000","5.64013","0.01602"
"67.82400","5.65214","0.01616"
"67.96800","5.66416","0.01524"
"68.11200","5.67612","0.01569"
"68.25600","5.68808","0.01571"
"68.40000","5.70015","0.01512"
"68.54400","5.71211","0.01513"
"68.68800","5.72413","0.01538"
"68.83200","5.73615","0.01509"
"68.97600","5.74817","0.01544"
"69.12000","5.76012","0.01628"
"69.26400","5.77208","0.01537"
"69.40800","5.78410","0.01604"
"69.55200","5.79612","0.01525"
"69.69600","5.80807","0.01480"
"69.84000","5.82009","0.01537"
"69.98400","5.83211","0.01561"
"70.12800","5.84419","0.01536"
"70.27200","5.85609","0.01565"
"70.41600","5.86810","0.01590"
"70.56000","5.88012","0.01582"
"70.70400","5.89214","0.01639"
"70.84800","5.90416","0.01507"
"70.99200","5.91617","0.01572"
"71.13600","5.92819","0.01556"
"71.28000","5.94015","0.01551"
"71.42400","5.95211","0.01492"
"71.56800","5.96413","0.01489"
"71.71200","5.97614","0.01625"
"71.85600","5.98810","0.01559"
"72.00000","6.00006","0.01512"
"72.14400","6.01214","0.01457"
"72.28800","6.02415","0.01529"
"72.43200","6.03611","0.01643"
"72.57600","6.04807","0.01559"
"72.72000","6.06015","0.01555"
"72.86400","6.07217","0.01557"
"73.00800","6.08406","0.01495"
"73.15200","6.09608","0.01606"
"73.29600","6.10810","0.01446"
"73.44000","6.12012","0.01573"
"73.58400","6.13207","0.01464"
"73.72800","6.14403","0.01530"
"73.87200","6.15617","0.01571"
"74.01600","6.16813","0.01495"
"74.16000","6.18009","0.01525"
"74.30400","6.19216","0.01541"
"74.44800","6.20418","0.01517"
"74.59200","6.21614","0.01478"
"74.73600","6.22810","0.01519"
"74.88000","6.24017","0.01504"
"75.02400","6.25219","0.01644"
"75.16800","6.26415","0.01555"
"75.31200","6.27617","0.01533"
"75.45600","6.28819","0.01557"
"75.60000","6.30020","0.01505"
"75.74400","6.31210","0.01566"
"75.88800","6.32412","0.01544"
"76.03200","6.33608","0.01513"
"76.17600","6.34809","0.01521"
"76.32000","6.36005","0.01630"
"76.46400","6.37213","0.01514"
"76.60800","6.38415","0.01569"
"76.75200","6.39610","0.01553"
"76.89600","6.40806","0.01521"
"77.04000","6.42014","0.01597"
"77.18400","6.43216","0.01555"
"77.32800","6.44412","0.01608"
"77.47200","6.45613","0.01525"
"77.61600","6.46815","0.01535"
"77.76000","6.48011","0.01497"
"77.90400","6.49207","0.01545"
"78.04800","6.50415","0.01546"
"78.19200","6.51610","0.01532"
"78.33600","6.52806","0.01658"
"78.48000","6.54008","0.01488"
"78.62400","6.55210","0.01538"
"78.76800","6.56417","0.01564"
"78.91200","6.57613","0.01601"
"79.05600","6.58809","0.01585"
"79.20000","6.60017","0.01602"
"79.34400","6.61212","0.01617"
"79.48800","6.62414","0.01552"
"79.63200","6.63616","0.01561"
"79.77600","6.64812","0.01589"
"79.92000","6.66008","0.01553"
"80.06400","6.67203","0.01573"
"80.20800","6.68411","0.01605"
"80.35200","6.69613","0.01581"
"80.49600","6.70809","0.01627"
"80.64000","6.72004","0.01600"
"80.78400","6.73218","0.01586"
"80.92800","6.74414","0.01531"
"81.07200","6.75610","0.01534"
"81.21600","6.76812","0.01553"
"81.36000","6.78013","0.01559"
"81.50400","6.79215","0.01548"
"81.64800","6.80411","0.01632"
"81.79200","6.81613","0.01576"
"81.93600","6.82814","0.01603"
"82.08000","6.84010","0.01559"
"82.22400","6.85206","0.01583"
"82.36800","6.86408","0.01519"
"82.51200","6.87615","0.01588"
"82.65600","6.88811","0.01534"
"82.80000","6.90007","0.01568"
"82.94400","6.91215","0.01550"
"83.08800","6.92417","0.01582"
"83.23200","6.93612","0.01592"
"83.37600","6.94808","0.01519"
"83.52000","6.96016","0.01498"
"83.66400","6.97212","0.01567"
"83.80800","6.98408","0.01590"
"83.95200","6.99615","0.01555"
"84.09600","7.00811","0.01574"
"84.24000","7.02013","0.01613"
"84.38400","7.03203","0.01562"
"84.52800","7.04410","0.01571"
"84.67200","7.05612","0.01551"
"84.81600","7.06814","0.01663"
"84.96000","7.08010","0.01553"
"85.10400","7.09218","0.01609"
"85.24800","7.10413","0.01591"
"85.39200","7.11609","0.01543"
"85.53600","7.12811","0.01546"
"85.68000","7.14013","0.01490"
"85.82400","7.15214","0.01618"
"85.96800","7.16410","0.01476"
"86.11200","7.17612","0.01553"
"86.25600","7.18814","0.01579"
"86.40000","7.20009","0.01552"
"86.54400","7.21205","0.01551"
"86.68800","7.22407","0.01627"
"86.83200","7.23615","0.01554"
"86.97600","7.24811","0.01624"
"87.12000","7.26012","0.01541"
"87.26400","7.27214","0.01615"
"87.40800","7.28416","0.01631"
"87.55200","7.29612","0.01545"
"87.69600","7.30814","0.01619"
"87.84000","7.32009","0.01473"
"87.98400","7.33217","0.01600"
"88.12800","7.34407","0.01584"
"88.27200","7.35620","0.01550"
"88.41600","7.36816","0.01549"
"88.56000","7.38012","0.01610"
"88.70400","7.39208","0.01584"
"88.84800","7.40416","0.01540"
"88.99200","7.41617","0.01578"
"89.13600","7.42813","0.01611"
"89.28000","7.44009","0.01565"
"89.42400","7.45217","0.01543"
"89.56800","7.46418","0.01588"
"89.71200","7.47608","0.01552"
"89.85600","7.48816","0.01614"
"90.00000","7.50018","0.01570"
"90.14400","7.51214","0.01553"
"90.28800","7.52409","0.01618"
"90.43200","7.53611","0.01626"
"90.57600","7.54819","0.01630"
"90.72000","7.56009","0.01677"
"90.86400","7.57210","0.01633"
"91.00800","7.58412","0.01617"
"91.15200","7.59620","0.01643"
"91.29600","7.60810","0.01626"
"91.44000","7.62012","0.01593"
"91.58400","7.63219","0.01573"
"91.72800","7.64421","0.01610"
"91.87200","7.65611","0.01629"
"92.01600","7.66813","0.01566"
"92.16000","7.68021","0.01599"
"92.30400","7.69216","0.01583"
"92.44800","7.70412","0.01566"
"92.59200","7.71614","0.01607"
"92.73600","7.72816","0.01668"
"92.88000","7.74011","0.01691"
"93.02400","7.75213","0.01618"
"93.16800","7.76421","0.01666"
"93.31200","7.77617","0.01628"
"93.45600","7.78819","0.01585"
"93.60000","7.80014","0.01652"
"93.74400","7.81216","0.01578"
"93.88800","7.82418","0.01620"
"94.03200","7.83614","0.01655"
"94.17600","7.84815","0.01589"
"94.32000","7.86017","0.01599"
"94.46400","7.87213","0.01535"
"94.60800","7.88415","0.01581"
"94.75200","7.89616","0.01642"
"94.89600","7.90818","0.01546"
"95.04000","7.92014","0.01601"
"95.18400","7.93210","0.01558"
"95.32800","7.94418","0.01560"
"95.47200","7.95613","0.01645"
"95.61600","7.96815","0.01549"
"95.76000","7.98017","0.01572"
"95.90400","7.99219","0.01586"
"96.04800","8.00414","0.01583"
"96.19200","8.01610","0.01636"
"96.33600","8.02818","0.01559"
"96.48000","8.04014","0.01656"
"96.62400","8.05216","0.01498"
"96.76800","8.06411","0.01594"
"96.91200","8.07619","0.01606"
"97.05600","8.08821","0.01480"
"97.20000","8.10011","0.01449"
"97.34400","8.11212","0.01514"
"97.48800","8.12420","0.01469"
"97.63200","8.13616","0.01587"
"97.77600","8.14812","0.01476"
"97.92000","8.16013","0.01615"
"98.06400","8.17215","0.01518"
"98.20800","8.18417","0.01515"
"98.35200","8.19613","0.01523"
"98.49600","8.20815","0.01460"
"98.64000","8.22016","0.01451"
"98.78400","8.23212","0.01521"
"98.92800","8.24408","0.01574"
"99.07200","8.25622","0.01557"
"99.21600","8.26812","0.01556"
"99.36000","8.28007","0.01556"
"99.50400","8.29209","0.01523"
"99.64800","8.30417","0.01565"
"99.79200","8.31619","0.01618"
"99.93600","8.32814","0.01557"
"100.08000","8.34016","0.01592"
"100.22400","8.35218","0.01595"
"100.36800","8.36420","0.01556"
"100.51200","8.37609","0.01584"
"100.65600","8.38811","0.01497"
"100.80000","8.40019","0.01631"
"100.94400","8.41215","0.01539"
"101.08800","8.42411","0.01501"
"101.23200","8.43618","0.01590"
"101.37600","8.44820","0.01581"
"101.52000","8.46010","0.01560"
"101.66400","8.47212","0.01548"
"101.80800","8.48413","0.01535"
"101.95200","8.49615","0.01695"
"102.09600","8.50811","0.01538"
"102.24000","8.52013","0.01602"
"102.38400","8.53215","0.01553"
"102.52800","8.54416","0.01550"
"102.67200","8.55612","0.01588"
"102.81600","8.56814","0.01603"
"102.96000","8.58016","0.01603"
"103.10400","8.59211","0.01558"
"103.24800","8.60407","0.01538"
"103.39200","8.61615","0.01568"
"103.53600","8.62811","0.01598"
"103.68000","8.64013","0.01524"
"103.82400","8.65208","0.01611"
"103.96800","8.66416","0.01529"
"104.11200","8.67612","0.01643"
"104.25600","8.68814","0.01660"
"104.40000","8.70009","0.01538"
"104.54400","8.71217","0.01613"
"104.68800","8.72413","0.01592"
"104.83200","8.73615","0.01564"
"104.97600","8.74817","0.01591"
"105.12000","8.76018","0.01634"
"105.26400","8.77214","0.01607"
"105.40800","8.78410","0.01622"
"105.55200","8.79618","0.01578"
"105.69600","8.80807","0.01618"
"105.84000","8.82003","0.01576"
"105.98400","8.83211","0.01705"
"106.12800","8.84413","0.01543"
"106.27200","8.85614","0.01564"
"106.41600","8.86810","0.01635"
"106.56000","8.88012","0.01570"
"106.70400","8.89220","0.01574"
"106.84800","8.90410","0.01604"
"106.99200","8.91605","0.01629"
"107.13600","8.92819","0.01601"
"107.28000","8.94015","0.01595"
"107.42400","8.95211","0.01618"
"107.56800","8.96418","0.01537"
"107.71200","8.97614","0.01569"
"107.85600","8.98816","0.01619"
"108.00000","9.00012","0.01651"
"108.14400","9.01214","0.01665"
"108.28800","9.02409","0.01663"
"108.43200","9.03611","0.01657"
"108.57600","9.04807","0.01611"
"108.72000","9.06015","0.01657"
"108.86400","9.07216","0.01644"
"109.00800","9.08412","0.01646"
"109.15200","9.09608","0.01619"
"109.29600","9.10810","0.01666"
"109.44000","9.12018","0.01664"
"109.58400","9.13207","0.01598"
"109.72800","9.14409","0.01741"
"109.87200","9.15605","0.01635"
"110.01600","9.16813","0.01637"
"110.16000","9.18003","0.01642"
"110.30400","9.19210","0.01648"
"110.44800","9.20412","0.01687"
"110.59200","9.21614","0.01667"
"110.73600","9.22810","0.01609"
"110.88000","9.24017","0.01736"
"111.02400","9.25219","0.01678"
"111.16800","9.26415","0.01652"
"111.31200","9.27611","0.01701"
"111.45600","9.28813","0.01654"
"111.60000","9.30014","0.01670"
"111.74400","9.31210","0.01622"
"111.88800","9.32412","0.01579"
"112.03200","9.33613","0.01662"
"112.17600","9.34809","0.01564"
"112.32000","9.36011","0.01655"
"112.46400","9.37207","0.01627"
"112.60800","9.38415","0.01638"
"112.75200","9.39610","0.01652"
"112.89600","9.40812","0.01627"
"113.04000","9.42014","0.01697"
"113.18400","9.43216","0.01631"
"113.32800","9.44412","0.01660"
"113.47200","9.45607","0.01707"
"113.61600","9.46815","0.01636"
"113.76000","9.48017","0.01643"
"113.90400","9.49213","0.01594"
"114.04800","9.50408","0.01719"
"114.19200","9.51616","0.01740"
"114.33600","9.52812","0.01654"
"114.48000","9.54008","0.01710"
"114.62400","9.55210","0.01659"
"114.76800","9.56417","0.01586"
"114.91200","9.57613","0.01794"
"115.05600","9.58809","0.01655"
"115.20000","9.60017","0.01744"
"115.34400","9.61218","0.01702"
"115.48800","9.62414","0.01672"
"115.63200","9.63604","0.01669"
"115.77600","9.64818","0.01692"
"115.92000","9.66014","0.01664"
"116.06400","9.67209","0.01659"
"116.20800","9.68411","0.01764"
"116.35200","9.69613","0.01767"
"116.49600","9.70809","0.01718"
"116.64000","9.72004","0.01665"
"116.78400","9.73206","0.01657"
"116.92800","9.74414","0.01680"
"117.07200","9.75610","0.01734"
"117.21600","9.76805","0.01723"
"117.36000","9.78013","0.01703"
"117.50400","9.79215","0.01742"
"117.64800","9.80411","0.01756"
"117.79200","9.81607","0.01689"
"117.93600","9.82808","0.01696"
"118.08000","9.84016","0.01683"
"118.22400","9.85206","0.01776"
"118.36800","9.86414","0.01759"
"118.51200","9.87609","0.01725"
"118.65600","9.88817","0.01720"
"118.80000","9.90007","0.01659"
"118.94400","9.91215","0.01757"
"119.08800","9.92416","0.01713"
"119.23200","9.93618","0.01753"
"119.37600","9.94808","0.01663"
"119.52000","9.96016","0.01731"
"119.66400","9.97212","0.01737"
"119.80800","9.98413","0.01820"
"119.95200","9.99609","0.01744"
"120.09600","10.00811","0.01706"
"120.24000","10.02013","0.01711"
"120.38400","10.03209","0.01761"
"120.52800","10.04410","0.01727"
"120.67200","10.05612","0.01743"
"120.81600","10.06808","0.01713"
"120.96000","10.08004","0.01694"
"121.10400","10.09212","0.01794"
"121.24800","10.10413","0.01699"
"121.39200","10.11609","0.01717"
"121.53600","10.12811","0.01753"
"121.68000","10.14012","0.01844"
"121.82400","10.15214","0.01711"
"121.96800","10.16410","0.01768"
"122.11200","10.17612","0.01788"
"122.25600","10.18814","0.01779"
"122.40000","10.20015","0.01784"
"122.54400","10.21211","0.01829"
"122.68800","10.22413","0.01786"
"122.83200","10.23615","0.01759"
"122.97600","10.24817","0.01729"
"123.12000","10.26006","0.01803"
"123.26400","10.27214","0.01795"
"123.40800","10.28416","0.01774"
"123.55200","10.29612","0.01755"
"123.69600","10.30807","0.01817"
"123.84000","10.32015","0.01740"
"123.98400","10.33217","0.01887"
"124.12800","10.34413","0.01825"
"124.27200","10.35608","0.01754"
"124.41600","10.36816","0.01833"
"124.56000","10.38012","0.01756"
"124.70400","10.39208","0.01836"
"124.84800","10.40409","0.01821"
"124.99200","10.41617","0.01742"
"125.13600","10.42813","0.01789"
"125.28000","10.44009","0.01789"
"125.42400","10.45217","0.01896"
"125.56800","10.46418","0.01758"
"125.71200","10.47614","0.01743"
"125.85600","10.48810","0.01754"
"126.00000","10.50018","0.01860"
"126.14400","10.51214","0.01872"
"126.28800","10.52409","0.01811"
"126.43200","10.53611","0.01838"
"126.57600","10.54813","0.01839"
"126.72000","10.56015","0.01853"
"126.86400","10.57210","0.01903"
"127.00800","10.58412","0.01869"
"127.15200","10.59614","0.01900"
"127.29600","10.60810","0.01830"
"127.44000","10.62006","0.01904"
"127.58400","10.63213","0.01879"
"127.72800","10.64415","0.01841"
"127.87200","10.65611","0.01817"
"128.01600","10.66813","0.01771"
"128.16000","10.68014","0.01836"
"128.30400","10.69216","0.01862"
"128.44800","10.70412","0.01867"
"128.59200","10.71614","0.01903"
"128.73600","10.72816","0.01856"
"128.88000","10.74017","0.01880"
"129.02400","10.75207","0.01835"
"129.16800","10.76415","0.01785"
"129.31200","10.77611","0.01888"
"129.45600","10.78806","0.01924"
"129.60000","10.80008","0.01917"
"129.74400","10.81216","0.01920"
"129.88800","10.82418","0.01840"
"130.03200","10.83613","0.01860"
"130.17600","10.84815","0.01903"
"130.32000","10.86017","0.01934"
"130.46400","10.87219","0.01964"
"130.60800","10.88409","0.01894"
"130.75200","10.89616","0.01925"
"130.89600","10.90818","0.01902"
"131.04000","10.92014","0.01923"
"131.18400","10.93210","0.01926"
"131.32800","10.94418","0.01974"
"131.47200","10.95613","0.01892"
"131.61600","10.96809","0.01943"
"131.76000","10.98011","0.01950"
"131.90400","10.99219","0.01929"
"132.04800","11.00420","0.01923"
"132.19200","11.01610","0.01968"
"132.33600","11.02812","0.01915"
"132.48000","11.04014","0.01993"
"132.62400","11.05222","0.01983"
"132.76800","11.06411","0.01902"
"132.91200","11.07619","0.02004"
"133.05600","11.08821","0.02008"
"133.20000","11.10017","0.01944"
"133.34400","11.11212","0.01957"
"133.48800","11.12414","0.01961"
"133.63200","11.13616","0.01925"
"133.77600","11.14812","0.01902"
"133.92000","11.16008","0.01988"
"134.06400","11.17215","0.02039"
"134.20800","11.18417","0.02060"
"134.35200","11.19613","0.01964"
"134.49600","11.20815","0.01961"
"134.64000","11.22016","0.02020"
"134.78400","11.23218","0.02006"
"134.92800","11.24414","0.02016"
"135.07200","11.25616","0.02022"
"135.21600","11.26818","0.01983"
"135.36000","11.28019","0.02060"
"135.50400","11.29209","0.02060"
"135.64800","11.30411","0.02037"
"135.79200","11.31613","0.01958"
"135.93600","11.32808","0.02021"
"136.08000","11.34010","0.01998"
"136.22400","11.35218","0.01998"
"136.36800","11.36414","0.02051"
"136.51200","11.37615","0.01979"
"136.65600","11.38817","0.02068"
"136.80000","11.40019","0.02066"
"136.94400","11.41215","0.02093"
"137.08800","11.42411","0.02053"
"137.23200","11.43618","0.02033"
"137.37600","11.44820","0.02061"
"137.52000","11.46016","0.02075"
"137.66400","11.47212","0.02070"
"137.80800","11.48419","0.02043"
"137.95200","11.49615","0.02127"
"138.09600","11.50817","0.02060"
"138.24000","11.52013","0.02136"
"138.38400","11.53221","0.02076"
"138.52800","11.54416","0.02054"
"138.67200","11.55612","0.02108"
"138.81600","11.56814","0.02080"
"138.96000","11.58016","0.02078"
"139.10400","11.59217","0.02092"
"139.24800","11.60407","0.02123"
"139.39200","11.61615","0.02087"
"139.53600","11.62817","0.02077"
"139.68000","11.64013","0.02117"
"139.82400","11.65208","0.02060"
"139.96800","11.66416","0.02116"
"140.11200","11.67618","0.02379"
"140.25600","11.68808","0.02666"
"140.40000","11.70015","0.02467"
"140.54400","11.71217","0.01747"
"140.68800","11.72419","0.01752"
"140.83200","11.73609","0.01837"
"140.97600","11.74816","0.01881"
"141.12000","11.76018","0.01903"
"141.26400","11.77220","0.01837"
"141.40800","11.78410","0.01837"
"141.55200","11.79618","0.01928"
"141.69600","11.80819","0.01991"
"141.84000","11.82015","0.01784"
"141.98400","11.83211","0.01698"
"142.12800","11.84413","0.01721"
"142.27200","11.85614","0.01918"
"142.41600","11.86804","0.01837"
"142.56000","11.88012","0.01704"
"142.70400","11.89220","0.01696"
"142.84800","11.90422","0.01819"
"142.99200","11.91611","0.01947"
"143.13600","11.92819","0.01944"
"143.28000","11.94015","0.01829"
"143.42400","11.95217","0.01801"
"143.56800","11.96406","0.01949"
"143.71200","11.97614","0.01954"
"143.85600","11.98816","0.01910"
"144.00000","12.00012","0.01810"
"144.14400","12.01214","0.01860"
"144.28800","12.02415","0.01892"
"144.43200","12.03617","0.01934"
"144.57600","12.04807","0.01883"
"144.72000","12.06015","0.01881"
"144.86400","12.07216","0.01968"
"145.00800","12.08418","0.01909"
"145.15200","12.09614","0.01985"
"145.29600","12.10816","0.02032"
"145.44000","12.12012","0.02026"
"145.58400","12.13213","0.01905"
"145.72800","12.14409","0.01932"
"145.87200","12.15611","0.01955"
"146.01600","12.16819","0.02002"
"146.16000","12.18014","0.01906"
"146.30400","12.19210","0.01969"
"146.44800","12.20424","0.01977"
"146.59200","12.21608","0.02088"
"146.73600","12.22810","0.02052"
"146.88000","12.24011","0.01999"
"147.02400","12.25213","0.02050"
"147.16800","12.26415","0.02033"
"147.31200","12.27611","0.02067"
"147.45600","12.28812","0.02019"
"147.60000","12.30014","0.01988"
"147.74400","12.31210","0.02055"
"147.88800","12.32412","0.02013"
"148.03200","12.33614","0.02069"
"148.17600","12.34821","0.02012"
"148.32000","12.36011","0.02102"
"148.46400","12.37213","0.02126"
"148.60800","12.38415","0.02139"
"148.75200","12.39610","0.02099"
"148.89600","12.40806","0.02138"
"149.04000","12.42008","0.02130"
"149.18400","12.43210","0.02057"
"149.32800","12.44417","0.01963"
"149.47200","12.45607","0.01980"
"149.61600","12.46815","0.02077"
"149.76000","12.48017","0.01932"
"149.90400","12.49213","0.02038"
"150.04800","12.50408","0.02032"
"150.19200","12.51616","0.02035"
"150.33600","12.52818","0.01990"
"150.48000","12.54014","0.02068"
"150.62400","12.55216","0.02096"
"150.76800","12.56417","0.02101"
"150.91200","12.57619","0.02074"
"151.05600","12.58809","0.02040"
"151.20000","12.60017","0.02056"
"151.34400","12.61218","0.01897"
"151.48800","12.62414","0.01963"
"151.63200","12.63610","0.01962"
"151.77600","12.64812","0.01953"
"151.92000","12.66013","0.01994"
"152.06400","12.67209","0.01966"
"152.20800","12.68405","0.02039"
"152.35200","12.69613","0.02032"
"152.49600","12.70815","0.01952"
"152.64000","12.72010","0.02016"
"152.78400","12.73212","0.02085"
"152.92800","12.74414","0.02033"
"153.07200","12.75610","0.02009"
"153.21600","12.76805","0.02081"
"153.36000","12.78013","0.01991"
"153.50400","12.79215","0.02086"
"153.64800","12.80417","0.02113"
"153.79200","12.81613","0.02144"
"153.93600","12.82814","0.02062"
"154.08000","12.84016","0.02106"
"154.22400","12.85206","0.02123"
"154.36800","12.86408","0.02145"
"154.51200","12.87615","0.02094"
"154.65600","12.88817","0.02029"
"154.80000","12.90013","0.02079"
"154.94400","12.91209","0.02138"
"155.08800","12.92416","0.02212"
"155.23200","12.93606","0.02129"
"155.37600","12.94808","0.02093"
"155.52000","12.96010","0.02150"
"155.66400","12.97218","0.02118"
"155.80800","12.98407","0.02105"
"155.95200","12.99609","0.02058"
"156.09600","13.00817","0.02120"
"156.24000","13.02013","0.02081"
"156.38400","13.03209","0.02202"
"156.52800","13.04410","0.02140"
"156.67200","13.05612","0.02161"
"156.81600","13.06814","0.02212"
"156.96000","13.08010","0.02174"
"157.10400","13.09211","0.02204"
"157.24800","13.10413","0.02146"
"157.39200","13.11609","0.02253"
"157.53600","13.12805","0.02190"
"157.68000","13.14012","0.02234"
"157.82400","13.15214","0.02234"
"157.96800","13.16410","0.02314"
"158.11200","13.17606","0.02229"
"158.25600","13.18814","0.02210"
"158.40000","13.20015","0.02305"
"158.54400","13.21211","0.02203"
"158.68800","13.22407","0.02304"
"158.83200","13.23621","0.02244"
"158.97600","13.24817","0.02264"
"159.12000","13.26012","0.02188"
"159.26400","13.27214","0.02242"
"159.40800","13.28410","0.02218"
"159.55200","13.29611","0.02281"
"159.69600","13.30807","0.02184"
"159.84000","13.32009","0.02273"
"159.98400","13.33217","0.02391"
"160.12800","13.34413","0.02369"
"160.27200","13.35609","0.02353"
"160.41600","13.36816","0.02320"
"160.56000","13.38018","0.02345"
"160.70400","13.39214","0.02335"
"160.84800","13.40410","0.02301"
"160.99200","13.41611","0.02326"
"161.13600","13.42813","0.02274"
"161.28000","13.44009","0.02379"
"161.42400","13.45211","0.02354"
"161.56800","13.46412","0.02355"
"161.71200","13.47614","0.02398"
"161.85600","13.48804","0.02433"
"162.00000","13.50012","0.02400"
"162.14400","13.51214","0.02431"
"162.28800","13.52415","0.02439"
"162.43200","13.53605","0.02358"
"162.57600","13.54813","0.02402"
"162.72000","13.56015","0.02458"
"162.86400","13.57210","0.02421"
"163.00800","13.58412","0.02394"
"163.15200","13.59614","0.02450"
"163.29600","13.60810","0.02381"
"163.44000","13.62006","0.02346"
"163.58400","13.63213","0.02469"
"163.72800","13.64409","0.02501"
"163.87200","13.65611","0.02382"
"164.01600","13.66807","0.02463"
"164.16000","13.68015","0.02463"
"164.30400","13.69216","0.02484"
"164.44800","13.70412","0.02473"
"164.59200","13.71608","0.02458"
"164.73600","13.72816","0.02516"
"164.88000","13.74011","0.02464"
"165.02400","13.75207","0.02418"
"165.16800","13.76409","0.02529"
"165.31200","13.77611","0.02522"
"165.45600","13.78812","0.02434"
"165.60000","13.80008","0.02466"
"165.74400","13.81210","0.02522"
"165.88800","13.82412","0.02508"
"166.03200","13.83607","0.02509"
"166.17600","13.84803","0.02443"
"166.32000","13.86017","0.02498"
"166.46400","13.87219","0.02487"
"166.60800","13.88415","0.02470"
"166.75200","13.89610","0.02563"
"166.89600","13.90818","0.02554"
"167.04000","13.92020","0.02575"
"167.18400","13.93210","0.02493"
"167.32800","13.94412","0.02528"
"167.47200","13.95619","0.02576"
"167.61600","13.96815","0.02555"
"167.76000","13.98011","0.02602"
"167.90400","13.99207","0.02489"
"168.04800","14.00414","0.02537"
"168.19200","14.01610","0.02503"
"168.33600","14.02806","0.02572"
"168.48000","14.04014","0.02508"
"168.62400","14.05215","0.02469"
"168.76800","14.06411","0.02524"
"168.91200","14.07607","0.02508"
"169.05600","14.08815","0.02455"
"169.20000","14.10017","0.02457"
"169.34400","14.11206","0.02605"
"169.48800","14.12408","0.02483"
"169.63200","14.13616","0.02548"
"169.77600","14.14818","0.02475"
"169.92000","14.16008","0.02590"
"170.06400","14.17215","0.02596"
"170.20800","14.18417","0.02599"
"170.35200","14.19613","0.02565"
"170.49600","14.20809","0.02566"
"170.64000","14.22016","0.02675"
"170.78400","14.23218","0.02617"
"170.92800","14.24414","0.02614"
"171.07200","14.25616","0.02642"
"171.21600","14.26817","0.02607"
"171.36000","14.28013","0.02644"
"171.50400","14.29209","0.02656"
"171.64800","14.30411","0.02643"
"171.79200","14.31612","0.02650"
"171.93600","14.32814","0.02636"
"172.08000","14.34010","0.02714"
"172.22400","14.35212","0.02621"
"172.36800","14.36414","0.02671"
"172.51200","14.37610","0.02712"
"172.65600","14.38811","0.02717"
"172.80000","14.40019","0.02682"
"172.94400","14.41215","0.02647"
"173.08800","14.42417","0.02736"
"173.23200","14.43618","0.02730"
"173.37600","14.44820","0.02785"
"173.52000","14.46016","0.02723"
"173.66400","14.47212","0.02682"
"173.80800","14.48413","0.02723"
"173.95200","14.49615","0.02714"
"174.09600","14.50817","0.02809"
"174.24000","14.52013","0.02765"
"174.38400","14.53220","0.02794"
"174.52800","14.54416","0.02787"
"174.67200","14.55612","0.02641"
"174.81600","14.56814","0.02694"
"174.96000","14.58022","0.02539"
"175.10400","14.59217","0.02635"
"175.24800","14.60413","0.02647"
"175.39200","14.61615","0.02701"
"175.53600","14.62817","0.02691"
"175.68000","14.64019","0.02738"
"175.82400","14.65208","0.02669"
"175.96800","14.66410","0.02645"
"176.11200","14.67618","0.02672"
"176.25600","14.68814","0.02598"
"176.40000","14.70015","0.02656"
"176.54400","14.71217","0.02692"
"176.68800","14.72419","0.02699"
"176.83200","14.73615","0.02734"
"176.97600","14.74811","0.02694"
"177.12000","14.76018","0.02775"
"177.26400","14.77220","0.02713"
"177.40800","14.78410","0.02721"
"177.55200","14.79618","0.02830"
"177.69600","14.80819","0.02735"
"177.84000","14.82021","0.02684"
"177.98400","14.83211","0.02771"
"178.12800","14.84413","0.02829"
"178.27200","14.85620","0.02675"
"178.41600","14.86816","0.02840"
"178.56000","14.88012","0.02790"
"178.70400","14.89214","0.02845"
"178.84800","14.90416","0.02828"
"178.99200","14.91611","0.02749"
"179.13600","14.92813","0.02791"
"179.28000","14.94015","0.02825"
"179.42400","14.95217","0.02832"
"179.56800","14.96412","0.02854"
"179.71200","14.97614","0.02808"
"179.85600","14.98816","0.02734"
"180.00000","15.00012","0.02833"
"180.14400","15.01208","0.02831"
"180.28800","15.02415","0.02859"
"180.43200","15.03617","0.02894"
"180.57600","15.04819","0.02861"
"180.72000","15.06015","0.02924"
"180.86400","15.07217","0.02838"
"181.00800","15.08412","0.02899"
"181.15200","15.09614","0.02889"
"181.29600","15.10816","0.02874"
"181.44000","15.12024","0.02966"
"181.58400","15.13213","0.02985"
"181.72800","15.14415","0.02919"
"181.87200","15.15617","0.03051"
"182.01600","15.16819","0.03057"
"182.16000","15.18014","0.03010"
"182.30400","15.19210","0.03076"
"182.44800","15.20412","0.03032"
"182.59200","15.21614","0.02967"
"182.73600","15.22816","0.03026"
"182.88000","15.24011","0.03017"
"183.02400","15.25219","0.03006"
"183.16800","15.26415","0.03011"
"183.31200","15.27605","0.03083"
"183.45600","15.28813","0.03069"
"183.60000","15.30014","0.03091"
"183.74400","15.31216","0.03124"
"183.88800","15.32406","0.03012"
"184.03200","15.33620","0.03120"
"184.17600","15.34815","0.03132"
"184.32000","15.36017","0.03097"
"184.46400","15.37207","0.03142"
"184.60800","15.38415","0.03130"
"184.75200","15.39616","0.03171"
"184.89600","15.40812","0.03091"
"185.04000","15.42008","0.03180"
"185.18400","15.43216","0.03159"
"185.32800","15.44417","0.03122"
"185.47200","15.45607","0.03176"
"185.61600","15.46809","0.03214"
"185.76000","15.48017","0.03182"
"185.90400","15.49219","0.03116"
"186.04800","15.50408","0.03227"
"186.19200","15.51616","0.03197"
"186.33600","15.52818","0.03228"
"186.48000","15.54014","0.03228"
"186.62400","15.55210","0.03148"
"186.76800","15.56417","0.03247"
"186.91200","15.57619","0.03308"
"187.05600","15.58815","0.03241"
"187.20000","15.60011","0.03269"
"187.34400","15.61212","0.03267"
"187.48800","15.62420","0.03258"
"187.63200","15.63610","0.03249"
"187.77600","15.64812","0.03159"
"187.92000","15.66013","0.03227"
"188.06400","15.67215","0.03174"
"188.20800","15.68411","0.03148"
"188.35200","15.69613","0.03190"
"188.49600","15.70815","0.03166"
"188.64000","15.72010","0.03085"
"188.78400","15.73206","0.03165"
"188.92800","15.74414","0.03236"
"189.07200","15.75616","0.03261"
"189.21600","15.76811","0.03259"
"189.36000","15.78013","0.03314"
"189.50400","15.79221","0.03236"
"189.64800","15.80411","0.03280"
"189.79200","15.81612","0.03255"
"189.93600","15.82808","0.03336"
"190.08000","15.84016","0.03336"
"190.22400","15.85206","0.03355"
"190.36800","15.86414","0.03341"
"190.51200","15.87609","0.03290"
"190.65600","15.88817","0.03369"
"190.80000","15.90007","0.03383"
"190.94400","15.91215","0.03298"
"191.08800","15.92416","0.03357"
"191.23200","15.93618","0.03408"
"191.37600","15.94808","0.03409"
"191.52000","15.96010","0.03355"
"191.66400","15.97217","0.03376"
"191.80800","15.98413","0.03409"
"191.95200","15.99609","0.03486"
"192.09600","16.00811","0.03497"
"192.24000","16.02013","0.03462"
"192.38400","16.03214","0.03463"
"192.52800","16.04410","0.03461"
"192.67200","16.05618","0.03388"
"192.81600","16.06820","0.03453"
"192.96000","16.08010","0.03473"
"193.10400","16.09211","0.03494"
"193.24800","16.10419","0.03487"
"193.39200","16.11615","0.03476"
"193.53600","16.12811","0.03548"
"193.68000","16.14012","0.03499"
"193.82400","16.15214","0.03465"
"193.96800","16.16410","0.03508"
"194.11200","16.17606","0.03492"
"194.25600","16.18814","0.03481"
"194.40000","16.20015","0.03522"
"194.54400","16.21211","0.03544"
"194.68800","16.22407","0.03491"
"194.83200","16.23615","0.03609"
"194.97600","16.24817","0.03573"
"195.12000","16.26012","0.03540"
"195.26400","16.27214","0.03615"
"195.40800","16.28416","0.03661"
"195.55200","16.29618","0.03640"
"195.69600","16.30807","0.03682"
"195.84000","16.32009","0.03665"
"195.98400","16.33211","0.03738"
"196.12800","16.34413","0.03734"
"196.27200","16.35603","0.03729"
"196.41600","16.36816","0.03762"
"196.56000","16.38018","0.03763"
"196.70400","16.39220","0.03738"
"196.84800","16.40410","0.03773"
"196.99200","16.41617","0.03823"
"197.13600","16.42813","0.03798"
"197.28000","16.44009","0.03768"
"197.42400","16.45205","0.03859"
"197.56800","16.46412","0.03884"
"197.71200","16.47614","0.03885"
"197.85600","16.48810","0.03909"
"198.00000","16.50012","0.03925"
"198.14400","16.51213","0.03904"
"198.28800","16.52409","0.03912"
"198.43200","16.53605","0.03986"
"198.57600","16.54813","0.03999"
"198.72000","16.56015","0.04010"
"198.86400","16.57210","0.04049"
"199.00800","16.58412","0.04072"
"199.15200","16.59614","0.04037"
"199.29600","16.60816","0.04079"
"199.44000","16.62005","0.04125"
"199.58400","16.63207","0.04122"
"199.72800","16.64415","0.04163"
"199.87200","16.65617","0.04188"
"200.01600","16.66813","0.04180"
"200.16000","16.68014","0.04203"
"200.30400","16.69216","0.04205"
"200.44800","16.70412","0.04220"
"200.59200","16.71608","0.04239"
"200.73600","16.72816","0.04274"
"200.88000","16.74017","0.04289"
"201.02400","16.75207","0.04292"
"201.16800","16.76403","0.04343"
"201.31200","16.77611","0.04380"
"201.45600","16.78812","0.04350"
"201.60000","16.80008","0.04416"
"201.74400","16.81210","0.04411"
"201.88800","16.82418","0.04452"
"202.03200","16.83613","0.04496"
"202.17600","16.84809","0.04475"
"202.32000","16.86011","0.04437"
"202.46400","16.87213","0.04468"
"202.60800","16.88408","0.04508"
"202.75200","16.89604","0.04561"
"202.89600","16.90806","0.04530"
"203.04000","16.92014","0.04573"
"203.18400","16.93210","0.04580"
"203.32800","16.94405","0.04541"
"203.47200","16.95613","0.04554"
"203.61600","16.96815","0.04619"
"203.76000","16.98011","0.04644"
"203.90400","16.99213","0.04645"
"204.04800","17.00414","0.04650"
"204.19200","17.01616","0.04710"
"204.33600","17.02812","0.04662"
"204.48000","17.04014","0.04719"
"204.62400","17.05215","0.04706"
"204.76800","17.06411","0.04743"
"204.91200","17.07607","0.04720"
"205.05600","17.08815","0.04707"
"205.20000","17.10011","0.04758"
"205.34400","17.11212","0.04806"
"205.48800","17.12408","0.04821"
"205.63200","17.13610","0.04810"
"205.77600","17.14812","0.04853"
"205.92000","17.16014","0.04841"
"206.06400","17.17215","0.04884"
"206.20800","17.18411","0.04891"
"206.35200","17.19613","0.04893"
"206.49600","17.20808","0.04921"
"206.64000","17.22010","0.04925"
"206.78400","17.23212","0.04929"
"206.92800","17.24414","0.04961"
"207.07200","17.25610","0.04948"
"207.21600","17.26811","0.04958"
"207.36000","17.28013","0.05024"
"207.50400","17.29209","0.05032"
"207.64800","17.30411","0.05042"
"207.79200","17.31613","0.05046"
"207.93600","17.32814","0.05039"
"208.08000","17.34010","0.05065"
"208.22400","17.35212","0.05107"
"208.36800","17.36414","0.05103"
"208.51200","17.37615","0.05095"
"208.65600","17.38811","0.05099"
"208.80000","17.40013","0.05110"
"208.81800","17.40168","0.05115"