File: Force_trajectories/161114/Specimen_RawData_5.csv
End date,"11/14/2016"
Specimen label,"20BT61"
Maximum Load,"0.31734",N

Time,Extension,Load
(s),(mm),(N)
"0.00000","0.00000","0.00000"
"0.32400","0.02661","0.00083"
"0.64800","0.05417","0.00197"
"0.97200","0.08119","0.00297"
"1.29600","0.10810","0.00424"
"1.62000","0.13518","0.00467"
"1.94400","0.16221","0.00602"
"2.26800","0.18911","0.00649"
"2.59200","0.21620","0.00767"
"2.91600","0.24310","0.00883"
"3.24000","0.27019","0.00882"
"3.56400","0.29721","0.00919"
"3.88800","0.32412","0.01024"
"4.21200","0.35114","0.01032"
"4.53600","0.37811","0.01025"
"4.86000","0.40513","0.01215"
"5.18400","0.43210","0.01229"
"5.50800","0.45912","0.01291"
"5.83200","0.48621","0.01330"
"6.15600","0.51305","0.01385"
"6.48000","0.54014","0.01440"
"6.80400","0.56716","0.01467"
"7.12800","0.59407","0.01425"
"7.45200","0.62109","0.01577"
"7.77600","0.64806","0.01600"
"8.10000","0.67514","0.01585"
"8.42400","0.70217","0.01766"
"8.74800","0.72907","0.01845"
"9.07200","0.75616","0.01800"
"9.39600","0.78312","0.01837"
"9.72000","0.81015","0.01909"
"10.04400","0.83717","0.01939"
"10.36800","0.86408","0.01962"
"10.69200","0.89116","0.02063"
"11.01600","0.91807","0.01907"
"11.34000","0.94509","0.02123"
"11.66400","0.97218","0.02190"
"11.98800","0.99908","0.02261"
"12.31200","1.02617","0.02319"
"12.63600","1.05307","0.02286"
"12.96000","1.08010","0.02400"
"13.28400","1.10718","0.02391"
"13.60800","1.13409","0.02507"
"13.93200","1.16117","0.02575"
"14.25600","1.18808","0.02477"
"14.58000","1.21510","0.02681"
"14.90400","1.24213","0.02706"
"15.22800","1.26903","0.02745"
"15.55200","1.29612","0.02821"
"15.87600","1.32314","0.02852"
"16.20000","1.35011","0.02883"
"16.52400","1.37707","0.02920"
"16.84800","1.40410","0.02974"
"17.17200","1.43118","0.03028"
"17.49600","1.45809","0.03076"
"17.82000","1.48511","0.03171"
"18.14400","1.51214","0.03159"
"18.46800","1.53904","0.03237"
"18.79200","1.56619","0.03248"
"19.11600","1.59315","0.03242"
"19.44000","1.62012","0.03305"
"19.76400","1.64714","0.03314"
"20.08800","1.67405","0.03319"
"20.41200","1.70113","0.03417"
"20.73600","1.72816","0.03466"
"21.06000","1.75512","0.03425"
"21.38400","1.78215","0.03504"
"21.70800","1.80905","0.03637"
"22.03200","1.83620","0.03674"
"22.35600","1.86310","0.03717"
"22.68000","1.89007","0.03693"
"23.00400","1.91709","0.03727"
"23.32800","1.94412","0.03847"
"23.65200","1.97114","0.03897"
"23.97600","1.99811","0.03849"
"24.30000","2.02513","0.03946"
"24.62400","2.05216","0.04004"
"24.94800","2.07912","0.04021"
"25.27200","2.10615","0.04053"
"25.59600","2.13311","0.04008"
"25.92000","2.16008","0.04064"
"26.24400","2.18710","0.04090"
"26.56800","2.21407","0.04084"
"26.89200","2.24115","0.04124"
"27.21600","2.26818","0.04164"
"27.54000","2.29514","0.04170"
"27.86400","2.32217","0.04199"
"28.18800","2.34907","0.04269"
"28.51200","2.37616","0.04269"
"28.83600","2.40318","0.04330"
"29.16000","2.43009","0.04409"
"29.48400","2.45717","0.04454"
"29.80800","2.48408","0.04495"
"30.13200","2.51110","0.04527"
"30.45600","2.53813","0.04603"
"30.78000","2.56509","0.04630"
"31.10400","2.59218","0.04716"
"31.42800","2.61908","0.04777"
"31.75200","2.64616","0.04791"
"32.07600","2.67313","0.04887"
"32.40000","2.70010","0.04950"
"32.72400","2.72712","0.04974"
"33.04800","2.75409","0.05080"
"33.37200","2.78117","0.05111"
"33.69600","2.80814","0.05125"
"34.02000","2.83510","0.05228"
"34.34400","2.86212","0.05253"
"34.66800","2.88909","0.05286"
"34.99200","2.91612","0.05322"
"35.31600","2.94314","0.05301"
"35.64000","2.97010","0.05284"
"35.96400","2.99719","0.05379"
"36.28800","3.02410","0.05352"
"36.61200","3.05112","0.05370"
"36.93600","3.07814","0.05422"
"37.26000","3.10511","0.05478"
"37.58400","3.13219","0.05506"
"37.90800","3.15910","0.05549"
"38.23200","3.18618","0.05601"
"38.55600","3.21315","0.05631"
"38.88000","3.24011","0.05683"
"39.20400","3.26714","0.05622"
"39.52800","3.29410","0.05625"
"39.85200","3.32113","0.05673"
"40.17600","3.34809","0.05728"
"40.50000","3.37506","0.05715"
"40.82400","3.40214","0.05788"
"41.14800","3.42911","0.05835"
"41.47200","3.45613","0.05857"
"41.79600","3.48316","0.05886"
"42.12000","3.51012","0.05941"
"42.44400","3.53715","0.05940"
"42.76800","3.56411","0.05997"
"43.09200","3.59114","0.06015"
"43.41600","3.61816","0.06045"
"43.74000","3.64513","0.06058"
"44.06400","3.67215","0.06079"
"44.38800","3.69912","0.06109"
"44.71200","3.72614","0.06102"
"45.03600","3.75317","0.06151"
"45.36000","3.78007","0.06129"
"45.68400","3.80710","0.06186"
"46.00800","3.83412","0.06198"
"46.33200","3.86115","0.06213"
"46.65600","3.88817","0.06220"
"46.98000","3.91502","0.06245"
"47.30400","3.94216","0.06222"
"47.62800","3.96907","0.06253"
"47.95200","3.99609","0.06257"
"48.27600","4.02312","0.06284"
"48.60000","4.05014","0.06303"
"48.92400","4.07717","0.06315"
"49.24800","4.10407","0.06309"
"49.57200","4.13110","0.06320"
"49.89600","4.15812","0.06332"
"50.22000","4.18503","0.06344"
"50.54400","4.21211","0.06357"
"50.86800","4.23914","0.06374"
"51.19200","4.26610","0.06378"
"51.51600","4.29313","0.06390"
"51.84000","4.32003","0.06406"
"52.16400","4.34712","0.06406"
"52.48800","4.37408","0.06410"
"52.81200","4.40111","0.06412"
"53.13600","4.42813","0.06408"
"53.46000","4.45510","0.06414"
"53.78400","4.48212","0.06423"
"54.10800","4.50909","0.06426"
"54.43200","4.53611","0.06430"
"54.75600","4.56314","0.06432"
"55.08000","4.59004","0.06447"
"55.40400","4.61713","0.06454"
"55.72800","4.64409","0.06452"
"56.05200","4.67106","0.06465"
"56.37600","4.69814","0.06493"
"56.70000","4.72505","0.06487"
"57.02400","4.75213","0.06501"
"57.34800","4.77916","0.06542"
"57.67200","4.80606","0.06565"
"57.99600","4.83309","0.06592"
"58.32000","4.86005","0.06589"
"58.64400","4.88714","0.06581"
"58.96800","4.91410","0.06634"
"59.29200","4.94113","0.06663"
"59.61600","4.96815","0.06713"
"59.94000","4.99512","0.06756"
"60.26400","5.02214","0.06816"
"60.58800","5.04911","0.06854"
"60.91200","5.07613","0.06914"
"61.23600","5.10316","0.06945"
"61.56000","5.13006","0.07024"
"61.88400","5.15715","0.07112"
"62.20800","5.18417","0.07203"
"62.53200","5.21114","0.07233"
"62.85600","5.23810","0.07337"
"63.18000","5.26507","0.07362"
"63.50400","5.29215","0.07452"
"63.82800","5.31918","0.07460"
"64.15200","5.34614","0.07601"
"64.47600","5.37317","0.07612"
"64.80000","5.40007","0.07660"
"65.12400","5.42710","0.07761"
"65.44800","5.45412","0.07795"
"65.77200","5.48109","0.07888"
"66.09600","5.50817","0.08017"
"66.42000","5.53508","0.08095"
"66.74400","5.56210","0.08168"
"67.06800","5.58913","0.08267"
"67.39200","5.61609","0.08374"
"67.71600","5.64318","0.08394"
"68.04000","5.67008","0.08436"
"68.36400","5.69717","0.06457"
"68.68800","5.72419","0.06469"
"69.01200","5.75110","0.06479"
"69.33600","5.77812","0.06515"
"69.66000","5.80515","0.06536"
"69.98400","5.83211","0.06572"
"70.30800","5.85920","0.06601"
"70.63200","5.88610","0.06639"
"70.95600","5.91319","0.06715"
"71.28000","5.94009","0.06738"
"71.60400","5.96711","0.06837"
"71.92800","5.99414","0.06906"
"72.25200","6.02111","0.06956"
"72.57600","6.04819","0.07023"
"72.90000","6.07509","0.07143"
"73.22400","6.10212","0.07268"
"73.54800","6.12914","0.07351"
"73.87200","6.15605","0.07402"
"74.19600","6.18313","0.07523"
"74.52000","6.21010","0.07719"
"74.84400","6.23712","0.07843"
"75.16800","6.26415","0.07985"
"75.49200","6.29106","0.08109"
"75.81600","6.31814","0.08317"
"76.14000","6.34516","0.08554"
"76.46400","6.37213","0.08699"
"76.78800","6.39915","0.08906"
"77.11200","6.42606","0.09021"
"77.43600","6.45314","0.09283"
"77.76000","6.48005","0.09346"
"78.08400","6.50707","0.09539"
"78.40800","6.53416","0.09652"
"78.73200","6.56106","0.09772"
"79.05600","6.58815","0.09887"
"79.38000","6.61511","0.10000"
"79.70400","6.64214","0.10160"
"80.02800","6.66916","0.10251"
"80.35200","6.69607","0.10411"
"80.67600","6.72315","0.10573"
"81.00000","6.75012","0.10820"
"81.32400","6.77714","0.11061"
"81.64800","6.80417","0.11278"
"81.97200","6.83101","0.11633"
"82.29600","6.85816","0.11893"
"82.62000","6.88512","0.12225"
"82.94400","6.91209","0.12587"
"83.26800","6.93911","0.12855"
"83.59200","6.96614","0.13099"
"83.91600","6.99310","0.13409"
"84.24000","7.02013","0.13555"
"84.56400","7.04715","0.13720"
"84.88800","7.07418","0.13926"
"85.21200","7.10108","0.14136"
"85.53600","7.12811","0.14294"
"85.86000","7.15513","0.14417"
"86.18400","7.18216","0.14487"
"86.50800","7.20912","0.14652"
"86.83200","7.23609","0.14764"
"87.15600","7.26311","0.14819"
"87.48000","7.29014","0.14736"
"87.80400","7.31710","0.14760"
"88.12800","7.34413","0.12708"
"88.45200","7.37109","0.10114"
"88.77600","7.39818","0.10396"
"89.10000","7.42514","0.10360"
"89.42400","7.45211","0.11122"
"89.74800","7.47919","0.11566"
"90.07200","7.50610","0.11928"
"90.39600","7.53312","0.11924"
"90.72000","7.56009","0.12539"
"91.04400","7.58711","0.13022"
"91.36800","7.61420","0.13537"
"91.69200","7.64110","0.13806"
"92.01600","7.66813","0.13970"
"92.34000","7.69509","0.14078"
"92.66400","7.72212","0.14390"
"92.98800","7.74908","0.14653"
"93.31200","7.77605","0.14850"
"93.63600","7.80313","0.14950"
"93.96000","7.83010","0.14981"
"94.28400","7.85712","0.15015"
"94.60800","7.88415","0.15057"
"94.93200","7.91111","0.15073"
"95.25600","7.93814","0.15125"
"95.58000","7.96516","0.15211"
"95.90400","7.99213","0.14806"
"96.22800","8.01915","0.14871"
"96.55200","8.04612","0.14970"
"96.87600","8.07308","0.15035"
"97.20000","8.10011","0.15128"
"97.52400","8.12707","0.15238"
"97.84800","8.15416","0.15327"
"98.17200","8.18106","0.15479"
"98.49600","8.20815","0.15624"
"98.82000","8.23517","0.15813"
"99.14400","8.26202","0.16074"
"99.46800","8.28916","0.16360"
"99.79200","8.31607","0.16629"
"100.11600","8.34315","0.16833"
"100.44000","8.37012","0.17062"
"100.76400","8.39708","0.17170"
"101.08800","8.42417","0.17317"
"101.41200","8.45107","0.17647"
"101.73600","8.47810","0.17905"
"102.06000","8.50518","0.18264"
"102.38400","8.53215","0.18572"
"102.70800","8.55917","0.18875"
"103.03200","8.58614","0.19145"
"103.35600","8.61310","0.19299"
"103.68000","8.64013","0.19511"
"104.00400","8.66715","0.19775"
"104.32800","8.69418","0.19942"
"104.65200","8.72114","0.17553"
"104.97600","8.74817","0.17608"
"105.30000","8.77513","0.17758"
"105.62400","8.80204","0.18052"
"105.94800","8.82912","0.18255"
"106.27200","8.85614","0.18594"
"106.59600","8.88317","0.18596"
"106.92000","8.91014","0.18553"
"107.24400","8.93710","0.18760"
"107.56800","8.96412","0.18932"
"107.89200","8.99109","0.19116"
"108.21600","9.01812","0.19353"
"108.54000","9.04520","0.19552"
"108.86400","9.07211","0.19703"
"109.18800","9.09919","0.19939"
"109.51200","9.12609","0.20176"
"109.83600","9.15312","0.20378"
"110.16000","9.18014","0.20454"
"110.48400","9.20705","0.20648"
"110.80800","9.23413","0.20853"
"111.13200","9.26110","0.20999"
"111.45600","9.28813","0.21096"
"111.78000","9.31515","0.21177"
"112.10400","9.34205","0.21224"
"112.42800","9.36914","0.21277"
"112.75200","9.39610","0.21293"
"113.07600","9.42313","0.21291"
"113.40000","9.45015","0.21366"
"113.72400","9.47712","0.21419"
"114.04800","9.50414","0.21593"
"114.37200","9.53111","0.21722"
"114.69600","9.55807","0.21909"
"115.02000","9.58516","0.22095"
"115.34400","9.61206","0.22270"
"115.66800","9.63909","0.22519"
"115.99200","9.66611","0.22623"
"116.31600","9.69308","0.22859"
"116.64000","9.72016","0.23024"
"116.96400","9.74707","0.23212"
"117.28800","9.77415","0.23449"
"117.61200","9.80112","0.23739"
"117.93600","9.82808","0.24021"
"118.26000","9.85511","0.24270"
"118.58400","9.88207","0.24532"
"118.90800","9.90916","0.24700"
"119.23200","9.93612","0.24912"
"119.55600","9.96309","0.25118"
"119.88000","9.99017","0.25304"
"120.20400","10.01708","0.25561"
"120.52800","10.04410","0.25785"
"120.85200","10.07113","0.26041"
"121.17600","10.09815","0.26242"
"121.50000","10.12518","0.26529"
"121.82400","10.15208","0.26746"
"122.14800","10.17911","0.27122"
"122.47200","10.20619","0.27372"
"122.79600","10.23304","0.27665"
"123.12000","10.26012","0.27924"
"123.44400","10.28709","0.28187"
"123.76800","10.31417","0.28368"
"124.09200","10.34114","0.28526"
"124.41600","10.36816","0.28846"
"124.74000","10.39519","0.29173"
"125.06400","10.42215","0.29483"
"125.38800","10.44912","0.29993"
"125.71200","10.47614","0.30291"
"126.03600","10.50311","0.30563"
"126.36000","10.53019","0.30681"
"126.68400","10.55710","0.30927"
"127.00800","10.58412","0.31143"
"127.33200","10.61115","0.31373"
"127.65600","10.63817","0.31505"
"127.98000","10.66514","0.27162"
"128.30400","10.69210","0.27377"
"128.62800","10.71913","0.27627"
"128.95200","10.74615","0.27763"
"129.27600","10.77306","0.27964"
"129.60000","10.80014","0.25709"
"129.92400","10.82711","0.25559"
"130.24800","10.85419","0.25877"
"130.57200","10.88116","0.25612"
"130.89600","10.90806","0.25972"
"131.22000","10.93521","0.26282"
"131.54400","10.96211","0.26641"
"131.86800","10.98914","0.27013"
"132.19200","11.01616","0.27441"
"132.51600","11.04307","0.27810"
"132.84000","11.07015","0.28193"
"133.16400","11.09712","0.28460"
"133.48800","11.12408","0.29092"
"133.81200","11.15117","0.29477"
"134.13600","11.17807","0.30139"
"134.46000","11.20516","0.30538"
"134.78400","11.23206","0.30837"
"135.10800","11.25915","0.31161"
"135.43200","11.28611","0.31592"
"135.75600","11.31308","0.03567"
"136.08000","11.34016","0.05131"
"136.40400","11.36713","0.05209"
"136.72800","11.39409","0.04914"
"137.05200","11.42112","0.05304"
"137.37600","11.44808","0.05775"
"137.70000","11.47517","0.05678"
"138.02400","11.50213","0.05694"
"138.34800","11.52910","0.05931"
"138.67200","11.55612","0.05817"
"138.99600","11.58309","0.05880"
"139.32000","11.61017","0.06086"
"139.64400","11.63714","0.06073"
"139.96800","11.66410","0.06107"
"140.29200","11.69113","0.06241"
"140.61600","11.71803","0.06274"
"140.94000","11.74512","0.06263"
"141.26400","11.77214","0.06306"
"141.58800","11.79917","0.06377"
"141.91200","11.82613","0.06363"
"142.23600","11.85304","0.06377"
"142.56000","11.88018","0.06426"
"142.88400","11.90708","0.06419"
"143.20800","11.93411","0.06419"
"143.53200","11.96113","0.06437"
"143.85600","11.98804","0.06453"
"144.18000","12.01512","0.06445"
"144.50400","12.04209","0.06451"
"144.82800","12.06912","0.06495"
"145.15200","12.09614","0.06479"
"145.47600","12.12311","0.06507"
"145.80000","12.15013","0.06558"
"146.12400","12.17709","0.06613"
"146.44800","12.20412","0.06584"
"146.77200","12.23114","0.06663"
"147.09600","12.25811","0.06769"
"147.42000","12.28513","0.06813"
"147.74400","12.31210","0.06866"
"148.06800","12.33906","0.07027"
"148.39200","12.36609","0.07176"
"148.71600","12.39305","0.07144"
"149.04000","12.42014","0.07300"
"149.36400","12.44710","0.07484"
"149.68800","12.47407","0.07568"
"150.01200","12.50115","0.07554"
"150.33600","12.52812","0.07779"
"150.66000","12.55509","0.07918"
"150.98400","12.58211","0.07973"
"151.30800","12.60913","0.08121"
"151.63200","12.63616","0.08353"
"151.95600","12.66306","0.08595"
"152.28000","12.69015","0.08758"
"152.60400","12.71711","0.08949"
"152.92800","12.74408","0.09105"
"153.25200","12.77116","0.09275"
"153.57600","12.79807","0.09417"
"153.90000","12.82515","0.09464"
"154.22400","12.85218","0.09603"
"154.54800","12.87908","0.09771"
"154.87200","12.90617","0.09835"
"155.19600","12.93313","0.09905"
"155.52000","12.96010","0.09936"
"155.84400","12.98712","0.10088"
"156.16800","13.01409","0.10202"
"156.49200","13.04111","0.10250"
"156.81600","13.06814","0.10372"
"157.14000","13.09510","0.10601"
"157.46400","13.12213","0.10828"
"157.78800","13.14909","0.11008"
"158.11200","13.17612","0.11367"
"158.43600","13.20302","0.11698"
"158.76000","13.23011","0.11999"
"159.08400","13.25713","0.12334"
"159.40800","13.28404","0.12117"
"159.73200","13.31112","0.02218"
"160.05600","13.33815","0.01519"
"160.38000","13.36511","0.02233"
"160.70400","13.39214","0.01730"
"161.02800","13.41910","0.01964"
"161.35200","13.44613","0.02168"
"161.67600","13.47309","0.02362"
"162.00000","13.50012","0.02286"
"162.32400","13.52714","0.02281"
"162.64800","13.55411","0.02512"
"162.97200","13.58113","0.02789"
"163.29600","13.60810","0.02655"
"163.62000","13.63506","0.02766"
"163.94400","13.66215","0.02947"
"164.26800","13.68905","0.02980"
"164.59200","13.71620","0.03106"
"164.91600","13.74310","0.03142"
"165.24000","13.77019","0.03245"
"165.56400","13.79715","0.03431"
"165.88800","13.82406","0.03379"
"166.21200","13.85114","0.03528"
"166.53600","13.87817","0.03674"
"166.86000","13.90507","0.03714"
"167.18400","13.93216","0.03833"
"167.50800","13.95912","0.03959"
"167.83200","13.98615","0.04013"
"168.15600","14.01311","0.04149"
"168.48000","14.04014","0.04199"
"168.80400","14.06716","0.03572"
"169.12800","14.09413","0.03733"
"169.45200","14.12115","0.03590"
"169.77600","14.14812","0.03545"
"170.10000","14.17514","0.03649"
"170.42400","14.20217","0.03658"
"170.74800","14.22907","0.03748"
"171.07200","14.25610","0.03920"
"171.39600","14.28312","0.04025"
"171.72000","14.31015","0.04050"
"172.04400","14.33717","0.04061"
"172.36800","14.36408","0.04087"
"172.69200","14.39116","0.04212"
"173.01600","14.41813","0.04242"
"173.34000","14.44509","0.04217"
"173.66400","14.47212","0.04211"
"173.98800","14.49908","0.04160"
"174.31200","14.52611","0.03944"
"174.63600","14.55307","0.03810"
"174.96000","14.58010","0.03872"
"175.28400","14.60718","0.03851"
"175.60800","14.63409","0.03998"
"175.93200","14.66117","0.04044"
"176.25600","14.68808","0.04078"
"176.58000","14.71510","0.04168"
"176.90400","14.74213","0.04170"
"177.22800","14.76909","0.04297"
"177.55200","14.79618","0.04335"
"177.87600","14.82314","0.04405"
"178.20000","14.85005","0.04406"
"178.52400","14.87707","0.04506"
"178.84800","14.90410","0.04413"
"179.17200","14.93118","0.04484"
"179.49600","14.95815","0.04612"
"179.82000","14.98511","0.04610"
"180.14400","15.01214","0.04738"
"180.46800","15.03910","0.04731"
"180.79200","15.06613","0.04748"
"181.11600","15.09315","0.04882"
"181.44000","15.12012","0.04922"
"181.76400","15.14714","0.04989"
"182.08800","15.17405","0.05041"
"182.41200","15.20113","0.05040"
"182.73600","15.22816","0.05043"
"183.06000","15.25506","0.05130"
"183.38400","15.28215","0.05198"
"183.70800","15.30911","0.05260"
"184.03200","15.33620","0.05342"
"184.35600","15.36316","0.05346"
"184.68000","15.39013","0.05352"
"185.00400","15.41715","0.05453"
"185.32800","15.44411","0.05499"
"185.65200","15.47114","0.05541"
"185.97600","15.49811","0.05570"
"186.30000","15.52507","0.05575"
"186.62400","15.55216","0.05595"
"186.94800","15.57912","0.05638"
"187.27200","15.60614","0.05706"
"187.59600","15.63317","0.05741"
"187.92000","15.66013","0.05777"
"188.24400","15.68710","0.05788"
"188.56800","15.71412","0.05843"
"188.89200","15.74115","0.05889"
"189.21600","15.76811","0.05868"
"189.54000","15.79514","0.05875"
"189.86400","15.82210","0.05877"
"190.18800","15.84913","0.05873"
"190.51200","15.87615","0.05914"
"190.83600","15.90312","0.05976"
"191.16000","15.93008","0.06032"
"191.48400","15.95711","0.06052"
"191.80800","15.98413","0.06082"
"192.13200","16.01110","0.06091"
"192.45600","16.03818","0.06130"
"192.78000","16.06503","0.06120"
"193.10400","16.09217","0.06135"
"193.42800","16.11908","0.06148"
"193.75200","16.14610","0.06144"
"194.07600","16.17313","0.05846"
"194.40000","16.20009","0.05885"
"194.72400","16.22712","0.05936"
"195.04800","16.25408","0.05979"
"195.37200","16.28117","0.06054"
"195.69600","16.30813","0.06071"
"196.02000","16.33504","0.06001"
"196.34400","16.36218","0.05995"
"196.66800","16.38909","0.05999"
"196.99200","16.41611","0.06009"
"197.31600","16.44314","0.06071"
"197.64000","16.47010","0.06097"
"197.96400","16.49713","0.06137"
"198.28800","16.52409","0.06124"
"198.61200","16.55106","0.06172"
"198.93600","16.57814","0.06214"
"199.26000","16.60511","0.06239"
"199.58400","16.63213","0.06234"
"199.90800","16.65910","0.06254"
"200.23200","16.68606","0.06258"
"200.55600","16.71315","0.06271"
"200.88000","16.74005","0.06288"
"201.20400","16.76714","0.06310"
"201.52800","16.79410","0.06286"
"201.85200","16.82113","0.06305"
"202.17600","16.84809","0.06329"
"202.50000","16.87506","0.06342"
"202.82400","16.90220","0.06353"
"203.14800","16.92917","0.06368"
"203.47200","16.95607","0.06371"
"203.79600","16.98310","0.06377"
"204.12000","17.01006","0.06383"
"204.44400","17.03715","0.06398"
"204.76800","17.06411","0.06394"
"205.09200","17.09108","0.06394"
"205.41600","17.11816","0.06380"
"205.74000","17.14507","0.06377"
"206.06400","17.17215","0.06333"
"206.38800","17.19912","0.06342"
"206.71200","17.22608","0.06350"
"207.03600","17.25317","0.06326"
"207.36000","17.28007","0.06345"
"207.68400","17.30710","0.06356"
"208.00800","17.33412","0.06370"
"208.33200","17.36109","0.06381"
"208.65600","17.38811","0.06377"
"208.98000","17.41508","0.06378"
"209.30400","17.44216","0.06394"
"209.62800","17.46913","0.06404"
"209.95200","17.49603","0.06393"
"210.27600","17.52317","0.06367"
"210.60000","17.55014","0.06353"
"210.92400","17.57711","0.06361"
"211.24800","17.60413","0.06361"
"211.57200","17.63116","0.06367"
"211.89600","17.65812","0.06377"
"212.22000","17.68509","0.06387"
"212.54400","17.71217","0.06402"
"212.86800","17.73914","0.06404"
"213.19200","17.76604","0.06417"
"213.51600","17.79313","0.06424"
"213.84000","17.82009","0.06427"
"214.16400","17.84718","0.06428"
"214.48800","17.87414","0.06432"
"214.81200","17.90111","0.06432"
"215.13600","17.92807","0.06438"
"215.46000","17.95510","0.06441"
"215.78400","17.98212","0.06444"
"216.10800","18.00915","0.06448"
"216.43200","18.03611","0.06451"
"216.75600","18.06319","0.06445"
"217.08000","18.09016","0.06464"
"217.40400","18.11713","0.06470"
"217.72800","18.14409","0.06463"
"218.05200","18.17111","0.06485"
"218.37600","18.19814","0.06482"
"218.70000","18.22511","0.06520"
"219.02400","18.25213","0.06515"
"219.34800","18.27916","0.06551"
"219.67200","18.30606","0.06550"
"219.99600","18.33315","0.06576"
"220.32000","18.36011","0.06608"
"220.64400","18.38713","0.06690"
"220.96800","18.41416","0.06712"
"221.29200","18.44113","0.06717"
"221.61600","18.46815","0.06769"
"221.94000","18.49512","0.06850"
"222.26400","18.52214","0.06916"
"222.58800","18.54910","0.06941"
"222.91200","18.57613","0.07007"
"223.23600","18.60316","0.07073"
"223.56000","18.63006","0.07113"
"223.88400","18.65709","0.07224"
"224.20800","18.68417","0.07333"
"224.53200","18.71113","0.07470"
"224.85600","18.73816","0.07567"
"225.18000","18.76512","0.07659"
"225.50400","18.79215","0.07730"
"225.82800","18.81917","0.07945"
"226.15200","18.84608","0.08054"
"226.47600","18.87317","0.08026"
"226.80000","18.90013","0.08184"
"227.12400","18.92709","0.08297"
"227.44800","18.95418","0.08489"
"227.77200","18.98108","0.08611"
"228.09600","19.00817","0.08730"
"228.42000","19.03507","0.08927"
"228.74400","19.06216","0.09000"
"229.06800","19.08912","0.09154"
"229.39200","19.11609","0.09126"
"229.71600","19.14317","0.07337"
"230.04000","19.17008","0.07297"
"230.36400","19.19711","0.07263"
"230.68800","19.22413","0.07312"
"231.01200","19.25109","0.07448"
"231.33600","19.27812","0.07376"
"231.66000","19.30514","0.06875"
"231.98400","19.33217","0.06983"
"232.30800","19.35913","0.07034"
"232.63200","19.38610","0.07107"
"232.95600","19.41312","0.07155"
"233.28000","19.44009","0.07158"
"233.60400","19.46711","0.06244"
"233.92800","19.49414","0.06163"
"234.25200","19.52110","0.06133"
"234.57600","19.54813","0.06102"
"234.90000","19.57509","0.06123"
"235.22400","19.60206","0.06187"
"235.54800","19.62914","0.06202"
"235.87200","19.65605","0.06253"
"236.19600","19.68313","0.06274"
"236.52000","19.71010","0.06292"
"236.84400","19.73706","0.06331"
"237.16800","19.76415","0.06341"
"237.49200","19.79105","0.06349"
"237.81600","19.81814","0.06358"
"238.14000","19.84516","0.06353"
"238.46400","19.87213","0.06367"
"238.78800","19.89909","0.06392"
"239.11200","19.92606","0.06390"
"239.43600","19.95320","0.06396"
"239.76000","19.98011","0.06405"
"240.08400","20.00713","0.06399"
"240.40800","20.03416","0.06411"
"240.73200","20.06112","0.06410"
"241.05600","20.08809","0.06394"
"241.38000","20.11511","0.06399"
"241.70400","20.14208","0.06412"
"242.02800","20.16916","0.06416"
"242.35200","20.19613","0.06395"
"242.67600","20.22315","0.06394"
"243.00000","20.25018","0.06392"
"243.32400","20.27708","0.06389"
"243.64800","20.30411","0.06399"
"243.97200","20.33107","0.06424"
"244.29600","20.35815","0.06413"
"244.62000","20.38518","0.06423"
"244.94400","20.41209","0.06431"
"245.26800","20.43911","0.06436"
"245.59200","20.46608","0.06431"
"245.91600","20.49316","0.06432"
"246.24000","20.52013","0.06449"
"246.56400","20.54709","0.06447"
"246.88800","20.57417","0.06457"
"247.21200","20.60108","0.06441"
"247.53600","20.62811","0.06455"
"247.86000","20.65513","0.06457"
"248.18400","20.68216","0.06468"
"248.50800","20.70912","0.06472"
"248.83200","20.73603","0.06468"
"249.15600","20.76311","0.06481"
"249.48000","20.79014","0.06460"
"249.80400","20.81710","0.06451"
"250.12800","20.84413","0.06451"
"250.45200","20.87109","0.06461"
"250.77600","20.89812","0.06473"
"251.10000","20.92514","0.06481"
"251.42400","20.95205","0.06478"
"251.74800","20.97913","0.06456"
"252.07200","21.00609","0.06464"
"252.39600","21.03318","0.06494"
"252.72000","21.06015","0.06531"
"253.04400","21.08705","0.06553"
"253.36800","21.11414","0.06573"
"253.69200","21.14110","0.06617"
"254.01600","21.16813","0.06649"
"254.34000","21.19515","0.06704"
"254.66400","21.22211","0.06748"
"254.98800","21.24914","0.06765"
"255.31200","21.27610","0.06796"
"255.63600","21.30313","0.06866"
"255.96000","21.33010","0.06705"
"256.28400","21.35700","0.06744"
"256.60800","21.38415","0.06804"
"256.93200","21.41111","0.06874"
"257.25600","21.43814","0.06956"
"257.58000","21.46516","0.06954"
"257.90400","21.49207","0.07053"
"258.22800","21.51915","0.07080"
"258.55200","21.54606","0.07132"
"258.87600","21.57308","0.07294"
"259.20000","21.60016","0.07413"
"259.52400","21.62707","0.07494"
"259.84800","21.65416","0.07544"
"260.17200","21.68112","0.07526"
"260.49600","21.70809","0.07612"
"260.82000","21.73517","0.07721"
"261.14400","21.76208","0.07879"
"261.46800","21.78916","0.08014"
"261.79200","21.81612","0.08135"
"262.11600","21.84315","0.08242"
"262.44000","21.87012","0.08353"
"262.76400","21.89708","0.08487"
"263.08800","21.92416","0.08662"
"263.41200","21.95113","0.08866"
"263.73600","21.97810","0.08995"
"264.06000","22.00506","0.09226"
"264.38400","22.03208","0.09358"
"264.70800","22.05917","0.09556"
"265.03200","22.08613","0.09673"
"265.35600","22.11310","0.09823"
"265.68000","22.14018","0.09947"
"266.00400","22.16715","0.10050"
"266.32800","22.19417","0.10132"
"266.65200","22.22114","0.10260"
"266.97600","22.24810","0.10487"
"267.30000","22.27513","0.10536"
"267.62400","22.30210","0.10710"
"267.94800","22.32918","0.10946"
"268.27200","22.35614","0.11234"
"268.59600","22.38311","0.11574"
"268.92000","22.41013","0.11825"
"269.24400","22.43704","0.12037"
"269.56800","22.46418","0.12284"
"269.89200","22.49115","0.12554"
"270.21600","22.51811","0.12864"
"270.54000","22.54514","0.13020"
"270.86400","22.57210","0.12951"
"271.18800","22.59913","0.13114"
"271.51200","22.62609","0.13408"
"271.83600","22.65312","0.13448"
"272.16000","22.68020","0.13676"
"272.48400","22.70711","0.13905"
"272.80800","22.73413","0.14137"
"273.13200","22.76110","0.14312"
"273.45600","22.78812","0.14468"
"273.78000","22.81509","0.14639"
"274.10400","22.84205","0.14790"
"274.42800","22.86914","0.14879"
"274.75200","22.89616","0.14938"
"275.07600","22.92307","0.14425"
"275.40000","22.95009","0.12340"
"275.72400","22.97712","0.11247"
"276.04800","23.00408","0.10889"
"276.37200","23.03111","0.10919"
"276.69600","23.05807","0.11079"
"277.02000","23.08516","0.11278"
"277.34400","23.11212","0.11223"
"277.66800","23.13915","0.11473"
"277.99200","23.16611","0.11965"
"278.31600","23.19308","0.12623"
"278.64000","23.22016","0.13158"
"278.96400","23.24707","0.13391"
"279.28800","23.27415","0.13709"
"279.61200","23.30118","0.13986"
"279.93600","23.32808","0.14120"
"280.26000","23.35517","0.14300"
"280.58400","23.38213","0.14360"
"280.90800","23.40916","0.14542"
"281.23200","23.43612","0.14724"
"281.55600","23.46309","0.14880"
"281.88000","23.49011","0.14966"
"282.20400","23.51708","0.15028"
"282.52800","23.54410","0.15089"
"282.85200","23.57113","0.15116"
"283.17600","23.59815","0.15204"
"283.50000","23.62518","0.15324"
"283.82400","23.65208","0.15343"
"284.14800","23.67911","0.15069"
"284.47200","23.70619","0.15092"
"284.79600","23.73310","0.15203"
"285.12000","23.76012","0.15277"
"285.44400","23.78714","0.15402"
"285.76800","23.81411","0.15556"
"286.09200","23.84114","0.15751"
"286.41600","23.86810","0.15918"
"286.74000","23.89513","0.15946"
"287.06400","23.92215","0.15852"
"287.38800","23.94912","0.15809"
"287.71200","23.97614","0.15669"
"288.03600","24.00305","0.15689"
"288.36000","24.03019","0.15866"
"288.68400","24.05710","0.16084"
"289.00800","24.08412","0.16321"
"289.33200","24.11115","0.16526"
"289.65600","24.13805","0.16787"
"289.98000","24.16514","0.16980"
"290.30400","24.19210","0.17171"
"290.62800","24.21913","0.17514"
"290.95200","24.24615","0.17703"
"291.27600","24.27306","0.18007"
"291.60000","24.30014","0.18315"
"291.92400","24.32710","0.18658"
"292.24800","24.35413","0.18963"
"292.57200","24.38116","0.19296"
"292.89600","24.40806","0.19622"
"293.22000","24.43508","0.19970"
"293.54400","24.46205","0.20294"
"293.86800","24.48907","0.20570"
"294.19200","24.51610","0.20821"
"294.51600","24.54307","0.21021"
"294.84000","24.57009","0.21120"
"295.16400","24.59711","0.21209"
"295.48800","24.62408","0.21250"
"295.81200","24.65117","0.21280"
"296.13600","24.67807","0.21308"
"296.46000","24.70515","0.21321"
"296.78400","24.73212","0.21429"
"297.10800","24.75908","0.21555"
"297.43200","24.78611","0.21717"
"297.75600","24.81308","0.21961"
"298.08000","24.84016","0.22262"
"298.40400","24.86718","0.22472"
"298.72800","24.89409","0.22746"
"299.05200","24.92111","0.22932"
"299.37600","24.94802","0.23113"
"299.70000","24.97522","0.23266"
"300.02400","25.00207","0.23467"
"300.34800","25.02909","0.23610"
"300.67200","25.05612","0.23785"
"300.99600","25.08309","0.23928"
"301.32000","25.11011","0.24132"
"301.64400","25.13713","0.24226"
"301.96800","25.16410","0.24315"
"302.29200","25.19118","0.24471"
"302.61600","25.21809","0.24610"
"302.94000","25.24512","0.24737"
"303.26400","25.27214","0.24847"
"303.58800","25.29911","0.25010"
"303.91200","25.32613","0.25132"
"304.23600","25.35303","0.25339"
"304.56000","25.38018","0.25515"
"304.88400","25.40714","0.25657"
"305.20800","25.43411","0.25807"
"305.53200","25.46113","0.25992"
"305.85600","25.48810","0.26196"
"306.18000","25.51518","0.26398"
"306.50400","25.54215","0.26567"
"306.82800","25.56911","0.25870"
"307.15200","25.59614","0.26111"
"307.47600","25.62310","0.26316"
"307.80000","25.65013","0.26523"
"308.12400","25.67715","0.26738"
"308.44800","25.70412","0.26985"
"308.77200","25.73108","0.27213"
"309.09600","25.75811","0.27477"
"309.42000","25.78513","0.27680"
"309.74400","25.81216","0.27922"
"310.06800","25.83906","0.28041"
"310.39200","25.86615","0.28219"
"310.71600","25.89311","0.28425"
"311.04000","25.92020","0.28703"
"311.36400","25.94716","0.28952"
"311.68800","25.97407","0.29302"
"312.01200","26.00115","0.29697"
"312.33600","26.02812","0.29981"
"312.66000","26.05514","0.30337"
"312.98400","26.08217","0.30533"
"313.30800","26.10907","0.30845"
"313.63200","26.13616","0.30984"
"313.95600","26.16306","0.31109"
"314.28000","26.19009","0.31313"
"314.60400","26.21711","0.06551"
"314.92800","26.24414","0.04863"
"315.25200","26.27116","0.06987"
"315.57600","26.29807","0.05809"
"315.90000","26.32515","0.06515"
"316.22400","26.35218","0.05460"
"316.54800","26.37908","0.06569"
"316.87200","26.40611","0.04888"
"317.19600","26.43313","0.04464"
"317.52000","26.46016","0.05065"
"317.84400","26.48712","0.05069"
"318.16800","26.51409","0.04132"
"318.49200","26.54111","0.05118"
"318.81600","26.56814","0.06001"
"319.14000","26.59510","0.05509"
"319.46400","26.62213","0.06224"
"319.78800","26.64909","0.06015"
"320.11200","26.67612","0.06427"
"320.43600","26.70314","0.06000"
"320.76000","26.73010","0.06437"
"321.08400","26.75719","0.06077"
"321.40800","26.78404","0.06437"
"321.73200","26.81118","0.05992"
"322.05600","26.83815","0.06414"
"322.38000","26.86511","0.06035"
"322.70400","26.89214","0.06418"
"323.02800","26.91904","0.06122"
"323.35200","26.94619","0.06428"
"323.67600","26.97315","0.06198"
"324.00000","27.00012","0.06472"
"324.32400","27.02708","0.06287"
"324.64800","27.05404","0.06554"
"324.97200","27.08119","0.06366"
"325.29600","27.10810","0.06621"
"325.62000","27.13512","0.06415"
"325.94400","27.16215","0.06646"
"326.26800","27.18911","0.06420"
"326.59200","27.21614","0.06510"
"326.91600","27.24310","0.06443"
"327.24000","27.27013","0.06474"
"327.56400","27.29715","0.06572"
"327.88800","27.32405","0.06499"
"328.21200","27.35114","0.07148"
"328.53600","27.37816","0.06632"
"328.86000","27.40513","0.07258"
"329.18400","27.43210","0.06762"
"329.50800","27.45906","0.06979"
"329.83200","27.48615","0.07265"
"330.15600","27.51311","0.07043"
"330.48000","27.54008","0.08095"
"330.80400","27.56716","0.07349"
"331.12800","27.59413","0.07651"
"331.45200","27.62115","0.08010"
"331.77600","27.64805","0.07786"
"332.10000","27.67514","0.08906"
"332.42400","27.70216","0.08124"
"332.74800","27.72907","0.08344"
"333.07200","27.75616","0.09312"
"333.39600","27.78312","0.08703"
"333.72000","27.81008","0.09248"
"334.04400","27.83717","0.09383"
"334.36800","27.86407","0.09081"
"334.69200","27.89110","0.09593"
"335.01600","27.91813","0.09075"
"335.34000","27.94509","0.08997"
"335.66400","27.97211","0.09604"
"335.98800","27.99908","0.09252"
"336.31200","28.02610","0.09489"
"336.63600","28.05313","0.09824"
"336.96000","28.08010","0.09716"
"337.28400","28.10712","0.09999"
"337.60800","28.13415","0.10233"
"337.93200","28.16111","0.10082"
"338.25600","28.18814","0.10491"
"338.58000","28.21510","0.10732"
"338.90400","28.24219","0.10522"
"339.22800","28.26909","0.11061"
"339.55200","28.29611","0.11480"
"339.87600","28.32314","0.11336"
"340.20000","28.35010","0.11738"
"340.52400","28.37713","0.12580"
"340.84800","28.40409","0.12397"
"341.17200","28.43112","0.12758"
"341.49600","28.45815","0.13405"
"341.82000","28.48505","0.13423"
"342.14400","28.51213","0.13492"
"342.46800","28.53910","0.13910"
"342.79200","28.56618","0.14193"
"343.11600","28.59315","0.14109"
"343.44000","28.62011","0.14247"
"343.76400","28.64714","0.14466"
"344.08800","28.67410","0.14664"
"344.41200","28.70107","0.14681"
"344.73600","28.72815","0.14798"
"345.06000","28.75512","0.14930"
"345.38400","28.78214","0.14991"
"345.70800","28.80911","0.15021"
"346.03200","28.83613","0.15073"
"346.35600","28.86316","0.15121"
"346.68000","28.89013","0.15164"
"347.00400","28.91715","0.15214"
"347.32800","28.94411","0.15278"
"347.65200","28.97114","0.15445"
"347.97600","28.99816","0.15569"
"348.30000","29.02507","0.15640"
"348.62400","29.05215","0.15679"
"348.94800","29.07906","0.15909"
"349.27200","29.10608","0.16119"
"349.59600","29.13311","0.16217"
"349.92000","29.16007","0.16265"
"350.24400","29.18716","0.16453"
"350.56800","29.21412","0.16639"
"350.89200","29.24115","0.16705"
"351.21600","29.26817","0.16856"
"351.54000","29.29508","0.00093"
"351.86400","29.32211","0.01601"
"352.18800","29.34913","0.01285"
"352.51200","29.37609","0.01226"
"352.83600","29.40312","0.01424"
"353.16000","29.43008","0.01140"
"353.48400","29.45717","0.00981"
"353.80800","29.48413","0.01902"
"354.13200","29.51110","0.01230"
"354.45600","29.53812","0.01073"
"354.78000","29.56509","0.01150"
"355.10400","29.59211","0.01115"
"355.42800","29.61914","0.01052"
"355.75200","29.64610","0.01058"
"356.07600","29.67319","0.01042"
"356.40000","29.70003","0.01133"
"356.72400","29.72712","0.01042"
"357.04800","29.75408","0.01806"
"357.37200","29.78111","0.01093"
"357.69600","29.80813","0.01247"
"358.02000","29.83510","0.01499"
"358.34400","29.86212","0.01076"
"358.66800","29.88909","0.01076"
"358.99200","29.91605","0.01169"
"359.31600","29.94314","0.01125"
"359.64000","29.97005","0.01205"
"359.96400","29.99719","0.01036"
"360.28800","30.02409","0.01203"
"360.61200","30.05106","0.01070"
"360.93600","30.07808","0.01072"
"361.26000","30.10511","0.01321"
"361.58400","30.13213","0.01125"
"361.90800","30.15916","0.01042"
"362.23200","30.18612","0.00958"
"362.55600","30.21321","0.01135"
"362.88000","30.24005","0.01087"
"363.20400","30.26714","0.01097"
"363.52800","30.29416","0.01080"
"363.85200","30.32113","0.01120"
"364.17600","30.34809","0.01029"
"364.50000","30.37506","0.01310"
"364.82400","30.40214","0.01050"
"365.14800","30.42917","0.01123"
"365.47200","30.45613","0.01074"
"365.79600","30.48316","0.01134"
"366.12000","30.51006","0.01120"
"366.44400","30.53715","0.01070"
"366.76800","30.56411","0.01130"
"367.09200","30.59108","0.00986"
"367.41600","30.61810","0.01099"
"367.74000","30.64512","0.01101"
"368.06400","30.67209","0.01081"
"368.38800","30.69912","0.00960"
"368.71200","30.72614","0.01016"
"369.03600","30.75317","0.01108"
"369.36000","30.78013","0.01055"
"369.68400","30.80710","0.01229"
"370.00800","30.83418","0.01033"
"370.33200","30.86109","0.01232"
"370.65600","30.88817","0.01106"
"370.98000","30.91508","0.01147"
"371.30400","30.94216","0.01133"
"371.62800","30.96912","0.01143"
"371.95200","30.99609","0.01110"
"372.27600","31.02312","0.01121"
"372.60000","31.05014","0.01148"
"372.92400","31.07711","0.01183"
"373.24800","31.10419","0.01156"
"373.57200","31.13110","0.01052"
"373.89600","31.15818","0.01170"
"374.22000","31.18509","0.01166"
"374.54400","31.21211","0.01113"
"374.86800","31.23914","0.01162"
"375.19200","31.26610","0.01021"
"375.51600","31.29312","0.01177"
"375.84000","31.32003","0.01177"
"376.16400","31.34717","0.01148"
"376.48800","31.37414","0.01145"
"376.81200","31.40104","0.01078"
"377.13600","31.42813","0.01106"
"377.46000","31.45509","0.01217"
"377.78400","31.48212","0.01151"
"378.10800","31.50914","0.01128"
"378.43200","31.53611","0.01156"
"378.75600","31.56313","0.01221"
"379.08000","31.59010","0.01048"
"379.40400","31.61706","0.01222"
"379.72800","31.64415","0.01133"
"380.05200","31.67111","0.01208"
"380.37600","31.69820","0.01172"
"380.70000","31.72510","0.01145"
"381.02400","31.75213","0.01148"
"381.34800","31.77915","0.01198"
"381.67200","31.80606","0.01215"
"381.99600","31.83314","0.01220"
"382.32000","31.86011","0.01191"
"382.64400","31.88713","0.01063"
"382.96800","31.91416","0.01213"
"383.29200","31.94106","0.01209"
"383.61600","31.96815","0.01221"
"383.94000","31.99511","0.01204"
"384.26400","32.02208","0.01230"
"384.58800","32.04910","0.01302"
"384.91200","32.07613","0.01264"
"385.23600","32.10315","0.01259"
"385.56000","32.13012","0.01177"
"385.88400","32.15714","0.01278"
"386.20800","32.18417","0.01241"
"386.53200","32.21107","0.01216"
"386.85600","32.23816","0.01299"
"387.18000","32.26512","0.01210"
"387.50400","32.29214","0.01179"
"387.82800","32.31917","0.01262"
"388.15200","32.34608","0.01259"
"388.47600","32.37316","0.01253"
"388.80000","32.40013","0.01315"
"389.12400","32.42715","0.01242"
"389.44800","32.45412","0.01225"
"389.77200","32.48108","0.01346"
"390.09600","32.50816","0.01312"
"390.42000","32.53513","0.01295"
"390.74400","32.56210","0.01243"
"391.06800","32.58918","0.01266"
"391.39200","32.61615","0.01282"
"391.71600","32.64311","0.01285"
"392.04000","32.67008","0.01374"
"392.36400","32.69704","0.01301"
"392.68800","32.72419","0.01264"
"393.01200","32.75109","0.01354"
"393.33600","32.77812","0.01365"
"393.66000","32.80514","0.01283"
"393.98400","32.83210","0.01262"
"394.30800","32.85913","0.01387"
"394.63200","32.88610","0.01315"
"394.95600","32.91312","0.01381"
"395.28000","32.94009","0.01407"
"395.60400","32.96711","0.01332"
"395.92800","32.99408","0.01403"
"396.25200","33.02110","0.01390"
"396.57600","33.04813","0.01325"
"396.90000","33.07509","0.01355"
"397.22400","33.10205","0.01340"
"397.54800","33.12920","0.01462"
"397.87200","33.15611","0.01357"
"398.19600","33.18319","0.01321"
"398.52000","33.21009","0.01393"
"398.84400","33.23712","0.01407"
"399.16800","33.26414","0.01439"
"399.49200","33.29105","0.01521"
"399.81600","33.31813","0.01451"
"400.14000","33.34516","0.01439"
"400.46400","33.37207","0.01395"
"400.78800","33.39915","0.01366"
"401.11200","33.42605","0.01428"
"401.43600","33.45314","0.01413"
"401.76000","33.48010","0.01500"
"402.08400","33.50707","0.01400"
"402.40800","33.53415","0.01492"
"402.73200","33.56112","0.01436"
"403.05600","33.58815","0.01463"
"403.38000","33.61511","0.01409"
"403.70400","33.64207","0.01571"
"404.02800","33.66916","0.01485"
"404.35200","33.69613","0.01422"
"404.67600","33.72309","0.01541"
"405.00000","33.75017","0.01514"
"405.32400","33.77714","0.01472"
"405.64800","33.80416","0.01487"
"405.97200","33.83107","0.01527"
"406.29600","33.85815","0.01509"
"406.62000","33.88518","0.01486"
"406.94400","33.91209","0.01520"
"407.26800","33.93917","0.01477"
"407.59200","33.96614","0.01516"
"407.91600","33.99316","0.01566"
"408.24000","34.02019","0.01616"
"408.56400","34.04709","0.01570"
"408.88800","34.07417","0.01585"
"409.21200","34.10108","0.01563"
"409.53600","34.12811","0.01615"
"409.86000","34.15513","0.01609"
"410.18400","34.18209","0.01672"
"410.50800","34.20918","0.01668"
"410.83200","34.23608","0.01593"
"411.15600","34.26311","0.01574"
"411.48000","34.29013","0.01565"
"411.80400","34.31710","0.01622"
"412.12800","34.34412","0.01448"
"412.45200","34.37109","0.01526"
"412.77600","34.39817","0.01492"
"413.10000","34.42514","0.01325"
"413.42400","34.45210","0.01385"
"413.74800","34.47913","0.01359"
"414.07200","34.50615","0.01366"
"414.39600","34.53306","0.01441"
"414.72000","34.56014","0.01483"
"415.04400","34.58705","0.01425"
"415.36800","34.61419","0.01523"
"415.69200","34.64110","0.01519"
"416.01600","34.66806","0.01442"
"416.34000","34.69515","0.01583"
"416.66400","34.72211","0.01503"
"416.98800","34.74914","0.01522"
"417.31200","34.77610","0.01506"
"417.63600","34.80307","0.01656"
"417.96000","34.83015","0.01618"
"418.28400","34.85706","0.01651"
"418.60800","34.88414","0.01716"
"418.93200","34.91111","0.01653"
"419.25600","34.93813","0.01744"
"419.58000","34.96510","0.01751"
"419.90400","34.99206","0.01737"
"420.22800","35.01921","0.01702"
"420.55200","35.04611","0.01774"
"420.87600","35.07308","0.01743"
"421.20000","35.10010","0.01763"
"421.52400","35.12707","0.01793"
"421.84800","35.15409","0.01779"
"422.17200","35.18112","0.01936"
"422.49600","35.20808","0.01908"
"422.82000","35.23511","0.02002"
"423.14400","35.26207","0.01858"
"423.46800","35.28916","0.01967"
"423.79200","35.31618","0.02025"
"424.11600","35.34309","0.01993"
"424.44000","35.37011","0.02151"
"424.76400","35.39702","0.02129"
"425.08800","35.42416","0.02087"
"425.41200","35.45119","0.02147"
"425.73600","35.47809","0.02155"
"426.06000","35.50518","0.02216"
"426.38400","35.53208","0.02203"
"426.70800","35.55917","0.02186"
"427.03200","35.58613","0.02354"
"427.35600","35.61304","0.02305"
"427.68000","35.64018","0.02323"
"428.00400","35.66709","0.02403"
"428.32800","35.69411","0.02423"
"428.65200","35.72114","0.02457"
"428.97600","35.74810","0.02569"
"429.30000","35.77512","0.02621"
"429.62400","35.80209","0.02679"
"429.94800","35.82912","0.02738"
"430.27200","35.85614","0.02838"
"430.59600","35.88311","0.02935"
"430.92000","35.91013","0.02916"
"431.24400","35.93710","0.02937"
"431.56800","35.96412","0.02945"
"431.89200","35.99115","0.03073"
"432.21600","36.01811","0.03205"
"432.54000","36.04514","0.03160"
"432.86400","36.07216","0.03127"
"433.18800","36.09912","0.03257"
"433.51200","36.12615","0.03331"
"433.83600","36.15311","0.03400"
"434.16000","36.18014","0.03410"
"434.48400","36.20711","0.03537"
"434.80800","36.23407","0.03565"
"435.13200","36.26110","0.03709"
"435.45600","36.28806","0.03657"
"435.78000","36.31515","0.03738"
"436.10400","36.34205","0.03795"
"436.42800","36.36914","0.03874"
"436.75200","36.39616","0.03929"
"437.07600","36.42307","0.04034"
"437.40000","36.45009","0.04087"
"437.72400","36.47712","0.04165"
"438.04800","36.50414","0.04217"
"438.37200","36.53117","0.04233"
"438.69600","36.55807","0.04335"
"439.02000","36.58516","0.04413"
"439.34400","36.61212","0.04501"
"439.66800","36.63909","0.04576"
"439.99200","36.66611","0.04680"
"440.31600","36.69307","0.04734"
"440.64000","36.72016","0.04836"
"440.96400","36.74712","0.04853"
"441.28800","36.77409","0.04939"
"441.61200","36.80117","0.05034"
"441.93600","36.82808","0.05091"
"442.26000","36.85511","0.05118"
"442.58400","36.88213","0.05187"
"442.90800","36.90916","0.05288"
"443.23200","36.93612","0.05411"
"443.55600","36.96309","0.05431"
"443.88000","36.99017","0.05503"
"444.20400","37.01713","0.05583"
"444.52800","37.04410","0.05640"
"444.85200","37.07113","0.05670"
"445.17600","37.09803","0.05747"
"445.50000","37.12511","0.05789"
"445.82400","37.15214","0.05833"
"446.14800","37.17910","0.05888"
"446.47200","37.20613","0.05606"
"446.79600","37.23310","0.05673"
"447.12000","37.26018","0.05835"
"447.44400","37.28709","0.05864"
"447.76800","37.31405","0.05950"
"448.09200","37.34113","0.05975"
"448.41600","37.36804","0.06044"
"448.74000","37.39512","0.06081"
"449.06400","37.42215","0.06125"
"449.38800","37.44912","0.06156"
"449.71200","37.47614","0.06194"
"450.03600","37.50304","0.06224"
"450.36000","37.53019","0.06247"
"450.68400","37.55709","0.06274"
"451.00800","37.58412","0.06318"
"451.33200","37.61115","0.06315"
"451.65600","37.63811","0.06345"
"451.98000","37.66513","0.06353"
"452.30400","37.69210","0.06384"
"452.62800","37.71912","0.06401"
"452.95200","37.74615","0.06399"
"453.27600","37.77305","0.06416"
"453.60000","37.80014","0.06419"
"453.92400","37.82710","0.06433"
"454.24800","37.85413","0.06443"
"454.57200","37.88110","0.06450"
"454.89600","37.90806","0.06463"
"455.22000","37.93515","0.06342"
"455.54400","37.96217","0.06350"
"455.86800","37.98907","0.06396"
"456.19200","38.01610","0.06415"
"456.51600","38.04312","0.06429"
"456.84000","38.07015","0.06428"
"457.16400","38.09711","0.06460"
"457.48800","38.12408","0.06459"
"457.81200","38.15117","0.06465"
"458.13600","38.17807","0.06506"
"458.46000","38.20515","0.06515"
"458.78400","38.23218","0.06563"
"459.10800","38.25908","0.06584"
"459.43200","38.28617","0.06660"
"459.75600","38.31307","0.06676"
"460.08000","38.34016","0.06688"
"460.40400","38.36712","0.06815"
"460.72800","38.39403","0.06867"
"461.05200","38.42111","0.06886"
"461.37600","38.44808","0.06952"
"461.70000","38.47516","0.07045"
"462.02400","38.50219","0.07174"
"462.34800","38.52916","0.07180"
"462.67200","38.55612","0.07282"
"462.99600","38.58308","0.07432"
"463.32000","38.61011","0.07462"
"463.64400","38.63713","0.07575"
"463.96800","38.66410","0.07675"
"464.29200","38.69112","0.07811"
"464.61600","38.71809","0.07918"
"464.94000","38.74505","0.07968"
"465.26400","38.77214","0.08082"
"465.58800","38.79916","0.08223"
"465.91200","38.82607","0.07876"
"466.23600","38.85315","0.07790"
"466.56000","38.88018","0.07860"
"466.88400","38.90714","0.07890"
"467.20800","38.93405","0.07949"
"467.53200","38.96113","0.08108"
"467.85600","38.98810","0.08255"
"468.18000","39.01512","0.08293"
"468.50400","39.04215","0.08366"
"468.82800","39.06911","0.08543"
"469.15200","39.09620","0.08465"
"469.47600","39.12310","0.08593"
"469.80000","39.15012","0.08731"
"470.12400","39.17715","0.08884"
"470.44800","39.20412","0.09151"
"470.77200","39.23114","0.09181"
"471.09600","39.25811","0.09282"
"471.42000","39.28507","0.09360"
"471.74400","39.31215","0.09460"
"472.06800","39.33912","0.09508"
"472.39200","39.36615","0.09666"
"472.71600","39.39311","0.09748"
"473.04000","39.42013","0.09819"
"473.36400","39.44716","0.09901"
"473.68800","39.47407","0.09971"
"474.01200","39.50115","0.10093"
"474.33600","39.52812","0.10219"
"474.66000","39.55514","0.10354"
"474.98400","39.58211","0.10449"
"475.30800","39.60907","0.01672"
"475.63200","39.63616","0.02131"
"475.95600","39.66312","0.02997"
"476.28000","39.69009","0.01547"
"476.60400","39.71717","0.03707"
"476.92800","39.74408","0.02272"
"477.25200","39.77116","0.02348"
"477.57600","39.79806","0.05458"
"477.90000","39.82509","0.02139"
"478.22400","39.85217","0.02670"
"478.54800","39.87902","0.03837"
"478.87200","39.90611","0.02533"
"479.19600","39.93313","0.03938"
"479.52000","39.96009","0.03081"
"479.84400","39.98712","0.02949"
"480.06800","40.00577","0.03606"