File: Force_trajectories/161114/Specimen_RawData_4.csv
End date,"11/14/2016"
Specimen label,"20AG64U"
Maximum Load,"0.26425",N

Time,Extension,Load
(s),(mm),(N)
"0.00000","0.00000","-0.00018"
"0.17400","0.01112","-0.00008"
"0.34800","0.02912","0.00025"
"0.52200","0.04377","0.00119"
"0.69600","0.05818","0.00108"
"0.87000","0.07276","0.00071"
"1.04400","0.08723","0.00125"
"1.21800","0.10170","0.00139"
"1.39200","0.11629","0.00162"
"1.56600","0.13070","0.00250"
"1.74000","0.14517","0.00161"
"1.91400","0.15976","0.00290"
"2.08800","0.17423","0.00262"
"2.26200","0.18870","0.00318"
"2.43600","0.20322","0.00304"
"2.61000","0.21775","0.00320"
"2.78400","0.23222","0.00338"
"2.95800","0.24675","0.00346"
"3.13200","0.26122","0.00371"
"3.30600","0.27569","0.00345"
"3.48000","0.29016","0.00518"
"3.65400","0.30475","0.00441"
"3.82800","0.31922","0.00479"
"4.00200","0.33363","0.00567"
"4.17600","0.34815","0.00611"
"4.35000","0.36268","0.00499"
"4.52400","0.37715","0.00577"
"4.69800","0.39168","0.00551"
"4.87200","0.40615","0.00525"
"5.04600","0.42062","0.00506"
"5.22000","0.43515","0.00649"
"5.39400","0.44974","0.00621"
"5.56800","0.46415","0.00646"
"5.74200","0.47868","0.00731"
"5.91600","0.49320","0.00675"
"6.09000","0.50761","0.00679"
"6.26400","0.52220","0.00694"
"6.43800","0.53667","0.00750"
"6.61200","0.55114","0.00743"
"6.78600","0.56567","0.00711"
"6.96000","0.58020","0.00720"
"7.13400","0.59467","0.00767"
"7.30800","0.60920","0.00716"
"7.48200","0.62372","0.00684"
"7.65600","0.63813","0.00719"
"7.83000","0.65272","0.00843"
"8.00400","0.66725","0.00825"
"8.17800","0.68160","0.00815"
"8.35200","0.69619","0.00898"
"8.52600","0.71066","0.00890"
"8.70000","0.72513","0.00922"
"8.87400","0.73966","0.00864"
"9.04800","0.75419","0.00848"
"9.22200","0.76865","0.00906"
"9.39600","0.78324","0.00988"
"9.57000","0.79777","0.00928"
"9.74400","0.81218","0.00981"
"9.91800","0.82665","0.00978"
"10.09200","0.84124","0.01002"
"10.26600","0.85571","0.01094"
"10.44000","0.87018","0.01003"
"10.61400","0.88471","0.00965"
"10.78800","0.89917","0.01030"
"10.96200","0.91370","0.01081"
"11.13600","0.92823","0.01047"
"11.31000","0.94270","0.01134"
"11.48400","0.95711","0.01132"
"11.65800","0.97170","0.01142"
"11.83200","0.98623","0.01068"
"12.00600","1.00070","0.01085"
"12.18000","1.01517","0.01191"
"12.35400","1.02970","0.01080"
"12.52800","1.04416","0.01116"
"12.70200","1.05869","0.01194"
"12.87600","1.07316","0.01096"
"13.05000","1.08757","0.01155"
"13.22400","1.10216","0.01259"
"13.39800","1.11675","0.01156"
"13.57200","1.13122","0.01157"
"13.74600","1.14569","0.01212"
"13.92000","1.16022","0.01179"
"14.09400","1.17469","0.01215"
"14.26800","1.18915","0.01160"
"14.44200","1.20368","0.01330"
"14.61600","1.21815","0.01217"
"14.79000","1.23268","0.01255"
"14.96400","1.24715","0.01226"
"15.13800","1.26168","0.01248"
"15.31200","1.27615","0.01239"
"15.48600","1.29068","0.01340"
"15.66000","1.30515","0.01226"
"15.83400","1.31967","0.01320"
"16.00800","1.33420","0.01329"
"16.18200","1.34867","0.01267"
"16.35600","1.36314","0.01266"
"16.53000","1.37767","0.01317"
"16.70400","1.39220","0.01266"
"16.87800","1.40667","0.01238"
"17.05200","1.42120","0.01277"
"17.22600","1.43567","0.01403"
"17.40000","1.45014","0.01278"
"17.57400","1.46472","0.01401"
"17.74800","1.47919","0.01316"
"17.92200","1.49366","0.01331"
"18.09600","1.50825","0.01264"
"18.27000","1.52272","0.01278"
"18.44400","1.53713","0.01443"
"18.61800","1.55172","0.01267"
"18.79200","1.56619","0.01395"
"18.96600","1.58066","0.01365"
"19.14000","1.59518","0.01259"
"19.31400","1.60971","0.01370"
"19.48800","1.62412","0.01359"
"19.66200","1.63865","0.01390"
"19.83600","1.65318","0.01376"
"20.01000","1.66765","0.01299"
"20.18400","1.68224","0.01400"
"20.35800","1.69671","0.01337"
"20.53200","1.71112","0.01468"
"20.70600","1.72565","0.01368"
"20.88000","1.74023","0.01413"
"21.05400","1.75464","0.01393"
"21.22800","1.76917","0.01379"
"21.40200","1.78364","0.01436"
"21.57600","1.79817","0.01377"
"21.75000","1.81264","0.01367"
"21.92400","1.82717","0.01409"
"22.09800","1.84170","0.01407"
"22.27200","1.85617","0.01422"
"22.44600","1.87075","0.01368"
"22.62000","1.88522","0.01381"
"22.79400","1.89969","0.01431"
"22.96800","1.91416","0.01424"
"23.14200","1.92869","0.01580"
"23.31600","1.94316","0.01439"
"23.49000","1.95775","0.01579"
"23.66400","1.97216","0.01547"
"23.83800","1.98657","0.01535"
"24.01200","2.00116","0.01447"
"24.18600","2.01574","0.01472"
"24.36000","2.03015","0.01500"
"24.53400","2.04468","0.01552"
"24.70800","2.05921","0.01543"
"24.88200","2.07368","0.01540"
"25.05600","2.08821","0.01543"
"25.23000","2.10274","0.01590"
"25.40400","2.11721","0.01624"
"25.57800","2.13168","0.01538"
"25.75200","2.14621","0.01631"
"25.92600","2.16061","0.01453"
"26.10000","2.17520","0.01569"
"26.27400","2.18967","0.01597"
"26.44800","2.20414","0.01634"
"26.62200","2.21873","0.01615"
"26.79600","2.23320","0.01591"
"26.97000","2.24767","0.01607"
"27.14400","2.26214","0.01570"
"27.31800","2.27673","0.01731"
"27.49200","2.29119","0.01691"
"27.66600","2.30560","0.01711"
"27.84000","2.32019","0.01663"
"28.01400","2.33466","0.01690"
"28.18800","2.34919","0.01672"
"28.36200","2.36372","0.01625"
"28.53600","2.37819","0.01869"
"28.71000","2.39266","0.01781"
"28.88400","2.40719","0.01757"
"29.05800","2.42172","0.01712"
"29.23200","2.43612","0.01692"
"29.40600","2.45071","0.01691"
"29.58000","2.46518","0.01747"
"29.75400","2.47959","0.01792"
"29.92800","2.49418","0.01871"
"30.10200","2.50871","0.01865"
"30.27600","2.52312","0.01831"
"30.45000","2.53771","0.01868"
"30.62400","2.55224","0.01910"
"30.79800","2.56664","0.01895"
"30.97200","2.58117","0.01812"
"31.14600","2.59570","0.01872"
"31.32000","2.61017","0.01920"
"31.49400","2.62470","0.01975"
"31.66800","2.63923","0.01915"
"31.84200","2.65364","0.01895"
"32.01600","2.66817","0.01951"
"32.19000","2.68264","0.01849"
"32.36400","2.69717","0.01984"
"32.53800","2.71163","0.01948"
"32.71200","2.72616","0.02039"
"32.88600","2.74063","0.01976"
"33.06000","2.75516","0.01966"
"33.23400","2.76969","0.01991"
"33.40800","2.78416","0.01990"
"33.58200","2.79863","0.01962"
"33.75600","2.81316","0.02002"
"33.93000","2.82769","0.02077"
"34.10400","2.84222","0.01902"
"34.27800","2.85668","0.02068"
"34.45200","2.87115","0.02011"
"34.62600","2.88562","0.02004"
"34.80000","2.90021","0.01995"
"34.97400","2.91474","0.02074"
"35.14800","2.92915","0.02069"
"35.32200","2.94374","0.02112"
"35.49600","2.95821","0.02063"
"35.67000","2.97262","0.02103"
"35.84400","2.98726","0.02031"
"36.01800","3.00173","0.02131"
"36.19200","3.01614","0.02144"
"36.36600","3.03073","0.02191"
"36.54000","3.04520","0.02198"
"36.71400","3.05961","0.02160"
"36.88800","3.07414","0.02177"
"37.06200","3.08873","0.02224"
"37.23600","3.10314","0.02144"
"37.41000","3.11767","0.02217"
"37.58400","3.13219","0.02120"
"37.75800","3.14666","0.02143"
"37.93200","3.16113","0.02202"
"38.10600","3.17572","0.02179"
"38.28000","3.19019","0.02206"
"38.45400","3.20466","0.02228"
"38.62800","3.21913","0.02170"
"38.80200","3.23366","0.02260"
"38.97600","3.24819","0.02256"
"39.15000","3.26271","0.02282"
"39.32400","3.27718","0.02245"
"39.49800","3.29165","0.02011"
"39.67200","3.30624","0.01952"
"39.84600","3.32071","0.01917"
"40.02000","3.33512","0.01972"
"40.19400","3.34965","0.01969"
"40.36800","3.36418","0.02048"
"40.54200","3.37865","0.02054"
"40.71600","3.39324","0.02190"
"40.89000","3.40764","0.02077"
"41.06400","3.42211","0.02021"
"41.23800","3.43676","0.01948"
"41.41200","3.45123","0.02056"
"41.58600","3.46564","0.02149"
"41.76000","3.48017","0.02108"
"41.93400","3.49470","0.02187"
"42.10800","3.50911","0.02103"
"42.28200","3.52370","0.02123"
"42.45600","3.53822","0.02142"
"42.63000","3.55269","0.02251"
"42.80400","3.56722","0.02188"
"42.97800","3.58169","0.02254"
"43.15200","3.59616","0.02104"
"43.32600","3.61069","0.02018"
"43.50000","3.62522","0.02024"
"43.67400","3.63963","0.02097"
"43.84800","3.65422","0.02115"
"44.02200","3.66869","0.02105"
"44.19600","3.68315","0.02098"
"44.37000","3.69762","0.02120"
"44.54400","3.71227","0.02160"
"44.71800","3.72668","0.02075"
"44.89200","3.74115","0.02156"
"45.06600","3.75568","0.02180"
"45.24000","3.77015","0.02185"
"45.41400","3.78468","0.02206"
"45.58800","3.79921","0.02114"
"45.76200","3.81368","0.02212"
"45.93600","3.82814","0.02114"
"46.11000","3.84273","0.02145"
"46.28400","3.85720","0.02141"
"46.45800","3.87167","0.02205"
"46.63200","3.88620","0.02279"
"46.80600","3.90067","0.02235"
"46.98000","3.91514","0.02138"
"47.15400","3.92973","0.02167"
"47.32800","3.94420","0.02235"
"47.50200","3.95861","0.02217"
"47.67600","3.97319","0.02271"
"47.85000","3.98772","0.02229"
"48.02400","4.00219","0.02171"
"48.19800","4.01672","0.02206"
"48.37200","4.03119","0.02217"
"48.54600","4.04572","0.02330"
"48.72000","4.06019","0.02239"
"48.89400","4.07478","0.02242"
"49.06800","4.08913","0.02224"
"49.24200","4.10365","0.02306"
"49.41600","4.11818","0.02269"
"49.59000","4.13265","0.02203"
"49.76400","4.14712","0.02281"
"49.93800","4.16171","0.02271"
"50.11200","4.17618","0.02293"
"50.28600","4.19065","0.02287"
"50.46000","4.20518","0.02225"
"50.63400","4.21965","0.02334"
"50.80800","4.23418","0.02315"
"50.98200","4.24870","0.02315"
"51.15600","4.26317","0.02265"
"51.33000","4.27764","0.02298"
"51.50400","4.29217","0.02376"
"51.67800","4.30664","0.02358"
"51.85200","4.32111","0.02293"
"52.02600","4.33576","0.02384"
"52.20000","4.35023","0.02308"
"52.37400","4.36464","0.02323"
"52.54800","4.37922","0.02359"
"52.72200","4.39369","0.02388"
"52.89600","4.40816","0.02394"
"53.07000","4.42275","0.02310"
"53.24400","4.43716","0.02345"
"53.41800","4.45169","0.02403"
"53.59200","4.46622","0.02429"
"53.76600","4.48075","0.02384"
"53.94000","4.49516","0.02388"
"54.11400","4.50969","0.02415"
"54.28800","4.52421","0.02370"
"54.46200","4.53868","0.02359"
"54.63600","4.55315","0.02428"
"54.81000","4.56768","0.02467"
"54.98400","4.58215","0.02389"
"55.15800","4.59668","0.02369"
"55.33200","4.61121","0.02420"
"55.50600","4.62568","0.02431"
"55.68000","4.64015","0.02396"
"55.85400","4.65468","0.02396"
"56.02800","4.66914","0.02435"
"56.20200","4.68367","0.02417"
"56.37600","4.69820","0.02466"
"56.55000","4.71267","0.02444"
"56.72400","4.72714","0.02473"
"56.89800","4.74173","0.02460"
"57.07200","4.75620","0.02399"
"57.24600","4.77061","0.02444"
"57.42000","4.78520","0.02530"
"57.59400","4.79972","0.02469"
"57.76800","4.81413","0.02441"
"57.94200","4.82872","0.02451"
"58.11600","4.84313","0.02538"
"58.29000","4.85760","0.02345"
"58.46400","4.87219","0.02355"
"58.63800","4.88672","0.02464"
"58.81200","4.90119","0.02322"
"58.98600","4.91572","0.02261"
"59.16000","4.93018","0.02392"
"59.33400","4.94465","0.02403"
"59.50800","4.95918","0.02309"
"59.68200","4.97371","0.02309"
"59.85600","4.98812","0.02331"
"60.03000","5.00271","0.02376"
"60.20400","5.01724","0.02364"
"60.37800","5.03171","0.02336"
"60.55200","5.04618","0.02457"
"60.72600","5.06071","0.02283"
"60.90000","5.07517","0.02347"
"61.07400","5.08970","0.02370"
"61.24800","5.10423","0.02335"
"61.42200","5.11864","0.02385"
"61.59600","5.13317","0.02428"
"61.77000","5.14770","0.02403"
"61.94400","5.16223","0.02387"
"62.11800","5.17670","0.02471"
"62.29200","5.19117","0.02434"
"62.46600","5.20564","0.02402"
"62.64000","5.22016","0.02394"
"62.81400","5.23469","0.02371"
"62.98800","5.24916","0.02421"
"63.16200","5.26363","0.02423"
"63.33600","5.27822","0.02401"
"63.51000","5.29269","0.02401"
"63.68400","5.30716","0.02356"
"63.85800","5.32169","0.02444"
"64.03200","5.33616","0.02425"
"64.20600","5.35069","0.02454"
"64.38000","5.36521","0.02449"
"64.55400","5.37968","0.02465"
"64.72800","5.39409","0.02505"
"64.90200","5.40868","0.02474"
"65.07600","5.42327","0.02519"
"65.25000","5.43762","0.02473"
"65.42400","5.45221","0.02500"
"65.59800","5.46668","0.02481"
"65.77200","5.48121","0.02515"
"65.94600","5.49567","0.02456"
"66.12000","5.51020","0.02566"
"66.29400","5.52467","0.02505"
"66.46800","5.53920","0.02565"
"66.64200","5.55373","0.02583"
"66.81600","5.56814","0.02537"
"66.99000","5.58273","0.02528"
"67.16400","5.59720","0.02554"
"67.33800","5.61167","0.02577"
"67.51200","5.62619","0.02595"
"67.68600","5.64066","0.02619"
"67.86000","5.65519","0.02572"
"68.03400","5.66966","0.02542"
"68.20800","5.68419","0.02542"
"68.38200","5.69872","0.02535"
"68.55600","5.71319","0.02570"
"68.73000","5.72766","0.02549"
"68.90400","5.74213","0.02590"
"69.07800","5.75666","0.02584"
"69.25200","5.77125","0.02579"
"69.42600","5.78571","0.02723"
"69.60000","5.80012","0.02614"
"69.77400","5.81471","0.02625"
"69.94800","5.82924","0.02627"
"70.12200","5.84365","0.02599"
"70.29600","5.85824","0.02570"
"70.47000","5.87271","0.02646"
"70.64400","5.88718","0.02632"
"70.81800","5.90165","0.02537"
"70.99200","5.91617","0.02662"
"71.16600","5.93064","0.02606"
"71.34000","5.94517","0.02608"
"71.51400","5.95976","0.02652"
"71.68800","5.97423","0.02652"
"71.86200","5.98864","0.02672"
"72.03600","6.00323","0.02621"
"72.21000","6.01764","0.02735"
"72.38400","6.03217","0.02671"
"72.55800","6.04675","0.02635"
"72.73200","6.06110","0.02677"
"72.90600","6.07569","0.02671"
"73.08000","6.09016","0.02670"
"73.25400","6.10469","0.02650"
"73.42800","6.11916","0.02678"
"73.60200","6.13369","0.02679"
"73.77600","6.14822","0.02654"
"73.95000","6.16269","0.02788"
"74.12400","6.17722","0.02764"
"74.29800","6.19168","0.02781"
"74.47200","6.20615","0.02792"
"74.64600","6.22068","0.02718"
"74.82000","6.23521","0.02661"
"74.99400","6.24968","0.02769"
"75.16800","6.26421","0.02777"
"75.34200","6.27868","0.02769"
"75.51600","6.29309","0.02756"
"75.69000","6.30774","0.02766"
"75.86400","6.32220","0.02688"
"76.03800","6.33667","0.02746"
"76.21200","6.35120","0.02823"
"76.38600","6.36573","0.02870"
"76.56000","6.38020","0.02817"
"76.73400","6.39473","0.02871"
"76.90800","6.40920","0.02894"
"77.08200","6.42361","0.02892"
"77.25600","6.43826","0.02888"
"77.43000","6.45273","0.02874"
"77.60400","6.46719","0.02927"
"77.77800","6.48166","0.02859"
"77.95200","6.49619","0.02944"
"78.12600","6.51066","0.02986"
"78.30000","6.52519","0.02947"
"78.47400","6.53972","0.02975"
"78.64800","6.55419","0.02957"
"78.82200","6.56866","0.03007"
"78.99600","6.58319","0.03045"
"79.17000","6.59766","0.03024"
"79.34400","6.61212","0.03043"
"79.51800","6.62671","0.03088"
"79.69200","6.64118","0.03069"
"79.86600","6.65565","0.03054"
"80.04000","6.67018","0.03111"
"80.21400","6.68465","0.03120"
"80.38800","6.69912","0.03087"
"80.56200","6.71371","0.03097"
"80.73600","6.72818","0.03098"
"80.91000","6.74265","0.03145"
"81.08400","6.75717","0.03129"
"81.25800","6.77170","0.03153"
"81.43200","6.78617","0.03186"
"81.60600","6.80070","0.03156"
"81.78000","6.81517","0.03241"
"81.95400","6.82958","0.03171"
"82.12800","6.84423","0.03217"
"82.30200","6.85870","0.03253"
"82.47600","6.87317","0.03251"
"82.65000","6.88769","0.03203"
"82.82400","6.90216","0.03323"
"82.99800","6.91663","0.03272"
"83.17200","6.93122","0.03284"
"83.34600","6.94569","0.03316"
"83.52000","6.96016","0.03332"
"83.69400","6.97463","0.03254"
"83.86800","6.98922","0.03281"
"84.04200","7.00363","0.02960"
"84.21600","7.01816","0.03010"
"84.39000","7.03268","0.03026"
"84.56400","7.04715","0.03063"
"84.73800","7.06168","0.03090"
"84.91200","7.07621","0.02993"
"85.08600","7.09062","0.03006"
"85.26000","7.10515","0.03057"
"85.43400","7.11968","0.03103"
"85.60800","7.13421","0.03075"
"85.78200","7.14862","0.03056"
"85.95600","7.16320","0.03081"
"86.13000","7.17767","0.03053"
"86.30400","7.19214","0.03040"
"86.47800","7.20667","0.03049"
"86.65200","7.22120","0.03089"
"86.82600","7.23561","0.03074"
"87.00000","7.25020","0.03141"
"87.17400","7.26473","0.03112"
"87.34800","7.27914","0.03101"
"87.52200","7.29373","0.03153"
"87.69600","7.30819","0.03085"
"87.87000","7.32266","0.03096"
"88.04400","7.33719","0.03127"
"88.21800","7.35172","0.03109"
"88.39200","7.36613","0.03109"
"88.56600","7.38066","0.03040"
"88.74000","7.39525","0.03102"
"88.91400","7.40966","0.03203"
"89.08800","7.42419","0.03036"
"89.26200","7.43871","0.03057"
"89.43600","7.45312","0.03137"
"89.61000","7.46771","0.03096"
"89.78400","7.48224","0.03068"
"89.95800","7.49671","0.03137"
"90.13200","7.51118","0.03172"
"90.30600","7.52571","0.03199"
"90.48000","7.54018","0.03219"
"90.65400","7.55471","0.03226"
"90.82800","7.56918","0.03169"
"91.00200","7.58365","0.03117"
"91.17600","7.59817","0.03148"
"91.35000","7.61270","0.03222"
"91.52400","7.62717","0.03228"
"91.69800","7.64164","0.03288"
"91.87200","7.65623","0.03265"
"92.04600","7.67070","0.03260"
"92.22000","7.68517","0.03291"
"92.39400","7.69970","0.02846"
"92.56800","7.71417","0.03002"
"92.74200","7.72863","0.03147"
"92.91600","7.74322","0.03015"
"93.09000","7.75763","0.03153"
"93.26400","7.77210","0.03103"
"93.43800","7.78669","0.03061"
"93.61200","7.80122","0.03161"
"93.78600","7.81563","0.03154"
"93.96000","7.83022","0.03250"
"94.13400","7.84475","0.03299"
"94.30800","7.85915","0.03332"
"94.48200","7.87368","0.03260"
"94.65600","7.88821","0.03119"
"94.83000","7.90262","0.03062"
"95.00400","7.91721","0.03217"
"95.17800","7.93174","0.03243"
"95.35200","7.94615","0.03164"
"95.52600","7.96068","0.03237"
"95.70000","7.97527","0.03172"
"95.87400","7.98962","0.03301"
"96.04800","8.00420","0.03130"
"96.22200","8.01873","0.03143"
"96.39600","8.03314","0.03112"
"96.57000","8.04767","0.03115"
"96.74400","8.06220","0.03137"
"96.91800","8.07667","0.03149"
"97.09200","8.09120","0.03202"
"97.26600","8.10573","0.03133"
"97.44000","8.12014","0.03079"
"97.61400","8.13466","0.03176"
"97.78800","8.14919","0.03264"
"97.96200","8.16366","0.03225"
"98.13600","8.17813","0.03191"
"98.31000","8.19266","0.03249"
"98.48400","8.20719","0.03223"
"98.65800","8.22172","0.03301"
"98.83200","8.23619","0.03349"
"99.00600","8.25066","0.03309"
"99.18000","8.26507","0.03343"
"99.35400","8.27971","0.03364"
"99.52800","8.29418","0.03356"
"99.70200","8.30865","0.03446"
"99.87600","8.32324","0.03405"
"100.05000","8.33765","0.03452"
"100.22400","8.35218","0.03424"
"100.39800","8.36671","0.03461"
"100.57200","8.38118","0.03562"
"100.74600","8.39565","0.03539"
"100.92000","8.41018","0.03515"
"101.09400","8.42470","0.03586"
"101.26800","8.43917","0.03557"
"101.44200","8.45364","0.03629"
"101.61600","8.46823","0.03614"
"101.79000","8.48270","0.03666"
"101.96400","8.49723","0.03671"
"102.13800","8.51170","0.03628"
"102.31200","8.52617","0.03659"
"102.48600","8.54064","0.03669"
"102.66000","8.55522","0.03708"
"102.83400","8.56969","0.03741"
"103.00800","8.58422","0.03769"
"103.18200","8.59869","0.03770"
"103.35600","8.61316","0.03792"
"103.53000","8.62769","0.03796"
"103.70400","8.64222","0.03892"
"103.87800","8.65669","0.03886"
"104.05200","8.67110","0.03900"
"104.22600","8.68569","0.03866"
"104.40000","8.70021","0.03908"
"104.57400","8.71462","0.03942"
"104.74800","8.72921","0.03881"
"104.92200","8.74368","0.03977"
"105.09600","8.75815","0.03909"
"105.27000","8.77274","0.03944"
"105.44400","8.78721","0.04003"
"105.61800","8.80162","0.04023"
"105.79200","8.81615","0.04041"
"105.96600","8.83073","0.04051"
"106.14000","8.84514","0.03960"
"106.31400","8.85967","0.04194"
"106.48800","8.87420","0.04175"
"106.66200","8.88867","0.04236"
"106.83600","8.90320","0.04158"
"107.01000","8.91773","0.04252"
"107.18400","8.93220","0.04294"
"107.35800","8.94667","0.04294"
"107.53200","8.96119","0.04338"
"107.70600","8.97566","0.04296"
"107.88000","8.99019","0.04355"
"108.05400","9.00466","0.04398"
"108.22800","9.01919","0.04415"
"108.40200","9.03372","0.04471"
"108.57600","9.04819","0.04555"
"108.75000","9.06266","0.04569"
"108.92400","9.07713","0.04529"
"109.09800","9.09172","0.04601"
"109.27200","9.10618","0.04511"
"109.44600","9.12065","0.04604"
"109.62000","9.13518","0.04680"
"109.79400","9.14965","0.04677"
"109.96800","9.16418","0.04721"
"110.14200","9.17877","0.04563"
"110.31600","9.19318","0.04620"
"110.49000","9.20765","0.04681"
"110.66400","9.22218","0.04368"
"110.83800","9.23671","0.04518"
"111.01200","9.25111","0.04555"
"111.18600","9.26570","0.04241"
"111.36000","9.28023","0.04394"
"111.53400","9.29464","0.04442"
"111.70800","9.30923","0.04530"
"111.88200","9.32370","0.04501"
"112.05600","9.33811","0.04398"
"112.23000","9.35270","0.04484"
"112.40400","9.36723","0.04570"
"112.57800","9.38170","0.04677"
"112.75200","9.39622","0.04701"
"112.92600","9.41069","0.04793"
"113.10000","9.42516","0.04818"
"113.27400","9.43969","0.04657"
"113.44800","9.45422","0.04724"
"113.62200","9.46869","0.04802"
"113.79600","9.48316","0.04872"
"113.97000","9.49769","0.04949"
"114.14400","9.51216","0.05037"
"114.31800","9.52668","0.04943"
"114.49200","9.54121","0.05054"
"114.66600","9.55568","0.05116"
"114.84000","9.57015","0.05183"
"115.01400","9.58468","0.05195"
"115.18800","9.59915","0.05204"
"115.36200","9.61362","0.05228"
"115.53600","9.62821","0.05194"
"115.71000","9.64274","0.05310"
"115.88400","9.65715","0.05329"
"116.05800","9.67167","0.05376"
"116.23200","9.68620","0.05412"
"116.40600","9.70061","0.05458"
"116.58000","9.71520","0.05535"
"116.75400","9.72973","0.05572"
"116.92800","9.74414","0.05616"
"117.10200","9.75867","0.05614"
"117.27600","9.77314","0.05629"
"117.45000","9.78767","0.05674"
"117.62400","9.80219","0.05720"
"117.79800","9.81672","0.05711"
"117.97200","9.83113","0.05636"
"118.14600","9.84572","0.05707"
"118.32000","9.86019","0.05763"
"118.49400","9.87466","0.05660"
"118.66800","9.88919","0.05735"
"118.84200","9.90366","0.05774"
"119.01600","9.91819","0.05782"
"119.19000","9.93266","0.05814"
"119.36400","9.94718","0.05871"
"119.53800","9.96165","0.05883"
"119.71200","9.97618","0.05889"
"119.88600","9.99071","0.05923"
"120.06000","10.00518","0.05934"
"120.23400","10.01965","0.05916"
"120.40800","10.03418","0.05943"
"120.58200","10.04871","0.05979"
"120.75600","10.06324","0.05975"
"120.93000","10.07771","0.05990"
"121.10400","10.09217","0.05984"
"121.27800","10.10658","0.06014"
"121.45200","10.12123","0.06032"
"121.62600","10.13576","0.06009"
"121.80000","10.15011","0.06013"
"121.97400","10.16470","0.06012"
"122.14800","10.17923","0.06014"
"122.32200","10.19364","0.06027"
"122.49600","10.20823","0.06031"
"122.67000","10.22269","0.06048"
"122.84400","10.23716","0.06051"
"123.01800","10.25169","0.06055"
"123.19200","10.26622","0.06058"
"123.36600","10.28063","0.06069"
"123.54000","10.29522","0.06077"
"123.71400","10.30975","0.06095"
"123.88800","10.32416","0.06105"
"124.06200","10.33869","0.06111"
"124.23600","10.35322","0.06119"
"124.41000","10.36768","0.06122"
"124.58400","10.38215","0.06120"
"124.75800","10.39668","0.06123"
"124.93200","10.41115","0.06140"
"125.10600","10.42568","0.06144"
"125.28000","10.44021","0.06153"
"125.45400","10.45468","0.06161"
"125.62800","10.46921","0.06172"
"125.80200","10.48368","0.06184"
"125.97600","10.49815","0.06188"
"126.15000","10.51267","0.06184"
"126.32400","10.52720","0.06208"
"126.49800","10.54167","0.06219"
"126.67200","10.55614","0.06231"
"126.84600","10.57067","0.06264"
"127.02000","10.58514","0.06265"
"127.19400","10.59967","0.06299"
"127.36800","10.61426","0.06311"
"127.54200","10.62866","0.06346"
"127.71600","10.64314","0.06348"
"127.89000","10.65766","0.06364"
"128.06400","10.67219","0.06394"
"128.23800","10.68666","0.06409"
"128.41200","10.70125","0.06447"
"128.58600","10.71572","0.06492"
"128.76000","10.73013","0.06540"
"128.93400","10.74478","0.06567"
"129.10800","10.75925","0.06612"
"129.28200","10.77360","0.06663"
"129.45600","10.78818","0.06687"
"129.63000","10.80271","0.06753"
"129.80400","10.81712","0.06803"
"129.97800","10.83171","0.06848"
"130.15200","10.84624","0.06914"
"130.32600","10.86071","0.06919"
"130.50000","10.87518","0.07033"
"130.67400","10.88977","0.07123"
"130.84800","10.90418","0.07175"
"131.02200","10.91864","0.07194"
"131.19600","10.93317","0.07261"
"131.37000","10.94764","0.07373"
"131.54400","10.96217","0.07414"
"131.71800","10.97670","0.07480"
"131.89200","10.99117","0.07570"
"132.06600","11.00564","0.07596"
"132.24000","11.02023","0.07651"
"132.41400","11.03470","0.07761"
"132.58800","11.04910","0.07810"
"132.76200","11.06369","0.07896"
"132.93600","11.07822","0.08021"
"133.11000","11.09269","0.08023"
"133.28400","11.10716","0.08150"
"133.45800","11.12169","0.08219"
"133.63200","11.13616","0.08273"
"133.80600","11.15075","0.08365"
"133.98000","11.16522","0.08450"
"134.15400","11.17963","0.08512"
"134.32800","11.19415","0.08699"
"134.50200","11.20868","0.08715"
"134.67600","11.22315","0.08768"
"134.85000","11.23768","0.08891"
"135.02400","11.25221","0.08936"
"135.19800","11.26668","0.09018"
"135.37200","11.28121","0.09105"
"135.54600","11.29568","0.09141"
"135.72000","11.31015","0.09214"
"135.89400","11.32468","0.09297"
"136.06800","11.33921","0.09351"
"136.24200","11.35367","0.09398"
"136.41600","11.36814","0.09431"
"136.59000","11.38267","0.09504"
"136.76400","11.39708","0.09558"
"136.93800","11.41167","0.09622"
"137.11200","11.42626","0.09671"
"137.28600","11.44067","0.09726"
"137.46000","11.45514","0.09780"
"137.63400","11.46967","0.09910"
"137.80800","11.48419","0.09973"
"137.98200","11.49866","0.09985"
"138.15600","11.51319","0.10090"
"138.33000","11.52766","0.10232"
"138.50400","11.54213","0.10296"
"138.67800","11.55672","0.10415"
"138.85200","11.57119","0.10449"
"139.02600","11.58566","0.10623"
"139.20000","11.60019","0.10684"
"139.37400","11.61466","0.10835"
"139.54800","11.62918","0.10964"
"139.72200","11.64371","0.11215"
"139.89600","11.65824","0.11261"
"140.07000","11.67265","0.11481"
"140.24400","11.68724","0.11612"
"140.41800","11.70177","0.11787"
"140.59200","11.71612","0.12066"
"140.76600","11.73065","0.12206"
"140.94000","11.74518","0.12363"
"141.11400","11.75970","0.12478"
"141.28800","11.77417","0.12579"
"141.46200","11.78876","0.12680"
"141.63600","11.80317","0.12870"
"141.81000","11.81764","0.12938"
"141.98400","11.83217","0.13055"
"142.15800","11.84664","0.13253"
"142.33200","11.86117","0.13377"
"142.50600","11.87570","0.13418"
"142.68000","11.89017","0.13576"
"142.85400","11.90463","0.13641"
"143.02800","11.91922","0.13771"
"143.20200","11.93369","0.13862"
"143.37600","11.94816","0.13977"
"143.55000","11.96269","0.14024"
"143.72400","11.97722","0.14176"
"143.89800","11.99169","0.14203"
"144.07200","12.00616","0.14297"
"144.24600","12.02069","0.14340"
"144.42000","12.03515","0.14412"
"144.59400","12.04968","0.14460"
"144.76800","12.06415","0.14488"
"144.94200","12.07862","0.14417"
"145.11600","12.09321","0.14419"
"145.29000","12.10774","0.14563"
"145.46400","12.12215","0.14569"
"145.63800","12.13668","0.14647"
"145.81200","12.15121","0.14657"
"145.98600","12.16562","0.14708"
"146.16000","12.18026","0.14723"
"146.33400","12.19467","0.14754"
"146.50800","12.20914","0.14783"
"146.68200","12.22367","0.14779"
"146.85600","12.23820","0.14822"
"147.03000","12.25267","0.14852"
"147.20400","12.26720","0.14858"
"147.37800","12.28173","0.14888"
"147.55200","12.29614","0.14937"
"147.72600","12.31072","0.14979"
"147.90000","12.32525","0.15032"
"148.07400","12.33966","0.15101"
"148.24800","12.35413","0.15105"
"148.42200","12.36872","0.15169"
"148.59600","12.38319","0.15229"
"148.77000","12.39760","0.15296"
"148.94400","12.41219","0.15338"
"149.11800","12.42660","0.15453"
"149.29200","12.44118","0.15439"
"149.46600","12.45577","0.15573"
"149.64000","12.47018","0.15652"
"149.81400","12.48465","0.15739"
"149.98800","12.49918","0.15804"
"150.16200","12.51371","0.15839"
"150.33600","12.52818","0.15899"
"150.51000","12.54265","0.15973"
"150.68400","12.55718","0.12652"
"150.85800","12.57159","0.13214"
"151.03200","12.58617","0.13647"
"151.20600","12.60064","0.13898"
"151.38000","12.61511","0.14115"
"151.55400","12.62970","0.14222"
"151.72800","12.64417","0.14382"
"151.90200","12.65870","0.14504"
"152.07600","12.67317","0.14580"
"152.25000","12.68770","0.14672"
"152.42400","12.70217","0.14692"
"152.59800","12.71670","0.14782"
"152.77200","12.73123","0.14792"
"152.94600","12.74569","0.14839"
"153.12000","12.76016","0.14850"
"153.29400","12.77469","0.14876"
"153.46800","12.78916","0.14884"
"153.64200","12.80369","0.14912"
"153.81600","12.81822","0.15000"
"153.99000","12.83263","0.15025"
"154.16400","12.84722","0.15161"
"154.33800","12.86175","0.15237"
"154.51200","12.87615","0.15357"
"154.68600","12.89068","0.15415"
"154.86000","12.90521","0.15578"
"155.03400","12.91968","0.15684"
"155.20800","12.93415","0.15834"
"155.38200","12.94868","0.15929"
"155.55600","12.96315","0.16093"
"155.73000","12.97762","0.16171"
"155.90400","12.99227","0.16303"
"156.07800","13.00673","0.16412"
"156.25200","13.02114","0.16480"
"156.42600","13.03573","0.16599"
"156.60000","13.05014","0.16689"
"156.77400","13.06467","0.16785"
"156.94800","13.07920","0.16901"
"157.12200","13.09367","0.17113"
"157.29600","13.10814","0.17154"
"157.47000","13.12273","0.17265"
"157.64400","13.13725","0.17364"
"157.81800","13.15166","0.17515"
"157.99200","13.16619","0.17683"
"158.16600","13.18072","0.17808"
"158.34000","13.19519","0.17900"
"158.51400","13.20966","0.18102"
"158.68800","13.22425","0.18219"
"158.86200","13.23866","0.18383"
"159.03600","13.25319","0.18481"
"159.21000","13.26778","0.18632"
"159.38400","13.28219","0.18734"
"159.55800","13.29665","0.18867"
"159.73200","13.31118","0.18997"
"159.90600","13.32565","0.19080"
"160.08000","13.34018","0.19201"
"160.25400","13.35471","0.19353"
"160.42800","13.36918","0.19506"
"160.60200","13.38371","0.19623"
"160.77600","13.39824","0.19756"
"160.95000","13.41271","0.19836"
"161.12400","13.42718","0.19998"
"161.29800","13.44164","0.20179"
"161.47200","13.45617","0.20280"
"161.64600","13.47070","0.20375"
"161.82000","13.48517","0.20552"
"161.99400","13.49964","0.20580"
"162.16800","13.51411","0.20698"
"162.34200","13.52870","0.20801"
"162.51600","13.54323","0.20820"
"162.69000","13.55764","0.20873"
"162.86400","13.57222","0.20895"
"163.03800","13.58669","0.20930"
"163.21200","13.60116","0.20931"
"163.38600","13.61581","0.20953"
"163.56000","13.63016","0.20975"
"163.73400","13.64463","0.20975"
"163.90800","13.65922","0.21001"
"164.08200","13.67375","0.21004"
"164.25600","13.68816","0.21022"
"164.43000","13.70268","0.21046"
"164.60400","13.71721","0.21098"
"164.77800","13.73168","0.21115"
"164.95200","13.74621","0.21161"
"165.12600","13.76068","0.21224"
"165.30000","13.77515","0.21247"
"165.47400","13.78962","0.21411"
"165.64800","13.80421","0.21504"
"165.82200","13.81868","0.21634"
"165.99600","13.83315","0.21743"
"166.17000","13.84773","0.21846"
"166.34400","13.86214","0.21987"
"166.51800","13.87667","0.22091"
"166.69200","13.89120","0.22198"
"166.86600","13.90567","0.22359"
"167.04000","13.92014","0.22362"
"167.21400","13.93473","0.22516"
"167.38800","13.94920","0.22591"
"167.56200","13.96367","0.22722"
"167.73600","13.97819","0.22781"
"167.91000","13.99266","0.22874"
"168.08400","14.00713","0.22944"
"168.25800","14.02166","0.23107"
"168.43200","14.03619","0.23195"
"168.60600","14.05060","0.23296"
"168.78000","14.06519","0.23342"
"168.95400","14.07972","0.23457"
"169.12800","14.09419","0.23586"
"169.30200","14.10872","0.23641"
"169.47600","14.12319","0.23769"
"169.65000","14.13765","0.23829"
"169.82400","14.15224","0.23906"
"169.99800","14.16665","0.24037"
"170.17200","14.18118","0.24087"
"170.34600","14.19565","0.24161"
"170.52000","14.21024","0.24245"
"170.69400","14.22471","0.24323"
"170.86800","14.23918","0.24396"
"171.04200","14.25371","0.24466"
"171.21600","14.26817","0.24566"
"171.39000","14.28270","0.24620"
"171.56400","14.29723","0.24675"
"171.73800","14.31164","0.24770"
"171.91200","14.32617","0.24824"
"172.08600","14.34070","0.24888"
"172.26000","14.35517","0.24954"
"172.43400","14.36970","0.24993"
"172.60800","14.38417","0.25084"
"172.78200","14.39863","0.25165"
"172.95600","14.41317","0.25242"
"173.13000","14.42775","0.25340"
"173.30400","14.44222","0.25382"
"173.47800","14.45663","0.25430"
"173.65200","14.47116","0.25559"
"173.82600","14.48569","0.25569"
"174.00000","14.50016","0.25683"
"174.17400","14.51469","0.25773"
"174.34800","14.52916","0.25835"
"174.52200","14.54363","0.25944"
"174.69600","14.55821","0.25999"
"174.87000","14.57274","0.26069"
"175.04400","14.58715","0.26202"
"175.21800","14.60174","0.26254"
"175.39200","14.61621","0.12398"
"175.56600","14.63062","0.02291"
"175.74000","14.64521","0.06029"
"175.91400","14.65974","0.03856"
"176.08800","14.67415","0.05400"
"176.26200","14.68867","0.04124"
"176.43600","14.70326","0.05512"
"176.61000","14.71761","0.04313"
"176.78400","14.73214","0.05154"
"176.95800","14.74667","0.04765"
"177.13200","14.76120","0.05251"
"177.30600","14.77573","0.04996"
"177.48000","14.79020","0.04973"
"177.65400","14.80467","0.05525"
"177.82800","14.81913","0.05200"
"178.00200","14.83378","0.05470"
"178.17600","14.84819","0.05244"
"178.35000","14.86266","0.05730"
"178.52400","14.87719","0.05464"
"178.69800","14.89166","0.05488"
"178.87200","14.90619","0.05405"
"179.04600","14.92072","0.05713"
"179.22000","14.93519","0.05788"
"179.39400","14.94966","0.05620"
"179.56800","14.96418","0.05720"
"179.74200","14.97865","0.05934"
"179.91600","14.99318","0.05854"
"180.09000","15.00771","0.05819"
"180.26400","15.02218","0.05841"
"180.43800","15.03665","0.06038"
"180.61200","15.05124","0.05879"
"180.78600","15.06565","0.05939"
"180.96000","15.08012","0.06025"
"181.13400","15.09465","0.06077"
"181.30800","15.10923","0.06001"
"181.48200","15.12364","0.06037"
"181.65600","15.13823","0.06108"
"181.83000","15.15270","0.06069"
"182.00400","15.16717","0.06083"
"182.17800","15.18170","0.06098"
"182.35200","15.19623","0.06133"
"182.52600","15.21064","0.06116"
"182.70000","15.22517","0.06123"
"182.87400","15.23970","0.06146"
"183.04800","15.25416","0.06145"
"183.22200","15.26869","0.06139"
"183.39600","15.28322","0.06161"
"183.57000","15.29763","0.06177"
"183.74400","15.31216","0.06178"
"183.91800","15.32675","0.06192"
"184.09200","15.34116","0.06195"
"184.26600","15.35569","0.06243"
"184.44000","15.37022","0.06250"
"184.61400","15.38469","0.06247"
"184.78800","15.39915","0.06282"
"184.96200","15.41368","0.06348"
"185.13600","15.42815","0.06314"
"185.31000","15.44262","0.06346"
"185.48400","15.45721","0.06475"
"185.65800","15.47168","0.06463"
"185.83200","15.48615","0.06460"
"186.00600","15.50068","0.06609"
"186.18000","15.51521","0.06604"
"186.35400","15.52961","0.06590"
"186.52800","15.54420","0.06697"
"186.70200","15.55867","0.06802"
"186.87600","15.57314","0.06734"
"187.05000","15.58773","0.06845"
"187.22400","15.60220","0.07062"
"187.39800","15.61667","0.06928"
"187.57200","15.63120","0.07024"
"187.74600","15.64572","0.07145"
"187.92000","15.66019","0.07129"
"188.09400","15.67472","0.07223"
"188.26800","15.68925","0.07323"
"188.44200","15.70366","0.07337"
"188.61600","15.71819","0.07439"
"188.79000","15.73272","0.07505"
"188.96400","15.74719","0.07584"
"189.13800","15.76166","0.07736"
"189.31200","15.77619","0.07752"
"189.48600","15.79065","0.07916"
"189.66000","15.80512","0.08019"
"189.83400","15.81965","0.08023"
"190.00800","15.83412","0.08232"
"190.18200","15.84865","0.08416"
"190.35600","15.86324","0.08356"
"190.53000","15.87771","0.08532"
"190.70400","15.89212","0.08713"
"190.87800","15.90671","0.08611"
"191.05200","15.92118","0.08771"
"191.22600","15.93564","0.08910"
"191.40000","15.95023","0.08880"
"191.57400","15.96464","0.09069"
"191.74800","15.97911","0.09164"
"191.92200","15.99370","0.09098"
"192.09600","16.00823","0.09252"
"192.27000","16.02264","0.09265"
"192.44400","16.03723","0.09306"
"192.61800","16.05169","0.09442"
"192.79200","16.06616","0.09419"
"192.96600","16.08069","0.09501"
"193.14000","16.09522","0.09553"
"193.31400","16.10963","0.09585"
"193.48800","16.12416","0.09672"
"193.66200","16.13869","0.09703"
"193.83600","16.15310","0.09780"
"194.01000","16.16769","0.09860"
"194.18400","16.18216","0.09826"
"194.35800","16.19669","0.09987"
"194.53200","16.21115","0.10014"
"194.70600","16.22568","0.10017"
"194.88000","16.24021","0.10222"
"195.05400","16.25468","0.10225"
"195.22800","16.26921","0.10284"
"195.40200","16.28368","0.10477"
"195.57600","16.29815","0.10479"
"195.75000","16.31268","0.10593"
"195.92400","16.32715","0.10815"
"196.09800","16.34167","0.10880"
"196.27200","16.35620","0.10931"
"196.44600","16.37067","0.10969"
"196.62000","16.38514","0.11207"
"196.79400","16.39973","0.11255"
"196.96800","16.41420","0.11367"
"197.14200","16.42861","0.11656"
"197.31600","16.44320","0.11599"
"197.49000","16.45767","0.11867"
"197.66400","16.47214","0.11937"
"197.83800","16.48672","0.12031"
"198.01200","16.50119","0.12194"
"198.18600","16.51560","0.12369"
"198.36000","16.53019","0.12336"
"198.53400","16.54472","0.12645"
"198.70800","16.55913","0.12658"
"198.88200","16.57372","0.12827"
"199.05600","16.58825","0.12952"
"199.23000","16.60266","0.13069"
"199.40400","16.61724","0.13176"
"199.57800","16.63171","0.13231"
"199.75200","16.64618","0.13371"
"199.92600","16.66065","0.13409"
"200.10000","16.67518","0.13556"
"200.27400","16.68959","0.13647"
"200.44800","16.70418","0.13639"
"200.62200","16.71871","0.13842"
"200.79600","16.73318","0.13875"
"200.97000","16.74771","0.13953"
"201.14400","16.76223","0.14085"
"201.31800","16.77664","0.14048"
"201.49200","16.79111","0.14172"
"201.66600","16.80570","0.14246"
"201.84000","16.82017","0.14270"
"202.01400","16.83470","0.14340"
"202.18800","16.84917","0.14390"
"202.36200","16.86370","0.14422"
"202.53600","16.87817","0.14466"
"202.71000","16.89270","0.14527"
"202.88400","16.90717","0.14518"
"203.05800","16.92163","0.14464"
"203.23200","16.93622","0.14246"
"203.40600","16.95069","0.05207"
"203.58000","16.96516","0.05526"
"203.75400","16.97969","0.05547"
"203.92800","16.99422","0.05673"
"204.10200","17.00863","0.05669"
"204.27600","17.02321","0.05764"
"204.45000","17.03768","0.05710"
"204.62400","17.05215","0.05790"
"204.79800","17.06668","0.05781"
"204.97200","17.08121","0.05831"
"205.14600","17.09568","0.05838"
"205.32000","17.11015","0.05813"
"205.49400","17.12468","0.05818"
"205.66800","17.13915","0.05864"
"205.84200","17.15368","0.05868"
"206.01600","17.16821","0.05853"
"206.19000","17.18262","0.05896"
"206.36400","17.19720","0.05849"
"206.53800","17.21167","0.04092"
"206.71200","17.22620","0.04155"
"206.88600","17.24073","0.03954"
"207.06000","17.25520","0.03068"
"207.23400","17.26967","0.02487"
"207.40800","17.28420","0.01198"
"207.58200","17.29873","0.01207"
"207.75600","17.31320","0.01197"
"207.93000","17.32767","0.01249"
"208.10400","17.34219","0.01303"
"208.27800","17.35666","0.01247"
"208.45200","17.37113","0.01105"
"208.62600","17.38572","0.01203"
"208.80000","17.40013","0.01273"
"208.97400","17.41466","0.01234"
"209.14800","17.42919","0.01283"
"209.32200","17.44372","0.01260"
"209.49600","17.45807","0.01139"
"209.67000","17.47271","0.01216"
"209.84400","17.48724","0.01331"
"210.01800","17.50165","0.01251"
"210.19200","17.51618","0.01282"
"210.36600","17.53071","0.01249"
"210.54000","17.54512","0.01227"
"210.71400","17.55971","0.01311"
"210.88800","17.57424","0.01265"
"211.06200","17.58865","0.01234"
"211.23600","17.60317","0.01182"
"211.41000","17.61770","0.01300"
"211.58400","17.63217","0.01217"
"211.75800","17.64664","0.01172"
"211.93200","17.66117","0.01197"
"212.10600","17.67570","0.01248"
"212.28000","17.69017","0.01237"
"212.45400","17.70470","0.01365"
"212.62800","17.71917","0.01231"
"212.80200","17.73363","0.01294"
"212.97600","17.74816","0.01249"
"213.15000","17.76269","0.01298"
"213.32400","17.77716","0.01193"
"213.49800","17.79169","0.01275"
"213.67200","17.80610","0.01240"
"213.84600","17.82069","0.01250"
"214.02000","17.83522","0.01315"
"214.19400","17.84969","0.01247"
"214.36800","17.86416","0.01259"
"214.54200","17.87868","0.01290"
"214.71600","17.89321","0.01271"
"214.89000","17.90768","0.01224"
"215.06400","17.92221","0.01176"
"215.23800","17.93668","0.01256"
"215.41200","17.95115","0.01207"
"215.58600","17.96568","0.01170"
"215.76000","17.98021","0.01258"
"215.93400","17.99462","0.01228"
"216.10800","18.00920","0.01203"
"216.28200","18.02367","0.01180"
"216.45600","18.03814","0.01287"
"216.63000","18.05273","0.01228"
"216.80400","18.06726","0.01130"
"216.97800","18.08167","0.01170"
"217.15200","18.09620","0.01197"
"217.32600","18.11073","0.01220"
"217.50000","18.12514","0.01155"
"217.67400","18.13967","0.01237"
"217.84800","18.15419","0.01243"
"218.02200","18.16866","0.01177"
"218.19600","18.18319","0.01122"
"218.37000","18.19772","0.01227"
"218.54400","18.21213","0.01219"
"218.71800","18.22666","0.01174"
"218.89200","18.24119","0.01239"
"219.06600","18.25572","0.01136"
"219.24000","18.27013","0.01192"
"219.41400","18.28466","0.01206"
"219.58800","18.29918","0.01221"
"219.76200","18.31365","0.01163"
"219.93600","18.32824","0.01163"
"220.11000","18.34271","0.01284"
"220.28400","18.35712","0.01168"
"220.45800","18.37171","0.01224"
"220.63200","18.38618","0.01317"
"220.80600","18.40065","0.01229"
"220.98000","18.41517","0.01233"
"221.15400","18.42964","0.01139"
"221.32800","18.44411","0.01195"
"221.50200","18.45876","0.01141"
"221.67600","18.47317","0.01249"
"221.85000","18.48764","0.01279"
"222.02400","18.50217","0.01208"
"222.19800","18.51670","0.01250"
"222.37200","18.53117","0.01278"
"222.54600","18.54570","0.01146"
"222.72000","18.56022","0.01214"
"222.89400","18.57463","0.01185"
"223.06800","18.58916","0.01244"
"223.24200","18.60369","0.01216"
"223.41600","18.61816","0.01221"
"223.59000","18.63269","0.01177"
"223.76400","18.64722","0.01272"
"223.93800","18.66169","0.01265"
"224.11200","18.67616","0.01207"
"224.28600","18.69069","0.01223"
"224.46000","18.70516","0.01164"
"224.63400","18.71968","0.01253"
"224.80800","18.73427","0.01235"
"224.98200","18.74868","0.01108"
"225.15600","18.76315","0.01226"
"225.33000","18.77768","0.01256"
"225.50400","18.79221","0.01178"
"225.67800","18.80668","0.01245"
"225.85200","18.82121","0.01186"
"226.02600","18.83562","0.01242"
"226.20000","18.85015","0.01277"
"226.37400","18.86473","0.01194"
"226.54800","18.87920","0.01247"
"226.72200","18.89367","0.01184"
"226.89600","18.90820","0.01305"
"227.07000","18.92273","0.01289"
"227.24400","18.93714","0.01178"
"227.41800","18.95167","0.01244"
"227.59200","18.96626","0.01156"
"227.76600","18.98061","0.01169"
"227.94000","18.99519","0.01240"
"228.11400","19.00966","0.01221"
"228.28800","19.02407","0.01151"
"228.46200","19.03872","0.01247"
"228.63600","19.05319","0.01312"
"228.81000","19.06766","0.01222"
"228.98400","19.08219","0.01208"
"229.15800","19.09672","0.01118"
"229.33200","19.11119","0.01271"
"229.50600","19.12572","0.01231"
"229.68000","19.14024","0.01281"
"229.85400","19.15465","0.01261"
"230.02800","19.16918","0.01129"
"230.20200","19.18365","0.01205"
"230.37600","19.19818","0.01278"
"230.55000","19.21265","0.01200"
"230.72400","19.22718","0.01183"
"230.89800","19.24165","0.01228"
"231.07200","19.25618","0.01193"
"231.24600","19.27070","0.01289"
"231.42000","19.28517","0.01160"
"231.59400","19.29964","0.01223"
"231.76800","19.31417","0.01253"
"231.94200","19.32870","0.01215"
"232.11600","19.34317","0.01252"
"232.29000","19.35776","0.01266"
"232.46400","19.37217","0.01197"
"232.63800","19.38664","0.01145"
"232.81200","19.40123","0.01166"
"232.98600","19.41575","0.01175"
"233.16000","19.43016","0.01186"
"233.33400","19.44469","0.01231"
"233.50800","19.45922","0.01204"
"233.68200","19.47363","0.01218"
"233.85600","19.48822","0.01167"
"234.03000","19.50269","0.01270"
"234.20400","19.51716","0.01176"
"234.37800","19.53169","0.01235"
"234.55200","19.54622","0.01203"
"234.72600","19.56062","0.01200"
"234.90000","19.57509","0.01240"
"235.07400","19.58974","0.01235"
"235.24800","19.60415","0.01241"
"235.42200","19.61868","0.01179"
"235.59600","19.63321","0.01283"
"235.77000","19.64768","0.01199"
"235.94400","19.66215","0.01194"
"236.11800","19.67668","0.01149"
"236.29200","19.69114","0.01125"
"236.46600","19.70567","0.01213"
"236.64000","19.72020","0.01233"
"236.81400","19.73467","0.01313"
"236.98800","19.74920","0.01216"
"237.16200","19.76367","0.01265"
"237.33600","19.77820","0.01296"
"237.51000","19.79261","0.01275"
"237.68400","19.80720","0.01231"
"237.85800","19.82173","0.01184"
"238.03200","19.83614","0.01206"
"238.20600","19.85066","0.01216"
"238.38000","19.86513","0.01232"
"238.55400","19.87966","0.01190"
"238.72800","19.89425","0.01164"
"238.90200","19.90866","0.01240"
"239.07600","19.92313","0.01307"
"239.25000","19.93772","0.01169"
"239.42400","19.95218","0.01194"
"239.59800","19.96665","0.01272"
"239.77200","19.98118","0.01215"
"239.94600","19.99571","0.01155"
"240.12000","20.01012","0.01159"
"240.29400","20.02471","0.01144"
"240.46800","20.03918","0.01121"
"240.64200","20.05365","0.01216"
"240.81600","20.06818","0.01206"
"240.99000","20.08271","0.01236"
"241.16400","20.09718","0.01224"
"241.33800","20.11164","0.01132"
"241.51200","20.12623","0.01151"
"241.68600","20.14064","0.01156"
"241.86000","20.15523","0.01147"
"242.03400","20.16970","0.01166"
"242.20800","20.18417","0.01201"
"242.38200","20.19864","0.01116"
"242.55600","20.21323","0.01080"
"242.73000","20.22770","0.01224"
"242.90400","20.24217","0.01185"
"243.07800","20.25669","0.01094"
"243.25200","20.27116","0.01138"
"243.42600","20.28569","0.01211"
"243.60000","20.30016","0.01152"
"243.77400","20.31469","0.01182"
"243.94800","20.32916","0.01188"
"244.12200","20.34369","0.01190"
"244.29600","20.35822","0.01172"
"244.47000","20.37263","0.01076"
"244.64400","20.38715","0.01179"
"244.81800","20.40168","0.01205"
"244.99200","20.41609","0.01190"
"245.16600","20.43074","0.01118"
"245.34000","20.44521","0.01143"
"245.51400","20.45962","0.01227"
"245.68800","20.47415","0.01117"
"245.86200","20.48874","0.01168"
"246.03600","20.50321","0.01143"
"246.21000","20.51767","0.01250"
"246.38400","20.53220","0.01209"
"246.55800","20.54667","0.01199"
"246.73200","20.56120","0.01208"
"246.90600","20.57573","0.01180"
"247.08000","20.59014","0.01277"
"247.25400","20.60467","0.01157"
"247.42800","20.61920","0.01220"
"247.60200","20.63367","0.01187"
"247.77600","20.64814","0.01158"
"247.95000","20.66267","0.01202"
"248.12400","20.67713","0.01185"
"248.29800","20.69166","0.01249"
"248.47200","20.70625","0.01122"
"248.64600","20.72066","0.01203"
"248.82000","20.73513","0.01208"
"248.99400","20.74966","0.01148"
"249.16800","20.76419","0.01191"
"249.34200","20.77866","0.01253"
"249.51600","20.79325","0.01326"
"249.69000","20.80766","0.01193"
"249.86400","20.82212","0.01102"
"250.03800","20.83677","0.01248"
"250.21200","20.85124","0.01142"
"250.38600","20.86559","0.01164"
"250.56000","20.88024","0.01164"
"250.73400","20.89471","0.01191"
"250.90800","20.90911","0.01145"
"251.08200","20.92371","0.01192"
"251.25600","20.93817","0.01086"
"251.43000","20.95264","0.01214"
"251.60400","20.96717","0.01143"
"251.77800","20.98170","0.01132"
"251.95200","20.99617","0.01214"
"252.12600","21.01064","0.01194"
"252.30000","21.02523","0.01190"
"252.47400","21.03970","0.01214"
"252.64800","21.05423","0.01184"
"252.82200","21.06870","0.01174"
"252.99600","21.08316","0.01203"
"253.17000","21.09763","0.01255"
"253.34400","21.11216","0.01229"
"253.51800","21.12669","0.01137"
"253.69200","21.14110","0.01290"
"253.86600","21.15563","0.01215"
"254.04000","21.17016","0.01233"
"254.21400","21.18469","0.01315"
"254.38800","21.19921","0.01161"
"254.56200","21.21369","0.01184"
"254.73600","21.22816","0.01124"
"254.91000","21.24274","0.01275"
"255.08400","21.25721","0.01240"
"255.25800","21.27168","0.01246"
"255.43200","21.28621","0.01171"
"255.60600","21.30068","0.01259"
"255.78000","21.31515","0.01260"
"255.95400","21.32974","0.01250"
"256.12800","21.34414","0.01244"
"256.30200","21.35861","0.01245"
"256.47600","21.37320","0.01182"
"256.57200","21.38121","0.01233"