File: Force_trajectories/161114/Specimen_RawData_8.csv
End date,"11/14/2016"
Specimen label,"20BT60"
Maximum Load,"0.35281",N

Time,Extension,Load
(s),(mm),(N)
"0.00000","0.00000","-0.00027"
"0.20400","0.01459","-0.00056"
"0.40800","0.03426","0.00013"
"0.61200","0.05124","0.00027"
"0.81600","0.06828","0.00082"
"1.02000","0.08520","0.00124"
"1.22400","0.10224","0.00103"
"1.42800","0.11928","0.00177"
"1.63200","0.13620","0.00115"
"1.83600","0.15330","0.00144"
"2.04000","0.17028","0.00165"
"2.24400","0.18720","0.00214"
"2.44800","0.20424","0.00182"
"2.65200","0.22122","0.00306"
"2.85600","0.23820","0.00221"
"3.06000","0.25524","0.00156"
"3.26400","0.27216","0.00255"
"3.46800","0.28926","0.00219"
"3.67200","0.30624","0.00231"
"3.87600","0.32316","0.00300"
"4.08000","0.34026","0.00270"
"4.28400","0.35718","0.00302"
"4.48800","0.37422","0.00314"
"4.69200","0.39114","0.00273"
"4.89600","0.40812","0.00322"
"5.10000","0.42522","0.00386"
"5.30400","0.44220","0.00386"
"5.50800","0.45918","0.00367"
"5.71200","0.47622","0.00406"
"5.91600","0.49314","0.00377"
"6.12000","0.51024","0.00342"
"6.32400","0.52722","0.00367"
"6.52800","0.54420","0.00368"
"6.73200","0.56118","0.00357"
"6.93600","0.57822","0.00362"
"7.14000","0.59520","0.00343"
"7.34400","0.61224","0.00318"
"7.54800","0.62917","0.00392"
"7.75200","0.64621","0.00361"
"7.95600","0.66325","0.00452"
"8.16000","0.68017","0.00337"
"8.36400","0.69727","0.00418"
"8.56800","0.71419","0.00477"
"8.77200","0.73123","0.00431"
"8.97600","0.74827","0.00447"
"9.18000","0.76513","0.00394"
"9.38400","0.78223","0.00477"
"9.58800","0.79921","0.00515"
"9.79200","0.81619","0.00535"
"9.99600","0.83323","0.00508"
"10.20000","0.85021","0.00465"
"10.40400","0.86719","0.00502"
"10.60800","0.88423","0.00578"
"10.81200","0.90121","0.00578"
"11.01600","0.91819","0.00549"
"11.22000","0.93523","0.00635"
"11.42400","0.95221","0.00621"
"11.62800","0.96919","0.00497"
"11.83200","0.98617","0.00585"
"12.03600","1.00321","0.00526"
"12.24000","1.02025","0.00547"
"12.44400","1.03717","0.00552"
"12.64800","1.05421","0.00533"
"12.85200","1.07119","0.00611"
"13.05600","1.08823","0.00569"
"13.26000","1.10521","0.00598"
"13.46400","1.12219","0.00667"
"13.66800","1.13923","0.00688"
"13.87200","1.15615","0.00611"
"14.07600","1.17319","0.00647"
"14.28000","1.19023","0.00655"
"14.48400","1.20721","0.00667"
"14.68800","1.22419","0.00693"
"14.89200","1.24123","0.00625"
"15.09600","1.25815","0.00650"
"15.30000","1.27525","0.00736"
"15.50400","1.29217","0.00734"
"15.70800","1.30921","0.00782"
"15.91200","1.32619","0.00715"
"16.11600","1.34317","0.00833"
"16.32000","1.36021","0.00792"
"16.52400","1.37725","0.00683"
"16.72800","1.39417","0.00762"
"16.93200","1.41127","0.00716"
"17.13600","1.42819","0.00844"
"17.34000","1.44517","0.00629"
"17.54400","1.46227","0.00654"
"17.74800","1.47913","0.00670"
"17.95200","1.49617","0.00703"
"18.15600","1.51321","0.00743"
"18.36000","1.53013","0.00740"
"18.56400","1.54723","0.00749"
"18.76800","1.56421","0.00721"
"18.97200","1.58119","0.00787"
"19.17600","1.59823","0.00544"
"19.38000","1.61515","0.00611"
"19.58400","1.63225","0.00647"
"19.78800","1.64917","0.00694"
"19.99200","1.66621","0.00682"
"20.19600","1.68319","0.00661"
"20.40000","1.70024","0.00648"
"20.60400","1.71722","0.00649"
"20.80800","1.73420","0.00714"
"21.01200","1.75118","0.00682"
"21.21600","1.76828","0.00637"
"21.42000","1.78526","0.00715"
"21.62400","1.80218","0.00609"
"21.82800","1.81922","0.00620"
"22.03200","1.83620","0.00765"
"22.23600","1.85324","0.00670"
"22.44000","1.87022","0.00729"
"22.64400","1.88720","0.00721"
"22.84800","1.90424","0.00772"
"23.05200","1.92122","0.00744"
"23.25600","1.93820","0.00786"
"23.46000","1.95524","0.00902"
"23.66400","1.97216","0.00761"
"23.86800","1.98926","0.00775"
"24.07200","2.00624","0.00795"
"24.27600","2.02316","0.00810"
"24.48000","2.04020","0.00794"
"24.68400","2.05718","0.00905"
"24.88800","2.07422","0.00906"
"25.09200","2.09120","0.00947"
"25.29600","2.10818","0.00853"
"25.50000","2.12522","0.00948"
"25.70400","2.14220","0.00943"
"25.90800","2.15918","0.00989"
"26.11200","2.17622","0.00996"
"26.31600","2.19314","0.00934"
"26.52000","2.21024","0.00854"
"26.72400","2.22728","0.01063"
"26.92800","2.24420","0.00900"
"27.13200","2.26124","0.00971"
"27.33600","2.27828","0.00871"
"27.54000","2.29514","0.01000"
"27.74400","2.31230","0.00988"
"27.94800","2.32916","0.01058"
"28.15200","2.34620","0.01035"
"28.35600","2.36324","0.01135"
"28.56000","2.38016","0.00982"
"28.76400","2.39720","0.01011"
"28.96800","2.41418","0.01094"
"29.17200","2.43122","0.01060"
"29.37600","2.44820","0.01047"
"29.58000","2.46518","0.01038"
"29.78400","2.48222","0.01176"
"29.98800","2.49920","0.01115"
"30.19200","2.51618","0.01089"
"30.39600","2.53322","0.01160"
"30.60000","2.55020","0.01181"
"30.80400","2.56718","0.01274"
"31.00800","2.58422","0.01176"
"31.21200","2.60120","0.01222"
"31.41600","2.61818","0.01244"
"31.62000","2.63522","0.01316"
"31.82400","2.65214","0.01310"
"32.02800","2.66924","0.01215"
"32.23200","2.68616","0.01323"
"32.43600","2.70320","0.01221"
"32.64000","2.72024","0.01287"
"32.84400","2.73716","0.01309"
"33.04800","2.75426","0.01263"
"33.25200","2.77119","0.01344"
"33.45600","2.78817","0.01287"
"33.66000","2.80521","0.01436"
"33.86400","2.82219","0.01333"
"34.06800","2.83923","0.01383"
"34.27200","2.85627","0.01322"
"34.47600","2.87319","0.01322"
"34.68000","2.89023","0.01386"
"34.88400","2.90715","0.01500"
"35.08800","2.92419","0.01414"
"35.29200","2.94117","0.01372"
"35.49600","2.95815","0.01443"
"35.70000","2.97525","0.01522"
"35.90400","2.99229","0.01500"
"36.10800","3.00921","0.01466"
"36.31200","3.02619","0.01480"
"36.51600","3.04323","0.01515"
"36.72000","3.06021","0.01507"
"36.92400","3.07725","0.01487"
"37.12800","3.09417","0.01620"
"37.33200","3.11121","0.01508"
"37.53600","3.12819","0.01588"
"37.74000","3.14517","0.01545"
"37.94400","3.16221","0.01647"
"38.14800","3.17919","0.01728"
"38.35200","3.19617","0.01685"
"38.55600","3.21321","0.01744"
"38.76000","3.23019","0.01739"
"38.96400","3.24723","0.01767"
"39.16800","3.26415","0.01780"
"39.37200","3.28119","0.01779"
"39.57600","3.29823","0.01842"
"39.78000","3.31521","0.01864"
"39.98400","3.33219","0.01950"
"40.18800","3.34923","0.01866"
"40.39200","3.36621","0.01861"
"40.59600","3.38325","0.01919"
"40.80000","3.40029","0.01896"
"41.00400","3.41721","0.01920"
"41.20800","3.43425","0.01975"
"41.41200","3.45117","0.01995"
"41.61600","3.46821","0.02025"
"41.82000","3.48519","0.02044"
"42.02400","3.50217","0.02081"
"42.22800","3.51927","0.02022"
"42.43200","3.53619","0.02064"
"42.63600","3.55323","0.02081"
"42.84000","3.57027","0.02121"
"43.04400","3.58719","0.02208"
"43.24800","3.60423","0.02188"
"43.45200","3.62121","0.02251"
"43.65600","3.63819","0.02240"
"43.86000","3.65517","0.02304"
"44.06400","3.67215","0.02287"
"44.26800","3.68925","0.02187"
"44.47200","3.70623","0.02289"
"44.67600","3.72321","0.02333"
"44.88000","3.74025","0.02363"
"45.08400","3.75723","0.02434"
"45.28800","3.77421","0.02333"
"45.49200","3.79119","0.02403"
"45.69600","3.80817","0.02500"
"45.90000","3.82521","0.02458"
"46.10400","3.84226","0.02530"
"46.30800","3.85912","0.02533"
"46.51200","3.87628","0.02549"
"46.71600","3.89326","0.02549"
"46.92000","3.91018","0.02605"
"47.12400","3.92728","0.02610"
"47.32800","3.94420","0.02577"
"47.53200","3.96124","0.02623"
"47.73600","3.97816","0.02699"
"47.94000","3.99514","0.02677"
"48.14400","4.01224","0.02724"
"48.34800","4.02910","0.02756"
"48.55200","4.04626","0.02786"
"48.75600","4.06324","0.02793"
"48.96000","4.08016","0.02821"
"49.16400","4.09720","0.02815"
"49.36800","4.11424","0.02850"
"49.57200","4.13116","0.02839"
"49.77600","4.14820","0.02871"
"49.98000","4.16518","0.02897"
"50.18400","4.18222","0.02915"
"50.38800","4.19926","0.02989"
"50.59200","4.21618","0.02967"
"50.79600","4.23322","0.03011"
"51.00000","4.25020","0.03072"
"51.20400","4.26718","0.03092"
"51.40800","4.28428","0.03069"
"51.61200","4.30120","0.03106"
"51.81600","4.31818","0.03150"
"52.02000","4.33528","0.03166"
"52.22400","4.35214","0.03158"
"52.42800","4.36924","0.03255"
"52.63200","4.38616","0.03223"
"52.83600","4.40320","0.03335"
"53.04000","4.42024","0.03312"
"53.24400","4.43716","0.03320"
"53.44800","4.45420","0.03371"
"53.65200","4.47124","0.03321"
"53.85600","4.48822","0.03356"
"54.06000","4.50514","0.03484"
"54.26400","4.52218","0.03456"
"54.46800","4.53916","0.03508"
"54.67200","4.55620","0.03421"
"54.87600","4.57318","0.03514"
"55.08000","4.59022","0.03614"
"55.28400","4.60726","0.03597"
"55.48800","4.62418","0.03607"
"55.69200","4.64122","0.03654"
"55.89600","4.65826","0.03636"
"56.10000","4.67518","0.03686"
"56.30400","4.69222","0.03691"
"56.50800","4.70914","0.03738"
"56.71200","4.72618","0.03770"
"56.91600","4.74316","0.03810"
"57.12000","4.76014","0.03829"
"57.32400","4.77724","0.03891"
"57.52800","4.79416","0.03878"
"57.73200","4.81126","0.03942"
"57.93600","4.82824","0.03955"
"58.14000","4.84516","0.04011"
"58.34400","4.86226","0.04014"
"58.54800","4.87918","0.04031"
"58.75200","4.89616","0.04086"
"58.95600","4.91320","0.04107"
"59.16000","4.93018","0.04099"
"59.36400","4.94723","0.04210"
"59.56800","4.96421","0.04154"
"59.77200","4.98113","0.04204"
"59.97600","4.99823","0.04242"
"60.18000","5.01527","0.04316"
"60.38400","5.03219","0.04339"
"60.58800","5.04923","0.04358"
"60.79200","5.06615","0.04399"
"60.99600","5.08319","0.04356"
"61.20000","5.10029","0.04362"
"61.40400","5.11715","0.04382"
"61.60800","5.13431","0.04442"
"61.81200","5.15123","0.04434"
"62.01600","5.16821","0.04486"
"62.22000","5.18525","0.04475"
"62.42400","5.20217","0.04558"
"62.62800","5.21921","0.04571"
"62.83200","5.23625","0.04626"
"63.03600","5.25317","0.04666"
"63.24000","5.27015","0.04661"
"63.44400","5.28719","0.04691"
"63.64800","5.30423","0.04723"
"63.85200","5.32121","0.04720"
"64.05600","5.33819","0.04764"
"64.26000","5.35523","0.04787"
"64.46400","5.37221","0.04775"
"64.66800","5.38919","0.04817"
"64.87200","5.40623","0.04827"
"65.07600","5.42321","0.04845"
"65.28000","5.44019","0.04913"
"65.48400","5.45723","0.04914"
"65.68800","5.47421","0.04941"
"65.89200","5.49125","0.04969"
"66.09600","5.50823","0.04939"
"66.30000","5.52521","0.04982"
"66.50400","5.54225","0.04992"
"66.70800","5.55917","0.05033"
"66.91200","5.57627","0.05063"
"67.11600","5.59319","0.05076"
"67.32000","5.61011","0.05083"
"67.52400","5.62721","0.05121"
"67.72800","5.64419","0.05114"
"67.93200","5.66123","0.05126"
"68.13600","5.67821","0.05151"
"68.34000","5.69519","0.05192"
"68.54400","5.71223","0.05172"
"68.74800","5.72921","0.05188"
"68.95200","5.74619","0.05209"
"69.15600","5.76323","0.05223"
"69.36000","5.78015","0.05243"
"69.56400","5.79719","0.05273"
"69.76800","5.81423","0.05305"
"69.97200","5.83115","0.05295"
"70.17600","5.84825","0.05305"
"70.38000","5.86523","0.05332"
"70.58400","5.88215","0.05343"
"70.78800","5.89925","0.05357"
"70.99200","5.91617","0.05361"
"71.19600","5.93321","0.05364"
"71.40000","5.95025","0.05392"
"71.60400","5.96711","0.05397"
"71.80800","5.98422","0.05426"
"72.01200","6.00120","0.05432"
"72.21600","6.01823","0.05433"
"72.42000","6.03522","0.05434"
"72.62400","6.05220","0.05446"
"72.82800","6.06924","0.05458"
"73.03200","6.08622","0.05476"
"73.23600","6.10320","0.05469"
"73.44000","6.12024","0.05474"
"73.64400","6.13716","0.05488"
"73.84800","6.15420","0.05489"
"74.05200","6.17124","0.05498"
"74.25600","6.18822","0.05521"
"74.46000","6.20520","0.05515"
"74.66400","6.22224","0.05529"
"74.86800","6.23916","0.05521"
"75.07200","6.25620","0.05531"
"75.27600","6.27318","0.05539"
"75.48000","6.29022","0.05544"
"75.68400","6.30726","0.05554"
"75.88800","6.32412","0.05551"
"76.09200","6.34128","0.05561"
"76.29600","6.35826","0.05564"
"76.50000","6.37518","0.05571"
"76.70400","6.39222","0.05574"
"76.90800","6.40920","0.05576"
"77.11200","6.42624","0.05585"
"77.31600","6.44328","0.05594"
"77.52000","6.46020","0.05599"
"77.72400","6.47724","0.05594"
"77.92800","6.49422","0.05604"
"78.13200","6.51114","0.05602"
"78.33600","6.52824","0.05609"
"78.54000","6.54522","0.05608"
"78.74400","6.56220","0.05619"
"78.94800","6.57924","0.05634"
"79.15200","6.59616","0.05637"
"79.35600","6.61320","0.05640"
"79.56000","6.63024","0.05659"
"79.76400","6.64716","0.05654"
"79.96800","6.66420","0.05668"
"80.17200","6.68112","0.05687"
"80.37600","6.69822","0.05689"
"80.58000","6.71526","0.05718"
"80.78400","6.73218","0.05718"
"80.98800","6.74922","0.05756"
"81.19200","6.76620","0.05763"
"81.39600","6.78318","0.05762"
"81.60000","6.80022","0.05804"
"81.80400","6.81720","0.05816"
"82.00800","6.83430","0.05811"
"82.21200","6.85116","0.05839"
"82.41600","6.86820","0.05865"
"82.62000","6.88524","0.05934"
"82.82400","6.90216","0.05939"
"83.02800","6.91920","0.05951"
"83.23200","6.93624","0.05945"
"83.43600","6.95316","0.06005"
"83.64000","6.97020","0.06051"
"83.84400","6.98724","0.06084"
"84.04800","7.00416","0.06098"
"84.25200","7.02120","0.06146"
"84.45600","7.03813","0.06182"
"84.66000","7.05516","0.06195"
"84.86400","7.07227","0.06269"
"85.06800","7.08913","0.06276"
"85.27200","7.10623","0.06342"
"85.47600","7.12321","0.06370"
"85.68000","7.14019","0.06402"
"85.88400","7.15723","0.06413"
"86.08800","7.17415","0.06472"
"86.29200","7.19125","0.06485"
"86.49600","7.20817","0.06568"
"86.70000","7.22515","0.06617"
"86.90400","7.24225","0.06586"
"87.10800","7.25923","0.06640"
"87.31200","7.27627","0.06708"
"87.51600","7.29319","0.06785"
"87.72000","7.31017","0.06780"
"87.92400","7.32721","0.06829"
"88.12800","7.34419","0.06914"
"88.33200","7.36117","0.06956"
"88.53600","7.37821","0.07047"
"88.74000","7.39525","0.07088"
"88.94400","7.41217","0.07159"
"89.14800","7.42927","0.07203"
"89.35200","7.44619","0.07209"
"89.55600","7.46323","0.07366"
"89.76000","7.48027","0.07403"
"89.96400","7.49713","0.07478"
"90.16800","7.51429","0.07587"
"90.37200","7.53121","0.07554"
"90.57600","7.54825","0.07692"
"90.78000","7.56523","0.07733"
"90.98400","7.58215","0.07851"
"91.18800","7.59925","0.07899"
"91.39200","7.61617","0.08003"
"91.59600","7.63321","0.08005"
"91.80000","7.65025","0.08099"
"92.00400","7.66717","0.08188"
"92.20800","7.68421","0.08285"
"92.41200","7.70119","0.08345"
"92.61600","7.71817","0.08445"
"92.82000","7.73521","0.08452"
"93.02400","7.75219","0.08495"
"93.22800","7.76917","0.08573"
"93.43200","7.78621","0.08609"
"93.63600","7.80319","0.08647"
"93.84000","7.82023","0.08670"
"94.04400","7.83721","0.08752"
"94.24800","7.85419","0.08695"
"94.45200","7.87123","0.08716"
"94.65600","7.88821","0.08803"
"94.86000","7.90525","0.08835"
"95.06400","7.92223","0.08897"
"95.26800","7.93915","0.08968"
"95.47200","7.95625","0.08988"
"95.67600","7.97317","0.09019"
"95.88000","7.99021","0.09069"
"96.08400","8.00725","0.09108"
"96.28800","8.02417","0.09132"
"96.49200","8.04121","0.09203"
"96.69600","8.05825","0.09242"
"96.90000","8.07517","0.09303"
"97.10400","8.09215","0.09345"
"97.30800","8.10913","0.09416"
"97.51200","8.12617","0.09463"
"97.71600","8.14321","0.09522"
"97.92000","8.16025","0.09524"
"98.12400","8.17723","0.09638"
"98.32800","8.19422","0.09719"
"98.53200","8.21119","0.09781"
"98.73600","8.22824","0.09889"
"98.94000","8.24522","0.09923"
"99.14400","8.26220","0.10080"
"99.34800","8.27924","0.10180"
"99.55200","8.29616","0.10253"
"99.75600","8.31320","0.10419"
"99.96000","8.33024","0.10445"
"100.16400","8.34716","0.10597"
"100.36800","8.36426","0.10660"
"100.57200","8.38118","0.10790"
"100.77600","8.39822","0.10975"
"100.98000","8.41526","0.11021"
"101.18400","8.43218","0.11169"
"101.38800","8.44928","0.11246"
"101.59200","8.46614","0.11290"
"101.79600","8.48318","0.11500"
"102.00000","8.50022","0.11662"
"102.20400","8.51720","0.11805"
"102.40800","8.53424","0.11740"
"102.61200","8.55122","0.11977"
"102.81600","8.56814","0.12020"
"103.02000","8.58524","0.12108"
"103.22400","8.60228","0.12285"
"103.42800","8.61920","0.12307"
"103.63200","8.63624","0.12506"
"103.83600","8.65316","0.12520"
"104.04000","8.67014","0.12677"
"104.24400","8.68724","0.12751"
"104.44800","8.70416","0.12878"
"104.65200","8.72126","0.12987"
"104.85600","8.73818","0.13016"
"105.06000","8.75516","0.13136"
"105.26400","8.77226","0.13169"
"105.46800","8.78918","0.13270"
"105.67200","8.80622","0.13310"
"105.87600","8.82320","0.13436"
"106.08000","8.84012","0.13465"
"106.28400","8.85722","0.13549"
"106.48800","8.87420","0.13594"
"106.69200","8.89124","0.13655"
"106.89600","8.90822","0.13728"
"107.10000","8.92520","0.13747"
"107.30400","8.94218","0.13795"
"107.50800","8.95922","0.13845"
"107.71200","8.97614","0.13929"
"107.91600","8.99318","0.13950"
"108.12000","9.01016","0.13972"
"108.32400","9.02714","0.14023"
"108.52800","9.04424","0.14035"
"108.73200","9.06122","0.14090"
"108.93600","9.07826","0.14090"
"109.14000","9.09524","0.14116"
"109.34400","9.11216","0.14108"
"109.54800","9.12926","0.14151"
"109.75200","9.14624","0.14193"
"109.95600","9.16322","0.14177"
"110.16000","9.18021","0.14211"
"110.36400","9.19713","0.14231"
"110.56800","9.21422","0.14263"
"110.77200","9.23120","0.14276"
"110.97600","9.24824","0.14281"
"111.18000","9.26523","0.14301"
"111.38400","9.28215","0.14320"
"111.58800","9.29925","0.14356"
"111.79200","9.31623","0.14375"
"111.99600","9.33321","0.14418"
"112.20000","9.35019","0.14497"
"112.40400","9.36717","0.14494"
"112.60800","9.38421","0.14555"
"112.81200","9.40131","0.14628"
"113.01600","9.41823","0.14656"
"113.22000","9.43521","0.14693"
"113.42400","9.45225","0.14792"
"113.62800","9.46917","0.14852"
"113.83200","9.48621","0.14922"
"114.03600","9.50319","0.14952"
"114.24000","9.52017","0.15027"
"114.44400","9.53727","0.15095"
"114.64800","9.55413","0.15157"
"114.85200","9.57123","0.15240"
"115.05600","9.58821","0.15283"
"115.26000","9.60519","0.15405"
"115.46400","9.62223","0.15455"
"115.66800","9.63915","0.15441"
"115.87200","9.65619","0.15555"
"116.07600","9.67323","0.15671"
"116.28000","9.69021","0.15710"
"116.48400","9.70719","0.15774"
"116.68800","9.72417","0.15809"
"116.89200","9.74115","0.15891"
"117.09600","9.75819","0.15951"
"117.30000","9.77523","0.16002"
"117.50400","9.79221","0.16047"
"117.70800","9.80925","0.16171"
"117.91200","9.82617","0.16203"
"118.11600","9.84321","0.16240"
"118.32000","9.86019","0.16320"
"118.52400","9.87723","0.16361"
"118.72800","9.89421","0.16432"
"118.93200","9.91113","0.16513"
"119.13600","9.92823","0.16616"
"119.34000","9.94521","0.16600"
"119.54400","9.96219","0.16686"
"119.74800","9.97923","0.16752"
"119.95200","9.99615","0.16863"
"120.15600","10.01325","0.16925"
"120.36000","10.03023","0.17034"
"120.56400","10.04715","0.17100"
"120.76800","10.06425","0.17158"
"120.97200","10.08117","0.17305"
"121.17600","10.09815","0.17419"
"121.38000","10.11525","0.17479"
"121.58400","10.13217","0.17609"
"121.78800","10.14921","0.17682"
"121.99200","10.16625","0.13523"
"122.19600","10.18317","0.13473"
"122.40000","10.20015","0.13457"
"122.60400","10.21725","0.13390"
"122.80800","10.23417","0.13449"
"123.01200","10.25121","0.13400"
"123.21600","10.26819","0.13443"
"123.42000","10.28517","0.13436"
"123.62400","10.30221","0.13576"
"123.82800","10.31913","0.13656"
"124.03200","10.33629","0.13700"
"124.23600","10.35316","0.13717"
"124.44000","10.37020","0.13733"
"124.64400","10.38724","0.13771"
"124.84800","10.40416","0.13801"
"125.05200","10.42126","0.13892"
"125.25600","10.43818","0.13866"
"125.46000","10.45522","0.13952"
"125.66400","10.47226","0.13950"
"125.86800","10.48918","0.14034"
"126.07200","10.50622","0.14034"
"126.27600","10.52320","0.14060"
"126.48000","10.54012","0.14069"
"126.68400","10.55722","0.14121"
"126.88800","10.57420","0.14140"
"127.09200","10.59124","0.14165"
"127.29600","10.60822","0.14162"
"127.50000","10.62514","0.14169"
"127.70400","10.64218","0.14206"
"127.90800","10.65928","0.14216"
"128.11200","10.67614","0.14247"
"128.31600","10.69330","0.14258"
"128.52000","10.71022","0.14304"
"128.72400","10.72714","0.14312"
"128.92800","10.74430","0.14335"
"129.13200","10.76116","0.14356"
"129.33600","10.77820","0.14420"
"129.54000","10.79518","0.14500"
"129.74400","10.81216","0.14543"
"129.94800","10.82926","0.14543"
"130.15200","10.84618","0.14659"
"130.35600","10.86322","0.14700"
"130.56000","10.88026","0.14738"
"130.76400","10.89718","0.14748"
"130.96800","10.91422","0.14923"
"131.17200","10.93120","0.15054"
"131.37600","10.94818","0.15088"
"131.58000","10.96516","0.15188"
"131.78400","10.98220","0.15262"
"131.98800","10.99918","0.15404"
"132.19200","11.01622","0.15457"
"132.39600","11.03314","0.15468"
"132.60000","11.05024","0.15619"
"132.80400","11.06722","0.15699"
"133.00800","11.08414","0.15774"
"133.21200","11.10130","0.15846"
"133.41600","11.11816","0.15929"
"133.62000","11.13520","0.15991"
"133.82400","11.15218","0.16060"
"134.02800","11.16910","0.16096"
"134.23200","11.18626","0.16228"
"134.43600","11.20318","0.16273"
"134.64000","11.22022","0.16405"
"134.84400","11.23726","0.16436"
"135.04800","11.25412","0.16520"
"135.25200","11.27122","0.16602"
"135.45600","11.28820","0.16746"
"135.66000","11.30519","0.16772"
"135.86400","11.32222","0.16914"
"136.06800","11.33921","0.17001"
"136.27200","11.35618","0.17105"
"136.47600","11.37322","0.17278"
"136.68000","11.39021","0.17348"
"136.88400","11.40724","0.17479"
"137.08800","11.42423","0.17603"
"137.29200","11.44114","0.17690"
"137.49600","11.45825","0.17733"
"137.70000","11.47523","0.17870"
"137.90400","11.49221","0.17965"
"138.10800","11.50925","0.18097"
"138.31200","11.52617","0.18153"
"138.51600","11.54327","0.18234"
"138.72000","11.56025","0.18312"
"138.92400","11.57723","0.18394"
"139.12800","11.59421","0.18502"
"139.33200","11.61119","0.18597"
"139.53600","11.62823","0.18664"
"139.74000","11.64527","0.18745"
"139.94400","11.66219","0.18912"
"140.14800","11.67923","0.18984"
"140.35200","11.69615","0.19080"
"140.55600","11.71319","0.19271"
"140.76000","11.73023","0.19412"
"140.96400","11.74721","0.19496"
"141.16800","11.76419","0.19629"
"141.37200","11.78123","0.19745"
"141.57600","11.79815","0.19837"
"141.78000","11.81519","0.19946"
"141.98400","11.83223","0.19996"
"142.18800","11.84921","0.20106"
"142.39200","11.86619","0.20179"
"142.59600","11.88317","0.20197"
"142.80000","11.90021","0.20270"
"143.00400","11.91719","0.20333"
"143.20800","11.93417","0.20300"
"143.41200","11.95127","0.20352"
"143.61600","11.96819","0.20378"
"143.82000","11.98517","0.20384"
"144.02400","12.00221","0.20401"
"144.22800","12.01913","0.20404"
"144.43200","12.03629","0.20414"
"144.63600","12.05315","0.20425"
"144.84000","12.07019","0.20446"
"145.04400","12.08723","0.20450"
"145.24800","12.10421","0.20467"
"145.45200","12.12125","0.20518"
"145.65600","12.13823","0.20540"
"145.86000","12.15515","0.20539"
"146.06400","12.17225","0.20566"
"146.26800","12.18923","0.20659"
"146.47200","12.20621","0.20664"
"146.67600","12.22319","0.20710"
"146.88000","12.24017","0.20837"
"147.08400","12.25715","0.20935"
"147.28800","12.27425","0.20969"
"147.49200","12.29117","0.21110"
"147.69600","12.30821","0.21151"
"147.90000","12.32519","0.21274"
"148.10400","12.34217","0.21447"
"148.30800","12.35927","0.21549"
"148.51200","12.37613","0.21526"
"148.71600","12.39323","0.21666"
"148.92000","12.41021","0.21777"
"149.12400","12.42719","0.21936"
"149.32800","12.44417","0.21979"
"149.53200","12.46122","0.22071"
"149.73600","12.47820","0.22131"
"149.94000","12.49523","0.22269"
"150.14400","12.51216","0.22348"
"150.34800","12.52919","0.22405"
"150.55200","12.54618","0.22560"
"150.75600","12.56316","0.22664"
"150.96000","12.58020","0.22716"
"151.16400","12.59718","0.22816"
"151.36800","12.61422","0.22927"
"151.57200","12.63120","0.23006"
"151.77600","12.64818","0.23140"
"151.98000","12.66522","0.23173"
"152.18400","12.68220","0.23279"
"152.38800","12.69918","0.23387"
"152.59200","12.71628","0.23473"
"152.79600","12.73320","0.23576"
"153.00000","12.75024","0.23616"
"153.20400","12.76722","0.23715"
"153.40800","12.78414","0.23724"
"153.61200","12.80124","0.23764"
"153.81600","12.81822","0.23843"
"154.02000","12.83520","0.23924"
"154.22400","12.85224","0.23960"
"154.42800","12.86916","0.24018"
"154.63200","12.88620","0.24103"
"154.83600","12.90324","0.24160"
"155.04000","12.92016","0.24257"
"155.24400","12.93720","0.24302"
"155.44800","12.95418","0.24348"
"155.65200","12.97122","0.24388"
"155.85600","12.98826","0.24452"
"156.06000","13.00524","0.24536"
"156.26400","13.02222","0.24580"
"156.46800","13.03926","0.24671"
"156.67200","13.05612","0.24765"
"156.87600","13.07322","0.24818"
"157.08000","13.09014","0.24945"
"157.28400","13.10718","0.25043"
"157.48800","13.12422","0.25110"
"157.69200","13.14114","0.25186"
"157.89600","13.15830","0.25444"
"158.10000","13.17522","0.25481"
"158.30400","13.19220","0.25673"
"158.50800","13.20924","0.25765"
"158.71200","13.22616","0.25930"
"158.91600","13.24320","0.26029"
"159.12000","13.26024","0.26084"
"159.32400","13.27716","0.26210"
"159.52800","13.29420","0.26341"
"159.73200","13.31118","0.26424"
"159.93600","13.32822","0.26554"
"160.14000","13.34520","0.26615"
"160.34400","13.36224","0.26762"
"160.54800","13.37922","0.26847"
"160.75200","13.39626","0.26931"
"160.95600","13.41318","0.27038"
"161.16000","13.43017","0.27122"
"161.36400","13.44720","0.27252"
"161.56800","13.46424","0.27339"
"161.77200","13.48123","0.27453"
"161.97600","13.49814","0.27598"
"162.18000","13.51525","0.27698"
"162.38400","13.53222","0.27724"
"162.58800","13.54915","0.27825"
"162.79200","13.56618","0.28006"
"162.99600","13.58323","0.28178"
"163.20000","13.60021","0.28332"
"163.40400","13.61725","0.28459"
"163.60800","13.63417","0.28575"
"163.81200","13.65127","0.28784"
"164.01600","13.66819","0.28806"
"164.22000","13.68517","0.29006"
"164.42400","13.70221","0.29173"
"164.62800","13.71919","0.29365"
"164.83200","13.73623","0.29519"
"165.03600","13.75327","0.29618"
"165.24000","13.77019","0.29704"
"165.44400","13.78723","0.29883"
"165.64800","13.80421","0.29893"
"165.85200","13.82119","0.30056"
"166.05600","13.83823","0.29921"
"166.26000","13.85515","0.29124"
"166.46400","13.87225","0.16521"
"166.66800","13.88923","0.14986"
"166.87200","13.90621","0.14194"
"167.07600","13.92319","0.15290"
"167.28000","13.94023","0.14645"
"167.48400","13.95721","0.14153"
"167.68800","13.97419","0.14048"
"167.89200","13.99117","0.14155"
"168.09600","14.00827","0.14230"
"168.30000","14.02519","0.14309"
"168.50400","14.04223","0.15080"
"168.70800","14.05921","0.15250"
"168.91200","14.07619","0.15323"
"169.11600","14.09323","0.14990"
"169.32000","14.11021","0.15483"
"169.52400","14.12719","0.15140"
"169.72800","14.14423","0.15224"
"169.93200","14.16121","0.15030"
"170.13600","14.17813","0.15292"
"170.34000","14.19523","0.15266"
"170.54400","14.21215","0.15472"
"170.74800","14.22919","0.15628"
"170.95200","14.24623","0.15703"
"171.15600","14.26315","0.16158"
"171.36000","14.28025","0.16296"
"171.56400","14.29717","0.16752"
"171.76800","14.31415","0.16767"
"171.97200","14.33125","0.17273"
"172.17600","14.34817","0.17004"
"172.38000","14.36521","0.17570"
"172.58400","14.38219","0.17264"
"172.78800","14.39917","0.17858"
"172.99200","14.41621","0.17603"
"173.19600","14.43319","0.18080"
"173.40000","14.45023","0.17699"
"173.60400","14.46721","0.18129"
"173.80800","14.48419","0.17887"
"174.01200","14.50123","0.18264"
"174.21600","14.51821","0.18191"
"174.42000","14.53519","0.18537"
"174.62400","14.55218","0.18427"
"174.82800","14.56921","0.18769"
"175.03200","14.58619","0.18703"
"175.23600","14.60324","0.18941"
"175.44000","14.62016","0.19023"
"175.64400","14.63720","0.19281"
"175.84800","14.65418","0.19329"
"176.05200","14.67116","0.19515"
"176.25600","14.68826","0.19596"
"176.46000","14.70518","0.19763"
"176.66400","14.72222","0.19902"
"176.86800","14.73920","0.20028"
"177.07200","14.75612","0.20115"
"177.27600","14.77328","0.20220"
"177.48000","14.79014","0.20299"
"177.68400","14.80724","0.20326"
"177.88800","14.82422","0.20341"
"178.09200","14.84114","0.20386"
"178.29600","14.85824","0.20399"
"178.50000","14.87522","0.20417"
"178.70400","14.89214","0.20422"
"178.90800","14.90924","0.20460"
"179.11200","14.92622","0.20452"
"179.31600","14.94320","0.20524"
"179.52000","14.96024","0.20551"
"179.72400","14.97716","0.20672"
"179.92800","14.99420","0.20641"
"180.13200","15.01124","0.20899"
"180.33600","15.02816","0.20918"
"180.54000","15.04520","0.21232"
"180.74400","15.06218","0.21172"
"180.94800","15.07916","0.21480"
"181.15200","15.09626","0.21451"
"181.35600","15.11312","0.21796"
"181.56000","15.13028","0.21670"
"181.76400","15.14720","0.22055"
"181.96800","15.16418","0.21896"
"182.17200","15.18122","0.22239"
"182.37600","15.19820","0.22080"
"182.58000","15.21518","0.22445"
"182.78400","15.23222","0.22278"
"182.98800","15.24914","0.22657"
"183.19200","15.26618","0.22524"
"183.39600","15.28316","0.17409"
"183.60000","15.30020","0.02589"
"183.80400","15.31724","0.01622"
"184.00800","15.33422","0.02291"
"184.21200","15.35120","0.01253"
"184.41600","15.36818","0.00837"
"184.62000","15.38516","0.02175"
"184.82400","15.40220","0.00556"
"185.02800","15.41924","0.02311"
"185.23200","15.43622","0.00869"
"185.43600","15.45320","0.01799"
"185.64000","15.47012","0.01407"
"185.84400","15.48722","0.01195"
"186.04800","15.50420","0.01462"
"186.25200","15.52118","0.02194"
"186.45600","15.53822","0.01956"
"186.66000","15.55520","0.01499"
"186.86400","15.57224","0.01192"
"187.06800","15.58922","0.02164"
"187.27200","15.60614","0.01852"
"187.47600","15.62324","0.01844"
"187.68000","15.64016","0.01575"
"187.88400","15.65714","0.02369"
"188.08800","15.67424","0.01911"
"188.29200","15.69116","0.02067"
"188.49600","15.70820","0.01779"
"188.70000","15.72518","0.02402"
"188.90400","15.74217","0.02132"
"189.10800","15.75921","0.02103"
"189.31200","15.77625","0.02002"
"189.51600","15.79317","0.02572"
"189.72000","15.81021","0.02337"
"189.92400","15.82719","0.02473"
"190.12800","15.84417","0.02285"
"190.33200","15.86127","0.02635"
"190.53600","15.87813","0.02353"
"190.74000","15.89529","0.02412"
"190.94400","15.91221","0.02483"
"191.14800","15.92919","0.02732"
"191.35200","15.94623","0.02488"
"191.55600","15.96321","0.02682"
"191.76000","15.98019","0.02773"
"191.96400","15.99723","0.02898"
"192.16800","16.01421","0.02670"
"192.37200","16.03119","0.02720"
"192.57600","16.04817","0.02897"
"192.78000","16.06521","0.02912"
"192.98400","16.08219","0.02908"
"193.18800","16.09923","0.02991"
"193.39200","16.11621","0.03107"
"193.59600","16.13319","0.03095"
"193.80000","16.15017","0.03096"
"194.00400","16.16721","0.03170"
"194.20800","16.18419","0.03236"
"194.41200","16.20123","0.03148"
"194.61600","16.21827","0.03226"
"194.82000","16.23519","0.03378"
"195.02400","16.25217","0.03326"
"195.22800","16.26921","0.03421"
"195.43200","16.28619","0.03506"
"195.63600","16.30323","0.03524"
"195.84000","16.32021","0.03522"
"196.04400","16.33725","0.03520"
"196.24800","16.35423","0.03682"
"196.45200","16.37109","0.03681"
"196.65600","16.38825","0.03737"
"196.86000","16.40517","0.03859"
"197.06400","16.42221","0.03942"
"197.26800","16.43919","0.03900"
"197.47200","16.45617","0.03894"
"197.67600","16.47321","0.04024"
"197.88000","16.49019","0.04031"
"198.08400","16.50717","0.04126"
"198.28800","16.52421","0.04227"
"198.49200","16.54119","0.04249"
"198.69600","16.55817","0.04332"
"198.90000","16.57527","0.04342"
"199.10400","16.59219","0.04432"
"199.30800","16.60923","0.04402"
"199.51200","16.62621","0.04466"
"199.71600","16.64319","0.04566"
"199.92000","16.66023","0.04605"
"200.12400","16.67715","0.04640"
"200.32800","16.69419","0.04669"
"200.53200","16.71123","0.04726"
"200.73600","16.72816","0.04752"
"200.94000","16.74525","0.04815"
"201.14400","16.76217","0.04852"
"201.34800","16.77915","0.04858"
"201.55200","16.79620","0.04891"
"201.75600","16.81318","0.04981"
"201.96000","16.83022","0.05017"
"202.16400","16.84725","0.05036"
"202.36800","16.86418","0.05064"
"202.57200","16.88122","0.05085"
"202.77600","16.89820","0.05123"
"202.98000","16.91518","0.05150"
"203.18400","16.93221","0.05190"
"203.38800","16.94920","0.05242"
"203.59200","16.96618","0.05239"
"203.79600","16.98322","0.05271"
"204.00000","17.00014","0.05285"
"204.20400","17.01718","0.05295"
"204.40800","17.03416","0.05316"
"204.61200","17.05120","0.05332"
"204.81600","17.06824","0.05377"
"205.02000","17.08516","0.05381"
"205.22400","17.10220","0.05414"
"205.42800","17.11924","0.05429"
"205.63200","17.13616","0.05441"
"205.83600","17.15326","0.05470"
"206.04000","17.17018","0.05470"
"206.24400","17.18722","0.05466"
"206.44800","17.20426","0.05495"
"206.65200","17.22118","0.05496"
"206.85600","17.23822","0.05507"
"207.06000","17.25520","0.05528"
"207.26400","17.27218","0.05537"
"207.46800","17.28922","0.05548"
"207.67200","17.30620","0.05557"
"207.87600","17.32318","0.05560"
"208.08000","17.34022","0.05574"
"208.28400","17.35720","0.05575"
"208.48800","17.37418","0.05591"
"208.69200","17.39128","0.05600"
"208.89600","17.40814","0.05608"
"209.10000","17.42518","0.05617"
"209.30400","17.44216","0.05621"
"209.50800","17.45920","0.05647"
"209.71200","17.47624","0.05651"
"209.91600","17.49310","0.05694"
"210.12000","17.51020","0.05679"
"210.32400","17.52718","0.05703"
"210.52800","17.54416","0.05727"
"210.73200","17.56120","0.05740"
"210.93600","17.57824","0.05785"
"211.14000","17.59522","0.05825"
"211.34400","17.61220","0.05850"
"211.54800","17.62924","0.05928"
"211.75200","17.64622","0.05997"
"211.95600","17.66320","0.06045"
"212.16000","17.68018","0.06126"
"212.36400","17.69722","0.06157"
"212.56800","17.71414","0.06230"
"212.77200","17.73124","0.06238"
"212.97600","17.74822","0.06295"
"213.18000","17.76520","0.06381"
"213.38400","17.78218","0.06429"
"213.58800","17.79917","0.06476"
"213.79200","17.81620","0.06507"
"213.99600","17.83330","0.06598"
"214.20000","17.85011","0.06652"
"214.40400","17.86721","0.06726"
"214.60800","17.88424","0.06832"
"214.81200","17.90122","0.06885"
"215.01600","17.91826","0.07032"
"215.22000","17.93519","0.07155"
"215.42400","17.95223","0.07216"
"215.62800","17.96921","0.07335"
"215.83200","17.98613","0.07442"
"216.03600","18.00323","0.07611"
"216.24000","18.02021","0.07518"
"216.44400","18.03725","0.07546"
"216.64800","18.05423","0.07642"
"216.85200","18.07121","0.07796"
"217.05600","18.08819","0.07886"
"217.26000","18.10523","0.08007"
"217.46400","18.12221","0.08127"
"217.66800","18.13919","0.08198"
"217.87200","18.15623","0.08346"
"218.07600","18.17321","0.08475"
"218.28000","18.19025","0.08585"
"218.48400","18.20717","0.08733"
"218.68800","18.22421","0.08772"
"218.89200","18.24125","0.08855"
"219.09600","18.25817","0.08916"
"219.30000","18.27527","0.09019"
"219.50400","18.29219","0.09055"
"219.70800","18.30923","0.09125"
"219.91200","18.32621","0.09209"
"220.11600","18.34319","0.09276"
"220.32000","18.36023","0.09364"
"220.52400","18.37715","0.09449"
"220.72800","18.39419","0.09484"
"220.93200","18.41123","0.09588"
"221.13600","18.42815","0.09637"
"221.34000","18.44525","0.09740"
"221.54400","18.46223","0.09832"
"221.74800","18.47921","0.09991"
"221.95200","18.49619","0.10046"
"222.15600","18.51317","0.10282"
"222.36000","18.53021","0.10363"
"222.56400","18.54725","0.10497"
"222.76800","18.56417","0.10618"
"222.97200","18.58121","0.10806"
"223.17600","18.59825","0.10989"
"223.38000","18.61517","0.11233"
"223.58400","18.63221","0.11346"
"223.78800","18.64919","0.11606"
"223.99200","18.66623","0.11808"
"224.19600","18.68327","0.12012"
"224.40000","18.70013","0.12266"
"224.60400","18.71723","0.12305"
"224.80800","18.73421","0.12435"
"225.01200","18.75113","0.12604"
"225.21600","18.76823","0.12746"
"225.42000","18.78521","0.12784"
"225.62400","18.80225","0.12955"
"225.82800","18.81923","0.13046"
"226.03200","18.83615","0.13145"
"226.23600","18.85320","0.13324"
"226.44000","18.87017","0.13352"
"226.64400","18.88721","0.13552"
"226.84800","18.90419","0.13633"
"227.05200","18.92124","0.13711"
"227.25600","18.93822","0.13811"
"227.46000","18.95519","0.13848"
"227.66400","18.97218","0.13958"
"227.86800","18.98928","0.13976"
"228.07200","19.00626","0.14001"
"228.27600","19.02318","0.14053"
"228.48000","19.04022","0.14083"
"228.68400","19.05720","0.14101"
"228.88800","19.07418","0.14137"
"229.09200","19.09122","0.14184"
"229.29600","19.10814","0.14211"
"229.50000","19.12524","0.14225"
"229.70400","19.14216","0.14242"
"229.90800","19.15926","0.14264"
"230.11200","19.17624","0.14316"
"230.31600","19.19316","0.14332"
"230.52000","19.21026","0.14390"
"230.72400","19.22718","0.14450"
"230.92800","19.24422","0.14259"
"231.13200","19.26126","0.14326"
"231.33600","19.27818","0.14382"
"231.54000","19.29516","0.14486"
"231.74400","19.31220","0.14611"
"231.94800","19.32918","0.14671"
"232.15200","19.34628","0.14777"
"232.35600","19.36326","0.14988"
"232.56000","19.38018","0.15106"
"232.76400","19.39722","0.15281"
"232.96800","19.41420","0.15407"
"233.17200","19.43118","0.15534"
"233.37600","19.44828","0.15638"
"233.58000","19.46514","0.15758"
"233.78400","19.48224","0.15921"
"233.98800","19.49922","0.16041"
"234.19200","19.51620","0.16197"
"234.39600","19.53324","0.16331"
"234.60000","19.55016","0.16367"
"234.80400","19.56720","0.16531"
"235.00800","19.58424","0.16684"
"235.21200","19.60116","0.16814"
"235.41600","19.61820","0.16966"
"235.62000","19.63518","0.17151"
"235.82400","19.65216","0.17236"
"236.02800","19.66920","0.17411"
"236.23200","19.68624","0.17503"
"236.43600","19.70322","0.17710"
"236.64000","19.72020","0.17761"
"236.84400","19.73718","0.17977"
"237.04800","19.75422","0.18110"
"237.25200","19.77120","0.18240"
"237.45600","19.78824","0.18358"
"237.66000","19.80522","0.18455"
"237.86400","19.82214","0.18626"
"238.06800","19.83918","0.18257"
"238.27200","19.85628","0.18469"
"238.47600","19.87314","0.18565"
"238.68000","19.89024","0.18695"
"238.88400","19.90722","0.18892"
"239.08800","19.92420","0.18991"
"239.29200","19.94124","0.19088"
"239.49600","19.95816","0.19246"
"239.70000","19.97520","0.18743"
"239.90400","19.99218","0.18908"
"240.10800","20.00923","0.18869"
"240.31200","20.02626","0.19001"
"240.51600","20.04318","0.19264"
"240.72000","20.06022","0.19447"
"240.92400","20.07721","0.19598"
"241.12800","20.09419","0.19730"
"241.33200","20.11122","0.19819"
"241.53600","20.12821","0.19983"
"241.74000","20.14519","0.20132"
"241.94400","20.16222","0.20196"
"242.14800","20.17921","0.20250"
"242.35200","20.19619","0.20324"
"242.55600","20.21323","0.20341"
"242.76000","20.23015","0.20372"
"242.96400","20.24725","0.20390"
"243.16800","20.26417","0.20401"
"243.37200","20.28121","0.20412"
"243.57600","20.29825","0.20427"
"243.78000","20.31517","0.20448"
"243.98400","20.33227","0.20447"
"244.18800","20.34919","0.20489"
"244.39200","20.36617","0.20563"
"244.59600","20.38321","0.20647"
"244.80000","20.40019","0.20757"
"245.00400","20.41723","0.20794"
"245.20800","20.43427","0.20856"
"245.41200","20.45119","0.20919"
"245.61600","20.46823","0.21116"
"245.82000","20.48515","0.21030"
"246.02400","20.50219","0.21121"
"246.22800","20.51917","0.21304"
"246.43200","20.53621","0.21444"
"246.63600","20.55319","0.21571"
"246.84000","20.57023","0.21698"
"247.04400","20.58715","0.21816"
"247.24800","20.60419","0.21939"
"247.45200","20.62123","0.22023"
"247.65600","20.63821","0.22140"
"247.86000","20.65525","0.22153"
"248.06400","20.67217","0.21766"
"248.26800","20.68921","0.21796"
"248.47200","20.70619","0.21930"
"248.67600","20.72317","0.22021"
"248.88000","20.74021","0.22191"
"249.08400","20.75719","0.22291"
"249.28800","20.77423","0.22425"
"249.49200","20.79121","0.22563"
"249.69600","20.80813","0.22686"
"249.90000","20.82529","0.22773"
"250.10400","20.84215","0.22862"
"250.30800","20.85919","0.22956"
"250.51200","20.87623","0.23092"
"250.71600","20.89322","0.23266"
"250.92000","20.91019","0.23341"
"251.12400","20.92723","0.23463"
"251.32800","20.94421","0.23577"
"251.53200","20.96119","0.23688"
"251.73600","20.97824","0.23405"
"251.94000","20.99516","0.23485"
"252.14400","21.01219","0.23529"
"252.34800","21.02917","0.23597"
"252.55200","21.04622","0.23709"
"252.75600","21.06319","0.23824"
"252.96000","21.08017","0.23935"
"253.16400","21.09727","0.24012"
"253.36800","21.11420","0.24085"
"253.57200","21.13124","0.24150"
"253.77600","21.14821","0.24278"
"253.98000","21.16520","0.24341"
"254.18400","21.18224","0.24375"
"254.38800","21.19921","0.24464"
"254.59200","21.21620","0.24533"
"254.79600","21.23323","0.24583"
"255.00000","21.25021","0.24761"
"255.20400","21.26720","0.24813"
"255.40800","21.28424","0.24931"
"255.61200","21.30116","0.25038"
"255.81600","21.31825","0.25132"
"256.02000","21.33524","0.25185"
"256.22400","21.35216","0.25281"
"256.42800","21.36926","0.25387"
"256.63200","21.38618","0.25514"
"256.83600","21.40322","0.25621"
"257.04000","21.42026","0.25724"
"257.24400","21.43712","0.25853"
"257.44800","21.45422","0.25970"
"257.65200","21.47126","0.26052"
"257.85600","21.48812","0.26152"
"258.06000","21.50528","0.26207"
"258.26400","21.52220","0.26403"
"258.46800","21.53918","0.26478"
"258.67200","21.55622","0.26599"
"258.87600","21.57314","0.26698"
"259.08000","21.59024","0.26914"
"259.28400","21.60716","0.26990"
"259.48800","21.62420","0.27091"
"259.69200","21.64124","0.27210"
"259.89600","21.65816","0.27327"
"260.10000","21.67520","0.27402"
"260.30400","21.69224","0.27549"
"260.50800","21.70922","0.27576"
"260.71200","21.72620","0.27697"
"260.91600","21.74324","0.27796"
"261.12000","21.76016","0.27901"
"261.32400","21.77720","0.28054"
"261.52800","21.79418","0.28159"
"261.73200","21.81122","0.28314"
"261.93600","21.82826","0.28603"
"262.14000","21.84518","0.28874"
"262.34400","21.86222","0.29103"
"262.54800","21.87920","0.29335"
"262.75200","21.89618","0.29384"
"262.95600","21.91322","0.29574"
"263.16000","21.93014","0.29704"
"263.36400","21.94724","0.29760"
"263.56800","21.96422","0.29879"
"263.77200","21.98120","0.30027"
"263.97600","21.99824","0.30119"
"264.18000","22.01516","0.30232"
"264.38400","22.03226","0.30330"
"264.58800","22.04924","0.30427"
"264.79200","22.06616","0.30526"
"264.99600","22.08320","0.30629"
"265.20000","22.10018","0.30656"
"265.40400","22.11716","0.30787"
"265.60800","22.13420","0.30897"
"265.81200","22.15118","0.30998"
"266.01600","22.16822","0.31125"
"266.22000","22.18527","0.31373"
"266.42400","22.20213","0.31470"
"266.62800","22.21922","0.31617"
"266.83200","22.23620","0.31806"
"267.03600","22.25319","0.32071"
"267.24000","22.27023","0.32290"
"267.44400","22.28720","0.32620"
"267.64800","22.30419","0.32818"
"267.85200","22.32122","0.33005"
"268.05600","22.33821","0.33110"
"268.26000","22.35525","0.33242"
"268.46400","22.37217","0.33417"
"268.66800","22.38921","0.33451"
"268.87200","22.40625","0.33539"
"269.07600","22.42317","0.33692"
"269.28000","22.44021","0.33861"
"269.48400","22.45719","0.33934"
"269.68800","22.47423","0.34123"
"269.89200","22.49121","0.34276"
"270.09600","22.50825","0.34383"
"270.30000","22.52517","0.34460"
"270.50400","22.54221","0.34305"
"270.70800","22.55919","0.34491"
"270.91200","22.57623","0.34675"
"271.11600","22.59321","0.34781"
"271.32000","22.61019","0.34863"
"271.52400","22.62723","0.34997"
"271.72800","22.64415","0.35052"
"271.93200","22.66119","0.35128"
"272.13600","22.67823","0.35179"
"272.34000","22.69515","0.35205"
"272.54400","22.71225","0.35229"
"272.74800","22.72923","0.35237"
"272.95200","22.74621","0.35253"
"273.15600","22.76325","0.35256"
"273.36000","22.78017","0.35259"
"273.56400","22.79727","0.35264"
"273.76800","22.81413","0.35260"
"273.97200","22.83117","0.35261"
"274.17600","22.84821","0.35266"
"274.38000","22.86519","0.35272"
"274.58400","22.88223","0.35273"
"274.78800","22.89921","0.26514"
"274.99200","22.91613","0.25915"
"275.19600","22.93329","0.25743"
"275.40000","22.95021","0.26026"
"275.60400","22.96719","0.25946"
"275.80800","22.98423","0.25993"
"276.01200","23.00115","0.25959"
"276.21600","23.01819","0.26208"
"276.42000","23.03529","0.26217"
"276.62400","23.05215","0.26454"
"276.82800","23.06919","0.26561"
"277.03200","23.08624","0.26699"
"277.23600","23.10321","0.26654"
"277.44000","23.12025","0.26856"
"277.64400","23.13712","0.26887"
"277.84800","23.15421","0.27098"
"278.05200","23.17120","0.27122"
"278.25600","23.18812","0.27193"
"278.46000","23.20522","0.10584"
"278.66400","23.22219","0.12108"
"278.86800","23.23918","0.10763"
"279.07200","23.25622","0.13872"
"279.27600","23.27319","0.12289"
"279.48000","23.29024","0.13537"
"279.68400","23.30716","0.11420"
"279.88800","23.32420","0.12799"
"280.09200","23.34118","0.11708"
"280.29600","23.35822","0.12899"
"280.50000","23.37526","0.11947"
"280.70400","23.39224","0.13324"
"280.90800","23.40916","0.12089"
"281.11200","23.42620","0.13449"
"281.31600","23.44324","0.12451"
"281.52000","23.46016","0.13099"
"281.72400","23.47726","0.12799"
"281.92800","23.49418","0.13122"
"282.13200","23.51122","0.13021"
"282.33600","23.52826","0.13479"
"282.54000","23.54512","0.13249"
"282.74400","23.56228","0.13801"
"282.94800","23.57920","0.13357"
"283.15200","23.59618","0.13924"
"283.35600","23.61322","0.13395"
"283.56000","23.63020","0.13846"
"283.76400","23.64724","0.13544"
"283.96800","23.66422","0.13967"
"284.17200","23.68114","0.13846"
"284.37600","23.69824","0.14110"
"284.58000","23.71516","0.13936"
"284.78400","23.73220","0.14152"
"284.98800","23.74924","0.13960"
"285.19200","23.76622","0.14137"
"285.39600","23.78320","0.13999"
"285.60000","23.80024","0.14142"
"285.80400","23.81716","0.14066"
"286.00800","23.83426","0.14153"
"286.21200","23.85118","0.14178"
"286.41600","23.86822","0.14166"
"286.62000","23.88526","0.14215"
"286.82400","23.90218","0.14160"
"287.02800","23.91922","0.14271"
"287.23200","23.93620","0.14193"
"287.43600","23.95318","0.14295"
"287.64000","23.97022","0.14235"
"287.84400","23.98714","0.14329"
"288.04800","24.00418","0.14259"
"288.25200","24.02128","0.14312"
"288.45600","24.03814","0.14342"
"288.66000","24.05524","0.14296"
"288.86400","24.07216","0.14388"
"289.06800","24.08920","0.14353"
"289.27200","24.10618","0.14461"
"289.47600","24.12322","0.14391"
"289.68000","24.14020","0.14502"
"289.88400","24.15718","0.14484"
"290.08800","24.17416","0.14455"
"290.29200","24.19114","0.14515"
"290.49600","24.20819","0.14477"
"290.70000","24.22523","0.14599"
"290.90400","24.24220","0.14609"
"291.10800","24.25918","0.14692"
"291.31200","24.27622","0.14642"
"291.51600","24.29327","0.14762"
"291.72000","24.31013","0.14727"
"291.92400","24.32723","0.14724"
"292.12800","24.34420","0.14729"
"292.33200","24.36118","0.14733"
"292.53600","24.37823","0.14843"
"292.74000","24.39515","0.14775"
"292.94400","24.41225","0.14918"
"293.14800","24.42917","0.14891"
"293.35200","24.44621","0.14955"
"293.55600","24.46319","0.15004"
"293.76000","24.48017","0.14935"
"293.96400","24.49727","0.15021"
"294.16800","24.51424","0.15005"
"294.37200","24.53117","0.15052"
"294.57600","24.54821","0.15072"
"294.78000","24.56519","0.15228"
"294.98400","24.58217","0.15293"
"295.18800","24.59921","0.15244"
"295.39200","24.61619","0.15332"
"295.59600","24.63317","0.15322"
"295.80000","24.65021","0.15275"
"296.00400","24.66719","0.15330"
"296.20800","24.68423","0.15316"
"296.41200","24.70121","0.15315"
"296.61600","24.71819","0.15310"
"296.82000","24.73523","0.15409"
"297.02400","24.75221","0.15453"
"297.22800","24.76925","0.15516"
"297.43200","24.78617","0.15554"
"297.57000","24.79765","0.15608"