File: Force_trajectories/161114/Specimen_RawData_2.csv
End date,"11/14/2016"
Specimen label,"20AG60"
Maximum Load,"1.40394",N

Time,Extension,Load
(s),(mm),(N)
"0.00000","17.40485","0.04586"
"0.30000","17.42877","0.04748"
"0.60000","17.45514","0.04838"
"0.90000","17.48007","0.04933"
"1.20000","17.50512","0.04994"
"1.50000","17.53005","0.05066"
"1.80000","17.55511","0.05133"
"2.10000","17.58010","0.05156"
"2.40000","17.60509","0.05190"
"2.70000","17.63014","0.05228"
"3.00000","17.65507","0.05253"
"3.30000","17.68006","0.05274"
"3.60000","17.70506","0.05300"
"3.90000","17.73017","0.05313"
"4.20000","17.75504","0.05331"
"4.50000","17.78009","0.05343"
"4.80000","17.80508","0.05352"
"5.10000","17.83008","0.05359"
"5.40000","17.85507","0.05374"
"5.70000","17.88006","0.05378"
"6.00000","17.90511","0.05392"
"6.30000","17.93010","0.05404"
"6.60000","17.95510","0.05423"
"6.90000","17.98003","0.05443"
"7.20000","18.00508","0.05459"
"7.50000","18.03007","0.05488"
"7.80000","18.05500","0.05508"
"8.10000","18.08006","0.05560"
"8.40000","18.10499","0.05642"
"8.70000","18.13010","0.05684"
"9.00000","18.15509","0.05777"
"9.30000","18.18014","0.05834"
"9.60000","18.20508","0.05894"
"9.90000","18.23013","0.06012"
"10.20000","18.25512","0.06068"
"10.50000","18.28011","0.06163"
"10.80000","18.30510","0.06294"
"11.10000","18.33004","0.06372"
"11.40000","18.35509","0.06547"
"11.70000","18.38002","0.06691"
"12.00000","18.40513","0.06877"
"12.30000","18.43012","0.07020"
"12.60000","18.45512","0.07185"
"12.90000","18.48011","0.07342"
"13.20000","18.50504","0.07521"
"13.50000","18.53009","0.07743"
"13.80000","18.55503","0.07720"
"14.10000","18.58008","0.07919"
"14.40000","18.60507","0.08053"
"14.70000","18.63012","0.08186"
"15.00000","18.65505","0.08370"
"15.30000","18.68004","0.08510"
"15.60000","18.70516","0.08686"
"15.90000","18.73009","0.08810"
"16.20000","18.75508","0.08948"
"16.50000","18.78007","0.09080"
"16.80000","18.80512","0.09266"
"17.10000","18.83006","0.09534"
"17.40000","18.85505","0.09715"
"17.70000","18.88010","0.10014"
"18.00000","18.90503","0.10329"
"18.30000","18.93008","0.10616"
"18.60000","18.95508","0.11043"
"18.90000","18.98019","0.11316"
"19.20000","19.00506","0.11644"
"19.50000","19.03011","0.11960"
"19.80000","19.05504","0.12259"
"20.10000","19.08010","0.12522"
"20.40000","19.10509","0.12825"
"20.70000","19.13008","0.13057"
"21.00000","19.15507","0.13100"
"21.30000","19.18006","0.13386"
"21.60000","19.20506","0.13574"
"21.90000","19.23005","0.13669"
"22.20000","19.25510","0.13840"
"22.50000","19.28009","0.13749"
"22.80000","19.30514","0.13827"
"23.10000","19.33007","0.13940"
"23.40000","19.35507","0.14001"
"23.70000","19.38006","0.14040"
"24.00000","19.40505","0.14158"
"24.30000","19.43004","0.14174"
"24.60000","19.45504","0.14252"
"24.90000","19.48009","0.14268"
"25.20000","19.50508","0.14374"
"25.50000","19.53007","0.14502"
"25.80000","19.55512","0.14702"
"26.10000","19.58005","0.14900"
"26.40000","19.60511","0.15087"
"26.70000","19.63004","0.15213"
"27.00000","19.65515","0.15431"
"27.30000","19.68002","0.15670"
"27.60000","19.70514","0.15859"
"27.90000","19.73013","0.16107"
"28.20000","19.75512","0.15265"
"28.50000","19.78011","0.15227"
"28.80000","19.80504","0.15332"
"29.10000","19.83010","0.15520"
"29.40000","19.85509","0.15702"
"29.70000","19.88014","0.15907"
"30.00000","19.90507","0.16252"
"30.30000","19.93006","0.16531"
"30.60000","19.95512","0.16741"
"30.90000","19.98005","0.17103"
"31.20000","20.00510","0.17513"
"31.50000","20.03009","0.17844"
"31.80000","20.05508","0.18070"
"32.10000","20.08002","0.18363"
"32.40000","20.10513","0.18747"
"32.70000","20.13006","0.19070"
"33.00000","20.15511","0.19316"
"33.30000","20.18011","0.19527"
"33.60000","20.20504","0.19822"
"33.90000","20.23009","0.19958"
"34.20000","20.25508","0.20078"
"34.50000","20.28007","0.20169"
"34.80000","20.30500","0.20193"
"35.10000","20.33012","0.20268"
"35.40000","20.35505","0.20358"
"35.70000","20.38010","0.20413"
"36.00000","20.40509","0.20584"
"36.30000","20.43008","0.20550"
"36.60000","20.45508","0.18525"
"36.90000","20.48007","0.19306"
"37.20000","20.50506","0.19597"
"37.50000","20.52999","0.19714"
"37.80000","20.55510","0.20031"
"38.10000","20.58010","0.20190"
"38.40000","20.60503","0.20249"
"38.70000","20.63008","0.20363"
"39.00000","20.65507","0.20519"
"39.30000","20.68007","0.20899"
"39.60000","20.70505","0.21329"
"39.90000","20.73011","0.21626"
"40.20000","20.75510","0.21798"
"40.50000","20.78009","0.22208"
"40.80000","20.80502","0.22755"
"41.10000","20.83007","0.22963"
"41.40000","20.85507","0.23004"
"41.70000","20.88006","0.23106"
"42.00000","20.90511","0.23496"
"42.30000","20.93004","0.23848"
"42.60000","20.95515","0.23990"
"42.90000","20.98003","0.24111"
"43.20000","21.00508","0.24316"
"43.50000","21.03007","0.24651"
"43.80000","21.05506","0.24975"
"44.10000","21.08012","0.25286"
"44.40000","21.10511","0.25564"
"44.70000","21.13010","0.25860"
"45.00000","21.15503","0.26179"
"45.30000","21.18014","0.26579"
"45.60000","21.20507","0.26955"
"45.90000","21.23013","0.27448"
"46.20000","21.25506","0.27908"
"46.50000","21.28005","0.28466"
"46.80000","21.30510","0.28808"
"47.10000","21.33010","0.29235"
"47.40000","21.35509","0.29726"
"47.70000","21.38002","0.30099"
"48.00000","21.40507","0.30510"
"48.30000","21.43006","0.30903"
"48.60000","21.45512","0.31447"
"48.90000","21.48011","0.31973"
"49.20000","21.50510","0.32563"
"49.50000","21.53015","0.32789"
"49.80000","21.55502","0.33319"
"50.10000","21.58008","0.33701"
"50.40000","21.60506","0.34091"
"50.70000","21.63012","0.34430"
"51.00000","21.65505","0.34692"
"51.30000","21.68004","0.34870"
"51.60000","21.70515","0.34855"
"51.90000","21.73009","0.34970"
"52.20000","21.75508","0.35031"
"52.50000","21.78001","0.35058"
"52.80000","21.80507","0.35072"
"53.10000","21.83000","0.35101"
"53.40000","21.85511","0.35149"
"53.70000","21.88004","0.35241"
"54.00000","21.90503","0.35435"
"54.30000","21.93002","0.35689"
"54.60000","21.95507","0.36025"
"54.90000","21.98013","0.36426"
"55.20000","22.00506","0.36912"
"55.50000","22.03011","0.37458"
"55.80000","22.05504","0.38094"
"56.10000","22.08010","0.38715"
"56.40000","22.10503","0.39382"
"56.70000","22.13008","0.39887"
"57.00000","22.15507","0.40268"
"57.30000","22.18006","0.40566"
"57.60000","22.20512","0.40910"
"57.90000","22.23005","0.41328"
"58.20000","22.25510","0.41952"
"58.50000","22.28009","0.42451"
"58.80000","22.30508","0.43172"
"59.10000","22.33008","0.43760"
"59.40000","22.35513","0.44256"
"59.70000","22.38012","0.44693"
"60.00000","22.40505","0.45126"
"60.30000","22.43010","0.45449"
"60.60000","22.45504","0.45749"
"60.90000","22.48009","0.46042"
"61.20000","22.50502","0.46314"
"61.50000","22.53013","0.46571"
"61.80000","22.55512","0.46770"
"62.10000","22.58011","0.46963"
"62.40000","22.60511","0.47182"
"62.70000","22.63004","0.47566"
"63.00000","22.65509","0.48025"
"63.30000","22.68008","0.48430"
"63.60000","22.70513","0.48922"
"63.90000","22.73007","0.49442"
"64.20000","22.75512","0.49886"
"64.50000","22.78005","0.50131"
"64.80000","22.80510","0.50319"
"65.10000","22.83010","0.50503"
"65.40000","22.85509","0.50818"
"65.70000","22.88014","0.51284"
"66.00000","22.90507","0.51942"
"66.30000","22.93012","0.52463"
"66.60000","22.95506","0.52950"
"66.90000","22.98005","0.53586"
"67.20000","23.00504","0.54156"
"67.50000","23.03003","0.54599"
"67.80000","23.05508","0.54986"
"68.10000","23.08002","0.55209"
"68.40000","23.10507","0.55375"
"68.70000","23.13000","0.55572"
"69.00000","23.15511","0.55842"
"69.30000","23.18004","0.56353"
"69.60000","23.20515","0.56959"
"69.90000","23.23009","0.57548"
"70.20000","23.25508","0.58117"
"70.50000","23.28007","0.57678"
"70.80000","23.30506","0.58281"
"71.10000","23.33012","0.58721"
"71.40000","23.35505","0.59175"
"71.70000","23.38010","0.59822"
"72.00000","23.40503","0.60483"
"72.30000","23.43014","0.61045"
"72.60000","23.45508","0.61432"
"72.90000","23.48007","0.61718"
"73.20000","23.50506","0.62215"
"73.50000","23.52999","0.62779"
"73.80000","23.55510","0.63384"
"74.10000","23.58003","0.63838"
"74.40000","23.60509","0.64374"
"74.70000","23.63008","0.64758"
"75.00000","23.65507","0.65068"
"75.30000","23.68007","0.65276"
"75.60000","23.70506","0.65411"
"75.90000","23.73011","0.65610"
"76.20000","23.75504","0.65781"
"76.50000","23.78009","0.66036"
"76.80000","23.80502","0.66264"
"77.10000","23.83008","0.66676"
"77.40000","23.85507","0.67199"
"77.70000","23.88000","0.67637"
"78.00000","23.90505","0.68115"
"78.30000","23.93004","0.68729"
"78.60000","23.95515","0.69475"
"78.90000","23.98003","0.70110"
"79.20000","24.00508","0.70516"
"79.50000","24.03007","0.71137"
"79.80000","24.05512","0.71727"
"80.10000","24.08000","0.72406"
"80.40000","24.10505","0.73089"
"80.70000","24.13010","0.73858"
"81.00000","24.15509","0.74454"
"81.30000","24.18008","0.75013"
"81.60000","24.20502","0.75533"
"81.90000","24.23007","0.75857"
"82.20000","24.25512","0.76241"
"82.50000","24.28011","0.76489"
"82.80000","24.30510","0.76651"
"83.10000","24.33010","0.76814"
"83.40000","24.35515","0.76949"
"83.70000","24.38002","0.77231"
"84.00000","24.40507","0.77592"
"84.30000","24.43000","0.78111"
"84.60000","24.45506","0.78712"
"84.90000","24.48005","0.79321"
"85.20000","24.50516","0.79948"
"85.50000","24.53015","0.80484"
"85.80000","24.55514","0.80974"
"86.10000","24.58014","0.81331"
"86.40000","24.60501","0.81781"
"86.70000","24.63012","0.82258"
"87.00000","24.65505","0.83016"
"87.30000","24.68010","0.83614"
"87.60000","24.70504","0.84298"
"87.90000","24.73009","0.84989"
"88.20000","24.75502","0.85628"
"88.50000","24.78001","0.86098"
"88.80000","24.80506","0.86629"
"89.10000","24.83006","0.87102"
"89.40000","24.85511","0.87535"
"89.70000","24.88004","0.87891"
"90.00000","24.90509","0.88316"
"90.30000","24.93008","0.88725"
"90.60000","24.95507","0.89217"
"90.90000","24.98007","0.89862"
"91.20000","25.00506","0.90657"
"91.50000","25.03011","0.91291"
"91.80000","25.05504","0.91738"
"92.10000","25.08010","0.92172"
"92.40000","25.10503","0.92793"
"92.70000","25.13008","0.93600"
"93.00000","25.15507","0.94303"
"93.30000","25.18006","0.95004"
"93.60000","25.20511","0.95727"
"93.90000","25.23005","0.96318"
"94.20000","25.25504","0.96782"
"94.50000","25.28003","0.97024"
"94.80000","25.30508","0.97112"
"95.10000","25.33007","0.97182"
"95.40000","25.35513","0.97416"
"95.70000","25.38012","0.97821"
"96.00000","25.40511","0.98319"
"96.30000","25.43010","0.98021"
"96.60000","25.45510","0.99211"
"96.90000","25.48009","0.99879"
"97.20000","25.50502","1.00484"
"97.50000","25.53007","1.01280"
"97.80000","25.55506","1.02023"
"98.10000","25.58012","1.02698"
"98.40000","25.60511","1.02993"
"98.70000","25.63010","1.03454"
"99.00000","25.65515","1.04002"
"99.30000","25.68003","1.04527"
"99.60000","25.70508","1.04710"
"99.90000","25.73007","1.05205"
"100.20000","25.75512","1.05750"
"100.50000","25.78005","1.06202"
"100.80000","25.80504","1.06588"
"101.10000","25.83009","1.06906"
"101.40000","25.85509","1.07206"
"101.70000","25.88014","1.07569"
"102.00000","25.90507","1.08039"
"102.30000","25.93012","1.08691"
"102.60000","25.95506","1.09358"
"102.90000","25.98005","1.10048"
"103.20000","26.00504","1.10911"
"103.50000","26.03009","1.11592"
"103.80000","26.05508","1.11947"
"104.10000","26.08008","1.12181"
"104.40000","26.10513","1.12537"
"104.70000","26.13006","1.13243"
"105.00000","26.15511","1.14080"
"105.30000","26.18004","1.14886"
"105.60000","26.20510","1.15657"
"105.90000","26.23009","1.16395"
"106.20000","26.25514","1.16983"
"106.50000","26.28013","1.17346"
"106.80000","26.30507","1.17574"
"107.10000","26.33005","1.17790"
"107.40000","26.35505","1.17904"
"107.70000","26.38004","1.18085"
"108.00000","26.40503","1.18288"
"108.30000","26.43014","1.18523"
"108.60000","26.45513","1.18893"
"108.90000","26.48007","1.19408"
"109.20000","26.50506","1.20116"
"109.50000","26.53005","1.21047"
"109.80000","26.55510","1.22097"
"110.10000","26.58004","1.22814"
"110.40000","26.60509","1.23473"
"110.70000","26.63002","1.24349"
"111.00000","26.65513","1.25278"
"111.30000","26.68012","1.26032"
"111.60000","26.70512","1.26638"
"111.90000","26.73010","1.27074"
"112.20000","26.75504","1.27479"
"112.50000","26.78009","1.27824"
"112.80000","26.80508","1.28119"
"113.10000","26.83014","1.28317"
"113.40000","26.85501","1.28647"
"113.70000","26.88006","1.29147"
"114.00000","26.90505","1.29762"
"114.30000","26.93004","1.30552"
"114.60000","26.95509","1.31419"
"114.90000","26.98009","1.32419"
"115.20000","27.00508","1.32993"
"115.50000","27.03007","1.33295"
"115.80000","27.05512","1.33613"
"116.10000","27.08006","1.34251"
"116.40000","27.10511","1.34959"
"116.70000","27.13010","1.35697"
"117.00000","27.15509","1.36491"
"117.30000","27.18008","1.37196"
"117.60000","27.20508","1.37757"
"117.90000","27.23013","1.38260"
"118.20000","27.25506","1.38702"
"118.50000","27.28011","1.39082"
"118.80000","27.30510","1.39362"
"119.10000","27.33010","1.39720"
"119.40000","27.35509","1.40141"
"119.70000","27.38002","1.08113"
"120.00000","27.40507","1.07378"
"120.30000","27.43000","1.08694"
"120.60000","27.45511","1.08550"
"120.90000","27.47999","1.09394"
"121.20000","27.50510","1.09620"
"121.50000","27.53009","1.10880"
"121.80000","27.55514","1.12167"
"122.10000","27.58014","1.12105"
"122.40000","27.60507","1.12452"
"122.70000","27.63012","1.13616"
"123.00000","27.65505","1.14888"
"123.30000","27.68010","1.16490"
"123.60000","27.70504","1.16410"
"123.90000","27.73009","1.17309"
"124.20000","27.75508","0.56583"
"124.50000","27.78007","0.55343"
"124.80000","27.80506","0.55504"
"125.10000","27.83012","0.55333"
"125.40000","27.85511","0.55753"
"125.70000","27.88010","0.56626"
"126.00000","27.90509","0.57906"
"126.30000","27.93003","0.58704"
"126.60000","27.95507","0.59212"
"126.90000","27.98007","0.59974"
"127.20000","28.00506","0.60293"
"127.50000","28.03005","0.60881"
"127.80000","28.05504","0.61368"
"128.10000","28.08010","0.61323"
"128.40000","28.10503","0.61668"
"128.70000","28.13008","0.62172"
"129.00000","28.15507","0.62443"
"129.30000","28.18012","0.63111"
"129.60000","28.20506","0.63748"
"129.90000","28.23005","0.64193"
"130.20000","28.25510","0.64828"
"130.50000","28.28009","0.65113"
"130.80000","28.30508","0.64791"
"131.10000","28.33002","0.65072"
"131.40000","28.35513","0.65238"
"131.70000","28.38012","0.65375"
"132.00000","28.40511","0.65495"
"132.30000","28.43004","0.65627"
"132.60000","28.45509","0.65788"
"132.90000","28.48009","0.66029"
"133.20000","28.50502","0.66257"
"133.50000","28.53007","0.66577"
"133.80000","28.55500","0.66927"
"134.10000","28.58006","0.67300"
"134.40000","28.60505","0.67668"
"134.70000","28.63010","0.67984"
"135.00000","28.65509","0.68374"
"135.30000","28.68014","0.68977"
"135.60000","28.70513","0.69424"
"135.90000","28.73007","0.70203"
"136.20000","28.75512","0.70678"
"136.50000","28.78011","0.71075"
"136.80000","28.80510","0.71443"
"137.10000","28.83004","0.71935"
"137.40000","28.85509","0.72398"
"137.70000","28.88008","0.73033"
"138.00000","28.90507","0.73642"
"138.30000","28.93012","0.74135"
"138.60000","28.95505","0.74488"
"138.90000","28.98011","0.74772"
"139.20000","29.00498","0.75142"
"139.50000","29.03009","0.75520"
"139.80000","29.05508","0.32847"
"140.10000","29.08007","0.33709"
"140.40000","29.10507","0.34660"
"140.70000","29.13006","0.34831"
"141.00000","29.15511","0.34718"
"141.30000","29.18004","0.34731"
"141.60000","29.20509","0.34920"
"141.90000","29.23009","0.35051"
"142.20000","29.25514","0.35111"
"142.50000","29.28001","0.35122"
"142.80000","29.30506","0.35111"
"143.10000","29.33011","0.35116"
"143.40000","29.35511","0.35156"
"143.70000","29.38016","0.35115"
"144.00000","29.40509","0.35231"
"144.30000","29.43008","0.35408"
"144.60000","29.45508","0.35521"
"144.90000","29.48013","0.35512"
"145.20000","29.50506","0.35518"
"145.50000","29.53005","0.35608"
"145.80000","29.55510","0.35858"
"146.10000","29.58003","0.18199"
"146.40000","29.60509","0.19451"
"146.70000","29.63002","0.18931"
"147.00000","29.65507","0.19351"
"147.30000","29.68000","0.19618"
"147.60000","29.70511","0.19323"
"147.90000","29.73011","0.19520"
"148.20000","29.75516","0.19860"
"148.50000","29.78015","0.19933"
"148.80000","29.80502","0.19894"
"149.10000","29.83013","0.20061"
"149.40000","29.85507","0.20151"
"149.70000","29.88012","0.20185"
"150.00000","29.90505","0.20193"
"150.30000","29.93010","0.20229"
"150.60000","29.95504","0.20245"
"150.90000","29.98009","0.20251"
"151.20000","30.00514","0.20261"
"151.50000","30.03013","0.20335"
"151.80000","30.05512","0.20366"
"152.10000","30.08005","0.20388"
"152.40000","30.10511","0.20490"
"152.70000","30.13004","0.20555"
"153.00000","30.15509","0.20626"
"153.30000","30.18008","0.20720"
"153.60000","30.20502","0.20874"
"153.90000","30.23007","0.20949"
"154.20000","30.25500","0.21065"
"154.50000","30.28011","0.21262"
"154.80000","30.30511","0.21443"
"155.10000","30.33009","0.21494"
"155.40000","30.35503","0.21719"
"155.70000","30.38014","0.21849"
"156.00000","30.40513","0.21971"
"156.30000","30.43006","0.22153"
"156.60000","30.45511","0.22260"
"156.90000","30.48011","0.22286"
"157.20000","30.50510","0.22355"
"157.50000","30.53003","0.22406"
"157.80000","30.55514","0.22453"
"158.10000","30.58007","0.22519"
"158.40000","30.60513","0.22548"
"158.70000","30.63006","0.22724"
"159.00000","30.65505","0.22808"
"159.30000","30.68004","0.03316"
"159.60000","30.70503","0.04725"
"159.90000","30.73009","0.04475"
"160.20000","30.75502","0.04183"
"160.50000","30.78007","0.04341"
"160.80000","30.80506","0.04413"
"161.10000","30.83011","0.04790"
"161.40000","30.85511","0.04124"
"161.70000","30.88010","0.04637"
"162.00000","30.90509","0.04004"
"162.30000","30.93008","0.04985"
"162.60000","30.95508","0.04328"
"162.90000","30.98001","0.04750"
"163.20000","31.00512","0.04323"
"163.50000","31.03005","0.04632"
"163.80000","31.05504","0.04808"
"164.10000","31.08010","0.04562"
"164.40000","31.10509","0.04856"
"164.70000","31.13008","0.04506"
"165.00000","31.15501","0.04830"
"165.30000","31.18012","0.04733"
"165.60000","31.20506","0.04830"
"165.90000","31.23011","0.04887"
"166.20000","31.25504","0.04812"
"166.50000","31.28009","0.04911"
"166.80000","31.30508","0.04824"
"167.10000","31.33001","0.04969"
"167.40000","31.35506","0.04946"
"167.70000","31.38006","0.04962"
"168.00000","31.40511","0.05026"
"168.30000","31.43004","0.05042"
"168.60000","31.45509","0.05089"
"168.90000","31.48009","0.05030"
"169.20000","31.50508","0.05116"
"169.50000","31.53007","0.05074"
"169.80000","31.55506","0.05137"
"170.10000","31.58005","0.05140"
"170.40000","31.60499","0.05160"
"170.70000","31.63010","0.05184"
"171.00000","31.65509","0.05186"
"171.30000","31.68014","0.05239"
"171.60000","31.70513","0.05224"
"171.90000","31.73013","0.05242"
"172.20000","31.75517","0.05246"
"172.50000","31.78005","0.05264"
"172.80000","31.80510","0.05279"
"173.10000","31.82997","0.05287"
"173.40000","31.85514","0.05291"
"173.70000","31.88002","0.05310"
"174.00000","31.90507","0.05315"
"174.30000","31.93006","0.05329"
"174.60000","31.95505","0.05334"
"174.90000","31.98016","0.05345"
"175.20000","32.00510","0.05336"
"175.50000","32.03009","0.05349"
"175.80000","32.05502","0.05355"
"176.10000","32.08013","0.05356"
"176.40000","32.10506","0.05367"
"176.70000","32.13006","0.05377"
"177.00000","32.15511","0.05378"
"177.30000","32.18010","0.05389"
"177.60000","32.20509","0.05393"
"177.90000","32.23003","0.05396"
"178.20000","32.25513","0.05412"
"178.50000","32.28007","0.05412"
"178.80000","32.30512","0.05418"
"179.10000","32.33006","0.05428"
"179.40000","32.35505","0.05454"
"179.70000","32.38010","0.05457"
"180.00000","32.40503","0.05484"
"180.30000","32.43008","0.05502"
"180.60000","32.45501","0.05532"
"180.90000","32.48006","0.05566"
"181.20000","32.50506","0.05587"
"181.50000","32.53017","0.05604"
"181.80000","32.55510","0.05644"
"182.10000","32.58009","0.05665"
"182.40000","32.60514","0.05712"
"182.70000","32.63008","0.05763"
"183.00000","32.65507","0.05817"
"183.30000","32.68000","0.05916"
"183.60000","32.70511","0.05937"
"183.90000","32.73005","0.06005"
"184.20000","32.75510","0.06019"
"184.50000","32.78009","0.06127"
"184.80000","32.80514","0.06255"
"185.10000","32.83014","0.06262"
"185.40000","32.85500","0.06335"
"185.70000","32.88006","0.06359"
"186.00000","32.90505","0.06368"
"186.30000","32.93010","0.06432"
"186.60000","32.95503","0.06523"
"186.90000","32.98008","0.06648"
"187.20000","33.00508","0.06692"
"187.50000","33.03007","0.06751"
"187.80000","33.05512","0.06779"
"188.10000","33.08005","0.06844"
"188.40000","33.10511","0.06786"
"188.70000","33.13004","0.06821"
"189.00000","33.15509","0.06867"
"189.30000","33.18008","0.06914"
"189.60000","33.20507","0.07047"
"189.90000","33.23006","0.07120"
"190.20000","33.25505","0.07200"
"190.50000","33.28011","0.07384"
"190.80000","33.30504","0.07489"
"191.10000","33.33015","0.07564"
"191.40000","33.35509","0.07699"
"191.70000","33.38013","0.07747"
"192.00000","33.40507","0.07814"
"192.30000","33.43012","0.07950"
"192.60000","33.45512","0.08102"
"192.90000","33.48010","0.08146"
"193.20000","33.50510","0.08285"
"193.50000","33.53009","0.08376"
"193.80000","33.55508","0.08445"
"194.10000","33.58001","0.08517"
"194.40000","33.60513","0.08597"
"194.70000","33.63012","0.08659"
"195.00000","33.65511","0.08762"
"195.30000","33.68010","0.08811"
"195.60000","33.70509","0.08886"
"195.90000","33.73009","0.08942"
"196.20000","33.75502","0.09082"
"196.50000","33.78013","0.09155"
"196.80000","33.80506","0.09218"
"197.10000","33.83006","0.09291"
"197.40000","33.85511","0.09424"
"197.70000","33.88010","0.09533"
"198.00000","33.90515","0.09563"
"198.30000","33.93002","0.09652"
"198.60000","33.95507","0.09632"
"198.90000","33.98000","0.09659"
"199.20000","34.00512","0.09622"
"199.50000","34.02999","0.09606"
"199.80000","34.05510","0.09477"
"200.10000","34.08009","0.09268"
"200.40000","34.10508","0.09150"
"200.70000","34.13008","0.09036"
"201.00000","34.15507","0.09076"
"201.30000","34.18012","0.09145"
"201.60000","34.20505","0.09140"
"201.90000","34.23011","0.09108"
"202.20000","34.25504","0.08417"
"202.50000","34.28009","0.08372"
"202.80000","34.30508","0.08265"
"203.10000","34.33007","0.08405"
"203.40000","34.35507","0.08502"
"203.70000","34.38005","0.08511"
"204.00000","34.40511","0.08600"
"204.30000","34.43004","0.08714"
"204.60000","34.45509","0.08814"
"204.90000","34.48002","0.08852"
"205.20000","34.50508","0.09012"
"205.50000","34.53007","0.09084"
"205.80000","34.55506","0.09198"
"206.10000","34.58011","0.09303"
"206.40000","34.60505","0.09373"
"206.70000","34.63004","0.09503"
"207.00000","34.65503","0.09608"
"207.30000","34.68014","0.09649"
"207.60000","34.70507","0.09864"
"207.90000","34.73013","0.09980"
"208.20000","34.75512","0.10140"
"208.50000","34.78005","0.10232"
"208.80000","34.80516","0.10456"
"209.10000","34.83003","0.10634"
"209.40000","34.85509","0.10705"
"209.70000","34.88002","0.10921"
"210.00000","34.90513","0.11024"
"210.30000","34.93006","0.11202"
"210.60000","34.95511","0.11407"
"210.90000","34.98011","0.11562"
"211.20000","35.00504","0.11708"
"211.50000","35.03009","0.11877"
"211.80000","35.05502","0.11965"
"212.10000","35.08007","0.12124"
"212.40000","35.10506","0.12291"
"212.70000","35.13006","0.12382"
"213.00000","35.15505","0.12477"
"213.30000","35.18004","0.12623"
"213.60000","35.20509","0.12816"
"213.90000","35.23008","0.12829"
"214.20000","35.25508","0.12978"
"214.50000","35.28001","0.13077"
"214.80000","35.30512","0.13200"
"215.10000","35.33011","0.13292"
"215.40000","35.35511","0.13354"
"215.70000","35.38010","0.13439"
"216.00000","35.40509","0.13572"
"216.30000","35.43014","0.13599"
"216.60000","35.45507","0.13662"
"216.90000","35.48013","0.13733"
"217.20000","35.50506","0.13792"
"217.50000","35.53011","0.13844"
"217.80000","35.55504","0.13883"
"218.10000","35.58015","0.13931"
"218.40000","35.60508","0.13964"
"218.70000","35.63008","0.13996"
"219.00000","35.65507","0.14031"
"219.30000","35.68000","0.14055"
"219.60000","35.70505","0.14095"
"219.90000","35.72998","0.14117"
"220.20000","35.75510","0.14168"
"220.50000","35.78003","0.14179"
"220.80000","35.80508","0.14215"
"221.10000","35.83007","0.14277"
"221.40000","35.85506","0.14294"
"221.70000","35.88012","0.14347"
"222.00000","35.90505","0.14426"
"222.30000","35.93010","0.14508"
"222.60000","35.95503","0.14530"
"222.90000","35.98009","0.14625"
"223.20000","36.00508","0.14661"
"223.50000","36.03007","0.14715"
"223.80000","36.05506","0.14844"
"224.10000","36.08012","0.14900"
"224.40000","36.10516","0.14953"
"224.70000","36.13004","0.14999"
"225.00000","36.15509","0.15112"
"225.30000","36.18002","0.15180"
"225.60000","36.20513","0.15273"
"225.90000","36.23006","0.15341"
"226.20000","36.25506","0.15449"
"226.50000","36.28005","0.15514"
"226.80000","36.30504","0.15636"
"227.10000","36.33009","0.15650"
"227.40000","36.35509","0.15685"
"227.70000","36.38014","0.15754"
"228.00000","36.40507","0.15858"
"228.30000","36.43012","0.15989"
"228.60000","36.45506","0.16140"
"228.90000","36.48005","0.16198"
"229.20000","36.50515","0.16281"
"229.50000","36.53009","0.16423"
"229.80000","36.55508","0.16546"
"230.10000","36.58001","0.16586"
"230.40000","36.60506","0.16690"
"230.70000","36.63006","0.16807"
"231.00000","36.65511","0.16943"
"231.30000","36.68010","0.17043"
"231.60000","36.70509","0.17124"
"231.90000","36.73008","0.17218"
"232.20000","36.75508","0.17293"
"232.50000","36.78007","0.17361"
"232.80000","36.80506","0.17482"
"233.10000","36.83011","0.17585"
"233.40000","36.85505","0.17633"
"233.70000","36.88010","0.17621"
"234.00000","36.90509","0.17728"
"234.30000","36.93008","0.17792"
"234.60000","36.95507","0.17864"
"234.90000","36.98001","0.17936"
"235.20000","37.00505","0.18094"
"235.50000","37.03005","0.18183"
"235.80000","37.05510","0.18313"
"236.10000","37.08004","0.18367"
"236.40000","37.10515","0.18465"
"236.70000","37.13008","0.18637"
"237.00000","37.15507","0.18660"
"237.30000","37.18012","0.18766"
"237.60000","37.20512","0.18799"
"237.90000","37.23010","0.18890"
"238.20000","37.25504","0.18961"
"238.50000","37.28009","0.19049"
"238.80000","37.30508","0.19128"
"239.10000","37.33001","0.19193"
"239.40000","37.35506","0.19273"
"239.70000","37.38000","0.19334"
"240.00000","37.40505","0.19382"
"240.30000","37.43004","0.19481"
"240.60000","37.45515","0.19660"
"240.90000","37.48003","0.19714"
"241.20000","37.50508","0.19792"
"241.50000","37.53007","0.19823"
"241.80000","37.55512","0.19876"
"242.10000","37.58011","0.19952"
"242.40000","37.60505","0.20006"
"242.70000","37.63010","0.20048"
"243.00000","37.65503","0.20061"
"243.30000","37.68014","0.20117"
"243.60000","37.70507","0.20134"
"243.90000","37.73013","0.20169"
"244.20000","37.75506","0.17127"
"244.50000","37.78011","0.03068"
"244.80000","37.80510","0.02065"
"245.10000","37.83003","0.01264"
"245.40000","37.85503","0.03480"
"245.70000","37.88002","0.02431"
"246.00000","37.90513","0.01498"
"246.30000","37.93006","0.02595"
"246.60000","37.95511","0.01203"
"246.90000","37.98011","0.03040"
"247.20000","38.00510","0.01275"
"247.50000","38.03015","0.02561"
"247.80000","38.05508","0.01545"
"248.10000","38.08007","0.01846"
"248.40000","38.10507","0.02390"
"248.70000","38.13012","0.01346"
"249.00000","38.15505","0.02786"
"249.30000","38.18010","0.01382"
"249.60000","38.20509","0.02380"
"249.90000","38.23008","0.01283"
"250.20000","38.25508","0.02183"
"250.50000","38.28007","0.01405"
"250.80000","38.30512","0.02213"
"251.10000","38.33005","0.01562"
"251.40000","38.35511","0.01771"
"251.70000","38.38010","0.01955"
"252.00000","38.40509","0.01573"
"252.30000","38.43002","0.02436"
"252.60000","38.45501","0.01658"
"252.90000","38.48006","0.02306"
"253.20000","38.50506","0.01460"
"253.50000","38.53011","0.02147"
"253.80000","38.55504","0.01467"
"254.10000","38.58015","0.02008"
"254.40000","38.60509","0.01795"
"254.70000","38.63013","0.01933"
"255.00000","38.65513","0.02048"
"255.30000","38.68006","0.01869"
"255.60000","38.70511","0.02248"
"255.90000","38.73005","0.01840"
"256.20000","38.75504","0.02101"
"256.50000","38.78003","0.01665"
"256.80000","38.80514","0.02045"
"257.10000","38.83007","0.01688"
"257.40000","38.85513","0.02031"
"257.70000","38.88012","0.01930"
"258.00000","38.90511","0.01963"
"258.30000","38.93010","0.02164"
"258.60000","38.95497","0.01960"
"258.90000","38.98009","0.02145"
"259.20000","39.00502","0.01855"
"259.50000","39.03013","0.02051"
"259.80000","39.05506","0.01762"
"260.10000","39.08011","0.02033"
"260.40000","39.10510","0.02066"
"260.70000","39.13004","0.02100"
"261.00000","39.15509","0.02083"
"261.30000","39.18002","0.02110"
"261.60000","39.20507","0.02081"
"261.90000","39.23007","0.02004"
"262.20000","39.25512","0.02066"
"262.50000","39.28005","0.02078"
"262.80000","39.30510","0.02153"
"263.10000","39.33009","0.02080"
"263.40000","39.35508","0.02144"
"263.70000","39.38014","0.02117"
"264.00000","39.40507","0.02126"
"264.30000","39.43018","0.02180"
"264.60000","39.45505","0.02156"
"264.90000","39.48011","0.02218"
"265.20000","39.50510","0.02114"
"265.50000","39.53009","0.02260"
"265.80000","39.55508","0.02209"
"266.10000","39.58007","0.02208"
"266.40000","39.60506","0.02249"
"266.70000","39.63000","0.02190"
"267.00000","39.65511","0.02266"
"267.30000","39.68010","0.02153"
"267.60000","39.70515","0.02364"
"267.90000","39.73009","0.02199"
"268.20000","39.75513","0.02281"
"268.50000","39.78012","0.02188"
"268.80000","39.80512","0.02297"
"269.10000","39.83012","0.02360"
"269.40000","39.85504","0.02253"
"269.70000","39.88009","0.02393"
"270.00000","39.90509","0.02296"
"270.30000","39.93008","0.02360"
"270.60000","39.95507","0.02373"
"270.90000","39.98012","0.02329"
"271.20000","40.00512","0.02382"
"271.50000","40.03005","0.02334"
"271.80000","40.05510","0.02452"
"272.10000","40.08003","0.02377"
"272.40000","40.10508","0.02395"
"272.70000","40.13008","0.02427"
"273.00000","40.15507","0.02460"
"273.30000","40.18006","0.02475"
"273.60000","40.20505","0.02528"
"273.90000","40.23016","0.02514"
"274.20000","40.25510","0.02533"
"274.50000","40.28009","0.02442"
"274.80000","40.30502","0.02560"
"275.10000","40.33007","0.02535"
"275.40000","40.35500","0.02569"
"275.70000","40.38006","0.02557"
"276.00000","40.40511","0.02616"
"276.30000","40.43004","0.02569"
"276.60000","40.45509","0.02571"
"276.90000","40.48008","0.02648"
"277.20000","40.50514","0.02560"
"277.50000","40.53007","0.02644"
"277.80000","40.55506","0.02618"
"278.10000","40.58005","0.02597"
"278.40000","40.60511","0.02650"
"278.70000","40.63010","0.02687"
"279.00000","40.65508","0.02747"
"279.30000","40.68008","0.02785"
"279.60000","40.70501","0.02653"
"279.90000","40.73007","0.02761"
"280.20000","40.75505","0.02664"
"280.50000","40.78011","0.02742"
"280.80000","40.80504","0.02801"
"281.10000","40.83009","0.02812"
"281.40000","40.85508","0.02838"
"281.70000","40.88007","0.02782"
"282.00000","40.90507","0.02819"
"282.30000","40.93006","0.02845"
"282.60000","40.95505","0.02863"
"282.90000","40.98004","0.02922"
"283.20000","41.00509","0.02841"
"283.50000","41.03015","0.02896"
"283.80000","41.05508","0.02983"
"284.10000","41.08013","0.02905"
"284.40000","41.10506","0.02917"
"284.70000","41.13012","0.02966"
"285.00000","41.15505","0.02994"
"285.30000","41.18016","0.03002"
"285.60000","41.20503","0.02961"
"285.90000","41.23008","0.03081"
"286.20000","41.25508","0.03029"
"286.50000","41.28007","0.03023"
"286.80000","41.30512","0.03029"
"287.10000","41.33011","0.03097"
"287.40000","41.35516","0.02994"
"287.70000","41.38004","0.03115"
"288.00000","41.40515","0.03089"
"288.30000","41.43002","0.03060"
"288.60000","41.45507","0.03161"
"288.90000","41.48006","0.03110"
"289.20000","41.50506","0.03082"
"289.50000","41.53011","0.03156"
"289.80000","41.55510","0.03194"
"290.10000","41.58009","0.03167"
"290.40000","41.60503","0.03205"
"290.70000","41.63014","0.03201"
"291.00000","41.65507","0.03180"
"291.30000","41.68006","0.03208"
"291.60000","41.70511","0.03269"
"291.90000","41.73005","0.03320"
"292.20000","41.75510","0.03295"
"292.50000","41.78003","0.03305"
"292.80000","41.80508","0.03269"
"293.10000","41.83001","0.03358"
"293.40000","41.85513","0.03329"
"293.70000","41.88005","0.03301"
"294.00000","41.90511","0.03289"
"294.30000","41.93010","0.03296"
"294.60000","41.95509","0.03284"
"294.90000","41.98008","0.03367"
"295.20000","42.00502","0.03397"
"295.50000","42.03007","0.03373"
"295.80000","42.05500","0.03376"
"296.10000","42.08011","0.03353"
"296.40000","42.10504","0.03461"
"296.70000","42.13009","0.03438"
"297.00000","42.15509","0.03443"
"297.30000","42.18002","0.03423"
"297.60000","42.20507","0.03477"
"297.90000","42.23006","0.03512"
"298.20000","42.25506","0.03466"
"298.50000","42.28005","0.03503"
"298.80000","42.30510","0.03581"
"299.10000","42.33003","0.03491"
"299.40000","42.35503","0.03535"
"299.70000","42.38008","0.03608"
"300.00000","42.40507","0.03634"
"300.30000","42.43012","0.03622"
"300.60000","42.45505","0.03686"
"300.90000","42.48010","0.03696"
"301.20000","42.50504","0.03676"
"301.50000","42.53009","0.03747"
"301.80000","42.55508","0.03747"
"302.10000","42.58001","0.03752"
"302.40000","42.60513","0.03757"
"302.70000","42.63006","0.03819"
"303.00000","42.65511","0.03845"
"303.30000","42.68004","0.03793"
"303.60000","42.70515","0.03852"
"303.90000","42.73009","0.03855"
"304.20000","42.75514","0.03874"
"304.50000","42.78006","0.03929"
"304.80000","42.80506","0.03947"
"305.10000","42.83011","0.03917"
"305.40000","42.85505","0.03949"
"305.70000","42.88003","0.03979"
"306.00000","42.90503","0.03989"
"306.30000","42.93008","0.03989"
"306.60000","42.95507","0.04029"
"306.90000","42.98006","0.04023"
"307.20000","43.00512","0.04071"
"307.50000","43.03011","0.04052"
"307.80000","43.05510","0.04048"
"308.10000","43.08003","0.04114"
"308.40000","43.10508","0.04150"
"308.70000","43.13007","0.04091"
"309.00000","43.15512","0.04191"
"309.30000","43.18007","0.04152"
"309.60000","43.20511","0.04203"
"309.90000","43.23010","0.04187"
"310.20000","43.25509","0.04232"
"310.50000","43.28009","0.04208"
"310.80000","43.30502","0.04269"
"311.10000","43.33007","0.04286"
"311.40000","43.35501","0.04322"
"311.70000","43.38006","0.04328"
"312.00000","43.40499","0.04334"
"312.30000","43.43004","0.04378"
"312.60000","43.45509","0.04406"
"312.90000","43.48003","0.04427"
"313.20000","43.50508","0.04444"
"313.50000","43.53007","0.04467"
"313.80000","43.55512","0.04465"
"314.10000","43.58005","0.04530"
"314.40000","43.60510","0.04544"
"314.70000","43.63004","0.04559"
"315.00000","43.65509","0.04579"
"315.30000","43.68008","0.04542"
"315.60000","43.70507","0.04633"
"315.90000","43.73006","0.04631"
"316.20000","43.75506","0.04628"
"316.50000","43.78011","0.04673"
"316.80000","43.80504","0.04649"
"317.10000","43.83009","0.04690"
"317.40000","43.85509","0.04680"
"317.70000","43.88008","0.04689"
"318.00000","43.90506","0.04727"
"318.30000","43.93006","0.04732"
"318.60000","43.95511","0.04726"
"318.90000","43.98005","0.04739"
"319.20000","44.00510","0.04729"
"319.50000","44.03003","0.04788"
"319.80000","44.05514","0.04782"
"320.10000","44.08014","0.04822"
"320.40000","44.10513","0.04820"
"320.70000","44.13012","0.04812"
"321.00000","44.15505","0.04872"
"321.30000","44.18010","0.04857"
"321.60000","44.20497","0.04881"
"321.90000","44.23014","0.04878"
"322.20000","44.25507","0.04926"
"322.50000","44.28013","0.04869"
"322.80000","44.30506","0.04914"
"323.10000","44.33011","0.04939"
"323.40000","44.35510","0.04965"
"323.70000","44.38010","0.04974"
"324.00000","44.40509","0.05020"
"324.30000","44.43002","0.05019"
"324.60000","44.45507","0.05033"
"324.90000","44.48001","0.05023"
"325.20000","44.50505","0.05054"
"325.50000","44.53011","0.05055"
"325.80000","44.55504","0.05089"
"326.10000","44.58009","0.05067"
"326.40000","44.60502","0.05091"
"326.70000","44.63008","0.05089"
"327.00000","44.65507","0.05107"
"327.30000","44.68006","0.05127"
"327.60000","44.70505","0.05120"
"327.90000","44.73011","0.05126"
"328.20000","44.75510","0.05144"
"328.50000","44.78009","0.05183"
"328.80000","44.80508","0.05176"
"329.10000","44.83007","0.05169"
"329.40000","44.85513","0.05214"
"329.70000","44.87999","0.05206"
"330.00000","44.90511","0.05200"
"330.30000","44.93010","0.05195"
"330.60000","44.95509","0.05200"
"330.90000","44.98009","0.05200"
"331.20000","45.00501","0.05211"
"331.50000","45.03001","0.05184"
"331.80000","45.05500","0.05169"
"332.10000","45.08006","0.05166"
"332.40000","45.10505","0.05157"
"332.70000","45.13010","0.05168"
"333.00000","45.15509","0.05160"
"333.30000","45.18008","0.05146"
"333.60000","45.20507","0.05164"
"333.90000","45.23006","0.05145"
"334.20000","45.25512","0.05168"
"334.50000","45.28005","0.05176"
"334.80000","45.30510","0.05157"
"335.10000","45.33009","0.05131"
"335.40000","45.35508","0.05013"
"335.70000","45.38007","0.05086"
"336.00000","45.40507","0.04981"
"336.30000","45.43012","0.04951"
"336.60000","45.45506","0.05041"
"336.90000","45.48010","0.04947"
"337.20000","45.50498","0.04999"
"337.50000","45.53009","0.05002"
"337.80000","45.55508","0.05004"
"338.10000","45.58014","0.05041"
"338.40000","45.60501","0.05053"
"338.70000","45.63006","0.05057"
"339.00000","45.65511","0.05082"
"339.30000","45.68004","0.05113"
"339.60000","45.70509","0.05121"
"339.90000","45.73008","0.05114"
"340.20000","45.75514","0.05120"
"340.50000","45.78007","0.05152"
"340.80000","45.80512","0.05146"
"341.10000","45.83011","0.05144"
"341.40000","45.85511","0.05169"
"341.70000","45.88010","0.05188"
"342.00000","45.90503","0.05189"
"342.30000","45.93002","0.05215"
"342.60000","45.95501","0.05202"
"342.90000","45.98006","0.05218"
"343.20000","46.00506","0.05206"
"343.50000","46.03011","0.05242"
"343.80000","46.05510","0.05245"
"344.10000","46.08009","0.05245"
"344.40000","46.10515","0.05267"
"344.70000","46.13001","0.05277"
"345.00000","46.15506","0.05283"
"345.30000","46.18006","0.05298"
"345.60000","46.20512","0.05285"
"345.90000","46.23004","0.05299"
"346.20000","46.25510","0.05306"
"346.50000","46.28009","0.05317"
"346.80000","46.30508","0.05320"
"347.10000","46.33007","0.05328"
"347.40000","46.35506","0.05336"
"347.70000","46.38012","0.05349"
"348.00000","46.40499","0.05347"
"348.30000","46.43010","0.05353"
"348.60000","46.45509","0.05366"
"348.90000","46.48008","0.05366"
"349.20000","46.50507","0.05375"
"349.50000","46.53007","0.05373"
"349.80000","46.55512","0.05382"
"350.10000","46.58006","0.05381"
"350.40000","46.60510","0.05388"
"350.70000","46.63010","0.05391"
"351.00000","46.65509","0.05393"
"351.30000","46.68008","0.05404"
"351.60000","46.70507","0.05410"
"351.90000","46.73006","0.05419"
"352.20000","46.75506","0.05421"
"352.50000","46.78005","0.05430"
"352.80000","46.80504","0.05439"
"353.10000","46.83010","0.05456"
"353.40000","46.85508","0.05467"
"353.70000","46.88019","0.05469"
"354.00000","46.90507","0.05496"
"354.30000","46.93012","0.05483"
"354.60000","46.95511","0.05505"
"354.90000","46.98010","0.05540"
"355.20000","47.00510","0.05552"
"355.50000","47.03003","0.05593"
"355.80000","47.05508","0.05583"
"356.10000","47.08007","0.05599"
"356.40000","47.10512","0.05619"
"356.70000","47.13012","0.05642"
"357.00000","47.15511","0.05680"
"357.30000","47.18010","0.05705"
"357.60000","47.20504","0.05747"
"357.90000","47.23009","0.05774"
"358.20000","47.25508","0.05808"
"358.50000","47.28012","0.05843"
"358.80000","47.30506","0.05884"
"359.10000","47.33011","0.05915"
"359.40000","47.35510","0.05932"
"359.70000","47.38010","0.05966"
"360.00000","47.40515","0.06028"
"360.30000","47.43008","0.06020"
"360.60000","47.45513","0.06098"
"360.90000","47.48006","0.06072"
"361.20000","47.50505","0.06088"
"361.50000","47.53005","0.06216"
"361.80000","47.55510","0.06178"
"362.10000","47.58009","0.06169"
"362.40000","47.60502","0.06207"
"362.70000","47.63014","0.06199"
"363.00000","47.65507","0.06151"
"363.30000","47.68012","0.06226"
"363.60000","47.70506","0.06200"
"363.90000","47.73010","0.06305"
"364.20000","47.75504","0.06386"
"364.50000","47.78009","0.06402"
"364.80000","47.80514","0.06472"
"365.10000","47.83001","0.06488"
"365.40000","47.85506","0.06574"
"365.70000","47.88006","0.06585"
"366.00000","47.90505","0.06735"
"366.30000","47.93004","0.06771"
"366.60000","47.95515","0.06747"
"366.90000","47.98014","0.06844"
"367.20000","48.00508","0.06939"
"367.50000","48.03007","0.06930"
"367.80000","48.05506","0.07137"
"368.10000","48.08011","0.07125"
"368.40000","48.10505","0.07265"
"368.70000","48.13010","0.07308"
"369.00000","48.15503","0.07392"
"369.30000","48.18008","0.07358"
"369.60000","48.20513","0.07492"
"369.90000","48.23012","0.07426"
"370.20000","48.25518","0.07491"
"370.50000","48.28004","0.07466"
"370.80000","48.30510","0.07457"
"371.10000","48.33004","0.07484"
"371.40000","48.35514","0.07633"
"371.70000","48.38001","0.07588"
"372.00000","48.40507","0.07703"
"372.30000","48.43006","0.07730"
"372.60000","48.45505","0.07805"
"372.90000","48.48011","0.07886"
"373.20000","48.50510","0.07924"
"373.50000","48.53009","0.08059"
"373.80000","48.55502","0.08144"
"374.10000","48.58013","0.08188"
"374.40000","48.60506","0.08275"
"374.70000","48.63012","0.08369"
"375.00000","48.65511","0.08365"
"375.30000","48.68010","0.08405"
"375.60000","48.70509","0.08443"
"375.90000","48.73008","0.08508"
"376.20000","48.75514","0.08510"
"376.50000","48.78012","0.08580"
"376.80000","48.80512","0.08633"
"377.10000","48.83006","0.08657"
"377.40000","48.85510","0.08736"
"377.70000","48.88009","0.08848"
"378.00000","48.90503","0.08903"
"378.30000","48.93008","0.09001"
"378.60000","48.95501","0.09026"
"378.90000","48.98006","0.09106"
"379.20000","49.00500","0.09110"
"379.50000","49.03017","0.09252"
"379.80000","49.05510","0.09289"
"380.10000","49.08015","0.09363"
"380.40000","49.10514","0.09444"
"380.70000","49.13008","0.09490"
"381.00000","49.15513","0.09674"
"381.30000","49.18006","0.09701"
"381.60000","49.20511","0.09812"
"381.90000","49.22999","0.09913"
"382.20000","49.25510","0.10164"
"382.50000","49.28009","0.10174"
"382.80000","49.30508","0.10266"
"383.10000","49.33007","0.10578"
"383.40000","49.35507","0.10581"
"383.70000","49.38006","0.10821"
"384.00000","49.40504","0.11057"
"384.30000","49.43004","0.11052"
"384.60000","49.45504","0.11181"
"384.90000","49.48008","0.11329"
"385.20000","49.50508","0.11448"
"385.50000","49.53007","0.02287"
"385.80000","49.55512","0.01321"
"386.10000","49.58005","0.01212"
"386.40000","49.60504","0.01118"
"386.70000","49.62997","0.01013"
"387.00000","49.65509","0.01200"
"387.30000","49.68008","0.01190"
"387.60000","49.70507","0.01185"
"387.90000","49.73006","0.01093"
"388.20000","49.75505","0.01124"
"388.50000","49.78011","0.01169"
"388.80000","49.80510","0.01191"
"389.10000","49.83009","0.01149"
"389.40000","49.85502","0.01007"
"389.70000","49.88013","0.01222"
"390.00000","49.90507","0.01152"
"390.30000","49.93012","0.01130"
"390.60000","49.95506","0.00997"
"390.90000","49.98004","0.01200"
"391.20000","50.00509","0.01161"
"391.50000","50.02997","0.01055"
"391.80000","50.05508","0.01021"
"392.10000","50.08001","0.01108"
"392.40000","50.10512","0.01186"
"392.70000","50.13006","0.01100"
"393.00000","50.15511","0.01151"
"393.30000","50.18010","0.01037"
"393.60000","50.20509","0.01173"
"393.90000","50.23014","0.01148"
"394.20000","50.25508","0.01135"
"394.50000","50.28013","0.01157"
"394.80000","50.30506","0.01091"
"395.10000","50.33005","0.01190"
"395.40000","50.35505","0.01131"
"395.70000","50.38010","0.01177"
"396.00000","50.40515","0.00980"
"396.30000","50.43008","0.01119"
"396.60000","50.45513","0.01158"
"396.90000","50.48006","0.01164"
"397.20000","50.50512","0.01029"
"397.50000","50.52999","0.01091"
"397.80000","50.55510","0.01169"
"398.10000","50.58009","0.01078"
"398.40000","50.60508","0.01056"
"398.70000","50.63008","0.01119"
"399.00000","50.65507","0.01182"
"399.30000","50.68012","0.01152"
"399.60000","50.70505","0.01132"
"399.90000","50.73011","0.01081"
"400.20000","50.75510","0.01101"
"400.50000","50.78009","0.01283"
"400.80000","50.80502","0.01140"
"401.10000","50.83007","0.01087"
"401.40000","50.85506","0.01078"
"401.70000","50.88005","0.01110"
"402.00000","50.90511","0.01224"
"402.30000","50.93004","0.01060"
"402.60000","50.95509","0.01075"
"402.90000","50.98008","0.01163"
"403.20000","51.00507","0.01185"
"403.50000","51.03007","0.01101"
"403.80000","51.05506","0.01142"
"404.10000","51.08012","0.00993"
"404.40000","51.10504","0.01198"
"404.70000","51.13009","0.01116"
"405.00000","51.15497","0.01179"
"405.30000","51.18014","0.01094"
"405.60000","51.20501","0.01143"
"405.90000","51.23006","0.01191"
"406.20000","51.25512","0.01205"
"406.50000","51.28011","0.01044"
"406.80000","51.30516","0.01075"
"407.10000","51.33003","0.01255"
"407.40000","51.35508","0.01176"
"407.70000","51.38002","0.01155"
"408.00000","51.40513","0.01031"
"408.30000","51.43000","0.01093"
"408.60000","51.45511","0.01187"
"408.90000","51.48005","0.01146"
"409.20000","51.50510","0.01028"
"409.50000","51.53015","0.01080"
"409.80000","51.55508","0.01177"
"410.10000","51.58013","0.01146"
"410.40000","51.60506","0.01122"
"410.70000","51.63012","0.01039"
"411.00000","51.65505","0.01140"
"411.30000","51.68004","0.01106"
"411.60000","51.70509","0.01042"
"411.90000","51.73002","0.00991"
"412.20000","51.75508","0.01108"
"412.50000","51.78007","0.01127"
"412.80000","51.80511","0.01161"
"413.10000","51.83011","0.01112"
"413.40000","51.85504","0.01080"
"413.70000","51.88004","0.01145"
"414.00000","51.90508","0.01149"
"414.30000","51.93008","0.01132"
"414.60000","51.95507","0.01009"
"414.90000","51.98013","0.01022"
"415.20000","52.00505","0.01119"
"415.50000","52.03011","0.01182"
"415.80000","52.05504","0.01099"
"416.10000","52.08015","0.01092"
"416.40000","52.10508","0.01113"
"416.70000","52.13007","0.01210"
"417.00000","52.15507","0.01102"
"417.30000","52.18006","0.01095"
"417.60000","52.20505","0.01147"
"417.90000","52.22998","0.01095"
"418.20000","52.25509","0.01145"
"418.50000","52.28003","0.01073"
"418.80000","52.30508","0.01139"
"419.10000","52.33007","0.01107"
"419.40000","52.35512","0.01206"
"419.70000","52.38017","0.01104"
"420.00000","52.40504","0.01066"
"420.30000","52.43010","0.01115"
"420.60000","52.45503","0.01173"
"420.90000","52.48008","0.01155"
"421.20000","52.50502","0.01083"
"421.50000","52.53013","0.01085"
"421.80000","52.55506","0.01194"
"422.10000","52.58005","0.01137"
"422.40000","52.60510","0.01198"
"422.70000","52.63010","0.01042"
"423.00000","52.65509","0.01183"
"423.30000","52.68002","0.01215"
"423.60000","52.70513","0.01144"
"423.90000","52.73006","0.01102"
"424.20000","52.75506","0.01089"
"424.50000","52.78005","0.01106"
"424.80000","52.80504","0.01142"
"425.10000","52.83009","0.01035"
"425.40000","52.85502","0.01068"
"425.70000","52.88014","0.01198"
"426.00000","52.90507","0.01199"
"426.30000","52.93011","0.01093"
"426.60000","52.95506","0.01052"
"426.90000","52.98004","0.01175"
"427.20000","53.00510","0.01152"
"427.50000","53.03003","0.01125"
"427.80000","53.05508","0.01134"
"428.10000","53.08007","0.01016"
"428.40000","53.10506","0.01183"
"428.70000","53.13000","0.01083"
"429.00000","53.15511","0.01172"
"429.30000","53.18010","0.01037"
"429.60000","53.20509","0.01159"
"429.90000","53.23014","0.01207"
"430.20000","53.25507","0.01098"
"430.50000","53.28012","0.01056"
"430.80000","53.30500","0.01133"
"431.10000","53.33005","0.01104"
"431.40000","53.35498","0.01157"
"431.70000","53.38009","0.01163"
"432.00000","53.40509","0.01124"
"432.30000","53.43008","0.01128"
"432.60000","53.45513","0.01142"
"432.90000","53.48001","0.01075"
"433.20000","53.50512","0.01046"
"433.50000","53.53011","0.01066"
"433.80000","53.55510","0.01170"
"434.10000","53.58003","0.01118"
"434.40000","53.60514","0.01026"
"434.70000","53.63008","0.01038"
"435.00000","53.65507","0.01142"
"435.30000","53.68006","0.01140"
"435.60000","53.70505","0.01033"
"435.90000","53.73010","0.01020"
"436.20000","53.75504","0.01154"
"436.50000","53.78015","0.01123"
"436.80000","53.80508","0.01050"
"437.10000","53.83007","0.01050"
"437.40000","53.85506","0.01118"
"437.70000","53.87999","0.01136"
"438.00000","53.90511","0.01151"
"438.30000","53.93004","0.01029"
"438.60000","53.95509","0.01017"
"438.90000","53.98002","0.01104"
"439.20000","54.00508","0.01121"
"439.50000","54.03006","0.01111"
"439.80000","54.05512","0.01013"
"440.10000","54.08011","0.01065"
"440.40000","54.10511","0.01144"
"440.70000","54.13016","0.01120"
"441.00000","54.15509","0.01081"
"441.30000","54.18008","0.01121"
"441.60000","54.20502","0.01072"
"441.90000","54.23013","0.01063"
"442.20000","54.25505","0.01075"
"442.50000","54.28011","0.01077"
"442.80000","54.30510","0.01037"
"443.10000","54.33009","0.01142"
"443.40000","54.35514","0.01089"
"443.61800","54.37326","0.01142"