File: Force_trajectories/161114/Specimen_RawData_9.csv
End date,"11/14/2016"
Specimen label,"20BT57"
Maximum Load,"0.48450",N

Time,Extension,Load
(s),(mm),(N)
"0.00000","-2.14704","-0.02490"
"0.26400","-2.12594","-0.02220"
"0.52800","-2.10280","-0.02033"
"0.79200","-2.08080","-0.01890"
"1.05600","-2.05891","-0.01672"
"1.32000","-2.03679","-0.01612"
"1.58400","-2.01485","-0.01488"
"1.84800","-1.99279","-0.01397"
"2.11200","-1.97084","-0.01400"
"2.37600","-1.94884","-0.01325"
"2.64000","-1.92684","-0.01270"
"2.90400","-1.90484","-0.01233"
"3.16800","-1.88283","-0.01217"
"3.43200","-1.86083","-0.01097"
"3.69600","-1.83889","-0.01101"
"3.96000","-1.81682","-0.01120"
"4.22400","-1.79488","-0.01090"
"4.48800","-1.77282","-0.01061"
"4.75200","-1.75088","-0.01020"
"5.01600","-1.72881","-0.01056"
"5.28000","-1.70687","-0.01005"
"5.54400","-1.68487","-0.00978"
"5.80800","-1.66287","-0.00993"
"6.07200","-1.64080","-0.01013"
"6.33600","-1.61886","-0.00950"
"6.60000","-1.59680","-0.00960"
"6.86400","-1.57486","-0.00949"
"7.12800","-1.55285","-0.00937"
"7.39200","-1.53085","-0.00947"
"7.65600","-1.50879","-0.00934"
"7.92000","-1.48685","-0.00912"
"8.18400","-1.46484","-0.00899"
"8.44800","-1.44284","-0.00911"
"8.71200","-1.42084","-0.00890"
"8.97600","-1.39884","-0.00909"
"9.24000","-1.37683","-0.00877"
"9.50400","-1.35483","-0.00843"
"9.76800","-1.33289","-0.00884"
"10.03200","-1.31083","-0.00829"
"10.29600","-1.28888","-0.00876"
"10.56000","-1.26682","-0.00835"
"10.82400","-1.24488","-0.00828"
"11.08800","-1.22282","-0.00811"
"11.35200","-1.20087","-0.00809"
"11.61600","-1.17881","-0.00820"
"11.88000","-1.15687","-0.00800"
"12.14400","-1.13487","-0.00766"
"12.40800","-1.11286","-0.00787"
"12.67200","-1.09080","-0.00799"
"12.93600","-1.06886","-0.00749"
"13.20000","-1.04680","-0.00730"
"13.46400","-1.02485","-0.00742"
"13.72800","-1.00285","-0.00682"
"13.99200","-0.98091","-0.00719"
"14.25600","-0.95884","-0.00731"
"14.52000","-0.93684","-0.00710"
"14.78400","-0.91478","-0.00691"
"15.04800","-0.89290","-0.00717"
"15.31200","-0.87083","-0.00675"
"15.57600","-0.84889","-0.00643"
"15.84000","-0.82683","-0.00702"
"16.10400","-0.80489","-0.00690"
"16.36800","-0.78282","-0.00634"
"16.63200","-0.76088","-0.00672"
"16.89600","-0.73882","-0.00640"
"17.16000","-0.71688","-0.00631"
"17.42400","-0.69487","-0.00637"
"17.68800","-0.67293","-0.00627"
"17.95200","-0.65081","-0.00647"
"18.21600","-0.62887","-0.00611"
"18.48000","-0.60680","-0.00584"
"18.74400","-0.58486","-0.00595"
"19.00800","-0.56286","-0.00597"
"19.27200","-0.54086","-0.00544"
"19.53600","-0.51885","-0.00564"
"19.80000","-0.49691","-0.00544"
"20.06400","-0.47479","-0.00559"
"20.32800","-0.45285","-0.00550"
"20.59200","-0.43084","-0.00499"
"20.85600","-0.40884","-0.00517"
"21.12000","-0.38684","-0.00501"
"21.38400","-0.36478","-0.00538"
"21.64800","-0.34277","-0.00544"
"21.91200","-0.32083","-0.00449"
"22.17600","-0.29883","-0.00508"
"22.44000","-0.27689","-0.00476"
"22.70400","-0.25482","-0.00398"
"22.96800","-0.23282","-0.00474"
"23.23200","-0.21082","-0.00462"
"23.49600","-0.18882","-0.00447"
"23.76000","-0.16681","-0.00396"
"24.02400","-0.14481","-0.00393"
"24.28800","-0.12287","-0.00458"
"24.55200","-0.10081","-0.00436"
"24.81600","-0.07880","-0.00438"
"25.08000","-0.05680","-0.00359"
"25.34400","-0.03486","-0.00359"
"25.60800","-0.01285","-0.00362"
"25.87200","0.00909","-0.00419"
"26.13600","0.03115","-0.00358"
"26.40000","0.05315","-0.00410"
"26.66400","0.07522","-0.00382"
"26.92800","0.09710","-0.00364"
"27.19200","0.11916","-0.00359"
"27.45600","0.14116","-0.00285"
"27.72000","0.16323","-0.00344"
"27.98400","0.18517","-0.00278"
"28.24800","0.20723","-0.00277"
"28.51200","0.22911","-0.00313"
"28.77600","0.25118","-0.00322"
"29.04000","0.27306","-0.00266"
"29.30400","0.29512","-0.00272"
"29.56800","0.31712","-0.00282"
"29.83200","0.33925","-0.00239"
"30.09600","0.36113","-0.00270"
"30.36000","0.38313","-0.00256"
"30.62400","0.40513","-0.00185"
"30.88800","0.42714","-0.00248"
"31.15200","0.44908","-0.00191"
"31.41600","0.47114","-0.00218"
"31.68000","0.49308","-0.00201"
"31.94400","0.51515","-0.00199"
"32.20800","0.53709","-0.00160"
"32.47200","0.55915","-0.00198"
"32.73600","0.58115","-0.00197"
"33.00000","0.60322","-0.00164"
"33.26400","0.62516","-0.00208"
"33.52800","0.64716","-0.00170"
"33.79200","0.66910","-0.00035"
"34.05600","0.69117","-0.00066"
"34.32000","0.71317","-0.00055"
"34.58400","0.73523","-0.00091"
"34.84800","0.75717","-0.00028"
"35.11200","0.77912","-0.00047"
"35.37600","0.80112","-0.00019"
"35.64000","0.82312","-0.00006"
"35.90400","0.84513","-0.00029"
"36.16800","0.86713","-0.00047"
"36.43200","0.88919","-0.00015"
"36.69600","0.91113","-0.00012"
"36.96000","0.93314","0.00005"
"37.22400","0.95514","0.00014"
"37.48800","0.97714","-0.00029"
"37.75200","0.99914","0.00011"
"38.01600","1.02121","0.00031"
"38.28000","1.04315","0.00048"
"38.54400","1.06515","0.00109"
"38.80800","1.08715","0.00072"
"39.07200","1.10916","0.00159"
"39.33600","1.13110","0.00150"
"39.60000","1.15316","0.00088"
"39.86400","1.17516","0.00144"
"40.12800","1.19717","0.00185"
"40.39200","1.21911","0.00211"
"40.65600","1.24117","0.00217"
"40.92000","1.26317","0.00190"
"41.18400","1.28518","0.00158"
"41.44800","1.30718","0.00238"
"41.71200","1.32918","0.00186"
"41.97600","1.35106","0.00190"
"42.24000","1.37319","0.00251"
"42.50400","1.39513","0.00313"
"42.76800","1.41719","0.00301"
"43.03200","1.43913","0.00405"
"43.29600","1.46114","0.00280"
"43.56000","1.48308","0.00372"
"43.82400","1.50520","0.00410"
"44.08800","1.52708","0.00340"
"44.35200","1.54915","0.00387"
"44.61600","1.57115","0.00410"
"44.88000","1.59315","0.00476"
"45.14400","1.61509","0.00446"
"45.40800","1.63716","0.00508"
"45.67200","1.65910","0.00550"
"45.93600","1.68116","0.00491"
"46.20000","1.70316","0.00534"
"46.46400","1.72517","0.00582"
"46.72800","1.74717","0.00597"
"46.99200","1.76917","0.00712"
"47.25600","1.79117","0.00700"
"47.52000","1.81324","0.00650"
"47.78400","1.83512","0.00651"
"48.04800","1.85718","0.00724"
"48.31200","1.87913","0.00692"
"48.57600","1.90113","0.00657"
"48.84000","1.92313","0.00720"
"49.10400","1.94519","0.00728"
"49.36800","1.96720","0.00787"
"49.63200","1.98920","0.00763"
"49.89600","2.01114","0.00816"
"50.16000","2.03314","0.00841"
"50.42400","2.05515","0.00801"
"50.68800","2.07721","0.00885"
"50.95200","2.09921","0.00840"
"51.21600","2.12121","0.01000"
"51.48000","2.14316","0.00913"
"51.74400","2.16516","0.01068"
"52.00800","2.18716","0.01010"
"52.27200","2.20916","0.01072"
"52.53600","2.23117","0.01047"
"52.80000","2.25317","0.01165"
"53.06400","2.27523","0.01113"
"53.32800","2.29711","0.01140"
"53.59200","2.31918","0.01125"
"53.85600","2.34112","0.01162"
"54.12000","2.36318","0.01199"
"54.38400","2.38512","0.01293"
"54.64800","2.40719","0.01199"
"54.91200","2.42907","0.01213"
"55.17600","2.45113","0.01219"
"55.44000","2.47313","0.01284"
"55.70400","2.49520","0.01375"
"55.96800","2.51714","0.01336"
"56.23200","2.53920","0.01314"
"56.49600","2.56108","0.01331"
"56.76000","2.58315","0.01409"
"57.02400","2.60509","0.01489"
"57.28800","2.62715","0.01440"
"57.55200","2.64909","0.01469"
"57.81600","2.67122","0.01453"
"58.08000","2.69310","0.01430"
"58.34400","2.71516","0.01478"
"58.60800","2.73710","0.01555"
"58.87200","2.75917","0.01496"
"59.13600","2.78111","0.01505"
"59.40000","2.80317","0.01548"
"59.66400","2.82512","0.01653"
"59.92800","2.84718","0.01590"
"60.19200","2.86918","0.01615"
"60.45600","2.89118","0.01648"
"60.72000","2.91319","0.01615"
"60.98400","2.93519","0.01610"
"61.24800","2.95713","0.01656"
"61.51200","2.97919","0.01695"
"61.77600","3.00114","0.01728"
"62.04000","3.02320","0.01682"
"62.30400","3.04514","0.01808"
"62.56800","3.06720","0.01778"
"62.83200","3.08915","0.01819"
"63.09600","3.11115","0.01791"
"63.36000","3.13315","0.01817"
"63.62400","3.15521","0.01827"
"63.88800","3.17716","0.01763"
"64.15200","3.19916","0.01796"
"64.41600","3.22122","0.01926"
"64.68000","3.24316","0.01908"
"64.94400","3.26511","0.01924"
"65.20800","3.28717","0.01943"
"65.47200","3.30911","0.01994"
"65.73600","3.33117","0.01981"
"66.00000","3.35318","0.01955"
"66.26400","3.37518","0.01995"
"66.52800","3.39718","0.01954"
"66.79200","3.41918","0.02033"
"67.05600","3.44119","0.02049"
"67.32000","3.46313","0.02041"
"67.58400","3.48513","0.02012"
"67.84800","3.50713","0.02040"
"68.11200","3.52914","0.02037"
"68.37600","3.55108","0.02152"
"68.64000","3.57320","0.02108"
"68.90400","3.59514","0.02148"
"69.16800","3.61721","0.02133"
"69.43200","3.63915","0.02159"
"69.69600","3.66115","0.02183"
"69.96000","3.68310","0.02184"
"70.22400","3.70516","0.02244"
"70.48800","3.72716","0.02102"
"70.75200","3.74922","0.02194"
"71.01600","3.77116","0.02193"
"71.28000","3.79317","0.02236"
"71.54400","3.81505","0.02224"
"71.80800","3.83717","0.02263"
"72.07200","3.85912","0.02277"
"72.33600","3.88118","0.02243"
"72.60000","3.90312","0.02297"
"72.86400","3.92518","0.02112"
"73.12800","3.94713","0.02157"
"73.39200","3.96919","0.02173"
"73.65600","3.99113","0.02202"
"73.92000","4.01319","0.02385"
"74.18400","4.03514","0.02338"
"74.44800","4.05720","0.02393"
"74.71200","4.07914","0.02374"
"74.97600","4.10120","0.02375"
"75.24000","4.12315","0.02448"
"75.50400","4.14521","0.02392"
"75.76800","4.16715","0.02499"
"76.03200","4.18921","0.02416"
"76.29600","4.21116","0.02536"
"76.56000","4.23316","0.02428"
"76.82400","4.25516","0.02486"
"77.08800","4.27722","0.02534"
"77.35200","4.29917","0.02544"
"77.61600","4.32123","0.02492"
"77.88000","4.34317","0.02653"
"78.14400","4.36511","0.02640"
"78.40800","4.38712","0.02556"
"78.67200","4.40918","0.02618"
"78.93600","4.43118","0.02647"
"79.20000","4.45312","0.02562"
"79.46400","4.47519","0.02577"
"79.72800","4.49713","0.02696"
"79.99200","4.51913","0.02676"
"80.25600","4.54113","0.02674"
"80.52000","4.56320","0.02730"
"80.78400","4.58514","0.02656"
"81.04800","4.60720","0.02803"
"81.31200","4.62915","0.02794"
"81.57600","4.65115","0.02839"
"81.84000","4.67315","0.02792"
"82.10400","4.69515","0.02866"
"82.36800","4.71715","0.02915"
"82.63200","4.73916","0.02854"
"82.89600","4.76110","0.02955"
"83.16000","4.78322","0.02922"
"83.42400","4.80511","0.02932"
"83.68800","4.82717","0.02958"
"83.95200","4.84917","0.02991"
"84.21600","4.87123","0.03081"
"84.48000","4.89312","0.03083"
"84.74400","4.91518","0.03088"
"85.00800","4.93706","0.03090"
"85.27200","4.95918","0.03225"
"85.53600","4.98113","0.03120"
"85.80000","5.00319","0.03235"
"86.06400","5.02513","0.03317"
"86.32800","5.04713","0.03298"
"86.59200","5.06908","0.03417"
"86.85600","5.09120","0.03400"
"87.12000","5.11308","0.03406"
"87.38400","5.13520","0.03479"
"87.64800","5.15715","0.03490"
"87.91200","5.17915","0.03522"
"88.17600","5.20115","0.03577"
"88.44000","5.22315","0.03596"
"88.70400","5.24510","0.03645"
"88.96800","5.26716","0.03673"
"89.23200","5.28916","0.03741"
"89.49600","5.31116","0.03781"
"89.76000","5.33311","0.03883"
"90.02400","5.35517","0.03837"
"90.28800","5.37717","0.03873"
"90.55200","5.39923","0.03856"
"90.81600","5.42118","0.03946"
"91.08000","5.44318","0.03910"
"91.34400","5.46512","0.03959"
"91.60800","5.48718","0.04027"
"91.87200","5.50919","0.04076"
"92.13600","5.53119","0.04096"
"92.40000","5.55319","0.04174"
"92.66400","5.57519","0.04111"
"92.92800","5.59708","0.04203"
"93.19200","5.61914","0.04201"
"93.45600","5.64114","0.04240"
"93.72000","5.66321","0.04291"
"93.98400","5.68521","0.04302"
"94.24800","5.70721","0.04383"
"94.51200","5.72915","0.04421"
"94.77600","5.75110","0.04435"
"95.04000","5.77316","0.04509"
"95.30400","5.79510","0.04546"
"95.56800","5.81716","0.04601"
"95.83200","5.83911","0.04604"
"96.09600","5.86123","0.04647"
"96.36000","5.88311","0.04706"
"96.62400","5.90517","0.04726"
"96.88800","5.92718","0.04727"
"97.15200","5.94918","0.04797"
"97.41600","5.97112","0.04795"
"97.68000","5.99312","0.04822"
"97.94400","6.01507","0.04849"
"98.20800","6.03713","0.04914"
"98.47200","6.05913","0.04943"
"98.73600","6.08119","0.04952"
"99.00000","6.10314","0.05010"
"99.26400","6.12520","0.05047"
"99.52800","6.14708","0.05098"
"99.79200","6.16920","0.05088"
"100.05600","6.19115","0.05139"
"100.32000","6.21321","0.05146"
"100.58400","6.23515","0.05174"
"100.84800","6.25715","0.05165"
"101.11200","6.27910","0.05194"
"101.37600","6.30116","0.05235"
"101.64000","6.32310","0.05239"
"101.90400","6.34516","0.05234"
"102.16800","6.36711","0.05266"
"102.43200","6.38923","0.05300"
"102.69600","6.41111","0.05320"
"102.96000","6.43317","0.05355"
"103.22400","6.45518","0.05366"
"103.48800","6.47718","0.05391"
"103.75200","6.49912","0.05410"
"104.01600","6.52118","0.05432"
"104.28000","6.54313","0.05462"
"104.54400","6.56519","0.05471"
"104.80800","6.58713","0.05485"
"105.07200","6.60919","0.05500"
"105.33600","6.63120","0.05517"
"105.60000","6.65314","0.05512"
"105.86400","6.67514","0.05533"
"106.12800","6.69715","0.05544"
"106.39200","6.71915","0.05567"
"106.65600","6.74115","0.05571"
"106.92000","6.76321","0.05579"
"107.18400","6.78516","0.05586"
"107.44800","6.80716","0.05601"
"107.71200","6.82916","0.05613"
"107.97600","6.85110","0.05619"
"108.24000","6.87311","0.05656"
"108.50400","6.89517","0.05677"
"108.76800","6.91717","0.05704"
"109.03200","6.93917","0.05721"
"109.29600","6.96118","0.05734"
"109.56000","6.98318","0.05798"
"109.82400","7.00512","0.05820"
"110.08800","7.02718","0.05845"
"110.35200","7.04919","0.05944"
"110.61600","7.07119","0.05971"
"110.88000","7.09313","0.05993"
"111.14400","7.11519","0.06086"
"111.40800","7.13714","0.06230"
"111.67200","7.15914","0.06243"
"111.93600","7.18114","0.06336"
"112.20000","7.20314","0.06426"
"112.46400","7.22509","0.06484"
"112.72800","7.24721","0.06650"
"112.99200","7.26909","0.06708"
"113.25600","7.29115","0.06907"
"113.52000","7.31310","0.07079"
"113.78400","7.33522","0.07269"
"114.04800","7.35716","0.07378"
"114.31200","7.37916","0.07634"
"114.57600","7.40111","0.07863"
"114.84000","7.42317","0.07907"
"115.10400","7.44511","0.08158"
"115.36800","7.46717","0.08288"
"115.63200","7.48918","0.08470"
"115.89600","7.51118","0.08497"
"116.16000","7.53312","0.08687"
"116.42400","7.55518","0.08794"
"116.68800","7.57713","0.08933"
"116.95200","7.59919","0.05416"
"117.21600","7.62119","0.05557"
"117.48000","7.64319","0.05610"
"117.74400","7.66508","0.05643"
"118.00800","7.68714","0.05689"
"118.27200","7.70914","0.05734"
"118.53600","7.73121","0.05813"
"118.80000","7.75315","0.06014"
"119.06400","7.77515","0.06080"
"119.32800","7.79715","0.06280"
"119.59200","7.81916","0.06334"
"119.85600","7.84110","0.06639"
"120.12000","7.86322","0.06812"
"120.38400","7.88516","0.07048"
"120.64800","7.90717","0.07418"
"120.91200","7.92917","0.07395"
"121.17600","7.95111","0.07808"
"121.44000","7.97317","0.08086"
"121.70400","7.99518","0.08451"
"121.96800","8.01718","0.08638"
"122.23200","8.03918","0.08758"
"122.49600","8.06118","0.08937"
"122.76000","8.08319","0.09020"
"123.02400","8.10513","0.09196"
"123.28800","8.12713","0.09275"
"123.55200","8.14919","0.09392"
"123.81600","8.17114","0.09340"
"124.08000","8.19314","0.08413"
"124.34400","8.21514","0.08581"
"124.60800","8.23720","0.08582"
"124.87200","8.25915","0.08799"
"125.13600","8.28115","0.08936"
"125.40000","8.30315","0.09223"
"125.66400","8.32515","0.09408"
"125.92800","8.34710","0.09644"
"126.19200","8.36922","0.10032"
"126.45600","8.39110","0.10426"
"126.72000","8.41317","0.10975"
"126.98400","8.43517","0.11491"
"127.24800","8.45723","0.11947"
"127.51200","8.47905","0.12296"
"127.77600","8.50117","0.12620"
"128.04000","8.52312","0.13074"
"128.30400","8.54518","0.13400"
"128.56800","8.56712","0.13614"
"128.83200","8.58924","0.13850"
"129.09600","8.61113","0.13981"
"129.36000","8.63319","0.14106"
"129.62400","8.65513","0.14189"
"129.88800","8.67714","0.14250"
"130.15200","8.69914","0.14314"
"130.41600","8.72120","0.14358"
"130.68000","8.74314","0.14506"
"130.94400","8.76515","0.14750"
"131.20800","8.78709","0.14987"
"131.47200","8.80915","0.15188"
"131.73600","8.83109","0.15460"
"132.00000","8.85316","0.15732"
"132.26400","8.87516","0.15969"
"132.52800","8.89722","0.16263"
"132.79200","8.91916","0.16520"
"133.05600","8.94117","0.16844"
"133.32000","8.96317","0.17258"
"133.58400","8.98523","0.17675"
"133.84800","9.00711","0.18001"
"134.11200","9.02912","0.17620"
"134.37600","9.05112","0.17104"
"134.64000","9.07318","0.17511"
"134.90400","9.09518","0.17801"
"135.16800","9.11719","0.17861"
"135.43200","9.13919","0.17711"
"135.69600","9.16119","0.18338"
"135.96000","9.18319","0.18872"
"136.22400","9.20514","0.19332"
"136.48800","9.22720","0.19850"
"136.75200","9.24920","0.20202"
"137.01600","9.27120","0.20333"
"137.28000","9.29315","0.20402"
"137.54400","9.31515","0.20447"
"137.80800","9.33709","0.20488"
"138.07200","9.35915","0.20603"
"138.33600","9.38116","0.20845"
"138.60000","9.40322","0.21067"
"138.86400","9.42510","0.21507"
"139.12800","9.44716","0.21871"
"139.39200","9.46911","0.22092"
"139.65600","9.49117","0.22500"
"139.92000","9.51317","0.22799"
"140.18400","9.53523","0.23124"
"140.44800","9.55712","0.23412"
"140.71200","9.57918","0.23733"
"140.97600","9.60112","0.23969"
"141.24000","9.62319","0.24265"
"141.50400","9.64507","0.24510"
"141.76800","9.66719","0.24775"
"142.03200","9.68913","0.25040"
"142.29600","9.71113","0.25348"
"142.56000","9.73308","0.25839"
"142.82400","9.75514","0.25758"
"143.08800","9.77714","0.17592"
"143.35200","9.79920","0.17845"
"143.61600","9.82115","0.18189"
"143.88000","9.84315","0.18626"
"144.14400","9.86509","0.19212"
"144.40800","9.88716","0.19694"
"144.67200","9.90910","0.14808"
"144.93600","9.93116","0.15973"
"145.20000","9.95310","0.16208"
"145.46400","9.97517","0.16381"
"145.72800","9.99711","0.17417"
"145.99200","10.01923","0.17684"
"146.25600","10.04111","0.18120"
"146.52000","10.06324","0.19091"
"146.78400","10.08512","0.19552"
"147.04800","10.10718","0.19930"
"147.31200","10.12912","0.20385"
"147.57600","10.15119","0.20428"
"147.84000","10.17313","0.20442"
"148.10400","10.19519","0.20791"
"148.36800","10.21719","0.21420"
"148.63200","10.23914","0.21615"
"148.89600","10.26114","0.22003"
"149.16000","10.28314","0.22515"
"149.42400","10.30515","0.22882"
"149.68800","10.32715","0.23105"
"149.95200","10.34915","0.23458"
"150.21600","10.37121","0.23850"
"150.48000","10.39316","0.24042"
"150.74400","10.41516","0.24273"
"151.00800","10.43716","0.24571"
"151.27200","10.45910","0.24947"
"151.53600","10.48116","0.25158"
"151.80000","10.50317","0.25419"
"152.06400","10.52517","0.25975"
"152.32800","10.54717","0.26618"
"152.59200","10.56923","0.26908"
"152.85600","10.59118","0.27198"
"153.12000","10.61318","0.27615"
"153.38400","10.63512","0.28172"
"153.64800","10.65719","0.28749"
"153.91200","10.67913","0.29126"
"154.17600","10.70119","0.29795"
"154.44000","10.72307","0.30289"
"154.70400","10.74520","0.30705"
"154.96800","10.76714","0.25409"
"155.23200","10.78920","0.25334"
"155.49600","10.81108","0.25936"
"155.76000","10.83315","0.26663"
"156.02400","10.85509","0.26943"
"156.28800","10.87715","0.27252"
"156.55200","10.89909","0.27879"
"156.81600","10.92115","0.28743"
"157.08000","10.94310","0.29339"
"157.34400","10.96516","0.29645"
"157.60800","10.98710","0.30157"
"157.87200","11.00917","0.30850"
"158.13600","11.03117","0.31536"
"158.40000","11.05317","0.32017"
"158.66400","11.07517","0.32482"
"158.92800","11.09712","0.33112"
"159.19200","11.11912","0.33696"
"159.45600","11.14118","0.34215"
"159.72000","11.16313","0.34474"
"159.98400","11.18519","0.34756"
"160.24800","11.20713","0.34999"
"160.51200","11.22919","0.35183"
"160.77600","11.25113","0.35250"
"161.04000","11.27320","0.35264"
"161.30400","11.29514","0.35277"
"161.56800","11.31720","0.35290"
"161.83200","11.33914","0.35337"
"162.09600","11.36115","0.35431"
"162.36000","11.38315","0.35622"
"162.62400","11.40515","0.35873"
"162.88800","11.42716","0.36203"
"163.15200","11.44916","0.36566"
"163.41600","11.47116","0.36968"
"163.68000","11.49316","0.37376"
"163.94400","11.51517","0.37874"
"164.20800","11.53717","0.37932"
"164.47200","11.55917","0.36357"
"164.73600","11.58111","0.35259"
"165.00000","11.60318","0.35272"
"165.26400","11.62518","0.35285"
"165.52800","11.64718","0.35338"
"165.79200","11.66918","0.35536"
"166.05600","11.69119","0.35996"
"166.32000","11.71319","0.36410"
"166.58400","11.73525","0.37041"
"166.84800","11.75713","0.37706"
"167.11200","11.77913","0.38460"
"167.37600","11.80114","0.39319"
"167.64000","11.82320","0.40012"
"167.90400","11.84514","0.40406"
"168.16800","11.86715","0.40616"
"168.43200","11.88909","0.40876"
"168.69600","11.91121","0.41113"
"168.96000","11.93309","0.41730"
"169.22400","11.95516","0.42327"
"169.48800","11.97710","0.42719"
"169.75200","11.99916","0.43227"
"170.01600","12.02110","0.43762"
"170.28000","12.04317","0.44235"
"170.54400","12.06511","0.44679"
"170.80800","12.08717","0.45143"
"171.07200","12.10911","0.45430"
"171.33600","12.13118","0.45768"
"171.60000","12.15312","0.46124"
"171.86400","12.17518","0.46425"
"172.12800","12.19712","0.46624"
"172.39200","12.21913","0.46816"
"172.65600","12.24107","0.47013"
"172.92000","12.26319","0.47211"
"173.18400","12.28513","0.47472"
"173.44800","12.30720","0.47799"
"173.71200","12.32914","0.48165"
"173.97600","12.35114","0.41658"
"174.24000","12.37309","0.13030"
"174.50400","12.39515","0.14058"
"174.76800","12.41715","0.14240"
"175.03200","12.43921","0.14239"
"175.29600","12.46116","0.14226"
"175.56000","12.48316","0.14377"
"175.82400","12.50516","0.14554"
"176.08800","12.52716","0.14826"
"176.35200","12.54917","0.14704"
"176.61600","12.57117","0.14869"
"176.88000","12.59311","0.15506"
"177.14400","12.61517","0.15414"
"177.40800","12.63718","0.15474"
"177.67200","12.65912","0.15946"
"177.93600","12.68118","0.16050"
"178.20000","12.70318","0.16190"
"178.46400","12.72519","0.16373"
"178.72800","12.74713","0.16568"
"178.99200","12.76913","0.17007"
"179.25600","12.79113","0.16936"
"179.52000","12.81320","0.17320"
"179.78400","12.83514","0.17952"
"180.04800","12.85720","0.17878"
"180.31200","12.87914","0.18053"
"180.57600","12.90121","0.18685"
"180.84000","12.92315","0.18592"
"181.10400","12.94515","0.18715"
"181.36800","12.96715","0.19385"
"181.63200","12.98922","0.19333"
"181.89600","13.01110","0.19563"
"182.16000","13.03316","0.20122"
"182.42400","13.05510","0.20027"
"182.68800","13.07723","0.20179"
"182.95200","13.09917","0.18765"
"183.21600","13.12117","0.18444"
"183.48000","13.14305","0.18383"
"183.74400","13.16518","0.18807"
"184.00800","13.18712","0.18872"
"184.27200","13.20918","0.19116"
"184.53600","13.23112","0.19467"
"184.80000","13.25319","0.19550"
"185.06400","13.27513","0.19898"
"185.32800","13.29713","0.20131"
"185.59200","13.31913","0.20146"
"185.85600","13.34114","0.20267"
"186.12000","13.36314","0.20320"
"186.38400","13.38520","0.20361"
"186.64800","13.40714","0.20401"
"186.91200","13.42915","0.20429"
"187.17600","13.45109","0.20435"
"187.44000","13.47321","0.20478"
"187.70400","13.49515","0.20533"
"187.96800","13.51722","0.20580"
"188.23200","13.53910","0.20710"
"188.49600","13.56116","0.20860"
"188.76000","13.58317","0.20949"
"189.02400","13.60523","0.21015"
"189.28800","13.62717","0.21304"
"189.55200","13.64923","0.21461"
"189.81600","13.67118","0.21671"
"190.08000","13.69312","0.21854"
"190.34400","13.71512","0.21927"
"190.60800","13.73718","0.21983"
"190.87200","13.75913","0.22183"
"191.13600","13.78119","0.22331"
"191.40000","13.80319","0.22412"
"191.66400","13.82513","0.22457"
"191.92800","13.84708","0.21762"
"192.19200","13.86914","0.21724"
"192.45600","13.89120","0.21811"
"192.72000","13.91314","0.21968"
"192.98400","13.93515","0.22197"
"193.24800","13.95715","0.22319"
"193.51200","13.97915","0.22594"
"193.77600","14.00109","0.14431"
"194.04000","14.02316","0.09760"
"194.30400","14.04510","0.07077"
"194.56800","14.06716","0.03188"
"194.83200","14.08916","0.04003"
"195.09600","14.11117","0.03286"
"195.36000","14.13311","0.03398"
"195.62400","14.15517","0.03538"
"195.88800","14.17711","0.02913"
"196.15200","14.19918","0.03300"
"196.41600","14.22112","0.03314"
"196.68000","14.24318","0.03280"
"196.94400","14.26512","0.03511"
"197.20800","14.28719","0.03162"
"197.47200","14.30907","0.03144"
"197.73600","14.33119","0.03498"
"198.00000","14.35314","0.03523"
"198.26400","14.37514","0.03617"
"198.52800","14.39708","0.03728"
"198.79200","14.41914","0.03518"
"199.05600","14.44115","0.03789"
"199.32000","14.46321","0.03978"
"199.58400","14.48515","0.03958"
"199.84800","14.50715","0.03987"
"200.11200","14.52916","0.03988"
"200.37600","14.55116","0.04038"
"200.64000","14.57310","0.04108"
"200.90400","14.59522","0.04149"
"201.16800","14.61717","0.04104"
"201.43200","14.63923","0.04182"
"201.69600","14.66117","0.04242"
"201.96000","14.68317","0.04326"
"202.22400","14.70518","0.04315"
"202.48800","14.72724","0.04340"
"202.75200","14.74912","0.04357"
"203.01600","14.77118","0.04460"
"203.28000","14.79313","0.04460"
"203.54400","14.81513","0.04495"
"203.80800","14.83707","0.04523"
"204.07200","14.85919","0.04625"
"204.33600","14.88114","0.04677"
"204.60000","14.90314","0.04633"
"204.86400","14.92514","0.04335"
"205.12800","14.94715","0.04357"
"205.39200","14.96915","0.04377"
"205.65600","14.99115","0.04527"
"205.92000","15.01315","0.04584"
"206.18400","15.03521","0.04507"
"206.44800","15.05716","0.04579"
"206.71200","15.07910","0.04655"
"206.97600","15.10116","0.04647"
"207.24000","15.12311","0.04614"
"207.50400","15.14517","0.04655"
"207.76800","15.16711","0.04669"
"208.03200","15.18917","0.04692"
"208.29600","15.21111","0.04768"
"208.56000","15.23318","0.04835"
"208.82400","15.25512","0.04841"
"209.08800","15.27718","0.04870"
"209.35200","15.29912","0.04905"
"209.61600","15.32119","0.04948"
"209.88000","15.34313","0.04964"
"210.14400","15.36513","0.04977"
"210.40800","15.38708","0.05010"
"210.67200","15.40914","0.05020"
"210.93600","15.43114","0.05077"
"211.20000","15.45314","0.05108"
"211.46400","15.47509","0.05106"
"211.72800","15.49715","0.05142"
"211.99200","15.51909","0.05111"
"212.25600","15.54115","0.05148"
"212.52000","15.56316","0.05196"
"212.78400","15.58522","0.05224"
"213.04800","15.60710","0.05275"
"213.31200","15.62916","0.05292"
"213.57600","15.65117","0.05261"
"213.84000","15.67317","0.05279"
"214.10400","15.69517","0.05295"
"214.36800","15.71717","0.05328"
"214.63200","15.73906","0.05354"
"214.89600","15.76118","0.05372"
"215.16000","15.78312","0.05384"
"215.42400","15.80518","0.05355"
"215.68800","15.82713","0.05355"
"215.95200","15.84919","0.05392"
"216.21600","15.87113","0.05423"
"216.48000","15.89319","0.05442"
"216.74400","15.91514","0.05431"
"217.00800","15.93720","0.05470"
"217.27200","15.95914","0.05484"
"217.53600","15.98114","0.05498"
"217.80000","16.00315","0.05498"
"218.06400","16.02515","0.05519"
"218.32800","16.04715","0.05544"
"218.59200","16.06915","0.05538"
"218.85600","16.09116","0.05553"
"219.12000","16.11316","0.05570"
"219.38400","16.13516","0.05576"
"219.64800","16.15717","0.05577"
"219.91200","16.17911","0.05591"
"220.17600","16.20117","0.05597"
"220.44000","16.22317","0.05606"
"220.70400","16.24512","0.05629"
"220.96800","16.26718","0.05635"
"221.23200","16.28912","0.05644"
"221.49600","16.31118","0.05675"
"221.76000","16.33313","0.05706"
"222.02400","16.35513","0.05713"
"222.28800","16.37713","0.05758"
"222.55200","16.39925","0.05793"
"222.81600","16.42113","0.05820"
"223.08000","16.44314","0.05888"
"223.34400","16.46508","0.05874"
"223.60800","16.48720","0.05935"
"223.87200","16.50915","0.06004"
"224.13600","16.53121","0.06066"
"224.40000","16.55315","0.06116"
"224.66400","16.57521","0.06231"
"224.92800","16.59715","0.06290"
"225.19200","16.61922","0.06369"
"225.45600","16.64110","0.06436"
"225.72000","16.66322","0.06506"
"225.98400","16.68511","0.06565"
"226.24800","16.70717","0.06663"
"226.51200","16.72911","0.06786"
"226.77600","16.75111","0.06895"
"227.04000","16.77312","0.07043"
"227.30400","16.79518","0.07099"
"227.56800","16.81712","0.07287"
"227.83200","16.83918","0.07506"
"228.09600","16.86113","0.07689"
"228.36000","16.88313","0.07820"
"228.62400","16.90513","0.07988"
"228.88800","16.92719","0.08194"
"229.15200","16.94914","0.08343"
"229.41600","16.97120","0.08521"
"229.68000","16.99314","0.08657"
"229.94400","17.01514","0.08779"
"230.20800","17.03709","0.08903"
"230.47200","17.05921","0.09021"
"230.73600","17.08115","0.09105"
"231.00000","17.10321","0.09247"
"231.26400","17.12510","0.09383"
"231.52800","17.14716","0.09498"
"231.79200","17.16916","0.09706"
"232.05600","17.19116","0.09864"
"232.32000","17.21317","0.09968"
"232.58400","17.23511","0.10383"
"232.84800","17.25711","0.10576"
"233.11200","17.27917","0.10895"
"233.37600","17.30112","0.11272"
"233.64000","17.32318","0.11442"
"233.90400","17.34518","0.11820"
"234.16800","17.36719","0.12076"
"234.43200","17.38919","0.12365"
"234.69600","17.41113","0.12325"
"234.96000","17.43313","0.12655"
"235.22400","17.45514","0.12755"
"235.48800","17.47720","0.13083"
"235.75200","17.49920","0.13287"
"236.01600","17.52120","0.13506"
"236.28000","17.54315","0.13672"
"236.54400","17.56521","0.13821"
"236.80800","17.58715","0.13950"
"237.07200","17.60915","0.14002"
"237.33600","17.63116","0.14113"
"237.60000","17.65322","0.14124"
"237.86400","17.67510","0.14188"
"238.12800","17.69716","0.14246"
"238.39200","17.71911","0.14303"
"238.65600","17.74117","0.14384"
"238.92000","17.76317","0.14454"
"239.18400","17.78523","0.14585"
"239.44800","17.80706","0.14710"
"239.71200","17.82918","0.14847"
"239.97600","17.85106","0.15060"
"240.24000","17.87318","0.15204"
"240.50400","17.89513","0.15409"
"240.76800","17.91725","0.15585"
"241.03200","17.93913","0.15727"
"241.29600","17.96114","0.15898"
"241.56000","17.98308","0.16100"
"241.82400","18.00520","0.16267"
"242.08800","18.02714","0.16452"
"242.35200","18.04920","0.16566"
"242.61600","18.07115","0.16779"
"242.88000","18.09315","0.16998"
"243.14400","18.11515","0.17176"
"243.40800","18.13716","0.17448"
"243.67200","18.15916","0.17747"
"243.93600","18.18122","0.17925"
"244.20000","18.20316","0.18152"
"244.46400","18.22516","0.18337"
"244.72800","18.24717","0.18583"
"244.99200","18.26917","0.18762"
"245.25600","18.29117","0.18985"
"245.52000","18.31318","0.19214"
"245.78400","18.33512","0.19414"
"246.04800","18.35712","0.19637"
"246.31200","18.37912","0.19764"
"246.57600","18.40112","0.20007"
"246.84000","18.42313","0.20121"
"247.10400","18.44519","0.20218"
"247.36800","18.46719","0.20255"
"247.63200","18.48914","0.20339"
"247.89600","18.51114","0.20375"
"248.16000","18.53314","0.20381"
"248.42400","18.55520","0.20414"
"248.68800","18.57714","0.20441"
"248.95200","18.59921","0.20450"
"249.21600","18.62115","0.20510"
"249.48000","18.64315","0.20575"
"249.74400","18.66516","0.20598"
"250.00800","18.68722","0.20722"
"250.27200","18.70916","0.20850"
"250.53600","18.73122","0.21043"
"250.80000","18.75317","0.21198"
"251.06400","18.77517","0.21408"
"251.32800","18.79711","0.21517"
"251.59200","18.81923","0.21695"
"251.85600","18.84112","0.21832"
"252.12000","18.86318","0.21946"
"252.38400","18.88512","0.22062"
"252.64800","18.90712","0.22238"
"252.91200","18.92907","0.22319"
"253.17600","18.95119","0.22469"
"253.44000","18.97313","0.22674"
"253.70400","18.99519","0.22773"
"253.96800","19.01714","0.22912"
"254.23200","19.03914","0.23028"
"254.49600","19.06108","0.23181"
"254.76000","19.08314","0.23360"
"255.02400","19.10515","0.23419"
"255.28800","19.12715","0.23540"
"255.55200","19.14915","0.23651"
"255.81600","19.17116","0.23762"
"256.08000","19.19310","0.23845"
"256.34400","19.21516","0.23964"
"256.60800","19.23716","0.24064"
"256.87200","19.25917","0.24132"
"257.13600","19.28111","0.24229"
"257.40000","19.30317","0.24295"
"257.66400","19.32511","0.24407"
"257.92800","19.34718","0.24449"
"258.19200","19.36912","0.24556"
"258.45600","19.39118","0.24647"
"258.72000","19.41312","0.24727"
"258.98400","19.43519","0.24822"
"259.24800","19.45713","0.24857"
"259.51200","19.47913","0.25023"
"259.77600","19.50113","0.25125"
"260.04000","19.52314","0.25276"
"260.30400","19.54514","0.25381"
"260.56800","19.56720","0.25606"
"260.83200","19.58914","0.25727"
"261.09600","19.61115","0.25856"
"261.36000","19.63315","0.26001"
"261.62400","19.65515","0.26212"
"261.88800","19.67715","0.26285"
"262.15200","19.69921","0.26531"
"262.41600","19.72116","0.26665"
"262.68000","19.74310","0.26858"
"262.94400","19.76516","0.26986"
"263.20800","19.78717","0.27140"
"263.47200","19.80917","0.27293"
"263.73600","19.83117","0.27423"
"264.00000","19.85323","0.27572"
"264.26400","19.87518","0.27701"
"264.52800","19.89718","0.27871"
"264.79200","19.91912","0.28034"
"265.05600","19.94118","0.28234"
"265.32000","19.96313","0.28438"
"265.58400","19.98519","0.28744"
"265.84800","20.00713","0.28920"
"266.11200","20.02919","0.29185"
"266.37600","20.05114","0.29388"
"266.64000","20.07320","0.29628"
"266.90400","20.09514","0.29797"
"267.16800","20.11720","0.29968"
"267.43200","20.13915","0.30128"
"267.69600","20.16121","0.30175"
"267.96000","20.18309","0.30366"
"268.22400","20.20515","0.30595"
"268.48800","20.22710","0.30677"
"268.75200","20.24916","0.30872"
"269.01600","20.27110","0.10372"
"269.28000","20.29317","0.07971"
"269.54400","20.31511","0.08475"
"269.80800","20.33717","0.08783"
"270.07200","20.35911","0.07687"
"270.33600","20.38118","0.08588"
"270.60000","20.40312","0.07740"
"270.86400","20.42512","0.09242"
"271.12800","20.44712","0.08361"
"271.39200","20.46913","0.09186"
"271.65600","20.49113","0.08782"
"271.92000","20.51319","0.09276"
"272.18400","20.53513","0.09547"
"272.44800","20.55714","0.09693"
"272.71200","20.57914","0.09755"
"272.97600","20.60120","0.10170"
"273.24000","20.62309","0.09711"
"273.50400","20.64526","0.11262"
"273.76800","20.66715","0.09999"
"274.03200","20.68915","0.11636"
"274.29600","20.71115","0.10643"
"274.56000","20.73316","0.11700"
"274.82400","20.75516","0.11710"
"275.08800","20.77722","0.12028"
"275.35200","20.79922","0.11673"
"275.61600","20.82117","0.12349"
"275.88000","20.84311","0.11974"
"276.14400","20.86511","0.12486"
"276.40800","20.88717","0.12382"
"276.67200","20.90918","0.12461"
"276.93600","20.93118","0.12993"
"277.20000","20.95318","0.12769"
"277.46400","20.97518","0.13225"
"277.72800","20.99713","0.13203"
"277.99200","21.01919","0.13475"
"278.25600","21.04113","0.13327"
"278.52000","21.06319","0.13657"
"278.78400","21.08514","0.13381"
"279.04800","21.10720","0.01126"
"279.31200","21.12914","0.00250"
"279.57600","21.15115","0.00114"
"279.84000","21.17315","0.00227"
"280.10400","21.19515","0.00611"
"280.36800","21.21715","0.00073"
"280.63200","21.23916","0.00173"
"280.89600","21.26110","0.00086"
"281.16000","21.28316","0.00415"
"281.42400","21.30516","0.00247"
"281.68800","21.32717","0.00123"
"281.95200","21.34911","0.00219"
"282.21600","21.37117","0.00272"
"282.48000","21.39311","0.00203"
"282.74400","21.41518","0.00152"
"283.00800","21.43712","0.00115"
"283.27200","21.45918","0.00170"
"283.53600","21.48112","0.00374"
"283.80000","21.50319","0.00249"
"284.06400","21.52513","0.00105"
"284.32800","21.54713","0.00133"
"284.59200","21.56907","0.00327"
"284.85600","21.59120","0.00250"
"285.12000","21.61314","0.00144"
"285.38400","21.63520","0.00270"
"285.64800","21.65714","0.00256"
"285.91200","21.67914","0.00325"
"286.17600","21.70115","0.00264"
"286.44000","21.72315","0.00196"
"286.70400","21.74516","0.00221"
"286.96800","21.76722","0.00399"
"287.23200","21.78916","0.00378"
"287.49600","21.81116","0.00168"
"287.76000","21.83316","0.00238"
"288.02400","21.85517","0.00270"
"288.28800","21.87717","0.00197"
"288.55200","21.89923","0.00149"
"288.81600","21.92112","0.00173"
"289.08000","21.94318","0.00211"
"289.34400","21.96512","0.00292"
"289.60800","21.98718","0.00193"
"289.87200","22.00912","0.00150"
"290.13600","22.03119","0.00212"
"290.40000","22.05313","0.00363"
"290.66400","22.07519","0.00298"
"290.92800","22.09714","0.00233"
"291.19200","22.11914","0.00233"
"291.45600","22.14120","0.00191"
"291.72000","22.16320","0.00341"
"291.98400","22.18521","0.00243"
"292.24800","22.20715","0.00251"
"292.51200","22.22915","0.00288"
"292.77600","22.25115","0.00351"
"293.04000","22.27321","0.00270"
"293.30400","22.29510","0.00230"
"293.56800","22.31722","0.00371"
"293.83200","22.33910","0.00272"
"294.09600","22.36117","0.00345"
"294.36000","22.38311","0.00251"
"294.62400","22.40517","0.00273"
"294.88800","22.42711","0.00315"
"295.15200","22.44918","0.00310"
"295.41600","22.47106","0.00281"
"295.68000","22.49312","0.00246"
"295.94400","22.51512","0.00300"
"296.20800","22.53719","0.00238"
"296.47200","22.55913","0.00338"
"296.73600","22.58119","0.00242"
"297.00000","22.60314","0.00318"
"297.26400","22.62520","0.00328"
"297.52800","22.64708","0.00260"
"297.79200","22.66914","0.00293"
"298.05600","22.69114","0.00262"
"298.32000","22.71321","0.00329"
"298.58400","22.73515","0.00215"
"298.84800","22.75721","0.00265"
"299.11200","22.77910","0.00258"
"299.37600","22.80116","0.00348"
"299.64000","22.82310","0.00337"
"299.90400","22.84522","0.00292"
"300.16800","22.86716","0.00371"
"300.43200","22.88917","0.00299"
"300.69600","22.91111","0.00319"
"300.96000","22.93323","0.00354"
"301.22400","22.95512","0.00414"
"301.48800","22.97724","0.00365"
"301.75200","22.99912","0.00348"
"302.01600","23.02112","0.00336"
"302.28000","23.04313","0.00289"
"302.54400","23.06519","0.00418"
"302.80800","23.08713","0.00407"
"303.07200","23.10913","0.00265"
"303.33600","23.13120","0.00358"
"303.60000","23.15314","0.00368"
"303.86400","23.17508","0.00357"
"304.12800","23.19714","0.00325"
"304.39200","23.21915","0.00348"
"304.65600","23.24115","0.00377"
"304.92000","23.26315","0.00325"
"305.18400","23.28515","0.00266"
"305.44800","23.30716","0.00315"
"305.71200","23.32910","0.00365"
"305.97600","23.35116","0.00402"
"306.24000","23.37316","0.00442"
"306.50400","23.39517","0.00333"
"306.76800","23.41717","0.00382"
"307.03200","23.43917","0.00344"
"307.29600","23.46111","0.00349"
"307.56000","23.48318","0.00338"
"307.82400","23.50512","0.00367"
"308.08800","23.52718","0.00399"
"308.35200","23.54912","0.00399"
"308.61600","23.57119","0.00436"
"308.88000","23.59313","0.00435"
"309.14400","23.61519","0.00418"
"309.40800","23.63708","0.00378"
"309.67200","23.65920","0.00401"
"309.93600","23.68114","0.00406"
"310.20000","23.70314","0.00329"
"310.46400","23.72508","0.00498"
"310.72800","23.74715","0.00425"
"310.99200","23.76909","0.00435"
"311.25600","23.79121","0.00414"
"311.52000","23.81315","0.00387"
"311.78400","23.83522","0.00421"
"312.04800","23.85710","0.00413"
"312.31200","23.87910","0.00480"
"312.57600","23.90111","0.00523"
"312.84000","23.92317","0.00423"
"313.10400","23.94517","0.00466"
"313.36800","23.96723","0.00437"
"313.63200","23.98912","0.00487"
"313.89600","24.01112","0.00425"
"314.16000","24.03318","0.00453"
"314.42400","24.05518","0.00369"
"314.68800","24.07713","0.00413"
"314.95200","24.09919","0.00474"
"315.21600","24.12113","0.00469"
"315.48000","24.14319","0.00492"
"315.74400","24.16514","0.00545"
"316.00800","24.18714","0.00492"
"316.27200","24.20914","0.00551"
"316.53600","24.23120","0.00451"
"316.80000","24.25315","0.00492"
"317.06400","24.27515","0.00461"
"317.32800","24.29715","0.00501"
"317.59200","24.31921","0.00533"
"317.85600","24.34116","0.00565"
"318.12000","24.36316","0.00488"
"318.38400","24.38516","0.00435"
"318.64800","24.40711","0.00533"
"318.91200","24.42911","0.00399"
"319.17600","24.45111","0.00554"
"319.44000","24.47317","0.00469"
"319.70400","24.49517","0.00457"
"319.96800","24.51723","0.00489"
"320.23200","24.53912","0.00450"
"320.49600","24.56118","0.00483"
"320.76000","24.58313","0.00538"
"321.02400","24.60519","0.00464"
"321.28800","24.62713","0.00528"
"321.55200","24.64913","0.00542"
"321.81600","24.67113","0.00560"
"322.08000","24.69320","0.00529"
"322.34400","24.71514","0.00551"
"322.60800","24.73714","0.00498"
"322.87200","24.75915","0.00587"
"323.13600","24.78121","0.00436"
"323.40000","24.80309","0.00537"
"323.66400","24.82515","0.00511"
"323.92800","24.84709","0.00526"
"324.19200","24.86922","0.00528"
"324.45600","24.89116","0.00560"
"324.72000","24.91316","0.00589"
"324.98400","24.93510","0.00574"
"325.24800","24.95717","0.00600"
"325.51200","24.97911","0.00646"
"325.77600","25.00117","0.00646"
"326.04000","25.02311","0.00602"
"326.30400","25.04518","0.00513"
"326.56800","25.06712","0.00572"
"326.83200","25.08918","0.00569"
"327.09600","25.11112","0.00504"
"327.36000","25.13313","0.00581"
"327.62400","25.15507","0.00592"
"327.88800","25.17719","0.00524"
"328.15200","25.19914","0.00563"
"328.41600","25.22120","0.00554"
"328.68000","25.24314","0.00608"
"328.94400","25.26514","0.00622"
"329.20800","25.28715","0.00598"
"329.47200","25.30915","0.00621"
"329.73600","25.33115","0.00620"
"330.00000","25.35315","0.00539"
"330.26400","25.37516","0.00665"
"330.52800","25.39716","0.00607"
"330.79200","25.41916","0.00625"
"331.05600","25.44110","0.00560"
"331.32000","25.46317","0.00680"
"331.58400","25.48517","0.00676"
"331.84800","25.50711","0.00625"
"332.11200","25.52911","0.00711"
"332.37600","25.55106","0.00632"
"332.64000","25.57312","0.00604"
"332.90400","25.59518","0.00706"
"333.16800","25.61718","0.00769"
"333.43200","25.63919","0.00684"
"333.69600","25.66119","0.00644"
"333.96000","25.68313","0.00624"
"334.22400","25.70514","0.00627"
"334.48800","25.72720","0.00640"
"334.75200","25.74914","0.00684"
"335.01600","25.77114","0.00626"
"335.28000","25.79309","0.00647"
"335.54400","25.81515","0.00665"
"335.80800","25.83709","0.00646"
"336.07200","25.85921","0.00627"
"336.33600","25.88116","0.00616"
"336.60000","25.90322","0.00663"
"336.86400","25.92510","0.00626"
"337.12800","25.94722","0.00667"
"337.39200","25.96917","0.00712"
"337.65600","25.99123","0.00678"
"337.92000","26.01317","0.00598"
"338.18400","26.03518","0.00746"
"338.44800","26.05705","0.00625"
"338.71200","26.07924","0.00676"
"338.97600","26.10112","0.00735"
"339.24000","26.12318","0.00717"
"339.50400","26.14519","0.00670"
"339.76800","26.16719","0.00638"
"340.03200","26.18907","0.00734"
"340.29600","26.21113","0.00745"
"340.56000","26.23314","0.00718"
"340.82400","26.25514","0.00742"
"341.08800","26.27714","0.00698"
"341.35200","26.29920","0.00723"
"341.61600","26.32108","0.00799"
"341.88000","26.34315","0.00752"
"342.14400","26.36509","0.00775"
"342.40800","26.38721","0.00749"
"342.67200","26.40916","0.00744"
"342.93600","26.43122","0.00735"
"343.20000","26.45316","0.00766"
"343.46400","26.47516","0.00701"
"343.72800","26.49711","0.00685"
"343.99200","26.51917","0.00780"
"344.25600","26.54117","0.00761"
"344.52000","26.56323","0.00719"
"344.78400","26.58512","0.00824"
"345.04800","26.60712","0.00822"
"345.31200","26.62912","0.00793"
"345.57600","26.65118","0.00831"
"345.84000","26.67313","0.00790"
"346.10400","26.69513","0.00806"
"346.36800","26.71713","0.00798"
"346.63200","26.73914","0.00729"
"346.89600","26.76114","0.00803"
"347.16000","26.78314","0.00782"
"347.42400","26.80520","0.00858"
"347.68800","26.82721","0.00915"
"347.95200","26.84921","0.00852"
"348.21600","26.87115","0.00887"
"348.48000","26.89315","0.00800"
"348.74400","26.91510","0.00806"
"349.00800","26.93716","0.00847"
"349.27200","26.95916","0.00970"
"349.53600","26.98116","0.00905"
"349.80000","27.00317","0.00998"
"350.06400","27.02523","0.00860"
"350.32800","27.04711","0.00919"
"350.59200","27.06917","0.00912"
"350.85600","27.09112","0.00890"
"351.12000","27.11324","0.00905"
"351.38400","27.13512","0.00890"
"351.64800","27.15718","0.00986"
"351.91200","27.17907","0.00918"
"352.17600","27.20119","0.00972"
"352.44000","27.22307","0.01006"
"352.70400","27.24519","0.00956"
"352.96800","27.26714","0.01026"
"353.23200","27.28920","0.00988"
"353.49600","27.31108","0.00966"
"353.76000","27.33314","0.00938"
"354.02400","27.35515","0.01008"
"354.28800","27.37715","0.01026"
"354.55200","27.39915","0.00989"
"354.81600","27.42115","0.00875"
"355.08000","27.44310","0.00886"
"355.34400","27.46516","0.00847"
"355.60800","27.48716","0.00901"
"355.87200","27.50916","0.01008"
"356.13600","27.53117","0.01042"
"356.40000","27.55317","0.00993"
"356.66400","27.57511","0.01013"
"356.92800","27.59712","0.01037"
"357.19200","27.61917","0.00975"
"357.45600","27.64124","0.01096"
"357.72000","27.66312","0.01122"
"357.98400","27.68513","0.01052"
"358.24800","27.70713","0.01133"
"358.51200","27.72913","0.01102"
"358.77600","27.75113","0.01151"
"359.04000","27.77314","0.01140"
"359.30400","27.79520","0.01142"
"359.56800","27.81720","0.01164"
"359.83200","27.83914","0.01183"
"360.09600","27.86115","0.01160"
"360.36000","27.88315","0.01225"
"360.62400","27.90521","0.01115"
"360.88800","27.92721","0.01099"
"361.15200","27.94916","0.01130"
"361.41600","27.97116","0.01089"
"361.68000","27.99316","0.01125"
"361.94400","28.01516","0.01162"
"362.20800","28.03711","0.01200"
"362.47200","28.05923","0.01149"
"362.73600","28.08117","0.01165"
"363.00000","28.10317","0.01187"
"363.26400","28.12511","0.01134"
"363.52800","28.14718","0.01190"
"363.79200","28.16912","0.01054"
"364.05600","28.19118","0.01178"
"364.32000","28.21313","0.01217"
"364.58400","28.23519","0.01134"
"364.84800","28.25707","0.01202"
"365.11200","28.27919","0.01139"
"365.37600","28.30114","0.01189"
"365.64000","28.32320","0.01171"
"365.90400","28.34514","0.01213"
"366.16800","28.36715","0.01186"
"366.43200","28.38909","0.01226"
"366.69600","28.41121","0.01145"
"366.96000","28.43309","0.01074"
"367.22400","28.45515","0.01172"
"367.48800","28.47710","0.01128"
"367.75200","28.49916","0.01063"
"368.01600","28.52110","0.01212"
"368.28000","28.54310","0.01184"
"368.54400","28.56505","0.01091"
"368.80800","28.58717","0.01162"
"369.07200","28.60911","0.01174"
"369.33600","28.63117","0.01150"
"369.60000","28.65312","0.01135"
"369.86400","28.67518","0.01200"
"370.12800","28.69712","0.01069"
"370.39200","28.71918","0.01178"
"370.65600","28.74113","0.01214"
"370.92000","28.76319","0.01182"
"371.18400","28.78513","0.01151"
"371.44800","28.80720","0.01184"
"371.71200","28.82914","0.01267"
"371.97600","28.85114","0.01201"
"372.24000","28.87320","0.01152"
"372.50400","28.89515","0.01153"
"372.76800","28.91715","0.01158"
"373.03200","28.93915","0.01165"
"373.29600","28.96115","0.01148"
"373.56000","28.98316","0.01158"
"373.82400","29.00516","0.01113"
"374.08800","29.02716","0.01164"
"374.35200","29.04916","0.01209"
"374.61600","29.07117","0.01083"
"374.88000","29.09317","0.01256"
"375.14400","29.11517","0.01145"
"375.40800","29.13712","0.01134"
"375.67200","29.15918","0.01180"
"375.93600","29.18118","0.01272"
"376.20000","29.20318","0.01180"
"376.46400","29.22518","0.01264"
"376.72800","29.24713","0.01176"
"376.99200","29.26919","0.01312"
"377.25600","29.29113","0.01291"
"377.52000","29.31319","0.01309"
"377.78400","29.33514","0.01327"
"378.04800","29.35720","0.01183"
"378.31200","29.37908","0.01281"
"378.57600","29.40120","0.01227"
"378.84000","29.42315","0.01273"
"379.10400","29.44521","0.01234"
"379.36800","29.46715","0.01180"
"379.63200","29.48916","0.01245"
"379.89600","29.51110","0.01186"
"380.16000","29.53316","0.01216"
"380.42400","29.55510","0.01241"
"380.68800","29.57722","0.00962"
"380.95200","29.59917","0.01013"
"381.21600","29.62117","0.00890"
"381.48000","29.64305","0.00215"
"381.74400","29.66518","0.00144"
"382.00800","29.68712","0.00169"
"382.27200","29.70918","0.00178"
"382.53600","29.73112","0.00248"
"382.80000","29.75319","0.00232"
"383.06400","29.77513","0.00225"
"383.32800","29.79713","0.00201"
"383.59200","29.81913","0.00206"
"383.85600","29.84120","0.00141"
"384.12000","29.86320","0.00222"
"384.38400","29.88520","0.00256"
"384.64800","29.90709","0.00136"
"384.91200","29.92915","0.00174"
"385.17600","29.95115","0.00193"
"385.44000","29.97321","0.00199"
"385.70400","29.99515","0.00213"
"385.96800","30.01716","0.00181"
"386.23200","30.03916","0.00134"
"386.49600","30.06122","0.00181"
"386.76000","30.08316","0.00280"
"387.02400","30.10523","0.00262"
"387.28800","30.12723","0.00223"
"387.55200","30.14917","0.00242"
"387.81600","30.17112","0.00254"
"388.08000","30.19312","0.00169"
"388.34400","30.21512","0.00098"
"388.60800","30.23718","0.00178"
"388.87200","30.25918","0.00312"
"389.13600","30.28113","0.00262"
"389.40000","30.30313","0.00178"
"389.66400","30.32513","0.00243"
"389.92800","30.34719","0.00228"
"390.19200","30.36914","0.00250"
"390.45600","30.39114","0.00222"
"390.72000","30.41314","0.00282"
"390.98400","30.43515","0.00240"
"391.24800","30.45709","0.00318"
"391.51200","30.47915","0.00288"
"391.77600","30.50115","0.00285"
"392.04000","30.52316","0.00229"
"392.30400","30.54516","0.00278"
"392.56800","30.56716","0.00365"
"392.83200","30.58910","0.00261"
"393.09600","30.61117","0.00230"
"393.36000","30.63311","0.00238"
"393.62400","30.65523","0.00274"
"393.88800","30.67711","0.00349"
"394.15200","30.69918","0.00254"
"394.41600","30.72106","0.00268"
"394.68000","30.74318","0.00312"
"394.94400","30.76506","0.00371"
"395.20800","30.78719","0.00258"
"395.47200","30.80907","0.00279"
"395.65800","30.82467","0.00326"