File: Force_trajectories/161114/Specimen_RawData_7.csv
End date,"11/14/2016"
Specimen label,"20BT63.2.r2"
Maximum Load,"0.05861",N

Time,Extension,Load
(s),(mm),(N)
"0.00000","19.54173","0.00819"
"0.07800","19.54382","0.00771"
"0.15600","19.55034","0.00717"
"0.23400","19.55907","0.00628"
"0.31200","19.56720","0.00648"
"0.39000","19.57444","0.00628"
"0.46800","19.58101","0.00695"
"0.54600","19.58747","0.00668"
"0.62400","19.59386","0.00754"
"0.70200","19.60038","0.00778"
"0.78000","19.60684","0.00674"
"0.85800","19.61342","0.00699"
"0.93600","19.61993","0.00698"
"1.01400","19.62639","0.00598"
"1.09200","19.63291","0.00803"
"1.17000","19.63931","0.00780"
"1.24800","19.64582","0.00823"
"1.32600","19.65234","0.00742"
"1.40400","19.65892","0.00684"
"1.48200","19.66537","0.00680"
"1.56000","19.67189","0.00711"
"1.63800","19.67841","0.00696"
"1.71600","19.68486","0.00834"
"1.79400","19.69132","0.00836"
"1.87200","19.69784","0.00766"
"1.95000","19.70436","0.00754"
"2.02800","19.71094","0.00682"
"2.10600","19.71739","0.00725"
"2.18400","19.72385","0.00728"
"2.26200","19.73037","0.00697"
"2.34000","19.73682","0.00883"
"2.41800","19.74334","0.00721"
"2.49600","19.74986","0.00852"
"2.57400","19.75637","0.00818"
"2.65200","19.76289","0.00744"
"2.73000","19.76935","0.00767"
"2.80800","19.77581","0.00732"
"2.88600","19.78226","0.00706"
"2.96400","19.78884","0.00856"
"3.04200","19.79536","0.00792"
"3.12000","19.80193","0.00722"
"3.19800","19.80833","0.00724"
"3.27600","19.81491","0.00787"
"3.35400","19.82130","0.00775"
"3.43200","19.82782","0.00764"
"3.51000","19.83434","0.00904"
"3.58800","19.84086","0.00792"
"3.66600","19.84737","0.00899"
"3.74400","19.85389","0.00850"
"3.82200","19.86035","0.00799"
"3.90000","19.86681","0.00809"
"3.97800","19.87332","0.00796"
"4.05600","19.87978","0.00815"
"4.13400","19.88636","0.00872"
"4.21200","19.89288","0.00856"
"4.29000","19.89939","0.00784"
"4.36800","19.90585","0.00865"
"4.44600","19.91231","0.00827"
"4.52400","19.91876","0.00830"
"4.60200","19.92528","0.00877"
"4.68000","19.93186","0.00930"
"4.75800","19.93831","0.00916"
"4.83600","19.94489","0.00849"
"4.91400","19.95135","0.00889"
"4.99200","19.95787","0.00834"
"5.07000","19.96426","0.00809"
"5.14800","19.97090","0.00901"
"5.22600","19.97736","0.00913"
"5.30400","19.98388","0.00966"
"5.38200","19.99039","0.00939"
"5.46000","19.99685","0.00902"
"5.53800","20.00330","0.00842"
"5.61600","20.00982","0.00818"
"5.69400","20.01634","0.00906"
"5.77200","20.02286","0.00885"
"5.85000","20.02937","0.00949"
"5.92800","20.03589","0.00944"
"6.00600","20.04235","0.00941"
"6.08400","20.04881","0.00924"
"6.16200","20.05532","0.00871"
"6.24000","20.06184","0.00824"
"6.31800","20.06836","0.00869"
"6.39600","20.07487","0.01064"
"6.47400","20.08139","0.01023"
"6.55200","20.08785","0.00997"
"6.63000","20.09425","0.00958"
"6.70800","20.10082","0.00904"
"6.78600","20.10734","0.00916"
"6.86400","20.11391","0.00875"
"6.94200","20.12037","0.00944"
"7.02000","20.12689","0.01007"
"7.09800","20.13335","0.01128"
"7.17600","20.13981","0.01001"
"7.25400","20.14632","0.00944"
"7.33200","20.15284","0.00959"
"7.41000","20.15942","0.00870"
"7.48800","20.16587","0.00962"
"7.56600","20.17239","0.01053"
"7.64400","20.17885","0.01082"
"7.72200","20.18536","0.01140"
"7.80000","20.19182","0.01064"
"7.87800","20.19834","0.00904"
"7.95600","20.20486","0.00900"
"8.03400","20.21137","0.01045"
"8.11200","20.21783","0.01021"
"8.19000","20.22435","0.01114"
"8.26800","20.23081","0.01075"
"8.34600","20.23732","0.01041"
"8.42400","20.24390","0.01116"
"8.50200","20.25035","0.01015"
"8.58000","20.25687","0.01029"
"8.65800","20.26327","0.01122"
"8.73600","20.26985","0.01120"
"8.81400","20.27630","0.01175"
"8.89200","20.28282","0.01154"
"8.97000","20.28934","0.01185"
"9.04800","20.29586","0.01071"
"9.12600","20.30231","0.01100"
"9.20400","20.30883","0.01102"
"9.28200","20.31529","0.01120"
"9.36000","20.32181","0.01128"
"9.43800","20.32832","0.01162"
"9.51600","20.33490","0.01192"
"9.59400","20.34135","0.01063"
"9.67200","20.34787","0.01101"
"9.75000","20.35433","0.01109"
"9.82800","20.36079","0.01149"
"9.90600","20.36730","0.01182"
"9.98400","20.37388","0.01254"
"10.06200","20.38034","0.01217"
"10.14000","20.38686","0.01043"
"10.21800","20.39337","0.01122"
"10.29600","20.39983","0.01197"
"10.37400","20.40629","0.01150"
"10.45200","20.41280","0.01259"
"10.53000","20.41938","0.01217"
"10.60800","20.42590","0.01214"
"10.68600","20.43235","0.01217"
"10.76400","20.43881","0.01126"
"10.84200","20.44533","0.01160"
"10.92000","20.45179","0.01234"
"10.99800","20.45831","0.01248"
"11.07600","20.46482","0.01313"
"11.15400","20.47140","0.01246"
"11.23200","20.47786","0.01185"
"11.31000","20.48443","0.01132"
"11.38800","20.49083","0.01191"
"11.46600","20.49728","0.01251"
"11.54400","20.50380","0.01315"
"11.62200","20.51032","0.01390"
"11.70000","20.51690","0.01307"
"11.77800","20.52342","0.01293"
"11.85600","20.52987","0.01220"
"11.93400","20.53633","0.01250"
"12.01200","20.54284","0.01224"
"12.09000","20.54930","0.01321"
"12.16800","20.55588","0.01350"
"12.24600","20.56234","0.01356"
"12.32400","20.56891","0.01329"
"12.40200","20.57531","0.01192"
"12.48000","20.58183","0.01212"
"12.55800","20.58828","0.01346"
"12.63600","20.59480","0.01435"
"12.71400","20.60132","0.01483"
"12.79200","20.60784","0.01502"
"12.87000","20.61442","0.01421"
"12.94800","20.62087","0.01273"
"13.02600","20.62733","0.01279"
"13.10400","20.63379","0.01374"
"13.18200","20.64030","0.01424"
"13.26000","20.64682","0.01486"
"13.33800","20.65334","0.01403"
"13.41600","20.65985","0.01389"
"13.49400","20.66637","0.01319"
"13.57200","20.67283","0.01285"
"13.65000","20.67935","0.01421"
"13.72800","20.68586","0.01416"
"13.80600","20.69238","0.01578"
"13.88400","20.69890","0.01585"
"13.96200","20.70535","0.01356"
"14.04000","20.71187","0.01377"
"14.11800","20.71833","0.01434"
"14.19600","20.72484","0.01544"
"14.27400","20.73136","0.01568"
"14.35200","20.73788","0.01570"
"14.43000","20.74434","0.01612"
"14.50800","20.75091","0.01430"
"14.58600","20.75737","0.01460"
"14.66400","20.76383","0.01411"
"14.74200","20.77035","0.01578"
"14.82000","20.77686","0.01608"
"14.89800","20.78332","0.01636"
"14.97600","20.78984","0.01596"
"15.05400","20.79635","0.01503"
"15.13200","20.80281","0.01475"
"15.21000","20.80927","0.01506"
"15.28800","20.81579","0.01569"
"15.36600","20.82236","0.01629"
"15.44400","20.82894","0.01678"
"15.52200","20.83534","0.01662"
"15.60000","20.84191","0.01499"
"15.67800","20.84831","0.01430"
"15.75600","20.85483","0.01579"
"15.83400","20.86129","0.01622"
"15.91200","20.86780","0.01747"
"15.99000","20.87438","0.01740"
"16.06800","20.88090","0.01682"
"16.14600","20.88735","0.01558"
"16.22400","20.89381","0.01501"
"16.30200","20.90033","0.01564"
"16.38000","20.90679","0.01708"
"16.45800","20.91336","0.01778"
"16.53600","20.91988","0.01854"
"16.61400","20.92634","0.01800"
"16.69200","20.93285","0.01708"
"16.77000","20.93931","0.01650"
"16.84800","20.94583","0.01579"
"16.92600","20.95228","0.01786"
"17.00400","20.95886","0.01927"
"17.08200","20.96538","0.01828"
"17.16000","20.97184","0.01858"
"17.23800","20.97835","0.01715"
"17.31600","20.98481","0.01693"
"17.39400","20.99127","0.01764"
"17.47200","20.99779","0.01824"
"17.55000","21.00430","0.01956"
"17.62800","21.01088","0.01943"
"17.70600","21.01734","0.01778"
"17.78400","21.02386","0.01731"
"17.86200","21.03031","0.01699"
"17.94000","21.03683","0.01833"
"18.01800","21.04334","0.01969"
"18.09600","21.04986","0.02074"
"18.17400","21.05638","0.01968"
"18.25200","21.06289","0.01835"
"18.33000","21.06941","0.01799"
"18.40800","21.07581","0.01858"
"18.48600","21.08233","0.01973"
"18.56400","21.08884","0.02095"
"18.64200","21.09536","0.02028"
"18.72000","21.10188","0.01985"
"18.79800","21.10834","0.01909"
"18.87600","21.11485","0.01799"
"18.95400","21.12131","0.01887"
"19.03200","21.12783","0.02038"
"19.11000","21.13434","0.02100"
"19.18800","21.14092","0.02098"
"19.26600","21.14738","0.02022"
"19.34400","21.15389","0.01814"
"19.42200","21.16029","0.01838"
"19.50000","21.16681","0.01995"
"19.57800","21.17327","0.02214"
"19.65600","21.17978","0.02148"
"19.73400","21.18636","0.02183"
"19.81200","21.19282","0.01970"
"19.89000","21.19940","0.01905"
"19.96800","21.20579","0.02013"
"20.04600","21.21231","0.02158"
"20.12400","21.21877","0.02236"
"20.20200","21.22534","0.02264"
"20.28000","21.23186","0.02077"
"20.35800","21.23838","0.02001"
"20.43600","21.24489","0.01942"
"20.51400","21.25135","0.02177"
"20.59200","21.25781","0.02290"
"20.67000","21.26427","0.02376"
"20.74800","21.27085","0.02312"
"20.82600","21.27742","0.02218"
"20.90400","21.28388","0.01989"
"20.98200","21.29033","0.02176"
"21.06000","21.29685","0.02259"
"21.13800","21.30331","0.02350"
"21.21600","21.30983","0.02497"
"21.29400","21.31634","0.02260"
"21.37200","21.32292","0.02167"
"21.45000","21.32938","0.02151"
"21.52800","21.33589","0.02207"
"21.60600","21.34235","0.02407"
"21.68400","21.34875","0.02447"
"21.76200","21.35533","0.02424"
"21.84000","21.36179","0.02316"
"21.91800","21.36836","0.02227"
"21.99600","21.37488","0.02269"
"22.07400","21.38140","0.02424"
"22.15200","21.38779","0.02571"
"22.23000","21.39431","0.02531"
"22.30800","21.40083","0.02449"
"22.38600","21.40734","0.02330"
"22.46400","21.41386","0.02255"
"22.54200","21.42038","0.02442"
"22.62000","21.42689","0.02525"
"22.69800","21.43335","0.02617"
"22.77600","21.43981","0.02579"
"22.85400","21.44633","0.02444"
"22.93200","21.45284","0.02464"
"23.01000","21.45936","0.02417"
"23.08800","21.46593","0.02613"
"23.16600","21.47233","0.02653"
"23.24400","21.47879","0.02689"
"23.32200","21.48531","0.02561"
"23.40000","21.49183","0.02540"
"23.47800","21.49834","0.02468"
"23.55600","21.50480","0.02599"
"23.63400","21.51138","0.02700"
"23.71200","21.51784","0.02670"
"23.79000","21.52429","0.02668"
"23.86800","21.53075","0.02576"
"23.94600","21.53733","0.02585"
"24.02400","21.54384","0.02545"
"24.10200","21.55036","0.02646"
"24.18000","21.55688","0.02754"
"24.25800","21.56333","0.02785"
"24.33600","21.56985","0.02648"
"24.41400","21.57631","0.02713"
"24.49200","21.58282","0.02766"
"24.57000","21.58934","0.02684"
"24.64800","21.59586","0.02740"
"24.72600","21.60238","0.02777"
"24.80400","21.60884","0.02752"
"24.88200","21.61535","0.02768"
"24.96000","21.62181","0.02795"
"25.03800","21.62833","0.02772"
"25.11600","21.63484","0.02873"
"25.19400","21.64136","0.02805"
"25.27200","21.64788","0.02779"
"25.35000","21.65439","0.02898"
"25.42800","21.66079","0.02857"
"25.50600","21.66731","0.02901"
"25.58400","21.67382","0.02921"
"25.66200","21.68040","0.02918"
"25.74000","21.68680","0.02959"
"25.81800","21.69337","0.02963"
"25.89600","21.69983","0.02982"
"25.97400","21.70629","0.02966"
"26.05200","21.71281","0.02986"
"26.13000","21.71939","0.02964"
"26.20800","21.72590","0.02998"
"26.28600","21.73236","0.03041"
"26.36400","21.73888","0.03056"
"26.44200","21.74533","0.03089"
"26.52000","21.75185","0.03056"
"26.59800","21.75831","0.03084"
"26.67600","21.76482","0.03083"
"26.75400","21.77134","0.03081"
"26.83200","21.77786","0.03125"
"26.91000","21.78438","0.03168"
"26.98800","21.79083","0.03170"
"27.06600","21.79735","0.03153"
"27.14400","21.80381","0.03193"
"27.22200","21.81038","0.03150"
"27.30000","21.81684","0.03214"
"27.37800","21.82342","0.03214"
"27.45600","21.82988","0.03223"
"27.53400","21.83640","0.03208"
"27.61200","21.84279","0.03225"
"27.69000","21.84931","0.03250"
"27.76800","21.85582","0.03298"
"27.84600","21.86234","0.03347"
"27.92400","21.86886","0.03333"
"28.00200","21.87537","0.03311"
"28.08000","21.88183","0.03390"
"28.15800","21.88829","0.03431"
"28.23600","21.89487","0.03437"
"28.31400","21.90133","0.03389"
"28.39200","21.90790","0.03442"
"28.47000","21.91436","0.03419"
"28.54800","21.92088","0.03480"
"28.62600","21.92733","0.03476"
"28.70400","21.93379","0.03501"
"28.78200","21.94031","0.03491"
"28.86000","21.94688","0.03470"
"28.93800","21.95340","0.03486"
"29.01600","21.95986","0.03556"
"29.09400","21.96643","0.03519"
"29.17200","21.97283","0.03552"
"29.25000","21.97929","0.03594"
"29.32800","21.98581","0.03563"
"29.40600","21.99238","0.03607"
"29.48400","21.99890","0.03639"
"29.56200","22.00536","0.03615"
"29.64000","22.01182","0.03695"
"29.71800","22.01833","0.03716"
"29.79600","22.02479","0.03694"
"29.87400","22.03131","0.03660"
"29.95200","22.03782","0.03737"
"30.03000","22.04434","0.03744"
"30.10800","22.05086","0.03732"
"30.18600","22.05732","0.03756"
"30.26400","22.06377","0.03792"
"30.34200","22.07029","0.03766"
"30.42000","22.07681","0.03800"
"30.49800","22.08332","0.03824"
"30.57600","22.08984","0.03825"
"30.65400","22.09636","0.03854"
"30.73200","22.10282","0.03888"
"30.81000","22.10933","0.03907"
"30.88800","22.11579","0.03880"
"30.96600","22.12230","0.03866"
"31.04400","22.12882","0.03902"
"31.12200","22.13540","0.03916"
"31.20000","22.14186","0.04002"
"31.27800","22.14838","0.04010"
"31.35600","22.15483","0.04043"
"31.43400","22.16129","0.03964"
"31.51200","22.16787","0.04002"
"31.59000","22.17432","0.04086"
"31.66800","22.18090","0.04029"
"31.74600","22.18736","0.04095"
"31.82400","22.19387","0.04077"
"31.90200","22.20027","0.04135"
"31.98000","22.20685","0.04124"
"32.05800","22.21337","0.04147"
"32.13600","22.21988","0.04183"
"32.21400","22.22634","0.04144"
"32.29200","22.23286","0.04161"
"32.37000","22.23938","0.04232"
"32.44800","22.24577","0.04223"
"32.52600","22.25229","0.04283"
"32.60400","22.25887","0.04250"
"32.68200","22.26538","0.04287"
"32.76000","22.27184","0.04287"
"32.83800","22.27835","0.04304"
"32.91600","22.28481","0.04361"
"32.99400","22.29133","0.04336"
"33.07200","22.29779","0.04332"
"33.15000","22.30430","0.04332"
"33.22800","22.31088","0.04402"
"33.30600","22.31734","0.04416"
"33.38400","22.32386","0.04462"
"33.46200","22.33031","0.04408"
"33.54000","22.33683","0.04440"
"33.61800","22.34329","0.04476"
"33.69600","22.34986","0.04524"
"33.77400","22.35632","0.04482"
"33.85200","22.36284","0.04536"
"33.93000","22.36930","0.04546"
"34.00800","22.37581","0.04560"
"34.08600","22.38227","0.04561"
"34.16400","22.38885","0.04609"
"34.24200","22.39537","0.04641"
"34.32000","22.40188","0.04609"
"34.39800","22.40834","0.04662"
"34.47600","22.41480","0.04685"
"34.55400","22.42131","0.04660"
"34.63200","22.42777","0.04724"
"34.71000","22.43435","0.04712"
"34.78800","22.44087","0.04760"
"34.86600","22.44738","0.04766"
"34.94400","22.45384","0.04749"
"35.02200","22.46030","0.04767"
"35.10000","22.46681","0.04825"
"35.17800","22.47327","0.04810"
"35.25600","22.47985","0.04864"
"35.33400","22.48637","0.04856"
"35.41200","22.49288","0.04860"
"35.49000","22.49934","0.04864"
"35.56800","22.50591","0.04906"
"35.64600","22.51231","0.04936"
"35.72400","22.51883","0.04908"
"35.80200","22.52535","0.04946"
"35.88000","22.53186","0.04943"
"35.95800","22.53832","0.04964"
"36.03600","22.54484","0.05044"
"36.11400","22.55136","0.05027"
"36.19200","22.55781","0.05007"
"36.27000","22.56433","0.05035"
"36.34800","22.57085","0.05021"
"36.42600","22.57737","0.05050"
"36.50400","22.58382","0.05074"
"36.58200","22.59034","0.05078"
"36.66000","22.59680","0.05093"
"36.73800","22.60331","0.05123"
"36.81600","22.60977","0.05127"
"36.89400","22.61635","0.05152"
"36.97200","22.62286","0.05143"
"37.05000","22.62932","0.05142"
"37.12800","22.63590","0.05163"
"37.20600","22.64235","0.05184"
"37.28400","22.64881","0.05198"
"37.36200","22.65527","0.05192"
"37.44000","22.66185","0.05204"
"37.51800","22.66837","0.05232"
"37.59600","22.67488","0.05218"
"37.67400","22.68134","0.05225"
"37.75200","22.68786","0.05237"
"37.83000","22.69431","0.05253"
"37.90800","22.70083","0.05257"
"37.98600","22.70735","0.05267"
"38.06400","22.71392","0.05304"
"38.14200","22.72038","0.05281"
"38.22000","22.72684","0.05304"
"38.29800","22.73336","0.05318"
"38.37600","22.73981","0.05318"
"38.45400","22.74627","0.05329"
"38.53200","22.75285","0.05337"
"38.61000","22.75937","0.05310"
"38.68800","22.76588","0.05346"
"38.76600","22.77234","0.05367"
"38.84400","22.77886","0.05361"
"38.92200","22.78525","0.05365"
"39.00000","22.79183","0.05397"
"39.07800","22.79829","0.05389"
"39.15600","22.80486","0.05407"
"39.23400","22.81132","0.05402"
"39.31200","22.81784","0.05400"
"39.39000","22.82430","0.05366"
"39.46800","22.83075","0.05415"
"39.54600","22.83733","0.05402"
"39.62400","22.84385","0.05412"
"39.70200","22.85042","0.05420"
"39.78000","22.85688","0.05424"
"39.85800","22.86340","0.05456"
"39.93600","22.86979","0.05436"
"40.01400","22.87637","0.05438"
"40.09200","22.88283","0.05447"
"40.17000","22.88935","0.05457"
"40.24800","22.89586","0.05464"
"40.32600","22.90238","0.05477"
"40.40400","22.90884","0.05457"
"40.48200","22.91536","0.05512"
"40.56000","22.92181","0.05519"
"40.63800","22.92833","0.05517"
"40.71600","22.93484","0.05505"
"40.79400","22.94131","0.05515"
"40.87200","22.94788","0.05527"
"40.95000","22.95428","0.05499"
"41.02800","22.96079","0.05532"
"41.10600","22.96725","0.05550"
"41.18400","22.97383","0.05576"
"41.26200","22.98035","0.05571"
"41.34000","22.98686","0.05568"
"41.41800","22.99332","0.05582"
"41.49600","22.99984","0.05558"
"41.57400","23.00630","0.05573"
"41.65200","23.01281","0.05578"
"41.73000","23.01933","0.05588"
"41.80800","23.02584","0.05601"
"41.88600","23.03236","0.05595"
"41.96400","23.03888","0.05622"
"42.04200","23.04534","0.05614"
"42.12000","23.05186","0.05605"
"42.19800","23.05831","0.05598"
"42.27600","23.06483","0.05627"
"42.35400","23.07141","0.05634"
"42.43200","23.07786","0.05632"
"42.51000","23.08432","0.05646"
"42.58800","23.09090","0.05647"
"42.66600","23.09730","0.05649"
"42.74400","23.10381","0.05665"
"42.82200","23.11033","0.05647"
"42.90000","23.11684","0.05666"
"42.97800","23.12336","0.05647"
"43.05600","23.12982","0.05661"
"43.13400","23.13628","0.05671"
"43.21200","23.14280","0.05668"
"43.29000","23.14931","0.05670"
"43.36800","23.15583","0.05671"
"43.44600","23.16241","0.05670"
"43.52400","23.16886","0.05684"
"43.60200","23.17532","0.05675"
"43.68000","23.18184","0.05679"
"43.75800","23.18835","0.05684"
"43.83600","23.19481","0.05684"
"43.91400","23.20133","0.05705"
"43.99200","23.20785","0.05699"
"44.07000","23.21436","0.05700"
"44.14800","23.22088","0.05703"
"44.22600","23.22733","0.05691"
"44.30400","23.23385","0.05707"
"44.38200","23.24031","0.05708"
"44.46000","23.24689","0.05715"
"44.53800","23.25335","0.05716"
"44.61600","23.25980","0.05715"
"44.69400","23.26632","0.05722"
"44.77200","23.27284","0.05714"
"44.85000","23.27929","0.05713"
"44.92800","23.28581","0.05722"
"45.00600","23.29239","0.05730"
"45.08400","23.29885","0.05727"
"45.16200","23.30536","0.05735"
"45.24000","23.31182","0.05731"
"45.31800","23.31828","0.05737"
"45.39600","23.32479","0.05736"
"45.47400","23.33131","0.05739"
"45.55200","23.33783","0.05738"
"45.63000","23.34435","0.05743"
"45.70800","23.35086","0.05736"
"45.78600","23.35738","0.05753"
"45.86400","23.36384","0.05742"
"45.94200","23.37029","0.05751"
"46.02000","23.37687","0.05755"
"46.09800","23.38339","0.05753"
"46.17600","23.38991","0.05748"
"46.25400","23.39636","0.05743"
"46.33200","23.40288","0.05754"
"46.41000","23.40933","0.05750"
"46.48800","23.41579","0.05756"
"46.56600","23.42237","0.05746"
"46.64400","23.42889","0.05756"
"46.72200","23.43540","0.05765"
"46.80000","23.44192","0.05763"
"46.87800","23.44838","0.05759"
"46.95600","23.45484","0.05763"
"47.03400","23.46135","0.05769"
"47.11200","23.46781","0.05764"
"47.19000","23.47439","0.05771"
"47.26800","23.48084","0.05773"
"47.34600","23.48736","0.05775"
"47.42400","23.49382","0.05778"
"47.50200","23.50028","0.05776"
"47.58000","23.50685","0.05770"
"47.65800","23.51331","0.05774"
"47.73600","23.51989","0.05774"
"47.81400","23.52634","0.05777"
"47.89200","23.53292","0.05778"
"47.97000","23.53932","0.05779"
"48.04800","23.54584","0.05788"
"48.12600","23.55229","0.05782"
"48.20400","23.55887","0.05791"
"48.28200","23.56539","0.05785"
"48.36000","23.57185","0.05784"
"48.43800","23.57836","0.05787"
"48.51600","23.58482","0.05785"
"48.59400","23.59133","0.05793"
"48.67200","23.59779","0.05805"
"48.75000","23.60431","0.05815"
"48.82800","23.61083","0.05792"
"48.90600","23.61734","0.05800"
"48.98400","23.62386","0.05797"
"49.06200","23.63032","0.05819"
"49.14000","23.63678","0.05810"
"49.21800","23.64329","0.05819"
"49.29600","23.64981","0.05817"
"49.37400","23.65633","0.05815"
"49.45200","23.66284","0.05830"
"49.53000","23.66936","0.05826"
"49.60800","23.67582","0.05825"
"49.68600","23.68228","0.05837"
"49.76400","23.68885","0.05823"
"49.84200","23.69531","0.05837"
"49.92000","23.70189","0.05853"
"49.99800","23.70834","0.05847"
"50.07600","23.71486","0.05849"
"50.15400","23.72138","0.05858"
"50.23200","23.72784","0.05849"
"50.31000","23.73435","0.05855"
"50.38800","23.74087","0.01123"
"50.46600","23.74739","0.00811"
"50.54400","23.75384","0.01317"
"50.62200","23.76036","0.03906"
"50.70000","23.76688","0.02832"
"50.77800","23.77333","0.00973"
"50.85600","23.77985","0.00306"
"50.93400","23.78631","0.00300"
"51.01200","23.79283","0.00572"
"51.09000","23.79934","0.02084"
"51.16800","23.80586","0.03172"
"51.24600","23.81232","0.02017"
"51.32400","23.81878","0.00837"
"51.40200","23.82529","0.00358"
"51.48000","23.83187","0.00647"
"51.55800","23.83833","0.01484"
"51.63600","23.84484","0.02675"
"51.71400","23.85130","0.02314"
"51.79200","23.85782","0.01245"
"51.87000","23.86427","0.00576"
"51.94800","23.87079","0.00685"
"52.02600","23.87737","0.01517"
"52.10400","23.88383","0.02267"
"52.18200","23.89034","0.02181"
"52.26000","23.89680","0.01445"
"52.33800","23.90338","0.00660"
"52.41600","23.90977","0.00955"
"52.49400","23.91635","0.01620"
"52.57200","23.92287","0.02208"
"52.65000","23.92938","0.02021"
"52.72800","23.93584","0.01287"
"52.80600","23.94230","0.00966"
"52.88400","23.94882","0.01126"
"52.96200","23.95533","0.01732"
"53.04000","23.96185","0.02084"
"53.11800","23.96837","0.01868"
"53.19600","23.97482","0.01208"
"53.27400","23.98140","0.00963"
"53.35200","23.98786","0.01329"
"53.43000","23.99432","0.01915"
"53.50800","24.00084","0.02046"
"53.58600","24.00735","0.01655"
"53.66400","24.01387","0.01149"
"53.74200","24.02039","0.01151"
"53.82000","24.02684","0.01525"
"53.89800","24.03336","0.01914"
"53.97600","24.03982","0.01906"
"54.05400","24.04634","0.01570"
"54.13200","24.05279","0.01248"
"54.21000","24.05937","0.01375"
"54.28800","24.06582","0.01732"
"54.36600","24.07240","0.01855"
"54.44400","24.07880","0.01784"
"54.52200","24.08532","0.01498"
"54.60000","24.09184","0.01264"
"54.67800","24.09835","0.01435"
"54.75600","24.10487","0.01774"
"54.83400","24.11139","0.01820"
"54.91200","24.11790","0.01661"
"54.99000","24.12430","0.01548"
"55.06800","24.13082","0.01387"
"55.14600","24.13727","0.01534"
"55.22400","24.14385","0.01774"
"55.30200","24.15031","0.01885"
"55.38000","24.15689","0.01642"
"55.45800","24.16334","0.01468"
"55.53600","24.16980","0.01545"
"55.61400","24.17632","0.01835"
"55.69200","24.18283","0.01808"
"55.77000","24.18935","0.01690"
"55.84800","24.19587","0.01529"
"55.92600","24.20238","0.01433"
"56.00400","24.20884","0.01676"
"56.08200","24.21536","0.01886"
"56.16000","24.22176","0.01929"
"56.23800","24.22833","0.01752"
"56.31600","24.23485","0.01450"
"56.39400","24.24137","0.01720"
"56.47200","24.24788","0.01824"
"56.55000","24.25434","0.01830"
"56.62800","24.26086","0.01835"
"56.70600","24.26731","0.01661"
"56.78400","24.27383","0.01623"
"56.86200","24.28035","0.01678"
"56.94000","24.28687","0.01939"
"57.01800","24.29338","0.01838"
"57.09600","24.29984","0.01662"
"57.17400","24.30630","0.01624"
"57.25200","24.31282","0.01803"
"57.33000","24.31927","0.01885"
"57.40800","24.32585","0.01923"
"57.48600","24.33231","0.01972"
"57.56400","24.33888","0.01724"
"57.64200","24.34534","0.01765"
"57.72000","24.35180","0.01905"
"57.79800","24.35831","0.01915"
"57.87600","24.36477","0.01924"
"57.95400","24.37135","0.01859"
"58.03200","24.37781","0.01807"
"58.11000","24.38433","0.01937"
"58.18800","24.39078","0.01826"
"58.26600","24.39724","0.02021"
"58.34400","24.40376","0.01963"
"58.42200","24.41033","0.01832"
"58.50000","24.41691","0.01834"
"58.57800","24.42337","0.01897"
"58.65600","24.42988","0.01908"
"58.73400","24.43640","0.01925"
"58.81200","24.44286","0.01852"
"58.89000","24.44931","0.01852"
"58.96800","24.45583","0.01925"
"59.04600","24.46235","0.02133"
"59.12400","24.46886","0.02094"
"59.20200","24.47538","0.02064"
"59.28000","24.48184","0.01977"
"59.35800","24.48836","0.02050"
"59.43600","24.49482","0.02118"
"59.51400","24.50139","0.02106"
"59.59200","24.50785","0.02060"
"59.67000","24.51437","0.02086"
"59.74800","24.52082","0.02044"
"59.82600","24.52734","0.02128"
"59.90400","24.53380","0.02098"
"59.98200","24.54031","0.02059"
"60.06000","24.54689","0.02072"
"60.13800","24.55335","0.02072"
"60.21600","24.55987","0.02129"
"60.29400","24.56632","0.02252"
"60.37200","24.57290","0.02282"
"60.45000","24.57930","0.02208"
"60.52800","24.58582","0.02214"
"60.60600","24.59233","0.02171"
"60.68400","24.59885","0.02280"
"60.76200","24.60537","0.02160"
"60.84000","24.61182","0.02150"
"60.91800","24.61834","0.02161"
"60.99600","24.62480","0.02181"
"61.07400","24.63138","0.02295"
"61.15200","24.63783","0.02209"
"61.23000","24.64435","0.02359"
"61.30800","24.65086","0.02384"
"61.38600","24.65738","0.02365"
"61.46400","24.66378","0.02336"
"61.54200","24.67030","0.02383"
"61.62000","24.67682","0.02345"
"61.69800","24.68333","0.02351"
"61.77600","24.68985","0.02279"
"61.85400","24.69637","0.02292"
"61.93200","24.70283","0.02348"
"62.01000","24.70934","0.02373"
"62.08800","24.71580","0.02431"
"62.16600","24.72231","0.02448"
"62.24400","24.72889","0.02429"
"62.32200","24.73535","0.02464"
"62.40000","24.74187","0.02497"
"62.47800","24.74832","0.02544"
"62.55600","24.75484","0.02449"
"62.63400","24.76130","0.02437"
"62.71200","24.76781","0.02514"
"62.79000","24.77433","0.02495"
"62.86800","24.78085","0.02480"
"62.94600","24.78736","0.02552"
"63.02400","24.79382","0.02558"
"63.10200","24.80034","0.02579"
"63.18000","24.80680","0.02689"
"63.25800","24.81337","0.02646"
"63.33600","24.81983","0.02594"
"63.41400","24.82635","0.02539"
"63.49200","24.83286","0.02620"
"63.57000","24.83932","0.02612"
"63.64800","24.84578","0.02584"
"63.72600","24.85230","0.02518"
"63.80400","24.85887","0.02601"
"63.88200","24.86539","0.02646"
"63.96000","24.87191","0.02671"
"64.03800","24.87836","0.02737"
"64.11600","24.88488","0.02751"
"64.19400","24.89128","0.02776"
"64.27200","24.89786","0.02805"
"64.35000","24.90431","0.02762"
"64.42800","24.91089","0.02705"
"64.50600","24.91735","0.02674"
"64.58400","24.92387","0.02745"
"64.66200","24.93032","0.02711"
"64.74000","24.93678","0.02773"
"64.81800","24.94330","0.02746"
"64.89600","24.94982","0.02823"
"64.97400","24.95639","0.02770"
"65.05200","24.96291","0.02874"
"65.13000","24.96943","0.02842"
"65.20800","24.97582","0.02817"
"65.28600","24.98228","0.02813"
"65.36400","24.98880","0.02809"
"65.44200","24.99537","0.02780"
"65.52000","25.00189","0.02768"
"65.59800","25.00841","0.02861"
"65.67600","25.01487","0.02926"
"65.75400","25.02132","0.02948"
"65.83200","25.02784","0.02944"
"65.91000","25.03430","0.02913"
"65.98800","25.04082","0.02895"
"66.06600","25.04733","0.02998"
"66.14400","25.05385","0.02955"
"66.22200","25.06036","0.02897"
"66.30000","25.06682","0.02903"
"66.37800","25.07328","0.02949"
"66.45600","25.07985","0.02916"
"66.53400","25.08631","0.02939"
"66.61200","25.09283","0.02989"
"66.69000","25.09941","0.03063"
"66.76800","25.10587","0.03057"
"66.84600","25.11232","0.03066"
"66.92400","25.11878","0.03078"
"67.00200","25.12535","0.03041"
"67.08000","25.13181","0.03064"
"67.15800","25.13833","0.03076"
"67.23600","25.14485","0.02988"
"67.31400","25.15136","0.03012"
"67.39200","25.15788","0.03041"
"67.47000","25.16428","0.03039"
"67.54800","25.17085","0.03113"
"67.62600","25.17737","0.02887"
"67.70400","25.18389","0.02724"
"67.78200","25.19035","0.02311"
"67.86000","25.19687","0.02555"
"67.93800","25.20332","0.02227"
"68.01600","25.20984","0.02615"
"68.09400","25.21636","0.02613"
"68.17200","25.22281","0.02411"
"68.25000","25.22939","0.02570"
"68.32800","25.23585","0.02241"
"68.40600","25.24236","0.02557"
"68.48400","25.24882","0.02643"
"68.56200","25.25534","0.02535"
"68.64000","25.26185","0.02664"
"68.71800","25.26837","0.02353"
"68.79600","25.27483","0.02406"
"68.87400","25.28135","0.02332"
"68.95200","25.28786","0.02473"
"69.03000","25.29432","0.02585"
"69.10800","25.30084","0.02371"
"69.18600","25.30735","0.02454"
"69.26400","25.31387","0.02454"
"69.34200","25.32033","0.02512"
"69.42000","25.32691","0.02544"
"69.49800","25.33330","0.02594"
"69.57600","25.33988","0.02460"
"69.65400","25.34628","0.02473"
"69.73200","25.35285","0.02609"
"69.81000","25.35937","0.02620"
"69.88800","25.36589","0.02517"
"69.96600","25.37240","0.02581"
"70.04400","25.37886","0.02595"
"70.12200","25.38532","0.02540"
"70.20000","25.39184","0.02586"
"70.27800","25.39836","0.02572"
"70.35600","25.40487","0.02589"
"70.43400","25.41139","0.02544"
"70.51200","25.41784","0.02522"
"70.59000","25.42430","0.02579"
"70.66800","25.43082","0.02655"
"70.74600","25.43734","0.02583"
"70.82400","25.44391","0.02650"
"70.90200","25.45037","0.02598"
"70.98000","25.45689","0.02557"
"71.05800","25.46335","0.02581"
"71.13600","25.46986","0.02617"
"71.21400","25.47626","0.02638"
"71.29200","25.48284","0.02537"
"71.37000","25.48935","0.02621"
"71.44800","25.49587","0.02570"
"71.52600","25.50239","0.02620"
"71.60400","25.50891","0.02681"
"71.68200","25.51530","0.02724"
"71.76000","25.52176","0.02646"
"71.83800","25.52840","0.02625"
"71.91600","25.53485","0.02718"
"71.99400","25.54143","0.02749"
"72.07200","25.54783","0.02724"
"72.15000","25.55440","0.02794"
"72.22800","25.56080","0.02723"
"72.30600","25.56726","0.02733"
"72.38400","25.57384","0.02689"
"72.46200","25.58041","0.02817"
"72.54000","25.58687","0.02808"
"72.61800","25.59339","0.02766"
"72.69600","25.59984","0.02754"
"72.77400","25.60630","0.02748"
"72.85200","25.61282","0.02691"
"72.93000","25.61928","0.02773"
"73.00800","25.62591","0.02750"
"73.08600","25.63237","0.02792"
"73.16400","25.63889","0.02760"
"73.24200","25.64529","0.02785"
"73.32000","25.65180","0.02732"
"73.39800","25.65826","0.02855"
"73.47600","25.66484","0.02823"
"73.55400","25.67129","0.02827"
"73.63200","25.67787","0.02690"
"73.71000","25.68439","0.02844"
"73.78800","25.69085","0.02865"
"73.86600","25.69730","0.02877"
"73.94400","25.70382","0.02885"
"74.02200","25.71028","0.02900"
"74.10000","25.71685","0.02934"
"74.17800","25.72337","0.02876"
"74.25600","25.72989","0.02890"
"74.33400","25.73635","0.02896"
"74.41200","25.74280","0.02943"
"74.49000","25.74932","0.03001"
"74.56800","25.75584","0.02944"
"74.64600","25.76229","0.02968"
"74.72400","25.76887","0.02893"
"74.80200","25.77533","0.02982"
"74.88000","25.78184","0.02939"
"74.95800","25.78824","0.03008"
"75.03600","25.79482","0.03034"
"75.11400","25.80133","0.03007"
"75.19200","25.80791","0.02967"
"75.27000","25.81437","0.03011"
"75.34800","25.82089","0.02973"
"75.42600","25.82734","0.02950"
"75.50400","25.83380","0.03011"
"75.58200","25.84032","0.03028"
"75.66000","25.84684","0.03009"
"75.73800","25.85341","0.03002"
"75.81600","25.85981","0.03024"
"75.89400","25.86639","0.03075"
"75.97200","25.87284","0.03094"
"76.05000","25.87936","0.03026"
"76.12800","25.88582","0.03128"
"76.20600","25.89233","0.03046"
"76.28400","25.89891","0.03149"
"76.36200","25.90537","0.03167"
"76.44000","25.91189","0.03178"
"76.51800","25.91829","0.03115"
"76.59600","25.92480","0.03194"
"76.67400","25.93132","0.03122"
"76.75200","25.93784","0.03132"
"76.83000","25.94429","0.03232"
"76.90800","25.95087","0.03207"
"76.98600","25.95733","0.03137"
"77.06400","25.96384","0.03227"
"77.14200","25.97030","0.03179"
"77.22000","25.97688","0.03152"
"77.29800","25.98340","0.03219"
"77.37600","25.98985","0.03267"
"77.45400","25.99637","0.03221"
"77.53200","26.00283","0.03144"
"77.61000","26.00934","0.03233"
"77.68800","26.01580","0.03219"
"77.76600","26.02232","0.03289"
"77.84400","26.02884","0.03376"
"77.92200","26.03535","0.03262"
"78.00000","26.04187","0.03207"
"78.07800","26.04833","0.03248"
"78.15600","26.05484","0.03331"
"78.23400","26.06136","0.03312"
"78.31200","26.06788","0.03313"
"78.39000","26.07434","0.03356"
"78.46800","26.08091","0.03330"
"78.54600","26.08737","0.03366"
"78.62400","26.09389","0.03447"
"78.70200","26.10028","0.03390"
"78.78000","26.10680","0.03406"
"78.85800","26.11332","0.03378"
"78.93600","26.11983","0.03411"
"79.01400","26.12635","0.03390"
"79.09200","26.13287","0.03410"
"79.17000","26.13939","0.03522"
"79.24800","26.14584","0.03504"
"79.32600","26.15236","0.03434"
"79.40400","26.15888","0.03448"
"79.48200","26.16540","0.03491"
"79.56000","26.17185","0.03465"
"79.63800","26.17837","0.03495"
"79.71600","26.18483","0.03548"
"79.79400","26.19128","0.03485"
"79.87200","26.19780","0.03436"
"79.95000","26.20432","0.03418"
"80.02800","26.21089","0.03530"
"80.10600","26.21735","0.03562"
"80.18400","26.22393","0.03564"
"80.26200","26.23033","0.03527"
"80.34000","26.23678","0.03535"
"80.41800","26.24330","0.03577"
"80.49600","26.24988","0.03556"
"80.57400","26.25640","0.03579"
"80.65200","26.26285","0.03614"
"80.73000","26.26937","0.03562"
"80.80800","26.27583","0.03601"
"80.88600","26.28234","0.03589"
"80.96400","26.28874","0.03659"
"81.04200","26.29538","0.03688"
"81.12000","26.30183","0.03686"
"81.19800","26.30835","0.03640"
"81.27600","26.31487","0.03652"
"81.35400","26.32133","0.03630"
"81.43200","26.32784","0.03726"
"81.51000","26.33430","0.03766"
"81.58800","26.34082","0.03781"
"81.66600","26.34739","0.03689"
"81.74400","26.35385","0.03735"
"81.82200","26.36037","0.03779"
"81.90000","26.36683","0.03787"
"81.97800","26.37328","0.03807"
"82.05600","26.37980","0.03759"
"82.13400","26.38632","0.03798"
"82.21200","26.39290","0.03766"
"82.29000","26.39935","0.03826"
"82.36800","26.40587","0.03840"
"82.44600","26.41233","0.03887"
"82.52400","26.41878","0.03803"
"82.60200","26.42536","0.03838"
"82.68000","26.43188","0.03834"
"82.75800","26.43839","0.03847"
"82.83600","26.44491","0.03914"
"82.91400","26.45137","0.03899"
"82.99200","26.45782","0.03934"
"83.07000","26.46434","0.03899"
"83.14800","26.47080","0.03921"
"83.22600","26.47732","0.03907"
"83.30400","26.48383","0.03960"
"83.38200","26.49035","0.03994"
"83.46000","26.49687","0.03982"
"83.53800","26.50333","0.03908"
"83.61600","26.50984","0.03951"
"83.69400","26.51630","0.03955"
"83.77200","26.52287","0.04054"
"83.85000","26.52934","0.03952"
"83.92800","26.53591","0.04024"
"84.00600","26.54231","0.03991"
"84.08400","26.54882","0.04028"
"84.16200","26.55528","0.04086"
"84.24000","26.56180","0.04009"
"84.31800","26.56838","0.04072"
"84.39600","26.57483","0.04069"
"84.47400","26.58135","0.04109"
"84.55200","26.58781","0.04090"
"84.63000","26.59433","0.04090"
"84.70800","26.60078","0.04105"
"84.78600","26.60736","0.04087"
"84.86400","26.61387","0.04107"
"84.94200","26.62039","0.04131"
"85.02000","26.62685","0.04143"
"85.09800","26.63337","0.04147"
"85.17600","26.63982","0.04103"
"85.25400","26.64634","0.04120"
"85.33200","26.65286","0.04179"
"85.41000","26.65938","0.04224"
"85.48800","26.66589","0.04188"
"85.56600","26.67241","0.04204"
"85.64400","26.67887","0.04216"
"85.72200","26.68533","0.04227"
"85.80000","26.69184","0.04284"
"85.87800","26.69836","0.04252"
"85.95600","26.70487","0.04280"
"86.03400","26.71133","0.04213"
"86.11200","26.71785","0.04243"
"86.19000","26.72437","0.04279"
"86.26800","26.73082","0.04285"
"86.34600","26.73734","0.04309"
"86.42400","26.74380","0.04276"
"86.50200","26.75038","0.04307"
"86.58000","26.75689","0.04306"
"86.65800","26.76335","0.04369"
"86.73600","26.76981","0.04367"
"86.81400","26.77633","0.04349"
"86.89200","26.78284","0.04338"
"86.97000","26.78936","0.04351"
"87.04800","26.79588","0.04366"
"87.12600","26.80239","0.04399"
"87.20400","26.80885","0.04425"
"87.28200","26.81531","0.04379"
"87.36000","26.82176","0.04425"
"87.43800","26.82834","0.04392"
"87.51600","26.83486","0.04434"
"87.59400","26.84131","0.04396"
"87.67200","26.84783","0.04428"
"87.75000","26.85435","0.04454"
"87.82800","26.86081","0.04477"
"87.90600","26.86732","0.04479"
"87.98400","26.87378","0.04465"
"88.06200","26.88042","0.04496"
"88.14000","26.88682","0.04459"
"88.21800","26.89339","0.04527"
"88.29600","26.89979","0.04498"
"88.37400","26.90631","0.04538"
"88.45200","26.91276","0.04523"
"88.53000","26.91934","0.04546"
"88.60800","26.92586","0.04519"
"88.68600","26.93237","0.04521"
"88.76400","26.93889","0.04596"
"88.84200","26.94535","0.04590"
"88.92000","26.95181","0.04579"
"88.99800","26.95827","0.04593"
"89.07600","26.96484","0.04563"
"89.15400","26.97136","0.04623"
"89.23200","26.97787","0.04624"
"89.31000","26.98433","0.04607"
"89.38800","26.99085","0.04631"
"89.46600","26.99731","0.04612"
"89.54400","27.00376","0.04680"
"89.62200","27.01034","0.04688"
"89.70000","27.01686","0.04664"
"89.77800","27.02337","0.04680"
"89.85600","27.02989","0.04679"
"89.93400","27.03641","0.04695"
"90.01200","27.04281","0.04701"
"90.09000","27.04932","0.04721"
"90.16800","27.05578","0.04734"
"90.24600","27.06242","0.04724"
"90.32400","27.06887","0.04718"
"90.40200","27.07539","0.04752"
"90.48000","27.08185","0.04774"
"90.55800","27.08831","0.04768"
"90.63600","27.09482","0.04799"
"90.71400","27.10134","0.04779"
"90.79200","27.10786","0.04794"
"90.87000","27.11437","0.04826"
"90.94800","27.12089","0.04816"
"91.02600","27.12735","0.04810"
"91.10400","27.13387","0.04860"
"91.18200","27.14026","0.04847"
"91.26000","27.14684","0.04819"
"91.33800","27.15336","0.04816"
"91.41600","27.15987","0.04845"
"91.49400","27.16639","0.04862"
"91.57200","27.17285","0.04858"
"91.65000","27.17931","0.04911"
"91.72800","27.18576","0.04856"
"91.80600","27.19234","0.04925"
"91.88400","27.19880","0.04877"
"91.96200","27.20537","0.04918"
"92.04000","27.21183","0.04923"
"92.11800","27.21835","0.04911"
"92.19600","27.22481","0.04954"
"92.27400","27.23132","0.04953"
"92.35200","27.23784","0.04992"
"92.43000","27.24430","0.04932"
"92.50800","27.25087","0.04983"
"92.58600","27.25733","0.04959"
"92.66400","27.26385","0.05016"
"92.74200","27.27024","0.05000"
"92.82000","27.27682","0.04997"
"92.89800","27.28334","0.05022"
"92.97600","27.28986","0.05007"
"93.05400","27.29638","0.05042"
"93.13200","27.30289","0.05064"
"93.21000","27.30935","0.05066"
"93.28800","27.31581","0.05035"
"93.36600","27.32232","0.05076"
"93.44400","27.32884","0.05069"
"93.52200","27.33536","0.05081"
"93.60000","27.34187","0.05110"
"93.67800","27.34839","0.05092"
"93.75600","27.35479","0.05086"
"93.83400","27.36131","0.05162"
"93.91200","27.36782","0.05127"
"93.99000","27.37434","0.05133"
"94.06800","27.38086","0.05140"
"94.14600","27.38737","0.05139"
"94.22400","27.39389","0.05135"
"94.30200","27.40035","0.05190"
"94.38000","27.40681","0.05172"
"94.45800","27.41332","0.05167"
"94.53600","27.41984","0.05172"
"94.61400","27.42636","0.05185"
"94.69200","27.43281","0.05199"
"94.77000","27.43933","0.05186"
"94.84800","27.44579","0.05202"
"94.92600","27.45230","0.05198"
"95.00400","27.45882","0.05188"
"95.08200","27.46534","0.05242"
"95.16000","27.47186","0.05249"
"95.23800","27.47837","0.05235"
"95.31600","27.48483","0.05227"
"95.39400","27.49135","0.05241"
"95.47200","27.49780","0.05249"
"95.55000","27.50432","0.05233"
"95.62800","27.51084","0.05269"
"95.70600","27.51736","0.05243"
"95.78400","27.52387","0.05279"
"95.86200","27.53027","0.05294"
"95.94000","27.53679","0.05262"
"96.01800","27.54330","0.05260"
"96.09600","27.54988","0.05285"
"96.17400","27.55634","0.05294"
"96.25200","27.56292","0.05303"
"96.33000","27.56937","0.05311"
"96.40800","27.57583","0.05321"
"96.48600","27.58229","0.05306"
"96.56400","27.58880","0.05323"
"96.64200","27.59538","0.05360"
"96.72000","27.60184","0.05345"
"96.79800","27.60835","0.05333"
"96.87600","27.61487","0.05335"
"96.95400","27.62133","0.05327"
"97.03200","27.62779","0.05359"
"97.11000","27.63431","0.05345"
"97.18800","27.64082","0.05373"
"97.26600","27.64734","0.05375"
"97.34400","27.65385","0.05388"
"97.42200","27.66037","0.05401"
"97.50000","27.66683","0.05404"
"97.57800","27.67328","0.05407"
"97.65600","27.67986","0.05410"
"97.73400","27.68638","0.05425"
"97.81200","27.69290","0.05409"
"97.89000","27.69942","0.05427"
"97.96800","27.70587","0.05410"
"98.04600","27.71233","0.05411"
"98.12400","27.71879","0.05432"
"98.20200","27.72531","0.05429"
"98.28000","27.73188","0.05462"
"98.35800","27.73834","0.05456"
"98.43600","27.74485","0.05455"
"98.51400","27.75131","0.05436"
"98.59200","27.75783","0.05453"
"98.67000","27.76435","0.05466"
"98.74800","27.77086","0.05470"
"98.82600","27.77738","0.05490"
"98.90400","27.78390","0.05475"
"98.98200","27.79041","0.05487"
"99.06000","27.79681","0.05485"
"99.13800","27.80333","0.05496"
"99.21600","27.80979","0.05499"
"99.29400","27.81636","0.05514"
"99.37200","27.82282","0.05500"
"99.45000","27.82934","0.05501"
"99.52800","27.83591","0.05509"
"99.60600","27.84231","0.05511"
"99.68400","27.84883","0.05523"
"99.76200","27.85528","0.05514"
"99.84000","27.86186","0.05529"
"99.91800","27.86832","0.05507"
"99.99600","27.87490","0.05542"
"100.07400","27.88136","0.05539"
"100.15200","27.88787","0.05540"
"100.23000","27.89433","0.05547"
"100.30800","27.90079","0.05552"
"100.38600","27.90730","0.05552"
"100.46400","27.91382","0.05576"
"100.54200","27.92040","0.05568"
"100.62000","27.92685","0.05563"
"100.69800","27.93337","0.05568"
"100.77600","27.93983","0.05576"
"100.85400","27.94635","0.05570"
"100.93200","27.95286","0.05563"
"101.01000","27.95938","0.05579"
"101.08800","27.96584","0.05567"
"101.16600","27.97235","0.05580"
"101.24400","27.97881","0.05592"
"101.32200","27.98527","0.05574"
"101.40000","27.99185","0.05589"
"101.47800","27.99836","0.05595"
"101.55600","28.00494","0.05598"
"101.63400","28.01134","0.05583"
"101.71200","28.01791","0.05607"
"101.79000","28.02437","0.05596"
"101.86800","28.03083","0.05602"
"101.94600","28.03729","0.05598"
"102.02400","28.04387","0.05606"
"102.10200","28.05038","0.05602"
"102.18000","28.05684","0.05622"
"102.25800","28.06329","0.05594"
"102.33600","28.06981","0.05610"
"102.41400","28.07627","0.05620"
"102.49200","28.08278","0.00967"
"102.57000","28.08930","0.00614"
"102.64800","28.09588","0.00317"
"102.72600","28.10234","0.00300"
"102.80400","28.10885","0.00328"
"102.88200","28.11537","0.00310"
"102.96000","28.12183","0.00334"
"103.03800","28.12835","0.00317"
"103.11600","28.13486","0.00215"
"103.19400","28.14138","0.00250"
"103.27200","28.14790","0.00214"
"103.35000","28.15429","0.00178"
"103.42800","28.16087","0.00213"
"103.50600","28.16727","0.00232"
"103.58400","28.17385","0.00228"
"103.66200","28.18030","0.00117"
"103.74000","28.18688","0.00123"
"103.81800","28.19340","0.00190"
"103.89600","28.19985","0.00226"
"103.97400","28.20631","0.00223"
"104.05200","28.21283","0.00226"
"104.13000","28.21934","0.00310"
"104.20800","28.22586","0.00213"
"104.28600","28.23238","0.00258"
"104.36400","28.23884","0.00239"
"104.44200","28.24541","0.00300"
"104.52000","28.25175","0.00228"
"104.59800","28.25827","0.00238"
"104.67600","28.26478","0.00270"
"104.75400","28.27136","0.00259"
"104.83200","28.27782","0.00263"
"104.91000","28.28440","0.00286"
"104.98800","28.29091","0.00230"
"105.06600","28.29737","0.00164"
"105.14400","28.30383","0.00186"
"105.22200","28.31034","0.00191"
"105.30000","28.31692","0.00133"
"105.37800","28.32332","0.00207"
"105.45600","28.32989","0.00339"
"105.53400","28.33629","0.00294"
"105.61200","28.34281","0.00279"
"105.69000","28.34927","0.00186"
"105.76800","28.35585","0.00185"
"105.84600","28.36236","0.00183"
"105.92400","28.36888","0.00173"
"106.00200","28.37540","0.00249"
"106.08000","28.38185","0.00292"
"106.15800","28.38831","0.00186"
"106.23600","28.39477","0.00261"
"106.31400","28.40134","0.00172"
"106.39200","28.40786","0.00288"
"106.47000","28.41438","0.00164"
"106.54800","28.42084","0.00191"
"106.62600","28.42735","0.00125"
"106.70400","28.43375","0.00245"
"106.78200","28.44027","0.00302"
"106.86000","28.44690","0.00209"
"106.93800","28.45342","0.00288"
"107.01600","28.45994","0.00198"
"107.09400","28.46634","0.00223"
"107.17200","28.47285","0.00147"
"107.25000","28.47931","0.00181"
"107.32800","28.48582","0.00209"
"107.40600","28.49234","0.00254"
"107.48400","28.49886","0.00173"
"107.56200","28.50538","0.00177"
"107.64000","28.51184","0.00296"
"107.71800","28.51835","0.00213"
"107.79600","28.52481","0.00189"
"107.87400","28.53133","0.00233"
"107.95200","28.53778","0.00182"
"108.03000","28.54442","0.00242"
"108.10800","28.55088","0.00232"
"108.18600","28.55740","0.00235"
"108.26400","28.56379","0.00246"
"108.34200","28.57025","0.00226"
"108.42000","28.57682","0.00213"
"108.49800","28.58334","0.00201"
"108.57600","28.58992","0.00214"
"108.62200","28.59374","0.00202"