File: Force_trajectories/161114/Specimen_RawData_6.csv
End date,"11/14/2016"
Specimen label,"20BT63.2"
Maximum Load,"0.14899",N

Time,Extension,Load
(s),(mm),(N)
"0.00000","0.00000","-0.00020"
"0.16200","0.00987","0.00055"
"0.32400","0.02679","0.00043"
"0.48600","0.04084","0.00034"
"0.64800","0.05417","0.00037"
"0.81000","0.06774","0.00000"
"0.97200","0.08119","0.00153"
"1.13400","0.09471","0.00090"
"1.29600","0.10822","0.00027"
"1.45800","0.12173","0.00146"
"1.62000","0.13512","0.00177"
"1.78200","0.14864","0.00140"
"1.94400","0.16215","0.00148"
"2.10600","0.17566","0.00128"
"2.26800","0.18917","0.00200"
"2.43000","0.20269","0.00107"
"2.59200","0.21620","0.00175"
"2.75400","0.22965","0.00224"
"2.91600","0.24322","0.00189"
"3.07800","0.25674","0.00223"
"3.24000","0.27013","0.00254"
"3.40200","0.28370","0.00280"
"3.56400","0.29721","0.00197"
"3.72600","0.31073","0.00201"
"3.88800","0.32418","0.00257"
"4.05000","0.33775","0.00210"
"4.21200","0.35120","0.00211"
"4.37400","0.36460","0.00254"
"4.53600","0.37817","0.00294"
"4.69800","0.39168","0.00274"
"4.86000","0.40513","0.00235"
"5.02200","0.41871","0.00260"
"5.18400","0.43216","0.00191"
"5.34600","0.44567","0.00185"
"5.50800","0.45912","0.00253"
"5.67000","0.47270","0.00267"
"5.83200","0.48615","0.00288"
"5.99400","0.49960","0.00226"
"6.15600","0.51317","0.00335"
"6.31800","0.52669","0.00247"
"6.48000","0.54014","0.00268"
"6.64200","0.55365","0.00318"
"6.80400","0.56722","0.00350"
"6.96600","0.58068","0.00276"
"7.12800","0.59413","0.00326"
"7.29000","0.60770","0.00291"
"7.45200","0.62127","0.00294"
"7.61400","0.63467","0.00319"
"7.77600","0.64818","0.00322"
"7.93800","0.66175","0.00401"
"8.10000","0.67514","0.00369"
"8.26200","0.68866","0.00361"
"8.42400","0.70217","0.00345"
"8.58600","0.71568","0.00244"
"8.74800","0.72919","0.00292"
"8.91000","0.74271","0.00405"
"9.07200","0.75616","0.00336"
"9.23400","0.76961","0.00378"
"9.39600","0.78318","0.00372"
"9.55800","0.79670","0.00366"
"9.72000","0.81021","0.00337"
"9.88200","0.82372","0.00379"
"10.04400","0.83723","0.00330"
"10.20600","0.85069","0.00369"
"10.36800","0.86420","0.00397"
"10.53000","0.87771","0.00402"
"10.69200","0.89116","0.00395"
"10.85400","0.90462","0.00418"
"11.01600","0.91825","0.00365"
"11.17800","0.93170","0.00379"
"11.34000","0.94521","0.00371"
"11.50200","0.95867","0.00340"
"11.66400","0.97218","0.00454"
"11.82600","0.98563","0.00362"
"11.98800","0.99914","0.00388"
"12.15000","1.01272","0.00428"
"12.31200","1.02623","0.00487"
"12.47400","1.03962","0.00448"
"12.63600","1.05325","0.00416"
"12.79800","1.06665","0.00478"
"12.96000","1.08016","0.00386"
"13.12200","1.09367","0.00443"
"13.28400","1.10718","0.00365"
"13.44600","1.12064","0.00387"
"13.60800","1.13415","0.00572"
"13.77000","1.14772","0.00400"
"13.93200","1.16123","0.00467"
"14.09400","1.17463","0.00542"
"14.25600","1.18826","0.00427"
"14.41800","1.20171","0.00602"
"14.58000","1.21516","0.00424"
"14.74200","1.22867","0.00440"
"14.90400","1.24219","0.00438"
"15.06600","1.25570","0.00415"
"15.22800","1.26915","0.00448"
"15.39000","1.28266","0.00551"
"15.55200","1.29612","0.00474"
"15.71400","1.30957","0.00409"
"15.87600","1.32320","0.00479"
"16.03800","1.33671","0.00519"
"16.20000","1.35017","0.00544"
"16.36200","1.36368","0.00419"
"16.52400","1.37719","0.00573"
"16.68600","1.39070","0.00509"
"16.84800","1.40416","0.00513"
"17.01000","1.41767","0.00509"
"17.17200","1.43118","0.00535"
"17.33400","1.44463","0.00537"
"17.49600","1.45821","0.00493"
"17.65800","1.47166","0.00466"
"17.82000","1.48511","0.00478"
"17.98200","1.49868","0.00495"
"18.14400","1.51226","0.00490"
"18.30600","1.52565","0.00479"
"18.46800","1.53916","0.00485"
"18.63000","1.55273","0.00445"
"18.79200","1.56625","0.00477"
"18.95400","1.57970","0.00458"
"19.11600","1.59321","0.00533"
"19.27800","1.60666","0.00561"
"19.44000","1.62012","0.00589"
"19.60200","1.63369","0.00524"
"19.76400","1.64720","0.00499"
"19.92600","1.66065","0.00491"
"20.08800","1.67423","0.00565"
"20.25000","1.68774","0.00437"
"20.41200","1.70113","0.00485"
"20.57400","1.71464","0.00493"
"20.73600","1.72822","0.00544"
"20.89800","1.74167","0.00546"
"21.06000","1.75512","0.00429"
"21.22200","1.76875","0.00576"
"21.38400","1.78221","0.00527"
"21.54600","1.79566","0.00507"
"21.70800","1.80917","0.00459"
"21.87000","1.82268","0.00439"
"22.03200","1.83614","0.00541"
"22.19400","1.84965","0.00507"
"22.35600","1.86322","0.00535"
"22.51800","1.87673","0.00496"
"22.68000","1.89019","0.00496"
"22.84200","1.90376","0.00485"
"23.00400","1.91721","0.00461"
"23.16600","1.93066","0.00511"
"23.32800","1.94418","0.00526"
"23.49000","1.95769","0.00570"
"23.65200","1.97114","0.00538"
"23.81400","1.98471","0.00539"
"23.97600","1.99823","0.00523"
"24.13800","2.01168","0.00547"
"24.30000","2.02507","0.00511"
"24.46200","2.03870","0.00463"
"24.62400","2.05222","0.00446"
"24.78600","2.06567","0.00533"
"24.94800","2.07924","0.00500"
"25.11000","2.09275","0.00603"
"25.27200","2.10615","0.00428"
"25.43400","2.11966","0.00507"
"25.59600","2.13317","0.00465"
"25.75800","2.14668","0.00451"
"25.92000","2.16008","0.00521"
"26.08200","2.17365","0.00548"
"26.24400","2.18722","0.00538"
"26.40600","2.20067","0.00457"
"26.56800","2.21419","0.00507"
"26.73000","2.22770","0.00523"
"26.89200","2.24121","0.00547"
"27.05400","2.25466","0.00473"
"27.21600","2.26818","0.00608"
"27.37800","2.28169","0.00534"
"27.54000","2.29514","0.00477"
"27.70200","2.30871","0.00509"
"27.86400","2.32217","0.00512"
"28.02600","2.33568","0.00474"
"28.18800","2.34913","0.00489"
"28.35000","2.36264","0.00449"
"28.51200","2.37610","0.00499"
"28.67400","2.38967","0.00524"
"28.83600","2.40324","0.00523"
"28.99800","2.41669","0.00520"
"29.16000","2.43015","0.00530"
"29.32200","2.44372","0.00478"
"29.48400","2.45723","0.00457"
"29.64600","2.47062","0.00508"
"29.80800","2.48420","0.00497"
"29.97000","2.49771","0.00516"
"30.13200","2.51116","0.00564"
"30.29400","2.52467","0.00555"
"30.45600","2.53819","0.00553"
"30.61800","2.55170","0.00500"
"30.78000","2.56509","0.00545"
"30.94200","2.57872","0.00505"
"31.10400","2.59218","0.00512"
"31.26600","2.60563","0.00579"
"31.42800","2.61920","0.00517"
"31.59000","2.63271","0.00489"
"31.75200","2.64616","0.00501"
"31.91400","2.65968","0.00614"
"32.07600","2.67319","0.00527"
"32.23800","2.68664","0.00543"
"32.40000","2.70016","0.00609"
"32.56200","2.71373","0.00442"
"32.72400","2.72724","0.00590"
"32.88600","2.74063","0.00600"
"33.04800","2.75420","0.00437"
"33.21000","2.76772","0.00548"
"33.37200","2.78117","0.00567"
"33.53400","2.79468","0.00570"
"33.69600","2.80819","0.00485"
"33.85800","2.82171","0.00527"
"34.02000","2.83516","0.00528"
"34.18200","2.84867","0.00607"
"34.34400","2.86218","0.00507"
"34.50600","2.87558","0.00547"
"34.66800","2.88921","0.00495"
"34.83000","2.90266","0.00495"
"34.99200","2.91617","0.00530"
"35.15400","2.92963","0.00536"
"35.31600","2.94320","0.00435"
"35.47800","2.95665","0.00527"
"35.64000","2.97010","0.00481"
"35.80200","2.98368","0.00603"
"35.96400","2.99719","0.00440"
"36.12600","3.01064","0.00511"
"36.28800","3.02421","0.00567"
"36.45000","3.03773","0.00439"
"36.61200","3.05118","0.00570"
"36.77400","3.06463","0.00543"
"36.93600","3.07820","0.00656"
"37.09800","3.09166","0.00578"
"37.26000","3.10517","0.00570"
"37.42200","3.11868","0.00522"
"37.58400","3.13225","0.00556"
"37.74600","3.14571","0.00521"
"37.90800","3.15922","0.00549"
"38.07000","3.17267","0.00437"
"38.23200","3.18618","0.00405"
"38.39400","3.19970","0.00449"
"38.55600","3.21321","0.00440"
"38.71800","3.22666","0.00420"
"38.88000","3.24017","0.00452"
"39.04200","3.25369","0.00422"
"39.20400","3.26720","0.00442"
"39.36600","3.28059","0.00412"
"39.52800","3.29416","0.00435"
"39.69000","3.30774","0.00424"
"39.85200","3.32113","0.00368"
"40.01400","3.33470","0.00460"
"40.17600","3.34821","0.00384"
"40.33800","3.36167","0.00531"
"40.50000","3.37518","0.00490"
"40.66200","3.38869","0.00472"
"40.82400","3.40214","0.00402"
"40.98600","3.41560","0.00531"
"41.14800","3.42917","0.00409"
"41.31000","3.44274","0.00387"
"41.47200","3.45619","0.00457"
"41.63400","3.46971","0.00452"
"41.79600","3.48322","0.00474"
"41.95800","3.49667","0.00428"
"42.12000","3.51012","0.00540"
"42.28200","3.52370","0.00508"
"42.44400","3.53721","0.00452"
"42.60600","3.55066","0.00457"
"42.76800","3.56417","0.00406"
"42.93000","3.57769","0.00407"
"43.09200","3.59114","0.00451"
"43.25400","3.60465","0.00447"
"43.41600","3.61816","0.00422"
"43.57800","3.63168","0.00474"
"43.74000","3.64513","0.00393"
"43.90200","3.65870","0.00412"
"44.06400","3.67221","0.00475"
"44.22600","3.68567","0.00443"
"44.38800","3.69918","0.00408"
"44.55000","3.71269","0.00426"
"44.71200","3.72614","0.00276"
"44.87400","3.73972","0.00316"
"45.03600","3.75323","0.00323"
"45.19800","3.76668","0.00301"
"45.36000","3.78019","0.00315"
"45.52200","3.79365","0.00288"
"45.68400","3.80716","0.00299"
"45.84600","3.82061","0.00294"
"46.00800","3.83418","0.00357"
"46.17000","3.84770","0.00337"
"46.33200","3.86115","0.00345"
"46.49400","3.87472","0.00374"
"46.65600","3.88823","0.00338"
"46.81800","3.90169","0.00257"
"46.98000","3.91514","0.00294"
"47.14200","3.92865","0.00350"
"47.30400","3.94216","0.00352"
"47.46600","3.95562","0.00311"
"47.62800","3.96919","0.00322"
"47.79000","3.98270","0.00310"
"47.95200","3.99615","0.00424"
"48.11400","4.00973","0.00377"
"48.27600","4.02324","0.00407"
"48.43800","4.03663","0.00345"
"48.60000","4.05014","0.00333"
"48.76200","4.06372","0.00370"
"48.92400","4.07723","0.00390"
"49.08600","4.09068","0.00321"
"49.24800","4.10419","0.00388"
"49.41000","4.11770","0.00396"
"49.57200","4.13110","0.00450"
"49.73400","4.14467","0.00397"
"49.89600","4.15824","0.00394"
"50.05800","4.17170","0.00389"
"50.22000","4.18515","0.00355"
"50.38200","4.19872","0.00385"
"50.54400","4.21217","0.00451"
"50.70600","4.22563","0.00441"
"50.86800","4.23920","0.00374"
"51.03000","4.25271","0.00394"
"51.19200","4.26610","0.00389"
"51.35400","4.27973","0.00372"
"51.51600","4.29325","0.00358"
"51.67800","4.30664","0.00423"
"51.84000","4.32015","0.00366"
"52.00200","4.33366","0.00371"
"52.16400","4.34718","0.00335"
"52.32600","4.36063","0.00358"
"52.48800","4.37426","0.00347"
"52.65000","4.38771","0.00380"
"52.81200","4.40117","0.00352"
"52.97400","4.41468","0.00351"
"53.13600","4.42819","0.00440"
"53.29800","4.44165","0.00379"
"53.46000","4.45516","0.00346"
"53.62200","4.46867","0.00258"
"53.78400","4.48212","0.00377"
"53.94600","4.49563","0.00371"
"54.10800","4.50921","0.00355"
"54.27000","4.52266","0.00432"
"54.43200","4.53617","0.00416"
"54.59400","4.54968","0.00374"
"54.75600","4.56320","0.00344"
"54.91800","4.57665","0.00436"
"55.08000","4.59022","0.00340"
"55.24200","4.60373","0.00371"
"55.40400","4.61719","0.00426"
"55.56600","4.63064","0.00428"
"55.72800","4.64421","0.00356"
"55.89000","4.65766","0.00351"
"56.05200","4.67106","0.00434"
"56.21400","4.68469","0.00360"
"56.37600","4.69826","0.00315"
"56.53800","4.71165","0.00334"
"56.70000","4.72523","0.00342"
"56.86200","4.73868","0.00377"
"57.02400","4.75219","0.00400"
"57.18600","4.76564","0.00472"
"57.34800","4.77922","0.00388"
"57.51000","4.79273","0.00360"
"57.67200","4.80612","0.00371"
"57.83400","4.81969","0.00359"
"57.99600","4.83321","0.00341"
"58.15800","4.84666","0.00371"
"58.32000","4.86017","0.00385"
"58.48200","4.87368","0.00421"
"58.64400","4.88714","0.00435"
"58.80600","4.90071","0.00398"
"58.96800","4.91422","0.00335"
"59.13000","4.92773","0.00337"
"59.29200","4.94113","0.00301"
"59.45400","4.95470","0.00314"
"59.61600","4.96821","0.00297"
"59.77800","4.98166","0.00360"
"59.94000","4.99518","0.00344"
"60.10200","5.00869","0.00350"
"60.26400","5.02214","0.00451"
"60.42600","5.03565","0.00385"
"60.58800","5.04917","0.00359"
"60.75000","5.06268","0.00310"
"60.91200","5.07613","0.00376"
"61.07400","5.08970","0.00396"
"61.23600","5.10322","0.00402"
"61.39800","5.11667","0.00414"
"61.56000","5.13018","0.00407"
"61.72200","5.14369","0.00369"
"61.88400","5.15721","0.00386"
"62.04600","5.17066","0.00425"
"62.20800","5.18423","0.00321"
"62.37000","5.19762","0.00439"
"62.53200","5.21114","0.00384"
"62.69400","5.22471","0.00324"
"62.85600","5.23816","0.00444"
"63.01800","5.25167","0.00405"
"63.18000","5.26525","0.00355"
"63.34200","5.27876","0.00354"
"63.50400","5.29215","0.00341"
"63.66600","5.30566","0.00272"
"63.82800","5.31918","0.00279"
"63.99000","5.33275","0.00381"
"64.15200","5.34620","0.00335"
"64.31400","5.35971","0.00295"
"64.47600","5.37317","0.00314"
"64.63800","5.38656","0.00365"
"64.80000","5.40019","0.00352"
"64.96200","5.41370","0.00379"
"65.12400","5.42716","0.00307"
"65.28600","5.44073","0.00327"
"65.44800","5.45418","0.00346"
"65.61000","5.46769","0.00404"
"65.77200","5.48115","0.00303"
"65.93400","5.49472","0.00327"
"66.09600","5.50817","0.00338"
"66.25800","5.52162","0.00377"
"66.42000","5.53520","0.00366"
"66.58200","5.54871","0.00345"
"66.74400","5.56210","0.00401"
"66.90600","5.57567","0.00316"
"67.06800","5.58924","0.00441"
"67.23000","5.60270","0.00330"
"67.39200","5.61615","0.00307"
"67.55400","5.62972","0.00294"
"67.71600","5.64324","0.00344"
"67.87800","5.65669","0.00309"
"68.04000","5.67020","0.00381"
"68.20200","5.68371","0.00365"
"68.36400","5.69717","0.00376"
"68.52600","5.71062","0.00322"
"68.68800","5.72419","0.00273"
"68.85000","5.73770","0.00323"
"69.01200","5.75115","0.00365"
"69.17400","5.76473","0.00366"
"69.33600","5.77818","0.00382"
"69.49800","5.79163","0.00311"
"69.66000","5.80520","0.00339"
"69.82200","5.81866","0.00430"
"69.98400","5.83217","0.00365"
"70.14600","5.84568","0.00375"
"70.30800","5.85925","0.00391"
"70.47000","5.87271","0.00363"
"70.63200","5.88616","0.00407"
"70.79400","5.89973","0.00323"
"70.95600","5.91319","0.00361"
"71.11800","5.92664","0.00325"
"71.28000","5.94021","0.00314"
"71.44200","5.95372","0.00336"
"71.60400","5.96717","0.00395"
"71.76600","5.98069","0.00389"
"71.92800","5.99420","0.00270"
"72.09000","6.00765","0.00407"
"72.25200","6.02116","0.00415"
"72.41400","6.03468","0.00349"
"72.57600","6.04819","0.00349"
"72.73800","6.06164","0.00338"
"72.90000","6.07527","0.00414"
"73.06200","6.08867","0.00382"
"73.22400","6.10212","0.00423"
"73.38600","6.11569","0.00383"
"73.54800","6.12920","0.00396"
"73.71000","6.14266","0.00395"
"73.87200","6.15617","0.00309"
"74.03400","6.16974","0.00411"
"74.19600","6.18319","0.00278"
"74.35800","6.19665","0.00401"
"74.52000","6.21022","0.00346"
"74.68200","6.22373","0.00275"
"74.84400","6.23718","0.00436"
"75.00600","6.25070","0.00421"
"75.16800","6.26421","0.00511"
"75.33000","6.27766","0.00363"
"75.49200","6.29117","0.00392"
"75.65400","6.30463","0.00413"
"75.81600","6.31820","0.00419"
"75.97800","6.33165","0.00444"
"76.14000","6.34516","0.00427"
"76.30200","6.35868","0.00372"
"76.46400","6.37219","0.00427"
"76.62600","6.38570","0.00416"
"76.78800","6.39921","0.00498"
"76.95000","6.41267","0.00383"
"77.11200","6.42618","0.00394"
"77.27400","6.43963","0.00428"
"77.43600","6.45314","0.00415"
"77.59800","6.46660","0.00453"
"77.76000","6.48023","0.00391"
"77.92200","6.49374","0.00368"
"78.08400","6.50719","0.00514"
"78.24600","6.52071","0.00363"
"78.40800","6.53422","0.00420"
"78.57000","6.54767","0.00394"
"78.73200","6.56112","0.00405"
"78.89400","6.57470","0.00425"
"79.05600","6.58821","0.00466"
"79.21800","6.60166","0.00360"
"79.38000","6.61523","0.00371"
"79.54200","6.62863","0.00490"
"79.70400","6.64208","0.00556"
"79.86600","6.65565","0.00351"
"80.02800","6.66922","0.00394"
"80.19000","6.68268","0.00459"
"80.35200","6.69619","0.00491"
"80.51400","6.70970","0.00406"
"80.67600","6.72315","0.00472"
"80.83800","6.73661","0.00420"
"81.00000","6.75018","0.00563"
"81.16200","6.76369","0.00420"
"81.32400","6.77714","0.00390"
"81.48600","6.79078","0.00451"
"81.64800","6.80423","0.00481"
"81.81000","6.81768","0.00391"
"81.97200","6.83113","0.00425"
"82.13400","6.84471","0.00453"
"82.29600","6.85816","0.00481"
"82.45800","6.87161","0.00443"
"82.62000","6.88524","0.00454"
"82.78200","6.89870","0.00447"
"82.94400","6.91215","0.00441"
"83.10600","6.92572","0.00396"
"83.26800","6.93917","0.00509"
"83.43000","6.95263","0.00517"
"83.59200","6.96614","0.00413"
"83.75400","6.97971","0.00528"
"83.91600","6.99316","0.00385"
"84.07800","7.00668","0.00458"
"84.24000","7.02019","0.00499"
"84.40200","7.03370","0.00392"
"84.56400","7.04709","0.00483"
"84.72600","7.06067","0.00444"
"84.88800","7.07424","0.00442"
"85.05000","7.08763","0.00508"
"85.21200","7.10114","0.00454"
"85.37400","7.11472","0.00468"
"85.53600","7.12817","0.00477"
"85.69800","7.14168","0.00483"
"85.86000","7.15513","0.00525"
"86.02200","7.16871","0.00493"
"86.18400","7.18210","0.00306"
"86.34600","7.19567","0.00423"
"86.50800","7.20918","0.00436"
"86.67000","7.22270","0.00395"
"86.83200","7.23621","0.00431"
"86.99400","7.24972","0.00454"
"87.15600","7.26317","0.00424"
"87.31800","7.27668","0.00449"
"87.48000","7.29020","0.00428"
"87.64200","7.30371","0.00461"
"87.80400","7.31716","0.00465"
"87.96600","7.33074","0.00437"
"88.12800","7.34419","0.00416"
"88.29000","7.35764","0.00445"
"88.45200","7.37115","0.00441"
"88.61400","7.38467","0.00417"
"88.77600","7.39818","0.00468"
"88.93800","7.41169","0.00400"
"89.10000","7.42526","0.00408"
"89.26200","7.43871","0.00424"
"89.42400","7.45217","0.00439"
"89.58600","7.46574","0.00394"
"89.74800","7.47919","0.00445"
"89.91000","7.49270","0.00400"
"90.07200","7.50622","0.00408"
"90.23400","7.51967","0.00435"
"90.39600","7.53318","0.00443"
"90.55800","7.54669","0.00472"
"90.72000","7.56021","0.00460"
"90.88200","7.57372","0.00448"
"91.04400","7.58711","0.00429"
"91.20600","7.60074","0.00402"
"91.36800","7.61420","0.00441"
"91.53000","7.62765","0.00456"
"91.69200","7.64116","0.00441"
"91.85400","7.65474","0.00452"
"92.01600","7.66819","0.00449"
"92.17800","7.68164","0.00450"
"92.34000","7.69515","0.00411"
"92.50200","7.70866","0.00479"
"92.66400","7.72212","0.00413"
"92.82600","7.73575","0.00474"
"92.98800","7.74926","0.00489"
"93.15000","7.76266","0.00477"
"93.31200","7.77617","0.00473"
"93.47400","7.78968","0.00366"
"93.63600","7.80313","0.00416"
"93.79800","7.81664","0.00443"
"93.96000","7.83022","0.00443"
"94.12200","7.84367","0.00429"
"94.28400","7.85712","0.00432"
"94.44600","7.87069","0.00441"
"94.60800","7.88421","0.00465"
"94.77000","7.89760","0.00461"
"94.93200","7.91117","0.00496"
"95.09400","7.92468","0.00424"
"95.25600","7.93820","0.00400"
"95.41800","7.95171","0.00436"
"95.58000","7.96522","0.00493"
"95.74200","7.97867","0.00473"
"95.90400","7.99213","0.00454"
"96.06600","8.00564","0.00487"
"96.22800","8.01921","0.00512"
"96.39000","8.03266","0.00433"
"96.55200","8.04624","0.00424"
"96.71400","8.05969","0.00540"
"96.87600","8.07314","0.00382"
"97.03800","8.08665","0.00507"
"97.20000","8.10017","0.00477"
"97.36200","8.11362","0.00459"
"97.52400","8.12713","0.00507"
"97.68600","8.14070","0.00485"
"97.84800","8.15422","0.00490"
"98.01000","8.16761","0.00510"
"98.17200","8.18118","0.00480"
"98.33400","8.19469","0.00488"
"98.49600","8.20815","0.00427"
"98.65800","8.22166","0.00500"
"98.82000","8.23517","0.00451"
"98.98200","8.24868","0.00468"
"99.14400","8.26214","0.00537"
"99.30600","8.27571","0.00524"
"99.46800","8.28922","0.00489"
"99.63000","8.30261","0.00506"
"99.79200","8.31625","0.00419"
"99.95400","8.32970","0.00520"
"100.11600","8.34315","0.00449"
"100.27800","8.35672","0.00468"
"100.44000","8.37024","0.00401"
"100.60200","8.38369","0.00417"
"100.76400","8.39714","0.00487"
"100.92600","8.41071","0.00476"
"101.08800","8.42417","0.00503"
"101.25000","8.43756","0.00438"
"101.41200","8.45119","0.00450"
"101.57400","8.46476","0.00438"
"101.73600","8.47816","0.00498"
"101.89800","8.49167","0.00504"
"102.06000","8.50518","0.00443"
"102.22200","8.51863","0.00365"
"102.38400","8.53215","0.00589"
"102.54600","8.54566","0.00497"
"102.70800","8.55923","0.00494"
"102.87000","8.57262","0.00457"
"103.03200","8.58619","0.00488"
"103.19400","8.59971","0.00554"
"103.35600","8.61316","0.00478"
"103.51800","8.62667","0.00468"
"103.68000","8.64019","0.00431"
"103.84200","8.65370","0.00477"
"104.00400","8.66721","0.00456"
"104.16600","8.68072","0.00520"
"104.32800","8.69418","0.00485"
"104.49000","8.70763","0.00520"
"104.65200","8.72120","0.00501"
"104.81400","8.73471","0.00515"
"104.97600","8.74811","0.00547"
"105.13800","8.76168","0.00538"
"105.30000","8.77519","0.00549"
"105.46200","8.78870","0.00557"
"105.62400","8.80216","0.00455"
"105.78600","8.81573","0.00508"
"105.94800","8.82918","0.00489"
"106.11000","8.84263","0.00616"
"106.27200","8.85620","0.00498"
"106.43400","8.86972","0.00533"
"106.59600","8.88311","0.00523"
"106.75800","8.89668","0.00506"
"106.92000","8.91020","0.00481"
"107.08200","8.92365","0.00534"
"107.24400","8.93722","0.00526"
"107.40600","8.95067","0.00532"
"107.56800","8.96418","0.00526"
"107.73000","8.97764","0.00547"
"107.89200","8.99127","0.00525"
"108.05400","9.00472","0.00531"
"108.21600","9.01817","0.00531"
"108.37800","9.03175","0.00491"
"108.54000","9.04520","0.00454"
"108.70200","9.05865","0.00573"
"108.86400","9.07211","0.00577"
"109.02600","9.08574","0.00545"
"109.18800","9.09919","0.00557"
"109.35000","9.11264","0.00499"
"109.51200","9.12621","0.00522"
"109.67400","9.13967","0.00531"
"109.83600","9.15312","0.00566"
"109.99800","9.16663","0.00518"
"110.16000","9.18021","0.00518"
"110.32200","9.19366","0.00528"
"110.48400","9.20723","0.00519"
"110.64600","9.22068","0.00584"
"110.80800","9.23419","0.00508"
"110.97000","9.24765","0.00530"
"111.13200","9.26116","0.00536"
"111.29400","9.27467","0.00529"
"111.45600","9.28813","0.00575"
"111.61800","9.30170","0.00532"
"111.78000","9.31521","0.00461"
"111.94200","9.32866","0.00505"
"112.10400","9.34211","0.00578"
"112.26600","9.35569","0.00587"
"112.42800","9.36920","0.00470"
"112.59000","9.38265","0.00593"
"112.75200","9.39622","0.00565"
"112.91400","9.40974","0.00586"
"113.07600","9.42319","0.00566"
"113.23800","9.43670","0.00569"
"113.40000","9.45021","0.00530"
"113.56200","9.46367","0.00570"
"113.72400","9.47712","0.00547"
"113.88600","9.49063","0.00565"
"114.04800","9.50414","0.00433"
"114.21000","9.51766","0.00593"
"114.37200","9.53123","0.00541"
"114.53400","9.54468","0.00500"
"114.69600","9.55813","0.00608"
"114.85800","9.57171","0.00631"
"115.02000","9.58522","0.00615"
"115.18200","9.59861","0.00555"
"115.34400","9.61218","0.00561"
"115.50600","9.62576","0.00598"
"115.66800","9.63921","0.00569"
"115.83000","9.65266","0.00621"
"115.99200","9.66617","0.00460"
"116.15400","9.67963","0.00562"
"116.31600","9.69308","0.00487"
"116.47800","9.70671","0.00511"
"116.64000","9.72022","0.00554"
"116.80200","9.73368","0.00615"
"116.96400","9.74719","0.00480"
"117.12600","9.76070","0.00500"
"117.28800","9.77415","0.00536"
"117.45000","9.78761","0.00551"
"117.61200","9.80118","0.00581"
"117.77400","9.81469","0.00568"
"117.93600","9.82820","0.00526"
"118.09800","9.84171","0.00596"
"118.26000","9.85523","0.00523"
"118.42200","9.86862","0.00607"
"118.58400","9.88219","0.00514"
"118.74600","9.89577","0.00532"
"118.90800","9.90916","0.00625"
"119.07000","9.92267","0.00506"
"119.23200","9.93624","0.00550"
"119.39400","9.94970","0.00589"
"119.55600","9.96315","0.00585"
"119.71800","9.97666","0.00636"
"119.88000","9.99023","0.00520"
"120.04200","10.00363","0.00594"
"120.20400","10.01720","0.00588"
"120.36600","10.03071","0.00540"
"120.52800","10.04416","0.00667"
"120.69000","10.05767","0.00632"
"120.85200","10.07119","0.00546"
"121.01400","10.08470","0.00591"
"121.17600","10.09815","0.00518"
"121.33800","10.11167","0.00559"
"121.50000","10.12518","0.00602"
"121.66200","10.13869","0.00598"
"121.82400","10.15220","0.00585"
"121.98600","10.16572","0.00582"
"122.14800","10.17917","0.00562"
"122.31000","10.19268","0.00607"
"122.47200","10.20619","0.00579"
"122.63400","10.21965","0.00506"
"122.79600","10.23310","0.00635"
"122.95800","10.24667","0.00567"
"123.12000","10.26024","0.00668"
"123.28200","10.27369","0.00613"
"123.44400","10.28721","0.00568"
"123.60600","10.30072","0.00576"
"123.76800","10.31417","0.00503"
"123.93000","10.32763","0.00545"
"124.09200","10.34120","0.00652"
"124.25400","10.35471","0.00663"
"124.41600","10.36816","0.00665"
"124.57800","10.38173","0.00531"
"124.74000","10.39513","0.00578"
"124.90200","10.40864","0.00603"
"125.06400","10.42215","0.00580"
"125.22600","10.43572","0.00597"
"125.38800","10.44918","0.00584"
"125.55000","10.46269","0.00557"
"125.71200","10.47620","0.00634"
"125.87400","10.48972","0.00592"
"126.03600","10.50311","0.00615"
"126.19800","10.51674","0.00625"
"126.36000","10.53019","0.00572"
"126.52200","10.54364","0.00496"
"126.68400","10.55716","0.00630"
"126.84600","10.57073","0.00565"
"127.00800","10.58418","0.00622"
"127.17000","10.59764","0.00610"
"127.33200","10.61121","0.00617"
"127.49400","10.62466","0.00575"
"127.65600","10.63817","0.00584"
"127.81800","10.65169","0.00587"
"127.98000","10.66520","0.00612"
"128.14200","10.67871","0.00632"
"128.30400","10.69216","0.00653"
"128.46600","10.70573","0.00638"
"128.62800","10.71913","0.00548"
"128.79000","10.73264","0.00580"
"128.95200","10.74615","0.00632"
"129.11400","10.75966","0.00637"
"129.27600","10.77318","0.00640"
"129.43800","10.78675","0.00647"
"129.60000","10.80020","0.00584"
"129.76200","10.81359","0.00704"
"129.92400","10.82723","0.00606"
"130.08600","10.84068","0.00690"
"130.24800","10.85419","0.00693"
"130.41000","10.86765","0.00745"
"130.57200","10.88122","0.00639"
"130.73400","10.89467","0.00652"
"130.89600","10.90812","0.00642"
"131.05800","10.92169","0.00649"
"131.22000","10.93515","0.00728"
"131.38200","10.94860","0.00630"
"131.54400","10.96217","0.00657"
"131.70600","10.97568","0.00738"
"131.86800","10.98920","0.00592"
"132.03000","11.00265","0.00595"
"132.19200","11.01616","0.00606"
"132.35400","11.02967","0.00661"
"132.51600","11.04313","0.00720"
"132.67800","11.05670","0.00637"
"132.84000","11.07021","0.00661"
"133.00200","11.08366","0.00640"
"133.16400","11.09724","0.00705"
"133.32600","11.11069","0.00611"
"133.48800","11.12408","0.00634"
"133.65000","11.13771","0.00689"
"133.81200","11.15123","0.00745"
"133.97400","11.16468","0.00736"
"134.13600","11.17813","0.00671"
"134.29800","11.19170","0.00695"
"134.46000","11.20522","0.00665"
"134.62200","11.21861","0.00728"
"134.78400","11.23218","0.00748"
"134.94600","11.24569","0.00694"
"135.10800","11.25915","0.00668"
"135.27000","11.27266","0.00713"
"135.43200","11.28617","0.00713"
"135.59400","11.29962","0.00771"
"135.75600","11.31314","0.00701"
"135.91800","11.32671","0.00820"
"136.08000","11.34022","0.00775"
"136.24200","11.35361","0.00759"
"136.40400","11.36718","0.00694"
"136.56600","11.38070","0.00812"
"136.72800","11.39415","0.00719"
"136.89000","11.40766","0.00765"
"137.05200","11.42124","0.00779"
"137.21400","11.43463","0.00761"
"137.37600","11.44814","0.00848"
"137.53800","11.46165","0.00832"
"137.70000","11.47517","0.00784"
"137.86200","11.48862","0.00794"
"138.02400","11.50219","0.00789"
"138.18600","11.51576","0.00757"
"138.34800","11.52915","0.00767"
"138.51000","11.54267","0.00817"
"138.67200","11.55618","0.00790"
"138.83400","11.56963","0.00871"
"138.99600","11.58315","0.00813"
"139.15800","11.59666","0.00906"
"139.32000","11.61017","0.00869"
"139.48200","11.62362","0.00930"
"139.64400","11.63720","0.00851"
"139.80600","11.65065","0.00878"
"139.96800","11.66416","0.00860"
"140.13000","11.67767","0.00845"
"140.29200","11.69119","0.00876"
"140.45400","11.70470","0.00922"
"140.61600","11.71821","0.00806"
"140.77800","11.73172","0.00861"
"140.94000","11.74518","0.00788"
"141.10200","11.75863","0.01057"
"141.26400","11.77220","0.00840"
"141.42600","11.78571","0.00896"
"141.58800","11.79911","0.00945"
"141.75000","11.81274","0.00964"
"141.91200","11.82619","0.00939"
"142.07400","11.83964","0.00956"
"142.23600","11.85321","0.00923"
"142.39800","11.86667","0.00898"
"142.56000","11.88018","0.00979"
"142.72200","11.89363","0.00932"
"142.88400","11.90721","0.00974"
"143.04600","11.92072","0.00929"
"143.20800","11.93411","0.00990"
"143.37000","11.94774","0.00900"
"143.53200","11.96119","0.00958"
"143.69400","11.97471","0.00934"
"143.85600","11.98816","0.00932"
"144.01800","12.00173","0.00989"
"144.18000","12.01518","0.00978"
"144.34200","12.02870","0.00891"
"144.50400","12.04221","0.00853"
"144.66600","12.05572","0.00786"
"144.82800","12.06912","0.00923"
"144.99000","12.08269","0.00870"
"145.15200","12.09620","0.00770"
"145.31400","12.10965","0.00860"
"145.47600","12.12317","0.00860"
"145.63800","12.13674","0.00857"
"145.80000","12.15025","0.00785"
"145.96200","12.16364","0.00891"
"146.12400","12.17715","0.00932"
"146.28600","12.19067","0.00768"
"146.44800","12.20412","0.00860"
"146.61000","12.21769","0.00855"
"146.77200","12.23120","0.00843"
"146.93400","12.24466","0.00821"
"147.09600","12.25817","0.00902"
"147.25800","12.27168","0.00899"
"147.42000","12.28520","0.00881"
"147.58200","12.29865","0.00995"
"147.74400","12.31216","0.00849"
"147.90600","12.32567","0.00780"
"148.06800","12.33918","0.00861"
"148.23000","12.35270","0.00749"
"148.39200","12.36615","0.00770"
"148.55400","12.37966","0.00871"
"148.71600","12.39318","0.00867"
"148.87800","12.40669","0.00841"
"149.04000","12.42014","0.00786"
"149.20200","12.43371","0.00826"
"149.36400","12.44722","0.00745"
"149.52600","12.46068","0.00807"
"149.68800","12.47413","0.00810"
"149.85000","12.48770","0.00817"
"150.01200","12.50121","0.00942"
"150.17400","12.51467","0.00856"
"150.33600","12.52818","0.00850"
"150.49800","12.54169","0.00851"
"150.66000","12.55514","0.00828"
"150.82200","12.56866","0.00885"
"150.98400","12.58217","0.00928"
"151.14600","12.59568","0.00871"
"151.30800","12.60913","0.00830"
"151.47000","12.62271","0.00987"
"151.63200","12.63616","0.00958"
"151.79400","12.64967","0.00867"
"151.95600","12.66318","0.00882"
"152.11800","12.67676","0.01008"
"152.28000","12.69015","0.00909"
"152.44200","12.70366","0.00948"
"152.60400","12.71717","0.00814"
"152.76600","12.73063","0.01000"
"152.92800","12.74414","0.00971"
"153.09000","12.75771","0.00976"
"153.25200","12.77122","0.00827"
"153.41400","12.78462","0.01024"
"153.57600","12.79819","0.00935"
"153.73800","12.81170","0.00986"
"153.90000","12.82515","0.00858"
"154.06200","12.83867","0.00948"
"154.22400","12.85218","0.00968"
"154.38600","12.86569","0.00927"
"154.54800","12.87914","0.00973"
"154.71000","12.89272","0.01041"
"154.87200","12.90623","0.01060"
"155.03400","12.91962","0.00983"
"155.19600","12.93319","0.01038"
"155.35800","12.94671","0.01048"
"155.52000","12.96016","0.01049"
"155.68200","12.97373","0.01067"
"155.84400","12.98718","0.01078"
"156.00600","13.00064","0.01078"
"156.16800","13.01415","0.01100"
"156.33000","13.02772","0.01017"
"156.49200","13.04117","0.01074"
"156.65400","13.05463","0.01090"
"156.81600","13.06820","0.01219"
"156.97800","13.08171","0.01142"
"157.14000","13.09516","0.01060"
"157.30200","13.10862","0.01145"
"157.46400","13.12219","0.01237"
"157.62600","13.13564","0.01223"
"157.78800","13.14915","0.01159"
"157.95000","13.16267","0.01161"
"158.11200","13.17618","0.01190"
"158.27400","13.18963","0.01071"
"158.43600","13.20320","0.01211"
"158.59800","13.21671","0.01227"
"158.76000","13.23017","0.01166"
"158.92200","13.24368","0.01165"
"159.08400","13.25719","0.01250"
"159.24600","13.27071","0.01227"
"159.40800","13.28422","0.01165"
"159.57000","13.29773","0.01271"
"159.73200","13.31124","0.01221"
"159.89400","13.32464","0.01226"
"160.05600","13.33821","0.01284"
"160.21800","13.35172","0.01205"
"160.38000","13.36511","0.01325"
"160.54200","13.37869","0.01254"
"160.70400","13.39220","0.01353"
"160.86600","13.40571","0.01383"
"161.02800","13.41916","0.01396"
"161.19000","13.43268","0.01356"
"161.35200","13.44613","0.01434"
"161.51400","13.45958","0.01355"
"161.67600","13.47321","0.01480"
"161.83800","13.48672","0.01400"
"162.00000","13.50018","0.01418"
"162.16200","13.51363","0.01354"
"162.32400","13.52720","0.01417"
"162.48600","13.54066","0.01487"
"162.64800","13.55417","0.01517"
"162.81000","13.56768","0.01563"
"162.97200","13.58119","0.01529"
"163.13400","13.59465","0.01498"
"163.29600","13.60822","0.01507"
"163.45800","13.62167","0.01508"
"163.62000","13.63512","0.01508"
"163.78200","13.64869","0.01613"
"163.94400","13.66221","0.01586"
"164.10600","13.67572","0.01606"
"164.26800","13.68917","0.01534"
"164.43000","13.70274","0.01599"
"164.59200","13.71620","0.01545"
"164.75400","13.72965","0.01563"
"164.91600","13.74322","0.01638"
"165.07800","13.75668","0.01644"
"165.24000","13.77013","0.01647"
"165.40200","13.78370","0.01758"
"165.56400","13.79715","0.01709"
"165.72600","13.81067","0.01703"
"165.88800","13.82418","0.01682"
"166.05000","13.83769","0.01770"
"166.21200","13.85120","0.01743"
"166.37400","13.86466","0.01757"
"166.53600","13.87823","0.01771"
"166.69800","13.89168","0.01842"
"166.86000","13.90519","0.01832"
"167.02200","13.91870","0.01825"
"167.18400","13.93222","0.01949"
"167.34600","13.94567","0.01879"
"167.50800","13.95918","0.01944"
"167.67000","13.97269","0.01916"
"167.83200","13.98615","0.01943"
"167.99400","13.99960","0.01966"
"168.15600","14.01323","0.01949"
"168.31800","14.02674","0.01972"
"168.48000","14.04020","0.01971"
"168.64200","14.05371","0.02049"
"168.80400","14.06716","0.02019"
"168.96600","14.08062","0.02100"
"169.12800","14.09413","0.02099"
"169.29000","14.10770","0.02145"
"169.45200","14.12121","0.02142"
"169.61400","14.13466","0.02206"
"169.77600","14.14824","0.02185"
"169.93800","14.16169","0.02201"
"170.10000","14.17514","0.02251"
"170.26200","14.18865","0.02253"
"170.42400","14.20223","0.02352"
"170.58600","14.21568","0.02321"
"170.74800","14.22919","0.02339"
"170.91000","14.24276","0.02381"
"171.07200","14.25616","0.02443"
"171.23400","14.26967","0.02440"
"171.39600","14.28318","0.02470"
"171.55800","14.29669","0.02451"
"171.72000","14.31015","0.02510"
"171.88200","14.32366","0.02530"
"172.04400","14.33723","0.02561"
"172.20600","14.35068","0.02554"
"172.36800","14.36420","0.02596"
"172.53000","14.37765","0.02721"
"172.69200","14.39116","0.02612"
"172.85400","14.40461","0.02764"
"173.01600","14.41819","0.02733"
"173.17800","14.43170","0.02796"
"173.34000","14.44521","0.02762"
"173.50200","14.45866","0.02887"
"173.66400","14.47218","0.02890"
"173.82600","14.48569","0.02934"
"173.98800","14.49914","0.02932"
"174.15000","14.51265","0.02926"
"174.31200","14.52617","0.03025"
"174.47400","14.53968","0.03042"
"174.63600","14.55325","0.03068"
"174.79800","14.56670","0.03091"
"174.96000","14.58016","0.03151"
"175.12200","14.59373","0.03175"
"175.28400","14.60718","0.03239"
"175.44600","14.62063","0.03172"
"175.60800","14.63421","0.03291"
"175.77000","14.64772","0.03284"
"175.93200","14.66117","0.03404"
"176.09400","14.67468","0.03401"
"176.25600","14.68820","0.03409"
"176.41800","14.70165","0.03507"
"176.58000","14.71510","0.03496"
"176.74200","14.72867","0.03539"
"176.90400","14.74224","0.03611"
"177.06600","14.75570","0.03615"
"177.22800","14.76921","0.03647"
"177.39000","14.78266","0.03707"
"177.55200","14.79618","0.03779"
"177.71400","14.80963","0.03819"
"177.87600","14.82320","0.03876"
"178.03800","14.83671","0.03892"
"178.20000","14.85017","0.03959"
"178.36200","14.86374","0.03982"
"178.52400","14.87719","0.04019"
"178.68600","14.89058","0.04083"
"178.84800","14.90416","0.04145"
"179.01000","14.91773","0.04171"
"179.17200","14.93118","0.04243"
"179.33400","14.94469","0.04190"
"179.49600","14.95820","0.04264"
"179.65800","14.97166","0.04314"
"179.82000","14.98511","0.04359"
"179.98200","14.99868","0.04366"
"180.14400","15.01220","0.04423"
"180.30600","15.02559","0.04488"
"180.46800","15.03916","0.04475"
"180.63000","15.05267","0.04538"
"180.79200","15.06619","0.04589"
"180.95400","15.07964","0.04574"
"181.11600","15.09321","0.04650"
"181.27800","15.10666","0.04677"
"181.44000","15.12012","0.04728"
"181.60200","15.13369","0.04779"
"181.76400","15.14714","0.04782"
"181.92600","15.16065","0.04830"
"182.08800","15.17422","0.04884"
"182.25000","15.18774","0.04905"
"182.41200","15.20119","0.04937"
"182.57400","15.21470","0.04937"
"182.73600","15.22816","0.04973"
"182.89800","15.24167","0.05045"
"183.06000","15.25512","0.05043"
"183.22200","15.26869","0.05073"
"183.38400","15.28215","0.05109"
"183.54600","15.29566","0.05119"
"183.70800","15.30917","0.05134"
"183.87000","15.32268","0.05165"
"184.03200","15.33614","0.05182"
"184.19400","15.34965","0.05177"
"184.35600","15.36316","0.05218"
"184.51800","15.37673","0.05280"
"184.68000","15.39013","0.05276"
"184.84200","15.40370","0.05314"
"185.00400","15.41715","0.05314"
"185.16600","15.43060","0.05344"
"185.32800","15.44417","0.05373"
"185.49000","15.45769","0.05372"
"185.65200","15.47114","0.05406"
"185.81400","15.48471","0.05411"
"185.97600","15.49822","0.05442"
"186.13800","15.51174","0.05451"
"186.30000","15.52507","0.05500"
"186.46200","15.53870","0.05517"
"186.62400","15.55222","0.05533"
"186.78600","15.56567","0.05549"
"186.94800","15.57918","0.05565"
"187.11000","15.59269","0.05575"
"187.27200","15.60614","0.05586"
"187.43400","15.61966","0.05608"
"187.59600","15.63317","0.05615"
"187.75800","15.64662","0.05646"
"187.92000","15.66013","0.05641"
"188.08200","15.67371","0.05654"
"188.24400","15.68722","0.05666"
"188.40600","15.70067","0.05678"
"188.56800","15.71418","0.05676"
"188.73000","15.72776","0.05688"
"188.89200","15.74115","0.05695"
"189.05400","15.75460","0.05712"
"189.21600","15.76811","0.05729"
"189.37800","15.78169","0.05718"
"189.54000","15.79514","0.05737"
"189.70200","15.80877","0.05738"
"189.86400","15.82222","0.05744"
"190.02600","15.83568","0.05751"
"190.18800","15.84919","0.05752"
"190.35000","15.86270","0.05757"
"190.51200","15.87615","0.05769"
"190.67400","15.88966","0.05769"
"190.83600","15.90324","0.05781"
"190.99800","15.91669","0.05785"
"191.16000","15.93020","0.05797"
"191.32200","15.94372","0.05810"
"191.48400","15.95717","0.05816"
"191.64600","15.97062","0.05832"
"191.80800","15.98419","0.05824"
"191.97000","15.99771","0.05846"
"192.13200","16.01116","0.05865"
"192.29400","16.02467","0.05868"
"192.45600","16.03818","0.05896"
"192.61800","16.05164","0.05892"
"192.78000","16.06515","0.05904"
"192.94200","16.07872","0.05968"
"193.10400","16.09217","0.05972"
"193.26600","16.10569","0.06006"
"193.42800","16.11926","0.06017"
"193.59000","16.13271","0.06070"
"193.75200","16.14610","0.06089"
"193.91400","16.15968","0.06107"
"194.07600","16.17319","0.06135"
"194.23800","16.18664","0.06163"
"194.40000","16.20015","0.06188"
"194.56200","16.21372","0.06229"
"194.72400","16.22718","0.06254"
"194.88600","16.24063","0.06292"
"195.04800","16.25420","0.06333"
"195.21000","16.26772","0.06383"
"195.37200","16.28117","0.06388"
"195.53400","16.29462","0.06423"
"195.69600","16.30819","0.06470"
"195.85800","16.32165","0.06480"
"196.02000","16.33516","0.06541"
"196.18200","16.34867","0.06598"
"196.34400","16.36218","0.06593"
"196.50600","16.37564","0.06665"
"196.66800","16.38921","0.06621"
"196.83000","16.40272","0.06729"
"196.99200","16.41617","0.06746"
"197.15400","16.42969","0.06719"
"197.31600","16.44326","0.06760"
"197.47800","16.45665","0.06795"
"197.64000","16.47016","0.06872"
"197.80200","16.48368","0.06843"
"197.96400","16.49719","0.06864"
"198.12600","16.51064","0.06878"
"198.28800","16.52421","0.06928"
"198.45000","16.53772","0.06958"
"198.61200","16.55118","0.06970"
"198.77400","16.56469","0.06962"
"198.93600","16.57814","0.07007"
"199.09800","16.59166","0.07078"
"199.26000","16.60511","0.07044"
"199.42200","16.61868","0.07116"
"199.58400","16.63219","0.07158"
"199.74600","16.64565","0.07155"
"199.90800","16.65922","0.07245"
"200.07000","16.67267","0.07312"
"200.23200","16.68618","0.07441"
"200.39400","16.69969","0.07526"
"200.55600","16.71321","0.07537"
"200.71800","16.72666","0.07597"
"200.88000","16.74017","0.07725"
"201.04200","16.75374","0.07846"
"201.20400","16.76714","0.07975"
"201.36600","16.78065","0.08121"
"201.52800","16.79416","0.08296"
"201.69000","16.80767","0.08358"
"201.85200","16.82113","0.08420"
"202.01400","16.83470","0.08540"
"202.17600","16.84821","0.08618"
"202.33800","16.86166","0.08688"
"202.50000","16.87512","0.08795"
"202.66200","16.88869","0.08830"
"202.82400","16.90220","0.08879"
"202.98600","16.91560","0.08966"
"203.14800","16.92923","0.08978"
"203.31000","16.94274","0.09023"
"203.47200","16.95613","0.09056"
"203.63400","16.96971","0.09104"
"203.79600","16.98322","0.09125"
"203.95800","16.99667","0.09193"
"204.12000","17.01018","0.09194"
"204.28200","17.02369","0.09196"
"204.44400","17.03721","0.09282"
"204.60600","17.05066","0.09312"
"204.76800","17.06423","0.09358"
"204.93000","17.07774","0.09391"
"205.09200","17.09114","0.09488"
"205.25400","17.10465","0.09536"
"205.41600","17.11822","0.09614"
"205.57800","17.13167","0.09657"
"205.74000","17.14519","0.09645"
"205.90200","17.15876","0.09732"
"206.06400","17.17215","0.09762"
"206.22600","17.18566","0.09722"
"206.38800","17.19912","0.09788"
"206.55000","17.21263","0.09804"
"206.71200","17.22602","0.09825"
"206.87400","17.23971","0.09983"
"207.03600","17.25317","0.09990"
"207.19800","17.26668","0.10051"
"207.36000","17.28013","0.10107"
"207.52200","17.29370","0.10157"
"207.68400","17.30722","0.10285"
"207.84600","17.32067","0.10323"
"208.00800","17.33418","0.10457"
"208.17000","17.34769","0.10438"
"208.33200","17.36115","0.10597"
"208.49400","17.37472","0.10630"
"208.65600","17.38817","0.10810"
"208.81800","17.40168","0.10844"
"208.98000","17.41514","0.10973"
"209.14200","17.42871","0.11067"
"209.30400","17.44216","0.11189"
"209.46600","17.45567","0.11323"
"209.62800","17.46925","0.11405"
"209.79000","17.48276","0.11467"
"209.95200","17.49615","0.11665"
"210.11400","17.50972","0.11782"
"210.27600","17.52324","0.11847"
"210.43800","17.53663","0.12118"
"210.60000","17.55020","0.12117"
"210.76200","17.56371","0.12149"
"210.92400","17.57717","0.12134"
"211.08600","17.59068","0.12335"
"211.24800","17.60419","0.12456"
"211.41000","17.61770","0.12619"
"211.57200","17.63116","0.12751"
"211.73400","17.64473","0.12927"
"211.89600","17.65818","0.13044"
"212.05800","17.67163","0.13198"
"212.22000","17.68521","0.13288"
"212.38200","17.69872","0.13411"
"212.54400","17.71217","0.13449"
"212.70600","17.72562","0.13460"
"212.86800","17.73919","0.13590"
"213.03000","17.75265","0.13698"
"213.19200","17.76610","0.13724"
"213.35400","17.77967","0.13745"
"213.51600","17.79325","0.13780"
"213.67800","17.80664","0.13871"
"213.84000","17.82021","0.13949"
"214.00200","17.83372","0.14000"
"214.16400","17.84711","0.14020"
"214.32600","17.86063","0.14035"
"214.48800","17.87420","0.14103"
"214.65000","17.88771","0.14163"
"214.81200","17.90117","0.14173"
"214.97400","17.91468","0.14193"
"215.13600","17.92819","0.14199"
"215.29800","17.94164","0.14223"
"215.46000","17.95522","0.14250"
"215.62200","17.96867","0.14263"
"215.78400","17.98212","0.14255"
"215.94600","17.99563","0.14304"
"216.10800","18.00920","0.14322"
"216.27000","18.02266","0.14349"
"216.43200","18.03617","0.14373"
"216.59400","18.04968","0.14413"
"216.75600","18.06319","0.14430"
"216.91800","18.07665","0.14450"
"217.08000","18.09016","0.14437"
"217.24200","18.10373","0.14476"
"217.40400","18.11719","0.14498"
"217.56600","18.13070","0.14489"
"217.72800","18.14415","0.14519"
"217.89000","18.15766","0.14486"
"218.05200","18.17111","0.14539"
"218.21400","18.18469","0.14564"
"218.37600","18.19826","0.14522"
"218.53800","18.21165","0.14556"
"218.70000","18.22523","0.14518"
"218.86200","18.23874","0.14548"
"219.02400","18.25219","0.14579"
"219.18600","18.26564","0.14603"
"219.34800","18.27916","0.14586"
"219.51000","18.29267","0.14631"
"219.67200","18.30618","0.14671"
"219.83400","18.31969","0.14719"
"219.99600","18.33320","0.14734"
"220.15800","18.34660","0.14785"
"220.32000","18.36023","0.14763"
"220.48200","18.37374","0.14745"
"220.64400","18.38720","0.14768"
"220.80600","18.40071","0.14752"
"220.96800","18.41422","0.14809"
"221.13000","18.42773","0.14815"
"221.29200","18.44113","0.14832"
"221.45400","18.45470","0.14827"
"221.61600","18.46821","0.14874"
"221.77800","18.48160","0.14846"
"221.94000","18.49517","0.14899"
"222.10200","18.50875","0.14804"
"222.26400","18.52220","0.14822"
"222.42600","18.53565","0.00501"
"222.58800","18.54916","0.01012"
"222.75000","18.56268","0.00365"
"222.91200","18.57613","0.00493"
"223.07400","18.58970","0.00179"
"223.23600","18.60316","0.00321"
"223.39800","18.61661","0.00355"
"223.56000","18.63024","0.00317"
"223.72200","18.64375","0.00360"
"223.88400","18.65714","0.00341"
"224.04600","18.67066","0.00974"
"224.20800","18.68417","0.00299"
"224.37000","18.69762","0.00434"
"224.53200","18.71113","0.00302"
"224.69400","18.72471","0.00947"
"224.85600","18.73822","0.00348"
"225.01800","18.75167","0.00358"
"225.18000","18.76525","0.00406"
"225.34200","18.77870","0.00918"
"225.50400","18.79215","0.00276"
"225.66600","18.80566","0.00327"
"225.82800","18.81917","0.01306"
"225.99000","18.83269","0.00745"
"226.15200","18.84620","0.00269"
"226.31400","18.85971","0.00322"
"226.47600","18.87317","0.01672"
"226.63800","18.88668","0.00251"
"226.80000","18.90019","0.00210"
"226.96200","18.91370","0.00575"
"227.12400","18.92715","0.01828"
"227.28600","18.94067","0.00349"
"227.44800","18.95424","0.00288"
"227.61000","18.96763","0.00984"
"227.77200","18.98114","0.00907"
"227.93400","18.99466","0.00292"
"228.09600","19.00817","0.00283"
"228.25800","19.02162","0.01224"
"228.42000","19.03519","0.00482"
"228.58200","19.04871","0.00290"
"228.74400","19.06210","0.00389"
"228.90600","19.07567","0.01449"
"229.06800","19.08918","0.00269"
"229.23000","19.10264","0.00297"
"229.39200","19.11615","0.00838"
"229.55400","19.12972","0.00921"
"229.71600","19.14323","0.00288"
"229.87800","19.15663","0.00289"
"230.04000","19.17026","0.00917"
"230.20200","19.18371","0.00318"
"230.36400","19.19716","0.00229"
"230.52600","19.21062","0.00873"
"230.68800","19.22419","0.00896"
"230.85000","19.23764","0.00282"
"231.01200","19.25121","0.00305"
"231.17400","19.26473","0.01343"
"231.33600","19.27818","0.00323"
"231.49800","19.29163","0.00326"
"231.66000","19.30520","0.00333"
"231.82200","19.31866","0.01375"
"231.98400","19.33211","0.00350"
"232.14600","19.34568","0.00290"
"232.30800","19.35919","0.00527"
"232.47000","19.37265","0.01363"
"232.63200","19.38616","0.00357"
"232.79400","19.39967","0.00462"
"232.95600","19.41318","0.01328"
"233.11800","19.42664","0.00486"
"233.28000","19.44021","0.00356"
"233.44200","19.45372","0.01014"
"233.60400","19.46717","0.00918"
"233.76600","19.48075","0.00301"
"233.92800","19.49420","0.00309"
"234.09000","19.50765","0.01319"
"234.25200","19.52116","0.00528"
"234.41400","19.53468","0.00193"
"234.42000","19.53515","0.00194"