File: Force_trajectories/161114/Specimen_RawData_3.csv
End date,"11/14/2016"
Specimen label,"20AG59"
Maximum Load,"0.54546",N

Time,Extension,Load
(s),(mm),(N)
"0.00000","0.00000","-0.00116"
"0.32400","0.02661","-0.00086"
"0.64800","0.05423","-0.00018"
"0.97200","0.08119","-0.00006"
"1.29600","0.10822","0.00007"
"1.62000","0.13524","-0.00064"
"1.94400","0.16215","-0.00006"
"2.26800","0.18917","-0.00084"
"2.59200","0.21614","-0.00013"
"2.91600","0.24316","-0.00009"
"3.24000","0.27019","0.00062"
"3.56400","0.29715","0.00012"
"3.88800","0.32418","0.00030"
"4.21200","0.35114","0.00057"
"4.53600","0.37817","0.00121"
"4.86000","0.40513","0.00121"
"5.18400","0.43216","0.00031"
"5.50800","0.45918","0.00164"
"5.83200","0.48615","0.00140"
"6.15600","0.51317","0.00116"
"6.48000","0.54020","0.00128"
"6.80400","0.56710","0.00084"
"7.12800","0.59413","0.00137"
"7.45200","0.62109","0.00152"
"7.77600","0.64818","0.00190"
"8.10000","0.67514","0.00191"
"8.42400","0.70217","0.00197"
"8.74800","0.72913","0.00120"
"9.07200","0.75616","0.00229"
"9.39600","0.78306","0.00128"
"9.72000","0.81015","0.00226"
"10.04400","0.83711","0.00250"
"10.36800","0.86414","0.00171"
"10.69200","0.89116","0.00297"
"11.01600","0.91813","0.00281"
"11.34000","0.94521","0.00257"
"11.66400","0.97212","0.00316"
"11.98800","0.99920","0.00213"
"12.31200","1.02611","0.00256"
"12.63600","1.05319","0.00269"
"12.96000","1.08016","0.00241"
"13.28400","1.10712","0.00242"
"13.60800","1.13415","0.00285"
"13.93200","1.16117","0.00268"
"14.25600","1.18814","0.00307"
"14.58000","1.21522","0.00318"
"14.90400","1.24213","0.00364"
"15.22800","1.26915","0.00261"
"15.55200","1.29612","0.00261"
"15.87600","1.32320","0.00340"
"16.20000","1.35017","0.00319"
"16.52400","1.37713","0.00389"
"16.84800","1.40416","0.00343"
"17.17200","1.43112","0.00340"
"17.49600","1.45815","0.00315"
"17.82000","1.48517","0.00324"
"18.14400","1.51208","0.00378"
"18.46800","1.53916","0.00357"
"18.79200","1.56619","0.00365"
"19.11600","1.59321","0.00343"
"19.44000","1.62024","0.00372"
"19.76400","1.64708","0.00464"
"20.08800","1.67417","0.00470"
"20.41200","1.70119","0.00428"
"20.73600","1.72810","0.00417"
"21.06000","1.75512","0.00477"
"21.38400","1.78209","0.00439"
"21.70800","1.80917","0.00354"
"22.03200","1.83608","0.00479"
"22.35600","1.86316","0.00509"
"22.68000","1.89025","0.00525"
"23.00400","1.91715","0.00437"
"23.32800","1.94424","0.00429"
"23.65200","1.97114","0.00440"
"23.97600","1.99817","0.00424"
"24.30000","2.02513","0.00504"
"24.62400","2.05210","0.00520"
"24.94800","2.07918","0.00494"
"25.27200","2.10615","0.00503"
"25.59600","2.13311","0.00498"
"25.92000","2.16014","0.00508"
"26.24400","2.18710","0.00475"
"26.56800","2.21419","0.00554"
"26.89200","2.24115","0.00514"
"27.21600","2.26818","0.00571"
"27.54000","2.29514","0.00572"
"27.86400","2.32211","0.00640"
"28.18800","2.34913","0.00551"
"28.51200","2.37616","0.00654"
"28.83600","2.40312","0.00651"
"29.16000","2.43021","0.00655"
"29.48400","2.45705","0.00635"
"29.80800","2.48420","0.00650"
"30.13200","2.51116","0.00591"
"30.45600","2.53813","0.00700"
"30.78000","2.56515","0.00680"
"31.10400","2.59212","0.00710"
"31.42800","2.61920","0.00721"
"31.75200","2.64616","0.00639"
"32.07600","2.67313","0.00693"
"32.40000","2.70016","0.00657"
"32.72400","2.72712","0.00671"
"33.04800","2.75414","0.00739"
"33.37200","2.78117","0.00732"
"33.69600","2.80814","0.00788"
"34.02000","2.83516","0.00821"
"34.34400","2.86212","0.00841"
"34.66800","2.88915","0.00829"
"34.99200","2.91612","0.00836"
"35.31600","2.94320","0.00873"
"35.64000","2.97016","0.00866"
"35.96600","2.99731","0.00726"
"36.29000","3.02433","0.00784"
"36.61400","3.05136","0.00852"
"36.93800","3.07832","0.00874"
"37.26200","3.10535","0.00873"
"37.58600","3.13231","0.00883"
"37.91000","3.15934","0.00906"
"38.23400","3.18636","0.00856"
"38.55800","3.21333","0.00904"
"38.88200","3.24035","0.00884"
"39.20600","3.26726","0.00798"
"39.53000","3.29434","0.00987"
"39.85400","3.32137","0.01036"
"40.17800","3.34833","0.01033"
"40.50200","3.37536","0.00951"
"40.82600","3.40226","0.00991"
"41.15000","3.42929","0.01018"
"41.47400","3.45631","0.01000"
"41.79800","3.48334","0.01041"
"42.12200","3.51036","0.01016"
"42.44600","3.53727","0.01102"
"42.77000","3.56435","0.00999"
"43.09400","3.59138","0.01074"
"43.41800","3.61828","0.01002"
"43.74200","3.64537","0.01101"
"44.06600","3.67239","0.01121"
"44.39000","3.69930","0.01167"
"44.71400","3.72632","0.01168"
"45.03800","3.75329","0.01197"
"45.36200","3.78037","0.01221"
"45.68600","3.80734","0.01187"
"46.01000","3.83430","0.01133"
"46.33400","3.86133","0.01214"
"46.65800","3.88829","0.01253"
"46.98200","3.91532","0.01275"
"47.30600","3.94228","0.01224"
"47.63000","3.96931","0.01266"
"47.95400","3.99633","0.01244"
"48.27800","4.02330","0.01355"
"48.60200","4.05032","0.01335"
"48.92600","4.07729","0.01336"
"49.25000","4.10437","0.01353"
"49.57400","4.13128","0.01313"
"49.89800","4.15824","0.01345"
"50.22200","4.18533","0.01378"
"50.54600","4.21235","0.01348"
"50.87000","4.23932","0.01434"
"51.19400","4.26628","0.01346"
"51.51800","4.29325","0.01537"
"51.84200","4.32027","0.01422"
"52.16600","4.34730","0.01469"
"52.49000","4.37426","0.01466"
"52.81400","4.40141","0.01479"
"53.13800","4.42831","0.01456"
"53.46200","4.45534","0.01434"
"53.78600","4.48230","0.01303"
"54.11000","4.50927","0.01366"
"54.43400","4.53635","0.01458"
"54.75800","4.56326","0.01289"
"55.08200","4.59034","0.01308"
"55.40600","4.61731","0.01418"
"55.73000","4.64433","0.01470"
"56.05400","4.67136","0.01407"
"56.37800","4.69826","0.01461"
"56.70200","4.72541","0.01541"
"57.02600","4.75231","0.01487"
"57.35000","4.77928","0.01563"
"57.67400","4.80636","0.01461"
"57.99800","4.83333","0.01542"
"58.32200","4.86029","0.01506"
"58.64600","4.88732","0.01553"
"58.97000","4.91434","0.01526"
"59.29400","4.94137","0.01550"
"59.61800","4.96827","0.01355"
"59.94200","4.99530","0.01326"
"60.26600","5.02232","0.01295"
"60.59000","5.04929","0.01315"
"60.91400","5.07631","0.01380"
"61.23800","5.10328","0.01389"
"61.56200","5.13036","0.01420"
"61.88600","5.15739","0.01424"
"62.21000","5.18429","0.01414"
"62.53400","5.21132","0.01414"
"62.85800","5.23828","0.01397"
"63.18200","5.26531","0.01477"
"63.50600","5.29233","0.01476"
"63.83000","5.31930","0.01483"
"64.15400","5.34638","0.01597"
"64.47800","5.37335","0.01657"
"64.80200","5.40031","0.01515"
"65.12600","5.42728","0.01573"
"65.45000","5.45430","0.01587"
"65.77400","5.48139","0.01656"
"66.09800","5.50829","0.01654"
"66.42200","5.53532","0.01689"
"66.74600","5.56234","0.01722"
"67.07000","5.58924","0.01700"
"67.39400","5.61633","0.01671"
"67.71800","5.64330","0.01723"
"68.04200","5.67038","0.01685"
"68.36600","5.69728","0.01692"
"68.69000","5.72431","0.01735"
"69.01400","5.75133","0.01732"
"69.33800","5.77830","0.01758"
"69.66200","5.80532","0.01750"
"69.98600","5.83235","0.01732"
"70.31000","5.85931","0.01825"
"70.63400","5.88640","0.01809"
"70.95800","5.91330","0.01863"
"71.28200","5.94033","0.01827"
"71.60600","5.96735","0.01849"
"71.93000","5.99432","0.01847"
"72.25400","6.02134","0.01862"
"72.57800","6.04825","0.01907"
"72.90200","6.07533","0.01895"
"73.22600","6.10236","0.01956"
"73.55000","6.12926","0.01949"
"73.87400","6.15635","0.01971"
"74.19800","6.18331","0.02021"
"74.52200","6.21034","0.02007"
"74.84600","6.23736","0.02042"
"75.17000","6.26427","0.02091"
"75.49400","6.29135","0.02076"
"75.81800","6.31832","0.02051"
"76.14200","6.34534","0.02065"
"76.46600","6.37231","0.02099"
"76.79000","6.39927","0.02140"
"77.11400","6.42636","0.02135"
"77.43800","6.45326","0.02217"
"77.76200","6.48029","0.02155"
"78.08600","6.50737","0.02150"
"78.41000","6.53434","0.02189"
"78.73400","6.56136","0.02210"
"79.05800","6.58833","0.02208"
"79.38200","6.61535","0.02351"
"79.70600","6.64232","0.02387"
"80.03000","6.66928","0.02386"
"80.35400","6.69637","0.02355"
"80.67800","6.72333","0.02330"
"81.00200","6.75036","0.02445"
"81.32600","6.77732","0.02390"
"81.65000","6.80429","0.02534"
"81.97400","6.83137","0.02417"
"82.29800","6.85828","0.02525"
"82.62200","6.88530","0.02494"
"82.94600","6.91233","0.02523"
"83.27000","6.93929","0.02559"
"83.59400","6.96638","0.02649"
"83.91800","6.99328","0.02629"
"84.24200","7.02025","0.02563"
"84.56600","7.04733","0.02634"
"84.89000","7.07424","0.02719"
"85.21400","7.10132","0.02665"
"85.53800","7.12835","0.02723"
"85.86200","7.15531","0.02783"
"86.18800","7.18252","0.02740"
"86.51200","7.20942","0.02730"
"86.83600","7.23651","0.02749"
"87.16000","7.26353","0.02813"
"87.48400","7.29044","0.02851"
"87.80800","7.31746","0.02864"
"88.13200","7.34443","0.02876"
"88.45600","7.37151","0.02932"
"88.78000","7.39848","0.02923"
"89.10400","7.42544","0.02977"
"89.42800","7.45253","0.02969"
"89.75200","7.47943","0.03015"
"90.07600","7.50646","0.03019"
"90.40000","7.53348","0.03034"
"90.72400","7.56045","0.03089"
"91.04800","7.58747","0.03107"
"91.37200","7.61444","0.03147"
"91.69600","7.64152","0.03162"
"92.02000","7.66849","0.03192"
"92.34400","7.69545","0.03249"
"92.66800","7.72248","0.03282"
"92.99200","7.74944","0.03276"
"93.31600","7.77653","0.03291"
"93.64000","7.80349","0.03330"
"93.96400","7.83046","0.03380"
"94.28800","7.85754","0.03453"
"94.61200","7.88445","0.03443"
"94.93600","7.91141","0.03464"
"95.26000","7.93849","0.03492"
"95.58400","7.96546","0.03551"
"95.90800","7.99255","0.03542"
"96.23200","8.01951","0.03604"
"96.55600","8.04648","0.03613"
"96.88000","8.07356","0.03678"
"97.20400","8.10046","0.03649"
"97.52800","8.12749","0.03698"
"97.85200","8.15445","0.03717"
"98.17600","8.18148","0.03800"
"98.50000","8.20850","0.03674"
"98.82400","8.23547","0.03688"
"99.14800","8.26255","0.03707"
"99.47200","8.28946","0.03736"
"99.79600","8.31649","0.03780"
"100.12000","8.34351","0.03789"
"100.44400","8.37047","0.03865"
"100.76800","8.39756","0.03866"
"101.09200","8.42446","0.03880"
"101.41600","8.45149","0.03929"
"101.74000","8.47857","0.03956"
"102.06400","8.50548","0.03968"
"102.38800","8.53250","0.03997"
"102.71200","8.55941","0.04015"
"103.03600","8.58649","0.04067"
"103.36000","8.61352","0.04137"
"103.68400","8.64042","0.04128"
"104.00800","8.66751","0.04130"
"104.33200","8.69447","0.04196"
"104.65600","8.72150","0.04215"
"104.98000","8.74852","0.04266"
"105.30400","8.77543","0.04291"
"105.62800","8.80251","0.04278"
"105.95200","8.82948","0.04381"
"106.27600","8.85644","0.04405"
"106.60000","8.88347","0.04416"
"106.92400","8.91043","0.04420"
"107.24800","8.93752","0.04489"
"107.57200","8.96448","0.04487"
"107.89600","8.99145","0.04491"
"108.22000","9.01853","0.04519"
"108.54400","9.04544","0.04530"
"108.86800","9.07258","0.04580"
"109.19200","9.09949","0.04598"
"109.51600","9.12651","0.04608"
"109.84000","9.15348","0.04634"
"110.16400","9.18038","0.04677"
"110.48800","9.20753","0.04717"
"110.81200","9.23443","0.04763"
"111.13600","9.26146","0.04763"
"111.46000","9.28848","0.04727"
"111.78400","9.31545","0.04773"
"112.10800","9.34253","0.04779"
"112.43200","9.36950","0.04799"
"112.75600","9.39646","0.04845"
"113.08000","9.42355","0.04836"
"113.40400","9.45045","0.04849"
"113.72800","9.47754","0.04868"
"114.05200","9.50444","0.04897"
"114.37600","9.53147","0.04899"
"114.70000","9.55849","0.04909"
"115.02400","9.58546","0.04926"
"115.34800","9.61248","0.04938"
"115.67200","9.63951","0.04882"
"115.99600","9.66647","0.04955"
"116.32000","9.69350","0.04969"
"116.64400","9.72046","0.04942"
"116.96800","9.74755","0.04997"
"117.29200","9.77445","0.05013"
"117.61600","9.80148","0.05020"
"117.94000","9.82850","0.05057"
"118.26400","9.85547","0.05051"
"118.58800","9.88249","0.05075"
"118.91200","9.90952","0.05097"
"119.23600","9.93648","0.05112"
"119.56000","9.96357","0.05140"
"119.88400","9.99047","0.05159"
"120.20800","10.01750","0.05160"
"120.53200","10.04446","0.05171"
"120.85600","10.07143","0.05196"
"121.18000","10.09845","0.05188"
"121.50400","10.12542","0.05205"
"121.82800","10.15250","0.05219"
"122.15200","10.17953","0.05231"
"122.47600","10.20643","0.05248"
"122.80000","10.23346","0.05239"
"123.12400","10.26042","0.05258"
"123.44800","10.28757","0.05275"
"123.77200","10.31453","0.05277"
"124.09600","10.34150","0.05282"
"124.42000","10.36852","0.05289"
"124.74400","10.39543","0.05293"
"125.06800","10.42245","0.05304"
"125.39200","10.44948","0.05305"
"125.71600","10.47650","0.05309"
"126.04000","10.50347","0.05316"
"126.36400","10.53043","0.05327"
"126.68800","10.55752","0.05329"
"127.01200","10.58454","0.05333"
"127.33600","10.61145","0.05342"
"127.66000","10.63853","0.05342"
"127.98400","10.66544","0.05345"
"128.30800","10.69246","0.05352"
"128.63200","10.71949","0.05364"
"128.95600","10.74645","0.05378"
"129.28000","10.77348","0.05386"
"129.60400","10.80050","0.05408"
"129.92800","10.82747","0.05402"
"130.25200","10.85449","0.05433"
"130.57600","10.88146","0.05467"
"130.90000","10.90848","0.05468"
"131.22400","10.93545","0.05484"
"131.54800","10.96247","0.05540"
"131.87200","10.98950","0.05568"
"132.19600","11.01646","0.05592"
"132.52000","11.04349","0.05638"
"132.84400","11.07045","0.05677"
"133.16800","11.09748","0.05741"
"133.49200","11.12456","0.05781"
"133.81600","11.15141","0.05810"
"134.14000","11.17849","0.05901"
"134.46400","11.20552","0.05904"
"134.78800","11.23254","0.05983"
"135.11200","11.25950","0.06029"
"135.43600","11.28647","0.06104"
"135.76000","11.31349","0.06134"
"136.08400","11.34052","0.06208"
"136.40800","11.36749","0.06343"
"136.73200","11.39451","0.06386"
"137.05600","11.42148","0.06457"
"137.38000","11.44850","0.06550"
"137.70400","11.47546","0.06639"
"138.02800","11.50243","0.06733"
"138.35200","11.52951","0.06865"
"138.67600","11.55648","0.06907"
"139.00000","11.58351","0.07048"
"139.32400","11.61053","0.07149"
"139.64800","11.63750","0.07287"
"139.97200","11.66452","0.07475"
"140.29600","11.69142","0.07505"
"140.62000","11.71851","0.07756"
"140.94400","11.74547","0.07774"
"141.26800","11.77244","0.07936"
"141.59200","11.79947","0.07997"
"141.91600","11.82649","0.08119"
"142.24000","11.85351","0.08191"
"142.56400","11.88048","0.08299"
"142.88800","11.90744","0.08380"
"143.21200","11.93447","0.08459"
"143.53600","11.96143","0.08545"
"143.86000","11.98852","0.08622"
"144.18400","12.01548","0.08665"
"144.50800","12.04245","0.08769"
"144.83200","12.06953","0.08851"
"145.15600","12.09644","0.08936"
"145.48000","12.12346","0.09035"
"145.80400","12.15049","0.09131"
"146.12800","12.17751","0.09232"
"146.45200","12.20448","0.09382"
"146.77600","12.23138","0.09454"
"147.10000","12.25853","0.09510"
"147.42400","12.28549","0.09693"
"147.74800","12.31246","0.09858"
"148.07200","12.33948","0.10088"
"148.39600","12.36645","0.10220"
"148.72000","12.39353","0.10509"
"149.04400","12.42050","0.10770"
"149.36800","12.44746","0.11043"
"149.69200","12.47449","0.11295"
"150.01600","12.50139","0.11468"
"150.34000","12.52848","0.11795"
"150.66400","12.55550","0.11843"
"150.98800","12.58247","0.12102"
"151.31200","12.60949","0.12304"
"151.63600","12.63640","0.12384"
"151.96000","12.66354","0.12587"
"152.28400","12.69045","0.12730"
"152.60800","12.71747","0.12893"
"152.93200","12.74450","0.13033"
"153.25600","12.77146","0.13200"
"153.58000","12.79855","0.13375"
"153.90400","12.82551","0.13447"
"154.22800","12.85242","0.13598"
"154.55200","12.87956","0.13632"
"154.87600","12.90647","0.13738"
"155.20000","12.93349","0.13784"
"155.52400","12.96052","0.13857"
"155.84800","12.98748","0.13888"
"156.17200","13.01445","0.13928"
"156.49600","13.04147","0.13961"
"156.82000","13.06850","0.14010"
"157.14400","13.09552","0.14045"
"157.46800","13.12243","0.14088"
"157.79200","13.14951","0.14165"
"158.11600","13.17642","0.14174"
"158.44000","13.20356","0.14238"
"158.76400","13.23053","0.14307"
"159.08800","13.25749","0.14448"
"159.41200","13.28452","0.14535"
"159.73600","13.31148","0.14648"
"160.06000","13.33851","0.14795"
"160.38400","13.36547","0.14861"
"160.70800","13.39244","0.15005"
"161.03200","13.41958","0.15203"
"161.35600","13.44649","0.15322"
"161.68000","13.47351","0.15519"
"162.00400","13.50054","0.15589"
"162.32800","13.52750","0.15690"
"162.65200","13.55447","0.15912"
"162.97600","13.58149","0.16065"
"163.30000","13.60852","0.16223"
"163.62400","13.63554","0.16321"
"163.94800","13.66245","0.16506"
"164.27200","13.68947","0.16680"
"164.59600","13.71650","0.16865"
"164.92000","13.74352","0.17055"
"165.24400","13.77049","0.17273"
"165.56800","13.79745","0.17385"
"165.89200","13.82454","0.17579"
"166.21600","13.85150","0.17722"
"166.54000","13.87853","0.17892"
"166.86400","13.90549","0.18065"
"167.18800","13.93246","0.18266"
"167.51200","13.95954","0.18402"
"167.83600","13.98645","0.18533"
"168.16000","14.01347","0.18794"
"168.48400","14.04050","0.18990"
"168.80800","14.06740","0.19161"
"169.13200","14.09455","0.19354"
"169.45600","14.12145","0.19500"
"169.78000","14.14854","0.19736"
"170.10400","14.17550","0.19881"
"170.42800","14.20241","0.19989"
"170.75200","14.22949","0.20032"
"171.07600","14.25651","0.20122"
"171.40000","14.28348","0.20132"
"171.72400","14.31056","0.20153"
"172.04800","14.33747","0.20165"
"172.37200","14.36450","0.20190"
"172.69600","14.39146","0.20200"
"173.02000","14.41848","0.20227"
"173.34400","14.44551","0.20313"
"173.66800","14.47248","0.20385"
"173.99200","14.49950","0.20484"
"174.31600","14.52653","0.20710"
"174.64000","14.55349","0.20874"
"174.96400","14.58058","0.21133"
"175.28800","14.60736","0.21219"
"175.61200","14.63451","0.21394"
"175.93600","14.66147","0.21611"
"176.26000","14.68849","0.21738"
"176.58400","14.71546","0.21756"
"176.90800","14.74243","0.21646"
"177.23200","14.76951","0.21811"
"177.55600","14.79648","0.21959"
"177.88000","14.82350","0.22178"
"178.20400","14.85046","0.22343"
"178.52800","14.87749","0.22521"
"178.85200","14.90451","0.22685"
"179.17600","14.93148","0.22849"
"179.50000","14.95850","0.23004"
"179.82400","14.98547","0.23152"
"180.14800","15.01244","0.23355"
"180.47200","15.03952","0.23420"
"180.79600","15.06648","0.23592"
"181.12000","15.09345","0.23700"
"181.44400","15.12047","0.23793"
"181.76800","15.14738","0.23961"
"182.09200","15.17447","0.23998"
"182.41600","15.20149","0.24059"
"182.74000","15.22845","0.24182"
"183.06400","15.25548","0.24301"
"183.38800","15.28244","0.24376"
"183.71200","15.30953","0.24501"
"184.03600","15.33649","0.24680"
"184.36000","15.36346","0.24842"
"184.68400","15.39054","0.25098"
"185.00800","15.41745","0.25330"
"185.33200","15.44453","0.25653"
"185.65600","15.47144","0.25925"
"185.98000","15.49846","0.26246"
"186.30400","15.52549","0.26531"
"186.62800","15.55245","0.26741"
"186.95200","15.57954","0.27016"
"187.27600","15.60644","0.27249"
"187.60000","15.63341","0.27487"
"187.92400","15.66049","0.27828"
"188.24800","15.68740","0.28204"
"188.57200","15.71448","0.28633"
"188.89600","15.74151","0.28929"
"189.22000","15.76847","0.29243"
"189.54400","15.79550","0.29553"
"189.86800","15.82246","0.29714"
"190.19200","15.84949","0.30020"
"190.51600","15.87651","0.30107"
"190.84000","15.90342","0.30318"
"191.16400","15.93050","0.30531"
"191.48800","15.95747","0.30766"
"191.81200","15.98443","0.31135"
"192.13600","16.01152","0.31493"
"192.46000","16.03842","0.31996"
"192.78400","16.06551","0.32440"
"193.10800","16.09241","0.32709"
"193.43200","16.11950","0.32997"
"193.75600","16.14652","0.33307"
"194.08000","16.17343","0.33547"
"194.40400","16.20051","0.33770"
"194.72800","16.22748","0.33937"
"195.05200","16.25450","0.34166"
"195.37600","16.28147","0.34373"
"195.70000","16.30843","0.34516"
"196.02400","16.33552","0.34696"
"196.34800","16.36248","0.34806"
"196.67200","16.38951","0.34893"
"196.99600","16.41647","0.34944"
"197.32000","16.44350","0.34975"
"197.64400","16.47052","0.34993"
"197.96800","16.49743","0.35005"
"198.29200","16.52445","0.35015"
"198.61600","16.55153","0.35026"
"198.94000","16.57844","0.35039"
"199.26400","16.60553","0.35075"
"199.58800","16.63249","0.35147"
"199.91200","16.65952","0.35250"
"200.23600","16.68654","0.35314"
"200.56000","16.71345","0.35499"
"200.88400","16.74053","0.35653"
"201.20800","16.76756","0.35901"
"201.53200","16.79452","0.36133"
"201.85600","16.82149","0.36413"
"202.18000","16.84845","0.36630"
"202.50400","16.87554","0.36908"
"202.82800","16.90250","0.37196"
"203.15200","16.92947","0.18978"
"203.47600","16.95655","0.20245"
"203.80000","16.98346","0.19933"
"204.12400","17.01054","0.19501"
"204.44800","17.03751","0.19831"
"204.77200","17.06447","0.20177"
"205.09600","17.09150","0.20543"
"205.42000","17.11846","0.20260"
"205.74400","17.14548","0.20195"
"206.06800","17.17251","0.20310"
"206.39200","17.19948","0.21365"
"206.71600","17.22650","0.22047"
"207.04000","17.25341","0.21663"
"207.36400","17.28049","0.21431"
"207.68800","17.30746","0.21627"
"208.01200","17.33448","0.22295"
"208.33600","17.36144","0.23087"
"208.66000","17.38847","0.23273"
"208.98400","17.41549","0.23136"
"209.30800","17.44246","0.23089"
"209.63200","17.46948","0.23321"
"209.95600","17.49651","0.23732"
"210.28000","17.52336","0.24222"
"210.60400","17.55050","0.24523"
"210.92800","17.57747","0.24529"
"211.25200","17.60449","0.24472"
"211.57600","17.63145","0.24513"
"211.90000","17.65842","0.24798"
"212.22400","17.68550","0.25301"
"212.54800","17.71253","0.25950"
"212.87200","17.73949","0.26555"
"213.19600","17.76646","0.26844"
"213.52000","17.79342","0.26921"
"213.84400","17.82051","0.27037"
"214.16800","17.84748","0.27223"
"214.49200","17.87450","0.27535"
"214.81600","17.90153","0.27907"
"215.14000","17.92849","0.28691"
"215.46400","17.95551","0.29429"
"215.78800","17.98248","0.29869"
"216.11200","18.00950","0.30208"
"216.43600","18.03653","0.30489"
"216.76000","18.06350","0.30694"
"217.08400","18.09052","0.31054"
"217.40800","18.11748","0.31216"
"217.73200","18.14445","0.31506"
"218.05600","18.17147","0.31969"
"218.38000","18.19844","0.32302"
"218.70400","18.22552","0.32814"
"219.02800","18.25255","0.33160"
"219.35200","18.27945","0.33577"
"219.67600","18.30648","0.33923"
"220.00000","18.33350","0.34196"
"220.32400","18.36053","0.34502"
"220.64800","18.38755","0.34690"
"220.97200","18.41446","0.34853"
"221.29600","18.44148","0.34945"
"221.62000","18.46845","0.34982"
"221.94400","18.49547","0.35003"
"222.26800","18.52250","0.35012"
"222.59200","18.54946","0.35024"
"222.91600","18.57649","0.35043"
"223.24000","18.60345","0.35070"
"223.56400","18.63048","0.35105"
"223.88800","18.65756","0.35167"
"224.21200","18.68447","0.35262"
"224.53600","18.71149","0.35389"
"224.86000","18.73846","0.35560"
"225.18400","18.76548","0.35747"
"225.50800","18.79251","0.36013"
"225.83200","18.81941","0.36283"
"226.15600","18.84650","0.36680"
"226.48000","18.87346","0.36970"
"226.80400","18.90049","0.37353"
"227.12800","18.92751","0.37724"
"227.45200","18.95448","0.37993"
"227.77600","18.98150","0.38508"
"228.10000","19.00847","0.38891"
"228.42400","19.03549","0.39400"
"228.74800","19.06246","0.39719"
"229.07200","19.08942","0.40076"
"229.39600","19.11651","0.40204"
"229.72000","19.14347","0.40434"
"230.04400","19.17050","0.40631"
"230.36800","19.19746","0.40943"
"230.69200","19.22437","0.41301"
"231.01600","19.25151","0.39347"
"231.34000","19.27848","0.37813"
"231.66400","19.30544","0.37744"
"231.98800","19.33247","0.37246"
"232.31200","19.35943","0.37249"
"232.63600","19.38646","0.37685"
"232.96000","19.41342","0.38071"
"233.28400","19.44045","0.38528"
"233.60800","19.46753","0.39111"
"233.93200","19.49450","0.39619"
"234.25600","19.52152","0.34651"
"234.58000","19.54849","0.34965"
"234.90400","19.57545","0.34962"
"235.22800","19.60254","0.34967"
"235.55200","19.62944","0.34998"
"235.87600","19.65652","0.35011"
"236.20000","19.68349","0.35021"
"236.52400","19.71051","0.35038"
"236.84800","19.73754","0.35067"
"237.17200","19.76439","0.35131"
"237.49600","19.79153","0.35263"
"237.82000","19.81843","0.35397"
"238.14400","19.84546","0.35594"
"238.46800","19.87249","0.35887"
"238.79200","19.89945","0.36286"
"239.11600","19.92648","0.36662"
"239.44000","19.95350","0.22068"
"239.76400","19.98047","0.20637"
"240.08800","20.00749","0.20577"
"240.41200","20.03445","0.20162"
"240.73600","20.06148","0.20364"
"241.06000","20.08845","0.21808"
"241.38400","20.11547","0.22255"
"241.70800","20.14250","0.21989"
"242.03200","20.16946","0.22435"
"242.35600","20.19655","0.23622"
"242.68000","20.22351","0.24051"
"243.00400","20.25047","0.23870"
"243.32800","20.27750","0.23983"
"243.65200","20.30446","0.24468"
"243.97600","20.33149","0.25121"
"244.30000","20.35852","0.25845"
"244.62400","20.38548","0.26424"
"244.94800","20.41256","0.26594"
"245.27200","20.43947","0.26750"
"245.59600","20.46644","0.27258"
"245.92000","20.49352","0.28057"
"246.24400","20.52048","0.29123"
"246.56800","20.54751","0.29775"
"246.89200","20.57442","0.30129"
"247.21600","20.60150","0.30389"
"247.54000","20.62852","0.30653"
"247.86400","20.65543","0.31309"
"248.18800","20.68246","0.32261"
"248.51200","20.70948","0.33167"
"248.83600","20.73650","0.33665"
"249.16000","20.76353","0.34199"
"249.48400","20.79049","0.34512"
"249.80800","20.81746","0.34746"
"250.13200","20.84449","0.34866"
"250.45600","20.87145","0.34964"
"250.78000","20.89847","0.35003"
"251.10400","20.92544","0.35024"
"251.42800","20.95252","0.35056"
"251.75200","20.97949","0.35117"
"252.07600","21.00646","0.35346"
"252.40000","21.03354","0.35733"
"252.72400","21.06044","0.36256"
"253.04800","21.08753","0.36789"
"253.37200","21.11449","0.37351"
"253.69600","21.14146","0.37869"
"254.02000","21.16854","0.38537"
"254.34400","21.19545","0.39196"
"254.66800","21.22247","0.39858"
"254.99200","21.24950","0.40173"
"255.31600","21.27652","0.40440"
"255.64000","21.30349","0.40913"
"255.96400","21.33046","0.41486"
"256.28800","21.35748","0.42218"
"256.61200","21.38444","0.42840"
"256.93600","21.41147","0.43538"
"257.26000","21.43849","0.44047"
"257.58400","21.46546","0.44481"
"257.90800","21.49249","0.44887"
"258.23200","21.51945","0.45170"
"258.55600","21.54647","0.45580"
"258.88000","21.57356","0.45903"
"259.20400","21.60046","0.46184"
"259.52800","21.62749","0.46455"
"259.85200","21.65451","0.46635"
"260.17600","21.68154","0.46830"
"260.50000","21.70850","0.47086"
"260.82400","21.73541","0.47365"
"261.14800","21.76249","0.47664"
"261.47200","21.78952","0.47946"
"261.79600","21.81648","0.48310"
"262.12000","21.84351","0.48737"
"262.44400","21.87047","0.49058"
"262.76800","21.89750","0.49480"
"263.09200","21.92446","0.49822"
"263.41600","21.95149","0.50042"
"263.74000","21.97851","0.50178"
"264.06400","22.00548","0.50311"
"264.38800","22.03250","0.50404"
"264.71200","22.05947","0.50494"
"265.03600","22.08649","0.50743"
"265.36000","22.11352","0.51072"
"265.68400","22.14042","0.51636"
"266.00800","22.16751","0.52175"
"266.33200","22.19447","0.52585"
"266.65600","22.22150","0.53017"
"266.98000","22.24852","0.53512"
"267.30400","22.27543","0.53902"
"267.62800","22.30251","0.54294"
"267.95200","22.32948","0.09189"
"268.27600","22.35644","0.04422"
"268.60000","22.38347","0.03397"
"268.92400","22.41043","0.02711"
"269.24800","22.43746","0.00558"
"269.57200","22.46448","0.01569"
"269.89600","22.49145","0.02886"
"270.22000","22.51853","0.02804"
"270.54400","22.54544","0.02512"
"270.86800","22.57246","0.02975"
"271.19200","22.59943","0.01356"
"271.51600","22.62651","0.03208"
"271.84000","22.65347","0.02350"
"272.16400","22.68044","0.02891"
"272.48800","22.70753","0.02692"
"272.81200","22.73443","0.03314"
"273.13600","22.76146","0.02921"
"273.46000","22.78842","0.03475"
"273.78400","22.81539","0.03038"
"274.10800","22.84247","0.03624"
"274.43200","22.86950","0.03438"
"274.75600","22.89646","0.03756"
"275.08000","22.92355","0.03680"
"275.40400","22.95051","0.03916"
"275.72800","22.97748","0.03938"
"276.05200","23.00450","0.04033"
"276.37600","23.03147","0.04144"
"276.70000","23.05849","0.04207"
"277.02400","23.08546","0.04306"
"277.34800","23.11248","0.04369"
"277.67200","23.13951","0.04412"
"277.99600","23.16647","0.04457"
"278.32000","23.19350","0.04537"
"278.64400","23.22046","0.04588"
"278.96800","23.24755","0.04662"
"279.29200","23.27451","0.04687"
"279.61600","23.30148","0.04689"
"279.94000","23.32850","0.04753"
"280.26400","23.35547","0.04809"
"280.58800","23.38249","0.04875"
"280.91200","23.40952","0.04906"
"281.23600","23.43648","0.04924"
"281.56000","23.46351","0.04965"
"281.88400","23.49047","0.05004"
"282.20800","23.51750","0.05029"
"282.53200","23.54452","0.05055"
"282.85600","23.57149","0.05081"
"283.18000","23.59851","0.05096"
"283.50400","23.62542","0.05123"
"283.82800","23.65250","0.05136"
"284.15200","23.67953","0.05161"
"284.47600","23.70643","0.05191"
"284.80000","23.73345","0.05205"
"285.12400","23.76048","0.05205"
"285.44800","23.78751","0.05247"
"285.77200","23.81453","0.05241"
"286.09600","23.84143","0.05257"
"286.42000","23.86852","0.05272"
"286.74400","23.89548","0.05283"
"287.06800","23.92251","0.05296"
"287.39200","23.94954","0.05306"
"287.71600","23.97644","0.05305"
"288.04000","24.00353","0.05320"
"288.36400","24.03043","0.05318"
"288.68800","24.05746","0.05333"
"289.01200","24.08448","0.05338"
"289.33600","24.11145","0.05343"
"289.66000","24.13853","0.05356"
"289.98400","24.16543","0.05366"
"290.30800","24.19246","0.05389"
"290.63200","24.21955","0.05409"
"290.95600","24.24645","0.05419"
"291.28000","24.27347","0.05435"
"291.60400","24.30050","0.05485"
"291.92800","24.32747","0.05501"
"292.25200","24.35449","0.05541"
"292.57600","24.38145","0.05554"
"292.90000","24.40848","0.05636"
"293.22400","24.43545","0.05642"
"293.54800","24.46247","0.05715"
"293.87200","24.48949","0.05748"
"294.19600","24.51646","0.05830"
"294.52000","24.54348","0.05900"
"294.84400","24.57051","0.05920"
"295.16800","24.59748","0.06017"
"295.49200","24.62456","0.06074"
"295.81600","24.65140","0.06164"
"296.14000","24.67849","0.06219"
"296.46400","24.70545","0.06347"
"296.78800","24.73248","0.06376"
"297.11200","24.75950","0.06508"
"297.43600","24.78641","0.06625"
"297.76000","24.81355","0.06699"
"298.08400","24.84052","0.06836"
"298.40800","24.86749","0.06568"
"298.73200","24.89445","0.06597"
"299.05600","24.92147","0.06872"
"299.38000","24.94850","0.06987"
"299.70400","24.97546","0.07186"
"300.02800","25.00249","0.07457"
"300.35200","25.02951","0.07497"
"300.67600","25.05648","0.07759"
"301.00000","25.08350","0.07824"
"301.32400","25.11047","0.07972"
"301.64800","25.13749","0.08197"
"301.97200","25.16452","0.08294"
"302.29600","25.19142","0.08406"
"302.62000","25.21851","0.08532"
"302.94400","25.24553","0.08611"
"303.26800","25.27244","0.08698"
"303.59200","25.29946","0.08792"
"303.91600","25.32643","0.08903"
"304.24000","25.35357","0.08943"
"304.56400","25.38054","0.08991"
"304.88800","25.40751","0.09094"
"305.21200","25.43453","0.09187"
"305.53600","25.46149","0.09409"
"305.86000","25.48846","0.09552"
"306.18400","25.51548","0.09774"
"306.50800","25.54251","0.09953"
"306.83200","25.56953","0.10185"
"307.15600","25.59638","0.10548"
"307.48000","25.62352","0.10746"
"307.80400","25.65049","0.11046"
"308.12800","25.67745","0.11252"
"308.45200","25.70454","0.11528"
"308.77600","25.73144","0.11768"
"309.10000","25.75853","0.10998"
"309.42400","25.78543","0.11203"
"309.74800","25.81246","0.11721"
"310.07200","25.83948","0.11937"
"310.39600","25.86645","0.12142"
"310.72000","25.89347","0.12508"
"311.04400","25.92050","0.12606"
"311.36800","25.94740","0.12858"
"311.69200","25.97455","0.13076"
"312.01600","26.00145","0.13181"
"312.34000","26.02847","0.13396"
"312.66400","26.05550","0.13485"
"312.98800","26.08247","0.13584"
"313.31200","26.10955","0.13716"
"313.63600","26.13640","0.13777"
"313.96000","26.16348","0.13857"
"314.28400","26.19050","0.13907"
"314.60800","26.21747","0.13934"
"314.93200","26.24450","0.13985"
"315.25600","26.27146","0.14022"
"315.58000","26.29855","0.14091"
"315.90400","26.32545","0.14126"
"316.22800","26.35248","0.14128"
"316.55200","26.37950","0.14232"
"316.87600","26.40647","0.14291"
"317.20000","26.43349","0.14341"
"317.52400","26.46052","0.14126"
"317.84800","26.48742","0.12436"
"318.17200","26.51450","0.10082"
"318.49600","26.54147","0.11182"
"318.82000","26.56844","0.11800"
"319.14400","26.59552","0.11911"
"319.46800","26.62249","0.12573"
"319.79200","26.64951","0.12243"
"320.11600","26.67648","0.12518"
"320.44000","26.70356","0.13405"
"320.76400","26.73052","0.13012"
"321.08800","26.75743","0.13058"
"321.41200","26.78452","0.13532"
"321.73600","26.81148","0.13556"
"322.06000","26.83850","0.13576"
"322.38400","26.86553","0.13749"
"322.70800","26.89244","0.13689"
"323.03200","26.91958","0.13817"
"323.35600","26.94643","0.13959"
"323.68000","26.97345","0.13895"
"324.00400","27.00053","0.13923"
"324.32800","27.02744","0.13774"
"324.65200","27.05453","0.03048"
"324.97600","27.08149","0.02192"
"325.30000","27.10846","0.03529"
"325.62400","27.13548","0.02655"
"325.94800","27.16244","0.03220"
"326.27200","27.18947","0.03019"
"326.59600","27.21650","0.03260"
"326.92000","27.24352","0.03105"
"327.24400","27.27054","0.03431"
"327.56800","27.29739","0.03390"
"327.89200","27.32454","0.03338"
"328.21600","27.35150","0.03720"
"328.54000","27.37846","0.03412"
"328.86400","27.40549","0.03774"
"329.18800","27.43245","0.03783"
"329.51200","27.45954","0.03782"
"329.83600","27.48651","0.03961"
"330.16000","27.51347","0.03879"
"330.48400","27.54055","0.04073"
"330.80800","27.56740","0.04024"
"331.13200","27.59448","0.04135"
"331.45600","27.62145","0.04188"
"331.78000","27.64847","0.04200"
"332.10400","27.67550","0.04305"
"332.42800","27.70240","0.04355"
"332.75200","27.72949","0.04362"
"333.07600","27.75645","0.04485"
"333.40000","27.78342","0.04471"
"333.72400","27.81050","0.04557"
"334.04800","27.83741","0.04550"
"334.37200","27.86456","0.04625"
"334.69600","27.89146","0.04675"
"335.02000","27.91842","0.04750"
"335.34400","27.94551","0.04793"
"335.66800","27.97248","0.04845"
"335.99200","27.99944","0.04858"
"336.31600","28.02646","0.04911"
"336.64000","28.05349","0.04940"
"336.96400","28.08051","0.04966"
"337.28800","28.10742","0.05008"
"337.61200","28.13450","0.05046"
"337.93600","28.16153","0.05109"
"338.26000","28.18843","0.05107"
"338.58400","28.21552","0.05130"
"338.90800","28.24242","0.05152"
"339.23200","28.26951","0.05162"
"339.55600","28.29653","0.05184"
"339.88000","28.32350","0.05210"
"340.20400","28.35052","0.05224"
"340.52800","28.37749","0.05260"
"340.85200","28.40451","0.05263"
"341.17600","28.43148","0.05276"
"341.50000","28.45844","0.05294"
"341.82400","28.48553","0.05296"
"342.14800","28.51250","0.05304"
"342.47200","28.53952","0.05322"
"342.79600","28.56648","0.05323"
"343.12000","28.59351","0.05326"
"343.44400","28.62047","0.05335"
"343.76800","28.64744","0.05349"
"344.09200","28.67452","0.05364"
"344.41600","28.70155","0.05385"
"344.74000","28.72845","0.05396"
"345.06400","28.75548","0.05415"
"345.38800","28.78250","0.05457"
"345.71200","28.80947","0.05494"
"346.03600","28.83649","0.05562"
"346.36000","28.86346","0.05605"
"346.68400","28.89054","0.05681"
"347.00800","28.91751","0.05751"
"347.33200","28.94447","0.05797"
"347.65600","28.97150","0.05849"
"347.98000","28.99846","0.05923"
"348.30400","29.02555","0.06012"
"348.62800","29.05245","0.06130"
"348.95200","29.07948","0.06185"
"349.27600","29.10650","0.06267"
"349.60000","29.13347","0.06388"
"349.92400","29.16049","0.06493"
"350.24800","29.18746","0.06625"
"350.57200","29.21448","0.06733"
"350.89600","29.24151","0.06927"
"351.22000","29.26841","0.07021"
"351.54400","29.29550","0.07163"
"351.86800","29.32252","0.07276"
"352.19200","29.34949","0.07466"
"352.51600","29.37651","0.07565"
"352.84000","29.40348","0.07809"
"353.16400","29.43050","0.07997"
"353.48800","29.45746","0.08146"
"353.81200","29.48449","0.08191"
"354.13600","29.51146","0.08373"
"354.46000","29.53842","0.08498"
"354.78400","29.56557","0.08626"
"355.10800","29.59247","0.08687"
"355.43200","29.61944","0.08816"
"355.75600","29.64652","0.08846"
"356.08000","29.67343","0.08994"
"356.40400","29.70051","0.09096"
"356.72800","29.72748","0.09290"
"357.05200","29.75450","0.09532"
"357.37600","29.78153","0.09688"
"357.70000","29.80843","0.09826"
"358.02400","29.83551","0.10115"
"358.34800","29.86248","0.10262"
"358.67200","29.88945","0.10409"
"358.99600","29.91647","0.10594"
"359.32000","29.94344","0.10807"
"359.64400","29.97052","0.11229"
"359.96800","29.99749","0.11524"
"360.29200","30.02451","0.11707"
"360.61600","30.05153","0.12057"
"360.94000","30.07844","0.12278"
"361.26400","30.10552","0.12524"
"361.58800","30.13249","0.12606"
"361.91200","30.15946","0.12896"
"362.23600","30.18648","0.13068"
"362.56000","30.21345","0.13303"
"362.88400","30.24053","0.13396"
"363.20800","30.26750","0.13549"
"363.53200","30.29446","0.13626"
"363.85600","30.32149","0.13759"
"364.18000","30.34845","0.13814"
"364.50400","30.37553","0.13873"
"364.82800","30.40250","0.13942"
"365.15200","30.42947","0.13986"
"365.47600","30.45649","0.14008"
"365.80000","30.48345","0.14073"
"366.12400","30.51048","0.14137"
"366.44800","30.53745","0.14165"
"366.77200","30.56441","0.14273"
"367.09600","30.59150","0.14377"
"367.42000","30.61846","0.14480"
"367.74400","30.64549","0.14592"
"368.06800","30.67251","0.14739"
"368.39200","30.69947","0.14838"
"368.71600","30.72644","0.14972"
"369.04000","30.75346","0.15196"
"369.36400","30.78049","0.15306"
"369.68800","30.80746","0.15466"
"370.01200","30.83448","0.15636"
"370.33600","30.86144","0.15725"
"370.66000","30.88847","0.15921"
"370.98400","30.91549","0.16099"
"371.30800","30.94246","0.16200"
"371.63200","30.96943","0.16403"
"371.95600","30.99657","0.16546"
"372.28000","31.02347","0.16741"
"372.60400","31.05044","0.16988"
"372.92800","31.07752","0.17175"
"373.25200","31.10443","0.17464"
"373.57600","31.13152","0.17729"
"373.90000","31.15842","0.17862"
"374.22400","31.18550","0.18095"
"374.54800","31.21247","0.18304"
"374.87200","31.23944","0.18580"
"375.19600","31.26652","0.18771"
"375.52000","31.29342","0.18938"
"375.84400","31.32051","0.19207"
"376.16800","31.34753","0.19396"
"376.49200","31.37444","0.19580"
"376.81600","31.40152","0.19787"
"377.14000","31.42849","0.19930"
"377.46400","31.45551","0.20004"
"377.78800","31.48248","0.20068"
"378.11200","31.50944","0.20117"
"378.43600","31.53653","0.20143"
"378.76000","31.56349","0.20158"
"379.08400","31.59046","0.20175"
"379.40800","31.61754","0.20218"
"379.73200","31.64445","0.15522"
"380.05600","31.67147","0.15300"
"380.38000","31.69843","0.15819"
"380.70400","31.72552","0.16100"
"381.02800","31.75255","0.15598"
"381.35200","31.77939","0.15748"
"381.67600","31.80654","0.16408"
"382.00000","31.83350","0.16306"
"382.32400","31.86047","0.16359"
"382.64800","31.88755","0.16859"
"382.97200","31.91446","0.16866"
"383.29600","31.94154","0.16735"
"383.62000","31.96844","0.17297"
"383.94400","31.99547","0.17575"
"384.26800","32.02250","0.17438"
"384.59200","32.04952","0.17703"
"384.91600","32.07655","0.18206"
"385.24000","32.10345","0.18173"
"385.56400","32.13048","0.18209"
"385.88800","32.15750","0.18586"
"386.21200","32.18441","0.18650"
"386.53600","32.21149","0.18689"
"386.86000","32.23846","0.19013"
"387.18400","32.26548","0.19232"
"387.50800","32.29250","0.19251"
"387.83200","32.31947","0.19388"
"388.15600","32.34655","0.19698"
"388.48000","32.37346","0.19794"
"388.80400","32.40042","0.19809"
"389.12800","32.42751","0.19956"
"389.45200","32.45448","0.20048"
"389.77600","32.48150","0.20073"
"390.10000","32.50853","0.20101"
"390.42400","32.53543","0.20115"
"390.74800","32.56252","0.20150"
"391.07200","32.58948","0.20147"
"391.39600","32.61656","0.20165"
"391.72000","32.64347","0.20203"
"392.04400","32.67043","0.20198"
"392.36800","32.69752","0.20227"
"392.69200","32.72443","0.20284"
"393.01600","32.75151","0.20349"
"393.34000","32.77853","0.20464"
"393.66400","32.80550","0.20592"
"393.98800","32.83247","0.20738"
"394.31200","32.85937","0.20851"
"394.63600","32.88652","0.21004"
"394.96000","32.91348","0.21169"
"395.28400","32.94050","0.21321"
"395.60800","32.96747","0.21491"
"395.93200","32.99450","0.21557"
"396.25600","33.02146","0.21567"
"396.58000","33.04848","0.21870"
"396.90400","33.07545","0.21973"
"397.22800","33.10254","0.22025"
"397.55200","33.12950","0.22248"
"397.87600","33.15652","0.22312"
"398.20000","33.18349","0.22463"
"398.52400","33.21045","0.22549"
"398.84800","33.23748","0.22687"
"399.17200","33.26444","0.22839"
"399.49600","33.29153","0.22994"
"399.82000","33.31855","0.23037"
"400.14400","33.34546","0.23195"
"400.46800","33.37248","0.23288"
"400.79200","33.39951","0.23404"
"401.11600","33.42653","0.23469"
"401.44000","33.45350","0.23567"
"401.76400","33.48046","0.23680"
"402.08800","33.50755","0.23761"
"402.41200","33.53445","0.23806"
"402.73600","33.56148","0.23910"
"403.06000","33.58850","0.24011"
"403.38400","33.61547","0.24118"
"403.70800","33.64249","0.24186"
"404.03200","33.66940","0.24297"
"404.35600","33.69648","0.24412"
"404.68000","33.72351","0.24434"
"405.00400","33.75047","0.24588"
"405.32800","33.77750","0.24619"
"405.65200","33.80447","0.24715"
"405.97600","33.83155","0.24865"
"406.30000","33.85851","0.24987"
"406.62400","33.88542","0.25110"
"406.94800","33.91250","0.25281"
"407.27200","33.93947","0.25408"
"407.59600","33.96649","0.25506"
"407.92000","33.99346","0.25677"
"408.24400","34.02042","0.25819"
"408.56800","34.04757","0.26017"
"408.89200","34.07441","0.26152"
"409.21600","34.10144","0.26323"
"409.54000","34.12852","0.26453"
"409.86400","34.15543","0.26639"
"410.18800","34.18251","0.26742"
"410.51200","34.20948","0.26830"
"410.83600","34.23650","0.27022"
"411.16000","34.26347","0.27205"
"411.48400","34.29043","0.27282"
"411.80800","34.31746","0.27511"
"412.13200","34.34448","0.27637"
"412.45600","34.37151","0.27873"
"412.78000","34.39848","0.28146"
"413.10400","34.42544","0.28255"
"413.42800","34.45252","0.28470"
"413.75200","34.47949","0.28694"
"414.07600","34.50645","0.28971"
"414.40000","34.53348","0.29173"
"414.72400","34.56044","0.29310"
"415.04800","34.58753","0.29427"
"415.37200","34.61449","0.13209"
"415.69600","34.64146","0.13946"
"416.02000","34.66854","0.13942"
"416.34400","34.69539","0.14179"
"416.66800","34.72247","0.14076"
"416.99200","34.74950","0.14184"
"417.31600","34.77652","0.14441"
"417.64000","34.80349","0.14239"
"417.96400","34.83039","0.14478"
"418.28800","34.85754","0.14395"
"418.61200","34.88444","0.14343"
"418.93600","34.91147","0.14702"
"419.26000","34.93849","0.14489"
"419.58400","34.96545","0.14739"
"419.90800","34.99254","0.15164"
"420.23200","35.01945","0.14726"
"420.55600","35.04641","0.14992"
"420.88000","35.07355","0.15210"
"421.20400","35.10046","0.15000"
"421.52800","35.12755","0.15434"
"421.85200","35.15445","0.15366"
"422.17600","35.18142","0.15427"
"422.50000","35.20850","0.15692"
"422.82400","35.23547","0.15528"
"423.14800","35.26249","0.15712"
"423.47200","35.28952","0.16006"
"423.79600","35.31648","0.15767"
"424.12000","35.34344","0.15939"
"424.44400","35.37041","0.16140"
"424.76800","35.39756","0.16081"
"425.09200","35.42452","0.16295"
"425.41600","35.45149","0.16358"
"425.74000","35.47851","0.16289"
"426.06400","35.50548","0.16672"
"426.38800","35.53250","0.16653"
"426.71200","35.55946","0.16595"
"427.03600","35.58649","0.16892"
"427.36000","35.61351","0.16966"
"427.68400","35.64048","0.16948"
"428.00800","35.66750","0.17213"
"428.33200","35.69447","0.17260"
"428.65600","35.72144","0.17327"
"428.98000","35.74852","0.17678"
"429.30400","35.77542","0.17638"
"429.62800","35.80251","0.17750"
"429.95200","35.82954","0.18096"
"430.27600","35.85650","0.18060"
"430.60000","35.88346","0.18102"
"430.92400","35.91049","0.18317"
"431.24800","35.93745","0.18280"
"431.57200","35.96448","0.18379"
"431.89600","35.99144","0.18607"
"432.22000","36.01853","0.18735"
"432.54400","36.04544","0.18735"
"432.86800","36.07246","0.18905"
"433.19200","36.09949","0.18976"
"433.51600","36.12645","0.19119"
"433.84000","36.15348","0.19229"
"434.16400","36.18044","0.19277"
"434.48800","36.20746","0.19375"
"434.81200","36.23455","0.19633"
"435.13600","36.26139","0.19630"
"435.46000","36.28854","0.19664"
"435.78400","36.31544","0.19805"
"436.10800","36.34253","0.19885"
"436.43200","36.36950","0.19932"
"436.75600","36.39646","0.20004"
"437.08000","36.42348","0.20023"
"437.40400","36.45051","0.20084"
"437.72800","36.47748","0.20085"
"438.05200","36.50450","0.20115"
"438.37600","36.53146","0.20129"
"438.70000","36.55855","0.20145"
"439.02400","36.58545","0.20153"
"439.34800","36.61248","0.20171"
"439.67200","36.63950","0.20172"
"439.99600","36.66647","0.20204"
"440.32000","36.69349","0.20221"
"440.64400","36.72046","0.20212"
"440.96800","36.74754","0.20303"
"441.29200","36.77451","0.20291"
"441.61600","36.80141","0.20344"
"441.94000","36.82850","0.20450"
"442.26400","36.85546","0.20531"
"442.58800","36.88249","0.20601"
"442.91200","36.90951","0.20728"
"443.23600","36.93642","0.20835"
"443.56000","36.96350","0.20970"
"443.88400","36.99047","0.21037"
"444.20800","37.01749","0.21148"
"444.53200","37.04446","0.21281"
"444.85600","37.07148","0.21332"
"445.18000","37.09851","0.21435"
"445.50400","37.12547","0.21588"
"445.82800","37.15244","0.21704"
"446.15200","37.17958","0.21813"
"446.47600","37.20643","0.21884"
"446.80000","37.23351","0.21947"
"447.12400","37.26048","0.22073"
"447.44800","37.28750","0.22144"
"447.77200","37.31447","0.22272"
"448.09600","37.34143","0.22381"
"448.42000","37.36852","0.22450"
"448.74400","37.39548","0.22509"
"449.06800","37.42245","0.22643"
"449.39200","37.44947","0.22736"
"449.71600","37.47644","0.22823"
"450.04000","37.50352","0.22922"
"450.36400","37.53049","0.23018"
"450.68800","37.55751","0.23143"
"451.01200","37.58448","0.23229"
"451.33600","37.61144","0.23240"
"451.66000","37.63853","0.23346"
"451.98400","37.66544","0.23458"
"452.30800","37.69246","0.23506"
"452.63200","37.71949","0.23594"
"452.95600","37.74639","0.23672"
"453.28000","37.77353","0.23726"
"453.60400","37.80050","0.23837"
"453.92800","37.82746","0.23840"
"454.25200","37.85449","0.23974"
"454.57600","37.88145","0.23986"
"454.90000","37.90847","0.24008"
"455.22400","37.93550","0.23990"
"455.54800","37.96247","0.24060"
"455.87200","37.98949","0.24164"
"456.19600","38.01646","0.24180"
"456.52000","38.04348","0.24319"
"456.84400","38.07045","0.24374"
"457.16800","38.09747","0.24514"
"457.49200","38.12450","0.24607"
"457.81600","38.15146","0.24705"
"458.14000","38.17849","0.24830"
"458.46400","38.20551","0.24908"
"458.78800","38.23241","0.24981"
"459.11200","38.25950","0.25127"
"459.43600","38.28641","0.25270"
"459.76000","38.31349","0.25357"
"460.08400","38.34052","0.25512"
"460.40800","38.36748","0.25633"
"460.73200","38.39451","0.25853"
"461.05600","38.42147","0.25901"
"461.38000","38.44850","0.26091"
"461.70400","38.47546","0.26215"
"462.02800","38.50249","0.26366"
"462.35200","38.52951","0.26481"
"462.67600","38.55648","0.26609"
"463.00000","38.58350","0.26747"
"463.32400","38.61047","0.26840"
"463.64800","38.63743","0.27023"
"463.97200","38.66452","0.27141"
"464.29600","38.69142","0.27258"
"464.62000","38.71851","0.27389"
"464.94400","38.74553","0.27532"
"465.26800","38.77244","0.27703"
"465.59200","38.79946","0.27865"
"465.91600","38.82648","0.28037"
"466.24000","38.85351","0.28142"
"466.56400","38.88054","0.28289"
"466.88800","38.90744","0.28529"
"467.21200","38.93447","0.28689"
"467.53600","38.96143","0.28906"
"467.86000","38.98851","0.29037"
"468.18400","39.01548","0.29174"
"468.50800","39.04245","0.29267"
"468.83200","39.06953","0.29467"
"469.15600","39.09644","0.29601"
"469.48000","39.12346","0.29680"
"469.80400","39.15048","0.29821"
"470.12800","39.17745","0.29920"
"470.45200","39.20448","0.29952"
"470.77600","39.23144","0.30048"
"471.10000","39.25853","0.30125"
"471.42400","39.28549","0.30216"
"471.74800","39.31245","0.30272"
"472.07200","39.33948","0.30338"
"472.39600","39.36650","0.30453"
"472.72000","39.39353","0.30543"
"473.04400","39.42050","0.27495"
"473.36800","39.44746","0.27682"
"473.69200","39.47448","0.01524"
"474.01600","39.50145","0.03797"
"474.34000","39.52842","0.00226"
"474.66400","39.55550","0.03217"
"474.98800","39.58246","0.00349"
"475.31200","39.60949","0.01819"
"475.63600","39.63652","0.01002"
"475.96000","39.66348","0.01625"
"476.28400","39.69057","0.01454"
"476.60800","39.71741","0.01694"
"476.93200","39.74449","0.01510"
"477.25600","39.77146","0.02016"
"477.58000","39.79848","0.01495"
"477.90400","39.82551","0.02299"
"478.22800","39.85241","0.01515"
"478.55200","39.87956","0.02300"
"478.87600","39.90652","0.01688"
"479.20000","39.93355","0.02188"
"479.52400","39.96051","0.02044"
"479.84800","39.98742","0.02032"
"480.17200","40.01456","0.02379"
"480.49600","40.04147","0.02151"
"480.82000","40.06843","0.02421"
"481.14400","40.09552","0.02388"
"481.46800","40.12248","0.02369"
"481.79200","40.14951","0.02550"
"482.11600","40.17647","0.02427"
"482.44000","40.20350","0.02611"
"482.76400","40.23046","0.02628"
"483.08800","40.25748","0.02685"
"483.32800","40.27746","0.02763"