File: Force_trajectories/170108_1/Specimen_RawData_1.csv
End date,"1/8/2017"
Specimen label,"2DG_15"
Maximum Load,"0.19619",N

Time,Extension,Load
(s),(mm),(N)
"0.00000","0.00000","0.00000"
"0.30600","0.02505","-0.00051"
"0.61200","0.05118","-0.00006"
"0.91800","0.07677","0.00035"
"1.22400","0.10218","0.00049"
"1.53000","0.12765","-0.00008"
"1.83600","0.15324","0.00030"
"2.14200","0.17865","0.00060"
"2.44800","0.20424","0.00093"
"2.75400","0.22965","0.00116"
"3.06000","0.25524","0.00055"
"3.36600","0.28065","0.00063"
"3.67200","0.30618","0.00023"
"3.97800","0.33165","0.00095"
"4.28400","0.35718","0.00104"
"4.59000","0.38271","0.00105"
"4.89600","0.40812","0.00146"
"5.20200","0.43371","0.00109"
"5.50800","0.45918","0.00178"
"5.81400","0.48465","0.00150"
"6.12000","0.51018","0.00110"
"6.42600","0.53571","0.00130"
"6.73200","0.56118","0.00166"
"7.03800","0.58671","0.00231"
"7.34400","0.61219","0.00154"
"7.65000","0.63760","0.00167"
"7.95600","0.66319","0.00170"
"8.26200","0.68866","0.00177"
"8.56800","0.71419","0.00207"
"8.87400","0.73978","0.00252"
"9.18000","0.76513","0.00202"
"9.48600","0.79072","0.00171"
"9.79200","0.81607","0.00258"
"10.09800","0.84166","0.00279"
"10.40400","0.86713","0.00226"
"10.71000","0.89266","0.00231"
"11.01600","0.91819","0.00267"
"11.32200","0.94366","0.00310"
"11.62800","0.96925","0.00308"
"11.93400","0.99466","0.00288"
"12.24000","1.02019","0.00314"
"12.54600","1.04566","0.00308"
"12.85200","1.07119","0.00311"
"13.15800","1.09672","0.00317"
"13.46400","1.12219","0.00354"
"13.77000","1.14772","0.00333"
"14.07600","1.17313","0.00339"
"14.38200","1.19872","0.00379"
"14.68800","1.22419","0.00405"
"14.99400","1.24966","0.00400"
"15.30000","1.27519","0.00393"
"15.60600","1.30066","0.00387"
"15.91200","1.32625","0.00355"
"16.21800","1.35166","0.00402"
"16.52400","1.37719","0.00415"
"16.83000","1.40266","0.00410"
"17.13600","1.42813","0.00393"
"17.44200","1.45366","0.00467"
"17.74800","1.47913","0.00415"
"18.05400","1.50472","0.00438"
"18.36000","1.53007","0.00467"
"18.66600","1.55566","0.00424"
"18.97200","1.58113","0.00483"
"19.27800","1.60666","0.00510"
"19.58400","1.63213","0.00508"
"19.89000","1.65766","0.00553"
"20.19600","1.68325","0.00494"
"20.50200","1.70867","0.00542"
"20.80800","1.73420","0.00512"
"21.11400","1.75967","0.00527"
"21.42000","1.78520","0.00528"
"21.72600","1.81067","0.00452"
"22.03200","1.83620","0.00547"
"22.33800","1.86173","0.00577"
"22.64400","1.88720","0.00553"
"22.95000","1.91273","0.00555"
"23.25600","1.93820","0.00548"
"23.56200","1.96367","0.00584"
"23.86800","1.98920","0.00600"
"24.17400","2.01461","0.00597"
"24.48000","2.04020","0.00584"
"24.78600","2.06567","0.00613"
"25.09200","2.09120","0.00607"
"25.39800","2.11667","0.00583"
"25.70400","2.14220","0.00615"
"26.01000","2.16767","0.00587"
"26.31600","2.19320","0.00589"
"26.62200","2.21873","0.00613"
"26.92800","2.24414","0.00593"
"27.23400","2.26973","0.00582"
"27.54000","2.29520","0.00602"
"27.84600","2.32073","0.00599"
"28.15200","2.34614","0.00626"
"28.45800","2.37167","0.00627"
"28.76400","2.39720","0.00620"
"29.07000","2.42267","0.00589"
"29.37600","2.44820","0.00650"
"29.68200","2.47367","0.00651"
"29.98800","2.49920","0.00664"
"30.29400","2.52467","0.00633"
"30.60000","2.55020","0.00645"
"30.90600","2.57573","0.00729"
"31.21200","2.60120","0.00692"
"31.51800","2.62667","0.00694"
"31.82400","2.65214","0.00697"
"32.13000","2.67773","0.00719"
"32.43600","2.70314","0.00689"
"32.74200","2.72867","0.00696"
"33.04800","2.75420","0.00738"
"33.35400","2.77962","0.00724"
"33.66000","2.80521","0.00716"
"33.96600","2.83062","0.00731"
"34.27200","2.85621","0.00759"
"34.57800","2.88168","0.00781"
"34.88400","2.90721","0.00795"
"35.19000","2.93274","0.00769"
"35.49600","2.95815","0.00851"
"35.80200","2.98368","0.00808"
"36.10800","3.00915","0.00783"
"36.41400","3.03474","0.00753"
"36.72000","3.06021","0.00837"
"37.02600","3.08574","0.00820"
"37.33200","3.11121","0.00861"
"37.63800","3.13668","0.00832"
"37.94400","3.16215","0.00887"
"38.25000","3.18762","0.00850"
"38.55600","3.21321","0.00905"
"38.86200","3.23862","0.00844"
"39.16800","3.26415","0.00859"
"39.47400","3.28968","0.00906"
"39.78000","3.31515","0.00862"
"40.08600","3.34074","0.00923"
"40.39200","3.36615","0.00885"
"40.69800","3.39168","0.00874"
"41.00400","3.41715","0.00923"
"41.31000","3.44274","0.00894"
"41.61600","3.46821","0.00894"
"41.92200","3.49368","0.00931"
"42.22800","3.51921","0.00911"
"42.53400","3.54462","0.00938"
"42.84000","3.57021","0.00887"
"43.14600","3.59562","0.00930"
"43.45200","3.62121","0.00911"
"43.75800","3.64668","0.00901"
"44.06400","3.67215","0.00919"
"44.37000","3.69774","0.00929"
"44.67600","3.72315","0.00926"
"44.98200","3.74868","0.00971"
"45.28800","3.77409","0.00911"
"45.59400","3.79974","0.00991"
"45.90000","3.82521","0.00964"
"46.20600","3.85069","0.00952"
"46.51200","3.87616","0.00992"
"46.81800","3.90169","0.00989"
"47.12400","3.92722","0.00954"
"47.43000","3.95263","0.00990"
"47.73600","3.97822","0.00970"
"48.04200","4.00369","0.00984"
"48.34800","4.02922","0.01003"
"48.65400","4.05469","0.01012"
"48.96000","4.08016","0.00992"
"49.26600","4.10569","0.00974"
"49.57200","4.13110","0.00975"
"49.87800","4.15669","0.00988"
"50.18400","4.18216","0.01005"
"50.49000","4.20775","0.01024"
"50.79600","4.23322","0.01054"
"51.10200","4.25869","0.01039"
"51.40800","4.28422","0.01035"
"51.71400","4.30963","0.01017"
"52.02000","4.33522","0.01048"
"52.32600","4.36063","0.01058"
"52.63200","4.38622","0.01019"
"52.93800","4.41175","0.01019"
"53.24400","4.43722","0.01051"
"53.55000","4.46269","0.01077"
"53.85600","4.48810","0.01073"
"54.16200","4.51375","0.01048"
"54.46800","4.53916","0.01041"
"54.77400","4.56469","0.01072"
"55.08000","4.59016","0.01065"
"55.38600","4.61569","0.01109"
"55.69200","4.64122","0.01079"
"55.99800","4.66663","0.01057"
"56.30400","4.69216","0.01047"
"56.61000","4.71757","0.01094"
"56.91600","4.74316","0.01086"
"57.22200","4.76869","0.01098"
"57.52800","4.79422","0.01051"
"57.83400","4.81975","0.01109"
"58.14000","4.84516","0.01095"
"58.44600","4.87069","0.01104"
"58.75200","4.89616","0.01088"
"59.05800","4.92170","0.01058"
"59.36400","4.94723","0.01051"
"59.67000","4.97269","0.01105"
"59.97600","4.99829","0.01149"
"60.28200","5.02364","0.01168"
"60.58800","5.04917","0.01094"
"60.89400","5.07458","0.01114"
"61.20000","5.10017","0.01088"
"61.50600","5.12564","0.01109"
"61.81200","5.15117","0.01129"
"62.11800","5.17670","0.01139"
"62.42400","5.20217","0.01099"
"62.73000","5.22770","0.01129"
"63.03600","5.25311","0.01142"
"63.34200","5.27870","0.01098"
"63.64800","5.30417","0.01107"
"63.95400","5.32970","0.01113"
"64.26000","5.35523","0.01124"
"64.56600","5.38064","0.01145"
"64.87200","5.40623","0.01166"
"65.17800","5.43164","0.01174"
"65.48400","5.45723","0.01110"
"65.79000","5.48264","0.01159"
"66.09600","5.50817","0.01203"
"66.40200","5.53370","0.01170"
"66.70800","5.55917","0.01114"
"67.01400","5.58470","0.01154"
"67.32000","5.61017","0.01149"
"67.62600","5.63576","0.01110"
"67.93200","5.66117","0.01163"
"68.23800","5.68670","0.01195"
"68.54400","5.71217","0.01219"
"68.85000","5.73770","0.01142"
"69.15600","5.76329","0.01139"
"69.46200","5.78864","0.01165"
"69.76800","5.81417","0.01187"
"70.07400","5.83964","0.01021"
"70.38000","5.86517","0.01027"
"70.68600","5.89064","0.01073"
"70.99200","5.91617","0.01083"
"71.29800","5.94170","0.01100"
"71.60400","5.96717","0.01102"
"71.91000","5.99270","0.01110"
"72.21600","6.01812","0.01114"
"72.52200","6.04371","0.01092"
"72.82800","6.06918","0.01172"
"73.13400","6.09465","0.01149"
"73.44000","6.12024","0.01082"
"73.74600","6.14571","0.01113"
"74.05200","6.17118","0.01108"
"74.35800","6.19665","0.01145"
"74.66400","6.22218","0.01122"
"74.97000","6.24771","0.01174"
"75.27600","6.27312","0.01144"
"75.58200","6.29871","0.01154"
"75.88800","6.32418","0.01145"
"76.19400","6.34971","0.01210"
"76.50000","6.37518","0.01165"
"76.80600","6.40071","0.01199"
"77.11200","6.42618","0.01184"
"77.41800","6.45165","0.01175"
"77.72400","6.47724","0.01168"
"78.03000","6.50265","0.01163"
"78.33600","6.52824","0.01145"
"78.64200","6.55365","0.01199"
"78.94800","6.57924","0.01123"
"79.25400","6.60465","0.01169"
"79.56000","6.63018","0.01153"
"79.86600","6.65565","0.01161"
"80.17200","6.68118","0.01179"
"80.47800","6.70677","0.01222"
"80.78400","6.73218","0.01174"
"81.09000","6.75771","0.01190"
"81.39600","6.78318","0.01193"
"81.70200","6.80871","0.01224"
"82.00800","6.83418","0.01245"
"82.31400","6.85965","0.01231"
"82.62000","6.88518","0.01211"
"82.92600","6.91059","0.01219"
"83.23200","6.93618","0.01238"
"83.53800","6.96165","0.01242"
"83.84400","6.98718","0.01232"
"84.15000","7.01265","0.01226"
"84.45600","7.03813","0.01238"
"84.76200","7.06371","0.01238"
"85.06800","7.08919","0.01222"
"85.37400","7.11472","0.01201"
"85.68000","7.14019","0.01237"
"85.98600","7.16566","0.01241"
"86.29200","7.19119","0.01268"
"86.59800","7.21672","0.01257"
"86.90400","7.24219","0.01299"
"87.21000","7.26766","0.01267"
"87.51600","7.29325","0.01206"
"87.82200","7.31872","0.01253"
"88.12800","7.34419","0.01340"
"88.43400","7.36966","0.01315"
"88.74000","7.39513","0.01275"
"89.04600","7.42066","0.01279"
"89.35200","7.44619","0.01279"
"89.65800","7.47172","0.01282"
"89.96400","7.49719","0.01282"
"90.27000","7.52266","0.01242"
"90.57600","7.54819","0.01243"
"90.88200","7.57372","0.01316"
"91.18800","7.59919","0.01289"
"91.49400","7.62466","0.01272"
"91.80000","7.65025","0.01339"
"92.10600","7.67566","0.01358"
"92.41200","7.70119","0.01350"
"92.71800","7.72672","0.01305"
"93.02400","7.75219","0.01331"
"93.33000","7.77766","0.01331"
"93.63600","7.80313","0.01292"
"93.94200","7.82866","0.01366"
"94.24800","7.85413","0.01332"
"94.55400","7.87972","0.01303"
"94.86000","7.90513","0.01291"
"95.16600","7.93072","0.01321"
"95.47200","7.95625","0.01304"
"95.77800","7.98166","0.01403"
"96.08400","8.00719","0.01384"
"96.39000","8.03266","0.01350"
"96.69600","8.05825","0.01311"
"97.00200","8.08366","0.01353"
"97.30800","8.10919","0.01342"
"97.61400","8.13466","0.01379"
"97.92000","8.16020","0.01362"
"98.22600","8.18567","0.01332"
"98.53200","8.21114","0.01348"
"98.83800","8.23673","0.01334"
"99.14400","8.26220","0.01359"
"99.45000","8.28773","0.01352"
"99.75600","8.31314","0.01389"
"100.06200","8.33867","0.01427"
"100.36800","8.36414","0.01365"
"100.67400","8.38961","0.01383"
"100.98000","8.41520","0.01450"
"101.28600","8.44067","0.01404"
"101.59200","8.46620","0.01259"
"101.89800","8.49167","0.01345"
"102.20400","8.51720","0.01274"
"102.51000","8.54273","0.01249"
"102.81600","8.56808","0.01308"
"103.12200","8.59367","0.01294"
"103.42800","8.61914","0.01317"
"103.73400","8.64473","0.01319"
"104.04000","8.67020","0.01300"
"104.34600","8.69567","0.01358"
"104.65200","8.72126","0.01324"
"104.95800","8.74661","0.01309"
"105.26400","8.77220","0.01316"
"105.57000","8.79761","0.01345"
"105.87600","8.82326","0.01362"
"106.18200","8.84867","0.01363"
"106.48800","8.87414","0.01361"
"106.79400","8.89967","0.01368"
"107.10000","8.92520","0.01353"
"107.40600","8.95067","0.01282"
"107.71200","8.97608","0.01299"
"108.01800","9.00173","0.01297"
"108.32400","9.02720","0.01314"
"108.63000","9.05267","0.01268"
"108.93600","9.07820","0.01320"
"109.24200","9.10367","0.01287"
"109.54800","9.12920","0.01326"
"109.85400","9.15462","0.01341"
"110.16000","9.18021","0.01294"
"110.46600","9.20568","0.01366"
"110.77200","9.23120","0.01321"
"111.07800","9.25667","0.01394"
"111.38400","9.28215","0.01421"
"111.69000","9.30774","0.01407"
"111.99600","9.33315","0.01408"
"112.30200","9.35874","0.01418"
"112.60800","9.38415","0.01432"
"112.91400","9.40974","0.01419"
"113.22000","9.43521","0.01418"
"113.52600","9.46068","0.01395"
"113.83200","9.48621","0.01385"
"114.13800","9.51162","0.01437"
"114.44400","9.53721","0.01460"
"114.75000","9.56262","0.01449"
"115.05600","9.58821","0.01419"
"115.36200","9.61368","0.01503"
"115.66800","9.63921","0.01512"
"115.97400","9.66468","0.01447"
"116.28000","9.69015","0.01428"
"116.58600","9.71568","0.01494"
"116.89200","9.74115","0.01492"
"117.19800","9.76668","0.01527"
"117.50400","9.79215","0.01541"
"117.81000","9.81768","0.01554"
"118.11600","9.84327","0.01515"
"118.42200","9.86868","0.01552"
"118.72800","9.89421","0.01578"
"119.03400","9.91968","0.01602"
"119.34000","9.94515","0.01542"
"119.64600","9.97074","0.01537"
"119.95200","9.99621","0.01617"
"120.25800","10.02174","0.01564"
"120.56400","10.04715","0.01621"
"120.87000","10.07268","0.01576"
"121.17600","10.09809","0.01584"
"121.48200","10.12368","0.01591"
"121.78800","10.14915","0.01556"
"122.09400","10.17468","0.01495"
"122.40000","10.20021","0.01554"
"122.70600","10.22563","0.01637"
"123.01200","10.25121","0.01563"
"123.31800","10.27668","0.01631"
"123.62400","10.30221","0.01622"
"123.93000","10.32769","0.01562"
"124.23600","10.35322","0.01565"
"124.54200","10.37869","0.01549"
"124.84800","10.40416","0.01571"
"125.15400","10.42969","0.01578"
"125.46000","10.45510","0.01589"
"125.76600","10.48063","0.01602"
"126.07200","10.50616","0.01637"
"126.37800","10.53169","0.01602"
"126.68400","10.55722","0.01613"
"126.99000","10.58263","0.01578"
"127.29600","10.60816","0.01623"
"127.60200","10.63363","0.01650"
"127.90800","10.65922","0.01631"
"128.21400","10.68469","0.01584"
"128.52000","10.71022","0.01575"
"128.82600","10.73575","0.01604"
"129.13200","10.76122","0.01587"
"129.43800","10.78675","0.01608"
"129.74400","10.81216","0.01657"
"130.05000","10.83775","0.01617"
"130.35600","10.86310","0.01653"
"130.66200","10.88869","0.01660"
"130.96800","10.91416","0.01696"
"131.27400","10.93969","0.01582"
"131.58000","10.96522","0.01654"
"131.88600","10.99063","0.01704"
"132.19200","11.01622","0.01677"
"132.49800","11.04163","0.01740"
"132.80400","11.06716","0.01781"
"133.11000","11.09269","0.01703"
"133.41600","11.11816","0.01691"
"133.72200","11.14375","0.01680"
"134.02800","11.16916","0.01671"
"134.33400","11.19469","0.01763"
"134.64000","11.22016","0.01679"
"134.94600","11.24569","0.01815"
"135.25200","11.27116","0.01733"
"135.55800","11.29663","0.01848"
"135.86400","11.32222","0.01794"
"136.17000","11.34770","0.01814"
"136.47600","11.37316","0.01810"
"136.78200","11.39863","0.01847"
"137.08800","11.42423","0.01852"
"137.39400","11.44963","0.01843"
"137.70000","11.47517","0.01816"
"138.00600","11.50070","0.01911"
"138.31200","11.52617","0.01870"
"138.61800","11.55170","0.01801"
"138.92400","11.57711","0.01839"
"139.23000","11.60270","0.01753"
"139.53600","11.62817","0.01762"
"139.84200","11.65364","0.01805"
"140.14800","11.67917","0.01791"
"140.45400","11.70464","0.01763"
"140.76000","11.73023","0.01780"
"141.06600","11.75564","0.01805"
"141.37200","11.78123","0.01719"
"141.67800","11.80670","0.01763"
"141.98400","11.83217","0.01784"
"142.29000","11.85770","0.01690"
"142.59600","11.88323","0.01656"
"142.90200","11.90876","0.01686"
"143.20800","11.93417","0.01772"
"143.51400","11.95970","0.01692"
"143.82000","11.98517","0.01760"
"144.12600","12.01070","0.01721"
"144.43200","12.03617","0.01738"
"144.73800","12.06164","0.01715"
"145.04400","12.08723","0.01808"
"145.35000","12.11270","0.01807"
"145.65600","12.13823","0.01793"
"145.96200","12.16370","0.01833"
"146.26800","12.18917","0.01808"
"146.57400","12.21470","0.01891"
"146.88000","12.24017","0.01892"
"147.18600","12.26570","0.01876"
"147.49200","12.29111","0.01892"
"147.79800","12.31670","0.01878"
"148.10400","12.34217","0.01925"
"148.41000","12.36764","0.01927"
"148.71600","12.39318","0.01935"
"149.02200","12.41865","0.01886"
"149.32800","12.44417","0.02000"
"149.63400","12.46965","0.01973"
"149.94000","12.49523","0.01994"
"150.24600","12.52071","0.01923"
"150.55200","12.54624","0.02031"
"150.85800","12.57165","0.02079"
"151.16400","12.59718","0.01981"
"151.47000","12.62265","0.01987"
"151.77600","12.64818","0.02054"
"152.08200","12.67371","0.01996"
"152.38800","12.69918","0.01928"
"152.69400","12.72465","0.01976"
"153.00000","12.75012","0.01979"
"153.30600","12.77565","0.01990"
"153.61200","12.80118","0.01955"
"153.91800","12.82665","0.02004"
"154.22400","12.85224","0.01981"
"154.53000","12.87765","0.02050"
"154.83600","12.90318","0.02031"
"155.14200","12.92871","0.02021"
"155.44800","12.95418","0.02107"
"155.75400","12.97971","0.02084"
"156.06000","13.00512","0.02040"
"156.36600","13.03071","0.02084"
"156.67200","13.05618","0.02143"
"156.97800","13.08171","0.02101"
"157.28400","13.10718","0.02122"
"157.59000","13.13265","0.02114"
"157.89600","13.15818","0.02198"
"158.20200","13.18365","0.02136"
"158.50800","13.20918","0.02134"
"158.81400","13.23465","0.02164"
"159.12000","13.26024","0.02139"
"159.42600","13.28571","0.02158"
"159.73200","13.31118","0.02214"
"160.03800","13.33671","0.02208"
"160.34400","13.36218","0.02188"
"160.65000","13.38771","0.02221"
"160.95600","13.41318","0.02204"
"161.26200","13.43871","0.02184"
"161.56800","13.46419","0.02017"
"161.87400","13.48971","0.02038"
"162.18000","13.51519","0.02021"
"162.48600","13.54060","0.02042"
"162.79200","13.56625","0.01970"
"163.09800","13.59166","0.01955"
"163.40400","13.61719","0.02019"
"163.71000","13.64266","0.01988"
"164.01600","13.66819","0.02003"
"164.32200","13.69366","0.01908"
"164.62800","13.71913","0.01950"
"164.93400","13.74472","0.02021"
"165.24000","13.77013","0.02046"
"165.54600","13.79572","0.02021"
"165.85200","13.82119","0.01996"
"166.15800","13.84672","0.02003"
"166.46400","13.87219","0.02079"
"166.77000","13.89772","0.01956"
"167.07600","13.92319","0.02057"
"167.38200","13.94866","0.02087"
"167.68800","13.97419","0.02051"
"167.99400","13.99960","0.02123"
"168.30000","14.02519","0.02080"
"168.60600","14.05066","0.02160"
"168.91200","14.07613","0.02140"
"169.21800","14.10172","0.02139"
"169.52400","14.12719","0.02155"
"169.83000","14.15266","0.02203"
"170.13600","14.17813","0.02206"
"170.44200","14.20372","0.02268"
"170.74800","14.22919","0.02259"
"171.05400","14.25472","0.02225"
"171.36000","14.28019","0.02213"
"171.66600","14.30566","0.02240"
"171.97200","14.33119","0.02276"
"172.27800","14.35660","0.02320"
"172.58400","14.38225","0.02339"
"172.89000","14.40766","0.02291"
"173.19600","14.43325","0.02301"
"173.50200","14.45878","0.02197"
"173.80800","14.48413","0.02211"
"174.11400","14.50966","0.02229"
"174.42000","14.53513","0.02200"
"174.72600","14.56073","0.02180"
"175.03200","14.58619","0.02232"
"175.33800","14.61172","0.02322"
"175.64400","14.63720","0.02276"
"175.95000","14.66267","0.02295"
"176.25600","14.68820","0.02358"
"176.56200","14.71361","0.02368"
"176.86800","14.73920","0.02372"
"177.17400","14.76467","0.02397"
"177.48000","14.79020","0.02437"
"177.78600","14.81567","0.02456"
"178.09200","14.84120","0.02503"
"178.39800","14.86667","0.02455"
"178.70400","14.89214","0.02458"
"179.01000","14.91767","0.02564"
"179.31600","14.94314","0.02583"
"179.62200","14.96873","0.02564"
"179.92800","14.99420","0.02556"
"180.23400","15.01967","0.02582"
"180.54000","15.04520","0.02576"
"180.84600","15.07061","0.02631"
"181.15200","15.09620","0.02500"
"181.45800","15.12161","0.02458"
"181.76400","15.14720","0.02445"
"182.07000","15.17273","0.02325"
"182.37600","15.19820","0.02319"
"182.68200","15.22373","0.02290"
"182.98800","15.24914","0.02230"
"183.29400","15.27473","0.02342"
"183.60000","15.30014","0.02398"
"183.90600","15.32573","0.02341"
"184.21200","15.35120","0.02511"
"184.51800","15.37673","0.02485"
"184.82400","15.40226","0.02511"
"185.13000","15.42767","0.02451"
"185.43600","15.45314","0.02535"
"185.74200","15.47861","0.02576"
"186.04800","15.50420","0.02494"
"186.35400","15.52967","0.02560"
"186.66000","15.55520","0.02596"
"186.96600","15.58073","0.02654"
"187.27200","15.60614","0.02595"
"187.57800","15.63167","0.02660"
"187.88400","15.65714","0.02685"
"188.19000","15.68268","0.02783"
"188.49600","15.70820","0.02762"
"188.80200","15.73367","0.02799"
"189.10800","15.75926","0.02800"
"189.41400","15.78468","0.02830"
"189.72000","15.81021","0.02851"
"190.02600","15.83562","0.02894"
"190.33200","15.86121","0.02880"
"190.63800","15.88668","0.02884"
"190.94400","15.91221","0.02921"
"191.25000","15.93768","0.02913"
"191.55600","15.96315","0.02926"
"191.86200","15.98868","0.02965"
"192.16800","16.01409","0.02945"
"192.47400","16.03974","0.02974"
"192.78000","16.06515","0.02973"
"193.08600","16.09068","0.03031"
"193.39200","16.11621","0.03049"
"193.69800","16.14168","0.03040"
"194.00400","16.16721","0.03054"
"194.31000","16.19262","0.03098"
"194.61600","16.21821","0.03085"
"194.92200","16.24368","0.03024"
"195.22800","16.26921","0.03064"
"195.53400","16.29468","0.03063"
"195.84000","16.32021","0.03097"
"196.14600","16.34574","0.03106"
"196.45200","16.37115","0.03076"
"196.75800","16.39668","0.03121"
"197.06400","16.42215","0.03130"
"197.37000","16.44768","0.03144"
"197.67600","16.47321","0.03158"
"197.98200","16.49868","0.03168"
"198.28800","16.52427","0.03221"
"198.59400","16.54962","0.03113"
"198.90000","16.57521","0.03145"
"199.20600","16.60062","0.03163"
"199.51200","16.62615","0.03222"
"199.81800","16.65162","0.03246"
"200.12400","16.67721","0.03271"
"200.43000","16.70268","0.03288"
"200.73600","16.72816","0.03340"
"201.04200","16.75374","0.03352"
"201.34800","16.77915","0.03365"
"201.65400","16.80469","0.03366"
"201.96000","16.83016","0.03386"
"202.26600","16.85568","0.03474"
"202.57200","16.88122","0.03449"
"202.87800","16.90669","0.03484"
"203.18400","16.93221","0.03467"
"203.49000","16.95769","0.03511"
"203.79600","16.98322","0.03473"
"204.10200","17.00869","0.03562"
"204.40800","17.03416","0.03367"
"204.71400","17.05969","0.03336"
"205.02000","17.08516","0.03379"
"205.32600","17.11075","0.03382"
"205.63200","17.13616","0.03485"
"205.93800","17.16175","0.03534"
"206.24400","17.18716","0.03557"
"206.55000","17.21269","0.03609"
"206.85600","17.23822","0.03654"
"207.16200","17.26363","0.03724"
"207.46800","17.28928","0.03802"
"207.77400","17.31463","0.03832"
"208.08000","17.34022","0.03949"
"208.38600","17.36569","0.04035"
"208.69200","17.39116","0.04098"
"208.99800","17.41663","0.04211"
"209.30400","17.44216","0.04276"
"209.61000","17.46775","0.04386"
"209.91600","17.49316","0.04414"
"210.22200","17.51869","0.04413"
"210.52800","17.54416","0.04597"
"210.83400","17.56969","0.04645"
"211.14000","17.59516","0.04679"
"211.44600","17.62069","0.04699"
"211.75200","17.64622","0.04049"
"212.05800","17.67163","0.03412"
"212.36400","17.69716","0.03498"
"212.67000","17.72269","0.03663"
"212.97600","17.74816","0.03650"
"213.28200","17.77363","0.03731"
"213.58800","17.79910","0.03682"
"213.89400","17.82469","0.03708"
"214.20000","17.85016","0.03692"
"214.50600","17.87570","0.03943"
"214.81200","17.90117","0.03870"
"215.11800","17.92664","0.03289"
"215.42400","17.95217","0.03219"
"215.73000","17.97770","0.03221"
"216.03600","18.00323","0.03231"
"216.34200","18.02870","0.03249"
"216.64800","18.05423","0.03166"
"216.95400","18.07970","0.03151"
"217.26000","18.10523","0.03166"
"217.56600","18.13064","0.02902"
"217.87200","18.15617","0.02661"
"218.17800","18.18170","0.02703"
"218.48400","18.20717","0.02748"
"218.79000","18.23270","0.02801"
"219.09600","18.25817","0.02747"
"219.40200","18.28370","0.02713"
"219.70800","18.30917","0.02741"
"220.01400","18.33470","0.02630"
"220.32000","18.36023","0.02560"
"220.62600","18.38570","0.02478"
"220.93200","18.41117","0.02510"
"221.23800","18.43664","0.02422"
"221.54400","18.46223","0.02320"
"221.85000","18.48770","0.02174"
"222.15600","18.51317","0.02158"
"222.46200","18.53864","0.02170"
"222.76800","18.56411","0.02194"
"223.07400","18.58970","0.01877"
"223.38000","18.61511","0.01776"
"223.68600","18.64070","0.01888"
"223.99200","18.66617","0.01821"
"224.29800","18.69170","0.01933"
"224.60400","18.71723","0.01922"
"224.91000","18.74270","0.01949"
"225.21600","18.76823","0.02069"
"225.52200","18.79364","0.01929"
"225.82800","18.81923","0.01965"
"226.13400","18.84471","0.02090"
"226.44000","18.87024","0.02059"
"226.74600","18.89565","0.02047"
"227.05200","18.92118","0.02131"
"227.35800","18.94670","0.02179"
"227.66400","18.97212","0.02169"
"227.97000","18.99771","0.02244"
"228.27600","19.02318","0.02287"
"228.58200","19.04871","0.02324"
"228.88800","19.07418","0.02279"
"229.19400","19.09971","0.02357"
"229.50000","19.12518","0.02375"
"229.80600","19.15065","0.02365"
"230.11200","19.17618","0.02378"
"230.41800","19.20165","0.02460"
"230.72400","19.22718","0.02402"
"231.03000","19.25271","0.02452"
"231.33600","19.27824","0.02432"
"231.64200","19.30377","0.02448"
"231.94800","19.32912","0.02409"
"232.25400","19.35465","0.02482"
"232.56000","19.38006","0.02477"
"232.86600","19.40571","0.02504"
"233.17200","19.43124","0.02514"
"233.47800","19.45671","0.02579"
"233.78400","19.48224","0.02636"
"234.09000","19.50765","0.02614"
"234.39600","19.53318","0.02629"
"234.70200","19.55859","0.02689"
"235.00800","19.58424","0.02657"
"235.31400","19.60965","0.02653"
"235.62000","19.63518","0.02669"
"235.92600","19.66071","0.02705"
"236.23200","19.68618","0.02662"
"236.53800","19.71165","0.02728"
"236.84400","19.73712","0.02740"
"237.15000","19.76271","0.02752"
"237.45600","19.78818","0.02795"
"237.76200","19.81371","0.02800"
"238.06800","19.83924","0.02816"
"238.37400","19.86465","0.02830"
"238.68000","19.89018","0.02896"
"238.98600","19.91566","0.02847"
"239.29200","19.94118","0.02872"
"239.59800","19.96665","0.02817"
"239.90400","19.99224","0.02888"
"240.21000","20.01772","0.02891"
"240.51600","20.04313","0.02896"
"240.82200","20.06872","0.02918"
"241.12800","20.09412","0.02939"
"241.43400","20.11971","0.02962"
"241.74000","20.14519","0.02924"
"242.04600","20.17072","0.02906"
"242.35200","20.19624","0.02961"
"242.65800","20.22166","0.02988"
"242.96400","20.24719","0.02977"
"243.27000","20.27266","0.03013"
"243.57600","20.29819","0.03028"
"243.88200","20.32360","0.03022"
"244.18800","20.34925","0.03029"
"244.49400","20.37466","0.03050"
"244.80000","20.40019","0.03050"
"245.10600","20.42566","0.03064"
"245.41200","20.45113","0.03066"
"245.71800","20.47666","0.03102"
"246.02400","20.50213","0.03098"
"246.33000","20.52766","0.03117"
"246.63600","20.55319","0.03130"
"246.94200","20.57872","0.03173"
"247.24800","20.60425","0.03181"
"247.55400","20.62966","0.03171"
"247.86000","20.65519","0.03210"
"248.16600","20.68066","0.03224"
"248.47200","20.70619","0.03219"
"248.77800","20.73172","0.03239"
"249.08400","20.75719","0.03267"
"249.39000","20.78272","0.03293"
"249.69600","20.80813","0.03291"
"250.00200","20.83366","0.03229"
"250.30800","20.85907","0.03252"
"250.61400","20.88472","0.03280"
"250.92000","20.91013","0.03251"
"251.22600","20.93572","0.03220"
"251.53200","20.96119","0.03208"
"251.83800","20.98667","0.03216"
"252.14400","21.01219","0.03264"
"252.45000","21.03766","0.03249"
"252.75600","21.06319","0.03250"
"253.06200","21.08861","0.03252"
"253.36800","21.11420","0.03240"
"253.67400","21.13973","0.03204"
"253.98000","21.16520","0.03265"
"254.28600","21.19073","0.03284"
"254.59200","21.21614","0.03314"
"254.89800","21.24166","0.03323"
"255.20400","21.26714","0.03368"
"255.51000","21.29267","0.03416"
"255.81600","21.31820","0.03447"
"256.12200","21.34367","0.03489"
"256.42800","21.36920","0.03517"
"256.73400","21.39467","0.03558"
"257.04000","21.42026","0.03619"
"257.34600","21.44567","0.03724"
"257.65200","21.47114","0.03780"
"257.95800","21.49673","0.03892"
"258.26400","21.52214","0.03923"
"258.57000","21.54779","0.03984"
"258.87600","21.57314","0.04170"
"259.18200","21.59873","0.04182"
"259.48800","21.62408","0.04068"
"259.79400","21.64967","0.03908"
"260.10000","21.67514","0.04087"
"260.40600","21.70067","0.04079"
"260.71200","21.72620","0.04303"
"261.01800","21.75161","0.04361"
"261.32400","21.77720","0.04522"
"261.63000","21.80267","0.04588"
"261.93600","21.82820","0.04682"
"262.24200","21.85367","0.04771"
"262.54800","21.87920","0.04809"
"262.85400","21.90473","0.04906"
"263.16000","21.93014","0.05051"
"263.46600","21.95567","0.05096"
"263.77200","21.98114","0.05195"
"264.07800","22.00673","0.05161"
"264.38400","22.03214","0.04168"
"264.69000","22.05761","0.04097"
"264.99600","22.08320","0.04126"
"265.30200","22.10868","0.03824"
"265.60800","22.13420","0.03615"
"265.91400","22.15961","0.03741"
"266.22000","22.18521","0.03776"
"266.52600","22.21068","0.03966"
"266.83200","22.23609","0.04111"
"267.13800","22.26174","0.04185"
"267.44400","22.28715","0.04234"
"267.75000","22.31274","0.04388"
"268.05600","22.33809","0.04343"
"268.36200","22.36368","0.04411"
"268.66800","22.38914","0.04474"
"268.97400","22.41468","0.04564"
"269.28000","22.44021","0.04495"
"269.58600","22.46568","0.04419"
"269.89200","22.49127","0.04378"
"270.19800","22.51668","0.04572"
"270.50400","22.54227","0.04528"
"270.81000","22.56768","0.04118"
"271.11600","22.59315","0.04226"
"271.42200","22.61868","0.04286"
"271.72800","22.64421","0.04372"
"272.03400","22.66974","0.04415"
"272.34000","22.69515","0.04545"
"272.64600","22.72074","0.04605"
"272.95200","22.74615","0.04699"
"273.25800","22.77168","0.04697"
"273.56400","22.79721","0.04730"
"273.87000","22.82262","0.04872"
"274.17600","22.84821","0.04936"
"274.48200","22.87368","0.04954"
"274.78800","22.89921","0.05096"
"275.09400","22.92468","0.05183"
"275.40000","22.95015","0.05249"
"275.70600","22.97568","0.05338"
"276.01200","23.00115","0.05363"
"276.31800","23.02674","0.05413"
"276.62400","23.05215","0.05485"
"276.93000","23.07768","0.05501"
"277.23600","23.10315","0.05623"
"277.54200","23.12868","0.05604"
"277.84800","23.15415","0.05653"
"278.15400","23.17969","0.05637"
"278.46000","23.20522","0.05718"
"278.76600","23.23062","0.05771"
"279.07200","23.25622","0.05769"
"279.37800","23.28169","0.05735"
"279.68400","23.30721","0.05814"
"279.99000","23.33269","0.05936"
"280.29600","23.35822","0.05926"
"280.60200","23.38369","0.06017"
"280.90800","23.40916","0.06086"
"281.21400","23.43475","0.06123"
"281.52000","23.46016","0.06278"
"281.82600","23.48569","0.06274"
"282.13200","23.51116","0.06382"
"282.43800","23.53663","0.06486"
"282.74400","23.56216","0.06511"
"283.05000","23.58763","0.06661"
"283.35600","23.61322","0.06749"
"283.66200","23.63863","0.06757"
"283.96800","23.66422","0.06886"
"284.27400","23.68963","0.06905"
"284.58000","23.71522","0.07028"
"284.88600","23.74075","0.07026"
"285.19200","23.76616","0.07146"
"285.49800","23.79169","0.07197"
"285.80400","23.81716","0.07227"
"286.11000","23.84269","0.07057"
"286.41600","23.86816","0.07144"
"286.72200","23.89369","0.07222"
"287.02800","23.91922","0.07298"
"287.33400","23.94463","0.07380"
"287.64000","23.97016","0.07385"
"287.94600","23.99569","0.07424"
"288.25200","24.02122","0.07296"
"288.55800","24.04669","0.07295"
"288.86400","24.07222","0.03525"
"289.17000","24.09769","0.03240"
"289.47600","24.12322","0.03988"
"289.78200","24.14869","0.03574"
"290.08800","24.17416","0.03323"
"290.39400","24.19969","0.04360"
"290.70000","24.22516","0.03885"
"291.00600","24.25069","0.03666"
"291.31200","24.27616","0.04386"
"291.61800","24.30163","0.04264"
"291.92400","24.32723","0.04647"
"292.23000","24.35263","0.04392"
"292.53600","24.37823","0.04511"
"292.84200","24.40370","0.05267"
"293.14800","24.42922","0.04950"
"293.45400","24.45470","0.05207"
"293.76000","24.48017","0.05411"
"294.06600","24.50570","0.05316"
"294.37200","24.53117","0.05786"
"294.67800","24.55670","0.05629"
"294.98400","24.58217","0.05668"
"295.29000","24.60776","0.05692"
"295.59600","24.63317","0.05595"
"295.90200","24.65870","0.05832"
"296.20800","24.68423","0.05983"
"296.51400","24.70964","0.05950"
"296.82000","24.73517","0.06238"
"297.12600","24.76058","0.06229"
"297.43200","24.78617","0.06259"
"297.73800","24.81164","0.06567"
"298.04400","24.83717","0.06532"
"298.35000","24.86270","0.06620"
"298.65600","24.88817","0.06824"
"298.96200","24.91364","0.06776"
"299.26800","24.93911","0.06935"
"299.57400","24.96470","0.06891"
"299.88000","24.99017","0.06918"
"300.18600","25.01570","0.07053"
"300.49200","25.04123","0.07124"
"300.79800","25.06670","0.07145"
"301.10400","25.09223","0.06724"
"301.41000","25.11764","0.06897"
"301.71600","25.14323","0.06851"
"302.02200","25.16870","0.06964"
"302.32800","25.19423","0.07112"
"302.63400","25.21970","0.07124"
"302.94000","25.24517","0.07132"
"303.24600","25.27070","0.07279"
"303.55200","25.29612","0.07356"
"303.85800","25.32170","0.07468"
"304.16400","25.34717","0.07465"
"304.47000","25.37271","0.07484"
"304.77600","25.39817","0.07547"
"305.08200","25.42365","0.07558"
"305.38800","25.44917","0.07584"
"305.69400","25.47465","0.07645"
"306.00000","25.50011","0.07643"
"306.30600","25.52565","0.07672"
"306.61200","25.55124","0.07756"
"306.91800","25.57671","0.07766"
"307.22400","25.60218","0.07651"
"307.53000","25.62771","0.07742"
"307.83600","25.65312","0.07731"
"308.14200","25.67871","0.07792"
"308.44800","25.70418","0.07842"
"308.75400","25.72971","0.07868"
"309.06000","25.75524","0.07899"
"309.36600","25.78071","0.07922"
"309.67200","25.80624","0.07926"
"309.97800","25.83165","0.07984"
"310.28400","25.85718","0.08003"
"310.59000","25.88259","0.08045"
"310.89600","25.90818","0.08095"
"311.20200","25.93371","0.08112"
"311.50800","25.95924","0.08150"
"311.81400","25.98477","0.08201"
"312.12000","26.01012","0.08265"
"312.42600","26.03571","0.08347"
"312.73200","26.06112","0.08325"
"313.03800","26.08671","0.08436"
"313.34400","26.11218","0.08485"
"313.65000","26.13771","0.08587"
"313.95600","26.16324","0.08715"
"314.26200","26.18865","0.08846"
"314.56800","26.21418","0.09019"
"314.87400","26.23959","0.09037"
"315.18000","26.26518","0.09211"
"315.48600","26.29066","0.09372"
"315.79200","26.31618","0.09518"
"316.09800","26.34171","0.09598"
"316.40400","26.36712","0.09829"
"316.71000","26.39271","0.09961"
"317.01600","26.41818","0.10125"
"317.32200","26.44366","0.10321"
"317.62800","26.46918","0.10443"
"317.93400","26.49466","0.10561"
"318.24000","26.52025","0.10779"
"318.54600","26.54565","0.10925"
"318.85200","26.57119","0.11087"
"319.15800","26.59660","0.11218"
"319.46400","26.62219","0.11453"
"319.77000","26.64766","0.11471"
"320.07600","26.67319","0.11535"
"320.38200","26.69866","0.11794"
"320.68800","26.72419","0.11989"
"320.99400","26.74972","0.12171"
"321.30000","26.77513","0.12437"
"321.60600","26.80072","0.12668"
"321.91200","26.82613","0.12831"
"322.21800","26.85166","0.13023"
"322.52400","26.87719","0.13157"
"322.83000","26.90272","0.13238"
"323.13600","26.92825","0.13357"
"323.44200","26.95366","0.13361"
"323.74800","26.97919","0.13450"
"324.05400","27.00466","0.13529"
"324.36000","27.03019","0.13591"
"324.66600","27.05566","0.13706"
"324.97200","27.08113","0.13749"
"325.27800","27.10672","0.13846"
"325.58400","27.13213","0.13839"
"325.89000","27.15766","0.13920"
"326.19600","27.18319","0.14001"
"326.50200","27.20866","0.14028"
"326.80800","27.23419","0.14059"
"327.11400","27.25966","0.14165"
"327.42000","27.28525","0.14207"
"327.72600","27.31066","0.14286"
"328.03200","27.33619","0.14395"
"328.33800","27.36160","0.14572"
"328.64400","27.38719","0.14655"
"328.95000","27.41266","0.14848"
"329.25600","27.43820","0.14967"
"329.56200","27.46366","0.15170"
"329.86800","27.48920","0.15318"
"330.17400","27.51472","0.15531"
"330.48000","27.54014","0.15642"
"330.78600","27.56573","0.15719"
"331.09200","27.59114","0.15935"
"331.39800","27.61667","0.16020"
"331.70400","27.64220","0.16195"
"332.01000","27.66773","0.16335"
"332.31600","27.69320","0.16446"
"332.62200","27.71867","0.16624"
"332.92800","27.74420","0.16741"
"333.23400","27.76967","0.16868"
"333.54000","27.79520","0.17070"
"333.84600","27.82067","0.17174"
"334.15200","27.84614","0.17288"
"334.45800","27.87173","0.17420"
"334.76400","27.89714","0.17504"
"335.07000","27.92273","0.17578"
"335.37600","27.94814","0.17677"
"335.68200","27.97367","0.17780"
"335.98800","27.99920","0.17813"
"336.29400","28.02467","0.17912"
"336.60000","28.05026","0.17996"
"336.90600","28.07561","0.18090"
"337.21200","28.10120","0.18162"
"337.51800","28.12667","0.18209"
"337.82400","28.15220","0.18296"
"338.13000","28.17767","0.18351"
"338.43600","28.20314","0.18440"
"338.74200","28.22867","0.18517"
"339.04800","28.25420","0.18583"
"339.35400","28.27973","0.18646"
"339.66000","28.30520","0.18704"
"339.96600","28.33068","0.18691"
"340.27200","28.35620","0.18797"
"340.57800","28.38167","0.18846"
"340.88400","28.40720","0.18929"
"341.19000","28.43262","0.19018"
"341.49600","28.45820","0.19064"
"341.80200","28.48367","0.19164"
"342.10800","28.50914","0.19285"
"342.41400","28.53461","0.19335"
"342.72000","28.56014","0.19406"
"343.02600","28.58568","0.19501"
"343.33200","28.61109","0.19580"
"343.63800","28.63668","0.06283"
"343.94400","28.66221","0.07238"
"344.25000","28.68768","0.06912"
"344.55600","28.71315","0.07195"
"344.86200","28.73868","0.07381"
"345.16800","28.76421","0.07099"
"345.47400","28.78962","0.07495"
"345.78000","28.81521","0.06870"
"346.08600","28.84068","0.07705"
"346.39200","28.86621","0.07049"
"346.69800","28.89168","0.07741"
"347.00400","28.91721","0.07319"
"347.31000","28.94268","0.07757"
"347.61600","28.96809","0.07556"
"347.92200","28.99368","0.07762"
"348.22800","29.01915","0.07544"
"348.53400","29.04474","0.07717"
"348.84000","29.07015","0.07610"
"349.14600","29.09574","0.07697"
"349.45200","29.12121","0.07747"
"349.75800","29.14668","0.07695"
"350.06400","29.17215","0.07868"
"350.37000","29.19762","0.07706"
"350.67600","29.22321","0.07930"
"350.98200","29.24874","0.07761"
"351.28800","29.27421","0.07911"
"351.59400","29.29968","0.07840"
"351.90000","29.32515","0.07894"
"352.20600","29.35068","0.07924"
"352.51200","29.37615","0.07913"
"352.81800","29.40168","0.07995"
"353.12400","29.42715","0.07927"
"353.43000","29.45274","0.08045"
"353.73600","29.47821","0.07960"
"354.04200","29.50368","0.08071"
"354.34800","29.52921","0.08045"
"354.65400","29.55468","0.08032"
"354.96000","29.58021","0.08131"
"355.26600","29.60568","0.08053"
"355.57200","29.63128","0.08206"
"355.87800","29.65668","0.08117"
"356.18400","29.68216","0.08197"
"356.49000","29.70769","0.08234"
"356.79600","29.73315","0.08205"
"357.10200","29.75869","0.08338"
"357.40800","29.78416","0.08276"
"357.71400","29.80975","0.08368"
"358.02000","29.83516","0.08394"
"358.32600","29.86069","0.08421"
"358.63200","29.88616","0.08546"
"358.93800","29.91163","0.08495"
"359.24400","29.93716","0.08721"
"359.55000","29.96263","0.08576"
"359.85600","29.98822","0.08696"
"360.16200","30.01369","0.08774"
"360.46800","30.03916","0.08770"
"360.77400","30.06475","0.08865"
"361.08000","30.09010","0.08874"
"361.38600","30.11569","0.08982"
"361.69200","30.14110","0.09102"
"361.99800","30.16675","0.09072"
"362.30400","30.19216","0.09238"
"362.61000","30.21775","0.09230"
"362.91600","30.24322","0.09263"
"363.22200","30.26863","0.09422"
"363.52800","30.29416","0.09453"
"363.83400","30.31957","0.09590"
"364.14000","30.34522","0.09648"
"364.44600","30.37069","0.09582"
"364.75200","30.39622","0.09793"
"365.05800","30.42169","0.09815"
"365.36400","30.44722","0.09929"
"365.67000","30.47269","0.10033"
"365.97600","30.49816","0.09993"
"366.28200","30.52369","0.10086"
"366.58800","30.54917","0.10074"
"366.89400","30.57469","0.10219"
"367.20000","30.60022","0.10315"
"367.50600","30.62570","0.10292"
"367.81200","30.65122","0.10437"
"368.11800","30.67664","0.10440"
"368.42400","30.70222","0.10440"
"368.73000","30.72769","0.10478"
"369.03600","30.75323","0.10564"
"369.34200","30.77876","0.10634"
"369.64800","30.80416","0.10782"
"369.95400","30.82970","0.10743"
"370.26000","30.85517","0.10902"
"370.56600","30.88070","0.11032"
"370.87200","30.90617","0.11039"
"371.17800","30.93170","0.11133"
"371.48400","30.95723","0.11256"
"371.79000","30.98270","0.11293"
"372.09600","31.00823","0.11419"
"372.40200","31.03364","0.11428"
"372.70800","31.05917","0.11549"
"373.01400","31.08458","0.11589"
"373.32000","31.11017","0.11617"
"373.62600","31.13570","0.11653"
"373.93200","31.16123","0.11846"
"374.23800","31.18670","0.11838"
"374.54400","31.21211","0.12041"
"374.85000","31.23770","0.11981"
"375.15600","31.26311","0.12081"
"375.46200","31.28870","0.12199"
"375.76800","31.31417","0.12330"
"376.07400","31.33970","0.12431"
"376.38000","31.36523","0.12494"
"376.68600","31.39064","0.12532"
"376.99200","31.41623","0.12645"
"377.29800","31.44170","0.12752"
"377.60400","31.46723","0.12787"
"377.91000","31.49270","0.12869"
"378.21600","31.51817","0.13015"
"378.52200","31.54376","0.13070"
"378.82800","31.56917","0.13109"
"379.13400","31.59470","0.13196"
"379.44000","31.62011","0.13293"
"379.74600","31.64570","0.13296"
"380.05200","31.67117","0.13383"
"380.35800","31.69670","0.13487"
"380.66400","31.72217","0.13540"
"380.97000","31.74764","0.13623"
"381.27600","31.77317","0.13615"
"381.58200","31.79864","0.13625"
"381.88800","31.82417","0.13671"
"382.19400","31.84965","0.13697"
"382.50000","31.87517","0.13666"
"382.80600","31.90070","0.01870"
"383.11200","31.92617","0.00832"
"383.41800","31.95177","0.01586"
"383.72400","31.97712","0.00435"
"384.03000","32.00270","0.01874"
"384.33600","32.02812","0.00386"
"384.64200","32.05371","0.01454"
"384.94800","32.07917","0.00483"
"385.25400","32.10464","0.01059"
"385.56000","32.13024","0.01061"
"385.86600","32.15565","0.00756"
"386.17200","32.18118","0.01317"
"386.47800","32.20665","0.00992"
"386.78400","32.23218","0.00855"
"387.09000","32.25771","0.01400"
"387.39600","32.28318","0.00565"
"387.70200","32.30877","0.01202"
"388.00800","32.33418","0.00815"
"388.31400","32.35971","0.00899"
"388.62000","32.38512","0.01351"
"388.92600","32.41065","0.00761"
"389.23200","32.43612","0.01272"
"389.53800","32.46165","0.00888"
"389.84400","32.48718","0.00855"
"390.15000","32.51265","0.01237"
"390.45600","32.53818","0.00926"
"390.76200","32.56365","0.01150"
"391.06800","32.58918","0.01057"
"391.37400","32.61465","0.00993"
"391.68000","32.64018","0.01139"
"391.98600","32.66571","0.01013"
"392.29200","32.69118","0.01117"
"392.59800","32.71671","0.01117"
"392.90400","32.74218","0.01072"
"393.21000","32.76771","0.01098"
"393.51600","32.79313","0.01156"
"393.82200","32.81865","0.01073"
"394.12800","32.84418","0.01047"
"394.43400","32.86966","0.01158"
"394.74000","32.89518","0.01032"
"395.04600","32.92065","0.01215"
"395.35200","32.94619","0.01211"
"395.65800","32.97165","0.01145"
"395.96400","32.99712","0.01161"
"396.27000","33.02272","0.01052"
"396.57600","33.04813","0.01187"
"396.88200","33.07372","0.01196"
"397.18800","33.09912","0.01135"
"397.49400","33.12471","0.01174"
"397.80000","33.15012","0.01183"
"398.10600","33.17572","0.01147"
"398.41200","33.20119","0.01200"
"398.71800","33.22666","0.01169"
"399.02400","33.25225","0.01238"
"399.33000","33.27766","0.01176"
"399.63600","33.30325","0.01241"
"399.94200","33.32866","0.01208"
"400.24800","33.35419","0.01165"
"400.55400","33.37972","0.01219"
"400.86000","33.40519","0.01156"
"401.16600","33.43072","0.01235"
"401.47200","33.45613","0.01188"
"401.77800","33.48172","0.01272"
"402.08400","33.50719","0.01258"
"402.39000","33.53266","0.01227"
"402.69600","33.55819","0.01282"
"403.00200","33.58366","0.01273"
"403.30800","33.60919","0.01238"
"403.61400","33.63466","0.01284"
"403.92000","33.66019","0.01263"
"404.22600","33.68566","0.01272"
"404.53200","33.71119","0.01318"
"404.83800","33.73672","0.01266"
"405.14400","33.76213","0.01313"
"405.45000","33.78778","0.01321"
"405.75600","33.81313","0.01321"
"406.06200","33.83872","0.01327"
"406.36800","33.86413","0.01300"
"406.67400","33.88972","0.01312"
"406.98000","33.91513","0.01345"
"407.28600","33.94061","0.01329"
"407.59200","33.96619","0.01364"
"407.89800","33.99166","0.01345"
"408.20400","34.01719","0.01338"
"408.51000","34.04266","0.01394"
"408.81600","34.06819","0.01392"
"409.12200","34.09367","0.01366"
"409.42800","34.11920","0.01436"
"409.73400","34.14473","0.01393"
"410.04000","34.17020","0.01377"
"410.34600","34.19572","0.01415"
"410.65200","34.22113","0.01418"
"410.95800","34.24673","0.01412"
"411.26400","34.27214","0.01455"
"411.57000","34.29761","0.01448"
"411.87600","34.32320","0.01451"
"412.18200","34.34867","0.01473"
"412.48800","34.37420","0.01506"
"412.79400","34.39961","0.01471"
"413.10000","34.42520","0.01529"
"413.40600","34.45067","0.01518"
"413.71200","34.47620","0.01519"
"414.01800","34.50173","0.01556"
"414.32400","34.52714","0.01600"
"414.63000","34.55273","0.01507"
"414.93600","34.57814","0.01572"
"415.24200","34.60367","0.01607"
"415.54800","34.62920","0.01619"
"415.85400","34.65473","0.01637"
"416.16000","34.68020","0.01628"
"416.46600","34.70567","0.01658"
"416.77200","34.73114","0.01666"
"417.07800","34.75667","0.01611"
"417.38400","34.78220","0.01674"
"417.69000","34.80761","0.01679"
"417.99600","34.83320","0.01680"
"418.30200","34.85873","0.01744"
"418.60800","34.88420","0.01725"
"418.91400","34.90973","0.01686"
"419.22000","34.93520","0.01724"
"419.52600","34.96067","0.01787"
"419.83200","34.98615","0.01746"
"420.13800","35.01168","0.01777"
"420.44400","35.03720","0.01771"
"420.75000","35.06261","0.01836"
"421.05600","35.08820","0.01811"
"421.36200","35.11367","0.01783"
"421.66800","35.13921","0.01806"
"421.97400","35.16462","0.01840"
"422.28000","35.19020","0.01898"
"422.58600","35.21568","0.01857"
"422.89200","35.24121","0.01895"
"423.19800","35.26674","0.01963"
"423.50400","35.29215","0.01897"
"423.81000","35.31768","0.01879"
"424.11600","35.34309","0.01912"
"424.42200","35.36874","0.01990"
"424.72800","35.39415","0.02030"
"425.03400","35.41968","0.01998"
"425.34000","35.44521","0.01985"
"425.64600","35.47062","0.02024"
"425.95200","35.49615","0.02037"
"426.25800","35.52162","0.02092"
"426.56400","35.54721","0.02111"
"426.87000","35.57268","0.02120"
"427.17600","35.59821","0.02043"
"427.48200","35.62374","0.02148"
"427.78800","35.64915","0.02075"
"428.09400","35.67468","0.02128"
"428.40000","35.70015","0.02142"
"428.70600","35.72568","0.02196"
"429.01200","35.75121","0.02229"
"429.31800","35.77674","0.02245"
"429.62400","35.80221","0.02241"
"429.93000","35.82768","0.02254"
"430.23600","35.85321","0.02238"
"430.54200","35.87862","0.02294"
"430.84800","35.90421","0.02265"
"431.15400","35.92962","0.02329"
"431.46000","35.95521","0.02340"
"431.76600","35.98074","0.02385"
"432.07200","36.00621","0.02393"
"432.37800","36.03168","0.02395"
"432.68400","36.05716","0.02399"
"432.99000","36.08268","0.02396"
"433.29600","36.10810","0.02476"
"433.60200","36.13374","0.02472"
"433.90800","36.15915","0.02464"
"434.21400","36.18468","0.02485"
"434.52000","36.21016","0.02464"
"434.82600","36.23563","0.02452"
"435.13200","36.26116","0.02534"
"435.43800","36.28657","0.02448"
"435.74400","36.31216","0.02441"
"436.05000","36.33768","0.02534"
"436.35600","36.36322","0.02506"
"436.66200","36.38875","0.02546"
"436.96800","36.41416","0.02579"
"437.27400","36.43963","0.02579"
"437.58000","36.46516","0.02596"
"437.88600","36.49075","0.02594"
"438.19200","36.51622","0.02551"
"438.49800","36.54169","0.02623"
"438.80400","36.56722","0.02595"
"439.11000","36.59263","0.02602"
"439.41600","36.61822","0.02629"
"439.72200","36.64357","0.02672"
"440.02800","36.66916","0.02667"
"440.33400","36.69469","0.02682"
"440.64000","36.72022","0.02774"
"440.94600","36.74575","0.02717"
"441.25200","36.77110","0.02789"
"441.55800","36.79669","0.02777"
"441.86400","36.82216","0.02824"
"442.17000","36.84775","0.02826"
"442.47600","36.87316","0.02820"
"442.78200","36.89869","0.02869"
"443.08800","36.92422","0.02879"
"443.39400","36.94963","0.02862"
"443.70000","36.97522","0.02900"
"444.00600","37.00063","0.02890"
"444.31200","37.02622","0.02919"
"444.61800","37.05163","0.02906"
"444.92400","37.07716","0.02928"
"445.23000","37.10270","0.02927"
"445.53600","37.12817","0.02925"
"445.84200","37.15369","0.02949"
"446.14800","37.17916","0.02955"
"446.45400","37.20469","0.03019"
"446.76000","37.23016","0.03006"
"447.06600","37.25570","0.03008"
"447.37200","37.28123","0.03031"
"447.67800","37.30670","0.03037"
"447.98400","37.33223","0.03048"
"448.29000","37.35764","0.03016"
"448.59600","37.38316","0.03021"
"448.90200","37.40863","0.03016"
"449.20800","37.43423","0.03012"
"449.51400","37.45970","0.03047"
"449.82000","37.48517","0.03034"
"450.12600","37.51070","0.03037"
"450.43200","37.53611","0.03062"
"450.73800","37.56170","0.03075"
"451.04400","37.58717","0.03044"
"451.35000","37.61270","0.03066"
"451.65600","37.63811","0.03063"
"451.96200","37.66364","0.03100"
"452.26800","37.68923","0.03088"
"452.57400","37.71464","0.03116"
"452.88000","37.74017","0.03100"
"453.18600","37.76564","0.03088"
"453.49200","37.79123","0.02809"
"453.79800","37.81664","0.00463"
"454.10400","37.84217","0.00761"
"454.41000","37.86770","0.00275"
"454.71600","37.89317","0.00220"
"455.02200","37.91870","0.00238"
"455.32800","37.94411","0.00619"
"455.63400","37.96970","0.00252"
"455.94000","37.99517","0.00283"
"456.24600","38.02065","0.00239"
"456.55200","38.04623","0.00421"
"456.85800","38.07164","0.00252"
"456.87400","38.07302","0.00248"