File: Force_trajectories/170108_1/Specimen_RawData_2.csv
End date,"1/8/2017"
Specimen label,"2DG_11"
Maximum Load,"0.19822",N

Time,Extension,Load
(s),(mm),(N)
"0.00000","0.00000","-0.00003"
"0.25800","0.02033","0.00043"
"0.51600","0.04323","0.00084"
"0.77400","0.06475","0.00076"
"1.03200","0.08622","0.00156"
"1.29000","0.10780","0.00126"
"1.54800","0.12921","0.00143"
"1.80600","0.15073","0.00188"
"2.06400","0.17219","0.00194"
"2.32200","0.19372","0.00225"
"2.58000","0.21524","0.00256"
"2.83800","0.23671","0.00298"
"3.09600","0.25817","0.00272"
"3.35400","0.27964","0.00329"
"3.61200","0.30122","0.00328"
"3.87000","0.32268","0.00329"
"4.12800","0.34427","0.00359"
"4.38600","0.36567","0.00402"
"4.64400","0.38726","0.00434"
"4.90200","0.40872","0.00473"
"5.16000","0.43031","0.00441"
"5.41800","0.45159","0.00468"
"5.67600","0.47317","0.00479"
"5.93400","0.49464","0.00509"
"6.19200","0.51622","0.00511"
"6.45000","0.53769","0.00555"
"6.70800","0.55921","0.00584"
"6.96600","0.58068","0.00580"
"7.22400","0.60226","0.00602"
"7.48200","0.62366","0.00596"
"7.74000","0.64525","0.00664"
"7.99800","0.66665","0.00641"
"8.25600","0.68824","0.00696"
"8.51400","0.70970","0.00686"
"8.77200","0.73123","0.00708"
"9.03000","0.75275","0.00742"
"9.28800","0.77421","0.00709"
"9.54600","0.79574","0.00809"
"9.80400","0.81720","0.00789"
"10.06200","0.83879","0.00821"
"10.32000","0.86019","0.00863"
"10.57800","0.88172","0.00823"
"10.83600","0.90318","0.00848"
"11.09400","0.92470","0.00856"
"11.35200","0.94617","0.00890"
"11.61000","0.96775","0.00846"
"11.86800","0.98916","0.00882"
"12.12600","1.01074","0.00890"
"12.38400","1.03215","0.00943"
"12.64200","1.05373","0.00958"
"12.90000","1.07520","0.01025"
"13.15800","1.09672","0.01033"
"13.41600","1.11812","0.00965"
"13.67400","1.13971","0.00962"
"13.93200","1.16123","0.00953"
"14.19000","1.18276","0.00971"
"14.44800","1.20422","0.00991"
"14.70600","1.22569","0.01051"
"14.96400","1.24721","0.01047"
"15.22200","1.26867","0.01072"
"15.48000","1.29020","0.01076"
"15.73800","1.31172","0.01133"
"15.99600","1.33319","0.01101"
"16.25400","1.35471","0.01094"
"16.51200","1.37624","0.01090"
"16.77000","1.39770","0.01138"
"17.02800","1.41922","0.01153"
"17.28600","1.44069","0.01157"
"17.54400","1.46227","0.01167"
"17.80200","1.48368","0.01242"
"18.06000","1.50520","0.01224"
"18.31800","1.52661","0.01215"
"18.57600","1.54819","0.01212"
"18.83400","1.56965","0.01293"
"19.09200","1.59124","0.01295"
"19.35000","1.61264","0.01318"
"19.60800","1.63423","0.01276"
"19.86600","1.65569","0.01295"
"20.12400","1.67728","0.01318"
"20.38200","1.69874","0.01359"
"20.64000","1.72020","0.01395"
"20.89800","1.74167","0.01398"
"21.15600","1.76325","0.01352"
"21.41400","1.78472","0.01378"
"21.67200","1.80624","0.01300"
"21.93000","1.82777","0.01306"
"22.18800","1.84917","0.01417"
"22.44600","1.87075","0.01391"
"22.70400","1.89216","0.01448"
"22.96200","1.91368","0.01468"
"23.22000","1.93521","0.01457"
"23.47800","1.95673","0.01455"
"23.73600","1.97820","0.01498"
"23.99400","1.99972","0.01476"
"24.25200","2.02119","0.01504"
"24.51000","2.04271","0.01537"
"24.76800","2.06417","0.01535"
"25.02600","2.08570","0.01479"
"25.28400","2.10722","0.01573"
"25.54200","2.12881","0.01592"
"25.80000","2.15015","0.01571"
"26.05800","2.17174","0.01583"
"26.31600","2.19320","0.01605"
"26.57400","2.21478","0.01596"
"26.83200","2.23619","0.01688"
"27.09000","2.25771","0.01668"
"27.34800","2.27924","0.01653"
"27.60600","2.30076","0.01661"
"27.86400","2.32229","0.01657"
"28.12200","2.34375","0.01690"
"28.38000","2.36521","0.01658"
"28.63800","2.38668","0.01738"
"28.89600","2.40826","0.01752"
"29.15400","2.42973","0.01745"
"29.41200","2.45125","0.01721"
"29.67000","2.47266","0.01751"
"29.92800","2.49424","0.01806"
"30.18600","2.51564","0.01784"
"30.44400","2.53723","0.01760"
"30.70200","2.55869","0.01807"
"30.96000","2.58022","0.01832"
"31.21800","2.60162","0.01850"
"31.47600","2.62327","0.01856"
"31.73400","2.64473","0.01874"
"31.99200","2.66625","0.01844"
"32.25000","2.68772","0.01881"
"32.50800","2.70924","0.01933"
"32.76600","2.73071","0.01872"
"33.02400","2.75229","0.01950"
"33.28200","2.77370","0.01935"
"33.54000","2.79522","0.01918"
"33.79800","2.81662","0.01959"
"34.05600","2.83821","0.01999"
"34.31400","2.85967","0.01991"
"34.57200","2.88126","0.01983"
"34.83000","2.90272","0.01960"
"35.08800","2.92425","0.02011"
"35.34600","2.94571","0.01990"
"35.60400","2.96724","0.02026"
"35.86200","2.98876","0.02079"
"36.12000","3.01022","0.02038"
"36.37800","3.03181","0.02077"
"36.63600","3.05315","0.02101"
"36.89400","3.07474","0.02132"
"37.15200","3.09620","0.02128"
"37.41000","3.11773","0.02133"
"37.66800","3.13913","0.02125"
"37.92600","3.16071","0.02180"
"38.18400","3.18218","0.02164"
"38.44200","3.20376","0.02150"
"38.70000","3.22517","0.02160"
"38.95800","3.24675","0.02194"
"39.21600","3.26822","0.02205"
"39.47400","3.28974","0.02241"
"39.73200","3.31120","0.02226"
"39.99000","3.33273","0.02297"
"40.24800","3.35425","0.02259"
"40.50600","3.37572","0.02276"
"40.76400","3.39724","0.02292"
"41.02200","3.41871","0.02288"
"41.28000","3.44023","0.02304"
"41.53800","3.46169","0.02326"
"41.79600","3.48316","0.02280"
"42.05400","3.50474","0.02338"
"42.31200","3.52621","0.02327"
"42.57000","3.54767","0.02351"
"42.82800","3.56926","0.02418"
"43.08600","3.59066","0.02366"
"43.34400","3.61224","0.02409"
"43.60200","3.63365","0.02471"
"43.86000","3.65523","0.02444"
"44.11800","3.67670","0.02455"
"44.37600","3.69822","0.02413"
"44.63400","3.71969","0.02512"
"44.89200","3.74121","0.02496"
"45.15000","3.76268","0.02530"
"45.40800","3.78426","0.02538"
"45.66600","3.80572","0.02576"
"45.92400","3.82725","0.02547"
"46.18200","3.84871","0.02563"
"46.44000","3.87012","0.02573"
"46.69800","3.89170","0.02562"
"46.95600","3.91328","0.02576"
"47.21400","3.93475","0.02625"
"47.47200","3.95615","0.02695"
"47.73000","3.97774","0.02659"
"47.98800","3.99920","0.02667"
"48.24600","4.02073","0.02757"
"48.50400","4.04219","0.02780"
"48.76200","4.06372","0.02752"
"49.02000","4.08512","0.02721"
"49.27800","4.10670","0.02780"
"49.53600","4.12823","0.02779"
"49.79400","4.14975","0.02784"
"50.05200","4.17116","0.02817"
"50.31000","4.19268","0.02816"
"50.56800","4.21415","0.02843"
"50.82600","4.23573","0.02933"
"51.08400","4.25719","0.02852"
"51.34200","4.27872","0.02916"
"51.60000","4.30018","0.02952"
"51.85800","4.32177","0.02956"
"52.11600","4.34323","0.02976"
"52.37400","4.36476","0.03003"
"52.63200","4.38616","0.02977"
"52.89000","4.40768","0.02995"
"53.14800","4.42921","0.03048"
"53.40600","4.45073","0.03092"
"53.66400","4.47226","0.03104"
"53.92200","4.49372","0.03143"
"54.18000","4.51519","0.03121"
"54.43800","4.53671","0.03166"
"54.69600","4.55823","0.03134"
"54.95400","4.57970","0.03215"
"55.21200","4.60128","0.03261"
"55.47000","4.62269","0.03304"
"55.72800","4.64421","0.03241"
"55.98600","4.66568","0.03276"
"56.24400","4.68726","0.03353"
"56.50200","4.70860","0.03411"
"56.76000","4.73019","0.03343"
"57.01800","4.75171","0.03405"
"57.27600","4.77324","0.03448"
"57.53400","4.79470","0.03376"
"57.79200","4.81623","0.03459"
"58.05000","4.83769","0.03494"
"58.30800","4.85922","0.03480"
"58.56600","4.88074","0.03590"
"58.82400","4.90226","0.03531"
"59.08200","4.92367","0.03546"
"59.34000","4.94525","0.03585"
"59.59800","4.96672","0.03588"
"59.85600","4.98824","0.03667"
"60.11400","5.00977","0.03619"
"60.37200","5.03117","0.03711"
"60.63000","5.05275","0.03705"
"60.88800","5.07422","0.03661"
"61.14600","5.09574","0.03785"
"61.40400","5.11715","0.03773"
"61.66200","5.13873","0.03719"
"61.92000","5.16014","0.03798"
"62.17800","5.18172","0.03787"
"62.43600","5.20318","0.03874"
"62.69400","5.22477","0.03863"
"62.95200","5.24617","0.03838"
"63.21000","5.26776","0.03900"
"63.46800","5.28916","0.03912"
"63.72600","5.31075","0.03922"
"63.98400","5.33221","0.03916"
"64.24200","5.35373","0.03924"
"64.50000","5.37520","0.03961"
"64.75800","5.39672","0.03960"
"65.01600","5.41825","0.04017"
"65.27400","5.43971","0.04005"
"65.53200","5.46118","0.03997"
"65.79000","5.48270","0.04030"
"66.04800","5.50422","0.04053"
"66.30600","5.52575","0.04086"
"66.56400","5.54721","0.04041"
"66.82200","5.56874","0.04123"
"67.08000","5.59026","0.04098"
"67.33800","5.61173","0.04113"
"67.59600","5.63325","0.04139"
"67.85400","5.65465","0.04150"
"68.11200","5.67624","0.04150"
"68.37000","5.69770","0.04172"
"68.62800","5.71923","0.04175"
"68.88600","5.74069","0.04161"
"69.14400","5.76222","0.04180"
"69.40200","5.78362","0.04190"
"69.66000","5.80520","0.04190"
"69.91800","5.82661","0.04195"
"70.17600","5.84825","0.04219"
"70.43400","5.86966","0.04252"
"70.69200","5.89124","0.04226"
"70.95000","5.91271","0.04246"
"71.20800","5.93423","0.04235"
"71.46600","5.95575","0.04224"
"71.72400","5.97722","0.04255"
"71.98200","5.99868","0.04216"
"72.24000","6.02021","0.04250"
"72.49800","6.04173","0.04279"
"72.75600","6.06326","0.04259"
"73.01400","6.08472","0.04277"
"73.27200","6.10619","0.04272"
"73.53000","6.12771","0.04302"
"73.78800","6.14917","0.04324"
"74.04600","6.17076","0.04352"
"74.30400","6.19210","0.04338"
"74.56200","6.21375","0.04375"
"74.82000","6.23521","0.04380"
"75.07800","6.25674","0.04383"
"75.33600","6.27820","0.04402"
"75.59400","6.29966","0.04412"
"75.85200","6.32119","0.04390"
"76.11000","6.34271","0.04430"
"76.36800","6.36418","0.04457"
"76.62600","6.38576","0.04459"
"76.88400","6.40723","0.04489"
"77.14200","6.42869","0.04531"
"77.40000","6.45015","0.04526"
"77.65800","6.47174","0.04603"
"77.91600","6.49326","0.04644"
"78.17400","6.51473","0.04627"
"78.43200","6.53619","0.04642"
"78.69000","6.55772","0.04683"
"78.94800","6.57930","0.04650"
"79.20600","6.60070","0.04680"
"79.46400","6.62223","0.04719"
"79.72200","6.64369","0.04737"
"79.98000","6.66522","0.04745"
"80.23800","6.68668","0.04770"
"80.49600","6.70821","0.04784"
"80.75400","6.72967","0.04810"
"81.01200","6.75119","0.04968"
"81.27000","6.77266","0.04881"
"81.52800","6.79424","0.04943"
"81.78600","6.81571","0.04972"
"82.04400","6.83717","0.05025"
"82.30200","6.85864","0.05102"
"82.56000","6.88016","0.05093"
"82.81800","6.90169","0.05189"
"83.07600","6.92327","0.05213"
"83.33400","6.94467","0.05274"
"83.59200","6.96626","0.05358"
"83.85000","6.98772","0.05362"
"84.10800","7.00919","0.05388"
"84.36600","7.03071","0.05505"
"84.62400","7.05224","0.05586"
"84.88200","7.07370","0.05639"
"85.14000","7.09516","0.05670"
"85.39800","7.11675","0.05761"
"85.65600","7.13821","0.05771"
"85.91400","7.15974","0.05877"
"86.17200","7.18120","0.06008"
"86.43000","7.20273","0.06048"
"86.68800","7.22419","0.06021"
"86.94600","7.24571","0.06045"
"87.20400","7.26712","0.06171"
"87.46200","7.28876","0.06210"
"87.72000","7.31017","0.06252"
"87.97800","7.33169","0.06314"
"88.23600","7.35316","0.06382"
"88.49400","7.37474","0.06441"
"88.75200","7.39620","0.06526"
"89.01000","7.41773","0.06517"
"89.26800","7.43919","0.06617"
"89.52600","7.46072","0.06635"
"89.78400","7.48218","0.06667"
"90.04200","7.50371","0.06793"
"90.30000","7.52523","0.06823"
"90.55800","7.54675","0.06876"
"90.81600","7.56822","0.06914"
"91.07400","7.58968","0.06981"
"91.33200","7.61121","0.07080"
"91.59000","7.63267","0.07092"
"91.84800","7.65420","0.07092"
"92.10600","7.67572","0.07205"
"92.36400","7.69719","0.07221"
"92.62200","7.71871","0.07270"
"92.88000","7.74023","0.07289"
"93.13800","7.76170","0.07413"
"93.39600","7.78322","0.07453"
"93.65400","7.80463","0.07487"
"93.91200","7.82621","0.07527"
"94.17000","7.84773","0.07626"
"94.42800","7.86926","0.07644"
"94.68600","7.89066","0.07742"
"94.94400","7.91219","0.07794"
"95.20200","7.93371","0.07628"
"95.46000","7.95524","0.07845"
"95.71800","7.97670","0.07921"
"95.97600","7.99823","0.08016"
"96.23400","8.01969","0.08038"
"96.49200","8.04127","0.08108"
"96.75000","8.06274","0.08176"
"97.00800","8.08426","0.08189"
"97.26600","8.10573","0.08245"
"97.52400","8.12719","0.08346"
"97.78200","8.14872","0.08302"
"98.04000","8.17018","0.08374"
"98.29800","8.19176","0.08425"
"98.55600","8.21317","0.08470"
"98.81400","8.23469","0.08526"
"99.07200","8.25616","0.08531"
"99.33000","8.27774","0.08617"
"99.58800","8.29915","0.08637"
"99.84600","8.32073","0.08663"
"100.10400","8.34213","0.08668"
"100.36200","8.36372","0.08717"
"100.62000","8.38518","0.08772"
"100.87800","8.40671","0.08765"
"101.13600","8.42817","0.08763"
"101.39400","8.44970","0.01654"
"101.65200","8.47116","0.00983"
"101.91000","8.49274","0.01449"
"102.16800","8.51421","0.01100"
"102.42600","8.53573","0.01220"
"102.68400","8.55714","0.01232"
"102.94200","8.57866","0.01153"
"103.20000","8.60025","0.01350"
"103.45800","8.62177","0.01134"
"103.71600","8.64323","0.01333"
"103.97400","8.66476","0.01244"
"104.23200","8.68616","0.01231"
"104.49000","8.70769","0.01297"
"104.74800","8.72927","0.01228"
"105.00600","8.75068","0.01367"
"105.26400","8.77226","0.01302"
"105.52200","8.79366","0.01353"
"105.78000","8.81525","0.01353"
"106.03800","8.83671","0.01371"
"106.29600","8.85824","0.01405"
"106.55400","8.87964","0.01323"
"106.81200","8.90123","0.01447"
"107.07000","8.92269","0.01405"
"107.32800","8.94421","0.01416"
"107.58600","8.96568","0.01423"
"107.84400","8.98720","0.01423"
"108.10200","9.00873","0.01420"
"108.36000","9.03019","0.01438"
"108.61800","9.05166","0.01511"
"108.87600","9.07324","0.01489"
"109.13400","9.09471","0.01458"
"109.39200","9.11623","0.01541"
"109.65000","9.13775","0.01509"
"109.90800","9.15928","0.01552"
"110.16600","9.18068","0.01537"
"110.42400","9.20221","0.01586"
"110.68200","9.22373","0.01592"
"110.94000","9.24520","0.01540"
"111.19800","9.26672","0.01566"
"111.45600","9.28818","0.01615"
"111.71400","9.30971","0.01627"
"111.97200","9.33117","0.01631"
"112.23000","9.35270","0.01684"
"112.48800","9.37416","0.01688"
"112.74600","9.39575","0.01716"
"113.00400","9.41715","0.01677"
"113.26200","9.43873","0.01729"
"113.52000","9.46020","0.01706"
"113.77800","9.48178","0.01737"
"114.03600","9.50319","0.01765"
"114.29400","9.52471","0.01722"
"114.55200","9.54618","0.01752"
"114.81000","9.56776","0.01746"
"115.06800","9.58916","0.01771"
"115.32600","9.61069","0.01799"
"115.58400","9.63221","0.01794"
"115.84200","9.65374","0.01830"
"116.10000","9.67520","0.01849"
"116.35800","9.69673","0.01847"
"116.61600","9.71825","0.01802"
"116.87400","9.73966","0.01854"
"117.13200","9.76124","0.01918"
"117.39000","9.78270","0.01846"
"117.64800","9.80423","0.01889"
"117.90600","9.82563","0.01982"
"118.16400","9.84716","0.01949"
"118.42200","9.86868","0.01922"
"118.68000","9.89026","0.01858"
"118.93800","9.91167","0.01914"
"119.19600","9.93319","0.01958"
"119.45400","9.95466","0.01918"
"119.71200","9.97624","0.01918"
"119.97000","9.99765","0.01942"
"120.22800","10.01923","0.01946"
"120.48600","10.04064","0.01945"
"120.74400","10.06222","0.01927"
"121.00200","10.08368","0.01932"
"121.26000","10.10527","0.01954"
"121.51800","10.12667","0.01984"
"121.77600","10.14820","0.01960"
"122.03400","10.16972","0.02008"
"122.29200","10.19125","0.01999"
"122.55000","10.21271","0.02028"
"122.80800","10.23417","0.02010"
"123.06600","10.25570","0.02064"
"123.32400","10.27722","0.02042"
"123.58200","10.29875","0.02036"
"123.84000","10.32021","0.02004"
"124.09800","10.34174","0.02039"
"124.35600","10.36320","0.02065"
"124.61400","10.38472","0.02053"
"124.87200","10.40619","0.02033"
"125.13000","10.42777","0.02049"
"125.38800","10.44918","0.02069"
"125.64600","10.47070","0.02057"
"125.90400","10.49217","0.02106"
"126.16200","10.51375","0.02101"
"126.42000","10.53522","0.02074"
"126.67800","10.55674","0.02014"
"126.93600","10.57814","0.02098"
"127.19400","10.59973","0.02033"
"127.45200","10.62119","0.02068"
"127.71000","10.64272","0.02018"
"127.96800","10.66418","0.02052"
"128.22600","10.68571","0.02052"
"128.48400","10.70717","0.02055"
"128.74200","10.72869","0.02040"
"129.00000","10.75028","0.02061"
"129.25800","10.77168","0.02088"
"129.51600","10.79321","0.02142"
"129.77400","10.81473","0.02135"
"130.03200","10.83626","0.02136"
"130.29000","10.85772","0.02146"
"130.54800","10.87924","0.02155"
"130.80600","10.90065","0.02140"
"131.06400","10.92223","0.02183"
"131.32200","10.94364","0.02194"
"131.58000","10.96528","0.02233"
"131.83800","10.98663","0.02230"
"132.09600","11.00821","0.02202"
"132.35400","11.02967","0.02263"
"132.61200","11.05126","0.02205"
"132.87000","11.07266","0.02150"
"133.12800","11.09419","0.02164"
"133.38600","11.11571","0.02182"
"133.64400","11.13724","0.02153"
"133.90200","11.15870","0.02183"
"134.16000","11.18022","0.02166"
"134.41800","11.20169","0.02210"
"134.67600","11.22321","0.02210"
"134.93400","11.24474","0.02244"
"135.19200","11.26620","0.02224"
"135.45000","11.28773","0.02276"
"135.70800","11.30925","0.02300"
"135.96600","11.33071","0.02327"
"136.22400","11.35218","0.02365"
"136.48200","11.37370","0.02346"
"136.74000","11.39523","0.02351"
"136.99800","11.41675","0.02330"
"137.25600","11.43816","0.02438"
"137.51400","11.45968","0.02370"
"137.77200","11.48115","0.02408"
"138.03000","11.50273","0.02417"
"138.28800","11.52419","0.02444"
"138.54600","11.54572","0.02521"
"138.80400","11.56718","0.02471"
"139.06200","11.58877","0.02538"
"139.32000","11.61017","0.02483"
"139.57800","11.63175","0.02579"
"139.83600","11.65322","0.02574"
"140.09400","11.67474","0.02541"
"140.35200","11.69627","0.02643"
"140.61000","11.71767","0.02572"
"140.86800","11.73920","0.02677"
"141.12600","11.76072","0.02682"
"141.38400","11.78225","0.02640"
"141.64200","11.80371","0.02695"
"141.90000","11.82523","0.02762"
"142.15800","11.84664","0.02780"
"142.41600","11.86822","0.02798"
"142.67400","11.88969","0.02764"
"142.93200","11.91127","0.02832"
"143.19000","11.93267","0.02869"
"143.44800","11.95420","0.02906"
"143.70600","11.97566","0.02833"
"143.96400","11.99719","0.02800"
"144.22200","12.01865","0.02854"
"144.48000","12.04018","0.02869"
"144.73800","12.06170","0.02873"
"144.99600","12.08323","0.02913"
"145.25400","12.10469","0.02933"
"145.51200","12.12627","0.02934"
"145.77000","12.14768","0.03016"
"146.02800","12.16920","0.03032"
"146.28600","12.19067","0.03034"
"146.54400","12.21225","0.03100"
"146.80200","12.23372","0.03132"
"147.06000","12.25524","0.03030"
"147.31800","12.27664","0.03130"
"147.57600","12.29823","0.03191"
"147.83400","12.31975","0.03171"
"148.09200","12.34122","0.03173"
"148.35000","12.36274","0.03182"
"148.60800","12.38421","0.03248"
"148.86600","12.40573","0.03261"
"149.12400","12.42719","0.03269"
"149.38200","12.44878","0.03378"
"149.64000","12.47018","0.03428"
"149.89800","12.49177","0.03446"
"150.15600","12.51311","0.03377"
"150.41400","12.53470","0.03464"
"150.67200","12.55616","0.03457"
"150.93000","12.57768","0.03492"
"151.18800","12.59915","0.03528"
"151.44600","12.62067","0.03506"
"151.70400","12.64220","0.03583"
"151.96200","12.66372","0.03565"
"152.22000","12.68519","0.03652"
"152.47800","12.70671","0.03584"
"152.73600","12.72824","0.03649"
"152.99400","12.74976","0.03716"
"153.25200","12.77122","0.03581"
"153.51000","12.79269","0.03630"
"153.76800","12.81415","0.03606"
"154.02600","12.83568","0.03612"
"154.28400","12.85720","0.03683"
"154.54200","12.87873","0.03563"
"154.80000","12.90025","0.03666"
"155.05800","12.92171","0.03649"
"155.31600","12.94318","0.03723"
"155.57400","12.96470","0.03738"
"155.83200","12.98623","0.03783"
"156.09000","13.00769","0.03851"
"156.34800","13.02928","0.03816"
"156.60600","13.05068","0.03892"
"156.86400","13.07226","0.03861"
"157.12200","13.09367","0.03928"
"157.38000","13.11525","0.03882"
"157.63800","13.13672","0.03906"
"157.89600","13.15824","0.03840"
"158.15400","13.17965","0.03889"
"158.41200","13.20123","0.03915"
"158.67000","13.22269","0.03936"
"158.92800","13.24422","0.03977"
"159.18600","13.26568","0.03960"
"159.44400","13.28727","0.03996"
"159.70200","13.30873","0.04009"
"159.96000","13.33020","0.04041"
"160.21800","13.35178","0.04045"
"160.47600","13.37324","0.04076"
"160.73400","13.39477","0.04060"
"160.99200","13.41623","0.04077"
"161.25000","13.43770","0.04127"
"161.50800","13.45922","0.04124"
"161.76600","13.48075","0.04153"
"162.02400","13.50221","0.04180"
"162.28200","13.52374","0.04150"
"162.54000","13.54514","0.04191"
"162.79800","13.56672","0.04158"
"163.05600","13.58819","0.04169"
"163.31400","13.60971","0.04190"
"163.57200","13.63118","0.04218"
"163.83000","13.65276","0.04186"
"164.08800","13.67417","0.04197"
"164.34600","13.69575","0.04244"
"164.60400","13.71721","0.04249"
"164.86200","13.73874","0.04271"
"165.12000","13.76020","0.04270"
"165.37800","13.78173","0.04298"
"165.63600","13.80319","0.04312"
"165.89400","13.82472","0.04311"
"166.15200","13.84624","0.04315"
"166.41000","13.86770","0.04355"
"166.66800","13.88917","0.04345"
"166.92600","13.91069","0.04377"
"167.18400","13.93228","0.04397"
"167.44200","13.95368","0.04454"
"167.70000","13.97520","0.04486"
"167.95800","13.99673","0.04504"
"168.21600","14.01825","0.04526"
"168.47400","14.03972","0.04582"
"168.73200","14.06124","0.04643"
"168.99000","14.08265","0.04650"
"169.24800","14.10423","0.04616"
"169.50600","14.12570","0.04701"
"169.76400","14.14722","0.04798"
"170.02200","14.16868","0.04939"
"170.28000","14.19021","0.05074"
"170.53800","14.21167","0.05165"
"170.79600","14.23326","0.05311"
"171.05400","14.25472","0.05464"
"171.31200","14.27619","0.05598"
"171.57000","14.29765","0.05671"
"171.82800","14.31923","0.05854"
"172.08600","14.34070","0.05987"
"172.34400","14.36222","0.06119"
"172.60200","14.38375","0.06246"
"172.86000","14.40521","0.06470"
"173.11800","14.42674","0.06592"
"173.37600","14.44820","0.06742"
"173.63400","14.46972","0.06900"
"173.89200","14.49119","0.07009"
"174.15000","14.51271","0.07109"
"174.40800","14.53412","0.07228"
"174.66600","14.55576","0.07385"
"174.92400","14.57723","0.07536"
"175.18200","14.59875","0.07652"
"175.44000","14.62016","0.07745"
"175.69800","14.64174","0.07884"
"175.95600","14.66314","0.07987"
"176.21400","14.68479","0.06628"
"176.47200","14.70619","0.05932"
"176.73000","14.72772","0.05183"
"176.98800","14.74918","0.05333"
"177.24600","14.77071","0.05200"
"177.50400","14.79223","0.05391"
"177.76200","14.81376","0.05588"
"178.02000","14.83522","0.05790"
"178.27800","14.85674","0.05976"
"178.53600","14.87821","0.06269"
"178.79400","14.89973","0.06259"
"179.05200","14.92120","0.06498"
"179.31000","14.94266","0.06575"
"179.56800","14.96418","0.06778"
"179.82600","14.98571","0.06942"
"180.08400","15.00723","0.07023"
"180.34200","15.02870","0.07164"
"180.60000","15.05022","0.07266"
"180.85800","15.07169","0.07427"
"181.11600","15.09321","0.07531"
"181.37400","15.11468","0.07738"
"181.63200","15.13620","0.07771"
"181.89000","15.15760","0.07940"
"182.14800","15.17919","0.08046"
"182.40600","15.20071","0.08201"
"182.66400","15.22229","0.08246"
"182.92200","15.24370","0.08348"
"183.18000","15.26529","0.08436"
"183.43800","15.28669","0.08532"
"183.69600","15.30827","0.08639"
"183.95400","15.32968","0.08707"
"184.21200","15.35120","0.08771"
"184.47000","15.37273","0.08824"
"184.72800","15.39419","0.08860"
"184.98600","15.41572","0.08904"
"185.24400","15.43718","0.08933"
"185.50200","15.45870","0.08990"
"185.76000","15.48023","0.09027"
"186.01800","15.50175","0.09082"
"186.27600","15.52322","0.09108"
"186.53400","15.54474","0.09138"
"186.79200","15.56614","0.09183"
"187.05000","15.58773","0.09242"
"187.30800","15.60919","0.09301"
"187.56600","15.63078","0.09394"
"187.82400","15.65218","0.09499"
"188.08200","15.67371","0.09601"
"188.34000","15.69517","0.09626"
"188.59800","15.71675","0.09641"
"188.85600","15.73822","0.09725"
"189.11400","15.75974","0.09511"
"189.37200","15.78115","0.02850"
"189.63000","15.80273","0.02101"
"189.88800","15.82420","0.02314"
"190.14600","15.84578","0.02756"
"190.40400","15.86718","0.02340"
"190.66200","15.88871","0.02989"
"190.92000","15.91023","0.02451"
"191.17800","15.93176","0.02985"
"191.43600","15.95328","0.02659"
"191.69400","15.97475","0.03161"
"191.95200","15.99621","0.02825"
"192.21000","16.01768","0.03170"
"192.46800","16.03920","0.03008"
"192.72600","16.06072","0.03346"
"192.98400","16.08225","0.03465"
"193.24200","16.10365","0.03353"
"193.50000","16.12524","0.03687"
"193.75800","16.14670","0.03655"
"194.01600","16.16823","0.03787"
"194.27400","16.18969","0.03739"
"194.53200","16.21115","0.03514"
"194.79000","16.23262","0.03626"
"195.04800","16.25426","0.03687"
"195.30600","16.27567","0.03822"
"195.56400","16.29725","0.03793"
"195.82200","16.31872","0.03902"
"196.08000","16.34030","0.03918"
"196.33800","16.36170","0.03953"
"196.59600","16.38323","0.04085"
"196.85400","16.40469","0.04086"
"197.11200","16.42616","0.04190"
"197.37000","16.44768","0.04175"
"197.62800","16.46921","0.04253"
"197.88600","16.49073","0.04228"
"198.14400","16.51220","0.04310"
"198.40200","16.53372","0.04340"
"198.66000","16.55518","0.04398"
"198.91800","16.57677","0.04383"
"199.17600","16.59823","0.04435"
"199.43400","16.61976","0.04466"
"199.69200","16.64116","0.04566"
"199.95000","16.66274","0.04608"
"200.20800","16.68415","0.04758"
"200.46600","16.70579","0.04733"
"200.72400","16.72720","0.04948"
"200.98200","16.74872","0.05051"
"201.24000","16.77019","0.05371"
"201.49800","16.79171","0.05478"
"201.75600","16.81318","0.05622"
"202.01400","16.83476","0.05743"
"202.27200","16.85622","0.05825"
"202.53000","16.87775","0.06077"
"202.78800","16.89921","0.06233"
"203.04600","16.92074","0.06402"
"203.30400","16.94220","0.06570"
"203.56200","16.96373","0.06674"
"203.82000","16.98525","0.06878"
"204.07800","17.00671","0.06990"
"204.33600","17.02824","0.07089"
"204.59400","17.04964","0.07304"
"204.85200","17.07123","0.07333"
"205.11000","17.09269","0.07457"
"205.36800","17.11415","0.07514"
"205.62600","17.13568","0.07624"
"205.88400","17.15720","0.07752"
"206.14200","17.17867","0.07924"
"206.40000","17.20019","0.07993"
"206.65800","17.22172","0.08120"
"206.91600","17.24324","0.08287"
"207.17400","17.26464","0.08325"
"207.43200","17.28623","0.08407"
"207.69000","17.30770","0.08393"
"207.94800","17.32922","0.02415"
"208.20600","17.35068","0.02343"
"208.46400","17.37227","0.02172"
"208.72200","17.39373","0.02444"
"208.98000","17.41525","0.02210"
"209.23800","17.43666","0.02559"
"209.49600","17.45819","0.02402"
"209.75400","17.47971","0.02482"
"210.01200","17.50117","0.02506"
"210.27000","17.52270","0.02436"
"210.52800","17.54422","0.02617"
"210.78600","17.56575","0.02408"
"211.04400","17.58715","0.02664"
"211.30200","17.60874","0.02597"
"211.56000","17.63020","0.02646"
"211.81800","17.65172","0.02625"
"212.07600","17.67319","0.02731"
"212.33400","17.69471","0.02600"
"212.59200","17.71612","0.02760"
"212.85000","17.73776","0.02646"
"213.10800","17.75916","0.02830"
"213.36600","17.78075","0.02707"
"213.62400","17.80221","0.02784"
"213.88200","17.82374","0.02759"
"214.14000","17.84520","0.02827"
"214.39800","17.86673","0.02819"
"214.65600","17.88819","0.02708"
"214.91400","17.90972","0.02820"
"215.17200","17.93118","0.02694"
"215.43000","17.95276","0.02854"
"215.68800","17.97423","0.02802"
"215.94600","17.99575","0.02855"
"216.20400","18.01716","0.02795"
"216.46200","18.03874","0.02855"
"216.72000","18.06021","0.02895"
"216.97800","18.08167","0.02879"
"217.23600","18.10325","0.02956"
"217.49400","18.12466","0.02875"
"217.75200","18.14618","0.02974"
"218.01000","18.16771","0.02912"
"218.26800","18.18929","0.02959"
"218.52600","18.21070","0.02967"
"218.78400","18.23222","0.03005"
"219.04200","18.25362","0.02907"
"219.30000","18.27527","0.02879"
"219.55800","18.29673","0.02859"
"219.81600","18.31826","0.02850"
"220.07400","18.33966","0.02920"
"220.33200","18.36119","0.02939"
"220.59000","18.38265","0.02941"
"220.84800","18.40417","0.02971"
"221.10600","18.42570","0.02997"
"221.36400","18.44722","0.02929"
"221.62200","18.46869","0.02901"
"221.88000","18.49021","0.02959"
"222.13800","18.51174","0.02991"
"222.39600","18.53320","0.02900"
"222.65400","18.55466","0.02968"
"222.91200","18.57619","0.02932"
"223.17000","18.59772","0.02968"
"223.42800","18.61924","0.02999"
"223.68600","18.64076","0.02971"
"223.94400","18.66217","0.02983"
"224.20200","18.68375","0.02999"
"224.46000","18.70522","0.02662"
"224.71800","18.72674","0.02763"
"224.97600","18.74814","0.02770"
"225.23400","18.76973","0.02784"
"225.49200","18.79113","0.02764"
"225.75000","18.81272","0.02782"
"226.00800","18.83418","0.02801"
"226.26600","18.85577","0.02877"
"226.52400","18.87717","0.02858"
"226.78200","18.89875","0.02869"
"227.04000","18.92016","0.02898"
"227.29800","18.94174","0.02860"
"227.55600","18.96321","0.02888"
"227.81400","18.98473","0.02806"
"228.07200","19.00620","0.02856"
"228.33000","19.02772","0.02880"
"228.58800","19.04924","0.02890"
"228.84600","19.07071","0.02936"
"229.10400","19.09217","0.02941"
"229.36200","19.11370","0.02882"
"229.62000","19.13522","0.02905"
"229.87800","19.15669","0.02947"
"230.13600","19.17821","0.02893"
"230.39400","19.19967","0.02941"
"230.65200","19.22120","0.03005"
"230.91000","19.24272","0.02969"
"231.16800","19.26425","0.02997"
"231.42600","19.28565","0.02990"
"231.68400","19.30724","0.02992"
"231.94200","19.32870","0.03038"
"232.20000","19.35023","0.03093"
"232.45800","19.37169","0.03086"
"232.71600","19.39321","0.02904"
"232.97400","19.41462","0.02932"
"233.23200","19.43620","0.02962"
"233.49000","19.45767","0.02977"
"233.74800","19.47925","0.02987"
"234.00600","19.50072","0.03023"
"234.26400","19.52224","0.02991"
"234.52200","19.54370","0.03056"
"234.78000","19.56529","0.03034"
"235.03800","19.58675","0.03060"
"235.29600","19.60816","0.03089"
"235.55400","19.62968","0.03003"
"235.81200","19.65114","0.03103"
"236.07000","19.67273","0.03197"
"236.32800","19.69419","0.03089"
"236.58600","19.71572","0.03098"
"236.84400","19.73712","0.03001"
"237.10200","19.75876","0.03106"
"237.36000","19.78017","0.03018"
"237.61800","19.80175","0.03145"
"237.87600","19.82310","0.03089"
"238.13400","19.84474","0.03182"
"238.39200","19.86621","0.03141"
"238.65000","19.88779","0.03207"
"238.90800","19.90920","0.03155"
"239.16600","19.93072","0.03269"
"239.42400","19.95218","0.03306"
"239.68200","19.97377","0.03248"
"239.94000","19.99517","0.03277"
"240.19800","20.01670","0.03215"
"240.45600","20.03816","0.03281"
"240.71400","20.05975","0.03319"
"240.97200","20.08121","0.03254"
"241.23000","20.10274","0.03367"
"241.48800","20.12420","0.03308"
"241.74600","20.14573","0.03380"
"242.00400","20.16719","0.03408"
"242.26200","20.18871","0.03442"
"242.52000","20.21024","0.03403"
"242.77800","20.23170","0.03467"
"243.03600","20.25323","0.03399"
"243.29400","20.27463","0.03384"
"243.55200","20.29621","0.03379"
"243.81000","20.31774","0.03336"
"244.06800","20.33926","0.03362"
"244.32600","20.36061","0.03423"
"244.58400","20.38219","0.03414"
"244.84200","20.40366","0.03306"
"245.10000","20.42524","0.03325"
"245.35800","20.44670","0.03332"
"245.61600","20.46823","0.03399"
"245.87400","20.48969","0.03356"
"246.13200","20.51122","0.03382"
"246.39000","20.53268","0.03333"
"246.64800","20.55421","0.03367"
"246.90600","20.57573","0.03216"
"247.16400","20.59725","0.03162"
"247.42200","20.61872","0.03224"
"247.68000","20.64024","0.03225"
"247.93800","20.66171","0.03309"
"248.19600","20.68317","0.03255"
"248.45400","20.70464","0.03307"
"248.71200","20.72616","0.03287"
"248.97000","20.74769","0.03353"
"249.22800","20.76915","0.03408"
"249.48600","20.79073","0.03412"
"249.74400","20.81220","0.03439"
"250.00200","20.83378","0.03385"
"250.26000","20.85518","0.03437"
"250.51800","20.87671","0.03389"
"250.77600","20.89812","0.03362"
"251.03400","20.91970","0.03437"
"251.29200","20.94116","0.03478"
"251.55000","20.96281","0.03476"
"251.80800","20.98421","0.03513"
"252.06600","21.00574","0.03501"
"252.32400","21.02720","0.03633"
"252.58200","21.04873","0.03573"
"252.84000","21.07019","0.03623"
"253.09800","21.09171","0.03647"
"253.35600","21.11318","0.03640"
"253.61400","21.13476","0.03640"
"253.87200","21.15623","0.03656"
"254.13000","21.17775","0.03737"
"254.38800","21.19921","0.03718"
"254.64600","21.22068","0.03778"
"254.90400","21.24220","0.03767"
"255.16200","21.26373","0.03722"
"255.42000","21.28526","0.03803"
"255.67800","21.30666","0.03727"
"255.93600","21.32818","0.03737"
"256.19400","21.34965","0.03798"
"256.45200","21.37123","0.03851"
"256.71000","21.39270","0.03847"
"256.96800","21.41422","0.03862"
"257.22600","21.43568","0.03862"
"257.48400","21.45721","0.03846"
"257.74200","21.47867","0.03908"
"258.00000","21.50025","0.03919"
"258.25800","21.52166","0.03923"
"258.51600","21.54324","0.03966"
"258.77400","21.56471","0.03972"
"259.03200","21.58629","0.03967"
"259.29000","21.60770","0.03995"
"259.54800","21.62922","0.04038"
"259.80600","21.65069","0.04004"
"260.06400","21.67221","0.04057"
"260.32200","21.69374","0.04053"
"260.58000","21.71526","0.04108"
"260.83800","21.73672","0.04110"
"261.09600","21.75819","0.04122"
"261.35400","21.77977","0.04115"
"261.61200","21.80118","0.04167"
"261.87000","21.82276","0.04061"
"262.12800","21.84416","0.04121"
"262.38600","21.86575","0.04100"
"262.64400","21.88715","0.04148"
"262.90200","21.90874","0.04169"
"263.16000","21.93020","0.04215"
"263.41800","21.95167","0.04243"
"263.67600","21.97313","0.04240"
"263.93400","21.99471","0.04260"
"264.19200","22.01618","0.04284"
"264.45000","22.03777","0.04249"
"264.70800","22.05923","0.04314"
"264.96600","22.08075","0.04283"
"265.22400","22.10222","0.04285"
"265.48200","22.12380","0.04273"
"265.74000","22.14520","0.04276"
"265.99800","22.16673","0.04274"
"266.25600","22.18819","0.04310"
"266.51400","22.20972","0.04285"
"266.77200","22.23124","0.04318"
"267.03000","22.25277","0.04324"
"267.28800","22.27417","0.04042"
"267.54600","22.29570","0.04061"
"267.80400","22.31716","0.04113"
"268.06200","22.33868","0.04105"
"268.32000","22.36027","0.03412"
"268.57800","22.38167","0.02971"
"268.83600","22.40320","0.03317"
"269.09400","22.42460","0.03042"
"269.35200","22.44631","0.03397"
"269.61000","22.46765","0.03207"
"269.86800","22.48923","0.03383"
"270.12600","22.51070","0.03330"
"270.38400","22.53222","0.03418"
"270.64200","22.55375","0.03461"
"270.90000","22.57527","0.03488"
"271.15800","22.59668","0.03490"
"271.41600","22.61820","0.03525"
"271.67400","22.63972","0.03627"
"271.93200","22.66125","0.03628"
"272.19000","22.68271","0.03594"
"272.44800","22.70424","0.03673"
"272.70600","22.72570","0.03621"
"272.96400","22.74717","0.03698"
"273.22200","22.76875","0.03672"
"273.48000","22.79015","0.03771"
"273.73800","22.81168","0.03788"
"273.99600","22.83321","0.03818"
"274.25400","22.85473","0.03858"
"274.51200","22.87619","0.03864"
"274.77000","22.89772","0.03857"
"275.02800","22.91918","0.03894"
"275.28600","22.94071","0.03917"
"275.54400","22.96217","0.03950"
"275.80200","22.98375","0.03956"
"276.06000","23.00516","0.03985"
"276.31800","23.02668","0.03987"
"276.57600","23.04815","0.03996"
"276.83400","23.06973","0.04018"
"277.09200","23.09120","0.04056"
"277.35000","23.11278","0.04115"
"277.60800","23.13424","0.04097"
"277.86600","23.15577","0.04121"
"278.12400","23.17723","0.04126"
"278.38200","23.19876","0.04162"
"278.64000","23.22016","0.04136"
"278.89800","23.24169","0.04150"
"279.15600","23.26321","0.04173"
"279.41400","23.28473","0.04188"
"279.67200","23.30626","0.04206"
"279.93000","23.32766","0.04215"
"280.18800","23.34919","0.04237"
"280.44600","23.37065","0.04219"
"280.70400","23.39224","0.04276"
"280.96200","23.41370","0.04275"
"281.22000","23.43523","0.04291"
"281.47800","23.45669","0.04294"
"281.73600","23.47821","0.04286"
"281.99400","23.49968","0.04327"
"282.25200","23.52126","0.04402"
"282.51000","23.54267","0.04336"
"282.76800","23.56419","0.04384"
"283.02600","23.58566","0.04442"
"283.28400","23.60724","0.04423"
"283.54200","23.62870","0.04448"
"283.80000","23.65023","0.04453"
"284.05800","23.67169","0.04422"
"284.31600","23.69328","0.04501"
"284.57400","23.71474","0.04470"
"284.83200","23.73627","0.04463"
"285.09000","23.75773","0.04238"
"285.34800","23.77925","0.04410"
"285.60600","23.80072","0.04248"
"285.86400","23.82224","0.04320"
"286.12200","23.84377","0.03856"
"286.38000","23.86517","0.04149"
"286.63800","23.88676","0.03515"
"286.89600","23.90822","0.03964"
"287.15400","23.92974","0.03841"
"287.41200","23.95121","0.03904"
"287.67000","23.97273","0.04021"
"287.92800","23.99414","0.03941"
"288.18600","24.01572","0.04161"
"288.44400","24.03718","0.04040"
"288.70200","24.05871","0.04206"
"288.96000","24.08017","0.04073"
"289.21800","24.10170","0.04190"
"289.47600","24.12316","0.04113"
"289.73400","24.14475","0.03797"
"289.99200","24.16627","0.03639"
"290.25000","24.18773","0.03565"
"290.50800","24.20926","0.03647"
"290.76600","24.23072","0.03687"
"291.02400","24.25225","0.03800"
"291.28200","24.27371","0.03826"
"291.54000","24.29518","0.03765"
"291.79800","24.31670","0.03857"
"292.05600","24.33817","0.03895"
"292.31400","24.35975","0.03891"
"292.57200","24.38121","0.03979"
"292.83000","24.40274","0.03965"
"293.08800","24.42426","0.04040"
"293.34600","24.44573","0.04064"
"293.60400","24.46725","0.04082"
"293.86200","24.48866","0.04074"
"294.12000","24.51024","0.04112"
"294.37800","24.53164","0.04129"
"294.63600","24.55323","0.04137"
"294.89400","24.57470","0.04153"
"295.15200","24.59622","0.04162"
"295.41000","24.61768","0.04191"
"295.66800","24.63921","0.04198"
"295.92600","24.66067","0.04206"
"296.18400","24.68225","0.04263"
"296.44200","24.70372","0.04286"
"296.70000","24.72524","0.04277"
"296.95800","24.74671","0.04296"
"297.21600","24.76823","0.04297"
"297.47400","24.78970","0.04350"
"297.73200","24.81122","0.04333"
"297.99000","24.83269","0.04365"
"298.24800","24.85421","0.04407"
"298.50600","24.87574","0.04454"
"298.76400","24.89720","0.04438"
"299.02200","24.91872","0.04435"
"299.28000","24.94013","0.04487"
"299.53800","24.96171","0.04538"
"299.79600","24.98323","0.04584"
"300.05400","25.00476","0.04583"
"300.31200","25.02617","0.04670"
"300.57000","25.04775","0.04661"
"300.82800","25.06915","0.04708"
"301.08600","25.09068","0.04725"
"301.34400","25.11220","0.04763"
"301.60200","25.13373","0.04769"
"301.86000","25.15513","0.04839"
"302.11800","25.17671","0.04836"
"302.37600","25.19818","0.04852"
"302.63400","25.21976","0.04908"
"302.89200","25.24123","0.04954"
"303.15000","25.26269","0.04997"
"303.40800","25.28416","0.04878"
"303.66600","25.30574","0.04176"
"303.92400","25.32726","0.04366"
"304.18200","25.34873","0.04287"
"304.44000","25.37020","0.04448"
"304.69800","25.39166","0.04535"
"304.95600","25.41324","0.04506"
"305.21400","25.43477","0.04721"
"305.47200","25.45623","0.04612"
"305.73000","25.47763","0.04989"
"305.98800","25.49922","0.04791"
"306.24600","25.52068","0.05090"
"306.50400","25.54221","0.04843"
"306.76200","25.56367","0.05166"
"307.02000","25.58520","0.05193"
"307.27800","25.60666","0.05364"
"307.53600","25.62825","0.05384"
"307.79400","25.64971","0.05498"
"308.05200","25.67123","0.05634"
"308.31000","25.69270","0.05643"
"308.56800","25.71422","0.05691"
"308.82600","25.73569","0.05179"
"309.08400","25.75727","0.05297"
"309.34200","25.77868","0.05350"
"309.60000","25.80026","0.05469"
"309.85800","25.82172","0.05488"
"310.11600","25.84325","0.05578"
"310.37400","25.86471","0.05791"
"310.63200","25.88624","0.05776"
"310.89000","25.90770","0.06084"
"311.14800","25.92923","0.05933"
"311.40600","25.95075","0.06276"
"311.66400","25.97221","0.06087"
"311.92200","25.99374","0.06244"
"312.18000","26.01514","0.06303"
"312.43800","26.03673","0.06483"
"312.69600","26.05819","0.06521"
"312.95400","26.07978","0.06533"
"313.21200","26.10112","0.06715"
"313.47000","26.12276","0.06679"
"313.72800","26.14417","0.06723"
"313.98600","26.16575","0.06210"
"314.24400","26.18722","0.05989"
"314.50200","26.20874","0.06322"
"314.76000","26.23014","0.06116"
"315.01800","26.25173","0.01346"
"315.27600","26.27320","0.03884"
"315.53400","26.29478","0.01920"
"315.79200","26.31618","0.03127"
"316.05000","26.33771","0.02293"
"316.30800","26.35917","0.02730"
"316.56600","26.38070","0.02792"
"316.82400","26.40222","0.02348"
"317.08200","26.42369","0.03134"
"317.34000","26.44521","0.02350"
"317.59800","26.46667","0.03252"
"317.85600","26.48820","0.02376"
"318.11400","26.50972","0.03318"
"318.37200","26.53119","0.02643"
"318.63000","26.55265","0.03171"
"318.88800","26.57424","0.02705"
"319.14600","26.59570","0.03272"
"319.40400","26.61723","0.02798"
"319.66200","26.63863","0.03263"
"319.92000","26.66021","0.03093"
"320.17800","26.68168","0.03266"
"320.43600","26.70326","0.03252"
"320.69400","26.72473","0.03477"
"320.95200","26.74625","0.03345"
"321.21000","26.76772","0.03438"
"321.46800","26.78924","0.03504"
"321.72600","26.81070","0.03464"
"321.98400","26.83223","0.03580"
"322.24200","26.85369","0.03608"
"322.50000","26.87522","0.03634"
"322.75800","26.89674","0.03597"
"323.01600","26.91821","0.03720"
"323.27400","26.93973","0.03705"
"323.53200","26.96119","0.03829"
"323.79000","26.98272","0.03862"
"324.04800","27.00418","0.03843"
"324.30600","27.02577","0.03921"
"324.56400","27.04717","0.03937"
"324.82200","27.06870","0.03956"
"325.08000","27.09022","0.04041"
"325.33800","27.11174","0.03996"
"325.59600","27.13321","0.04037"
"325.85400","27.15467","0.04075"
"326.11200","27.17614","0.04077"
"326.37000","27.19772","0.04147"
"326.62800","27.21918","0.04133"
"326.88600","27.24071","0.04151"
"327.14400","27.26217","0.04207"
"327.40200","27.28370","0.04177"
"327.66000","27.30516","0.04226"
"327.91800","27.32675","0.04264"
"328.17600","27.34821","0.04266"
"328.43400","27.36974","0.04292"
"328.69200","27.39120","0.04264"
"328.95000","27.41273","0.04316"
"329.20800","27.43419","0.04372"
"329.46600","27.45571","0.04385"
"329.72400","27.47724","0.04379"
"329.98200","27.49864","0.04417"
"330.24000","27.52023","0.04458"
"330.49800","27.54169","0.04496"
"330.75600","27.56327","0.04545"
"331.01400","27.58468","0.04525"
"331.27200","27.60620","0.04560"
"331.53000","27.62767","0.04616"
"331.78800","27.64925","0.04659"
"332.04600","27.67072","0.04752"
"332.30400","27.69218","0.04744"
"332.56200","27.71365","0.04799"
"332.82000","27.73523","0.04912"
"333.07800","27.75675","0.04939"
"333.33600","27.77828","0.05066"
"333.59400","27.79974","0.05055"
"333.85200","27.82121","0.05102"
"334.11000","27.84267","0.05176"
"334.36800","27.86426","0.05251"
"334.62600","27.88572","0.05315"
"334.88400","27.90718","0.05430"
"335.14200","27.92871","0.05477"
"335.40000","27.95017","0.05607"
"335.65800","27.97170","0.05735"
"335.91600","27.99322","0.05898"
"336.17400","28.01469","0.05840"
"336.43200","28.03621","0.06034"
"336.69000","28.05767","0.06125"
"336.94800","28.07920","0.06211"
"337.20600","28.10072","0.06279"
"337.46400","28.12219","0.06324"
"337.72200","28.14371","0.06378"
"337.98000","28.16518","0.06518"
"338.23800","28.18676","0.06582"
"338.49600","28.20816","0.06673"
"338.75400","28.22975","0.06710"
"339.01200","28.25115","0.06813"
"339.27000","28.27268","0.06850"
"339.52800","28.29420","0.06974"
"339.78600","28.31578","0.07024"
"340.04400","28.33719","0.07090"
"340.30200","28.35872","0.07082"
"340.56000","28.38018","0.07166"
"340.81800","28.40170","0.07268"
"341.07600","28.42317","0.07314"
"341.33400","28.44469","0.07422"
"341.59200","28.46622","0.07523"
"341.85000","28.48774","0.07600"
"342.10800","28.50914","0.07672"
"342.36600","28.53073","0.07678"
"342.62400","28.55225","0.07795"
"342.88200","28.57372","0.07816"
"343.14000","28.59518","0.07884"
"343.39800","28.61671","0.07992"
"343.65600","28.63823","0.08024"
"343.91400","28.65969","0.08076"
"344.17200","28.68122","0.08166"
"344.43000","28.70268","0.08270"
"344.68800","28.72421","0.08320"
"344.94600","28.74567","0.08375"
"345.20400","28.76719","0.08408"
"345.46200","28.78866","0.08442"
"345.72000","28.81024","0.08542"
"345.97800","28.83171","0.08607"
"346.23600","28.85323","0.08604"
"346.49400","28.87470","0.08656"
"346.75200","28.89628","0.08717"
"347.01000","28.91769","0.07884"
"347.26800","28.93921","0.08434"
"347.52600","28.96068","0.08289"
"347.78400","28.98220","0.08603"
"348.04200","29.00372","0.08495"
"348.30000","29.02525","0.08698"
"348.55800","29.04671","0.08623"
"348.81600","29.06818","0.08769"
"349.07400","29.08970","0.08756"
"349.33200","29.11117","0.08878"
"349.59000","29.13275","0.08796"
"349.84800","29.15416","0.08907"
"350.10600","29.17574","0.08908"
"350.36400","29.19714","0.08981"
"350.62200","29.21873","0.08948"
"350.88000","29.24019","0.09014"
"351.13800","29.26178","0.08989"
"351.39600","29.28318","0.09055"
"351.65400","29.30464","0.09044"
"351.91200","29.32617","0.09140"
"352.17000","29.34775","0.09102"
"352.42800","29.36922","0.09168"
"352.68600","29.39074","0.09141"
"352.94400","29.41215","0.09253"
"353.20200","29.43373","0.09207"
"353.46000","29.45520","0.09321"
"353.71800","29.47678","0.09302"
"353.97600","29.49818","0.09444"
"354.23400","29.51971","0.09414"
"354.49200","29.54123","0.09509"
"354.75000","29.56276","0.09546"
"355.00800","29.58428","0.09711"
"355.26600","29.60568","0.09729"
"355.52400","29.62721","0.09865"
"355.78200","29.64867","0.09966"
"356.04000","29.67026","0.10011"
"356.29800","29.69172","0.10253"
"356.55600","29.71325","0.10246"
"356.81400","29.73465","0.10465"
"357.07200","29.75624","0.10557"
"357.33000","29.77764","0.10777"
"357.58800","29.79922","0.10789"
"357.84600","29.82069","0.10994"
"358.10400","29.84221","0.11188"
"358.36200","29.86368","0.11332"
"358.62000","29.88526","0.11425"
"358.87800","29.90672","0.11626"
"359.13600","29.92819","0.11722"
"359.39400","29.94971","0.11821"
"359.65200","29.97118","0.11974"
"359.91000","29.99270","0.12056"
"360.16800","30.01423","0.12305"
"360.42600","30.03569","0.12397"
"360.68400","30.05722","0.12557"
"360.94200","30.07868","0.12743"
"361.20000","30.10021","0.12853"
"361.45800","30.12173","0.13179"
"361.71600","30.14319","0.13264"
"361.97400","30.16472","0.13478"
"362.23200","30.18618","0.13576"
"362.49000","30.20771","0.13831"
"362.74800","30.22917","0.13879"
"363.00600","30.25075","0.14141"
"363.26400","30.27216","0.14140"
"363.52200","30.29374","0.14411"
"363.78000","30.31515","0.14478"
"364.03800","30.33679","0.14612"
"364.29600","30.35820","0.14688"
"364.55400","30.37972","0.14792"
"364.81200","30.40118","0.14858"
"365.07000","30.42271","0.14889"
"365.32800","30.44417","0.14975"
"365.58600","30.46570","0.14975"
"365.84400","30.48716","0.15006"
"366.10200","30.50875","0.15065"
"366.36000","30.53021","0.15085"
"366.61800","30.55167","0.15138"
"366.87600","30.57320","0.15188"
"367.13400","30.59472","0.15202"
"367.39200","30.61619","0.15289"
"367.65000","30.63771","0.15318"
"367.90800","30.65924","0.15396"
"368.16600","30.68070","0.15462"
"368.42400","30.70222","0.15563"
"368.68200","30.72369","0.15597"
"368.94000","30.74521","0.15789"
"369.19800","30.76668","0.15857"
"369.45600","30.78820","0.16033"
"369.71400","30.80967","0.16122"
"369.97200","30.83119","0.16294"
"370.23000","30.85266","0.16367"
"370.48800","30.87418","0.16534"
"370.74600","30.89564","0.16623"
"371.00400","30.91723","0.16796"
"371.26200","30.93869","0.16920"
"371.52000","30.96028","0.17079"
"371.77800","30.98168","0.17174"
"372.03600","31.00321","0.17274"
"372.29400","31.02467","0.17410"
"372.55200","31.04625","0.17444"
"372.81000","31.06772","0.17594"
"373.06800","31.08919","0.17730"
"373.32600","31.11071","0.17826"
"373.58400","31.13217","0.17953"
"373.84200","31.15376","0.18028"
"374.10000","31.17522","0.18163"
"374.35800","31.19668","0.18227"
"374.61600","31.21821","0.18299"
"374.87400","31.23979","0.18426"
"375.13200","31.26119","0.18535"
"375.39000","31.28278","0.18634"
"375.64800","31.30412","0.18654"
"375.90600","31.32571","0.18765"
"376.16400","31.34717","0.18832"
"376.42200","31.36870","0.18894"
"376.68000","31.39022","0.18974"
"376.93800","31.41175","0.19002"
"377.19600","31.43315","0.19120"
"377.45400","31.45473","0.19210"
"377.71200","31.47620","0.19278"
"377.97000","31.49778","0.19334"
"378.22800","31.51919","0.19387"
"378.48600","31.54071","0.19478"
"378.74400","31.56218","0.19516"
"379.00200","31.58376","0.19558"
"379.26000","31.60522","0.19628"
"379.51800","31.62675","0.19673"
"379.77600","31.64816","0.19748"
"380.03400","31.66968","0.19816"
"380.29200","31.69126","0.19773"
"380.55000","31.71273","0.02384"
"380.80800","31.73419","0.01200"
"381.06600","31.75566","0.01012"
"381.32400","31.77724","0.01244"
"381.58200","31.79871","0.01274"
"381.84000","31.82023","0.01006"
"382.09800","31.84163","0.01116"
"382.35600","31.86328","0.01177"
"382.61400","31.88468","0.01007"
"382.78200","31.89867","0.01068"