File: Force_trajectories/170108_1/Specimen_RawData_7.csv
End date,"1/8/2017"
Specimen label,"10DG_59"
Maximum Load,"0.72436",N

Time,Extension,Load
(s),(mm),(N)
"0.00000","0.00000","-0.00017"
"0.28200","0.02278","0.00017"
"0.56400","0.04717","-0.00056"
"0.84600","0.07067","0.00049"
"1.12800","0.09411","-0.00021"
"1.41000","0.11767","0.00006"
"1.69200","0.14110","-0.00039"
"1.97400","0.16466","0.00001"
"2.25600","0.18810","-0.00014"
"2.53800","0.21165","0.00018"
"2.82000","0.23515","0.00030"
"3.10200","0.25865","0.00024"
"3.38400","0.28215","0.00013"
"3.66600","0.30570","0.00033"
"3.94800","0.32920","0.00056"
"4.23000","0.35270","0.00024"
"4.51200","0.37620","0.00012"
"4.79400","0.39963","0.00046"
"5.07600","0.42319","0.00044"
"5.35800","0.44663","0.00090"
"5.64000","0.47018","0.00035"
"5.92200","0.49362","0.00037"
"6.20400","0.51724","0.00045"
"6.48600","0.54062","0.00054"
"6.76800","0.56423","0.00057"
"7.05000","0.58767","0.00024"
"7.33200","0.61123","0.00025"
"7.61400","0.63461","0.00089"
"7.89600","0.65822","0.00024"
"8.17800","0.68160","0.00050"
"8.46000","0.70522","0.00025"
"8.74200","0.72866","0.00071"
"9.02400","0.75215","0.00061"
"9.30600","0.77571","0.00030"
"9.58800","0.79915","0.00074"
"9.87000","0.82264","0.00053"
"10.15200","0.84614","0.00064"
"10.43400","0.86970","0.00054"
"10.71600","0.89314","0.00050"
"10.99800","0.91669","0.00075"
"11.28000","0.94013","0.00046"
"11.56200","0.96369","0.00079"
"11.84400","0.98713","0.00094"
"12.12600","1.01068","0.00082"
"12.40800","1.03418","0.00090"
"12.69000","1.05768","0.00071"
"12.97200","1.08111","0.00080"
"13.25400","1.10473","0.00070"
"13.53600","1.12817","0.00070"
"13.81800","1.15167","0.00060"
"14.10000","1.17522","0.00084"
"14.38200","1.19878","0.00069"
"14.66400","1.22222","0.00050"
"14.94600","1.24571","0.00109"
"15.22800","1.26921","0.00054"
"15.51000","1.29271","0.00090"
"15.79200","1.31615","0.00113"
"16.07400","1.33964","0.00109"
"16.35600","1.36314","0.00143"
"16.63800","1.38664","0.00127"
"16.92000","1.41020","0.00134"
"17.20200","1.43363","0.00099"
"17.48400","1.45713","0.00091"
"17.76600","1.48063","0.00120"
"18.04800","1.50413","0.00114"
"18.33000","1.52756","0.00134"
"18.61200","1.55118","0.00093"
"18.89400","1.57462","0.00065"
"19.17600","1.59817","0.00144"
"19.45800","1.62167","0.00108"
"19.74000","1.64523","0.00098"
"20.02200","1.66867","0.00094"
"20.30400","1.69216","0.00143"
"20.58600","1.71560","0.00102"
"20.86800","1.73916","0.00098"
"21.15000","1.76266","0.00112"
"21.43200","1.78615","0.00157"
"21.71400","1.80971","0.00101"
"21.99600","1.83321","0.00175"
"22.27800","1.85676","0.00107"
"22.56000","1.88014","0.00114"
"22.84200","1.90376","0.00145"
"23.12400","1.92714","0.00134"
"23.40600","1.95069","0.00182"
"23.68800","1.97413","0.00165"
"23.97000","1.99769","0.00122"
"24.25200","2.02113","0.00145"
"24.53400","2.04468","0.00148"
"24.81600","2.06812","0.00135"
"25.09800","2.09168","0.00180"
"25.38000","2.11511","0.00191"
"25.66200","2.13867","0.00163"
"25.94400","2.16211","0.00141"
"26.22600","2.18567","0.00154"
"26.50800","2.20916","0.00144"
"26.79000","2.23266","0.00159"
"27.07200","2.25616","0.00147"
"27.35400","2.27972","0.00178"
"27.63600","2.30321","0.00165"
"27.91800","2.32665","0.00150"
"28.20000","2.35021","0.00197"
"28.48200","2.37364","0.00154"
"28.76400","2.39720","0.00116"
"29.04600","2.42064","0.00179"
"29.32800","2.44420","0.00128"
"29.61000","2.46769","0.00159"
"29.89200","2.49119","0.00148"
"30.17400","2.51469","0.00167"
"30.45600","2.53825","0.00145"
"30.73800","2.56168","0.00198"
"31.02000","2.58518","0.00152"
"31.30200","2.60862","0.00170"
"31.58400","2.63223","0.00145"
"31.86600","2.65567","0.00144"
"32.14800","2.67917","0.00163"
"32.43000","2.70267","0.00215"
"32.71200","2.72616","0.00186"
"32.99400","2.74966","0.00160"
"33.27600","2.77316","0.00122"
"33.55800","2.79666","0.00196"
"33.84000","2.82015","0.00143"
"34.12200","2.84371","0.00200"
"34.40400","2.86715","0.00163"
"34.68600","2.89064","0.00148"
"34.96800","2.91414","0.00164"
"35.25000","2.93764","0.00143"
"35.53200","2.96108","0.00173"
"35.81400","2.98469","0.00192"
"36.09600","3.00807","0.00147"
"36.37800","3.03169","0.00202"
"36.66000","3.05513","0.00158"
"36.94200","3.07868","0.00207"
"37.22400","3.10218","0.00198"
"37.50600","3.12568","0.00062"
"37.78800","3.14917","0.00126"
"38.07000","3.17273","0.00046"
"38.35200","3.19623","0.00096"
"38.63400","3.21973","0.00121"
"38.91600","3.24322","0.00140"
"39.19800","3.26672","0.00101"
"39.48000","3.29022","0.00087"
"39.76200","3.31366","0.00094"
"40.04400","3.33721","0.00084"
"40.32600","3.36065","0.00125"
"40.60800","3.38421","0.00120"
"40.89000","3.40764","0.00153"
"41.17200","3.43120","0.00118"
"41.45400","3.45464","0.00163"
"41.73600","3.47814","0.00117"
"42.01800","3.50157","0.00114"
"42.30000","3.52519","0.00173"
"42.58200","3.54863","0.00134"
"42.86400","3.57219","0.00159"
"43.14600","3.59568","0.00170"
"43.42800","3.61918","0.00158"
"43.71000","3.64262","0.00175"
"43.99200","3.66617","0.00210"
"44.27400","3.68967","0.00133"
"44.55600","3.71323","0.00136"
"44.83800","3.73667","0.00144"
"45.12000","3.76016","0.00154"
"45.40200","3.78366","0.00176"
"45.68400","3.80716","0.00200"
"45.96600","3.83072","0.00162"
"46.24800","3.85415","0.00223"
"46.53000","3.87771","0.00130"
"46.81200","3.90121","0.00138"
"47.09400","3.92470","0.00124"
"47.37600","3.94814","0.00118"
"47.65800","3.97170","0.00114"
"47.94000","3.99514","0.00121"
"48.22200","4.01869","0.00118"
"48.50400","4.04213","0.00129"
"48.78600","4.06569","0.00132"
"49.06800","4.08913","0.00162"
"49.35000","4.11268","0.00110"
"49.63200","4.13618","0.00168"
"49.91400","4.15968","0.00143"
"50.19600","4.18312","0.00135"
"50.47800","4.20667","0.00211"
"50.76000","4.23017","0.00149"
"51.04200","4.25361","0.00192"
"51.32400","4.27716","0.00171"
"51.60600","4.30066","0.00180"
"51.88800","4.32422","0.00135"
"52.17000","4.34766","0.00164"
"52.45200","4.37115","0.00176"
"52.73400","4.39465","0.00174"
"53.01600","4.41821","0.00180"
"53.29800","4.44165","0.00171"
"53.58000","4.46520","0.00162"
"53.86200","4.48864","0.00162"
"54.14400","4.51226","0.00211"
"54.42600","4.53569","0.00168"
"54.70800","4.55919","0.00155"
"54.99000","4.58269","0.00171"
"55.27200","4.60619","0.00180"
"55.55400","4.62968","0.00136"
"55.83600","4.65318","0.00171"
"56.11800","4.67674","0.00183"
"56.40000","4.70023","0.00176"
"56.68200","4.72373","0.00163"
"56.96400","4.74717","0.00222"
"57.24600","4.77073","0.00202"
"57.52800","4.79416","0.00182"
"57.81000","4.81772","0.00225"
"58.09200","4.84116","0.00185"
"58.37400","4.86466","0.00163"
"58.65600","4.88815","0.00229"
"58.93800","4.91165","0.00193"
"59.22000","4.93515","0.00227"
"59.50200","4.95870","0.00189"
"59.78400","4.98208","0.00230"
"60.06600","5.00570","0.00171"
"60.34800","5.02914","0.00192"
"60.63000","5.05269","0.00188"
"60.91200","5.07613","0.00214"
"61.19400","5.09969","0.00213"
"61.47600","5.12313","0.00210"
"61.75800","5.14668","0.00182"
"62.04000","5.17018","0.00235"
"62.32200","5.19368","0.00222"
"62.60400","5.21723","0.00264"
"62.88600","5.24073","0.00179"
"63.16800","5.26423","0.00226"
"63.45000","5.28767","0.00215"
"63.73200","5.31122","0.00266"
"64.01400","5.33466","0.00241"
"64.29600","5.35822","0.00176"
"64.57800","5.38160","0.00233"
"64.86000","5.40515","0.00203"
"65.14200","5.42859","0.00225"
"65.42400","5.45221","0.00240"
"65.70600","5.47559","0.00212"
"65.98800","5.49920","0.00196"
"66.27000","5.52264","0.00204"
"66.55200","5.54614","0.00187"
"66.83400","5.56957","0.00208"
"67.11600","5.59313","0.00175"
"67.39800","5.61663","0.00151"
"67.68000","5.64019","0.00186"
"67.96200","5.66362","0.00183"
"68.24400","5.68718","0.00208"
"68.52600","5.71074","0.00188"
"68.80800","5.73417","0.00196"
"69.09000","5.75773","0.00213"
"69.37200","5.78117","0.00172"
"69.65400","5.80467","0.00137"
"69.93600","5.82816","0.00172"
"70.21800","5.85172","0.00170"
"70.50000","5.87516","0.00180"
"70.78200","5.89872","0.00165"
"71.06400","5.92215","0.00137"
"71.34600","5.94571","0.00229"
"71.62800","5.96915","0.00145"
"71.91000","5.99270","0.00203"
"72.19200","6.01614","0.00202"
"72.47400","6.03964","0.00215"
"72.75600","6.06314","0.00183"
"73.03800","6.08669","0.00166"
"73.32000","6.11019","0.00206"
"73.60200","6.13369","0.00250"
"73.88400","6.15719","0.00189"
"74.16600","6.18062","0.00184"
"74.44800","6.20418","0.00206"
"74.73000","6.22762","0.00254"
"75.01200","6.25117","0.00241"
"75.29400","6.27461","0.00226"
"75.57600","6.29823","0.00233"
"75.85800","6.32167","0.00254"
"76.14000","6.34522","0.00236"
"76.42200","6.36866","0.00266"
"76.70400","6.39222","0.00258"
"76.98600","6.41566","0.00232"
"77.26800","6.43921","0.00226"
"77.55000","6.46265","0.00220"
"77.83200","6.48621","0.00227"
"78.11400","6.50964","0.00268"
"78.39600","6.53320","0.00248"
"78.67800","6.55670","0.00231"
"78.96000","6.58020","0.00223"
"79.24200","6.60363","0.00270"
"79.52400","6.62719","0.00294"
"79.80600","6.65069","0.00246"
"80.08800","6.67419","0.00271"
"80.37000","6.69768","0.00256"
"80.65200","6.72112","0.00224"
"80.93400","6.74468","0.00283"
"81.21600","6.76812","0.00268"
"81.49800","6.79167","0.00283"
"81.78000","6.81517","0.00288"
"82.06200","6.83867","0.00278"
"82.34400","6.86210","0.00226"
"82.62600","6.88566","0.00274"
"82.90800","6.90910","0.00235"
"83.19000","6.93272","0.00318"
"83.47200","6.95609","0.00267"
"83.75400","6.97971","0.00296"
"84.03600","7.00315","0.00329"
"84.31800","7.02671","0.00293"
"84.60000","7.05014","0.00304"
"84.88200","7.07370","0.00277"
"85.16400","7.09714","0.00328"
"85.44600","7.12069","0.00286"
"85.72800","7.14413","0.00355"
"86.01000","7.16769","0.00347"
"86.29200","7.19119","0.00344"
"86.57400","7.21468","0.00299"
"86.85600","7.23818","0.00334"
"87.13800","7.26162","0.00333"
"87.42000","7.28524","0.00353"
"87.70200","7.30867","0.00325"
"87.98400","7.33217","0.00298"
"88.26600","7.35567","0.00315"
"88.54800","7.37922","0.00327"
"88.83000","7.40266","0.00337"
"89.11200","7.42616","0.00297"
"89.39400","7.44966","0.00373"
"89.67600","7.47315","0.00371"
"89.95800","7.49665","0.00323"
"90.24000","7.52021","0.00301"
"90.52200","7.54365","0.00334"
"90.80400","7.56720","0.00325"
"91.08600","7.59064","0.00370"
"91.36800","7.61414","0.00412"
"91.65000","7.63769","0.00363"
"91.93200","7.66119","0.00397"
"92.21400","7.68469","0.00347"
"92.49600","7.70813","0.00344"
"92.77800","7.73168","0.00417"
"93.06000","7.75518","0.00396"
"93.34200","7.77868","0.00415"
"93.62400","7.80212","0.00444"
"93.90600","7.82567","0.00391"
"94.18800","7.84917","0.00367"
"94.47000","7.87273","0.00386"
"94.75200","7.89616","0.00402"
"95.03400","7.91972","0.00381"
"95.31600","7.94316","0.00479"
"95.59800","7.96672","0.00424"
"95.88000","7.99015","0.00459"
"96.16200","8.01371","0.00475"
"96.44400","8.03715","0.00449"
"96.72600","8.06071","0.00483"
"97.00800","8.08414","0.00507"
"97.29000","8.10764","0.00436"
"97.57200","8.13114","0.00486"
"97.85400","8.15463","0.00579"
"98.13600","8.17819","0.00469"
"98.41800","8.20163","0.00501"
"98.70000","8.22519","0.00472"
"98.98200","8.24862","0.00413"
"99.26400","8.27218","0.00513"
"99.54600","8.29556","0.00489"
"99.82800","8.31917","0.00501"
"100.11000","8.34261","0.00485"
"100.39200","8.36617","0.00438"
"100.67400","8.38961","0.00485"
"100.95600","8.41322","0.00479"
"101.23800","8.43666","0.00465"
"101.52000","8.46022","0.00456"
"101.80200","8.48360","0.00477"
"102.08400","8.50715","0.00504"
"102.36600","8.53065","0.00421"
"102.64800","8.55421","0.00488"
"102.93000","8.57771","0.00421"
"103.21200","8.60120","0.00474"
"103.49400","8.62470","0.00553"
"103.77600","8.64826","0.00517"
"104.05800","8.67175","0.00513"
"104.34000","8.69519","0.00420"
"104.62200","8.71869","0.00451"
"104.90400","8.74219","0.00406"
"105.18600","8.76568","0.00440"
"105.46800","8.78918","0.00384"
"105.75000","8.81268","0.00388"
"106.03200","8.83612","0.00407"
"106.31400","8.85967","0.00388"
"106.59600","8.88311","0.00387"
"106.87800","8.90673","0.00425"
"107.16000","8.93011","0.00426"
"107.44200","8.95372","0.00409"
"107.72400","8.97716","0.00375"
"108.00600","9.00066","0.00414"
"108.28800","9.02415","0.00430"
"108.57000","9.04771","0.00441"
"108.85200","9.07121","0.00421"
"109.13400","9.09471","0.00460"
"109.41600","9.11820","0.00448"
"109.69800","9.14164","0.00498"
"109.98000","9.16520","0.00408"
"110.26200","9.18863","0.00424"
"110.54400","9.21225","0.00439"
"110.82600","9.23563","0.00487"
"111.10800","9.25925","0.00506"
"111.39000","9.28262","0.00467"
"111.67200","9.30624","0.00514"
"111.95400","9.32968","0.00450"
"112.23600","9.35324","0.00455"
"112.51800","9.37661","0.00449"
"112.80000","9.40017","0.00506"
"113.08200","9.42361","0.00473"
"113.36400","9.44722","0.00481"
"113.64600","9.47066","0.00498"
"113.92800","9.49416","0.00458"
"114.21000","9.51766","0.00500"
"114.49200","9.54115","0.00500"
"114.77400","9.56465","0.00504"
"115.05600","9.58809","0.00539"
"115.33800","9.61165","0.00487"
"115.62000","9.63508","0.00523"
"115.90200","9.65864","0.00499"
"116.18400","9.68214","0.00548"
"116.46600","9.70569","0.00512"
"116.74800","9.72913","0.00570"
"117.03000","9.75269","0.00509"
"117.31200","9.77613","0.00580"
"117.59400","9.79968","0.00565"
"117.87600","9.82312","0.00540"
"118.15800","9.84668","0.00524"
"118.44000","9.87012","0.00557"
"118.72200","9.89367","0.00557"
"119.00400","9.91717","0.00569"
"119.28600","9.94073","0.00611"
"119.56800","9.96417","0.00609"
"119.85000","9.98772","0.00631"
"120.13200","10.01116","0.00672"
"120.41400","10.03472","0.00661"
"120.69600","10.05815","0.00634"
"120.97800","10.08171","0.00642"
"121.26000","10.10521","0.00666"
"121.54200","10.12865","0.00681"
"121.82400","10.15220","0.00617"
"122.10600","10.17564","0.00673"
"122.38800","10.19914","0.00625"
"122.67000","10.22264","0.00690"
"122.95200","10.24619","0.00668"
"123.23400","10.26963","0.00659"
"123.51600","10.29313","0.00727"
"123.79800","10.31662","0.00751"
"124.08000","10.34018","0.00700"
"124.36200","10.36362","0.00712"
"124.64400","10.38724","0.00663"
"124.92600","10.41061","0.00732"
"125.20800","10.43417","0.00773"
"125.49000","10.45767","0.00722"
"125.77200","10.48116","0.00737"
"126.05400","10.50466","0.00750"
"126.33600","10.52822","0.00722"
"126.61800","10.55172","0.00731"
"126.90000","10.57515","0.00817"
"127.18200","10.59871","0.00781"
"127.46400","10.62221","0.00781"
"127.74600","10.64571","0.00726"
"128.02800","10.66914","0.00792"
"128.31000","10.69270","0.00785"
"128.59200","10.71614","0.00810"
"128.87400","10.73970","0.00794"
"129.15600","10.76313","0.00792"
"129.43800","10.78669","0.00818"
"129.72000","10.81013","0.00817"
"130.00200","10.83368","0.00835"
"130.28400","10.85712","0.00759"
"130.56600","10.88062","0.00799"
"130.84800","10.90412","0.00809"
"131.13000","10.92767","0.00795"
"131.41200","10.95117","0.00823"
"131.69400","10.97467","0.00845"
"131.97600","10.99817","0.00884"
"132.25800","11.02166","0.00836"
"132.54000","11.04516","0.00820"
"132.82200","11.06866","0.00889"
"133.10400","11.09221","0.00899"
"133.38600","11.11565","0.00829"
"133.66800","11.13921","0.00667"
"133.95000","11.16265","0.00681"
"134.23200","11.18620","0.00702"
"134.51400","11.20964","0.00688"
"134.79600","11.23320","0.00634"
"135.07800","11.25664","0.00666"
"135.36000","11.28019","0.00674"
"135.64200","11.30363","0.00654"
"135.92400","11.32725","0.00708"
"136.20600","11.35062","0.00715"
"136.48800","11.37418","0.00645"
"136.77000","11.39768","0.00638"
"137.05200","11.42118","0.00666"
"137.33400","11.44461","0.00635"
"137.61600","11.46817","0.00724"
"137.89800","11.49167","0.00709"
"138.18000","11.51517","0.00706"
"138.46200","11.53872","0.00717"
"138.74400","11.56216","0.00749"
"139.02600","11.58566","0.00684"
"139.30800","11.60915","0.00724"
"139.59000","11.63271","0.00656"
"139.87200","11.65615","0.00820"
"140.15400","11.67965","0.00768"
"140.43600","11.70314","0.00770"
"140.71800","11.72664","0.00721"
"141.00000","11.75014","0.00743"
"141.28200","11.77369","0.00756"
"141.56400","11.79713","0.00787"
"141.84600","11.82069","0.00743"
"142.12800","11.84413","0.00746"
"142.41000","11.86774","0.00751"
"142.69200","11.89112","0.00664"
"142.97400","11.91468","0.00678"
"143.25600","11.93818","0.00725"
"143.53800","11.96173","0.00659"
"143.82000","11.98517","0.00692"
"144.10200","12.00873","0.00771"
"144.38400","12.03223","0.00742"
"144.66600","12.05566","0.00771"
"144.94800","12.07916","0.00790"
"145.23000","12.10266","0.00746"
"145.51200","12.12621","0.00804"
"145.79400","12.14965","0.00794"
"146.07600","12.17321","0.00814"
"146.35800","12.19665","0.00814"
"146.64000","12.22014","0.00855"
"146.92200","12.24364","0.00836"
"147.20400","12.26714","0.00849"
"147.48600","12.29058","0.00844"
"147.76800","12.31413","0.00868"
"148.05000","12.33757","0.00891"
"148.33200","12.36119","0.00848"
"148.61400","12.38468","0.00881"
"148.89600","12.40818","0.00865"
"149.17800","12.43162","0.00902"
"149.46000","12.45518","0.00899"
"149.74200","12.47861","0.00944"
"150.02400","12.50217","0.00953"
"150.30600","12.52567","0.00928"
"150.58800","12.54917","0.00903"
"150.87000","12.57272","0.00968"
"151.15200","12.59616","0.00960"
"151.43400","12.61972","0.00973"
"151.71600","12.64316","0.00999"
"151.99800","12.66677","0.00983"
"152.28000","12.69015","0.00996"
"152.56200","12.71371","0.01013"
"152.84400","12.73714","0.00951"
"153.12600","12.76076","0.00969"
"153.40800","12.78414","0.01042"
"153.69000","12.80764","0.01028"
"153.97200","12.83113","0.01073"
"154.25400","12.85469","0.01136"
"154.53600","12.87807","0.01109"
"154.81800","12.90168","0.01108"
"155.10000","12.92518","0.01079"
"155.38200","12.94868","0.01125"
"155.66400","12.97212","0.01129"
"155.94600","12.99567","0.01100"
"156.22800","13.01917","0.01162"
"156.51000","13.04267","0.01156"
"156.79200","13.06617","0.01183"
"157.07400","13.08966","0.01174"
"157.35600","13.11316","0.01226"
"157.63800","13.13666","0.01206"
"157.92000","13.16021","0.01221"
"158.20200","13.18365","0.01271"
"158.48400","13.20721","0.01307"
"158.76600","13.23065","0.01246"
"159.04800","13.25420","0.01312"
"159.33000","13.27770","0.01348"
"159.61200","13.30126","0.01310"
"159.89400","13.32469","0.01373"
"160.17600","13.34819","0.01378"
"160.45800","13.37169","0.01363"
"160.74000","13.39519","0.01413"
"161.02200","13.41868","0.01442"
"161.30400","13.44218","0.01416"
"161.58600","13.46568","0.01495"
"161.86800","13.48918","0.01442"
"162.15000","13.51261","0.01448"
"162.43200","13.53617","0.01469"
"162.71400","13.55967","0.01502"
"162.99600","13.58311","0.01518"
"163.27800","13.60666","0.01544"
"163.56000","13.63016","0.01555"
"163.84200","13.65366","0.01609"
"164.12400","13.67710","0.01594"
"164.40600","13.70065","0.01600"
"164.68800","13.72409","0.01609"
"164.97000","13.74765","0.01599"
"165.25200","13.77114","0.01676"
"165.53400","13.79470","0.01664"
"165.81600","13.81814","0.01758"
"166.09800","13.84170","0.01717"
"166.38000","13.86519","0.01793"
"166.66200","13.88863","0.01835"
"166.94400","13.91213","0.01814"
"167.22600","13.93569","0.01815"
"167.50800","13.95918","0.01802"
"167.79000","13.98274","0.01861"
"168.07200","14.00624","0.01891"
"168.35400","14.02967","0.01866"
"168.63600","14.05323","0.01902"
"168.91800","14.07667","0.01892"
"169.20000","14.10023","0.01970"
"169.48200","14.12366","0.01946"
"169.76400","14.14722","0.01998"
"170.04600","14.17066","0.01970"
"170.32800","14.19421","0.01995"
"170.61000","14.21759","0.02097"
"170.89200","14.24121","0.02077"
"171.17400","14.26459","0.02211"
"171.45600","14.28820","0.02114"
"171.73800","14.31158","0.02149"
"172.02000","14.33520","0.02183"
"172.30200","14.35864","0.02234"
"172.58400","14.38219","0.02235"
"172.86600","14.40563","0.02207"
"173.14800","14.42919","0.02266"
"173.43000","14.45268","0.02304"
"173.71200","14.47618","0.02323"
"173.99400","14.49968","0.02387"
"174.27600","14.52318","0.02445"
"174.55800","14.54667","0.02460"
"174.84000","14.57017","0.02343"
"175.12200","14.59373","0.02397"
"175.40400","14.61717","0.02377"
"175.68600","14.64066","0.02313"
"175.96800","14.66416","0.02390"
"176.25000","14.68772","0.02104"
"176.53200","14.71115","0.02257"
"176.81400","14.73471","0.02283"
"177.09600","14.75815","0.02348"
"177.37800","14.78171","0.02318"
"177.66000","14.80514","0.02353"
"177.94200","14.82870","0.02359"
"178.22400","14.85214","0.02337"
"178.50600","14.87570","0.02435"
"178.78800","14.89913","0.02475"
"179.07000","14.92263","0.02480"
"179.35200","14.94613","0.02537"
"179.63400","14.96962","0.02603"
"179.91600","14.99312","0.02591"
"180.19800","15.01662","0.02572"
"180.48000","15.04018","0.02678"
"180.76200","15.06367","0.02564"
"181.04400","15.08723","0.02707"
"181.32600","15.11067","0.02774"
"181.60800","15.13417","0.02737"
"181.89000","15.15760","0.02792"
"182.17200","15.18116","0.02870"
"182.45400","15.20466","0.02974"
"182.73600","15.22821","0.02940"
"183.01800","15.25165","0.02893"
"183.30000","15.27521","0.02727"
"183.58200","15.29865","0.02710"
"183.86400","15.32220","0.02769"
"184.14600","15.34564","0.02900"
"184.42800","15.36920","0.02843"
"184.71000","15.39270","0.02880"
"184.99200","15.41619","0.02941"
"185.27400","15.43969","0.02921"
"185.55600","15.46319","0.02935"
"185.83800","15.48674","0.02948"
"186.12000","15.51018","0.02990"
"186.40200","15.53368","0.01580"
"186.68400","15.55712","0.01672"
"186.96600","15.58073","0.01830"
"187.24800","15.60411","0.01860"
"187.53000","15.62767","0.01992"
"187.81200","15.65110","0.02080"
"188.09400","15.67466","0.02133"
"188.37600","15.69810","0.02218"
"188.65800","15.72172","0.02342"
"188.94000","15.74509","0.02423"
"189.22200","15.76871","0.02561"
"189.50400","15.79215","0.02625"
"189.78600","15.81571","0.02716"
"190.06800","15.83914","0.02792"
"190.35000","15.86270","0.02775"
"190.63200","15.88614","0.02817"
"190.91400","15.90964","0.02967"
"191.19600","15.93319","0.02974"
"191.47800","15.95669","0.03065"
"191.76000","15.98025","0.03054"
"192.04200","16.00368","0.03140"
"192.32400","16.02724","0.03173"
"192.60600","16.05068","0.03154"
"192.88800","16.07418","0.03165"
"193.17000","16.09767","0.03133"
"193.45200","16.12123","0.02986"
"193.73400","16.14461","0.02875"
"194.01600","16.16817","0.03007"
"194.29800","16.19160","0.03055"
"194.58000","16.21516","0.02649"
"194.86200","16.23860","0.02880"
"195.14400","16.26221","0.02924"
"195.42600","16.28565","0.02847"
"195.70800","16.30915","0.02554"
"195.99000","16.33259","0.01360"
"196.27200","16.35614","0.01604"
"196.55400","16.37964","0.01685"
"196.83600","16.40314","0.01566"
"197.11800","16.42664","0.01613"
"197.40000","16.45013","0.01736"
"197.68200","16.47375","0.01631"
"197.96400","16.49719","0.01770"
"198.24600","16.52069","0.01772"
"198.52800","16.54418","0.01765"
"198.81000","16.56768","0.01834"
"199.09200","16.59112","0.01922"
"199.37400","16.61467","0.01853"
"199.65600","16.63817","0.01961"
"199.93800","16.66167","0.01937"
"200.22000","16.68517","0.01959"
"200.50200","16.70872","0.01998"
"200.78400","16.73210","0.02069"
"201.06600","16.75572","0.02116"
"201.34800","16.77915","0.02085"
"201.63000","16.80265","0.02116"
"201.91200","16.82615","0.02108"
"202.19400","16.84971","0.02121"
"202.47600","16.87320","0.02180"
"202.75800","16.89670","0.02197"
"203.04000","16.92020","0.02333"
"203.32200","16.94364","0.02340"
"203.60400","16.96719","0.02401"
"203.88600","16.99063","0.02464"
"204.16800","17.01425","0.02599"
"204.45000","17.03762","0.02699"
"204.73200","17.06118","0.02664"
"205.01400","17.08462","0.02770"
"205.29600","17.10818","0.02836"
"205.57800","17.13161","0.02882"
"205.86000","17.15523","0.03003"
"206.14200","17.17867","0.03030"
"206.42400","17.20223","0.02996"
"206.70600","17.22560","0.03132"
"206.98800","17.24922","0.03263"
"207.27000","17.27266","0.03282"
"207.55200","17.29616","0.03313"
"207.83400","17.31971","0.03354"
"208.11600","17.34321","0.03383"
"208.39800","17.36665","0.03457"
"208.68000","17.39021","0.03481"
"208.96200","17.41370","0.03531"
"209.24400","17.43720","0.03510"
"209.52600","17.46070","0.03564"
"209.80800","17.48413","0.03579"
"210.09000","17.50769","0.03592"
"210.37200","17.53113","0.03625"
"210.65400","17.55469","0.03643"
"210.93600","17.57812","0.03701"
"211.21800","17.60168","0.03737"
"211.50000","17.62512","0.03783"
"211.78200","17.64867","0.03823"
"212.06400","17.67205","0.03860"
"212.34600","17.69567","0.03895"
"212.62800","17.71911","0.03929"
"212.91000","17.74272","0.03857"
"213.19400","17.76628","0.03885"
"213.47600","17.78984","0.03914"
"213.75800","17.81333","0.03976"
"214.04000","17.83683","0.04048"
"214.32200","17.86027","0.04146"
"214.60400","17.88383","0.04218"
"214.88600","17.90732","0.04385"
"215.16800","17.93082","0.04373"
"215.45000","17.95432","0.04469"
"215.73200","17.97782","0.04563"
"216.01400","18.00137","0.03686"
"216.29600","18.02481","0.03813"
"216.57800","18.04837","0.03971"
"216.86000","18.07180","0.03818"
"217.14200","18.09536","0.03803"
"217.42400","18.11880","0.03975"
"217.70600","18.14235","0.04120"
"217.98800","18.16579","0.04059"
"218.27000","18.18935","0.04030"
"218.55200","18.21285","0.04030"
"218.83400","18.23635","0.04152"
"219.11600","18.25984","0.03985"
"219.39800","18.28340","0.04110"
"219.68000","18.30684","0.04165"
"219.96200","18.33034","0.04194"
"220.24400","18.35383","0.04442"
"220.52600","18.37727","0.04597"
"220.80800","18.40083","0.04034"
"221.09000","18.42439","0.04228"
"221.37200","18.44794","0.04041"
"221.65400","18.47132","0.04142"
"221.93600","18.49488","0.04314"
"222.21800","18.51831","0.04522"
"222.50000","18.54187","0.04743"
"222.78200","18.56531","0.04724"
"223.06400","18.58887","0.04927"
"223.34600","18.61230","0.05018"
"223.62800","18.63586","0.05167"
"223.91000","18.65930","0.05367"
"224.19200","18.68291","0.05246"
"224.47400","18.70635","0.04394"
"224.75600","18.72985","0.04486"
"225.03800","18.75329","0.04642"
"225.32000","18.77690","0.04841"
"225.60200","18.80034","0.05162"
"225.88400","18.82384","0.04930"
"226.16600","18.84734","0.05134"
"226.44800","18.87083","0.05405"
"226.73000","18.89433","0.05549"
"227.01200","18.91783","0.05634"
"227.29400","18.94138","0.05840"
"227.57600","18.96482","0.05499"
"227.85800","18.98832","0.05810"
"228.14000","19.01182","0.05985"
"228.42200","19.03531","0.05996"
"228.70400","19.05875","0.06206"
"228.98600","19.08231","0.06309"
"229.26800","19.10575","0.06473"
"229.55000","19.12936","0.06636"
"229.83200","19.15274","0.06634"
"230.11400","19.17636","0.06689"
"230.39600","19.19979","0.06758"
"230.67800","19.22335","0.06859"
"230.96000","19.24679","0.06938"
"231.24200","19.27035","0.07102"
"231.52400","19.29384","0.07301"
"231.80600","19.31740","0.07320"
"232.08800","19.34090","0.07475"
"232.37000","19.36433","0.07590"
"232.65200","19.38783","0.07637"
"232.93400","19.41139","0.07717"
"233.21600","19.43489","0.07888"
"233.49800","19.45832","0.07942"
"233.78000","19.48188","0.07960"
"234.06200","19.50532","0.07697"
"234.34400","19.52888","0.07830"
"234.62600","19.55231","0.07920"
"234.90800","19.57587","0.08032"
"235.19000","19.59931","0.08085"
"235.47200","19.62280","0.08212"
"235.75400","19.64630","0.08229"
"236.03600","19.66986","0.08283"
"236.31800","19.69336","0.08341"
"236.60000","19.71686","0.08361"
"236.88200","19.74035","0.08395"
"237.16400","19.76385","0.08440"
"237.44600","19.78735","0.08475"
"237.72800","19.81084","0.08510"
"238.01000","19.83440","0.08525"
"238.29200","19.85784","0.08606"
"238.57400","19.88139","0.08694"
"238.85600","19.90483","0.08839"
"239.13800","19.92839","0.08984"
"239.42000","19.95183","0.09131"
"239.70200","19.97538","0.09262"
"239.98400","19.99876","0.09524"
"240.26600","20.02238","0.09643"
"240.54800","20.04576","0.09717"
"240.83000","20.06937","0.09776"
"241.11200","20.09281","0.10103"
"241.39400","20.11637","0.10471"
"241.67600","20.13981","0.10576"
"241.95800","20.16336","0.10892"
"242.24000","20.18680","0.11114"
"242.52200","20.21036","0.11325"
"242.80400","20.23385","0.11619"
"243.08600","20.25735","0.12077"
"243.36800","20.28079","0.12456"
"243.65000","20.30434","0.12799"
"243.93200","20.32784","0.13175"
"244.21400","20.35128","0.13363"
"244.49600","20.37484","0.13646"
"244.77800","20.39828","0.13983"
"245.06000","20.42183","0.14087"
"245.34200","20.44527","0.14179"
"245.62400","20.46889","0.14249"
"245.90600","20.49232","0.14391"
"246.18800","20.51582","0.14447"
"246.47000","20.53926","0.14515"
"246.75200","20.56282","0.14626"
"247.03400","20.58631","0.14746"
"247.31600","20.60993","0.14969"
"247.59800","20.63331","0.15095"
"247.88000","20.65686","0.15199"
"248.16200","20.68030","0.15321"
"248.44400","20.70386","0.15698"
"248.72600","20.72736","0.16099"
"249.00800","20.75085","0.16255"
"249.29000","20.77435","0.16516"
"249.57200","20.79785","0.16917"
"249.85400","20.82135","0.17244"
"250.13600","20.84484","0.17596"
"250.41800","20.86834","0.17763"
"250.70000","20.89184","0.18032"
"250.98200","20.91539","0.18289"
"251.26400","20.93883","0.18417"
"251.54600","20.96233","0.18523"
"251.82800","20.98583","0.18483"
"252.11000","21.00933","0.18490"
"252.39200","21.03282","0.18578"
"252.67400","21.05632","0.18819"
"252.95600","21.07976","0.19008"
"253.23800","21.10337","0.19172"
"253.52000","21.12681","0.19345"
"253.80200","21.15037","0.19484"
"254.08400","21.17381","0.19632"
"254.36600","21.19736","0.19768"
"254.64800","21.22086","0.19989"
"254.93000","21.24436","0.20299"
"255.21200","21.26785","0.20658"
"255.49400","21.29135","0.20877"
"255.77600","21.31485","0.21353"
"256.05800","21.33835","0.21729"
"256.34000","21.36190","0.21977"
"256.62200","21.38534","0.22172"
"256.90400","21.40890","0.22497"
"257.18600","21.43228","0.22772"
"257.46800","21.45583","0.23037"
"257.75000","21.47933","0.23247"
"258.03200","21.50289","0.23440"
"258.31400","21.52633","0.23585"
"258.59600","21.54982","0.23769"
"258.87800","21.57326","0.23945"
"259.16000","21.59682","0.24251"
"259.44200","21.62031","0.24580"
"259.72400","21.64381","0.25214"
"260.00600","21.66731","0.25769"
"260.28800","21.69081","0.26214"
"260.57000","21.71430","0.26423"
"260.85200","21.73780","0.26622"
"261.13400","21.76130","0.27009"
"261.41600","21.78479","0.27205"
"261.69800","21.80829","0.27133"
"261.98000","21.83179","0.19996"
"262.26200","21.85535","0.19953"
"262.54400","21.87884","0.20183"
"262.82600","21.90240","0.20612"
"263.10800","21.92584","0.20956"
"263.39000","21.94934","0.21235"
"263.67200","21.97277","0.21706"
"263.95400","21.99639","0.22024"
"264.23600","22.01977","0.22317"
"264.51800","22.04333","0.22502"
"264.80000","22.06676","0.21922"
"265.08200","22.09038","0.21012"
"265.36400","22.11382","0.18058"
"265.64600","22.13737","0.18141"
"265.92800","22.16087","0.18327"
"266.21000","22.18437","0.18464"
"266.49200","22.20781","0.18614"
"266.77400","22.23136","0.18767"
"267.05600","22.25480","0.18828"
"267.33800","22.27835","0.18935"
"267.62000","22.30185","0.19087"
"267.90200","22.32529","0.19172"
"268.18400","22.34885","0.19250"
"268.46600","22.37234","0.19393"
"268.74800","22.39584","0.19544"
"269.03000","22.41934","0.19625"
"269.31200","22.44284","0.19707"
"269.59400","22.46628","0.19812"
"269.87600","22.48983","0.20048"
"270.15800","22.51333","0.20244"
"270.44000","22.53689","0.20550"
"270.72200","22.56032","0.20859"
"271.00400","22.58382","0.21134"
"271.28600","22.60726","0.21381"
"271.56800","22.63088","0.21575"
"271.85000","22.65431","0.21749"
"272.13200","22.67781","0.21945"
"272.41400","22.70137","0.22127"
"272.69600","22.72487","0.22305"
"272.97800","22.74836","0.22564"
"273.26000","22.77192","0.22777"
"273.54200","22.79536","0.23028"
"273.82400","22.81880","0.23219"
"274.10600","22.84229","0.23357"
"274.38800","22.86579","0.23487"
"274.67000","22.88941","0.23536"
"274.95200","22.91285","0.23661"
"275.23400","22.93634","0.23851"
"275.51600","22.95978","0.24024"
"275.79800","22.98334","0.24320"
"276.08000","23.00677","0.24445"
"276.36200","23.03033","0.24775"
"276.64400","23.05377","0.25079"
"276.92600","23.07733","0.25501"
"277.20800","23.10076","0.25891"
"277.49000","23.12432","0.26218"
"277.77200","23.14782","0.26276"
"278.05400","23.17137","0.26575"
"278.33600","23.19481","0.26901"
"278.61800","23.21825","0.27179"
"278.90000","23.24181","0.27517"
"279.18200","23.26530","0.27853"
"279.46400","23.28886","0.28281"
"279.74600","23.31230","0.28807"
"280.02800","23.33585","0.29143"
"280.31000","23.35929","0.29352"
"280.59200","23.38285","0.29460"
"280.87400","23.40623","0.29594"
"281.15600","23.42990","0.29541"
"281.43800","23.45328","0.29681"
"281.72000","23.47684","0.29714"
"282.00200","23.50028","0.29738"
"282.28400","23.52395","0.29756"
"282.56600","23.54733","0.29780"
"282.84800","23.57089","0.29823"
"283.13000","23.59432","0.29887"
"283.41200","23.61788","0.29941"
"283.69400","23.64132","0.30050"
"283.97600","23.66488","0.30243"
"284.25800","23.68831","0.30416"
"284.54000","23.71181","0.30584"
"284.82200","23.73531","0.30817"
"285.10400","23.75880","0.31035"
"285.38600","23.78236","0.31343"
"285.66800","23.80580","0.31705"
"285.95000","23.82936","0.32101"
"286.23200","23.85286","0.32418"
"286.51400","23.87635","0.32814"
"286.79600","23.89979","0.33230"
"287.07800","23.92335","0.33662"
"287.36000","23.94684","0.33870"
"287.64200","23.97034","0.34201"
"287.92400","23.99384","0.34401"
"288.20600","24.01740","0.34533"
"288.48800","24.04083","0.34662"
"288.77000","24.06439","0.34826"
"289.05200","24.08783","0.34938"
"289.33400","24.11133","0.35082"
"289.61600","24.13482","0.35316"
"289.89800","24.15838","0.35530"
"290.18000","24.18188","0.35960"
"290.46200","24.20537","0.36179"
"290.74400","24.22887","0.36629"
"291.02600","24.25231","0.36898"
"291.30800","24.27581","0.37180"
"291.59000","24.29930","0.37376"
"291.87200","24.32286","0.37529"
"292.15400","24.34630","0.37745"
"292.43600","24.36985","0.37892"
"292.71800","24.39329","0.38084"
"293.00000","24.41679","0.38237"
"293.28200","24.44029","0.38427"
"293.56400","24.46379","0.38559"
"293.84600","24.48722","0.38725"
"294.12800","24.51084","0.38871"
"294.41000","24.53428","0.39025"
"294.69200","24.55783","0.39357"
"294.97400","24.58127","0.39540"
"295.25600","24.60489","0.39720"
"295.53800","24.62832","0.39900"
"295.82000","24.65182","0.40082"
"296.10200","24.67532","0.40252"
"296.38400","24.69882","0.40486"
"296.66600","24.72238","0.40779"
"296.94800","24.74587","0.41006"
"297.23000","24.76937","0.41309"
"297.51200","24.79287","0.41568"
"297.79400","24.81642","0.41790"
"298.07600","24.83986","0.42072"
"298.35800","24.86342","0.42385"
"298.64000","24.88686","0.42753"
"298.92200","24.91035","0.43059"
"299.20400","24.93379","0.43316"
"299.48600","24.95741","0.43528"
"299.76800","24.98078","0.43864"
"300.05000","25.00434","0.44209"
"300.33200","25.02778","0.44433"
"300.61400","25.05140","0.44447"
"300.89600","25.07477","0.44547"
"301.17800","25.09839","0.44546"
"301.46000","25.12177","0.44607"
"301.74200","25.14533","0.44720"
"302.02400","25.16882","0.44666"
"302.30600","25.19238","0.44805"
"302.58800","25.21588","0.45045"
"302.87000","25.23937","0.45175"
"303.15200","25.26287","0.46064"
"303.43400","25.28631","0.46747"
"303.71600","25.30986","0.47221"
"303.99800","25.33330","0.47783"
"304.28000","25.35686","0.48239"
"304.56200","25.38030","0.48774"
"304.84400","25.40385","0.49178"
"305.12600","25.42729","0.49522"
"305.40800","25.45085","0.49848"
"305.69000","25.47429","0.50119"
"305.97200","25.49784","0.50390"
"306.25400","25.52128","0.50672"
"306.53600","25.54484","0.50791"
"306.81800","25.56834","0.50905"
"307.10000","25.59189","0.50973"
"307.38200","25.61533","0.51110"
"307.66400","25.63889","0.51300"
"307.94600","25.66232","0.51535"
"308.22800","25.68582","0.51748"
"308.51000","25.70932","0.52168"
"308.79200","25.73282","0.52464"
"309.07400","25.75638","0.52252"
"309.35600","25.77981","0.52592"
"309.63800","25.80331","0.53081"
"309.92000","25.82681","0.53595"
"310.20200","25.85036","0.54093"
"310.48400","25.87380","0.54633"
"310.76600","25.89730","0.54989"
"311.04800","25.92074","0.55196"
"311.33000","25.94435","0.55404"
"311.61200","25.96785","0.55646"
"311.89400","25.99135","0.56022"
"312.17600","26.01478","0.56515"
"312.45800","26.03840","0.57068"
"312.74000","26.06184","0.57500"
"313.02200","26.08534","0.58045"
"313.30400","26.10884","0.58436"
"313.58600","26.13233","0.58654"
"313.86800","26.15583","0.58923"
"314.15000","26.17933","0.59254"
"314.43200","26.20288","0.59463"
"314.71400","26.22638","0.59602"
"314.99600","26.24994","0.59688"
"315.27800","26.27332","0.59741"
"315.56000","26.29687","0.59778"
"315.84200","26.32031","0.59837"
"316.12400","26.34386","0.59938"
"316.40600","26.36731","0.60108"
"316.68800","26.39086","0.60355"
"316.97000","26.41430","0.60687"
"317.25200","26.43785","0.61049"
"317.53400","26.46129","0.61417"
"317.81600","26.48485","0.61680"
"318.09800","26.50829","0.61905"
"318.38000","26.53184","0.62199"
"318.66200","26.55528","0.62540"
"318.94400","26.57884","0.62902"
"319.22600","26.60233","0.63278"
"319.50800","26.62589","0.63725"
"319.79000","26.64933","0.64324"
"320.07200","26.67283","0.64585"
"320.35400","26.69632","0.64854"
"320.63600","26.71982","0.65225"
"320.91800","26.74338","0.65488"
"321.20000","26.76688","0.65582"
"321.48200","26.79037","0.65660"
"321.76400","26.81381","0.65732"
"322.04600","26.83737","0.65818"
"322.32800","26.86081","0.65927"
"322.61000","26.88436","0.66053"
"322.89200","26.90780","0.66403"
"323.17400","26.93130","0.66761"
"323.45600","26.95474","0.67225"
"323.73800","26.97836","0.67706"
"324.02000","27.00179","0.67944"
"324.30200","27.02541","0.68178"
"324.58400","27.04885","0.68444"
"324.86600","27.07234","0.68723"
"325.14800","27.09578","0.68963"
"325.43000","27.11934","0.69152"
"325.71200","27.14277","0.69362"
"325.99400","27.16633","0.69662"
"326.27600","27.18983","0.69885"
"326.55800","27.21333","0.70033"
"326.84000","27.23688","0.70206"
"327.12200","27.26038","0.70342"
"327.40400","27.28388","0.70476"
"327.68600","27.30732","0.70539"
"327.96800","27.33081","0.70625"
"328.25000","27.35425","0.70689"
"328.53200","27.37787","0.70783"
"328.81400","27.40131","0.70891"
"329.09600","27.42480","0.71061"
"329.37800","27.44836","0.71168"
"329.66000","27.47191","0.71351"
"329.94200","27.49529","0.71532"
"330.22400","27.51879","0.71790"
"330.50600","27.54235","0.64214"
"330.78800","27.56579","0.59469"
"331.07000","27.58928","0.59633"
"331.35200","27.61284","0.59611"
"331.63400","27.63640","0.59411"
"331.91600","27.65983","0.59445"
"332.19800","27.68339","0.59638"
"332.48000","27.70683","0.59779"
"332.76200","27.73039","0.59794"
"333.04400","27.75382","0.59772"
"333.32600","27.77738","0.59840"
"333.60800","27.80082","0.60046"
"333.89000","27.82438","0.60277"
"334.17200","27.84781","0.60266"
"334.45400","27.87137","0.60418"
"334.73600","27.89481","0.60840"
"335.01800","27.91842","0.61294"
"335.30000","27.94180","0.61474"
"335.58200","27.96536","0.61757"
"335.86400","27.98879","0.62153"
"336.14600","28.01235","0.62580"
"336.42800","28.03579","0.62729"
"336.71000","28.05935","0.63090"
"336.99200","28.08284","0.63479"
"337.27400","28.10634","0.63700"
"337.55600","28.12978","0.63949"
"337.83800","28.15334","0.64299"
"338.12000","28.17690","0.64394"
"338.40200","28.20033","0.64670"
"338.68400","28.22389","0.64997"
"338.96600","28.24733","0.65253"
"339.24800","28.27088","0.65352"
"339.53000","28.29432","0.65540"
"339.81200","28.31782","0.65610"
"340.09400","28.34132","0.65649"
"340.37600","28.36487","0.65692"
"340.65800","28.38831","0.65728"
"340.94000","28.41181","0.65739"
"341.22200","28.43524","0.65777"
"341.50400","28.45886","0.65818"
"341.78600","28.48230","0.65867"
"342.06800","28.50586","0.65944"
"342.35000","28.52929","0.66041"
"342.63200","28.55279","0.66015"
"342.91400","28.57629","0.66061"
"343.19600","28.59979","0.66060"
"343.47800","28.62334","0.66231"
"343.76000","28.64684","0.66369"
"344.04200","28.67034","0.66464"
"344.32400","28.69383","0.66682"
"344.60600","28.71733","0.66967"
"344.88800","28.74077","0.67297"
"345.17000","28.76433","0.67553"
"345.45200","28.78782","0.67702"
"345.73400","28.81132","0.67923"
"346.01600","28.83476","0.68044"
"346.29800","28.85831","0.68214"
"346.58000","28.88181","0.68438"
"346.86200","28.90537","0.68668"
"347.14400","28.92881","0.68912"
"347.42600","28.95236","0.68944"
"347.70800","28.97580","0.69069"
"347.99000","28.99930","0.69406"
"348.27200","29.02280","0.69616"
"348.55400","29.04635","0.69806"
"348.83600","29.06991","0.69997"
"349.11800","29.09335","0.70159"
"349.40000","29.11685","0.70253"
"349.68200","29.14028","0.70307"
"349.96400","29.16384","0.70446"
"350.24600","29.18734","0.70561"
"350.52800","29.21090","0.70618"
"350.81000","29.23433","0.70704"
"351.09200","29.25789","0.70771"
"351.37400","29.28133","0.70833"
"351.65600","29.30488","0.70826"
"351.93800","29.32832","0.70893"
"352.22000","29.35188","0.70944"
"352.50200","29.37526","0.70943"
"352.78400","29.39887","0.70967"
"353.06600","29.42231","0.70999"
"353.34800","29.44593","0.71026"
"353.63000","29.46930","0.71052"
"353.91200","29.49286","0.71116"
"354.19400","29.51630","0.71195"
"354.47600","29.53986","0.71243"
"354.75800","29.56335","0.71336"
"355.04000","29.58685","0.71494"
"355.32200","29.61029","0.71579"
"355.60400","29.63379","0.71586"
"355.88600","29.65734","0.71789"
"356.16800","29.68084","0.72084"
"356.45000","29.70440","0.72326"
"356.73200","29.72783","0.32339"
"357.01400","29.75139","0.31631"
"357.29600","29.77477","0.31163"
"357.57800","29.79833","0.31152"
"357.86000","29.82176","0.31130"
"358.14200","29.84532","0.31150"
"358.42400","29.86876","0.31224"
"358.70600","29.89238","0.31144"
"358.98800","29.91575","0.31138"
"359.27000","29.93937","0.31350"
"359.55200","29.96287","0.31514"
"359.83400","29.98637","0.31418"
"360.11600","30.00974","0.31494"
"360.39800","30.03330","0.31690"
"360.68000","30.05680","0.31857"
"360.96200","30.08036","0.31868"
"361.24400","30.10385","0.31917"
"361.52600","30.12735","0.32137"
"361.80800","30.15085","0.32308"
"362.09000","30.17435","0.32474"
"362.37200","30.19790","0.32516"
"362.65400","30.22134","0.32734"
"362.93600","30.24483","0.32934"
"363.21800","30.26827","0.32982"
"363.50000","30.29183","0.33136"
"363.78200","30.31533","0.33259"
"364.06400","30.33888","0.33500"
"364.34600","30.36232","0.33626"
"364.62800","30.38588","0.33759"
"364.91000","30.40932","0.33862"
"365.19200","30.43287","0.34023"
"365.47400","30.45637","0.34106"
"365.75600","30.47987","0.34199"
"366.03800","30.50337","0.34278"
"366.32000","30.52686","0.34432"
"366.60200","30.55036","0.34493"
"366.88400","30.57386","0.34591"
"367.16600","30.59735","0.34630"
"367.44800","30.62085","0.34727"
"367.73000","30.64435","0.34792"
"368.01200","30.66785","0.34763"
"368.29400","30.69140","0.34869"
"368.57600","30.71484","0.34881"
"368.85800","30.73834","0.35009"
"369.14000","30.76177","0.35091"
"369.42200","30.78533","0.35212"
"369.70400","30.80877","0.35287"
"369.98600","30.83239","0.35605"
"370.26800","30.85583","0.35889"
"370.55000","30.87938","0.36118"
"370.83200","30.90282","0.36309"
"371.11400","30.92637","0.36469"
"371.39600","30.94981","0.36501"
"371.67800","30.97337","0.36804"
"371.96000","30.99687","0.36930"
"372.24200","31.02036","0.37108"
"372.52400","31.04386","0.37208"
"372.80600","31.06736","0.37384"
"373.08800","31.09085","0.37453"
"373.37000","31.11430","0.37500"
"373.65200","31.13785","0.37616"
"373.93400","31.16129","0.37671"
"374.21600","31.18484","0.37824"
"374.49800","31.20828","0.37897"
"374.78000","31.23184","0.37968"
"375.06200","31.25528","0.38073"
"375.34400","31.27883","0.38122"
"375.62600","31.30227","0.38187"
"375.90800","31.32583","0.38201"
"376.19000","31.34926","0.38276"
"376.47200","31.37288","0.38323"
"376.75400","31.39632","0.38296"
"377.03600","31.41988","0.38357"
"377.31800","31.44332","0.38465"
"377.60000","31.46687","0.38592"
"377.88200","31.49031","0.38579"
"378.16400","31.51387","0.38590"
"378.44600","31.53731","0.38670"
"378.72800","31.56086","0.38697"
"379.01000","31.58430","0.38758"
"379.29200","31.60785","0.38876"
"379.57400","31.63135","0.39003"
"379.85600","31.65485","0.39105"
"380.13800","31.67841","0.39198"
"380.42000","31.70184","0.39201"
"380.70200","31.72534","0.39321"
"380.98400","31.74884","0.39423"
"381.26600","31.77240","0.39538"
"381.54800","31.79577","0.39559"
"381.83000","31.81927","0.39610"
"382.11200","31.84277","0.39681"
"382.39400","31.86633","0.10977"
"382.67600","31.88982","0.08991"
"382.95800","31.91338","0.08137"
"383.24000","31.93682","0.09629"
"383.52200","31.96037","0.07995"
"383.80400","31.98387","0.11521"
"384.08600","32.00731","0.08172"
"384.36800","32.03086","0.10983"
"384.65000","32.05436","0.08443"
"384.93200","32.07786","0.09576"
"385.21400","32.10130","0.09672"
"385.49600","32.12486","0.08909"
"385.77800","32.14829","0.11545"
"386.06000","32.17185","0.08881"
"386.34200","32.19529","0.10740"
"386.62400","32.21885","0.10254"
"386.90600","32.24228","0.09724"
"387.18800","32.26590","0.12034"
"387.47000","32.28934","0.10740"
"387.75200","32.31283","0.11244"
"388.03400","32.33633","0.12694"
"388.31600","32.35989","0.10313"
"388.59800","32.38333","0.14153"
"388.88000","32.40682","0.10606"
"389.16200","32.43032","0.13738"
"389.44400","32.45382","0.12024"
"389.72600","32.47731","0.12850"
"390.00800","32.50081","0.13588"
"390.29000","32.52431","0.13020"
"390.57200","32.54781","0.13167"
"390.85400","32.57130","0.13884"
"391.13600","32.59474","0.13640"
"391.41800","32.61836","0.13927"
"391.70000","32.64185","0.14326"
"391.98200","32.66541","0.13315"
"392.26400","32.68879","0.14507"
"392.54600","32.71229","0.13886"
"392.82800","32.73578","0.14352"
"393.11000","32.75934","0.14383"
"393.39200","32.78278","0.14244"
"393.67400","32.80634","0.14509"
"393.95600","32.82977","0.14397"
"394.23800","32.85339","0.14563"
"394.52000","32.87683","0.14479"
"394.80200","32.90039","0.14760"
"395.08400","32.92382","0.14466"
"395.36600","32.94738","0.14741"
"395.64800","32.97082","0.14716"
"395.93000","32.99437","0.14588"
"396.21200","33.01781","0.15183"
"396.49400","33.04137","0.14680"
"396.77600","33.06487","0.15079"
"397.05800","33.08830","0.14898"
"397.34000","33.11186","0.15100"
"397.62200","33.13530","0.15101"
"397.90400","33.15886","0.15190"
"398.18600","33.18229","0.15425"
"398.46800","33.20579","0.15177"
"398.75000","33.22929","0.15784"
"399.03200","33.25285","0.15404"
"399.31400","33.27628","0.15666"
"399.59600","33.29990","0.15933"
"399.87800","33.32334","0.15776"
"400.16000","33.34684","0.16161"
"400.44200","33.37027","0.16003"
"400.72400","33.39389","0.16277"
"401.00600","33.41732","0.16214"
"401.28800","33.44083","0.16315"
"401.57000","33.46432","0.16623"
"401.85200","33.48788","0.16376"
"402.13400","33.51138","0.16787"
"402.41600","33.53487","0.16688"
"402.69800","33.55837","0.16795"
"402.98000","33.58181","0.17020"
"403.26200","33.60536","0.16970"
"403.54400","33.62880","0.17200"
"403.82600","33.65236","0.17157"
"404.10800","33.67586","0.17327"
"404.39000","33.69941","0.17468"
"404.67200","33.72279","0.17426"
"404.95400","33.74635","0.17658"
"405.23600","33.76979","0.17617"
"405.51800","33.79334","0.17802"
"405.80000","33.81678","0.17879"
"406.08200","33.84027","0.17904"
"406.36400","33.86378","0.18037"
"406.64600","33.88733","0.18030"
"406.92800","33.91083","0.18123"
"407.21000","33.93438","0.18183"
"407.49200","33.95782","0.18186"
"407.77400","33.98132","0.18310"
"408.05600","34.00482","0.18298"
"408.33800","34.02831","0.18354"
"408.62000","34.05187","0.18445"
"408.90200","34.07531","0.18433"
"409.18400","34.09887","0.18510"
"409.46600","34.12230","0.18517"
"409.74800","34.14586","0.18574"
"410.03000","34.16924","0.18621"
"410.31200","34.19292","0.18616"
"410.59400","34.21629","0.18700"
"410.87600","34.23985","0.18734"
"411.15800","34.26329","0.18701"
"411.44000","34.28690","0.18755"
"411.72200","34.31034","0.18681"
"412.00400","34.33384","0.18827"
"412.28600","34.35734","0.18857"
"412.56800","34.38083","0.18859"
"412.85000","34.40434","0.18909"
"413.13200","34.42789","0.18945"
"413.41400","34.45133","0.18993"
"413.69600","34.47488","0.19005"
"413.97800","34.49832","0.19067"
"414.26000","34.52182","0.19073"
"414.54200","34.54532","0.19126"
"414.82400","34.56881","0.19159"
"415.10600","34.59237","0.19204"
"415.38800","34.61581","0.19225"
"415.67000","34.63937","0.19269"
"415.95200","34.66280","0.19288"
"416.23400","34.68636","0.19329"
"416.51600","34.70980","0.19363"
"416.79800","34.73336","0.19368"
"417.08000","34.75679","0.19404"
"417.36200","34.78035","0.19389"
"417.64400","34.80379","0.19399"
"417.92600","34.82740","0.19424"
"418.20800","34.85084","0.19414"
"418.49000","34.87434","0.19458"
"418.77200","34.89783","0.18814"
"419.05400","34.92139","0.01126"
"419.33600","34.94489","0.00369"
"419.61800","34.96833","0.00086"
"419.90000","34.99188","0.00189"
"420.18200","35.01532","-0.00076"
"420.46400","35.03882","0.00097"
"420.74600","35.06232","0.00109"
"421.02800","35.08587","0.00034"
"421.31000","35.10931","0.00049"
"421.59200","35.13287","-0.00001"
"421.87400","35.15631","0.00008"
"422.15600","35.17986","-0.00002"
"422.41200","35.20109","0.00047"