File: Force_trajectories/170108_1/Specimen_RawData_3.csv
End date,"1/8/2017"
Specimen label,"20DT_UNK"
Maximum Load,"0.19153",N

Time,Extension,Load
(s),(mm),(N)
"0.00000","0.00000","-0.00038"
"0.39600","0.03318","0.00010"
"0.79200","0.06619","0.00071"
"1.18800","0.09919","0.00176"
"1.58400","0.13213","0.00182"
"1.98000","0.16520","0.00281"
"2.37600","0.19814","0.00294"
"2.77200","0.23121","0.00336"
"3.16800","0.26415","0.00377"
"3.56400","0.29715","0.00437"
"3.96000","0.33022","0.00458"
"4.35600","0.36316","0.00497"
"4.75200","0.39617","0.00509"
"5.14800","0.42917","0.00534"
"5.54400","0.46217","0.00614"
"5.94000","0.49518","0.00607"
"6.33600","0.52818","0.00645"
"6.73200","0.56118","0.00714"
"7.12800","0.59419","0.00743"
"7.52400","0.62719","0.00794"
"7.92000","0.66020","0.00834"
"8.31600","0.69320","0.00860"
"8.71200","0.72620","0.00899"
"9.10800","0.75915","0.00842"
"9.50400","0.79215","0.00831"
"9.90000","0.82522","0.00866"
"10.29600","0.85822","0.00880"
"10.69200","0.89110","0.00872"
"11.08800","0.92423","0.01022"
"11.48400","0.95723","0.01045"
"11.88000","0.99017","0.01109"
"12.27600","1.02312","0.01184"
"12.67200","1.05618","0.01300"
"13.06800","1.08919","0.01424"
"13.46400","1.12219","0.01677"
"13.86000","1.15513","0.01600"
"14.25600","1.18820","0.01698"
"14.65200","1.22120","0.01785"
"15.04800","1.25420","0.01910"
"15.44400","1.28715","0.02062"
"15.84000","1.32021","0.02187"
"16.23600","1.35322","0.02305"
"16.63200","1.38616","0.02399"
"17.02800","1.41910","0.02476"
"17.42400","1.45217","0.02612"
"17.82000","1.48523","0.02707"
"18.21600","1.51812","0.02771"
"18.61200","1.55118","0.02854"
"19.00800","1.58418","0.02998"
"19.40400","1.61719","0.03137"
"19.80000","1.65013","0.03214"
"20.19600","1.68314","0.03315"
"20.59200","1.71620","0.03369"
"20.98800","1.74920","0.03453"
"21.38400","1.78215","0.03521"
"21.78000","1.81521","0.03601"
"22.17600","1.84815","0.03769"
"22.57200","1.88116","0.03859"
"22.96800","1.91422","0.03948"
"23.36400","1.94717","0.04016"
"23.76000","1.98023","0.04155"
"24.15600","2.01317","0.04236"
"24.55200","2.04618","0.04326"
"24.94800","2.07918","0.04459"
"25.34400","2.11219","0.04488"
"25.74000","2.14513","0.04559"
"26.13600","2.17819","0.04613"
"26.53200","2.21120","0.04714"
"26.92800","2.24420","0.04798"
"27.32400","2.27714","0.04872"
"27.72000","2.31021","0.04964"
"28.11600","2.34321","0.05018"
"28.51200","2.37616","0.05053"
"28.90800","2.40910","0.05126"
"29.30400","2.44222","0.05154"
"29.70000","2.47517","0.05187"
"30.09600","2.50817","0.05241"
"30.49200","2.54117","0.05269"
"30.88800","2.57424","0.05289"
"31.28400","2.60718","0.05337"
"31.68000","2.64013","0.05377"
"32.07600","2.67319","0.05425"
"32.47200","2.70619","0.05484"
"32.86800","2.73920","0.05537"
"33.26400","2.77208","0.05630"
"33.66000","2.80515","0.05721"
"34.05600","2.83821","0.05844"
"34.45200","2.87121","0.05984"
"34.84800","2.90410","0.02662"
"35.24400","2.93716","0.02467"
"35.64000","2.97022","0.01127"
"36.03600","3.00323","0.01251"
"36.43200","3.03611","0.01302"
"36.82800","3.06918","0.01424"
"37.22400","3.10224","0.01603"
"37.62000","3.13518","0.01615"
"38.01600","3.16813","0.01749"
"38.41200","3.20119","0.01725"
"38.80800","3.23419","0.01723"
"39.20400","3.26714","0.01660"
"39.60000","3.30020","0.01652"
"39.99600","3.33315","0.01698"
"40.39200","3.36621","0.01894"
"40.78800","3.39921","0.01893"
"41.18400","3.43216","0.02015"
"41.58000","3.46516","0.02101"
"41.97600","3.49817","0.02197"
"42.37200","3.53117","0.02355"
"42.76800","3.56417","0.02474"
"43.16400","3.59718","0.02652"
"43.56000","3.63018","0.02738"
"43.95600","3.66313","0.02794"
"44.35200","3.69625","-0.00727"
"44.74800","3.72919","-0.00339"
"45.14400","3.76214","-0.00236"
"45.54000","3.79520","-0.00139"
"45.93600","3.82826","-0.00009"
"46.33200","3.86121","0.00067"
"46.72800","3.89415","0.00140"
"47.12400","3.92722","0.00189"
"47.52000","3.96022","0.00303"
"47.91600","3.99322","0.00320"
"48.31200","4.02617","0.00366"
"48.70800","4.05923","0.00396"
"49.10400","4.09223","0.00424"
"49.50000","4.12518","0.00462"
"49.89600","4.15812","0.00530"
"50.29200","4.19119","0.00566"
"50.68800","4.22419","0.00595"
"51.08400","4.25719","0.00623"
"51.48000","4.29014","0.00664"
"51.87600","4.32320","-0.00558"
"52.27200","4.35627","-0.00566"
"52.66800","4.38915","-0.00421"
"53.06400","4.42215","-0.00238"
"53.46000","4.45516","-0.00140"
"53.85600","4.48828","-0.00106"
"54.25200","4.52116","0.00051"
"54.64800","4.55417","0.00078"
"55.04400","4.58717","0.00168"
"55.44000","4.62024","0.00241"
"55.83600","4.65318","0.00261"
"56.23200","4.68618","0.00342"
"56.62800","4.71919","0.00370"
"57.02400","4.75213","0.00374"
"57.42000","4.78520","0.00407"
"57.81600","4.81820","-0.00870"
"58.21200","4.85126","-0.01083"
"58.60800","4.88415","-0.01025"
"59.00400","4.91715","-0.00901"
"59.40000","4.95021","-0.00839"
"59.79600","4.98322","-0.00806"
"60.19200","5.01616","-0.00711"
"60.58800","5.04923","-0.00691"
"60.98400","5.08217","-0.00647"
"61.38000","5.11517","-0.00527"
"61.77600","5.14812","-0.00445"
"62.17200","5.18118","-0.00382"
"62.56800","5.21424","-0.00353"
"62.96400","5.24713","-0.00280"
"63.36000","5.28013","-0.00213"
"63.75600","5.31320","-0.02295"
"64.15200","5.34620","-0.02240"
"64.54800","5.37915","-0.02182"
"64.94400","5.41215","-0.02151"
"65.34000","5.44521","-0.02104"
"65.73600","5.47822","-0.02092"
"66.13200","5.51116","-0.02092"
"66.52800","5.54416","-0.02078"
"66.92400","5.57723","-0.02008"
"67.32000","5.61023","-0.02043"
"67.71600","5.64312","-0.01985"
"68.11200","5.67612","-0.01959"
"68.50800","5.70918","-0.01930"
"68.90400","5.74225","-0.02027"
"69.30000","5.77513","-0.01893"
"69.69600","5.80814","-0.01917"
"70.09200","5.84120","-0.01874"
"70.48800","5.87420","-0.01828"
"70.88400","5.90715","-0.01863"
"71.28000","5.94021","-0.01848"
"71.67600","5.97315","-0.01837"
"72.07200","6.00622","-0.01831"
"72.46800","6.03916","-0.01833"
"72.86400","6.07223","-0.01765"
"73.26000","6.10517","-0.01726"
"73.65600","6.13817","-0.01742"
"74.05200","6.17118","-0.01693"
"74.44800","6.20418","-0.01650"
"74.84400","6.23718","-0.01653"
"75.24000","6.27013","-0.01648"
"75.63600","6.30319","-0.01621"
"76.03200","6.33614","-0.01548"
"76.42800","6.36914","-0.01583"
"76.82400","6.40220","-0.01500"
"77.22000","6.43527","-0.01546"
"77.61600","6.46815","-0.01528"
"78.01200","6.50116","-0.01423"
"78.40800","6.53416","-0.01440"
"78.80400","6.56722","-0.01389"
"79.20000","6.60023","-0.01370"
"79.59600","6.63311","-0.01358"
"79.99200","6.66617","-0.01304"
"80.38800","6.69924","-0.01267"
"80.78400","6.73218","-0.01219"
"81.18000","6.76513","-0.01221"
"81.57600","6.79813","-0.01108"
"81.97200","6.83125","-0.01049"
"82.36800","6.86420","-0.01004"
"82.76400","6.89714","-0.01055"
"83.16000","6.93020","-0.00942"
"83.55600","6.96321","-0.00882"
"83.95200","6.99621","-0.00797"
"84.34800","7.02916","-0.00694"
"84.74400","7.06216","-0.00706"
"85.14000","7.09522","-0.00599"
"85.53600","7.12817","-0.00465"
"85.93200","7.16111","-0.00381"
"86.32800","7.19424","-0.00299"
"86.72400","7.22724","-0.00148"
"87.12000","7.26012","-0.00167"
"87.51600","7.29313","-0.00032"
"87.91200","7.32619","0.00041"
"88.30800","7.35919","0.00118"
"88.70400","7.39220","0.00195"
"89.10000","7.42514","0.00264"
"89.49600","7.45815","0.00338"
"89.89200","7.49115","0.00374"
"90.28800","7.52415","0.00434"
"90.68400","7.55722","0.00498"
"91.08000","7.59016","0.00522"
"91.47600","7.62317","0.00576"
"91.87200","7.65617","0.00630"
"92.26800","7.68917","-0.00863"
"92.66400","7.72218","-0.00434"
"93.06000","7.75518","-0.00346"
"93.45600","7.78819","-0.00210"
"93.85200","7.82125","-0.00101"
"94.24800","7.85419","-0.00469"
"94.64400","7.88720","-0.00441"
"95.04000","7.92020","-0.00313"
"95.43600","7.95320","-0.00745"
"95.83200","7.98621","-0.00579"
"96.22800","8.01915","-0.00516"
"96.62400","8.05221","-0.00325"
"97.02000","8.08522","-0.00307"
"97.41600","8.11816","-0.00240"
"97.81200","8.15111","-0.00069"
"98.20800","8.18423","0.00021"
"98.60400","8.21723","0.00069"
"99.00000","8.25012","0.00078"
"99.39600","8.28318","0.00210"
"99.79200","8.31619","0.00270"
"100.18800","8.34925","0.00336"
"100.58400","8.38219","0.00359"
"100.98000","8.41514","0.00415"
"101.37600","8.44820","0.00450"
"101.77200","8.48127","0.00520"
"102.16800","8.51415","0.00563"
"102.56400","8.54715","0.00607"
"102.96000","8.58022","0.00657"
"103.35600","8.61322","0.00692"
"103.75200","8.64610","0.00790"
"104.14800","8.67917","0.00771"
"104.54400","8.71217","0.00815"
"104.94000","8.74524","0.00919"
"105.33600","8.77818","0.00980"
"105.73200","8.81112","0.01088"
"106.12800","8.84419","0.01232"
"106.52400","8.87719","0.01365"
"106.92000","8.91020","-0.00872"
"107.31600","8.94320","-0.00849"
"107.71200","8.97620","-0.00537"
"108.10800","9.00921","-0.00394"
"108.50400","9.04221","-0.00448"
"108.90000","9.07521","-0.00164"
"109.29600","9.10822","-0.00010"
"109.69200","9.14116","-0.00124"
"110.08800","9.17423","-0.00055"
"110.48400","9.20717","0.00160"
"110.88000","9.24017","0.00183"
"111.27600","9.27312","0.00202"
"111.67200","9.30618","0.00322"
"112.06800","9.33918","0.00365"
"112.46400","9.37219","0.00376"
"112.86000","9.40513","0.00430"
"113.25600","9.43826","0.00568"
"113.65200","9.47126","0.00650"
"114.04800","9.50414","0.00615"
"114.44400","9.53721","0.00741"
"114.84000","9.57021","0.00906"
"115.23600","9.60322","0.01016"
"115.63200","9.63616","0.01072"
"116.02800","9.66916","0.00808"
"116.42400","9.70223","0.00952"
"116.82000","9.73523","0.01067"
"117.21600","9.76812","0.01191"
"117.61200","9.80118","0.01601"
"118.00800","9.83418","0.01854"
"118.40400","9.86719","0.02012"
"118.80000","9.90013","0.02323"
"119.19600","9.93319","0.02580"
"119.59200","9.96620","0.02842"
"119.98800","9.99920","0.02948"
"120.38400","10.03215","0.03060"
"120.78000","10.06521","0.03265"
"121.17600","10.09821","0.03426"
"121.57200","10.13116","0.00363"
"121.96800","10.16416","0.00174"
"122.36400","10.19722","0.00443"
"122.76000","10.23023","0.00571"
"123.15600","10.26317","0.00485"
"123.55200","10.29618","0.00461"
"123.94800","10.32924","0.00587"
"124.34400","10.36218","0.00707"
"124.74000","10.39519","0.00668"
"125.13600","10.42819","0.00709"
"125.53200","10.46114","0.00926"
"125.92800","10.49420","0.01066"
"126.32400","10.52714","0.01142"
"126.72000","10.56015","0.01241"
"127.11600","10.59321","0.01542"
"127.51200","10.62615","-0.01197"
"127.90800","10.65916","-0.01579"
"128.30400","10.69216","-0.01317"
"128.70000","10.72517","-0.01360"
"129.09600","10.75811","-0.01399"
"129.49200","10.79117","-0.01086"
"129.88800","10.82424","-0.01237"
"130.28400","10.85724","-0.01034"
"130.68000","10.89012","-0.00981"
"131.07600","10.92319","-0.01104"
"131.47200","10.95625","-0.00803"
"131.86800","10.98914","-0.00993"
"132.26400","11.02214","-0.00897"
"132.66000","11.05520","-0.00643"
"133.05600","11.08821","-0.00714"
"133.45200","11.12115","-0.00603"
"133.84800","11.15410","-0.00526"
"134.24400","11.18716","-0.00628"
"134.64000","11.22022","-0.00399"
"135.03600","11.25317","-0.00374"
"135.43200","11.28611","-0.00291"
"135.82800","11.31923","-0.00106"
"136.22400","11.35224","-0.00107"
"136.62000","11.38518","-0.00088"
"137.01600","11.41813","-0.00109"
"137.41200","11.45119","0.00011"
"137.80800","11.48419","0.00070"
"138.20400","11.51714","0.00194"
"138.60000","11.55014","0.00230"
"138.99600","11.58321","0.00305"
"139.39200","11.61621","0.00375"
"139.78800","11.64909","0.00390"
"140.18400","11.68216","0.00401"
"140.58000","11.71522","0.00495"
"140.97600","11.74816","0.00507"
"141.37200","11.78117","0.00569"
"141.76800","11.81423","0.00594"
"142.16400","11.84718","0.00670"
"142.56000","11.88012","0.00679"
"142.95600","11.91318","0.00800"
"143.35200","11.94619","0.00888"
"143.74800","11.97919","0.01046"
"144.14400","12.01214","0.01183"
"144.54000","12.04520","0.01338"
"144.93600","12.07820","0.01535"
"145.33200","12.11115","0.01740"
"145.72800","12.14415","0.01981"
"146.12400","12.17721","0.02108"
"146.52000","12.21022","0.02396"
"146.91600","12.24316","0.02615"
"147.31200","12.27617","0.02791"
"147.70800","12.30917","0.03018"
"148.10400","12.34223","0.03204"
"148.50000","12.37512","0.03385"
"148.89600","12.40818","0.01076"
"149.29200","12.44118","0.00938"
"149.68800","12.47425","0.01000"
"150.08400","12.50713","0.01264"
"150.48000","12.54014","0.01579"
"150.87600","12.57326","0.01862"
"151.27200","12.60620","0.02052"
"151.66800","12.63909","0.01995"
"152.06400","12.67215","0.01908"
"152.46000","12.70516","0.01829"
"152.85600","12.73822","0.02087"
"153.25200","12.77116","0.02320"
"153.64800","12.80411","0.02404"
"154.04400","12.83717","0.02634"
"154.44000","12.87017","0.02831"
"154.83600","12.90312","0.03030"
"155.23200","12.93624","0.03204"
"155.62800","12.96919","0.03103"
"156.02400","13.00219","0.03262"
"156.42000","13.03514","0.03494"
"156.81600","13.06820","0.03672"
"157.21200","13.10126","0.03951"
"157.60800","13.13421","0.04077"
"158.00400","13.16715","0.04215"
"158.40000","13.20021","0.04406"
"158.79600","13.23316","0.04576"
"159.19200","13.26616","0.04655"
"159.58800","13.29923","0.04668"
"159.98400","13.33217","0.04819"
"160.38000","13.36523","0.04898"
"160.77600","13.39818","0.05027"
"161.17200","13.43118","0.05113"
"161.56800","13.46424","0.05152"
"161.96400","13.49713","0.05210"
"162.36000","13.53013","0.05268"
"162.75600","13.56320","0.05317"
"163.15200","13.59620","0.05356"
"163.54800","13.62914","0.05400"
"163.94400","13.66215","0.05517"
"164.34000","13.69521","0.05617"
"164.73600","13.72822","0.05736"
"165.13200","13.76110","0.05910"
"165.52800","13.79416","0.06092"
"165.92400","13.82723","0.06317"
"166.32000","13.86017","0.06577"
"166.71600","13.89312","0.06807"
"167.11200","13.92618","0.07039"
"167.50800","13.95924","0.07411"
"167.90400","13.99219","0.07707"
"168.30000","14.02513","0.08095"
"168.69600","14.05819","0.08523"
"169.09200","14.09120","0.08861"
"169.48800","14.12420","0.09235"
"169.88400","14.15715","0.09692"
"170.28000","14.19021","0.10069"
"170.67600","14.22321","0.10395"
"171.07200","14.25622","0.10659"
"171.46800","14.28916","0.10890"
"171.86400","14.32216","0.11044"
"172.26000","14.35523","0.11213"
"172.65600","14.38817","0.11227"
"173.05200","14.42118","0.11214"
"173.44800","14.45418","0.11306"
"173.84400","14.48718","0.11401"
"174.24000","14.52013","0.11517"
"174.63600","14.55319","0.01390"
"175.03200","14.58619","-0.00624"
"175.42800","14.61914","-0.00520"
"175.82400","14.65214","-0.00694"
"176.22000","14.68521","-0.00403"
"176.61600","14.71815","-0.00053"
"177.01200","14.75115","-0.00153"
"177.40800","14.78416","-0.00181"
"177.80400","14.81722","0.00209"
"178.20000","14.85017","0.00191"
"178.59600","14.88317","0.00205"
"178.99200","14.91617","0.00376"
"179.38800","14.94918","0.00495"
"179.78400","14.98218","0.00478"
"180.18000","15.01518","0.00564"
"180.57600","15.04819","0.00717"
"180.97200","15.08125","0.00797"
"181.36800","15.11420","0.00822"
"181.76400","15.14714","0.00961"
"182.16000","15.18020","0.01289"
"182.55600","15.21321","0.01452"
"182.95200","15.24615","0.01683"
"183.34800","15.27916","0.01935"
"183.74400","15.31222","0.02306"
"184.14000","15.34522","0.02553"
"184.53600","15.37817","0.02629"
"184.93200","15.41117","0.02840"
"185.32800","15.44423","0.03110"
"185.72400","15.47724","0.03439"
"186.12000","15.51012","0.03552"
"186.51600","15.54313","0.03729"
"186.91200","15.57619","0.03846"
"187.30800","15.60919","0.04041"
"187.70400","15.64220","0.04229"
"188.10000","15.67514","0.04439"
"188.49600","15.70820","0.04570"
"188.89200","15.74115","0.01819"
"189.28800","15.77415","0.02093"
"189.68400","15.80722","0.02789"
"190.08000","15.84016","0.03239"
"190.47600","15.87322","0.03305"
"190.87200","15.90617","0.03601"
"191.26800","15.93923","0.03900"
"191.66400","15.97224","0.04254"
"192.06000","16.00518","0.04463"
"192.45600","16.03818","0.04585"
"192.85200","16.07119","0.04729"
"193.24800","16.10425","0.04874"
"193.64400","16.13713","0.05029"
"194.04000","16.17026","0.05153"
"194.43600","16.20320","0.05197"
"194.83200","16.23621","0.05238"
"195.22800","16.26915","0.05320"
"195.62400","16.30221","0.05373"
"196.02000","16.33522","0.05491"
"196.41600","16.36816","0.05610"
"196.81200","16.40117","0.05766"
"197.20800","16.43417","0.05892"
"197.60400","16.46723","0.06071"
"198.00000","16.50018","0.06239"
"198.39600","16.53312","0.06556"
"198.79200","16.56618","0.06154"
"199.18800","16.59925","0.06454"
"199.58400","16.63213","0.06770"
"199.98000","16.66514","0.07097"
"200.37600","16.69820","0.07354"
"200.77200","16.73114","0.07626"
"201.16800","16.76409","0.07924"
"201.56400","16.79715","0.08240"
"201.96000","16.83022","0.08634"
"202.35600","16.86316","0.09099"
"202.75200","16.89610","0.09130"
"203.14800","16.92917","0.09604"
"203.54400","16.96223","0.09861"
"203.94000","16.99517","0.10384"
"204.33600","17.02818","0.10682"
"204.73200","17.06118","0.10884"
"205.12800","17.09418","0.11085"
"205.52400","17.12719","0.11201"
"205.92000","17.16014","0.11315"
"206.31600","17.19320","0.11383"
"206.71200","17.22620","0.11510"
"207.10800","17.25915","0.11719"
"207.50400","17.29215","0.11947"
"207.90000","17.32521","0.12228"
"208.29600","17.35822","0.12556"
"208.69200","17.39116","0.12710"
"209.08800","17.42422","0.13013"
"209.48400","17.45723","0.13340"
"209.88000","17.49017","0.13640"
"210.27600","17.52312","0.13906"
"210.67200","17.55624","0.14234"
"211.06800","17.58918","0.14530"
"211.46400","17.62213","0.14805"
"211.86000","17.65513","0.15034"
"212.25600","17.68814","0.15238"
"212.65200","17.72120","0.15444"
"213.04800","17.75414","0.15608"
"213.44400","17.78715","0.15764"
"213.84000","17.82021","0.15910"
"214.23600","17.85321","0.16045"
"214.63200","17.88610","0.16198"
"215.02800","17.91916","0.16325"
"215.42400","17.95223","0.16473"
"215.82000","17.98523","0.16645"
"216.21600","18.01811","0.16855"
"216.61200","18.05118","0.16932"
"217.00800","18.08424","0.17229"
"217.40400","18.11719","0.17516"
"217.80000","18.15019","0.17768"
"218.19600","18.18319","0.17958"
"218.59200","18.21620","0.18177"
"218.98800","18.24920","0.18385"
"219.38400","18.28214","0.18424"
"219.78000","18.31521","0.18433"
"220.17600","18.34821","0.18653"
"220.57200","18.38116","0.18814"
"220.96800","18.41416","0.19144"
"221.36400","18.44722","0.02991"
"221.76000","18.48023","0.03679"
"222.15600","18.51317","0.04074"
"222.55200","18.54618","0.04376"
"222.94800","18.57918","0.04410"
"223.34400","18.61218","0.04510"
"223.74000","18.64513","0.04706"
"224.13600","18.67819","0.04896"
"224.53200","18.71113","0.04831"
"224.92800","18.74414","0.04565"
"225.32400","18.77714","0.04704"
"225.72000","18.81021","0.04716"
"226.11600","18.84321","0.04793"
"226.51200","18.87609","0.04815"
"226.90800","18.90916","0.04962"
"227.30400","18.94222","0.05074"
"227.70000","18.97516","0.03085"
"228.09600","19.00811","0.00727"
"228.49200","19.04117","0.00718"
"228.88800","19.07418","0.00904"
"229.28400","19.10718","0.01460"
"229.68000","19.14013","0.01353"
"230.07600","19.17319","0.01036"
"230.47200","19.20625","0.00169"
"230.86800","19.23920","0.00237"
"231.26400","19.27214","0.00479"
"231.66000","19.30514","0.00403"
"232.05600","19.33827","0.00433"
"232.45200","19.37121","0.00743"
"232.84800","19.40415","0.00622"
"233.24400","19.43722","0.00682"
"233.64000","19.47022","0.00897"
"234.03600","19.50317","0.00734"
"234.43200","19.53617","0.00829"
"234.82800","19.56917","0.01104"
"235.22400","19.60218","0.01044"
"235.62000","19.63512","0.01184"
"236.01600","19.66813","0.01669"
"236.41200","19.70125","0.01547"
"236.80800","19.73419","0.01853"
"237.20400","19.76714","0.02365"
"237.60000","19.80014","0.02532"
"237.99600","19.83321","0.02666"
"238.39200","19.86621","0.02897"
"238.78800","19.89921","0.03196"
"239.18400","19.93216","0.03335"
"239.58000","19.96522","0.03357"
"239.97600","19.99816","0.03530"
"240.37200","20.03111","0.03786"
"240.76800","20.06423","0.03816"
"241.16400","20.09718","0.03927"
"241.56000","20.13018","0.04172"
"241.95600","20.16318","0.04235"
"242.35200","20.19619","-0.00957"
"242.74800","20.22919","-0.01524"
"243.14400","20.26213","-0.01321"
"243.54000","20.29520","-0.01337"
"243.93600","20.32820","-0.01371"
"244.33200","20.36121","-0.01078"
"244.72800","20.39415","-0.01319"
"245.12400","20.42721","-0.01396"
"245.52000","20.46016","-0.01147"
"245.91600","20.49316","-0.01342"
"246.31200","20.52611","-0.01318"
"246.70800","20.55923","-0.01123"
"247.10400","20.59223","-0.01227"
"247.50000","20.62512","-0.01077"
"247.89600","20.65818","-0.00998"
"248.29200","20.69118","-0.01133"
"248.68800","20.72419","-0.01001"
"249.08400","20.75713","-0.00838"
"249.48000","20.79020","-0.01015"
"249.87600","20.82320","-0.00886"
"250.27200","20.85626","-0.00719"
"250.66800","20.88909","-0.00918"
"251.06400","20.92215","-0.00755"
"251.46000","20.95522","-0.00589"
"251.85600","20.98822","-0.00646"
"252.25200","21.02110","-0.00628"
"252.64800","21.05417","-0.00470"
"253.04400","21.08717","-0.00467"
"253.44000","21.12017","-0.00430"
"253.83600","21.15318","-0.00287"
"254.23200","21.18618","-0.00190"
"254.62800","21.21919","-0.00252"
"255.02400","21.25219","-0.00160"
"255.42000","21.28519","-0.00036"
"255.81600","21.31820","-0.00002"
"256.21200","21.35120","-0.00019"
"256.60800","21.38420","0.00096"
"257.00400","21.41715","0.00167"
"257.40000","21.45021","0.00180"
"257.79600","21.48322","0.00248"
"258.19200","21.51616","0.00324"
"258.58800","21.54922","0.00243"
"258.98400","21.58217","0.00126"
"259.38000","21.61517","0.00098"
"259.77600","21.64818","0.00182"
"260.17200","21.68124","0.00216"
"260.56800","21.71424","0.00260"
"260.96400","21.74718","0.00305"
"261.36000","21.78013","0.00372"
"261.75600","21.81325","0.00420"
"262.15200","21.84620","0.00369"
"262.54800","21.87914","0.00433"
"262.94400","21.91215","0.00477"
"263.34000","21.94521","0.00560"
"263.73600","21.97821","0.00577"
"264.13200","22.01110","0.00638"
"264.52800","22.04416","0.00663"
"264.92400","22.07722","0.00736"
"265.32000","22.11017","0.00794"
"265.71600","22.14311","0.00853"
"266.11200","22.17618","0.01018"
"266.50800","22.20924","0.01073"
"266.90400","22.24218","0.01094"
"267.30000","22.27513","0.01219"
"267.69600","22.30813","0.01372"
"268.09200","22.34126","0.01474"
"268.48800","22.37420","0.01466"
"268.88400","22.40714","0.00162"
"269.28000","22.44021","0.00311"
"269.67600","22.47327","0.00395"
"270.07200","22.50616","-0.02213"
"270.46800","22.53916","-0.02075"
"270.86400","22.57216","-0.02397"
"271.26000","22.60517","-0.02705"
"271.65600","22.63817","-0.02236"
"272.05200","22.67111","-0.02527"
"272.44800","22.70424","-0.02161"
"272.84400","22.73718","-0.02080"
"273.24000","22.77019","-0.02575"
"273.63600","22.80319","-0.02220"
"274.03200","22.83619","-0.02309"
"274.42800","22.86914","-0.02359"
"274.82400","22.90220","-0.01996"
"275.22000","22.93521","-0.02411"
"275.61600","22.96821","-0.02332"
"276.01200","23.00115","-0.02205"
"276.40800","23.03410","-0.02337"
"276.80400","23.06722","-0.02145"
"277.20000","23.10023","-0.02134"
"277.59600","23.13311","-0.02303"
"277.99200","23.16617","-0.02276"
"278.38800","23.19917","-0.02188"
"278.78400","23.23212","-0.02247"
"279.18000","23.26513","-0.02213"
"279.57600","23.29825","-0.02128"
"279.97200","23.33119","-0.02325"
"280.36800","23.36419","-0.02184"
"280.76400","23.39714","-0.02221"
"281.16000","23.43020","-0.02288"
"281.55600","23.46321","-0.02188"
"281.95200","23.49615","-0.02138"
"282.34800","23.52916","-0.02229"
"282.74400","23.56216","-0.02181"
"283.14000","23.59522","-0.02084"
"283.53600","23.62817","-0.02162"
"283.93200","23.66111","-0.02115"
"284.32800","23.69423","-0.02103"
"284.72400","23.72724","-0.02124"
"285.12000","23.76012","-0.02075"
"285.51600","23.79318","-0.02064"
"285.91200","23.82625","-0.02096"
"286.30800","23.85919","-0.02094"
"286.70400","23.89214","-0.02048"
"287.10000","23.92514","-0.02046"
"287.49600","23.95820","-0.02031"
"287.89200","23.99121","-0.02081"
"288.28800","24.02415","-0.02070"
"288.68400","24.05722","-0.02066"
"289.08000","24.09016","-0.02029"
"289.47600","24.12316","-0.02046"
"289.87200","24.15617","-0.02059"
"290.26800","24.18917","-0.02033"
"290.66400","24.22224","-0.02028"
"291.06000","24.25518","-0.02086"
"291.45600","24.28818","-0.01997"
"291.85200","24.32119","-0.02009"
"292.24800","24.35419","-0.01971"
"292.64400","24.38713","-0.02034"
"293.04000","24.42020","-0.01936"
"293.43600","24.45320","-0.01982"
"293.83200","24.48620","-0.01943"
"294.22800","24.51915","-0.01926"
"294.62400","24.55222","-0.01920"
"295.02000","24.58522","-0.01947"
"295.41600","24.61816","-0.01902"
"295.81200","24.65117","-0.01910"
"296.20800","24.68423","-0.01895"
"296.60400","24.71723","-0.01904"
"297.00000","24.75012","-0.01861"
"297.39600","24.78318","-0.01845"
"297.79200","24.81618","-0.01807"
"298.18800","24.84925","-0.01887"
"298.58400","24.88213","-0.01828"
"298.98000","24.91520","-0.01854"
"299.37600","24.94826","-0.01798"
"299.77200","24.98120","-0.01787"
"300.16800","25.01415","-0.01781"
"300.56400","25.04715","-0.01764"
"300.96000","25.08015","-0.01694"
"301.35600","25.11322","-0.01769"
"301.75200","25.14616","-0.01760"
"302.14800","25.17916","-0.01695"
"302.54400","25.21223","-0.01724"
"302.94000","25.24523","-0.01725"
"303.33600","25.27818","-0.01684"
"303.73200","25.31118","-0.01656"
"304.12800","25.34418","-0.01626"
"304.52400","25.37719","-0.01659"
"304.92000","25.41019","-0.01637"
"305.31600","25.44326","-0.01568"
"305.71200","25.47620","-0.01636"
"306.10800","25.50915","-0.01560"
"306.50400","25.54215","-0.01626"
"306.90000","25.57515","-0.01603"
"307.29600","25.60816","-0.01547"
"307.69200","25.64116","-0.01581"
"308.08800","25.67416","-0.01549"
"308.48400","25.70717","-0.01504"
"308.88000","25.74017","-0.01527"
"309.27600","25.77318","-0.01499"
"309.67200","25.80618","-0.01492"
"310.06800","25.83918","-0.01506"
"310.46400","25.87219","-0.01525"
"310.86000","25.90519","-0.01470"
"311.25600","25.93826","-0.01454"
"311.65200","25.97120","-0.01365"
"312.04800","26.00414","-0.01442"
"312.44400","26.03715","-0.01431"
"312.84000","26.07021","-0.01415"
"313.23600","26.10315","-0.01323"
"313.63200","26.13610","-0.01419"
"314.02800","26.16922","-0.01696"
"314.42400","26.20216","-0.01603"
"314.82000","26.23517","-0.01648"
"315.21600","26.26811","-0.01678"
"315.61200","26.30118","-0.01574"
"316.00800","26.33418","-0.01604"
"316.40400","26.36719","-0.01659"
"316.80000","26.40019","-0.01622"
"317.19600","26.43313","-0.01580"
"317.59200","26.46625","-0.01611"
"317.98800","26.49920","-0.01602"
"318.38400","26.53214","-0.01506"
"318.78000","26.56521","-0.01539"
"319.17600","26.59821","-0.01558"
"319.57200","26.63116","-0.01520"
"319.96800","26.66416","-0.01555"
"320.36400","26.69722","-0.01482"
"320.76000","26.73023","-0.01470"
"321.15600","26.76317","-0.01420"
"321.55200","26.79617","-0.01465"
"321.94800","26.82924","-0.01478"
"322.34400","26.86218","-0.01421"
"322.74000","26.89518","-0.01384"
"323.13600","26.92819","-0.01415"
"323.53200","26.96113","-0.01387"
"323.92800","26.99420","-0.01384"
"324.32400","27.02720","-0.01363"
"324.72000","27.06015","-0.01375"
"325.11600","27.09321","-0.01304"
"325.51200","27.12615","-0.01340"
"325.90800","27.15916","-0.01262"
"326.30400","27.19222","-0.01274"
"326.70000","27.22516","-0.01221"
"327.09600","27.25817","-0.01165"
"327.49200","27.29123","-0.01234"
"327.88800","27.32417","-0.01167"
"328.28400","27.35718","-0.01169"
"328.68000","27.39012","-0.01066"
"329.07600","27.42319","-0.01092"
"329.47200","27.45619","-0.01061"
"329.86800","27.48920","-0.01078"
"330.26400","27.52208","-0.01053"
"330.66000","27.55526","-0.01108"
"331.05600","27.58821","-0.01271"
"331.45200","27.62115","-0.01150"
"331.84800","27.65415","-0.01316"
"332.24400","27.68722","-0.01320"
"332.64000","27.72022","-0.01301"
"333.03600","27.75311","-0.01283"
"333.43200","27.78617","-0.01346"
"333.82800","27.81917","-0.01333"
"334.22400","27.85230","-0.01220"
"334.62000","27.88512","-0.01238"
"335.01600","27.91813","-0.01224"
"335.41200","27.95119","-0.01135"
"335.80800","27.98425","-0.01197"
"336.20400","28.01714","-0.01131"
"336.60000","28.05014","-0.01108"
"336.99600","28.08320","-0.01048"
"337.39200","28.11615","-0.01044"
"337.78800","28.14915","-0.01034"
"338.18400","28.18216","-0.00979"
"338.58000","28.21522","-0.00953"
"338.97600","28.24817","-0.00951"
"339.37200","28.28117","-0.00912"
"339.76800","28.31417","-0.00883"
"340.16400","28.34718","-0.00801"
"340.56000","28.38018","-0.00794"
"340.95600","28.41318","-0.00721"
"341.35200","28.44619","-0.00627"
"341.74800","28.47919","-0.00634"
"342.14400","28.51220","-0.00595"
"342.54000","28.54520","-0.00530"
"342.93600","28.57814","-0.00431"
"343.33200","28.61114","-0.00507"
"343.72800","28.64415","-0.00433"
"344.12400","28.67721","-0.00372"
"344.52000","28.71022","-0.00388"
"344.91600","28.74322","-0.00484"
"345.31200","28.77616","-0.00392"
"345.70800","28.80923","-0.00399"
"346.10400","28.84217","-0.00332"
"346.50000","28.87512","-0.00240"
"346.89600","28.90818","-0.00265"
"347.29200","28.94124","-0.00344"
"347.68800","28.97419","-0.00612"
"348.08400","29.00713","-0.00736"
"348.48000","29.04014","-0.00668"
"348.87600","29.07320","-0.00610"
"349.27200","29.10620","-0.00589"
"349.66800","29.13909","-0.00604"
"350.06400","29.17221","-0.00470"
"350.46000","29.20521","-0.00404"
"350.85600","29.23816","-0.00442"
"351.25200","29.27116","-0.00356"
"351.64800","29.30417","-0.00229"
"352.04400","29.33723","-0.00251"
"352.44000","29.37017","-0.00212"
"352.83600","29.40312","-0.00173"
"353.23200","29.43624","-0.00100"
"353.62800","29.46924","-0.00034"
"354.02400","29.50213","-0.00071"
"354.42000","29.53519","-0.00023"
"354.81600","29.56820","0.00004"
"355.21200","29.60126","0.00019"
"355.60800","29.63414","0.00058"
"356.00400","29.66715","0.00072"
"356.40000","29.70021","0.00063"
"356.79600","29.73322","0.00046"
"357.19200","29.76616","0.00066"
"357.58800","29.79922","0.00106"
"357.98400","29.83217","0.00071"
"358.38000","29.86517","0.00121"
"358.77600","29.89817","0.00199"
"359.17200","29.93118","0.00159"
"359.56800","29.96418","0.00215"
"359.96400","29.99713","0.00239"
"360.36000","30.03013","0.00276"
"360.75600","30.06319","0.00304"
"361.15200","30.09614","0.00335"
"361.54800","30.12914","0.00358"
"361.94400","30.16215","0.00365"
"362.34000","30.19521","0.00391"
"362.73600","30.22821","0.00421"
"363.13200","30.26116","0.00434"
"363.52800","30.29422","0.00481"
"363.92400","30.32729","0.00466"
"364.32000","30.36017","0.00509"
"364.71600","30.39311","0.00543"
"365.11200","30.42624","-0.01549"
"365.50800","30.45918","-0.01404"
"365.90400","30.49218","-0.00914"
"366.30000","30.52519","-0.01700"
"366.69600","30.55819","-0.01403"
"367.09200","30.59126","-0.00964"
"367.48800","30.62414","-0.01364"
"367.88400","30.65720","-0.01372"
"368.28000","30.69021","-0.01086"
"368.67600","30.72327","-0.00951"
"369.07200","30.75616","-0.01203"
"369.46800","30.78916","-0.01152"
"369.86400","30.82222","-0.00850"
"370.26000","30.85523","-0.00983"
"370.65600","30.88811","-0.00998"
"371.05200","30.92112","-0.00751"
"371.44800","30.95418","-0.00682"
"371.84400","30.98718","-0.00920"
"372.24000","31.02019","-0.00730"
"372.63600","31.05319","-0.00430"
"373.03200","31.08619","-0.00603"
"373.42800","31.11914","-0.00660"
"373.82400","31.15214","-0.00294"
"374.22000","31.18515","-0.00172"
"374.61600","31.21821","-0.00327"
"375.01200","31.25115","-0.00295"
"375.40800","31.28421","-0.00049"
"375.80400","31.31716","-0.00028"
"376.20000","31.35016","-0.00113"
"376.59600","31.38311","0.00009"
"376.99200","31.41623","0.00093"
"377.38800","31.44917","0.00095"
"377.78400","31.48218","-0.00054"
"378.18000","31.51512","-0.00133"
"378.57600","31.54819","-0.00008"
"378.97200","31.58125","-0.00003"
"379.36800","31.61413","0.00032"
"379.76400","31.64714","0.00115"
"380.16000","31.68020","0.00163"
"380.55600","31.71327","0.00184"
"380.95200","31.74615","0.00225"
"381.34800","31.77915","0.00237"
"381.74400","31.81222","0.00271"
"382.14000","31.84522","-0.00808"
"382.53600","31.87816","-0.00557"
"382.93200","31.91117","-0.02827"
"383.32800","31.94423","-0.05167"
"383.72400","31.97724","-0.00388"
"384.12000","32.01012","-0.04402"
"384.51600","32.04318","-0.00448"
"384.91200","32.07619","-0.02141"
"385.30800","32.10919","-0.03549"
"385.70400","32.14214","-0.03418"
"386.10000","32.17514","-0.03196"
"386.49600","32.20820","-0.02873"
"386.89200","32.24115","-0.02289"
"387.28800","32.27409","-0.01923"
"387.68400","32.30716","-0.02907"
"388.08000","32.34022","-0.01668"
"388.47600","32.37322","-0.02767"
"388.87200","32.40617","-0.02478"
"389.26800","32.43917","-0.02059"
"389.66400","32.47223","-0.02702"
"390.06000","32.50518","-0.02314"
"390.45600","32.53812","-0.01923"
"390.85200","32.57124","-0.02636"
"391.24800","32.60419","-0.02138"
"391.64400","32.63713","-0.02087"
"392.04000","32.67020","-0.02409"
"392.43600","32.70314","-0.02287"
"392.83200","32.73621","-0.02052"
"393.22800","32.76915","-0.02364"
"393.62400","32.80221","-0.02210"
"394.02000","32.83516","-0.02110"
"394.41600","32.86822","-0.02156"
"394.81200","32.90117","-0.02309"
"395.20800","32.93423","-0.02031"
"395.60400","32.96717","-0.02069"
"396.00000","33.00011","-0.02185"
"396.39600","33.03312","-0.02054"
"396.79200","33.06618","-0.02054"
"397.18800","33.09919","-0.02102"
"397.58400","33.13213","-0.02121"
"397.98000","33.16520","-0.01907"
"398.37600","33.19820","-0.01964"
"398.77200","33.23114","-0.02003"
"399.16800","33.26414","-0.01998"
"399.56400","33.29715","-0.01890"
"399.96000","33.33021","-0.01930"
"400.35600","33.36316","-0.01963"
"400.75200","33.39616","-0.01854"
"401.14800","33.42923","-0.01847"
"401.54400","33.46217","-0.01884"
"401.94000","33.49511","-0.01839"
"402.33600","33.52818","-0.01733"
"402.73200","33.56118","-0.01756"
"403.12800","33.59424","-0.01756"
"403.52400","33.62719","-0.01717"
"403.92000","33.66013","-0.01667"
"404.31600","33.69320","-0.01651"
"404.71200","33.72626","-0.01643"
"405.10800","33.75914","-0.01608"
"405.50400","33.79214","-0.01547"
"405.90000","33.82521","-0.01533"
"406.29600","33.85822","-0.01572"
"406.69200","33.89116","-0.01465"
"407.08800","33.92416","-0.01414"
"407.48400","33.95716","-0.01481"
"407.88000","33.99017","-0.01342"
"408.27600","34.02317","-0.01348"
"408.67200","34.05618","-0.01284"
"409.06800","34.08918","-0.01313"
"409.46400","34.12218","-0.01251"
"409.86000","34.15513","-0.01166"
"410.25600","34.18819","-0.01131"
"410.65200","34.22120","-0.01125"
"411.04800","34.25414","-0.01049"
"411.44400","34.28720","-0.01061"
"411.84000","34.32021","-0.00967"
"412.23600","34.35315","-0.00956"
"412.63200","34.38615","-0.00886"
"413.02800","34.41916","-0.00838"
"413.42400","34.45222","-0.00894"
"413.82000","34.48523","-0.00791"
"414.21600","34.51811","-0.00718"
"414.61200","34.55123","-0.00602"
"415.00800","34.58424","-0.00556"
"415.40400","34.61712","-0.00466"
"415.80000","34.65019","-0.00426"
"416.19600","34.68319","-0.00394"
"416.59200","34.71619","-0.00307"
"416.98800","34.74920","-0.00247"
"417.38400","34.78214","-0.00161"
"417.78000","34.81521","-0.00079"
"418.17600","34.84821","-0.00076"
"418.57200","34.88109","0.00027"
"418.96800","34.91422","0.00071"
"419.36400","34.94716","0.00120"
"419.76000","34.98022","0.00191"
"420.15600","35.01317","0.00241"
"420.55200","35.04611","0.00302"
"420.94800","35.07918","0.00329"
"421.34400","35.11218","0.00388"
"421.74000","35.14519","0.00367"
"422.13600","35.17819","0.00416"
"422.53200","35.21119","0.00460"
"422.92800","35.24414","0.00497"
"423.32400","35.27720","0.00547"
"423.72000","35.31020","0.00537"
"424.11600","35.34321","0.00590"
"424.51200","35.37621","0.00639"
"424.90800","35.40916","0.00632"
"425.30400","35.44222","0.00690"
"425.70000","35.47522","0.00652"
"426.09600","35.50817","0.00702"
"426.49200","35.54117","0.00745"
"426.88800","35.57418","0.00778"
"427.28400","35.60718","0.00821"
"427.68000","35.64012","0.00876"
"428.07600","35.67324","0.00905"
"428.47200","35.70619","0.01015"
"428.86800","35.73914","0.00930"
"429.26400","35.77214","0.00758"
"429.66000","35.80520","0.00793"
"430.05600","35.83821","0.01003"
"430.45200","35.87115","0.00961"
"430.84800","35.90416","0.01019"
"431.24400","35.93722","0.01162"
"431.64000","35.97022","0.01218"
"432.03600","36.00311","0.01114"
"432.43200","36.03617","0.01242"
"432.82800","36.06923","0.01466"
"433.22400","36.10218","0.01406"
"433.62000","36.13512","0.01484"
"434.01600","36.16818","0.01714"
"434.41200","36.20119","0.01787"
"434.80800","36.23419","0.01895"
"435.20400","36.26714","0.01972"
"435.60000","36.30020","0.02148"
"435.99600","36.33320","0.02227"
"436.39200","36.36621","0.02326"
"436.78800","36.39915","0.02488"
"437.18400","36.43221","0.02572"
"437.58000","36.46522","0.02678"
"437.97600","36.49816","0.02747"
"438.37200","36.53117","0.02793"
"438.76800","36.56417","0.02880"
"439.16400","36.59723","0.02892"
"439.56000","36.63012","0.02984"
"439.95600","36.66318","0.03072"
"440.35200","36.69619","0.03056"
"440.74800","36.72925","0.03157"
"441.14400","36.76213","0.03254"
"441.54000","36.79520","0.03305"
"441.93600","36.82820","0.03408"
"442.33200","36.86115","0.03493"
"442.72800","36.89415","0.03592"
"443.12400","36.92721","0.03696"
"443.52000","36.96016","0.03761"
"443.91600","36.99310","0.03843"
"444.31200","37.02617","0.03919"
"444.70800","37.05917","0.04032"
"445.10400","37.09217","0.04095"
"445.50000","37.12518","0.04158"
"445.89600","37.15818","0.04214"
"446.29200","37.19118","0.04270"
"446.68800","37.22419","0.04363"
"447.08400","37.25713","0.04410"
"447.48000","37.29019","0.04461"
"447.87600","37.32320","0.04515"
"448.27200","37.35620","0.04555"
"448.66800","37.38908","0.04532"
"449.06400","37.42221","0.04550"
"449.46000","37.45521","0.04625"
"449.85600","37.48816","0.04665"
"450.25200","37.52116","0.04690"
"450.64800","37.55422","0.04739"
"451.04400","37.58717","0.04763"
"451.44000","37.62017","0.04787"
"451.83600","37.65311","0.04845"
"452.23200","37.68618","0.04848"
"452.62800","37.71918","0.04974"
"453.02400","37.75213","0.04916"
"453.42000","37.78519","0.04959"
"453.81600","37.81819","0.04966"
"454.21200","37.85120","0.04987"
"454.60800","37.88414","0.04989"
"455.00400","37.91715","0.05034"
"455.40000","37.95021","0.05034"
"455.79600","37.98315","0.05084"
"456.19200","38.01616","0.05097"
"456.58800","38.04916","0.05132"
"456.98400","38.08217","0.05198"
"457.38000","38.11517","0.05208"
"457.77600","38.14817","0.05227"
"458.17200","38.18118","0.05284"
"458.56800","38.21424","0.05291"
"458.96400","38.24719","0.05321"
"459.36000","38.28019","0.05368"
"459.75600","38.31325","0.05364"
"460.15200","38.34620","0.05389"
"460.54800","38.37914","0.05450"
"460.94400","38.41220","0.05489"
"461.34000","38.44521","0.05526"
"461.73600","38.47821","0.05585"
"462.13200","38.51110","0.05699"
"462.52800","38.54416","0.05722"
"462.92400","38.57716","0.05754"
"463.32000","38.61017","0.05809"
"463.71600","38.64311","0.05805"
"464.11200","38.67618","0.05903"
"464.50800","38.70924","0.05973"
"464.90400","38.74218","0.06182"
"465.30000","38.77519","0.06341"
"465.69600","38.80819","0.05400"
"466.09200","38.84126","0.05382"
"466.48800","38.87414","0.05399"
"466.88400","38.90714","0.05457"
"467.28000","38.94020","0.05563"
"467.67600","38.97321","0.05653"
"468.07200","39.00610","0.05780"
"468.46800","39.03916","0.05990"
"468.86400","39.07222","0.06205"
"469.26000","39.10522","0.06420"
"469.65600","39.13811","0.06469"
"470.05200","39.17117","0.06575"
"470.44800","39.20418","0.06699"
"470.84400","39.23718","0.06842"
"471.24000","39.27018","0.07052"
"471.63600","39.30319","0.07288"
"472.03200","39.33625","0.07424"
"472.42800","39.36919","0.07605"
"472.82400","39.40214","0.07758"
"473.22000","39.43520","0.07908"
"473.61600","39.46821","0.07120"
"474.01200","39.50115","0.07173"
"474.40800","39.53416","0.07249"
"474.80400","39.56722","0.07311"
"475.20000","39.60022","0.07405"
"475.59600","39.63311","0.07639"
"475.99200","39.66623","0.07844"
"476.38800","39.69923","0.07920"
"476.78400","39.73218","0.08106"
"477.18000","39.76518","0.08346"
"477.57600","39.79818","0.08457"
"477.97200","39.83119","0.08595"
"478.36800","39.86419","0.08739"
"478.76400","39.89714","0.08939"
"479.16000","39.93020","0.09172"
"479.55600","39.96320","0.09420"
"479.95200","39.99615","0.09642"
"480.34800","40.02909","0.09780"
"480.74400","40.06221","0.10062"
"481.14000","40.09522","0.10114"
"481.53600","40.12816","0.10244"
"481.93200","40.16122","0.10370"
"482.32800","40.19423","0.10446"
"482.72400","40.22729","0.09877"
"483.12000","40.26012","0.03137"
"483.51600","40.29318","0.03555"
"483.91200","40.32619","0.03000"
"484.30800","40.35919","0.02928"
"484.70400","40.39214","0.04295"
"485.10000","40.42514","0.04496"
"485.49600","40.45820","0.04065"
"485.89200","40.49120","0.03845"
"486.28800","40.52415","0.04223"
"486.68400","40.55721","0.04780"
"487.08000","40.59022","0.04927"
"487.47600","40.62316","0.04841"
"487.87200","40.65617","0.04882"
"488.26800","40.68917","0.04958"
"488.66400","40.72223","0.05033"
"489.06000","40.75518","0.05129"
"489.45600","40.78812","0.05236"
"489.85200","40.82118","0.05313"
"490.24800","40.85419","0.05337"
"490.64400","40.88713","0.05338"
"491.04000","40.92019","0.05341"
"491.43600","40.95320","0.05387"
"491.83200","40.98620","0.05461"
"492.22800","41.01915","0.05532"
"492.62400","41.05221","0.05576"
"493.02000","41.08515","0.05636"
"493.41600","41.11816","0.05762"
"493.81200","41.15116","0.05798"
"494.20800","41.18422","0.05910"
"494.60400","41.21723","0.06016"
"495.00000","41.25017","0.06207"
"495.39600","41.28318","0.06374"
"495.79200","41.31624","0.06500"
"496.18800","41.34919","0.06600"
"496.58400","41.38213","0.06824"
"496.98000","41.41519","0.06957"
"497.37600","41.44825","0.07127"
"497.77200","41.48114","0.07284"
"498.16800","41.51415","0.07480"
"498.56400","41.54715","0.07602"
"498.96000","41.58015","0.07807"
"499.35600","41.61316","0.07966"
"499.75200","41.64610","0.08082"
"500.14800","41.67916","0.08244"
"500.54400","41.71223","0.08321"
"500.94000","41.74517","0.08412"
"501.33600","41.77812","0.08684"
"501.73200","41.81118","0.08813"
"502.12800","41.84418","0.08892"
"502.52400","41.87713","0.09062"
"502.92000","41.91013","0.09295"
"503.31600","41.94320","0.09456"
"503.71200","41.97620","0.09599"
"504.10800","42.00914","0.09885"
"504.50400","42.04214","0.10130"
"504.90000","42.07515","0.10220"
"505.29600","42.10815","0.10396"
"505.69200","42.14116","0.10449"
"506.08800","42.17416","0.10524"
"506.48400","42.20723","0.10698"
"506.88000","42.24017","0.10799"
"507.27600","42.27317","0.10877"
"507.67200","42.30618","0.11002"
"508.06800","42.33918","0.11078"
"508.46400","42.37218","0.11161"
"508.86000","42.40519","0.11230"
"509.25600","42.43819","0.11270"
"509.65200","42.47120","0.11293"
"510.04800","42.50414","0.11293"
"510.44400","42.53720","0.11319"
"510.84000","42.57020","0.11350"
"511.23600","42.60315","0.11406"
"511.63200","42.63610","0.11484"
"512.02800","42.66922","0.11487"
"512.42400","42.70216","0.11540"
"512.82000","42.73517","0.11640"
"513.21600","42.76811","0.11692"
"513.61200","42.80124","0.11821"
"514.00800","42.83418","0.12004"
"514.40400","42.86718","0.12199"
"514.80000","42.90013","0.12329"
"515.19600","42.93319","0.12510"
"515.59200","42.96619","0.12673"
"515.98800","42.99920","0.12827"
"516.38400","43.03220","0.12967"
"516.78000","43.06514","0.13167"
"517.17600","43.09827","0.13241"
"517.57200","43.13110","0.13383"
"517.96800","43.16422","0.13540"
"518.36400","43.19722","0.13743"
"518.76000","43.23022","0.13867"
"519.15600","43.26317","0.14058"
"519.55200","43.29617","0.14229"
"519.94800","43.32917","0.14376"
"520.34400","43.36218","0.14512"
"520.74000","43.39518","0.14697"
"521.13600","43.42818","0.14796"
"521.53200","43.46113","0.14939"
"521.92800","43.49419","0.15076"
"522.32400","43.52720","0.15199"
"522.72000","43.56014","0.15303"
"523.11600","43.59320","0.15406"
"523.51200","43.62615","0.15518"
"523.90800","43.65915","0.15612"
"524.30400","43.69216","0.15690"
"524.70000","43.72516","0.15768"
"525.09600","43.75810","0.15839"
"525.49200","43.79123","0.15889"
"525.88800","43.82417","0.01898"
"526.28400","43.85718","0.03984"
"526.68000","43.89012","0.01954"
"527.07600","43.92318","0.01504"
"527.47200","43.95619","0.04098"
"527.86800","43.98913","0.03322"
"528.26400","44.02220","0.02545"
"528.66000","44.05520","0.04085"
"529.05600","44.08820","0.03959"
"529.45200","44.12115","0.03518"
"529.84800","44.15415","0.04411"
"530.24400","44.18722","0.04730"
"530.64000","44.22022","0.04183"
"531.03600","44.25316","0.04547"
"531.43200","44.28617","0.05133"
"531.82800","44.31923","0.04976"
"532.22400","44.35223","0.04873"
"532.62000","44.38512","0.05168"
"533.01600","44.41812","0.05308"
"533.41200","44.45125","0.05249"
"533.80800","44.48419","0.05278"
"534.20400","44.51713","0.05467"
"534.60000","44.55019","0.05577"
"534.99600","44.58320","0.05517"
"535.39200","44.61620","0.05611"
"535.78800","44.64915","0.05928"
"536.18400","44.68222","0.06268"
"536.58000","44.71522","0.06261"
"536.97600","44.74816","0.06331"
"537.37200","44.78116","0.06812"
"537.76800","44.81417","0.07318"
"538.16400","44.84717","0.04013"
"538.56000","44.88018","-0.01119"
"538.95600","44.91318","-0.03007"
"539.35200","44.94619","-0.00901"
"539.74800","44.97919","-0.02490"
"540.14400","45.01213","-0.00521"
"540.54000","45.04520","-0.03010"
"540.93600","45.07820","-0.00746"
"541.33200","45.11115","-0.02061"
"541.72800","45.14421","-0.00788"
"542.12400","45.17715","-0.02590"
"542.52000","45.21022","-0.01901"
"542.91600","45.24322","-0.01311"
"543.31200","45.27617","-0.01574"
"543.70800","45.30922","-0.01754"
"544.10400","45.34222","-0.02267"
"544.50000","45.37511","-0.01185"
"544.89600","45.40818","-0.01527"
"545.29200","45.44124","-0.01815"
"545.68800","45.47413","-0.01847"
"546.08400","45.50713","-0.01541"
"546.48000","45.54019","-0.01132"
"546.87600","45.57319","-0.01590"
"547.27200","45.60620","-0.01794"
"547.66800","45.63909","-0.01571"
"548.06400","45.67221","-0.01310"
"548.46000","45.70522","-0.01186"
"548.85600","45.73815","-0.01457"
"549.25200","45.77116","-0.01727"
"549.64800","45.80416","-0.01392"
"550.04400","45.83722","-0.01062"
"550.44000","45.87017","-0.01173"
"550.83600","45.90312","-0.01318"
"551.23200","45.93618","-0.01507"
"551.62800","45.96925","-0.01220"
"552.02400","46.00212","-0.01068"
"552.42000","46.03513","-0.00928"
"552.81600","46.06819","-0.01083"
"553.21200","46.10125","-0.01299"
"553.60800","46.13414","-0.01166"
"554.00400","46.16714","-0.01020"
"554.40000","46.20021","-0.00806"
"554.79600","46.23322","-0.00812"
"555.19200","46.26616","-0.00916"
"555.58800","46.29922","-0.01018"
"555.98400","46.33216","-0.00926"
"556.38000","46.36523","-0.00826"
"556.77600","46.39817","-0.00589"
"557.17200","46.43118","-0.00489"
"557.56800","46.46418","-0.00611"
"557.96400","46.49718","-0.00559"
"558.36000","46.53019","-0.00778"
"558.75600","46.56319","-0.00709"
"559.15200","46.59620","-0.00366"
"559.54800","46.62914","-0.00347"
"559.94400","46.66220","-0.00139"
"560.34000","46.69521","-0.00259"
"560.73600","46.72821","-0.00385"
"561.13200","46.76110","-0.00314"
"561.52800","46.79422","-0.00266"
"561.92400","46.82722","-0.00193"
"562.32000","46.86011","-0.00080"
"562.71600","46.89311","-0.00024"
"563.11200","46.92617","0.00031"
"563.50800","46.95918","0.00165"
"563.90400","46.99212","0.00063"
"564.30000","47.02512","0.00109"
"564.69600","47.05819","0.00085"
"565.09200","47.09119","0.00118"
"565.48800","47.12408","0.00109"
"565.88400","47.15714","0.00163"
"566.28000","47.19020","0.00257"
"566.67600","47.22321","0.00220"
"567.07200","47.25609","0.00158"
"567.46800","47.28915","-0.00024"
"567.86400","47.32216","-0.00359"
"568.26000","47.35522","-0.00131"
"568.65600","47.38811","-0.00231"
"569.05200","47.42117","-0.00294"
"569.44800","47.45418","-0.00179"
"569.84400","47.48718","-0.00195"
"570.24000","47.52012","-0.00053"
"570.63600","47.55318","-0.00021"
"571.03200","47.58619","-0.00002"
"571.42800","47.61919","-0.00002"
"571.82400","47.65214","-0.00055"
"572.22000","47.68520","0.00007"
"572.61600","47.71821","-0.00054"
"573.01200","47.75115","0.00052"
"573.40800","47.78415","0.00072"
"573.80400","47.81715","0.00080"
"574.20000","47.85016","0.00205"
"574.59600","47.88317","0.00159"
"574.99200","47.91617","0.00263"
"575.38800","47.94917","0.00208"
"575.78400","47.98218","0.00229"
"576.18000","48.01512","0.00245"
"576.57600","48.04818","0.00256"
"576.97200","48.08118","0.00285"
"577.36800","48.11413","0.00262"
"577.76400","48.14708","0.00297"
"578.16000","48.18026","0.00277"
"578.55600","48.21321","0.00389"
"578.95200","48.24615","0.00331"
"579.34800","48.27921","0.00420"
"579.74400","48.31221","0.00372"
"580.14000","48.34516","0.00413"
"580.53600","48.37811","0.00392"
"580.93200","48.41117","0.00388"
"581.32800","48.44423","0.00407"
"581.72400","48.47717","0.00401"
"582.12000","48.51012","0.00467"
"582.51600","48.54318","0.00442"
"582.91200","48.57618","0.00448"
"583.30800","48.60919","0.00451"
"583.70400","48.64220","0.00498"
"584.10000","48.67514","0.00496"
"584.49600","48.70820","0.00506"
"584.89200","48.74121","0.00490"
"585.28800","48.77409","0.00547"
"585.68400","48.80721","0.00553"
"586.08000","48.84027","0.00561"
"586.47600","48.87317","0.00510"
"586.87200","48.90617","0.00628"
"587.26800","48.93923","0.00586"
"587.66400","48.97223","0.00599"
"588.06000","49.00517","0.00597"
"588.45600","49.03818","0.00669"
"588.85200","49.07118","0.00618"
"588.96600","49.08069","0.00620"