File: Force_trajectories/170108_1/Specimen_RawData_4.csv
End date,"1/8/2017"
Specimen label,"11AT_86"
Maximum Load,"0.17094",N

Time,Extension,Load
(s),(mm),(N)
"0.00000","0.00000","-0.00013"
"0.17400","0.01112","0.00055"
"0.34800","0.02888","-0.00001"
"0.52200","0.04365","-0.00027"
"0.69600","0.05818","-0.00009"
"0.87000","0.07264","0.00031"
"1.04400","0.08711","0.00009"
"1.21800","0.10170","0.00035"
"1.39200","0.11611","-0.00005"
"1.56600","0.13052","0.00028"
"1.74000","0.14517","0.00029"
"1.91400","0.15970","0.00052"
"2.08800","0.17405","0.00027"
"2.26200","0.18864","0.00058"
"2.43600","0.20311","0.00035"
"2.61000","0.21757","-0.00010"
"2.78400","0.23216","0.00098"
"2.95800","0.24663","0.00040"
"3.13200","0.26110","0.00049"
"3.30600","0.27557","0.00097"
"3.48000","0.29016","0.00096"
"3.65400","0.30457","0.00082"
"3.82800","0.31910","0.00079"
"4.00200","0.33363","0.00096"
"4.17600","0.34809","0.00055"
"4.35000","0.36262","0.00058"
"4.52400","0.37715","0.00094"
"4.69800","0.39156","0.00054"
"4.87200","0.40603","0.00099"
"5.04600","0.42062","0.00108"
"5.22000","0.43509","0.00123"
"5.39400","0.44956","0.00108"
"5.56800","0.46409","0.00115"
"5.74200","0.47862","0.00114"
"5.91600","0.49308","0.00093"
"6.09000","0.50767","0.00040"
"6.26400","0.52208","0.00094"
"6.43800","0.53655","0.00112"
"6.61200","0.55114","0.00135"
"6.78600","0.56567","0.00082"
"6.96000","0.58008","0.00145"
"7.13400","0.59467","0.00133"
"7.30800","0.60914","0.00111"
"7.48200","0.62354","0.00123"
"7.65600","0.63813","0.00082"
"7.83000","0.65260","0.00182"
"8.00400","0.66707","0.00142"
"8.17800","0.68160","0.00117"
"8.35200","0.69613","0.00119"
"8.52600","0.71060","0.00127"
"8.70000","0.72513","0.00141"
"8.87400","0.73960","0.00144"
"9.04800","0.75407","0.00127"
"9.22200","0.76865","0.00130"
"9.39600","0.78312","0.00166"
"9.57000","0.79759","0.00146"
"9.74400","0.81212","0.00115"
"9.91800","0.82665","0.00163"
"10.09200","0.84112","0.00119"
"10.26600","0.85559","0.00139"
"10.44000","0.87012","0.00147"
"10.61400","0.88459","0.00193"
"10.78800","0.89912","0.00175"
"10.96200","0.91370","0.00191"
"11.13600","0.92811","0.00181"
"11.31000","0.94258","0.00177"
"11.48400","0.95717","0.00194"
"11.65800","0.97164","0.00139"
"11.83200","0.98611","0.00221"
"12.00600","1.00064","0.00191"
"12.18000","1.01511","0.00227"
"12.35400","1.02958","0.00189"
"12.52800","1.04416","0.00147"
"12.70200","1.05863","0.00182"
"12.87600","1.07304","0.00190"
"13.05000","1.08763","0.00191"
"13.22400","1.10216","0.00188"
"13.39800","1.11657","0.00201"
"13.57200","1.13110","0.00206"
"13.74600","1.14563","0.00261"
"13.92000","1.16004","0.00195"
"14.09400","1.17463","0.00260"
"14.26800","1.18915","0.00224"
"14.44200","1.20356","0.00176"
"14.61600","1.21809","0.00221"
"14.79000","1.23262","0.00275"
"14.96400","1.24715","0.00257"
"15.13800","1.26162","0.00292"
"15.31200","1.27615","0.00233"
"15.48600","1.29062","0.00224"
"15.66000","1.30509","0.00246"
"15.83400","1.31961","0.00262"
"16.00800","1.33408","0.00303"
"16.18200","1.34861","0.00247"
"16.35600","1.36308","0.00263"
"16.53000","1.37761","0.00301"
"16.70400","1.39208","0.00251"
"16.87800","1.40661","0.00280"
"17.05200","1.42114","0.00256"
"17.22600","1.43561","0.00233"
"17.40000","1.45014","0.00220"
"17.57400","1.46466","0.00297"
"17.74800","1.47907","0.00271"
"17.92200","1.49360","0.00309"
"18.09600","1.50813","0.00265"
"18.27000","1.52260","0.00268"
"18.44400","1.53719","0.00331"
"18.61800","1.55160","0.00289"
"18.79200","1.56601","0.00310"
"18.96600","1.58066","0.00298"
"19.14000","1.59513","0.00287"
"19.31400","1.60953","0.00286"
"19.48800","1.62418","0.00301"
"19.66200","1.63865","0.00314"
"19.83600","1.65306","0.00310"
"20.01000","1.66771","0.00338"
"20.18400","1.68212","0.00341"
"20.35800","1.69659","0.00340"
"20.53200","1.71112","0.00328"
"20.70600","1.72565","0.00339"
"20.88000","1.74005","0.00303"
"21.05400","1.75458","0.00359"
"21.22800","1.76917","0.00299"
"21.40200","1.78358","0.00395"
"21.57600","1.79811","0.00349"
"21.75000","1.81264","0.00355"
"21.92400","1.82711","0.00270"
"22.09800","1.84158","0.00267"
"22.27200","1.85617","0.00299"
"22.44600","1.87064","0.00306"
"22.62000","1.88510","0.00293"
"22.79400","1.89957","0.00368"
"22.96800","1.91410","0.00316"
"23.14200","1.92857","0.00317"
"23.31600","1.94316","0.00298"
"23.49000","1.95763","0.00340"
"23.66400","1.97204","0.00372"
"23.83800","1.98663","0.00353"
"24.01200","2.00116","0.00370"
"24.18600","2.01556","0.00318"
"24.36000","2.03009","0.00348"
"24.53400","2.04462","0.00360"
"24.70800","2.05909","0.00361"
"24.88200","2.07368","0.00386"
"25.05600","2.08815","0.00357"
"25.23000","2.10250","0.00364"
"25.40400","2.11709","0.00391"
"25.57800","2.13162","0.00366"
"25.75200","2.14609","0.00432"
"25.92600","2.16061","0.00380"
"26.10000","2.17514","0.00414"
"26.27400","2.18955","0.00433"
"26.44800","2.20414","0.00398"
"26.62200","2.21867","0.00334"
"26.79600","2.23308","0.00306"
"26.97000","2.24761","0.00368"
"27.14400","2.26214","0.00385"
"27.31800","2.27661","0.00352"
"27.49200","2.29114","0.00369"
"27.66600","2.30560","0.00375"
"27.84000","2.32007","0.00356"
"28.01400","2.33460","0.00367"
"28.18800","2.34913","0.00379"
"28.36200","2.36360","0.00431"
"28.53600","2.37813","0.00381"
"28.71000","2.39266","0.00399"
"28.88400","2.40713","0.00383"
"29.05800","2.42160","0.00439"
"29.23200","2.43618","0.00413"
"29.40600","2.45059","0.00442"
"29.58000","2.46506","0.00400"
"29.75400","2.47965","0.00426"
"29.92800","2.49418","0.00459"
"30.10200","2.50853","0.00321"
"30.27600","2.52312","0.00446"
"30.45000","2.53765","0.00440"
"30.62400","2.55212","0.00406"
"30.79800","2.56664","0.00451"
"30.97200","2.58117","0.00518"
"31.14600","2.59558","0.00438"
"31.32000","2.61017","0.00449"
"31.49400","2.62464","0.00427"
"31.66800","2.63905","0.00465"
"31.84200","2.65364","0.00399"
"32.01600","2.66811","0.00430"
"32.19000","2.68258","0.00452"
"32.36400","2.69711","0.00437"
"32.53800","2.71169","0.00457"
"32.71200","2.72610","0.00427"
"32.88600","2.74063","0.00445"
"33.06000","2.75516","0.00375"
"33.23400","2.76963","0.00413"
"33.40800","2.78410","0.00413"
"33.58200","2.79857","0.00401"
"33.75600","2.81304","0.00458"
"33.93000","2.82763","0.00443"
"34.10400","2.84210","0.00448"
"34.27800","2.85650","0.00443"
"34.45200","2.87109","0.00432"
"34.62600","2.88568","0.00279"
"34.80000","2.90009","0.00224"
"34.97400","2.91456","0.00281"
"35.14800","2.92909","0.00242"
"35.32200","2.94362","0.00298"
"35.49600","2.95809","0.00277"
"35.67000","2.97262","0.00273"
"35.84400","2.98714","0.00283"
"36.01800","3.00155","0.00284"
"36.19200","3.01614","0.00284"
"36.36600","3.03061","0.00368"
"36.54000","3.04508","0.00298"
"36.71400","3.05967","0.00355"
"36.88800","3.07408","0.00329"
"37.06200","3.08861","0.00320"
"37.23600","3.10314","0.00347"
"37.41000","3.11767","0.00373"
"37.58400","3.13213","0.00349"
"37.75800","3.14666","0.00342"
"37.93200","3.16119","0.00330"
"38.10600","3.17554","0.00341"
"38.28000","3.19007","0.00354"
"38.45400","3.20460","0.00355"
"38.62800","3.21907","0.00410"
"38.80200","3.23366","0.00363"
"38.97600","3.24813","0.00361"
"39.15000","3.26260","0.00429"
"39.32400","3.27706","0.00411"
"39.49800","3.29165","0.00411"
"39.67200","3.30612","0.00395"
"39.84600","3.32059","0.00394"
"40.02000","3.33512","0.00429"
"40.19400","3.34959","0.00389"
"40.36800","3.36412","0.00333"
"40.54200","3.37871","0.00347"
"40.71600","3.39312","0.00364"
"40.89000","3.40753","0.00352"
"41.06400","3.42217","0.00369"
"41.23800","3.43664","0.00370"
"41.41200","3.45111","0.00404"
"41.58600","3.46564","0.00384"
"41.76000","3.48011","0.00344"
"41.93400","3.49464","0.00224"
"42.10800","3.50923","0.00257"
"42.28200","3.52358","0.00305"
"42.45600","3.53805","0.00305"
"42.63000","3.55263","0.00314"
"42.80400","3.56716","0.00313"
"42.97800","3.58163","0.00341"
"43.15200","3.59610","0.00331"
"43.32600","3.61063","0.00352"
"43.50000","3.62504","0.00321"
"43.67400","3.63963","0.00325"
"43.84800","3.65416","0.00394"
"44.02200","3.66863","0.00347"
"44.19600","3.68315","0.00413"
"44.37000","3.69762","0.00403"
"44.54400","3.71209","0.00360"
"44.71800","3.72662","0.00333"
"44.89200","3.74109","0.00387"
"45.06600","3.75562","0.00421"
"45.24000","3.77009","0.00451"
"45.41400","3.78468","0.00460"
"45.58800","3.79909","0.00424"
"45.76200","3.81356","0.00382"
"45.93600","3.82814","0.00426"
"46.11000","3.84261","0.00477"
"46.28400","3.85714","0.00407"
"46.45800","3.87161","0.00458"
"46.63200","3.88608","0.00460"
"46.80600","3.90055","0.00494"
"46.98000","3.91514","0.00489"
"47.15400","3.92961","0.00501"
"47.32800","3.94408","0.00525"
"47.50200","3.95861","0.00555"
"47.67600","3.97313","0.00578"
"47.85000","3.98760","0.00542"
"48.02400","4.00213","0.00579"
"48.19800","4.01666","0.00540"
"48.37200","4.03107","0.00479"
"48.54600","4.04566","0.00486"
"48.72000","4.06013","0.00507"
"48.89400","4.07460","0.00491"
"49.06800","4.08913","0.00551"
"49.24200","4.10359","0.00528"
"49.41600","4.11806","0.00567"
"49.59000","4.13259","0.00594"
"49.76400","4.14712","0.00630"
"49.93800","4.16159","0.00640"
"50.11200","4.17612","0.00608"
"50.28600","4.19065","0.00568"
"50.46000","4.20512","0.00622"
"50.63400","4.21959","0.00650"
"50.80800","4.23412","0.00689"
"50.98200","4.24864","0.00702"
"51.15600","4.26311","0.00662"
"51.33000","4.27758","0.00682"
"51.50400","4.29205","0.00709"
"51.67800","4.30658","0.00667"
"51.85200","4.32117","0.00699"
"52.02600","4.33564","0.00724"
"52.20000","4.35011","0.00758"
"52.37400","4.36458","0.00775"
"52.54800","4.37916","0.00746"
"52.72200","4.39357","0.00734"
"52.89600","4.40816","0.00854"
"53.07000","4.42257","0.00815"
"53.24400","4.43704","0.00803"
"53.41800","4.45163","0.00823"
"53.59200","4.46616","0.00846"
"53.76600","4.48057","0.00896"
"53.94000","4.49510","0.00895"
"54.11400","4.50963","0.00874"
"54.28800","4.52409","0.00913"
"54.46200","4.53868","0.00916"
"54.63600","4.55315","0.00960"
"54.81000","4.56756","0.00995"
"54.98400","4.58215","0.01041"
"55.15800","4.59668","0.01020"
"55.33200","4.61109","0.01043"
"55.50600","4.62556","0.01136"
"55.68000","4.64015","0.01062"
"55.85400","4.65462","0.01091"
"56.02800","4.66914","0.01134"
"56.20200","4.68361","0.01071"
"56.37600","4.69808","0.01066"
"56.55000","4.71261","0.01049"
"56.72400","4.72714","0.01120"
"56.89800","4.74161","0.01170"
"57.07200","4.75614","0.01168"
"57.24600","4.77061","0.01267"
"57.42000","4.78508","0.01179"
"57.59400","4.79960","0.00957"
"57.76800","4.81413","0.01014"
"57.94200","4.82860","0.01040"
"58.11600","4.84301","0.01102"
"58.29000","4.85766","0.01093"
"58.46400","4.87219","0.01145"
"58.63800","4.88660","0.01211"
"58.81200","4.90113","0.01134"
"58.98600","4.91560","0.01115"
"59.16000","4.93007","0.01177"
"59.33400","4.94465","0.01193"
"59.50800","4.95906","0.01189"
"59.68200","4.97353","0.01265"
"59.85600","4.98812","0.01250"
"60.03000","5.00265","0.01146"
"60.20400","5.01712","0.01162"
"60.37800","5.03165","0.01206"
"60.55200","5.04612","0.01177"
"60.72600","5.06053","0.01265"
"60.90000","5.07511","0.01272"
"61.07400","5.08964","0.01320"
"61.24800","5.10411","0.01344"
"61.42200","5.11864","0.01318"
"61.59600","5.13317","0.01430"
"61.77000","5.14758","0.01378"
"61.94400","5.16211","0.01437"
"62.11800","5.17664","0.01481"
"62.29200","5.19111","0.01457"
"62.46600","5.20564","0.01525"
"62.64000","5.22016","0.01547"
"62.81400","5.23463","0.01549"
"62.98800","5.24910","0.01629"
"63.16200","5.26363","0.01626"
"63.33600","5.27816","0.01651"
"63.51000","5.29263","0.01647"
"63.68400","5.30710","0.01652"
"63.85800","5.32157","0.01680"
"64.03200","5.33610","0.01701"
"64.20600","5.35063","0.01751"
"64.38000","5.36515","0.01749"
"64.55400","5.37962","0.01804"
"64.72800","5.39415","0.01831"
"64.90200","5.40862","0.01906"
"65.07600","5.42309","0.01939"
"65.25000","5.43762","0.01949"
"65.42400","5.45209","0.01978"
"65.59800","5.46656","0.02001"
"65.77200","5.48115","0.02012"
"65.94600","5.49567","0.02074"
"66.12000","5.51008","0.02085"
"66.29400","5.52461","0.02149"
"66.46800","5.53914","0.02211"
"66.64200","5.55361","0.02243"
"66.81600","5.56808","0.02229"
"66.99000","5.58261","0.02360"
"67.16400","5.59708","0.02338"
"67.33800","5.61167","0.02372"
"67.51200","5.62614","0.02365"
"67.68600","5.64060","0.02424"
"67.86000","5.65513","0.02500"
"68.03400","5.66960","0.02542"
"68.20800","5.68407","0.02544"
"68.38200","5.69860","0.02601"
"68.55600","5.71313","0.02670"
"68.73000","5.72760","0.02739"
"68.90400","5.74213","0.02726"
"69.07800","5.75666","0.02798"
"69.25200","5.77112","0.02824"
"69.42600","5.78553","0.02949"
"69.60000","5.80012","0.02928"
"69.77400","5.81465","0.02972"
"69.94800","5.82912","0.03016"
"70.12200","5.84365","0.03032"
"70.29600","5.85806","0.03092"
"70.47000","5.87253","0.03146"
"70.64400","5.88718","0.03169"
"70.81800","5.90170","0.03188"
"70.99200","5.91599","0.03236"
"71.16600","5.93064","0.03242"
"71.34000","5.94517","0.03273"
"71.51400","5.95958","0.03302"
"71.68800","5.97417","0.02706"
"71.86200","5.98864","0.02715"
"72.03600","6.00311","0.02606"
"72.21000","6.01758","0.02781"
"72.38400","6.03211","0.02833"
"72.55800","6.04658","0.02827"
"72.73200","6.06110","0.02830"
"72.90600","6.07569","0.02953"
"73.08000","6.09010","0.02978"
"73.25400","6.10463","0.02987"
"73.42800","6.11916","0.03049"
"73.60200","6.13357","0.03074"
"73.77600","6.14810","0.03145"
"73.95000","6.16263","0.03167"
"74.12400","6.17716","0.03176"
"74.29800","6.19157","0.03190"
"74.47200","6.20609","0.03230"
"74.64600","6.22062","0.03245"
"74.82000","6.23509","0.03278"
"74.99400","6.24962","0.03307"
"75.16800","6.26409","0.03341"
"75.34200","6.27856","0.03350"
"75.51600","6.29315","0.03374"
"75.69000","6.30768","0.03390"
"75.86400","6.32209","0.03419"
"76.03800","6.33667","0.03432"
"76.21200","6.35114","0.03465"
"76.38600","6.36561","0.03462"
"76.56000","6.38014","0.03502"
"76.73400","6.39461","0.03502"
"76.90800","6.40902","0.03529"
"77.08200","6.42361","0.03541"
"77.25600","6.43814","0.03560"
"77.43000","6.45261","0.03561"
"77.60400","6.46713","0.03588"
"77.77800","6.48160","0.03612"
"77.95200","6.49607","0.03626"
"78.12600","6.51066","0.03637"
"78.30000","6.52513","0.03677"
"78.47400","6.53954","0.03691"
"78.64800","6.55413","0.03677"
"78.82200","6.56866","0.03726"
"78.99600","6.58307","0.03803"
"79.17000","6.59760","0.03768"
"79.34400","6.61212","0.03838"
"79.51800","6.62659","0.03805"
"79.69200","6.64112","0.03869"
"79.86600","6.65559","0.03863"
"80.04000","6.67012","0.03909"
"80.21400","6.68459","0.03955"
"80.38800","6.69918","0.04019"
"80.56200","6.71365","0.04113"
"80.73600","6.72806","0.04095"
"80.91000","6.74259","0.04204"
"81.08400","6.75705","0.04268"
"81.25800","6.77158","0.04266"
"81.43200","6.78617","0.04373"
"81.60600","6.80064","0.04440"
"81.78000","6.81505","0.04555"
"81.95400","6.82964","0.04603"
"82.12800","6.84417","0.04732"
"82.30200","6.85858","0.04697"
"82.47600","6.87311","0.04870"
"82.65000","6.88764","0.04913"
"82.82400","6.90204","0.04990"
"82.99800","6.91663","0.05021"
"83.17200","6.93116","0.05114"
"83.34600","6.94551","0.05205"
"83.52000","6.96016","0.05294"
"83.69400","6.97463","0.05377"
"83.86800","6.98910","0.05475"
"84.04200","7.00363","0.05537"
"84.21600","7.01810","0.05643"
"84.39000","7.03262","0.05785"
"84.56400","7.04715","0.05775"
"84.73800","7.06168","0.05881"
"84.91200","7.07609","0.05878"
"85.08600","7.09062","0.05969"
"85.26000","7.10515","0.06051"
"85.43400","7.11956","0.06080"
"85.60800","7.13409","0.06092"
"85.78200","7.14862","0.06098"
"85.95600","7.16309","0.06041"
"86.13000","7.17761","0.06125"
"86.30400","7.19214","0.06175"
"86.47800","7.20655","0.06178"
"86.65200","7.22108","0.06301"
"86.82600","7.23561","0.06359"
"87.00000","7.25014","0.06425"
"87.17400","7.26461","0.06483"
"87.34800","7.27914","0.06516"
"87.52200","7.29361","0.06648"
"87.69600","7.30801","0.06759"
"87.87000","7.32266","0.06742"
"88.04400","7.33719","0.06845"
"88.21800","7.35154","0.06859"
"88.39200","7.36613","0.06949"
"88.56600","7.38066","0.06995"
"88.74000","7.39507","0.07054"
"88.91400","7.40966","0.07124"
"89.08800","7.42413","0.07183"
"89.26200","7.43859","0.07203"
"89.43600","7.45306","0.07219"
"89.61000","7.46765","0.07098"
"89.78400","7.48206","0.07162"
"89.95800","7.49659","0.07175"
"90.13200","7.51118","0.07200"
"90.30600","7.52559","0.07282"
"90.48000","7.54012","0.07366"
"90.65400","7.55465","0.07391"
"90.82800","7.56906","0.07437"
"91.00200","7.58359","0.07472"
"91.17600","7.59817","0.07508"
"91.35000","7.61258","0.07601"
"91.52400","7.62711","0.07645"
"91.69800","7.64164","0.07685"
"91.87200","7.65611","0.07729"
"92.04600","7.67064","0.07753"
"92.22000","7.68511","0.07838"
"92.39400","7.69964","0.07885"
"92.56800","7.71405","0.07919"
"92.74200","7.72863","0.08030"
"92.91600","7.74310","0.08009"
"93.09000","7.75757","0.08042"
"93.26400","7.77216","0.08088"
"93.43800","7.78663","0.08133"
"93.61200","7.80110","0.08163"
"93.78600","7.81563","0.08197"
"93.96000","7.83010","0.08204"
"94.13400","7.84451","0.08220"
"94.30800","7.85915","0.07776"
"94.48200","7.87362","0.03891"
"94.65600","7.88809","0.03793"
"94.83000","7.90262","0.03874"
"95.00400","7.91715","0.03830"
"95.17800","7.93162","0.04046"
"95.35200","7.94615","0.04238"
"95.52600","7.96062","0.04134"
"95.70000","7.97509","0.04419"
"95.87400","7.98962","0.04527"
"96.04800","8.00414","0.04519"
"96.22200","8.01861","0.04977"
"96.39600","8.03314","0.04883"
"96.57000","8.04767","0.04968"
"96.74400","8.06208","0.05314"
"96.91800","8.07661","0.05232"
"97.09200","8.09114","0.05500"
"97.26600","8.10561","0.05838"
"97.44000","8.12008","0.05744"
"97.61400","8.13466","0.06060"
"97.78800","8.14913","0.06173"
"97.96200","8.16360","0.06136"
"98.13600","8.17813","0.06313"
"98.31000","8.19254","0.06326"
"98.48400","8.20707","0.06337"
"98.65800","8.22166","0.06490"
"98.83200","8.23613","0.06484"
"99.00600","8.25054","0.06702"
"99.18000","8.26513","0.06791"
"99.35400","8.27965","0.06804"
"99.52800","8.29406","0.07077"
"99.70200","8.30859","0.07126"
"99.87600","8.32312","0.07220"
"100.05000","8.33759","0.07442"
"100.22400","8.35212","0.07431"
"100.39800","8.36659","0.07626"
"100.57200","8.38106","0.07674"
"100.74600","8.39565","0.07667"
"100.92000","8.41012","0.07811"
"101.09400","8.42458","0.07817"
"101.26800","8.43911","0.07910"
"101.44200","8.45364","0.07984"
"101.61600","8.46811","0.08016"
"101.79000","8.48258","0.08092"
"101.96400","8.49717","0.08153"
"102.13800","8.51158","0.08165"
"102.31200","8.52605","0.08240"
"102.48600","8.54058","0.08229"
"102.66000","8.55505","0.08170"
"102.83400","8.56963","0.08230"
"103.00800","8.58410","0.08220"
"103.18200","8.59857","0.08294"
"103.35600","8.61316","0.08311"
"103.53000","8.62763","0.08355"
"103.70400","8.64210","0.08389"
"103.87800","8.65657","0.08399"
"104.05200","8.67110","0.08480"
"104.22600","8.68563","0.08491"
"104.40000","8.70009","0.08599"
"104.57400","8.71468","0.08671"
"104.74800","8.72915","0.08675"
"104.92200","8.74356","0.08870"
"105.09600","8.75815","0.08916"
"105.27000","8.77262","0.09071"
"105.44400","8.78703","0.09149"
"105.61800","8.80168","0.09224"
"105.79200","8.81615","0.09507"
"105.96600","8.83056","0.09589"
"106.14000","8.84514","0.09834"
"106.31400","8.85967","0.09995"
"106.48800","8.87408","0.10181"
"106.66200","8.88867","0.10581"
"106.83600","8.90314","0.10601"
"107.01000","8.91755","0.11072"
"107.18400","8.93214","0.11220"
"107.35800","8.94667","0.11413"
"107.53200","8.96114","0.11735"
"107.70600","8.97561","0.11845"
"107.88000","8.99013","0.12256"
"108.05400","9.00460","0.12392"
"108.22800","9.01907","0.12713"
"108.40200","9.03366","0.12982"
"108.57600","9.04807","0.13182"
"108.75000","9.06260","0.13576"
"108.92400","9.07713","0.13542"
"109.09800","9.09166","0.13770"
"109.27200","9.10613","0.13909"
"109.44600","9.12065","0.13948"
"109.62000","9.13512","0.14079"
"109.79400","9.14959","0.14136"
"109.96800","9.16418","0.14256"
"110.14200","9.17865","0.14271"
"110.31600","9.19306","0.14352"
"110.49000","9.20759","0.14377"
"110.66400","9.22212","0.14425"
"110.83800","9.23659","0.14462"
"111.01200","9.25111","0.14493"
"111.18600","9.26558","0.14629"
"111.36000","9.27999","0.14645"
"111.53400","9.29470","0.14845"
"111.70800","9.30911","0.15011"
"111.88200","9.32358","0.15207"
"112.05600","9.33811","0.15389"
"112.23000","9.35258","0.15397"
"112.40400","9.36705","0.15199"
"112.57800","9.38163","0.15116"
"112.75200","9.39616","0.15263"
"112.92600","9.41051","0.15340"
"113.10000","9.42516","0.15611"
"113.27400","9.43963","0.15686"
"113.44800","9.45404","0.15832"
"113.62200","9.46863","0.16013"
"113.79600","9.48316","0.16131"
"113.97000","9.49763","0.16385"
"114.14400","9.51216","0.16403"
"114.31800","9.52663","0.16619"
"114.49200","9.54109","0.16732"
"114.66600","9.55556","0.16903"
"114.84000","9.57015","0.17025"
"115.01400","9.58462","0.16973"
"115.18800","9.59903","0.01555"
"115.36200","9.61362","0.01830"
"115.53600","9.62809","0.03381"
"115.71000","9.64262","0.01269"
"115.88400","9.65715","0.01514"
"116.05800","9.67161","0.02300"
"116.23200","9.68608","0.01668"
"116.40600","9.70061","0.01676"
"116.58000","9.71514","0.02211"
"116.75400","9.72961","0.02473"
"116.92800","9.74414","0.02444"
"117.10200","9.75861","0.02723"
"117.27600","9.77308","0.03289"
"117.45000","9.78761","0.02656"
"117.62400","9.80213","0.02932"
"117.79800","9.81654","0.03441"
"117.97200","9.83113","0.02536"
"118.14600","9.84560","0.03221"
"118.32000","9.86007","0.03562"
"118.49400","9.87460","0.02827"
"118.66800","9.88913","0.03544"
"118.84200","9.90360","0.03595"
"119.01600","9.91813","0.03248"
"119.19000","9.93266","0.03856"
"119.36400","9.94707","0.03557"
"119.53800","9.96159","0.03534"
"119.71200","9.97612","0.04071"
"119.88600","9.99059","0.03648"
"120.06000","10.00506","0.03843"
"120.23400","10.01965","0.04128"
"120.40800","10.03412","0.03917"
"120.58200","10.04865","0.04194"
"120.75600","10.06312","0.04489"
"120.93000","10.07759","0.04594"
"121.10400","10.09212","0.04511"
"121.27800","10.10664","0.05182"
"121.45200","10.12111","0.04785"
"121.62600","10.13558","0.05139"
"121.80000","10.15011","0.05676"
"121.97400","10.16458","0.05116"
"122.14800","10.17911","0.06033"
"122.32200","10.19370","0.05791"
"122.49600","10.20811","0.05864"
"122.67000","10.22252","0.06404"
"122.84400","10.23716","0.06089"
"123.01800","10.25163","0.06508"
"123.19200","10.26610","0.06691"
"123.36600","10.28063","0.06611"
"123.54000","10.29510","0.06887"
"123.71400","10.30957","0.07042"
"123.88800","10.32416","0.06976"
"124.06200","10.33863","0.07352"
"124.23600","10.35304","0.07334"
"124.41000","10.36757","0.07381"
"124.58400","10.38215","0.07661"
"124.75800","10.39656","0.07536"
"124.93200","10.41115","0.07830"
"125.10600","10.42568","0.07833"
"125.28000","10.44009","0.07847"
"125.45400","10.45462","0.08058"
"125.62800","10.46915","0.08017"
"125.80200","10.48362","0.08115"
"125.97600","10.49809","0.08153"
"126.15000","10.51261","0.08145"
"126.32400","10.52714","0.08255"
"126.49800","10.54161","0.08279"
"126.67200","10.55614","0.08321"
"126.84600","10.57061","0.08379"
"127.02000","10.58508","0.08368"
"127.19400","10.59967","0.08450"
"127.36800","10.61414","0.08478"
"127.54200","10.62855","0.08517"
"127.71600","10.64314","0.08698"
"127.89000","10.65760","0.08681"
"128.06400","10.67207","0.08913"
"128.23800","10.68666","0.08990"
"128.41200","10.70107","0.08966"
"128.58600","10.71554","0.09293"
"128.76000","10.73019","0.09223"
"128.93400","10.74460","0.09679"
"129.10800","10.75907","0.09687"
"129.28200","10.77366","0.10003"
"129.45600","10.78813","0.10293"
"129.63000","10.80253","0.10151"
"129.80400","10.81712","0.10552"
"129.97800","10.83165","0.10599"
"130.15200","10.84606","0.10852"
"130.32600","10.86065","0.11081"
"130.50000","10.87512","0.10939"
"130.67400","10.88959","0.11202"
"130.84800","10.90412","0.10758"
"131.02200","10.91858","0.02700"
"131.19600","10.93311","0.02082"
"131.37000","10.94764","0.02541"
"131.54400","10.96217","0.00733"
"131.71800","10.97658","0.00963"
"131.89200","10.99111","0.02869"
"132.06600","11.00570","0.01242"
"132.24000","11.02011","0.00934"
"132.41400","11.03458","0.02177"
"132.58800","11.04910","0.02149"
"132.76200","11.06357","0.01054"
"132.93600","11.07810","0.01744"
"133.11000","11.09263","0.02486"
"133.28400","11.10710","0.01345"
"133.45800","11.12163","0.01767"
"133.63200","11.13616","0.02627"
"133.80600","11.15063","0.01699"
"133.98000","11.16504","0.01885"
"134.15400","11.17957","0.02776"
"134.32800","11.19410","0.02086"
"134.50200","11.20856","0.02221"
"134.67600","11.22315","0.02985"
"134.85000","11.23762","0.02442"
"135.02400","11.25203","0.02622"
"135.19800","11.26668","0.03121"
"135.37200","11.28115","0.02794"
"135.54600","11.29556","0.02941"
"135.72000","11.31009","0.03217"
"135.89400","11.32456","0.03038"
"136.06800","11.33909","0.03237"
"136.24200","11.35367","0.03333"
"136.41600","11.36814","0.03258"
"136.59000","11.38261","0.03412"
"136.76400","11.39714","0.03487"
"136.93800","11.41161","0.03453"
"137.11200","11.42608","0.03521"
"137.28600","11.44061","0.03538"
"137.46000","11.45514","0.01643"
"137.63400","11.46961","0.01252"
"137.80800","11.48413","0.01480"
"137.98200","11.49860","0.00915"
"138.15600","11.51313","0.01037"
"138.33000","11.52760","0.01074"
"138.50400","11.54213","0.01371"
"138.67800","11.55666","0.01389"
"138.85200","11.57113","0.01107"
"139.02600","11.58560","0.01071"
"139.20000","11.60007","0.01421"
"139.37400","11.61459","0.01580"
"139.54800","11.62918","0.01131"
"139.72200","11.64359","0.01336"
"139.89600","11.65806","0.01477"
"140.07000","11.67265","0.01559"
"140.24400","11.68718","0.01469"
"140.41800","11.70153","0.01476"
"140.59200","11.71618","0.01485"
"140.76600","11.73059","0.01774"
"140.94000","11.74506","0.01588"
"141.11400","11.75964","0.01440"
"141.28800","11.77417","0.01754"
"141.46200","11.78858","0.01883"
"141.63600","11.80305","0.01676"
"141.81000","11.81764","0.01757"
"141.98400","11.83205","0.01832"
"142.15800","11.84658","0.01913"
"142.33200","11.86117","0.01944"
"142.50600","11.87558","0.01889"
"142.68000","11.89017","0.01879"
"142.85400","11.90469","0.02244"
"143.02800","11.91910","0.02002"
"143.20200","11.93363","0.01922"
"143.37600","11.94816","0.02209"
"143.55000","11.96263","0.02201"
"143.72400","11.97710","0.02117"
"143.89800","11.99157","0.02363"
"144.07200","12.00616","0.02323"
"144.24600","12.02063","0.02402"
"144.42000","12.03510","0.02455"
"144.59400","12.04962","0.02427"
"144.76800","12.06409","0.02589"
"144.94200","12.07862","0.02713"
"145.11600","12.09315","0.02543"
"145.29000","12.10762","0.02731"
"145.46400","12.12215","0.02868"
"145.63800","12.13656","0.02596"
"145.81200","12.15109","0.02882"
"145.98600","12.16562","0.03020"
"146.16000","12.18014","0.02927"
"146.33400","12.19461","0.03131"
"146.50800","12.20908","0.03195"
"146.68200","12.22361","0.03145"
"146.85600","12.23808","0.03234"
"147.03000","12.25267","0.03264"
"147.20400","12.26714","0.03323"
"147.37800","12.28155","0.03383"
"147.55200","12.29620","0.03353"
"147.72600","12.31066","0.03394"
"147.90000","12.32507","0.03459"
"148.07400","12.33966","0.03407"
"148.24800","12.35419","0.03508"
"148.42200","12.36860","0.03527"
"148.59600","12.38313","0.03490"
"148.77000","12.39760","0.03581"
"148.94400","12.41213","0.03611"
"149.11800","12.42660","0.03582"
"149.29200","12.44118","0.03686"
"149.46600","12.45560","0.03693"
"149.64000","12.47007","0.03672"
"149.81400","12.48465","0.03778"
"149.98800","12.49906","0.03753"
"150.16200","12.51359","0.03800"
"150.33600","12.52812","0.03945"
"150.51000","12.54259","0.03932"
"150.68400","12.55706","0.03980"
"150.85800","12.57165","0.04125"
"151.03200","12.58617","0.04157"
"151.20600","12.60058","0.04285"
"151.38000","12.61511","0.04274"
"151.55400","12.62964","0.04349"
"151.72800","12.64411","0.04497"
"151.90200","12.65864","0.04555"
"152.07600","12.67311","0.04696"
"152.25000","12.68752","0.04803"
"152.42400","12.70217","0.04620"
"152.59800","12.71664","0.04794"
"152.77200","12.73110","0.04839"
"152.94600","12.74563","0.04971"
"153.12000","12.76010","0.05246"
"153.29400","12.77457","0.05206"
"153.46800","12.78910","0.05340"
"153.64200","12.80369","0.05485"
"153.81600","12.81810","0.05453"
"153.99000","12.83263","0.05734"
"154.16400","12.84716","0.05731"
"154.33800","12.86157","0.05798"
"154.51200","12.87609","0.05917"
"154.68600","12.89056","0.05928"
"154.86000","12.90509","0.06054"
"155.03400","12.91962","0.06172"
"155.20800","12.93409","0.06217"
"155.38200","12.94856","0.06375"
"155.55600","12.96309","0.06431"
"155.73000","12.97768","0.06512"
"155.90400","12.99215","0.06698"
"156.07800","13.00661","0.06648"
"156.25200","13.02108","0.06843"
"156.42600","13.03555","0.06861"
"156.60000","13.05008","0.06855"
"156.77400","13.06461","0.07111"
"156.94800","13.07914","0.07062"
"157.12200","13.09355","0.07209"
"157.29600","13.10814","0.07276"
"157.47000","13.12261","0.07298"
"157.64400","13.13708","0.07438"
"157.81800","13.15172","0.07460"
"157.99200","13.16613","0.07517"
"158.16600","13.18060","0.07652"
"158.34000","13.19519","0.07634"
"158.51400","13.20960","0.07781"
"158.68800","13.22407","0.07820"
"158.86200","13.23860","0.07844"
"159.03600","13.25319","0.07928"
"159.21000","13.26754","0.07934"
"159.38400","13.28213","0.08013"
"159.55800","13.29665","0.08024"
"159.73200","13.31106","0.08064"
"159.90600","13.32565","0.08121"
"160.08000","13.34012","0.08138"
"160.25400","13.35459","0.08173"
"160.42800","13.36912","0.08193"
"160.60200","13.38365","0.08243"
"160.77600","13.39812","0.08252"
"160.95000","13.41259","0.08244"
"161.12400","13.42718","0.08330"
"161.29800","13.44164","0.08356"
"161.47200","13.45611","0.08374"
"161.64600","13.47064","0.08409"
"161.82000","13.48511","0.08432"
"161.99400","13.49958","0.08465"
"162.16800","13.51417","0.08509"
"162.34200","13.52864","0.08514"
"162.51600","13.54311","0.08579"
"162.69000","13.55764","0.08656"
"162.86400","13.57204","0.08684"
"163.03800","13.58657","0.08786"
"163.21200","13.60122","0.08902"
"163.38600","13.61557","0.09004"
"163.56000","13.63004","0.09037"
"163.73400","13.64457","0.09243"
"163.90800","13.65916","0.09338"
"164.08200","13.67357","0.09441"
"164.25600","13.68816","0.08995"
"164.43000","13.70262","0.09047"
"164.60400","13.71704","0.08996"
"164.77800","13.73168","0.09106"
"164.95200","13.74615","0.09003"
"165.12600","13.76056","0.00956"
"165.30000","13.77515","0.00243"
"165.47400","13.78962","0.00393"
"165.64800","13.80403","0.00413"
"165.82200","13.81862","0.00438"
"165.99600","13.83309","-0.00039"
"166.17000","13.84756","0.00089"
"166.34400","13.86208","0.00045"
"166.51800","13.87667","0.00064"
"166.69200","13.89108","0.00256"
"166.86600","13.90555","0.00273"
"167.04000","13.92008","0.00017"
"167.21400","13.93461","0.00731"
"167.38800","13.94914","0.00092"
"167.56200","13.96361","0.00057"
"167.73600","13.97808","0.00338"
"167.91000","13.99254","0.00103"
"168.08400","14.00719","0.00085"
"168.25800","14.02160","0.00030"
"168.43200","14.03607","0.00249"
"168.60600","14.05060","0.00162"
"168.78000","14.06513","0.00055"
"168.95400","14.07954","0.00056"
"169.12800","14.09413","0.00038"
"169.30200","14.10866","0.00095"
"169.47600","14.12300","0.00139"
"169.65000","14.13771","0.00561"
"169.82400","14.15218","0.00137"
"169.99800","14.16653","0.00017"
"170.17200","14.18112","0.00172"
"170.34600","14.19559","0.00090"
"170.52000","14.21012","0.00080"
"170.69400","14.22465","0.00117"
"170.86800","14.23918","0.00258"
"171.04200","14.25359","0.00050"
"171.21600","14.26811","0.00019"
"171.39000","14.28264","0.00136"
"171.56400","14.29711","0.00091"
"171.73800","14.31158","0.00073"
"171.91200","14.32611","0.00425"
"172.08600","14.34058","0.00403"
"172.26000","14.35511","0.00028"
"172.43400","14.36964","0.00102"
"172.60800","14.38405","0.00196"
"172.78200","14.39863","0.00046"
"172.95600","14.41310","0.00057"
"173.13000","14.42763","0.00374"
"173.30400","14.44210","0.00137"
"173.47800","14.45663","0.00050"
"173.65200","14.47110","0.00291"
"173.82600","14.48563","0.00184"
"174.00000","14.50016","0.00090"
"174.17400","14.51463","0.00324"
"174.34800","14.52904","0.00401"
"174.52200","14.54363","0.00103"
"174.69600","14.55809","0.00176"
"174.87000","14.57256","0.00313"
"175.04400","14.58715","0.00109"
"175.21800","14.60162","0.00092"
"175.39200","14.61609","0.00497"
"175.56600","14.63062","0.00254"
"175.74000","14.64509","0.00026"
"175.91400","14.65950","0.00230"
"176.08800","14.67415","0.00177"
"176.26200","14.68867","0.00102"
"176.43600","14.70308","0.00449"
"176.61000","14.71761","0.00418"
"176.78400","14.73214","0.00184"
"176.95800","14.74661","0.00246"
"177.13200","14.76108","0.00304"
"177.30600","14.77567","0.00127"
"177.48000","14.79008","0.00398"
"177.65400","14.80461","0.00531"
"177.82800","14.81913","0.00239"
"178.00200","14.83355","0.00220"
"178.17600","14.84813","0.00342"
"178.35000","14.86266","0.00223"
"178.52400","14.87713","0.00422"
"178.69800","14.89160","0.00619"
"178.87200","14.90607","0.00343"
"179.04600","14.92054","0.00243"
"179.22000","14.93507","0.00417"
"179.39400","14.94966","0.00312"
"179.56800","14.96418","0.00486"
"179.74200","14.97859","0.00676"
"179.91600","14.99312","0.00431"
"180.09000","15.00759","0.00352"
"180.26400","15.02206","0.00396"
"180.43800","15.03665","0.00374"
"180.61200","15.05112","0.00700"
"180.78600","15.06559","0.00661"
"180.96000","15.08012","0.00452"
"181.13400","15.09465","0.00394"
"181.30800","15.10912","0.00443"
"181.48200","15.12364","0.00547"
"181.65600","15.13811","0.00769"
"181.83000","15.15252","0.00697"
"182.00400","15.16717","0.00522"
"182.17800","15.18164","0.00508"
"182.35200","15.19611","0.00559"
"182.52600","15.21064","0.00801"
"182.70000","15.22517","0.00897"
"182.87400","15.23964","0.00776"
"183.04800","15.25410","0.00608"
"183.22200","15.26863","0.00695"
"183.39600","15.28304","0.00776"
"183.57000","15.29763","0.01026"
"183.74400","15.31216","0.00909"
"183.91800","15.32657","0.00793"
"184.09200","15.34104","0.00792"
"184.26600","15.35563","0.00873"
"184.44000","15.37010","0.01066"
"184.61400","15.38462","0.01123"
"184.78800","15.39915","0.01018"
"184.96200","15.41356","0.00926"
"185.13600","15.42809","0.01054"
"185.31000","15.44268","0.01208"
"185.48400","15.45709","0.01189"
"185.65800","15.47156","0.01185"
"185.83200","15.48609","0.01095"
"186.00600","15.50062","0.01236"
"186.18000","15.51509","0.01378"
"186.35400","15.52961","0.01398"
"186.52800","15.54414","0.01279"
"186.70200","15.55855","0.01315"
"186.87600","15.57314","0.01437"
"187.05000","15.58767","0.01526"
"187.22400","15.60202","0.01511"
"187.39800","15.61661","0.01454"
"187.57200","15.63108","0.01484"
"187.74600","15.64560","0.01546"
"187.92000","15.66013","0.01697"
"188.09400","15.67460","0.01704"
"188.26800","15.68907","0.01601"
"188.44200","15.70360","0.01647"
"188.61600","15.71813","0.01778"
"188.79000","15.73254","0.01845"
"188.96400","15.74713","0.01771"
"189.13800","15.76166","0.01817"
"189.31200","15.77613","0.01888"
"189.48600","15.79060","0.02015"
"189.66000","15.80512","0.01944"
"189.83400","15.81959","0.00367"
"190.00800","15.83412","0.00169"
"190.18200","15.84865","0.00051"
"190.35600","15.86312","0.00085"
"190.53000","15.87759","0.00111"
"190.70400","15.89212","0.00197"
"190.87800","15.90659","0.00077"
"191.05200","15.92112","0.00120"
"191.22600","15.93559","0.00120"
"191.40000","15.95011","0.00116"
"191.57400","15.96458","0.00154"
"191.74800","15.97917","0.00251"
"191.92200","15.99364","0.00032"
"192.09600","16.00805","0.00123"
"192.27000","16.02264","0.00073"
"192.44400","16.03711","0.00184"
"192.61800","16.05157","0.00123"
"192.79200","16.06616","0.00085"
"192.96600","16.08064","0.00072"
"193.14000","16.09504","0.00172"
"193.31400","16.10963","0.00157"
"193.48800","16.12416","0.00172"
"193.66200","16.13857","0.00122"
"193.83600","16.15310","0.00135"
"194.01000","16.16763","0.00100"
"194.18400","16.18210","0.00205"
"194.35800","16.19662","0.00156"
"194.53200","16.21115","0.00111"
"194.70600","16.22556","0.00115"
"194.88000","16.24015","0.00113"
"195.05400","16.25468","0.00217"
"195.22800","16.26909","0.00097"
"195.40200","16.28362","0.00139"
"195.57600","16.29809","0.00172"
"195.75000","16.31262","0.00146"
"195.92400","16.32715","0.00169"
"196.09800","16.34162","0.00144"
"196.27200","16.35608","0.00198"
"196.44600","16.37061","0.00077"
"196.62000","16.38514","0.00145"
"196.79400","16.39967","0.00264"
"196.96800","16.41414","0.00111"
"197.14200","16.42861","0.00117"
"197.31600","16.44308","0.00226"
"197.49000","16.45761","0.00209"
"197.66400","16.47214","0.00219"
"197.83800","16.48660","0.00161"
"198.01200","16.50107","0.00219"
"198.18600","16.51560","0.00209"
"198.36000","16.53019","0.00200"
"198.53400","16.54460","0.00192"
"198.70800","16.55913","0.00219"
"198.88200","16.57366","0.00193"
"199.05600","16.58801","0.00195"
"199.23000","16.60271","0.00237"
"199.40400","16.61712","0.00202"
"199.57800","16.63153","0.00199"
"199.75200","16.64612","0.00201"
"199.92600","16.66065","0.00262"
"200.10000","16.67506","0.00183"
"200.27400","16.68965","0.00233"
"200.44800","16.70412","0.00267"
"200.62200","16.71859","0.00209"
"200.79600","16.73318","0.00234"
"200.97000","16.74765","0.00186"
"201.14400","16.76212","0.00279"
"201.31800","16.77658","0.00252"
"201.49200","16.79117","0.00173"
"201.66600","16.80558","0.00240"
"201.84000","16.82011","0.00223"
"202.01400","16.83464","0.00217"
"202.18800","16.84911","0.00304"
"202.36200","16.86364","0.00298"
"202.53600","16.87817","0.00253"
"202.71000","16.89264","0.00206"
"202.88400","16.90710","0.00307"
"203.05800","16.92157","0.00255"
"203.23200","16.93616","0.00189"
"203.40600","16.95057","0.00284"
"203.58000","16.96510","0.00322"
"203.75400","16.97963","0.00168"
"203.92800","16.99404","0.00257"
"204.10200","17.00869","0.00335"
"204.27600","17.02310","0.00231"
"204.45000","17.03751","0.00259"
"204.62400","17.05215","0.00342"
"204.79800","17.06662","0.00301"
"204.97200","17.08109","0.00256"
"205.14600","17.09568","0.00303"
"205.32000","17.11015","0.00378"
"205.49400","17.12462","0.00221"
"205.66800","17.13915","0.00335"
"205.84200","17.15362","0.00314"
"206.01600","17.16809","0.00323"
"206.19000","17.18255","0.00229"
"206.36400","17.19714","0.00379"
"206.53800","17.21155","0.00285"
"206.71200","17.22608","0.00241"
"206.88600","17.24067","0.00325"
"207.06000","17.25508","0.00424"
"207.23400","17.26961","0.00256"
"207.40800","17.28414","0.00305"
"207.58200","17.29855","0.00372"
"207.75600","17.31308","0.00317"
"207.93000","17.32760","0.00307"
"208.10400","17.34213","0.00346"
"208.27800","17.35666","0.00345"
"208.45200","17.37113","0.00305"
"208.62600","17.38560","0.00412"
"208.80000","17.40007","0.00456"
"208.97400","17.41466","0.00321"
"209.14800","17.42913","0.00341"
"209.32200","17.44360","0.00493"
"209.49600","17.45812","0.00401"
"209.67000","17.47260","0.00382"
"209.84400","17.48712","0.00462"
"210.01800","17.50165","0.00435"
"210.19200","17.51612","0.00325"
"210.36600","17.53053","0.00429"
"210.54000","17.54512","0.00445"
"210.71400","17.55965","0.00343"
"210.88800","17.57406","0.00440"
"211.06200","17.58865","0.00412"
"211.23600","17.60312","0.00355"
"211.41000","17.61758","0.00405"
"211.58400","17.63217","0.00456"
"211.75800","17.64664","0.00377"
"211.93200","17.66105","0.00387"
"212.10600","17.67558","0.00489"
"212.28000","17.69017","0.00455"
"212.45400","17.70458","0.00401"
"212.62800","17.71911","0.00449"
"212.80200","17.73363","0.00448"
"212.97600","17.74810","0.00439"
"213.15000","17.76263","0.00476"
"213.32400","17.77710","0.00512"
"213.49800","17.79163","0.00439"
"213.67200","17.80604","0.00467"
"213.84600","17.82069","0.00515"
"214.02000","17.83510","0.00402"
"214.19400","17.84957","0.00491"
"214.36800","17.86416","0.00507"
"214.54200","17.87863","0.00432"
"214.71600","17.89310","0.00456"
"214.89000","17.90762","0.00503"
"215.06400","17.92209","0.00444"
"215.23800","17.93656","0.00489"
"215.41200","17.95115","0.00577"
"215.58600","17.96562","0.00507"
"215.76000","17.98015","0.00482"
"215.93400","17.99462","0.00510"
"216.10800","18.00908","0.00558"
"216.28200","18.02355","0.00530"
"216.45600","18.03820","0.00540"
"216.63000","18.05261","0.00570"
"216.80400","18.06702","0.00526"
"216.97800","18.08167","0.00527"
"217.15200","18.09614","0.00542"
"217.32600","18.11061","0.00497"
"217.50000","18.12514","0.00561"
"217.67400","18.13967","0.00564"
"217.84800","18.15408","0.00571"
"218.02200","18.16860","0.00561"
"218.19600","18.18313","0.00590"
"218.37000","18.19760","0.00563"
"218.54400","18.21213","0.00602"
"218.71800","18.22666","0.00628"
"218.89200","18.24107","0.00597"
"219.06600","18.25560","0.00570"
"219.24000","18.27013","0.00596"
"219.41400","18.28460","0.00595"
"219.58800","18.29913","0.00576"
"219.76200","18.31365","0.00632"
"219.93600","18.32806","0.00635"
"220.11000","18.34253","0.00615"
"220.28400","18.35712","0.00683"
"220.45800","18.37165","0.00631"
"220.63200","18.38612","0.00628"
"220.80600","18.40059","0.00622"
"220.98000","18.41512","0.00621"
"221.15400","18.42958","0.00640"
"221.32800","18.44418","0.00662"
"221.50200","18.45864","0.00663"
"221.67600","18.47305","0.00628"
"221.85000","18.48764","0.00686"
"222.02400","18.50211","0.00678"
"222.19800","18.51658","0.00655"
"222.37200","18.53117","0.00663"
"222.54600","18.54564","0.00675"
"222.72000","18.56011","0.00702"
"222.89400","18.57469","0.00632"
"223.06800","18.58916","0.00660"
"223.24200","18.60357","0.00683"
"223.41600","18.61810","0.00671"
"223.59000","18.63263","0.00709"
"223.76400","18.64710","0.00628"
"223.93800","18.66163","0.00680"
"224.11200","18.67616","0.00679"
"224.28600","18.69057","0.00768"
"224.46000","18.70516","0.00677"
"224.63400","18.71963","0.00710"
"224.80800","18.73409","0.00735"
"224.98200","18.74862","0.00741"
"225.15600","18.76309","0.00717"
"225.33000","18.77762","0.00666"
"225.50400","18.79209","0.00710"
"225.67800","18.80668","0.00753"
"225.85200","18.82115","0.00741"
"226.02600","18.83556","0.00742"
"226.20000","18.85015","0.00734"
"226.37400","18.86461","0.00718"
"226.54800","18.87908","0.00772"
"226.72200","18.89361","0.00836"
"226.89600","18.90814","0.00777"
"227.07000","18.92261","0.00744"
"227.24400","18.93714","0.00759"
"227.41800","18.95161","0.00779"
"227.59200","18.96602","0.00779"
"227.76600","18.98061","0.00758"
"227.94000","18.99513","0.00717"
"228.11400","19.00954","0.00715"
"228.28800","19.02407","0.00718"
"228.46200","19.03866","0.00794"
"228.63600","19.05313","0.00731"
"228.81000","19.06766","0.00790"
"228.98400","19.08219","0.00804"
"229.15800","19.09654","0.00816"
"229.33200","19.11113","0.00827"
"229.50600","19.12566","0.00852"
"229.68000","19.14006","0.00787"
"229.85400","19.15465","0.00831"
"230.02800","19.16912","0.00898"
"230.20200","19.18359","0.00862"
"230.37600","19.19812","0.00846"
"230.55000","19.21265","0.00833"
"230.72400","19.22712","0.00874"
"230.89800","19.24165","0.00902"
"231.07200","19.25618","0.00911"
"231.24600","19.27059","0.00873"
"231.42000","19.28506","0.00874"
"231.59400","19.29958","0.00955"
"231.76800","19.31405","0.00864"
"231.94200","19.32864","0.00919"
"232.11600","19.34311","0.00935"
"232.29000","19.35758","0.00963"
"232.46400","19.37205","0.00981"
"232.63800","19.38664","0.01015"
"232.81200","19.40117","0.00890"
"232.98600","19.41551","0.00964"
"233.16000","19.43010","0.00986"
"233.33400","19.44463","0.00999"
"233.50800","19.45904","0.00970"
"233.68200","19.47369","0.01000"
"233.85600","19.48816","0.01016"
"234.03000","19.50251","0.00995"
"234.20400","19.51710","0.01014"
"234.37800","19.53169","0.01041"
"234.55200","19.54604","0.00998"
"234.72600","19.56068","0.01044"
"234.90000","19.57515","0.01003"
"235.07400","19.58962","0.01077"
"235.24800","19.60415","0.01014"
"235.42200","19.61862","0.01103"
"235.59600","19.63309","0.01097"
"235.77000","19.64756","0.01054"
"235.94400","19.66215","0.01101"
"236.11800","19.67656","0.01121"
"236.29200","19.69109","0.01090"
"236.46600","19.70561","0.01176"
"236.64000","19.72008","0.01162"
"236.81400","19.73461","0.01162"
"236.98800","19.74914","0.01238"
"237.16200","19.76361","0.01186"
"237.33600","19.77808","0.01151"
"237.51000","19.79261","0.01170"
"237.68400","19.80714","0.01245"
"237.85800","19.82160","0.01217"
"238.03200","19.83607","0.01261"
"238.20600","19.85060","0.01265"
"238.38000","19.86507","0.01261"
"238.55400","19.87966","0.01260"
"238.72800","19.89413","0.01260"
"238.90200","19.90854","0.01262"
"239.07600","19.92313","0.01325"
"239.25000","19.93766","0.01332"
"239.42400","19.95207","0.01348"
"239.59800","19.96659","0.01327"
"239.77200","19.98106","0.01366"
"239.94600","19.99559","0.01425"
"240.12000","20.01018","0.01378"
"240.29400","20.02465","0.01372"
"240.46800","20.03906","0.01385"
"240.64200","20.05359","0.01412"
"240.81600","20.06812","0.01497"
"240.99000","20.08259","0.01405"
"241.16400","20.09711","0.01371"
"241.33800","20.11164","0.01491"
"241.51200","20.12605","0.01487"
"241.68600","20.14064","0.01489"
"241.86000","20.15517","0.01541"
"242.03400","20.16958","0.01517"
"242.20800","20.18417","0.01522"
"242.38200","20.19858","0.01586"
"242.55600","20.21305","0.01570"
"242.73000","20.22757","0.01538"
"242.90400","20.24211","0.01566"
"243.07800","20.25664","0.01619"
"243.25200","20.27110","0.01592"
"243.42600","20.28563","0.01681"
"243.60000","20.30016","0.01615"
"243.77400","20.31451","0.01645"
"243.94800","20.32916","0.01677"
"244.12200","20.34363","0.01694"
"244.29600","20.35810","0.01751"
"244.47000","20.37263","0.01717"
"244.64400","20.38709","0.01729"
"244.81800","20.40150","0.01758"
"244.99200","20.41615","0.01781"
"245.16600","20.43062","0.01803"
"245.34000","20.44503","0.01783"
"245.51400","20.45962","0.01789"
"245.68800","20.47415","0.01821"
"245.86200","20.48862","0.01885"
"246.03600","20.50315","0.01876"
"246.21000","20.51762","0.01890"
"246.38400","20.53209","0.01915"
"246.55800","20.54661","0.01909"
"246.73200","20.56114","0.01945"
"246.90600","20.57561","0.01928"
"247.08000","20.59014","0.01952"
"247.25400","20.60461","0.01925"
"247.42800","20.61914","0.01969"
"247.60200","20.63361","0.01986"
"247.77600","20.64814","0.02039"
"247.95000","20.66255","0.02042"
"248.12400","20.67713","0.02093"
"248.29800","20.69166","0.02103"
"248.47200","20.70613","0.02105"
"248.64600","20.72060","0.02155"
"248.82000","20.73513","0.02183"
"248.99400","20.74960","0.02154"
"249.16800","20.76407","0.02152"
"249.34200","20.77866","0.02193"
"249.51600","20.79306","0.02224"
"249.69000","20.80759","0.01583"
"249.86400","20.82218","0.00216"
"250.03800","20.83665","0.00112"
"250.21200","20.85106","0.00210"
"250.38600","20.86565","0.00275"
"250.56000","20.88012","0.00071"
"250.73400","20.89453","0.00094"
"250.90800","20.90911","0.00087"
"251.08200","20.92365","0.00099"
"251.25600","20.93805","0.00111"
"251.43000","20.95264","0.00174"
"251.60400","20.96717","0.00199"
"251.77800","20.98158","0.00093"
"251.95200","20.99617","0.00066"
"252.12600","21.01058","0.00059"
"252.30000","21.02511","0.00083"
"252.47400","21.03970","0.00065"
"252.64800","21.05411","0.00138"
"252.81400","21.06792","0.00214"