File: Force_trajectories/170108_1/Specimen_RawData_9.csv
End date,"1/8/2017"
Specimen label,"19AG_UNK"
Maximum Load,"0.04795",N

Time,Extension,Load
(s),(mm),(N)
"0.00000","0.00000","0.00111"
"0.48000","0.04030","0.00148"
"0.96000","0.08024","0.00191"
"1.44000","0.12030","0.00228"
"1.92000","0.16024","0.00281"
"2.40000","0.20024","0.00286"
"2.88000","0.24023","0.00318"
"3.36000","0.28023","0.00344"
"3.84000","0.32017","0.00379"
"4.32000","0.36029","0.00408"
"4.80000","0.40023","0.00413"
"5.28000","0.44023","0.00449"
"5.76000","0.48029","0.00455"
"6.24000","0.52023","0.00470"
"6.72000","0.56023","0.00509"
"7.20000","0.60023","0.00531"
"7.68000","0.64017","0.00554"
"8.16000","0.68023","0.00581"
"8.64000","0.72028","0.00584"
"9.12000","0.76022","0.00616"
"9.60000","0.80022","0.00636"
"10.08000","0.84028","0.00680"
"10.56000","0.88022","0.00621"
"11.04000","0.92028","0.00672"
"11.52000","0.96022","0.00692"
"12.00000","1.00016","0.00705"
"12.48000","1.04022","0.00750"
"12.96000","1.08028","0.00725"
"13.44000","1.12022","0.00748"
"13.92000","1.16028","0.00742"
"14.40000","1.20022","0.00788"
"14.88000","1.24027","0.00768"
"15.36000","1.28021","0.00801"
"15.84000","1.32021","0.00815"
"16.32000","1.36015","0.00781"
"16.80000","1.40021","0.00818"
"17.28000","1.44021","0.00830"
"17.76000","1.48021","0.00818"
"18.24000","1.52027","0.00842"
"18.72000","1.56027","0.00903"
"19.20000","1.60027","0.00887"
"19.68000","1.64027","0.00908"
"20.16000","1.68027","0.00886"
"20.64000","1.72014","0.00933"
"21.12000","1.76020","0.00944"
"21.60000","1.80020","0.00909"
"22.08000","1.84026","0.00924"
"22.56000","1.88026","0.00920"
"23.04000","1.92026","0.00986"
"23.52000","1.96026","0.00946"
"24.00000","2.00026","0.00915"
"24.48000","2.04020","0.00942"
"24.96000","2.08020","0.00971"
"25.44000","2.12020","0.00930"
"25.92000","2.16020","0.01011"
"26.40000","2.20025","0.01009"
"26.88000","2.24025","0.00999"
"27.36000","2.28025","0.01010"
"27.84000","2.32025","0.01032"
"28.32000","2.36025","0.01011"
"28.80000","2.40019","0.01021"
"29.28000","2.44025","0.01045"
"29.76000","2.48019","0.01071"
"30.24000","2.52019","0.01041"
"30.72000","2.56025","0.01083"
"31.20000","2.60025","0.01111"
"31.68000","2.64031","0.01050"
"32.16000","2.68030","0.01109"
"32.64000","2.72024","0.01116"
"33.12000","2.76018","0.01053"
"33.60000","2.80024","0.01086"
"34.08000","2.84018","0.01118"
"34.56000","2.88024","0.01103"
"35.04000","2.92024","0.01126"
"35.52000","2.96024","0.01129"
"36.00000","3.00024","0.01152"
"36.48000","3.04024","0.01115"
"36.96000","3.08024","0.01137"
"37.44000","3.12030","0.01197"
"37.92000","3.16024","0.01190"
"38.40000","3.20017","0.01168"
"38.88000","3.24023","0.01189"
"39.36000","3.28023","0.01192"
"39.84000","3.32017","0.01222"
"40.32000","3.36029","0.01170"
"40.80000","3.40023","0.01184"
"41.28000","3.44017","0.01223"
"41.76000","3.48023","0.01184"
"42.24000","3.52023","0.01205"
"42.72000","3.56011","0.01208"
"43.20000","3.60017","0.01243"
"43.68000","3.64023","0.01229"
"44.16000","3.68022","0.01246"
"44.64000","3.72028","0.01272"
"45.12000","3.76022","0.01250"
"45.60000","3.80022","0.01282"
"46.08000","3.84028","0.01259"
"46.56000","3.88022","0.01291"
"47.04000","3.92016","0.01304"
"47.52000","3.96016","0.01261"
"48.00000","4.00022","0.01285"
"48.48000","4.04022","0.01304"
"48.96000","4.08028","0.01307"
"49.44000","4.12028","0.01324"
"49.92000","4.16027","0.01297"
"50.40000","4.20021","0.01351"
"50.88000","4.24027","0.01317"
"51.36000","4.28021","0.01335"
"51.84000","4.32021","0.01306"
"52.32000","4.36021","0.01318"
"52.80000","4.40021","0.01293"
"53.28000","4.44027","0.01345"
"53.76000","4.48021","0.01344"
"54.24000","4.52027","0.01300"
"54.72000","4.56027","0.01330"
"55.20000","4.60027","0.01388"
"55.68000","4.64027","0.01358"
"56.16000","4.68021","0.01388"
"56.64000","4.72020","0.01358"
"57.12000","4.76020","0.01373"
"57.60000","4.80020","0.01354"
"58.08000","4.84026","0.01381"
"58.56000","4.88020","0.01373"
"59.04000","4.92020","0.01374"
"59.52000","4.96026","0.01420"
"60.00000","5.00026","0.01355"
"60.48000","5.04020","0.01413"
"60.96000","5.08014","0.01407"
"61.44000","5.12020","0.01391"
"61.92000","5.16020","0.01377"
"62.40000","5.20025","0.01432"
"62.88000","5.24025","0.01429"
"63.36000","5.28019","0.01411"
"63.84000","5.32025","0.01419"
"64.32000","5.36025","0.01402"
"64.80000","5.40013","0.01416"
"65.28000","5.44019","0.01446"
"65.76000","5.48019","0.01449"
"66.24000","5.52019","0.01410"
"66.72000","5.56025","0.01492"
"67.20000","5.60025","0.01461"
"67.68000","5.64019","0.01499"
"68.16000","5.68024","0.01464"
"68.64000","5.72024","0.01484"
"69.12000","5.76018","0.01466"
"69.60000","5.80024","0.01500"
"70.08000","5.84024","0.01512"
"70.56000","5.88018","0.01438"
"71.04000","5.92030","0.01494"
"71.52000","5.96024","0.01532"
"72.00000","6.00024","0.01583"
"72.48000","6.04030","0.01500"
"72.96000","6.08024","0.01539"
"73.44000","6.12018","0.01520"
"73.92000","6.16024","0.01518"
"74.40000","6.20017","0.01514"
"74.88000","6.24017","0.01508"
"75.36000","6.28023","0.01541"
"75.84000","6.32029","0.01492"
"76.32000","6.36023","0.01492"
"76.80000","6.40029","0.01525"
"77.28000","6.44023","0.01499"
"77.76000","6.48023","0.01566"
"78.24000","6.52023","0.01539"
"78.72000","6.56017","0.01565"
"79.20000","6.60017","0.01550"
"79.68000","6.64017","0.01562"
"80.16000","6.68022","0.01538"
"80.64000","6.72022","0.01532"
"81.12000","6.76022","0.01530"
"81.60000","6.80028","0.01589"
"82.08000","6.84022","0.01553"
"82.56000","6.88022","0.01561"
"83.04000","6.92016","0.01573"
"83.52000","6.96022","0.01526"
"84.00000","7.00022","0.01558"
"84.48000","7.04028","0.01542"
"84.96000","7.08028","0.01572"
"85.44000","7.12022","0.01588"
"85.92000","7.16022","0.01601"
"86.40000","7.20027","0.01581"
"86.88000","7.24021","0.01580"
"87.36000","7.28015","0.01567"
"87.84000","7.32021","0.01464"
"88.32000","7.36021","0.01484"
"88.80000","7.40021","0.01513"
"89.28000","7.44027","0.01485"
"89.76000","7.48027","0.01505"
"90.24000","7.52027","0.01509"
"90.72000","7.56027","0.01561"
"91.20000","7.60021","0.01556"
"91.68000","7.64021","0.01581"
"92.16000","7.68015","0.01522"
"92.64000","7.72020","0.01530"
"93.12000","7.76026","0.01563"
"93.60000","7.80026","0.01609"
"94.08000","7.84020","0.01567"
"94.56000","7.88026","0.01570"
"95.04000","7.92026","0.01602"
"95.52000","7.96020","0.01582"
"96.00000","8.00026","0.01612"
"96.48000","8.04020","0.01584"
"96.96000","8.08014","0.01599"
"97.44000","8.12026","0.01589"
"97.92000","8.16025","0.01613"
"98.40000","8.20025","0.01611"
"98.88000","8.24025","0.01573"
"99.36000","8.28025","0.01590"
"99.84000","8.32019","0.01627"
"100.32000","8.36019","0.01629"
"100.80000","8.40019","0.01625"
"101.28000","8.44019","0.01638"
"101.76000","8.48025","0.01536"
"102.24000","8.52025","0.01530"
"102.72000","8.56025","0.01465"
"103.20000","8.60025","0.01519"
"103.68000","8.64025","0.01493"
"104.16000","8.68024","0.01562"
"104.64000","8.72024","0.01518"
"105.12000","8.76018","0.01477"
"105.60000","8.80018","0.01436"
"106.08000","8.84018","0.01448"
"106.56000","8.88018","0.01479"
"107.04000","8.92024","0.01417"
"107.52000","8.96024","0.01446"
"108.00000","9.00030","0.01423"
"108.48000","9.04024","0.01466"
"108.96000","9.08024","0.01435"
"109.44000","9.12018","0.01482"
"109.92000","9.16023","0.01456"
"110.40000","9.20023","0.01471"
"110.88000","9.24023","0.01495"
"111.36000","9.28023","0.01461"
"111.84000","9.32023","0.01443"
"112.32000","9.36023","0.01487"
"112.80000","9.40029","0.01442"
"113.28000","9.44017","0.01439"
"113.76000","9.48023","0.01471"
"114.24000","9.52023","0.01499"
"114.72000","9.56017","0.01464"
"115.20000","9.60023","0.01434"
"115.68000","9.64023","0.01503"
"116.16000","9.68022","0.01482"
"116.64000","9.72028","0.01505"
"117.12000","9.76028","0.01484"
"117.60000","9.80022","0.01524"
"118.08000","9.84022","0.01501"
"118.56000","9.88022","0.01525"
"119.04000","9.92022","0.01521"
"119.52000","9.96022","0.01494"
"120.00000","10.00028","0.01503"
"120.48000","10.04022","0.01545"
"120.96000","10.08028","0.01498"
"121.44000","10.12027","0.01516"
"121.92000","10.16022","0.01543"
"122.40000","10.20021","0.01564"
"122.88000","10.24021","0.01557"
"123.36000","10.28015","0.01545"
"123.84000","10.32021","0.01566"
"124.32000","10.36027","0.01538"
"124.80000","10.40027","0.01549"
"125.28000","10.44027","0.01573"
"125.76000","10.48021","0.01544"
"126.24000","10.52021","0.01581"
"126.72000","10.56021","0.01555"
"127.20000","10.60021","0.01559"
"127.68000","10.64020","0.01594"
"128.16000","10.68020","0.01585"
"128.64000","10.72026","0.01642"
"129.12000","10.76020","0.01598"
"129.60000","10.80026","0.01595"
"130.08000","10.84020","0.01670"
"130.56000","10.88020","0.01667"
"131.04000","10.92026","0.01645"
"131.52000","10.96020","0.01666"
"132.00000","11.00020","0.01615"
"132.48000","11.04020","0.01612"
"132.96000","11.08020","0.01684"
"133.44000","11.12025","0.01682"
"133.92000","11.16025","0.01688"
"134.40000","11.20025","0.01676"
"134.88000","11.24025","0.01661"
"135.36000","11.28025","0.01654"
"135.84000","11.32019","0.01687"
"136.32000","11.36019","0.01663"
"136.80000","11.40019","0.01688"
"137.28000","11.44019","0.01719"
"137.76000","11.48025","0.01709"
"138.24000","11.52025","0.01713"
"138.72000","11.56025","0.01711"
"139.20000","11.60031","0.01695"
"139.68000","11.64025","0.01751"
"140.16000","11.68024","0.01814"
"140.64000","11.72018","0.01772"
"141.12000","11.76018","0.01770"
"141.60000","11.80018","0.01775"
"142.08000","11.84030","0.01773"
"142.56000","11.88024","0.01765"
"143.04000","11.92024","0.01808"
"143.52000","11.96024","0.01753"
"144.00000","12.00024","0.01796"
"144.48000","12.04024","0.01794"
"144.96000","12.08024","0.01802"
"145.44000","12.12024","0.01835"
"145.92000","12.16023","0.01835"
"146.40000","12.20023","0.01817"
"146.88000","12.24023","0.01829"
"147.36000","12.28023","0.01828"
"147.84000","12.32023","0.01856"
"148.32000","12.36017","0.01855"
"148.80000","12.40023","0.01886"
"149.28000","12.44023","0.01836"
"149.76000","12.48017","0.01896"
"150.24000","12.52023","0.01918"
"150.72000","12.56023","0.01916"
"151.20000","12.60023","0.01873"
"151.68000","12.64023","0.01869"
"152.16000","12.68028","0.01900"
"152.64000","12.72022","0.01897"
"153.12000","12.76022","0.01933"
"153.60000","12.80022","0.01950"
"154.08000","12.84010","0.01910"
"154.56000","12.88022","0.01947"
"155.04000","12.92022","0.01912"
"155.52000","12.96022","0.01947"
"156.00000","13.00022","0.01924"
"156.48000","13.04022","0.01973"
"156.96000","13.08022","0.01951"
"157.44000","13.12028","0.01966"
"157.92000","13.16021","0.01981"
"158.40000","13.20021","0.01982"
"158.88000","13.24015","0.01972"
"159.36000","13.28027","0.01992"
"159.84000","13.32021","0.01996"
"160.32000","13.36027","0.02030"
"160.80000","13.40027","0.02011"
"161.28000","13.44027","0.02048"
"161.76000","13.48027","0.02068"
"162.24000","13.52021","0.02038"
"162.72000","13.56021","0.02002"
"163.20000","13.60021","0.02013"
"163.68000","13.64021","0.02084"
"164.16000","13.68026","0.02041"
"164.64000","13.72020","0.01974"
"165.12000","13.76026","0.02059"
"165.60000","13.80026","0.02061"
"166.08000","13.84026","0.02090"
"166.56000","13.88026","0.02020"
"167.04000","13.92020","0.02064"
"167.52000","13.96014","0.02055"
"168.00000","14.00020","0.02047"
"168.48000","14.04020","0.02091"
"168.96000","14.08026","0.02044"
"169.44000","14.12026","0.02054"
"169.92000","14.16031","0.02089"
"170.40000","14.20019","0.02039"
"170.88000","14.24025","0.02141"
"171.36000","14.28025","0.02073"
"171.84000","14.32013","0.02107"
"172.32000","14.36019","0.02109"
"172.80000","14.40025","0.01998"
"173.28000","14.44019","0.01982"
"173.76000","14.48025","0.01988"
"174.24000","14.52025","0.02011"
"174.72000","14.56025","0.01946"
"175.20000","14.60025","0.01988"
"175.68000","14.64025","0.01940"
"176.16000","14.68018","0.01936"
"176.64000","14.72018","0.01957"
"177.12000","14.76018","0.01960"
"177.60000","14.80024","0.02030"
"178.08000","14.84030","0.01967"
"178.56000","14.88030","0.01935"
"179.04000","14.92024","0.01966"
"179.52000","14.96024","0.02007"
"180.00000","15.00024","0.02026"
"180.48000","15.04018","0.01986"
"180.96000","15.08024","0.01979"
"181.44000","15.12024","0.02037"
"181.92000","15.16018","0.02040"
"182.40000","15.20023","0.02016"
"182.88000","15.24023","0.02022"
"183.36000","15.28023","0.02027"
"183.84000","15.32029","0.01976"
"184.32000","15.36029","0.02057"
"184.80000","15.40023","0.02007"
"185.28000","15.44017","0.02033"
"185.76000","15.48023","0.01989"
"186.24000","15.52017","0.02004"
"186.72000","15.56029","0.01965"
"187.20000","15.60029","0.01972"
"187.68000","15.64022","0.01991"
"188.16000","15.68022","0.02004"
"188.64000","15.72022","0.02010"
"189.12000","15.76022","0.01975"
"189.60000","15.80022","0.02003"
"190.08000","15.84022","0.02073"
"190.56000","15.88022","0.02013"
"191.04000","15.92022","0.02074"
"191.52000","15.96028","0.02068"
"192.00000","16.00028","0.02043"
"192.48000","16.04028","0.02073"
"192.96000","16.08027","0.02079"
"193.44000","16.12021","0.02064"
"193.92000","16.16015","0.02089"
"194.40000","16.20021","0.02119"
"194.88000","16.24021","0.02127"
"195.36000","16.28021","0.02129"
"195.84000","16.32027","0.02122"
"196.32000","16.36027","0.02135"
"196.80000","16.40021","0.02130"
"197.28000","16.44021","0.02204"
"197.76000","16.48027","0.02160"
"198.24000","16.52021","0.02179"
"198.72000","16.56021","0.02174"
"199.20000","16.60020","0.02204"
"199.68000","16.64014","0.02187"
"200.16000","16.68026","0.02240"
"200.64000","16.72020","0.02237"
"201.12000","16.76026","0.02253"
"201.60000","16.80026","0.02296"
"202.08000","16.84026","0.02259"
"202.56000","16.88014","0.02269"
"203.04000","16.92020","0.02264"
"203.52000","16.96020","0.02303"
"204.00000","17.00020","0.02331"
"204.48000","17.04026","0.02306"
"204.96000","17.08026","0.02334"
"205.44000","17.12025","0.02334"
"205.92000","17.16031","0.02271"
"206.40000","17.20025","0.02332"
"206.88000","17.24019","0.02326"
"207.36000","17.28019","0.02322"
"207.84000","17.32019","0.02360"
"208.32000","17.36019","0.02375"
"208.80000","17.40025","0.02394"
"209.28000","17.44025","0.02362"
"209.76000","17.48025","0.02396"
"210.24000","17.52031","0.02359"
"210.72000","17.56025","0.02368"
"211.20000","17.60018","0.02380"
"211.68000","17.64024","0.02397"
"212.16000","17.68018","0.02373"
"212.64000","17.72018","0.02421"
"213.12000","17.76024","0.02431"
"213.60000","17.80024","0.02459"
"214.08000","17.84024","0.02464"
"214.56000","17.88024","0.02474"
"215.04000","17.92024","0.02463"
"215.52000","17.96024","0.02439"
"216.00000","18.00018","0.02472"
"216.48000","18.04018","0.02499"
"216.96000","18.08023","0.02504"
"217.44000","18.12024","0.02478"
"217.92000","18.16023","0.02518"
"218.40000","18.20023","0.02507"
"218.88000","18.24023","0.02437"
"219.36000","18.28023","0.02521"
"219.84000","18.32023","0.02515"
"220.32000","18.36023","0.02515"
"220.80000","18.40017","0.02555"
"221.28000","18.44017","0.02550"
"221.76000","18.48023","0.02545"
"222.24000","18.52023","0.02536"
"222.72000","18.56029","0.02490"
"223.20000","18.60023","0.02540"
"223.68000","18.64028","0.02541"
"224.16000","18.68022","0.02537"
"224.64000","18.72016","0.02564"
"225.12000","18.76016","0.02549"
"225.60000","18.80022","0.02559"
"226.08000","18.84022","0.02537"
"226.56000","18.88022","0.02623"
"227.04000","18.92028","0.02629"
"227.52000","18.96022","0.02643"
"228.00000","19.00028","0.02640"
"228.48000","19.04028","0.02498"
"228.96000","19.08022","0.02530"
"229.44000","19.12016","0.02511"
"229.92000","19.16021","0.02522"
"230.40000","19.20021","0.02520"
"230.88000","19.24027","0.02460"
"231.36000","19.28021","0.02462"
"231.84000","19.32021","0.02453"
"232.32000","19.36027","0.02486"
"232.80000","19.40027","0.02571"
"233.28000","19.44021","0.02511"
"233.76000","19.48027","0.02543"
"234.24000","19.52021","0.02578"
"234.72000","19.56021","0.02609"
"235.20000","19.60026","0.02669"
"235.68000","19.64020","0.02593"
"236.16000","19.68026","0.02610"
"236.64000","19.72026","0.02626"
"237.12000","19.76032","0.02650"
"237.60000","19.80020","0.02663"
"238.08000","19.84020","0.02666"
"238.56000","19.88014","0.02670"
"239.04000","19.92020","0.02740"
"239.52000","19.96026","0.02709"
"240.00000","20.00020","0.02690"
"240.48000","20.04020","0.02724"
"240.96000","20.08026","0.02782"
"241.44000","20.12025","0.02748"
"241.92000","20.16025","0.02702"
"242.40000","20.20019","0.02763"
"242.88000","20.24019","0.02787"
"243.36000","20.28019","0.02812"
"243.84000","20.32019","0.02787"
"244.32000","20.36025","0.02816"
"244.80000","20.40025","0.02785"
"245.28000","20.44025","0.02854"
"245.76000","20.48025","0.02871"
"246.24000","20.52024","0.02856"
"246.72000","20.56019","0.02865"
"247.20000","20.60019","0.02926"
"247.68000","20.64018","0.02926"
"248.16000","20.68024","0.02938"
"248.64000","20.72024","0.02808"
"249.12000","20.76024","0.02828"
"249.60000","20.80024","0.02813"
"250.08000","20.84024","0.02864"
"250.56000","20.88030","0.02873"
"251.04000","20.92024","0.02941"
"251.52000","20.96024","0.02908"
"252.00000","21.00018","0.02918"
"252.48000","21.04018","0.02956"
"252.96000","21.08023","0.02961"
"253.44000","21.12029","0.02882"
"253.92000","21.16029","0.02893"
"254.40000","21.20023","0.02959"
"254.88000","21.24023","0.02984"
"255.36000","21.28023","0.02997"
"255.84000","21.32023","0.03002"
"256.32000","21.36017","0.02975"
"256.80000","21.40017","0.02998"
"257.28000","21.44023","0.03045"
"257.76000","21.48023","0.03010"
"258.24000","21.52023","0.03019"
"258.72000","21.56029","0.03016"
"259.20000","21.60029","0.03013"
"259.68000","21.64022","0.03025"
"260.16000","21.68022","0.02967"
"260.64000","21.72016","0.02969"
"261.12000","21.76016","0.03001"
"261.60000","21.80022","0.02997"
"262.08000","21.84028","0.02999"
"262.56000","21.88022","0.02968"
"263.04000","21.92028","0.02974"
"263.52000","21.96022","0.02981"
"264.00000","22.00022","0.03034"
"264.48000","22.04027","0.03032"
"264.96000","22.08015","0.03035"
"265.44000","22.12016","0.03063"
"265.92000","22.16021","0.03053"
"266.40000","22.20021","0.03008"
"266.88000","22.24021","0.03071"
"267.36000","22.28027","0.03062"
"267.84000","22.32021","0.03119"
"268.32000","22.36021","0.03103"
"268.80000","22.40021","0.03055"
"269.28000","22.44021","0.03074"
"269.76000","22.48021","0.03076"
"270.24000","22.52021","0.03100"
"270.72000","22.56021","0.03068"
"271.20000","22.60027","0.03096"
"271.68000","22.64026","0.03070"
"272.16000","22.68020","0.03145"
"272.64000","22.72026","0.03133"
"273.12000","22.76020","0.03117"
"273.60000","22.80020","0.03239"
"274.08000","22.84020","0.03240"
"274.56000","22.88020","0.03231"
"275.04000","22.92020","0.03283"
"275.52000","22.96026","0.03291"
"276.00000","23.00026","0.03272"
"276.48000","23.04025","0.03290"
"276.96000","23.08026","0.03313"
"277.44000","23.12020","0.03334"
"277.92000","23.16019","0.03338"
"278.40000","23.20019","0.03424"
"278.88000","23.24019","0.03225"
"279.36000","23.28019","0.03254"
"279.84000","23.32025","0.03381"
"280.32000","23.36025","0.03198"
"280.80000","23.40025","0.03199"
"281.28000","23.44024","0.03225"
"281.76000","23.48025","0.03326"
"282.24000","23.52019","0.03237"
"282.72000","23.56018","0.03324"
"283.20000","23.60012","0.03387"
"283.68000","23.64024","0.03365"
"284.16000","23.68024","0.03404"
"284.64000","23.72024","0.03423"
"285.12000","23.76024","0.03458"
"285.60000","23.80024","0.03267"
"286.08000","23.84024","0.03321"
"286.56000","23.88024","0.03317"
"287.04000","23.92024","0.03317"
"287.52000","23.96018","0.03449"
"288.00000","24.00024","0.03404"
"288.48000","24.04017","0.03495"
"288.96000","24.08024","0.03490"
"289.44000","24.12023","0.03513"
"289.92000","24.16023","0.03547"
"290.40000","24.20023","0.03556"
"290.88000","24.24023","0.03550"
"291.36000","24.28017","0.03631"
"291.84000","24.32017","0.03561"
"292.32000","24.36023","0.03593"
"292.80000","24.40023","0.03609"
"293.28000","24.44023","0.03650"
"293.76000","24.48022","0.03685"
"294.24000","24.52022","0.03693"
"294.72000","24.56022","0.03675"
"295.20000","24.60023","0.03726"
"295.68000","24.64022","0.03794"
"296.16000","24.68016","0.03755"
"296.64000","24.72022","0.03778"
"297.12000","24.76016","0.03800"
"297.60000","24.80022","0.03866"
"298.08000","24.84022","0.03891"
"298.56000","24.88022","0.03857"
"299.04000","24.92028","0.03910"
"299.52000","24.96022","0.03966"
"300.00000","25.00022","0.03701"
"300.48000","25.04022","0.03878"
"300.96000","25.08015","0.03793"
"301.44000","25.12021","0.03647"
"301.92000","25.16027","0.03676"
"302.40000","25.20015","0.03598"
"302.88000","25.24021","0.03684"
"303.36000","25.28027","0.03675"
"303.84000","25.32027","0.03741"
"304.32000","25.36021","0.03751"
"304.80000","25.40021","0.03805"
"305.28000","25.44021","0.03830"
"305.76000","25.48021","0.03676"
"306.24000","25.52027","0.03762"
"306.72000","25.56020","0.03834"
"307.20000","25.60027","0.03852"
"307.68000","25.64026","0.03910"
"308.16000","25.68020","0.03936"
"308.64000","25.72020","0.03952"
"309.12000","25.76020","0.03980"
"309.60000","25.80020","0.04008"
"310.08000","25.84020","0.04058"
"310.56000","25.88020","0.04053"
"311.04000","25.92020","0.04121"
"311.52000","25.96025","0.04148"
"312.00000","26.00026","0.04215"
"312.48000","26.04025","0.04239"
"312.96000","26.08025","0.04183"
"313.44000","26.12025","0.04190"
"313.92000","26.16013","0.04148"
"314.40000","26.20019","0.04174"
"314.88000","26.24019","0.04207"
"315.36000","26.28019","0.04216"
"315.84000","26.32031","0.04298"
"316.32000","26.36025","0.04281"
"316.80000","26.40025","0.04328"
"317.28000","26.44025","0.04340"
"317.76000","26.48025","0.04364"
"318.24000","26.52019","0.04418"
"318.72000","26.56018","0.04377"
"319.20000","26.60018","0.04391"
"319.68000","26.64018","0.04460"
"320.16000","26.68024","0.04402"
"320.64000","26.72024","0.04402"
"321.12000","26.76024","0.04369"
"321.60000","26.80030","0.04386"
"322.08000","26.84024","0.04414"
"322.56000","26.88018","0.04442"
"323.04000","26.92018","0.04467"
"323.52000","26.96018","0.04540"
"324.00000","27.00018","0.04511"
"324.48000","27.04023","0.04491"
"324.96000","27.08023","0.04551"
"325.44000","27.12029","0.04550"
"325.92000","27.16023","0.04574"
"326.40000","27.20023","0.04492"
"326.88000","27.24023","0.02362"
"327.36000","27.28017","0.02474"
"327.84000","27.32023","0.02601"
"328.32000","27.36017","0.02792"
"328.80000","27.40017","0.02866"
"329.28000","27.44023","0.02798"
"329.76000","27.48023","0.02858"
"330.24000","27.52028","0.02957"
"330.72000","27.56023","0.02947"
"331.20000","27.60023","0.02986"
"331.68000","27.64016","0.03065"
"332.16000","27.68016","0.03075"
"332.64000","27.72022","0.03122"
"333.12000","27.76022","0.03176"
"333.60000","27.80022","0.03172"
"334.08000","27.84028","0.03136"
"334.56000","27.88022","0.03236"
"335.04000","27.92028","0.03235"
"335.52000","27.96028","0.03246"
"336.00000","28.00016","0.03331"
"336.48000","28.04021","0.03363"
"336.96000","28.08021","0.03398"
"337.44000","28.12021","0.03414"
"337.92000","28.16021","0.03525"
"338.40000","28.20027","0.03537"
"338.88000","28.24021","0.03540"
"339.36000","28.28027","0.03623"
"339.84000","28.32021","0.03761"
"340.32000","28.36015","0.03889"
"340.80000","28.40021","0.03853"
"341.28000","28.44021","0.03884"
"341.76000","28.48021","0.03881"
"342.24000","28.52026","0.03969"
"342.72000","28.56026","0.04061"
"343.20000","28.60020","0.04045"
"343.68000","28.64032","0.04092"
"344.16000","28.68014","0.04145"
"344.64000","28.72020","0.04177"
"345.12000","28.76020","0.04175"
"345.60000","28.80020","0.04125"
"346.08000","28.84020","0.04212"
"346.56000","28.88026","0.04204"
"347.04000","28.92026","0.04204"
"347.52000","28.96020","0.04134"
"348.00000","29.00032","0.04041"
"348.48000","29.04026","0.04071"
"348.96000","29.08019","0.04155"
"349.44000","29.12019","0.04171"
"349.92000","29.16019","0.04252"
"350.40000","29.20019","0.04278"
"350.88000","29.24025","0.04295"
"351.36000","29.28025","0.04336"
"351.84000","29.32025","0.04319"
"352.32000","29.36025","0.04339"
"352.80000","29.40025","0.04331"
"353.28000","29.44025","0.04419"
"353.76000","29.48019","0.04438"
"354.24000","29.52013","0.04446"
"354.72000","29.56019","0.04442"
"355.20000","29.60024","0.04344"
"355.68000","29.64024","0.04396"
"356.16000","29.68030","0.04374"
"356.64000","29.72024","0.04453"
"357.12000","29.76030","0.04447"
"357.60000","29.80030","0.04530"
"358.08000","29.84018","0.04473"
"358.56000","29.88018","0.04441"
"359.04000","29.92024","0.04530"
"359.52000","29.96024","0.04542"
"360.00000","30.00024","0.04575"
"360.48000","30.04029","0.04529"
"360.96000","30.08023","0.04584"
"361.44000","30.12024","0.04503"
"361.92000","30.16023","0.04511"
"362.40000","30.20023","0.04467"
"362.88000","30.24017","0.04513"
"363.36000","30.28023","0.04555"
"363.84000","30.32017","0.04574"
"364.32000","30.36023","0.04639"
"364.80000","30.40023","0.04653"
"365.28000","30.44023","0.04679"
"365.76000","30.48029","0.04666"
"366.24000","30.52029","0.04718"
"366.72000","30.56017","0.04748"
"367.20000","30.60022","0.04738"
"367.68000","30.64016","0.04774"
"368.16000","30.68016","0.04742"
"368.64000","30.72022","0.04781"
"369.12000","30.76028","0.04722"
"369.60000","30.80022","0.04511"
"370.08000","30.84022","0.04553"
"370.56000","30.88028","0.04385"
"371.04000","30.92022","0.04349"
"371.52000","30.96028","0.04439"
"372.00000","31.00016","0.04407"
"372.48000","31.04015","0.04413"
"372.96000","31.08027","0.04413"
"373.44000","31.12021","0.04439"
"373.92000","31.16027","0.04479"
"374.40000","31.20027","0.04542"
"374.88000","31.24027","0.04566"
"375.36000","31.28021","0.04534"
"375.84000","31.32027","0.04588"
"376.32000","31.36015","0.04611"
"376.80000","31.40021","0.04476"
"377.28000","31.44027","0.04551"
"377.76000","31.48026","0.04586"
"378.24000","31.52026","0.04549"
"378.72000","31.56026","0.04442"
"379.20000","31.60026","0.04479"
"379.68000","31.64026","0.04482"
"380.16000","31.68020","0.04410"
"380.64000","31.72020","0.04459"
"381.12000","31.76020","0.04494"
"381.60000","31.80020","0.04518"
"382.08000","31.84020","0.04551"
"382.56000","31.88026","0.04551"
"383.04000","31.92025","0.04599"
"383.52000","31.96026","0.04571"
"384.00000","32.00026","0.04577"
"384.48000","32.04020","0.04625"
"384.96000","32.08019","0.04558"
"385.44000","32.12019","0.04594"
"385.92000","32.16019","0.04583"
"386.40000","32.20019","0.04511"
"386.88000","32.24019","0.04531"
"387.36000","32.28019","0.04553"
"387.84000","32.32025","0.04516"
"388.32000","32.36025","0.04471"
"388.80000","32.40019","0.04460"
"389.28000","32.44019","0.04483"
"389.76000","32.48018","0.04395"
"390.24000","32.52018","0.04397"
"390.72000","32.56018","0.04432"
"391.20000","32.60024","0.04487"
"391.68000","32.64024","0.04506"
"392.16000","32.68024","0.04557"
"392.64000","32.72024","0.04556"
"393.12000","32.76018","0.04604"
"393.60000","32.80024","0.04595"
"394.08000","32.84018","0.04580"
"394.56000","32.88023","0.04493"
"395.04000","32.92024","0.04520"
"395.52000","32.96024","0.04542"
"396.00000","33.00023","0.04557"
"396.48000","33.04029","0.03918"
"396.96000","33.08023","0.03530"
"397.44000","33.12024","0.03799"
"397.92000","33.16023","0.03613"
"398.40000","33.20017","0.03541"
"398.88000","33.24017","0.03606"
"399.36000","33.28023","0.03768"
"399.84000","33.32023","0.03700"
"400.32000","33.36023","0.03696"
"400.80000","33.40029","0.03828"
"401.28000","33.44022","0.03834"
"401.76000","33.48022","0.03929"
"402.24000","33.52016","0.04020"
"402.72000","33.56022","0.03977"
"403.20000","33.60016","0.04040"
"403.68000","33.64022","0.03997"
"404.16000","33.68022","0.03904"
"404.64000","33.72022","0.03812"
"405.12000","33.76028","0.03830"
"405.60000","33.80022","0.03856"
"406.08000","33.84022","0.03943"
"406.56000","33.88021","0.03982"
"407.04000","33.92022","0.04051"
"407.52000","33.96016","0.04047"
"408.00000","34.00021","0.04137"
"408.48000","34.04021","0.04087"
"408.96000","34.08027","0.04099"
"409.44000","34.12021","0.04181"
"409.92000","34.16027","0.04175"
"410.40000","34.20027","0.04112"
"410.88000","34.24027","0.04176"
"411.36000","34.28021","0.04163"
"411.84000","34.32021","0.04088"
"412.32000","34.36015","0.04164"
"412.80000","34.40021","0.04231"
"413.28000","34.44027","0.04243"
"413.76000","34.48027","0.04254"
"414.24000","34.52026","0.04261"
"414.72000","34.56026","0.04311"
"415.20000","34.60026","0.04240"
"415.68000","34.64026","0.04296"
"416.16000","34.68020","0.04374"
"416.64000","34.72014","0.04376"
"417.12000","34.76020","0.04363"
"417.60000","34.80026","0.04467"
"418.08000","34.84019","0.04449"
"418.56000","34.88026","0.04463"
"419.04000","34.92026","0.04458"
"419.52000","34.96025","0.04487"
"420.00000","35.00025","0.04103"
"420.48000","35.04019","0.03880"
"420.96000","35.08014","0.03980"
"421.44000","35.12025","0.04016"
"421.92000","35.16025","0.03967"
"422.40000","35.20025","0.03986"
"422.88000","35.24019","0.04057"
"423.36000","35.28025","0.03779"
"423.84000","35.32019","0.03772"
"424.32000","35.36025","0.03836"
"424.80000","35.40018","0.03947"
"425.28000","35.44012","0.03994"
"425.76000","35.48019","0.04023"
"426.24000","35.52024","0.04080"
"426.72000","35.56024","0.04148"
"427.20000","35.60030","0.04115"
"427.68000","35.64018","0.04115"
"428.16000","35.68024","0.04104"
"428.64000","35.72024","0.04093"
"429.12000","35.76024","0.04152"
"429.60000","35.80018","0.04236"
"430.08000","35.84024","0.04248"
"430.56000","35.88024","0.04221"
"431.04000","35.92023","0.04327"
"431.52000","35.96024","0.04343"
"432.00000","36.00023","0.04364"
"432.48000","36.04023","0.04384"
"432.96000","36.08029","0.04316"
"433.44000","36.12023","0.04119"
"433.92000","36.16017","0.03685"
"434.40000","36.20023","0.03736"
"434.88000","36.24023","0.03757"
"435.36000","36.28023","0.03864"
"435.84000","36.32023","0.03937"
"436.32000","36.36029","0.03985"
"436.80000","36.40028","0.04064"
"437.28000","36.44023","0.04109"
"437.76000","36.48022","0.04067"
"438.24000","36.52016","0.04085"
"438.72000","36.56016","0.04180"
"439.20000","36.60022","0.04184"
"439.68000","36.64022","0.04120"
"440.16000","36.68022","0.04197"
"440.64000","36.72022","0.04219"
"441.12000","36.76028","0.04231"
"441.60000","36.80028","0.04156"
"442.08000","36.84022","0.04206"
"442.56000","36.88022","0.04213"
"443.04000","36.92015","0.04250"
"443.52000","36.96021","0.04253"
"444.00000","37.00021","0.04279"
"444.48000","37.04021","0.04200"
"444.96000","37.08027","0.03968"
"445.44000","37.12027","0.03935"
"445.92000","37.16027","0.04014"
"446.40000","37.20021","0.04025"
"446.88000","37.24021","0.04011"
"447.36000","37.28021","0.04037"
"447.84000","37.32021","0.04005"
"448.32000","37.36021","0.04134"
"448.80000","37.40020","0.04105"
"449.28000","37.44027","0.04136"
"449.76000","37.48021","0.04153"
"450.24000","37.52020","0.04168"
"450.72000","37.56032","0.04165"
"451.20000","37.60020","0.04215"
"451.68000","37.64020","0.04320"
"452.16000","37.68020","0.04236"
"452.64000","37.72020","0.04303"
"453.12000","37.76020","0.04296"
"453.60000","37.80026","0.04300"
"454.08000","37.84026","0.04354"
"454.56000","37.88020","0.04365"
"455.04000","37.92025","0.04290"
"455.52000","37.96025","0.04377"
"456.00000","38.00019","0.04401"
"456.48000","38.04020","0.04366"
"456.96000","38.08019","0.04122"
"457.44000","38.12019","0.04169"
"457.92000","38.16019","0.04206"
"458.40000","38.20025","0.04250"
"458.88000","38.24019","0.04347"
"459.36000","38.28025","0.02755"
"459.84000","38.32025","0.02605"
"460.32000","38.36024","0.02631"
"460.80000","38.40019","0.02881"
"461.28000","38.44019","0.02664"
"461.76000","38.48019","0.02561"
"462.24000","38.52024","0.02672"
"462.72000","38.56024","0.02659"
"463.20000","38.60024","0.02568"
"463.68000","38.64024","0.02685"
"464.16000","38.68024","0.02756"
"464.64000","38.72024","0.02741"
"465.12000","38.76018","0.02823"
"465.60000","38.80024","0.02814"
"466.08000","38.84024","0.02705"
"466.56000","38.88024","0.02644"
"467.04000","38.92030","0.02736"
"467.52000","38.96030","0.02704"
"468.00000","39.00024","0.02757"
"468.48000","39.04023","0.02791"
"468.96000","39.08029","0.02805"
"469.44000","39.12017","0.02817"
"469.92000","39.16023","0.02783"
"470.40000","39.20017","0.02752"
"470.88000","39.24023","0.02829"
"471.36000","39.28023","0.02819"
"471.84000","39.32029","0.02846"
"472.32000","39.36023","0.02882"
"472.80000","39.40029","0.02888"
"473.28000","39.44017","0.02928"
"473.76000","39.48016","0.02940"
"474.24000","39.52016","0.02980"
"474.72000","39.56022","0.02967"
"475.20000","39.60016","0.02961"
"475.68000","39.64028","0.03054"
"476.16000","39.68028","0.03076"
"476.64000","39.72022","0.03097"
"477.12000","39.76028","0.03062"
"477.60000","39.80022","0.03078"
"478.08000","39.84016","0.03091"
"478.56000","39.88021","0.03162"
"479.04000","39.92015","0.03154"
"479.52000","39.96022","0.03197"
"480.00000","40.00027","0.03209"
"480.48000","40.04027","0.03244"
"480.96000","40.08021","0.03294"
"481.44000","40.12027","0.03335"
"481.92000","40.16021","0.03356"
"482.40000","40.20021","0.03325"
"482.88000","40.24021","0.03321"
"483.36000","40.28021","0.03384"
"483.84000","40.32020","0.03364"
"484.32000","40.36026","0.03421"
"484.80000","40.40021","0.03282"
"485.28000","40.44020","0.03151"
"485.76000","40.48026","0.03218"
"486.24000","40.52032","0.03155"
"486.72000","40.56026","0.03194"
"487.20000","40.60020","0.03278"
"487.68000","40.64020","0.03349"
"488.16000","40.68020","0.03346"
"488.64000","40.72026","0.03436"
"489.12000","40.76020","0.03445"
"489.60000","40.80026","0.03473"
"490.08000","40.84019","0.03449"
"490.56000","40.88026","0.03533"
"491.04000","40.92019","0.03572"
"491.52000","40.96020","0.03617"
"492.00000","41.00013","0.03640"
"492.48000","41.04025","0.03635"
"492.96000","41.08019","0.03741"
"493.44000","41.12025","0.03770"
"493.92000","41.16025","0.03862"
"494.40000","41.20025","0.03928"
"494.88000","41.24025","0.03970"
"495.36000","41.28019","0.03950"
"495.84000","41.32019","0.04035"
"496.32000","41.36013","0.04192"
"496.80000","41.40019","0.04178"
"497.28000","41.44019","0.04208"
"497.76000","41.48024","0.04253"
"498.24000","41.52024","0.04259"
"498.72000","41.56024","0.04240"
"499.20000","41.60024","0.04313"
"499.68000","41.64024","0.04324"
"500.16000","41.68018","0.04357"
"500.64000","41.72018","0.04392"
"501.12000","41.76018","0.04396"
"501.60000","41.80018","0.04227"
"502.08000","41.84023","0.04256"
"502.56000","41.88023","0.04359"
"503.04000","41.92030","0.04399"
"503.52000","41.96030","0.04365"
"504.00000","42.00029","0.04269"
"504.48000","42.04023","0.04216"
"504.96000","42.08023","0.04217"
"505.44000","42.12017","0.04301"
"505.92000","42.16017","0.04401"
"506.40000","42.20029","0.04391"
"506.88000","42.24029","0.04018"
"507.36000","42.28023","0.03922"
"507.84000","42.32029","0.04074"
"508.32000","42.36028","0.03776"
"508.80000","42.40023","0.03807"
"509.28000","42.44022","0.03769"
"509.76000","42.48023","0.03856"
"510.24000","42.52016","0.03841"
"510.72000","42.56022","0.03876"
"511.20000","42.60022","0.03643"
"511.68000","42.64028","0.03577"
"512.16000","42.68028","0.03306"
"512.64000","42.72028","0.03188"
"513.12000","42.76022","0.03256"
"513.60000","42.80022","0.03291"
"514.08000","42.84021","0.03260"
"514.56000","42.88022","0.03363"
"515.04000","42.92022","0.03366"
"515.52000","42.96022","0.03361"
"516.00000","43.00021","0.03418"
"516.48000","43.04021","0.03379"
"516.96000","43.08021","0.03451"
"517.44000","43.12027","0.03420"
"517.92000","43.16021","0.03465"
"518.40000","43.20021","0.03459"
"518.88000","43.24021","0.03399"
"519.36000","43.28020","0.03426"
"519.84000","43.32015","0.03475"
"520.32000","43.36026","0.03399"
"520.80000","43.40026","0.03361"
"521.28000","43.44027","0.03348"
"521.76000","43.48027","0.03394"
"522.24000","43.52021","0.03349"
"522.72000","43.56020","0.03339"
"523.20000","43.60020","0.03392"
"523.68000","43.64020","0.03482"
"524.16000","43.68026","0.03459"
"524.64000","43.72026","0.03508"
"525.12000","43.76026","0.03539"
"525.60000","43.80025","0.03578"
"526.08000","43.84032","0.03609"
"526.56000","43.88020","0.03702"
"527.04000","43.92020","0.03650"
"527.52000","43.96014","0.03737"
"528.00000","44.00019","0.03750"
"528.48000","44.04020","0.03751"
"528.96000","44.08025","0.03813"
"529.44000","44.12025","0.03639"
"529.92000","44.16025","0.03722"
"530.40000","44.20025","0.03857"
"530.88000","44.24025","0.03943"
"531.36000","44.28019","0.03973"
"531.84000","44.32019","0.03992"
"532.32000","44.36013","0.04156"
"532.80000","44.40018","0.04013"
"533.28000","44.44025","0.04060"
"533.76000","44.48024","0.04095"
"534.24000","44.52030","0.04200"
"534.72000","44.56024","0.04200"
"535.20000","44.60024","0.04291"
"535.68000","44.64024","0.04235"
"536.16000","44.68018","0.04302"
"536.64000","44.72018","0.04282"
"537.12000","44.76024","0.04162"
"537.60000","44.80023","0.03999"
"538.08000","44.84024","0.04020"
"538.56000","44.88029","0.04106"
"539.04000","44.92030","0.04083"
"539.52000","44.96024","0.04060"
"540.00000","45.00023","0.04091"
"540.48000","45.04023","0.04187"
"540.96000","45.08017","0.04208"
"541.44000","45.12017","0.04282"
"541.92000","45.16022","0.04288"
"542.40000","45.20023","0.04323"
"542.88000","45.24023","0.04338"
"543.36000","45.28023","0.04427"
"543.84000","45.32028","0.04446"
"544.32000","45.36022","0.04480"
"544.80000","45.40023","0.04540"
"545.28000","45.44023","0.04542"
"545.76000","45.48017","0.04559"
"546.24000","45.52016","0.04573"
"546.72000","45.56028","0.04570"
"547.20000","45.60022","0.04427"
"547.68000","45.64022","0.04426"
"548.16000","45.68022","0.04373"
"548.64000","45.72028","0.04322"
"549.12000","45.76022","0.04322"
"549.60000","45.80022","0.04317"
"550.08000","45.84016","0.04405"
"550.56000","45.88021","0.04437"
"551.04000","45.92028","0.04509"
"551.52000","45.96027","0.04470"
"552.00000","46.00022","0.04370"
"552.48000","46.04027","0.04485"
"552.96000","46.08021","0.04513"
"553.44000","46.12027","0.04555"
"553.92000","46.16021","0.04617"
"554.40000","46.20015","0.04529"
"554.88000","46.24021","0.04622"
"555.36000","46.28021","0.04575"
"555.84000","46.32026","0.04597"
"556.32000","46.36027","0.04450"
"556.80000","46.40026","0.04502"
"557.28000","46.44027","0.04485"
"557.76000","46.48026","0.04573"
"558.24000","46.52020","0.04623"
"558.72000","46.56014","0.04644"
"559.20000","46.60020","0.04610"
"559.68000","46.64020","0.04600"
"560.16000","46.68020","0.04597"
"560.64000","46.72026","0.04468"
"561.12000","46.76026","0.04447"
"561.60000","46.80020","0.04463"
"562.08000","46.84026","0.04513"
"562.56000","46.88019","0.04586"
"563.04000","46.92014","0.04572"
"563.52000","46.96019","0.04562"
"564.00000","47.00026","0.04540"
"564.48000","47.04019","0.04328"
"564.96000","47.08025","0.04135"
"565.44000","47.12025","0.04194"
"565.92000","47.16025","0.04162"
"566.40000","47.20025","0.04057"
"566.88000","47.24018","0.03871"
"567.36000","47.28019","0.03833"
"567.84000","47.32018","0.03795"
"568.32000","47.36019","0.03469"
"568.80000","47.40024","0.03466"
"569.28000","47.44025","0.03460"
"569.76000","47.48019","0.03445"
"570.24000","47.52024","0.03445"
"570.72000","47.56024","0.03587"
"571.20000","47.60024","0.03596"
"571.68000","47.64018","0.03646"
"572.16000","47.68018","0.03773"
"572.64000","47.72024","0.03803"
"573.12000","47.76024","0.03918"
"573.60000","47.80024","0.03940"
"574.08000","47.84023","0.03918"
"574.56000","47.88023","0.03860"
"575.04000","47.92023","0.03866"
"575.52000","47.96024","0.03763"
"576.00000","48.00024","0.03602"
"576.48000","48.04017","0.03587"
"576.96000","48.08023","0.03597"
"577.44000","48.12023","0.03561"
"577.92000","48.16023","0.03668"
"578.40000","48.20023","0.03586"
"578.88000","48.24023","0.03679"
"579.36000","48.28028","0.03701"
"579.84000","48.32029","0.03750"
"580.32000","48.36017","0.03766"
"580.80000","48.40016","0.03820"
"581.28000","48.44022","0.03821"
"581.76000","48.48022","0.03918"
"582.24000","48.52023","0.04022"
"582.72000","48.56028","0.04048"
"583.20000","48.60028","0.03928"
"583.68000","48.64022","0.04019"
"584.16000","48.68022","0.04012"
"584.64000","48.72022","0.04096"
"585.12000","48.76016","0.04003"
"585.60000","48.80022","0.03999"
"586.08000","48.84021","0.04039"
"586.56000","48.88021","0.04112"
"587.04000","48.92022","0.04115"
"587.52000","48.96022","0.04195"
"588.00000","49.00027","0.04192"
"588.48000","49.04027","0.04183"
"588.96000","49.08021","0.04206"
"589.44000","49.12015","0.04183"
"589.92000","49.16021","0.04232"
"590.40000","49.20015","0.04200"
"590.88000","49.24015","0.04158"
"591.36000","49.28026","0.04218"
"591.84000","49.32027","0.04193"
"592.32000","49.36021","0.04191"
"592.80000","49.40026","0.04249"
"593.28000","49.44020","0.04261"
"593.76000","49.48020","0.04262"
"594.24000","49.52026","0.04267"
"594.72000","49.56020","0.04262"
"595.20000","49.60020","0.04293"
"595.68000","49.64020","0.04296"
"596.16000","49.68026","0.04364"
"596.64000","49.72026","0.04337"
"597.12000","49.76032","0.04362"
"597.60000","49.80026","0.04320"
"598.08000","49.84025","0.04379"
"598.56000","49.88013","0.04343"
"599.04000","49.92019","0.04135"
"599.52000","49.96020","0.03971"
"600.00000","50.00025","0.03982"
"600.48000","50.04025","0.03937"
"600.96000","50.08025","0.03807"
"601.44000","50.12019","0.03987"
"601.92000","50.16025","0.03906"
"602.40000","50.20019","0.03820"
"602.88000","50.24019","0.03905"
"603.36000","50.28019","0.04107"
"603.84000","50.32025","0.04007"
"604.32000","50.36019","0.04047"
"604.80000","50.40024","0.04086"
"605.28000","50.44024","0.04079"
"605.76000","50.48025","0.04142"
"606.24000","50.52024","0.04226"
"606.72000","50.56024","0.04227"
"607.20000","50.60018","0.04217"
"607.68000","50.64012","0.04247"
"608.16000","50.68018","0.04217"
"608.64000","50.72024","0.04345"
"609.12000","50.76024","0.04332"
"609.60000","50.80029","0.04402"
"610.08000","50.84017","0.04365"
"610.56000","50.88029","0.04413"
"611.04000","50.92023","0.04410"
"611.52000","50.96024","0.04397"
"612.00000","51.00023","0.04206"
"612.48000","51.04017","0.04171"
"612.96000","51.08017","0.04157"
"613.44000","51.12029","0.04261"
"613.92000","51.16023","0.04267"
"614.40000","51.20023","0.04260"
"614.88000","51.24029","0.04293"
"615.36000","51.28029","0.04324"
"615.84000","51.32016","0.04400"
"616.32000","51.36022","0.04410"
"616.80000","51.40016","0.04434"
"617.28000","51.44016","0.04442"
"617.76000","51.48029","0.04462"
"618.24000","51.52028","0.04493"
"618.72000","51.56022","0.04491"
"619.20000","51.60028","0.04555"
"619.68000","51.64022","0.04532"
"620.16000","51.68022","0.04538"
"620.64000","51.72022","0.04462"
"621.12000","51.76015","0.04177"
"621.60000","51.80022","0.03974"
"622.08000","51.84028","0.03853"
"622.56000","51.88022","0.03927"
"623.04000","51.92021","0.03888"
"623.52000","51.96027","0.03876"
"624.00000","52.00027","0.03966"
"624.48000","52.04028","0.03982"
"624.96000","52.08021","0.03955"
"625.44000","52.12015","0.03987"
"625.92000","52.16021","0.03977"
"626.40000","52.20021","0.03952"
"626.88000","52.24021","0.04051"
"627.36000","52.28027","0.04122"
"627.84000","52.32021","0.04109"
"628.32000","52.36026","0.04151"
"628.80000","52.40026","0.04124"
"629.28000","52.44020","0.04144"
"629.76000","52.48014","0.04139"
"630.24000","52.52020","0.04146"
"630.72000","52.56020","0.04151"
"631.20000","52.60020","0.04223"
"631.68000","52.64026","0.04157"
"632.16000","52.68026","0.04160"
"632.64000","52.72026","0.04141"
"633.12000","52.76026","0.04216"
"633.60000","52.80020","0.04145"
"634.08000","52.84019","0.04115"
"634.56000","52.88020","0.04116"
"635.04000","52.92019","0.04099"
"635.52000","52.96025","0.04152"
"636.00000","53.00026","0.04162"
"636.48000","53.04026","0.04143"
"636.96000","53.08025","0.04035"
"637.44000","53.12025","0.04076"
"637.92000","53.16019","0.03928"
"638.40000","53.20019","0.04009"
"638.88000","53.24025","0.04019"
"639.36000","53.28019","0.04086"
"639.84000","53.32025","0.04037"
"640.32000","53.36024","0.04075"
"640.80000","53.40025","0.04015"
"641.28000","53.44024","0.04032"
"641.76000","53.48030","0.04048"
"642.24000","53.52024","0.04013"
"642.72000","53.56024","0.04022"
"643.20000","53.60019","0.03990"
"643.68000","53.64024","0.04036"
"644.16000","53.68024","0.04030"
"644.64000","53.72024","0.03995"
"645.12000","53.76024","0.04080"
"645.60000","53.80030","0.04146"
"646.08000","53.84024","0.04034"
"646.56000","53.88023","0.03988"
"647.04000","53.92023","0.04014"
"647.52000","53.96017","0.03958"
"648.00000","54.00017","0.04029"
"648.48000","54.04023","0.04057"
"648.96000","54.08023","0.04064"
"649.44000","54.12029","0.04059"
"649.92000","54.16029","0.04140"
"650.40000","54.20023","0.04120"
"650.88000","54.24023","0.04140"
"651.36000","54.28023","0.04100"
"651.84000","54.32010","0.04191"
"652.32000","54.36016","0.04232"
"652.80000","54.40017","0.04244"
"653.28000","54.44022","0.04206"
"653.76000","54.48029","0.04255"
"654.24000","54.52022","0.04279"
"654.72000","54.56023","0.04286"
"655.20000","54.60028","0.04319"
"655.68000","54.64022","0.04252"
"656.16000","54.68016","0.04211"
"656.64000","54.72016","0.04212"
"657.12000","54.76022","0.04159"
"657.60000","54.80016","0.04152"
"658.08000","54.84033","0.04186"
"658.56000","54.88021","0.04181"
"659.04000","54.92028","0.04145"
"659.52000","54.96027","0.04209"
"660.00000","55.00022","0.04197"
"660.48000","55.04021","0.04155"
"660.96000","55.08021","0.04150"
"661.44000","55.12015","0.04179"
"661.92000","55.16021","0.04234"
"662.40000","55.20027","0.04203"
"662.88000","55.24021","0.04256"
"663.36000","55.28021","0.04250"
"663.84000","55.32026","0.04291"
"664.32000","55.36027","0.04260"
"664.80000","55.40021","0.04237"
"665.28000","55.44014","0.04296"
"665.76000","55.48021","0.04298"
"666.24000","55.52020","0.04296"
"666.72000","55.56026","0.04373"
"667.20000","55.60026","0.04393"
"667.68000","55.64026","0.04381"
"668.16000","55.68026","0.04377"
"668.64000","55.72020","0.04437"
"669.12000","55.76026","0.04416"
"669.60000","55.80020","0.04401"
"670.08000","55.84020","0.04446"
"670.56000","55.88019","0.04362"
"671.04000","55.92019","0.04357"
"671.52000","55.96025","0.04445"
"672.00000","56.00026","0.04378"
"672.48000","56.04025","0.04410"
"672.96000","56.08025","0.04351"
"673.44000","56.12025","0.04367"
"673.92000","56.16019","0.04405"
"674.40000","56.20019","0.04401"
"674.88000","56.24018","0.04357"
"675.36000","56.28019","0.04376"
"675.84000","56.32025","0.04339"
"676.32000","56.36025","0.04258"
"676.80000","56.40024","0.04332"
"677.28000","56.44024","0.04307"
"677.76000","56.48024","0.04363"
"678.24000","56.52018","0.04389"
"678.72000","56.56018","0.04390"
"679.20000","56.60018","0.04402"
"679.68000","56.64024","0.04429"
"680.16000","56.68024","0.04421"
"680.64000","56.72024","0.04432"
"681.12000","56.76023","0.04472"
"681.60000","56.80024","0.04464"
"682.08000","56.84024","0.04435"
"682.56000","56.88017","0.04470"
"683.04000","56.92024","0.04451"
"683.52000","56.96017","0.04495"
"684.00000","57.00018","0.04475"
"684.48000","57.04023","0.04386"
"684.96000","57.08023","0.04312"
"685.44000","57.12029","0.04270"
"685.92000","57.16023","0.04262"
"686.40000","57.20023","0.04172"
"686.88000","57.24023","0.04305"
"687.36000","57.28023","0.04328"
"687.84000","57.32017","0.04345"
"688.32000","57.36023","0.04334"
"688.80000","57.40022","0.04371"
"689.28000","57.44022","0.04395"
"689.76000","57.48022","0.04401"
"690.24000","57.52029","0.04368"
"690.72000","57.56022","0.04477"
"691.20000","57.60028","0.04476"
"691.68000","57.64022","0.04501"
"692.16000","57.68016","0.04455"
"692.64000","57.72022","0.04458"
"693.12000","57.76022","0.04486"
"693.60000","57.80022","0.04419"
"694.08000","57.84027","0.04463"
"694.56000","57.88021","0.04506"
"695.04000","57.92022","0.04449"
"695.52000","57.96021","0.04400"
"696.00000","58.00021","0.04396"
"696.48000","58.04021","0.04411"
"696.96000","58.08022","0.04378"
"697.44000","58.12021","0.04312"
"697.92000","58.16021","0.04355"
"698.40000","58.20027","0.04242"
"698.88000","58.24020","0.04199"
"699.36000","58.28021","0.04311"
"699.84000","58.32027","0.04358"
"700.32000","58.36027","0.04336"
"700.80000","58.40015","0.04297"
"701.28000","58.44020","0.04259"
"701.76000","58.48020","0.04195"
"702.24000","58.52021","0.04306"
"702.72000","58.56026","0.04326"
"703.20000","58.60026","0.04330"
"703.68000","58.64026","0.04348"
"704.16000","58.68020","0.04295"
"704.64000","58.72026","0.04295"
"705.12000","58.76020","0.04222"
"705.60000","58.80020","0.04176"
"706.08000","58.84019","0.04183"
"706.56000","58.88020","0.04087"
"707.04000","58.92025","0.03842"
"707.52000","58.96019","0.03831"
"708.00000","59.00025","0.03845"
"708.48000","59.04026","0.03904"
"708.96000","59.08025","0.03850"
"709.44000","59.12019","0.03876"
"709.92000","59.16013","0.03739"
"710.40000","59.20019","0.03628"
"710.88000","59.24025","0.03688"
"711.36000","59.28019","0.03664"
"711.84000","59.32025","0.03705"
"712.32000","59.36025","0.03717"
"712.80000","59.40024","0.03726"
"713.11600","59.42655","0.03638"