File: Force_trajectories/170108_1/Specimen_RawData_5.csv
End date,"1/8/2017"
Specimen label,"11AT_NL"
Maximum Load,"0.06823",N

Time,Extension,Load
(s),(mm),(N)
"0.00000","0.00000","-0.00002"
"0.12000","0.00544","0.00032"
"0.24000","0.01836","-0.00017"
"0.36000","0.03001","-0.00004"
"0.48000","0.04024","0.00000"
"0.60000","0.05028","-0.00036"
"0.72000","0.06027","0.00011"
"0.84000","0.07025","0.00044"
"0.96000","0.08012","-0.00049"
"1.08000","0.09022","-0.00019"
"1.20000","0.10021","0.00047"
"1.32000","0.11025","0.00042"
"1.44000","0.12024","0.00003"
"1.56000","0.13022","-0.00022"
"1.68000","0.14027","-0.00011"
"1.80000","0.15019","0.00011"
"1.92000","0.16024","0.00051"
"2.04000","0.17016","0.00027"
"2.16000","0.18021","0.00025"
"2.28000","0.19025","0.00001"
"2.40000","0.20018","0.00008"
"2.52000","0.21022","0.00043"
"2.64000","0.22020","0.00006"
"2.76000","0.23025","0.00023"
"2.88000","0.24017","-0.00006"
"3.00000","0.25016","0.00016"
"3.12000","0.26014","0.00031"
"3.24000","0.27019","0.00041"
"3.36000","0.28023","0.00051"
"3.48000","0.29022","0.00008"
"3.60000","0.30014","0.00022"
"3.72000","0.31019","0.00064"
"3.84000","0.32023","0.00020"
"3.96000","0.33022","0.00030"
"4.08000","0.34020","0.00042"
"4.20000","0.35019","0.00023"
"4.32000","0.36029","0.00048"
"4.44000","0.37022","0.00008"
"4.56000","0.38020","0.00063"
"4.68000","0.39013","0.00066"
"4.80000","0.40017","0.00049"
"4.92000","0.41022","0.00040"
"5.04000","0.42026","0.00002"
"5.16000","0.43019","0.00024"
"5.28000","0.44011","0.00019"
"5.40000","0.45022","0.00008"
"5.52000","0.46020","0.00033"
"5.64000","0.47018","0.00050"
"5.76000","0.48017","0.00042"
"5.88000","0.49021","0.00004"
"6.00000","0.50020","-0.00026"
"6.12000","0.51018","0.00025"
"6.24000","0.52023","0.00031"
"6.36000","0.53015","0.00033"
"6.48000","0.54026","0.00036"
"6.60000","0.55030","0.00032"
"6.72000","0.56023","0.00047"
"6.84000","0.57021","0.00054"
"6.96000","0.58014","0.00040"
"7.08000","0.59024","0.00061"
"7.20000","0.60023","0.00081"
"7.32000","0.61021","0.00035"
"7.44000","0.62020","0.00071"
"7.56000","0.63018","0.00056"
"7.68000","0.64029","0.00032"
"7.80000","0.65021","0.00036"
"7.92000","0.66020","0.00046"
"8.04000","0.67024","0.00005"
"8.16000","0.68023","0.00013"
"8.28000","0.69021","0.00017"
"8.40000","0.70020","0.00063"
"8.52000","0.71012","0.00054"
"8.64000","0.72022","0.00062"
"8.76000","0.73027","0.00028"
"8.88000","0.74025","0.00079"
"9.00000","0.75018","0.00055"
"9.12000","0.76016","0.00038"
"9.24000","0.77015","0.00081"
"9.36000","0.78025","0.00095"
"9.48000","0.79018","0.00083"
"9.60000","0.80016","0.00065"
"9.72000","0.81021","0.00076"
"9.84000","0.82025","0.00001"
"9.96000","0.83024","0.00072"
"10.08000","0.84022","0.00055"
"10.20000","0.85021","0.00078"
"10.32000","0.86025","0.00037"
"10.44000","0.87018","0.00048"
"10.56000","0.88022","0.00054"
"10.68000","0.89021","0.00059"
"10.80000","0.90019","0.00042"
"10.92000","0.91030","0.00036"
"11.04000","0.92022","0.00020"
"11.16000","0.93021","0.00054"
"11.28000","0.94025","0.00091"
"11.40000","0.95024","0.00103"
"11.52000","0.96016","0.00073"
"11.64000","0.97015","0.00070"
"11.76000","0.98013","0.00082"
"11.88000","0.99023","0.00076"
"12.00000","1.00022","0.00041"
"12.12000","1.01020","0.00116"
"12.24000","1.02019","0.00065"
"12.36000","1.03023","0.00055"
"12.48000","1.04028","0.00070"
"12.60000","1.05020","0.00075"
"12.72000","1.06013","0.00089"
"12.84000","1.07017","0.00059"
"12.96000","1.08022","0.00041"
"13.08000","1.09026","0.00098"
"13.20000","1.10025","0.00109"
"13.32000","1.11017","0.00114"
"13.44000","1.12022","0.00107"
"13.56000","1.13020","0.00077"
"13.68000","1.14019","0.00099"
"13.80000","1.15017","0.00087"
"13.92000","1.16022","0.00129"
"14.04000","1.17026","0.00113"
"14.16000","1.18025","0.00102"
"14.28000","1.19023","0.00116"
"14.40000","1.20016","0.00116"
"14.52000","1.21026","0.00084"
"14.64000","1.22030","0.00105"
"14.76000","1.23023","0.00083"
"14.88000","1.24015","0.00089"
"15.00000","1.25014","0.00121"
"15.12000","1.26024","0.00142"
"15.24000","1.27023","0.00094"
"15.36000","1.28021","0.00110"
"15.48000","1.29020","0.00127"
"15.60000","1.30018","0.00150"
"15.72000","1.31023","0.00148"
"15.84000","1.32021","0.00112"
"15.96000","1.33020","0.00076"
"16.08000","1.34024","0.00119"
"16.20000","1.35023","0.00141"
"16.32000","1.36027","0.00152"
"16.44000","1.37020","0.00147"
"16.56000","1.38018","0.00098"
"16.68000","1.39023","0.00136"
"16.80000","1.40027","0.00146"
"16.92000","1.41026","0.00136"
"17.04000","1.42018","0.00141"
"17.16000","1.43017","0.00144"
"17.28000","1.44021","0.00112"
"17.40000","1.45025","0.00124"
"17.52000","1.46024","0.00175"
"17.64000","1.47016","0.00150"
"17.76000","1.48021","0.00104"
"17.88000","1.49019","0.00040"
"18.00000","1.50024","0.00121"
"18.12000","1.51016","0.00094"
"18.24000","1.52021","0.00109"
"18.36000","1.53025","0.00077"
"18.48000","1.54018","0.00164"
"18.60000","1.55022","0.00087"
"18.72000","1.56015","0.00191"
"18.84000","1.57019","0.00126"
"18.96000","1.58024","0.00103"
"19.08000","1.59016","0.00133"
"19.20000","1.60021","0.00109"
"19.32000","1.61019","0.00138"
"19.44000","1.62024","0.00156"
"19.56000","1.63022","0.00156"
"19.68000","1.64021","0.00137"
"19.80000","1.65019","0.00146"
"19.92000","1.66024","0.00121"
"20.04000","1.67016","0.00143"
"20.16000","1.68015","0.00112"
"20.28000","1.69019","0.00161"
"20.40000","1.70018","0.00164"
"20.52000","1.71022","0.00183"
"20.64000","1.72026","0.00252"
"20.76000","1.73019","0.00146"
"20.88000","1.74017","0.00149"
"21.00000","1.75022","0.00222"
"21.12000","1.76020","0.00202"
"21.24000","1.77025","0.00188"
"21.36000","1.78017","0.00183"
"21.48000","1.79022","0.00175"
"21.60000","1.80020","0.00200"
"21.72000","1.81025","0.00176"
"21.84000","1.82023","0.00217"
"21.96000","1.83022","0.00242"
"22.08000","1.84026","0.00262"
"22.20000","1.85019","0.00227"
"22.32000","1.86017","0.00198"
"22.44000","1.87016","0.00251"
"22.56000","1.88020","0.00282"
"22.68000","1.89025","0.00227"
"22.80000","1.90029","0.00241"
"22.92000","1.91022","0.00277"
"23.04000","1.92020","0.00221"
"23.16000","1.93025","0.00244"
"23.28000","1.94023","0.00299"
"23.40000","1.95022","0.00298"
"23.52000","1.96020","0.00281"
"23.64000","1.97018","0.00265"
"23.76000","1.98023","0.00256"
"23.88000","1.99021","0.00306"
"24.00000","2.00020","0.00324"
"24.12000","2.01024","0.00320"
"24.24000","2.02023","0.00332"
"24.36000","2.03021","0.00307"
"24.48000","2.04020","0.00351"
"24.60000","2.05018","0.00372"
"24.72000","2.06017","0.00320"
"24.84000","2.07027","0.00300"
"24.96000","2.08026","0.00297"
"25.08000","2.09018","0.00315"
"25.20000","2.10011","0.00362"
"25.32000","2.11021","0.00324"
"25.44000","2.12026","0.00432"
"25.56000","2.13024","0.00339"
"25.68000","2.14017","0.00365"
"25.80000","2.15021","0.00425"
"25.92000","2.16020","0.00367"
"26.04000","2.17024","0.00359"
"26.16000","2.18017","0.00361"
"26.28000","2.19021","0.00411"
"26.40000","2.20020","0.00448"
"26.52000","2.21018","0.00398"
"26.64000","2.22016","0.00481"
"26.76000","2.23015","0.00408"
"26.88000","2.24019","0.00455"
"27.00000","2.25024","0.00468"
"27.12000","2.26022","0.00464"
"27.24000","2.27021","0.00477"
"27.36000","2.28019","0.00445"
"27.48000","2.29024","0.00461"
"27.60000","2.30022","0.00523"
"27.72000","2.31027","0.00540"
"27.84000","2.32019","0.00566"
"27.96000","2.33024","0.00528"
"28.08000","2.34022","0.00557"
"28.20000","2.35021","0.00535"
"28.32000","2.36019","0.00549"
"28.44000","2.37018","0.00595"
"28.56000","2.38022","0.00581"
"28.68000","2.39021","0.00629"
"28.80000","2.40013","0.00612"
"28.92000","2.41012","0.00675"
"29.04000","2.42022","0.00618"
"29.16000","2.43027","0.00695"
"29.28000","2.44025","0.00646"
"29.40000","2.45017","0.00703"
"29.52000","2.46016","0.00713"
"29.64000","2.47020","0.00740"
"29.76000","2.48019","0.00777"
"29.88000","2.49023","0.00766"
"30.00000","2.50016","0.00750"
"30.12000","2.51026","0.00790"
"30.24000","2.52019","0.00746"
"30.36000","2.53023","0.00833"
"30.48000","2.54022","0.00833"
"30.60000","2.55020","0.00838"
"30.72000","2.56025","0.00864"
"30.84000","2.57023","0.00916"
"30.96000","2.58022","0.00911"
"31.08000","2.59014","0.00919"
"31.20000","2.60025","0.00961"
"31.32000","2.61023","0.00974"
"31.44000","2.62028","0.00984"
"31.56000","2.63020","0.01000"
"31.68000","2.64019","0.00977"
"31.80000","2.65023","0.01058"
"31.92000","2.66022","0.01066"
"32.04000","2.67020","0.01075"
"32.16000","2.68013","0.01032"
"32.28000","2.69023","0.01086"
"32.40000","2.70021","0.01132"
"32.52000","2.71020","0.01217"
"32.64000","2.72018","0.01181"
"32.76000","2.73017","0.01185"
"32.88000","2.74027","0.01224"
"33.00000","2.75026","0.01289"
"33.12000","2.76018","0.01292"
"33.24000","2.77017","0.01265"
"33.36000","2.78021","0.01325"
"33.48000","2.79020","0.01386"
"33.60000","2.80024","0.01355"
"33.72000","2.81023","0.01445"
"33.84000","2.82021","0.01428"
"33.96000","2.83020","0.01482"
"34.08000","2.84024","0.01465"
"34.20000","2.85023","0.01525"
"34.32000","2.86015","0.01507"
"34.44000","2.87020","0.01577"
"34.56000","2.88024","0.01538"
"34.68000","2.89023","0.01332"
"34.80000","2.90021","0.01279"
"34.92000","2.91020","0.00968"
"35.04000","2.92024","0.00980"
"35.16000","2.93023","0.00982"
"35.28000","2.94021","0.01110"
"35.40000","2.95014","0.01143"
"35.52000","2.96024","0.01240"
"35.64000","2.97022","0.01166"
"35.76000","2.98027","0.01144"
"35.88000","2.99019","0.01159"
"36.00000","3.00018","0.01190"
"36.12000","3.01022","0.01260"
"36.24000","3.02021","0.01253"
"36.36000","3.03019","0.01223"
"36.48000","3.04018","0.01254"
"36.60000","3.05016","0.01331"
"36.72000","3.06021","0.01382"
"36.84000","3.07019","0.01392"
"36.96000","3.08012","0.01426"
"37.08000","3.09016","0.01409"
"37.20000","3.10021","0.01453"
"37.32000","3.11025","0.01509"
"37.44000","3.12018","0.01558"
"37.56000","3.13010","0.01587"
"37.68000","3.14021","0.01542"
"37.80000","3.15019","0.01629"
"37.92000","3.16018","0.01642"
"38.04000","3.17022","0.01720"
"38.16000","3.18021","0.01693"
"38.28000","3.19019","0.01748"
"38.40000","3.20023","0.01768"
"38.52000","3.21022","0.01782"
"38.64000","3.22020","0.01905"
"38.76000","3.23025","0.01845"
"38.88000","3.24023","0.01893"
"39.00000","3.25022","0.01944"
"39.12000","3.26014","0.01997"
"39.24000","3.27019","0.01903"
"39.36000","3.28023","0.01930"
"39.48000","3.29016","0.02016"
"39.60000","3.30020","0.02025"
"39.72000","3.31013","0.02077"
"39.84000","3.32023","0.02244"
"39.96000","3.33028","0.02294"
"40.08000","3.34026","0.02253"
"40.20000","3.35019","0.02262"
"40.32000","3.36023","0.02394"
"40.44000","3.37028","0.02384"
"40.56000","3.38020","0.02444"
"40.68000","3.39019","0.02497"
"40.80000","3.40011","0.02533"
"40.92000","3.41028","0.02439"
"41.04000","3.42026","0.02576"
"41.16000","3.43024","0.02610"
"41.28000","3.44017","0.02683"
"41.40000","3.45016","0.02758"
"41.52000","3.46026","0.02790"
"41.64000","3.47024","0.02805"
"41.76000","3.48023","0.02867"
"41.88000","3.49015","0.02878"
"42.00000","3.50020","0.02922"
"42.12000","3.51024","0.02973"
"42.24000","3.52023","0.03051"
"42.36000","3.53015","0.03085"
"42.48000","3.54020","0.03085"
"42.60000","3.55024","0.03128"
"42.72000","3.56023","0.03180"
"42.84000","3.57015","0.03214"
"42.96000","3.58014","0.03226"
"43.08000","3.59024","0.03270"
"43.20000","3.60029","0.03318"
"43.32000","3.61021","0.03341"
"43.44000","3.62014","0.03339"
"43.56000","3.63018","0.03372"
"43.68000","3.64023","0.03414"
"43.80000","3.65021","0.03397"
"43.92000","3.66014","0.03457"
"44.04000","3.67012","0.03479"
"44.16000","3.68022","0.03486"
"44.28000","3.69027","0.03520"
"44.40000","3.70019","0.03530"
"44.52000","3.71018","0.03546"
"44.64000","3.72022","0.03558"
"44.76000","3.73027","0.03600"
"44.88000","3.74019","0.03627"
"45.00000","3.75018","0.03660"
"45.12000","3.76016","0.03681"
"45.24000","3.77027","0.03679"
"45.36000","3.78025","0.03666"
"45.48000","3.79024","0.03598"
"45.60000","3.80016","0.03642"
"45.72000","3.81021","0.03681"
"45.84000","3.82025","0.03676"
"45.96000","3.83018","0.03743"
"46.08000","3.84022","0.03779"
"46.20000","3.85021","0.03825"
"46.32000","3.86025","0.03835"
"46.44000","3.87024","0.03838"
"46.56000","3.88016","0.03894"
"46.68000","3.89021","0.03891"
"46.80000","3.90025","0.03950"
"46.92000","3.91030","0.03949"
"47.04000","3.92022","0.04065"
"47.16000","3.93015","0.03982"
"47.28000","3.94019","0.04188"
"47.40000","3.95023","0.04193"
"47.52000","3.96022","0.04236"
"47.64000","3.97020","0.04215"
"47.76000","3.98013","0.04370"
"47.88000","3.99023","0.04338"
"48.00000","4.00022","0.04448"
"48.12000","4.01020","0.04382"
"48.24000","4.02019","0.04501"
"48.36000","4.03023","0.04569"
"48.48000","4.04022","0.04575"
"48.60000","4.05026","0.04635"
"48.72000","4.06019","0.04689"
"48.84000","4.07011","0.04823"
"48.96000","4.08022","0.04879"
"49.08000","4.09026","0.04828"
"49.20000","4.10019","0.04889"
"49.32000","4.11017","0.04896"
"49.44000","4.12010","0.05019"
"49.56000","4.13026","0.05148"
"49.68000","4.14025","0.05169"
"49.80000","4.15023","0.05236"
"49.92000","4.16016","0.05314"
"50.04000","4.17020","0.05365"
"50.16000","4.18018","0.05383"
"50.28000","4.19017","0.05582"
"50.40000","4.20015","0.05586"
"50.52000","4.21020","0.05615"
"50.64000","4.22024","0.05704"
"50.76000","4.23023","0.05765"
"50.88000","4.24015","0.05762"
"51.00000","4.25014","0.05688"
"51.12000","4.26024","0.05687"
"51.24000","4.27023","0.05740"
"51.36000","4.28021","0.05677"
"51.48000","4.29020","0.05396"
"51.60000","4.30018","0.05383"
"51.72000","4.31023","0.05423"
"51.84000","4.32027","0.05447"
"51.96000","4.33020","0.05548"
"52.08000","4.34018","0.05673"
"52.20000","4.35017","0.05711"
"52.32000","4.36015","0.05762"
"52.44000","4.37020","0.05761"
"52.56000","4.38018","0.05751"
"52.68000","4.39023","0.05818"
"52.80000","4.40027","0.05855"
"52.92000","4.41026","0.05894"
"53.04000","4.42024","0.05955"
"53.16000","4.43016","0.05954"
"53.28000","4.44027","0.05975"
"53.40000","4.45025","0.06018"
"53.52000","4.46024","0.06031"
"53.64000","4.47022","0.06103"
"53.76000","4.48015","0.06192"
"53.88000","4.49019","0.06262"
"54.00000","4.50024","0.06287"
"54.12000","4.51022","0.06343"
"54.24000","4.52021","0.06360"
"54.36000","4.53019","0.06413"
"54.48000","4.54018","0.06455"
"54.60000","4.55016","0.06458"
"54.72000","4.56021","0.06557"
"54.84000","4.57019","0.06413"
"54.96000","4.58024","0.06384"
"55.08000","4.59022","0.06414"
"55.20000","4.60021","0.06458"
"55.32000","4.61019","0.06478"
"55.44000","4.62018","0.06509"
"55.56000","4.63022","0.06594"
"55.68000","4.64021","0.06638"
"55.80000","4.65013","0.06703"
"55.92000","4.66024","0.06759"
"56.04000","4.67022","0.06743"
"56.16000","4.68026","0.06802"
"56.28000","4.69019","0.06733"
"56.40000","4.70017","0.06502"
"56.52000","4.71028","0.06129"
"56.64000","4.72020","0.05890"
"56.76000","4.73019","0.05659"
"56.88000","4.74017","0.05571"
"57.00000","4.75022","0.05387"
"57.12000","4.76026","0.04960"
"57.24000","4.77025","0.04581"
"57.36000","4.78017","0.04287"
"57.48000","4.79010","0.04190"
"57.60000","4.80020","0.04236"
"57.72000","4.81025","0.04177"
"57.84000","4.82023","0.04009"
"57.96000","4.83016","0.03876"
"58.08000","4.84020","0.03875"
"58.20000","4.85025","0.03870"
"58.32000","4.86023","0.03856"
"58.44000","4.87022","0.03829"
"58.56000","4.88020","0.03862"
"58.68000","4.89019","0.03913"
"58.80000","4.90023","0.04015"
"58.92000","4.91021","0.04030"
"59.04000","4.92020","0.04083"
"59.16000","4.93018","0.04063"
"59.28000","4.94023","0.03885"
"59.40000","4.95027","0.03823"
"59.52000","4.96020","0.03861"
"59.64000","4.97018","0.03859"
"59.76000","4.98023","0.03782"
"59.88000","4.99021","0.03778"
"60.00000","5.00026","0.03772"
"60.12000","5.01018","0.03731"
"60.24000","5.02017","0.03661"
"60.36000","5.03021","0.03687"
"60.48000","5.04026","0.03718"
"60.60000","5.05018","0.03734"
"60.72000","5.06023","0.03750"
"60.84000","5.07021","0.03658"
"60.96000","5.08026","0.02010"
"61.08000","5.09024","0.00838"
"61.20000","5.10017","0.01004"
"61.32000","5.11021","0.01175"
"61.44000","5.12026","0.01244"
"61.56000","5.13024","0.00818"
"61.68000","5.14023","0.00938"
"61.80000","5.15015","0.01145"
"61.92000","5.16020","0.01075"
"62.04000","5.17018","0.01364"
"62.16000","5.18023","0.01386"
"62.28000","5.19021","0.01267"
"62.40000","5.20019","0.01248"
"62.52000","5.21024","0.01250"
"62.64000","5.22022","0.01384"
"62.76000","5.23021","0.01558"
"62.88000","5.24019","0.01649"
"63.00000","5.25024","0.01470"
"63.12000","5.26022","0.01475"
"63.24000","5.27021","0.01526"
"63.36000","5.28019","0.01603"
"63.48000","5.29018","0.01782"
"63.60000","5.30022","0.01822"
"63.72000","5.31027","0.01722"
"63.84000","5.32019","0.01781"
"63.96000","5.33018","0.01858"
"64.08000","5.34022","0.01910"
"64.20000","5.35027","0.02050"
"64.32000","5.36019","0.02089"
"64.44000","5.37018","0.02021"
"64.56000","5.38022","0.02089"
"64.68000","5.39021","0.02171"
"64.80000","5.40019","0.02318"
"64.92000","5.41018","0.02409"
"65.04000","5.42022","0.02391"
"65.16000","5.43026","0.02440"
"65.28000","5.44025","0.02501"
"65.40000","5.45017","0.02536"
"65.52000","5.46016","0.02787"
"65.64000","5.47020","0.02719"
"65.76000","5.48025","0.02844"
"65.88000","5.49029","0.02785"
"66.00000","5.50022","0.02896"
"66.12000","5.51020","0.02889"
"66.24000","5.52025","0.03017"
"66.36000","5.53023","0.03050"
"66.48000","5.54022","0.03061"
"66.60000","5.55014","0.03102"
"66.72000","5.56025","0.03183"
"66.84000","5.57023","0.03244"
"66.96000","5.58022","0.03233"
"67.08000","5.59020","0.03274"
"67.20000","5.60025","0.03307"
"67.32000","5.61029","0.03360"
"67.44000","5.62028","0.03397"
"67.56000","5.63020","0.03412"
"67.68000","5.64013","0.03435"
"67.80000","5.65017","0.03453"
"67.92000","5.66022","0.03479"
"68.04000","5.67026","0.03519"
"68.16000","5.68013","0.03554"
"68.28000","5.69017","0.03551"
"68.40000","5.70021","0.03585"
"68.52000","5.71026","0.03620"
"68.64000","5.72018","0.03697"
"68.76000","5.73023","0.03720"
"68.88000","5.74027","0.03693"
"69.00000","5.75026","0.03713"
"69.12000","5.76018","0.03769"
"69.24000","5.77017","0.03840"
"69.36000","5.78021","0.03860"
"69.48000","5.79026","0.03926"
"69.60000","5.80024","0.03934"
"69.72000","5.81017","0.04051"
"69.84000","5.82009","0.04145"
"69.96000","5.83020","0.04197"
"70.08000","5.84018","0.04270"
"70.20000","5.85023","0.04298"
"70.32000","5.86021","0.04441"
"70.44000","5.87020","0.04459"
"70.56000","5.88024","0.04567"
"70.68000","5.89023","0.04670"
"70.80000","5.90021","0.04771"
"70.92000","5.91020","0.04857"
"71.04000","5.92018","0.04916"
"71.16000","5.93022","0.05021"
"71.28000","5.94021","0.05055"
"71.40000","5.95019","0.05159"
"71.52000","5.96018","0.05227"
"71.64000","5.97028","0.05301"
"71.76000","5.98021","0.05330"
"71.88000","5.99019","0.05398"
"72.00000","6.00018","0.05515"
"72.12000","6.01028","0.05551"
"72.24000","6.02027","0.05554"
"72.36000","6.03019","0.05676"
"72.48000","6.04018","0.05746"
"72.60000","6.05016","0.05832"
"72.72000","6.06021","0.05837"
"72.84000","6.07019","0.05936"
"72.96000","6.08018","0.05934"
"73.08000","6.09016","0.06005"
"73.20000","6.10027","0.06020"
"73.32000","6.11025","0.06084"
"73.44000","6.12024","0.06087"
"73.56000","6.13016","0.06161"
"73.68000","6.14021","0.06296"
"73.80000","6.15025","0.06275"
"73.92000","6.16024","0.06292"
"74.04000","6.17022","0.06389"
"74.16000","6.18020","0.06388"
"74.28000","6.19025","0.01631"
"74.40000","6.20023","0.01392"
"74.52000","6.21022","0.01350"
"74.64000","6.22014","0.01501"
"74.76000","6.23019","0.01543"
"74.88000","6.24023","0.01592"
"75.00000","6.25022","0.01529"
"75.12000","6.26020","0.01429"
"75.24000","6.27013","0.01575"
"75.36000","6.28023","0.01599"
"75.48000","6.29028","0.01580"
"75.60000","6.30020","0.01639"
"75.72000","6.31019","0.01599"
"75.84000","6.32017","0.01595"
"75.96000","6.33022","0.01707"
"76.08000","6.34020","0.01640"
"76.20000","6.35013","0.01660"
"76.32000","6.36017","0.01752"
"76.44000","6.37022","0.01717"
"76.56000","6.38026","0.01750"
"76.68000","6.39025","0.01791"
"76.80000","6.40017","0.01793"
"76.92000","6.41021","0.01779"
"77.04000","6.42026","0.01798"
"77.16000","6.43019","0.01803"
"77.28000","6.44017","0.01851"
"77.40000","6.45015","0.01901"
"77.52000","6.46020","0.01838"
"77.64000","6.47024","0.01858"
"77.76000","6.48023","0.01923"
"77.88000","6.49015","0.01895"
"78.00000","6.50020","0.01868"
"78.12000","6.51018","0.01959"
"78.24000","6.52023","0.01954"
"78.36000","6.53021","0.01895"
"78.48000","6.54020","0.02050"
"78.60000","6.55024","0.02006"
"78.72000","6.56023","0.01983"
"78.84000","6.57021","0.01979"
"78.96000","6.58020","0.01968"
"79.08000","6.59024","0.02012"
"79.20000","6.60029","0.02074"
"79.32000","6.61021","0.02037"
"79.44000","6.62020","0.01963"
"79.56000","6.63018","0.02028"
"79.68000","6.64023","0.02060"
"79.80000","6.65021","0.02050"
"79.92000","6.66019","0.02118"
"80.04000","6.67018","0.02026"
"80.16000","6.68016","0.02058"
"80.28000","6.69021","0.02107"
"80.40000","6.70019","0.02124"
"80.52000","6.71018","0.02191"
"80.64000","6.72022","0.02114"
"80.76000","6.73027","0.02165"
"80.88000","6.74019","0.02183"
"81.00000","6.75018","0.02179"
"81.12000","6.76016","0.02176"
"81.24000","6.77021","0.02228"
"81.36000","6.78025","0.02220"
"81.48000","6.79024","0.02205"
"81.60000","6.80016","0.02212"
"81.72000","6.81021","0.02184"
"81.84000","6.82025","0.02293"
"81.96000","6.83024","0.02243"
"82.08000","6.84022","0.02195"
"82.20000","6.85015","0.02295"
"82.32000","6.86025","0.02306"
"82.44000","6.87018","0.02276"
"82.56000","6.88016","0.02325"
"82.68000","6.89021","0.02344"
"82.80000","6.90025","0.02346"
"82.92000","6.91024","0.02293"
"83.04000","6.92022","0.02323"
"83.16000","6.93020","0.02326"
"83.28000","6.94013","0.02387"
"83.40000","6.95023","0.02394"
"83.52000","6.96022","0.02403"
"83.64000","6.97020","0.02393"
"83.76000","6.98019","0.02418"
"83.88000","6.99017","0.02366"
"84.00000","7.00028","0.01850"
"84.12000","7.01020","0.01495"
"84.24000","7.02025","0.01088"
"84.36000","7.03017","0.00969"
"84.48000","7.04016","0.00956"
"84.60000","7.05020","0.01062"
"84.72000","7.06019","0.01085"
"84.84000","7.07017","0.01070"
"84.96000","7.08022","0.01046"
"85.08000","7.09020","0.01044"
"85.20000","7.10025","0.01093"
"85.32000","7.11017","0.01208"
"85.44000","7.12010","0.01111"
"85.56000","7.13020","0.01102"
"85.68000","7.14025","0.01126"
"85.80000","7.15023","0.01128"
"85.92000","7.16016","0.01152"
"86.04000","7.17014","0.01173"
"86.16000","7.18024","0.01241"
"86.28000","7.19023","0.01236"
"86.40000","7.20027","0.01246"
"86.52000","7.21020","0.01206"
"86.64000","7.22018","0.01256"
"86.76000","7.23017","0.01253"
"86.88000","7.24021","0.01376"
"87.00000","7.25020","0.01312"
"87.12000","7.26018","0.01321"
"87.24000","7.27023","0.01281"
"87.36000","7.28021","0.01316"
"87.48000","7.29020","0.01359"
"87.60000","7.30018","0.01419"
"87.72000","7.31023","0.01394"
"87.84000","7.32021","0.01399"
"87.96000","7.33020","0.01389"
"88.08000","7.34018","0.01422"
"88.20000","7.35017","0.01372"
"88.32000","7.36021","0.01443"
"88.44000","7.37026","0.01500"
"88.56000","7.38024","0.01493"
"88.68000","7.39023","0.01516"
"88.80000","7.40021","0.01465"
"88.92000","7.41020","0.01534"
"89.04000","7.42018","0.01493"
"89.16000","7.43017","0.01507"
"89.28000","7.44021","0.01464"
"89.40000","7.45025","0.01468"
"89.52000","7.46024","0.01551"
"89.64000","7.47016","0.01487"
"89.76000","7.48015","0.01480"
"89.88000","7.49019","0.01522"
"90.00000","7.50024","0.01520"
"90.12000","7.51022","0.01571"
"90.24000","7.52015","0.01606"
"90.36000","7.53019","0.01549"
"90.48000","7.54024","0.01593"
"90.60000","7.55022","0.01589"
"90.72000","7.56021","0.01541"
"90.84000","7.57019","0.01556"
"90.96000","7.58024","0.01507"
"91.08000","7.59022","0.01500"
"91.20000","7.60021","0.01494"
"91.32000","7.61019","0.01510"
"91.44000","7.62018","0.01480"
"91.56000","7.63022","0.01532"
"91.68000","7.64021","0.01576"
"91.80000","7.65019","0.01554"
"91.92000","7.66018","0.01561"
"92.04000","7.67028","0.01540"
"92.16000","7.68021","0.01534"
"92.28000","7.69025","0.01552"
"92.40000","7.70018","0.01583"
"92.52000","7.71016","0.01565"
"92.64000","7.72026","0.01583"
"92.76000","7.73025","0.01625"
"92.88000","7.74017","0.01606"
"93.00000","7.75022","0.01661"
"93.12000","7.76020","0.01670"
"93.24000","7.77019","0.01658"
"93.36000","7.78017","0.01666"
"93.48000","7.79016","0.01628"
"93.60000","7.80020","0.01724"
"93.72000","7.81025","0.01729"
"93.84000","7.82029","0.01682"
"93.96000","7.83016","0.01699"
"94.08000","7.84014","0.01736"
"94.20000","7.85025","0.01733"
"94.32000","7.86023","0.01716"
"94.44000","7.87028","0.01740"
"94.56000","7.88020","0.01770"
"94.68000","7.89024","0.01756"
"94.80000","7.90017","0.01774"
"94.92000","7.91021","0.01796"
"95.04000","7.92020","0.01830"
"95.16000","7.93018","0.01870"
"95.28000","7.94023","0.01808"
"95.40000","7.95021","0.01907"
"95.52000","7.96020","0.01880"
"95.64000","7.97012","0.01907"
"95.76000","7.98023","0.01905"
"95.88000","7.99027","0.01882"
"96.00000","8.00026","0.01916"
"96.12000","8.01024","0.01964"
"96.24000","8.02011","0.01994"
"96.36000","8.03027","0.01968"
"96.48000","8.04020","0.01948"
"96.60000","8.05024","0.02021"
"96.72000","8.06023","0.01983"
"96.84000","8.07021","0.02040"
"96.96000","8.08026","0.02006"
"97.08000","8.09024","0.01964"
"97.20000","8.10017","0.01955"
"97.32000","8.11021","0.00958"
"97.44000","8.12026","0.00072"
"97.56000","8.13024","-0.00029"
"97.68000","8.14017","-0.00025"
"97.80000","8.15015","-0.00064"
"97.92000","8.16020","-0.00072"
"98.04000","8.17024","-0.00128"
"98.16000","8.18022","-0.00119"
"98.28000","8.19021","-0.00084"
"98.40000","8.20019","-0.00046"
"98.52000","8.21018","-0.00040"
"98.64000","8.22022","-0.00005"
"98.76000","8.23015","-0.00023"
"98.88000","8.24013","-0.00029"
"99.00000","8.25024","-0.00049"
"99.12000","8.26022","-0.00087"
"99.24000","8.27027","-0.00084"
"99.36000","8.28019","-0.00111"
"99.48000","8.29018","-0.00089"
"99.60000","8.30028","-0.00062"
"99.72000","8.31027","-0.00009"
"99.84000","8.32019","-0.00059"
"99.96000","8.33012","-0.00093"
"100.08000","8.34022","-0.00100"
"100.20000","8.35021","-0.00090"
"100.32000","8.36025","-0.00043"
"100.44000","8.37018","-0.00084"
"100.56000","8.38016","-0.00068"
"100.68000","8.39027","-0.00069"
"100.80000","8.40025","-0.00087"
"100.92000","8.41018","-0.00073"
"101.04000","8.42016","-0.00058"
"101.16000","8.43020","-0.00047"
"101.28000","8.44025","-0.00078"
"101.40000","8.45017","-0.00068"
"101.52000","8.46016","-0.00106"
"101.64000","8.47020","-0.00093"
"101.76000","8.48019","-0.00084"
"101.88000","8.49023","-0.00037"
"102.00000","8.50016","-0.00076"
"102.12000","8.51014","-0.00101"
"102.24000","8.52019","0.00000"
"102.36000","8.53023","-0.00068"
"102.48000","8.54028","-0.00049"
"102.60000","8.55020","-0.00074"
"102.72000","8.56019","-0.00086"
"102.84000","8.57023","-0.00058"
"102.96000","8.58028","-0.00085"
"103.08000","8.59020","-0.00050"
"103.20000","8.60019","-0.00123"
"103.32000","8.61017","-0.00092"
"103.44000","8.62022","-0.00065"
"103.56000","8.63026","-0.00083"
"103.68000","8.64019","-0.00053"
"103.80000","8.65017","-0.00043"
"103.92000","8.66022","-0.00055"
"104.04000","8.67026","-0.00095"
"104.16000","8.68024","-0.00061"
"104.28000","8.69011","-0.00133"
"104.40000","8.70027","-0.00046"
"104.52000","8.71020","-0.00081"
"104.64000","8.72024","-0.00117"
"104.76000","8.73017","-0.00068"
"104.88000","8.74015","-0.00043"
"105.00000","8.75020","-0.00012"
"105.12000","8.76018","-0.00063"
"105.24000","8.77017","-0.00089"
"105.36000","8.78015","-0.00086"
"105.48000","8.79026","-0.00086"
"105.60000","8.80024","-0.00088"
"105.72000","8.81023","-0.00067"
"105.84000","8.82021","-0.00092"
"105.96000","8.83020","-0.00096"
"106.08000","8.84024","-0.00051"
"106.20000","8.85023","-0.00038"
"106.32000","8.86021","-0.00046"
"106.44000","8.87014","-0.00056"
"106.56000","8.88018","-0.00066"
"106.68000","8.89023","-0.00070"
"106.80000","8.90021","-0.00090"
"106.92000","8.91020","-0.00064"
"107.04000","8.92024","-0.00125"
"107.16000","8.93022","-0.00085"
"107.28000","8.94021","-0.00065"
"107.40000","8.95019","-0.00016"
"107.52000","8.96018","-0.00032"
"107.64000","8.97028","-0.00077"
"107.76000","8.98027","-0.00097"
"107.88000","8.99025","-0.00082"
"108.00000","9.00012","-0.00086"
"108.12000","9.01022","-0.00038"
"108.24000","9.02021","-0.00081"
"108.36000","9.03019","-0.00133"
"108.48000","9.04018","-0.00090"
"108.60000","9.05016","-0.00119"
"108.72000","9.06021","-0.00054"
"108.84000","9.07025","-0.00026"
"108.96000","9.08024","-0.00060"
"109.08000","9.09016","-0.00113"
"109.20000","9.10021","-0.00032"
"109.32000","9.11025","-0.00094"
"109.44000","9.12024","-0.00092"
"109.56000","9.13016","-0.00076"
"109.68000","9.14015","-0.00051"
"109.80000","9.15025","-0.00050"
"109.92000","9.16029","-0.00034"
"110.04000","9.17028","-0.00088"
"110.16000","9.18014","-0.00085"
"110.28000","9.19019","-0.00105"
"110.40000","9.20023","-0.00067"
"110.52000","9.21022","-0.00127"
"110.64000","9.22020","-0.00060"
"110.76000","9.23019","-0.00083"
"110.88000","9.24017","-0.00078"
"111.00000","9.25022","-0.00117"
"111.12000","9.26020","-0.00037"
"111.24000","9.27013","-0.00060"
"111.36000","9.28023","-0.00079"
"111.48000","9.29022","-0.00048"
"111.60000","9.30020","-0.00060"
"111.72000","9.31019","-0.00080"
"111.84000","9.32017","-0.00075"
"111.96000","9.33022","-0.00092"
"112.08000","9.34020","-0.00049"
"112.20000","9.35025","-0.00070"
"112.32000","9.36017","-0.00068"
"112.44000","9.37022","-0.00021"
"112.56000","9.38020","-0.00019"
"112.68000","9.39025","-0.00025"
"112.80000","9.40023","-0.00068"
"112.92000","9.41021","-0.00063"
"113.04000","9.42026","-0.00090"
"113.16000","9.43019","-0.00097"
"113.28000","9.44023","-0.00103"
"113.40000","9.45015","-0.00077"
"113.52000","9.46020","-0.00057"
"113.64000","9.47024","-0.00027"
"113.76000","9.48017","-0.00008"
"113.88000","9.49015","-0.00078"
"114.00000","9.50014","-0.00066"
"114.12000","9.51024","-0.00104"
"114.24000","9.52029","-0.00137"
"114.36000","9.53027","-0.00082"
"114.48000","9.54020","-0.00082"
"114.60000","9.55018","-0.00055"
"114.72000","9.56023","-0.00073"
"114.84000","9.57021","-0.00095"
"114.96000","9.58020","0.00004"
"115.08000","9.59018","-0.00058"
"115.20000","9.60023","-0.00041"
"115.32000","9.61021","-0.00086"
"115.44000","9.62020","-0.00048"
"115.56000","9.63024","-0.00096"
"115.68000","9.64023","-0.00105"
"115.80000","9.65021","-0.00088"
"115.92000","9.66026","-0.00116"
"116.04000","9.67018","-0.00047"
"116.16000","9.68022","-0.00031"
"116.28000","9.69027","-0.00032"
"116.40000","9.70025","-0.00059"
"116.52000","9.71024","-0.00055"
"116.64000","9.72016","-0.00049"
"116.76000","9.73027","-0.00090"
"116.88000","9.74019","-0.00059"
"117.00000","9.75024","-0.00091"
"117.12000","9.76016","-0.00060"
"117.24000","9.77021","-0.00048"
"117.36000","9.78025","-0.00051"
"117.48000","9.79024","-0.00074"
"117.60000","9.80016","-0.00077"
"117.72000","9.81015","-0.00087"
"117.84000","9.82025","-0.00086"
"117.96000","9.83024","-0.00086"
"118.08000","9.84028","-0.00077"
"118.20000","9.85021","-0.00080"
"118.32000","9.86013","-0.00052"
"118.44000","9.87030","-0.00042"
"118.56000","9.88028","-0.00030"
"118.68000","9.89026","-0.00012"
"118.80000","9.90019","-0.00063"
"118.92000","9.91017","-0.00049"
"119.04000","9.92016","-0.00094"
"119.16000","9.93020","-0.00057"
"119.28000","9.94013","-0.00080"
"119.40000","9.95023","-0.00043"
"119.52000","9.96022","-0.00074"
"119.64000","9.97026","-0.00053"
"119.76000","9.98019","-0.00049"
"119.88000","9.99017","-0.00019"
"120.00000","10.00016","-0.00051"
"120.12000","10.01020","-0.00057"
"120.24000","10.02025","-0.00073"
"120.36000","10.03017","-0.00085"
"120.48000","10.04016","-0.00103"
"120.60000","10.05020","-0.00084"
"120.72000","10.06025","-0.00070"
"120.84000","10.07023","-0.00060"
"120.96000","10.08016","-0.00038"
"121.08000","10.09020","-0.00036"
"121.20000","10.10019","-0.00040"
"121.32000","10.11023","-0.00067"
"121.44000","10.12022","-0.00050"
"121.56000","10.13020","-0.00014"
"121.68000","10.14031","-0.00066"
"121.80000","10.15023","-0.00053"
"121.92000","10.16015","-0.00015"
"122.04000","10.17014","-0.00039"
"122.16000","10.18018","-0.00025"
"122.28000","10.19023","0.00047"
"122.40000","10.20027","-0.00001"
"122.52000","10.21020","-0.00042"
"122.64000","10.22018","-0.00077"
"122.76000","10.23023","-0.00034"
"122.88000","10.24027","-0.00094"
"123.00000","10.25020","-0.00038"
"123.12000","10.26018","-0.00081"
"123.24000","10.27023","-0.00040"
"123.36000","10.28021","-0.00024"
"123.48000","10.29020","0.00072"
"123.60000","10.30018","-0.00037"
"123.72000","10.31017","-0.00024"
"123.84000","10.32021","-0.00052"
"123.96000","10.33020","-0.00093"
"124.08000","10.34018","-0.00050"
"124.20000","10.35023","-0.00042"
"124.32000","10.36021","-0.00030"
"124.44000","10.37025","-0.00022"
"124.56000","10.38024","-0.00047"
"124.68000","10.39017","-0.00029"
"124.80000","10.40021","0.00005"
"124.92000","10.41019","0.00017"
"125.04000","10.42024","0.00007"
"125.16000","10.43016","-0.00025"
"125.28000","10.44021","-0.00074"
"125.40000","10.45025","-0.00047"
"125.52000","10.46024","-0.00070"
"125.64000","10.47022","-0.00086"
"125.76000","10.48015","0.00007"
"125.88000","10.49019","0.00030"
"126.00000","10.50024","0.00006"
"126.12000","10.51028","-0.00072"
"126.24000","10.52015","-0.00080"
"126.36000","10.53013","-0.00108"
"126.48000","10.54024","-0.00067"
"126.60000","10.55022","-0.00009"
"126.72000","10.56027","-0.00084"
"126.84000","10.57019","-0.00050"
"126.96000","10.58018","-0.00020"
"127.08000","10.59022","-0.00011"
"127.20000","10.60027","0.00002"
"127.32000","10.61019","-0.00023"
"127.44000","10.62018","-0.00048"
"127.56000","10.63022","-0.00089"
"127.68000","10.64027","-0.00039"
"127.80000","10.65019","-0.00073"
"127.92000","10.66018","-0.00026"
"128.04000","10.67016","-0.00033"
"128.16000","10.68020","-0.00023"
"128.28000","10.69025","-0.00028"
"128.40000","10.70017","0.00004"
"128.52000","10.71016","-0.00051"
"128.64000","10.72020","-0.00079"
"128.76000","10.73025","-0.00080"
"128.88000","10.74023","-0.00038"
"129.00000","10.75022","-0.00040"
"129.12000","10.76020","-0.00071"
"129.24000","10.77019","-0.00004"
"129.36000","10.78023","0.00000"
"129.48000","10.79022","-0.00027"
"129.60000","10.80020","-0.00031"
"129.72000","10.81025","-0.00048"
"129.84000","10.82023","-0.00053"
"129.96000","10.83016","-0.00031"
"130.08000","10.84014","-0.00038"
"130.20000","10.85019","-0.00072"
"130.32000","10.86023","-0.00019"
"130.44000","10.87022","-0.00032"
"130.56000","10.88020","-0.00084"
"130.68000","10.89012","-0.00014"
"130.80000","10.90023","-0.00005"
"130.92000","10.91021","0.00001"
"131.04000","10.92026","-0.00037"
"131.16000","10.93024","-0.00099"
"131.28000","10.94023","-0.00061"
"131.40000","10.95027","-0.00038"
"131.52000","10.96026","-0.00012"
"131.64000","10.97024","-0.00021"
"131.76000","10.98023","-0.00070"
"131.88000","10.99027","-0.00047"
"132.00000","11.00026","-0.00015"
"132.12000","11.01018","-0.00032"
"132.24000","11.02017","-0.00014"
"132.36000","11.03015","-0.00068"
"132.48000","11.04020","-0.00026"
"132.60000","11.05018","-0.00069"
"132.72000","11.06017","-0.00029"
"132.84000","11.07015","-0.00019"
"132.96000","11.08020","0.00002"
"133.08000","11.09024","-0.00009"
"133.20000","11.10017","-0.00060"
"133.32000","11.11015","-0.00032"
"133.44000","11.12020","-0.00007"
"133.56000","11.13018","-0.00058"
"133.68000","11.14023","0.00003"
"133.80000","11.15015","-0.00014"
"133.92000","11.16019","-0.00040"
"134.04000","11.17024","-0.00019"
"134.16000","11.18022","-0.00042"
"134.28000","11.19021","-0.00021"
"134.40000","11.20013","-0.00042"
"134.52000","11.21024","-0.00039"
"134.64000","11.22022","-0.00045"
"134.76000","11.23027","0.00020"
"134.88000","11.24019","-0.00022"
"135.00000","11.25018","0.00013"
"135.12000","11.26022","-0.00038"
"135.24000","11.27027","-0.00072"
"135.36000","11.28025","-0.00077"
"135.48000","11.29018","0.00025"
"135.60000","11.30022","-0.00005"
"135.72000","11.31027","0.00014"
"135.84000","11.32019","-0.00006"
"135.96000","11.33018","-0.00012"
"136.08000","11.34016","-0.00002"
"136.20000","11.35027","-0.00064"
"136.32000","11.36025","0.00004"
"136.44000","11.37017","-0.00037"
"136.56000","11.38016","-0.00063"
"136.68000","11.39021","-0.00040"
"136.80000","11.40025","-0.00012"
"136.92000","11.41023","0.00002"
"137.04000","11.42016","-0.00020"
"137.16000","11.43020","-0.00045"
"137.28000","11.44025","0.00037"
"137.40000","11.45023","-0.00036"
"137.52000","11.46022","-0.00017"
"137.64000","11.47020","-0.00009"
"137.76000","11.48025","0.00024"
"137.88000","11.49023","0.00015"
"138.00000","11.50022","0.00018"
"138.12000","11.51020","0.00032"
"138.24000","11.52013","0.00019"
"138.36000","11.53023","-0.00058"
"138.48000","11.54028","-0.00020"
"138.60000","11.55020","0.00002"
"138.72000","11.56013","-0.00022"
"138.84000","11.57023","0.00004"
"138.96000","11.58022","-0.00003"
"139.08000","11.59020","-0.00025"
"139.20000","11.60019","-0.00053"
"139.32000","11.61017","-0.00012"
"139.44000","11.62022","-0.00010"
"139.56000","11.63020","0.00026"
"139.68000","11.64019","0.00048"
"139.80000","11.65017","-0.00028"
"139.92000","11.66021","0.00044"
"140.04000","11.67026","0.00012"
"140.16000","11.68018","-0.00001"
"140.28000","11.69017","0.00007"
"140.40000","11.70021","-0.00009"
"140.52000","11.71026","-0.00020"
"140.64000","11.72018","0.00039"
"140.76000","11.73023","0.00053"
"140.88000","11.74015","0.00076"
"141.00000","11.75020","-0.00024"
"141.12000","11.76024","0.00021"
"141.24000","11.77017","-0.00023"
"141.36000","11.78021","-0.00026"
"141.48000","11.79020","-0.00042"
"141.60000","11.80024","0.00034"
"141.72000","11.81023","0.00022"
"141.84000","11.82015","0.00033"
"141.96000","11.83020","0.00018"
"142.08000","11.84024","-0.00008"
"142.20000","11.85029","0.00007"
"142.32000","11.86021","0.00054"
"142.44000","11.87013","0.00022"
"142.56200","11.88036","0.00003"
"142.68200","11.89040","0.00040"
"142.80200","11.90039","-0.00013"
"142.92200","11.91037","0.00006"
"143.04200","11.92030","0.00053"
"143.16200","11.93040","0.00041"
"143.28200","11.94039","-0.00018"
"143.40200","11.95037","0.00032"
"143.52200","11.96036","0.00040"
"143.64200","11.97040","-0.00015"
"143.76200","11.98045","-0.00032"
"143.88200","11.99037","0.00021"
"144.00200","12.00036","0.00013"
"144.12200","12.01034","0.00032"
"144.24200","12.02039","0.00023"
"144.36200","12.03043","-0.00010"
"144.48200","12.04036","0.00020"
"144.60200","12.05034","0.00040"
"144.72200","12.06038","0.00041"
"144.84200","12.07037","0.00041"
"144.96200","12.08042","0.00015"
"145.08200","12.09034","0.00013"
"145.20200","12.10039","-0.00028"
"145.32200","12.11037","-0.00026"
"145.44200","12.12035","0.00023"
"145.56200","12.13040","0.00008"
"145.68200","12.14033","0.00025"
"145.80200","12.15037","0.00041"
"145.92200","12.16041","0.00013"
"146.04200","12.17040","0.00014"
"146.16200","12.18032","0.00008"
"146.28200","12.19031","0.00025"
"146.40200","12.20035","0.00019"
"146.52200","12.21040","0.00021"
"146.64200","12.22038","0.00069"
"146.76200","12.23031","0.00019"
"146.88200","12.24035","0.00007"
"147.00200","12.25034","-0.00010"
"147.12200","12.26038","0.00033"
"147.24200","12.27037","0.00050"
"147.36200","12.28035","0.00016"
"147.48200","12.29040","0.00001"
"147.60200","12.30038","0.00005"
"147.72200","12.31037","0.00064"
"147.84200","12.32029","0.00054"
"147.96200","12.33034","0.00037"
"148.08200","12.34038","0.00063"
"148.20200","12.35037","0.00049"
"148.32200","12.36035","0.00044"
"148.44200","12.37033","0.00071"
"148.56200","12.38038","-0.00001"
"148.68200","12.39036","0.00043"
"148.80200","12.40041","0.00034"
"148.92200","12.41033","0.00046"
"149.04200","12.42038","0.00038"
"149.16200","12.43036","0.00001"
"149.28200","12.44035","-0.00008"
"149.40200","12.45033","0.00002"
"149.52200","12.46038","0.00010"
"149.64200","12.47036","-0.00008"
"149.76200","12.48041","0.00030"
"149.88200","12.49027","0.00054"
"150.00200","12.50032","0.00048"
"150.12200","12.51042","-0.00004"
"150.24200","12.52041","0.00049"
"150.36200","12.53045","0.00016"
"150.48200","12.54032","0.00016"
"150.60200","12.55036","0.00050"
"150.72200","12.56041","0.00090"
"150.84200","12.57039","0.00067"
"150.96200","12.58044","0.00065"
"151.08200","12.59030","0.00024"
"151.20200","12.60040","-0.00015"
"151.32200","12.61039","0.00020"
"151.44200","12.62031","0.00059"
"151.56200","12.63036","0.00017"
"151.68200","12.64034","0.00028"
"151.80200","12.65039","0.00028"
"151.92200","12.66043","0.00024"
"152.04200","12.67036","0.00095"
"152.16200","12.68034","0.00055"
"152.28200","12.69039","0.00042"
"152.40200","12.70037","0.00035"
"152.52200","12.71042","0.00001"
"152.64200","12.72034","0.00013"
"152.76200","12.73033","0.00062"
"152.88200","12.74043","0.00024"
"153.00200","12.75036","0.00053"
"153.12200","12.76040","0.00029"
"153.24200","12.77033","0.00041"
"153.36200","12.78037","0.00024"
"153.48200","12.79036","0.00080"
"153.60200","12.80034","0.00009"
"153.72200","12.81033","0.00052"
"153.84200","12.82037","0.00063"
"153.96200","12.83042","0.00031"
"154.08200","12.84040","0.00045"
"154.20200","12.85032","0.00073"
"154.32200","12.86031","0.00048"
"154.44200","12.87041","0.00034"
"154.56200","12.88046","-0.00003"
"154.68200","12.89044","0.00038"
"154.80200","12.90037","-0.00016"
"154.92200","12.91035","-0.00014"
"155.04200","12.92034","0.00070"
"155.16200","12.93044","0.00061"
"155.28200","12.94037","0.00040"
"155.40200","12.95041","0.00065"
"155.52200","12.96040","0.00056"
"155.64200","12.97038","0.00010"
"155.76200","12.98043","0.00030"
"155.88200","12.99035","0.00039"
"156.00200","13.00034","0.00045"
"156.12200","13.01038","0.00054"
"156.24200","13.02037","-0.00005"
"156.36200","13.03041","0.00030"
"156.48200","13.04034","0.00050"
"156.60200","13.05038","0.00026"
"156.72200","13.06043","0.00005"
"156.84200","13.07041","0.00070"
"156.96200","13.08040","0.00079"
"157.08200","13.09038","0.00001"
"157.20200","13.10037","0.00029"
"157.32200","13.11041","0.00011"
"157.44200","13.12033","0.00036"
"157.56200","13.13038","0.00028"
"157.68200","13.14036","0.00090"
"157.80200","13.15035","0.00098"
"157.92200","13.16033","0.00091"
"158.04200","13.17032","0.00070"
"158.16200","13.18036","0.00054"
"158.28200","13.19041","0.00057"
"158.40200","13.20039","0.00052"
"158.52200","13.21032","0.00037"
"158.64200","13.22030","0.00086"
"158.76200","13.23035","0.00084"
"158.88200","13.24033","0.00011"
"159.00200","13.25044","0.00034"
"159.12200","13.26030","0.00068"
"159.24200","13.27041","0.00079"
"159.36200","13.28039","0.00039"
"159.48200","13.29038","0.00103"
"159.60200","13.30036","0.00084"
"159.72200","13.31035","0.00031"
"159.84200","13.32045","0.00101"
"159.96200","13.33037","0.00064"
"160.08200","13.34042","0.00055"
"160.20200","13.35035","0.00082"
"160.32200","13.36039","0.00092"
"160.44200","13.37043","0.00029"
"160.56200","13.38042","0.00075"
"160.68200","13.39034","0.00075"
"160.80200","13.40027","0.00055"
"160.92200","13.41043","0.00060"
"161.04200","13.42036","0.00031"
"161.16200","13.43040","0.00050"
"161.28200","13.44033","0.00083"
"161.40200","13.45037","0.00068"
"161.52200","13.46042","0.00049"
"161.64200","13.47040","0.00025"
"161.76200","13.48039","0.00114"
"161.88200","13.49037","0.00066"
"162.00200","13.50042","0.00037"
"162.12200","13.51040","0.00099"
"162.24200","13.52033","0.00080"
"162.36200","13.53025","0.00018"
"162.48200","13.54036","0.00071"
"162.60200","13.55040","0.00067"
"162.72200","13.56045","0.00052"
"162.84200","13.57037","0.00041"
"162.96200","13.58030","0.00054"
"163.08200","13.59034","0.00093"
"163.20200","13.60038","0.00082"
"163.32200","13.61043","0.00075"
"163.44200","13.62036","0.00113"
"163.56200","13.63034","0.00052"
"163.68200","13.64038","0.00095"
"163.80200","13.65043","0.00066"
"163.92200","13.66035","0.00057"
"164.04200","13.67034","0.00090"
"164.16200","13.68038","0.00073"
"164.28200","13.69037","0.00057"
"164.40200","13.70035","0.00066"
"164.52200","13.71028","0.00044"
"164.64200","13.72038","0.00074"
"164.76200","13.73043","0.00051"
"164.88200","13.74041","0.00092"
"165.00200","13.75040","0.00036"
"165.12200","13.76038","0.00090"
"165.24200","13.77037","0.00013"
"165.36200","13.78041","0.00056"
"165.48200","13.79040","0.00055"
"165.60200","13.80038","0.00053"
"165.72200","13.81037","0.00061"
"165.84200","13.82035","0.00099"
"165.96200","13.83040","0.00077"
"166.08200","13.84032","0.00093"
"166.20200","13.85036","0.00097"
"166.32200","13.86041","0.00077"
"166.44200","13.87039","0.00035"
"166.56200","13.88038","0.00058"
"166.68200","13.89030","0.00085"
"166.80200","13.90035","0.00112"
"166.92200","13.91039","0.00077"
"167.04200","13.92038","0.00046"
"167.16200","13.93036","0.00116"
"167.28200","13.94035","0.00078"
"167.40200","13.95039","0.00111"
"167.52200","13.96044","0.00069"
"167.64200","13.97042","0.00036"
"167.76200","13.98035","0.00015"
"167.88200","13.99039","0.00115"
"168.00200","14.00038","0.00119"
"168.12200","14.01036","0.00079"
"168.24200","14.02035","0.00082"
"168.36200","14.03039","0.00097"
"168.48200","14.04050","0.00041"
"168.60200","14.05042","0.00031"
"168.72200","14.06035","0.00101"
"168.84200","14.07033","0.00108"
"168.96200","14.08038","0.00069"
"169.08200","14.09036","0.00093"
"169.20200","14.10041","0.00016"
"169.32200","14.11033","0.00035"
"169.44200","14.12037","0.00088"
"169.56200","14.13042","0.00134"
"169.68200","14.14040","0.00100"
"169.80200","14.15039","0.00051"
"169.92200","14.16031","0.00075"
"170.04200","14.17042","0.00073"
"170.16200","14.18040","0.00074"
"170.28200","14.19033","0.00095"
"170.40200","14.20031","0.00056"
"170.52200","14.21030","0.00077"
"170.64200","14.22046","0.00077"
"170.76200","14.23045","0.00043"
"170.88200","14.24037","0.00093"
"171.00200","14.25030","0.00103"
"171.12200","14.26034","0.00089"
"171.24200","14.27039","0.00116"
"171.36200","14.28037","0.00101"
"171.48200","14.29030","0.00100"
"171.60200","14.30034","0.00072"
"171.72200","14.31039","0.00067"
"171.84200","14.32043","0.00081"
"171.96200","14.33036","0.00091"
"172.08200","14.34034","0.00098"
"172.20200","14.35039","0.00126"
"172.32200","14.36037","0.00086"
"172.44200","14.37035","0.00113"
"172.56200","14.38040","0.00103"
"172.68200","14.39033","0.00094"
"172.80200","14.40037","0.00111"
"172.92200","14.41041","0.00081"
"173.04200","14.42034","0.00085"
"173.16200","14.43026","0.00114"
"173.28200","14.44037","0.00079"
"173.40200","14.45035","0.00087"
"173.52200","14.46040","0.00127"
"173.64200","14.47038","0.00111"
"173.76200","14.48037","0.00077"
"173.88200","14.49041","0.00070"
"174.00200","14.50040","0.00114"
"174.12200","14.51032","0.00086"
"174.24200","14.52037","0.00095"
"174.36200","14.53041","0.00077"
"174.48200","14.54045","0.00125"
"174.60200","14.55038","0.00112"
"174.72200","14.56037","0.00059"
"174.84200","14.57035","0.00080"
"174.96200","14.58039","0.00079"
"175.08200","14.59038","0.00066"
"175.20200","14.60036","0.00078"
"175.32200","14.61035","0.00090"
"175.44200","14.62040","0.00068"
"175.56200","14.63038","0.00061"
"175.68200","14.64031","0.00054"
"175.80200","14.65035","0.00083"
"175.92200","14.66039","0.00076"
"176.04200","14.67038","0.00089"
"176.16200","14.68042","0.00038"
"176.28200","14.69035","0.00123"
"176.40200","14.70033","0.00066"
"176.52200","14.71038","0.00089"
"176.64200","14.72036","0.00086"
"176.76200","14.73041","0.00086"
"176.88200","14.74033","0.00033"
"177.00200","14.75038","0.00025"
"177.12200","14.76042","0.00083"
"177.24200","14.77041","0.00079"
"177.36200","14.78039","0.00067"
"177.48200","14.79032","0.00062"
"177.60200","14.80036","0.00091"
"177.72200","14.81035","0.00032"
"177.84200","14.82039","0.00057"
"177.96200","14.83038","0.00097"
"178.08200","14.84042","0.00105"
"178.20200","14.85040","0.00089"
"178.32200","14.86039","0.00068"
"178.32600","14.86069","0.00062"