File: Force_trajectories/170108_1/Specimen_RawData_10.csv
End date,"1/8/2017"
Specimen label,"19AG_UNK"
Maximum Load,"0.01075",N

Time,Extension,Load
(s),(mm),(N)
"0.00000","0.00000","0.00756"
"0.10800","0.00395","0.00783"
"0.21600","0.01495","0.00744"
"0.32400","0.02655","0.00793"
"0.43200","0.03623","0.00789"
"0.54000","0.04520","0.00773"
"0.64800","0.05423","0.00769"
"0.75600","0.06320","0.00798"
"0.86400","0.07217","0.00771"
"0.97200","0.08119","0.00786"
"1.08000","0.09016","0.00782"
"1.18800","0.09919","0.00802"
"1.29600","0.10822","0.00759"
"1.40400","0.11719","0.00779"
"1.51200","0.12610","0.00768"
"1.62000","0.13512","0.00759"
"1.72800","0.14421","0.00824"
"1.83600","0.15324","0.00761"
"1.94400","0.16215","0.00782"
"2.05200","0.17112","0.00794"
"2.16000","0.18021","0.00755"
"2.26800","0.18923","0.00762"
"2.37600","0.19820","0.00777"
"2.48400","0.20711","0.00787"
"2.59200","0.21614","0.00783"
"2.70000","0.22517","0.00799"
"2.80800","0.23420","0.00807"
"2.91600","0.24316","0.00801"
"3.02400","0.25213","0.00805"
"3.13200","0.26116","0.00810"
"3.24000","0.27013","0.00774"
"3.34800","0.27916","0.00744"
"3.45600","0.28819","0.00795"
"3.56400","0.29721","0.00798"
"3.67200","0.30612","0.00785"
"3.78000","0.31515","0.00785"
"3.88800","0.32418","0.00819"
"3.99600","0.33315","0.00795"
"4.10400","0.34218","0.00748"
"4.21200","0.35114","0.00795"
"4.32000","0.36011","0.00792"
"4.42800","0.36920","0.00787"
"4.53600","0.37817","0.00793"
"4.64400","0.38714","0.00760"
"4.75200","0.39611","0.00798"
"4.86000","0.40513","0.00785"
"4.96800","0.41416","0.00772"
"5.07600","0.42313","0.00826"
"5.18400","0.43216","0.00795"
"5.29200","0.44113","0.00796"
"5.40000","0.45010","0.00763"
"5.50800","0.45918","0.00774"
"5.61600","0.46815","0.00785"
"5.72400","0.47718","0.00808"
"5.83200","0.48609","0.00835"
"5.94000","0.49506","0.00783"
"6.04800","0.50415","0.00775"
"6.15600","0.51323","0.00765"
"6.26400","0.52214","0.00766"
"6.37200","0.53111","0.00760"
"6.48000","0.54014","0.00791"
"6.58800","0.54917","0.00797"
"6.69600","0.55814","0.00757"
"6.80400","0.56710","0.00794"
"6.91200","0.57607","0.00793"
"7.02000","0.58516","0.00810"
"7.12800","0.59413","0.00815"
"7.23600","0.60316","0.00761"
"7.34400","0.61213","0.00810"
"7.45200","0.62115","0.00795"
"7.56000","0.63012","0.00762"
"7.66800","0.63921","0.00823"
"7.77600","0.64818","0.00797"
"7.88400","0.65715","0.00798"
"7.99200","0.66612","0.00803"
"8.10000","0.67514","0.00782"
"8.20800","0.68417","0.00778"
"8.31600","0.69314","0.00764"
"8.42400","0.70217","0.00816"
"8.53200","0.71114","0.00791"
"8.64000","0.72016","0.00782"
"8.74800","0.72919","0.00783"
"8.85600","0.73816","0.00762"
"8.96400","0.74713","0.00781"
"9.07200","0.75610","0.00827"
"9.18000","0.76513","0.00796"
"9.28800","0.77415","0.00810"
"9.39600","0.78318","0.00774"
"9.50400","0.79215","0.00791"
"9.61200","0.80112","0.00783"
"9.72000","0.81015","0.00817"
"9.82800","0.81918","0.00800"
"9.93600","0.82814","0.00780"
"10.04400","0.83717","0.00809"
"10.15200","0.84614","0.00830"
"10.26000","0.85511","0.00782"
"10.36800","0.86414","0.00807"
"10.47600","0.87323","0.00759"
"10.58400","0.88213","0.00776"
"10.69200","0.89110","0.00792"
"10.80000","0.90007","0.00831"
"10.90800","0.90922","0.00793"
"11.01600","0.91813","0.00814"
"11.12400","0.92710","0.00806"
"11.23200","0.93606","0.00824"
"11.34000","0.94509","0.00816"
"11.44800","0.95418","0.00795"
"11.55600","0.96315","0.00804"
"11.66400","0.97212","0.00813"
"11.77200","0.98109","0.00805"
"11.88000","0.99011","0.00810"
"11.98800","0.99920","0.00782"
"12.09600","1.00817","0.00801"
"12.20400","1.01714","0.00807"
"12.31200","1.02611","0.00861"
"12.42000","1.03514","0.00845"
"12.52800","1.04416","0.00784"
"12.63600","1.05319","0.00755"
"12.74400","1.06216","0.00849"
"12.85200","1.07107","0.00803"
"12.96000","1.08010","0.00798"
"13.06800","1.08919","0.00801"
"13.17600","1.09815","0.00839"
"13.28400","1.10712","0.00793"
"13.39200","1.11609","0.00787"
"13.50000","1.12512","0.00804"
"13.60800","1.13421","0.00784"
"13.71600","1.14318","0.00856"
"13.82400","1.15214","0.00793"
"13.93200","1.16111","0.00842"
"14.04000","1.17014","0.00832"
"14.14800","1.17917","0.00796"
"14.25600","1.18814","0.00798"
"14.36400","1.19711","0.00782"
"14.47200","1.20613","0.00820"
"14.58000","1.21510","0.00784"
"14.68800","1.22419","0.00829"
"14.79600","1.23316","0.00813"
"14.90400","1.24213","0.00802"
"15.01200","1.25116","0.00821"
"15.12000","1.26018","0.00819"
"15.22800","1.26921","0.00795"
"15.33600","1.27818","0.00814"
"15.44400","1.28715","0.00807"
"15.55200","1.29612","0.00798"
"15.66000","1.30515","0.00808"
"15.76800","1.31417","0.00785"
"15.87600","1.32314","0.00796"
"15.98400","1.33211","0.00813"
"16.09200","1.34114","0.00795"
"16.20000","1.35017","0.00797"
"16.30800","1.35914","0.00803"
"16.41600","1.36816","0.00777"
"16.52400","1.37713","0.00830"
"16.63200","1.38616","0.00799"
"16.74000","1.39513","0.00825"
"16.84800","1.40410","0.00798"
"16.95600","1.41319","0.00823"
"17.06400","1.42215","0.00816"
"17.17200","1.43106","0.00794"
"17.28000","1.44015","0.00811"
"17.38800","1.44912","0.00839"
"17.49600","1.45821","0.00794"
"17.60400","1.46712","0.00897"
"17.71200","1.47602","0.00877"
"17.82000","1.48511","0.00842"
"17.92800","1.49420","0.00792"
"18.03600","1.50317","0.00805"
"18.14400","1.51214","0.00753"
"18.25200","1.52111","0.00766"
"18.36000","1.53013","0.00828"
"18.46800","1.53916","0.00820"
"18.57600","1.54813","0.00739"
"18.68400","1.55710","0.00874"
"18.79200","1.56613","0.00830"
"18.90000","1.57510","0.00870"
"19.00800","1.58412","0.00869"
"19.11600","1.59315","0.00884"
"19.22400","1.60212","0.00827"
"19.33200","1.61109","0.00754"
"19.44000","1.62018","0.00815"
"19.54800","1.62915","0.00891"
"19.65600","1.63811","0.00833"
"19.76400","1.64714","0.00859"
"19.87200","1.65611","0.00909"
"19.98000","1.66514","0.00793"
"20.08800","1.67417","0.00814"
"20.19600","1.68319","0.00871"
"20.30400","1.69210","0.00889"
"20.41200","1.70113","0.00900"
"20.52000","1.71016","0.00776"
"20.62800","1.71919","0.00837"
"20.73600","1.72816","0.00874"
"20.84400","1.73713","0.00897"
"20.95200","1.74609","0.00913"
"21.06000","1.75518","0.00835"
"21.16800","1.76415","0.00784"
"21.27600","1.77318","0.00817"
"21.38400","1.78215","0.00845"
"21.49200","1.79112","0.00883"
"21.60000","1.80014","0.00897"
"21.70800","1.80917","0.00889"
"21.81600","1.81814","0.00862"
"21.92400","1.82711","0.00847"
"22.03200","1.83608","0.00899"
"22.14000","1.84510","0.00852"
"22.24800","1.85419","0.00891"
"22.35600","1.86316","0.00883"
"22.46400","1.87207","0.00885"
"22.57200","1.88104","0.00891"
"22.68000","1.89013","0.00865"
"22.78800","1.89921","0.00860"
"22.89600","1.90818","0.00866"
"23.00400","1.91709","0.00817"
"23.11200","1.92606","0.00848"
"23.22000","1.93515","0.00855"
"23.32800","1.94418","0.00884"
"23.43600","1.95314","0.00889"
"23.54400","1.96211","0.00830"
"23.65200","1.97108","0.00869"
"23.76000","1.98011","0.00843"
"23.86800","1.98914","0.00852"
"23.97600","1.99817","0.00908"
"24.08400","2.00713","0.00863"
"24.19200","2.01604","0.00866"
"24.30000","2.02507","0.00898"
"24.40800","2.03416","0.00932"
"24.51600","2.04319","0.00879"
"24.62400","2.05210","0.00881"
"24.73200","2.06106","0.00886"
"24.84000","2.07009","0.00835"
"24.94800","2.07918","0.00864"
"25.05600","2.08815","0.00876"
"25.16400","2.09712","0.00867"
"25.27200","2.10609","0.00848"
"25.38000","2.11517","0.00870"
"25.48800","2.12414","0.00871"
"25.59600","2.13317","0.00880"
"25.70400","2.14208","0.00874"
"25.81200","2.15111","0.00897"
"25.92000","2.16014","0.00885"
"26.02800","2.16910","0.00862"
"26.13600","2.17819","0.00829"
"26.24400","2.18716","0.00741"
"26.35200","2.19607","0.00794"
"26.46000","2.20516","0.00830"
"26.56800","2.21413","0.00821"
"26.67600","2.22321","0.00832"
"26.78400","2.23212","0.00847"
"26.89200","2.24109","0.00788"
"27.00000","2.25012","0.00769"
"27.10800","2.25915","0.00806"
"27.21600","2.26812","0.00814"
"27.32400","2.27714","0.00808"
"27.43200","2.28611","0.00834"
"27.54000","2.29514","0.00832"
"27.64800","2.30417","0.00872"
"27.75600","2.31314","0.00828"
"27.86400","2.32217","0.00834"
"27.97200","2.33119","0.00823"
"28.08000","2.34016","0.00808"
"28.18800","2.34913","0.00790"
"28.29600","2.35816","0.00819"
"28.40400","2.36713","0.00788"
"28.51200","2.37610","0.00837"
"28.62000","2.38518","0.00829"
"28.72800","2.39415","0.00839"
"28.83600","2.40318","0.00835"
"28.94400","2.41215","0.00815"
"29.05200","2.42112","0.00827"
"29.16000","2.43015","0.00824"
"29.26800","2.43917","0.00772"
"29.37600","2.44820","0.00842"
"29.48400","2.45711","0.00803"
"29.59200","2.46608","0.00846"
"29.70000","2.47523","0.00830"
"29.80800","2.48414","0.00827"
"29.91600","2.49316","0.00872"
"30.02400","2.50213","0.00819"
"30.13200","2.51116","0.00838"
"30.24000","2.52019","0.00865"
"30.34800","2.52910","0.00833"
"30.45600","2.53813","0.00806"
"30.56400","2.54709","0.00858"
"30.67200","2.55612","0.00861"
"30.78000","2.56515","0.00823"
"30.88800","2.57418","0.00829"
"30.99600","2.58315","0.00817"
"31.10400","2.59212","0.00860"
"31.21200","2.60108","0.00821"
"31.32000","2.61017","0.00849"
"31.42800","2.61914","0.00839"
"31.53600","2.62817","0.00846"
"31.64400","2.63714","0.00845"
"31.75200","2.64605","0.00836"
"31.86000","2.65519","0.00828"
"31.96800","2.66422","0.00833"
"32.07600","2.67313","0.00829"
"32.18400","2.68210","0.00825"
"32.29200","2.69107","0.00819"
"32.40000","2.70010","0.00825"
"32.50800","2.70918","0.00821"
"32.61600","2.71815","0.00823"
"32.72400","2.72706","0.00854"
"32.83200","2.73609","0.00886"
"32.94000","2.74512","0.00863"
"33.04800","2.75414","0.00864"
"33.15600","2.76317","0.00862"
"33.26400","2.77214","0.00823"
"33.37200","2.78111","0.00830"
"33.48000","2.79014","0.00850"
"33.58800","2.79917","0.00830"
"33.69600","2.80819","0.00872"
"33.80400","2.81710","0.00835"
"33.91200","2.82607","0.00861"
"34.02000","2.83516","0.00879"
"34.12800","2.84419","0.00854"
"34.23600","2.85316","0.00825"
"34.34400","2.86207","0.00841"
"34.45200","2.87115","0.00845"
"34.56000","2.88018","0.00817"
"34.66800","2.88909","0.00833"
"34.77600","2.89812","0.00851"
"34.88400","2.90709","0.00841"
"34.99200","2.91612","0.00843"
"35.10000","2.92514","0.00850"
"35.20800","2.93411","0.00846"
"35.31600","2.94314","0.00851"
"35.42400","2.95217","0.00827"
"35.53200","2.96108","0.00863"
"35.64000","2.97016","0.00830"
"35.74800","2.97919","0.00829"
"35.85600","2.98816","0.00863"
"35.96400","2.99713","0.00859"
"36.07200","3.00610","0.00835"
"36.18000","3.01513","0.00850"
"36.28800","3.02421","0.00839"
"36.39600","3.03312","0.00865"
"36.50400","3.04215","0.00861"
"36.61200","3.05112","0.00826"
"36.72000","3.06015","0.00866"
"36.82800","3.06918","0.00830"
"36.93600","3.07808","0.00875"
"37.04400","3.08711","0.00847"
"37.15200","3.09614","0.00826"
"37.26000","3.10517","0.00846"
"37.36800","3.11414","0.00860"
"37.47600","3.12311","0.00861"
"37.58400","3.13213","0.00873"
"37.69200","3.14116","0.00852"
"37.80000","3.15013","0.00857"
"37.90800","3.15916","0.00886"
"38.01600","3.16819","0.00845"
"38.12400","3.17710","0.00829"
"38.23200","3.18606","0.00846"
"38.34000","3.19515","0.00860"
"38.44800","3.20418","0.00832"
"38.55600","3.21315","0.00868"
"38.66400","3.22206","0.00879"
"38.77200","3.23115","0.00845"
"38.88000","3.24023","0.00803"
"38.98800","3.24914","0.00808"
"39.09600","3.25811","0.00835"
"39.20400","3.26714","0.00903"
"39.31200","3.27617","0.00878"
"39.42000","3.28520","0.00826"
"39.52800","3.29416","0.00765"
"39.63600","3.30313","0.00768"
"39.74400","3.31210","0.00805"
"39.85200","3.32113","0.00828"
"39.96000","3.33022","0.00888"
"40.06800","3.33919","0.00916"
"40.17600","3.34815","0.00906"
"40.28400","3.35712","0.00839"
"40.39200","3.36615","0.00795"
"40.50000","3.37524","0.00770"
"40.60800","3.38415","0.00788"
"40.71600","3.39312","0.00885"
"40.82400","3.40214","0.00887"
"40.93200","3.41111","0.00870"
"41.04000","3.42020","0.00861"
"41.14800","3.42917","0.00832"
"41.25600","3.43808","0.00843"
"41.36400","3.44711","0.00849"
"41.47200","3.45613","0.00899"
"41.58000","3.46516","0.00891"
"41.68800","3.47413","0.00891"
"41.79600","3.48310","0.00895"
"41.90400","3.49213","0.00870"
"42.01200","3.50116","0.00872"
"42.12000","3.51012","0.00887"
"42.22800","3.51915","0.00875"
"42.33600","3.52818","0.00890"
"42.44400","3.53715","0.00976"
"42.55200","3.54612","0.00897"
"42.66000","3.55515","0.00910"
"42.76800","3.56417","0.00904"
"42.87600","3.57314","0.00870"
"42.98400","3.58205","0.00881"
"43.09200","3.59108","0.00925"
"43.20000","3.60017","0.00966"
"43.30800","3.60914","0.00942"
"43.41600","3.61810","0.00940"
"43.52400","3.62707","0.00988"
"43.63200","3.63610","0.00888"
"43.74000","3.64519","0.00781"
"43.84800","3.65416","0.00886"
"43.95600","3.66313","0.00759"
"44.06400","3.67215","0.00827"
"44.17200","3.68112","0.00841"
"44.28000","3.69015","0.00876"
"44.38800","3.69918","0.00875"
"44.49600","3.70815","0.00845"
"44.60400","3.71712","0.00831"
"44.71200","3.72614","0.00788"
"44.82000","3.73517","0.00822"
"44.92800","3.74420","0.00827"
"45.03600","3.75317","0.00850"
"45.14400","3.76214","0.00852"
"45.25200","3.77116","0.00904"
"45.36000","3.78019","0.00854"
"45.46800","3.78916","0.00888"
"45.57600","3.79813","0.00866"
"45.68400","3.80710","0.00876"
"45.79200","3.81613","0.00860"
"45.90000","3.82521","0.00828"
"46.00800","3.83418","0.00807"
"46.11600","3.84309","0.00840"
"46.22400","3.85212","0.00839"
"46.33200","3.86121","0.00857"
"46.44000","3.87018","0.00843"
"46.54800","3.87914","0.00863"
"46.65600","3.88811","0.00858"
"46.76400","3.89714","0.00866"
"46.87200","3.90617","0.00868"
"46.98000","3.91514","0.00846"
"47.08800","3.92417","0.00850"
"47.19600","3.93319","0.00833"
"47.30400","3.94210","0.00820"
"47.41200","3.95113","0.00903"
"47.52000","3.96016","0.00861"
"47.62800","3.96919","0.00834"
"47.73600","3.97810","0.00869"
"47.84400","3.98707","0.00876"
"47.95200","3.99615","0.00868"
"48.06000","4.00518","0.00853"
"48.16800","4.01415","0.00820"
"48.27600","4.02312","0.00843"
"48.38400","4.03209","0.00845"
"48.49200","4.04117","0.00835"
"48.60000","4.05014","0.00856"
"48.70800","4.05911","0.00878"
"48.81600","4.06814","0.00852"
"48.92400","4.07711","0.00871"
"49.03200","4.08614","0.00872"
"49.14000","4.09516","0.00885"
"49.24800","4.10413","0.00887"
"49.35600","4.11316","0.00868"
"49.46400","4.12213","0.00828"
"49.57200","4.13110","0.00845"
"49.68000","4.14013","0.00837"
"49.78800","4.14915","0.00847"
"49.89600","4.15812","0.00840"
"50.00400","4.16703","0.00823"
"50.11200","4.17612","0.00877"
"50.22000","4.18515","0.00847"
"50.32800","4.19418","0.00890"
"50.43600","4.20308","0.00895"
"50.54400","4.21211","0.00854"
"50.65200","4.22120","0.00872"
"50.76000","4.23017","0.00885"
"50.86800","4.23914","0.00882"
"50.97600","4.24811","0.00929"
"51.08400","4.25713","0.00828"
"51.19200","4.26616","0.00906"
"51.30000","4.27513","0.00916"
"51.40800","4.28416","0.00878"
"51.51600","4.29313","0.00867"
"51.62400","4.30210","0.00892"
"51.73200","4.31112","0.00904"
"51.84000","4.32015","0.00849"
"51.94800","4.32918","0.00862"
"52.05600","4.33815","0.00891"
"52.16400","4.34706","0.00845"
"52.27200","4.35615","0.00895"
"52.38000","4.36517","0.00903"
"52.48800","4.37414","0.00914"
"52.59600","4.38311","0.00858"
"52.70400","4.39208","0.00854"
"52.81200","4.40117","0.00882"
"52.92000","4.41020","0.00930"
"53.02800","4.41916","0.00854"
"53.13600","4.42813","0.00886"
"53.24400","4.43710","0.00886"
"53.35200","4.44613","0.00882"
"53.46000","4.45516","0.00879"
"53.56800","4.46419","0.00845"
"53.67600","4.47315","0.00879"
"53.78400","4.48212","0.00825"
"53.89200","4.49115","0.00899"
"54.00000","4.50012","0.00865"
"54.10800","4.50915","0.00893"
"54.21600","4.51812","0.00916"
"54.32400","4.52708","0.00863"
"54.43200","4.53611","0.00902"
"54.54000","4.54520","0.00878"
"54.64800","4.55417","0.00862"
"54.75600","4.56308","0.00883"
"54.86400","4.57211","0.00939"
"54.97200","4.58113","0.00937"
"55.08000","4.59022","0.00881"
"55.18800","4.59913","0.00850"
"55.29600","4.60810","0.00868"
"55.40400","4.61713","0.00889"
"55.51200","4.62616","0.00922"
"55.62000","4.63518","0.00922"
"55.72800","4.64421","0.00903"
"55.83600","4.65312","0.00886"
"55.94400","4.66209","0.00867"
"56.05200","4.67118","0.00904"
"56.16000","4.68015","0.00874"
"56.26800","4.68911","0.00894"
"56.37600","4.69814","0.00908"
"56.48400","4.70705","0.00849"
"56.59200","4.71614","0.00904"
"56.70000","4.72517","0.00869"
"56.80800","4.73419","0.00908"
"56.91600","4.74310","0.01027"
"57.02400","4.75207","0.00911"
"57.13200","4.76116","0.00878"
"57.24000","4.77019","0.00934"
"57.34800","4.77916","0.01006"
"57.45600","4.78813","0.00903"
"57.56400","4.79709","0.00987"
"57.67200","4.80618","0.01015"
"57.78000","4.81515","0.00965"
"57.88800","4.82412","0.00868"
"57.99600","4.83315","0.00873"
"58.10400","4.84218","0.00910"
"58.21200","4.85114","0.00913"
"58.32000","4.86017","0.00957"
"58.42800","4.86914","0.00892"
"58.53600","4.87817","0.00991"
"58.64400","4.88708","0.00949"
"58.75200","4.89611","0.00887"
"58.86000","4.90513","0.00843"
"58.96800","4.91422","0.00860"
"59.07600","4.92313","0.00885"
"59.18400","4.93210","0.00854"
"59.29200","4.94113","0.00909"
"59.40000","4.95015","0.00912"
"59.50800","4.95918","0.00905"
"59.61600","4.96815","0.00880"
"59.72400","4.97712","0.00875"
"59.83200","4.98615","0.00892"
"59.94000","4.99518","0.00874"
"60.04800","5.00420","0.00844"
"60.15600","5.01311","0.00888"
"60.26400","5.02214","0.00857"
"60.37200","5.03117","0.00883"
"60.48000","5.04014","0.00896"
"60.58800","5.04911","0.00920"
"60.69600","5.05807","0.00873"
"60.80400","5.06710","0.00894"
"60.91200","5.07619","0.00877"
"61.02000","5.08516","0.00901"
"61.12800","5.09419","0.00886"
"61.23600","5.10316","0.00844"
"61.34400","5.11206","0.00867"
"61.45200","5.12115","0.00917"
"61.56000","5.13018","0.00847"
"61.66800","5.13915","0.00905"
"61.77600","5.14812","0.00927"
"61.88400","5.15709","0.00883"
"61.99200","5.16617","0.00891"
"62.10000","5.17520","0.00894"
"62.20800","5.18411","0.00887"
"62.31600","5.19314","0.00824"
"62.42400","5.20217","0.00873"
"62.53200","5.21114","0.00910"
"62.64000","5.22010","0.00916"
"62.74800","5.22907","0.00880"
"62.85600","5.23810","0.00869"
"62.96400","5.24713","0.00886"
"63.07200","5.25610","0.00878"
"63.18000","5.26519","0.00887"
"63.28800","5.27415","0.00869"
"63.39600","5.28312","0.00892"
"63.50400","5.29215","0.00841"
"63.61200","5.30112","0.00878"
"63.72000","5.31015","0.00860"
"63.82800","5.31918","0.00902"
"63.93600","5.32808","0.00881"
"64.04400","5.33711","0.00897"
"64.15200","5.34620","0.00896"
"64.26000","5.35517","0.00865"
"64.36800","5.36414","0.00904"
"64.47600","5.37311","0.00816"
"64.58400","5.38213","0.00820"
"64.69200","5.39116","0.00897"
"64.80000","5.40013","0.00881"
"64.90800","5.40916","0.00848"
"65.01600","5.41813","0.00882"
"65.12400","5.42710","0.00879"
"65.23200","5.43618","0.00892"
"65.34000","5.44515","0.00874"
"65.44800","5.45418","0.00845"
"65.55600","5.46315","0.00875"
"65.66400","5.47212","0.00863"
"65.77200","5.48115","0.00884"
"65.88000","5.49017","0.00909"
"65.98800","5.49920","0.00852"
"66.09600","5.50811","0.00854"
"66.20400","5.51708","0.00881"
"66.31200","5.52623","0.00875"
"66.42000","5.53520","0.00906"
"66.52800","5.54416","0.00884"
"66.63600","5.55307","0.00837"
"66.74400","5.56216","0.00905"
"66.85200","5.57119","0.00853"
"66.96000","5.58016","0.00895"
"67.06800","5.58913","0.00854"
"67.17600","5.59809","0.00857"
"67.28400","5.60712","0.00866"
"67.39200","5.61609","0.00913"
"67.50000","5.62518","0.00926"
"67.60800","5.63415","0.00885"
"67.71600","5.64312","0.00876"
"67.82400","5.65208","0.00888"
"67.93200","5.66117","0.00902"
"68.04000","5.67014","0.00858"
"68.14800","5.67917","0.00878"
"68.25600","5.68808","0.00858"
"68.36400","5.69711","0.00908"
"68.47200","5.70613","0.00858"
"68.58000","5.71516","0.00886"
"68.68800","5.72413","0.00897"
"68.79600","5.73310","0.00924"
"68.90400","5.74213","0.00914"
"69.01200","5.75115","0.00897"
"69.12000","5.76012","0.00885"
"69.22800","5.76915","0.00869"
"69.33600","5.77806","0.00909"
"69.44400","5.78715","0.00889"
"69.55200","5.79618","0.00911"
"69.66000","5.80515","0.00901"
"69.76800","5.81417","0.00917"
"69.87600","5.82314","0.00857"
"69.98400","5.83211","0.00875"
"70.09200","5.84114","0.00853"
"70.20000","5.85017","0.00905"
"70.30800","5.85920","0.00912"
"70.41600","5.86816","0.00862"
"70.52400","5.87707","0.00890"
"70.63200","5.88616","0.00913"
"70.74000","5.89519","0.00884"
"70.84800","5.90416","0.00923"
"70.95600","5.91313","0.00935"
"71.06400","5.92209","0.00921"
"71.17200","5.93118","0.00909"
"71.28000","5.94015","0.00887"
"71.38800","5.94912","0.00896"
"71.49600","5.95809","0.00879"
"71.60400","5.96717","0.00917"
"71.71200","5.97620","0.00880"
"71.82000","5.98517","0.00861"
"71.92800","5.99414","0.00905"
"72.03600","6.00317","0.00914"
"72.14400","6.01214","0.00944"
"72.25200","6.02116","0.00911"
"72.36000","6.03019","0.00917"
"72.46800","6.03916","0.00878"
"72.57600","6.04807","0.00902"
"72.68400","6.05716","0.00928"
"72.79200","6.06619","0.00864"
"72.90000","6.07515","0.00907"
"73.00800","6.08418","0.00877"
"73.11600","6.09309","0.00912"
"73.22400","6.10212","0.00907"
"73.33200","6.11121","0.00933"
"73.44000","6.12018","0.00925"
"73.54800","6.12909","0.00883"
"73.65600","6.13805","0.00922"
"73.76400","6.14714","0.00893"
"73.87200","6.15623","0.00894"
"73.98000","6.16520","0.00868"
"74.08800","6.17411","0.00850"
"74.19600","6.18307","0.00940"
"74.30400","6.19216","0.00910"
"74.41200","6.20119","0.00899"
"74.52000","6.21016","0.00915"
"74.62800","6.21919","0.00869"
"74.73600","6.22810","0.00919"
"74.84400","6.23712","0.00888"
"74.95200","6.24621","0.00899"
"75.06000","6.25518","0.00889"
"75.16800","6.26415","0.00894"
"75.27600","6.27312","0.00939"
"75.38400","6.28209","0.00894"
"75.49200","6.29117","0.00904"
"75.60000","6.30020","0.00879"
"75.70800","6.30911","0.00875"
"75.81600","6.31808","0.00901"
"75.92400","6.32711","0.00898"
"76.03200","6.33614","0.00894"
"76.14000","6.34522","0.00916"
"76.24800","6.35413","0.00914"
"76.35600","6.36310","0.00901"
"76.46400","6.37213","0.00929"
"76.57200","6.38116","0.00904"
"76.68000","6.39019","0.00867"
"76.78800","6.39915","0.00898"
"76.89600","6.40812","0.00880"
"77.00400","6.41709","0.00887"
"77.11200","6.42618","0.00896"
"77.22000","6.43521","0.00920"
"77.32800","6.44418","0.00895"
"77.43600","6.45308","0.00933"
"77.54400","6.46211","0.00900"
"77.65200","6.47120","0.00891"
"77.76000","6.48017","0.00884"
"77.86800","6.48914","0.00874"
"77.97600","6.49811","0.00920"
"78.08400","6.50713","0.00863"
"78.19200","6.51622","0.00882"
"78.30000","6.52519","0.00919"
"78.40800","6.53410","0.00926"
"78.51600","6.54313","0.00928"
"78.62400","6.55216","0.00911"
"78.73200","6.56118","0.00898"
"78.84000","6.57015","0.00892"
"78.94800","6.57912","0.00877"
"79.05600","6.58815","0.00906"
"79.16400","6.59718","0.00891"
"79.27200","6.60615","0.00868"
"79.38000","6.61517","0.00887"
"79.48800","6.62414","0.00902"
"79.59600","6.63311","0.00923"
"79.70400","6.64214","0.00899"
"79.81200","6.65117","0.00949"
"79.92000","6.66014","0.00896"
"80.02800","6.66910","0.00912"
"80.13600","6.67807","0.00909"
"80.24400","6.68710","0.00905"
"80.35200","6.69613","0.00887"
"80.46000","6.70516","0.00899"
"80.56800","6.71407","0.00904"
"80.67600","6.72315","0.00912"
"80.78400","6.73218","0.00889"
"80.89200","6.74115","0.00932"
"81.00000","6.75012","0.00897"
"81.10800","6.75909","0.00960"
"81.21600","6.76812","0.00899"
"81.32400","6.77714","0.00934"
"81.43200","6.78611","0.00949"
"81.54000","6.79514","0.00924"
"81.64800","6.80411","0.00866"
"81.75600","6.81308","0.00874"
"81.86400","6.82217","0.00922"
"81.97200","6.83113","0.00920"
"82.08000","6.84016","0.00878"
"82.18800","6.84913","0.00940"
"82.29600","6.85804","0.00911"
"82.40400","6.86713","0.00930"
"82.51200","6.87622","0.00901"
"82.62000","6.88518","0.00917"
"82.72800","6.89409","0.00900"
"82.83600","6.90306","0.00893"
"82.94400","6.91215","0.00906"
"83.05200","6.92118","0.00897"
"83.16000","6.93015","0.00895"
"83.26800","6.93911","0.00914"
"83.37600","6.94808","0.00889"
"83.48400","6.95717","0.00897"
"83.59200","6.96620","0.00875"
"83.70000","6.97517","0.00902"
"83.80800","6.98413","0.00880"
"83.91600","6.99310","0.00902"
"84.02400","7.00213","0.00901"
"84.13200","7.01122","0.00886"
"84.24000","7.02013","0.00895"
"84.34800","7.02910","0.00864"
"84.45600","7.03813","0.00880"
"84.56400","7.04715","0.00905"
"84.67200","7.05618","0.00896"
"84.78000","7.06521","0.00863"
"84.88800","7.07412","0.00883"
"84.99600","7.08309","0.00851"
"85.10400","7.09218","0.00866"
"85.21200","7.10120","0.00865"
"85.32000","7.11017","0.00861"
"85.42800","7.11914","0.00841"
"85.53600","7.12811","0.00882"
"85.64400","7.13714","0.00904"
"85.75200","7.14611","0.00880"
"85.86000","7.15519","0.00858"
"85.96800","7.16416","0.00879"
"86.07600","7.17313","0.00811"
"86.18400","7.18210","0.00857"
"86.29200","7.19107","0.00857"
"86.40000","7.20015","0.00829"
"86.50800","7.20912","0.00883"
"86.61600","7.21803","0.00889"
"86.72400","7.22712","0.00842"
"86.83200","7.23615","0.00887"
"86.94000","7.24518","0.00881"
"87.04800","7.25415","0.00841"
"87.15600","7.26305","0.00889"
"87.26400","7.27214","0.00866"
"87.37200","7.28117","0.00865"
"87.48000","7.29014","0.00863"
"87.58800","7.29911","0.00940"
"87.69600","7.30814","0.00902"
"87.80400","7.31716","0.00852"
"87.91200","7.32619","0.00861"
"88.02000","7.33516","0.00893"
"88.12800","7.34413","0.00868"
"88.23600","7.35310","0.00834"
"88.34400","7.36212","0.00871"
"88.45200","7.37115","0.00872"
"88.56000","7.38012","0.00871"
"88.66800","7.38915","0.00882"
"88.77600","7.39812","0.00844"
"88.88400","7.40715","0.00869"
"88.99200","7.41611","0.00885"
"89.10000","7.42514","0.00888"
"89.20800","7.43411","0.00874"
"89.31600","7.44308","0.00884"
"89.42400","7.45211","0.00857"
"89.53200","7.46114","0.00864"
"89.64000","7.47016","0.00872"
"89.74800","7.47907","0.00884"
"89.85600","7.48810","0.00867"
"89.96400","7.49719","0.00879"
"90.07200","7.50616","0.00907"
"90.18000","7.51519","0.00863"
"90.28800","7.52415","0.00880"
"90.39600","7.53318","0.00875"
"90.50400","7.54221","0.00894"
"90.61200","7.55112","0.00872"
"90.72000","7.56015","0.00889"
"90.82800","7.56912","0.00882"
"90.93600","7.57808","0.00899"
"91.04400","7.58717","0.00852"
"91.15200","7.59614","0.00861"
"91.26000","7.60523","0.00909"
"91.36800","7.61414","0.00828"
"91.47600","7.62311","0.00885"
"91.58400","7.63219","0.00914"
"91.69200","7.64116","0.00891"
"91.80000","7.65013","0.00884"
"91.90800","7.65916","0.00891"
"92.01600","7.66807","0.00912"
"92.12400","7.67716","0.00898"
"92.23200","7.68618","0.00900"
"92.34000","7.69509","0.00880"
"92.44800","7.70406","0.00859"
"92.55600","7.71309","0.00899"
"92.66400","7.72212","0.00886"
"92.77200","7.73115","0.00890"
"92.88000","7.74011","0.00870"
"92.98800","7.74908","0.00892"
"93.09600","7.75811","0.00897"
"93.20400","7.76714","0.00911"
"93.31200","7.77617","0.00898"
"93.42000","7.78520","0.00888"
"93.52800","7.79410","0.00884"
"93.63600","7.80307","0.00878"
"93.74400","7.81222","0.00902"
"93.85200","7.82113","0.00906"
"93.96000","7.83016","0.00884"
"94.06800","7.83912","0.00910"
"94.17600","7.84809","0.00900"
"94.28400","7.85718","0.00926"
"94.39200","7.86621","0.00899"
"94.50000","7.87512","0.00931"
"94.60800","7.88409","0.00918"
"94.71600","7.89312","0.00867"
"94.82400","7.90220","0.00898"
"94.93200","7.91111","0.00908"
"95.04000","7.92014","0.00870"
"95.14800","7.92911","0.00881"
"95.25600","7.93814","0.00901"
"95.36400","7.94716","0.00869"
"95.47200","7.95619","0.00908"
"95.58000","7.96516","0.00896"
"95.68800","7.97413","0.00896"
"95.79600","7.98310","0.00877"
"95.90400","7.99219","0.00935"
"96.01200","8.00115","0.00905"
"96.12000","8.01018","0.00886"
"96.22800","8.01915","0.00873"
"96.33600","8.02812","0.00907"
"96.44400","8.03715","0.00917"
"96.55200","8.04624","0.00922"
"96.66000","8.05515","0.00910"
"96.76800","8.06411","0.00842"
"96.87600","8.07308","0.00912"
"96.98400","8.08217","0.00870"
"97.09200","8.09114","0.00913"
"97.20000","8.10011","0.00897"
"97.30800","8.10913","0.00928"
"97.41600","8.11810","0.00905"
"97.52400","8.12713","0.00887"
"97.63200","8.13616","0.00935"
"97.74000","8.14513","0.00903"
"97.84800","8.15416","0.00892"
"97.95600","8.16312","0.00894"
"98.06400","8.17215","0.00864"
"98.17200","8.18118","0.00864"
"98.28000","8.19015","0.00905"
"98.38800","8.19906","0.00891"
"98.49600","8.20815","0.00875"
"98.60400","8.21717","0.00929"
"98.71200","8.22620","0.00937"
"98.82000","8.23511","0.00906"
"98.92800","8.24408","0.00893"
"99.03600","8.25311","0.00895"
"99.14400","8.26226","0.00886"
"99.25200","8.27116","0.00914"
"99.36000","8.28013","0.00922"
"99.46800","8.28910","0.00887"
"99.57600","8.29813","0.00902"
"99.68400","8.30716","0.00878"
"99.79200","8.31619","0.00890"
"99.90000","8.32515","0.00952"
"100.00800","8.33412","0.00920"
"100.11600","8.34309","0.00934"
"100.22400","8.35218","0.00883"
"100.33200","8.36121","0.00873"
"100.44000","8.37018","0.00890"
"100.54800","8.37908","0.00873"
"100.65600","8.38811","0.00899"
"100.76400","8.39720","0.00938"
"100.87200","8.40617","0.00900"
"100.98000","8.41514","0.00895"
"101.08800","8.42417","0.00849"
"101.19600","8.43313","0.00869"
"101.30400","8.44216","0.00909"
"101.41200","8.45119","0.00877"
"101.52000","8.46016","0.00897"
"101.62800","8.46907","0.00905"
"101.73600","8.47816","0.00877"
"101.84400","8.48718","0.00905"
"101.95200","8.49615","0.00872"
"102.06000","8.50512","0.00895"
"102.16800","8.51415","0.00880"
"102.27600","8.52312","0.00849"
"102.38400","8.53215","0.00864"
"102.49200","8.54117","0.00860"
"102.60000","8.55014","0.00856"
"102.70800","8.55911","0.00873"
"102.81600","8.56808","0.00865"
"102.92400","8.57717","0.00889"
"103.03200","8.58619","0.00887"
"103.14000","8.59516","0.00872"
"103.24800","8.60407","0.00880"
"103.35600","8.61310","0.00906"
"103.46400","8.62213","0.00918"
"103.57200","8.63116","0.00901"
"103.68000","8.64013","0.00862"
"103.78800","8.64903","0.00885"
"103.89600","8.65818","0.00907"
"104.00400","8.66721","0.00879"
"104.11200","8.67612","0.00873"
"104.22000","8.68515","0.00883"
"104.32800","8.69411","0.00891"
"104.43600","8.70314","0.00872"
"104.54400","8.71217","0.00872"
"104.65200","8.72120","0.00856"
"104.76000","8.73017","0.00892"
"104.86800","8.73914","0.00894"
"104.97600","8.74817","0.00913"
"105.08400","8.75719","0.00915"
"105.19200","8.76616","0.00912"
"105.30000","8.77513","0.00904"
"105.40800","8.78410","0.00900"
"105.51600","8.79313","0.00917"
"105.62400","8.80216","0.00942"
"105.73200","8.81112","0.00854"
"105.84000","8.82009","0.00877"
"105.94800","8.82906","0.00887"
"106.05600","8.83815","0.00906"
"106.16400","8.84718","0.00901"
"106.27200","8.85614","0.00893"
"106.38000","8.86511","0.00895"
"106.48800","8.87414","0.00890"
"106.59600","8.88317","0.00886"
"106.70400","8.89214","0.00913"
"106.81200","8.90117","0.00924"
"106.92000","8.91014","0.00896"
"107.02800","8.91910","0.00907"
"107.13600","8.92813","0.00872"
"107.24400","8.93716","0.00919"
"107.35200","8.94613","0.00932"
"107.46000","8.95516","0.00888"
"107.56800","8.96407","0.00893"
"107.67600","8.97315","0.00876"
"107.78400","8.98218","0.00904"
"107.89200","8.99121","0.00913"
"108.00000","9.00012","0.00912"
"108.10800","9.00909","0.00904"
"108.21600","9.01812","0.00895"
"108.32400","9.02720","0.00911"
"108.43200","9.03617","0.00893"
"108.54000","9.04514","0.00923"
"108.64800","9.05411","0.00888"
"108.75600","9.06314","0.00881"
"108.86400","9.07216","0.00912"
"108.97200","9.08119","0.00946"
"109.08000","9.09016","0.00908"
"109.18800","9.09907","0.00939"
"109.29600","9.10816","0.00933"
"109.40400","9.11719","0.00902"
"109.51200","9.12615","0.00911"
"109.62000","9.13518","0.00924"
"109.72800","9.14409","0.00898"
"109.83600","9.15312","0.00918"
"109.94400","9.16215","0.00937"
"110.05200","9.17118","0.00907"
"110.16000","9.18009","0.00932"
"110.26800","9.18905","0.00959"
"110.37600","9.19808","0.00909"
"110.48400","9.20717","0.00899"
"110.59200","9.21620","0.00914"
"110.70000","9.22511","0.00916"
"110.80800","9.23407","0.00900"
"110.91600","9.24316","0.00907"
"111.02400","9.25219","0.00962"
"111.13200","9.26116","0.00900"
"111.24000","9.27013","0.00932"
"111.34800","9.27916","0.00915"
"111.45600","9.28813","0.00948"
"111.56400","9.29715","0.00922"
"111.67200","9.30618","0.00913"
"111.78000","9.31515","0.00894"
"111.88800","9.32412","0.00900"
"111.99600","9.33315","0.00928"
"112.10400","9.34211","0.00871"
"112.21200","9.35114","0.00921"
"112.32000","9.36017","0.00909"
"112.42800","9.36914","0.00904"
"112.53600","9.37817","0.00924"
"112.64400","9.38714","0.00905"
"112.75200","9.39616","0.00919"
"112.86000","9.40519","0.00897"
"112.96800","9.41410","0.00922"
"113.07600","9.42313","0.00925"
"113.18400","9.43216","0.00905"
"113.29200","9.44113","0.00929"
"113.40000","9.45010","0.00914"
"113.50800","9.45912","0.00901"
"113.61600","9.46815","0.00900"
"113.72400","9.47712","0.00928"
"113.83200","9.48615","0.00897"
"113.94000","9.49512","0.00904"
"114.04800","9.50408","0.00937"
"114.15600","9.51311","0.00935"
"114.26400","9.52214","0.00932"
"114.37200","9.53117","0.00887"
"114.48000","9.54014","0.00912"
"114.58800","9.54905","0.00905"
"114.69600","9.55813","0.00937"
"114.80400","9.56716","0.00917"
"114.91200","9.57619","0.00905"
"115.02000","9.58510","0.00925"
"115.12800","9.59407","0.00904"
"115.23600","9.60316","0.00919"
"115.34400","9.61218","0.00924"
"115.45200","9.62115","0.00917"
"115.56000","9.63012","0.00887"
"115.66800","9.63909","0.00904"
"115.77600","9.64818","0.00929"
"115.88400","9.65715","0.00910"
"115.99200","9.66617","0.00925"
"116.10000","9.67514","0.00895"
"116.20800","9.68411","0.00914"
"116.31600","9.69314","0.00919"
"116.42400","9.70217","0.00918"
"116.53200","9.71113","0.00912"
"116.64000","9.72010","0.00913"
"116.74800","9.72907","0.00889"
"116.85600","9.73816","0.00924"
"116.96400","9.74719","0.00926"
"117.07200","9.75622","0.00928"
"117.18000","9.76513","0.00939"
"117.28800","9.77403","0.00899"
"117.39600","9.78318","0.00938"
"117.50400","9.79221","0.00895"
"117.61200","9.80118","0.00918"
"117.72000","9.81015","0.00919"
"117.82800","9.81906","0.00932"
"117.93600","9.82820","0.00920"
"118.04400","9.83717","0.00939"
"118.15200","9.84614","0.00892"
"118.26000","9.85511","0.00935"
"118.36800","9.86414","0.00911"
"118.47600","9.87311","0.00935"
"118.58400","9.88213","0.00921"
"118.69200","9.89116","0.00905"
"118.80000","9.90013","0.00892"
"118.90800","9.90910","0.00947"
"119.01600","9.91813","0.00949"
"119.12400","9.92715","0.00895"
"119.23200","9.93618","0.00871"
"119.34000","9.94509","0.00928"
"119.44800","9.95406","0.00959"
"119.55600","9.96309","0.00943"
"119.66400","9.97218","0.00910"
"119.77200","9.98114","0.00945"
"119.88000","9.99011","0.00922"
"119.98800","9.99908","0.00946"
"120.09600","10.00811","0.00912"
"120.20400","10.01714","0.00909"
"120.31200","10.02617","0.00912"
"120.42000","10.03508","0.00923"
"120.52800","10.04410","0.00920"
"120.63600","10.05313","0.00910"
"120.74400","10.06210","0.00911"
"120.85200","10.07113","0.00924"
"120.96000","10.08016","0.00931"
"121.06800","10.08906","0.00907"
"121.17600","10.09815","0.00909"
"121.28400","10.10712","0.00889"
"121.39200","10.11615","0.00899"
"121.50000","10.12512","0.00932"
"121.60800","10.13409","0.00911"
"121.71600","10.14311","0.00935"
"121.82400","10.15220","0.00932"
"121.93200","10.16117","0.00879"
"122.04000","10.17014","0.00906"
"122.14800","10.17911","0.00920"
"122.25600","10.18814","0.00938"
"122.36400","10.19716","0.00883"
"122.47200","10.20613","0.00909"
"122.58000","10.21510","0.00909"
"122.68800","10.22413","0.00896"
"122.79600","10.23316","0.00873"
"122.90400","10.24213","0.00876"
"123.01200","10.25109","0.00890"
"123.12000","10.26012","0.00868"
"123.22800","10.26909","0.00904"
"123.33600","10.27812","0.00895"
"123.44400","10.28715","0.00894"
"123.55200","10.29618","0.00865"
"123.66000","10.30515","0.00824"
"123.76800","10.31411","0.00849"
"123.87600","10.32314","0.00915"
"123.98400","10.33217","0.00897"
"124.09200","10.34114","0.00856"
"124.20000","10.35011","0.00863"
"124.30800","10.35913","0.00896"
"124.41600","10.36816","0.00877"
"124.52400","10.37713","0.00908"
"124.63200","10.38616","0.00881"
"124.74000","10.39507","0.00903"
"124.84800","10.40416","0.00881"
"124.95600","10.41324","0.00857"
"125.06400","10.42209","0.00870"
"125.17200","10.43112","0.00870"
"125.28000","10.44009","0.00876"
"125.38800","10.44912","0.00877"
"125.49600","10.45821","0.00864"
"125.60400","10.46717","0.00868"
"125.71200","10.47620","0.00886"
"125.82000","10.48511","0.00895"
"125.92800","10.49408","0.00916"
"126.03600","10.50317","0.00904"
"126.14400","10.51214","0.00876"
"126.25200","10.52116","0.00898"
"126.36000","10.53007","0.00926"
"126.46800","10.53904","0.00891"
"126.57600","10.54819","0.00892"
"126.68400","10.55722","0.00913"
"126.79200","10.56613","0.00912"
"126.90000","10.57509","0.00888"
"127.00800","10.58412","0.00883"
"127.11600","10.59321","0.00915"
"127.22400","10.60218","0.00913"
"127.33200","10.61115","0.00883"
"127.44000","10.62012","0.00869"
"127.54800","10.62914","0.00882"
"127.65600","10.63817","0.00904"
"127.76400","10.64720","0.00874"
"127.87200","10.65617","0.00916"
"127.98000","10.66508","0.00903"
"128.08800","10.67411","0.00930"
"128.19600","10.68313","0.00907"
"128.30400","10.69216","0.00917"
"128.41200","10.70119","0.00909"
"128.52000","10.71010","0.00921"
"128.62800","10.71913","0.00934"
"128.73600","10.72816","0.00895"
"128.84400","10.73718","0.00945"
"128.95200","10.74615","0.00901"
"129.06000","10.75512","0.00876"
"129.16800","10.76409","0.00924"
"129.27600","10.77312","0.00931"
"129.38400","10.78215","0.00905"
"129.49200","10.79111","0.00902"
"129.60000","10.80008","0.00923"
"129.70800","10.80911","0.00916"
"129.81600","10.81820","0.00945"
"129.92400","10.82717","0.00908"
"130.03200","10.83613","0.00941"
"130.14000","10.84516","0.00951"
"130.24800","10.85413","0.00951"
"130.35600","10.86316","0.00896"
"130.46400","10.87219","0.00902"
"130.57200","10.88116","0.00918"
"130.68000","10.89012","0.00906"
"130.78800","10.89909","0.00931"
"130.89600","10.90818","0.00902"
"131.00400","10.91721","0.00936"
"131.11200","10.92612","0.00947"
"131.22000","10.93509","0.00932"
"131.32800","10.94412","0.00909"
"131.43600","10.95320","0.00949"
"131.54400","10.96217","0.00942"
"131.65200","10.97114","0.00950"
"131.76000","10.98011","0.00947"
"131.86800","10.98914","0.00932"
"131.97600","10.99817","0.00923"
"132.08400","11.00719","0.00903"
"132.19200","11.01610","0.00907"
"132.30000","11.02513","0.00957"
"132.40800","11.03416","0.00901"
"132.51600","11.04313","0.00914"
"132.62400","11.05215","0.00917"
"132.73200","11.06112","0.00967"
"132.84000","11.07009","0.00945"
"132.94800","11.07918","0.00941"
"133.05600","11.08821","0.00953"
"133.16400","11.09718","0.00930"
"133.27200","11.10614","0.00923"
"133.38000","11.11511","0.00942"
"133.48800","11.12414","0.00970"
"133.59600","11.13317","0.00894"
"133.70400","11.14220","0.00947"
"133.81200","11.15117","0.00934"
"133.92000","11.16008","0.00974"
"134.02800","11.16916","0.00905"
"134.13600","11.17819","0.00929"
"134.24400","11.18716","0.00953"
"134.35200","11.19613","0.00945"
"134.46000","11.20510","0.00939"
"134.56800","11.21418","0.00946"
"134.67600","11.22315","0.00970"
"134.78400","11.23212","0.00933"
"134.89200","11.24115","0.00942"
"135.00000","11.25012","0.00956"
"135.10800","11.25909","0.00914"
"135.21600","11.26818","0.00951"
"135.32400","11.27714","0.00909"
"135.43200","11.28617","0.00947"
"135.54000","11.29508","0.00958"
"135.64800","11.30411","0.00953"
"135.75600","11.31314","0.00960"
"135.86400","11.32216","0.00936"
"135.97200","11.33107","0.00938"
"136.08000","11.34010","0.00915"
"136.18800","11.34913","0.00969"
"136.29600","11.35822","0.00948"
"136.40400","11.36718","0.00957"
"136.51200","11.37615","0.01001"
"136.62000","11.38512","0.00992"
"136.72800","11.39415","0.00958"
"136.83600","11.40318","0.00959"
"136.94400","11.41221","0.00989"
"137.05200","11.42118","0.00944"
"137.16000","11.43008","0.00958"
"137.26800","11.43911","0.00950"
"137.37600","11.44814","0.00933"
"137.48400","11.45717","0.00934"
"137.59200","11.46614","0.00969"
"137.70000","11.47511","0.00961"
"137.80800","11.48407","0.00938"
"137.91600","11.49316","0.00922"
"138.02400","11.50219","0.00954"
"138.13200","11.51116","0.00997"
"138.24000","11.52013","0.00929"
"138.34800","11.52910","0.00928"
"138.45600","11.53818","0.00914"
"138.56400","11.54715","0.00912"
"138.67200","11.55612","0.00991"
"138.78000","11.56509","0.00974"
"138.88800","11.57418","0.00950"
"138.99600","11.58315","0.00997"
"139.10400","11.59211","0.00980"
"139.21200","11.60114","0.00965"
"139.32000","11.61011","0.00977"
"139.42800","11.61908","0.00968"
"139.53600","11.62811","0.00978"
"139.64400","11.63714","0.00966"
"139.75200","11.64616","0.00978"
"139.86000","11.65507","0.00973"
"139.96800","11.66410","0.00934"
"140.07600","11.67319","0.00988"
"140.18400","11.68216","0.00973"
"140.29200","11.69113","0.00983"
"140.40000","11.70009","0.00977"
"140.50800","11.70912","0.00971"
"140.61600","11.71815","0.00955"
"140.72400","11.72712","0.00930"
"140.83200","11.73609","0.00998"
"140.94000","11.74512","0.00980"
"141.04800","11.75408","0.00971"
"141.15600","11.76317","0.00985"
"141.26400","11.77220","0.00988"
"141.37200","11.78111","0.00970"
"141.48000","11.79008","0.00961"
"141.58800","11.79917","0.00977"
"141.69600","11.80814","0.00947"
"141.80400","11.81716","0.00975"
"141.91200","11.82613","0.00962"
"142.02000","11.83510","0.00980"
"142.12800","11.84413","0.01007"
"142.23600","11.85316","0.01001"
"142.34400","11.86212","0.01015"
"142.45200","11.87109","0.01001"
"142.56000","11.88006","0.00980"
"142.66800","11.88915","0.00930"
"142.77600","11.89818","0.00963"
"142.88400","11.90721","0.00983"
"142.99200","11.91611","0.00944"
"143.10000","11.92508","0.00968"
"143.20800","11.93417","0.00986"
"143.31600","11.94320","0.00974"
"143.42400","11.95211","0.00969"
"143.53200","11.96113","0.00982"
"143.64000","11.97010","0.00955"
"143.74800","11.97913","0.00979"
"143.85600","11.98816","0.00936"
"143.96400","11.99719","0.00967"
"144.07200","12.00616","0.00953"
"144.18000","12.01518","0.00989"
"144.28800","12.02415","0.01015"
"144.39600","12.03318","0.00973"
"144.50400","12.04221","0.00954"
"144.61200","12.05112","0.00964"
"144.72000","12.06009","0.00953"
"144.82800","12.06917","0.00993"
"144.93600","12.07814","0.01018"
"145.04400","12.08717","0.00953"
"145.15200","12.09614","0.00977"
"145.26000","12.10511","0.00933"
"145.36800","12.11408","0.00976"
"145.47600","12.12317","0.00972"
"145.58400","12.13213","0.00954"
"145.69200","12.14110","0.00984"
"145.80000","12.15013","0.01012"
"145.90800","12.15916","0.00977"
"146.01600","12.16813","0.01038"
"146.12400","12.17715","0.01003"
"146.23200","12.18612","0.00978"
"146.34000","12.19509","0.00968"
"146.44800","12.20412","0.00939"
"146.55600","12.21309","0.01012"
"146.66400","12.22212","0.00993"
"146.77200","12.23114","0.00981"
"146.88000","12.24005","0.00995"
"146.98800","12.24914","0.01004"
"147.09600","12.25817","0.00985"
"147.20400","12.26720","0.00989"
"147.31200","12.27611","0.00971"
"147.42000","12.28508","0.00990"
"147.52800","12.29410","0.00999"
"147.63600","12.30319","0.00971"
"147.74400","12.31210","0.01010"
"147.85200","12.32107","0.00989"
"147.96000","12.33010","0.00968"
"148.06800","12.33918","0.00993"
"148.17600","12.34815","0.01010"
"148.28400","12.35718","0.00997"
"148.39200","12.36615","0.00996"
"148.50000","12.37512","0.01018"
"148.60800","12.38415","0.00999"
"148.71600","12.39318","0.00961"
"148.82400","12.40214","0.01020"
"148.93200","12.41111","0.01032"
"149.04000","12.42008","0.00977"
"149.14800","12.42917","0.01027"
"149.25600","12.43814","0.00995"
"149.36400","12.44716","0.00939"
"149.47200","12.45607","0.01004"
"149.58000","12.46510","0.01013"
"149.68800","12.47419","0.01001"
"149.79600","12.48316","0.00991"
"149.90400","12.49219","0.00989"
"150.01200","12.50110","0.01016"
"150.12000","12.51012","0.01044"
"150.22800","12.51915","0.01005"
"150.33600","12.52818","0.00997"
"150.44400","12.53715","0.00986"
"150.55200","12.54612","0.00980"
"150.66000","12.55514","0.01023"
"150.76800","12.56417","0.00986"
"150.87600","12.57314","0.00990"
"150.98400","12.58211","0.00999"
"151.09200","12.59114","0.00968"
"151.20000","12.60011","0.00994"
"151.30800","12.60913","0.01018"
"151.41600","12.61816","0.01021"
"151.52400","12.62719","0.00964"
"151.63200","12.63610","0.01044"
"151.74000","12.64507","0.00986"
"151.84800","12.65416","0.01035"
"151.95600","12.66318","0.00985"
"152.06400","12.67215","0.01005"
"152.17200","12.68112","0.01042"
"152.28000","12.69009","0.01017"
"152.38800","12.69918","0.01037"
"152.49600","12.70815","0.01017"
"152.60400","12.71711","0.01031"
"152.71200","12.72614","0.01019"
"152.82000","12.73511","0.01046"
"152.92800","12.74414","0.01008"
"153.03600","12.75311","0.01007"
"153.14400","12.76214","0.00988"
"153.25200","12.77110","0.01004"
"153.36000","12.78013","0.00990"
"153.46800","12.78910","0.01012"
"153.57600","12.79813","0.00994"
"153.68400","12.80716","0.00993"
"153.79200","12.81613","0.01034"
"153.90000","12.82509","0.00973"
"154.00800","12.83418","0.00988"
"154.11600","12.84315","0.01011"
"154.22400","12.85218","0.01042"
"154.33200","12.86115","0.01005"
"154.44000","12.87012","0.01000"
"154.54800","12.87914","0.01012"
"154.65600","12.88817","0.01001"
"154.76400","12.89714","0.00990"
"154.87200","12.90611","0.01008"
"154.98000","12.91514","0.01023"
"155.08800","12.92416","0.00996"
"155.19600","12.93313","0.00999"
"155.30400","12.94216","0.01006"
"155.39800","12.94993","0.01002"