File: Force_trajectories/170108_2/Specimen_RawData_5.csv
End date,"1/8/2017"
Specimen label,"13DG_5"
Maximum Load,"0.54248",N

Time,Extension,Load
(s),(mm),(N)
"0.00000","0.00000","0.00040"
"0.25800","0.02021","0.00070"
"0.51600","0.04329","0.00166"
"0.77400","0.06481","0.00189"
"1.03200","0.08628","0.00250"
"1.29000","0.10780","0.00265"
"1.54800","0.12926","0.00298"
"1.80600","0.15073","0.00346"
"2.06400","0.17225","0.00357"
"2.32200","0.19372","0.00392"
"2.58000","0.21524","0.00435"
"2.83800","0.23671","0.00464"
"3.09600","0.25829","0.00464"
"3.35400","0.27970","0.00484"
"3.61200","0.30122","0.00491"
"3.87000","0.32262","0.00494"
"4.12800","0.34427","0.00548"
"4.38600","0.36573","0.00556"
"4.64400","0.38726","0.00567"
"4.90200","0.40872","0.00552"
"5.16000","0.43025","0.00624"
"5.41800","0.45171","0.00638"
"5.67600","0.47323","0.00630"
"5.93400","0.49470","0.00568"
"6.19200","0.51622","0.00698"
"6.45000","0.53775","0.00697"
"6.70800","0.55927","0.00679"
"6.96600","0.58074","0.00647"
"7.22400","0.60220","0.00677"
"7.48200","0.62372","0.00691"
"7.74000","0.64519","0.00669"
"7.99800","0.66671","0.00747"
"8.25600","0.68818","0.00769"
"8.51400","0.70970","0.00758"
"8.77200","0.73123","0.00754"
"9.03000","0.75275","0.00748"
"9.28800","0.77415","0.00762"
"9.54600","0.79574","0.00827"
"9.80400","0.81714","0.00760"
"10.06200","0.83873","0.00787"
"10.32000","0.86019","0.00813"
"10.57800","0.88172","0.00799"
"10.83600","0.90318","0.00803"
"11.09400","0.92476","0.00866"
"11.35200","0.94617","0.00827"
"11.61000","0.96775","0.00843"
"11.86800","0.98916","0.00855"
"12.12600","1.01074","0.00865"
"12.38400","1.03221","0.00838"
"12.64200","1.05379","0.00864"
"12.90000","1.07520","0.00878"
"13.15800","1.09672","0.00890"
"13.41600","1.11818","0.00873"
"13.67400","1.13971","0.00920"
"13.93200","1.16129","0.00906"
"14.19000","1.18276","0.00914"
"14.44800","1.20422","0.00891"
"14.70600","1.22569","0.00870"
"14.96400","1.24727","0.00916"
"15.22200","1.26867","0.00931"
"15.48000","1.29026","0.00935"
"15.73800","1.31166","0.00900"
"15.99600","1.33325","0.00891"
"16.25400","1.35471","0.00930"
"16.51200","1.37624","0.00930"
"16.77000","1.39770","0.00965"
"17.02800","1.41922","0.00978"
"17.28600","1.44069","0.00980"
"17.54400","1.46227","0.00964"
"17.80200","1.48368","0.00955"
"18.06000","1.50526","0.00961"
"18.31800","1.52667","0.01008"
"18.57600","1.54825","0.01012"
"18.83400","1.56971","0.00907"
"19.09200","1.59124","0.00988"
"19.35000","1.61270","0.01012"
"19.60800","1.63423","0.00949"
"19.86600","1.65569","0.00971"
"20.12400","1.67722","0.00979"
"20.38200","1.69880","0.01013"
"20.64000","1.72020","0.00935"
"20.89800","1.74173","0.01013"
"21.15600","1.76319","0.01031"
"21.41400","1.78478","0.01023"
"21.67200","1.80624","0.00983"
"21.93000","1.82777","0.01054"
"22.18800","1.84917","0.01025"
"22.44600","1.87069","0.01057"
"22.70400","1.89222","0.01030"
"22.96200","1.91374","0.01028"
"23.22000","1.93521","0.01008"
"23.47800","1.95673","0.01030"
"23.73600","1.97820","0.01059"
"23.99400","1.99972","0.01057"
"24.25200","2.02119","0.01043"
"24.51000","2.04277","0.01078"
"24.76800","2.06423","0.01078"
"25.02600","2.08576","0.01061"
"25.28400","2.10722","0.01052"
"25.54200","2.12875","0.01059"
"25.80000","2.15027","0.01049"
"26.05800","2.17174","0.01095"
"26.31600","2.19320","0.01074"
"26.57400","2.21466","0.01054"
"26.83200","2.23625","0.01076"
"27.09000","2.25777","0.01086"
"27.34800","2.27924","0.01042"
"27.60600","2.30070","0.01105"
"27.86400","2.32223","0.01071"
"28.12200","2.34369","0.01077"
"28.38000","2.36527","0.01103"
"28.63800","2.38662","0.01081"
"28.89600","2.40826","0.01162"
"29.15400","2.42967","0.01120"
"29.41200","2.45131","0.01135"
"29.67000","2.47266","0.01128"
"29.92800","2.49424","0.01116"
"30.18600","2.51570","0.01124"
"30.44400","2.53729","0.01133"
"30.70200","2.55869","0.01121"
"30.96000","2.58022","0.01096"
"31.21800","2.60168","0.01087"
"31.47600","2.62321","0.01138"
"31.73400","2.64473","0.01121"
"31.99200","2.66619","0.01093"
"32.25000","2.68778","0.01164"
"32.50800","2.70924","0.01115"
"32.76600","2.73077","0.01201"
"33.02400","2.75223","0.01171"
"33.28200","2.77382","0.01175"
"33.54000","2.79522","0.01120"
"33.79800","2.81674","0.01208"
"34.05600","2.83821","0.01155"
"34.31400","2.85973","0.01119"
"34.57200","2.88120","0.01197"
"34.83000","2.90272","0.01121"
"35.08800","2.92413","0.01173"
"35.34600","2.94571","0.01157"
"35.60400","2.96724","0.01147"
"35.86200","2.98870","0.01144"
"36.12000","3.01016","0.01179"
"36.37800","3.03175","0.01167"
"36.63600","3.05321","0.01178"
"36.89400","3.07480","0.01150"
"37.15200","3.09620","0.01172"
"37.41000","3.11773","0.01174"
"37.66800","3.13919","0.01186"
"37.92600","3.16077","0.01155"
"38.18400","3.18224","0.01196"
"38.44200","3.20376","0.01163"
"38.70000","3.22523","0.01185"
"38.95800","3.24669","0.01218"
"39.21600","3.26822","0.01192"
"39.47400","3.28974","0.01160"
"39.73200","3.31126","0.01148"
"39.99000","3.33273","0.01181"
"40.24800","3.35425","0.01185"
"40.50600","3.37572","0.01238"
"40.76400","3.39724","0.01163"
"41.02200","3.41871","0.01227"
"41.28000","3.44023","0.01231"
"41.53800","3.46163","0.01194"
"41.79600","3.48322","0.01231"
"42.05400","3.50474","0.01222"
"42.31200","3.52627","0.01198"
"42.57000","3.54767","0.01273"
"42.82800","3.56920","0.01182"
"43.08600","3.59072","0.01181"
"43.34400","3.61224","0.01225"
"43.60200","3.63365","0.01218"
"43.86000","3.65523","0.01211"
"44.11800","3.67670","0.01211"
"44.37600","3.69822","0.01227"
"44.63400","3.71981","0.01199"
"44.89200","3.74127","0.01232"
"45.15000","3.76273","0.01301"
"45.40800","3.78426","0.01239"
"45.66600","3.80572","0.01234"
"45.92400","3.82725","0.01208"
"46.18200","3.84877","0.01224"
"46.44000","3.87018","0.01242"
"46.69800","3.89170","0.01219"
"46.95600","3.91311","0.01202"
"47.21400","3.93475","0.01175"
"47.47200","3.95621","0.01205"
"47.73000","3.97780","0.01289"
"47.98800","3.99920","0.01264"
"48.24600","4.02073","0.01286"
"48.50400","4.04219","0.01289"
"48.76200","4.06378","0.01270"
"49.02000","4.08518","0.01321"
"49.27800","4.10670","0.01236"
"49.53600","4.12823","0.01277"
"49.79400","4.14975","0.01305"
"50.05200","4.17122","0.01249"
"50.31000","4.19274","0.01251"
"50.56800","4.21421","0.01309"
"50.82600","4.23573","0.01283"
"51.08400","4.25725","0.01247"
"51.34200","4.27872","0.01266"
"51.60000","4.30018","0.01271"
"51.85800","4.32171","0.01294"
"52.11600","4.34323","0.01219"
"52.37400","4.36476","0.01242"
"52.63200","4.38628","0.01258"
"52.89000","4.40768","0.01255"
"53.14800","4.42927","0.01274"
"53.40600","4.45067","0.01318"
"53.66400","4.47220","0.01219"
"53.92200","4.49366","0.01257"
"54.18000","4.51519","0.01291"
"54.43800","4.53665","0.01266"
"54.69600","4.55823","0.01317"
"54.95400","4.57970","0.01255"
"55.21200","4.60122","0.01317"
"55.47000","4.62269","0.01273"
"55.72800","4.64427","0.01248"
"55.98600","4.66574","0.01246"
"56.24400","4.68726","0.01301"
"56.50200","4.70872","0.01290"
"56.76000","4.73019","0.01269"
"57.01800","4.75171","0.01287"
"57.27600","4.77330","0.01327"
"57.53400","4.79476","0.01337"
"57.79200","4.81623","0.01295"
"58.05000","4.83775","0.01282"
"58.30800","4.85922","0.01326"
"58.56600","4.88074","0.01267"
"58.82400","4.90226","0.01306"
"59.08200","4.92373","0.01293"
"59.34000","4.94519","0.01279"
"59.59800","4.96672","0.01306"
"59.85600","4.98824","0.01354"
"60.11400","5.00977","0.01284"
"60.37200","5.03117","0.01308"
"60.63000","5.05269","0.01324"
"60.88800","5.07416","0.01286"
"61.14600","5.09574","0.01297"
"61.40400","5.11721","0.01310"
"61.66200","5.13873","0.01334"
"61.92000","5.16014","0.01354"
"62.17800","5.18172","0.01337"
"62.43600","5.20324","0.01308"
"62.69400","5.22483","0.01341"
"62.95200","5.24617","0.01375"
"63.21000","5.26776","0.01364"
"63.46800","5.28922","0.01313"
"63.72600","5.31075","0.01347"
"63.98400","5.33221","0.01355"
"64.24200","5.35373","0.01348"
"64.50000","5.37526","0.01321"
"64.75800","5.39672","0.01327"
"65.01600","5.41825","0.01411"
"65.27400","5.43971","0.01329"
"65.53200","5.46130","0.01333"
"65.79000","5.48264","0.01369"
"66.04800","5.50422","0.01368"
"66.30600","5.52569","0.01360"
"66.56400","5.54727","0.01361"
"66.82200","5.56868","0.01364"
"67.08000","5.59020","0.01302"
"67.33800","5.61167","0.01332"
"67.59600","5.63325","0.01348"
"67.85400","5.65472","0.01353"
"68.11200","5.67624","0.01391"
"68.37000","5.69776","0.01352"
"68.62800","5.71929","0.01355"
"68.88600","5.74069","0.01346"
"69.14400","5.76228","0.01365"
"69.40200","5.78368","0.01368"
"69.66000","5.80520","0.01328"
"69.91800","5.82673","0.01330"
"70.17600","5.84825","0.01313"
"70.43400","5.86984","0.01343"
"70.69200","5.89124","0.01393"
"70.95000","5.91271","0.01352"
"71.20800","5.93417","0.01336"
"71.46600","5.95575","0.01366"
"71.72400","5.97722","0.01403"
"71.98200","5.99874","0.01340"
"72.24000","6.02021","0.01317"
"72.49800","6.04173","0.01387"
"72.75600","6.06314","0.01348"
"73.01400","6.08478","0.01354"
"73.27200","6.10619","0.01366"
"73.53000","6.12771","0.01354"
"73.78800","6.14917","0.01360"
"74.04600","6.17076","0.01347"
"74.30400","6.19222","0.01320"
"74.56200","6.21375","0.01350"
"74.82000","6.23521","0.01339"
"75.07800","6.25674","0.01335"
"75.33600","6.27826","0.01376"
"75.59400","6.29972","0.01329"
"75.85200","6.32119","0.01353"
"76.11000","6.34277","0.01407"
"76.36800","6.36430","0.01351"
"76.62600","6.38576","0.01415"
"76.88400","6.40729","0.01335"
"77.14200","6.42869","0.01342"
"77.40000","6.45027","0.01444"
"77.65800","6.47168","0.01392"
"77.91600","6.49326","0.01380"
"78.17400","6.51473","0.01380"
"78.43200","6.53625","0.01426"
"78.69000","6.55772","0.01405"
"78.94800","6.57924","0.01401"
"79.20600","6.60070","0.01414"
"79.46400","6.62223","0.01405"
"79.72200","6.64369","0.01381"
"79.98000","6.66528","0.01401"
"80.23800","6.68668","0.01362"
"80.49600","6.70827","0.01305"
"80.75400","6.72973","0.01253"
"81.01200","6.75126","0.01295"
"81.27000","6.77272","0.01235"
"81.52800","6.79424","0.01302"
"81.78600","6.81577","0.01278"
"82.04400","6.83723","0.01250"
"82.30200","6.85870","0.01327"
"82.56000","6.88022","0.01286"
"82.81800","6.90175","0.01298"
"83.07600","6.92321","0.01303"
"83.33400","6.94473","0.01297"
"83.59200","6.96620","0.01357"
"83.85000","6.98778","0.01324"
"84.10800","7.00919","0.01322"
"84.36600","7.03077","0.01295"
"84.62400","7.05218","0.01321"
"84.88200","7.07376","0.01327"
"85.14000","7.09516","0.01323"
"85.39800","7.11675","0.01366"
"85.65600","7.13821","0.01313"
"85.91400","7.15968","0.01308"
"86.17200","7.18114","0.01352"
"86.43000","7.20267","0.01282"
"86.68800","7.22419","0.01327"
"86.94600","7.24577","0.01340"
"87.20400","7.26724","0.01296"
"87.46200","7.28870","0.01373"
"87.72000","7.31023","0.01390"
"87.97800","7.33175","0.01343"
"88.23600","7.35328","0.01392"
"88.49400","7.37480","0.01379"
"88.75200","7.39620","0.01412"
"89.01000","7.41773","0.01376"
"89.26800","7.43925","0.01345"
"89.52600","7.46072","0.01351"
"89.78400","7.48224","0.01352"
"90.04200","7.50365","0.01389"
"90.30000","7.52523","0.01349"
"90.55800","7.54669","0.01304"
"90.81600","7.56828","0.01430"
"91.07400","7.58968","0.01358"
"91.33200","7.61127","0.01367"
"91.59000","7.63267","0.01355"
"91.84800","7.65426","0.01403"
"92.10600","7.67572","0.01449"
"92.36400","7.69719","0.01419"
"92.62200","7.71871","0.01420"
"92.88000","7.74023","0.01438"
"93.13800","7.76164","0.01405"
"93.39600","7.78328","0.01404"
"93.65400","7.80475","0.01462"
"93.91200","7.82621","0.01437"
"94.17000","7.84773","0.01461"
"94.42800","7.86926","0.01413"
"94.68600","7.89078","0.01411"
"94.94400","7.91225","0.01421"
"95.20200","7.93365","0.01483"
"95.46000","7.95524","0.01453"
"95.71800","7.97676","0.01451"
"95.97600","7.99823","0.01478"
"96.23400","8.01975","0.01427"
"96.49200","8.04121","0.01486"
"96.75000","8.06274","0.01464"
"97.00800","8.08420","0.01403"
"97.26600","8.10573","0.01468"
"97.52400","8.12713","0.01437"
"97.78200","8.14872","0.01509"
"98.04000","8.17012","0.01454"
"98.29800","8.19176","0.01459"
"98.55600","8.21323","0.01402"
"98.81400","8.23475","0.01426"
"99.07200","8.25616","0.01470"
"99.33000","8.27774","0.01466"
"99.58800","8.29915","0.01412"
"99.84600","8.32073","0.01437"
"100.10400","8.34219","0.01406"
"100.36200","8.36378","0.01450"
"100.62000","8.38524","0.01417"
"100.87800","8.40671","0.01436"
"101.13600","8.42829","0.01441"
"101.39400","8.44970","0.01449"
"101.65200","8.47122","0.01446"
"101.91000","8.49269","0.01451"
"102.16800","8.51427","0.01468"
"102.42600","8.53573","0.01423"
"102.68400","8.55720","0.01449"
"102.94200","8.57866","0.01500"
"103.20000","8.60025","0.01480"
"103.45800","8.62171","0.01439"
"103.71600","8.64323","0.01463"
"103.97400","8.66464","0.01440"
"104.23200","8.68622","0.01491"
"104.49000","8.70769","0.01454"
"104.74800","8.72921","0.01462"
"105.00600","8.75068","0.01453"
"105.26400","8.77220","0.01532"
"105.52200","8.79366","0.01465"
"105.78000","8.81525","0.01478"
"106.03800","8.83671","0.01514"
"106.29600","8.85830","0.01490"
"106.55400","8.87970","0.01485"
"106.81200","8.90123","0.01493"
"107.07000","8.92269","0.01522"
"107.32800","8.94427","0.01446"
"107.58600","8.96574","0.01485"
"107.84400","8.98720","0.01507"
"108.10200","9.00873","0.01534"
"108.36000","9.03019","0.01530"
"108.61800","9.05178","0.01509"
"108.87600","9.07324","0.01525"
"109.13400","9.09477","0.01557"
"109.39200","9.11617","0.01517"
"109.65000","9.13775","0.01496"
"109.90800","9.15922","0.01541"
"110.16600","9.18074","0.01523"
"110.42400","9.20215","0.01575"
"110.68200","9.22373","0.01390"
"110.94000","9.24520","0.01392"
"111.19800","9.26672","0.01423"
"111.45600","9.28818","0.01384"
"111.71400","9.30971","0.01411"
"111.97200","9.33123","0.01437"
"112.23000","9.35276","0.01416"
"112.48800","9.37422","0.01387"
"112.74600","9.39575","0.01393"
"113.00400","9.41715","0.01468"
"113.26200","9.43873","0.01426"
"113.52000","9.46026","0.01453"
"113.77800","9.48172","0.01416"
"114.03600","9.50325","0.01390"
"114.29400","9.52471","0.01433"
"114.55200","9.54618","0.01414"
"114.81000","9.56770","0.01451"
"115.06800","9.58928","0.01423"
"115.32600","9.61069","0.01450"
"115.58400","9.63227","0.01451"
"115.84200","9.65368","0.01473"
"116.10000","9.67526","0.01471"
"116.35800","9.69673","0.01464"
"116.61600","9.71825","0.01485"
"116.87400","9.73966","0.01463"
"117.13200","9.76124","0.01495"
"117.39000","9.78264","0.01510"
"117.64800","9.80423","0.01439"
"117.90600","9.82569","0.01446"
"118.16400","9.84722","0.01385"
"118.42200","9.86868","0.01494"
"118.68000","9.89026","0.01480"
"118.93800","9.91173","0.01471"
"119.19600","9.93325","0.01546"
"119.45400","9.95472","0.01431"
"119.71200","9.97624","0.01448"
"119.97000","9.99771","0.01511"
"120.22800","10.01923","0.01494"
"120.48600","10.04070","0.01457"
"120.74400","10.06222","0.01512"
"121.00200","10.08374","0.01476"
"121.26000","10.10521","0.01538"
"121.51800","10.12673","0.01490"
"121.77600","10.14820","0.01558"
"122.03400","10.16972","0.01551"
"122.29200","10.19113","0.01491"
"122.55000","10.21277","0.01518"
"122.80800","10.23423","0.01545"
"123.06600","10.25576","0.01560"
"123.32400","10.27710","0.01545"
"123.58200","10.29875","0.01584"
"123.84000","10.32021","0.01506"
"124.09800","10.34174","0.01538"
"124.35600","10.36320","0.01514"
"124.61400","10.38472","0.01514"
"124.87200","10.40625","0.01562"
"125.13000","10.42771","0.01547"
"125.38800","10.44918","0.01542"
"125.64600","10.47070","0.01557"
"125.90400","10.49223","0.01583"
"126.16200","10.51369","0.01564"
"126.42000","10.53527","0.01585"
"126.67800","10.55674","0.01583"
"126.93600","10.57820","0.01572"
"127.19400","10.59973","0.01654"
"127.45200","10.62125","0.01574"
"127.71000","10.64272","0.01577"
"127.96800","10.66424","0.01600"
"128.22600","10.68565","0.01634"
"128.48400","10.70723","0.01608"
"128.74200","10.72869","0.01638"
"129.00000","10.75028","0.01630"
"129.25800","10.77168","0.01603"
"129.51600","10.79321","0.01618"
"129.77400","10.81467","0.01627"
"130.03200","10.83626","0.01592"
"130.29000","10.85772","0.01660"
"130.54800","10.87924","0.01668"
"130.80600","10.90065","0.01628"
"131.06400","10.92223","0.01618"
"131.32200","10.94370","0.01624"
"131.58000","10.96528","0.01665"
"131.83800","10.98675","0.01718"
"132.09600","11.00821","0.01655"
"132.35400","11.02973","0.01720"
"132.61200","11.05126","0.01717"
"132.87000","11.07272","0.01704"
"133.12800","11.09425","0.01677"
"133.38600","11.11577","0.01716"
"133.64400","11.13718","0.01684"
"133.90200","11.15876","0.01714"
"134.16000","11.18022","0.01694"
"134.41800","11.20181","0.01721"
"134.67600","11.22315","0.01747"
"134.93400","11.24474","0.01758"
"135.19200","11.26620","0.01778"
"135.45000","11.28779","0.01788"
"135.70800","11.30919","0.01801"
"135.96600","11.33071","0.01732"
"136.22400","11.35218","0.01779"
"136.48200","11.37376","0.01765"
"136.74000","11.39517","0.01804"
"136.99800","11.41669","0.01826"
"137.25600","11.43822","0.01799"
"137.51400","11.45980","0.01765"
"137.77200","11.48127","0.01816"
"138.03000","11.50279","0.01829"
"138.28800","11.52419","0.01825"
"138.54600","11.54572","0.01798"
"138.80400","11.56718","0.01813"
"139.06200","11.58871","0.01834"
"139.32000","11.61023","0.01819"
"139.57800","11.63175","0.01856"
"139.83600","11.65322","0.01898"
"140.09400","11.67468","0.01886"
"140.35200","11.69621","0.01818"
"140.61000","11.71767","0.01690"
"140.86800","11.73926","0.01764"
"141.12600","11.76066","0.01731"
"141.38400","11.78225","0.01801"
"141.64200","11.80365","0.01780"
"141.90000","11.82529","0.01783"
"142.15800","11.84670","0.01809"
"142.41600","11.86822","0.01828"
"142.67400","11.88969","0.01797"
"142.93200","11.91127","0.01863"
"143.19000","11.93273","0.01852"
"143.44800","11.95426","0.01892"
"143.70600","11.97572","0.01891"
"143.96400","11.99725","0.01924"
"144.22200","12.01871","0.01927"
"144.48000","12.04024","0.01918"
"144.73800","12.06176","0.01965"
"144.99600","12.08323","0.01927"
"145.25400","12.10475","0.01955"
"145.51200","12.12627","0.01912"
"145.77000","12.14774","0.01972"
"146.02800","12.16920","0.01974"
"146.28600","12.19073","0.01953"
"146.54400","12.21219","0.01933"
"146.80200","12.23372","0.01937"
"147.06000","12.25524","0.01968"
"147.31800","12.27670","0.02019"
"147.57600","12.29817","0.02038"
"147.83400","12.31975","0.02044"
"148.09200","12.34116","0.02020"
"148.35000","12.36274","0.01991"
"148.60800","12.38415","0.02028"
"148.86600","12.40573","0.02034"
"149.12400","12.42719","0.02028"
"149.38200","12.44878","0.02081"
"149.64000","12.47018","0.02129"
"149.89800","12.49177","0.02022"
"150.15600","12.51317","0.02037"
"150.41400","12.53476","0.02105"
"150.67200","12.55622","0.02123"
"150.93000","12.57774","0.02096"
"151.18800","12.59921","0.02101"
"151.44600","12.62073","0.02113"
"151.70400","12.64226","0.02213"
"151.96200","12.66372","0.02177"
"152.22000","12.68525","0.02237"
"152.47800","12.70671","0.02232"
"152.73600","12.72829","0.02177"
"152.99400","12.74970","0.02232"
"153.25200","12.77128","0.02172"
"153.51000","12.79269","0.02117"
"153.76800","12.81427","0.02212"
"154.02600","12.83568","0.02154"
"154.28400","12.85720","0.02249"
"154.54200","12.87873","0.02105"
"154.80000","12.90025","0.02178"
"155.05800","12.92171","0.02237"
"155.31600","12.94324","0.02151"
"155.57400","12.96470","0.02189"
"155.83200","12.98623","0.02261"
"156.09000","13.00769","0.02284"
"156.34800","13.02922","0.02196"
"156.60600","13.05068","0.02231"
"156.86400","13.07226","0.02252"
"157.12200","13.09373","0.02248"
"157.38000","13.11525","0.02306"
"157.63800","13.13666","0.02312"
"157.89600","13.15824","0.02367"
"158.15400","13.17976","0.02385"
"158.41200","13.20123","0.02398"
"158.67000","13.22275","0.02426"
"158.92800","13.24422","0.02407"
"159.18600","13.26574","0.02339"
"159.44400","13.28721","0.02446"
"159.70200","13.30873","0.02403"
"159.96000","13.33020","0.02431"
"160.21800","13.35172","0.02469"
"160.47600","13.37313","0.02487"
"160.73400","13.39471","0.02541"
"160.99200","13.41623","0.02543"
"161.25000","13.43776","0.02556"
"161.50800","13.45922","0.02626"
"161.76600","13.48075","0.02620"
"162.02400","13.50221","0.02630"
"162.28200","13.52380","0.02685"
"162.54000","13.54520","0.02710"
"162.79800","13.56672","0.02765"
"163.05600","13.58819","0.02729"
"163.31400","13.60971","0.02749"
"163.57200","13.63130","0.02799"
"163.83000","13.65270","0.02791"
"164.08800","13.67417","0.02837"
"164.34600","13.69575","0.02876"
"164.60400","13.71727","0.02883"
"164.86200","13.73874","0.02901"
"165.12000","13.76026","0.02916"
"165.37800","13.78173","0.02946"
"165.63600","13.80325","0.02974"
"165.89400","13.82472","0.02967"
"166.15200","13.84624","0.02996"
"166.41000","13.86764","0.02994"
"166.66800","13.88923","0.03024"
"166.92600","13.91063","0.02838"
"167.18400","13.93228","0.02878"
"167.44200","13.95368","0.02889"
"167.70000","13.97527","0.02926"
"167.95800","13.99673","0.02944"
"168.21600","14.01825","0.02927"
"168.47400","14.03966","0.02958"
"168.73200","14.06124","0.02972"
"168.99000","14.08271","0.03019"
"169.24800","14.10423","0.02987"
"169.50600","14.12570","0.03045"
"169.76400","14.14722","0.03058"
"170.02200","14.16875","0.03114"
"170.28000","14.19021","0.03096"
"170.53800","14.21173","0.03139"
"170.79600","14.23320","0.03155"
"171.05400","14.25478","0.03166"
"171.31200","14.27625","0.03184"
"171.57000","14.29771","0.03225"
"171.82800","14.31918","0.03272"
"172.08600","14.34076","0.03259"
"172.34400","14.36222","0.03314"
"172.60200","14.38375","0.03363"
"172.86000","14.40515","0.03424"
"173.11800","14.42680","0.03447"
"173.37600","14.44820","0.03407"
"173.63400","14.46979","0.03314"
"173.89200","14.49119","0.03316"
"174.15000","14.51271","0.03396"
"174.40800","14.53418","0.03440"
"174.66600","14.55576","0.03478"
"174.92400","14.57723","0.03509"
"175.18200","14.59875","0.03571"
"175.44000","14.62021","0.03615"
"175.69800","14.64174","0.03711"
"175.95600","14.66326","0.03836"
"176.21400","14.68479","0.03904"
"176.47200","14.70625","0.04032"
"176.73000","14.72772","0.04114"
"176.98800","14.74924","0.04226"
"177.24600","14.77071","0.04276"
"177.50400","14.79229","0.04404"
"177.76200","14.81376","0.04632"
"178.02000","14.83522","0.04711"
"178.27800","14.85668","0.04729"
"178.53600","14.87827","0.04792"
"178.79400","14.89967","0.05031"
"179.05200","14.92126","0.05152"
"179.31000","14.94260","0.05137"
"179.56800","14.96424","0.05293"
"179.82600","14.98565","0.05395"
"180.08400","15.00723","0.05577"
"180.34200","15.02870","0.05626"
"180.60000","15.05028","0.05759"
"180.85800","15.07175","0.05910"
"181.11600","15.09327","0.06013"
"181.37400","15.11473","0.06119"
"181.63200","15.13626","0.06276"
"181.89000","15.15766","0.06280"
"182.14800","15.17925","0.06416"
"182.40600","15.20071","0.06501"
"182.66400","15.22224","0.06660"
"182.92200","15.24376","0.06764"
"183.18000","15.26522","0.06918"
"183.43800","15.28675","0.07025"
"183.69600","15.30821","0.07199"
"183.95400","15.32980","0.07224"
"184.21200","15.35120","0.07374"
"184.47000","15.37273","0.07480"
"184.72800","15.39419","0.07548"
"184.98600","15.41577","0.07593"
"185.24400","15.43724","0.07697"
"185.50200","15.45876","0.07762"
"185.76000","15.48017","0.07819"
"186.01800","15.50175","0.07860"
"186.27600","15.52316","0.07895"
"186.53400","15.54474","0.07951"
"186.79200","15.56621","0.07945"
"187.05000","15.58773","0.08041"
"187.30800","15.60919","0.08181"
"187.56600","15.63072","0.08309"
"187.82400","15.65224","0.08518"
"188.08200","15.67377","0.08660"
"188.34000","15.69517","0.08710"
"188.59800","15.71675","0.08712"
"188.85600","15.73828","0.09037"
"189.11400","15.75974","0.09430"
"189.37200","15.78121","0.09717"
"189.63000","15.80273","0.10279"
"189.88800","15.82426","0.10433"
"190.14600","15.84572","0.10850"
"190.40400","15.86724","0.11201"
"190.66200","15.88871","0.11548"
"190.92000","15.91023","0.11981"
"191.17800","15.93170","0.12145"
"191.43600","15.95328","0.12277"
"191.69400","15.97469","0.12293"
"191.95200","15.99621","0.12739"
"192.21000","16.01762","0.13229"
"192.46800","16.03920","0.13486"
"192.72600","16.06072","0.13688"
"192.98400","16.08231","0.13817"
"193.24200","16.10371","0.13900"
"193.50000","16.12524","0.14018"
"193.75800","16.14670","0.14160"
"194.01600","16.16823","0.14325"
"194.27400","16.18969","0.14295"
"194.53200","16.21121","0.14700"
"194.79000","16.23268","0.15018"
"195.04800","16.25426","0.15346"
"195.30600","16.27573","0.15628"
"195.56400","16.29725","0.15893"
"195.82200","16.31872","0.16260"
"196.08000","16.34024","0.16630"
"196.33800","16.36170","0.16947"
"196.59600","16.38323","0.17232"
"196.85400","16.40475","0.17493"
"197.11200","16.42616","0.17692"
"197.37000","16.44774","0.17958"
"197.62800","16.46921","0.18109"
"197.88600","16.49073","0.18319"
"198.14400","16.51225","0.18520"
"198.40200","16.53372","0.18712"
"198.66000","16.55518","0.18904"
"198.91800","16.57671","0.19085"
"199.17600","16.59823","0.19274"
"199.43400","16.61976","0.19457"
"199.69200","16.64116","0.19832"
"199.95000","16.66274","0.20221"
"200.20800","16.68421","0.20601"
"200.46600","16.70579","0.21007"
"200.72400","16.72720","0.21350"
"200.98200","16.74872","0.21740"
"201.24000","16.77024","0.22012"
"201.49800","16.79171","0.22323"
"201.75600","16.81324","0.22665"
"202.01400","16.83476","0.22910"
"202.27200","16.85622","0.23076"
"202.53000","16.87769","0.23342"
"202.78800","16.89921","0.23651"
"203.04600","16.92074","0.24068"
"203.30400","16.94226","0.24766"
"203.56200","16.96367","0.25331"
"203.82000","16.98525","0.25907"
"204.07800","17.00671","0.26400"
"204.33600","17.02830","0.26779"
"204.59400","17.04970","0.27360"
"204.85200","17.07123","0.27816"
"205.11000","17.09269","0.28348"
"205.36800","17.11422","0.28748"
"205.62600","17.13568","0.28956"
"205.88400","17.15726","0.29114"
"206.14200","17.17873","0.29176"
"206.40000","17.20025","0.29203"
"206.65800","17.22172","0.29230"
"206.91600","17.24324","0.29311"
"207.17400","17.26471","0.29511"
"207.43200","17.28617","0.29690"
"207.69000","17.30770","0.30043"
"207.94800","17.32922","0.30379"
"208.20600","17.35074","0.30775"
"208.46400","17.37227","0.31214"
"208.72200","17.39373","0.31720"
"208.98000","17.41525","0.32308"
"209.23800","17.43672","0.32893"
"209.49600","17.45824","0.33463"
"209.75400","17.47977","0.33845"
"210.01200","17.50111","0.34160"
"210.27000","17.52276","0.34401"
"210.52800","17.54416","0.34580"
"210.78600","17.56581","0.34729"
"211.04400","17.58721","0.34761"
"211.30200","17.60874","0.34973"
"211.56000","17.63014","0.35090"
"211.81800","17.65172","0.35581"
"212.07600","17.67325","0.36201"
"212.33400","17.69477","0.36540"
"212.59200","17.71624","0.36864"
"212.85000","17.73776","0.37146"
"213.10800","17.75922","0.37395"
"213.36600","17.78075","0.37696"
"213.62400","17.80221","0.37989"
"213.88200","17.82374","0.38228"
"214.14000","17.84520","0.38489"
"214.39800","17.86673","0.38774"
"214.65600","17.88825","0.39054"
"214.91400","17.90972","0.39296"
"215.17200","17.93118","0.39651"
"215.43000","17.95271","0.39964"
"215.68800","17.97423","0.40385"
"215.94600","17.99575","0.40774"
"216.20400","18.01722","0.41306"
"216.46200","18.03868","0.41926"
"216.72000","18.06026","0.42355"
"216.97800","18.08167","0.42882"
"217.23600","18.10325","0.43298"
"217.49400","18.12466","0.43705"
"217.75200","18.14618","0.43923"
"218.01000","18.16765","0.44018"
"218.26800","18.18923","0.44120"
"218.52600","18.21070","0.44280"
"218.78400","18.23228","0.44699"
"219.04200","18.25368","0.44851"
"219.30000","18.27527","0.45458"
"219.55800","18.29673","0.46142"
"219.81600","18.31826","0.46734"
"220.07400","18.33972","0.47343"
"220.33200","18.36119","0.47876"
"220.59000","18.38271","0.48362"
"220.84800","18.40423","0.48733"
"221.10600","18.42576","0.49065"
"221.36400","18.44716","0.49358"
"221.62200","18.46875","0.49698"
"221.88000","18.49021","0.49952"
"222.13800","18.51174","0.50050"
"222.39600","18.53320","0.50230"
"222.65400","18.55473","0.50347"
"222.91200","18.57613","0.50462"
"223.17000","18.59772","0.50661"
"223.42800","18.61924","0.50802"
"223.68600","18.64076","0.50148"
"223.94400","18.66217","0.50329"
"224.20200","18.68375","0.50431"
"224.46000","18.70522","0.50493"
"224.71800","18.72674","0.50702"
"224.97600","18.74820","0.51051"
"225.23400","18.76973","0.51402"
"225.49200","18.79119","0.51681"
"225.75000","18.81272","0.52052"
"226.00800","18.83424","0.52493"
"226.26600","18.85577","0.53014"
"226.52400","18.87723","0.53514"
"226.78200","18.89869","0.53858"
"227.04000","18.92022","0.54144"
"227.29800","18.94174","0.53013"
"227.55600","18.96327","0.52416"
"227.81400","18.98467","0.04847"
"228.07200","19.00620","0.07619"
"228.33000","19.02772","0.05414"
"228.58800","19.04924","0.07734"
"228.84600","19.07071","0.06061"
"229.10400","19.09223","0.07510"
"229.36200","19.11364","0.06072"
"229.62000","19.13528","0.07303"
"229.87800","19.15669","0.06633"
"230.13600","19.17821","0.06961"
"230.39400","19.19967","0.06258"
"230.65200","19.22120","0.06271"
"230.91000","19.24266","0.06885"
"231.16800","19.26425","0.06341"
"231.42600","19.28571","0.07328"
"231.68400","19.30724","0.06312"
"231.94200","19.32870","0.07610"
"232.20000","19.35023","0.06653"
"232.45800","19.37175","0.07702"
"232.71600","19.39327","0.06853"
"232.97400","19.41468","0.07784"
"233.23200","19.43620","0.07239"
"233.49000","19.45773","0.07777"
"233.74800","19.47919","0.07563"
"234.00600","19.50072","0.07802"
"234.26400","19.52224","0.07794"
"234.52200","19.54376","0.07824"
"234.78000","19.56523","0.07986"
"235.03800","19.58675","0.07851"
"235.29600","19.60816","0.08341"
"235.55400","19.62968","0.07992"
"235.81200","19.65114","0.08573"
"236.07000","19.67279","0.08241"
"236.32800","19.69419","0.08798"
"236.58600","19.71578","0.08752"
"236.84400","19.73718","0.08997"
"237.10200","19.75871","0.09418"
"237.36000","19.78017","0.09262"
"237.61800","19.80169","0.10039"
"237.87600","19.82322","0.09796"
"238.13400","19.84474","0.10459"
"238.39200","19.86621","0.10191"
"238.65000","19.88773","0.10686"
"238.90800","19.90926","0.10803"
"239.16600","19.93072","0.10955"
"239.42400","19.95218","0.11543"
"239.68200","19.97371","0.11389"
"239.94000","19.99524","0.12071"
"240.19800","20.01670","0.12029"
"240.45600","20.03822","0.12687"
"240.71400","20.05969","0.12860"
"240.97200","20.08127","0.13065"
"241.23000","20.10274","0.13332"
"241.48800","20.12420","0.07101"
"241.74600","20.14566","0.07067"
"242.00400","20.16725","0.06083"
"242.26200","20.18871","0.07060"
"242.52000","20.21024","0.06504"
"242.77800","20.23170","0.07329"
"243.03600","20.25323","0.07116"
"243.29400","20.27469","0.07326"
"243.55200","20.29621","0.07419"
"243.81000","20.31768","0.07436"
"244.06800","20.33926","0.07599"
"244.32600","20.36073","0.07627"
"244.58400","20.38225","0.07747"
"244.84200","20.40372","0.07709"
"245.10000","20.42524","0.07900"
"245.35800","20.44670","0.07791"
"245.61600","20.46817","0.07997"
"245.87400","20.48969","0.07837"
"246.13200","20.51116","0.08113"
"246.39000","20.53274","0.08003"
"246.64800","20.55421","0.08279"
"246.90600","20.57573","0.08303"
"247.16400","20.59719","0.08554"
"247.42200","20.61878","0.08863"
"247.68000","20.64024","0.08867"
"247.93800","20.66177","0.09595"
"248.19600","20.68311","0.09402"
"248.45400","20.70470","0.10167"
"248.71200","20.72616","0.10002"
"248.97000","20.74775","0.10575"
"249.22800","20.76921","0.10632"
"249.48600","20.79073","0.10732"
"249.74400","20.81220","0.11096"
"250.00200","20.83372","0.11213"
"250.26000","20.85518","0.11636"
"250.51800","20.87671","0.11705"
"250.77600","20.89824","0.12355"
"251.03400","20.91976","0.12340"
"251.29200","20.94122","0.12802"
"251.55000","20.96275","0.13066"
"251.80800","20.98427","0.13153"
"252.06600","21.00574","0.13411"
"252.32400","21.02720","0.13447"
"252.58200","21.04873","0.13638"
"252.84000","21.07025","0.13698"
"253.09800","21.09171","0.13783"
"253.35600","21.11324","0.13858"
"253.61400","21.13464","0.13883"
"253.87200","21.15623","0.13984"
"254.13000","21.17769","0.14030"
"254.38800","21.19921","0.14134"
"254.64600","21.22068","0.14220"
"254.90400","21.24226","0.14364"
"255.16200","21.26373","0.14283"
"255.42000","21.28531","0.14389"
"255.67800","21.30672","0.14441"
"255.93600","21.32824","0.14684"
"256.19400","21.34965","0.14838"
"256.45200","21.37123","0.15007"
"256.71000","21.39270","0.14644"
"256.96800","21.41428","0.14757"
"257.22600","21.43574","0.15003"
"257.48400","21.45721","0.15401"
"257.74200","21.47873","0.15449"
"258.00000","21.50020","0.15765"
"258.25800","21.52172","0.15857"
"258.51600","21.54319","0.16025"
"258.77400","21.56471","0.16368"
"259.03200","21.58623","0.16462"
"259.29000","21.60776","0.16749"
"259.54800","21.62922","0.16868"
"259.80600","21.65075","0.17035"
"260.06400","21.67215","0.17192"
"260.32200","21.69380","0.17289"
"260.58000","21.71520","0.17435"
"260.83800","21.73672","0.17559"
"261.09600","21.75813","0.17596"
"261.35400","21.77971","0.17495"
"261.61200","21.80118","0.17503"
"261.87000","21.82276","0.17642"
"262.12800","21.84416","0.17733"
"262.38600","21.86575","0.17819"
"262.64400","21.88721","0.17947"
"262.90200","21.90874","0.18036"
"263.16000","21.93020","0.18184"
"263.41800","21.95173","0.18216"
"263.67600","21.97319","0.18329"
"263.93400","21.99471","0.18362"
"264.19200","22.01624","0.18467"
"264.45000","22.03777","0.18590"
"264.70800","22.05923","0.18693"
"264.96600","22.08069","0.18773"
"265.22400","22.10222","0.18878"
"265.48200","22.12368","0.18972"
"265.74000","22.14520","0.19138"
"265.99800","22.16673","0.19228"
"266.25600","22.18826","0.19431"
"266.51400","22.20972","0.19540"
"266.77200","22.23124","0.19664"
"267.03000","22.25271","0.19837"
"267.28800","22.27423","0.20099"
"267.54600","22.29570","0.20349"
"267.80400","22.31722","0.20537"
"268.06200","22.33868","0.20716"
"268.32000","22.36027","0.20932"
"268.57800","22.38167","0.21175"
"268.83600","22.40320","0.21330"
"269.09400","22.42472","0.21489"
"269.35200","22.44625","0.21677"
"269.61000","22.46771","0.21831"
"269.86800","22.48923","0.21958"
"270.12600","22.51070","0.22192"
"270.38400","22.53222","0.22423"
"270.64200","22.55375","0.22580"
"270.90000","22.57521","0.22738"
"271.15800","22.59674","0.22848"
"271.41600","22.61820","0.22926"
"271.67400","22.63972","0.23027"
"271.93200","22.66119","0.23161"
"272.19000","22.68277","0.23340"
"272.44800","22.70418","0.23532"
"272.70600","22.72576","0.23804"
"272.96400","22.74717","0.24090"
"273.22200","22.76875","0.24428"
"273.48000","22.79022","0.24790"
"273.73800","22.81174","0.25239"
"273.99600","22.83315","0.25558"
"274.25400","22.85479","0.25869"
"274.51200","22.87625","0.26153"
"274.77000","22.89778","0.26402"
"275.02800","22.91924","0.26625"
"275.28600","22.94077","0.27017"
"275.54400","22.96217","0.27302"
"275.80200","22.98375","0.27608"
"276.06000","23.00522","0.27862"
"276.31800","23.02674","0.28186"
"276.57600","23.04820","0.28229"
"276.83400","23.06967","0.28487"
"277.09200","23.09120","0.28684"
"277.35000","23.11272","0.28833"
"277.60800","23.13424","0.28963"
"277.86600","23.15577","0.29023"
"278.12400","23.17723","0.29102"
"278.38200","23.19876","0.29140"
"278.64000","23.22028","0.29167"
"278.89800","23.24169","0.29185"
"279.15600","23.26327","0.29215"
"279.41400","23.28468","0.29213"
"279.67200","23.30626","0.29234"
"279.93000","23.32772","0.29285"
"280.18800","23.34925","0.29346"
"280.44600","23.37065","0.29455"
"280.70400","23.39224","0.29521"
"280.96200","23.41370","0.29727"
"281.22000","23.43523","0.29877"
"281.47800","23.45669","0.30059"
"281.73600","23.47821","0.30308"
"281.99400","23.49968","0.30477"
"282.25200","23.52126","0.30735"
"282.51000","23.54273","0.30857"
"282.76800","23.56425","0.31036"
"283.02600","23.58577","0.31253"
"283.28400","23.60724","0.31419"
"283.54200","23.62876","0.31785"
"283.80000","23.65023","0.31778"
"284.05800","23.67169","0.32086"
"284.31600","23.69322","0.32445"
"284.57400","23.71468","0.32795"
"284.83200","23.73621","0.33226"
"285.09000","23.75779","0.33600"
"285.34800","23.77919","0.33802"
"285.60600","23.80078","0.33973"
"285.86400","23.82218","0.34125"
"286.12200","23.84377","0.34301"
"286.38000","23.86517","0.34482"
"286.63800","23.88676","0.34570"
"286.89600","23.90822","0.34900"
"287.15400","23.92974","0.34952"
"287.41200","23.95121","0.35133"
"287.67000","23.97279","0.35461"
"287.92800","23.99420","0.35770"
"288.18600","24.01572","0.35802"
"288.44400","24.03718","0.35420"
"288.70200","24.05877","0.35054"
"288.96000","24.08017","0.34940"
"289.21800","24.10170","0.34893"
"289.47600","24.12322","0.35093"
"289.73400","24.14475","0.35175"
"289.99200","24.16627","0.35339"
"290.25000","24.18773","0.35531"
"290.50800","24.20926","0.35699"
"290.76600","24.23072","0.35773"
"291.02400","24.25225","0.35917"
"291.28200","24.27377","0.35989"
"291.54000","24.29524","0.35810"
"291.79800","24.31664","0.35936"
"292.05600","24.33822","0.36026"
"292.31400","24.35975","0.36066"
"292.57200","24.38128","0.36114"
"292.83000","24.40268","0.34679"
"293.08800","24.42420","0.34539"
"293.34600","24.44567","0.34486"
"293.60400","24.46725","0.34264"
"293.86200","24.48872","0.34128"
"294.12000","24.51024","0.32509"
"294.37800","24.53171","0.30228"
"294.63600","24.55329","0.28265"
"294.89400","24.57470","0.23341"
"295.15200","24.59628","0.20773"
"295.41000","24.61768","0.19300"
"295.66800","24.63921","0.18210"
"295.92600","24.66073","0.16722"
"296.18400","24.68225","0.14773"
"296.44200","24.70378","0.13244"
"296.70000","24.72524","0.09925"
"296.95800","24.74671","0.07969"
"297.21600","24.76817","0.07875"
"297.47400","24.78976","0.07903"
"297.73200","24.81122","0.07867"
"297.99000","24.83280","0.07914"
"298.24800","24.85421","0.07987"
"298.50600","24.87579","0.07974"
"298.76400","24.89720","0.08110"
"299.02200","24.91878","0.08014"
"299.28000","24.94019","0.08208"
"299.53800","24.96171","0.08098"
"299.79600","24.98318","0.08176"
"300.05400","25.00476","0.08202"
"300.31200","25.02622","0.08253"
"300.57000","25.04775","0.08372"
"300.82800","25.06921","0.08407"
"301.08600","25.09074","0.08659"
"301.34400","25.11226","0.08353"
"301.60200","25.13373","0.08488"
"301.86000","25.15519","0.08383"
"302.11800","25.17677","0.08361"
"302.37600","25.19818","0.08612"
"302.63400","25.21970","0.08487"
"302.89200","25.24123","0.08597"
"303.15000","25.26269","0.08550"
"303.40800","25.28422","0.08755"
"303.66600","25.30574","0.08895"
"303.92400","25.32721","0.08900"
"304.18200","25.34867","0.09141"
"304.44000","25.37025","0.09090"
"304.69800","25.39166","0.09330"
"304.95600","25.41324","0.09359"
"305.21400","25.43471","0.09463"
"305.47200","25.45629","0.09518"
"305.73000","25.47770","0.09614"
"305.98800","25.49928","0.09691"
"306.24600","25.52068","0.09647"
"306.50400","25.54227","0.09854"
"306.76200","25.56373","0.10009"
"307.02000","25.58526","0.10098"
"307.27800","25.60672","0.10312"
"307.53600","25.62825","0.10403"
"307.79400","25.64977","0.10608"
"308.05200","25.67123","0.10691"
"308.31000","25.69270","0.10815"
"308.56800","25.71422","0.10883"
"308.82600","25.73575","0.11038"
"309.08400","25.75721","0.11212"
"309.34200","25.77874","0.11282"
"309.60000","25.80020","0.11452"
"309.85800","25.82178","0.11669"
"310.11600","25.84319","0.11897"
"310.37400","25.86471","0.12028"
"310.63200","25.88618","0.12278"
"310.89000","25.90776","0.12583"
"311.14800","25.92923","0.12734"
"311.40600","25.95075","0.12948"
"311.66400","25.97216","0.13071"
"311.92200","25.99374","0.13226"
"312.18000","26.01520","0.13321"
"312.43800","26.03667","0.13422"
"312.69600","26.05813","0.13495"
"312.95400","26.07984","0.13695"
"313.21200","26.10118","0.13734"
"313.47000","26.12276","0.13822"
"313.72800","26.14423","0.13831"
"313.98600","26.16575","0.13910"
"314.24400","26.18728","0.13970"
"314.50200","26.20874","0.13996"
"314.76000","26.23021","0.13927"
"315.01800","26.25173","0.13955"
"315.27600","26.27325","0.14028"
"315.53400","26.29478","0.14053"
"315.79200","26.31624","0.14107"
"316.05000","26.33765","0.14198"
"316.30800","26.35923","0.14290"
"316.56600","26.38070","0.14319"
"316.82400","26.40228","0.14331"
"317.08200","26.42363","0.14513"
"317.34000","26.44521","0.14449"
"317.59800","26.46667","0.14539"
"317.85600","26.48826","0.14736"
"318.11400","26.50972","0.14745"
"318.37200","26.53125","0.14970"
"318.63000","26.55271","0.15029"
"318.88800","26.57424","0.15233"
"319.14600","26.59570","0.15388"
"319.40400","26.61728","0.14312"
"319.66200","26.63869","0.14204"
"319.92000","26.66021","0.14459"
"320.17800","26.68162","0.14318"
"320.43600","26.70326","0.14619"
"320.69400","26.72478","0.14673"
"320.95200","26.74625","0.14855"
"321.21000","26.76772","0.15164"
"321.46800","26.78924","0.15232"
"321.72600","26.81076","0.15472"
"321.98400","26.83223","0.15691"
"322.24200","26.85369","0.15728"
"322.50000","26.87516","0.16026"
"322.75800","26.89674","0.16013"
"323.01600","26.91821","0.15945"
"323.27400","26.93979","0.16098"
"323.53200","26.96119","0.16080"
"323.79000","26.98272","0.16257"
"324.04800","27.00418","0.12815"
"324.30600","27.02577","0.11995"
"324.56400","27.04723","0.12535"
"324.82200","27.06876","0.11673"
"325.08000","27.09016","0.12658"
"325.33800","27.11168","0.11982"
"325.59600","27.13321","0.12848"
"325.85400","27.15479","0.12462"
"326.11200","27.17626","0.12941"
"326.37000","27.19772","0.13078"
"326.62800","27.21918","0.13171"
"326.88600","27.24071","0.13475"
"327.14400","27.26223","0.13368"
"327.40200","27.28376","0.13671"
"327.66000","27.30516","0.13630"
"327.91800","27.32669","0.13769"
"328.17600","27.34827","0.13742"
"328.43400","27.36974","0.02754"
"328.69200","27.39126","0.02674"
"328.95000","27.41266","0.03094"
"329.20800","27.43425","0.02840"
"329.46600","27.45571","0.03156"
"329.72400","27.47724","0.03031"
"329.98200","27.49864","0.03049"
"330.24000","27.52028","0.03216"
"330.49800","27.54175","0.03047"
"330.75600","27.56327","0.03214"
"331.01400","27.58468","0.03130"
"331.27200","27.60626","0.03239"
"331.53000","27.62767","0.03284"
"331.78800","27.64925","0.03295"
"332.04600","27.67072","0.03350"
"332.30400","27.69224","0.03340"
"332.56200","27.71370","0.03394"
"332.82000","27.73523","0.03441"
"333.07800","27.75669","0.03442"
"333.33600","27.77822","0.03504"
"333.59400","27.79974","0.03468"
"333.85200","27.82121","0.03544"
"334.11000","27.84273","0.03609"
"334.36800","27.86419","0.03563"
"334.62600","27.88572","0.03642"
"334.88400","27.90718","0.03618"
"335.14200","27.92871","0.03636"
"335.40000","27.95017","0.03663"
"335.65800","27.97176","0.03691"
"335.91600","27.99322","0.03688"
"336.17400","28.01474","0.03696"
"336.43200","28.03615","0.03759"
"336.69000","28.05773","0.03750"
"336.94800","28.07920","0.03665"
"337.20600","28.10072","0.03672"
"337.46400","28.12219","0.03676"
"337.72200","28.14371","0.03722"
"337.98000","28.16523","0.03708"
"338.23800","28.18676","0.03668"
"338.49600","28.20822","0.03707"
"338.75400","28.22975","0.03782"
"339.01200","28.25121","0.03848"
"339.27000","28.27274","0.03923"
"339.52800","28.29420","0.04028"
"339.78600","28.31578","0.04072"
"340.04400","28.33719","0.04157"
"340.30200","28.35865","0.03870"
"340.56000","28.38018","0.03464"
"340.81800","28.40176","0.03433"
"341.07600","28.42328","0.03363"
"341.33400","28.44469","0.03373"
"341.59200","28.46622","0.03336"
"341.85000","28.48768","0.03331"
"342.10800","28.50926","0.03344"
"342.36600","28.53067","0.03339"
"342.62400","28.55219","0.03337"
"342.88200","28.57360","0.03310"
"343.14000","28.59524","0.03283"
"343.39800","28.61671","0.03340"
"343.65600","28.63823","0.03377"
"343.91400","28.65969","0.03384"
"344.17200","28.68116","0.03390"
"344.43000","28.70268","0.03407"
"344.68800","28.72427","0.03485"
"344.94600","28.74567","0.03481"
"345.20400","28.76726","0.03539"
"345.46200","28.78866","0.03581"
"345.72000","28.81024","0.03523"
"345.97800","28.83171","0.03591"
"346.23600","28.85323","0.03614"
"346.49400","28.87476","0.03631"
"346.75200","28.89622","0.03794"
"347.01000","28.91769","0.03765"
"347.26800","28.93921","0.03845"
"347.52600","28.96074","0.03867"
"347.78400","28.98220","0.03930"
"348.04200","29.00378","0.03968"
"348.30000","29.02513","0.03973"
"348.55800","29.04677","0.04129"
"348.81600","29.06818","0.04107"
"349.07400","29.08976","0.04269"
"349.33200","29.11110","0.04164"
"349.59000","29.13275","0.04239"
"349.84800","29.15416","0.04204"
"350.10600","29.17574","0.04224"
"350.36400","29.19720","0.04299"
"350.62200","29.21873","0.04431"
"350.88000","29.24025","0.04405"
"351.13800","29.26178","0.04461"
"351.39600","29.28318","0.04345"
"351.65400","29.30476","0.04318"
"351.91200","29.32623","0.04070"
"352.17000","29.34769","0.04147"
"352.42800","29.36922","0.02769"
"352.68600","29.39074","0.03227"
"352.94400","29.41227","0.01776"
"353.20200","29.43367","0.03011"
"353.46000","29.45520","0.02679"
"353.71800","29.47672","0.02867"
"353.97600","29.49824","0.02879"
"354.23400","29.51971","0.02400"
"354.49200","29.54123","0.03104"
"354.75000","29.56269","0.02560"
"355.00800","29.58422","0.02996"
"355.26600","29.60568","0.02837"
"355.52400","29.62721","0.02932"
"355.78200","29.64867","0.03000"
"356.04000","29.67026","0.02845"
"356.29800","29.69172","0.03101"
"356.55600","29.71325","0.02892"
"356.81400","29.73465","0.03128"
"357.07200","29.75624","0.02958"
"357.33000","29.77770","0.03092"
"357.58800","29.79922","0.03075"
"357.84600","29.82069","0.03062"
"358.10400","29.84221","0.03193"
"358.36200","29.86368","0.03077"
"358.62000","29.88526","0.03221"
"358.87800","29.90672","0.03150"
"359.13600","29.92825","0.03226"
"359.39400","29.94977","0.03237"
"359.65200","29.97118","0.03193"
"359.91000","29.99276","0.03353"
"360.16800","30.01423","0.03264"
"360.42600","30.03575","0.03401"
"360.68400","30.05715","0.03292"
"360.94200","30.07868","0.03418"
"361.20000","30.10021","0.03455"
"361.45800","30.12179","0.03471"
"361.71600","30.14319","0.03508"
"361.97400","30.16472","0.03493"
"362.23200","30.18618","0.03650"
"362.49000","30.20776","0.03537"
"362.74800","30.22917","0.03672"
"363.00600","30.25075","0.03668"
"363.26400","30.27216","0.03711"
"363.52200","30.29374","0.03739"
"363.78000","30.31521","0.03785"
"364.03800","30.33679","0.03926"
"364.29600","30.35820","0.03851"
"364.55400","30.37972","0.03981"
"364.81200","30.40118","0.04125"
"365.07000","30.42271","0.04086"
"365.32800","30.44423","0.04171"
"365.58600","30.46570","0.04286"
"365.84400","30.48722","0.04405"
"366.10200","30.50869","0.04426"
"366.36000","30.53027","0.04533"
"366.61800","30.55173","0.04660"
"366.87600","30.57326","0.04631"
"367.13400","30.59472","0.04793"
"367.39200","30.61625","0.04732"
"367.65000","30.63771","0.04870"
"367.90800","30.65930","0.04979"
"368.16600","30.68064","0.05034"
"368.42400","30.70217","0.05152"
"368.68200","30.72363","0.05216"
"368.94000","30.74528","0.05238"
"369.19800","30.76674","0.05297"
"369.45600","30.78826","0.05358"
"369.71400","30.80967","0.05452"
"369.97200","30.83125","0.05549"
"370.23000","30.85271","0.05562"
"370.48800","30.87424","0.05639"
"370.74600","30.89570","0.05656"
"371.00400","30.91723","0.05779"
"371.26200","30.93869","0.05739"
"371.52000","30.96022","0.05844"
"371.77800","30.98174","0.05915"
"372.03600","31.00327","0.05968"
"372.29400","31.02473","0.06033"
"372.55200","31.04619","0.06051"
"372.81000","31.06772","0.06147"
"373.06800","31.08919","0.06227"
"373.32600","31.11077","0.06273"
"373.58400","31.13211","0.06309"
"373.84200","31.15376","0.06371"
"374.10000","31.17516","0.06385"
"374.35800","31.19674","0.06467"
"374.61600","31.21815","0.06584"
"374.87400","31.23967","0.06581"
"375.13200","31.26114","0.06707"
"375.39000","31.28272","0.06743"
"375.64800","31.30418","0.06814"
"375.90600","31.32571","0.06832"
"376.16400","31.34723","0.06858"
"376.42200","31.36876","0.06896"
"376.68000","31.39022","0.07005"
"376.93800","31.41175","0.07018"
"377.19600","31.43321","0.06996"
"377.45400","31.45473","0.07128"
"377.71200","31.47620","0.07123"
"377.97000","31.49772","0.07171"
"378.22800","31.51925","0.07207"
"378.48600","31.54071","0.07246"
"378.74400","31.56223","0.07164"
"379.00200","31.58370","0.06811"
"379.26000","31.60522","0.00846"
"379.51800","31.62669","0.00559"
"379.77600","31.64821","0.00840"
"380.03400","31.66968","0.00527"
"380.29200","31.69120","0.00625"
"380.55000","31.71267","0.00564"
"380.80800","31.73425","0.00652"
"381.06600","31.75566","0.00708"
"381.32400","31.77718","0.00559"
"381.58200","31.79871","0.00596"
"381.84000","31.82029","0.00612"
"382.09800","31.84169","0.00684"
"382.35600","31.86328","0.00642"
"382.61400","31.88474","0.00617"
"382.87200","31.90627","0.00588"
"383.13000","31.92773","0.00629"
"383.38800","31.94919","0.00760"
"383.64600","31.97072","0.00660"
"383.90400","31.99224","0.00586"
"384.16200","32.01371","0.00568"
"384.35600","32.02985","0.00635"