File: Force_trajectories/170108_2/Specimen_RawData_3.csv
End date,"1/8/2017"
Specimen label,"11DG_85"
Maximum Load,"0.06319",N

Time,Extension,Load
(s),(mm),(N)
"0.00000","0.00000","0.00068"
"0.37800","0.03169","0.00199"
"0.75600","0.06320","0.00349"
"1.13400","0.09471","0.00423"
"1.51200","0.12622","0.00510"
"1.89000","0.15772","0.00596"
"2.26800","0.18917","0.00658"
"2.64600","0.22068","0.00667"
"3.02400","0.25219","0.00747"
"3.40200","0.28364","0.00779"
"3.78000","0.31515","0.00854"
"4.15800","0.34672","0.00843"
"4.53600","0.37817","0.00860"
"4.91400","0.40962","0.00909"
"5.29200","0.44119","0.00928"
"5.67000","0.47270","0.00968"
"6.04800","0.50415","0.00988"
"6.42600","0.53577","0.01024"
"6.80400","0.56716","0.01013"
"7.18200","0.59867","0.01012"
"7.56000","0.63024","0.01069"
"7.93800","0.66169","0.01088"
"8.31600","0.69308","0.01072"
"8.69400","0.72465","0.01135"
"9.07200","0.75622","0.01159"
"9.45000","0.78773","0.01137"
"9.82800","0.81912","0.01155"
"10.20600","0.85063","0.01173"
"10.58400","0.88219","0.01170"
"10.96200","0.91364","0.01230"
"11.34000","0.94515","0.01223"
"11.71800","0.97672","0.01161"
"12.09600","1.00817","0.01245"
"12.47400","1.03968","0.01211"
"12.85200","1.07119","0.01242"
"13.23000","1.10276","0.01281"
"13.60800","1.13421","0.01296"
"13.98600","1.16566","0.01327"
"14.36400","1.19717","0.01238"
"14.74200","1.22867","0.01299"
"15.12000","1.26018","0.01309"
"15.49800","1.29169","0.01355"
"15.87600","1.32320","0.01362"
"16.25400","1.35459","0.01372"
"16.63200","1.38622","0.01336"
"17.01000","1.41773","0.01386"
"17.38800","1.44918","0.01411"
"17.76600","1.48069","0.01419"
"18.14400","1.51214","0.01414"
"18.52200","1.54371","0.01499"
"18.90000","1.57516","0.01441"
"19.27800","1.60672","0.01389"
"19.65600","1.63823","0.01490"
"20.03400","1.66968","0.01474"
"20.41200","1.70119","0.01404"
"20.79000","1.73270","0.01480"
"21.16800","1.76415","0.01467"
"21.54600","1.79572","0.01512"
"21.92400","1.82723","0.01511"
"22.30200","1.85868","0.01446"
"22.68000","1.89013","0.01524"
"23.05800","1.92176","0.01520"
"23.43600","1.95320","0.01533"
"23.81400","1.98465","0.01540"
"24.19200","2.01616","0.01570"
"24.57000","2.04767","0.01549"
"24.94800","2.07918","0.01578"
"25.32600","2.11069","0.01519"
"25.70400","2.14214","0.01585"
"26.08200","2.17365","0.01600"
"26.46000","2.20516","0.01646"
"26.83800","2.23667","0.01581"
"27.21600","2.26824","0.01609"
"27.59400","2.29962","0.01563"
"27.97200","2.33119","0.01620"
"28.35000","2.36270","0.01644"
"28.72800","2.39421","0.01642"
"29.10600","2.42566","0.01637"
"29.48400","2.45717","0.01670"
"29.86200","2.48874","0.01626"
"30.24000","2.52013","0.01654"
"30.61800","2.55170","0.01603"
"30.99600","2.58327","0.01652"
"31.37400","2.61466","0.01696"
"31.75200","2.64616","0.01583"
"32.13000","2.67773","0.01646"
"32.50800","2.70918","0.01713"
"32.88600","2.74069","0.01702"
"33.26400","2.77226","0.01657"
"33.64200","2.80371","0.01708"
"34.02000","2.83516","0.01675"
"34.39800","2.86667","0.01708"
"34.77600","2.89818","0.01694"
"35.15400","2.92969","0.01701"
"35.53200","2.96114","0.01690"
"35.91000","2.99271","0.01704"
"36.28800","3.02421","0.01767"
"36.66600","3.05566","0.01747"
"37.04400","3.08717","0.01704"
"37.42200","3.11874","0.01708"
"37.80000","3.15013","0.01702"
"38.17800","3.18170","0.01691"
"38.55600","3.21321","0.01697"
"38.93400","3.24460","0.01689"
"39.31200","3.27617","0.01737"
"39.69000","3.30774","0.01740"
"40.06800","3.33913","0.01752"
"40.44600","3.37063","0.01757"
"40.82400","3.40220","0.01778"
"41.20200","3.43371","0.01763"
"41.58000","3.46516","0.01748"
"41.95800","3.49667","0.01778"
"42.33600","3.52824","0.01767"
"42.71400","3.55969","0.01817"
"43.09200","3.59120","0.01797"
"43.47000","3.62271","0.01755"
"43.84800","3.65422","0.01763"
"44.22600","3.68561","0.01808"
"44.60400","3.71718","0.01813"
"44.98200","3.74868","0.01782"
"45.36000","3.78019","0.01770"
"45.73800","3.81170","0.01819"
"46.11600","3.84321","0.01825"
"46.49400","3.87466","0.01794"
"46.87200","3.90617","0.01828"
"47.25000","3.93774","0.01835"
"47.62800","3.96919","0.01845"
"48.00600","4.00064","0.01878"
"48.38400","4.03215","0.01881"
"48.76200","4.06372","0.01867"
"49.14000","4.09516","0.01845"
"49.51800","4.12667","0.01881"
"49.89600","4.15824","0.01864"
"50.27400","4.18969","0.01823"
"50.65200","4.22114","0.01843"
"51.03000","4.25265","0.01874"
"51.40800","4.28416","0.01863"
"51.78600","4.31567","0.01934"
"52.16400","4.34718","0.01893"
"52.54200","4.37869","0.01934"
"52.92000","4.41020","0.01924"
"53.29800","4.44165","0.01882"
"53.67600","4.47321","0.01882"
"54.05400","4.50472","0.01884"
"54.43200","4.53611","0.01898"
"54.81000","4.56768","0.01953"
"55.18800","4.59919","0.01985"
"55.56600","4.63064","0.01892"
"55.94400","4.66221","0.01886"
"56.32200","4.69372","0.01905"
"56.70000","4.72517","0.01925"
"57.07800","4.75668","0.01919"
"57.45600","4.78824","0.01876"
"57.83400","4.81969","0.01901"
"58.21200","4.85114","0.01896"
"58.59000","4.88271","0.01876"
"58.96800","4.91416","0.01961"
"59.34600","4.94561","0.01857"
"59.72400","4.97718","0.01944"
"60.10200","5.00875","0.01922"
"60.48000","5.04014","0.01909"
"60.85800","5.07165","0.01880"
"61.23600","5.10322","0.01933"
"61.61400","5.13467","0.01900"
"61.99200","5.16617","0.01932"
"62.37000","5.19768","0.01944"
"62.74800","5.22919","0.01932"
"63.12600","5.26070","0.01960"
"63.50400","5.29215","0.01937"
"63.88200","5.32372","0.01925"
"64.26000","5.35523","0.01891"
"64.63800","5.38668","0.01979"
"65.01600","5.41819","0.01995"
"65.39400","5.44970","0.01926"
"65.77200","5.48109","0.01944"
"66.15000","5.51271","0.01981"
"66.52800","5.54422","0.01976"
"66.90600","5.57561","0.02017"
"67.28400","5.60718","0.01992"
"67.66200","5.63869","0.02001"
"68.04000","5.67020","0.02005"
"68.41800","5.70171","0.02021"
"68.79600","5.73316","0.01998"
"69.17400","5.76467","0.02062"
"69.55200","5.79618","0.02017"
"69.93000","5.82763","0.01949"
"70.30800","5.85920","0.01986"
"70.68600","5.89070","0.02028"
"71.06400","5.92215","0.02004"
"71.44200","5.95372","0.02041"
"71.82000","5.98523","0.02075"
"72.19800","6.01662","0.02037"
"72.57600","6.04825","0.02031"
"72.95400","6.07976","0.02042"
"73.33200","6.11109","0.02014"
"73.71000","6.14272","0.02048"
"74.08800","6.17423","0.02067"
"74.46600","6.20568","0.02041"
"74.84400","6.23718","0.02053"
"75.22200","6.26869","0.02008"
"75.60000","6.30020","0.02030"
"75.97800","6.33165","0.02059"
"76.35600","6.36316","0.02071"
"76.73400","6.39473","0.02016"
"77.11200","6.42612","0.02046"
"77.49000","6.45769","0.02105"
"77.86800","6.48926","0.02020"
"78.24600","6.52071","0.02050"
"78.62400","6.55216","0.02033"
"79.00200","6.58372","0.02001"
"79.38000","6.61523","0.02034"
"79.75800","6.64662","0.02005"
"80.13600","6.67819","0.02054"
"80.51400","6.70970","0.02072"
"80.89200","6.74121","0.02073"
"81.27000","6.77266","0.02077"
"81.64800","6.80417","0.02023"
"82.02600","6.83568","0.02061"
"82.40400","6.86719","0.02055"
"82.78200","6.89870","0.02078"
"83.16000","6.93020","0.02059"
"83.53800","6.96165","0.02052"
"83.91600","6.99322","0.02092"
"84.29400","7.02467","0.02084"
"84.67200","7.05612","0.02047"
"85.05000","7.08769","0.02006"
"85.42800","7.11920","0.02023"
"85.80600","7.15071","0.02025"
"86.18400","7.18216","0.02061"
"86.56200","7.21367","0.02050"
"86.94000","7.24524","0.02065"
"87.31800","7.27663","0.02042"
"87.69600","7.30814","0.02038"
"88.07400","7.33976","0.02076"
"88.45200","7.37121","0.02081"
"88.83000","7.40266","0.02015"
"89.20800","7.43423","0.02018"
"89.58600","7.46568","0.02074"
"89.96400","7.49713","0.02051"
"90.34200","7.52870","0.02026"
"90.72000","7.56021","0.02044"
"91.09800","7.59166","0.02026"
"91.47600","7.62317","0.02038"
"91.85400","7.65468","0.02059"
"92.23200","7.68618","0.02105"
"92.61000","7.71763","0.02060"
"92.98800","7.74926","0.02004"
"93.36600","7.78071","0.02034"
"93.74400","7.81210","0.02108"
"94.12200","7.84373","0.02073"
"94.50000","7.87524","0.02063"
"94.87800","7.90669","0.02069"
"95.25600","7.93820","0.02050"
"95.63400","7.96965","0.02030"
"96.01200","8.00115","0.02051"
"96.39000","8.03266","0.02060"
"96.76800","8.06423","0.02065"
"97.14600","8.09574","0.02048"
"97.52400","8.12713","0.02085"
"97.90200","8.15864","0.02093"
"98.28000","8.19021","0.02094"
"98.65800","8.22166","0.02098"
"99.03600","8.25317","0.02094"
"99.41400","8.28474","0.02118"
"99.79200","8.31619","0.02159"
"100.17000","8.34764","0.02117"
"100.54800","8.37926","0.02128"
"100.92600","8.41065","0.02120"
"101.30400","8.44216","0.02158"
"101.68200","8.47373","0.02106"
"102.06000","8.50518","0.02072"
"102.43800","8.53663","0.02162"
"102.81600","8.56820","0.02113"
"103.19400","8.59971","0.02198"
"103.57200","8.63122","0.02157"
"103.95000","8.66267","0.02180"
"104.32800","8.69418","0.02163"
"104.70600","8.72574","0.02231"
"105.08400","8.75713","0.02109"
"105.46200","8.78870","0.02112"
"105.84000","8.82021","0.02148"
"106.21800","8.85172","0.02128"
"106.59600","8.88311","0.02163"
"106.97400","8.91474","0.02157"
"107.35200","8.94625","0.02096"
"107.73000","8.97764","0.02111"
"108.10800","9.00921","0.02136"
"108.48600","9.04072","0.02111"
"108.86400","9.07216","0.02184"
"109.24200","9.10367","0.02120"
"109.62000","9.13524","0.02157"
"109.99800","9.16669","0.02148"
"110.37600","9.19814","0.02137"
"110.75400","9.22971","0.02145"
"111.13200","9.26122","0.02121"
"111.51000","9.29267","0.02097"
"111.88800","9.32418","0.02169"
"112.26600","9.35563","0.02137"
"112.64400","9.38714","0.02162"
"113.02200","9.41864","0.02198"
"113.40000","9.45015","0.02176"
"113.77800","9.48166","0.02217"
"114.15600","9.51317","0.02166"
"114.53400","9.54474","0.02228"
"114.91200","9.57631","0.02213"
"115.29000","9.60764","0.02216"
"115.66800","9.63921","0.02197"
"116.04600","9.67072","0.02195"
"116.42400","9.70211","0.02187"
"116.80200","9.73368","0.02165"
"117.18000","9.76525","0.02166"
"117.55800","9.79663","0.02133"
"117.93600","9.82814","0.02187"
"118.31400","9.85971","0.02261"
"118.69200","9.89116","0.02208"
"119.07000","9.92267","0.02174"
"119.44800","9.95418","0.02221"
"119.82600","9.98569","0.02227"
"120.20400","10.01720","0.02218"
"120.58200","10.04865","0.02188"
"120.96000","10.08022","0.02232"
"121.33800","10.11172","0.02262"
"121.71600","10.14318","0.02259"
"122.09400","10.17468","0.02250"
"122.47200","10.20619","0.02258"
"122.85000","10.23764","0.02213"
"123.22800","10.26915","0.02206"
"123.60600","10.30072","0.02247"
"123.98400","10.33223","0.02196"
"124.36200","10.36368","0.02208"
"124.74000","10.39519","0.02172"
"125.11800","10.42676","0.02210"
"125.49600","10.45815","0.02254"
"125.87400","10.48965","0.02186"
"126.25200","10.52122","0.02242"
"126.63000","10.55261","0.02248"
"127.00800","10.58424","0.02213"
"127.38600","10.61569","0.02242"
"127.76400","10.64714","0.02182"
"128.14200","10.67865","0.02214"
"128.52000","10.71022","0.02267"
"128.89800","10.74167","0.02198"
"129.27600","10.77318","0.02229"
"129.65400","10.80469","0.02203"
"130.03200","10.83619","0.02237"
"130.41000","10.86765","0.02220"
"130.78800","10.89915","0.02248"
"131.16600","10.93072","0.02281"
"131.54400","10.96223","0.02231"
"131.92200","10.99362","0.02232"
"132.30000","11.02519","0.02253"
"132.67800","11.05676","0.02265"
"133.05600","11.08809","0.02241"
"133.43400","11.11972","0.02252"
"133.81200","11.15123","0.02301"
"134.19000","11.18268","0.02222"
"134.56800","11.21418","0.02286"
"134.94600","11.24575","0.02246"
"135.32400","11.27720","0.02297"
"135.70200","11.30865","0.02212"
"136.08000","11.34022","0.02269"
"136.45800","11.37167","0.02269"
"136.83600","11.40318","0.02272"
"137.21400","11.43469","0.02314"
"137.59200","11.46620","0.02299"
"137.97000","11.49765","0.02245"
"138.34800","11.52915","0.02272"
"138.72600","11.56067","0.02296"
"139.10400","11.59217","0.02270"
"139.48200","11.62362","0.02283"
"139.86000","11.65525","0.02288"
"140.23800","11.68670","0.02242"
"140.61600","11.71815","0.02251"
"140.99400","11.74966","0.02293"
"141.37200","11.78123","0.02331"
"141.75000","11.81268","0.02264"
"142.12800","11.84413","0.02345"
"142.50600","11.87576","0.02274"
"142.88400","11.90721","0.02274"
"143.26200","11.93859","0.02308"
"143.64000","11.97022","0.02264"
"144.01800","12.00167","0.02313"
"144.39600","12.03312","0.02279"
"144.77400","12.06469","0.02290"
"145.15200","12.09614","0.02303"
"145.53000","12.12771","0.02280"
"145.90800","12.15916","0.02299"
"146.28600","12.19067","0.02283"
"146.66400","12.22224","0.02294"
"147.04200","12.25369","0.02345"
"147.42000","12.28513","0.02308"
"147.79800","12.31670","0.02354"
"148.17600","12.34815","0.02365"
"148.55400","12.37966","0.02382"
"148.93200","12.41123","0.02346"
"149.31000","12.44274","0.02338"
"149.68800","12.47413","0.02383"
"150.06600","12.50570","0.02378"
"150.44400","12.53721","0.02345"
"150.82200","12.56860","0.02358"
"151.20000","12.60023","0.02332"
"151.57800","12.63173","0.02325"
"151.95600","12.66318","0.02360"
"152.33400","12.69469","0.02307"
"152.71200","12.72620","0.02355"
"153.09000","12.75771","0.02321"
"153.46800","12.78910","0.02317"
"153.84600","12.82067","0.02319"
"154.22400","12.85224","0.02319"
"154.60200","12.88363","0.02284"
"154.98000","12.91520","0.02317"
"155.35800","12.94671","0.02310"
"155.73600","12.97816","0.02314"
"156.11400","13.00966","0.02312"
"156.49200","13.04123","0.02368"
"156.87000","13.07268","0.02310"
"157.24800","13.10419","0.02339"
"157.62600","13.13570","0.02298"
"158.00400","13.16721","0.02316"
"158.38200","13.19866","0.02365"
"158.76000","13.23017","0.02373"
"159.13800","13.26168","0.02328"
"159.51600","13.29319","0.02341"
"159.89400","13.32469","0.02320"
"160.27200","13.35620","0.02289"
"160.65000","13.38771","0.02354"
"161.02800","13.41910","0.02343"
"161.40600","13.45073","0.02358"
"161.78400","13.48218","0.02358"
"162.16200","13.51363","0.02311"
"162.54000","13.54514","0.02223"
"162.91800","13.57671","0.02290"
"163.29600","13.60816","0.02295"
"163.67400","13.63967","0.02301"
"164.05200","13.67118","0.02257"
"164.43000","13.70274","0.02368"
"164.80800","13.73413","0.02270"
"165.18600","13.76564","0.02285"
"165.56400","13.79721","0.02288"
"165.94200","13.82872","0.02254"
"166.32000","13.86017","0.02308"
"166.69800","13.89174","0.02322"
"167.07600","13.92325","0.02250"
"167.45400","13.95464","0.02274"
"167.83200","13.98621","0.02237"
"168.21000","14.01772","0.02208"
"168.58800","14.04916","0.02134"
"168.96600","14.08068","0.02143"
"169.34400","14.11218","0.02145"
"169.72200","14.14369","0.02125"
"170.10000","14.17514","0.02202"
"170.47800","14.20671","0.02152"
"170.85600","14.23816","0.02130"
"171.23400","14.26961","0.02205"
"171.61200","14.30118","0.02170"
"171.99000","14.33275","0.02226"
"172.36800","14.36414","0.02180"
"172.74600","14.39571","0.02183"
"173.12400","14.42721","0.02212"
"173.50200","14.45866","0.02178"
"173.88000","14.49017","0.02191"
"174.25800","14.52168","0.02206"
"174.63600","14.55319","0.02212"
"175.01400","14.58464","0.02211"
"175.39200","14.61615","0.02156"
"175.77000","14.64772","0.02215"
"176.14800","14.67917","0.02147"
"176.52600","14.71062","0.02138"
"176.90400","14.74224","0.02199"
"177.28200","14.77363","0.02153"
"177.66000","14.80509","0.02181"
"178.03800","14.83677","0.02200"
"178.41600","14.86822","0.02223"
"178.79400","14.89967","0.02175"
"179.17200","14.93124","0.02212"
"179.55000","14.96269","0.02234"
"179.92800","14.99420","0.02182"
"180.30600","15.02571","0.02254"
"180.68400","15.05716","0.02171"
"181.06200","15.08873","0.02279"
"181.44000","15.12018","0.02205"
"181.81800","15.15163","0.02220"
"182.19600","15.18319","0.02190"
"182.57400","15.21464","0.02191"
"182.95200","15.24621","0.02223"
"183.33000","15.27772","0.02194"
"183.70800","15.30917","0.02208"
"184.08600","15.34062","0.02234"
"184.46400","15.37225","0.02271"
"184.84200","15.40370","0.02218"
"185.22000","15.43515","0.02190"
"185.59800","15.46666","0.02160"
"185.97600","15.49822","0.02258"
"186.35400","15.52967","0.02225"
"186.73200","15.56112","0.02217"
"187.11000","15.59269","0.02240"
"187.48800","15.62420","0.02187"
"187.86600","15.65571","0.02183"
"188.24400","15.68722","0.02179"
"188.62200","15.71873","0.02244"
"189.00000","15.75012","0.02241"
"189.37800","15.78169","0.02213"
"189.75600","15.81319","0.02210"
"190.13400","15.84464","0.02213"
"190.51200","15.87615","0.02246"
"190.89000","15.90766","0.02210"
"191.26800","15.93917","0.02264"
"191.64600","15.97062","0.02255"
"192.02400","16.00225","0.02215"
"192.40200","16.03376","0.02217"
"192.78000","16.06509","0.02233"
"193.15800","16.09672","0.02206"
"193.53600","16.12823","0.02274"
"193.91400","16.15968","0.02259"
"194.29200","16.19118","0.02261"
"194.67000","16.22275","0.02225"
"195.04800","16.25414","0.02247"
"195.42600","16.28565","0.02237"
"195.80400","16.31722","0.02209"
"196.18200","16.34867","0.02211"
"196.56000","16.38018","0.02210"
"196.93800","16.41169","0.02195"
"197.31600","16.44320","0.02219"
"197.69400","16.47465","0.02180"
"198.07200","16.50616","0.02200"
"198.45000","16.53772","0.02188"
"198.82800","16.56918","0.02168"
"199.20600","16.60062","0.02188"
"199.58400","16.63219","0.02174"
"199.96200","16.66364","0.02127"
"200.34000","16.69515","0.02163"
"200.71800","16.72672","0.02143"
"201.09600","16.75817","0.02225"
"201.47400","16.78968","0.02169"
"201.85200","16.82119","0.02179"
"202.23000","16.85270","0.02193"
"202.60800","16.88427","0.02203"
"202.98600","16.91566","0.02128"
"203.36400","16.94716","0.02186"
"203.74200","16.97873","0.02208"
"204.12000","17.01018","0.02202"
"204.49800","17.04163","0.02204"
"204.87600","17.07320","0.02155"
"205.25400","17.10465","0.02178"
"205.63200","17.13616","0.02206"
"206.01000","17.16773","0.02235"
"206.38800","17.19918","0.02254"
"206.76600","17.23069","0.02190"
"207.14400","17.26219","0.02211"
"207.52200","17.29370","0.02269"
"207.90000","17.32515","0.02250"
"208.27800","17.35666","0.02203"
"208.65600","17.38823","0.02210"
"209.03400","17.41974","0.02219"
"209.41200","17.45113","0.02202"
"209.79000","17.48270","0.02251"
"210.16800","17.51421","0.02257"
"210.54600","17.54566","0.02299"
"210.92400","17.57722","0.02248"
"211.30200","17.60874","0.02262"
"211.68000","17.64013","0.02280"
"212.05800","17.67163","0.02299"
"212.43600","17.70320","0.02297"
"212.81400","17.73471","0.02243"
"213.19200","17.76616","0.02321"
"213.57000","17.79767","0.02249"
"213.94800","17.82918","0.02196"
"214.32600","17.86063","0.02212"
"214.70400","17.89220","0.02204"
"215.08200","17.92371","0.02224"
"215.46000","17.95516","0.02253"
"215.83800","17.98666","0.02231"
"216.21600","18.01817","0.02225"
"216.59400","18.04968","0.02262"
"216.97200","18.08113","0.02306"
"217.35000","18.11270","0.02264"
"217.72800","18.14415","0.02283"
"218.10600","18.17566","0.02323"
"218.48400","18.20717","0.02309"
"218.86200","18.23868","0.02317"
"219.24000","18.27019","0.02363"
"219.61800","18.30164","0.02346"
"219.99600","18.33320","0.02335"
"220.37400","18.36465","0.02278"
"220.75200","18.39610","0.02230"
"221.13000","18.42767","0.02289"
"221.50800","18.45924","0.02316"
"221.88600","18.49063","0.02286"
"222.26400","18.52214","0.02293"
"222.64200","18.55371","0.02281"
"223.02000","18.58516","0.02235"
"223.39800","18.61667","0.02261"
"223.77600","18.64818","0.02229"
"224.15400","18.67974","0.02230"
"224.53200","18.71119","0.02222"
"224.91000","18.74264","0.02322"
"225.28800","18.77421","0.02240"
"225.66600","18.80566","0.02284"
"226.04400","18.83711","0.02307"
"226.42200","18.86868","0.02261"
"226.80000","18.90019","0.02321"
"227.17800","18.93164","0.02334"
"227.55600","18.96321","0.02320"
"227.93400","18.99472","0.02310"
"228.31200","19.02611","0.02362"
"228.69000","19.05773","0.02335"
"229.06800","19.08918","0.02328"
"229.44600","19.12063","0.02326"
"229.82400","19.15214","0.02353"
"230.20200","19.18371","0.02284"
"230.58000","19.21522","0.02385"
"230.95800","19.24667","0.02336"
"231.33600","19.27824","0.02342"
"231.71400","19.30969","0.02354"
"232.09200","19.34114","0.02270"
"232.47000","19.37271","0.02260"
"232.84800","19.40421","0.02297"
"233.22600","19.43560","0.02325"
"233.60400","19.46711","0.02312"
"233.98200","19.49874","0.02330"
"234.36000","19.53019","0.02278"
"234.73800","19.56164","0.02315"
"235.11600","19.59321","0.02274"
"235.49400","19.62472","0.02247"
"235.87200","19.65617","0.02351"
"236.25000","19.68768","0.02341"
"236.62800","19.71918","0.02303"
"237.00600","19.75070","0.02291"
"237.38400","19.78220","0.02312"
"237.76200","19.81371","0.02289"
"238.14000","19.84522","0.02302"
"238.51800","19.87661","0.02315"
"238.89600","19.90824","0.02315"
"239.27400","19.93969","0.02321"
"239.65200","19.97114","0.02301"
"240.03000","20.00271","0.02320"
"240.40800","20.03416","0.02325"
"240.78600","20.06567","0.02325"
"241.16400","20.09718","0.02339"
"241.54200","20.12868","0.02344"
"241.92000","20.16025","0.02360"
"242.29800","20.19164","0.02304"
"242.67600","20.22315","0.02349"
"243.05400","20.25472","0.02343"
"243.43200","20.28617","0.02326"
"243.81000","20.31762","0.02324"
"244.18800","20.34919","0.02376"
"244.56600","20.38070","0.02367"
"244.94400","20.41215","0.02369"
"245.32200","20.44372","0.02372"
"245.70000","20.47522","0.02414"
"246.07800","20.50667","0.02399"
"246.45600","20.53818","0.02413"
"246.83400","20.56969","0.02403"
"247.21200","20.60114","0.02368"
"247.59000","20.63265","0.02419"
"247.96800","20.66422","0.02408"
"248.34600","20.69567","0.02409"
"248.72400","20.72712","0.02398"
"249.10200","20.75869","0.02375"
"249.48000","20.79026","0.02378"
"249.85800","20.82165","0.02362"
"250.23600","20.85321","0.02366"
"250.61400","20.88466","0.02469"
"250.99200","20.91617","0.02362"
"251.37000","20.94768","0.02387"
"251.74800","20.97925","0.02387"
"252.12600","21.01070","0.02395"
"252.50400","21.04209","0.02382"
"252.88200","21.07366","0.02387"
"253.26000","21.10523","0.02389"
"253.63800","21.13667","0.02361"
"254.01600","21.16813","0.02381"
"254.39400","21.19975","0.02374"
"254.77200","21.23114","0.02384"
"255.15000","21.26265","0.02340"
"255.52800","21.29422","0.02428"
"255.90600","21.32573","0.02393"
"256.28400","21.35718","0.02433"
"256.66200","21.38869","0.02430"
"257.04000","21.42014","0.02357"
"257.41800","21.45165","0.02418"
"257.79600","21.48315","0.02468"
"258.17400","21.51467","0.02433"
"258.55200","21.54618","0.02373"
"258.93000","21.57763","0.02394"
"259.30800","21.60913","0.02432"
"259.68600","21.64070","0.02422"
"260.06400","21.67215","0.02476"
"260.44200","21.70366","0.02380"
"260.82000","21.73523","0.02427"
"261.19800","21.76668","0.02369"
"261.57600","21.79813","0.02421"
"261.95400","21.82970","0.02364"
"262.33200","21.86121","0.02433"
"262.71000","21.89266","0.02420"
"263.08800","21.92416","0.02420"
"263.46600","21.95573","0.02374"
"263.84400","21.98718","0.02401"
"264.22200","22.01869","0.02425"
"264.60000","22.05020","0.02464"
"264.97800","22.08165","0.02428"
"265.35600","22.11316","0.02389"
"265.73400","22.14473","0.02472"
"266.11200","22.17624","0.02412"
"266.49000","22.20763","0.02386"
"266.86800","22.23919","0.02384"
"267.24600","22.27071","0.02452"
"267.62400","22.30221","0.02388"
"268.00200","22.33366","0.02416"
"268.38000","22.36517","0.02452"
"268.75800","22.39668","0.02374"
"269.13600","22.42819","0.02417"
"269.51400","22.45970","0.02426"
"269.89200","22.49127","0.02330"
"270.27000","22.52260","0.02403"
"270.64800","22.55417","0.02367"
"271.02600","22.58574","0.02414"
"271.40400","22.61712","0.02434"
"271.78200","22.64863","0.02421"
"272.16000","22.68020","0.02416"
"272.53800","22.71165","0.02414"
"272.91600","22.74310","0.02474"
"273.29400","22.77473","0.02435"
"273.67200","22.80618","0.02466"
"274.05000","22.83769","0.02415"
"274.42800","22.86920","0.02488"
"274.80600","22.90071","0.02451"
"275.18400","22.93222","0.02482"
"275.56200","22.96372","0.02447"
"275.94000","22.99523","0.02470"
"276.31800","23.02668","0.02504"
"276.69600","23.05813","0.02470"
"277.07400","23.08970","0.02414"
"277.45200","23.12121","0.02451"
"277.83000","23.15266","0.02509"
"278.20800","23.18423","0.02508"
"278.58600","23.21568","0.02449"
"278.96400","23.24719","0.02534"
"279.34200","23.27870","0.02452"
"279.72000","23.31021","0.02533"
"280.09800","23.34171","0.02569"
"280.47600","23.37316","0.02526"
"280.85400","23.40467","0.02507"
"281.23200","23.43618","0.02461"
"281.61000","23.46769","0.02541"
"281.98800","23.49914","0.02512"
"282.36600","23.53077","0.02567"
"282.74400","23.56216","0.02535"
"283.12200","23.59361","0.02577"
"283.50000","23.62523","0.02603"
"283.87800","23.65668","0.02594"
"284.25600","23.68813","0.02570"
"284.63400","23.71964","0.02572"
"285.01200","23.75121","0.02531"
"285.39000","23.78272","0.02609"
"285.76800","23.81411","0.02579"
"286.14600","23.84568","0.02578"
"286.52400","23.87725","0.02558"
"286.90200","23.90858","0.02603"
"287.28000","23.94015","0.02600"
"287.65800","23.97178","0.02619"
"288.03600","24.00311","0.02648"
"288.41400","24.03468","0.02653"
"288.79200","24.06624","0.02698"
"289.17000","24.09764","0.02652"
"289.54800","24.12920","0.02668"
"289.92600","24.16071","0.02679"
"290.30400","24.19222","0.02604"
"290.68200","24.22367","0.02697"
"291.06000","24.25518","0.02701"
"291.43800","24.28669","0.02743"
"291.81600","24.31814","0.02701"
"292.19400","24.34971","0.02707"
"292.57200","24.38116","0.02722"
"292.95000","24.41267","0.02733"
"293.32800","24.44417","0.02755"
"293.70600","24.47568","0.02709"
"294.08400","24.50719","0.02743"
"294.46200","24.53864","0.02743"
"294.84000","24.57021","0.02735"
"295.21800","24.60172","0.02750"
"295.59600","24.63317","0.02784"
"295.97400","24.66468","0.02787"
"296.35200","24.69625","0.02686"
"296.73000","24.72770","0.02774"
"297.10800","24.75915","0.02757"
"297.48600","24.79071","0.02711"
"297.86400","24.82222","0.02713"
"298.24200","24.85361","0.02763"
"298.62000","24.88518","0.02805"
"298.99800","24.91675","0.02808"
"299.37600","24.94814","0.02809"
"299.75400","24.97971","0.02827"
"300.13200","25.01116","0.02834"
"300.51000","25.04273","0.02838"
"300.88800","25.07417","0.02856"
"301.26600","25.10568","0.02811"
"301.64400","25.13720","0.02850"
"302.02200","25.16864","0.02887"
"302.40000","25.20015","0.02876"
"302.77800","25.23172","0.02925"
"303.15600","25.26323","0.02951"
"303.53400","25.29462","0.02711"
"303.91200","25.32625","0.02705"
"304.29000","25.35770","0.02711"
"304.66800","25.38909","0.02662"
"305.04600","25.42071","0.02762"
"305.42400","25.45223","0.02686"
"305.80200","25.48368","0.02771"
"306.18000","25.51518","0.02743"
"306.55800","25.54669","0.02825"
"306.93600","25.57820","0.02824"
"307.31400","25.60971","0.02759"
"307.69200","25.64122","0.02848"
"308.07000","25.67267","0.02591"
"308.44800","25.70412","0.02509"
"308.82600","25.73569","0.02534"
"309.20400","25.76720","0.02532"
"309.58200","25.79859","0.02528"
"309.96000","25.83015","0.02519"
"310.33800","25.86172","0.02563"
"310.71600","25.89317","0.02453"
"311.09400","25.92462","0.02415"
"311.47200","25.95619","0.02508"
"311.85000","25.98770","0.02413"
"312.22800","26.01915","0.02459"
"312.60600","26.05072","0.02471"
"312.98400","26.08223","0.02467"
"313.36200","26.11368","0.02470"
"313.74000","26.14519","0.02251"
"314.11800","26.17676","0.02303"
"314.49600","26.20820","0.02292"
"314.87400","26.23965","0.02293"
"315.25200","26.27122","0.02294"
"315.63000","26.30267","0.02281"
"316.00800","26.33412","0.02299"
"316.38600","26.36569","0.02321"
"316.76400","26.39720","0.02338"
"317.14200","26.42871","0.02343"
"317.52000","26.46016","0.02356"
"317.89800","26.49167","0.02397"
"318.27600","26.52324","0.02401"
"318.65400","26.55469","0.02443"
"319.03200","26.58619","0.02389"
"319.41000","26.61770","0.02341"
"319.78800","26.64915","0.02429"
"320.16600","26.68066","0.02429"
"320.54400","26.71217","0.02422"
"320.92200","26.74368","0.02448"
"321.30000","26.77519","0.02407"
"321.67800","26.80670","0.02412"
"322.05600","26.83821","0.02421"
"322.43400","26.86960","0.02420"
"322.81200","26.90122","0.02400"
"323.19000","26.93273","0.02440"
"323.56800","26.96418","0.02495"
"323.94600","26.99563","0.02502"
"324.32400","27.02720","0.02482"
"324.70200","27.05865","0.02455"
"325.08000","27.09016","0.02493"
"325.45800","27.12173","0.02444"
"325.83600","27.15324","0.02470"
"326.21400","27.18463","0.02483"
"326.59200","27.21620","0.02460"
"326.97000","27.24776","0.02478"
"327.34800","27.27916","0.02492"
"327.72600","27.31066","0.02548"
"328.10400","27.34217","0.02505"
"328.48200","27.37368","0.02504"
"328.86000","27.40519","0.02498"
"329.23800","27.43664","0.02571"
"329.61600","27.46821","0.02595"
"329.99400","27.49966","0.02590"
"330.37200","27.53117","0.02560"
"330.75000","27.56268","0.02597"
"331.12800","27.59418","0.02563"
"331.50600","27.62564","0.02562"
"331.88400","27.65721","0.02552"
"332.26200","27.68865","0.02526"
"332.64000","27.72016","0.02576"
"333.01800","27.75179","0.02565"
"333.39600","27.78318","0.02608"
"333.77400","27.81463","0.02623"
"334.15200","27.84620","0.02570"
"334.53000","27.87765","0.02607"
"334.90800","27.90916","0.02597"
"335.28600","27.94066","0.02640"
"335.66400","27.97218","0.02645"
"336.04200","28.00368","0.02637"
"336.42000","28.03519","0.02627"
"336.79800","28.06664","0.02613"
"337.17600","28.09827","0.02609"
"337.55400","28.12966","0.02667"
"337.93200","28.16117","0.02688"
"338.31000","28.19274","0.02685"
"338.68800","28.22419","0.02677"
"339.06600","28.25558","0.02736"
"339.44400","28.28721","0.02747"
"339.82200","28.31872","0.02683"
"340.20000","28.35010","0.02711"
"340.57800","28.38167","0.02670"
"340.95600","28.41318","0.02699"
"341.33400","28.44469","0.02683"
"341.71200","28.47620","0.02672"
"342.09000","28.50771","0.02726"
"342.46800","28.53916","0.02715"
"342.84600","28.57067","0.02625"
"343.22400","28.60224","0.02635"
"343.60200","28.63369","0.02631"
"343.98000","28.66520","0.02594"
"344.35800","28.69670","0.02562"
"344.73600","28.72821","0.02657"
"345.11400","28.75966","0.02652"
"345.49200","28.79117","0.02593"
"345.87000","28.82268","0.02646"
"346.24800","28.85419","0.02637"
"346.62600","28.88564","0.02683"
"347.00400","28.91721","0.02646"
"347.38200","28.94878","0.02664"
"347.76000","28.98011","0.02743"
"348.13800","29.01168","0.02616"
"348.51600","29.04325","0.02707"
"348.89400","29.07463","0.02708"
"349.27200","29.10614","0.02734"
"349.65000","29.13771","0.02670"
"350.02800","29.16916","0.02676"
"350.40600","29.20067","0.02714"
"350.78400","29.23218","0.02750"
"351.16200","29.26369","0.02720"
"351.54000","29.29514","0.02680"
"351.91800","29.32665","0.02719"
"352.29600","29.35816","0.02721"
"352.67400","29.38966","0.02673"
"353.05200","29.42117","0.02773"
"353.43000","29.45274","0.02747"
"353.80800","29.48425","0.02789"
"354.18600","29.51564","0.02827"
"354.56400","29.54721","0.02793"
"354.94200","29.57872","0.02774"
"355.32000","29.61011","0.02794"
"355.69800","29.64174","0.02820"
"356.07600","29.67319","0.02799"
"356.45400","29.70470","0.02759"
"356.83200","29.73621","0.02811"
"357.21000","29.76771","0.02772"
"357.58800","29.79922","0.02824"
"357.96600","29.83067","0.02812"
"358.34400","29.86218","0.02814"
"358.72200","29.89369","0.02869"
"359.10000","29.92514","0.02857"
"359.47800","29.95665","0.02876"
"359.85600","29.98822","0.02844"
"360.23400","30.01967","0.02850"
"360.61200","30.05112","0.02876"
"360.99000","30.08269","0.02869"
"361.36800","30.11419","0.02890"
"361.74600","30.14570","0.02914"
"362.12400","30.17721","0.02912"
"362.50200","30.20866","0.02968"
"362.88000","30.24023","0.02887"
"363.25800","30.27162","0.02906"
"363.63600","30.30319","0.02919"
"364.01400","30.33476","0.02797"
"364.39200","30.36615","0.02937"
"364.77000","30.39772","0.02904"
"365.14800","30.42923","0.02929"
"365.52600","30.46062","0.02943"
"365.90400","30.49218","0.02900"
"366.28200","30.52369","0.02975"
"366.66000","30.55514","0.02925"
"367.03800","30.58665","0.02853"
"367.41600","30.61822","0.02933"
"367.79400","30.64967","0.02992"
"368.17200","30.68112","0.02998"
"368.55000","30.71275","0.02921"
"368.92800","30.74420","0.02987"
"369.30600","30.77565","0.02949"
"369.68400","30.80722","0.02949"
"370.06200","30.83873","0.03002"
"370.44000","30.87017","0.02988"
"370.81800","30.90162","0.02776"
"371.19600","30.93319","0.02784"
"371.57400","30.96470","0.02881"
"371.95200","30.99615","0.02840"
"372.33000","31.02772","0.02918"
"372.70800","31.05917","0.02946"
"373.08600","31.09068","0.02923"
"373.46400","31.12213","0.02935"
"373.84200","31.15370","0.02968"
"374.22000","31.18521","0.02961"
"374.59800","31.21666","0.02971"
"374.97600","31.24816","0.03027"
"375.35400","31.27973","0.03065"
"375.73200","31.31112","0.03041"
"376.11000","31.34269","0.03046"
"376.48800","31.37420","0.03083"
"376.86600","31.40565","0.03015"
"377.24400","31.43715","0.03072"
"377.62200","31.46873","0.03012"
"378.00000","31.50018","0.03041"
"378.37800","31.53168","0.03033"
"378.75600","31.56319","0.03074"
"379.13400","31.59470","0.03041"
"379.51200","31.62621","0.03082"
"379.89000","31.65766","0.03035"
"380.26800","31.68923","0.03057"
"380.64600","31.72068","0.03030"
"381.02400","31.75213","0.03099"
"381.40200","31.78370","0.03078"
"381.78000","31.81520","0.03120"
"382.15800","31.84659","0.03100"
"382.53600","31.87823","0.03088"
"382.91400","31.90973","0.03138"
"383.29200","31.94112","0.03174"
"383.67000","31.97269","0.03211"
"384.04800","32.00420","0.03179"
"384.42600","32.03565","0.03194"
"384.80400","32.06716","0.03246"
"385.18200","32.09873","0.03143"
"385.56000","32.13024","0.03185"
"385.93800","32.16163","0.03232"
"386.31600","32.19320","0.03202"
"386.69400","32.22476","0.03252"
"387.07200","32.25615","0.03174"
"387.45000","32.28772","0.03073"
"387.82800","32.31923","0.03130"
"388.20600","32.35062","0.03123"
"388.58400","32.38213","0.03000"
"388.96200","32.41370","0.03048"
"389.34000","32.44521","0.03100"
"389.71800","32.47666","0.03105"
"390.09600","32.50823","0.03156"
"390.47400","32.53968","0.03192"
"390.85200","32.57119","0.03091"
"391.23000","32.60263","0.03105"
"391.60800","32.63426","0.03100"
"391.98600","32.66571","0.03134"
"392.36400","32.69716","0.03175"
"392.74200","32.72867","0.03197"
"393.12000","32.76018","0.03222"
"393.49800","32.79163","0.03148"
"393.87600","32.82320","0.03201"
"394.25400","32.85471","0.03178"
"394.63200","32.88615","0.03289"
"395.01000","32.91766","0.03275"
"395.38800","32.94918","0.03312"
"395.76600","32.98063","0.03282"
"396.14400","33.01219","0.03258"
"396.52200","33.04370","0.03305"
"396.90000","33.07521","0.03323"
"397.27800","33.10666","0.03331"
"397.65600","33.13811","0.03343"
"398.03400","33.16968","0.03327"
"398.41200","33.20119","0.03337"
"398.79000","33.23270","0.03439"
"399.16800","33.26421","0.03423"
"399.54600","33.29571","0.03403"
"399.92400","33.32710","0.03423"
"400.30200","33.35873","0.03405"
"400.68000","33.39024","0.03473"
"401.05800","33.42163","0.03449"
"401.43600","33.45314","0.03479"
"401.81400","33.48471","0.03521"
"402.19200","33.51616","0.03523"
"402.57000","33.54761","0.03550"
"402.94800","33.57924","0.03592"
"403.32600","33.61074","0.03540"
"403.70400","33.64207","0.03567"
"404.08200","33.67370","0.03583"
"404.46000","33.70521","0.03595"
"404.83800","33.73672","0.03619"
"405.21600","33.76817","0.03604"
"405.59400","33.79968","0.03603"
"405.97200","33.83125","0.03668"
"406.35000","33.86270","0.03637"
"406.72800","33.89421","0.03649"
"407.10600","33.92572","0.03634"
"407.48400","33.95716","0.03704"
"407.86200","33.98861","0.03679"
"408.24000","34.02024","0.03704"
"408.61800","34.05164","0.03711"
"408.99600","34.08320","0.03695"
"409.37400","34.11477","0.03757"
"409.75200","34.14616","0.03732"
"410.13000","34.17767","0.03719"
"410.50800","34.20924","0.03746"
"410.88600","34.24069","0.03743"
"411.26400","34.27214","0.03751"
"411.64200","34.30371","0.03732"
"412.02000","34.33516","0.03739"
"412.39800","34.36666","0.03733"
"412.77600","34.39823","0.03764"
"413.15400","34.42968","0.03770"
"413.53200","34.46119","0.03771"
"413.91000","34.49264","0.03788"
"414.28800","34.52415","0.03791"
"414.66600","34.55572","0.03795"
"415.04400","34.58711","0.03826"
"415.42200","34.61868","0.03841"
"415.80000","34.65025","0.03875"
"416.17800","34.68170","0.03874"
"416.55600","34.71315","0.03896"
"416.93400","34.74471","0.03896"
"417.31200","34.77622","0.03902"
"417.69000","34.80761","0.03880"
"418.06800","34.83918","0.03933"
"418.44600","34.87069","0.03897"
"418.82400","34.90220","0.03946"
"419.20200","34.93365","0.03935"
"419.58000","34.96522","0.03960"
"419.95800","34.99667","0.03923"
"420.33600","35.02811","0.03984"
"420.71400","35.05975","0.03997"
"421.09200","35.09126","0.03997"
"421.47000","35.12264","0.04011"
"421.84800","35.15415","0.03996"
"422.22600","35.18572","0.04008"
"422.60400","35.21717","0.04024"
"422.98200","35.24868","0.04055"
"423.36000","35.28019","0.04042"
"423.73800","35.31170","0.04029"
"424.11600","35.34315","0.04065"
"424.49400","35.37466","0.04079"
"424.87200","35.40622","0.04077"
"425.25000","35.43761","0.04097"
"425.62800","35.46918","0.04111"
"426.00600","35.50076","0.04130"
"426.38400","35.53214","0.04009"
"426.76200","35.56365","0.03934"
"427.14000","35.59522","0.03979"
"427.51800","35.62667","0.03995"
"427.89600","35.65812","0.04009"
"428.27400","35.68975","0.04012"
"428.65200","35.72120","0.04057"
"429.03000","35.75265","0.04021"
"429.40800","35.78416","0.04055"
"429.78600","35.81572","0.04079"
"430.16400","35.84723","0.04088"
"430.54200","35.87868","0.04085"
"430.92000","35.91019","0.04088"
"431.29800","35.94170","0.04146"
"431.67600","35.97315","0.04150"
"432.05400","36.00466","0.04149"
"432.43200","36.03623","0.04173"
"432.81000","36.06768","0.04177"
"433.18800","36.09919","0.04199"
"433.56600","36.13070","0.04207"
"433.94400","36.16220","0.04249"
"434.32200","36.19365","0.04276"
"434.70000","36.22522","0.04272"
"435.07800","36.25673","0.04285"
"435.45600","36.28818","0.04274"
"435.83400","36.31963","0.04334"
"436.21200","36.35120","0.04386"
"436.59000","36.38265","0.04380"
"436.96800","36.41416","0.04367"
"437.34600","36.44572","0.04408"
"437.72400","36.47717","0.04419"
"438.10200","36.50863","0.04471"
"438.48000","36.54020","0.04495"
"438.85800","36.57170","0.04547"
"439.23600","36.60315","0.04603"
"439.61400","36.63472","0.04621"
"439.99200","36.66617","0.04657"
"440.37000","36.69768","0.04706"
"440.74800","36.72913","0.04801"
"441.12600","36.76070","0.04796"
"441.50400","36.79227","0.04908"
"441.88200","36.82366","0.04962"
"442.26000","36.85516","0.04916"
"442.63800","36.88673","0.05051"
"443.01600","36.91806","0.05110"
"443.39400","36.94970","0.05137"
"443.77200","36.98120","0.05233"
"444.15000","37.01265","0.05275"
"444.52800","37.04416","0.05331"
"444.90600","37.07573","0.05408"
"445.28400","37.10718","0.05468"
"445.66200","37.13863","0.05608"
"446.04000","37.17020","0.05681"
"446.41800","37.20171","0.05832"
"446.79600","37.23315","0.05770"
"447.17400","37.26466","0.05882"
"447.55200","37.29623","0.05881"
"447.93000","37.32774","0.05985"
"448.30800","37.35913","0.06083"
"448.68600","37.39070","0.06157"
"449.06400","37.42221","0.06192"
"449.44200","37.45372","0.06200"
"449.82000","37.48523","0.06286"
"450.19800","37.51667","0.06222"
"450.57600","37.54813","0.03528"
"450.95400","37.57969","0.02595"
"451.33200","37.61121","0.03379"
"451.71000","37.64272","0.02676"
"452.08800","37.67416","0.03320"
"452.46600","37.70567","0.02743"
"452.84400","37.73724","0.03186"
"453.22200","37.76863","0.02855"
"453.60000","37.80020","0.03244"
"453.97800","37.83171","0.03013"
"454.35600","37.86316","0.03192"
"454.73400","37.89466","0.03163"
"455.11200","37.92617","0.03110"
"455.49000","37.95768","0.03257"
"455.86800","37.98919","0.03156"
"456.24600","38.02070","0.03312"
"456.62400","38.05221","0.03272"
"457.00200","38.08366","0.03411"
"457.38000","38.11517","0.03300"
"457.75800","38.14668","0.03323"
"458.13600","38.17819","0.03367"
"458.51400","38.20964","0.03416"
"458.89200","38.24121","0.03369"
"459.27000","38.27272","0.03407"
"459.64800","38.30410","0.03402"
"460.02600","38.33573","0.03526"
"460.40400","38.36724","0.03452"
"460.78200","38.39863","0.03458"
"461.16000","38.43020","0.03536"
"461.53800","38.46171","0.03544"
"461.91600","38.49316","0.03490"
"462.29400","38.52467","0.03518"
"462.67200","38.55624","0.03538"
"463.05000","38.58768","0.03579"
"463.42800","38.61913","0.03541"
"463.80600","38.65065","0.03538"
"464.18400","38.68222","0.03579"
"464.56200","38.71360","0.03613"
"464.94000","38.74517","0.03631"
"465.31800","38.77668","0.03660"
"465.69600","38.80813","0.03657"
"466.07400","38.83970","0.03603"
"466.45200","38.87121","0.03646"
"466.83000","38.90272","0.03658"
"467.20800","38.93417","0.03694"
"467.58600","38.96568","0.03620"
"467.96400","38.99718","0.03482"
"468.34200","39.02869","0.03476"
"468.72000","39.06014","0.03585"
"469.09800","39.09171","0.03572"
"469.47600","39.12322","0.03578"
"469.85400","39.15461","0.03608"
"470.23200","39.18618","0.03641"
"470.61000","39.21769","0.03601"
"470.98800","39.24908","0.02784"
"471.36600","39.28071","0.02860"
"471.74400","39.31221","0.02393"
"472.12200","39.34367","0.02801"
"472.50000","39.37517","0.02548"
"472.87800","39.40668","0.02732"
"473.25600","39.43819","0.02581"
"473.63400","39.46970","0.02688"
"474.01200","39.50115","0.02797"
"474.39000","39.53272","0.02834"
"474.76800","39.56417","0.02866"
"475.14600","39.59568","0.02867"
"475.52400","39.62725","0.02954"
"475.90200","39.65870","0.02993"
"476.28000","39.69009","0.02977"
"476.65800","39.72171","0.03096"
"477.03600","39.75322","0.03076"
"477.41400","39.78461","0.03032"
"477.79200","39.81624","0.03017"
"478.17000","39.84769","0.03001"
"478.54800","39.87920","0.03082"
"478.92600","39.91064","0.03081"
"479.30400","39.94216","0.03181"
"479.68200","39.97373","0.03132"
"480.06000","40.00518","0.03078"
"480.43800","40.03674","0.03143"
"480.81600","40.06820","0.03129"
"481.19400","40.09958","0.03151"
"481.57200","40.13121","0.03174"
"481.95000","40.16272","0.03145"
"482.32800","40.19417","0.03208"
"482.70600","40.22568","0.03176"
"483.08400","40.25719","0.03169"
"483.46200","40.28864","0.03214"
"483.84000","40.32014","0.03209"
"484.21800","40.35172","0.03250"
"484.59600","40.38323","0.03280"
"484.97400","40.41467","0.03327"
"485.35200","40.44613","0.03253"
"485.73000","40.47769","0.03259"
"486.10800","40.50914","0.03292"
"486.48600","40.54065","0.03295"
"486.86400","40.57222","0.03361"
"487.24200","40.60367","0.03372"
"487.62000","40.63512","0.03371"
"487.99800","40.66674","0.03345"
"488.37600","40.69820","0.03387"
"488.75400","40.72964","0.03377"
"489.13200","40.76122","0.03409"
"489.51000","40.79267","0.03399"
"489.88800","40.82417","0.03443"
"490.26600","40.85568","0.03440"
"490.64400","40.88719","0.03459"
"491.02200","40.91870","0.03449"
"491.40000","40.95015","0.03492"
"491.77800","40.98166","0.03512"
"492.15600","41.01323","0.03463"
"492.53400","41.04467","0.03453"
"492.91200","41.07619","0.03478"
"493.29000","41.10769","0.03478"
"493.66800","41.13921","0.03497"
"494.04600","41.17065","0.03446"
"494.42400","41.20222","0.03518"
"494.80200","41.23373","0.03545"
"495.18000","41.26512","0.03528"
"495.55800","41.29669","0.03516"
"495.93600","41.32820","0.03520"
"496.31400","41.35970","0.03533"
"496.69200","41.39110","0.03579"
"497.07000","41.42273","0.03634"
"497.44800","41.45418","0.03553"
"497.82600","41.48562","0.03599"
"498.20400","41.51719","0.03615"
"498.58200","41.54876","0.03586"
"498.96000","41.58015","0.03613"
"499.33800","41.61172","0.03597"
"499.71600","41.64317","0.03623"
"500.09400","41.67462","0.03506"
"500.47200","41.70619","0.03571"
"500.85000","41.73770","0.03585"
"501.22800","41.76921","0.03555"
"501.60600","41.80059","0.03554"
"501.98400","41.83216","0.03582"
"502.36200","41.86374","0.03562"
"502.74000","41.89507","0.03602"
"503.11800","41.92669","0.03599"
"503.49600","41.95820","0.03591"
"503.87400","41.98965","0.03597"
"504.25200","42.02116","0.03577"
"504.63000","42.05273","0.03628"
"505.00800","42.08418","0.03640"
"505.38600","42.11563","0.03482"
"505.76400","42.14719","0.03550"
"506.14200","42.17865","0.03570"
"506.52000","42.21015","0.03581"
"506.89800","42.24166","0.03564"
"507.27600","42.27317","0.03626"
"507.65400","42.30468","0.03594"
"508.03200","42.33613","0.03624"
"508.41000","42.36770","0.03595"
"508.78800","42.39921","0.03513"
"509.16600","42.43065","0.03475"
"509.54400","42.46217","0.03361"
"509.92200","42.49374","0.03477"
"510.30000","42.52519","0.03479"
"510.67800","42.55669","0.03425"
"511.05600","42.58820","0.03508"
"511.43400","42.61971","0.03453"
"511.81200","42.65116","0.03547"
"512.19000","42.68267","0.03525"
"512.56800","42.71424","0.03528"
"512.94600","42.74569","0.03494"
"513.32400","42.77714","0.03522"
"513.70200","42.80871","0.03535"
"514.08000","42.84015","0.03528"
"514.45800","42.87167","0.03476"
"514.83600","42.90324","0.03417"
"515.21400","42.93468","0.03434"
"515.59200","42.96608","0.03386"
"515.97000","42.99770","0.03482"
"516.34800","43.02921","0.03523"
"516.72600","43.06066","0.03508"
"517.10400","43.09217","0.03506"
"517.48200","43.12368","0.03489"
"517.86000","43.15512","0.03458"
"518.23800","43.18664","0.03611"
"518.61600","43.21821","0.03580"
"518.99400","43.24971","0.03563"
"519.37200","43.28110","0.03619"
"519.75000","43.31268","0.03622"
"520.12800","43.34424","0.03603"
"520.50600","43.37563","0.03605"
"520.88400","43.40714","0.03596"
"521.26200","43.43871","0.03637"
"521.64000","43.47015","0.03648"
"522.01800","43.50167","0.03582"
"522.39600","43.53318","0.03668"
"522.77400","43.56469","0.03605"
"523.15200","43.59620","0.03652"
"523.53000","43.62770","0.03661"
"523.90800","43.65921","0.03559"
"524.28600","43.69072","0.03605"
"524.66400","43.72217","0.03618"
"525.04200","43.75368","0.03623"
"525.42000","43.78519","0.03626"
"525.79800","43.81664","0.03622"
"526.17600","43.84821","0.03643"
"526.55400","43.87966","0.03647"
"526.93200","43.91111","0.03605"
"527.31000","43.94268","0.03631"
"527.68800","43.97419","0.03643"
"528.06600","44.00570","0.03621"
"528.44400","44.03714","0.03591"
"528.82200","44.06871","0.03660"
"529.20000","44.10022","0.03635"
"529.57800","44.13161","0.03640"
"529.95600","44.16318","0.03686"
"530.33400","44.19475","0.03677"
"530.71200","44.22614","0.03705"
"531.09000","44.25771","0.03716"
"531.46800","44.28922","0.03716"
"531.84600","44.32066","0.03754"
"532.22400","44.35217","0.03728"
"532.60200","44.38375","0.03695"
"532.98000","44.41519","0.03747"
"533.35800","44.44664","0.03764"
"533.73600","44.47815","0.03737"
"534.11400","44.50966","0.03804"
"534.49200","44.54117","0.03763"
"534.87000","44.57262","0.03636"
"535.24800","44.60419","0.03592"
"535.62600","44.63570","0.03684"
"536.00400","44.66715","0.03693"
"536.38200","44.69872","0.03696"
"536.76000","44.73028","0.03742"
"537.13800","44.76161","0.03633"
"537.51600","44.79324","0.03701"
"537.89400","44.82469","0.03728"
"538.27200","44.85608","0.03728"
"538.65000","44.88771","0.03729"
"539.02800","44.91922","0.03718"
"539.40600","44.95066","0.03764"
"539.78400","44.98218","0.03788"
"540.16200","45.01369","0.03792"
"540.54000","45.04520","0.03783"
"540.91800","45.07664","0.03791"
"541.29600","45.10815","0.03836"
"541.67400","45.13972","0.03798"
"542.05200","45.17111","0.03801"
"542.43000","45.20268","0.03810"
"542.80800","45.23419","0.03819"
"543.18600","45.26570","0.03828"
"543.56400","45.29715","0.03864"
"543.94200","45.32872","0.03844"
"544.32000","45.36016","0.03888"
"544.69800","45.39162","0.03868"
"545.07600","45.42319","0.03788"
"545.45400","45.45469","0.03772"
"545.83200","45.48621","0.03714"
"546.21000","45.51765","0.03685"
"546.58800","45.54922","0.03718"
"546.96600","45.58067","0.03721"
"547.34400","45.61212","0.03708"
"547.72200","45.64369","0.03761"
"548.10000","45.67520","0.03754"
"548.47800","45.70659","0.03784"
"548.85600","45.73815","0.03757"
"549.23400","45.76966","0.03749"
"549.61200","45.80117","0.03730"
"549.99000","45.83269","0.03756"
"550.36800","45.86425","0.03722"
"550.74600","45.89570","0.03767"
"551.12400","45.92715","0.03489"
"551.50200","45.95866","0.03449"
"551.88000","45.99023","0.03546"
"552.25800","46.02168","0.03411"
"552.63600","46.05313","0.03441"
"553.01400","46.08475","0.03498"
"553.39200","46.11621","0.03483"
"553.77000","46.14765","0.03452"
"554.14800","46.17922","0.03520"
"554.52600","46.21067","0.03535"
"554.90400","46.24212","0.03568"
"555.28200","46.27369","0.03625"
"555.66000","46.30520","0.03565"
"556.03800","46.33671","0.03576"
"556.41600","46.36816","0.03602"
"556.79400","46.39967","0.03603"
"557.17200","46.43124","0.03600"
"557.55000","46.46262","0.03659"
"557.92800","46.49420","0.03635"
"558.30600","46.52571","0.03668"
"558.68400","46.55709","0.03659"
"559.06200","46.58866","0.03653"
"559.44000","46.62023","0.03680"
"559.81800","46.65162","0.03696"
"560.19600","46.68319","0.03676"
"560.57400","46.71470","0.03636"
"560.95200","46.74615","0.03661"
"561.30800","46.77587","0.03709"