File: Force_trajectories/170108_2/Specimen_RawData_9.csv
End date,"1/8/2017"
Specimen label,"9BT_78"
Maximum Load,"0.08908",N

Time,Extension,Load
(s),(mm),(N)
"0.00000","0.00000","-0.00030"
"0.17400","0.01052","0.00100"
"0.34800","0.02876","0.00086"
"0.52200","0.04377","0.00222"
"0.69600","0.05824","0.00252"
"0.87000","0.07276","0.00247"
"1.04400","0.08723","0.00322"
"1.21800","0.10164","0.00374"
"1.39200","0.11629","0.00364"
"1.56600","0.13070","0.00387"
"1.74000","0.14511","0.00469"
"1.91400","0.15976","0.00468"
"2.08800","0.17423","0.00481"
"2.26200","0.18864","0.00484"
"2.43600","0.20322","0.00490"
"2.61000","0.21769","0.00548"
"2.78400","0.23216","0.00566"
"2.95800","0.24669","0.00625"
"3.13200","0.26116","0.00540"
"3.30600","0.27569","0.00601"
"3.48000","0.29022","0.00642"
"3.65400","0.30475","0.00564"
"3.82800","0.31916","0.00657"
"4.00200","0.33369","0.00686"
"4.17600","0.34821","0.00699"
"4.35000","0.36268","0.00696"
"4.52400","0.37715","0.00724"
"4.69800","0.39162","0.00731"
"4.87200","0.40615","0.00708"
"5.04600","0.42068","0.00758"
"5.22000","0.43515","0.00736"
"5.39400","0.44968","0.00747"
"5.56800","0.46415","0.00789"
"5.74200","0.47868","0.00844"
"5.91600","0.49320","0.00777"
"6.09000","0.50761","0.00812"
"6.26400","0.52214","0.00728"
"6.43800","0.53667","0.00822"
"6.61200","0.55108","0.00818"
"6.78600","0.56573","0.00787"
"6.96000","0.58020","0.00870"
"7.13400","0.59467","0.00851"
"7.30800","0.60920","0.00908"
"7.48200","0.62366","0.00922"
"7.65600","0.63819","0.00866"
"7.83000","0.65266","0.00865"
"8.00400","0.66719","0.00886"
"8.17800","0.68166","0.00920"
"8.35200","0.69619","0.00922"
"8.52600","0.71066","0.00868"
"8.70000","0.72513","0.00879"
"8.87400","0.73966","0.00937"
"9.04800","0.75419","0.00926"
"9.22200","0.76859","0.00967"
"9.39600","0.78312","0.00964"
"9.57000","0.79765","0.00955"
"9.74400","0.81212","0.00981"
"9.91800","0.82665","0.00963"
"10.09200","0.84118","0.01022"
"10.26600","0.85565","0.01013"
"10.44000","0.87018","0.01003"
"10.61400","0.88465","0.01017"
"10.78800","0.89917","0.01048"
"10.96200","0.91370","0.00987"
"11.13600","0.92817","0.01024"
"11.31000","0.94264","0.01022"
"11.48400","0.95711","0.00963"
"11.65800","0.97170","0.00994"
"11.83200","0.98623","0.01039"
"12.00600","1.00064","0.01071"
"12.18000","1.01517","0.01066"
"12.35400","1.02970","0.01097"
"12.52800","1.04416","0.01073"
"12.70200","1.05869","0.01086"
"12.87600","1.07316","0.01095"
"13.05000","1.08763","0.01068"
"13.22400","1.10216","0.01057"
"13.39800","1.11669","0.01088"
"13.57200","1.13116","0.01070"
"13.74600","1.14569","0.01101"
"13.92000","1.16022","0.01101"
"14.09400","1.17469","0.01085"
"14.26800","1.18921","0.01137"
"14.44200","1.20374","0.01111"
"14.61600","1.21815","0.01164"
"14.79000","1.23268","0.01129"
"14.96400","1.24721","0.01063"
"15.13800","1.26168","0.01160"
"15.31200","1.27615","0.01167"
"15.48600","1.29068","0.01144"
"15.66000","1.30515","0.01154"
"15.83400","1.31961","0.01195"
"16.00800","1.33420","0.01138"
"16.18200","1.34861","0.01168"
"16.35600","1.36314","0.01207"
"16.53000","1.37767","0.01197"
"16.70400","1.39220","0.01192"
"16.87800","1.40667","0.01210"
"17.05200","1.42120","0.01193"
"17.22600","1.43567","0.01192"
"17.40000","1.45014","0.01192"
"17.57400","1.46466","0.01201"
"17.74800","1.47913","0.01246"
"17.92200","1.49360","0.01202"
"18.09600","1.50819","0.01197"
"18.27000","1.52272","0.01196"
"18.44400","1.53713","0.01230"
"18.61800","1.55172","0.01267"
"18.79200","1.56619","0.01274"
"18.96600","1.58066","0.01224"
"19.14000","1.59524","0.01225"
"19.31400","1.60965","0.01233"
"19.48800","1.62412","0.01240"
"19.66200","1.63871","0.01257"
"19.83600","1.65324","0.01237"
"20.01000","1.66771","0.01330"
"20.18400","1.68218","0.01257"
"20.35800","1.69671","0.01292"
"20.53200","1.71112","0.01318"
"20.70600","1.72571","0.01348"
"20.88000","1.74023","0.01292"
"21.05400","1.75464","0.01295"
"21.22800","1.76917","0.01289"
"21.40200","1.78370","0.01341"
"21.57600","1.79817","0.01408"
"21.75000","1.81264","0.01306"
"21.92400","1.82723","0.01312"
"22.09800","1.84164","0.01329"
"22.27200","1.85617","0.01351"
"22.44600","1.87069","0.01318"
"22.62000","1.88516","0.01382"
"22.79400","1.89963","0.01375"
"22.96800","1.91416","0.01385"
"23.14200","1.92869","0.01369"
"23.31600","1.94316","0.01339"
"23.49000","1.95763","0.01369"
"23.66400","1.97216","0.01369"
"23.83800","1.98657","0.01352"
"24.01200","2.00122","0.01373"
"24.18600","2.01568","0.01391"
"24.36000","2.03015","0.01351"
"24.53400","2.04468","0.01353"
"24.70800","2.05921","0.01364"
"24.88200","2.07362","0.01329"
"25.05600","2.08821","0.01408"
"25.23000","2.10268","0.01442"
"25.40400","2.11715","0.01396"
"25.57800","2.13174","0.01401"
"25.75200","2.14615","0.01387"
"25.92600","2.16061","0.01457"
"26.10000","2.17520","0.01454"
"26.27400","2.18967","0.01452"
"26.44800","2.20414","0.01452"
"26.62200","2.21867","0.01427"
"26.79600","2.23320","0.01420"
"26.97000","2.24767","0.01449"
"27.14400","2.26220","0.01454"
"27.31800","2.27673","0.01497"
"27.49200","2.29119","0.01437"
"27.66600","2.30566","0.01439"
"27.84000","2.32019","0.01504"
"28.01400","2.33466","0.01423"
"28.18800","2.34919","0.01423"
"28.36200","2.36366","0.01535"
"28.53600","2.37819","0.01462"
"28.71000","2.39266","0.01523"
"28.88400","2.40719","0.01520"
"29.05800","2.42172","0.01520"
"29.23200","2.43606","0.01489"
"29.40600","2.45071","0.01517"
"29.58000","2.46518","0.01564"
"29.75400","2.47965","0.01483"
"29.92800","2.49418","0.01482"
"30.10200","2.50865","0.01544"
"30.27600","2.52312","0.01511"
"30.45000","2.53765","0.01516"
"30.62400","2.55224","0.01489"
"30.79800","2.56664","0.01508"
"30.97200","2.58117","0.01524"
"31.14600","2.59570","0.01535"
"31.32000","2.61017","0.01519"
"31.49400","2.62470","0.01498"
"31.66800","2.63917","0.01524"
"31.84200","2.65358","0.01546"
"32.01600","2.66817","0.01568"
"32.19000","2.68270","0.01549"
"32.36400","2.69717","0.01537"
"32.53800","2.71169","0.01531"
"32.71200","2.72622","0.01534"
"32.88600","2.74069","0.01559"
"33.06000","2.75516","0.01518"
"33.23400","2.76969","0.01567"
"33.40800","2.78416","0.01564"
"33.58200","2.79869","0.01552"
"33.75600","2.81322","0.01592"
"33.93000","2.82769","0.01613"
"34.10400","2.84216","0.01563"
"34.27800","2.85668","0.01597"
"34.45200","2.87115","0.01536"
"34.62600","2.88568","0.01585"
"34.80000","2.90021","0.01643"
"34.97400","2.91468","0.01594"
"35.14800","2.92915","0.01621"
"35.32200","2.94374","0.01616"
"35.49600","2.95821","0.01578"
"35.67000","2.97262","0.01617"
"35.84400","2.98720","0.01645"
"36.01800","3.00167","0.01632"
"36.19200","3.01614","0.01609"
"36.36600","3.03073","0.01621"
"36.54000","3.04514","0.01624"
"36.71400","3.05961","0.01600"
"36.88800","3.07420","0.01673"
"37.06200","3.08873","0.01645"
"37.23600","3.10314","0.01642"
"37.41000","3.11773","0.01677"
"37.58400","3.13219","0.01664"
"37.75800","3.14666","0.01661"
"37.93200","3.16119","0.01620"
"38.10600","3.17566","0.01658"
"38.28000","3.19019","0.01636"
"38.45400","3.20466","0.01632"
"38.62800","3.21925","0.01654"
"38.80200","3.23366","0.01715"
"38.97600","3.24813","0.01699"
"39.15000","3.26265","0.01675"
"39.32400","3.27712","0.01676"
"39.49800","3.29171","0.01676"
"39.67200","3.30618","0.01693"
"39.84600","3.32065","0.01713"
"40.02000","3.33512","0.01628"
"40.19400","3.34965","0.01706"
"40.36800","3.36424","0.01711"
"40.54200","3.37865","0.01697"
"40.71600","3.39318","0.01644"
"40.89000","3.40764","0.01743"
"41.06400","3.42211","0.01711"
"41.23800","3.43670","0.01725"
"41.41200","3.45117","0.01736"
"41.58600","3.46564","0.01723"
"41.76000","3.48017","0.01728"
"41.93400","3.49470","0.01748"
"42.10800","3.50917","0.01732"
"42.28200","3.52376","0.01712"
"42.45600","3.53817","0.01708"
"42.63000","3.55263","0.01746"
"42.80400","3.56722","0.01751"
"42.97800","3.58169","0.01722"
"43.15200","3.59616","0.01744"
"43.32600","3.61069","0.01798"
"43.50000","3.62522","0.01735"
"43.67400","3.63969","0.01787"
"43.84800","3.65416","0.01766"
"44.02200","3.66869","0.01797"
"44.19600","3.68310","0.01753"
"44.37000","3.69768","0.01769"
"44.54400","3.71215","0.01784"
"44.71800","3.72668","0.01844"
"44.89200","3.74115","0.01806"
"45.06600","3.75568","0.01811"
"45.24000","3.77015","0.01809"
"45.41400","3.78462","0.01776"
"45.58800","3.79915","0.01777"
"45.76200","3.81368","0.01806"
"45.93600","3.82814","0.01844"
"46.11000","3.84273","0.01815"
"46.28400","3.85720","0.01841"
"46.45800","3.87161","0.01828"
"46.63200","3.88620","0.01835"
"46.80600","3.90067","0.01869"
"46.98000","3.91514","0.01858"
"47.15400","3.92973","0.01842"
"47.32800","3.94420","0.01817"
"47.50200","3.95861","0.01834"
"47.67600","3.97319","0.01805"
"47.85000","3.98772","0.01840"
"48.02400","4.00207","0.01877"
"48.19800","4.01672","0.01887"
"48.37200","4.03119","0.01850"
"48.54600","4.04566","0.01866"
"48.72000","4.06019","0.01866"
"48.89400","4.07472","0.01881"
"49.06800","4.08919","0.01867"
"49.24200","4.10365","0.01884"
"49.41600","4.11824","0.01887"
"49.59000","4.13265","0.01853"
"49.76400","4.14718","0.01881"
"49.93800","4.16171","0.01885"
"50.11200","4.17618","0.01934"
"50.28600","4.19071","0.01880"
"50.46000","4.20518","0.01919"
"50.63400","4.21971","0.01896"
"50.80800","4.23418","0.01903"
"50.98200","4.24870","0.01936"
"51.15600","4.26317","0.01959"
"51.33000","4.27764","0.01923"
"51.50400","4.29217","0.01878"
"51.67800","4.30664","0.01923"
"51.85200","4.32117","0.01929"
"52.02600","4.33570","0.01952"
"52.20000","4.35011","0.01948"
"52.37400","4.36464","0.01981"
"52.54800","4.37922","0.01915"
"52.72200","4.39369","0.01944"
"52.89600","4.40816","0.01925"
"53.07000","4.42269","0.01975"
"53.24400","4.43722","0.01980"
"53.41800","4.45163","0.01945"
"53.59200","4.46622","0.01958"
"53.76600","4.48069","0.01997"
"53.94000","4.49510","0.01968"
"54.11400","4.50969","0.01975"
"54.28800","4.52421","0.02002"
"54.46200","4.53868","0.01980"
"54.63600","4.55321","0.01983"
"54.81000","4.56768","0.02006"
"54.98400","4.58215","0.02015"
"55.15800","4.59674","0.02020"
"55.33200","4.61121","0.02011"
"55.50600","4.62562","0.01990"
"55.68000","4.64015","0.02027"
"55.85400","4.65474","0.02005"
"56.02800","4.66914","0.02046"
"56.20200","4.68367","0.02079"
"56.37600","4.69814","0.01996"
"56.55000","4.71267","0.01972"
"56.72400","4.72720","0.02051"
"56.89800","4.74167","0.02041"
"57.07200","4.75620","0.02020"
"57.24600","4.77067","0.02043"
"57.42000","4.78514","0.02097"
"57.59400","4.79966","0.02048"
"57.76800","4.81419","0.02069"
"57.94200","4.82866","0.02024"
"58.11600","4.84319","0.02098"
"58.29000","4.85760","0.02021"
"58.46400","4.87219","0.02094"
"58.63800","4.88666","0.02056"
"58.81200","4.90113","0.02070"
"58.98600","4.91566","0.02078"
"59.16000","4.93018","0.02141"
"59.33400","4.94465","0.02117"
"59.50800","4.95924","0.02097"
"59.68200","4.97365","0.02115"
"59.85600","4.98812","0.02112"
"60.03000","5.00271","0.02144"
"60.20400","5.01718","0.02146"
"60.37800","5.03159","0.02176"
"60.55200","5.04618","0.02123"
"60.72600","5.06071","0.02165"
"60.90000","5.07517","0.02179"
"61.07400","5.08970","0.02151"
"61.24800","5.10423","0.02213"
"61.42200","5.11864","0.02221"
"61.59600","5.13323","0.02213"
"61.77000","5.14770","0.02191"
"61.94400","5.16217","0.02201"
"62.11800","5.17670","0.02183"
"62.29200","5.19117","0.02229"
"62.46600","5.20564","0.02207"
"62.64000","5.22016","0.02240"
"62.81400","5.23469","0.02231"
"62.98800","5.24916","0.02194"
"63.16200","5.26363","0.02198"
"63.33600","5.27822","0.02217"
"63.51000","5.29263","0.02230"
"63.68400","5.30710","0.02269"
"63.85800","5.32169","0.02279"
"64.03200","5.33622","0.02256"
"64.20600","5.35069","0.02269"
"64.38000","5.36521","0.02319"
"64.55400","5.37962","0.02305"
"64.72800","5.39409","0.02292"
"64.90200","5.40874","0.02324"
"65.07600","5.42321","0.02271"
"65.25000","5.43762","0.02274"
"65.42400","5.45221","0.02322"
"65.59800","5.46668","0.02285"
"65.77200","5.48115","0.02301"
"65.94600","5.49567","0.02322"
"66.12000","5.51020","0.02344"
"66.29400","5.52467","0.02314"
"66.46800","5.53920","0.02335"
"66.64200","5.55367","0.02349"
"66.81600","5.56814","0.02353"
"66.99000","5.58267","0.02337"
"67.16400","5.59720","0.02414"
"67.33800","5.61167","0.02319"
"67.51200","5.62619","0.02376"
"67.68600","5.64072","0.02404"
"67.86000","5.65513","0.02401"
"68.03400","5.66966","0.02473"
"68.20800","5.68425","0.02423"
"68.38200","5.69866","0.02389"
"68.55600","5.71313","0.02393"
"68.73000","5.72766","0.02416"
"68.90400","5.74213","0.02418"
"69.07800","5.75666","0.02450"
"69.25200","5.77118","0.02467"
"69.42600","5.78565","0.02498"
"69.60000","5.80012","0.02421"
"69.77400","5.81471","0.02482"
"69.94800","5.82918","0.02551"
"70.12200","5.84365","0.02492"
"70.29600","5.85824","0.02490"
"70.47000","5.87271","0.02508"
"70.64400","5.88718","0.02515"
"70.81800","5.90176","0.02467"
"70.99200","5.91617","0.02492"
"71.16600","5.93058","0.02487"
"71.34000","5.94523","0.02542"
"71.51400","5.95976","0.02569"
"71.68800","5.97411","0.02529"
"71.86200","5.98870","0.02498"
"72.03600","6.00317","0.02564"
"72.21000","6.01764","0.02559"
"72.38400","6.03223","0.02582"
"72.55800","6.04670","0.02629"
"72.73200","6.06116","0.02600"
"72.90600","6.07563","0.02613"
"73.08000","6.09022","0.02613"
"73.25400","6.10457","0.02572"
"73.42800","6.11916","0.02582"
"73.60200","6.13375","0.02672"
"73.77600","6.14816","0.02660"
"73.95000","6.16263","0.02653"
"74.12400","6.17716","0.02619"
"74.29800","6.19168","0.02670"
"74.47200","6.20615","0.02666"
"74.64600","6.22068","0.02638"
"74.82000","6.23521","0.02694"
"74.99400","6.24968","0.02747"
"75.16800","6.26415","0.02681"
"75.34200","6.27868","0.02731"
"75.51600","6.29315","0.02737"
"75.69000","6.30774","0.02784"
"75.86400","6.32215","0.02761"
"76.03800","6.33656","0.02763"
"76.21200","6.35120","0.02771"
"76.38600","6.36573","0.02805"
"76.56000","6.38014","0.02806"
"76.73400","6.39467","0.02772"
"76.90800","6.40920","0.02832"
"77.08200","6.42367","0.02862"
"77.25600","6.43820","0.02830"
"77.43000","6.45273","0.02831"
"77.60400","6.46713","0.02813"
"77.77800","6.48166","0.02873"
"77.95200","6.49619","0.02817"
"78.12600","6.51066","0.02879"
"78.30000","6.52519","0.02897"
"78.47400","6.53972","0.02887"
"78.64800","6.55413","0.02894"
"78.82200","6.56872","0.02894"
"78.99600","6.58325","0.02964"
"79.17000","6.59766","0.02971"
"79.34400","6.61218","0.02864"
"79.51800","6.62665","0.02821"
"79.69200","6.64118","0.02893"
"79.86600","6.65571","0.02886"
"80.04000","6.67018","0.02888"
"80.21400","6.68465","0.02908"
"80.38800","6.69918","0.02860"
"80.56200","6.71371","0.02923"
"80.73600","6.72818","0.02951"
"80.91000","6.74259","0.02977"
"81.08400","6.75723","0.02976"
"81.25800","6.77170","0.03022"
"81.43200","6.78611","0.02995"
"81.60600","6.80070","0.03060"
"81.78000","6.81517","0.03040"
"81.95400","6.82958","0.03036"
"82.12800","6.84423","0.03075"
"82.30200","6.85870","0.03031"
"82.47600","6.87311","0.03052"
"82.65000","6.88769","0.03106"
"82.82400","6.90222","0.03081"
"82.99800","6.91663","0.03175"
"83.17200","6.93122","0.03127"
"83.34600","6.94569","0.03153"
"83.52000","6.96016","0.03158"
"83.69400","6.97469","0.03192"
"83.86800","6.98922","0.03188"
"84.04200","7.00357","0.03224"
"84.21600","7.01816","0.03216"
"84.39000","7.03268","0.03276"
"84.56400","7.04715","0.03258"
"84.73800","7.06168","0.03297"
"84.91200","7.07621","0.03304"
"85.08600","7.09068","0.03291"
"85.26000","7.10515","0.03328"
"85.43400","7.11974","0.03345"
"85.60800","7.13421","0.03346"
"85.78200","7.14868","0.03379"
"85.95600","7.16320","0.03333"
"86.13000","7.17767","0.03417"
"86.30400","7.19220","0.03448"
"86.47800","7.20667","0.03461"
"86.65200","7.22114","0.03396"
"86.82600","7.23567","0.03458"
"87.00000","7.25020","0.03490"
"87.17400","7.26467","0.03475"
"87.34800","7.27914","0.03526"
"87.52200","7.29367","0.03492"
"87.69600","7.30819","0.03455"
"87.87000","7.32266","0.03444"
"88.04400","7.33719","0.03448"
"88.21800","7.35166","0.03478"
"88.39200","7.36607","0.03544"
"88.56600","7.38072","0.03557"
"88.74000","7.39525","0.03531"
"88.91400","7.40960","0.03562"
"89.08800","7.42419","0.03565"
"89.26200","7.43865","0.03566"
"89.43600","7.45312","0.03625"
"89.61000","7.46771","0.03584"
"89.78400","7.48218","0.03616"
"89.95800","7.49665","0.03657"
"90.13200","7.51112","0.03671"
"90.30600","7.52571","0.03700"
"90.48000","7.54012","0.03726"
"90.65400","7.55471","0.03709"
"90.82800","7.56924","0.03729"
"91.00200","7.58365","0.03688"
"91.17600","7.59817","0.03720"
"91.35000","7.61270","0.03733"
"91.52400","7.62717","0.03755"
"91.69800","7.64164","0.03789"
"91.87200","7.65623","0.03771"
"92.04600","7.67076","0.03770"
"92.22000","7.68511","0.03813"
"92.39400","7.69964","0.03805"
"92.56800","7.71417","0.03786"
"92.74200","7.72869","0.03847"
"92.91600","7.74322","0.03849"
"93.09000","7.75769","0.03831"
"93.26400","7.77216","0.03846"
"93.43800","7.78669","0.03842"
"93.61200","7.80122","0.03824"
"93.78600","7.81569","0.03797"
"93.96000","7.83016","0.03798"
"94.13400","7.84469","0.03776"
"94.30800","7.85915","0.03830"
"94.48200","7.87368","0.03841"
"94.65600","7.88815","0.03840"
"94.83000","7.90262","0.03848"
"95.00400","7.91721","0.03813"
"95.17800","7.93168","0.03855"
"95.35200","7.94615","0.03855"
"95.52600","7.96068","0.03852"
"95.70000","7.97515","0.03923"
"95.87400","7.98962","0.03913"
"96.04800","8.00420","0.03914"
"96.22200","8.01873","0.03947"
"96.39600","8.03314","0.03923"
"96.57000","8.04767","0.03968"
"96.74400","8.06220","0.03912"
"96.91800","8.07667","0.03991"
"97.09200","8.09114","0.03947"
"97.26600","8.10573","0.04016"
"97.44000","8.12014","0.04017"
"97.61400","8.13472","0.03943"
"97.78800","8.14925","0.03986"
"97.96200","8.16366","0.03976"
"98.13600","8.17813","0.03980"
"98.31000","8.19266","0.04023"
"98.48400","8.20713","0.04024"
"98.65800","8.22166","0.04052"
"98.83200","8.23619","0.04017"
"99.00600","8.25066","0.04064"
"99.18000","8.26513","0.04053"
"99.35400","8.27971","0.04061"
"99.52800","8.29418","0.04094"
"99.70200","8.30859","0.04086"
"99.87600","8.32318","0.04072"
"100.05000","8.33771","0.04094"
"100.22400","8.35218","0.04089"
"100.39800","8.36671","0.04114"
"100.57200","8.38124","0.04091"
"100.74600","8.39565","0.04143"
"100.92000","8.41018","0.04158"
"101.09400","8.42470","0.04147"
"101.26800","8.43911","0.04173"
"101.44200","8.45370","0.04177"
"101.61600","8.46817","0.04170"
"101.79000","8.48264","0.04173"
"101.96400","8.49717","0.04195"
"102.13800","8.51170","0.04233"
"102.31200","8.52617","0.04233"
"102.48600","8.54070","0.04207"
"102.66000","8.55516","0.04218"
"102.83400","8.56969","0.04236"
"103.00800","8.58416","0.04257"
"103.18200","8.59869","0.04287"
"103.35600","8.61316","0.04341"
"103.53000","8.62769","0.04288"
"103.70400","8.64216","0.04308"
"103.87800","8.65663","0.04301"
"104.05200","8.67116","0.04332"
"104.22600","8.68575","0.04340"
"104.40000","8.70021","0.04310"
"104.57400","8.71462","0.04341"
"104.74800","8.72915","0.04397"
"104.92200","8.74368","0.04366"
"105.09600","8.75815","0.04321"
"105.27000","8.77268","0.04297"
"105.44400","8.78715","0.04357"
"105.61800","8.80162","0.04295"
"105.79200","8.81621","0.04331"
"105.96600","8.83073","0.04333"
"106.14000","8.84514","0.04322"
"106.31400","8.85967","0.04354"
"106.48800","8.87420","0.04325"
"106.66200","8.88861","0.04351"
"106.83600","8.90326","0.04358"
"107.01000","8.91767","0.04391"
"107.18400","8.93214","0.04384"
"107.35800","8.94667","0.04413"
"107.53200","8.96119","0.04451"
"107.70600","8.97566","0.04440"
"107.88000","8.99013","0.04474"
"108.05400","9.00472","0.04477"
"108.22800","9.01913","0.04506"
"108.40200","9.03372","0.04473"
"108.57600","9.04819","0.04510"
"108.75000","9.06266","0.04519"
"108.92400","9.07719","0.04547"
"109.09800","9.09172","0.04535"
"109.27200","9.10618","0.04594"
"109.44600","9.12065","0.04585"
"109.62000","9.13518","0.04654"
"109.79400","9.14965","0.04702"
"109.96800","9.16412","0.04716"
"110.14200","9.17865","0.04765"
"110.31600","9.19324","0.04802"
"110.49000","9.20765","0.04824"
"110.66400","9.22224","0.04787"
"110.83800","9.23671","0.04786"
"111.01200","9.25117","0.04839"
"111.18600","9.26564","0.04861"
"111.36000","9.28017","0.04927"
"111.53400","9.29464","0.04919"
"111.70800","9.30923","0.04936"
"111.88200","9.32364","0.04940"
"112.05600","9.33811","0.05043"
"112.23000","9.35270","0.05111"
"112.40400","9.36723","0.05112"
"112.57800","9.38170","0.05184"
"112.75200","9.39616","0.05148"
"112.92600","9.41069","0.05193"
"113.10000","9.42510","0.05191"
"113.27400","9.43969","0.05239"
"113.44800","9.45422","0.05232"
"113.62200","9.46869","0.05269"
"113.79600","9.48322","0.05281"
"113.97000","9.49769","0.05299"
"114.14400","9.51216","0.01785"
"114.31800","9.52668","0.02094"
"114.49200","9.54115","0.01999"
"114.66600","9.55568","0.02050"
"114.84000","9.57021","0.01979"
"115.01400","9.58468","0.02017"
"115.18800","9.59921","0.02131"
"115.36200","9.61362","0.01941"
"115.53600","9.62821","0.01987"
"115.71000","9.64274","0.02208"
"115.88400","9.65715","0.02005"
"116.05800","9.67167","0.02073"
"116.23200","9.68614","0.02238"
"116.40600","9.70067","0.02116"
"116.58000","9.71520","0.02139"
"116.75400","9.72967","0.02151"
"116.92800","9.74408","0.02129"
"117.10200","9.75867","0.02198"
"117.27600","9.77320","0.02135"
"117.45000","9.78761","0.02233"
"117.62400","9.80219","0.02223"
"117.79800","9.81666","0.02186"
"117.97200","9.83107","0.02249"
"118.14600","9.84572","0.02284"
"118.32000","9.86019","0.02206"
"118.49400","9.87460","0.02281"
"118.66800","9.88919","0.02247"
"118.84200","9.90372","0.02229"
"119.01600","9.91813","0.02298"
"119.19000","9.93266","0.02292"
"119.36400","9.94718","0.02360"
"119.53800","9.96165","0.02316"
"119.71200","9.97618","0.02313"
"119.88600","9.99077","0.02343"
"120.06000","10.00512","0.02330"
"120.23400","10.01965","0.02358"
"120.40800","10.03418","0.02402"
"120.58200","10.04865","0.02401"
"120.75600","10.06318","0.02397"
"120.93000","10.07771","0.02364"
"121.10400","10.09212","0.02380"
"121.27800","10.10664","0.02337"
"121.45200","10.12117","0.02371"
"121.62600","10.13570","0.02414"
"121.80000","10.15017","0.02356"
"121.97400","10.16470","0.02359"
"122.14800","10.17923","0.02383"
"122.32200","10.19370","0.02401"
"122.49600","10.20817","0.02411"
"122.67000","10.22264","0.02414"
"122.84400","10.23710","0.02409"
"123.01800","10.25169","0.02419"
"123.19200","10.26622","0.02441"
"123.36600","10.28063","0.02434"
"123.54000","10.29522","0.02500"
"123.71400","10.30969","0.02412"
"123.88800","10.32416","0.02418"
"124.06200","10.33875","0.02412"
"124.23600","10.35316","0.02402"
"124.41000","10.36762","0.02446"
"124.58400","10.38215","0.02493"
"124.75800","10.39674","0.02431"
"124.93200","10.41115","0.02451"
"125.10600","10.42562","0.02467"
"125.28000","10.44021","0.02427"
"125.45400","10.45462","0.02421"
"125.62800","10.46915","0.02474"
"125.80200","10.48368","0.02476"
"125.97600","10.49815","0.02382"
"126.15000","10.51267","0.02321"
"126.32400","10.52720","0.02380"
"126.49800","10.54167","0.02382"
"126.67200","10.55614","0.02404"
"126.84600","10.57067","0.02369"
"127.02000","10.58514","0.02400"
"127.19400","10.59967","0.02412"
"127.36800","10.61420","0.02440"
"127.54200","10.62866","0.02409"
"127.71600","10.64314","0.02440"
"127.89000","10.65772","0.02426"
"128.06400","10.67219","0.02426"
"128.23800","10.68660","0.02465"
"128.41200","10.70119","0.02425"
"128.58600","10.71566","0.02454"
"128.76000","10.73019","0.02453"
"128.93400","10.74472","0.02496"
"129.10800","10.75919","0.02511"
"129.28200","10.77366","0.02490"
"129.45600","10.78818","0.02546"
"129.63000","10.80271","0.02541"
"129.80400","10.81718","0.02522"
"129.97800","10.83165","0.02550"
"130.15200","10.84618","0.02563"
"130.32600","10.86065","0.02547"
"130.50000","10.87518","0.02525"
"130.67400","10.88971","0.02546"
"130.84800","10.90418","0.02605"
"131.02200","10.91870","0.02655"
"131.19600","10.93317","0.02581"
"131.37000","10.94764","0.02593"
"131.54400","10.96217","0.02624"
"131.71800","10.97670","0.02632"
"131.89200","10.99111","0.02601"
"132.06600","11.00570","0.02647"
"132.24000","11.02023","0.02607"
"132.41400","11.03464","0.02640"
"132.58800","11.04910","0.02602"
"132.76200","11.06376","0.02676"
"132.93600","11.07816","0.02597"
"133.11000","11.09263","0.02695"
"133.28400","11.10716","0.02697"
"133.45800","11.12163","0.02693"
"133.63200","11.13616","0.02704"
"133.80600","11.15069","0.02681"
"133.98000","11.16516","0.02695"
"134.15400","11.17957","0.02702"
"134.32800","11.19421","0.02737"
"134.50200","11.20868","0.02669"
"134.67600","11.22315","0.02753"
"134.85000","11.23774","0.02667"
"135.02400","11.25221","0.02772"
"135.19800","11.26662","0.02762"
"135.37200","11.28121","0.02785"
"135.54600","11.29574","0.02742"
"135.72000","11.31009","0.02718"
"135.89400","11.32468","0.02729"
"136.06800","11.33921","0.02714"
"136.24200","11.35367","0.02701"
"136.41600","11.36820","0.02787"
"136.59000","11.38267","0.02755"
"136.76400","11.39714","0.02783"
"136.93800","11.41167","0.02783"
"137.11200","11.42620","0.02790"
"137.28600","11.44067","0.02785"
"137.46000","11.45514","0.02835"
"137.63400","11.46967","0.02882"
"137.80800","11.48419","0.02871"
"137.98200","11.49866","0.02861"
"138.15600","11.51319","0.02866"
"138.33000","11.52766","0.02921"
"138.50400","11.54219","0.02916"
"138.67800","11.55666","0.02841"
"138.85200","11.57113","0.02902"
"139.02600","11.58566","0.02988"
"139.20000","11.60019","0.03052"
"139.37400","11.61471","0.02997"
"139.54800","11.62918","0.03017"
"139.72200","11.64371","0.03004"
"139.89600","11.65812","0.03056"
"140.07000","11.67259","0.03064"
"140.24400","11.68724","0.03082"
"140.41800","11.70171","0.03128"
"140.59200","11.71612","0.03145"
"140.76600","11.73071","0.03102"
"140.94000","11.74518","0.03113"
"141.11400","11.75964","0.03189"
"141.28800","11.77423","0.03167"
"141.46200","11.78870","0.03134"
"141.63600","11.80317","0.03163"
"141.81000","11.81770","0.03171"
"141.98400","11.83217","0.03253"
"142.15800","11.84664","0.03198"
"142.33200","11.86123","0.03244"
"142.50600","11.87570","0.03275"
"142.68000","11.89017","0.03329"
"142.85400","11.90469","0.03260"
"143.02800","11.91922","0.03311"
"143.20200","11.93363","0.03333"
"143.37600","11.94816","0.03287"
"143.55000","11.96275","0.03349"
"143.72400","11.97716","0.03317"
"143.89800","11.99169","0.03363"
"144.07200","12.00616","0.03439"
"144.24600","12.02069","0.03407"
"144.42000","12.03522","0.03484"
"144.59400","12.04968","0.03514"
"144.76800","12.06415","0.03495"
"144.94200","12.07862","0.03540"
"145.11600","12.09321","0.03521"
"145.29000","12.10768","0.03529"
"145.46400","12.12209","0.03518"
"145.63800","12.13668","0.03554"
"145.81200","12.15115","0.03524"
"145.98600","12.16562","0.03556"
"146.16000","12.18020","0.03582"
"146.33400","12.19467","0.03644"
"146.50800","12.20914","0.03598"
"146.68200","12.22367","0.03698"
"146.85600","12.23820","0.03684"
"147.03000","12.25267","0.03659"
"147.20400","12.26720","0.03683"
"147.37800","12.28173","0.03706"
"147.55200","12.29614","0.03737"
"147.72600","12.31072","0.03733"
"147.90000","12.32519","0.03769"
"148.07400","12.33960","0.03752"
"148.24800","12.35419","0.03762"
"148.42200","12.36872","0.03743"
"148.59600","12.38313","0.03788"
"148.77000","12.39766","0.03790"
"148.94400","12.41219","0.03818"
"149.11800","12.42666","0.03814"
"149.29200","12.44118","0.03814"
"149.46600","12.45571","0.03861"
"149.64000","12.47012","0.03903"
"149.81400","12.48465","0.03874"
"149.98800","12.49924","0.03904"
"150.16200","12.51365","0.03905"
"150.33600","12.52818","0.03907"
"150.51000","12.54265","0.03954"
"150.68400","12.55718","0.03905"
"150.85800","12.57171","0.03981"
"151.03200","12.58623","0.03995"
"151.20600","12.60070","0.04005"
"151.38000","12.61511","0.04023"
"151.55400","12.62970","0.03995"
"151.72800","12.64423","0.04001"
"151.90200","12.65864","0.04022"
"152.07600","12.67317","0.04047"
"152.25000","12.68770","0.04031"
"152.42400","12.70217","0.04063"
"152.59800","12.71670","0.04038"
"152.77200","12.73117","0.04071"
"152.94600","12.74557","0.04053"
"153.12000","12.76022","0.04100"
"153.29400","12.77469","0.04090"
"153.46800","12.78916","0.04089"
"153.64200","12.80369","0.04116"
"153.81600","12.81822","0.04153"
"153.99000","12.83269","0.04169"
"154.16400","12.84716","0.04175"
"154.33800","12.86169","0.04162"
"154.51200","12.87615","0.04202"
"154.68600","12.89062","0.04197"
"154.86000","12.90521","0.04200"
"155.03400","12.91962","0.04259"
"155.20800","12.93421","0.04235"
"155.38200","12.94868","0.04243"
"155.55600","12.96315","0.04302"
"155.73000","12.97768","0.04292"
"155.90400","12.99215","0.04267"
"156.07800","13.00667","0.04299"
"156.25200","13.02114","0.04329"
"156.42600","13.03567","0.04351"
"156.60000","13.05026","0.04387"
"156.77400","13.06467","0.04378"
"156.94800","13.07920","0.04399"
"157.12200","13.09367","0.04405"
"157.29600","13.10814","0.04373"
"157.47000","13.12273","0.04326"
"157.64400","13.13720","0.04392"
"157.81800","13.15161","0.04400"
"157.99200","13.16619","0.04425"
"158.16600","13.18072","0.04471"
"158.34000","13.19513","0.04498"
"158.51400","13.20972","0.04511"
"158.68800","13.22419","0.04526"
"158.86200","13.23866","0.04549"
"159.03600","13.25313","0.04564"
"159.21000","13.26766","0.04631"
"159.38400","13.28213","0.04663"
"159.55800","13.29665","0.04698"
"159.73200","13.31124","0.04765"
"159.90600","13.32565","0.04821"
"160.08000","13.34018","0.04829"
"160.25400","13.35471","0.04841"
"160.42800","13.36912","0.04871"
"160.60200","13.38371","0.04960"
"160.77600","13.39824","0.05009"
"160.95000","13.41265","0.05028"
"161.12400","13.42718","0.04972"
"161.29800","13.44164","0.05031"
"161.47200","13.45623","0.05103"
"161.64600","13.47070","0.05116"
"161.82000","13.48517","0.05208"
"161.99400","13.49970","0.05264"
"162.16800","13.51411","0.05381"
"162.34200","13.52870","0.05483"
"162.51600","13.54317","0.05503"
"162.69000","13.55764","0.05591"
"162.86400","13.57210","0.05647"
"163.03800","13.58663","0.05697"
"163.21200","13.60116","0.05758"
"163.38600","13.61569","0.05770"
"163.56000","13.63016","0.05893"
"163.73400","13.64463","0.05837"
"163.90800","13.65922","0.05763"
"164.08200","13.67369","0.05873"
"164.25600","13.68816","0.06009"
"164.43000","13.70268","0.06006"
"164.60400","13.71715","0.06101"
"164.77800","13.73162","0.06122"
"164.95200","13.74621","0.05903"
"165.12600","13.76068","0.05997"
"165.30000","13.77509","0.06122"
"165.47400","13.78974","0.06142"
"165.64800","13.80421","0.06233"
"165.82200","13.81868","0.06292"
"165.99600","13.83315","0.06399"
"166.17000","13.84768","0.06430"
"166.34400","13.86214","0.06461"
"166.51800","13.87673","0.06561"
"166.69200","13.89120","0.06604"
"166.86600","13.90567","0.06618"
"167.04000","13.92020","0.06695"
"167.21400","13.93473","0.06786"
"167.38800","13.94920","0.06747"
"167.56200","13.96361","0.06790"
"167.73600","13.97819","0.06863"
"167.91000","13.99266","0.06883"
"168.08400","14.00719","0.06621"
"168.25800","14.02166","0.06630"
"168.43200","14.03613","0.06608"
"168.60600","14.05060","0.06583"
"168.78000","14.06519","0.06650"
"168.95400","14.07972","0.06628"
"169.12800","14.09413","0.06707"
"169.30200","14.10866","0.06768"
"169.47600","14.12319","0.06764"
"169.65000","14.13765","0.06768"
"169.82400","14.15224","0.06779"
"169.99800","14.16665","0.06795"
"170.17200","14.18106","0.06886"
"170.34600","14.19571","0.06933"
"170.52000","14.21018","0.06950"
"170.69400","14.22465","0.06970"
"170.86800","14.23924","0.07062"
"171.04200","14.25371","0.07096"
"171.21600","14.26817","0.07137"
"171.39000","14.28270","0.07160"
"171.56400","14.29717","0.07208"
"171.73800","14.31164","0.07276"
"171.91200","14.32617","0.07347"
"172.08600","14.34070","0.07381"
"172.26000","14.35517","0.07419"
"172.43400","14.36964","0.07452"
"172.60800","14.38423","0.07502"
"172.78200","14.39869","0.07583"
"172.95600","14.41322","0.07598"
"173.13000","14.42775","0.07631"
"173.30400","14.44216","0.07639"
"173.47800","14.45663","0.07699"
"173.65200","14.47116","0.07713"
"173.82600","14.48569","0.07796"
"174.00000","14.50016","0.07833"
"174.17400","14.51469","0.07912"
"174.34800","14.52916","0.07924"
"174.52200","14.54363","0.07953"
"174.69600","14.55821","0.08036"
"174.87000","14.57268","0.08060"
"175.04400","14.58709","0.08093"
"175.21800","14.60168","0.08218"
"175.39200","14.61621","0.08197"
"175.56600","14.63062","0.07849"
"175.74000","14.64521","0.07962"
"175.91400","14.65968","0.08001"
"176.08800","14.67415","0.07966"
"176.26200","14.68867","0.07960"
"176.43600","14.70320","0.08050"
"176.61000","14.71761","0.08057"
"176.78400","14.73214","0.08138"
"176.95800","14.74673","0.08177"
"177.13200","14.76114","0.08194"
"177.30600","14.77573","0.08267"
"177.48000","14.79020","0.08309"
"177.65400","14.80467","0.08333"
"177.82800","14.81920","0.08386"
"178.00200","14.83372","0.08455"
"178.17600","14.84819","0.08535"
"178.35000","14.86266","0.08545"
"178.52400","14.87719","0.08566"
"178.69800","14.89166","0.08523"
"178.87200","14.90619","0.08605"
"179.04600","14.92072","0.08617"
"179.22000","14.93513","0.08597"
"179.39400","14.94966","0.08601"
"179.56800","14.96418","0.08614"
"179.74200","14.97865","0.08641"
"179.91600","14.99312","0.08649"
"180.09000","15.00771","0.08615"
"180.26400","15.02218","0.08675"
"180.43800","15.03665","0.08676"
"180.61200","15.05118","0.08709"
"180.78600","15.06565","0.08717"
"180.96000","15.08012","0.08692"
"181.13400","15.09470","0.08658"
"181.30800","15.10917","0.08689"
"181.48200","15.12364","0.08691"
"181.65600","15.13817","0.08713"
"181.83000","15.15270","0.08743"
"182.00400","15.16711","0.08743"
"182.17800","15.18170","0.08796"
"182.35200","15.19623","0.08791"
"182.52600","15.21064","0.08801"
"182.70000","15.22523","0.08836"
"182.87400","15.23970","0.08845"
"183.04800","15.25410","0.08856"
"183.22200","15.26869","0.08878"
"183.39600","15.28322","0.08876"
"183.57000","15.29763","0.08899"
"183.74400","15.31216","0.07707"
"183.91800","15.32675","0.07357"
"184.09200","15.34110","0.07330"
"184.26600","15.35569","0.07543"
"184.44000","15.37022","0.07578"
"184.61400","15.38469","0.07718"
"184.78800","15.39915","0.07800"
"184.96200","15.41368","0.07819"
"185.13600","15.42815","0.06656"
"185.31000","15.44268","0.06712"
"185.48400","15.45721","0.06846"
"185.65800","15.47168","0.06922"
"185.83200","15.48615","0.06972"
"186.00600","15.50074","0.07052"
"186.18000","15.51521","0.07215"
"186.35400","15.52967","0.07221"
"186.52800","15.54420","0.07344"
"186.70200","15.55873","0.07387"
"186.87600","15.57320","0.07457"
"187.05000","15.58767","0.07556"
"187.22400","15.60220","0.07669"
"187.39800","15.61661","0.07733"
"187.57200","15.63126","0.07779"
"187.74600","15.64566","0.07873"
"187.92000","15.66013","0.07943"
"188.09400","15.67472","0.08029"
"188.26800","15.68913","0.08083"
"188.44200","15.70366","0.08192"
"188.61600","15.71825","0.08242"
"188.79000","15.73266","0.08261"
"188.96400","15.74713","0.08348"
"189.13800","15.76166","0.08413"
"189.31200","15.77619","0.08462"
"189.48600","15.79065","0.08116"
"189.66000","15.80512","0.07488"
"189.83400","15.81971","0.07547"
"190.00800","15.83412","0.07573"
"190.18200","15.84871","0.07626"
"190.35600","15.86318","0.07552"
"190.53000","15.87765","0.07543"
"190.70400","15.89218","0.07606"
"190.87800","15.90671","0.07647"
"191.05200","15.92118","0.07737"
"191.22600","15.93564","0.07821"
"191.40000","15.95017","0.07812"
"191.57400","15.96464","0.07922"
"191.74800","15.97911","0.07907"
"191.92200","15.99370","0.07912"
"192.09600","16.00817","0.07878"
"192.27000","16.02258","0.07836"
"192.44400","16.03723","0.07882"
"192.61800","16.05176","0.07617"
"192.79200","16.06610","0.07643"
"192.96600","16.08075","0.07734"
"193.14000","16.09516","0.07761"
"193.31400","16.10963","0.07762"
"193.48800","16.12422","0.07837"
"193.66200","16.13869","0.07878"
"193.83600","16.15316","0.07934"
"194.01000","16.16763","0.08020"
"194.18400","16.18222","0.08092"
"194.35800","16.19662","0.08144"
"194.53200","16.21121","0.08183"
"194.70600","16.22568","0.08228"
"194.88000","16.24015","0.08274"
"195.05400","16.25468","0.08302"
"195.22800","16.26921","0.08363"
"195.40200","16.28368","0.08423"
"195.57600","16.29821","0.08464"
"195.75000","16.31268","0.08468"
"195.92400","16.32721","0.08524"
"196.09800","16.34167","0.08548"
"196.27200","16.35614","0.08552"
"196.44600","16.37067","0.08592"
"196.62000","16.38520","0.08641"
"196.79400","16.39967","0.08627"
"196.96800","16.41414","0.08693"
"197.14200","16.42861","0.08684"
"197.31600","16.44320","0.08720"
"197.49000","16.45773","0.08772"
"197.66400","16.47214","0.08771"
"197.83800","16.48667","0.08794"
"198.01200","16.50113","0.08802"
"198.18600","16.51560","0.08822"
"198.36000","16.53025","0.08849"
"198.53400","16.54472","0.08866"
"198.70800","16.55919","0.08867"
"198.88200","16.57366","0.08343"
"199.05600","16.58819","0.07299"
"199.23000","16.60260","0.07383"
"199.40400","16.61724","0.07486"
"199.57800","16.63171","0.07504"
"199.75200","16.64612","0.07568"
"199.92600","16.66077","0.07660"
"200.10000","16.67518","0.07644"
"200.27400","16.68965","0.07694"
"200.44800","16.70418","0.07426"
"200.62200","16.71871","0.07269"
"200.79600","16.73318","0.07383"
"200.97000","16.74771","0.07401"
"201.14400","16.76217","0.07518"
"201.31800","16.77664","0.07539"
"201.49200","16.79117","0.02705"
"201.66600","16.80576","0.01988"
"201.84000","16.82017","0.02242"
"202.01400","16.83464","0.02265"
"202.18800","16.84917","0.02289"
"202.36200","16.86364","0.02236"
"202.53600","16.87817","0.02229"
"202.71000","16.89270","0.02294"
"202.88400","16.90717","0.02381"
"203.05800","16.92163","0.02316"
"203.23200","16.93616","0.02377"
"203.40600","16.95069","0.02376"
"203.58000","16.96516","0.02511"
"203.75400","16.97963","0.02528"
"203.92800","16.99416","0.02505"
"204.10200","17.00863","0.02523"
"204.27600","17.02321","0.02585"
"204.45000","17.03768","0.02532"
"204.62400","17.05209","0.02440"
"204.79800","17.06674","0.02493"
"204.97200","17.08121","0.02682"
"205.14600","17.09568","0.02641"
"205.32000","17.11015","0.02582"
"205.49400","17.12468","0.02654"
"205.66800","17.13921","0.02735"
"205.84200","17.15368","0.02795"
"206.01600","17.16821","0.02799"
"206.19000","17.18262","0.02836"
"206.36400","17.19720","0.02956"
"206.53800","17.21167","0.03042"
"206.71200","17.22614","0.02958"
"206.88600","17.24073","0.02961"
"207.06000","17.25520","0.01601"
"207.23400","17.26961","0.01245"
"207.40800","17.28420","0.00939"
"207.58200","17.29867","0.00591"
"207.75600","17.31314","0.01592"
"207.93000","17.32767","0.03232"
"208.10400","17.34219","0.00930"
"208.27800","17.35666","0.00926"
"208.45200","17.37119","0.01539"
"208.62600","17.38566","0.01719"
"208.80000","17.40019","0.02219"
"208.97400","17.41466","0.01189"
"209.14800","17.42919","0.00842"
"209.32200","17.44372","0.01123"
"209.49600","17.45807","0.03119"
"209.67000","17.47271","0.01069"
"209.84400","17.48724","0.00447"
"210.01800","17.50159","0.00845"
"210.19200","17.51624","0.01509"
"210.36600","17.53065","-0.00476"
"210.54000","17.54512","0.00468"
"210.71400","17.55965","0.00727"
"210.88800","17.57418","0.01396"
"211.06200","17.58865","0.01385"
"211.23600","17.60317","0.01333"
"211.41000","17.61776","0.01306"
"211.58400","17.63211","0.01401"
"211.75800","17.64670","0.01354"
"211.93200","17.66117","0.01309"
"212.10600","17.67564","0.01411"
"212.28000","17.69017","0.01466"
"212.45400","17.70470","0.01416"
"212.62800","17.71917","0.01338"
"212.80200","17.73363","0.01348"
"212.97600","17.74816","0.01407"
"213.15000","17.76263","0.01329"
"213.32400","17.77716","0.01429"
"213.49800","17.79163","0.01519"
"213.67200","17.80616","0.01440"
"213.84600","17.82069","0.01403"
"214.02000","17.83522","0.01465"
"214.19400","17.84969","0.01432"
"214.36800","17.86416","0.01422"
"214.54200","17.87874","0.01524"
"214.71600","17.89315","0.01451"
"214.89000","17.90762","0.01439"
"215.06400","17.92215","0.01495"
"215.23800","17.93662","0.01460"
"215.41200","17.95115","0.01536"
"215.58600","17.96574","0.01569"
"215.76000","17.98015","0.01498"
"215.93400","17.99462","0.01478"
"216.10800","18.00920","0.01498"
"216.28200","18.02367","0.01533"
"216.45600","18.03814","0.01535"
"216.63000","18.05267","0.01504"
"216.80400","18.06714","0.01516"
"216.97800","18.08161","0.01603"
"217.15200","18.09620","0.01570"
"217.32600","18.11073","0.01597"
"217.50000","18.12508","0.01604"
"217.67400","18.13967","0.01548"
"217.84800","18.15419","0.01573"
"218.02200","18.16860","0.01592"
"218.19600","18.18319","0.01585"
"218.37000","18.19772","0.01577"
"218.54400","18.21219","0.01573"
"218.71800","18.22666","0.01635"
"218.89200","18.24125","0.01640"
"219.06600","18.25566","0.01672"
"219.24000","18.27013","0.01675"
"219.41400","18.28466","0.01681"
"219.58800","18.29918","0.01702"
"219.76200","18.31365","0.01662"
"219.93600","18.32818","0.01618"
"220.11000","18.34265","0.01605"
"220.28400","18.35712","0.01643"
"220.45800","18.37171","0.01664"
"220.63200","18.38624","0.01682"
"220.80600","18.40065","0.01708"
"220.98000","18.41517","0.01677"
"221.15400","18.42971","0.01664"
"221.32800","18.44418","0.01770"
"221.50200","18.45870","0.01678"
"221.67600","18.47323","0.01744"
"221.85000","18.48758","0.01737"
"222.02400","18.50223","0.01770"
"222.19800","18.51670","0.01738"
"222.37200","18.53117","0.01724"
"222.54600","18.54570","0.01764"
"222.72000","18.56017","0.01777"
"222.89400","18.57469","0.01752"
"223.06800","18.58916","0.01769"
"223.24200","18.60369","0.01805"
"223.41600","18.61816","0.01818"
"223.59000","18.63269","0.01756"
"223.76400","18.64716","0.01813"
"223.93800","18.66163","0.01780"
"224.11200","18.67616","0.01857"
"224.28600","18.69069","0.01867"
"224.46000","18.70516","0.01854"
"224.63400","18.71968","0.01841"
"224.80800","18.73421","0.01901"
"224.98200","18.74862","0.01890"
"225.15600","18.76321","0.01895"
"225.33000","18.77774","0.01835"
"225.50400","18.79221","0.01908"
"225.67800","18.80668","0.01910"
"225.85200","18.82115","0.01931"
"226.02600","18.83568","0.01929"
"226.20000","18.85015","0.01926"
"226.37400","18.86467","0.01946"
"226.54800","18.87914","0.01987"
"226.72200","18.89361","0.01975"
"226.89600","18.90826","0.01974"
"227.07000","18.92273","0.01941"
"227.24400","18.93714","0.02004"
"227.41800","18.95173","0.02050"
"227.59200","18.96614","0.01983"
"227.76600","18.98067","0.02015"
"227.94000","18.99519","0.01980"
"228.11400","19.00966","0.02028"
"228.28800","19.02407","0.02072"
"228.46200","19.03866","0.02087"
"228.63600","19.05325","0.02039"
"228.81000","19.06766","0.02047"
"228.98400","19.08219","0.02073"
"229.15800","19.09672","0.02028"
"229.33200","19.11119","0.02088"
"229.50600","19.12572","0.02065"
"229.68000","19.14024","0.02130"
"229.85400","19.15465","0.02110"
"230.02800","19.16918","0.02091"
"230.20200","19.18371","0.02178"
"230.37600","19.19812","0.02220"
"230.55000","19.21265","0.02185"
"230.72400","19.22718","0.02163"
"230.89800","19.24165","0.02173"
"231.07200","19.25612","0.02242"
"231.24600","19.27070","0.02196"
"231.42000","19.28517","0.02188"
"231.59400","19.29964","0.02148"
"231.76800","19.31417","0.02198"
"231.94200","19.32870","0.02236"
"232.11600","19.34317","0.02261"
"232.29000","19.35764","0.02251"
"232.46400","19.37211","0.02203"
"232.63800","19.38664","0.02278"
"232.81200","19.40123","0.02331"
"232.98600","19.41563","0.02287"
"233.16000","19.43016","0.02353"
"233.33400","19.44469","0.02333"
"233.50800","19.45928","0.02368"
"233.68200","19.47363","0.02328"
"233.85600","19.48822","0.02356"
"234.03000","19.50269","0.02398"
"234.20400","19.51710","0.02398"
"234.37800","19.53175","0.02395"
"234.55200","19.54615","0.02470"
"234.72600","19.56062","0.02446"
"234.90000","19.57515","0.02497"
"235.07400","19.58968","0.02423"
"235.24800","19.60415","0.02500"
"235.42200","19.61868","0.02483"
"235.59600","19.63327","0.02540"
"235.77000","19.64768","0.02511"
"235.94400","19.66220","0.02551"
"236.11800","19.67673","0.02580"
"236.29200","19.69114","0.02575"
"236.46600","19.70561","0.02616"
"236.64000","19.72020","0.02576"
"236.81400","19.73467","0.02623"
"236.98800","19.74914","0.02676"
"237.16200","19.76367","0.02697"
"237.33600","19.77814","0.02708"
"237.51000","19.79267","0.02739"
"237.68400","19.80726","0.02733"
"237.85800","19.82167","0.02790"
"238.03200","19.83614","0.02772"
"238.20600","19.85066","0.02807"
"238.38000","19.86519","0.02869"
"238.55400","19.87972","0.02803"
"238.72800","19.89419","0.02851"
"238.90200","19.90872","0.02899"
"239.07600","19.92313","0.02907"
"239.25000","19.93766","0.02921"
"239.42400","19.95218","0.02942"
"239.59800","19.96665","0.02962"
"239.77200","19.98125","0.03041"
"239.94600","19.99571","0.03041"
"240.12000","20.01018","0.03036"
"240.29400","20.02471","0.03070"
"240.46800","20.03924","0.03110"
"240.64200","20.05365","0.03091"
"240.81600","20.06818","0.03172"
"240.99000","20.08271","0.03209"
"241.16400","20.09711","0.03217"
"241.33800","20.11164","0.03215"
"241.51200","20.12617","0.03265"
"241.68600","20.14064","0.03300"
"241.86000","20.15517","0.03267"
"242.03400","20.16970","0.03335"
"242.20800","20.18411","0.03358"
"242.38200","20.19870","0.03373"
"242.55600","20.21317","0.03422"
"242.73000","20.22764","0.03431"
"242.90400","20.24222","0.03451"
"243.07800","20.25669","0.03525"
"243.25200","20.27116","0.03551"
"243.42600","20.28563","0.03518"
"243.60000","20.30016","0.03532"
"243.77400","20.31463","0.03597"
"243.94800","20.32910","0.03647"
"244.12200","20.34375","0.03634"
"244.29600","20.35822","0.03708"
"244.47000","20.37263","0.03724"
"244.64400","20.38721","0.03723"
"244.81800","20.40168","0.03769"
"244.99200","20.41615","0.03787"
"245.16600","20.43074","0.03734"
"245.34000","20.44515","0.03843"
"245.51400","20.45956","0.03821"
"245.68800","20.47421","0.03841"
"245.86200","20.48874","0.03910"
"246.03600","20.50315","0.03930"
"246.21000","20.51767","0.03889"
"246.38400","20.53220","0.03934"
"246.55800","20.54667","0.03976"
"246.73200","20.56114","0.03973"
"246.90600","20.57573","0.04006"
"247.08000","20.59014","0.04016"
"247.25400","20.60467","0.04023"
"247.42800","20.61920","0.04069"
"247.60200","20.63367","0.04086"
"247.77600","20.64814","0.04076"
"247.95000","20.66267","0.04112"
"248.12400","20.67713","0.04129"
"248.29800","20.69166","0.04135"
"248.47200","20.70619","0.04149"
"248.64600","20.72066","0.04168"
"248.82000","20.73513","0.04191"
"248.99400","20.74972","0.04220"
"249.16800","20.76419","0.04246"
"249.34200","20.77866","0.04264"
"249.51600","20.79318","0.04279"
"249.69000","20.80766","0.04278"
"249.86400","20.82218","0.04311"
"250.03800","20.83671","0.04354"
"250.21200","20.85112","0.04375"
"250.38600","20.86565","0.04414"
"250.56000","20.88018","0.04442"
"250.73400","20.89471","0.04490"
"250.90800","20.90911","0.04469"
"251.08200","20.92371","0.04588"
"251.25600","20.93817","0.04587"
"251.43000","20.95258","0.04661"
"251.60400","20.96729","0.04732"
"251.77800","20.98164","0.04837"
"251.95200","20.99611","0.04832"
"252.12600","21.01070","0.04920"
"252.30000","21.02523","0.04996"
"252.47400","21.03964","0.05016"
"252.64800","21.05423","0.05081"
"252.82200","21.06870","0.05171"
"252.99600","21.08316","0.05277"
"253.17000","21.09769","0.05382"
"253.34400","21.11222","0.05384"
"253.51800","21.12663","0.05516"
"253.69200","21.14110","0.05576"
"253.86600","21.15569","0.05699"
"254.04000","21.17022","0.05792"
"254.21400","21.18463","0.05844"
"254.38800","21.19921","0.05967"
"254.56200","21.21363","0.06102"
"254.73600","21.22816","0.06053"
"254.91000","21.24268","0.06136"
"255.08400","21.25715","0.06221"
"255.25800","21.27162","0.06306"
"255.43200","21.28615","0.06345"
"255.60600","21.30068","0.06434"
"255.78000","21.31515","0.06490"
"255.95400","21.32968","0.06521"
"256.12800","21.34414","0.06623"
"256.30200","21.35861","0.06691"
"256.47600","21.37320","0.06795"
"256.65000","21.38767","0.06865"
"256.82400","21.40208","0.06884"
"256.99800","21.41667","0.06987"
"257.17200","21.43120","0.07023"
"257.34600","21.44567","0.07061"
"257.52000","21.46020","0.07146"
"257.69400","21.47467","0.07215"
"257.86800","21.48913","0.07279"
"258.04200","21.50373","0.07343"
"258.21600","21.51819","0.07374"
"258.39000","21.53266","0.07449"
"258.51400","21.54295","0.07528"