File: Force_trajectories/170108_2/Specimen_RawData_4.csv
End date,"1/8/2017"
Specimen label,"13DG_7"
Maximum Load,"0.06960",N

Time,Extension,Load
(s),(mm),(N)
"0.00000","0.00000","-0.00019"
"0.32400","0.02691","-0.00007"
"0.64800","0.05417","0.00023"
"0.97200","0.08125","0.00027"
"1.29600","0.10822","0.00039"
"1.62000","0.13524","0.00053"
"1.94400","0.16227","0.00041"
"2.26800","0.18917","0.00087"
"2.59200","0.21626","0.00141"
"2.91600","0.24322","0.00083"
"3.24000","0.27019","0.00145"
"3.56400","0.29721","0.00103"
"3.88800","0.32412","0.00108"
"4.21200","0.35126","0.00164"
"4.53600","0.37823","0.00093"
"4.86000","0.40519","0.00154"
"5.18400","0.43222","0.00150"
"5.50800","0.45918","0.00108"
"5.83200","0.48627","0.00165"
"6.15600","0.51323","0.00166"
"6.48000","0.54020","0.00110"
"6.80400","0.56728","0.00183"
"7.12800","0.59413","0.00186"
"7.45200","0.62121","0.00132"
"7.77600","0.64824","0.00179"
"8.10000","0.67520","0.00184"
"8.42400","0.70217","0.00169"
"8.74800","0.72913","0.00193"
"9.07200","0.75628","0.00174"
"9.39600","0.78324","0.00219"
"9.72000","0.81021","0.00207"
"10.04400","0.83723","0.00240"
"10.36800","0.86420","0.00244"
"10.69200","0.89122","0.00276"
"11.01600","0.91819","0.00226"
"11.34000","0.94515","0.00247"
"11.66400","0.97230","0.00221"
"11.98800","0.99920","0.00210"
"12.31200","1.02629","0.00215"
"12.63600","1.05325","0.00254"
"12.96000","1.08022","0.00205"
"13.28400","1.10724","0.00274"
"13.60800","1.13415","0.00253"
"13.93200","1.16123","0.00231"
"14.25600","1.18826","0.00286"
"14.58000","1.21522","0.00257"
"14.90400","1.24219","0.00248"
"15.22800","1.26915","0.00251"
"15.55200","1.29630","0.00264"
"15.87600","1.32320","0.00245"
"16.20000","1.35017","0.00267"
"16.52400","1.37719","0.00264"
"16.84800","1.40422","0.00257"
"17.17200","1.43124","0.00259"
"17.49600","1.45827","0.00271"
"17.82000","1.48517","0.00244"
"18.14400","1.51226","0.00269"
"18.46800","1.53916","0.00247"
"18.79200","1.56625","0.00282"
"19.11600","1.59327","0.00274"
"19.44000","1.62024","0.00264"
"19.76400","1.64720","0.00216"
"20.08800","1.67423","0.00347"
"20.41200","1.70131","0.00302"
"20.73600","1.72828","0.00296"
"21.06000","1.75518","0.00293"
"21.38400","1.78227","0.00323"
"21.70800","1.80917","0.00305"
"22.03200","1.83626","0.00359"
"22.35600","1.86322","0.00286"
"22.68000","1.89019","0.00299"
"23.00400","1.91727","0.00306"
"23.32800","1.94424","0.00349"
"23.65200","1.97120","0.00280"
"23.97600","1.99817","0.00303"
"24.30000","2.02519","0.00308"
"24.62400","2.05222","0.00324"
"24.94800","2.07918","0.00321"
"25.27200","2.10621","0.00266"
"25.59600","2.13323","0.00274"
"25.92000","2.16014","0.00251"
"26.24400","2.18722","0.00238"
"26.56800","2.21425","0.00201"
"26.89200","2.24127","0.00242"
"27.21600","2.26824","0.00220"
"27.54000","2.29520","0.00292"
"27.86400","2.32223","0.00233"
"28.18800","2.34925","0.00199"
"28.51200","2.37622","0.00283"
"28.83600","2.40324","0.00279"
"29.16000","2.43015","0.00180"
"29.48400","2.45723","0.00175"
"29.80800","2.48426","0.00159"
"30.13200","2.51122","0.00237"
"30.45600","2.53830","0.00195"
"30.78000","2.56515","0.00192"
"31.10400","2.59224","0.00250"
"31.42800","2.61920","0.00203"
"31.75200","2.64628","0.00203"
"32.07600","2.67325","0.00208"
"32.40000","2.70016","0.00206"
"32.72400","2.72730","0.00274"
"33.04800","2.75420","0.00260"
"33.37200","2.78123","0.00265"
"33.69600","2.80819","0.00253"
"34.02000","2.83516","0.00251"
"34.34400","2.86224","0.00319"
"34.66800","2.88921","0.00279"
"34.99200","2.91617","0.00255"
"35.31600","2.94326","0.00276"
"35.64000","2.97022","0.00274"
"35.96400","2.99725","0.00276"
"36.28800","3.02421","0.00287"
"36.61200","3.05118","0.00267"
"36.93600","3.07820","0.00297"
"37.26000","3.10523","0.00331"
"37.58400","3.13225","0.00291"
"37.90800","3.15928","0.00247"
"38.23200","3.18624","0.00331"
"38.55600","3.21321","0.00263"
"38.88000","3.24011","0.00317"
"39.20400","3.26732","0.00281"
"39.52800","3.29428","0.00273"
"39.85200","3.32119","0.00354"
"40.17600","3.34821","0.00316"
"40.50000","3.37518","0.00298"
"40.82400","3.40220","0.00286"
"41.14800","3.42917","0.00340"
"41.47200","3.45619","0.00355"
"41.79600","3.48328","0.00357"
"42.12000","3.51018","0.00369"
"42.44400","3.53727","0.00347"
"42.76800","3.56423","0.00299"
"43.09200","3.59120","0.00345"
"43.41600","3.61822","0.00317"
"43.74000","3.64513","0.00371"
"44.06400","3.67221","0.00301"
"44.38800","3.69924","0.00343"
"44.71200","3.72620","0.00273"
"45.03600","3.75323","0.00352"
"45.36000","3.78019","0.00298"
"45.68400","3.80722","0.00327"
"46.00800","3.83424","0.00359"
"46.33200","3.86115","0.00395"
"46.65600","3.88823","0.00415"
"46.98000","3.91520","0.00360"
"47.30400","3.94222","0.00357"
"47.62800","3.96925","0.00358"
"47.95200","3.99621","0.00395"
"48.27600","4.02324","0.00393"
"48.60000","4.05014","0.00399"
"48.92400","4.07723","0.00352"
"49.24800","4.10425","0.00408"
"49.57200","4.13116","0.00381"
"49.89600","4.15824","0.00373"
"50.22000","4.18515","0.00400"
"50.54400","4.21229","0.00391"
"50.86800","4.23926","0.00403"
"51.19200","4.26622","0.00413"
"51.51600","4.29319","0.00386"
"51.84000","4.32021","0.00427"
"52.16400","4.34730","0.00414"
"52.48800","4.37426","0.00429"
"52.81200","4.40123","0.00429"
"53.13600","4.42825","0.00431"
"53.46000","4.45522","0.00459"
"53.78400","4.48218","0.00489"
"54.10800","4.50921","0.00428"
"54.43200","4.53623","0.00488"
"54.75600","4.56326","0.00494"
"55.08000","4.59022","0.00448"
"55.40400","4.61725","0.00463"
"55.72800","4.64433","0.00490"
"56.05200","4.67112","0.00455"
"56.37600","4.69826","0.00510"
"56.70000","4.72523","0.00478"
"57.02400","4.75225","0.00458"
"57.34800","4.77928","0.00492"
"57.67200","4.80624","0.00471"
"57.99600","4.83327","0.00429"
"58.32000","4.86023","0.00479"
"58.64400","4.88726","0.00441"
"58.96800","4.91422","0.00453"
"59.29200","4.94119","0.00494"
"59.61600","4.96827","0.00499"
"59.94000","4.99524","0.00515"
"60.26400","5.02220","0.00500"
"60.58800","5.04929","0.00433"
"60.91200","5.07619","0.00484"
"61.23600","5.10328","0.00498"
"61.56000","5.13018","0.00520"
"61.88400","5.15727","0.00508"
"62.20800","5.18429","0.00476"
"62.53200","5.21114","0.00484"
"62.85600","5.23822","0.00483"
"63.18000","5.26525","0.00451"
"63.50400","5.29221","0.00474"
"63.82800","5.31924","0.00472"
"64.15200","5.34614","0.00469"
"64.47600","5.37323","0.00477"
"64.80000","5.40019","0.00485"
"65.12400","5.42722","0.00495"
"65.44800","5.45424","0.00463"
"65.77200","5.48121","0.00458"
"66.09600","5.50823","0.00429"
"66.42000","5.53520","0.00432"
"66.74400","5.56216","0.00426"
"67.06800","5.58924","0.00452"
"67.39200","5.61615","0.00422"
"67.71600","5.64324","0.00479"
"68.04000","5.67020","0.00418"
"68.36400","5.69723","0.00463"
"68.68800","5.72419","0.00415"
"69.01200","5.75115","0.00423"
"69.33600","5.77824","0.00449"
"69.66000","5.80520","0.00462"
"69.98400","5.83223","0.00486"
"70.30800","5.85925","0.00466"
"70.63200","5.88622","0.00425"
"70.95600","5.91324","0.00438"
"71.28000","5.94027","0.00440"
"71.60400","5.96717","0.00427"
"71.92800","5.99426","0.00487"
"72.25200","6.02116","0.00486"
"72.57600","6.04825","0.00489"
"72.90000","6.07527","0.00480"
"73.22400","6.10218","0.00465"
"73.54800","6.12926","0.00507"
"73.87200","6.15611","0.00520"
"74.19600","6.18325","0.00514"
"74.52000","6.21028","0.00486"
"74.84400","6.23724","0.00495"
"75.16800","6.26421","0.00524"
"75.49200","6.29117","0.00476"
"75.81600","6.31826","0.00533"
"76.14000","6.34522","0.00508"
"76.46400","6.37219","0.00525"
"76.78800","6.39921","0.00522"
"77.11200","6.42618","0.00552"
"77.43600","6.45320","0.00590"
"77.76000","6.48029","0.00538"
"78.08400","6.50719","0.00505"
"78.40800","6.53422","0.00528"
"78.73200","6.56118","0.00583"
"79.05600","6.58821","0.00546"
"79.38000","6.61523","0.00552"
"79.70400","6.64220","0.00592"
"80.02800","6.66922","0.00552"
"80.35200","6.69619","0.00535"
"80.67600","6.72321","0.00587"
"81.00000","6.75024","0.00603"
"81.32400","6.77714","0.00611"
"81.64800","6.80417","0.00582"
"81.97200","6.83119","0.00613"
"82.29600","6.85828","0.00602"
"82.62000","6.88524","0.00612"
"82.94400","6.91221","0.00586"
"83.26800","6.93929","0.00648"
"83.59200","6.96620","0.00638"
"83.91600","6.99322","0.00597"
"84.24000","7.02019","0.00641"
"84.56400","7.04721","0.00618"
"84.88800","7.07424","0.00665"
"85.21200","7.10114","0.00661"
"85.53600","7.12823","0.00705"
"85.86000","7.15525","0.00658"
"86.18400","7.18216","0.00601"
"86.50800","7.20924","0.00688"
"86.83200","7.23621","0.00670"
"87.15600","7.26323","0.00661"
"87.48000","7.29026","0.00663"
"87.80400","7.31722","0.00691"
"88.12800","7.34425","0.00688"
"88.45200","7.37121","0.00642"
"88.77600","7.39818","0.00689"
"89.10000","7.42520","0.00742"
"89.42400","7.45217","0.00699"
"89.74800","7.47919","0.00720"
"90.07200","7.50622","0.00620"
"90.39600","7.53324","0.00611"
"90.72000","7.56027","0.00633"
"91.04400","7.58717","0.00664"
"91.36800","7.61420","0.00688"
"91.69200","7.64116","0.00585"
"92.01600","7.66825","0.00635"
"92.34000","7.69521","0.00588"
"92.66400","7.72218","0.00657"
"92.98800","7.74920","0.00546"
"93.31200","7.77623","0.00574"
"93.63600","7.80325","0.00574"
"93.96000","7.83028","0.00573"
"94.28400","7.85718","0.00590"
"94.60800","7.88427","0.00612"
"94.93200","7.91123","0.00574"
"95.25600","7.93826","0.00626"
"95.58000","7.96528","0.00597"
"95.90400","7.99225","0.00626"
"96.22800","8.01927","0.00584"
"96.55200","8.04618","0.00651"
"96.87600","8.07320","0.00571"
"97.20000","8.10029","0.00607"
"97.52400","8.12719","0.00644"
"97.84800","8.15422","0.00613"
"98.17200","8.18124","0.00606"
"98.49600","8.20821","0.00642"
"98.82000","8.23523","0.00709"
"99.14400","8.26214","0.00655"
"99.46800","8.28928","0.00650"
"99.79200","8.31625","0.00646"
"100.11600","8.34321","0.00642"
"100.44000","8.37024","0.00698"
"100.76400","8.39726","0.00711"
"101.08800","8.42422","0.00680"
"101.41200","8.45125","0.00703"
"101.73600","8.47822","0.00685"
"102.06000","8.50524","0.00731"
"102.38400","8.53221","0.00641"
"102.70800","8.55929","0.00733"
"103.03200","8.58626","0.00735"
"103.35600","8.61322","0.00709"
"103.68000","8.64025","0.00639"
"104.00400","8.66715","0.00676"
"104.32800","8.69418","0.00717"
"104.65200","8.72126","0.00741"
"104.97600","8.74823","0.00665"
"105.30000","8.77525","0.00709"
"105.62400","8.80216","0.00743"
"105.94800","8.82924","0.00732"
"106.27200","8.85627","0.00710"
"106.59600","8.88323","0.00744"
"106.92000","8.91025","0.00719"
"107.24400","8.93722","0.00657"
"107.56800","8.96418","0.00708"
"107.89200","8.99121","0.00787"
"108.21600","9.01824","0.00746"
"108.54000","9.04526","0.00780"
"108.86400","9.07216","0.00763"
"109.18800","9.09925","0.00740"
"109.51200","9.12621","0.00784"
"109.83600","9.15318","0.00742"
"110.16000","9.18021","0.00786"
"110.48400","9.20717","0.00754"
"110.80800","9.23425","0.00832"
"111.13200","9.26122","0.00827"
"111.45600","9.28818","0.00853"
"111.78000","9.31515","0.00814"
"112.10400","9.34223","0.00885"
"112.42800","9.36926","0.00834"
"112.75200","9.39628","0.00845"
"113.07600","9.42325","0.00856"
"113.40000","9.45027","0.00865"
"113.72400","9.47724","0.00901"
"114.04800","9.50420","0.00879"
"114.37200","9.53123","0.00889"
"114.69600","9.55819","0.00945"
"115.02000","9.58522","0.00913"
"115.34400","9.61218","0.00925"
"115.66800","9.63927","0.00903"
"115.99200","9.66629","0.00963"
"116.31600","9.69320","0.00954"
"116.64000","9.72022","0.00902"
"116.96400","9.74719","0.01018"
"117.28800","9.77421","0.00963"
"117.61200","9.80130","0.00933"
"117.93600","9.82820","0.01025"
"118.26000","9.85523","0.01048"
"118.58400","9.88219","0.01006"
"118.90800","9.90922","0.01058"
"119.23200","9.93624","0.01059"
"119.55600","9.96321","0.01062"
"119.88000","9.99029","0.01049"
"120.20400","10.01720","0.01026"
"120.52800","10.04422","0.01053"
"120.85200","10.07131","0.01082"
"121.17600","10.09821","0.01113"
"121.50000","10.12524","0.00986"
"121.82400","10.15220","0.00997"
"122.14800","10.17923","0.00990"
"122.47200","10.20625","0.01073"
"122.79600","10.23316","0.00997"
"123.12000","10.26018","0.01017"
"123.44400","10.28721","0.01016"
"123.76800","10.31423","0.01048"
"124.09200","10.34120","0.01102"
"124.41600","10.36816","0.01049"
"124.74000","10.39525","0.01105"
"125.06400","10.42227","0.01056"
"125.38800","10.44924","0.01121"
"125.71200","10.47626","0.01109"
"126.03600","10.50317","0.01176"
"126.36000","10.53025","0.01177"
"126.68400","10.55716","0.01184"
"127.00800","10.58418","0.01180"
"127.33200","10.61127","0.01238"
"127.65600","10.63811","0.01154"
"127.98000","10.66520","0.01278"
"128.30400","10.69216","0.01257"
"128.62800","10.71925","0.01282"
"128.95200","10.74621","0.01280"
"129.27600","10.77318","0.01267"
"129.60000","10.80020","0.01215"
"129.92400","10.82717","0.01312"
"130.24800","10.85419","0.01316"
"130.57200","10.88122","0.01335"
"130.89600","10.90818","0.01369"
"131.22000","10.93521","0.01346"
"131.54400","10.96217","0.01380"
"131.86800","10.98920","0.01410"
"132.19200","11.01628","0.01379"
"132.51600","11.04319","0.01405"
"132.84000","11.07021","0.01471"
"133.16400","11.09724","0.01415"
"133.48800","11.12420","0.01452"
"133.81200","11.15123","0.01359"
"134.13600","11.17813","0.01423"
"134.46000","11.20522","0.01434"
"134.78400","11.23224","0.01394"
"135.10800","11.25921","0.01463"
"135.43200","11.28623","0.01440"
"135.75600","11.31320","0.01451"
"136.08000","11.34028","0.01520"
"136.40400","11.36725","0.01553"
"136.72800","11.39421","0.01541"
"137.05200","11.42124","0.01516"
"137.37600","11.44820","0.01544"
"137.70000","11.47523","0.01603"
"138.02400","11.50225","0.01594"
"138.34800","11.52922","0.01618"
"138.67200","11.55624","0.01644"
"138.99600","11.58321","0.01640"
"139.32000","11.61023","0.01686"
"139.64400","11.63726","0.01676"
"139.96800","11.66422","0.01659"
"140.29200","11.69119","0.01636"
"140.61600","11.71815","0.01682"
"140.94000","11.74523","0.01763"
"141.26400","11.77226","0.01724"
"141.58800","11.79917","0.01753"
"141.91200","11.82625","0.01703"
"142.23600","11.85321","0.01746"
"142.56000","11.88024","0.01766"
"142.88400","11.90727","0.01792"
"143.20800","11.93417","0.01783"
"143.53200","11.96126","0.01832"
"143.85600","11.98822","0.01825"
"144.18000","12.01518","0.01810"
"144.50400","12.04221","0.01795"
"144.82800","12.06923","0.01805"
"145.15200","12.09626","0.01801"
"145.47600","12.12323","0.01834"
"145.80000","12.15025","0.01887"
"146.12400","12.17727","0.01911"
"146.44800","12.20418","0.01891"
"146.77200","12.23126","0.01877"
"147.09600","12.25817","0.01921"
"147.42000","12.28525","0.01858"
"147.74400","12.31228","0.01857"
"148.06800","12.33918","0.01868"
"148.39200","12.36621","0.01826"
"148.71600","12.39323","0.01943"
"149.04000","12.42020","0.01909"
"149.36400","12.44722","0.01872"
"149.68800","12.47419","0.01998"
"150.01200","12.50127","0.01952"
"150.33600","12.52824","0.01942"
"150.66000","12.55520","0.01955"
"150.98400","12.58229","0.01933"
"151.30800","12.60919","0.01995"
"151.63200","12.63622","0.01983"
"151.95600","12.66318","0.01951"
"152.28000","12.69027","0.02020"
"152.60400","12.71729","0.01996"
"152.92800","12.74420","0.02014"
"153.25200","12.77128","0.01991"
"153.57600","12.79825","0.02035"
"153.90000","12.82521","0.02038"
"154.22400","12.85224","0.02067"
"154.54800","12.87920","0.02046"
"154.87200","12.90629","0.02061"
"155.19600","12.93319","0.01985"
"155.52000","12.96022","0.02024"
"155.84400","12.98724","0.02041"
"156.16800","13.01421","0.02079"
"156.49200","13.04123","0.02088"
"156.81600","13.06820","0.02098"
"157.14000","13.09516","0.02103"
"157.46400","13.12225","0.02130"
"157.78800","13.14921","0.02039"
"158.11200","13.17624","0.01987"
"158.43600","13.20320","0.02071"
"158.76000","13.23023","0.02031"
"159.08400","13.25725","0.02073"
"159.40800","13.28416","0.02120"
"159.73200","13.31124","0.02129"
"160.05600","13.33827","0.02091"
"160.38000","13.36523","0.02146"
"160.70400","13.39226","0.02100"
"161.02800","13.41916","0.02122"
"161.35200","13.44625","0.02033"
"161.67600","13.47321","0.02059"
"162.00000","13.50018","0.02072"
"162.32400","13.52720","0.02117"
"162.64800","13.55417","0.02108"
"162.97200","13.58125","0.02086"
"163.29600","13.60822","0.02158"
"163.62000","13.63518","0.02121"
"163.94400","13.66227","0.02150"
"164.26800","13.68917","0.02162"
"164.59200","13.71620","0.02157"
"164.91600","13.74322","0.02145"
"165.24000","13.77025","0.02134"
"165.56400","13.79721","0.02132"
"165.88800","13.82418","0.02179"
"166.21200","13.85120","0.02161"
"166.53600","13.87823","0.02188"
"166.86000","13.90519","0.02191"
"167.18400","13.93222","0.02171"
"167.50800","13.95918","0.02232"
"167.83200","13.98621","0.02190"
"168.15600","14.01323","0.02230"
"168.48000","14.04020","0.02209"
"168.80400","14.06728","0.02185"
"169.12800","14.09413","0.02185"
"169.45200","14.12121","0.02207"
"169.77600","14.14818","0.02238"
"170.10000","14.17514","0.02259"
"170.42400","14.20223","0.02238"
"170.74800","14.22913","0.02278"
"171.07200","14.25628","0.02323"
"171.39600","14.28324","0.02293"
"171.72000","14.31021","0.02277"
"172.04400","14.33717","0.02285"
"172.36800","14.36420","0.02276"
"172.69200","14.39122","0.02310"
"173.01600","14.41825","0.02283"
"173.34000","14.44521","0.02230"
"173.66400","14.47230","0.02273"
"173.98800","14.49920","0.02324"
"174.31200","14.52623","0.02290"
"174.63600","14.55319","0.02306"
"174.96000","14.58022","0.02319"
"175.28400","14.60724","0.02318"
"175.60800","14.63421","0.02294"
"175.93200","14.66123","0.02343"
"176.25600","14.68826","0.02361"
"176.58000","14.71516","0.02312"
"176.90400","14.74224","0.02330"
"177.22800","14.76921","0.02356"
"177.55200","14.79624","0.02329"
"177.87600","14.82326","0.02343"
"178.20000","14.85023","0.02383"
"178.52400","14.87725","0.02379"
"178.84800","14.90422","0.02400"
"179.17200","14.93124","0.02427"
"179.49600","14.95827","0.02379"
"179.82000","14.98523","0.02440"
"180.14400","15.01225","0.02401"
"180.46800","15.03916","0.02423"
"180.79200","15.06619","0.02424"
"181.11600","15.09327","0.02411"
"181.44000","15.12018","0.02419"
"181.76400","15.14720","0.02422"
"182.08800","15.17417","0.02441"
"182.41200","15.20125","0.02425"
"182.73600","15.22827","0.02453"
"183.06000","15.25524","0.02436"
"183.38400","15.28227","0.02441"
"183.70800","15.30923","0.02452"
"184.03200","15.33620","0.02474"
"184.35600","15.36322","0.02474"
"184.68000","15.39018","0.02491"
"185.00400","15.41727","0.02495"
"185.32800","15.44423","0.02482"
"185.65200","15.47120","0.02497"
"185.97600","15.49822","0.02452"
"186.30000","15.52519","0.02492"
"186.62400","15.55222","0.02525"
"186.94800","15.57924","0.02515"
"187.27200","15.60620","0.02526"
"187.59600","15.63323","0.02498"
"187.92000","15.66019","0.02538"
"188.24400","15.68728","0.02472"
"188.56800","15.71424","0.02521"
"188.89200","15.74121","0.02534"
"189.21600","15.76817","0.02483"
"189.54000","15.79514","0.02513"
"189.86400","15.82222","0.02525"
"190.18800","15.84919","0.02533"
"190.51200","15.87621","0.02569"
"190.83600","15.90324","0.02550"
"191.16000","15.93020","0.02565"
"191.48400","15.95723","0.02527"
"191.80800","15.98419","0.02550"
"192.13200","16.01116","0.02463"
"192.45600","16.03824","0.02460"
"192.78000","16.06521","0.02493"
"193.10400","16.09223","0.02496"
"193.42800","16.11926","0.02529"
"193.75200","16.14622","0.02518"
"194.07600","16.17325","0.02535"
"194.40000","16.20021","0.02568"
"194.72400","16.22724","0.02570"
"195.04800","16.25426","0.02570"
"195.37200","16.28117","0.02574"
"195.69600","16.30825","0.02576"
"196.02000","16.33516","0.02560"
"196.34400","16.36230","0.02595"
"196.66800","16.38921","0.02551"
"196.99200","16.41617","0.02583"
"197.31600","16.44320","0.02606"
"197.64000","16.47022","0.02560"
"197.96400","16.49725","0.02574"
"198.28800","16.52421","0.02611"
"198.61200","16.55118","0.02574"
"198.93600","16.57826","0.02591"
"199.26000","16.60523","0.02583"
"199.58400","16.63225","0.02583"
"199.90800","16.65922","0.02591"
"200.23200","16.68618","0.02618"
"200.55600","16.71321","0.02605"
"200.88000","16.74017","0.02626"
"201.20400","16.76726","0.02633"
"201.52800","16.79428","0.02629"
"201.85200","16.82125","0.02612"
"202.17600","16.84821","0.02626"
"202.50000","16.87524","0.02671"
"202.82400","16.90226","0.02650"
"203.14800","16.92929","0.02673"
"203.47200","16.95619","0.02662"
"203.79600","16.98328","0.02680"
"204.12000","17.01024","0.02675"
"204.44400","17.03721","0.02693"
"204.76800","17.06423","0.02695"
"205.09200","17.09120","0.02700"
"205.41600","17.11828","0.02705"
"205.74000","17.14519","0.02659"
"206.06400","17.17227","0.02676"
"206.38800","17.19924","0.02685"
"206.71200","17.22620","0.02667"
"207.03600","17.25323","0.02735"
"207.36000","17.28019","0.02711"
"207.68400","17.30722","0.02706"
"208.00800","17.33424","0.02761"
"208.33200","17.36115","0.02744"
"208.65600","17.38823","0.02742"
"208.98000","17.41525","0.02776"
"209.30400","17.44216","0.02766"
"209.62800","17.46919","0.02726"
"209.95200","17.49615","0.02787"
"210.27600","17.52330","0.02778"
"210.60000","17.55020","0.02788"
"210.92400","17.57717","0.02779"
"211.24800","17.60425","0.02797"
"211.57200","17.63116","0.02779"
"211.89600","17.65824","0.02782"
"212.22000","17.68514","0.02766"
"212.54400","17.71223","0.02816"
"212.86800","17.73932","0.02802"
"213.19200","17.76616","0.02858"
"213.51600","17.79325","0.02848"
"213.84000","17.82021","0.02789"
"214.16400","17.84724","0.02808"
"214.48800","17.87420","0.02783"
"214.81200","17.90117","0.02844"
"215.13600","17.92825","0.02849"
"215.46000","17.95516","0.02864"
"215.78400","17.98218","0.02869"
"216.10800","18.00927","0.02844"
"216.43200","18.03623","0.02795"
"216.75600","18.06326","0.02857"
"217.08000","18.09016","0.02803"
"217.40400","18.11719","0.02855"
"217.72800","18.14427","0.02841"
"218.05200","18.17118","0.02847"
"218.37600","18.19826","0.02832"
"218.70000","18.22523","0.02725"
"219.02400","18.25219","0.02791"
"219.34800","18.27921","0.02803"
"219.67200","18.30612","0.02796"
"219.99600","18.33326","0.02840"
"220.32000","18.36023","0.02873"
"220.64400","18.38720","0.02817"
"220.96800","18.41422","0.02861"
"221.29200","18.44118","0.02871"
"221.61600","18.46827","0.02851"
"221.94000","18.49517","0.02861"
"222.26400","18.52220","0.02916"
"222.58800","18.54922","0.02916"
"222.91200","18.57619","0.02936"
"223.23600","18.60328","0.02997"
"223.56000","18.63018","0.02956"
"223.88400","18.65720","0.03004"
"224.20800","18.68423","0.03007"
"224.53200","18.71119","0.03014"
"224.85600","18.73822","0.03073"
"225.18000","18.76525","0.03048"
"225.50400","18.79221","0.03059"
"225.82800","18.81923","0.03100"
"226.15200","18.84614","0.03041"
"226.47600","18.87322","0.03114"
"226.80000","18.90025","0.03084"
"227.12400","18.92715","0.03168"
"227.44800","18.95418","0.03151"
"227.77200","18.98120","0.03136"
"228.09600","19.00823","0.03186"
"228.42000","19.03519","0.03179"
"228.74400","19.06216","0.03207"
"229.06800","19.08930","0.03297"
"229.39200","19.11615","0.03300"
"229.71600","19.14323","0.03338"
"230.04000","19.17020","0.03290"
"230.36400","19.19716","0.03370"
"230.68800","19.22425","0.03353"
"231.01200","19.25121","0.03366"
"231.33600","19.27824","0.03456"
"231.66000","19.30526","0.03423"
"231.98400","19.33217","0.03332"
"232.30800","19.35925","0.03249"
"232.63200","19.38616","0.03354"
"232.95600","19.41330","0.03374"
"233.28000","19.44021","0.03429"
"233.60400","19.46717","0.03403"
"233.92800","19.49426","0.03487"
"234.25200","19.52122","0.03463"
"234.57600","19.54825","0.03560"
"234.90000","19.57521","0.03562"
"235.22400","19.60218","0.03618"
"235.54800","19.62926","0.03636"
"235.87200","19.65623","0.03626"
"236.19600","19.68325","0.03749"
"236.52000","19.71028","0.03653"
"236.84400","19.73718","0.03688"
"237.16800","19.76427","0.03670"
"237.49200","19.79117","0.03577"
"237.81600","19.81826","0.03572"
"238.14000","19.84528","0.03615"
"238.46400","19.87219","0.03653"
"238.78800","19.89921","0.03667"
"239.11200","19.92624","0.03651"
"239.43600","19.95320","0.03698"
"239.76000","19.98023","0.03760"
"240.08400","20.00719","0.03790"
"240.40800","20.03428","0.03727"
"240.73200","20.06124","0.03746"
"241.05600","20.08821","0.03852"
"241.38000","20.11529","0.03955"
"241.70400","20.14220","0.03759"
"242.02800","20.16922","0.03736"
"242.35200","20.19619","0.03775"
"242.67600","20.22327","0.03834"
"243.00000","20.25030","0.03953"
"243.32400","20.27714","0.04029"
"243.64800","20.30423","0.04050"
"243.97200","20.33125","0.04073"
"244.29600","20.35828","0.04071"
"244.62000","20.38524","0.04052"
"244.94400","20.41215","0.04133"
"245.26800","20.43923","0.04110"
"245.59200","20.46620","0.04185"
"245.91600","20.49322","0.04169"
"246.24000","20.52024","0.04309"
"246.56400","20.54715","0.04224"
"246.88800","20.57424","0.04316"
"247.21200","20.60120","0.04263"
"247.53600","20.62817","0.04390"
"247.86000","20.65525","0.04428"
"248.18400","20.68222","0.04505"
"248.50800","20.70924","0.04471"
"248.83200","20.73621","0.04505"
"249.15600","20.76323","0.04559"
"249.48000","20.79020","0.04523"
"249.80400","20.81716","0.04568"
"250.12800","20.84425","0.04489"
"250.45200","20.87121","0.04519"
"250.77600","20.89824","0.04554"
"251.10000","20.92520","0.04601"
"251.42400","20.95217","0.04621"
"251.74800","20.97919","0.04698"
"252.07200","21.00622","0.04719"
"252.39600","21.03318","0.04742"
"252.72000","21.06027","0.04756"
"253.04400","21.08717","0.04800"
"253.36800","21.11426","0.04822"
"253.69200","21.14128","0.04822"
"254.01600","21.16825","0.04773"
"254.34000","21.19521","0.04867"
"254.66400","21.22218","0.04868"
"254.98800","21.24926","0.04859"
"255.31200","21.27622","0.04983"
"255.63600","21.30319","0.04980"
"255.96000","21.33021","0.04999"
"256.28400","21.35712","0.05031"
"256.60800","21.38427","0.05067"
"256.93200","21.41123","0.05073"
"257.25600","21.43819","0.05067"
"257.58000","21.46522","0.05105"
"257.90400","21.49219","0.05097"
"258.22800","21.51927","0.05111"
"258.55200","21.54623","0.05097"
"258.87600","21.57320","0.05137"
"259.20000","21.60022","0.05188"
"259.52400","21.62719","0.03837"
"259.84800","21.65421","0.03551"
"260.17200","21.68124","0.03097"
"260.49600","21.70821","0.03118"
"260.82000","21.73523","0.02883"
"261.14400","21.76219","0.02965"
"261.46800","21.78928","0.02958"
"261.79200","21.81624","0.03036"
"262.11600","21.84321","0.03056"
"262.44000","21.87023","0.03126"
"262.76400","21.89720","0.03122"
"263.08800","21.92422","0.03195"
"263.41200","21.95125","0.03161"
"263.73600","21.97815","0.02923"
"264.06000","22.00530","0.02888"
"264.38400","22.03221","0.02930"
"264.70800","22.05923","0.02886"
"265.03200","22.08619","0.02934"
"265.35600","22.11322","0.02877"
"265.68000","22.14024","0.02830"
"266.00400","22.16715","0.02847"
"266.32800","22.19423","0.02895"
"266.65200","22.22126","0.02896"
"266.97600","22.24816","0.02934"
"267.30000","22.27525","0.02892"
"267.62400","22.30221","0.02945"
"267.94800","22.32924","0.02954"
"268.27200","22.35620","0.02939"
"268.59600","22.38323","0.02997"
"268.92000","22.41019","0.02976"
"269.24400","22.43722","0.02984"
"269.56800","22.46418","0.03038"
"269.89200","22.49121","0.03052"
"270.21600","22.51817","0.03040"
"270.54000","22.54526","0.03045"
"270.86400","22.57222","0.03057"
"271.18800","22.59919","0.03125"
"271.51200","22.62627","0.03135"
"271.83600","22.65318","0.03155"
"272.16000","22.68026","0.03167"
"272.48400","22.70717","0.03219"
"272.80800","22.73425","0.03187"
"273.13200","22.76122","0.03142"
"273.45600","22.78812","0.03190"
"273.78000","22.81527","0.03254"
"274.10400","22.84223","0.03228"
"274.42800","22.86926","0.03273"
"274.75200","22.89622","0.03303"
"275.07600","22.92319","0.03272"
"275.40000","22.95027","0.03252"
"275.72400","22.97724","0.03194"
"276.04800","23.00426","0.03250"
"276.37200","23.03123","0.03197"
"276.69600","23.05819","0.03220"
"277.02000","23.08522","0.03197"
"277.34400","23.11218","0.03296"
"277.66800","23.13921","0.03355"
"277.99200","23.16629","0.03281"
"278.31600","23.19320","0.03375"
"278.64000","23.22028","0.03270"
"278.96400","23.24725","0.03260"
"279.28800","23.27427","0.03210"
"279.61200","23.30124","0.03308"
"279.93600","23.32814","0.03451"
"280.26000","23.35522","0.03326"
"280.58400","23.38225","0.03339"
"280.90800","23.40916","0.03306"
"281.23200","23.43624","0.03350"
"281.55600","23.46314","0.03386"
"281.88000","23.49023","0.03428"
"282.20400","23.51720","0.03457"
"282.52800","23.54416","0.03322"
"282.85200","23.57125","0.03438"
"283.17600","23.59821","0.03483"
"283.50000","23.62530","0.03378"
"283.82400","23.65226","0.03441"
"284.14800","23.67923","0.03603"
"284.47200","23.70625","0.03575"
"284.79600","23.73316","0.03658"
"285.12000","23.76018","0.03586"
"285.44400","23.78726","0.03683"
"285.76800","23.81423","0.03656"
"286.09200","23.84120","0.03753"
"286.41600","23.86816","0.03824"
"286.74000","23.89524","0.03950"
"287.06400","23.92227","0.04090"
"287.38800","23.94924","0.04028"
"287.71200","23.97620","0.04120"
"288.03600","24.00316","0.04172"
"288.36000","24.03025","0.04231"
"288.68400","24.05722","0.04322"
"289.00800","24.08418","0.04441"
"289.33200","24.11126","0.04328"
"289.65600","24.13811","0.04272"
"289.98000","24.16519","0.04320"
"290.30400","24.19216","0.04070"
"290.62800","24.21918","0.04136"
"290.95200","24.24627","0.04272"
"291.27600","24.27317","0.04424"
"291.60000","24.30026","0.04393"
"291.92400","24.32723","0.04321"
"292.24800","24.35413","0.04456"
"292.57200","24.38121","0.04480"
"292.89600","24.40818","0.04481"
"293.22000","24.43526","0.04508"
"293.54400","24.46223","0.04510"
"293.86800","24.48919","0.04638"
"294.19200","24.51622","0.04690"
"294.51600","24.54325","0.04728"
"294.84000","24.57021","0.04735"
"295.16400","24.59723","0.04791"
"295.48800","24.62420","0.04836"
"295.81200","24.65122","0.04872"
"296.13600","24.67819","0.04940"
"296.46000","24.70521","0.05001"
"296.78400","24.73230","0.04903"
"297.10800","24.75920","0.05024"
"297.43200","24.78623","0.05033"
"297.75600","24.81319","0.05054"
"298.08000","24.84028","0.05056"
"298.40400","24.86724","0.05111"
"298.72800","24.89421","0.05155"
"299.05200","24.92123","0.05160"
"299.37600","24.94820","0.05248"
"299.70000","24.97522","0.05281"
"300.02400","25.00225","0.05261"
"300.34800","25.02921","0.05239"
"300.67200","25.05624","0.05284"
"300.99600","25.08320","0.05309"
"301.32000","25.11017","0.05105"
"301.64400","25.13725","0.02382"
"301.96800","25.16422","0.02497"
"302.29200","25.19124","0.02490"
"302.61600","25.21821","0.02547"
"302.94000","25.24523","0.02597"
"303.26400","25.27226","0.02611"
"303.58800","25.29916","0.02678"
"303.91200","25.32625","0.02641"
"304.23600","25.35321","0.02697"
"304.56000","25.38024","0.02737"
"304.88400","25.40726","0.02711"
"305.20800","25.43417","0.02769"
"305.53200","25.46125","0.02846"
"305.85600","25.48828","0.02804"
"306.18000","25.51518","0.02765"
"306.50400","25.54227","0.02794"
"306.82800","25.56917","0.02765"
"307.15200","25.59626","0.02764"
"307.47600","25.62316","0.02778"
"307.80000","25.65025","0.02823"
"308.12400","25.67721","0.02833"
"308.44800","25.70418","0.02820"
"308.77200","25.73120","0.02838"
"309.09600","25.75817","0.02879"
"309.42000","25.78531","0.02874"
"309.74400","25.81222","0.02896"
"310.06800","25.83912","0.02634"
"310.39200","25.86627","0.02023"
"310.71600","25.89323","0.02253"
"311.04000","25.92026","0.02239"
"311.36400","25.94722","0.02273"
"311.68800","25.97419","0.02332"
"312.01200","26.00115","0.02239"
"312.33600","26.02818","0.02383"
"312.66000","26.05520","0.02377"
"312.98400","26.08223","0.02404"
"313.30800","26.10919","0.02428"
"313.63200","26.13628","0.02400"
"313.95600","26.16324","0.02526"
"314.28000","26.19021","0.02492"
"314.60400","26.21723","0.02476"
"314.92800","26.24414","0.02581"
"315.25200","26.27122","0.02529"
"315.57600","26.29825","0.02560"
"315.90000","26.32521","0.02601"
"316.22400","26.35224","0.02565"
"316.54800","26.37914","0.02626"
"316.87200","26.40629","0.02663"
"317.19600","26.43319","0.02679"
"317.52000","26.46021","0.02725"
"317.84400","26.48718","0.02719"
"318.16800","26.51421","0.02772"
"318.49200","26.54123","0.02792"
"318.81600","26.56820","0.02784"
"319.14000","26.59522","0.02832"
"319.46400","26.62225","0.02823"
"319.78800","26.64915","0.02850"
"320.11200","26.67624","0.02895"
"320.43600","26.70326","0.02922"
"320.76000","26.73023","0.02969"
"321.08400","26.75725","0.03002"
"321.40800","26.78416","0.02979"
"321.73200","26.81130","0.03041"
"322.05600","26.83827","0.03089"
"322.38000","26.86517","0.03065"
"322.70400","26.89220","0.03112"
"323.02800","26.91916","0.03134"
"323.35200","26.94625","0.03214"
"323.67600","26.97327","0.03278"
"324.00000","27.00018","0.03297"
"324.32400","27.02726","0.03326"
"324.64800","27.05422","0.03335"
"324.97200","27.08119","0.03424"
"325.29600","27.10822","0.03522"
"325.62000","27.13518","0.03496"
"325.94400","27.16227","0.03500"
"326.26800","27.18917","0.03598"
"326.59200","27.21620","0.03594"
"326.91600","27.24328","0.03697"
"327.24000","27.27019","0.03634"
"327.56400","27.29721","0.03721"
"327.88800","27.32417","0.03639"
"328.21200","27.35126","0.03759"
"328.53600","27.37822","0.03728"
"328.86000","27.40519","0.03722"
"329.18400","27.43222","0.03756"
"329.50800","27.45924","0.03832"
"329.83200","27.48621","0.03800"
"330.15600","27.51323","0.03847"
"330.48000","27.54020","0.03845"
"330.80400","27.56728","0.03888"
"331.12800","27.59425","0.03556"
"331.45200","27.62127","0.03463"
"331.77600","27.64824","0.03580"
"332.10000","27.67520","0.03562"
"332.42400","27.70222","0.03678"
"332.74800","27.72919","0.03759"
"333.07200","27.75622","0.03770"
"333.39600","27.78330","0.03736"
"333.72000","27.81015","0.03789"
"334.04400","27.83723","0.03838"
"334.36800","27.86426","0.03835"
"334.69200","27.89122","0.03850"
"335.01600","27.91825","0.03886"
"335.34000","27.94521","0.03910"
"335.66400","27.97224","0.03982"
"335.98800","27.99920","0.03979"
"336.31200","28.02628","0.03921"
"336.63600","28.05325","0.04001"
"336.96000","28.08021","0.03974"
"337.28400","28.10724","0.04061"
"337.60800","28.13420","0.04079"
"337.93200","28.16117","0.04094"
"338.25600","28.18831","0.04049"
"338.58000","28.21522","0.04128"
"338.90400","28.24224","0.04134"
"339.22800","28.26921","0.04130"
"339.55200","28.29630","0.04162"
"339.87600","28.32326","0.04193"
"340.20000","28.35016","0.04217"
"340.52400","28.37725","0.04222"
"340.84800","28.40421","0.04322"
"341.17200","28.43124","0.04319"
"341.49600","28.45827","0.04321"
"341.82000","28.48517","0.04327"
"342.14400","28.51225","0.04302"
"342.46800","28.53916","0.04306"
"342.79200","28.56624","0.04380"
"343.11600","28.59327","0.04425"
"343.44000","28.62023","0.04364"
"343.76400","28.64726","0.04452"
"344.08800","28.67422","0.04407"
"344.41200","28.70119","0.04401"
"344.73600","28.72828","0.04493"
"345.06000","28.75518","0.04422"
"345.38400","28.78220","0.04459"
"345.70800","28.80923","0.04381"
"346.03200","28.83625","0.04494"
"346.35600","28.86322","0.04408"
"346.68000","28.89018","0.04429"
"347.00400","28.91721","0.04369"
"347.32800","28.94423","0.04407"
"347.65200","28.97114","0.04372"
"347.97600","28.99822","0.04454"
"348.30000","29.02513","0.04451"
"348.62400","29.05222","0.04434"
"348.94800","29.07924","0.04534"
"349.27200","29.10614","0.04535"
"349.59600","29.13323","0.04444"
"349.92000","29.16014","0.04023"
"350.24400","29.18722","0.04083"
"350.56800","29.21418","0.04153"
"350.89200","29.24121","0.04149"
"351.21600","29.26823","0.04219"
"351.54000","29.29514","0.04244"
"351.86400","29.32222","0.04258"
"352.18800","29.34925","0.04252"
"352.51200","29.37621","0.04292"
"352.83600","29.40318","0.04339"
"353.16000","29.43014","0.04389"
"353.48400","29.45723","0.04447"
"353.80800","29.48425","0.04515"
"354.13200","29.51122","0.04483"
"354.45600","29.53824","0.04582"
"354.78000","29.56521","0.04606"
"355.10400","29.59217","0.04607"
"355.42800","29.61920","0.04656"
"355.75200","29.64622","0.04682"
"356.07600","29.67319","0.04775"
"356.40000","29.70021","0.04735"
"356.72400","29.72724","0.04840"
"357.04800","29.75432","0.04888"
"357.37200","29.78117","0.04874"
"357.69600","29.80819","0.04982"
"358.02000","29.83516","0.04952"
"358.34400","29.86224","0.04984"
"358.66800","29.88927","0.04961"
"358.99200","29.91617","0.04998"
"359.31600","29.94326","0.04996"
"359.64000","29.97022","0.05033"
"359.96400","29.99725","0.05066"
"360.28800","30.02421","0.05130"
"360.61200","30.05118","0.05118"
"360.93600","30.07826","0.05124"
"361.26000","30.10523","0.05092"
"361.58400","30.13225","0.05175"
"361.90800","30.15928","0.05152"
"362.23200","30.18618","0.02621"
"362.55600","30.21321","0.02059"
"362.88000","30.24017","0.02216"
"363.20400","30.26720","0.01932"
"363.52800","30.29428","0.02040"
"363.85200","30.32118","0.02200"
"364.17600","30.34827","0.02257"
"364.50000","30.37523","0.02266"
"364.82400","30.40226","0.02220"
"365.14800","30.42929","0.02329"
"365.47200","30.45613","0.02416"
"365.79600","30.48322","0.02394"
"366.12000","30.51018","0.02416"
"366.44400","30.53721","0.02457"
"366.76800","30.56423","0.02533"
"367.09200","30.59120","0.02556"
"367.41600","30.61822","0.02542"
"367.74000","30.64519","0.02602"
"368.06400","30.67215","0.02617"
"368.38800","30.69923","0.02612"
"368.71200","30.72614","0.02662"
"369.03600","30.75323","0.02673"
"369.36000","30.78019","0.02732"
"369.68400","30.80728","0.02743"
"370.00800","30.83424","0.02775"
"370.33200","30.86115","0.02848"
"370.65600","30.88823","0.02859"
"370.98000","30.91520","0.02885"
"371.30400","30.94222","0.02913"
"371.62800","30.96924","0.02995"
"371.95200","30.99621","0.03070"
"372.27600","31.02323","0.03153"
"372.60000","31.05026","0.03133"
"372.92400","31.07717","0.03232"
"373.24800","31.10425","0.03354"
"373.57200","31.13115","0.03453"
"373.89600","31.15824","0.03464"
"374.22000","31.18521","0.03571"
"374.54400","31.21223","0.03656"
"374.86800","31.23926","0.03721"
"375.19200","31.26616","0.03766"
"375.51600","31.29324","0.03886"
"375.84000","31.32027","0.04014"
"376.16400","31.34723","0.04075"
"376.48800","31.37426","0.04053"
"376.81200","31.40117","0.04126"
"377.13600","31.42825","0.04258"
"377.46000","31.45521","0.04357"
"377.78400","31.48218","0.04429"
"378.10800","31.50926","0.04493"
"378.43200","31.53617","0.04541"
"378.75600","31.56325","0.04545"
"379.08000","31.59022","0.04635"
"379.40400","31.61724","0.04681"
"379.72800","31.64427","0.04724"
"380.05200","31.67117","0.04766"
"380.37600","31.69826","0.04806"
"380.70000","31.72522","0.04855"
"381.02400","31.75219","0.04862"
"381.34800","31.77921","0.04935"
"381.67200","31.80618","0.04922"
"381.99600","31.83320","0.04978"
"382.32000","31.86029","0.04854"
"382.64400","31.88719","0.04877"
"382.96800","31.91422","0.04949"
"383.29200","31.94112","0.04980"
"383.61600","31.96827","0.04973"
"383.94000","31.99523","0.05011"
"384.26400","32.02225","0.04964"
"384.58800","32.04922","0.05020"
"384.91200","32.07625","0.05023"
"385.23600","32.10321","0.05055"
"385.56000","32.13018","0.05049"
"385.88400","32.15714","0.05107"
"386.20800","32.18423","0.05063"
"386.53200","32.21119","0.05080"
"386.85600","32.23822","0.05103"
"387.18000","32.26524","0.05119"
"387.50400","32.29221","0.05091"
"387.82800","32.31923","0.05173"
"388.15200","32.34620","0.05166"
"388.47600","32.37322","0.05201"
"388.80000","32.40025","0.05269"
"389.12400","32.42721","0.05320"
"389.44800","32.45424","0.05346"
"389.77200","32.48126","0.05456"
"390.09600","32.50816","0.05518"
"390.42000","32.53519","0.05600"
"390.74400","32.56216","0.04047"
"391.06800","32.58924","0.04298"
"391.39200","32.61615","0.04326"
"391.71600","32.64323","0.04468"
"392.04000","32.67026","0.04612"
"392.36400","32.69716","0.04660"
"392.68800","32.72419","0.04823"
"393.01200","32.75115","0.04794"
"393.33600","32.77824","0.02247"
"393.66000","32.80526","0.01935"
"393.98400","32.83216","0.01777"
"394.30800","32.85925","0.02024"
"394.63200","32.88622","0.02021"
"394.95600","32.91330","0.02155"
"395.28000","32.94027","0.02012"
"395.60400","32.96717","0.02134"
"395.92800","32.99426","0.01972"
"396.25200","33.02122","0.02069"
"396.57600","33.04819","0.02066"
"396.90000","33.07527","0.02108"
"397.22400","33.10224","0.02113"
"397.54800","33.12926","0.02162"
"397.87200","33.15616","0.02122"
"398.19600","33.18313","0.02128"
"398.52000","33.21027","0.02195"
"398.84400","33.23724","0.02201"
"399.16800","33.26426","0.02241"
"399.49200","33.29123","0.02247"
"399.81600","33.31826","0.02247"
"400.14000","33.34528","0.02223"
"400.46400","33.37218","0.02266"
"400.78800","33.39921","0.02254"
"401.11200","33.42624","0.02229"
"401.43600","33.45320","0.02270"
"401.76000","33.48022","0.02248"
"402.08400","33.50719","0.02325"
"402.40800","33.53428","0.02315"
"402.73200","33.56118","0.02303"
"403.05600","33.58820","0.02301"
"403.38000","33.61523","0.02373"
"403.70400","33.64220","0.02341"
"404.02800","33.66928","0.02393"
"404.35200","33.69619","0.02364"
"404.67600","33.72321","0.02414"
"405.00000","33.75024","0.02385"
"405.32400","33.77714","0.02417"
"405.64800","33.80422","0.02423"
"405.97200","33.83119","0.02396"
"406.29600","33.85822","0.02427"
"406.62000","33.88524","0.02431"
"406.94400","33.91214","0.02440"
"407.26800","33.93923","0.02475"
"407.59200","33.96619","0.02485"
"407.91600","33.99316","0.02495"
"408.24000","34.02024","0.02498"
"408.56400","34.04715","0.02448"
"408.88800","34.07423","0.02462"
"409.21200","34.10126","0.02492"
"409.53600","34.12822","0.02486"
"409.86000","34.15531","0.02504"
"410.18400","34.18215","0.02484"
"410.50800","34.20918","0.02514"
"410.83200","34.23620","0.02520"
"411.15600","34.26317","0.02513"
"411.48000","34.29025","0.02544"
"411.80400","34.31710","0.02543"
"412.12800","34.34425","0.02559"
"412.45200","34.37121","0.02533"
"412.77600","34.39817","0.02567"
"413.10000","34.42520","0.02530"
"413.42400","34.45216","0.02601"
"413.74800","34.47925","0.02594"
"414.07200","34.50627","0.02586"
"414.39600","34.53318","0.02589"
"414.72000","34.56026","0.02592"
"415.04400","34.58723","0.02571"
"415.36800","34.61419","0.02579"
"415.69200","34.64122","0.02610"
"416.01600","34.66819","0.02616"
"416.34000","34.69521","0.02618"
"416.66400","34.72217","0.02678"
"416.98800","34.74920","0.02653"
"417.31200","34.77628","0.02662"
"417.63600","34.80319","0.02668"
"417.96000","34.83021","0.02683"
"418.28400","34.85712","0.02684"
"418.60800","34.88426","0.02710"
"418.93200","34.91129","0.02711"
"419.25600","34.93819","0.02791"
"419.58000","34.96522","0.02764"
"419.90400","34.99224","0.02782"
"420.22800","35.01927","0.02857"
"420.55200","35.04623","0.02803"
"420.87600","35.07320","0.02841"
"421.20000","35.10028","0.02893"
"421.52400","35.12719","0.02958"
"421.84800","35.15421","0.02901"
"422.17200","35.18124","0.02956"
"422.49600","35.20826","0.02933"
"422.82000","35.23523","0.03000"
"423.14400","35.26219","0.03013"
"423.46800","35.28922","0.03007"
"423.79200","35.31624","0.03025"
"424.11600","35.34321","0.03072"
"424.44000","35.37023","0.03172"
"424.76400","35.39720","0.03217"
"425.08800","35.42428","0.03258"
"425.41200","35.45125","0.03227"
"425.73600","35.47821","0.03264"
"426.06000","35.50523","0.03266"
"426.38400","35.53220","0.03275"
"426.70800","35.55923","0.03312"
"427.03200","35.58625","0.03429"
"427.35600","35.61322","0.03469"
"427.68000","35.64024","0.03554"
"428.00400","35.66721","0.03625"
"428.32800","35.69423","0.03644"
"428.65200","35.72126","0.03829"
"428.97600","35.74816","0.03808"
"429.30000","35.77525","0.03903"
"429.62400","35.80221","0.04038"
"429.94800","35.82924","0.04032"
"430.27200","35.85626","0.04079"
"430.59600","35.88311","0.04114"
"430.92000","35.91019","0.04155"
"431.24400","35.93722","0.04215"
"431.56800","35.96424","0.04369"
"431.89200","35.99127","0.04351"
"432.21600","36.01817","0.04174"
"432.54000","36.04526","0.04258"
"432.86400","36.07222","0.04323"
"433.18800","36.09919","0.04470"
"433.51200","36.12627","0.04366"
"433.83600","36.15318","0.04491"
"434.16000","36.18026","0.04563"
"434.48400","36.20723","0.04559"
"434.80800","36.23419","0.04710"
"435.13200","36.26128","0.04727"
"435.45600","36.28818","0.04853"
"435.78000","36.31520","0.04862"
"436.10400","36.34223","0.04953"
"436.42800","36.36920","0.05019"
"436.75200","36.39622","0.05027"
"437.07600","36.42313","0.05076"
"437.40000","36.45027","0.05207"
"437.72400","36.47723","0.05278"
"438.04800","36.50420","0.05301"
"438.37200","36.53122","0.05368"
"438.69600","36.55819","0.05263"
"439.02000","36.58527","0.05271"
"439.34400","36.61224","0.05359"
"439.66800","36.63921","0.05467"
"439.99200","36.66623","0.05551"
"440.31600","36.69326","0.05641"
"440.64000","36.72022","0.05716"
"440.96400","36.74718","0.05793"
"441.28800","36.77421","0.05901"
"441.61200","36.80124","0.05995"
"441.93600","36.82820","0.06049"
"442.26000","36.85522","0.06128"
"442.58400","36.88225","0.06090"
"442.90800","36.90921","0.05721"
"443.23200","36.93618","0.05825"
"443.55600","36.96315","0.05492"
"443.88000","36.99029","0.05618"
"444.20400","37.01726","0.05824"
"444.52800","37.04416","0.05778"
"444.85200","37.07124","0.05934"
"445.17600","37.09821","0.06112"
"445.50000","37.12523","0.06183"
"445.82400","37.15220","0.06290"
"446.14800","37.17923","0.06377"
"446.47200","37.20625","0.06457"
"446.79600","37.23322","0.06530"
"447.12000","37.26024","0.06617"
"447.44400","37.28720","0.06597"
"447.76800","37.31417","0.06678"
"448.09200","37.34120","0.06714"
"448.41600","37.36816","0.06801"
"448.74000","37.39518","0.06844"
"449.06400","37.42221","0.06882"
"449.38800","37.44923","0.05548"
"449.71200","37.47614","0.05462"
"450.03600","37.50322","0.05485"
"450.36000","37.53025","0.05502"
"450.68400","37.55721","0.05550"
"451.00800","37.58418","0.05477"
"451.33200","37.61126","0.05481"
"451.65600","37.63817","0.05398"
"451.98000","37.66519","0.05393"
"452.30400","37.69222","0.05386"
"452.62800","37.71918","0.05123"
"452.95200","37.74621","0.05170"
"453.27600","37.77311","0.05218"
"453.60000","37.80026","0.05271"
"453.92400","37.82722","0.05330"
"454.24800","37.85419","0.05406"
"454.57200","37.88128","0.05493"
"454.89600","37.90818","0.05568"
"455.22000","37.93526","0.05667"
"455.54400","37.96217","0.05785"
"455.86800","37.98919","0.05910"
"456.19200","38.01622","0.05991"
"456.51600","38.04318","0.05794"
"456.84000","38.07021","0.05893"
"457.16400","38.09723","0.06058"
"457.48800","38.12420","0.06136"
"457.81200","38.15122","0.06237"
"458.13600","38.17819","0.06345"
"458.46000","38.20515","0.06431"
"458.78400","38.23224","0.06491"
"459.10800","38.25920","0.06534"
"459.43200","38.28623","0.06605"
"459.75600","38.31325","0.06662"
"460.08000","38.34022","0.06784"
"460.40400","38.36724","0.06817"
"460.72800","38.39421","0.06891"
"461.05200","38.42129","0.06905"
"461.37600","38.44826","0.05809"
"461.70000","38.47522","0.05810"
"462.02400","38.50225","0.00915"
"462.34800","38.52916","0.01538"
"462.67200","38.55630","0.00721"
"462.99600","38.58320","0.01554"
"463.32000","38.61017","0.00890"
"463.64400","38.63725","0.01355"
"463.96800","38.66422","0.00797"
"464.29200","38.69124","0.01295"
"464.61600","38.71821","0.01172"
"464.94000","38.74523","0.01158"
"465.26400","38.77225","0.01255"
"465.58800","38.79922","0.01109"
"465.91200","38.82624","0.01391"
"466.23600","38.85321","0.01119"
"466.56000","38.88018","0.01367"
"466.88400","38.90720","0.01151"
"467.20800","38.93417","0.01304"
"467.53200","38.96125","0.01392"
"467.85600","38.98822","0.01388"
"468.18000","39.01524","0.01453"
"468.50400","39.04221","0.01372"
"468.82800","39.06917","0.01490"
"469.15200","39.09620","0.01450"
"469.47600","39.12322","0.01572"
"469.80000","39.15025","0.01580"
"470.12400","39.17727","0.01544"
"470.44800","39.20412","0.01647"
"470.77200","39.23120","0.01534"
"471.09600","39.25817","0.01641"
"471.42000","39.28519","0.01587"
"471.74400","39.31221","0.01604"
"472.06800","39.33918","0.01632"
"472.39200","39.36626","0.01684"
"472.71600","39.39323","0.01701"
"473.04000","39.42020","0.01691"
"473.36400","39.44722","0.01721"
"473.68800","39.47412","0.01717"
"474.01200","39.50121","0.01702"
"474.33600","39.52824","0.01806"
"474.66000","39.55520","0.01755"
"474.98400","39.58222","0.01831"
"475.30800","39.60925","0.01835"
"475.63200","39.63622","0.01850"
"475.95600","39.66318","0.01810"
"476.28000","39.69020","0.01892"
"476.60400","39.71729","0.01851"
"476.92800","39.74419","0.01911"
"477.25200","39.77128","0.01939"
"477.57600","39.79824","0.01942"
"477.90000","39.82515","0.01938"
"478.22400","39.85223","0.01966"
"478.54800","39.87914","0.01941"
"478.87200","39.90623","0.01931"
"479.19600","39.93325","0.01946"
"479.52000","39.96015","0.01991"
"479.84400","39.98724","0.01985"
"480.16800","40.01420","0.02000"
"480.49200","40.04123","0.02086"
"480.81600","40.06825","0.02086"
"481.14000","40.09516","0.02075"
"481.46400","40.12224","0.02140"
"481.78800","40.14921","0.02058"
"482.11200","40.17624","0.02130"
"482.43600","40.20326","0.02110"
"482.76000","40.23029","0.02119"
"483.08400","40.25719","0.02173"
"483.40800","40.28416","0.02167"
"483.71400","40.30975","0.02200"