File: Force_trajectories/170108_2/Specimen_RawData_10.csv
End date,"1/8/2017"
Specimen label,"2DG_13"
Maximum Load,"0.07742",N

Time,Extension,Load
(s),(mm),(N)
"0.00000","0.00000","0.00295"
"0.24000","0.01842","0.00459"
"0.48000","0.04030","0.00811"
"0.72000","0.06027","0.01062"
"0.96000","0.08024","0.01146"
"1.20000","0.10033","0.01314"
"1.44000","0.12024","0.01521"
"1.68000","0.14027","0.01671"
"1.92000","0.16024","0.01811"
"2.16000","0.18021","0.01836"
"2.40000","0.20024","0.01969"
"2.64000","0.22020","0.02066"
"2.88000","0.24023","0.02119"
"3.12000","0.26020","0.02196"
"3.36000","0.28023","0.02325"
"3.60000","0.30020","0.02326"
"3.84000","0.32023","0.02417"
"4.08000","0.34026","0.02422"
"4.32000","0.36023","0.02502"
"4.56000","0.38026","0.02512"
"4.80000","0.40023","0.02541"
"5.04000","0.42020","0.02625"
"5.28000","0.44017","0.02635"
"5.52000","0.46026","0.02666"
"5.76000","0.48023","0.02690"
"6.00000","0.50026","0.02732"
"6.24000","0.52029","0.02783"
"6.48000","0.54026","0.02761"
"6.72000","0.56023","0.02786"
"6.96000","0.58020","0.02790"
"7.20000","0.60023","0.02820"
"7.44000","0.62020","0.02878"
"7.68000","0.64029","0.02910"
"7.92000","0.66020","0.02946"
"8.16000","0.68029","0.02914"
"8.40000","0.70020","0.02966"
"8.64000","0.72022","0.02970"
"8.88000","0.74025","0.02958"
"9.12000","0.76022","0.03011"
"9.36000","0.78025","0.02980"
"9.60000","0.80016","0.03025"
"9.84000","0.82025","0.03033"
"10.08000","0.84022","0.03070"
"10.32000","0.86025","0.03098"
"10.56000","0.88022","0.03114"
"10.80000","0.90019","0.03134"
"11.04000","0.92022","0.03166"
"11.28000","0.94019","0.03215"
"11.52000","0.96028","0.03227"
"11.76000","0.98013","0.03249"
"12.00000","1.00022","0.03237"
"12.24000","1.02019","0.03258"
"12.48000","1.04028","0.03311"
"12.72000","1.06025","0.03292"
"12.96000","1.08022","0.03352"
"13.20000","1.10019","0.03383"
"13.44000","1.12016","0.03363"
"13.68000","1.14025","0.03430"
"13.92000","1.16022","0.03428"
"14.16000","1.18019","0.03466"
"14.40000","1.20022","0.03507"
"14.64000","1.22024","0.03504"
"14.88000","1.24021","0.03507"
"15.12000","1.26030","0.03580"
"15.36000","1.28021","0.03583"
"15.60000","1.30018","0.03589"
"15.84000","1.32021","0.03668"
"16.08000","1.34018","0.03688"
"16.32000","1.36021","0.03779"
"16.56000","1.38018","0.03736"
"16.80000","1.40021","0.03780"
"17.04000","1.42018","0.03800"
"17.28000","1.44033","0.03808"
"17.52000","1.46018","0.03879"
"17.76000","1.48021","0.03840"
"18.00000","1.50030","0.03900"
"18.24000","1.52015","0.03939"
"18.48000","1.54024","0.03996"
"18.72000","1.56027","0.03989"
"18.96000","1.58024","0.04069"
"19.20000","1.60021","0.04074"
"19.44000","1.62024","0.04108"
"19.68000","1.64021","0.04143"
"19.92000","1.66024","0.04136"
"20.16000","1.68027","0.04183"
"20.40000","1.70024","0.04187"
"20.64000","1.72026","0.04250"
"20.88000","1.74023","0.04292"
"21.12000","1.76020","0.04245"
"21.36000","1.78023","0.04295"
"21.60000","1.80026","0.04353"
"21.84000","1.82023","0.04347"
"22.08000","1.84026","0.04383"
"22.32000","1.86029","0.04399"
"22.56000","1.88020","0.04393"
"22.80000","1.90023","0.04458"
"23.04000","1.92020","0.04475"
"23.28000","1.94023","0.04520"
"23.52000","1.96026","0.04514"
"23.76000","1.98029","0.04495"
"24.00000","2.00026","0.04554"
"24.24000","2.02023","0.04561"
"24.48000","2.04026","0.04572"
"24.72000","2.06023","0.04614"
"24.96000","2.08026","0.04620"
"25.20000","2.10017","0.04623"
"25.44000","2.12026","0.04648"
"25.68000","2.14017","0.04611"
"25.92000","2.16032","0.04676"
"26.16000","2.18017","0.04690"
"26.40000","2.20020","0.04658"
"26.64000","2.22028","0.04688"
"26.88000","2.24025","0.04667"
"27.12000","2.26028","0.04708"
"27.36000","2.28013","0.04710"
"27.60000","2.30028","0.04771"
"27.84000","2.32019","0.04733"
"28.08000","2.34028","0.04746"
"28.32000","2.36019","0.04763"
"28.56000","2.38016","0.04770"
"28.80000","2.40025","0.04853"
"29.04000","2.42022","0.04786"
"29.28000","2.44025","0.04838"
"29.52000","2.46022","0.04828"
"29.76000","2.48025","0.04830"
"30.00000","2.50016","0.04873"
"30.24000","2.52019","0.04892"
"30.48000","2.54022","0.04887"
"30.72000","2.56025","0.04871"
"30.96000","2.58028","0.04893"
"31.20000","2.60025","0.04880"
"31.44000","2.62028","0.04877"
"31.68000","2.64019","0.04914"
"31.92000","2.66028","0.04873"
"32.16000","2.68019","0.04948"
"32.40000","2.70027","0.04927"
"32.64000","2.72024","0.04942"
"32.88000","2.74027","0.04936"
"33.12000","2.76024","0.04908"
"33.36000","2.78021","0.04929"
"33.60000","2.80024","0.04966"
"33.84000","2.82015","0.04959"
"34.08000","2.84030","0.05012"
"34.32000","2.86015","0.04944"
"34.56000","2.88024","0.05001"
"34.80000","2.90021","0.04987"
"35.04000","2.92024","0.04955"
"35.28000","2.94027","0.05032"
"35.52000","2.96024","0.05032"
"35.76000","2.98027","0.05056"
"36.00000","3.00018","0.05054"
"36.24000","3.02027","0.05028"
"36.48000","3.04018","0.05077"
"36.72000","3.06027","0.05073"
"36.96000","3.08018","0.05079"
"37.20000","3.10021","0.05054"
"37.44000","3.12024","0.05056"
"37.68000","3.14021","0.05085"
"37.92000","3.16024","0.05051"
"38.16000","3.18015","0.05077"
"38.40000","3.20029","0.05074"
"38.64000","3.22014","0.05127"
"38.88000","3.24023","0.05108"
"39.12000","3.26020","0.05117"
"39.36000","3.28023","0.05160"
"39.60000","3.30020","0.05116"
"39.84000","3.32023","0.05115"
"40.08000","3.34026","0.05119"
"40.32000","3.36023","0.05179"
"40.56000","3.38026","0.05189"
"40.80000","3.40017","0.05179"
"41.04000","3.42026","0.05188"
"41.28000","3.44023","0.05161"
"41.52000","3.46026","0.05177"
"41.76000","3.48017","0.05210"
"42.00000","3.50020","0.05217"
"42.24000","3.52029","0.05200"
"42.48000","3.54020","0.05181"
"42.72000","3.56029","0.05253"
"42.96000","3.58020","0.05240"
"43.20000","3.60023","0.05240"
"43.44000","3.62020","0.05080"
"43.68000","3.64029","0.05147"
"43.92000","3.66020","0.05162"
"44.16000","3.68028","0.05134"
"44.40000","3.70025","0.05151"
"44.64000","3.72022","0.05219"
"44.88000","3.74025","0.05180"
"45.12000","3.76022","0.05186"
"45.36000","3.78025","0.05189"
"45.60000","3.80022","0.05218"
"45.84000","3.82025","0.05219"
"46.08000","3.84016","0.05216"
"46.32000","3.86025","0.05273"
"46.56000","3.88028","0.05255"
"46.80000","3.90019","0.05280"
"47.04000","3.92028","0.05225"
"47.28000","3.94025","0.05278"
"47.52000","3.96022","0.05281"
"47.76000","3.98019","0.05341"
"48.00000","4.00028","0.05286"
"48.24000","4.02019","0.05291"
"48.48000","4.04028","0.05291"
"48.72000","4.06025","0.05335"
"48.96000","4.08022","0.05292"
"49.20000","4.10025","0.05327"
"49.44000","4.12022","0.05296"
"49.68000","4.14025","0.05313"
"49.92000","4.16016","0.05360"
"50.16000","4.18030","0.05387"
"50.40000","4.20021","0.05320"
"50.64000","4.22024","0.05349"
"50.88000","4.24021","0.05371"
"51.12000","4.26024","0.05331"
"51.36000","4.28021","0.05325"
"51.60000","4.30018","0.05364"
"51.84000","4.32027","0.05369"
"52.08000","4.34024","0.05412"
"52.32000","4.36021","0.05372"
"52.56000","4.38018","0.05326"
"52.80000","4.40027","0.05377"
"53.04000","4.42024","0.05321"
"53.28000","4.44021","0.05338"
"53.52000","4.46024","0.05335"
"53.76000","4.48027","0.05352"
"54.00000","4.50024","0.05344"
"54.24000","4.52015","0.05390"
"54.48000","4.54024","0.05432"
"54.72000","4.56021","0.05392"
"54.96000","4.58024","0.05395"
"55.20000","4.60027","0.05378"
"55.44000","4.62024","0.05360"
"55.68000","4.64027","0.05374"
"55.92000","4.66024","0.05416"
"56.16000","4.68026","0.05384"
"56.40000","4.70011","0.05418"
"56.64000","4.72026","0.05432"
"56.88000","4.74023","0.05401"
"57.12000","4.76026","0.05423"
"57.36000","4.78023","0.05440"
"57.60000","4.80020","0.05380"
"57.84000","4.82023","0.05397"
"58.08000","4.84020","0.05451"
"58.32000","4.86023","0.05386"
"58.56000","4.88014","0.05420"
"58.80000","4.90023","0.05381"
"59.04000","4.92020","0.05396"
"59.28000","4.94023","0.05341"
"59.52000","4.96020","0.05354"
"59.76000","4.98023","0.05434"
"60.00000","5.00026","0.05319"
"60.24000","5.02023","0.05322"
"60.48000","5.04026","0.05326"
"60.72000","5.06011","0.05272"
"60.96000","5.08020","0.05346"
"61.20000","5.10023","0.05377"
"61.44000","5.12026","0.05377"
"61.68000","5.14023","0.05388"
"61.92000","5.16026","0.05364"
"62.16000","5.18023","0.05333"
"62.40000","5.20019","0.05360"
"62.64000","5.22028","0.05375"
"62.88000","5.24013","0.05378"
"63.12000","5.26022","0.05366"
"63.36000","5.28019","0.05360"
"63.60000","5.30022","0.05404"
"63.84000","5.32019","0.05353"
"64.08000","5.34022","0.05364"
"64.32000","5.36025","0.05259"
"64.56000","5.38022","0.05258"
"64.80000","5.40025","0.05304"
"65.04000","5.42016","0.05329"
"65.28000","5.44025","0.05325"
"65.52000","5.46016","0.05259"
"65.76000","5.48025","0.05360"
"66.00000","5.50022","0.05345"
"66.24000","5.52031","0.05310"
"66.48000","5.54022","0.05389"
"66.72000","5.56019","0.05312"
"66.96000","5.58022","0.05341"
"67.20000","5.60019","0.05305"
"67.44000","5.62028","0.05160"
"67.68000","5.64019","0.05066"
"67.92000","5.66028","0.05020"
"68.16000","5.68019","0.05014"
"68.40000","5.70027","0.04934"
"68.64000","5.72024","0.04946"
"68.88000","5.74021","0.04896"
"69.12000","5.76024","0.04919"
"69.36000","5.78021","0.04900"
"69.60000","5.80024","0.04923"
"69.84000","5.82021","0.04917"
"70.08000","5.84030","0.04928"
"70.32000","5.86015","0.04937"
"70.56000","5.88030","0.04991"
"70.80000","5.90027","0.04948"
"71.04000","5.92018","0.04977"
"71.28000","5.94021","0.04911"
"71.52000","5.96024","0.04918"
"71.76000","5.98027","0.04981"
"72.00000","6.00018","0.04927"
"72.24000","6.02033","0.04970"
"72.48000","6.04024","0.04940"
"72.72000","6.06021","0.05021"
"72.96000","6.08024","0.04975"
"73.20000","6.10027","0.04933"
"73.44000","6.12024","0.04962"
"73.68000","6.14027","0.04981"
"73.92000","6.16024","0.04990"
"74.16000","6.18014","0.04958"
"74.40000","6.20029","0.04994"
"74.64000","6.22020","0.04970"
"74.88000","6.24023","0.05003"
"75.12000","6.26026","0.05032"
"75.36000","6.28023","0.04979"
"75.60000","6.30020","0.04989"
"75.84000","6.32023","0.05023"
"76.08000","6.34026","0.05057"
"76.32000","6.36017","0.05052"
"76.56000","6.38020","0.04981"
"76.80000","6.40017","0.05040"
"77.04000","6.42026","0.05040"
"77.28000","6.44023","0.05044"
"77.52000","6.46026","0.05070"
"77.76000","6.48023","0.05020"
"78.00000","6.50026","0.05015"
"78.24000","6.52023","0.05033"
"78.48000","6.54014","0.05009"
"78.72000","6.56029","0.05089"
"78.96000","6.58020","0.05023"
"79.20000","6.60029","0.05028"
"79.44000","6.62026","0.05091"
"79.68000","6.64023","0.05072"
"79.92000","6.66019","0.05042"
"80.16000","6.68022","0.05120"
"80.40000","6.70025","0.05070"
"80.64000","6.72022","0.05092"
"80.88000","6.74025","0.05087"
"81.12000","6.76022","0.05070"
"81.36000","6.78025","0.05115"
"81.60000","6.80022","0.05106"
"81.84000","6.82025","0.05125"
"82.08000","6.84022","0.05138"
"82.32000","6.86019","0.05054"
"82.56000","6.88028","0.05092"
"82.80000","6.90013","0.05091"
"83.04000","6.92022","0.05131"
"83.28000","6.94019","0.05176"
"83.52000","6.96022","0.05085"
"83.76000","6.98025","0.05106"
"84.00000","7.00028","0.05115"
"84.24000","7.02019","0.05099"
"84.48000","7.04022","0.05093"
"84.72000","7.06025","0.05112"
"84.96000","7.08022","0.05143"
"85.20000","7.10025","0.05125"
"85.44000","7.12022","0.05098"
"85.68000","7.14025","0.05128"
"85.92000","7.16022","0.05065"
"86.16000","7.18030","0.05095"
"86.40000","7.20021","0.05115"
"86.64000","7.22024","0.05103"
"86.88000","7.24027","0.05119"
"87.12000","7.26018","0.05130"
"87.36000","7.28021","0.05168"
"87.60000","7.30018","0.05111"
"87.84000","7.32027","0.05154"
"88.08000","7.34024","0.05126"
"88.32000","7.36021","0.05136"
"88.56000","7.38018","0.05076"
"88.80000","7.40021","0.05138"
"89.04000","7.42030","0.05159"
"89.28000","7.44021","0.05073"
"89.52000","7.46024","0.05146"
"89.76000","7.48021","0.05186"
"90.00000","7.50024","0.05144"
"90.24000","7.52027","0.05156"
"90.48000","7.54030","0.05184"
"90.72000","7.56021","0.05183"
"90.96000","7.58024","0.05129"
"91.20000","7.60027","0.05158"
"91.44000","7.62024","0.05202"
"91.68000","7.64027","0.05169"
"91.92000","7.66024","0.05139"
"92.16000","7.68026","0.05189"
"92.40000","7.70023","0.05123"
"92.64000","7.72026","0.05174"
"92.88000","7.74023","0.05153"
"93.12000","7.76020","0.05190"
"93.36000","7.78023","0.05142"
"93.60000","7.80020","0.05203"
"93.84000","7.82029","0.05193"
"94.08000","7.84020","0.05216"
"94.32000","7.86023","0.05237"
"94.56000","7.88014","0.05193"
"94.80000","7.90029","0.05183"
"95.04000","7.92020","0.05236"
"95.28000","7.94023","0.05200"
"95.52000","7.96026","0.05255"
"95.76000","7.98023","0.05178"
"96.00000","8.00026","0.05168"
"96.24000","8.02017","0.05147"
"96.48000","8.04026","0.05195"
"96.72000","8.06023","0.05182"
"96.96000","8.08026","0.05179"
"97.20000","8.10023","0.05213"
"97.44000","8.12020","0.05228"
"97.68000","8.14023","0.05226"
"97.92000","8.16025","0.05198"
"98.16000","8.18022","0.05211"
"98.40000","8.20019","0.05231"
"98.64000","8.22028","0.05208"
"98.88000","8.24019","0.05228"
"99.12000","8.26022","0.05204"
"99.36000","8.28025","0.05202"
"99.60000","8.30022","0.05187"
"99.84000","8.32025","0.05267"
"100.08000","8.34022","0.05243"
"100.32000","8.36019","0.05204"
"100.56000","8.38016","0.05219"
"100.80000","8.40031","0.05252"
"101.04000","8.42022","0.05213"
"101.28000","8.44025","0.05244"
"101.52000","8.46016","0.05248"
"101.76000","8.48025","0.05243"
"102.00000","8.50022","0.05192"
"102.24000","8.52025","0.05145"
"102.48000","8.54022","0.05216"
"102.72000","8.56019","0.05206"
"102.96000","8.58034","0.05250"
"103.20000","8.60013","0.05263"
"103.44000","8.62022","0.05200"
"103.68000","8.64019","0.05213"
"103.92000","8.66027","0.05235"
"104.16000","8.68024","0.05221"
"104.40000","8.70027","0.05237"
"104.64000","8.72024","0.05257"
"104.88000","8.74021","0.05283"
"105.12000","8.76024","0.05202"
"105.36000","8.78021","0.05279"
"105.60000","8.80024","0.05262"
"105.84000","8.82015","0.05246"
"106.08000","8.84024","0.05260"
"106.32000","8.86021","0.05247"
"106.56000","8.88024","0.05260"
"106.80000","8.90027","0.05272"
"107.04000","8.92018","0.05277"
"107.28000","8.94027","0.05282"
"107.52000","8.96018","0.05284"
"107.76000","8.98021","0.05235"
"108.00000","9.00018","0.05282"
"108.24000","9.02027","0.05270"
"108.48000","9.04024","0.05301"
"108.72000","9.06021","0.05203"
"108.96000","9.08018","0.05273"
"109.20000","9.10021","0.05263"
"109.44000","9.12024","0.05223"
"109.68000","9.14021","0.05172"
"109.92000","9.16023","0.05207"
"110.16000","9.18021","0.05191"
"110.40000","9.20023","0.05227"
"110.64000","9.22014","0.05208"
"110.88000","9.24023","0.05271"
"111.12000","9.26032","0.05178"
"111.36000","9.28023","0.05238"
"111.60000","9.30020","0.05264"
"111.84000","9.32017","0.05227"
"112.08000","9.34020","0.05274"
"112.32000","9.36023","0.05257"
"112.56000","9.38026","0.05192"
"112.80000","9.40023","0.05212"
"113.04000","9.42026","0.05218"
"113.28000","9.44023","0.05241"
"113.52000","9.46014","0.05212"
"113.76000","9.48023","0.05207"
"114.00000","9.50020","0.05227"
"114.24000","9.52023","0.05268"
"114.48000","9.54020","0.05230"
"114.72000","9.56029","0.05209"
"114.96000","9.58020","0.05209"
"115.20000","9.60023","0.05223"
"115.44000","9.62026","0.05303"
"115.68000","9.64023","0.05277"
"115.92000","9.66031","0.05261"
"116.16000","9.68022","0.05210"
"116.40000","9.70025","0.05242"
"116.64000","9.72022","0.05238"
"116.88000","9.74025","0.05256"
"117.12000","9.76022","0.05250"
"117.36000","9.78025","0.05249"
"117.60000","9.80028","0.05273"
"117.84000","9.82019","0.05213"
"118.08000","9.84028","0.05282"
"118.32000","9.86019","0.05244"
"118.56000","9.88022","0.05183"
"118.80000","9.90019","0.05255"
"119.04000","9.92028","0.05259"
"119.28000","9.94019","0.05239"
"119.52000","9.96022","0.05215"
"119.76000","9.98025","0.05250"
"120.00000","10.00028","0.05215"
"120.24000","10.02025","0.05286"
"120.48000","10.04022","0.05286"
"120.72000","10.06025","0.05274"
"120.96000","10.08016","0.05194"
"121.20000","10.10025","0.05224"
"121.44000","10.12022","0.05215"
"121.68000","10.14024","0.05247"
"121.92000","10.16027","0.05232"
"122.16000","10.18024","0.05201"
"122.40000","10.20021","0.05292"
"122.64000","10.22018","0.05206"
"122.88000","10.24027","0.05283"
"123.12000","10.26018","0.05263"
"123.36000","10.28027","0.05250"
"123.60000","10.30024","0.05245"
"123.84000","10.32021","0.05207"
"124.08000","10.34024","0.05256"
"124.32000","10.36021","0.05230"
"124.56000","10.38024","0.05263"
"124.80000","10.40021","0.05240"
"125.04000","10.42024","0.05244"
"125.28000","10.44015","0.05256"
"125.52000","10.46024","0.05251"
"125.76000","10.48021","0.05204"
"126.00000","10.50024","0.05277"
"126.24000","10.52027","0.05267"
"126.48000","10.54024","0.05254"
"126.72000","10.56021","0.05288"
"126.96000","10.58018","0.05232"
"127.20000","10.60027","0.05292"
"127.44000","10.62012","0.05271"
"127.68000","10.64027","0.05274"
"127.92000","10.66023","0.05238"
"128.16000","10.68020","0.05251"
"128.40000","10.70023","0.05260"
"128.64000","10.72026","0.05230"
"128.88000","10.74023","0.05242"
"129.12000","10.76020","0.05211"
"129.36000","10.78023","0.05213"
"129.60000","10.80014","0.05267"
"129.84000","10.82023","0.05265"
"130.08000","10.84020","0.05287"
"130.32000","10.86023","0.05306"
"130.56000","10.88020","0.05234"
"130.80000","10.90029","0.05231"
"131.04000","10.92020","0.05245"
"131.28000","10.94017","0.05267"
"131.52000","10.96026","0.05239"
"131.76000","10.98017","0.05279"
"132.00000","11.00026","0.05269"
"132.24000","11.02017","0.05255"
"132.48000","11.04026","0.05288"
"132.72000","11.06017","0.05270"
"132.96000","11.08026","0.05292"
"133.20000","11.10023","0.05234"
"133.44000","11.12020","0.05241"
"133.68000","11.14029","0.05257"
"133.92000","11.16014","0.05233"
"134.16000","11.18022","0.05195"
"134.40000","11.20025","0.05255"
"134.64000","11.22028","0.05209"
"134.88000","11.24019","0.05292"
"135.12000","11.26028","0.05240"
"135.36000","11.28025","0.05238"
"135.60000","11.30022","0.05246"
"135.84000","11.32025","0.05258"
"136.08000","11.34022","0.05268"
"136.32000","11.36025","0.05258"
"136.56000","11.38022","0.05249"
"136.80000","11.40025","0.05252"
"137.04000","11.42016","0.05245"
"137.28000","11.44025","0.05282"
"137.52000","11.46022","0.05283"
"137.76000","11.48025","0.05247"
"138.00000","11.50022","0.05272"
"138.24000","11.52025","0.05269"
"138.48000","11.54028","0.05248"
"138.72000","11.56019","0.05325"
"138.96000","11.58028","0.05231"
"139.20000","11.60019","0.05273"
"139.44000","11.62028","0.05268"
"139.68000","11.64025","0.05254"
"139.92000","11.66016","0.05244"
"140.16000","11.68024","0.05259"
"140.40000","11.70021","0.05124"
"140.64000","11.72024","0.05175"
"140.88000","11.74015","0.05158"
"141.12000","11.76024","0.05165"
"141.36000","11.78021","0.05134"
"141.60000","11.80030","0.05152"
"141.84000","11.82027","0.05186"
"142.08000","11.84018","0.05148"
"142.32000","11.86027","0.05185"
"142.56000","11.88024","0.05180"
"142.80000","11.90027","0.05184"
"143.04000","11.92018","0.05163"
"143.28000","11.94027","0.05178"
"143.52000","11.96024","0.05160"
"143.76000","11.98021","0.05163"
"144.00000","12.00024","0.05187"
"144.24000","12.02021","0.05217"
"144.48000","12.04018","0.05245"
"144.72000","12.06021","0.05185"
"144.96000","12.08024","0.05197"
"145.20000","12.10020","0.05183"
"145.44000","12.12018","0.05185"
"145.68000","12.14014","0.05159"
"145.92000","12.16023","0.05219"
"146.16000","12.18026","0.05222"
"146.40000","12.20029","0.05200"
"146.64000","12.22020","0.05200"
"146.88000","12.24023","0.05228"
"147.12000","12.26026","0.05268"
"147.36000","12.28017","0.05198"
"147.60000","12.30032","0.05199"
"147.84000","12.32017","0.05207"
"148.08000","12.34026","0.05219"
"148.32000","12.36023","0.05239"
"148.56000","12.38020","0.05238"
"148.80000","12.40023","0.05202"
"149.04000","12.42020","0.05181"
"149.28000","12.44029","0.05260"
"149.52000","12.46020","0.05228"
"149.76000","12.48029","0.05237"
"150.00000","12.50020","0.05272"
"150.24000","12.52023","0.05207"
"150.48000","12.54020","0.05227"
"150.72000","12.56023","0.05238"
"150.96000","12.58026","0.05254"
"151.20000","12.60023","0.05187"
"151.44000","12.62025","0.05278"
"151.68000","12.64017","0.05237"
"151.92000","12.66025","0.05207"
"152.16000","12.68022","0.05271"
"152.40000","12.70019","0.05264"
"152.64000","12.72022","0.05249"
"152.88000","12.74025","0.05231"
"153.12000","12.76022","0.05217"
"153.36000","12.78019","0.05229"
"153.60000","12.80028","0.05245"
"153.84000","12.82019","0.05209"
"154.08000","12.84022","0.05258"
"154.32000","12.86019","0.05258"
"154.56000","12.88022","0.05246"
"154.80000","12.90019","0.05257"
"155.04000","12.92028","0.05259"
"155.28000","12.94019","0.05217"
"155.52000","12.96022","0.05287"
"155.76000","12.98031","0.05262"
"156.00000","13.00016","0.05245"
"156.24000","13.02025","0.05265"
"156.48000","13.04016","0.05302"
"156.72000","13.06025","0.05294"
"156.96000","13.08022","0.05325"
"157.20000","13.10025","0.05265"
"157.44000","13.12022","0.05272"
"157.68000","13.14018","0.05232"
"157.92000","13.16027","0.05302"
"158.16000","13.18018","0.05315"
"158.40000","13.20027","0.05265"
"158.64000","13.22018","0.05230"
"158.88000","13.24021","0.05254"
"159.12000","13.26018","0.05276"
"159.36000","13.28027","0.05352"
"159.60000","13.30024","0.05278"
"159.84000","13.32021","0.05317"
"160.08000","13.34030","0.05286"
"160.32000","13.36021","0.05304"
"160.56000","13.38024","0.05259"
"160.80000","13.40021","0.05336"
"161.04000","13.42024","0.05307"
"161.28000","13.44021","0.05293"
"161.52000","13.46030","0.05330"
"161.76000","13.48021","0.05291"
"162.00000","13.50030","0.05317"
"162.24000","13.52027","0.05338"
"162.48000","13.54018","0.05316"
"162.72000","13.56021","0.05322"
"162.96000","13.58018","0.05348"
"163.20000","13.60027","0.05349"
"163.44000","13.62018","0.05315"
"163.68000","13.64026","0.05331"
"163.92000","13.66023","0.05286"
"164.16000","13.68026","0.05367"
"164.40000","13.70029","0.05317"
"164.64000","13.72020","0.05327"
"164.88000","13.74023","0.05369"
"165.12000","13.76014","0.05334"
"165.36000","13.78029","0.05316"
"165.60000","13.80020","0.05367"
"165.84000","13.82023","0.05365"
"166.08000","13.84020","0.05362"
"166.32000","13.86023","0.05361"
"166.56000","13.88026","0.05304"
"166.80000","13.90023","0.05412"
"167.04000","13.92026","0.05364"
"167.28000","13.94017","0.05399"
"167.52000","13.96032","0.05408"
"167.76000","13.98017","0.05363"
"168.00000","14.00020","0.05339"
"168.24000","14.02029","0.05376"
"168.48000","14.04026","0.05389"
"168.72000","14.06023","0.05406"
"168.96000","14.08026","0.05357"
"169.20000","14.10023","0.05400"
"169.44000","14.12020","0.05368"
"169.68000","14.14022","0.05372"
"169.92000","14.16020","0.05347"
"170.16000","14.18028","0.05375"
"170.40000","14.20019","0.05403"
"170.64000","14.22022","0.05416"
"170.88000","14.24019","0.05388"
"171.12000","14.26022","0.05395"
"171.36000","14.28025","0.05414"
"171.60000","14.30016","0.05433"
"171.84000","14.32025","0.05390"
"172.08000","14.34016","0.05365"
"172.32000","14.36025","0.05431"
"172.56000","14.38022","0.05445"
"172.80000","14.40025","0.05432"
"173.04000","14.42022","0.05424"
"173.28000","14.44025","0.05402"
"173.52000","14.46022","0.05439"
"173.76000","14.48019","0.05455"
"174.00000","14.50028","0.05424"
"174.24000","14.52019","0.05459"
"174.48000","14.54022","0.05453"
"174.72000","14.56025","0.05460"
"174.96000","14.58022","0.05506"
"175.20000","14.60019","0.05419"
"175.44000","14.62027","0.05487"
"175.68000","14.64025","0.05467"
"175.92000","14.66015","0.05486"
"176.16000","14.68024","0.05455"
"176.40000","14.70015","0.05455"
"176.64000","14.72018","0.05516"
"176.88000","14.74021","0.05470"
"177.12000","14.76024","0.05470"
"177.36000","14.78021","0.05446"
"177.60000","14.80024","0.05414"
"177.84000","14.82021","0.05514"
"178.08000","14.84018","0.05505"
"178.32000","14.86021","0.05465"
"178.56000","14.88018","0.05468"
"178.80000","14.90021","0.05535"
"179.04000","14.92018","0.05475"
"179.28000","14.94027","0.05507"
"179.52000","14.96018","0.05476"
"179.76000","14.98021","0.05580"
"180.00000","15.00024","0.05498"
"180.24000","15.02021","0.05483"
"180.48000","15.04024","0.05550"
"180.72000","15.06021","0.05481"
"180.96000","15.08024","0.05487"
"181.20000","15.10021","0.05507"
"181.44000","15.12024","0.05510"
"181.68000","15.14020","0.05539"
"181.92000","15.16023","0.05576"
"182.16000","15.18026","0.05542"
"182.40000","15.20017","0.05542"
"182.64000","15.22026","0.05537"
"182.88000","15.24023","0.05565"
"183.12000","15.26026","0.05566"
"183.36000","15.28017","0.05653"
"183.60000","15.30026","0.05584"
"183.84000","15.32017","0.05564"
"184.08000","15.34026","0.05433"
"184.32000","15.36029","0.05444"
"184.56000","15.38020","0.05452"
"184.80000","15.40029","0.05485"
"185.04000","15.42020","0.05447"
"185.28000","15.44023","0.05463"
"185.52000","15.46020","0.05536"
"185.76000","15.48029","0.05476"
"186.00000","15.50026","0.05549"
"186.24000","15.52029","0.05482"
"186.48000","15.54026","0.05562"
"186.72000","15.56023","0.05512"
"186.96000","15.58026","0.05555"
"187.20000","15.60023","0.05507"
"187.44000","15.62025","0.05533"
"187.68000","15.64022","0.05568"
"187.92000","15.66031","0.05592"
"188.16000","15.68022","0.05605"
"188.40000","15.70019","0.05555"
"188.64000","15.72022","0.05557"
"188.88000","15.74025","0.05583"
"189.12000","15.76028","0.05594"
"189.36000","15.78019","0.05592"
"189.60000","15.80022","0.05617"
"189.84000","15.82013","0.05648"
"190.08000","15.84028","0.05638"
"190.32000","15.86019","0.05671"
"190.56000","15.88028","0.05621"
"190.80000","15.90019","0.05650"
"191.04000","15.92022","0.05641"
"191.28000","15.94019","0.05695"
"191.52000","15.96022","0.05684"
"191.76000","15.98031","0.05673"
"192.00000","16.00016","0.05650"
"192.24000","16.02025","0.05705"
"192.48000","16.04021","0.05730"
"192.72000","16.06025","0.05761"
"192.96000","16.08022","0.05750"
"193.20000","16.10024","0.05743"
"193.44000","16.12027","0.05757"
"193.68000","16.14018","0.05826"
"193.92000","16.16027","0.05795"
"194.16000","16.18012","0.05775"
"194.40000","16.20021","0.05784"
"194.64000","16.22024","0.05872"
"194.88000","16.24021","0.05855"
"195.12000","16.26018","0.05850"
"195.36000","16.28027","0.05879"
"195.60000","16.30024","0.05837"
"195.84000","16.32021","0.05893"
"196.08000","16.34024","0.05920"
"196.32000","16.36015","0.05875"
"196.56000","16.38024","0.05942"
"196.80000","16.40021","0.05902"
"197.04000","16.42024","0.05944"
"197.28000","16.44021","0.05957"
"197.52000","16.46024","0.05986"
"197.76000","16.48021","0.05949"
"198.00000","16.50024","0.06005"
"198.24000","16.52021","0.05987"
"198.48000","16.54012","0.06037"
"198.72000","16.56027","0.06046"
"198.96000","16.58023","0.06048"
"199.20000","16.60026","0.06088"
"199.44000","16.62017","0.06131"
"199.68000","16.64026","0.06173"
"199.92000","16.66023","0.06191"
"200.16000","16.68020","0.06132"
"200.40000","16.70029","0.06169"
"200.64000","16.72014","0.06166"
"200.88000","16.74023","0.06185"
"201.12000","16.76020","0.06202"
"201.36000","16.78023","0.06208"
"201.60000","16.80020","0.06273"
"201.84000","16.82023","0.06379"
"202.08000","16.84026","0.06323"
"202.32000","16.86023","0.06363"
"202.56000","16.88026","0.06214"
"202.80000","16.90023","0.06246"
"203.04000","16.92020","0.06312"
"203.28000","16.94023","0.05740"
"203.52000","16.96026","0.05800"
"203.76000","16.98023","0.05756"
"204.00000","17.00026","0.05897"
"204.24000","17.02023","0.05861"
"204.48000","17.04020","0.05896"
"204.72000","17.06023","0.05976"
"204.96000","17.08019","0.05989"
"205.20000","17.10022","0.06033"
"205.44000","17.12025","0.06034"
"205.68000","17.14022","0.06073"
"205.92000","17.16019","0.06072"
"206.16000","17.18028","0.06174"
"206.40000","17.20025","0.06239"
"206.64000","17.22022","0.06238"
"206.88000","17.24025","0.06258"
"207.12000","17.26022","0.06320"
"207.36000","17.28025","0.06327"
"207.60000","17.30016","0.06352"
"207.84000","17.32031","0.05996"
"208.08000","17.34022","0.05795"
"208.32000","17.36031","0.05624"
"208.56000","17.38028","0.05279"
"208.80000","17.40019","0.05407"
"209.04000","17.42022","0.05426"
"209.28000","17.44025","0.05461"
"209.52000","17.46028","0.05499"
"209.76000","17.48019","0.05523"
"210.00000","17.50022","0.05511"
"210.24000","17.52019","0.05541"
"210.48000","17.54022","0.05536"
"210.72000","17.56025","0.05575"
"210.96000","17.58022","0.05594"
"211.20000","17.60024","0.05638"
"211.44000","17.62021","0.05546"
"211.68000","17.64018","0.05518"
"211.92000","17.66015","0.05503"
"212.16000","17.68030","0.05592"
"212.40000","17.70021","0.05593"
"212.64000","17.72024","0.05600"
"212.88000","17.74027","0.05625"
"213.12000","17.76024","0.05590"
"213.36000","17.78021","0.05706"
"213.60000","17.80024","0.05711"
"213.84000","17.82021","0.05642"
"214.08000","17.84024","0.05688"
"214.32000","17.86027","0.05696"
"214.56000","17.88018","0.05766"
"214.80000","17.90027","0.05739"
"215.04000","17.92024","0.05732"
"215.28000","17.94027","0.05761"
"215.52000","17.96024","0.05743"
"215.76000","17.98027","0.05770"
"216.00000","18.00024","0.05812"
"216.24000","18.02015","0.05823"
"216.48000","18.04024","0.05849"
"216.72000","18.06021","0.05814"
"216.96000","18.08023","0.05831"
"217.20000","18.10021","0.05936"
"217.44000","18.12024","0.05967"
"217.68000","18.14020","0.05938"
"217.92000","18.16017","0.05924"
"218.16000","18.18026","0.05991"
"218.40000","18.20011","0.06002"
"218.64000","18.22026","0.05978"
"218.88000","18.24023","0.05979"
"219.12000","18.26020","0.05993"
"219.36000","18.28023","0.06022"
"219.60000","18.30026","0.06032"
"219.84000","18.32023","0.06070"
"220.08000","18.34020","0.06097"
"220.32000","18.36023","0.06105"
"220.56000","18.38014","0.06123"
"220.80000","18.40023","0.06199"
"221.04000","18.42026","0.06207"
"221.28000","18.44029","0.06228"
"221.52000","18.46020","0.06231"
"221.76000","18.48029","0.06228"
"222.00000","18.50020","0.06302"
"222.24000","18.52017","0.06068"
"222.48000","18.54026","0.06077"
"222.72000","18.56017","0.06132"
"222.96000","18.58026","0.06160"
"223.20000","18.60017","0.06220"
"223.44000","18.62020","0.06196"
"223.68000","18.64022","0.06274"
"223.92000","18.66025","0.06202"
"224.16000","18.68022","0.06286"
"224.40000","18.70019","0.06361"
"224.64000","18.72028","0.06320"
"224.88000","18.74019","0.06448"
"225.12000","18.76022","0.06425"
"225.36000","18.78019","0.06465"
"225.60000","18.80028","0.06508"
"225.84000","18.82019","0.06467"
"226.08000","18.84028","0.06524"
"226.32000","18.86025","0.06520"
"226.56000","18.88022","0.06506"
"226.80000","18.90025","0.06574"
"227.04000","18.92016","0.06550"
"227.28000","18.94025","0.06656"
"227.52000","18.96022","0.06653"
"227.76000","18.98025","0.06717"
"228.00000","19.00022","0.06753"
"228.24000","19.02031","0.06780"
"228.48000","19.04022","0.06748"
"228.72000","19.06025","0.06811"
"228.96000","19.08022","0.06825"
"229.20000","19.10019","0.06898"
"229.44000","19.12021","0.06894"
"229.68000","19.14024","0.06906"
"229.92000","19.16027","0.06901"
"230.16000","19.18018","0.06911"
"230.40000","19.20027","0.06967"
"230.64000","19.22024","0.06991"
"230.88000","19.24021","0.07104"
"231.12000","19.26018","0.07086"
"231.36000","19.28021","0.07085"
"231.60000","19.30024","0.07073"
"231.84000","19.32021","0.07087"
"232.08000","19.34030","0.07040"
"232.32000","19.36015","0.07122"
"232.56000","19.38024","0.07163"
"232.80000","19.40021","0.07171"
"233.04000","19.42024","0.07215"
"233.28000","19.44027","0.07231"
"233.52000","19.46024","0.07260"
"233.76000","19.48027","0.07291"
"234.00000","19.50024","0.07281"
"234.24000","19.52027","0.07299"
"234.48000","19.54024","0.07355"
"234.72000","19.56027","0.07339"
"234.96000","19.58017","0.07367"
"235.20000","19.60020","0.07400"
"235.44000","19.62023","0.07437"
"235.68000","19.64026","0.07430"
"235.92000","19.66023","0.07463"
"236.16000","19.68020","0.07471"
"236.40000","19.70029","0.07496"
"236.64000","19.72020","0.07501"
"236.88000","19.74023","0.07509"
"237.12000","19.76020","0.07490"
"237.36000","19.78023","0.05704"
"237.60000","19.80020","0.05237"
"237.84000","19.82017","0.05150"
"238.08000","19.84026","0.05057"
"238.32000","19.86023","0.05237"
"238.56000","19.88026","0.05083"
"238.80000","19.90023","0.05248"
"239.04000","19.92026","0.05087"
"239.28000","19.94023","0.05220"
"239.52000","19.96020","0.05183"
"239.76000","19.98017","0.05230"
"240.00000","20.00026","0.05128"
"240.24000","20.02029","0.05226"
"240.48000","20.04020","0.05205"
"240.72000","20.06022","0.05254"
"240.96000","20.08014","0.05171"
"241.20000","20.10023","0.05262"
"241.44000","20.12019","0.05210"
"241.68000","20.14028","0.05220"
"241.92000","20.16025","0.05228"
"242.16000","20.18022","0.05279"
"242.40000","20.20025","0.05222"
"242.64000","20.22016","0.05256"
"242.88000","20.24025","0.05205"
"243.12000","20.26016","0.05302"
"243.36000","20.28025","0.05268"
"243.60000","20.30022","0.05245"
"243.84000","20.32019","0.05230"
"244.08000","20.34016","0.05303"
"244.32000","20.36025","0.05315"
"244.56000","20.38028","0.05323"
"244.80000","20.40019","0.05373"
"245.04000","20.42027","0.05338"
"245.28000","20.44019","0.05334"
"245.52000","20.46022","0.05299"
"245.76000","20.48019","0.05333"
"246.00000","20.50022","0.05354"
"246.24000","20.52024","0.05337"
"246.48000","20.54022","0.05375"
"246.72000","20.56025","0.05345"
"246.96000","20.58022","0.05340"
"247.20000","20.60030","0.05370"
"247.44000","20.62021","0.05363"
"247.68000","20.64018","0.05395"
"247.92000","20.66021","0.05462"
"248.16000","20.68024","0.05393"
"248.40000","20.70021","0.05388"
"248.64000","20.72024","0.05437"
"248.88000","20.74027","0.05399"
"249.12000","20.76018","0.05457"
"249.36000","20.78027","0.05360"
"249.60000","20.80018","0.05407"
"249.84000","20.82027","0.05445"
"250.08000","20.84018","0.05434"
"250.32000","20.86027","0.05494"
"250.56000","20.88018","0.05462"
"250.80000","20.90027","0.05462"
"251.04000","20.92030","0.05496"
"251.28000","20.94021","0.05462"
"251.52000","20.96024","0.05505"
"251.76000","20.98021","0.05464"
"252.00000","21.00024","0.05464"
"252.24000","21.02015","0.05517"
"252.48000","21.04029","0.05467"
"252.72000","21.06020","0.05515"
"252.96000","21.08023","0.05500"
"253.20000","21.10026","0.05528"
"253.44000","21.12024","0.05513"
"253.68000","21.14026","0.05517"
"253.92000","21.16017","0.05602"
"254.16000","21.18020","0.05547"
"254.40000","21.20017","0.05540"
"254.64000","21.22026","0.05530"
"254.88000","21.24023","0.05571"
"255.12000","21.26026","0.05603"
"255.36000","21.28023","0.05556"
"255.60000","21.30020","0.05520"
"255.84000","21.32023","0.05580"
"256.08000","21.34020","0.05597"
"256.32000","21.36023","0.05549"
"256.56000","21.38014","0.05552"
"256.80000","21.40023","0.05551"
"257.04000","21.42020","0.05550"
"257.28000","21.44023","0.05552"
"257.52000","21.46026","0.05586"
"257.76000","21.48023","0.05548"
"258.00000","21.50025","0.05594"
"258.24000","21.52023","0.05551"
"258.48000","21.54025","0.05549"
"258.72000","21.56017","0.05633"
"258.96000","21.58019","0.05595"
"259.20000","21.60022","0.05551"
"259.44000","21.62025","0.05591"
"259.68000","21.64028","0.05589"
"259.92000","21.66025","0.05546"
"260.16000","21.68022","0.05621"
"260.40000","21.70019","0.05614"
"260.64000","21.72028","0.05620"
"260.88000","21.74013","0.05575"
"261.12000","21.76022","0.05540"
"261.36000","21.78019","0.05589"
"261.60000","21.80022","0.05584"
"261.84000","21.82019","0.05592"
"262.08000","21.84022","0.05514"
"262.32000","21.86019","0.05579"
"262.56000","21.88022","0.05573"
"262.80000","21.90025","0.05618"
"263.04000","21.92016","0.05613"
"263.28000","21.94025","0.05618"
"263.52000","21.96022","0.05597"
"263.76000","21.98025","0.05648"
"264.00000","22.00022","0.05640"
"264.24000","22.02025","0.05629"
"264.48000","22.04022","0.05660"
"264.72000","22.06018","0.05658"
"264.96000","22.08027","0.05630"
"265.20000","22.10018","0.05573"
"265.44000","22.12027","0.05620"
"265.68000","22.14024","0.05621"
"265.92000","22.16021","0.05619"
"266.16000","22.18018","0.05616"
"266.40000","22.20027","0.05594"
"266.64000","22.22024","0.05656"
"266.88000","22.24021","0.05567"
"267.12000","22.26030","0.05586"
"267.36000","22.28015","0.05612"
"267.60000","22.30024","0.05570"
"267.84000","22.32021","0.05615"
"268.08000","22.34030","0.05610"
"268.32000","22.36021","0.05635"
"268.56000","22.38024","0.05625"
"268.80000","22.40021","0.05652"
"269.04000","22.42018","0.05618"
"269.28000","22.44027","0.05670"
"269.52000","22.46018","0.05664"
"269.76000","22.48021","0.05642"
"270.00000","22.50018","0.05686"
"270.24000","22.52027","0.05749"
"270.48000","22.54023","0.05670"
"270.72000","22.56026","0.05676"
"270.96000","22.58023","0.05697"
"271.20000","22.60020","0.05680"
"271.44000","22.62029","0.05564"
"271.68000","22.64020","0.05600"
"271.92000","22.66023","0.05641"
"272.16000","22.68020","0.05580"
"272.40000","22.70029","0.05569"
"272.64000","22.72020","0.05569"
"272.88000","22.74023","0.05552"
"273.12000","22.76020","0.05572"
"273.36000","22.78017","0.05613"
"273.60000","22.80020","0.05563"
"273.84000","22.82017","0.05592"
"274.08000","22.84026","0.05591"
"274.32000","22.86017","0.05598"
"274.56000","22.88026","0.05563"
"274.80000","22.90017","0.05587"
"275.04000","22.92026","0.05606"
"275.28000","22.94023","0.05605"
"275.52000","22.96026","0.05647"
"275.76000","22.98023","0.05667"
"276.00000","23.00020","0.05662"
"276.24000","23.02023","0.05684"
"276.48000","23.04014","0.05652"
"276.72000","23.06028","0.05678"
"276.96000","23.08020","0.05679"
"277.20000","23.10028","0.05697"
"277.44000","23.12025","0.05681"
"277.68000","23.14022","0.05715"
"277.92000","23.16025","0.05667"
"278.16000","23.18022","0.05615"
"278.40000","23.20025","0.05622"
"278.64000","23.22022","0.05652"
"278.88000","23.24031","0.05609"
"279.12000","23.26022","0.05665"
"279.36000","23.28025","0.05640"
"279.60000","23.30022","0.05678"
"279.84000","23.32025","0.05726"
"280.08000","23.34022","0.05664"
"280.32000","23.36025","0.05693"
"280.56000","23.38022","0.05716"
"280.80000","23.40019","0.05699"
"281.04000","23.42028","0.05738"
"281.28000","23.44019","0.05683"
"281.52000","23.46028","0.05744"
"281.76000","23.48025","0.05737"
"282.00000","23.50028","0.05740"
"282.24000","23.52024","0.05671"
"282.48000","23.54021","0.05719"
"282.72000","23.56025","0.05694"
"282.96000","23.58016","0.05716"
"283.20000","23.60024","0.05724"
"283.44000","23.62021","0.05702"
"283.68000","23.64024","0.05616"
"283.92000","23.66021","0.05682"
"284.16000","23.68024","0.05212"
"284.40000","23.70015","0.05346"
"284.64000","23.72018","0.05546"
"284.88000","23.74027","0.05345"
"285.12000","23.76018","0.05605"
"285.36000","23.78027","0.05378"
"285.60000","23.80018","0.05461"
"285.84000","23.82027","0.05513"
"286.08000","23.84024","0.05414"
"286.32000","23.86021","0.05586"
"286.56000","23.88018","0.05421"
"286.80000","23.90015","0.05567"
"287.04000","23.92030","0.05570"
"287.28000","23.94020","0.05484"
"287.52000","23.96024","0.05664"
"287.76000","23.98021","0.05471"
"288.00000","24.00024","0.05576"
"288.24000","24.02021","0.05596"
"288.48000","24.04029","0.05493"
"288.72000","24.06021","0.05644"
"288.96000","24.08024","0.05555"
"289.20000","24.10026","0.05667"
"289.44000","24.12017","0.05638"
"289.68000","24.14026","0.05627"
"289.92000","24.16023","0.05637"
"290.16000","24.18026","0.05601"
"290.40000","24.20023","0.05691"
"290.64000","24.22026","0.05692"
"290.88000","24.24017","0.05708"
"291.12000","24.26020","0.05685"
"291.36000","24.28023","0.05667"
"291.60000","24.30020","0.05686"
"291.84000","24.32023","0.05650"
"292.08000","24.34020","0.05680"
"292.32000","24.36023","0.05662"
"292.56000","24.38020","0.05687"
"292.80000","24.40029","0.05653"
"293.04000","24.42020","0.05676"
"293.28000","24.44023","0.05682"
"293.52000","24.46026","0.05678"
"293.76000","24.48017","0.05670"
"294.00000","24.50026","0.05625"
"294.24000","24.52017","0.05696"
"294.48000","24.54026","0.05688"
"294.72000","24.56022","0.05713"
"294.96000","24.58019","0.05654"
"295.20000","24.60016","0.05693"
"295.44000","24.62019","0.05741"
"295.68000","24.64028","0.05757"
"295.92000","24.66019","0.05773"
"296.16000","24.68028","0.05811"
"296.40000","24.70019","0.05742"
"296.64000","24.72022","0.05716"
"296.88000","24.74019","0.05758"
"297.12000","24.76028","0.05819"
"297.36000","24.78025","0.05790"
"297.60000","24.80022","0.05811"
"297.84000","24.82025","0.05771"
"298.08000","24.84022","0.05877"
"298.32000","24.86025","0.05867"
"298.56000","24.88016","0.05830"
"298.80000","24.90025","0.05819"
"299.04000","24.92022","0.05834"
"299.28000","24.94025","0.05907"
"299.52000","24.96022","0.05861"
"299.76000","24.98019","0.05904"
"300.00000","25.00022","0.05774"
"300.24000","25.02024","0.05876"
"300.48000","25.04027","0.05831"
"300.72000","25.06019","0.05831"
"300.96000","25.08027","0.05839"
"301.20000","25.10012","0.05814"
"301.44000","25.12028","0.05873"
"301.68000","25.14024","0.05934"
"301.92000","25.16027","0.05791"
"302.16000","25.18030","0.05881"
"302.40000","25.20021","0.05868"
"302.64000","25.22024","0.05869"
"302.88000","25.24015","0.05875"
"303.12000","25.26024","0.05947"
"303.36000","25.28021","0.06004"
"303.60000","25.30024","0.05911"
"303.84000","25.32021","0.05932"
"304.08000","25.34024","0.05940"
"304.32000","25.36021","0.05973"
"304.56000","25.38024","0.05984"
"304.80000","25.40027","0.06037"
"305.04000","25.42018","0.06002"
"305.28000","25.44027","0.05988"
"305.52000","25.46018","0.06043"
"305.76000","25.48021","0.05991"
"306.00000","25.50018","0.06050"
"306.24000","25.52027","0.05996"
"306.48000","25.54024","0.06068"
"306.72000","25.56020","0.06097"
"306.96000","25.58023","0.06073"
"307.20000","25.60020","0.06097"
"307.44000","25.62029","0.06083"
"307.68000","25.64021","0.06045"
"307.92000","25.66023","0.06013"
"308.16000","25.68020","0.06099"
"308.40000","25.70023","0.06013"
"308.64000","25.72020","0.06101"
"308.88000","25.74023","0.06014"
"309.12000","25.76026","0.06076"
"309.36000","25.78017","0.06071"
"309.60000","25.80026","0.06065"
"309.84000","25.82017","0.06117"
"310.08000","25.84026","0.06127"
"310.32000","25.86017","0.06107"
"310.56000","25.88026","0.06210"
"310.80000","25.90023","0.06145"
"311.04000","25.92026","0.06169"
"311.28000","25.94023","0.06188"
"311.52000","25.96014","0.06220"
"311.76000","25.98023","0.06257"
"312.00000","26.00020","0.06270"
"312.24000","26.02023","0.06246"
"312.48000","26.04020","0.06297"
"312.72000","26.06022","0.06285"
"312.96000","26.08019","0.06275"
"313.20000","26.10028","0.06321"
"313.44000","26.12025","0.06350"
"313.68000","26.14017","0.06365"
"313.92000","26.16025","0.06354"
"314.16000","26.18016","0.06407"
"314.40000","26.20019","0.06366"
"314.64000","26.22016","0.06407"
"314.88000","26.24031","0.06410"
"315.12000","26.26022","0.06494"
"315.36000","26.28025","0.06484"
"315.60000","26.30022","0.06424"
"315.84000","26.32019","0.06466"
"316.08000","26.34022","0.06436"
"316.32000","26.36019","0.06574"
"316.56000","26.38022","0.06489"
"316.80000","26.40019","0.06556"
"317.04000","26.42028","0.06581"
"317.28000","26.44019","0.06526"
"317.52000","26.46021","0.06617"
"317.76000","26.48025","0.06576"
"318.00000","26.50022","0.06641"
"318.24000","26.52030","0.06644"
"318.48000","26.54016","0.06646"
"318.72000","26.56024","0.06668"
"318.96000","26.58015","0.06688"
"319.20000","26.60031","0.06688"
"319.44000","26.62021","0.06714"
"319.68000","26.64024","0.06707"
"319.92000","26.66021","0.06759"
"320.16000","26.68018","0.06768"
"320.40000","26.70027","0.06790"
"320.64000","26.72024","0.06799"
"320.88000","26.74021","0.06793"
"321.12000","26.76018","0.06848"
"321.36000","26.78027","0.06846"
"321.60000","26.80018","0.06877"
"321.84000","26.82027","0.06879"
"322.08000","26.84024","0.06909"
"322.32000","26.86021","0.06917"
"322.56000","26.88024","0.06943"
"322.80000","26.90021","0.06970"
"323.04000","26.92024","0.06970"
"323.28000","26.94021","0.07035"
"323.52000","26.96024","0.07065"
"323.76000","26.98027","0.07055"
"324.00000","27.00023","0.07096"
"324.24000","27.02020","0.07085"
"324.48000","27.04018","0.07145"
"324.72000","27.06020","0.07075"
"324.96000","27.08023","0.07146"
"325.20000","27.10020","0.07166"
"325.44000","27.12017","0.07179"
"325.68000","27.14026","0.07183"
"325.92000","27.16017","0.07201"
"326.16000","27.18020","0.07236"
"326.40000","27.20023","0.07244"
"326.64000","27.22026","0.07313"
"326.88000","27.24023","0.07313"
"327.12000","27.26020","0.07328"
"327.36000","27.28023","0.07325"
"327.60000","27.30014","0.07306"
"327.84000","27.32029","0.07376"
"328.08000","27.34026","0.07362"
"328.32000","27.36023","0.07348"
"328.56000","27.38020","0.07371"
"328.80000","27.40023","0.07383"
"329.04000","27.42020","0.07426"
"329.28000","27.44023","0.07448"
"329.52000","27.46026","0.07440"
"329.76000","27.48017","0.07444"
"330.00000","27.50026","0.07464"
"330.24000","27.52023","0.07518"
"330.48000","27.54025","0.07497"
"330.72000","27.56023","0.07513"
"330.96000","27.58020","0.07522"
"331.20000","27.60028","0.07538"
"331.44000","27.62020","0.07537"
"331.68000","27.64029","0.07576"
"331.92000","27.66013","0.07572"
"332.16000","27.68022","0.07594"
"332.40000","27.70019","0.07618"
"332.64000","27.72022","0.07634"
"332.88000","27.74025","0.07653"
"333.12000","27.76028","0.07653"
"333.36000","27.78019","0.07681"
"333.60000","27.80016","0.07676"
"333.84000","27.82025","0.07701"
"334.08000","27.84016","0.07528"
"334.32000","27.86025","0.06952"
"334.56000","27.88022","0.06780"
"334.80000","27.90025","0.06446"
"335.04000","27.92022","0.06275"
"335.28000","27.94025","0.06171"
"335.52000","27.96022","0.06219"
"335.76000","27.98019","0.06139"
"336.00000","28.00028","0.06187"
"336.24000","28.02012","0.05982"
"336.48000","28.04028","0.06349"
"336.72000","28.06019","0.06187"
"336.96000","28.08027","0.06349"
"337.20000","28.10024","0.06342"
"337.44000","28.12027","0.06339"
"337.68000","28.14025","0.06317"
"337.92000","28.16015","0.06196"
"338.16000","28.18024","0.06406"
"338.40000","28.20015","0.06295"
"338.64000","28.22024","0.06418"
"338.88000","28.24021","0.06432"
"339.12000","28.26024","0.06447"
"339.36000","28.28021","0.06565"
"339.60000","28.30024","0.06366"
"339.84000","28.32027","0.06635"
"340.08000","28.34018","0.06545"
"340.32000","28.36027","0.06506"
"340.56000","28.38018","0.06659"
"340.80000","28.40021","0.06632"
"341.04000","28.42024","0.06713"
"341.28000","28.44027","0.06625"
"341.52000","28.46018","0.06729"
"341.76000","28.48021","0.06770"
"342.00000","28.50024","0.06748"
"342.24000","28.52021","0.06849"
"342.48000","28.54024","0.06760"
"342.72000","28.56021","0.06840"
"342.96000","28.58030","0.06843"
"343.20000","28.60026","0.06858"
"343.44000","28.62023","0.06885"
"343.68000","28.64014","0.06908"
"343.92000","28.66023","0.06923"
"344.16000","28.68026","0.06974"
"344.40000","28.70023","0.06977"
"344.64000","28.72020","0.07038"
"344.88000","28.74023","0.07026"
"345.12000","28.76026","0.07056"
"345.36000","28.78017","0.07033"
"345.60000","28.80026","0.07051"
"345.84000","28.82017","0.07137"
"346.08000","28.84026","0.07082"
"346.32000","28.86023","0.07114"
"346.56000","28.88020","0.07132"
"346.80000","28.90023","0.07169"
"347.04000","28.92020","0.07164"
"347.28000","28.94029","0.07160"
"347.52000","28.96014","0.07221"
"347.76000","28.98022","0.07236"
"348.00000","29.00019","0.07269"
"348.24000","29.02023","0.07284"
"348.48000","29.04026","0.07283"
"348.72000","29.06023","0.07327"
"348.96000","29.08025","0.07254"
"349.20000","29.10022","0.07304"
"349.44000","29.12025","0.07333"
"349.68000","29.14016","0.07344"
"349.92000","29.16025","0.07349"
"350.16000","29.18022","0.07349"
"350.40000","29.20031","0.07394"
"350.64000","29.22022","0.07417"
"350.88000","29.24025","0.07450"
"351.12000","29.26016","0.07441"
"351.36000","29.28019","0.07447"
"351.60000","29.30028","0.07465"
"351.84000","29.32019","0.07466"
"352.08000","29.34022","0.07479"
"352.32000","29.36019","0.07457"
"352.56000","29.38022","0.07451"
"352.80000","29.40025","0.07286"
"353.04000","29.42028","0.06299"
"353.28000","29.44025","0.04536"
"353.52000","29.46028","0.04735"
"353.76000","29.48025","0.04613"
"354.00000","29.50015","0.04601"
"354.24000","29.52024","0.04482"
"354.48000","29.54021","0.04500"
"354.72000","29.56024","0.04498"
"354.96000","29.58021","0.04537"
"355.20000","29.60024","0.04479"
"355.44000","29.62021","0.04536"
"355.52600","29.62739","0.04494"