File: Force_trajectories/170108_2/Specimen_RawData_8.csv
End date,"1/8/2017"
Specimen label,"9BT_74_2"
Maximum Load,"0.16759",N

Time,Extension,Load
(s),(mm),(N)
"0.00000","17.88723","0.05831"
"0.05400","17.88825","0.05823"
"0.10800","17.89124","0.05871"
"0.16200","17.89614","0.05969"
"0.21600","17.90218","0.06016"
"0.27000","17.90828","0.06072"
"0.32400","17.91378","0.06172"
"0.37800","17.91880","0.06212"
"0.43200","17.92347","0.06303"
"0.48600","17.92801","0.06341"
"0.54000","17.93244","0.06423"
"0.59400","17.93692","0.06436"
"0.64800","17.94140","0.06499"
"0.70200","17.94589","0.06553"
"0.75600","17.95037","0.06609"
"0.81000","17.95492","0.06642"
"0.86400","17.95946","0.06666"
"0.91800","17.96388","0.06757"
"0.97200","17.96843","0.06752"
"1.02600","17.97285","0.06813"
"1.08000","17.97734","0.06847"
"1.13400","17.98188","0.06944"
"1.18800","17.98637","0.06962"
"1.24200","17.99085","0.06991"
"1.29600","17.99539","0.07021"
"1.35000","17.99988","0.07073"
"1.40400","18.00442","0.07107"
"1.45800","18.00891","0.07118"
"1.51200","18.01339","0.07175"
"1.56600","18.01788","0.07211"
"1.62000","18.02230","0.07247"
"1.67400","18.02678","0.07262"
"1.72800","18.03139","0.07299"
"1.78200","18.03587","0.07286"
"1.83600","18.04041","0.07339"
"1.89000","18.04490","0.07446"
"1.94400","18.04938","0.07413"
"1.99800","18.05393","0.07418"
"2.05200","18.05841","0.07442"
"2.10600","18.06290","0.07445"
"2.16000","18.06738","0.07489"
"2.21400","18.07180","0.07480"
"2.26800","18.07635","0.07483"
"2.32200","18.08083","0.07521"
"2.37600","18.08538","0.07522"
"2.43000","18.08998","0.07481"
"2.48400","18.09441","0.07465"
"2.53800","18.09889","0.07492"
"2.59200","18.10337","0.07514"
"2.64600","18.10786","0.07475"
"2.70000","18.11234","0.07414"
"2.75400","18.11683","0.07411"
"2.80800","18.12125","0.07437"
"2.86200","18.12585","0.07414"
"2.91600","18.13034","0.07390"
"2.97000","18.13488","0.07359"
"3.02400","18.13937","0.07334"
"3.07800","18.14391","0.07363"
"3.13200","18.14840","0.07423"
"3.18600","18.15288","0.07464"
"3.24000","18.15730","0.07425"
"3.29400","18.16185","0.07379"
"3.34800","18.16627","0.07341"
"3.40200","18.17082","0.07332"
"3.45600","18.17536","0.07358"
"3.51000","18.17990","0.07365"
"3.56400","18.18445","0.07349"
"3.61800","18.18893","0.07281"
"3.67200","18.19336","0.07285"
"3.72600","18.19790","0.07314"
"3.78000","18.20233","0.07332"
"3.83400","18.20681","0.07385"
"3.88800","18.21129","0.07365"
"3.94200","18.21578","0.07375"
"3.99600","18.22038","0.07366"
"4.05000","18.22493","0.07320"
"4.10400","18.22941","0.07357"
"4.15800","18.23389","0.07418"
"4.21200","18.23838","0.07462"
"4.26600","18.24286","0.07461"
"4.32000","18.24735","0.07453"
"4.37400","18.25183","0.07477"
"4.42800","18.25632","0.07456"
"4.48200","18.26086","0.07470"
"4.53600","18.26534","0.07496"
"4.59000","18.26983","0.07509"
"4.64400","18.27431","0.07492"
"4.69800","18.27886","0.07513"
"4.75200","18.28340","0.07544"
"4.80600","18.28782","0.07544"
"4.86000","18.29231","0.07574"
"4.91400","18.29679","0.07582"
"4.96800","18.30128","0.07570"
"5.02200","18.30588","0.07570"
"5.07600","18.31030","0.07585"
"5.13000","18.31485","0.07608"
"5.18400","18.31933","0.07648"
"5.23800","18.32388","0.07650"
"5.29200","18.32842","0.07656"
"5.34600","18.33285","0.07654"
"5.40000","18.33727","0.07649"
"5.45400","18.34182","0.07662"
"5.50800","18.34630","0.07686"
"5.56200","18.35084","0.07714"
"5.61600","18.35533","0.07724"
"5.67000","18.35987","0.07721"
"5.72400","18.36441","0.07740"
"5.77800","18.36890","0.07746"
"5.83200","18.37338","0.07741"
"5.88600","18.37787","0.07755"
"5.94000","18.38229","0.07740"
"5.99400","18.38684","0.07779"
"6.04800","18.39132","0.07791"
"6.10200","18.39580","0.07830"
"6.15600","18.40035","0.07772"
"6.21000","18.40483","0.07775"
"6.26400","18.40932","0.07790"
"6.31800","18.41386","0.07745"
"6.37200","18.41835","0.07791"
"6.42600","18.42289","0.07846"
"6.48000","18.42731","0.07833"
"6.53400","18.43180","0.07851"
"6.58800","18.43634","0.07866"
"6.64200","18.44083","0.07878"
"6.69600","18.44531","0.07895"
"6.75000","18.44985","0.07900"
"6.80400","18.45434","0.07916"
"6.85800","18.45888","0.07896"
"6.91200","18.46337","0.07917"
"6.96600","18.46785","0.07955"
"7.02000","18.47233","0.07945"
"7.07400","18.47682","0.07973"
"7.12800","18.48124","0.07989"
"7.18200","18.48585","0.07972"
"7.23600","18.49033","0.07979"
"7.29000","18.49488","0.08022"
"7.34400","18.49936","0.08078"
"7.39800","18.50385","0.08107"
"7.45200","18.50839","0.08114"
"7.50600","18.51287","0.08112"
"7.56000","18.51736","0.08136"
"7.61400","18.52184","0.08136"
"7.66800","18.52627","0.08228"
"7.72200","18.53081","0.08238"
"7.77600","18.53535","0.08222"
"7.83000","18.53990","0.08279"
"7.88400","18.54438","0.08262"
"7.93800","18.54886","0.08340"
"7.99200","18.55335","0.08401"
"8.04600","18.55783","0.08418"
"8.10000","18.56238","0.08406"
"8.15400","18.56680","0.08421"
"8.20800","18.57129","0.08473"
"8.26200","18.57583","0.08510"
"8.31600","18.58032","0.08563"
"8.37000","18.58492","0.08566"
"8.42400","18.58934","0.08610"
"8.47800","18.59389","0.08616"
"8.53200","18.59837","0.08693"
"8.58600","18.60286","0.08806"
"8.64000","18.60734","0.08875"
"8.69400","18.61182","0.08888"
"8.74800","18.61637","0.08934"
"8.80200","18.62085","0.08955"
"8.85600","18.62539","0.08985"
"8.91000","18.62988","0.09021"
"8.96400","18.63430","0.09101"
"9.01800","18.63885","0.09082"
"9.07200","18.64333","0.09048"
"9.12600","18.64782","0.09110"
"9.18000","18.65236","0.09149"
"9.23400","18.65679","0.09192"
"9.28800","18.66133","0.09195"
"9.34200","18.66582","0.09190"
"9.39600","18.67030","0.09304"
"9.45000","18.67484","0.09347"
"9.50400","18.67933","0.09431"
"9.55800","18.68387","0.09530"
"9.61200","18.68835","0.09542"
"9.66600","18.69278","0.09591"
"9.72000","18.69732","0.09638"
"9.77400","18.70181","0.09623"
"9.82800","18.70629","0.09671"
"9.88200","18.71083","0.09760"
"9.93600","18.71538","0.09852"
"9.99000","18.71986","0.09890"
"10.04400","18.72441","0.09929"
"10.09800","18.72889","0.09929"
"10.15200","18.73338","0.10059"
"10.20600","18.73786","0.10071"
"10.26000","18.74228","0.10208"
"10.31400","18.74683","0.10202"
"10.36800","18.75131","0.10329"
"10.42200","18.75586","0.10332"
"10.47600","18.76040","0.10356"
"10.53000","18.76488","0.10446"
"10.58400","18.76937","0.10508"
"10.63800","18.77385","0.10534"
"10.69200","18.77840","0.10556"
"10.74600","18.78288","0.10748"
"10.80000","18.78731","0.10781"
"10.85400","18.79179","0.10683"
"10.90800","18.79633","0.10750"
"10.96200","18.80082","0.10919"
"11.01600","18.80536","0.10943"
"11.07000","18.80991","0.10984"
"11.12400","18.81433","0.10943"
"11.17800","18.81888","0.11055"
"11.23200","18.82330","0.11086"
"11.28600","18.82778","0.11171"
"11.34000","18.83233","0.11210"
"11.39400","18.83681","0.11219"
"11.44800","18.84130","0.11195"
"11.50200","18.84584","0.11426"
"11.55600","18.85038","0.11360"
"11.61000","18.85487","0.11487"
"11.66400","18.85935","0.11556"
"11.71800","18.86384","0.11652"
"11.77200","18.86838","0.11670"
"11.82600","18.87286","0.11799"
"11.88000","18.87735","0.11823"
"11.93400","18.88183","0.11869"
"11.98800","18.88632","0.11905"
"12.04200","18.89080","0.11963"
"12.09600","18.89535","0.11992"
"12.15000","18.89989","0.12109"
"12.20400","18.90438","0.12234"
"12.25800","18.90892","0.12265"
"12.31200","18.91334","0.12335"
"12.36600","18.91789","0.12477"
"12.42000","18.92231","0.12502"
"12.47400","18.92680","0.12560"
"12.52800","18.93128","0.12683"
"12.58200","18.93582","0.12710"
"12.63600","18.94037","0.12805"
"12.69000","18.94485","0.12811"
"12.74400","18.94939","0.12931"
"12.79800","18.95382","0.12892"
"12.85200","18.95830","0.12978"
"12.90600","18.96285","0.13052"
"12.96000","18.96727","0.13093"
"13.01400","18.97176","0.13153"
"13.06800","18.97636","0.13232"
"13.12200","18.98079","0.13251"
"13.17600","18.98539","0.13283"
"13.23000","18.98987","0.13310"
"13.28400","18.99436","0.13066"
"13.33800","18.99890","0.13074"
"13.39200","19.00339","0.13037"
"13.44600","19.00781","0.12999"
"13.50000","19.01235","0.13193"
"13.55400","19.01678","0.13261"
"13.60800","19.02132","0.13259"
"13.66200","19.02581","0.13331"
"13.71600","19.03029","0.13367"
"13.77000","19.03483","0.13417"
"13.82400","19.03932","0.13457"
"13.87800","19.04386","0.13470"
"13.93200","19.04835","0.13509"
"13.98600","19.05277","0.13511"
"14.04000","19.05732","0.13182"
"14.09400","19.06180","0.12778"
"14.14800","19.06628","0.12583"
"14.20200","19.07089","0.12711"
"14.25600","19.07537","0.12739"
"14.31000","19.07986","0.12764"
"14.36400","19.08440","0.12805"
"14.41800","19.08888","0.12784"
"14.47200","19.09337","0.12850"
"14.52600","19.09785","0.12951"
"14.58000","19.10228","0.13055"
"14.63400","19.10682","0.13060"
"14.68800","19.11131","0.13214"
"14.74200","19.11585","0.13271"
"14.79600","19.12033","0.13269"
"14.85000","19.12482","0.13205"
"14.90400","19.12942","0.13192"
"14.95800","19.13391","0.13273"
"15.01200","19.13833","0.13330"
"15.06600","19.14288","0.13379"
"15.12000","19.14730","0.13312"
"15.17400","19.15184","0.13328"
"15.22800","19.15633","0.13168"
"15.28200","19.16087","0.13039"
"15.33600","19.16541","0.10606"
"15.39000","19.16984","0.10312"
"15.44400","19.17438","0.10581"
"15.49800","19.17887","0.10666"
"15.55200","19.18341","0.10592"
"15.60600","19.18784","0.10433"
"15.66000","19.19232","0.10332"
"15.71400","19.19680","0.10391"
"15.76800","19.20129","0.10338"
"15.82200","19.20583","0.10484"
"15.87600","19.21038","0.10649"
"15.93000","19.21486","0.10830"
"15.98400","19.21935","0.10876"
"16.03800","19.22383","0.10864"
"16.09200","19.22837","0.10785"
"16.14600","19.23286","0.10784"
"16.20000","19.23734","0.10774"
"16.25400","19.24177","0.10932"
"16.30800","19.24631","0.11180"
"16.36200","19.25085","0.11328"
"16.41600","19.25540","0.11485"
"16.47000","19.25988","0.11310"
"16.52400","19.26437","0.11220"
"16.57800","19.26885","0.11150"
"16.63200","19.27340","0.11235"
"16.68600","19.27782","0.11362"
"16.74000","19.28236","0.11583"
"16.79400","19.28685","0.11897"
"16.84800","19.29133","0.11856"
"16.90200","19.29588","0.11746"
"16.95600","19.30036","0.11664"
"17.01000","19.30490","0.11655"
"17.06400","19.30945","0.11750"
"17.11800","19.31393","0.11832"
"17.17200","19.31836","0.12085"
"17.22600","19.32284","0.12306"
"17.28000","19.32733","0.12222"
"17.33400","19.33181","0.12121"
"17.38800","19.33629","0.12055"
"17.44200","19.34084","0.12037"
"17.49600","19.34538","0.12174"
"17.55000","19.34986","0.12431"
"17.60400","19.35435","0.12532"
"17.65800","19.35889","0.12608"
"17.71200","19.36332","0.12627"
"17.76600","19.36786","0.12507"
"17.82000","19.37229","0.12442"
"17.87400","19.37677","0.12462"
"17.92800","19.38138","0.12631"
"17.98200","19.38586","0.12776"
"18.03600","19.39034","0.12930"
"18.09000","19.39489","0.12971"
"18.14400","19.39937","0.13019"
"18.19800","19.40392","0.12882"
"18.25200","19.40834","0.12762"
"18.30600","19.41282","0.12870"
"18.36000","19.41737","0.12970"
"18.41400","19.42179","0.13169"
"18.46800","19.42634","0.13244"
"18.52200","19.43088","0.12123"
"18.57600","19.43530","0.12094"
"18.63000","19.43985","0.11767"
"18.68400","19.44433","0.11737"
"18.73800","19.44882","0.11758"
"18.79200","19.45336","0.11058"
"18.84600","19.45785","0.10755"
"18.90000","19.46227","0.10366"
"18.95400","19.46681","0.10409"
"19.00800","19.47130","0.10559"
"19.06200","19.47590","0.10882"
"19.11600","19.48039","0.10961"
"19.17000","19.48481","0.10699"
"19.22400","19.48936","0.10549"
"19.27800","19.49384","0.10759"
"19.33200","19.49838","0.11092"
"19.38600","19.50281","0.11358"
"19.44000","19.50735","0.11288"
"19.49400","19.51178","0.10887"
"19.54800","19.51632","0.10664"
"19.60200","19.52086","0.10838"
"19.65600","19.52541","0.11209"
"19.71000","19.52989","0.11546"
"19.76400","19.53438","0.11654"
"19.81800","19.53886","0.11359"
"19.87200","19.54341","0.11197"
"19.92600","19.54783","0.11465"
"19.98000","19.55231","0.11762"
"20.03400","19.55680","0.11857"
"20.08800","19.56134","0.11675"
"20.14200","19.56589","0.11590"
"20.19600","19.57037","0.11738"
"20.25000","19.57485","0.05500"
"20.30400","19.57934","0.05282"
"20.35800","19.58388","0.06124"
"20.41200","19.58837","0.06119"
"20.46600","19.59285","0.06061"
"20.52000","19.59733","0.05722"
"20.57400","19.60176","0.05713"
"20.62800","19.60636","0.05854"
"20.68200","19.61091","0.06137"
"20.73600","19.61539","0.06125"
"20.79000","19.61993","0.06065"
"20.84400","19.62436","0.05997"
"20.89800","19.62884","0.06255"
"20.95200","19.63339","0.06547"
"21.00600","19.63787","0.06608"
"21.06000","19.64236","0.06314"
"21.11400","19.64678","0.05859"
"21.16800","19.65133","0.05545"
"21.22200","19.65587","0.05611"
"21.27600","19.66041","0.05992"
"21.33000","19.66490","0.06559"
"21.38400","19.66938","0.06730"
"21.43800","19.67386","0.06471"
"21.49200","19.67835","0.06149"
"21.54600","19.68283","0.06022"
"21.60000","19.68732","0.06183"
"21.65400","19.69186","0.06536"
"21.70800","19.69628","0.06642"
"21.76200","19.70083","0.06631"
"21.81600","19.70543","0.06516"
"21.87000","19.70986","0.06634"
"21.92400","19.71440","0.06872"
"21.97800","19.71889","0.06955"
"22.03200","19.72331","0.06817"
"22.08600","19.72780","0.06472"
"22.14000","19.73228","0.06286"
"22.19400","19.73676","0.06358"
"22.24800","19.74137","0.06741"
"22.30200","19.74585","0.07071"
"22.35600","19.75039","0.07139"
"22.41000","19.75488","0.06917"
"22.46400","19.75937","0.06620"
"22.51800","19.76391","0.06476"
"22.57200","19.76833","0.06629"
"22.62600","19.77282","0.06885"
"22.68000","19.77736","0.07075"
"22.73400","19.78179","0.07030"
"22.78800","19.78633","0.06978"
"22.84200","19.79081","0.07070"
"22.89600","19.79536","0.07100"
"22.95000","19.79990","0.07163"
"23.00400","19.80439","0.07073"
"23.05800","19.80887","0.06944"
"23.11200","19.81335","0.06851"
"23.16600","19.81784","0.06991"
"23.22000","19.82232","0.07214"
"23.27400","19.82681","0.07385"
"23.32800","19.83135","0.07404"
"23.38200","19.83583","0.07225"
"23.43600","19.84038","0.06989"
"23.49000","19.84486","0.06976"
"23.54400","19.84941","0.07087"
"23.59800","19.85389","0.07285"
"23.65200","19.85838","0.07427"
"23.70600","19.86280","0.07408"
"23.76000","19.86728","0.07340"
"23.81400","19.87183","0.07334"
"23.86800","19.87631","0.07361"
"23.92200","19.88086","0.07411"
"23.97600","19.88534","0.07408"
"24.03000","19.88983","0.07350"
"24.08400","19.89437","0.07351"
"24.13800","19.89885","0.07431"
"24.19200","19.90334","0.07524"
"24.24600","19.90782","0.07589"
"24.30000","19.91231","0.07561"
"24.35400","19.91679","0.07450"
"24.40800","19.92134","0.07346"
"24.46200","19.92588","0.07400"
"24.51600","19.93036","0.07502"
"24.57000","19.93485","0.07616"
"24.62400","19.93933","0.07616"
"24.67800","19.94387","0.07615"
"24.73200","19.94836","0.07579"
"24.78600","19.95284","0.07535"
"24.84000","19.95733","0.07587"
"24.89400","19.96181","0.07596"
"24.94800","19.96636","0.07590"
"25.00200","19.97084","0.07612"
"25.05600","19.97538","0.07620"
"25.11000","19.97987","0.07707"
"25.16400","19.98441","0.07722"
"25.21800","19.98890","0.07708"
"25.27200","19.99338","0.07678"
"25.32600","19.99786","0.07624"
"25.38000","20.00235","0.07614"
"25.43400","20.00683","0.07644"
"25.48800","20.01138","0.07728"
"25.54200","20.01586","0.07779"
"25.59600","20.02035","0.07776"
"25.65000","20.02483","0.07733"
"25.70400","20.02937","0.07696"
"25.75800","20.03386","0.07708"
"25.81200","20.03834","0.07744"
"25.86600","20.04283","0.07776"
"25.92000","20.04731","0.07787"
"25.97400","20.05186","0.07788"
"26.02800","20.05634","0.07802"
"26.08200","20.06088","0.07833"
"26.13600","20.06536","0.07833"
"26.19000","20.06985","0.07823"
"26.24400","20.07440","0.07786"
"26.29800","20.07882","0.07785"
"26.35200","20.08330","0.07841"
"26.40600","20.08785","0.07906"
"26.46000","20.09233","0.07945"
"26.51400","20.09682","0.07948"
"26.56800","20.10130","0.07913"
"26.62200","20.10584","0.07875"
"26.67600","20.11039","0.07872"
"26.73000","20.11481","0.07917"
"26.78400","20.11936","0.07980"
"26.83800","20.12384","0.08025"
"26.89200","20.12827","0.08039"
"26.94600","20.13281","0.08045"
"27.00000","20.13735","0.08041"
"27.05400","20.14184","0.08048"
"27.10800","20.14638","0.08050"
"27.16200","20.15087","0.08033"
"27.21600","20.15535","0.08037"
"27.27000","20.15989","0.08113"
"27.32400","20.16438","0.08204"
"27.37800","20.16886","0.08262"
"27.43200","20.17341","0.08338"
"27.48600","20.17783","0.08227"
"27.54000","20.18232","0.08177"
"27.59400","20.18686","0.08151"
"27.64800","20.19134","0.08211"
"27.70200","20.19589","0.08375"
"27.75600","20.20037","0.08431"
"27.81000","20.20486","0.08477"
"27.86400","20.20940","0.08473"
"27.91800","20.21388","0.08433"
"27.97200","20.21837","0.08452"
"28.02600","20.22279","0.08442"
"28.08000","20.22728","0.08502"
"28.13400","20.23188","0.08564"
"28.18800","20.23637","0.08600"
"28.24200","20.24091","0.08770"
"28.29600","20.24539","0.08836"
"28.35000","20.24982","0.08827"
"28.40400","20.25436","0.08727"
"28.45800","20.25885","0.08668"
"28.51200","20.26333","0.08715"
"28.56600","20.26781","0.08906"
"28.62000","20.27230","0.09023"
"28.67400","20.27678","0.09110"
"28.72800","20.28133","0.09053"
"28.78200","20.28587","0.09076"
"28.83600","20.29035","0.09016"
"28.89000","20.29484","0.09112"
"28.94400","20.29939","0.09157"
"28.99800","20.30387","0.09239"
"29.05200","20.30835","0.09203"
"29.10600","20.31284","0.09352"
"29.16000","20.31726","0.09459"
"29.21400","20.32181","0.09513"
"29.26800","20.32635","0.09480"
"29.32200","20.33089","0.09441"
"29.37600","20.33537","0.09416"
"29.43000","20.33986","0.09534"
"29.48400","20.34434","0.09702"
"29.53800","20.34889","0.09824"
"29.59200","20.35337","0.09921"
"29.64600","20.35786","0.09864"
"29.70000","20.36228","0.09791"
"29.75400","20.36677","0.09810"
"29.80800","20.37137","0.09888"
"29.86200","20.37592","0.09923"
"29.91600","20.38034","0.10150"
"29.97000","20.38488","0.10154"
"30.02400","20.38937","0.10140"
"30.07800","20.39385","0.10234"
"30.13200","20.39840","0.10323"
"30.18600","20.40282","0.10247"
"30.24000","20.40730","0.10272"
"30.29400","20.41179","0.10288"
"30.34800","20.41627","0.10346"
"30.40200","20.42088","0.10578"
"30.45600","20.42536","0.10631"
"30.51000","20.42990","0.10649"
"30.56400","20.43439","0.10642"
"30.61800","20.43881","0.10626"
"30.67200","20.44330","0.10616"
"30.72600","20.44784","0.10803"
"30.78000","20.45226","0.10898"
"30.83400","20.45681","0.10952"
"30.88800","20.46129","0.11004"
"30.94200","20.46584","0.10991"
"30.99600","20.47038","0.11115"
"31.05000","20.47487","0.11074"
"31.10400","20.47941","0.11110"
"31.15800","20.48384","0.11164"
"31.21200","20.48832","0.11312"
"31.26600","20.49280","0.11348"
"31.32000","20.49728","0.11597"
"31.37400","20.50183","0.11598"
"31.42800","20.50632","0.11524"
"31.48200","20.51086","0.11465"
"31.53600","20.51534","0.11656"
"31.59000","20.51983","0.11661"
"31.64400","20.52437","0.11915"
"31.69800","20.52886","0.12011"
"31.75200","20.53328","0.12039"
"31.80600","20.53782","0.12031"
"31.86000","20.54231","0.12058"
"31.91400","20.54679","0.12097"
"31.96800","20.55134","0.12218"
"32.02200","20.55588","0.12278"
"32.07600","20.56030","0.12394"
"32.13000","20.56491","0.12481"
"32.18400","20.56939","0.12553"
"32.23800","20.57382","0.12537"
"32.29200","20.57836","0.12637"
"32.34600","20.58285","0.12581"
"32.40000","20.58727","0.12605"
"32.45400","20.59181","0.12750"
"32.50800","20.59630","0.12840"
"32.56200","20.60084","0.12916"
"32.61600","20.60538","0.12918"
"32.67000","20.60987","0.12961"
"32.72400","20.61442","0.12973"
"32.77800","20.61890","0.12934"
"32.83200","20.62332","0.13005"
"32.88600","20.62781","0.13133"
"32.94000","20.63223","0.13223"
"32.99400","20.63684","0.13315"
"33.04800","20.64132","0.13298"
"33.10200","20.64586","0.13364"
"33.15600","20.65035","0.13322"
"33.21000","20.65489","0.13350"
"33.26400","20.65938","0.13371"
"33.31800","20.66386","0.13418"
"33.37200","20.66834","0.13474"
"33.42600","20.67283","0.13501"
"33.48000","20.67725","0.13519"
"33.53400","20.68180","0.13581"
"33.58800","20.68634","0.13538"
"33.64200","20.69082","0.13605"
"33.69600","20.69543","0.13637"
"33.75000","20.69986","0.13658"
"33.80400","20.70434","0.13696"
"33.85800","20.70888","0.13707"
"33.91200","20.71330","0.13731"
"33.96600","20.71785","0.13710"
"34.02000","20.72234","0.13723"
"34.07400","20.72682","0.13742"
"34.12800","20.73136","0.13773"
"34.18200","20.73591","0.13802"
"34.23600","20.74033","0.13796"
"34.29000","20.74487","0.13852"
"34.34400","20.74936","0.13843"
"34.39800","20.75384","0.13808"
"34.45200","20.75839","0.13863"
"34.50600","20.76281","0.13870"
"34.56000","20.76736","0.13887"
"34.61400","20.77184","0.13914"
"34.66800","20.77638","0.13930"
"34.72200","20.78093","0.13969"
"34.77600","20.78535","0.13934"
"34.83000","20.78984","0.13961"
"34.88400","20.79432","0.13994"
"34.93800","20.79881","0.14043"
"34.99200","20.80335","0.14094"
"35.04600","20.80783","0.14054"
"35.10000","20.81232","0.14107"
"35.15400","20.81680","0.14169"
"35.20800","20.82135","0.14190"
"35.26200","20.82589","0.14181"
"35.31600","20.83037","0.14175"
"35.37000","20.83486","0.14298"
"35.42400","20.83934","0.14315"
"35.47800","20.84383","0.14400"
"35.53200","20.84831","0.14411"
"35.58600","20.85285","0.14434"
"35.64000","20.85728","0.14452"
"35.69400","20.86189","0.14479"
"35.74800","20.86637","0.14521"
"35.80200","20.87085","0.14624"
"35.85600","20.87546","0.14611"
"35.91000","20.87988","0.14654"
"35.96400","20.88437","0.14709"
"36.01800","20.88891","0.14734"
"36.07200","20.89327","0.14736"
"36.12600","20.89782","0.14826"
"36.18000","20.90230","0.14895"
"36.23400","20.90684","0.14915"
"36.28800","20.91139","0.15015"
"36.34200","20.91587","0.15046"
"36.39600","20.92036","0.15121"
"36.45000","20.92484","0.15162"
"36.50400","20.92939","0.15147"
"36.55800","20.93387","0.15247"
"36.61200","20.93829","0.15259"
"36.66600","20.94278","0.15421"
"36.72000","20.94726","0.15387"
"36.77400","20.95181","0.15429"
"36.82800","20.95635","0.15480"
"36.88200","20.96090","0.15511"
"36.93600","20.96538","0.15536"
"36.99000","20.96986","0.15560"
"37.04400","20.97435","0.15659"
"37.09800","20.97883","0.15728"
"37.15200","20.98338","0.15746"
"37.20600","20.98780","0.15803"
"37.26000","20.99228","0.15868"
"37.31400","20.99683","0.15854"
"37.36800","21.00137","0.15873"
"37.42200","21.00592","0.15963"
"37.47600","21.01040","0.16029"
"37.53000","21.01489","0.16058"
"37.58400","21.01937","0.16104"
"37.63800","21.02386","0.16085"
"37.69200","21.02828","0.16165"
"37.74600","21.03282","0.16189"
"37.80000","21.03725","0.16227"
"37.85400","21.04185","0.16278"
"37.90800","21.04639","0.16348"
"37.96200","21.05088","0.16351"
"38.01600","21.05542","0.16430"
"38.07000","21.05985","0.16496"
"38.12400","21.06433","0.16456"
"38.17800","21.06887","0.16530"
"38.23200","21.07330","0.16591"
"38.28600","21.07784","0.16693"
"38.34000","21.08227","0.16680"
"38.39400","21.08675","0.16739"
"38.44800","21.09136","0.16735"
"38.50200","21.09590","0.16732"
"38.55600","21.10038","0.16037"
"38.61000","21.10493","0.01864"
"38.66400","21.10935","0.01204"
"38.71800","21.11384","0.03481"
"38.77200","21.11832","0.03826"
"38.82600","21.12281","0.04220"
"38.88000","21.12735","0.02152"
"38.93400","21.13177","0.02261"
"38.98800","21.13632","0.01393"
"39.04200","21.14086","0.01206"
"39.09600","21.14535","0.02450"
"39.15000","21.14989","0.03797"
"39.20400","21.15437","0.03458"
"39.25800","21.15880","0.04200"
"39.31200","21.16334","0.03588"
"39.36600","21.16777","0.02434"
"39.42000","21.17231","0.01618"
"39.47400","21.17679","0.01575"
"39.52800","21.18128","0.02270"
"39.58200","21.18588","0.02693"
"39.63600","21.19036","0.02944"
"39.69000","21.19485","0.03212"
"39.74400","21.19940","0.03025"
"39.79800","21.20382","0.03015"
"39.85200","21.20830","0.03771"
"39.90600","21.21285","0.03250"
"39.96000","21.21727","0.02767"
"40.01400","21.22188","0.02906"
"40.06800","21.22642","0.02688"
"40.12200","21.23084","0.02965"
"40.17600","21.23539","0.03000"
"40.23000","21.23987","0.03087"
"40.28400","21.24436","0.02595"
"40.33800","21.24884","0.02084"
"40.39200","21.25332","0.02237"
"40.44600","21.25781","0.02826"
"40.50000","21.26235","0.02886"
"40.55400","21.26684","0.03514"
"40.60800","21.27138","0.03876"
"40.66200","21.27593","0.03019"
"40.71600","21.28035","0.02845"
"40.77000","21.28489","0.02633"
"40.82400","21.28938","0.02381"
"40.87800","21.29386","0.02345"
"40.93200","21.29835","0.02544"
"40.98600","21.30283","0.02798"
"41.04000","21.30732","0.02853"
"41.09400","21.31180","0.03010"
"41.14800","21.31634","0.03326"
"41.20200","21.32089","0.03244"
"41.25600","21.32531","0.03191"
"41.31000","21.32992","0.03237"
"41.36400","21.33434","0.02839"
"41.41800","21.33882","0.02656"
"41.47200","21.34331","0.02829"
"41.52600","21.34779","0.03027"
"41.58000","21.35228","0.03049"
"41.63400","21.35682","0.02857"
"41.68800","21.36137","0.02650"
"41.74200","21.36591","0.02622"
"41.79600","21.37033","0.02880"
"41.85000","21.37488","0.03197"
"41.90400","21.37936","0.03370"
"41.95800","21.38385","0.03302"
"42.01200","21.38833","0.03095"
"42.06600","21.39281","0.02913"
"42.12000","21.39730","0.02790"
"42.17400","21.40184","0.02815"
"42.22800","21.40639","0.02796"
"42.28200","21.41087","0.02783"
"42.33600","21.41542","0.02826"
"42.39000","21.41984","0.02935"
"42.44400","21.42439","0.03178"
"42.49800","21.42887","0.03420"
"42.55200","21.43335","0.03636"
"42.60600","21.43784","0.03421"
"42.66000","21.44232","0.03086"
"42.71400","21.44681","0.02936"
"42.76800","21.45135","0.02867"
"42.82200","21.45583","0.02925"
"42.87600","21.46037","0.03016"
"42.93000","21.46492","0.03038"
"42.98400","21.46934","0.02968"
"43.03800","21.47383","0.02923"
"43.09200","21.47831","0.03011"
"43.14600","21.48280","0.03202"
"43.20000","21.48734","0.03327"
"43.25400","21.49183","0.03442"
"43.30800","21.49637","0.03207"
"43.36200","21.50092","0.03054"
"43.41600","21.50534","0.02997"
"43.47000","21.50988","0.03015"
"43.52400","21.51431","0.02994"
"43.57800","21.51879","0.02964"
"43.63200","21.52333","0.02941"
"43.68600","21.52776","0.02997"
"43.74000","21.53230","0.03155"
"43.79400","21.53679","0.03480"
"43.84800","21.54133","0.03721"
"43.90200","21.54588","0.03644"
"43.95600","21.55036","0.03360"
"44.01000","21.55484","0.03131"
"44.06400","21.55933","0.03020"
"44.11800","21.56381","0.02999"
"44.17200","21.56830","0.03047"
"44.22600","21.57278","0.03095"
"44.28000","21.57732","0.03092"
"44.33400","21.58181","0.03161"
"44.38800","21.58635","0.03277"
"44.44200","21.59084","0.03472"
"44.49600","21.59532","0.03656"
"44.55000","21.59987","0.03562"
"44.60400","21.60435","0.03270"
"44.65800","21.60884","0.03145"
"44.71200","21.61332","0.03125"
"44.76600","21.61780","0.03158"
"44.82000","21.62235","0.03208"
"44.87400","21.62689","0.03168"
"44.92800","21.63137","0.03110"
"44.98200","21.63586","0.03228"
"45.03600","21.64040","0.03469"
"45.09000","21.64489","0.03733"
"45.14400","21.64937","0.03899"
"45.19800","21.65385","0.03861"
"45.25200","21.65828","0.03486"
"45.30600","21.66276","0.03298"
"45.36000","21.66731","0.03208"
"45.41400","21.67185","0.03198"
"45.46800","21.67640","0.03168"
"45.52200","21.68088","0.03176"
"45.57600","21.68536","0.03300"
"45.63000","21.68985","0.03509"
"45.68400","21.69433","0.03817"
"45.73800","21.69882","0.04116"
"45.79200","21.70330","0.03901"
"45.84600","21.70773","0.03577"
"45.90000","21.71233","0.03342"
"45.95400","21.71681","0.03262"
"46.00800","21.72136","0.03266"
"46.06200","21.72590","0.03367"
"46.11600","21.73033","0.03452"
"46.17000","21.73487","0.03483"
"46.22400","21.73942","0.03608"
"46.27800","21.74384","0.03861"
"46.33200","21.74832","0.04049"
"46.38600","21.75275","0.04153"
"46.44000","21.75729","0.04009"
"46.49400","21.76190","0.03847"
"46.54800","21.76638","0.03600"
"46.60200","21.77092","0.03552"
"46.65600","21.77541","0.03498"
"46.71000","21.77983","0.03469"
"46.76400","21.78438","0.03460"
"46.81800","21.78880","0.03595"
"46.87200","21.79334","0.03940"
"46.92600","21.79783","0.04316"
"46.98000","21.80231","0.04498"
"47.03400","21.80686","0.04425"
"47.08800","21.81140","0.04086"
"47.14200","21.81589","0.03685"
"47.19600","21.82043","0.03569"
"47.25000","21.82485","0.03560"
"47.30400","21.82934","0.03580"
"47.35800","21.83388","0.03782"
"47.41200","21.83831","0.04045"
"47.46600","21.84285","0.04376"
"47.52000","21.84734","0.04627"
"47.57400","21.85182","0.04733"
"47.62800","21.85636","0.04564"
"47.68200","21.86085","0.04275"
"47.73600","21.86539","0.04105"
"47.79000","21.86987","0.04003"
"47.84400","21.87436","0.03976"
"47.89800","21.87878","0.04067"
"47.95200","21.88333","0.04055"
"48.00600","21.88775","0.04081"
"48.06000","21.89235","0.04427"
"48.11400","21.89684","0.04701"
"48.16800","21.90138","0.04874"
"48.22200","21.90587","0.04835"
"48.27600","21.91041","0.04592"
"48.33000","21.91490","0.04376"
"48.38400","21.91938","0.04153"
"48.43800","21.92387","0.04194"
"48.49200","21.92835","0.04091"
"48.54600","21.93283","0.04191"
"48.60000","21.93738","0.04405"
"48.65400","21.94186","0.04742"
"48.70800","21.94640","0.05046"
"48.76200","21.95089","0.05198"
"48.81600","21.95537","0.05032"
"48.87000","21.95986","0.04747"
"48.92400","21.96440","0.04598"
"48.97800","21.96883","0.04461"
"49.03200","21.97331","0.04388"
"49.08600","21.97786","0.04415"
"49.14000","21.98228","0.04654"
"49.19400","21.98688","0.04902"
"49.24800","21.99137","0.05121"
"49.30200","21.99585","0.05157"
"49.35600","22.00039","0.05226"
"49.41000","22.00488","0.05146"
"49.46400","22.00937","0.04968"
"49.51800","22.01385","0.04812"
"49.57200","22.01833","0.04754"
"49.62600","22.02282","0.04658"
"49.68000","22.02730","0.04744"
"49.73400","22.03184","0.04857"
"49.78800","22.03639","0.05032"
"49.84200","22.04081","0.05267"
"49.89600","22.04536","0.05385"
"49.95000","22.04984","0.05402"
"50.00400","22.05433","0.05370"
"50.05800","22.05881","0.05210"
"50.11200","22.06323","0.05045"
"50.16600","22.06772","0.04937"
"50.22000","22.07238","0.04934"
"50.27400","22.07687","0.04996"
"50.32800","22.08141","0.05192"
"50.38200","22.08590","0.05419"
"50.43600","22.09032","0.05562"
"50.49000","22.09492","0.05623"
"50.54400","22.09935","0.05560"
"50.59800","22.10383","0.05415"
"50.65200","22.10831","0.05299"
"50.70600","22.11280","0.05113"
"50.76000","22.11734","0.05079"
"50.81400","22.12183","0.05195"
"50.86800","22.12631","0.05318"
"50.92200","22.13085","0.05468"
"50.97600","22.13534","0.05622"
"51.03000","22.13983","0.05762"
"51.08400","22.14437","0.05749"
"51.13800","22.14879","0.05622"
"51.19200","22.15334","0.05545"
"51.24600","22.15776","0.05431"
"51.30000","22.16225","0.05381"
"51.35400","22.16685","0.05428"
"51.40800","22.17139","0.05451"
"51.46200","22.17582","0.05554"
"51.51600","22.18036","0.05705"
"51.57000","22.18485","0.05817"
"51.62400","22.18939","0.05886"
"51.67800","22.19387","0.05866"
"51.73200","22.19836","0.05784"
"51.78600","22.20284","0.05612"
"51.84000","22.20733","0.05606"
"51.89400","22.21187","0.05544"
"51.94800","22.21641","0.05575"
"52.00200","22.22090","0.05691"
"52.05600","22.22538","0.05849"
"52.11000","22.22987","0.05979"
"52.16400","22.23435","0.06110"
"52.21800","22.23884","0.06043"
"52.27200","22.24332","0.05983"
"52.32600","22.24781","0.05843"
"52.38000","22.25229","0.05780"
"52.43400","22.25683","0.05759"
"52.48800","22.26132","0.05798"
"52.54200","22.26586","0.05886"
"52.59600","22.27035","0.05980"
"52.65000","22.27489","0.06136"
"52.70400","22.27931","0.06222"
"52.75800","22.28380","0.06213"
"52.81200","22.28834","0.06169"
"52.86600","22.29283","0.06077"
"52.92000","22.29737","0.05967"
"52.97400","22.30191","0.05988"
"53.02800","22.30640","0.05988"
"53.08200","22.31088","0.06040"
"53.13600","22.31543","0.06157"
"53.19000","22.31991","0.06230"
"53.24400","22.32440","0.06330"
"53.29800","22.32882","0.06372"
"53.35200","22.33330","0.06377"
"53.40600","22.33779","0.06221"
"53.46000","22.34233","0.06188"
"53.51400","22.34688","0.06119"
"53.56800","22.35136","0.06151"
"53.62200","22.35584","0.06156"
"53.67600","22.36039","0.06253"
"53.73000","22.36487","0.06403"
"53.78400","22.36942","0.06577"
"53.83800","22.37384","0.06545"
"53.89200","22.37827","0.06542"
"53.94600","22.38281","0.06457"
"54.00000","22.38735","0.06350"
"54.05400","22.39190","0.06293"
"54.10800","22.39644","0.06301"
"54.16200","22.40081","0.06364"
"54.21600","22.40535","0.06497"
"54.27000","22.40984","0.06576"
"54.32400","22.41426","0.06671"
"54.37800","22.41886","0.06692"
"54.43200","22.42329","0.06646"
"54.48600","22.42777","0.06603"
"54.54000","22.43232","0.06546"
"54.59400","22.43680","0.06529"
"54.64800","22.44140","0.06546"
"54.70200","22.44589","0.06556"
"54.75600","22.45037","0.06639"
"54.81000","22.45492","0.06710"
"54.86400","22.45934","0.06786"
"54.91800","22.46383","0.06846"
"54.97200","22.46837","0.06837"
"55.02600","22.47279","0.06777"
"55.08000","22.47740","0.06709"
"55.13400","22.48188","0.06667"
"55.18800","22.48637","0.06651"
"55.24200","22.49091","0.06723"
"55.29600","22.49539","0.06773"
"55.35000","22.49988","0.06920"
"55.40400","22.50436","0.06926"
"55.45800","22.50879","0.06976"
"55.51200","22.51327","0.06978"
"55.56600","22.51776","0.06934"
"55.62000","22.52230","0.06856"
"55.67400","22.52690","0.06835"
"55.72800","22.53145","0.06849"
"55.78200","22.53587","0.06887"
"55.83600","22.54036","0.06987"
"55.89000","22.54484","0.07036"
"55.94400","22.54932","0.07106"
"55.99800","22.55381","0.07120"
"56.05200","22.55829","0.07069"
"56.10600","22.56278","0.07013"
"56.16000","22.56732","0.07015"
"56.21400","22.57181","0.06984"
"56.26800","22.57635","0.07030"
"56.32200","22.58083","0.07058"
"56.37600","22.58537","0.07101"
"56.43000","22.58986","0.07142"
"56.48400","22.59434","0.07202"
"56.53800","22.59883","0.07190"
"56.59200","22.60325","0.07159"
"56.64600","22.60780","0.07162"
"56.70000","22.61228","0.07131"
"56.75400","22.61683","0.07042"
"56.80800","22.62137","0.07084"
"56.86200","22.62585","0.07187"
"56.91600","22.63040","0.07233"
"56.97000","22.63488","0.07293"
"57.02400","22.63931","0.07301"
"57.07800","22.64379","0.07330"
"57.13200","22.64828","0.07292"
"57.18600","22.65282","0.07276"
"57.24000","22.65736","0.07262"
"57.29400","22.66185","0.07243"
"57.34800","22.66639","0.07274"
"57.40200","22.67088","0.07300"
"57.45600","22.67542","0.07342"
"57.51000","22.67990","0.07389"
"57.56400","22.68433","0.07374"
"57.61800","22.68881","0.07333"
"57.67200","22.69330","0.07329"
"57.72600","22.69778","0.07330"
"57.78000","22.70233","0.07319"
"57.83400","22.70687","0.07317"
"57.88800","22.71135","0.07336"
"57.94200","22.71590","0.07400"
"57.99600","22.72038","0.07403"
"58.05000","22.72481","0.07476"
"58.10400","22.72935","0.07476"
"58.15800","22.73384","0.07495"
"58.21200","22.73832","0.07432"
"58.26600","22.74286","0.07428"
"58.32000","22.74735","0.07431"
"58.37400","22.75189","0.07433"
"58.42800","22.75638","0.07451"
"58.48200","22.76080","0.07494"
"58.53600","22.76540","0.07524"
"58.59000","22.76989","0.07512"
"58.64400","22.77437","0.07528"
"58.69800","22.77879","0.07532"
"58.75200","22.78328","0.07530"
"58.80600","22.78782","0.07432"
"58.86000","22.79237","0.07471"
"58.91400","22.79685","0.07464"
"58.96800","22.80146","0.07503"
"59.02200","22.80582","0.07537"
"59.07600","22.81036","0.07527"
"59.13000","22.81491","0.07554"
"59.18400","22.81933","0.07528"
"59.23800","22.82388","0.07540"
"59.29200","22.82830","0.07536"
"59.34600","22.83279","0.07523"
"59.40000","22.83739","0.07513"
"59.45400","22.84188","0.07533"
"59.50800","22.84636","0.07548"
"59.56200","22.85084","0.07595"
"59.61600","22.85538","0.07612"
"59.67000","22.85987","0.07605"
"59.72400","22.86435","0.07596"
"59.77800","22.86884","0.07604"
"59.83200","22.87332","0.07588"
"59.88600","22.87781","0.07600"
"59.94000","22.88235","0.07570"
"59.99400","22.88690","0.07594"
"60.04800","22.89138","0.07630"
"60.10200","22.89586","0.07651"
"60.15600","22.90035","0.07667"
"60.21000","22.90483","0.07660"
"60.26400","22.90944","0.07654"
"60.31800","22.91386","0.07627"
"60.37200","22.91829","0.07642"
"60.42600","22.92283","0.07655"
"60.48000","22.92731","0.07625"
"60.53400","22.93192","0.07655"
"60.58800","22.93640","0.07671"
"60.64200","22.94082","0.07692"
"60.69600","22.94537","0.07718"
"60.75000","22.94979","0.07690"
"60.80400","22.95434","0.07682"
"60.85800","22.95882","0.07695"
"60.91200","22.96331","0.07701"
"60.96600","22.96785","0.07687"
"61.02000","22.97234","0.07715"
"61.07400","22.97688","0.07729"
"61.12800","22.98136","0.07728"
"61.18200","22.98585","0.07744"
"61.23600","22.99033","0.07745"
"61.29000","22.99488","0.07755"
"61.34400","22.99930","0.07738"
"61.39800","23.00385","0.07738"
"61.45200","23.00839","0.07731"
"61.50600","23.01287","0.07748"
"61.56000","23.01736","0.07760"
"61.61400","23.02190","0.07773"
"61.66800","23.02638","0.07769"
"61.72200","23.03087","0.07793"
"61.77600","23.03535","0.07817"
"61.83000","23.03990","0.07790"
"61.88400","23.04432","0.07777"
"61.93800","23.04880","0.07765"
"61.99200","23.05329","0.07775"
"62.04600","23.05777","0.07819"
"62.10000","23.06238","0.07796"
"62.15400","23.06692","0.07835"
"62.20800","23.07135","0.07820"
"62.26200","23.07589","0.07821"
"62.31600","23.08031","0.07854"
"62.37000","23.08486","0.07820"
"62.42400","23.08934","0.07861"
"62.47800","23.09383","0.07850"
"62.53200","23.09831","0.07839"
"62.58600","23.10286","0.07856"
"62.64000","23.10734","0.07867"
"62.69400","23.11194","0.07908"
"62.74800","23.11637","0.07899"
"62.80200","23.12085","0.07896"
"62.85600","23.12534","0.07889"
"62.91000","23.12982","0.07908"
"62.96400","23.13430","0.07878"
"63.01800","23.13879","0.07894"
"63.07200","23.14327","0.07926"
"63.12600","23.14787","0.07909"
"63.18000","23.15236","0.07950"
"63.23400","23.15684","0.07982"
"63.28800","23.16139","0.07961"
"63.34200","23.16587","0.07941"
"63.39600","23.17036","0.07965"
"63.45000","23.17490","0.07940"
"63.50400","23.17933","0.07942"
"63.55800","23.18381","0.07948"
"63.61200","23.18830","0.07997"
"63.66600","23.19284","0.07973"
"63.72000","23.19732","0.08019"
"63.77400","23.20193","0.08045"
"63.82800","23.20641","0.07996"
"63.88200","23.21090","0.08015"
"63.93600","23.21532","0.07998"
"63.99000","23.21986","0.08047"
"64.04400","23.22435","0.08063"
"64.09800","23.22883","0.08098"
"64.15200","23.23326","0.08070"
"64.20600","23.23774","0.08117"
"64.26000","23.24240","0.08127"
"64.31400","23.24689","0.08119"
"64.36800","23.25137","0.08135"
"64.42200","23.25592","0.08087"
"64.47600","23.26034","0.08119"
"64.53000","23.26483","0.08147"
"64.58400","23.26931","0.08152"
"64.63800","23.27385","0.08184"
"64.69200","23.27828","0.08214"
"64.74600","23.28282","0.08174"
"64.80000","23.28730","0.08234"
"64.85400","23.29185","0.08229"
"64.90800","23.29639","0.08215"
"64.96200","23.30088","0.08215"
"65.01600","23.30536","0.08222"
"65.07000","23.30985","0.08261"
"65.12400","23.31433","0.08290"
"65.17800","23.31882","0.08403"
"65.23200","23.32330","0.08365"
"65.28600","23.32784","0.08349"
"65.34000","23.33233","0.08377"
"65.39400","23.33687","0.08398"
"65.44800","23.34136","0.08399"
"65.50200","23.34590","0.08439"
"65.55600","23.35038","0.08399"
"65.61000","23.35487","0.08482"
"65.66400","23.35929","0.08548"
"65.71800","23.36384","0.08567"
"65.77200","23.36826","0.08559"
"65.82600","23.37286","0.08527"
"65.88000","23.37735","0.08540"
"65.93400","23.38183","0.08553"
"65.98800","23.38638","0.08582"
"66.04200","23.39086","0.08657"
"66.09600","23.39535","0.08620"
"66.15000","23.39989","0.08697"
"66.20400","23.40432","0.08702"
"66.25800","23.40886","0.08769"
"66.31200","23.41328","0.08708"
"66.36600","23.41777","0.08772"
"66.42000","23.42237","0.08770"
"66.47400","23.42685","0.08753"
"66.52800","23.43134","0.08815"
"66.58200","23.43594","0.08872"
"66.63600","23.44037","0.08921"
"66.69000","23.44485","0.08904"
"66.74400","23.44933","0.08937"
"66.79800","23.45376","0.08913"
"66.85200","23.45830","0.08948"
"66.90600","23.46279","0.08905"
"66.96000","23.46733","0.08978"
"67.01400","23.47188","0.09012"
"67.06800","23.47630","0.09094"
"67.12200","23.48084","0.09088"
"67.17600","23.48539","0.09185"
"67.23000","23.48987","0.09078"
"67.28400","23.49436","0.09164"
"67.33800","23.49878","0.09104"
"67.39200","23.50327","0.09123"
"67.44600","23.50787","0.09115"
"67.50000","23.51235","0.09156"
"67.55400","23.51690","0.09180"
"67.60800","23.52138","0.09235"
"67.66200","23.52587","0.09271"
"67.71600","23.53041","0.09260"
"67.77000","23.53489","0.09286"
"67.82400","23.53938","0.09278"
"67.87800","23.54386","0.09324"
"67.93200","23.54835","0.09289"
"67.98600","23.55289","0.09346"
"68.04000","23.55738","0.09377"
"68.09400","23.56186","0.09397"
"68.14800","23.56640","0.09374"
"68.20200","23.57089","0.09371"
"68.25600","23.57531","0.09256"
"68.31000","23.57986","0.09269"
"68.36400","23.58434","0.09282"
"68.41800","23.58883","0.09265"
"68.47200","23.59331","0.08597"
"68.52600","23.59779","0.08768"
"68.58000","23.60234","0.08755"
"68.63400","23.60688","0.08730"
"68.68800","23.61136","0.08731"
"68.74200","23.61591","0.08801"
"68.79600","23.62039","0.08744"
"68.85000","23.62482","0.03702"
"68.90400","23.62930","0.03648"
"68.95800","23.63379","0.03791"
"69.01200","23.63833","0.04715"
"69.06600","23.64287","0.05009"
"69.12000","23.64736","0.03612"
"69.17400","23.65184","0.03083"
"69.22800","23.65633","0.00873"
"69.28200","23.66087","0.00946"
"69.33600","23.66535","0.00296"
"69.39000","23.66984","0.00576"
"69.44400","23.67432","0.00729"
"69.49800","23.67881","0.00495"
"69.55200","23.68329","0.00514"
"69.60600","23.68784","0.00757"
"69.66000","23.69232","0.00385"
"69.71400","23.69693","0.00423"
"69.76800","23.70135","0.00591"
"69.82200","23.70583","0.00438"
"69.87600","23.71037","0.00421"
"69.93000","23.71480","0.00437"
"69.98400","23.71935","0.00345"
"70.03800","23.72383","0.00347"
"70.09200","23.72831","0.00524"
"70.14600","23.73292","0.00437"
"70.20000","23.73734","0.00471"
"70.25400","23.74189","0.00549"
"70.30800","23.74637","0.00441"
"70.36200","23.75085","0.00494"
"70.41600","23.75534","0.00540"
"70.47000","23.75988","0.00395"
"70.52400","23.76431","0.00387"
"70.57800","23.76885","0.00457"
"70.63200","23.77328","0.00363"
"70.68600","23.77782","0.00316"
"70.74000","23.78242","0.00411"
"70.79400","23.78685","0.00396"
"70.84800","23.79133","0.00350"
"70.90200","23.79588","0.00407"
"70.95600","23.80036","0.00416"
"71.01000","23.80490","0.00407"
"71.06400","23.80933","0.00430"
"71.11800","23.81381","0.00380"
"71.17200","23.81836","0.00404"
"71.22600","23.82284","0.00409"
"71.28000","23.82738","0.00489"
"71.33400","23.83193","0.00555"
"71.38800","23.83635","0.00565"
"71.44200","23.84090","0.00492"
"71.49600","23.84532","0.00553"
"71.55000","23.84980","0.00502"
"71.60400","23.85435","0.00377"
"71.65800","23.85877","0.00333"
"71.71200","23.86332","0.00378"
"71.76600","23.86786","0.00386"
"71.82000","23.87235","0.00337"
"71.87400","23.87689","0.00383"
"71.92800","23.88132","0.00371"
"71.98200","23.88586","0.00430"
"72.03600","23.89040","0.00355"
"72.09000","23.89483","0.00437"
"72.14400","23.89931","0.00378"
"72.19800","23.90380","0.00397"
"72.25200","23.90828","0.00425"
"72.30600","23.91288","0.00461"
"72.36000","23.91737","0.00429"
"72.41400","23.92191","0.00482"
"72.46800","23.92634","0.00539"
"72.52200","23.93088","0.00531"
"72.57600","23.93536","0.00457"
"72.63000","23.93985","0.00455"
"72.68400","23.94433","0.00452"
"72.73800","23.94876","0.00436"
"72.79200","23.95330","0.00404"
"72.84600","23.95785","0.00347"
"72.90000","23.96239","0.00325"
"72.92000","23.96406","0.00312"