File: Force_trajectories/170108_2/Specimen_RawData_7.csv
End date,"1/8/2017"
Specimen label,"9BT_74"
Maximum Load,"0.29177",N

Time,Extension,Load
(s),(mm),(N)
"0.00000","0.00000","-0.00173"
"0.14400","0.00676","-0.00075"
"0.28800","0.02284","0.00040"
"0.43200","0.03629","0.00109"
"0.57600","0.04825","0.00123"
"0.72000","0.06021","0.00184"
"0.86400","0.07223","0.00241"
"1.00800","0.08418","0.00264"
"1.15200","0.09620","0.00274"
"1.29600","0.10828","0.00289"
"1.44000","0.12024","0.00349"
"1.58400","0.13213","0.00376"
"1.72800","0.14415","0.00317"
"1.87200","0.15623","0.00401"
"2.01600","0.16813","0.00408"
"2.16000","0.18015","0.00403"
"2.30400","0.19216","0.00399"
"2.44800","0.20418","0.00440"
"2.59200","0.21620","0.00456"
"2.73600","0.22816","0.00409"
"2.88000","0.24023","0.00455"
"3.02400","0.25225","0.00467"
"3.16800","0.26415","0.00490"
"3.31200","0.27617","0.00457"
"3.45600","0.28819","0.00508"
"3.60000","0.30020","0.00468"
"3.74400","0.31216","0.00519"
"3.88800","0.32418","0.00476"
"4.03200","0.33620","0.00431"
"4.17600","0.34821","0.00577"
"4.32000","0.36017","0.00561"
"4.46400","0.37219","0.00532"
"4.60800","0.38421","0.00551"
"4.75200","0.39623","0.00569"
"4.89600","0.40812","0.00556"
"5.04000","0.42020","0.00609"
"5.18400","0.43222","0.00562"
"5.32800","0.44418","0.00565"
"5.47200","0.45613","0.00555"
"5.61600","0.46821","0.00632"
"5.76000","0.48023","0.00565"
"5.90400","0.49213","0.00612"
"6.04800","0.50415","0.00548"
"6.19200","0.51616","0.00618"
"6.33600","0.52818","0.00506"
"6.48000","0.54014","0.00610"
"6.62400","0.55216","0.00587"
"6.76800","0.56417","0.00652"
"6.91200","0.57613","0.00568"
"7.05600","0.58809","0.00627"
"7.20000","0.60011","0.00615"
"7.34400","0.61219","0.00628"
"7.48800","0.62414","0.00661"
"7.63200","0.63610","0.00700"
"7.77600","0.64824","0.00610"
"7.92000","0.66020","0.00744"
"8.06400","0.67215","0.00653"
"8.20800","0.68417","0.00683"
"8.35200","0.69619","0.00667"
"8.49600","0.70821","0.00723"
"8.64000","0.72016","0.00662"
"8.78400","0.73212","0.00700"
"8.92800","0.74420","0.00660"
"9.07200","0.75616","0.00703"
"9.21600","0.76812","0.00680"
"9.36000","0.78019","0.00702"
"9.50400","0.79221","0.00657"
"9.64800","0.80417","0.00738"
"9.79200","0.81613","0.00741"
"9.93600","0.82820","0.00703"
"10.08000","0.84022","0.00756"
"10.22400","0.85218","0.00737"
"10.36800","0.86420","0.00705"
"10.51200","0.87616","0.00766"
"10.65600","0.88817","0.00724"
"10.80000","0.90013","0.00730"
"10.94400","0.91221","0.00709"
"11.08800","0.92423","0.00703"
"11.23200","0.93618","0.00765"
"11.37600","0.94808","0.00806"
"11.52000","0.96022","0.00736"
"11.66400","0.97224","0.00790"
"11.80800","0.98414","0.00787"
"11.95200","0.99609","0.00768"
"12.09600","1.00823","0.00742"
"12.24000","1.02019","0.00812"
"12.38400","1.03215","0.00761"
"12.52800","1.04416","0.00769"
"12.67200","1.05618","0.00831"
"12.81600","1.06814","0.00832"
"12.96000","1.08010","0.00807"
"13.10400","1.09212","0.00815"
"13.24800","1.10425","0.00840"
"13.39200","1.11615","0.00830"
"13.53600","1.12817","0.00864"
"13.68000","1.14025","0.00805"
"13.82400","1.15226","0.00846"
"13.96800","1.16416","0.00821"
"14.11200","1.17612","0.00844"
"14.25600","1.18820","0.00803"
"14.40000","1.20022","0.00868"
"14.54400","1.21217","0.00816"
"14.68800","1.22419","0.00843"
"14.83200","1.23615","0.00872"
"14.97600","1.24817","0.00884"
"15.12000","1.26006","0.00875"
"15.26400","1.27220","0.00833"
"15.40800","1.28416","0.00895"
"15.55200","1.29618","0.00902"
"15.69600","1.30814","0.00876"
"15.84000","1.32021","0.00904"
"15.98400","1.33217","0.00856"
"16.12800","1.34419","0.00908"
"16.27200","1.35615","0.00880"
"16.41600","1.36816","0.00944"
"16.56000","1.38018","0.00898"
"16.70400","1.39214","0.00916"
"16.84800","1.40416","0.00926"
"16.99200","1.41617","0.00903"
"17.13600","1.42819","0.00924"
"17.28000","1.44009","0.00923"
"17.42400","1.45217","0.00910"
"17.56800","1.46419","0.00894"
"17.71200","1.47614","0.00916"
"17.85600","1.48816","0.00916"
"18.00000","1.50018","0.00955"
"18.14400","1.51220","0.00953"
"18.28800","1.52415","0.00949"
"18.43200","1.53617","0.00949"
"18.57600","1.54819","0.00965"
"18.72000","1.56015","0.00992"
"18.86400","1.57217","0.01016"
"19.00800","1.58418","0.00958"
"19.15200","1.59620","0.00953"
"19.29600","1.60816","0.00983"
"19.44000","1.62012","0.00939"
"19.58400","1.63219","0.01007"
"19.72800","1.64421","0.00997"
"19.87200","1.65617","0.00983"
"20.01600","1.66813","0.00989"
"20.16000","1.68027","0.00997"
"20.30400","1.69222","0.01003"
"20.44800","1.70418","0.00982"
"20.59200","1.71620","0.01039"
"20.73600","1.72822","0.01040"
"20.88000","1.74017","0.00985"
"21.02400","1.75213","0.01060"
"21.16800","1.76415","0.00996"
"21.31200","1.77623","0.01043"
"21.45600","1.78819","0.01005"
"21.60000","1.80008","0.01025"
"21.74400","1.81222","0.01036"
"21.88800","1.82424","0.01018"
"22.03200","1.83614","0.01029"
"22.17600","1.84815","0.01076"
"22.32000","1.86023","0.01085"
"22.46400","1.87219","0.01068"
"22.60800","1.88415","0.01123"
"22.75200","1.89617","0.01034"
"22.89600","1.90824","0.01066"
"23.04000","1.92020","0.01027"
"23.18400","1.93210","0.01069"
"23.32800","1.94424","0.01042"
"23.47200","1.95619","0.01066"
"23.61600","1.96821","0.01066"
"23.76000","1.98011","0.01098"
"23.90400","1.99219","0.01047"
"24.04800","2.00420","0.01071"
"24.19200","2.01616","0.01114"
"24.33600","2.02812","0.01095"
"24.48000","2.04020","0.01098"
"24.62400","2.05222","0.01087"
"24.76800","2.06417","0.01076"
"24.91200","2.07619","0.01113"
"25.05600","2.08821","0.01109"
"25.20000","2.10023","0.01129"
"25.34400","2.11213","0.01072"
"25.48800","2.12420","0.01092"
"25.63200","2.13622","0.01104"
"25.77600","2.14818","0.01077"
"25.92000","2.16014","0.01128"
"26.06400","2.17221","0.01133"
"26.20800","2.18417","0.01146"
"26.35200","2.19619","0.01156"
"26.49600","2.20821","0.01083"
"26.64000","2.22022","0.01129"
"26.78400","2.23224","0.01156"
"26.92800","2.24420","0.01169"
"27.07200","2.25622","0.01133"
"27.21600","2.26824","0.01181"
"27.36000","2.28019","0.01156"
"27.50400","2.29215","0.01116"
"27.64800","2.30423","0.01150"
"27.79200","2.31619","0.01144"
"27.93600","2.32814","0.01163"
"28.08000","2.34016","0.01166"
"28.22400","2.35224","0.01144"
"28.36800","2.36426","0.01166"
"28.51200","2.37616","0.01150"
"28.65600","2.38817","0.01153"
"28.80000","2.40025","0.01135"
"28.94400","2.41221","0.01178"
"29.08800","2.42411","0.01190"
"29.23200","2.43618","0.01165"
"29.37600","2.44820","0.01152"
"29.52000","2.46016","0.01181"
"29.66400","2.47218","0.01214"
"29.80800","2.48420","0.01233"
"29.95200","2.49621","0.01147"
"30.09600","2.50817","0.01221"
"30.24000","2.52019","0.01185"
"30.38400","2.53221","0.01264"
"30.52800","2.54422","0.01187"
"30.67200","2.55612","0.01226"
"30.81600","2.56820","0.01194"
"30.96000","2.58028","0.01177"
"31.10400","2.59224","0.01209"
"31.24800","2.60413","0.01203"
"31.39200","2.61621","0.01188"
"31.53600","2.62823","0.01219"
"31.68000","2.64025","0.01207"
"31.82400","2.65220","0.01231"
"31.96800","2.66422","0.01163"
"32.11200","2.67624","0.01247"
"32.25600","2.68814","0.01266"
"32.40000","2.70016","0.01237"
"32.54400","2.71223","0.01221"
"32.68800","2.72419","0.01236"
"32.83200","2.73615","0.01181"
"32.97600","2.74817","0.01200"
"33.12000","2.76018","0.01267"
"33.26400","2.77220","0.01244"
"33.40800","2.78422","0.01187"
"33.55200","2.79624","0.01116"
"33.69600","2.80825","0.01117"
"33.84000","2.82021","0.01156"
"33.98400","2.83217","0.01190"
"34.12800","2.84425","0.01175"
"34.27200","2.85621","0.01176"
"34.41600","2.86822","0.01160"
"34.56000","2.88018","0.01208"
"34.70400","2.89226","0.01177"
"34.84800","2.90422","0.01157"
"34.99200","2.91617","0.01196"
"35.13600","2.92819","0.01107"
"35.28000","2.94021","0.01114"
"35.42400","2.95223","0.01075"
"35.56800","2.96419","0.01063"
"35.71200","2.97626","0.01095"
"35.85600","2.98822","0.01084"
"36.00000","3.00018","0.01153"
"36.14400","3.01214","0.01167"
"36.28800","3.02421","0.01129"
"36.43200","3.03617","0.01123"
"36.57600","3.04813","0.01129"
"36.72000","3.06015","0.01183"
"36.86400","3.07217","0.01106"
"37.00800","3.08418","0.01185"
"37.15200","3.09608","0.01178"
"37.29600","3.10822","0.01153"
"37.44000","3.12018","0.01179"
"37.58400","3.13225","0.01159"
"37.72800","3.14415","0.01162"
"37.87200","3.15623","0.01185"
"38.01600","3.16819","0.01207"
"38.16000","3.18015","0.01112"
"38.30400","3.19216","0.01137"
"38.44800","3.20424","0.01149"
"38.59200","3.21620","0.01072"
"38.73600","3.22816","0.01132"
"38.88000","3.24017","0.01161"
"39.02400","3.25219","0.01200"
"39.16800","3.26421","0.01151"
"39.31200","3.27611","0.01104"
"39.45600","3.28824","0.01159"
"39.60000","3.30020","0.01169"
"39.74400","3.31222","0.01173"
"39.88800","3.32418","0.01198"
"40.03200","3.33620","0.01151"
"40.17600","3.34821","0.01115"
"40.32000","3.36017","0.01167"
"40.46400","3.37219","0.01206"
"40.60800","3.38421","0.01162"
"40.75200","3.39622","0.01175"
"40.89600","3.40812","0.01189"
"41.04000","3.42020","0.01195"
"41.18400","3.43222","0.01178"
"41.32800","3.44418","0.01193"
"41.47200","3.45619","0.01176"
"41.61600","3.46821","0.01235"
"41.76000","3.48017","0.01229"
"41.90400","3.49219","0.01194"
"42.04800","3.50415","0.01203"
"42.19200","3.51622","0.01263"
"42.33600","3.52818","0.01205"
"42.48000","3.54020","0.01227"
"42.62400","3.55216","0.01208"
"42.76800","3.56423","0.01202"
"42.91200","3.57613","0.01196"
"43.05600","3.58815","0.01232"
"43.20000","3.60017","0.01218"
"43.34400","3.61218","0.01234"
"43.48800","3.62414","0.01237"
"43.63200","3.63616","0.01217"
"43.77600","3.64818","0.01267"
"43.92000","3.66020","0.01302"
"44.06400","3.67215","0.01291"
"44.20800","3.68417","0.01264"
"44.35200","3.69625","0.01302"
"44.49600","3.70827","0.01278"
"44.64000","3.72016","0.01278"
"44.78400","3.73218","0.01274"
"44.92800","3.74420","0.01271"
"45.07200","3.75616","0.01260"
"45.21600","3.76812","0.01284"
"45.36000","3.78019","0.01252"
"45.50400","3.79215","0.01280"
"45.64800","3.80423","0.01274"
"45.79200","3.81613","0.01300"
"45.93600","3.82820","0.01268"
"46.08000","3.84022","0.01290"
"46.22400","3.85218","0.01260"
"46.36800","3.86414","0.01267"
"46.51200","3.87622","0.01316"
"46.65600","3.88817","0.01282"
"46.80000","3.90013","0.01328"
"46.94400","3.91215","0.01288"
"47.08800","3.92417","0.01321"
"47.23200","3.93618","0.01308"
"47.37600","3.94814","0.01308"
"47.52000","3.96016","0.01327"
"47.66400","3.97218","0.01311"
"47.80800","3.98420","0.01334"
"47.95200","3.99615","0.01346"
"48.09600","4.00817","0.01351"
"48.24000","4.02025","0.01352"
"48.38400","4.03221","0.01328"
"48.52800","4.04416","0.01359"
"48.67200","4.05624","0.01216"
"48.81600","4.06826","0.01214"
"48.96000","4.08016","0.01268"
"49.10400","4.09218","0.01199"
"49.24800","4.10419","0.01211"
"49.39200","4.11621","0.01173"
"49.53600","4.12811","0.01246"
"49.68000","4.14019","0.01204"
"49.82400","4.15220","0.01224"
"49.96800","4.16422","0.01238"
"50.11200","4.17612","0.01195"
"50.25600","4.18820","0.01159"
"50.40000","4.20021","0.01157"
"50.54400","4.21217","0.01175"
"50.68800","4.22413","0.01264"
"50.83200","4.23621","0.01232"
"50.97600","4.24817","0.01288"
"51.12000","4.26018","0.01226"
"51.26400","4.27214","0.01222"
"51.40800","4.28416","0.01200"
"51.55200","4.29612","0.01286"
"51.69600","4.30813","0.01245"
"51.84000","4.32015","0.01285"
"51.98400","4.33223","0.01309"
"52.12800","4.34419","0.01327"
"52.27200","4.35621","0.01293"
"52.41600","4.36822","0.01298"
"52.56000","4.38024","0.01328"
"52.70400","4.39214","0.01333"
"52.84800","4.40416","0.01286"
"52.99200","4.41617","0.01258"
"53.13600","4.42819","0.01342"
"53.28000","4.44015","0.01301"
"53.42400","4.45223","0.01274"
"53.56800","4.46419","0.01283"
"53.71200","4.47614","0.01319"
"53.85600","4.48810","0.01318"
"54.00000","4.50018","0.01347"
"54.14400","4.51220","0.01328"
"54.28800","4.52415","0.01306"
"54.43200","4.53611","0.01310"
"54.57600","4.54819","0.01330"
"54.72000","4.56021","0.01345"
"54.86400","4.57211","0.01359"
"55.00800","4.58412","0.01376"
"55.15200","4.59620","0.01362"
"55.29600","4.60816","0.01390"
"55.44000","4.62012","0.01368"
"55.58400","4.63213","0.01346"
"55.72800","4.64421","0.01354"
"55.87200","4.65617","0.01440"
"56.01600","4.66813","0.01393"
"56.16000","4.68015","0.01437"
"56.30400","4.69222","0.01385"
"56.44800","4.70412","0.01436"
"56.59200","4.71614","0.01428"
"56.73600","4.72816","0.01382"
"56.88000","4.74023","0.01332"
"57.02400","4.75213","0.01439"
"57.16800","4.76415","0.01402"
"57.31200","4.77617","0.01427"
"57.45600","4.78824","0.01419"
"57.60000","4.80020","0.01485"
"57.74400","4.81222","0.01502"
"57.88800","4.82418","0.01485"
"58.03200","4.83620","0.01479"
"58.17600","4.84809","0.01498"
"58.32000","4.86017","0.01481"
"58.46400","4.87219","0.01489"
"58.60800","4.88415","0.01503"
"58.75200","4.89611","0.01502"
"58.89600","4.90824","0.01514"
"59.04000","4.92020","0.01552"
"59.18400","4.93216","0.01475"
"59.32800","4.94418","0.01541"
"59.47200","4.95619","0.01560"
"59.61600","4.96815","0.01571"
"59.76000","4.98017","0.01579"
"59.90400","4.99219","0.01523"
"60.04800","5.00420","0.01549"
"60.19200","5.01616","0.01577"
"60.33600","5.02812","0.01556"
"60.48000","5.04020","0.01579"
"60.62400","5.05222","0.01546"
"60.76800","5.06411","0.01489"
"60.91200","5.07613","0.01545"
"61.05600","5.08815","0.01563"
"61.20000","5.10023","0.01606"
"61.34400","5.11212","0.01644"
"61.48800","5.12414","0.01578"
"61.63200","5.13616","0.01585"
"61.77600","5.14818","0.01613"
"61.92000","5.16014","0.01633"
"62.06400","5.17221","0.01674"
"62.20800","5.18417","0.01686"
"62.35200","5.19613","0.01657"
"62.49600","5.20809","0.01709"
"62.64000","5.22016","0.01665"
"62.78400","5.23218","0.01720"
"62.92800","5.24414","0.01702"
"63.07200","5.25616","0.01700"
"63.21600","5.26824","0.01709"
"63.36000","5.28019","0.01751"
"63.50400","5.29215","0.01772"
"63.64800","5.30423","0.01794"
"63.79200","5.31625","0.01841"
"63.93600","5.32820","0.01847"
"64.08000","5.34016","0.01703"
"64.22400","5.35212","0.01779"
"64.36800","5.36420","0.01771"
"64.51200","5.37616","0.01820"
"64.65600","5.38811","0.01719"
"64.80000","5.40019","0.01842"
"64.94400","5.41227","0.01854"
"65.08800","5.42417","0.01841"
"65.23200","5.43612","0.01872"
"65.37600","5.44820","0.01853"
"65.52000","5.46022","0.01804"
"65.66400","5.47218","0.01849"
"65.80800","5.48419","0.01898"
"65.95200","5.49621","0.01954"
"66.09600","5.50817","0.01910"
"66.24000","5.52013","0.01902"
"66.38400","5.53221","0.01964"
"66.52800","5.54422","0.01979"
"66.67200","5.55618","0.01978"
"66.81600","5.56814","0.01944"
"66.96000","5.58028","0.02020"
"67.10400","5.59218","0.02020"
"67.24800","5.60419","0.02001"
"67.39200","5.61615","0.01996"
"67.53600","5.62823","0.02036"
"67.68000","5.64019","0.02083"
"67.82400","5.65220","0.02069"
"67.96800","5.66422","0.02101"
"68.11200","5.67624","0.02134"
"68.25600","5.68820","0.02155"
"68.40000","5.70015","0.02089"
"68.54400","5.71223","0.02137"
"68.68800","5.72419","0.02151"
"68.83200","5.73615","0.02130"
"68.97600","5.74817","0.02195"
"69.12000","5.76018","0.02134"
"69.26400","5.77220","0.02269"
"69.40800","5.78416","0.02204"
"69.55200","5.79618","0.02212"
"69.69600","5.80819","0.02205"
"69.84000","5.82021","0.02252"
"69.98400","5.83217","0.02225"
"70.12800","5.84425","0.02312"
"70.27200","5.85627","0.02279"
"70.41600","5.86822","0.02293"
"70.56000","5.88018","0.02313"
"70.70400","5.89226","0.02224"
"70.84800","5.90422","0.02293"
"70.99200","5.91617","0.02236"
"71.13600","5.92819","0.02232"
"71.28000","5.94027","0.02271"
"71.42400","5.95223","0.02293"
"71.56800","5.96419","0.02287"
"71.71200","5.97620","0.02333"
"71.85600","5.98822","0.02287"
"72.00000","6.00024","0.02317"
"72.14400","6.01214","0.02340"
"72.28800","6.02421","0.02331"
"72.43200","6.03623","0.02379"
"72.57600","6.04819","0.02387"
"72.72000","6.06015","0.02382"
"72.86400","6.07217","0.02450"
"73.00800","6.08418","0.02416"
"73.15200","6.09614","0.02425"
"73.29600","6.10816","0.02484"
"73.44000","6.12024","0.02522"
"73.58400","6.13225","0.02520"
"73.72800","6.14415","0.02520"
"73.87200","6.15623","0.02575"
"74.01600","6.16825","0.02582"
"74.16000","6.18020","0.02584"
"74.30400","6.19216","0.02561"
"74.44800","6.20418","0.02631"
"74.59200","6.21620","0.02617"
"74.73600","6.22822","0.02646"
"74.88000","6.24017","0.02655"
"75.02400","6.25219","0.02661"
"75.16800","6.26421","0.02641"
"75.31200","6.27617","0.02658"
"75.45600","6.28819","0.02696"
"75.60000","6.30020","0.02675"
"75.74400","6.31222","0.02699"
"75.88800","6.32418","0.02692"
"76.03200","6.33620","0.02726"
"76.17600","6.34821","0.02745"
"76.32000","6.36023","0.02759"
"76.46400","6.37219","0.02764"
"76.60800","6.38421","0.02797"
"76.75200","6.39622","0.02786"
"76.89600","6.40818","0.02822"
"77.04000","6.42020","0.02808"
"77.18400","6.43222","0.02819"
"77.32800","6.44418","0.02837"
"77.47200","6.45619","0.02849"
"77.61600","6.46815","0.02867"
"77.76000","6.48023","0.02866"
"77.90400","6.49219","0.02879"
"78.04800","6.50415","0.02887"
"78.19200","6.51616","0.02912"
"78.33600","6.52818","0.02893"
"78.48000","6.54020","0.02927"
"78.62400","6.55216","0.02927"
"78.76800","6.56423","0.02966"
"78.91200","6.57619","0.02971"
"79.05600","6.58821","0.02979"
"79.20000","6.60017","0.02967"
"79.34400","6.61224","0.03005"
"79.48800","6.62420","0.03000"
"79.63200","6.63610","0.03007"
"79.77600","6.64818","0.03029"
"79.92000","6.66025","0.03042"
"80.06400","6.67221","0.03065"
"80.20800","6.68411","0.03053"
"80.35200","6.69619","0.03062"
"80.49600","6.70821","0.03094"
"80.64000","6.72022","0.03132"
"80.78400","6.73212","0.03078"
"80.92800","6.74420","0.03128"
"81.07200","6.75622","0.03124"
"81.21600","6.76818","0.03168"
"81.36000","6.78019","0.03174"
"81.50400","6.79221","0.03158"
"81.64800","6.80417","0.03210"
"81.79200","6.81613","0.03222"
"81.93600","6.82814","0.03264"
"82.08000","6.84022","0.03221"
"82.22400","6.85218","0.03263"
"82.36800","6.86414","0.03289"
"82.51200","6.87622","0.03318"
"82.65600","6.88823","0.03341"
"82.80000","6.90019","0.03385"
"82.94400","6.91215","0.03415"
"83.08800","6.92423","0.03423"
"83.23200","6.93624","0.03470"
"83.37600","6.94820","0.03515"
"83.52000","6.96016","0.03409"
"83.66400","6.97218","0.03533"
"83.80800","6.98420","0.03493"
"83.95200","6.99615","0.03549"
"84.09600","7.00817","0.03632"
"84.24000","7.02025","0.03673"
"84.38400","7.03221","0.03694"
"84.52800","7.04416","0.03788"
"84.67200","7.05618","0.03830"
"84.81600","7.06814","0.03850"
"84.96000","7.08022","0.03970"
"85.10400","7.09218","0.04027"
"85.24800","7.10419","0.04044"
"85.39200","7.11621","0.04085"
"85.53600","7.12817","0.04199"
"85.68000","7.14019","0.04253"
"85.82400","7.15220","0.04282"
"85.96800","7.16416","0.04333"
"86.11200","7.17612","0.04461"
"86.25600","7.18820","0.04475"
"86.40000","7.20015","0.04479"
"86.54400","7.21217","0.04686"
"86.68800","7.22413","0.04792"
"86.83200","7.23615","0.04810"
"86.97600","7.24823","0.04820"
"87.12000","7.26012","0.04926"
"87.26400","7.27214","0.04969"
"87.40800","7.28422","0.05044"
"87.55200","7.29624","0.05028"
"87.69600","7.30814","0.05118"
"87.84000","7.32015","0.05190"
"87.98400","7.33217","0.05217"
"88.12800","7.34419","0.05269"
"88.27200","7.35615","0.05303"
"88.41600","7.36816","0.05330"
"88.56000","7.38018","0.05378"
"88.70400","7.39220","0.05419"
"88.84800","7.40416","0.05516"
"88.99200","7.41617","0.05584"
"89.13600","7.42825","0.05669"
"89.28000","7.44015","0.05706"
"89.42400","7.45217","0.05761"
"89.56800","7.46425","0.05812"
"89.71200","7.47620","0.05808"
"89.85600","7.48816","0.05922"
"90.00000","7.50018","0.05949"
"90.14400","7.51220","0.05971"
"90.28800","7.52415","0.05994"
"90.43200","7.53611","0.06086"
"90.57600","7.54819","0.06118"
"90.72000","7.56015","0.06178"
"90.86400","7.57216","0.06232"
"91.00800","7.58412","0.06301"
"91.15200","7.59620","0.06336"
"91.29600","7.60822","0.06303"
"91.44000","7.62018","0.06448"
"91.58400","7.63213","0.06544"
"91.72800","7.64415","0.06564"
"91.87200","7.65623","0.06629"
"92.01600","7.66813","0.06680"
"92.16000","7.68021","0.06632"
"92.30400","7.69216","0.06748"
"92.44800","7.70418","0.06736"
"92.59200","7.71608","0.06785"
"92.73600","7.72816","0.06791"
"92.88000","7.74017","0.06819"
"93.02400","7.75219","0.06917"
"93.16800","7.76409","0.06915"
"93.31200","7.77617","0.06999"
"93.45600","7.78819","0.07106"
"93.60000","7.80020","0.07106"
"93.74400","7.81216","0.07141"
"93.88800","7.82424","0.07178"
"94.03200","7.83620","0.07242"
"94.17600","7.84821","0.07345"
"94.32000","7.86017","0.07304"
"94.46400","7.87219","0.07352"
"94.60800","7.88415","0.07394"
"94.75200","7.89610","0.07391"
"94.89600","7.90812","0.07464"
"95.04000","7.92020","0.07479"
"95.18400","7.93210","0.07492"
"95.32800","7.94412","0.07536"
"95.47200","7.95619","0.07530"
"95.61600","7.96821","0.07558"
"95.76000","7.98011","0.07590"
"95.90400","7.99219","0.07604"
"96.04800","8.00414","0.07639"
"96.19200","8.01616","0.07651"
"96.33600","8.02812","0.07651"
"96.48000","8.04020","0.07691"
"96.62400","8.05216","0.07735"
"96.76800","8.06411","0.07699"
"96.91200","8.07607","0.07746"
"97.05600","8.08821","0.07767"
"97.20000","8.10023","0.07774"
"97.34400","8.11218","0.07794"
"97.48800","8.12414","0.07804"
"97.63200","8.13622","0.07842"
"97.77600","8.14818","0.07855"
"97.92000","8.16013","0.07885"
"98.06400","8.17215","0.07921"
"98.20800","8.18417","0.07927"
"98.35200","8.19619","0.07949"
"98.49600","8.20815","0.07959"
"98.64000","8.22016","0.08024"
"98.78400","8.23218","0.08041"
"98.92800","8.24414","0.08087"
"99.07200","8.25610","0.08116"
"99.21600","8.26812","0.08150"
"99.36000","8.28019","0.08180"
"99.50400","8.29215","0.08266"
"99.64800","8.30411","0.08281"
"99.79200","8.31619","0.08384"
"99.93600","8.32826","0.08433"
"100.08000","8.34016","0.08553"
"100.22400","8.35212","0.08527"
"100.36800","8.36420","0.08618"
"100.51200","8.37615","0.08622"
"100.65600","8.38811","0.08745"
"100.80000","8.40019","0.08814"
"100.94400","8.41215","0.08975"
"101.08800","8.42417","0.09129"
"101.23200","8.43612","0.09100"
"101.37600","8.44820","0.09212"
"101.52000","8.46022","0.09298"
"101.66400","8.47224","0.09490"
"101.80800","8.48413","0.09562"
"101.95200","8.49621","0.09808"
"102.09600","8.50817","0.09804"
"102.24000","8.52019","0.09987"
"102.38400","8.53221","0.10033"
"102.52800","8.54422","0.10163"
"102.67200","8.55618","0.10326"
"102.81600","8.56814","0.10455"
"102.96000","8.58016","0.10542"
"103.10400","8.59217","0.10647"
"103.24800","8.60419","0.10724"
"103.39200","8.61615","0.10895"
"103.53600","8.62823","0.10994"
"103.68000","8.64025","0.11122"
"103.82400","8.65214","0.11189"
"103.96800","8.66416","0.11300"
"104.11200","8.67618","0.11393"
"104.25600","8.68820","0.11580"
"104.40000","8.70009","0.11699"
"104.54400","8.71223","0.11890"
"104.68800","8.72419","0.11995"
"104.83200","8.73621","0.12060"
"104.97600","8.74811","0.12221"
"105.12000","8.76018","0.12412"
"105.26400","8.77220","0.12537"
"105.40800","8.78416","0.12606"
"105.55200","8.79612","0.12717"
"105.69600","8.80819","0.12853"
"105.84000","8.82021","0.12971"
"105.98400","8.83217","0.13050"
"106.12800","8.84419","0.13100"
"106.27200","8.85627","0.13114"
"106.41600","8.86822","0.13175"
"106.56000","8.88018","0.12260"
"106.70400","8.89220","0.12429"
"106.84800","8.90422","0.12596"
"106.99200","8.91617","0.12726"
"107.13600","8.92819","0.12906"
"107.28000","8.94021","0.13016"
"107.42400","8.95223","0.13148"
"107.56800","8.96418","0.13157"
"107.71200","8.97620","0.13285"
"107.85600","8.98822","0.13407"
"108.00000","9.00024","0.13482"
"108.14400","9.01220","0.13533"
"108.28800","9.02415","0.13569"
"108.43200","9.03623","0.12552"
"108.57600","9.04819","0.11169"
"108.72000","9.06015","0.07594"
"108.86400","9.07216","0.07635"
"109.00800","9.08418","0.07725"
"109.15200","9.09620","0.07693"
"109.29600","9.10816","0.07749"
"109.44000","9.12018","0.07832"
"109.58400","9.13225","0.07830"
"109.72800","9.14421","0.07825"
"109.87200","9.15617","0.07923"
"110.01600","9.16825","0.07909"
"110.16000","9.18021","0.07983"
"110.30400","9.19216","0.08031"
"110.44800","9.20418","0.08082"
"110.59200","9.21620","0.08086"
"110.73600","9.22816","0.08213"
"110.88000","9.24017","0.08300"
"111.02400","9.25219","0.08328"
"111.16800","9.26421","0.08539"
"111.31200","9.27623","0.08632"
"111.45600","9.28818","0.08646"
"111.60000","9.30020","0.08843"
"111.74400","9.31222","0.08991"
"111.88800","9.32418","0.09015"
"112.03200","9.33619","0.09220"
"112.17600","9.34827","0.09372"
"112.32000","9.36023","0.09440"
"112.46400","9.37219","0.09658"
"112.60800","9.38421","0.09971"
"112.75200","9.39622","0.09888"
"112.89600","9.40824","0.10105"
"113.04000","9.42014","0.10333"
"113.18400","9.43222","0.10262"
"113.32800","9.44423","0.10504"
"113.47200","9.45619","0.10644"
"113.61600","9.46815","0.10638"
"113.76000","9.48029","0.10904"
"113.90400","9.49219","0.10929"
"114.04800","9.50414","0.06167"
"114.19200","9.51616","0.06156"
"114.33600","9.52824","0.06345"
"114.48000","9.54020","0.06272"
"114.62400","9.55216","0.06425"
"114.76800","9.56423","0.06451"
"114.91200","9.57625","0.06297"
"115.05600","9.58821","0.06419"
"115.20000","9.60011","0.06629"
"115.34400","9.61224","0.06618"
"115.48800","9.62426","0.06621"
"115.63200","9.63622","0.06862"
"115.77600","9.64818","0.06755"
"115.92000","9.66026","0.06697"
"116.06400","9.67221","0.06888"
"116.20800","9.68417","0.06860"
"116.35200","9.69619","0.06778"
"116.49600","9.70821","0.06404"
"116.64000","9.72022","0.06472"
"116.78400","9.73212","0.06201"
"116.92800","9.74420","0.06203"
"117.07200","9.75622","0.06329"
"117.21600","9.76823","0.06142"
"117.36000","9.78019","0.06027"
"117.50400","9.79221","0.06327"
"117.64800","9.80423","0.06250"
"117.79200","9.81619","0.06212"
"117.93600","9.82814","0.06319"
"118.08000","9.84022","0.06423"
"118.22400","9.85218","0.06123"
"118.36800","9.86414","0.06207"
"118.51200","9.87615","0.06430"
"118.65600","9.88817","0.06366"
"118.80000","9.90019","0.06313"
"118.94400","9.91215","0.06490"
"119.08800","9.92423","0.06556"
"119.23200","9.93624","0.06453"
"119.37600","9.94820","0.06677"
"119.52000","9.96016","0.06750"
"119.66400","9.97223","0.06631"
"119.80800","9.98425","0.06684"
"119.95200","9.99621","0.06788"
"120.09600","10.00817","0.06770"
"120.24000","10.02025","0.06765"
"120.38400","10.03221","0.06928"
"120.52800","10.04416","0.06847"
"120.67200","10.05612","0.06855"
"120.81600","10.06820","0.07000"
"120.96000","10.08016","0.07009"
"121.10400","10.09217","0.06953"
"121.24800","10.10419","0.07114"
"121.39200","10.11621","0.07195"
"121.53600","10.12817","0.07073"
"121.68000","10.14012","0.07176"
"121.82400","10.15220","0.07260"
"121.96800","10.16422","0.07199"
"122.11200","10.17618","0.07282"
"122.25600","10.18814","0.07365"
"122.40000","10.20021","0.07378"
"122.54400","10.21223","0.07371"
"122.68800","10.22413","0.07431"
"122.83200","10.23621","0.07468"
"122.97600","10.24823","0.07415"
"123.12000","10.26018","0.07472"
"123.26400","10.27214","0.07539"
"123.40800","10.28422","0.07522"
"123.55200","10.29618","0.07556"
"123.69600","10.30819","0.07575"
"123.84000","10.32015","0.07563"
"123.98400","10.33223","0.07588"
"124.12800","10.34425","0.07628"
"124.27200","10.35614","0.07637"
"124.41600","10.36816","0.07624"
"124.56000","10.38018","0.07671"
"124.70400","10.39220","0.07676"
"124.84800","10.40416","0.07692"
"124.99200","10.41617","0.07734"
"125.13600","10.42819","0.07736"
"125.28000","10.44021","0.07722"
"125.42400","10.45211","0.07771"
"125.56800","10.46424","0.07792"
"125.71200","10.47620","0.07768"
"125.85600","10.48822","0.07801"
"126.00000","10.50018","0.07811"
"126.14400","10.51220","0.07819"
"126.28800","10.52421","0.07846"
"126.43200","10.53617","0.07916"
"126.57600","10.54819","0.07895"
"126.72000","10.56015","0.07922"
"126.86400","10.57222","0.07987"
"127.00800","10.58412","0.07996"
"127.15200","10.59620","0.08003"
"127.29600","10.60822","0.08070"
"127.44000","10.62024","0.08090"
"127.58400","10.63213","0.08112"
"127.72800","10.64421","0.08214"
"127.87200","10.65617","0.08231"
"128.01600","10.66819","0.08252"
"128.16000","10.68014","0.08340"
"128.30400","10.69216","0.08408"
"128.44800","10.70418","0.08413"
"128.59200","10.71614","0.08572"
"128.73600","10.72810","0.08582"
"128.88000","10.74017","0.08631"
"129.02400","10.75213","0.08731"
"129.16800","10.76415","0.08788"
"129.31200","10.77617","0.08801"
"129.45600","10.78818","0.08982"
"129.60000","10.80014","0.09029"
"129.74400","10.81216","0.09104"
"129.88800","10.82418","0.09290"
"130.03200","10.83619","0.09410"
"130.17600","10.84815","0.09393"
"130.32000","10.86017","0.09602"
"130.46400","10.87219","0.09748"
"130.60800","10.88421","0.09739"
"130.75200","10.89616","0.09974"
"130.89600","10.90818","0.10051"
"131.04000","10.92020","0.10118"
"131.18400","10.93216","0.10257"
"131.32800","10.94412","0.10342"
"131.47200","10.95619","0.10393"
"131.61600","10.96815","0.10599"
"131.76000","10.98017","0.10671"
"131.90400","10.99207","0.10758"
"132.04800","11.00420","0.10920"
"132.19200","11.01622","0.10991"
"132.33600","11.02818","0.11098"
"132.48000","11.04014","0.11368"
"132.62400","11.05222","0.11530"
"132.76800","11.06417","0.11418"
"132.91200","11.07613","0.11808"
"133.05600","11.08821","0.11764"
"133.20000","11.10017","0.11956"
"133.34400","11.11218","0.12193"
"133.48800","11.12414","0.12241"
"133.63200","11.13622","0.12503"
"133.77600","11.14824","0.12619"
"133.92000","11.16019","0.12790"
"134.06400","11.17215","0.12903"
"134.20800","11.18417","0.13110"
"134.35200","11.19619","0.13244"
"134.49600","11.20815","0.13285"
"134.64000","11.22010","0.13407"
"134.78400","11.23218","0.13440"
"134.92800","11.24420","0.13483"
"135.07200","11.25616","0.13589"
"135.21600","11.26818","0.13609"
"135.36000","11.28013","0.13653"
"135.50400","11.29221","0.13685"
"135.64800","11.30411","0.08212"
"135.79200","11.31618","0.08130"
"135.93600","11.32820","0.08104"
"136.08000","11.34016","0.08009"
"136.22400","11.35212","0.08279"
"136.36800","11.36414","0.08227"
"136.51200","11.37615","0.08223"
"136.65600","11.38811","0.08444"
"136.80000","11.40013","0.08513"
"136.94400","11.41221","0.08456"
"137.08800","11.42423","0.08864"
"137.23200","11.43618","0.08893"
"137.37600","11.44820","0.08862"
"137.52000","11.46022","0.09155"
"137.66400","11.47218","0.09364"
"137.80800","11.48413","0.09236"
"137.95200","11.49615","0.09702"
"138.09600","11.50823","0.09893"
"138.24000","11.52013","0.09782"
"138.38400","11.53214","0.10254"
"138.52800","11.54422","0.10385"
"138.67200","11.55624","0.10346"
"138.81600","11.56814","0.10734"
"138.96000","11.58022","0.10839"
"139.10400","11.59217","0.10864"
"139.24800","11.60419","0.11223"
"139.39200","11.61615","0.11282"
"139.53600","11.62817","0.11341"
"139.68000","11.64019","0.11821"
"139.82400","11.65214","0.11848"
"139.96800","11.66410","0.11885"
"140.11200","11.67618","0.12327"
"140.25600","11.68820","0.12296"
"140.40000","11.70015","0.12410"
"140.54400","11.71211","0.12931"
"140.68800","11.72419","0.12900"
"140.83200","11.73621","0.13002"
"140.97600","11.74810","0.13287"
"141.12000","11.76012","0.13319"
"141.26400","11.77220","0.13432"
"141.40800","11.78416","0.13605"
"141.55200","11.79612","0.13565"
"141.69600","11.80819","0.13666"
"141.84000","11.82021","0.13711"
"141.98400","11.83217","0.13721"
"142.12800","11.84413","0.13781"
"142.27200","11.85614","0.13845"
"142.41600","11.86822","0.13833"
"142.56000","11.88018","0.13918"
"142.70400","11.89214","0.13943"
"142.84800","11.90422","0.13994"
"142.99200","11.91623","0.14130"
"143.13600","11.92819","0.14145"
"143.28000","11.94015","0.14188"
"143.42400","11.95223","0.14409"
"143.56800","11.96418","0.14361"
"143.71200","11.97614","0.14474"
"143.85600","11.98816","0.14666"
"144.00000","12.00018","0.14575"
"144.14400","12.01219","0.14812"
"144.28800","12.02409","0.14700"
"144.43200","12.03623","0.14531"
"144.57600","12.04819","0.14747"
"144.72000","12.06021","0.14786"
"144.86400","12.07216","0.14724"
"145.00800","12.08418","0.14947"
"145.15200","12.09620","0.15020"
"145.29600","12.10816","0.15138"
"145.44000","12.12018","0.15458"
"145.58400","12.13219","0.15482"
"145.72800","12.14421","0.15565"
"145.87200","12.15617","0.15769"
"146.01600","12.16819","0.15649"
"146.16000","12.18014","0.15829"
"146.30400","12.19216","0.15962"
"146.44800","12.20412","0.15888"
"146.59200","12.21620","0.16099"
"146.73600","12.22821","0.16225"
"146.88000","12.24017","0.16251"
"147.02400","12.25213","0.16459"
"147.16800","12.26421","0.16521"
"147.31200","12.27623","0.16683"
"147.45600","12.28812","0.16829"
"147.60000","12.30020","0.16842"
"147.74400","12.31222","0.16984"
"147.88800","12.32424","0.17138"
"148.03200","12.33614","0.17155"
"148.17600","12.34821","0.17288"
"148.32000","12.36023","0.17310"
"148.46400","12.37219","0.17390"
"148.60800","12.38415","0.17532"
"148.75200","12.39622","0.17548"
"148.89600","12.40818","0.17687"
"149.04000","12.42014","0.17777"
"149.18400","12.43216","0.17775"
"149.32800","12.44423","0.17881"
"149.47200","12.45619","0.17923"
"149.61600","12.46815","0.17947"
"149.76000","12.48023","0.18066"
"149.90400","12.49224","0.18065"
"150.04800","12.50420","0.18143"
"150.19200","12.51616","0.18214"
"150.33600","12.52812","0.18205"
"150.48000","12.54020","0.18301"
"150.62400","12.55216","0.18286"
"150.76800","12.56417","0.18294"
"150.91200","12.57619","0.18372"
"151.05600","12.58821","0.18403"
"151.20000","12.60017","0.18454"
"151.34400","12.61218","0.18528"
"151.48800","12.62426","0.18537"
"151.63200","12.63622","0.18655"
"151.77600","12.64818","0.18676"
"151.92000","12.66019","0.18679"
"152.06400","12.67221","0.18798"
"152.20800","12.68423","0.18782"
"152.35200","12.69619","0.18871"
"152.49600","12.70826","0.18898"
"152.64000","12.72022","0.18917"
"152.78400","12.73224","0.19020"
"152.92800","12.74420","0.19065"
"153.07200","12.75628","0.19124"
"153.21600","12.76824","0.19177"
"153.36000","12.78019","0.19190"
"153.50400","12.79221","0.19327"
"153.64800","12.80423","0.19345"
"153.79200","12.81619","0.19451"
"153.93600","12.82814","0.19566"
"154.08000","12.84016","0.19564"
"154.22400","12.85218","0.19770"
"154.36800","12.86414","0.19844"
"154.51200","12.87615","0.19856"
"154.65600","12.88817","0.20045"
"154.80000","12.90019","0.20052"
"154.94400","12.91215","0.20174"
"155.08800","12.92422","0.20302"
"155.23200","12.93624","0.20215"
"155.37600","12.94820","0.20508"
"155.52000","12.96022","0.20528"
"155.66400","12.97218","0.20638"
"155.80800","12.98425","0.20706"
"155.95200","12.99621","0.20722"
"156.09600","13.00817","0.20894"
"156.24000","13.02025","0.20944"
"156.38400","13.03226","0.21104"
"156.52800","13.04416","0.21162"
"156.67200","13.05618","0.21267"
"156.81600","13.06826","0.21389"
"156.96000","13.08022","0.21465"
"157.10400","13.09217","0.21584"
"157.24800","13.10419","0.21637"
"157.39200","13.11627","0.21706"
"157.53600","13.12829","0.21869"
"157.68000","13.14012","0.21931"
"157.82400","13.15220","0.22039"
"157.96800","13.16416","0.22158"
"158.11200","13.17618","0.22185"
"158.25600","13.18808","0.22340"
"158.40000","13.20021","0.22438"
"158.54400","13.21223","0.22546"
"158.68800","13.22419","0.22681"
"158.83200","13.23615","0.22688"
"158.97600","13.24822","0.22758"
"159.12000","13.26024","0.22785"
"159.26400","13.27220","0.22845"
"159.40800","13.28416","0.22933"
"159.55200","13.29624","0.22960"
"159.69600","13.30825","0.23053"
"159.84000","13.32015","0.23076"
"159.98400","13.33223","0.23202"
"160.12800","13.34419","0.23275"
"160.27200","13.35620","0.23305"
"160.41600","13.36816","0.23503"
"160.56000","13.38018","0.23536"
"160.70400","13.39220","0.23710"
"160.84800","13.40421","0.23824"
"160.99200","13.41617","0.23903"
"161.13600","13.42825","0.24165"
"161.28000","13.44021","0.24243"
"161.42400","13.45217","0.24432"
"161.56800","13.46419","0.24594"
"161.71200","13.47620","0.24722"
"161.85600","13.48816","0.24978"
"162.00000","13.50018","0.25102"
"162.14400","13.51214","0.25262"
"162.28800","13.52415","0.25443"
"162.43200","13.53617","0.25571"
"162.57600","13.54813","0.25719"
"162.72000","13.56021","0.25887"
"162.86400","13.57222","0.26134"
"163.00800","13.58418","0.26210"
"163.15200","13.59614","0.26343"
"163.29600","13.60822","0.26499"
"163.44000","13.62018","0.26579"
"163.58400","13.63213","0.26773"
"163.72800","13.64415","0.26784"
"163.87200","13.65623","0.27021"
"164.01600","13.66819","0.27164"
"164.16000","13.68015","0.27282"
"164.30400","13.69216","0.27422"
"164.44800","13.70424","0.27545"
"164.59200","13.71620","0.27716"
"164.73600","13.72816","0.27787"
"164.88000","13.74023","0.27956"
"165.02400","13.75213","0.27841"
"165.16800","13.76415","0.27921"
"165.31200","13.77617","0.28104"
"165.45600","13.78818","0.28099"
"165.60000","13.80020","0.28210"
"165.74400","13.81216","0.28243"
"165.88800","13.82418","0.28383"
"166.03200","13.83619","0.28447"
"166.17600","13.84821","0.28538"
"166.32000","13.86011","0.28631"
"166.46400","13.87219","0.28749"
"166.60800","13.88421","0.28828"
"166.75200","13.89616","0.28812"
"166.89600","13.90812","0.28870"
"167.04000","13.92026","0.28886"
"167.18400","13.93222","0.28958"
"167.32800","13.94417","0.29008"
"167.47200","13.95613","0.28990"
"167.61600","13.96821","0.29004"
"167.76000","13.98023","0.29045"
"167.90400","13.99213","0.29053"
"168.04800","14.00414","0.29069"
"168.19200","14.01616","0.29081"
"168.33600","14.02818","0.29099"
"168.48000","14.04008","0.29106"
"168.62400","14.05221","0.29113"
"168.76800","14.06423","0.29122"
"168.91200","14.07619","0.29124"
"169.05600","14.08815","0.29117"
"169.20000","14.10023","0.29132"
"169.34400","14.11224","0.29139"
"169.48800","14.12420","0.29156"
"169.63200","14.13616","0.29162"
"169.77600","14.14818","0.29164"
"169.92000","14.16026","0.20367"
"170.06400","14.17215","0.19983"
"170.20800","14.18423","0.20948"
"170.35200","14.19619","0.20459"
"170.49600","14.20815","0.21072"
"170.64000","14.22010","0.21389"
"170.78400","14.23218","0.21209"
"170.92800","14.24420","0.21883"
"171.07200","14.25622","0.21571"
"171.21600","14.26817","0.21904"
"171.36000","14.28025","0.22266"
"171.50400","14.29221","0.22140"
"171.64800","14.30417","0.22640"
"171.79200","14.31619","0.22407"
"171.93600","14.32820","0.22700"
"172.08000","14.34016","0.22855"
"172.22400","14.35218","0.22748"
"172.36800","14.36420","0.23138"
"172.51200","14.37615","0.23019"
"172.65600","14.38811","0.23160"
"172.80000","14.40013","0.23450"
"172.94400","14.41215","0.23315"
"173.08800","14.42417","0.23945"
"173.23200","14.43612","0.23722"
"173.37600","14.44820","0.24171"
"173.52000","14.46022","0.24597"
"173.66400","14.47224","0.24399"
"173.80800","14.48419","0.25366"
"173.95200","14.49621","0.25113"
"174.09600","14.50823","0.25768"
"174.24000","14.52019","0.25881"
"174.38400","14.53209","0.25840"
"174.52800","14.54422","0.26424"
"174.67200","14.55618","0.26258"
"174.81600","14.56820","0.22872"
"174.96000","14.58010","0.19491"
"175.10400","14.59223","0.19473"
"175.24800","14.60419","0.19640"
"175.39200","14.61615","0.19102"
"175.53600","14.62811","0.18968"
"175.68000","14.64019","0.18962"
"175.82400","14.65214","0.18910"
"175.96800","14.66416","0.19070"
"176.11200","14.67618","0.18995"
"176.25600","14.68820","0.19189"
"176.40000","14.70015","0.19251"
"176.54400","14.71211","0.19152"
"176.68800","14.72419","0.19395"
"176.83200","14.73621","0.19373"
"176.97600","14.74816","0.19443"
"177.12000","14.76018","0.19712"
"177.26400","14.77220","0.19743"
"177.40800","14.78422","0.19827"
"177.55200","14.79618","0.20021"
"177.69600","14.80819","0.19935"
"177.84000","14.82021","0.20296"
"177.98400","14.83223","0.20184"
"178.12800","14.84413","0.20310"
"178.27200","14.85620","0.20348"
"178.41600","14.86816","0.20185"
"178.56000","14.88018","0.20513"
"178.70400","14.89214","0.20492"
"178.84800","14.90422","0.20570"
"178.99200","14.91623","0.20737"
"179.13600","14.92819","0.20563"
"179.28000","14.94015","0.20359"
"179.42400","14.95217","0.18947"
"179.56800","14.96418","0.18935"
"179.71200","14.97614","0.18930"
"179.85600","14.98810","0.18901"
"180.00000","15.00018","0.18948"
"180.14400","15.01220","0.19048"
"180.28800","15.02415","0.19003"
"180.43200","15.03617","0.19054"
"180.57600","15.04819","0.19033"
"180.72000","15.06015","0.19060"
"180.86400","15.07211","0.19169"
"181.00800","15.08418","0.19167"
"181.15200","15.09620","0.19248"
"181.29600","15.10816","0.19229"
"181.44000","15.12018","0.19260"
"181.58400","15.13219","0.19364"
"181.72800","15.14421","0.19343"
"181.87200","15.15611","0.19376"
"182.01600","15.16819","0.19443"
"182.16000","15.18014","0.19429"
"182.30400","15.19216","0.19550"
"182.44800","15.20412","0.19573"
"182.59200","15.21620","0.19562"
"182.73600","15.22821","0.19737"
"182.88000","15.24017","0.19578"
"183.02400","15.25213","0.19707"
"183.16800","15.26421","0.19724"
"183.31200","15.27623","0.19712"
"183.45600","15.28818","0.19827"
"183.60000","15.30014","0.19727"
"183.74400","15.31222","0.19817"
"183.88800","15.32418","0.19916"
"184.03200","15.33614","0.19901"
"184.17600","15.34815","0.20034"
"184.32000","15.36023","0.20079"
"184.46400","15.37219","0.20052"
"184.60800","15.38415","0.20173"
"184.75200","15.39622","0.20189"
"184.89600","15.40824","0.20355"
"185.04000","15.42014","0.20382"
"185.18400","15.43210","0.20345"
"185.32800","15.44417","0.20471"
"185.47200","15.45619","0.20437"
"185.61600","15.46815","0.20608"
"185.76000","15.48011","0.20653"
"185.90400","15.49219","0.20583"
"186.04800","15.50420","0.20726"
"186.19200","15.51616","0.20620"
"186.33600","15.52818","0.20648"
"186.48000","15.54020","0.20681"
"186.62400","15.55222","0.20703"
"186.76800","15.56411","0.20788"
"186.91200","15.57619","0.20849"
"187.05600","15.58821","0.20821"
"187.20000","15.60017","0.21026"
"187.34400","15.61212","0.20942"
"187.48800","15.62420","0.21035"
"187.63200","15.63616","0.21041"
"187.77600","15.64818","0.21095"
"187.92000","15.66019","0.21144"
"188.06400","15.67221","0.21127"
"188.20800","15.68417","0.21259"
"188.35200","15.69619","0.21246"
"188.49600","15.70820","0.21327"
"188.64000","15.72022","0.21519"
"188.78400","15.73218","0.21445"
"188.92800","15.74420","0.21565"
"189.07200","15.75622","0.21602"
"189.21600","15.76817","0.21606"
"189.36000","15.78019","0.21767"
"189.50400","15.79215","0.21729"
"189.64800","15.80423","0.21760"
"189.79200","15.81618","0.21940"
"189.93600","15.82814","0.21956"
"190.08000","15.84016","0.22018"
"190.22400","15.85218","0.22054"
"190.36800","15.86419","0.22135"
"190.51200","15.87609","0.22210"
"190.65600","15.88823","0.22190"
"190.80000","15.90019","0.22372"
"190.94400","15.91221","0.22288"
"191.08800","15.92416","0.22407"
"191.23200","15.93624","0.22503"
"191.37600","15.94820","0.22508"
"191.52000","15.96022","0.22523"
"191.66400","15.97217","0.22618"
"191.80800","15.98425","0.22632"
"191.95200","15.99621","0.22710"
"192.09600","16.00817","0.22674"
"192.24000","16.02019","0.22733"
"192.38400","16.03226","0.22791"
"192.52800","16.04422","0.22789"
"192.67200","16.05618","0.22793"
"192.81600","16.06820","0.22775"
"192.96000","16.08022","0.22811"
"193.10400","16.09223","0.22882"
"193.24800","16.10419","0.22858"
"193.39200","16.11621","0.22936"
"193.53600","16.12823","0.22932"
"193.68000","16.14018","0.23001"
"193.82400","16.15220","0.23014"
"193.96800","16.16422","0.23035"
"194.11200","16.17618","0.23112"
"194.25600","16.18819","0.23139"
"194.40000","16.20015","0.23173"
"194.54400","16.21217","0.23225"
"194.68800","16.22419","0.23273"
"194.83200","16.23615","0.23371"
"194.97600","16.24817","0.23459"
"195.12000","16.26024","0.23552"
"195.26400","16.27220","0.23618"
"195.40800","16.28416","0.23592"
"195.55200","16.29623","0.23744"
"195.69600","16.30819","0.23784"
"195.84000","16.32021","0.23799"
"195.98400","16.33217","0.23867"
"196.12800","16.34425","0.23928"
"196.27200","16.35620","0.24118"
"196.41600","16.36822","0.24198"
"196.56000","16.38018","0.24239"
"196.70400","16.39226","0.24393"
"196.84800","16.40421","0.24570"
"196.99200","16.41623","0.24546"
"197.13600","16.42819","0.24555"
"197.28000","16.44027","0.24849"
"197.42400","16.45222","0.24852"
"197.56800","16.46418","0.24964"
"197.71200","16.47620","0.25059"
"197.85600","16.48816","0.25226"
"198.00000","16.50012","0.25292"
"198.14400","16.51220","0.25402"
"198.28800","16.52421","0.25471"
"198.43200","16.53617","0.25600"
"198.57600","16.54819","0.25599"
"198.72000","16.56021","0.25636"
"198.86400","16.57222","0.25719"
"199.00800","16.58424","0.25754"
"199.15200","16.59620","0.25814"
"199.29600","16.60822","0.25925"
"199.44000","16.62023","0.25990"
"199.58400","16.63219","0.26115"
"199.72800","16.64415","0.26254"
"199.87200","16.65629","0.26369"
"200.01600","16.66819","0.26441"
"200.16000","16.68020","0.26609"
"200.30400","16.69222","0.26659"
"200.44800","16.70418","0.26757"
"200.59200","16.71626","0.26864"
"200.73600","16.72816","0.27024"
"200.88000","16.74017","0.27049"
"201.02400","16.75219","0.27113"
"201.16800","16.76427","0.27075"
"201.31200","16.77617","0.27068"
"201.45600","16.78824","0.27125"
"201.60000","16.80020","0.27085"
"201.74400","16.81216","0.27242"
"201.88800","16.82412","0.27278"
"202.03200","16.83619","0.27337"
"202.17600","16.84815","0.27405"
"202.32000","16.86017","0.27372"
"202.46400","16.87213","0.27431"
"202.60800","16.88421","0.12635"
"202.75200","16.89622","0.07316"
"202.89600","16.90812","0.08092"
"203.04000","16.92020","0.07612"
"203.18400","16.93221","0.07884"
"203.32800","16.94417","0.08028"
"203.47200","16.95613","0.07728"
"203.61600","16.96821","0.07819"
"203.76000","16.98023","0.08135"
"203.90400","16.99219","0.07999"
"204.04800","17.00414","0.07865"
"204.19200","17.01622","0.09255"
"204.33600","17.02824","0.08106"
"204.48000","17.04014","0.08239"
"204.62400","17.05215","0.08815"
"204.76800","17.06417","0.08385"
"204.91200","17.07619","0.08250"
"205.05600","17.08809","0.09328"
"205.20000","17.10016","0.09044"
"205.34400","17.11218","0.08578"
"205.48800","17.12420","0.09967"
"205.63200","17.13616","0.09353"
"205.77600","17.14824","0.09059"
"205.92000","17.16019","0.10207"
"206.06400","17.17215","0.09999"
"206.20800","17.18417","0.09352"
"206.35200","17.19625","0.10436"
"206.49600","17.20821","0.10217"
"206.64000","17.22016","0.09449"
"206.78400","17.23212","0.10795"
"206.92800","17.24420","0.10376"
"207.07200","17.25616","0.10191"
"207.21600","17.26811","0.11101"
"207.36000","17.28019","0.11211"
"207.50400","17.29221","0.10422"
"207.64800","17.30417","0.12067"
"207.79200","17.31613","0.11238"
"207.93600","17.32820","0.11161"
"208.08000","17.34016","0.12139"
"208.22400","17.35218","0.12241"
"208.36800","17.36414","0.11406"
"208.51200","17.37615","0.13226"
"208.65600","17.38823","0.12253"
"208.80000","17.40013","0.12493"
"208.94400","17.41221","0.13256"
"209.08800","17.42416","0.13016"
"209.23200","17.43618","0.12693"
"209.37600","17.44814","0.13645"
"209.52000","17.46022","0.12981"
"209.66400","17.47218","0.13366"
"209.80800","17.48419","0.13703"
"209.95200","17.49615","0.13505"
"210.09600","17.50823","0.13525"
"210.24000","17.52019","0.13831"
"210.38400","17.53214","0.13513"
"210.52800","17.54416","0.13769"
"210.67200","17.55618","0.13790"
"210.81600","17.56820","0.13634"
"210.96000","17.58010","0.13766"
"211.10400","17.59217","0.13894"
"211.24800","17.60419","0.13697"
"211.39200","17.61621","0.13974"
"211.53600","17.62811","0.13906"
"211.68000","17.64024","0.13880"
"211.82400","17.65220","0.14194"
"211.96800","17.66416","0.14116"
"212.11200","17.67612","0.14031"
"212.25600","17.68819","0.14769"
"212.40000","17.70021","0.14239"
"212.54400","17.71217","0.14471"
"212.68800","17.72413","0.15059"
"212.83200","17.73615","0.14572"
"212.97600","17.74822","0.14949"
"213.12000","17.76012","0.15331"
"213.26400","17.77220","0.14810"
"213.40800","17.78422","0.15410"
"213.55200","17.79618","0.15505"
"213.69600","17.80813","0.15284"
"213.84000","17.82021","0.15918"
"213.98400","17.83217","0.15723"
"214.12800","17.84418","0.15690"
"214.27200","17.85614","0.16203"
"214.41600","17.86822","0.15831"
"214.56000","17.88018","0.16062"
"214.57000","17.88102","0.16100"