File: Force_trajectories/170108_2/Specimen_RawData_2.csv
End date,"1/8/2017"
Specimen label,"11DG_unk1"
Maximum Load,"0.74045",N

Time,Extension,Load
(s),(mm),(N)
"0.00000","0.00000","0.00059"
"0.32400","0.02673","0.00110"
"0.64800","0.05429","0.00196"
"0.97200","0.08119","0.00250"
"1.29600","0.10822","0.00339"
"1.62000","0.13518","0.00353"
"1.94400","0.16227","0.00436"
"2.26800","0.18923","0.00380"
"2.59200","0.21620","0.00394"
"2.91600","0.24322","0.00416"
"3.24000","0.27025","0.00458"
"3.56400","0.29721","0.00496"
"3.88800","0.32424","0.00470"
"4.21200","0.35120","0.00490"
"4.53600","0.37823","0.00495"
"4.86000","0.40519","0.00571"
"5.18400","0.43216","0.00539"
"5.50800","0.45924","0.00589"
"5.83200","0.48615","0.00579"
"6.15600","0.51323","0.00595"
"6.48000","0.54020","0.00542"
"6.80400","0.56722","0.00604"
"7.12800","0.59425","0.00612"
"7.45200","0.62115","0.00650"
"7.77600","0.64824","0.00609"
"8.10000","0.67520","0.00630"
"8.42400","0.70223","0.00667"
"8.74800","0.72919","0.00677"
"9.07200","0.75616","0.00569"
"9.39600","0.78324","0.00627"
"9.72000","0.81021","0.00651"
"10.04400","0.83723","0.00678"
"10.36800","0.86420","0.00661"
"10.69200","0.89116","0.00650"
"11.01600","0.91825","0.00732"
"11.34000","0.94521","0.00723"
"11.66400","0.97218","0.00741"
"11.98800","0.99926","0.00731"
"12.31200","1.02617","0.00689"
"12.63600","1.05325","0.00740"
"12.96000","1.08022","0.00691"
"13.28400","1.10718","0.00709"
"13.60800","1.13427","0.00786"
"13.93200","1.16111","0.00762"
"14.25600","1.18820","0.00794"
"14.58000","1.21522","0.00741"
"14.90400","1.24219","0.00743"
"15.22800","1.26921","0.00754"
"15.55200","1.29618","0.00765"
"15.87600","1.32326","0.00789"
"16.20000","1.35017","0.00786"
"16.52400","1.37719","0.00802"
"16.84800","1.40428","0.00838"
"17.17200","1.43118","0.00820"
"17.49600","1.45827","0.00832"
"17.82000","1.48517","0.00784"
"18.14400","1.51220","0.00802"
"18.46800","1.53922","0.00800"
"18.79200","1.56619","0.00873"
"19.11600","1.59321","0.00810"
"19.44000","1.62024","0.00806"
"19.76400","1.64720","0.00825"
"20.08800","1.67423","0.00858"
"20.41200","1.70113","0.00849"
"20.73600","1.72822","0.00880"
"21.06000","1.75524","0.00873"
"21.38400","1.78215","0.00893"
"21.70800","1.80923","0.00904"
"22.03200","1.83620","0.00909"
"22.35600","1.86322","0.00877"
"22.68000","1.89025","0.00899"
"23.00400","1.91721","0.00891"
"23.32800","1.94424","0.00877"
"23.65200","1.97114","0.00878"
"23.97600","1.99823","0.00936"
"24.30000","2.02525","0.00963"
"24.62400","2.05216","0.00903"
"24.94800","2.07918","0.00942"
"25.27200","2.10615","0.00942"
"25.59600","2.13323","0.00911"
"25.92000","2.16026","0.00928"
"26.24400","2.18722","0.00933"
"26.56800","2.21419","0.00922"
"26.89200","2.24115","0.00986"
"27.21600","2.26824","0.00952"
"27.54000","2.29520","0.00995"
"27.86400","2.32223","0.00988"
"28.18800","2.34925","0.00951"
"28.51200","2.37622","0.00988"
"28.83600","2.40318","0.01015"
"29.16000","2.43021","0.01006"
"29.48400","2.45723","0.00996"
"29.80800","2.48426","0.01022"
"30.13200","2.51122","0.01022"
"30.45600","2.53825","0.01058"
"30.78000","2.56527","0.01041"
"31.10400","2.59218","0.01016"
"31.42800","2.61920","0.01054"
"31.75200","2.64616","0.01026"
"32.07600","2.67325","0.01069"
"32.40000","2.70027","0.01030"
"32.72400","2.72718","0.01038"
"33.04800","2.75426","0.01114"
"33.37200","2.78123","0.01045"
"33.69600","2.80819","0.01035"
"34.02000","2.83522","0.01126"
"34.34400","2.86218","0.01034"
"34.66800","2.88921","0.01141"
"34.99200","2.91617","0.01087"
"35.31600","2.94320","0.01102"
"35.64000","2.97022","0.01138"
"35.96400","2.99719","0.01094"
"36.28800","3.02421","0.01140"
"36.61200","3.05118","0.01111"
"36.93600","3.07820","0.01128"
"37.26000","3.10529","0.01102"
"37.58400","3.13213","0.01120"
"37.90800","3.15922","0.01157"
"38.23200","3.18624","0.01104"
"38.55600","3.21321","0.01207"
"38.88000","3.24023","0.01186"
"39.20400","3.26714","0.01177"
"39.52800","3.29422","0.01198"
"39.85200","3.32119","0.01202"
"40.17600","3.34821","0.01235"
"40.50000","3.37524","0.01196"
"40.82400","3.40214","0.01235"
"41.14800","3.42923","0.01222"
"41.47200","3.45619","0.01209"
"41.79600","3.48316","0.01242"
"42.12000","3.51024","0.01217"
"42.44400","3.53715","0.01236"
"42.76800","3.56423","0.01249"
"43.09200","3.59120","0.01227"
"43.41600","3.61822","0.01292"
"43.74000","3.64519","0.01267"
"44.06400","3.67209","0.01319"
"44.38800","3.69924","0.01286"
"44.71200","3.72626","0.01226"
"45.03600","3.75317","0.01313"
"45.36000","3.78025","0.01306"
"45.68400","3.80716","0.01298"
"46.00800","3.83424","0.01266"
"46.33200","3.86121","0.01338"
"46.65600","3.88817","0.01368"
"46.98000","3.91520","0.01312"
"47.30400","3.94210","0.01371"
"47.62800","3.96925","0.01296"
"47.95200","3.99627","0.01361"
"48.27600","4.02324","0.01382"
"48.60000","4.05020","0.01369"
"48.92400","4.07711","0.01325"
"49.24800","4.10419","0.01346"
"49.57200","4.13122","0.01407"
"49.89600","4.15818","0.01350"
"50.22000","4.18521","0.01405"
"50.54400","4.21217","0.01408"
"50.86800","4.23926","0.01371"
"51.19200","4.26622","0.01491"
"51.51600","4.29319","0.01426"
"51.84000","4.32021","0.01447"
"52.16400","4.34718","0.01395"
"52.48800","4.37426","0.01466"
"52.81200","4.40123","0.01446"
"53.13600","4.42819","0.01517"
"53.46000","4.45528","0.01305"
"53.78400","4.48218","0.01255"
"54.10800","4.50921","0.01273"
"54.43200","4.53623","0.01305"
"54.75600","4.56314","0.01252"
"55.08000","4.59022","0.01249"
"55.40400","4.61719","0.01259"
"55.72800","4.64427","0.01285"
"56.05200","4.67124","0.01289"
"56.37600","4.69814","0.01286"
"56.70000","4.72517","0.01292"
"57.02400","4.75219","0.01323"
"57.34800","4.77928","0.01389"
"57.67200","4.80624","0.01355"
"57.99600","4.83315","0.01364"
"58.32000","4.86029","0.01327"
"58.64400","4.88720","0.01326"
"58.96800","4.91422","0.01404"
"59.29200","4.94119","0.01365"
"59.61600","4.96821","0.01292"
"59.94000","4.99524","0.01319"
"60.26400","5.02214","0.01302"
"60.58800","5.04923","0.01328"
"60.91200","5.07625","0.01345"
"61.23600","5.10316","0.01375"
"61.56000","5.13018","0.01408"
"61.88400","5.15715","0.01413"
"62.20800","5.18423","0.01395"
"62.53200","5.21126","0.01376"
"62.85600","5.23822","0.01381"
"63.18000","5.26525","0.01370"
"63.50400","5.29221","0.01443"
"63.82800","5.31918","0.01391"
"64.15200","5.34626","0.01433"
"64.47600","5.37317","0.01438"
"64.80000","5.40019","0.01394"
"65.12400","5.42716","0.01295"
"65.44800","5.45418","0.01347"
"65.77200","5.48127","0.01371"
"66.09600","5.50817","0.01351"
"66.42000","5.53525","0.01385"
"66.74400","5.56216","0.01342"
"67.06800","5.58924","0.01353"
"67.39200","5.61627","0.01355"
"67.71600","5.64312","0.01423"
"68.04000","5.67020","0.01354"
"68.36400","5.69723","0.01403"
"68.68800","5.72425","0.01391"
"69.01200","5.75122","0.01426"
"69.33600","5.77818","0.01448"
"69.66000","5.80520","0.01473"
"69.98400","5.83223","0.01439"
"70.30800","5.85925","0.01451"
"70.63200","5.88622","0.01506"
"70.95600","5.91319","0.01486"
"71.28000","5.94027","0.01495"
"71.60400","5.96723","0.01523"
"71.92800","5.99414","0.01521"
"72.25200","6.02122","0.01586"
"72.57600","6.04819","0.01534"
"72.90000","6.07521","0.01573"
"73.22400","6.10224","0.01544"
"73.54800","6.12920","0.01576"
"73.87200","6.15623","0.01597"
"74.19600","6.18313","0.01592"
"74.52000","6.21028","0.01614"
"74.84400","6.23724","0.01608"
"75.16800","6.26421","0.01632"
"75.49200","6.29123","0.01630"
"75.81600","6.31820","0.01683"
"76.14000","6.34522","0.01714"
"76.46400","6.37219","0.01713"
"76.78800","6.39915","0.01705"
"77.11200","6.42624","0.01724"
"77.43600","6.45320","0.01733"
"77.76000","6.48023","0.01693"
"78.08400","6.50719","0.01755"
"78.40800","6.53422","0.01849"
"78.73200","6.56124","0.01794"
"79.05600","6.58815","0.01782"
"79.38000","6.61523","0.01743"
"79.70400","6.64220","0.01757"
"80.02800","6.66922","0.01813"
"80.35200","6.69619","0.01795"
"80.67600","6.72315","0.01805"
"81.00000","6.75024","0.01820"
"81.32400","6.77726","0.01873"
"81.64800","6.80417","0.01866"
"81.97200","6.83119","0.01901"
"82.29600","6.85822","0.01911"
"82.62000","6.88518","0.01891"
"82.94400","6.91221","0.01911"
"83.26800","6.93923","0.01956"
"83.59200","6.96626","0.01932"
"83.91600","6.99310","0.01989"
"84.24000","7.02019","0.02013"
"84.56400","7.04721","0.01964"
"84.88800","7.07418","0.02016"
"85.21200","7.10120","0.02061"
"85.53600","7.12811","0.02032"
"85.86000","7.15525","0.02100"
"86.18400","7.18222","0.02036"
"86.50800","7.20918","0.02090"
"86.83200","7.23621","0.02100"
"87.15600","7.26317","0.02124"
"87.48000","7.29020","0.02131"
"87.80400","7.31722","0.02099"
"88.12800","7.34419","0.02141"
"88.45200","7.37127","0.02169"
"88.77600","7.39818","0.02193"
"89.10000","7.42520","0.02160"
"89.42400","7.45223","0.02177"
"89.74800","7.47925","0.02154"
"90.07200","7.50622","0.02239"
"90.39600","7.53318","0.02264"
"90.72000","7.56021","0.02230"
"91.04400","7.58723","0.02248"
"91.36800","7.61420","0.02258"
"91.69200","7.64122","0.02202"
"92.01600","7.66813","0.02246"
"92.34000","7.69527","0.02352"
"92.66400","7.72224","0.02201"
"92.98800","7.74920","0.02265"
"93.31200","7.77623","0.02306"
"93.63600","7.80319","0.02244"
"93.96000","7.83022","0.02309"
"94.28400","7.85724","0.02303"
"94.60800","7.88421","0.02374"
"94.93200","7.91123","0.02360"
"95.25600","7.93820","0.02404"
"95.58000","7.96522","0.02372"
"95.90400","7.99225","0.02463"
"96.22800","8.01921","0.02372"
"96.55200","8.04624","0.02440"
"96.87600","8.07314","0.02502"
"97.20000","8.10023","0.02473"
"97.52400","8.12725","0.02432"
"97.84800","8.15416","0.02509"
"98.17200","8.18118","0.02453"
"98.49600","8.20821","0.02490"
"98.82000","8.23523","0.02481"
"99.14400","8.26226","0.02544"
"99.46800","8.28910","0.02554"
"99.79200","8.31619","0.02559"
"100.11600","8.34321","0.02605"
"100.44000","8.37024","0.02567"
"100.76400","8.39726","0.02602"
"101.08800","8.42417","0.02610"
"101.41200","8.45125","0.02656"
"101.73600","8.47816","0.02610"
"102.06000","8.50518","0.02657"
"102.38400","8.53227","0.02670"
"102.70800","8.55917","0.02642"
"103.03200","8.58619","0.02694"
"103.35600","8.61316","0.02703"
"103.68000","8.64025","0.02725"
"104.00400","8.66721","0.02725"
"104.32800","8.69418","0.02724"
"104.65200","8.72120","0.02763"
"104.97600","8.74823","0.02738"
"105.30000","8.77519","0.02763"
"105.62400","8.80221","0.02744"
"105.94800","8.82918","0.02768"
"106.27200","8.85620","0.02761"
"106.59600","8.88317","0.02781"
"106.92000","8.91020","0.02783"
"107.24400","8.93728","0.02813"
"107.56800","8.96412","0.02797"
"107.89200","8.99127","0.02801"
"108.21600","9.01824","0.02830"
"108.54000","9.04520","0.02795"
"108.86400","9.07228","0.02852"
"109.18800","9.09913","0.02852"
"109.51200","9.12621","0.02860"
"109.83600","9.15324","0.02887"
"110.16000","9.18021","0.02851"
"110.48400","9.20717","0.02858"
"110.80800","9.23413","0.02891"
"111.13200","9.26122","0.02949"
"111.45600","9.28824","0.02920"
"111.78000","9.31521","0.02904"
"112.10400","9.34223","0.02919"
"112.42800","9.36920","0.02939"
"112.75200","9.39622","0.02951"
"113.07600","9.42319","0.02924"
"113.40000","9.45021","0.02923"
"113.72400","9.47724","0.02916"
"114.04800","9.50420","0.02958"
"114.37200","9.53123","0.02952"
"114.69600","9.55825","0.02938"
"115.02000","9.58522","0.02935"
"115.34400","9.61224","0.02979"
"115.66800","9.63921","0.02961"
"115.99200","9.66617","0.02989"
"116.31600","9.69326","0.03004"
"116.64000","9.72016","0.03026"
"116.96400","9.74719","0.03015"
"117.28800","9.77415","0.03035"
"117.61200","9.80124","0.03064"
"117.93600","9.82820","0.03062"
"118.26000","9.85517","0.03069"
"118.58400","9.88225","0.03054"
"118.90800","9.90922","0.03070"
"119.23200","9.93624","0.03121"
"119.55600","9.96321","0.03111"
"119.88000","9.99017","0.03142"
"120.20400","10.01726","0.03162"
"120.52800","10.04416","0.03136"
"120.85200","10.07119","0.03165"
"121.17600","10.09821","0.03186"
"121.50000","10.12518","0.03172"
"121.82400","10.15220","0.03188"
"122.14800","10.17917","0.03226"
"122.47200","10.20625","0.03240"
"122.79600","10.23328","0.03280"
"123.12000","10.26018","0.03297"
"123.44400","10.28721","0.03322"
"123.76800","10.31417","0.03310"
"124.09200","10.34120","0.03314"
"124.41600","10.36822","0.03351"
"124.74000","10.39519","0.03380"
"125.06400","10.42227","0.03442"
"125.38800","10.44918","0.03423"
"125.71200","10.47614","0.03435"
"126.03600","10.50323","0.03468"
"126.36000","10.53019","0.03495"
"126.68400","10.55722","0.03469"
"127.00800","10.58418","0.03558"
"127.33200","10.61121","0.03553"
"127.65600","10.63823","0.03508"
"127.98000","10.66514","0.03536"
"128.30400","10.69222","0.03616"
"128.62800","10.71919","0.03638"
"128.95200","10.74621","0.03625"
"129.27600","10.77318","0.03723"
"129.60000","10.80014","0.03740"
"129.92400","10.82723","0.03802"
"130.24800","10.85425","0.03829"
"130.57200","10.88122","0.03826"
"130.89600","10.90824","0.03882"
"131.22000","10.93515","0.03898"
"131.54400","10.96223","0.03956"
"131.86800","10.98920","0.04031"
"132.19200","11.01616","0.04055"
"132.51600","11.04325","0.04088"
"132.84000","11.07021","0.03919"
"133.16400","11.09724","0.03955"
"133.48800","11.12426","0.03988"
"133.81200","11.15123","0.04080"
"134.13600","11.17825","0.04147"
"134.46000","11.20510","0.04106"
"134.78400","11.23224","0.04228"
"135.10800","11.25921","0.04279"
"135.43200","11.28623","0.04356"
"135.75600","11.31326","0.04464"
"136.08000","11.34016","0.04468"
"136.40400","11.36725","0.04560"
"136.72800","11.39421","0.04581"
"137.05200","11.42118","0.04634"
"137.37600","11.44826","0.04643"
"137.70000","11.47517","0.04744"
"138.02400","11.50225","0.04774"
"138.34800","11.52922","0.04903"
"138.67200","11.55618","0.04902"
"138.99600","11.58327","0.04931"
"139.32000","11.61017","0.04986"
"139.64400","11.63720","0.05034"
"139.96800","11.66416","0.05108"
"140.29200","11.69119","0.05140"
"140.61600","11.71821","0.05166"
"140.94000","11.74518","0.05017"
"141.26400","11.77226","0.05092"
"141.58800","11.79917","0.05170"
"141.91200","11.82613","0.05227"
"142.23600","11.85321","0.05238"
"142.56000","11.88018","0.05317"
"142.88400","11.90721","0.05301"
"143.20800","11.93423","0.05367"
"143.53200","11.96119","0.05422"
"143.85600","11.98822","0.05480"
"144.18000","12.01518","0.05476"
"144.50400","12.04221","0.05548"
"144.82800","12.06917","0.05612"
"145.15200","12.09620","0.05678"
"145.47600","12.12323","0.05707"
"145.80000","12.15013","0.05774"
"146.12400","12.17727","0.05777"
"146.44800","12.20424","0.05859"
"146.77200","12.23120","0.05914"
"147.09600","12.25823","0.05969"
"147.42000","12.28513","0.06013"
"147.74400","12.31222","0.06081"
"148.06800","12.33924","0.06061"
"148.39200","12.36621","0.06083"
"148.71600","12.39323","0.06188"
"149.04000","12.42020","0.06214"
"149.36400","12.44716","0.06092"
"149.68800","12.47419","0.06211"
"150.01200","12.50121","0.06269"
"150.33600","12.52824","0.06315"
"150.66000","12.55520","0.06389"
"150.98400","12.58223","0.06459"
"151.30800","12.60925","0.06537"
"151.63200","12.63616","0.06579"
"151.95600","12.66324","0.06653"
"152.28000","12.69015","0.06675"
"152.60400","12.71723","0.06723"
"152.92800","12.74426","0.06770"
"153.25200","12.77122","0.06809"
"153.57600","12.79819","0.06811"
"153.90000","12.82521","0.06868"
"154.22400","12.85218","0.06904"
"154.54800","12.87926","0.06974"
"154.87200","12.90617","0.06945"
"155.19600","12.93325","0.07036"
"155.52000","12.96022","0.07091"
"155.84400","12.98724","0.07117"
"156.16800","13.01421","0.07124"
"156.49200","13.04123","0.07125"
"156.81600","13.06820","0.07176"
"157.14000","13.09516","0.07224"
"157.46400","13.12225","0.07247"
"157.78800","13.14927","0.07372"
"158.11200","13.17618","0.07328"
"158.43600","13.20326","0.07379"
"158.76000","13.23023","0.07407"
"159.08400","13.25719","0.07468"
"159.40800","13.28428","0.07447"
"159.73200","13.31118","0.07451"
"160.05600","13.33827","0.07507"
"160.38000","13.36523","0.07570"
"160.70400","13.39220","0.07572"
"161.02800","13.41922","0.07600"
"161.35200","13.44613","0.07626"
"161.67600","13.47321","0.07615"
"162.00000","13.50018","0.07626"
"162.32400","13.52714","0.07637"
"162.64800","13.55423","0.07651"
"162.97200","13.58119","0.07688"
"163.29600","13.60822","0.07696"
"163.62000","13.63518","0.07731"
"163.94400","13.66221","0.07743"
"164.26800","13.68917","0.07778"
"164.59200","13.71614","0.07763"
"164.91600","13.74322","0.07750"
"165.24000","13.77019","0.07785"
"165.56400","13.79715","0.07779"
"165.88800","13.82424","0.07842"
"166.21200","13.85120","0.07871"
"166.53600","13.87823","0.07881"
"166.86000","13.90513","0.07899"
"167.18400","13.93216","0.07917"
"167.50800","13.95924","0.07865"
"167.83200","13.98621","0.07916"
"168.15600","14.01323","0.07962"
"168.48000","14.04020","0.07977"
"168.80400","14.06716","0.08044"
"169.12800","14.09425","0.08077"
"169.45200","14.12115","0.08058"
"169.77600","14.14824","0.08005"
"170.10000","14.17526","0.08059"
"170.42400","14.20223","0.08125"
"170.74800","14.22919","0.08223"
"171.07200","14.25616","0.08277"
"171.39600","14.28324","0.08290"
"171.72000","14.31021","0.08400"
"172.04400","14.33717","0.08359"
"172.36800","14.36420","0.08427"
"172.69200","14.39116","0.08545"
"173.01600","14.41825","0.08591"
"173.34000","14.44521","0.08711"
"173.66400","14.47218","0.08775"
"173.98800","14.49920","0.08996"
"174.31200","14.52617","0.09130"
"174.63600","14.55319","0.09337"
"174.96000","14.58016","0.09479"
"175.28400","14.60718","0.09647"
"175.60800","14.63421","0.09722"
"175.93200","14.66117","0.09985"
"176.25600","14.68826","0.10032"
"176.58000","14.71528","0.10226"
"176.90400","14.74219","0.10367"
"177.22800","14.76921","0.10588"
"177.55200","14.79618","0.10691"
"177.87600","14.82326","0.10864"
"178.20000","14.85023","0.10853"
"178.52400","14.87719","0.10930"
"178.84800","14.90428","0.11135"
"179.17200","14.93118","0.11210"
"179.49600","14.95820","0.11454"
"179.82000","14.98517","0.11583"
"180.14400","15.01220","0.11723"
"180.46800","15.03922","0.11809"
"180.79200","15.06619","0.12163"
"181.11600","15.09321","0.12347"
"181.44000","15.12024","0.12473"
"181.76400","15.14720","0.12676"
"182.08800","15.17417","0.12894"
"182.41200","15.20113","0.12971"
"182.73600","15.22821","0.13163"
"183.06000","15.25524","0.13333"
"183.38400","15.28215","0.13398"
"183.70800","15.30923","0.13470"
"184.03200","15.33620","0.13535"
"184.35600","15.36322","0.13642"
"184.68000","15.39018","0.13627"
"185.00400","15.41715","0.13708"
"185.32800","15.44429","0.13713"
"185.65200","15.47120","0.13759"
"185.97600","15.49822","0.13779"
"186.30000","15.52525","0.13834"
"186.62400","15.55216","0.13866"
"186.94800","15.57924","0.13925"
"187.27200","15.60614","0.14018"
"187.59600","15.63323","0.14102"
"187.92000","15.66019","0.14161"
"188.24400","15.68716","0.14364"
"188.56800","15.71424","0.14442"
"188.89200","15.74121","0.14620"
"189.21600","15.76823","0.14771"
"189.54000","15.79520","0.14960"
"189.86400","15.82216","0.15217"
"190.18800","15.84925","0.15351"
"190.51200","15.87621","0.15449"
"190.83600","15.90318","0.15602"
"191.16000","15.93020","0.15681"
"191.48400","15.95723","0.15768"
"191.80800","15.98419","0.16029"
"192.13200","16.01122","0.16104"
"192.45600","16.03812","0.16202"
"192.78000","16.06527","0.16139"
"193.10400","16.09217","0.16285"
"193.42800","16.11926","0.16431"
"193.75200","16.14622","0.16610"
"194.07600","16.17325","0.16740"
"194.40000","16.20027","0.16784"
"194.72400","16.22712","0.16940"
"195.04800","16.25420","0.17036"
"195.37200","16.28123","0.17169"
"195.69600","16.30825","0.17244"
"196.02000","16.33528","0.17395"
"196.34400","16.36218","0.17505"
"196.66800","16.38921","0.17564"
"196.99200","16.41617","0.17724"
"197.31600","16.44320","0.17846"
"197.64000","16.47028","0.17974"
"197.96400","16.49719","0.18061"
"198.28800","16.52421","0.18180"
"198.61200","16.55118","0.18215"
"198.93600","16.57820","0.18317"
"199.26000","16.60523","0.18392"
"199.58400","16.63219","0.18491"
"199.90800","16.65916","0.18599"
"200.23200","16.68624","0.18680"
"200.55600","16.71321","0.18730"
"200.88000","16.74023","0.18834"
"201.20400","16.76714","0.18895"
"201.52800","16.79422","0.18970"
"201.85200","16.82119","0.19061"
"202.17600","16.84815","0.19163"
"202.50000","16.87518","0.19273"
"202.82400","16.90220","0.19403"
"203.14800","16.92923","0.19524"
"203.47200","16.95625","0.19710"
"203.79600","16.98316","0.19906"
"204.12000","17.01030","0.20026"
"204.44400","17.03715","0.20285"
"204.76800","17.06423","0.20519"
"205.09200","17.09120","0.20714"
"205.41600","17.11816","0.20804"
"205.74000","17.14519","0.21052"
"206.06400","17.17215","0.21216"
"206.38800","17.19924","0.21378"
"206.71200","17.22620","0.21489"
"207.03600","17.25317","0.21747"
"207.36000","17.28019","0.21937"
"207.68400","17.30716","0.22059"
"208.00800","17.33424","0.22271"
"208.33200","17.36121","0.22451"
"208.65600","17.38823","0.22605"
"208.98000","17.41525","0.22698"
"209.30400","17.44222","0.22819"
"209.62800","17.46919","0.22929"
"209.95200","17.49621","0.23011"
"210.27600","17.52317","0.23190"
"210.60000","17.55026","0.23360"
"210.92400","17.57717","0.23519"
"211.24800","17.60419","0.23839"
"211.57200","17.63128","0.24139"
"211.89600","17.65818","0.24329"
"212.22000","17.68527","0.24678"
"212.54400","17.71217","0.25051"
"212.86800","17.73926","0.25257"
"213.19200","17.76628","0.25626"
"213.51600","17.79319","0.25959"
"213.84000","17.82021","0.26175"
"214.16400","17.84724","0.26270"
"214.48800","17.87420","0.26562"
"214.81200","17.90122","0.26749"
"215.13600","17.92819","0.27044"
"215.46000","17.95527","0.27243"
"215.78400","17.98218","0.27549"
"216.10800","18.00927","0.27875"
"216.43200","18.03623","0.28267"
"216.75600","18.06319","0.28476"
"217.08000","18.09022","0.28681"
"217.40400","18.11719","0.28831"
"217.72800","18.14421","0.28935"
"218.05200","18.17123","0.29011"
"218.37600","18.19814","0.29054"
"218.70000","18.22523","0.29059"
"219.02400","18.25219","0.29088"
"219.34800","18.27927","0.29102"
"219.67200","18.30624","0.29127"
"219.99600","18.33320","0.29153"
"220.32000","18.36023","0.29204"
"220.64400","18.38720","0.29299"
"220.96800","18.41422","0.29371"
"221.29200","18.44124","0.29456"
"221.61600","18.46821","0.29667"
"221.94000","18.49523","0.29909"
"222.26400","18.52214","0.30189"
"222.58800","18.54916","0.30426"
"222.91200","18.57625","0.30489"
"223.23600","18.60321","0.30836"
"223.56000","18.63024","0.31089"
"223.88400","18.65720","0.31343"
"224.20800","18.68423","0.31679"
"224.53200","18.71119","0.31917"
"224.85600","18.73816","0.32269"
"225.18000","18.76518","0.32687"
"225.50400","18.79221","0.33084"
"225.82800","18.81923","0.33361"
"226.15200","18.84614","0.33651"
"226.47600","18.87317","0.33813"
"226.80000","18.90025","0.33986"
"227.12400","18.92722","0.34175"
"227.44800","18.95418","0.34083"
"227.77200","18.98120","0.34196"
"228.09600","19.00817","0.34403"
"228.42000","19.03525","0.34704"
"228.74400","19.06222","0.34912"
"229.06800","19.08918","0.35355"
"229.39200","19.11621","0.35587"
"229.71600","19.14311","0.35857"
"230.04000","19.17026","0.36012"
"230.36400","19.19722","0.36198"
"230.68800","19.22425","0.36453"
"231.01200","19.25121","0.36645"
"231.33600","19.27812","0.36759"
"231.66000","19.30526","0.36984"
"231.98400","19.33217","0.37100"
"232.30800","19.35919","0.37266"
"232.63200","19.38616","0.37427"
"232.95600","19.41318","0.37590"
"233.28000","19.44021","0.37769"
"233.60400","19.46723","0.37908"
"233.92800","19.49420","0.38083"
"234.25200","19.52128","0.38292"
"234.57600","19.54819","0.38506"
"234.90000","19.57521","0.38651"
"235.22400","19.60218","0.38879"
"235.54800","19.62920","0.39026"
"235.87200","19.65623","0.39207"
"236.19600","19.68313","0.39425"
"236.52000","19.71022","0.39628"
"236.84400","19.73724","0.39857"
"237.16800","19.76415","0.40130"
"237.49200","19.79123","0.40480"
"237.81600","19.81814","0.40804"
"238.14000","19.84528","0.41232"
"238.46400","19.87225","0.41511"
"238.78800","19.89915","0.41905"
"239.11200","19.92630","0.42205"
"239.43600","19.95320","0.42481"
"239.76000","19.98023","0.42740"
"240.08400","20.00719","0.43070"
"240.40800","20.03422","0.43393"
"240.73200","20.06124","0.43694"
"241.05600","20.08821","0.43754"
"241.38000","20.11523","0.43862"
"241.70400","20.14226","0.43902"
"242.02800","20.16916","0.43972"
"242.35200","20.19619","0.44073"
"242.67600","20.22315","0.44420"
"243.00000","20.25023","0.44875"
"243.32400","20.27720","0.45589"
"243.64800","20.30416","0.46165"
"243.97200","20.33119","0.46606"
"244.29600","20.35822","0.46878"
"244.62000","20.38518","0.46715"
"244.94400","20.41226","0.46948"
"245.26800","20.43917","0.45134"
"245.59200","20.46626","0.44789"
"245.91600","20.49322","0.45647"
"246.24000","20.52019","0.45769"
"246.56400","20.54727","0.46556"
"246.88800","20.57424","0.46671"
"247.21200","20.60126","0.47316"
"247.53600","20.62817","0.47521"
"247.86000","20.65519","0.47989"
"248.18400","20.68222","0.48225"
"248.50800","20.70918","0.48644"
"248.83200","20.73627","0.48807"
"249.15600","20.76323","0.49125"
"249.48000","20.79026","0.49397"
"249.80400","20.81722","0.49662"
"250.12800","20.84418","0.49894"
"250.45200","20.87121","0.50061"
"250.77600","20.89824","0.50168"
"251.10000","20.92520","0.50260"
"251.42400","20.95223","0.50364"
"251.74800","20.97919","0.50479"
"252.07200","21.00622","0.50704"
"252.39600","21.03324","0.51031"
"252.72000","21.06020","0.51269"
"253.04400","21.08723","0.51644"
"253.36800","21.11420","0.51900"
"253.69200","21.14128","0.52352"
"254.01600","21.16818","0.52795"
"254.34000","21.19527","0.53352"
"254.66400","21.22223","0.53678"
"254.98800","21.24914","0.54021"
"255.31200","21.27622","0.54306"
"255.63600","21.30325","0.54516"
"255.96000","21.33021","0.54748"
"256.28400","21.35724","0.54970"
"256.60800","21.38415","0.55420"
"256.93200","21.41129","0.55742"
"257.25600","21.43814","0.56229"
"257.58000","21.46516","0.56674"
"257.90400","21.49224","0.56910"
"258.22800","21.51921","0.57214"
"258.55200","21.54623","0.55924"
"258.87600","21.57320","0.55905"
"259.20000","21.60022","0.56443"
"259.52400","21.62725","0.56593"
"259.84800","21.65416","0.57033"
"260.17200","21.68124","0.57323"
"260.49600","21.70821","0.57720"
"260.82000","21.73523","0.58117"
"261.14400","21.76219","0.58443"
"261.46800","21.78916","0.58714"
"261.79200","21.81624","0.58914"
"262.11600","21.84321","0.59030"
"262.44000","21.87018","0.59105"
"262.76400","21.89720","0.59173"
"263.08800","21.92416","0.59263"
"263.41200","21.95125","0.59347"
"263.73600","21.97821","0.59625"
"264.06000","22.00518","0.59804"
"264.38400","22.03221","0.60071"
"264.70800","22.05911","0.59507"
"265.03200","22.08625","0.59407"
"265.35600","22.11322","0.59723"
"265.68000","22.14013","0.60189"
"266.00400","22.16721","0.60784"
"266.32800","22.19417","0.61490"
"266.65200","22.22120","0.62070"
"266.97600","22.24822","0.62677"
"267.30000","22.27513","0.63216"
"267.62400","22.30215","0.63933"
"267.94800","22.32912","0.64480"
"268.27200","22.35626","0.64847"
"268.59600","22.38323","0.64973"
"268.92000","22.41013","0.65040"
"269.24400","22.43722","0.65152"
"269.56800","22.46418","0.65212"
"269.89200","22.49121","0.65574"
"270.21600","22.51823","0.66226"
"270.54000","22.54520","0.66692"
"270.86400","22.57222","0.67158"
"271.18800","22.59913","0.67617"
"271.51200","22.62621","0.67939"
"271.83600","22.65330","0.68311"
"272.16000","22.68020","0.68674"
"272.48400","22.70723","0.68996"
"272.80800","22.73413","0.69343"
"273.13200","22.76122","0.69575"
"273.45600","22.78824","0.69790"
"273.78000","22.81521","0.70055"
"274.10400","22.84223","0.70217"
"274.42800","22.86920","0.70389"
"274.75200","22.89622","0.70511"
"275.07600","22.92319","0.70765"
"275.40000","22.95015","0.71135"
"275.72400","22.97724","0.71699"
"276.04800","23.00420","0.72185"
"276.37200","23.03117","0.72689"
"276.69600","23.05825","0.73243"
"277.02000","23.08522","0.73648"
"277.34400","23.11218","0.60426"
"277.66800","23.13915","0.54547"
"277.99200","23.16623","0.53816"
"278.31600","23.19326","0.53272"
"278.64000","23.22016","0.51581"
"278.96400","23.24725","0.51341"
"279.28800","23.27427","0.52240"
"279.61200","23.30124","0.51783"
"279.93600","23.32826","0.52478"
"280.26000","23.35517","0.52278"
"280.58400","23.38219","0.52899"
"280.90800","23.40916","0.53697"
"281.23200","23.43624","0.53693"
"281.55600","23.46321","0.54217"
"281.88000","23.49017","0.54316"
"282.20400","23.51725","0.54685"
"282.52800","23.54416","0.54927"
"282.85200","23.57119","0.54956"
"283.17600","23.59827","0.55434"
"283.50000","23.62518","0.55719"
"283.82400","23.65220","0.56372"
"284.14800","23.67916","0.56637"
"284.47200","23.70625","0.56863"
"284.79600","23.73322","0.57212"
"285.12000","23.76012","0.31906"
"285.44400","23.78721","0.29093"
"285.76800","23.81423","0.29247"
"286.09200","23.84126","0.29515"
"286.41600","23.86822","0.29529"
"286.74000","23.89519","0.29548"
"287.06400","23.92221","0.29897"
"287.38800","23.94917","0.29978"
"287.71200","23.97614","0.30306"
"288.03600","24.00323","0.30649"
"288.36000","24.03019","0.30759"
"288.68400","24.05727","0.31236"
"289.00800","24.08424","0.31640"
"289.33200","24.11121","0.31991"
"289.65600","24.13829","0.32737"
"289.98000","24.16514","0.33303"
"290.30400","24.19222","0.33747"
"290.62800","24.21925","0.33991"
"290.95200","24.24621","0.34193"
"291.27600","24.27317","0.34234"
"291.60000","24.30014","0.34389"
"291.92400","24.32728","0.34696"
"292.24800","24.35419","0.35169"
"292.57200","24.38121","0.35786"
"292.89600","24.40818","0.36172"
"293.22000","24.43520","0.36484"
"293.54400","24.46223","0.36747"
"293.86800","24.48926","0.37014"
"294.19200","24.51622","0.37287"
"294.51600","24.54325","0.37549"
"294.84000","24.57015","0.37693"
"295.16400","24.59718","0.37918"
"295.48800","24.62420","0.38162"
"295.81200","24.65122","0.38426"
"296.13600","24.67819","0.38664"
"296.46000","24.70521","0.38934"
"296.78400","24.73224","0.39119"
"297.10800","24.75926","0.39380"
"297.43200","24.78617","0.39570"
"297.75600","24.81326","0.39884"
"298.08000","24.84016","0.40271"
"298.40400","24.86724","0.40579"
"298.72800","24.89421","0.40792"
"299.05200","24.92118","0.36946"
"299.37600","24.94826","0.37212"
"299.70000","24.97522","0.37123"
"300.02400","25.00219","0.37262"
"300.34800","25.02921","0.37343"
"300.67200","25.05618","0.37182"
"300.99600","25.08326","0.37337"
"301.32000","25.11017","0.37450"
"301.64400","25.13725","0.37542"
"301.96800","25.16422","0.37687"
"302.29200","25.19118","0.37823"
"302.61600","25.21815","0.37986"
"302.94000","25.24512","0.38102"
"303.26400","25.27226","0.38284"
"303.58800","25.29922","0.38426"
"303.91200","25.32619","0.38546"
"304.23600","25.35321","0.38704"
"304.56000","25.38018","0.38866"
"304.88400","25.40720","0.38990"
"305.20800","25.43423","0.39159"
"305.53200","25.46119","0.39226"
"305.85600","25.48822","0.39391"
"306.18000","25.51518","0.39533"
"306.50400","25.54221","0.39671"
"306.82800","25.56923","0.39867"
"307.15200","25.59620","0.40047"
"307.47600","25.62322","0.40227"
"307.80000","25.65013","0.40490"
"308.12400","25.67721","0.40576"
"308.44800","25.70430","0.40687"
"308.77200","25.73114","0.40946"
"309.09600","25.75823","0.41171"
"309.42000","25.78519","0.41368"
"309.74400","25.81222","0.41685"
"310.06800","25.83924","0.41944"
"310.39200","25.86615","0.42122"
"310.71600","25.89323","0.42417"
"311.04000","25.92020","0.42623"
"311.36400","25.94722","0.42927"
"311.68800","25.97419","0.42977"
"312.01200","26.00121","0.43234"
"312.33600","26.02824","0.43412"
"312.66000","26.05520","0.43577"
"312.98400","26.08223","0.43729"
"313.30800","26.10925","0.43841"
"313.63200","26.13622","0.43878"
"313.95600","26.16318","0.43906"
"314.28000","26.19021","0.43940"
"314.60400","26.21723","0.44013"
"314.92800","26.24426","0.44085"
"315.25200","26.27110","0.44258"
"315.57600","26.29825","0.44385"
"315.90000","26.32521","0.44767"
"316.22400","26.35224","0.45232"
"316.54800","26.37926","0.45615"
"316.87200","26.40617","0.45973"
"317.19600","26.43319","0.46333"
"317.52000","26.46016","0.46614"
"317.84400","26.48718","0.46937"
"318.16800","26.51421","0.47237"
"318.49200","26.54117","0.47509"
"318.81600","26.56826","0.47834"
"319.14000","26.59516","0.48015"
"319.46400","26.62219","0.48326"
"319.78800","26.64927","0.48567"
"320.11200","26.67618","0.48780"
"320.43600","26.70320","0.48980"
"320.76000","26.73017","0.49108"
"321.08400","26.75719","0.49225"
"321.40800","26.78428","0.49437"
"321.73200","26.81112","0.49605"
"322.05600","26.83827","0.49777"
"322.38000","26.86523","0.49885"
"322.70400","26.89220","0.50019"
"323.02800","26.91922","0.50124"
"323.35200","26.94619","0.50205"
"323.67600","26.97321","0.50291"
"324.00000","27.00023","0.50361"
"324.32400","27.02720","0.38537"
"324.64800","27.05422","0.38353"
"324.97200","27.08113","0.38097"
"325.29600","27.10822","0.38209"
"325.62000","27.13518","0.38281"
"325.94400","27.16221","0.38294"
"326.26800","27.18923","0.38458"
"326.59200","27.21614","0.38587"
"326.91600","27.24322","0.38671"
"327.24000","27.27024","0.38876"
"327.56400","27.29721","0.38981"
"327.88800","27.32417","0.39141"
"328.21200","27.35114","0.39292"
"328.53600","27.37822","0.39384"
"328.86000","27.40525","0.39582"
"329.18400","27.43222","0.39761"
"329.50800","27.45918","0.39874"
"329.83200","27.48621","0.40105"
"330.15600","27.51323","0.40320"
"330.48000","27.54020","0.40512"
"330.80400","27.56722","0.40810"
"331.12800","27.59425","0.41077"
"331.45200","27.62121","0.41362"
"331.77600","27.64824","0.41642"
"332.10000","27.67526","0.41990"
"332.42400","27.70216","0.42234"
"332.74800","27.72919","0.42381"
"333.07200","27.75616","0.42654"
"333.39600","27.78324","0.42912"
"333.72000","27.81021","0.43249"
"334.04400","27.83723","0.43391"
"334.36800","27.86426","0.43611"
"334.69200","27.89122","0.43715"
"335.01600","27.91825","0.43817"
"335.34000","27.94521","0.43841"
"335.66400","27.97218","0.43887"
"335.98800","27.99926","0.43909"
"336.31200","28.02616","0.43941"
"336.63600","28.05319","0.43967"
"336.96000","28.08027","0.44107"
"337.28400","28.10718","0.44242"
"337.60800","28.13420","0.44444"
"337.93200","28.16117","0.44655"
"338.25600","28.18819","0.45038"
"338.58000","28.21528","0.45277"
"338.90400","28.24219","0.45647"
"339.22800","28.26921","0.45931"
"339.55200","28.29617","0.46237"
"339.87600","28.32326","0.46488"
"340.20000","28.35022","0.46810"
"340.52400","28.37719","0.47059"
"340.84800","28.40421","0.47362"
"341.17200","28.43118","0.47594"
"341.49600","28.45827","0.47825"
"341.82000","28.48523","0.48112"
"342.14400","28.51220","0.48338"
"342.46800","28.53922","0.46949"
"342.79200","28.56618","0.47178"
"343.11600","28.59321","0.47434"
"343.44000","28.62023","0.47642"
"343.76400","28.64714","0.47823"
"344.08800","28.67428","0.47984"
"344.41200","28.70119","0.47799"
"344.73600","28.72828","0.46983"
"345.06000","28.75524","0.47270"
"345.38400","28.78220","0.47607"
"345.70800","28.80923","0.47929"
"346.03200","28.83619","0.48259"
"346.35600","28.86322","0.48566"
"346.68000","28.89018","0.48830"
"347.00400","28.91715","0.49047"
"347.32800","28.94423","0.29243"
"347.65200","28.97126","0.29027"
"347.97600","28.99816","0.28922"
"348.30000","29.02519","0.29056"
"348.62400","29.05215","0.29071"
"348.94800","29.07924","0.29076"
"349.27200","29.10620","0.29083"
"349.59600","29.13323","0.29079"
"349.92000","29.16025","0.29100"
"350.24400","29.18710","0.29101"
"350.56800","29.21424","0.29112"
"350.89200","29.24121","0.29119"
"351.21600","29.26823","0.29135"
"351.54000","29.29520","0.29152"
"351.86400","29.32216","0.29187"
"352.18800","29.34925","0.29245"
"352.51200","29.37621","0.29339"
"352.83600","29.40318","0.29358"
"353.16000","29.43020","0.29553"
"353.48400","29.45717","0.29658"
"353.80800","29.48425","0.29777"
"354.13200","29.51122","0.29926"
"354.45600","29.53824","0.30085"
"354.78000","29.56527","0.30318"
"355.10400","29.59217","0.30542"
"355.42800","29.61926","0.30719"
"355.75200","29.64622","0.30960"
"356.07600","29.67319","0.31164"
"356.40000","29.70021","0.31399"
"356.72400","29.72718","0.31604"
"357.04800","29.75420","0.31079"
"357.37200","29.78123","0.31176"
"357.69600","29.80819","0.31480"
"358.02000","29.83522","0.31675"
"358.34400","29.86212","0.32065"
"358.66800","29.88921","0.32403"
"358.99200","29.91623","0.32815"
"359.31600","29.94320","0.33155"
"359.64000","29.97022","0.32976"
"359.96400","29.99719","0.33323"
"360.28800","30.02421","0.33567"
"360.61200","30.05118","0.33712"
"360.93600","30.07820","0.33942"
"361.26000","30.10523","0.34071"
"361.58400","30.13219","0.34237"
"361.90800","30.15922","0.34378"
"362.23200","30.18624","0.34513"
"362.55600","30.21315","0.34715"
"362.88000","30.24023","0.35030"
"363.20400","30.26714","0.35303"
"363.52800","30.29422","0.35635"
"363.85200","30.32125","0.35895"
"364.17600","30.34821","0.36128"
"364.50000","30.37518","0.36393"
"364.82400","30.40220","0.36460"
"365.14800","30.42923","0.36641"
"365.47200","30.45619","0.36653"
"365.79600","30.48316","0.36857"
"366.12000","30.51018","0.36984"
"366.44400","30.53715","0.37139"
"366.76800","30.56417","0.37291"
"367.09200","30.59126","0.37523"
"367.41600","30.61816","0.37677"
"367.74000","30.64525","0.37841"
"368.06400","30.67209","0.37941"
"368.38800","30.69918","0.38162"
"368.71200","30.72626","0.38413"
"369.03600","30.75317","0.38561"
"369.36000","30.78025","0.38759"
"369.68400","30.80715","0.38904"
"370.00800","30.83424","0.39044"
"370.33200","30.86126","0.39266"
"370.65600","30.88817","0.39386"
"370.98000","30.91525","0.39556"
"371.30400","30.94222","0.39747"
"371.62800","30.96918","0.39383"
"371.95200","30.99621","0.39318"
"372.27600","31.02323","0.39439"
"372.60000","31.05026","0.39644"
"372.92400","31.07717","0.39814"
"373.24800","31.10413","0.40072"
"373.57200","31.13122","0.40296"
"373.89600","31.15812","0.40407"
"374.22000","31.18526","0.40665"
"374.54400","31.21223","0.40841"
"374.86800","31.23926","0.41055"
"375.19200","31.26628","0.41320"
"375.51600","31.29312","0.41279"
"375.84000","31.32021","0.41588"
"376.16400","31.34723","0.41911"
"376.48800","31.37420","0.42187"
"376.81200","31.40122","0.42407"
"377.13600","31.42819","0.42660"
"377.46000","31.45521","0.42973"
"377.78400","31.48218","0.43208"
"378.10800","31.50920","0.43465"
"378.43200","31.53623","0.43614"
"378.75600","31.56319","0.43747"
"379.08000","31.59028","0.43813"
"379.40400","31.61718","0.43867"
"379.72800","31.64421","0.43909"
"380.05200","31.67129","0.43918"
"380.37600","31.69814","0.43943"
"380.70000","31.72516","0.43969"
"381.02400","31.75219","0.44052"
"381.34800","31.77921","0.44176"
"381.67200","31.80624","0.44337"
"381.99600","31.83314","0.44624"
"382.32000","31.86023","0.44914"
"382.64400","31.88719","0.45215"
"382.96800","31.91422","0.45549"
"383.29200","31.94124","0.45926"
"383.61600","31.96815","0.46108"
"383.94000","31.99523","0.46494"
"384.26400","32.02220","0.46753"
"384.58800","32.04916","0.47057"
"384.91200","32.07625","0.44705"
"385.23600","32.10315","0.44815"
"385.56000","32.13024","0.45187"
"385.88400","32.15720","0.45474"
"386.20800","32.18417","0.45515"
"386.53200","32.21125","0.45796"
"386.85600","32.23816","0.46219"
"387.18000","32.26524","0.46392"
"387.50400","32.29227","0.46750"
"387.82800","32.31917","0.46983"
"388.15200","32.34620","0.47210"
"388.47600","32.37310","0.47530"
"388.80000","32.40025","0.47829"
"389.12400","32.42721","0.48089"
"389.44800","32.45424","0.48285"
"389.77200","32.48126","0.48476"
"390.09600","32.50816","0.48590"
"390.42000","32.53519","0.48799"
"390.74400","32.56227","0.48974"
"391.06800","32.58918","0.49102"
"391.39200","32.61621","0.49276"
"391.71600","32.64311","0.49419"
"392.04000","32.67020","0.49581"
"392.36400","32.69728","0.49716"
"392.68800","32.72419","0.49871"
"393.01200","32.75121","0.49880"
"393.33600","32.77812","0.50001"
"393.66000","32.80526","0.50027"
"393.98400","32.83229","0.50114"
"394.30800","32.85919","0.50146"
"394.63200","32.88622","0.50217"
"394.95600","32.91318","0.50281"
"395.28000","32.94027","0.50300"
"395.60400","32.96723","0.50334"
"395.92800","32.99419","0.50404"
"396.25200","33.02128","0.50462"
"396.57600","33.04819","0.50548"
"396.90000","33.07521","0.50626"
"397.22400","33.10224","0.50675"
"397.54800","33.12920","0.50822"
"397.87200","33.15622","0.50922"
"398.19600","33.18319","0.51046"
"398.52000","33.21016","0.51214"
"398.84400","33.23724","0.51364"
"399.16800","33.26414","0.51310"
"399.49200","33.29123","0.05167"
"399.81600","33.31820","0.06235"
"400.14000","33.34522","0.05229"
"400.46400","33.37225","0.06866"
"400.78800","33.39915","0.04987"
"401.11200","33.42624","0.05638"
"401.43600","33.45320","0.05437"
"401.76000","33.48022","0.04901"
"402.08400","33.50725","0.06159"
"402.40800","33.53415","0.04962"
"402.73200","33.56124","0.06354"
"403.05600","33.58815","0.05198"
"403.38000","33.61517","0.06234"
"403.70400","33.64220","0.05670"
"404.02800","33.66916","0.06010"
"404.35200","33.69625","0.06116"
"404.67600","33.72321","0.06114"
"405.00000","33.75024","0.06219"
"405.32400","33.77726","0.06500"
"405.64800","33.80416","0.06327"
"405.97200","33.83125","0.06784"
"406.29600","33.85822","0.06282"
"406.62000","33.88524","0.06989"
"406.94400","33.91226","0.06569"
"407.26800","33.93917","0.06948"
"407.59200","33.96626","0.06719"
"407.91600","33.99316","0.07018"
"408.24000","34.02013","0.06836"
"408.56400","34.04721","0.07024"
"408.88800","34.07417","0.07014"
"409.21200","34.10120","0.07114"
"409.53600","34.12816","0.07233"
"409.86000","34.15519","0.07176"
"410.18400","34.18221","0.07421"
"410.50800","34.20912","0.07286"
"410.83200","34.23620","0.07486"
"411.15600","34.26317","0.07415"
"411.48000","34.29020","0.07507"
"411.80400","34.31728","0.07524"
"412.12800","34.34418","0.07520"
"412.45200","34.37127","0.07622"
"412.77600","34.39823","0.07563"
"413.10000","34.42520","0.07656"
"413.42400","34.45222","0.07649"
"413.74800","34.47919","0.07687"
"414.07200","34.50627","0.07719"
"414.39600","34.53324","0.07715"
"414.72000","34.56020","0.07767"
"415.04400","34.58729","0.07757"
"415.36800","34.61419","0.07814"
"415.69200","34.64122","0.07810"
"416.01600","34.66819","0.07846"
"416.34000","34.69521","0.07919"
"416.66400","34.72223","0.07894"
"416.98800","34.74914","0.08002"
"417.31200","34.77622","0.08044"
"417.63600","34.80325","0.08098"
"417.96000","34.83021","0.08219"
"418.28400","34.85724","0.08202"
"418.60800","34.88414","0.08331"
"418.93200","34.91123","0.08406"
"419.25600","34.93819","0.08520"
"419.58000","34.96516","0.08644"
"419.90400","34.99224","0.08723"
"420.22800","35.01921","0.08843"
"420.55200","35.04623","0.08974"
"420.87600","35.07320","0.09098"
"421.20000","35.10016","0.09226"
"421.52400","35.12725","0.09333"
"421.84800","35.15421","0.09475"
"422.17200","35.18124","0.09567"
"422.49600","35.20820","0.09636"
"422.82000","35.23517","0.09810"
"423.14400","35.26219","0.09934"
"423.46800","35.28916","0.10121"
"423.79200","35.31618","0.10227"
"424.11600","35.34327","0.10393"
"424.44000","35.37023","0.10442"
"424.76400","35.39720","0.10526"
"425.08800","35.42422","0.10692"
"425.41200","35.45119","0.10732"
"425.73600","35.47821","0.10943"
"426.06000","35.50518","0.11065"
"426.38400","35.53226","0.11121"
"426.70800","35.55923","0.11233"
"427.03200","35.58619","0.11376"
"427.35600","35.61322","0.11507"
"427.68000","35.64018","0.11660"
"428.00400","35.66727","0.11665"
"428.32800","35.69411","0.11800"
"428.65200","35.72120","0.11994"
"428.97600","35.74822","0.12034"
"429.30000","35.77519","0.12112"
"429.62400","35.80221","0.12340"
"429.94800","35.82917","0.12474"
"430.27200","35.85626","0.12548"
"430.59600","35.88317","0.12629"
"430.92000","35.91019","0.12730"
"431.24400","35.93722","0.12860"
"431.56800","35.96424","0.13004"
"431.89200","35.99121","0.13112"
"432.21600","36.01823","0.13158"
"432.54000","36.04520","0.13228"
"432.86400","36.07228","0.13281"
"433.18800","36.09919","0.13393"
"433.51200","36.12615","0.13414"
"433.83600","36.15324","0.13458"
"434.16000","36.18020","0.13516"
"434.48400","36.20723","0.13580"
"434.80800","36.23419","0.13588"
"435.13200","36.26122","0.13613"
"435.45600","36.28824","0.13626"
"435.78000","36.31515","0.13649"
"436.10400","36.34223","0.13695"
"436.42800","36.36926","0.13685"
"436.75200","36.39622","0.13696"
"437.07600","36.42324","0.13722"
"437.40000","36.45021","0.13764"
"437.72400","36.47723","0.13757"
"438.04800","36.50420","0.13799"
"438.37200","36.53122","0.13805"
"438.69600","36.55825","0.13802"
"439.02000","36.58522","0.13849"
"439.34400","36.61230","0.13856"
"439.66800","36.63921","0.13888"
"439.99200","36.66617","0.13899"
"440.31600","36.69326","0.13919"
"440.64000","36.72016","0.13937"
"440.96400","36.74724","0.13988"
"441.28800","36.77421","0.14011"
"441.61200","36.80124","0.14049"
"441.93600","36.82826","0.14088"
"442.26000","36.85516","0.14075"
"442.58400","36.88225","0.14135"
"442.90800","36.90921","0.14164"
"443.23200","36.93618","0.14257"
"443.55600","36.96321","0.14325"
"443.88000","36.99017","0.14323"
"444.20400","37.01726","0.14359"
"444.52800","37.04422","0.14375"
"444.85200","37.07118","0.14451"
"445.17600","37.09827","0.14499"
"445.50000","37.12518","0.14556"
"445.82400","37.15226","0.14665"
"446.14800","37.17916","0.14721"
"446.47200","37.20619","0.14751"
"446.79600","37.23327","0.14848"
"447.12000","37.26012","0.14840"
"447.44400","37.28727","0.14937"
"447.76800","37.31423","0.14953"
"448.09200","37.34120","0.15027"
"448.41600","37.36816","0.15089"
"448.74000","37.39512","0.15061"
"449.06400","37.42221","0.15196"
"449.38800","37.44923","0.15205"
"449.71200","37.47620","0.15156"
"450.03600","37.50328","0.15316"
"450.36000","37.53019","0.15302"
"450.68400","37.55721","0.15408"
"451.00800","37.58418","0.15507"
"451.33200","37.61115","0.15597"
"451.65600","37.63823","0.15601"
"451.98000","37.66519","0.15665"
"452.30400","37.69222","0.15675"
"452.62800","37.71924","0.15683"
"452.95200","37.74621","0.15733"
"453.27600","37.77317","0.15771"
"453.60000","37.80014","0.15868"
"453.92400","37.82722","0.15869"
"454.24800","37.85425","0.16010"
"454.57200","37.88115","0.15963"
"454.89600","37.90818","0.15875"
"455.22000","37.93520","0.15845"
"455.54400","37.96223","0.15785"
"455.86800","37.98925","0.15172"
"456.19200","38.01616","0.14951"
"456.51600","38.04324","0.14963"
"456.84000","38.07021","0.14943"
"457.16400","38.09723","0.15018"
"457.48800","38.12420","0.15022"
"457.81200","38.15122","0.15097"
"458.13600","38.17825","0.15104"
"458.46000","38.20515","0.15307"
"458.78400","38.23218","0.15389"
"459.10800","38.25920","0.15528"
"459.43200","38.28617","0.15709"
"459.75600","38.31325","0.15738"
"460.08000","38.34022","0.15879"
"460.40400","38.36724","0.15798"
"460.72800","38.39421","0.15946"
"461.05200","38.42111","0.16030"
"461.37600","38.44820","0.15538"
"461.70000","38.47516","0.15138"
"462.02400","38.50225","0.15999"
"462.34800","38.52921","0.15362"
"462.67200","38.55618","0.15674"
"462.99600","38.58320","0.15874"
"463.32000","38.61023","0.15359"
"463.64400","38.63719","0.15928"
"463.96800","38.66422","0.16160"
"464.29200","38.69118","0.15795"
"464.61600","38.71827","0.16182"
"464.94000","38.74517","0.15616"
"465.26400","38.77225","0.03531"
"465.58800","38.79922","0.01568"
"465.91200","38.82613","0.01850"
"466.23600","38.85321","0.02766"
"466.56000","38.88018","0.02268"
"466.88400","38.90720","0.02078"
"467.20800","38.93423","0.02362"
"467.53200","38.96119","0.02477"
"467.85600","38.98822","0.02556"
"468.18000","39.01518","0.02029"
"468.50400","39.04215","0.02458"
"468.82800","39.06917","0.02551"
"469.15200","39.09620","0.02243"
"469.47600","39.12322","0.02503"
"469.80000","39.15018","0.02426"
"470.12400","39.17715","0.02480"
"470.44800","39.20423","0.02459"
"470.77200","39.23120","0.02415"
"471.09600","39.25829","0.02596"
"471.42000","39.28519","0.02511"
"471.74400","39.31221","0.02503"
"472.06800","39.33918","0.02495"
"472.39200","39.36615","0.02548"
"472.71600","39.39323","0.02622"
"473.04000","39.42020","0.02501"
"473.36400","39.44716","0.02549"
"473.68800","39.47419","0.02538"
"474.01200","39.50115","0.02628"
"474.33600","39.52824","0.02628"
"474.66000","39.55520","0.02555"
"474.98400","39.58216","0.02645"
"475.30800","39.60925","0.02610"
"475.63200","39.63622","0.02616"
"475.95600","39.66324","0.02589"
"476.28000","39.69014","0.02640"
"476.60400","39.71717","0.02670"
"476.92800","39.74425","0.02667"
"477.25200","39.77116","0.02673"
"477.57600","39.79824","0.02663"
"477.90000","39.82527","0.02682"
"478.22400","39.85217","0.02703"
"478.54800","39.87925","0.02726"
"478.87200","39.90617","0.02707"
"479.19600","39.93325","0.02735"
"479.52000","39.96022","0.02707"
"479.84400","39.98717","0.02723"
"480.16800","40.01420","0.02770"
"480.49200","40.04117","0.02773"
"480.81600","40.06820","0.02753"
"481.14000","40.09522","0.02781"
"481.46400","40.12218","0.02764"
"481.78800","40.14927","0.02800"
"482.11200","40.17617","0.02837"
"482.43600","40.20326","0.02816"
"482.76000","40.23022","0.02786"
"483.08400","40.25719","0.02783"
"483.37800","40.28176","0.02846"