File: Force_trajectories/170108_2/Specimen_RawData_1.csv
End date,"1/8/2017"
Specimen label,"11DG_Unk2"
Maximum Load,"0.18525",N

Time,Extension,Load
(s),(mm),(N)
"0.00000","1.72068","-0.00531"
"0.29400","1.74454","-0.00482"
"0.58800","1.77001","-0.00451"
"0.88200","1.79446","-0.00466"
"1.17600","1.81898","-0.00462"
"1.47000","1.84343","-0.00441"
"1.76400","1.86800","-0.00409"
"2.05800","1.89240","-0.00447"
"2.35200","1.91697","-0.00397"
"2.64600","1.94137","-0.00447"
"2.94000","1.96594","-0.00377"
"3.23400","1.99039","-0.00392"
"3.52800","2.01497","-0.00411"
"3.82200","2.03936","-0.00368"
"4.11600","2.06393","-0.00383"
"4.41000","2.08839","-0.00391"
"4.70400","2.11290","-0.00370"
"4.99800","2.13742","-0.00348"
"5.29200","2.16187","-0.00339"
"5.58600","2.18644","-0.00398"
"5.88000","2.21096","-0.00346"
"6.17400","2.23547","-0.00370"
"6.46800","2.25992","-0.00366"
"6.76200","2.28444","-0.00384"
"7.05600","2.30889","-0.00329"
"7.35000","2.33341","-0.00350"
"7.64400","2.35792","-0.00354"
"7.93800","2.38237","-0.00354"
"8.23200","2.40695","-0.00311"
"8.52600","2.43140","-0.00364"
"8.82000","2.45591","-0.00348"
"9.11400","2.48037","-0.00340"
"9.40800","2.50494","-0.00345"
"9.70200","2.52934","-0.00308"
"9.99600","2.55391","-0.00292"
"10.29000","2.57836","-0.00330"
"10.58400","2.60294","-0.00335"
"10.87800","2.62739","-0.00284"
"11.17200","2.65185","-0.00278"
"11.46600","2.67642","-0.00319"
"11.76000","2.70087","-0.00309"
"12.05400","2.72545","-0.00266"
"12.34800","2.74984","-0.00279"
"12.64200","2.77441","-0.00265"
"12.93600","2.79887","-0.00256"
"13.23000","2.82344","-0.00232"
"13.52400","2.84790","-0.00254"
"13.81800","2.87247","-0.00249"
"14.11200","2.89692","-0.00294"
"14.40600","2.92144","-0.00364"
"14.70000","2.94595","-0.00292"
"14.99400","2.97040","-0.00357"
"15.28800","2.99492","-0.00339"
"15.58200","3.01931","-0.00335"
"15.87600","3.04389","-0.00317"
"16.17000","3.06840","-0.00289"
"16.46400","3.09291","-0.00309"
"16.75800","3.11743","-0.00318"
"17.05200","3.14194","-0.00267"
"17.34600","3.16645","-0.00304"
"17.64000","3.19091","-0.00282"
"17.93400","3.21548","-0.00300"
"18.22800","3.23993","-0.00309"
"18.52200","3.26445","-0.00321"
"18.81600","3.28884","-0.00292"
"19.11000","3.31342","-0.00303"
"19.40400","3.33793","-0.00313"
"19.69800","3.36244","-0.00296"
"19.99200","3.38690","-0.00298"
"20.28600","3.41141","-0.00282"
"20.58000","3.43593","-0.00222"
"20.87400","3.46038","-0.00290"
"21.16800","3.48489","-0.00282"
"21.46200","3.50941","-0.00277"
"21.75600","3.53392","-0.00232"
"22.05000","3.55831","-0.00274"
"22.34400","3.58289","-0.00261"
"22.63800","3.60734","-0.00276"
"22.93200","3.63192","-0.00294"
"23.22600","3.65643","-0.00253"
"23.52000","3.68094","-0.00291"
"23.81400","3.70540","-0.00212"
"24.10800","3.72985","-0.00236"
"24.40200","3.75442","-0.00215"
"24.69600","3.77894","-0.00244"
"24.99000","3.80339","-0.00269"
"25.28400","3.82791","-0.00211"
"25.57800","3.85242","-0.00173"
"25.87200","3.87687","-0.00206"
"26.16600","3.90139","-0.00199"
"26.46000","3.92590","-0.00186"
"26.75400","3.95041","-0.00223"
"27.04800","3.97493","-0.00199"
"27.34200","3.99938","-0.00199"
"27.63600","4.02396","-0.00187"
"27.93000","4.04835","-0.00225"
"28.22400","4.07292","-0.00150"
"28.51800","4.09732","-0.00238"
"28.81200","4.12195","-0.00249"
"29.10600","4.14640","-0.00242"
"29.40000","4.17092","-0.00109"
"29.69400","4.19543","-0.00182"
"29.98800","4.21994","-0.00158"
"30.28200","4.24446","-0.00169"
"30.57600","4.26885","-0.00183"
"30.87000","4.29343","-0.00171"
"31.16400","4.31788","-0.00166"
"31.45800","4.34239","-0.00163"
"31.75200","4.36685","-0.00170"
"32.04600","4.39142","-0.00160"
"32.34000","4.41588","-0.00150"
"32.63400","4.44045","-0.00163"
"32.92800","4.46496","-0.00109"
"33.22200","4.48936","-0.00090"
"33.51600","4.51393","-0.00100"
"33.81000","4.53838","-0.00116"
"34.10400","4.56290","-0.00091"
"34.39800","4.58735","-0.00134"
"34.69200","4.61193","-0.00063"
"34.98600","4.63638","-0.00062"
"35.28000","4.66095","-0.00124"
"35.57400","4.68541","-0.00096"
"35.86800","4.70992","-0.00087"
"36.16200","4.73449","-0.00068"
"36.45600","4.75895","-0.00074"
"36.75000","4.78340","-0.00031"
"37.04400","4.80786","-0.00081"
"37.33800","4.83243","-0.00076"
"37.63200","4.85688","-0.00083"
"37.92600","4.88146","-0.00080"
"38.22000","4.90585","-0.00087"
"38.51400","4.93042","-0.00094"
"38.80800","4.95488","-0.00058"
"39.10200","4.97939","-0.00059"
"39.39600","5.00397","-0.00047"
"39.69000","5.02842","-0.00038"
"39.98400","5.05293","-0.00042"
"40.27800","5.07739","0.00002"
"40.57200","5.10190","-0.00013"
"40.86600","5.12635","-0.00015"
"41.16000","5.15093","-0.00061"
"41.45400","5.17538","-0.00047"
"41.74800","5.19996","-0.00077"
"42.04200","5.22441","-0.00094"
"42.33600","5.24898","0.00008"
"42.63000","5.27350","0.00006"
"42.92400","5.29789","-0.00039"
"43.21800","5.32246","-0.00004"
"43.51200","5.34686","-0.00059"
"43.80600","5.37137","-0.00009"
"44.10000","5.39583","0.00009"
"44.39400","5.42046","0.00057"
"44.68800","5.44491","0.00015"
"44.98200","5.46943","0.00004"
"45.27600","5.49388","0.00049"
"45.57000","5.51833","0.00002"
"45.86400","5.54291","-0.00003"
"46.15800","5.56736","0.00020"
"46.45200","5.59194","0.00056"
"46.74600","5.61633","0.00032"
"47.04000","5.64090","0.00078"
"47.33400","5.66536","0.00038"
"47.62800","5.68993","0.00087"
"47.92200","5.71439","0.00045"
"48.21600","5.73890","0.00051"
"48.51000","5.76341","0.00095"
"48.80400","5.78793","0.00066"
"49.09800","5.81244","0.00070"
"49.39200","5.83695","0.00110"
"49.68600","5.86147","0.00050"
"49.98000","5.88586","0.00085"
"50.27400","5.91037","0.00099"
"50.56800","5.93489","0.00075"
"50.86200","5.95946","0.00088"
"51.15600","5.98386","0.00153"
"51.45000","6.00837","0.00164"
"51.74400","6.03288","0.00134"
"52.03800","6.05740","0.00173"
"52.33200","6.08197","0.00134"
"52.62600","6.10637","0.00119"
"52.92000","6.13094","0.00196"
"53.21400","6.15539","0.00141"
"53.50800","6.17997","0.00107"
"53.80200","6.20442","0.00197"
"54.09600","6.22893","0.00141"
"54.39000","6.25345","0.00178"
"54.68400","6.27796","0.00165"
"54.97800","6.30247","0.00215"
"55.27200","6.32699","0.00193"
"55.56600","6.35144","0.00271"
"55.86000","6.37590","0.00186"
"56.15400","6.40035","0.00285"
"56.44800","6.42486","0.00226"
"56.74200","6.44944","0.00183"
"57.03600","6.47383","0.00293"
"57.33000","6.49841","0.00168"
"57.62400","6.52286","0.00211"
"57.91800","6.54743","0.00243"
"58.21200","6.57189","0.00271"
"58.50600","6.59634","0.00278"
"58.80000","6.62091","0.00269"
"59.09400","6.64537","0.00264"
"59.38800","6.66994","0.00257"
"59.68200","6.69440","0.00277"
"59.97600","6.71897","0.00310"
"60.27000","6.74336","0.00303"
"60.56400","6.76794","0.00359"
"60.85800","6.79245","0.00322"
"61.15200","6.81696","0.00301"
"61.44600","6.84142","0.00374"
"61.74000","6.86593","0.00392"
"62.03400","6.89045","0.00322"
"62.32800","6.91484","0.00293"
"62.62200","6.93941","0.00353"
"62.91600","6.96381","0.00336"
"63.21000","6.98838","0.00357"
"63.50400","7.01289","0.00356"
"63.79800","7.03747","0.00456"
"64.09200","7.06186","0.00382"
"64.38600","7.08644","0.00409"
"64.68000","7.11095","0.00486"
"64.97400","7.13540","0.00401"
"65.26800","7.15992","0.00401"
"65.56200","7.18437","0.00406"
"65.85600","7.20894","0.00369"
"66.15000","7.23340","0.00448"
"66.44400","7.25797","0.00442"
"66.73800","7.28243","0.00454"
"67.03200","7.30694","0.00473"
"67.32600","7.33139","0.00423"
"67.62000","7.35591","0.00458"
"67.91400","7.38042","0.00456"
"68.20800","7.40487","0.00476"
"68.50200","7.42945","0.00476"
"68.79600","7.45384","0.00493"
"69.09000","7.47842","0.00523"
"69.38400","7.50287","0.00492"
"69.67800","7.52744","0.00553"
"69.97200","7.55184","0.00562"
"70.26600","7.57641","0.00534"
"70.56000","7.60086","0.00551"
"70.85400","7.62544","0.00556"
"71.14800","7.64989","0.00528"
"71.44200","7.67441","0.00547"
"71.73600","7.69892","0.00570"
"72.03000","7.72343","0.00567"
"72.32400","7.74801","0.00596"
"72.61800","7.77240","0.00588"
"72.91200","7.79691","0.00563"
"73.20600","7.82143","0.00563"
"73.50000","7.84594","0.00613"
"73.79400","7.87039","0.00553"
"74.08800","7.89497","0.00655"
"74.38200","7.91942","0.00660"
"74.67600","7.94388","0.00648"
"74.97000","7.96839","0.00697"
"75.26400","7.99290","0.00672"
"75.55800","8.01742","0.00598"
"75.85200","8.04187","0.00668"
"76.14600","8.06639","0.00678"
"76.44000","8.09090","0.00663"
"76.73400","8.11541","0.00696"
"77.02800","8.13993","0.00724"
"77.32200","8.16444","0.00727"
"77.61600","8.18901","0.00734"
"77.91000","8.21341","0.00701"
"78.20400","8.23798","0.00782"
"78.49800","8.26243","0.00711"
"78.79200","8.28695","0.00746"
"79.08600","8.31134","0.00761"
"79.38000","8.33592","0.00716"
"79.67400","8.36037","0.00709"
"79.96800","8.38494","0.00815"
"80.26200","8.40940","0.00788"
"80.55600","8.43391","0.00755"
"80.85000","8.45848","0.00778"
"81.14400","8.48288","0.00803"
"81.43800","8.50739","0.00851"
"81.73200","8.53179","0.00801"
"82.02600","8.55636","0.00830"
"82.32000","8.58081","0.00831"
"82.61400","8.60545","0.00623"
"82.90800","8.62984","0.00636"
"83.20200","8.65442","0.00623"
"83.49600","8.67893","0.00653"
"83.79000","8.70344","0.00688"
"84.08400","8.72796","0.00683"
"84.37800","8.75235","0.00697"
"84.67200","8.77692","0.00734"
"84.96600","8.80144","0.00715"
"85.26000","8.82595","0.00727"
"85.55400","8.85035","0.00692"
"85.84800","8.87492","0.00739"
"86.14200","8.89943","0.00715"
"86.43600","8.92389","0.00735"
"86.73000","8.94840","0.00757"
"87.02400","8.97291","0.00719"
"87.31800","8.99743","0.00744"
"87.61200","9.02188","0.00831"
"87.90600","9.04646","0.00796"
"88.20000","9.07091","0.00804"
"88.49400","9.09548","0.00760"
"88.78800","9.11982","0.00858"
"89.08200","9.14445","0.00833"
"89.37600","9.16890","0.00820"
"89.67000","9.19342","0.00745"
"89.96400","9.21793","0.00720"
"90.25800","9.24244","0.00666"
"90.55200","9.26696","0.00727"
"90.84600","9.29135","0.00753"
"91.14000","9.31599","0.00740"
"91.43400","9.34038","0.00794"
"91.72800","9.36495","0.00716"
"92.02200","9.38941","0.00789"
"92.31600","9.41392","0.00830"
"92.61000","9.43838","0.00776"
"92.90400","9.46289","0.00855"
"93.19800","9.48740","0.00796"
"93.49200","9.51192","0.00880"
"93.78600","9.53643","0.00841"
"94.08000","9.56088","0.00803"
"94.37400","9.58540","0.00887"
"94.66800","9.60979","0.00923"
"94.96200","9.63443","0.00909"
"95.25600","9.65888","0.00838"
"95.55000","9.68345","0.00925"
"95.84400","9.70791","0.00934"
"96.13800","9.73242","0.00970"
"96.43200","9.75694","0.00888"
"96.72600","9.78145","0.00941"
"97.02000","9.80596","0.00922"
"97.31400","9.83036","0.00851"
"97.60800","9.85493","0.00894"
"97.90200","9.87938","0.00939"
"98.19600","9.90396","0.00988"
"98.49000","9.92835","0.00964"
"98.78400","9.95292","0.00852"
"99.07800","9.97738","0.00847"
"99.37200","10.00189","0.00829"
"99.66600","10.02641","0.00856"
"99.96000","10.05092","0.00910"
"100.25400","10.07543","0.00903"
"100.54800","10.09989","0.00863"
"100.84200","10.12440","0.00901"
"101.13600","10.14886","0.00905"
"101.43000","10.17343","0.00951"
"101.72400","10.19782","0.00899"
"102.01800","10.22246","0.00930"
"102.31200","10.24691","0.00930"
"102.60600","10.27136","0.01004"
"102.90000","10.29594","0.00960"
"103.19400","10.32045","0.00931"
"103.48800","10.34496","0.00949"
"103.78200","10.36936","0.00924"
"104.07600","10.39393","0.00944"
"104.37000","10.41839","0.00951"
"104.66400","10.44296","0.00914"
"104.95800","10.46735","0.00956"
"105.25200","10.49193","0.00990"
"105.54600","10.51644","0.01050"
"105.84000","10.54090","0.00971"
"106.13400","10.56541","0.00996"
"106.42800","10.58986","0.01005"
"106.72200","10.61444","0.01062"
"107.01600","10.63889","0.01074"
"107.31000","10.66340","0.01006"
"107.60400","10.68786","0.01096"
"107.89800","10.71243","0.01084"
"108.19200","10.73688","0.01086"
"108.48600","10.76146","0.01114"
"108.78000","10.78585","0.01047"
"109.07400","10.81036","0.01083"
"109.36800","10.83494","0.01142"
"109.66200","10.85939","0.01114"
"109.95600","10.88397","0.01108"
"110.25000","10.90836","0.01131"
"110.54400","10.93287","0.01165"
"110.83800","10.95739","0.01165"
"111.13200","10.98196","0.01187"
"111.42600","11.00636","0.01243"
"111.72000","11.03093","0.01152"
"112.01400","11.05538","0.00994"
"112.30800","11.07984","0.00966"
"112.60200","11.10441","0.01000"
"112.89600","11.12892","0.00983"
"113.19000","11.15344","0.00860"
"113.48400","11.17783","0.00884"
"113.77800","11.20247","0.00856"
"114.07200","11.22692","0.00851"
"114.36600","11.25143","0.00843"
"114.66000","11.27589","0.00891"
"114.95400","11.30046","0.00845"
"115.24800","11.32491","0.00912"
"115.54200","11.34943","0.00932"
"115.83600","11.37394","0.00929"
"116.13000","11.39840","0.00941"
"116.42400","11.42291","0.00861"
"116.71800","11.44736","0.00953"
"117.01200","11.47194","0.00926"
"117.30600","11.49633","0.00899"
"117.60000","11.52091","0.01029"
"117.89400","11.54542","0.00923"
"118.18800","11.56993","0.01004"
"118.48200","11.59439","0.00996"
"118.77600","11.61890","0.00950"
"119.07000","11.64341","0.01032"
"119.36400","11.66787","0.01005"
"119.65800","11.69244","0.01049"
"119.95200","11.71684","0.01076"
"120.24600","11.74147","0.01005"
"120.54000","11.76586","0.01037"
"120.83400","11.79038","0.01069"
"121.12800","11.81489","0.01044"
"121.42200","11.83946","0.01114"
"121.71600","11.86398","0.01056"
"122.01000","11.88843","0.01132"
"122.30400","11.91295","0.01100"
"122.59800","11.93740","0.01114"
"122.89200","11.96191","0.01118"
"123.18600","11.98637","0.01147"
"123.48000","12.01094","0.01142"
"123.77400","12.03533","0.01148"
"124.06800","12.05997","0.01126"
"124.36200","12.08436","0.01193"
"124.65600","12.10894","0.01216"
"124.95000","12.13339","0.01219"
"125.24400","12.15790","0.01197"
"125.53800","12.18248","0.01201"
"125.83200","12.20687","0.01258"
"126.12600","12.23144","0.01234"
"126.42000","12.25584","0.01270"
"126.71400","12.28047","0.01219"
"127.00800","12.30492","0.01262"
"127.30200","12.32944","0.01240"
"127.59600","12.35389","0.01282"
"127.89000","12.37841","0.01315"
"128.18400","12.40292","0.01284"
"128.47800","12.42737","0.01233"
"128.77200","12.45195","0.01261"
"129.06600","12.47634","0.01270"
"129.36000","12.50086","0.01275"
"129.65400","12.52531","0.01233"
"129.94800","12.54994","0.01312"
"130.24200","12.57434","0.01340"
"130.53600","12.59897","0.01358"
"130.83000","12.62337","0.01297"
"131.12400","12.64788","0.01320"
"131.41800","12.67239","0.01383"
"131.71200","12.69691","0.01318"
"132.00600","12.72148","0.01343"
"132.30000","12.74587","0.01418"
"132.59400","12.77045","0.01381"
"132.88800","12.79490","0.01394"
"133.18200","12.81941","0.01392"
"133.47600","12.84387","0.01425"
"133.77000","12.86844","0.01378"
"134.06400","12.89290","0.01424"
"134.35800","12.91741","0.01444"
"134.65200","12.94192","0.01440"
"134.94600","12.96638","0.01419"
"135.24000","12.99095","0.01486"
"135.53400","13.01540","0.01461"
"135.82800","13.03992","0.01478"
"136.12200","13.06437","0.01431"
"136.41600","13.08895","0.01475"
"136.71000","13.11340","0.01511"
"137.00400","13.13791","0.01463"
"137.29800","13.16243","0.01500"
"137.59200","13.18694","0.01511"
"137.88600","13.21139","0.01545"
"138.18000","13.23591","0.01489"
"138.47400","13.26048","0.01508"
"138.76800","13.28487","0.01510"
"139.06200","13.30945","0.01506"
"139.35600","13.33390","0.01562"
"139.65000","13.35848","0.01558"
"139.94400","13.38287","0.01580"
"140.23800","13.40744","0.01576"
"140.53200","13.43190","0.01569"
"140.82600","13.45641","0.01591"
"141.12000","13.48099","0.01603"
"141.41400","13.50544","0.01606"
"141.70800","13.52995","0.01612"
"142.00200","13.55435","0.01595"
"142.29600","13.57886","0.01648"
"142.59000","13.60332","0.01635"
"142.88400","13.62795","0.01648"
"143.17800","13.65240","0.01629"
"143.47200","13.67692","0.01649"
"143.76600","13.70143","0.01678"
"144.06000","13.72588","0.01647"
"144.35400","13.75046","0.01641"
"144.64800","13.77491","0.01665"
"144.94200","13.79949","0.01688"
"145.23600","13.82388","0.01712"
"145.53000","13.84839","0.01687"
"145.82400","13.87285","0.01699"
"146.11800","13.89748","0.01699"
"146.41200","13.92187","0.01715"
"146.70600","13.94639","0.01743"
"147.00000","13.97090","0.01725"
"147.29400","13.99541","0.01714"
"147.58800","14.01993","0.01763"
"147.88200","14.04438","0.01733"
"148.17600","14.06890","0.01737"
"148.47000","14.09341","0.01736"
"148.76400","14.11792","0.01771"
"149.05800","14.14238","0.01759"
"149.35200","14.16695","0.01757"
"149.64600","14.19141","0.01775"
"149.94000","14.21598","0.01803"
"150.23400","14.24043","0.01788"
"150.52800","14.26495","0.01805"
"150.82200","14.28946","0.01801"
"151.11600","14.31391","0.01797"
"151.41000","14.33843","0.01818"
"151.70400","14.36288","0.01822"
"151.99800","14.38739","0.01817"
"152.29200","14.41185","0.01830"
"152.58600","14.43642","0.01837"
"152.88000","14.46088","0.01815"
"153.17400","14.48539","0.01866"
"153.46800","14.50984","0.01876"
"153.76200","14.53436","0.01857"
"154.05600","14.55893","0.01858"
"154.35000","14.58338","0.01827"
"154.64400","14.60796","0.01896"
"154.93800","14.63235","0.01881"
"155.23200","14.65693","0.01950"
"155.52600","14.68138","0.01918"
"155.82000","14.70595","0.01908"
"156.11400","14.73041","0.01934"
"156.40800","14.75492","0.01937"
"156.70200","14.77944","0.01954"
"156.99600","14.80389","0.01951"
"157.29000","14.82846","0.01948"
"157.58400","14.85292","0.01966"
"157.87800","14.87743","0.01987"
"158.17200","14.90182","0.01964"
"158.46600","14.92640","0.01998"
"158.76000","14.95091","0.01914"
"159.05400","14.97542","0.01947"
"159.34800","14.99988","0.01939"
"159.64200","15.02439","0.01990"
"159.93600","15.04891","0.02001"
"160.23000","15.07342","0.01986"
"160.52400","15.09793","0.01988"
"160.81800","15.12245","0.02044"
"161.11200","15.14696","0.02001"
"161.40600","15.17141","0.02041"
"161.70000","15.19593","0.02035"
"161.99400","15.22044","0.02044"
"162.28800","15.24496","0.02045"
"162.58200","15.26941","0.02089"
"162.87600","15.29398","0.02078"
"163.17000","15.31844","0.02130"
"163.46400","15.34295","0.02114"
"163.75800","15.36747","0.02143"
"164.05200","15.39186","0.02132"
"164.34600","15.41643","0.02154"
"164.64000","15.44083","0.02183"
"164.93400","15.46540","0.02131"
"165.22800","15.48979","0.02185"
"165.52200","15.51443","0.02226"
"165.81600","15.53888","0.02247"
"166.11000","15.56340","0.02246"
"166.40400","15.58791","0.02225"
"166.69800","15.61236","0.02271"
"166.99200","15.63694","0.02295"
"167.28600","15.66139","0.02315"
"167.58000","15.68596","0.02295"
"167.87400","15.71036","0.02365"
"168.16800","15.73493","0.02389"
"168.46200","15.75938","0.02436"
"168.75600","15.78396","0.02425"
"169.05000","15.80841","0.02365"
"169.34400","15.83292","0.02434"
"169.63800","15.85738","0.02470"
"169.93200","15.88189","0.02480"
"170.22600","15.90647","0.02508"
"170.52000","15.93092","0.02529"
"170.81400","15.95543","0.02553"
"171.10800","15.97983","0.02583"
"171.40200","16.00440","0.02629"
"171.69600","16.02886","0.02574"
"171.99000","16.05343","0.02725"
"172.28400","16.07794","0.02727"
"172.57800","16.10234","0.02833"
"172.87200","16.12691","0.02770"
"173.16600","16.15137","0.02809"
"173.46000","16.17594","0.02800"
"173.75400","16.20033","0.02853"
"174.04800","16.22497","0.02818"
"174.34200","16.24942","0.02910"
"174.63600","16.27393","0.02899"
"174.93000","16.29839","0.02784"
"175.22400","16.32296","0.02786"
"175.51800","16.34741","0.02853"
"175.81200","16.37187","0.02946"
"176.10600","16.39644","0.02946"
"176.40000","16.42089","0.02998"
"176.69400","16.44541","0.02986"
"176.98800","16.46986","0.03034"
"177.28200","16.49444","0.03121"
"177.57600","16.51889","0.03180"
"177.87000","16.54341","0.03164"
"178.16400","16.56786","0.03215"
"178.45800","16.59237","0.03246"
"178.75200","16.61689","0.03327"
"179.04600","16.64134","0.03318"
"179.34000","16.66591","0.03354"
"179.63400","16.69043","0.03342"
"179.92800","16.71500","0.03405"
"180.22200","16.73940","0.03452"
"180.51600","16.76391","0.03452"
"180.81000","16.78842","0.03473"
"181.10400","16.81293","0.03569"
"181.39800","16.83739","0.03616"
"181.69200","16.86190","0.03559"
"181.98600","16.88642","0.03628"
"182.28000","16.91087","0.03668"
"182.57400","16.93545","0.03218"
"182.86800","16.95990","0.03168"
"183.16200","16.98441","0.03262"
"183.45600","17.00887","0.03383"
"183.75000","17.03338","0.03395"
"184.04400","17.05783","0.03411"
"184.33800","17.08241","0.03458"
"184.63200","17.10692","0.03532"
"184.92600","17.13144","0.03609"
"185.22000","17.15589","0.03567"
"185.51400","17.18040","0.03670"
"185.80800","17.20498","0.03767"
"186.10200","17.22943","0.03769"
"186.39600","17.25394","0.03752"
"186.69000","17.27840","0.03854"
"186.98400","17.30297","0.03941"
"187.27800","17.32743","0.03911"
"187.57200","17.35194","0.03989"
"187.86600","17.37639","0.04002"
"188.16000","17.40091","0.04046"
"188.45400","17.42536","0.04109"
"188.74800","17.44987","0.04114"
"189.04200","17.47445","0.04090"
"189.33600","17.49890","0.04103"
"189.63000","17.52341","0.04187"
"189.92400","17.54781","0.04232"
"190.21800","17.57244","0.04284"
"190.51200","17.59684","0.04307"
"190.80600","17.62141","0.04292"
"191.10000","17.64586","0.04367"
"191.39400","17.67038","0.04402"
"191.68800","17.69489","0.04377"
"191.98200","17.71940","0.04447"
"192.27600","17.74398","0.04428"
"192.57000","17.76843","0.04497"
"192.86400","17.79295","0.04470"
"193.15800","17.81740","0.04551"
"193.45200","17.84197","0.04572"
"193.74600","17.86643","0.04585"
"194.04000","17.89094","0.04608"
"194.33400","17.91540","0.04648"
"194.62800","17.93991","0.04667"
"194.92200","17.96442","0.04724"
"195.21600","17.98882","0.04725"
"195.51000","18.01345","0.04718"
"195.80400","18.03790","0.01840"
"196.09800","18.06242","0.01879"
"196.39200","18.08681","0.01913"
"196.68600","18.11139","0.01926"
"196.98000","18.13590","0.01915"
"197.27400","18.16041","0.01982"
"197.56800","18.18493","0.01936"
"197.86200","18.20944","0.01958"
"198.15600","18.23396","0.01971"
"198.45000","18.25841","0.01971"
"198.74400","18.28298","0.02028"
"199.03800","18.30737","0.02016"
"199.33200","18.33201","0.02020"
"199.62600","18.35640","0.02031"
"199.92000","18.38092","0.02027"
"200.21400","18.40543","0.02064"
"200.50800","18.42994","0.02077"
"200.80200","18.45440","0.02103"
"201.09600","18.47891","0.02075"
"201.39000","18.50343","0.02081"
"201.68400","18.52788","0.02111"
"201.97800","18.55245","0.02102"
"202.27200","18.57691","0.02190"
"202.56600","18.60142","0.02209"
"202.86000","18.62587","0.02200"
"203.15400","18.65039","0.02214"
"203.44800","18.67484","0.02307"
"203.74200","18.69942","0.02308"
"204.03600","18.72393","0.02157"
"204.33000","18.74844","0.02143"
"204.62400","18.77296","0.02172"
"204.91800","18.79735","0.02200"
"205.21200","18.82192","0.02206"
"205.50600","18.84644","0.02223"
"205.80000","18.87089","0.02237"
"206.09400","18.89535","0.02245"
"206.38800","18.91992","0.02254"
"206.68200","18.94437","0.02292"
"206.97600","18.96889","0.02342"
"207.27000","18.99340","0.02369"
"207.56400","19.01791","0.02439"
"207.85800","19.04243","0.02473"
"208.15200","19.06688","0.02532"
"208.44600","19.09146","0.02321"
"208.74000","19.11591","0.02170"
"209.03400","19.14042","0.00720"
"209.32800","19.16482","0.00576"
"209.62200","19.18945","0.00567"
"209.91600","19.21384","0.00606"
"210.21000","19.23842","0.00542"
"210.50400","19.26293","0.00459"
"210.79800","19.28745","0.00463"
"211.09200","19.31196","0.00531"
"211.38600","19.33641","0.00501"
"211.68000","19.36093","0.00638"
"211.97400","19.38538","0.00436"
"212.26800","19.40989","0.00532"
"212.56200","19.43435","0.00431"
"212.85600","19.45892","0.00390"
"213.15000","19.48338","-0.00036"
"213.44400","19.50789","-0.00022"
"213.73800","19.53246","0.00005"
"214.03200","19.55686","0.00078"
"214.32600","19.58137","0.00114"
"214.62000","19.60588","-0.00019"
"214.91400","19.63040","0.00049"
"215.20800","19.65485","0.00022"
"215.50200","19.67943","0.00050"
"215.79600","19.70388","-0.00047"
"216.09000","19.72845","-0.00048"
"216.38400","19.75291","-0.00045"
"216.67800","19.77748","-0.00013"
"216.97200","19.80199","-0.00034"
"217.26600","19.82639","-0.00048"
"217.56000","19.85090","-0.00029"
"217.85400","19.87536","0.00021"
"218.14800","19.89993","-0.00023"
"218.44200","19.92432","-0.00036"
"218.73600","19.94890","-0.00008"
"219.03000","19.97341","0.00032"
"219.32400","19.99792","0.00087"
"219.61800","20.02238","0.00024"
"219.91200","20.04689","0.00050"
"220.20600","20.07141","0.00014"
"220.50000","20.09586","0.00038"
"220.79400","20.12037","0.00034"
"221.08800","20.14489","-0.00027"
"221.38200","20.16946","0.00056"
"221.67600","20.19392","-0.00028"
"221.97000","20.21843","-0.00021"
"222.26400","20.24288","0.00048"
"222.55800","20.26746","0.00023"
"222.85200","20.29191","0.00048"
"223.14600","20.31642","0.00068"
"223.44000","20.34094","0.00020"
"223.73400","20.36539","0.00079"
"224.02800","20.38997","0.00032"
"224.32200","20.41430","0.00100"
"224.61600","20.43893","0.00083"
"224.91000","20.46333","0.00017"
"225.20400","20.48796","0.00120"
"225.49800","20.51235","0.00089"
"225.79200","20.53693","0.00079"
"226.08600","20.56138","0.00068"
"226.38000","20.58590","0.00087"
"226.67400","20.61041","0.00025"
"226.96800","20.63486","0.00094"
"227.26200","20.65944","0.00053"
"227.55600","20.68389","0.00080"
"227.85000","20.70846","0.00093"
"228.14400","20.73292","0.00050"
"228.43800","20.75743","0.00065"
"228.73200","20.78189","0.00051"
"229.02600","20.80646","0.00087"
"229.32000","20.83085","0.00094"
"229.61400","20.85542","0.00123"
"229.90800","20.87988","0.00116"
"230.20200","20.90439","0.00115"
"230.49600","20.92891","0.00173"
"230.79000","20.95342","0.00147"
"231.08400","20.97793","0.00131"
"231.37800","21.00239","0.00114"
"231.67200","21.02690","0.00156"
"231.96600","21.05141","0.00188"
"232.26000","21.07593","0.00164"
"232.55400","21.10044","0.00155"
"232.84800","21.12490","0.00190"
"233.14200","21.14941","0.00136"
"233.43600","21.17386","0.00149"
"233.73000","21.19850","0.00140"
"234.02400","21.22289","0.00234"
"234.31800","21.24747","0.00207"
"234.61200","21.27186","0.00204"
"234.90600","21.29643","0.00191"
"235.20000","21.32089","0.00175"
"235.49400","21.34546","0.00197"
"235.78800","21.36992","0.00240"
"236.08200","21.39443","0.00226"
"236.37600","21.41888","0.00273"
"236.67000","21.44340","0.00217"
"236.96400","21.46791","0.00305"
"237.25800","21.49236","0.00261"
"237.55200","21.51688","0.00246"
"237.84600","21.54133","0.00245"
"238.14000","21.56597","0.00314"
"238.43400","21.59042","0.00318"
"238.72800","21.61493","0.00256"
"239.02200","21.63945","0.00304"
"239.31600","21.66390","0.00368"
"239.61000","21.68842","0.00320"
"239.90400","21.71287","0.00279"
"240.19800","21.73744","0.00356"
"240.49200","21.76190","0.00363"
"240.78600","21.78641","0.00353"
"241.08000","21.81092","0.00219"
"241.37400","21.83544","0.00260"
"241.66800","21.85989","0.00213"
"241.96200","21.88440","0.00206"
"242.25600","21.90892","0.00241"
"242.55000","21.93343","0.00236"
"242.84400","21.95794","0.00237"
"243.13800","21.98234","0.00239"
"243.43200","22.00691","0.00228"
"243.72600","22.03137","0.00316"
"244.02000","22.05594","0.00269"
"244.31400","22.08034","0.00272"
"244.60800","22.10497","0.00277"
"244.90200","22.12936","0.00257"
"245.19600","22.15388","0.00257"
"245.49000","22.17839","0.00225"
"245.78400","22.20290","0.00269"
"246.07800","22.22742","0.00234"
"246.37200","22.25187","0.00249"
"246.66600","22.27644","0.00355"
"246.96000","22.30096","0.00241"
"247.25400","22.32547","0.00308"
"247.54800","22.34986","0.00266"
"247.84200","22.37444","0.00321"
"248.13600","22.39895","0.00337"
"248.43000","22.42341","0.00357"
"248.72400","22.44792","0.00311"
"249.01800","22.47237","0.00372"
"249.31200","22.49695","0.00372"
"249.60600","22.52140","0.00418"
"249.90000","22.54598","0.00398"
"250.19400","22.57031","0.00399"
"250.48800","22.59494","0.00422"
"250.78200","22.61934","0.00419"
"251.07600","22.64391","0.00364"
"251.37000","22.66842","0.00338"
"251.66400","22.69288","0.00342"
"251.95800","22.71739","0.00395"
"252.25200","22.74191","0.00399"
"252.54600","22.76642","0.00374"
"252.84000","22.79093","0.00362"
"253.13400","22.81545","0.00412"
"253.42800","22.83990","0.00412"
"253.72200","22.86447","0.00399"
"254.01600","22.88887","0.00399"
"254.31000","22.91344","0.00418"
"254.60400","22.93789","0.00440"
"254.89800","22.96241","0.00441"
"255.19200","22.98693","0.00511"
"255.48600","23.01138","0.00500"
"255.78000","23.03589","0.00455"
"256.07400","23.06035","0.00526"
"256.36800","23.08486","0.00523"
"256.66200","23.10931","0.00515"
"256.95600","23.13389","0.00544"
"257.25000","23.15840","0.00520"
"257.54400","23.18291","0.00450"
"257.83800","23.20743","0.00504"
"258.13200","23.23194","0.00579"
"258.42600","23.25651","0.00521"
"258.72000","23.28091","0.00514"
"259.01400","23.30542","0.00556"
"259.30800","23.32987","0.00548"
"259.60200","23.35445","0.00600"
"259.89600","23.37884","0.00589"
"260.19000","23.40342","0.00658"
"260.48400","23.42781","0.00618"
"260.77800","23.45239","0.00613"
"261.07200","23.47684","0.00642"
"261.36600","23.50141","0.00667"
"261.66000","23.52592","0.00668"
"261.95400","23.55038","0.00715"
"262.24800","23.57489","0.00736"
"262.54200","23.59941","0.00626"
"262.83600","23.62392","0.00736"
"263.13000","23.64831","0.00695"
"263.42400","23.67289","0.00749"
"263.71800","23.69740","0.00674"
"264.01200","23.72191","0.00712"
"264.30600","23.74643","0.00678"
"264.60000","23.77094","0.00770"
"264.89400","23.79546","0.00742"
"265.18800","23.81985","0.00746"
"265.48200","23.84443","0.00776"
"265.77600","23.86888","0.00737"
"266.07000","23.89345","0.00688"
"266.36400","23.91784","0.00716"
"266.65800","23.94248","0.00736"
"266.95200","23.96688","0.00741"
"267.24600","23.99145","0.00744"
"267.54000","24.01590","0.00706"
"267.83400","24.04042","0.00693"
"268.12800","24.06493","0.00736"
"268.42200","24.08938","0.00678"
"268.71600","24.11390","0.00763"
"269.01000","24.13835","0.00657"
"269.30400","24.16292","0.00634"
"269.59800","24.18732","0.00406"
"269.89200","24.21195","0.00367"
"270.18600","24.23640","0.00331"
"270.48000","24.26092","0.00401"
"270.77400","24.28543","0.00405"
"271.06800","24.30994","0.00396"
"271.36200","24.33446","0.00468"
"271.65600","24.35885","0.00470"
"271.95000","24.38349","0.00534"
"272.24400","24.40788","0.00523"
"272.53800","24.43239","0.00519"
"272.83200","24.45685","0.00591"
"273.12600","24.48142","0.00545"
"273.42000","24.50582","0.00615"
"273.71400","24.53039","0.00640"
"274.00800","24.55490","0.00655"
"274.30200","24.57936","0.00694"
"274.59600","24.60393","0.00664"
"274.89000","24.62832","0.00714"
"275.18400","24.65290","0.00728"
"275.47800","24.67735","0.00739"
"275.77200","24.70193","0.00775"
"276.06600","24.72638","0.00754"
"276.36000","24.75095","0.00781"
"276.65400","24.77541","0.00769"
"276.94800","24.79998","0.00755"
"277.24200","24.82450","0.00771"
"277.53600","24.84889","0.00727"
"277.83000","24.87346","0.00703"
"278.12400","24.89786","0.00789"
"278.41800","24.92243","0.00798"
"278.71200","24.94688","0.00758"
"279.00600","24.97146","0.00797"
"279.30000","24.99585","0.00800"
"279.59400","25.02043","0.00852"
"279.88800","25.04488","0.00905"
"280.18200","25.06939","0.00901"
"280.47600","25.09391","0.00944"
"280.77000","25.11842","0.00880"
"281.06400","25.14287","0.00923"
"281.35800","25.16739","0.00522"
"281.65200","25.19190","0.00593"
"281.94600","25.21642","0.00643"
"282.24000","25.24093","0.00647"
"282.53400","25.26538","0.00723"
"282.82800","25.28996","0.00702"
"283.12200","25.31441","0.00708"
"283.41600","25.33899","0.00679"
"283.71000","25.36344","0.00756"
"284.00400","25.38789","0.00725"
"284.29800","25.41247","0.00713"
"284.59200","25.43686","0.00818"
"284.88600","25.46143","0.00792"
"285.18000","25.48589","0.00818"
"285.47400","25.51046","0.00782"
"285.76800","25.53480","0.00827"
"286.06200","25.55937","0.00881"
"286.35600","25.58388","0.00865"
"286.65000","25.60834","0.00854"
"286.94400","25.63285","0.00811"
"287.23800","25.65736","0.00879"
"287.53200","25.68194","0.00929"
"287.82600","25.70639","0.00824"
"288.12000","25.73096","0.00884"
"288.41400","25.75536","0.00915"
"288.70800","25.77993","0.00920"
"289.00200","25.80445","0.00951"
"289.29600","25.82896","0.00931"
"289.59000","25.85341","0.00959"
"289.88400","25.87793","0.00950"
"290.17800","25.90244","0.00964"
"290.47200","25.92689","0.00983"
"290.76600","25.95147","0.00963"
"291.06000","25.97586","0.01029"
"291.35400","26.00044","0.01015"
"291.64800","26.02495","0.01036"
"291.94200","26.04946","0.01087"
"292.23600","26.07386","0.01060"
"292.53000","26.09837","0.01133"
"292.82400","26.12288","0.01065"
"293.11800","26.14740","0.01102"
"293.41200","26.17191","0.01100"
"293.70600","26.19636","0.01160"
"294.00000","26.22094","0.01210"
"294.29400","26.24533","0.01248"
"294.58800","26.27003","0.01242"
"294.88200","26.29442","0.01203"
"295.17600","26.31893","0.01027"
"295.47000","26.34339","0.01112"
"295.76400","26.36796","0.01146"
"296.05800","26.39242","0.01111"
"296.35200","26.41693","0.01204"
"296.64600","26.44138","0.01199"
"296.94000","26.46584","0.01243"
"297.23400","26.49035","0.01233"
"297.52800","26.51487","0.01267"
"297.82200","26.53944","0.01287"
"298.11600","26.56389","0.01333"
"298.41000","26.58840","0.01347"
"298.70400","26.61286","0.01400"
"298.99800","26.63737","0.01388"
"299.29200","26.66189","0.01400"
"299.58600","26.68640","0.01381"
"299.88000","26.71092","0.01405"
"300.17400","26.73537","0.01422"
"300.46800","26.75994","0.01494"
"300.76200","26.78440","0.01477"
"301.05600","26.80897","0.01465"
"301.35000","26.83342","0.01485"
"301.64400","26.85794","0.01465"
"301.93800","26.88245","0.01508"
"302.23200","26.90696","0.01513"
"302.52600","26.93142","0.01508"
"302.82000","26.95593","0.01502"
"303.11400","26.98044","0.01554"
"303.40800","27.00490","0.01548"
"303.70200","27.02941","0.01550"
"303.99600","27.05387","0.01593"
"304.29000","27.07844","0.01579"
"304.58400","27.10283","0.01623"
"304.87800","27.12747","0.01624"
"305.17200","27.15186","0.01591"
"305.46600","27.17637","0.01644"
"305.76000","27.20089","0.01658"
"306.05400","27.22540","0.01683"
"306.34800","27.24992","0.01723"
"306.64200","27.27437","0.01732"
"306.93600","27.29889","0.01731"
"307.23000","27.32340","0.01747"
"307.52400","27.34797","0.01759"
"307.81800","27.37243","0.01765"
"308.11200","27.39688","0.01797"
"308.40600","27.42133","0.01809"
"308.70000","27.44585","0.01829"
"308.99400","27.47042","0.01843"
"309.28800","27.49487","0.01841"
"309.58200","27.51945","0.01865"
"309.87600","27.54384","0.01898"
"310.17000","27.56841","0.01901"
"310.46400","27.59287","0.01916"
"310.75800","27.61744","0.01935"
"311.05200","27.64190","0.01965"
"311.34600","27.66641","0.02009"
"311.64000","27.69086","0.01985"
"311.93400","27.71544","0.02006"
"312.22800","27.73995","0.02010"
"312.52200","27.76441","0.02052"
"312.81600","27.78898","0.02097"
"313.11000","27.81337","0.02089"
"313.40400","27.83795","0.02115"
"313.69800","27.86240","0.01990"
"313.99200","27.88697","0.02020"
"314.28600","27.91137","0.02046"
"314.58000","27.93594","0.02090"
"314.87400","27.96045","0.02110"
"315.16800","27.98491","0.02125"
"315.46200","28.00942","0.02139"
"315.75600","28.03394","0.02211"
"316.05000","28.05845","0.02240"
"316.34400","28.08290","0.02301"
"316.63800","28.10742","0.02326"
"316.93200","28.13181","0.02359"
"317.22600","28.15644","0.02406"
"317.52000","28.18090","0.02467"
"317.81400","28.20541","0.02568"
"318.10800","28.22993","0.02669"
"318.40200","28.25444","0.02727"
"318.69600","28.27896","0.02734"
"318.99000","28.30341","0.02854"
"319.28400","28.32798","0.02938"
"319.57800","28.35238","0.03063"
"319.87200","28.37695","0.03045"
"320.16600","28.40134","0.03108"
"320.46000","28.42598","0.03111"
"320.75400","28.45043","0.03271"
"321.04800","28.47489","0.03338"
"321.34200","28.49940","0.02273"
"321.63600","28.52391","0.02461"
"321.93000","28.54843","0.02497"
"322.22400","28.57288","0.02666"
"322.51800","28.59739","0.02762"
"322.81200","28.62185","0.02880"
"323.10600","28.64642","0.03057"
"323.40000","28.67081","0.03127"
"323.69400","28.69545","0.03217"
"323.98800","28.71984","0.03346"
"324.28200","28.74442","0.03226"
"324.57600","28.76893","0.03420"
"324.87000","28.79344","0.03535"
"325.16400","28.81796","0.03690"
"325.45800","28.84241","0.03750"
"325.75200","28.86692","0.03807"
"326.04600","28.89138","0.03933"
"326.34000","28.91595","0.03999"
"326.63400","28.94035","0.04066"
"326.92800","28.96492","0.04161"
"327.22200","28.98943","0.04286"
"327.51600","29.01389","0.04279"
"327.81000","29.03840","0.04333"
"328.10400","29.06292","0.03925"
"328.39800","29.08743","0.04043"
"328.69200","29.11189","0.04191"
"328.98600","29.13640","0.04250"
"329.28000","29.16085","0.04353"
"329.57400","29.18542","0.04455"
"329.86800","29.20988","0.04594"
"330.16200","29.23445","0.04650"
"330.45600","29.25891","0.04756"
"330.75000","29.28348","0.04861"
"331.04400","29.30787","0.04921"
"331.33800","29.33239","0.05017"
"331.63200","29.35690","0.05155"
"331.92600","29.38136","0.05254"
"332.22000","29.40593","0.05294"
"332.51400","29.43038","0.05389"
"332.80800","29.45490","0.05474"
"333.10200","29.47941","0.05374"
"333.39600","29.50393","0.05524"
"333.69000","29.52838","0.05630"
"333.98400","29.55289","0.05756"
"334.27800","29.57741","0.05889"
"334.57200","29.60186","0.05895"
"334.86600","29.62643","0.05974"
"335.16000","29.65089","0.06097"
"335.45400","29.67540","0.06207"
"335.74800","29.69985","0.06207"
"336.04200","29.72443","0.06287"
"336.33600","29.74888","0.06339"
"336.63000","29.77345","0.06392"
"336.92400","29.79791","0.06430"
"337.21800","29.82242","0.06487"
"337.51200","29.84694","0.06507"
"337.80600","29.87145","0.06546"
"338.10000","29.89597","0.06572"
"338.39400","29.92036","0.06622"
"338.68800","29.94493","0.06632"
"338.98200","29.96938","0.06682"
"339.27600","29.99396","0.06722"
"339.57000","30.01835","0.06745"
"339.86400","30.04293","0.06805"
"340.15800","30.06738","0.06813"
"340.45200","30.09189","0.06920"
"340.74600","30.11641","0.06936"
"341.04000","30.14092","0.07069"
"341.33400","30.16544","0.07114"
"341.62800","30.18989","0.07317"
"341.92200","30.21440","0.07429"
"342.21600","30.23892","0.07610"
"342.51000","30.26343","0.07868"
"342.80400","30.28788","0.07888"
"343.09800","30.31246","0.08163"
"343.39200","30.33691","0.08446"
"343.68600","30.36142","0.08596"
"343.98000","30.38594","0.08919"
"344.27400","30.41039","0.09198"
"344.56800","30.43497","0.09456"
"344.86200","30.45936","0.09708"
"345.15600","30.48387","0.10025"
"345.45000","30.50833","0.09084"
"345.74400","30.53290","0.09379"
"346.03800","30.55735","0.09078"
"346.33200","30.58193","0.09341"
"346.62600","30.60638","0.09592"
"346.92000","30.63090","0.09837"
"347.21400","30.65541","0.10072"
"347.50800","30.67992","0.10451"
"347.80200","30.70444","0.10752"
"348.09600","30.72889","0.11069"
"348.39000","30.75341","0.11463"
"348.68400","30.77786","0.11815"
"348.97800","30.80243","0.12063"
"349.27200","30.82689","0.12262"
"349.56600","30.85146","0.12419"
"349.86000","30.87591","0.12455"
"350.15400","30.90037","0.12541"
"350.44800","30.92488","0.12603"
"350.74200","30.94939","0.12686"
"351.03600","30.97397","0.12715"
"351.33000","30.99836","0.12790"
"351.62400","31.02294","0.12948"
"351.91800","31.04739","0.13116"
"352.21200","31.07196","0.13370"
"352.50600","31.09642","0.13612"
"352.80000","31.12093","0.13949"
"353.09400","31.14538","0.14284"
"353.38800","31.16990","0.14427"
"353.68200","31.19447","0.14387"
"353.97600","31.21887","0.14644"
"354.27000","31.24344","0.14872"
"354.56400","31.26789","0.15043"
"354.85800","31.29247","0.15249"
"355.15200","31.31692","0.15506"
"355.44600","31.34143","0.15737"
"355.74000","31.36589","0.15897"
"356.03400","31.39046","0.16126"
"356.32800","31.41497","0.16279"
"356.62200","31.43943","0.16447"
"356.91600","31.46394","0.16601"
"357.21000","31.48840","0.16707"
"357.50400","31.51291","0.16792"
"357.79800","31.53731","0.16862"
"358.09200","31.56194","0.16988"
"358.38600","31.58639","0.16855"
"358.68000","31.61091","0.16817"
"358.97400","31.63536","0.16970"
"359.26800","31.65987","0.17134"
"359.56200","31.68439","0.17259"
"359.85600","31.70890","0.17390"
"360.15000","31.73341","0.17532"
"360.44400","31.75793","0.17655"
"360.73800","31.78244","0.17749"
"361.03200","31.80689","0.17853"
"361.32600","31.83147","0.17973"
"361.62000","31.85592","0.18151"
"361.91400","31.88043","0.18333"
"362.20800","31.90489","0.18506"
"362.50200","31.92940","0.00688"
"362.79600","31.95392","0.00866"
"363.09000","31.97843","0.02604"
"363.38400","32.00294","-0.00015"
"363.67800","32.02740","0.01592"
"363.97200","32.05191","0.02334"
"364.26600","32.07631","0.01304"
"364.56000","32.10094","0.01195"
"364.85400","32.12534","0.01643"
"365.14800","32.14991","0.01233"
"365.44200","32.17442","0.01904"
"365.73600","32.19894","0.01486"
"366.03000","32.22339","0.01020"
"366.32400","32.24790","0.01974"
"366.61800","32.27248","0.01256"
"366.91200","32.29693","0.01782"
"367.20600","32.32144","0.01608"
"367.50000","32.34584","0.01269"
"367.79400","32.37041","0.02054"
"368.08800","32.39492","0.01282"
"368.38200","32.41944","0.01867"
"368.67600","32.44389","0.01658"
"368.97000","32.46840","0.01549"
"369.26400","32.49292","0.02040"
"369.55800","32.51737","0.01455"
"369.85200","32.54195","0.01984"
"370.14600","32.56640","0.01681"
"370.44000","32.59092","0.01747"
"370.73400","32.61531","0.01990"
"371.02800","32.63994","0.01683"
"371.32200","32.66439","0.02109"
"371.61600","32.68891","0.01747"
"371.91000","32.71342","0.01962"
"372.20400","32.73794","0.01949"
"372.49800","32.76245","0.01865"
"372.79200","32.78691","0.02228"
"373.08600","32.81148","0.01842"
"373.38000","32.83588","0.02191"
"373.67400","32.86045","0.02035"
"373.96800","32.88490","0.02094"
"374.26200","32.90947","0.02278"
"374.55600","32.93393","0.02105"
"374.85000","32.95844","0.02301"
"375.14400","32.98290","0.02273"
"375.43800","33.00741","0.02323"
"375.73200","33.03192","0.02366"
"376.02600","33.05638","0.02444"
"376.32000","33.08089","0.02427"
"376.61400","33.10534","0.02644"
"376.90800","33.12986","0.02498"
"377.20200","33.15431","0.02800"
"377.49600","33.17894","0.02691"
"377.79000","33.20340","0.02751"
"378.08400","33.22797","0.03082"
"378.37800","33.25248","0.02794"
"378.67200","33.27694","0.03205"
"378.96600","33.30145","0.03068"
"379.26000","33.32591","0.03095"
"379.55400","33.35048","0.03264"
"379.84800","33.37487","0.03159"
"380.14200","33.39945","0.03395"
"380.43600","33.42384","0.03424"
"380.73000","33.44847","0.03362"
"381.02400","33.47287","0.02298"
"381.31800","33.49739","0.01896"
"381.61200","33.52190","0.01868"
"381.90600","33.54641","0.01986"
"382.20000","33.57093","0.01969"
"382.49400","33.59538","0.01956"
"382.78800","33.61995","0.02106"
"383.08200","33.64435","0.02033"
"383.37600","33.66886","0.02104"
"383.67000","33.69331","0.02088"
"383.96400","33.71795","0.02185"
"384.25800","33.74240","0.02259"
"384.55200","33.76691","0.02206"
"384.84600","33.79143","0.02312"
"385.14000","33.81594","0.02337"
"385.43400","33.84052","0.02409"
"385.72800","33.86491","0.02474"
"386.02200","33.88942","0.02568"
"386.31600","33.91394","0.02541"
"386.61000","33.93839","0.02666"
"386.90400","33.96284","0.02676"
"387.19800","33.98748","0.02820"
"387.49200","34.01193","0.02921"
"387.78600","34.03639","0.02974"
"388.08000","34.06090","0.03177"
"388.37400","34.08541","0.03206"
"388.66800","34.10993","0.03213"
"388.96200","34.13438","0.03359"
"389.25600","34.15895","0.03370"
"389.55000","34.18335","0.03459"
"389.84400","34.20792","0.03609"
"390.13800","34.23238","0.03605"
"390.43200","34.25695","0.03701"
"390.72600","34.28140","0.03769"
"391.02000","34.30598","0.03887"
"391.31400","34.33043","0.03919"
"391.60800","34.35495","0.03892"
"391.90200","34.37946","0.03993"
"392.19600","34.40385","0.04026"
"392.49000","34.42843","0.04087"
"392.78400","34.45288","0.04188"
"393.07800","34.47739","0.04199"
"393.37200","34.50185","0.04317"
"393.66600","34.52642","0.04442"
"393.96000","34.55088","0.04427"
"394.25400","34.57539","0.04591"
"394.54800","34.59990","0.04603"
"394.84200","34.62436","0.04662"
"395.13600","34.64887","0.04740"
"395.43000","34.67332","0.04715"
"395.72400","34.69790","0.04804"
"396.01800","34.72235","0.04832"
"396.31200","34.74693","0.04933"
"396.60600","34.77138","0.04987"
"396.90000","34.79596","0.05032"
"397.19400","34.82047","0.05118"
"397.48800","34.84492","0.05209"
"397.78200","34.86943","0.05287"
"398.07600","34.89389","0.05378"
"398.37000","34.91840","0.05464"
"398.66400","34.94286","0.05456"
"398.95800","34.96743","0.05484"
"399.25200","34.99182","0.05511"
"399.54600","35.01646","0.05659"
"399.84000","35.04091","0.05660"
"400.13400","35.06548","0.05794"
"400.42800","35.08988","0.05881"
"400.72200","35.11439","0.05960"
"401.01600","35.13890","0.05999"
"401.31000","35.16342","0.06058"
"401.60400","35.18793","0.06100"
"401.89800","35.21239","0.06126"
"402.19200","35.23696","0.06198"
"402.48600","35.26136","0.06225"
"402.78000","35.28593","0.06273"
"403.07400","35.31038","0.06341"
"403.36800","35.33490","0.06331"
"403.66200","35.35935","0.06346"
"403.95600","35.38387","0.06385"
"404.25000","35.40844","0.06378"
"404.54400","35.43289","0.06433"
"404.83800","35.45747","0.06461"
"405.13200","35.48186","0.06461"
"405.42600","35.50637","0.06502"
"405.72000","35.53083","0.06532"
"406.01400","35.55546","0.06577"
"406.30800","35.57985","0.06566"
"406.60200","35.60437","0.06602"
"406.89600","35.62888","0.06629"
"407.19000","35.65339","0.06652"
"407.48400","35.67791","0.06687"
"407.77800","35.70236","0.06718"
"408.07200","35.72694","0.06760"
"408.36600","35.75139","0.06820"
"408.66000","35.77590","0.06849"
"408.95400","35.80036","0.06859"
"409.24800","35.82493","0.06894"
"409.54200","35.84945","0.06951"
"409.83600","35.87396","0.07021"
"410.13000","35.89835","0.07015"
"410.42400","35.92292","0.07133"
"410.71800","35.94744","0.07147"
"411.01200","35.97189","0.07228"
"411.30600","35.99641","0.07283"
"411.60000","36.02086","0.07408"
"411.89400","36.04544","0.07504"
"412.18800","36.06983","0.07646"
"412.48200","36.09446","0.07750"
"412.77600","36.11892","0.07821"
"413.07000","36.14343","0.07881"
"413.36400","36.16788","0.07975"
"413.65800","36.19234","0.08145"
"413.95200","36.21691","0.08271"
"414.24600","36.24137","0.08435"
"414.54000","36.26594","0.08514"
"414.83400","36.29039","0.08670"
"415.12800","36.31497","0.08740"
"415.42200","36.33936","0.08929"
"415.71600","36.36393","0.09089"
"416.01000","36.38839","0.09294"
"416.30400","36.41296","0.09414"
"416.59800","36.43742","0.09568"
"416.89200","36.46193","0.09714"
"417.18600","36.48639","0.09883"
"417.48000","36.51089","0.10051"
"417.77400","36.53535","0.10154"
"418.06800","36.55986","0.10300"
"418.36200","36.58438","0.10414"
"418.65600","36.60883","0.10603"
"418.95000","36.63341","0.10798"
"419.24400","36.65792","0.10878"
"419.53800","36.68243","0.10978"
"419.83200","36.70689","0.11072"
"420.12600","36.73140","0.11257"
"420.42000","36.75592","0.11403"
"420.71400","36.78037","0.11661"
"421.00800","36.80494","0.11753"
"421.30200","36.82940","0.11924"
"421.59600","36.85391","0.12027"
"421.89000","36.87842","0.12188"
"422.18400","36.90294","0.12213"
"422.47800","36.92739","0.12336"
"422.77200","36.95190","0.12343"
"423.06600","36.97642","0.12299"
"423.36000","37.00093","0.12350"
"423.65400","37.02544","0.12401"
"423.94800","37.04990","0.12467"
"424.24200","37.07447","0.12548"
"424.53600","37.09887","0.12580"
"424.83000","37.12344","0.12603"
"425.12400","37.14783","0.12656"
"425.41800","37.17241","0.12679"
"425.71200","37.19687","0.12728"
"426.00600","37.22144","0.12744"
"426.30000","37.24595","0.12775"
"426.59400","37.27040","0.12708"
"426.88800","37.29498","-0.00652"
"427.18200","37.31943","-0.00958"
"427.47600","37.34394","-0.00432"
"427.77000","37.36840","0.00270"
"428.06400","37.39297","-0.00410"
"428.35800","37.41737","-0.00397"
"428.65200","37.44188","-0.00403"
"428.94600","37.46639","-0.00366"
"429.24000","37.49091","-0.00504"
"429.53400","37.51536","-0.00474"
"429.82800","37.53988","-0.00422"
"430.12200","37.56445","-0.00322"
"430.41600","37.58884","-0.00355"
"430.71000","37.61341","-0.00425"
"431.00400","37.63781","-0.00345"
"431.29800","37.66244","-0.00304"
"431.59200","37.68684","-0.00346"
"431.88600","37.71141","-0.00455"
"432.18000","37.73592","-0.00393"
"432.47400","37.76038","-0.00364"
"432.76800","37.78489","-0.00247"
"433.06200","37.80941","-0.00423"
"433.35600","37.83392","-0.00432"
"433.62400","37.85622","-0.00381"