File: Force_trajectories/170122_1/Specimen_RawData_4.csv
End date,"1/22/2017"
Specimen label,"18BG_42"
Maximum Load,"0.08799",N

Time,Extension,Load
(s),(mm),(N)
"0.00000","0.00000","0.00082"
"0.22800","0.01722","-0.00011"
"0.45600","0.03833","0.00034"
"0.68400","0.05716","-0.00012"
"0.91200","0.07629","0.00021"
"1.14000","0.09524","0.00065"
"1.36800","0.11426","0.00018"
"1.59600","0.13327","0.00057"
"1.82400","0.15216","0.00096"
"2.05200","0.17124","0.00051"
"2.28000","0.19019","0.00102"
"2.50800","0.20926","0.00077"
"2.73600","0.22822","0.00084"
"2.96400","0.24723","0.00143"
"3.19200","0.26624","0.00044"
"3.42000","0.28514","0.00011"
"3.64800","0.30421","0.00121"
"3.87600","0.32322","0.00062"
"4.10400","0.34224","0.00077"
"4.33200","0.36125","0.00050"
"4.56000","0.38020","0.00109"
"4.78800","0.39927","0.00098"
"5.01600","0.41817","0.00082"
"5.24400","0.43718","0.00076"
"5.47200","0.45625","0.00123"
"5.70000","0.47521","0.00098"
"5.92800","0.49428","0.00142"
"6.15600","0.51323","0.00085"
"6.38400","0.53225","0.00067"
"6.61200","0.55120","0.00102"
"6.84000","0.57021","0.00132"
"7.06800","0.58929","0.00114"
"7.29600","0.60824","0.00176"
"7.52400","0.62719","0.00130"
"7.75200","0.64627","0.00135"
"7.98000","0.66522","0.00136"
"8.20800","0.68423","0.00121"
"8.43600","0.70324","0.00150"
"8.66400","0.72214","0.00125"
"8.89200","0.74121","0.00169"
"9.12000","0.76022","0.00106"
"9.34800","0.77924","0.00183"
"9.57600","0.79825","0.00143"
"9.80400","0.81720","0.00116"
"10.03200","0.83622","0.00066"
"10.26000","0.85523","0.00177"
"10.48800","0.87424","0.00189"
"10.71600","0.89326","0.00202"
"10.94400","0.91221","0.00133"
"11.17200","0.93122","0.00163"
"11.40000","0.95018","0.00199"
"11.62800","0.96931","0.00191"
"11.85600","0.98820","0.00173"
"12.08400","1.00727","0.00140"
"12.31200","1.02623","0.00199"
"12.54000","1.04524","0.00208"
"12.76800","1.06425","0.00179"
"12.99600","1.08315","0.00212"
"13.22400","1.10228","0.00197"
"13.45200","1.12123","0.00110"
"13.68000","1.14019","0.00145"
"13.90800","1.15926","0.00191"
"14.13600","1.17821","0.00186"
"14.36400","1.19723","0.00136"
"14.59200","1.21624","0.00178"
"14.82000","1.23531","0.00171"
"15.04800","1.25420","0.00110"
"15.27600","1.27322","0.00195"
"15.50400","1.29223","0.00151"
"15.73200","1.31112","0.00195"
"15.96000","1.33026","0.00159"
"16.18800","1.34915","0.00163"
"16.41600","1.36828","0.00110"
"16.64400","1.38724","0.00204"
"16.87200","1.40619","0.00222"
"17.10000","1.42526","0.00174"
"17.32800","1.44416","0.00182"
"17.55600","1.46329","0.00179"
"17.78400","1.48224","0.00130"
"18.01200","1.50126","0.00190"
"18.24000","1.52021","0.00251"
"18.46800","1.53916","0.00130"
"18.69600","1.55829","0.00191"
"18.92400","1.57719","0.00184"
"19.15200","1.59626","0.00244"
"19.38000","1.61521","0.00170"
"19.60800","1.63417","0.00166"
"19.83600","1.65330","0.00203"
"20.06400","1.67219","0.00189"
"20.29200","1.69127","0.00187"
"20.52000","1.71016","0.00201"
"20.74800","1.72917","0.00208"
"20.97600","1.74825","0.00212"
"21.20400","1.76720","0.00251"
"21.43200","1.78621","0.00178"
"21.66000","1.80517","0.00228"
"21.88800","1.82424","0.00212"
"22.11600","1.84325","0.00183"
"22.34400","1.86226","0.00184"
"22.57200","1.88128","0.00223"
"22.80000","1.90017","0.00173"
"23.02800","1.91924","0.00204"
"23.25600","1.93820","0.00250"
"23.48400","1.95721","0.00201"
"23.71200","1.97622","0.00188"
"23.94000","1.99524","0.00138"
"24.16800","2.01425","0.00134"
"24.39600","2.03320","0.00241"
"24.62400","2.05222","0.00227"
"24.85200","2.07117","0.00245"
"25.08000","2.09024","0.00183"
"25.30800","2.10926","0.00190"
"25.53600","2.12827","0.00240"
"25.76400","2.14728","0.00174"
"25.99200","2.16623","0.00256"
"26.22000","2.18525","0.00265"
"26.44800","2.20420","0.00217"
"26.67600","2.22327","0.00178"
"26.90400","2.24223","0.00236"
"27.13200","2.26124","0.00220"
"27.36000","2.28025","0.00219"
"27.58800","2.29921","0.00204"
"27.81600","2.31822","0.00296"
"28.04400","2.33717","0.00258"
"28.27200","2.35625","0.00189"
"28.50000","2.37520","0.00229"
"28.72800","2.39421","0.00224"
"28.95600","2.41323","0.00222"
"29.18400","2.43218","0.00231"
"29.41200","2.45125","0.00267"
"29.64000","2.47020","0.00293"
"29.86800","2.48928","0.00224"
"30.09600","2.50823","0.00251"
"30.32400","2.52724","0.00267"
"30.55200","2.54626","0.00268"
"30.78000","2.56521","0.00293"
"31.00800","2.58422","0.00275"
"31.23600","2.60324","0.00285"
"31.46400","2.62225","0.00275"
"31.69200","2.64120","0.00281"
"31.92000","2.66022","0.00289"
"32.14800","2.67923","0.00280"
"32.37600","2.69812","0.00326"
"32.60400","2.71731","0.00271"
"32.83200","2.73621","0.00217"
"33.06000","2.75522","0.00300"
"33.28800","2.77423","0.00262"
"33.51600","2.79319","0.00242"
"33.74400","2.81226","0.00311"
"33.97200","2.83115","0.00321"
"34.20000","2.85029","0.00318"
"34.42800","2.86924","0.00380"
"34.65600","2.88819","0.00337"
"34.88400","2.90727","0.00338"
"35.11200","2.92622","0.00372"
"35.34000","2.94523","0.00338"
"35.56800","2.96419","0.00313"
"35.79600","2.98326","0.00370"
"36.02400","3.00227","0.00376"
"36.25200","3.02117","0.00329"
"36.48000","3.04030","0.00314"
"36.70800","3.05913","0.00342"
"36.93600","3.07820","0.00309"
"37.16400","3.09716","0.00308"
"37.39200","3.11623","0.00402"
"37.62000","3.13524","0.00365"
"37.84800","3.15420","0.00381"
"38.07600","3.17327","0.00411"
"38.30400","3.19216","0.00356"
"38.53200","3.21124","0.00358"
"38.76000","3.23019","0.00347"
"38.98800","3.24920","0.00370"
"39.21600","3.26828","0.00373"
"39.44400","3.28723","0.00354"
"39.67200","3.30624","0.00365"
"39.90000","3.32525","0.00432"
"40.12800","3.34427","0.00373"
"40.35600","3.36328","0.00354"
"40.58400","3.38223","0.00370"
"40.81200","3.40125","0.00363"
"41.04000","3.42020","0.00369"
"41.26800","3.43927","0.00396"
"41.49600","3.45823","0.00414"
"41.72400","3.47718","0.00394"
"41.95200","3.49625","0.00394"
"42.18000","3.51527","0.00351"
"42.40800","3.53428","0.00352"
"42.63600","3.55317","0.00379"
"42.86400","3.57225","0.00384"
"43.09200","3.59120","0.00402"
"43.32000","3.61021","0.00409"
"43.54800","3.62922","0.00451"
"43.77600","3.64824","0.00448"
"44.00400","3.66725","0.00393"
"44.23200","3.68620","0.00418"
"44.46000","3.70522","0.00412"
"44.68800","3.72423","0.00419"
"44.91600","3.74318","0.00423"
"45.14400","3.76220","0.00405"
"45.37200","3.78127","0.00439"
"45.60000","3.80022","0.00420"
"45.82800","3.81924","0.00390"
"46.05600","3.83825","0.00414"
"46.28400","3.85720","0.00413"
"46.51200","3.87622","0.00432"
"46.74000","3.89523","0.00396"
"46.96800","3.91424","0.00436"
"47.19600","3.93319","0.00451"
"47.42400","3.95215","0.00416"
"47.65200","3.97128","0.00476"
"47.88000","3.99023","0.00440"
"48.10800","4.00925","0.00450"
"48.33600","4.02820","0.00447"
"48.56400","4.04721","0.00489"
"48.79200","4.06629","0.00471"
"49.02000","4.08524","0.00486"
"49.24800","4.10431","0.00405"
"49.47600","4.12315","0.00491"
"49.70400","4.14222","0.00479"
"49.93200","4.16123","0.00464"
"50.16000","4.18018","0.00478"
"50.38800","4.19920","0.00473"
"50.61600","4.21815","0.00464"
"50.84400","4.23728","0.00472"
"51.07200","4.25624","0.00439"
"51.30000","4.27519","0.00456"
"51.52800","4.29426","0.00514"
"51.75600","4.31316","0.00443"
"51.98400","4.33229","0.00506"
"52.21200","4.35118","0.00507"
"52.44000","4.37026","0.00511"
"52.66800","4.38927","0.00500"
"52.89600","4.40816","0.00494"
"53.12400","4.42724","0.00566"
"53.35200","4.44619","0.00491"
"53.58000","4.46526","0.00544"
"53.80800","4.48421","0.00452"
"54.03600","4.50323","0.00508"
"54.26400","4.52224","0.00495"
"54.49200","4.54119","0.00443"
"54.72000","4.56027","0.00514"
"54.94800","4.57916","0.00565"
"55.17600","4.59823","0.00515"
"55.40400","4.61725","0.00518"
"55.63200","4.63626","0.00505"
"55.86000","4.65527","0.00539"
"56.08800","4.67411","0.00510"
"56.31600","4.69324","0.00518"
"56.54400","4.71219","0.00536"
"56.77200","4.73121","0.00572"
"57.00000","4.75028","0.00525"
"57.22800","4.76917","0.00490"
"57.45600","4.78824","0.00520"
"57.68400","4.80720","0.00555"
"57.91200","4.82627","0.00538"
"58.14000","4.84522","0.00580"
"58.36800","4.86424","0.00578"
"58.59600","4.88325","0.00575"
"58.82400","4.90220","0.00520"
"59.05200","4.92122","0.00554"
"59.28000","4.94017","0.00564"
"59.50800","4.95924","0.00617"
"59.73600","4.97826","0.00585"
"59.96400","4.99721","0.00588"
"60.19200","5.01622","0.00537"
"60.42000","5.03524","0.00578"
"60.64800","5.05425","0.00576"
"60.87600","5.07320","0.00563"
"61.10400","5.09221","0.00594"
"61.33200","5.11123","0.00594"
"61.56000","5.13024","0.00611"
"61.78800","5.14925","0.00629"
"62.01600","5.16821","0.00582"
"62.24400","5.18722","0.00584"
"62.47200","5.20617","0.00646"
"62.70000","5.22519","0.00590"
"62.92800","5.24420","0.00632"
"63.15600","5.26321","0.00638"
"63.38400","5.28229","0.00601"
"63.61200","5.30124","0.00612"
"63.84000","5.32025","0.00679"
"64.06800","5.33921","0.00627"
"64.29600","5.35828","0.00679"
"64.52400","5.37723","0.00681"
"64.75200","5.39624","0.00601"
"64.98000","5.41520","0.00660"
"65.20800","5.43421","0.00608"
"65.43600","5.45328","0.00626"
"65.66400","5.47224","0.00619"
"65.89200","5.49119","0.00691"
"66.12000","5.51020","0.00661"
"66.34800","5.52922","0.00617"
"66.57600","5.54823","0.00633"
"66.80400","5.56718","0.00714"
"67.03200","5.58626","0.00670"
"67.26000","5.60521","0.00656"
"67.48800","5.62422","0.00687"
"67.71600","5.64330","0.00690"
"67.94400","5.66219","0.00688"
"68.17200","5.68126","0.00675"
"68.40000","5.70021","0.00640"
"68.62800","5.71929","0.00709"
"68.85600","5.73818","0.00630"
"69.08400","5.75719","0.00656"
"69.31200","5.77627","0.00698"
"69.54000","5.79516","0.00678"
"69.76800","5.81429","0.00655"
"69.99600","5.83319","0.00674"
"70.22400","5.85226","0.00675"
"70.45200","5.87121","0.00571"
"70.68000","5.89017","0.00626"
"70.90800","5.90924","0.00654"
"71.13600","5.92819","0.00612"
"71.36400","5.94726","0.00688"
"71.59200","5.96622","0.00612"
"71.82000","5.98517","0.00643"
"72.04800","6.00424","0.00654"
"72.27600","6.02320","0.00599"
"72.50400","6.04233","0.00695"
"72.73200","6.06116","0.00647"
"72.96000","6.08024","0.00690"
"73.18800","6.09925","0.00652"
"73.41600","6.11826","0.00671"
"73.64400","6.13728","0.00677"
"73.87200","6.15617","0.00685"
"74.10000","6.17524","0.00697"
"74.32800","6.19420","0.00714"
"74.55600","6.21327","0.00698"
"74.78400","6.23222","0.00750"
"75.01200","6.25124","0.00714"
"75.24000","6.27025","0.00724"
"75.46800","6.28914","0.00710"
"75.69600","6.30821","0.00678"
"75.92400","6.32723","0.00686"
"76.15200","6.34624","0.00739"
"76.38000","6.36525","0.00679"
"76.60800","6.38421","0.00664"
"76.83600","6.40328","0.00696"
"77.06400","6.42217","0.00653"
"77.29200","6.44125","0.00732"
"77.52000","6.46020","0.00655"
"77.74800","6.47921","0.00682"
"77.97600","6.49829","0.00690"
"78.20400","6.51724","0.00769"
"78.43200","6.53625","0.00695"
"78.66000","6.55514","0.00676"
"78.88800","6.57428","0.00739"
"79.11600","6.59323","0.00726"
"79.34400","6.61218","0.00747"
"79.57200","6.63120","0.00744"
"79.80000","6.65021","0.00733"
"80.02800","6.66922","0.00781"
"80.25600","6.68818","0.00711"
"80.48400","6.70725","0.00716"
"80.71200","6.72620","0.00738"
"80.94000","6.74522","0.00755"
"81.16800","6.76423","0.00727"
"81.39600","6.78324","0.00819"
"81.62400","6.80220","0.00738"
"81.85200","6.82121","0.00735"
"82.08000","6.84028","0.00709"
"82.30800","6.85923","0.00743"
"82.53600","6.87819","0.00781"
"82.76400","6.89726","0.00734"
"82.99200","6.91621","0.00766"
"83.22000","6.93523","0.00758"
"83.44800","6.95418","0.00763"
"83.67600","6.97331","0.00797"
"83.90400","6.99221","0.00800"
"84.13200","7.01122","0.00728"
"84.36000","7.03023","0.00762"
"84.58800","7.04919","0.00734"
"84.81600","7.06826","0.00721"
"85.04400","7.08721","0.00761"
"85.27200","7.10629","0.00804"
"85.50000","7.12524","0.00769"
"85.72800","7.14419","0.00819"
"85.95600","7.16326","0.00808"
"86.18400","7.18222","0.00782"
"86.41200","7.20123","0.00869"
"86.64000","7.22024","0.00853"
"86.86800","7.23926","0.00769"
"87.09600","7.25821","0.00820"
"87.32400","7.27716","0.00845"
"87.55200","7.29630","0.00783"
"87.78000","7.31519","0.00772"
"88.00800","7.33426","0.00857"
"88.23600","7.35322","0.00851"
"88.46400","7.37223","0.00887"
"88.69200","7.39130","0.00859"
"88.92000","7.41014","0.00860"
"89.14800","7.42927","0.00835"
"89.37600","7.44822","0.00852"
"89.60400","7.46729","0.00875"
"89.83200","7.48625","0.00861"
"90.06000","7.50520","0.00875"
"90.28800","7.52427","0.00868"
"90.51600","7.54311","0.00898"
"90.74400","7.56230","0.00826"
"90.97200","7.58125","0.00927"
"91.20000","7.60027","0.00897"
"91.42800","7.61922","0.00855"
"91.65600","7.63823","0.00884"
"91.88400","7.65725","0.00926"
"92.11200","7.67620","0.00847"
"92.34000","7.69527","0.00918"
"92.56800","7.71417","0.00890"
"92.79600","7.73318","0.00865"
"93.02400","7.75225","0.00950"
"93.25200","7.77120","0.00887"
"93.48000","7.79022","0.00950"
"93.70800","7.80917","0.00916"
"93.93600","7.82824","0.00941"
"94.16400","7.84726","0.00953"
"94.39200","7.86627","0.00875"
"94.62000","7.88522","0.01002"
"94.84800","7.90418","0.00950"
"95.07600","7.92319","0.00952"
"95.30400","7.94220","0.00969"
"95.53200","7.96128","0.00976"
"95.76000","7.98023","0.00979"
"95.98800","7.99918","0.00993"
"96.21600","8.01825","0.00952"
"96.44400","8.03727","0.00910"
"96.67200","8.05622","0.00930"
"96.90000","8.07517","0.00850"
"97.12800","8.09419","0.00870"
"97.35600","8.11326","0.00870"
"97.58400","8.13221","0.00882"
"97.81200","8.15123","0.00946"
"98.04000","8.17018","0.00944"
"98.26800","8.18919","0.00913"
"98.49600","8.20821","0.00958"
"98.72400","8.22728","0.00875"
"98.95200","8.24623","0.00920"
"99.18000","8.26519","0.00965"
"99.40800","8.28426","0.00964"
"99.63600","8.30321","0.00887"
"99.86400","8.32228","0.00941"
"100.09200","8.34124","0.00989"
"100.32000","8.36025","0.00965"
"100.54800","8.37920","0.01012"
"100.77600","8.39828","0.00983"
"101.00400","8.41717","0.00986"
"101.23200","8.43618","0.01007"
"101.46000","8.45526","0.01009"
"101.68800","8.47415","0.00983"
"101.91600","8.49322","0.00994"
"102.14400","8.51224","0.01050"
"102.37200","8.53119","0.01027"
"102.60000","8.55026","0.01066"
"102.82800","8.56922","0.01036"
"103.05600","8.58829","0.01051"
"103.28400","8.60718","0.01031"
"103.51200","8.62619","0.01104"
"103.74000","8.64527","0.01101"
"103.96800","8.66416","0.01072"
"104.19600","8.68329","0.01095"
"104.42400","8.70219","0.01075"
"104.65200","8.72126","0.01094"
"104.88000","8.74021","0.01066"
"105.10800","8.75917","0.01088"
"105.33600","8.77824","0.01144"
"105.56400","8.79719","0.01143"
"105.79200","8.81627","0.01102"
"106.02000","8.83516","0.01160"
"106.24800","8.85423","0.01163"
"106.47600","8.87324","0.01123"
"106.70400","8.89226","0.01186"
"106.93200","8.91127","0.01148"
"107.16000","8.93022","0.01197"
"107.38800","8.94924","0.01169"
"107.61600","8.96825","0.01191"
"107.84400","8.98720","0.01166"
"108.07200","9.00628","0.01176"
"108.30000","9.02517","0.01273"
"108.52800","9.04424","0.01199"
"108.75600","9.06320","0.01215"
"108.98400","9.08221","0.01236"
"109.21200","9.10128","0.01189"
"109.44000","9.12024","0.01213"
"109.66800","9.13925","0.01223"
"109.89600","9.15814","0.01195"
"110.12400","9.17722","0.01232"
"110.35200","9.19623","0.01217"
"110.58000","9.21524","0.01266"
"110.80800","9.23425","0.01319"
"111.03600","9.25321","0.01292"
"111.26400","9.27228","0.01247"
"111.49200","9.29117","0.01242"
"111.72000","9.31025","0.01230"
"111.94800","9.32920","0.01252"
"112.17600","9.34821","0.01266"
"112.40400","9.36729","0.01249"
"112.63200","9.38618","0.01236"
"112.86000","9.40525","0.01297"
"113.08800","9.42421","0.01261"
"113.31600","9.44328","0.01334"
"113.54400","9.46223","0.01269"
"113.77200","9.48118","0.01299"
"114.00000","9.50026","0.01344"
"114.22800","9.51921","0.01315"
"114.45600","9.53828","0.01252"
"114.68400","9.55718","0.01217"
"114.91200","9.57625","0.01206"
"115.14000","9.59520","0.01187"
"115.36800","9.61422","0.01235"
"115.59600","9.63329","0.01268"
"115.82400","9.65218","0.01238"
"116.05200","9.67120","0.01305"
"116.28000","9.69021","0.01282"
"116.50800","9.70922","0.01276"
"116.73600","9.72824","0.01317"
"116.96400","9.74725","0.01312"
"117.19200","9.76620","0.01309"
"117.42000","9.78521","0.01345"
"117.64800","9.80423","0.01362"
"117.87600","9.82318","0.01297"
"118.10400","9.84225","0.01336"
"118.33200","9.86121","0.01351"
"118.56000","9.88022","0.01322"
"118.78800","9.89929","0.01329"
"119.01600","9.91825","0.01342"
"119.24400","9.93726","0.01435"
"119.47200","9.95621","0.01350"
"119.70000","9.97529","0.01361"
"119.92800","9.99424","0.01388"
"120.15600","10.01319","0.01412"
"120.38400","10.03221","0.01477"
"120.61200","10.05116","0.01443"
"120.84000","10.07029","0.01371"
"121.06800","10.08924","0.01407"
"121.29600","10.10826","0.01406"
"121.52400","10.12727","0.01443"
"121.75200","10.14610","0.01452"
"121.98000","10.16530","0.01486"
"122.20800","10.18425","0.01517"
"122.43600","10.20326","0.01397"
"122.66400","10.22222","0.01496"
"122.89200","10.24117","0.01521"
"123.12000","10.26024","0.01508"
"123.34800","10.27914","0.01461"
"123.57600","10.29827","0.01514"
"123.80400","10.31722","0.01455"
"124.03200","10.33624","0.01553"
"124.26000","10.35525","0.01552"
"124.48800","10.37420","0.01510"
"124.71600","10.39328","0.01498"
"124.94400","10.41211","0.01518"
"125.17200","10.43124","0.01586"
"125.40000","10.45019","0.01505"
"125.62800","10.46921","0.01582"
"125.85600","10.48828","0.01606"
"126.08400","10.50723","0.01629"
"126.31200","10.52625","0.01644"
"126.54000","10.54520","0.01650"
"126.76800","10.56427","0.01621"
"126.99600","10.58322","0.01693"
"127.22400","10.60218","0.01619"
"127.45200","10.62125","0.01669"
"127.68000","10.64020","0.01656"
"127.90800","10.65928","0.01680"
"128.13600","10.67817","0.01683"
"128.36400","10.69724","0.01668"
"128.59200","10.71626","0.01786"
"128.82000","10.73521","0.01718"
"129.04800","10.75428","0.01735"
"129.27600","10.77318","0.01742"
"129.50400","10.79225","0.01467"
"129.73200","10.81120","0.01533"
"129.96000","10.83028","0.01486"
"130.18800","10.84923","0.01525"
"130.41600","10.86824","0.01552"
"130.64400","10.88725","0.01521"
"130.87200","10.90621","0.01538"
"131.10000","10.92522","0.01551"
"131.32800","10.94418","0.01556"
"131.55600","10.96325","0.01590"
"131.78400","10.98226","0.01581"
"132.01200","11.00121","0.01533"
"132.24000","11.02023","0.01541"
"132.46800","11.03924","0.01534"
"132.69600","11.05819","0.01623"
"132.92400","11.07727","0.01597"
"133.15200","11.09622","0.01494"
"133.38000","11.11523","0.01592"
"133.60800","11.13419","0.01577"
"133.83600","11.15326","0.01622"
"134.06400","11.17221","0.01608"
"134.29200","11.19123","0.01621"
"134.52000","11.21024","0.01675"
"134.74800","11.22925","0.01663"
"134.97600","11.24821","0.01553"
"135.20400","11.26722","0.01509"
"135.43200","11.28623","0.01467"
"135.66000","11.30519","0.01534"
"135.88800","11.32426","0.01512"
"136.11600","11.34321","0.01550"
"136.34400","11.36222","0.01546"
"136.57200","11.38124","0.01529"
"136.80000","11.40025","0.01575"
"137.02800","11.41920","0.01351"
"137.25600","11.43822","0.01374"
"137.48400","11.45729","0.01424"
"137.71200","11.47618","0.01438"
"137.94000","11.49519","0.01361"
"138.16800","11.51427","0.01421"
"138.39600","11.53316","0.01510"
"138.62400","11.55229","0.01516"
"138.85200","11.57119","0.01505"
"139.08000","11.59026","0.01517"
"139.30800","11.60921","0.01531"
"139.53600","11.62823","0.01537"
"139.76400","11.64724","0.01496"
"139.99200","11.66619","0.01455"
"140.22000","11.68527","0.01465"
"140.44800","11.70422","0.01462"
"140.67600","11.72323","0.01548"
"140.90400","11.74225","0.01515"
"141.13200","11.76120","0.01525"
"141.36000","11.78027","0.01532"
"141.58800","11.79917","0.01508"
"141.81600","11.81824","0.01537"
"142.04400","11.83725","0.01560"
"142.27200","11.85620","0.01547"
"142.50000","11.87522","0.01588"
"142.72800","11.89417","0.01463"
"142.95600","11.91324","0.01415"
"143.18400","11.93226","0.01411"
"143.41200","11.95127","0.01436"
"143.64000","11.97022","0.01429"
"143.86800","11.98924","0.01425"
"144.09600","12.00825","0.01436"
"144.32400","12.02714","0.01439"
"144.55200","12.04622","0.01437"
"144.78000","12.06517","0.01460"
"145.00800","12.08424","0.01468"
"145.23600","12.10326","0.01446"
"145.46400","12.12221","0.01468"
"145.69200","12.14122","0.01525"
"145.92000","12.16018","0.01597"
"146.14800","12.17925","0.01567"
"146.37600","12.19820","0.01574"
"146.60400","12.21721","0.01533"
"146.83200","12.23623","0.01540"
"147.06000","12.25518","0.01567"
"147.28800","12.27425","0.01444"
"147.51600","12.29321","0.01474"
"147.74400","12.31228","0.01495"
"147.97200","12.33129","0.01408"
"148.20000","12.35018","0.01433"
"148.42800","12.36920","0.01431"
"148.65600","12.38815","0.01491"
"148.88400","12.40722","0.01418"
"149.11200","12.42618","0.01443"
"149.34000","12.44525","0.01315"
"149.56800","12.46426","0.01331"
"149.79600","12.48322","0.01339"
"150.02400","12.50229","0.01388"
"150.25200","12.52124","0.01353"
"150.48000","12.54020","0.01377"
"150.70800","12.55921","0.01408"
"150.93600","12.57822","0.01340"
"151.16400","12.59724","0.01404"
"151.39200","12.61619","0.01435"
"151.62000","12.63526","0.01413"
"151.84800","12.65421","0.01414"
"152.07600","12.67323","0.01396"
"152.30400","12.69224","0.01429"
"152.53200","12.71119","0.01439"
"152.76000","12.73021","0.01444"
"152.98800","12.74922","0.01453"
"153.21600","12.76824","0.01412"
"153.44400","12.78725","0.01349"
"153.67200","12.80620","0.01401"
"153.90000","12.82521","0.01385"
"154.12800","12.84429","0.01371"
"154.35600","12.86324","0.01400"
"154.58400","12.88219","0.01314"
"154.81200","12.90121","0.01251"
"155.04000","12.92016","0.01259"
"155.26800","12.93923","0.01351"
"155.49600","12.95825","0.01253"
"155.72400","12.97726","0.01213"
"155.95200","12.99627","0.01312"
"156.18000","13.01517","0.01292"
"156.40800","13.03424","0.01293"
"156.63600","13.05319","0.01327"
"156.86400","13.07226","0.01338"
"157.09200","13.09122","0.01374"
"157.32000","13.11023","0.01313"
"157.54800","13.12924","0.01318"
"157.77600","13.14820","0.01260"
"158.00400","13.16727","0.01312"
"158.23200","13.18622","0.01344"
"158.46000","13.20518","0.01257"
"158.68800","13.22425","0.01293"
"158.91600","13.24320","0.01306"
"159.14400","13.26228","0.01378"
"159.37200","13.28117","0.01377"
"159.60000","13.30030","0.01304"
"159.82800","13.31925","0.01414"
"160.05600","13.33821","0.01408"
"160.28400","13.35722","0.01383"
"160.51200","13.37617","0.01415"
"160.74000","13.39531","0.01393"
"160.96800","13.41420","0.01466"
"161.19600","13.43321","0.01421"
"161.42400","13.45223","0.01477"
"161.65200","13.47124","0.01477"
"161.88000","13.49025","0.01461"
"162.10800","13.50921","0.01529"
"162.33600","13.52822","0.01519"
"162.56400","13.54723","0.01505"
"162.79200","13.56631","0.01548"
"163.02000","13.58526","0.01534"
"163.24800","13.60421","0.01554"
"163.47600","13.62322","0.01588"
"163.70400","13.64218","0.01581"
"163.93200","13.66125","0.01531"
"164.16000","13.68020","0.01591"
"164.38800","13.69928","0.01506"
"164.61600","13.71829","0.01587"
"164.84400","13.73718","0.01576"
"165.07200","13.75626","0.01581"
"165.30000","13.77515","0.01582"
"165.52800","13.79422","0.01584"
"165.75600","13.81324","0.01535"
"165.98400","13.83219","0.01609"
"166.21200","13.85126","0.01622"
"166.44000","13.87022","0.01615"
"166.66800","13.88923","0.01606"
"166.89600","13.90824","0.01517"
"167.12400","13.92719","0.01508"
"167.35200","13.94627","0.01422"
"167.58000","13.96516","0.01492"
"167.80800","13.98423","0.01485"
"168.03600","14.00313","0.01537"
"168.26400","14.02226","0.01465"
"168.49200","14.04121","0.01576"
"168.72000","14.06023","0.01615"
"168.94800","14.07924","0.01579"
"169.17600","14.09819","0.01594"
"169.40400","14.11721","0.01557"
"169.63200","14.13622","0.01433"
"169.86000","14.15523","0.01428"
"170.08800","14.17418","0.01476"
"170.31600","14.19326","0.01469"
"170.54400","14.21221","0.01413"
"170.77200","14.23123","0.01488"
"171.00000","14.25024","0.01473"
"171.22800","14.26919","0.01417"
"171.45600","14.28820","0.01405"
"171.68400","14.30722","0.01503"
"171.91200","14.32623","0.01421"
"172.14000","14.34524","0.01276"
"172.36800","14.36426","0.01305"
"172.59600","14.38321","0.01383"
"172.82400","14.40216","0.01398"
"173.05200","14.42130","0.01370"
"173.28000","14.44019","0.01373"
"173.50800","14.45926","0.01430"
"173.73600","14.47822","0.01376"
"173.96400","14.49723","0.01429"
"174.19200","14.51624","0.01411"
"174.42000","14.53519","0.01493"
"174.64800","14.55427","0.01495"
"174.87600","14.57316","0.01417"
"175.10400","14.59223","0.01578"
"175.33200","14.61125","0.01514"
"175.56000","14.63020","0.01516"
"175.78800","14.64921","0.01449"
"176.01600","14.66823","0.01476"
"176.24400","14.68724","0.01421"
"176.47200","14.70619","0.01537"
"176.70000","14.72521","0.01562"
"176.92800","14.74428","0.01526"
"177.15600","14.76317","0.01533"
"177.38400","14.78225","0.01578"
"177.61200","14.80120","0.01577"
"177.84000","14.82021","0.01594"
"178.06800","14.83922","0.01674"
"178.29600","14.85818","0.01633"
"178.52400","14.87725","0.01637"
"178.75200","14.89614","0.01688"
"178.98000","14.91528","0.01711"
"179.20800","14.93423","0.01725"
"179.43600","14.95324","0.01707"
"179.66400","14.97226","0.01719"
"179.89200","14.99121","0.01811"
"180.12000","15.01028","0.01759"
"180.34800","15.02918","0.01816"
"180.57600","15.04831","0.01800"
"180.80400","15.06720","0.01837"
"181.03200","15.08622","0.01837"
"181.26000","15.10529","0.01856"
"181.48800","15.12412","0.01802"
"181.71600","15.14325","0.01810"
"181.94400","15.16221","0.01822"
"182.17200","15.18128","0.01826"
"182.40000","15.20023","0.01871"
"182.62800","15.21925","0.01870"
"182.85600","15.23826","0.01452"
"183.08400","15.25715","0.01140"
"183.31200","15.27629","0.01122"
"183.54000","15.29518","0.01188"
"183.76800","15.31419","0.01160"
"183.99600","15.33327","0.01185"
"184.22400","15.35216","0.01238"
"184.45200","15.37129","0.01198"
"184.68000","15.39018","0.01187"
"184.90800","15.40920","0.01232"
"185.13600","15.42827","0.01209"
"185.36400","15.44722","0.01239"
"185.59200","15.46624","0.01298"
"185.82000","15.48519","0.01286"
"186.04800","15.50420","0.01266"
"186.27600","15.52322","0.01335"
"186.50400","15.54223","0.01321"
"186.73200","15.56118","0.01374"
"186.96000","15.58020","0.01372"
"187.18800","15.59921","0.01324"
"187.41600","15.61822","0.01320"
"187.64400","15.63723","0.01400"
"187.87200","15.65625","0.01425"
"188.10000","15.67526","0.01416"
"188.32800","15.69427","0.01439"
"188.55600","15.71323","0.01445"
"188.78400","15.73224","0.01465"
"189.01200","15.75119","0.01489"
"189.24000","15.77021","0.01474"
"189.46800","15.78922","0.01525"
"189.69600","15.80823","0.01487"
"189.92400","15.82725","0.01544"
"190.15200","15.84626","0.01505"
"190.38000","15.86521","0.01580"
"190.60800","15.88416","0.01552"
"190.83600","15.90324","0.01290"
"191.06400","15.92219","0.01294"
"191.29200","15.94126","0.01364"
"191.52000","15.96022","0.01348"
"191.74800","15.97923","0.01400"
"191.97600","15.99824","0.01409"
"192.20400","16.01714","0.01417"
"192.43200","16.03627","0.01404"
"192.66000","16.05522","0.01542"
"192.88800","16.07424","0.01443"
"193.11600","16.09325","0.01514"
"193.34400","16.11220","0.01494"
"193.57200","16.13121","0.01523"
"193.80000","16.15017","0.01489"
"194.02800","16.16930","0.01386"
"194.25600","16.18826","0.01376"
"194.48400","16.20721","0.01499"
"194.71200","16.22622","0.01401"
"194.94000","16.24517","0.01442"
"195.16800","16.26425","0.01431"
"195.39600","16.28320","0.01509"
"195.62400","16.30227","0.01513"
"195.85200","16.32117","0.01446"
"196.08000","16.34024","0.01447"
"196.30800","16.35925","0.01468"
"196.53600","16.37821","0.01494"
"196.76400","16.39722","0.01544"
"196.99200","16.41617","0.01509"
"197.22000","16.43525","0.01454"
"197.44800","16.45426","0.01471"
"197.67600","16.47321","0.01488"
"197.90400","16.49228","0.01465"
"198.13200","16.51112","0.01557"
"198.36000","16.53025","0.01518"
"198.58800","16.54920","0.01553"
"198.81600","16.56828","0.01492"
"199.04400","16.58723","0.01635"
"199.27200","16.60612","0.01567"
"199.50000","16.62526","0.01620"
"199.72800","16.64421","0.01637"
"199.95600","16.66328","0.01676"
"200.18400","16.68224","0.01679"
"200.41200","16.70125","0.01547"
"200.64000","16.72026","0.01602"
"200.86800","16.73916","0.01631"
"201.09600","16.75823","0.01633"
"201.32400","16.77724","0.01754"
"201.55200","16.79620","0.01720"
"201.78000","16.81527","0.01763"
"202.00800","16.83422","0.01744"
"202.23600","16.85323","0.01711"
"202.46400","16.87219","0.01786"
"202.69200","16.89120","0.01672"
"202.92000","16.91027","0.01694"
"203.14800","16.92923","0.01774"
"203.37600","16.94824","0.01783"
"203.60400","16.96725","0.01769"
"203.83200","16.98627","0.01821"
"204.06000","17.00516","0.01804"
"204.28800","17.02423","0.01847"
"204.51600","17.04319","0.01878"
"204.74400","17.06226","0.01765"
"204.97200","17.08121","0.01852"
"205.20000","17.10022","0.01826"
"205.42800","17.11924","0.01936"
"205.65600","17.13819","0.01902"
"205.88400","17.15720","0.01908"
"206.11200","17.17622","0.01960"
"206.34000","17.19529","0.01953"
"206.56800","17.21418","0.01994"
"206.79600","17.23320","0.02023"
"207.02400","17.25221","0.02078"
"207.25200","17.27116","0.02056"
"207.48000","17.29024","0.02077"
"207.70800","17.30925","0.02106"
"207.93600","17.32826","0.02115"
"208.16400","17.34727","0.02125"
"208.39200","17.36623","0.02152"
"208.62000","17.38524","0.01681"
"208.84800","17.40420","0.01527"
"209.07600","17.42321","0.01569"
"209.30400","17.44222","0.01535"
"209.53200","17.46129","0.01630"
"209.76000","17.48025","0.01686"
"209.98800","17.49920","0.01690"
"210.21600","17.51821","0.01631"
"210.44400","17.53723","0.01670"
"210.67200","17.55630","0.01742"
"210.90000","17.57519","0.01734"
"211.12800","17.59421","0.01703"
"211.35600","17.61322","0.01722"
"211.58400","17.63217","0.01679"
"211.81200","17.65125","0.01721"
"212.04000","17.67020","0.01771"
"212.26800","17.68921","0.01734"
"212.49600","17.70823","0.01696"
"212.72400","17.72718","0.01705"
"212.95200","17.74625","0.01743"
"213.18000","17.76520","0.01746"
"213.40800","17.78428","0.01636"
"213.63600","17.80323","0.01649"
"213.86400","17.82224","0.01729"
"214.09200","17.84126","0.01748"
"214.32000","17.86021","0.01714"
"214.54800","17.87922","0.01766"
"214.77600","17.89818","0.01727"
"215.00400","17.91725","0.01745"
"215.23200","17.93620","0.01812"
"215.46000","17.95522","0.01754"
"215.68800","17.97423","0.01755"
"215.91600","17.99318","0.01749"
"216.14400","18.01225","0.01346"
"216.37200","18.03121","0.01206"
"216.60000","18.05028","0.01274"
"216.82800","18.06923","0.01319"
"217.05600","18.08819","0.01361"
"217.28400","18.10726","0.01352"
"217.51200","18.12615","0.01319"
"217.74000","18.14523","0.01425"
"217.96800","18.16424","0.01416"
"218.19600","18.18325","0.01490"
"218.42400","18.20226","0.01446"
"218.65200","18.22116","0.01450"
"218.88000","18.24023","0.01520"
"219.10800","18.25918","0.01529"
"219.33600","18.27826","0.01502"
"219.56400","18.29721","0.01554"
"219.79200","18.31623","0.01600"
"220.02000","18.33524","0.01562"
"220.24800","18.35413","0.01630"
"220.47600","18.37321","0.01688"
"220.70400","18.39222","0.01661"
"220.93200","18.41129","0.01681"
"221.16000","18.43024","0.01673"
"221.38800","18.44926","0.01726"
"221.61600","18.46821","0.01664"
"221.84400","18.48722","0.01644"
"222.07200","18.50624","0.01641"
"222.30000","18.52525","0.01563"
"222.52800","18.54426","0.01576"
"222.75600","18.56322","0.01592"
"222.98400","18.58223","0.01645"
"223.21200","18.60124","0.01705"
"223.44000","18.62020","0.01623"
"223.66800","18.63927","0.01653"
"223.89600","18.65822","0.01693"
"224.12400","18.67723","0.01712"
"224.35200","18.69625","0.01745"
"224.58000","18.71520","0.01778"
"224.80800","18.73427","0.01785"
"225.03600","18.75317","0.01821"
"225.26400","18.77224","0.01778"
"225.49200","18.79119","0.01863"
"225.72000","18.81021","0.01804"
"225.94800","18.82922","0.01856"
"226.17600","18.84823","0.01912"
"226.40400","18.86724","0.01867"
"226.63200","18.88620","0.01916"
"226.86000","18.90527","0.02001"
"227.08800","18.92422","0.01943"
"227.31600","18.94324","0.01971"
"227.54400","18.96225","0.02002"
"227.77200","18.98126","0.01970"
"228.00000","19.00022","0.02004"
"228.22800","19.01917","0.01963"
"228.45600","19.03824","0.02027"
"228.68400","19.05725","0.02054"
"228.91200","19.07621","0.02064"
"229.14000","19.09522","0.02099"
"229.36800","19.11418","0.02074"
"229.59600","19.13325","0.02119"
"229.82400","19.15220","0.02090"
"230.05200","19.17128","0.02025"
"230.28000","19.19017","0.02139"
"230.50800","19.20918","0.02073"
"230.73600","19.22825","0.02118"
"230.96400","19.24721","0.02117"
"231.19200","19.26622","0.02140"
"231.42000","19.28517","0.02193"
"231.64800","19.30425","0.02184"
"231.87600","19.32326","0.02148"
"232.10400","19.34221","0.02149"
"232.33200","19.36123","0.02149"
"232.56000","19.38018","0.02143"
"232.78800","19.39925","0.02193"
"233.01600","19.41821","0.02173"
"233.24400","19.43722","0.02194"
"233.47200","19.45629","0.02203"
"233.70000","19.47518","0.02228"
"233.92800","19.49432","0.02266"
"234.15600","19.51315","0.02185"
"234.38400","19.53228","0.02249"
"234.61200","19.55124","0.02208"
"234.84000","19.57019","0.02202"
"235.06800","19.58926","0.02319"
"235.29600","19.60816","0.02288"
"235.52400","19.62729","0.02316"
"235.75200","19.64624","0.02417"
"235.98000","19.66526","0.02332"
"236.20800","19.68421","0.02347"
"236.43600","19.70322","0.02196"
"236.66400","19.72223","0.02124"
"236.89200","19.74113","0.02154"
"237.12000","19.76020","0.02172"
"237.34800","19.77921","0.02265"
"237.57600","19.79823","0.02175"
"237.80400","19.81730","0.02144"
"238.03200","19.83619","0.02125"
"238.26000","19.85527","0.02217"
"238.48800","19.87416","0.02312"
"238.71600","19.89323","0.02253"
"238.94400","19.91225","0.02278"
"239.17200","19.93126","0.02333"
"239.40000","19.95027","0.02361"
"239.62800","19.96922","0.02360"
"239.85600","19.98824","0.02396"
"240.08400","20.00719","0.02371"
"240.31200","20.02626","0.02354"
"240.54000","20.04528","0.02433"
"240.76800","20.06429","0.02430"
"240.99600","20.08324","0.02278"
"241.22400","20.10220","0.02328"
"241.45200","20.12121","0.02403"
"241.68000","20.14022","0.02373"
"241.90800","20.15924","0.02413"
"242.13600","20.17825","0.02453"
"242.36400","20.19726","0.02440"
"242.59200","20.21628","0.02439"
"242.82000","20.23523","0.02501"
"243.04800","20.25418","0.02529"
"243.27600","20.27313","0.02559"
"243.50400","20.29221","0.02604"
"243.73200","20.31122","0.02613"
"243.96000","20.33018","0.02595"
"244.18800","20.34925","0.02627"
"244.41600","20.36820","0.02642"
"244.64400","20.38721","0.02523"
"244.87200","20.40617","0.02412"
"245.10000","20.42524","0.02463"
"245.32800","20.44425","0.02511"
"245.55600","20.46321","0.02479"
"245.78400","20.48222","0.02590"
"246.01200","20.50123","0.02536"
"246.24000","20.52024","0.02620"
"246.46800","20.53920","0.02625"
"246.69600","20.55827","0.02633"
"246.92400","20.57723","0.02640"
"247.15200","20.59624","0.02634"
"247.38000","20.61525","0.02724"
"247.60800","20.63421","0.02733"
"247.83600","20.65322","0.02709"
"248.06400","20.67217","0.02766"
"248.29200","20.69118","0.02763"
"248.52000","20.71020","0.02775"
"248.74800","20.72915","0.02760"
"248.97600","20.74828","0.02790"
"249.20400","20.76717","0.02771"
"249.43200","20.78631","0.02806"
"249.66000","20.80520","0.02816"
"249.88800","20.82422","0.02811"
"250.11600","20.84329","0.02818"
"250.34400","20.86212","0.02827"
"250.57200","20.88126","0.02798"
"250.80000","20.90021","0.02774"
"251.02800","20.91928","0.02863"
"251.25600","20.93823","0.02843"
"251.48400","20.95719","0.02899"
"251.71200","20.97626","0.02881"
"251.94000","20.99521","0.02735"
"252.16800","21.01423","0.02758"
"252.39600","21.03318","0.02764"
"252.62400","21.05225","0.02801"
"252.85200","21.07121","0.02803"
"253.08000","21.09022","0.02863"
"253.30800","21.10923","0.02838"
"253.53600","21.12819","0.02798"
"253.76400","21.14726","0.02787"
"253.99200","21.16621","0.02836"
"254.22000","21.18522","0.02810"
"254.44800","21.20424","0.02821"
"254.67600","21.22313","0.02853"
"254.90400","21.24220","0.02897"
"255.13200","21.26122","0.02874"
"255.36000","21.28029","0.02814"
"255.58800","21.29924","0.01545"
"255.81600","21.31825","0.01254"
"256.04400","21.33727","0.01357"
"256.27200","21.35616","0.01167"
"256.50000","21.37523","0.00688"
"256.72800","21.39419","0.00732"
"256.95600","21.41326","0.00754"
"257.18400","21.43222","0.00650"
"257.41200","21.45123","0.00699"
"257.64000","21.47024","0.00653"
"257.86800","21.48919","0.00682"
"258.09600","21.50821","0.00721"
"258.32400","21.52722","0.00752"
"258.55200","21.54623","0.00737"
"258.78000","21.56525","0.00839"
"259.00800","21.58420","0.00877"
"259.23600","21.60328","0.00912"
"259.46400","21.62223","0.00832"
"259.69200","21.64124","0.00924"
"259.92000","21.66019","0.00982"
"260.14800","21.67921","0.01013"
"260.37600","21.69822","0.00993"
"260.60400","21.71723","0.01109"
"260.83200","21.73625","0.01050"
"261.06000","21.75520","0.01074"
"261.28800","21.77427","0.01151"
"261.51600","21.79323","0.01099"
"261.74400","21.81224","0.01121"
"261.97200","21.83125","0.01171"
"262.20000","21.85020","0.01194"
"262.42800","21.86922","0.01253"
"262.65600","21.88817","0.01236"
"262.88400","21.90724","0.01330"
"263.11200","21.92620","0.01308"
"263.34000","21.94521","0.01352"
"263.56800","21.96422","0.01307"
"263.79600","21.98324","0.01317"
"264.02400","22.00225","0.01408"
"264.25200","22.02120","0.01420"
"264.48000","22.04027","0.01471"
"264.70800","22.05923","0.01506"
"264.93600","22.07818","0.01531"
"265.16400","22.09726","0.01538"
"265.39200","22.11621","0.01542"
"265.62000","22.13522","0.01600"
"265.84800","22.15412","0.01561"
"266.07600","22.17331","0.01686"
"266.30400","22.19220","0.01750"
"266.53200","22.21121","0.01758"
"266.76000","22.23022","0.01759"
"266.98800","22.24912","0.01787"
"267.21600","22.26826","0.01900"
"267.44400","22.28720","0.01815"
"267.67200","22.30622","0.01953"
"267.90000","22.32523","0.01929"
"268.12800","22.34419","0.01686"
"268.35600","22.36326","0.01777"
"268.58400","22.38221","0.01761"
"268.81200","22.40129","0.01894"
"269.04000","22.42024","0.01914"
"269.26800","22.43919","0.01997"
"269.49600","22.45832","0.01975"
"269.72400","22.47716","0.02063"
"269.95200","22.49629","0.02032"
"270.18000","22.51518","0.01957"
"270.40800","22.53425","0.02013"
"270.63600","22.55327","0.02020"
"270.86400","22.57222","0.01972"
"271.09200","22.59124","0.02027"
"271.32000","22.61007","0.02037"
"271.54800","22.62926","0.02109"
"271.77600","22.64822","0.02137"
"272.00400","22.66729","0.02214"
"272.23200","22.68618","0.02213"
"272.46000","22.70520","0.02316"
"272.68800","22.72427","0.02317"
"272.91600","22.74322","0.02331"
"273.14400","22.76223","0.02382"
"273.37200","22.78125","0.02367"
"273.60000","22.80020","0.02441"
"273.82800","22.81921","0.02437"
"274.05600","22.83817","0.02456"
"274.28400","22.85724","0.02526"
"274.51200","22.87619","0.02469"
"274.74000","22.89527","0.02518"
"274.96800","22.91428","0.02610"
"275.19600","22.93323","0.02618"
"275.42400","22.95219","0.02653"
"275.65200","22.97114","0.02672"
"275.88000","22.99027","0.02706"
"276.10800","23.00916","0.02687"
"276.33600","23.02824","0.02712"
"276.56400","23.04725","0.02721"
"276.79200","23.06620","0.02694"
"277.02000","23.08522","0.02706"
"277.24800","23.10417","0.02736"
"277.47600","23.12324","0.02760"
"277.70400","23.14220","0.02758"
"277.93200","23.16121","0.02829"
"278.16000","23.18022","0.02822"
"278.38800","23.19924","0.02823"
"278.61600","23.21825","0.02829"
"278.84400","23.23726","0.02928"
"279.07200","23.25622","0.02926"
"279.30000","23.27523","0.02931"
"279.52800","23.29418","0.02915"
"279.75600","23.31326","0.02918"
"279.98400","23.33215","0.02968"
"280.21200","23.35122","0.02986"
"280.44000","23.37017","0.02934"
"280.66800","23.38925","0.02980"
"280.89600","23.40820","0.03002"
"281.12400","23.42727","0.03028"
"281.35200","23.44629","0.03056"
"281.58000","23.46524","0.03050"
"281.80800","23.48419","0.03081"
"282.03600","23.50321","0.03084"
"282.26400","23.52228","0.03103"
"282.49200","23.54117","0.03022"
"282.72000","23.56025","0.03148"
"282.94800","23.57926","0.03217"
"283.17600","23.59815","0.03188"
"283.40400","23.61722","0.03205"
"283.63200","23.63624","0.03210"
"283.86000","23.65525","0.03234"
"284.08800","23.67426","0.03268"
"284.31600","23.69322","0.03265"
"284.54400","23.71229","0.03258"
"284.77200","23.73112","0.03280"
"285.00000","23.75032","0.03270"
"285.22800","23.76921","0.03309"
"285.45600","23.78822","0.03313"
"285.68400","23.80724","0.03324"
"285.91200","23.82619","0.03343"
"286.14000","23.84526","0.03364"
"286.36800","23.86415","0.03366"
"286.59600","23.88329","0.03410"
"286.82400","23.90218","0.03417"
"287.05200","23.92120","0.03427"
"287.28000","23.94027","0.03429"
"287.50800","23.95916","0.03433"
"287.73600","23.97823","0.03450"
"287.96400","23.99719","0.03479"
"288.19200","24.01626","0.03491"
"288.42000","24.03521","0.03474"
"288.64800","24.05423","0.03340"
"288.87600","24.07324","0.03426"
"289.10400","24.09219","0.03415"
"289.33200","24.11126","0.03427"
"289.56000","24.13022","0.03441"
"289.78800","24.14923","0.03462"
"290.01600","24.16825","0.03506"
"290.24400","24.18726","0.03514"
"290.47200","24.20627","0.03550"
"290.70000","24.22516","0.03564"
"290.92800","24.24424","0.03499"
"291.15600","24.26319","0.03560"
"291.38400","24.28220","0.03594"
"291.61200","24.30128","0.03538"
"291.84000","24.32023","0.03599"
"292.06800","24.33924","0.03598"
"292.29600","24.35814","0.03631"
"292.52400","24.37727","0.03645"
"292.75200","24.39622","0.03678"
"292.98000","24.41524","0.03689"
"293.20800","24.43425","0.03701"
"293.43600","24.45320","0.03688"
"293.66400","24.47221","0.03727"
"293.89200","24.49123","0.03754"
"294.12000","24.51024","0.03788"
"294.34800","24.52925","0.03767"
"294.57600","24.54815","0.03826"
"294.80400","24.56722","0.03867"
"295.03200","24.58617","0.03856"
"295.26000","24.60525","0.03889"
"295.48800","24.62420","0.03922"
"295.71600","24.64322","0.03912"
"295.94400","24.66222","0.03935"
"296.17200","24.68124","0.03858"
"296.40000","24.70025","0.03777"
"296.62800","24.71920","0.03821"
"296.85600","24.73822","0.03835"
"297.08400","24.75717","0.03894"
"297.31200","24.77625","0.03917"
"297.54000","24.79520","0.03980"
"297.76800","24.81427","0.03968"
"297.99600","24.83322","0.04008"
"298.22400","24.85224","0.03973"
"298.45200","24.87119","0.04026"
"298.68000","24.89020","0.04037"
"298.90800","24.90922","0.04084"
"299.13600","24.92817","0.04149"
"299.36400","24.94718","0.04157"
"299.59200","24.96626","0.04215"
"299.82000","24.98521","0.04244"
"300.04800","25.00428","0.04262"
"300.27600","25.02318","0.04322"
"300.50400","25.04225","0.04376"
"300.73200","25.06126","0.04451"
"300.96000","25.08015","0.04472"
"301.18800","25.09923","0.04563"
"301.41600","25.11818","0.04557"
"301.64400","25.13725","0.04622"
"301.87200","25.15621","0.04541"
"302.10000","25.17522","0.04477"
"302.32800","25.19423","0.04549"
"302.55600","25.21313","0.04612"
"302.78400","25.23232","0.04623"
"303.01200","25.25121","0.03975"
"303.24000","25.27028","0.04027"
"303.46800","25.28918","0.03989"
"303.69600","25.30819","0.04006"
"303.92400","25.32726","0.04053"
"304.15200","25.34616","0.04087"
"304.38000","25.36523","0.04081"
"304.60800","25.38424","0.04104"
"304.83600","25.40326","0.04205"
"305.06400","25.42221","0.04226"
"305.29200","25.44122","0.04300"
"305.52000","25.46029","0.04349"
"305.74800","25.47913","0.04404"
"305.97600","25.49826","0.04477"
"306.20400","25.51722","0.04511"
"306.43200","25.53623","0.04601"
"306.66000","25.55524","0.04605"
"306.88800","25.57419","0.04565"
"307.11600","25.59327","0.04573"
"307.34400","25.61216","0.04580"
"307.57200","25.63129","0.04659"
"307.80000","25.65019","0.04725"
"308.02800","25.66920","0.04782"
"308.25600","25.68821","0.04898"
"308.48400","25.70723","0.04927"
"308.71200","25.72624","0.04959"
"308.94000","25.74519","0.05050"
"309.16800","25.76427","0.05124"
"309.39600","25.78328","0.05242"
"309.62400","25.80223","0.05241"
"309.85200","25.82125","0.05335"
"310.08000","25.84014","0.05383"
"310.30800","25.85921","0.05478"
"310.53600","25.87823","0.05537"
"310.76400","25.89724","0.05587"
"310.99200","25.91625","0.05667"
"311.22000","25.93521","0.05771"
"311.44800","25.95428","0.05807"
"311.67600","25.97323","0.05825"
"311.90400","25.99224","0.05915"
"312.13200","26.01120","0.05950"
"312.36000","26.03027","0.06052"
"312.58800","26.04928","0.06053"
"312.81600","26.06824","0.06163"
"313.04400","26.08725","0.06231"
"313.27200","26.10620","0.06264"
"313.50000","26.12522","0.06327"
"313.72800","26.14423","0.06386"
"313.95600","26.16324","0.06402"
"314.18400","26.18220","0.06519"
"314.41200","26.20121","0.06522"
"314.64000","26.22022","0.06597"
"314.86800","26.23923","0.06637"
"315.09600","26.25825","0.06683"
"315.32400","26.27720","0.06774"
"315.55200","26.29621","0.06695"
"315.78000","26.31523","0.06780"
"316.00800","26.33424","0.06856"
"316.23600","26.35325","0.06884"
"316.46400","26.37221","0.06914"
"316.69200","26.39122","0.06993"
"316.92000","26.41017","0.07118"
"317.14800","26.42925","0.07176"
"317.37600","26.44826","0.07223"
"317.60400","26.46721","0.07301"
"317.83200","26.48623","0.07363"
"318.06000","26.50524","0.07482"
"318.28800","26.52425","0.07557"
"318.51600","26.54314","0.07590"
"318.74400","26.56222","0.07697"
"318.97200","26.58123","0.07748"
"319.20000","26.60018","0.07813"
"319.42800","26.61926","0.07937"
"319.65600","26.63821","0.08040"
"319.88400","26.65728","0.07816"
"320.11200","26.67624","0.07782"
"320.34000","26.69519","0.07723"
"320.56800","26.71426","0.07642"
"320.79600","26.73316","0.07455"
"321.02400","26.75229","0.07520"
"321.25200","26.77118","0.07577"
"321.48000","26.79019","0.07608"
"321.70800","26.80927","0.07253"
"321.93600","26.82822","0.07401"
"322.16400","26.84729","0.07273"
"322.39200","26.86619","0.07152"
"322.62000","26.88526","0.07186"
"322.84800","26.90421","0.07188"
"323.07600","26.92323","0.07191"
"323.30400","26.94224","0.07220"
"323.53200","26.96119","0.07319"
"323.76000","26.98021","0.07255"
"323.98800","26.99922","0.07298"
"324.21600","27.01823","0.07410"
"324.44400","27.03724","0.07476"
"324.67200","27.05620","0.07505"
"324.90000","27.07527","0.07584"
"325.12800","27.09417","0.07619"
"325.35600","27.11324","0.07568"
"325.58400","27.13219","0.07722"
"325.81200","27.15121","0.07833"
"326.04000","27.17028","0.07860"
"326.26800","27.18923","0.07935"
"326.49600","27.20824","0.07938"
"326.72400","27.22714","0.08011"
"326.95200","27.24621","0.08049"
"327.18000","27.26522","0.08098"
"327.40800","27.28424","0.08162"
"327.63600","27.30325","0.08198"
"327.86400","27.32220","0.08217"
"328.09200","27.34122","0.08323"
"328.32000","27.36017","0.08310"
"328.54800","27.37924","0.08367"
"328.77600","27.39825","0.08439"
"329.00400","27.41721","0.08441"
"329.23200","27.43622","0.08466"
"329.46000","27.45518","0.08471"
"329.68800","27.47425","0.08522"
"329.91600","27.49326","0.08544"
"330.14400","27.51221","0.08571"
"330.37200","27.53129","0.08580"
"330.60000","27.55018","0.08611"
"330.82800","27.56925","0.08642"
"331.05600","27.58821","0.08618"
"331.28400","27.60716","0.08664"
"331.51200","27.62623","0.08696"
"331.74000","27.64525","0.08718"
"331.96800","27.66426","0.08713"
"332.19600","27.68321","0.08708"
"332.42400","27.70222","0.08713"
"332.65200","27.72118","0.08718"
"332.88000","27.74019","0.08721"
"333.10800","27.75920","0.08748"
"333.33600","27.77822","0.08751"
"333.56400","27.79723","0.08778"
"333.79200","27.81624","0.08773"
"334.02000","27.83520","0.08777"
"334.24800","27.85421","0.08779"
"334.47600","27.87322","-0.00925"
"334.70400","27.89223","-0.00427"
"334.93200","27.91125","0.00141"
"335.16000","27.93026","0.00161"
"335.38800","27.94921","0.00655"
"335.61600","27.96823","-0.00076"
"335.84400","27.98718","0.00073"
"336.07200","28.00631","0.00121"
"336.30000","28.02521","0.00167"
"336.52800","28.04428","0.00095"
"336.75600","28.06324","0.00067"
"336.98400","28.08219","0.00008"
"337.21200","28.10126","0.00062"
"337.44000","28.12021","0.00200"
"337.66800","28.13929","0.00053"
"337.89600","28.15818","0.00057"
"338.12400","28.17725","0.00071"
"338.35200","28.19627","0.00139"
"338.58000","28.21516","0.00159"
"338.80800","28.23429","0.00047"
"339.03600","28.25319","0.00065"
"339.26400","28.27226","0.00141"
"339.33000","28.27770","0.00095"