File: Force_trajectories/170122_1/Specimen_RawData_3.csv
End date,"1/22/2017"
Specimen label,"3BT_19"
Maximum Load,"0.13672",N

Time,Extension,Load
(s),(mm),(N)
"0.00000","0.00000","0.00028"
"0.23400","0.01788","-0.00045"
"0.46800","0.03928","0.00011"
"0.70200","0.05877","-0.00031"
"0.93600","0.07826","0.00009"
"1.17000","0.09776","-0.00063"
"1.40400","0.11725","-0.00063"
"1.63800","0.13662","-0.00030"
"1.87200","0.15629","-0.00024"
"2.10600","0.17566","0.00000"
"2.34000","0.19521","-0.00049"
"2.57400","0.21470","-0.00019"
"2.80800","0.23420","-0.00087"
"3.04200","0.25375","-0.00057"
"3.27600","0.27318","-0.00029"
"3.51000","0.29267","-0.00062"
"3.74400","0.31216","-0.00019"
"3.97800","0.33171","-0.00052"
"4.21200","0.35126","0.00018"
"4.44600","0.37070","0.00012"
"4.68000","0.39019","0.00008"
"4.91400","0.40968","-0.00018"
"5.14800","0.42923","-0.00002"
"5.38200","0.44872","0.00002"
"5.61600","0.46827","0.00013"
"5.85000","0.48770","-0.00006"
"6.08400","0.50719","0.00050"
"6.31800","0.52675","0.00014"
"6.55200","0.54618","-0.00025"
"6.78600","0.56573","0.00011"
"7.02000","0.58522","0.00028"
"7.25400","0.60471","0.00029"
"7.48800","0.62420","0.00002"
"7.72200","0.64369","-0.00015"
"7.95600","0.66319","0.00013"
"8.19000","0.68268","0.00092"
"8.42400","0.70223","0.00048"
"8.65800","0.72166","0.00025"
"8.89200","0.74127","0.00027"
"9.12600","0.76064","0.00051"
"9.36000","0.78019","0.00053"
"9.59400","0.79974","0.00014"
"9.82800","0.81918","0.00032"
"10.06200","0.83873","0.00058"
"10.29600","0.85816","0.00015"
"10.53000","0.87771","-0.00023"
"10.76400","0.89720","0.00024"
"10.99800","0.91675","0.00065"
"11.23200","0.93618","0.00053"
"11.46600","0.95574","0.00040"
"11.70000","0.97523","0.00012"
"11.93400","0.99472","0.00019"
"12.16800","1.01427","0.00025"
"12.40200","1.03364","0.00053"
"12.63600","1.05325","0.00107"
"12.87000","1.07268","0.00091"
"13.10400","1.09224","0.00078"
"13.33800","1.11173","0.00094"
"13.57200","1.13116","0.00086"
"13.80600","1.15077","0.00070"
"14.04000","1.17020","0.00109"
"14.27400","1.18969","0.00015"
"14.50800","1.20918","0.00092"
"14.74200","1.22873","0.00066"
"14.97600","1.24823","0.00079"
"15.21000","1.26766","0.00090"
"15.44400","1.28721","0.00111"
"15.67800","1.30664","0.00100"
"15.91200","1.32619","0.00090"
"16.14600","1.34568","0.00080"
"16.38000","1.36529","0.00141"
"16.61400","1.38473","0.00087"
"16.84800","1.40422","0.00056"
"17.08200","1.42371","0.00107"
"17.31600","1.44314","0.00103"
"17.55000","1.46269","0.00124"
"17.78400","1.48218","0.00148"
"18.01800","1.50173","0.00174"
"18.25200","1.52123","0.00116"
"18.48600","1.54072","0.00187"
"18.72000","1.56015","0.00199"
"18.95400","1.57970","0.00120"
"19.18800","1.59925","0.00154"
"19.42200","1.61868","0.00165"
"19.65600","1.63823","0.00176"
"19.89000","1.65766","0.00120"
"20.12400","1.67728","0.00148"
"20.35800","1.69677","0.00155"
"20.59200","1.71620","0.00188"
"20.82600","1.73575","0.00163"
"21.06000","1.75512","0.00169"
"21.29400","1.77473","0.00221"
"21.52800","1.79422","0.00167"
"21.76200","1.81372","0.00230"
"21.99600","1.83321","0.00232"
"22.23000","1.85270","0.00242"
"22.46400","1.87225","0.00229"
"22.69800","1.89168","0.00246"
"22.93200","1.91123","0.00211"
"23.16600","1.93072","0.00196"
"23.40000","1.95022","0.00235"
"23.63400","1.96971","0.00253"
"23.86800","1.98926","0.00219"
"24.10200","2.00875","0.00241"
"24.33600","2.02818","0.00247"
"24.57000","2.04773","0.00230"
"24.80400","2.06716","0.00265"
"25.03800","2.08671","0.00267"
"25.27200","2.10621","0.00291"
"25.50600","2.12570","0.00285"
"25.74000","2.14519","0.00261"
"25.97400","2.16474","0.00280"
"26.20800","2.18417","0.00258"
"26.44200","2.20360","0.00287"
"26.67600","2.22321","0.00311"
"26.91000","2.24271","0.00310"
"27.14400","2.26226","0.00298"
"27.37800","2.28169","0.00267"
"27.61200","2.30124","0.00328"
"27.84600","2.32079","0.00312"
"28.08000","2.34016","0.00331"
"28.31400","2.35971","0.00346"
"28.54800","2.37920","0.00315"
"28.78200","2.39876","0.00321"
"29.01600","2.41819","0.00315"
"29.25000","2.43768","0.00322"
"29.48400","2.45723","0.00375"
"29.71800","2.47672","0.00344"
"29.95200","2.49627","0.00280"
"30.18600","2.51564","0.00353"
"30.42000","2.53526","0.00373"
"30.65400","2.55469","0.00362"
"30.88800","2.57424","0.00374"
"31.12200","2.59373","0.00361"
"31.35600","2.61322","0.00365"
"31.59000","2.63277","0.00387"
"31.82400","2.65214","0.00406"
"32.05800","2.67170","0.00436"
"32.29200","2.69119","0.00433"
"32.52600","2.71068","0.00377"
"32.76000","2.73023","0.00421"
"32.99400","2.74972","0.00429"
"33.22800","2.76921","0.00411"
"33.46200","2.78876","0.00452"
"33.69600","2.80819","0.00456"
"33.93000","2.82763","0.00457"
"34.16400","2.84724","0.00408"
"34.39800","2.86667","0.00455"
"34.63200","2.88622","0.00485"
"34.86600","2.90571","0.00404"
"35.10000","2.92514","0.00481"
"35.33400","2.94469","0.00377"
"35.56800","2.96419","0.00445"
"35.80200","2.98374","0.00483"
"36.03600","3.00317","0.00514"
"36.27000","3.02272","0.00478"
"36.50400","3.04227","0.00485"
"36.73800","3.06170","0.00494"
"36.97200","3.08119","0.00352"
"37.20600","3.10063","0.00377"
"37.44000","3.12024","0.00367"
"37.67400","3.13967","0.00381"
"37.90800","3.15928","0.00429"
"38.14200","3.17871","0.00428"
"38.37600","3.19820","0.00446"
"38.61000","3.21775","0.00381"
"38.84400","3.23718","0.00371"
"39.07800","3.25674","0.00408"
"39.31200","3.27617","0.00477"
"39.54600","3.29572","0.00398"
"39.78000","3.31521","0.00483"
"40.01400","3.33470","0.00450"
"40.24800","3.35425","0.00451"
"40.48200","3.37368","0.00425"
"40.71600","3.39324","0.00461"
"40.95000","3.41267","0.00497"
"41.18400","3.43228","0.00493"
"41.41800","3.45171","0.00513"
"41.65200","3.47126","0.00519"
"41.88600","3.49075","0.00484"
"42.12000","3.51018","0.00484"
"42.35400","3.52973","0.00489"
"42.58800","3.54917","0.00501"
"42.82200","3.56872","0.00486"
"43.05600","3.58821","0.00524"
"43.29000","3.60770","0.00521"
"43.52400","3.62719","0.00350"
"43.75800","3.64674","0.00398"
"43.99200","3.66623","0.00413"
"44.22600","3.68567","0.00452"
"44.46000","3.70522","0.00465"
"44.69400","3.72465","0.00409"
"44.92800","3.74426","0.00429"
"45.16200","3.76363","0.00449"
"45.39600","3.78324","0.00431"
"45.63000","3.80279","0.00543"
"45.86400","3.82217","0.00491"
"46.09800","3.84178","0.00501"
"46.33200","3.86115","0.00447"
"46.56600","3.88070","0.00498"
"46.80000","3.90013","0.00530"
"47.03400","3.91968","0.00471"
"47.26800","3.93917","0.00529"
"47.50200","3.95872","0.00562"
"47.73600","3.97822","0.00531"
"47.97000","3.99765","0.00534"
"48.20400","4.01720","0.00531"
"48.43800","4.03669","0.00576"
"48.67200","4.05624","0.00550"
"48.90600","4.07573","0.00561"
"49.14000","4.09522","0.00588"
"49.37400","4.11478","0.00585"
"49.60800","4.13421","0.00567"
"49.84200","4.15370","0.00580"
"50.07600","4.17319","0.00568"
"50.31000","4.19268","0.00573"
"50.54400","4.21223","0.00604"
"50.77800","4.23172","0.00598"
"51.01200","4.25116","0.00622"
"51.24600","4.27071","0.00644"
"51.48000","4.29020","0.00639"
"51.71400","4.30969","0.00603"
"51.94800","4.32918","0.00645"
"52.18200","4.34867","0.00652"
"52.41600","4.36822","0.00627"
"52.65000","4.38771","0.00688"
"52.88400","4.40721","0.00744"
"53.11800","4.42670","0.00690"
"53.35200","4.44613","0.00704"
"53.58600","4.46568","0.00769"
"53.82000","4.48523","0.00731"
"54.05400","4.50472","0.00778"
"54.28800","4.52421","0.00720"
"54.52200","4.54371","0.00841"
"54.75600","4.56320","0.00853"
"54.99000","4.58269","0.00826"
"55.22400","4.60230","0.00829"
"55.45800","4.62167","0.00831"
"55.69200","4.64116","0.00816"
"55.92600","4.66065","0.00871"
"56.16000","4.68021","0.00817"
"56.39400","4.69976","0.00881"
"56.62800","4.71919","0.00853"
"56.86200","4.73874","0.00870"
"57.09600","4.75817","0.00897"
"57.33000","4.77772","0.00898"
"57.56400","4.79715","0.00889"
"57.79800","4.81676","0.00922"
"58.03200","4.83620","0.00892"
"58.26600","4.85569","0.00935"
"58.50000","4.87518","0.00922"
"58.73400","4.89467","0.00970"
"58.96800","4.91422","0.00942"
"59.20200","4.93371","0.01009"
"59.43600","4.95326","0.00987"
"59.67000","4.97269","0.01086"
"59.90400","4.99219","0.01019"
"60.13800","5.01174","0.01018"
"60.37200","5.03117","0.01109"
"60.60600","5.05066","0.01051"
"60.84000","5.07015","0.01076"
"61.07400","5.08970","0.01033"
"61.30800","5.10919","0.01172"
"61.54200","5.12875","0.01084"
"61.77600","5.14818","0.01074"
"62.01000","5.16773","0.01158"
"62.24400","5.18722","0.01168"
"62.47800","5.20665","0.01091"
"62.71200","5.22626","0.01182"
"62.94600","5.24564","0.01145"
"63.18000","5.26531","0.01225"
"63.41400","5.28474","0.01180"
"63.64800","5.30423","0.01130"
"63.88200","5.32378","0.01134"
"64.11600","5.34315","0.01219"
"64.35000","5.36276","0.01243"
"64.58400","5.38213","0.01186"
"64.81800","5.40175","0.01236"
"65.05200","5.42124","0.01251"
"65.28600","5.44073","0.01272"
"65.52000","5.46022","0.01305"
"65.75400","5.47971","0.01345"
"65.98800","5.49920","0.01327"
"66.22200","5.51863","0.01315"
"66.45600","5.53824","0.01375"
"66.69000","5.55774","0.01358"
"66.92400","5.57723","0.01455"
"67.15800","5.59672","0.01396"
"67.39200","5.61621","0.01484"
"67.62600","5.63570","0.01467"
"67.86000","5.65519","0.01582"
"68.09400","5.67468","0.01529"
"68.32800","5.69412","0.01520"
"68.56200","5.71373","0.01528"
"68.79600","5.73322","0.01605"
"69.03000","5.75271","0.01595"
"69.26400","5.77226","0.01569"
"69.49800","5.79163","0.01637"
"69.73200","5.81124","0.01676"
"69.96600","5.83068","0.01622"
"70.20000","5.85029","0.01705"
"70.43400","5.86972","0.01666"
"70.66800","5.88921","0.01709"
"70.90200","5.90876","0.01707"
"71.13600","5.92819","0.01700"
"71.37000","5.94774","0.01724"
"71.60400","5.96717","0.01740"
"71.83800","5.98673","0.01805"
"72.07200","6.00622","0.01821"
"72.30600","6.02565","0.01799"
"72.54000","6.04520","0.01824"
"72.77400","6.06469","0.01848"
"73.00800","6.08424","0.01868"
"73.24200","6.10361","0.01870"
"73.47600","6.12329","0.01861"
"73.71000","6.14266","0.01925"
"73.94400","6.16221","0.01951"
"74.17800","6.18176","0.01918"
"74.41200","6.20119","0.01907"
"74.64600","6.22074","0.01943"
"74.88000","6.24017","0.02001"
"75.11400","6.25973","0.01958"
"75.34800","6.27922","0.02047"
"75.58200","6.29871","0.02054"
"75.81600","6.31820","0.02080"
"76.05000","6.33769","0.02130"
"76.28400","6.35724","0.02059"
"76.51800","6.37673","0.02095"
"76.75200","6.39622","0.02135"
"76.98600","6.41566","0.02139"
"77.22000","6.43527","0.02169"
"77.45400","6.45464","0.02137"
"77.68800","6.47419","0.02167"
"77.92200","6.49374","0.02215"
"78.15600","6.51317","0.02200"
"78.39000","6.53272","0.02229"
"78.62400","6.55216","0.02211"
"78.85800","6.57171","0.02258"
"79.09200","6.59120","0.02265"
"79.32600","6.61075","0.02309"
"79.56000","6.63024","0.02349"
"79.79400","6.64973","0.02345"
"80.02800","6.66922","0.02409"
"80.26200","6.68866","0.02396"
"80.49600","6.70821","0.02382"
"80.73000","6.72770","0.02399"
"80.96400","6.74725","0.02470"
"81.19800","6.76668","0.02430"
"81.43200","6.78617","0.02436"
"81.66600","6.80578","0.02495"
"81.90000","6.82521","0.02470"
"82.13400","6.84477","0.02497"
"82.36800","6.86420","0.02551"
"82.60200","6.88369","0.02558"
"82.83600","6.90324","0.02532"
"83.07000","6.92273","0.02605"
"83.30400","6.94222","0.02552"
"83.53800","6.96171","0.02604"
"83.77200","6.98121","0.02635"
"84.00600","7.00064","0.02680"
"84.24000","7.02019","0.02629"
"84.47400","7.03968","0.02714"
"84.70800","7.05923","0.02694"
"84.94200","7.07872","0.02680"
"85.17600","7.09821","0.02724"
"85.41000","7.11770","0.02731"
"85.64400","7.13720","0.02741"
"85.87800","7.15669","0.02826"
"86.11200","7.17618","0.02780"
"86.34600","7.19567","0.02813"
"86.58000","7.21522","0.02814"
"86.81400","7.23477","0.02776"
"87.04800","7.25420","0.02808"
"87.28200","7.27370","0.02780"
"87.51600","7.29325","0.02768"
"87.75000","7.31268","0.02816"
"87.98400","7.33223","0.02845"
"88.21800","7.35166","0.02828"
"88.45200","7.37121","0.02829"
"88.68600","7.39076","0.02883"
"88.92000","7.41014","0.02885"
"89.15400","7.42975","0.02906"
"89.38800","7.44918","0.02889"
"89.62200","7.46867","0.02932"
"89.85600","7.48816","0.02953"
"90.09000","7.50771","0.02971"
"90.32400","7.52720","0.02925"
"90.55800","7.54675","0.02986"
"90.79200","7.56625","0.02958"
"91.02600","7.58568","0.02966"
"91.26000","7.60523","0.02993"
"91.49400","7.62472","0.03007"
"91.72800","7.64421","0.03027"
"91.96200","7.66370","0.03024"
"92.19600","7.68319","0.03018"
"92.43000","7.70275","0.03040"
"92.66400","7.72218","0.03060"
"92.89800","7.74173","0.03053"
"93.13200","7.76122","0.03067"
"93.36600","7.78071","0.03071"
"93.60000","7.80020","0.03103"
"93.83400","7.81975","0.00709"
"94.06800","7.83912","0.00955"
"94.30200","7.85868","0.00762"
"94.53600","7.87823","0.00909"
"94.77000","7.89766","0.00854"
"95.00400","7.91727","0.00902"
"95.23800","7.93664","0.00947"
"95.47200","7.95625","0.00906"
"95.70600","7.97574","0.00999"
"95.94000","7.99524","0.00996"
"96.17400","8.01473","0.01054"
"96.40800","8.03416","0.01020"
"96.64200","8.05371","0.01021"
"96.87600","8.07320","0.01029"
"97.11000","8.09275","0.01138"
"97.34400","8.11218","0.01131"
"97.57800","8.13173","0.01083"
"97.81200","8.15117","0.01198"
"98.04600","8.17072","0.01221"
"98.28000","8.19027","0.01218"
"98.51400","8.20964","0.01184"
"98.74800","8.22919","0.01260"
"98.98200","8.24868","0.01228"
"99.21600","8.26818","0.01270"
"99.45000","8.28773","0.01241"
"99.68400","8.30722","0.01233"
"99.91800","8.32677","0.01223"
"100.15200","8.34620","0.01139"
"100.38600","8.36569","0.01181"
"100.62000","8.38518","0.01186"
"100.85400","8.40473","0.01263"
"101.08800","8.42422","0.01225"
"101.32200","8.44372","0.01223"
"101.55600","8.46321","0.01264"
"101.79000","8.48270","0.01296"
"102.02400","8.50225","0.01332"
"102.25800","8.52168","0.01357"
"102.49200","8.54129","0.01372"
"102.72600","8.56073","0.01369"
"102.96000","8.58016","0.01424"
"103.19400","8.59971","0.01434"
"103.42800","8.61920","0.01441"
"103.66200","8.63875","0.01507"
"103.89600","8.65818","0.01435"
"104.13000","8.67767","0.01483"
"104.36400","8.69722","0.01554"
"104.59800","8.71678","0.01365"
"104.83200","8.73615","0.01460"
"105.06600","8.75570","0.01514"
"105.30000","8.77525","0.01524"
"105.53400","8.79468","0.01582"
"105.76800","8.81429","0.01601"
"106.00200","8.83366","0.01527"
"106.23600","8.85322","0.01505"
"106.47000","8.87277","0.01469"
"106.70400","8.89214","0.01487"
"106.93800","8.91169","0.01538"
"107.17200","8.93112","0.01545"
"107.40600","8.95073","0.01620"
"107.64000","8.97022","0.01604"
"107.87400","8.98971","0.01651"
"108.10800","9.00921","0.01704"
"108.34200","9.02870","0.01720"
"108.57600","9.04825","0.01689"
"108.81000","9.06774","0.01720"
"109.04400","9.08723","0.01713"
"109.27800","9.10666","0.01772"
"109.51200","9.12621","0.01700"
"109.74600","9.14571","0.01747"
"109.98000","9.16526","0.01756"
"110.21400","9.18475","0.01874"
"110.44800","9.20418","0.01834"
"110.68200","9.22373","0.01938"
"110.91600","9.24322","0.02001"
"111.15000","9.26271","0.01990"
"111.38400","9.28215","0.01971"
"111.61800","9.30170","0.02037"
"111.85200","9.32113","0.02053"
"112.08600","9.34068","0.02122"
"112.32000","9.36023","0.02090"
"112.55400","9.37972","0.02169"
"112.78800","9.39921","0.02159"
"113.02200","9.41870","0.02169"
"113.25600","9.43826","0.02203"
"113.49000","9.45769","0.02188"
"113.72400","9.47724","0.02246"
"113.95800","9.49673","0.02310"
"114.19200","9.51616","0.02326"
"114.42600","9.53571","0.02327"
"114.66000","9.55515","0.02413"
"114.89400","9.57476","0.02469"
"115.12800","9.59419","0.02526"
"115.36200","9.61374","0.02551"
"115.59600","9.63317","0.02532"
"115.83000","9.65266","0.02626"
"116.06400","9.67227","0.02609"
"116.29800","9.69170","0.02623"
"116.53200","9.71120","0.02691"
"116.76600","9.73069","0.02663"
"117.00000","9.75024","0.02756"
"117.23400","9.76973","0.02792"
"117.46800","9.78922","0.02806"
"117.70200","9.80877","0.02860"
"117.93600","9.82820","0.02851"
"118.17000","9.84769","0.02879"
"118.40400","9.86719","0.02844"
"118.63800","9.88674","0.02939"
"118.87200","9.90617","0.02881"
"119.10600","9.92578","0.02950"
"119.34000","9.94521","0.02962"
"119.57400","9.96470","0.02984"
"119.80800","9.98425","0.03005"
"120.04200","10.00363","0.02999"
"120.27600","10.02324","0.03050"
"120.51000","10.04273","0.03045"
"120.74400","10.06216","0.03106"
"120.97800","10.08177","0.03084"
"121.21200","10.10120","0.03125"
"121.44600","10.12075","0.03152"
"121.68000","10.14019","0.03181"
"121.91400","10.15968","0.03180"
"122.14800","10.17917","0.03220"
"122.38200","10.19878","0.03225"
"122.61600","10.21821","0.03274"
"122.85000","10.23776","0.03250"
"123.08400","10.25725","0.03324"
"123.31800","10.27662","0.03285"
"123.55200","10.29624","0.03355"
"123.78600","10.31573","0.03328"
"124.02000","10.33522","0.03285"
"124.25400","10.35465","0.03253"
"124.48800","10.37420","0.03273"
"124.72200","10.39375","0.03295"
"124.95600","10.41318","0.03329"
"125.19000","10.43274","0.03380"
"125.42400","10.45217","0.03388"
"125.65800","10.47166","0.03436"
"125.89200","10.49121","0.03433"
"126.12600","10.51076","0.03550"
"126.36000","10.53019","0.03523"
"126.59400","10.54968","0.03646"
"126.82800","10.56923","0.03625"
"127.06200","10.58867","0.03697"
"127.29600","10.60822","0.03713"
"127.53000","10.62771","0.03787"
"127.76400","10.64726","0.03809"
"127.99800","10.66675","0.03841"
"128.23200","10.68618","0.03792"
"128.46600","10.70568","0.03715"
"128.70000","10.72517","0.03186"
"128.93400","10.74472","0.03237"
"129.16800","10.76421","0.03161"
"129.40200","10.78376","0.03152"
"129.63600","10.80319","0.03107"
"129.87000","10.82274","0.03160"
"130.10400","10.84223","0.03137"
"130.33800","10.86167","0.03169"
"130.57200","10.88128","0.03167"
"130.80600","10.90065","0.03188"
"131.04000","10.92026","0.02958"
"131.27400","10.93969","0.02989"
"131.50800","10.95924","0.02991"
"131.74200","10.97873","0.03042"
"131.97600","10.99817","0.03075"
"132.21000","11.01772","0.03057"
"132.44400","11.03715","0.03087"
"132.67800","11.05670","0.03128"
"132.91200","11.07613","0.03112"
"133.14600","11.09574","0.03149"
"133.38000","11.11523","0.03189"
"133.61400","11.13472","0.03160"
"133.84800","11.15422","0.03165"
"134.08200","11.17365","0.03165"
"134.31600","11.19326","0.03186"
"134.55000","11.21269","0.03166"
"134.78400","11.23218","0.03143"
"135.01800","11.25173","0.03003"
"135.25200","11.27122","0.03028"
"135.48600","11.29072","0.03044"
"135.72000","11.31021","0.03067"
"135.95400","11.32970","0.03102"
"136.18800","11.34925","0.03094"
"136.42200","11.36874","0.03151"
"136.65600","11.38817","0.03129"
"136.89000","11.40772","0.03160"
"137.12400","11.42716","0.03165"
"137.35800","11.44665","0.03183"
"137.59200","11.46620","0.03208"
"137.82600","11.48569","0.03195"
"138.06000","11.50524","0.03237"
"138.29400","11.52461","0.03221"
"138.52800","11.54422","0.03138"
"138.76200","11.56371","0.03115"
"138.99600","11.58321","0.03069"
"139.23000","11.60270","0.03092"
"139.46400","11.62219","0.03094"
"139.69800","11.64174","0.03128"
"139.93200","11.66117","0.03147"
"140.16600","11.68072","0.03178"
"140.40000","11.70021","0.03136"
"140.63400","11.71971","0.03165"
"140.86800","11.73920","0.03117"
"141.10200","11.75869","0.03082"
"141.33600","11.77824","0.02981"
"141.57000","11.79767","0.02963"
"141.80400","11.81722","0.02990"
"142.03800","11.83665","0.02876"
"142.27200","11.85620","0.02584"
"142.50600","11.87576","0.02611"
"142.74000","11.89519","0.02735"
"142.97400","11.91474","0.02790"
"143.20800","11.93417","0.02814"
"143.44200","11.95372","0.02932"
"143.67600","11.97315","0.02925"
"143.91000","11.99276","0.02929"
"144.14400","12.01219","0.03020"
"144.37800","12.03169","0.03035"
"144.61200","12.05124","0.03099"
"144.84600","12.07073","0.03049"
"145.08000","12.09022","0.03125"
"145.31400","12.10965","0.03116"
"145.54800","12.12920","0.03142"
"145.78200","12.14869","0.03200"
"146.01600","12.16819","0.03234"
"146.25000","12.18774","0.03293"
"146.48400","12.20717","0.03355"
"146.71800","12.22672","0.03392"
"146.95200","12.24621","0.03451"
"147.18600","12.26570","0.03513"
"147.42000","12.28520","0.03616"
"147.65400","12.30475","0.03675"
"147.88800","12.32418","0.03716"
"148.12200","12.34373","0.03885"
"148.35600","12.36322","0.03969"
"148.59000","12.38271","0.04113"
"148.82400","12.40220","0.04254"
"149.05800","12.42169","0.04335"
"149.29200","12.44125","0.04362"
"149.52600","12.46074","0.04471"
"149.76000","12.48017","0.04431"
"149.99400","12.49966","0.03482"
"150.22800","12.51921","0.03383"
"150.46200","12.53870","0.03405"
"150.69600","12.55813","0.03413"
"150.93000","12.57774","0.03380"
"151.16400","12.59718","0.03430"
"151.39800","12.61673","0.03414"
"151.63200","12.63622","0.03534"
"151.86600","12.65565","0.03651"
"152.10000","12.67520","0.03676"
"152.33400","12.69463","0.03791"
"152.56800","12.71418","0.03209"
"152.80200","12.73368","0.03039"
"153.03600","12.75323","0.03072"
"153.27000","12.77272","0.03140"
"153.50400","12.79221","0.03128"
"153.73800","12.81176","0.03237"
"153.97200","12.83119","0.03227"
"154.20600","12.85068","0.03241"
"154.44000","12.87017","0.03290"
"154.67400","12.88973","0.03299"
"154.90800","12.90916","0.03341"
"155.14200","12.92871","0.03419"
"155.37600","12.94826","0.03482"
"155.61000","12.96769","0.03560"
"155.84400","12.98724","0.03505"
"156.07800","13.00667","0.03546"
"156.31200","13.02629","0.03580"
"156.54600","13.04566","0.03706"
"156.78000","13.06521","0.03664"
"157.01400","13.08476","0.03501"
"157.24800","13.10419","0.03497"
"157.48200","13.12374","0.03633"
"157.71600","13.14311","0.03703"
"157.95000","13.16273","0.03877"
"158.18400","13.18222","0.03907"
"158.41800","13.20177","0.04165"
"158.65200","13.22120","0.04219"
"158.88600","13.24069","0.04464"
"159.12000","13.26024","0.04648"
"159.35400","13.27967","0.04750"
"159.58800","13.29923","0.04993"
"159.82200","13.31872","0.05173"
"160.05600","13.33821","0.05354"
"160.29000","13.35770","0.05505"
"160.52400","13.37725","0.05707"
"160.75800","13.39674","0.05812"
"160.99200","13.41623","0.05943"
"161.22600","13.43573","0.06163"
"161.46000","13.45516","0.06227"
"161.69400","13.47471","0.06426"
"161.92800","13.49420","0.06496"
"162.16200","13.51369","0.06644"
"162.39600","13.53318","0.06773"
"162.63000","13.55267","0.06990"
"162.86400","13.57222","0.07216"
"163.09800","13.59160","0.07350"
"163.33200","13.61127","0.07486"
"163.56600","13.63070","0.07672"
"163.80000","13.65019","0.07834"
"164.03400","13.66974","0.07852"
"164.26800","13.68923","0.08004"
"164.50200","13.70872","0.08058"
"164.73600","13.72822","0.08159"
"164.97000","13.74765","0.08209"
"165.20400","13.76714","0.08263"
"165.43800","13.78675","0.08274"
"165.67200","13.80624","0.08341"
"165.90600","13.82573","0.08339"
"166.14000","13.84528","0.08397"
"166.37400","13.86466","0.08386"
"166.60800","13.88426","0.08412"
"166.84200","13.90364","0.08463"
"167.07600","13.92325","0.08584"
"167.31000","13.94268","0.01465"
"167.54400","13.96217","0.00487"
"167.77800","13.98172","0.00850"
"168.01200","14.00115","0.00143"
"168.24600","14.02071","0.00255"
"168.48000","14.04020","0.01116"
"168.71400","14.05969","0.00266"
"168.94800","14.07924","0.00145"
"169.18200","14.09873","0.00814"
"169.41600","14.11816","0.00290"
"169.65000","14.13765","0.00191"
"169.88400","14.15721","0.00487"
"170.11800","14.17664","0.00690"
"170.35200","14.19625","0.00344"
"170.58600","14.21568","0.00236"
"170.82000","14.23523","0.00962"
"171.05400","14.25472","0.00218"
"171.28800","14.27421","0.00384"
"171.52200","14.29370","0.00791"
"171.75600","14.31320","0.00304"
"171.99000","14.33275","0.00481"
"172.22400","14.35218","0.00696"
"172.45800","14.37173","0.00478"
"172.69200","14.39116","0.00364"
"172.92600","14.41071","0.00772"
"173.16000","14.43020","0.00400"
"173.39400","14.44970","0.00543"
"173.62800","14.46925","0.00740"
"173.86200","14.48868","0.00356"
"174.09600","14.50823","0.00776"
"174.33000","14.52766","0.00572"
"174.56400","14.54727","0.00634"
"174.79800","14.56676","0.00675"
"175.03200","14.58619","0.00739"
"175.26600","14.60569","0.00629"
"175.50000","14.62518","0.00822"
"175.73400","14.64473","0.00783"
"175.96800","14.66416","0.00667"
"176.20200","14.68377","0.00959"
"176.43600","14.70314","0.00660"
"176.67000","14.72276","0.00947"
"176.90400","14.74224","0.00890"
"177.13800","14.76174","0.00830"
"177.37200","14.78123","0.01086"
"177.60600","14.80066","0.00880"
"177.84000","14.82015","0.01075"
"178.07400","14.83970","0.01032"
"178.30800","14.85919","0.01115"
"178.54200","14.87875","0.01038"
"178.77600","14.89818","0.01150"
"179.01000","14.91773","0.01165"
"179.24400","14.93722","0.01201"
"179.47800","14.95671","0.01316"
"179.71200","14.97620","0.01179"
"179.94600","14.99575","0.01430"
"180.18000","15.01518","0.01245"
"180.41400","15.03468","0.01427"
"180.64800","15.05423","0.01411"
"180.88200","15.07366","0.01429"
"181.11600","15.09321","0.01540"
"181.35000","15.11264","0.01449"
"181.58400","15.13219","0.01539"
"181.81800","15.15174","0.01488"
"182.05200","15.17124","0.01654"
"182.28600","15.19067","0.01578"
"182.52000","15.21022","0.01676"
"182.75400","15.22971","0.01691"
"182.98800","15.24920","0.01737"
"183.22200","15.26875","0.01835"
"183.45600","15.28813","0.01801"
"183.69000","15.30773","0.01945"
"183.92400","15.32723","0.01886"
"184.15800","15.34672","0.01974"
"184.39200","15.36627","0.01913"
"184.62600","15.38564","0.02067"
"184.86000","15.40525","0.02066"
"185.09400","15.42468","0.02092"
"185.32800","15.44417","0.02101"
"185.56200","15.46373","0.02156"
"185.79600","15.48316","0.02245"
"186.03000","15.50277","0.02227"
"186.26400","15.52220","0.02353"
"186.49800","15.54175","0.02279"
"186.73200","15.56112","0.02348"
"186.96600","15.58079","0.02321"
"187.20000","15.60023","0.02405"
"187.43400","15.61966","0.02448"
"187.66800","15.63921","0.02476"
"187.90200","15.65864","0.02517"
"188.13600","15.67819","0.02532"
"188.37000","15.69768","0.02580"
"188.60400","15.71723","0.02610"
"188.83800","15.73666","0.02643"
"189.07200","15.75622","0.02636"
"189.30600","15.77565","0.02690"
"189.54000","15.79520","0.02649"
"189.77400","15.81475","0.02687"
"190.00800","15.83418","0.02710"
"190.24200","15.85373","0.02723"
"190.47600","15.87322","0.02768"
"190.71000","15.89278","0.02840"
"190.94400","15.91215","0.02861"
"191.17800","15.93170","0.02836"
"191.41200","15.95125","0.02899"
"191.64600","15.97068","0.02882"
"191.88000","15.99023","0.02937"
"192.11400","16.00966","0.02955"
"192.34800","16.02927","0.03007"
"192.58200","16.04871","0.02987"
"192.81600","16.06820","0.03051"
"193.05000","16.08775","0.03081"
"193.28400","16.10724","0.03049"
"193.51800","16.12673","0.03122"
"193.75200","16.14616","0.03123"
"193.98600","16.16571","0.03170"
"194.22000","16.18521","0.03171"
"194.45400","16.20470","0.03213"
"194.68800","16.22419","0.03172"
"194.92200","16.24368","0.03248"
"195.15600","16.26329","0.03234"
"195.39000","16.28260","0.03313"
"195.62400","16.30221","0.03328"
"195.85800","16.32170","0.03392"
"196.09200","16.34120","0.03384"
"196.32600","16.36069","0.03446"
"196.56000","16.38018","0.03466"
"196.79400","16.39973","0.03532"
"197.02800","16.41922","0.03562"
"197.26200","16.43871","0.03638"
"197.49600","16.45815","0.03585"
"197.73000","16.47776","0.03690"
"197.96400","16.49719","0.03749"
"198.19800","16.51674","0.03739"
"198.43200","16.53623","0.03831"
"198.66600","16.55566","0.03857"
"198.90000","16.57521","0.03950"
"199.13400","16.59464","0.03993"
"199.36800","16.61419","0.04120"
"199.60200","16.63375","0.04169"
"199.83600","16.65324","0.04302"
"200.07000","16.67273","0.04316"
"200.30400","16.69216","0.04399"
"200.53800","16.71171","0.04450"
"200.77200","16.73114","0.04627"
"201.00600","16.75076","0.00298"
"201.24000","16.77019","-0.00149"
"201.47400","16.78968","0.00513"
"201.70800","16.80917","0.00337"
"201.94200","16.82872","0.00516"
"202.17600","16.84827","0.00157"
"202.41000","16.86764","0.00551"
"202.64400","16.88725","0.00239"
"202.87800","16.90669","0.00344"
"203.11200","16.92618","0.00371"
"203.34600","16.94573","0.00143"
"203.58000","16.96522","0.00592"
"203.81400","16.98471","0.00070"
"204.04800","17.00420","0.00589"
"204.28200","17.02369","0.00162"
"204.51600","17.04319","0.00514"
"204.75000","17.06274","0.00412"
"204.98400","17.08217","0.00417"
"205.21800","17.10172","0.00555"
"205.45200","17.12121","0.00267"
"205.68600","17.14070","0.00520"
"205.92000","17.16019","0.00340"
"206.15400","17.17962","0.00456"
"206.38800","17.19918","0.00427"
"206.62200","17.21873","0.00296"
"206.85600","17.23822","0.00498"
"207.09000","17.25771","0.00489"
"207.32400","17.27720","0.00419"
"207.55800","17.29675","0.00504"
"207.79200","17.31618","0.00295"
"208.02600","17.33574","0.00595"
"208.26000","17.35517","0.00307"
"208.49400","17.37478","0.00551"
"208.72800","17.39421","0.00358"
"208.96200","17.41370","0.00590"
"209.19600","17.43319","0.00500"
"209.43000","17.45268","0.00352"
"209.66400","17.47223","0.00597"
"209.89800","17.49167","0.00406"
"210.13200","17.51122","0.00618"
"210.36600","17.53071","0.00383"
"210.60000","17.55020","0.00486"
"210.83400","17.56975","0.00556"
"211.06800","17.58924","0.00514"
"211.30200","17.60874","0.00579"
"211.53600","17.62817","0.00412"
"211.77000","17.64772","0.00614"
"212.00400","17.66721","0.00517"
"212.23800","17.68676","0.00540"
"212.47200","17.70619","0.00539"
"212.70600","17.72568","0.00496"
"212.94000","17.74523","0.00704"
"213.17400","17.76467","0.00448"
"213.40800","17.78422","0.00620"
"213.64200","17.80365","0.00464"
"213.87600","17.82320","0.00583"
"214.11000","17.84275","0.00636"
"214.34400","17.86224","0.00445"
"214.57800","17.88167","0.00688"
"214.81200","17.90122","0.00518"
"215.04600","17.92072","0.00630"
"215.28000","17.94021","0.00528"
"215.51400","17.95976","0.00621"
"215.74800","17.97913","0.00673"
"215.98200","17.99874","0.00539"
"216.21600","18.01823","0.00756"
"216.45000","18.03767","0.00562"
"216.68400","18.05722","0.00826"
"216.91800","18.07665","0.00661"
"217.15200","18.09620","0.00651"
"217.38600","18.11569","0.00720"
"217.62000","18.13524","0.00658"
"217.85400","18.15473","0.00742"
"218.08800","18.17416","0.00631"
"218.32200","18.19372","0.00734"
"218.55600","18.21321","0.00673"
"218.79000","18.23270","0.00694"
"219.02400","18.25213","0.00727"
"219.25800","18.27174","0.00688"
"219.49200","18.29117","0.00840"
"219.72600","18.31072","0.00649"
"219.96000","18.33027","0.00826"
"220.19400","18.34965","0.00756"
"220.42800","18.36926","0.00869"
"220.66200","18.38863","0.00804"
"220.89600","18.40818","0.00761"
"221.13000","18.42767","0.00906"
"221.36400","18.44722","0.00766"
"221.59800","18.46671","0.00829"
"221.83200","18.48621","0.00769"
"222.06600","18.50570","0.00881"
"222.30000","18.52519","0.00796"
"222.53400","18.54474","0.00800"
"222.76800","18.56417","0.00897"
"223.00200","18.58378","0.00845"
"223.23600","18.60316","0.00888"
"223.47000","18.62271","0.00844"
"223.70400","18.64220","0.00940"
"223.93800","18.66163","0.00658"
"224.17200","18.68124","0.00724"
"224.40600","18.70067","0.00763"
"224.64000","18.72022","0.00674"
"224.87400","18.73971","0.00801"
"225.10800","18.75927","0.00781"
"225.34200","18.77870","0.00885"
"225.57600","18.79819","0.00816"
"225.81000","18.81774","0.00822"
"226.04400","18.83717","0.00902"
"226.27800","18.85672","0.00800"
"226.51200","18.87615","0.00879"
"226.74600","18.89576","0.00865"
"226.98000","18.91520","0.00946"
"227.21400","18.93469","0.00855"
"227.44800","18.95424","0.00921"
"227.68200","18.97361","0.00935"
"227.91600","18.99322","0.00890"
"228.15000","19.01265","0.00993"
"228.38400","19.03220","0.00904"
"228.61800","19.05169","0.01018"
"228.85200","19.07119","0.00949"
"229.08600","19.09074","0.00963"
"229.32000","19.11023","0.00957"
"229.55400","19.12972","0.00983"
"229.78800","19.14915","0.01033"
"230.02200","19.16876","0.01003"
"230.25600","19.18826","0.01064"
"230.49000","19.20769","0.00985"
"230.72400","19.22724","0.01076"
"230.95800","19.24667","0.01075"
"231.19200","19.26622","0.01036"
"231.42600","19.28565","0.01106"
"231.66000","19.30520","0.01057"
"231.89400","19.32469","0.01142"
"232.12800","19.34419","0.01113"
"232.36200","19.36368","0.01110"
"232.59600","19.38323","0.01170"
"232.83000","19.40272","0.01108"
"233.06400","19.42221","0.01192"
"233.29800","19.44170","0.01191"
"233.53200","19.46119","0.01292"
"233.76600","19.48075","0.01125"
"234.00000","19.50018","0.01252"
"234.23400","19.51973","0.01211"
"234.46800","19.53922","0.01210"
"234.70200","19.55859","0.01248"
"234.93600","19.57826","0.01243"
"235.17000","19.59769","0.01318"
"235.40400","19.61724","0.01245"
"235.63800","19.63674","0.01288"
"235.87200","19.65623","0.01309"
"236.10600","19.67572","0.01314"
"236.34000","19.69521","0.01188"
"236.57400","19.71476","0.01171"
"236.80800","19.73413","0.01251"
"237.04200","19.75374","0.01126"
"237.27600","19.77317","0.01294"
"237.51000","19.79267","0.01264"
"237.74400","19.81222","0.01295"
"237.97800","19.83171","0.01248"
"238.21200","19.85126","0.01340"
"238.44600","19.87063","0.01384"
"238.68000","19.89018","0.01261"
"238.91400","19.90974","0.01380"
"239.14800","19.92922","0.01346"
"239.38200","19.94872","0.01320"
"239.61600","19.96827","0.01377"
"239.85000","19.98770","0.01365"
"240.08400","20.00719","0.01417"
"240.31800","20.02674","0.01442"
"240.55200","20.04618","0.01462"
"240.78600","20.06578","0.01413"
"241.02000","20.08516","0.01469"
"241.25400","20.10471","0.01133"
"241.48800","20.12420","0.01215"
"241.72200","20.14369","0.01341"
"241.95600","20.16324","0.01236"
"242.19000","20.18267","0.01379"
"242.42400","20.20222","0.01338"
"242.65800","20.22172","0.01283"
"242.89200","20.24121","0.01344"
"243.12600","20.26070","0.01454"
"243.36000","20.28025","0.01445"
"243.59400","20.29968","0.01303"
"243.82800","20.31911","0.01530"
"244.06200","20.33878","0.01523"
"244.29600","20.35822","0.01530"
"244.53000","20.37777","0.01497"
"244.76400","20.39714","0.01575"
"244.99800","20.41669","0.01507"
"245.23200","20.43624","0.01610"
"245.46600","20.45567","0.01705"
"245.70000","20.47522","0.01600"
"245.93400","20.49466","0.01689"
"246.16800","20.51421","0.01702"
"246.40200","20.53376","0.01761"
"246.63600","20.55325","0.01751"
"246.87000","20.57274","0.01835"
"247.10400","20.59217","0.01845"
"247.33800","20.61166","0.01825"
"247.57200","20.63116","0.01944"
"247.80600","20.65077","0.01934"
"248.04000","20.67020","0.01946"
"248.27400","20.68975","0.01938"
"248.50800","20.70924","0.02033"
"248.74200","20.72867","0.02001"
"248.97600","20.74822","0.02024"
"249.21000","20.76765","0.02104"
"249.44400","20.78720","0.02076"
"249.67800","20.80670","0.02140"
"249.91200","20.82619","0.02163"
"250.14600","20.84574","0.02157"
"250.38000","20.86523","0.02215"
"250.61400","20.88472","0.02228"
"250.84800","20.90421","0.02219"
"251.08200","20.92371","0.02300"
"251.31600","20.94314","0.02286"
"251.55000","20.96275","0.02296"
"251.78400","20.98218","0.02367"
"252.01800","21.00173","0.02325"
"252.25200","21.02122","0.02348"
"252.48600","21.04065","0.02364"
"252.72000","21.06020","0.02325"
"252.95400","21.07970","0.02381"
"253.18800","21.09925","0.02371"
"253.42200","21.11868","0.02440"
"253.65600","21.13817","0.02465"
"253.89000","21.15772","0.02524"
"254.12400","21.17721","0.02507"
"254.35800","21.19670","0.02540"
"254.59200","21.21620","0.02549"
"254.82600","21.23569","0.02617"
"255.06000","21.25518","0.02627"
"255.29400","21.27473","0.02641"
"255.52800","21.29416","0.02707"
"255.76200","21.31371","0.02710"
"255.99600","21.33326","0.02778"
"256.23000","21.35264","0.02721"
"256.46400","21.37219","0.02775"
"256.69800","21.39168","0.02837"
"256.93200","21.41123","0.02882"
"257.16600","21.43072","0.02886"
"257.40000","21.45021","0.02911"
"257.63400","21.46971","0.02929"
"257.86800","21.48919","0.02967"
"258.10200","21.50875","0.02945"
"258.33600","21.52818","0.03012"
"258.57000","21.54773","0.03044"
"258.80400","21.56716","0.02983"
"259.03800","21.58677","0.03021"
"259.27200","21.60620","0.03045"
"259.50600","21.62569","0.03104"
"259.74000","21.64524","0.03102"
"259.97400","21.66462","0.03107"
"260.20800","21.68417","0.03156"
"260.44200","21.70366","0.03186"
"260.67600","21.72327","0.03187"
"260.91000","21.74270","0.03218"
"261.14400","21.76219","0.03230"
"261.37800","21.78175","0.03261"
"261.61200","21.80124","0.03270"
"261.84600","21.82073","0.03306"
"262.08000","21.84016","0.03295"
"262.31400","21.85971","0.03350"
"262.54800","21.87920","0.03373"
"262.78200","21.89875","0.03378"
"263.01600","21.91825","0.03393"
"263.25000","21.93768","0.03452"
"263.48400","21.95723","0.03476"
"263.71800","21.97666","0.03504"
"263.95200","21.99621","0.03569"
"264.18600","22.01570","0.03585"
"264.42000","22.03519","0.03598"
"264.65400","22.05474","0.03663"
"264.88800","22.07417","0.03675"
"265.12200","22.09367","0.03765"
"265.35600","22.11316","0.03789"
"265.59000","22.13271","0.03790"
"265.82400","22.15220","0.03847"
"266.05800","22.17175","0.03922"
"266.29200","22.19118","0.03949"
"266.52600","22.21074","0.04048"
"266.76000","22.23022","0.04094"
"266.99400","22.24966","0.04167"
"267.22800","22.26921","0.04243"
"267.46200","22.28864","0.04375"
"267.69600","22.30819","0.04345"
"267.93000","22.32774","0.04434"
"268.16400","22.34724","0.04509"
"268.39800","22.36666","0.04569"
"268.63200","22.38616","0.04678"
"268.86600","22.40571","0.04762"
"269.10000","22.42514","0.04802"
"269.33400","22.44475","0.04884"
"269.56800","22.46418","0.04957"
"269.80200","22.48373","0.05045"
"270.03600","22.50323","0.05157"
"270.27000","22.52272","0.05259"
"270.50400","22.54221","0.05355"
"270.73800","22.56164","0.05419"
"270.97200","22.58119","0.05537"
"271.20600","22.60074","0.05627"
"271.44000","22.62024","0.05691"
"271.67400","22.63972","0.05735"
"271.90800","22.65922","0.05791"
"272.14200","22.67871","0.05824"
"272.37600","22.69820","0.05951"
"272.61000","22.71769","0.06005"
"272.84400","22.73712","0.06060"
"273.07800","22.75679","0.06184"
"273.31200","22.77622","0.06213"
"273.54600","22.79572","0.06287"
"273.78000","22.81521","0.06428"
"274.01400","22.83470","0.06449"
"274.24800","22.85419","0.06594"
"274.48200","22.87368","0.06606"
"274.71600","22.89317","0.06682"
"274.95000","22.91273","0.06770"
"275.18400","22.93222","0.06827"
"275.41800","22.95164","0.06832"
"275.65200","22.97120","0.07016"
"275.88600","22.99069","0.07111"
"276.12000","23.01018","0.07166"
"276.35400","23.02973","0.07287"
"276.58800","23.04916","0.07427"
"276.82200","23.06878","0.07493"
"277.05600","23.08815","0.07594"
"277.29000","23.10770","0.07566"
"277.52400","23.12725","0.07739"
"277.75800","23.14662","0.07850"
"277.99200","23.16623","0.07901"
"278.22600","23.18567","0.07942"
"278.46000","23.20522","0.08019"
"278.69400","23.22471","0.08044"
"278.92800","23.24420","0.08112"
"279.16200","23.26375","0.08129"
"279.39600","23.28318","0.08202"
"279.63000","23.30273","0.08186"
"279.86400","23.32216","0.08229"
"280.09800","23.34171","0.08250"
"280.33200","23.36115","0.08256"
"280.56600","23.38070","0.08290"
"280.80000","23.40025","0.08314"
"281.03400","23.41968","0.08327"
"281.26800","23.43923","0.08346"
"281.50200","23.45866","0.08362"
"281.73600","23.47815","0.08396"
"281.97000","23.49764","0.08414"
"282.20400","23.51720","0.08461"
"282.43800","23.53669","0.08457"
"282.67200","23.55624","0.08508"
"282.90600","23.57573","0.08519"
"283.14000","23.59516","0.08508"
"283.37400","23.61471","0.08606"
"283.60800","23.63415","0.08596"
"283.84200","23.65376","0.08724"
"284.07600","23.67319","0.08754"
"284.31000","23.69268","0.08807"
"284.54400","23.71223","0.08866"
"284.77800","23.73166","0.08887"
"285.01200","23.75121","0.08981"
"285.24600","23.77065","0.09008"
"285.48000","23.79020","0.09134"
"285.71400","23.80963","0.09189"
"285.94800","23.82924","0.09251"
"286.18200","23.84873","0.09285"
"286.41600","23.86828","0.09394"
"286.65000","23.88771","0.09529"
"286.88400","23.90714","0.09565"
"287.11800","23.92676","0.09738"
"287.35200","23.94618","0.09758"
"287.58600","23.96574","0.09887"
"287.82000","23.98517","0.09974"
"288.05400","24.00472","0.10120"
"288.28800","24.02427","0.10197"
"288.52200","24.04364","0.10234"
"288.75600","24.06325","0.10372"
"288.99000","24.08269","0.10419"
"289.22400","24.10224","0.10494"
"289.45800","24.12173","0.10600"
"289.69200","24.14122","0.10720"
"289.92600","24.16071","0.10760"
"290.16000","24.18020","0.10873"
"290.39400","24.19969","0.10904"
"290.62800","24.21918","0.11003"
"290.86200","24.23874","0.11097"
"291.09600","24.25817","0.11103"
"291.33000","24.27772","0.11177"
"291.56400","24.29727","0.11241"
"291.79800","24.31670","0.11318"
"292.03200","24.33625","0.11346"
"292.26600","24.35562","0.11437"
"292.50000","24.37518","0.11496"
"292.73400","24.39467","0.11547"
"292.96800","24.41422","0.11593"
"293.20200","24.43371","0.11637"
"293.43600","24.45320","0.11675"
"293.67000","24.47269","0.11704"
"293.90400","24.49224","0.11788"
"294.13800","24.51167","0.11822"
"294.37200","24.53117","0.11851"
"294.60600","24.55072","0.11881"
"294.84000","24.57021","0.11943"
"295.07400","24.58970","0.11981"
"295.30800","24.60925","0.11979"
"295.54200","24.62862","0.12013"
"295.77600","24.64823","0.12031"
"296.01000","24.66767","0.12089"
"296.24400","24.68722","0.12140"
"296.47800","24.70671","0.12149"
"296.71200","24.72620","0.12208"
"296.94600","24.74569","0.12215"
"297.18000","24.76518","0.12272"
"297.41400","24.78474","0.12299"
"297.64800","24.80416","0.12334"
"297.88200","24.82372","0.12405"
"298.11600","24.84321","0.12451"
"298.35000","24.86270","0.12527"
"298.58400","24.88213","0.12577"
"298.81800","24.90168","0.12589"
"299.05200","24.92123","0.12678"
"299.28600","24.94067","0.12758"
"299.52000","24.96022","0.12773"
"299.75400","24.97971","0.12814"
"299.98800","24.99920","0.12822"
"300.22200","25.01875","0.12905"
"300.45600","25.03824","0.12922"
"300.69000","25.05767","0.12926"
"300.92400","25.07716","0.12999"
"301.15800","25.09672","0.13024"
"301.39200","25.11615","0.13032"
"301.62600","25.13582","0.13109"
"301.86000","25.15513","0.13099"
"302.09400","25.17474","0.13170"
"302.32800","25.19423","0.13188"
"302.56200","25.21372","0.13205"
"302.79600","25.23322","0.13218"
"303.03000","25.25265","0.13275"
"303.26400","25.27220","0.13329"
"303.49800","25.29169","0.13328"
"303.73200","25.31124","0.13318"
"303.96600","25.33073","0.13373"
"304.20000","25.35022","0.13371"
"304.43400","25.36971","0.13422"
"304.66800","25.38921","0.13448"
"304.90200","25.40870","0.13518"
"305.13600","25.42813","0.13564"
"305.37000","25.44774","0.13582"
"305.60400","25.46717","0.13622"
"305.83800","25.48678","-0.01695"
"306.07200","25.50622","-0.00547"
"306.30600","25.52571","0.00252"
"306.54000","25.54526","-0.00670"
"306.77400","25.56469","0.00030"
"307.00800","25.58418","-0.00205"
"307.24200","25.60367","-0.00260"
"307.47600","25.62322","-0.00058"
"307.71000","25.64272","-0.00275"
"307.94400","25.66227","0.00004"
"308.17800","25.68170","-0.00268"
"308.41200","25.70119","-0.00140"
"308.64600","25.72074","-0.00141"
"308.88000","25.74017","-0.00241"
"309.11400","25.75978","-0.00047"
"309.34800","25.77916","-0.00120"
"309.58200","25.79871","-0.00218"
"309.81600","25.81820","-0.00105"
"310.05000","25.83769","-0.00215"
"310.28400","25.85724","-0.00208"
"310.51800","25.87667","-0.00108"
"310.75200","25.89622","-0.00122"
"310.98600","25.91571","-0.00043"
"311.22000","25.93527","-0.00171"
"311.45400","25.95469","-0.00164"
"311.68800","25.97425","-0.00155"
"311.92200","25.99374","-0.00124"
"312.15600","26.01311","-0.00120"
"312.39000","26.03278","-0.00158"
"312.62400","26.05215","-0.00179"
"312.85800","26.07176","-0.00147"
"313.09200","26.09126","-0.00124"
"313.32600","26.11069","-0.00034"
"313.56000","26.13024","-0.00136"
"313.79400","26.14967","-0.00138"
"314.02800","26.16928","-0.00226"
"314.26200","26.18865","-0.00132"
"314.49600","26.20827","-0.00157"
"314.73000","26.22769","-0.00138"
"314.96400","26.24725","-0.00160"
"315.19800","26.26674","-0.00200"
"315.43200","26.28623","-0.00193"
"315.66600","26.30572","-0.00124"
"315.90000","26.32509","-0.00070"
"316.13400","26.34476","-0.00109"
"316.36800","26.36420","-0.00129"
"316.60200","26.38369","-0.00147"
"316.83600","26.40324","-0.00218"
"317.07000","26.42267","-0.00080"
"317.30400","26.44222","-0.00130"
"317.53800","26.46171","-0.00124"
"317.77200","26.48126","-0.00214"
"318.00600","26.50064","-0.00204"
"318.24000","26.52019","-0.00119"
"318.47400","26.53968","-0.00153"
"318.70800","26.55923","-0.00115"
"318.94200","26.57872","-0.00184"
"319.17600","26.59815","-0.00202"
"319.41000","26.61770","-0.00188"
"319.64400","26.63720","-0.00138"
"319.87800","26.65675","-0.00141"
"320.11200","26.67612","-0.00189"
"320.34600","26.69567","-0.00166"
"320.58000","26.71528","-0.00133"
"320.81400","26.73465","-0.00161"
"321.04800","26.75426","-0.00057"
"321.28200","26.77363","-0.00158"
"321.51600","26.79325","-0.00115"
"321.75000","26.81274","-0.00173"
"321.98400","26.83223","-0.00148"
"322.21800","26.85172","-0.00156"
"322.45200","26.87121","-0.00092"
"322.68600","26.89076","-0.00118"
"322.92000","26.91019","-0.00178"
"323.15400","26.92974","-0.00103"
"323.38800","26.94918","-0.00206"
"323.62200","26.96873","-0.00140"
"323.85600","26.98822","-0.00175"
"324.09000","27.00765","-0.00078"
"324.32400","27.02726","-0.00159"
"324.55800","27.04663","-0.00140"
"324.79200","27.06618","-0.00096"
"325.02600","27.08574","-0.00152"
"325.26000","27.10523","-0.00123"
"325.49400","27.12472","-0.00144"
"325.72800","27.14427","-0.00130"
"325.96200","27.16370","-0.00211"
"326.19600","27.18319","-0.00133"
"326.43000","27.20268","-0.00115"
"326.66400","27.22218","-0.00130"
"326.89800","27.24173","-0.00186"
"327.13200","27.26122","-0.00170"
"327.36600","27.28071","-0.00166"
"327.60000","27.30026","-0.00148"
"327.83400","27.31969","-0.00170"
"328.06800","27.33924","-0.00133"
"328.30200","27.35867","-0.00181"
"328.53600","27.37816","-0.00145"
"328.77000","27.39766","-0.00127"
"329.00400","27.41721","-0.00132"
"329.23800","27.43676","-0.00151"
"329.47200","27.45625","-0.00189"
"329.70600","27.47568","-0.00192"
"329.94000","27.49511","-0.00172"
"330.17400","27.51479","-0.00113"
"330.40800","27.53422","-0.00187"
"330.64200","27.55371","-0.00065"
"330.87600","27.57314","-0.00255"
"331.11000","27.59269","-0.00241"
"331.34400","27.61224","-0.00015"
"331.57800","27.63167","-0.00113"
"331.81200","27.65123","-0.00249"
"332.04600","27.67072","-0.00209"
"332.28000","27.69015","-0.00181"
"332.51400","27.70970","-0.00203"
"332.74800","27.72925","-0.00107"
"332.98200","27.74868","-0.00173"
"333.21600","27.76818","-0.00133"
"333.45000","27.78772","-0.00167"
"333.68400","27.80716","-0.00142"
"333.91800","27.82677","-0.00195"
"334.15200","27.84620","-0.00188"
"334.38600","27.86569","-0.00199"
"334.62000","27.88518","-0.00202"
"334.85400","27.90473","-0.00163"
"335.08800","27.92422","-0.00171"
"335.32200","27.94365","-0.00139"
"335.55600","27.96321","-0.00125"
"335.79000","27.98270","-0.00164"
"336.02400","28.00219","-0.00221"
"336.25800","28.02168","-0.00206"
"336.49200","28.04123","-0.00144"
"336.72600","28.06072","-0.00147"
"336.96000","28.08021","-0.00172"
"337.19400","28.09971","-0.00230"
"337.42800","28.11914","-0.00272"
"337.66200","28.13875","-0.00115"
"337.89600","28.15818","-0.00120"
"338.13000","28.17773","-0.00169"
"338.36400","28.19722","-0.00093"
"338.59800","28.21672","-0.00149"
"338.83200","28.23621","-0.00198"
"339.06600","28.25570","-0.00184"
"339.30000","28.27525","-0.00146"
"339.53400","28.29468","-0.00235"
"339.76800","28.31423","-0.00148"
"340.00200","28.33372","-0.00215"
"340.23600","28.35327","-0.00154"
"340.47000","28.37271","-0.00145"
"340.70400","28.39220","-0.00099"
"340.93800","28.41175","-0.00115"
"341.17200","28.43118","-0.00230"
"341.40600","28.45067","-0.00131"
"341.64000","28.47022","-0.00160"
"341.87400","28.48971","-0.00240"
"342.10800","28.50920","-0.00211"
"342.34200","28.52869","-0.00222"
"342.57600","28.54825","-0.00144"
"342.81000","28.56768","-0.00154"
"343.04400","28.58723","-0.00149"
"343.27800","28.60672","-0.00160"
"343.51200","28.62621","-0.00240"
"343.74600","28.64565","-0.00156"
"343.98000","28.66520","-0.00158"
"344.21400","28.68475","-0.00143"
"344.44800","28.70418","-0.00189"
"344.68200","28.72379","-0.00192"
"344.91600","28.74316","-0.00200"
"345.15000","28.76277","-0.00210"
"345.38400","28.78226","-0.00168"
"345.61800","28.80169","-0.00200"
"345.85200","28.82119","-0.00170"
"346.08600","28.84068","-0.00161"
"346.32000","28.86023","-0.00204"
"346.55400","28.87966","-0.00159"
"346.78800","28.89927","-0.00178"
"347.02200","28.91870","-0.00167"
"347.25600","28.93825","-0.00205"
"347.49000","28.95774","-0.00216"
"347.72400","28.97718","-0.00128"
"347.95800","28.99673","-0.00161"
"348.19200","29.01610","-0.00140"
"348.42600","29.03577","-0.00179"
"348.66000","29.05520","-0.00193"
"348.89400","29.07475","-0.00239"
"349.12800","29.09425","-0.00154"
"349.36200","29.11362","-0.00124"
"349.56600","29.13072","-0.00201"