File: Force_trajectories/170122_1/Specimen_RawData_6.csv
End date,"1/22/2017"
Specimen label,"18BG_48"
Maximum Load,"0.13923",N

Time,Extension,Load
(s),(mm),(N)
"0.00000","0.00000","0.00028"
"0.16200","0.00981","-0.00033"
"0.32400","0.02679","0.00036"
"0.48600","0.04084","0.00043"
"0.64800","0.05417","0.00013"
"0.81000","0.06774","-0.00002"
"0.97200","0.08125","0.00064"
"1.13400","0.09465","0.00030"
"1.29600","0.10822","0.00075"
"1.45800","0.12173","0.00058"
"1.62000","0.13524","0.00078"
"1.78200","0.14864","0.00112"
"1.94400","0.16221","0.00057"
"2.10600","0.17572","0.00014"
"2.26800","0.18917","0.00073"
"2.43000","0.20275","0.00114"
"2.59200","0.21620","0.00094"
"2.75400","0.22965","0.00108"
"2.91600","0.24316","0.00060"
"3.07800","0.25674","0.00072"
"3.24000","0.27025","0.00114"
"3.40200","0.28370","0.00099"
"3.56400","0.29727","0.00040"
"3.72600","0.31067","0.00105"
"3.88800","0.32412","0.00115"
"4.05000","0.33769","0.00123"
"4.21200","0.35120","0.00101"
"4.37400","0.36472","0.00081"
"4.53600","0.37823","0.00115"
"4.69800","0.39168","0.00079"
"4.86000","0.40519","0.00135"
"5.02200","0.41865","0.00133"
"5.18400","0.43222","0.00175"
"5.34600","0.44567","0.00097"
"5.50800","0.45912","0.00164"
"5.67000","0.47276","0.00102"
"5.83200","0.48621","0.00150"
"5.99400","0.49966","0.00172"
"6.15600","0.51317","0.00158"
"6.31800","0.52669","0.00157"
"6.48000","0.54014","0.00116"
"6.64200","0.55365","0.00170"
"6.80400","0.56722","0.00117"
"6.96600","0.58074","0.00070"
"7.12800","0.59413","0.00178"
"7.29000","0.60776","0.00113"
"7.45200","0.62121","0.00163"
"7.61400","0.63467","0.00105"
"7.77600","0.64818","0.00166"
"7.93800","0.66175","0.00118"
"8.10000","0.67520","0.00110"
"8.26200","0.68872","0.00136"
"8.42400","0.70223","0.00133"
"8.58600","0.71568","0.00118"
"8.74800","0.72913","0.00107"
"8.91000","0.74271","0.00198"
"9.07200","0.75622","0.00082"
"9.23400","0.76967","0.00087"
"9.39600","0.78318","0.00079"
"9.55800","0.79676","0.00132"
"9.72000","0.81015","0.00135"
"9.88200","0.82366","0.00128"
"10.04400","0.83717","0.00112"
"10.20600","0.85069","0.00105"
"10.36800","0.86414","0.00090"
"10.53000","0.87771","0.00145"
"10.69200","0.89122","0.00134"
"10.85400","0.90468","0.00126"
"11.01600","0.91819","0.00122"
"11.17800","0.93170","0.00079"
"11.34000","0.94515","0.00088"
"11.50200","0.95873","0.00176"
"11.66400","0.97218","0.00129"
"11.82600","0.98575","0.00128"
"11.98800","0.99920","0.00117"
"12.15000","1.01277","0.00099"
"12.31200","1.02623","0.00095"
"12.47400","1.03962","0.00165"
"12.63600","1.05319","0.00164"
"12.79800","1.06671","0.00125"
"12.96000","1.08016","0.00150"
"13.12200","1.09367","0.00198"
"13.28400","1.10718","0.00136"
"13.44600","1.12069","0.00147"
"13.60800","1.13415","0.00109"
"13.77000","1.14772","0.00152"
"13.93200","1.16117","0.00143"
"14.09400","1.17463","0.00120"
"14.25600","1.18826","0.00190"
"14.41800","1.20171","0.00196"
"14.58000","1.21516","0.00126"
"14.74200","1.22867","0.00185"
"14.90400","1.24219","0.00168"
"15.06600","1.25570","0.00144"
"15.22800","1.26915","0.00149"
"15.39000","1.28272","0.00156"
"15.55200","1.29624","0.00162"
"15.71400","1.30969","0.00143"
"15.87600","1.32326","0.00149"
"16.03800","1.33671","0.00171"
"16.20000","1.35017","0.00157"
"16.36200","1.36362","0.00168"
"16.52400","1.37719","0.00143"
"16.68600","1.39070","0.00140"
"16.84800","1.40422","0.00169"
"17.01000","1.41773","0.00139"
"17.17200","1.43124","0.00175"
"17.33400","1.44463","0.00159"
"17.49600","1.45821","0.00159"
"17.65800","1.47172","0.00188"
"17.82000","1.48511","0.00184"
"17.98200","1.49862","0.00097"
"18.14400","1.51226","0.00199"
"18.30600","1.52571","0.00132"
"18.46800","1.53916","0.00182"
"18.63000","1.55273","0.00163"
"18.79200","1.56625","0.00210"
"18.95400","1.57964","0.00200"
"19.11600","1.59321","0.00196"
"19.27800","1.60672","0.00191"
"19.44000","1.62024","0.00222"
"19.60200","1.63375","0.00196"
"19.76400","1.64720","0.00206"
"19.92600","1.66071","0.00157"
"20.08800","1.67417","0.00200"
"20.25000","1.68768","0.00161"
"20.41200","1.70119","0.00236"
"20.57400","1.71470","0.00201"
"20.73600","1.72828","0.00238"
"20.89800","1.74173","0.00250"
"21.06000","1.75518","0.00184"
"21.22200","1.76869","0.00176"
"21.38400","1.78221","0.00256"
"21.54600","1.79566","0.00260"
"21.70800","1.80917","0.00241"
"21.87000","1.82274","0.00230"
"22.03200","1.83626","0.00255"
"22.19400","1.84965","0.00245"
"22.35600","1.86322","0.00189"
"22.51800","1.87673","0.00214"
"22.68000","1.89019","0.00263"
"22.84200","1.90376","0.00169"
"23.00400","1.91721","0.00213"
"23.16600","1.93066","0.00262"
"23.32800","1.94424","0.00181"
"23.49000","1.95775","0.00240"
"23.65200","1.97120","0.00209"
"23.81400","1.98459","0.00287"
"23.97600","1.99823","0.00238"
"24.13800","2.01168","0.00295"
"24.30000","2.02513","0.00236"
"24.46200","2.03870","0.00296"
"24.62400","2.05228","0.00288"
"24.78600","2.06567","0.00226"
"24.94800","2.07918","0.00217"
"25.11000","2.09269","0.00259"
"25.27200","2.10615","0.00298"
"25.43400","2.11966","0.00273"
"25.59600","2.13323","0.00284"
"25.75800","2.14674","0.00218"
"25.92000","2.16020","0.00239"
"26.08200","2.17371","0.00274"
"26.24400","2.18722","0.00269"
"26.40600","2.20073","0.00195"
"26.56800","2.21419","0.00246"
"26.73000","2.22770","0.00253"
"26.89200","2.24121","0.00244"
"27.05400","2.25472","0.00236"
"27.21600","2.26824","0.00271"
"27.37800","2.28175","0.00275"
"27.54000","2.29514","0.00220"
"27.70200","2.30871","0.00286"
"27.86400","2.32223","0.00207"
"28.02600","2.33568","0.00254"
"28.18800","2.34919","0.00290"
"28.35000","2.36276","0.00278"
"28.51200","2.37622","0.00288"
"28.67400","2.38967","0.00305"
"28.83600","2.40318","0.00283"
"28.99800","2.41669","0.00228"
"29.16000","2.43015","0.00266"
"29.32200","2.44372","0.00272"
"29.48400","2.45723","0.00337"
"29.64600","2.47068","0.00230"
"29.80800","2.48420","0.00261"
"29.97000","2.49771","0.00259"
"30.13200","2.51116","0.00250"
"30.29400","2.52467","0.00320"
"30.45600","2.53819","0.00179"
"30.61800","2.55170","0.00222"
"30.78000","2.56515","0.00269"
"30.94200","2.57872","0.00316"
"31.10400","2.59224","0.00241"
"31.26600","2.60569","0.00260"
"31.42800","2.61920","0.00273"
"31.59000","2.63265","0.00264"
"31.75200","2.64616","0.00225"
"31.91400","2.65968","0.00246"
"32.07600","2.67325","0.00272"
"32.23800","2.68676","0.00295"
"32.40000","2.70016","0.00294"
"32.56200","2.71373","0.00247"
"32.72400","2.72724","0.00307"
"32.88600","2.74063","0.00300"
"33.04800","2.75414","0.00338"
"33.21000","2.76772","0.00295"
"33.37200","2.78123","0.00259"
"33.53400","2.79468","0.00276"
"33.69600","2.80819","0.00306"
"33.85800","2.82171","0.00252"
"34.02000","2.83516","0.00279"
"34.18200","2.84867","0.00262"
"34.34400","2.86218","0.00289"
"34.50600","2.87564","0.00263"
"34.66800","2.88921","0.00320"
"34.83000","2.90272","0.00296"
"34.99200","2.91617","0.00260"
"35.15400","2.92969","0.00224"
"35.31600","2.94320","0.00256"
"35.47800","2.95671","0.00302"
"35.64000","2.97016","0.00251"
"35.80200","2.98374","0.00322"
"35.96400","2.99725","0.00290"
"36.12600","3.01064","0.00244"
"36.28800","3.02421","0.00280"
"36.45000","3.03767","0.00345"
"36.61200","3.05118","0.00288"
"36.77400","3.06469","0.00342"
"36.93600","3.07820","0.00281"
"37.09800","3.09172","0.00321"
"37.26000","3.10517","0.00261"
"37.42200","3.11874","0.00267"
"37.58400","3.13219","0.00290"
"37.74600","3.14571","0.00266"
"37.90800","3.15922","0.00311"
"38.07000","3.17273","0.00319"
"38.23200","3.18618","0.00300"
"38.39400","3.19970","0.00283"
"38.55600","3.21321","0.00357"
"38.71800","3.22666","0.00348"
"38.88000","3.24011","0.00336"
"39.04200","3.25369","0.00308"
"39.20400","3.26720","0.00297"
"39.36600","3.28065","0.00300"
"39.52800","3.29422","0.00279"
"39.69000","3.30774","0.00327"
"39.85200","3.32125","0.00343"
"40.01400","3.33470","0.00308"
"40.17600","3.34821","0.00291"
"40.33800","3.36167","0.00340"
"40.50000","3.37512","0.00329"
"40.66200","3.38875","0.00384"
"40.82400","3.40226","0.00333"
"40.98600","3.41572","0.00394"
"41.14800","3.42917","0.00351"
"41.31000","3.44274","0.00304"
"41.47200","3.45613","0.00313"
"41.63400","3.46965","0.00313"
"41.79600","3.48322","0.00317"
"41.95800","3.49673","0.00292"
"42.12000","3.51018","0.00319"
"42.28200","3.52376","0.00341"
"42.44400","3.53727","0.00349"
"42.60600","3.55066","0.00357"
"42.76800","3.56417","0.00305"
"42.93000","3.57775","0.00303"
"43.09200","3.59114","0.00261"
"43.25400","3.60465","0.00342"
"43.41600","3.61822","0.00341"
"43.57800","3.63174","0.00375"
"43.74000","3.64519","0.00402"
"43.90200","3.65870","0.00319"
"44.06400","3.67227","0.00294"
"44.22600","3.68567","0.00372"
"44.38800","3.69918","0.00334"
"44.55000","3.71275","0.00359"
"44.71200","3.72620","0.00285"
"44.87400","3.73972","0.00367"
"45.03600","3.75317","0.00366"
"45.19800","3.76668","0.00320"
"45.36000","3.78013","0.00376"
"45.52200","3.79371","0.00357"
"45.68400","3.80722","0.00374"
"45.84600","3.82067","0.00354"
"46.00800","3.83418","0.00377"
"46.17000","3.84770","0.00376"
"46.33200","3.86115","0.00327"
"46.49400","3.87466","0.00368"
"46.65600","3.88817","0.00334"
"46.81800","3.90169","0.00326"
"46.98000","3.91514","0.00377"
"47.14200","3.92871","0.00417"
"47.30400","3.94222","0.00313"
"47.46600","3.95568","0.00364"
"47.62800","3.96919","0.00359"
"47.79000","3.98270","0.00350"
"47.95200","3.99615","0.00387"
"48.11400","4.00973","0.00397"
"48.27600","4.02324","0.00385"
"48.43800","4.03675","0.00363"
"48.60000","4.05020","0.00344"
"48.76200","4.06372","0.00374"
"48.92400","4.07717","0.00408"
"49.08600","4.09062","0.00381"
"49.24800","4.10419","0.00411"
"49.41000","4.11770","0.00362"
"49.57200","4.13116","0.00402"
"49.73400","4.14467","0.00390"
"49.89600","4.15818","0.00360"
"50.05800","4.17170","0.00369"
"50.22000","4.18515","0.00365"
"50.38200","4.19872","0.00401"
"50.54400","4.21217","0.00371"
"50.70600","4.22563","0.00365"
"50.86800","4.23914","0.00396"
"51.03000","4.25271","0.00367"
"51.19200","4.26616","0.00397"
"51.35400","4.27968","0.00342"
"51.51600","4.29319","0.00346"
"51.67800","4.30670","0.00416"
"51.84000","4.32015","0.00386"
"52.00200","4.33372","0.00430"
"52.16400","4.34724","0.00370"
"52.32600","4.36069","0.00368"
"52.48800","4.37420","0.00353"
"52.65000","4.38771","0.00345"
"52.81200","4.40117","0.00390"
"52.97400","4.41468","0.00357"
"53.13600","4.42819","0.00344"
"53.29800","4.44170","0.00329"
"53.46000","4.45516","0.00361"
"53.62200","4.46873","0.00315"
"53.78400","4.48224","0.00366"
"53.94600","4.49569","0.00383"
"54.10800","4.50921","0.00335"
"54.27000","4.52266","0.00379"
"54.43200","4.53617","0.00364"
"54.59400","4.54974","0.00366"
"54.75600","4.56326","0.00387"
"54.91800","4.57671","0.00391"
"55.08000","4.59022","0.00343"
"55.24200","4.60373","0.00391"
"55.40400","4.61719","0.00368"
"55.56600","4.63058","0.00435"
"55.72800","4.64421","0.00456"
"55.89000","4.65772","0.00395"
"56.05200","4.67118","0.00370"
"56.21400","4.68469","0.00363"
"56.37600","4.69820","0.00350"
"56.53800","4.71165","0.00425"
"56.70000","4.72517","0.00376"
"56.86200","4.73868","0.00348"
"57.02400","4.75219","0.00386"
"57.18600","4.76564","0.00350"
"57.34800","4.77928","0.00374"
"57.51000","4.79273","0.00345"
"57.67200","4.80612","0.00368"
"57.83400","4.81969","0.00423"
"57.99600","4.83321","0.00367"
"58.15800","4.84666","0.00412"
"58.32000","4.86017","0.00411"
"58.48200","4.87374","0.00381"
"58.64400","4.88720","0.00415"
"58.80600","4.90065","0.00445"
"58.96800","4.91428","0.00435"
"59.13000","4.92773","0.00351"
"59.29200","4.94119","0.00435"
"59.45400","4.95464","0.00439"
"59.61600","4.96827","0.00423"
"59.77800","4.98166","0.00415"
"59.94000","4.99518","0.00410"
"60.10200","5.00869","0.00400"
"60.26400","5.02220","0.00417"
"60.42600","5.03559","0.00420"
"60.58800","5.04923","0.00429"
"60.75000","5.06274","0.00388"
"60.91200","5.07619","0.00390"
"61.07400","5.08970","0.00403"
"61.23600","5.10322","0.00451"
"61.39800","5.11673","0.00390"
"61.56000","5.13018","0.00406"
"61.72200","5.14363","0.00427"
"61.88400","5.15721","0.00414"
"62.04600","5.17066","0.00429"
"62.20800","5.18423","0.00405"
"62.37000","5.19768","0.00417"
"62.53200","5.21114","0.00374"
"62.69400","5.22471","0.00377"
"62.85600","5.23822","0.00453"
"63.01800","5.25167","0.00387"
"63.18000","5.26519","0.00410"
"63.34200","5.27876","0.00390"
"63.50400","5.29227","0.00450"
"63.66600","5.30572","0.00439"
"63.82800","5.31924","0.00432"
"63.99000","5.33269","0.00441"
"64.15200","5.34614","0.00386"
"64.31400","5.35971","0.00414"
"64.47600","5.37323","0.00435"
"64.63800","5.38668","0.00400"
"64.80000","5.40019","0.00451"
"64.96200","5.41376","0.00438"
"65.12400","5.42722","0.00421"
"65.28600","5.44067","0.00438"
"65.44800","5.45418","0.00420"
"65.61000","5.46769","0.00373"
"65.77200","5.48115","0.00354"
"65.93400","5.49472","0.00340"
"66.09600","5.50823","0.00354"
"66.25800","5.52162","0.00373"
"66.42000","5.53520","0.00319"
"66.58200","5.54871","0.00327"
"66.74400","5.56222","0.00362"
"66.90600","5.57567","0.00355"
"67.06800","5.58924","0.00371"
"67.23000","5.60276","0.00360"
"67.39200","5.61615","0.00352"
"67.55400","5.62972","0.00370"
"67.71600","5.64324","0.00362"
"67.87800","5.65669","0.00418"
"68.04000","5.67020","0.00340"
"68.20200","5.68365","0.00368"
"68.36400","5.69717","0.00371"
"68.52600","5.71074","0.00351"
"68.68800","5.72425","0.00396"
"68.85000","5.73770","0.00410"
"69.01200","5.75115","0.00364"
"69.17400","5.76473","0.00358"
"69.33600","5.77818","0.00357"
"69.49800","5.79169","0.00423"
"69.66000","5.80526","0.00410"
"69.82200","5.81872","0.00367"
"69.98400","5.83223","0.00380"
"70.14600","5.84568","0.00384"
"70.30800","5.85920","0.00424"
"70.47000","5.87277","0.00358"
"70.63200","5.88610","0.00364"
"70.79400","5.89973","0.00386"
"70.95600","5.91324","0.00360"
"71.11800","5.92670","0.00394"
"71.28000","5.94021","0.00366"
"71.44200","5.95366","0.00400"
"71.60400","5.96723","0.00381"
"71.76600","5.98069","0.00384"
"71.92800","5.99420","0.00348"
"72.09000","6.00771","0.00386"
"72.25200","6.02122","0.00431"
"72.41400","6.03480","0.00408"
"72.57600","6.04819","0.00398"
"72.73800","6.06170","0.00377"
"72.90000","6.07515","0.00369"
"73.06200","6.08867","0.00400"
"73.22400","6.10212","0.00374"
"73.38600","6.11569","0.00410"
"73.54800","6.12926","0.00410"
"73.71000","6.14266","0.00380"
"73.87200","6.15617","0.00438"
"74.03400","6.16974","0.00430"
"74.19600","6.18325","0.00423"
"74.35800","6.19665","0.00383"
"74.52000","6.21022","0.00356"
"74.68200","6.22373","0.00418"
"74.84400","6.23718","0.00445"
"75.00600","6.25070","0.00426"
"75.16800","6.26421","0.00427"
"75.33000","6.27772","0.00439"
"75.49200","6.29111","0.00436"
"75.65400","6.30475","0.00379"
"75.81600","6.31820","0.00414"
"75.97800","6.33165","0.00455"
"76.14000","6.34522","0.00426"
"76.30200","6.35874","0.00425"
"76.46400","6.37219","0.00448"
"76.62600","6.38570","0.00445"
"76.78800","6.39921","0.00436"
"76.95000","6.41267","0.00428"
"77.11200","6.42618","0.00381"
"77.27400","6.43969","0.00401"
"77.43600","6.45320","0.00453"
"77.59800","6.46666","0.00416"
"77.76000","6.48017","0.00439"
"77.92200","6.49374","0.00403"
"78.08400","6.50719","0.00437"
"78.24600","6.52071","0.00424"
"78.40800","6.53422","0.00372"
"78.57000","6.54773","0.00488"
"78.73200","6.56124","0.00368"
"78.89400","6.57470","0.00412"
"79.05600","6.58821","0.00420"
"79.21800","6.60166","0.00450"
"79.38000","6.61523","0.00421"
"79.54200","6.62869","0.00462"
"79.70400","6.64220","0.00435"
"79.86600","6.65571","0.00468"
"80.02800","6.66922","0.00431"
"80.19000","6.68268","0.00445"
"80.35200","6.69613","0.00423"
"80.51400","6.70970","0.00428"
"80.67600","6.72321","0.00404"
"80.83800","6.73667","0.00386"
"81.00000","6.75024","0.00477"
"81.16200","6.76369","0.00481"
"81.32400","6.77720","0.00475"
"81.48600","6.79066","0.00462"
"81.64800","6.80417","0.00462"
"81.81000","6.81768","0.00472"
"81.97200","6.83119","0.00449"
"82.13400","6.84471","0.00452"
"82.29600","6.85828","0.00427"
"82.45800","6.87167","0.00467"
"82.62000","6.88524","0.00419"
"82.78200","6.89870","0.00468"
"82.94400","6.91215","0.00461"
"83.10600","6.92566","0.00470"
"83.26800","6.93917","0.00422"
"83.43000","6.95269","0.00416"
"83.59200","6.96620","0.00471"
"83.75400","6.97971","0.00470"
"83.91600","6.99322","0.00457"
"84.07800","7.00662","0.00445"
"84.24000","7.02019","0.00512"
"84.40200","7.03370","0.00438"
"84.56400","7.04715","0.00439"
"84.72600","7.06073","0.00484"
"84.88800","7.07424","0.00488"
"85.05000","7.08775","0.00487"
"85.21200","7.10120","0.00469"
"85.37400","7.11466","0.00469"
"85.53600","7.12817","0.00506"
"85.69800","7.14162","0.00454"
"85.86000","7.15519","0.00387"
"86.02200","7.16876","0.00470"
"86.18400","7.18222","0.00437"
"86.34600","7.19573","0.00464"
"86.50800","7.20924","0.00431"
"86.67000","7.22270","0.00439"
"86.83200","7.23621","0.00450"
"86.99400","7.24972","0.00478"
"87.15600","7.26323","0.00438"
"87.31800","7.27668","0.00454"
"87.48000","7.29020","0.00409"
"87.64200","7.30371","0.00520"
"87.80400","7.31716","0.00488"
"87.96600","7.33068","0.00461"
"88.12800","7.34419","0.00480"
"88.29000","7.35770","0.00468"
"88.45200","7.37121","0.00477"
"88.61400","7.38473","0.00503"
"88.77600","7.39824","0.00479"
"88.93800","7.41169","0.00495"
"89.10000","7.42520","0.00521"
"89.26200","7.43871","0.00475"
"89.42400","7.45217","0.00523"
"89.58600","7.46568","0.00475"
"89.74800","7.47919","0.00523"
"89.91000","7.49270","0.00491"
"90.07200","7.50622","0.00485"
"90.23400","7.51967","0.00462"
"90.39600","7.53318","0.00508"
"90.55800","7.54663","0.00462"
"90.72000","7.56021","0.00530"
"90.88200","7.57372","0.00531"
"91.04400","7.58717","0.00498"
"91.20600","7.60074","0.00506"
"91.36800","7.61426","0.00472"
"91.53000","7.62771","0.00489"
"91.69200","7.64116","0.00496"
"91.85400","7.65468","0.00484"
"92.01600","7.66813","0.00463"
"92.17800","7.68164","0.00548"
"92.34000","7.69527","0.00491"
"92.50200","7.70878","0.00487"
"92.66400","7.72212","0.00512"
"92.82600","7.73575","0.00527"
"92.98800","7.74920","0.00455"
"93.15000","7.76266","0.00518"
"93.31200","7.77623","0.00505"
"93.47400","7.78974","0.00534"
"93.63600","7.80325","0.00531"
"93.79800","7.81670","0.00498"
"93.96000","7.83022","0.00476"
"94.12200","7.84373","0.00529"
"94.28400","7.85718","0.00560"
"94.44600","7.87069","0.00502"
"94.60800","7.88427","0.00485"
"94.77000","7.89772","0.00528"
"94.93200","7.91117","0.00506"
"95.09400","7.92468","0.00510"
"95.25600","7.93820","0.00491"
"95.41800","7.95165","0.00537"
"95.58000","7.96522","0.00498"
"95.74200","7.97867","0.00506"
"95.90400","7.99213","0.00539"
"96.06600","8.00576","0.00514"
"96.22800","8.01921","0.00520"
"96.39000","8.03266","0.00551"
"96.55200","8.04618","0.00505"
"96.71400","8.05969","0.00499"
"96.87600","8.07314","0.00526"
"97.03800","8.08659","0.00527"
"97.20000","8.10023","0.00557"
"97.36200","8.11374","0.00512"
"97.52400","8.12719","0.00483"
"97.68600","8.14070","0.00460"
"97.84800","8.15428","0.00541"
"98.01000","8.16767","0.00581"
"98.17200","8.18118","0.00539"
"98.33400","8.19469","0.00572"
"98.49600","8.20815","0.00542"
"98.65800","8.22166","0.00553"
"98.82000","8.23523","0.00460"
"98.98200","8.24868","0.00530"
"99.14400","8.26220","0.00510"
"99.30600","8.27565","0.00535"
"99.46800","8.28916","0.00518"
"99.63000","8.30267","0.00503"
"99.79200","8.31625","0.00533"
"99.95400","8.32976","0.00496"
"100.11600","8.34315","0.00517"
"100.27800","8.35666","0.00492"
"100.44000","8.37018","0.00511"
"100.60200","8.38369","0.00494"
"100.76400","8.39714","0.00504"
"100.92600","8.41071","0.00488"
"101.08800","8.42422","0.00488"
"101.25000","8.43768","0.00484"
"101.41200","8.45125","0.00492"
"101.57400","8.46470","0.00501"
"101.73600","8.47816","0.00522"
"101.89800","8.49167","0.00471"
"102.06000","8.50524","0.00498"
"102.22200","8.51869","0.00515"
"102.38400","8.53215","0.00532"
"102.54600","8.54572","0.00492"
"102.70800","8.55917","0.00464"
"102.87000","8.57262","0.00519"
"103.03200","8.58619","0.00509"
"103.19400","8.59971","0.00490"
"103.35600","8.61316","0.00540"
"103.51800","8.62673","0.00518"
"103.68000","8.64025","0.00505"
"103.84200","8.65376","0.00511"
"104.00400","8.66715","0.00538"
"104.16600","8.68072","0.00504"
"104.32800","8.69418","0.00477"
"104.49000","8.70763","0.00480"
"104.65200","8.72120","0.00504"
"104.81400","8.73471","0.00468"
"104.97600","8.74817","0.00479"
"105.13800","8.76168","0.00478"
"105.30000","8.77525","0.00497"
"105.46200","8.78870","0.00476"
"105.62400","8.80210","0.00492"
"105.78600","8.81573","0.00479"
"105.94800","8.82924","0.00500"
"106.11000","8.84269","0.00527"
"106.27200","8.85620","0.00497"
"106.43400","8.86972","0.00478"
"106.59600","8.88317","0.00483"
"106.75800","8.89668","0.00560"
"106.92000","8.91020","0.00455"
"107.08200","8.92365","0.00532"
"107.24400","8.93716","0.00501"
"107.40600","8.95079","0.00479"
"107.56800","8.96418","0.00493"
"107.73000","8.97764","0.00454"
"107.89200","8.99121","0.00473"
"108.05400","9.00478","0.00494"
"108.21600","9.01817","0.00502"
"108.37800","9.03169","0.00519"
"108.54000","9.04526","0.00522"
"108.70200","9.05877","0.00477"
"108.86400","9.07222","0.00445"
"109.02600","9.08574","0.00477"
"109.18800","9.09919","0.00529"
"109.35000","9.11258","0.00482"
"109.51200","9.12621","0.00535"
"109.67400","9.13973","0.00533"
"109.83600","9.15318","0.00479"
"109.99800","9.16669","0.00486"
"110.16000","9.18021","0.00514"
"110.32200","9.19372","0.00495"
"110.48400","9.20717","0.00517"
"110.64600","9.22074","0.00516"
"110.80800","9.23419","0.00498"
"110.97000","9.24765","0.00510"
"111.13200","9.26122","0.00500"
"111.29400","9.27473","0.00549"
"111.45600","9.28813","0.00492"
"111.61800","9.30170","0.00533"
"111.78000","9.31521","0.00447"
"111.94200","9.32872","0.00508"
"112.10400","9.34211","0.00487"
"112.26600","9.35575","0.00548"
"112.42800","9.36926","0.00518"
"112.59000","9.38271","0.00515"
"112.75200","9.39622","0.00556"
"112.91400","9.40974","0.00538"
"113.07600","9.42319","0.00509"
"113.23800","9.43670","0.00563"
"113.40000","9.45015","0.00500"
"113.56200","9.46373","0.00535"
"113.72400","9.47718","0.00548"
"113.88600","9.49075","0.00581"
"114.04800","9.50426","0.00525"
"114.21000","9.51772","0.00576"
"114.37200","9.53123","0.00539"
"114.53400","9.54468","0.00536"
"114.69600","9.55819","0.00570"
"114.85800","9.57171","0.00567"
"115.02000","9.58522","0.00546"
"115.18200","9.59873","0.00530"
"115.34400","9.61218","0.00599"
"115.50600","9.62570","0.00605"
"115.66800","9.63921","0.00594"
"115.83000","9.65266","0.00565"
"115.99200","9.66623","0.00569"
"116.15400","9.67975","0.00578"
"116.31600","9.69320","0.00620"
"116.47800","9.70671","0.00596"
"116.64000","9.72022","0.00631"
"116.80200","9.73362","0.00613"
"116.96400","9.74719","0.00629"
"117.12600","9.76070","0.00640"
"117.28800","9.77421","0.00635"
"117.45000","9.78767","0.00643"
"117.61200","9.80130","0.00597"
"117.77400","9.81469","0.00612"
"117.93600","9.82814","0.00597"
"118.09800","9.84171","0.00635"
"118.26000","9.85523","0.00613"
"118.42200","9.86868","0.00639"
"118.58400","9.88219","0.00664"
"118.74600","9.89577","0.00701"
"118.90800","9.90922","0.00667"
"119.07000","9.92267","0.00679"
"119.23200","9.93624","0.00611"
"119.39400","9.94976","0.00664"
"119.55600","9.96321","0.00691"
"119.71800","9.97666","0.00694"
"119.88000","9.99023","0.00732"
"120.04200","10.00369","0.00684"
"120.20400","10.01720","0.00726"
"120.36600","10.03071","0.00724"
"120.52800","10.04422","0.00806"
"120.69000","10.05762","0.00746"
"120.85200","10.07119","0.00725"
"121.01400","10.08470","0.00815"
"121.17600","10.09821","0.00756"
"121.33800","10.11172","0.00786"
"121.50000","10.12524","0.00758"
"121.66200","10.13869","0.00749"
"121.82400","10.15220","0.00738"
"121.98600","10.16566","0.00737"
"122.14800","10.17917","0.00723"
"122.31000","10.19262","0.00723"
"122.47200","10.20631","0.00781"
"122.63400","10.21971","0.00728"
"122.79600","10.23316","0.00794"
"122.95800","10.24673","0.00772"
"123.12000","10.26024","0.00755"
"123.28200","10.27376","0.00703"
"123.44400","10.28721","0.00783"
"123.60600","10.30072","0.00755"
"123.76800","10.31417","0.00709"
"123.93000","10.32769","0.00672"
"124.09200","10.34126","0.00707"
"124.25400","10.35465","0.00685"
"124.41600","10.36816","0.00725"
"124.57800","10.38168","0.00742"
"124.74000","10.39519","0.00732"
"124.90200","10.40870","0.00722"
"125.06400","10.42221","0.00760"
"125.22600","10.43572","0.00744"
"125.38800","10.44918","0.00772"
"125.55000","10.46269","0.00780"
"125.71200","10.47620","0.00806"
"125.87400","10.48972","0.00793"
"126.03600","10.50317","0.00805"
"126.19800","10.51674","0.00812"
"126.36000","10.53025","0.00817"
"126.52200","10.54370","0.00828"
"126.68400","10.55722","0.00831"
"126.84600","10.57073","0.00816"
"127.00800","10.58418","0.00810"
"127.17000","10.59764","0.00813"
"127.33200","10.61121","0.00783"
"127.49400","10.62472","0.00766"
"127.65600","10.63817","0.00793"
"127.81800","10.65174","0.00747"
"127.98000","10.66520","0.00800"
"128.14200","10.67865","0.00772"
"128.30400","10.69216","0.00813"
"128.46600","10.70573","0.00801"
"128.62800","10.71919","0.00837"
"128.79000","10.73270","0.00816"
"128.95200","10.74621","0.00800"
"129.11400","10.75972","0.00816"
"129.27600","10.77312","0.00820"
"129.43800","10.78669","0.00843"
"129.60000","10.80020","0.00852"
"129.76200","10.81365","0.00812"
"129.92400","10.82723","0.00839"
"130.08600","10.84080","0.00862"
"130.24800","10.85419","0.00834"
"130.41000","10.86765","0.00883"
"130.57200","10.88116","0.00880"
"130.73400","10.89467","0.00875"
"130.89600","10.90812","0.00945"
"131.05800","10.92169","0.00921"
"131.22000","10.93521","0.00966"
"131.38200","10.94866","0.00895"
"131.54400","10.96217","0.00940"
"131.70600","10.97568","0.00941"
"131.86800","10.98920","0.01010"
"132.03000","11.00265","0.00977"
"132.19200","11.01622","0.00870"
"132.35400","11.02973","0.00839"
"132.51600","11.04319","0.00951"
"132.67800","11.05676","0.00894"
"132.84000","11.07021","0.00903"
"133.00200","11.08366","0.00888"
"133.16400","11.09718","0.00931"
"133.32600","11.11069","0.00922"
"133.48800","11.12420","0.00871"
"133.65000","11.13771","0.00895"
"133.81200","11.15123","0.00961"
"133.97400","11.16474","0.00956"
"134.13600","11.17813","0.00912"
"134.29800","11.19176","0.00955"
"134.46000","11.20522","0.00975"
"134.62200","11.21867","0.00968"
"134.78400","11.23218","0.00948"
"134.94600","11.24569","0.01006"
"135.10800","11.25915","0.00984"
"135.27000","11.27272","0.00982"
"135.43200","11.28623","0.01029"
"135.59400","11.29968","0.00966"
"135.75600","11.31314","0.01057"
"135.91800","11.32671","0.01022"
"136.08000","11.34022","0.00963"
"136.24200","11.35367","0.00978"
"136.40400","11.36718","0.00988"
"136.56600","11.38070","0.01023"
"136.72800","11.39421","0.01047"
"136.89000","11.40766","0.01101"
"137.05200","11.42118","0.01069"
"137.21400","11.43469","0.01087"
"137.37600","11.44820","0.01078"
"137.53800","11.46177","0.01174"
"137.70000","11.47529","0.01137"
"137.86200","11.48868","0.01064"
"138.02400","11.50213","0.01141"
"138.18600","11.51570","0.01162"
"138.34800","11.52922","0.01167"
"138.51000","11.54267","0.01232"
"138.67200","11.55618","0.01208"
"138.83400","11.56969","0.01244"
"138.99600","11.58315","0.01225"
"139.15800","11.59672","0.01226"
"139.32000","11.61023","0.01275"
"139.48200","11.62362","0.01219"
"139.64400","11.63720","0.01322"
"139.80600","11.65071","0.01338"
"139.96800","11.66422","0.01314"
"140.13000","11.67773","0.01345"
"140.29200","11.69125","0.01369"
"140.45400","11.70476","0.01350"
"140.61600","11.71821","0.01330"
"140.77800","11.73172","0.01310"
"140.94000","11.74518","0.01324"
"141.10200","11.75863","0.01378"
"141.26400","11.77226","0.01409"
"141.42600","11.78571","0.01419"
"141.58800","11.79917","0.01252"
"141.75000","11.81268","0.01291"
"141.91200","11.82619","0.01371"
"142.07400","11.83964","0.01406"
"142.23600","11.85316","0.01409"
"142.39800","11.86667","0.01429"
"142.56000","11.88024","0.01459"
"142.72200","11.89369","0.01465"
"142.88400","11.90721","0.01460"
"143.04600","11.92072","0.01533"
"143.20800","11.93411","0.01535"
"143.37000","11.94774","0.01476"
"143.53200","11.96119","0.01523"
"143.69400","11.97471","0.01505"
"143.85600","11.98816","0.01447"
"144.01800","12.00173","0.01445"
"144.18000","12.01518","0.01525"
"144.34200","12.02864","0.01481"
"144.50400","12.04221","0.01526"
"144.66600","12.05572","0.01573"
"144.82800","12.06917","0.01541"
"144.99000","12.08275","0.01536"
"145.15200","12.09626","0.01566"
"145.31400","12.10971","0.01605"
"145.47600","12.12317","0.01653"
"145.63800","12.13668","0.01647"
"145.80000","12.15019","0.01690"
"145.96200","12.16364","0.01696"
"146.12400","12.17721","0.01712"
"146.28600","12.19073","0.01716"
"146.44800","12.20412","0.01784"
"146.61000","12.21769","0.01734"
"146.77200","12.23120","0.01805"
"146.93400","12.24472","0.01790"
"147.09600","12.25817","0.01814"
"147.25800","12.27168","0.01891"
"147.42000","12.28520","0.01883"
"147.58200","12.29865","0.01852"
"147.74400","12.31222","0.01882"
"147.90600","12.32573","0.01869"
"148.06800","12.33918","0.01916"
"148.23000","12.35270","0.01873"
"148.39200","12.36621","0.01942"
"148.55400","12.37966","0.02017"
"148.71600","12.39318","0.02026"
"148.87800","12.40675","0.02037"
"149.04000","12.42020","0.01996"
"149.20200","12.43365","0.02081"
"149.36400","12.44722","0.02058"
"149.52600","12.46068","0.02049"
"149.68800","12.47419","0.02032"
"149.85000","12.48770","0.02082"
"150.01200","12.50121","0.02070"
"150.17400","12.51467","0.01381"
"150.33600","12.52818","0.01426"
"150.49800","12.54169","0.01308"
"150.66000","12.55514","0.01383"
"150.82200","12.56866","0.01380"
"150.98400","12.58223","0.01446"
"151.14600","12.59574","0.01392"
"151.30800","12.60913","0.01477"
"151.47000","12.62271","0.01493"
"151.63200","12.63622","0.01453"
"151.79400","12.64967","0.01465"
"151.95600","12.66318","0.01547"
"152.11800","12.67670","0.01501"
"152.28000","12.69021","0.01561"
"152.44200","12.70366","0.01524"
"152.60400","12.71723","0.01651"
"152.76600","12.73075","0.01539"
"152.92800","12.74414","0.01577"
"153.09000","12.75771","0.01521"
"153.25200","12.77122","0.01490"
"153.41400","12.78468","0.01580"
"153.57600","12.79813","0.01589"
"153.73800","12.81176","0.01526"
"153.90000","12.82521","0.01530"
"154.06200","12.83873","0.01549"
"154.22400","12.85224","0.01530"
"154.38600","12.86569","0.01538"
"154.54800","12.87914","0.01642"
"154.71000","12.89266","0.01653"
"154.87200","12.90623","0.01584"
"155.03400","12.91968","0.01751"
"155.19600","12.93319","0.01649"
"155.35800","12.94671","0.01709"
"155.52000","12.96022","0.01632"
"155.68200","12.97367","0.01751"
"155.84400","12.98724","0.01693"
"156.00600","13.00070","0.01840"
"156.16800","13.01415","0.01831"
"156.33000","13.02772","0.01813"
"156.49200","13.04123","0.01846"
"156.65400","13.05469","0.01947"
"156.81600","13.06820","0.01898"
"156.97800","13.08171","0.01910"
"157.14000","13.09522","0.01936"
"157.30200","13.10868","0.01885"
"157.46400","13.12225","0.01958"
"157.62600","13.13570","0.01956"
"157.78800","13.14921","0.02005"
"157.95000","13.16273","0.02008"
"158.11200","13.17624","0.02064"
"158.27400","13.18969","0.02128"
"158.43600","13.20314","0.02106"
"158.59800","13.21666","0.02122"
"158.76000","13.23017","0.02179"
"158.92200","13.24368","0.02164"
"159.08400","13.25725","0.02151"
"159.24600","13.27071","0.02141"
"159.40800","13.28416","0.02184"
"159.57000","13.29773","0.02210"
"159.73200","13.31124","0.02252"
"159.89400","13.32464","0.02209"
"160.05600","13.33821","0.02249"
"160.21800","13.35172","0.02321"
"160.38000","13.36523","0.02221"
"160.54200","13.37869","0.02307"
"160.70400","13.39220","0.02342"
"160.86600","13.40565","0.02369"
"161.02800","13.41910","0.02402"
"161.19000","13.43274","0.02427"
"161.35200","13.44625","0.02469"
"161.51400","13.45970","0.02442"
"161.67600","13.47321","0.02509"
"161.83800","13.48672","0.02575"
"162.00000","13.50018","0.02569"
"162.16200","13.51363","0.02600"
"162.32400","13.52720","0.02627"
"162.48600","13.54072","0.02638"
"162.64800","13.55423","0.02628"
"162.81000","13.56774","0.02674"
"162.97200","13.58119","0.02684"
"163.13400","13.59471","0.02726"
"163.29600","13.60822","0.02754"
"163.45800","13.62173","0.02743"
"163.62000","13.63518","0.02785"
"163.78200","13.64869","0.02806"
"163.94400","13.66221","0.02838"
"164.10600","13.67572","0.02841"
"164.26800","13.68917","0.02882"
"164.43000","13.70268","0.02880"
"164.59200","13.71626","0.02864"
"164.75400","13.72965","0.02855"
"164.91600","13.74322","0.02920"
"165.07800","13.75673","0.02878"
"165.24000","13.77025","0.02948"
"165.40200","13.78370","0.02974"
"165.56400","13.79721","0.02989"
"165.72600","13.81067","0.03060"
"165.88800","13.82418","0.03043"
"166.05000","13.83769","0.03094"
"166.21200","13.85120","0.03088"
"166.37400","13.86466","0.03086"
"166.53600","13.87823","0.03093"
"166.69800","13.89168","0.03105"
"166.86000","13.90519","0.03176"
"167.02200","13.91870","0.03170"
"167.18400","13.93222","0.03159"
"167.34600","13.94567","0.03146"
"167.50800","13.95918","0.03163"
"167.67000","13.97275","0.03156"
"167.83200","13.98621","0.03172"
"167.99400","13.99966","0.03218"
"168.15600","14.01323","0.03173"
"168.31800","14.02674","0.03201"
"168.48000","14.04020","0.03196"
"168.64200","14.05371","0.03210"
"168.80400","14.06722","0.03244"
"168.96600","14.08074","0.03254"
"169.12800","14.09419","0.03278"
"169.29000","14.10776","0.03291"
"169.45200","14.12115","0.03274"
"169.61400","14.13466","0.03334"
"169.77600","14.14818","0.03336"
"169.93800","14.16169","0.03340"
"170.10000","14.17520","0.03346"
"170.26200","14.18871","0.03347"
"170.42400","14.20223","0.03369"
"170.58600","14.21574","0.03440"
"170.74800","14.22913","0.03441"
"170.91000","14.24276","0.03425"
"171.07200","14.25616","0.03488"
"171.23400","14.26961","0.03475"
"171.39600","14.28318","0.03502"
"171.55800","14.29675","0.03517"
"171.72000","14.31021","0.03522"
"171.88200","14.32366","0.03494"
"172.04400","14.33723","0.03531"
"172.20600","14.35068","0.03518"
"172.36800","14.36414","0.03536"
"172.53000","14.37771","0.03562"
"172.69200","14.39122","0.03576"
"172.85400","14.40467","0.03606"
"173.01600","14.41819","0.03644"
"173.17800","14.43176","0.03653"
"173.34000","14.44515","0.03675"
"173.50200","14.45866","0.03699"
"173.66400","14.47218","0.03717"
"173.82600","14.48569","0.03734"
"173.98800","14.49920","0.03805"
"174.15000","14.51277","0.03845"
"174.31200","14.52623","0.03868"
"174.47400","14.53968","0.03880"
"174.63600","14.55319","0.03906"
"174.79800","14.56670","0.03983"
"174.96000","14.58016","0.04017"
"175.12200","14.59367","0.04063"
"175.28400","14.60724","0.04106"
"175.44600","14.62069","0.04243"
"175.60800","14.63421","0.04252"
"175.77000","14.64772","0.04284"
"175.93200","14.66117","0.04374"
"176.09400","14.67462","0.04437"
"176.25600","14.68820","0.04475"
"176.41800","14.70171","0.04542"
"176.58000","14.71516","0.04607"
"176.74200","14.72867","0.04709"
"176.90400","14.74219","0.04716"
"177.06600","14.75570","0.04770"
"177.22800","14.76915","0.04845"
"177.39000","14.78266","0.04979"
"177.55200","14.79624","0.05029"
"177.71400","14.80969","0.05108"
"177.87600","14.82326","0.05253"
"178.03800","14.83671","0.05287"
"178.20000","14.85017","0.05367"
"178.36200","14.86368","0.05473"
"178.52400","14.87719","0.05528"
"178.68600","14.89070","0.05651"
"178.84800","14.90422","0.05723"
"179.01000","14.91773","0.05714"
"179.17200","14.93124","0.05690"
"179.33400","14.94463","0.04643"
"179.49600","14.95820","0.04509"
"179.65800","14.97172","0.04346"
"179.82000","14.98517","0.04392"
"179.98200","14.99868","0.03975"
"180.14400","15.01225","0.04103"
"180.30600","15.02565","0.04068"
"180.46800","15.03916","0.04204"
"180.63000","15.05267","0.04272"
"180.79200","15.06619","0.04301"
"180.95400","15.07964","0.04289"
"181.11600","15.09321","0.04433"
"181.27800","15.10672","0.04391"
"181.44000","15.12018","0.04454"
"181.60200","15.13369","0.04543"
"181.76400","15.14726","0.04565"
"181.92600","15.16065","0.04596"
"182.08800","15.17417","0.04621"
"182.25000","15.18768","0.04798"
"182.41200","15.20119","0.04687"
"182.57400","15.21464","0.04848"
"182.73600","15.22821","0.04867"
"182.89800","15.24173","0.04897"
"183.06000","15.25518","0.05006"
"183.22200","15.26869","0.05074"
"183.38400","15.28220","0.05119"
"183.54600","15.29566","0.05182"
"183.70800","15.30917","0.05242"
"183.87000","15.32268","0.05271"
"184.03200","15.33620","0.05388"
"184.19400","15.34971","0.05358"
"184.35600","15.36322","0.05303"
"184.51800","15.37673","0.05282"
"184.68000","15.39013","0.05433"
"184.84200","15.40370","0.05259"
"185.00400","15.41721","0.05318"
"185.16600","15.43066","0.05206"
"185.32800","15.44423","0.05162"
"185.49000","15.45769","0.05272"
"185.65200","15.47120","0.05337"
"185.81400","15.48465","0.05327"
"185.97600","15.49822","0.05424"
"186.13800","15.51168","0.05505"
"186.30000","15.52513","0.05544"
"186.46200","15.53876","0.05612"
"186.62400","15.55222","0.05667"
"186.78600","15.56567","0.05723"
"186.94800","15.57924","0.05826"
"187.11000","15.59269","0.05860"
"187.27200","15.60614","0.05830"
"187.43400","15.61960","0.05780"
"187.59600","15.63323","0.05861"
"187.75800","15.64668","0.05871"
"187.92000","15.66013","0.05950"
"188.08200","15.67371","0.05977"
"188.24400","15.68722","0.06012"
"188.40600","15.70073","0.06120"
"188.56800","15.71412","0.06152"
"188.73000","15.72770","0.06147"
"188.89200","15.74115","0.06193"
"189.05400","15.75472","0.06243"
"189.21600","15.76823","0.06232"
"189.37800","15.78174","0.06291"
"189.54000","15.79514","0.06307"
"189.70200","15.80871","0.06388"
"189.86400","15.82222","0.06429"
"190.02600","15.83568","0.06496"
"190.18800","15.84919","0.06565"
"190.35000","15.86276","0.06586"
"190.51200","15.87627","0.06615"
"190.67400","15.88966","0.06619"
"190.83600","15.90318","0.06689"
"190.99800","15.91669","0.06716"
"191.16000","15.93008","0.06816"
"191.32200","15.94372","0.06785"
"191.48400","15.95717","0.06850"
"191.64600","15.97068","0.06817"
"191.80800","15.98413","0.06873"
"191.97000","15.99765","0.06915"
"192.13200","16.01116","0.06969"
"192.29400","16.02461","0.07015"
"192.45600","16.03818","0.07062"
"192.61800","16.05169","0.07091"
"192.78000","16.06521","0.07132"
"192.94200","16.07878","0.07175"
"193.10400","16.09217","0.07236"
"193.26600","16.10569","0.07329"
"193.42800","16.11920","0.07380"
"193.59000","16.13271","0.07434"
"193.75200","16.14616","0.07471"
"193.91400","16.15973","0.07559"
"194.07600","16.17325","0.07633"
"194.23800","16.18670","0.07646"
"194.40000","16.20015","0.07704"
"194.56200","16.21372","0.07764"
"194.72400","16.22718","0.07782"
"194.88600","16.24063","0.07893"
"195.04800","16.25420","0.07962"
"195.21000","16.26772","0.08019"
"195.37200","16.28117","0.08014"
"195.53400","16.29468","0.08137"
"195.69600","16.30819","0.08126"
"195.85800","16.32170","0.08182"
"196.02000","16.33516","0.08169"
"196.18200","16.34873","0.08243"
"196.34400","16.36218","0.08336"
"196.50600","16.37569","0.08363"
"196.66800","16.38921","0.08401"
"196.83000","16.40272","0.08414"
"196.99200","16.41617","0.08444"
"197.15400","16.42969","0.08421"
"197.31600","16.44320","0.08502"
"197.47800","16.45665","0.08490"
"197.64000","16.47016","0.08530"
"197.80200","16.48374","0.08545"
"197.96400","16.49725","0.08537"
"198.12600","16.51064","0.08568"
"198.28800","16.52421","0.08606"
"198.45000","16.53772","0.08597"
"198.61200","16.55118","0.08609"
"198.77400","16.56469","0.08604"
"198.93600","16.57820","0.08629"
"199.09800","16.59171","0.08630"
"199.26000","16.60517","0.08650"
"199.42200","16.61868","0.08645"
"199.58400","16.63225","0.08670"
"199.74600","16.64565","0.08670"
"199.90800","16.65922","0.08701"
"200.07000","16.67273","0.08697"
"200.23200","16.68618","0.08716"
"200.39400","16.69969","0.08716"
"200.55600","16.71321","0.08723"
"200.71800","16.72672","0.08744"
"200.88000","16.74017","0.08761"
"201.04200","16.75374","0.08794"
"201.20400","16.76720","0.08809"
"201.36600","16.78065","0.08835"
"201.52800","16.79422","0.08889"
"201.69000","16.80774","0.08928"
"201.85200","16.82119","0.08978"
"202.01400","16.83470","0.08995"
"202.17600","16.84821","0.08952"
"202.33800","16.86160","0.09070"
"202.50000","16.87512","0.09083"
"202.66200","16.88869","0.09129"
"202.82400","16.90220","0.09176"
"202.98600","16.91566","0.09319"
"203.14800","16.92923","0.09323"
"203.31000","16.94274","0.09473"
"203.47200","16.95619","0.09539"
"203.63400","16.96971","0.09571"
"203.79600","16.98322","0.09712"
"203.95800","16.99667","0.09663"
"204.12000","17.01018","0.09770"
"204.28200","17.02375","0.09805"
"204.44400","17.03721","0.09992"
"204.60600","17.05066","0.09997"
"204.76800","17.06423","0.10128"
"204.93000","17.07768","0.10211"
"205.09200","17.09108","0.10256"
"205.25400","17.10471","0.10365"
"205.41600","17.11822","0.10424"
"205.57800","17.13173","0.10491"
"205.74000","17.14519","0.10569"
"205.90200","17.15870","0.10585"
"206.06400","17.17215","0.10684"
"206.22600","17.18560","0.10688"
"206.38800","17.19924","0.10832"
"206.55000","17.21275","0.10864"
"206.71200","17.22620","0.10980"
"206.87400","17.23965","0.11018"
"207.03600","17.25323","0.11057"
"207.19800","17.26668","0.11111"
"207.36000","17.28019","0.11115"
"207.52200","17.29370","0.11227"
"207.68400","17.30722","0.11279"
"207.84600","17.32073","0.11369"
"208.00800","17.33424","0.11341"
"208.17000","17.34769","0.11436"
"208.33200","17.36115","0.11475"
"208.49400","17.37472","0.11485"
"208.65600","17.38823","0.11558"
"208.81800","17.40174","0.11575"
"208.98000","17.41520","0.11629"
"209.14200","17.42871","0.11696"
"209.30400","17.44222","0.11708"
"209.46600","17.45567","0.11757"
"209.62800","17.46925","0.11766"
"209.79000","17.48270","0.11855"
"209.95200","17.49615","0.11864"
"210.11400","17.50972","0.11915"
"210.27600","17.52317","0.11938"
"210.43800","17.53675","0.11974"
"210.60000","17.55020","0.12000"
"210.76200","17.56371","0.11984"
"210.92400","17.57717","0.12029"
"211.08600","17.59062","0.12025"
"211.24800","17.60419","0.12046"
"211.41000","17.61770","0.12099"
"211.57200","17.63116","0.12110"
"211.73400","17.64473","0.12169"
"211.89600","17.65824","0.12146"
"212.05800","17.67169","0.12215"
"212.22000","17.68521","0.12248"
"212.38200","17.69872","0.12256"
"212.54400","17.71217","0.12297"
"212.70600","17.72562","0.12327"
"212.86800","17.73919","0.12379"
"213.03000","17.75271","0.12402"
"213.19200","17.76616","0.12476"
"213.35400","17.77973","0.12464"
"213.51600","17.79325","0.12450"
"213.67800","17.80664","0.12493"
"213.84000","17.82021","0.12559"
"214.00200","17.83372","0.12567"
"214.16400","17.84724","0.12619"
"214.32600","17.86069","0.12671"
"214.48800","17.87426","0.12628"
"214.65000","17.88771","0.12702"
"214.81200","17.90117","0.12764"
"214.97400","17.91468","0.12825"
"215.13600","17.92825","0.12800"
"215.29800","17.94164","0.12742"
"215.46000","17.95522","0.12839"
"215.62200","17.96879","0.12854"
"215.78400","17.98218","0.12963"
"215.94600","17.99569","0.12944"
"216.10800","18.00920","0.12999"
"216.27000","18.02278","0.13049"
"216.43200","18.03617","0.13076"
"216.59400","18.04968","0.13096"
"216.75600","18.06326","0.13093"
"216.91800","18.07665","0.13169"
"217.08000","18.09022","0.13156"
"217.24200","18.10367","0.13266"
"217.40400","18.11719","0.13269"
"217.56600","18.13064","0.13296"
"217.72800","18.14421","0.13314"
"217.89000","18.15772","0.13373"
"218.05200","18.17123","0.13367"
"218.21400","18.18469","0.13427"
"218.37600","18.19820","0.13430"
"218.53800","18.21165","0.13453"
"218.70000","18.22516","0.13480"
"218.86200","18.23868","0.13526"
"219.02400","18.25219","0.13553"
"219.18600","18.26570","0.13569"
"219.34800","18.27927","0.13570"
"219.51000","18.29273","0.13593"
"219.67200","18.30624","0.13616"
"219.83400","18.31975","0.13632"
"219.99600","18.33320","0.13648"
"220.15800","18.34666","0.13687"
"220.32000","18.36023","0.13719"
"220.48200","18.37374","0.13739"
"220.64400","18.38720","0.13775"
"220.80600","18.40071","0.13758"
"220.96800","18.41422","0.13824"
"221.13000","18.42767","0.13849"
"221.29200","18.44113","0.13877"
"221.45400","18.45470","0.13894"
"221.61600","18.46827","0.13883"
"221.77800","18.48172","0.13848"
"221.94000","18.49523","0.13732"
"222.10200","18.50869","0.13721"
"222.26400","18.52220","0.13647"
"222.42600","18.53565","0.13656"
"222.58800","18.54922","0.13606"
"222.75000","18.56274","0.13548"
"222.91200","18.57619","0.13561"
"223.07400","18.58976","0.13556"
"223.23600","18.60321","-0.00929"
"223.39800","18.61661","0.00145"
"223.56000","18.63018","0.01503"
"223.72200","18.64375","0.00702"
"223.88400","18.65720","0.00119"
"224.04600","18.67066","0.00362"
"224.20800","18.68417","0.00587"
"224.37000","18.69768","0.00708"
"224.53200","18.71113","0.00840"
"224.69400","18.72471","0.00729"
"224.85600","18.73822","0.00496"
"225.01800","18.75167","0.00450"
"225.18000","18.76518","0.00584"
"225.34200","18.77870","0.00716"
"225.50400","18.79221","0.00514"
"225.66600","18.80572","0.00617"
"225.82800","18.81917","0.00632"
"225.99000","18.83269","0.00599"
"226.15200","18.84614","0.00605"
"226.31400","18.85971","0.00523"
"226.47600","18.87317","0.00502"
"226.63800","18.88668","0.00662"
"226.80000","18.90025","0.00850"
"226.96200","18.91376","0.00671"
"227.12400","18.92722","0.00504"
"227.28600","18.94073","0.00485"
"227.44800","18.95418","0.00588"
"227.61000","18.96763","0.00721"
"227.77200","18.98114","0.00783"
"227.93400","18.99472","0.00646"
"228.09600","19.00823","0.00626"
"228.25800","19.02168","0.00641"
"228.42000","19.03519","0.00661"
"228.58200","19.04871","0.00776"
"228.74400","19.06216","0.00842"
"228.90600","19.07567","0.00683"
"229.06800","19.08918","0.00648"
"229.23000","19.10276","0.00730"
"229.39200","19.11615","0.00689"
"229.55400","19.12978","0.00737"
"229.71600","19.14317","0.00836"
"229.87800","19.15669","0.00832"
"230.04000","19.17020","0.00707"
"230.20200","19.18371","0.00742"
"230.36400","19.19716","0.00731"
"230.52600","19.21068","0.00872"
"230.68800","19.22425","0.00925"
"230.85000","19.23776","0.00892"
"231.01200","19.25115","0.00758"
"231.17400","19.26473","0.00741"
"231.33600","19.27824","0.00776"
"231.49800","19.29169","0.00910"
"231.66000","19.30520","0.00967"
"231.82200","19.31872","0.00882"
"231.98400","19.33217","0.00825"
"232.14600","19.34568","0.00798"
"232.30800","19.35919","0.00907"
"232.47000","19.37271","0.00923"
"232.63200","19.38616","0.01013"
"232.79400","19.39973","0.00939"
"232.95600","19.41324","0.00904"
"233.11800","19.42670","0.00899"
"233.28000","19.44021","0.00919"
"233.44200","19.45378","0.01007"
"233.60400","19.46723","0.01031"
"233.76600","19.48063","0.00961"
"233.92800","19.49414","0.00871"
"234.09000","19.50771","0.00874"
"234.25200","19.52122","0.00979"
"234.41400","19.53473","0.01079"
"234.57600","19.54819","0.01046"
"234.73800","19.56164","0.00983"
"234.90000","19.57521","0.00992"
"235.06200","19.58872","0.00971"
"235.22400","19.60218","0.01019"
"235.38600","19.61569","0.01098"
"235.54800","19.62926","0.01112"
"235.71000","19.64271","0.01031"
"235.87200","19.65623","0.01046"
"236.03400","19.66974","0.01040"
"236.19600","19.68313","0.01121"
"236.35800","19.69665","0.00437"
"236.52000","19.71022","0.00499"
"236.68200","19.72373","0.00528"
"236.84400","19.73718","0.00470"
"237.00600","19.75070","0.00460"
"237.16800","19.76421","0.00476"
"237.33000","19.77766","0.00492"
"237.49200","19.79117","0.00405"
"237.65400","19.80468","0.00476"
"237.81600","19.81820","0.00433"
"237.97800","19.83165","0.00455"
"238.14000","19.84528","0.00488"
"238.30200","19.85873","0.00505"
"238.46400","19.87213","0.00443"
"238.62600","19.88570","0.00453"
"238.78800","19.89921","0.00427"
"238.95000","19.91267","0.00400"
"239.11200","19.92618","0.00385"
"239.27400","19.93975","0.00446"
"239.43600","19.95320","0.00367"
"239.59800","19.96665","0.00400"
"239.76000","19.98023","0.00361"
"239.92200","19.99374","0.00411"
"240.08400","20.00719","0.00367"
"240.24600","20.02070","0.00361"
"240.40800","20.03422","0.00385"
"240.57000","20.04767","0.00363"
"240.73200","20.06118","0.00362"
"240.89400","20.07470","0.00384"
"241.05600","20.08821","0.00382"
"241.08200","20.09036","0.00395"