File: Force_trajectories/170122_1/Specimen_RawData_1.csv
End date,"1/22/2017"
Specimen label,"3BT_18"
Maximum Load,"0.23093",N

Time,Extension,Load
(s),(mm),(N)
"0.00000","0.00000","-0.00007"
"0.21600","0.01489","-0.00001"
"0.43200","0.03629","0.00020"
"0.64800","0.05417","0.00042"
"0.86400","0.07223","0.00029"
"1.08000","0.09022","0.00079"
"1.29600","0.10816","0.00068"
"1.51200","0.12622","0.00091"
"1.72800","0.14421","0.00093"
"1.94400","0.16221","0.00124"
"2.16000","0.18021","0.00100"
"2.37600","0.19820","0.00179"
"2.59200","0.21626","0.00153"
"2.80800","0.23420","0.00116"
"3.02400","0.25225","0.00114"
"3.24000","0.27013","0.00175"
"3.45600","0.28819","0.00200"
"3.67200","0.30618","0.00221"
"3.88800","0.32418","0.00260"
"4.10400","0.34224","0.00314"
"4.32000","0.36023","0.00207"
"4.53600","0.37817","0.00181"
"4.75200","0.39623","0.00145"
"4.96800","0.41416","0.00247"
"5.18400","0.43222","0.00205"
"5.40000","0.45022","0.00332"
"5.61600","0.46821","0.00259"
"5.83200","0.48621","0.00297"
"6.04800","0.50415","0.00372"
"6.26400","0.52220","0.00279"
"6.48000","0.54020","0.00352"
"6.69600","0.55814","0.00348"
"6.91200","0.57625","0.00302"
"7.12800","0.59413","0.00345"
"7.34400","0.61219","0.00332"
"7.56000","0.63018","0.00311"
"7.77600","0.64818","0.00407"
"7.99200","0.66623","0.00335"
"8.20800","0.68411","0.00394"
"8.42400","0.70217","0.00354"
"8.64000","0.72016","0.00354"
"8.85600","0.73810","0.00390"
"9.07200","0.75622","0.00426"
"9.28800","0.77415","0.00396"
"9.50400","0.79227","0.00393"
"9.72000","0.81021","0.00404"
"9.93600","0.82820","0.00496"
"10.15200","0.84620","0.00441"
"10.36800","0.86420","0.00423"
"10.58400","0.88219","0.00472"
"10.80000","0.90019","0.00530"
"11.01600","0.91813","0.00513"
"11.23200","0.93624","0.00479"
"11.44800","0.95418","0.00494"
"11.66400","0.97218","0.00482"
"11.88000","0.99017","0.00509"
"12.09600","1.00817","0.00564"
"12.31200","1.02623","0.00596"
"12.52800","1.04422","0.00559"
"12.74400","1.06216","0.00554"
"12.96000","1.08016","0.00555"
"13.17600","1.09815","0.00637"
"13.39200","1.11621","0.00635"
"13.60800","1.13409","0.00622"
"13.82400","1.15226","0.00664"
"14.04000","1.17020","0.00607"
"14.25600","1.18814","0.00658"
"14.47200","1.20619","0.00668"
"14.68800","1.22413","0.00584"
"14.90400","1.24219","0.00616"
"15.12000","1.26018","0.00645"
"15.33600","1.27812","0.00622"
"15.55200","1.29618","0.00660"
"15.76800","1.31417","0.00650"
"15.98400","1.33223","0.00657"
"16.20000","1.35017","0.00706"
"16.41600","1.36816","0.00617"
"16.63200","1.38622","0.00676"
"16.84800","1.40416","0.00683"
"17.06400","1.42215","0.00666"
"17.28000","1.44015","0.00739"
"17.49600","1.45815","0.00760"
"17.71200","1.47620","0.00740"
"17.92800","1.49414","0.00719"
"18.14400","1.51214","0.00740"
"18.36000","1.53019","0.00722"
"18.57600","1.54819","0.00781"
"18.79200","1.56619","0.00795"
"19.00800","1.58412","0.00774"
"19.22400","1.60218","0.00807"
"19.44000","1.62018","0.00833"
"19.65600","1.63817","0.00794"
"19.87200","1.65617","0.00710"
"20.08800","1.67411","0.00784"
"20.30400","1.69222","0.00783"
"20.52000","1.71016","0.00733"
"20.73600","1.72816","0.00805"
"20.95200","1.74621","0.00803"
"21.16800","1.76409","0.00776"
"21.38400","1.78215","0.00762"
"21.60000","1.80014","0.00783"
"21.81600","1.81820","0.00789"
"22.03200","1.83620","0.00795"
"22.24800","1.85413","0.00835"
"22.46400","1.87219","0.00824"
"22.68000","1.89019","0.00854"
"22.89600","1.90818","0.00830"
"23.11200","1.92624","0.00880"
"23.32800","1.94418","0.00940"
"23.54400","1.96217","0.00894"
"23.76000","1.98017","0.00900"
"23.97600","1.99823","0.00935"
"24.19200","2.01616","0.01017"
"24.40800","2.03416","0.00935"
"24.62400","2.05222","0.01043"
"24.84000","2.07021","0.01054"
"25.05600","2.08815","0.01027"
"25.27200","2.10627","0.01050"
"25.48800","2.12408","0.01093"
"25.70400","2.14220","0.01041"
"25.92000","2.16014","0.01119"
"26.13600","2.17813","0.01057"
"26.35200","2.19619","0.01113"
"26.56800","2.21419","0.01030"
"26.78400","2.23218","0.01040"
"27.00000","2.25018","0.01108"
"27.21600","2.26818","0.01066"
"27.43200","2.28617","0.01265"
"27.64800","2.30417","0.00989"
"27.86400","2.32223","0.01034"
"28.08000","2.34016","0.00956"
"28.29600","2.35816","0.00965"
"28.51200","2.37616","0.00881"
"28.72800","2.39415","0.00946"
"28.94400","2.41215","0.00990"
"29.16000","2.43015","0.01043"
"29.37600","2.44820","0.01056"
"29.59200","2.46620","0.01031"
"29.80800","2.48414","0.01119"
"30.02400","2.50225","0.01132"
"30.24000","2.52013","0.01137"
"30.45600","2.53819","0.01167"
"30.67200","2.55618","0.01225"
"30.88800","2.57418","0.01230"
"31.10400","2.59224","0.01274"
"31.32000","2.61017","0.01240"
"31.53600","2.62817","0.01302"
"31.75200","2.64622","0.01330"
"31.96800","2.66410","0.01328"
"32.18400","2.68222","0.01283"
"32.40000","2.70016","0.01264"
"32.61600","2.71821","-0.00501"
"32.83200","2.73621","-0.00247"
"33.04800","2.75420","-0.00502"
"33.26400","2.77220","0.00420"
"33.48000","2.79014","0.01088"
"33.69600","2.80814","0.00823"
"33.91200","2.82619","0.00835"
"34.12800","2.84407","0.00808"
"34.34400","2.86224","0.01260"
"34.56000","2.88018","0.01193"
"34.77600","2.89818","0.00875"
"34.99200","2.91623","0.00886"
"35.20800","2.93417","0.00858"
"35.42400","2.95217","0.01127"
"35.64000","2.97016","0.01063"
"35.85600","2.98822","0.01036"
"36.07200","3.00622","0.01102"
"36.28800","3.02415","0.00673"
"36.50400","3.04215","0.00915"
"36.72000","3.06015","0.00848"
"36.93600","3.07814","0.01477"
"37.15200","3.09614","0.01333"
"37.36800","3.11420","0.01039"
"37.58400","3.13219","0.01002"
"37.80000","3.15013","0.00920"
"38.01600","3.16819","0.01246"
"38.23200","3.18618","0.01334"
"38.44800","3.20418","0.01460"
"38.66400","3.22218","0.01326"
"38.88000","3.24011","0.01073"
"39.09600","3.25823","0.01153"
"39.31200","3.27617","0.01300"
"39.52800","3.29416","0.01523"
"39.74400","3.31216","0.01526"
"39.96000","3.33010","0.00693"
"40.17600","3.34821","0.01472"
"40.39200","3.36621","0.01464"
"40.60800","3.38421","0.02032"
"40.82400","3.40220","0.01953"
"41.04000","3.42014","0.01547"
"41.25600","3.43826","0.01326"
"41.47200","3.45619","0.01413"
"41.68800","3.47413","0.02006"
"41.90400","3.49225","0.01955"
"42.12000","3.51018","0.01979"
"42.33600","3.52818","0.01527"
"42.55200","3.54618","0.01680"
"42.76800","3.56417","0.02120"
"42.98400","3.58223","0.02192"
"43.20000","3.60017","0.02427"
"43.41600","3.61816","0.02205"
"43.63200","3.63616","0.02361"
"43.84800","3.65416","0.02522"
"44.06400","3.67221","0.01684"
"44.28000","3.69015","0.02031"
"44.49600","3.70821","0.02115"
"44.71200","3.72614","0.02144"
"44.92800","3.74420","0.02262"
"45.14400","3.76220","0.02430"
"45.36000","3.78019","0.02662"
"45.57600","3.79819","0.02775"
"45.79200","3.81625","0.02819"
"46.00800","3.83412","0.02802"
"46.22400","3.85218","0.02802"
"46.44000","3.87018","0.02738"
"46.65600","3.88817","0.02645"
"46.87200","3.90605","0.02696"
"47.08800","3.92423","0.02656"
"47.30400","3.94222","0.02722"
"47.52000","3.96010","0.02794"
"47.73600","3.97822","0.02710"
"47.95200","3.99615","0.02751"
"48.16800","4.01421","0.02706"
"48.38400","4.03221","0.02785"
"48.60000","4.05014","0.02852"
"48.81600","4.06826","0.02807"
"49.03200","4.08614","0.01983"
"49.24800","4.10419","0.01948"
"49.46400","4.12219","0.01888"
"49.68000","4.14019","0.01623"
"49.89600","4.15818","0.01560"
"50.11200","4.17624","0.02728"
"50.32800","4.19418","0.03061"
"50.54400","4.21223","0.03076"
"50.76000","4.23011","0.03079"
"50.97600","4.24823","0.03156"
"51.19200","4.26616","0.03195"
"51.40800","4.28422","0.03222"
"51.62400","4.30216","0.03245"
"51.84000","4.32009","0.03255"
"52.05600","4.33815","0.03282"
"52.27200","4.35621","0.03211"
"52.48800","4.37414","0.03098"
"52.70400","4.39226","0.03144"
"52.92000","4.41008","0.03125"
"53.13600","4.42825","0.03162"
"53.35200","4.44619","0.03197"
"53.56800","4.46419","0.03237"
"53.78400","4.48218","0.03218"
"54.00000","4.50012","0.03235"
"54.21600","4.51818","0.03226"
"54.43200","4.53617","0.03244"
"54.64800","4.55417","0.03294"
"54.86400","4.57217","0.03266"
"55.08000","4.59010","0.03298"
"55.29600","4.60816","0.03325"
"55.51200","4.62616","0.03347"
"55.72800","4.64415","0.03360"
"55.94400","4.66221","0.03368"
"56.16000","4.68015","0.03370"
"56.37600","4.69814","0.03393"
"56.59200","4.71620","0.03437"
"56.80800","4.73419","0.03470"
"57.02400","4.75219","0.03483"
"57.24000","4.77007","0.03505"
"57.45600","4.78819","0.03558"
"57.67200","4.80612","0.03543"
"57.88800","4.82418","0.03554"
"58.10400","4.84218","0.03556"
"58.32000","4.86011","0.03580"
"58.53600","4.87817","0.03563"
"58.75200","4.89616","0.03592"
"58.96800","4.91416","0.03584"
"59.18400","4.93222","0.03601"
"59.40000","4.95015","0.03595"
"59.61600","4.96815","0.03560"
"59.83200","4.98609","0.03602"
"60.04800","5.00414","0.03561"
"60.26400","5.02220","0.03567"
"60.48000","5.04014","0.03541"
"60.69600","5.05819","0.03604"
"60.91200","5.07619","0.03531"
"61.12800","5.09419","0.03528"
"61.34400","5.11218","0.03478"
"61.56000","5.13012","0.03423"
"61.77600","5.14818","0.03394"
"61.99200","5.16617","0.03377"
"62.20800","5.18411","0.03361"
"62.42400","5.20217","0.03342"
"62.64000","5.22010","0.03370"
"62.85600","5.23816","0.03377"
"63.07200","5.25616","0.03376"
"63.28800","5.27421","0.03367"
"63.50400","5.29221","0.03380"
"63.72000","5.31015","0.03372"
"63.93600","5.32814","0.03370"
"64.15200","5.34614","0.03397"
"64.36800","5.36414","0.03399"
"64.58400","5.38219","0.03417"
"64.80000","5.40013","0.03395"
"65.01600","5.41819","0.03440"
"65.23200","5.43618","0.03409"
"65.44800","5.45424","0.00008"
"65.66400","5.47218","-0.00226"
"65.88000","5.49017","-0.00225"
"66.09600","5.50817","-0.00109"
"66.31200","5.52617","-0.00204"
"66.52800","5.54416","-0.00309"
"66.74400","5.56222","-0.00172"
"66.96000","5.58010","-0.00345"
"67.17600","5.59821","-0.00194"
"67.39200","5.61615","-0.00258"
"67.60800","5.63421","-0.00223"
"67.82400","5.65214","-0.00285"
"68.04000","5.67020","-0.00327"
"68.25600","5.68820","-0.00165"
"68.47200","5.70613","-0.00269"
"68.68800","5.72419","-0.00133"
"68.90400","5.74219","-0.00283"
"69.12000","5.76018","-0.00183"
"69.33600","5.77824","-0.00298"
"69.55200","5.79618","-0.00230"
"69.76800","5.81423","-0.00192"
"69.98400","5.83217","-0.00265"
"70.20000","5.85023","-0.00219"
"70.41600","5.86816","-0.00240"
"70.63200","5.88616","-0.00253"
"70.84800","5.90422","-0.00279"
"71.06400","5.92215","-0.00186"
"71.28000","5.94015","-0.00231"
"71.49600","5.95821","-0.00262"
"71.71200","5.97614","-0.00186"
"71.92800","5.99426","-0.00204"
"72.14400","6.01214","-0.00212"
"72.36000","6.03013","-0.00189"
"72.57600","6.04813","-0.00242"
"72.79200","6.06613","-0.00270"
"73.00800","6.08418","-0.00206"
"73.22400","6.10224","-0.00196"
"73.44000","6.12012","-0.00227"
"73.65600","6.13823","-0.00257"
"73.87200","6.15617","-0.00184"
"74.08800","6.17423","-0.00238"
"74.30400","6.19216","-0.00242"
"74.52000","6.21016","-0.00274"
"74.73600","6.22822","-0.00246"
"74.95200","6.24615","-0.00206"
"75.16800","6.26421","-0.00149"
"75.38400","6.28221","-0.00178"
"75.60000","6.30014","-0.00211"
"75.81600","6.31820","-0.00234"
"76.03200","6.33614","-0.00150"
"76.24800","6.35425","-0.00214"
"76.46400","6.37219","-0.00237"
"76.68000","6.39013","-0.00281"
"76.89600","6.40818","-0.00217"
"77.11200","6.42618","-0.00174"
"77.32800","6.44418","-0.00182"
"77.54400","6.46223","-0.00181"
"77.76000","6.48017","-0.00189"
"77.97600","6.49823","-0.00245"
"78.19200","6.51610","-0.00170"
"78.40800","6.53416","-0.00225"
"78.62400","6.55216","-0.00218"
"78.84000","6.57015","-0.00181"
"79.05600","6.58821","-0.00220"
"79.27200","6.60615","-0.00161"
"79.48800","6.62420","-0.00209"
"79.70400","6.64220","-0.00133"
"79.92000","6.66014","-0.00162"
"80.13600","6.67825","-0.00159"
"80.35200","6.69607","-0.00189"
"80.56800","6.71424","-0.00197"
"80.78400","6.73218","-0.00157"
"81.00000","6.75018","-0.00193"
"81.21600","6.76818","-0.00116"
"81.43200","6.78611","-0.00185"
"81.64800","6.80417","-0.00126"
"81.86400","6.82217","-0.00130"
"82.08000","6.84022","-0.00066"
"82.29600","6.85822","-0.00118"
"82.51200","6.87610","-0.00179"
"82.72800","6.89421","-0.00122"
"82.94400","6.91221","-0.00175"
"83.16000","6.93020","-0.00167"
"83.37600","6.94820","-0.00175"
"83.59200","6.96614","-0.00104"
"83.80800","6.98420","-0.00160"
"84.02400","7.00219","-0.00100"
"84.24000","7.02019","-0.00239"
"84.45600","7.03818","-0.00078"
"84.67200","7.05612","-0.00129"
"84.88800","7.07418","-0.00137"
"85.10400","7.09211","-0.00174"
"85.32000","7.11017","-0.00146"
"85.53600","7.12823","-0.00147"
"85.75200","7.14611","-0.00151"
"85.96800","7.16422","-0.00115"
"86.18400","7.18216","-0.00155"
"86.40000","7.20015","-0.00121"
"86.61600","7.21821","-0.00128"
"86.83200","7.23615","-0.00141"
"87.04800","7.25415","-0.00126"
"87.26400","7.27220","-0.00148"
"87.48000","7.29014","-0.00141"
"87.69600","7.30819","-0.00055"
"87.91200","7.32613","-0.00099"
"88.12800","7.34419","-0.00090"
"88.34400","7.36218","-0.00064"
"88.56000","7.38024","-0.00096"
"88.77600","7.39818","-0.00065"
"88.99200","7.41617","-0.00108"
"89.20800","7.43417","-0.00127"
"89.42400","7.45217","-0.00157"
"89.64000","7.47016","-0.00116"
"89.85600","7.48816","-0.00076"
"90.07200","7.50610","-0.00055"
"90.28800","7.52421","-0.00052"
"90.50400","7.54215","-0.00070"
"90.72000","7.56027","-0.00095"
"90.93600","7.57820","-0.00081"
"91.15200","7.59614","-0.00129"
"91.36800","7.61420","-0.00098"
"91.58400","7.63213","-0.00130"
"91.80000","7.65019","-0.00126"
"92.01600","7.66819","-0.00085"
"92.23200","7.68612","-0.00121"
"92.44800","7.70424","-0.00069"
"92.66400","7.72218","-0.00130"
"92.88000","7.74023","-0.00016"
"93.09600","7.75823","-0.00094"
"93.31200","7.77617","-0.00016"
"93.52800","7.79416","-0.00086"
"93.74400","7.81216","-0.00066"
"93.96000","7.83016","-0.00071"
"94.17600","7.84827","-0.00097"
"94.39200","7.86615","-0.00071"
"94.60800","7.88421","-0.00068"
"94.82400","7.90214","-0.00095"
"95.04000","7.92020","-0.00083"
"95.25600","7.93820","-0.00057"
"95.47200","7.95619","-0.00067"
"95.68800","7.97419","-0.00026"
"95.90400","7.99213","-0.00033"
"96.12000","8.01018","-0.00050"
"96.33600","8.02824","-0.00108"
"96.55200","8.04612","-0.00071"
"96.76800","8.06417","-0.00105"
"96.98400","8.08223","-0.00020"
"97.20000","8.10017","-0.00029"
"97.41600","8.11822","-0.00062"
"97.63200","8.13616","-0.00055"
"97.84800","8.15416","-0.00046"
"98.06400","8.17215","-0.00076"
"98.28000","8.19015","-0.00053"
"98.49600","8.20815","-0.00066"
"98.71200","8.22614","-0.00051"
"98.92800","8.24420","-0.00110"
"99.14400","8.26214","-0.00056"
"99.36000","8.28019","-0.00072"
"99.57600","8.29819","-0.00056"
"99.79200","8.31619","-0.00044"
"100.00800","8.33418","-0.00048"
"100.22400","8.35212","-0.00068"
"100.44000","8.37024","-0.00015"
"100.65600","8.38823","-0.00020"
"100.87200","8.40617","-0.00039"
"101.08800","8.42422","-0.00053"
"101.30400","8.44216","-0.00040"
"101.52000","8.46022","-0.00102"
"101.73600","8.47816","-0.00115"
"101.95200","8.49621","-0.00060"
"102.16800","8.51421","-0.00066"
"102.38400","8.53209","-0.00046"
"102.60000","8.55020","-0.00075"
"102.81600","8.56820","-0.00050"
"103.03200","8.58619","-0.00042"
"103.24800","8.60419","-0.00003"
"103.46400","8.62213","0.00003"
"103.68000","8.64019","-0.00001"
"103.89600","8.65824","0.00033"
"104.11200","8.67618","-0.00029"
"104.32800","8.69423","0.00013"
"104.54400","8.71211","-0.00049"
"104.76000","8.73023","-0.00041"
"104.97600","8.74823","-0.00049"
"105.19200","8.76616","-0.00024"
"105.40800","8.78422","-0.00045"
"105.62400","8.80221","-0.00022"
"105.84000","8.82021","-0.00079"
"106.05600","8.83821","0.00020"
"106.27200","8.85614","-0.00016"
"106.48800","8.87420","0.00038"
"106.70400","8.89214","-0.00017"
"106.92000","8.91020","0.00040"
"107.13600","8.92813","0.00029"
"107.35200","8.94619","0.00011"
"107.56800","8.96418","0.00016"
"107.78400","8.98218","0.00014"
"108.00000","9.00018","0.00005"
"108.21600","9.01824","-0.00013"
"108.43200","9.03617","-0.00013"
"108.64800","9.05417","0.00022"
"108.86400","9.07216","-0.00002"
"109.08000","9.09022","0.00027"
"109.29600","9.10816","0.00002"
"109.51200","9.12621","-0.00019"
"109.72800","9.14421","-0.00003"
"109.94400","9.16215","0.00020"
"110.16000","9.18021","0.00009"
"110.37600","9.19826","-0.00001"
"110.59200","9.21614","0.00011"
"110.80800","9.23419","-0.00023"
"111.02400","9.25207","-0.00032"
"111.24000","9.27019","0.00033"
"111.45600","9.28818","-0.00036"
"111.67200","9.30618","0.00060"
"111.88800","9.32418","0.00037"
"112.10400","9.34217","0.00004"
"112.32000","9.36023","0.00018"
"112.53600","9.37817","0.00033"
"112.75200","9.39622","0.00015"
"112.96800","9.41422","0.00014"
"113.18400","9.43210","0.00028"
"113.40000","9.45021","0.00045"
"113.61600","9.46815","0.00011"
"113.83200","9.48621","0.00050"
"114.04800","9.50420","-0.00012"
"114.26400","9.52220","-0.00014"
"114.48000","9.54020","-0.00014"
"114.69600","9.55819","0.00045"
"114.91200","9.57619","0.00038"
"115.12800","9.59419","0.00069"
"115.34400","9.61206","0.00014"
"115.56000","9.63018","0.00034"
"115.77600","9.64812","0.00031"
"115.99200","9.66617","0.00058"
"116.20800","9.68423","-0.00002"
"116.42400","9.70211","-0.00020"
"116.64000","9.72016","0.00064"
"116.85600","9.73816","0.00044"
"117.07200","9.75622","0.00025"
"117.28800","9.77421","0.00054"
"117.50400","9.79209","0.00120"
"117.72000","9.81015","0.00039"
"117.93600","9.82814","-0.00005"
"118.15200","9.84620","0.00081"
"118.36800","9.86420","0.00037"
"118.58400","9.88207","0.00060"
"118.80000","9.90019","0.00011"
"119.01600","9.91819","0.00055"
"119.23200","9.93612","0.00060"
"119.44800","9.95418","0.00122"
"119.66400","9.97212","0.00066"
"119.88000","9.99017","0.00056"
"120.09600","10.00817","0.00045"
"120.31200","10.02617","0.00015"
"120.52800","10.04422","0.00118"
"120.74400","10.06216","0.00046"
"120.96000","10.08022","0.00086"
"121.17600","10.09815","0.00055"
"121.39200","10.11621","0.00062"
"121.60800","10.13421","0.00106"
"121.82400","10.15214","0.00106"
"122.04000","10.17020","0.00092"
"122.25600","10.18820","0.00140"
"122.47200","10.20613","0.00108"
"122.68800","10.22419","0.00081"
"122.90400","10.24213","0.00091"
"123.12000","10.26018","0.00079"
"123.33600","10.27812","0.00103"
"123.55200","10.29618","0.00076"
"123.76800","10.31417","0.00141"
"123.98400","10.33217","0.00090"
"124.20000","10.35023","0.00117"
"124.41600","10.36816","0.00107"
"124.63200","10.38616","0.00129"
"124.84800","10.40421","0.00115"
"125.06400","10.42215","0.00103"
"125.28000","10.44021","0.00114"
"125.49600","10.45815","0.00141"
"125.71200","10.47620","0.00188"
"125.92800","10.49420","0.00164"
"126.14400","10.51214","0.00092"
"126.36000","10.53019","0.00152"
"126.57600","10.54813","0.00115"
"126.79200","10.56625","0.00140"
"127.00800","10.58424","0.00195"
"127.22400","10.60212","0.00178"
"127.44000","10.62024","0.00193"
"127.65600","10.63817","0.00174"
"127.87200","10.65617","0.00171"
"128.08800","10.67417","0.00185"
"128.30400","10.69216","0.00189"
"128.52000","10.71016","0.00198"
"128.73600","10.72816","0.00162"
"128.95200","10.74621","0.00177"
"129.16800","10.76421","0.00218"
"129.38400","10.78215","0.00225"
"129.60000","10.80020","0.00231"
"129.81600","10.81820","0.00227"
"130.03200","10.83619","0.00216"
"130.24800","10.85413","0.00231"
"130.46400","10.87219","0.00219"
"130.68000","10.89019","0.00242"
"130.89600","10.90818","0.00233"
"131.11200","10.92618","0.00271"
"131.32800","10.94423","0.00219"
"131.54400","10.96217","0.00231"
"131.76000","10.98023","0.00241"
"131.97600","10.99823","0.00249"
"132.19200","11.01628","0.00264"
"132.40800","11.03410","0.00294"
"132.62400","11.05215","0.00264"
"132.84000","11.07021","0.00276"
"133.05600","11.08815","0.00261"
"133.27200","11.10620","0.00243"
"133.48800","11.12420","0.00303"
"133.70400","11.14220","0.00297"
"133.92000","11.16019","0.00300"
"134.13600","11.17813","0.00276"
"134.35200","11.19625","0.00291"
"134.56800","11.21412","0.00285"
"134.78400","11.23218","0.00291"
"135.00000","11.25018","0.00267"
"135.21600","11.26812","0.00313"
"135.43200","11.28623","0.00325"
"135.64800","11.30423","0.00263"
"135.86400","11.32216","0.00342"
"136.08000","11.34022","0.00329"
"136.29600","11.35810","0.00318"
"136.51200","11.37621","0.00340"
"136.72800","11.39415","0.00326"
"136.94400","11.41215","0.00370"
"137.16000","11.43020","0.00341"
"137.37600","11.44814","0.00297"
"137.59200","11.46620","0.00361"
"137.80800","11.48419","0.00340"
"138.02400","11.50213","0.00422"
"138.24000","11.52019","0.00400"
"138.45600","11.53812","0.00385"
"138.67200","11.55618","0.00371"
"138.88800","11.57418","0.00415"
"139.10400","11.59217","0.00405"
"139.32000","11.61023","0.00376"
"139.53600","11.62817","0.00443"
"139.75200","11.64622","0.00345"
"139.96800","11.66422","0.00445"
"140.18400","11.68216","0.00406"
"140.40000","11.70021","0.00426"
"140.61600","11.71815","0.00459"
"140.83200","11.73621","0.00450"
"141.04800","11.75414","0.00441"
"141.26400","11.77214","0.00471"
"141.48000","11.79020","0.00411"
"141.69600","11.80814","0.00477"
"141.91200","11.82619","0.00482"
"142.12800","11.84413","0.00455"
"142.34400","11.86218","0.00538"
"142.56000","11.88024","0.00485"
"142.77600","11.89812","0.00552"
"142.99200","11.91617","0.00557"
"143.20800","11.93411","0.00504"
"143.42400","11.95217","0.00537"
"143.64000","11.97016","0.00540"
"143.85600","11.98810","0.00537"
"144.07200","12.00622","0.00554"
"144.28800","12.02415","0.00612"
"144.50400","12.04221","0.00502"
"144.72000","12.06027","0.00599"
"144.93600","12.07814","0.00601"
"145.15200","12.09620","0.00612"
"145.36800","12.11420","0.00590"
"145.58400","12.13219","0.00589"
"145.80000","12.15025","0.00590"
"146.01600","12.16813","0.00636"
"146.23200","12.18624","0.00606"
"146.44800","12.20418","0.00589"
"146.66400","12.22218","0.00649"
"146.88000","12.24023","0.00601"
"147.09600","12.25817","0.00646"
"147.31200","12.27617","0.00659"
"147.52800","12.29416","0.00670"
"147.74400","12.31216","0.00715"
"147.96000","12.33022","0.00657"
"148.17600","12.34815","0.00652"
"148.39200","12.36621","0.00702"
"148.60800","12.38421","0.00636"
"148.82400","12.40220","0.00692"
"149.04000","12.42020","0.00704"
"149.25600","12.43814","0.00712"
"149.47200","12.45613","0.00716"
"149.68800","12.47419","0.00699"
"149.90400","12.49219","0.00701"
"150.12000","12.51018","0.00747"
"150.33600","12.52812","0.00749"
"150.55200","12.54618","0.00792"
"150.76800","12.56411","0.00754"
"150.98400","12.58223","0.00732"
"151.20000","12.60017","0.00750"
"151.41600","12.61816","0.00763"
"151.63200","12.63616","0.00804"
"151.84800","12.65416","0.00795"
"152.06400","12.67215","0.00844"
"152.28000","12.69021","0.00853"
"152.49600","12.70815","0.00818"
"152.71200","12.72620","0.00846"
"152.92800","12.74414","0.00803"
"153.14400","12.76226","0.00940"
"153.36000","12.78013","0.00905"
"153.57600","12.79819","0.00832"
"153.79200","12.81613","0.00904"
"154.00800","12.83412","0.00938"
"154.22400","12.85212","0.00907"
"154.44000","12.87024","0.00930"
"154.65600","12.88811","0.00929"
"154.87200","12.90623","0.00931"
"155.08800","12.92416","0.00916"
"155.30400","12.94222","0.00924"
"155.52000","12.96016","0.00990"
"155.73600","12.97822","0.00913"
"155.95200","12.99615","0.00987"
"156.16800","13.01415","0.00949"
"156.38400","13.03221","0.00977"
"156.60000","13.05020","0.01010"
"156.81600","13.06814","0.00998"
"157.03200","13.08619","0.01043"
"157.24800","13.10413","0.01014"
"157.46400","13.12219","0.01025"
"157.68000","13.14018","0.01082"
"157.89600","13.15818","0.01090"
"158.11200","13.17612","0.01086"
"158.32800","13.19412","0.01119"
"158.54400","13.21217","0.01136"
"158.76000","13.23023","0.01151"
"158.97600","13.24817","0.01156"
"159.19200","13.26616","0.01206"
"159.40800","13.28416","0.01122"
"159.62400","13.30222","0.01139"
"159.84000","13.32021","0.01161"
"160.05600","13.33815","0.01145"
"160.27200","13.35614","0.01215"
"160.48800","13.37414","0.01225"
"160.70400","13.39220","0.01202"
"160.92000","13.41019","0.01256"
"161.13600","13.42813","0.01225"
"161.35200","13.44619","0.01306"
"161.56800","13.46419","0.01233"
"161.78400","13.48218","0.01324"
"162.00000","13.50018","0.01313"
"162.21600","13.51812","0.01330"
"162.43200","13.53623","0.01318"
"162.64800","13.55411","0.01402"
"162.86400","13.57222","0.01374"
"163.08000","13.59016","0.01413"
"163.29600","13.60816","0.01440"
"163.51200","13.62615","0.01408"
"163.72800","13.64415","0.01452"
"163.94400","13.66221","0.01488"
"164.16000","13.68015","0.01503"
"164.37600","13.69814","0.01516"
"164.59200","13.71620","0.01563"
"164.80800","13.73413","0.01581"
"165.02400","13.75225","0.01590"
"165.24000","13.77019","0.01567"
"165.45600","13.78818","0.01648"
"165.67200","13.80624","0.01583"
"165.88800","13.82418","0.01623"
"166.10400","13.84217","0.01646"
"166.32000","13.86017","0.01636"
"166.53600","13.87817","0.01707"
"166.75200","13.89622","0.01693"
"166.96800","13.91410","0.01703"
"167.18400","13.93222","0.01693"
"167.40000","13.95015","0.01789"
"167.61600","13.96815","0.01787"
"167.83200","13.98621","0.01765"
"168.04800","14.00414","0.01857"
"168.26400","14.02220","0.01811"
"168.48000","14.04020","0.01856"
"168.69600","14.05819","0.01880"
"168.91200","14.07619","0.01877"
"169.12800","14.09413","0.01870"
"169.34400","14.11218","0.01941"
"169.56000","14.13018","0.01958"
"169.77600","14.14818","0.02022"
"169.99200","14.16623","0.01995"
"170.20800","14.18417","0.02030"
"170.42400","14.20223","0.02011"
"170.64000","14.22022","0.02078"
"170.85600","14.23810","0.02074"
"171.07200","14.25622","0.02152"
"171.28800","14.27409","0.02176"
"171.50400","14.29221","0.02175"
"171.72000","14.31015","0.02179"
"171.93600","14.32820","0.02231"
"172.15200","14.34620","0.02219"
"172.36800","14.36420","0.02249"
"172.58400","14.38213","0.02322"
"172.80000","14.40019","0.02319"
"173.01600","14.41819","0.02359"
"173.23200","14.43618","0.02367"
"173.44800","14.45412","0.02433"
"173.66400","14.47218","0.02427"
"173.88000","14.49017","0.02483"
"174.09600","14.50817","0.02484"
"174.31200","14.52617","0.02543"
"174.52800","14.54410","0.02577"
"174.74400","14.56216","0.02544"
"174.96000","14.58022","0.02594"
"175.17600","14.59815","0.02517"
"175.39200","14.61621","0.02625"
"175.60800","14.63415","0.02575"
"175.82400","14.65220","0.02595"
"176.04000","14.67014","0.02611"
"176.25600","14.68820","0.02651"
"176.47200","14.70619","0.02644"
"176.68800","14.72413","0.02680"
"176.90400","14.74219","0.02697"
"177.12000","14.76018","0.02701"
"177.33600","14.77824","0.02802"
"177.55200","14.79618","0.02770"
"177.76800","14.81411","0.02764"
"177.98400","14.83223","0.02812"
"178.20000","14.85017","0.02816"
"178.41600","14.86822","0.02875"
"178.63200","14.88622","0.02885"
"178.84800","14.90416","0.02892"
"179.06400","14.92221","0.02919"
"179.28000","14.94015","0.02902"
"179.49600","14.95815","0.02940"
"179.71200","14.97620","0.03012"
"179.92800","14.99414","0.03026"
"180.14400","15.01220","0.03011"
"180.36000","15.03013","0.03038"
"180.57600","15.04825","0.03052"
"180.79200","15.06619","0.03059"
"181.00800","15.08412","0.03096"
"181.22400","15.10218","0.03122"
"181.44000","15.12018","0.03168"
"181.65600","15.13817","0.03139"
"181.87200","15.15623","0.03174"
"182.08800","15.17410","0.03188"
"182.30400","15.19216","0.03204"
"182.52000","15.21016","0.03186"
"182.73600","15.22821","0.03250"
"182.95200","15.24615","0.03257"
"183.16800","15.26415","0.03290"
"183.38400","15.28220","0.03277"
"183.60000","15.30020","0.03321"
"183.81600","15.31820","0.03341"
"184.03200","15.33614","0.03355"
"184.24800","15.35413","0.03369"
"184.46400","15.37219","0.03375"
"184.68000","15.39018","0.03411"
"184.89600","15.40818","0.03416"
"185.11200","15.42618","0.03448"
"185.32800","15.44417","0.03453"
"185.54400","15.46217","0.03484"
"185.76000","15.48017","0.03498"
"185.97600","15.49822","0.03515"
"186.19200","15.51616","0.03548"
"186.40800","15.53416","0.03607"
"186.62400","15.55216","0.03626"
"186.84000","15.57015","0.03650"
"187.05600","15.58821","0.03707"
"187.27200","15.60614","0.03741"
"187.48800","15.62408","0.03775"
"187.70400","15.64226","0.03809"
"187.92000","15.66019","0.03824"
"188.13600","15.67819","0.03909"
"188.35200","15.69619","0.03907"
"188.56800","15.71418","0.04036"
"188.78400","15.73224","0.03986"
"189.00000","15.75018","0.04105"
"189.21600","15.76817","0.04144"
"189.43200","15.78623","0.04192"
"189.64800","15.80411","0.04252"
"189.86400","15.82222","0.04328"
"190.08000","15.84016","0.04369"
"190.29600","15.85822","0.04438"
"190.51200","15.87621","0.04472"
"190.72800","15.89421","0.04555"
"190.94400","15.91215","0.04669"
"191.16000","15.93020","0.04695"
"191.37600","15.94820","0.03820"
"191.59200","15.96620","0.03745"
"191.80800","15.98413","0.03946"
"192.02400","16.00219","0.03861"
"192.24000","16.02013","0.04135"
"192.45600","16.03818","0.03932"
"192.67200","16.05618","0.04315"
"192.88800","16.07418","0.04040"
"193.10400","16.09217","0.04539"
"193.32000","16.11017","0.04214"
"193.53600","16.12817","0.04724"
"193.75200","16.14622","0.04377"
"193.96800","16.16416","0.04887"
"194.18400","16.18222","0.04663"
"194.40000","16.20015","0.04916"
"194.61600","16.21827","0.03713"
"194.83200","16.23615","0.02953"
"195.04800","16.25420","0.03174"
"195.26400","16.27220","0.03076"
"195.48000","16.29020","0.03172"
"195.69600","16.30819","0.03234"
"195.91200","16.32619","0.03167"
"196.12800","16.34413","0.03300"
"196.34400","16.36218","0.03188"
"196.56000","16.38012","0.03375"
"196.77600","16.39824","0.03283"
"196.99200","16.41611","0.03386"
"197.20800","16.43417","0.03421"
"197.42400","16.45222","0.03409"
"197.64000","16.47010","0.03477"
"197.85600","16.48822","0.03536"
"198.07200","16.50616","0.03549"
"198.28800","16.52415","0.03622"
"198.50400","16.54221","0.03632"
"198.72000","16.56015","0.03703"
"198.93600","16.57814","0.03664"
"199.15200","16.59614","0.03820"
"199.36800","16.61419","0.03800"
"199.58400","16.63219","0.03919"
"199.80000","16.65013","0.03988"
"200.01600","16.66813","0.04077"
"200.23200","16.68612","0.04205"
"200.44800","16.70418","0.04274"
"200.66400","16.72218","0.04394"
"200.88000","16.74011","0.04470"
"201.09600","16.75823","0.04614"
"201.31200","16.77617","0.04741"
"201.52800","16.79416","0.04874"
"201.74400","16.81216","0.04953"
"201.96000","16.83016","0.05091"
"202.17600","16.84815","0.05221"
"202.39200","16.86615","0.05410"
"202.60800","16.88421","0.05512"
"202.82400","16.90220","0.05630"
"203.04000","16.92014","0.05738"
"203.25600","16.93819","0.05892"
"203.47200","16.95619","0.05876"
"203.68800","16.97419","0.06030"
"203.90400","16.99224","0.06157"
"204.12000","17.01012","0.06305"
"204.33600","17.02818","0.06416"
"204.55200","17.04618","0.06497"
"204.76800","17.06417","0.06568"
"204.98400","17.08217","0.06650"
"205.20000","17.10016","0.06778"
"205.41600","17.11822","0.06924"
"205.63200","17.13616","0.07020"
"205.84800","17.15416","0.07198"
"206.06400","17.17221","0.07290"
"206.28000","17.19015","0.07428"
"206.49600","17.20821","0.07586"
"206.71200","17.22620","0.07726"
"206.92800","17.24414","0.07805"
"207.14400","17.26219","0.07507"
"207.36000","17.28013","0.07469"
"207.57600","17.29813","0.07076"
"207.79200","17.31618","0.07219"
"208.00800","17.33418","0.07310"
"208.22400","17.35224","0.07222"
"208.44000","17.37017","0.07481"
"208.65600","17.38823","0.07370"
"208.87200","17.40617","0.07461"
"209.08800","17.42416","0.07552"
"209.30400","17.44222","0.07580"
"209.52000","17.46016","0.07839"
"209.73600","17.47821","0.07838"
"209.95200","17.49615","0.07976"
"210.16800","17.51415","0.08031"
"210.38400","17.53220","0.08087"
"210.60000","17.55014","0.08186"
"210.81600","17.56820","0.08256"
"211.03200","17.58613","0.08346"
"211.24800","17.60419","0.08412"
"211.46400","17.62219","0.08443"
"211.68000","17.64013","0.08465"
"211.89600","17.65818","0.08492"
"212.11200","17.67618","0.08526"
"212.32800","17.69417","0.08556"
"212.54400","17.71223","0.08577"
"212.76000","17.73005","0.08610"
"212.97600","17.74816","0.08661"
"213.19200","17.76616","0.08715"
"213.40800","17.78416","0.08739"
"213.62400","17.80221","0.08873"
"213.84000","17.82021","0.08900"
"214.05600","17.83821","0.09068"
"214.27200","17.85620","0.09195"
"214.48800","17.87414","0.09372"
"214.70400","17.89226","0.08928"
"214.92000","17.91007","0.09122"
"215.13600","17.92819","0.09243"
"215.35200","17.94613","0.09062"
"215.56800","17.96418","0.09387"
"215.78400","17.98218","0.09459"
"216.00000","18.00018","0.09448"
"216.21600","18.01817","0.09689"
"216.43200","18.03617","0.09763"
"216.64800","18.05417","0.09866"
"216.86400","18.07216","0.10027"
"217.08000","18.09016","0.10099"
"217.29600","18.10816","0.10251"
"217.51200","18.12609","0.10374"
"217.72800","18.14421","0.00494"
"217.94400","18.16215","0.02989"
"218.16000","18.18020","0.00856"
"218.37600","18.19820","0.02743"
"218.59200","18.21620","0.01536"
"218.80800","18.23419","0.01745"
"219.02400","18.25219","0.02219"
"219.24000","18.27019","0.01488"
"219.45600","18.28824","0.02351"
"219.67200","18.30612","0.01628"
"219.88800","18.32424","0.02093"
"220.10400","18.34217","0.02035"
"220.32000","18.36017","0.01857"
"220.53600","18.37817","0.02296"
"220.75200","18.39610","0.01891"
"220.96800","18.41422","0.02118"
"221.18400","18.43222","0.02227"
"221.40000","18.45015","0.01907"
"221.61600","18.46821","0.02216"
"221.83200","18.48615","0.02265"
"222.04800","18.50420","0.02244"
"222.26400","18.52220","0.02177"
"222.48000","18.54014","0.02338"
"222.69600","18.55819","0.02258"
"222.91200","18.57613","0.02259"
"223.12800","18.59419","0.02416"
"223.34400","18.61218","0.02297"
"223.56000","18.63012","0.02448"
"223.77600","18.64818","0.02408"
"223.99200","18.66617","0.02345"
"224.20800","18.68423","0.02492"
"224.42400","18.70217","0.02472"
"224.64000","18.72016","0.02514"
"224.85600","18.73822","0.02611"
"225.07200","18.75616","0.02444"
"225.28800","18.77421","0.02599"
"225.50400","18.79215","0.02636"
"225.72000","18.81015","0.02584"
"225.93600","18.82820","0.02697"
"226.15200","18.84620","0.02619"
"226.36800","18.86426","0.02696"
"226.58400","18.88219","0.02803"
"226.80000","18.90013","0.02692"
"227.01600","18.91819","0.02745"
"227.23200","18.93618","0.02780"
"227.44800","18.95418","0.02813"
"227.66400","18.97212","0.02837"
"227.88000","18.99017","0.02822"
"228.09600","19.00817","0.02892"
"228.31200","19.02611","0.02940"
"228.52800","19.04422","0.02886"
"228.74400","19.06222","0.02938"
"228.96000","19.08022","0.02954"
"229.17600","19.09821","0.02994"
"229.39200","19.11609","0.03031"
"229.60800","19.13420","0.03010"
"229.82400","19.15220","0.03092"
"230.04000","19.17014","0.03051"
"230.25600","19.18826","0.03089"
"230.47200","19.20613","0.03132"
"230.68800","19.22419","0.03090"
"230.90400","19.24218","0.03136"
"231.12000","19.26012","0.03170"
"231.33600","19.27824","0.03169"
"231.55200","19.29612","0.03251"
"231.76800","19.31423","0.03231"
"231.98400","19.33217","0.03223"
"232.20000","19.35017","0.03273"
"232.41600","19.36822","0.03329"
"232.63200","19.38616","0.03352"
"232.84800","19.40421","0.03343"
"233.06400","19.42221","0.03349"
"233.28000","19.44015","0.03347"
"233.49600","19.45820","0.03388"
"233.71200","19.47614","0.03418"
"233.92800","19.49420","0.03453"
"234.14400","19.51220","0.03464"
"234.36000","19.53019","0.03501"
"234.57600","19.54819","0.03521"
"234.79200","19.56618","0.03578"
"235.00800","19.58418","0.03609"
"235.22400","19.60224","0.03587"
"235.44000","19.62017","0.03667"
"235.65600","19.63823","0.03711"
"235.87200","19.65611","0.03736"
"236.08800","19.67422","0.03785"
"236.30400","19.69216","0.03873"
"236.52000","19.71016","0.03888"
"236.73600","19.72815","0.03967"
"236.95200","19.74615","0.03979"
"237.16800","19.76415","0.04074"
"237.38400","19.78220","0.04138"
"237.60000","19.80020","0.04227"
"237.81600","19.81820","0.04312"
"238.03200","19.83607","0.04403"
"238.24800","19.85419","0.04415"
"238.46400","19.87213","0.04499"
"238.68000","19.89018","0.04571"
"238.89600","19.90818","0.04651"
"239.11200","19.92612","0.04780"
"239.32800","19.94417","0.04813"
"239.54400","19.96223","0.04946"
"239.76000","19.98017","0.05067"
"239.97600","19.99822","0.05193"
"240.19200","20.01610","0.05295"
"240.40800","20.03422","0.05282"
"240.62400","20.05215","0.05453"
"240.84000","20.07021","0.05546"
"241.05600","20.08821","0.05593"
"241.27200","20.10614","0.05674"
"241.48800","20.12420","0.05766"
"241.70400","20.14214","0.05864"
"241.92000","20.16019","0.05964"
"242.13600","20.17819","0.06027"
"242.35200","20.19613","0.06140"
"242.56800","20.21418","0.06190"
"242.78400","20.23218","0.05564"
"243.00000","20.25018","0.05657"
"243.21600","20.26817","0.05293"
"243.43200","20.28617","0.05628"
"243.64800","20.30416","0.05557"
"243.86400","20.32216","0.05674"
"244.08000","20.34016","0.05895"
"244.29600","20.35815","0.05860"
"244.51200","20.37615","0.06061"
"244.72800","20.39415","0.06075"
"244.94400","20.41215","0.06198"
"245.16000","20.43020","0.06345"
"245.37600","20.44820","0.06382"
"245.59200","20.46614","0.06515"
"245.80800","20.48419","0.06567"
"246.02400","20.50219","0.06636"
"246.24000","20.52024","0.06795"
"246.45600","20.53818","0.06839"
"246.67200","20.55612","0.07099"
"246.88800","20.57417","0.07150"
"247.10400","20.59217","0.07324"
"247.32000","20.61017","0.07384"
"247.53600","20.62823","0.07478"
"247.75200","20.64610","0.07678"
"247.96800","20.66422","0.07822"
"248.18400","20.68216","0.07986"
"248.40000","20.70021","0.08037"
"248.61600","20.71815","0.08214"
"248.83200","20.73615","0.08202"
"249.04800","20.75420","0.08317"
"249.26400","20.77214","0.08370"
"249.48000","20.79020","0.08406"
"249.69600","20.80819","0.08460"
"249.91200","20.82613","0.08484"
"250.12800","20.84425","0.08540"
"250.34400","20.86212","0.08534"
"250.56000","20.88024","0.08561"
"250.77600","20.89824","0.08630"
"250.99200","20.91617","0.08645"
"251.20800","20.93417","0.08687"
"251.42400","20.95217","0.08778"
"251.64000","20.97016","0.08867"
"251.85600","20.98822","0.08549"
"252.07200","21.00616","0.08685"
"252.28800","21.02421","0.08632"
"252.50400","21.04215","0.08833"
"252.72000","21.06020","0.08586"
"252.93600","21.07814","0.08790"
"253.15200","21.09614","0.08718"
"253.36800","21.11420","0.08864"
"253.58400","21.13219","0.08958"
"253.80000","21.15013","0.09086"
"254.01600","21.16825","0.09533"
"254.23200","21.18618","0.09280"
"254.44800","21.20424","0.09832"
"254.66400","21.22218","0.09850"
"254.88000","21.24023","0.10162"
"255.09600","21.25817","0.09835"
"255.31200","21.27622","0.10279"
"255.52800","21.29416","0.10319"
"255.74400","21.31216","0.10520"
"255.96000","21.33021","0.10670"
"256.17600","21.34821","0.10732"
"256.39200","21.36615","0.10951"
"256.60800","21.38420","0.11017"
"256.82400","21.40220","0.11277"
"257.04000","21.42020","0.11316"
"257.25600","21.43819","0.11450"
"257.47200","21.45619","0.11535"
"257.68800","21.47419","0.11619"
"257.90400","21.49212","0.11736"
"258.12000","21.51018","0.11767"
"258.33600","21.52818","0.11924"
"258.55200","21.54618","0.12018"
"258.76800","21.56423","0.12105"
"258.98400","21.58217","0.12158"
"259.20000","21.60022","0.12209"
"259.41600","21.61816","0.12291"
"259.63200","21.63616","0.12313"
"259.84800","21.65416","0.12420"
"260.06400","21.67215","0.12497"
"260.28000","21.69015","0.12569"
"260.49600","21.70821","0.12741"
"260.71200","21.72614","0.12769"
"260.92800","21.74420","0.12909"
"261.14400","21.76219","0.12958"
"261.36000","21.78025","0.13070"
"261.57600","21.79819","0.13124"
"261.79200","21.81612","0.13221"
"262.00800","21.83418","0.13311"
"262.22400","21.85218","0.13318"
"262.44000","21.87018","0.09039"
"262.65600","21.88817","0.06208"
"262.87200","21.90617","0.08581"
"263.08800","21.92416","0.06710"
"263.30400","21.94210","0.08446"
"263.52000","21.96022","0.07021"
"263.73600","21.97815","0.08291"
"263.95200","21.99615","0.07166"
"264.16800","22.01421","0.08413"
"264.38400","22.03208","0.07538"
"264.60000","22.05020","0.08474"
"264.81600","22.06820","0.07785"
"265.03200","22.08619","0.08423"
"265.24800","22.10419","0.08069"
"265.46400","22.12213","0.08414"
"265.68000","22.14018","0.08241"
"265.89600","22.15818","0.08477"
"266.11200","22.17618","0.08304"
"266.32800","22.19417","0.08539"
"266.54400","22.21211","0.08401"
"266.76000","22.23022","0.08549"
"266.97600","22.24816","0.08451"
"267.19200","22.26622","0.08591"
"267.40800","22.28422","0.08506"
"267.62400","22.30215","0.08600"
"267.84000","22.32015","0.08573"
"268.05600","22.33821","0.08640"
"268.27200","22.35614","0.08643"
"268.48800","22.37420","0.08671"
"268.70400","22.39214","0.08727"
"268.92000","22.41019","0.08708"
"269.13600","22.42819","0.08867"
"269.35200","22.44619","0.08816"
"269.56800","22.46418","0.09048"
"269.78400","22.48218","0.09002"
"270.00000","22.50018","0.09195"
"270.21600","22.51817","0.09180"
"270.43200","22.53617","0.09396"
"270.64800","22.55417","0.09292"
"270.86400","22.57210","0.09523"
"271.08000","22.59022","0.09424"
"271.29600","22.60810","0.09756"
"271.51200","22.62621","0.09706"
"271.72800","22.64421","0.09888"
"271.94400","22.66215","0.10034"
"272.16000","22.68014","0.09918"
"272.37600","22.69814","0.10229"
"272.59200","22.71620","0.10169"
"272.80800","22.73419","0.10379"
"273.02400","22.75207","0.10435"
"273.24000","22.77024","0.10621"
"273.45600","22.78812","0.10710"
"273.67200","22.80618","0.10727"
"273.88800","22.82424","0.10774"
"274.10400","22.84217","0.10823"
"274.32000","22.86017","0.11010"
"274.53600","22.87816","0.11045"
"274.75200","22.89616","0.11202"
"274.96800","22.91428","0.11268"
"275.18400","22.93210","0.11293"
"275.40000","22.95021","0.11406"
"275.61600","22.96815","0.11411"
"275.83200","22.98621","0.11462"
"276.04800","23.00420","0.11523"
"276.26400","23.02214","0.11619"
"276.48000","23.04014","0.11701"
"276.69600","23.05813","0.11744"
"276.91200","23.07619","0.11812"
"277.12800","23.09425","0.11878"
"277.34400","23.11212","0.11891"
"277.56000","23.13024","0.11943"
"277.77600","23.14817","0.11999"
"277.99200","23.16617","0.12039"
"278.20800","23.18417","0.12076"
"278.42400","23.20217","0.12105"
"278.64000","23.22016","0.12150"
"278.85600","23.23816","0.12129"
"279.07200","23.25616","0.12205"
"279.28800","23.27415","0.12231"
"279.50400","23.29215","0.12314"
"279.72000","23.31021","0.12329"
"279.93600","23.32814","0.12269"
"280.15200","23.34626","0.12393"
"280.36800","23.36419","0.12461"
"280.58400","23.38219","0.12498"
"280.80000","23.40019","0.12498"
"281.01600","23.41813","0.12615"
"281.23200","23.43618","0.12673"
"281.44800","23.45418","0.12710"
"281.66400","23.47211","0.12744"
"281.88000","23.49017","0.12853"
"282.09600","23.50817","0.12897"
"282.31200","23.52622","0.12920"
"282.52800","23.54416","0.12989"
"282.74400","23.56216","0.13044"
"282.96000","23.58021","0.13123"
"283.17600","23.59815","0.13163"
"283.39200","23.61615","0.13187"
"283.60800","23.63415","0.13219"
"283.82400","23.65214","0.13303"
"284.04000","23.67020","0.13302"
"284.25600","23.68813","0.13387"
"284.47200","23.70619","0.13406"
"284.68800","23.72419","0.13446"
"284.90400","23.74219","0.13532"
"285.12000","23.76018","0.13582"
"285.33600","23.77812","0.13622"
"285.55200","23.79618","0.13248"
"285.76800","23.81417","0.13300"
"285.98400","23.83217","0.13217"
"286.20000","23.85016","0.13177"
"286.41600","23.86816","0.13366"
"286.63200","23.88622","0.13201"
"286.84800","23.90421","0.13438"
"287.06400","23.92215","0.13321"
"287.28000","23.94020","0.13411"
"287.49600","23.95814","0.13476"
"287.71200","23.97620","0.13382"
"287.92800","23.99414","0.13564"
"288.14400","24.01220","0.13498"
"288.36000","24.03019","0.13581"
"288.57600","24.04813","0.13608"
"288.79200","24.06618","0.13588"
"289.00800","24.08418","0.13749"
"289.22400","24.10218","0.13694"
"289.44000","24.12017","0.13809"
"289.65600","24.13811","0.13863"
"289.87200","24.15623","0.13909"
"290.08800","24.17416","0.13947"
"290.30400","24.19222","0.14016"
"290.52000","24.21016","0.14060"
"290.73600","24.22815","0.14111"
"290.95200","24.24621","0.14149"
"291.16800","24.26421","0.14206"
"291.38400","24.28214","0.14210"
"291.60000","24.30020","0.14323"
"291.81600","24.31808","0.14366"
"292.03200","24.33625","0.14469"
"292.24800","24.35413","0.14525"
"292.46400","24.37219","0.14584"
"292.68000","24.39018","0.14640"
"292.89600","24.40818","0.14765"
"293.11200","24.42618","0.14825"
"293.32800","24.44417","0.14928"
"293.54400","24.46223","0.15120"
"293.76000","24.48022","0.15251"
"293.97600","24.49810","0.15364"
"294.19200","24.51622","0.15481"
"294.40800","24.53416","0.15564"
"294.62400","24.55215","0.15703"
"294.84000","24.57021","0.15893"
"295.05600","24.58821","0.16036"
"295.27200","24.60614","0.16058"
"295.48800","24.62420","0.16370"
"295.70400","24.64220","0.16516"
"295.92000","24.66025","0.16546"
"296.13600","24.67813","0.16720"
"296.35200","24.69625","0.16864"
"296.56800","24.71412","0.17046"
"296.78400","24.73218","0.17187"
"297.00000","24.75018","0.17319"
"297.21600","24.76817","0.17476"
"297.43200","24.78617","0.17490"
"297.64800","24.80416","0.17694"
"297.86400","24.82216","0.17811"
"298.08000","24.84016","0.17938"
"298.29600","24.85810","0.18027"
"298.51200","24.87615","0.18167"
"298.72800","24.89415","0.18217"
"298.94400","24.91221","0.18298"
"299.16000","24.93020","0.18418"
"299.37600","24.94814","0.18469"
"299.59200","24.96614","0.18524"
"299.80800","24.98419","0.18559"
"300.02400","25.00213","0.18660"
"300.24000","25.02019","0.18685"
"300.45600","25.03812","0.18719"
"300.67200","25.05618","0.18767"
"300.88800","25.07417","0.18807"
"301.10400","25.09217","0.18796"
"301.32000","25.11023","0.18837"
"301.53600","25.12817","0.18875"
"301.75200","25.14616","0.18902"
"301.96800","25.16416","0.18933"
"302.18400","25.18210","0.18946"
"302.40000","25.20015","0.18989"
"302.61600","25.21809","0.18998"
"302.83200","25.23621","0.19069"
"303.04800","25.25420","0.19104"
"303.26400","25.27220","0.19173"
"303.48000","25.29020","0.19238"
"303.69600","25.30813","0.19259"
"303.91200","25.32619","0.19315"
"304.12800","25.34418","0.19358"
"304.34400","25.36218","0.19404"
"304.56000","25.38012","0.19541"
"304.77600","25.39812","0.19569"
"304.99200","25.41623","0.19723"
"305.20800","25.43417","0.19783"
"305.42400","25.45217","0.19933"
"305.64000","25.47022","0.20020"
"305.85600","25.48816","0.20111"
"306.07200","25.50615","0.20225"
"306.28800","25.52415","0.20362"
"306.50400","25.54221","0.20472"
"306.72000","25.56015","0.20623"
"306.93600","25.57808","0.20599"
"307.15200","25.59620","0.20819"
"307.36800","25.61414","0.20898"
"307.58400","25.63225","0.20940"
"307.80000","25.65019","0.21055"
"308.01600","25.66813","0.21191"
"308.23200","25.68624","0.21278"
"308.44800","25.70418","0.21334"
"308.66400","25.72218","0.21399"
"308.88000","25.74017","0.21529"
"309.09600","25.75817","0.21587"
"309.31200","25.77617","0.21633"
"309.52800","25.79416","0.21793"
"309.74400","25.81222","0.21855"
"309.96000","25.83021","0.21948"
"310.17600","25.84815","0.21997"
"310.39200","25.86621","0.22106"
"310.60800","25.88420","0.22244"
"310.82400","25.90220","0.22238"
"311.04000","25.92014","0.22293"
"311.25600","25.93819","0.22407"
"311.47200","25.95619","0.22434"
"311.68800","25.97419","0.22565"
"311.90400","25.99219","0.22596"
"312.12000","26.01018","0.22659"
"312.33600","26.02818","0.22763"
"312.55200","26.04623","0.22816"
"312.76800","26.06417","0.22887"
"312.98400","26.08223","0.22940"
"313.20000","26.10010","0.23006"
"313.41600","26.11816","0.23029"
"313.63200","26.13616","0.23093"
"313.84800","26.15416","-0.00860"
"314.06400","26.17221","-0.01715"
"314.28000","26.19015","-0.00032"
"314.49600","26.20820","-0.00340"
"314.71200","26.22620","-0.00904"
"314.92800","26.24408","-0.00689"
"315.14400","26.26225","-0.00526"
"315.36000","26.28013","-0.00347"
"315.57600","26.29819","-0.00446"
"315.79200","26.31618","-0.00609"
"316.00800","26.33418","-0.00542"
"316.22400","26.35218","-0.00423"
"316.44000","26.37023","-0.00353"
"316.65600","26.38811","-0.00495"
"316.87200","26.40623","-0.00508"
"317.08800","26.42416","-0.00587"
"317.10200","26.42530","-0.00586"