File: Force_trajectories/170122_1/Specimen_RawData_5.csv
End date,"1/22/2017"
Specimen label,"18BG_43"
Maximum Load,"0.06172",N

Time,Extension,Load
(s),(mm),(N)
"0.00000","0.00000","-0.00022"
"0.34800","0.02906","0.00067"
"0.69600","0.05824","0.00167"
"1.04400","0.08729","0.00174"
"1.39200","0.11617","0.00226"
"1.74000","0.14523","0.00231"
"2.08800","0.17429","0.00333"
"2.43600","0.20322","0.00400"
"2.78400","0.23222","0.00350"
"3.13200","0.26122","0.00433"
"3.48000","0.29022","0.00425"
"3.82800","0.31922","0.00477"
"4.17600","0.34827","0.00483"
"4.52400","0.37721","0.00509"
"4.87200","0.40621","0.00512"
"5.22000","0.43521","0.00574"
"5.56800","0.46421","0.00650"
"5.91600","0.49320","0.00685"
"6.26400","0.52220","0.00668"
"6.61200","0.55120","0.00686"
"6.96000","0.58020","0.00745"
"7.30800","0.60920","0.00695"
"7.65600","0.63819","0.00773"
"8.00400","0.66719","0.00747"
"8.35200","0.69619","0.00793"
"8.70000","0.72525","0.00766"
"9.04800","0.75430","0.00767"
"9.39600","0.78318","0.00869"
"9.74400","0.81218","0.00835"
"10.09200","0.84124","0.00882"
"10.44000","0.87012","0.00871"
"10.78800","0.89929","0.00874"
"11.13600","0.92823","0.00908"
"11.48400","0.95723","0.00882"
"11.83200","0.98629","0.00941"
"12.18000","1.01523","0.00917"
"12.52800","1.04422","0.00941"
"12.87600","1.07322","0.00960"
"13.22400","1.10222","0.00966"
"13.57200","1.13122","0.01027"
"13.92000","1.16022","0.00992"
"14.26800","1.18921","0.00997"
"14.61600","1.21821","0.01084"
"14.96400","1.24727","0.01113"
"15.31200","1.27615","0.01157"
"15.66000","1.30527","0.01133"
"16.00800","1.33426","0.01055"
"16.35600","1.36320","0.01058"
"16.70400","1.39220","0.01070"
"17.05200","1.42120","0.01130"
"17.40000","1.45020","0.01099"
"17.74800","1.47925","0.01122"
"18.09600","1.50825","0.01051"
"18.44400","1.53719","0.01084"
"18.79200","1.56625","0.01138"
"19.14000","1.59518","0.01109"
"19.48800","1.62418","0.01114"
"19.83600","1.65330","0.01171"
"20.18400","1.68218","0.01117"
"20.53200","1.71124","0.01094"
"20.88000","1.74023","0.01178"
"21.22800","1.76917","0.01204"
"21.57600","1.79823","0.01287"
"21.92400","1.82729","0.01194"
"22.27200","1.85623","0.01246"
"22.62000","1.88522","0.01307"
"22.96800","1.91422","0.01299"
"23.31600","1.94316","0.01294"
"23.66400","1.97228","0.01313"
"24.01200","2.00122","0.01265"
"24.36000","2.03015","0.01318"
"24.70800","2.05927","0.01345"
"25.05600","2.08821","0.01359"
"25.40400","2.11721","0.01320"
"25.75200","2.14621","0.01346"
"26.10000","2.17520","0.01406"
"26.44800","2.20426","0.01351"
"26.79600","2.23326","0.01379"
"27.14400","2.26220","0.01341"
"27.49200","2.29125","0.01373"
"27.84000","2.32031","0.01317"
"28.18800","2.34919","0.01368"
"28.53600","2.37819","0.01365"
"28.88400","2.40719","0.01375"
"29.23200","2.43618","0.01451"
"29.58000","2.46530","0.01491"
"29.92800","2.49424","0.01415"
"30.27600","2.52324","0.01464"
"30.62400","2.55224","0.01548"
"30.97200","2.58117","0.01496"
"31.32000","2.61023","0.01504"
"31.66800","2.63923","0.01590"
"32.01600","2.66823","0.01530"
"32.36400","2.69717","0.01553"
"32.71200","2.72622","0.01564"
"33.06000","2.75516","0.01566"
"33.40800","2.78422","0.01561"
"33.75600","2.81334","0.01542"
"34.10400","2.84216","0.01596"
"34.45200","2.87127","0.01675"
"34.80000","2.90027","0.01683"
"35.14800","2.92921","0.01676"
"35.49600","2.95827","0.01681"
"35.84400","2.98720","0.01683"
"36.19200","3.01620","0.01668"
"36.54000","3.04526","0.01738"
"36.88800","3.07420","0.01760"
"37.23600","3.10320","0.01863"
"37.58400","3.13219","0.01793"
"37.93200","3.16119","0.01795"
"38.28000","3.19025","0.01772"
"38.62800","3.21925","0.01885"
"38.97600","3.24819","0.01816"
"39.32400","3.27724","0.01898"
"39.67200","3.30624","0.01906"
"40.02000","3.33518","0.01936"
"40.36800","3.36424","0.01957"
"40.71600","3.39324","0.01988"
"41.06400","3.42223","0.01987"
"41.41200","3.45123","0.02029"
"41.76000","3.48023","0.02020"
"42.10800","3.50923","0.02018"
"42.45600","3.53822","0.02108"
"42.80400","3.56722","0.02112"
"43.15200","3.59616","0.02071"
"43.50000","3.62528","0.02016"
"43.84800","3.65416","0.02092"
"44.19600","3.68321","0.02090"
"44.54400","3.71221","0.02080"
"44.89200","3.74115","0.02112"
"45.24000","3.77027","0.02094"
"45.58800","3.79927","0.02099"
"45.93600","3.82814","0.02177"
"46.28400","3.85726","0.02140"
"46.63200","3.88620","0.02136"
"46.98000","3.91520","0.02178"
"47.32800","3.94426","0.02215"
"47.67600","3.97325","0.02153"
"48.02400","4.00219","0.02218"
"48.37200","4.03125","0.02221"
"48.72000","4.06019","0.02312"
"49.06800","4.08919","0.02245"
"49.41600","4.11824","0.02316"
"49.76400","4.14718","0.02325"
"50.11200","4.17624","0.02270"
"50.46000","4.20524","0.02289"
"50.80800","4.23418","0.02401"
"51.15600","4.26317","0.02380"
"51.50400","4.29223","0.02391"
"51.85200","4.32117","0.02366"
"52.20000","4.35023","0.02413"
"52.54800","4.37922","0.02443"
"52.89600","4.40816","0.02368"
"53.24400","4.43728","0.02473"
"53.59200","4.46622","0.02460"
"53.94000","4.49516","0.02527"
"54.28800","4.52427","0.02528"
"54.63600","4.55321","0.02553"
"54.98400","4.58227","0.02594"
"55.33200","4.61121","0.02605"
"55.68000","4.64021","0.02567"
"56.02800","4.66920","0.02593"
"56.37600","4.69826","0.02656"
"56.72400","4.72720","0.02639"
"57.07200","4.75626","0.02678"
"57.42000","4.78526","0.02715"
"57.76800","4.81419","0.02712"
"58.11600","4.84325","0.02764"
"58.46400","4.87219","0.02695"
"58.81200","4.90119","0.02734"
"59.16000","4.93024","0.02774"
"59.50800","4.95924","0.02774"
"59.85600","4.98824","0.02783"
"60.20400","5.01724","0.02791"
"60.55200","5.04624","0.02792"
"60.90000","5.07523","0.02831"
"61.24800","5.10423","0.02842"
"61.59600","5.13323","0.02877"
"61.94400","5.16223","0.02857"
"62.29200","5.19123","0.02878"
"62.64000","5.22016","0.02856"
"62.98800","5.24928","0.02876"
"63.33600","5.27822","0.02907"
"63.68400","5.30716","0.02899"
"64.03200","5.33628","0.02908"
"64.38000","5.36521","0.02948"
"64.72800","5.39427","0.02905"
"65.07600","5.42321","0.02954"
"65.42400","5.45221","0.02995"
"65.77200","5.48121","0.03006"
"66.12000","5.51020","0.02992"
"66.46800","5.53920","0.02998"
"66.81600","5.56820","0.02969"
"67.16400","5.59720","0.03049"
"67.51200","5.62614","0.02935"
"67.86000","5.65525","0.03049"
"68.20800","5.68431","0.03036"
"68.55600","5.71313","0.02978"
"68.90400","5.74225","0.03082"
"69.25200","5.77125","0.03080"
"69.60000","5.80018","0.03124"
"69.94800","5.82924","0.03116"
"70.29600","5.85818","0.03142"
"70.64400","5.88718","0.03123"
"70.99200","5.91623","0.03182"
"71.34000","5.94523","0.03161"
"71.68800","5.97417","0.03155"
"72.03600","6.00329","0.03187"
"72.38400","6.03223","0.03208"
"72.73200","6.06122","0.03221"
"73.08000","6.09028","0.03251"
"73.42800","6.11916","0.03269"
"73.77600","6.14822","0.03265"
"74.12400","6.17722","0.03257"
"74.47200","6.20615","0.03285"
"74.82000","6.23521","0.03326"
"75.16800","6.26427","0.03319"
"75.51600","6.29321","0.03349"
"75.86400","6.32220","0.03331"
"76.21200","6.35126","0.03346"
"76.56000","6.38014","0.03383"
"76.90800","6.40926","0.03412"
"77.25600","6.43826","0.03367"
"77.60400","6.46719","0.03415"
"77.95200","6.49625","0.03338"
"78.30000","6.52519","0.03340"
"78.64800","6.55425","0.03412"
"78.99600","6.58325","0.03398"
"79.34400","6.61218","0.03396"
"79.69200","6.64124","0.03423"
"80.04000","6.67024","0.03425"
"80.38800","6.69924","0.03402"
"80.73600","6.72824","0.03403"
"81.08400","6.75723","0.03392"
"81.43200","6.78617","0.03412"
"81.78000","6.81523","0.03454"
"82.12800","6.84423","0.03462"
"82.47600","6.87323","0.03485"
"82.82400","6.90228","0.03511"
"83.17200","6.93122","0.03491"
"83.52000","6.96022","0.03519"
"83.86800","6.98922","0.03506"
"84.21600","7.01822","0.03512"
"84.56400","7.04721","0.03475"
"84.91200","7.07621","0.03471"
"85.26000","7.10521","0.03574"
"85.60800","7.13427","0.03546"
"85.95600","7.16326","0.03558"
"86.30400","7.19214","0.03575"
"86.65200","7.22120","0.03576"
"87.00000","7.25026","0.03593"
"87.34800","7.27920","0.03622"
"87.69600","7.30825","0.03572"
"88.04400","7.33719","0.03640"
"88.39200","7.36619","0.03638"
"88.74000","7.39525","0.03652"
"89.08800","7.42419","0.03638"
"89.43600","7.45324","0.03610"
"89.78400","7.48218","0.03608"
"90.13200","7.51118","0.03661"
"90.48000","7.54024","0.03683"
"90.82800","7.56924","0.03672"
"91.17600","7.59817","0.03688"
"91.52400","7.62723","0.03686"
"91.87200","7.65629","0.03708"
"92.22000","7.68517","0.03707"
"92.56800","7.71422","0.03693"
"92.91600","7.74322","0.03716"
"93.26400","7.77216","0.03691"
"93.61200","7.80128","0.03702"
"93.96000","7.83022","0.03720"
"94.30800","7.85921","0.03731"
"94.65600","7.88821","0.03755"
"95.00400","7.91721","0.03747"
"95.35200","7.94621","0.03745"
"95.70000","7.97521","0.03770"
"96.04800","8.00426","0.03784"
"96.39600","8.03320","0.03795"
"96.74400","8.06226","0.03765"
"97.09200","8.09120","0.03815"
"97.44000","8.12026","0.03827"
"97.78800","8.14925","0.03822"
"98.13600","8.17819","0.03809"
"98.48400","8.20725","0.03830"
"98.83200","8.23625","0.03837"
"99.18000","8.26519","0.03817"
"99.52800","8.29424","0.00423"
"99.87600","8.32324","0.01004"
"100.22400","8.35224","0.00979"
"100.57200","8.38118","0.01164"
"100.92000","8.41018","0.00940"
"101.26800","8.43917","0.00998"
"101.61600","8.46823","0.01199"
"101.96400","8.49717","0.00990"
"102.31200","8.52623","0.01070"
"102.66000","8.55528","0.01172"
"103.00800","8.58416","0.01002"
"103.35600","8.61328","0.01081"
"103.70400","8.64222","0.01204"
"104.05200","8.67116","0.01040"
"104.40000","8.70021","0.01168"
"104.74800","8.72921","0.01218"
"105.09600","8.75821","0.01098"
"105.44400","8.78727","0.01166"
"105.79200","8.81627","0.01232"
"106.14000","8.84520","0.01153"
"106.48800","8.87426","0.01199"
"106.83600","8.90320","0.01175"
"107.18400","8.93220","0.01202"
"107.53200","8.96126","0.01233"
"107.88000","8.99013","0.01221"
"108.22800","9.01925","0.01206"
"108.57600","9.04819","0.01290"
"108.92400","9.07719","0.01261"
"109.27200","9.10625","0.01208"
"109.62000","9.13524","0.01247"
"109.96800","9.16424","0.01221"
"110.31600","9.19324","0.01247"
"110.66400","9.22224","0.01276"
"111.01200","9.25123","0.01186"
"111.36000","9.28023","0.01295"
"111.70800","9.30923","0.01259"
"112.05600","9.33823","0.01277"
"112.40400","9.36723","0.01288"
"112.75200","9.39616","0.01300"
"113.10000","9.42528","0.01306"
"113.44800","9.45422","0.01325"
"113.79600","9.48316","0.01354"
"114.14400","9.51228","0.01351"
"114.49200","9.54127","0.01353"
"114.84000","9.57021","0.01418"
"115.18800","9.59921","0.01450"
"115.53600","9.62827","0.01364"
"115.88400","9.65720","0.01401"
"116.23200","9.68626","0.01331"
"116.58000","9.71520","0.01412"
"116.92800","9.74420","0.01395"
"117.27600","9.77332","0.01289"
"117.62400","9.80219","0.01328"
"117.97200","9.83119","0.01351"
"118.32000","9.86025","0.01308"
"118.66800","9.88925","0.01339"
"119.01600","9.91825","0.01351"
"119.36400","9.94718","0.01391"
"119.71200","9.97618","0.01409"
"120.06000","10.00518","0.01497"
"120.40800","10.03430","0.01471"
"120.75600","10.06312","0.01389"
"121.10400","10.09223","0.01393"
"121.45200","10.12123","0.01460"
"121.80000","10.15023","0.01443"
"122.14800","10.17923","0.01428"
"122.49600","10.20817","0.01483"
"122.84400","10.23722","0.01512"
"123.19200","10.26628","0.01489"
"123.54000","10.29522","0.01535"
"123.88800","10.32428","0.01548"
"124.23600","10.35322","0.01506"
"124.58400","10.38221","0.01486"
"124.93200","10.41121","0.01590"
"125.28000","10.44027","0.01509"
"125.62800","10.46921","0.01576"
"125.97600","10.49820","0.01581"
"126.32400","10.52726","0.01612"
"126.67200","10.55614","0.01650"
"127.02000","10.58520","0.01610"
"127.36800","10.61426","0.01602"
"127.71600","10.64319","0.01603"
"128.06400","10.67225","0.01594"
"128.41200","10.70125","0.01598"
"128.76000","10.73019","0.01648"
"129.10800","10.75925","0.01659"
"129.45600","10.78824","0.01695"
"129.80400","10.81724","0.01662"
"130.15200","10.84624","0.01737"
"130.50000","10.87518","0.01678"
"130.84800","10.90418","0.01663"
"131.19600","10.93323","0.01654"
"131.54400","10.96217","0.01704"
"131.89200","10.99129","0.01676"
"132.24000","11.02023","0.01735"
"132.58800","11.04917","0.01728"
"132.93600","11.07828","0.01772"
"133.28400","11.10722","0.01777"
"133.63200","11.13622","0.01867"
"133.98000","11.16522","0.01860"
"134.32800","11.19421","0.01861"
"134.67600","11.22321","0.01819"
"135.02400","11.25221","0.01846"
"135.37200","11.28121","0.01881"
"135.72000","11.31021","0.01862"
"136.06800","11.33926","0.01953"
"136.41600","11.36820","0.01962"
"136.76400","11.39726","0.01982"
"137.11200","11.42620","0.01927"
"137.46000","11.45514","0.01945"
"137.80800","11.48425","0.02061"
"138.15600","11.51325","0.02048"
"138.50400","11.54219","0.02008"
"138.85200","11.57125","0.02050"
"139.20000","11.60019","0.01996"
"139.54800","11.62918","0.02043"
"139.89600","11.65830","0.02059"
"140.24400","11.68724","0.02024"
"140.59200","11.71618","0.02110"
"140.94000","11.74530","0.02104"
"141.28800","11.77423","0.02097"
"141.63600","11.80323","0.02160"
"141.98400","11.83223","0.02163"
"142.33200","11.86123","0.02259"
"142.68000","11.89022","0.02246"
"143.02800","11.91922","0.02235"
"143.37600","11.94822","0.02215"
"143.72400","11.97722","0.02185"
"144.07200","12.00628","0.02224"
"144.42000","12.03515","0.02240"
"144.76800","12.06427","0.02241"
"145.11600","12.09327","0.02243"
"145.46400","12.12215","0.02255"
"145.81200","12.15127","0.02296"
"146.16000","12.18020","0.02334"
"146.50800","12.20920","0.02301"
"146.85600","12.23826","0.02285"
"147.20400","12.26720","0.02312"
"147.55200","12.29626","0.02371"
"147.90000","12.32519","0.02288"
"148.24800","12.35419","0.02356"
"148.59600","12.38319","0.02373"
"148.94400","12.41225","0.02432"
"149.29200","12.44125","0.02325"
"149.64000","12.47024","0.02290"
"149.98800","12.49924","0.02388"
"150.33600","12.52818","0.02361"
"150.68400","12.55724","0.02373"
"151.03200","12.58623","0.02266"
"151.38000","12.61523","0.02315"
"151.72800","12.64429","0.02366"
"152.07600","12.67323","0.02374"
"152.42400","12.70223","0.02287"
"152.77200","12.73123","0.02323"
"153.12000","12.76022","0.02362"
"153.46800","12.78922","0.02331"
"153.81600","12.81822","0.02341"
"154.16400","12.84722","0.02417"
"154.51200","12.87621","0.02454"
"154.86000","12.90527","0.02454"
"155.20800","12.93409","0.02426"
"155.55600","12.96327","0.02527"
"155.90400","12.99227","0.02489"
"156.25200","13.02114","0.02535"
"156.60000","13.05026","0.02470"
"156.94800","13.07920","0.02537"
"157.29600","13.10826","0.02516"
"157.64400","13.13725","0.02606"
"157.99200","13.16619","0.02553"
"158.34000","13.19519","0.02513"
"158.68800","13.22419","0.02566"
"159.03600","13.25325","0.02429"
"159.38400","13.28224","0.02349"
"159.73200","13.31124","0.02364"
"160.08000","13.34018","0.02382"
"160.42800","13.36924","0.02168"
"160.77600","13.39824","0.02124"
"161.12400","13.42712","0.02111"
"161.47200","13.45623","0.02004"
"161.82000","13.48523","0.02036"
"162.16800","13.51417","0.02045"
"162.51600","13.54323","0.02288"
"162.86400","13.57228","0.02281"
"163.21200","13.60116","0.02185"
"163.56000","13.63028","0.02177"
"163.90800","13.65928","0.02090"
"164.25600","13.68822","0.02091"
"164.60400","13.71727","0.02020"
"164.95200","13.74615","0.01899"
"165.30000","13.77521","0.01875"
"165.64800","13.80421","0.01857"
"165.99600","13.83315","0.01993"
"166.34400","13.86226","0.01995"
"166.69200","13.89120","0.01987"
"167.04000","13.92020","0.02010"
"167.38800","13.94926","0.02009"
"167.73600","13.97826","0.02097"
"168.08400","14.00719","0.02058"
"168.43200","14.03619","0.02098"
"168.78000","14.06525","0.02137"
"169.12800","14.09419","0.02113"
"169.47600","14.12325","0.02180"
"169.82400","14.15218","0.02222"
"170.17200","14.18124","0.02213"
"170.52000","14.21024","0.02223"
"170.86800","14.23924","0.02271"
"171.21600","14.26823","0.02301"
"171.56400","14.29723","0.02321"
"171.91200","14.32623","0.02328"
"172.26000","14.35523","0.02342"
"172.60800","14.38429","0.02326"
"172.95600","14.41317","0.02335"
"173.30400","14.44222","0.02305"
"173.65200","14.47128","0.02346"
"174.00000","14.50016","0.02331"
"174.34800","14.52927","0.02421"
"174.69600","14.55827","0.02434"
"175.04400","14.58721","0.02444"
"175.39200","14.61627","0.02486"
"175.74000","14.64521","0.02476"
"176.08800","14.67421","0.02474"
"176.43600","14.70320","0.02497"
"176.78400","14.73220","0.02499"
"177.13200","14.76126","0.02461"
"177.48000","14.79026","0.02590"
"177.82800","14.81920","0.02549"
"178.17600","14.84819","0.02617"
"178.52400","14.87725","0.02618"
"178.87200","14.90619","0.02614"
"179.22000","14.93525","0.02659"
"179.56800","14.96424","0.02700"
"179.91600","14.99318","0.02680"
"180.26400","15.02224","0.02735"
"180.61200","15.05124","0.02756"
"180.96000","15.08024","0.02728"
"181.30800","15.10923","0.02739"
"181.65600","15.13823","0.02751"
"182.00400","15.16723","0.02814"
"182.35200","15.19623","0.02846"
"182.70000","15.22523","0.02875"
"183.04800","15.25422","0.02872"
"183.39600","15.28328","0.02879"
"183.74400","15.31216","0.02928"
"184.09200","15.34122","0.02916"
"184.44000","15.37022","0.02958"
"184.78800","15.39915","0.02957"
"185.13600","15.42827","0.02976"
"185.48400","15.45721","0.03033"
"185.83200","15.48621","0.02993"
"186.18000","15.51521","0.03067"
"186.52800","15.54426","0.03100"
"186.87600","15.57320","0.03070"
"187.22400","15.60220","0.03111"
"187.57200","15.63126","0.03144"
"187.92000","15.66019","0.03129"
"188.26800","15.68925","0.03168"
"188.61600","15.71819","0.03178"
"188.96400","15.74719","0.03216"
"189.31200","15.77625","0.03193"
"189.66000","15.80512","0.03235"
"190.00800","15.83424","0.03260"
"190.35600","15.86330","0.03263"
"190.70400","15.89218","0.03231"
"191.05200","15.92124","0.03302"
"191.40000","15.95017","0.03325"
"191.74800","15.97917","0.03326"
"192.09600","16.00829","0.03377"
"192.44400","16.03723","0.03389"
"192.79200","16.06616","0.03378"
"193.14000","16.09522","0.03413"
"193.48800","16.12422","0.03449"
"193.83600","16.15322","0.03424"
"194.18400","16.18222","0.03459"
"194.53200","16.21121","0.03471"
"194.88000","16.24027","0.03450"
"195.22800","16.26927","0.03489"
"195.57600","16.29821","0.03479"
"195.92400","16.32721","0.03497"
"196.27200","16.35620","0.03488"
"196.62000","16.38520","0.03510"
"196.96800","16.41426","0.03547"
"197.31600","16.44326","0.03509"
"197.66400","16.47214","0.03519"
"198.01200","16.50125","0.03541"
"198.36000","16.53025","0.03597"
"198.70800","16.55919","0.03553"
"199.05600","16.58831","0.03603"
"199.40400","16.61718","0.03608"
"199.75200","16.64618","0.03604"
"200.10000","16.67524","0.02469"
"200.44800","16.70418","0.02233"
"200.79600","16.73330","0.02193"
"201.14400","16.76217","0.02159"
"201.49200","16.79123","0.02556"
"201.84000","16.82023","0.02746"
"202.18800","16.84929","0.02379"
"202.53600","16.87823","0.02442"
"202.88400","16.90722","0.02562"
"203.23200","16.93622","0.02506"
"203.58000","16.96522","0.02773"
"203.92800","16.99422","0.02699"
"204.27600","17.02321","0.02596"
"204.62400","17.05221","0.02723"
"204.97200","17.08121","0.02706"
"205.32000","17.11021","0.02798"
"205.66800","17.13921","0.02912"
"206.01600","17.16821","0.02845"
"206.36400","17.19720","0.02829"
"206.71200","17.22620","0.02903"
"207.06000","17.25526","0.02920"
"207.40800","17.28414","0.02940"
"207.75600","17.31326","0.02977"
"208.10400","17.34231","0.02986"
"208.45200","17.37119","0.02940"
"208.80000","17.40025","0.01371"
"209.14800","17.42925","0.01544"
"209.49600","17.45819","0.01379"
"209.84400","17.48724","0.01424"
"210.19200","17.51618","0.01409"
"210.54000","17.54518","0.01283"
"210.88800","17.57424","0.01520"
"211.23600","17.60317","0.01320"
"211.58400","17.63223","0.01461"
"211.93200","17.66123","0.01428"
"212.28000","17.69023","0.01398"
"212.62800","17.71923","0.01505"
"212.97600","17.74828","0.01445"
"213.32400","17.77716","0.01445"
"213.67200","17.80628","0.01480"
"214.02000","17.83528","0.01461"
"214.36800","17.86416","0.01531"
"214.71600","17.89321","0.01496"
"215.06400","17.92227","0.01555"
"215.41200","17.95115","0.01586"
"215.76000","17.98021","0.01514"
"216.10800","18.00920","0.01624"
"216.45600","18.03820","0.01586"
"216.80400","18.06720","0.01596"
"217.15200","18.09620","0.01511"
"217.50000","18.12520","0.01543"
"217.84800","18.15425","0.01428"
"218.19600","18.18319","0.01476"
"218.54400","18.21225","0.01560"
"218.89200","18.24119","0.01527"
"219.24000","18.27013","0.01491"
"219.58800","18.29924","0.01555"
"219.93600","18.32824","0.01590"
"220.28400","18.35724","0.01507"
"220.63200","18.38624","0.01577"
"220.98000","18.41524","0.01568"
"221.32800","18.44423","0.01607"
"221.67600","18.47323","0.01384"
"222.02400","18.50223","0.01525"
"222.37200","18.53117","0.01493"
"222.72000","18.56022","0.01502"
"223.06800","18.58922","0.01546"
"223.41600","18.61822","0.01487"
"223.76400","18.64722","0.01494"
"224.11200","18.67616","0.01482"
"224.46000","18.70522","0.01548"
"224.80800","18.73421","0.01591"
"225.15600","18.76327","0.01565"
"225.50400","18.79221","0.01584"
"225.85200","18.82127","0.01585"
"226.20000","18.85021","0.01638"
"226.54800","18.87926","0.01620"
"226.89600","18.90820","0.01614"
"227.24400","18.93720","0.01659"
"227.59200","18.96626","0.01646"
"227.94000","18.99525","0.01644"
"228.28800","19.02425","0.01656"
"228.63600","19.05325","0.01696"
"228.98400","19.08219","0.01638"
"229.33200","19.11125","0.01662"
"229.68000","19.14018","0.01653"
"230.02800","19.16924","0.01735"
"230.37600","19.19818","0.01689"
"230.72400","19.22718","0.01737"
"231.07200","19.25618","0.01710"
"231.42000","19.28523","0.01741"
"231.76800","19.31429","0.01784"
"232.11600","19.34323","0.01778"
"232.46400","19.37223","0.01645"
"232.81200","19.40123","0.01619"
"233.16000","19.43016","0.01655"
"233.50800","19.45928","0.01719"
"233.85600","19.48822","0.01742"
"234.20400","19.51722","0.01654"
"234.55200","19.54622","0.01581"
"234.90000","19.57521","0.01542"
"235.24800","19.60421","0.01637"
"235.59600","19.63327","0.01598"
"235.94400","19.66220","0.01600"
"236.29200","19.69126","0.01588"
"236.64000","19.72026","0.01613"
"236.98800","19.74914","0.01651"
"237.33600","19.77820","0.01666"
"237.68400","19.80720","0.01633"
"238.03200","19.83619","0.01669"
"238.38000","19.86525","0.01755"
"238.72800","19.89425","0.01705"
"239.07600","19.92325","0.01752"
"239.42400","19.95225","0.01749"
"239.77200","19.98125","0.01732"
"240.12000","20.01024","0.01734"
"240.46800","20.03924","0.01787"
"240.81600","20.06824","0.01818"
"241.16400","20.09718","0.01839"
"241.51200","20.12629","0.01885"
"241.86000","20.15511","0.01839"
"242.20800","20.18423","0.01876"
"242.55600","20.21329","0.01885"
"242.90400","20.24217","0.01885"
"243.25200","20.27122","0.01922"
"243.60000","20.30022","0.01966"
"243.94800","20.32922","0.01932"
"244.29600","20.35828","0.01994"
"244.64400","20.38721","0.01956"
"244.99200","20.41621","0.02063"
"245.34000","20.44521","0.01992"
"245.68800","20.47421","0.02034"
"246.03600","20.50321","0.02044"
"246.38400","20.53226","0.02024"
"246.73200","20.56120","0.02090"
"247.08000","20.59020","0.02102"
"247.42800","20.61920","0.02096"
"247.77600","20.64820","0.02166"
"248.12400","20.67725","0.02158"
"248.47200","20.70625","0.02213"
"248.82000","20.73519","0.02224"
"249.16800","20.76425","0.02210"
"249.51600","20.79325","0.02210"
"249.86400","20.82218","0.02208"
"250.21200","20.85124","0.02261"
"250.56000","20.88024","0.02317"
"250.90800","20.90924","0.02281"
"251.25600","20.93823","0.02299"
"251.60400","20.96717","0.02340"
"251.95200","20.99617","0.02311"
"252.30000","21.02523","0.02298"
"252.64800","21.05423","0.02332"
"252.99600","21.08328","0.02340"
"253.34400","21.11222","0.02413"
"253.69200","21.14116","0.02336"
"254.04000","21.17022","0.02425"
"254.38800","21.19921","0.02405"
"254.73600","21.22821","0.02399"
"255.08400","21.25727","0.02457"
"255.43200","21.28627","0.02452"
"255.78000","21.31521","0.02483"
"256.12800","21.34426","0.02522"
"256.47600","21.37320","0.02524"
"256.82400","21.40220","0.02523"
"257.17200","21.43126","0.02486"
"257.52000","21.46020","0.02547"
"257.86800","21.48919","0.02585"
"258.21600","21.51825","0.02596"
"258.56400","21.54719","0.02638"
"258.91200","21.57625","0.02651"
"259.26000","21.60525","0.02632"
"259.60800","21.63419","0.02642"
"259.95600","21.66324","0.02622"
"260.30400","21.69224","0.02668"
"260.65200","21.72118","0.02712"
"261.00000","21.75017","0.02664"
"261.34800","21.77924","0.02716"
"261.69600","21.80817","0.02703"
"262.04400","21.83729","0.02747"
"262.39200","21.86623","0.02767"
"262.74000","21.89523","0.02771"
"263.08800","21.92416","0.02763"
"263.43600","21.95316","0.02759"
"263.78400","21.98228","0.02782"
"264.13200","22.01122","0.02828"
"264.48000","22.04022","0.02818"
"264.82800","22.06915","0.02847"
"265.17600","22.09821","0.02839"
"265.52400","22.12721","0.02899"
"265.87200","22.15621","0.02879"
"266.22000","22.18533","0.02854"
"266.56800","22.21414","0.02876"
"266.91600","22.24326","0.02872"
"267.26400","22.27226","0.02826"
"267.61200","22.30120","0.02884"
"267.96000","22.33025","0.02884"
"268.30800","22.35919","0.02906"
"268.65600","22.38819","0.02926"
"269.00400","22.41719","0.02947"
"269.35200","22.44625","0.02926"
"269.70000","22.47518","0.02957"
"270.04800","22.50424","0.02950"
"270.39600","22.53324","0.02953"
"270.74400","22.56218","0.02929"
"271.09200","22.59130","0.02942"
"271.44000","22.62017","0.03006"
"271.78800","22.64917","0.02934"
"272.13600","22.67823","0.02928"
"272.48400","22.70717","0.02990"
"272.83200","22.73623","0.02942"
"273.18000","22.76517","0.03016"
"273.52800","22.79422","0.03002"
"273.87600","22.82322","0.03059"
"274.22400","22.85228","0.02983"
"274.57200","22.88122","0.03031"
"274.92000","22.91021","0.03006"
"275.26800","22.93921","0.02632"
"275.61600","22.96821","0.02705"
"275.96400","22.99727","0.02667"
"276.31200","23.02615","0.02783"
"276.66000","23.05526","0.02862"
"277.00800","23.08426","0.02934"
"277.35600","23.11314","0.02916"
"277.70400","23.14226","0.02965"
"278.05200","23.17120","0.02966"
"278.40000","23.20019","0.02987"
"278.74800","23.22925","0.03044"
"279.09600","23.25825","0.03057"
"279.44400","23.28718","0.03053"
"279.79200","23.31618","0.03062"
"280.14000","23.34524","0.03123"
"280.48800","23.37418","0.03100"
"280.83600","23.40330","0.03179"
"281.18400","23.43218","0.03158"
"281.53200","23.46123","0.03155"
"281.88000","23.49023","0.03187"
"282.22800","23.51917","0.03236"
"282.57600","23.54829","0.03253"
"282.92400","23.57722","0.03233"
"283.27200","23.60616","0.03250"
"283.62000","23.63522","0.03196"
"283.96800","23.66422","0.03206"
"284.31600","23.69316","0.03260"
"284.66400","23.72221","0.03260"
"285.01200","23.75127","0.03283"
"285.36000","23.78021","0.03248"
"285.70800","23.80927","0.03222"
"286.05600","23.83821","0.03309"
"286.40400","23.86720","0.03298"
"286.75200","23.89626","0.03292"
"287.10000","23.92520","0.03292"
"287.44800","23.95426","0.03300"
"287.79600","23.98320","0.03324"
"288.14400","24.01220","0.03325"
"288.49200","24.04125","0.03317"
"288.84000","24.07019","0.03365"
"289.18800","24.09919","0.03370"
"289.53600","24.12825","0.03375"
"289.88400","24.15730","0.03399"
"290.23200","24.18618","0.03421"
"290.58000","24.21524","0.03372"
"290.92800","24.24424","0.03443"
"291.27600","24.27317","0.03392"
"291.62400","24.30223","0.03443"
"291.97200","24.33123","0.03460"
"292.32000","24.36023","0.03490"
"292.66800","24.38923","0.03468"
"293.01600","24.41823","0.03492"
"293.36400","24.44722","0.03551"
"293.71200","24.47622","0.03526"
"294.06000","24.50522","0.03529"
"294.40800","24.53422","0.03550"
"294.75600","24.56327","0.03502"
"295.10400","24.59215","0.03537"
"295.45200","24.62127","0.03555"
"295.80000","24.65027","0.03595"
"296.14800","24.67921","0.03614"
"296.49600","24.70820","0.03603"
"296.84400","24.73726","0.03634"
"297.19200","24.76626","0.03666"
"297.54000","24.79520","0.03658"
"297.88800","24.82425","0.03691"
"298.23600","24.85319","0.03695"
"298.58400","24.88219","0.03659"
"298.93200","24.91119","0.03722"
"299.28000","24.94019","0.03737"
"299.62800","24.96931","0.03754"
"299.97600","24.99818","0.03760"
"300.32400","25.02724","0.03779"
"300.67200","25.05624","0.03811"
"301.02000","25.08517","0.03792"
"301.36800","25.11430","0.03822"
"301.71600","25.14323","0.03814"
"302.06400","25.17223","0.03856"
"302.41200","25.20123","0.03842"
"302.76000","25.23023","0.03854"
"303.10800","25.25916","0.03855"
"303.45600","25.28822","0.03890"
"303.80400","25.31722","0.03923"
"304.15200","25.34628","0.03907"
"304.50000","25.37522","0.03900"
"304.84800","25.40421","0.03923"
"305.19600","25.43321","0.03902"
"305.54400","25.46227","0.03912"
"305.89200","25.49115","0.03927"
"306.24000","25.52027","0.03954"
"306.58800","25.54921","0.03962"
"306.93600","25.57820","0.03964"
"307.28400","25.60714","0.03984"
"307.63200","25.63626","0.04020"
"307.98000","25.66514","0.04049"
"308.32800","25.69425","0.04050"
"308.67600","25.72325","0.04123"
"309.02400","25.75213","0.04128"
"309.37200","25.78125","0.04158"
"309.72000","25.81025","0.03868"
"310.06800","25.83918","0.03852"
"310.41600","25.86830","0.03496"
"310.76400","25.89718","0.03533"
"311.11200","25.92624","0.03562"
"311.46000","25.95523","0.03622"
"311.80800","25.98417","0.03617"
"312.15600","26.01323","0.03557"
"312.50400","26.04223","0.03567"
"312.85200","26.07122","0.03579"
"313.20000","26.10028","0.03609"
"313.54800","26.12922","0.03616"
"313.89600","26.15816","0.03619"
"314.24400","26.18722","0.03631"
"314.59200","26.21615","0.03641"
"314.94000","26.24516","0.03664"
"315.28800","26.27421","0.03662"
"315.63600","26.30321","0.03703"
"315.98400","26.33221","0.03686"
"316.33200","26.36121","0.03733"
"316.68000","26.39020","0.03700"
"317.02800","26.41926","0.03730"
"317.37600","26.44826","0.03716"
"317.72400","26.47720","0.03773"
"318.07200","26.50614","0.03779"
"318.42000","26.53525","0.03808"
"318.76800","26.56419","0.03797"
"319.11600","26.59319","0.03788"
"319.46400","26.62225","0.03837"
"319.81200","26.65118","0.03828"
"320.16000","26.68030","0.03869"
"320.50800","26.70918","0.03850"
"320.85600","26.73818","0.03865"
"321.20400","26.76723","0.03865"
"321.55200","26.79617","0.03870"
"321.90000","26.82523","0.03901"
"322.24800","26.85417","0.03914"
"322.59600","26.88323","0.03979"
"322.94400","26.91223","0.03949"
"323.29200","26.94123","0.03943"
"323.64000","26.97022","0.03956"
"323.98800","26.99922","0.03968"
"324.33600","27.02828","0.03964"
"324.68400","27.05716","0.03982"
"325.03200","27.08621","0.04017"
"325.38000","27.11527","0.04045"
"325.72800","27.14415","0.04031"
"326.07600","27.17321","0.04058"
"326.42400","27.20220","0.04034"
"326.77200","27.23114","0.02505"
"327.12000","27.26020","0.02640"
"327.46800","27.28920","0.02694"
"327.81600","27.31820","0.02816"
"328.16400","27.34725","0.02884"
"328.51200","27.37619","0.02872"
"328.86000","27.40519","0.02922"
"329.20800","27.43419","0.02933"
"329.55600","27.46318","0.02921"
"329.90400","27.49224","0.03012"
"330.25200","27.52124","0.03084"
"330.60000","27.55018","0.02998"
"330.94800","27.57924","0.03048"
"331.29600","27.60824","0.03105"
"331.64400","27.63723","0.03099"
"331.99200","27.66623","0.03016"
"332.34000","27.69523","0.03138"
"332.68800","27.72423","0.03118"
"333.03600","27.75323","0.03127"
"333.38400","27.78222","0.03149"
"333.73200","27.81122","0.03096"
"334.08000","27.84028","0.03049"
"334.42800","27.86916","0.03132"
"334.77600","27.89827","0.03166"
"335.12400","27.92727","0.03204"
"335.47200","27.95615","0.03204"
"335.82000","27.98527","0.03295"
"336.16800","28.01427","0.03319"
"336.51600","28.04315","0.03307"
"336.86400","28.07226","0.03371"
"337.21200","28.10120","0.03404"
"337.56000","28.13020","0.03354"
"337.90800","28.15926","0.03443"
"338.25600","28.18826","0.03438"
"338.60400","28.21719","0.03464"
"338.95200","28.24625","0.03482"
"339.30000","28.27519","0.03474"
"339.64800","28.30419","0.03472"
"339.99600","28.33324","0.03474"
"340.34400","28.36218","0.03547"
"340.69200","28.39124","0.03527"
"341.04000","28.42024","0.03557"
"341.38800","28.44924","0.03531"
"341.73600","28.47818","0.03538"
"342.08400","28.50723","0.03537"
"342.43200","28.53617","0.03592"
"342.78000","28.56523","0.03596"
"343.12800","28.59429","0.03595"
"343.47600","28.62316","0.03610"
"343.82400","28.65222","0.03580"
"344.17200","28.68122","0.03614"
"344.52000","28.71022","0.03608"
"344.86800","28.73922","0.03611"
"345.21600","28.76815","0.03628"
"345.56400","28.79721","0.03603"
"345.91200","28.82621","0.03618"
"346.26000","28.85521","0.03617"
"346.60800","28.88421","0.03637"
"346.95600","28.91326","0.03646"
"347.30400","28.94220","0.03652"
"347.65200","28.97120","0.03659"
"348.00000","29.00019","0.03664"
"348.34800","29.02913","0.03591"
"348.69600","29.05825","0.03654"
"349.04400","29.08725","0.03673"
"349.39200","29.11625","0.03674"
"349.74000","29.14525","0.03686"
"350.08800","29.17418","0.03659"
"350.43600","29.20318","0.03694"
"350.78400","29.23224","0.03698"
"351.13200","29.26124","0.03720"
"351.48000","29.29018","0.03713"
"351.82800","29.31923","0.03742"
"352.17600","29.34817","0.03722"
"352.52400","29.37723","0.03683"
"352.87200","29.40629","0.03719"
"353.22000","29.43517","0.03727"
"353.56800","29.46422","0.03755"
"353.91600","29.49328","0.03752"
"354.26400","29.52216","0.03761"
"354.61200","29.55128","0.03768"
"354.96000","29.58021","0.03794"
"355.30800","29.60921","0.03775"
"355.65600","29.63827","0.03777"
"356.00400","29.66721","0.03761"
"356.35200","29.69621","0.03786"
"356.70000","29.72520","0.03805"
"357.04800","29.75420","0.03789"
"357.39600","29.78326","0.03829"
"357.74400","29.81226","0.03824"
"358.09200","29.84120","0.03852"
"358.44000","29.87025","0.03889"
"358.78800","29.89925","0.03862"
"359.13600","29.92819","0.03855"
"359.48400","29.95725","0.03894"
"359.83200","29.98618","0.03858"
"360.18000","30.01518","0.03893"
"360.52800","30.04424","0.03905"
"360.87600","30.07324","0.03925"
"361.22400","30.10224","0.03934"
"361.57200","30.13124","0.03999"
"361.92000","30.16023","0.03947"
"362.26800","30.18917","0.03997"
"362.61600","30.21829","0.03994"
"362.96400","30.24723","0.04031"
"363.31200","30.27623","0.04026"
"363.66000","30.30528","0.04001"
"364.00800","30.33416","0.04075"
"364.35600","30.36328","0.04051"
"364.70400","30.39221","0.04054"
"365.05200","30.42115","0.04066"
"365.40000","30.45021","0.04118"
"365.74800","30.47921","0.04143"
"366.09600","30.50821","0.04202"
"366.44400","30.53721","0.04217"
"366.79200","30.56626","0.04209"
"367.14000","30.59520","0.04251"
"367.48800","30.62420","0.04260"
"367.83600","30.65320","0.04321"
"368.18400","30.68220","0.04412"
"368.53200","30.71119","0.04473"
"368.88000","30.74019","0.04470"
"369.22800","30.76925","0.04467"
"369.57600","30.79819","0.04532"
"369.92400","30.82719","0.04533"
"370.27200","30.85625","0.04578"
"370.62000","30.88524","0.04622"
"370.96800","30.91418","0.04676"
"371.31600","30.94324","0.04677"
"371.66400","30.97223","0.04570"
"372.01200","31.00117","0.03261"
"372.36000","31.03029","0.03326"
"372.70800","31.05917","0.03409"
"373.05600","31.08817","0.03406"
"373.40400","31.11728","0.03503"
"373.75200","31.14622","0.03540"
"374.10000","31.17522","0.03590"
"374.44800","31.20422","0.03620"
"374.79600","31.23316","0.03635"
"375.14400","31.26221","0.03664"
"375.49200","31.29121","0.03648"
"375.84000","31.32021","0.03665"
"376.18800","31.34921","0.03674"
"376.53600","31.37820","0.03677"
"376.88400","31.40720","0.03606"
"377.23200","31.43620","0.03682"
"377.58000","31.46526","0.03682"
"377.92800","31.49420","0.03665"
"378.27600","31.52325","0.03620"
"378.62400","31.55225","0.03657"
"378.97200","31.58119","0.03655"
"379.32000","31.61025","0.03661"
"379.66800","31.63918","0.03662"
"380.01600","31.66818","0.03641"
"380.36400","31.69724","0.03637"
"380.71200","31.72624","0.03648"
"381.06000","31.75517","0.03660"
"381.40800","31.78424","0.03670"
"381.75600","31.81318","0.03674"
"382.10400","31.84217","0.03670"
"382.45200","31.87123","0.03603"
"382.80000","31.90011","0.03609"
"383.14800","31.92922","0.03621"
"383.49600","31.95822","0.03644"
"383.84400","31.98722","0.03690"
"384.19200","32.01622","0.03673"
"384.54000","32.04522","0.03703"
"384.88800","32.07421","0.03700"
"385.23600","32.10327","0.03756"
"385.58400","32.13221","0.03749"
"385.93200","32.16121","0.03744"
"386.28000","32.19021","0.03751"
"386.62800","32.21920","0.03800"
"386.97600","32.24820","0.03790"
"387.32400","32.27732","0.03775"
"387.67200","32.30614","0.03757"
"388.02000","32.33525","0.03735"
"388.36800","32.36425","0.03782"
"388.71600","32.39319","0.03764"
"389.06400","32.42225","0.03785"
"389.41200","32.45119","0.03759"
"389.76000","32.48024","0.03782"
"390.10800","32.50924","0.03779"
"390.45600","32.53824","0.03811"
"390.80400","32.56718","0.03820"
"391.15200","32.59624","0.03865"
"391.50000","32.62524","0.03854"
"391.84800","32.65423","0.03816"
"392.19600","32.68323","0.03855"
"392.54400","32.71217","0.03903"
"392.89200","32.74123","0.03879"
"393.24000","32.77023","0.03916"
"393.58800","32.79916","0.03886"
"393.93600","32.82822","0.03872"
"394.28400","32.85722","0.03779"
"394.63200","32.88622","0.03836"
"394.98000","32.91527","0.03876"
"395.32800","32.94427","0.03900"
"395.67600","32.97315","0.03912"
"396.02400","33.00227","0.03959"
"396.37200","33.03127","0.03994"
"396.72000","33.06020","0.04013"
"397.06800","33.08926","0.04028"
"397.41600","33.11820","0.04057"
"397.76400","33.14720","0.04086"
"398.11200","33.17619","0.04114"
"398.46000","33.20513","0.04113"
"398.80800","33.23425","0.04054"
"399.15600","33.26319","0.04071"
"399.50400","33.29219","0.04085"
"399.85200","33.32124","0.04105"
"400.20000","33.35024","0.03942"
"400.54800","33.37918","0.03996"
"400.89600","33.40824","0.04001"
"401.24400","33.43724","0.03995"
"401.59200","33.46624","0.04040"
"401.94000","33.49523","0.04082"
"402.28800","33.52417","0.04146"
"402.63600","33.55317","0.04130"
"402.98400","33.58223","0.04164"
"403.33200","33.61116","0.04198"
"403.68000","33.64028","0.04192"
"404.02800","33.66922","0.04128"
"404.37600","33.69822","0.04139"
"404.72400","33.72727","0.04151"
"405.07200","33.75628","0.04085"
"405.42000","33.78515","0.04073"
"405.76800","33.81421","0.04096"
"406.11600","33.84327","0.04110"
"406.46400","33.87221","0.04092"
"406.81200","33.90126","0.04131"
"407.16000","33.93026","0.04106"
"407.50800","33.95920","0.04133"
"407.85600","33.98825","0.04171"
"408.20400","34.01719","0.04165"
"408.55200","34.04619","0.04203"
"408.90000","34.07525","0.04190"
"409.24800","34.10425","0.04178"
"409.59600","34.13324","0.04202"
"409.94400","34.16225","0.04147"
"410.29200","34.19118","0.04119"
"410.64000","34.22018","0.04070"
"410.98800","34.24930","0.03895"
"411.33600","34.27818","0.03511"
"411.68400","34.30724","0.02665"
"412.03200","34.33629","0.03174"
"412.38000","34.36523","0.02887"
"412.72800","34.39423","0.02808"
"413.07600","34.42323","0.03221"
"413.42400","34.45222","0.02995"
"413.77200","34.48122","0.03014"
"414.12000","34.51022","0.03206"
"414.46800","34.53922","0.03113"
"414.81600","34.56822","0.03117"
"415.16400","34.59727","0.03229"
"415.51200","34.62621","0.03197"
"415.86000","34.65527","0.03155"
"416.20800","34.68415","0.03279"
"416.55600","34.71326","0.03234"
"416.90400","34.74220","0.03230"
"417.25200","34.77114","0.03324"
"417.60000","34.80026","0.03370"
"417.94800","34.82925","0.03271"
"418.29600","34.85819","0.03364"
"418.64400","34.88725","0.03365"
"418.99200","34.91625","0.03357"
"419.34000","34.94519","0.03404"
"419.68800","34.97419","0.03391"
"420.03600","35.00325","0.03383"
"420.38400","35.03218","0.03395"
"420.73200","35.06124","0.03422"
"421.08000","35.09024","0.03395"
"421.42800","35.11924","0.03391"
"421.77600","35.14823","0.03439"
"422.12400","35.17717","0.03401"
"422.47200","35.20629","0.03457"
"422.82000","35.23523","0.03485"
"423.16800","35.26423","0.03479"
"423.51600","35.29322","0.03473"
"423.86400","35.32222","0.03498"
"424.21200","35.35116","0.03501"
"424.56000","35.38022","0.03510"
"424.90800","35.40928","0.03520"
"425.25600","35.43821","0.03528"
"425.60400","35.46721","0.03559"
"425.95200","35.49621","0.03574"
"426.30000","35.52521","0.03579"
"426.64800","35.55426","0.03528"
"426.99600","35.58320","0.03556"
"427.34400","35.61226","0.03612"
"427.69200","35.64126","0.03610"
"428.04000","35.67020","0.03633"
"428.38800","35.69913","0.03589"
"428.73600","35.72820","0.03635"
"429.08400","35.75713","0.03639"
"429.43200","35.78625","0.03642"
"429.78000","35.81525","0.03658"
"430.12800","35.84418","0.03585"
"430.47600","35.87330","0.03600"
"430.82400","35.90224","0.03609"
"431.17200","35.93118","0.03560"
"431.52000","35.96029","0.03562"
"431.86800","35.98917","0.03631"
"432.21600","36.01823","0.03582"
"432.56400","36.04723","0.03609"
"432.91200","36.07616","0.03595"
"433.26000","36.10522","0.03636"
"433.60800","36.13422","0.03646"
"433.95600","36.16322","0.03637"
"434.30400","36.19222","0.03641"
"434.65200","36.22128","0.03656"
"435.00000","36.25021","0.03662"
"435.34800","36.27921","0.03679"
"435.69600","36.30821","0.03672"
"436.04400","36.33721","0.03723"
"436.39200","36.36621","0.03714"
"436.74000","36.39520","0.03701"
"437.08800","36.42414","0.03728"
"437.43600","36.45326","0.03753"
"437.78400","36.48220","0.03756"
"438.13200","36.51126","0.03792"
"438.48000","36.54020","0.03772"
"438.82800","36.56919","0.03794"
"439.17600","36.59819","0.03799"
"439.52400","36.62725","0.03802"
"439.87200","36.65619","0.03815"
"440.22000","36.68518","0.03810"
"440.56800","36.71424","0.03831"
"440.91600","36.74318","0.03819"
"441.26400","36.77224","0.03847"
"441.61200","36.80117","0.03814"
"441.96000","36.83023","0.03865"
"442.30800","36.85923","0.03854"
"442.65600","36.88823","0.03882"
"443.00400","36.91723","0.03877"
"443.35200","36.94622","0.03895"
"443.70000","36.97522","0.03911"
"444.04800","37.00416","0.03927"
"444.39600","37.03322","0.03930"
"444.74400","37.06222","0.03936"
"445.09200","37.09121","0.03930"
"445.44000","37.12027","0.03952"
"445.78800","37.14915","0.03979"
"446.13600","37.17827","0.03981"
"446.48400","37.20726","0.03975"
"446.83200","37.23614","0.04039"
"447.18000","37.26520","0.04019"
"447.52800","37.29420","0.04073"
"447.87600","37.32320","0.04060"
"448.22400","37.35226","0.04023"
"448.57200","37.38125","0.04086"
"448.92000","37.41019","0.04072"
"449.26800","37.43925","0.04076"
"449.61600","37.46819","0.04094"
"449.96400","37.49718","0.04103"
"450.31200","37.52624","0.04131"
"450.66000","37.55518","0.04132"
"451.00800","37.58424","0.04124"
"451.35600","37.61317","0.04138"
"451.70400","37.64211","0.04218"
"452.05200","37.67123","0.04157"
"452.40000","37.70023","0.04180"
"452.74800","37.72917","0.04136"
"453.09600","37.75823","0.04196"
"453.44400","37.78722","0.04223"
"453.79200","37.81616","0.04225"
"454.14000","37.84522","0.04161"
"454.48800","37.87422","0.04121"
"454.83600","37.90316","0.04110"
"455.18400","37.93227","0.04062"
"455.53200","37.96115","0.04108"
"455.88000","37.99021","0.04065"
"456.22800","38.01926","0.04063"
"456.57600","38.04815","0.04054"
"456.92400","38.07727","0.04029"
"457.27200","38.10626","0.03793"
"457.62000","38.13520","0.03762"
"457.96800","38.16426","0.03766"
"458.31600","38.19326","0.03812"
"458.66400","38.22219","0.03791"
"459.01200","38.25125","0.03788"
"459.36000","38.28025","0.03834"
"459.70800","38.30913","0.03857"
"460.05600","38.33825","0.03845"
"460.40400","38.36724","0.03801"
"460.75200","38.39624","0.03790"
"461.10000","38.42524","0.03825"
"461.44800","38.45417","0.03816"
"461.79600","38.48317","0.03823"
"462.14400","38.51223","0.03875"
"462.49200","38.54123","0.03828"
"462.84000","38.57017","0.03861"
"463.18800","38.59923","0.03881"
"463.53600","38.62817","0.03899"
"463.88400","38.65722","0.03874"
"464.23200","38.68628","0.03874"
"464.58000","38.71510","0.03918"
"464.92800","38.74427","0.03940"
"465.27600","38.77327","0.03910"
"465.62400","38.80221","0.03971"
"465.97200","38.83121","0.04005"
"466.32000","38.86021","0.03935"
"466.66800","38.88921","0.03947"
"467.01600","38.91821","0.03935"
"467.36400","38.94726","0.03981"
"467.71200","38.97620","0.03945"
"468.06000","39.00520","0.03773"
"468.40800","39.03419","0.03683"
"468.75600","39.06319","0.03671"
"469.10400","39.09225","0.03686"
"469.45200","39.12119","0.03713"
"469.80000","39.15018","0.03782"
"470.14800","39.17924","0.03751"
"470.49600","39.20818","0.03769"
"470.84400","39.23724","0.03780"
"471.19200","39.26618","0.03788"
"471.54000","39.29524","0.03816"
"471.88800","39.32423","0.03794"
"472.23600","39.35323","0.03832"
"472.58400","39.38223","0.03856"
"472.93200","39.41123","0.03868"
"473.28000","39.44017","0.03885"
"473.62800","39.46922","0.03921"
"473.97600","39.49828","0.03942"
"474.32400","39.52716","0.03936"
"474.67200","39.55622","0.03959"
"475.02000","39.58521","0.03940"
"475.36800","39.61415","0.03954"
"475.71600","39.64327","0.03933"
"476.06400","39.67227","0.04000"
"476.41200","39.70121","0.04009"
"476.76000","39.73026","0.04035"
"477.10800","39.75920","0.04006"
"477.45600","39.78814","0.03951"
"477.80400","39.81726","0.03963"
"478.15200","39.84626","0.03990"
"478.50000","39.87525","0.04002"
"478.84800","39.90419","0.03991"
"479.19600","39.93319","0.03987"
"479.54400","39.96219","0.04003"
"479.89200","39.99125","0.03958"
"480.24000","40.02018","0.04044"
"480.58800","40.04924","0.04022"
"480.93600","40.07824","0.04065"
"481.28400","40.10718","0.04043"
"481.63200","40.13624","0.04053"
"481.98000","40.16523","0.04106"
"482.32800","40.19417","0.04078"
"482.67600","40.22329","0.04105"
"483.02400","40.25223","0.04166"
"483.37200","40.28122","0.04168"
"483.72000","40.31028","0.04065"
"484.06800","40.33922","0.04113"
"484.41600","40.36816","0.04153"
"484.76400","40.39722","0.04225"
"485.11200","40.42621","0.04231"
"485.46000","40.45522","0.04266"
"485.80800","40.48421","0.04250"
"486.15600","40.51315","0.04363"
"486.50400","40.54226","0.04365"
"486.85200","40.57121","0.04398"
"487.20000","40.60020","0.04426"
"487.54800","40.62920","0.04510"
"487.89600","40.65826","0.04497"
"488.24400","40.68719","0.04587"
"488.59200","40.71625","0.04568"
"488.94000","40.74519","0.04614"
"489.28800","40.77419","0.04563"
"489.63600","40.80325","0.04587"
"489.98400","40.83224","0.04716"
"490.33200","40.86119","0.04768"
"490.68000","40.89024","0.04853"
"491.02800","40.91924","0.04841"
"491.37600","40.94817","0.04889"
"491.72400","40.97723","0.04958"
"492.07200","41.00623","0.05030"
"492.42000","41.03523","0.05140"
"492.76800","41.06423","0.05007"
"493.11600","41.09316","0.05068"
"493.46400","41.12222","0.05045"
"493.81200","41.15122","0.05145"
"494.16000","41.18022","0.05152"
"494.50800","41.20928","0.05286"
"494.85600","41.23822","0.05308"
"495.20400","41.26722","0.05405"
"495.55200","41.29622","0.05419"
"495.90000","41.32521","0.05470"
"496.24800","41.35421","0.05547"
"496.59600","41.38321","0.05623"
"496.94400","41.41227","0.05657"
"497.29200","41.44120","0.05656"
"497.64000","41.47026","0.05608"
"497.98800","41.49920","0.05524"
"498.33600","41.52826","0.05605"
"498.68400","41.55731","0.05719"
"499.03200","41.58613","0.05733"
"499.38000","41.61531","0.05850"
"499.72800","41.64425","0.05826"
"500.07600","41.67319","0.05857"
"500.42400","41.70224","0.05883"
"500.77200","41.73118","0.05967"
"501.12000","41.76018","0.05984"
"501.46800","41.78930","0.05997"
"501.81600","41.81818","0.06077"
"502.16400","41.84723","0.06059"
"502.51200","41.87623","0.06076"
"502.86000","41.90523","0.06135"
"503.20800","41.93422","0.05935"
"503.55600","41.96328","0.05337"
"503.90400","41.99216","0.05338"
"504.25200","42.02122","0.05380"
"504.60000","42.05022","0.05436"
"504.94800","42.07922","0.05599"
"505.29600","42.10822","0.05569"
"505.64400","42.13721","0.05463"
"505.99200","42.16621","0.05418"
"506.34000","42.19521","0.05519"
"506.68800","42.22427","0.05665"
"507.03600","42.25320","0.05738"
"507.38400","42.28220","0.05506"
"507.73200","42.31126","0.05592"
"508.08000","42.34020","0.05573"
"508.42800","42.36926","0.05606"
"508.77600","42.39819","0.05626"
"509.12400","42.42725","0.05698"
"509.47200","42.45625","0.05763"
"509.82000","42.48513","0.05509"
"510.16800","42.51424","0.05667"
"510.51600","42.54324","0.05803"
"510.86400","42.57218","0.05842"
"511.21200","42.60123","0.05742"
"511.56000","42.63023","0.05746"
"511.90800","42.65918","0.05765"
"512.25600","42.68823","0.05848"
"512.60400","42.71723","0.05901"
"512.95200","42.74616","0.05858"
"513.30000","42.77522","0.05883"
"513.64800","42.80416","0.05904"
"513.99600","42.83323","0.05886"
"514.34400","42.86222","0.05938"
"514.66200","42.88871","0.04188"