File: Force_trajectories/170122_1/Specimen_RawData_9.csv
End date,"1/22/2017"
Specimen label,"12DT_92"
Maximum Load,"0.37435",N

Time,Extension,Load
(s),(mm),(N)
"0.00000","0.00000","-0.00153"
"0.18000","0.01184","-0.00115"
"0.36000","0.03001","-0.00133"
"0.54000","0.04526","-0.00116"
"0.72000","0.06027","-0.00047"
"0.90000","0.07522","-0.00078"
"1.08000","0.09022","-0.00077"
"1.26000","0.10523","-0.00038"
"1.44000","0.12018","0.00015"
"1.62000","0.13518","0.00007"
"1.80000","0.15019","-0.00024"
"1.98000","0.16526","0.00031"
"2.16000","0.18015","0.00008"
"2.34000","0.19521","0.00036"
"2.52000","0.21016","0.00034"
"2.70000","0.22523","0.00007"
"2.88000","0.24023","0.00125"
"3.06000","0.25512","0.00157"
"3.24000","0.27019","0.00119"
"3.42000","0.28520","0.00136"
"3.60000","0.30020","0.00102"
"3.78000","0.31515","0.00154"
"3.96000","0.33022","0.00177"
"4.14000","0.34522","0.00113"
"4.32000","0.36017","0.00146"
"4.50000","0.37518","0.00255"
"4.68000","0.39019","0.00177"
"4.86000","0.40519","0.00218"
"5.04000","0.42020","0.00309"
"5.22000","0.43515","0.00308"
"5.40000","0.45016","0.00298"
"5.58000","0.46522","0.00319"
"5.76000","0.48017","0.00326"
"5.94000","0.49512","0.00281"
"6.12000","0.51018","0.00369"
"6.30000","0.52525","0.00400"
"6.48000","0.54014","0.00413"
"6.66000","0.55515","0.00419"
"6.84000","0.57021","0.00373"
"7.02000","0.58516","0.00442"
"7.20000","0.60017","0.00462"
"7.38000","0.61517","0.00441"
"7.56000","0.63018","0.00522"
"7.74000","0.64519","0.00506"
"7.92000","0.66020","0.00506"
"8.10000","0.67508","0.00621"
"8.28000","0.69021","0.00510"
"8.46000","0.70522","0.00592"
"8.64000","0.72016","0.00585"
"8.82000","0.73517","0.00659"
"9.00000","0.75018","0.00600"
"9.18000","0.76513","0.00658"
"9.36000","0.78019","0.00696"
"9.54000","0.79520","0.00697"
"9.72000","0.81021","0.00717"
"9.90000","0.82522","0.00709"
"10.08000","0.84016","0.00784"
"10.26000","0.85517","0.00770"
"10.44000","0.87024","0.00831"
"10.62000","0.88518","0.00816"
"10.80000","0.90019","0.00834"
"10.98000","0.91520","0.00835"
"11.16000","0.93021","0.00917"
"11.34000","0.94515","0.00892"
"11.52000","0.96022","0.00922"
"11.70000","0.97517","0.00959"
"11.88000","0.99023","0.00945"
"12.06000","1.00524","0.01007"
"12.24000","1.02013","0.01033"
"12.42000","1.03514","0.01006"
"12.60000","1.05020","0.01059"
"12.78000","1.06515","0.01068"
"12.96000","1.08022","0.01082"
"13.14000","1.09522","0.01066"
"13.32000","1.11017","0.01108"
"13.50000","1.12518","0.01115"
"13.68000","1.14019","0.01126"
"13.86000","1.15513","0.01184"
"14.04000","1.17020","0.01188"
"14.22000","1.18521","0.01229"
"14.40000","1.20016","0.01273"
"14.58000","1.21516","0.01256"
"14.76000","1.23023","0.01302"
"14.94000","1.24518","0.01253"
"15.12000","1.26018","0.01331"
"15.30000","1.27519","0.01316"
"15.48000","1.29020","0.01367"
"15.66000","1.30515","0.01394"
"15.84000","1.32015","0.01376"
"16.02000","1.33516","0.01449"
"16.20000","1.35017","0.01429"
"16.38000","1.36523","0.01491"
"16.56000","1.38018","0.01524"
"16.74000","1.39519","0.01485"
"16.92000","1.41020","0.01567"
"17.10000","1.42520","0.01540"
"17.28000","1.44021","0.01607"
"17.46000","1.45516","0.01569"
"17.64000","1.47016","0.01612"
"17.82000","1.48517","0.01606"
"18.00000","1.50018","0.01698"
"18.18000","1.51519","0.01707"
"18.36000","1.53019","0.01686"
"18.54000","1.54514","0.01714"
"18.72000","1.56009","0.01742"
"18.90000","1.57522","0.01747"
"19.08000","1.59022","0.01818"
"19.26000","1.60517","0.01861"
"19.44000","1.62018","0.01860"
"19.62000","1.63524","0.01852"
"19.80000","1.65019","0.01760"
"19.98000","1.66520","0.01846"
"20.16000","1.68027","0.01960"
"20.34000","1.69521","0.01939"
"20.52000","1.71016","0.01921"
"20.70000","1.72523","0.01990"
"20.88000","1.74011","0.01953"
"21.06000","1.75524","0.02005"
"21.24000","1.77025","0.02043"
"21.42000","1.78514","0.02042"
"21.60000","1.80020","0.02038"
"21.78000","1.81527","0.02082"
"21.96000","1.83016","0.02090"
"22.14000","1.84516","0.02094"
"22.32000","1.86023","0.02173"
"22.50000","1.87518","0.02145"
"22.68000","1.89019","0.02150"
"22.86000","1.90519","0.02161"
"23.04000","1.92014","0.02248"
"23.22000","1.93521","0.02237"
"23.40000","1.95022","0.02213"
"23.58000","1.96510","0.02238"
"23.76000","1.98017","0.02279"
"23.94000","1.99524","0.02320"
"24.12000","2.01018","0.02320"
"24.30000","2.02519","0.02351"
"24.48000","2.04020","0.02353"
"24.66000","2.05515","0.02357"
"24.84000","2.07021","0.02366"
"25.02000","2.08522","0.02396"
"25.20000","2.10017","0.02396"
"25.38000","2.11517","0.02412"
"25.56000","2.13024","0.02445"
"25.74000","2.14513","0.02462"
"25.92000","2.16020","0.02442"
"26.10000","2.17520","0.02424"
"26.28000","2.19015","0.02440"
"26.46000","2.20516","0.02527"
"26.64000","2.22022","0.02505"
"26.82000","2.23517","0.02517"
"27.00000","2.25018","0.02558"
"27.18000","2.26519","0.02589"
"27.36000","2.28013","0.02566"
"27.54000","2.29520","0.02534"
"27.72000","2.31021","0.02626"
"27.90000","2.32516","0.02641"
"28.08000","2.34022","0.02663"
"28.26000","2.35523","0.02616"
"28.44000","2.37012","0.02643"
"28.62000","2.38518","0.02666"
"28.80000","2.40025","0.02652"
"28.98000","2.41514","0.02701"
"29.16000","2.43021","0.02698"
"29.34000","2.44521","0.02712"
"29.52000","2.46016","0.02736"
"29.70000","2.47523","0.02723"
"29.88000","2.49023","0.02742"
"30.06000","2.50512","0.02776"
"30.24000","2.52019","0.02766"
"30.42000","2.53526","0.02816"
"30.60000","2.55008","0.02792"
"30.78000","2.56515","0.02803"
"30.96000","2.58022","0.02800"
"31.14000","2.59516","0.02843"
"31.32000","2.61017","0.02852"
"31.50000","2.62518","0.02869"
"31.68000","2.64019","0.02887"
"31.86000","2.65519","0.02919"
"32.04000","2.67026","0.02919"
"32.22000","2.68515","0.02985"
"32.40000","2.70021","0.02983"
"32.58000","2.71522","0.02983"
"32.76000","2.73011","0.02977"
"32.94000","2.74518","0.03019"
"33.12000","2.76024","0.03048"
"33.30000","2.77519","0.03048"
"33.48000","2.79020","0.03090"
"33.66000","2.80515","0.03104"
"33.84000","2.82015","0.03093"
"34.02000","2.83516","0.03125"
"34.20000","2.85017","0.03250"
"34.38000","2.86511","0.03193"
"34.56000","2.88024","0.03206"
"34.74000","2.89519","0.03272"
"34.92000","2.91014","0.03310"
"35.10000","2.92520","0.03332"
"35.28000","2.94021","0.03359"
"35.46000","2.95522","0.03373"
"35.64000","2.97016","0.03430"
"35.82000","2.98517","0.03461"
"36.00000","3.00012","0.03501"
"36.18000","3.01525","0.03574"
"36.36000","3.03019","0.03521"
"36.54000","3.04514","0.03618"
"36.72000","3.06027","0.03647"
"36.90000","3.07516","0.03703"
"37.08000","3.09016","0.03760"
"37.26000","3.10523","0.03778"
"37.44000","3.12024","0.03870"
"37.62000","3.13518","0.03953"
"37.80000","3.15025","0.03929"
"37.98000","3.16526","0.04000"
"38.16000","3.18015","0.03986"
"38.34000","3.19521","0.04063"
"38.52000","3.21016","0.03268"
"38.70000","3.22517","0.03371"
"38.88000","3.24029","0.03325"
"39.06000","3.25518","0.03407"
"39.24000","3.27007","0.03471"
"39.42000","3.28520","0.03444"
"39.60000","3.30020","0.03500"
"39.78000","3.31515","0.03505"
"39.96000","3.33022","0.03584"
"40.14000","3.34522","0.03635"
"40.32000","3.36017","0.03670"
"40.50000","3.37518","0.03696"
"40.68000","3.39019","0.03675"
"40.86000","3.40513","0.03774"
"41.04000","3.42020","0.03796"
"41.22000","3.43521","0.03831"
"41.40000","3.45010","0.03922"
"41.58000","3.46522","0.03959"
"41.76000","3.48023","0.04012"
"41.94000","3.49512","0.04093"
"42.12000","3.51018","0.04106"
"42.30000","3.52525","0.04247"
"42.48000","3.54020","0.04234"
"42.66000","3.55521","0.04312"
"42.84000","3.57015","0.04376"
"43.02000","3.58522","0.04427"
"43.20000","3.60023","0.04515"
"43.38000","3.61517","0.04612"
"43.56000","3.63012","0.04627"
"43.74000","3.64519","0.04695"
"43.92000","3.66014","0.04716"
"44.10000","3.67514","0.04771"
"44.28000","3.69021","0.04853"
"44.46000","3.70522","0.04921"
"44.64000","3.72016","0.04986"
"44.82000","3.73523","0.05040"
"45.00000","3.75018","0.05096"
"45.18000","3.76513","0.05186"
"45.36000","3.78025","0.05212"
"45.54000","3.79520","0.05255"
"45.72000","3.81015","0.05290"
"45.90000","3.82527","0.05358"
"46.08000","3.84022","0.05446"
"46.26000","3.85511","0.05453"
"46.44000","3.87018","0.05531"
"46.62000","3.88524","0.05638"
"46.80000","3.90013","0.05592"
"46.98000","3.91520","0.05696"
"47.16000","3.93015","0.05703"
"47.34000","3.94521","0.05756"
"47.52000","3.96016","0.05862"
"47.70000","3.97517","0.05864"
"47.88000","3.99017","0.05935"
"48.06000","4.00524","0.05971"
"48.24000","4.02019","0.06060"
"48.42000","4.03514","0.06065"
"48.60000","4.05020","0.06149"
"48.78000","4.06521","0.06224"
"48.96000","4.08016","0.06207"
"49.14000","4.09516","0.06333"
"49.32000","4.11023","0.06361"
"49.50000","4.12518","0.06152"
"49.68000","4.14019","0.05089"
"49.86000","4.15519","0.05001"
"50.04000","4.17014","0.05043"
"50.22000","4.18521","0.05270"
"50.40000","4.20021","0.05163"
"50.58000","4.21510","0.05372"
"50.76000","4.23023","0.05346"
"50.94000","4.24518","0.05426"
"51.12000","4.26012","0.05600"
"51.30000","4.27519","0.05505"
"51.48000","4.29020","0.05670"
"51.66000","4.30515","0.05726"
"51.84000","4.32021","0.05754"
"52.02000","4.33516","0.05881"
"52.20000","4.35017","0.05863"
"52.38000","4.36523","0.05976"
"52.56000","4.38018","0.05990"
"52.74000","4.39519","0.06031"
"52.92000","4.41014","0.06187"
"53.10000","4.42514","0.06187"
"53.28000","4.44015","0.06329"
"53.46000","4.45522","0.06379"
"53.64000","4.47022","0.06401"
"53.82000","4.48517","0.06616"
"54.00000","4.50018","0.06539"
"54.18000","4.51519","0.06729"
"54.36000","4.53019","0.06806"
"54.54000","4.54520","0.06812"
"54.72000","4.56015","0.07040"
"54.90000","4.57515","0.06917"
"55.08000","4.59028","0.07171"
"55.26000","4.60517","0.07166"
"55.44000","4.62012","0.07192"
"55.62000","4.63518","0.07375"
"55.80000","4.65019","0.07321"
"55.98000","4.66514","0.07489"
"56.16000","4.68021","0.07495"
"56.34000","4.69521","0.07553"
"56.52000","4.71016","0.07624"
"56.70000","4.72517","0.07579"
"56.88000","4.74011","0.07757"
"57.06000","4.75518","0.07711"
"57.24000","4.77019","0.07766"
"57.42000","4.78514","0.07820"
"57.60000","4.80014","0.07777"
"57.78000","4.81521","0.07833"
"57.96000","4.83022","0.07806"
"58.14000","4.84516","0.07860"
"58.32000","4.86017","0.07887"
"58.50000","4.87518","0.07875"
"58.68000","4.89019","0.07923"
"58.86000","4.90519","0.07916"
"59.04000","4.92014","0.07958"
"59.22000","4.93515","0.07918"
"59.40000","4.95021","0.07746"
"59.58000","4.96516","0.05431"
"59.76000","4.98017","0.05529"
"59.94000","4.99518","0.05728"
"60.12000","5.01018","0.05715"
"60.30000","5.02519","0.05733"
"60.48000","5.04020","0.05868"
"60.66000","5.05520","0.05829"
"60.84000","5.07015","0.05950"
"61.02000","5.08516","0.05965"
"61.20000","5.10011","0.05986"
"61.38000","5.11517","0.06107"
"61.56000","5.13018","0.06061"
"61.74000","5.14519","0.06169"
"61.92000","5.16014","0.06149"
"62.10000","5.17520","0.06183"
"62.28000","5.19021","0.06317"
"62.46000","5.20516","0.06295"
"62.64000","5.22016","0.06475"
"62.82000","5.23517","0.06533"
"63.00000","5.25018","0.06577"
"63.18000","5.26519","0.06716"
"63.36000","5.28013","0.06647"
"63.54000","5.29520","0.06901"
"63.72000","5.31021","0.06923"
"63.90000","5.32515","0.06941"
"64.08000","5.34016","0.07107"
"64.26000","5.35523","0.07100"
"64.44000","5.37018","0.07156"
"64.62000","5.38518","0.07188"
"64.80000","5.40019","0.07219"
"64.98000","5.41520","0.07302"
"65.16000","5.43015","0.07233"
"65.34000","5.44521","0.07451"
"65.52000","5.46016","0.07404"
"65.70000","5.47517","0.07517"
"65.88000","5.49023","0.07619"
"66.06000","5.50518","0.07580"
"66.24000","5.52019","0.07706"
"66.42000","5.53525","0.07686"
"66.60000","5.55014","0.07720"
"66.78000","5.56515","0.07776"
"66.96000","5.58016","0.07789"
"67.14000","5.59516","0.07814"
"67.32000","5.61017","0.07804"
"67.50000","5.62518","0.07828"
"67.68000","5.64019","0.07845"
"67.86000","5.65519","0.07857"
"68.04000","5.67020","0.07898"
"68.22000","5.68521","0.07900"
"68.40000","5.70015","0.07921"
"68.58000","5.71522","0.07948"
"68.76000","5.73017","0.07957"
"68.94000","5.74512","0.07960"
"69.12000","5.76018","0.07983"
"69.30000","5.77513","0.08020"
"69.48000","5.79020","0.08056"
"69.66000","5.80515","0.08052"
"69.84000","5.82015","0.08062"
"70.02000","5.83516","0.08097"
"70.20000","5.85023","0.08105"
"70.38000","5.86517","0.08084"
"70.56000","5.88024","0.08176"
"70.74000","5.89519","0.08191"
"70.92000","5.91014","0.08290"
"71.10000","5.92520","0.08337"
"71.28000","5.94021","0.08432"
"71.46000","5.95516","0.08679"
"71.64000","5.97016","0.08617"
"71.82000","5.98517","0.08706"
"72.00000","6.00012","0.07975"
"72.18000","6.01519","0.07877"
"72.36000","6.03019","0.07883"
"72.54000","6.04514","0.07894"
"72.72000","6.06027","0.07901"
"72.90000","6.07521","0.07913"
"73.08000","6.09016","0.07959"
"73.26000","6.10517","0.07935"
"73.44000","6.12024","0.08005"
"73.62000","6.13518","0.07992"
"73.80000","6.15019","0.08017"
"73.98000","6.16520","0.08074"
"74.16000","6.18014","0.08042"
"74.34000","6.19515","0.08215"
"74.52000","6.21022","0.08187"
"74.70000","6.22517","0.08235"
"74.88000","6.24023","0.08332"
"75.06000","6.25524","0.08310"
"75.24000","6.27013","0.08524"
"75.42000","6.28520","0.08488"
"75.60000","6.30026","0.08647"
"75.78000","6.31515","0.08788"
"75.96000","6.33022","0.08806"
"76.14000","6.34522","0.09021"
"76.32000","6.36023","0.09078"
"76.50000","6.37518","0.08455"
"76.68000","6.39019","0.01723"
"76.86000","6.40513","0.01613"
"77.04000","6.42014","0.01994"
"77.22000","6.43527","0.01578"
"77.40000","6.45015","0.02462"
"77.58000","6.46516","0.02055"
"77.76000","6.48023","0.01961"
"77.94000","6.49512","0.02113"
"78.12000","6.51018","0.02322"
"78.30000","6.52519","0.01914"
"78.48000","6.54020","0.02270"
"78.66000","6.55514","0.02433"
"78.84000","6.57021","0.02223"
"79.02000","6.58516","0.02473"
"79.20000","6.60023","0.02362"
"79.38000","6.61523","0.02219"
"79.56000","6.63012","0.02647"
"79.74000","6.64525","0.02568"
"79.92000","6.66019","0.02431"
"80.10000","6.67514","0.02725"
"80.28000","6.69021","0.02496"
"80.46000","6.70522","0.02676"
"80.64000","6.72016","0.02835"
"80.82000","6.73523","0.02557"
"81.00000","6.75024","0.02816"
"81.18000","6.76513","0.02725"
"81.36000","6.78019","0.02708"
"81.54000","6.79520","0.03059"
"81.72000","6.81015","0.02758"
"81.90000","6.82521","0.02860"
"82.08000","6.84022","0.03021"
"82.26000","6.85511","0.02782"
"82.44000","6.87018","0.03083"
"82.62000","6.88524","0.03048"
"82.80000","6.90013","0.02946"
"82.98000","6.91520","0.03304"
"83.16000","6.93020","0.03065"
"83.34000","6.94515","0.03103"
"83.52000","6.96022","0.03527"
"83.70000","6.97523","0.03126"
"83.88000","6.99011","0.03505"
"84.06000","7.00518","0.03572"
"84.24000","7.02025","0.03322"
"84.42000","7.03514","0.03938"
"84.60000","7.05020","0.03459"
"84.78000","7.06521","0.03734"
"84.96000","7.08016","0.04083"
"85.14000","7.09522","0.03675"
"85.32000","7.11017","0.04360"
"85.50000","7.12518","0.04064"
"85.68000","7.14025","0.04015"
"85.86000","7.15519","0.04689"
"86.04000","7.17014","0.04146"
"86.22000","7.18527","0.04616"
"86.40000","7.20015","0.04757"
"86.58000","7.21510","0.03941"
"86.76000","7.23017","0.04693"
"86.94000","7.24518","0.04271"
"87.12000","7.26012","0.04488"
"87.30000","7.27519","0.04912"
"87.48000","7.29020","0.04410"
"87.66000","7.30521","0.05138"
"87.84000","7.32021","0.04849"
"88.02000","7.33516","0.04941"
"88.20000","7.35011","0.05384"
"88.38000","7.36523","0.04969"
"88.56000","7.38024","0.05477"
"88.74000","7.39513","0.05421"
"88.92000","7.41020","0.05337"
"89.10000","7.42520","0.05850"
"89.28000","7.44015","0.05507"
"89.46000","7.45522","0.05904"
"89.64000","7.47022","0.05831"
"89.82000","7.48517","0.05749"
"90.00000","7.50024","0.06168"
"90.18000","7.51519","0.05884"
"90.36000","7.53013","0.06249"
"90.54000","7.54526","0.06171"
"90.72000","7.56021","0.06155"
"90.90000","7.57509","0.06575"
"91.08000","7.59022","0.06168"
"91.26000","7.60523","0.06613"
"91.44000","7.62012","0.06557"
"91.62000","7.63518","0.06442"
"91.80000","7.65025","0.06448"
"91.98000","7.66520","0.05503"
"92.16000","7.68021","0.05946"
"92.34000","7.69521","0.05978"
"92.52000","7.71016","0.05948"
"92.70000","7.72517","0.06325"
"92.88000","7.74023","0.06185"
"93.06000","7.75506","0.06572"
"93.24000","7.77025","0.06559"
"93.42000","7.78520","0.06579"
"93.60000","7.80014","0.06967"
"93.78000","7.81521","0.06729"
"93.96000","7.83022","0.07169"
"94.14000","7.84516","0.07102"
"94.32000","7.86023","0.07132"
"94.50000","7.87518","0.07447"
"94.68000","7.89019","0.07290"
"94.86000","7.90525","0.07616"
"95.04000","7.92014","0.07590"
"95.22000","7.93509","0.07603"
"95.40000","7.95021","0.07784"
"95.58000","7.96516","0.07724"
"95.76000","7.98011","0.07849"
"95.94000","7.99524","0.07805"
"96.12000","8.01018","0.07885"
"96.30000","8.02513","0.07906"
"96.48000","8.04020","0.07886"
"96.66000","8.05520","0.07974"
"96.84000","8.07015","0.07922"
"97.02000","8.08522","0.08029"
"97.20000","8.10017","0.08011"
"97.38000","8.11511","0.08079"
"97.56000","8.13024","0.08222"
"97.74000","8.14525","0.08092"
"97.92000","8.16013","0.08376"
"98.10000","8.17520","0.08236"
"98.28000","8.19021","0.08480"
"98.46000","8.20516","0.08549"
"98.64000","8.22016","0.08601"
"98.82000","8.23517","0.09001"
"99.00000","8.25018","0.08870"
"99.18000","8.26519","0.09330"
"99.36000","8.28013","0.09113"
"99.54000","8.29514","0.09547"
"99.72000","8.31021","0.09639"
"99.90000","8.32515","0.09661"
"100.08000","8.34016","0.09984"
"100.26000","8.35517","0.09907"
"100.44000","8.37018","0.10240"
"100.62000","8.38518","0.10117"
"100.80000","8.40019","0.10413"
"100.98000","8.41526","0.10454"
"101.16000","8.43020","0.10553"
"101.34000","8.44515","0.10709"
"101.52000","8.46016","0.10696"
"101.70000","8.47517","0.10907"
"101.88000","8.49017","0.10840"
"102.06000","8.50524","0.11083"
"102.24000","8.52013","0.11010"
"102.42000","8.53525","0.11213"
"102.60000","8.55020","0.11259"
"102.78000","8.56515","0.11278"
"102.96000","8.58016","0.11414"
"103.14000","8.59522","0.11378"
"103.32000","8.61023","0.11519"
"103.50000","8.62518","0.11479"
"103.68000","8.64013","0.11659"
"103.86000","8.65519","0.11639"
"104.04000","8.67020","0.11745"
"104.22000","8.68515","0.11786"
"104.40000","8.70015","0.11863"
"104.58000","8.71516","0.12014"
"104.76000","8.73017","0.12034"
"104.94000","8.74512","0.12200"
"105.12000","8.76018","0.12158"
"105.30000","8.77525","0.12331"
"105.48000","8.79020","0.12302"
"105.66000","8.80520","0.12461"
"105.84000","8.82015","0.12453"
"106.02000","8.83516","0.12536"
"106.20000","8.85023","0.12577"
"106.38000","8.86517","0.12643"
"106.56000","8.88018","0.12717"
"106.74000","8.89525","0.12735"
"106.92000","8.91020","0.12361"
"107.10000","8.92514","0.12377"
"107.28000","8.94021","0.12527"
"107.46000","8.95522","0.12545"
"107.64000","8.97016","0.12709"
"107.82000","8.98517","0.12695"
"108.00000","9.00018","0.12799"
"108.18000","9.01519","0.12842"
"108.36000","9.03019","0.12942"
"108.54000","9.04514","0.13005"
"108.72000","9.06015","0.13033"
"108.90000","9.07527","0.13183"
"109.08000","9.09016","0.13185"
"109.26000","9.10517","0.13383"
"109.44000","9.12024","0.13442"
"109.62000","9.13518","0.13633"
"109.80000","9.15019","0.13660"
"109.98000","9.16520","0.13943"
"110.16000","9.18021","0.13905"
"110.34000","9.19521","0.14304"
"110.52000","9.21016","0.14406"
"110.70000","9.22517","0.14757"
"110.88000","9.24017","0.14929"
"111.06000","9.25524","0.15322"
"111.24000","9.27013","0.15447"
"111.42000","9.28514","0.15829"
"111.60000","9.30020","0.16106"
"111.78000","9.31521","0.16330"
"111.96000","9.33016","0.16739"
"112.14000","9.34516","0.16969"
"112.32000","9.36017","0.17307"
"112.50000","9.37518","0.17347"
"112.68000","9.39019","0.17648"
"112.86000","9.40513","0.17603"
"113.04000","9.42020","0.17884"
"113.22000","9.43515","0.17923"
"113.40000","9.45015","0.18082"
"113.58000","9.46516","0.18065"
"113.76000","9.48023","0.18229"
"113.94000","9.49518","0.18221"
"114.12000","9.51012","0.18320"
"114.30000","9.52519","0.18384"
"114.48000","9.54020","0.18444"
"114.66000","9.55515","0.18480"
"114.84000","9.57021","0.18605"
"115.02000","9.58516","0.18679"
"115.20000","9.60023","0.18841"
"115.38000","9.61523","0.18943"
"115.56000","9.63018","0.19199"
"115.74000","9.64519","0.19185"
"115.92000","9.66019","0.19453"
"116.10000","9.67520","0.19569"
"116.28000","9.69015","0.19828"
"116.46000","9.70522","0.19867"
"116.64000","9.72010","0.20241"
"116.82000","9.73517","0.20236"
"117.00000","9.75024","0.20493"
"117.18000","9.76519","0.20614"
"117.36000","9.78013","0.20776"
"117.54000","9.79520","0.20899"
"117.72000","9.81021","0.21126"
"117.90000","9.82515","0.21178"
"118.08000","9.84028","0.21406"
"118.26000","9.85517","0.21349"
"118.44000","9.87018","0.13020"
"118.62000","9.88518","0.12403"
"118.80000","9.90019","0.12607"
"118.98000","9.91514","0.12655"
"119.16000","9.93014","0.12528"
"119.34000","9.94515","0.13051"
"119.52000","9.96022","0.12625"
"119.70000","9.97517","0.13412"
"119.88000","9.99017","0.12698"
"120.06000","10.00518","0.13518"
"120.24000","10.02025","0.12951"
"120.42000","10.03514","0.13584"
"120.60000","10.05014","0.13171"
"120.78000","10.06515","0.13443"
"120.96000","10.08010","0.13740"
"121.14000","10.09522","0.13595"
"121.32000","10.11017","0.14529"
"121.50000","10.12518","0.13662"
"121.68000","10.14019","0.15605"
"121.86000","10.15519","0.13987"
"122.04000","10.17014","0.16484"
"122.22000","10.18521","0.14524"
"122.40000","10.20021","0.16904"
"122.58000","10.21516","0.15052"
"122.76000","10.23023","0.17030"
"122.94000","10.24518","0.15737"
"123.12000","10.26012","0.17207"
"123.30000","10.27519","0.16650"
"123.48000","10.29020","0.17425"
"123.66000","10.30515","0.17523"
"123.84000","10.32021","0.17608"
"124.02000","10.33522","0.18011"
"124.20000","10.35017","0.17847"
"124.38000","10.36523","0.18251"
"124.56000","10.38018","0.18021"
"124.74000","10.39519","0.18409"
"124.92000","10.41019","0.18168"
"125.10000","10.42520","0.18711"
"125.28000","10.44009","0.18318"
"125.46000","10.45516","0.18989"
"125.64000","10.47022","0.18442"
"125.82000","10.48517","0.19483"
"126.00000","10.50024","0.18583"
"126.18000","10.51519","0.19928"
"126.36000","10.53019","0.18905"
"126.54000","10.54520","0.20233"
"126.72000","10.56021","0.19152"
"126.90000","10.57515","0.20517"
"127.08000","10.59016","0.19566"
"127.26000","10.60523","0.20761"
"127.44000","10.62018","0.19857"
"127.62000","10.63518","0.20521"
"127.80000","10.65019","0.19756"
"127.98000","10.66514","0.20929"
"128.16000","10.68020","0.20260"
"128.34000","10.69521","0.21292"
"128.52000","10.71022","0.20673"
"128.70000","10.72523","0.21621"
"128.88000","10.74023","0.21052"
"129.06000","10.75518","0.21966"
"129.24000","10.77019","0.21476"
"129.42000","10.78520","0.22207"
"129.60000","10.80014","0.21736"
"129.78000","10.81515","0.22460"
"129.96000","10.83022","0.22064"
"130.14000","10.84516","0.22630"
"130.32000","10.86017","0.22363"
"130.50000","10.87524","0.22734"
"130.68000","10.89012","0.22497"
"130.86000","10.90525","0.22836"
"131.04000","10.92020","0.22647"
"131.22000","10.93515","0.22914"
"131.40000","10.95021","0.22736"
"131.58000","10.96522","0.22988"
"131.76000","10.98011","0.22843"
"131.94000","10.99518","0.23054"
"132.12000","11.01024","0.22923"
"132.30000","11.02513","0.23151"
"132.48000","11.04020","0.23015"
"132.66000","11.05520","0.23221"
"132.84000","11.07015","0.23142"
"133.02000","11.08522","0.23334"
"133.20000","11.10017","0.23263"
"133.38000","11.11511","0.23453"
"133.56000","11.13018","0.23453"
"133.74000","11.14519","0.23573"
"133.92000","11.16014","0.23791"
"134.10000","11.17514","0.23704"
"134.28000","11.19021","0.24072"
"134.46000","11.20516","0.23790"
"134.64000","11.22022","0.24433"
"134.82000","11.23517","0.24003"
"135.00000","11.25018","0.24875"
"135.18000","11.26519","0.24291"
"135.36000","11.28019","0.25229"
"135.54000","11.29514","0.24657"
"135.72000","11.31021","0.25472"
"135.90000","11.32521","0.25057"
"136.08000","11.34010","0.25728"
"136.26000","11.35517","0.25559"
"136.44000","11.37024","0.25882"
"136.62000","11.38518","0.26025"
"136.80000","11.40019","0.26031"
"136.98000","11.41514","0.26497"
"137.16000","11.43020","0.26247"
"137.34000","11.44521","0.26918"
"137.52000","11.46016","0.26477"
"137.70000","11.47511","0.27273"
"137.88000","11.49017","0.26896"
"138.06000","11.50518","0.27484"
"138.24000","11.52013","0.27264"
"138.42000","11.53519","0.27586"
"138.60000","11.55020","0.27554"
"138.78000","11.56515","0.27620"
"138.96000","11.58016","0.27746"
"139.14000","11.59522","0.27722"
"139.32000","11.61017","0.28023"
"139.50000","11.62518","0.27861"
"139.68000","11.64019","0.28266"
"139.86000","11.65513","0.28080"
"140.04000","11.67026","0.28492"
"140.22000","11.68515","0.28167"
"140.40000","11.70009","0.00959"
"140.58000","11.71522","-0.00131"
"140.76000","11.73023","-0.00351"
"140.94000","11.74512","-0.00346"
"141.12000","11.76018","-0.00525"
"141.30000","11.77519","0.00632"
"141.48000","11.79014","0.02180"
"141.66000","11.80526","0.00633"
"141.84000","11.82021","-0.00381"
"142.02000","11.83516","0.01213"
"142.20000","11.85017","0.01294"
"142.38000","11.86517","0.00265"
"142.56000","11.88012","0.00928"
"142.74000","11.89525","0.01914"
"142.92000","11.91026","0.00620"
"143.10000","11.92514","0.00479"
"143.28000","11.94021","0.01510"
"143.46000","11.95522","0.00899"
"143.64000","11.97016","0.00793"
"143.82000","11.98517","0.01848"
"144.00000","12.00024","0.01482"
"144.18000","12.01512","0.00924"
"144.36000","12.03019","0.01767"
"144.54000","12.04520","0.01518"
"144.72000","12.06009","0.01047"
"144.90000","12.07527","0.01849"
"145.08000","12.09022","0.01525"
"145.26000","12.10517","0.01380"
"145.44000","12.12024","0.01841"
"145.62000","12.13518","0.01855"
"145.80000","12.15019","0.01487"
"145.98000","12.16520","0.02126"
"146.16000","12.18014","0.01973"
"146.34000","12.19515","0.01786"
"146.52000","12.21022","0.02231"
"146.70000","12.22517","0.02074"
"146.88000","12.24017","0.02011"
"147.06000","12.25524","0.02268"
"147.24000","12.27019","0.02341"
"147.42000","12.28508","0.02214"
"147.60000","12.30020","0.02378"
"147.78000","12.31527","0.02475"
"147.96000","12.33016","0.02309"
"148.14000","12.34516","0.02527"
"148.32000","12.36017","0.02583"
"148.50000","12.37518","0.02517"
"148.68000","12.39019","0.02628"
"148.86000","12.40513","0.02680"
"149.04000","12.42014","0.02696"
"149.22000","12.43521","0.02742"
"149.40000","12.45021","0.02743"
"149.58000","12.46516","0.02819"
"149.76000","12.48023","0.02828"
"149.94000","12.49523","0.02831"
"150.12000","12.51012","0.02957"
"150.30000","12.52519","0.02947"
"150.48000","12.54020","0.02985"
"150.66000","12.55520","0.03194"
"150.84000","12.57015","0.03168"
"151.02000","12.58516","0.03211"
"151.20000","12.60017","0.03460"
"151.38000","12.61517","0.03359"
"151.56000","12.63018","0.03516"
"151.74000","12.64513","0.03825"
"151.92000","12.66019","0.03623"
"152.10000","12.67520","0.03964"
"152.28000","12.69021","0.04271"
"152.46000","12.70522","0.04125"
"152.64000","12.72022","0.04584"
"152.82000","12.73517","0.04647"
"153.00000","12.75018","0.04590"
"153.18000","12.76519","0.05056"
"153.36000","12.78013","0.05032"
"153.54000","12.79520","0.05240"
"153.72000","12.81021","0.05587"
"153.90000","12.82515","0.05513"
"154.08000","12.84022","0.05741"
"154.26000","12.85517","0.05898"
"154.44000","12.87017","0.05958"
"154.62000","12.88518","0.06213"
"154.80000","12.90019","0.06333"
"154.98000","12.91514","0.06466"
"155.16000","12.93020","0.06772"
"155.34000","12.94515","0.06887"
"155.52000","12.96022","0.07096"
"155.70000","12.97517","0.07332"
"155.88000","12.99011","0.07457"
"156.06000","13.00512","0.07590"
"156.24000","13.02025","0.07736"
"156.42000","13.03520","0.07754"
"156.60000","13.05014","0.07850"
"156.78000","13.06521","0.07897"
"156.96000","13.08022","0.07933"
"157.14000","13.09516","0.08004"
"157.32000","13.11017","0.08005"
"157.50000","13.12518","0.08137"
"157.68000","13.14018","0.08196"
"157.86000","13.15519","0.08408"
"158.04000","13.17014","0.08676"
"158.22000","13.18515","0.08828"
"158.40000","13.20021","0.09189"
"158.58000","13.21522","0.09445"
"158.76000","13.23017","0.09665"
"158.94000","13.24518","0.09945"
"159.12000","13.26018","0.10060"
"159.30000","13.27513","0.10322"
"159.48000","13.29020","0.10588"
"159.66000","13.30514","0.10712"
"159.84000","13.32021","0.10931"
"160.02000","13.33516","0.11066"
"160.20000","13.35017","0.11236"
"160.38000","13.36517","0.11334"
"160.56000","13.38024","0.11429"
"160.74000","13.39519","0.11554"
"160.92000","13.41019","0.11659"
"161.10000","13.42520","0.11763"
"161.28000","13.44015","0.11887"
"161.46000","13.45516","0.12026"
"161.64000","13.47016","0.12184"
"161.82000","13.48517","0.12274"
"162.00000","13.50024","0.12432"
"162.18000","13.51519","0.12546"
"162.36000","13.53019","0.12653"
"162.54000","13.54520","0.12754"
"162.72000","13.56021","0.12836"
"162.90000","13.57521","0.12957"
"163.08000","13.59016","0.13087"
"163.26000","13.60523","0.13249"
"163.44000","13.62024","0.13377"
"163.62000","13.63518","0.13567"
"163.80000","13.65013","0.13838"
"163.98000","13.66520","0.14171"
"164.16000","13.68020","0.14446"
"164.34000","13.69515","0.14734"
"164.52000","13.71016","0.15206"
"164.70000","13.72523","0.15724"
"164.88000","13.74023","0.16192"
"165.06000","13.75524","0.16733"
"165.24000","13.77019","0.17091"
"165.42000","13.78526","0.17464"
"165.60000","13.80014","0.17715"
"165.78000","13.81521","0.17825"
"165.96000","13.83016","0.17985"
"166.14000","13.84516","0.18094"
"166.32000","13.86017","0.17346"
"166.50000","13.87524","0.14044"
"166.68000","13.89018","0.14341"
"166.86000","13.90519","0.14550"
"167.04000","13.92020","0.14856"
"167.22000","13.93515","0.15310"
"167.40000","13.95015","0.15548"
"167.58000","13.96522","0.16247"
"167.76000","13.98017","0.16377"
"167.94000","13.99512","0.17182"
"168.12000","14.01024","0.17274"
"168.30000","14.02519","0.17666"
"168.48000","14.04014","0.17935"
"168.66000","14.05520","0.17958"
"168.84000","14.07015","0.18181"
"169.02000","14.08516","0.18186"
"169.20000","14.10017","0.18371"
"169.38000","14.11517","0.18392"
"169.56000","14.13018","0.18566"
"169.74000","14.14525","0.18687"
"169.92000","14.16020","0.18860"
"170.10000","14.17514","0.19209"
"170.28000","14.19021","0.19305"
"170.46000","14.20516","0.19803"
"170.64000","14.22016","0.19860"
"170.82000","14.23523","0.20276"
"171.00000","14.25018","0.20416"
"171.18000","14.26518","0.20724"
"171.36000","14.28019","0.20860"
"171.54000","14.29514","0.21135"
"171.72000","14.31021","0.21362"
"171.90000","14.32521","0.21603"
"172.08000","14.34016","0.21823"
"172.26000","14.35517","0.21967"
"172.44000","14.37023","0.22182"
"172.62000","14.38518","0.22261"
"172.80000","14.40019","0.22488"
"172.98000","14.41520","0.22531"
"173.16000","14.43020","0.22645"
"173.34000","14.44521","0.22707"
"173.52000","14.46022","0.22783"
"173.70000","14.47517","0.22825"
"173.88000","14.49023","0.22902"
"174.06000","14.50518","0.22942"
"174.24000","14.52019","0.22987"
"174.42000","14.53519","0.23065"
"174.60000","14.55020","0.23111"
"174.78000","14.56515","0.23198"
"174.96000","14.58022","0.23253"
"175.14000","14.59522","0.23364"
"175.32000","14.61017","0.23430"
"175.50000","14.62524","0.23561"
"175.68000","14.64019","0.23653"
"175.86000","14.65513","0.23880"
"176.04000","14.67026","0.24106"
"176.22000","14.68521","0.24296"
"176.40000","14.70015","0.24446"
"176.58000","14.71516","0.24791"
"176.76000","14.73023","0.25017"
"176.94000","14.74512","0.25306"
"177.12000","14.76018","0.25474"
"177.30000","14.77525","0.25741"
"177.48000","14.79014","0.25917"
"177.66000","14.80520","0.26217"
"177.84000","14.82021","0.26382"
"178.02000","14.83516","0.26690"
"178.20000","14.85017","0.26917"
"178.38000","14.86523","0.27138"
"178.56000","14.88018","0.27302"
"178.74000","14.89519","0.27487"
"178.92000","14.91025","0.27532"
"179.10000","14.92514","0.27698"
"179.28000","14.94021","0.27759"
"179.46000","14.95522","0.27932"
"179.64000","14.97016","0.28013"
"179.82000","14.98517","0.28184"
"180.00000","15.00018","0.28386"
"180.18000","15.01518","0.28653"
"180.36000","15.03019","0.28955"
"180.54000","15.04520","0.29438"
"180.72000","15.06015","0.29692"
"180.90000","15.07521","0.30251"
"181.08000","15.09022","0.30572"
"181.26000","15.10517","0.31011"
"181.44000","15.12018","0.31312"
"181.62000","15.13518","0.31677"
"181.80000","15.15013","0.31913"
"181.98000","15.16520","0.32225"
"182.16000","15.18020","0.32439"
"182.34000","15.19515","0.32688"
"182.52000","15.21022","0.32870"
"182.70000","15.22523","0.33108"
"182.88000","15.24011","0.33238"
"183.06000","15.25524","0.33389"
"183.24000","15.27019","0.33462"
"183.42000","15.28514","0.33562"
"183.60000","15.30020","0.33605"
"183.78000","15.31521","0.33662"
"183.96000","15.33016","0.33719"
"184.14000","15.34522","0.33775"
"184.32000","15.36017","0.33845"
"184.50000","15.37512","0.33874"
"184.68000","15.39025","0.33942"
"184.86000","15.40519","0.33975"
"185.04000","15.42014","0.34048"
"185.22000","15.43521","0.34179"
"185.40000","15.45021","0.34257"
"185.58000","15.46516","0.34291"
"185.76000","15.48017","0.34443"
"185.94000","15.49524","0.34499"
"186.12000","15.51012","0.34627"
"186.30000","15.52519","0.34782"
"186.48000","15.54020","0.34894"
"186.66000","15.55520","0.35031"
"186.84000","15.57015","0.35169"
"187.02000","15.58522","0.35289"
"187.20000","15.60017","0.35550"
"187.38000","15.61517","0.35663"
"187.56000","15.63018","0.35943"
"187.74000","15.64513","0.36137"
"187.92000","15.66019","0.36402"
"188.10000","15.67526","0.36712"
"188.28000","15.69015","0.36846"
"188.46000","15.70516","0.37056"
"188.64000","15.72016","0.37250"
"188.82000","15.73517","0.37332"
"189.00000","15.75018","0.26394"
"189.18000","15.76518","0.25272"
"189.36000","15.78013","0.25566"
"189.54000","15.79520","0.25233"
"189.72000","15.81021","0.25465"
"189.90000","15.82521","0.25550"
"190.08000","15.84022","0.25502"
"190.26000","15.85523","0.25714"
"190.44000","15.87011","0.25773"
"190.62000","15.88518","0.25942"
"190.80000","15.90025","0.26107"
"190.98000","15.91520","0.26276"
"191.16000","15.93020","0.26221"
"191.34000","15.94515","0.26670"
"191.52000","15.96016","0.26418"
"191.70000","15.97522","0.26929"
"191.88000","15.99017","0.26717"
"192.06000","16.00512","0.27074"
"192.24000","16.02019","0.27050"
"192.42000","16.03525","0.27354"
"192.60000","16.05014","0.27302"
"192.78000","16.06515","0.27519"
"192.96000","16.08022","0.27370"
"193.14000","16.09510","0.27669"
"193.32000","16.11023","0.27585"
"193.50000","16.12518","0.27764"
"193.68000","16.14012","0.27664"
"193.86000","16.15519","0.27848"
"194.04000","16.17020","0.27801"
"194.22000","16.18509","0.27953"
"194.40000","16.20021","0.27896"
"194.58000","16.21522","0.28165"
"194.76000","16.23011","0.28021"
"194.94000","16.24517","0.28344"
"195.12000","16.26024","0.28268"
"195.30000","16.27519","0.28529"
"195.48000","16.29020","0.28528"
"195.66000","16.30520","0.28901"
"195.84000","16.32015","0.28811"
"196.02000","16.33516","0.29263"
"196.20000","16.35016","0.29132"
"196.38000","16.36511","0.29515"
"196.56000","16.38024","0.29667"
"196.74000","16.39519","0.29816"
"196.92000","16.41014","0.30039"
"197.10000","16.42520","0.30268"
"197.28000","16.44015","0.30326"
"197.46000","16.45515","0.30642"
"197.64000","16.47022","0.30770"
"197.82000","16.48517","0.30861"
"198.00000","16.50018","0.31199"
"198.18000","16.51524","0.31234"
"198.36000","16.53013","0.31486"
"198.54000","16.54514","0.31502"
"198.72000","16.56021","0.31715"
"198.90000","16.57515","0.31793"
"199.08000","16.59016","0.32156"
"199.26000","16.60517","0.31991"
"199.44000","16.62023","0.32314"
"199.62000","16.63512","0.32237"
"199.80000","16.65019","0.32486"
"199.98000","16.66520","0.32472"
"200.16000","16.68020","0.32666"
"200.34000","16.69521","0.32525"
"200.52000","16.71016","0.32862"
"200.70000","16.72517","0.32705"
"200.88000","16.74023","0.32932"
"201.06000","16.75518","0.32921"
"201.24000","16.77013","0.33077"
"201.42000","16.78519","0.33006"
"201.60000","16.80020","0.33150"
"201.78000","16.81503","0.33136"
"201.96000","16.83022","0.33259"
"202.14000","16.84522","0.33256"
"202.32000","16.86017","0.33334"
"202.50000","16.87524","0.33377"
"202.68000","16.89018","0.33426"
"202.86000","16.90513","0.33491"
"203.04000","16.92020","0.33525"
"203.22000","16.93515","0.33545"
"203.40000","16.95009","0.33543"
"203.58000","16.96522","0.33624"
"203.76000","16.98023","0.33614"
"203.94000","16.99512","0.33674"
"204.12000","17.01018","0.33669"
"204.30000","17.02519","0.33711"
"204.48000","17.04020","0.33717"
"204.66000","17.05514","0.33739"
"204.84000","17.07021","0.33778"
"205.02000","17.08516","0.33780"
"205.20000","17.10022","0.33812"
"205.38000","17.11523","0.33819"
"205.56000","17.13018","0.33821"
"205.74000","17.14525","0.33864"
"205.92000","17.16019","0.33864"
"206.10000","17.17514","0.33893"
"206.28000","17.19015","0.33891"
"206.46000","17.20522","0.33915"
"206.64000","17.22016","0.33961"
"206.82000","17.23517","0.33966"
"207.00000","17.25018","0.33997"
"207.18000","17.26518","0.34034"
"207.36000","17.28019","0.33997"
"207.54000","17.29514","0.34015"
"207.72000","17.31015","0.33971"
"207.90000","17.32521","0.33933"
"208.08000","17.34016","0.21383"
"208.26000","17.35517","0.21468"
"208.44000","17.37017","0.21021"
"208.62000","17.38518","0.19419"
"208.80000","17.40019","0.18788"
"208.98000","17.41520","0.19018"
"209.16000","17.43014","0.18469"
"209.34000","17.44521","0.18665"
"209.52000","17.46016","0.18430"
"209.70000","17.47517","0.18510"
"209.88000","17.49017","0.18448"
"210.06000","17.50518","0.18497"
"210.24000","17.52019","0.18517"
"210.42000","17.53519","0.18442"
"210.60000","17.55020","0.18546"
"210.78000","17.56521","0.18322"
"210.96000","17.58015","0.18390"
"211.14000","17.59522","0.18271"
"211.32000","17.61017","0.18354"
"211.50000","17.62518","0.18301"
"211.68000","17.64018","0.18315"
"211.86000","17.65513","0.18311"
"212.04000","17.67020","0.18300"
"212.22000","17.68521","0.18372"
"212.40000","17.70015","0.18313"
"212.58000","17.71516","0.18401"
"212.76000","17.73023","0.18361"
"212.94000","17.74523","0.18435"
"213.12000","17.76018","0.18452"
"213.30000","17.77519","0.18483"
"213.48000","17.79014","0.18577"
"213.66000","17.80514","0.18523"
"213.84000","17.82021","0.18634"
"214.02000","17.83516","0.18605"
"214.20000","17.85016","0.18704"
"214.38000","17.86517","0.18631"
"214.56000","17.88018","0.18768"
"214.74000","17.89513","0.18822"
"214.92000","17.91019","0.18868"
"215.10000","17.92520","0.18888"
"215.28000","17.94015","0.18376"
"215.46000","17.95522","0.17984"
"215.64000","17.97022","-0.01383"
"215.82000","17.98517","-0.00586"
"216.00000","18.00018","-0.00805"
"216.18000","18.01518","-0.00170"
"216.36000","18.03025","-0.00474"
"216.54000","18.04526","-0.00563"
"216.72000","18.06015","-0.00456"
"216.90000","18.07521","-0.00416"
"217.08000","18.09022","-0.00365"
"217.26000","18.10517","-0.00345"
"217.44000","18.12017","-0.00466"
"217.62000","18.13518","-0.00514"
"217.80000","18.15013","-0.00391"
"217.98000","18.16520","-0.00436"
"218.16000","18.18020","-0.00476"
"218.34000","18.19515","-0.00384"
"218.52000","18.21022","-0.00414"
"218.70000","18.22516","-0.00472"
"218.88000","18.24017","-0.00475"
"219.06000","18.25518","-0.00393"
"219.24000","18.27025","-0.00477"
"219.42000","18.28514","-0.00444"
"219.60000","18.30014","-0.00380"
"219.78000","18.31521","-0.00470"
"219.96000","18.33015","-0.00545"
"220.14000","18.34516","-0.00391"
"220.32000","18.36017","-0.00444"
"220.50000","18.37518","-0.00461"
"220.68000","18.39018","-0.00421"
"220.86000","18.40519","-0.00382"
"221.04000","18.42014","-0.00466"
"221.22000","18.43521","-0.00440"
"221.40000","18.45021","-0.00387"
"221.58000","18.46516","-0.00416"
"221.76000","18.48017","-0.00469"
"221.94000","18.49517","-0.00416"
"222.12000","18.51018","-0.00447"
"222.30000","18.52525","-0.00474"
"222.48000","18.54020","-0.00437"
"222.66000","18.55520","-0.00392"
"222.84000","18.57021","-0.00482"
"223.02000","18.58516","-0.00417"
"223.20000","18.60023","-0.00420"
"223.38000","18.61517","-0.00411"
"223.56000","18.63018","-0.00454"
"223.74000","18.64519","-0.00411"
"223.92000","18.66019","-0.00427"
"224.10000","18.67520","-0.00466"
"224.28000","18.69015","-0.00380"
"224.46000","18.70516","-0.00434"
"224.64000","18.72016","-0.00474"
"224.82000","18.73517","-0.00401"
"225.00000","18.75018","-0.00414"
"225.18000","18.76518","-0.00415"
"225.36000","18.78013","-0.00447"
"225.54000","18.79520","-0.00433"
"225.72000","18.81021","-0.00394"
"225.90000","18.82515","-0.00396"
"226.08000","18.84022","-0.00439"
"226.26000","18.85523","-0.00408"
"226.44000","18.87017","-0.00475"
"226.62000","18.88518","-0.00414"
"226.80000","18.90019","-0.00426"
"226.98000","18.91514","-0.00434"
"227.16000","18.93020","-0.00399"
"227.34000","18.94521","-0.00403"
"227.52000","18.96010","-0.00404"
"227.70000","18.97522","-0.00430"
"227.88000","18.99023","-0.00329"
"228.06000","19.00518","-0.00404"
"228.24000","19.02019","-0.00408"
"228.42000","19.03525","-0.00405"
"228.60000","19.05014","-0.00413"
"228.78000","19.06515","-0.00363"
"228.96000","19.08022","-0.00435"
"229.14000","19.09516","-0.00369"
"229.32000","19.11017","-0.00457"
"229.50000","19.12524","-0.00369"
"229.68000","19.14018","-0.00411"
"229.86000","19.15519","-0.00406"
"230.04000","19.17026","-0.00413"
"230.22000","19.18515","-0.00360"
"230.40000","19.20021","-0.00404"
"230.58000","19.21522","-0.00399"
"230.76000","19.23011","-0.00372"
"230.94000","19.24524","-0.00405"
"231.12000","19.26018","-0.00398"
"231.30000","19.27519","-0.00365"
"231.48000","19.29020","-0.00388"
"231.66000","19.30520","-0.00439"
"231.84000","19.32015","-0.00334"
"232.02000","19.33522","-0.00345"
"232.20000","19.35017","-0.00402"
"232.38000","19.36517","-0.00360"
"232.56000","19.38024","-0.00419"
"232.74000","19.39519","-0.00371"
"232.92000","19.41013","-0.00367"
"233.10000","19.42514","-0.00376"
"233.28000","19.44021","-0.00342"
"233.46000","19.45515","-0.00412"
"233.64000","19.47016","-0.00317"
"233.82000","19.48517","-0.00387"
"234.00000","19.50018","-0.00405"
"234.18000","19.51524","-0.00337"
"234.36000","19.53019","-0.00388"
"234.54000","19.54514","-0.00308"
"234.72000","19.56021","-0.00370"
"234.90000","19.57521","-0.00309"
"235.08000","19.59016","-0.00357"
"235.26000","19.60517","-0.00383"
"235.44000","19.62017","-0.00315"
"235.62000","19.63512","-0.00348"
"235.80000","19.65019","-0.00335"
"235.98000","19.66520","-0.00306"
"236.16000","19.68014","-0.00283"
"236.34000","19.69527","-0.00333"
"236.52000","19.71016","-0.00316"
"236.70000","19.72511","-0.00328"
"236.88000","19.74023","-0.00325"
"237.06000","19.75524","-0.00306"
"237.24000","19.77013","-0.00356"
"237.42000","19.78513","-0.00314"
"237.60000","19.80020","-0.00316"
"237.78000","19.81515","-0.00302"
"237.96000","19.83016","-0.00311"
"238.14000","19.84516","-0.00334"
"238.32000","19.86017","-0.00319"
"238.50000","19.87518","-0.00278"
"238.68000","19.89024","-0.00332"
"238.86000","19.90513","-0.00308"
"239.04000","19.92020","-0.00336"
"239.22000","19.93520","-0.00285"
"239.40000","19.95015","-0.00321"
"239.58000","19.96522","-0.00306"
"239.76000","19.98023","-0.00289"
"239.94000","19.99517","-0.00334"
"240.12000","20.01018","-0.00287"
"240.30000","20.02519","-0.00291"
"240.48000","20.04020","-0.00301"
"240.66000","20.05520","-0.00284"
"240.84000","20.07021","-0.00325"
"241.02000","20.08516","-0.00303"
"241.20000","20.10028","-0.00303"
"241.38000","20.11517","-0.00293"
"241.56000","20.13012","-0.00277"
"241.74000","20.14524","-0.00255"
"241.92000","20.16025","-0.00351"
"242.10000","20.17520","-0.00259"
"242.28000","20.19021","-0.00274"
"242.46000","20.20521","-0.00262"
"242.64000","20.22010","-0.00303"
"242.82000","20.23523","-0.00342"
"243.00000","20.25023","-0.00197"
"243.18000","20.26518","-0.00242"
"243.36000","20.28025","-0.00301"
"243.54000","20.29520","-0.00264"
"243.72000","20.31009","-0.00284"
"243.90000","20.32521","-0.00274"
"244.08000","20.34022","-0.00250"
"244.26000","20.35511","-0.00228"
"244.44000","20.37017","-0.00236"
"244.62000","20.38524","-0.00261"
"244.80000","20.40013","-0.00225"
"244.98000","20.41525","-0.00258"
"245.16000","20.43014","-0.00234"
"245.34000","20.44515","-0.00284"
"245.52000","20.46022","-0.00263"
"245.70000","20.47517","-0.00229"
"245.88000","20.49011","-0.00241"
"246.06000","20.50518","-0.00278"
"246.24000","20.52019","-0.00245"
"246.42000","20.53519","-0.00236"
"246.60000","20.55020","-0.00236"
"246.78000","20.56521","-0.00252"
"246.96000","20.58015","-0.00271"
"247.14000","20.59516","-0.00235"
"247.32000","20.61017","-0.00255"
"247.50000","20.62518","-0.00273"
"247.68000","20.64024","-0.00201"
"247.86000","20.65519","-0.00255"
"248.04000","20.67014","-0.00269"
"248.22000","20.68526","-0.00220"
"248.40000","20.70021","-0.00209"
"248.58000","20.71510","-0.00222"
"248.76000","20.73023","-0.00203"
"248.94000","20.74523","-0.00178"
"249.12000","20.76018","-0.00244"
"249.30000","20.77519","-0.00157"
"249.48000","20.79020","-0.00242"
"249.66000","20.80520","-0.00147"
"249.84000","20.82021","-0.00232"
"250.02000","20.83516","-0.00201"
"250.20000","20.85011","-0.00182"
"250.38000","20.86517","-0.00194"
"250.56000","20.88012","-0.00218"
"250.74000","20.89513","-0.00202"
"250.92000","20.91019","-0.00190"
"251.10000","20.92520","-0.00212"
"251.28000","20.94015","-0.00221"
"251.46000","20.95515","-0.00159"
"251.64000","20.97022","-0.00229"
"251.82000","20.98517","-0.00207"
"252.00000","21.00018","-0.00147"
"252.18000","21.01518","-0.00228"
"252.36000","21.03013","-0.00185"
"252.54000","21.04526","-0.00193"
"252.72000","21.06020","-0.00199"
"252.90000","21.07509","-0.00210"
"253.08000","21.09022","-0.00189"
"253.26000","21.10523","-0.00240"
"253.44000","21.12011","-0.00201"
"253.62000","21.13518","-0.00194"
"253.80000","21.15025","-0.00199"
"253.98000","21.16514","-0.00125"
"254.16000","21.18020","-0.00196"
"254.34000","21.19521","-0.00190"
"254.52000","21.21016","-0.00219"
"254.70000","21.22517","-0.00142"
"254.88000","21.24017","-0.00180"
"255.06000","21.25512","-0.00175"
"255.24000","21.27024","-0.00158"
"255.42000","21.28519","-0.00220"
"255.60000","21.30020","-0.00165"
"255.78000","21.31515","-0.00147"
"255.96000","21.33021","-0.00124"
"256.14000","21.34516","-0.00149"
"256.32000","21.36017","-0.00100"
"256.50000","21.37518","-0.00154"
"256.68000","21.39018","-0.00217"
"256.86000","21.40519","-0.00114"
"257.04000","21.42014","-0.00172"
"257.22000","21.43514","-0.00190"
"257.40000","21.45021","-0.00158"
"257.58000","21.46522","-0.00108"
"257.76000","21.48017","-0.00106"
"257.94000","21.49523","-0.00073"
"258.12000","21.51018","-0.00086"
"258.30000","21.52519","-0.00119"
"258.48000","21.54020","-0.00154"
"258.66000","21.55515","-0.00083"
"258.84000","21.57021","-0.00050"
"259.02000","21.58522","-0.00117"
"259.20000","21.60016","-0.00082"
"259.38000","21.61517","-0.00106"
"259.56000","21.63018","-0.00123"
"259.74000","21.64519","-0.00072"
"259.92000","21.66019","-0.00118"
"260.10000","21.67520","-0.00123"
"260.28000","21.69021","-0.00073"
"260.46000","21.70515","-0.00054"
"260.64000","21.72016","-0.00107"
"260.82000","21.73517","-0.00066"
"261.00000","21.75017","-0.00094"
"261.18000","21.76518","-0.00114"
"261.36000","21.78013","-0.00047"
"261.54000","21.79514","-0.00061"
"261.72000","21.81021","-0.00074"
"261.90000","21.82521","-0.00110"
"262.08000","21.84016","-0.00061"
"262.26000","21.85523","-0.00059"
"262.44000","21.87023","0.00010"
"262.62000","21.88518","-0.00035"
"262.80000","21.90019","-0.00070"
"262.98000","21.91520","-0.00057"
"263.16000","21.93020","-0.00051"
"263.34000","21.94521","-0.00072"
"263.52000","21.96016","-0.00090"
"263.70000","21.97516","-0.00059"
"263.88000","21.99023","-0.00062"
"264.06000","22.00518","-0.00032"
"264.24000","22.02019","-0.00028"
"264.42000","22.03519","-0.00085"
"264.60000","22.05020","-0.00022"
"264.72400","22.06048","-0.00055"