File: Force_trajectories/170122_1/Specimen_RawData_10.csv
End date,"1/22/2017"
Specimen label,"12DT_90"
Maximum Load,"0.03407",N

Time,Extension,Load
(s),(mm),(N)
"0.00000","0.00006","-0.00067"
"0.25200","0.01979","0.00023"
"0.50400","0.04227","0.00030"
"0.75600","0.06326","0.00106"
"1.00800","0.08418","0.00089"
"1.26000","0.10523","0.00184"
"1.51200","0.12616","0.00154"
"1.76400","0.14720","0.00266"
"2.01600","0.16819","0.00248"
"2.26800","0.18917","0.00295"
"2.52000","0.21022","0.00332"
"2.77200","0.23121","0.00313"
"3.02400","0.25219","0.00362"
"3.27600","0.27318","0.00423"
"3.52800","0.29422","0.00423"
"3.78000","0.31515","0.00445"
"4.03200","0.33620","0.00452"
"4.28400","0.35712","0.00467"
"4.53600","0.37823","0.00473"
"4.78800","0.39915","0.00451"
"5.04000","0.42020","0.00568"
"5.29200","0.44113","0.00510"
"5.54400","0.46223","0.00562"
"5.79600","0.48322","0.00562"
"6.04800","0.50415","0.00567"
"6.30000","0.52519","0.00546"
"6.55200","0.54624","0.00639"
"6.80400","0.56722","0.00620"
"7.05600","0.58815","0.00696"
"7.30800","0.60920","0.00651"
"7.56000","0.63024","0.00696"
"7.81200","0.65123","0.00725"
"8.06400","0.67215","0.00807"
"8.31600","0.69320","0.00743"
"8.56800","0.71419","0.00739"
"8.82000","0.73523","0.00728"
"9.07200","0.75616","0.00740"
"9.32400","0.77720","0.00824"
"9.57600","0.79819","0.00768"
"9.82800","0.81924","0.00790"
"10.08000","0.84022","0.00789"
"10.33200","0.86121","0.00842"
"10.58400","0.88219","0.00821"
"10.83600","0.90324","0.00901"
"11.08800","0.92423","0.00761"
"11.34000","0.94515","0.00800"
"11.59200","0.96626","0.00809"
"11.84400","0.98718","0.00813"
"12.09600","1.00823","0.00812"
"12.34800","1.02916","0.00844"
"12.60000","1.05020","0.00851"
"12.85200","1.07119","0.00892"
"13.10400","1.09224","0.00910"
"13.35600","1.11316","0.00887"
"13.60800","1.13421","0.00896"
"13.86000","1.15519","0.00875"
"14.11200","1.17618","0.00883"
"14.36400","1.19723","0.00854"
"14.61600","1.21821","0.00924"
"14.86800","1.23926","0.00903"
"15.12000","1.26018","0.00909"
"15.37200","1.28123","0.00935"
"15.62400","1.30216","0.00919"
"15.87600","1.32326","0.00897"
"16.12800","1.34419","0.00866"
"16.38000","1.36517","0.00969"
"16.63200","1.38616","0.00917"
"16.88400","1.40727","0.00973"
"17.13600","1.42819","0.00998"
"17.38800","1.44924","0.00968"
"17.64000","1.47022","0.01016"
"17.89200","1.49115","0.01023"
"18.14400","1.51220","0.01022"
"18.39600","1.53318","0.01069"
"18.64800","1.55417","0.01071"
"18.90000","1.57516","0.01075"
"19.15200","1.59620","0.01000"
"19.40400","1.61713","0.01028"
"19.65600","1.63817","0.01047"
"19.90800","1.65916","0.01046"
"20.16000","1.68021","0.01111"
"20.41200","1.70119","0.01115"
"20.66400","1.72224","0.01071"
"20.91600","1.74322","0.01080"
"21.16800","1.76427","0.01080"
"21.42000","1.78520","0.01104"
"21.67200","1.80624","0.01165"
"21.92400","1.82723","0.01011"
"22.17600","1.84821","0.01011"
"22.42800","1.86920","0.01020"
"22.68000","1.89019","0.01008"
"22.93200","1.91123","0.00918"
"23.18400","1.93216","0.00921"
"23.43600","1.95326","0.00943"
"23.68800","1.97413","0.01040"
"23.94000","1.99524","0.00983"
"24.19200","2.01616","0.01016"
"24.44400","2.03721","0.00971"
"24.69600","2.05814","0.01008"
"24.94800","2.07924","0.01070"
"25.20000","2.10017","0.01069"
"25.45200","2.12121","0.01071"
"25.70400","2.14226","0.01069"
"25.95600","2.16325","0.01120"
"26.20800","2.18423","0.01088"
"26.46000","2.20516","0.01093"
"26.71200","2.22620","0.01024"
"26.96400","2.24713","0.01077"
"27.21600","2.26824","0.01035"
"27.46800","2.28916","0.01095"
"27.72000","2.31021","0.01002"
"27.97200","2.33119","0.01051"
"28.22400","2.35224","0.01078"
"28.47600","2.37317","0.01092"
"28.72800","2.39421","0.01068"
"28.98000","2.41520","0.01131"
"29.23200","2.43624","0.01157"
"29.48400","2.45723","0.01144"
"29.73600","2.47822","0.01149"
"29.98800","2.49920","0.01179"
"30.24000","2.52025","0.01199"
"30.49200","2.54123","0.01226"
"30.74400","2.56222","0.01197"
"30.99600","2.58321","0.01183"
"31.24800","2.60419","0.01212"
"31.50000","2.62524","0.01174"
"31.75200","2.64616","0.01235"
"32.00400","2.66715","0.01266"
"32.25600","2.68814","0.01281"
"32.50800","2.70924","0.01260"
"32.76000","2.73017","0.01274"
"33.01200","2.75122","0.01240"
"33.26400","2.77220","0.01292"
"33.51600","2.79325","0.01283"
"33.76800","2.81417","0.01324"
"34.02000","2.83522","0.01337"
"34.27200","2.85621","0.01335"
"34.52400","2.87719","0.01334"
"34.77600","2.89818","0.01406"
"35.02800","2.91916","0.01334"
"35.28000","2.94027","0.01367"
"35.53200","2.96120","0.01324"
"35.78400","2.98218","0.01305"
"36.03600","3.00311","0.01288"
"36.28800","3.02421","0.01326"
"36.54000","3.04520","0.01341"
"36.79200","3.06625","0.01363"
"37.04400","3.08717","0.01377"
"37.29600","3.10822","0.01384"
"37.54800","3.12920","0.01381"
"37.80000","3.15025","0.01376"
"38.05200","3.17118","0.01426"
"38.30400","3.19216","0.01496"
"38.55600","3.21321","0.01447"
"38.80800","3.23419","0.01415"
"39.06000","3.25518","0.01438"
"39.31200","3.27611","0.01496"
"39.56400","3.29727","0.01452"
"39.81600","3.31820","0.01479"
"40.06800","3.33919","0.01507"
"40.32000","3.36017","0.01462"
"40.57200","3.38122","0.01543"
"40.82400","3.40220","0.01583"
"41.07600","3.42319","0.01596"
"41.32800","3.44418","0.01568"
"41.58000","3.46522","0.01547"
"41.83200","3.48621","0.01576"
"42.08400","3.50719","0.01545"
"42.33600","3.52824","0.01638"
"42.58800","3.54917","0.01565"
"42.84000","3.57021","0.01573"
"43.09200","3.59114","0.01612"
"43.34400","3.61218","0.01644"
"43.59600","3.63317","0.01635"
"43.84800","3.65422","0.01660"
"44.10000","3.67514","0.01683"
"44.35200","3.69619","0.01746"
"44.60400","3.71718","0.01721"
"44.85600","3.73822","0.01770"
"45.10800","3.75915","0.01734"
"45.36000","3.78019","0.01803"
"45.61200","3.80118","0.01809"
"45.86400","3.82223","0.01813"
"46.11600","3.84321","0.01836"
"46.36800","3.86426","0.01788"
"46.62000","3.88524","0.01839"
"46.87200","3.90623","0.01824"
"47.12400","3.92722","0.01845"
"47.37600","3.94814","0.01861"
"47.62800","3.96919","0.01925"
"47.88000","3.99017","0.01884"
"48.13200","4.01122","0.01921"
"48.38400","4.03221","0.01871"
"48.63600","4.05319","0.01885"
"48.88800","4.07412","0.01901"
"49.14000","4.09522","0.01934"
"49.39200","4.11615","0.02014"
"49.64400","4.13726","0.02029"
"49.89600","4.15818","0.01958"
"50.14800","4.17917","0.02051"
"50.40000","4.20021","0.02028"
"50.65200","4.22120","0.02009"
"50.90400","4.24225","0.02068"
"51.15600","4.26317","0.02036"
"51.40800","4.28422","0.02094"
"51.66000","4.30515","0.02091"
"51.91200","4.32619","0.02116"
"52.16400","4.34718","0.02118"
"52.41600","4.36816","0.02062"
"52.66800","4.38921","0.02110"
"52.92000","4.41026","0.02103"
"53.17200","4.43124","0.02049"
"53.42400","4.45223","0.02039"
"53.67600","4.47321","0.02020"
"53.92800","4.49420","0.02027"
"54.18000","4.51519","0.02047"
"54.43200","4.53623","0.02059"
"54.68400","4.55722","0.02086"
"54.93600","4.57820","0.02095"
"55.18800","4.59919","0.02139"
"55.44000","4.62012","0.02121"
"55.69200","4.64116","0.02120"
"55.94400","4.66215","0.02136"
"56.19600","4.68325","0.02190"
"56.44800","4.70418","0.02148"
"56.70000","4.72517","0.02118"
"56.95200","4.74621","0.02167"
"57.20400","4.76720","0.02124"
"57.45600","4.78819","0.02212"
"57.70800","4.80923","0.02191"
"57.96000","4.83022","0.02256"
"58.21200","4.85120","0.02245"
"58.46400","4.87225","0.02278"
"58.71600","4.89318","0.02296"
"58.96800","4.91422","0.02295"
"59.22000","4.93521","0.02316"
"59.47200","4.95625","0.02339"
"59.72400","4.97712","0.02307"
"59.97600","4.99817","0.02366"
"60.22800","5.01915","0.02369"
"60.48000","5.04026","0.02412"
"60.73200","5.06112","0.02347"
"60.98400","5.08223","0.02429"
"61.23600","5.10322","0.02439"
"61.48800","5.12420","0.02444"
"61.74000","5.14519","0.02503"
"61.99200","5.16617","0.02493"
"62.24400","5.18716","0.02515"
"62.49600","5.20821","0.02464"
"62.74800","5.22919","0.02496"
"63.00000","5.25018","0.02489"
"63.25200","5.27122","0.02554"
"63.50400","5.29215","0.02532"
"63.75600","5.31320","0.02609"
"64.00800","5.33418","0.02553"
"64.26000","5.35523","0.02612"
"64.51200","5.37621","0.02635"
"64.76400","5.39720","0.02631"
"65.01600","5.41819","0.02664"
"65.26800","5.43923","0.02668"
"65.52000","5.46022","0.02661"
"65.77200","5.48121","0.02715"
"66.02400","5.50219","0.02696"
"66.27600","5.52312","0.02733"
"66.52800","5.54428","0.02675"
"66.78000","5.56515","0.02743"
"67.03200","5.58626","0.02738"
"67.28400","5.60718","0.02768"
"67.53600","5.62829","0.02769"
"67.78800","5.64915","0.02797"
"68.04000","5.67020","0.02798"
"68.29200","5.69113","0.02803"
"68.54400","5.71223","0.02803"
"68.79600","5.73322","0.02791"
"69.04800","5.75420","0.02827"
"69.30000","5.77525","0.02828"
"69.55200","5.79618","0.02875"
"69.80400","5.81722","0.02778"
"70.05600","5.83815","0.02832"
"70.30800","5.85920","0.02820"
"70.56000","5.88018","0.02903"
"70.81200","5.90117","0.02932"
"71.06400","5.92215","0.02914"
"71.31600","5.94320","0.02925"
"71.56800","5.96419","0.02915"
"71.82000","5.98523","0.02924"
"72.07200","6.00616","0.02953"
"72.32400","6.02720","0.02959"
"72.57600","6.04819","0.02943"
"72.82800","6.06924","0.02970"
"73.08000","6.09016","0.02921"
"73.33200","6.11127","0.02939"
"73.58400","6.13225","0.02991"
"73.83600","6.15324","0.02939"
"74.08800","6.17417","0.02999"
"74.34000","6.19515","0.02963"
"74.59200","6.21620","0.03037"
"74.84400","6.23718","0.03048"
"75.09600","6.25823","0.03099"
"75.34800","6.27916","0.03108"
"75.60000","6.30026","0.03068"
"75.85200","6.32119","0.03113"
"76.10400","6.34223","0.03136"
"76.35600","6.36316","0.03156"
"76.60800","6.38421","0.03100"
"76.86000","6.40525","0.03106"
"77.11200","6.42624","0.03143"
"77.36400","6.44717","0.03154"
"77.61600","6.46821","0.03137"
"77.86800","6.48920","0.03142"
"78.12000","6.51018","0.03167"
"78.37200","6.53123","0.03138"
"78.62400","6.55222","0.03179"
"78.87600","6.57320","0.03224"
"79.12800","6.59419","0.03207"
"79.38000","6.61517","0.03254"
"79.63200","6.63616","0.03252"
"79.88400","6.65727","0.03300"
"80.13600","6.67819","0.03294"
"80.38800","6.69918","0.03300"
"80.64000","6.72016","0.03286"
"80.89200","6.74127","0.03319"
"81.14400","6.76220","0.03339"
"81.39600","6.78324","0.03310"
"81.64800","6.80423","0.03333"
"81.90000","6.82521","0.03352"
"82.15200","6.84626","0.03382"
"82.40400","6.86719","0.03323"
"82.65600","6.88823","0.03380"
"82.90800","6.90916","0.03368"
"83.16000","6.93026","0.03380"
"83.41200","6.95113","0.03385"
"83.66400","6.97218","0.00419"
"83.91600","6.99316","0.00492"
"84.16800","7.01427","0.00755"
"84.42000","7.03514","0.00694"
"84.67200","7.05618","0.00816"
"84.92400","7.07723","0.00826"
"85.17600","7.09821","0.00712"
"85.42800","7.11920","0.00817"
"85.68000","7.14019","0.00735"
"85.93200","7.16117","0.00785"
"86.18400","7.18216","0.00807"
"86.43600","7.20320","0.00786"
"86.68800","7.22419","0.00777"
"86.94000","7.24524","0.00822"
"87.19200","7.26622","0.00867"
"87.44400","7.28721","0.00814"
"87.69600","7.30814","0.00800"
"87.94800","7.32918","0.00830"
"88.20000","7.35017","0.00839"
"88.45200","7.37121","0.00827"
"88.70400","7.39214","0.00879"
"88.95600","7.41324","0.00848"
"89.20800","7.43423","0.00884"
"89.46000","7.45522","0.00848"
"89.71200","7.47620","0.00851"
"89.96400","7.49719","0.00920"
"90.21600","7.51823","0.00875"
"90.46800","7.53916","0.00917"
"90.72000","7.56021","0.00947"
"90.97200","7.58113","0.00901"
"91.22400","7.60224","0.00838"
"91.47600","7.62317","0.00932"
"91.72800","7.64421","0.00968"
"91.98000","7.66514","0.00913"
"92.23200","7.68624","0.00918"
"92.48400","7.70717","0.00911"
"92.73600","7.72822","0.00895"
"92.98800","7.74920","0.00927"
"93.24000","7.77025","0.00961"
"93.49200","7.79123","0.00990"
"93.74400","7.81216","0.00984"
"93.99600","7.83327","0.00980"
"94.24800","7.85419","0.00992"
"94.50000","7.87524","0.00999"
"94.75200","7.89616","0.00941"
"95.00400","7.91721","0.00975"
"95.25600","7.93820","0.01015"
"95.50800","7.95924","0.01024"
"95.76000","7.98017","0.00984"
"96.01200","8.00121","0.01066"
"96.26400","8.02214","0.01063"
"96.51600","8.04325","0.01043"
"96.76800","8.06417","0.01084"
"97.02000","8.08522","0.01047"
"97.27200","8.10614","0.01116"
"97.52400","8.12719","0.01069"
"97.77600","8.14824","0.01047"
"98.02800","8.16922","0.01084"
"98.28000","8.19021","0.00994"
"98.53200","8.21119","0.01032"
"98.78400","8.23224","0.00997"
"99.03600","8.25311","0.01010"
"99.28800","8.27427","0.01033"
"99.54000","8.29514","0.01017"
"99.79200","8.31619","0.01037"
"100.04400","8.33717","0.01056"
"100.29600","8.35822","0.01008"
"100.54800","8.37914","0.01073"
"100.80000","8.40025","0.01052"
"101.05200","8.42118","0.01048"
"101.30400","8.44222","0.01011"
"101.55600","8.46321","0.01071"
"101.80800","8.48419","0.01057"
"102.06000","8.50524","0.01057"
"102.31200","8.52617","0.00990"
"102.56400","8.54721","0.01023"
"102.81600","8.56814","0.01092"
"103.06800","8.58924","0.01106"
"103.32000","8.61017","0.01114"
"103.57200","8.63122","0.01097"
"103.82400","8.65220","0.01163"
"104.07600","8.67319","0.01087"
"104.32800","8.69423","0.01123"
"104.58000","8.71528","0.01140"
"104.83200","8.73621","0.01139"
"105.08400","8.75719","0.01104"
"105.33600","8.77812","0.01167"
"105.58800","8.79917","0.01141"
"105.84000","8.82021","0.01187"
"106.09200","8.84120","0.01160"
"106.34400","8.86218","0.01177"
"106.59600","8.88323","0.01236"
"106.84800","8.90422","0.01252"
"107.10000","8.92514","0.01202"
"107.35200","8.94625","0.01237"
"107.60400","8.96717","0.01169"
"107.85600","8.98828","0.01253"
"108.10800","9.00915","0.01310"
"108.36000","9.03025","0.01267"
"108.61200","9.05118","0.01328"
"108.86400","9.07222","0.01280"
"109.11600","9.09315","0.01312"
"109.36800","9.11414","0.01302"
"109.62000","9.13524","0.01340"
"109.87200","9.15623","0.01274"
"110.12400","9.17722","0.01375"
"110.37600","9.19820","0.01391"
"110.62800","9.21925","0.01417"
"110.88000","9.24017","0.01396"
"111.13200","9.26122","0.01399"
"111.38400","9.28215","0.01396"
"111.63600","9.30319","0.01433"
"111.88800","9.32418","0.01454"
"112.14000","9.34522","0.01444"
"112.39200","9.36615","0.01447"
"112.64400","9.38720","0.01486"
"112.89600","9.40824","0.01496"
"113.14800","9.42923","0.01565"
"113.40000","9.45015","0.01595"
"113.65200","9.47120","0.01589"
"113.90400","9.49219","0.01588"
"114.15600","9.51317","0.01557"
"114.40800","9.53422","0.01603"
"114.66000","9.55520","0.01632"
"114.91200","9.57625","0.01600"
"115.16400","9.59718","0.01628"
"115.41600","9.61822","0.01710"
"115.66800","9.63909","0.01682"
"115.92000","9.66019","0.01692"
"116.17200","9.68118","0.01703"
"116.42400","9.70223","0.01830"
"116.67600","9.72315","0.01753"
"116.92800","9.74426","0.01730"
"117.18000","9.76525","0.01874"
"117.43200","9.78617","0.01791"
"117.68400","9.80716","0.01876"
"117.93600","9.82814","0.01888"
"118.18800","9.84925","0.01927"
"118.44000","9.87018","0.01949"
"118.69200","9.89122","0.01977"
"118.94400","9.91221","0.02029"
"119.19600","9.93331","0.02011"
"119.44800","9.95412","0.02075"
"119.70000","9.97517","0.02109"
"119.95200","9.99621","0.02088"
"120.20400","10.01726","0.02146"
"120.45600","10.03818","0.02051"
"120.70800","10.05923","0.02155"
"120.96000","10.08016","0.02142"
"121.21200","10.10120","0.02196"
"121.46400","10.12225","0.02213"
"121.71600","10.14318","0.02235"
"121.96800","10.16422","0.02267"
"122.22000","10.18521","0.02248"
"122.47200","10.20625","0.02090"
"122.72400","10.22718","0.02017"
"122.97600","10.24823","0.02024"
"123.22800","10.26915","0.01952"
"123.48000","10.29026","0.02020"
"123.73200","10.31118","0.02065"
"123.98400","10.33217","0.02107"
"124.23600","10.35316","0.02200"
"124.48800","10.37426","0.02147"
"124.74000","10.39519","0.02304"
"124.99200","10.41623","0.02271"
"125.24400","10.43722","0.02297"
"125.49600","10.45821","0.02343"
"125.74800","10.47925","0.02336"
"126.00000","10.50018","0.02376"
"126.25200","10.52122","0.02358"
"126.50400","10.54215","0.02374"
"126.75600","10.56320","0.02449"
"127.00800","10.58412","0.02507"
"127.26000","10.60523","0.02038"
"127.51200","10.62615","0.02201"
"127.76400","10.64720","0.02270"
"128.01600","10.66819","0.02254"
"128.26800","10.68923","0.02305"
"128.52000","10.71016","0.02242"
"128.77200","10.73120","0.02327"
"129.02400","10.75219","0.02344"
"129.27600","10.77324","0.02379"
"129.52800","10.79422","0.02406"
"129.78000","10.81521","0.02448"
"130.03200","10.83619","0.02494"
"130.28400","10.85718","0.02407"
"130.53600","10.87817","0.02461"
"130.78800","10.89915","0.02441"
"131.04000","10.92026","0.02548"
"131.29200","10.94119","0.02529"
"131.54400","10.96223","0.02567"
"131.79600","10.98316","0.02585"
"132.04800","11.00420","0.02579"
"132.30000","11.02519","0.02622"
"132.55200","11.04624","0.02684"
"132.80400","11.06716","0.02699"
"133.05600","11.08821","0.02727"
"133.30800","11.10919","0.02670"
"133.56000","11.13024","0.02686"
"133.81200","11.15123","0.02694"
"134.06400","11.17215","0.02753"
"134.31600","11.19320","0.02766"
"134.56800","11.21418","0.02565"
"134.82000","11.23523","0.02502"
"135.07200","11.25610","0.02531"
"135.32400","11.27726","0.02569"
"135.57600","11.29819","0.02595"
"135.82800","11.31923","0.02626"
"136.08000","11.34016","0.02669"
"136.33200","11.36121","0.02697"
"136.58400","11.38225","0.02722"
"136.83600","11.40324","0.02704"
"137.08800","11.42417","0.02773"
"137.34000","11.44521","0.02706"
"137.59200","11.46626","0.02691"
"137.84400","11.48724","0.02740"
"138.09600","11.50817","0.02753"
"138.34800","11.52915","0.02779"
"138.60000","11.55020","0.02819"
"138.85200","11.57119","0.02816"
"139.10400","11.59217","0.02833"
"139.35600","11.61316","0.02827"
"139.60800","11.63421","0.02884"
"139.86000","11.65519","0.02899"
"140.11200","11.67624","0.02884"
"140.36400","11.69711","0.02913"
"140.61600","11.71821","0.02922"
"140.86800","11.73920","0.02865"
"141.12000","11.76024","0.02934"
"141.37200","11.78117","0.03025"
"141.62400","11.80221","0.02970"
"141.87600","11.82326","0.03013"
"142.12800","11.84419","0.03002"
"142.38000","11.86523","0.03027"
"142.63200","11.88616","0.03014"
"142.88400","11.90721","0.03070"
"143.13600","11.92813","0.03061"
"143.38800","11.94918","0.03009"
"143.64000","11.97016","0.02968"
"143.89200","11.99121","0.03046"
"144.14400","12.01219","0.03056"
"144.39600","12.03324","0.03067"
"144.64800","12.05417","0.03083"
"144.90000","12.07521","0.03115"
"145.15200","12.09620","0.03120"
"145.40400","12.11719","0.01927"
"145.65600","12.13823","0.02098"
"145.90800","12.15922","0.01887"
"146.16000","12.18020","0.02098"
"146.41200","12.20119","0.02020"
"146.66400","12.22224","0.02082"
"146.91600","12.24316","0.01944"
"147.16800","12.26421","0.01900"
"147.42000","12.28520","0.01937"
"147.67200","12.30618","0.01839"
"147.92400","12.32717","0.01839"
"148.17600","12.34821","0.01194"
"148.42800","12.36914","0.01302"
"148.68000","12.39019","0.00843"
"148.93200","12.41117","0.00919"
"149.18400","12.43228","0.00906"
"149.43600","12.45320","0.00894"
"149.68800","12.47419","0.01063"
"149.94000","12.49518","0.00812"
"150.19200","12.51622","0.01129"
"150.44400","12.53721","0.00954"
"150.69600","12.55813","0.01096"
"150.94800","12.57924","0.00950"
"151.20000","12.60017","0.01100"
"151.45200","12.62121","0.01011"
"151.70400","12.64214","0.01068"
"151.95600","12.66318","0.01169"
"152.20800","12.68417","0.00952"
"152.46000","12.70522","0.01141"
"152.71200","12.72614","0.01083"
"152.96400","12.74719","0.01273"
"153.21600","12.76824","0.01088"
"153.46800","12.78922","0.01196"
"153.72000","12.81021","0.01124"
"153.97200","12.83119","0.01196"
"154.22400","12.85218","0.01187"
"154.47600","12.87316","0.01184"
"154.72800","12.89421","0.01256"
"154.98000","12.91514","0.01265"
"155.23200","12.93618","0.01350"
"155.48400","12.95723","0.01182"
"155.73600","12.97822","0.01348"
"155.98800","12.99920","0.01239"
"156.24000","13.02025","0.01377"
"156.49200","13.04117","0.01262"
"156.74400","13.06222","0.01377"
"156.99600","13.08315","0.01332"
"157.24800","13.10419","0.01367"
"157.50000","13.12524","0.01468"
"157.75200","13.14622","0.01401"
"158.00400","13.16721","0.01485"
"158.25600","13.18820","0.01452"
"158.50800","13.20918","0.01489"
"158.76000","13.23011","0.01398"
"159.01200","13.25121","0.01612"
"159.26400","13.27214","0.01476"
"159.51600","13.29325","0.01499"
"159.76800","13.31417","0.01545"
"160.02000","13.33522","0.01548"
"160.27200","13.35614","0.01499"
"160.52400","13.37725","0.01563"
"160.77600","13.39818","0.01665"
"161.02800","13.41916","0.01551"
"161.28000","13.44015","0.01585"
"161.53200","13.46120","0.01643"
"161.78400","13.48224","0.01586"
"162.03600","13.50317","0.01627"
"162.28800","13.52421","0.01695"
"162.54000","13.54514","0.01693"
"162.79200","13.56618","0.01740"
"163.04400","13.58711","0.01667"
"163.29600","13.60822","0.01759"
"163.54800","13.62920","0.01779"
"163.80000","13.65025","0.01755"
"164.05200","13.67118","0.01756"
"164.30400","13.69216","0.01828"
"164.55600","13.71321","0.01824"
"164.80800","13.73419","0.01785"
"165.06000","13.75518","0.01842"
"165.31200","13.77623","0.01850"
"165.56400","13.79721","0.01864"
"165.81600","13.81820","0.01866"
"166.06800","13.83918","0.01880"
"166.32000","13.86017","0.01921"
"166.57200","13.88122","0.01901"
"166.82400","13.90220","0.02000"
"167.07600","13.92319","0.01987"
"167.32800","13.94417","0.02011"
"167.58000","13.96522","0.01982"
"167.83200","13.98615","0.02065"
"168.08400","14.00725","0.02066"
"168.33600","14.02818","0.02071"
"168.58800","14.04922","0.02082"
"168.84000","14.07021","0.02136"
"169.09200","14.09114","0.02125"
"169.34400","14.11218","0.02131"
"169.59600","14.13317","0.02140"
"169.84800","14.15422","0.02133"
"170.10000","14.17520","0.02175"
"170.35200","14.19625","0.01956"
"170.60400","14.21717","0.01952"
"170.85600","14.23822","0.01971"
"171.10800","14.25915","0.01905"
"171.36000","14.28019","0.02027"
"171.61200","14.30118","0.01984"
"171.86400","14.32222","0.02126"
"172.11600","14.34321","0.02035"
"172.36800","14.36420","0.02111"
"172.62000","14.38518","0.02170"
"172.87200","14.40623","0.02206"
"173.12400","14.42721","0.02165"
"173.37600","14.44814","0.02207"
"173.62800","14.46919","0.02173"
"173.88000","14.49017","0.02221"
"174.13200","14.51122","0.02259"
"174.38400","14.53215","0.02220"
"174.63600","14.55325","0.02329"
"174.88800","14.57412","0.02342"
"175.14000","14.59516","0.02339"
"175.39200","14.61615","0.02308"
"175.64400","14.63720","0.02374"
"175.89600","14.65818","0.01894"
"176.14800","14.67923","0.01848"
"176.40000","14.70015","0.01565"
"176.65200","14.72126","0.01814"
"176.90400","14.74219","0.01645"
"177.15600","14.76323","0.01839"
"177.40800","14.78416","0.01713"
"177.66000","14.80514","0.01728"
"177.91200","14.82619","0.01584"
"178.16400","14.84718","0.01434"
"178.41600","14.86822","0.01354"
"178.66800","14.88915","0.01354"
"178.92000","14.91020","0.01199"
"179.17200","14.93112","0.01340"
"179.42400","14.95217","0.01220"
"179.67600","14.97321","0.01419"
"179.92800","14.99420","0.01246"
"180.18000","15.01518","0.01340"
"180.43200","15.03623","0.01240"
"180.68400","15.05722","0.01442"
"180.93600","15.07820","0.01303"
"181.18800","15.09925","0.01423"
"181.44000","15.12018","0.01343"
"181.69200","15.14122","0.01419"
"181.94400","15.16215","0.01466"
"182.19600","15.18325","0.01385"
"182.44800","15.20418","0.01395"
"182.70000","15.22523","0.01362"
"182.95200","15.24621","0.01357"
"183.20400","15.26720","0.01455"
"183.45600","15.28813","0.01431"
"183.70800","15.30923","0.01413"
"183.96000","15.33016","0.01539"
"184.21200","15.35126","0.01527"
"184.46400","15.37219","0.01455"
"184.71600","15.39317","0.01432"
"184.96800","15.41416","0.01606"
"185.22000","15.43521","0.01463"
"185.47200","15.45619","0.01488"
"185.72400","15.47712","0.01417"
"185.97600","15.49822","0.01595"
"186.22800","15.51921","0.01553"
"186.48000","15.54026","0.01516"
"186.73200","15.56112","0.01589"
"186.98400","15.58223","0.01675"
"187.23600","15.60316","0.01574"
"187.48800","15.62426","0.01588"
"187.74000","15.64519","0.01622"
"187.99200","15.66617","0.01629"
"188.24400","15.68716","0.01613"
"188.49600","15.70820","0.01638"
"188.74800","15.72919","0.01715"
"189.00000","15.75024","0.01636"
"189.25200","15.77122","0.01670"
"189.50400","15.79215","0.01705"
"189.75600","15.81319","0.01724"
"190.00800","15.83412","0.01754"
"190.26000","15.85517","0.01740"
"190.51200","15.87615","0.01704"
"190.76400","15.89720","0.01778"
"191.01600","15.91819","0.01715"
"191.26800","15.93917","0.01813"
"191.52000","15.96016","0.01804"
"191.77200","15.98120","0.01772"
"192.02400","16.00219","0.01804"
"192.27600","16.02324","0.01765"
"192.52800","16.04422","0.01763"
"192.78000","16.06521","0.01768"
"193.03200","16.08614","0.01886"
"193.28400","16.10718","0.01841"
"193.53600","16.12823","0.01928"
"193.78800","16.14921","0.01869"
"194.04000","16.17020","0.01935"
"194.29200","16.19112","0.01934"
"194.54400","16.21223","0.01999"
"194.79600","16.23316","0.02031"
"195.04800","16.25420","0.02077"
"195.30000","16.27513","0.02022"
"195.55200","16.29623","0.02051"
"195.80400","16.31716","0.02035"
"196.05600","16.33821","0.02066"
"196.30800","16.35919","0.02123"
"196.56000","16.38018","0.02055"
"196.81200","16.40123","0.02139"
"197.06400","16.42215","0.02201"
"197.31600","16.44320","0.02207"
"197.56800","16.46418","0.02226"
"197.82000","16.48523","0.02218"
"198.07200","16.50616","0.02221"
"198.32400","16.52720","0.02239"
"198.57600","16.54819","0.02298"
"198.82800","16.56923","0.02274"
"199.08000","16.59016","0.02329"
"199.33200","16.61121","0.02353"
"199.58400","16.63213","0.02326"
"199.83600","16.65324","0.02411"
"200.08800","16.67416","0.02419"
"200.34000","16.69521","0.02409"
"200.59200","16.71620","0.02529"
"200.84400","16.73724","0.02510"
"201.09600","16.75823","0.02593"
"201.34800","16.77915","0.02529"
"201.60000","16.80020","0.02585"
"201.85200","16.82119","0.02612"
"202.10400","16.84223","0.02631"
"202.35600","16.86316","0.02683"
"202.60800","16.88421","0.02694"
"202.86000","16.90513","0.02679"
"203.11200","16.92624","0.02680"
"203.36400","16.94716","0.02684"
"203.61600","16.96821","0.02720"
"203.86800","16.98914","0.02788"
"204.12000","17.01018","0.02743"
"204.37200","17.03117","0.02836"
"204.62400","17.05221","0.02836"
"204.87600","17.07320","0.02867"
"205.12800","17.09418","0.02887"
"205.38000","17.11517","0.02860"
"205.63200","17.13616","0.02924"
"205.88400","17.15726","0.02979"
"206.13600","17.17819","0.02915"
"206.38800","17.19924","0.02928"
"206.64000","17.22016","0.02906"
"206.89200","17.24121","0.02854"
"207.14400","17.26219","0.02911"
"207.39600","17.28318","0.02040"
"207.64800","17.30423","0.02067"
"207.90000","17.32521","0.02271"
"208.15200","17.34620","0.02218"
"208.40400","17.36724","0.02177"
"208.65600","17.38817","0.02452"
"208.90800","17.40916","0.02411"
"209.16000","17.43026","0.02365"
"209.41200","17.45119","0.02368"
"209.66400","17.47223","0.02540"
"209.91600","17.49322","0.02602"
"210.16800","17.51421","0.02510"
"210.42000","17.53513","0.02548"
"210.67200","17.55618","0.02650"
"210.92400","17.57711","0.02685"
"211.17600","17.59821","0.02630"
"211.42800","17.61914","0.02676"
"211.68000","17.64024","0.02644"
"211.93200","17.66123","0.02712"
"212.18400","17.68228","0.02735"
"212.43600","17.70314","0.02816"
"212.68800","17.72419","0.02806"
"212.94000","17.74517","0.02855"
"213.19200","17.76622","0.02819"
"213.44400","17.78721","0.02890"
"213.69600","17.80813","0.02897"
"213.94800","17.82924","0.02903"
"214.20000","17.85022","0.02916"
"214.45200","17.87121","0.02998"
"214.70400","17.89214","0.03015"
"214.95600","17.91324","0.03031"
"215.20800","17.93417","0.02833"
"215.46000","17.95522","0.02865"
"215.71200","17.97614","0.02851"
"215.96400","17.99725","0.02871"
"216.21600","18.01823","0.02846"
"216.46800","18.03922","0.02866"
"216.72000","18.06015","0.02880"
"216.97200","18.08119","0.02909"
"217.22400","18.10218","0.02939"
"217.47600","18.12322","0.03013"
"217.72800","18.14421","0.03009"
"217.98000","18.16520","0.02975"
"218.23200","18.18618","0.03031"
"218.48400","18.20717","0.03066"
"218.73600","18.22821","0.03046"
"218.98800","18.24914","0.03040"
"219.24000","18.27019","0.03090"
"219.49200","18.29117","0.03039"
"219.74400","18.31222","0.03067"
"219.99600","18.33315","0.02470"
"220.24800","18.35425","0.02541"
"220.50000","18.37518","0.02532"
"220.75200","18.39616","0.02589"
"221.00400","18.41721","0.02649"
"221.25600","18.43820","0.02698"
"221.50800","18.45924","0.02643"
"221.76000","18.48017","0.02640"
"222.01200","18.50121","0.02713"
"222.26400","18.52214","0.02776"
"222.51600","18.54325","0.02724"
"222.76800","18.56411","0.02798"
"223.02000","18.58516","0.02800"
"223.27200","18.60614","0.02775"
"223.52400","18.62725","0.02701"
"223.77600","18.64818","0.02620"
"224.02800","18.66922","0.02661"
"224.28000","18.69021","0.02631"
"224.53200","18.71125","0.02669"
"224.78400","18.73224","0.02595"
"225.03600","18.75323","0.02664"
"225.28800","18.77421","0.02619"
"225.54000","18.79520","0.02631"
"225.79200","18.81618","0.02663"
"226.04400","18.83717","0.02648"
"226.29600","18.85822","0.02667"
"226.54800","18.87914","0.02722"
"226.80000","18.90019","0.02672"
"227.05200","18.92118","0.02814"
"227.30400","18.94222","0.02699"
"227.55600","18.96321","0.02799"
"227.80800","18.98425","0.02748"
"228.06000","19.00518","0.02860"
"228.31200","19.02623","0.02804"
"228.56400","19.04721","0.02764"
"228.81600","19.06826","0.02754"
"229.06800","19.08918","0.02766"
"229.32000","19.11017","0.02778"
"229.57200","19.13122","0.02848"
"229.82400","19.15220","0.02761"
"230.07600","19.17325","0.02857"
"230.32800","19.19417","0.02838"
"230.58000","19.21522","0.02934"
"230.83200","19.23615","0.02921"
"231.08400","19.25719","0.02926"
"231.33600","19.27818","0.02933"
"231.58800","19.29916","0.02981"
"231.84000","19.32021","0.03017"
"232.09200","19.34126","0.03016"
"232.34400","19.36224","0.02986"
"232.59600","19.38323","0.03052"
"232.84800","19.40421","0.03050"
"233.10000","19.42520","0.03063"
"233.35200","19.44619","0.03072"
"233.60400","19.46717","0.03114"
"233.85600","19.48822","0.03114"
"234.10800","19.50915","0.03143"
"234.36000","19.53019","0.03145"
"234.61200","19.55118","0.03038"
"234.86400","19.57216","0.02915"
"235.11600","19.59315","0.03028"
"235.36800","19.61419","0.02889"
"235.62000","19.63518","0.02523"
"235.87200","19.65623","0.02563"
"236.12400","19.67721","0.02631"
"236.37600","19.69820","0.02600"
"236.62800","19.71918","0.02603"
"236.88000","19.74023","0.02719"
"237.13200","19.76122","0.02717"
"237.38400","19.78220","0.02756"
"237.63600","19.80319","0.02625"
"237.88800","19.82424","0.02691"
"238.14000","19.84528","0.02664"
"238.39200","19.86615","0.02721"
"238.64400","19.88719","0.02734"
"238.89600","19.90812","0.01832"
"239.14800","19.92929","0.02194"
"239.40000","19.95021","0.02121"
"239.65200","19.97126","0.02122"
"239.90400","19.99218","0.02037"
"240.15600","20.01317","0.02219"
"240.40800","20.03422","0.02166"
"240.66000","20.05520","0.02160"
"240.91200","20.07625","0.02201"
"241.16400","20.09723","0.02319"
"241.41600","20.11822","0.02303"
"241.66800","20.13915","0.02313"
"241.92000","20.16019","0.02327"
"242.17200","20.18118","0.02408"
"242.42400","20.20217","0.02438"
"242.67600","20.22315","0.02439"
"242.92800","20.24420","0.02467"
"243.18000","20.26518","0.02499"
"243.43200","20.28623","0.02493"
"243.68400","20.30722","0.02512"
"243.93600","20.32826","0.02557"
"244.18800","20.34919","0.02579"
"244.44000","20.37029","0.02618"
"244.69200","20.39116","0.02617"
"244.94400","20.41221","0.02622"
"245.19600","20.43325","0.02550"
"245.44800","20.45424","0.02625"
"245.70000","20.47517","0.02656"
"245.95200","20.49609","0.02707"
"246.20400","20.51726","0.02682"
"246.45600","20.53818","0.02712"
"246.70800","20.55917","0.02682"
"246.96000","20.58015","0.02788"
"247.21200","20.60120","0.02719"
"247.46400","20.62219","0.02728"
"247.71600","20.64317","0.02758"
"247.96800","20.66416","0.02797"
"248.22000","20.68521","0.02697"
"248.47200","20.70619","0.02813"
"248.72400","20.72718","0.02832"
"248.97600","20.74822","0.02855"
"249.22800","20.76915","0.02805"
"249.48000","20.79026","0.02852"
"249.73200","20.81112","0.02813"
"249.98400","20.83223","0.02873"
"250.23600","20.85315","0.02865"
"250.48800","20.87426","0.02868"
"250.74000","20.89519","0.02918"
"250.99200","20.91617","0.02905"
"251.24400","20.93716","0.02939"
"251.49600","20.95821","0.02955"
"251.74800","20.97913","0.02955"
"252.00000","21.00018","0.02966"
"252.25200","21.02116","0.02938"
"252.50400","21.04227","0.02895"
"252.75600","21.06319","0.01008"
"253.00800","21.08424","0.01000"
"253.26000","21.10517","0.00811"
"253.51200","21.12621","0.00517"
"253.76400","21.14720","0.01416"
"254.01600","21.16813","0.00680"
"254.26800","21.18917","0.00723"
"254.52000","21.21016","0.00935"
"254.77200","21.23126","0.01073"
"255.02400","21.25219","0.00742"
"255.27600","21.27324","0.00886"
"255.52800","21.29416","0.01119"
"255.78000","21.31521","0.00681"
"256.03200","21.33613","0.00907"
"256.28400","21.35724","0.01052"
"256.53600","21.37823","0.00879"
"256.78800","21.39921","0.00855"
"257.04000","21.42020","0.01000"
"257.29200","21.44118","0.00875"
"257.54400","21.46223","0.00853"
"257.79600","21.48315","0.01101"
"258.04800","21.50420","0.00959"
"258.30000","21.52513","0.00843"
"258.55200","21.54618","0.01101"
"258.80400","21.56716","0.00925"
"259.05600","21.58821","0.00937"
"259.30800","21.60919","0.01088"
"259.56000","21.63024","0.00993"
"259.81200","21.65122","0.00986"
"260.06400","21.67221","0.01118"
"260.31600","21.69320","0.01014"
"260.56800","21.71418","0.01025"
"260.82000","21.73523","0.01077"
"261.07200","21.75621","0.01041"
"261.32400","21.77720","0.01074"
"261.57600","21.79819","0.01083"
"261.82800","21.81923","0.01061"
"262.08000","21.84010","0.01066"
"262.33200","21.86121","0.01159"
"262.58400","21.88213","0.01101"
"262.83600","21.90324","0.01135"
"263.08800","21.92416","0.01209"
"263.34000","21.94521","0.01156"
"263.59200","21.96619","0.01208"
"263.84400","21.98724","0.01205"
"264.09600","22.00823","0.01175"
"264.34800","22.02921","0.01202"
"264.60000","22.05020","0.01209"
"264.85200","22.07125","0.01242"
"265.10400","22.09223","0.01235"
"265.35600","22.11316","0.01248"
"265.60800","22.13420","0.01289"
"265.86000","22.15519","0.01282"
"266.11200","22.17624","0.01260"
"266.36400","22.19710","0.01286"
"266.61600","22.21821","0.01352"
"266.86800","22.23919","0.01346"
"267.12000","22.26024","0.01352"
"267.37200","22.28117","0.01330"
"267.62400","22.30221","0.01335"
"267.87600","22.32320","0.01376"
"268.12800","22.34425","0.01327"
"268.38000","22.36517","0.01396"
"268.63200","22.38622","0.01380"
"268.88400","22.40714","0.01404"
"269.13600","22.42819","0.01446"
"269.38800","22.44918","0.01434"
"269.64000","22.47016","0.01418"
"269.89200","22.49127","0.01438"
"270.14400","22.51219","0.01485"
"270.39600","22.53318","0.01455"
"270.64800","22.55411","0.01465"
"270.90000","22.57521","0.01459"
"271.15200","22.59620","0.01511"
"271.40400","22.61724","0.01499"
"271.65600","22.63817","0.01498"
"271.90800","22.65928","0.01545"
"272.16000","22.68020","0.01533"
"272.41200","22.70119","0.01571"
"272.66400","22.72218","0.01517"
"272.91600","22.74316","0.01566"
"273.16800","22.76427","0.01622"
"273.42000","22.78519","0.01595"
"273.67200","22.80624","0.01586"
"273.92400","22.82717","0.01647"
"274.17600","22.84827","0.01613"
"274.42800","22.86914","0.01650"
"274.68000","22.89018","0.01599"
"274.93200","22.91111","0.01609"
"275.18400","22.93227","0.01660"
"275.43600","22.95320","0.01635"
"275.68800","22.97425","0.01658"
"275.94000","22.99517","0.01651"
"276.19200","23.01622","0.01651"
"276.44400","23.03721","0.01715"
"276.69600","23.05819","0.01745"
"276.94800","23.07918","0.01720"
"277.20000","23.10016","0.01736"
"277.45200","23.12121","0.01744"
"277.70400","23.14214","0.01719"
"277.95600","23.16318","0.01787"
"278.20800","23.18417","0.01746"
"278.46000","23.20522","0.01732"
"278.71200","23.22614","0.01741"
"278.96400","23.24719","0.01772"
"279.21600","23.26818","0.01734"
"279.46800","23.28922","0.01809"
"279.72000","23.31014","0.01840"
"279.97200","23.33125","0.01851"
"280.22400","23.35224","0.01842"
"280.47600","23.37322","0.01801"
"280.72800","23.39421","0.01750"
"280.98000","23.41514","0.01798"
"281.23200","23.43618","0.01799"
"281.48400","23.45717","0.01804"
"281.73600","23.47821","0.01796"
"281.98800","23.49914","0.01827"
"282.24000","23.52024","0.01852"
"282.49200","23.54117","0.01864"
"282.74400","23.56222","0.01923"
"282.99600","23.58315","0.01898"
"283.24800","23.60419","0.01893"
"283.50000","23.62512","0.01903"
"283.75200","23.64622","0.01925"
"284.00400","23.66721","0.01920"
"284.25600","23.68819","0.01908"
"284.50800","23.70924","0.01956"
"284.76000","23.73023","0.01963"
"285.01200","23.75121","0.01980"
"285.26400","23.77220","0.01919"
"285.51600","23.79324","0.01999"
"285.76800","23.81417","0.02008"
"286.02000","23.83516","0.01981"
"286.27200","23.85614","0.01982"
"286.52400","23.87719","0.02013"
"286.77600","23.89817","0.02038"
"287.02800","23.91916","0.02099"
"287.28000","23.94020","0.02055"
"287.53200","23.96125","0.02135"
"287.78400","23.98218","0.02102"
"288.03600","24.00323","0.02124"
"288.28800","24.02421","0.02156"
"288.54000","24.04526","0.02220"
"288.79200","24.06624","0.02172"
"289.04400","24.08717","0.02190"
"289.29600","24.10822","0.02214"
"289.54800","24.12920","0.02149"
"289.80000","24.15025","0.02243"
"290.05200","24.17112","0.02184"
"290.30400","24.19222","0.02211"
"290.55600","24.21321","0.02209"
"290.80800","24.23425","0.02294"
"291.06000","24.25518","0.02314"
"291.31200","24.27622","0.02279"
"291.56400","24.29721","0.02209"
"291.81600","24.31826","0.02230"
"292.06800","24.33918","0.02230"
"292.32000","24.36017","0.02293"
"292.57200","24.38121","0.02329"
"292.82400","24.40220","0.02322"
"293.07600","24.42319","0.02367"
"293.32800","24.44417","0.02407"
"293.58000","24.46522","0.02397"
"293.83200","24.48620","0.02377"
"294.08400","24.50725","0.02398"
"294.33600","24.52812","0.02494"
"294.58800","24.54916","0.02404"
"294.84000","24.57021","0.02425"
"295.09200","24.59120","0.02377"
"295.34400","24.61218","0.02414"
"295.59600","24.63323","0.02476"
"295.84800","24.65421","0.02482"
"296.10000","24.67526","0.02469"
"296.35200","24.69619","0.02496"
"296.60400","24.71717","0.02476"
"296.85600","24.73822","0.02541"
"297.10800","24.75920","0.02482"
"297.36000","24.78025","0.02519"
"297.61200","24.80112","0.02529"
"297.86400","24.82222","0.02542"
"298.11600","24.84321","0.02511"
"298.36800","24.86419","0.02524"
"298.62000","24.88512","0.02464"
"298.87200","24.90623","0.02471"
"299.12400","24.92715","0.02500"
"299.37600","24.94820","0.02475"
"299.62800","24.96919","0.02372"
"299.88000","24.99023","0.02414"
"300.13200","25.01122","0.02520"
"300.38400","25.03214","0.02515"
"300.63600","25.05325","0.02506"
"300.88800","25.07417","0.02539"
"301.14000","25.09522","0.02572"
"301.39200","25.11615","0.02596"
"301.64400","25.13720","0.02560"
"301.89600","25.15818","0.02509"
"302.14800","25.17923","0.02449"
"302.40000","25.20015","0.02471"
"302.65200","25.22120","0.02462"
"302.90400","25.24212","0.02479"
"303.15600","25.26323","0.02559"
"303.40800","25.28416","0.02536"
"303.66000","25.30520","0.02512"
"303.91200","25.32619","0.02536"
"304.16400","25.34723","0.02562"
"304.41600","25.36822","0.02523"
"304.66800","25.38921","0.02609"
"304.92000","25.41019","0.02605"
"305.17200","25.43118","0.02667"
"305.42400","25.45223","0.02672"
"305.67600","25.47315","0.02662"
"305.92800","25.49420","0.02722"
"306.18000","25.51518","0.02697"
"306.43200","25.53623","0.02695"
"306.68400","25.55716","0.02723"
"306.93600","25.57820","0.02751"
"307.18800","25.59913","0.02760"
"307.44000","25.62024","0.02751"
"307.69200","25.64116","0.02718"
"307.94400","25.66227","0.02797"
"308.19600","25.68319","0.02783"
"308.44800","25.70424","0.02520"
"308.70000","25.72523","0.02651"
"308.95200","25.74615","0.02702"
"309.20400","25.76726","0.02668"
"309.45600","25.78818","0.02584"
"309.70800","25.80923","0.02722"
"309.96000","25.83015","0.02756"
"310.21200","25.85120","0.02690"
"310.46400","25.87225","0.02692"
"310.71600","25.89317","0.02691"
"310.96800","25.91416","0.02751"
"311.22000","25.93527","0.02744"
"311.47200","25.95619","0.02769"
"311.72400","25.97717","0.02800"
"311.97600","25.99816","0.02610"
"312.22800","26.01921","0.02405"
"312.48000","26.04020","0.02440"
"312.73200","26.06118","0.02412"
"312.98400","26.08223","0.02436"
"313.23600","26.10315","0.02396"
"313.48800","26.12420","0.02416"
"313.74000","26.14513","0.02382"
"313.99200","26.16623","0.02496"
"314.24400","26.18716","0.02517"
"314.49600","26.20827","0.02443"
"314.74800","26.22919","0.02470"
"315.00000","26.25018","0.02509"
"315.25200","26.27116","0.02515"
"315.50400","26.29221","0.02562"
"315.75600","26.31319","0.02561"
"316.00800","26.33418","0.02498"
"316.26000","26.35523","0.02622"
"316.51200","26.37621","0.02560"
"316.76400","26.39726","0.02592"
"317.01600","26.41818","0.02562"
"317.26800","26.43923","0.02578"
"317.52000","26.46021","0.02606"
"317.77200","26.48126","0.02645"
"318.02400","26.50207","0.02646"
"318.27600","26.52317","0.02659"
"318.52800","26.54416","0.02604"
"318.78000","26.56527","0.02673"
"319.03200","26.58613","0.02625"
"319.28400","26.60724","0.02680"
"319.53600","26.62823","0.02669"
"319.78800","26.64921","0.02667"
"320.04000","26.67014","0.02697"
"320.29200","26.69118","0.02725"
"320.54400","26.71217","0.02708"
"320.79600","26.73322","0.02678"
"321.04800","26.75426","0.02678"
"321.30000","26.77519","0.02677"
"321.55200","26.79623","0.02685"
"321.80400","26.81716","0.02715"
"322.05600","26.83821","0.02740"
"322.30800","26.85913","0.02692"
"322.56000","26.88024","0.02721"
"322.81200","26.90122","0.02707"
"323.06400","26.92221","0.02750"
"323.31600","26.94314","0.02728"
"323.56800","26.96424","0.02716"
"323.82000","26.98523","0.02713"
"324.07200","27.00616","0.02774"
"324.32400","27.02714","0.02792"
"324.57600","27.04813","0.02772"
"324.82800","27.06923","0.02783"
"325.08000","27.09016","0.02798"
"325.33200","27.11127","0.02812"
"325.58400","27.13219","0.02856"
"325.83600","27.15324","0.02852"
"326.08800","27.17417","0.02858"
"326.34000","27.19515","0.02927"
"326.59200","27.21614","0.02883"
"326.84400","27.23724","0.02952"
"327.09600","27.25817","0.02899"
"327.34800","27.27921","0.02953"
"327.60000","27.30020","0.02954"
"327.85200","27.32125","0.02927"
"328.10400","27.34223","0.03002"
"328.35600","27.36316","0.02975"
"328.60800","27.38420","0.02992"
"328.86000","27.40519","0.03024"
"329.11200","27.42618","0.02994"
"329.36400","27.44716","0.03012"
"329.61600","27.46821","0.03014"
"329.86800","27.48914","0.03016"
"330.12000","27.51024","0.03038"
"330.37200","27.53117","0.03016"
"330.62400","27.55215","0.03026"
"330.87600","27.57314","0.02997"
"331.12800","27.59425","0.02999"
"331.38000","27.61517","0.02943"
"331.63200","27.63628","0.02967"
"331.88400","27.65721","0.03028"
"332.13600","27.67825","0.03010"
"332.38800","27.69917","0.02980"
"332.64000","27.72016","0.02994"
"332.89200","27.74115","0.03038"
"333.14400","27.76213","0.03007"
"333.39600","27.78324","0.03028"
"333.64800","27.80410","0.03038"
"333.90000","27.82521","0.03038"
"334.15200","27.84620","0.03024"
"334.40400","27.86718","0.03056"
"334.65600","27.88811","0.03101"
"334.90800","27.90916","0.03150"
"335.16000","27.93020","0.03127"
"335.41200","27.95119","0.03145"
"335.66400","27.97218","0.03121"
"335.91600","27.99322","0.03181"
"336.16800","28.01421","0.03160"
"336.42000","28.03519","0.03121"
"336.67200","28.05618","0.03130"
"336.92400","28.07722","0.03137"
"337.17600","28.09821","0.03154"
"337.42800","28.11920","0.03139"
"337.68000","28.14018","0.03150"
"337.93200","28.16117","0.03166"
"338.18400","28.18221","0.03178"
"338.43600","28.20320","0.03180"
"338.68800","28.22419","0.03190"
"338.94000","28.24511","0.03179"
"339.19200","28.26628","0.03206"
"339.44400","28.28721","0.03200"
"339.69600","28.30819","0.01933"
"339.94800","28.32918","0.01381"
"340.20000","28.35022","0.01820"
"340.45200","28.37121","0.01003"
"340.70400","28.39220","0.01147"
"340.95600","28.41324","0.01997"
"341.20800","28.43417","0.01420"
"341.46000","28.45528","0.01076"
"341.71200","28.47614","0.01937"
"341.96400","28.49725","0.00760"
"342.21600","28.51811","0.00423"
"342.46800","28.53928","0.01245"
"342.72000","28.56014","0.01120"
"342.97200","28.58119","0.01139"
"343.22400","28.60217","0.00981"
"343.47600","28.62322","0.00506"
"343.72800","28.64415","0.01061"
"343.98000","28.66520","0.00899"
"344.23200","28.68624","0.00636"
"344.48400","28.70723","0.00943"
"344.73600","28.72821","0.00974"
"344.98800","28.74914","0.00843"
"345.24000","28.77018","0.00891"
"345.49200","28.79123","0.00719"
"345.74400","28.81222","0.00926"
"345.99600","28.83314","0.00916"
"346.24800","28.85419","0.00668"
"346.50000","28.87518","0.00834"
"346.75200","28.89628","0.00964"
"347.00400","28.91715","0.00757"
"347.25600","28.93825","0.00826"
"347.50800","28.95924","0.00887"
"347.76000","28.98022","0.00942"
"348.01200","29.00115","0.00922"
"348.26400","29.02220","0.00806"
"348.51600","29.04325","0.00893"
"348.76800","29.06423","0.01052"
"349.02000","29.08521","0.00877"
"349.27200","29.10614","0.00856"
"349.52400","29.12725","0.01031"
"349.77600","29.14818","0.00950"
"350.02800","29.16916","0.00890"
"350.28000","29.19015","0.01013"
"350.53200","29.21125","0.01031"
"350.78400","29.23218","0.01034"
"351.03600","29.25322","0.00929"
"351.28800","29.27415","0.00998"
"351.54000","29.29520","0.01061"
"351.79200","29.31624","0.01061"
"352.04400","29.33717","0.00915"
"352.29600","29.35828","0.01066"
"352.54800","29.37920","0.01177"
"352.80000","29.40025","0.00983"
"353.05200","29.42117","0.01037"
"353.30400","29.44222","0.01170"
"353.55600","29.46315","0.01069"
"353.80800","29.48419","0.00993"
"354.06000","29.50512","0.01101"
"354.31200","29.52617","0.01118"
"354.56400","29.54721","0.01109"
"354.81600","29.56825","0.01103"
"355.06800","29.58918","0.01209"
"355.32000","29.61023","0.01212"
"355.57200","29.63116","0.01171"
"355.82400","29.65220","0.01155"
"356.07600","29.67325","0.01258"
"356.32800","29.69423","0.01184"
"356.58000","29.71522","0.01167"
"356.83200","29.73621","0.01248"
"357.08400","29.75725","0.01257"
"357.33600","29.77812","0.01187"
"357.58800","29.79928","0.01194"
"357.84000","29.82015","0.01244"
"358.09200","29.84126","0.01248"
"358.34400","29.86212","0.01161"
"358.59600","29.88317","0.01288"
"358.84800","29.90415","0.01313"
"359.10000","29.92526","0.01310"
"359.35200","29.94619","0.01291"
"359.60400","29.96723","0.01347"
"359.85600","29.98822","0.01305"
"360.10800","30.00921","0.01333"
"360.36000","30.03025","0.01391"
"360.61200","30.05112","0.01394"
"360.86400","30.07222","0.01374"
"361.11600","30.09315","0.01390"
"361.36800","30.11426","0.01425"
"361.62000","30.13518","0.01425"
"361.87200","30.15623","0.01440"
"362.12400","30.17721","0.01466"
"362.37600","30.19820","0.01436"
"362.62800","30.21918","0.01429"
"362.88000","30.24023","0.01514"
"363.13200","30.26122","0.01532"
"363.38400","30.28221","0.01462"
"363.63600","30.30319","0.01495"
"363.88800","30.32418","0.01505"
"364.14000","30.34522","0.01504"
"364.39200","30.36621","0.01497"
"364.64400","30.38719","0.01545"
"364.89600","30.40824","0.01505"
"365.14800","30.42923","0.01557"
"365.40000","30.45015","0.01567"
"365.65200","30.47126","0.01606"
"365.90400","30.49212","0.01586"
"366.15600","30.51329","0.01625"
"366.40800","30.53415","0.01516"
"366.66000","30.55520","0.01524"
"366.91200","30.57613","0.01595"
"367.16400","30.59723","0.01559"
"367.41600","30.61816","0.01629"
"367.66800","30.63914","0.01576"
"367.92000","30.66019","0.01654"
"368.17200","30.68124","0.01651"
"368.42400","30.70222","0.01609"
"368.67600","30.72315","0.01653"
"368.92800","30.74426","0.01630"
"369.18000","30.76518","0.01697"
"369.43200","30.78623","0.01635"
"369.68400","30.80710","0.01730"
"369.93600","30.82814","0.01694"
"370.18800","30.84919","0.01652"
"370.44000","30.87023","0.01542"
"370.69200","30.89116","0.01574"
"370.94400","30.91221","0.01615"
"371.19600","30.93319","0.01650"
"371.44800","30.95418","0.01557"
"371.70000","30.97516","0.01658"
"371.95200","30.99621","0.01596"
"372.20400","31.01719","0.01637"
"372.45600","31.03818","0.01639"
"372.70800","31.05923","0.00245"
"372.96000","31.08022","0.00259"
"373.21200","31.10120","0.00221"
"373.46400","31.12218","0.00154"
"373.71600","31.14323","0.00225"
"373.96800","31.16416","0.00138"
"374.22000","31.18521","0.00122"
"374.47200","31.20619","0.00270"
"374.72400","31.22724","0.00143"
"374.97600","31.24822","0.00192"
"375.22800","31.26921","0.00108"
"375.48000","31.29025","0.00171"
"375.73200","31.31118","0.00222"
"375.92600","31.32738","0.00155"