File: Force_trajectories/170122_1/Specimen_RawData_2.csv
End date,"1/22/2017"
Specimen label,"3BT_23"
Maximum Load,"0.05389",N

Time,Extension,Load
(s),(mm),(N)
"0.00000","0.00000","-0.00042"
"0.30600","0.02511","0.00623"
"0.61200","0.05124","0.01503"
"0.91800","0.07671","0.01805"
"1.22400","0.10224","0.01922"
"1.53000","0.12771","0.01988"
"1.83600","0.15330","0.01915"
"2.14200","0.17871","0.01998"
"2.44800","0.20424","0.01908"
"2.75400","0.22971","0.01988"
"3.06000","0.25518","0.01906"
"3.36600","0.28077","0.02010"
"3.67200","0.30624","0.01992"
"3.97800","0.33177","0.01976"
"4.28400","0.35724","0.01999"
"4.59000","0.38277","0.01991"
"4.89600","0.40824","0.01982"
"5.20200","0.43371","0.01903"
"5.50800","0.45924","0.01911"
"5.81400","0.48465","0.01983"
"6.12000","0.51024","0.01980"
"6.42600","0.53571","0.01996"
"6.73200","0.56124","0.01973"
"7.03800","0.58671","0.01894"
"7.34400","0.61224","0.01986"
"7.65000","0.63772","0.01954"
"7.95600","0.66319","0.01954"
"8.26200","0.68878","0.01968"
"8.56800","0.71419","0.01933"
"8.87400","0.73972","0.01975"
"9.18000","0.76519","0.01872"
"9.48600","0.79072","0.01894"
"9.79200","0.81625","0.01862"
"10.09800","0.84166","0.01884"
"10.40400","0.86719","0.01919"
"10.71000","0.89266","0.01909"
"11.01600","0.91825","0.01947"
"11.32200","0.94372","0.01938"
"11.62800","0.96919","0.01926"
"11.93400","0.99472","0.01904"
"12.24000","1.02019","0.01903"
"12.54600","1.04572","0.01918"
"12.85200","1.07119","0.01876"
"13.15800","1.09672","0.01966"
"13.46400","1.12219","0.01874"
"13.77000","1.14772","0.01927"
"14.07600","1.17325","0.01930"
"14.38200","1.19872","0.01891"
"14.68800","1.22419","0.01928"
"14.99400","1.24966","0.01913"
"15.30000","1.27525","0.01871"
"15.60600","1.30072","0.01943"
"15.91200","1.32625","0.01848"
"16.21800","1.35172","0.01970"
"16.52400","1.37725","0.01908"
"16.83000","1.40272","0.01896"
"17.13600","1.42819","0.01930"
"17.44200","1.45372","0.01931"
"17.74800","1.47919","0.01901"
"18.05400","1.50472","0.01918"
"18.36000","1.53025","0.01897"
"18.66600","1.55566","0.01907"
"18.97200","1.58119","0.01887"
"19.27800","1.60666","0.01937"
"19.58400","1.63225","0.01908"
"19.89000","1.65772","0.01870"
"20.19600","1.68325","0.01930"
"20.50200","1.70872","0.01868"
"20.80800","1.73426","0.01908"
"21.11400","1.75973","0.01933"
"21.42000","1.78526","0.01918"
"21.72600","1.81073","0.01889"
"22.03200","1.83620","0.01867"
"22.33800","1.86173","0.01937"
"22.64400","1.88726","0.01945"
"22.95000","1.91267","0.01983"
"23.25600","1.93820","0.01935"
"23.56200","1.96367","0.01925"
"23.86800","1.98920","0.01873"
"24.17400","2.01467","0.01919"
"24.48000","2.04026","0.01842"
"24.78600","2.06573","0.01958"
"25.09200","2.09120","0.01899"
"25.39800","2.11673","0.01895"
"25.70400","2.14220","0.01967"
"26.01000","2.16773","0.01914"
"26.31600","2.19314","0.01938"
"26.62200","2.21879","0.01901"
"26.92800","2.24426","0.01928"
"27.23400","2.26973","0.01918"
"27.54000","2.29520","0.01943"
"27.84600","2.32067","0.01962"
"28.15200","2.34620","0.02013"
"28.45800","2.37161","0.01985"
"28.76400","2.39720","0.02005"
"29.07000","2.42267","0.01923"
"29.37600","2.44820","0.01968"
"29.68200","2.47373","0.01990"
"29.98800","2.49920","0.01922"
"30.29400","2.52473","0.01938"
"30.60000","2.55014","0.01981"
"30.90600","2.57573","0.01952"
"31.21200","2.60114","0.02016"
"31.51800","2.62673","0.01956"
"31.82400","2.65226","0.01934"
"32.13000","2.67773","0.01882"
"32.43600","2.70326","0.01987"
"32.74200","2.72867","0.01921"
"33.04800","2.75426","0.01923"
"33.35400","2.77968","0.01975"
"33.66000","2.80521","0.01950"
"33.96600","2.83080","0.01939"
"34.27200","2.85627","0.01910"
"34.57800","2.88174","0.01924"
"34.88400","2.90721","0.01946"
"35.19000","2.93274","0.01981"
"35.49600","2.95815","0.01983"
"35.80200","2.98374","0.01937"
"36.10800","3.00921","0.01919"
"36.41400","3.03474","0.01961"
"36.72000","3.06021","0.01916"
"37.02600","3.08568","0.01924"
"37.33200","3.11121","0.01929"
"37.63800","3.13668","0.01990"
"37.94400","3.16221","0.01970"
"38.25000","3.18774","0.01924"
"38.55600","3.21321","0.01961"
"38.86200","3.23880","0.02008"
"39.16800","3.26421","0.01996"
"39.47400","3.28974","0.01945"
"39.78000","3.31515","0.01937"
"40.08600","3.34074","0.02014"
"40.39200","3.36621","0.01908"
"40.69800","3.39174","0.02010"
"41.00400","3.41727","0.01950"
"41.31000","3.44268","0.02033"
"41.61600","3.46821","0.01965"
"41.92200","3.49362","0.02021"
"42.22800","3.51927","0.02000"
"42.53400","3.54474","0.01920"
"42.84000","3.57021","0.01893"
"43.14600","3.59580","0.01886"
"43.45200","3.62115","0.01930"
"43.75800","3.64674","0.01904"
"44.06400","3.67215","0.01889"
"44.37000","3.69774","0.01889"
"44.67600","3.72321","0.01885"
"44.98200","3.74874","0.01910"
"45.28800","3.77421","0.01902"
"45.59400","3.79974","0.01947"
"45.90000","3.82527","0.01936"
"46.20600","3.85069","0.01944"
"46.51200","3.87622","0.01844"
"46.81800","3.90169","0.01917"
"47.12400","3.92722","0.02047"
"47.43000","3.95275","0.01934"
"47.73600","3.97822","0.01974"
"48.04200","4.00375","0.01922"
"48.34800","4.02922","0.01928"
"48.65400","4.05469","0.01933"
"48.96000","4.08016","0.01996"
"49.26600","4.10569","0.01895"
"49.57200","4.13128","0.02000"
"49.87800","4.15669","0.01877"
"50.18400","4.18222","0.01945"
"50.49000","4.20769","0.01979"
"50.79600","4.23322","0.01962"
"51.10200","4.25863","0.01876"
"51.40800","4.28422","0.01930"
"51.71400","4.30969","0.02013"
"52.02000","4.33522","0.02000"
"52.32600","4.36075","0.01994"
"52.63200","4.38616","0.01967"
"52.93800","4.41169","0.01952"
"53.24400","4.43716","0.01963"
"53.55000","4.46275","0.01961"
"53.85600","4.48822","0.01972"
"54.16200","4.51369","0.01966"
"54.46800","4.53922","0.01987"
"54.77400","4.56469","0.01968"
"55.08000","4.59022","0.02031"
"55.38600","4.61569","0.01967"
"55.69200","4.64122","0.01949"
"55.99800","4.66669","0.01993"
"56.30400","4.69222","0.01910"
"56.61000","4.71775","0.01987"
"56.91600","4.74322","0.01982"
"57.22200","4.76875","0.02006"
"57.52800","4.79416","0.01963"
"57.83400","4.81975","0.01915"
"58.14000","4.84522","0.01990"
"58.44600","4.87069","0.02002"
"58.75200","4.89622","0.01986"
"59.05800","4.92170","0.01984"
"59.36400","4.94729","0.01999"
"59.67000","4.97269","0.01988"
"59.97600","4.99823","0.01947"
"60.28200","5.02370","0.01939"
"60.58800","5.04923","0.01964"
"60.89400","5.07470","0.01934"
"61.20000","5.10017","0.01917"
"61.50600","5.12570","0.01936"
"61.81200","5.15117","0.01957"
"62.11800","5.17676","0.01979"
"62.42400","5.20223","0.02007"
"62.73000","5.22770","0.01967"
"63.03600","5.25323","0.01962"
"63.34200","5.27870","0.02026"
"63.64800","5.30429","0.01973"
"63.95400","5.32970","0.02019"
"64.26000","5.35529","0.01956"
"64.56600","5.38070","0.01950"
"64.87200","5.40617","0.01955"
"65.17800","5.43170","0.01958"
"65.48400","5.45717","0.01892"
"65.79000","5.48270","0.01926"
"66.09600","5.50817","0.01926"
"66.40200","5.53376","0.01939"
"66.70800","5.55917","0.01932"
"67.01400","5.58470","0.01913"
"67.32000","5.61017","0.01942"
"67.62600","5.63570","0.01929"
"67.93200","5.66123","0.01925"
"68.23800","5.68670","0.02006"
"68.54400","5.71229","0.01946"
"68.85000","5.73776","0.01904"
"69.15600","5.76329","0.02015"
"69.46200","5.78870","0.01933"
"69.76800","5.81417","0.02002"
"70.07400","5.83970","0.01938"
"70.38000","5.86523","0.01936"
"70.68600","5.89076","0.01889"
"70.99200","5.91623","0.01866"
"71.29800","5.94176","0.01976"
"71.60400","5.96723","0.01918"
"71.91000","5.99270","0.01919"
"72.21600","6.01817","0.02013"
"72.52200","6.04371","0.01924"
"72.82800","6.06924","0.01975"
"73.13400","6.09471","0.01935"
"73.44000","6.12024","0.01930"
"73.74600","6.14571","0.01974"
"74.05200","6.17118","0.01959"
"74.35800","6.19671","0.01914"
"74.66400","6.22218","0.02035"
"74.97000","6.24771","0.01971"
"75.27600","6.27318","0.02022"
"75.58200","6.29877","0.02019"
"75.88800","6.32418","0.01949"
"76.19400","6.34971","0.01993"
"76.50000","6.37524","0.01930"
"76.80600","6.40065","0.01979"
"77.11200","6.42624","0.02061"
"77.41800","6.45165","0.01966"
"77.72400","6.47730","0.01977"
"78.03000","6.50271","0.01987"
"78.33600","6.52824","0.02007"
"78.64200","6.55371","0.01993"
"78.94800","6.57924","0.02052"
"79.25400","6.60471","0.01994"
"79.56000","6.63018","0.01971"
"79.86600","6.65577","0.01981"
"80.17200","6.68124","0.01936"
"80.47800","6.70677","0.01962"
"80.78400","6.73218","0.01946"
"81.09000","6.75771","0.01939"
"81.39600","6.78324","0.01994"
"81.70200","6.80865","0.01992"
"82.00800","6.83424","0.01991"
"82.31400","6.85971","0.02012"
"82.62000","6.88524","0.02000"
"82.92600","6.91071","0.01949"
"83.23200","6.93624","0.01986"
"83.53800","6.96171","0.01995"
"83.84400","6.98718","0.02033"
"84.15000","7.01271","0.01972"
"84.45600","7.03818","0.02009"
"84.76200","7.06377","0.02032"
"85.06800","7.08925","0.02040"
"85.37400","7.11472","0.02024"
"85.68000","7.14025","0.01985"
"85.98600","7.16572","0.01976"
"86.29200","7.19125","0.02058"
"86.59800","7.21666","0.02025"
"86.90400","7.24225","0.01979"
"87.21000","7.26772","0.02042"
"87.51600","7.29325","0.02019"
"87.82200","7.31872","0.02022"
"88.12800","7.34413","0.02056"
"88.43400","7.36972","0.02049"
"88.74000","7.39519","0.02037"
"89.04600","7.42078","0.02002"
"89.35200","7.44619","0.02011"
"89.65800","7.47172","0.02004"
"89.96400","7.49725","0.02027"
"90.27000","7.52272","0.02017"
"90.57600","7.54825","0.02008"
"90.88200","7.57366","0.01972"
"91.18800","7.59919","0.01987"
"91.49400","7.62472","0.02009"
"91.80000","7.65025","0.01966"
"92.10600","7.67578","0.01969"
"92.41200","7.70113","0.01955"
"92.71800","7.72672","0.01984"
"93.02400","7.75213","0.01995"
"93.33000","7.77772","0.01990"
"93.63600","7.80319","0.01967"
"93.94200","7.82872","0.02036"
"94.24800","7.85419","0.01996"
"94.55400","7.87972","0.01984"
"94.86000","7.90525","0.02002"
"95.16600","7.93060","0.02041"
"95.47200","7.95625","0.02032"
"95.77800","7.98172","0.02014"
"96.08400","8.00725","0.02092"
"96.39000","8.03272","0.02067"
"96.69600","8.05825","0.02028"
"97.00200","8.08372","0.02050"
"97.30800","8.10913","0.02034"
"97.61400","8.13472","0.02009"
"97.92000","8.16020","0.02106"
"98.22600","8.18572","0.02085"
"98.53200","8.21126","0.02109"
"98.83800","8.23679","0.02065"
"99.14400","8.26226","0.02019"
"99.45000","8.28767","0.02076"
"99.75600","8.31320","0.02066"
"100.06200","8.33867","0.02051"
"100.36800","8.36420","0.02088"
"100.67400","8.38979","0.02100"
"100.98000","8.41526","0.02124"
"101.28600","8.44073","0.02079"
"101.59200","8.46620","0.02062"
"101.89800","8.49173","0.02112"
"102.20400","8.51714","0.02065"
"102.51000","8.54273","0.02089"
"102.81600","8.56820","0.02090"
"103.12200","8.59373","0.02103"
"103.42800","8.61926","0.02075"
"103.73400","8.64467","0.02104"
"104.04000","8.67020","0.02115"
"104.34600","8.69567","0.02124"
"104.65200","8.72126","0.02065"
"104.95800","8.74673","0.02103"
"105.26400","8.77226","0.02068"
"105.57000","8.79773","0.02109"
"105.87600","8.82320","0.02081"
"106.18200","8.84873","0.02128"
"106.48800","8.87414","0.02086"
"106.79400","8.89973","0.02072"
"107.10000","8.92520","0.02078"
"107.40600","8.95073","0.02149"
"107.71200","8.97626","0.02105"
"108.01800","9.00167","0.02096"
"108.32400","9.02726","0.02065"
"108.63000","9.05273","0.02040"
"108.93600","9.07826","0.02109"
"109.24200","9.10373","0.02060"
"109.54800","9.12926","0.02086"
"109.85400","9.15473","0.02030"
"110.16000","9.18021","0.02015"
"110.46600","9.20573","0.02115"
"110.77200","9.23120","0.02074"
"111.07800","9.25679","0.02099"
"111.38400","9.28221","0.02097"
"111.69000","9.30768","0.02037"
"111.99600","9.33321","0.02066"
"112.30200","9.35874","0.02128"
"112.60800","9.38427","0.02118"
"112.91400","9.40968","0.02175"
"113.22000","9.43521","0.02083"
"113.52600","9.46074","0.02103"
"113.83200","9.48621","0.02102"
"114.13800","9.51174","0.02110"
"114.44400","9.53721","0.02112"
"114.75000","9.56274","0.02134"
"115.05600","9.58821","0.02119"
"115.36200","9.61374","0.02118"
"115.66800","9.63915","0.02180"
"115.97400","9.66468","0.02186"
"116.28000","9.69021","0.02204"
"116.58600","9.71568","0.02225"
"116.89200","9.74121","0.02151"
"117.19800","9.76668","0.02183"
"117.50400","9.79221","0.02151"
"117.81000","9.81768","0.02210"
"118.11600","9.84321","0.02170"
"118.42200","9.86874","0.01982"
"118.72800","9.89421","0.01894"
"119.03400","9.91974","0.01970"
"119.34000","9.94521","0.01938"
"119.64600","9.97080","0.01929"
"119.95200","9.99615","0.01970"
"120.25800","10.02174","0.01927"
"120.56400","10.04715","0.01951"
"120.87000","10.07262","0.01976"
"121.17600","10.09821","0.01972"
"121.48200","10.12374","0.01990"
"121.78800","10.14927","0.01970"
"122.09400","10.17468","0.01961"
"122.40000","10.20027","0.01966"
"122.70600","10.22574","0.01944"
"123.01200","10.25121","0.01964"
"123.31800","10.27674","0.01915"
"123.62400","10.30221","0.01914"
"123.93000","10.32774","0.01968"
"124.23600","10.35322","0.01978"
"124.54200","10.37874","0.02038"
"124.84800","10.40416","0.01998"
"125.15400","10.42969","0.01936"
"125.46000","10.45522","0.01977"
"125.76600","10.48069","0.01986"
"126.07200","10.50622","0.02054"
"126.37800","10.53163","0.01981"
"126.68400","10.55728","0.01972"
"126.99000","10.58269","0.02053"
"127.29600","10.60822","0.01999"
"127.60200","10.63375","0.02046"
"127.90800","10.65922","0.01997"
"128.21400","10.68475","0.01992"
"128.52000","10.71016","0.01923"
"128.82600","10.73575","0.01940"
"129.13200","10.76122","0.01984"
"129.43800","10.78669","0.02010"
"129.74400","10.81222","0.02008"
"130.05000","10.83775","0.01977"
"130.35600","10.86322","0.01998"
"130.66200","10.88869","0.02012"
"130.96800","10.91428","0.01980"
"131.27400","10.93969","0.01976"
"131.58000","10.96528","0.01957"
"131.88600","10.99069","0.02001"
"132.19200","11.01622","0.01996"
"132.49800","11.04175","0.01981"
"132.80400","11.06722","0.01992"
"133.11000","11.09275","0.01995"
"133.41600","11.11822","0.01892"
"133.72200","11.14375","0.01874"
"134.02800","11.16922","0.01909"
"134.33400","11.19469","0.01887"
"134.64000","11.22022","0.01906"
"134.94600","11.24569","0.01841"
"135.25200","11.27122","0.01886"
"135.55800","11.29669","0.01821"
"135.86400","11.32222","0.01920"
"136.17000","11.34775","0.01897"
"136.47600","11.37322","0.01891"
"136.78200","11.39876","0.01965"
"137.08800","11.42417","0.01920"
"137.39400","11.44975","0.01905"
"137.70000","11.47517","0.01925"
"138.00600","11.50070","0.01866"
"138.31200","11.52617","0.01905"
"138.61800","11.55170","0.01893"
"138.92400","11.57723","0.01946"
"139.23000","11.60270","0.01930"
"139.53600","11.62817","0.01935"
"139.84200","11.65364","0.01893"
"140.14800","11.67923","0.01915"
"140.45400","11.70470","0.01968"
"140.76000","11.73023","0.01952"
"141.06600","11.75570","0.02005"
"141.37200","11.78117","0.01939"
"141.67800","11.80676","0.01962"
"141.98400","11.83217","0.01977"
"142.29000","11.85776","0.01954"
"142.59600","11.88323","0.01986"
"142.90200","11.90870","0.01913"
"143.20800","11.93423","0.01997"
"143.51400","11.95970","0.01982"
"143.82000","11.98523","0.01956"
"144.12600","12.01064","0.02025"
"144.43200","12.03623","0.02009"
"144.73800","12.06176","0.02006"
"145.04400","12.08729","0.02015"
"145.35000","12.11270","0.01971"
"145.65600","12.13823","0.02039"
"145.96200","12.16376","0.01991"
"146.26800","12.18917","0.01996"
"146.57400","12.21470","0.01973"
"146.88000","12.24023","0.01978"
"147.18600","12.26576","0.02055"
"147.49200","12.29123","0.02002"
"147.79800","12.31670","0.02035"
"148.10400","12.34223","0.02051"
"148.41000","12.36770","0.02082"
"148.71600","12.39318","0.02062"
"149.02200","12.41870","0.02072"
"149.32800","12.44423","0.01992"
"149.63400","12.46971","0.01948"
"149.94000","12.49523","0.02085"
"150.24600","12.52077","0.02106"
"150.55200","12.54624","0.02093"
"150.85800","12.57171","0.02066"
"151.16400","12.59718","0.02080"
"151.47000","12.62271","0.02071"
"151.77600","12.64824","0.02064"
"152.08200","12.67371","0.02108"
"152.38800","12.69924","0.02037"
"152.69400","12.72465","0.02062"
"153.00000","12.75018","0.02080"
"153.30600","12.77559","0.02094"
"153.61200","12.80124","0.02085"
"153.91800","12.82671","0.02020"
"154.22400","12.85224","0.02061"
"154.53000","12.87777","0.02092"
"154.83600","12.90324","0.02105"
"155.14200","12.92871","0.02063"
"155.44800","12.95412","0.02038"
"155.75400","12.97977","0.02030"
"156.06000","13.00524","0.02057"
"156.36600","13.03077","0.02072"
"156.67200","13.05624","0.02041"
"156.97800","13.08171","0.02052"
"157.28400","13.10718","0.02060"
"157.59000","13.13259","0.02089"
"157.89600","13.15818","0.02080"
"158.20200","13.18371","0.02155"
"158.50800","13.20918","0.02073"
"158.81400","13.23471","0.02073"
"159.12000","13.26018","0.02115"
"159.42600","13.28571","0.02143"
"159.73200","13.31118","0.02110"
"160.03800","13.33671","0.02114"
"160.34400","13.36218","0.02110"
"160.65000","13.38777","0.02139"
"160.95600","13.41324","0.02125"
"161.26200","13.43871","0.02134"
"161.56800","13.46424","0.02077"
"161.87400","13.48965","0.02111"
"162.18000","13.51530","0.02127"
"162.48600","13.54066","0.02150"
"162.79200","13.56625","0.02138"
"163.09800","13.59172","0.02153"
"163.40400","13.61725","0.02113"
"163.71000","13.64272","0.02113"
"164.01600","13.66819","0.02128"
"164.32200","13.69372","0.02123"
"164.62800","13.71913","0.02178"
"164.93400","13.74478","0.02168"
"165.24000","13.77025","0.02118"
"165.54600","13.79572","0.02157"
"165.85200","13.82119","0.02192"
"166.15800","13.84666","0.02148"
"166.46400","13.87219","0.02158"
"166.77000","13.89766","0.02172"
"167.07600","13.92319","0.02167"
"167.38200","13.94872","0.02158"
"167.68800","13.97425","0.02216"
"167.99400","13.99978","0.02237"
"168.30000","14.02519","0.02201"
"168.60600","14.05072","0.02235"
"168.91200","14.07619","0.02263"
"169.21800","14.10172","0.02232"
"169.52400","14.12725","0.02261"
"169.83000","14.15278","0.02241"
"170.13600","14.17825","0.02248"
"170.44200","14.20366","0.02300"
"170.74800","14.22925","0.02233"
"171.05400","14.25460","0.02272"
"171.36000","14.28025","0.02325"
"171.66600","14.30566","0.02336"
"171.97200","14.33119","0.02316"
"172.27800","14.35672","0.02335"
"172.58400","14.38219","0.02323"
"172.89000","14.40778","0.02350"
"173.19600","14.43319","0.02330"
"173.50200","14.45872","0.02354"
"173.80800","14.48419","0.02374"
"174.11400","14.50972","0.02340"
"174.42000","14.53525","0.02342"
"174.72600","14.56073","0.02226"
"175.03200","14.58625","0.02318"
"175.33800","14.61166","0.02293"
"175.64400","14.63726","0.02288"
"175.95000","14.66272","0.02297"
"176.25600","14.68820","0.02290"
"176.56200","14.71373","0.02316"
"176.86800","14.73920","0.02278"
"177.17400","14.76479","0.02307"
"177.48000","14.79026","0.02379"
"177.78600","14.81573","0.02331"
"178.09200","14.84120","0.02349"
"178.39800","14.86673","0.02373"
"178.70400","14.89226","0.02375"
"179.01000","14.91767","0.02404"
"179.31600","14.94326","0.02442"
"179.62200","14.96867","0.02421"
"179.92800","14.99420","0.02412"
"180.23400","15.01967","0.02420"
"180.54000","15.04526","0.02421"
"180.84600","15.07067","0.02423"
"181.15200","15.09620","0.02487"
"181.45800","15.12173","0.02483"
"181.76400","15.14720","0.02502"
"182.07000","15.17273","0.02372"
"182.37600","15.19820","0.02389"
"182.68200","15.22373","0.02501"
"182.98800","15.24920","0.02085"
"183.29400","15.27473","0.02215"
"183.60000","15.30026","0.02312"
"183.90600","15.32573","0.02235"
"184.21200","15.35126","0.02324"
"184.51800","15.37667","0.02538"
"184.82400","15.40220","0.02127"
"185.13000","15.42767","0.02165"
"185.43600","15.45320","0.02524"
"185.74200","15.47873","0.02129"
"186.04800","15.50420","0.02181"
"186.35400","15.52979","0.02562"
"186.66000","15.55515","0.02187"
"186.96600","15.58073","0.02454"
"187.27200","15.60620","0.02437"
"187.57800","15.63173","0.02302"
"187.88400","15.65726","0.02732"
"188.19000","15.68268","0.02411"
"188.49600","15.70826","0.02525"
"188.80200","15.73367","0.02716"
"189.10800","15.75926","0.02488"
"189.41400","15.78468","0.02840"
"189.72000","15.81021","0.02617"
"190.02600","15.83568","0.02784"
"190.33200","15.86121","0.02879"
"190.63800","15.88674","0.02767"
"190.94400","15.91215","0.02892"
"191.25000","15.93774","0.02408"
"191.55600","15.96321","0.02459"
"191.86200","15.98874","0.02327"
"192.16800","16.01421","0.02394"
"192.47400","16.03974","0.02454"
"192.78000","16.06527","0.02401"
"193.08600","16.09074","0.02576"
"193.39200","16.11627","0.02528"
"193.69800","16.14168","0.01882"
"194.00400","16.16715","0.01943"
"194.31000","16.19268","0.01996"
"194.61600","16.21821","0.01951"
"194.92200","16.24374","0.02007"
"195.22800","16.26915","0.01969"
"195.53400","16.29474","0.01932"
"195.84000","16.32021","0.02007"
"196.14600","16.34568","0.01917"
"196.45200","16.37121","0.01992"
"196.75800","16.39668","0.01930"
"197.06400","16.42227","0.01951"
"197.37000","16.44768","0.02028"
"197.67600","16.47327","0.02024"
"197.98200","16.49874","0.01980"
"198.28800","16.52427","0.02022"
"198.59400","16.54968","0.02082"
"198.90000","16.57521","0.02022"
"199.20600","16.60068","0.02084"
"199.51200","16.62615","0.02072"
"199.81800","16.65168","0.02063"
"200.12400","16.67721","0.02052"
"200.43000","16.70274","0.02046"
"200.73600","16.72821","0.02033"
"201.04200","16.75374","0.02060"
"201.34800","16.77921","0.02145"
"201.65400","16.80469","0.02073"
"201.96000","16.83022","0.02062"
"202.26600","16.85568","0.02061"
"202.57200","16.88122","0.02108"
"202.87800","16.90669","0.02103"
"203.18400","16.93216","0.02124"
"203.49000","16.95775","0.02049"
"203.79600","16.98322","0.02121"
"204.10200","17.00869","0.02093"
"204.40800","17.03416","0.02094"
"204.71400","17.05975","0.02117"
"205.02000","17.08522","0.02129"
"205.32600","17.11075","0.02133"
"205.63200","17.13622","0.02149"
"205.93800","17.16169","0.02158"
"206.24400","17.18722","0.02180"
"206.55000","17.21263","0.02137"
"206.85600","17.23822","0.02153"
"207.16200","17.26375","0.02178"
"207.46800","17.28922","0.02115"
"207.77400","17.31469","0.02143"
"208.08000","17.34022","0.02215"
"208.38600","17.36569","0.02231"
"208.69200","17.39116","0.02261"
"208.99800","17.41669","0.02167"
"209.30400","17.44222","0.02233"
"209.61000","17.46781","0.02233"
"209.91600","17.49322","0.02264"
"210.22200","17.51869","0.02224"
"210.52800","17.54422","0.02224"
"210.83400","17.56969","0.02287"
"211.14000","17.59522","0.02218"
"211.44600","17.62069","0.02297"
"211.75200","17.64622","0.02329"
"212.05800","17.67169","0.02320"
"212.36400","17.69722","0.02282"
"212.67000","17.72275","0.02302"
"212.97600","17.74822","0.02366"
"213.28200","17.77369","0.02293"
"213.58800","17.79917","0.02338"
"213.89400","17.82475","0.02382"
"214.20000","17.85022","0.02343"
"214.50600","17.87576","0.02384"
"214.81200","17.90122","0.02380"
"215.11800","17.92669","0.02249"
"215.42400","17.95223","0.02361"
"215.73000","17.97764","0.02310"
"216.03600","18.00323","0.02321"
"216.34200","18.02870","0.02309"
"216.64800","18.05429","0.02330"
"216.95400","18.07970","0.02402"
"217.26000","18.10517","0.02357"
"217.56600","18.13070","0.02374"
"217.87200","18.15617","0.02431"
"218.17800","18.18176","0.02400"
"218.48400","18.20723","0.02447"
"218.79000","18.23276","0.02454"
"219.09600","18.25823","0.02472"
"219.40200","18.28370","0.02420"
"219.70800","18.30923","0.02450"
"220.01400","18.33464","0.02527"
"220.32000","18.36023","0.02462"
"220.62600","18.38570","0.02469"
"220.93200","18.41129","0.02537"
"221.23800","18.43676","0.02557"
"221.54400","18.46217","0.02530"
"221.85000","18.48776","0.02560"
"222.15600","18.51311","0.02576"
"222.46200","18.53876","0.02497"
"222.76800","18.56417","0.02495"
"223.07400","18.58976","0.02519"
"223.38000","18.61523","0.02533"
"223.68600","18.64070","0.02529"
"223.99200","18.66629","0.02575"
"224.29800","18.69170","0.02596"
"224.60400","18.71723","0.02653"
"224.91000","18.74264","0.02680"
"225.21600","18.76823","0.02624"
"225.52200","18.79370","0.02646"
"225.82800","18.81923","0.02629"
"226.13400","18.84476","0.02669"
"226.44000","18.87017","0.02704"
"226.74600","18.89576","0.02751"
"227.05200","18.92118","0.02713"
"227.35800","18.94670","0.02625"
"227.66400","18.97218","0.02650"
"227.97000","18.99777","0.02662"
"228.27600","19.02324","0.02696"
"228.58200","19.04871","0.02725"
"228.88800","19.07424","0.02738"
"229.19400","19.09971","0.02730"
"229.50000","19.12524","0.02813"
"229.80600","19.15077","0.02801"
"230.11200","19.17624","0.02870"
"230.41800","19.20177","0.02841"
"230.72400","19.22718","0.02905"
"231.03000","19.25277","0.02826"
"231.33600","19.27818","0.02866"
"231.64200","19.30371","0.02854"
"231.94800","19.32918","0.02867"
"232.25400","19.35471","0.02904"
"232.56000","19.38024","0.02832"
"232.86600","19.40565","0.02846"
"233.17200","19.43124","0.02840"
"233.47800","19.45665","0.02842"
"233.78400","19.48224","0.02868"
"234.09000","19.50771","0.02879"
"234.39600","19.53324","0.02927"
"234.70200","19.55871","0.02969"
"235.00800","19.58418","0.02996"
"235.31400","19.60977","0.02979"
"235.62000","19.63512","0.03000"
"235.92600","19.66071","0.03073"
"236.23200","19.68624","0.03101"
"236.53800","19.71171","0.03100"
"236.84400","19.73724","0.03120"
"237.15000","19.76271","0.03123"
"237.45600","19.78824","0.03165"
"237.76200","19.81371","0.03143"
"238.06800","19.83918","0.03247"
"238.37400","19.86471","0.03245"
"238.68000","19.89024","0.03310"
"238.98600","19.91571","0.03330"
"239.29200","19.94118","0.03381"
"239.59800","19.96677","0.03370"
"239.90400","19.99218","0.03433"
"240.21000","20.01777","0.03458"
"240.51600","20.04318","0.03441"
"240.82200","20.06872","0.03555"
"241.12800","20.09419","0.03616"
"241.43400","20.11971","0.03562"
"241.74000","20.14524","0.03536"
"242.04600","20.17072","0.03649"
"242.35200","20.19624","0.03629"
"242.65800","20.22172","0.03702"
"242.96400","20.24725","0.03804"
"243.27000","20.27271","0.03817"
"243.57600","20.29819","0.03927"
"243.88200","20.32378","0.03938"
"244.18800","20.34919","0.04016"
"244.49400","20.37472","0.04129"
"244.80000","20.40013","0.04189"
"245.10600","20.42572","0.04280"
"245.41200","20.45119","0.04267"
"245.71800","20.47666","0.04371"
"246.02400","20.50219","0.04458"
"246.33000","20.52766","0.04527"
"246.63600","20.55319","0.04682"
"246.94200","20.57866","0.04625"
"247.24800","20.60419","0.04773"
"247.55400","20.62972","0.04835"
"247.86000","20.65519","0.04925"
"248.16600","20.68072","0.04972"
"248.47200","20.70619","0.05049"
"248.77800","20.73178","0.05151"
"249.08400","20.75719","0.05203"
"249.39000","20.78272","0.05152"
"249.69600","20.80819","0.05204"
"250.00200","20.83372","0.05264"
"250.30800","20.85919","0.05328"
"250.61400","20.88466","0.05310"
"250.92000","20.91025","0.02087"
"251.22600","20.93572","0.01751"
"251.53200","20.96125","0.01713"
"251.83800","20.98672","0.01941"
"252.14400","21.01219","0.01967"
"252.45000","21.03772","0.01815"
"252.75600","21.06319","0.01836"
"253.06200","21.08872","0.02015"
"253.36800","21.11426","0.01925"
"253.67400","21.13973","0.01850"
"253.98000","21.16520","0.01917"
"254.28600","21.19073","0.01940"
"254.59200","21.21620","0.01980"
"254.89800","21.24166","0.01891"
"255.20400","21.26720","0.01884"
"255.51000","21.29267","0.01978"
"255.81600","21.31825","0.01920"
"256.12200","21.34373","0.01799"
"256.42800","21.36920","0.01903"
"256.73400","21.39473","0.01972"
"257.04000","21.42020","0.01939"
"257.34600","21.44573","0.01896"
"257.65200","21.47120","0.01869"
"257.95800","21.49679","0.01960"
"258.26400","21.52220","0.01914"
"258.57000","21.54773","0.01841"
"258.87600","21.57320","0.01940"
"259.18200","21.59873","0.01995"
"259.48800","21.62420","0.01918"
"259.79400","21.64967","0.01883"
"260.10000","21.67526","0.01943"
"260.40600","21.70073","0.01926"
"260.71200","21.72626","0.01931"
"261.01800","21.75167","0.01928"
"261.32400","21.77720","0.02019"
"261.63000","21.80273","0.01963"
"261.93600","21.82820","0.01900"
"262.24200","21.85373","0.01909"
"262.54800","21.87926","0.01986"
"262.85400","21.90473","0.01955"
"263.16000","21.93020","0.01874"
"263.46600","21.95567","0.01872"
"263.77200","21.98120","0.02049"
"264.07800","22.00661","0.01954"
"264.38400","22.03226","0.01859"
"264.69000","22.05767","0.01928"
"264.99600","22.08320","0.02032"
"265.30200","22.10873","0.02003"
"265.60800","22.13426","0.01974"
"265.91400","22.15973","0.01964"
"266.22000","22.18515","0.01970"
"266.52600","22.21074","0.01907"
"266.83200","22.23620","0.01983"
"267.13800","22.26174","0.02041"
"267.44400","22.28720","0.01971"
"267.75000","22.31274","0.01961"
"268.05600","22.33821","0.01989"
"268.36200","22.36368","0.02024"
"268.66800","22.38921","0.02001"
"268.97400","22.41468","0.01930"
"269.28000","22.44021","0.02047"
"269.58600","22.46574","0.01975"
"269.89200","22.49121","0.01982"
"270.19800","22.51668","0.01950"
"270.50400","22.54221","0.02005"
"270.81000","22.56774","0.01989"
"271.11600","22.59321","0.01963"
"271.42200","22.61874","0.01983"
"271.72800","22.64421","0.01992"
"272.03400","22.66974","0.01974"
"272.34000","22.69521","0.01959"
"272.64600","22.72068","0.02096"
"272.95200","22.74627","0.02004"
"273.25800","22.77168","0.02034"
"273.56400","22.79721","0.01988"
"273.87000","22.82268","0.02092"
"274.17600","22.84827","0.02068"
"274.48200","22.87374","0.02018"
"274.78800","22.89927","0.01959"
"275.09400","22.92474","0.02036"
"275.40000","22.95015","0.02033"
"275.70600","22.97574","0.02035"
"276.01200","23.00121","0.02029"
"276.31800","23.02674","0.02023"
"276.62400","23.05227","0.02071"
"276.93000","23.07775","0.02043"
"277.23600","23.10321","0.02091"
"277.54200","23.12868","0.02043"
"277.84800","23.15421","0.02091"
"278.15400","23.17962","0.02064"
"278.46000","23.20522","0.02047"
"278.76600","23.23068","0.02030"
"279.07200","23.25622","0.02089"
"279.37800","23.28174","0.02139"
"279.68400","23.30721","0.02120"
"279.99000","23.33274","0.02055"
"280.29600","23.35816","0.02054"
"280.60200","23.38375","0.02026"
"280.90800","23.40922","0.02049"
"281.21400","23.43475","0.02046"
"281.52000","23.46028","0.02078"
"281.82600","23.48563","0.02072"
"282.13200","23.51122","0.02119"
"282.43800","23.53663","0.02027"
"282.74400","23.56222","0.02056"
"283.05000","23.58769","0.02090"
"283.35600","23.61322","0.02093"
"283.66200","23.63875","0.02077"
"283.96800","23.66416","0.02093"
"284.27400","23.68975","0.02065"
"284.58000","23.71510","0.02032"
"284.88600","23.74075","0.02038"
"285.19200","23.76616","0.02103"
"285.49800","23.79175","0.02090"
"285.80400","23.81722","0.02034"
"286.11000","23.84269","0.02102"
"286.41600","23.86816","0.02063"
"286.72200","23.89363","0.02086"
"287.02800","23.91922","0.02151"
"287.33400","23.94469","0.02115"
"287.64000","23.97022","0.02064"
"287.94600","23.99569","0.02142"
"288.25200","24.02122","0.02150"
"288.55800","24.04675","0.02112"
"288.86400","24.07216","0.02106"
"289.17000","24.09769","0.02129"
"289.47600","24.12316","0.02108"
"289.78200","24.14875","0.02096"
"290.08800","24.17428","0.02100"
"290.39400","24.19975","0.02099"
"290.70000","24.22528","0.02148"
"291.00600","24.25069","0.02079"
"291.31200","24.27622","0.02121"
"291.61800","24.30163","0.02067"
"291.92400","24.32723","0.02163"
"292.23000","24.35275","0.02096"
"292.53600","24.37828","0.02151"
"292.84200","24.40376","0.02178"
"293.14800","24.42917","0.02147"
"293.45400","24.45470","0.02181"
"293.76000","24.48011","0.02208"
"294.06600","24.50576","0.02153"
"294.37200","24.53123","0.02140"
"294.67800","24.55676","0.02258"
"294.98400","24.58223","0.02148"
"295.29000","24.60764","0.02192"
"295.59600","24.63317","0.02192"
"295.90200","24.65864","0.02216"
"296.20800","24.68423","0.02202"
"296.51400","24.70970","0.02197"
"296.82000","24.73523","0.02201"
"297.12600","24.76076","0.02197"
"297.43200","24.78623","0.02165"
"297.73800","24.81170","0.02221"
"298.04400","24.83717","0.02264"
"298.35000","24.86270","0.02228"
"298.65600","24.88823","0.02226"
"298.96200","24.91376","0.02306"
"299.26800","24.93923","0.02255"
"299.57400","24.96470","0.02254"
"299.88000","24.99023","0.02122"
"300.18600","25.01570","0.02271"
"300.49200","25.04123","0.02209"
"300.79800","25.06670","0.02222"
"301.10400","25.09223","0.02319"
"301.41000","25.11770","0.02257"
"301.71600","25.14318","0.02298"
"302.02200","25.16876","0.02299"
"302.32800","25.19423","0.02267"
"302.63400","25.21970","0.02290"
"302.94000","25.24517","0.02284"
"303.24600","25.27076","0.02306"
"303.55200","25.29623","0.02347"
"303.85800","25.32170","0.02344"
"304.16400","25.34723","0.02360"
"304.47000","25.37271","0.02400"
"304.77600","25.39824","0.02335"
"305.08200","25.42371","0.02388"
"305.38800","25.44924","0.02360"
"305.69400","25.47471","0.02359"
"306.00000","25.50024","0.02390"
"306.30600","25.52577","0.02425"
"306.61200","25.55124","0.02370"
"306.91800","25.57671","0.02390"
"307.22400","25.60218","0.02374"
"307.53000","25.62771","0.02435"
"307.83600","25.65324","0.02442"
"308.14200","25.67871","0.02430"
"308.44800","25.70424","0.02458"
"308.75400","25.72965","0.02422"
"309.06000","25.75524","0.02423"
"309.36600","25.78065","0.02442"
"309.67200","25.80624","0.02462"
"309.97800","25.83165","0.02486"
"310.28400","25.85718","0.02529"
"310.59000","25.88271","0.02537"
"310.89600","25.90818","0.02504"
"311.20200","25.93377","0.02526"
"311.50800","25.95924","0.02555"
"311.81400","25.98471","0.02589"
"312.12000","26.01018","0.02538"
"312.42600","26.03571","0.02543"
"312.73200","26.06124","0.02585"
"313.03800","26.08671","0.02638"
"313.34400","26.11230","0.02584"
"313.65000","26.13771","0.02603"
"313.95600","26.16324","0.02562"
"314.26200","26.18871","0.02580"
"314.56800","26.21418","0.02496"
"314.87400","26.23971","0.02541"
"315.18000","26.26518","0.02479"
"315.48600","26.29077","0.02560"
"315.79200","26.31618","0.02606"
"316.09800","26.34171","0.02593"
"316.40400","26.36719","0.02576"
"316.71000","26.39271","0.02601"
"317.01600","26.41818","0.02611"
"317.32200","26.44366","0.02659"
"317.62800","26.46931","0.02634"
"317.93400","26.49471","0.02663"
"318.24000","26.52030","0.02642"
"318.54600","26.54572","0.02706"
"318.85200","26.57125","0.02713"
"319.15800","26.59672","0.02711"
"319.46400","26.62219","0.02730"
"319.77000","26.64772","0.02755"
"320.07600","26.67319","0.02744"
"320.38200","26.69872","0.02706"
"320.68800","26.72419","0.02749"
"320.99400","26.74972","0.02761"
"321.30000","26.77519","0.02715"
"321.60600","26.80072","0.02687"
"321.91200","26.82625","0.02415"
"322.21800","26.85172","0.02381"
"322.52400","26.87725","0.02265"
"322.83000","26.90272","0.02505"
"323.13600","26.92819","0.02219"
"323.44200","26.95372","0.02419"
"323.74800","26.97919","0.02370"
"324.05400","27.00478","0.02335"
"324.36000","27.03013","0.02454"
"324.66600","27.05578","0.02317"
"324.97200","27.08119","0.02500"
"325.27800","27.10672","0.02380"
"325.58400","27.13219","0.02489"
"325.89000","27.15772","0.02420"
"326.19600","27.18325","0.02449"
"326.50200","27.20866","0.02532"
"326.80800","27.23425","0.02450"
"327.11400","27.25972","0.02585"
"327.42000","27.28519","0.02430"
"327.72600","27.31072","0.02549"
"328.03200","27.33625","0.02478"
"328.33800","27.36172","0.02524"
"328.64400","27.38719","0.02556"
"328.95000","27.41273","0.02564"
"329.25600","27.43813","0.02504"
"329.56200","27.46378","0.02562"
"329.86800","27.48920","0.02500"
"330.17400","27.51472","0.02556"
"330.48000","27.54020","0.02669"
"330.78600","27.56567","0.02626"
"331.09200","27.59119","0.02634"
"331.39800","27.61667","0.02705"
"331.70400","27.64226","0.02694"
"332.01000","27.66767","0.02683"
"332.31600","27.69320","0.02677"
"332.62200","27.71873","0.02728"
"332.92800","27.74420","0.02641"
"333.23400","27.76973","0.02746"
"333.54000","27.79520","0.02702"
"333.84600","27.82073","0.02740"
"334.15200","27.84620","0.02781"
"334.45800","27.87173","0.02783"
"334.76400","27.89720","0.02749"
"335.07000","27.92273","0.02728"
"335.37600","27.94826","0.02809"
"335.68200","27.97367","0.02863"
"335.98800","27.99926","0.02840"
"336.29400","28.02473","0.02807"
"336.60000","28.05026","0.02813"
"336.90600","28.07567","0.02793"
"337.21200","28.10120","0.02854"
"337.51800","28.12673","0.02826"
"337.82400","28.15214","0.02824"
"338.13000","28.17767","0.02912"
"338.43600","28.20320","0.02894"
"338.74200","28.22879","0.02910"
"339.04800","28.25420","0.02873"
"339.35400","28.27973","0.02819"
"339.66000","28.30526","0.02873"
"339.96600","28.33068","0.02861"
"340.27200","28.35620","0.02905"
"340.57800","28.38167","0.02933"
"340.88400","28.40720","0.02903"
"341.19000","28.43273","0.02897"
"341.49600","28.45827","0.02981"
"341.80200","28.48374","0.02933"
"342.10800","28.50920","0.02949"
"342.41400","28.53467","0.02986"
"342.72000","28.56014","0.02952"
"343.02600","28.58574","0.02925"
"343.33200","28.61127","0.02932"
"343.63800","28.63673","0.02887"
"343.94400","28.66226","0.02947"
"344.25000","28.68774","0.02943"
"344.55600","28.71321","0.02958"
"344.86200","28.73868","0.02983"
"345.16800","28.76427","0.02893"
"345.47400","28.78974","0.02960"
"345.78000","28.81527","0.02926"
"346.08600","28.84074","0.02880"
"346.39200","28.86615","0.02952"
"346.69800","28.89168","0.02966"
"347.00400","28.91715","0.02969"
"347.31000","28.94274","0.03029"
"347.61600","28.96821","0.02960"
"347.92200","28.99374","0.03040"
"348.22800","29.01921","0.03039"
"348.53400","29.04468","0.02910"
"348.84000","29.07027","0.02961"
"349.14600","29.09562","0.03021"
"349.45200","29.12121","0.02934"
"349.75800","29.14668","0.02917"
"350.06400","29.17221","0.02935"
"350.37000","29.19774","0.02881"
"350.67600","29.22321","0.02814"
"350.98200","29.24874","0.02735"
"351.28800","29.27415","0.02704"
"351.59400","29.29974","0.02676"
"351.90000","29.32515","0.02696"
"352.20600","29.35074","0.02730"
"352.51200","29.37621","0.02722"
"352.81800","29.40174","0.02732"
"353.12400","29.42727","0.02767"
"353.43000","29.45268","0.02824"
"353.73600","29.47821","0.02842"
"354.04200","29.50362","0.02835"
"354.34800","29.52921","0.02910"
"354.65400","29.55468","0.02857"
"354.96000","29.58021","0.02927"
"355.26600","29.60575","0.02938"
"355.57200","29.63116","0.02900"
"355.87800","29.65675","0.02904"
"356.18400","29.68222","0.02919"
"356.49000","29.70775","0.02926"
"356.79600","29.73322","0.02978"
"357.10200","29.75875","0.02973"
"357.40800","29.78428","0.02962"
"357.71400","29.80969","0.03037"
"358.02000","29.83522","0.03056"
"358.32600","29.86069","0.03060"
"358.63200","29.88622","0.03048"
"358.93800","29.91175","0.03123"
"359.24400","29.93728","0.03088"
"359.55000","29.96275","0.03051"
"359.85600","29.98816","0.03028"
"360.16200","30.01369","0.03105"
"360.46800","30.03916","0.03154"
"360.77400","30.06475","0.03119"
"361.08000","30.09016","0.03141"
"361.38600","30.11575","0.03187"
"361.69200","30.14122","0.03264"
"361.99800","30.16669","0.03268"
"362.30400","30.19228","0.03235"
"362.61000","30.21763","0.03201"
"362.91600","30.24322","0.03023"
"363.22200","30.26863","0.03040"
"363.52800","30.29422","0.03058"
"363.83400","30.31969","0.03056"
"364.14000","30.34522","0.03106"
"364.44600","30.37081","0.02924"
"364.75200","30.39622","0.03027"
"365.05800","30.42169","0.02857"
"365.36400","30.44722","0.03083"
"365.67000","30.47275","0.02930"
"365.97600","30.49822","0.03046"
"366.28200","30.52369","0.02987"
"366.58800","30.54928","0.02924"
"366.89400","30.57475","0.02974"
"367.20000","30.60022","0.02915"
"367.50600","30.62570","0.02880"
"367.81200","30.65122","0.02885"
"368.11800","30.67669","0.02782"
"368.42400","30.70222","0.02917"
"368.73000","30.72776","0.02795"
"369.03600","30.75317","0.03000"
"369.34200","30.77876","0.02888"
"369.64800","30.80416","0.02943"
"369.95400","30.82976","0.03031"
"370.26000","30.85517","0.03012"
"370.56600","30.88070","0.03068"
"370.87200","30.90629","0.03070"
"371.17800","30.93170","0.03148"
"371.48400","30.95723","0.03116"
"371.79000","30.98270","0.03191"
"372.09600","31.00829","0.03215"
"372.40200","31.03370","0.03148"
"372.70800","31.05917","0.03287"
"373.01400","31.08476","0.03307"
"373.32000","31.11023","0.03298"
"373.62600","31.13576","0.03259"
"373.93200","31.16117","0.03273"
"374.23800","31.18670","0.03208"
"374.54400","31.21217","0.03206"
"374.85000","31.23764","0.03096"
"375.15600","31.26323","0.03197"
"375.46200","31.28870","0.03157"
"375.76800","31.31423","0.03227"
"376.07400","31.33970","0.03317"
"376.38000","31.36523","0.03337"
"376.68600","31.39070","0.03385"
"376.99200","31.41617","0.03238"
"377.29800","31.44170","0.03280"
"377.60400","31.46723","0.03258"
"377.91000","31.49276","0.03313"
"378.21600","31.51817","0.03437"
"378.52200","31.54376","0.03373"
"378.82800","31.56923","0.03478"
"379.13400","31.59470","0.03471"
"379.44000","31.62017","0.03546"
"379.74600","31.64570","0.03551"
"380.05200","31.67123","0.03423"
"380.35800","31.69670","0.03493"
"380.66400","31.72223","0.03445"
"380.97000","31.74770","0.03631"
"381.27600","31.77323","0.03512"
"381.58200","31.79871","0.03688"
"381.88800","31.82423","0.03629"
"382.19400","31.84970","0.03750"
"382.50000","31.87523","0.03763"
"382.80600","31.90076","0.03787"
"383.11200","31.92617","0.03834"
"383.41800","31.95171","0.03627"
"383.72400","31.97724","0.03336"
"384.03000","32.00265","0.03057"
"384.33600","32.02824","0.02253"
"384.64200","32.05365","0.02502"
"384.94800","32.07924","0.02451"
"385.25400","32.10471","0.02141"
"385.56000","32.13024","0.02305"
"385.86600","32.15571","0.02118"
"386.17200","32.18118","0.02176"
"386.47800","32.20677","0.02341"
"386.78400","32.23218","0.02211"
"387.09000","32.25777","0.02150"
"387.39600","32.28318","0.02222"
"387.70200","32.30871","0.02303"
"388.00800","32.33418","0.02194"
"388.31400","32.35977","0.02260"
"388.62000","32.38524","0.02245"
"388.92600","32.41065","0.02281"
"389.23200","32.43624","0.02267"
"389.53800","32.46171","0.02242"
"389.84400","32.48724","0.02314"
"390.15000","32.51271","0.02251"
"390.45600","32.53824","0.02233"
"390.76200","32.56371","0.02380"
"391.06800","32.58918","0.02300"
"391.37400","32.61471","0.02322"
"391.68000","32.64018","0.02365"
"391.98600","32.66577","0.02294"
"392.29200","32.69124","0.02374"
"392.59800","32.71671","0.02368"
"392.90400","32.74218","0.02362"
"393.21000","32.76765","0.02403"
"393.51600","32.79318","0.02403"
"393.82200","32.81865","0.02387"
"394.12800","32.84424","0.02425"
"394.43400","32.86977","0.02406"
"394.74000","32.89524","0.02420"
"395.04600","32.92077","0.02418"
"395.35200","32.94619","0.02447"
"395.65800","32.97171","0.02370"
"395.96400","32.99718","0.02446"
"396.27000","33.02272","0.02396"
"396.57600","33.04819","0.02426"
"396.88200","33.07378","0.02410"
"397.18800","33.09925","0.02448"
"397.49400","33.12471","0.02435"
"397.80000","33.15018","0.02422"
"398.10600","33.17566","0.02490"
"398.41200","33.20119","0.02483"
"398.71800","33.22672","0.02501"
"399.02400","33.25225","0.02463"
"399.33000","33.27772","0.02484"
"399.63600","33.30325","0.02484"
"399.94200","33.32878","0.02544"
"400.24800","33.35419","0.02525"
"400.55400","33.37972","0.02577"
"400.86000","33.40519","0.02599"
"401.16600","33.43072","0.02583"
"401.47200","33.45619","0.02604"
"401.77800","33.48166","0.02572"
"402.08400","33.50725","0.02635"
"402.39000","33.53272","0.02565"
"402.69600","33.55819","0.02601"
"403.00200","33.58366","0.02654"
"403.30800","33.60925","0.02686"
"403.61400","33.63472","0.02414"
"403.92000","33.66025","0.02420"
"404.22600","33.68572","0.02420"
"404.53200","33.71119","0.02626"
"404.83800","33.73672","0.02417"
"405.14400","33.76219","0.02496"
"405.45000","33.78772","0.02552"
"405.75600","33.81325","0.02453"
"406.06200","33.83872","0.02598"
"406.36800","33.86425","0.02490"
"406.67400","33.88972","0.02535"
"406.98000","33.91519","0.02373"
"407.28600","33.94061","0.02451"
"407.59200","33.96626","0.02445"
"407.89800","33.99173","0.02514"
"408.20400","34.01725","0.02415"
"408.51000","34.04272","0.02498"
"408.81600","34.06819","0.02476"
"409.12200","34.09373","0.02459"
"409.42800","34.11920","0.02526"
"409.73400","34.14473","0.02519"
"410.04000","34.17020","0.02602"
"410.34600","34.19579","0.02563"
"410.65200","34.22126","0.02580"
"410.95800","34.24667","0.02548"
"411.26400","34.27220","0.02567"
"411.57000","34.29761","0.02663"
"411.87600","34.32326","0.02517"
"412.18200","34.34872","0.02620"
"412.48800","34.37426","0.02640"
"412.79400","34.39973","0.02629"
"413.10000","34.42520","0.02722"
"413.40600","34.45073","0.02660"
"413.71200","34.47614","0.02731"
"414.01800","34.50173","0.02746"
"414.32400","34.52714","0.02740"
"414.63000","34.55273","0.02734"
"414.93600","34.57826","0.02776"
"415.24200","34.60373","0.02688"
"415.54800","34.62920","0.02627"
"415.85400","34.65467","0.02594"
"416.16000","34.68020","0.02477"
"416.46600","34.70567","0.02734"
"416.77200","34.73120","0.02526"
"417.07800","34.75673","0.02668"
"417.38400","34.78226","0.02670"
"417.69000","34.80779","0.02642"
"417.99600","34.83320","0.02328"
"418.30200","34.85873","0.02376"
"418.60800","34.88414","0.02173"
"418.91400","34.90967","0.02304"
"419.22000","34.93520","0.02367"
"419.52600","34.96079","0.02229"
"419.83200","34.98632","0.02370"
"420.13800","35.01173","0.02261"
"420.44400","35.03727","0.02279"
"420.75000","35.06273","0.02409"
"421.05600","35.08826","0.02308"
"421.36200","35.11367","0.02396"
"421.66800","35.13927","0.02367"
"421.97400","35.16479","0.02375"
"422.28000","35.19020","0.02394"
"422.58600","35.21574","0.02264"
"422.89200","35.24115","0.02354"
"423.19800","35.26674","0.02350"
"423.50400","35.29215","0.02415"
"423.81000","35.31768","0.02426"
"424.11600","35.34321","0.02356"
"424.42200","35.36868","0.02422"
"424.72800","35.39421","0.02381"
"425.03400","35.41968","0.02344"
"425.34000","35.44521","0.02408"
"425.64600","35.47068","0.02436"
"425.95200","35.49621","0.02442"
"426.25800","35.52174","0.02423"
"426.56400","35.54721","0.02431"
"426.87000","35.57274","0.02423"
"427.17600","35.59815","0.02429"
"427.48200","35.62374","0.02469"
"427.78800","35.64921","0.02410"
"428.09400","35.67474","0.02450"
"428.40000","35.70021","0.02420"
"428.70600","35.72574","0.02389"
"429.01200","35.75127","0.02417"
"429.31800","35.77668","0.02374"
"429.62400","35.80221","0.02450"
"429.93000","35.82768","0.02399"
"430.23600","35.85321","0.02443"
"430.54200","35.87868","0.02418"
"430.84800","35.90421","0.02457"
"431.15400","35.92980","0.02442"
"431.46000","35.95521","0.02425"
"431.76600","35.98074","0.02482"
"432.07200","36.00615","0.02438"
"432.37800","36.03174","0.02496"
"432.68400","36.05722","0.02447"
"432.99000","36.08268","0.02468"
"433.29600","36.10827","0.02407"
"433.60200","36.13369","0.02472"
"433.90800","36.15921","0.02544"
"434.21400","36.18468","0.02516"
"434.52000","36.21022","0.02548"
"434.82600","36.23569","0.02547"
"435.13200","36.26116","0.02492"
"435.43800","36.28675","0.02493"
"435.74400","36.31227","0.02488"
"436.05000","36.33775","0.02510"
"436.35600","36.36316","0.02509"
"436.66200","36.38875","0.02510"
"436.96800","36.41422","0.02553"
"437.27400","36.43969","0.02551"
"437.58000","36.46527","0.02530"
"437.88600","36.49068","0.02567"
"438.19200","36.51622","0.02564"
"438.49800","36.54163","0.02554"
"438.80400","36.56722","0.02579"
"439.11000","36.59269","0.02637"
"439.41600","36.61816","0.02605"
"439.72200","36.64369","0.02599"
"440.02800","36.66916","0.02623"
"440.33400","36.69475","0.02568"
"440.64000","36.72022","0.02613"
"440.94600","36.74575","0.02652"
"441.25200","36.77122","0.02630"
"441.55800","36.79675","0.02636"
"441.86400","36.82222","0.02674"
"442.17000","36.84769","0.02661"
"442.47600","36.87328","0.02660"
"442.78200","36.89875","0.02658"
"443.08800","36.92428","0.02703"
"443.39400","36.94970","0.02676"
"443.70000","36.97516","0.02651"
"444.00600","37.00069","0.02632"
"444.31200","37.02617","0.02710"
"444.61800","37.05169","0.02733"
"444.92400","37.07716","0.02704"
"445.23000","37.10270","0.02778"
"445.53600","37.12822","0.02696"
"445.84200","37.15376","0.02772"
"446.14800","37.17923","0.02813"
"446.45400","37.20469","0.02752"
"446.76000","37.23022","0.02821"
"447.06600","37.25570","0.02753"
"447.37200","37.28128","0.02820"
"447.67800","37.30670","0.02812"
"447.98400","37.33223","0.02760"
"448.29000","37.35770","0.02799"
"448.59600","37.38316","0.02789"
"448.90200","37.40876","0.02829"
"449.20800","37.43417","0.02868"
"449.51400","37.45976","0.02834"
"449.82000","37.48523","0.02765"
"450.12600","37.51076","0.02804"
"450.43200","37.53617","0.02840"
"450.73800","37.56170","0.02828"
"451.04400","37.58723","0.02789"
"451.35000","37.61270","0.02851"
"451.65600","37.63823","0.02725"
"451.96200","37.66370","0.02872"
"452.26800","37.68923","0.02738"
"452.57400","37.71464","0.02807"
"452.88000","37.74017","0.02725"
"453.18600","37.76570","0.02775"
"453.49200","37.79117","0.02810"
"453.79800","37.81670","0.02808"
"454.10400","37.84217","0.02782"
"454.41000","37.86770","0.02794"
"454.71600","37.89323","0.02852"
"455.02200","37.91870","0.02861"
"455.32800","37.94423","0.02852"
"455.63400","37.96970","0.02844"
"455.94000","37.99523","0.02845"
"456.24600","38.02070","0.02907"
"456.47600","38.03990","0.02851"