File: Force_trajectories/170122_1/Specimen_RawData_7.csv
End date,"1/22/2017"
Specimen label,"18BG_46"
Maximum Load,"0.05879",N

Time,Extension,Load
(s),(mm),(N)
"0.00000","0.00000","-0.00024"
"0.24000","0.01842","0.00105"
"0.48000","0.04030","0.00153"
"0.72000","0.06015","0.00408"
"0.96000","0.08024","0.00357"
"1.20000","0.10015","0.00635"
"1.44000","0.12024","0.00636"
"1.68000","0.14021","0.00771"
"1.92000","0.16018","0.00836"
"2.16000","0.18021","0.00920"
"2.40000","0.20018","0.01013"
"2.64000","0.22020","0.00915"
"2.88000","0.24005","0.01205"
"3.12000","0.26020","0.01202"
"3.36000","0.28017","0.01238"
"3.60000","0.30014","0.01315"
"3.84000","0.32023","0.01324"
"4.08000","0.34020","0.01418"
"4.32000","0.36017","0.01358"
"4.56000","0.38020","0.01517"
"4.80000","0.40017","0.01477"
"5.04000","0.42014","0.01503"
"5.28000","0.44017","0.01619"
"5.52000","0.46014","0.01550"
"5.76000","0.48017","0.01749"
"6.00000","0.50014","0.01611"
"6.24000","0.52017","0.01729"
"6.48000","0.54020","0.01714"
"6.72000","0.56017","0.01719"
"6.96000","0.58020","0.01771"
"7.20000","0.60017","0.01844"
"7.44000","0.62020","0.01902"
"7.68000","0.64017","0.01779"
"7.92000","0.66014","0.01846"
"8.16000","0.68017","0.01810"
"8.40000","0.70026","0.01827"
"8.64000","0.72016","0.01929"
"8.88000","0.74019","0.01924"
"9.12000","0.76022","0.01954"
"9.36000","0.78013","0.01895"
"9.60000","0.80022","0.01918"
"9.84000","0.82013","0.01963"
"10.08000","0.84016","0.01913"
"10.32000","0.86013","0.02017"
"10.56000","0.88016","0.02007"
"10.80000","0.90013","0.01980"
"11.04000","0.92016","0.02004"
"11.28000","0.94025","0.02079"
"11.52000","0.96010","0.02064"
"11.76000","0.98019","0.02092"
"12.00000","1.00016","0.02081"
"12.24000","1.02019","0.02042"
"12.48000","1.04016","0.02022"
"12.72000","1.06019","0.02081"
"12.96000","1.08016","0.02130"
"13.20000","1.10019","0.02094"
"13.44000","1.12022","0.02111"
"13.68000","1.14013","0.02161"
"13.92000","1.16022","0.02068"
"14.16000","1.18013","0.02125"
"14.40000","1.20016","0.02133"
"14.64000","1.22018","0.02222"
"14.88000","1.24021","0.02204"
"15.12000","1.26012","0.02122"
"15.36000","1.28015","0.02121"
"15.60000","1.30018","0.02209"
"15.84000","1.32015","0.02217"
"16.08000","1.34018","0.02240"
"16.32000","1.36015","0.02220"
"16.56000","1.38018","0.02189"
"16.80000","1.40015","0.02294"
"17.04000","1.42024","0.02253"
"17.28000","1.44015","0.02248"
"17.52000","1.46018","0.02273"
"17.76000","1.48021","0.02274"
"18.00000","1.50018","0.02251"
"18.24000","1.52021","0.02208"
"18.48000","1.54012","0.02275"
"18.72000","1.56021","0.02279"
"18.96000","1.58012","0.02366"
"19.20000","1.60021","0.02319"
"19.44000","1.62018","0.02300"
"19.68000","1.64015","0.02337"
"19.92000","1.66018","0.02299"
"20.16000","1.68021","0.02374"
"20.40000","1.70018","0.02361"
"20.64000","1.72014","0.02384"
"20.88000","1.74023","0.02328"
"21.12000","1.76014","0.02350"
"21.36000","1.78017","0.02315"
"21.60000","1.80014","0.02326"
"21.84000","1.82017","0.02390"
"22.08000","1.84020","0.02369"
"22.32000","1.86017","0.02439"
"22.56000","1.88020","0.02423"
"22.80000","1.90017","0.02348"
"23.04000","1.92020","0.02401"
"23.28000","1.94011","0.02369"
"23.52000","1.96026","0.02405"
"23.76000","1.98017","0.02419"
"24.00000","2.00014","0.02403"
"24.24000","2.02017","0.02450"
"24.48000","2.04020","0.02438"
"24.72000","2.06017","0.02426"
"24.96000","2.08014","0.02477"
"25.20000","2.10023","0.02366"
"25.44000","2.12014","0.02427"
"25.68000","2.14023","0.02426"
"25.92000","2.16014","0.02441"
"26.16000","2.18017","0.02491"
"26.40000","2.20014","0.02483"
"26.64000","2.22022","0.02500"
"26.88000","2.24019","0.02504"
"27.12000","2.26016","0.02507"
"27.36000","2.28019","0.02443"
"27.60000","2.30010","0.02468"
"27.84000","2.32019","0.02463"
"28.08000","2.34010","0.02522"
"28.32000","2.36019","0.02511"
"28.56000","2.38010","0.02518"
"28.80000","2.40013","0.02501"
"29.04000","2.42016","0.02512"
"29.28000","2.44013","0.02592"
"29.52000","2.46022","0.02528"
"29.76000","2.48013","0.02559"
"30.00000","2.50016","0.02545"
"30.24000","2.52019","0.02610"
"30.48000","2.54022","0.02590"
"30.72000","2.56019","0.02611"
"30.96000","2.58016","0.02588"
"31.20000","2.60019","0.02542"
"31.44000","2.62016","0.02570"
"31.68000","2.64025","0.02631"
"31.92000","2.66016","0.02594"
"32.16000","2.68013","0.02641"
"32.40000","2.70010","0.02675"
"32.64000","2.72024","0.02632"
"32.88000","2.74015","0.02583"
"33.12000","2.76018","0.02626"
"33.36000","2.78015","0.02635"
"33.60000","2.80012","0.02645"
"33.84000","2.82021","0.02634"
"34.08000","2.84018","0.02708"
"34.32000","2.86015","0.02640"
"34.56000","2.88012","0.02666"
"34.80000","2.90021","0.02667"
"35.04000","2.92018","0.02716"
"35.28000","2.94021","0.02693"
"35.52000","2.96024","0.02646"
"35.76000","2.98015","0.02663"
"36.00000","3.00018","0.02705"
"36.24000","3.02015","0.02766"
"36.48000","3.04018","0.02741"
"36.72000","3.06015","0.02693"
"36.96000","3.08024","0.02647"
"37.20000","3.10015","0.02745"
"37.44000","3.12018","0.02737"
"37.68000","3.14021","0.02709"
"37.92000","3.16012","0.02783"
"38.16000","3.18021","0.02695"
"38.40000","3.20012","0.02776"
"38.64000","3.22014","0.02757"
"38.88000","3.24011","0.02747"
"39.12000","3.26020","0.02807"
"39.36000","3.28017","0.02782"
"39.60000","3.30014","0.02789"
"39.84000","3.32023","0.02807"
"40.08000","3.34014","0.02753"
"40.32000","3.36017","0.02812"
"40.56000","3.38020","0.02865"
"40.80000","3.40017","0.02798"
"41.04000","3.42014","0.02836"
"41.28000","3.44023","0.02841"
"41.52200","3.46032","0.02804"
"41.76200","3.48035","0.02803"
"42.00200","3.50038","0.02812"
"42.24200","3.52035","0.02822"
"42.48200","3.54038","0.02853"
"42.72200","3.56029","0.02905"
"42.96200","3.58038","0.02876"
"43.20200","3.60029","0.02813"
"43.44200","3.62038","0.02855"
"43.68200","3.64029","0.02835"
"43.92200","3.66038","0.02905"
"44.16200","3.68034","0.02917"
"44.40200","3.70037","0.02924"
"44.64200","3.72034","0.02887"
"44.88200","3.74031","0.02912"
"45.12200","3.76034","0.02921"
"45.36200","3.78031","0.02942"
"45.60200","3.80034","0.02897"
"45.84200","3.82031","0.02951"
"46.08200","3.84040","0.02901"
"46.32200","3.86037","0.02959"
"46.56200","3.88034","0.02948"
"46.80200","3.90037","0.02936"
"47.04200","3.92034","0.02963"
"47.28200","3.94037","0.02973"
"47.52200","3.96028","0.02921"
"47.76200","3.98037","0.02973"
"48.00200","4.00034","0.02961"
"48.24200","4.02037","0.02973"
"48.48200","4.04034","0.02980"
"48.72200","4.06037","0.03020"
"48.96200","4.08034","0.03021"
"49.20200","4.10031","0.02977"
"49.44200","4.12034","0.02968"
"49.68200","4.14031","0.03008"
"49.92200","4.16033","0.03023"
"50.16200","4.18030","0.03052"
"50.40200","4.20033","0.03015"
"50.64200","4.22030","0.03099"
"50.88200","4.24039","0.03116"
"51.12200","4.26036","0.03047"
"51.36200","4.28033","0.03109"
"51.60200","4.30036","0.03057"
"51.84200","4.32027","0.03106"
"52.08200","4.34030","0.03061"
"52.32200","4.36033","0.03081"
"52.56200","4.38036","0.03103"
"52.80200","4.40033","0.03098"
"53.04200","4.42036","0.03124"
"53.28200","4.44033","0.03147"
"53.52200","4.46036","0.03138"
"53.76200","4.48039","0.03152"
"54.00200","4.50030","0.03124"
"54.24200","4.52039","0.03136"
"54.48200","4.54030","0.03165"
"54.72200","4.56033","0.03161"
"54.96200","4.58036","0.03153"
"55.20200","4.60039","0.03098"
"55.44200","4.62036","0.03146"
"55.68200","4.64033","0.03137"
"55.92200","4.66036","0.03165"
"56.16200","4.68026","0.03150"
"56.40200","4.70035","0.03174"
"56.64200","4.72032","0.03167"
"56.88200","4.74035","0.03193"
"57.12200","4.76032","0.03161"
"57.36200","4.78041","0.03206"
"57.60200","4.80038","0.03279"
"57.84200","4.82035","0.03269"
"58.08200","4.84032","0.03196"
"58.32200","4.86029","0.03274"
"58.56200","4.88032","0.03279"
"58.80200","4.90029","0.03268"
"59.04200","4.92032","0.03271"
"59.28200","4.94029","0.03275"
"59.52200","4.96032","0.03282"
"59.76200","4.98035","0.03255"
"60.00200","5.00032","0.03304"
"60.24200","5.02035","0.03299"
"60.48200","5.04032","0.03221"
"60.72200","5.06035","0.03261"
"60.96200","5.08032","0.03250"
"61.20200","5.10041","0.03276"
"61.44200","5.12032","0.03280"
"61.68200","5.14041","0.03290"
"61.92200","5.16031","0.03371"
"62.16200","5.18034","0.03318"
"62.40200","5.20037","0.03323"
"62.64200","5.22034","0.03360"
"62.88200","5.24037","0.03362"
"63.12200","5.26028","0.03340"
"63.36200","5.28037","0.03411"
"63.60200","5.30034","0.03382"
"63.84200","5.32037","0.03370"
"64.08200","5.34040","0.03367"
"64.32200","5.36031","0.03412"
"64.56200","5.38040","0.03389"
"64.80200","5.40037","0.03414"
"65.04200","5.42034","0.03388"
"65.28200","5.44031","0.03396"
"65.52200","5.46034","0.03475"
"65.76200","5.48031","0.03519"
"66.00200","5.50034","0.03476"
"66.24200","5.52037","0.03446"
"66.48200","5.54034","0.03435"
"66.72200","5.56031","0.03447"
"66.96200","5.58034","0.03446"
"67.20200","5.60031","0.03467"
"67.44200","5.62034","0.03399"
"67.68200","5.64036","0.03435"
"67.92200","5.66028","0.03500"
"68.16200","5.68036","0.03534"
"68.40200","5.70039","0.03533"
"68.64200","5.72036","0.03567"
"68.88200","5.74033","0.03519"
"69.12200","5.76036","0.03580"
"69.36200","5.78039","0.03564"
"69.60200","5.80024","0.03576"
"69.84200","5.82039","0.03565"
"70.08200","5.84030","0.03588"
"70.32200","5.86039","0.03548"
"70.56200","5.88036","0.03538"
"70.80200","5.90033","0.03585"
"71.04200","5.92036","0.03602"
"71.28200","5.94033","0.03639"
"71.52200","5.96036","0.03650"
"71.76200","5.98027","0.03611"
"72.00200","6.00036","0.03639"
"72.24200","6.02033","0.03580"
"72.48200","6.04036","0.03609"
"72.72200","6.06033","0.03635"
"72.96200","6.08042","0.03577"
"73.20200","6.10033","0.03631"
"73.44200","6.12036","0.03573"
"73.68200","6.14038","0.03674"
"73.92200","6.16029","0.03577"
"74.16200","6.18032","0.03683"
"74.40200","6.20035","0.03651"
"74.64200","6.22032","0.03594"
"74.88200","6.24035","0.03617"
"75.12200","6.26032","0.03615"
"75.36200","6.28029","0.03596"
"75.60200","6.30032","0.03641"
"75.84200","6.32035","0.03679"
"76.08200","6.34026","0.03668"
"76.32200","6.36035","0.03689"
"76.56200","6.38032","0.03684"
"76.80200","6.40035","0.03702"
"77.04200","6.42026","0.03701"
"77.28200","6.44041","0.03668"
"77.52200","6.46032","0.03718"
"77.76200","6.48035","0.03684"
"78.00200","6.50038","0.03711"
"78.24200","6.52029","0.03767"
"78.48200","6.54038","0.03686"
"78.72200","6.56029","0.03705"
"78.96200","6.58038","0.03593"
"79.20200","6.60035","0.03587"
"79.44200","6.62038","0.03588"
"79.68200","6.64029","0.03580"
"79.92200","6.66032","0.03608"
"80.16200","6.68040","0.03616"
"80.40200","6.70031","0.03446"
"80.64200","6.72034","0.03508"
"80.88200","6.74031","0.03524"
"81.12200","6.76034","0.03506"
"81.36200","6.78031","0.03550"
"81.60200","6.80040","0.03580"
"81.84200","6.82031","0.03638"
"82.08200","6.84034","0.03559"
"82.32200","6.86031","0.03579"
"82.56200","6.88028","0.03536"
"82.80200","6.90037","0.03590"
"83.04200","6.92028","0.03578"
"83.28200","6.94037","0.03609"
"83.52200","6.96034","0.03645"
"83.76200","6.98037","0.03630"
"84.00200","7.00034","0.03625"
"84.24200","7.02031","0.03629"
"84.48200","7.04028","0.03622"
"84.72200","7.06037","0.03661"
"84.96200","7.08040","0.03684"
"85.20200","7.10037","0.03685"
"85.44200","7.12040","0.03714"
"85.68200","7.14031","0.03716"
"85.92200","7.16039","0.03733"
"86.16200","7.18036","0.03704"
"86.40200","7.20039","0.03737"
"86.64200","7.22036","0.03722"
"86.88200","7.24033","0.03750"
"87.12200","7.26036","0.03710"
"87.36200","7.28027","0.03730"
"87.60200","7.30036","0.03726"
"87.84200","7.32027","0.03760"
"88.08200","7.34036","0.03721"
"88.32200","7.36033","0.03759"
"88.56200","7.38030","0.03756"
"88.80200","7.40033","0.03793"
"89.04200","7.42036","0.03780"
"89.28200","7.44033","0.03748"
"89.52200","7.46030","0.03746"
"89.76200","7.48039","0.03766"
"90.00200","7.50030","0.03755"
"90.24200","7.52033","0.03879"
"90.48200","7.54030","0.03874"
"90.72200","7.56033","0.03851"
"90.96200","7.58036","0.03853"
"91.20200","7.60039","0.03825"
"91.44200","7.62036","0.03853"
"91.68200","7.64033","0.03951"
"91.92200","7.66041","0.03621"
"92.16200","7.68032","0.03715"
"92.40200","7.70035","0.03713"
"92.64200","7.72032","0.03793"
"92.88200","7.74029","0.03790"
"93.12200","7.76026","0.03804"
"93.36200","7.78035","0.03824"
"93.60200","7.80038","0.03858"
"93.84200","7.82035","0.03841"
"94.08200","7.84038","0.03879"
"94.32200","7.86029","0.03704"
"94.56200","7.88032","0.03751"
"94.80200","7.90035","0.03708"
"95.04200","7.92038","0.03765"
"95.28200","7.94035","0.03730"
"95.52200","7.96032","0.03772"
"95.76200","7.98035","0.03818"
"96.00200","8.00032","0.03782"
"96.24200","8.02035","0.03751"
"96.48200","8.04032","0.03795"
"96.72200","8.06035","0.03803"
"96.96200","8.08032","0.03821"
"97.20200","8.10035","0.03835"
"97.44200","8.12032","0.03840"
"97.68200","8.14035","0.03821"
"97.92200","8.16037","0.03832"
"98.16200","8.18034","0.03875"
"98.40200","8.20037","0.03945"
"98.64200","8.22034","0.03781"
"98.88200","8.24031","0.03876"
"99.12200","8.26028","0.03903"
"99.36200","8.28037","0.03962"
"99.60200","8.30034","0.03860"
"99.84200","8.32031","0.03944"
"100.08200","8.34034","0.03948"
"100.32200","8.36031","0.03917"
"100.56200","8.38034","0.04016"
"100.80200","8.40031","0.04004"
"101.04200","8.42034","0.03986"
"101.28200","8.44031","0.03998"
"101.52200","8.46034","0.03995"
"101.76200","8.48031","0.04028"
"102.00200","8.50034","0.04018"
"102.24200","8.52037","0.04024"
"102.48200","8.54028","0.04079"
"102.72200","8.56037","0.04043"
"102.96200","8.58028","0.04063"
"103.20200","8.60037","0.04085"
"103.44200","8.62033","0.04047"
"103.68200","8.64036","0.04035"
"103.92200","8.66033","0.04074"
"104.16200","8.68030","0.04119"
"104.40200","8.70039","0.04065"
"104.64200","8.72030","0.04108"
"104.88200","8.74033","0.04113"
"105.12200","8.76036","0.04153"
"105.36200","8.78033","0.04112"
"105.60200","8.80030","0.04134"
"105.84200","8.82039","0.04154"
"106.08200","8.84030","0.04194"
"106.32200","8.86033","0.04182"
"106.56200","8.88036","0.04187"
"106.80200","8.90033","0.04191"
"107.04200","8.92042","0.04274"
"107.28200","8.94033","0.04223"
"107.52200","8.96036","0.04280"
"107.76200","8.98027","0.04282"
"108.00200","9.00042","0.04260"
"108.24200","9.02033","0.04308"
"108.48200","9.04036","0.04304"
"108.72200","9.06039","0.04288"
"108.96200","9.08036","0.04333"
"109.20200","9.10033","0.04296"
"109.44200","9.12030","0.04317"
"109.68200","9.14032","0.04337"
"109.92200","9.16029","0.04371"
"110.16200","9.18032","0.04398"
"110.40200","9.20029","0.04323"
"110.64200","9.22038","0.04386"
"110.88200","9.24035","0.04369"
"111.12200","9.26032","0.04392"
"111.36200","9.28041","0.04345"
"111.60200","9.30038","0.04357"
"111.84200","9.32041","0.04373"
"112.08200","9.34026","0.04378"
"112.32200","9.36035","0.04426"
"112.56200","9.38032","0.04395"
"112.80200","9.40035","0.04454"
"113.04200","9.42038","0.04447"
"113.28200","9.44035","0.04445"
"113.52200","9.46032","0.04447"
"113.76200","9.48035","0.04395"
"114.00200","9.50038","0.04446"
"114.24200","9.52029","0.04435"
"114.48200","9.54032","0.04421"
"114.72200","9.56035","0.04438"
"114.96200","9.58038","0.04452"
"115.20200","9.60035","0.04421"
"115.44200","9.62032","0.04435"
"115.68200","9.64034","0.04465"
"115.92200","9.66031","0.04483"
"116.16200","9.68034","0.04504"
"116.40200","9.70031","0.04456"
"116.64200","9.72034","0.04531"
"116.88200","9.74031","0.04576"
"117.12200","9.76034","0.04551"
"117.36200","9.78031","0.04648"
"117.60200","9.80040","0.04546"
"117.84200","9.82037","0.04623"
"118.08200","9.84034","0.04658"
"118.32200","9.86037","0.04596"
"118.56200","9.88028","0.04628"
"118.80200","9.90037","0.04579"
"119.04200","9.92034","0.04568"
"119.28200","9.94037","0.04643"
"119.52200","9.96034","0.04640"
"119.76200","9.98037","0.04650"
"120.00200","10.00034","0.04645"
"120.24200","10.02031","0.04642"
"120.48200","10.04034","0.04668"
"120.72200","10.06025","0.04646"
"120.96200","10.08034","0.04656"
"121.20200","10.10031","0.04689"
"121.44200","10.12033","0.04748"
"121.68200","10.14031","0.04702"
"121.92200","10.16039","0.04678"
"122.16200","10.18036","0.04666"
"122.40200","10.20027","0.04693"
"122.64200","10.22036","0.04727"
"122.88200","10.24027","0.04745"
"123.12200","10.26036","0.04784"
"123.36200","10.28027","0.04756"
"123.60200","10.30036","0.04746"
"123.84200","10.32033","0.04705"
"124.08200","10.34036","0.04716"
"124.32200","10.36033","0.04704"
"124.56200","10.38030","0.04763"
"124.80200","10.40039","0.04687"
"125.04200","10.42030","0.04712"
"125.28200","10.44033","0.04732"
"125.52200","10.46036","0.04743"
"125.76200","10.48039","0.04731"
"126.00200","10.50036","0.04727"
"126.24200","10.52039","0.04721"
"126.48200","10.54036","0.04732"
"126.72200","10.56033","0.04712"
"126.96200","10.58030","0.04660"
"127.20200","10.60032","0.04754"
"127.44200","10.62036","0.04747"
"127.68200","10.64032","0.04744"
"127.92200","10.66035","0.04740"
"128.16200","10.68032","0.04748"
"128.40200","10.70035","0.04709"
"128.64200","10.72038","0.04689"
"128.88200","10.74029","0.04736"
"129.12200","10.76038","0.04765"
"129.36200","10.78035","0.04734"
"129.60200","10.80038","0.04739"
"129.84200","10.82023","0.04742"
"130.08200","10.84038","0.04787"
"130.32200","10.86035","0.04773"
"130.56200","10.88038","0.04884"
"130.80200","10.90035","0.04810"
"131.04200","10.92026","0.04775"
"131.28200","10.94035","0.04851"
"131.52200","10.96032","0.04824"
"131.76200","10.98035","0.04878"
"132.00200","11.00032","0.04846"
"132.24200","11.02041","0.04845"
"132.48200","11.04032","0.04880"
"132.72200","11.06035","0.04861"
"132.96200","11.08043","0.04765"
"133.20200","11.10029","0.04813"
"133.44200","11.12032","0.04779"
"133.68200","11.14034","0.04844"
"133.92200","11.16037","0.04815"
"134.16200","11.18034","0.04785"
"134.40200","11.20037","0.04845"
"134.64200","11.22034","0.04897"
"134.88200","11.24037","0.04933"
"135.12200","11.26034","0.04859"
"135.36200","11.28031","0.04823"
"135.60200","11.30034","0.04870"
"135.84200","11.32031","0.04861"
"136.08200","11.34034","0.04912"
"136.32200","11.36031","0.04894"
"136.56200","11.38040","0.04878"
"136.80200","11.40025","0.04853"
"137.04200","11.42034","0.04918"
"137.28200","11.44037","0.04918"
"137.52200","11.46040","0.04906"
"137.76200","11.48031","0.04826"
"138.00200","11.50034","0.04869"
"138.24200","11.52037","0.04872"
"138.48200","11.54028","0.04920"
"138.72200","11.56042","0.04920"
"138.96200","11.58034","0.04952"
"139.20200","11.60037","0.04933"
"139.44200","11.62034","0.04953"
"139.68200","11.64030","0.04960"
"139.92200","11.66033","0.04884"
"140.16200","11.68030","0.03926"
"140.40200","11.70039","0.03609"
"140.64200","11.72024","0.03922"
"140.88200","11.74039","0.03674"
"141.12200","11.76036","0.03921"
"141.36200","11.78033","0.03870"
"141.60200","11.80030","0.03944"
"141.84200","11.82033","0.03985"
"142.08200","11.84036","0.04045"
"142.32200","11.86033","0.04038"
"142.56200","11.88036","0.04116"
"142.80200","11.90027","0.04142"
"143.04200","11.92036","0.04105"
"143.28200","11.94033","0.04202"
"143.52200","11.96036","0.04270"
"143.76200","11.98033","0.04239"
"144.00200","12.00036","0.04241"
"144.24200","12.02033","0.04276"
"144.48200","12.04036","0.04256"
"144.72200","12.06038","0.04293"
"144.96200","12.08030","0.04339"
"145.20200","12.10032","0.04346"
"145.44200","12.12035","0.04469"
"145.68200","12.14033","0.04400"
"145.92200","12.16029","0.04467"
"146.16200","12.18038","0.04455"
"146.40200","12.20029","0.04459"
"146.64200","12.22032","0.04536"
"146.88200","12.24035","0.04468"
"147.12200","12.26026","0.04534"
"147.36200","12.28035","0.04599"
"147.60200","12.30026","0.04581"
"147.84200","12.32035","0.04407"
"148.08200","12.34032","0.04467"
"148.32200","12.36035","0.04427"
"148.56200","12.38026","0.04476"
"148.80200","12.40029","0.04513"
"149.04200","12.42038","0.04512"
"149.28200","12.44029","0.04536"
"149.52200","12.46038","0.04542"
"149.76200","12.48035","0.04539"
"150.00200","12.50032","0.04540"
"150.24200","12.52029","0.04576"
"150.48200","12.54032","0.04566"
"150.72200","12.56035","0.04585"
"150.96200","12.58037","0.04559"
"151.20200","12.60035","0.04441"
"151.44200","12.62031","0.04402"
"151.68200","12.64034","0.04485"
"151.92200","12.66031","0.04474"
"152.16200","12.68034","0.04474"
"152.40200","12.70031","0.04490"
"152.64200","12.72040","0.04505"
"152.88200","12.74031","0.04573"
"153.12200","12.76034","0.04595"
"153.36200","12.78037","0.04566"
"153.60200","12.80034","0.04627"
"153.84200","12.82037","0.04617"
"154.08200","12.84034","0.04635"
"154.32200","12.86037","0.04611"
"154.56200","12.88034","0.04665"
"154.80200","12.90037","0.04621"
"155.04200","12.92034","0.04731"
"155.28200","12.94037","0.04668"
"155.52200","12.96034","0.04704"
"155.76200","12.98037","0.04717"
"156.00200","13.00034","0.04685"
"156.24200","13.02031","0.04753"
"156.48200","13.04040","0.04761"
"156.72200","13.06031","0.04774"
"156.96200","13.08034","0.04714"
"157.20200","13.10030","0.04761"
"157.44200","13.12033","0.04780"
"157.68200","13.14030","0.04819"
"157.92200","13.16033","0.04792"
"158.16200","13.18036","0.04804"
"158.40200","13.20033","0.04859"
"158.64200","13.22036","0.04865"
"158.88200","13.24033","0.04879"
"159.12200","13.26030","0.04905"
"159.36200","13.28033","0.04769"
"159.60200","13.30036","0.04777"
"159.84200","13.32033","0.04910"
"160.08200","13.34036","0.04808"
"160.32200","13.36033","0.04821"
"160.56200","13.38030","0.04848"
"160.80200","13.40039","0.04878"
"161.04200","13.42030","0.04909"
"161.28200","13.44033","0.04933"
"161.52200","13.46036","0.04883"
"161.76200","13.48033","0.04925"
"162.00200","13.50030","0.04928"
"162.24200","13.52033","0.04915"
"162.48200","13.54036","0.04953"
"162.72200","13.56033","0.04937"
"162.96200","13.58035","0.04917"
"163.20200","13.60027","0.04962"
"163.44200","13.62036","0.04969"
"163.68200","13.64026","0.04991"
"163.92200","13.66035","0.04997"
"164.16200","13.68032","0.05026"
"164.40200","13.70035","0.05011"
"164.64200","13.72038","0.04965"
"164.88200","13.74029","0.04954"
"165.12200","13.76038","0.04963"
"165.36200","13.78029","0.04957"
"165.60200","13.80032","0.05003"
"165.84200","13.82035","0.05062"
"166.08200","13.84032","0.05019"
"166.32200","13.86035","0.04990"
"166.56200","13.88032","0.05067"
"166.80200","13.90035","0.05039"
"167.04200","13.92032","0.05074"
"167.28200","13.94041","0.05094"
"167.52200","13.96032","0.05077"
"167.76200","13.98035","0.05085"
"168.00200","14.00032","0.05173"
"168.24200","14.02035","0.05134"
"168.48200","14.04032","0.05137"
"168.72200","14.06035","0.05132"
"168.96200","14.08038","0.05205"
"169.20200","14.10029","0.05159"
"169.44200","14.12037","0.05197"
"169.68200","14.14035","0.05212"
"169.92200","14.16037","0.05193"
"170.16200","14.18034","0.05186"
"170.40200","14.20037","0.04852"
"170.64200","14.22028","0.04959"
"170.88200","14.24037","0.04878"
"171.12200","14.26040","0.04970"
"171.36200","14.28037","0.04945"
"171.60200","14.30034","0.05029"
"171.84200","14.32025","0.05039"
"172.08200","14.34034","0.05067"
"172.32200","14.36031","0.05032"
"172.56200","14.38040","0.05049"
"172.80200","14.40031","0.05086"
"173.04200","14.42040","0.05002"
"173.28200","14.44037","0.05072"
"173.52200","14.46028","0.05003"
"173.76200","14.48037","0.05087"
"174.00200","14.50034","0.05104"
"174.24200","14.52031","0.05141"
"174.48200","14.54028","0.05128"
"174.72200","14.56037","0.05098"
"174.96200","14.58028","0.05136"
"175.20200","14.60036","0.05181"
"175.44200","14.62040","0.05176"
"175.68200","14.64036","0.05186"
"175.92200","14.66039","0.05179"
"176.16200","14.68030","0.05177"
"176.40200","14.70033","0.05171"
"176.64200","14.72030","0.05200"
"176.88200","14.74039","0.05224"
"177.12200","14.76036","0.05176"
"177.36200","14.78039","0.05233"
"177.60200","14.80036","0.05246"
"177.84200","14.82033","0.05225"
"178.08200","14.84036","0.05225"
"178.32200","14.86033","0.05268"
"178.56200","14.88030","0.05301"
"178.80200","14.90027","0.05283"
"179.04200","14.92036","0.05247"
"179.28200","14.94033","0.05280"
"179.52200","14.96036","0.05297"
"179.76200","14.98033","0.05305"
"180.00200","15.00036","0.05295"
"180.24200","15.02039","0.05282"
"180.48200","15.04036","0.05371"
"180.72200","15.06033","0.05296"
"180.96200","15.08024","0.05306"
"181.20200","15.10038","0.05366"
"181.44200","15.12030","0.05347"
"181.68200","15.14038","0.05358"
"181.92200","15.16029","0.05337"
"182.16200","15.18032","0.05382"
"182.40200","15.20035","0.05382"
"182.64200","15.22032","0.05405"
"182.88200","15.24035","0.05376"
"183.12200","15.26032","0.05401"
"183.36200","15.28035","0.05373"
"183.60200","15.30032","0.05362"
"183.84200","15.32035","0.05405"
"184.08200","15.34032","0.05394"
"184.32200","15.36035","0.05246"
"184.56200","15.38038","0.05296"
"184.80200","15.40035","0.05287"
"185.04200","15.42038","0.05353"
"185.28200","15.44023","0.05372"
"185.52200","15.46032","0.05305"
"185.76200","15.48035","0.05289"
"186.00200","15.50032","0.05312"
"186.24200","15.52029","0.05276"
"186.48200","15.54032","0.05297"
"186.72200","15.56035","0.05288"
"186.96200","15.58032","0.05289"
"187.20200","15.60035","0.05317"
"187.44200","15.62031","0.05320"
"187.68200","15.64034","0.05335"
"187.92200","15.66031","0.05328"
"188.16200","15.68034","0.05306"
"188.40200","15.70031","0.05319"
"188.64200","15.72034","0.05325"
"188.88200","15.74031","0.05342"
"189.12200","15.76034","0.05295"
"189.36200","15.78037","0.05246"
"189.60200","15.80028","0.05299"
"189.84200","15.82037","0.05288"
"190.08200","15.84034","0.05310"
"190.32200","15.86037","0.05314"
"190.56200","15.88034","0.05290"
"190.80200","15.90037","0.05329"
"191.04200","15.92028","0.05297"
"191.28200","15.94037","0.05319"
"191.52200","15.96034","0.05353"
"191.76200","15.98031","0.05322"
"192.00200","16.00039","0.05344"
"192.24200","16.02031","0.05358"
"192.48200","16.04034","0.05351"
"192.72200","16.06031","0.05323"
"192.96200","16.08034","0.05337"
"193.20200","16.10036","0.05373"
"193.44200","16.12033","0.05332"
"193.68200","16.14036","0.05348"
"193.92200","16.16033","0.05352"
"194.16200","16.18030","0.05321"
"194.40200","16.20033","0.05386"
"194.64200","16.22036","0.05398"
"194.88200","16.24033","0.05377"
"195.12200","16.26036","0.05364"
"195.36200","16.28039","0.05358"
"195.60200","16.30030","0.05384"
"195.84200","16.32033","0.05343"
"196.08200","16.34036","0.05359"
"196.32200","16.36039","0.05389"
"196.56200","16.38036","0.05400"
"196.80200","16.40033","0.05445"
"197.04200","16.42030","0.05300"
"197.28200","16.44039","0.05334"
"197.52200","16.46036","0.05404"
"197.76200","16.48033","0.05407"
"198.00200","16.50035","0.05412"
"198.24200","16.52033","0.05374"
"198.48200","16.54036","0.05401"
"198.72200","16.56027","0.05278"
"198.96200","16.58035","0.05312"
"199.20200","16.60026","0.05312"
"199.44200","16.62036","0.05362"
"199.68200","16.64038","0.05392"
"199.92200","16.66035","0.05363"
"200.16200","16.68032","0.05381"
"200.40200","16.70029","0.05389"
"200.64200","16.72038","0.05429"
"200.88200","16.74029","0.04311"
"201.12200","16.76038","0.04407"
"201.36200","16.78029","0.04122"
"201.60200","16.80032","0.04276"
"201.84200","16.82035","0.04146"
"202.08200","16.84032","0.03996"
"202.32200","16.86035","0.04164"
"202.56200","16.88032","0.04111"
"202.80200","16.90035","0.04149"
"203.04200","16.92032","0.04250"
"203.28200","16.94041","0.04140"
"203.52200","16.96032","0.04293"
"203.76200","16.98035","0.04212"
"204.00200","17.00032","0.04249"
"204.24200","17.02035","0.04257"
"204.48200","17.04037","0.04257"
"204.72200","17.06034","0.04296"
"204.96200","17.08031","0.04332"
"205.20200","17.10028","0.04410"
"205.44200","17.12037","0.04337"
"205.68200","17.14028","0.04329"
"205.92200","17.16037","0.04470"
"206.16200","17.18034","0.04369"
"206.40200","17.20037","0.04487"
"206.64200","17.22028","0.04439"
"206.88200","17.24037","0.04437"
"207.12200","17.26034","0.04520"
"207.36200","17.28025","0.04489"
"207.60200","17.30034","0.04447"
"207.84200","17.32031","0.04418"
"208.08200","17.34040","0.04400"
"208.32200","17.36037","0.04440"
"208.56200","17.38034","0.04442"
"208.80200","17.40031","0.04461"
"209.04200","17.42034","0.04510"
"209.28200","17.44037","0.04496"
"209.52200","17.46028","0.04500"
"209.76200","17.48037","0.04534"
"210.00200","17.50028","0.04508"
"210.24200","17.52031","0.04566"
"210.48200","17.54034","0.04589"
"210.72200","17.56036","0.04567"
"210.96200","17.58033","0.04623"
"211.20200","17.60031","0.04592"
"211.44200","17.62033","0.04597"
"211.68200","17.64030","0.04605"
"211.92200","17.66033","0.04631"
"212.16200","17.68030","0.04669"
"212.40200","17.70033","0.04650"
"212.64200","17.72030","0.04577"
"212.88200","17.74039","0.04589"
"213.12200","17.76030","0.04600"
"213.36200","17.78027","0.04640"
"213.60200","17.80036","0.04664"
"213.84200","17.82033","0.04672"
"214.08200","17.84036","0.04745"
"214.32200","17.86033","0.04746"
"214.56200","17.88036","0.04790"
"214.80200","17.90033","0.04796"
"215.04200","17.92042","0.04802"
"215.28200","17.94033","0.04867"
"215.52200","17.96036","0.04846"
"215.76200","17.98039","0.04874"
"216.00200","18.00030","0.04859"
"216.24200","18.02039","0.04910"
"216.48200","18.04030","0.04943"
"216.72200","18.06038","0.04925"
"216.96200","18.08029","0.05003"
"217.20200","18.10038","0.04984"
"217.44200","18.12029","0.05041"
"217.68200","18.14032","0.05084"
"217.92200","18.16035","0.05061"
"218.16200","18.18032","0.05078"
"218.40200","18.20035","0.05118"
"218.64200","18.22032","0.05164"
"218.88200","18.24035","0.05130"
"219.12200","18.26032","0.05209"
"219.36200","18.28029","0.05238"
"219.60200","18.30032","0.05266"
"219.84200","18.32035","0.05272"
"220.08200","18.34038","0.05245"
"220.32200","18.36029","0.05257"
"220.56200","18.38032","0.05250"
"220.80200","18.40035","0.05219"
"221.04200","18.42038","0.05229"
"221.28200","18.44035","0.05209"
"221.52200","18.46044","0.05249"
"221.76200","18.48035","0.05294"
"222.00200","18.50032","0.05306"
"222.24200","18.52035","0.05275"
"222.48200","18.54032","0.05324"
"222.72200","18.56034","0.05332"
"222.96200","18.58032","0.05351"
"223.20200","18.60035","0.05351"
"223.44200","18.62031","0.05417"
"223.68200","18.64040","0.05378"
"223.92200","18.66031","0.05436"
"224.16200","18.68034","0.05447"
"224.40200","18.70037","0.05531"
"224.64200","18.72034","0.05505"
"224.88200","18.74037","0.05479"
"225.12200","18.76028","0.05544"
"225.36200","18.78037","0.05518"
"225.60200","18.80028","0.05583"
"225.84200","18.82037","0.05572"
"226.08200","18.84034","0.05596"
"226.32200","18.86031","0.05585"
"226.56200","18.88034","0.05607"
"226.80200","18.90031","0.05628"
"227.04200","18.92034","0.05657"
"227.28200","18.94031","0.05653"
"227.52200","18.96040","0.05671"
"227.76200","18.98031","0.05686"
"228.00200","19.00034","0.05725"
"228.24200","19.02036","0.05726"
"228.48200","19.04033","0.05745"
"228.72200","19.06037","0.05730"
"228.96200","19.08034","0.05721"
"229.20200","19.10031","0.05735"
"229.44200","19.12027","0.05791"
"229.68200","19.14036","0.05776"
"229.92200","19.16027","0.05760"
"230.16200","19.18036","0.05762"
"230.40200","19.20033","0.05817"
"230.64200","19.22030","0.05790"
"230.88200","19.24033","0.05815"
"231.12200","19.26036","0.05812"
"231.36200","19.28033","0.05780"
"231.60200","19.30030","0.05834"
"231.84200","19.32039","0.05781"
"232.08200","19.34030","0.05786"
"232.32200","19.36033","0.05848"
"232.56200","19.38030","0.05825"
"232.80200","19.40033","0.05818"
"233.04200","19.42030","0.05824"
"233.28200","19.44033","0.05800"
"233.52200","19.46036","0.05777"
"233.76200","19.48027","0.05763"
"234.00200","19.50036","0.05797"
"234.24200","19.52027","0.05780"
"234.48200","19.54036","0.05784"
"234.72200","19.56033","0.05838"
"234.96200","19.58035","0.05741"
"235.20200","19.60032","0.05729"
"235.44200","19.62035","0.05755"
"235.68200","19.64033","0.05791"
"235.92200","19.66029","0.05759"
"236.16200","19.68038","0.05541"
"236.40200","19.70029","0.05268"
"236.64200","19.72032","0.05266"
"236.88200","19.74029","0.05253"
"237.12200","19.76038","0.05284"
"237.36200","19.78035","0.05284"
"237.60200","19.80038","0.05267"
"237.84200","19.82035","0.05303"
"238.08200","19.84032","0.05323"
"238.32200","19.86035","0.05331"
"238.56200","19.88032","0.05380"
"238.80200","19.90035","0.05323"
"239.04200","19.92032","0.05401"
"239.28200","19.94041","0.05449"
"239.52200","19.96032","0.05416"
"239.76200","19.98034","0.05452"
"240.00200","20.00038","0.05450"
"240.24200","20.02035","0.05412"
"240.48200","20.04038","0.05381"
"240.72200","20.06034","0.05441"
"240.96200","20.08031","0.05422"
"241.20200","20.10028","0.05488"
"241.44200","20.12037","0.05527"
"241.68200","20.14028","0.05505"
"241.92200","20.16037","0.05463"
"242.16200","20.18040","0.05445"
"242.40200","20.20031","0.05477"
"242.64200","20.22034","0.05487"
"242.88200","20.24031","0.05497"
"243.12200","20.26034","0.05489"
"243.36200","20.28025","0.05490"
"243.60200","20.30034","0.05061"
"243.84200","20.32031","0.04683"
"244.08200","20.34034","0.04947"
"244.32200","20.36031","0.04894"
"244.56200","20.38028","0.04948"
"244.80200","20.40037","0.05047"
"245.04200","20.42034","0.05010"
"245.28200","20.44031","0.05147"
"245.52200","20.46034","0.05091"
"245.76200","20.48036","0.05171"
"246.00200","20.50034","0.05144"
"246.24200","20.52037","0.05200"
"246.48200","20.54034","0.05171"
"246.72200","20.56036","0.05173"
"246.96200","20.58033","0.05203"
"247.20200","20.60036","0.05180"
"247.44200","20.62033","0.05185"
"247.68200","20.64030","0.05181"
"247.92200","20.66033","0.05219"
"248.16200","20.68030","0.05113"
"248.40200","20.70033","0.05160"
"248.64200","20.72036","0.05181"
"248.88200","20.74033","0.05194"
"249.12200","20.76036","0.05183"
"249.36200","20.78033","0.05230"
"249.60200","20.80036","0.05249"
"249.84200","20.82027","0.05162"
"250.08200","20.84036","0.05155"
"250.32200","20.86033","0.05211"
"250.56200","20.88036","0.05229"
"250.80200","20.90039","0.05224"
"251.04200","20.92036","0.05232"
"251.28200","20.94039","0.05180"
"251.52200","20.96030","0.05191"
"251.76200","20.98039","0.05162"
"252.00200","21.00030","0.05243"
"252.24200","21.02032","0.05212"
"252.48200","21.04036","0.05146"
"252.72200","21.06033","0.05074"
"252.96200","21.08035","0.05033"
"253.20200","21.10032","0.05013"
"253.44200","21.12035","0.04916"
"253.68200","21.14032","0.04742"
"253.92200","21.16035","0.04772"
"254.16200","21.18026","0.04824"
"254.40200","21.20035","0.04858"
"254.64200","21.22032","0.04884"
"254.88200","21.24029","0.04895"
"255.12200","21.26038","0.04948"
"255.36200","21.28035","0.04972"
"255.60200","21.30032","0.05030"
"255.84200","21.32035","0.05012"
"256.08200","21.34032","0.05012"
"256.32200","21.36029","0.05030"
"256.56200","21.38038","0.05093"
"256.80200","21.40035","0.05093"
"257.04200","21.42038","0.05093"
"257.28200","21.44029","0.04980"
"257.52200","21.46037","0.05048"
"257.76200","21.48034","0.05003"
"258.00200","21.50032","0.05005"
"258.24200","21.52041","0.05041"
"258.48200","21.54025","0.05107"
"258.72200","21.56034","0.05070"
"258.96200","21.58026","0.05141"
"259.20200","21.60040","0.05117"
"259.44200","21.62037","0.05205"
"259.68200","21.64034","0.05156"
"259.92200","21.66031","0.05229"
"260.16200","21.68034","0.05241"
"260.40200","21.70037","0.05235"
"260.64200","21.72034","0.05236"
"260.88200","21.74037","0.05300"
"261.12200","21.76028","0.05304"
"261.36200","21.78037","0.05330"
"261.60200","21.80034","0.05309"
"261.84200","21.82037","0.05327"
"262.08200","21.84034","0.05379"
"262.32200","21.86031","0.05375"
"262.56200","21.88040","0.05307"
"262.80200","21.90031","0.05337"
"263.04200","21.92034","0.05362"
"263.28200","21.94031","0.05355"
"263.52200","21.96034","0.05338"
"263.76200","21.98030","0.05359"
"264.00200","22.00034","0.04911"
"264.24200","22.02037","0.04917"
"264.48200","22.04033","0.04944"
"264.72200","22.06030","0.05012"
"264.96200","22.08034","0.05052"
"265.20200","22.10036","0.05095"
"265.44200","22.12027","0.05138"
"265.68200","22.14036","0.05132"
"265.92200","22.16027","0.05164"
"266.16200","22.18036","0.05135"
"266.40200","22.20039","0.05207"
"266.64200","22.22036","0.05149"
"266.88200","22.24033","0.05146"
"267.12200","22.26036","0.05199"
"267.36200","22.28039","0.05189"
"267.60200","22.30030","0.05298"
"267.84200","22.32039","0.05246"
"268.08200","22.34030","0.05247"
"268.32200","22.36039","0.05333"
"268.56200","22.38036","0.05343"
"268.80200","22.40033","0.05317"
"269.04200","22.42036","0.05304"
"269.28200","22.44033","0.05353"
"269.52200","22.46035","0.05339"
"269.76200","22.48027","0.05385"
"270.00200","22.50042","0.05360"
"270.24200","22.52033","0.05399"
"270.48200","22.54036","0.05361"
"270.72200","22.56032","0.05384"
"270.96200","22.58035","0.05411"
"271.20200","22.60032","0.05390"
"271.44200","22.62035","0.05458"
"271.68200","22.64032","0.05466"
"271.92200","22.66029","0.05437"
"272.16200","22.68038","0.05452"
"272.40200","22.70035","0.05428"
"272.64200","22.72038","0.05442"
"272.88200","22.74035","0.05487"
"273.12200","22.76038","0.05443"
"273.36200","22.78035","0.05474"
"273.60200","22.80032","0.05441"
"273.84200","22.82035","0.05469"
"274.08200","22.84032","0.05463"
"274.32200","22.86035","0.05509"
"274.56200","22.88032","0.05510"
"274.80200","22.90035","0.05503"
"275.04200","22.92032","0.05500"
"275.28200","22.94040","0.05499"
"275.52200","22.96026","0.05494"
"275.76200","22.98035","0.05533"
"276.00200","23.00032","0.05451"
"276.24200","23.02028","0.05516"
"276.48200","23.04037","0.05540"
"276.72200","23.06028","0.05499"
"276.96200","23.08037","0.05518"
"277.20200","23.10034","0.05522"
"277.44200","23.12031","0.05582"
"277.68200","23.14034","0.05550"
"277.92200","23.16031","0.05587"
"278.16200","23.18040","0.05607"
"278.40200","23.20025","0.05612"
"278.64200","23.22040","0.05594"
"278.88200","23.24031","0.05596"
"279.12200","23.26028","0.05574"
"279.36200","23.28031","0.05543"
"279.60200","23.30034","0.05557"
"279.84200","23.32037","0.05572"
"280.08200","23.34034","0.05585"
"280.32200","23.36031","0.05569"
"280.56200","23.38028","0.05538"
"280.80200","23.40031","0.05550"
"281.04200","23.42034","0.05575"
"281.28200","23.44037","0.05584"
"281.52200","23.46034","0.05542"
"281.76200","23.48037","0.05597"
"282.00200","23.50028","0.05609"
"282.24200","23.52036","0.05588"
"282.48200","23.54040","0.05603"
"282.72200","23.56030","0.05601"
"282.96200","23.58033","0.05596"
"283.20200","23.60030","0.05614"
"283.44200","23.62033","0.05595"
"283.68200","23.64036","0.05608"
"283.92200","23.66033","0.05619"
"284.16200","23.68030","0.05644"
"284.40200","23.70039","0.05639"
"284.64200","23.72042","0.05650"
"284.88200","23.74027","0.05648"
"285.12200","23.76036","0.05661"
"285.36200","23.78027","0.05629"
"285.60200","23.80036","0.05641"
"285.84200","23.82033","0.05657"
"286.08200","23.84042","0.05660"
"286.32200","23.86033","0.05708"
"286.56200","23.88030","0.05685"
"286.80200","23.90039","0.05678"
"287.04200","23.92030","0.05666"
"287.28200","23.94039","0.05679"
"287.52200","23.96030","0.05693"
"287.76200","23.98038","0.05679"
"288.00200","24.00035","0.05658"
"288.24200","24.02039","0.05666"
"288.48200","24.04036","0.05706"
"288.72200","24.06033","0.05683"
"288.96200","24.08035","0.05691"
"289.20200","24.10032","0.05726"
"289.44200","24.12035","0.05691"
"289.68200","24.14032","0.05736"
"289.92200","24.16035","0.05684"
"290.16200","24.18032","0.05695"
"290.40200","24.20035","0.05699"
"290.64200","24.22032","0.05714"
"290.88200","24.24035","0.05707"
"291.12200","24.26032","0.05713"
"291.36200","24.28035","0.05733"
"291.60200","24.30038","0.05725"
"291.84200","24.32029","0.05699"
"292.08200","24.34038","0.05718"
"292.32200","24.36029","0.05727"
"292.56200","24.38038","0.05739"
"292.80200","24.40029","0.05747"
"293.04200","24.42038","0.05750"
"293.28200","24.44035","0.05743"
"293.52200","24.46032","0.05777"
"293.76200","24.48034","0.05804"
"294.00200","24.50026","0.05645"
"294.24200","24.52040","0.05671"
"294.48200","24.54031","0.05627"
"294.72200","24.56034","0.05692"
"294.96200","24.58031","0.05736"
"295.20200","24.60028","0.05732"
"295.44200","24.62031","0.05713"
"295.68200","24.64034","0.05707"
"295.92200","24.66037","0.05703"
"296.16200","24.68028","0.05635"
"296.40200","24.70037","0.05720"
"296.64200","24.72028","0.05598"
"296.88200","24.74037","0.05590"
"297.12200","24.76028","0.05607"
"297.36200","24.78037","0.05637"
"297.60200","24.80034","0.05592"
"297.84200","24.82037","0.05631"
"298.08200","24.84034","0.05666"
"298.32200","24.86031","0.05665"
"298.56200","24.88040","0.05672"
"298.80200","24.90031","0.05714"
"299.04200","24.92034","0.05710"
"299.28200","24.94031","0.05705"
"299.52200","24.96034","0.05708"
"299.76200","24.98031","0.05736"
"300.00200","25.00034","0.05699"
"300.24200","25.02036","0.05681"
"300.48200","25.04034","0.05691"
"300.72200","25.06036","0.05736"
"300.96200","25.08027","0.05690"
"301.20200","25.10036","0.05707"
"301.44200","25.12033","0.05721"
"301.68200","25.14036","0.05772"
"301.92200","25.16033","0.05762"
"302.16200","25.18036","0.05746"
"302.40200","25.20033","0.05759"
"302.64200","25.22024","0.05784"
"302.88200","25.24039","0.05767"
"303.12200","25.26030","0.05767"
"303.36200","25.28033","0.05807"
"303.60200","25.30024","0.05779"
"303.84200","25.32039","0.05829"
"304.08200","25.34030","0.05811"
"304.32200","25.36039","0.05802"
"304.56200","25.38036","0.05819"
"304.80200","25.40033","0.05807"
"305.04200","25.42036","0.05846"
"305.28200","25.44033","0.05820"
"305.52200","25.46029","0.05788"
"305.76200","25.48027","0.05783"
"306.00200","25.50036","0.05780"
"306.24200","25.52032","0.05804"
"306.48200","25.54036","0.05783"
"306.72200","25.56038","0.05793"
"306.96200","25.58029","0.05742"
"307.20200","25.60038","0.05744"
"307.44200","25.62029","0.05767"
"307.68200","25.64032","0.05766"
"307.92200","25.66029","0.05779"
"308.16200","25.68038","0.05742"
"308.40200","25.70029","0.05794"
"308.64200","25.72032","0.05785"
"308.88200","25.74035","0.05788"
"309.12200","25.76032","0.05783"
"309.36200","25.78041","0.05780"
"309.60200","25.80032","0.05753"
"309.84200","25.82035","0.05730"
"310.08200","25.84032","0.05727"
"310.32200","25.86041","0.05704"
"310.56200","25.88032","0.05761"
"310.80200","25.90035","0.05774"
"311.04200","25.92038","0.05780"
"311.28200","25.94029","0.05781"
"311.52200","25.96037","0.05799"
"311.76200","25.98035","0.05795"
"312.00200","26.00038","0.05770"
"312.24200","26.02029","0.05778"
"312.48200","26.04037","0.05757"
"312.72200","26.06034","0.05740"
"312.96200","26.08038","0.05738"
"313.20200","26.10040","0.05633"
"313.44200","26.12031","0.05646"
"313.68200","26.14040","0.05679"
"313.92200","26.16031","0.05688"
"314.16200","26.18034","0.05681"
"314.40200","26.20025","0.05613"
"314.64200","26.22040","0.05458"
"314.88200","26.24031","0.05471"
"315.12200","26.26034","0.05469"
"315.36200","26.28037","0.05495"
"315.60200","26.30034","0.05491"
"315.84200","26.32037","0.05556"
"316.08200","26.34028","0.05487"
"316.32200","26.36037","0.05581"
"316.56200","26.38034","0.05544"
"316.80200","26.40037","0.05515"
"317.04200","26.42034","0.05529"
"317.28200","26.44037","0.05506"
"317.52200","26.46040","0.05515"
"317.76200","26.48037","0.05564"
"318.00200","26.50034","0.05588"
"318.24200","26.52030","0.05613"
"318.48200","26.54033","0.05598"
"318.72200","26.56024","0.05568"
"318.96200","26.58039","0.05559"
"319.20200","26.60036","0.05601"
"319.44200","26.62033","0.05610"
"319.68200","26.64036","0.05577"
"319.92200","26.66033","0.05625"
"320.16200","26.68030","0.05593"
"320.40200","26.70033","0.05563"
"320.64200","26.72036","0.05608"
"320.88200","26.74027","0.05638"
"321.12200","26.76036","0.05622"
"321.36200","26.78027","0.05614"
"321.60200","26.80036","0.05493"
"321.84200","26.82033","0.05439"
"322.08200","26.84036","0.05436"
"322.32200","26.86033","0.05272"
"322.56200","26.88030","0.05338"
"322.80200","26.90039","0.05379"
"323.04200","26.92024","0.05400"
"323.28200","26.94033","0.05451"
"323.52200","26.96036","0.05447"
"323.76200","26.98039","0.05509"
"324.00200","27.00035","0.05524"
"324.24200","27.02032","0.05564"
"324.48200","27.04036","0.05581"
"324.72200","27.06027","0.05570"
"324.96200","27.08035","0.05535"
"325.20200","27.10027","0.05585"
"325.44200","27.12035","0.05500"
"325.68200","27.14032","0.05563"
"325.92200","27.16035","0.05525"
"326.16200","27.18032","0.05583"
"326.40200","27.20041","0.05585"
"326.64200","27.22032","0.05626"
"326.88200","27.24029","0.05656"
"327.12200","27.26038","0.05632"
"327.36200","27.28029","0.05691"
"327.60200","27.30032","0.05685"
"327.84200","27.32029","0.05705"
"328.08200","27.34038","0.05700"
"328.32200","27.36029","0.05690"
"328.56200","27.38038","0.05747"
"328.80200","27.40035","0.05739"
"329.04200","27.42032","0.05750"
"329.28200","27.44035","0.05737"
"329.52200","27.46026","0.05729"
"329.76200","27.48035","0.05779"
"330.00200","27.50032","0.05777"
"330.24200","27.52034","0.05733"
"330.48200","27.54032","0.05735"
"330.72200","27.56035","0.05760"
"330.96200","27.58037","0.05751"
"331.20200","27.60034","0.05738"
"331.44200","27.62037","0.05784"
"331.68200","27.64029","0.05753"
"331.92200","27.66037","0.05775"
"332.16200","27.68034","0.05780"
"332.40200","27.70043","0.05756"
"332.64200","27.72034","0.05742"
"332.88200","27.74031","0.05735"
"333.12200","27.76034","0.05730"
"333.36200","27.78031","0.05736"
"333.60200","27.80034","0.05732"
"333.84200","27.82031","0.05772"
"334.08200","27.84034","0.05749"
"334.32200","27.86031","0.05738"
"334.56200","27.88040","0.05782"
"334.80200","27.90031","0.05760"
"335.04200","27.92040","0.05756"
"335.28200","27.94037","0.05786"
"335.52200","27.96034","0.05757"
"335.76200","27.98030","0.05788"
"336.00200","28.00033","0.05758"
"336.24200","28.02037","0.05794"
"336.48200","28.04021","0.05784"
"336.72200","28.06037","0.05766"
"336.96200","28.08034","0.05777"
"337.20200","28.10036","0.05768"
"337.44200","28.12033","0.05815"
"337.68200","28.14030","0.05810"
"337.92200","28.16033","0.05805"
"338.16200","28.18036","0.05826"
"338.40200","28.20039","0.05805"
"338.64200","28.22024","0.05787"
"338.88200","28.24039","0.05814"
"339.12200","28.26030","0.05802"
"339.36200","28.28033","0.05799"
"339.60200","28.30036","0.05823"
"339.84200","28.32033","0.05803"
"340.08200","28.34030","0.05856"
"340.32200","28.36033","0.05826"
"340.56200","28.38036","0.05833"
"340.80200","28.40033","0.05831"
"341.04200","28.42036","0.05825"
"341.28200","28.44033","0.05847"
"341.52200","28.46042","0.05828"
"341.76200","28.48038","0.05831"
"342.00200","28.50030","0.05802"
"342.24200","28.52026","0.05849"
"342.48200","28.54030","0.05829"
"342.72200","28.56038","0.05879"
"342.96200","28.58030","0.05843"
"343.20200","28.60039","0.05820"
"343.44200","28.62029","0.05805"
"343.68200","28.64038","0.05824"
"343.92200","28.66035","0.05807"
"344.16200","28.68032","0.05806"
"344.40200","28.70035","0.05804"
"344.64200","28.72032","0.05803"
"344.88200","28.74035","0.05803"
"345.12200","28.76032","0.05820"
"345.36200","28.78035","0.05813"
"345.60200","28.80032","0.05824"
"345.84200","28.82035","0.05829"
"346.08200","28.84032","0.05814"
"346.32200","28.86035","0.05842"
"346.56200","28.88032","0.05808"
"346.80200","28.90029","0.05810"
"347.04200","28.92038","0.05776"
"347.28200","28.94029","0.05794"
"347.52200","28.96032","0.05804"
"347.76200","28.98035","0.05266"
"348.00200","29.00032","0.04825"
"348.24200","29.02035","0.04845"
"348.48200","29.04031","0.04813"
"348.72200","29.06034","0.04888"
"348.96200","29.08031","0.04779"
"349.20200","29.10040","0.04889"
"349.44200","29.12025","0.04848"
"349.68200","29.14034","0.04872"
"349.92200","29.16031","0.04892"
"350.16200","29.18034","0.04838"
"350.40200","29.20031","0.04895"
"350.64200","29.22040","0.04911"
"350.88200","29.24031","0.04933"
"351.12200","29.26028","0.04911"
"351.36200","29.28037","0.04910"
"351.60200","29.30028","0.04915"
"351.84200","29.32037","0.05010"
"352.08200","29.34028","0.04943"
"352.32200","29.36037","0.04910"
"352.56200","29.38028","0.04984"
"352.68400","29.39050","0.04940"