File: Force_trajectories/170122_1/Specimen_RawData_8.csv
End date,"1/22/2017"
Specimen label,"18BG_46 run 2"
Maximum Load,"0.06005",N

Time,Extension,Load
(s),(mm),(N)
"0.00000","29.39702","0.04281"
"0.14400","29.40396","0.04350"
"0.28800","29.41980","0.04343"
"0.43200","29.43325","0.04415"
"0.57600","29.44533","0.04481"
"0.72000","29.45723","0.04508"
"0.86400","29.46919","0.04520"
"1.00800","29.48120","0.04558"
"1.15200","29.49328","0.04622"
"1.29600","29.50518","0.04642"
"1.44000","29.51714","0.04682"
"1.58400","29.52921","0.04649"
"1.72800","29.54123","0.04768"
"1.87200","29.55319","0.04748"
"2.01600","29.56515","0.04769"
"2.16000","29.57717","0.04756"
"2.30400","29.58924","0.04702"
"2.44800","29.60120","0.04749"
"2.59200","29.61316","0.04760"
"2.73600","29.62524","0.04758"
"2.88000","29.63725","0.04777"
"3.02400","29.64915","0.04829"
"3.16800","29.66123","0.04842"
"3.31200","29.67325","0.04800"
"3.45600","29.68521","0.04804"
"3.60000","29.69716","0.04865"
"3.74400","29.70918","0.04858"
"3.88800","29.72120","0.04846"
"4.03200","29.73322","0.04850"
"4.17600","29.74517","0.04853"
"4.32000","29.75719","0.04843"
"4.46400","29.76921","0.04899"
"4.60800","29.78117","0.04875"
"4.75200","29.79313","0.04897"
"4.89600","29.80520","0.04944"
"5.04000","29.81716","0.04929"
"5.18400","29.82918","0.04885"
"5.32800","29.84120","0.04959"
"5.47200","29.85321","0.04957"
"5.61600","29.86517","0.04967"
"5.76000","29.87719","0.04988"
"5.90400","29.88921","0.05009"
"6.04800","29.90123","0.04988"
"6.19200","29.91318","0.05019"
"6.33600","29.92514","0.04992"
"6.48000","29.93722","0.04984"
"6.62400","29.94917","0.05027"
"6.76800","29.96119","0.05048"
"6.91200","29.97315","0.05057"
"7.05600","29.98523","0.05061"
"7.20000","29.99719","0.05129"
"7.34400","30.00914","0.05081"
"7.48800","30.02116","0.05071"
"7.63200","30.03318","0.05096"
"7.77600","30.04520","0.05130"
"7.92000","30.05715","0.05094"
"8.06400","30.06923","0.05156"
"8.20800","30.08119","0.05152"
"8.35200","30.09321","0.05176"
"8.49600","30.10517","0.05171"
"8.64000","30.11724","0.05205"
"8.78400","30.12920","0.05168"
"8.92800","30.14116","0.05191"
"9.07200","30.15318","0.05121"
"9.21600","30.16520","0.05217"
"9.36000","30.17721","0.05173"
"9.50400","30.18917","0.05200"
"9.64800","30.20119","0.05233"
"9.79200","30.21321","0.05223"
"9.93600","30.22523","0.05258"
"10.08000","30.23718","0.05192"
"10.22400","30.24920","0.05209"
"10.36800","30.26122","0.05201"
"10.51200","30.27324","0.05218"
"10.65600","30.28519","0.05232"
"10.80000","30.29721","0.05262"
"10.94400","30.30923","0.05237"
"11.08800","30.32113","0.05255"
"11.23200","30.33320","0.05258"
"11.37600","30.34522","0.05268"
"11.52000","30.35724","0.05298"
"11.66400","30.36914","0.05329"
"11.80800","30.38121","0.05340"
"11.95200","30.39323","0.05230"
"12.09600","30.40519","0.05339"
"12.24000","30.41715","0.05292"
"12.38400","30.42917","0.05305"
"12.52800","30.44118","0.05322"
"12.67200","30.45314","0.05388"
"12.81600","30.46510","0.05300"
"12.96000","30.47712","0.05316"
"13.10400","30.48914","0.05349"
"13.24800","30.50109","0.05343"
"13.39200","30.51317","0.05385"
"13.53600","30.52519","0.05369"
"13.68000","30.53721","0.05401"
"13.82400","30.54917","0.05387"
"13.96800","30.56118","0.05382"
"14.11200","30.57320","0.05393"
"14.25600","30.58522","0.05365"
"14.40000","30.59718","0.05374"
"14.54400","30.60919","0.05377"
"14.68800","30.62121","0.05380"
"14.83200","30.63317","0.05419"
"14.97600","30.64512","0.05407"
"15.12000","30.65720","0.05433"
"15.26400","30.66916","0.05423"
"15.40800","30.68112","0.05374"
"15.55200","30.69320","0.05406"
"15.69600","30.70521","0.05376"
"15.84000","30.71717","0.05439"
"15.98400","30.72919","0.05396"
"16.12800","30.74115","0.05335"
"16.27200","30.75317","0.05327"
"16.41600","30.76518","0.05331"
"16.56000","30.77714","0.05325"
"16.70400","30.78922","0.05308"
"16.84800","30.80124","0.05347"
"16.99200","30.81313","0.05355"
"17.13600","30.82515","0.05404"
"17.28000","30.83723","0.05394"
"17.42400","30.84919","0.05364"
"17.56800","30.86115","0.05396"
"17.71200","30.87317","0.05364"
"17.85600","30.88518","0.05371"
"18.00000","30.89720","0.05419"
"18.14400","30.90910","0.05388"
"18.28800","30.92118","0.05374"
"18.43200","30.93319","0.05394"
"18.57600","30.94521","0.05395"
"18.72000","30.95711","0.05385"
"18.86400","30.96918","0.05439"
"19.00800","30.98120","0.05388"
"19.15200","30.99316","0.05433"
"19.29600","31.00512","0.05438"
"19.44000","31.01719","0.05413"
"19.58400","31.02921","0.05473"
"19.72800","31.04111","0.05466"
"19.87200","31.05313","0.05475"
"20.01600","31.06521","0.05480"
"20.16000","31.07717","0.05465"
"20.30400","31.08912","0.05436"
"20.44800","31.10120","0.05433"
"20.59200","31.11316","0.05466"
"20.73600","31.12518","0.05515"
"20.88000","31.13713","0.05464"
"21.02400","31.14915","0.05464"
"21.16800","31.16123","0.05443"
"21.31200","31.17313","0.05450"
"21.45600","31.18515","0.05496"
"21.60000","31.19716","0.05515"
"21.74400","31.20918","0.05486"
"21.88800","31.22114","0.05488"
"22.03200","31.23316","0.05512"
"22.17600","31.24517","0.05510"
"22.32000","31.25719","0.05526"
"22.46400","31.26915","0.05518"
"22.60800","31.28117","0.05479"
"22.75200","31.29318","0.05523"
"22.89600","31.30514","0.05543"
"23.04000","31.31710","0.05494"
"23.18400","31.32918","0.05464"
"23.32800","31.34119","0.05548"
"23.47200","31.35315","0.05535"
"23.61600","31.36517","0.05537"
"23.76000","31.37719","0.05540"
"23.90400","31.38921","0.05543"
"24.04800","31.40117","0.05605"
"24.19200","31.41318","0.05564"
"24.33600","31.42520","0.05593"
"24.48000","31.43715","0.05550"
"24.62400","31.44917","0.05565"
"24.76800","31.46119","0.05556"
"24.91200","31.47321","0.05561"
"25.05600","31.48511","0.05571"
"25.20000","31.49712","0.05576"
"25.34400","31.50920","0.05556"
"25.48800","31.52122","0.05553"
"25.63200","31.53312","0.05580"
"25.77600","31.54520","0.05616"
"25.92000","31.55715","0.05577"
"26.06400","31.56917","0.05602"
"26.20800","31.58113","0.05597"
"26.35200","31.59321","0.05621"
"26.49600","31.60517","0.05622"
"26.64000","31.61718","0.05643"
"26.78400","31.62908","0.05607"
"26.92800","31.64122","0.05603"
"27.07200","31.65318","0.05643"
"27.21600","31.66513","0.05614"
"27.36000","31.67709","0.05661"
"27.50400","31.68917","0.05611"
"27.64800","31.70119","0.05620"
"27.79200","31.71315","0.05641"
"27.93600","31.72516","0.05653"
"28.08000","31.73724","0.05635"
"28.22400","31.74920","0.05625"
"28.36800","31.76115","0.05611"
"28.51200","31.77317","0.05642"
"28.65600","31.78519","0.05628"
"28.80000","31.79715","0.05623"
"28.94400","31.80911","0.05653"
"29.08800","31.82118","0.05659"
"29.23200","31.83320","0.05629"
"29.37600","31.84516","0.05620"
"29.52000","31.85712","0.05646"
"29.66400","31.86913","0.05596"
"29.80800","31.88115","0.05224"
"29.95200","31.89311","0.05200"
"30.09600","31.90513","0.05211"
"30.24000","31.91715","0.05257"
"30.38400","31.92911","0.05280"
"30.52800","31.94106","0.05256"
"30.67200","31.95314","0.05294"
"30.81600","31.96516","0.05263"
"30.96000","31.97712","0.05259"
"31.10400","31.98907","0.05292"
"31.24800","32.00115","0.05334"
"31.39200","32.01317","0.05343"
"31.53600","32.02512","0.05336"
"31.68000","32.03714","0.05349"
"31.82400","32.04922","0.05377"
"31.96800","32.06118","0.05320"
"32.11200","32.07320","0.05331"
"32.25600","32.08516","0.05373"
"32.40000","32.09717","0.05305"
"32.54400","32.10913","0.05372"
"32.68800","32.12109","0.05343"
"32.83200","32.13317","0.05351"
"32.97600","32.14518","0.05317"
"33.12000","32.15714","0.05320"
"33.26400","32.16916","0.05353"
"33.40800","32.18118","0.05333"
"33.55200","32.19320","0.05377"
"33.69600","32.20509","0.05324"
"33.84000","32.21717","0.05386"
"33.98400","32.22919","0.05353"
"34.12800","32.24121","0.05343"
"34.27200","32.25311","0.05374"
"34.41600","32.26518","0.05384"
"34.56000","32.27714","0.05335"
"34.70400","32.28910","0.05365"
"34.84800","32.30106","0.05384"
"34.99200","32.31319","0.05413"
"35.13600","32.32521","0.05354"
"35.28000","32.33711","0.05386"
"35.42400","32.34912","0.05358"
"35.56800","32.36120","0.05385"
"35.71200","32.37316","0.05375"
"35.85600","32.38518","0.05420"
"36.00000","32.39714","0.05379"
"36.14400","32.40921","0.05365"
"36.28800","32.42117","0.05408"
"36.43200","32.43313","0.05395"
"36.57600","32.44515","0.05399"
"36.72000","32.45716","0.05350"
"36.86400","32.46918","0.05379"
"37.00800","32.48114","0.05369"
"37.15200","32.49316","0.05368"
"37.29600","32.50518","0.05390"
"37.44000","32.51720","0.05408"
"37.58400","32.52909","0.05338"
"37.72800","32.54117","0.05405"
"37.87200","32.55319","0.05401"
"38.01600","32.56515","0.05454"
"38.16000","32.57711","0.05448"
"38.30400","32.58918","0.05412"
"38.44800","32.60114","0.05451"
"38.59200","32.61310","0.05445"
"38.73600","32.62518","0.05429"
"38.88000","32.63713","0.05487"
"39.02400","32.64915","0.05459"
"39.16800","32.66111","0.05482"
"39.31200","32.67318","0.05454"
"39.45600","32.68520","0.05484"
"39.60000","32.69716","0.05485"
"39.74400","32.70912","0.05502"
"39.88800","32.72120","0.05457"
"40.03200","32.73315","0.05472"
"40.17600","32.74517","0.05474"
"40.32000","32.75713","0.05514"
"40.46400","32.76921","0.05477"
"40.60800","32.78117","0.05499"
"40.75200","32.79313","0.05502"
"40.89600","32.80520","0.05507"
"41.04000","32.81722","0.05521"
"41.18400","32.82918","0.05571"
"41.32800","32.84113","0.05533"
"41.47200","32.85321","0.05520"
"41.61600","32.86517","0.05564"
"41.76000","32.87713","0.05531"
"41.90400","32.88914","0.05533"
"42.04800","32.90117","0.05570"
"42.19200","32.91318","0.05545"
"42.33600","32.92508","0.05571"
"42.48000","32.93722","0.05572"
"42.62400","32.94918","0.05576"
"42.76800","32.96119","0.05558"
"42.91200","32.97309","0.05579"
"43.05600","32.98523","0.05545"
"43.20000","32.99718","0.05534"
"43.34400","33.00914","0.05519"
"43.48800","33.02110","0.05570"
"43.63200","33.03318","0.05584"
"43.77600","33.04520","0.05592"
"43.92000","33.05715","0.05563"
"44.06400","33.06917","0.05566"
"44.20800","33.08125","0.05626"
"44.35200","33.09321","0.05599"
"44.49600","33.10516","0.05602"
"44.64000","33.11718","0.05594"
"44.78400","33.12920","0.05592"
"44.92800","33.14116","0.05620"
"45.07200","33.15312","0.05608"
"45.21600","33.16513","0.05590"
"45.36000","33.17715","0.05598"
"45.50400","33.18917","0.05596"
"45.64800","33.20113","0.05628"
"45.79200","33.21321","0.05661"
"45.93600","33.22522","0.05635"
"46.08000","33.23718","0.05622"
"46.22400","33.24914","0.05608"
"46.36800","33.26122","0.05623"
"46.51200","33.27324","0.05652"
"46.65600","33.28519","0.05643"
"46.80000","33.29721","0.05687"
"46.94400","33.30922","0.05684"
"47.08800","33.32118","0.05713"
"47.23200","33.33314","0.05654"
"47.37600","33.34516","0.05689"
"47.52000","33.35723","0.05670"
"47.66400","33.36914","0.05645"
"47.80800","33.38115","0.05636"
"47.95200","33.39323","0.05686"
"48.09600","33.40519","0.05694"
"48.24000","33.41721","0.05677"
"48.38400","33.42916","0.05696"
"48.52800","33.44118","0.05700"
"48.67200","33.45314","0.05703"
"48.81600","33.46510","0.05731"
"48.96000","33.47718","0.05720"
"49.10400","33.48914","0.05691"
"49.24800","33.50121","0.05716"
"49.39200","33.51317","0.05692"
"49.53600","33.52525","0.05717"
"49.68000","33.53720","0.05742"
"49.82400","33.54916","0.05735"
"49.96800","33.56118","0.05708"
"50.11200","33.57320","0.05725"
"50.25600","33.58522","0.05698"
"50.40000","33.59717","0.05723"
"50.54400","33.60919","0.05691"
"50.68800","33.62121","0.05729"
"50.83200","33.63322","0.05720"
"50.97600","33.64512","0.05675"
"51.12000","33.65720","0.05710"
"51.26400","33.66916","0.05704"
"51.40800","33.68118","0.05722"
"51.55200","33.69313","0.05747"
"51.69600","33.70521","0.05699"
"51.84000","33.71717","0.05764"
"51.98400","33.72919","0.05750"
"52.12800","33.74115","0.05690"
"52.27200","33.75316","0.05703"
"52.41600","33.76518","0.05728"
"52.56000","33.77714","0.05731"
"52.70400","33.78916","0.05717"
"52.84800","33.80124","0.05732"
"52.99200","33.81319","0.05765"
"53.13600","33.82509","0.05787"
"53.28000","33.83723","0.05779"
"53.42400","33.84919","0.05759"
"53.56800","33.86121","0.05781"
"53.71200","33.87316","0.05766"
"53.85600","33.88524","0.05773"
"54.00000","33.89720","0.05801"
"54.14400","33.90915","0.05768"
"54.28800","33.92117","0.05823"
"54.43200","33.93319","0.05799"
"54.57600","33.94521","0.05826"
"54.72000","33.95710","0.05819"
"54.86400","33.96918","0.05814"
"55.00800","33.98126","0.05835"
"55.15200","33.99316","0.05820"
"55.29600","34.00518","0.05836"
"55.44000","34.01714","0.05848"
"55.58400","34.02921","0.05840"
"55.72800","34.04117","0.05850"
"55.87200","34.05319","0.05845"
"56.01600","34.06520","0.05864"
"56.16000","34.07716","0.05844"
"56.30400","34.08912","0.05873"
"56.44800","34.10114","0.05860"
"56.59200","34.11316","0.05887"
"56.73600","34.12518","0.05855"
"56.88000","34.13713","0.05852"
"57.02400","34.14915","0.05859"
"57.16800","34.16117","0.05885"
"57.31200","34.17319","0.05854"
"57.45600","34.18515","0.05871"
"57.60000","34.19716","0.05891"
"57.74400","34.20918","0.05894"
"57.88800","34.22120","0.05897"
"58.03200","34.23315","0.05838"
"58.17600","34.24523","0.05860"
"58.32000","34.25719","0.05871"
"58.46400","34.26915","0.05849"
"58.60800","34.28117","0.05811"
"58.75200","34.29318","0.05815"
"58.89600","34.30520","0.05839"
"59.04000","34.31716","0.05845"
"59.18400","34.32918","0.05875"
"59.32800","34.34119","0.05862"
"59.47200","34.35321","0.05875"
"59.61600","34.36511","0.05875"
"59.76000","34.37719","0.05876"
"59.90400","34.38921","0.05895"
"60.04800","34.40117","0.05851"
"60.19200","34.41318","0.05898"
"60.33600","34.42520","0.05903"
"60.48000","34.43716","0.05894"
"60.62400","34.44912","0.05931"
"60.76800","34.46113","0.05920"
"60.91200","34.47321","0.05919"
"61.05600","34.48523","0.05937"
"61.20000","34.49713","0.05941"
"61.34400","34.50914","0.05918"
"61.48800","34.52116","0.05851"
"61.63200","34.53318","0.05850"
"61.77600","34.54514","0.05847"
"61.92000","34.55721","0.05803"
"62.06400","34.56917","0.05805"
"62.20800","34.58119","0.05822"
"62.35200","34.59315","0.05835"
"62.49600","34.60516","0.05823"
"62.64000","34.61718","0.05816"
"62.78400","34.62908","0.05838"
"62.92800","34.64116","0.05846"
"63.07200","34.65318","0.05852"
"63.21600","34.66513","0.05814"
"63.36000","34.67715","0.05849"
"63.50400","34.68917","0.05820"
"63.64800","34.70119","0.05815"
"63.79200","34.71315","0.05818"
"63.93600","34.72511","0.05828"
"64.08000","34.73718","0.05849"
"64.22400","34.74920","0.05829"
"64.36800","34.76116","0.05880"
"64.51200","34.77317","0.05847"
"64.65600","34.78513","0.05890"
"64.80000","34.79721","0.05893"
"64.94400","34.80911","0.05935"
"65.08800","34.82113","0.05891"
"65.23200","34.83320","0.05942"
"65.37600","34.84522","0.05930"
"65.52000","34.85718","0.05939"
"65.66400","34.86919","0.05932"
"65.80800","34.88121","0.05982"
"65.95200","34.89317","0.05952"
"66.09600","34.90513","0.05963"
"66.24000","34.91714","0.05933"
"66.38400","34.92916","0.05927"
"66.52800","34.94112","0.05909"
"66.67200","34.95314","0.05976"
"66.81600","34.96516","0.05970"
"66.96000","34.97718","0.05941"
"67.10400","34.98913","0.05970"
"67.24800","35.00115","0.05953"
"67.39200","35.01317","0.05928"
"67.53600","35.02513","0.05976"
"67.68000","35.03714","0.05959"
"67.82400","35.04922","0.05962"
"67.96800","35.06118","0.05945"
"68.11200","35.07320","0.05940"
"68.25600","35.08516","0.05946"
"68.40000","35.09718","0.05941"
"68.54400","35.10919","0.05906"
"68.68800","35.12109","0.05966"
"68.83200","35.13317","0.05957"
"68.97600","35.14519","0.05961"
"69.12000","35.15720","0.05936"
"69.26400","35.16910","0.05940"
"69.40800","35.18118","0.05987"
"69.55200","35.19320","0.05976"
"69.69600","35.20521","0.05939"
"69.84000","35.21711","0.05984"
"69.98400","35.22919","0.05060"
"70.12800","35.24121","0.04417"
"70.27200","35.25316","0.04614"
"70.41600","35.26512","0.04386"
"70.56000","35.27720","0.04291"
"70.70400","35.28916","0.04599"
"70.84800","35.30117","0.04314"
"70.99200","35.31313","0.04135"
"71.13600","35.32515","0.04157"
"71.28000","35.33717","0.04256"
"71.42400","35.34907","0.04295"
"71.56800","35.36115","0.04260"
"71.71200","35.37316","0.04172"
"71.85600","35.38518","0.04299"
"72.00000","35.39714","0.04357"
"72.14400","35.40916","0.04328"
"72.28800","35.42117","0.04336"
"72.43200","35.43319","0.04327"
"72.57600","35.44515","0.04362"
"72.72000","35.45717","0.04295"
"72.86400","35.46918","0.04396"
"73.00800","35.48114","0.04393"
"73.15200","35.49316","0.04403"
"73.29600","35.50518","0.04342"
"73.44000","35.51714","0.04434"
"73.58400","35.52909","0.04437"
"73.72800","35.54117","0.04504"
"73.87200","35.55319","0.04470"
"74.01600","35.56514","0.04439"
"74.16000","35.57710","0.04388"
"74.30400","35.58918","0.04452"
"74.44800","35.60120","0.04454"
"74.59200","35.61316","0.04457"
"74.73600","35.62511","0.04427"
"74.88000","35.63719","0.04457"
"75.02400","35.64915","0.04407"
"75.16800","35.66117","0.04395"
"75.31200","35.67313","0.04417"
"75.45600","35.68514","0.04404"
"75.60000","35.69710","0.04396"
"75.74400","35.70912","0.04341"
"75.88800","35.72114","0.04405"
"76.03200","35.73315","0.04362"
"76.17600","35.74511","0.04345"
"76.32000","35.75713","0.04463"
"76.46400","35.76915","0.04435"
"76.60800","35.78116","0.04435"
"76.75200","35.79312","0.04378"
"76.89600","35.80520","0.04413"
"77.04000","35.81716","0.04459"
"77.18400","35.82917","0.04438"
"77.32800","35.84113","0.04233"
"77.47200","35.85321","0.04198"
"77.61600","35.86517","0.04313"
"77.76000","35.87713","0.04284"
"77.90400","35.88908","0.04283"
"78.04800","35.90116","0.04336"
"78.19200","35.91318","0.04383"
"78.33600","35.92514","0.04380"
"78.48000","35.93710","0.04388"
"78.62400","35.94917","0.04441"
"78.76800","35.96113","0.04414"
"78.91200","35.97309","0.04448"
"79.05600","35.98511","0.04449"
"79.20000","35.99718","0.04527"
"79.34400","36.00914","0.04513"
"79.48800","36.02110","0.04529"
"79.63200","36.03312","0.04602"
"79.77600","36.04520","0.04668"
"79.92000","36.05716","0.04617"
"80.06400","36.06911","0.04579"
"80.20800","36.08113","0.04667"
"80.35200","36.09321","0.04633"
"80.49600","36.10516","0.04673"
"80.64000","36.11712","0.04646"
"80.78400","36.12920","0.04675"
"80.92800","36.14116","0.04757"
"81.07200","36.15311","0.04721"
"81.21600","36.16519","0.04779"
"81.36000","36.17715","0.04800"
"81.50400","36.18917","0.04851"
"81.64800","36.20113","0.04788"
"81.79200","36.21315","0.04814"
"81.93600","36.22522","0.04847"
"82.08000","36.23718","0.04853"
"82.22400","36.24914","0.04865"
"82.36800","36.26122","0.04924"
"82.51200","36.27317","0.04936"
"82.65600","36.28519","0.04942"
"82.80000","36.29715","0.04936"
"82.94400","36.30923","0.04988"
"83.08800","36.32119","0.05012"
"83.23200","36.33315","0.04981"
"83.37600","36.34516","0.04968"
"83.52000","36.35718","0.05022"
"83.66400","36.36920","0.05065"
"83.80800","36.38116","0.05062"
"83.95200","36.39317","0.05047"
"84.09600","36.40519","0.05063"
"84.24000","36.41714","0.05085"
"84.38400","36.42916","0.05096"
"84.52800","36.44118","0.05107"
"84.67200","36.45320","0.05150"
"84.81600","36.46516","0.05121"
"84.96000","36.47717","0.05177"
"85.10400","36.48919","0.05185"
"85.24800","36.50121","0.05224"
"85.39200","36.51311","0.05233"
"85.53600","36.52518","0.05202"
"85.68000","36.53720","0.05239"
"85.82400","36.54922","0.05252"
"85.96800","36.56112","0.05258"
"86.11200","36.57320","0.05278"
"86.25600","36.58516","0.05340"
"86.40000","36.59711","0.05342"
"86.54400","36.60913","0.05353"
"86.68800","36.62121","0.05322"
"86.83200","36.63317","0.05334"
"86.97600","36.64518","0.05380"
"87.12000","36.65720","0.05313"
"87.26400","36.66922","0.05367"
"87.40800","36.68118","0.05353"
"87.55200","36.69314","0.05390"
"87.69600","36.70522","0.05409"
"87.84000","36.71723","0.05399"
"87.98400","36.72919","0.05412"
"88.12800","36.74115","0.05422"
"88.27200","36.75316","0.05391"
"88.41600","36.76518","0.05451"
"88.56000","36.77714","0.05464"
"88.70400","36.78916","0.05468"
"88.84800","36.80117","0.05441"
"88.99200","36.81319","0.05476"
"89.13600","36.82515","0.05482"
"89.28000","36.83717","0.05454"
"89.42400","36.84919","0.05505"
"89.56800","36.86120","0.05478"
"89.71200","36.87316","0.05493"
"89.85600","36.88518","0.05540"
"90.00000","36.89726","0.05512"
"90.14400","36.90921","0.05492"
"90.28800","36.92117","0.05536"
"90.43200","36.93319","0.05582"
"90.57600","36.94521","0.05522"
"90.72000","36.95717","0.05561"
"90.86400","36.96918","0.05562"
"91.00800","36.98126","0.05553"
"91.15200","36.99322","0.05577"
"91.29600","37.00512","0.05565"
"91.44000","37.01713","0.05545"
"91.58400","37.02921","0.05611"
"91.72800","37.04117","0.05570"
"91.87200","37.05319","0.05520"
"92.01600","37.06520","0.05520"
"92.16000","37.07716","0.05513"
"92.30400","37.08918","0.05560"
"92.44800","37.10114","0.05477"
"92.59200","37.11322","0.05326"
"92.73600","37.12518","0.05307"
"92.88000","37.13719","0.05317"
"93.02400","37.14915","0.05318"
"93.16800","37.16123","0.05270"
"93.31200","37.17319","0.05327"
"93.45600","37.18514","0.05300"
"93.60000","37.19716","0.05343"
"93.74400","37.20918","0.05305"
"93.88800","37.22120","0.05349"
"94.03200","37.23315","0.05355"
"94.17600","37.24517","0.05336"
"94.32000","37.25719","0.05370"
"94.46400","37.26921","0.05341"
"94.60800","37.28117","0.05364"
"94.75200","37.29324","0.05371"
"94.89600","37.30520","0.05350"
"95.04000","37.31716","0.05401"
"95.18400","37.32918","0.05415"
"95.32800","37.34126","0.05396"
"95.47200","37.35321","0.05344"
"95.61600","37.36517","0.05399"
"95.76000","37.37719","0.05375"
"95.90400","37.38926","0.05400"
"96.04800","37.40116","0.05406"
"96.19200","37.41312","0.05419"
"96.33600","37.42520","0.05432"
"96.48000","37.43721","0.05412"
"96.62400","37.44917","0.05388"
"96.76800","37.46113","0.05435"
"96.91200","37.47321","0.05461"
"97.05600","37.48523","0.05330"
"97.20000","37.49712","0.05175"
"97.34400","37.50914","0.05289"
"97.48800","37.52116","0.05253"
"97.63200","37.53318","0.05215"
"97.77600","37.54514","0.05239"
"97.92000","37.55716","0.05302"
"98.06400","37.56917","0.05297"
"98.20800","37.58119","0.05287"
"98.35200","37.59315","0.05314"
"98.49600","37.60517","0.05281"
"98.64000","37.61724","0.05291"
"98.78400","37.62914","0.05273"
"98.92800","37.64116","0.05356"
"99.07200","37.65318","0.05381"
"99.21600","37.66519","0.05306"
"99.36000","37.67715","0.05357"
"99.50400","37.68917","0.05382"
"99.64800","37.70119","0.05358"
"99.79200","37.71320","0.05231"
"99.93600","37.72510","0.05232"
"100.08000","37.73718","0.05218"
"100.22400","37.74914","0.05149"
"100.36800","37.76115","0.05229"
"100.51200","37.77317","0.05166"
"100.65600","37.78519","0.05247"
"100.80000","37.79721","0.05189"
"100.94400","37.80917","0.05213"
"101.08800","37.82113","0.05207"
"101.23200","37.83320","0.05189"
"101.37600","37.84516","0.05200"
"101.52000","37.85712","0.05260"
"101.66400","37.86914","0.05222"
"101.80800","37.88115","0.05206"
"101.95200","37.89317","0.05247"
"102.09600","37.90513","0.05235"
"102.24000","37.91715","0.05251"
"102.38400","37.92916","0.05262"
"102.52800","37.94118","0.05165"
"102.67200","37.95314","0.05229"
"102.81600","37.96522","0.05225"
"102.96000","37.97717","0.05283"
"103.10400","37.98919","0.05244"
"103.24800","38.00115","0.05246"
"103.39200","38.01317","0.05240"
"103.53600","38.02518","0.05223"
"103.68000","38.03714","0.05230"
"103.82400","38.04916","0.05260"
"103.96800","38.06118","0.05291"
"104.11200","38.07320","0.05280"
"104.25600","38.08509","0.05240"
"104.40000","38.09717","0.05288"
"104.54400","38.10919","0.05229"
"104.68800","38.12115","0.05282"
"104.83200","38.13311","0.05308"
"104.97600","38.14518","0.05270"
"105.12000","38.15720","0.05270"
"105.26400","38.16916","0.05288"
"105.40800","38.18112","0.05348"
"105.55200","38.19320","0.05261"
"105.69600","38.20515","0.05267"
"105.84000","38.21711","0.05249"
"105.98400","38.22913","0.05263"
"106.12800","38.24121","0.05318"
"106.27200","38.25317","0.05292"
"106.41600","38.26512","0.05295"
"106.56000","38.27714","0.05339"
"106.70400","38.28922","0.05312"
"106.84800","38.30117","0.05299"
"106.99200","38.31313","0.05282"
"107.13600","38.32515","0.05351"
"107.28000","38.33717","0.05305"
"107.42400","38.34912","0.05318"
"107.56800","38.36115","0.05347"
"107.71200","38.37316","0.05299"
"107.85600","38.38518","0.05371"
"108.00000","38.39714","0.05317"
"108.14400","38.40921","0.05303"
"108.28800","38.42117","0.05365"
"108.43200","38.43313","0.05369"
"108.57600","38.44509","0.05421"
"108.72000","38.45716","0.05363"
"108.86400","38.46918","0.05386"
"109.00800","38.48114","0.05352"
"109.15200","38.49316","0.05436"
"109.29600","38.50518","0.05452"
"109.44000","38.51720","0.05402"
"109.58400","38.52916","0.05418"
"109.72800","38.54117","0.05444"
"109.87200","38.55319","0.05401"
"110.01600","38.56515","0.05389"
"110.16000","38.57710","0.05398"
"110.30400","38.58918","0.05414"
"110.44800","38.60114","0.05430"
"110.59200","38.61316","0.05414"
"110.73600","38.62511","0.05453"
"110.88000","38.63719","0.05456"
"111.02400","38.64921","0.05478"
"111.16800","38.66111","0.05477"
"111.31200","38.67313","0.05423"
"111.45600","38.68520","0.05476"
"111.60000","38.69716","0.05481"
"111.74400","38.70912","0.05454"
"111.88800","38.72120","0.05494"
"112.03200","38.73315","0.05450"
"112.17600","38.74511","0.05471"
"112.32000","38.75707","0.05479"
"112.46400","38.76921","0.05473"
"112.60800","38.78117","0.05495"
"112.75200","38.79318","0.05535"
"112.89600","38.80514","0.05455"
"113.04000","38.81722","0.05491"
"113.18400","38.82924","0.05468"
"113.32800","38.84119","0.05497"
"113.47200","38.85315","0.05526"
"113.61600","38.86523","0.05487"
"113.76000","38.87719","0.05505"
"113.90400","38.88915","0.05478"
"114.04800","38.90116","0.05503"
"114.19200","38.91318","0.05497"
"114.33600","38.92508","0.05517"
"114.48000","38.93710","0.05498"
"114.62400","38.94911","0.05564"
"114.76800","38.96119","0.05514"
"114.91200","38.97309","0.05534"
"115.05600","38.98511","0.05524"
"115.20000","38.99718","0.05550"
"115.34400","39.00920","0.05554"
"115.48800","39.02110","0.05538"
"115.63200","39.03312","0.05557"
"115.77600","39.04514","0.05587"
"115.92000","39.05716","0.05563"
"116.06400","39.06911","0.05531"
"116.20800","39.08113","0.05559"
"116.35200","39.09314","0.05575"
"116.49600","39.10516","0.05565"
"116.64000","39.11706","0.05566"
"116.78400","39.12914","0.05593"
"116.92800","39.14116","0.05616"
"117.07200","39.15312","0.05602"
"117.21600","39.16513","0.05583"
"117.36000","39.17715","0.05595"
"117.50400","39.18917","0.05621"
"117.64800","39.20119","0.05569"
"117.79200","39.21314","0.05608"
"117.93600","39.22516","0.05609"
"118.08000","39.23712","0.05595"
"118.22400","39.24914","0.05599"
"118.36800","39.26115","0.05599"
"118.51200","39.27317","0.05593"
"118.65600","39.28513","0.05604"
"118.80000","39.29715","0.05622"
"118.94400","39.30917","0.05640"
"119.08800","39.32118","0.05611"
"119.23200","39.33314","0.05585"
"119.37600","39.34516","0.05589"
"119.52000","39.35717","0.05628"
"119.66400","39.36919","0.05639"
"119.80800","39.38109","0.05629"
"119.95200","39.39317","0.05652"
"120.09600","39.40519","0.05652"
"120.24000","39.41715","0.05628"
"120.38400","39.42911","0.05643"
"120.52800","39.44118","0.05602"
"120.67200","39.45320","0.05662"
"120.81600","39.46516","0.05658"
"120.96000","39.47712","0.05659"
"121.10400","39.48919","0.05643"
"121.24800","39.50121","0.05679"
"121.39200","39.51317","0.05650"
"121.53600","39.52512","0.05697"
"121.68000","39.53720","0.05673"
"121.82400","39.54916","0.05678"
"121.96800","39.56118","0.05681"
"122.11200","39.57313","0.05677"
"122.25600","39.58521","0.05656"
"122.40000","39.59717","0.05689"
"122.54400","39.60913","0.05672"
"122.68800","39.62115","0.05698"
"122.83200","39.63316","0.05691"
"122.97600","39.64512","0.05680"
"123.12000","39.65714","0.05664"
"123.26400","39.66922","0.05674"
"123.40800","39.68124","0.05701"
"123.55200","39.69313","0.05676"
"123.69600","39.70515","0.05629"
"123.84000","39.71723","0.05700"
"123.98400","39.72919","0.05640"
"124.12800","39.74114","0.05674"
"124.27200","39.75317","0.05670"
"124.41600","39.76518","0.05648"
"124.56000","39.77720","0.05683"
"124.70400","39.78910","0.05689"
"124.84800","39.80117","0.05633"
"124.99200","39.81319","0.05679"
"125.13600","39.82515","0.05647"
"125.28000","39.83710","0.05671"
"125.42400","39.84919","0.05665"
"125.56800","39.86120","0.05691"
"125.71200","39.87322","0.05677"
"125.85600","39.88518","0.05662"
"126.00000","39.89719","0.05683"
"126.14400","39.90915","0.05673"
"126.28800","39.92117","0.05716"
"126.43200","39.93313","0.05688"
"126.57600","39.94515","0.05667"
"126.72000","39.95716","0.05706"
"126.86400","39.96912","0.05682"
"127.00800","39.98120","0.05736"
"127.15200","39.99316","0.05727"
"127.29600","40.00512","0.05683"
"127.44000","40.01714","0.05679"
"127.58400","40.02915","0.05690"
"127.72800","40.04117","0.05713"
"127.87200","40.05319","0.05703"
"128.01600","40.06520","0.05727"
"128.16000","40.07722","0.05731"
"128.30400","40.08918","0.05761"
"128.44800","40.10114","0.05740"
"128.59200","40.11316","0.05694"
"128.73600","40.12518","0.05730"
"128.88000","40.13720","0.05747"
"129.02400","40.14909","0.05727"
"129.16800","40.16122","0.05727"
"129.31200","40.17318","0.05739"
"129.45600","40.18514","0.05676"
"129.60000","40.19715","0.04586"
"129.74400","40.20924","0.04437"
"129.88800","40.22120","0.04160"
"130.03200","40.23315","0.04250"
"130.17600","40.24517","0.04185"
"130.32000","40.25719","0.04033"
"130.46400","40.26920","0.04019"
"130.60800","40.28116","0.04172"
"130.75200","40.29318","0.04132"
"130.89600","40.30520","0.04071"
"131.04000","40.31722","0.04117"
"131.18400","40.32918","0.04201"
"131.32800","40.34119","0.04109"
"131.47200","40.35321","0.03968"
"131.61600","40.36517","0.04047"
"131.76000","40.37719","0.04197"
"131.90400","40.38921","0.04243"
"132.04800","40.40122","0.04098"
"132.19200","40.41318","0.03968"
"132.33600","40.42520","0.04116"
"132.48000","40.43721","0.04259"
"132.62400","40.44917","0.03997"
"132.76800","40.46113","0.03944"
"132.91200","40.47315","0.03920"
"133.05600","40.48523","0.03948"
"133.20000","40.49718","0.04056"
"133.34400","40.50920","0.04016"
"133.48800","40.52116","0.04077"
"133.63200","40.53324","0.03904"
"133.77600","40.54513","0.04003"
"133.92000","40.55709","0.03956"
"134.06400","40.56917","0.04094"
"134.20800","40.58119","0.04039"
"134.35200","40.59315","0.03966"
"134.49600","40.60516","0.04029"
"134.64000","40.61718","0.04073"
"134.78400","40.62920","0.04107"
"134.92800","40.64116","0.04090"
"135.07200","40.65324","0.04109"
"135.21600","40.66520","0.04060"
"135.36000","40.67721","0.04049"
"135.50400","40.68917","0.04084"
"135.64800","40.70118","0.04113"
"135.79200","40.71314","0.04096"
"135.93600","40.72516","0.04103"
"136.08000","40.73712","0.04069"
"136.22400","40.74920","0.04083"
"136.36800","40.76116","0.04085"
"136.51200","40.77311","0.04116"
"136.65600","40.78513","0.04068"
"136.80000","40.79715","0.04136"
"136.94400","40.80922","0.04116"
"137.08800","40.82118","0.04142"
"137.23200","40.83320","0.04153"
"137.37600","40.84522","0.04164"
"137.52000","40.85718","0.04150"
"137.66400","40.86914","0.04189"
"137.80800","40.88121","0.04165"
"137.95200","40.89317","0.04178"
"138.09600","40.90512","0.04185"
"138.24000","40.91714","0.04199"
"138.38400","40.92923","0.04211"
"138.52800","40.94118","0.04191"
"138.67200","40.95314","0.04221"
"138.81600","40.96516","0.04248"
"138.96000","40.97723","0.04257"
"139.10400","40.98919","0.04274"
"139.24800","41.00109","0.04259"
"139.39200","41.01323","0.04273"
"139.53600","41.02519","0.04261"
"139.68000","41.03720","0.04295"
"139.82400","41.04916","0.04323"
"139.96800","41.06124","0.04297"
"140.11200","41.07320","0.04343"
"140.25600","41.08515","0.04317"
"140.40000","41.09711","0.04332"
"140.54400","41.10919","0.04372"
"140.68800","41.12121","0.04352"
"140.83200","41.13311","0.04320"
"140.97600","41.14518","0.04373"
"141.12000","41.15720","0.04360"
"141.26400","41.16916","0.04401"
"141.40800","41.18111","0.04373"
"141.55200","41.19313","0.04366"
"141.69600","41.20521","0.04402"
"141.84000","41.21717","0.04463"
"141.98400","41.22919","0.04432"
"142.12800","41.24120","0.04424"
"142.27200","41.25316","0.04487"
"142.41600","41.26512","0.04435"
"142.56000","41.27714","0.04487"
"142.70400","41.28916","0.04503"
"142.84800","41.30117","0.04554"
"142.99200","41.31313","0.04537"
"143.13600","41.32521","0.04544"
"143.28000","41.33717","0.04530"
"143.42400","41.34919","0.04590"
"143.56800","41.36115","0.04556"
"143.71200","41.37317","0.04571"
"143.85600","41.38518","0.04573"
"144.00000","41.39714","0.04637"
"144.14400","41.40910","0.04597"
"144.28800","41.42117","0.04557"
"144.43200","41.43319","0.04630"
"144.57600","41.44514","0.04689"
"144.72000","41.45716","0.04617"
"144.86400","41.46912","0.04577"
"145.00800","41.48114","0.04672"
"145.15200","41.49316","0.04683"
"145.29600","41.50518","0.04614"
"145.44000","41.51719","0.04692"
"145.58400","41.52921","0.04684"
"145.72800","41.54117","0.04674"
"145.87200","41.55325","0.04698"
"146.01600","41.56520","0.04729"
"146.16000","41.57716","0.04657"
"146.30400","41.58918","0.04801"
"146.44800","41.60120","0.04742"
"146.59200","41.61316","0.04726"
"146.73600","41.62511","0.04745"
"146.88000","41.63719","0.04757"
"147.02400","41.64915","0.04739"
"147.16800","41.66117","0.04797"
"147.31200","41.67313","0.04771"
"147.45600","41.68520","0.04767"
"147.60000","41.69716","0.04801"
"147.74400","41.70912","0.04795"
"147.88800","41.72108","0.04807"
"148.03200","41.73321","0.04797"
"148.17600","41.74517","0.04765"
"148.32000","41.75713","0.04814"
"148.46400","41.76909","0.04889"
"148.60800","41.78117","0.04883"
"148.75200","41.79318","0.04863"
"148.89600","41.80508","0.04872"
"149.04000","41.81716","0.04915"
"149.18400","41.82918","0.04940"
"149.32800","41.84119","0.04962"
"149.47200","41.85315","0.04920"
"149.61600","41.86517","0.04975"
"149.76000","41.87725","0.04947"
"149.90400","41.88921","0.04937"
"150.04800","41.90117","0.04949"
"150.19200","41.91318","0.04971"
"150.33600","41.92520","0.04992"
"150.48000","41.93710","0.05009"
"150.62400","41.94918","0.04977"
"150.76800","41.96113","0.04950"
"150.91200","41.97315","0.05037"
"151.05600","41.98511","0.05037"
"151.20000","41.99719","0.05030"
"151.34400","42.00920","0.05052"
"151.48800","42.02116","0.05033"
"151.63200","42.03312","0.05017"
"151.77600","42.04520","0.05034"
"151.92000","42.05715","0.04924"
"152.06400","42.06911","0.04970"
"152.20800","42.08107","0.04941"
"152.35200","42.09314","0.04913"
"152.49600","42.10516","0.04959"
"152.64000","42.11712","0.05027"
"152.78400","42.12914","0.04997"
"152.92800","42.14116","0.04976"
"153.07200","42.15312","0.04955"
"153.21600","42.16507","0.04954"
"153.36000","42.17721","0.05026"
"153.50400","42.18917","0.05024"
"153.64800","42.20113","0.05020"
"153.79200","42.21315","0.05062"
"153.93600","42.22522","0.05076"
"154.08000","42.23718","0.05052"
"154.22400","42.24913","0.05116"
"154.36800","42.26115","0.05091"
"154.51200","42.27317","0.05066"
"154.65600","42.28519","0.05105"
"154.80000","42.29715","0.05105"
"154.94400","42.30922","0.05098"
"155.08800","42.32118","0.05072"
"155.23200","42.33314","0.05059"
"155.37600","42.34510","0.05119"
"155.52000","42.35718","0.05058"
"155.66400","42.36913","0.05154"
"155.80800","42.38115","0.05112"
"155.95200","42.39311","0.05115"
"156.09600","42.40519","0.05142"
"156.24000","42.41714","0.05117"
"156.38400","42.42910","0.05108"
"156.52800","42.44112","0.05186"
"156.67200","42.45320","0.05173"
"156.81600","42.46522","0.05162"
"156.96000","42.47718","0.05173"
"157.10400","42.48919","0.05159"
"157.24800","42.50121","0.05183"
"157.39200","42.51316","0.05174"
"157.53600","42.52512","0.05176"
"157.68000","42.53714","0.05116"
"157.82400","42.54916","0.05168"
"157.96800","42.56112","0.05111"
"158.11200","42.57308","0.02860"
"158.25600","42.58516","0.03412"
"158.40000","42.59717","0.03429"
"158.54400","42.60913","0.03409"
"158.68800","42.62115","0.03270"
"158.83200","42.63310","0.03108"
"158.97600","42.64519","0.03129"
"159.12000","42.65714","0.03096"
"159.26400","42.66916","0.03247"
"159.40800","42.68112","0.03322"
"159.55200","42.69313","0.03320"
"159.69600","42.70509","0.03212"
"159.84000","42.71717","0.03093"
"159.98400","42.72913","0.03125"
"160.12800","42.74115","0.03102"
"160.27200","42.75311","0.03280"
"160.41600","42.76518","0.03337"
"160.56000","42.77719","0.03241"
"160.70400","42.78915","0.03234"
"160.84800","42.80117","0.03138"
"160.99200","42.81319","0.03141"
"161.13600","42.82515","0.03182"
"161.28000","42.83711","0.03287"
"161.42400","42.84919","0.03332"
"161.56800","42.86115","0.03271"
"161.71200","42.87316","0.03281"
"161.85600","42.88512","0.03225"
"162.00000","42.89720","0.03253"
"162.14400","42.90922","0.03259"
"162.28800","42.92117","0.03307"
"162.43200","42.93319","0.03223"
"162.57600","42.94521","0.03166"
"162.72000","42.95723","0.03186"
"162.86400","42.96912","0.03184"
"163.00800","42.98120","0.03187"
"163.15200","42.99316","0.03205"
"163.29600","43.00518","0.03228"
"163.44000","43.01714","0.03192"
"163.58400","43.02921","0.03192"
"163.72800","43.04117","0.03159"
"163.87200","43.05313","0.03203"
"164.01600","43.06514","0.03186"
"164.16000","43.07722","0.03202"
"164.30400","43.08918","0.03236"
"164.44800","43.10114","0.03247"
"164.59200","43.11316","0.03252"
"164.73600","43.12523","0.03252"
"164.88000","43.13719","0.03274"
"165.02400","43.14915","0.03256"
"165.16800","43.16117","0.03293"
"165.31200","43.17319","0.03241"
"165.45600","43.18515","0.03277"
"165.60000","43.19716","0.03196"
"165.74400","43.20918","0.03271"
"165.88800","43.22114","0.03241"
"166.03200","43.23315","0.03280"
"166.17600","43.24511","0.03217"
"166.32000","43.25719","0.03280"
"166.46400","43.26921","0.03286"
"166.60800","43.28116","0.03225"
"166.75200","43.29318","0.03231"
"166.89600","43.30520","0.03271"
"167.04000","43.31721","0.03268"
"167.18400","43.32917","0.03267"
"167.32800","43.34119","0.03274"
"167.47200","43.35321","0.03337"
"167.61600","43.36523","0.03265"
"167.76000","43.37713","0.03237"
"167.90400","43.38921","0.03272"
"168.04800","43.40122","0.03285"
"168.19200","43.41318","0.03299"
"168.33600","43.42514","0.03303"
"168.48000","43.43722","0.03313"
"168.62400","43.44917","0.03286"
"168.76800","43.46119","0.03285"
"168.91200","43.47321","0.03368"
"169.05600","43.48523","0.03271"
"169.20000","43.49718","0.03311"
"169.34400","43.50920","0.03286"
"169.48800","43.52122","0.03240"
"169.63200","43.53324","0.03269"
"169.77600","43.54520","0.03259"
"169.92000","43.55716","0.03351"
"170.06400","43.56917","0.03304"
"170.20800","43.58119","0.03271"
"170.35200","43.59315","0.03291"
"170.49600","43.60516","0.03269"
"170.64000","43.61718","0.03264"
"170.78400","43.62920","0.03274"
"170.92800","43.64116","0.03306"
"171.07200","43.65318","0.03280"
"171.21600","43.66519","0.03308"
"171.36000","43.67721","0.03258"
"171.50400","43.68911","0.03310"
"171.64800","43.70125","0.03313"
"171.79200","43.71320","0.03316"
"171.93600","43.72522","0.03305"
"172.08000","43.73718","0.03293"
"172.22400","43.74925","0.03287"
"172.36800","43.76121","0.03269"
"172.51200","43.77317","0.03271"
"172.65600","43.78513","0.03275"
"172.80000","43.79721","0.03295"
"172.94400","43.80923","0.03294"
"173.08800","43.82119","0.03290"
"173.23200","43.83320","0.03287"
"173.37600","43.84522","0.03283"
"173.52000","43.85718","0.03291"
"173.66400","43.86913","0.03296"
"173.80800","43.88116","0.03329"
"173.95200","43.89317","0.03309"
"174.09600","43.90512","0.03333"
"174.24000","43.91714","0.03362"
"174.38400","43.92916","0.03291"
"174.52800","43.94118","0.03350"
"174.67200","43.95314","0.03177"
"174.81600","43.96515","0.03177"
"174.96000","43.97717","0.03201"
"175.10400","43.98925","0.03160"
"175.24800","44.00115","0.03176"
"175.39200","44.01317","0.03139"
"175.53600","44.02524","0.03230"
"175.68000","44.03720","0.03180"
"175.82400","44.04916","0.03190"
"175.96800","44.06118","0.03232"
"176.11200","44.07326","0.03209"
"176.25600","44.08516","0.03214"
"176.40000","44.09718","0.03190"
"176.54400","44.10919","0.03239"
"176.68800","44.12120","0.03219"
"176.83200","44.13316","0.03241"
"176.97600","44.14518","0.03250"
"177.12000","44.15726","0.03239"
"177.26400","44.16922","0.03231"
"177.40800","44.18118","0.03203"
"177.55200","44.19314","0.03242"
"177.69600","44.20515","0.03200"
"177.84000","44.21717","0.03198"
"177.98400","44.22913","0.03287"
"178.12800","44.24114","0.03255"
"178.27200","44.25316","0.03211"
"178.41600","44.26518","0.03244"
"178.56000","44.27714","0.03278"
"178.70400","44.28922","0.03253"
"178.84800","44.30117","0.03231"
"178.99200","44.31313","0.03223"
"179.13600","44.32515","0.03236"
"179.28000","44.33717","0.03226"
"179.42400","44.34919","0.03293"
"179.56800","44.36115","0.03292"
"179.71200","44.37316","0.03213"
"179.85600","44.38518","0.03244"
"180.00000","44.39719","0.03231"
"180.14400","44.40915","0.03244"
"180.28800","44.42123","0.03251"
"180.43200","44.43319","0.03273"
"180.57600","44.44515","0.03223"
"180.72000","44.45717","0.03274"
"180.86400","44.46924","0.03287"
"181.00800","44.48114","0.03254"
"181.15200","44.49316","0.03287"
"181.29600","44.50518","0.03292"
"181.44000","44.51720","0.03268"
"181.58400","44.52921","0.03289"
"181.72800","44.54117","0.03241"
"181.87200","44.55319","0.03283"
"182.01600","44.56520","0.03282"
"182.16000","44.57716","0.03241"
"182.30400","44.58912","0.03256"
"182.44800","44.60126","0.03275"
"182.59200","44.61322","0.03306"
"182.73600","44.62511","0.03260"
"182.88000","44.63713","0.03252"
"183.02400","44.64915","0.03284"
"183.16800","44.66117","0.03274"
"183.31200","44.67313","0.03223"
"183.45600","44.68514","0.03246"
"183.60000","44.69716","0.03267"
"183.74400","44.70918","0.03266"
"183.88800","44.72107","0.03300"
"184.03200","44.73322","0.03233"
"184.17600","44.74523","0.03343"
"184.32000","44.75719","0.03324"
"184.46400","44.76915","0.03262"
"184.60800","44.78116","0.03269"
"184.75200","44.79324","0.03282"
"184.89600","44.80514","0.03275"
"185.04000","44.81716","0.03274"
"185.18400","44.82917","0.03243"
"185.32800","44.84119","0.03349"
"185.47200","44.85315","0.03339"
"185.61600","44.86517","0.03282"
"185.76000","44.87712","0.03256"
"185.90400","44.88921","0.03253"
"186.04800","44.90110","0.03289"
"186.19200","44.91318","0.03314"
"186.33600","44.92520","0.03268"
"186.48000","44.93716","0.03310"
"186.62400","44.94912","0.03240"
"186.76800","44.96113","0.03327"
"186.91200","44.97321","0.03297"
"187.05600","44.98517","0.03247"
"187.20000","44.99713","0.03271"
"187.34400","45.00920","0.03326"
"187.48800","45.02116","0.03339"
"187.63200","45.03312","0.03318"
"187.77600","45.04520","0.03342"
"187.92000","45.05716","0.03343"
"188.06400","45.06917","0.03320"
"188.20800","45.08113","0.03324"
"188.35200","45.09321","0.03331"
"188.49600","45.10517","0.03330"
"188.64000","45.11713","0.03306"
"188.78400","45.12914","0.03275"
"188.92800","45.14122","0.03296"
"189.07200","45.15317","0.03337"
"189.21600","45.16519","0.03361"
"189.36000","45.17721","0.03292"
"189.50400","45.18923","0.03326"
"189.64800","45.20119","0.03324"
"189.79200","45.21314","0.03329"
"189.93600","45.22522","0.03294"
"190.08000","45.23717","0.03308"
"190.22400","45.24913","0.03391"
"190.36800","45.26109","0.03334"
"190.51200","45.27317","0.03264"
"190.65600","45.28519","0.03288"
"190.80000","45.29721","0.03330"
"190.94400","45.30911","0.03372"
"191.08800","45.32118","0.03314"
"191.23200","45.33314","0.03362"
"191.37600","45.34516","0.03308"
"191.52000","45.35712","0.03327"
"191.66400","45.36914","0.03384"
"191.80800","45.38115","0.03305"
"191.95200","45.39305","0.03348"
"192.09600","45.40519","0.03341"
"192.24000","45.41721","0.03362"
"192.38400","45.42916","0.03344"
"192.52800","45.44112","0.03328"
"192.67200","45.45314","0.03337"
"192.81600","45.46522","0.03342"
"192.96000","45.47717","0.03301"
"193.10400","45.48913","0.03338"
"193.24800","45.50121","0.03303"
"193.39200","45.51323","0.03346"
"193.53600","45.52513","0.03401"
"193.68000","45.53720","0.03314"
"193.82400","45.54916","0.03306"
"193.96800","45.56118","0.03349"
"194.11200","45.57308","0.03379"
"194.25600","45.58515","0.03371"
"194.40000","45.59717","0.03326"
"194.54400","45.60919","0.03316"
"194.68800","45.62115","0.03342"
"194.83200","45.63317","0.03364"
"194.97600","45.64518","0.03345"
"195.12000","45.65714","0.03377"
"195.26400","45.66910","0.03356"
"195.40800","45.68111","0.03370"
"195.55200","45.69320","0.03353"
"195.69600","45.70509","0.03340"
"195.84000","45.71717","0.03347"
"195.98400","45.72919","0.03355"
"196.12800","45.74115","0.03409"
"196.27200","45.75310","0.03396"
"196.41600","45.76518","0.03302"
"196.56000","45.77713","0.03386"
"196.70400","45.78915","0.03374"
"196.84800","45.80111","0.03336"
"196.99200","45.81319","0.03366"
"197.13600","45.82521","0.03380"
"197.28000","45.83717","0.03372"
"197.42400","45.84912","0.03415"
"197.56800","45.86114","0.03360"
"197.71200","45.87316","0.03385"
"197.85600","45.88512","0.03308"
"198.00000","45.89720","0.03372"
"198.14400","45.90916","0.03388"
"198.28800","45.92111","0.03396"
"198.43200","45.93313","0.03406"
"198.57600","45.94521","0.03359"
"198.72000","45.95723","0.03372"
"198.86400","45.96918","0.03385"
"199.00800","45.98114","0.03366"
"199.15200","45.99322","0.03338"
"199.29600","46.00518","0.03398"
"199.44000","46.01714","0.03370"
"199.58400","46.02909","0.03352"
"199.72800","46.04117","0.03402"
"199.87200","46.05313","0.03335"
"200.01600","46.06515","0.03349"
"200.16000","46.07710","0.03299"
"200.30400","46.08918","0.03335"
"200.44800","46.10114","0.03360"
"200.59200","46.11309","0.03385"
"200.73600","46.12511","0.03269"
"200.88000","46.13719","0.03291"
"201.02400","46.14915","0.03325"
"201.16800","46.16117","0.03323"
"201.31200","46.17318","0.03399"
"201.45600","46.18520","0.03369"
"201.60000","46.19710","0.03343"
"201.74400","46.20912","0.03385"
"201.88800","46.22113","0.03303"
"202.03200","46.23315","0.03343"
"202.17600","46.24511","0.03352"
"202.32000","46.25713","0.03367"
"202.46400","46.26915","0.03350"
"202.60800","46.28117","0.03347"
"202.75200","46.29306","0.03368"
"202.89600","46.30520","0.03377"
"203.04000","46.31716","0.03369"
"203.18400","46.32918","0.03270"
"203.32800","46.34114","0.03298"
"203.47200","46.35321","0.03310"
"203.61600","46.36517","0.03251"
"203.76000","46.37712","0.03235"
"203.90400","46.38914","0.03244"
"204.04800","46.40116","0.03282"
"204.19200","46.41312","0.03265"
"204.33600","46.42513","0.03262"
"204.48000","46.43721","0.03232"
"204.62400","46.44917","0.03237"
"204.76800","46.46113","0.03258"
"204.91200","46.47315","0.03307"
"205.05600","46.48516","0.03235"
"205.20000","46.49718","0.03330"
"205.34400","46.50914","0.03295"
"205.48800","46.52116","0.03254"
"205.63200","46.53318","0.03294"
"205.77600","46.54520","0.03312"
"205.92000","46.55716","0.03343"
"206.06400","46.56917","0.03331"
"206.20800","46.58113","0.03285"
"206.35200","46.59314","0.03267"
"206.49600","46.60510","0.03280"
"206.64000","46.61718","0.03339"
"206.78400","46.62920","0.03333"
"206.92800","46.64116","0.03296"
"207.07200","46.65312","0.03308"
"207.21600","46.66519","0.03297"
"207.36000","46.67721","0.03316"
"207.50400","46.68917","0.03266"
"207.64800","46.70119","0.03264"
"207.79200","46.71320","0.03282"
"207.93600","46.72516","0.03296"
"208.08000","46.73712","0.03286"
"208.22400","46.74920","0.03308"
"208.36800","46.76122","0.03309"
"208.51200","46.77317","0.03297"
"208.65600","46.78513","0.03345"
"208.80000","46.79715","0.03233"
"208.94400","46.80917","0.03279"
"209.08800","46.82119","0.03323"
"209.23200","46.83314","0.03306"
"209.37600","46.84522","0.03268"
"209.52000","46.85724","0.03269"
"209.66400","46.86914","0.03267"
"209.80800","46.88115","0.03258"
"209.95200","46.89317","0.03233"
"210.09600","46.90519","0.03282"
"210.24000","46.91714","0.03287"
"210.38400","46.92916","0.03276"
"210.52800","46.94118","0.03344"
"210.67200","46.95320","0.03288"
"210.81600","46.96516","0.03295"
"210.96000","46.97718","0.03290"
"211.10400","46.98925","0.03240"
"211.24800","47.00115","0.03335"
"211.39200","47.01323","0.03314"
"211.53600","47.02525","0.03248"
"211.68000","47.03720","0.03326"
"211.82400","47.04916","0.03284"
"211.96800","47.06124","0.03310"
"212.11200","47.07320","0.03311"
"212.25600","47.08521","0.03265"
"212.29800","47.08868","0.03310"