File: Force_trajectories/170121_3/Specimen_RawData_1.csv
End date,"1/21/2017"
Specimen label,"4DG_31"
Maximum Load,"1.04612",N

Time,Extension,Load
(s),(mm),(N)
"0.00000","0.00000","-0.00001"
"0.34200","0.02846","0.00187"
"0.68400","0.05716","0.00247"
"1.02600","0.08580","0.00291"
"1.36800","0.11426","0.00360"
"1.71000","0.14266","0.00456"
"2.05200","0.17124","0.00464"
"2.39400","0.19970","0.00529"
"2.73600","0.22822","0.00589"
"3.07800","0.25680","0.00567"
"3.42000","0.28520","0.00640"
"3.76200","0.31372","0.00667"
"4.10400","0.34224","0.00709"
"4.44600","0.37064","0.00714"
"4.78800","0.39921","0.00772"
"5.13000","0.42767","0.00787"
"5.47200","0.45613","0.00839"
"5.81400","0.48477","0.00860"
"6.15600","0.51323","0.00929"
"6.49800","0.54169","0.00981"
"6.84000","0.57021","0.00977"
"7.18200","0.59867","0.01064"
"7.52400","0.62719","0.01059"
"7.86600","0.65577","0.01092"
"8.20800","0.68417","0.01179"
"8.55000","0.71275","0.01280"
"8.89200","0.74115","0.01273"
"9.23400","0.76967","0.01295"
"9.57600","0.79825","0.01318"
"9.91800","0.82665","0.01400"
"10.26000","0.85523","0.01482"
"10.60200","0.88369","0.01485"
"10.94400","0.91215","0.01632"
"11.28600","0.94073","0.01702"
"11.62800","0.96925","0.01634"
"11.97000","0.99771","0.01671"
"12.31200","1.02623","0.01746"
"12.65400","1.05469","0.01836"
"12.99600","1.08321","0.01804"
"13.33800","1.11167","0.01972"
"13.68000","1.14019","0.01960"
"14.02200","1.16871","0.02050"
"14.36400","1.19723","0.02143"
"14.70600","1.22569","0.02151"
"15.04800","1.25426","0.02225"
"15.39000","1.28272","0.02287"
"15.73200","1.31112","0.02410"
"16.07400","1.33970","0.02308"
"16.41600","1.36822","0.02390"
"16.75800","1.39668","0.02452"
"17.10000","1.42520","0.02459"
"17.44200","1.45372","0.02488"
"17.78400","1.48218","0.02537"
"18.12600","1.51076","0.02514"
"18.46800","1.53916","0.02513"
"18.81000","1.56774","0.02453"
"19.15200","1.59620","0.02565"
"19.49400","1.62466","0.02549"
"19.83600","1.65324","0.02628"
"20.17800","1.68176","0.02708"
"20.52000","1.71022","0.02727"
"20.86200","1.73874","0.02793"
"21.20400","1.76720","0.02826"
"21.54600","1.79566","0.02867"
"21.88800","1.82424","0.02907"
"22.23000","1.85264","0.02973"
"22.57200","1.88122","0.02996"
"22.91400","1.90974","0.03093"
"23.25600","1.93814","0.03155"
"23.59800","1.96672","0.03053"
"23.94000","1.99518","0.03085"
"24.28200","2.02370","0.02976"
"24.62400","2.05228","0.02460"
"24.96600","2.08068","0.02432"
"25.30800","2.10920","0.02541"
"25.65000","2.13772","0.03165"
"25.99200","2.16612","0.03952"
"26.33400","2.19475","0.03341"
"26.67600","2.22321","0.03336"
"27.01800","2.25167","0.03056"
"27.36000","2.28025","0.02841"
"27.70200","2.30871","0.02926"
"28.04400","2.33723","0.02975"
"28.38600","2.36569","0.03528"
"28.72800","2.39421","0.03414"
"29.07000","2.42273","0.03068"
"29.41200","2.45119","0.02931"
"29.75400","2.47971","0.02985"
"30.09600","2.50817","0.03088"
"30.43800","2.53669","0.03096"
"30.78000","2.56515","0.03080"
"31.12200","2.59373","0.03221"
"31.46400","2.62225","0.03274"
"31.80600","2.65071","0.03293"
"32.14800","2.67923","0.03363"
"32.49000","2.70769","0.03378"
"32.83200","2.73621","0.03445"
"33.17400","2.76467","0.03423"
"33.51600","2.79319","0.03488"
"33.85800","2.82171","0.03622"
"34.20000","2.85023","0.03587"
"34.54200","2.87869","0.03676"
"34.88400","2.90727","0.03756"
"35.22600","2.93573","0.03769"
"35.56800","2.96419","0.03898"
"35.91000","2.99271","0.03844"
"36.25200","3.02117","0.03904"
"36.59400","3.04968","0.03944"
"36.93600","3.07826","0.03991"
"37.27800","3.10666","0.04108"
"37.62000","3.13524","0.04145"
"37.96200","3.16370","0.04091"
"38.30400","3.19216","0.04189"
"38.64600","3.22068","0.04204"
"38.98800","3.24920","0.04252"
"39.33000","3.27766","0.04244"
"39.67200","3.30618","0.04397"
"40.01400","3.33470","0.04374"
"40.35600","3.36322","0.04341"
"40.69800","3.39180","0.04414"
"41.04000","3.42008","0.04432"
"41.38200","3.44878","0.04564"
"41.72400","3.47724","0.04505"
"42.06600","3.50570","0.04558"
"42.40800","3.53422","0.04624"
"42.75000","3.56268","0.04701"
"43.09200","3.59114","0.04655"
"43.43400","3.61972","0.04787"
"43.77600","3.64818","0.04789"
"44.11800","3.67670","0.04834"
"44.46000","3.70522","0.04813"
"44.80200","3.73362","0.04939"
"45.14400","3.76226","0.04967"
"45.48600","3.79072","0.04943"
"45.82800","3.81924","0.05049"
"46.17000","3.84770","0.05046"
"46.51200","3.87616","0.05156"
"46.85400","3.90474","0.05161"
"47.19600","3.93319","0.05174"
"47.53800","3.96171","0.05214"
"47.88000","3.99023","0.05288"
"48.22200","4.01869","0.05304"
"48.56400","4.04721","0.05366"
"48.90600","4.07573","0.05370"
"49.24800","4.10425","0.05424"
"49.59000","4.13265","0.05488"
"49.93200","4.16123","0.05513"
"50.27400","4.18969","0.05509"
"50.61600","4.21821","0.05554"
"50.95800","4.24673","0.05612"
"51.30000","4.27519","0.05627"
"51.64200","4.30371","0.05655"
"51.98400","4.33223","0.05585"
"52.32600","4.36063","0.05654"
"52.66800","4.38927","0.05671"
"53.01000","4.41773","0.05688"
"53.35200","4.44625","0.05652"
"53.69400","4.47471","0.05687"
"54.03600","4.50317","0.05727"
"54.37800","4.53169","0.05720"
"54.72000","4.56027","0.05778"
"55.06200","4.58867","0.05767"
"55.40400","4.61719","0.05828"
"55.74600","4.64571","0.05842"
"56.08800","4.67411","0.05893"
"56.43000","4.70275","0.05856"
"56.77200","4.73121","0.05890"
"57.11400","4.75967","0.05969"
"57.45600","4.78824","0.05949"
"57.79800","4.81664","0.05957"
"58.14000","4.84516","0.05915"
"58.48200","4.87380","0.05915"
"58.82400","4.90214","0.06004"
"59.16600","4.93072","0.05990"
"59.50800","4.95924","0.06033"
"59.85000","4.98764","0.06041"
"60.19200","5.01622","0.06053"
"60.53400","5.04468","0.06074"
"60.87600","5.07320","0.06099"
"61.21800","5.10172","0.06125"
"61.56000","5.13012","0.06149"
"61.90200","5.15876","0.06211"
"62.24400","5.18716","0.06219"
"62.58600","5.21562","0.06170"
"62.92800","5.24426","0.05945"
"63.27000","5.27272","0.05985"
"63.61200","5.30118","0.05940"
"63.95400","5.32970","0.05948"
"64.29600","5.35816","0.05993"
"64.63800","5.38668","0.05883"
"64.98000","5.41520","0.05813"
"65.32200","5.44372","0.05846"
"65.66400","5.47218","0.05849"
"66.00600","5.50070","0.05876"
"66.34800","5.52916","0.05922"
"66.69000","5.55768","0.05903"
"67.03200","5.58626","0.05879"
"67.37400","5.61472","0.05837"
"67.71600","5.64324","0.05852"
"68.05800","5.67169","0.05920"
"68.40000","5.70021","0.05919"
"68.74200","5.72873","0.05964"
"69.08400","5.75719","0.06035"
"69.42600","5.78571","0.06023"
"69.76800","5.81423","0.06031"
"70.11000","5.84269","0.06053"
"70.45200","5.87121","0.06124"
"70.79400","5.89973","0.06164"
"71.13600","5.92813","0.06182"
"71.47800","5.95671","0.06190"
"71.82000","5.98517","0.06243"
"72.16200","6.01375","0.06250"
"72.50400","6.04221","0.06310"
"72.84600","6.07073","0.06286"
"73.18800","6.09913","0.06369"
"73.53000","6.12777","0.06382"
"73.87200","6.15617","0.06404"
"74.21400","6.18475","0.06463"
"74.55600","6.21327","0.06473"
"74.89800","6.24167","0.06513"
"75.24000","6.27025","0.06544"
"75.58200","6.29871","0.06555"
"75.92400","6.32723","0.06586"
"76.26600","6.35569","0.06644"
"76.60800","6.38415","0.06676"
"76.95000","6.41273","0.06700"
"77.29200","6.44119","0.06747"
"77.63400","6.46965","0.06810"
"77.97600","6.49829","0.06858"
"78.31800","6.52675","0.06898"
"78.66000","6.55514","0.06970"
"79.00200","6.58378","0.06972"
"79.34400","6.61218","0.07020"
"79.68600","6.64070","0.07103"
"80.02800","6.66922","0.07153"
"80.37000","6.69768","0.07199"
"80.71200","6.72626","0.07247"
"81.05400","6.75472","0.07327"
"81.39600","6.78312","0.07421"
"81.73800","6.81170","0.07500"
"82.08000","6.84016","0.07562"
"82.42200","6.86868","0.07688"
"82.76400","6.89720","0.07742"
"83.10600","6.92572","0.07836"
"83.44800","6.95418","0.07865"
"83.79000","6.98270","0.08021"
"84.13200","7.01116","0.08053"
"84.47400","7.03974","0.08140"
"84.81600","7.06826","0.08279"
"85.15800","7.09666","0.08283"
"85.50000","7.12524","0.08355"
"85.84200","7.15370","0.08470"
"86.18400","7.18216","0.08495"
"86.52600","7.21068","0.08579"
"86.86800","7.23920","0.08486"
"87.21000","7.26766","0.08503"
"87.55200","7.29618","0.08633"
"87.89400","7.32470","0.08769"
"88.23600","7.35322","0.08749"
"88.57800","7.38174","0.08912"
"88.92000","7.41020","0.08985"
"89.26200","7.43871","0.09149"
"89.60400","7.46717","0.09205"
"89.94600","7.49563","0.09322"
"90.28800","7.52421","0.09354"
"90.63000","7.55273","0.09468"
"90.97200","7.58119","0.09524"
"91.31400","7.60971","0.09559"
"91.65600","7.63817","0.09661"
"91.99800","7.66669","0.09740"
"92.34000","7.69533","0.09824"
"92.68200","7.72367","0.09974"
"93.02400","7.75225","0.10025"
"93.36600","7.78071","0.10178"
"93.70800","7.80917","0.10265"
"94.05000","7.83775","0.10377"
"94.39200","7.86615","0.10465"
"94.73400","7.89467","0.10549"
"95.07600","7.92319","0.10706"
"95.41800","7.95165","0.10757"
"95.76000","7.98023","0.10896"
"96.10200","8.00875","0.10949"
"96.44400","8.03721","0.11107"
"96.78600","8.06573","0.11059"
"97.12800","8.09425","0.11102"
"97.47000","8.12271","0.11203"
"97.81200","8.15123","0.11261"
"98.15400","8.17969","0.11365"
"98.49600","8.20827","0.11398"
"98.83800","8.23673","0.11456"
"99.18000","8.26519","0.11522"
"99.52200","8.29370","0.11524"
"99.86400","8.32216","0.11575"
"100.20600","8.35063","0.11617"
"100.54800","8.37920","0.11641"
"100.89000","8.40772","0.11685"
"101.23200","8.43624","0.11685"
"101.57400","8.46470","0.11735"
"101.91600","8.49316","0.11745"
"102.25800","8.52174","0.11771"
"102.60000","8.55020","0.11780"
"102.94200","8.57872","0.11804"
"103.28400","8.60718","0.11876"
"103.62600","8.63570","0.11933"
"103.96800","8.66416","0.12040"
"104.31000","8.69274","0.12078"
"104.65200","8.72120","0.12218"
"104.99400","8.74972","0.12295"
"105.33600","8.77818","0.12427"
"105.67800","8.80670","0.12546"
"106.02000","8.83522","0.12663"
"106.36200","8.86374","0.12838"
"106.70400","8.89220","0.13012"
"107.04600","8.92072","0.13168"
"107.38800","8.94924","0.13291"
"107.73000","8.97764","0.13458"
"108.07200","9.00622","0.13604"
"108.41400","9.03468","0.13674"
"108.75600","9.06320","0.13865"
"109.09800","9.09172","0.14003"
"109.44000","9.12018","0.14143"
"109.78200","9.14864","0.14205"
"110.12400","9.17727","0.14334"
"110.46600","9.20562","0.14442"
"110.80800","9.23419","0.14539"
"111.15000","9.26277","0.14641"
"111.49200","9.29117","0.14774"
"111.83400","9.31975","0.14862"
"112.17600","9.34815","0.14947"
"112.51800","9.37667","0.15025"
"112.86000","9.40519","0.15081"
"113.20200","9.43365","0.15124"
"113.54400","9.46223","0.15238"
"113.88600","9.49069","0.15290"
"114.22800","9.51915","0.15321"
"114.57000","9.54773","0.15434"
"114.91200","9.57619","0.15482"
"115.25400","9.60465","0.15611"
"115.59600","9.63323","0.15654"
"115.93800","9.66169","0.15688"
"116.28000","9.69021","0.15835"
"116.62200","9.71873","0.15875"
"116.96400","9.74719","0.15938"
"117.30600","9.77577","0.16022"
"117.64800","9.80423","0.16102"
"117.99000","9.83263","0.16162"
"118.33200","9.86121","0.16252"
"118.67400","9.88967","0.16314"
"119.01600","9.91819","0.16396"
"119.35800","9.94677","0.16464"
"119.70000","9.97517","0.16467"
"120.04200","10.00369","0.16545"
"120.38400","10.03221","0.16652"
"120.72600","10.06073","0.16712"
"121.06800","10.08924","0.16786"
"121.41000","10.11770","0.16882"
"121.75200","10.14622","0.17049"
"122.09400","10.17474","0.17121"
"122.43600","10.20320","0.17217"
"122.77800","10.23166","0.17413"
"123.12000","10.26018","0.17536"
"123.46200","10.28870","0.17762"
"123.80400","10.31722","0.17856"
"124.14600","10.34574","0.17932"
"124.48800","10.37420","0.18122"
"124.83000","10.40266","0.18337"
"125.17200","10.43124","0.18580"
"125.51400","10.45970","0.18955"
"125.85600","10.48822","0.19188"
"126.19800","10.51674","0.19367"
"126.54000","10.54520","0.19700"
"126.88200","10.57372","0.20038"
"127.22400","10.60224","0.20233"
"127.56600","10.63070","0.20536"
"127.90800","10.65922","0.20672"
"128.25000","10.68756","0.20906"
"128.59200","10.71620","0.21183"
"128.93400","10.74472","0.21421"
"129.27600","10.77318","0.21592"
"129.61800","10.80176","0.21747"
"129.96000","10.83016","0.21372"
"130.30200","10.85868","0.21634"
"130.64400","10.88725","0.21744"
"130.98600","10.91566","0.21814"
"131.32800","10.94423","0.21923"
"131.67000","10.97276","0.22030"
"132.01200","11.00115","0.22161"
"132.35400","11.02973","0.22252"
"132.69600","11.05819","0.22366"
"133.03800","11.08665","0.22506"
"133.38000","11.11523","0.22678"
"133.72200","11.14369","0.22764"
"134.06400","11.17221","0.22973"
"134.40600","11.20073","0.23149"
"134.74800","11.22919","0.23415"
"135.09000","11.25771","0.23589"
"135.43200","11.28623","0.23878"
"135.77400","11.31463","0.24122"
"136.11600","11.34327","0.24370"
"136.45800","11.37173","0.24525"
"136.80000","11.40013","0.24813"
"137.14200","11.42871","0.25043"
"137.48400","11.45717","0.25199"
"137.82600","11.48569","0.25246"
"138.16800","11.51421","0.25312"
"138.51000","11.54273","0.25525"
"138.85200","11.57119","0.25726"
"139.19400","11.59971","0.25855"
"139.53600","11.62817","0.25993"
"139.87800","11.65669","0.26196"
"140.22000","11.68521","0.26267"
"140.56200","11.71367","0.26370"
"140.90400","11.74219","0.26429"
"141.24600","11.77071","0.26499"
"141.58800","11.79922","0.26561"
"141.93000","11.82775","0.26617"
"142.27200","11.85620","0.26672"
"142.61400","11.88466","0.26737"
"142.95600","11.91318","0.26775"
"143.29800","11.94170","0.26813"
"143.64000","11.97022","0.26871"
"143.98200","11.99874","0.26916"
"144.32400","12.02720","0.27014"
"144.66600","12.05578","0.27112"
"145.00800","12.08424","0.27220"
"145.35000","12.11270","0.27314"
"145.69200","12.14122","0.27454"
"146.03400","12.16968","0.27559"
"146.37600","12.19820","0.27730"
"146.71800","12.22672","0.27995"
"147.06000","12.25512","0.28257"
"147.40200","12.28370","0.28452"
"147.74400","12.31222","0.28708"
"148.08600","12.34068","0.28956"
"148.42800","12.36920","0.29225"
"148.77000","12.39772","0.29367"
"149.11200","12.42624","0.29533"
"149.45400","12.45470","0.29704"
"149.79600","12.48316","0.29993"
"150.13800","12.51174","0.30227"
"150.48000","12.54026","0.30364"
"150.82200","12.56866","0.30556"
"151.16400","12.59724","0.30812"
"151.50600","12.62570","0.30968"
"151.84800","12.65416","0.31209"
"152.19000","12.68274","0.31337"
"152.53200","12.71125","0.31475"
"152.87400","12.73965","0.31577"
"153.21600","12.76824","0.18889"
"153.55800","12.79663","0.20300"
"153.90000","12.82521","0.21488"
"154.24200","12.85373","0.21190"
"154.58400","12.88219","0.21584"
"154.92600","12.91077","0.21828"
"155.26800","12.93917","0.22247"
"155.61000","12.96769","0.22224"
"155.95200","12.99621","0.22547"
"156.29400","13.02467","0.23039"
"156.63600","13.05319","0.23570"
"156.97800","13.08171","0.24030"
"157.32000","13.11017","0.24480"
"157.66200","13.13875","0.24957"
"158.00400","13.16721","0.25376"
"158.34600","13.19567","0.25713"
"158.68800","13.22419","0.26118"
"159.03000","13.25271","0.26314"
"159.37200","13.28123","0.26482"
"159.71400","13.30975","0.26604"
"160.05600","13.33821","0.26700"
"160.39800","13.36667","0.26832"
"160.74000","13.39519","0.26934"
"161.08200","13.42365","0.27037"
"161.42400","13.45217","0.27151"
"161.76600","13.48075","0.27269"
"162.10800","13.50915","0.27424"
"162.45000","13.53773","0.27564"
"162.79200","13.56625","0.27808"
"163.13400","13.59465","0.27969"
"163.47600","13.62322","0.28378"
"163.81800","13.65168","0.28642"
"164.16000","13.68015","0.29138"
"164.50200","13.70878","0.29627"
"164.84400","13.73718","0.29976"
"165.18600","13.76576","0.30414"
"165.52800","13.79422","0.30859"
"165.87000","13.82262","0.31118"
"166.21200","13.85120","0.31205"
"166.55400","13.87972","0.31363"
"166.89600","13.90818","0.31471"
"167.23800","13.93682","0.31570"
"167.58000","13.96516","0.31772"
"167.92200","13.99368","0.32054"
"168.26400","14.02226","0.32627"
"168.60600","14.05066","0.33346"
"168.94800","14.07924","0.33852"
"169.29000","14.10776","0.34273"
"169.63200","14.13616","0.34630"
"169.97400","14.16474","0.34934"
"170.31600","14.19320","0.35211"
"170.65800","14.22172","0.35670"
"171.00000","14.25024","0.35974"
"171.34200","14.27864","0.36484"
"171.68400","14.30728","0.36878"
"172.02600","14.33574","0.37064"
"172.36800","14.36414","0.37230"
"172.71000","14.39272","0.37349"
"173.05200","14.42124","0.37443"
"173.39400","14.44970","0.37601"
"173.73600","14.47822","0.37699"
"174.07800","14.50668","0.37876"
"174.42000","14.53519","0.37967"
"174.76200","14.56371","0.38038"
"175.10400","14.59217","0.38153"
"175.44600","14.62069","0.38354"
"175.78800","14.64915","0.38643"
"176.13000","14.67773","0.38844"
"176.47200","14.70625","0.39187"
"176.81400","14.73471","0.39414"
"177.15600","14.76323","0.39702"
"177.49800","14.79169","0.40283"
"177.84000","14.82021","0.40920"
"178.18200","14.84867","0.41345"
"178.52400","14.87719","0.41457"
"178.86600","14.90571","0.41673"
"179.20800","14.93417","0.42085"
"179.55000","14.96275","0.42341"
"179.89200","14.99115","0.42524"
"180.23400","15.01973","0.42663"
"180.57600","15.04819","0.42931"
"180.91800","15.07671","0.43332"
"181.26000","15.10523","0.43843"
"181.60200","15.13369","0.44189"
"181.94400","15.16215","0.44468"
"182.28600","15.19073","0.44797"
"182.62800","15.21919","0.45262"
"182.97000","15.24771","0.45565"
"183.31200","15.27623","0.45746"
"183.65400","15.30463","0.45957"
"183.99600","15.33321","0.46207"
"184.33800","15.36172","0.46382"
"184.68000","15.39025","0.46524"
"185.02200","15.41876","0.46690"
"185.36400","15.44716","0.47082"
"185.70600","15.47569","0.47407"
"186.04800","15.50420","0.47694"
"186.39000","15.53266","0.47956"
"186.73200","15.56124","0.48347"
"187.07400","15.58970","0.48707"
"187.41600","15.61810","0.49039"
"187.75800","15.64674","0.49614"
"188.10000","15.67526","0.50165"
"188.44200","15.70372","0.50543"
"188.78400","15.73224","0.50984"
"189.12600","15.76064","0.51375"
"189.46800","15.78922","0.51794"
"189.81000","15.81774","0.52088"
"190.15200","15.84614","0.52342"
"190.49400","15.87472","0.52534"
"190.83600","15.90324","0.52715"
"191.17800","15.93164","0.53039"
"191.52000","15.96022","0.53722"
"191.86200","15.98868","0.54251"
"192.20400","16.01720","0.54792"
"192.54600","16.04566","0.55479"
"192.88800","16.07424","0.55930"
"193.23000","16.10270","0.56333"
"193.57200","16.13121","0.56824"
"193.91400","16.15968","0.57236"
"194.25600","16.18819","0.57424"
"194.59800","16.21671","0.57743"
"194.94000","16.24517","0.57901"
"195.28200","16.27375","0.58186"
"195.62400","16.30227","0.58430"
"195.96600","16.33068","0.58603"
"196.30800","16.35925","0.58597"
"196.65000","16.38771","0.58741"
"196.99200","16.41617","0.58670"
"197.33400","16.44469","0.58865"
"197.67600","16.47315","0.59158"
"198.01800","16.50167","0.59511"
"198.36000","16.53025","0.59926"
"198.70200","16.55865","0.60543"
"199.04400","16.58723","0.59666"
"199.38600","16.61569","0.56202"
"199.72800","16.64415","0.56808"
"200.07000","16.67273","0.57313"
"200.41200","16.70125","0.56578"
"200.75400","16.72971","0.57113"
"201.09600","16.75823","0.57605"
"201.43800","16.78669","0.57863"
"201.78000","16.81521","0.57642"
"202.12200","16.84379","0.58238"
"202.46400","16.87213","0.58430"
"202.80600","16.90071","0.58717"
"203.14800","16.92923","0.59023"
"203.49000","16.95763","0.59260"
"203.83200","16.98621","0.59495"
"204.17400","17.01472","0.60078"
"204.51600","17.04319","0.60606"
"204.85800","17.07170","0.60852"
"205.20000","17.10016","0.61335"
"205.54200","17.12875","0.62127"
"205.88400","17.15726","0.62764"
"206.22600","17.18560","0.59708"
"206.56800","17.21424","0.60033"
"206.91000","17.24264","0.60740"
"207.25200","17.27116","0.61233"
"207.59400","17.29974","0.61917"
"207.93600","17.32814","0.62451"
"208.27800","17.35672","0.62864"
"208.62000","17.38518","0.63346"
"208.96200","17.41364","0.63824"
"209.30400","17.44216","0.64494"
"209.64600","17.47074","0.65360"
"209.98800","17.49920","0.65999"
"210.33000","17.52778","0.66578"
"210.67200","17.55618","0.66923"
"211.01400","17.58470","0.67250"
"211.35600","17.61316","0.67457"
"211.69800","17.64168","0.67613"
"212.04000","17.67020","0.67802"
"212.38200","17.69872","0.68030"
"212.72400","17.72718","0.68330"
"213.06600","17.75570","0.68577"
"213.40800","17.78422","0.68869"
"213.75000","17.81268","0.69319"
"214.09200","17.84120","0.69832"
"214.43400","17.86972","0.70433"
"214.77600","17.89818","0.70967"
"215.11800","17.92669","0.71657"
"215.46000","17.95522","0.72313"
"215.80200","17.98368","0.72901"
"216.14400","18.01225","0.73304"
"216.48600","18.04066","0.73513"
"216.82800","18.06923","0.73660"
"217.17000","18.09775","0.74009"
"217.51200","18.12615","0.74495"
"217.85400","18.15473","0.75215"
"218.19600","18.18319","0.75854"
"218.53800","18.21171","0.76521"
"218.88000","18.24023","0.77112"
"219.22200","18.26869","0.77685"
"219.56400","18.29721","0.78090"
"219.90600","18.32573","0.78441"
"220.24800","18.35419","0.78723"
"220.59000","18.38271","0.78982"
"220.93200","18.41123","0.79272"
"221.27400","18.43963","0.79683"
"221.61600","18.46821","0.80116"
"221.95800","18.49667","0.80550"
"222.30000","18.52519","0.80906"
"222.64200","18.55371","0.81344"
"222.98400","18.58211","0.81969"
"223.32600","18.61075","0.82446"
"223.66800","18.63927","0.82822"
"224.01000","18.66761","0.83250"
"224.35200","18.69625","0.83887"
"224.69400","18.72471","0.84723"
"225.03600","18.75317","0.85684"
"225.37800","18.78175","0.86666"
"225.72000","18.81021","0.87551"
"226.06200","18.83867","0.88134"
"226.40400","18.86719","0.88502"
"226.74600","18.89565","0.88713"
"227.08800","18.92422","0.88860"
"227.43000","18.95274","0.88997"
"227.77200","18.98120","0.89176"
"228.11400","19.00966","0.89544"
"228.45600","19.03818","0.89732"
"228.79800","19.06670","0.90013"
"229.14000","19.09522","0.90561"
"229.48200","19.12374","0.91167"
"229.82400","19.15220","0.91779"
"230.16600","19.18072","0.92562"
"230.50800","19.20918","0.93256"
"230.85000","19.23770","0.93730"
"231.19200","19.26622","0.94097"
"231.53400","19.29468","0.94458"
"231.87600","19.32320","0.95174"
"232.21800","19.35172","0.95914"
"232.56000","19.38012","0.96551"
"232.90200","19.40870","0.97175"
"233.24400","19.43722","0.97561"
"233.58600","19.46574","0.97991"
"233.92800","19.49420","0.98460"
"234.27000","19.52272","0.98931"
"234.61200","19.55118","0.99389"
"234.95400","19.57976","0.99929"
"235.29600","19.60816","1.00569"
"235.63800","19.63667","1.01391"
"235.98000","19.66520","1.02113"
"236.32200","19.69371","1.02810"
"236.66400","19.72223","1.03650"
"237.00600","19.75070","1.04205"
"237.34800","19.77915","1.04430"
"237.69000","19.80767","1.04526"
"238.03200","19.83619","0.96732"
"238.37400","19.86471","0.97343"
"238.71600","19.89329","0.97805"
"239.05800","19.92163","0.93905"
"239.40000","19.95027","0.94195"
"239.74200","19.97873","0.78622"
"240.08400","20.00719","0.66304"
"240.42600","20.03577","0.65676"
"240.76800","20.06423","0.65906"
"241.11000","20.09269","0.53034"
"241.45200","20.12121","0.45806"
"241.79400","20.14973","0.45384"
"242.13600","20.17825","0.45278"
"242.47800","20.20671","0.39234"
"242.82000","20.23517","0.39304"
"243.16200","20.26369","0.39419"
"243.50400","20.29221","0.39552"
"243.84600","20.32073","0.39514"
"244.18800","20.34925","0.39745"
"244.53000","20.37765","0.40037"
"244.87200","20.40623","0.40550"
"245.21400","20.43475","0.40915"
"245.55600","20.46315","0.41205"
"245.89800","20.49172","0.41398"
"246.24000","20.52024","0.41667"
"246.58200","20.54870","0.41968"
"246.92400","20.57723","0.42238"
"247.26600","20.60575","0.42491"
"247.60800","20.63421","0.42656"
"247.95000","20.66273","0.43080"
"248.29200","20.69118","0.43592"
"248.63400","20.71970","0.44147"
"248.97600","20.74822","0.44589"
"249.31800","20.77668","0.44918"
"249.66000","20.80520","0.45259"
"250.00200","20.83366","0.45607"
"250.34400","20.86212","0.46029"
"250.68600","20.89076","0.46167"
"251.02800","20.91922","0.46292"
"251.37000","20.94768","0.46454"
"251.71200","20.97620","0.46746"
"252.05400","21.00472","0.46983"
"252.39600","21.03318","0.47279"
"252.73800","21.06176","0.47589"
"253.08000","21.09022","0.47936"
"253.42200","21.11868","0.48241"
"253.76400","21.14726","0.48422"
"254.10600","21.17566","0.48739"
"254.44800","21.20418","0.49120"
"254.79000","21.23270","0.49397"
"255.13200","21.26116","0.49801"
"255.47400","21.28974","0.50155"
"255.81600","21.31814","0.50424"
"256.15800","21.34666","0.50075"
"256.50000","21.37523","0.49808"
"256.84200","21.40369","0.50322"
"257.18400","21.43222","0.50736"
"257.52600","21.46074","0.51078"
"257.86800","21.48919","0.51459"
"258.21000","21.51771","0.51835"
"258.55200","21.54618","0.52137"
"258.89400","21.57470","0.52279"
"259.23600","21.60328","0.52488"
"259.57800","21.63167","0.52629"
"259.92000","21.66025","0.52801"
"260.26200","21.68865","0.53040"
"260.60400","21.71711","0.53527"
"260.94600","21.74575","0.54024"
"261.28800","21.77421","0.54546"
"261.63000","21.80267","0.55154"
"261.97200","21.83125","0.55696"
"262.31400","21.85971","0.56247"
"262.65600","21.88817","0.56674"
"262.99800","21.91669","0.56948"
"263.34000","21.94515","0.57245"
"263.68200","21.97373","0.57590"
"264.02400","22.00219","0.57789"
"264.36600","22.03065","0.43889"
"264.70800","22.05917","0.43786"
"265.05000","22.08769","0.44450"
"265.39200","22.11615","0.44586"
"265.73400","22.14473","0.44470"
"266.07600","22.17319","0.44603"
"266.41800","22.20171","0.45117"
"266.76000","22.23022","0.45557"
"267.10200","22.25869","0.45654"
"267.44400","22.28720","0.45600"
"267.78600","22.31573","0.45837"
"268.12800","22.34419","0.46146"
"268.47000","22.37271","0.46381"
"268.81200","22.40117","0.46326"
"269.15400","22.42969","0.46460"
"269.49600","22.45827","0.46758"
"269.83800","22.48666","0.47179"
"270.18000","22.51518","0.47254"
"270.52200","22.54376","0.47357"
"270.86400","22.57216","0.47746"
"271.20600","22.60062","0.48355"
"271.54800","22.62926","0.48341"
"271.89000","22.65766","0.48579"
"272.23200","22.68624","0.49297"
"272.57400","22.71476","0.49962"
"272.91600","22.74316","0.50107"
"273.25800","22.77168","0.50415"
"273.60000","22.80020","0.50982"
"273.94200","22.82872","0.51406"
"274.28400","22.85724","0.51491"
"274.62600","22.88564","0.51621"
"274.96800","22.91422","0.52098"
"275.31000","22.94274","0.52226"
"275.65200","22.97114","0.52382"
"275.99400","22.99978","0.39741"
"276.33600","23.02824","0.39607"
"276.67800","23.05670","0.39857"
"277.02000","23.08522","0.39904"
"277.36200","23.11374","0.39998"
"277.70400","23.14220","0.40097"
"278.04600","23.17072","0.40428"
"278.38800","23.19912","0.39590"
"278.73000","23.22775","0.39964"
"279.07200","23.25622","0.36259"
"279.41400","23.28468","0.36655"
"279.75600","23.31319","0.36918"
"280.09800","23.34171","0.37190"
"280.44000","23.37023","0.37323"
"280.78200","23.39869","0.37450"
"281.12400","23.42721","0.37598"
"281.46600","23.45567","0.37771"
"281.80800","23.48425","0.37995"
"282.15000","23.51271","0.38072"
"282.49200","23.54123","0.38150"
"282.83400","23.56975","0.38275"
"283.17600","23.59815","0.38461"
"283.51800","23.62673","0.38766"
"283.86000","23.65519","0.39141"
"284.20200","23.68365","0.39599"
"284.54400","23.71223","0.39796"
"284.88600","23.74069","0.40228"
"285.22800","23.76921","0.40620"
"285.57000","23.79773","0.41406"
"285.91200","23.82619","0.41910"
"286.25400","23.85471","0.42227"
"286.59600","23.88323","0.42305"
"286.93800","23.91169","0.27265"
"287.28000","23.94020","0.26856"
"287.62200","23.96873","0.26904"
"287.96400","23.99719","0.26918"
"288.30600","24.02571","0.27000"
"288.64800","24.05417","0.27112"
"288.99000","24.08269","0.27226"
"289.33200","24.11121","0.27395"
"289.67400","24.13967","0.27588"
"290.01600","24.16825","0.27819"
"290.35800","24.19676","0.27992"
"290.70000","24.22523","0.28262"
"291.04200","24.25374","0.28453"
"291.38400","24.28220","0.28614"
"291.72600","24.31066","0.28888"
"292.06800","24.33924","0.29063"
"292.41000","24.36770","0.29367"
"292.75200","24.39622","0.29579"
"293.09400","24.42474","0.29889"
"293.43600","24.45314","0.30131"
"293.77800","24.48172","0.30463"
"294.12000","24.51018","0.30781"
"294.46200","24.53864","0.31030"
"294.80400","24.56722","0.31160"
"295.14600","24.59574","0.31349"
"295.48800","24.62420","0.31463"
"295.83000","24.65272","0.31584"
"296.17200","24.68118","0.31735"
"296.51400","24.70976","0.31884"
"296.85600","24.73822","0.32047"
"297.19800","24.76662","0.32294"
"297.54000","24.79526","0.32580"
"297.88200","24.82372","0.32900"
"298.22400","24.85218","0.33139"
"298.56600","24.88076","0.33646"
"298.90800","24.90922","0.34089"
"299.25000","24.93767","0.34540"
"299.59200","24.96620","0.34894"
"299.93400","24.99466","0.34879"
"300.27600","25.02324","0.31939"
"300.61800","25.05176","0.32131"
"300.96000","25.08015","0.32460"
"301.30200","25.10867","0.06320"
"301.64400","25.13720","0.05991"
"301.98600","25.16566","0.07046"
"302.32800","25.19423","0.06375"
"302.67000","25.22269","0.06809"
"303.01200","25.25115","0.06926"
"303.35400","25.27967","0.07228"
"303.69600","25.30819","0.07208"
"304.03800","25.33671","0.07243"
"304.38000","25.36523","0.08027"
"304.72200","25.39369","0.07885"
"305.06400","25.42221","0.08018"
"305.40600","25.45073","0.07957"
"305.74800","25.47919","0.08688"
"306.09000","25.50771","0.08678"
"306.43200","25.53623","0.08836"
"306.77400","25.56463","0.08766"
"307.11600","25.59321","0.09254"
"307.45800","25.62167","0.09451"
"307.80000","25.65019","0.09442"
"308.14200","25.67877","0.09569"
"308.48400","25.70711","0.09758"
"308.82600","25.73575","0.10056"
"309.16800","25.76427","0.09910"
"309.51000","25.79267","0.10065"
"309.85200","25.82125","0.10060"
"310.19400","25.84965","0.10240"
"310.53600","25.87817","0.07972"
"310.87800","25.90675","0.07924"
"311.22000","25.93521","0.07807"
"311.56200","25.96373","0.08146"
"311.90400","25.99224","0.08335"
"312.24600","26.02064","0.08063"
"312.58800","26.04922","0.08240"
"312.93000","26.07774","0.08622"
"313.27200","26.10620","0.08782"
"313.61400","26.13472","0.08913"
"313.95600","26.16318","0.09084"
"314.29800","26.19170","0.09341"
"314.64000","26.22022","0.09554"
"314.98200","26.24868","0.09640"
"315.32400","26.27720","0.09822"
"315.66600","26.30572","0.10046"
"316.00800","26.33412","0.10210"
"316.35000","26.36270","0.10362"
"316.69200","26.39122","0.10539"
"317.03400","26.41968","0.10668"
"317.37600","26.44820","0.10910"
"317.71800","26.47666","0.11045"
"318.06000","26.50524","0.11145"
"318.40200","26.53370","0.11279"
"318.74400","26.56216","0.11388"
"319.08600","26.59074","0.11494"
"319.42800","26.61920","0.11563"
"319.77000","26.64766","0.11595"
"320.11200","26.67624","0.11595"
"320.45400","26.70470","0.11646"
"320.79600","26.73322","0.11680"
"321.13800","26.76174","0.11734"
"321.48000","26.79019","0.11669"
"321.82200","26.81871","0.11506"
"322.16400","26.84718","0.11550"
"322.50600","26.87569","0.11466"
"322.84800","26.90421","0.11536"
"323.19000","26.93273","0.11452"
"323.53200","26.96119","0.11483"
"323.87400","26.98971","0.11545"
"324.21600","27.01823","0.11577"
"324.55800","27.04663","0.11612"
"324.90000","27.07521","0.11649"
"325.24200","27.10367","0.11679"
"325.58400","27.13219","0.11717"
"325.92600","27.16077","0.11756"
"326.26800","27.18917","0.11792"
"326.61000","27.21769","0.11838"
"326.95200","27.24615","0.11976"
"327.29400","27.27461","0.12036"
"327.63600","27.30331","0.12140"
"327.97800","27.33171","0.12154"
"328.32000","27.36017","0.12342"
"328.66200","27.38875","0.12425"
"329.00400","27.41721","0.12578"
"329.34600","27.44567","0.12561"
"329.68800","27.47425","0.12385"
"330.03000","27.50265","0.12307"
"330.37200","27.53117","0.12201"
"330.71400","27.55975","0.12168"
"331.05600","27.58821","0.12049"
"331.39800","27.61672","0.12014"
"331.74000","27.64519","0.12097"
"332.08200","27.67371","0.12331"
"332.42400","27.70222","0.12461"
"332.76600","27.73069","0.12442"
"333.10800","27.75926","0.12574"
"333.45000","27.78772","0.12615"
"333.79200","27.81612","0.12612"
"334.13400","27.84470","0.12631"
"334.47600","27.87328","0.12583"
"334.81800","27.90168","0.12617"
"335.16000","27.93020","0.12085"
"335.50200","27.95866","0.12106"
"335.84400","27.98724","0.12184"
"336.18600","28.01570","0.12023"
"336.52800","28.04416","0.12020"
"336.87000","28.07268","0.11809"
"337.21200","28.10114","0.11825"
"337.55400","28.12966","0.11816"
"337.89600","28.15824","0.11798"
"338.23800","28.18670","0.11708"
"338.58000","28.21516","0.11662"
"338.92200","28.24368","0.11690"
"339.26400","28.27220","0.11709"
"339.60600","28.30066","0.11734"
"339.94800","28.32918","0.11774"
"340.29000","28.35770","0.11835"
"340.63200","28.38622","0.11854"
"340.97400","28.41474","0.11831"
"341.31600","28.44320","0.11896"
"341.65800","28.47172","0.12037"
"342.00000","28.50024","0.12127"
"342.34200","28.52864","0.11798"
"342.68400","28.55722","0.11761"
"343.02600","28.58574","0.11754"
"343.36800","28.61419","0.11737"
"343.71000","28.64271","0.11796"
"344.05200","28.67123","0.11836"
"344.39400","28.69969","0.11876"
"344.73600","28.72828","0.11973"
"345.07800","28.75667","0.11998"
"345.42000","28.78519","0.11887"
"345.76200","28.81371","0.11978"
"346.10400","28.84217","0.12036"
"346.44600","28.87075","0.12187"
"346.78800","28.89915","0.12232"
"347.13000","28.92773","0.12347"
"347.47200","28.95619","0.12085"
"347.81400","28.98465","0.12196"
"348.15600","29.01323","0.12367"
"348.49800","29.04175","0.12570"
"348.84000","29.07015","0.12669"
"349.18200","29.09873","0.12642"
"349.52400","29.12725","0.12635"
"349.86600","29.15565","0.12903"
"350.20800","29.18423","0.13041"
"350.55000","29.21269","0.13223"
"350.89200","29.24121","0.13374"
"351.23400","29.26973","0.13467"
"351.57600","29.29813","0.13589"
"351.91800","29.32677","0.13656"
"352.26000","29.35523","0.13811"
"352.60200","29.38369","0.14016"
"352.94400","29.41221","0.13829"
"353.28600","29.44067","0.13949"
"353.62800","29.46919","0.14120"
"353.97000","29.49771","0.14206"
"354.31200","29.52617","0.14412"
"354.65400","29.55474","0.14412"
"354.99600","29.58320","0.14394"
"355.33800","29.61166","0.14489"
"355.68000","29.64024","0.14625"
"356.02200","29.66870","0.14695"
"356.36400","29.69722","0.14780"
"356.70600","29.72574","0.14916"
"357.04800","29.75420","0.15043"
"357.39000","29.78266","0.15152"
"357.73200","29.81118","0.15201"
"358.07400","29.83970","0.15270"
"358.41600","29.86816","0.15308"
"358.75800","29.89668","0.15430"
"359.10000","29.92514","0.15464"
"359.44200","29.95372","0.15549"
"359.78400","29.98224","0.15652"
"360.12600","30.01064","0.15698"
"360.46800","30.03916","0.15866"
"360.81000","30.06774","0.15920"
"361.15200","30.09620","0.16071"
"361.49400","30.12472","0.16157"
"361.83600","30.15318","0.16243"
"362.17800","30.18164","0.16339"
"362.52000","30.21022","0.16415"
"362.86200","30.23868","0.16510"
"363.20400","30.26720","0.16592"
"363.54600","30.29577","0.16589"
"363.88800","30.32418","0.16687"
"364.23000","30.35275","0.16741"
"364.57200","30.38121","0.16847"
"364.91400","30.40968","0.16916"
"365.25600","30.43826","0.16977"
"365.59800","30.46665","0.17007"
"365.94000","30.49517","0.16999"
"366.28200","30.52369","0.17070"
"366.62400","30.55221","0.17225"
"366.96600","30.58073","0.17260"
"367.30800","30.60919","0.17511"
"367.65000","30.63765","0.17572"
"367.99200","30.66623","0.17642"
"368.33400","30.69469","0.17871"
"368.67600","30.72315","0.18068"
"369.01800","30.75179","0.18228"
"369.36000","30.78019","0.18258"
"369.70200","30.80871","0.18510"
"370.04400","30.83723","0.18790"
"370.38600","30.86569","0.19219"
"370.72800","30.89421","0.19494"
"371.07000","30.92267","0.19822"
"371.41200","30.95119","0.20144"
"371.75400","30.97977","0.18840"
"372.09600","31.00823","0.18990"
"372.43800","31.03669","0.19018"
"372.78000","31.06521","0.19199"
"373.12200","31.09367","0.19150"
"373.46400","31.12218","0.19084"
"373.80600","31.15071","0.18508"
"374.14800","31.17917","0.17674"
"374.49000","31.20774","0.17295"
"374.83200","31.23621","0.17066"
"375.17400","31.26472","0.17040"
"375.51600","31.29318","0.17099"
"375.85800","31.32170","0.17201"
"376.20000","31.35022","0.17076"
"376.54200","31.37868","0.17223"
"376.88400","31.40720","0.17266"
"377.22600","31.43566","0.17162"
"377.56800","31.46424","0.17204"
"377.91000","31.49264","0.17268"
"378.25200","31.52122","0.17359"
"378.59400","31.54968","0.17413"
"378.93600","31.57814","0.17100"
"379.27800","31.60672","0.17147"
"379.62000","31.63518","0.17161"
"379.96200","31.66370","0.17188"
"380.30400","31.69222","0.17286"
"380.64600","31.72068","0.17473"
"380.98800","31.74920","0.17594"
"381.33000","31.77778","0.17833"
"381.67200","31.80612","0.18091"
"382.01400","31.83470","0.18299"
"382.35600","31.86322","0.18462"
"382.69800","31.89168","0.18726"
"383.04000","31.92019","0.19089"
"383.38200","31.94872","0.19380"
"383.72400","31.97718","0.19156"
"384.06600","32.00570","0.19108"
"384.40800","32.03416","0.19152"
"384.75000","32.06274","0.19257"
"385.09200","32.09125","0.19387"
"385.43400","32.11959","0.19633"
"385.77600","32.14824","0.19531"
"386.11800","32.17675","0.19675"
"386.46000","32.20515","0.19783"
"386.80200","32.23373","0.19477"
"387.14400","32.26219","0.19426"
"387.48600","32.29065","0.19397"
"387.82800","32.31917","0.19664"
"388.17000","32.34763","0.19738"
"388.51200","32.37627","0.19969"
"388.85400","32.40467","0.20175"
"389.19600","32.43313","0.20465"
"389.53800","32.46171","0.20641"
"389.88000","32.49023","0.20750"
"390.22200","32.51869","0.20683"
"390.56400","32.54721","0.20867"
"390.90600","32.57567","0.21090"
"391.24800","32.60419","0.21301"
"391.59000","32.63271","0.21400"
"391.93200","32.66123","0.21583"
"392.27400","32.68969","0.21770"
"392.61600","32.71821","0.21911"
"392.95800","32.74667","0.21906"
"393.30000","32.77525","0.21908"
"393.64200","32.80371","0.22006"
"393.98400","32.83223","0.22106"
"394.32600","32.86068","0.22161"
"394.66800","32.88921","0.22312"
"395.01000","32.91772","0.22444"
"395.35200","32.94624","0.22689"
"395.69400","32.97470","0.22696"
"396.03600","33.00316","0.22566"
"396.37800","33.03174","0.22847"
"396.72000","33.06015","0.23116"
"397.06200","33.08872","0.23319"
"397.40400","33.11724","0.23679"
"397.74600","33.14565","0.23842"
"398.08800","33.17422","0.24003"
"398.43000","33.20268","0.24133"
"398.77200","33.23120","0.24337"
"399.11400","33.25972","0.24538"
"399.45600","33.28818","0.24750"
"399.79800","33.31670","0.25062"
"400.14000","33.34528","0.25266"
"400.48200","33.37368","0.25410"
"400.82400","33.40226","0.25655"
"401.16600","33.43072","0.25841"
"401.50800","33.45912","0.25838"
"401.85000","33.48770","0.25967"
"402.19200","33.51616","0.26105"
"402.53400","33.54468","0.26226"
"402.87600","33.57320","0.26320"
"403.21800","33.60166","0.26418"
"403.56000","33.63024","0.26427"
"403.90200","33.65876","0.26509"
"404.24400","33.68716","0.26586"
"404.58600","33.71574","0.26608"
"404.92800","33.74420","0.26686"
"405.27000","33.77271","0.26721"
"405.61200","33.80124","0.26766"
"405.95400","33.82963","0.26811"
"406.29600","33.85822","0.26882"
"406.63800","33.88667","0.26929"
"406.98000","33.91513","0.26967"
"407.32200","33.94377","0.26994"
"407.66400","33.97223","0.27011"
"408.00600","34.00069","0.27128"
"408.34800","34.02921","0.27191"
"408.69000","34.05767","0.27189"
"409.03200","34.08619","0.27381"
"409.37400","34.11465","0.27486"
"409.71600","34.14323","0.27108"
"410.05800","34.17169","0.27112"
"410.40000","34.20021","0.27156"
"410.74200","34.22867","0.27213"
"411.08400","34.25719","0.27419"
"411.42600","34.28571","0.27563"
"411.76800","34.31417","0.27691"
"412.11000","34.34275","0.27806"
"412.45200","34.37121","0.27978"
"412.79400","34.39967","0.28060"
"413.13600","34.42825","0.27727"
"413.47800","34.45671","0.27672"
"413.82000","34.48517","0.27657"
"414.16200","34.51374","0.27726"
"414.50400","34.54221","0.27890"
"414.84600","34.57073","0.27891"
"415.18800","34.59924","0.27941"
"415.53000","34.62765","0.27983"
"415.87200","34.65623","0.27707"
"416.21400","34.68468","0.27715"
"416.55600","34.71315","0.27776"
"416.89800","34.74173","0.27593"
"417.24000","34.77018","0.27512"
"417.58200","34.79865","0.27169"
"417.92400","34.82722","0.27143"
"418.26600","34.85568","0.27168"
"418.60800","34.88420","0.27170"
"418.95000","34.91278","0.27302"
"419.29200","34.94118","0.27454"
"419.63400","34.96970","0.27564"
"419.97600","34.99822","0.27658"
"420.31800","35.02668","0.27740"
"420.66000","35.05526","0.27865"
"421.00200","35.08366","0.28103"
"421.34400","35.11224","0.28432"
"421.68600","35.14070","0.28494"
"422.02800","35.16916","0.28455"
"422.37000","35.19774","0.28463"
"422.71200","35.22620","0.28643"
"423.05400","35.25466","0.28871"
"423.39600","35.28324","0.29140"
"423.73800","35.31170","0.29310"
"424.08000","35.34022","0.29342"
"424.42200","35.36868","0.29589"
"424.76400","35.39714","0.29725"
"425.10600","35.42572","0.29868"
"425.44800","35.45424","0.29949"
"425.79000","35.48264","0.30119"
"426.13200","35.51122","0.30346"
"426.47400","35.53968","0.30638"
"426.81600","35.56820","0.30799"
"427.15800","35.59671","0.31046"
"427.50000","35.62518","0.31161"
"427.84200","35.65369","0.31313"
"428.18400","35.68221","0.31422"
"428.52600","35.71073","0.31523"
"428.86800","35.73919","0.31642"
"429.21000","35.76771","0.31666"
"429.55200","35.79617","0.31859"
"429.89400","35.82475","0.32102"
"430.23600","35.85321","0.32256"
"430.57800","35.88161","0.32627"
"430.92000","35.91025","0.32867"
"431.26200","35.93865","0.33055"
"431.60400","35.96723","0.33601"
"431.94600","35.99569","0.34257"
"432.28800","36.02421","0.34714"
"432.63000","36.05273","0.35154"
"432.97200","36.08125","0.35557"
"433.31400","36.10971","0.35863"
"433.65600","36.13823","0.36069"
"433.99800","36.16669","0.36291"
"434.34000","36.19515","0.36527"
"434.68200","36.22373","0.36700"
"435.02400","36.25219","0.36816"
"435.36600","36.28065","0.37019"
"435.70800","36.30929","0.37133"
"436.05000","36.33762","0.37252"
"436.39200","36.36621","0.37382"
"436.73400","36.39479","0.37429"
"437.07600","36.42313","0.37483"
"437.41800","36.45176","0.35900"
"437.76000","36.48022","0.35519"
"438.10200","36.50868","0.35614"
"438.44400","36.53726","0.35941"
"438.78600","36.56567","0.36115"
"439.12800","36.59418","0.36011"
"439.47000","36.62270","0.36206"
"439.81200","36.65117","0.36161"
"440.15400","36.67974","0.36238"
"440.49600","36.70820","0.36449"
"440.83800","36.73666","0.36789"
"441.18000","36.76524","0.37032"
"441.52200","36.79370","0.37247"
"441.86400","36.82222","0.37369"
"442.20600","36.85068","0.37495"
"442.54800","36.87920","0.37515"
"442.89000","36.90772","0.37530"
"443.23200","36.93624","0.37570"
"443.57400","36.96464","0.37633"
"443.91600","36.99316","0.37712"
"444.25800","37.02174","0.37882"
"444.60000","37.05014","0.37989"
"444.94200","37.07866","0.38141"
"445.28400","37.10718","0.37955"
"445.62600","37.13564","0.38051"
"445.96800","37.16422","0.38250"
"446.31000","37.19268","0.38373"
"446.65200","37.22120","0.38564"
"446.99400","37.24972","0.38800"
"447.33600","37.27818","0.39001"
"447.67800","37.30670","0.39330"
"448.02000","37.33522","0.39583"
"448.36200","37.36367","0.39964"
"448.70400","37.39220","0.40439"
"449.04600","37.42072","0.40574"
"449.38800","37.44923","0.40977"
"449.73000","37.47770","0.41285"
"450.07200","37.50621","0.41585"
"450.41400","37.53473","0.41876"
"450.75600","37.56325","0.40381"
"451.09800","37.59171","0.40588"
"451.44000","37.62017","0.40814"
"451.78200","37.64869","0.40840"
"452.12400","37.67715","0.40825"
"452.46600","37.70573","0.41024"
"452.80800","37.73419","0.41418"
"453.15000","37.76265","0.41492"
"453.49200","37.79123","0.41439"
"453.83400","37.81969","0.41508"
"454.17600","37.84821","0.41689"
"454.51800","37.87673","0.41925"
"454.86000","37.90513","0.41954"
"455.20200","37.93371","0.41820"
"455.54400","37.96223","0.42131"
"455.88600","37.99069","0.42175"
"456.22800","38.01926","0.41978"
"456.57000","38.04773","0.42166"
"456.91200","38.07619","0.42303"
"457.25400","38.10477","0.42441"
"457.59600","38.13317","0.42677"
"457.93800","38.16175","0.42901"
"458.28000","38.19014","0.43290"
"458.62200","38.21861","0.43725"
"458.96400","38.24731","0.43977"
"459.30600","38.27570","0.44318"
"459.64800","38.30416","0.44645"
"459.99000","38.33269","0.45012"
"460.33200","38.36120","0.45266"
"460.67400","38.38972","0.45544"
"461.01600","38.41819","0.45709"
"461.35800","38.44670","0.45887"
"461.70000","38.47522","0.46032"
"462.04200","38.50374","0.46082"
"462.38400","38.53214","0.46149"
"462.72600","38.56072","0.46277"
"463.06800","38.58918","0.46397"
"463.41000","38.61770","0.46537"
"463.75200","38.64628","0.46751"
"464.09400","38.67468","0.46981"
"464.43600","38.70320","0.47232"
"464.77800","38.73166","0.47506"
"465.12000","38.76018","0.47640"
"465.46200","38.78870","0.46978"
"465.80400","38.81722","0.47308"
"466.14600","38.84574","0.47497"
"466.48800","38.87426","0.47787"
"466.83000","38.90272","0.47807"
"467.17200","38.93118","0.47580"
"467.51400","38.95970","0.45896"
"467.85600","38.98822","0.45888"
"468.19800","39.01667","0.45944"
"468.54000","39.04520","0.45876"
"468.88200","39.07372","0.45900"
"469.22400","39.10217","0.46098"
"469.56600","39.13075","0.46234"
"469.90800","39.15916","0.46328"
"470.25000","39.18773","0.46455"
"470.59200","39.21625","0.46443"
"470.93400","39.24471","0.46204"
"471.27600","39.27323","0.46100"
"471.61800","39.30169","0.46214"
"471.96000","39.33015","0.46423"
"472.30200","39.35879","0.46620"
"472.64400","39.38713","0.46706"
"472.98600","39.41565","0.46959"
"473.32800","39.44423","0.47198"
"473.67000","39.47263","0.47441"
"474.01200","39.50127","0.47749"
"474.35400","39.52967","0.47949"
"474.69600","39.55819","0.48024"
"475.03800","39.58671","0.48178"
"475.38000","39.61523","0.48438"
"475.72200","39.64368","0.48613"
"476.06400","39.67221","0.48663"
"476.40600","39.70066","0.48969"
"476.74800","39.72925","0.49354"
"477.09000","39.75771","0.49683"
"477.43200","39.78617","0.50182"
"477.77400","39.81475","0.50456"
"478.11600","39.84321","0.50642"
"478.45800","39.87173","0.50928"
"478.80000","39.90019","0.51010"
"479.14200","39.92870","0.51096"
"479.48400","39.95723","0.51379"
"479.82600","39.98569","0.51688"
"480.16800","40.01414","0.51907"
"480.51000","40.04272","0.52092"
"480.85200","40.07124","0.52201"
"481.19400","40.09970","0.52207"
"481.53600","40.12822","0.52320"
"481.87800","40.15668","0.52404"
"482.22000","40.18520","0.52470"
"482.56200","40.21372","0.52599"
"482.90400","40.24218","0.52768"
"483.24600","40.27070","0.52651"
"483.58800","40.29916","0.52165"
"483.93000","40.32763","0.52249"
"484.27200","40.35626","0.52361"
"484.61400","40.38472","0.52480"
"484.95600","40.41318","0.52660"
"485.29800","40.44170","0.52866"
"485.64000","40.47021","0.53322"
"485.98200","40.49868","0.53658"
"486.32400","40.52719","0.53999"
"486.66600","40.55572","0.54574"
"487.00800","40.58418","0.54662"
"487.35000","40.61276","0.55003"
"487.69200","40.64116","0.55428"
"488.03400","40.66974","0.55833"
"488.37600","40.69826","0.55167"
"488.71800","40.72666","0.35018"
"489.06000","40.75524","0.35642"
"489.40200","40.78376","0.36276"
"489.74400","40.81216","0.36614"
"490.08600","40.84073","0.36462"
"490.42800","40.86914","0.36584"
"490.77000","40.89771","0.36919"
"491.11200","40.92623","0.37106"
"491.45400","40.95464","0.37181"
"491.79600","40.98322","0.37383"
"492.13800","41.01173","0.37524"
"492.48000","41.04019","0.37690"
"492.82200","41.06878","0.37928"
"493.16400","41.09717","0.38174"
"493.50600","41.12569","0.38364"
"493.84800","41.15421","0.38422"
"494.19000","41.18267","0.38494"
"494.53200","41.21125","0.38702"
"494.87400","41.23977","0.38867"
"495.21600","41.26811","0.39331"
"495.55800","41.29669","0.40131"
"495.90000","41.32527","0.40799"
"496.24200","41.35361","0.41030"
"496.58400","41.38224","0.41242"
"496.92600","41.41071","0.41589"
"497.26800","41.43916","0.41906"
"497.61000","41.46769","0.42139"
"497.95200","41.49621","0.42401"
"498.29400","41.52473","0.42689"
"498.63600","41.55319","0.42894"
"498.97800","41.58171","0.43155"
"499.32000","41.61023","0.43417"
"499.66200","41.63875","0.43686"
"500.00400","41.66721","0.44126"
"500.34600","41.69572","0.44580"
"500.68800","41.72419","0.44696"
"501.03000","41.75270","0.44867"
"501.37200","41.78122","0.44431"
"501.71400","41.80968","0.44611"
"502.05600","41.83821","0.44962"
"502.39800","41.86672","0.45156"
"502.74000","41.89518","0.45329"
"503.08200","41.92371","0.45431"
"503.42400","41.95222","0.45546"
"503.76600","41.98068","0.45763"
"504.10800","42.00920","0.45940"
"504.45000","42.03772","0.46075"
"504.79200","42.06618","0.46147"
"505.13400","42.09476","0.46252"
"505.47600","42.12322","0.46357"
"505.81800","42.15162","0.46431"
"506.16000","42.18026","0.46591"
"506.50200","42.20866","0.46749"
"506.84400","42.23724","0.46855"
"507.18600","42.26576","0.46961"
"507.52800","42.29422","0.46918"
"507.87000","42.32274","0.47003"
"508.21200","42.35114","0.47120"
"508.55400","42.37965","0.47305"
"508.89600","42.40824","0.47345"
"509.23800","42.43664","0.47515"
"509.58000","42.46522","0.47442"
"509.92200","42.49374","0.47183"
"510.10400","42.50886","0.47154"