File: Force_trajectories/170121_3/Specimen_RawData_3.csv
End date,"1/21/2017"
Specimen label,"13CT_5"
Maximum Load,"0.06552",N

Time,Extension,Load
(s),(mm),(N)
"0.00000","0.00000","-0.00001"
"0.18600","0.01262","0.00078"
"0.37200","0.03121","0.00113"
"0.55800","0.04670","0.00253"
"0.74400","0.06230","0.00335"
"0.93000","0.07773","0.00345"
"1.11600","0.09321","0.00432"
"1.30200","0.10876","0.00443"
"1.48800","0.12424","0.00396"
"1.67400","0.13967","0.00431"
"1.86000","0.15521","0.00403"
"2.04600","0.17076","0.00422"
"2.23200","0.18618","0.00476"
"2.41800","0.20173","0.00420"
"2.60400","0.21722","0.00461"
"2.79000","0.23264","0.00401"
"2.97600","0.24825","0.00467"
"3.16200","0.26373","0.00479"
"3.34800","0.27922","0.00467"
"3.53400","0.29470","0.00451"
"3.72000","0.31019","0.00456"
"3.90600","0.32573","0.00519"
"4.09200","0.34122","0.00481"
"4.27800","0.35670","0.00522"
"4.46400","0.37219","0.00523"
"4.65000","0.38774","0.00466"
"4.83600","0.40316","0.00477"
"5.02200","0.41871","0.00531"
"5.20800","0.43425","0.00467"
"5.39400","0.44968","0.00473"
"5.58000","0.46522","0.00446"
"5.76600","0.48077","0.00552"
"5.95200","0.49619","0.00499"
"6.13800","0.51174","0.00463"
"6.32400","0.52722","0.00476"
"6.51000","0.54271","0.00502"
"6.69600","0.55825","0.00434"
"6.88200","0.57374","0.00395"
"7.06800","0.58923","0.00455"
"7.25400","0.60471","0.00496"
"7.44000","0.62020","0.00427"
"7.62600","0.63568","0.00435"
"7.81200","0.65129","0.00457"
"7.99800","0.66671","0.00471"
"8.18400","0.68214","0.00446"
"8.37000","0.69774","0.00478"
"8.55600","0.71323","0.00439"
"8.74200","0.72866","0.00521"
"8.92800","0.74426","0.00400"
"9.11400","0.75969","0.00450"
"9.30000","0.77517","0.00468"
"9.48600","0.79072","0.00453"
"9.67200","0.80620","0.00473"
"9.85800","0.82175","0.00497"
"10.04400","0.83723","0.00466"
"10.23000","0.85272","0.00498"
"10.41600","0.86820","0.00433"
"10.60200","0.88375","0.00470"
"10.78800","0.89923","0.00502"
"10.97400","0.91478","0.00447"
"11.16000","0.93027","0.00503"
"11.34600","0.94569","0.00412"
"11.53200","0.96124","0.00448"
"11.71800","0.97672","0.00508"
"11.90400","0.99221","0.00431"
"12.09000","1.00781","0.00481"
"12.27600","1.02324","0.00440"
"12.46200","1.03866","0.00440"
"12.64800","1.05427","0.00446"
"12.83400","1.06975","0.00450"
"13.02000","1.08518","0.00508"
"13.20600","1.10073","0.00513"
"13.39200","1.11627","0.00406"
"13.57800","1.13170","0.00485"
"13.76400","1.14718","0.00454"
"13.95000","1.16273","0.00441"
"14.13600","1.17821","0.00466"
"14.32200","1.19370","0.00485"
"14.50800","1.20924","0.00465"
"14.69400","1.22473","0.00416"
"14.88000","1.24021","0.00500"
"15.06600","1.25570","0.00400"
"15.25200","1.27119","0.00479"
"15.43800","1.28673","0.00476"
"15.62400","1.30216","0.00452"
"15.81000","1.31776","0.00468"
"15.99600","1.33325","0.00489"
"16.18200","1.34867","0.00425"
"16.36800","1.36428","0.00483"
"16.55400","1.37976","0.00468"
"16.74000","1.39513","0.00441"
"16.92600","1.41073","0.00490"
"17.11200","1.42622","0.00369"
"17.29800","1.44170","0.00467"
"17.48400","1.45719","0.00419"
"17.67000","1.47274","0.00425"
"17.85600","1.48816","0.00466"
"18.04200","1.50377","0.00437"
"18.22800","1.51925","0.00422"
"18.41400","1.53474","0.00469"
"18.60000","1.55022","0.00455"
"18.78600","1.56571","0.00394"
"18.97200","1.58119","0.00430"
"19.15800","1.59674","0.00432"
"19.34400","1.61222","0.00478"
"19.53000","1.62771","0.00473"
"19.71600","1.64326","0.00464"
"19.90200","1.65868","0.00426"
"20.08800","1.67423","0.00433"
"20.27400","1.68977","0.00448"
"20.46000","1.70520","0.00441"
"20.64600","1.72068","0.00423"
"20.83200","1.73629","0.00453"
"21.01800","1.75171","0.00494"
"21.20400","1.76720","0.00529"
"21.39000","1.78274","0.00462"
"21.57600","1.79817","0.00448"
"21.76200","1.81372","0.00494"
"21.94800","1.82926","0.00438"
"22.13400","1.84469","0.00435"
"22.32000","1.86023","0.00492"
"22.50600","1.87572","0.00488"
"22.69200","1.89114","0.00475"
"22.87800","1.90675","0.00519"
"23.06400","1.92223","0.00403"
"23.25000","1.93766","0.00471"
"23.43600","1.95320","0.00445"
"23.62200","1.96869","0.00392"
"23.80800","1.98418","0.00436"
"23.99400","1.99978","0.00444"
"24.18000","2.01521","0.00495"
"24.36600","2.03069","0.00430"
"24.55200","2.04624","0.00477"
"24.73800","2.06172","0.00424"
"24.92400","2.07721","0.00462"
"25.11000","2.09269","0.00494"
"25.29600","2.10824","0.00468"
"25.48200","2.12366","0.00405"
"25.66800","2.13921","0.00514"
"25.85400","2.15470","0.00490"
"26.04000","2.17024","0.00528"
"26.22600","2.18573","0.00452"
"26.41200","2.20115","0.00475"
"26.59800","2.21676","0.00452"
"26.78400","2.23224","0.00494"
"26.97000","2.24767","0.00475"
"27.15600","2.26327","0.00530"
"27.34200","2.27876","0.00469"
"27.52800","2.29418","0.00445"
"27.71400","2.30973","0.00456"
"27.90000","2.32521","0.00463"
"28.08600","2.34064","0.00514"
"28.27200","2.35625","0.00505"
"28.45800","2.37179","0.00501"
"28.64400","2.38716","0.00502"
"28.83000","2.40270","0.00483"
"29.01600","2.41825","0.00428"
"29.20200","2.43367","0.00520"
"29.38800","2.44922","0.00446"
"29.57400","2.46464","0.00557"
"29.76000","2.48025","0.00487"
"29.94600","2.49573","0.00420"
"30.13200","2.51116","0.00462"
"30.31800","2.52677","0.00433"
"30.50400","2.54225","0.00491"
"30.69000","2.55774","0.00483"
"30.87600","2.57322","0.00445"
"31.06200","2.58877","0.00508"
"31.24800","2.60425","0.00540"
"31.43400","2.61974","0.00498"
"31.62000","2.63528","0.00461"
"31.80600","2.65065","0.00515"
"31.99200","2.66625","0.00446"
"32.17800","2.68180","0.00479"
"32.36400","2.69717","0.00442"
"32.55000","2.71271","0.00495"
"32.73600","2.72820","0.00479"
"32.92200","2.74368","0.00490"
"33.10800","2.75923","0.00497"
"33.29400","2.77471","0.00486"
"33.48000","2.79020","0.00510"
"33.66600","2.80574","0.00547"
"33.85200","2.82117","0.00456"
"34.03800","2.83671","0.00508"
"34.22400","2.85220","0.00473"
"34.41000","2.86774","0.00466"
"34.59600","2.88317","0.00448"
"34.78200","2.89872","0.00465"
"34.96800","2.91414","0.00537"
"35.15400","2.92975","0.00475"
"35.34000","2.94529","0.00497"
"35.52600","2.96066","0.00482"
"35.71200","2.97626","0.00498"
"35.89800","2.99175","0.00490"
"36.08400","3.00717","0.00496"
"36.27000","3.02272","0.00552"
"36.45600","3.03820","0.00525"
"36.64200","3.05375","0.00499"
"36.82800","3.06924","0.00429"
"37.01400","3.08472","0.00562"
"37.20000","3.10021","0.00487"
"37.38600","3.11575","0.00495"
"37.57200","3.13118","0.00515"
"37.75800","3.14672","0.00556"
"37.94400","3.16227","0.00526"
"38.13000","3.17775","0.00530"
"38.31600","3.19312","0.00491"
"38.50200","3.20872","0.00507"
"38.68800","3.22421","0.00471"
"38.87400","3.23970","0.00547"
"39.06000","3.25524","0.00505"
"39.24600","3.27073","0.00491"
"39.43200","3.28615","0.00516"
"39.61800","3.30170","0.00480"
"39.80400","3.31724","0.00500"
"39.99000","3.33273","0.00430"
"40.17600","3.34821","0.00516"
"40.36200","3.36376","0.00500"
"40.54800","3.37924","0.00520"
"40.73400","3.39473","0.00487"
"40.92000","3.41022","0.00446"
"41.10600","3.42564","0.00474"
"41.29200","3.44125","0.00531"
"41.47800","3.45667","0.00460"
"41.66400","3.47228","0.00474"
"41.85000","3.48770","0.00484"
"42.03600","3.50319","0.00498"
"42.22200","3.51873","0.00500"
"42.40800","3.53422","0.00497"
"42.59400","3.54964","0.00488"
"42.78000","3.56519","0.00498"
"42.96600","3.58074","0.00475"
"43.15200","3.59616","0.00544"
"43.33800","3.61171","0.00527"
"43.52400","3.62725","0.00466"
"43.71000","3.64268","0.00449"
"43.89600","3.65822","0.00530"
"44.08200","3.67377","0.00504"
"44.26800","3.68925","0.00484"
"44.45400","3.70468","0.00476"
"44.64000","3.72022","0.00468"
"44.82600","3.73577","0.00448"
"45.01200","3.75126","0.00494"
"45.19800","3.76668","0.00506"
"45.38400","3.78223","0.00516"
"45.57000","3.79777","0.00487"
"45.75600","3.81320","0.00470"
"45.94200","3.82874","0.00511"
"46.12800","3.84429","0.00498"
"46.31400","3.85971","0.00515"
"46.50000","3.87520","0.00502"
"46.68600","3.89080","0.00490"
"46.87200","3.90617","0.00587"
"47.05800","3.92165","0.00476"
"47.24400","3.93726","0.00486"
"47.43000","3.95269","0.00475"
"47.61600","3.96823","0.00518"
"47.80200","3.98378","0.00533"
"47.98800","3.99920","0.00502"
"48.17400","4.01475","0.00500"
"48.36000","4.03023","0.00513"
"48.54600","4.04572","0.00550"
"48.73200","4.06120","0.00518"
"48.91800","4.07669","0.00481"
"49.10400","4.09223","0.00552"
"49.29000","4.10772","0.00503"
"49.47600","4.12321","0.00567"
"49.66200","4.13869","0.00623"
"49.84800","4.15424","0.00485"
"50.03400","4.16972","0.00576"
"50.22000","4.18521","0.00523"
"50.40600","4.20075","0.00485"
"50.59200","4.21618","0.00528"
"50.77800","4.23166","0.00560"
"50.96400","4.24727","0.00547"
"51.15000","4.26269","0.00500"
"51.33600","4.27824","0.00506"
"51.52200","4.29373","0.00525"
"51.70800","4.30921","0.00511"
"51.89400","4.32476","0.00513"
"52.08000","4.34024","0.00483"
"52.26600","4.35567","0.00460"
"52.45200","4.37121","0.00510"
"52.63800","4.38670","0.00536"
"52.82400","4.40218","0.00485"
"53.01000","4.41779","0.00530"
"53.19600","4.43321","0.00512"
"53.38200","4.44864","0.00481"
"53.56800","4.46425","0.00561"
"53.75400","4.47973","0.00464"
"53.94000","4.49516","0.00523"
"54.12600","4.51076","0.00562"
"54.31200","4.52625","0.00453"
"54.49800","4.54167","0.00512"
"54.68400","4.55728","0.00560"
"54.87000","4.57270","0.00592"
"55.05600","4.58819","0.00553"
"55.24200","4.60379","0.00547"
"55.42800","4.61916","0.00562"
"55.61400","4.63471","0.00548"
"55.80000","4.65025","0.00596"
"55.98600","4.66568","0.00518"
"56.17200","4.68122","0.00587"
"56.35800","4.69671","0.00533"
"56.54400","4.71219","0.00560"
"56.73000","4.72774","0.00543"
"56.91600","4.74328","0.00523"
"57.10200","4.75865","0.00555"
"57.28800","4.77425","0.00557"
"57.47400","4.78974","0.00553"
"57.66000","4.80517","0.00567"
"57.84600","4.82077","0.00519"
"58.03200","4.83626","0.00578"
"58.21800","4.85168","0.00571"
"58.40400","4.86723","0.00532"
"58.59000","4.88277","0.00573"
"58.77600","4.89820","0.00520"
"58.96200","4.91374","0.00576"
"59.14800","4.92923","0.00538"
"59.33400","4.94471","0.00518"
"59.52000","4.96026","0.00483"
"59.70600","4.97568","0.00560"
"59.89200","4.99123","0.00540"
"60.07800","5.00672","0.00514"
"60.26400","5.02214","0.00588"
"60.45000","5.03775","0.00513"
"60.63600","5.05323","0.00528"
"60.82200","5.06866","0.00550"
"61.00800","5.08426","0.00533"
"61.19400","5.09975","0.00479"
"61.38000","5.11517","0.00530"
"61.56600","5.13078","0.00614"
"61.75200","5.14626","0.00597"
"61.93800","5.16169","0.00566"
"62.12400","5.17724","0.00584"
"62.31000","5.19278","0.00575"
"62.49600","5.20815","0.00586"
"62.68200","5.22375","0.00527"
"62.86800","5.23924","0.00656"
"63.05400","5.25466","0.00545"
"63.24000","5.27027","0.00466"
"63.42600","5.28575","0.00521"
"63.61200","5.30124","0.00540"
"63.79800","5.31678","0.00579"
"63.98400","5.33221","0.00578"
"64.17000","5.34770","0.00527"
"64.35600","5.36324","0.00568"
"64.54200","5.37867","0.00514"
"64.72800","5.39421","0.00541"
"64.91400","5.40976","0.00622"
"65.10000","5.42518","0.00551"
"65.28600","5.44067","0.00526"
"65.47200","5.45627","0.00623"
"65.65800","5.47170","0.00536"
"65.84400","5.48718","0.00574"
"66.03000","5.50273","0.00600"
"66.21600","5.51816","0.00587"
"66.40200","5.53370","0.00594"
"66.58800","5.54919","0.00575"
"66.77400","5.56467","0.00569"
"66.96000","5.58022","0.00575"
"67.14600","5.59570","0.00527"
"67.33200","5.61119","0.00581"
"67.51800","5.62673","0.00562"
"67.70400","5.64222","0.00600"
"67.89000","5.65770","0.00582"
"68.07600","5.67331","0.00620"
"68.26200","5.68867","0.00634"
"68.44800","5.70416","0.00592"
"68.63400","5.71977","0.00569"
"68.82000","5.73519","0.00574"
"69.00600","5.75068","0.00607"
"69.19200","5.76628","0.00591"
"69.37800","5.78171","0.00574"
"69.56400","5.79719","0.00573"
"69.75000","5.81274","0.00589"
"69.93600","5.82828","0.00557"
"70.12200","5.84371","0.00601"
"70.30800","5.85925","0.00599"
"70.49400","5.87468","0.00590"
"70.68000","5.89023","0.00620"
"70.86600","5.90577","0.00640"
"71.05200","5.92120","0.00610"
"71.23800","5.93674","0.00618"
"71.42400","5.95223","0.00606"
"71.61000","5.96771","0.00647"
"71.79600","5.98326","0.00646"
"71.98200","5.99880","0.00605"
"72.16800","6.01417","0.00661"
"72.35400","6.02972","0.00613"
"72.54000","6.04526","0.00625"
"72.72600","6.06063","0.00594"
"72.91200","6.07623","0.00601"
"73.09800","6.09178","0.00613"
"73.28400","6.10714","0.00583"
"73.47000","6.12275","0.00622"
"73.65600","6.13829","0.00610"
"73.84200","6.15372","0.00623"
"74.02800","6.16920","0.00566"
"74.21400","6.18475","0.00605"
"74.40000","6.20017","0.00580"
"74.58600","6.21572","0.00620"
"74.77200","6.23120","0.00608"
"74.95800","6.24669","0.00591"
"75.14400","6.26224","0.00643"
"75.33000","6.27772","0.00655"
"75.51600","6.29327","0.00574"
"75.70200","6.30869","0.00620"
"75.88800","6.32424","0.00629"
"76.07400","6.33972","0.00619"
"76.26000","6.35527","0.00628"
"76.44600","6.37069","0.00647"
"76.63200","6.38624","0.00556"
"76.81800","6.40173","0.00629"
"77.00400","6.41721","0.00599"
"77.19000","6.43270","0.00620"
"77.37600","6.44824","0.00605"
"77.56200","6.46373","0.00616"
"77.74800","6.47921","0.00621"
"77.93400","6.49470","0.00600"
"78.12000","6.51018","0.00626"
"78.30600","6.52573","0.00649"
"78.49200","6.54127","0.00619"
"78.67800","6.55670","0.00633"
"78.86400","6.57225","0.00594"
"79.05000","6.58767","0.00604"
"79.23600","6.60322","0.00608"
"79.42200","6.61876","0.00643"
"79.60800","6.63425","0.00582"
"79.79400","6.64967","0.00652"
"79.98000","6.66528","0.00623"
"80.16600","6.68070","0.00542"
"80.35200","6.69619","0.00566"
"80.53800","6.71179","0.00677"
"80.72400","6.72722","0.00668"
"80.91000","6.74271","0.00606"
"81.09600","6.75831","0.00615"
"81.28200","6.77368","0.00580"
"81.46800","6.78922","0.00665"
"81.65400","6.80477","0.00650"
"81.84000","6.82019","0.00637"
"82.02600","6.83574","0.00685"
"82.21200","6.85128","0.00672"
"82.39800","6.86671","0.00686"
"82.58400","6.88225","0.00692"
"82.77000","6.89774","0.00657"
"82.95600","6.91322","0.00650"
"83.14200","6.92877","0.00660"
"83.32800","6.94426","0.00633"
"83.51400","6.95968","0.00687"
"83.70000","6.97523","0.00626"
"83.88600","6.99077","0.00678"
"84.07200","7.00620","0.00665"
"84.25800","7.02174","0.00648"
"84.44400","7.03723","0.00624"
"84.63000","7.05265","0.00695"
"84.81600","7.06826","0.00631"
"85.00200","7.08374","0.00698"
"85.18800","7.09923","0.00644"
"85.37400","7.11472","0.00720"
"85.56000","7.13020","0.00672"
"85.74600","7.14569","0.00622"
"85.93200","7.16123","0.00685"
"86.11800","7.17666","0.00707"
"86.30400","7.19220","0.00701"
"86.49000","7.20775","0.00624"
"86.67600","7.22317","0.00721"
"86.86200","7.23878","0.00651"
"87.04800","7.25426","0.00712"
"87.23400","7.26969","0.00681"
"87.42000","7.28529","0.00669"
"87.60600","7.30072","0.00742"
"87.79200","7.31621","0.00731"
"87.97800","7.33175","0.00674"
"88.16400","7.34724","0.00702"
"88.35000","7.36266","0.00717"
"88.53600","7.37821","0.00702"
"88.72200","7.39375","0.00741"
"88.90800","7.40918","0.00629"
"89.09400","7.42472","0.00697"
"89.28000","7.44027","0.00714"
"89.46600","7.45570","0.00699"
"89.65200","7.47118","0.00705"
"89.83800","7.48667","0.00662"
"90.02400","7.50221","0.00701"
"90.21000","7.51776","0.00692"
"90.39600","7.53318","0.00664"
"90.58200","7.54873","0.00713"
"90.76800","7.56421","0.00696"
"90.95400","7.57970","0.00661"
"91.14000","7.59524","0.00730"
"91.32600","7.61079","0.00677"
"91.51200","7.62621","0.00686"
"91.69800","7.64176","0.00759"
"91.88400","7.65725","0.00717"
"92.07000","7.67267","0.00729"
"92.25600","7.68822","0.00687"
"92.44200","7.70376","0.00748"
"92.62800","7.71919","0.00720"
"92.81400","7.73473","0.00717"
"93.00000","7.75022","0.00709"
"93.18600","7.76576","0.00728"
"93.37200","7.78119","0.00715"
"93.55800","7.79667","0.00693"
"93.74400","7.81222","0.00720"
"93.93000","7.82771","0.00720"
"94.11600","7.84319","0.00751"
"94.30200","7.85868","0.00730"
"94.48800","7.87422","0.00730"
"94.67400","7.88971","0.00779"
"94.86000","7.90519","0.00738"
"95.04600","7.92074","0.00752"
"95.23200","7.93622","0.00734"
"95.41800","7.95171","0.00746"
"95.60400","7.96725","0.00768"
"95.79000","7.98274","0.00745"
"95.97600","7.99823","0.00789"
"96.16200","8.01377","0.00783"
"96.34800","8.02914","0.00761"
"96.53400","8.04474","0.00764"
"96.72000","8.06023","0.00754"
"96.90600","8.07571","0.00755"
"97.09200","8.09126","0.00730"
"97.27800","8.10674","0.00790"
"97.46400","8.12217","0.00752"
"97.65000","8.13777","0.00728"
"97.83600","8.15320","0.00705"
"98.02200","8.16868","0.00773"
"98.20800","8.18429","0.00788"
"98.39400","8.19972","0.00760"
"98.58000","8.21514","0.00746"
"98.76600","8.23075","0.00760"
"98.95200","8.24623","0.00752"
"99.13800","8.26172","0.00775"
"99.32400","8.27726","0.00723"
"99.51000","8.29275","0.00782"
"99.69600","8.30817","0.00819"
"99.88200","8.32372","0.00792"
"100.06800","8.33920","0.00745"
"100.25400","8.35469","0.00755"
"100.44000","8.37024","0.00781"
"100.62600","8.38572","0.00753"
"100.81200","8.40121","0.00734"
"100.99800","8.41669","0.00767"
"101.18400","8.43224","0.00757"
"101.37000","8.44772","0.00760"
"101.55600","8.46321","0.00787"
"101.74200","8.47869","0.00739"
"101.92800","8.49424","0.00777"
"102.11400","8.50978","0.00754"
"102.30000","8.52515","0.00786"
"102.48600","8.54076","0.00782"
"102.67200","8.55624","0.00779"
"102.85800","8.57167","0.00757"
"103.04400","8.58721","0.00740"
"103.23000","8.60276","0.00796"
"103.41600","8.61824","0.00756"
"103.60200","8.63373","0.00782"
"103.78800","8.64927","0.00762"
"103.97400","8.66464","0.00797"
"104.16000","8.68018","0.00800"
"104.34600","8.69573","0.00750"
"104.53200","8.71122","0.00764"
"104.71800","8.72670","0.00767"
"104.90400","8.74219","0.00805"
"105.09000","8.75773","0.00809"
"105.27600","8.77322","0.00800"
"105.46200","8.78870","0.00747"
"105.64800","8.80425","0.00780"
"105.83400","8.81973","0.00809"
"106.02000","8.83516","0.00786"
"106.20600","8.85070","0.00818"
"106.39200","8.86625","0.00831"
"106.57800","8.88173","0.00748"
"106.76400","8.89722","0.00794"
"106.95000","8.91271","0.00825"
"107.13600","8.92819","0.00754"
"107.32200","8.94368","0.00812"
"107.50800","8.95928","0.00781"
"107.69400","8.97465","0.00788"
"107.88000","8.99025","0.00788"
"108.06600","9.00574","0.00784"
"108.25200","9.02116","0.00819"
"108.43800","9.03671","0.00802"
"108.62400","9.05219","0.00844"
"108.81000","9.06768","0.00801"
"108.99600","9.08323","0.00831"
"109.18200","9.09865","0.00765"
"109.36800","9.11420","0.00787"
"109.55400","9.12974","0.00801"
"109.74000","9.14523","0.00755"
"109.92600","9.16071","0.00809"
"110.11200","9.17626","0.00783"
"110.29800","9.19174","0.00786"
"110.48400","9.20723","0.00824"
"110.67000","9.22277","0.00777"
"110.85600","9.23820","0.00768"
"111.04200","9.25375","0.00809"
"111.22800","9.26923","0.00818"
"111.41400","9.28472","0.00813"
"111.60000","9.30020","0.00803"
"111.78600","9.31575","0.00749"
"111.97200","9.33117","0.00731"
"112.15800","9.34672","0.00762"
"112.34400","9.36226","0.00759"
"112.53000","9.37769","0.00766"
"112.71600","9.39329","0.00777"
"112.90200","9.40872","0.00730"
"113.08800","9.42421","0.00722"
"113.27400","9.43981","0.00761"
"113.46000","9.45524","0.00765"
"113.64600","9.47066","0.00737"
"113.83200","9.48633","0.00693"
"114.01800","9.50169","0.00799"
"114.20400","9.51718","0.00791"
"114.39000","9.53278","0.00790"
"114.57600","9.54827","0.00776"
"114.76200","9.56369","0.00732"
"114.94800","9.57924","0.00829"
"115.13400","9.59473","0.00764"
"115.32000","9.61015","0.00781"
"115.50600","9.62570","0.00779"
"115.69200","9.64118","0.00780"
"115.87800","9.65673","0.00757"
"116.06400","9.67227","0.00813"
"116.25000","9.68770","0.00782"
"116.43600","9.70324","0.00787"
"116.62200","9.71873","0.00788"
"116.80800","9.73421","0.00792"
"116.99400","9.74976","0.00817"
"117.18000","9.76525","0.00811"
"117.36600","9.78067","0.00803"
"117.55200","9.79628","0.00793"
"117.73800","9.81176","0.00790"
"117.92400","9.82719","0.00801"
"118.11000","9.84273","0.00803"
"118.29600","9.85828","0.00781"
"118.48200","9.87370","0.00715"
"118.66800","9.88925","0.00822"
"118.85400","9.90473","0.00797"
"119.04000","9.92022","0.00801"
"119.22600","9.93570","0.00785"
"119.41200","9.95125","0.00760"
"119.59800","9.96667","0.00764"
"119.78400","9.98222","0.00755"
"119.97000","9.99765","0.00769"
"120.15600","10.01319","0.00763"
"120.34200","10.02874","0.00753"
"120.52800","10.04422","0.00766"
"120.71400","10.05977","0.00773"
"120.90000","10.07525","0.00768"
"121.08600","10.09062","0.00783"
"121.27200","10.10629","0.00775"
"121.45800","10.12177","0.00802"
"121.64400","10.13720","0.00757"
"121.83000","10.15274","0.00719"
"122.01600","10.16823","0.00784"
"122.20200","10.18365","0.00780"
"122.38800","10.19926","0.00720"
"122.57400","10.21474","0.00798"
"122.76000","10.23017","0.00791"
"122.94600","10.24577","0.00824"
"123.13200","10.26126","0.00806"
"123.31800","10.27668","0.00814"
"123.50400","10.29223","0.00795"
"123.69000","10.30772","0.00813"
"123.87600","10.32314","0.00833"
"124.06200","10.33869","0.00783"
"124.24800","10.35417","0.00789"
"124.43400","10.36972","0.00840"
"124.62000","10.38526","0.00786"
"124.80600","10.40069","0.00831"
"124.99200","10.41617","0.00790"
"125.17800","10.43178","0.00791"
"125.36400","10.44720","0.00840"
"125.55000","10.46269","0.00798"
"125.73600","10.47830","0.00804"
"125.92200","10.49366","0.00806"
"126.10800","10.50921","0.00773"
"126.29400","10.52475","0.00803"
"126.48000","10.54018","0.00855"
"126.66600","10.55572","0.00816"
"126.85200","10.57121","0.00837"
"127.03800","10.58675","0.00805"
"127.22400","10.60224","0.00847"
"127.41000","10.61778","0.00827"
"127.59600","10.63321","0.00775"
"127.78200","10.64876","0.00796"
"127.96800","10.66424","0.00826"
"128.15400","10.67967","0.00835"
"128.34000","10.69527","0.00868"
"128.52600","10.71070","0.00823"
"128.71200","10.72618","0.00797"
"128.89800","10.74173","0.00832"
"129.08400","10.75721","0.00816"
"129.27000","10.77264","0.00855"
"129.45600","10.78824","0.00841"
"129.64200","10.80373","0.00855"
"129.82800","10.81922","0.00861"
"130.01400","10.83470","0.00824"
"130.20000","10.85025","0.00847"
"130.38600","10.86573","0.00806"
"130.57200","10.88122","0.00811"
"130.75800","10.89670","0.00833"
"130.94400","10.91225","0.00811"
"131.13000","10.92779","0.00880"
"131.31600","10.94322","0.00840"
"131.50200","10.95870","0.00834"
"131.68800","10.97425","0.00843"
"131.87400","10.98968","0.00819"
"132.06000","11.00528","0.00823"
"132.24600","11.02071","0.00844"
"132.43200","11.03619","0.00826"
"132.61800","11.05174","0.00855"
"132.80400","11.06722","0.00895"
"132.99000","11.08265","0.00831"
"133.17600","11.09819","0.00775"
"133.36200","11.11380","0.00861"
"133.54800","11.12916","0.00854"
"133.73400","11.14471","0.00886"
"133.92000","11.16025","0.00851"
"134.10600","11.17568","0.00834"
"134.29200","11.19123","0.00907"
"134.47800","11.20677","0.00899"
"134.66400","11.22220","0.00886"
"134.85000","11.23768","0.00874"
"135.03600","11.25323","0.00918"
"135.22200","11.26871","0.00862"
"135.40800","11.28426","0.00889"
"135.59400","11.29974","0.00899"
"135.78000","11.31523","0.00894"
"135.96600","11.33071","0.00864"
"136.15200","11.34620","0.00917"
"136.33800","11.36174","0.00872"
"136.52400","11.37729","0.00893"
"136.71000","11.39272","0.00893"
"136.89600","11.40820","0.00879"
"137.08200","11.42375","0.00889"
"137.26800","11.43917","0.00954"
"137.45400","11.45472","0.00892"
"137.64000","11.47026","0.00929"
"137.82600","11.48569","0.00879"
"138.01200","11.50123","0.00950"
"138.19800","11.51678","0.00894"
"138.38400","11.53221","0.00895"
"138.57000","11.54775","0.00887"
"138.75600","11.56324","0.00877"
"138.94200","11.57866","0.00890"
"139.12800","11.59427","0.00923"
"139.31400","11.60975","0.00873"
"139.50000","11.62518","0.00916"
"139.68600","11.64072","0.00920"
"139.87200","11.65621","0.00960"
"140.05800","11.67169","0.00978"
"140.24400","11.68724","0.00981"
"140.43000","11.70273","0.00867"
"140.61600","11.71821","0.00941"
"140.80200","11.73382","0.00921"
"140.98800","11.74924","0.00922"
"141.17400","11.76473","0.00951"
"141.36000","11.78027","0.00899"
"141.54600","11.79564","0.00921"
"141.73200","11.81118","0.00964"
"141.91800","11.82679","0.00918"
"142.10400","11.84221","0.00903"
"142.29000","11.85770","0.00945"
"142.47600","11.87325","0.00949"
"142.66200","11.88873","0.00922"
"142.84800","11.90422","0.01004"
"143.03400","11.91976","0.00936"
"143.22000","11.93519","0.00919"
"143.40600","11.95073","0.00936"
"143.59200","11.96622","0.00878"
"143.77800","11.98164","0.00921"
"143.96400","11.99731","0.00911"
"144.15000","12.01273","0.00930"
"144.33600","12.02822","0.00906"
"144.52200","12.04377","0.00940"
"144.70800","12.05925","0.00950"
"144.89400","12.07468","0.00909"
"145.08000","12.09016","0.00920"
"145.26600","12.10571","0.00924"
"145.45200","12.12119","0.00935"
"145.63800","12.13668","0.00957"
"145.82400","12.15222","0.00961"
"146.01000","12.16771","0.00946"
"146.19600","12.18319","0.00989"
"146.38200","12.19874","0.00918"
"146.56800","12.21422","0.01010"
"146.75400","12.22977","0.00974"
"146.94000","12.24520","0.00983"
"147.12600","12.26074","0.00976"
"147.31200","12.27629","0.00950"
"147.49800","12.29165","0.00962"
"147.68400","12.30732","0.00921"
"147.87000","12.32268","0.00961"
"148.05600","12.33817","0.00961"
"148.24200","12.35377","0.00970"
"148.42800","12.36926","0.00956"
"148.61400","12.38468","0.00980"
"148.80000","12.40023","0.00987"
"148.98600","12.41577","0.00978"
"149.17200","12.43114","0.01039"
"149.35800","12.44674","0.01014"
"149.54400","12.46223","0.01037"
"149.73000","12.47772","0.00993"
"149.91600","12.49320","0.01002"
"150.10200","12.50869","0.00942"
"150.28800","12.52423","0.00987"
"150.47400","12.53972","0.00942"
"150.66000","12.55520","0.00918"
"150.84600","12.57075","0.00911"
"151.03200","12.58623","0.00995"
"151.21800","12.60172","0.00963"
"151.40400","12.61721","0.00917"
"151.59000","12.63275","0.00881"
"151.77600","12.64824","0.00938"
"151.96200","12.66372","0.00943"
"152.14800","12.67921","0.00941"
"152.33400","12.69469","0.00932"
"152.52000","12.71024","0.00963"
"152.70600","12.72572","0.00941"
"152.89200","12.74121","0.00955"
"153.07800","12.75669","0.00975"
"153.26400","12.77224","0.00928"
"153.45000","12.78772","0.00878"
"153.63600","12.80327","0.00945"
"153.82200","12.81870","0.00883"
"154.00800","12.83424","0.00926"
"154.19400","12.84979","0.00939"
"154.38000","12.86521","0.00926"
"154.56600","12.88070","0.00942"
"154.75200","12.89624","0.00944"
"154.93800","12.91167","0.00930"
"155.12400","12.92721","0.00923"
"155.31000","12.94276","0.00931"
"155.49600","12.95819","0.00897"
"155.68200","12.97373","0.00876"
"155.86800","12.98922","0.00900"
"156.05400","13.00470","0.00894"
"156.24000","13.02025","0.00895"
"156.42600","13.03573","0.00892"
"156.61200","13.05122","0.00915"
"156.79800","13.06670","0.00905"
"156.98400","13.08225","0.00920"
"157.17000","13.09767","0.00902"
"157.35600","13.11328","0.00900"
"157.54200","13.12871","0.00892"
"157.72800","13.14419","0.00884"
"157.91400","13.15974","0.00870"
"158.10000","13.17522","0.00854"
"158.28600","13.19065","0.00910"
"158.47200","13.20625","0.00893"
"158.65800","13.22168","0.00892"
"158.84400","13.23716","0.00881"
"159.03000","13.25277","0.00871"
"159.21600","13.26825","0.00851"
"159.40200","13.28362","0.00899"
"159.58800","13.29923","0.00896"
"159.77400","13.31471","0.00927"
"159.96000","13.33026","0.00884"
"160.14600","13.34574","0.00877"
"160.33200","13.36123","0.00930"
"160.51800","13.37671","0.00956"
"160.70400","13.39220","0.00910"
"160.89000","13.40774","0.00983"
"161.07600","13.42317","0.00932"
"161.26200","13.43871","0.00991"
"161.44800","13.45426","0.00984"
"161.63400","13.46975","0.00978"
"161.82000","13.48523","0.01027"
"162.00600","13.50072","0.01014"
"162.19200","13.51620","0.01019"
"162.37800","13.53175","0.01035"
"162.56400","13.54717","0.01050"
"162.75000","13.56278","0.01042"
"162.93600","13.57820","0.01049"
"163.12200","13.59369","0.01055"
"163.30800","13.60923","0.01045"
"163.49400","13.62472","0.01102"
"163.68000","13.64021","0.01093"
"163.86600","13.65575","0.01115"
"164.05200","13.67124","0.01100"
"164.23800","13.68672","0.01115"
"164.42400","13.70221","0.01160"
"164.61000","13.71775","0.01144"
"164.79600","13.73324","0.01165"
"164.98200","13.74872","0.01163"
"165.16800","13.76421","0.01221"
"165.35400","13.77969","0.01203"
"165.54000","13.79524","0.01193"
"165.72600","13.81067","0.01221"
"165.91200","13.82627","0.01281"
"166.09800","13.84181","0.01187"
"166.28400","13.85718","0.01235"
"166.47000","13.87273","0.01329"
"166.65600","13.88827","0.01290"
"166.84200","13.90370","0.01297"
"167.02800","13.91918","0.01301"
"167.21400","13.93473","0.01400"
"167.40000","13.95021","0.01411"
"167.58600","13.96576","0.01395"
"167.77200","13.98124","0.01455"
"167.95800","13.99667","0.01399"
"168.14400","14.01221","0.01432"
"168.33000","14.02776","0.01476"
"168.51600","14.04319","0.01540"
"168.70200","14.05873","0.01522"
"168.88800","14.07422","0.01486"
"169.07400","14.08970","0.01607"
"169.26000","14.10525","0.01652"
"169.44600","14.12073","0.01714"
"169.63200","14.13622","0.01604"
"169.81800","14.15176","0.01642"
"170.00400","14.16719","0.01684"
"170.19000","14.18267","0.01699"
"170.37600","14.19822","0.01721"
"170.56200","14.21365","0.01813"
"170.74800","14.22919","0.01874"
"170.93400","14.24474","0.01916"
"171.12000","14.26016","0.01912"
"171.30600","14.27571","0.01957"
"171.49200","14.29119","0.02025"
"171.67800","14.30668","0.02011"
"171.86400","14.32222","0.02125"
"172.05000","14.33771","0.02183"
"172.23600","14.35320","0.02255"
"172.42200","14.36874","0.02257"
"172.60800","14.38429","0.02379"
"172.79400","14.39965","0.02323"
"172.98000","14.41520","0.02479"
"173.16600","14.43074","0.02533"
"173.35200","14.44617","0.02697"
"173.53800","14.46177","0.02572"
"173.72400","14.47720","0.02782"
"173.91000","14.49268","0.02837"
"174.09600","14.50829","0.02963"
"174.28200","14.52372","0.03005"
"174.46800","14.53914","0.03074"
"174.65400","14.55475","0.03184"
"174.84000","14.57023","0.03240"
"175.02600","14.58566","0.03408"
"175.21200","14.60126","0.03425"
"175.39800","14.61669","0.03513"
"175.58400","14.63223","0.02059"
"175.77000","14.64772","0.01703"
"175.95600","14.66320","0.01874"
"176.14200","14.67869","0.01444"
"176.32800","14.69423","0.01499"
"176.51400","14.70972","0.01529"
"176.70000","14.72521","0.01601"
"176.88600","14.74075","0.01653"
"177.07200","14.75618","0.01570"
"177.25800","14.77172","0.01803"
"177.44400","14.78727","0.01784"
"177.63000","14.80269","0.01840"
"177.81600","14.81824","0.01864"
"178.00200","14.83378","0.02034"
"178.18800","14.84915","0.02024"
"178.37400","14.86475","0.02027"
"178.56000","14.88030","0.02214"
"178.74600","14.89567","0.02372"
"178.93200","14.91127","0.02417"
"179.11800","14.92670","0.02224"
"179.30400","14.94224","0.02510"
"179.49000","14.95773","0.02558"
"179.67600","14.97327","0.02403"
"179.86200","14.98870","0.02567"
"180.04800","15.00424","0.02772"
"180.23400","15.01967","0.02846"
"180.42000","15.03521","0.02808"
"180.60600","15.05076","0.02978"
"180.79200","15.06619","0.03193"
"180.97800","15.08173","0.03220"
"181.16400","15.09722","0.03120"
"181.35000","15.11270","0.03366"
"181.53600","15.12825","0.03466"
"181.72200","15.14379","0.03450"
"181.90800","15.15922","0.03605"
"182.09400","15.17470","0.03749"
"182.28000","15.19025","0.03770"
"182.46600","15.20568","0.03841"
"182.65200","15.22122","0.03924"
"182.83800","15.23676","0.04074"
"183.02400","15.25219","0.04111"
"183.21000","15.26774","0.04290"
"183.39600","15.28316","0.04378"
"183.58200","15.29865","0.04483"
"183.76800","15.31425","0.04513"
"183.95400","15.32974","0.04587"
"184.14000","15.34522","0.04762"
"184.32600","15.36077","0.04721"
"184.51200","15.37626","0.04858"
"184.69800","15.39168","0.05002"
"184.88400","15.40722","0.05019"
"185.07000","15.42271","0.05062"
"185.25600","15.43820","0.05288"
"185.44200","15.45374","0.05357"
"185.62800","15.46923","0.05359"
"185.81400","15.48465","0.05505"
"186.00000","15.50026","0.05624"
"186.18600","15.51568","0.05640"
"186.37200","15.53123","0.05739"
"186.55800","15.54671","0.05826"
"186.74400","15.56226","0.05611"
"186.93000","15.57774","0.03266"
"187.11600","15.59323","0.00772"
"187.30200","15.60878","0.00623"
"187.48800","15.62420","0.00564"
"187.67400","15.63968","0.00593"
"187.86000","15.65523","0.00547"
"188.04600","15.67072","0.00631"
"188.23200","15.68626","0.00727"
"188.41800","15.70163","0.00812"
"188.60400","15.71723","0.00625"
"188.79000","15.73272","0.00654"
"188.97600","15.74814","0.00686"
"189.16200","15.76381","0.00687"
"189.34800","15.77917","0.00711"
"189.53400","15.79466","0.00672"
"189.72000","15.81027","0.00728"
"189.90600","15.82575","0.00668"
"190.09200","15.84118","0.00711"
"190.27800","15.85672","0.00756"
"190.46400","15.87221","0.00675"
"190.65000","15.88775","0.00639"
"190.83600","15.90324","0.00672"
"191.02200","15.91872","0.00677"
"191.20800","15.93427","0.00696"
"191.39400","15.94969","0.00702"
"191.58000","15.96518","0.00741"
"191.76600","15.98073","0.00723"
"191.95200","15.99627","0.00723"
"192.13800","16.01170","0.00722"
"192.32400","16.02724","0.00717"
"192.51000","16.04273","0.00710"
"192.69600","16.05821","0.00751"
"192.88200","16.07370","0.00791"
"193.06800","16.08924","0.00663"
"193.25400","16.10467","0.00800"
"193.44000","16.12021","0.00771"
"193.62600","16.13576","0.00762"
"193.81200","16.15113","0.00763"
"193.99800","16.16673","0.00816"
"194.18400","16.18228","0.00715"
"194.37000","16.19770","0.00796"
"194.55600","16.21319","0.00805"
"194.74200","16.22873","0.00792"
"194.92800","16.24422","0.00849"
"195.11400","16.25970","0.00785"
"195.30000","16.27519","0.00822"
"195.48600","16.29073","0.00880"
"195.67200","16.30622","0.00860"
"195.85800","16.32170","0.00881"
"196.04400","16.33719","0.00848"
"196.23000","16.35268","0.00810"
"196.41600","16.36822","0.00929"
"196.60200","16.38371","0.00888"
"196.78800","16.39925","0.00895"
"196.97400","16.41474","0.00974"
"197.16000","16.43022","0.00935"
"197.34600","16.44577","0.00963"
"197.53200","16.46119","0.00981"
"197.71800","16.47674","0.00966"
"197.90400","16.49228","0.01021"
"198.09000","16.50771","0.00996"
"198.27600","16.52325","0.00978"
"198.46200","16.53874","0.01016"
"198.64800","16.55423","0.01040"
"198.83400","16.56977","0.00919"
"199.02000","16.58520","0.00849"
"199.20600","16.60074","0.00822"
"199.39200","16.61623","0.00859"
"199.57800","16.63171","0.00853"
"199.76400","16.64720","0.00837"
"199.95000","16.66274","0.00908"
"200.13600","16.67823","0.00867"
"200.32200","16.69371","0.00949"
"200.50800","16.70926","0.00957"
"200.69400","16.72469","0.00887"
"200.88000","16.74017","0.00906"
"201.06600","16.75572","0.00959"
"201.25200","16.77120","0.00974"
"201.43800","16.78669","0.01007"
"201.62400","16.80223","0.00928"
"201.81000","16.81772","0.00886"
"201.99600","16.83320","0.00891"
"202.18200","16.84875","0.00892"
"202.36800","16.86423","0.00900"
"202.55400","16.87972","0.00893"
"202.74000","16.89521","0.00887"
"202.92600","16.91069","0.00918"
"203.11200","16.92624","0.00904"
"203.29800","16.94172","0.00938"
"203.48400","16.95715","0.00898"
"203.67000","16.97269","0.00958"
"203.85600","16.98824","0.00933"
"204.04200","17.00360","0.00956"
"204.22800","17.01933","0.00964"
"204.41400","17.03476","0.01005"
"204.60000","17.05018","0.01011"
"204.78600","17.06579","0.00960"
"204.97200","17.08121","0.00994"
"205.15800","17.09670","0.00963"
"205.34400","17.11224","0.01043"
"205.53000","17.12779","0.01057"
"205.71600","17.14321","0.01071"
"205.90200","17.15870","0.01113"
"206.08800","17.17424","0.01105"
"206.27400","17.18973","0.01067"
"206.46000","17.20522","0.01165"
"206.64600","17.22070","0.01089"
"206.83200","17.23625","0.01125"
"207.01800","17.25173","0.01166"
"207.20400","17.26716","0.01147"
"207.39000","17.28276","0.01160"
"207.57600","17.29825","0.01180"
"207.76200","17.31373","0.01231"
"207.94800","17.32928","0.01249"
"208.13400","17.34470","0.01224"
"208.32000","17.36013","0.01222"
"208.50600","17.37574","0.01318"
"208.69200","17.39128","0.01267"
"208.87800","17.40665","0.01332"
"209.06400","17.42225","0.01340"
"209.25000","17.43774","0.01337"
"209.43600","17.45316","0.01378"
"209.62200","17.46871","0.01427"
"209.80800","17.48425","0.01464"
"209.99400","17.49974","0.01445"
"210.18000","17.51522","0.01486"
"210.36600","17.53071","0.01480"
"210.55200","17.54626","0.01520"
"210.73800","17.56174","0.01565"
"210.92400","17.57722","0.01563"
"211.11000","17.59271","0.01626"
"211.29600","17.60826","0.01699"
"211.48200","17.62374","0.01696"
"211.66800","17.63923","0.01798"
"211.85400","17.65477","0.01849"
"212.04000","17.67020","0.01841"
"212.22600","17.68574","0.01875"
"212.41200","17.70129","0.01928"
"212.59800","17.71666","0.01979"
"212.78400","17.73226","0.02042"
"212.97000","17.74775","0.02100"
"213.15600","17.76317","0.02172"
"213.34200","17.77872","0.02220"
"213.52800","17.79420","0.02258"
"213.71400","17.80969","0.02321"
"213.90000","17.82529","0.02398"
"214.08600","17.84072","0.02479"
"214.27200","17.85620","0.02475"
"214.45800","17.87175","0.02612"
"214.64400","17.88717","0.02690"
"214.83000","17.90272","0.02750"
"215.01600","17.91821","0.02787"
"215.20200","17.93369","0.02940"
"215.38800","17.94918","0.03092"
"215.57400","17.96472","0.03192"
"215.76000","17.98015","0.03259"
"215.94600","17.99569","0.03326"
"216.13200","18.01124","0.03351"
"216.31800","18.02672","0.03053"
"216.50400","18.04221","0.00642"
"216.69000","18.05770","0.00546"
"216.87600","18.07318","0.00555"
"217.06200","18.08872","0.00706"
"217.24800","18.10427","0.00678"
"217.43400","18.11976","0.00659"
"217.62000","18.13524","0.00657"
"217.80600","18.15073","0.00689"
"217.99200","18.16621","0.00780"
"218.17800","18.18176","0.00712"
"218.36400","18.19724","0.00647"
"218.55000","18.21267","0.00719"
"218.73600","18.22827","0.00739"
"218.92200","18.24376","0.00722"
"219.10800","18.25918","0.00754"
"219.29400","18.27473","0.00788"
"219.48000","18.29028","0.00830"
"219.66600","18.30564","0.00791"
"219.85200","18.32125","0.00791"
"220.03800","18.33673","0.00811"
"220.22400","18.35222","0.00787"
"220.41000","18.36770","0.00842"
"220.59600","18.38325","0.00904"
"220.78200","18.39873","0.00851"
"220.96800","18.41422","0.00896"
"221.15400","18.42971","0.00935"
"221.34000","18.44519","0.00873"
"221.52600","18.46068","0.01016"
"221.71200","18.47622","0.00980"
"221.89800","18.49177","0.00983"
"222.08400","18.50719","0.00917"
"222.27000","18.52268","0.01014"
"222.45600","18.53828","0.01029"
"222.64200","18.55377","0.01012"
"222.82800","18.56919","0.01031"
"223.01400","18.58474","0.01010"
"223.20000","18.60023","0.01024"
"223.38600","18.61571","0.01011"
"223.57200","18.63126","0.01015"
"223.75800","18.64674","0.01099"
"223.94400","18.66223","0.01130"
"224.13000","18.67771","0.01122"
"224.31600","18.69326","0.01138"
"224.50200","18.70868","0.01170"
"224.68800","18.72429","0.01195"
"224.87400","18.73977","0.01205"
"225.06000","18.75526","0.01202"
"225.24600","18.77074","0.01237"
"225.43200","18.78617","0.01236"
"225.61800","18.80172","0.01274"
"225.80400","18.81720","0.01286"
"225.99000","18.83269","0.01297"
"226.17600","18.84823","0.01269"
"226.36200","18.86372","0.01333"
"226.54800","18.87920","0.01367"
"226.73400","18.89475","0.01391"
"226.92000","18.91023","0.01447"
"227.10600","18.92572","0.01444"
"227.29200","18.94120","0.01500"
"227.47800","18.95675","0.01551"
"227.66400","18.97218","0.01510"
"227.85000","18.98772","0.01497"
"228.03600","19.00327","0.01569"
"228.22200","19.01869","0.01607"
"228.40800","19.03424","0.01590"
"228.59400","19.04972","0.01593"
"228.78000","19.06521","0.01719"
"228.96600","19.08075","0.01708"
"229.15200","19.09624","0.01687"
"229.33800","19.11167","0.01498"
"229.52400","19.12727","0.01464"
"229.71000","19.14275","0.01606"
"229.89600","19.15818","0.01660"
"230.08200","19.17373","0.01651"
"230.26800","19.18921","0.01721"
"230.45400","19.20470","0.01779"
"230.64000","19.22030","0.01897"
"230.82600","19.23573","0.01973"
"231.01200","19.25121","0.01949"
"231.19800","19.26676","0.01936"
"231.38400","19.28218","0.01985"
"231.57000","19.29773","0.02011"
"231.75600","19.31322","0.02152"
"231.94200","19.32870","0.02310"
"232.12800","19.34425","0.02345"
"232.31400","19.35973","0.02431"
"232.50000","19.37522","0.02546"
"232.68600","19.39070","0.02558"
"232.87200","19.40625","0.02807"
"233.05800","19.42167","0.02763"
"233.24400","19.43728","0.02910"
"233.43000","19.45276","0.02949"
"233.61600","19.46819","0.03071"
"233.80200","19.48380","0.03115"
"233.98800","19.49922","0.03139"
"234.17400","19.51465","0.03263"
"234.36000","19.53025","0.03297"
"234.54600","19.54573","0.03360"
"234.73200","19.56110","0.03452"
"234.91800","19.57677","0.03609"
"235.10400","19.59225","0.03696"
"235.29000","19.60768","0.01498"
"235.47600","19.62322","0.01629"
"235.66200","19.63871","0.01834"
"235.84800","19.65420","0.01686"
"236.03400","19.66974","0.01692"
"236.22000","19.68523","0.01805"
"236.40600","19.70071","0.01904"
"236.59200","19.71626","0.01950"
"236.77800","19.73174","0.01861"
"236.96400","19.74722","0.02085"
"237.15000","19.76277","0.02153"
"237.33600","19.77820","0.02337"
"237.52200","19.79374","0.02287"
"237.70800","19.80929","0.02464"
"237.89400","19.82471","0.02373"
"238.08000","19.84026","0.02553"
"238.26600","19.85580","0.02645"
"238.45200","19.87117","0.02864"
"238.63800","19.88672","0.02848"
"238.82400","19.90226","0.02870"
"239.01000","19.91763","0.02871"
"239.19600","19.93323","0.03092"
"239.38200","19.94872","0.03268"
"239.56800","19.96420","0.03140"
"239.75400","19.97975","0.03253"
"239.94000","19.99524","0.03382"
"240.12600","20.01072","0.03573"
"240.31200","20.02626","0.03498"
"240.49800","20.04169","0.03593"
"240.68400","20.05724","0.03714"
"240.87000","20.07272","0.03866"
"241.05600","20.08821","0.03821"
"241.24200","20.10375","0.03904"
"241.42800","20.11924","0.04017"
"241.61400","20.13472","0.03959"
"241.80000","20.15021","0.03978"
"241.98600","20.16570","0.02308"
"242.17200","20.18118","0.00928"
"242.35800","20.19672","0.00775"
"242.54400","20.21227","0.00873"
"242.73000","20.22764","0.00613"
"242.91600","20.24324","0.00588"
"243.10200","20.25879","0.00609"
"243.28800","20.27415","0.00781"
"243.47400","20.28976","0.00815"
"243.66000","20.30524","0.00641"
"243.84600","20.32067","0.00650"
"244.03200","20.33627","0.00571"
"244.21800","20.35170","0.00841"
"244.40400","20.36724","0.00768"
"244.59000","20.38273","0.00645"
"244.77600","20.39822","0.00652"
"244.96200","20.41370","0.00734"
"245.14800","20.42925","0.00844"
"245.33400","20.44473","0.00681"
"245.52000","20.46016","0.00667"
"245.70600","20.47576","0.00661"
"245.89200","20.49125","0.00751"
"246.07800","20.50667","0.00804"
"246.26400","20.52228","0.00643"
"246.45000","20.53776","0.00665"
"246.63600","20.55319","0.00787"
"246.82200","20.56874","0.00797"
"247.00800","20.58422","0.00667"
"247.19400","20.59970","0.00673"
"247.38000","20.61525","0.00790"
"247.56600","20.63068","0.00750"
"247.75200","20.64622","0.00747"
"247.93800","20.66171","0.00772"
"248.12400","20.67719","0.00744"
"248.31000","20.69274","0.00801"
"248.49600","20.70822","0.00764"
"248.68200","20.72371","0.00785"
"248.86800","20.73925","0.00802"
"249.05400","20.75474","0.00839"
"249.24000","20.77017","0.00749"
"249.42600","20.78577","0.00771"
"249.61200","20.80120","0.00924"
"249.79800","20.81668","0.00817"
"249.98400","20.83223","0.00826"
"250.17000","20.84771","0.00895"
"250.35600","20.86320","0.00755"
"250.54200","20.87875","0.00812"
"250.72800","20.89429","0.00891"
"250.91400","20.90972","0.00827"
"251.10000","20.92520","0.00820"
"251.28600","20.94069","0.00928"
"251.47200","20.95623","0.00826"
"251.65800","20.97172","0.00799"
"251.84400","20.98720","0.00947"
"252.03000","21.00275","0.00849"
"252.21600","21.01829","0.00888"
"252.40200","21.03366","0.00951"
"252.58800","21.04921","0.00899"
"252.77400","21.06475","0.00905"
"252.96000","21.08023","0.00961"
"253.14600","21.09572","0.00860"
"253.33200","21.11127","0.00927"
"253.51800","21.12663","0.00972"
"253.70400","21.14223","0.00775"
"253.89000","21.15778","0.00978"
"254.07600","21.17315","0.01010"
"254.26200","21.18875","0.00804"
"254.44800","21.20424","0.01170"
"254.63400","21.21967","0.00922"
"254.82000","21.23521","0.00761"
"255.00600","21.25075","0.01255"
"255.19200","21.26618","0.00969"
"255.37800","21.28167","0.00785"
"255.56400","21.29721","0.01290"
"255.75000","21.31276","0.00956"
"255.93600","21.32824","0.00959"
"256.12200","21.34373","0.01192"
"256.30800","21.35921","0.00927"
"256.49400","21.37476","0.01108"
"256.68000","21.39024","0.01189"
"256.86600","21.40573","0.01017"
"257.05200","21.42121","0.01214"
"257.23800","21.43670","0.01051"
"257.42400","21.45224","0.01055"
"257.61000","21.46773","0.01373"
"257.79600","21.48322","0.00968"
"257.98200","21.49870","0.01233"
"258.16800","21.51425","0.01236"
"258.35400","21.52973","0.01055"
"258.54000","21.54522","0.01331"
"258.72600","21.56076","0.01154"
"258.91200","21.57625","0.01228"
"259.09800","21.59173","0.01340"
"259.28400","21.60722","0.01131"
"259.47000","21.62270","0.01411"
"259.65600","21.63825","0.01266"
"259.84200","21.65368","0.01218"
"260.02800","21.66916","0.01387"
"260.21400","21.68471","0.01221"
"260.40000","21.70025","0.01460"
"260.58600","21.71568","0.01309"
"260.77200","21.73122","0.01370"
"260.95800","21.74677","0.01469"
"261.14400","21.76219","0.01378"
"261.33000","21.77780","0.01514"
"261.51600","21.79323","0.01525"
"261.70200","21.80871","0.01477"
"261.88800","21.82425","0.01613"
"262.07400","21.83968","0.01481"
"262.26000","21.85517","0.01649"
"262.44600","21.87071","0.01541"
"262.63200","21.88620","0.01573"
"262.81800","21.90174","0.01629"
"263.00400","21.91723","0.01600"
"263.19000","21.93271","0.01726"
"263.37600","21.94826","0.01625"
"263.56200","21.96375","0.01773"
"263.74800","21.97917","0.01854"
"263.93400","21.99471","0.01884"
"264.12000","22.01026","0.01932"
"264.30600","22.02569","0.01812"
"264.49200","22.04123","0.01987"
"264.67800","22.05672","0.01920"
"264.86400","22.07214","0.02003"
"265.05000","22.08775","0.02055"
"265.23600","22.10324","0.02097"
"265.42200","22.11872","0.02195"
"265.60800","22.13426","0.02198"
"265.79400","22.14975","0.02325"
"265.98000","22.16518","0.02288"
"266.16600","22.18072","0.02472"
"266.35200","22.19621","0.02368"
"266.53800","22.21175","0.02544"
"266.72400","22.22718","0.02586"
"266.91000","22.24266","0.02636"
"267.09600","22.25821","0.02757"
"267.28200","22.27369","0.02724"
"267.46800","22.28918","0.02873"
"267.65400","22.30478","0.02886"
"267.84000","22.32027","0.03014"
"268.02600","22.33570","0.03032"
"268.21200","22.35124","0.03211"
"268.39800","22.36673","0.03187"
"268.58400","22.38215","0.03367"
"268.77000","22.39776","0.03349"
"268.95600","22.41330","0.03570"
"269.14200","22.42867","0.03560"
"269.32800","22.44427","0.03638"
"269.51400","22.45976","0.03712"
"269.70000","22.47518","0.03819"
"269.88600","22.49079","0.03864"
"270.07200","22.50621","0.03984"
"270.25800","22.52170","0.04026"
"270.44400","22.53724","0.04192"
"270.63000","22.55267","0.04232"
"270.81600","22.56822","0.04287"
"271.00200","22.58370","0.04366"
"271.18800","22.59919","0.04555"
"271.37400","22.61473","0.04536"
"271.56000","22.63022","0.04684"
"271.74600","22.64570","0.04761"
"271.93200","22.66119","0.04868"
"272.11800","22.67674","0.04880"
"272.30400","22.69222","0.05023"
"272.49000","22.70770","0.05126"
"272.67600","22.72325","0.05225"
"272.86200","22.73868","0.05318"
"273.04800","22.75422","0.05430"
"273.23400","22.76977","0.05496"
"273.42000","22.78519","0.05574"
"273.60600","22.80074","0.05666"
"273.79200","22.81622","0.05796"
"273.97800","22.83171","0.05944"
"274.16400","22.84725","0.05881"
"274.35000","22.86274","0.05997"
"274.53600","22.87823","0.06138"
"274.72200","22.89377","0.06184"
"274.90800","22.90920","0.06302"
"275.09400","22.92468","0.06287"
"275.28000","22.94023","0.06438"
"275.46600","22.95565","0.06486"
"275.65200","22.97120","0.06540"
"275.83800","22.98674","0.06471"
"276.02400","23.00223","0.00671"
"276.21000","23.01771","0.00171"
"276.39600","23.03326","0.00408"
"276.58200","23.04869","0.00550"
"276.76800","23.06423","0.00573"
"276.95400","23.07972","0.00517"
"277.14000","23.09520","0.00522"
"277.32600","23.11069","0.00639"
"277.51200","23.12623","0.00638"
"277.69800","23.14166","0.00601"
"277.88400","23.15720","0.00547"
"278.07000","23.17275","0.00602"
"278.25600","23.18823","0.00637"
"278.44200","23.20378","0.00637"
"278.56000","23.21358","0.00605"