File: Force_trajectories/170121_3/Specimen_RawData_2.csv
End date,"1/21/2017"
Specimen label,"13CT_6"
Maximum Load,"0.10381",N

Time,Extension,Load
(s),(mm),(N)
"0.00000","0.00000","0.00027"
"0.14400","0.00801","0.00108"
"0.28800","0.02338","0.00375"
"0.43200","0.03623","0.00596"
"0.57600","0.04825","0.00760"
"0.72000","0.06027","0.00824"
"0.86400","0.07223","0.00943"
"1.00800","0.08418","0.00915"
"1.15200","0.09620","0.00975"
"1.29600","0.10828","0.01053"
"1.44000","0.12024","0.01070"
"1.58400","0.13219","0.01118"
"1.72800","0.14421","0.01157"
"1.87200","0.15617","0.01214"
"2.01600","0.16825","0.01185"
"2.16000","0.18015","0.01259"
"2.30400","0.19222","0.01266"
"2.44800","0.20424","0.01251"
"2.59200","0.21620","0.01301"
"2.73600","0.22816","0.01319"
"2.88000","0.24023","0.01274"
"3.02400","0.25219","0.01280"
"3.16800","0.26415","0.01324"
"3.31200","0.27617","0.01306"
"3.45600","0.28819","0.01351"
"3.60000","0.30020","0.01304"
"3.74400","0.31216","0.01240"
"3.88800","0.32418","0.01280"
"4.03200","0.33620","0.01290"
"4.17600","0.34821","0.01321"
"4.32000","0.36017","0.01276"
"4.46400","0.37219","0.01343"
"4.60800","0.38421","0.01315"
"4.75200","0.39617","0.01310"
"4.89600","0.40818","0.01328"
"5.04000","0.42020","0.01337"
"5.18400","0.43222","0.01287"
"5.32800","0.44418","0.01299"
"5.47200","0.45619","0.01323"
"5.61600","0.46815","0.01226"
"5.76000","0.48023","0.01233"
"5.90400","0.49213","0.01290"
"6.04800","0.50421","0.01248"
"6.19200","0.51622","0.01305"
"6.33600","0.52818","0.01281"
"6.48000","0.54014","0.01272"
"6.62400","0.55222","0.01298"
"6.76800","0.56423","0.01278"
"6.91200","0.57619","0.01302"
"7.05600","0.58815","0.01317"
"7.20000","0.60017","0.01273"
"7.34400","0.61224","0.01320"
"7.48800","0.62414","0.01312"
"7.63200","0.63622","0.01326"
"7.77600","0.64818","0.01301"
"7.92000","0.66020","0.01302"
"8.06400","0.67209","0.01307"
"8.20800","0.68417","0.01300"
"8.35200","0.69619","0.01354"
"8.49600","0.70815","0.01322"
"8.64000","0.72016","0.01316"
"8.78400","0.73218","0.01288"
"8.92800","0.74420","0.01335"
"9.07200","0.75616","0.01367"
"9.21600","0.76818","0.01295"
"9.36000","0.78019","0.01353"
"9.50400","0.79221","0.01347"
"9.64800","0.80417","0.01368"
"9.79200","0.81625","0.01348"
"9.93600","0.82820","0.01354"
"10.08000","0.84016","0.01327"
"10.22400","0.85212","0.01335"
"10.36800","0.86420","0.01341"
"10.51200","0.87622","0.01315"
"10.65600","0.88823","0.01274"
"10.80000","0.90013","0.01313"
"10.94400","0.91221","0.01341"
"11.08800","0.92423","0.01343"
"11.23200","0.93618","0.01377"
"11.37600","0.94814","0.01432"
"11.52000","0.96022","0.01428"
"11.66400","0.97218","0.01403"
"11.80800","0.98420","0.01367"
"11.95200","0.99615","0.01459"
"12.09600","1.00823","0.01424"
"12.24000","1.02019","0.01418"
"12.38400","1.03215","0.01444"
"12.52800","1.04416","0.01431"
"12.67200","1.05624","0.01430"
"12.81600","1.06820","0.01438"
"12.96000","1.08016","0.01470"
"13.10400","1.09224","0.01513"
"13.24800","1.10419","0.01514"
"13.39200","1.11615","0.01481"
"13.53600","1.12817","0.01539"
"13.68000","1.14019","0.01440"
"13.82400","1.15220","0.01472"
"13.96800","1.16416","0.01490"
"14.11200","1.17618","0.01470"
"14.25600","1.18820","0.01522"
"14.40000","1.20022","0.01492"
"14.54400","1.21211","0.01494"
"14.68800","1.22419","0.01512"
"14.83200","1.23621","0.01509"
"14.97600","1.24817","0.01486"
"15.12000","1.26012","0.01482"
"15.26400","1.27220","0.01508"
"15.40800","1.28422","0.01453"
"15.55200","1.29618","0.01458"
"15.69600","1.30820","0.01403"
"15.84000","1.32015","0.01460"
"15.98400","1.33217","0.01413"
"16.12800","1.34413","0.01475"
"16.27200","1.35621","0.01468"
"16.41600","1.36822","0.01498"
"16.56000","1.38018","0.01479"
"16.70400","1.39214","0.01401"
"16.84800","1.40422","0.01378"
"16.99200","1.41623","0.01445"
"17.13600","1.42819","0.01493"
"17.28000","1.44021","0.01495"
"17.42400","1.45223","0.01452"
"17.56800","1.46425","0.01468"
"17.71200","1.47614","0.01469"
"17.85600","1.48822","0.01448"
"18.00000","1.50018","0.01418"
"18.14400","1.51220","0.01521"
"18.28800","1.52415","0.01484"
"18.43200","1.53623","0.01418"
"18.57600","1.54819","0.01483"
"18.72000","1.56021","0.01476"
"18.86400","1.57217","0.01459"
"19.00800","1.58418","0.01430"
"19.15200","1.59620","0.01471"
"19.29600","1.60816","0.01473"
"19.44000","1.62018","0.01463"
"19.58400","1.63225","0.01492"
"19.72800","1.64421","0.01420"
"19.87200","1.65617","0.01507"
"20.01600","1.66819","0.01455"
"20.16000","1.68027","0.01498"
"20.30400","1.69216","0.01474"
"20.44800","1.70418","0.01500"
"20.59200","1.71620","0.01508"
"20.73600","1.72822","0.01495"
"20.88000","1.74017","0.01482"
"21.02400","1.75213","0.01436"
"21.16800","1.76421","0.01486"
"21.31200","1.77623","0.01562"
"21.45600","1.78819","0.01515"
"21.60000","1.80014","0.01504"
"21.74400","1.81222","0.01496"
"21.88800","1.82418","0.01500"
"22.03200","1.83620","0.01509"
"22.17600","1.84821","0.01560"
"22.32000","1.86017","0.01491"
"22.46400","1.87225","0.01499"
"22.60800","1.88415","0.01493"
"22.75200","1.89623","0.01523"
"22.89600","1.90824","0.01550"
"23.04000","1.92020","0.01538"
"23.18400","1.93216","0.01559"
"23.32800","1.94424","0.01584"
"23.47200","1.95625","0.01516"
"23.61600","1.96821","0.01523"
"23.76000","1.98023","0.01491"
"23.90400","1.99225","0.01529"
"24.04800","2.00420","0.01544"
"24.19200","2.01616","0.01530"
"24.33600","2.02818","0.01578"
"24.48000","2.04026","0.01532"
"24.62400","2.05222","0.01573"
"24.76800","2.06417","0.01580"
"24.91200","2.07625","0.01531"
"25.05600","2.08821","0.01598"
"25.20000","2.10023","0.01535"
"25.34400","2.11219","0.01563"
"25.48800","2.12426","0.01523"
"25.63200","2.13616","0.01618"
"25.77600","2.14818","0.01583"
"25.92000","2.16014","0.01582"
"26.06400","2.17215","0.01606"
"26.20800","2.18417","0.01651"
"26.35200","2.19613","0.01613"
"26.49600","2.20827","0.01605"
"26.64000","2.22022","0.01656"
"26.78400","2.23224","0.01642"
"26.92800","2.24420","0.01642"
"27.07200","2.25628","0.01661"
"27.21600","2.26824","0.01653"
"27.36000","2.28019","0.01617"
"27.50400","2.29221","0.01624"
"27.64800","2.30423","0.01700"
"27.79200","2.31625","0.01675"
"27.93600","2.32820","0.01625"
"28.08000","2.34022","0.01706"
"28.22400","2.35224","0.01703"
"28.36800","2.36426","0.01651"
"28.51200","2.37616","0.01679"
"28.65600","2.38823","0.01664"
"28.80000","2.40025","0.01679"
"28.94400","2.41221","0.01712"
"29.08800","2.42423","0.01722"
"29.23200","2.43624","0.01713"
"29.37600","2.44826","0.01717"
"29.52000","2.46016","0.01700"
"29.66400","2.47218","0.01715"
"29.80800","2.48420","0.01704"
"29.95200","2.49621","0.01747"
"30.09600","2.50817","0.01733"
"30.24000","2.52019","0.01742"
"30.38400","2.53221","0.01728"
"30.52800","2.54422","0.01763"
"30.67200","2.55618","0.01743"
"30.81600","2.56820","0.01785"
"30.96000","2.58028","0.01763"
"31.10400","2.59224","0.01794"
"31.24800","2.60419","0.01791"
"31.39200","2.61621","0.01775"
"31.53600","2.62823","0.01746"
"31.68000","2.64019","0.01814"
"31.82400","2.65226","0.01808"
"31.96800","2.66428","0.01841"
"32.11200","2.67624","0.01823"
"32.25600","2.68820","0.01861"
"32.40000","2.70016","0.01825"
"32.54400","2.71223","0.01772"
"32.68800","2.72425","0.01869"
"32.83200","2.73621","0.01853"
"32.97600","2.74823","0.01895"
"33.12000","2.76024","0.01879"
"33.26400","2.77220","0.01864"
"33.40800","2.78416","0.01955"
"33.55200","2.79624","0.01895"
"33.69600","2.80819","0.01944"
"33.84000","2.82015","0.01953"
"33.98400","2.83217","0.01968"
"34.12800","2.84419","0.01943"
"34.27200","2.85621","0.02017"
"34.41600","2.86816","0.01992"
"34.56000","2.88018","0.02003"
"34.70400","2.89220","0.02033"
"34.84800","2.90422","0.02061"
"34.99200","2.91617","0.02085"
"35.13600","2.92825","0.02068"
"35.28000","2.94027","0.02070"
"35.42400","2.95223","0.02107"
"35.56800","2.96419","0.02114"
"35.71200","2.97626","0.02170"
"35.85600","2.98822","0.02106"
"36.00000","3.00018","0.02184"
"36.14400","3.01220","0.02194"
"36.28800","3.02421","0.02195"
"36.43200","3.03623","0.02191"
"36.57600","3.04819","0.02213"
"36.72000","3.06021","0.02319"
"36.86400","3.07223","0.02298"
"37.00800","3.08424","0.02336"
"37.15200","3.09614","0.02338"
"37.29600","3.10828","0.02405"
"37.44000","3.12024","0.02408"
"37.58400","3.13219","0.02380"
"37.72800","3.14421","0.02486"
"37.87200","3.15623","0.02524"
"38.01600","3.16825","0.02546"
"38.16000","3.18021","0.02549"
"38.30400","3.19216","0.02532"
"38.44800","3.20418","0.02515"
"38.59200","3.21620","0.02676"
"38.73600","3.22816","0.02670"
"38.88000","3.24017","0.02674"
"39.02400","3.25219","0.02788"
"39.16800","3.26421","0.02831"
"39.31200","3.27617","0.02884"
"39.45600","3.28819","0.02946"
"39.60000","3.30026","0.03014"
"39.74400","3.31216","0.03072"
"39.88800","3.32418","0.03060"
"40.03200","3.33620","0.03104"
"40.17600","3.34821","0.03159"
"40.32000","3.36011","0.03273"
"40.46400","3.37219","0.03362"
"40.60800","3.38421","0.03380"
"40.75200","3.39622","0.03417"
"40.89600","3.40818","0.03475"
"41.04000","3.42020","0.03577"
"41.18400","3.43222","0.03581"
"41.32800","3.44424","0.03689"
"41.47200","3.45613","0.03694"
"41.61600","3.46821","0.03846"
"41.76000","3.48017","0.03868"
"41.90400","3.49213","0.03941"
"42.04800","3.50415","0.04037"
"42.19200","3.51622","0.04080"
"42.33600","3.52818","0.04099"
"42.48000","3.54014","0.04220"
"42.62400","3.55222","0.04216"
"42.76800","3.56417","0.04324"
"42.91200","3.57619","0.04373"
"43.05600","3.58821","0.04328"
"43.20000","3.60023","0.04424"
"43.34400","3.61218","0.04493"
"43.48800","3.62420","0.04479"
"43.63200","3.63616","0.04615"
"43.77600","3.64824","0.04594"
"43.92000","3.66020","0.04690"
"44.06400","3.67215","0.04754"
"44.20800","3.68417","0.04860"
"44.35200","3.69619","0.04877"
"44.49600","3.70821","0.04979"
"44.64000","3.72010","0.05007"
"44.78400","3.73218","0.05077"
"44.92800","3.74420","0.05179"
"45.07200","3.75622","0.05154"
"45.21600","3.76812","0.05266"
"45.36000","3.78025","0.05287"
"45.50400","3.79221","0.05349"
"45.64800","3.80423","0.05396"
"45.79200","3.81613","0.05373"
"45.93600","3.82826","0.05411"
"46.08000","3.84022","0.05375"
"46.22400","3.85218","0.05493"
"46.36800","3.86414","0.05500"
"46.51200","3.87622","0.05505"
"46.65600","3.88823","0.02406"
"46.80000","3.90013","0.01758"
"46.94400","3.91215","0.01688"
"47.08800","3.92417","0.01716"
"47.23200","3.93618","0.01799"
"47.37600","3.94814","0.01807"
"47.52000","3.96016","0.01818"
"47.66400","3.97224","0.01790"
"47.80800","3.98414","0.01799"
"47.95200","3.99615","0.01804"
"48.09600","4.00823","0.01801"
"48.24000","4.02025","0.01781"
"48.38400","4.03215","0.01823"
"48.52800","4.04416","0.01826"
"48.67200","4.05618","0.01799"
"48.81600","4.06820","0.01863"
"48.96000","4.08016","0.01861"
"49.10400","4.09223","0.01842"
"49.24800","4.10419","0.01821"
"49.39200","4.11621","0.01871"
"49.53600","4.12817","0.01856"
"49.68000","4.14025","0.01831"
"49.82400","4.15220","0.01858"
"49.96800","4.16416","0.01858"
"50.11200","4.17618","0.01813"
"50.25600","4.18820","0.01722"
"50.40000","4.20027","0.01755"
"50.54400","4.21223","0.01767"
"50.68800","4.22425","0.01767"
"50.83200","4.23621","0.01830"
"50.97600","4.24817","0.01827"
"51.12000","4.26012","0.01822"
"51.26400","4.27220","0.01848"
"51.40800","4.28416","0.01801"
"51.55200","4.29612","0.01806"
"51.69600","4.30813","0.01807"
"51.84000","4.32015","0.01817"
"51.98400","4.33217","0.01798"
"52.12800","4.34413","0.01813"
"52.27200","4.35615","0.01835"
"52.41600","4.36816","0.01785"
"52.56000","4.38018","0.01843"
"52.70400","4.39214","0.01781"
"52.84800","4.40422","0.01850"
"52.99200","4.41617","0.01890"
"53.13600","4.42819","0.01847"
"53.28000","4.44009","0.01807"
"53.42400","4.45223","0.01859"
"53.56800","4.46419","0.01845"
"53.71200","4.47614","0.01865"
"53.85600","4.48816","0.01877"
"54.00000","4.50024","0.01849"
"54.14400","4.51220","0.01859"
"54.28800","4.52421","0.01866"
"54.43200","4.53617","0.01871"
"54.57600","4.54825","0.01908"
"54.72000","4.56021","0.01908"
"54.86400","4.57217","0.01909"
"55.00800","4.58418","0.01907"
"55.15200","4.59620","0.01877"
"55.29600","4.60816","0.01876"
"55.44000","4.62012","0.01891"
"55.58400","4.63219","0.01878"
"55.72800","4.64421","0.01860"
"55.87200","4.65617","0.01896"
"56.01600","4.66813","0.01914"
"56.16000","4.68021","0.01964"
"56.30400","4.69222","0.01914"
"56.44800","4.70412","0.01931"
"56.59200","4.71614","0.01949"
"56.73600","4.72816","0.01969"
"56.88000","4.74023","0.01985"
"57.02400","4.75213","0.01959"
"57.16800","4.76421","0.01966"
"57.31200","4.77617","0.01938"
"57.45600","4.78819","0.01915"
"57.60000","4.80008","0.01948"
"57.74400","4.81222","0.01930"
"57.88800","4.82418","0.01962"
"58.03200","4.83620","0.01949"
"58.17600","4.84815","0.01974"
"58.32000","4.86017","0.01925"
"58.46400","4.87219","0.01978"
"58.60800","4.88421","0.02023"
"58.75200","4.89622","0.01967"
"58.89600","4.90824","0.01992"
"59.04000","4.92020","0.01975"
"59.18400","4.93216","0.01969"
"59.32800","4.94418","0.01987"
"59.47200","4.95619","0.01986"
"59.61600","4.96815","0.01997"
"59.76000","4.98011","0.02055"
"59.90400","4.99219","0.02030"
"60.04800","5.00420","0.02016"
"60.19200","5.01616","0.01998"
"60.33600","5.02818","0.02059"
"60.48000","5.04020","0.02025"
"60.62400","5.05222","0.02080"
"60.76800","5.06417","0.02036"
"60.91200","5.07625","0.02097"
"61.05600","5.08821","0.02062"
"61.20000","5.10023","0.02063"
"61.34400","5.11212","0.02061"
"61.48800","5.12420","0.02028"
"61.63200","5.13622","0.02019"
"61.77600","5.14818","0.02053"
"61.92000","5.16014","0.02017"
"62.06400","5.17221","0.02076"
"62.20800","5.18423","0.02053"
"62.35200","5.19619","0.02139"
"62.49600","5.20815","0.02072"
"62.64000","5.22022","0.02068"
"62.78400","5.23224","0.02086"
"62.92800","5.24420","0.02131"
"63.07200","5.25622","0.02101"
"63.21600","5.26824","0.02133"
"63.36000","5.28019","0.02132"
"63.50400","5.29215","0.02096"
"63.64800","5.30423","0.02098"
"63.79200","5.31619","0.02124"
"63.93600","5.32814","0.02098"
"64.08000","5.34016","0.02136"
"64.22400","5.35218","0.02120"
"64.36800","5.36426","0.02096"
"64.51200","5.37621","0.02082"
"64.65600","5.38817","0.02177"
"64.80000","5.40025","0.02172"
"64.94400","5.41227","0.02156"
"65.08800","5.42423","0.02148"
"65.23200","5.43624","0.02143"
"65.37600","5.44826","0.02198"
"65.52000","5.46022","0.02175"
"65.66400","5.47218","0.02203"
"65.80800","5.48425","0.02192"
"65.95200","5.49621","0.02219"
"66.09600","5.50817","0.02222"
"66.24000","5.52019","0.02253"
"66.38400","5.53227","0.02237"
"66.52800","5.54422","0.02249"
"66.67200","5.55624","0.02287"
"66.81600","5.56820","0.02291"
"66.96000","5.58022","0.02275"
"67.10400","5.59223","0.02289"
"67.24800","5.60419","0.02337"
"67.39200","5.61621","0.02325"
"67.53600","5.62823","0.02359"
"67.68000","5.64025","0.02313"
"67.82400","5.65220","0.02344"
"67.96800","5.66428","0.02347"
"68.11200","5.67624","0.02425"
"68.25600","5.68820","0.02429"
"68.40000","5.70021","0.02395"
"68.54400","5.71223","0.02458"
"68.68800","5.72425","0.02396"
"68.83200","5.73621","0.02401"
"68.97600","5.74823","0.02468"
"69.12000","5.76024","0.02470"
"69.26400","5.77220","0.02503"
"69.40800","5.78416","0.02526"
"69.55200","5.79624","0.02527"
"69.69600","5.80819","0.02537"
"69.84000","5.82021","0.02530"
"69.98400","5.83217","0.02556"
"70.12800","5.84425","0.02583"
"70.27200","5.85621","0.02619"
"70.41600","5.86816","0.02577"
"70.56000","5.88018","0.02622"
"70.70400","5.89226","0.02653"
"70.84800","5.90428","0.02698"
"70.99200","5.91617","0.02726"
"71.13600","5.92819","0.02790"
"71.28000","5.94027","0.02806"
"71.42400","5.95223","0.02891"
"71.56800","5.96419","0.02899"
"71.71200","5.97626","0.02942"
"71.85600","5.98822","0.02955"
"72.00000","6.00024","0.02961"
"72.14400","6.01220","0.02996"
"72.28800","6.02427","0.03034"
"72.43200","6.03623","0.02972"
"72.57600","6.04819","0.03093"
"72.72000","6.06021","0.03048"
"72.86400","6.07223","0.03114"
"73.00800","6.08424","0.03175"
"73.15200","6.09620","0.03206"
"73.29600","6.10822","0.03296"
"73.44000","6.12024","0.03335"
"73.58400","6.13225","0.03393"
"73.72800","6.14415","0.03239"
"73.87200","6.15617","0.03284"
"74.01600","6.16825","0.03274"
"74.16000","6.18020","0.03374"
"74.30400","6.19222","0.03459"
"74.44800","6.20424","0.03457"
"74.59200","6.21626","0.03551"
"74.73600","6.22816","0.03523"
"74.88000","6.24017","0.03586"
"75.02400","6.25219","0.03619"
"75.16800","6.26421","0.03647"
"75.31200","6.27617","0.03664"
"75.45600","6.28819","0.03813"
"75.60000","6.30026","0.03819"
"75.74400","6.31222","0.03898"
"75.88800","6.32418","0.03960"
"76.03200","6.33626","0.03966"
"76.17600","6.34821","0.03728"
"76.32000","6.36023","0.03161"
"76.46400","6.37225","0.03151"
"76.60800","6.38427","0.03222"
"76.75200","6.39622","0.03328"
"76.89600","6.40818","0.03330"
"77.04000","6.42020","0.03431"
"77.18400","6.43222","0.03328"
"77.32800","6.44418","0.03385"
"77.47200","6.45613","0.03301"
"77.61600","6.46821","0.03446"
"77.76000","6.48017","0.03473"
"77.90400","6.49219","0.03492"
"78.04800","6.50415","0.03530"
"78.19200","6.51622","0.03440"
"78.33600","6.52818","0.03461"
"78.48000","6.54020","0.03363"
"78.62400","6.55222","0.03220"
"78.76800","6.56423","0.03145"
"78.91200","6.57619","0.03179"
"79.05600","6.58821","0.03297"
"79.20000","6.60017","0.03350"
"79.34400","6.61218","0.03393"
"79.48800","6.62420","0.03433"
"79.63200","6.63616","0.03388"
"79.77600","6.64818","0.03456"
"79.92000","6.66025","0.03535"
"80.06400","6.67221","0.03657"
"80.20800","6.68417","0.03650"
"80.35200","6.69625","0.03572"
"80.49600","6.70821","0.03673"
"80.64000","6.72016","0.03647"
"80.78400","6.73218","0.03637"
"80.92800","6.74420","0.03669"
"81.07200","6.75622","0.03668"
"81.21600","6.76818","0.03790"
"81.36000","6.78013","0.03759"
"81.50400","6.79221","0.03886"
"81.64800","6.80423","0.03844"
"81.79200","6.81613","0.03911"
"81.93600","6.82820","0.03855"
"82.08000","6.84022","0.03933"
"82.22400","6.85218","0.03117"
"82.36800","6.86420","0.02824"
"82.51200","6.87622","0.02804"
"82.65600","6.88823","0.02805"
"82.80000","6.90019","0.02789"
"82.94400","6.91221","0.02728"
"83.08800","6.92423","0.02821"
"83.23200","6.93624","0.02812"
"83.37600","6.94814","0.02818"
"83.52000","6.96016","0.02945"
"83.66400","6.97218","0.02836"
"83.80800","6.98425","0.02497"
"83.95200","6.99615","0.02487"
"84.09600","7.00823","0.02495"
"84.24000","7.02025","0.02415"
"84.38400","7.03221","0.02407"
"84.52800","7.04416","0.02470"
"84.67200","7.05618","0.02492"
"84.81600","7.06820","0.02511"
"84.96000","7.08016","0.02533"
"85.10400","7.09218","0.02519"
"85.24800","7.10419","0.02558"
"85.39200","7.11615","0.02600"
"85.53600","7.12811","0.02565"
"85.68000","7.14019","0.02572"
"85.82400","7.15220","0.02539"
"85.96800","7.16422","0.02619"
"86.11200","7.17618","0.02621"
"86.25600","7.18826","0.02580"
"86.40000","7.20021","0.02597"
"86.54400","7.21217","0.02591"
"86.68800","7.22419","0.02603"
"86.83200","7.23627","0.02546"
"86.97600","7.24823","0.02555"
"87.12000","7.26018","0.02601"
"87.26400","7.27220","0.02587"
"87.40800","7.28422","0.02614"
"87.55200","7.29624","0.02543"
"87.69600","7.30814","0.02609"
"87.84000","7.32021","0.02466"
"87.98400","7.33223","0.02418"
"88.12800","7.34419","0.02383"
"88.27200","7.35615","0.02353"
"88.41600","7.36822","0.02309"
"88.56000","7.38018","0.02316"
"88.70400","7.39220","0.02322"
"88.84800","7.40410","0.02345"
"88.99200","7.41623","0.02269"
"89.13600","7.42819","0.02307"
"89.28000","7.44015","0.02313"
"89.42400","7.45217","0.02292"
"89.56800","7.46418","0.02372"
"89.71200","7.47620","0.02375"
"89.85600","7.48810","0.02408"
"90.00000","7.50018","0.02396"
"90.14400","7.51220","0.02416"
"90.28800","7.52421","0.02401"
"90.43200","7.53617","0.02423"
"90.57600","7.54819","0.02436"
"90.72000","7.56027","0.02420"
"90.86400","7.57223","0.02424"
"91.00800","7.58418","0.02466"
"91.15200","7.59620","0.02457"
"91.29600","7.60822","0.02429"
"91.44000","7.62018","0.02508"
"91.58400","7.63219","0.02499"
"91.72800","7.64421","0.02539"
"91.87200","7.65623","0.02567"
"92.01600","7.66813","0.02606"
"92.16000","7.68021","0.02614"
"92.30400","7.69216","0.02626"
"92.44800","7.70418","0.02659"
"92.59200","7.71614","0.02643"
"92.73600","7.72822","0.02677"
"92.88000","7.74017","0.02664"
"93.02400","7.75219","0.02761"
"93.16800","7.76415","0.02758"
"93.31200","7.77617","0.02724"
"93.45600","7.78819","0.02741"
"93.60000","7.80014","0.02754"
"93.74400","7.81216","0.02769"
"93.88800","7.82424","0.02784"
"94.03200","7.83620","0.02818"
"94.17600","7.84815","0.02826"
"94.32000","7.86023","0.02872"
"94.46400","7.87225","0.02848"
"94.60800","7.88415","0.02800"
"94.75200","7.89616","0.02756"
"94.89600","7.90818","0.02729"
"95.04000","7.92020","0.02774"
"95.18400","7.93216","0.02767"
"95.32800","7.94418","0.02753"
"95.47200","7.95619","0.02760"
"95.61600","7.96821","0.02767"
"95.76000","7.98017","0.02839"
"95.90400","7.99225","0.02821"
"96.04800","8.00420","0.02842"
"96.19200","8.01622","0.02879"
"96.33600","8.02812","0.02936"
"96.48000","8.04020","0.03005"
"96.62400","8.05221","0.02858"
"96.76800","8.06417","0.02811"
"96.91200","8.07613","0.02896"
"97.05600","8.08827","0.02866"
"97.20000","8.10023","0.02879"
"97.34400","8.11212","0.02814"
"97.48800","8.12414","0.02840"
"97.63200","8.13622","0.02960"
"97.77600","8.14824","0.02949"
"97.92000","8.16020","0.02994"
"98.06400","8.17215","0.03024"
"98.20800","8.18423","0.03021"
"98.35200","8.19619","0.03028"
"98.49600","8.20815","0.03127"
"98.64000","8.22016","0.03124"
"98.78400","8.23224","0.03233"
"98.92800","8.24420","0.03230"
"99.07200","8.25616","0.03244"
"99.21600","8.26823","0.03235"
"99.36000","8.28025","0.03241"
"99.50400","8.29215","0.03315"
"99.64800","8.30417","0.03286"
"99.79200","8.31619","0.03342"
"99.93600","8.32820","0.03374"
"100.08000","8.34016","0.03312"
"100.22400","8.35218","0.03474"
"100.36800","8.36420","0.03405"
"100.51200","8.37615","0.03490"
"100.65600","8.38811","0.03521"
"100.80000","8.40019","0.03523"
"100.94400","8.41221","0.03584"
"101.08800","8.42422","0.03612"
"101.23200","8.43618","0.03638"
"101.37600","8.44820","0.03733"
"101.52000","8.46022","0.03716"
"101.66400","8.47224","0.03753"
"101.80800","8.48419","0.03808"
"101.95200","8.49627","0.03850"
"102.09600","8.50817","0.03852"
"102.24000","8.52019","0.03873"
"102.38400","8.53221","0.03950"
"102.52800","8.54416","0.03991"
"102.67200","8.55618","0.04036"
"102.81600","8.56814","0.04054"
"102.96000","8.58022","0.04100"
"103.10400","8.59223","0.04069"
"103.24800","8.60419","0.04229"
"103.39200","8.61621","0.04220"
"103.53600","8.62823","0.04270"
"103.68000","8.64025","0.04277"
"103.82400","8.65214","0.04249"
"103.96800","8.66422","0.04290"
"104.11200","8.67624","0.04306"
"104.25600","8.68820","0.04370"
"104.40000","8.70015","0.04460"
"104.54400","8.71223","0.04441"
"104.68800","8.72419","0.04488"
"104.83200","8.73621","0.04347"
"104.97600","8.74817","0.04417"
"105.12000","8.76024","0.04445"
"105.26400","8.77226","0.04493"
"105.40800","8.78416","0.04587"
"105.55200","8.79618","0.04601"
"105.69600","8.80825","0.04575"
"105.84000","8.82021","0.04623"
"105.98400","8.83217","0.04676"
"106.12800","8.84425","0.04761"
"106.27200","8.85627","0.04795"
"106.41600","8.86822","0.04824"
"106.56000","8.88018","0.04813"
"106.70400","8.89220","0.04869"
"106.84800","8.90422","0.04914"
"106.99200","8.91617","0.04912"
"107.13600","8.92819","0.04977"
"107.28000","8.94021","0.05004"
"107.42400","8.95223","0.05100"
"107.56800","8.96418","0.05061"
"107.71200","8.97620","0.05112"
"107.85600","8.98822","0.05104"
"108.00000","9.00024","0.05169"
"108.14400","9.01220","0.05157"
"108.28800","9.02421","0.05072"
"108.43200","9.03623","0.05200"
"108.57600","9.04825","0.05220"
"108.72000","9.06021","0.05288"
"108.86400","9.07222","0.05287"
"109.00800","9.08424","0.05236"
"109.15200","9.09620","0.05379"
"109.29600","9.10822","0.05393"
"109.44000","9.12024","0.05370"
"109.58400","9.13219","0.05476"
"109.72800","9.14421","0.05506"
"109.87200","9.15623","0.05476"
"110.01600","9.16825","0.05517"
"110.16000","9.18021","0.05516"
"110.30400","9.19222","0.05546"
"110.44800","9.20418","0.05572"
"110.59200","9.21626","0.05572"
"110.73600","9.22822","0.05699"
"110.88000","9.24017","0.05636"
"111.02400","9.25219","0.05674"
"111.16800","9.26415","0.05741"
"111.31200","9.27611","0.05744"
"111.45600","9.28818","0.05786"
"111.60000","9.30020","0.05842"
"111.74400","9.31222","0.05942"
"111.88800","9.32424","0.05932"
"112.03200","9.33626","0.05919"
"112.17600","9.34827","0.05995"
"112.32000","9.36023","0.06043"
"112.46400","9.37219","0.06147"
"112.60800","9.38427","0.06169"
"112.75200","9.39628","0.06199"
"112.89600","9.40824","0.06217"
"113.04000","9.42020","0.06299"
"113.18400","9.43228","0.06330"
"113.32800","9.44423","0.06325"
"113.47200","9.45619","0.06392"
"113.61600","9.46821","0.06458"
"113.76000","9.48023","0.06496"
"113.90400","9.49225","0.06469"
"114.04800","9.50420","0.06588"
"114.19200","9.51622","0.06585"
"114.33600","9.52830","0.06667"
"114.48000","9.54026","0.06675"
"114.62400","9.55216","0.06681"
"114.76800","9.56423","0.06772"
"114.91200","9.57625","0.06797"
"115.05600","9.58821","0.06839"
"115.20000","9.60023","0.06829"
"115.34400","9.61224","0.06844"
"115.48800","9.62426","0.06955"
"115.63200","9.63616","0.06901"
"115.77600","9.64818","0.07024"
"115.92000","9.66019","0.07033"
"116.06400","9.67227","0.07104"
"116.20800","9.68417","0.07105"
"116.35200","9.69619","0.07201"
"116.49600","9.70821","0.07200"
"116.64000","9.72022","0.07279"
"116.78400","9.73218","0.07249"
"116.92800","9.74420","0.07304"
"117.07200","9.75628","0.07344"
"117.21600","9.76818","0.07341"
"117.36000","9.78019","0.07358"
"117.50400","9.79221","0.07379"
"117.64800","9.80423","0.07431"
"117.79200","9.81619","0.07465"
"117.93600","9.82820","0.07529"
"118.08000","9.84022","0.07530"
"118.22400","9.85224","0.07572"
"118.36800","9.86420","0.07598"
"118.51200","9.87615","0.07584"
"118.65600","9.88823","0.07651"
"118.80000","9.90019","0.07658"
"118.94400","9.91221","0.07687"
"119.08800","9.92423","0.07689"
"119.23200","9.93624","0.07747"
"119.37600","9.94820","0.07740"
"119.52000","9.96022","0.07796"
"119.66400","9.97223","0.07790"
"119.80800","9.98419","0.07799"
"119.95200","9.99621","0.07817"
"120.09600","10.00817","0.07837"
"120.24000","10.02019","0.07861"
"120.38400","10.03221","0.07858"
"120.52800","10.04416","0.07894"
"120.67200","10.05624","0.07937"
"120.81600","10.06820","0.07884"
"120.96000","10.08022","0.07954"
"121.10400","10.09217","0.07986"
"121.24800","10.10425","0.07986"
"121.39200","10.11621","0.08041"
"121.53600","10.12817","0.08035"
"121.68000","10.14019","0.08072"
"121.82400","10.15220","0.08063"
"121.96800","10.16422","0.08105"
"122.11200","10.17618","0.08135"
"122.25600","10.18820","0.08161"
"122.40000","10.20021","0.08152"
"122.54400","10.21223","0.08178"
"122.68800","10.22419","0.08173"
"122.83200","10.23621","0.08160"
"122.97600","10.24823","0.08213"
"123.12000","10.26018","0.08247"
"123.26400","10.27214","0.08256"
"123.40800","10.28422","0.08323"
"123.55200","10.29618","0.08279"
"123.69600","10.30813","0.08323"
"123.84000","10.32015","0.08359"
"123.98400","10.33217","0.08383"
"124.12800","10.34419","0.08407"
"124.27200","10.35614","0.08448"
"124.41600","10.36816","0.08439"
"124.56000","10.38018","0.08480"
"124.70400","10.39220","0.08507"
"124.84800","10.40416","0.08554"
"124.99200","10.41623","0.08574"
"125.13600","10.42825","0.08558"
"125.28000","10.44021","0.08625"
"125.42400","10.45223","0.08676"
"125.56800","10.46418","0.08713"
"125.71200","10.47626","0.08704"
"125.85600","10.48816","0.08768"
"126.00000","10.50018","0.08792"
"126.14400","10.51220","0.08855"
"126.28800","10.52421","0.08935"
"126.43200","10.53617","0.08953"
"126.57600","10.54819","0.09039"
"126.72000","10.56021","0.09031"
"126.86400","10.57228","0.09095"
"127.00800","10.58418","0.09115"
"127.15200","10.59620","0.09151"
"127.29600","10.60822","0.09263"
"127.44000","10.62018","0.09211"
"127.58400","10.63219","0.09328"
"127.72800","10.64421","0.09325"
"127.87200","10.65623","0.09406"
"128.01600","10.66819","0.09348"
"128.16000","10.68014","0.09341"
"128.30400","10.69222","0.09404"
"128.44800","10.70418","0.09471"
"128.59200","10.71614","0.03825"
"128.73600","10.72822","0.03255"
"128.88000","10.74017","0.03095"
"129.02400","10.75219","0.03055"
"129.16800","10.76415","0.02792"
"129.31200","10.77617","0.03172"
"129.45600","10.78818","0.03358"
"129.60000","10.80014","0.03114"
"129.74400","10.81216","0.02852"
"129.88800","10.82424","0.03401"
"130.03200","10.83619","0.03536"
"130.17600","10.84821","0.03133"
"130.32000","10.86023","0.03261"
"130.46400","10.87225","0.03853"
"130.60800","10.88421","0.03709"
"130.75200","10.89616","0.03386"
"130.89600","10.90818","0.03923"
"131.04000","10.92020","0.04153"
"131.18400","10.93216","0.03724"
"131.32800","10.94412","0.03765"
"131.47200","10.95625","0.04353"
"131.61600","10.96821","0.04267"
"131.76000","10.98023","0.03927"
"131.90400","10.99219","0.04306"
"132.04800","11.00426","0.04531"
"132.19200","11.01622","0.04217"
"132.33600","11.02818","0.04208"
"132.48000","11.04014","0.04544"
"132.62400","11.05222","0.04562"
"132.76800","11.06417","0.04331"
"132.91200","11.07613","0.04550"
"133.05600","11.08821","0.04728"
"133.20000","11.10023","0.04509"
"133.34400","11.11218","0.04607"
"133.48800","11.12414","0.04859"
"133.63200","11.13622","0.04886"
"133.77600","11.14824","0.04681"
"133.92000","11.16019","0.04828"
"134.06400","11.17215","0.05109"
"134.20800","11.18423","0.04900"
"134.35200","11.19625","0.04978"
"134.49600","11.20815","0.05180"
"134.64000","11.22022","0.05159"
"134.78400","11.23218","0.05077"
"134.92800","11.24420","0.05336"
"135.07200","11.25616","0.05381"
"135.21600","11.26824","0.05234"
"135.36000","11.28025","0.05345"
"135.50400","11.29221","0.05537"
"135.64800","11.30417","0.05439"
"135.79200","11.31618","0.05480"
"135.93600","11.32820","0.05674"
"136.08000","11.34016","0.05722"
"136.22400","11.35218","0.05647"
"136.36800","11.36414","0.05712"
"136.51200","11.37621","0.05899"
"136.65600","11.38811","0.05827"
"136.80000","11.40019","0.05818"
"136.94400","11.41215","0.06042"
"137.08800","11.42417","0.05985"
"137.23200","11.43612","0.05933"
"137.37600","11.44820","0.06107"
"137.52000","11.46022","0.06237"
"137.66400","11.47218","0.06147"
"137.80800","11.48419","0.06273"
"137.95200","11.49621","0.06281"
"138.09600","11.50823","0.06265"
"138.24000","11.52019","0.04670"
"138.38400","11.53221","0.04559"
"138.52800","11.54422","0.04196"
"138.67200","11.55618","0.04136"
"138.81600","11.56814","0.04302"
"138.96000","11.58022","0.04347"
"139.10400","11.59217","0.04181"
"139.24800","11.60419","0.04233"
"139.39200","11.61615","0.04310"
"139.53600","11.62823","0.04336"
"139.68000","11.64025","0.04225"
"139.82400","11.65220","0.04279"
"139.96800","11.66416","0.04312"
"140.11200","11.67624","0.04162"
"140.25600","11.68820","0.04205"
"140.40000","11.70015","0.04463"
"140.54400","11.71217","0.04280"
"140.68800","11.72419","0.04205"
"140.83200","11.73621","0.04380"
"140.97600","11.74816","0.04418"
"141.12000","11.76012","0.04307"
"141.26400","11.77220","0.04314"
"141.40800","11.78416","0.04484"
"141.55200","11.79612","0.04460"
"141.69600","11.80819","0.04347"
"141.84000","11.82027","0.04469"
"141.98400","11.83217","0.04545"
"142.12800","11.84419","0.04520"
"142.27200","11.85620","0.04465"
"142.41600","11.86822","0.04602"
"142.56000","11.88018","0.04577"
"142.70400","11.89220","0.04610"
"142.84800","11.90422","0.04710"
"142.99200","11.91623","0.04767"
"143.13600","11.92813","0.04745"
"143.28000","11.94021","0.04716"
"143.42400","11.95217","0.04813"
"143.56800","11.96418","0.04735"
"143.71200","11.97608","0.04779"
"143.85600","11.98822","0.04814"
"144.00000","12.00018","0.04740"
"144.14400","12.01219","0.04787"
"144.28800","12.02421","0.04731"
"144.43200","12.03623","0.04774"
"144.57600","12.04825","0.04805"
"144.72000","12.06021","0.04872"
"144.86400","12.07222","0.05002"
"145.00800","12.08424","0.04912"
"145.15200","12.09626","0.04951"
"145.29600","12.10816","0.05011"
"145.44000","12.12024","0.05045"
"145.58400","12.13219","0.04992"
"145.72800","12.14415","0.04999"
"145.87200","12.15617","0.05041"
"146.01600","12.16819","0.05077"
"146.16000","12.18020","0.05086"
"146.30400","12.19216","0.05138"
"146.44800","12.20418","0.05145"
"146.59200","12.21620","0.05088"
"146.73600","12.22821","0.05122"
"146.88000","12.24017","0.05067"
"147.02400","12.25219","0.04498"
"147.16800","12.26415","0.04539"
"147.31200","12.27623","0.04499"
"147.45600","12.28812","0.04551"
"147.60000","12.30020","0.02160"
"147.74400","12.31222","0.02515"
"147.88800","12.32418","0.02727"
"148.03200","12.33619","0.02194"
"148.17600","12.34821","0.02241"
"148.32000","12.36023","0.02444"
"148.46400","12.37219","0.02380"
"148.60800","12.38421","0.02469"
"148.75200","12.39622","0.02449"
"148.89600","12.40824","0.02529"
"149.04000","12.42014","0.02445"
"149.18400","12.43222","0.02372"
"149.32800","12.44423","0.02744"
"149.47200","12.45619","0.02615"
"149.61600","12.46821","0.02455"
"149.76000","12.48023","0.02543"
"149.90400","12.49224","0.02704"
"150.04800","12.50414","0.02927"
"150.19200","12.51622","0.02607"
"150.33600","12.52824","0.02600"
"150.48000","12.54026","0.02834"
"150.62400","12.55216","0.02788"
"150.76800","12.56423","0.02760"
"150.91200","12.57619","0.02840"
"151.05600","12.58821","0.02962"
"151.20000","12.60017","0.02902"
"151.34400","12.61218","0.02890"
"151.48800","12.62420","0.03102"
"151.63200","12.63622","0.03125"
"151.77600","12.64818","0.03010"
"151.92000","12.66025","0.03060"
"152.06400","12.67227","0.03406"
"152.20800","12.68423","0.03334"
"152.35200","12.69619","0.03227"
"152.49600","12.70826","0.03377"
"152.64000","12.72022","0.03518"
"152.78400","12.73224","0.03624"
"152.92800","12.74426","0.03482"
"153.07200","12.75622","0.03544"
"153.21600","12.76824","0.03776"
"153.36000","12.78019","0.03811"
"153.50400","12.79221","0.03757"
"153.64800","12.80423","0.03804"
"153.79200","12.81619","0.03928"
"153.93600","12.82814","0.04060"
"154.08000","12.84028","0.04023"
"154.22400","12.85224","0.04070"
"154.36800","12.86420","0.04224"
"154.51200","12.87621","0.04260"
"154.65600","12.88823","0.04275"
"154.80000","12.90019","0.04410"
"154.94400","12.91215","0.04473"
"155.08800","12.92416","0.04487"
"155.23200","12.93618","0.04548"
"155.37600","12.94820","0.04613"
"155.52000","12.96016","0.04743"
"155.66400","12.97224","0.04710"
"155.80800","12.98425","0.04766"
"155.95200","12.99621","0.04930"
"156.09600","13.00817","0.04950"
"156.24000","13.02025","0.05028"
"156.38400","13.03221","0.05080"
"156.52800","13.04416","0.05091"
"156.67200","13.05618","0.05232"
"156.81600","13.06820","0.05232"
"156.96000","13.08022","0.05299"
"157.10400","13.09217","0.05312"
"157.24800","13.10419","0.05409"
"157.39200","13.11627","0.05486"
"157.53600","13.12823","0.05567"
"157.68000","13.14018","0.05594"
"157.82400","13.15226","0.05652"
"157.96800","13.16428","0.05779"
"158.11200","13.17618","0.05814"
"158.25600","13.18820","0.05824"
"158.40000","13.20021","0.05916"
"158.54400","13.21223","0.06112"
"158.68800","13.22419","0.06086"
"158.83200","13.23615","0.06138"
"158.97600","13.24822","0.06279"
"159.12000","13.26024","0.06382"
"159.26400","13.27214","0.06413"
"159.40800","13.28416","0.06483"
"159.55200","13.29624","0.06601"
"159.69600","13.30819","0.06659"
"159.84000","13.32015","0.06631"
"159.98400","13.33223","0.06765"
"160.12800","13.34425","0.06867"
"160.27200","13.35620","0.06881"
"160.41600","13.36822","0.06887"
"160.56000","13.38018","0.07015"
"160.70400","13.39220","0.07099"
"160.84800","13.40415","0.07157"
"160.99200","13.41623","0.07222"
"161.13600","13.42825","0.07331"
"161.28000","13.44021","0.07330"
"161.42400","13.45217","0.07336"
"161.56800","13.46412","0.07415"
"161.71200","13.47620","0.07488"
"161.85600","13.48816","0.07501"
"162.00000","13.50012","0.07524"
"162.14400","13.51220","0.07566"
"162.28800","13.52415","0.07656"
"162.43200","13.53617","0.07669"
"162.57600","13.54819","0.07662"
"162.72000","13.56021","0.07769"
"162.86400","13.57216","0.07788"
"163.00800","13.58418","0.07786"
"163.15200","13.59620","0.07848"
"163.29600","13.60822","0.07874"
"163.44000","13.62018","0.07905"
"163.58400","13.63219","0.07935"
"163.72800","13.64421","0.07960"
"163.87200","13.65623","0.07966"
"164.01600","13.66819","0.08027"
"164.16000","13.68020","0.08065"
"164.30400","13.69222","0.08091"
"164.44800","13.70424","0.08080"
"164.59200","13.71620","0.08115"
"164.73600","13.72822","0.08129"
"164.88000","13.74023","0.08181"
"165.02400","13.75219","0.08182"
"165.16800","13.76415","0.08217"
"165.31200","13.77617","0.08268"
"165.45600","13.78824","0.08316"
"165.60000","13.80020","0.08298"
"165.74400","13.81216","0.08315"
"165.88800","13.82418","0.08410"
"166.03200","13.83625","0.08416"
"166.17600","13.84821","0.08445"
"166.32000","13.86011","0.08506"
"166.46400","13.87225","0.08522"
"166.60800","13.88421","0.08551"
"166.75200","13.89616","0.08590"
"166.89600","13.90818","0.08634"
"167.04000","13.92020","0.08683"
"167.18400","13.93222","0.08692"
"167.32800","13.94417","0.08741"
"167.47200","13.95613","0.08779"
"167.61600","13.96821","0.08753"
"167.76000","13.98023","0.08752"
"167.90400","13.99219","0.08771"
"168.04800","14.00420","0.08759"
"168.19200","14.01622","0.08759"
"168.33600","14.02818","0.08768"
"168.48000","14.04020","0.08807"
"168.62400","14.05221","0.08885"
"168.76800","14.06423","0.08927"
"168.91200","14.07613","0.08949"
"169.05600","14.08815","0.08963"
"169.20000","14.10017","0.09035"
"169.34400","14.11224","0.09089"
"169.48800","14.12414","0.09145"
"169.63200","14.13622","0.09168"
"169.77600","14.14818","0.09260"
"169.92000","14.16020","0.09259"
"170.06400","14.17215","0.09306"
"170.20800","14.18423","0.09335"
"170.35200","14.19619","0.09510"
"170.49600","14.20821","0.09418"
"170.64000","14.22016","0.09441"
"170.78400","14.23224","0.09507"
"170.92800","14.24420","0.09563"
"171.07200","14.25616","0.09698"
"171.21600","14.26817","0.09668"
"171.36000","14.28019","0.09748"
"171.50400","14.29215","0.09760"
"171.64800","14.30417","0.09887"
"171.79200","14.31625","0.09883"
"171.93600","14.32820","0.09938"
"172.08000","14.34016","0.10005"
"172.22400","14.35218","0.10060"
"172.36800","14.36420","0.10081"
"172.51200","14.37621","0.10179"
"172.65600","14.38811","0.10232"
"172.80000","14.40019","0.10193"
"172.94400","14.41221","0.10228"
"173.08800","14.42422","0.10346"
"173.23200","14.43618","0.10371"
"173.37600","14.44820","0.10209"
"173.52000","14.46016","0.01864"
"173.66400","14.47218","0.02262"
"173.80800","14.48413","0.01671"
"173.95200","14.49621","0.01247"
"174.09600","14.50823","0.01328"
"174.24000","14.52019","0.01694"
"174.38400","14.53215","0.01959"
"174.52800","14.54422","0.01465"
"174.67200","14.55618","0.01420"
"174.81600","14.56814","0.01549"
"174.96000","14.58010","0.01810"
"175.10400","14.59223","0.01561"
"175.24800","14.60419","0.01436"
"175.39200","14.61621","0.01637"
"175.53600","14.62817","0.01894"
"175.68000","14.64025","0.01604"
"175.82400","14.65220","0.01446"
"175.96800","14.66416","0.01672"
"176.11200","14.67618","0.01761"
"176.25600","14.68826","0.01551"
"176.40000","14.70015","0.01419"
"176.54400","14.71211","0.01697"
"176.68800","14.72419","0.01539"
"176.83200","14.73621","0.01508"
"176.97600","14.74816","0.01642"
"177.12000","14.76012","0.01602"
"177.26400","14.77220","0.01531"
"177.40800","14.78422","0.01578"
"177.55200","14.79612","0.01606"
"177.69600","14.80819","0.01507"
"177.84000","14.82015","0.01659"
"177.98400","14.83217","0.01539"
"178.12800","14.84413","0.01530"
"178.27200","14.85620","0.01571"
"178.41600","14.86822","0.01645"
"178.56000","14.88018","0.01550"
"178.70400","14.89214","0.01574"
"178.84800","14.90422","0.01678"
"178.99200","14.91617","0.01580"
"179.13600","14.92819","0.01628"
"179.28000","14.94015","0.01646"
"179.42400","14.95217","0.01552"
"179.56800","14.96418","0.01533"
"179.71200","14.97614","0.01620"
"179.85600","14.98822","0.01614"
"180.00000","15.00024","0.01671"
"180.14400","15.01220","0.01607"
"180.28800","15.02409","0.01597"
"180.43200","15.03623","0.01677"
"180.57600","15.04819","0.01582"
"180.72000","15.06015","0.01585"
"180.86400","15.07217","0.01643"
"181.00800","15.08418","0.01642"
"181.15200","15.09620","0.01656"
"181.29600","15.10816","0.01646"
"181.44000","15.12018","0.01684"
"181.58400","15.13219","0.01596"
"181.72800","15.14421","0.01620"
"181.87200","15.15611","0.01646"
"182.01600","15.16825","0.01629"
"182.16000","15.18020","0.01617"
"182.30400","15.19216","0.01599"
"182.44800","15.20412","0.01620"
"182.59200","15.21620","0.01662"
"182.73600","15.22821","0.01642"
"182.88000","15.24017","0.01641"
"183.02400","15.25219","0.01653"
"183.16800","15.26421","0.01626"
"183.31200","15.27623","0.01691"
"183.45600","15.28818","0.01673"
"183.60000","15.30020","0.01650"
"183.74400","15.31222","0.01625"
"183.88800","15.32424","0.01712"
"184.03200","15.33614","0.01663"
"184.17600","15.34815","0.01654"
"184.32000","15.36023","0.01666"
"184.46400","15.37219","0.01709"
"184.60800","15.38415","0.01653"
"184.75200","15.39616","0.01698"
"184.89600","15.40824","0.01676"
"185.04000","15.42014","0.01695"
"185.18400","15.43222","0.01706"
"185.32800","15.44423","0.01713"
"185.47200","15.45619","0.01681"
"185.61600","15.46815","0.01702"
"185.76000","15.48017","0.01685"
"185.90400","15.49225","0.01676"
"186.04800","15.50420","0.01730"
"186.19200","15.51616","0.01689"
"186.33600","15.52824","0.01698"
"186.48000","15.54020","0.01679"
"186.62400","15.55216","0.01715"
"186.76800","15.56417","0.01657"
"186.91200","15.57619","0.01732"
"187.05600","15.58821","0.01730"
"187.20000","15.60017","0.01726"
"187.34400","15.61212","0.01724"
"187.48800","15.62420","0.01691"
"187.63200","15.63616","0.01734"
"187.77600","15.64818","0.01716"
"187.92000","15.66019","0.01722"
"188.06400","15.67221","0.01770"
"188.20800","15.68423","0.01711"
"188.35200","15.69619","0.01695"
"188.49600","15.70826","0.01735"
"188.64000","15.72022","0.01784"
"188.78400","15.73218","0.01724"
"188.92800","15.74420","0.01748"
"189.07200","15.75628","0.01713"
"189.21600","15.76823","0.01746"
"189.36000","15.78019","0.01742"
"189.50400","15.79221","0.01737"
"189.64800","15.80423","0.01748"
"189.79200","15.81625","0.01774"
"189.93600","15.82820","0.01761"
"190.08000","15.84022","0.01737"
"190.22400","15.85224","0.01795"
"190.36800","15.86425","0.01701"
"190.51200","15.87621","0.01747"
"190.65600","15.88823","0.01733"
"190.80000","15.90025","0.01724"
"190.94400","15.91215","0.01756"
"191.08800","15.92416","0.01735"
"191.23200","15.93624","0.01769"
"191.37600","15.94820","0.01743"
"191.52000","15.96016","0.01805"
"191.66400","15.97224","0.01767"
"191.80800","15.98425","0.01778"
"191.95200","15.99627","0.01787"
"192.09600","16.00817","0.01809"
"192.24000","16.02019","0.01742"
"192.38400","16.03220","0.01723"
"192.52800","16.04422","0.01783"
"192.67200","16.05618","0.01756"
"192.81600","16.06820","0.01769"
"192.96000","16.08022","0.01749"
"193.10400","16.09217","0.01737"
"193.24800","16.10425","0.01785"
"193.39200","16.11627","0.01823"
"193.53600","16.12829","0.01806"
"193.68000","16.14018","0.01768"
"193.82400","16.15220","0.01790"
"193.96800","16.16428","0.01769"
"194.11200","16.17624","0.01779"
"194.25600","16.18819","0.01758"
"194.40000","16.20021","0.01795"
"194.54400","16.21223","0.01772"
"194.68800","16.22419","0.01808"
"194.83200","16.23615","0.01786"
"194.97600","16.24817","0.01775"
"195.12000","16.26018","0.01800"
"195.26400","16.27214","0.01787"
"195.40800","16.28422","0.01765"
"195.55200","16.29623","0.01829"
"195.69600","16.30825","0.01799"
"195.84000","16.32021","0.01790"
"195.98400","16.33223","0.01819"
"196.12800","16.34425","0.01802"
"196.27200","16.35620","0.01826"
"196.41600","16.36816","0.01862"
"196.56000","16.38018","0.01798"
"196.70400","16.39226","0.01797"
"196.84800","16.40421","0.01822"
"196.99200","16.41623","0.01840"
"197.13600","16.42825","0.01844"
"197.28000","16.44021","0.01824"
"197.42400","16.45217","0.01819"
"197.56800","16.46418","0.01801"
"197.71200","16.47626","0.01842"
"197.85600","16.48822","0.01778"
"198.00000","16.50018","0.01830"
"198.14400","16.51220","0.01784"
"198.28800","16.52421","0.01766"
"198.43200","16.53617","0.01813"
"198.57600","16.54813","0.01850"
"198.72000","16.56021","0.01870"
"198.86400","16.57222","0.01778"
"199.00800","16.58418","0.01857"
"199.15200","16.59620","0.01820"
"199.29600","16.60828","0.01835"
"199.44000","16.62023","0.01832"
"199.58400","16.63219","0.01834"
"199.72800","16.64421","0.01846"
"199.87200","16.65623","0.01843"
"200.01600","16.66825","0.01845"
"200.16000","16.68014","0.01885"
"200.30400","16.69222","0.01844"
"200.44800","16.70424","0.01849"
"200.59200","16.71620","0.01875"
"200.73600","16.72816","0.01845"
"200.88000","16.74023","0.01870"
"201.02400","16.75225","0.01845"
"201.16800","16.76421","0.01866"
"201.31200","16.77622","0.01842"
"201.45600","16.78824","0.01864"
"201.60000","16.80026","0.01889"
"201.74400","16.81216","0.01858"
"201.88800","16.82418","0.01846"
"202.03200","16.83619","0.01859"
"202.17600","16.84821","0.01873"
"202.32000","16.86017","0.01868"
"202.46400","16.87219","0.01916"
"202.60800","16.88421","0.01872"
"202.75200","16.89622","0.01857"
"202.89600","16.90818","0.01839"
"203.04000","16.92020","0.01889"
"203.18400","16.93228","0.01899"
"203.32800","16.94417","0.01912"
"203.47200","16.95619","0.01877"
"203.61600","16.96815","0.01878"
"203.76000","16.98017","0.01884"
"203.90400","16.99213","0.01911"
"204.04800","17.00420","0.01887"
"204.19200","17.01622","0.01925"
"204.33600","17.02824","0.01883"
"204.48000","17.04020","0.01873"
"204.62400","17.05215","0.01958"
"204.76800","17.06417","0.01901"
"204.91200","17.07613","0.01886"
"205.05600","17.08815","0.01875"
"205.20000","17.10022","0.01863"
"205.34400","17.11218","0.01890"
"205.48800","17.12420","0.01861"
"205.63200","17.13616","0.01910"
"205.77600","17.14818","0.01941"
"205.92000","17.16019","0.01917"
"206.06400","17.17215","0.01940"
"206.20800","17.18417","0.01924"
"206.35200","17.19619","0.01907"
"206.49600","17.20821","0.01965"
"206.64000","17.22016","0.01927"
"206.78400","17.23218","0.01946"
"206.92800","17.24420","0.01958"
"207.07200","17.25616","0.01922"
"207.21600","17.26811","0.01965"
"207.36000","17.28025","0.01940"
"207.50400","17.29221","0.01945"
"207.64800","17.30417","0.01939"
"207.79200","17.31618","0.01987"
"207.93600","17.32820","0.02001"
"208.08000","17.34022","0.01962"
"208.22400","17.35218","0.01980"
"208.36800","17.36420","0.01980"
"208.51200","17.37621","0.01955"
"208.65600","17.38817","0.02028"
"208.80000","17.40013","0.01971"
"208.94400","17.41221","0.01972"
"209.08800","17.42422","0.02013"
"209.23200","17.43618","0.01976"
"209.37600","17.44814","0.02004"
"209.52000","17.46022","0.01725"
"209.66400","17.47223","0.01423"
"209.80800","17.48413","0.01447"
"209.95200","17.49615","0.01440"
"210.09600","17.50823","0.01435"
"210.24000","17.52019","0.01441"
"210.38400","17.53214","0.01405"
"210.52800","17.54416","0.01397"
"210.67200","17.55624","0.01400"
"210.81600","17.56820","0.01427"
"210.96000","17.58015","0.01389"
"211.10400","17.59217","0.01430"
"211.24800","17.60419","0.01395"
"211.39200","17.61615","0.01437"
"211.53600","17.62817","0.01398"
"211.68000","17.64024","0.01421"
"211.82400","17.65226","0.01374"
"211.96800","17.66422","0.01440"
"212.11200","17.67624","0.01401"
"212.25600","17.68819","0.01362"
"212.40000","17.70021","0.01397"
"212.54400","17.71211","0.01404"
"212.68800","17.72419","0.01426"
"212.83200","17.73615","0.01392"
"212.97600","17.74816","0.01435"
"213.12000","17.76012","0.01322"
"213.26400","17.77220","0.01386"
"213.40800","17.78416","0.01434"
"213.55200","17.79618","0.01388"
"213.69600","17.80819","0.01416"
"213.84000","17.82021","0.01400"
"213.98400","17.83217","0.01375"
"214.12800","17.84418","0.01389"
"214.27200","17.85620","0.01367"
"214.41600","17.86816","0.01352"
"214.56000","17.88018","0.01393"
"214.70400","17.89214","0.01401"
"214.84800","17.90421","0.01416"
"214.99200","17.91617","0.01386"
"215.12600","17.92735","0.01419"