File: Force_trajectories/170212_1/Specimen_RawData_7.csv
End date,"2/12/2017"
Specimen label,"9DT_73"
Maximum Load,"0.29008",N

Time,Extension,Load
(s),(mm),(N)
"0.00000","0.00000","-0.00057"
"0.21000","0.01519","0.00143"
"0.42000","0.03528","0.00097"
"0.63000","0.05267","0.00157"
"0.84000","0.07019","0.00216"
"1.05000","0.08777","0.00195"
"1.26000","0.10517","0.00324"
"1.47000","0.12281","0.00292"
"1.68000","0.14015","0.00351"
"1.89000","0.15766","0.00416"
"2.10000","0.17518","0.00421"
"2.31000","0.19270","0.00478"
"2.52000","0.21022","0.00471"
"2.73000","0.22768","0.00480"
"2.94000","0.24514","0.00575"
"3.15000","0.26272","0.00570"
"3.36000","0.28017","0.00612"
"3.57000","0.29775","0.00648"
"3.78000","0.31521","0.00570"
"3.99000","0.33267","0.00667"
"4.20000","0.35019","0.00626"
"4.41000","0.36771","0.00735"
"4.62000","0.38522","0.00721"
"4.83000","0.40274","0.00744"
"5.04000","0.42014","0.00876"
"5.25000","0.43772","0.00725"
"5.46000","0.45518","0.00886"
"5.67000","0.47264","0.00911"
"5.88000","0.49021","0.00864"
"6.09000","0.50767","0.00942"
"6.30000","0.52525","0.00930"
"6.51000","0.54265","0.01020"
"6.72000","0.56017","0.01002"
"6.93000","0.57775","0.01047"
"7.14000","0.59520","0.01099"
"7.35000","0.61272","0.01011"
"7.56000","0.63024","0.01028"
"7.77000","0.64764","0.01083"
"7.98000","0.66522","0.01038"
"8.19000","0.68268","0.01107"
"8.40000","0.70014","0.01128"
"8.61000","0.71771","0.01116"
"8.82000","0.73511","0.01135"
"9.03000","0.75275","0.01114"
"9.24000","0.77021","0.01205"
"9.45000","0.78767","0.01143"
"9.66000","0.80513","0.01213"
"9.87000","0.82264","0.01231"
"10.08000","0.84016","0.01218"
"10.29000","0.85774","0.01211"
"10.50000","0.87520","0.01177"
"10.71000","0.89272","0.01221"
"10.92000","0.91018","0.01253"
"11.13000","0.92769","0.01169"
"11.34000","0.94521","0.01265"
"11.55000","0.96267","0.01246"
"11.76000","0.98025","0.01260"
"11.97000","0.99765","0.01289"
"12.18000","1.01523","0.01311"
"12.39000","1.03268","0.01277"
"12.60000","1.05020","0.01230"
"12.81000","1.06766","0.01316"
"13.02000","1.08518","0.01360"
"13.23000","1.10270","0.01389"
"13.44000","1.12022","0.01328"
"13.65000","1.13762","0.01361"
"13.86000","1.15525","0.01357"
"14.07000","1.17271","0.01404"
"14.28000","1.19017","0.01370"
"14.49000","1.20769","0.01391"
"14.70000","1.22515","0.01375"
"14.91000","1.24273","0.01391"
"15.12000","1.26024","0.01456"
"15.33000","1.27770","0.01381"
"15.54000","1.29522","0.01404"
"15.75000","1.31268","0.01404"
"15.96000","1.33020","0.01426"
"16.17000","1.34772","0.01416"
"16.38000","1.36511","0.01399"
"16.59000","1.38269","0.01491"
"16.80000","1.40015","0.01436"
"17.01000","1.41773","0.01446"
"17.22000","1.43525","0.01535"
"17.43000","1.45259","0.01476"
"17.64000","1.47022","0.01435"
"17.85000","1.48768","0.01482"
"18.06000","1.50520","0.01479"
"18.27000","1.52272","0.01466"
"18.48000","1.54012","0.01471"
"18.69000","1.55776","0.01444"
"18.90000","1.57522","0.01550"
"19.11000","1.59267","0.01504"
"19.32000","1.61019","0.01479"
"19.53000","1.62765","0.01523"
"19.74000","1.64517","0.01587"
"19.95000","1.66269","0.01551"
"20.16000","1.68015","0.01539"
"20.37000","1.69772","0.01550"
"20.58000","1.71512","0.01561"
"20.79000","1.73276","0.01565"
"21.00000","1.75022","0.01560"
"21.21000","1.76768","0.01628"
"21.42000","1.78520","0.01629"
"21.63000","1.80265","0.01603"
"21.84000","1.82023","0.01546"
"22.05000","1.83775","0.01548"
"22.26000","1.85521","0.01538"
"22.47000","1.87273","0.01577"
"22.68000","1.89019","0.01556"
"22.89000","1.90764","0.01643"
"23.10000","1.92522","0.01580"
"23.31000","1.94268","0.01506"
"23.52000","1.96026","0.01599"
"23.73000","1.97766","0.01621"
"23.94000","1.99518","0.01590"
"24.15000","2.01269","0.01665"
"24.36000","2.03015","0.01650"
"24.57000","2.04773","0.01616"
"24.78000","2.06525","0.01620"
"24.99000","2.08271","0.01619"
"25.20000","2.10023","0.01726"
"25.41000","2.11763","0.01636"
"25.62000","2.13520","0.01633"
"25.83000","2.15272","0.01623"
"26.04000","2.17012","0.01634"
"26.25000","2.18770","0.01680"
"26.46000","2.20522","0.01696"
"26.67000","2.22274","0.01697"
"26.88000","2.24019","0.01700"
"27.09000","2.25765","0.01645"
"27.30000","2.27517","0.01701"
"27.51000","2.29269","0.01717"
"27.72000","2.31015","0.01743"
"27.93000","2.32767","0.01698"
"28.14000","2.34518","0.01752"
"28.35000","2.36270","0.01758"
"28.56000","2.38022","0.01779"
"28.77000","2.39768","0.01751"
"28.98000","2.41520","0.01767"
"29.19000","2.43266","0.01820"
"29.40000","2.45023","0.01772"
"29.61000","2.46775","0.01811"
"29.82000","2.48515","0.01829"
"30.03000","2.50273","0.01817"
"30.24000","2.52019","0.01816"
"30.45000","2.53771","0.01880"
"30.66000","2.55523","0.01829"
"30.87000","2.57262","0.01817"
"31.08000","2.59020","0.01812"
"31.29000","2.60766","0.01828"
"31.50000","2.62518","0.01819"
"31.71000","2.64270","0.01809"
"31.92000","2.66016","0.01883"
"32.13000","2.67779","0.01869"
"32.34000","2.69519","0.01869"
"32.55000","2.71271","0.01846"
"32.76000","2.73017","0.01904"
"32.97000","2.74769","0.01871"
"33.18000","2.76521","0.01857"
"33.39000","2.78272","0.01850"
"33.60000","2.80018","0.01895"
"33.81000","2.81770","0.01912"
"34.02000","2.83516","0.01938"
"34.23000","2.85268","0.01958"
"34.44000","2.87026","0.01920"
"34.65000","2.88766","0.01976"
"34.86000","2.90523","0.01985"
"35.07000","2.92269","0.01955"
"35.28000","2.94021","0.02007"
"35.49000","2.95773","0.02003"
"35.70000","2.97519","0.02000"
"35.91000","2.99271","0.02062"
"36.12000","3.01022","0.02020"
"36.33000","3.02768","0.02029"
"36.54000","3.04520","0.02002"
"36.75000","3.06260","0.02074"
"36.96000","3.08024","0.02066"
"37.17000","3.09770","0.02043"
"37.38000","3.11515","0.02038"
"37.59000","3.13273","0.02123"
"37.80000","3.15019","0.02110"
"38.01000","3.16771","0.02084"
"38.22000","3.18523","0.02058"
"38.43000","3.20269","0.02068"
"38.64000","3.22020","0.02059"
"38.85000","3.23766","0.02089"
"39.06000","3.25518","0.02070"
"39.27000","3.27276","0.02109"
"39.48000","3.29016","0.02085"
"39.69000","3.30774","0.02131"
"39.90000","3.32520","0.01950"
"40.11000","3.34265","0.02009"
"40.32000","3.36023","0.02001"
"40.53000","3.37769","0.02017"
"40.74000","3.39527","0.02019"
"40.95000","3.41267","0.02047"
"41.16000","3.43019","0.02089"
"41.37000","3.44770","0.02108"
"41.58000","3.46516","0.02077"
"41.79000","3.48268","0.02079"
"42.00000","3.50020","0.01988"
"42.21000","3.51766","0.02015"
"42.42000","3.53518","0.02027"
"42.63000","3.55269","0.02015"
"42.84000","3.57015","0.02057"
"43.05000","3.58773","0.02069"
"43.26000","3.60513","0.02028"
"43.47000","3.62271","0.02081"
"43.68000","3.64017","0.02093"
"43.89000","3.65768","0.02082"
"44.10000","3.67520","0.02094"
"44.31000","3.69272","0.02096"
"44.52000","3.71024","0.01975"
"44.73000","3.72776","0.02009"
"44.94000","3.74516","0.01977"
"45.15000","3.76268","0.02057"
"45.36000","3.78019","0.01967"
"45.57000","3.79771","0.01992"
"45.78000","3.81517","0.01981"
"45.99000","3.83263","0.02103"
"46.20000","3.85021","0.02095"
"46.41000","3.86767","0.02063"
"46.62000","3.88524","0.02113"
"46.83000","3.90270","0.02061"
"47.04000","3.92010","0.02110"
"47.25000","3.93768","0.02149"
"47.46000","3.95520","0.02139"
"47.67000","3.97272","0.02120"
"47.88000","3.99023","0.02115"
"48.09000","4.00763","0.02145"
"48.30000","4.02521","0.02189"
"48.51000","4.04273","0.02185"
"48.72000","4.06013","0.02122"
"48.93000","4.07777","0.02181"
"49.14000","4.09516","0.02261"
"49.35000","4.11274","0.02257"
"49.56000","4.13014","0.02261"
"49.77000","4.14772","0.02295"
"49.98000","4.16518","0.02267"
"50.19000","4.18270","0.02303"
"50.40000","4.20021","0.02310"
"50.61000","4.21767","0.02257"
"50.82000","4.23519","0.02356"
"51.03000","4.25265","0.02426"
"51.24000","4.27017","0.02426"
"51.45000","4.28769","0.02371"
"51.66000","4.30521","0.02448"
"51.87000","4.32260","0.02404"
"52.08000","4.34024","0.02396"
"52.29000","4.35770","0.02454"
"52.50000","4.37522","0.02506"
"52.71000","4.39268","0.02538"
"52.92000","4.41020","0.02542"
"53.13000","4.42771","0.02534"
"53.34000","4.44517","0.02576"
"53.55000","4.46263","0.02525"
"53.76000","4.48021","0.02572"
"53.97000","4.49767","0.02571"
"54.18000","4.51519","0.02601"
"54.39000","4.53270","0.02632"
"54.60000","4.55016","0.02695"
"54.81000","4.56768","0.02593"
"55.02000","4.58514","0.02685"
"55.23000","4.60272","0.02701"
"55.44000","4.62018","0.02712"
"55.65000","4.63769","0.02726"
"55.86000","4.65521","0.02728"
"56.07000","4.67267","0.02710"
"56.28000","4.69019","0.02738"
"56.49000","4.70771","0.02771"
"56.70000","4.72511","0.02791"
"56.91000","4.74274","0.02827"
"57.12000","4.76020","0.02839"
"57.33000","4.77766","0.02833"
"57.54000","4.79524","0.02854"
"57.75000","4.81264","0.02916"
"57.96000","4.83022","0.02840"
"58.17000","4.84768","0.02894"
"58.38000","4.86513","0.02907"
"58.59000","4.88277","0.02908"
"58.80000","4.90017","0.02973"
"59.01000","4.91769","0.02895"
"59.22000","4.93521","0.02984"
"59.43000","4.95267","0.02965"
"59.64000","4.97018","0.03057"
"59.85000","4.98764","0.03062"
"60.06000","5.00522","0.03061"
"60.27000","5.02268","0.03056"
"60.48000","5.04008","0.03111"
"60.69000","5.05772","0.03039"
"60.90000","5.07517","0.02851"
"61.11000","5.09263","0.02908"
"61.32000","5.11021","0.02966"
"61.53000","5.12767","0.03037"
"61.74000","5.14519","0.03063"
"61.95000","5.16271","0.03056"
"62.16000","5.18017","0.03071"
"62.37000","5.19768","0.03150"
"62.58000","5.21520","0.03136"
"62.79000","5.23266","0.03226"
"63.00000","5.25018","0.03188"
"63.21000","5.26764","0.03225"
"63.42000","5.28522","0.03133"
"63.63000","5.30267","0.03168"
"63.84000","5.32019","0.03236"
"64.05000","5.33771","0.03232"
"64.26000","5.35517","0.03260"
"64.47000","5.37269","0.03340"
"64.68000","5.39021","0.03327"
"64.89000","5.40766","0.03396"
"65.10000","5.42524","0.03376"
"65.31000","5.44264","0.03423"
"65.52000","5.46022","0.03477"
"65.73000","5.47768","0.03536"
"65.94000","5.49520","0.03542"
"66.15000","5.51271","0.03574"
"66.36000","5.53017","0.03515"
"66.57000","5.54775","0.03548"
"66.78000","5.56515","0.03575"
"66.99000","5.58273","0.03657"
"67.20000","5.60019","0.03729"
"67.41000","5.61765","0.03701"
"67.62000","5.63522","0.03735"
"67.83000","5.65274","0.03706"
"68.04000","5.67020","0.03732"
"68.25000","5.68772","0.03839"
"68.46000","5.70518","0.03878"
"68.67000","5.72270","0.03904"
"68.88000","5.74021","0.03967"
"69.09000","5.75761","0.04025"
"69.30000","5.77519","0.04009"
"69.51000","5.79271","0.03979"
"69.72000","5.81017","0.04054"
"69.93000","5.82769","0.04061"
"70.14000","5.84514","0.04081"
"70.35000","5.86272","0.04108"
"70.56000","5.88018","0.04146"
"70.77000","5.89764","0.04168"
"70.98000","5.91522","0.04229"
"71.19000","5.93268","0.04255"
"71.40000","5.95019","0.04260"
"71.61000","5.96771","0.04310"
"71.82000","5.98517","0.04333"
"72.03000","6.00269","0.04304"
"72.24000","6.02015","0.04368"
"72.45000","6.03773","0.04425"
"72.66000","6.05518","0.04474"
"72.87000","6.07270","0.04455"
"73.08000","6.09016","0.04497"
"73.29000","6.10768","0.04482"
"73.50000","6.12520","0.04514"
"73.71000","6.14272","0.04561"
"73.92000","6.16012","0.04598"
"74.13000","6.17775","0.04632"
"74.34000","6.19521","0.04641"
"74.55000","6.21273","0.04690"
"74.76000","6.23025","0.04703"
"74.97000","6.24765","0.04693"
"75.18000","6.26523","0.04753"
"75.39000","6.28268","0.04784"
"75.60000","6.30020","0.04813"
"75.81000","6.31772","0.04859"
"76.02000","6.33518","0.04874"
"76.23000","6.35270","0.04885"
"76.44000","6.37028","0.04970"
"76.65000","6.38767","0.04993"
"76.86000","6.40519","0.05056"
"77.07000","6.42259","0.05056"
"77.28000","6.44017","0.05148"
"77.49000","6.45769","0.05165"
"77.70000","6.47515","0.05228"
"77.91000","6.49272","0.05277"
"78.12000","6.51018","0.05322"
"78.33000","6.52770","0.05424"
"78.54000","6.54516","0.05503"
"78.75000","6.56268","0.05633"
"78.96000","6.58020","0.05688"
"79.17000","6.59766","0.05719"
"79.38000","6.61517","0.05801"
"79.59000","6.63269","0.05903"
"79.80000","6.65015","0.06029"
"80.01000","6.66773","0.06087"
"80.22000","6.68519","0.06219"
"80.43000","6.70265","0.06240"
"80.64000","6.72022","0.06304"
"80.85000","6.73768","0.06420"
"81.06000","6.75526","0.06527"
"81.27000","6.77272","0.06496"
"81.48000","6.79018","0.06216"
"81.69000","6.80770","0.05170"
"81.90000","6.82521","0.05193"
"82.11000","6.84273","0.05276"
"82.32000","6.86025","0.05389"
"82.53000","6.87759","0.05420"
"82.74000","6.89523","0.05537"
"82.95000","6.91269","0.05545"
"83.16000","6.93020","0.05620"
"83.37000","6.94772","0.05691"
"83.58000","6.96518","0.05782"
"83.79000","6.98276","0.05883"
"84.00000","7.00016","0.05943"
"84.21000","7.01768","0.06077"
"84.42000","7.03519","0.06134"
"84.63000","7.05271","0.06077"
"84.84000","7.07023","0.06256"
"85.05000","7.08775","0.06356"
"85.26000","7.10515","0.06421"
"85.47000","7.12273","0.06498"
"85.68000","7.14019","0.06610"
"85.89000","7.15764","0.06622"
"86.10000","7.17522","0.06873"
"86.31000","7.19262","0.06857"
"86.52000","7.21020","0.06871"
"86.73000","7.22766","0.07016"
"86.94000","7.24518","0.07127"
"87.15000","7.26275","0.07259"
"87.36000","7.28015","0.07346"
"87.57000","7.29773","0.07477"
"87.78000","7.31525","0.07488"
"87.99000","7.33265","0.07621"
"88.20000","7.35023","0.07728"
"88.41000","7.36769","0.07693"
"88.62000","7.38520","0.03055"
"88.83000","7.40266","0.02014"
"89.04000","7.42018","0.02696"
"89.25000","7.43776","0.02251"
"89.46000","7.45516","0.02657"
"89.67000","7.47273","0.02284"
"89.88000","7.49019","0.02831"
"90.09000","7.50765","0.02380"
"90.30000","7.52517","0.02928"
"90.51000","7.54269","0.02628"
"90.72000","7.56021","0.02935"
"90.93000","7.57773","0.02972"
"91.14000","7.59512","0.03040"
"91.35000","7.61270","0.03053"
"91.56000","7.63022","0.03205"
"91.77000","7.64768","0.03104"
"91.98000","7.66526","0.03402"
"92.19000","7.68266","0.03179"
"92.40000","7.70023","0.03434"
"92.61000","7.71769","0.03305"
"92.82000","7.73521","0.03202"
"93.03000","7.75273","0.03332"
"93.24000","7.77019","0.03181"
"93.45000","7.78777","0.03481"
"93.66000","7.80522","0.03337"
"93.87000","7.82268","0.03505"
"94.08000","7.84020","0.03492"
"94.29000","7.85772","0.03533"
"94.50000","7.87524","0.03678"
"94.71000","7.89276","0.03670"
"94.92000","7.91010","0.03659"
"95.13000","7.92773","0.03538"
"95.34000","7.94519","0.03535"
"95.55000","7.96277","0.03678"
"95.76000","7.98017","0.03601"
"95.97000","7.99769","0.03716"
"96.18000","8.01521","0.03763"
"96.39000","8.03272","0.03776"
"96.60000","8.05018","0.03893"
"96.81000","8.06770","0.03794"
"97.02000","8.08516","0.03890"
"97.23000","8.10268","0.03844"
"97.44000","8.12014","0.03837"
"97.65000","8.13765","0.03966"
"97.86000","8.15523","0.03893"
"98.07000","8.17263","0.04008"
"98.28000","8.19021","0.03840"
"98.49000","8.20773","0.04046"
"98.70000","8.22519","0.04065"
"98.91000","8.24271","0.04079"
"99.12000","8.26016","0.04165"
"99.33000","8.27768","0.04090"
"99.54000","8.29526","0.04222"
"99.75000","8.31266","0.04253"
"99.96000","8.33024","0.04306"
"100.17000","8.34769","0.04350"
"100.38000","8.36515","0.04373"
"100.59000","8.38273","0.04469"
"100.80000","8.40019","0.04475"
"101.01000","8.41777","0.04572"
"101.22000","8.43517","0.04602"
"101.43000","8.45269","0.04681"
"101.64000","8.47020","0.04695"
"101.85000","8.48766","0.04715"
"102.06000","8.50518","0.04824"
"102.27000","8.52270","0.04832"
"102.48000","8.54016","0.04924"
"102.69000","8.55768","0.04943"
"102.90000","8.57513","0.05039"
"103.11000","8.59271","0.05126"
"103.32000","8.61023","0.05191"
"103.53000","8.62763","0.05317"
"103.74000","8.64521","0.05372"
"103.95000","8.66267","0.05541"
"104.16000","8.68018","0.05543"
"104.37000","8.69764","0.05709"
"104.58000","8.71516","0.05793"
"104.79000","8.73274","0.05891"
"105.00000","8.75026","0.06058"
"105.21000","8.76766","0.06188"
"105.42000","8.78518","0.06453"
"105.63000","8.80263","0.06501"
"105.84000","8.82015","0.06772"
"106.05000","8.83767","0.06876"
"106.26000","8.85519","0.07084"
"106.47000","8.87271","0.07231"
"106.68000","8.89017","0.07405"
"106.89000","8.90774","0.07488"
"107.10000","8.92520","0.07742"
"107.31000","8.94266","0.07920"
"107.52000","8.96024","0.08134"
"107.73000","8.97770","0.08321"
"107.94000","8.99522","0.08397"
"108.15000","9.01273","0.08615"
"108.36000","9.03019","0.08825"
"108.57000","9.04771","0.08967"
"108.78000","9.06517","0.09124"
"108.99000","9.08269","0.09249"
"109.20000","9.10021","0.09376"
"109.41000","9.11766","0.09476"
"109.62000","9.13524","0.09574"
"109.83000","9.15270","0.09663"
"110.04000","9.17016","0.09778"
"110.25000","9.18774","0.09912"
"110.46000","9.20520","0.10060"
"110.67000","9.22272","0.10222"
"110.88000","9.24023","0.10372"
"111.09000","9.25769","0.10619"
"111.30000","9.27521","0.10797"
"111.51000","9.29267","0.11070"
"111.72000","9.31019","0.11353"
"111.93000","9.32771","0.11559"
"112.14000","9.34510","0.11818"
"112.35000","9.36274","0.12037"
"112.56000","9.38020","0.12289"
"112.77000","9.39772","0.12432"
"112.98000","9.41518","0.12661"
"113.19000","9.43270","0.12842"
"113.40000","9.45015","0.13017"
"113.61000","9.46767","0.13182"
"113.82000","9.48513","0.13296"
"114.03000","9.50271","0.13396"
"114.24000","9.52011","0.13585"
"114.45000","9.53775","0.13689"
"114.66000","9.55520","0.13815"
"114.87000","9.57266","0.13867"
"115.08000","9.59018","0.13988"
"115.29000","9.60770","0.14070"
"115.50000","9.62522","0.14189"
"115.71000","9.64274","0.14297"
"115.92000","9.66019","0.14395"
"116.13000","9.67771","0.14488"
"116.34000","9.69523","0.14636"
"116.55000","9.71269","0.14802"
"116.76000","9.73021","0.14918"
"116.97000","9.74761","0.15144"
"117.18000","9.76525","0.15319"
"117.39000","9.78270","0.15581"
"117.60000","9.80022","0.15913"
"117.81000","9.81774","0.16174"
"118.02000","9.83514","0.16635"
"118.23000","9.85278","0.16939"
"118.44000","9.87012","0.17310"
"118.65000","9.88769","0.17695"
"118.86000","9.90521","0.18098"
"119.07000","9.92267","0.18420"
"119.28000","9.94019","0.18904"
"119.49000","9.95771","0.19153"
"119.70000","9.97517","0.19480"
"119.91000","9.99274","0.19648"
"120.12000","10.01014","0.19913"
"120.33000","10.02772","0.20066"
"120.54000","10.04524","0.20226"
"120.75000","10.06264","0.20351"
"120.96000","10.08022","0.20528"
"121.17000","10.09768","0.20769"
"121.38000","10.11519","0.20937"
"121.59000","10.13271","0.21184"
"121.80000","10.15023","0.21514"
"122.01000","10.16769","0.21748"
"122.22000","10.18521","0.22056"
"122.43000","10.20267","0.22310"
"122.64000","10.22018","0.22556"
"122.85000","10.23764","0.22786"
"123.06000","10.25516","0.23099"
"123.27000","10.27268","0.23382"
"123.48000","10.29014","0.23579"
"123.69000","10.30772","0.23836"
"123.90000","10.32511","0.23983"
"124.11000","10.34275","0.24180"
"124.32000","10.36021","0.24317"
"124.53000","10.37767","0.24424"
"124.74000","10.39519","0.24505"
"124.95000","10.41271","0.24638"
"125.16000","10.43022","0.24669"
"125.37000","10.44774","0.15330"
"125.58000","10.46508","0.10277"
"125.79000","10.48272","0.09323"
"126.00000","10.50018","0.09964"
"126.21000","10.51770","0.09673"
"126.42000","10.53522","0.09846"
"126.63000","10.55267","0.09953"
"126.84000","10.57025","0.10025"
"127.05000","10.58771","0.10409"
"127.26000","10.60517","0.10437"
"127.47000","10.62269","0.11166"
"127.68000","10.64020","0.10826"
"127.89000","10.65772","0.11981"
"128.10000","10.67524","0.11363"
"128.31000","10.69270","0.12406"
"128.52000","10.71016","0.11878"
"128.73000","10.72774","0.12752"
"128.94000","10.74520","0.12196"
"129.15000","10.76271","0.13071"
"129.36000","10.78011","0.12565"
"129.57000","10.79769","0.13272"
"129.78000","10.81515","0.12941"
"129.99000","10.83273","0.13481"
"130.20000","10.85019","0.13260"
"130.41000","10.86770","0.13728"
"130.62000","10.88528","0.13454"
"130.83000","10.90268","0.13859"
"131.04000","10.92020","0.13719"
"131.25000","10.93766","0.14032"
"131.46000","10.95518","0.13407"
"131.67000","10.97269","0.13365"
"131.88000","10.99015","0.13384"
"132.09000","11.00767","0.13612"
"132.30000","11.02519","0.13537"
"132.51000","11.04265","0.13695"
"132.72000","11.06023","0.13764"
"132.93000","11.07769","0.13500"
"133.14000","11.09520","0.13411"
"133.35000","11.11266","0.13501"
"133.56000","11.13018","0.13574"
"133.77000","11.14770","0.13664"
"133.98000","11.16522","0.13747"
"134.19000","11.18262","0.13857"
"134.40000","11.20019","0.13862"
"134.61000","11.21771","0.13996"
"134.82000","11.23517","0.14017"
"135.03000","11.25275","0.14131"
"135.24000","11.27015","0.14204"
"135.45000","11.28773","0.14276"
"135.66000","11.30512","0.14372"
"135.87000","11.32270","0.14464"
"136.08000","11.34028","0.14557"
"136.29000","11.35768","0.14639"
"136.50000","11.37526","0.14738"
"136.71000","11.39272","0.14835"
"136.92000","11.41017","0.14988"
"137.13000","11.42769","0.15134"
"137.34000","11.44521","0.15275"
"137.55000","11.46267","0.15485"
"137.76000","11.48025","0.15694"
"137.97000","11.49759","0.15900"
"138.18000","11.51523","0.16092"
"138.39000","11.53268","0.16422"
"138.60000","11.55020","0.16605"
"138.81000","11.56766","0.16833"
"139.02000","11.58518","0.17197"
"139.23000","11.60270","0.17400"
"139.44000","11.62022","0.17658"
"139.65000","11.63767","0.17934"
"139.86000","11.65519","0.18229"
"140.07000","11.67265","0.18582"
"140.28000","11.69017","0.18759"
"140.49000","11.70769","0.19017"
"140.70000","11.72515","0.19235"
"140.91000","11.74272","0.19483"
"141.12000","11.76012","0.19628"
"141.33000","11.77770","0.19770"
"141.54000","11.79522","0.19908"
"141.75000","11.81268","0.19965"
"141.96000","11.83020","0.20094"
"142.17000","11.84765","0.20212"
"142.38000","11.86523","0.20266"
"142.59000","11.88275","0.20441"
"142.80000","11.90015","0.20578"
"143.01000","11.91773","0.20659"
"143.22000","11.93519","0.20878"
"143.43000","11.95271","0.20953"
"143.64000","11.97022","0.21196"
"143.85000","11.98768","0.21349"
"144.06000","12.00520","0.21528"
"144.27000","12.02266","0.21637"
"144.48000","12.04018","0.21930"
"144.69000","12.05769","0.22148"
"144.90000","12.07521","0.22381"
"145.11000","12.09267","0.22576"
"145.32000","12.11025","0.22804"
"145.53000","12.12765","0.22996"
"145.74000","12.14517","0.23200"
"145.95000","12.16263","0.23336"
"146.16000","12.18020","0.23531"
"146.37000","12.19772","0.23723"
"146.58000","12.21506","0.23887"
"146.79000","12.23276","0.24015"
"147.00000","12.25016","0.24157"
"147.21000","12.26768","0.24269"
"147.42000","12.28525","0.24384"
"147.63000","12.30265","0.24482"
"147.84000","12.32023","0.24557"
"148.05000","12.33775","0.24645"
"148.26000","12.35521","0.24713"
"148.47000","12.37273","0.24803"
"148.68000","12.39019","0.24871"
"148.89000","12.40770","0.24830"
"149.10000","12.42522","0.24950"
"149.31000","12.44268","0.25032"
"149.52000","12.46026","0.25139"
"149.73000","12.47766","0.25207"
"149.94000","12.49529","0.25243"
"150.15000","12.51269","0.25104"
"150.36000","12.53021","0.25170"
"150.57000","12.54767","0.25254"
"150.78000","12.56519","0.25375"
"150.99000","12.58271","0.25497"
"151.20000","12.60023","0.25620"
"151.41000","12.61768","0.25733"
"151.62000","12.63520","0.25859"
"151.83000","12.65266","0.25877"
"152.04000","12.67018","0.26020"
"152.25000","12.68770","0.26069"
"152.46000","12.70516","0.26273"
"152.67000","12.72273","0.26481"
"152.88000","12.74019","0.26681"
"153.09000","12.75771","0.26865"
"153.30000","12.77523","0.27022"
"153.51000","12.79269","0.27232"
"153.72000","12.81021","0.27398"
"153.93000","12.82773","0.27550"
"154.14000","12.84518","0.27686"
"154.35000","12.86270","0.27819"
"154.56000","12.88016","0.27924"
"154.77000","12.89768","0.25399"
"154.98000","12.91520","0.25234"
"155.19000","12.93266","0.25308"
"155.40000","12.95017","0.25264"
"155.61000","12.96769","0.25445"
"155.82000","12.98521","0.25433"
"156.03000","13.00267","0.25586"
"156.24000","13.02019","0.25658"
"156.45000","13.03771","0.25698"
"156.66000","13.05522","0.25635"
"156.87000","13.07262","0.25580"
"157.08000","13.09020","0.25522"
"157.29000","13.10766","0.25592"
"157.50000","13.12524","0.25719"
"157.71000","13.14276","0.25847"
"157.92000","13.16016","0.25824"
"158.13000","13.17773","0.25931"
"158.34000","13.19513","0.26020"
"158.55000","13.21271","0.26232"
"158.76000","13.23023","0.26343"
"158.97000","13.24763","0.26519"
"159.18000","13.26527","0.26612"
"159.39000","13.28266","0.26715"
"159.60000","13.30024","0.26967"
"159.81000","13.31770","0.27053"
"160.02000","13.33510","0.27229"
"160.23000","13.35274","0.27416"
"160.44000","13.37020","0.27525"
"160.65000","13.38771","0.27715"
"160.86000","13.40517","0.27818"
"161.07000","13.42269","0.27976"
"161.28000","13.44027","0.27593"
"161.49000","13.45767","0.27560"
"161.70000","13.47519","0.27300"
"161.91000","13.49270","0.27183"
"162.12000","13.51022","0.26690"
"162.33000","13.52768","0.26659"
"162.54000","13.54526","0.26761"
"162.75000","13.56266","0.26606"
"162.96000","13.58018","0.26488"
"163.17000","13.59764","0.26583"
"163.38000","13.61521","0.26704"
"163.59000","13.63273","0.26849"
"163.80000","13.65013","0.26940"
"164.01000","13.66777","0.27086"
"164.22000","13.68517","0.26598"
"164.43000","13.70268","0.26641"
"164.64000","13.72020","0.26729"
"164.85000","13.73766","0.26832"
"165.06000","13.75518","0.26982"
"165.27000","13.77270","0.27063"
"165.48000","13.79016","0.27180"
"165.69000","13.80773","0.27359"
"165.90000","13.82513","0.27425"
"166.11000","13.84271","0.27615"
"166.32000","13.86017","0.27697"
"166.53000","13.87763","0.27912"
"166.74000","13.89515","0.28000"
"166.95000","13.91267","0.28184"
"167.16000","13.93018","0.28247"
"167.37000","13.94770","0.28331"
"167.58000","13.96522","0.28501"
"167.79000","13.98268","0.28604"
"168.00000","14.00020","0.28719"
"168.21000","14.01772","0.28736"
"168.42000","14.03524","0.28883"
"168.63000","14.05263","0.28919"
"168.84000","14.07021","0.29008"
"169.05000","14.08773","0.13784"
"169.26000","14.10519","0.13075"
"169.47000","14.12271","0.13451"
"169.68000","14.14016","0.13403"
"169.89000","14.15780","0.13634"
"170.10000","14.17514","0.13698"
"170.31000","14.19272","0.13756"
"170.52000","14.21024","0.13992"
"170.73000","14.22770","0.13876"
"170.94000","14.24522","0.14078"
"171.15000","14.26273","0.14042"
"171.36000","14.28019","0.14168"
"171.57000","14.29771","0.14234"
"171.78000","14.31523","0.14361"
"171.99000","14.33269","0.14354"
"172.20000","14.35021","0.14592"
"172.41000","14.36760","0.14461"
"172.62000","14.38518","0.14789"
"172.83000","14.40264","0.14734"
"173.04000","14.42016","0.14861"
"173.25000","14.43768","0.15071"
"173.46000","14.45520","0.15067"
"173.67000","14.47271","0.15200"
"173.88000","14.49023","0.15392"
"174.09000","14.50769","0.15573"
"174.30000","14.52521","0.15658"
"174.51000","14.54267","0.16184"
"174.72000","14.56019","0.15838"
"174.93000","14.57765","0.16451"
"175.14000","14.59516","0.16265"
"175.35000","14.61274","0.16814"
"175.56000","14.63014","0.16685"
"175.77000","14.64772","0.17237"
"175.98000","14.66524","0.17025"
"176.19000","14.68264","0.17778"
"176.40000","14.70021","0.17557"
"176.61000","14.71767","0.18087"
"176.82000","14.73519","0.18074"
"177.03000","14.75271","0.18470"
"177.24000","14.77011","0.18472"
"177.45000","14.78774","0.18839"
"177.66000","14.80520","0.18847"
"177.87000","14.82266","0.19092"
"178.08000","14.84024","0.19136"
"178.29000","14.85764","0.19230"
"178.50000","14.87522","0.19367"
"178.71000","14.89268","0.19497"
"178.92000","14.91020","0.19704"
"179.13000","14.92771","0.19702"
"179.34000","14.94517","0.19888"
"179.55000","14.96275","0.19902"
"179.76000","14.98021","0.20028"
"179.97000","14.99773","0.20062"
"180.18000","15.01518","0.20155"
"180.39000","15.03270","0.20193"
"180.60000","15.05016","0.20218"
"180.81000","15.06774","0.20301"
"181.02000","15.08514","0.20420"
"181.23000","15.10278","0.20514"
"181.44000","15.12018","0.20510"
"181.65000","15.13769","0.20642"
"181.86000","15.15515","0.20703"
"182.07000","15.17267","0.20826"
"182.28000","15.19019","0.20900"
"182.49000","15.20771","0.21018"
"182.70000","15.22517","0.21144"
"182.91000","15.24268","0.21248"
"183.12000","15.26014","0.21393"
"183.33000","15.27772","0.21500"
"183.54000","15.29518","0.21637"
"183.75000","15.31270","0.21705"
"183.96000","15.33022","0.21857"
"184.17000","15.34762","0.21904"
"184.38000","15.36525","0.21991"
"184.59000","15.38271","0.21107"
"184.80000","15.40017","0.19735"
"185.01000","15.41769","0.19717"
"185.22200","15.43533","0.19737"
"185.43200","15.45284","0.19817"
"185.64200","15.47042","0.19912"
"185.85200","15.48776","0.19937"
"186.06200","15.50540","0.20018"
"186.27200","15.52286","0.20077"
"186.48200","15.54032","0.20032"
"186.69200","15.55789","0.20144"
"186.90200","15.57535","0.20105"
"187.11200","15.59287","0.20190"
"187.32200","15.61039","0.20240"
"187.53200","15.62785","0.20273"
"187.74200","15.64543","0.20354"
"187.95200","15.66282","0.20478"
"188.16200","15.68034","0.20562"
"188.37200","15.69792","0.20424"
"188.58200","15.71532","0.20320"
"188.79200","15.73284","0.20311"
"189.00200","15.75030","0.20370"
"189.21200","15.76787","0.20338"
"189.42200","15.78539","0.20404"
"189.63200","15.80279","0.20424"
"189.84200","15.82037","0.20429"
"190.05200","15.83783","0.20486"
"190.26200","15.85529","0.20567"
"190.47200","15.87287","0.20578"
"190.68200","15.89032","0.20595"
"190.89200","15.90784","0.20444"
"191.10200","15.92536","0.20400"
"191.31200","15.94288","0.20377"
"191.52200","15.96034","0.20249"
"191.73200","15.97786","0.20205"
"191.94200","15.99537","0.20166"
"192.15200","16.01283","0.20195"
"192.36200","16.03029","0.20191"
"192.57200","16.04787","0.07442"
"192.78200","16.06533","0.06929"
"192.99200","16.08290","0.06867"
"193.20200","16.10036","0.06889"
"193.41200","16.11782","0.07076"
"193.62200","16.13534","0.07037"
"193.83200","16.15286","0.07183"
"194.04200","16.17038","0.07169"
"194.25200","16.18790","0.07278"
"194.46200","16.20529","0.06934"
"194.67200","16.22293","0.06937"
"194.88200","16.24039","0.06958"
"195.09200","16.25785","0.06956"
"195.30200","16.27537","0.07097"
"195.51200","16.29283","0.07232"
"195.72200","16.31041","0.07409"
"195.93200","16.32786","0.07381"
"196.14200","16.34538","0.07276"
"196.35200","16.36290","0.07330"
"196.56200","16.38030","0.07362"
"196.77200","16.39788","0.07380"
"196.98200","16.41540","0.07498"
"197.19200","16.43285","0.07538"
"197.40200","16.45043","0.07386"
"197.61200","16.46783","0.04686"
"197.82200","16.48535","0.04650"
"198.03200","16.50293","0.03790"
"198.24200","16.52027","0.03903"
"198.45200","16.53790","0.03904"
"198.66200","16.55536","0.04266"
"198.87200","16.57288","0.04035"
"199.08200","16.59034","0.04466"
"199.29200","16.60780","0.04137"
"199.50200","16.62538","0.04596"
"199.71200","16.64289","0.04348"
"199.92200","16.66029","0.04686"
"200.13200","16.67787","0.04500"
"200.34200","16.69533","0.04767"
"200.55200","16.71291","0.04702"
"200.76200","16.73037","0.04834"
"200.97200","16.74783","0.04837"
"201.18200","16.76534","0.04929"
"201.39200","16.78280","0.04997"
"201.60200","16.80038","0.05025"
"201.81200","16.81790","0.05141"
"202.02200","16.83536","0.05144"
"202.23200","16.85288","0.05206"
"202.44200","16.87033","0.05163"
"202.65200","16.88785","0.05293"
"202.86200","16.90537","0.05162"
"203.07200","16.92283","0.05245"
"203.28200","16.94041","0.05144"
"203.49200","16.95787","0.05278"
"203.70200","16.97538","0.05224"
"203.91200","16.99290","0.05354"
"204.12200","17.01036","0.05243"
"204.33200","17.02788","0.05353"
"204.54200","17.04534","0.05287"
"204.75200","17.06286","0.05435"
"204.96200","17.08037","0.05307"
"205.17200","17.09783","0.05527"
"205.38200","17.11535","0.05517"
"205.59200","17.13293","0.05607"
"205.80200","17.15033","0.05638"
"206.01200","17.16791","0.05767"
"206.22200","17.18531","0.05777"
"206.43200","17.20288","0.05950"
"206.64200","17.22040","0.05872"
"206.85200","17.23780","0.06064"
"207.06200","17.25538","0.05787"
"207.27200","17.27284","0.05781"
"207.48200","17.29036","0.05835"
"207.69200","17.30781","0.05974"
"207.90200","17.32533","0.06045"
"208.11200","17.34285","0.06149"
"208.32200","17.36037","0.06186"
"208.53200","17.37789","0.06300"
"208.74200","17.39540","0.06321"
"208.95200","17.41286","0.06398"
"209.16200","17.43038","0.06317"
"209.37200","17.44784","0.06082"
"209.58200","17.46530","0.06107"
"209.79200","17.48288","0.06126"
"210.00200","17.50034","0.05879"
"210.21200","17.51792","0.05761"
"210.42200","17.53537","0.05588"
"210.63200","17.55283","0.05534"
"210.84200","17.57035","0.05468"
"211.05200","17.58787","0.05535"
"211.26200","17.60539","0.05473"
"211.47200","17.62291","0.05449"
"211.68200","17.64024","0.05376"
"211.89200","17.65788","0.05372"
"212.10200","17.67540","0.05385"
"212.31200","17.69286","0.05372"
"212.52200","17.71038","0.05405"
"212.73200","17.72783","0.05309"
"212.94200","17.74541","0.05362"
"213.15200","17.76281","0.05379"
"213.36200","17.78039","0.05439"
"213.57200","17.79785","0.05319"
"213.78200","17.81537","0.04923"
"213.99200","17.83289","0.04857"
"214.20200","17.85040","0.04861"
"214.41200","17.86780","0.04869"
"214.62200","17.88538","0.04888"
"214.83200","17.90290","0.04918"
"215.04200","17.92036","0.04907"
"215.25200","17.93788","0.04912"
"215.46200","17.95527","0.04908"
"215.67200","17.97285","0.04903"
"215.88200","17.99031","0.04838"
"216.09200","18.00783","0.04806"
"216.30200","18.02535","0.04814"
"216.51200","18.04281","0.04808"
"216.72200","18.06038","0.04799"
"216.93200","18.07790","0.04778"
"217.14200","18.09536","0.04771"
"217.35200","18.11288","0.04781"
"217.56200","18.13034","0.04729"
"217.77200","18.14786","0.03977"
"217.98200","18.16532","0.03802"
"218.19200","18.18289","0.03640"
"218.40200","18.20041","0.03611"
"218.61200","18.21781","0.03693"
"218.82200","18.23539","0.03691"
"219.03200","18.25285","0.03609"
"219.24200","18.27037","0.03803"
"219.45200","18.28788","0.03749"
"219.66200","18.30534","0.03830"
"219.87200","18.32286","0.03915"
"220.08200","18.34038","0.03872"
"220.29200","18.35784","0.03930"
"220.50200","18.37542","0.03949"
"220.71200","18.39281","0.03920"
"220.92200","18.41033","0.03808"
"221.13200","18.42791","0.03887"
"221.34200","18.44531","0.03939"
"221.55200","18.46289","0.03953"
"221.76200","18.48035","0.03973"
"221.97200","18.49787","0.03913"
"222.18200","18.51538","0.03896"
"222.39200","18.53284","0.03955"
"222.60200","18.55036","0.03926"
"222.81200","18.56794","0.03920"
"223.02200","18.58534","0.03908"
"223.23200","18.60286","0.03843"
"223.44200","18.62037","0.03798"
"223.65200","18.63783","0.03816"
"223.86200","18.65541","0.03843"
"224.07200","18.67275","0.03828"
"224.28200","18.69039","0.03809"
"224.49200","18.70785","0.03825"
"224.70200","18.72536","0.03766"
"224.91200","18.74288","0.03802"
"225.12200","18.76034","0.03832"
"225.33200","18.77792","0.03790"
"225.54200","18.79538","0.03736"
"225.75200","18.81284","0.03690"
"225.96200","18.83035","0.03656"
"226.17200","18.84781","0.03672"
"226.38200","18.86539","0.03707"
"226.59200","18.88279","0.03732"
"226.80200","18.90031","0.03746"
"227.01200","18.91789","0.03751"
"227.22200","18.93529","0.03776"
"227.43200","18.95292","0.03823"
"227.64200","18.97044","0.03750"
"227.85200","18.98784","0.03832"
"228.06200","19.00536","0.03894"
"228.27200","19.02282","0.03876"
"228.48200","19.04039","0.03884"
"228.69200","19.05791","0.03912"
"228.90200","19.07531","0.03980"
"229.11200","19.09289","0.03954"
"229.32200","19.11035","0.03979"
"229.53200","19.12787","0.03996"
"229.74200","19.14539","0.04070"
"229.95200","19.16285","0.04103"
"230.16200","19.18036","0.04144"
"230.37200","19.19782","0.04117"
"230.58200","19.21540","0.04177"
"230.79200","19.23286","0.04150"
"231.00200","19.25032","0.04210"
"231.21200","19.26789","0.04194"
"231.42200","19.28541","0.04220"
"231.63200","19.30287","0.04237"
"231.84200","19.32039","0.04229"
"232.05200","19.33785","0.04317"
"232.26200","19.35537","0.04334"
"232.47200","19.37288","0.04331"
"232.68200","19.39028","0.04290"
"232.89200","19.40786","0.04373"
"233.10200","19.42538","0.04386"
"233.31200","19.44284","0.04433"
"233.52200","19.46036","0.04434"
"233.73200","19.47782","0.04466"
"233.94200","19.49539","0.04467"
"234.15200","19.51291","0.04466"
"234.36200","19.53037","0.04454"
"234.57200","19.54783","0.04496"
"234.78200","19.56535","0.04483"
"234.99200","19.58287","0.04538"
"235.20200","19.60032","0.04227"
"235.41200","19.61784","0.02031"
"235.62200","19.63536","0.02108"
"235.83200","19.65282","0.02015"
"236.04200","19.67040","0.01926"
"236.25200","19.68785","0.01824"
"236.46200","19.70531","0.02147"
"236.67200","19.72289","0.01974"
"236.88200","19.74035","0.02033"
"237.09200","19.75793","0.02002"
"237.30200","19.77539","0.02235"
"237.51200","19.79279","0.02203"
"237.72200","19.81042","0.01981"
"237.93200","19.82782","0.02170"
"238.14200","19.84534","0.02245"
"238.35200","19.86286","0.02219"
"238.56200","19.88032","0.02100"
"238.77200","19.89790","0.02143"
"238.98200","19.91536","0.02276"
"239.19200","19.93287","0.02187"
"239.40200","19.95039","0.02196"
"239.61200","19.96785","0.02327"
"239.82200","19.98537","0.02353"
"240.03200","20.00289","0.02173"
"240.24200","20.02035","0.02339"
"240.45200","20.03786","0.02355"
"240.66200","20.05538","0.02418"
"240.87200","20.07290","0.02391"
"241.08200","20.09036","0.02405"
"241.29200","20.10776","0.02455"
"241.50200","20.12534","0.02514"
"241.71200","20.14285","0.02465"
"241.92200","20.16043","0.02533"
"242.13200","20.17783","0.02526"
"242.34200","20.19535","0.02471"
"242.55200","20.21287","0.02543"
"242.76200","20.23039","0.02573"
"242.97200","20.24784","0.02555"
"243.18200","20.26536","0.02547"
"243.39200","20.28282","0.02652"
"243.60200","20.30040","0.02647"
"243.81200","20.31786","0.02636"
"244.02200","20.33532","0.02662"
"244.23200","20.35283","0.02760"
"244.44200","20.37036","0.02763"
"244.65200","20.38787","0.02770"
"244.86200","20.40539","0.02867"
"245.07200","20.42285","0.02785"
"245.28200","20.44031","0.02878"
"245.49200","20.45782","0.02829"
"245.70200","20.47534","0.02975"
"245.91200","20.49292","0.02929"
"246.12200","20.51026","0.02946"
"246.33200","20.52790","0.02935"
"246.54200","20.54536","0.02977"
"246.75200","20.56288","0.03058"
"246.96200","20.58039","0.03032"
"247.17200","20.59785","0.03123"
"247.38200","20.61543","0.03058"
"247.59200","20.63283","0.03111"
"247.80200","20.65035","0.03078"
"248.01200","20.66793","0.03204"
"248.22200","20.68532","0.03202"
"248.43200","20.70290","0.03192"
"248.64200","20.72036","0.03259"
"248.85200","20.73782","0.03231"
"249.06200","20.75540","0.03271"
"249.27200","20.77280","0.03341"
"249.48200","20.79038","0.03355"
"249.69200","20.80789","0.03322"
"249.90200","20.82529","0.03395"
"250.11200","20.84287","0.03401"
"250.32200","20.86033","0.03438"
"250.53200","20.87785","0.03476"
"250.74200","20.89536","0.03517"
"250.95200","20.91282","0.03566"
"251.16200","20.93034","0.03551"
"251.37200","20.94786","0.03589"
"251.58200","20.96538","0.03610"
"251.79200","20.98284","0.03698"
"252.00200","21.00030","0.03680"
"252.21200","21.01781","0.03708"
"252.42200","21.03533","0.03734"
"252.63200","21.05285","0.03708"
"252.84200","21.07037","0.03775"
"253.05200","21.08783","0.03724"
"253.26200","21.10541","0.03805"
"253.47200","21.12286","0.03774"
"253.68200","21.14032","0.03897"
"253.89200","21.15784","0.03880"
"254.10200","21.17536","0.03921"
"254.31200","21.19288","0.03959"
"254.52200","21.21040","0.03996"
"254.73200","21.22780","0.04004"
"254.94200","21.24543","0.03990"
"255.15200","21.26289","0.04052"
"255.36200","21.28035","0.04109"
"255.57200","21.29787","0.04121"
"255.78200","21.31533","0.04178"
"255.99200","21.33285","0.04177"
"256.20200","21.35036","0.04222"
"256.41200","21.36782","0.04234"
"256.62200","21.38540","0.04269"
"256.83200","21.40286","0.04301"
"257.04200","21.42038","0.04325"
"257.25200","21.43789","0.04371"
"257.46200","21.45535","0.04391"
"257.67200","21.47287","0.04447"
"257.88200","21.49039","0.04463"
"258.09200","21.50785","0.04479"
"258.30200","21.52543","0.04516"
"258.51200","21.54277","0.04560"
"258.72200","21.56034","0.04541"
"258.93200","21.57780","0.04556"
"259.14200","21.59538","0.04642"
"259.35200","21.61290","0.04638"
"259.56200","21.63036","0.04694"
"259.77200","21.64794","0.04703"
"259.98200","21.66540","0.04770"
"260.19200","21.68286","0.04797"
"260.40200","21.70037","0.04798"
"260.61200","21.71783","0.04859"
"260.82200","21.73541","0.04899"
"261.03200","21.75281","0.04918"
"261.24200","21.77033","0.04973"
"261.45200","21.78790","0.05012"
"261.66200","21.80530","0.05057"
"261.87200","21.82288","0.05082"
"262.08200","21.84034","0.05137"
"262.29200","21.85786","0.05173"
"262.50200","21.87532","0.05177"
"262.71200","21.89283","0.05256"
"262.92200","21.91035","0.05303"
"263.13200","21.92793","0.05414"
"263.34200","21.94533","0.05390"
"263.55200","21.96291","0.05479"
"263.76200","21.98037","0.05517"
"263.97200","21.99782","0.05555"
"264.18200","22.01540","0.05642"
"264.39200","22.03280","0.05684"
"264.60200","22.05044","0.05753"
"264.81200","22.06784","0.05826"
"265.02200","22.08536","0.05924"
"265.23200","22.10287","0.06005"
"265.44200","22.12027","0.06107"
"265.65200","22.13791","0.06182"
"265.86200","22.15543","0.06260"
"266.07200","22.17283","0.06367"
"266.28200","22.19041","0.06397"
"266.49200","22.20786","0.06556"
"266.70200","22.22532","0.06645"
"266.91200","22.24290","0.06731"
"267.12200","22.26030","0.06880"
"267.33200","22.27794","0.06962"
"267.54200","22.29534","0.07032"
"267.75200","22.31286","0.07130"
"267.96200","22.33031","0.07211"
"268.17200","22.34789","0.07302"
"268.38200","22.36535","0.07411"
"268.59200","22.38287","0.07515"
"268.80200","22.40033","0.07605"
"269.01200","22.41785","0.07704"
"269.22200","22.43537","0.07724"
"269.43200","22.45288","0.07844"
"269.64200","22.47034","0.08033"
"269.85200","22.48786","0.08105"
"270.06200","22.50538","0.08185"
"270.27200","22.52278","0.08334"
"270.48200","22.54041","0.08376"
"270.69200","22.55787","0.08433"
"270.90200","22.57539","0.08516"
"271.11200","22.59285","0.08651"
"271.32200","22.61037","0.08716"
"271.53200","22.62789","0.08805"
"271.74200","22.64541","0.08904"
"271.95200","22.66281","0.08982"
"272.16200","22.68044","0.09040"
"272.37200","22.69784","0.09138"
"272.58200","22.71536","0.09192"
"272.79200","22.73288","0.09235"
"273.00200","22.75034","0.09310"
"273.21200","22.76785","0.09383"
"273.42200","22.78531","0.09431"
"273.63200","22.80283","0.09505"
"273.84200","22.82035","0.09531"
"274.05200","22.83787","0.09590"
"274.26200","22.85538","0.09561"
"274.47200","22.87290","0.09601"
"274.68200","22.89030","0.09679"
"274.89200","22.90788","0.09704"
"275.10200","22.92534","0.09767"
"275.31200","22.94286","0.09806"
"275.52200","22.96038","0.09876"
"275.73200","22.97778","0.09913"
"275.94200","22.99541","0.10055"
"276.15200","23.01281","0.10166"
"276.36200","23.03033","0.10225"
"276.57200","23.04791","0.10340"
"276.78200","23.06531","0.10369"
"276.99200","23.08289","0.10488"
"277.20200","23.10040","0.10602"
"277.41200","23.11786","0.10771"
"277.62200","23.13538","0.10887"
"277.83200","23.15284","0.11053"
"278.04200","23.17036","0.11105"
"278.25200","23.18788","0.11284"
"278.46200","23.20533","0.11338"
"278.67200","23.22285","0.11503"
"278.88200","23.24031","0.11633"
"279.09200","23.25795","0.11770"
"279.30200","23.27535","0.11848"
"279.51200","23.29287","0.12023"
"279.72200","23.31033","0.12107"
"279.93200","23.32784","0.12190"
"280.14200","23.34542","0.12352"
"280.35200","23.36288","0.12385"
"280.56200","23.38034","0.12497"
"280.77200","23.39792","0.12565"
"280.98200","23.41537","0.12699"
"281.19200","23.43289","0.12763"
"281.40200","23.45035","0.12862"
"281.61200","23.46781","0.12936"
"281.82200","23.48539","0.13018"
"282.03200","23.50279","0.13099"
"282.24200","23.52031","0.13210"
"282.45200","23.53788","0.13266"
"282.66200","23.55534","0.13324"
"282.87200","23.57286","0.13392"
"283.08200","23.59038","0.13453"
"283.29200","23.60784","0.13512"
"283.50200","23.62542","0.13532"
"283.71200","23.64282","0.13606"
"283.92200","23.66033","0.13691"
"284.13200","23.67785","0.13717"
"284.34200","23.69531","0.13762"
"284.55200","23.71283","0.13827"
"284.76200","23.73034","0.13849"
"284.97200","23.74787","0.13913"
"285.18200","23.76538","0.13952"
"285.39200","23.78290","0.13999"
"285.60200","23.80036","0.14064"
"285.81200","23.81788","0.14139"
"286.02200","23.83534","0.14166"
"286.23200","23.85286","0.14207"
"286.44200","23.87031","0.14270"
"286.65200","23.88789","0.14328"
"286.86200","23.90535","0.14361"
"287.07200","23.92281","0.14462"
"287.28200","23.94039","0.14525"
"287.49200","23.95779","0.14527"
"287.70200","23.97542","0.14661"
"287.91200","23.99288","0.14737"
"288.12200","24.01034","0.14773"
"288.33200","24.02792","0.14794"
"288.54200","24.04532","0.14951"
"288.75200","24.06290","0.15050"
"288.96200","24.08041","0.15072"
"289.17200","24.09781","0.15187"
"289.38200","24.11539","0.15321"
"289.59200","24.13285","0.15434"
"289.80200","24.15037","0.15530"
"290.01200","24.16789","0.15730"
"290.22200","24.18534","0.15833"
"290.43200","24.20292","0.15938"
"290.64200","24.22032","0.16117"
"290.85200","24.23790","0.16301"
"291.06200","24.25536","0.16469"
"291.27200","24.27288","0.16605"
"291.48200","24.29039","0.16800"
"291.69200","24.30791","0.16910"
"291.90200","24.32531","0.17088"
"292.11200","24.34289","0.17316"
"292.32200","24.36035","0.17466"
"292.53200","24.37787","0.17516"
"292.74200","24.39538","0.17644"
"292.95200","24.41278","0.17774"
"293.16200","24.43036","0.18078"
"293.37200","24.44788","0.18178"
"293.58200","24.46534","0.18424"
"293.79200","24.48286","0.18481"
"294.00200","24.50031","0.18680"
"294.21200","24.51783","0.18831"
"294.42200","24.53541","0.18825"
"294.63200","24.55287","0.06144"
"294.84200","24.57039","0.05901"
"295.05200","24.58785","0.06160"
"295.26200","24.60543","0.06936"
"295.47200","24.62283","0.06678"
"295.68200","24.64034","0.06875"
"295.89200","24.65786","0.06359"
"296.10200","24.67532","0.06482"
"296.31200","24.69290","0.06068"
"296.52200","24.71036","0.06894"
"296.73200","24.72787","0.06671"
"296.94200","24.74533","0.07532"
"297.15200","24.76285","0.07282"
"297.36200","24.78037","0.06843"
"297.57200","24.79789","0.07266"
"297.78200","24.81535","0.06798"
"297.99200","24.83292","0.07563"
"298.20200","24.85039","0.07646"
"298.41200","24.86790","0.07895"
"298.62200","24.88536","0.07378"
"298.83200","24.90282","0.07909"
"299.04200","24.92046","0.07659"
"299.25200","24.93780","0.07645"
"299.46200","24.95538","0.08535"
"299.67200","24.97289","0.07751"
"299.88200","24.99035","0.08146"
"300.09200","25.00787","0.08154"
"300.30200","25.02539","0.08268"
"300.51200","25.04279","0.08321"
"300.72200","25.06036","0.08651"
"300.93200","25.07788","0.08403"
"301.14200","25.09534","0.08513"
"301.35200","25.11292","0.08755"
"301.56200","25.13026","0.08424"
"301.77200","25.14783","0.08991"
"301.98200","25.16535","0.08622"
"302.19200","25.18287","0.08746"
"302.40200","25.20033","0.09124"
"302.61200","25.21785","0.08865"
"302.82200","25.23537","0.09028"
"303.03200","25.25289","0.09140"
"303.24200","25.27035","0.09095"
"303.45200","25.28786","0.09142"
"303.66200","25.30532","0.09340"
"303.87200","25.32284","0.09058"
"304.08200","25.34030","0.09399"
"304.29200","25.35788","0.09275"
"304.50200","25.37539","0.09319"
"304.71200","25.39279","0.09455"
"304.92200","25.41043","0.09331"
"305.13200","25.42789","0.09452"
"305.34200","25.44529","0.09594"
"305.55200","25.46287","0.09479"
"305.76200","25.48032","0.09581"
"305.97200","25.49784","0.09634"
"306.18200","25.51542","0.09527"
"306.39200","25.53282","0.00023"
"306.60200","25.55040","0.00186"
"306.81200","25.56786","0.01012"
"307.02200","25.58532","0.01011"
"307.23200","25.60290","0.00787"
"307.44200","25.62029","0.00520"
"307.65200","25.63787","0.00720"
"307.86200","25.65533","0.00720"
"308.07200","25.67285","0.00811"
"308.28200","25.69036","0.00572"
"308.49200","25.70783","0.00639"
"308.70200","25.72540","0.00786"
"308.91200","25.74286","0.00523"
"309.12200","25.76038","0.00646"
"309.33200","25.77784","0.00713"
"309.37200","25.78119","0.00713"