File: Force_trajectories/170212_1/Specimen_RawData_8.csv
End date,"2/12/2017"
Specimen label,"9AG_76"
Maximum Load,"0.27510",N

Time,Extension,Load
(s),(mm),(N)
"0.00000","0.00000","-0.00004"
"0.21600","0.01531","0.00125"
"0.43200","0.03617","0.00005"
"0.64800","0.05417","0.00165"
"0.86400","0.07217","0.00286"
"1.08000","0.09010","0.00198"
"1.29600","0.10816","0.00421"
"1.51200","0.12610","0.00371"
"1.72800","0.14409","0.00447"
"1.94400","0.16215","0.00480"
"2.16000","0.18009","0.00503"
"2.37600","0.19814","0.00666"
"2.59200","0.21608","0.00712"
"2.80800","0.23414","0.00785"
"3.02400","0.25213","0.00789"
"3.24000","0.27007","0.00889"
"3.45600","0.28819","0.00957"
"3.67200","0.30612","0.01045"
"3.88800","0.32406","0.01059"
"4.10400","0.34218","0.01176"
"4.32000","0.36005","0.01236"
"4.53600","0.37811","0.01231"
"4.75200","0.39611","0.01380"
"4.96800","0.41410","0.01431"
"5.18400","0.43210","0.01519"
"5.40000","0.45004","0.01645"
"5.61600","0.46803","0.01729"
"5.83200","0.48609","0.01889"
"6.04800","0.50409","0.01974"
"6.26400","0.52214","0.02142"
"6.48000","0.54008","0.02296"
"6.69600","0.55814","0.02526"
"6.91200","0.57613","0.02632"
"7.12800","0.59413","0.02952"
"7.34400","0.61213","0.03164"
"7.56000","0.63006","0.03471"
"7.77600","0.64812","0.03790"
"7.99200","0.66606","0.04092"
"8.20800","0.68411","0.04361"
"8.42400","0.70211","0.04650"
"8.64000","0.72011","0.04956"
"8.85600","0.73810","0.05276"
"9.07200","0.75604","0.05562"
"9.28800","0.77415","0.05795"
"9.50400","0.79215","0.06045"
"9.72000","0.81009","0.06337"
"9.93600","0.82809","0.06548"
"10.15200","0.84614","0.06698"
"10.36800","0.86414","0.06878"
"10.58400","0.88213","0.07005"
"10.80000","0.90007","0.07111"
"11.01600","0.91813","0.07197"
"11.23200","0.93612","0.07264"
"11.44800","0.95418","0.07336"
"11.66400","0.97212","0.07428"
"11.88000","0.99005","0.07550"
"12.09600","1.00811","0.07685"
"12.31200","1.02605","0.07866"
"12.52800","1.04410","0.08094"
"12.74400","1.06216","0.08290"
"12.96000","1.08004","0.08582"
"13.17600","1.09815","0.08932"
"13.39200","1.11609","0.09257"
"13.60800","1.13415","0.09606"
"13.82400","1.15208","0.09907"
"14.04000","1.17014","0.10123"
"14.25600","1.18808","0.10353"
"14.47200","1.20613","0.10496"
"14.68800","1.22413","0.10627"
"14.90400","1.24213","0.10770"
"15.12000","1.26006","0.10821"
"15.33600","1.27812","0.10896"
"15.55200","1.29612","0.10945"
"15.76800","1.31411","0.11024"
"15.98400","1.33217","0.11094"
"16.20000","1.35005","0.11179"
"16.41600","1.36816","0.11268"
"16.63200","1.38610","0.11264"
"16.84800","1.40410","0.11279"
"17.06400","1.42209","0.11346"
"17.28000","1.44003","0.11476"
"17.49600","1.45815","0.11497"
"17.71200","1.47608","0.11551"
"17.92800","1.49414","0.11559"
"18.14400","1.51208","0.11585"
"18.36000","1.53013","0.11608"
"18.57600","1.54807","0.11622"
"18.79200","1.56613","0.11626"
"19.00800","1.58412","0.11742"
"19.22400","1.60218","0.11758"
"19.44000","1.62006","0.11825"
"19.65600","1.63811","0.11807"
"19.87200","1.65611","0.11841"
"20.08800","1.67417","0.11892"
"20.30400","1.69210","0.11922"
"20.52000","1.71010","0.11968"
"20.73600","1.72816","0.12024"
"20.95200","1.74609","0.11988"
"21.16800","1.76409","0.12107"
"21.38400","1.78215","0.12123"
"21.60000","1.80008","0.12184"
"21.81600","1.81814","0.12207"
"22.03200","1.83608","0.12204"
"22.24800","1.85413","0.12233"
"22.46400","1.87207","0.12216"
"22.68000","1.89007","0.12216"
"22.89600","1.90806","0.12317"
"23.11200","1.92606","0.12321"
"23.32800","1.94412","0.12347"
"23.54400","1.96211","0.12374"
"23.76000","1.98011","0.12377"
"23.97600","1.99811","0.12499"
"24.19200","2.01610","0.12441"
"24.40800","2.03416","0.12474"
"24.62400","2.05216","0.12469"
"24.84000","2.07009","0.12472"
"25.05600","2.08809","0.12478"
"25.27200","2.10609","0.12535"
"25.48800","2.12414","0.12534"
"25.70400","2.14208","0.12510"
"25.92000","2.16014","0.12546"
"26.13600","2.17813","0.12560"
"26.35200","2.19607","0.12616"
"26.56800","2.21413","0.12564"
"26.78400","2.23212","0.12630"
"27.00000","2.25006","0.12602"
"27.21600","2.26812","0.12633"
"27.43200","2.28611","0.12653"
"27.64800","2.30411","0.12657"
"27.86400","2.32211","0.12716"
"28.08000","2.34010","0.12717"
"28.29600","2.35810","0.12716"
"28.51200","2.37610","0.12742"
"28.72800","2.39415","0.12710"
"28.94400","2.41215","0.12760"
"29.16000","2.43009","0.12796"
"29.37600","2.44814","0.12782"
"29.59200","2.46602","0.12788"
"29.80800","2.48420","0.12841"
"30.02400","2.50207","0.12827"
"30.24000","2.52013","0.12830"
"30.45600","2.53813","0.12855"
"30.67200","2.55612","0.12824"
"30.88800","2.57412","0.12809"
"31.10400","2.59218","0.12860"
"31.32000","2.61011","0.12911"
"31.53600","2.62811","0.12890"
"31.75200","2.64605","0.12863"
"31.96800","2.66416","0.12925"
"32.18400","2.68210","0.12934"
"32.40000","2.70016","0.12956"
"32.61600","2.71809","0.12939"
"32.83200","2.73609","0.12956"
"33.04800","2.75414","0.13018"
"33.26400","2.77214","0.12979"
"33.48000","2.79008","0.13045"
"33.69600","2.80814","0.12943"
"33.91200","2.82607","0.12983"
"34.12800","2.84413","0.13003"
"34.34400","2.86207","0.12966"
"34.56000","2.88012","0.13029"
"34.77600","2.89812","0.13025"
"34.99200","2.91605","0.13012"
"35.20800","2.93411","0.13037"
"35.42400","2.95211","0.13002"
"35.64000","2.97016","0.13021"
"35.85600","2.98810","0.12941"
"36.07200","3.00604","0.12989"
"36.28800","3.02415","0.13016"
"36.50400","3.04209","0.13032"
"36.72000","3.06009","0.13030"
"36.93600","3.07814","0.13056"
"37.15200","3.09608","0.13084"
"37.36800","3.11408","0.13018"
"37.58400","3.13213","0.13111"
"37.80000","3.15007","0.13074"
"38.01600","3.16819","0.13137"
"38.23200","3.18600","0.13084"
"38.44800","3.20412","0.13059"
"38.66400","3.22212","0.13103"
"38.88000","3.24005","0.13127"
"39.09600","3.25811","0.13094"
"39.31200","3.27605","0.13106"
"39.52800","3.29410","0.13098"
"39.74400","3.31210","0.13109"
"39.96000","3.33010","0.13142"
"40.17600","3.34809","0.13058"
"40.39200","3.36603","0.13142"
"40.60800","3.38415","0.13137"
"40.82400","3.40208","0.13106"
"41.04000","3.42008","0.13124"
"41.25600","3.43814","0.13078"
"41.47200","3.45607","0.13046"
"41.68800","3.47413","0.13098"
"41.90400","3.49213","0.13193"
"42.12000","3.51012","0.13138"
"42.33600","3.52812","0.13101"
"42.55200","3.54606","0.13152"
"42.76800","3.56411","0.13089"
"42.98400","3.58205","0.13104"
"43.20000","3.60011","0.13087"
"43.41600","3.61816","0.13165"
"43.63200","3.63610","0.13131"
"43.84800","3.65410","0.13167"
"44.06400","3.67209","0.13149"
"44.28000","3.69015","0.13102"
"44.49600","3.70815","0.13160"
"44.71200","3.72602","0.13136"
"44.92800","3.74414","0.13127"
"45.14400","3.76214","0.13184"
"45.36000","3.78013","0.13118"
"45.57600","3.79813","0.13099"
"45.79200","3.81607","0.13151"
"46.00800","3.83412","0.13174"
"46.22400","3.85206","0.13184"
"46.44000","3.87012","0.13172"
"46.65600","3.88811","0.13133"
"46.87200","3.90605","0.13133"
"47.08800","3.92411","0.13182"
"47.30400","3.94210","0.13149"
"47.52000","3.96016","0.13118"
"47.73600","3.97816","0.13143"
"47.95200","3.99609","0.13163"
"48.16800","4.01415","0.13203"
"48.38400","4.03209","0.13124"
"48.60000","4.05014","0.13139"
"48.81600","4.06814","0.13122"
"49.03200","4.08608","0.13143"
"49.24800","4.10407","0.13156"
"49.46400","4.12213","0.13137"
"49.68000","4.14013","0.13069"
"49.89600","4.15812","0.13183"
"50.11200","4.17606","0.13169"
"50.32800","4.19418","0.13188"
"50.54400","4.21205","0.13193"
"50.76000","4.23017","0.13170"
"50.97600","4.24805","0.13175"
"51.19200","4.26610","0.13223"
"51.40800","4.28410","0.13191"
"51.62400","4.30210","0.13163"
"51.84000","4.32015","0.13209"
"52.05600","4.33815","0.13157"
"52.27200","4.35615","0.13187"
"52.48800","4.37408","0.13246"
"52.70400","4.39208","0.13259"
"52.92000","4.41020","0.13236"
"53.13600","4.42807","0.13215"
"53.35200","4.44613","0.13201"
"53.56800","4.46413","0.13178"
"53.78400","4.48206","0.13209"
"54.00000","4.50012","0.13176"
"54.21600","4.51818","0.13167"
"54.43200","4.53605","0.13274"
"54.64800","4.55417","0.13254"
"54.86400","4.57211","0.13236"
"55.08000","4.59016","0.13217"
"55.29600","4.60810","0.13268"
"55.51200","4.62616","0.13230"
"55.72800","4.64415","0.13219"
"55.94400","4.66209","0.13239"
"56.16000","4.68015","0.13288"
"56.37600","4.69814","0.13237"
"56.59200","4.71608","0.13224"
"56.80800","4.73419","0.13263"
"57.02400","4.75201","0.13253"
"57.24000","4.77019","0.13239"
"57.45600","4.78813","0.13298"
"57.67200","4.80612","0.13292"
"57.88800","4.82412","0.13248"
"58.10400","4.84211","0.13293"
"58.32000","4.86011","0.13308"
"58.53600","4.87817","0.13324"
"58.75200","4.89611","0.13297"
"58.96800","4.91416","0.13267"
"59.18400","4.93210","0.13301"
"59.40000","4.95015","0.13296"
"59.61600","4.96809","0.13298"
"59.83200","4.98609","0.13261"
"60.04800","5.00414","0.13325"
"60.26400","5.02208","0.13308"
"60.48000","5.04014","0.13327"
"60.69600","5.05813","0.13285"
"60.91200","5.07607","0.13328"
"61.12800","5.09413","0.13275"
"61.34400","5.11206","0.13307"
"61.56000","5.13018","0.13333"
"61.77600","5.14806","0.13308"
"61.99200","5.16611","0.13337"
"62.20800","5.18411","0.13375"
"62.42400","5.20205","0.13347"
"62.64000","5.22016","0.13362"
"62.85600","5.23816","0.13370"
"63.07200","5.25610","0.13289"
"63.28800","5.27409","0.13412"
"63.50400","5.29209","0.13449"
"63.72000","5.31015","0.13320"
"63.93600","5.32808","0.13378"
"64.15200","5.34608","0.13372"
"64.36800","5.36414","0.13362"
"64.58400","5.38207","0.13416"
"64.80000","5.40013","0.13416"
"65.01600","5.41813","0.13368"
"65.23200","5.43612","0.13363"
"65.44800","5.45418","0.13435"
"65.66400","5.47212","0.13348"
"65.88000","5.49011","0.13353"
"66.09600","5.50811","0.13406"
"66.31200","5.52611","0.13402"
"66.52800","5.54410","0.13438"
"66.74400","5.56204","0.13427"
"66.96000","5.58016","0.13469"
"67.17600","5.59815","0.13368"
"67.39200","5.61615","0.13413"
"67.60800","5.63415","0.13446"
"67.82400","5.65208","0.13416"
"68.04000","5.67014","0.13431"
"68.25600","5.68814","0.13394"
"68.47200","5.70607","0.13458"
"68.68800","5.72413","0.13439"
"68.90400","5.74207","0.13475"
"69.12000","5.76012","0.13476"
"69.33600","5.77806","0.13509"
"69.55200","5.79612","0.13466"
"69.76800","5.81411","0.13456"
"69.98400","5.83211","0.13502"
"70.20000","5.85011","0.13450"
"70.41600","5.86810","0.13487"
"70.63200","5.88616","0.13465"
"70.84800","5.90416","0.13417"
"71.06400","5.92203","0.13476"
"71.28000","5.94015","0.13482"
"71.49600","5.95809","0.13524"
"71.71200","5.97614","0.13507"
"71.92800","5.99414","0.13503"
"72.14400","6.01214","0.13452"
"72.36000","6.03013","0.13468"
"72.57600","6.04807","0.13558"
"72.79200","6.06613","0.13506"
"73.00800","6.08412","0.13488"
"73.22400","6.10206","0.13392"
"73.44000","6.12018","0.13533"
"73.65600","6.13811","0.13522"
"73.87200","6.15617","0.13527"
"74.08800","6.17411","0.13483"
"74.30400","6.19210","0.13521"
"74.52000","6.21004","0.13486"
"74.73600","6.22810","0.13483"
"74.95200","6.24615","0.13483"
"75.16800","6.26415","0.13541"
"75.38400","6.28209","0.13550"
"75.60000","6.30014","0.13493"
"75.81600","6.31808","0.13491"
"76.03200","6.33614","0.13582"
"76.24800","6.35413","0.13530"
"76.46400","6.37213","0.13498"
"76.68000","6.39013","0.13455"
"76.89600","6.40812","0.13490"
"77.11200","6.42612","0.13493"
"77.32800","6.44412","0.13542"
"77.54400","6.46211","0.13502"
"77.76000","6.48017","0.13531"
"77.97600","6.49805","0.13477"
"78.19200","6.51616","0.13468"
"78.40800","6.53410","0.13491"
"78.62400","6.55210","0.13541"
"78.84000","6.57009","0.13531"
"79.05600","6.58809","0.13528"
"79.27200","6.60609","0.13520"
"79.48800","6.62414","0.13553"
"79.70400","6.64208","0.13536"
"79.92000","6.66019","0.13505"
"80.13600","6.67807","0.13509"
"80.35200","6.69613","0.13480"
"80.56800","6.71413","0.13478"
"80.78400","6.73212","0.13465"
"81.00000","6.75012","0.13367"
"81.21600","6.76806","0.13436"
"81.43200","6.78611","0.13415"
"81.64800","6.80417","0.13394"
"81.86400","6.82205","0.13419"
"82.08000","6.84016","0.13429"
"82.29600","6.85804","0.13409"
"82.51200","6.87610","0.13459"
"82.72800","6.89415","0.13443"
"82.94400","6.91209","0.13386"
"83.16000","6.93009","0.13384"
"83.37600","6.94808","0.13355"
"83.59200","6.96614","0.13355"
"83.80800","6.98413","0.13389"
"84.02400","7.00207","0.13447"
"84.24000","7.02013","0.13405"
"84.45600","7.03813","0.13370"
"84.67200","7.05612","0.13393"
"84.88800","7.07412","0.13432"
"85.10400","7.09211","0.13400"
"85.32000","7.11011","0.13401"
"85.53600","7.12811","0.13413"
"85.75200","7.14611","0.13447"
"85.96800","7.16410","0.13367"
"86.18400","7.18210","0.13418"
"86.40000","7.20009","0.13404"
"86.61600","7.21809","0.13370"
"86.83200","7.23615","0.13420"
"87.04800","7.25415","0.13400"
"87.26400","7.27208","0.13380"
"87.48000","7.29014","0.13370"
"87.69600","7.30814","0.13392"
"87.91200","7.32613","0.13447"
"88.12800","7.34413","0.13420"
"88.34400","7.36206","0.13461"
"88.56000","7.38012","0.13444"
"88.77600","7.39806","0.13375"
"88.99200","7.41617","0.13429"
"89.20800","7.43411","0.13392"
"89.42400","7.45211","0.13420"
"89.64000","7.47016","0.13410"
"89.85600","7.48804","0.13410"
"90.07200","7.50610","0.13397"
"90.28800","7.52409","0.13389"
"90.50400","7.54215","0.13404"
"90.72000","7.56015","0.13416"
"90.93600","7.57808","0.13408"
"91.15200","7.59608","0.13374"
"91.36800","7.61414","0.13415"
"91.58400","7.63207","0.13429"
"91.80000","7.65013","0.13415"
"92.01600","7.66807","0.13424"
"92.23200","7.68612","0.13314"
"92.44800","7.70412","0.13418"
"92.66400","7.72212","0.13368"
"92.88000","7.74011","0.13392"
"93.09600","7.75811","0.13372"
"93.31200","7.77611","0.13472"
"93.52800","7.79410","0.13377"
"93.74400","7.81210","0.13411"
"93.96000","7.83010","0.13418"
"94.17600","7.84803","0.13394"
"94.39200","7.86615","0.13427"
"94.60800","7.88409","0.13415"
"94.82400","7.90214","0.13375"
"95.04000","7.92014","0.13406"
"95.25600","7.93808","0.13426"
"95.47200","7.95613","0.13427"
"95.68800","7.97413","0.13360"
"95.90400","7.99213","0.13412"
"96.12000","8.01012","0.13404"
"96.33600","8.02806","0.13377"
"96.55200","8.04612","0.13417"
"96.76800","8.06405","0.13410"
"96.98400","8.08217","0.13414"
"97.20000","8.10011","0.13396"
"97.41600","8.11804","0.13407"
"97.63200","8.13616","0.13423"
"97.84800","8.15416","0.13384"
"98.06400","8.17209","0.13450"
"98.28000","8.19015","0.13436"
"98.49600","8.20803","0.13515"
"98.71200","8.22614","0.13404"
"98.92800","8.24408","0.13441"
"99.14400","8.26214","0.13415"
"99.36000","8.28013","0.13394"
"99.57600","8.29807","0.13422"
"99.79200","8.31613","0.13399"
"100.00800","8.33412","0.13373"
"100.22400","8.35212","0.13367"
"100.44000","8.37018","0.13357"
"100.65600","8.38805","0.13401"
"100.87200","8.40617","0.13404"
"101.08800","8.42411","0.13299"
"101.30400","8.44210","0.13286"
"101.52000","8.46010","0.13371"
"101.73600","8.47810","0.13365"
"101.95200","8.49609","0.13318"
"102.16800","8.51415","0.13279"
"102.38400","8.53215","0.13353"
"102.60000","8.55014","0.13355"
"102.81600","8.56802","0.13378"
"103.03200","8.58614","0.13335"
"103.24800","8.60407","0.13359"
"103.46400","8.62213","0.13303"
"103.68000","8.64013","0.13282"
"103.89600","8.65806","0.13391"
"104.11200","8.67612","0.13367"
"104.32800","8.69406","0.13368"
"104.54400","8.71217","0.13410"
"104.76000","8.73005","0.13323"
"104.97600","8.74805","0.13412"
"105.19200","8.76610","0.13341"
"105.40800","8.78410","0.13372"
"105.62400","8.80216","0.13370"
"105.84000","8.82015","0.13327"
"106.05600","8.83803","0.13380"
"106.27200","8.85614","0.13372"
"106.48800","8.87408","0.13357"
"106.70400","8.89208","0.13366"
"106.92000","8.91014","0.13376"
"107.13600","8.92807","0.13394"
"107.35200","8.94613","0.13422"
"107.56800","8.96407","0.13365"
"107.78400","8.98212","0.13380"
"108.00000","9.00012","0.13413"
"108.21600","9.01805","0.13356"
"108.43200","9.03611","0.13351"
"108.64800","9.05411","0.13413"
"108.86400","9.07211","0.13362"
"109.08000","9.09016","0.13344"
"109.29600","9.10804","0.13439"
"109.51200","9.12609","0.13470"
"109.72800","9.14409","0.13424"
"109.94400","9.16209","0.13372"
"110.16000","9.18014","0.13367"
"110.37600","9.19808","0.13401"
"110.59200","9.21614","0.13405"
"110.80800","9.23407","0.13399"
"111.02400","9.25213","0.13359"
"111.24000","9.27007","0.13407"
"111.45600","9.28806","0.13459"
"111.67200","9.30612","0.13410"
"111.88800","9.32412","0.13392"
"112.10400","9.34211","0.13389"
"112.32000","9.36017","0.13389"
"112.53600","9.37811","0.13422"
"112.75200","9.39610","0.13398"
"112.96800","9.41410","0.13417"
"113.18400","9.43216","0.13376"
"113.40000","9.45010","0.13426"
"113.61600","9.46809","0.13426"
"113.83200","9.48609","0.13482"
"114.04800","9.50408","0.13424"
"114.26400","9.52214","0.13432"
"114.48000","9.54014","0.13461"
"114.69600","9.55801","0.13417"
"114.91200","9.57619","0.13483"
"115.12800","9.59407","0.13428"
"115.34400","9.61212","0.13465"
"115.56000","9.63006","0.13450"
"115.77600","9.64812","0.13486"
"115.99200","9.66611","0.13460"
"116.20800","9.68411","0.13433"
"116.42400","9.70217","0.13392"
"116.64000","9.72010","0.13412"
"116.85600","9.73816","0.13484"
"117.07200","9.75610","0.13465"
"117.28800","9.77415","0.13430"
"117.50400","9.79215","0.13476"
"117.72000","9.81009","0.13526"
"117.93600","9.82808","0.13464"
"118.15200","9.84614","0.13475"
"118.36800","9.86414","0.13475"
"118.58400","9.88213","0.13450"
"118.80000","9.90013","0.13489"
"119.01600","9.91807","0.13499"
"119.23200","9.93612","0.13457"
"119.44800","9.95412","0.13470"
"119.66400","9.97223","0.13503"
"119.88000","9.99005","0.13527"
"120.09600","10.00811","0.13531"
"120.31200","10.02611","0.13485"
"120.52800","10.04404","0.13471"
"120.74400","10.06210","0.13516"
"120.96000","10.08010","0.13443"
"121.17600","10.09809","0.13477"
"121.39200","10.11615","0.13526"
"121.60800","10.13403","0.13447"
"121.82400","10.15220","0.13493"
"122.04000","10.17008","0.13452"
"122.25600","10.18814","0.13484"
"122.47200","10.20613","0.13494"
"122.68800","10.22407","0.13468"
"122.90400","10.24213","0.13506"
"123.12000","10.26012","0.13534"
"123.33600","10.27806","0.13483"
"123.55200","10.29612","0.13487"
"123.76800","10.31405","0.13558"
"123.98400","10.33211","0.13518"
"124.20000","10.35011","0.13487"
"124.41600","10.36810","0.13479"
"124.63200","10.38610","0.13458"
"124.84800","10.40409","0.13507"
"125.06400","10.42209","0.13470"
"125.28000","10.44009","0.13519"
"125.49600","10.45809","0.13543"
"125.71200","10.47614","0.13516"
"125.92800","10.49408","0.13540"
"126.14400","10.51214","0.13512"
"126.36000","10.53013","0.13486"
"126.57600","10.54813","0.13564"
"126.79200","10.56613","0.13577"
"127.00800","10.58406","0.13506"
"127.22400","10.60212","0.13521"
"127.44000","10.62006","0.13493"
"127.65600","10.63811","0.13521"
"127.87200","10.65611","0.13531"
"128.08800","10.67405","0.13558"
"128.30400","10.69210","0.13501"
"128.52000","10.71010","0.13509"
"128.73600","10.72804","0.13547"
"128.95200","10.74615","0.13539"
"129.16800","10.76409","0.13534"
"129.38400","10.78215","0.13535"
"129.60000","10.80008","0.13532"
"129.81600","10.81814","0.13552"
"130.03200","10.83613","0.13549"
"130.24800","10.85407","0.13516"
"130.46400","10.87213","0.13498"
"130.68000","10.89007","0.13553"
"130.89600","10.90812","0.13547"
"131.11200","10.92618","0.13549"
"131.32800","10.94406","0.13532"
"131.54400","10.96217","0.13549"
"131.76000","10.98011","0.13507"
"131.97600","10.99811","0.13551"
"132.19200","11.01616","0.13477"
"132.40800","11.03404","0.13526"
"132.62400","11.05215","0.13572"
"132.84000","11.07009","0.13530"
"133.05600","11.08809","0.13565"
"133.27200","11.10614","0.13572"
"133.48800","11.12408","0.13590"
"133.70400","11.14214","0.13579"
"133.92000","11.16014","0.13572"
"134.13600","11.17813","0.13542"
"134.35200","11.19619","0.13523"
"134.56800","11.21412","0.13538"
"134.78400","11.23206","0.13554"
"135.00000","11.25012","0.13646"
"135.21600","11.26812","0.13535"
"135.43200","11.28617","0.13605"
"135.64800","11.30405","0.13491"
"135.86400","11.32211","0.13440"
"136.08000","11.34010","0.13409"
"136.29600","11.35810","0.13489"
"136.51200","11.37609","0.13457"
"136.72800","11.39409","0.13543"
"136.94400","11.41209","0.13416"
"137.16000","11.43008","0.13475"
"137.37600","11.44814","0.13458"
"137.59200","11.46614","0.13466"
"137.80800","11.48407","0.13488"
"138.02400","11.50213","0.13530"
"138.24000","11.52013","0.13446"
"138.45600","11.53818","0.13430"
"138.67200","11.55612","0.13468"
"138.88800","11.57412","0.13497"
"139.10400","11.59211","0.13442"
"139.32000","11.61011","0.13452"
"139.53600","11.62811","0.13486"
"139.75200","11.64610","0.13480"
"139.96800","11.66404","0.13491"
"140.18400","11.68210","0.13519"
"140.40000","11.70009","0.13505"
"140.61600","11.71815","0.13515"
"140.83200","11.73609","0.13517"
"141.04800","11.75408","0.13494"
"141.26400","11.77214","0.13523"
"141.48000","11.79008","0.13493"
"141.69600","11.80814","0.13514"
"141.91200","11.82613","0.13544"
"142.12800","11.84407","0.13554"
"142.34400","11.86218","0.13530"
"142.56000","11.88006","0.13534"
"142.77600","11.89812","0.13571"
"142.99200","11.91611","0.13543"
"143.20800","11.93411","0.13555"
"143.42400","11.95211","0.13552"
"143.64000","11.97010","0.13563"
"143.85600","11.98810","0.13540"
"144.07200","12.00610","0.13534"
"144.28800","12.02409","0.13530"
"144.50400","12.04209","0.13548"
"144.72000","12.06009","0.13569"
"144.93600","12.07814","0.13556"
"145.15200","12.09608","0.13526"
"145.36800","12.11408","0.13523"
"145.58400","12.13213","0.13535"
"145.80000","12.15007","0.13521"
"146.01600","12.16813","0.13572"
"146.23200","12.18606","0.13595"
"146.44800","12.20406","0.13590"
"146.66400","12.22212","0.13615"
"146.88000","12.24011","0.13594"
"147.09600","12.25817","0.13625"
"147.31200","12.27611","0.13677"
"147.52800","12.29416","0.13588"
"147.74400","12.31210","0.13543"
"147.96000","12.33010","0.13639"
"148.17600","12.34815","0.13503"
"148.39200","12.36615","0.13560"
"148.60800","12.38409","0.13642"
"148.82400","12.40214","0.13577"
"149.04000","12.42008","0.13598"
"149.25600","12.43820","0.13558"
"149.47200","12.45613","0.13572"
"149.68800","12.47407","0.13570"
"149.90400","12.49213","0.13583"
"150.12000","12.51012","0.13591"
"150.33600","12.52812","0.13600"
"150.55200","12.54612","0.13558"
"150.76800","12.56411","0.13613"
"150.98400","12.58211","0.13668"
"151.20000","12.60011","0.13581"
"151.41600","12.61810","0.13637"
"151.63200","12.63616","0.13599"
"151.84800","12.65410","0.13594"
"152.06400","12.67215","0.13559"
"152.28000","12.69009","0.13537"
"152.49600","12.70815","0.13601"
"152.71200","12.72608","0.13557"
"152.92800","12.74408","0.13632"
"153.14400","12.76220","0.13647"
"153.36000","12.78007","0.13617"
"153.57600","12.79813","0.13585"
"153.79200","12.81613","0.13584"
"154.00800","12.83406","0.13581"
"154.22400","12.85212","0.13635"
"154.44000","12.87006","0.13582"
"154.65600","12.88817","0.13573"
"154.87200","12.90605","0.13587"
"155.08800","12.92416","0.13585"
"155.30400","12.94216","0.13528"
"155.52000","12.96010","0.13586"
"155.73600","12.97816","0.13625"
"155.95200","12.99615","0.13578"
"156.16800","13.01409","0.13610"
"156.38400","13.03215","0.13604"
"156.60000","13.05008","0.13607"
"156.81600","13.06814","0.13649"
"157.03200","13.08613","0.13635"
"157.24800","13.10413","0.13639"
"157.46400","13.12207","0.13671"
"157.68000","13.14007","0.13623"
"157.89600","13.15812","0.13636"
"158.11200","13.17612","0.13623"
"158.32800","13.19412","0.13621"
"158.54400","13.21211","0.13644"
"158.76000","13.23005","0.13641"
"158.97600","13.24817","0.13632"
"159.19200","13.26604","0.13506"
"159.40800","13.28416","0.13477"
"159.62400","13.30209","0.13508"
"159.84000","13.32009","0.13545"
"160.05600","13.33809","0.13546"
"160.27200","13.35614","0.13522"
"160.48800","13.37414","0.13511"
"160.70400","13.39214","0.13541"
"160.92000","13.41002","0.13536"
"161.13600","13.42813","0.13504"
"161.35200","13.44613","0.13511"
"161.56800","13.46412","0.13485"
"161.78400","13.48206","0.13600"
"162.00000","13.50006","0.13555"
"162.21600","13.51812","0.13588"
"162.43200","13.53611","0.13562"
"162.64800","13.55411","0.13543"
"162.86400","13.57210","0.13590"
"163.08000","13.59004","0.13620"
"163.29600","13.60816","0.13660"
"163.51200","13.62604","0.13629"
"163.72800","13.64415","0.13580"
"163.94400","13.66215","0.13553"
"164.16000","13.68008","0.13651"
"164.37600","13.69814","0.13603"
"164.59200","13.71608","0.13679"
"164.80800","13.73413","0.13623"
"165.02400","13.75213","0.13689"
"165.24000","13.77001","0.13637"
"165.45600","13.78812","0.13641"
"165.67200","13.80612","0.13573"
"165.88800","13.82412","0.13673"
"166.10400","13.84211","0.13618"
"166.32000","13.86005","0.13639"
"166.53600","13.87811","0.13653"
"166.75200","13.89610","0.13672"
"166.96800","13.91410","0.13644"
"167.18400","13.93210","0.13672"
"167.40000","13.95003","0.13671"
"167.61600","13.96809","0.13671"
"167.83200","13.98609","0.13741"
"168.04800","14.00408","0.13757"
"168.26400","14.02214","0.13688"
"168.48000","14.04008","0.13786"
"168.69600","14.05807","0.13713"
"168.91200","14.07607","0.13744"
"169.12800","14.09413","0.13784"
"169.34400","14.11212","0.13756"
"169.56000","14.13006","0.13764"
"169.77600","14.14812","0.13713"
"169.99200","14.16611","0.13778"
"170.20800","14.18411","0.13795"
"170.42400","14.20211","0.13830"
"170.64000","14.22004","0.13799"
"170.85600","14.23816","0.13745"
"171.07200","14.25610","0.13777"
"171.28800","14.27415","0.13811"
"171.50400","14.29209","0.13853"
"171.72000","14.31009","0.13817"
"171.93600","14.32808","0.13791"
"172.15200","14.34608","0.13828"
"172.36800","14.36414","0.13784"
"172.58400","14.38213","0.13778"
"172.80000","14.40007","0.13780"
"173.01600","14.41813","0.13805"
"173.23200","14.43612","0.13792"
"173.44800","14.45418","0.13811"
"173.66400","14.47212","0.13840"
"173.88000","14.49011","0.13842"
"174.09600","14.50817","0.13832"
"174.31200","14.52611","0.13863"
"174.52800","14.54410","0.13815"
"174.74400","14.56216","0.13867"
"174.96000","14.58010","0.13829"
"175.17600","14.59815","0.13856"
"175.39200","14.61609","0.13923"
"175.60800","14.63415","0.13880"
"175.82400","14.65214","0.13887"
"176.04000","14.67008","0.13878"
"176.25600","14.68814","0.13921"
"176.47200","14.70613","0.13908"
"176.68800","14.72407","0.13988"
"176.90400","14.74219","0.13973"
"177.12000","14.76012","0.13974"
"177.33600","14.77818","0.14002"
"177.55200","14.79612","0.14060"
"177.76800","14.81411","0.14031"
"177.98400","14.83211","0.14013"
"178.20000","14.85011","0.14072"
"178.41600","14.86810","0.14061"
"178.63200","14.88616","0.14090"
"178.84800","14.90416","0.14119"
"179.06400","14.92215","0.14121"
"179.28000","14.94009","0.14039"
"179.49600","14.95815","0.14126"
"179.71200","14.97608","0.14109"
"179.92800","14.99414","0.14123"
"180.14400","15.01208","0.14149"
"180.36000","15.03013","0.14166"
"180.57600","15.04813","0.14208"
"180.79200","15.06613","0.14130"
"181.00800","15.08412","0.14246"
"181.22400","15.10212","0.14244"
"181.44000","15.12006","0.14214"
"181.65600","15.13811","0.14305"
"181.87200","15.15611","0.14327"
"182.08800","15.17417","0.14314"
"182.30400","15.19210","0.14395"
"182.52000","15.21016","0.14378"
"182.73600","15.22810","0.14449"
"182.95200","15.24609","0.14399"
"183.16800","15.26415","0.14510"
"183.38400","15.28215","0.14530"
"183.60000","15.30008","0.14542"
"183.81600","15.31814","0.14537"
"184.03200","15.33607","0.14617"
"184.24800","15.35419","0.14492"
"184.46400","15.37207","0.14235"
"184.68000","15.39013","0.14362"
"184.89600","15.40818","0.14281"
"185.11200","15.42606","0.14314"
"185.32800","15.44411","0.14364"
"185.54400","15.46211","0.14386"
"185.76000","15.48011","0.14402"
"185.97600","15.49817","0.14404"
"186.19200","15.51604","0.14444"
"186.40800","15.53416","0.14278"
"186.62400","15.55210","0.13386"
"186.84000","15.57009","0.13703"
"187.05600","15.58809","0.13524"
"187.27200","15.60608","0.13529"
"187.48800","15.62414","0.13494"
"187.70400","15.64208","0.13479"
"187.92000","15.66013","0.13674"
"188.13600","15.67813","0.13488"
"188.35200","15.69607","0.13573"
"188.56800","15.71412","0.13631"
"188.78400","15.73206","0.13600"
"189.00000","15.75012","0.13666"
"189.21600","15.76811","0.13571"
"189.43200","15.78611","0.13656"
"189.64800","15.80411","0.13600"
"189.86400","15.82210","0.13529"
"190.08000","15.84010","0.13686"
"190.29600","15.85816","0.13698"
"190.51200","15.87603","0.13748"
"190.72800","15.89409","0.13725"
"190.94400","15.91209","0.13731"
"191.16000","15.93014","0.13883"
"191.37600","15.94814","0.13699"
"191.59200","15.96602","0.13826"
"191.80800","15.98413","0.13776"
"192.02400","16.00207","0.13856"
"192.24000","16.02013","0.13890"
"192.45600","16.03812","0.13827"
"192.67200","16.05606","0.13936"
"192.88800","16.07418","0.13866"
"193.10400","16.09205","0.13899"
"193.32000","16.11011","0.13953"
"193.53600","16.12817","0.13873"
"193.75200","16.14604","0.14067"
"193.96800","16.16416","0.14023"
"194.18400","16.18210","0.14099"
"194.40000","16.20015","0.14077"
"194.61600","16.21815","0.14108"
"194.83200","16.23609","0.14160"
"195.04800","16.25408","0.14177"
"195.26400","16.27208","0.14259"
"195.48000","16.29014","0.14211"
"195.69600","16.30813","0.14290"
"195.91200","16.32607","0.14349"
"196.12800","16.34413","0.14385"
"196.34400","16.36212","0.14438"
"196.56000","16.38012","0.14390"
"196.77600","16.39818","0.14456"
"196.99200","16.41605","0.14471"
"197.20800","16.43411","0.14508"
"197.42400","16.45211","0.14592"
"197.64000","16.47010","0.14597"
"197.85600","16.48810","0.14664"
"198.07200","16.50610","0.14728"
"198.28800","16.52415","0.14722"
"198.50400","16.54209","0.14789"
"198.72000","16.56015","0.14729"
"198.93600","16.57808","0.14671"
"199.15200","16.59608","0.14728"
"199.36800","16.61408","0.14683"
"199.58400","16.63207","0.14863"
"199.80000","16.65013","0.14864"
"200.01600","16.66819","0.14976"
"200.23200","16.68606","0.15024"
"200.44800","16.70412","0.15001"
"200.66400","16.72212","0.15086"
"200.88000","16.74011","0.15183"
"201.09600","16.75811","0.15202"
"201.31200","16.77611","0.15208"
"201.52800","16.79410","0.15327"
"201.74400","16.81204","0.15327"
"201.96000","16.83010","0.15424"
"202.17600","16.84815","0.15481"
"202.39200","16.86603","0.15522"
"202.60800","16.88415","0.15640"
"202.82400","16.90208","0.15628"
"203.04000","16.92014","0.15591"
"203.25600","16.93814","0.15693"
"203.47200","16.95613","0.15495"
"203.68800","16.97407","0.13545"
"203.90400","16.99207","0.13364"
"204.12000","17.01012","0.13691"
"204.33600","17.02812","0.13305"
"204.55200","17.04605","0.13331"
"204.76800","17.06411","0.13259"
"204.98400","17.08211","0.13250"
"205.20000","17.10011","0.13941"
"205.41600","17.11810","0.13597"
"205.63200","17.13610","0.13605"
"205.84800","17.15410","0.13489"
"206.06400","17.17209","0.13588"
"206.28000","17.19009","0.13585"
"206.49600","17.20808","0.13369"
"206.71200","17.22608","0.13715"
"206.92800","17.24414","0.13684"
"207.14400","17.26202","0.13740"
"207.36000","17.28013","0.13698"
"207.57600","17.29813","0.13738"
"207.79200","17.31606","0.13725"
"208.00800","17.33412","0.13595"
"208.22400","17.35206","0.13934"
"208.44000","17.37017","0.13702"
"208.65600","17.38811","0.13828"
"208.87200","17.40611","0.13770"
"209.08800","17.42416","0.14041"
"209.30400","17.44210","0.13859"
"209.52000","17.46016","0.13872"
"209.73600","17.47810","0.13948"
"209.95200","17.49609","0.14080"
"210.16800","17.51409","0.14014"
"210.38400","17.53208","0.14086"
"210.60000","17.55014","0.14105"
"210.81600","17.56808","0.14138"
"211.03200","17.58613","0.14155"
"211.24800","17.60413","0.14227"
"211.46400","17.62207","0.14148"
"211.68000","17.64013","0.14314"
"211.89600","17.65812","0.14359"
"212.11200","17.67612","0.14324"
"212.32800","17.69411","0.14336"
"212.54400","17.71205","0.14550"
"212.76000","17.73017","0.14449"
"212.97600","17.74810","0.14542"
"213.19200","17.76610","0.14610"
"213.40800","17.78416","0.14638"
"213.62400","17.80210","0.14660"
"213.84000","17.82015","0.14759"
"214.05600","17.83815","0.14757"
"214.27200","17.85608","0.14808"
"214.48800","17.87414","0.14891"
"214.70400","17.89208","0.14970"
"214.92000","17.91013","0.15034"
"215.13600","17.92807","0.14987"
"215.35200","17.94613","0.15116"
"215.56800","17.96412","0.15078"
"215.78400","17.98212","0.15133"
"216.00000","18.00012","0.15242"
"216.21600","18.01811","0.15207"
"216.43200","18.03611","0.15236"
"216.64800","18.05417","0.15342"
"216.86400","18.07204","0.15410"
"217.08000","18.09016","0.15475"
"217.29600","18.10810","0.15515"
"217.51200","18.12609","0.15563"
"217.72800","18.14415","0.15599"
"217.94400","18.16203","0.15630"
"218.16000","18.18014","0.15707"
"218.37600","18.19814","0.15746"
"218.59200","18.21608","0.15742"
"218.80800","18.23413","0.15866"
"219.02400","18.25207","0.15886"
"219.24000","18.27013","0.15899"
"219.45600","18.28806","0.15942"
"219.67200","18.30612","0.16013"
"219.88800","18.32412","0.15989"
"220.10400","18.34211","0.16078"
"220.32000","18.36011","0.16112"
"220.53600","18.37817","0.16112"
"220.75200","18.39610","0.16212"
"220.96800","18.41410","0.16273"
"221.18400","18.43204","0.16300"
"221.40000","18.45009","0.16339"
"221.61600","18.46815","0.16344"
"221.83200","18.48615","0.16382"
"222.04800","18.50408","0.16407"
"222.26400","18.52214","0.16496"
"222.48000","18.54008","0.16485"
"222.69600","18.55807","0.16530"
"222.91200","18.57607","0.16576"
"223.12800","18.59413","0.16627"
"223.34400","18.61206","0.16625"
"223.56000","18.63012","0.16708"
"223.77600","18.64806","0.16737"
"223.99200","18.66617","0.16788"
"224.20800","18.68411","0.16803"
"224.42400","18.70205","0.16815"
"224.64000","18.72010","0.16913"
"224.85600","18.73810","0.16926"
"225.07200","18.75616","0.16933"
"225.28800","18.77415","0.16918"
"225.50400","18.79203","0.16991"
"225.72000","18.81015","0.17011"
"225.93600","18.82808","0.17038"
"226.15200","18.84614","0.17067"
"226.36800","18.86414","0.17122"
"226.58400","18.88201","0.17115"
"226.80000","18.90013","0.17217"
"227.01600","18.91813","0.17219"
"227.23200","18.93606","0.17215"
"227.44800","18.95412","0.17279"
"227.66400","18.97206","0.17299"
"227.88000","18.99011","0.17317"
"228.09600","19.00805","0.17346"
"228.31200","19.02611","0.17389"
"228.52800","19.04410","0.17421"
"228.74400","19.06210","0.17443"
"228.96000","19.08010","0.17488"
"229.17600","19.09809","0.17511"
"229.39200","19.11615","0.17596"
"229.60800","19.13415","0.17607"
"229.82400","19.15208","0.17672"
"230.04000","19.17014","0.17712"
"230.25600","19.18814","0.17753"
"230.47200","19.20613","0.17819"
"230.68800","19.22413","0.17821"
"230.90400","19.24207","0.17891"
"231.12000","19.26012","0.17983"
"231.33600","19.27806","0.18016"
"231.55200","19.29612","0.18043"
"231.76800","19.31411","0.18117"
"231.98400","19.33211","0.18168"
"232.20000","19.35011","0.18252"
"232.41600","19.36810","0.18301"
"232.63200","19.38610","0.18313"
"232.84800","19.40409","0.18273"
"233.06400","19.42209","0.18317"
"233.28000","19.44015","0.18393"
"233.49600","19.45809","0.18463"
"233.71200","19.47620","0.18493"
"233.92800","19.49408","0.18582"
"234.14400","19.51208","0.18668"
"234.36000","19.53013","0.18738"
"234.57600","19.54807","0.18799"
"234.79200","19.56612","0.18885"
"235.00800","19.58418","0.18909"
"235.22400","19.60206","0.19080"
"235.44000","19.62012","0.19144"
"235.65600","19.63805","0.19169"
"235.87200","19.65617","0.19260"
"236.08800","19.67410","0.19302"
"236.30400","19.69210","0.19449"
"236.52000","19.71016","0.19476"
"236.73600","19.72809","0.19541"
"236.95200","19.74615","0.19651"
"237.16800","19.76415","0.19752"
"237.38400","19.78209","0.19840"
"237.60000","19.80014","0.19870"
"237.81600","19.81814","0.19940"
"238.03200","19.83614","0.20081"
"238.24800","19.85413","0.20175"
"238.46400","19.87207","0.20276"
"238.68000","19.89012","0.20294"
"238.89600","19.90812","0.20428"
"239.11200","19.92612","0.20426"
"239.32800","19.94411","0.20535"
"239.54400","19.96205","0.20584"
"239.76000","19.98017","0.20686"
"239.97600","19.99811","0.20778"
"240.19200","20.01616","0.20825"
"240.40800","20.03403","0.20960"
"240.62400","20.05209","0.21019"
"240.84000","20.07015","0.21098"
"241.05600","20.08809","0.21158"
"241.27200","20.10608","0.21277"
"241.48800","20.12414","0.21230"
"241.70400","20.14214","0.21357"
"241.92000","20.16014","0.21469"
"242.13600","20.17807","0.21500"
"242.35200","20.19619","0.21626"
"242.56800","20.21412","0.21637"
"242.78400","20.23212","0.21716"
"243.00000","20.25012","0.21777"
"243.21600","20.26805","0.21880"
"243.43200","20.28611","0.21872"
"243.64800","20.30416","0.21919"
"243.86400","20.32204","0.21961"
"244.08000","20.34016","0.21976"
"244.29600","20.35804","0.22038"
"244.51200","20.37615","0.22067"
"244.72800","20.39409","0.22067"
"244.94400","20.41209","0.22149"
"245.16000","20.43014","0.22190"
"245.37600","20.44808","0.22187"
"245.59200","20.46614","0.22265"
"245.80800","20.48413","0.22315"
"246.02400","20.50213","0.22322"
"246.24000","20.52013","0.22388"
"246.45600","20.53806","0.22424"
"246.67200","20.55612","0.22511"
"246.88800","20.57405","0.22540"
"247.10400","20.59211","0.22603"
"247.32000","20.61011","0.22659"
"247.53600","20.62811","0.22735"
"247.75200","20.64616","0.22832"
"247.96800","20.66410","0.22907"
"248.18400","20.68210","0.22925"
"248.40000","20.70015","0.23059"
"248.61600","20.71803","0.23141"
"248.83200","20.73615","0.23180"
"249.04800","20.75408","0.23306"
"249.26400","20.77208","0.23421"
"249.48000","20.79007","0.23439"
"249.69600","20.80807","0.23665"
"249.91200","20.82613","0.23658"
"250.12800","20.84406","0.23813"
"250.34400","20.86212","0.23932"
"250.56000","20.88018","0.23998"
"250.77600","20.89806","0.24086"
"250.99200","20.91617","0.24223"
"251.20800","20.93405","0.24303"
"251.42400","20.95211","0.24367"
"251.64000","20.97010","0.24443"
"251.85600","20.98804","0.24538"
"252.07200","21.00616","0.24631"
"252.28800","21.02409","0.24710"
"252.50400","21.04209","0.24823"
"252.72000","21.06015","0.24922"
"252.93600","21.07808","0.24958"
"253.15200","21.09614","0.25030"
"253.36800","21.11414","0.25082"
"253.58400","21.13213","0.25203"
"253.80000","21.15013","0.25263"
"254.01600","21.16807","0.25343"
"254.23200","21.18612","0.25369"
"254.44800","21.20406","0.25464"
"254.66400","21.22211","0.25531"
"254.88000","21.24011","0.25545"
"255.09600","21.25811","0.25678"
"255.31200","21.27610","0.25732"
"255.52800","21.29416","0.25811"
"255.74400","21.31210","0.25860"
"255.96000","21.33016","0.25916"
"256.17600","21.34803","0.25984"
"256.39200","21.36615","0.26037"
"256.60800","21.38409","0.26047"
"256.82400","21.40214","0.26123"
"257.04000","21.42014","0.26182"
"257.25600","21.43808","0.26224"
"257.47200","21.45613","0.26244"
"257.68800","21.47407","0.26318"
"257.90400","21.49212","0.26360"
"258.12000","21.51012","0.26373"
"258.33600","21.52806","0.26439"
"258.55200","21.54618","0.26461"
"258.76800","21.56411","0.26532"
"258.98400","21.58211","0.26596"
"259.20000","21.60011","0.26615"
"259.41600","21.61810","0.26641"
"259.63200","21.63610","0.26719"
"259.84800","21.65409","0.26732"
"260.06400","21.67209","0.26831"
"260.28000","21.69015","0.26855"
"260.49600","21.70802","0.26879"
"260.71200","21.72614","0.26899"
"260.92800","21.74408","0.26940"
"261.14400","21.76213","0.26911"
"261.36000","21.78013","0.13976"
"261.57600","21.79807","0.13976"
"261.79200","21.81612","0.14590"
"262.00800","21.83412","0.13961"
"262.22400","21.85206","0.14119"
"262.44000","21.87018","0.13796"
"262.65600","21.88805","0.14616"
"262.87200","21.90611","0.13778"
"263.08800","21.92410","0.14103"
"263.30400","21.94216","0.14193"
"263.52000","21.96010","0.14073"
"263.73600","21.97815","0.14327"
"263.95200","21.99609","0.14119"
"264.16800","22.01409","0.14291"
"264.38400","22.03214","0.14119"
"264.60000","22.05014","0.14490"
"264.81600","22.06808","0.13999"
"265.03200","22.08613","0.14561"
"265.24800","22.10407","0.14098"
"265.46400","22.12213","0.14529"
"265.68000","22.14006","0.14121"
"265.89600","22.15812","0.14514"
"266.11200","22.17606","0.14159"
"266.32800","22.19405","0.14650"
"266.54400","22.21217","0.14310"
"266.76000","22.23011","0.14568"
"266.97600","22.24810","0.14388"
"267.19200","22.26610","0.14692"
"267.40800","22.28404","0.14439"
"267.62400","22.30215","0.14687"
"267.84000","22.32015","0.14464"
"268.05600","22.33809","0.14658"
"268.27200","22.35614","0.14509"
"268.48800","22.37408","0.14714"
"268.70400","22.39214","0.14558"
"268.92000","22.41013","0.14822"
"269.13600","22.42807","0.14588"
"269.35200","22.44613","0.14864"
"269.56800","22.46406","0.14660"
"269.78400","22.48218","0.14978"
"270.00000","22.50012","0.14668"
"270.21600","22.51811","0.14956"
"270.43200","22.53611","0.14708"
"270.64800","22.55411","0.15040"
"270.86400","22.57210","0.14843"
"271.08000","22.59010","0.15074"
"271.29600","22.60810","0.14961"
"271.51200","22.62615","0.15228"
"271.72800","22.64409","0.14988"
"271.94400","22.66215","0.15250"
"272.16000","22.68014","0.15216"
"272.37600","22.69808","0.15149"
"272.59200","22.71614","0.15366"
"272.80800","22.73407","0.15253"
"273.02400","22.75219","0.15506"
"273.24000","22.77013","0.15322"
"273.45600","22.78812","0.15569"
"273.67200","22.80612","0.15424"
"273.88800","22.82412","0.15578"
"274.10400","22.84211","0.15517"
"274.32000","22.86011","0.15560"
"274.53600","22.87816","0.15715"
"274.75200","22.89616","0.15566"
"274.96800","22.91410","0.15869"
"275.18400","22.93216","0.15757"
"275.40000","22.95009","0.15820"
"275.61600","22.96815","0.15885"
"275.83200","22.98609","0.15837"
"276.04800","23.00408","0.15991"
"276.26400","23.02214","0.15940"
"276.48000","23.04014","0.16140"
"276.69600","23.05813","0.16095"
"276.91200","23.07613","0.16043"
"277.12800","23.09406","0.16250"
"277.34400","23.11218","0.16213"
"277.56000","23.13012","0.16186"
"277.77600","23.14812","0.16321"
"277.99200","23.16617","0.16315"
"278.20800","23.18405","0.16363"
"278.42400","23.20217","0.16461"
"278.64000","23.22010","0.16464"
"278.85600","23.23804","0.16466"
"279.07200","23.25616","0.16480"
"279.28800","23.27403","0.16587"
"279.50400","23.29215","0.16576"
"279.72000","23.31008","0.16577"
"279.93600","23.32814","0.16749"
"280.15200","23.34614","0.16650"
"280.36800","23.36407","0.16680"
"280.58400","23.38207","0.16860"
"280.80000","23.40013","0.16784"
"281.01600","23.41807","0.16796"
"281.23200","23.43618","0.16973"
"281.44800","23.45406","0.16911"
"281.66400","23.47211","0.16909"
"281.88000","23.49011","0.17035"
"282.09600","23.50811","0.16998"
"282.31200","23.52610","0.17012"
"282.52800","23.54404","0.17172"
"282.74400","23.56216","0.17104"
"282.96000","23.58016","0.17119"
"283.17600","23.59809","0.17305"
"283.39200","23.61615","0.17212"
"283.60800","23.63402","0.17240"
"283.82400","23.65214","0.17389"
"284.04000","23.67008","0.17272"
"284.25600","23.68813","0.17370"
"284.47200","23.70613","0.17494"
"284.68800","23.72413","0.17334"
"284.90400","23.74212","0.17575"
"285.12000","23.76012","0.17697"
"285.33600","23.77812","0.17550"
"285.55200","23.79611","0.17773"
"285.76800","23.81405","0.17774"
"285.98400","23.83211","0.17690"
"286.20000","23.85011","0.17996"
"286.41600","23.86816","0.17904"
"286.63200","23.88610","0.17928"
"286.84800","23.90409","0.18237"
"287.06400","23.92215","0.18025"
"287.28000","23.94009","0.18255"
"287.49600","23.95809","0.18408"
"287.71200","23.97614","0.18256"
"287.92800","23.99408","0.18592"
"288.14400","24.01213","0.18571"
"288.36000","24.03007","0.18598"
"288.57600","24.04813","0.18928"
"288.79200","24.06612","0.18797"
"289.00800","24.08406","0.18955"
"289.22400","24.10212","0.19170"
"289.44000","24.12012","0.19093"
"289.65600","24.13811","0.19305"
"289.87200","24.15617","0.19484"
"290.08800","24.17404","0.19403"
"290.30400","24.19216","0.19673"
"290.52000","24.21010","0.19728"
"290.73600","24.22809","0.19755"
"290.95200","24.24615","0.20036"
"291.16800","24.26409","0.19935"
"291.38400","24.28214","0.20145"
"291.60000","24.30008","0.20369"
"291.81600","24.31814","0.20254"
"292.03200","24.33607","0.20577"
"292.24800","24.35407","0.20550"
"292.46400","24.37213","0.20606"
"292.68000","24.39012","0.20854"
"292.89600","24.40812","0.20806"
"293.11200","24.42612","0.21028"
"293.32800","24.44411","0.21067"
"293.54400","24.46211","0.21157"
"293.76000","24.48011","0.21319"
"293.97600","24.49816","0.21335"
"294.19200","24.51610","0.21554"
"294.40800","24.53410","0.21558"
"294.62400","24.55209","0.21618"
"294.84000","24.57009","0.21743"
"295.05600","24.58815","0.21810"
"295.27200","24.60614","0.21856"
"295.48800","24.62408","0.21981"
"295.70400","24.64214","0.21931"
"295.92000","24.66007","0.22036"
"296.13600","24.67813","0.22065"
"296.35200","24.69607","0.22149"
"296.56800","24.71412","0.22196"
"296.78400","24.73212","0.22200"
"297.00000","24.75012","0.22288"
"297.21600","24.76811","0.22308"
"297.43200","24.78611","0.22384"
"297.64800","24.80411","0.22490"
"297.86400","24.82216","0.22507"
"298.08000","24.84010","0.22600"
"298.29600","24.85815","0.22686"
"298.51200","24.87609","0.22767"
"298.72800","24.89409","0.22937"
"298.94400","24.91215","0.22969"
"299.16000","24.93014","0.23094"
"299.37600","24.94814","0.23210"
"299.59200","24.96614","0.23276"
"299.80800","24.98407","0.23468"
"300.02400","25.00213","0.23515"
"300.24000","25.02007","0.23707"
"300.45600","25.03818","0.23770"
"300.67200","25.05606","0.23895"
"300.88800","25.07412","0.24049"
"301.10400","25.09211","0.24147"
"301.32000","25.11005","0.24254"
"301.53600","25.12811","0.24423"
"301.75200","25.14616","0.24558"
"301.96800","25.16410","0.24573"
"302.18400","25.18215","0.24737"
"302.40000","25.20009","0.24811"
"302.61600","25.21815","0.24892"
"302.83200","25.23609","0.25026"
"303.04800","25.25408","0.25075"
"303.26400","25.27214","0.25219"
"303.48000","25.29008","0.25280"
"303.69600","25.30813","0.25351"
"303.91200","25.32619","0.25429"
"304.12800","25.34406","0.25467"
"304.34400","25.36218","0.25617"
"304.56000","25.38006","0.25606"
"304.77600","25.39817","0.25744"
"304.99200","25.41611","0.25773"
"305.20800","25.43411","0.25850"
"305.42400","25.45217","0.25890"
"305.64000","25.47010","0.25963"
"305.85600","25.48816","0.26007"
"306.07200","25.50609","0.26109"
"306.28800","25.52409","0.26136"
"306.50400","25.54215","0.26167"
"306.72000","25.56009","0.26255"
"306.93600","25.57814","0.26302"
"307.15200","25.59608","0.26332"
"307.36800","25.61414","0.26389"
"307.58400","25.63207","0.26424"
"307.80000","25.65013","0.26475"
"308.01600","25.66813","0.26499"
"308.23200","25.68612","0.26563"
"308.44800","25.70412","0.26583"
"308.66400","25.72211","0.26669"
"308.88000","25.74005","0.26696"
"309.09600","25.75811","0.26695"
"309.31200","25.77604","0.26776"
"309.52800","25.79410","0.26796"
"309.74400","25.81210","0.26836"
"309.96000","25.83009","0.26881"
"310.17600","25.84809","0.26906"
"310.39200","25.86609","0.27033"
"310.60800","25.88415","0.27027"
"310.82400","25.90214","0.27099"
"311.04000","25.92008","0.27142"
"311.25600","25.93814","0.27225"
"311.47200","25.95607","0.27274"
"311.68800","25.97413","0.27360"
"311.90400","25.99212","0.27438"
"312.12000","26.01006","0.13981"
"312.33600","26.02818","0.13878"
"312.55200","26.04611","0.13617"
"312.76800","26.06417","0.13119"
"312.98400","26.08217","0.12921"
"313.20000","26.10010","0.13010"
"313.41600","26.11816","0.13018"
"313.63200","26.13610","0.13082"
"313.84800","26.15409","0.13226"
"314.06400","26.17215","0.13111"
"314.28000","26.19009","0.13158"
"314.49600","26.20814","0.13252"
"314.71200","26.22608","0.13204"
"314.92800","26.24408","0.13117"
"315.14400","26.26213","0.13144"
"315.36000","26.28007","0.13125"
"315.38000","26.28175","0.13106"