File: Force_trajectories/170212_1/Specimen_RawData_6.csv
End date,"2/12/2017"
Specimen label,"9AG_79"
Maximum Load,"0.58789",N

Time,Extension,Load
(s),(mm),(N)
"0.00000","0.00000","0.00024"
"0.37800","0.03169","0.00236"
"0.75600","0.06326","0.00454"
"1.13400","0.09471","0.00630"
"1.51200","0.12622","0.00857"
"1.89000","0.15778","0.01048"
"2.26800","0.18917","0.01227"
"2.64600","0.22074","0.01396"
"3.02400","0.25225","0.01510"
"3.40200","0.28370","0.01744"
"3.78000","0.31521","0.01887"
"4.15800","0.34672","0.02088"
"4.53600","0.37823","0.02169"
"4.91400","0.40968","0.02371"
"5.29200","0.44125","0.02511"
"5.67000","0.47276","0.02602"
"6.04800","0.50421","0.02717"
"6.42600","0.53571","0.02864"
"6.80400","0.56722","0.02974"
"7.18200","0.59867","0.03032"
"7.56000","0.63018","0.03164"
"7.93800","0.66175","0.03204"
"8.31600","0.69326","0.03347"
"8.69400","0.72471","0.03408"
"9.07200","0.75622","0.03464"
"9.45000","0.78773","0.03543"
"9.82800","0.81918","0.03656"
"10.20600","0.85075","0.03762"
"10.58400","0.88219","0.03816"
"10.96200","0.91370","0.03880"
"11.34000","0.94521","0.03946"
"11.71800","0.97678","0.04023"
"12.09600","1.00823","0.03982"
"12.47400","1.03968","0.03551"
"12.85200","1.07125","0.03181"
"13.23000","1.10276","0.03099"
"13.60800","1.13415","0.03014"
"13.98600","1.16572","0.03200"
"14.36400","1.19723","0.03214"
"14.74200","1.22873","0.03193"
"15.12000","1.26018","0.03363"
"15.49800","1.29175","0.03444"
"15.87600","1.32326","0.03523"
"16.25400","1.35465","0.03595"
"16.63200","1.38622","0.03652"
"17.01000","1.41773","0.03798"
"17.38800","1.44918","0.03843"
"17.76600","1.48069","0.03925"
"18.14400","1.51220","0.03959"
"18.52200","1.54377","0.04111"
"18.90000","1.57522","0.04256"
"19.27800","1.60672","0.04226"
"19.65600","1.63823","0.04345"
"20.03400","1.66974","0.04374"
"20.41200","1.70125","0.04450"
"20.79000","1.73276","0.04540"
"21.16800","1.76421","0.04652"
"21.54600","1.79572","0.04685"
"21.92400","1.82723","0.04718"
"22.30200","1.85874","0.04813"
"22.68000","1.89019","0.04833"
"23.05800","1.92176","0.05019"
"23.43600","1.95326","0.05016"
"23.81400","1.98465","0.05116"
"24.19200","2.01622","0.05152"
"24.57000","2.04779","0.05154"
"24.94800","2.07918","0.05238"
"25.32600","2.11069","0.05260"
"25.70400","2.14226","0.05350"
"26.08200","2.17371","0.05453"
"26.46000","2.20522","0.05472"
"26.83800","2.23679","0.05527"
"27.21600","2.26824","0.05499"
"27.59400","2.29968","0.05563"
"27.97200","2.33125","0.05597"
"28.35000","2.36270","0.05723"
"28.72800","2.39427","0.05718"
"29.10600","2.42572","0.05709"
"29.48400","2.45723","0.05847"
"29.86200","2.48874","0.05851"
"30.24000","2.52013","0.05873"
"30.61800","2.55176","0.05861"
"30.99600","2.58327","0.05951"
"31.37400","2.61466","0.06021"
"31.75200","2.64616","0.06091"
"32.13000","2.67773","0.06073"
"32.50800","2.70918","0.06106"
"32.88600","2.74069","0.06144"
"33.26400","2.77220","0.06190"
"33.64200","2.80377","0.06226"
"34.02000","2.83522","0.06269"
"34.39800","2.86667","0.06325"
"34.77600","2.89824","0.06370"
"35.15400","2.92975","0.06347"
"35.53200","2.96126","0.06380"
"35.91000","2.99277","0.06394"
"36.28800","3.02427","0.06402"
"36.66600","3.05560","0.06478"
"37.04400","3.08729","0.06518"
"37.42200","3.11874","0.06459"
"37.80000","3.15013","0.06503"
"38.17800","3.18176","0.06513"
"38.55600","3.21321","0.06541"
"38.93400","3.24472","0.06571"
"39.31200","3.27617","0.06287"
"39.69000","3.30774","0.06328"
"40.06800","3.33925","0.06419"
"40.44600","3.37069","0.06393"
"40.82400","3.40226","0.06454"
"41.20200","3.43371","0.06525"
"41.58000","3.46516","0.06556"
"41.95800","3.49673","0.06614"
"42.33600","3.52824","0.06601"
"42.71400","3.55969","0.06655"
"43.09200","3.59120","0.06666"
"43.47000","3.62271","0.06763"
"43.84800","3.65422","0.05340"
"44.22600","3.68567","0.05645"
"44.60400","3.71723","0.05784"
"44.98200","3.74874","0.05790"
"45.36000","3.78019","0.05886"
"45.73800","3.81170","0.05933"
"46.11600","3.84321","0.05935"
"46.49400","3.87472","0.06007"
"46.87200","3.90623","0.06171"
"47.25000","3.93774","0.06238"
"47.62800","3.96919","0.06291"
"48.00600","4.00070","0.06346"
"48.38400","4.03221","0.06343"
"48.76200","4.06372","0.06382"
"49.14000","4.09522","0.06482"
"49.51800","4.12673","0.06518"
"49.89600","4.15824","0.06536"
"50.27400","4.18975","0.06614"
"50.65200","4.22120","0.06633"
"51.03000","4.25277","0.06668"
"51.40800","4.28434","0.06743"
"51.78600","4.31567","0.06861"
"52.16400","4.34718","0.06872"
"52.54200","4.37875","0.06879"
"52.92000","4.41020","0.06942"
"53.29800","4.44170","0.07056"
"53.67600","4.47321","0.07135"
"54.05400","4.50472","0.07152"
"54.43200","4.53623","0.07269"
"54.81000","4.56774","0.07298"
"55.18800","4.59925","0.06725"
"55.56600","4.63070","0.06768"
"55.94400","4.66221","0.06843"
"56.32200","4.69372","0.06877"
"56.70000","4.72523","0.06946"
"57.07800","4.75668","0.06986"
"57.45600","4.78824","0.07050"
"57.83400","4.81975","0.07109"
"58.21200","4.85114","0.07231"
"58.59000","4.88277","0.07320"
"58.96800","4.91422","0.07407"
"59.34600","4.94567","0.07533"
"59.72400","4.97724","0.07642"
"60.10200","5.00875","0.07814"
"60.48000","5.04020","0.07900"
"60.85800","5.07171","0.08004"
"61.23600","5.10328","0.08121"
"61.61400","5.13473","0.08258"
"61.99200","5.16617","0.08398"
"62.37000","5.19768","0.08579"
"62.74800","5.22925","0.08670"
"63.12600","5.26064","0.08832"
"63.50400","5.29221","0.08917"
"63.88200","5.32372","0.09064"
"64.26000","5.35523","0.09159"
"64.63800","5.38668","0.09349"
"65.01600","5.41831","0.09518"
"65.39400","5.44976","0.09613"
"65.77200","5.48121","0.09701"
"66.15000","5.51271","0.09807"
"66.52800","5.54416","0.09971"
"66.90600","5.57573","0.10150"
"67.28400","5.60724","0.10311"
"67.66200","5.63875","0.10414"
"68.04000","5.67020","0.10575"
"68.41800","5.70171","0.10699"
"68.79600","5.73322","0.10847"
"69.17400","5.76473","0.10957"
"69.55200","5.79618","0.11070"
"69.93000","5.82775","0.11167"
"70.30800","5.85925","0.11267"
"70.68600","5.89070","0.11365"
"71.06400","5.92221","0.11405"
"71.44200","5.95372","0.11480"
"71.82000","5.98523","0.11591"
"72.19800","6.01668","0.11615"
"72.57600","6.04819","0.11740"
"72.95400","6.07976","0.11807"
"73.33200","6.11115","0.11921"
"73.71000","6.14272","0.12041"
"74.08800","6.17423","0.12164"
"74.46600","6.20568","0.12279"
"74.84400","6.23712","0.12478"
"75.22200","6.26875","0.12670"
"75.60000","6.30020","0.12923"
"75.97800","6.33171","0.13130"
"76.35600","6.36322","0.13278"
"76.73400","6.39473","0.13449"
"77.11200","6.42624","0.13649"
"77.49000","6.45769","0.13864"
"77.86800","6.48920","0.14050"
"78.24600","6.52071","0.14166"
"78.62400","6.55222","0.14311"
"79.00200","6.58372","0.14347"
"79.38000","6.61529","0.14498"
"79.75800","6.64662","0.14649"
"80.13600","6.67825","0.14745"
"80.51400","6.70976","0.14936"
"80.89200","6.74121","0.15045"
"81.27000","6.77272","0.15159"
"81.64800","6.80429","0.15276"
"82.02600","6.83568","0.15398"
"82.40400","6.86719","0.15497"
"82.78200","6.89876","0.15586"
"83.16000","6.93020","0.15674"
"83.53800","6.96171","0.15747"
"83.91600","6.99316","0.15809"
"84.29400","7.02467","0.15896"
"84.67200","7.05618","0.15999"
"85.05000","7.08775","0.16111"
"85.42800","7.11926","0.16156"
"85.80600","7.15071","0.16251"
"86.18400","7.18216","0.16373"
"86.56200","7.21373","0.16471"
"86.94000","7.24524","0.16548"
"87.31800","7.27668","0.15891"
"87.69600","7.30825","0.15970"
"88.07400","7.33970","0.16079"
"88.45200","7.37121","0.16203"
"88.83000","7.40272","0.16319"
"89.20800","7.43423","0.16406"
"89.58600","7.46574","0.16495"
"89.96400","7.49719","0.16610"
"90.34200","7.52876","0.16803"
"90.72000","7.56027","0.16946"
"91.09800","7.59166","0.17190"
"91.47600","7.62323","0.17392"
"91.85400","7.65474","0.17646"
"92.23200","7.68624","0.17928"
"92.61000","7.71769","0.18218"
"92.98800","7.74926","0.18514"
"93.36600","7.78077","0.18950"
"93.74400","7.81216","0.19376"
"94.12200","7.84373","0.19661"
"94.50000","7.87524","0.20141"
"94.87800","7.90675","0.20420"
"95.25600","7.93820","0.20843"
"95.63400","7.96971","0.21204"
"96.01200","8.00127","0.21524"
"96.39000","8.03272","0.21647"
"96.76800","8.06423","0.21870"
"97.14600","8.09574","0.21976"
"97.52400","8.12719","0.22095"
"97.90200","8.15876","0.22260"
"98.28000","8.19021","0.22426"
"98.65800","8.22172","0.22640"
"99.03600","8.25323","0.22826"
"99.41400","8.28474","0.23137"
"99.79200","8.31619","0.23344"
"100.17000","8.34769","0.23648"
"100.54800","8.37926","0.23963"
"100.92600","8.41071","0.24237"
"101.30400","8.44216","0.24514"
"101.68200","8.47373","0.24777"
"102.06000","8.50524","0.24892"
"102.43800","8.53669","0.25120"
"102.81600","8.56820","0.25358"
"103.19400","8.59971","0.25524"
"103.57200","8.63122","0.24334"
"103.95000","8.66267","0.24680"
"104.32800","8.69423","0.24940"
"104.70600","8.72574","0.25308"
"105.08400","8.75725","0.25539"
"105.46200","8.78870","0.25842"
"105.84000","8.82027","0.26039"
"106.21800","8.85172","0.26215"
"106.59600","8.88317","0.26339"
"106.97400","8.91474","0.26458"
"107.35200","8.94625","0.26578"
"107.73000","8.97764","0.26634"
"108.10800","9.00927","0.26764"
"108.48600","9.04078","0.26819"
"108.86400","9.07222","0.26942"
"109.24200","9.10373","0.27072"
"109.62000","9.13518","0.27178"
"109.99800","9.16669","0.27326"
"110.37600","9.19820","0.27451"
"110.75400","9.22971","0.27590"
"111.13200","9.26122","0.27482"
"111.51000","9.29273","0.27690"
"111.88800","9.32418","0.27759"
"112.26600","9.35575","0.27868"
"112.64400","9.38720","0.28101"
"113.02200","9.41870","0.28388"
"113.40000","9.45021","0.28731"
"113.77800","9.48178","0.29004"
"114.15600","9.51317","0.29265"
"114.53400","9.54474","0.29618"
"114.91200","9.57625","0.29946"
"115.29000","9.60764","0.30193"
"115.66800","9.63927","0.30513"
"116.04600","9.67072","0.30814"
"116.42400","9.70223","0.30986"
"116.80200","9.73374","0.31230"
"117.18000","9.76525","0.31479"
"117.55800","9.79675","0.31775"
"117.93600","9.82814","0.31944"
"118.31400","9.85977","0.32431"
"118.69200","9.89128","0.32804"
"119.07000","9.92267","0.32965"
"119.44800","9.95418","0.31836"
"119.82600","9.98575","0.31832"
"120.20400","10.01720","0.30873"
"120.58200","10.04865","0.28370"
"120.96000","10.08022","0.28145"
"121.33800","10.11172","0.28444"
"121.71600","10.14323","0.28718"
"122.09400","10.17474","0.29037"
"122.47200","10.20625","0.29442"
"122.85000","10.23770","0.29829"
"123.22800","10.26921","0.30279"
"123.60600","10.30072","0.30592"
"123.98400","10.33223","0.30959"
"124.36200","10.36374","0.31256"
"124.74000","10.39525","0.31497"
"125.11800","10.42670","0.31757"
"125.49600","10.45815","0.32115"
"125.87400","10.48972","0.32538"
"126.25200","10.52122","0.33017"
"126.63000","10.55273","0.33509"
"127.00800","10.58418","0.34153"
"127.38600","10.61569","0.34848"
"127.76400","10.64720","0.35291"
"128.14200","10.67871","0.35484"
"128.52000","10.71028","0.30064"
"128.89800","10.74173","0.30184"
"129.27600","10.77318","0.30531"
"129.65400","10.80469","0.30726"
"130.03200","10.83626","0.31091"
"130.41000","10.86770","0.31298"
"130.78800","10.89921","0.31534"
"131.16600","10.93072","0.31833"
"131.54400","10.96223","0.31999"
"131.92200","10.99368","0.32485"
"132.30000","11.02525","0.33032"
"132.67800","11.05676","0.33464"
"133.05600","11.08821","0.34093"
"133.43400","11.11966","0.34664"
"133.81200","11.15123","0.35192"
"134.19000","11.18274","0.35769"
"134.56800","11.21418","0.36073"
"134.94600","11.24575","0.31198"
"135.32400","11.27720","0.31334"
"135.70200","11.30865","0.31456"
"136.08000","11.34022","0.31704"
"136.45800","11.37173","0.32006"
"136.83600","11.40318","0.32190"
"137.21400","11.43475","0.32771"
"137.59200","11.46620","0.33149"
"137.97000","11.49771","0.33690"
"138.34800","11.52922","0.34315"
"138.72600","11.56073","0.34824"
"139.10400","11.59223","0.35271"
"139.48200","11.62368","0.35703"
"139.86000","11.65519","0.36026"
"140.23800","11.68676","0.36427"
"140.61600","11.71821","0.36819"
"140.99400","11.74972","0.36977"
"141.37200","11.78123","0.37160"
"141.75000","11.81274","0.37332"
"142.12800","11.84419","0.37417"
"142.50600","11.87582","0.37484"
"142.88400","11.90721","0.37564"
"143.26200","11.93871","0.37612"
"143.64000","11.97022","0.37720"
"144.01800","12.00173","0.37869"
"144.39600","12.03324","0.37999"
"144.77400","12.06469","0.38134"
"145.15200","12.09626","0.38262"
"145.53000","12.12771","0.38531"
"145.90800","12.15922","0.38631"
"146.28600","12.19067","0.38880"
"146.66400","12.22224","0.38857"
"147.04200","12.25369","0.38733"
"147.42000","12.28525","0.39011"
"147.79800","12.31670","0.39305"
"148.17600","12.34821","0.39606"
"148.55400","12.37972","0.39978"
"148.93200","12.41129","0.40435"
"149.31000","12.44274","0.40852"
"149.68800","12.47413","0.41379"
"150.06600","12.50570","0.41678"
"150.44400","12.53721","0.41963"
"150.82200","12.56872","0.42210"
"151.20000","12.60017","0.42407"
"151.57800","12.63173","0.42576"
"151.95600","12.66324","0.42804"
"152.33400","12.69469","0.43160"
"152.71200","12.72626","0.43364"
"153.09000","12.75771","0.43725"
"153.46800","12.78916","0.44147"
"153.84600","12.82079","0.44465"
"154.22400","12.85224","0.44716"
"154.60200","12.88369","0.44988"
"154.98000","12.91520","0.45289"
"155.35800","12.94671","0.45481"
"155.73600","12.97822","0.45747"
"156.11400","13.00972","0.45312"
"156.49200","13.04129","0.45554"
"156.87000","13.07274","0.45743"
"157.24800","13.10413","0.45934"
"157.62600","13.13576","0.46139"
"158.00400","13.16727","0.46293"
"158.38200","13.19872","0.46457"
"158.76000","13.23023","0.46642"
"159.13800","13.26174","0.46857"
"159.51600","13.29325","0.47053"
"159.89400","13.32469","0.46836"
"160.27200","13.35620","0.46900"
"160.65000","13.38777","0.47063"
"161.02800","13.41916","0.47155"
"161.40600","13.45073","0.47394"
"161.78400","13.48224","0.47616"
"162.16200","13.51369","0.47810"
"162.54000","13.54520","0.48014"
"162.91800","13.57677","0.48281"
"163.29600","13.60822","0.48564"
"163.67400","13.63967","0.48826"
"164.05200","13.67124","0.49146"
"164.43000","13.70268","0.49373"
"164.80800","13.73419","0.49732"
"165.18600","13.76576","0.50058"
"165.56400","13.79715","0.50363"
"165.94200","13.82866","0.50629"
"166.32000","13.86023","0.50749"
"166.69800","13.89174","0.51115"
"167.07600","13.92331","0.51419"
"167.45400","13.95464","0.51680"
"167.83200","13.98621","0.51877"
"168.21000","14.01778","0.52076"
"168.58800","14.04916","0.52181"
"168.96600","14.08074","0.52331"
"169.34400","14.11224","0.52469"
"169.72200","14.14369","0.52592"
"170.10000","14.17520","0.52843"
"170.47800","14.20671","0.52992"
"170.85600","14.23822","0.53331"
"171.23400","14.26973","0.53735"
"171.61200","14.30124","0.53980"
"171.99000","14.33275","0.54375"
"172.36800","14.36420","0.54803"
"172.74600","14.39571","0.55221"
"173.12400","14.42721","0.55409"
"173.50200","14.45872","0.54656"
"173.88000","14.49023","0.12880"
"174.25800","14.52174","0.14673"
"174.63600","14.55325","0.14667"
"175.01400","14.58464","0.14953"
"175.39200","14.61627","0.15341"
"175.77000","14.64772","0.15383"
"176.14800","14.67917","0.15437"
"176.52600","14.71074","0.15772"
"176.90400","14.74219","0.15600"
"177.28200","14.77376","0.15614"
"177.66000","14.80520","0.15834"
"178.03800","14.83677","0.15890"
"178.41600","14.86822","0.15985"
"178.79400","14.89967","0.16185"
"179.17200","14.93124","0.16285"
"179.55000","14.96275","0.16454"
"179.92800","14.99420","0.16686"
"180.30600","15.02571","0.16844"
"180.68400","15.05722","0.17142"
"181.06200","15.08873","0.17476"
"181.44000","15.12018","0.17683"
"181.81800","15.15168","0.18247"
"182.19600","15.18325","0.18527"
"182.57400","15.21470","0.19090"
"182.95200","15.24621","0.19582"
"183.33000","15.27772","0.20199"
"183.70800","15.30923","0.20945"
"184.08600","15.34068","0.21221"
"184.46400","15.37225","0.21516"
"184.84200","15.40376","0.21835"
"185.22000","15.43515","0.22070"
"185.59800","15.46672","0.22226"
"185.97600","15.49822","0.22419"
"186.35400","15.52967","0.22669"
"186.73200","15.56118","0.23124"
"187.11000","15.59275","0.23563"
"187.48800","15.62420","0.19083"
"187.86600","15.65571","0.13174"
"188.24400","15.68722","0.13974"
"188.62200","15.71873","0.13981"
"189.00000","15.75018","0.14346"
"189.37800","15.78169","0.14825"
"189.75600","15.81319","0.14949"
"190.13400","15.84476","0.15046"
"190.51200","15.87621","0.15393"
"190.89000","15.90772","0.15528"
"191.26800","15.93923","0.15678"
"191.64600","15.97068","0.15879"
"192.02400","16.00225","0.16014"
"192.40200","16.03376","0.16147"
"192.78000","16.06515","0.16278"
"193.15800","16.09672","0.16256"
"193.53600","16.12823","0.16388"
"193.91400","16.15968","0.16686"
"194.29200","16.19118","0.16885"
"194.67000","16.22275","0.17240"
"195.04800","16.25420","0.17670"
"195.42600","16.28571","0.18130"
"195.80400","16.31722","0.18795"
"196.18200","16.34879","0.19362"
"196.56000","16.38018","0.20098"
"196.93800","16.41169","0.20830"
"197.31600","16.44326","0.21246"
"197.69400","16.47471","0.21688"
"198.07200","16.50616","0.21910"
"198.45000","16.53772","0.22177"
"198.82800","16.56923","0.22466"
"199.20600","16.60062","0.22864"
"199.58400","16.63225","0.23331"
"199.96200","16.66370","0.23845"
"200.34000","16.69521","0.24377"
"200.71800","16.72672","0.24863"
"201.09600","16.75823","0.25356"
"201.47400","16.78974","0.25789"
"201.85200","16.82125","0.26186"
"202.23000","16.85275","0.26402"
"202.60800","16.88421","0.26601"
"202.98600","16.91566","0.26749"
"203.36400","16.94728","0.26960"
"203.74200","16.97873","0.27174"
"204.12000","17.01018","0.27518"
"204.49800","17.04175","0.27849"
"204.87600","17.07320","0.28408"
"205.25400","17.10471","0.28964"
"205.63200","17.13616","0.29484"
"206.01000","17.16779","0.30123"
"206.38800","17.19924","0.30642"
"206.76600","17.23069","0.31109"
"207.14400","17.26219","0.31296"
"207.52200","17.29376","0.31632"
"207.90000","17.32521","0.32181"
"208.27800","17.35672","0.32910"
"208.65600","17.38823","0.33825"
"209.03400","17.41974","0.34763"
"209.41200","17.45119","0.35679"
"209.79000","17.48276","0.36386"
"210.16800","17.51427","0.36924"
"210.54600","17.54572","0.37266"
"210.92400","17.57717","0.37469"
"211.30200","17.60874","0.37615"
"211.68000","17.64024","0.37779"
"212.05800","17.67169","0.37972"
"212.43600","17.70326","0.38292"
"212.81400","17.73477","0.38786"
"213.19200","17.76616","0.39227"
"213.57000","17.79773","0.39918"
"213.94800","17.82918","0.40810"
"214.32600","17.86069","0.41587"
"214.70400","17.89226","0.42141"
"215.08200","17.92371","0.42504"
"215.46000","17.95516","0.42912"
"215.83800","17.98672","0.43500"
"216.21600","18.01823","0.44202"
"216.59400","18.04974","0.44774"
"216.97200","18.08119","0.45321"
"217.35000","18.11270","0.45775"
"217.72800","18.14421","0.46008"
"218.10600","18.17572","0.46345"
"218.48400","18.20723","0.46731"
"218.86200","18.23880","0.47215"
"219.24000","18.27025","0.47727"
"219.61800","18.30164","0.48278"
"219.99600","18.33326","0.48940"
"220.37400","18.36471","0.49556"
"220.75200","18.39622","0.50212"
"221.13000","18.42773","0.49875"
"221.50800","18.45918","0.50335"
"221.88600","18.49069","0.47173"
"222.26400","18.52220","0.47403"
"222.64200","18.55371","0.47723"
"223.02000","18.58522","0.48262"
"223.39800","18.61667","0.48793"
"223.77600","18.64818","0.49358"
"224.15400","18.67974","0.49863"
"224.53200","18.71113","0.50570"
"224.91000","18.74270","0.51238"
"225.28800","18.77427","0.51798"
"225.66600","18.80572","0.52259"
"226.04400","18.83717","0.52504"
"226.42200","18.86874","0.52856"
"226.80000","18.90025","0.53392"
"227.17800","18.93164","0.54282"
"227.55600","18.96321","0.55084"
"227.93400","18.99472","0.55785"
"228.31200","19.02623","0.56469"
"228.69000","19.05767","0.57079"
"229.06800","19.08924","0.57603"
"229.44600","19.12069","0.57960"
"229.82400","19.15220","0.58232"
"230.20200","19.18377","0.58424"
"230.58000","19.21528","0.58609"
"230.95800","19.24667","0.51128"
"231.33600","19.27824","0.45876"
"231.71400","19.30975","0.45943"
"232.09200","19.34126","0.46259"
"232.47000","19.37271","0.46500"
"232.84800","19.40421","0.46637"
"233.22600","19.43572","0.46647"
"233.60400","19.46717","0.47015"
"233.98200","19.49868","0.47442"
"234.36000","19.53025","0.47994"
"234.73800","19.56164","0.48578"
"235.11600","19.59321","0.49023"
"235.49400","19.62478","0.41055"
"235.87200","19.65617","0.41310"
"236.25000","19.68773","0.42123"
"236.62800","19.71925","0.42747"
"237.00600","19.75070","0.43350"
"237.38400","19.78220","0.44106"
"237.76200","19.81377","0.44847"
"238.14000","19.84522","0.45469"
"238.51800","19.87673","0.45924"
"238.89600","19.90824","0.46309"
"239.27400","19.93969","0.46679"
"239.65200","19.97126","0.46892"
"240.03000","20.00271","0.47397"
"240.40800","20.03428","0.47749"
"240.78600","20.06573","0.48136"
"241.16400","20.09718","0.48727"
"241.54200","20.12874","0.49026"
"241.92000","20.16019","0.49269"
"242.29800","20.19170","0.49744"
"242.67600","20.22321","0.48980"
"243.05400","20.25472","0.49569"
"243.43200","20.28623","0.50183"
"243.81000","20.31774","0.50742"
"244.18800","20.34919","0.51273"
"244.56600","20.38076","0.51720"
"244.94400","20.41221","0.52103"
"245.32200","20.44372","0.52357"
"245.70000","20.47522","0.52600"
"246.07800","20.50667","0.52915"
"246.45600","20.53818","0.53273"
"246.83400","20.56975","0.53916"
"247.21200","20.60120","0.54411"
"247.59000","20.63271","0.55148"
"247.96800","20.66422","0.55403"
"248.34600","20.69573","0.55975"
"248.72400","20.72718","0.56381"
"249.10200","20.75875","0.56945"
"249.48000","20.79020","0.57324"
"249.85800","20.82170","0.57731"
"250.23600","20.85315","0.57973"
"250.61400","20.88472","0.57987"
"250.99200","20.91629","0.58164"
"251.37000","20.94768","0.58343"
"251.74800","20.97919","0.58547"
"252.12600","21.01076","0.58700"
"252.50400","21.04209","0.45121"
"252.88200","21.07378","0.45160"
"253.26000","21.10523","0.45145"
"253.63800","21.13667","0.45334"
"254.01600","21.16818","0.45556"
"254.39400","21.19975","0.45784"
"254.77200","21.23126","0.45902"
"255.15000","21.26271","0.46115"
"255.52800","21.29422","0.46375"
"255.90600","21.32579","0.46531"
"256.28400","21.35718","0.46831"
"256.66200","21.38869","0.47170"
"257.04000","21.42020","0.47454"
"257.41800","21.45177","0.47776"
"257.79600","21.48322","0.48134"
"258.17400","21.51472","0.48389"
"258.55200","21.54623","0.48821"
"258.93000","21.57768","0.49248"
"259.30800","21.60925","0.49639"
"259.68600","21.64070","0.50031"
"260.06400","21.67221","0.50483"
"260.44200","21.70372","0.50824"
"260.82000","21.73523","0.51255"
"261.19800","21.76674","0.51589"
"261.57600","21.79819","0.51877"
"261.95400","21.82976","0.51947"
"262.33200","21.86127","0.51724"
"262.71000","21.89266","0.25885"
"263.08800","21.92422","0.26209"
"263.46600","21.95579","0.26186"
"263.84400","21.98718","0.26289"
"264.22200","22.01875","0.26437"
"264.60000","22.05026","0.26503"
"264.97800","22.08171","0.26569"
"265.35600","22.11322","0.26645"
"265.73400","22.14467","0.26668"
"266.11200","22.17624","0.26696"
"266.49000","22.20769","0.26772"
"266.86800","22.23919","0.26826"
"267.24600","22.27071","0.26930"
"267.62400","22.30221","0.27006"
"268.00200","22.33366","0.27099"
"268.38000","22.36529","0.27274"
"268.75800","22.39674","0.27489"
"269.13600","22.42813","0.27608"
"269.51400","22.45976","0.27770"
"269.89200","22.49127","0.27674"
"270.27000","22.52266","0.04451"
"270.64800","22.55423","0.05997"
"271.02600","22.58574","0.04999"
"271.40400","22.61719","0.05075"
"271.78200","22.64869","0.05524"
"272.16000","22.68020","0.05735"
"272.53800","22.71171","0.05689"
"272.91600","22.74316","0.05747"
"273.29400","22.77473","0.05965"
"273.67200","22.80630","0.06205"
"274.05000","22.83763","0.06152"
"274.42800","22.86920","0.06218"
"274.80600","22.90071","0.06434"
"275.18400","22.93222","0.06411"
"275.56200","22.96367","0.06456"
"275.94000","22.99523","0.06644"
"276.31800","23.02674","0.06632"
"276.69600","23.05819","0.06672"
"277.07400","23.08970","0.06850"
"277.45200","23.12121","0.06930"
"277.83000","23.15272","0.06974"
"278.20800","23.18423","0.07050"
"278.58600","23.21574","0.07194"
"278.96400","23.24725","0.07145"
"279.34200","23.27870","0.07178"
"279.72000","23.31027","0.07355"
"280.09800","23.34171","0.07344"
"280.47600","23.37310","0.07307"
"280.85400","23.40473","0.07351"
"281.23200","23.43624","0.07614"
"281.61000","23.46769","0.07601"
"281.98800","23.49920","0.07632"
"282.36600","23.53071","0.07728"
"282.74400","23.56222","0.07725"
"283.12200","23.59373","0.07783"
"283.50000","23.62530","0.07861"
"283.87800","23.65675","0.08032"
"284.25600","23.68813","0.08244"
"284.63400","23.71970","0.08397"
"285.01200","23.75127","0.08511"
"285.39000","23.78272","0.08714"
"285.76800","23.81423","0.08869"
"286.14600","23.84574","0.08993"
"286.52400","23.87731","0.09174"
"286.90200","23.90870","0.09339"
"287.28000","23.94027","0.09421"
"287.65800","23.97178","0.09640"
"288.03600","24.00323","0.09630"
"288.41400","24.03468","0.09827"
"288.79200","24.06618","0.09973"
"289.17000","24.09775","0.10124"
"289.54800","24.12920","0.10279"
"289.92600","24.16077","0.10443"
"290.30400","24.19228","0.10590"
"290.68200","24.22367","0.10571"
"291.06000","24.25524","0.10159"
"291.43800","24.28675","0.10195"
"291.81600","24.31820","0.10304"
"292.19400","24.34971","0.10479"
"292.57200","24.38121","0.10630"
"292.95000","24.41272","0.10800"
"293.32800","24.44423","0.10947"
"293.70600","24.47574","0.11111"
"294.08400","24.50725","0.11147"
"294.46200","24.53870","0.11276"
"294.84000","24.57021","0.11311"
"295.21800","24.60172","0.11399"
"295.59600","24.63317","0.11434"
"295.97400","24.66474","0.10251"
"296.35200","24.69625","0.10530"
"296.73000","24.72770","0.10770"
"297.10800","24.75915","0.10956"
"297.48600","24.79077","0.11148"
"297.86400","24.82222","0.11312"
"298.24200","24.85367","0.11390"
"298.62000","24.88524","0.11497"
"298.99800","24.91675","0.11558"
"299.37600","24.94820","0.11587"
"299.75400","24.97971","0.11653"
"300.13200","25.01122","0.11747"
"300.51000","25.04279","0.11830"
"300.88800","25.07417","0.11928"
"301.26600","25.10568","0.12144"
"301.64400","25.13725","0.12360"
"302.02200","25.16870","0.12456"
"302.40000","25.20021","0.12743"
"302.77800","25.23172","0.12952"
"303.15600","25.26323","0.13218"
"303.53400","25.29468","0.13487"
"303.91200","25.32625","0.13712"
"304.29000","25.35776","0.13915"
"304.66800","25.38921","0.14101"
"305.04600","25.42071","0.14286"
"305.42400","25.45223","0.14479"
"305.80200","25.48368","0.14667"
"306.18000","25.51518","0.14824"
"306.55800","25.54675","0.15003"
"306.93600","25.57826","0.15152"
"307.31400","25.60971","0.15294"
"307.69200","25.64128","0.15425"
"308.07000","25.67273","0.15565"
"308.44800","25.70418","0.15637"
"308.82600","25.73575","0.15748"
"309.20400","25.76720","0.15806"
"309.58200","25.79871","0.15896"
"309.96000","25.83021","0.15971"
"310.33800","25.86172","0.16097"
"310.71600","25.89317","0.16218"
"311.09400","25.92468","0.16297"
"311.47200","25.95625","0.16394"
"311.85000","25.98782","0.16559"
"312.22800","26.01915","0.16661"
"312.60600","26.05078","0.16832"
"312.98400","26.08229","0.17046"
"313.36200","26.11368","0.17210"
"313.74000","26.14519","0.17542"
"314.11800","26.17669","0.17801"
"314.49600","26.20827","0.18138"
"314.87400","26.23971","0.18500"
"315.25200","26.27122","0.18830"
"315.63000","26.30273","0.19353"
"316.00800","26.33424","0.19738"
"316.38600","26.36569","0.20186"
"316.76400","26.39720","0.20573"
"317.14200","26.42871","0.20982"
"317.52000","26.46016","0.21302"
"317.89800","26.49173","0.21569"
"318.27600","26.52324","0.21711"
"318.65400","26.55469","0.21876"
"319.03200","26.58625","0.22053"
"319.41000","26.61776","0.22202"
"319.78800","26.64921","0.22340"
"320.16600","26.68072","0.22567"
"320.54400","26.71217","0.22805"
"320.92200","26.74368","0.23140"
"321.30000","26.77525","0.23418"
"321.67800","26.80676","0.22048"
"322.05600","26.83827","0.22146"
"322.43400","26.86966","0.22261"
"322.81200","26.90122","0.22235"
"323.19000","26.93273","0.22335"
"323.56800","26.96418","0.22524"
"323.94600","26.99569","0.22761"
"324.32400","27.02726","0.22991"
"324.70200","27.05871","0.23336"
"325.08000","27.09016","0.23541"
"325.45800","27.12173","0.23826"
"325.83600","27.15324","0.24048"
"326.21400","27.18469","0.24190"
"326.59200","27.21626","0.24372"
"326.97000","27.24771","0.24608"
"327.34800","27.27921","0.24782"
"327.72600","27.31072","0.25010"
"328.10400","27.34223","0.25215"
"328.48200","27.37374","0.25439"
"328.86000","27.40519","0.25545"
"329.23800","27.43670","0.25551"
"329.61600","27.46827","0.25195"
"329.99400","27.49972","0.25413"
"330.37200","27.53123","0.25572"
"330.75000","27.56280","0.25772"
"331.12800","27.59418","0.25906"
"331.50600","27.62569","0.25987"
"331.88400","27.65721","0.26121"
"332.26200","27.68871","0.26251"
"332.64000","27.72022","0.26392"
"333.01800","27.75173","0.26494"
"333.39600","27.78324","0.26608"
"333.77400","27.81463","0.26691"
"334.15200","27.84620","0.26779"
"334.53000","27.87777","0.26862"
"334.90800","27.90922","0.26934"
"335.28600","27.94072","0.27036"
"335.66400","27.97224","0.27140"
"336.04200","28.00368","0.27228"
"336.42000","28.03519","0.27375"
"336.79800","28.06676","0.27456"
"337.17600","28.09821","0.27435"
"337.55400","28.12972","0.27636"
"337.93200","28.16117","0.27624"
"338.31000","28.19274","0.27771"
"338.68800","28.22425","0.27919"
"339.06600","28.25570","0.28022"
"339.44400","28.28727","0.28269"
"339.82200","28.31877","0.28365"
"340.20000","28.35016","0.28512"
"340.57800","28.38173","0.05017"
"340.95600","28.41324","0.05044"
"341.33400","28.44469","0.05778"
"341.71200","28.47626","0.05474"
"342.09000","28.50771","0.06399"
"342.46800","28.53922","0.05574"
"342.84600","28.57073","0.05974"
"343.22400","28.60217","0.06151"
"343.60200","28.63381","0.06016"
"343.98000","28.66525","0.06495"
"344.35800","28.69665","0.06203"
"344.73600","28.72821","0.06249"
"345.11400","28.75978","0.06652"
"345.49200","28.79117","0.06454"
"345.87000","28.82274","0.06556"
"346.24800","28.85419","0.06833"
"346.62600","28.88564","0.06697"
"347.00400","28.91727","0.06745"
"347.38200","28.94878","0.07089"
"347.76000","28.98017","0.06980"
"348.13800","29.01173","0.07115"
"348.51600","29.04318","0.07380"
"348.89400","29.07470","0.07311"
"349.27200","29.10620","0.05523"
"349.65000","29.13771","0.06091"
"350.02800","29.16922","0.05936"
"350.40600","29.20067","0.06003"
"350.78400","29.23230","0.06334"
"351.16200","29.26381","0.06209"
"351.54000","29.29514","0.06281"
"351.91800","29.32671","0.06498"
"352.29600","29.35822","0.06375"
"352.67400","29.38966","0.06495"
"353.05200","29.42123","0.06634"
"353.43000","29.45274","0.06567"
"353.80800","29.48419","0.06627"
"354.18600","29.51570","0.06799"
"354.56400","29.54721","0.06712"
"354.94200","29.57872","0.06761"
"355.32000","29.61023","0.06934"
"355.69800","29.64168","0.06976"
"356.07600","29.67325","0.06944"
"356.45400","29.70476","0.07068"
"356.83200","29.73621","0.07209"
"357.21000","29.76777","0.07201"
"357.58800","29.79922","0.07284"
"357.96600","29.83067","0.07468"
"358.34400","29.86224","0.07508"
"358.72200","29.89369","0.07576"
"359.10000","29.92520","0.07678"
"359.47800","29.95671","0.07839"
"359.85600","29.98828","0.07962"
"360.23400","30.01973","0.07963"
"360.61200","30.05124","0.08052"
"360.99000","30.08269","0.08167"
"361.36800","30.11426","0.08257"
"361.74600","30.14565","0.08354"
"362.12400","30.17715","0.08457"
"362.50200","30.20872","0.08587"
"362.88000","30.24017","0.08692"
"363.25800","30.27174","0.08790"
"363.63600","30.30325","0.08892"
"364.01400","30.33476","0.09049"
"364.39200","30.36621","0.09108"
"364.77000","30.39778","0.09175"
"365.14800","30.42923","0.09355"
"365.52600","30.46073","0.09415"
"365.90400","30.49224","0.09494"
"366.28200","30.52375","0.09612"
"366.66000","30.55526","0.09689"
"367.03800","30.58671","0.09840"
"367.41600","30.61822","0.09995"
"367.79400","30.64973","0.10158"
"368.17200","30.68112","0.10264"
"368.55000","30.71275","0.10378"
"368.92800","30.74426","0.10493"
"369.30600","30.77571","0.10683"
"369.68400","30.80722","0.10747"
"370.06200","30.83867","0.10906"
"370.44000","30.87023","0.11043"
"370.81800","30.90174","0.11079"
"371.19600","30.93325","0.11174"
"371.57400","30.96476","0.11257"
"371.95200","30.99615","0.11359"
"372.33000","31.02772","0.11422"
"372.70800","31.05923","0.11457"
"373.08600","31.09074","0.11494"
"373.46400","31.12218","0.11500"
"373.84200","31.15376","0.11516"
"374.22000","31.18515","0.11576"
"374.59800","31.21666","0.11645"
"374.97600","31.24822","0.11707"
"375.35400","31.27973","0.11781"
"375.73200","31.31118","0.11835"
"376.11000","31.34275","0.11917"
"376.48800","31.37420","0.12022"
"376.86600","31.40571","0.12156"
"377.24400","31.43721","0.12226"
"377.62200","31.46873","0.12331"
"378.00000","31.50023","0.12420"
"378.37800","31.53168","0.12623"
"378.75600","31.56325","0.12739"
"379.13400","31.59476","0.12859"
"379.51200","31.62621","0.12962"
"379.89000","31.65772","0.13115"
"380.26800","31.68923","0.13309"
"380.64600","31.72074","0.13453"
"381.02400","31.75219","0.13555"
"381.40200","31.78370","0.13620"
"381.78000","31.81526","0.13690"
"382.15800","31.84671","0.13853"
"382.53600","31.87823","0.13983"
"382.91400","31.90973","0.14052"
"383.29200","31.94118","0.14109"
"383.67000","31.97269","0.14129"
"384.04800","32.00426","0.14196"
"384.42600","32.03571","0.14261"
"384.80400","32.06716","0.14272"
"385.18200","32.09879","0.14336"
"385.56000","32.13024","0.14358"
"385.93800","32.16163","0.14461"
"386.31600","32.19326","0.14540"
"386.69400","32.22476","0.14668"
"387.07200","32.25621","0.14741"
"387.45000","32.28772","0.14759"
"387.82800","32.31923","0.13336"
"388.20600","32.35074","0.06796"
"388.58400","32.38219","0.07018"
"388.96200","32.41370","0.07506"
"389.34000","32.44527","0.07596"
"389.71800","32.47666","0.07531"
"390.09600","32.50823","0.07777"
"390.47400","32.53979","0.08254"
"390.85200","32.57119","0.08563"
"391.23000","32.60270","0.08578"
"391.60800","32.63426","0.08784"
"391.98600","32.66571","0.09145"
"392.36400","32.69722","0.09380"
"392.74200","32.72873","0.09449"
"393.12000","32.76018","0.09480"
"393.49800","32.79169","0.09726"
"393.87600","32.82320","0.10012"
"394.25400","32.85471","0.10140"
"394.63200","32.88622","0.10280"
"395.01000","32.91772","0.10429"
"395.38800","32.94923","0.10529"
"395.76600","32.98074","0.10726"
"396.14400","33.01219","0.10814"
"396.52200","33.04370","0.10927"
"396.90000","33.07527","0.10996"
"397.27800","33.10672","0.11079"
"397.65600","33.13823","0.11092"
"398.03400","33.16974","0.11001"
"398.41200","33.20119","0.10911"
"398.79000","33.23270","0.10907"
"399.16800","33.26421","0.10943"
"399.54600","33.29577","0.11016"
"399.92400","33.32716","0.11178"
"400.30200","33.35873","0.11267"
"400.68000","33.39024","0.11343"
"401.05800","33.42169","0.11422"
"401.43600","33.45320","0.11452"
"401.81400","33.48477","0.11552"
"402.19200","33.51622","0.11560"
"402.57000","33.54766","0.11626"
"402.94800","33.57924","0.11653"
"403.32600","33.61074","0.11692"
"403.70400","33.64220","0.11741"
"404.08200","33.67370","0.11751"
"404.46000","33.70521","0.11746"
"404.83800","33.73672","0.11749"
"405.21600","33.76817","0.11711"
"405.59400","33.79974","0.11607"
"405.97200","33.83125","0.11565"
"406.35000","33.86264","0.11598"
"406.72800","33.89421","0.11589"
"407.10600","33.92577","0.11547"
"407.48400","33.95723","0.11433"
"407.86200","33.98874","0.11399"
"408.24000","34.02024","0.11035"
"408.61800","34.05169","0.11133"
"408.99600","34.08326","0.11220"
"409.37400","34.11477","0.11177"
"409.75200","34.14622","0.11284"
"410.13000","34.17773","0.11391"
"410.50800","34.20924","0.11501"
"410.88600","34.24075","0.11500"
"411.26400","34.27220","0.11557"
"411.64200","34.30376","0.11582"
"412.02000","34.33522","0.11638"
"412.39800","34.36672","0.11738"
"412.77600","34.39817","0.11839"
"413.15400","34.42974","0.11895"
"413.53200","34.46119","0.11912"
"413.91000","34.49270","0.11783"
"414.28800","34.52427","0.09074"
"414.66600","34.55572","0.09192"
"415.04400","34.58717","0.09342"
"415.42200","34.61868","0.09399"
"415.80000","34.65025","0.09358"
"416.17800","34.68176","0.09318"
"416.55600","34.71320","0.09372"
"416.93400","34.74471","0.09374"
"417.31200","34.77628","0.09352"
"417.69000","34.80767","0.06679"
"418.06800","34.83924","0.07048"
"418.44600","34.87075","0.07075"
"418.82400","34.90220","0.07207"
"419.20200","34.93371","0.07448"
"419.58000","34.96522","0.07615"
"419.95800","34.99673","0.07674"
"420.33600","35.02818","0.07808"
"420.71400","35.05969","0.08013"
"421.09200","35.09119","0.08168"
"421.47000","35.12270","0.08297"
"421.84800","35.15415","0.08499"
"422.22600","35.18572","0.08749"
"422.60400","35.21723","0.08798"
"422.98200","35.24868","0.08941"
"423.36000","35.28025","0.09055"
"423.73800","35.31176","0.09111"
"424.11600","35.34315","0.09225"
"424.49400","35.37477","0.09347"
"424.87200","35.40622","0.09493"
"425.25000","35.43761","0.09605"
"425.62800","35.46925","0.09706"
"426.00600","35.50069","0.09820"
"426.38400","35.53220","0.09966"
"426.76200","35.56371","0.10088"
"427.14000","35.59522","0.10234"
"427.51800","35.62673","0.10328"
"427.89600","35.65818","0.10420"
"428.27400","35.68975","0.10555"
"428.65200","35.72126","0.10606"
"429.03000","35.75265","0.10713"
"429.40800","35.78421","0.10837"
"429.78600","35.81578","0.10865"
"430.16400","35.84723","0.10980"
"430.54200","35.87868","0.11031"
"430.92000","35.91025","0.10998"
"431.29800","35.94170","0.11079"
"431.67600","35.97315","0.11201"
"432.05400","36.00472","0.11293"
"432.43200","36.03623","0.11384"
"432.81000","36.06773","0.11420"
"433.18800","36.09919","0.11472"
"433.56600","36.13070","0.11527"
"433.94400","36.16227","0.11553"
"434.32200","36.19371","0.11623"
"434.70000","36.22528","0.11641"
"435.07800","36.25673","0.11693"
"435.45600","36.28812","0.11728"
"435.83400","36.31969","0.11840"
"436.21200","36.35120","0.11914"
"436.59000","36.38271","0.11959"
"436.96800","36.41422","0.12204"
"437.34600","36.44572","0.12276"
"437.72400","36.47723","0.12336"
"438.10200","36.50874","0.12509"
"438.48000","36.54020","0.12573"
"438.85800","36.57176","0.12736"
"439.23600","36.60315","0.12449"
"439.61400","36.63472","0.12079"
"439.99200","36.66623","0.12052"
"440.37000","36.69774","0.12136"
"440.74800","36.72919","0.12242"
"441.12600","36.76070","0.12242"
"441.50400","36.79227","0.12291"
"441.88200","36.82366","0.12269"
"442.26000","36.85522","0.12304"
"442.63800","36.88673","0.12441"
"443.01600","36.91824","0.12568"
"443.39400","36.94970","0.12538"
"443.77200","36.98132","0.12564"
"444.15000","37.01271","0.12791"
"444.52800","37.04416","0.12699"
"444.90600","37.07573","0.12731"
"445.28400","37.10723","0.12703"
"445.66200","37.13863","0.12739"
"446.04000","37.17026","0.12748"
"446.41800","37.20177","0.12830"
"446.79600","37.23315","0.12754"
"447.17400","37.26472","0.12859"
"447.55200","37.29623","0.12820"
"447.93000","37.32768","0.12682"
"448.30800","37.35919","0.12553"
"448.68600","37.39070","0.12435"
"449.06400","37.42227","0.12421"
"449.44200","37.45366","0.07596"
"449.82000","37.48517","0.07872"
"450.19800","37.51674","0.08115"
"450.57600","37.54818","0.08237"
"450.95400","37.57969","0.08376"
"451.33200","37.61121","0.08640"
"451.71000","37.64272","0.08789"
"452.08800","37.67416","0.08657"
"452.46600","37.70579","0.08749"
"452.84400","37.73724","0.08799"
"453.22200","37.76869","0.08930"
"453.60000","37.80026","0.08842"
"453.97800","37.83165","0.08945"
"454.35600","37.86322","0.09040"
"454.73400","37.89473","0.09091"
"455.11200","37.92624","0.08985"
"455.49000","37.95774","0.09009"
"455.86800","37.98919","0.09214"
"456.24600","38.02070","0.09246"
"456.62400","38.05227","0.09135"
"457.00200","38.08366","0.09086"
"457.38000","38.11523","0.09036"
"457.75800","38.14674","0.09241"
"458.13600","38.17819","0.09317"
"458.51400","38.20969","0.09460"
"458.89200","38.24127","0.09627"
"459.27000","38.27278","0.09745"
"459.64800","38.30416","0.09620"
"460.02600","38.33573","0.09845"
"460.40400","38.36724","0.10038"
"460.78200","38.39869","0.10187"
"461.16000","38.43020","0.10377"
"461.53800","38.46177","0.10496"
"461.91600","38.49322","0.10597"
"462.29400","38.52467","0.10747"
"462.67200","38.55624","0.10836"
"463.05000","38.58775","0.10928"
"463.42800","38.61919","0.10935"
"463.80600","38.65071","0.11033"
"464.18400","38.68216","0.11082"
"464.56200","38.71372","0.11120"
"464.94000","38.74517","0.11252"
"465.31800","38.77668","0.11226"
"465.69600","38.80825","0.11325"
"466.07400","38.83970","0.11343"
"466.45200","38.87121","0.11382"
"466.83000","38.90278","0.11507"
"467.20800","38.93411","0.11488"
"467.58600","38.96574","0.11480"
"467.96400","38.99725","0.11549"
"468.34200","39.02869","0.11564"
"468.72000","39.06020","0.11624"
"469.09800","39.09177","0.11633"
"469.47600","39.12322","0.11676"
"469.85400","39.15467","0.11764"
"470.23200","39.18624","0.11855"
"470.61000","39.21769","0.11799"
"470.98800","39.24920","0.11880"
"471.36600","39.28071","0.11997"
"471.74400","39.31221","0.11969"
"472.12200","39.34373","0.12040"
"472.50000","39.37523","0.11946"
"472.87800","39.40674","0.12041"
"473.25600","39.43825","0.12152"
"473.63400","39.46964","0.12227"
"474.01200","39.50121","0.12348"
"474.39000","39.53272","0.12448"
"474.76800","39.56422","0.12525"
"475.14600","39.59574","0.12616"
"475.52400","39.62725","0.12750"
"475.90200","39.65870","0.12853"
"476.28000","39.69020","0.12902"
"476.65800","39.72171","0.13093"
"477.03600","39.75322","0.13093"
"477.41400","39.78467","0.13154"
"477.79200","39.81618","0.13061"
"478.17000","39.84775","0.13123"
"478.54800","39.87920","0.13244"
"478.92600","39.91071","0.13484"
"479.30400","39.94222","0.13454"
"479.68200","39.97373","0.13592"
"480.06000","40.00518","0.13722"
"480.43800","40.03674","0.13928"
"480.81600","40.06825","0.14019"
"481.19400","40.09970","0.14116"
"481.57200","40.13121","0.14210"
"481.95000","40.16272","0.14191"
"482.32800","40.19423","0.14293"
"482.70600","40.22568","0.14373"
"483.08400","40.25724","0.14287"
"483.46200","40.28870","0.14191"
"483.84000","40.32014","0.14326"
"484.21800","40.35172","0.14463"
"484.59600","40.38329","0.14525"
"484.97400","40.41467","0.14533"
"485.35200","40.44624","0.14630"
"485.73000","40.47775","0.14681"
"486.10800","40.50920","0.14741"
"486.48600","40.54071","0.14793"
"486.86400","40.57222","0.14910"
"487.24200","40.60373","0.14985"
"487.62000","40.63518","0.15046"
"487.99800","40.66674","0.15126"
"488.37600","40.69820","0.15182"
"488.75400","40.72964","0.15231"
"489.13200","40.76127","0.15290"
"489.51000","40.79272","0.15316"
"489.88800","40.82423","0.15334"
"490.26600","40.85574","0.15398"
"490.64400","40.88719","0.15488"
"491.02200","40.91870","0.15503"
"491.40000","40.95015","0.15524"
"491.77800","40.98178","0.15568"
"492.15600","41.01323","0.15492"
"492.53400","41.04473","0.14446"
"492.91200","41.07619","0.14477"
"493.29000","41.10775","0.14571"
"493.66800","41.13926","0.14748"
"494.04600","41.17065","0.14871"
"494.42400","41.20222","0.15045"
"494.80200","41.23373","0.15211"
"495.18000","41.26518","0.15229"
"495.55800","41.29675","0.15349"
"495.93600","41.32832","0.15324"
"496.31400","41.35965","0.15356"
"496.69200","41.39116","0.15421"
"497.07000","41.42273","0.15403"
"497.44800","41.45424","0.15401"
"497.82600","41.48569","0.15098"
"498.20400","41.51719","0.12013"
"498.58200","41.54876","0.12153"
"498.96000","41.58021","0.12238"
"499.33800","41.61166","0.12406"
"499.71600","41.64323","0.12679"
"500.09400","41.67474","0.12993"
"500.47200","41.70625","0.13187"
"500.85000","41.73770","0.13412"
"501.22800","41.76926","0.13440"
"501.60600","41.80066","0.13513"
"501.98400","41.83229","0.13912"
"502.36200","41.86379","0.14114"
"502.74000","41.89512","0.14304"
"503.11800","41.92675","0.14376"
"503.49600","41.95820","0.14135"
"503.87400","41.98971","0.14078"
"504.25200","42.02122","0.14142"
"504.63000","42.05279","0.14272"
"505.00800","42.08424","0.14376"
"505.38600","42.11569","0.14369"
"505.76400","42.14719","0.14406"
"506.14200","42.17876","0.14324"
"506.52000","42.21015","0.13717"
"506.89800","42.24172","0.12866"
"507.27600","42.27324","0.13184"
"507.65400","42.30474","0.13431"
"508.03200","42.33619","0.13707"
"508.41000","42.36770","0.14029"
"508.78800","42.39921","0.14174"
"509.16600","42.43065","0.14335"
"509.54400","42.46223","0.14560"
"509.92200","42.49374","0.14732"
"510.30000","42.52525","0.14815"
"510.67800","42.55669","0.14895"
"511.05600","42.58826","0.14967"
"511.43400","42.61977","0.15088"
"511.81200","42.65123","0.15165"
"512.19000","42.68273","0.15314"
"512.56800","42.71424","0.15388"
"512.94600","42.74563","0.15397"
"513.32400","42.77719","0.15511"
"513.70200","42.80871","0.15584"
"514.08000","42.84015","0.15672"
"514.45800","42.87167","0.15737"
"514.83600","42.90318","0.15701"
"515.21400","42.93475","0.15854"
"515.59200","42.96619","0.15893"
"515.97000","42.99776","0.15995"
"516.34800","43.02927","0.15979"
"516.72600","43.06072","0.16081"
"517.10400","43.09217","0.16119"
"517.48200","43.12374","0.16209"
"517.86000","43.15525","0.16268"
"518.23800","43.18670","0.16349"
"518.61600","43.21821","0.16359"
"518.99400","43.24971","0.16445"
"519.37200","43.28116","0.16454"
"519.75000","43.31274","0.16482"
"520.12800","43.34424","0.16606"
"520.50600","43.37569","0.16617"
"520.88400","43.40720","0.16651"
"521.26200","43.43877","0.16654"
"521.64000","43.47022","0.16715"
"522.01800","43.50167","0.16744"
"522.39600","43.53324","0.16844"
"522.77400","43.56481","0.16699"
"523.15200","43.59614","0.16817"
"523.53000","43.62777","0.16933"
"523.90800","43.65927","0.16974"
"524.28600","43.69066","0.17074"
"524.66400","43.72223","0.17122"
"525.04200","43.75374","0.17309"
"525.42000","43.78519","0.17413"
"525.79800","43.81676","0.17642"
"526.17600","43.84821","0.17798"
"526.55400","43.87978","0.17969"
"526.93200","43.91122","0.18299"
"527.31000","43.94268","0.18325"
"527.68800","43.97424","0.17976"
"528.06600","44.00570","0.17050"
"528.44400","44.03714","0.16448"
"528.82200","44.06871","0.16173"
"529.20000","44.10022","0.16148"
"529.57800","44.13167","0.16110"
"529.95600","44.16330","0.15813"
"530.33400","44.19475","0.15448"
"530.71200","44.22620","0.15097"
"531.09000","44.25771","0.15204"
"531.46800","44.28916","0.15345"
"531.84600","44.32072","0.15370"
"532.22400","44.35223","0.15237"
"532.60200","44.38375","0.15161"
"532.98000","44.41519","0.15208"
"533.35800","44.44670","0.15373"
"533.73600","44.47821","0.15489"
"534.11400","44.50978","0.15618"
"534.49200","44.54117","0.15751"
"534.87000","44.57268","0.15815"
"535.24800","44.60424","0.15867"
"535.62600","44.63570","0.15938"
"536.00400","44.66720","0.16066"
"536.38200","44.69872","0.16185"
"536.76000","44.73028","0.16133"
"537.13800","44.76161","0.16284"
"537.51600","44.79319","0.16416"
"537.89400","44.82469","0.16540"
"538.27200","44.85620","0.16623"
"538.65000","44.88771","0.16846"
"539.02800","44.91922","0.16970"
"539.40600","44.95073","0.17145"
"539.78400","44.98218","0.17299"
"540.16200","45.01375","0.17178"
"540.54000","45.04526","0.17532"
"540.91800","45.07664","0.17955"
"541.29600","45.10827","0.18207"
"541.67400","45.13972","0.18541"
"542.05200","45.17123","0.19048"
"542.43000","45.20268","0.19408"
"542.80800","45.23419","0.19783"
"543.18600","45.26576","0.20264"
"543.56400","45.29721","0.20479"
"543.94200","45.32872","0.20811"
"544.32000","45.36029","0.20986"
"544.69800","45.39167","0.21037"
"545.07600","45.42325","0.21208"
"545.45400","45.45475","0.21406"
"545.83200","45.48621","0.21240"
"546.21000","45.51771","0.21608"
"546.58800","45.54928","0.21724"
"546.96600","45.58073","0.21957"
"547.34400","45.61218","0.22048"
"547.72200","45.64375","0.22150"
"548.10000","45.67526","0.22205"
"548.47800","45.70671","0.22213"
"548.85600","45.73822","0.22442"
"549.23400","45.76972","0.22597"
"549.61200","45.80124","0.22736"
"549.99000","45.83274","0.22888"
"550.36800","45.86425","0.23182"
"550.74600","45.89576","0.23452"
"551.12400","45.92715","0.23723"
"551.50200","45.95872","0.23958"
"551.88000","45.99023","0.24323"
"552.25800","46.02168","0.24612"
"552.63600","46.05325","0.24834"
"553.01400","46.08469","0.25023"
"553.39200","46.11621","0.25332"
"553.77000","46.14771","0.25531"
"554.14800","46.17922","0.25710"
"554.52600","46.21079","0.25929"
"554.90400","46.24218","0.26097"
"555.28200","46.27363","0.26243"
"555.66000","46.30520","0.26398"
"556.03800","46.33671","0.26506"
"556.41600","46.36816","0.26563"
"556.79400","46.39972","0.26627"
"557.17200","46.43124","0.26728"
"557.55000","46.46268","0.26813"
"557.92800","46.49425","0.26938"
"558.30600","46.52571","0.27013"
"558.68400","46.55716","0.27085"
"559.06200","46.58872","0.27182"
"559.44000","46.62023","0.27304"
"559.81800","46.65168","0.27464"
"560.19600","46.68319","0.27673"
"560.57400","46.71470","0.27846"
"560.95200","46.74627","0.28136"
"561.33000","46.77765","0.28318"
"561.70800","46.80923","0.28134"
"562.08600","46.84079","0.28426"
"562.46400","46.87212","0.28598"
"562.84200","46.90375","0.28868"
"563.22000","46.93526","0.29109"
"563.59800","46.96665","0.29365"
"563.97600","46.99822","0.29645"
"564.35400","47.02973","0.29851"
"564.73200","47.06129","0.29703"
"565.11000","47.09262","0.29938"
"565.48800","47.12426","0.30006"
"565.86600","47.15571","0.30245"
"566.24400","47.18721","0.30481"
"566.52600","47.21071","0.30707"