File: Force_trajectories/170212_1/Specimen_RawData_1.csv
End date,"2/12/2017"
Specimen label,"10BG_Unk1"
Maximum Load,"0.11691",N

Time,Extension,Load
(s),(mm),(N)
"0.00000","0.00000","0.00067"
"0.28200","0.02266","0.00008"
"0.56400","0.04729","0.00116"
"0.84600","0.07067","0.00142"
"1.12800","0.09429","0.00159"
"1.41000","0.11767","0.00079"
"1.69200","0.14122","0.00178"
"1.97400","0.16472","0.00223"
"2.25600","0.18822","0.00196"
"2.53800","0.21165","0.00277"
"2.82000","0.23521","0.00292"
"3.10200","0.25865","0.00320"
"3.38400","0.28221","0.00285"
"3.66600","0.30564","0.00406"
"3.94800","0.32920","0.00341"
"4.23000","0.35270","0.00417"
"4.51200","0.37620","0.00399"
"4.79400","0.39969","0.00440"
"5.07600","0.42313","0.00423"
"5.35800","0.44669","0.00525"
"5.64000","0.47013","0.00452"
"5.92200","0.49368","0.00525"
"6.20400","0.51712","0.00490"
"6.48600","0.54074","0.00552"
"6.76800","0.56417","0.00539"
"7.05000","0.58773","0.00586"
"7.33200","0.61111","0.00621"
"7.61400","0.63467","0.00613"
"7.89600","0.65816","0.00594"
"8.17800","0.68172","0.00621"
"8.46000","0.70516","0.00594"
"8.74200","0.72871","0.00682"
"9.02400","0.75215","0.00663"
"9.30600","0.77571","0.00660"
"9.58800","0.79921","0.00656"
"9.87000","0.82276","0.00632"
"10.15200","0.84620","0.00711"
"10.43400","0.86970","0.00770"
"10.71600","0.89314","0.00746"
"10.99800","0.91669","0.00733"
"11.28000","0.94019","0.00775"
"11.56200","0.96369","0.00765"
"11.84400","0.98724","0.00826"
"12.12600","1.01068","0.00810"
"12.40800","1.03418","0.00845"
"12.69000","1.05768","0.00840"
"12.97200","1.08117","0.00885"
"13.25400","1.10461","0.00889"
"13.53600","1.12811","0.00878"
"13.81800","1.15161","0.00902"
"14.10000","1.17522","0.00961"
"14.38200","1.19866","0.00945"
"14.66400","1.22222","0.00947"
"14.94600","1.24566","0.00982"
"15.22800","1.26921","0.00956"
"15.51000","1.29271","0.01035"
"15.79200","1.31621","0.00981"
"16.07400","1.33970","0.01002"
"16.35600","1.36320","0.01058"
"16.63800","1.38670","0.01085"
"16.92000","1.41020","0.01077"
"17.20200","1.43369","0.01094"
"17.48400","1.45719","0.01053"
"17.76600","1.48075","0.01168"
"18.04800","1.50413","0.01143"
"18.33000","1.52774","0.01122"
"18.61200","1.55118","0.01209"
"18.89400","1.57474","0.01128"
"19.17600","1.59817","0.01168"
"19.45800","1.62173","0.01175"
"19.74000","1.64517","0.01220"
"20.02200","1.66873","0.01210"
"20.30400","1.69216","0.01191"
"20.58600","1.71566","0.01255"
"20.86800","1.73910","0.01271"
"21.15000","1.76271","0.01272"
"21.43200","1.78615","0.01302"
"21.71400","1.80965","0.01306"
"21.99600","1.83315","0.01324"
"22.27800","1.85664","0.01344"
"22.56000","1.88020","0.01366"
"22.84200","1.90364","0.01384"
"23.12400","1.92720","0.01397"
"23.40600","1.95069","0.01396"
"23.68800","1.97425","0.01428"
"23.97000","1.99769","0.01463"
"24.25200","2.02125","0.01473"
"24.53400","2.04468","0.01526"
"24.81600","2.06818","0.01485"
"25.09800","2.09162","0.01528"
"25.38000","2.11523","0.01518"
"25.66200","2.13861","0.01556"
"25.94400","2.16223","0.01641"
"26.22600","2.18567","0.01585"
"26.50800","2.20922","0.01610"
"26.79000","2.23272","0.01609"
"27.07200","2.25628","0.01592"
"27.35400","2.27972","0.01695"
"27.63600","2.30321","0.01664"
"27.91800","2.32665","0.01708"
"28.20000","2.35021","0.01692"
"28.48200","2.37370","0.01711"
"28.76400","2.39720","0.01765"
"29.04600","2.42070","0.01769"
"29.32800","2.44420","0.01803"
"29.61000","2.46769","0.01773"
"29.89200","2.49119","0.01803"
"30.17400","2.51469","0.01877"
"30.45600","2.53813","0.01875"
"30.73800","2.56168","0.01833"
"31.02000","2.58512","0.01902"
"31.30200","2.60874","0.01941"
"31.58400","2.63217","0.02020"
"31.86600","2.65567","0.02003"
"32.14800","2.67911","0.01996"
"32.43000","2.70273","0.02052"
"32.71200","2.72616","0.02109"
"32.99400","2.74966","0.02008"
"33.27600","2.77322","0.02082"
"33.55800","2.79677","0.02128"
"33.84000","2.82021","0.02145"
"34.12200","2.84377","0.02117"
"34.40400","2.86727","0.02174"
"34.68600","2.89070","0.02176"
"34.96800","2.91420","0.02182"
"35.25000","2.93770","0.02217"
"35.53200","2.96126","0.02227"
"35.81400","2.98469","0.02235"
"36.09600","3.00819","0.02294"
"36.37800","3.03169","0.02279"
"36.66000","3.05519","0.02317"
"36.94200","3.07868","0.02348"
"37.22400","3.10218","0.02382"
"37.50600","3.12562","0.02374"
"37.78800","3.14917","0.02437"
"38.07000","3.17261","0.02400"
"38.35200","3.19617","0.02448"
"38.63400","3.21967","0.02453"
"38.91600","3.24322","0.02393"
"39.19800","3.26666","0.02506"
"39.48000","3.29016","0.02555"
"39.76200","3.31366","0.02528"
"40.04400","3.33715","0.02592"
"40.32600","3.36071","0.02581"
"40.60800","3.38415","0.02692"
"40.89000","3.40770","0.02681"
"41.17200","3.43120","0.02644"
"41.45400","3.45476","0.02661"
"41.73600","3.47814","0.02732"
"42.01800","3.50175","0.02721"
"42.30000","3.52513","0.02791"
"42.58200","3.54869","0.02767"
"42.86400","3.57219","0.02816"
"43.14600","3.59574","0.02838"
"43.42800","3.61918","0.02841"
"43.71000","3.64268","0.02935"
"43.99200","3.66612","0.02775"
"44.27400","3.68973","0.02830"
"44.55600","3.71317","0.02860"
"44.83800","3.73673","0.02889"
"45.12000","3.76016","0.02881"
"45.40200","3.78366","0.02946"
"45.68400","3.80716","0.02936"
"45.96600","3.83066","0.02946"
"46.24800","3.85415","0.03039"
"46.53000","3.87765","0.03012"
"46.81200","3.90121","0.02989"
"47.09400","3.92464","0.03105"
"47.37600","3.94820","0.03111"
"47.65800","3.97170","0.03094"
"47.94000","3.99520","0.03139"
"48.22200","4.01863","0.03161"
"48.50400","4.04219","0.03186"
"48.78600","4.06569","0.03186"
"49.06800","4.08919","0.03196"
"49.35000","4.11268","0.03268"
"49.63200","4.13624","0.03255"
"49.91400","4.15968","0.03311"
"50.19600","4.18323","0.03323"
"50.47800","4.20667","0.03354"
"50.76000","4.23023","0.03383"
"51.04200","4.25373","0.03361"
"51.32400","4.27722","0.03414"
"51.60600","4.30066","0.03423"
"51.88800","4.32416","0.03463"
"52.17000","4.34766","0.03463"
"52.45200","4.37115","0.03490"
"52.73400","4.39471","0.03533"
"53.01600","4.41815","0.03510"
"53.29800","4.44170","0.03554"
"53.58000","4.46514","0.03579"
"53.86200","4.48864","0.03599"
"54.14400","4.51214","0.03617"
"54.42600","4.53569","0.03645"
"54.70800","4.55907","0.03609"
"54.99000","4.58269","0.03652"
"55.27200","4.60613","0.03694"
"55.55400","4.62968","0.03693"
"55.83600","4.65318","0.03735"
"56.11800","4.67668","0.03752"
"56.40000","4.70017","0.03743"
"56.68200","4.72361","0.03730"
"56.96400","4.74717","0.03651"
"57.24600","4.77067","0.03642"
"57.52800","4.79422","0.03667"
"57.81000","4.81772","0.03671"
"58.09200","4.84122","0.03654"
"58.37400","4.86472","0.03724"
"58.65600","4.88827","0.03727"
"58.93800","4.91171","0.03753"
"59.22000","4.93521","0.03752"
"59.50200","4.95870","0.03766"
"59.78400","4.98220","0.03805"
"60.06600","5.00564","0.03860"
"60.34800","5.02926","0.03892"
"60.63000","5.05263","0.03876"
"60.91200","5.07625","0.03915"
"61.19400","5.09963","0.03904"
"61.47600","5.12325","0.03930"
"61.75800","5.14662","0.03959"
"62.04000","5.17024","0.03972"
"62.32200","5.19368","0.03985"
"62.60400","5.21718","0.03988"
"62.88600","5.24067","0.03961"
"63.16800","5.26423","0.03995"
"63.45000","5.28773","0.04053"
"63.73200","5.31122","0.04066"
"64.01400","5.33472","0.04076"
"64.29600","5.35816","0.04102"
"64.57800","5.38172","0.04112"
"64.86000","5.40515","0.04104"
"65.14200","5.42871","0.04105"
"65.42400","5.45221","0.04101"
"65.70600","5.47570","0.04167"
"65.98800","5.49920","0.04172"
"66.27000","5.52270","0.04169"
"66.55200","5.54614","0.04198"
"66.83400","5.56969","0.04182"
"67.11600","5.59313","0.04220"
"67.39800","5.61669","0.04251"
"67.68000","5.64019","0.04265"
"67.96200","5.66374","0.04271"
"68.24400","5.68718","0.04300"
"68.52600","5.71074","0.04311"
"68.80800","5.73417","0.04350"
"69.09000","5.75767","0.04351"
"69.37200","5.78117","0.04400"
"69.65400","5.80467","0.04387"
"69.93600","5.82816","0.04436"
"70.21800","5.85166","0.04471"
"70.50000","5.87516","0.04479"
"70.78200","5.89866","0.04536"
"71.06400","5.92221","0.04542"
"71.34600","5.94565","0.04594"
"71.62800","5.96915","0.04615"
"71.91000","5.99265","0.04650"
"72.19200","6.01620","0.04699"
"72.47400","6.03964","0.04695"
"72.75600","6.06320","0.04720"
"73.03800","6.08669","0.04739"
"73.32000","6.11025","0.04787"
"73.60200","6.13369","0.04794"
"73.88400","6.15725","0.04881"
"74.16600","6.18068","0.04892"
"74.44800","6.20418","0.04977"
"74.73000","6.22768","0.05013"
"75.01200","6.25117","0.05060"
"75.29400","6.27467","0.05114"
"75.57600","6.29823","0.05115"
"75.85800","6.32179","0.05186"
"76.14000","6.34516","0.05260"
"76.42200","6.36872","0.05290"
"76.70400","6.39216","0.05322"
"76.98600","6.41572","0.05421"
"77.26800","6.43915","0.05417"
"77.55000","6.46271","0.05502"
"77.83200","6.48615","0.05547"
"78.11400","6.50971","0.05603"
"78.39600","6.53314","0.05614"
"78.67800","6.55670","0.05768"
"78.96000","6.58014","0.05792"
"79.24200","6.60369","0.05842"
"79.52400","6.62713","0.05849"
"79.80600","6.65069","0.05933"
"80.08800","6.67419","0.06034"
"80.37000","6.69774","0.06051"
"80.65200","6.72118","0.06170"
"80.93400","6.74468","0.06104"
"81.21600","6.76818","0.06162"
"81.49800","6.79167","0.06238"
"81.78000","6.81523","0.06302"
"82.06200","6.83867","0.06322"
"82.34400","6.86222","0.06460"
"82.62600","6.88566","0.06511"
"82.90800","6.90922","0.06611"
"83.19000","6.93272","0.06655"
"83.47200","6.95627","0.06706"
"83.75400","6.97965","0.06778"
"84.03600","7.00315","0.06819"
"84.31800","7.02665","0.06912"
"84.60000","7.05020","0.06995"
"84.88200","7.07364","0.06974"
"85.16400","7.09720","0.07082"
"85.44600","7.12063","0.07130"
"85.72800","7.14419","0.07192"
"86.01000","7.16763","0.07269"
"86.29200","7.19119","0.07324"
"86.57400","7.21462","0.07390"
"86.85600","7.23812","0.07481"
"87.13800","7.26168","0.07549"
"87.42000","7.28518","0.07608"
"87.70200","7.30873","0.07668"
"87.98400","7.33223","0.07758"
"88.26600","7.35573","0.07800"
"88.54800","7.37922","0.07869"
"88.83000","7.40266","0.07973"
"89.11200","7.42610","0.07987"
"89.39400","7.44966","0.08023"
"89.67600","7.47315","0.08172"
"89.95800","7.49665","0.06970"
"90.24000","7.52015","0.06991"
"90.52200","7.54377","0.07007"
"90.80400","7.56720","0.07033"
"91.08600","7.59070","0.07141"
"91.36800","7.61420","0.07181"
"91.65000","7.63769","0.07270"
"91.93200","7.66113","0.07333"
"92.21400","7.68469","0.07386"
"92.49600","7.70825","0.07532"
"92.77800","7.73174","0.07571"
"93.06000","7.75524","0.07566"
"93.34200","7.77862","0.07715"
"93.62400","7.80224","0.07758"
"93.90600","7.82567","0.07872"
"94.18800","7.84923","0.07947"
"94.47000","7.87261","0.08039"
"94.75200","7.89616","0.08090"
"95.03400","7.91966","0.08123"
"95.31600","7.94322","0.08176"
"95.59800","7.96666","0.07952"
"95.88000","7.99027","0.07959"
"96.16200","8.01365","0.07926"
"96.44400","8.03721","0.08060"
"96.72600","8.06065","0.08163"
"97.00800","8.08420","0.08186"
"97.29000","8.10764","0.06340"
"97.57200","8.13120","0.06299"
"97.85400","8.15469","0.06317"
"98.13600","8.17819","0.06404"
"98.41800","8.20163","0.06435"
"98.70000","8.22525","0.06516"
"98.98200","8.24874","0.06612"
"99.26400","8.27224","0.06588"
"99.54600","8.29574","0.06681"
"99.82800","8.31917","0.06728"
"100.11000","8.34273","0.03480"
"100.39200","8.36617","0.03735"
"100.67400","8.38973","0.03704"
"100.95600","8.41317","0.03845"
"101.23800","8.43672","0.03684"
"101.52000","8.46016","0.03839"
"101.80200","8.48372","0.03803"
"102.08400","8.50709","0.03879"
"102.36600","8.53071","0.03903"
"102.64800","8.55409","0.03836"
"102.93000","8.57771","0.03957"
"103.21200","8.60114","0.03881"
"103.49400","8.62470","0.04001"
"103.77600","8.64820","0.03953"
"104.05800","8.67169","0.03993"
"104.34000","8.69513","0.03990"
"104.62200","8.71869","0.04031"
"104.90400","8.74219","0.04045"
"105.18600","8.76568","0.04055"
"105.46800","8.78918","0.04102"
"105.75000","8.81268","0.04089"
"106.03200","8.83617","0.04138"
"106.31400","8.85967","0.04139"
"106.59600","8.88323","0.04174"
"106.87800","8.90667","0.04184"
"107.16000","8.93022","0.04157"
"107.44200","8.95366","0.04257"
"107.72400","8.97722","0.04197"
"108.00600","9.00066","0.04272"
"108.28800","9.02421","0.04268"
"108.57000","9.04765","0.04298"
"108.85200","9.07121","0.04306"
"109.13400","9.09465","0.04279"
"109.41600","9.11820","0.04387"
"109.69800","9.14170","0.04327"
"109.98000","9.16520","0.04391"
"110.26200","9.18869","0.04384"
"110.54400","9.21213","0.04401"
"110.82600","9.23569","0.04420"
"111.10800","9.25919","0.04405"
"111.39000","9.28274","0.04462"
"111.67200","9.30618","0.04401"
"111.95400","9.32974","0.04456"
"112.23600","9.35318","0.04469"
"112.51800","9.37673","0.04486"
"112.80000","9.40017","0.04563"
"113.08200","9.42373","0.04516"
"113.36400","9.44716","0.04616"
"113.64600","9.47072","0.04603"
"113.92800","9.49416","0.04645"
"114.21000","9.51772","0.04686"
"114.49200","9.54115","0.04660"
"114.77400","9.56471","0.04781"
"115.05600","9.58815","0.04746"
"115.33800","9.61171","0.04789"
"115.62000","9.63520","0.04830"
"115.90200","9.65870","0.04754"
"116.18400","9.68220","0.04013"
"116.46600","9.70569","0.04007"
"116.74800","9.72919","0.04144"
"117.03000","9.75269","0.04132"
"117.31200","9.77625","0.04140"
"117.59400","9.79962","0.04173"
"117.87600","9.82318","0.04159"
"118.15800","9.84668","0.04222"
"118.44000","9.87018","0.04262"
"118.72200","9.89361","0.04193"
"119.00400","9.91717","0.04175"
"119.28600","9.94061","0.02539"
"119.56800","9.96417","0.02618"
"119.85000","9.98760","0.02770"
"120.13200","10.01122","0.02888"
"120.41400","10.03466","0.02799"
"120.69600","10.05821","0.03029"
"120.97800","10.08165","0.02887"
"121.26000","10.10521","0.03131"
"121.54200","10.12865","0.02931"
"121.82400","10.15220","0.03171"
"122.10600","10.17570","0.03020"
"122.38800","10.19920","0.03158"
"122.67000","10.22269","0.03108"
"122.95200","10.24619","0.03198"
"123.23400","10.26975","0.03223"
"123.51600","10.29313","0.03249"
"123.79800","10.31668","0.03313"
"124.08000","10.34012","0.03278"
"124.36200","10.36368","0.03367"
"124.64400","10.38718","0.03359"
"124.92600","10.41073","0.03415"
"125.20800","10.43417","0.03329"
"125.49000","10.45767","0.03423"
"125.77200","10.48116","0.03294"
"126.05400","10.50472","0.03431"
"126.33600","10.52822","0.03476"
"126.61800","10.55172","0.03464"
"126.90000","10.57521","0.03450"
"127.18200","10.59865","0.03460"
"127.46400","10.62221","0.03515"
"127.74600","10.64571","0.03476"
"128.02800","10.66920","0.03528"
"128.31000","10.69270","0.03466"
"128.59200","10.71620","0.03551"
"128.87400","10.73970","0.03494"
"129.15600","10.76325","0.03551"
"129.43800","10.78669","0.03559"
"129.72000","10.81025","0.03595"
"130.00200","10.83362","0.03598"
"130.28400","10.85718","0.03562"
"130.56600","10.88062","0.03599"
"130.84800","10.90424","0.03552"
"131.13000","10.92767","0.03569"
"131.41200","10.95123","0.03609"
"131.69400","10.97467","0.03631"
"131.97600","10.99823","0.03642"
"132.25800","11.02166","0.03661"
"132.54000","11.04522","0.03677"
"132.82200","11.06872","0.03665"
"133.10400","11.09215","0.03681"
"133.38600","11.11565","0.03709"
"133.66800","11.13921","0.03666"
"133.95000","11.16271","0.03715"
"134.23200","11.18614","0.03698"
"134.51400","11.20970","0.03710"
"134.79600","11.23314","0.03735"
"135.07800","11.25670","0.03749"
"135.36000","11.28013","0.03808"
"135.64200","11.30369","0.03685"
"135.92400","11.32719","0.03706"
"136.20600","11.35069","0.03669"
"136.48800","11.37412","0.03681"
"136.77000","11.39768","0.03758"
"137.05200","11.42118","0.03736"
"137.33400","11.44473","0.03777"
"137.61600","11.46817","0.03770"
"137.89800","11.49173","0.03823"
"138.18000","11.51517","0.03810"
"138.46200","11.53872","0.03798"
"138.74400","11.56216","0.03864"
"139.02600","11.58572","0.03846"
"139.30800","11.60915","0.03866"
"139.59000","11.63271","0.03890"
"139.87200","11.65615","0.03885"
"140.15400","11.67971","0.03922"
"140.43600","11.70320","0.03923"
"140.71800","11.72670","0.03937"
"141.00000","11.75026","0.03916"
"141.28200","11.77369","0.03934"
"141.56400","11.79719","0.03925"
"141.84600","11.82069","0.03971"
"142.12800","11.84419","0.03985"
"142.41000","11.86762","0.04008"
"142.69200","11.89118","0.03994"
"142.97400","11.91462","0.04011"
"143.25600","11.93818","0.04034"
"143.53800","11.96167","0.04022"
"143.82000","11.98523","0.04030"
"144.10200","12.00867","0.04057"
"144.38400","12.03223","0.04018"
"144.66600","12.05572","0.04066"
"144.94800","12.07922","0.04087"
"145.23000","12.10272","0.04059"
"145.51200","12.12621","0.04113"
"145.79400","12.14971","0.04118"
"146.07600","12.17315","0.04119"
"146.35800","12.19677","0.04181"
"146.64000","12.22020","0.04136"
"146.92200","12.24370","0.04126"
"147.20400","12.26714","0.04153"
"147.48600","12.29070","0.04121"
"147.76800","12.31419","0.04123"
"148.05000","12.33775","0.04120"
"148.33200","12.36119","0.04167"
"148.61400","12.38474","0.04142"
"148.89600","12.40818","0.04170"
"149.17800","12.43174","0.04181"
"149.46000","12.45518","0.04212"
"149.74200","12.47873","0.04203"
"150.02400","12.50217","0.04251"
"150.30600","12.52573","0.04253"
"150.58800","12.54917","0.04276"
"150.87000","12.57266","0.04268"
"151.15200","12.59616","0.04305"
"151.43400","12.61966","0.04329"
"151.71600","12.64321","0.04345"
"151.99800","12.66665","0.04341"
"152.28000","12.69021","0.04344"
"152.56200","12.71371","0.04351"
"152.84400","12.73726","0.04376"
"153.12600","12.76070","0.04422"
"153.40800","12.78420","0.04419"
"153.69000","12.80758","0.04408"
"153.97200","12.83119","0.04432"
"154.25400","12.85463","0.04438"
"154.53600","12.87819","0.04464"
"154.81800","12.90163","0.04471"
"155.10000","12.92524","0.04490"
"155.38200","12.94868","0.04485"
"155.66400","12.97224","0.04501"
"155.94600","12.99567","0.03201"
"156.22800","13.01923","0.01037"
"156.51000","13.04267","0.00973"
"156.79200","13.06623","0.00904"
"157.07400","13.08966","0.01266"
"157.35600","13.11322","0.00943"
"157.63800","13.13672","0.01011"
"157.92000","13.16021","0.01091"
"158.20200","13.18371","0.01038"
"158.48400","13.20715","0.01209"
"158.76600","13.23071","0.01008"
"159.04800","13.25414","0.01271"
"159.33000","13.27764","0.01036"
"159.61200","13.30114","0.01272"
"159.89400","13.32469","0.01123"
"160.17600","13.34819","0.01243"
"160.45800","13.37175","0.01235"
"160.74000","13.39519","0.01239"
"161.02200","13.41868","0.01302"
"161.30400","13.44212","0.01271"
"161.58600","13.46574","0.01372"
"161.86800","13.48918","0.01290"
"162.15000","13.51267","0.01471"
"162.43200","13.53623","0.01346"
"162.71400","13.55973","0.01459"
"162.99600","13.58323","0.01418"
"163.27800","13.60672","0.01595"
"163.56000","13.63022","0.01464"
"163.84200","13.65372","0.01575"
"164.12400","13.67722","0.01534"
"164.40600","13.70065","0.01615"
"164.68800","13.72427","0.01542"
"164.97000","13.74771","0.01640"
"165.25200","13.77120","0.01555"
"165.53400","13.79464","0.01624"
"165.81600","13.81820","0.01633"
"166.09800","13.84164","0.01661"
"166.38000","13.86519","0.01704"
"166.66200","13.88863","0.01731"
"166.94400","13.91219","0.01650"
"167.22600","13.93563","0.01728"
"167.50800","13.95918","0.01808"
"167.79000","13.98268","0.01789"
"168.07200","14.00618","0.01838"
"168.35400","14.02967","0.01624"
"168.63600","14.05311","0.01601"
"168.91800","14.07667","0.01470"
"169.20000","14.10017","0.01606"
"169.48200","14.12366","0.01606"
"169.76400","14.14716","0.01606"
"170.04600","14.17072","0.01556"
"170.32800","14.19421","0.01576"
"170.61000","14.21771","0.01590"
"170.89200","14.24115","0.01604"
"171.17400","14.26471","0.01610"
"171.45600","14.28815","0.01639"
"171.73800","14.31170","0.01694"
"172.02000","14.33514","0.01613"
"172.30200","14.35876","0.01663"
"172.58400","14.38219","0.01688"
"172.86600","14.40569","0.01686"
"173.14800","14.42919","0.01684"
"173.43000","14.45268","0.01700"
"173.71200","14.47618","0.01658"
"173.99400","14.49974","0.01760"
"174.27600","14.52318","0.01744"
"174.55800","14.54673","0.01716"
"174.84000","14.57017","0.01709"
"175.12200","14.59367","0.01713"
"175.40400","14.61722","0.01721"
"175.68600","14.64072","0.01729"
"175.96800","14.66422","0.01724"
"176.25000","14.68766","0.01722"
"176.53200","14.71115","0.01759"
"176.81400","14.73465","0.01801"
"177.09600","14.75821","0.01822"
"177.37800","14.78165","0.01861"
"177.66000","14.80520","0.01853"
"177.94200","14.82864","0.01887"
"178.22400","14.85220","0.01875"
"178.50600","14.87564","0.01805"
"178.78800","14.89925","0.01830"
"179.07000","14.92269","0.01819"
"179.35200","14.94619","0.01885"
"179.63400","14.96969","0.01814"
"179.91600","14.99324","0.01854"
"180.19800","15.01674","0.01838"
"180.48000","15.04018","0.01932"
"180.76200","15.06367","0.01872"
"181.04400","15.08717","0.01881"
"181.32600","15.11067","0.01851"
"181.60800","15.13417","0.01888"
"181.89000","15.15772","0.01883"
"182.17200","15.18116","0.01914"
"182.45400","15.20466","0.01980"
"182.73600","15.22816","0.01906"
"183.01800","15.25165","0.01950"
"183.30000","15.27515","0.01958"
"183.58200","15.29865","0.01988"
"183.86400","15.32209","0.02014"
"184.14600","15.34570","0.02059"
"184.42800","15.36908","0.02050"
"184.71000","15.39270","0.02029"
"184.99200","15.41619","0.02050"
"185.27400","15.43969","0.02091"
"185.55600","15.46319","0.02148"
"185.83800","15.48668","0.02177"
"186.12000","15.51018","0.02136"
"186.40200","15.53368","0.02120"
"186.68400","15.55718","0.02139"
"186.96600","15.58067","0.02188"
"187.24800","15.60423","0.02204"
"187.53000","15.62773","0.02269"
"187.81200","15.65123","0.02273"
"188.09400","15.67466","0.02284"
"188.37600","15.69822","0.02271"
"188.65800","15.72166","0.02313"
"188.94000","15.74516","0.02283"
"189.22200","15.76859","0.02314"
"189.50400","15.79227","0.02351"
"189.78600","15.81571","0.02339"
"190.06800","15.83920","0.02420"
"190.35000","15.86264","0.02414"
"190.63200","15.88626","0.02436"
"190.91400","15.90964","0.02336"
"191.19600","15.93319","0.02310"
"191.47800","15.95669","0.01696"
"191.76000","15.98019","0.01518"
"192.04200","16.00368","0.01518"
"192.32400","16.02718","0.01644"
"192.60600","16.05074","0.01512"
"192.88800","16.07424","0.01616"
"193.17000","16.09773","0.01623"
"193.45200","16.12117","0.01678"
"193.73400","16.14467","0.01699"
"194.01600","16.16817","0.01685"
"194.29800","16.19172","0.01736"
"194.58000","16.21516","0.01618"
"194.86200","16.23872","0.01679"
"195.14400","16.26216","0.01713"
"195.42600","16.28571","0.01775"
"195.70800","16.30915","0.01683"
"195.99000","16.33271","0.01755"
"196.27200","16.35614","0.01729"
"196.55400","16.37970","0.01731"
"196.83600","16.40320","0.01757"
"197.11800","16.42676","0.01807"
"197.40000","16.45019","0.01795"
"197.68200","16.47375","0.01793"
"197.96400","16.49719","0.01811"
"198.24600","16.52069","0.01816"
"198.52800","16.54418","0.01836"
"198.81000","16.56762","0.01863"
"199.09200","16.59118","0.01868"
"199.37400","16.61461","0.01888"
"199.65600","16.63817","0.01913"
"199.93800","16.66167","0.01882"
"200.22000","16.68517","0.01874"
"200.50200","16.70866","0.01941"
"200.78400","16.73216","0.01888"
"201.06600","16.75566","0.01914"
"201.34800","16.77921","0.02000"
"201.63000","16.80265","0.01961"
"201.91200","16.82621","0.01960"
"202.19400","16.84965","0.01945"
"202.47600","16.87326","0.01988"
"202.75800","16.89670","0.01976"
"203.04000","16.92020","0.01939"
"203.32200","16.94370","0.02030"
"203.60400","16.96719","0.02115"
"203.88600","16.99063","0.02088"
"204.16800","17.01419","0.02115"
"204.45000","17.03768","0.02034"
"204.73200","17.06118","0.02088"
"205.01400","17.08480","0.02083"
"205.29600","17.10818","0.02089"
"205.57800","17.13173","0.02071"
"205.86000","17.15517","0.02179"
"206.14200","17.17873","0.02103"
"206.42400","17.20217","0.02138"
"206.70600","17.22572","0.02174"
"206.98800","17.24916","0.02008"
"207.27000","17.27272","0.02081"
"207.55200","17.29609","0.02103"
"207.83400","17.31971","0.02031"
"208.11600","17.34315","0.01997"
"208.39800","17.36671","0.02007"
"208.68000","17.39014","0.01906"
"208.96200","17.41370","0.01938"
"209.24400","17.43720","0.01911"
"209.52600","17.46070","0.01952"
"209.80800","17.48419","0.01950"
"210.09000","17.50769","0.01862"
"210.37200","17.53119","0.01925"
"210.65400","17.55463","0.01925"
"210.93600","17.57824","0.01972"
"211.21800","17.60168","0.02011"
"211.50000","17.62524","0.01978"
"211.78200","17.64861","0.02016"
"212.06400","17.67223","0.02012"
"212.34600","17.69567","0.02083"
"212.62800","17.71923","0.01994"
"212.91000","17.74266","0.02093"
"213.19200","17.76616","0.02092"
"213.47400","17.78960","0.02073"
"213.75600","17.81322","0.02094"
"214.03800","17.83671","0.02105"
"214.32000","17.86021","0.02100"
"214.60200","17.88365","0.02235"
"214.88400","17.90720","0.02168"
"215.16600","17.93064","0.02206"
"215.44800","17.95414","0.02245"
"215.73000","17.97764","0.02207"
"216.01200","18.00113","0.02221"
"216.29400","18.02463","0.02222"
"216.57600","18.04813","0.02282"
"216.85800","18.07174","0.02252"
"217.14000","18.09524","0.02235"
"217.42200","18.11874","0.02115"
"217.70400","18.14224","0.02137"
"217.98600","18.16562","0.02048"
"218.26800","18.18911","0.01998"
"218.55000","18.21273","0.02034"
"218.83200","18.23617","0.02074"
"219.11400","18.25966","0.02023"
"219.39600","18.28316","0.02085"
"219.67800","18.30672","0.02148"
"219.96000","18.33015","0.02142"
"220.24200","18.35371","0.02146"
"220.52400","18.37715","0.02216"
"220.80600","18.40071","0.02196"
"221.08800","18.42414","0.02163"
"221.37000","18.44770","0.02187"
"221.65200","18.47120","0.02214"
"221.93400","18.49470","0.02240"
"222.21600","18.51825","0.02292"
"222.49800","18.54163","0.02284"
"222.78000","18.56519","0.02294"
"223.06200","18.58869","0.02284"
"223.34400","18.61224","0.02344"
"223.62600","18.63562","0.02288"
"223.90800","18.65918","0.02362"
"224.19000","18.68268","0.02387"
"224.47200","18.70623","0.02379"
"224.75400","18.72967","0.02336"
"225.03600","18.75323","0.02414"
"225.31800","18.77666","0.02359"
"225.60000","18.80022","0.02384"
"225.88200","18.82366","0.02488"
"226.16400","18.84722","0.02457"
"226.44600","18.87065","0.02508"
"226.72800","18.89421","0.02539"
"227.01000","18.91765","0.02580"
"227.29200","18.94120","0.02518"
"227.57400","18.96464","0.02605"
"227.85600","18.98820","0.02602"
"228.13800","19.01176","0.02615"
"228.42000","19.03519","0.02680"
"228.70200","19.05869","0.02687"
"228.98400","19.08219","0.02646"
"229.26600","19.10575","0.02684"
"229.54800","19.12918","0.02815"
"229.83000","19.15274","0.02716"
"230.11200","19.17618","0.02746"
"230.39400","19.19973","0.02709"
"230.67600","19.22317","0.02777"
"230.95800","19.24673","0.02772"
"231.24000","19.27017","0.02725"
"231.52200","19.29372","0.02768"
"231.80400","19.31716","0.02762"
"232.08600","19.34072","0.02793"
"232.36800","19.36416","0.02903"
"232.65000","19.38765","0.02867"
"232.93200","19.41115","0.02890"
"233.21400","19.43471","0.02926"
"233.49600","19.45815","0.02924"
"233.77800","19.48164","0.02938"
"234.06000","19.50520","0.03006"
"234.34200","19.52864","0.02932"
"234.62400","19.55219","0.03031"
"234.90600","19.57563","0.03002"
"235.18800","19.59919","0.03046"
"235.47000","19.62262","0.03083"
"235.75200","19.64618","0.03054"
"236.03400","19.66968","0.03116"
"236.31600","19.69318","0.03115"
"236.59800","19.71667","0.03108"
"236.88000","19.74023","0.03166"
"237.16200","19.76367","0.01836"
"237.44400","19.78723","0.01227"
"237.72600","19.81072","0.01303"
"238.00800","19.83422","0.01506"
"238.29000","19.85766","0.01329"
"238.57200","19.88121","0.01356"
"238.85400","19.90471","0.01508"
"239.13600","19.92821","0.01452"
"239.41800","19.95171","0.01354"
"239.70000","19.97520","0.01493"
"239.98200","19.99870","0.01536"
"240.26400","20.02220","0.01444"
"240.54600","20.04576","0.01541"
"240.82800","20.06913","0.01583"
"241.11000","20.09275","0.01538"
"241.39200","20.11619","0.01556"
"241.67400","20.13975","0.01632"
"241.95600","20.16318","0.01681"
"242.23800","20.18668","0.01643"
"242.52000","20.21012","0.01613"
"242.80200","20.23374","0.01649"
"243.08400","20.25717","0.01625"
"243.36600","20.28073","0.01590"
"243.64800","20.30416","0.01654"
"243.93000","20.32772","0.01700"
"244.21200","20.35116","0.01663"
"244.49400","20.37472","0.01649"
"244.77600","20.39822","0.01615"
"245.05800","20.42171","0.01624"
"245.34000","20.44515","0.01621"
"245.62200","20.46865","0.01582"
"245.90400","20.49220","0.01581"
"246.18600","20.51564","0.01659"
"246.46800","20.53926","0.01656"
"246.75000","20.56270","0.01634"
"247.03200","20.58619","0.01622"
"247.31400","20.60969","0.01646"
"247.59600","20.63319","0.01631"
"247.87800","20.65663","0.01723"
"248.16000","20.68018","0.01720"
"248.44200","20.70356","0.01722"
"248.72400","20.72718","0.01727"
"249.00600","20.75061","0.01739"
"249.28800","20.77423","0.01628"
"249.57000","20.79767","0.01627"
"249.85200","20.82123","0.01673"
"250.13400","20.84466","0.01689"
"250.41600","20.86816","0.01672"
"250.69800","20.89166","0.01716"
"250.98000","20.91522","0.01630"
"251.26200","20.93871","0.01667"
"251.54400","20.96215","0.01695"
"251.82600","20.98571","0.01681"
"252.10800","21.00920","0.01798"
"252.39000","21.03276","0.01729"
"252.67200","21.05614","0.01743"
"252.95400","21.07970","0.01752"
"253.23600","21.10313","0.01781"
"253.51800","21.12663","0.01805"
"253.80000","21.15013","0.01735"
"254.08200","21.17375","0.01782"
"254.36400","21.19718","0.01774"
"254.64600","21.22074","0.01718"
"254.92800","21.24418","0.01765"
"255.21000","21.26773","0.01813"
"255.49200","21.29117","0.01753"
"255.77400","21.31473","0.01808"
"256.05600","21.33817","0.01768"
"256.33800","21.36166","0.01750"
"256.62000","21.38522","0.01845"
"256.90200","21.40872","0.01752"
"257.18400","21.43222","0.01798"
"257.46600","21.45565","0.01815"
"257.74800","21.47921","0.01767"
"258.03000","21.50265","0.01785"
"258.31200","21.52621","0.01844"
"258.59400","21.54964","0.01831"
"258.87600","21.57320","0.01842"
"259.15800","21.59664","0.01850"
"259.44000","21.62020","0.01801"
"259.72200","21.64363","0.01840"
"260.00400","21.66719","0.01887"
"260.28600","21.69063","0.01877"
"260.56800","21.71424","0.01887"
"260.85000","21.73762","0.01921"
"261.13200","21.76124","0.01897"
"261.41400","21.78468","0.01958"
"261.69600","21.80823","0.01861"
"261.97800","21.83173","0.01968"
"262.26000","21.85523","0.02040"
"262.54200","21.87873","0.01929"
"262.82400","21.90222","0.02015"
"263.10600","21.92572","0.02007"
"263.38800","21.94916","0.02020"
"263.67000","21.97271","0.02044"
"263.95200","21.99615","0.02033"
"264.23400","22.01971","0.02074"
"264.51600","22.04315","0.02081"
"264.79800","22.06670","0.02101"
"265.08000","22.09014","0.02083"
"265.36200","22.11370","0.02169"
"265.64400","22.13707","0.02175"
"265.92600","22.16069","0.02056"
"266.20800","22.18413","0.02031"
"266.49000","22.20774","0.02039"
"266.77200","22.23118","0.02068"
"267.05400","22.25474","0.02171"
"267.33600","22.27818","0.02204"
"267.61800","22.30168","0.02188"
"267.90000","22.32517","0.02183"
"268.18200","22.34873","0.02172"
"268.46400","22.37217","0.02137"
"268.74600","22.39566","0.02097"
"269.02800","22.41916","0.02137"
"269.31000","22.44266","0.02178"
"269.59200","22.46622","0.02165"
"269.87400","22.48971","0.02150"
"270.15600","22.51327","0.02119"
"270.43800","22.53671","0.02185"
"270.72000","22.56021","0.02242"
"271.00200","22.58370","0.02238"
"271.28400","22.60726","0.02213"
"271.56600","22.63064","0.02263"
"271.84800","22.65419","0.02289"
"272.13000","22.67763","0.02368"
"272.41200","22.70119","0.02333"
"272.69400","22.72463","0.02297"
"272.97600","22.74818","0.02326"
"273.25800","22.77168","0.02311"
"273.54000","22.79518","0.02333"
"273.82200","22.81874","0.02371"
"274.10400","22.84217","0.02339"
"274.38600","22.86573","0.02342"
"274.66800","22.88917","0.02359"
"274.95000","22.91266","0.02398"
"275.23200","22.93616","0.02320"
"275.51400","22.95972","0.02434"
"275.79600","22.98316","0.02369"
"276.07800","23.00672","0.02390"
"276.36000","23.03015","0.02488"
"276.64200","23.05371","0.02487"
"276.92400","23.07715","0.02491"
"277.20600","23.10076","0.02464"
"277.48800","23.12420","0.02582"
"277.77000","23.14770","0.02557"
"278.05200","23.17120","0.02545"
"278.33400","23.19469","0.02518"
"278.61600","23.21819","0.02619"
"278.89800","23.24175","0.02563"
"279.18000","23.26518","0.02645"
"279.46200","23.28868","0.02403"
"279.74400","23.31218","0.02353"
"280.02600","23.33568","0.02395"
"280.30800","23.35917","0.02436"
"280.59000","23.38261","0.02374"
"280.87200","23.40617","0.02492"
"281.15400","23.42967","0.02396"
"281.43600","23.45322","0.02488"
"281.71800","23.47666","0.02448"
"282.00000","23.50022","0.02454"
"282.28200","23.52371","0.02492"
"282.56400","23.54715","0.02499"
"282.84600","23.57065","0.02513"
"283.12800","23.59420","0.02474"
"283.41000","23.61764","0.02351"
"283.69200","23.64120","0.02332"
"283.97400","23.66458","0.02358"
"284.25600","23.68819","0.02392"
"284.53800","23.71169","0.02417"
"284.82000","23.73525","0.02373"
"285.10200","23.75869","0.02430"
"285.38400","23.78224","0.02398"
"285.66600","23.80562","0.02450"
"285.94800","23.82918","0.02492"
"286.23000","23.85268","0.02497"
"286.51200","23.87617","0.02546"
"286.79400","23.89973","0.02558"
"287.07600","23.92317","0.02572"
"287.35800","23.94672","0.02637"
"287.64000","23.97022","0.02618"
"287.92200","23.99372","0.02652"
"288.20400","24.01715","0.02626"
"288.48600","24.04066","0.02704"
"288.76800","24.06415","0.02718"
"289.05000","24.08771","0.02694"
"289.33200","24.11115","0.02630"
"289.61400","24.13476","0.02707"
"289.89600","24.15820","0.02712"
"290.17800","24.18170","0.02759"
"290.46000","24.20513","0.02742"
"290.74200","24.22869","0.02785"
"291.02400","24.25219","0.02846"
"291.30600","24.27563","0.02835"
"291.58800","24.29918","0.02827"
"291.87000","24.32274","0.02839"
"292.15200","24.34624","0.02894"
"292.43400","24.36974","0.02816"
"292.71600","24.39323","0.02838"
"292.99800","24.41667","0.02664"
"293.28000","24.44017","0.02730"
"293.56200","24.46367","0.02779"
"293.84400","24.48722","0.02778"
"294.12600","24.51066","0.02721"
"294.40800","24.53422","0.02795"
"294.69000","24.55765","0.02846"
"294.97200","24.58121","0.02828"
"295.25400","24.60465","0.02849"
"295.53600","24.62821","0.02810"
"295.81800","24.65164","0.02939"
"296.10000","24.67520","0.02884"
"296.38200","24.69864","0.02886"
"296.66400","24.72220","0.02925"
"296.94600","24.74569","0.02910"
"297.22800","24.76919","0.03027"
"297.51000","24.79269","0.03054"
"297.79200","24.81618","0.02993"
"298.07400","24.83968","0.02976"
"298.35600","24.86318","0.03121"
"298.63800","24.88667","0.03127"
"298.92000","24.91017","0.03043"
"299.20200","24.93367","0.03050"
"299.48400","24.95717","0.03115"
"299.76600","24.98066","0.03145"
"300.04800","25.00410","0.03116"
"300.33000","25.02772","0.03116"
"300.61200","25.05110","0.03130"
"300.89400","25.07471","0.03099"
"301.17600","25.09815","0.03146"
"301.45800","25.12171","0.03138"
"301.74000","25.14521","0.03170"
"302.02200","25.16870","0.03107"
"302.30400","25.19214","0.03121"
"302.58600","25.21570","0.03163"
"302.86800","25.23919","0.03137"
"303.15000","25.26275","0.03219"
"303.43200","25.28625","0.03210"
"303.71400","25.30975","0.03153"
"303.99600","25.33319","0.03208"
"304.27800","25.35668","0.03248"
"304.56000","25.38024","0.03262"
"304.84200","25.40368","0.03196"
"305.12400","25.42723","0.03272"
"305.40600","25.45067","0.03265"
"305.68800","25.47423","0.03260"
"305.97000","25.49767","0.03320"
"306.25200","25.52116","0.03307"
"306.53400","25.54466","0.03310"
"306.81600","25.56821","0.03344"
"307.09800","25.59165","0.03356"
"307.38000","25.61521","0.03329"
"307.66200","25.63871","0.03375"
"307.94400","25.66227","0.03371"
"308.22600","25.68570","0.03410"
"308.50800","25.70914","0.03448"
"308.79000","25.73270","0.03474"
"309.07200","25.75619","0.03422"
"309.35400","25.77969","0.03495"
"309.63600","25.80319","0.03492"
"309.91800","25.82668","0.03092"
"310.20000","25.85018","0.03123"
"310.48200","25.87368","0.03167"
"310.76400","25.89718","0.03144"
"311.04600","25.92074","0.03238"
"311.32800","25.94417","0.03278"
"311.61000","25.96773","0.03242"
"311.89200","25.99117","0.03268"
"312.17400","26.01473","0.03231"
"312.45600","26.03816","0.03233"
"312.73800","26.06172","0.03232"
"313.02000","26.08510","0.03278"
"313.30200","26.10866","0.03295"
"313.58400","26.13209","0.03318"
"313.86600","26.15571","0.03368"
"314.14800","26.17915","0.03355"
"314.43000","26.20271","0.03423"
"314.71200","26.22620","0.03415"
"314.99400","26.24964","0.03427"
"315.27600","26.27313","0.03445"
"315.55800","26.29663","0.03440"
"315.84000","26.32019","0.03460"
"316.12200","26.34369","0.03418"
"316.40400","26.36724","0.03500"
"316.68600","26.39068","0.03499"
"316.96800","26.41424","0.03497"
"317.25000","26.43768","0.03538"
"317.53200","26.46123","0.03534"
"317.81400","26.48467","0.03534"
"318.09600","26.50823","0.03521"
"318.37800","26.53161","0.03583"
"318.66000","26.55522","0.03520"
"318.94200","26.57866","0.03556"
"319.22400","26.60228","0.03579"
"319.50600","26.62566","0.03573"
"319.78800","26.64921","0.03594"
"320.07000","26.67265","0.03612"
"320.35200","26.69621","0.03614"
"320.63400","26.71970","0.03642"
"320.91600","26.74320","0.03579"
"321.19800","26.76670","0.03606"
"321.48000","26.79019","0.03670"
"321.76200","26.81369","0.03677"
"322.04400","26.83719","0.03650"
"322.32600","26.86069","0.03635"
"322.60800","26.88418","0.03708"
"322.89000","26.90768","0.03679"
"323.17200","26.93118","0.03725"
"323.45400","26.95474","0.03670"
"323.73600","26.97812","0.03732"
"324.01800","27.00167","0.03669"
"324.30000","27.02517","0.03694"
"324.58200","27.04866","0.03727"
"324.86400","27.07210","0.03676"
"325.14600","27.09572","0.03674"
"325.42800","27.11916","0.03680"
"325.71000","27.14265","0.03702"
"325.99200","27.16621","0.03652"
"326.27400","27.18971","0.03699"
"326.55600","27.21321","0.03693"
"326.83800","27.23676","0.03754"
"327.12000","27.26026","0.03716"
"327.40200","27.28370","0.03770"
"327.68400","27.30720","0.03715"
"327.96600","27.33063","0.03714"
"328.24800","27.35419","0.03740"
"328.53000","27.37769","0.03735"
"328.81200","27.40119","0.03731"
"329.09400","27.42468","0.03743"
"329.37600","27.44818","0.03710"
"329.65800","27.47168","0.03723"
"329.94000","27.49518","0.03700"
"330.22200","27.51861","0.03736"
"330.50400","27.54217","0.03762"
"330.78600","27.56567","0.03705"
"331.06800","27.58922","0.03723"
"331.35000","27.61266","0.03730"
"331.63200","27.63622","0.03739"
"331.91400","27.65966","0.03754"
"332.19600","27.68315","0.03721"
"332.47800","27.70665","0.03751"
"332.76000","27.73015","0.03749"
"333.04200","27.75370","0.03755"
"333.32400","27.77720","0.03746"
"333.60600","27.80076","0.03766"
"333.88800","27.82420","0.03812"
"334.17000","27.84775","0.03779"
"334.45200","27.87119","0.03774"
"334.73400","27.89475","0.03814"
"335.01600","27.91818","0.03783"
"335.29800","27.94174","0.03754"
"335.58000","27.96518","0.03777"
"335.86200","27.98874","0.03805"
"336.14400","28.01217","0.03779"
"336.42600","28.03573","0.03765"
"336.70800","28.05911","0.03767"
"336.99000","28.08273","0.03778"
"337.27200","28.10616","0.03807"
"337.55400","28.12966","0.03765"
"337.83600","28.15316","0.03751"
"338.11800","28.17665","0.03828"
"338.40000","28.20015","0.03769"
"338.68200","28.22371","0.03760"
"338.96400","28.24721","0.03746"
"339.24600","28.27064","0.03730"
"339.52800","28.29420","0.03752"
"339.81000","28.31764","0.03728"
"340.09200","28.34125","0.03750"
"340.37400","28.36469","0.03742"
"340.65600","28.38825","0.03714"
"340.93800","28.41163","0.03682"
"341.22000","28.43519","0.03744"
"341.50200","28.45868","0.03747"
"341.78400","28.48224","0.03700"
"342.06600","28.50562","0.03714"
"342.34800","28.52917","0.03756"
"342.63000","28.55261","0.03756"
"342.91200","28.57623","0.03770"
"343.19400","28.59967","0.03794"
"343.47600","28.62322","0.03758"
"343.75800","28.64672","0.03762"
"344.04000","28.67022","0.03777"
"344.32200","28.69371","0.03752"
"344.60400","28.71715","0.03817"
"344.88600","28.74065","0.03811"
"345.16800","28.76415","0.03833"
"345.45000","28.78765","0.03812"
"345.73200","28.81114","0.03866"
"346.01400","28.83470","0.03839"
"346.29600","28.85820","0.03843"
"346.57800","28.88169","0.03838"
"346.86000","28.90519","0.03880"
"347.14200","28.92863","0.03887"
"347.42400","28.95206","0.03915"
"347.70600","28.97568","0.03877"
"347.98800","28.99912","0.03886"
"348.27000","29.02268","0.03908"
"348.55200","29.04618","0.03867"
"348.83400","29.06973","0.03869"
"349.11600","29.09317","0.03866"
"349.39800","29.11667","0.03873"
"349.68000","29.14016","0.03901"
"349.96200","29.16366","0.03920"
"350.24400","29.18716","0.03928"
"350.52600","29.21066","0.03754"
"350.80800","29.23421","0.03708"
"351.09000","29.25771","0.03808"
"351.37200","29.28127","0.03851"
"351.65400","29.30464","0.03777"
"351.93600","29.32826","0.03853"
"352.21800","29.35170","0.03908"
"352.50000","29.37526","0.03824"
"352.78200","29.39863","0.03866"
"353.06400","29.42219","0.03877"
"353.34600","29.44569","0.03910"
"353.62800","29.46919","0.03919"
"353.91000","29.49262","0.03934"
"354.19200","29.51624","0.03930"
"354.47400","29.53974","0.03948"
"354.75600","29.56318","0.03938"
"355.03800","29.58667","0.04013"
"355.32000","29.61023","0.03991"
"355.60200","29.63367","0.04051"
"355.88400","29.65717","0.04051"
"356.16600","29.68072","0.04037"
"356.44800","29.70422","0.04068"
"356.73000","29.72766","0.04089"
"357.01200","29.75115","0.04078"
"357.29400","29.77471","0.04111"
"357.57600","29.79821","0.04086"
"357.85800","29.82170","0.04066"
"358.14000","29.84514","0.04096"
"358.42200","29.86870","0.04080"
"358.70400","29.89219","0.04122"
"358.98600","29.91569","0.04114"
"359.26800","29.93919","0.04151"
"359.55000","29.96275","0.04147"
"359.83200","29.98618","0.04180"
"360.11400","30.00968","0.04190"
"360.39600","30.03312","0.04217"
"360.67800","30.05674","0.04194"
"360.96000","30.08017","0.04225"
"361.24200","30.10367","0.04246"
"361.52400","30.12717","0.04270"
"361.80600","30.15067","0.04244"
"362.08800","30.17416","0.03649"
"362.37000","30.19766","0.03840"
"362.65200","30.22116","0.03979"
"362.93400","30.24465","0.03796"
"363.21600","30.26822","0.03764"
"363.49800","30.29165","0.03951"
"363.78000","30.31521","0.03965"
"364.06200","30.33864","0.03845"
"364.34400","30.36214","0.03979"
"364.62600","30.38564","0.03995"
"364.90800","30.40920","0.03997"
"365.19000","30.43263","0.03956"
"365.47200","30.45619","0.04030"
"365.75400","30.47969","0.04096"
"366.03600","30.50324","0.04063"
"366.31800","30.52668","0.04070"
"366.60000","30.55018","0.04120"
"366.88200","30.57368","0.04128"
"367.16400","30.59718","0.04121"
"367.44600","30.62067","0.04131"
"367.72800","30.64423","0.04180"
"368.01000","30.66773","0.04181"
"368.29200","30.69122","0.04173"
"368.57400","30.71472","0.04201"
"368.85600","30.73816","0.04225"
"369.13800","30.76171","0.04224"
"369.42000","30.78515","0.04213"
"369.70200","30.80871","0.04237"
"369.98400","30.83215","0.04237"
"370.26600","30.85570","0.04263"
"370.54800","30.87914","0.04239"
"370.83000","30.90270","0.04278"
"371.11200","30.92614","0.04295"
"371.39400","30.94969","0.04335"
"371.67600","30.97313","0.04333"
"371.95800","30.99675","0.04360"
"372.24000","31.02013","0.04346"
"372.52200","31.04374","0.04385"
"372.80400","31.06718","0.04382"
"373.08600","31.09068","0.04461"
"373.36800","31.11417","0.04441"
"373.65000","31.13767","0.04461"
"373.93200","31.16117","0.04499"
"374.21400","31.18472","0.04472"
"374.49600","31.20816","0.04445"
"374.77800","31.23166","0.04461"
"375.06000","31.25516","0.04489"
"375.34200","31.27865","0.04544"
"375.62400","31.30221","0.04530"
"375.90600","31.32565","0.04556"
"376.18800","31.34921","0.04595"
"376.47000","31.37264","0.04576"
"376.75200","31.39620","0.04577"
"377.03400","31.41964","0.04641"
"377.31600","31.44313","0.04692"
"377.59800","31.46657","0.04732"
"377.88000","31.49019","0.04719"
"378.16200","31.51363","0.04711"
"378.44400","31.53724","0.04749"
"378.72600","31.56068","0.04802"
"379.00800","31.58418","0.04884"
"379.29000","31.60762","0.04896"
"379.57200","31.63117","0.04965"
"379.85400","31.65467","0.05049"
"380.13600","31.67817","0.05040"
"380.41800","31.70173","0.04986"
"380.70000","31.72516","0.04950"
"380.98200","31.74866","0.04910"
"381.26400","31.77216","0.04991"
"381.54600","31.79565","0.05024"
"381.82800","31.81915","0.05062"
"382.11000","31.84271","0.05077"
"382.39200","31.86615","0.05146"
"382.67400","31.88964","0.05210"
"382.95600","31.91314","0.05280"
"383.23800","31.93670","0.05280"
"383.52000","31.96020","0.05360"
"383.80200","31.98369","0.05396"
"384.08400","32.00719","0.05476"
"384.36600","32.03075","0.05564"
"384.64800","32.05418","0.05615"
"384.93000","32.07774","0.05678"
"385.21200","32.10118","0.05718"
"385.49400","32.12474","0.05742"
"385.77600","32.14817","0.05786"
"386.05800","32.17167","0.05924"
"386.34000","32.19523","0.05999"
"386.62200","32.21867","0.05950"
"386.90400","32.24222","0.05934"
"387.18600","32.26566","0.06117"
"387.46800","32.28922","0.06070"
"387.75000","32.31265","0.06183"
"388.03200","32.33615","0.06337"
"388.31400","32.35959","0.06384"
"388.59600","32.38321","0.06433"
"388.87800","32.40658","0.06540"
"389.16000","32.43020","0.06650"
"389.44200","32.45364","0.06695"
"389.72400","32.47720","0.06754"
"390.00600","32.50063","0.06820"
"390.28800","32.52419","0.06879"
"390.57000","32.54769","0.06973"
"390.85200","32.57124","0.07049"
"391.13400","32.59474","0.07089"
"391.41600","32.61824","0.07219"
"391.69800","32.64167","0.07264"
"391.98000","32.66523","0.07354"
"392.26200","32.68873","0.07416"
"392.54400","32.71217","0.07395"
"392.82600","32.73573","0.07308"
"393.10800","32.75916","0.07442"
"393.39000","32.78272","0.07531"
"393.67200","32.80610","0.07618"
"393.95400","32.82971","0.07696"
"394.23600","32.85315","0.07832"
"394.51800","32.87671","0.07933"
"394.80000","32.90009","0.08099"
"395.08200","32.92370","0.08139"
"395.36400","32.94708","0.08222"
"395.64600","32.97076","0.08091"
"395.92800","32.99414","0.08312"
"396.21000","33.01769","0.08306"
"396.49200","33.04119","0.08398"
"396.77400","33.06469","0.08600"
"397.05600","33.08818","0.08632"
"397.33800","33.11168","0.08698"
"397.62000","33.13518","0.08787"
"397.90200","33.15868","0.08860"
"398.18400","33.18217","0.08956"
"398.46600","33.20561","0.08983"
"398.74800","33.22917","0.08992"
"399.03000","33.25267","0.08863"
"399.31200","33.27622","0.09022"
"399.59400","33.29972","0.08997"
"399.87600","33.32322","0.09011"
"400.15800","33.34666","0.09089"
"400.44000","33.37021","0.09117"
"400.72200","33.39365","0.09164"
"401.00400","33.41721","0.09201"
"401.28600","33.44065","0.09221"
"401.56800","33.46420","0.09261"
"401.85000","33.48770","0.09310"
"402.13200","33.51120","0.09381"
"402.41400","33.53469","0.09461"
"402.69600","33.55819","0.09495"
"402.97800","33.58169","0.09549"
"403.26000","33.60518","0.09610"
"403.54200","33.62874","0.09724"
"403.82400","33.65218","0.09817"
"404.10600","33.67568","0.09918"
"404.38800","33.69917","0.10029"
"404.67000","33.72273","0.10090"
"404.95200","33.74617","0.10271"
"405.23400","33.76973","0.10252"
"405.51600","33.79316","0.10361"
"405.79800","33.81672","0.10510"
"406.08000","33.84016","0.10527"
"406.36200","33.86372","0.10726"
"406.64400","33.88715","0.10846"
"406.92600","33.91071","0.10902"
"407.20800","33.93415","0.11026"
"407.49000","33.95771","0.11046"
"407.77200","33.98120","0.11169"
"408.05400","34.00470","0.11266"
"408.33600","34.02819","0.11466"
"408.61800","34.05169","0.11572"
"408.90000","34.07519","0.11671"
"409.18200","34.09869","0.00406"
"409.46400","34.12218","0.00901"
"409.74600","34.14562","0.00352"
"410.02800","34.16924","0.00342"
"410.31000","34.19268","0.00221"
"410.59200","34.21623","0.00540"
"410.87400","34.23967","0.00537"
"411.15600","34.26323","0.00457"
"411.43800","34.28667","0.00365"
"411.72000","34.31016","0.00489"
"412.00200","34.33360","0.00545"
"412.28400","34.35722","0.00439"
"412.56600","34.38060","0.00368"
"412.84800","34.40415","0.00456"
"413.13000","34.42759","0.00492"
"413.41200","34.45121","0.00492"
"413.69400","34.47464","0.00493"
"413.97600","34.49820","0.00468"
"414.25800","34.52170","0.00356"
"414.54000","34.54519","0.00418"
"414.82200","34.56863","0.00486"
"415.10400","34.59219","0.00499"
"415.38600","34.61569","0.00404"
"415.40000","34.61688","0.00427"