File: Force_trajectories/170212_1/Specimen_RawData_3.csv
End date,"2/12/2017"
Specimen label,"10BG_67"
Maximum Load,"0.04377",N

Time,Extension,Load
(s),(mm),(N)
"0.00000","0.00000","-0.00037"
"0.21000","0.01519","0.00185"
"0.42000","0.03528","0.00423"
"0.63000","0.05267","0.00640"
"0.84000","0.07019","0.00781"
"1.05000","0.08777","0.00875"
"1.26000","0.10517","0.00975"
"1.47000","0.12275","0.01112"
"1.68000","0.14021","0.01207"
"1.89000","0.15772","0.01294"
"2.10000","0.17518","0.01375"
"2.31000","0.19264","0.01440"
"2.52000","0.21022","0.01490"
"2.73000","0.22768","0.01562"
"2.94000","0.24520","0.01675"
"3.15000","0.26272","0.01686"
"3.36000","0.28017","0.01744"
"3.57000","0.29769","0.01729"
"3.78000","0.31521","0.01809"
"3.99000","0.33267","0.01816"
"4.20000","0.35025","0.01962"
"4.41000","0.36765","0.01866"
"4.62000","0.38522","0.01910"
"4.83000","0.40268","0.01986"
"5.04000","0.42014","0.02039"
"5.25000","0.43772","0.02096"
"5.46000","0.45518","0.02039"
"5.67000","0.47270","0.02118"
"5.88000","0.49021","0.02152"
"6.09000","0.50767","0.02147"
"6.30000","0.52525","0.02203"
"6.51000","0.54271","0.02192"
"6.72000","0.56017","0.02192"
"6.93000","0.57775","0.02212"
"7.14000","0.59520","0.02207"
"7.35000","0.61272","0.02269"
"7.56000","0.63018","0.02198"
"7.77000","0.64764","0.02342"
"7.98000","0.66516","0.02330"
"8.19000","0.68268","0.02336"
"8.40000","0.70020","0.02348"
"8.61000","0.71771","0.02318"
"8.82000","0.73517","0.02293"
"9.03000","0.75269","0.02340"
"9.24000","0.77021","0.02344"
"9.45000","0.78767","0.02399"
"9.66000","0.80525","0.02371"
"9.87000","0.82264","0.02448"
"10.08000","0.84022","0.02408"
"10.29000","0.85774","0.02413"
"10.50000","0.87520","0.02406"
"10.71000","0.89272","0.02407"
"10.92000","0.91018","0.02456"
"11.13000","0.92775","0.02362"
"11.34000","0.94521","0.02503"
"11.55000","0.96267","0.02519"
"11.76000","0.98019","0.02482"
"11.97000","0.99771","0.02377"
"12.18000","1.01523","0.02496"
"12.39000","1.03274","0.02501"
"12.60000","1.05014","0.02486"
"12.81000","1.06772","0.02510"
"13.02000","1.08518","0.02503"
"13.23000","1.10270","0.02477"
"13.44000","1.12016","0.02542"
"13.65000","1.13762","0.02490"
"13.86000","1.15519","0.02540"
"14.07000","1.17265","0.02460"
"14.28000","1.19017","0.02544"
"14.49000","1.20775","0.02532"
"14.70000","1.22515","0.02500"
"14.91000","1.24273","0.02542"
"15.12000","1.26024","0.02495"
"15.33000","1.27764","0.02560"
"15.54000","1.29522","0.02545"
"15.75000","1.31268","0.02544"
"15.96000","1.33020","0.02497"
"16.17000","1.34772","0.02608"
"16.38000","1.36517","0.02563"
"16.59000","1.38269","0.02572"
"16.80000","1.40021","0.02557"
"17.01000","1.41773","0.02542"
"17.22000","1.43519","0.02500"
"17.43000","1.45265","0.02540"
"17.64000","1.47016","0.02635"
"17.85000","1.48768","0.02509"
"18.06000","1.50520","0.02621"
"18.27000","1.52272","0.02616"
"18.48000","1.54012","0.02622"
"18.69000","1.55776","0.02620"
"18.90000","1.57522","0.02607"
"19.11000","1.59267","0.02661"
"19.32000","1.61019","0.02579"
"19.53000","1.62771","0.02588"
"19.74000","1.64523","0.02562"
"19.95000","1.66269","0.02601"
"20.16000","1.68015","0.02626"
"20.37000","1.69766","0.02637"
"20.58000","1.71518","0.02571"
"20.79000","1.73264","0.02568"
"21.00000","1.75022","0.02626"
"21.21000","1.76762","0.02581"
"21.42000","1.78526","0.02589"
"21.63000","1.80265","0.02632"
"21.84000","1.82023","0.02637"
"22.05000","1.83775","0.02628"
"22.26000","1.85515","0.02630"
"22.47000","1.87273","0.02661"
"22.68000","1.89019","0.02614"
"22.89000","1.90770","0.02639"
"23.10000","1.92522","0.02638"
"23.31000","1.94268","0.02609"
"23.52000","1.96020","0.02629"
"23.73000","1.97772","0.02638"
"23.94000","1.99518","0.02690"
"24.15000","2.01269","0.02710"
"24.36000","2.03015","0.02660"
"24.57000","2.04773","0.02641"
"24.78000","2.06519","0.02587"
"24.99000","2.08265","0.02658"
"25.20000","2.10023","0.02669"
"25.41000","2.11769","0.02686"
"25.62000","2.13514","0.02724"
"25.83000","2.15266","0.02672"
"26.04000","2.17012","0.02706"
"26.25000","2.18770","0.02676"
"26.46000","2.20516","0.02659"
"26.67000","2.22268","0.02669"
"26.88000","2.24025","0.02685"
"27.09000","2.25765","0.02690"
"27.30000","2.27523","0.02625"
"27.51000","2.29275","0.02660"
"27.72000","2.31015","0.02681"
"27.93000","2.32773","0.02623"
"28.14000","2.34518","0.02692"
"28.35000","2.36276","0.02717"
"28.56000","2.38022","0.02663"
"28.77000","2.39768","0.02703"
"28.98000","2.41514","0.02659"
"29.19000","2.43272","0.02669"
"29.40000","2.45017","0.02653"
"29.61000","2.46775","0.02657"
"29.82000","2.48521","0.02626"
"30.03000","2.50273","0.02732"
"30.24000","2.52019","0.02696"
"30.45000","2.53771","0.02664"
"30.66000","2.55523","0.02666"
"30.87000","2.57262","0.02727"
"31.08000","2.59020","0.02683"
"31.29000","2.60766","0.02731"
"31.50000","2.62518","0.02690"
"31.71000","2.64276","0.02706"
"31.92000","2.66016","0.02722"
"32.13000","2.67767","0.02693"
"32.34000","2.69525","0.02683"
"32.55000","2.71265","0.02668"
"32.76000","2.73023","0.02679"
"32.97000","2.74763","0.02771"
"33.18000","2.76521","0.02693"
"33.39000","2.78272","0.02685"
"33.60000","2.80012","0.02767"
"33.81000","2.81770","0.02743"
"34.02000","2.83516","0.02720"
"34.23000","2.85274","0.02715"
"34.44000","2.87020","0.02676"
"34.65000","2.88766","0.02704"
"34.86000","2.90523","0.02699"
"35.07000","2.92269","0.02746"
"35.28000","2.94021","0.02739"
"35.49000","2.95773","0.02753"
"35.70000","2.97513","0.02642"
"35.91000","2.99277","0.02734"
"36.12000","3.01022","0.02711"
"36.33000","3.02768","0.02691"
"36.54000","3.04520","0.02679"
"36.75000","3.06272","0.02750"
"36.96000","3.08018","0.02779"
"37.17000","3.09764","0.02693"
"37.38000","3.11515","0.02751"
"37.59000","3.13267","0.02707"
"37.80000","3.15019","0.02677"
"38.01000","3.16771","0.02700"
"38.22000","3.18523","0.02670"
"38.43000","3.20269","0.02702"
"38.64000","3.22014","0.02747"
"38.85000","3.23766","0.02721"
"39.06000","3.25518","0.02707"
"39.27000","3.27270","0.02735"
"39.48000","3.29016","0.02709"
"39.69000","3.30774","0.02760"
"39.90000","3.32520","0.02693"
"40.11000","3.34271","0.02713"
"40.32000","3.36017","0.02736"
"40.53000","3.37763","0.02699"
"40.74000","3.39521","0.02698"
"40.95000","3.41273","0.02671"
"41.16000","3.43019","0.02666"
"41.37000","3.44770","0.02661"
"41.58000","3.46516","0.02691"
"41.79000","3.48274","0.02764"
"42.00000","3.50020","0.02644"
"42.21000","3.51766","0.02701"
"42.42000","3.53524","0.02690"
"42.63000","3.55269","0.02645"
"42.84000","3.57021","0.02715"
"43.05000","3.58773","0.02687"
"43.26000","3.60513","0.02755"
"43.47000","3.62271","0.02643"
"43.68000","3.64023","0.02715"
"43.89000","3.65768","0.02703"
"44.10000","3.67520","0.02666"
"44.31000","3.69266","0.02698"
"44.52000","3.71024","0.02628"
"44.73000","3.72770","0.02649"
"44.94000","3.74522","0.02663"
"45.15000","3.76273","0.02715"
"45.36000","3.78019","0.02690"
"45.57000","3.79771","0.02727"
"45.78000","3.81517","0.02680"
"45.99000","3.83269","0.02705"
"46.20000","3.85021","0.02696"
"46.41000","3.86761","0.02619"
"46.62000","3.88524","0.02668"
"46.83000","3.90270","0.02720"
"47.04000","3.92022","0.02773"
"47.25000","3.93774","0.02647"
"47.46000","3.95514","0.02699"
"47.67000","3.97272","0.02649"
"47.88000","3.99023","0.02649"
"48.09000","4.00763","0.02702"
"48.30000","4.02521","0.02715"
"48.51000","4.04267","0.02630"
"48.72000","4.06019","0.02699"
"48.93000","4.07771","0.02600"
"49.14000","4.09516","0.02672"
"49.35000","4.11274","0.02601"
"49.56000","4.13026","0.02665"
"49.77000","4.14760","0.02667"
"49.98000","4.16524","0.02685"
"50.19000","4.18270","0.02635"
"50.40000","4.20021","0.02695"
"50.61000","4.21773","0.02675"
"50.82000","4.23519","0.02700"
"51.03000","4.25271","0.02674"
"51.24000","4.27017","0.02699"
"51.45000","4.28775","0.02699"
"51.66000","4.30521","0.02685"
"51.87000","4.32266","0.02677"
"52.08000","4.34018","0.02726"
"52.29000","4.35776","0.02697"
"52.50000","4.37516","0.02631"
"52.71000","4.39274","0.02650"
"52.92000","4.41014","0.02752"
"53.13000","4.42771","0.02728"
"53.34000","4.44517","0.02774"
"53.55000","4.46269","0.02742"
"53.76000","4.48021","0.02726"
"53.97000","4.49767","0.02699"
"54.18000","4.51519","0.02704"
"54.39000","4.53270","0.02671"
"54.60000","4.55016","0.02694"
"54.81000","4.56768","0.02689"
"55.02000","4.58520","0.02659"
"55.23000","4.60266","0.02648"
"55.44000","4.62018","0.02734"
"55.65000","4.63769","0.02762"
"55.86000","4.65521","0.02719"
"56.07000","4.67261","0.02680"
"56.28000","4.69019","0.02714"
"56.49000","4.70765","0.02708"
"56.70000","4.72517","0.02753"
"56.91000","4.74269","0.02749"
"57.12000","4.76014","0.02695"
"57.33000","4.77772","0.02689"
"57.54000","4.79518","0.02746"
"57.75000","4.81264","0.02737"
"57.96000","4.83022","0.02706"
"58.17000","4.84768","0.02741"
"58.38000","4.86513","0.02749"
"58.59000","4.88277","0.02725"
"58.80000","4.90017","0.02698"
"59.01000","4.91775","0.02722"
"59.22000","4.93521","0.02730"
"59.43000","4.95267","0.02702"
"59.64000","4.97024","0.02754"
"59.85000","4.98764","0.02780"
"60.06000","5.00522","0.02760"
"60.27000","5.02268","0.02688"
"60.48000","5.04020","0.02769"
"60.69000","5.05766","0.02702"
"60.90000","5.07523","0.02728"
"61.11000","5.09269","0.02716"
"61.32000","5.11021","0.02773"
"61.53000","5.12761","0.02714"
"61.74000","5.14525","0.02716"
"61.95000","5.16271","0.02715"
"62.16000","5.18017","0.02733"
"62.37000","5.19768","0.02685"
"62.58000","5.21520","0.02679"
"62.79000","5.23266","0.02791"
"63.00000","5.25018","0.02745"
"63.21000","5.26770","0.02785"
"63.42000","5.28522","0.02772"
"63.63000","5.30267","0.02776"
"63.84000","5.32019","0.02726"
"64.05000","5.33771","0.02687"
"64.26000","5.35517","0.02731"
"64.47000","5.37275","0.02749"
"64.68000","5.39015","0.02775"
"64.89000","5.40772","0.02815"
"65.10000","5.42524","0.02744"
"65.31000","5.44264","0.02734"
"65.52000","5.46022","0.02730"
"65.73000","5.47768","0.02723"
"65.94000","5.49520","0.02727"
"66.15000","5.51271","0.02729"
"66.36000","5.53017","0.02792"
"66.57000","5.54775","0.02918"
"66.78000","5.56521","0.02885"
"66.99000","5.58267","0.02782"
"67.20000","5.60019","0.02613"
"67.41000","5.61771","0.02719"
"67.62000","5.63516","0.02651"
"67.83000","5.65274","0.02663"
"68.04000","5.67020","0.02708"
"68.25000","5.68772","0.02717"
"68.46000","5.70518","0.02739"
"68.67000","5.72270","0.02675"
"68.88000","5.74015","0.02739"
"69.09000","5.75767","0.02746"
"69.30000","5.77519","0.02728"
"69.51000","5.79271","0.02773"
"69.72000","5.81023","0.02725"
"69.93000","5.82775","0.02736"
"70.14000","5.84508","0.02736"
"70.35000","5.86278","0.02691"
"70.56000","5.88018","0.02735"
"70.77000","5.89770","0.02765"
"70.98000","5.91522","0.02706"
"71.19000","5.93268","0.02739"
"71.40000","5.95019","0.02722"
"71.61000","5.96771","0.02760"
"71.82000","5.98517","0.02698"
"72.03000","6.00269","0.02730"
"72.24000","6.02021","0.02756"
"72.45000","6.03767","0.02776"
"72.66000","6.05525","0.02722"
"72.87000","6.07264","0.02753"
"73.08000","6.09022","0.02745"
"73.29000","6.10762","0.02780"
"73.50000","6.12520","0.02753"
"73.71000","6.14272","0.02766"
"73.92000","6.16017","0.02758"
"74.13000","6.17769","0.02798"
"74.34000","6.19515","0.02770"
"74.55000","6.21273","0.02724"
"74.76000","6.23025","0.02769"
"74.97000","6.24765","0.02762"
"75.18000","6.26523","0.02805"
"75.39000","6.28268","0.02815"
"75.60000","6.30014","0.02787"
"75.81000","6.31772","0.02742"
"76.02000","6.33518","0.02786"
"76.23000","6.35276","0.02815"
"76.44000","6.37016","0.02771"
"76.65000","6.38767","0.02711"
"76.86000","6.40519","0.02732"
"77.07000","6.42265","0.02756"
"77.28000","6.44023","0.02808"
"77.49000","6.45775","0.02756"
"77.70000","6.47515","0.02827"
"77.91000","6.49266","0.02739"
"78.12000","6.51018","0.02755"
"78.33000","6.52770","0.02756"
"78.54000","6.54522","0.02774"
"78.75000","6.56262","0.02820"
"78.96000","6.58020","0.02750"
"79.17000","6.59771","0.02774"
"79.38000","6.61517","0.02810"
"79.59000","6.63269","0.02806"
"79.80000","6.65021","0.02782"
"80.01000","6.66767","0.02776"
"80.22000","6.68519","0.02741"
"80.43000","6.70265","0.02790"
"80.64000","6.72016","0.02735"
"80.85000","6.73768","0.02782"
"81.06000","6.75520","0.02697"
"81.27000","6.77278","0.02779"
"81.48000","6.79018","0.02753"
"81.69000","6.80770","0.02795"
"81.90000","6.82516","0.02753"
"82.11000","6.84273","0.02776"
"82.32000","6.86025","0.02778"
"82.53000","6.87765","0.02791"
"82.74000","6.89523","0.02704"
"82.95000","6.91269","0.02817"
"83.16000","6.93020","0.02751"
"83.37000","6.94772","0.02814"
"83.58000","6.96512","0.02791"
"83.79000","6.98270","0.02813"
"84.00000","7.00022","0.02824"
"84.21000","7.01768","0.02813"
"84.42000","7.03525","0.02759"
"84.63000","7.05265","0.02741"
"84.84000","7.07023","0.02821"
"85.05000","7.08769","0.02815"
"85.26000","7.10521","0.02716"
"85.47000","7.12267","0.02743"
"85.68000","7.14013","0.02801"
"85.89000","7.15764","0.02848"
"86.10000","7.17522","0.02767"
"86.31000","7.19268","0.02828"
"86.52000","7.21020","0.02829"
"86.73000","7.22772","0.02839"
"86.94000","7.24518","0.02821"
"87.15000","7.26275","0.02790"
"87.36000","7.28015","0.02739"
"87.57000","7.29779","0.02820"
"87.78000","7.31519","0.02783"
"87.99000","7.33271","0.02817"
"88.20000","7.35023","0.02777"
"88.41000","7.36769","0.02761"
"88.62000","7.38526","0.02766"
"88.83000","7.40272","0.02828"
"89.04000","7.42018","0.02811"
"89.25000","7.43770","0.02835"
"89.46000","7.45522","0.02777"
"89.67000","7.47268","0.02815"
"89.88000","7.49019","0.02783"
"90.09000","7.50765","0.02797"
"90.30000","7.52523","0.02784"
"90.51000","7.54269","0.02798"
"90.72000","7.56021","0.02814"
"90.93000","7.57773","0.02827"
"91.14000","7.59518","0.02820"
"91.35000","7.61270","0.02837"
"91.56000","7.63016","0.02807"
"91.77000","7.64768","0.02826"
"91.98000","7.66526","0.02787"
"92.19000","7.68266","0.02810"
"92.40000","7.70023","0.02801"
"92.61000","7.71775","0.02850"
"92.82000","7.73509","0.02840"
"93.03000","7.75273","0.02806"
"93.24000","7.77019","0.02836"
"93.45000","7.78777","0.02834"
"93.66000","7.80517","0.02833"
"93.87000","7.82268","0.02843"
"94.08000","7.84020","0.02810"
"94.29000","7.85766","0.02788"
"94.50000","7.87518","0.02765"
"94.71000","7.89270","0.02798"
"94.92000","7.91015","0.02812"
"95.13000","7.92767","0.02798"
"95.34000","7.94519","0.02866"
"95.55000","7.96265","0.02823"
"95.76000","7.98023","0.02792"
"95.97000","7.99769","0.02808"
"96.18000","8.01521","0.02765"
"96.39000","8.03266","0.02854"
"96.60000","8.05018","0.02835"
"96.81000","8.06770","0.02833"
"97.02000","8.08522","0.02772"
"97.23000","8.10274","0.02850"
"97.44000","8.12020","0.02831"
"97.65000","8.13765","0.02827"
"97.86000","8.15517","0.02862"
"98.07000","8.17263","0.02883"
"98.28000","8.19021","0.02838"
"98.49000","8.20767","0.02880"
"98.70000","8.22513","0.02871"
"98.91000","8.24276","0.02806"
"99.12000","8.26016","0.02847"
"99.33000","8.27774","0.02813"
"99.54000","8.29520","0.02880"
"99.75000","8.31260","0.02808"
"99.96000","8.33024","0.02816"
"100.17000","8.34769","0.02863"
"100.38000","8.36521","0.02788"
"100.59000","8.38273","0.02817"
"100.80000","8.40013","0.02859"
"101.01000","8.41771","0.02810"
"101.22000","8.43523","0.02752"
"101.43000","8.45263","0.02896"
"101.64000","8.47026","0.02811"
"101.85000","8.48766","0.02870"
"102.06000","8.50524","0.02820"
"102.27000","8.52264","0.02841"
"102.48000","8.54016","0.02895"
"102.69000","8.55768","0.02812"
"102.90000","8.57513","0.02797"
"103.11000","8.59277","0.02773"
"103.32000","8.61023","0.02871"
"103.53000","8.62763","0.02843"
"103.74000","8.64515","0.02829"
"103.95000","8.66267","0.02840"
"104.16000","8.68018","0.02821"
"104.37000","8.69776","0.02800"
"104.58000","8.71510","0.02801"
"104.79000","8.73274","0.02771"
"105.00000","8.75020","0.02834"
"105.21000","8.76772","0.02814"
"105.42000","8.78518","0.02857"
"105.63000","8.80263","0.02890"
"105.84000","8.82021","0.02836"
"106.05000","8.83767","0.02792"
"106.26000","8.85519","0.02780"
"106.47000","8.87271","0.02816"
"106.68000","8.89017","0.02856"
"106.89000","8.90768","0.02792"
"107.10000","8.92514","0.02782"
"107.31000","8.94266","0.02810"
"107.52000","8.96018","0.02808"
"107.73000","8.97764","0.02863"
"107.94000","8.99522","0.02868"
"108.15000","9.01273","0.02931"
"108.36000","9.03013","0.02820"
"108.57000","9.04771","0.02791"
"108.78000","9.06517","0.02829"
"108.99000","9.08269","0.02808"
"109.20000","9.10021","0.02870"
"109.41000","9.11766","0.02799"
"109.62000","9.13524","0.02831"
"109.83000","9.15270","0.02805"
"110.04000","9.17010","0.02812"
"110.25000","9.18774","0.02836"
"110.46000","9.20514","0.02862"
"110.67000","9.22265","0.02830"
"110.88000","9.24017","0.02861"
"111.09000","9.25763","0.02796"
"111.30000","9.27521","0.02827"
"111.51000","9.29261","0.02776"
"111.72000","9.31013","0.02887"
"111.93000","9.32771","0.02841"
"112.14000","9.34516","0.02794"
"112.35000","9.36268","0.02781"
"112.56000","9.38020","0.02877"
"112.77000","9.39772","0.02780"
"112.98000","9.41524","0.02844"
"113.19000","9.43264","0.02834"
"113.40000","9.45027","0.02849"
"113.61000","9.46767","0.02797"
"113.82000","9.48519","0.02784"
"114.03000","9.50271","0.02805"
"114.24000","9.52017","0.02815"
"114.45000","9.53775","0.02865"
"114.66000","9.55520","0.02797"
"114.87000","9.57266","0.02820"
"115.08000","9.59018","0.02830"
"115.29000","9.60770","0.02843"
"115.50000","9.62516","0.02845"
"115.71000","9.64274","0.02824"
"115.92000","9.66014","0.02816"
"116.13000","9.67771","0.02836"
"116.34000","9.69517","0.02766"
"116.55000","9.71269","0.02765"
"116.76000","9.73027","0.02783"
"116.97000","9.74767","0.02782"
"117.18000","9.76525","0.02820"
"117.39000","9.78264","0.02786"
"117.60000","9.80016","0.02760"
"117.81000","9.81768","0.02868"
"118.02000","9.83520","0.02810"
"118.23000","9.85272","0.02783"
"118.44000","9.87018","0.02775"
"118.65000","9.88763","0.02773"
"118.86000","9.90521","0.02794"
"119.07000","9.92267","0.02829"
"119.28000","9.94019","0.02807"
"119.49000","9.95771","0.02836"
"119.70000","9.97517","0.02806"
"119.91000","9.99268","0.02834"
"120.12000","10.01014","0.02802"
"120.33000","10.02766","0.02805"
"120.54000","10.04524","0.02791"
"120.75000","10.06270","0.02750"
"120.96000","10.08022","0.02834"
"121.17000","10.09773","0.02805"
"121.38000","10.11519","0.02741"
"121.59000","10.13271","0.02763"
"121.80000","10.15011","0.02733"
"122.01000","10.16775","0.02816"
"122.22000","10.18521","0.02759"
"122.43000","10.20267","0.02818"
"122.64000","10.22018","0.02824"
"122.85000","10.23770","0.02802"
"123.06000","10.25522","0.02835"
"123.27000","10.27268","0.02795"
"123.48000","10.29020","0.02799"
"123.69000","10.30766","0.02800"
"123.90000","10.32517","0.02765"
"124.11000","10.34275","0.02837"
"124.32000","10.36021","0.02792"
"124.53000","10.37767","0.02829"
"124.74000","10.39519","0.02795"
"124.95000","10.41271","0.02770"
"125.16000","10.43022","0.02745"
"125.37000","10.44774","0.02852"
"125.58000","10.46520","0.02784"
"125.79000","10.48272","0.02831"
"126.00000","10.50018","0.02819"
"126.21000","10.51770","0.02802"
"126.42000","10.53522","0.02765"
"126.63000","10.55261","0.02795"
"126.84000","10.57025","0.02780"
"127.05000","10.58771","0.02812"
"127.26000","10.60517","0.02836"
"127.47000","10.62275","0.02747"
"127.68000","10.64020","0.02817"
"127.89000","10.65766","0.02847"
"128.10000","10.67518","0.02791"
"128.31000","10.69264","0.02811"
"128.52000","10.71022","0.02850"
"128.73000","10.72768","0.02799"
"128.94000","10.74520","0.02835"
"129.15000","10.76271","0.02777"
"129.36000","10.78017","0.02807"
"129.57000","10.79769","0.02793"
"129.78000","10.81515","0.02815"
"129.99000","10.83267","0.02861"
"130.20000","10.85025","0.02858"
"130.41000","10.86765","0.02799"
"130.62000","10.88528","0.02847"
"130.83000","10.90268","0.02817"
"131.04000","10.92020","0.02834"
"131.25000","10.93772","0.02810"
"131.46000","10.95518","0.02773"
"131.67000","10.97269","0.02849"
"131.88000","10.99015","0.02842"
"132.09000","11.00767","0.02821"
"132.30000","11.02525","0.02879"
"132.51000","11.04265","0.02872"
"132.72000","11.06017","0.02835"
"132.93000","11.07769","0.02852"
"133.14000","11.09514","0.02813"
"133.35000","11.11272","0.02892"
"133.56000","11.13012","0.02846"
"133.77000","11.14776","0.02933"
"133.98000","11.16522","0.02891"
"134.19000","11.18262","0.02892"
"134.40000","11.20025","0.02813"
"134.61000","11.21765","0.02844"
"134.82000","11.23523","0.02829"
"135.03000","11.25269","0.02848"
"135.24000","11.27015","0.02864"
"135.45000","11.28773","0.02853"
"135.66000","11.30519","0.02867"
"135.87000","11.32270","0.02854"
"136.08000","11.34022","0.02830"
"136.29000","11.35768","0.02927"
"136.50000","11.37526","0.02845"
"136.71000","11.39266","0.02861"
"136.92000","11.41017","0.02940"
"137.13000","11.42769","0.02899"
"137.34000","11.44515","0.02887"
"137.55000","11.46273","0.02850"
"137.76000","11.48025","0.02852"
"137.97000","11.49771","0.02876"
"138.18000","11.51517","0.02819"
"138.39000","11.53274","0.02950"
"138.60000","11.55014","0.02879"
"138.81000","11.56772","0.02908"
"139.02000","11.58512","0.02894"
"139.23000","11.60270","0.02842"
"139.44000","11.62022","0.02866"
"139.65000","11.63767","0.02862"
"139.86000","11.65519","0.02893"
"140.07000","11.67265","0.02892"
"140.28000","11.69023","0.02857"
"140.49000","11.70769","0.02920"
"140.70000","11.72515","0.02909"
"140.91000","11.74266","0.02843"
"141.12000","11.76018","0.02870"
"141.33000","11.77770","0.02853"
"141.54000","11.79516","0.02851"
"141.75000","11.81262","0.02900"
"141.96000","11.83026","0.02938"
"142.17000","11.84765","0.02929"
"142.38000","11.86523","0.02893"
"142.59000","11.88263","0.02916"
"142.80000","11.90015","0.02951"
"143.01000","11.91773","0.02877"
"143.22000","11.93519","0.02970"
"143.43000","11.95265","0.02854"
"143.64000","11.97022","0.02946"
"143.85000","11.98762","0.02896"
"144.06000","12.00520","0.02905"
"144.27000","12.02272","0.02922"
"144.48000","12.04012","0.02880"
"144.69000","12.05775","0.02898"
"144.90000","12.07521","0.02916"
"145.11000","12.09273","0.02943"
"145.32000","12.11019","0.02885"
"145.53000","12.12771","0.02882"
"145.74000","12.14517","0.02905"
"145.95000","12.16269","0.02935"
"146.16000","12.18020","0.02925"
"146.37000","12.19772","0.02922"
"146.58000","12.21518","0.02918"
"146.79000","12.23270","0.02903"
"147.00000","12.25022","0.02853"
"147.21000","12.26774","0.02967"
"147.42000","12.28525","0.02898"
"147.63000","12.30265","0.02999"
"147.84000","12.32023","0.02905"
"148.05000","12.33769","0.02926"
"148.26000","12.35521","0.02970"
"148.47000","12.37267","0.02908"
"148.68000","12.39019","0.02927"
"148.89000","12.40770","0.02973"
"149.10000","12.42522","0.02918"
"149.31000","12.44268","0.02909"
"149.52000","12.46020","0.02974"
"149.73000","12.47766","0.02955"
"149.94000","12.49518","0.02946"
"150.15000","12.51269","0.02911"
"150.36000","12.53015","0.02878"
"150.57000","12.54773","0.02989"
"150.78000","12.56513","0.02981"
"150.99000","12.58271","0.02955"
"151.20000","12.60029","0.02989"
"151.41000","12.61762","0.02877"
"151.62000","12.63520","0.02914"
"151.83000","12.65266","0.02948"
"152.04000","12.67018","0.02967"
"152.25000","12.68770","0.02939"
"152.46000","12.70516","0.02969"
"152.67000","12.72273","0.02978"
"152.88000","12.74019","0.02974"
"153.09000","12.75765","0.02981"
"153.30000","12.77523","0.02980"
"153.51000","12.79263","0.02951"
"153.72000","12.81021","0.02953"
"153.93000","12.82766","0.02953"
"154.14000","12.84518","0.02995"
"154.35000","12.86270","0.02925"
"154.56000","12.88016","0.02975"
"154.77000","12.89768","0.02930"
"154.98000","12.91520","0.02940"
"155.19000","12.93266","0.02935"
"155.40000","12.95017","0.02931"
"155.61000","12.96769","0.02969"
"155.82000","12.98521","0.02951"
"156.03000","13.00273","0.02972"
"156.24000","13.02019","0.03023"
"156.45000","13.03771","0.03006"
"156.66000","13.05522","0.02994"
"156.87000","13.07268","0.03019"
"157.08000","13.09020","0.02987"
"157.29000","13.10772","0.03001"
"157.50000","13.12524","0.02999"
"157.71000","13.14270","0.02921"
"157.92000","13.16021","0.03022"
"158.13000","13.17767","0.02945"
"158.34000","13.19519","0.02967"
"158.55000","13.21271","0.02970"
"158.76000","13.23023","0.03021"
"158.97000","13.24763","0.03017"
"159.18000","13.26520","0.02908"
"159.39000","13.28266","0.02924"
"159.60000","13.30024","0.03024"
"159.81000","13.31770","0.02972"
"160.02000","13.33516","0.03033"
"160.23000","13.35274","0.02978"
"160.44000","13.37020","0.02984"
"160.65000","13.38771","0.03011"
"160.86000","13.40523","0.02996"
"161.07000","13.42269","0.03077"
"161.28000","13.44021","0.02919"
"161.49000","13.45773","0.03009"
"161.70000","13.47513","0.03037"
"161.91000","13.49276","0.02947"
"162.12000","13.51016","0.02963"
"162.33000","13.52774","0.03055"
"162.54000","13.54520","0.02951"
"162.75000","13.56266","0.03050"
"162.96000","13.58024","0.03081"
"163.17000","13.59764","0.02998"
"163.38000","13.61521","0.02972"
"163.59000","13.63273","0.02966"
"163.80000","13.65019","0.03046"
"164.01000","13.66771","0.03074"
"164.22000","13.68517","0.03041"
"164.43000","13.70274","0.03020"
"164.64000","13.72020","0.03028"
"164.85000","13.73760","0.03080"
"165.06000","13.75524","0.03087"
"165.27000","13.77270","0.03052"
"165.48000","13.79022","0.03033"
"165.69000","13.80773","0.03043"
"165.90000","13.82519","0.03077"
"166.11000","13.84271","0.03088"
"166.32000","13.86017","0.03065"
"166.53000","13.87763","0.03067"
"166.74000","13.89521","0.03010"
"166.95000","13.91267","0.03095"
"167.16000","13.93018","0.03061"
"167.37000","13.94770","0.03094"
"167.58000","13.96516","0.03078"
"167.79000","13.98268","0.03076"
"168.00000","14.00020","0.03100"
"168.21000","14.01766","0.03061"
"168.42000","14.03524","0.03115"
"168.63000","14.05263","0.03072"
"168.84000","14.07021","0.03092"
"169.05000","14.08767","0.03109"
"169.26000","14.10519","0.03103"
"169.47000","14.12271","0.03123"
"169.68000","14.14016","0.03068"
"169.89000","14.15774","0.03090"
"170.10000","14.17526","0.03118"
"170.31000","14.19266","0.03135"
"170.52000","14.21024","0.03120"
"170.73000","14.22770","0.03096"
"170.94000","14.24522","0.03165"
"171.15000","14.26267","0.03120"
"171.36000","14.28019","0.03128"
"171.57000","14.29771","0.03144"
"171.78000","14.31517","0.03172"
"171.99000","14.33269","0.03115"
"172.20000","14.35021","0.03123"
"172.41000","14.36766","0.03137"
"172.62000","14.38518","0.03161"
"172.83000","14.40270","0.03148"
"173.04000","14.42016","0.03211"
"173.25000","14.43774","0.03154"
"173.46000","14.45514","0.03139"
"173.67000","14.47278","0.03163"
"173.88000","14.49017","0.03186"
"174.09000","14.50769","0.03157"
"174.30000","14.52521","0.03170"
"174.51000","14.54267","0.03213"
"174.72000","14.56025","0.03220"
"174.93000","14.57770","0.03205"
"175.14000","14.59522","0.03153"
"175.35000","14.61268","0.03188"
"175.56000","14.63014","0.03158"
"175.77000","14.64778","0.03138"
"175.98000","14.66518","0.03173"
"176.19000","14.68270","0.03178"
"176.40000","14.70021","0.03227"
"176.61000","14.71761","0.03211"
"176.82000","14.73525","0.03226"
"177.03000","14.75271","0.03138"
"177.24000","14.77011","0.03191"
"177.45000","14.78769","0.03233"
"177.66000","14.80514","0.03213"
"177.87000","14.82272","0.03176"
"178.08000","14.84024","0.03245"
"178.29000","14.85764","0.03182"
"178.50000","14.87522","0.03225"
"178.71000","14.89274","0.03274"
"178.92000","14.91013","0.03248"
"179.13000","14.92771","0.03171"
"179.34000","14.94517","0.03270"
"179.55000","14.96269","0.03207"
"179.76000","14.98021","0.03176"
"179.97000","14.99767","0.03206"
"180.18000","15.01518","0.03199"
"180.39000","15.03264","0.03197"
"180.60000","15.05022","0.03210"
"180.81000","15.06768","0.03199"
"181.02000","15.08520","0.03227"
"181.23000","15.10266","0.03211"
"181.44000","15.12024","0.03280"
"181.65000","15.13763","0.03182"
"181.86000","15.15521","0.03215"
"182.07000","15.17261","0.03235"
"182.28000","15.19025","0.03221"
"182.49000","15.20765","0.03163"
"182.70000","15.22517","0.03204"
"182.91000","15.24274","0.03235"
"183.12000","15.26020","0.03270"
"183.33000","15.27778","0.03204"
"183.54000","15.29518","0.03205"
"183.75000","15.31270","0.03207"
"183.96000","15.33022","0.03226"
"184.17000","15.34767","0.03244"
"184.38000","15.36519","0.03295"
"184.59000","15.38271","0.03272"
"184.80000","15.40017","0.03190"
"185.01000","15.41769","0.03254"
"185.22000","15.43515","0.03285"
"185.43000","15.45273","0.03313"
"185.64000","15.47018","0.03310"
"185.85000","15.48770","0.03365"
"186.06000","15.50522","0.03335"
"186.27000","15.52268","0.03229"
"186.48000","15.54020","0.03280"
"186.69000","15.55772","0.03330"
"186.90000","15.57511","0.03285"
"187.11000","15.59275","0.03314"
"187.32000","15.61021","0.03303"
"187.53000","15.62767","0.03258"
"187.74000","15.64525","0.03334"
"187.95000","15.66271","0.03310"
"188.16000","15.68022","0.03350"
"188.37000","15.69768","0.03267"
"188.58000","15.71514","0.03332"
"188.79000","15.73272","0.03354"
"189.00000","15.75018","0.03356"
"189.21000","15.76770","0.03315"
"189.42000","15.78521","0.03307"
"189.63000","15.80267","0.03314"
"189.84000","15.82019","0.03268"
"190.05000","15.83771","0.03299"
"190.26000","15.85517","0.03310"
"190.47000","15.87274","0.03340"
"190.68000","15.89014","0.03343"
"190.89000","15.90772","0.03300"
"191.10000","15.92518","0.03378"
"191.31000","15.94270","0.03344"
"191.52000","15.96016","0.03357"
"191.73000","15.97768","0.03340"
"191.94000","15.99520","0.03365"
"192.15000","16.01271","0.03359"
"192.36000","16.03017","0.03347"
"192.57000","16.04769","0.03402"
"192.78000","16.06515","0.03370"
"192.99000","16.08273","0.03380"
"193.20000","16.10019","0.03412"
"193.41000","16.11764","0.03392"
"193.62000","16.13522","0.03415"
"193.83000","16.15262","0.03404"
"194.04000","16.17026","0.03326"
"194.25000","16.18778","0.03339"
"194.46000","16.20518","0.03368"
"194.67000","16.22269","0.03419"
"194.88000","16.24015","0.03399"
"195.09000","16.25767","0.03411"
"195.30000","16.27519","0.03377"
"195.51000","16.29271","0.03461"
"195.72000","16.31023","0.03378"
"195.93000","16.32774","0.03417"
"196.14000","16.34514","0.03385"
"196.35000","16.36272","0.03432"
"196.56000","16.38024","0.03393"
"196.77000","16.39770","0.03407"
"196.98000","16.41522","0.03471"
"197.19000","16.43267","0.03437"
"197.40000","16.45019","0.03414"
"197.61000","16.46771","0.03455"
"197.82000","16.48517","0.03394"
"198.03000","16.50269","0.03381"
"198.24000","16.52015","0.03462"
"198.45000","16.53766","0.03453"
"198.66000","16.55518","0.03461"
"198.87000","16.57270","0.03426"
"199.08000","16.59022","0.03425"
"199.29000","16.60762","0.03466"
"199.50000","16.62526","0.03485"
"199.71000","16.64272","0.03471"
"199.92000","16.66017","0.03449"
"200.13000","16.67775","0.03476"
"200.34000","16.69521","0.03499"
"200.55000","16.71273","0.03511"
"200.76000","16.73019","0.03589"
"200.97000","16.74771","0.03521"
"201.18000","16.76516","0.03453"
"201.39000","16.78268","0.03467"
"201.60000","16.80014","0.03479"
"201.81000","16.81772","0.03528"
"202.02000","16.83512","0.03496"
"202.23000","16.85275","0.03467"
"202.44000","16.87015","0.03529"
"202.65000","16.88773","0.03444"
"202.86000","16.90525","0.03445"
"203.07000","16.92265","0.03470"
"203.28000","16.94017","0.03533"
"203.49000","16.95769","0.03549"
"203.70000","16.97520","0.03527"
"203.91000","16.99272","0.03508"
"204.12000","17.01018","0.03491"
"204.33000","17.02770","0.03512"
"204.54000","17.04516","0.03593"
"204.75000","17.06262","0.03540"
"204.96000","17.08026","0.03537"
"205.17000","17.09765","0.03506"
"205.38000","17.11523","0.03542"
"205.59000","17.13269","0.03552"
"205.80000","17.15021","0.03595"
"206.01000","17.16773","0.03510"
"206.22000","17.18513","0.03563"
"206.43000","17.20270","0.03561"
"206.64000","17.22022","0.03605"
"206.85000","17.23768","0.03574"
"207.06000","17.25520","0.03557"
"207.27000","17.27272","0.03560"
"207.48000","17.29018","0.03572"
"207.69000","17.30770","0.03604"
"207.90000","17.32515","0.03613"
"208.11000","17.34267","0.03569"
"208.32000","17.36019","0.03625"
"208.53000","17.37771","0.03622"
"208.74000","17.39523","0.03646"
"208.95000","17.41269","0.03650"
"209.16000","17.43020","0.03662"
"209.37000","17.44766","0.03650"
"209.58000","17.46518","0.03638"
"209.79000","17.48270","0.03669"
"210.00000","17.50016","0.03644"
"210.21000","17.51768","0.03651"
"210.42000","17.53525","0.03667"
"210.63000","17.55265","0.03643"
"210.84000","17.57023","0.03682"
"211.05000","17.58769","0.03705"
"211.26000","17.60527","0.03680"
"211.47000","17.62273","0.03656"
"211.68000","17.64013","0.03678"
"211.89000","17.65776","0.03716"
"212.10000","17.67516","0.03705"
"212.31000","17.69268","0.03676"
"212.52000","17.71020","0.03738"
"212.73000","17.72766","0.03719"
"212.94000","17.74523","0.03745"
"213.15000","17.76275","0.03776"
"213.36000","17.78015","0.03756"
"213.57000","17.79773","0.03753"
"213.78000","17.81519","0.03715"
"213.99000","17.83277","0.03786"
"214.20000","17.85016","0.03755"
"214.41000","17.86768","0.03691"
"214.62000","17.88520","0.03782"
"214.83000","17.90266","0.03765"
"215.04000","17.92018","0.03776"
"215.25000","17.93770","0.03753"
"215.46000","17.95516","0.03740"
"215.67000","17.97273","0.03794"
"215.88000","17.99019","0.03757"
"216.09000","18.00771","0.03856"
"216.30000","18.02523","0.03846"
"216.51000","18.04263","0.03858"
"216.72000","18.06021","0.03791"
"216.93000","18.07766","0.03785"
"217.14000","18.09518","0.03767"
"217.35000","18.11270","0.03808"
"217.56000","18.13016","0.03796"
"217.77000","18.14774","0.03865"
"217.98000","18.16520","0.03862"
"218.19000","18.18271","0.03863"
"218.40000","18.20017","0.03828"
"218.61000","18.21769","0.03856"
"218.82000","18.23521","0.03846"
"219.03000","18.25273","0.03859"
"219.24000","18.27013","0.03863"
"219.45000","18.28770","0.03863"
"219.66000","18.30522","0.03858"
"219.87000","18.32274","0.03876"
"220.08000","18.34026","0.03830"
"220.29000","18.35766","0.03877"
"220.50000","18.37518","0.03890"
"220.71000","18.39269","0.03874"
"220.92000","18.41015","0.03891"
"221.13000","18.42773","0.03862"
"221.34000","18.44513","0.03923"
"221.55000","18.46271","0.03905"
"221.76000","18.48023","0.03903"
"221.97000","18.49763","0.03907"
"222.18000","18.51521","0.03870"
"222.39000","18.53266","0.03910"
"222.60000","18.55024","0.03854"
"222.81000","18.56764","0.03931"
"223.02000","18.58516","0.03905"
"223.23000","18.60268","0.03914"
"223.44000","18.62020","0.03926"
"223.65000","18.63771","0.03931"
"223.86000","18.65523","0.03949"
"224.07000","18.67269","0.03973"
"224.28000","18.69021","0.03966"
"224.49000","18.70773","0.03951"
"224.70000","18.72519","0.03947"
"224.91000","18.74270","0.03935"
"225.12000","18.76016","0.03958"
"225.33000","18.77768","0.03980"
"225.54000","18.79514","0.04011"
"225.75000","18.81272","0.03956"
"225.96000","18.83018","0.03977"
"226.17000","18.84769","0.03994"
"226.38000","18.86521","0.04037"
"226.59000","18.88267","0.04027"
"226.80000","18.90019","0.04036"
"227.01000","18.91771","0.04006"
"227.22000","18.93517","0.04055"
"227.43000","18.95268","0.03995"
"227.64000","18.97020","0.04020"
"227.85000","18.98766","0.04090"
"228.06000","19.00530","0.04023"
"228.27000","19.02264","0.04040"
"228.48000","19.04022","0.04040"
"228.69000","19.05773","0.04012"
"228.90000","19.07513","0.04007"
"229.11000","19.09271","0.04023"
"229.32000","19.11017","0.04022"
"229.53000","19.12769","0.04026"
"229.74000","19.14521","0.03997"
"229.95000","19.16266","0.04006"
"230.16000","19.18018","0.04004"
"230.37000","19.19770","0.04028"
"230.58000","19.21510","0.04055"
"230.79000","19.23274","0.04064"
"231.00000","19.25020","0.04062"
"231.21000","19.26777","0.04076"
"231.42000","19.28517","0.04060"
"231.63000","19.30269","0.04049"
"231.84000","19.32021","0.04099"
"232.05000","19.33767","0.04065"
"232.26000","19.35525","0.04067"
"232.47000","19.37271","0.04061"
"232.68000","19.39016","0.04115"
"232.89000","19.40768","0.04051"
"233.10000","19.42520","0.04065"
"233.31000","19.44266","0.04088"
"233.52000","19.46024","0.04087"
"233.73000","19.47764","0.04119"
"233.94000","19.49528","0.04104"
"234.15000","19.51267","0.04119"
"234.36000","19.53025","0.04085"
"234.57000","19.54765","0.04141"
"234.78000","19.56517","0.04099"
"234.99000","19.58269","0.04121"
"235.20000","19.60015","0.04151"
"235.41000","19.61766","0.04127"
"235.62000","19.63518","0.04088"
"235.83000","19.65270","0.04152"
"236.04000","19.67022","0.04163"
"236.25000","19.68768","0.04139"
"236.46000","19.70514","0.04171"
"236.67000","19.72271","0.04153"
"236.88000","19.74017","0.04147"
"237.09000","19.75775","0.04180"
"237.30000","19.77521","0.04161"
"237.51000","19.79267","0.04219"
"237.72000","19.81025","0.04164"
"237.93000","19.82764","0.04182"
"238.14000","19.84516","0.04231"
"238.35000","19.86268","0.04181"
"238.56000","19.88014","0.04201"
"238.77000","19.89772","0.04214"
"238.98000","19.91524","0.04224"
"239.19000","19.93263","0.04186"
"239.40000","19.95021","0.04241"
"239.61000","19.96767","0.04217"
"239.82000","19.98519","0.04182"
"240.03000","20.00271","0.04166"
"240.24000","20.02017","0.04211"
"240.45000","20.03774","0.04213"
"240.66000","20.05514","0.04221"
"240.87000","20.07266","0.04186"
"241.08000","20.09018","0.04246"
"241.29000","20.10764","0.04235"
"241.50000","20.12516","0.04248"
"241.71000","20.14267","0.04214"
"241.92000","20.16019","0.04228"
"242.13000","20.17771","0.04227"
"242.34000","20.19511","0.04227"
"242.55000","20.21275","0.04189"
"242.76000","20.23015","0.04197"
"242.97000","20.24766","0.04190"
"243.18000","20.26518","0.04147"
"243.39000","20.28270","0.04271"
"243.60000","20.30022","0.04254"
"243.81000","20.31768","0.04233"
"244.02000","20.33520","0.04241"
"244.23000","20.35272","0.04220"
"244.44000","20.37017","0.04236"
"244.65000","20.38769","0.04254"
"244.86000","20.40521","0.04238"
"245.07000","20.42267","0.04217"
"245.28000","20.44025","0.04237"
"245.49000","20.45771","0.04265"
"245.70000","20.47522","0.04220"
"245.91000","20.49274","0.04225"
"246.12000","20.51014","0.04154"
"246.33000","20.52772","0.04179"
"246.54000","20.54518","0.04206"
"246.75000","20.56270","0.04198"
"246.96000","20.58022","0.04178"
"247.17000","20.59767","0.04167"
"247.38000","20.61519","0.04198"
"247.59000","20.63271","0.04212"
"247.80000","20.65011","0.04204"
"248.01000","20.66769","0.04207"
"248.22000","20.68514","0.04189"
"248.43000","20.70272","0.04175"
"248.64000","20.72018","0.04244"
"248.85000","20.73770","0.04185"
"249.06000","20.75522","0.04181"
"249.27000","20.77268","0.04275"
"249.48000","20.79020","0.04216"
"249.69000","20.80771","0.04194"
"249.90000","20.82517","0.04197"
"250.11000","20.84269","0.04172"
"250.32000","20.86021","0.04120"
"250.53000","20.87767","0.04155"
"250.74000","20.89525","0.04178"
"250.95000","20.91265","0.04142"
"251.16000","20.93028","0.04243"
"251.37000","20.94768","0.04169"
"251.58000","20.96520","0.04218"
"251.79000","20.98272","0.04193"
"252.00000","21.00018","0.04206"
"252.21000","21.01769","0.04135"
"252.42000","21.03521","0.04168"
"252.63000","21.05267","0.04162"
"252.84000","21.07019","0.04225"
"253.05000","21.08765","0.04191"
"253.26000","21.10523","0.04184"
"253.47000","21.12269","0.04229"
"253.68000","21.14014","0.04209"
"253.89000","21.15766","0.04222"
"254.10000","21.17512","0.04203"
"254.31000","21.19276","0.04146"
"254.52000","21.21022","0.04091"
"254.73000","21.22767","0.04099"
"254.94000","21.24519","0.04135"
"255.15000","21.26271","0.04114"
"255.36000","21.28023","0.04111"
"255.57000","21.29769","0.04124"
"255.78000","21.31515","0.04014"
"255.99000","21.33273","0.03923"
"256.20000","21.35018","0.03963"
"256.41000","21.36764","0.03997"
"256.62000","21.38528","0.03950"
"256.83000","21.40268","0.03969"
"257.04000","21.42020","0.03994"
"257.25000","21.43772","0.03968"
"257.46000","21.45518","0.03951"
"257.67000","21.47269","0.03966"
"257.88000","21.49015","0.03975"
"258.09000","21.50773","0.03997"
"258.30000","21.52525","0.04019"
"258.51000","21.54265","0.04027"
"258.72000","21.56023","0.04010"
"258.93000","21.57768","0.03986"
"259.14000","21.59520","0.04019"
"259.35000","21.61272","0.04044"
"259.56000","21.63012","0.04055"
"259.77000","21.64776","0.04047"
"259.98000","21.66521","0.04064"
"260.19000","21.68267","0.04107"
"260.40000","21.70019","0.04045"
"260.61000","21.71765","0.04051"
"260.82000","21.73523","0.04052"
"261.03000","21.75269","0.04068"
"261.24000","21.77015","0.04096"
"261.45000","21.78767","0.04142"
"261.66000","21.80518","0.04086"
"261.87000","21.82270","0.04125"
"262.08000","21.84022","0.04071"
"262.29000","21.85762","0.04129"
"262.50000","21.87526","0.04095"
"262.71000","21.89266","0.04086"
"262.92000","21.91023","0.04149"
"263.13000","21.92775","0.04113"
"263.34000","21.94515","0.04124"
"263.55000","21.96273","0.04120"
"263.76000","21.98013","0.04116"
"263.97000","21.99771","0.04118"
"264.18000","22.01522","0.04158"
"264.39000","22.03262","0.04140"
"264.60000","22.05026","0.04135"
"264.81000","22.06772","0.04195"
"265.02000","22.08518","0.04134"
"265.23000","22.10270","0.04101"
"265.44000","22.12021","0.04140"
"265.65000","22.13773","0.04153"
"265.86000","22.15519","0.04156"
"266.07000","22.17271","0.04157"
"266.28000","22.19017","0.04141"
"266.49000","22.20769","0.04148"
"266.70000","22.22520","0.04140"
"266.91000","22.24272","0.04203"
"267.12000","22.26018","0.04180"
"267.33000","22.27770","0.04146"
"267.54000","22.29522","0.04167"
"267.75000","22.31268","0.04212"
"267.96000","22.33025","0.04184"
"268.17000","22.34759","0.04143"
"268.38000","22.36523","0.04150"
"268.59000","22.38269","0.04215"
"268.80000","22.40015","0.04189"
"269.01000","22.41773","0.04173"
"269.22000","22.43513","0.04222"
"269.43000","22.45276","0.04173"
"269.64000","22.47022","0.04217"
"269.85000","22.48768","0.04232"
"270.06000","22.50520","0.04249"
"270.27000","22.52266","0.04253"
"270.48000","22.54018","0.04250"
"270.69000","22.55770","0.04238"
"270.90000","22.57515","0.04215"
"271.11000","22.59273","0.04213"
"271.32000","22.61013","0.04209"
"271.53000","22.62777","0.04178"
"271.74000","22.64517","0.04251"
"271.95000","22.66262","0.04253"
"272.16000","22.68020","0.04267"
"272.37000","22.69766","0.04202"
"272.58000","22.71518","0.04203"
"272.79000","22.73276","0.04294"
"273.00000","22.75016","0.04205"
"273.21000","22.76774","0.04240"
"273.42000","22.78519","0.04256"
"273.63000","22.80265","0.04154"
"273.84000","22.82023","0.04264"
"274.05000","22.83769","0.04217"
"274.26000","22.85521","0.04241"
"274.47000","22.87267","0.04241"
"274.68000","22.89018","0.04228"
"274.89000","22.90770","0.04267"
"275.10000","22.92516","0.04150"
"275.31000","22.94268","0.04187"
"275.52000","22.96020","0.04113"
"275.73000","22.97766","0.04117"
"275.94000","22.99517","0.04136"
"276.15000","23.01269","0.04173"
"276.36000","23.03021","0.04198"
"276.57000","23.04773","0.04163"
"276.78000","23.06513","0.04173"
"276.99000","23.08277","0.04202"
"277.20000","23.10016","0.04262"
"277.41000","23.11774","0.04214"
"277.62000","23.13520","0.04244"
"277.83000","23.15266","0.04195"
"278.04000","23.17024","0.04200"
"278.25000","23.18770","0.04172"
"278.46000","23.20515","0.04222"
"278.67000","23.22267","0.04217"
"278.88000","23.24019","0.04239"
"279.09000","23.25771","0.04211"
"279.30000","23.27523","0.04237"
"279.51000","23.29263","0.04262"
"279.72000","23.31027","0.04194"
"279.93000","23.32760","0.04293"
"280.14000","23.34524","0.04265"
"280.35000","23.36276","0.04233"
"280.56000","23.38016","0.04258"
"280.77000","23.39774","0.04324"
"280.98000","23.41514","0.04250"
"281.19000","23.43271","0.04237"
"281.40000","23.45023","0.04204"
"281.61000","23.46769","0.04269"
"281.82000","23.48521","0.04286"
"282.03000","23.50273","0.04289"
"282.24000","23.52019","0.04226"
"282.45000","23.53770","0.04285"
"282.66000","23.55516","0.04267"
"282.87000","23.57274","0.04274"
"283.08000","23.59014","0.04267"
"283.29000","23.60772","0.04338"
"283.50000","23.62518","0.04250"
"283.71000","23.64269","0.04274"
"283.92000","23.66021","0.04189"
"284.13000","23.67767","0.04208"
"284.34000","23.69513","0.04189"
"284.55000","23.71265","0.04217"
"284.76000","23.73017","0.04152"
"284.97000","23.74768","0.04174"
"285.18000","23.76526","0.04236"
"285.39000","23.78260","0.04283"
"285.60000","23.80024","0.04203"
"285.81000","23.81776","0.04233"
"286.02000","23.83522","0.04278"
"286.23000","23.85268","0.04216"
"286.44000","23.87019","0.04201"
"286.65000","23.88777","0.04275"
"286.86000","23.90517","0.04296"
"287.07000","23.92269","0.04246"
"287.28000","23.94015","0.04210"
"287.49000","23.95767","0.04262"
"287.70000","23.97518","0.04261"
"287.91000","23.99270","0.04267"
"288.12000","24.01016","0.04293"
"288.33000","24.02768","0.04233"
"288.54000","24.04514","0.04269"
"288.75000","24.06272","0.04256"
"288.96000","24.08024","0.04227"
"289.17000","24.09764","0.04266"
"289.38000","24.11521","0.04224"
"289.59000","24.13267","0.04295"
"289.80000","24.15019","0.04285"
"290.01000","24.16771","0.04291"
"290.22000","24.18516","0.04281"
"290.43000","24.20268","0.04244"
"290.64000","24.22026","0.04244"
"290.85000","24.23766","0.04302"
"291.06000","24.25524","0.04306"
"291.27000","24.27264","0.04310"
"291.48000","24.29021","0.04298"
"291.69000","24.30773","0.04247"
"291.90000","24.32519","0.04309"
"292.11000","24.34271","0.04257"
"292.32000","24.36017","0.04239"
"292.53000","24.37769","0.04316"
"292.74000","24.39520","0.04286"
"292.95000","24.41267","0.04253"
"293.16000","24.43018","0.04282"
"293.37000","24.44770","0.04274"
"293.58000","24.46522","0.04255"
"293.79000","24.48268","0.04288"
"294.00000","24.50014","0.04287"
"294.21000","24.51772","0.04265"
"294.42000","24.53517","0.04347"
"294.63000","24.55269","0.04282"
"294.84000","24.57021","0.04213"
"295.05000","24.58773","0.04088"
"295.26000","24.60519","0.04080"
"295.47000","24.62271","0.04054"
"295.68000","24.64017","0.04065"
"295.89000","24.65768","0.04121"
"296.10000","24.67514","0.04109"
"296.31000","24.69272","0.04090"
"296.52000","24.71024","0.04070"
"296.73000","24.72770","0.04037"
"296.94000","24.74521","0.04074"
"297.15000","24.76267","0.04031"
"297.36000","24.78019","0.04034"
"297.57000","24.79777","0.04090"
"297.78000","24.81517","0.04072"
"297.99000","24.83269","0.04098"
"298.20000","24.85020","0.04070"
"298.41000","24.86772","0.04110"
"298.62000","24.88518","0.04090"
"298.83000","24.90264","0.04111"
"299.04000","24.92022","0.04080"
"299.25000","24.93774","0.04119"
"299.46000","24.95513","0.04089"
"299.67000","24.97272","0.04058"
"299.88000","24.99017","0.04106"
"300.09000","25.00775","0.04099"
"300.30000","25.02515","0.04114"
"300.51000","25.04267","0.04101"
"300.72000","25.06019","0.04160"
"300.93000","25.07770","0.04095"
"301.14000","25.09516","0.04079"
"301.35000","25.11268","0.04123"
"301.56000","25.13014","0.04109"
"301.77000","25.14766","0.04184"
"301.98000","25.16517","0.04148"
"302.19000","25.18269","0.04145"
"302.40000","25.20021","0.04115"
"302.61000","25.21767","0.04140"
"302.82000","25.23525","0.04148"
"303.03000","25.25265","0.04112"
"303.24000","25.27023","0.04119"
"303.45000","25.28768","0.04113"
"303.66000","25.30520","0.04072"
"303.87000","25.32272","0.04111"
"304.08000","25.34018","0.04132"
"304.29000","25.35770","0.04128"
"304.50000","25.37522","0.04091"
"304.71000","25.39268","0.04214"
"304.92000","25.41025","0.04126"
"305.13000","25.42765","0.04093"
"305.34000","25.44517","0.04182"
"305.55000","25.46269","0.04024"
"305.76000","25.48015","0.04121"
"305.97000","25.49772","0.04178"
"306.18000","25.51524","0.04158"
"306.39000","25.53264","0.04138"
"306.60000","25.55016","0.04175"
"306.81000","25.56762","0.04174"
"307.02000","25.58520","0.04146"
"307.23000","25.60272","0.04170"
"307.44000","25.62017","0.04130"
"307.65000","25.63775","0.04136"
"307.86000","25.65527","0.04146"
"308.07000","25.67261","0.04169"
"308.28000","25.69025","0.04178"
"308.49000","25.70771","0.04234"
"308.70000","25.72516","0.04150"
"308.91000","25.74268","0.04135"
"309.12000","25.76020","0.04174"
"309.33000","25.77772","0.04115"
"309.54000","25.79518","0.04128"
"309.75000","25.81269","0.04149"
"309.96000","25.83021","0.04119"
"310.17000","25.84767","0.04190"
"310.38000","25.86519","0.04171"
"310.59000","25.88271","0.04120"
"310.80000","25.90017","0.04159"
"311.01000","25.91775","0.04136"
"311.22000","25.93508","0.04165"
"311.43000","25.95272","0.04201"
"311.64000","25.97012","0.04118"
"311.85000","25.98770","0.04209"
"312.06000","26.00522","0.04175"
"312.27000","26.02268","0.04217"
"312.48000","26.04025","0.04166"
"312.69000","26.05771","0.04169"
"312.90000","26.07517","0.04155"
"313.11000","26.09269","0.04204"
"313.32000","26.11021","0.04171"
"313.53000","26.12767","0.04177"
"313.74000","26.14519","0.04118"
"313.95000","26.16264","0.04187"
"314.16000","26.18016","0.04204"
"314.37000","26.19768","0.04161"
"314.58000","26.21526","0.04129"
"314.66400","26.22219","0.04139"