File: Force_trajectories/170212_1/Specimen_RawData_9.csv
End date,"2/12/2017"
Specimen label,"9DG_77"
Maximum Load,"0.07952",N

Time,Extension,Load
(s),(mm),(N)
"0.00000","0.00000","-0.00007"
"0.34800","0.02888","0.00095"
"0.69600","0.05818","0.00044"
"1.04400","0.08723","0.00040"
"1.39200","0.11611","0.00108"
"1.74000","0.14517","0.00059"
"2.08800","0.17417","0.00082"
"2.43600","0.20311","0.00052"
"2.78400","0.23216","0.00141"
"3.13200","0.26116","0.00076"
"3.48000","0.29016","0.00137"
"3.82800","0.31916","0.00072"
"4.17600","0.34809","0.00143"
"4.52400","0.37715","0.00139"
"4.87200","0.40615","0.00061"
"5.22000","0.43509","0.00071"
"5.56800","0.46415","0.00113"
"5.91600","0.49314","0.00133"
"6.26400","0.52208","0.00177"
"6.61200","0.55120","0.00186"
"6.96000","0.58014","0.00180"
"7.30800","0.60914","0.00198"
"7.65600","0.63813","0.00165"
"8.00400","0.66713","0.00176"
"8.35200","0.69613","0.00111"
"8.70000","0.72513","0.00141"
"9.04800","0.75413","0.00162"
"9.39600","0.78312","0.00219"
"9.74400","0.81218","0.00151"
"10.09200","0.84118","0.00198"
"10.44000","0.87012","0.00223"
"10.78800","0.89917","0.00156"
"11.13600","0.92811","0.00203"
"11.48400","0.95717","0.00135"
"11.83200","0.98623","0.00221"
"12.18000","1.01505","0.00240"
"12.52800","1.04416","0.00233"
"12.87600","1.07316","0.00183"
"13.22400","1.10210","0.00237"
"13.57200","1.13116","0.00194"
"13.92000","1.16010","0.00237"
"14.26800","1.18909","0.00239"
"14.61600","1.21821","0.00164"
"14.96400","1.24715","0.00233"
"15.31200","1.27615","0.00223"
"15.66000","1.30515","0.00250"
"16.00800","1.33414","0.00247"
"16.35600","1.36314","0.00248"
"16.70400","1.39220","0.00297"
"17.05200","1.42114","0.00248"
"17.40000","1.45014","0.00270"
"17.74800","1.47913","0.00264"
"18.09600","1.50807","0.00224"
"18.44400","1.53713","0.00328"
"18.79200","1.56613","0.00277"
"19.14000","1.59513","0.00251"
"19.48800","1.62412","0.00307"
"19.83600","1.65318","0.00292"
"20.18400","1.68212","0.00300"
"20.53200","1.71112","0.00284"
"20.88000","1.74011","0.00269"
"21.22800","1.76911","0.00337"
"21.57600","1.79823","0.00321"
"21.92400","1.82711","0.00356"
"22.27200","1.85611","0.00366"
"22.62000","1.88516","0.00337"
"22.96800","1.91410","0.00338"
"23.31600","1.94322","0.00349"
"23.66400","1.97216","0.00335"
"24.01200","2.00110","0.00352"
"24.36000","2.03021","0.00371"
"24.70800","2.05915","0.00367"
"25.05600","2.08815","0.00336"
"25.40400","2.11715","0.00400"
"25.75200","2.14609","0.00381"
"26.10000","2.17514","0.00372"
"26.44800","2.20414","0.00234"
"26.79600","2.23314","0.00319"
"27.14400","2.26214","0.00338"
"27.49200","2.29114","0.00336"
"27.84000","2.32007","0.00392"
"28.18800","2.34919","0.00308"
"28.53600","2.37813","0.00357"
"28.88400","2.40713","0.00334"
"29.23200","2.43612","0.00390"
"29.58000","2.46518","0.00391"
"29.92800","2.49412","0.00440"
"30.27600","2.52318","0.00451"
"30.62400","2.55218","0.00472"
"30.97200","2.58111","0.00432"
"31.32000","2.61017","0.00471"
"31.66800","2.63905","0.00490"
"32.01600","2.66811","0.00465"
"32.36400","2.69717","0.00471"
"32.71200","2.72610","0.00491"
"33.06000","2.75516","0.00472"
"33.40800","2.78410","0.00544"
"33.75600","2.81310","0.00533"
"34.10400","2.84216","0.00525"
"34.45200","2.87115","0.00571"
"34.80000","2.90015","0.00562"
"35.14800","2.92915","0.00614"
"35.49600","2.95821","0.00641"
"35.84400","2.98708","0.00607"
"36.19200","3.01614","0.00614"
"36.54000","3.04514","0.00697"
"36.88800","3.07408","0.00615"
"37.23600","3.10320","0.00751"
"37.58400","3.13219","0.00676"
"37.93200","3.16113","0.00695"
"38.28000","3.19013","0.00726"
"38.62800","3.21913","0.00663"
"38.97600","3.24813","0.00720"
"39.32400","3.27718","0.00679"
"39.67200","3.30612","0.00672"
"40.02000","3.33512","0.00641"
"40.36800","3.36418","0.00715"
"40.71600","3.39312","0.00674"
"41.06400","3.42217","0.00680"
"41.41200","3.45111","0.00663"
"41.76000","3.48011","0.00742"
"42.10800","3.50923","0.00708"
"42.45600","3.53817","0.00710"
"42.80400","3.56716","0.00708"
"43.15200","3.59616","0.00711"
"43.50000","3.62516","0.00749"
"43.84800","3.65416","0.00747"
"44.19600","3.68310","0.00718"
"44.54400","3.71215","0.00805"
"44.89200","3.74109","0.00737"
"45.24000","3.77015","0.00726"
"45.58800","3.79915","0.00795"
"45.93600","3.82814","0.00762"
"46.28400","3.85720","0.00803"
"46.63200","3.88602","0.00801"
"46.98000","3.91520","0.00846"
"47.32800","3.94420","0.00834"
"47.67600","3.97313","0.00848"
"48.02400","4.00219","0.00809"
"48.37200","4.03113","0.00795"
"48.72000","4.06013","0.00866"
"49.06800","4.08919","0.00894"
"49.41600","4.11818","0.00843"
"49.76400","4.14712","0.00921"
"50.11200","4.17618","0.00930"
"50.46000","4.20512","0.00906"
"50.80800","4.23412","0.00975"
"51.15600","4.26317","0.00914"
"51.50400","4.29205","0.00886"
"51.85200","4.32117","0.00976"
"52.20000","4.35017","0.01016"
"52.54800","4.37910","0.00984"
"52.89600","4.40816","0.00924"
"53.24400","4.43716","0.00993"
"53.59200","4.46610","0.01044"
"53.94000","4.49516","0.01036"
"54.28800","4.52415","0.00998"
"54.63600","4.55315","0.01061"
"54.98400","4.58215","0.01070"
"55.33200","4.61115","0.00986"
"55.68000","4.64009","0.01031"
"56.02800","4.66920","0.01059"
"56.37600","4.69808","0.01057"
"56.72400","4.72714","0.01020"
"57.07200","4.75614","0.01045"
"57.42000","4.78508","0.00990"
"57.76800","4.81419","0.01016"
"58.11600","4.84313","0.00979"
"58.46400","4.87207","0.01019"
"58.81200","4.90119","0.01071"
"59.16000","4.93013","0.01027"
"59.50800","4.95906","0.01074"
"59.85600","4.98812","0.01051"
"60.20400","5.01718","0.01104"
"60.55200","5.04612","0.01080"
"60.90000","5.07517","0.01132"
"61.24800","5.10411","0.01138"
"61.59600","5.13317","0.01160"
"61.94400","5.16217","0.01216"
"62.29200","5.19111","0.01218"
"62.64000","5.22010","0.01258"
"62.98800","5.24910","0.01242"
"63.33600","5.27810","0.01249"
"63.68400","5.30710","0.01302"
"64.03200","5.33616","0.01321"
"64.38000","5.36509","0.01317"
"64.72800","5.39415","0.01412"
"65.07600","5.42321","0.01299"
"65.42400","5.45209","0.01324"
"65.77200","5.48115","0.01359"
"66.12000","5.51014","0.01367"
"66.46800","5.53908","0.01437"
"66.81600","5.56814","0.01425"
"67.16400","5.59714","0.01446"
"67.51200","5.62614","0.01404"
"67.86000","5.65513","0.01438"
"68.20800","5.68419","0.01491"
"68.55600","5.71313","0.01473"
"68.90400","5.74219","0.01507"
"69.25200","5.77112","0.01548"
"69.60000","5.80018","0.00144"
"69.94800","5.82918","0.00220"
"70.29600","5.85812","0.00302"
"70.64400","5.88718","0.00201"
"70.99200","5.91617","0.00382"
"71.34000","5.94511","0.00276"
"71.68800","5.97417","0.00230"
"72.03600","6.00311","0.00278"
"72.38400","6.03211","0.00287"
"72.73200","6.06116","0.00328"
"73.08000","6.09016","0.00355"
"73.42800","6.11916","0.00384"
"73.77600","6.14816","0.00347"
"74.12400","6.17716","0.00387"
"74.47200","6.20609","0.00379"
"74.82000","6.23521","0.00351"
"75.16800","6.26409","0.00339"
"75.51600","6.29315","0.00418"
"75.86400","6.32215","0.00459"
"76.21200","6.35108","0.00400"
"76.56000","6.38020","0.00447"
"76.90800","6.40914","0.00427"
"77.25600","6.43814","0.00521"
"77.60400","6.46713","0.00520"
"77.95200","6.49613","0.00556"
"78.30000","6.52513","0.00540"
"78.64800","6.55413","0.00514"
"78.99600","6.58313","0.00565"
"79.34400","6.61212","0.00572"
"79.69200","6.64118","0.00573"
"80.04000","6.67006","0.00636"
"80.38800","6.69918","0.00608"
"80.73600","6.72818","0.00547"
"81.08400","6.75705","0.00510"
"81.43200","6.78617","0.00537"
"81.78000","6.81523","0.00531"
"82.12800","6.84411","0.00547"
"82.47600","6.87317","0.00563"
"82.82400","6.90210","0.00578"
"83.17200","6.93110","0.00618"
"83.52000","6.96022","0.00675"
"83.86800","6.98916","0.00668"
"84.21600","7.01810","0.00700"
"84.56400","7.04721","0.00741"
"84.91200","7.07609","0.00773"
"85.26000","7.10515","0.00771"
"85.60800","7.13415","0.00777"
"85.95600","7.16309","0.00707"
"86.30400","7.19214","0.00709"
"86.65200","7.22114","0.00757"
"87.00000","7.25008","0.00909"
"87.34800","7.27914","0.00773"
"87.69600","7.30814","0.00758"
"88.04400","7.33713","0.00796"
"88.39200","7.36613","0.00865"
"88.74000","7.39519","0.00854"
"89.08800","7.42407","0.00903"
"89.43600","7.45318","0.00856"
"89.78400","7.48218","0.00900"
"90.13200","7.51112","0.00929"
"90.48000","7.54012","0.00934"
"90.82800","7.56912","0.00963"
"91.17600","7.59817","0.01019"
"91.52400","7.62717","0.00982"
"91.87200","7.65611","0.01006"
"92.22000","7.68517","0.01000"
"92.56800","7.71417","0.00989"
"92.91600","7.74316","0.01000"
"93.26400","7.77216","0.01007"
"93.61200","7.80116","0.00927"
"93.96000","7.83010","0.01067"
"94.30800","7.85910","0.01054"
"94.65600","7.88815","0.01027"
"95.00400","7.91715","0.01048"
"95.35200","7.94615","0.01077"
"95.70000","7.97515","0.01059"
"96.04800","8.00414","0.01059"
"96.39600","8.03314","0.00941"
"96.74400","8.06214","0.00747"
"97.09200","8.09114","0.00510"
"97.44000","8.12014","0.00672"
"97.78800","8.14913","0.00815"
"98.13600","8.17813","0.00778"
"98.48400","8.20719","0.00678"
"98.83200","8.23607","0.00745"
"99.18000","8.26513","0.00798"
"99.52800","8.29418","0.00841"
"99.87600","8.32312","0.00883"
"100.22400","8.35212","0.00961"
"100.57200","8.38112","0.01060"
"100.92000","8.41012","0.01015"
"101.26800","8.43917","0.01078"
"101.61600","8.46817","0.01020"
"101.96400","8.49717","0.01099"
"102.31200","8.52617","0.01221"
"102.66000","8.55511","0.01185"
"103.00800","8.58410","0.01230"
"103.35600","8.61316","0.01292"
"103.70400","8.64210","0.01290"
"104.05200","8.67116","0.01345"
"104.40000","8.70021","0.01390"
"104.74800","8.72909","0.01416"
"105.09600","8.75815","0.01486"
"105.44400","8.78715","0.01619"
"105.79200","8.81609","0.01573"
"106.14000","8.84520","0.01603"
"106.48800","8.87414","0.01682"
"106.83600","8.90314","0.01716"
"107.18400","8.93214","0.01727"
"107.53200","8.96114","0.01773"
"107.88000","8.99013","0.01923"
"108.22800","9.01919","0.01881"
"108.57600","9.04813","0.02084"
"108.92400","9.07713","0.02060"
"109.27200","9.10618","0.02188"
"109.62000","9.13512","0.02166"
"109.96800","9.16412","0.02110"
"110.31600","9.19318","0.02177"
"110.66400","9.22212","0.02227"
"111.01200","9.25117","0.02240"
"111.36000","9.28017","0.02286"
"111.70800","9.30911","0.02416"
"112.05600","9.33811","0.02371"
"112.40400","9.36717","0.02501"
"112.75200","9.39610","0.02582"
"113.10000","9.42510","0.02641"
"113.44800","9.45410","0.02683"
"113.79600","9.48310","0.02748"
"114.14400","9.51216","0.02759"
"114.49200","9.54109","0.02786"
"114.84000","9.57015","0.02935"
"115.18800","9.59915","0.03015"
"115.53600","9.62809","0.03048"
"115.88400","9.65715","0.03151"
"116.23200","9.68614","0.03134"
"116.58000","9.71514","0.03135"
"116.92800","9.74414","0.03179"
"117.27600","9.77320","0.02332"
"117.62400","9.80213","0.02216"
"117.97200","9.83119","0.02115"
"118.32000","9.86019","0.01938"
"118.66800","9.88913","0.00998"
"119.01600","9.91819","0.00863"
"119.36400","9.94718","0.00909"
"119.71200","9.97612","0.00973"
"120.06000","10.00512","0.01064"
"120.40800","10.03412","0.01053"
"120.75600","10.06318","0.01052"
"121.10400","10.09212","0.01105"
"121.45200","10.12111","0.01142"
"121.80000","10.15011","0.01194"
"122.14800","10.17917","0.01202"
"122.49600","10.20817","0.01217"
"122.84400","10.23716","0.01324"
"123.19200","10.26616","0.01327"
"123.54000","10.29510","0.01420"
"123.88800","10.32422","0.01424"
"124.23600","10.35316","0.01468"
"124.58400","10.38209","0.01486"
"124.93200","10.41115","0.01462"
"125.28000","10.44015","0.01551"
"125.62800","10.46915","0.01550"
"125.97600","10.49815","0.01600"
"126.32400","10.52714","0.01619"
"126.67200","10.55614","0.01733"
"127.02000","10.58514","0.01687"
"127.36800","10.61414","0.01684"
"127.71600","10.64314","0.01691"
"128.06400","10.67219","0.01688"
"128.41200","10.70107","0.01763"
"128.76000","10.73019","0.01802"
"129.10800","10.75913","0.01885"
"129.45600","10.78813","0.01834"
"129.80400","10.81718","0.01863"
"130.15200","10.84612","0.01962"
"130.50000","10.87512","0.01900"
"130.84800","10.90418","0.01867"
"131.19600","10.93311","0.01936"
"131.54400","10.96211","0.01871"
"131.89200","10.99111","0.01913"
"132.24000","11.02017","0.01918"
"132.58800","11.04910","0.01926"
"132.93600","11.07822","0.01991"
"133.28400","11.10704","0.01988"
"133.63200","11.13616","0.01936"
"133.98000","11.16522","0.01802"
"134.32800","11.19410","0.01871"
"134.67600","11.22315","0.00618"
"135.02400","11.25215","0.00516"
"135.37200","11.28115","0.00511"
"135.72000","11.31015","0.00545"
"136.06800","11.33914","0.00363"
"136.41600","11.36814","0.00669"
"136.76400","11.39714","0.00560"
"137.11200","11.42614","0.00573"
"137.46000","11.45508","0.00582"
"137.80800","11.48419","0.00620"
"138.15600","11.51313","0.00641"
"138.50400","11.54213","0.00628"
"138.85200","11.57113","0.00611"
"139.20000","11.60007","0.00672"
"139.54800","11.62912","0.00674"
"139.89600","11.65818","0.00629"
"140.24400","11.68712","0.00677"
"140.59200","11.71612","0.00721"
"140.94000","11.74518","0.00704"
"141.28800","11.77405","0.00689"
"141.63600","11.80317","0.00732"
"141.98400","11.83217","0.00731"
"142.33200","11.86111","0.00733"
"142.68000","11.89022","0.00756"
"143.02800","11.91910","0.00733"
"143.37600","11.94810","0.00759"
"143.72400","11.97716","0.00721"
"144.07200","12.00604","0.00770"
"144.42000","12.03515","0.00742"
"144.76800","12.06415","0.00703"
"145.11600","12.09309","0.00725"
"145.46400","12.12215","0.00777"
"145.81200","12.15115","0.00764"
"146.16000","12.18014","0.00754"
"146.50800","12.20908","0.00839"
"146.85600","12.23814","0.00839"
"147.20400","12.26714","0.00796"
"147.55200","12.29614","0.00844"
"147.90000","12.32513","0.00890"
"148.24800","12.35413","0.00920"
"148.59600","12.38313","0.00929"
"148.94400","12.41213","0.00930"
"149.29200","12.44118","0.00913"
"149.64000","12.47012","0.00965"
"149.98800","12.49912","0.00957"
"150.33600","12.52818","0.00928"
"150.68400","12.55718","0.00973"
"151.03200","12.58612","0.01043"
"151.38000","12.61517","0.00977"
"151.72800","12.64411","0.01065"
"152.07600","12.67311","0.01110"
"152.42400","12.70223","0.01118"
"152.77200","12.73110","0.01086"
"153.12000","12.76010","0.01101"
"153.46800","12.78916","0.01079"
"153.81600","12.81816","0.01063"
"154.16400","12.84710","0.01130"
"154.51200","12.87615","0.00942"
"154.86000","12.90509","0.00902"
"155.20800","12.93415","0.00903"
"155.55600","12.96315","0.00943"
"155.90400","12.99215","0.00977"
"156.25200","13.02108","0.00992"
"156.60000","13.05014","0.00999"
"156.94800","13.07908","0.01065"
"157.29600","13.10820","0.00968"
"157.64400","13.13720","0.01111"
"157.99200","13.16607","0.01158"
"158.34000","13.19519","0.01130"
"158.68800","13.22419","0.01135"
"159.03600","13.25313","0.01166"
"159.38400","13.28219","0.01219"
"159.73200","13.31112","0.01133"
"160.08000","13.34012","0.01033"
"160.42800","13.36912","0.01049"
"160.77600","13.39812","0.00846"
"161.12400","13.42712","0.00915"
"161.47200","13.45617","0.00957"
"161.82000","13.48511","0.00954"
"162.16800","13.51417","0.01073"
"162.51600","13.54317","0.01014"
"162.86400","13.57210","0.01027"
"163.21200","13.60110","0.00985"
"163.56000","13.63016","0.01015"
"163.90800","13.65916","0.01034"
"164.25600","13.68816","0.00999"
"164.60400","13.71715","0.01017"
"164.95200","13.74609","0.01035"
"165.30000","13.77515","0.01141"
"165.64800","13.80415","0.01082"
"165.99600","13.83315","0.01135"
"166.34400","13.86220","0.01123"
"166.69200","13.89114","0.01167"
"167.04000","13.92014","0.01144"
"167.38800","13.94914","0.01258"
"167.73600","13.97808","0.01217"
"168.08400","14.00719","0.01258"
"168.43200","14.03619","0.01299"
"168.78000","14.06513","0.01331"
"169.12800","14.09413","0.01290"
"169.47600","14.12313","0.01320"
"169.82400","14.15212","0.01321"
"170.17200","14.18118","0.01385"
"170.52000","14.21012","0.01440"
"170.86800","14.23912","0.01417"
"171.21600","14.26817","0.01443"
"171.56400","14.29711","0.01503"
"171.91200","14.32617","0.01386"
"172.26000","14.35517","0.01455"
"172.60800","14.38411","0.01481"
"172.95600","14.41317","0.01589"
"173.30400","14.44216","0.01533"
"173.65200","14.47110","0.01560"
"174.00000","14.50016","0.01595"
"174.34800","14.52910","0.01618"
"174.69600","14.55809","0.01608"
"175.04400","14.58715","0.01618"
"175.39200","14.61621","0.01630"
"175.74000","14.64509","0.01679"
"176.08800","14.67415","0.01657"
"176.43600","14.70314","0.01771"
"176.78400","14.73208","0.01804"
"177.13200","14.76120","0.01843"
"177.48000","14.79008","0.01936"
"177.82800","14.81913","0.01786"
"178.17600","14.84813","0.01719"
"178.52400","14.87713","0.01819"
"178.87200","14.90613","0.01838"
"179.22000","14.93513","0.01871"
"179.56800","14.96406","0.01923"
"179.91600","14.99312","0.01909"
"180.26400","15.02218","0.01959"
"180.61200","15.05112","0.01985"
"180.96000","15.08012","0.01947"
"181.30800","15.10917","0.01961"
"181.65600","15.13811","0.01987"
"182.00400","15.16717","0.02047"
"182.35200","15.19611","0.02100"
"182.70000","15.22511","0.02178"
"183.04800","15.25416","0.02074"
"183.39600","15.28316","0.02221"
"183.74400","15.31210","0.02189"
"184.09200","15.34116","0.02262"
"184.44000","15.37016","0.02302"
"184.78800","15.39909","0.01870"
"185.13600","15.42815","0.01820"
"185.48400","15.45709","0.01609"
"185.83200","15.48609","0.01357"
"186.18000","15.51521","0.01282"
"186.52800","15.54408","0.01436"
"186.87600","15.57314","0.01493"
"187.22400","15.60220","0.01510"
"187.57200","15.63114","0.01452"
"187.92000","15.66019","0.01524"
"188.26800","15.68907","0.01580"
"188.61600","15.71813","0.01608"
"188.96400","15.74713","0.01666"
"189.31200","15.77619","0.01686"
"189.66000","15.80512","0.01702"
"190.00800","15.83412","0.01803"
"190.35600","15.86312","0.01781"
"190.70400","15.89206","0.01789"
"191.05200","15.92118","0.01919"
"191.40000","15.95011","0.01915"
"191.74800","15.97917","0.01947"
"192.09600","16.00817","0.01880"
"192.44400","16.03711","0.01977"
"192.79200","16.06616","0.01970"
"193.14000","16.09516","0.01914"
"193.48800","16.12410","0.02054"
"193.83600","16.15316","0.02048"
"194.18400","16.18216","0.02168"
"194.53200","16.21115","0.02249"
"194.88000","16.24015","0.02213"
"195.22800","16.26909","0.02310"
"195.57600","16.29815","0.02302"
"195.92400","16.32715","0.02384"
"196.27200","16.35608","0.02220"
"196.62000","16.38514","0.02475"
"196.96800","16.41414","0.02668"
"197.31600","16.44308","0.02694"
"197.66400","16.47220","0.02627"
"198.01200","16.50113","0.02662"
"198.36000","16.53013","0.02746"
"198.70800","16.55913","0.02757"
"199.05600","16.58813","0.02805"
"199.40400","16.61712","0.02841"
"199.75200","16.64612","0.02790"
"200.10000","16.67518","0.02886"
"200.44800","16.70412","0.02928"
"200.79600","16.73318","0.02997"
"201.14400","16.76217","0.02953"
"201.49200","16.79111","0.03099"
"201.84000","16.82017","0.03154"
"202.18800","16.84911","0.03167"
"202.53600","16.87817","0.03284"
"202.88400","16.90722","0.03310"
"203.23200","16.93610","0.03265"
"203.58000","16.96516","0.03186"
"203.92800","16.99416","0.03241"
"204.27600","17.02310","0.03271"
"204.62400","17.05215","0.03133"
"204.97200","17.08115","0.03007"
"205.32000","17.11009","0.03077"
"205.66800","17.13915","0.03342"
"206.01600","17.16815","0.03315"
"206.36400","17.19714","0.03314"
"206.71200","17.22614","0.03480"
"207.06000","17.25514","0.03442"
"207.40800","17.28420","0.03455"
"207.75600","17.31314","0.03534"
"208.10400","17.34213","0.03586"
"208.45200","17.37113","0.03557"
"208.80000","17.40013","0.03593"
"209.14800","17.42907","0.03672"
"209.49600","17.45812","0.03684"
"209.84400","17.48724","0.03763"
"210.19200","17.51606","0.03747"
"210.54000","17.54518","0.03845"
"210.88800","17.57412","0.03867"
"211.23600","17.60312","0.03913"
"211.58400","17.63217","0.03956"
"211.93200","17.66111","0.03997"
"212.28000","17.69011","0.04052"
"212.62800","17.71911","0.04077"
"212.97600","17.74816","0.04155"
"213.32400","17.77716","0.04173"
"213.67200","17.80616","0.04209"
"214.02000","17.83516","0.04308"
"214.36800","17.86410","0.04252"
"214.71600","17.89321","0.04357"
"215.06400","17.92209","0.04393"
"215.41200","17.95115","0.04492"
"215.76000","17.98015","0.04526"
"216.10800","18.00908","0.04612"
"216.45600","18.03814","0.04662"
"216.80400","18.06714","0.04790"
"217.15200","18.09614","0.04832"
"217.50000","18.12514","0.04973"
"217.84800","18.15413","0.04977"
"218.19600","18.18313","0.05130"
"218.54400","18.21213","0.05196"
"218.89200","18.24119","0.05308"
"219.24000","18.27013","0.05417"
"219.58800","18.29918","0.05450"
"219.93600","18.32812","0.05533"
"220.28400","18.35712","0.05716"
"220.63200","18.38618","0.05797"
"220.98000","18.41506","0.05904"
"221.32800","18.44423","0.05811"
"221.67600","18.47317","0.05945"
"222.02400","18.50211","0.06025"
"222.37200","18.53117","0.06118"
"222.72000","18.56011","0.06250"
"223.06800","18.58910","0.06373"
"223.41600","18.61816","0.06443"
"223.76400","18.64710","0.06543"
"224.11200","18.67616","0.06603"
"224.46000","18.70516","0.06768"
"224.80800","18.73409","0.06785"
"225.15600","18.76309","0.06874"
"225.50400","18.79215","0.07010"
"225.85200","18.82109","0.07184"
"226.20000","18.85015","0.07214"
"226.54800","18.87914","0.07264"
"226.89600","18.90808","0.07447"
"227.24400","18.93714","0.07445"
"227.59200","18.96620","0.07554"
"227.94000","18.99508","0.07487"
"228.28800","19.02413","0.07519"
"228.63600","19.05319","0.07621"
"228.98400","19.08213","0.07797"
"229.33200","19.11113","0.07873"
"229.68000","19.14013","0.07937"
"230.02800","19.16906","-0.00422"
"230.37600","19.19818","-0.00253"
"230.72400","19.22712","-0.00162"
"231.07200","19.25618","-0.00090"
"231.42000","19.28511","-0.00212"
"231.76800","19.31405","-0.00153"
"232.11600","19.34317","-0.00143"
"232.46400","19.37217","-0.00137"
"232.81200","19.40117","-0.00098"
"233.16000","19.43016","-0.00161"
"233.50800","19.45916","-0.00128"
"233.85600","19.48810","-0.00065"
"234.20400","19.51716","-0.00087"
"234.55200","19.54615","-0.00175"
"234.90000","19.57509","-0.00124"
"235.24800","19.60415","-0.00092"
"235.59600","19.63315","-0.00154"
"235.94400","19.66209","-0.00109"
"236.29200","19.69114","-0.00160"
"236.64000","19.72008","-0.00183"
"236.98800","19.74914","-0.00089"
"237.33600","19.77814","-0.00128"
"237.68400","19.80714","-0.00123"
"238.03200","19.83614","-0.00098"
"238.38000","19.86519","-0.00122"
"238.72800","19.89413","-0.00151"
"239.07600","19.92319","-0.00103"
"239.42400","19.95213","-0.00064"
"239.77200","19.98106","-0.00120"
"240.12000","20.01018","-0.00101"
"240.46800","20.03918","-0.00186"
"240.81600","20.06812","-0.00078"
"241.16400","20.09718","-0.00143"
"241.51200","20.12611","-0.00145"
"241.86000","20.15517","-0.00099"
"242.20800","20.18411","-0.00099"
"242.55600","20.21317","-0.00161"
"242.90400","20.24211","-0.00069"
"243.25200","20.27116","-0.00106"
"243.60000","20.30010","-0.00153"
"243.94800","20.32916","-0.00090"
"244.29600","20.35815","-0.00065"
"244.64400","20.38709","-0.00087"
"244.99200","20.41615","-0.00137"
"245.34000","20.44515","-0.00053"
"245.68800","20.47409","-0.00118"
"246.03600","20.50315","-0.00146"
"246.38400","20.53214","-0.00060"
"246.73200","20.56114","-0.00108"
"247.08000","20.59020","-0.00082"
"247.42800","20.61920","-0.00056"
"247.77600","20.64814","-0.00166"
"248.12400","20.67713","-0.00084"
"248.47200","20.70613","-0.00026"
"248.82000","20.73513","-0.00111"
"249.16800","20.76419","-0.00113"
"249.51600","20.79306","-0.00123"
"249.86400","20.82218","-0.00098"
"250.21200","20.85112","-0.00113"
"250.56000","20.88012","-0.00090"
"250.90800","20.90911","-0.00075"
"251.25600","20.93812","-0.00096"
"251.60400","20.96717","-0.00138"
"251.95200","20.99617","-0.00123"
"252.30000","21.02517","-0.00084"
"252.64800","21.05411","-0.00112"
"252.99600","21.08316","-0.00069"
"253.34400","21.11216","-0.00079"
"253.69200","21.14110","-0.00089"
"254.04000","21.17022","-0.00093"
"254.38800","21.19910","-0.00054"
"254.73600","21.22816","-0.00073"
"255.08400","21.25715","-0.00100"
"255.43200","21.28609","-0.00087"
"255.78000","21.31515","-0.00080"
"256.12800","21.34414","-0.00136"
"256.47600","21.37314","-0.00096"
"256.82400","21.40214","-0.00145"
"257.17200","21.43114","-0.00089"
"257.52000","21.46014","-0.00105"
"257.86800","21.48913","-0.00053"
"258.21600","21.51813","-0.00133"
"258.56400","21.54713","-0.00100"
"258.91200","21.57619","-0.00079"
"259.26000","21.60513","-0.00134"
"259.60800","21.63412","-0.00096"
"259.95600","21.66312","-0.00131"
"260.30400","21.69212","-0.00094"
"260.65200","21.72118","-0.00048"
"261.00000","21.75017","-0.00053"
"261.34800","21.77911","-0.00056"
"261.69600","21.80811","-0.00073"
"262.04400","21.83717","-0.00163"
"262.39200","21.86611","-0.00024"
"262.74000","21.89517","-0.00100"
"263.08800","21.92422","-0.00173"
"263.43600","21.95316","-0.00123"
"263.78400","21.98216","-0.00118"
"264.13200","22.01116","-0.00119"
"264.48000","22.04016","-0.00155"
"264.82800","22.06915","-0.00142"
"265.17600","22.09815","-0.00043"
"265.52400","22.12715","-0.00117"
"265.87200","22.15615","-0.00161"
"266.22000","22.18508","-0.00096"
"266.56800","22.21408","-0.00124"
"266.91600","22.24314","-0.00110"
"267.26400","22.27214","-0.00087"
"267.61200","22.30114","-0.00133"
"267.96000","22.33019","-0.00095"
"268.30800","22.35907","-0.00097"
"268.65600","22.38819","-0.00133"
"269.00400","22.41713","-0.00137"
"269.35200","22.44607","-0.00093"
"269.70000","22.47512","-0.00113"
"270.04800","22.50412","-0.00116"
"270.39600","22.53312","-0.00123"
"270.74400","22.56212","-0.00012"
"271.09200","22.59112","-0.00057"
"271.44000","22.62017","-0.00122"
"271.78800","22.64917","-0.00127"
"272.13600","22.67817","-0.00082"
"272.48400","22.70711","-0.00103"
"272.83200","22.73617","-0.00055"
"273.18000","22.76510","-0.00117"
"273.52800","22.79416","-0.00093"
"273.87600","22.82316","-0.00064"
"274.22400","22.85210","-0.00045"
"274.57200","22.88115","-0.00153"
"274.92000","22.91015","-0.00057"
"275.26800","22.93915","-0.00069"
"275.61600","22.96815","-0.00098"
"275.96400","22.99715","-0.00055"
"276.31200","23.02615","-0.00108"
"276.66000","23.05514","-0.00128"
"277.00800","23.08414","-0.00024"
"277.35600","23.11308","-0.00044"
"277.70400","23.14220","-0.00166"
"278.05200","23.17107","-0.00124"
"278.40000","23.20013","-0.00084"
"278.74800","23.22919","-0.00112"
"279.09600","23.25801","-0.00049"
"279.44400","23.28718","-0.00021"
"279.79200","23.31618","-0.00036"
"280.14000","23.34512","-0.00084"
"280.48800","23.37418","-0.00033"
"280.83600","23.40312","-0.00066"
"281.18400","23.43212","-0.00053"
"281.53200","23.46117","-0.00047"
"281.88000","23.49017","-0.00094"
"282.22800","23.51911","-0.00069"
"282.57600","23.54817","-0.00042"
"282.92400","23.57710","-0.00105"
"283.27200","23.60610","-0.00132"
"283.62000","23.63516","-0.00071"
"283.96800","23.66410","-0.00076"
"284.31600","23.69310","-0.00060"
"284.66400","23.72221","-0.00100"
"285.01200","23.75109","-0.00040"
"285.36000","23.78009","-0.00032"
"285.70800","23.80915","-0.00100"
"286.05600","23.83815","-0.00145"
"286.40400","23.86714","-0.00048"
"286.75200","23.89620","-0.00085"
"287.10000","23.92508","-0.00102"
"287.44800","23.95414","-0.00114"
"287.79600","23.98314","0.00014"
"288.14400","24.01213","-0.00022"
"288.49200","24.04113","-0.00075"
"288.84000","24.07007","-0.00071"
"289.18800","24.09919","-0.00028"
"289.53600","24.12813","-0.00015"
"289.88400","24.15713","-0.00063"
"290.23200","24.18618","-0.00110"
"290.58000","24.21512","-0.00082"
"290.92800","24.24412","-0.00094"
"291.27600","24.27317","-0.00135"
"291.62400","24.30217","-0.00040"
"291.97200","24.33105","-0.00018"
"292.32000","24.36011","-0.00064"
"292.66800","24.38917","-0.00077"
"293.01600","24.41810","-0.00032"
"293.36400","24.44716","-0.00090"
"293.71200","24.47610","0.00021"
"294.06000","24.50510","-0.00033"
"294.40800","24.53410","-0.00051"
"294.75600","24.56310","0.00008"
"295.10400","24.59215","-0.00032"
"295.45200","24.62115","-0.00094"
"295.80000","24.65015","-0.00054"
"296.14800","24.67914","-0.00064"
"296.49600","24.70820","-0.00084"
"296.84400","24.73708","-0.00096"
"297.19200","24.76614","-0.00032"
"297.54000","24.79514","-0.00074"
"297.88800","24.82413","-0.00105"
"298.23600","24.85319","-0.00073"
"298.58400","24.88213","-0.00041"
"298.93200","24.91113","-0.00008"
"299.28000","24.94019","-0.00059"
"299.62800","24.96913","-0.00066"
"299.97600","24.99812","-0.00074"
"300.32400","25.02712","-0.00115"
"300.67200","25.05612","-0.00041"
"301.02000","25.08512","-0.00068"
"301.36800","25.11418","-0.00091"
"301.71600","25.14311","-0.00115"
"302.06400","25.17211","-0.00066"
"302.41200","25.20123","-0.00058"
"302.76000","25.23011","-0.00079"
"303.10800","25.25916","-0.00050"
"303.45600","25.28816","-0.00060"
"303.80400","25.31710","-0.00053"
"304.15200","25.34622","-0.00053"
"304.50000","25.37516","-0.00139"
"304.84800","25.40409","-0.00060"
"305.19600","25.43315","-0.00029"
"305.54400","25.46215","-0.00089"
"305.89200","25.49115","-0.00119"
"306.24000","25.52015","-0.00111"
"306.58800","25.54908","-0.00054"
"306.93600","25.57808","-0.00111"
"307.28400","25.60714","-0.00114"
"307.63200","25.63608","-0.00023"
"307.98000","25.66519","-0.00026"
"308.32800","25.69419","-0.00111"
"308.67600","25.72313","-0.00053"
"309.02400","25.75219","-0.00043"
"309.37200","25.78113","-0.00092"
"309.72000","25.81012","-0.00084"
"310.06800","25.83918","-0.00098"
"310.41600","25.86818","-0.00078"
"310.76400","25.89712","-0.00074"
"311.11200","25.92618","-0.00061"
"311.46000","25.95511","-0.00107"
"311.80800","25.98411","-0.00079"
"312.15600","26.01323","-0.00107"
"312.50400","26.04211","-0.00094"
"312.85200","26.07111","-0.00037"
"313.20000","26.10017","0.00023"
"313.54800","26.12904","-0.00095"
"313.89600","26.15816","-0.00069"
"314.24400","26.18716","-0.00018"
"314.59200","26.21610","-0.00036"
"314.94000","26.24516","-0.00097"
"315.28800","26.27415","-0.00025"
"315.63600","26.30309","-0.00032"
"315.98400","26.33215","-0.00091"
"316.33200","26.36115","-0.00016"
"316.68000","26.39014","-0.00038"
"317.02800","26.41914","-0.00105"
"317.37600","26.44814","-0.00062"
"317.72400","26.47714","-0.00070"
"318.07200","26.50614","-0.00064"
"318.42000","26.53507","-0.00068"
"318.76800","26.56419","-0.00136"
"319.11600","26.59313","-0.00082"
"319.46400","26.62207","-0.00056"
"319.81200","26.65106","-0.00094"
"320.16000","26.68018","-0.00117"
"320.50800","26.70912","-0.00036"
"320.85600","26.73818","-0.00067"
"321.20400","26.76718","-0.00122"
"321.55200","26.79605","-0.00109"
"321.90000","26.82517","-0.00063"
"322.24800","26.85417","-0.00056"
"322.59600","26.88311","-0.00064"
"322.94400","26.91223","-0.00106"
"323.29200","26.94110","-0.00045"
"323.64000","26.97016","-0.00003"
"323.98800","26.99916","-0.00109"
"324.33600","27.02810","0.00013"
"324.68400","27.05716","-0.00038"
"325.03200","27.08615","-0.00055"
"325.38000","27.11515","-0.00049"
"325.72800","27.14415","-0.00072"
"326.07600","27.17315","-0.00082"
"326.42400","27.20209","0.00012"
"326.77200","27.23120","-0.00033"
"327.12000","27.26008","-0.00118"
"327.46800","27.28908","-0.00089"
"327.81600","27.31814","-0.00032"
"328.16400","27.34720","-0.00055"
"328.51200","27.37613","-0.00086"
"328.86000","27.40513","-0.00057"
"329.20800","27.43413","-0.00104"
"329.55600","27.46318","-0.00058"
"329.90400","27.49212","-0.00068"
"330.25200","27.52112","-0.00111"
"330.60000","27.55006","-0.00070"
"330.94800","27.57924","-0.00080"
"331.29600","27.60806","-0.00081"
"331.64400","27.63717","-0.00118"
"331.99200","27.66617","-0.00089"
"332.34000","27.69511","-0.00057"
"332.68800","27.72417","-0.00014"
"333.03600","27.75311","-0.00089"
"333.38400","27.78210","-0.00088"
"333.73200","27.81116","-0.00088"
"334.08000","27.84016","-0.00106"
"334.42800","27.86910","-0.00120"
"334.77600","27.89816","-0.00144"
"335.12400","27.92715","-0.00094"
"335.47200","27.95615","-0.00064"
"335.82000","27.98521","-0.00040"
"336.16800","28.01414","-0.00110"
"336.51600","28.04315","-0.00049"
"336.86400","28.07220","-0.00074"
"337.21200","28.10108","-0.00096"
"337.56000","28.13014","-0.00072"
"337.90800","28.15914","-0.00038"
"338.25600","28.18808","-0.00085"
"338.60400","28.21713","-0.00085"
"338.95200","28.24613","-0.00085"
"339.30000","28.27513","-0.00134"
"339.64800","28.30413","-0.00109"
"339.99600","28.33312","-0.00072"
"340.34400","28.36212","-0.00040"
"340.69200","28.39118","-0.00105"
"341.04000","28.42012","-0.00060"
"341.38800","28.44911","-0.00081"
"341.73600","28.47818","-0.00114"
"342.08400","28.50705","-0.00106"
"342.43200","28.53617","-0.00099"
"342.78000","28.56511","-0.00052"
"343.12800","28.59411","-0.00073"
"343.47600","28.62316","-0.00073"
"343.82400","28.65216","-0.00127"
"344.17200","28.68116","-0.00094"
"344.52000","28.71010","-0.00084"
"344.86800","28.73915","-0.00121"
"345.21600","28.76815","-0.00032"
"345.56400","28.79715","-0.00154"
"345.91200","28.82615","-0.00088"
"346.26000","28.85509","-0.00063"
"346.60800","28.88415","-0.00095"
"346.95600","28.91308","-0.00131"
"347.30400","28.94214","-0.00081"
"347.65200","28.97114","-0.00048"
"348.00000","29.00008","-0.00089"
"348.34800","29.02919","-0.00036"
"348.69600","29.05819","-0.00122"
"349.04400","29.08707","-0.00134"
"349.39200","29.11619","-0.00063"
"349.74000","29.14512","-0.00110"
"350.08800","29.17413","-0.00080"
"350.43600","29.20318","-0.00089"
"350.78400","29.23218","-0.00088"
"351.13200","29.26112","-0.00072"
"351.48000","29.29018","-0.00079"
"351.82800","29.31911","-0.00043"
"352.17600","29.34811","-0.00059"
"352.52400","29.37717","-0.00086"
"352.87200","29.40611","-0.00111"
"353.22000","29.43510","-0.00096"
"353.56800","29.46416","-0.00070"
"353.91600","29.49316","-0.00102"
"354.26400","29.52210","-0.00121"
"354.61200","29.55122","-0.00092"
"354.96000","29.58009","-0.00082"
"355.30800","29.60915","-0.00098"
"355.65600","29.63815","-0.00076"
"356.00400","29.66709","-0.00076"
"356.35200","29.69615","-0.00056"
"356.70000","29.72514","-0.00085"
"357.04800","29.75414","-0.00039"
"357.39600","29.78314","-0.00068"
"357.74400","29.81214","-0.00089"
"358.09200","29.84114","-0.00063"
"358.44000","29.87013","-0.00102"
"358.78800","29.89913","-0.00022"
"359.13600","29.92813","-0.00079"
"359.48400","29.95719","-0.00135"
"359.83200","29.98613","-0.00029"
"360.18000","30.01518","-0.00067"
"360.52800","30.04412","-0.00086"
"360.87600","30.07306","-0.00117"
"361.22400","30.10218","-0.00109"
"361.57200","30.13117","-0.00051"
"361.92000","30.16011","-0.00053"
"362.26800","30.18917","-0.00049"
"362.61600","30.21811","-0.00105"
"362.96400","30.24711","-0.00095"
"363.31200","30.27617","-0.00038"
"363.66000","30.30516","-0.00065"
"364.00800","30.33404","-0.00133"
"364.35600","30.36316","-0.00087"
"364.70400","30.39216","-0.00090"
"365.05200","30.42109","-0.00071"
"365.40000","30.45021","-0.00122"
"365.74800","30.47909","-0.00042"
"366.09600","30.50815","-0.00040"
"366.44400","30.53721","-0.00017"
"366.79200","30.56614","-0.00079"
"367.14000","30.59514","-0.00046"
"367.48800","30.62414","-0.00082"
"367.83600","30.65314","-0.00054"
"368.18400","30.68220","-0.00058"
"368.53200","30.71113","-0.00103"
"368.88000","30.74007","-0.00072"
"369.22800","30.76913","-0.00099"
"369.57600","30.79813","-0.00084"
"369.92400","30.82719","-0.00114"
"370.27200","30.85618","-0.00081"
"370.62000","30.88506","-0.00120"
"370.96800","30.91418","-0.00029"
"371.31600","30.94318","-0.00068"
"371.66400","30.97205","-0.00062"
"372.01200","31.00111","-0.00059"
"372.36000","31.03017","-0.00088"
"372.70800","31.05911","-0.00038"
"373.05600","31.08817","-0.00060"
"373.40400","31.11722","-0.00056"
"373.75200","31.14610","-0.00063"
"374.10000","31.17516","-0.00060"
"374.44800","31.20416","-0.00056"
"374.79600","31.23310","-0.00036"
"375.14400","31.26221","-0.00161"
"375.49200","31.29115","-0.00081"
"375.84000","31.32015","-0.00111"
"376.18800","31.34914","-0.00099"
"376.53600","31.37808","-0.00098"
"376.88400","31.40714","-0.00081"
"377.23200","31.43614","-0.00096"
"377.58000","31.46514","-0.00047"
"377.92800","31.49414","-0.00059"
"378.27600","31.52319","-0.00126"
"378.62400","31.55207","-0.00081"
"378.97200","31.58113","-0.00130"
"379.32000","31.61019","-0.00138"
"379.66800","31.63913","-0.00090"
"380.01600","31.66812","-0.00101"
"380.36400","31.69712","-0.00126"
"380.71200","31.72612","-0.00148"
"381.06000","31.75517","-0.00043"
"381.40800","31.78411","-0.00062"
"381.75600","31.81311","-0.00110"
"382.10400","31.84211","-0.00120"
"382.45200","31.87117","-0.00023"
"382.80000","31.90017","-0.00055"
"383.14800","31.92916","-0.00082"
"383.49600","31.95804","-0.00108"
"383.84400","31.98710","-0.00010"
"384.19200","32.01622","-0.00087"
"384.54000","32.04510","-0.00109"
"384.88800","32.07415","-0.00140"
"385.23600","32.10315","-0.00105"
"385.58400","32.13209","-0.00092"
"385.93200","32.16121","-0.00095"
"386.28000","32.19014","-0.00109"
"386.62800","32.21915","-0.00072"
"386.97600","32.24814","-0.00050"
"387.32400","32.27714","-0.00124"
"387.67200","32.30614","-0.00106"
"388.02000","32.33514","-0.00110"
"388.36800","32.36413","-0.00035"
"388.71600","32.39313","-0.00141"
"389.06400","32.42213","-0.00112"
"389.41200","32.45113","-0.00137"
"389.76000","32.48013","-0.00128"
"390.10800","32.50918","-0.00194"
"390.45600","32.53812","-0.00122"
"390.80400","32.56712","-0.00066"
"391.15200","32.59618","-0.00102"
"391.50000","32.62512","-0.00112"
"391.84800","32.65417","-0.00079"
"392.19600","32.68317","-0.00105"
"392.54400","32.71211","-0.00091"
"392.89200","32.74117","-0.00094"
"393.24000","32.77016","-0.00092"
"393.58800","32.79910","-0.00097"
"393.93600","32.82816","-0.00135"
"394.28400","32.85716","-0.00097"
"394.63200","32.88610","-0.00092"
"394.98000","32.91515","-0.00122"
"395.32800","32.94403","-0.00080"
"395.67600","32.97315","0.00002"
"396.02400","33.00215","-0.00165"
"396.37200","33.03115","-0.00115"
"396.72000","33.06020","-0.00050"
"397.06800","33.08914","-0.00072"
"397.41600","33.11814","-0.00091"
"397.76400","33.14714","-0.00079"
"398.11200","33.17614","-0.00098"
"398.46000","33.20507","-0.00099"
"398.80800","33.23419","-0.00092"
"399.15600","33.26313","-0.00065"
"399.50400","33.29213","-0.00125"
"399.85200","33.32118","-0.00025"
"400.20000","33.35006","-0.00078"
"400.54800","33.37918","-0.00069"
"400.89600","33.40818","-0.00103"
"401.24400","33.43712","-0.00073"
"401.59200","33.46618","-0.00122"
"401.94000","33.49511","-0.00022"
"402.28800","33.52411","-0.00051"
"402.63600","33.55311","-0.00132"
"402.98400","33.58216","-0.00066"
"403.33200","33.61116","-0.00102"
"403.68000","33.64016","-0.00064"
"404.02800","33.66916","-0.00123"
"404.37600","33.69810","-0.00064"
"404.72400","33.72715","-0.00039"
"405.07200","33.75609","-0.00063"
"405.42000","33.78515","-0.00065"
"405.76800","33.81415","-0.00065"
"406.11600","33.84309","-0.00034"
"406.46400","33.87215","-0.00053"
"406.81200","33.90114","-0.00031"
"407.16000","33.93014","-0.00084"
"407.50800","33.95914","-0.00061"
"407.85600","33.98825","-0.00090"
"408.20400","34.01707","-0.00040"
"408.55200","34.04613","-0.00019"
"408.90000","34.07513","-0.00141"
"409.24800","34.10407","-0.00059"
"409.59600","34.13313","-0.00069"
"409.94400","34.16212","-0.00098"
"410.29200","34.19112","-0.00053"
"410.64000","34.22012","-0.00056"
"410.98800","34.24912","-0.00008"
"411.33600","34.27818","-0.00063"
"411.68400","34.30711","-0.00094"
"412.03200","34.33611","-0.00031"
"412.38000","34.36511","-0.00040"
"412.72800","34.39423","-0.00081"
"413.07600","34.42311","-0.00045"
"413.42400","34.45216","-0.00009"
"413.77200","34.48116","-0.00068"
"414.12000","34.51010","-0.00117"
"414.46800","34.53915","-0.00028"
"414.81600","34.56809","-0.00024"
"415.16400","34.59710","-0.00076"
"415.51200","34.62615","-0.00072"
"415.86000","34.65515","-0.00011"
"416.20800","34.68415","-0.00033"
"416.55600","34.71315","-0.00054"
"416.90400","34.74208","0.00022"
"417.25200","34.77114","-0.00016"
"417.60000","34.80020","-0.00019"
"417.94800","34.82907","0.00002"
"418.29600","34.85814","-0.00050"
"418.64400","34.88719","-0.00024"
"418.99200","34.91607","-0.00078"
"419.34000","34.94519","-0.00019"
"419.68800","34.97419","-0.00033"
"420.03600","35.00312","0.00023"
"420.38400","35.03218","-0.00018"
"420.73200","35.06112","0.00010"
"421.08000","35.09012","-0.00044"
"421.42800","35.11912","-0.00014"
"421.77600","35.14811","0.00002"
"422.12400","35.17711","-0.00017"
"422.47200","35.20617","-0.00018"
"422.82000","35.23511","-0.00001"
"423.16800","35.26405","0.00023"
"423.51600","35.29322","0.00002"
"423.86400","35.32210","-0.00031"
"424.21200","35.35122","0.00030"
"424.56000","35.38016","0.00036"
"424.90800","35.40910","0.00024"
"425.25600","35.43815","0.00000"
"425.60400","35.46715","-0.00033"
"425.95200","35.49615","-0.00039"
"426.30000","35.52515","-0.00051"
"426.64800","35.55415","0.00034"
"426.99600","35.58314","-0.00051"
"427.34400","35.61214","-0.00001"
"427.69200","35.64114","0.00003"
"428.04000","35.67007","0.00004"
"428.38800","35.69919","0.00064"
"428.73600","35.72813","-0.00019"
"429.08400","35.75713","0.00044"
"429.43200","35.78613","-0.00002"
"429.78000","35.81507","0.00004"
"430.12800","35.84418","-0.00093"
"430.47600","35.87318","-0.00100"
"430.82400","35.90212","-0.00130"
"431.17200","35.93112","-0.00065"
"431.52000","35.96017","-0.00087"
"431.86800","35.98911","-0.00113"
"432.21600","36.01817","0.00008"
"432.56400","36.04717","-0.00094"
"432.91200","36.07611","-0.00157"
"433.26000","36.10516","-0.00105"
"433.60800","36.13416","-0.00066"
"433.95600","36.16310","-0.00034"
"434.30400","36.19216","-0.00088"
"434.65200","36.22110","-0.00073"
"435.00000","36.25016","-0.00110"
"435.34800","36.27915","-0.00085"
"435.69600","36.30809","-0.00058"
"436.04400","36.33709","-0.00098"
"436.39200","36.36615","-0.00045"
"436.74000","36.39508","-0.00052"
"437.08800","36.42414","-0.00072"
"437.43600","36.45320","-0.00091"
"437.78400","36.48214","-0.00079"
"438.13200","36.51120","-0.00121"
"438.48000","36.54013","-0.00059"
"438.82800","36.56913","-0.00065"
"439.17600","36.59813","-0.00134"
"439.52400","36.62713","-0.00063"
"439.87200","36.65619","-0.00018"
"440.22000","36.68518","-0.00134"
"440.56800","36.71412","-0.00010"
"440.91600","36.74306","-0.00104"
"441.26400","36.77212","-0.00096"
"441.61200","36.80111","-0.00092"
"441.96000","36.83017","-0.00107"
"442.30800","36.85917","-0.00084"
"442.65600","36.88805","-0.00128"
"443.00400","36.91717","-0.00115"
"443.35200","36.94617","-0.00181"
"443.70000","36.97511","-0.00122"
"444.04800","37.00422","-0.00061"
"444.39600","37.03310","-0.00025"
"444.74400","37.06210","-0.00076"
"445.09200","37.09116","-0.00103"
"445.44000","37.12015","-0.00114"
"445.78800","37.14915","0.00005"
"446.13600","37.17815","-0.00074"
"446.48400","37.20715","-0.00054"
"446.83200","37.23614","-0.00058"
"447.18000","37.26520","-0.00112"
"447.52800","37.29408","-0.00110"
"447.87600","37.32314","-0.00087"
"448.22400","37.35214","-0.00097"
"448.57200","37.38108","-0.00095"
"448.92000","37.41013","-0.00085"
"449.26800","37.43913","-0.00080"
"449.61600","37.46813","-0.00079"
"449.96400","37.49718","-0.00093"
"450.31200","37.52612","0.00004"
"450.66000","37.55512","-0.00106"
"451.00800","37.58412","-0.00081"
"451.35600","37.61312","-0.00118"
"451.70400","37.64211","-0.00063"
"452.05200","37.67117","-0.00029"
"452.40000","37.70011","-0.00090"
"452.74800","37.72911","-0.00073"
"453.09600","37.75817","-0.00084"
"453.44400","37.78704","-0.00075"
"453.79200","37.81616","-0.00071"
"454.14000","37.84516","-0.00058"
"454.48800","37.87416","-0.00036"
"454.83600","37.90322","-0.00036"
"455.18400","37.93216","-0.00051"
"455.53200","37.96109","-0.00055"
"455.88000","37.99015","-0.00049"
"456.22800","38.01909","-0.00066"
"456.57600","38.04808","-0.00013"
"456.92400","38.07714","-0.00063"
"457.27200","38.10614","-0.00026"
"457.62000","38.13514","-0.00083"
"457.96800","38.16420","-0.00075"
"458.31600","38.19308","0.00019"
"458.66400","38.22213","0.00008"
"459.01200","38.25119","0.00017"
"459.36000","38.28007","-0.00041"
"459.70800","38.30913","-0.00018"
"460.05600","38.33812","0.00012"
"460.40400","38.36712","-0.00022"
"460.75200","38.39618","-0.00025"
"461.10000","38.42518","-0.00011"
"461.44800","38.45412","0.00001"
"461.79600","38.48317","0.00020"
"462.14400","38.51205","-0.00027"
"462.49200","38.54111","-0.00025"
"462.84000","38.57017","0.00017"
"463.18800","38.59911","-0.00009"
"463.53600","38.62817","0.00054"
"463.88400","38.65710","0.00011"
"464.23200","38.68610","0.00065"
"464.58000","38.71516","-0.00019"
"464.92800","38.74416","0.00028"
"465.27600","38.77315","-0.00028"
"465.62400","38.80215","0.00003"
"465.97200","38.83115","0.00020"
"466.32000","38.86008","0.00071"
"466.66800","38.88915","0.00061"
"467.01600","38.91814","0.00029"
"467.36400","38.94708","0.00067"
"467.71200","38.97620","0.00031"
"468.06000","39.00514","0.00024"
"468.40800","39.03413","0.00045"
"468.75600","39.06313","0.00082"
"469.10400","39.09213","0.00017"
"469.45200","39.12113","-0.00026"
"469.80000","39.15018","0.00054"
"470.14800","39.17912","0.00011"
"470.49600","39.20812","0.00020"
"470.84400","39.23712","0.00100"
"471.19200","39.26605","0.00070"
"471.54000","39.29518","0.00025"
"471.88800","39.32417","0.00132"
"472.23600","39.35305","0.00093"
"472.58400","39.38217","0.00140"
"472.93200","39.41117","0.00137"
"473.28000","39.44017","0.00090"
"473.62800","39.46916","0.00091"
"473.97600","39.49810","0.00122"
"474.32400","39.52710","0.00058"
"474.67200","39.55616","0.00069"
"475.02000","39.58516","0.00093"
"475.36800","39.61409","0.00131"
"475.71600","39.64315","0.00132"
"476.06400","39.67209","0.00197"
"476.41200","39.70115","0.00138"
"476.76000","39.73021","0.00188"
"477.10800","39.75902","0.00205"
"477.45600","39.78820","0.00130"
"477.80400","39.81720","0.00134"
"478.15200","39.84608","0.00165"
"478.50000","39.87513","0.00206"
"478.84800","39.90407","0.00199"
"479.19600","39.93313","0.00233"
"479.54400","39.96212","0.00198"
"479.89200","39.99118","0.00187"
"480.24000","40.02012","0.00237"
"480.58800","40.04912","0.00266"
"480.93600","40.07812","0.00276"
"481.28400","40.10712","0.00254"
"481.63200","40.13617","0.00244"
"481.98000","40.16512","0.00267"
"482.32800","40.19411","0.00338"
"482.67600","40.22317","0.00284"
"483.02400","40.25211","0.00281"
"483.37200","40.28110","0.00277"
"483.72000","40.31010","0.00334"
"484.06800","40.33916","0.00352"
"484.41600","40.36816","0.00346"
"484.76400","40.39722","0.00373"
"485.11200","40.42609","0.00353"
"485.46000","40.45515","0.00363"
"485.80800","40.48415","0.00437"
"486.15600","40.51309","0.00423"
"486.50400","40.54221","0.00404"
"486.85200","40.57102","0.00444"
"487.20000","40.60014","0.00483"
"487.54800","40.62920","0.00445"
"487.89600","40.65808","0.00447"
"488.24400","40.68719","0.00473"
"488.59200","40.71613","0.00517"
"488.94000","40.74513","0.00558"
"489.28800","40.77419","0.00498"
"489.63600","40.80313","0.00014"
"489.98400","40.83212","-0.00096"
"490.33200","40.86119","-0.00086"
"490.68000","40.89018","-0.00122"
"491.02800","40.91912","-0.00143"
"491.37600","40.94812","-0.00147"
"491.72400","40.97712","-0.00169"
"492.07200","41.00611","-0.00162"
"492.42000","41.03517","-0.00122"
"492.76800","41.06411","-0.00128"
"493.11600","41.09316","-0.00164"
"493.46400","41.12216","-0.00098"
"493.81200","41.15110","-0.00132"
"494.16000","41.18016","-0.00138"
"494.50800","41.20916","-0.00103"
"494.85600","41.23809","-0.00102"
"495.20400","41.26716","-0.00158"
"495.55200","41.29615","-0.00185"
"495.90000","41.32509","-0.00187"
"496.24800","41.35421","-0.00117"
"496.59600","41.38309","-0.00150"
"496.94400","41.41208","-0.00136"
"497.29200","41.44114","-0.00117"
"497.64000","41.47014","-0.00135"
"497.98800","41.49914","-0.00052"
"498.33600","41.52814","-0.00045"
"498.68400","41.55707","-0.00131"
"499.03200","41.58619","-0.00167"
"499.38000","41.61513","-0.00111"
"499.72800","41.64407","-0.00161"
"500.07600","41.67313","-0.00139"
"500.42400","41.70219","-0.00143"
"500.77200","41.73106","-0.00184"
"501.12000","41.76018","-0.00118"
"501.46800","41.78912","-0.00190"
"501.81600","41.81806","-0.00076"
"502.16400","41.84717","-0.00143"
"502.51200","41.87617","-0.00111"
"502.86000","41.90511","-0.00096"
"503.20800","41.93416","-0.00138"
"503.55600","41.96317","-0.00145"
"503.90400","41.99210","-0.00141"
"504.25200","42.02116","-0.00134"
"504.60000","42.05016","-0.00110"
"504.94800","42.07916","-0.00107"
"505.29600","42.10815","-0.00130"
"505.64400","42.13704","-0.00181"
"505.99200","42.16615","-0.00073"
"506.34000","42.19515","-0.00150"
"506.68800","42.22415","-0.00152"
"507.03600","42.25320","-0.00128"
"507.38400","42.28214","-0.00160"
"507.73200","42.31114","-0.00205"
"508.08000","42.34014","-0.00070"
"508.42800","42.36913","-0.00108"
"508.77600","42.39813","-0.00137"
"509.12400","42.42713","-0.00127"
"509.47200","42.45613","-0.00174"
"509.82000","42.48513","-0.00140"
"510.16800","42.51413","-0.00104"
"510.51600","42.54312","-0.00100"
"510.86400","42.57212","-0.00110"
"511.21200","42.60118","-0.00141"
"511.56000","42.63006","-0.00074"
"511.90800","42.65918","-0.00066"
"512.25600","42.68817","-0.00098"
"512.60400","42.71711","-0.00049"
"512.95200","42.74616","-0.00141"
"513.30000","42.77510","-0.00085"
"513.64800","42.80404","-0.00094"
"513.99600","42.83323","-0.00045"
"514.34400","42.86210","-0.00141"
"514.69200","42.89116","0.00147"
"515.04000","42.92022","0.00071"
"515.38800","42.94915","-0.00043"
"515.73600","42.97809","-0.00009"
"516.08400","43.00715","-0.00020"
"516.43200","43.03608","-0.00044"
"516.78000","43.06514","-0.00018"
"517.12800","43.09414","-0.00046"
"517.47600","43.12314","-0.00061"
"517.82400","43.15214","-0.00025"
"518.17200","43.18114","-0.00027"
"518.52000","43.21013","-0.00050"
"518.86800","43.23913","0.00003"
"519.21600","43.26819","-0.00091"
"519.56400","43.29713","-0.00022"
"519.91200","43.32619","-0.00018"
"520.26000","43.35519","-0.00117"
"520.60800","43.38412","-0.00066"
"520.95600","43.41318","-0.00089"
"521.30400","43.44206","-0.00067"
"521.36200","43.44702","-0.00066"