File: Force_trajectories/170212_1/Specimen_RawData_5.csv
End date,"2/12/2017"
Specimen label,"9AG_80"
Maximum Load,"0.51878",N

Time,Extension,Load
(s),(mm),(N)
"0.00000","0.00000","-0.00025"
"0.16200","0.00981","0.00032"
"0.32400","0.02685","0.00076"
"0.48600","0.04084","0.00069"
"0.64800","0.05417","0.00152"
"0.81000","0.06774","0.00155"
"0.97200","0.08119","0.00188"
"1.13400","0.09471","0.00232"
"1.29600","0.10810","0.00196"
"1.45800","0.12173","0.00280"
"1.62000","0.13524","0.00265"
"1.78200","0.14864","0.00288"
"1.94400","0.16221","0.00309"
"2.10600","0.17566","0.00322"
"2.26800","0.18917","0.00375"
"2.43000","0.20263","0.00363"
"2.59200","0.21620","0.00408"
"2.75400","0.22971","0.00348"
"2.91600","0.24316","0.00415"
"3.07800","0.25674","0.00465"
"3.24000","0.27019","0.00459"
"3.40200","0.28370","0.00435"
"3.56400","0.29721","0.00547"
"3.72600","0.31073","0.00511"
"3.88800","0.32418","0.00483"
"4.05000","0.33769","0.00530"
"4.21200","0.35120","0.00469"
"4.37400","0.36472","0.00564"
"4.53600","0.37817","0.00618"
"4.69800","0.39168","0.00569"
"4.86000","0.40519","0.00591"
"5.02200","0.41865","0.00601"
"5.18400","0.43216","0.00650"
"5.34600","0.44573","0.00656"
"5.50800","0.45918","0.00657"
"5.67000","0.47270","0.00657"
"5.83200","0.48621","0.00733"
"5.99400","0.49966","0.00688"
"6.15600","0.51311","0.00769"
"6.31800","0.52669","0.00744"
"6.48000","0.54020","0.00761"
"6.64200","0.55371","0.00781"
"6.80400","0.56722","0.00773"
"6.96600","0.58068","0.00783"
"7.12800","0.59419","0.00848"
"7.29000","0.60770","0.00853"
"7.45200","0.62121","0.00799"
"7.61400","0.63467","0.00851"
"7.77600","0.64818","0.00868"
"7.93800","0.66181","0.00869"
"8.10000","0.67520","0.00837"
"8.26200","0.68866","0.00824"
"8.42400","0.70217","0.00866"
"8.58600","0.71568","0.00914"
"8.74800","0.72913","0.00888"
"8.91000","0.74271","0.00917"
"9.07200","0.75622","0.00909"
"9.23400","0.76973","0.00933"
"9.39600","0.78318","0.00899"
"9.55800","0.79670","0.00980"
"9.72000","0.81021","0.00999"
"9.88200","0.82360","0.00940"
"10.04400","0.83717","0.01015"
"10.20600","0.85075","0.00999"
"10.36800","0.86420","0.00983"
"10.53000","0.87771","0.01024"
"10.69200","0.89116","0.01032"
"10.85400","0.90468","0.01085"
"11.01600","0.91813","0.01096"
"11.17800","0.93170","0.01078"
"11.34000","0.94521","0.01054"
"11.50200","0.95867","0.01083"
"11.66400","0.97224","0.01089"
"11.82600","0.98569","0.01080"
"11.98800","0.99914","0.01085"
"12.15000","1.01272","0.01105"
"12.31200","1.02623","0.01157"
"12.47400","1.03968","0.01135"
"12.63600","1.05319","0.01182"
"12.79800","1.06671","0.01134"
"12.96000","1.08022","0.01173"
"13.12200","1.09367","0.01181"
"13.28400","1.10718","0.01209"
"13.44600","1.12069","0.01237"
"13.60800","1.13415","0.01228"
"13.77000","1.14766","0.01198"
"13.93200","1.16123","0.01148"
"14.09400","1.17469","0.01219"
"14.25600","1.18820","0.01157"
"14.41800","1.20171","0.01228"
"14.58000","1.21522","0.01256"
"14.74200","1.22867","0.01324"
"14.90400","1.24219","0.01234"
"15.06600","1.25564","0.01355"
"15.22800","1.26915","0.01279"
"15.39000","1.28266","0.01310"
"15.55200","1.29624","0.01314"
"15.71400","1.30969","0.01210"
"15.87600","1.32314","0.01293"
"16.03800","1.33671","0.01329"
"16.20000","1.35017","0.01367"
"16.36200","1.36362","0.01423"
"16.52400","1.37719","0.01343"
"16.68600","1.39070","0.01324"
"16.84800","1.40422","0.01363"
"17.01000","1.41767","0.01342"
"17.17200","1.43118","0.01290"
"17.33400","1.44463","0.01360"
"17.49600","1.45815","0.01401"
"17.65800","1.47166","0.01381"
"17.82000","1.48523","0.01395"
"17.98200","1.49868","0.01426"
"18.14400","1.51226","0.01385"
"18.30600","1.52565","0.01385"
"18.46800","1.53916","0.01426"
"18.63000","1.55267","0.01459"
"18.79200","1.56619","0.01450"
"18.95400","1.57964","0.01451"
"19.11600","1.59321","0.01501"
"19.27800","1.60678","0.01496"
"19.44000","1.62024","0.01505"
"19.60200","1.63363","0.01443"
"19.76400","1.64726","0.01437"
"19.92600","1.66071","0.01476"
"20.08800","1.67417","0.01574"
"20.25000","1.68768","0.01495"
"20.41200","1.70119","0.01510"
"20.57400","1.71464","0.01593"
"20.73600","1.72816","0.01522"
"20.89800","1.74167","0.01538"
"21.06000","1.75518","0.01581"
"21.22200","1.76863","0.01528"
"21.38400","1.78221","0.01509"
"21.54600","1.79572","0.01513"
"21.70800","1.80917","0.01569"
"21.87000","1.82268","0.01559"
"22.03200","1.83626","0.01611"
"22.19400","1.84965","0.01541"
"22.35600","1.86322","0.01592"
"22.51800","1.87673","0.01649"
"22.68000","1.89019","0.01630"
"22.84200","1.90370","0.01643"
"23.00400","1.91727","0.01604"
"23.16600","1.93072","0.01631"
"23.32800","1.94418","0.01602"
"23.49000","1.95769","0.01668"
"23.65200","1.97120","0.01631"
"23.81400","1.98471","0.01683"
"23.97600","1.99823","0.01697"
"24.13800","2.01168","0.01646"
"24.30000","2.02525","0.01689"
"24.46200","2.03870","0.01632"
"24.62400","2.05222","0.01705"
"24.78600","2.06561","0.01698"
"24.94800","2.07912","0.01705"
"25.11000","2.09269","0.01746"
"25.27200","2.10621","0.01681"
"25.43400","2.11972","0.01691"
"25.59600","2.13323","0.01660"
"25.75800","2.14668","0.01717"
"25.92000","2.16020","0.01742"
"26.08200","2.17365","0.01692"
"26.24400","2.18716","0.01636"
"26.40600","2.20067","0.01688"
"26.56800","2.21413","0.01721"
"26.73000","2.22776","0.01631"
"26.89200","2.24121","0.01662"
"27.05400","2.25466","0.01628"
"27.21600","2.26824","0.01707"
"27.37800","2.28175","0.01671"
"27.54000","2.29520","0.01703"
"27.70200","2.30865","0.01647"
"27.86400","2.32223","0.01684"
"28.02600","2.33568","0.01715"
"28.18800","2.34913","0.01705"
"28.35000","2.36276","0.01699"
"28.51200","2.37622","0.01672"
"28.67400","2.38967","0.01730"
"28.83600","2.40318","0.01734"
"28.99800","2.41675","0.01706"
"29.16000","2.43021","0.01684"
"29.32200","2.44366","0.01702"
"29.48400","2.45723","0.01722"
"29.64600","2.47068","0.01744"
"29.80800","2.48414","0.01740"
"29.97000","2.49771","0.01769"
"30.13200","2.51122","0.01765"
"30.29400","2.52467","0.01740"
"30.45600","2.53819","0.01737"
"30.61800","2.55176","0.01792"
"30.78000","2.56515","0.01774"
"30.94200","2.57866","0.01827"
"31.10400","2.59218","0.01806"
"31.26600","2.60569","0.01789"
"31.42800","2.61914","0.01730"
"31.59000","2.63271","0.01762"
"31.75200","2.64616","0.01716"
"31.91400","2.65968","0.01726"
"32.07600","2.67319","0.01672"
"32.23800","2.68670","0.01761"
"32.40000","2.70016","0.01758"
"32.56200","2.71367","0.01764"
"32.72400","2.72718","0.01745"
"32.88600","2.74069","0.01752"
"33.04800","2.75414","0.01840"
"33.21000","2.76772","0.01794"
"33.37200","2.78117","0.01800"
"33.53400","2.79468","0.01872"
"33.69600","2.80819","0.01771"
"33.85800","2.82171","0.01885"
"34.02000","2.83516","0.01752"
"34.18200","2.84867","0.01830"
"34.34400","2.86224","0.01831"
"34.50600","2.87570","0.01833"
"34.66800","2.88915","0.01824"
"34.83000","2.90272","0.01856"
"34.99200","2.91623","0.01836"
"35.15400","2.92963","0.01838"
"35.31600","2.94320","0.01852"
"35.47800","2.95671","0.01925"
"35.64000","2.97016","0.01882"
"35.80200","2.98368","0.01818"
"35.96400","2.99719","0.01829"
"36.12600","3.01070","0.01909"
"36.28800","3.02410","0.01854"
"36.45000","3.03773","0.01889"
"36.61200","3.05124","0.01901"
"36.77400","3.06463","0.01892"
"36.93600","3.07820","0.01897"
"37.09800","3.09172","0.01956"
"37.26000","3.10517","0.01864"
"37.42200","3.11868","0.01936"
"37.58400","3.13219","0.01937"
"37.74600","3.14565","0.01972"
"37.90800","3.15922","0.01964"
"38.07000","3.17273","0.01963"
"38.23200","3.18624","0.01924"
"38.39400","3.19970","0.02032"
"38.55600","3.21321","0.02043"
"38.71800","3.22672","0.02010"
"38.88000","3.24017","0.01966"
"39.04200","3.25369","0.02021"
"39.20400","3.26720","0.01988"
"39.36600","3.28071","0.02024"
"39.52800","3.29416","0.02010"
"39.69000","3.30768","0.02008"
"39.85200","3.32119","0.02055"
"40.01400","3.33464","0.02048"
"40.17600","3.34821","0.02040"
"40.33800","3.36173","0.02061"
"40.50000","3.37518","0.02072"
"40.66200","3.38869","0.01997"
"40.82400","3.40220","0.02015"
"40.98600","3.41572","0.02010"
"41.14800","3.42917","0.02067"
"41.31000","3.44268","0.02036"
"41.47200","3.45619","0.02057"
"41.63400","3.46965","0.02108"
"41.79600","3.48328","0.02137"
"41.95800","3.49673","0.02089"
"42.12000","3.51018","0.02081"
"42.28200","3.52370","0.02097"
"42.44400","3.53715","0.02057"
"42.60600","3.55066","0.02132"
"42.76800","3.56417","0.02070"
"42.93000","3.57769","0.02091"
"43.09200","3.59120","0.02145"
"43.25400","3.60465","0.02146"
"43.41600","3.61822","0.02126"
"43.57800","3.63174","0.02157"
"43.74000","3.64513","0.02141"
"43.90200","3.65870","0.02221"
"44.06400","3.67215","0.02247"
"44.22600","3.68567","0.02225"
"44.38800","3.69918","0.02195"
"44.55000","3.71269","0.02096"
"44.71200","3.72620","0.02170"
"44.87400","3.73966","0.02180"
"45.03600","3.75323","0.02243"
"45.19800","3.76668","0.02167"
"45.36000","3.78019","0.02232"
"45.52200","3.79371","0.02238"
"45.68400","3.80722","0.02172"
"45.84600","3.82073","0.02255"
"46.00800","3.83418","0.02196"
"46.17000","3.84770","0.02198"
"46.33200","3.86115","0.02232"
"46.49400","3.87460","0.02251"
"46.65600","3.88823","0.02177"
"46.81800","3.90175","0.02244"
"46.98000","3.91514","0.02289"
"47.14200","3.92871","0.02228"
"47.30400","3.94222","0.02293"
"47.46600","3.95568","0.02288"
"47.62800","3.96919","0.02277"
"47.79000","3.98270","0.02247"
"47.95200","3.99621","0.02327"
"48.11400","4.00967","0.02317"
"48.27600","4.02324","0.02260"
"48.43800","4.03675","0.02344"
"48.60000","4.05014","0.02317"
"48.76200","4.06372","0.02317"
"48.92400","4.07723","0.02345"
"49.08600","4.09068","0.02333"
"49.24800","4.10419","0.02392"
"49.41000","4.11770","0.02339"
"49.57200","4.13122","0.02384"
"49.73400","4.14467","0.02334"
"49.89600","4.15824","0.02368"
"50.05800","4.17170","0.02402"
"50.22000","4.18515","0.02388"
"50.38200","4.19872","0.02341"
"50.54400","4.21223","0.02400"
"50.70600","4.22568","0.02422"
"50.86800","4.23914","0.02419"
"51.03000","4.25271","0.02375"
"51.19200","4.26616","0.02406"
"51.35400","4.27968","0.02403"
"51.51600","4.29319","0.02439"
"51.67800","4.30676","0.02447"
"51.84000","4.32015","0.02470"
"52.00200","4.33372","0.02450"
"52.16400","4.34718","0.02497"
"52.32600","4.36069","0.02452"
"52.48800","4.37420","0.02482"
"52.65000","4.38771","0.02459"
"52.81200","4.40117","0.02538"
"52.97400","4.41468","0.02531"
"53.13600","4.42825","0.02466"
"53.29800","4.44170","0.02513"
"53.46000","4.45516","0.02506"
"53.62200","4.46873","0.02464"
"53.78400","4.48218","0.02434"
"53.94600","4.49563","0.02480"
"54.10800","4.50921","0.02585"
"54.27000","4.52272","0.02493"
"54.43200","4.53623","0.02523"
"54.59400","4.54968","0.02485"
"54.75600","4.56320","0.02553"
"54.91800","4.57665","0.02507"
"55.08000","4.59010","0.02573"
"55.24200","4.60367","0.02549"
"55.40400","4.61725","0.02563"
"55.56600","4.63070","0.02595"
"55.72800","4.64421","0.02549"
"55.89000","4.65766","0.02587"
"56.05200","4.67118","0.02550"
"56.21400","4.68469","0.02553"
"56.37600","4.69820","0.02580"
"56.53800","4.71171","0.02558"
"56.70000","4.72517","0.02624"
"56.86200","4.73868","0.02615"
"57.02400","4.75225","0.02598"
"57.18600","4.76564","0.02589"
"57.34800","4.77916","0.02630"
"57.51000","4.79273","0.02682"
"57.67200","4.80618","0.02503"
"57.83400","4.81969","0.02550"
"57.99600","4.83321","0.02594"
"58.15800","4.84672","0.02552"
"58.32000","4.86017","0.02609"
"58.48200","4.87368","0.02554"
"58.64400","4.88720","0.02581"
"58.80600","4.90071","0.02617"
"58.96800","4.91416","0.02586"
"59.13000","4.92767","0.02654"
"59.29200","4.94119","0.02592"
"59.45400","4.95470","0.02614"
"59.61600","4.96821","0.02625"
"59.77800","4.98166","0.02661"
"59.94000","4.99518","0.02652"
"60.10200","5.00869","0.02707"
"60.26400","5.02220","0.02665"
"60.42600","5.03565","0.02692"
"60.58800","5.04923","0.02710"
"60.75000","5.06274","0.02673"
"60.91200","5.07619","0.02740"
"61.07400","5.08970","0.02688"
"61.23600","5.10322","0.02717"
"61.39800","5.11667","0.02724"
"61.56000","5.13012","0.02709"
"61.72200","5.14375","0.02667"
"61.88400","5.15727","0.02724"
"62.04600","5.17066","0.02764"
"62.20800","5.18423","0.02729"
"62.37000","5.19774","0.02675"
"62.53200","5.21114","0.02693"
"62.69400","5.22465","0.02732"
"62.85600","5.23816","0.02702"
"63.01800","5.25167","0.02751"
"63.18000","5.26519","0.02724"
"63.34200","5.27870","0.02745"
"63.50400","5.29221","0.02731"
"63.66600","5.30566","0.02783"
"63.82800","5.31924","0.02707"
"63.99000","5.33269","0.02668"
"64.15200","5.34614","0.02743"
"64.31400","5.35965","0.02739"
"64.47600","5.37323","0.02805"
"64.63800","5.38668","0.02804"
"64.80000","5.40019","0.02845"
"64.96200","5.41370","0.02836"
"65.12400","5.42722","0.02827"
"65.28600","5.44067","0.02802"
"65.44800","5.45418","0.02846"
"65.61000","5.46775","0.02816"
"65.77200","5.48121","0.02821"
"65.93400","5.49472","0.02818"
"66.09600","5.50817","0.02860"
"66.25800","5.52168","0.02875"
"66.42000","5.53514","0.02842"
"66.58200","5.54871","0.02909"
"66.74400","5.56222","0.02863"
"66.90600","5.57567","0.02857"
"67.06800","5.58924","0.02893"
"67.23000","5.60270","0.02883"
"67.39200","5.61621","0.02884"
"67.55400","5.62972","0.02825"
"67.71600","5.64324","0.02841"
"67.87800","5.65669","0.02932"
"68.04000","5.67014","0.02914"
"68.20200","5.68371","0.02868"
"68.36400","5.69723","0.02897"
"68.52600","5.71068","0.02895"
"68.68800","5.72419","0.02930"
"68.85000","5.73770","0.02925"
"69.01200","5.75115","0.02900"
"69.17400","5.76467","0.02923"
"69.33600","5.77824","0.02949"
"69.49800","5.79169","0.02920"
"69.66000","5.80515","0.02976"
"69.82200","5.81872","0.02965"
"69.98400","5.83211","0.02962"
"70.14600","5.84562","0.02959"
"70.30800","5.85920","0.03004"
"70.47000","5.87271","0.02985"
"70.63200","5.88622","0.02987"
"70.79400","5.89967","0.02974"
"70.95600","5.91324","0.03008"
"71.11800","5.92670","0.03063"
"71.28000","5.94015","0.03044"
"71.44200","5.95372","0.02979"
"71.60400","5.96717","0.02985"
"71.76600","5.98063","0.02991"
"71.92800","5.99420","0.03050"
"72.09000","6.00771","0.03018"
"72.25200","6.02116","0.03019"
"72.41400","6.03462","0.02992"
"72.57600","6.04819","0.03010"
"72.73800","6.06164","0.03023"
"72.90000","6.07515","0.03066"
"73.06200","6.08873","0.03021"
"73.22400","6.10224","0.03047"
"73.38600","6.11569","0.03058"
"73.54800","6.12920","0.03087"
"73.71000","6.14272","0.02996"
"73.87200","6.15617","0.03025"
"74.03400","6.16968","0.03040"
"74.19600","6.18319","0.03024"
"74.35800","6.19671","0.03014"
"74.52000","6.21022","0.03050"
"74.68200","6.22373","0.03022"
"74.84400","6.23718","0.03049"
"75.00600","6.25064","0.03061"
"75.16800","6.26421","0.03069"
"75.33000","6.27766","0.03090"
"75.49200","6.29117","0.03072"
"75.65400","6.30469","0.03082"
"75.81600","6.31820","0.03098"
"75.97800","6.33171","0.03073"
"76.14000","6.34516","0.03132"
"76.30200","6.35868","0.03172"
"76.46400","6.37213","0.03205"
"76.62600","6.38564","0.03112"
"76.78800","6.39921","0.03202"
"76.95000","6.41267","0.03185"
"77.11200","6.42618","0.03202"
"77.27400","6.43969","0.03132"
"77.43600","6.45320","0.03173"
"77.59800","6.46666","0.03153"
"77.76000","6.48017","0.03204"
"77.92200","6.49368","0.03230"
"78.08400","6.50725","0.03196"
"78.24600","6.52071","0.03210"
"78.40800","6.53428","0.03190"
"78.57000","6.54773","0.03220"
"78.73200","6.56112","0.03242"
"78.89400","6.57470","0.03217"
"79.05600","6.58821","0.03245"
"79.21800","6.60166","0.03276"
"79.38000","6.61517","0.03294"
"79.54200","6.62869","0.03288"
"79.70400","6.64220","0.03341"
"79.86600","6.65559","0.03317"
"80.02800","6.66922","0.03295"
"80.19000","6.68268","0.03347"
"80.35200","6.69619","0.03319"
"80.51400","6.70970","0.03346"
"80.67600","6.72321","0.03340"
"80.83800","6.73661","0.03416"
"81.00000","6.75018","0.03342"
"81.16200","6.76369","0.03368"
"81.32400","6.77720","0.03445"
"81.48600","6.79060","0.03416"
"81.64800","6.80417","0.03413"
"81.81000","6.81774","0.03377"
"81.97200","6.83119","0.03403"
"82.13400","6.84471","0.03407"
"82.29600","6.85828","0.03447"
"82.45800","6.87161","0.03412"
"82.62000","6.88518","0.03507"
"82.78200","6.89864","0.03452"
"82.94400","6.91215","0.03459"
"83.10600","6.92566","0.03502"
"83.26800","6.93923","0.03495"
"83.43000","6.95275","0.03457"
"83.59200","6.96620","0.03484"
"83.75400","6.97971","0.03501"
"83.91600","6.99316","0.03495"
"84.07800","7.00668","0.03500"
"84.24000","7.02019","0.03522"
"84.40200","7.03370","0.03558"
"84.56400","7.04721","0.03534"
"84.72600","7.06067","0.03554"
"84.88800","7.07424","0.03635"
"85.05000","7.08769","0.03565"
"85.21200","7.10108","0.03577"
"85.37400","7.11472","0.03637"
"85.53600","7.12817","0.03639"
"85.69800","7.14168","0.03652"
"85.86000","7.15519","0.03547"
"86.02200","7.16871","0.03525"
"86.18400","7.18216","0.03631"
"86.34600","7.19567","0.03604"
"86.50800","7.20918","0.03698"
"86.67000","7.22270","0.03624"
"86.83200","7.23609","0.03654"
"86.99400","7.24978","0.03660"
"87.15600","7.26317","0.03707"
"87.31800","7.27668","0.03706"
"87.48000","7.29020","0.03627"
"87.64200","7.30365","0.03751"
"87.80400","7.31716","0.03569"
"87.96600","7.33062","0.03734"
"88.12800","7.34425","0.03699"
"88.29000","7.35770","0.03717"
"88.45200","7.37109","0.03719"
"88.61400","7.38473","0.03742"
"88.77600","7.39824","0.03774"
"88.93800","7.41169","0.03783"
"89.10000","7.42514","0.03795"
"89.26200","7.43871","0.03755"
"89.42400","7.45217","0.03833"
"89.58600","7.46568","0.03792"
"89.74800","7.47919","0.03825"
"89.91000","7.49270","0.03864"
"90.07200","7.50610","0.03859"
"90.23400","7.51973","0.03905"
"90.39600","7.53324","0.03887"
"90.55800","7.54663","0.03884"
"90.72000","7.56021","0.03997"
"90.88200","7.57372","0.03999"
"91.04400","7.58723","0.03955"
"91.20600","7.60063","0.04041"
"91.36800","7.61420","0.04079"
"91.53000","7.62765","0.04024"
"91.69200","7.64110","0.04023"
"91.85400","7.65474","0.04102"
"92.01600","7.66819","0.04071"
"92.17800","7.68164","0.04128"
"92.34000","7.69521","0.04108"
"92.50200","7.70872","0.04172"
"92.66400","7.72224","0.04150"
"92.82600","7.73569","0.04185"
"92.98800","7.74920","0.04222"
"93.15000","7.76271","0.04279"
"93.31200","7.77617","0.04255"
"93.47400","7.78974","0.04258"
"93.63600","7.80319","0.04276"
"93.79800","7.81664","0.04285"
"93.96000","7.83022","0.04335"
"94.12200","7.84373","0.04335"
"94.28400","7.85718","0.04452"
"94.44600","7.87069","0.04386"
"94.60800","7.88427","0.04448"
"94.77000","7.89772","0.04379"
"94.93200","7.91117","0.04419"
"95.09400","7.92474","0.04449"
"95.25600","7.93820","0.04470"
"95.41800","7.95159","0.04532"
"95.58000","7.96516","0.04567"
"95.74200","7.97873","0.04549"
"95.90400","7.99213","0.04573"
"96.06600","8.00570","0.04602"
"96.22800","8.01921","0.04582"
"96.39000","8.03272","0.04555"
"96.55200","8.04618","0.04551"
"96.71400","8.05969","0.04601"
"96.87600","8.07320","0.04574"
"97.03800","8.08665","0.04691"
"97.20000","8.10023","0.04669"
"97.36200","8.11374","0.04694"
"97.52400","8.12719","0.04693"
"97.68600","8.14070","0.04686"
"97.84800","8.15422","0.04685"
"98.01000","8.16767","0.04676"
"98.17200","8.18118","0.04811"
"98.33400","8.19475","0.04869"
"98.49600","8.20821","0.04801"
"98.65800","8.22166","0.04802"
"98.82000","8.23523","0.04837"
"98.98200","8.24868","0.04871"
"99.14400","8.26214","0.04903"
"99.30600","8.27571","0.04900"
"99.46800","8.28922","0.04849"
"99.63000","8.30267","0.04914"
"99.79200","8.31619","0.04923"
"99.95400","8.32970","0.04885"
"100.11600","8.34327","0.04936"
"100.27800","8.35660","0.04976"
"100.44000","8.37018","0.05037"
"100.60200","8.38369","0.04958"
"100.76400","8.39720","0.05006"
"100.92600","8.41071","0.05016"
"101.08800","8.42417","0.05077"
"101.25000","8.43768","0.05065"
"101.41200","8.45113","0.05056"
"101.57400","8.46470","0.05129"
"101.73600","8.47822","0.05183"
"101.89800","8.49167","0.05204"
"102.06000","8.50524","0.05163"
"102.22200","8.51869","0.05217"
"102.38400","8.53215","0.05184"
"102.54600","8.54566","0.05266"
"102.70800","8.55917","0.05281"
"102.87000","8.57262","0.05253"
"103.03200","8.58614","0.05256"
"103.19400","8.59971","0.05257"
"103.35600","8.61322","0.05299"
"103.51800","8.62661","0.05333"
"103.68000","8.64025","0.05351"
"103.84200","8.65376","0.05353"
"104.00400","8.66721","0.05400"
"104.16600","8.68072","0.05372"
"104.32800","8.69418","0.05422"
"104.49000","8.70769","0.05487"
"104.65200","8.72120","0.05459"
"104.81400","8.73471","0.05439"
"104.97600","8.74828","0.05458"
"105.13800","8.76168","0.05522"
"105.30000","8.77525","0.05529"
"105.46200","8.78870","0.05544"
"105.62400","8.80216","0.05516"
"105.78600","8.81573","0.05546"
"105.94800","8.82924","0.05544"
"106.11000","8.84269","0.05590"
"106.27200","8.85620","0.05548"
"106.43400","8.86966","0.05549"
"106.59600","8.88317","0.05635"
"106.75800","8.89662","0.05582"
"106.92000","8.91020","0.05605"
"107.08200","8.92377","0.05652"
"107.24400","8.93722","0.05640"
"107.40600","8.95067","0.05675"
"107.56800","8.96424","0.05681"
"107.73000","8.97770","0.05685"
"107.89200","8.99121","0.05686"
"108.05400","9.00466","0.05718"
"108.21600","9.01824","0.05745"
"108.37800","9.03169","0.05798"
"108.54000","9.04520","0.05739"
"108.70200","9.05871","0.05791"
"108.86400","9.07211","0.05794"
"109.02600","9.08574","0.05804"
"109.18800","9.09919","0.05781"
"109.35000","9.11270","0.05821"
"109.51200","9.12621","0.05867"
"109.67400","9.13973","0.05842"
"109.83600","9.15318","0.05862"
"109.99800","9.16669","0.05842"
"110.16000","9.18026","0.05879"
"110.32200","9.19366","0.05893"
"110.48400","9.20717","0.05893"
"110.64600","9.22068","0.05917"
"110.80800","9.23419","0.05878"
"110.97000","9.24771","0.05889"
"111.13200","9.26116","0.05877"
"111.29400","9.27467","0.05899"
"111.45600","9.28818","0.05907"
"111.61800","9.30164","0.05894"
"111.78000","9.31521","0.05953"
"111.94200","9.32872","0.05990"
"112.10400","9.34217","0.05932"
"112.26600","9.35575","0.05990"
"112.42800","9.36926","0.05977"
"112.59000","9.38271","0.06023"
"112.75200","9.39622","0.06036"
"112.91400","9.40974","0.06004"
"113.07600","9.42319","0.06048"
"113.23800","9.43664","0.06069"
"113.40000","9.45021","0.06064"
"113.56200","9.46373","0.06100"
"113.72400","9.47718","0.06097"
"113.88600","9.49069","0.06137"
"114.04800","9.50420","0.06119"
"114.21000","9.51766","0.06126"
"114.37200","9.53117","0.06162"
"114.53400","9.54474","0.06139"
"114.69600","9.55825","0.06159"
"114.85800","9.57171","0.06164"
"115.02000","9.58522","0.06194"
"115.18200","9.59873","0.06206"
"115.34400","9.61212","0.06187"
"115.50600","9.62564","0.06223"
"115.66800","9.63921","0.06244"
"115.83000","9.65266","0.06249"
"115.99200","9.66623","0.06246"
"116.15400","9.67975","0.06293"
"116.31600","9.69314","0.06234"
"116.47800","9.70671","0.06327"
"116.64000","9.72022","0.06333"
"116.80200","9.73374","0.06358"
"116.96400","9.74713","0.06359"
"117.12600","9.76070","0.06392"
"117.28800","9.77421","0.06416"
"117.45000","9.78767","0.06435"
"117.61200","9.80118","0.06497"
"117.77400","9.81469","0.06455"
"117.93600","9.82820","0.06511"
"118.09800","9.84166","0.06540"
"118.26000","9.85523","0.06554"
"118.42200","9.86874","0.06561"
"118.58400","9.88219","0.06602"
"118.74600","9.89570","0.06604"
"118.90800","9.90922","0.06634"
"119.07000","9.92267","0.06696"
"119.23200","9.93618","0.06711"
"119.39400","9.94964","0.06765"
"119.55600","9.96315","0.06768"
"119.71800","9.97666","0.06819"
"119.88000","9.99023","0.06837"
"120.04200","10.00369","0.06810"
"120.20400","10.01720","0.06917"
"120.36600","10.03071","0.06934"
"120.52800","10.04422","0.06992"
"120.69000","10.05767","0.07027"
"120.85200","10.07119","0.07055"
"121.01400","10.08470","0.07063"
"121.17600","10.09815","0.07127"
"121.33800","10.11167","0.07142"
"121.50000","10.12518","0.07188"
"121.66200","10.13869","0.07237"
"121.82400","10.15208","0.07325"
"121.98600","10.16572","0.07354"
"122.14800","10.17923","0.07406"
"122.31000","10.19268","0.07457"
"122.47200","10.20619","0.07491"
"122.63400","10.21971","0.07509"
"122.79600","10.23322","0.07543"
"122.95800","10.24667","0.07595"
"123.12000","10.26024","0.07603"
"123.28200","10.27369","0.07590"
"123.44400","10.28715","0.07449"
"123.60600","10.30072","0.07457"
"123.76800","10.31423","0.07470"
"123.93000","10.32763","0.07416"
"124.09200","10.34120","0.07360"
"124.25400","10.35471","0.07326"
"124.41600","10.36822","0.07046"
"124.57800","10.38168","0.07145"
"124.74000","10.39519","0.07215"
"124.90200","10.40870","0.07260"
"125.06400","10.42215","0.07327"
"125.22600","10.43572","0.07370"
"125.38800","10.44918","0.07477"
"125.55000","10.46263","0.07553"
"125.71200","10.47620","0.07567"
"125.87400","10.48972","0.07621"
"126.03600","10.50317","0.07724"
"126.19800","10.51668","0.07760"
"126.36000","10.53019","0.07808"
"126.52200","10.54370","0.07793"
"126.68400","10.55710","0.07764"
"126.84600","10.57073","0.07825"
"127.00800","10.58418","0.07945"
"127.17000","10.59769","0.07983"
"127.33200","10.61121","0.08056"
"127.49400","10.62472","0.08057"
"127.65600","10.63817","0.08187"
"127.81800","10.65169","0.08253"
"127.98000","10.66520","0.08284"
"128.14200","10.67865","0.08399"
"128.30400","10.69216","0.08430"
"128.46600","10.70568","0.08485"
"128.62800","10.71919","0.08601"
"128.79000","10.73270","0.08569"
"128.95200","10.74615","0.08636"
"129.11400","10.75966","0.08714"
"129.27600","10.77312","0.08726"
"129.43800","10.78669","0.08816"
"129.60000","10.80020","0.08857"
"129.76200","10.81371","0.08875"
"129.92400","10.82717","0.08931"
"130.08600","10.84074","0.08984"
"130.24800","10.85419","0.08931"
"130.41000","10.86758","0.08762"
"130.57200","10.88122","0.08849"
"130.73400","10.89473","0.08874"
"130.89600","10.90818","0.08955"
"131.05800","10.92169","0.09021"
"131.22000","10.93521","0.09051"
"131.38200","10.94866","0.09118"
"131.54400","10.96211","0.09181"
"131.70600","10.97574","0.09241"
"131.86800","10.98920","0.09268"
"132.03000","11.00265","0.09347"
"132.19200","11.01622","0.09385"
"132.35400","11.02967","0.09415"
"132.51600","11.04313","0.09438"
"132.67800","11.05664","0.09463"
"132.84000","11.07021","0.09581"
"133.00200","11.08366","0.09598"
"133.16400","11.09718","0.09602"
"133.32600","11.11075","0.09686"
"133.48800","11.12420","0.09735"
"133.65000","11.13765","0.09824"
"133.81200","11.15123","0.09842"
"133.97400","11.16474","0.09873"
"134.13600","11.17819","0.09961"
"134.29800","11.19164","0.09987"
"134.46000","11.20522","0.10044"
"134.62200","11.21867","0.10116"
"134.78400","11.23218","0.10129"
"134.94600","11.24575","0.10201"
"135.10800","11.25921","0.10281"
"135.27000","11.27266","0.10276"
"135.43200","11.28617","0.10382"
"135.59400","11.29968","0.10324"
"135.75600","11.31320","0.10408"
"135.91800","11.32671","0.10456"
"136.08000","11.34022","0.10457"
"136.24200","11.35367","0.10111"
"136.40400","11.36718","0.10229"
"136.56600","11.38070","0.10223"
"136.72800","11.39415","0.10276"
"136.89000","11.40760","0.10360"
"137.05200","11.42124","0.10394"
"137.21400","11.43475","0.10432"
"137.37600","11.44820","0.10465"
"137.53800","11.46171","0.10513"
"137.70000","11.47523","0.10523"
"137.86200","11.48868","0.10555"
"138.02400","11.50219","0.10597"
"138.18600","11.51570","0.10543"
"138.34800","11.52922","0.10570"
"138.51000","11.54267","0.10641"
"138.67200","11.55624","0.10712"
"138.83400","11.56969","0.10734"
"138.99600","11.58309","0.10773"
"139.15800","11.59672","0.10797"
"139.32000","11.61017","0.10801"
"139.48200","11.62362","0.10831"
"139.64400","11.63720","0.10863"
"139.80600","11.65077","0.10865"
"139.96800","11.66416","0.10867"
"140.13000","11.67761","0.10895"
"140.29200","11.69125","0.10948"
"140.45400","11.70470","0.10856"
"140.61600","11.71815","0.10882"
"140.77800","11.73166","0.10899"
"140.94000","11.74523","0.10892"
"141.10200","11.75863","0.10881"
"141.26400","11.77214","0.10947"
"141.42600","11.78571","0.10947"
"141.58800","11.79922","0.10985"
"141.75000","11.81262","0.11044"
"141.91200","11.82619","0.11071"
"142.07400","11.83970","0.11054"
"142.23600","11.85316","0.11092"
"142.39800","11.86673","0.11121"
"142.56000","11.88024","0.11165"
"142.72200","11.89369","0.11201"
"142.88400","11.90715","0.11178"
"143.04600","11.92066","0.11214"
"143.20800","11.93417","0.11266"
"143.37000","11.94762","0.11259"
"143.53200","11.96126","0.11336"
"143.69400","11.97471","0.11377"
"143.85600","11.98816","0.11448"
"144.01800","12.00173","0.11431"
"144.18000","12.01518","0.11553"
"144.34200","12.02870","0.11589"
"144.50400","12.04215","0.11571"
"144.66600","12.05572","0.11629"
"144.82800","12.06923","0.11749"
"144.99000","12.08269","0.11754"
"145.15200","12.09620","0.11789"
"145.31400","12.10965","0.11895"
"145.47600","12.12317","0.11905"
"145.63800","12.13674","0.12017"
"145.80000","12.15019","0.12089"
"145.96200","12.16370","0.12192"
"146.12400","12.17721","0.12340"
"146.28600","12.19073","0.12348"
"146.44800","12.20418","0.12362"
"146.61000","12.21769","0.12459"
"146.77200","12.23120","0.12487"
"146.93400","12.24472","0.12231"
"147.09600","12.25811","0.12233"
"147.25800","12.27180","0.12384"
"147.42000","12.28520","0.12424"
"147.58200","12.29865","0.12454"
"147.74400","12.31216","0.12573"
"147.90600","12.32573","0.12613"
"148.06800","12.33918","0.12699"
"148.23000","12.35264","0.12787"
"148.39200","12.36627","0.12959"
"148.55400","12.37972","0.12966"
"148.71600","12.39311","0.13025"
"148.87800","12.40675","0.13167"
"149.04000","12.42020","0.13203"
"149.20200","12.43371","0.13244"
"149.36400","12.44722","0.13252"
"149.52600","12.46068","0.13363"
"149.68800","12.47419","0.13470"
"149.85000","12.48770","0.13466"
"150.01200","12.50121","0.13564"
"150.17400","12.51473","0.13636"
"150.33600","12.52818","0.13684"
"150.49800","12.54169","0.13767"
"150.66000","12.55520","0.13775"
"150.82200","12.56866","0.13824"
"150.98400","12.58223","0.13839"
"151.14600","12.59574","0.13945"
"151.30800","12.60919","0.13957"
"151.47000","12.62271","0.14023"
"151.63200","12.63616","0.14059"
"151.79400","12.64973","0.13940"
"151.95600","12.66312","0.13960"
"152.11800","12.67676","0.14023"
"152.28000","12.69021","0.14045"
"152.44200","12.70366","0.14113"
"152.60400","12.71717","0.14107"
"152.76600","12.73069","0.14188"
"152.92800","12.74420","0.14276"
"153.09000","12.75771","0.14303"
"153.25200","12.77122","0.14318"
"153.41400","12.78474","0.14344"
"153.57600","12.79819","0.14386"
"153.73800","12.81176","0.14418"
"153.90000","12.82515","0.14439"
"154.06200","12.83867","0.14451"
"154.22400","12.85218","0.14495"
"154.38600","12.86569","0.14522"
"154.54800","12.87914","0.14616"
"154.71000","12.89272","0.14619"
"154.87200","12.90623","0.14606"
"155.03400","12.91974","0.14482"
"155.19600","12.93313","0.14466"
"155.35800","12.94677","0.14453"
"155.52000","12.96022","0.14526"
"155.68200","12.97361","0.14550"
"155.84400","12.98718","0.14596"
"156.00600","13.00070","0.14667"
"156.16800","13.01421","0.14692"
"156.33000","13.02772","0.14766"
"156.49200","13.04123","0.14770"
"156.65400","13.05475","0.14817"
"156.81600","13.06814","0.14855"
"156.97800","13.08171","0.14874"
"157.14000","13.09516","0.14883"
"157.30200","13.10862","0.14941"
"157.46400","13.12225","0.14989"
"157.62600","13.13570","0.15009"
"157.78800","13.14915","0.15054"
"157.95000","13.16267","0.15072"
"158.11200","13.17618","0.15118"
"158.27400","13.18963","0.15086"
"158.43600","13.20314","0.15036"
"158.59800","13.21671","0.15071"
"158.76000","13.23029","0.15046"
"158.92200","13.24362","0.15114"
"159.08400","13.25719","0.15168"
"159.24600","13.27071","0.15188"
"159.40800","13.28416","0.15215"
"159.57000","13.29767","0.15273"
"159.73200","13.31124","0.15282"
"159.89400","13.32469","0.15350"
"160.05600","13.33821","0.15387"
"160.21800","13.35166","0.15405"
"160.38000","13.36517","0.15449"
"160.54200","13.37863","0.15458"
"160.70400","13.39220","0.15479"
"160.86600","13.40571","0.15532"
"161.02800","13.41916","0.15526"
"161.19000","13.43274","0.15591"
"161.35200","13.44625","0.15609"
"161.51400","13.45970","0.15675"
"161.67600","13.47321","0.15698"
"161.83800","13.48672","0.15711"
"162.00000","13.50024","0.15754"
"162.16200","13.51363","0.15778"
"162.32400","13.52720","0.15837"
"162.48600","13.54072","0.15881"
"162.64800","13.55417","0.15928"
"162.81000","13.56774","0.15933"
"162.97200","13.58119","0.16001"
"163.13400","13.59465","0.16024"
"163.29600","13.60816","0.16092"
"163.45800","13.62173","0.16106"
"163.62000","13.63524","0.16137"
"163.78200","13.64863","0.16279"
"163.94400","13.66221","0.15960"
"164.10600","13.67572","0.16041"
"164.26800","13.68917","0.16041"
"164.43000","13.70268","0.16126"
"164.59200","13.71620","0.16156"
"164.75400","13.72965","0.16180"
"164.91600","13.74316","0.16244"
"165.07800","13.75673","0.16291"
"165.24000","13.77019","0.16409"
"165.40200","13.78358","0.16393"
"165.56400","13.79721","0.16493"
"165.72600","13.81072","0.16568"
"165.88800","13.82418","0.16609"
"166.05000","13.83775","0.16693"
"166.21200","13.85126","0.16852"
"166.37400","13.86472","0.16854"
"166.53600","13.87817","0.16971"
"166.69800","13.89168","0.17067"
"166.86000","13.90513","0.17166"
"167.02200","13.91858","0.17162"
"167.18400","13.93216","0.17300"
"167.34600","13.94573","0.17370"
"167.50800","13.95918","0.17556"
"167.67000","13.97269","0.17672"
"167.83200","13.98621","0.17782"
"167.99400","13.99966","0.17878"
"168.15600","14.01317","0.17936"
"168.31800","14.02668","0.18075"
"168.48000","14.04020","0.18287"
"168.64200","14.05365","0.18333"
"168.80400","14.06722","0.18432"
"168.96600","14.08074","0.18598"
"169.12800","14.09419","0.18613"
"169.29000","14.10770","0.18873"
"169.45200","14.12121","0.18946"
"169.61400","14.13466","0.19120"
"169.77600","14.14818","0.19246"
"169.93800","14.16169","0.19252"
"170.10000","14.17520","0.19500"
"170.26200","14.18865","0.19651"
"170.42400","14.20223","0.19798"
"170.58600","14.21568","0.19895"
"170.74800","14.22913","0.19985"
"170.91000","14.24271","0.20041"
"171.07200","14.25622","0.20283"
"171.23400","14.26973","0.20412"
"171.39600","14.28324","0.20516"
"171.55800","14.29669","0.20625"
"171.72000","14.31015","0.20763"
"171.88200","14.32366","0.20831"
"172.04400","14.33717","0.20924"
"172.20600","14.35068","0.21052"
"172.36800","14.36414","0.21101"
"172.53000","14.37771","0.21129"
"172.69200","14.39122","0.21129"
"172.85400","14.40461","0.21225"
"173.01600","14.41819","0.21265"
"173.17800","14.43164","0.21332"
"173.34000","14.44515","0.21375"
"173.50200","14.45860","0.21402"
"173.66400","14.47224","0.21498"
"173.82600","14.48575","0.21499"
"173.98800","14.49914","0.21521"
"174.15000","14.51271","0.21590"
"174.31200","14.52623","0.21672"
"174.47400","14.53968","0.21720"
"174.63600","14.55313","0.21765"
"174.79800","14.56670","0.21773"
"174.96000","14.58022","0.21858"
"175.12200","14.59367","0.21910"
"175.28400","14.60724","0.21966"
"175.44600","14.62069","0.22001"
"175.60800","14.63415","0.22068"
"175.77000","14.64766","0.22210"
"175.93200","14.66123","0.22183"
"176.09400","14.67468","0.22336"
"176.25600","14.68820","0.22428"
"176.41800","14.70171","0.22543"
"176.58000","14.71516","0.22642"
"176.74200","14.72867","0.22688"
"176.90400","14.74219","0.22831"
"177.06600","14.75570","0.22761"
"177.22800","14.76915","0.22825"
"177.39000","14.78272","0.23003"
"177.55200","14.79624","0.23102"
"177.71400","14.80963","0.23315"
"177.87600","14.82320","0.23360"
"178.03800","14.83671","0.23420"
"178.20000","14.85017","0.23561"
"178.36200","14.86362","0.23667"
"178.52400","14.87725","0.23729"
"178.68600","14.89070","0.23884"
"178.84800","14.90416","0.23903"
"179.01000","14.91773","0.24012"
"179.17200","14.93118","0.24143"
"179.33400","14.94469","0.24160"
"179.49600","14.95820","0.24327"
"179.65800","14.97172","0.24372"
"179.82000","14.98517","0.24472"
"179.98200","14.99868","0.24607"
"180.14400","15.01220","0.24673"
"180.30600","15.02565","0.24798"
"180.46800","15.03916","0.24885"
"180.63000","15.05267","0.24976"
"180.79200","15.06625","0.24991"
"180.95400","15.07964","0.25148"
"181.11600","15.09321","0.25222"
"181.27800","15.10666","0.25278"
"181.44000","15.12018","0.25341"
"181.60200","15.13369","0.25402"
"181.76400","15.14720","0.25450"
"181.92600","15.16071","0.25519"
"182.08800","15.17417","0.25588"
"182.25000","15.18774","0.25647"
"182.41200","15.20119","0.25707"
"182.57400","15.21464","0.25713"
"182.73600","15.22821","0.25796"
"182.89800","15.24167","0.25859"
"183.06000","15.25518","0.25869"
"183.22200","15.26863","0.25858"
"183.38400","15.28220","0.25920"
"183.54600","15.29566","0.25934"
"183.70800","15.30917","0.25961"
"183.87000","15.32274","0.24791"
"184.03200","15.33620","0.24552"
"184.19400","15.34965","0.24685"
"184.35600","15.36316","0.24715"
"184.51800","15.37667","0.24922"
"184.68000","15.39013","0.24953"
"184.84200","15.40364","0.25048"
"185.00400","15.41721","0.25164"
"185.16600","15.43072","0.25189"
"185.32800","15.44417","0.25370"
"185.49000","15.45775","0.25438"
"185.65200","15.47126","0.25477"
"185.81400","15.48465","0.25591"
"185.97600","15.49817","0.25637"
"186.13800","15.51174","0.25680"
"186.30000","15.52519","0.25743"
"186.46200","15.53870","0.25751"
"186.62400","15.55222","0.25797"
"186.78600","15.56573","0.25844"
"186.94800","15.57912","0.25844"
"187.11000","15.59269","0.25897"
"187.27200","15.60614","0.25906"
"187.43400","15.61972","0.25985"
"187.59600","15.63317","0.25999"
"187.75800","15.64674","0.26075"
"187.92000","15.66019","0.26097"
"188.08200","15.67365","0.26144"
"188.24400","15.68722","0.26159"
"188.40600","15.70061","0.26157"
"188.56800","15.71412","0.26142"
"188.73000","15.72776","0.26160"
"188.89200","15.74115","0.26194"
"189.05400","15.75466","0.26234"
"189.21600","15.76823","0.26259"
"189.37800","15.78174","0.26342"
"189.54000","15.79514","0.26348"
"189.70200","15.80871","0.26405"
"189.86400","15.82222","0.26454"
"190.02600","15.83574","0.26480"
"190.18800","15.84919","0.26517"
"190.35000","15.86276","0.26611"
"190.51200","15.87615","0.26629"
"190.67400","15.88966","0.26667"
"190.83600","15.90318","0.26726"
"190.99800","15.91669","0.26833"
"191.16000","15.93020","0.26871"
"191.32200","15.94372","0.26965"
"191.48400","15.95729","0.27036"
"191.64600","15.97068","0.27075"
"191.80800","15.98413","0.27173"
"191.97000","15.99771","0.27322"
"192.13200","16.01122","0.27391"
"192.29400","16.02467","0.27542"
"192.45600","16.03818","0.27582"
"192.61800","16.05169","0.27746"
"192.78000","16.06515","0.27859"
"192.94200","16.07866","0.27933"
"193.10400","16.09229","0.28024"
"193.26600","16.10569","0.28149"
"193.42800","16.11920","0.28276"
"193.59000","16.13271","0.28401"
"193.75200","16.14622","0.28489"
"193.91400","16.15968","0.28550"
"194.07600","16.17319","0.28709"
"194.23800","16.18670","0.28869"
"194.40000","16.20021","0.28959"
"194.56200","16.21367","0.29064"
"194.72400","16.22718","0.29176"
"194.88600","16.24069","0.29283"
"195.04800","16.25420","0.29499"
"195.21000","16.26772","0.29664"
"195.37200","16.28123","0.29689"
"195.53400","16.29468","0.29854"
"195.69600","16.30819","0.29893"
"195.85800","16.32165","0.30044"
"196.02000","16.33516","0.30084"
"196.18200","16.34867","0.30298"
"196.34400","16.36218","0.30381"
"196.50600","16.37569","0.30544"
"196.66800","16.38921","0.30630"
"196.83000","16.40272","0.30680"
"196.99200","16.41617","0.30801"
"197.15400","16.42962","0.30849"
"197.31600","16.44314","0.30947"
"197.47800","16.45665","0.30997"
"197.64000","16.47016","0.31088"
"197.80200","16.48368","0.31174"
"197.96400","16.49719","0.31345"
"198.12600","16.51070","0.31357"
"198.28800","16.52421","0.31476"
"198.45000","16.53772","0.31628"
"198.61200","16.55118","0.31724"
"198.77400","16.56463","0.31859"
"198.93600","16.57826","0.32066"
"199.09800","16.59171","0.32278"
"199.26000","16.60517","0.32392"
"199.42200","16.61868","0.32591"
"199.58400","16.63219","0.32649"
"199.74600","16.64565","0.32956"
"199.90800","16.65916","0.33252"
"200.07000","16.67273","0.33407"
"200.23200","16.68618","0.33554"
"200.39400","16.69963","0.33691"
"200.55600","16.71327","0.33965"
"200.71800","16.72672","0.34192"
"200.88000","16.74017","0.34317"
"201.04200","16.75368","0.34588"
"201.20400","16.76720","0.34711"
"201.36600","16.78071","0.34954"
"201.52800","16.79422","0.35069"
"201.69000","16.80767","0.35324"
"201.85200","16.82119","0.35436"
"202.01400","16.83464","0.35600"
"202.17600","16.84821","0.35738"
"202.33800","16.86172","0.35882"
"202.50000","16.87518","0.36032"
"202.66200","16.88875","0.36130"
"202.82400","16.90226","0.36190"
"202.98600","16.91566","0.36325"
"203.14800","16.92917","0.36421"
"203.31000","16.94268","0.36528"
"203.47200","16.95619","0.36589"
"203.63400","16.96964","0.36664"
"203.79600","16.98328","0.36693"
"203.95800","16.99673","0.36765"
"204.12000","17.01018","0.36805"
"204.28200","17.02369","0.36832"
"204.44400","17.03721","0.36880"
"204.60600","17.05066","0.36908"
"204.76800","17.06417","0.36937"
"204.93000","17.07768","0.36956"
"205.09200","17.09120","0.36983"
"205.25400","17.10465","0.36999"
"205.41600","17.11822","0.37056"
"205.57800","17.13167","0.37062"
"205.74000","17.14513","0.37092"
"205.90200","17.15870","0.37128"
"206.06400","17.17221","0.37141"
"206.22600","17.18566","0.37162"
"206.38800","17.19918","0.37219"
"206.55000","17.21269","0.37296"
"206.71200","17.22614","0.37341"
"206.87400","17.23965","0.37344"
"207.03600","17.25323","0.37426"
"207.19800","17.26668","0.37454"
"207.36000","17.28013","0.37522"
"207.52200","17.29376","0.37597"
"207.68400","17.30722","0.37590"
"207.84600","17.32067","0.37638"
"208.00800","17.33418","0.37697"
"208.17000","17.34769","0.37752"
"208.33200","17.36121","0.37882"
"208.49400","17.37466","0.37925"
"208.65600","17.38817","0.37986"
"208.81800","17.40174","0.38052"
"208.98000","17.41514","0.38161"
"209.14200","17.42877","0.38295"
"209.30400","17.44222","0.38368"
"209.46600","17.45567","0.38521"
"209.62800","17.46919","0.38638"
"209.79000","17.48276","0.38704"
"209.95200","17.49615","0.38857"
"210.11400","17.50966","0.39031"
"210.27600","17.52317","0.39141"
"210.43800","17.53669","0.39249"
"210.60000","17.55014","0.39448"
"210.76200","17.56371","0.39606"
"210.92400","17.57722","0.39731"
"211.08600","17.59068","0.39870"
"211.24800","17.60419","0.40096"
"211.41000","17.61776","0.40255"
"211.57200","17.63116","0.40402"
"211.73400","17.64467","0.40590"
"211.89600","17.65818","0.40712"
"212.05800","17.67169","0.40901"
"212.22000","17.68514","0.41077"
"212.38200","17.69872","0.41139"
"212.54400","17.71223","0.41306"
"212.70600","17.72568","0.41410"
"212.86800","17.73919","0.41506"
"213.03000","17.75271","0.41616"
"213.19200","17.76616","0.41691"
"213.35400","17.77967","0.41771"
"213.51600","17.79313","0.41823"
"213.67800","17.80670","0.41907"
"213.84000","17.82015","0.41954"
"214.00200","17.83372","0.42102"
"214.16400","17.84724","0.42199"
"214.32600","17.86069","0.42296"
"214.48800","17.87426","0.42346"
"214.65000","17.88765","0.42449"
"214.81200","17.90117","0.42554"
"214.97400","17.91468","0.42665"
"215.13600","17.92819","0.42855"
"215.29800","17.94170","0.42917"
"215.46000","17.95510","0.43064"
"215.62200","17.96873","0.43268"
"215.78400","17.98218","0.43387"
"215.94600","17.99563","0.43544"
"216.10800","18.00927","0.43662"
"216.27000","18.02266","0.43841"
"216.43200","18.03617","0.43915"
"216.59400","18.04974","0.44084"
"216.75600","18.06319","0.44205"
"216.91800","18.07671","0.44338"
"217.08000","18.09010","0.44460"
"217.24200","18.10373","0.44475"
"217.40400","18.11719","0.44605"
"217.56600","18.13064","0.44692"
"217.72800","18.14421","0.44773"
"217.89000","18.15772","0.44806"
"218.05200","18.17118","0.44911"
"218.21400","18.18463","0.44983"
"218.37600","18.19820","0.45088"
"218.53800","18.21165","0.45151"
"218.70000","18.22516","0.45240"
"218.86200","18.23868","0.45344"
"219.02400","18.25225","0.45372"
"219.18600","18.26564","0.45467"
"219.34800","18.27921","0.45493"
"219.51000","18.29267","0.45587"
"219.67200","18.30612","0.45612"
"219.83400","18.31963","0.45676"
"219.99600","18.33320","0.45725"
"220.15800","18.34672","0.45792"
"220.32000","18.36023","0.45886"
"220.48200","18.37374","0.46035"
"220.64400","18.38720","0.46085"
"220.80600","18.40065","0.46202"
"220.96800","18.41416","0.46243"
"221.13000","18.42767","0.46398"
"221.29200","18.44113","0.46438"
"221.45400","18.45470","0.46568"
"221.61600","18.46815","0.46696"
"221.77800","18.48166","0.46806"
"221.94000","18.49517","0.46902"
"222.10200","18.50875","0.47019"
"222.26400","18.52220","0.47195"
"222.42600","18.53565","0.47284"
"222.58800","18.54922","0.47351"
"222.75000","18.56274","0.47485"
"222.91200","18.57619","0.47595"
"223.07400","18.58964","0.47713"
"223.23600","18.60316","0.47843"
"223.39800","18.61661","0.48004"
"223.56000","18.63018","0.48173"
"223.72200","18.64369","0.48258"
"223.88400","18.65720","0.48394"
"224.04600","18.67066","0.48534"
"224.20800","18.68423","0.48705"
"224.37000","18.69762","0.48896"
"224.53200","18.71113","0.49018"
"224.69400","18.72471","0.49175"
"224.85600","18.73822","0.49345"
"225.01800","18.75167","0.49459"
"225.18000","18.76518","0.49656"
"225.34200","18.77870","0.49780"
"225.50400","18.79221","0.49917"
"225.66600","18.80566","0.50047"
"225.82800","18.81923","0.50224"
"225.99000","18.83269","0.50342"
"226.15200","18.84614","0.50469"
"226.31400","18.85971","0.50625"
"226.47600","18.87322","0.50758"
"226.63800","18.88668","0.50922"
"226.80000","18.90019","0.51089"
"226.96200","18.91370","0.51199"
"227.12400","18.92722","0.51354"
"227.28600","18.94061","0.51497"
"227.44800","18.95418","0.51533"
"227.61000","18.96775","0.51656"
"227.77200","18.98114","0.51682"
"227.93400","18.99472","0.51768"
"228.09600","19.00823","0.51838"
"228.25800","19.02168","0.51869"
"228.42000","19.03514","0.51805"
"228.58200","19.04865","0.51713"
"228.74400","19.06216","0.51708"
"228.90600","19.07561","0.51766"
"229.06800","19.08918","0.51469"
"229.23000","19.10270","0.51389"
"229.39200","19.11615","0.51442"
"229.55400","19.12972","0.51488"
"229.71600","19.14323","0.51241"
"229.87800","19.15669","0.51274"
"230.04000","19.17020","0.51255"
"230.20200","19.18371","0.49756"
"230.36400","19.19722","0.49769"
"230.52600","19.21068","0.49862"
"230.68800","19.22425","0.49334"
"230.85000","19.23776","0.48739"
"231.01200","19.25115","0.47315"
"231.17400","19.26467","0.47409"
"231.33600","19.27818","0.47504"
"231.49800","19.29169","0.47856"
"231.66000","19.30520","0.48079"
"231.82200","19.31872","0.48161"
"231.98400","19.33217","0.47522"
"232.14600","19.34562","0.47801"
"232.30800","19.35919","0.48085"
"232.47000","19.37271","0.48258"
"232.63200","19.38616","0.48568"
"232.79400","19.39973","0.48818"
"232.95600","19.41324","0.49035"
"233.11800","19.42664","0.13158"
"233.28000","19.44021","0.07338"
"233.44200","19.45372","0.07976"
"233.60400","19.46717","0.08715"
"233.76600","19.48063","0.08084"
"233.92800","19.49426","0.07380"
"234.09000","19.50777","0.09354"
"234.25200","19.52116","0.08177"
"234.41400","19.53473","0.07756"
"234.57600","19.54825","0.09642"
"234.73800","19.56164","0.08067"
"234.90000","19.57515","0.08212"
"235.06200","19.58872","0.09174"
"235.22400","19.60218","0.08451"
"235.38600","19.61569","0.08541"
"235.54800","19.62920","0.09228"
"235.71000","19.64265","0.08811"
"235.87200","19.65611","0.08789"
"236.03400","19.66968","0.09438"
"236.19600","19.68319","0.08890"
"236.35800","19.69670","0.09331"
"236.52000","19.71016","0.09257"
"236.68200","19.72373","0.09083"
"236.84400","19.73718","0.09631"
"237.00600","19.75070","0.09356"
"237.16800","19.76421","0.09264"
"237.33000","19.77772","0.09929"
"237.49200","19.79117","0.09513"
"237.65400","19.80468","0.09031"
"237.81600","19.81826","0.09997"
"237.97800","19.83165","0.09232"
"238.14000","19.84516","0.09360"
"238.30200","19.85868","0.10171"
"238.46400","19.87225","0.09591"
"238.62600","19.88564","0.09564"
"238.78800","19.89921","0.10462"
"238.95000","19.91272","0.09845"
"239.11200","19.92618","0.09910"
"239.27400","19.93975","0.10565"
"239.43600","19.95320","0.10145"
"239.59800","19.96671","0.10334"
"239.76000","19.98017","0.10666"
"239.92200","19.99368","0.10463"
"240.08400","20.00719","0.10644"
"240.24600","20.02070","0.10738"
"240.40800","20.03422","0.10649"
"240.57000","20.04767","0.10893"
"240.73200","20.06112","0.10825"
"240.89400","20.07470","0.10795"
"241.05600","20.08821","0.11049"
"241.20600","20.10064","0.10940"