File: Force_trajectories/170212_1/Specimen_RawData_4.csv
End date,"2/12/2017"
Specimen label,"9AG_77"
Maximum Load,"1.58650",N

Time,Extension,Load
(s),(mm),(N)
"0.00000","0.00000","-0.00044"
"0.37800","0.03157","0.00062"
"0.75600","0.06320","0.00176"
"1.13400","0.09477","0.00255"
"1.51200","0.12616","0.00293"
"1.89000","0.15772","0.00335"
"2.26800","0.18917","0.00366"
"2.64600","0.22068","0.00425"
"3.02400","0.25219","0.00457"
"3.40200","0.28364","0.00538"
"3.78000","0.31521","0.00576"
"4.15800","0.34672","0.00645"
"4.53600","0.37817","0.00630"
"4.91400","0.40974","0.00682"
"5.29200","0.44113","0.00777"
"5.67000","0.47264","0.00751"
"6.04800","0.50421","0.00849"
"6.42600","0.53565","0.00827"
"6.80400","0.56716","0.00948"
"7.18200","0.59873","0.00960"
"7.56000","0.63024","0.01009"
"7.93800","0.66169","0.01030"
"8.31600","0.69326","0.01132"
"8.69400","0.72471","0.01182"
"9.07200","0.75616","0.01201"
"9.45000","0.78773","0.01223"
"9.82800","0.81918","0.01266"
"10.20600","0.85069","0.01236"
"10.58400","0.88213","0.01224"
"10.96200","0.91376","0.01292"
"11.34000","0.94521","0.01386"
"11.71800","0.97666","0.01457"
"12.09600","1.00823","0.01449"
"12.47400","1.03974","0.01465"
"12.85200","1.07113","0.01532"
"13.23000","1.10270","0.01588"
"13.60800","1.13421","0.01552"
"13.98600","1.16566","0.01618"
"14.36400","1.19717","0.01734"
"14.74200","1.22867","0.01672"
"15.12000","1.26018","0.01734"
"15.49800","1.29157","0.01778"
"15.87600","1.32320","0.01796"
"16.25400","1.35477","0.01840"
"16.63200","1.38616","0.01853"
"17.01000","1.41767","0.01830"
"17.38800","1.44924","0.01862"
"17.76600","1.48069","0.01867"
"18.14400","1.51214","0.01870"
"18.52200","1.54377","0.01864"
"18.90000","1.57522","0.01973"
"19.27800","1.60666","0.01966"
"19.65600","1.63823","0.01991"
"20.03400","1.66968","0.02073"
"20.41200","1.70119","0.02090"
"20.79000","1.73270","0.02050"
"21.16800","1.76421","0.02102"
"21.54600","1.79572","0.02153"
"21.92400","1.82717","0.02118"
"22.30200","1.85874","0.02129"
"22.68000","1.89025","0.02257"
"23.05800","1.92164","0.02256"
"23.43600","1.95320","0.02260"
"23.81400","1.98471","0.02276"
"24.19200","2.01616","0.02319"
"24.57000","2.04767","0.02322"
"24.94800","2.07918","0.02294"
"25.32600","2.11069","0.02373"
"25.70400","2.14214","0.02303"
"26.08200","2.17371","0.02325"
"26.46000","2.20522","0.02352"
"26.83800","2.23667","0.02185"
"27.21600","2.26818","0.02084"
"27.59400","2.29968","0.02030"
"27.97200","2.33119","0.01991"
"28.35000","2.36270","0.02131"
"28.72800","2.39421","0.02214"
"29.10600","2.42572","0.02251"
"29.48400","2.45717","0.02261"
"29.86200","2.48874","0.02248"
"30.24000","2.52025","0.02242"
"30.61800","2.55170","0.02215"
"30.99600","2.58321","0.02154"
"31.37400","2.61472","0.02216"
"31.75200","2.64616","0.02305"
"32.13000","2.67767","0.02212"
"32.50800","2.70924","0.02304"
"32.88600","2.74075","0.02319"
"33.26400","2.77214","0.02380"
"33.64200","2.80371","0.02426"
"34.02000","2.83528","0.02465"
"34.39800","2.86667","0.02356"
"34.77600","2.89818","0.01875"
"35.15400","2.92975","0.02181"
"35.53200","2.96114","0.02144"
"35.91000","2.99265","0.02225"
"36.28800","3.02421","0.02239"
"36.66600","3.05572","0.02407"
"37.04400","3.08717","0.02295"
"37.42200","3.11874","0.02397"
"37.80000","3.15019","0.02402"
"38.17800","3.18170","0.02598"
"38.55600","3.21315","0.02503"
"38.93400","3.24466","0.02663"
"39.31200","3.27623","0.02612"
"39.69000","3.30768","0.02702"
"40.06800","3.33919","0.02761"
"40.44600","3.37069","0.02778"
"40.82400","3.40214","0.02768"
"41.20200","3.43371","0.02802"
"41.58000","3.46516","0.02891"
"41.95800","3.49667","0.02870"
"42.33600","3.52818","0.02925"
"42.71400","3.55969","0.02944"
"43.09200","3.59120","0.03025"
"43.47000","3.62265","0.02998"
"43.84800","3.65422","0.03039"
"44.22600","3.68573","0.03059"
"44.60400","3.71718","0.03100"
"44.98200","3.74868","0.03130"
"45.36000","3.78025","0.03122"
"45.73800","3.81164","0.03192"
"46.11600","3.84315","0.03189"
"46.49400","3.87472","0.03234"
"46.87200","3.90623","0.03261"
"47.25000","3.93768","0.03279"
"47.62800","3.96919","0.03303"
"48.00600","4.00070","0.03316"
"48.38400","4.03221","0.03335"
"48.76200","4.06366","0.03369"
"49.14000","4.09522","0.03452"
"49.51800","4.12673","0.03407"
"49.89600","4.15812","0.03468"
"50.27400","4.18969","0.03496"
"50.65200","4.22126","0.03481"
"51.03000","4.25265","0.03550"
"51.40800","4.28422","0.03544"
"51.78600","4.31573","0.03569"
"52.16400","4.34712","0.03595"
"52.54200","4.37875","0.03669"
"52.92000","4.41026","0.03651"
"53.29800","4.44165","0.03703"
"53.67600","4.47315","0.03713"
"54.05400","4.50472","0.03743"
"54.43200","4.53617","0.03813"
"54.81000","4.56768","0.03798"
"55.18800","4.59919","0.03862"
"55.56600","4.63070","0.03915"
"55.94400","4.66221","0.03956"
"56.32200","4.69366","0.04030"
"56.70000","4.72523","0.04042"
"57.07800","4.75668","0.04060"
"57.45600","4.78819","0.04121"
"57.83400","4.81975","0.04161"
"58.21200","4.85120","0.04255"
"58.59000","4.88265","0.04301"
"58.96800","4.91422","0.04302"
"59.34600","4.94573","0.04407"
"59.72400","4.97718","0.04467"
"60.10200","5.00869","0.04539"
"60.48000","5.04020","0.04670"
"60.85800","5.07171","0.04620"
"61.23600","5.10316","0.04641"
"61.61400","5.13473","0.04786"
"61.99200","5.16623","0.04851"
"62.37000","5.19762","0.04957"
"62.74800","5.22919","0.05019"
"63.12600","5.26070","0.05003"
"63.50400","5.29221","0.05085"
"63.88200","5.32372","0.05204"
"64.26000","5.35523","0.05292"
"64.63800","5.38668","0.05368"
"65.01600","5.41819","0.05431"
"65.39400","5.44970","0.05500"
"65.77200","5.48121","0.05514"
"66.15000","5.51271","0.05653"
"66.52800","5.54416","0.05681"
"66.90600","5.57573","0.05751"
"67.28400","5.60724","0.05839"
"67.66200","5.63863","0.05888"
"68.04000","5.67014","0.05912"
"68.41800","5.70171","0.05984"
"68.79600","5.73316","0.06061"
"69.17400","5.76473","0.06163"
"69.55200","5.79624","0.06207"
"69.93000","5.82769","0.06194"
"70.30800","5.85920","0.06262"
"70.68600","5.89070","0.06324"
"71.06400","5.92221","0.06382"
"71.44200","5.95366","0.06503"
"71.82000","5.98523","0.06615"
"72.19800","6.01674","0.06678"
"72.57600","6.04813","0.06736"
"72.95400","6.07970","0.06783"
"73.33200","6.11127","0.06844"
"73.71000","6.14266","0.06926"
"74.08800","6.17417","0.07031"
"74.46600","6.20574","0.07178"
"74.84400","6.23718","0.07247"
"75.22200","6.26869","0.07287"
"75.60000","6.30020","0.07338"
"75.97800","6.33171","0.07416"
"76.35600","6.36316","0.07578"
"76.73400","6.39467","0.07576"
"77.11200","6.42618","0.07712"
"77.49000","6.45775","0.07802"
"77.86800","6.48920","0.07836"
"78.24600","6.52071","0.07833"
"78.62400","6.55222","0.07920"
"79.00200","6.58360","0.07977"
"79.38000","6.61523","0.08040"
"79.75800","6.64668","0.08109"
"80.13600","6.67819","0.08137"
"80.51400","6.70970","0.08162"
"80.89200","6.74115","0.08210"
"81.27000","6.77266","0.08206"
"81.64800","6.80423","0.08236"
"82.02600","6.83568","0.08268"
"82.40400","6.86719","0.08317"
"82.78200","6.89870","0.08346"
"83.16000","6.93015","0.08410"
"83.53800","6.96171","0.08449"
"83.91600","6.99316","0.08499"
"84.29400","7.02467","0.08490"
"84.67200","7.05624","0.08558"
"85.05000","7.08769","0.08655"
"85.42800","7.11914","0.08708"
"85.80600","7.15077","0.08821"
"86.18400","7.18222","0.08834"
"86.56200","7.21367","0.08953"
"86.94000","7.24518","0.09055"
"87.31800","7.27668","0.09138"
"87.69600","7.30814","0.09309"
"88.07400","7.33964","0.09347"
"88.45200","7.37121","0.09544"
"88.83000","7.40272","0.09543"
"89.20800","7.43411","0.09727"
"89.58600","7.46574","0.09864"
"89.96400","7.49725","0.09886"
"90.34200","7.52864","0.09962"
"90.72000","7.56021","0.09908"
"91.09800","7.59172","0.10066"
"91.47600","7.62323","0.10180"
"91.85400","7.65468","0.10343"
"92.23200","7.68618","0.10384"
"92.61000","7.71775","0.10557"
"92.98800","7.74920","0.10571"
"93.36600","7.78071","0.10710"
"93.74400","7.81222","0.10779"
"94.12200","7.84367","0.10811"
"94.50000","7.87518","0.09312"
"94.87800","7.90669","0.09088"
"95.25600","7.93820","0.08857"
"95.63400","7.96971","0.08529"
"96.01200","8.00121","0.08602"
"96.39000","8.03266","0.08704"
"96.76800","8.06411","0.08762"
"97.14600","8.09574","0.08805"
"97.52400","8.12719","0.08920"
"97.90200","8.15870","0.08987"
"98.28000","8.19021","0.09222"
"98.65800","8.22166","0.09005"
"99.03600","8.25317","0.09187"
"99.41400","8.28468","0.09280"
"99.79200","8.31619","0.09464"
"100.17000","8.34775","0.09564"
"100.54800","8.37914","0.09651"
"100.92600","8.41071","0.09847"
"101.30400","8.44222","0.10004"
"101.68200","8.47367","0.10178"
"102.06000","8.50518","0.10310"
"102.43800","8.53675","0.10420"
"102.81600","8.56826","0.10567"
"103.19400","8.59965","0.10683"
"103.57200","8.63122","0.10842"
"103.95000","8.66273","0.10913"
"104.32800","8.69418","0.11044"
"104.70600","8.72568","0.11144"
"105.08400","8.75719","0.11259"
"105.46200","8.78870","0.11391"
"105.84000","8.82015","0.11414"
"106.21800","8.85178","0.11534"
"106.59600","8.88323","0.11602"
"106.97400","8.91468","0.11713"
"107.35200","8.94625","0.11782"
"107.73000","8.97770","0.11832"
"108.10800","9.00915","0.11911"
"108.48600","9.04072","0.11981"
"108.86400","9.07222","0.12088"
"109.24200","9.10367","0.12093"
"109.62000","9.13518","0.12171"
"109.99800","9.16669","0.12254"
"110.37600","9.19820","0.12326"
"110.75400","9.22965","0.12382"
"111.13200","9.26116","0.12463"
"111.51000","9.29273","0.12525"
"111.88800","9.32412","0.12563"
"112.26600","9.35569","0.12613"
"112.64400","9.38720","0.12677"
"113.02200","9.41864","0.12692"
"113.40000","9.45015","0.12727"
"113.77800","9.48172","0.12765"
"114.15600","9.51323","0.12833"
"114.53400","9.54468","0.12838"
"114.91200","9.57619","0.12898"
"115.29000","9.60770","0.12960"
"115.66800","9.63915","0.13011"
"116.04600","9.67066","0.13060"
"116.42400","9.70223","0.13105"
"116.80200","9.73374","0.13174"
"117.18000","9.76519","0.13287"
"117.55800","9.79669","0.13216"
"117.93600","9.82826","0.13289"
"118.31400","9.85965","0.13324"
"118.69200","9.89122","0.13411"
"119.07000","9.92267","0.13523"
"119.44800","9.95418","0.13555"
"119.82600","9.98569","0.13645"
"120.20400","10.01720","0.13766"
"120.58200","10.04871","0.13897"
"120.96000","10.08022","0.14031"
"121.33800","10.11172","0.14191"
"121.71600","10.14323","0.14337"
"122.09400","10.17468","0.14527"
"122.47200","10.20613","0.14652"
"122.85000","10.23776","0.14934"
"123.22800","10.26921","0.15070"
"123.60600","10.30072","0.15263"
"123.98400","10.33223","0.15548"
"124.36200","10.36374","0.15784"
"124.74000","10.39519","0.15789"
"125.11800","10.42670","0.15634"
"125.49600","10.45821","0.15767"
"125.87400","10.48965","0.16176"
"126.25200","10.52116","0.16432"
"126.63000","10.55267","0.16631"
"127.00800","10.58424","0.16917"
"127.38600","10.61563","0.17271"
"127.76400","10.64726","0.17422"
"128.14200","10.67877","0.17660"
"128.52000","10.71010","0.17835"
"128.89800","10.74173","0.18065"
"129.27600","10.77324","0.18277"
"129.65400","10.80463","0.18344"
"130.03200","10.83619","0.18420"
"130.41000","10.86770","0.18529"
"130.78800","10.89915","0.18640"
"131.16600","10.93066","0.18700"
"131.54400","10.96223","0.18760"
"131.92200","10.99368","0.18797"
"132.30000","11.02519","0.18892"
"132.67800","11.05670","0.18981"
"133.05600","11.08821","0.19132"
"133.43400","11.11966","0.18234"
"133.81200","11.15117","0.18353"
"134.19000","11.18274","0.18395"
"134.56800","11.21424","0.18446"
"134.94600","11.24563","0.18562"
"135.32400","11.27720","0.18651"
"135.70200","11.30865","0.18748"
"136.08000","11.34016","0.18759"
"136.45800","11.37173","0.18799"
"136.83600","11.40324","0.18879"
"137.21400","11.43469","0.18956"
"137.59200","11.46620","0.19013"
"137.97000","11.49771","0.19099"
"138.34800","11.52922","0.19199"
"138.72600","11.56067","0.19283"
"139.10400","11.59223","0.19454"
"139.48200","11.62374","0.19510"
"139.86000","11.65513","0.19572"
"140.23800","11.68670","0.19717"
"140.61600","11.71821","0.19864"
"140.99400","11.74972","0.18591"
"141.37200","11.78117","0.18621"
"141.75000","11.81274","0.18531"
"142.12800","11.84425","0.18568"
"142.50600","11.87570","0.18656"
"142.88400","11.90715","0.18770"
"143.26200","11.93871","0.18835"
"143.64000","11.97022","0.18839"
"144.01800","12.00167","0.18886"
"144.39600","12.03324","0.19032"
"144.77400","12.06469","0.19219"
"145.15200","12.09620","0.09646"
"145.53000","12.12771","0.10057"
"145.90800","12.15922","0.09933"
"146.28600","12.19061","0.09883"
"146.66400","12.22224","0.09849"
"147.04200","12.25375","0.09953"
"147.42000","12.28520","0.09587"
"147.79800","12.31664","0.09678"
"148.17600","12.34827","0.09838"
"148.55400","12.37966","0.10082"
"148.93200","12.41117","0.10315"
"149.31000","12.44274","0.10537"
"149.68800","12.47425","0.10635"
"150.06600","12.50564","0.10702"
"150.44400","12.53721","0.10786"
"150.82200","12.56878","0.10892"
"151.20000","12.60017","0.10992"
"151.57800","12.63167","0.11066"
"151.95600","12.66324","0.11154"
"152.33400","12.69475","0.11253"
"152.71200","12.72614","0.11339"
"153.09000","12.75771","0.11437"
"153.46800","12.78922","0.10821"
"153.84600","12.82067","0.10804"
"154.22400","12.85218","0.10910"
"154.60200","12.88369","0.10907"
"154.98000","12.91520","0.11005"
"155.35800","12.94665","0.11135"
"155.73600","12.97822","0.11223"
"156.11400","13.00972","0.11293"
"156.49200","13.04111","0.11281"
"156.87000","13.07274","0.11437"
"157.24800","13.10425","0.11482"
"157.62600","13.13564","0.11578"
"158.00400","13.16721","0.11763"
"158.38200","13.19866","0.11853"
"158.76000","13.23017","0.12013"
"159.13800","13.26168","0.12099"
"159.51600","13.29325","0.12177"
"159.89400","13.32476","0.12286"
"160.27200","13.35614","0.12421"
"160.65000","13.38765","0.12470"
"161.02800","13.41922","0.12541"
"161.40600","13.45067","0.12598"
"161.78400","13.48218","0.12695"
"162.16200","13.51369","0.12782"
"162.54000","13.54520","0.12907"
"162.91800","13.57659","0.12957"
"163.29600","13.60828","0.13030"
"163.67400","13.63973","0.13166"
"164.05200","13.67112","0.13266"
"164.43000","13.70268","0.13373"
"164.80800","13.73419","0.13488"
"165.18600","13.76564","0.13592"
"165.56400","13.79715","0.13414"
"165.94200","13.82872","0.13304"
"166.32000","13.86023","0.13477"
"166.69800","13.89168","0.13710"
"167.07600","13.92319","0.13991"
"167.45400","13.95476","0.14300"
"167.83200","13.98621","0.14686"
"168.21000","14.01772","0.15073"
"168.58800","14.04922","0.15415"
"168.96600","14.08068","0.15933"
"169.34400","14.11218","0.16427"
"169.72200","14.14369","0.16780"
"170.10000","14.17520","0.17305"
"170.47800","14.20671","0.17690"
"170.85600","14.23816","0.18067"
"171.23400","14.26973","0.18351"
"171.61200","14.30118","0.18567"
"171.99000","14.33269","0.18711"
"172.36800","14.36426","0.18858"
"172.74600","14.39571","0.19010"
"173.12400","14.42721","0.19137"
"173.50200","14.45872","0.19424"
"173.88000","14.49017","0.19663"
"174.25800","14.52162","0.19811"
"174.63600","14.55325","0.19948"
"175.01400","14.58464","0.20278"
"175.39200","14.61621","0.20473"
"175.77000","14.64766","0.20648"
"176.14800","14.67917","0.20857"
"176.52600","14.71068","0.20946"
"176.90400","14.74219","0.21196"
"177.28200","14.77376","0.21416"
"177.66000","14.80526","0.21747"
"178.03800","14.83659","0.21933"
"178.41600","14.86816","0.22154"
"178.79400","14.89973","0.22433"
"179.17200","14.93118","0.22600"
"179.55000","14.96269","0.22828"
"179.92800","14.99420","0.22983"
"180.30600","15.02571","0.23117"
"180.68400","15.05716","0.23220"
"181.06200","15.08867","0.23309"
"181.44000","15.12024","0.23335"
"181.81800","15.15168","0.23186"
"182.19600","15.18319","0.23326"
"182.57400","15.21470","0.23448"
"182.95200","15.24621","0.23566"
"183.33000","15.27766","0.23700"
"183.70800","15.30923","0.23832"
"184.08600","15.34074","0.23979"
"184.46400","15.37213","0.24238"
"184.84200","15.40370","0.24508"
"185.22000","15.43521","0.24787"
"185.59800","15.46672","0.25136"
"185.97600","15.49817","0.25371"
"186.35400","15.52967","0.25611"
"186.73200","15.56124","0.25915"
"187.11000","15.59269","0.26327"
"187.48800","15.62420","0.26682"
"187.86600","15.65571","0.26996"
"188.24400","15.68716","0.27339"
"188.62200","15.71873","0.27613"
"189.00000","15.75024","0.27836"
"189.37800","15.78163","0.28049"
"189.75600","15.81319","0.28229"
"190.13400","15.84476","0.28492"
"190.51200","15.87615","0.28751"
"190.89000","15.90760","0.29162"
"191.26800","15.93923","0.29620"
"191.64600","15.97068","0.30328"
"192.02400","16.00219","0.30737"
"192.40200","16.03370","0.31147"
"192.78000","16.06515","0.31661"
"193.15800","16.09672","0.32208"
"193.53600","16.12817","0.32532"
"193.91400","16.15973","0.33046"
"194.29200","16.19118","0.33458"
"194.67000","16.22263","0.33736"
"195.04800","16.25420","0.33954"
"195.42600","16.28577","0.34097"
"195.80400","16.31716","0.34176"
"196.18200","16.34867","0.34251"
"196.56000","16.38018","0.34349"
"196.93800","16.41169","0.34438"
"197.31600","16.44320","0.34524"
"197.69400","16.47471","0.34743"
"198.07200","16.50622","0.34906"
"198.45000","16.53766","0.35138"
"198.82800","16.56918","0.35419"
"199.20600","16.60074","0.35730"
"199.58400","16.63213","0.35619"
"199.96200","16.66370","0.35974"
"200.34000","16.69521","0.36458"
"200.71800","16.72666","0.37077"
"201.09600","16.75823","0.37779"
"201.47400","16.78974","0.38390"
"201.85200","16.82119","0.38759"
"202.23000","16.85264","0.39007"
"202.60800","16.88421","0.39278"
"202.98600","16.91566","0.39625"
"203.36400","16.94716","0.40060"
"203.74200","16.97867","0.40496"
"204.12000","17.01024","0.40564"
"204.49800","17.04169","0.40979"
"204.87600","17.07314","0.41391"
"205.25400","17.10471","0.41822"
"205.63200","17.13622","0.42166"
"206.01000","17.16767","0.42494"
"206.38800","17.19918","0.42737"
"206.76600","17.23075","0.42937"
"207.14400","17.26213","0.43185"
"207.52200","17.29370","0.43475"
"207.90000","17.32521","0.43780"
"208.27800","17.35666","0.44185"
"208.65600","17.38817","0.44546"
"209.03400","17.41974","0.44879"
"209.41200","17.45125","0.45373"
"209.79000","17.48264","0.45815"
"210.16800","17.51415","0.46196"
"210.54600","17.54572","0.46727"
"210.92400","17.57722","0.47159"
"211.30200","17.60868","0.47501"
"211.68000","17.64024","0.47985"
"212.05800","17.67169","0.48025"
"212.43600","17.70314","0.48321"
"212.81400","17.73465","0.48642"
"213.19200","17.76622","0.48976"
"213.57000","17.79767","0.49115"
"213.94800","17.82924","0.49355"
"214.32600","17.86069","0.49782"
"214.70400","17.89220","0.50468"
"215.08200","17.92371","0.51007"
"215.46000","17.95522","0.51606"
"215.83800","17.98672","0.52087"
"216.21600","18.01817","0.52561"
"216.59400","18.04968","0.52860"
"216.97200","18.08119","0.53186"
"217.35000","18.11270","0.53701"
"217.72800","18.14415","0.54134"
"218.10600","18.17572","0.54504"
"218.48400","18.20717","0.54854"
"218.86200","18.23868","0.55045"
"219.24000","18.27019","0.55012"
"219.61800","18.30164","0.55153"
"219.99600","18.33320","0.55298"
"220.37400","18.36471","0.55494"
"220.75200","18.39622","0.55708"
"221.13000","18.42767","0.55955"
"221.50800","18.45912","0.56358"
"221.88600","18.49069","0.56936"
"222.26400","18.52220","0.57330"
"222.64200","18.55365","0.57849"
"223.02000","18.58522","0.58377"
"223.39800","18.61673","0.59066"
"223.77600","18.64812","0.59486"
"224.15400","18.67974","0.59905"
"224.53200","18.71125","0.60461"
"224.91000","18.74270","0.61081"
"225.28800","18.77421","0.61675"
"225.66600","18.80572","0.62184"
"226.04400","18.83717","0.62788"
"226.42200","18.86868","0.63173"
"226.80000","18.90019","0.63513"
"227.17800","18.93170","0.63677"
"227.55600","18.96315","0.63903"
"227.93400","18.99472","0.63898"
"228.31200","19.02623","0.64033"
"228.69000","19.05767","0.63997"
"229.06800","19.08918","0.62236"
"229.44600","19.12069","0.62571"
"229.82400","19.15226","0.62879"
"230.20200","19.18371","0.63150"
"230.58000","19.21522","0.63468"
"230.95800","19.24673","0.63734"
"231.33600","19.27818","0.63954"
"231.71400","19.30969","0.64155"
"232.09200","19.34120","0.64273"
"232.47000","19.37265","0.64419"
"232.84800","19.40415","0.64586"
"233.22600","19.43572","0.64353"
"233.60400","19.46717","0.64366"
"233.98200","19.49862","0.64477"
"234.36000","19.53019","0.64657"
"234.73800","19.56176","0.64917"
"235.11600","19.59315","0.65125"
"235.49400","19.62466","0.65424"
"235.87200","19.65617","0.65851"
"236.25000","19.68773","0.66374"
"236.62800","19.71925","0.66936"
"237.00600","19.75070","0.67495"
"237.38400","19.78220","0.67998"
"237.76200","19.81365","0.68842"
"238.14000","19.84516","0.69662"
"238.51800","19.87673","0.70092"
"238.89600","19.90818","0.70292"
"239.27400","19.93963","0.70548"
"239.65200","19.97126","0.71173"
"240.03000","20.00271","0.71836"
"240.40800","20.03416","0.72522"
"240.78600","20.06578","0.73332"
"241.16400","20.09723","0.73975"
"241.54200","20.12862","0.74494"
"241.92000","20.16025","0.74935"
"242.29800","20.19170","0.75275"
"242.67600","20.22321","0.75510"
"243.05400","20.25466","0.75737"
"243.43200","20.28623","0.76035"
"243.81000","20.31774","0.76468"
"244.18800","20.34919","0.77004"
"244.56600","20.38070","0.77706"
"244.94400","20.41221","0.78364"
"245.32200","20.44366","0.79082"
"245.70000","20.47517","0.79580"
"246.07800","20.50673","0.80082"
"246.45600","20.53818","0.80952"
"246.83400","20.56969","0.81922"
"247.21200","20.60120","0.82943"
"247.59000","20.63271","0.83703"
"247.96800","20.66422","0.84296"
"248.34600","20.69567","0.84988"
"248.72400","20.72724","0.85335"
"249.10200","20.75869","0.85584"
"249.48000","20.79020","0.85740"
"249.85800","20.82170","0.85938"
"250.23600","20.85321","0.86219"
"250.61400","20.88466","0.86473"
"250.99200","20.91623","0.86833"
"251.37000","20.94768","0.87346"
"251.74800","20.97913","0.87802"
"252.12600","21.01076","0.88388"
"252.50400","21.04221","0.88986"
"252.88200","21.07366","0.89525"
"253.26000","21.10517","0.90014"
"253.63800","21.13674","0.90023"
"254.01600","21.16825","0.90254"
"254.39400","21.19969","0.90642"
"254.77200","21.23120","0.91069"
"255.15000","21.26277","0.91728"
"255.52800","21.29410","0.91261"
"255.90600","21.32567","0.90628"
"256.28400","21.35724","0.91294"
"256.66200","21.38869","0.92203"
"257.04000","21.42020","0.93168"
"257.41800","21.45171","0.92183"
"257.79600","21.48322","0.93262"
"258.17400","21.51467","0.93996"
"258.55200","21.54623","0.94481"
"258.93000","21.57774","0.94826"
"259.30800","21.60919","0.95102"
"259.68600","21.64064","0.95232"
"260.06400","21.67221","0.95515"
"260.44200","21.70366","0.95966"
"260.82000","21.73517","0.96628"
"261.19800","21.76674","0.97271"
"261.57600","21.79825","0.98087"
"261.95400","21.82964","0.98841"
"262.33200","21.86121","0.99795"
"262.71000","21.89271","1.00658"
"263.08800","21.92410","1.01230"
"263.46600","21.95573","1.01625"
"263.84400","21.98718","1.02356"
"264.22200","22.01863","1.03119"
"264.60000","22.05020","1.03833"
"264.97800","22.08171","1.04433"
"265.35600","22.11328","1.04899"
"265.73400","22.14461","1.05300"
"266.11200","22.17618","1.05520"
"266.49000","22.20774","1.05707"
"266.86800","22.23914","1.05921"
"267.24600","22.27064","1.06249"
"267.62400","22.30227","1.06736"
"268.00200","22.33366","1.07400"
"268.38000","22.36517","1.08121"
"268.75800","22.39674","1.08765"
"269.13600","22.42819","1.09754"
"269.51400","22.45970","1.10704"
"269.89200","22.49121","1.10426"
"270.27000","22.52272","1.11165"
"270.64800","22.55423","1.11799"
"271.02600","22.58567","1.12514"
"271.40400","22.61719","1.13732"
"271.78200","22.64875","1.14793"
"272.16000","22.68020","1.15719"
"272.53800","22.71165","1.16371"
"272.91600","22.74322","1.16848"
"273.29400","22.77467","1.17086"
"273.67200","22.80618","1.17313"
"274.05000","22.83769","1.17497"
"274.42800","22.86920","1.17740"
"274.80600","22.90071","1.18254"
"275.18400","22.93222","1.19206"
"275.56200","22.96372","1.20143"
"275.94000","22.99517","1.20628"
"276.31800","23.02668","1.21234"
"276.69600","23.05819","1.21941"
"277.07400","23.08964","1.23139"
"277.45200","23.12121","1.23916"
"277.83000","23.15272","1.24670"
"278.20800","23.18417","1.24915"
"278.58600","23.21562","1.17710"
"278.96400","23.24725","1.17522"
"279.34200","23.27870","1.17629"
"279.72000","23.31021","1.18009"
"280.09800","23.34171","1.18530"
"280.47600","23.37316","1.19485"
"280.85400","23.40473","1.20572"
"281.23200","23.43612","1.21276"
"281.61000","23.46775","1.22156"
"281.98800","23.49920","1.23341"
"282.36600","23.53065","1.24291"
"282.74400","23.56222","1.25505"
"283.12200","23.59379","1.26400"
"283.50000","23.62512","1.26884"
"283.87800","23.65675","1.27316"
"284.25600","23.68826","1.28050"
"284.63400","23.71964","1.29331"
"285.01200","23.75121","1.30367"
"285.39000","23.78272","1.31368"
"285.76800","23.81423","1.32095"
"286.14600","23.84568","1.32349"
"286.52400","23.87719","1.32761"
"286.90200","23.90870","1.33577"
"287.28000","23.94020","1.34464"
"287.65800","23.97166","1.35105"
"288.03600","24.00316","1.35673"
"288.41400","24.03468","1.35932"
"288.79200","24.06618","1.36079"
"289.17000","24.09769","1.18333"
"289.54800","24.12920","1.17473"
"289.92600","24.16065","1.17462"
"290.30400","24.19216","1.17510"
"290.68200","24.22367","1.17614"
"291.06000","24.25518","1.17760"
"291.43800","24.28675","1.17729"
"291.81600","24.31814","1.17389"
"292.19400","24.34971","1.17569"
"292.57200","24.38116","1.18012"
"292.95000","24.41272","1.18500"
"293.32800","24.44423","1.19525"
"293.70600","24.47562","1.20434"
"294.08400","24.50719","1.21212"
"294.46200","24.53870","1.22504"
"294.84000","24.57015","1.23646"
"295.21800","24.60172","1.23047"
"295.59600","24.63323","1.23697"
"295.97400","24.66468","1.24780"
"296.35200","24.69619","1.26008"
"296.73000","24.72770","1.26631"
"297.10800","24.75926","1.27053"
"297.48600","24.79071","1.27086"
"297.86400","24.82216","0.93481"
"298.24200","24.85373","0.92751"
"298.62000","24.88518","0.93472"
"298.99800","24.91663","0.93989"
"299.37600","24.94820","0.94395"
"299.75400","24.97977","0.95044"
"300.13200","25.01116","0.95376"
"300.51000","25.04267","0.95762"
"300.88800","25.07424","0.96727"
"301.26600","25.10563","0.97530"
"301.64400","25.13720","0.98698"
"302.02200","25.16870","0.99749"
"302.40000","25.20021","1.00782"
"302.77800","25.23166","1.01365"
"303.15600","25.26317","1.01761"
"303.53400","25.29468","1.02759"
"303.91200","25.32619","1.03221"
"304.29000","25.35776","1.04167"
"304.66800","25.38921","1.04895"
"305.04600","25.42060","1.05362"
"305.42400","25.45217","1.05645"
"305.80200","25.48373","1.05950"
"306.18000","25.51518","1.06326"
"306.55800","25.54669","1.07105"
"306.93600","25.57820","1.08029"
"307.31400","25.60965","1.09198"
"307.69200","25.64122","1.10600"
"308.07000","25.67273","1.11715"
"308.44800","25.70424","1.12464"
"308.82600","25.73569","1.13799"
"309.20400","25.76714","1.15063"
"309.58200","25.79871","1.16070"
"309.96000","25.83021","1.16652"
"310.33800","25.86166","1.16911"
"310.71600","25.89317","1.15415"
"311.09400","25.92474","1.15844"
"311.47200","25.95613","1.16426"
"311.85000","25.98770","1.16896"
"312.22800","26.01921","1.17205"
"312.60600","26.05066","1.17460"
"312.98400","26.08223","1.17979"
"313.36200","26.11368","1.18770"
"313.74000","26.14519","1.20039"
"314.11800","26.17669","1.20931"
"314.49600","26.20820","1.21730"
"314.87400","26.23971","1.22989"
"315.25200","26.27116","1.24018"
"315.63000","26.30261","1.25051"
"316.00800","26.33418","1.25888"
"316.38600","26.36569","1.26567"
"316.76400","26.39714","1.26739"
"317.14200","26.42871","1.27027"
"317.52000","26.46021","1.27370"
"317.89800","26.49167","1.28111"
"318.27600","26.52324","1.29222"
"318.65400","26.55474","1.30210"
"319.03200","26.58613","1.31101"
"319.41000","26.61770","1.31781"
"319.78800","26.64921","1.32223"
"320.16600","26.68072","1.32480"
"320.54400","26.71217","1.33234"
"320.92200","26.74374","1.34181"
"321.30000","26.77519","1.34861"
"321.67800","26.80664","1.35298"
"322.05600","26.83821","1.35815"
"322.43400","26.86977","1.36343"
"322.81200","26.90116","1.36799"
"323.19000","26.93273","1.37469"
"323.56800","26.96418","1.38363"
"323.94600","26.99569","1.39401"
"324.32400","27.02720","1.40224"
"324.70200","27.05871","1.41421"
"325.08000","27.09022","1.42316"
"325.45800","27.12167","1.43060"
"325.83600","27.15318","1.42882"
"326.21400","27.18469","1.43818"
"326.59200","27.21614","1.44591"
"326.97000","27.24771","1.45259"
"327.34800","27.27921","1.46017"
"327.72600","27.31072","1.46634"
"328.10400","27.34217","1.46877"
"328.48200","27.37374","1.47233"
"328.86000","27.40519","1.47364"
"329.23800","27.43664","1.47399"
"329.61600","27.46821","1.47466"
"329.99400","27.49966","1.47722"
"330.37200","27.53117","1.48200"
"330.75000","27.56268","1.48929"
"331.12800","27.59425","1.49970"
"331.50600","27.62569","1.51316"
"331.88400","27.65721","1.52360"
"332.26200","27.68871","1.53273"
"332.64000","27.72028","1.54385"
"333.01800","27.75167","1.50073"
"333.39600","27.78312","1.51150"
"333.77400","27.81475","1.52163"
"334.15200","27.84620","1.52778"
"334.53000","27.87765","1.53885"
"334.90800","27.90922","1.55080"
"335.28600","27.94072","1.55867"
"335.66400","27.97218","1.56593"
"336.04200","28.00374","1.57106"
"336.42000","28.03525","1.53590"
"336.79800","28.06670","1.53444"
"337.17600","28.09815","1.53634"
"337.55400","28.12972","1.54506"
"337.93200","28.16117","1.55327"
"338.31000","28.19268","1.56052"
"338.68800","28.22425","1.56448"
"339.06600","28.25570","1.52812"
"339.44400","28.28709","1.53943"
"339.82200","28.31872","1.54614"
"340.20000","28.35022","1.51038"
"340.57800","28.38167","1.51546"
"340.95600","28.41324","1.52324"
"341.33400","28.44469","1.53236"
"341.71200","28.47614","1.54064"
"342.09000","28.50765","1.52659"
"342.46800","28.53922","1.52345"
"342.84600","28.57073","1.53120"
"343.22400","28.60217","1.54257"
"343.60200","28.63369","1.54911"
"343.98000","28.66525","1.55539"
"344.35800","28.69665","1.56302"
"344.73600","28.72815","1.57356"
"345.11400","28.75972","1.58282"
"345.49200","28.79117","1.34540"
"345.87000","28.82268","1.33147"
"346.24800","28.85419","1.33347"
"346.62600","28.88576","1.33663"
"347.00400","28.91715","1.34339"
"347.38200","28.94872","1.35002"
"347.76000","28.98017","1.35422"
"348.13800","29.01173","1.33765"
"348.51600","29.04318","1.34561"
"348.89400","29.07470","1.35189"
"349.27200","29.10620","1.35780"
"349.65000","29.13765","1.36462"
"350.02800","29.16916","1.37492"
"350.40600","29.20073","1.38461"
"350.78400","29.23212","1.10307"
"351.16200","29.26369","1.09910"
"351.54000","29.29526","1.09978"
"351.91800","29.32671","1.10397"
"352.29600","29.35816","1.11102"
"352.67400","29.38973","1.10983"
"353.05200","29.42117","1.11523"
"353.43000","29.45268","1.12027"
"353.80800","29.48419","1.11363"
"354.18600","29.51576","1.08828"
"354.56400","29.54721","1.09974"
"354.94200","29.57866","1.11046"
"355.32000","29.61017","1.11769"
"355.69800","29.64168","1.12287"
"356.07600","29.67319","1.13745"
"356.45400","29.70476","1.14167"
"356.83200","29.73621","1.15327"
"357.21000","29.76765","1.16019"
"357.58800","29.79922","1.05415"
"357.96600","29.83073","0.86229"
"358.34400","29.86218","0.84804"
"358.72200","29.89363","0.66144"
"359.10000","29.92520","0.65139"
"359.47800","29.95671","0.64674"
"359.85600","29.98816","0.64703"
"360.23400","30.01967","0.65405"
"360.61200","30.05124","0.66072"
"360.99000","30.08262","0.66575"
"361.36800","30.11419","0.68300"
"361.74600","30.14570","0.68451"
"362.12400","30.17715","0.69976"
"362.50200","30.20872","0.70274"
"362.88000","30.24023","0.70426"
"363.25800","30.27168","0.71651"
"363.63600","30.30319","0.72037"
"364.01400","30.33470","0.73151"
"364.39200","30.36621","0.74335"
"364.77000","30.39772","0.56374"
"365.14800","30.42917","0.55930"
"365.52600","30.46067","0.57058"
"365.90400","30.49224","0.56958"
"366.28200","30.52363","0.58316"
"366.66000","30.55520","0.58015"
"367.03800","30.58671","0.59042"
"367.41600","30.61816","0.59167"
"367.79400","30.64973","0.59941"
"368.17200","30.68118","0.60147"
"368.55000","30.71263","0.61629"
"368.92800","30.74420","0.62044"
"369.30600","30.77565","0.63133"
"369.68400","30.80722","0.63325"
"370.06200","30.83867","0.63811"
"370.44000","30.87023","0.63950"
"370.81800","30.90174","0.63972"
"371.19600","30.93313","0.63330"
"371.57400","30.96470","0.63639"
"371.95200","30.99621","0.64100"
"372.33000","31.02766","0.64233"
"372.70800","31.05917","0.64541"
"373.08600","31.09074","0.64706"
"373.46400","31.12213","0.65372"
"373.84200","31.15364","0.65955"
"374.22000","31.18521","0.66688"
"374.59800","31.21671","0.67660"
"374.97600","31.24816","0.68365"
"375.35400","31.27973","0.69510"
"375.73200","31.31118","0.70063"
"376.11000","31.34269","0.70323"
"376.48800","31.37414","0.70818"
"376.86600","31.40571","0.71457"
"377.24400","31.43721","0.72602"
"377.62200","31.46867","0.73377"
"378.00000","31.50018","0.73887"
"378.37800","31.53174","0.74570"
"378.75600","31.56313","0.74962"
"379.13400","31.59470","0.75359"
"379.51200","31.62621","0.75758"
"379.89000","31.65766","0.76084"
"380.26800","31.68917","0.76571"
"380.64600","31.72068","0.77376"
"381.02400","31.75225","0.78065"
"381.40200","31.78370","0.78794"
"381.78000","31.81520","0.79451"
"382.15800","31.84671","0.79882"
"382.53600","31.87810","0.80449"
"382.91400","31.90967","0.81440"
"383.29200","31.94118","0.82253"
"383.67000","31.97269","0.82737"
"384.04800","32.00420","0.83407"
"384.42600","32.03571","0.84103"
"384.80400","32.06722","0.84008"
"385.18200","32.09867","0.84345"
"385.56000","32.13024","0.84815"
"385.93800","32.16169","0.76786"
"386.31600","32.19320","0.77134"
"386.69400","32.22464","0.77973"
"387.07200","32.25621","0.79179"
"387.45000","32.28766","0.79547"
"387.82800","32.31911","0.79954"
"388.20600","32.35074","0.81434"
"388.58400","32.38225","0.82709"
"388.96200","32.41364","0.83561"
"389.34000","32.44521","0.84661"
"389.71800","32.47672","0.85305"
"390.09600","32.50823","0.85532"
"390.47400","32.53968","0.85705"
"390.85200","32.57119","0.86028"
"391.23000","32.60270","0.86375"
"391.60800","32.63420","0.86501"
"391.98600","32.66571","0.86878"
"392.36400","32.69722","0.87523"
"392.74200","32.72873","0.88221"
"393.12000","32.76012","0.88853"
"393.49800","32.79169","0.89357"
"393.87600","32.82320","0.90036"
"394.25400","32.85464","0.90593"
"394.63200","32.88627","0.91077"
"395.01000","32.91772","0.91784"
"395.38800","32.94918","0.92523"
"395.76600","32.98074","0.93415"
"396.14400","33.01219","0.94072"
"396.52200","33.04364","0.94549"
"396.90000","33.07521","0.94555"
"397.27800","33.10672","0.94926"
"397.65600","33.13817","0.95368"
"398.03400","33.16968","0.95869"
"398.41200","33.20119","0.96459"
"398.79000","33.23270","0.97026"
"399.16800","33.26414","0.97562"
"399.54600","33.29571","0.98203"
"399.92400","33.32722","0.98857"
"400.30200","33.35861","0.99788"
"400.68000","33.39024","1.00545"
"401.05800","33.42175","1.01184"
"401.43600","33.45314","1.01473"
"401.81400","33.48465","1.01909"
"402.19200","33.51622","1.02574"
"402.57000","33.54779","1.03234"
"402.94800","33.57911","1.03634"
"403.32600","33.61069","1.04106"
"403.70400","33.64220","1.02792"
"404.08200","33.67370","1.03230"
"404.46000","33.70515","1.03629"
"404.83800","33.73672","1.04040"
"405.21600","33.76823","1.04270"
"405.59400","33.79968","0.95562"
"405.97200","33.83119","0.95845"
"406.35000","33.86270","0.96055"
"406.72800","33.89415","0.96411"
"407.10600","33.92572","0.96487"
"407.48400","33.95716","0.97091"
"407.86200","33.98867","0.97698"
"408.24000","34.02019","0.98304"
"408.61800","34.05169","0.99009"
"408.99600","34.08320","0.99841"
"409.37400","34.11465","1.00366"
"409.75200","34.14616","1.00966"
"410.13000","34.17773","1.01419"
"410.50800","34.20918","1.01948"
"410.88600","34.24063","1.02644"
"411.26400","34.27220","1.03193"
"411.64200","34.30371","1.03765"
"412.02000","34.33516","1.04256"
"412.39800","34.36672","1.04726"
"412.77600","34.39823","1.05100"
"413.15400","34.42963","1.05401"
"413.53200","34.46125","1.05601"
"413.91000","34.49270","1.05722"
"414.28800","34.52415","1.05931"
"414.66600","34.55572","1.06194"
"415.04400","34.58723","1.06625"
"415.42200","34.61868","1.07109"
"415.80000","34.65019","1.07570"
"416.17800","34.68170","1.08006"
"416.55600","34.71320","1.08525"
"416.93400","34.74459","1.09278"
"417.31200","34.77622","1.09804"
"417.69000","34.80773","1.10687"
"418.06800","34.83918","1.11253"
"418.44600","34.87069","1.11725"
"418.82400","34.90220","1.12295"
"419.20200","34.93365","1.13166"
"419.58000","34.96522","1.14099"
"419.95800","34.99673","1.14854"
"420.33600","35.02823","1.15636"
"420.71400","35.05969","1.16210"
"421.09200","35.09119","1.16601"
"421.47000","35.12276","1.16915"
"421.84800","35.15415","1.17108"
"422.22600","35.18566","1.17279"
"422.60400","35.21729","1.17331"
"422.98200","35.24868","1.17418"
"423.36000","35.28013","1.17563"
"423.73800","35.31170","1.17819"
"424.11600","35.34321","1.18075"
"424.49400","35.37466","1.18372"
"424.87200","35.40622","1.19000"
"425.25000","35.43767","1.19543"
"425.62800","35.46918","1.19978"
"426.00600","35.50069","1.20549"
"426.38400","35.53220","1.20724"
"426.76200","35.56371","1.20903"
"427.14000","35.59516","1.20951"
"427.51800","35.62667","1.21162"
"427.89600","35.65824","1.21289"
"428.27400","35.68962","1.21756"
"428.65200","35.72120","1.22320"
"429.03000","35.75270","1.22978"
"429.40800","35.78421","1.23686"
"429.78600","35.81566","1.24338"
"430.16400","35.84723","1.25011"
"430.54200","35.87874","1.25664"
"430.92000","35.91013","1.26136"
"431.29800","35.94170","1.26554"
"431.67600","35.97321","1.26811"
"432.05400","36.00466","1.27027"
"432.43200","36.03617","1.27278"
"432.81000","36.06773","1.27710"
"433.18800","36.09919","1.28356"
"433.56600","36.13070","1.28927"
"433.94400","36.16220","1.29633"
"434.32200","36.19371","1.30216"
"434.70000","36.22516","1.30827"
"435.07800","36.25667","1.31416"
"435.45600","36.28818","1.31898"
"435.83400","36.31969","1.32186"
"436.21200","36.35120","1.32323"
"436.59000","36.38265","1.32699"
"436.96800","36.41422","1.30375"
"437.34600","36.44561","1.30872"
"437.72400","36.47723","1.31328"
"438.10200","36.50880","1.31864"
"438.48000","36.54007","1.32186"
"438.85800","36.57170","1.32332"
"439.23600","36.60321","1.32776"
"439.61400","36.63466","1.33277"
"439.99200","36.66617","1.33862"
"440.37000","36.69774","1.34404"
"440.74800","36.72919","1.34748"
"441.12600","36.76064","1.26027"
"441.50400","36.79221","1.26034"
"441.88200","36.82366","1.26343"
"442.26000","36.85522","1.26827"
"442.63800","36.88667","1.27207"
"443.01600","36.91818","1.27855"
"443.39400","36.94970","1.28684"
"443.77200","36.98114","1.29279"
"444.15000","37.01271","1.30074"
"444.52800","37.04416","1.24530"
"444.90600","37.07561","1.25321"
"445.28400","37.10723","1.25735"
"445.66200","37.13869","1.26201"
"446.04000","37.17014","1.26542"
"446.41800","37.20171","1.26821"
"446.79600","37.23322","1.27049"
"447.17400","37.26466","1.27301"
"447.55200","37.29617","1.27787"
"447.93000","37.32768","1.28472"
"448.30800","37.35919","1.29287"
"448.68600","37.39070","1.30097"
"449.06400","37.42215","1.30867"
"449.44200","37.45378","1.31595"
"449.82000","37.48517","1.32028"
"450.19800","37.51667","1.32218"
"450.57600","37.54824","1.32305"
"450.95400","37.57969","1.32571"
"451.33200","37.61115","1.33039"
"451.71000","37.64272","1.33677"
"452.08800","37.67422","1.34219"
"452.46600","37.70567","1.34599"
"452.84400","37.73718","1.35091"
"453.22200","37.76869","1.35475"
"453.60000","37.80020","1.35771"
"453.97800","37.83165","1.35692"
"454.35600","37.86322","1.36070"
"454.73400","37.89473","1.36508"
"455.11200","37.92612","1.36901"
"455.49000","37.95768","1.37295"
"455.86800","37.98925","1.36970"
"456.24600","38.02065","1.32204"
"456.62400","38.05221","1.32248"
"457.00200","38.08372","1.32425"
"457.38000","38.11511","1.32563"
"457.75800","38.14668","1.33007"
"458.13600","38.17825","1.33575"
"458.51400","38.20969","1.34099"
"458.89200","38.24121","1.34635"
"459.27000","38.27266","1.34561"
"459.64800","38.30423","1.34864"
"460.02600","38.33561","1.35279"
"460.40400","38.36718","1.35617"
"460.78200","38.39869","1.35925"
"461.16000","38.43020","1.36246"
"461.53800","38.46171","1.36619"
"461.91600","38.49322","1.37146"
"462.29400","38.52473","1.37698"
"462.67200","38.55618","1.38330"
"463.05000","38.58775","1.38940"
"463.42800","38.61919","1.39613"
"463.80600","38.65065","1.40335"
"464.18400","38.68216","1.41088"
"464.56200","38.71372","1.41808"
"464.94000","38.74523","1.42443"
"465.31800","38.77662","1.43054"
"465.69600","38.80819","1.43461"
"466.07400","38.83976","1.44198"
"466.45200","38.87109","1.44911"
"466.83000","38.90272","1.45395"
"467.20800","38.93423","1.45922"
"467.58600","38.96574","1.46494"
"467.96400","38.99718","1.46926"
"468.34200","39.02869","1.47230"
"468.72000","39.06020","1.47346"
"469.09800","39.09171","1.47394"
"469.47600","39.12316","1.47415"
"469.85400","39.15467","1.47475"
"470.23200","39.18618","1.47633"
"470.61000","39.21762","1.47992"
"470.98800","39.24920","1.20906"
"471.36600","39.28071","1.18696"
"471.74400","39.31215","1.18528"
"472.12200","39.34373","1.18293"
"472.50000","39.37523","1.18550"
"472.87800","39.40662","1.19083"
"473.25600","39.43825","1.19778"
"473.63400","39.46970","1.20150"
"474.01200","39.50115","1.20706"
"474.39000","39.53272","1.21113"
"474.76800","39.56417","1.21702"
"475.14600","39.59568","1.22481"
"475.52400","39.62718","1.23253"
"475.90200","39.65870","1.24076"
"476.28000","39.69020","1.24901"
"476.65800","39.72166","1.25441"
"477.03600","39.75317","1.25899"
"477.41400","39.78479","1.26146"
"477.79200","39.81618","1.26475"
"478.17000","39.84763","1.26796"
"478.54800","39.87925","1.27075"
"478.92600","39.91071","1.27362"
"479.30400","39.94222","1.27772"
"479.68200","39.97367","1.28217"
"480.06000","40.00524","1.28925"
"480.43800","40.03669","1.29454"
"480.81600","40.06820","1.30099"
"481.19400","40.09970","1.30487"
"481.57200","40.13121","1.30863"
"481.95000","40.16266","1.31204"
"482.32800","40.19423","1.31628"
"482.70600","40.22568","1.31957"
"483.08400","40.25713","1.32159"
"483.46200","40.28870","1.32347"
"483.84000","40.32020","1.32595"
"484.21800","40.35166","1.33085"
"484.59600","40.38323","1.33616"
"484.97400","40.41473","1.34212"
"485.35200","40.44619","1.34688"
"485.73000","40.47769","1.35109"
"486.10800","40.50920","1.35487"
"486.48600","40.54071","1.35799"
"486.86400","40.57222","1.36140"
"487.24200","40.60367","1.36423"
"487.62000","40.63524","1.36762"
"487.99800","40.66663","1.37095"
"488.37600","40.69820","1.37623"
"488.75400","40.72970","1.38025"
"489.13200","40.76116","1.38626"
"489.51000","40.79260","1.39119"
"489.88800","40.82423","1.39595"
"490.26600","40.85574","1.40307"
"490.64400","40.88713","1.41069"
"491.02200","40.91870","1.41632"
"491.40000","40.95021","1.41995"
"491.77800","40.98172","1.04275"
"492.15600","41.01317","0.73866"
"492.53400","41.04473","0.73534"
"492.91200","41.07619","0.73388"
"493.29000","41.10769","0.73806"
"493.66800","41.13926","0.73742"
"494.04600","41.17078","0.74075"
"494.42400","41.20216","0.74397"
"494.80200","41.23367","0.74678"
"495.18000","41.26524","0.74968"
"495.55800","41.29669","0.75135"
"495.93600","41.32814","0.75327"
"496.31400","41.35970","0.75456"
"496.69200","41.39122","0.75620"
"497.07000","41.42273","0.75842"
"497.44800","41.45418","0.76111"
"497.82600","41.48574","0.76394"
"498.20400","41.51714","0.76731"
"498.58200","41.54865","0.77136"
"498.96000","41.58021","0.77593"
"499.33800","41.61166","0.78288"
"499.71600","41.64323","0.78506"
"500.09400","41.67468","0.78352"
"500.47200","41.70613","0.78474"
"500.85000","41.73764","0.78651"
"501.22800","41.76926","0.78593"
"501.60600","41.80072","0.78581"
"501.98400","41.83216","0.78565"
"502.36200","41.86368","0.78142"
"502.74000","41.89518","0.77803"
"503.11800","41.92669","0.77959"
"503.49600","41.95814","0.78183"
"503.87400","41.98971","0.78487"
"504.25200","42.02122","0.78795"
"504.63000","42.05267","0.79087"
"505.00800","42.08418","0.79284"
"505.38600","42.11575","0.79451"
"505.76400","42.14714","0.79556"
"506.14200","42.17871","0.79721"
"506.52000","42.21021","0.79946"
"506.89800","42.24166","0.80291"
"507.27600","42.27317","0.80713"
"507.65400","42.30474","0.81068"
"508.03200","42.33625","0.81364"
"508.41000","42.36764","0.81851"
"508.78800","42.39921","0.82116"
"509.16600","42.43072","0.82455"
"509.54400","42.46217","0.82794"
"509.92200","42.49368","0.83147"
"510.30000","42.52519","0.83308"
"510.67800","42.55669","0.83410"
"511.05600","42.58820","0.83353"
"511.43400","42.61971","0.83164"
"511.81200","42.65123","0.83061"
"512.19000","42.68267","0.82822"
"512.56800","42.71424","0.82475"
"512.94600","42.74569","0.82229"
"513.32400","42.77714","0.82033"
"513.70200","42.80865","0.81931"
"514.08000","42.84021","0.81857"
"514.45800","42.87172","0.81896"
"514.83600","42.90318","0.82027"
"515.21400","42.93475","0.82359"
"515.59200","42.96626","0.82875"
"515.97000","42.99764","0.83355"
"516.34800","43.02921","0.83769"
"516.72600","43.06072","0.84206"
"517.10400","43.09217","0.84641"
"517.48200","43.12368","0.85035"
"517.86000","43.15525","0.85331"
"518.23800","43.18664","0.85470"
"518.61600","43.21814","0.85601"
"518.99400","43.24971","0.85766"
"519.37200","43.28123","0.85919"
"519.75000","43.31268","0.86074"
"520.12800","43.34418","0.86255"
"520.50600","43.37569","0.86524"
"520.88400","43.40720","0.86779"
"521.26200","43.43865","0.87119"
"521.64000","43.47022","0.87600"
"522.01800","43.50173","0.87960"
"522.39600","43.53318","0.88386"
"522.77400","43.56469","0.88982"
"523.15200","43.59620","0.89592"
"523.53000","43.62764","0.90013"
"523.90800","43.65921","0.90381"
"524.28600","43.69072","0.90678"
"524.66400","43.72217","0.91017"
"525.04200","43.75368","0.91431"
"525.42000","43.78519","0.92049"
"525.79800","43.81676","0.92686"
"526.17600","43.84815","0.93186"
"526.55400","43.87971","0.93668"
"526.93200","43.91122","0.94095"
"527.31000","43.94262","0.94432"
"527.68800","43.97419","0.94719"
"528.06600","44.00570","0.94958"
"528.44400","44.03720","0.95280"
"528.82200","44.06865","0.95560"
"529.20000","44.10022","0.95928"
"529.57800","44.13173","0.96302"
"529.95600","44.16324","0.96701"
"530.33400","44.19469","0.97066"
"530.71200","44.22620","0.97479"
"531.09000","44.25771","0.97935"
"531.46800","44.28916","0.98408"
"531.84600","44.32072","0.98844"
"532.22400","44.35217","0.99282"
"532.60200","44.38369","0.80723"
"532.98000","44.41525","0.79928"
"533.35800","44.44676","0.79707"
"533.73600","44.47809","0.79501"
"534.11400","44.50972","0.79631"
"534.49200","44.54123","0.79959"
"534.87000","44.57268","0.80388"
"535.24800","44.60413","0.80578"
"535.62600","44.63576","0.80988"
"536.00400","44.66720","0.81755"
"536.38200","44.69865","0.82738"
"536.76000","44.73022","0.83381"
"537.13800","44.76167","0.83681"
"537.51600","44.79312","0.84096"
"537.89400","44.82469","0.64607"
"538.27200","44.85626","0.55970"
"538.65000","44.88765","0.56451"
"539.02800","44.91916","0.55780"
"539.40600","44.95066","0.56362"
"539.78400","44.98224","0.55889"
"540.16200","45.01369","0.56572"
"540.54000","45.04520","0.56123"
"540.91800","45.07671","0.56865"
"541.29600","45.10822","0.56588"
"541.67400","45.13966","0.57425"
"542.05200","45.17117","0.57164"
"542.43000","45.20274","0.58065"
"542.80800","45.23413","0.57986"
"543.18600","45.26570","0.58878"
"543.56400","45.29721","0.58911"
"543.94200","45.32859","0.59497"
"544.32000","45.36022","0.59469"
"544.69800","45.39174","0.60000"
"545.07600","45.42319","0.60002"
"545.45400","45.45469","0.60672"
"545.83200","45.48621","0.60653"
"546.21000","45.51771","0.61539"
"546.58800","45.54916","0.61528"
"546.96600","45.58073","0.62403"
"547.34400","45.61224","0.62431"
"547.72200","45.64369","0.63004"
"548.10000","45.67514","0.63186"
"548.47800","45.70671","0.63499"
"548.85600","45.73822","0.63734"
"549.23400","45.76966","0.63843"
"549.61200","45.80117","0.64073"
"549.99000","45.83274","0.64133"
"550.36800","45.86414","0.64305"
"550.74600","45.89576","0.64327"
"551.12400","45.92721","0.64472"
"551.50200","45.95860","0.64521"
"551.88000","45.99023","0.64678"
"552.25800","46.02168","0.64851"
"552.63600","46.05319","0.64927"
"553.01400","46.08469","0.65222"
"553.39200","46.11621","0.65394"
"553.77000","46.14771","0.65766"
"554.14800","46.17916","0.66010"
"554.52600","46.21073","0.66344"
"554.90400","46.24224","0.66783"
"555.28200","46.27369","0.67051"
"555.66000","46.30520","0.67358"
"556.03800","46.33677","0.67492"
"556.41600","46.36822","0.67906"
"556.79400","46.39967","0.68346"
"557.17200","46.43118","0.68789"
"557.55000","46.46268","0.69217"
"557.92800","46.49420","0.69526"
"558.30600","46.52564","0.69858"
"558.68400","46.55721","0.70070"
"559.06200","46.58866","0.70143"
"559.44000","46.62017","0.70247"
"559.81800","46.65174","0.70294"
"560.19600","46.68319","0.70401"
"560.57400","46.71470","0.70523"
"560.95200","46.74621","0.70751"
"561.33000","46.77772","0.53984"
"561.70800","46.80911","0.05088"
"562.08600","46.84074","0.04766"
"562.46400","46.87218","0.05522"
"562.84200","46.90369","0.05274"
"563.22000","46.93514","0.07845"
"563.59800","46.96671","0.04056"
"563.97600","46.99816","0.04043"
"564.35400","47.02961","0.07074"
"564.72200","47.06040","0.05111"