File: Force_trajectories/170212_1/Specimen_RawData_10.csv
End date,"2/12/2017"
Specimen label,"12BT_95"
Maximum Load,"0.39216",N

Time,Extension,Load
(s),(mm),(N)
"0.00000","0.00000","0.00051"
"0.17400","0.01124","0.00107"
"0.34800","0.02906","0.00215"
"0.52200","0.04371","0.00164"
"0.69600","0.05824","0.00254"
"0.87000","0.07276","0.00304"
"1.04400","0.08717","0.00344"
"1.21800","0.10176","0.00394"
"1.39200","0.11623","0.00429"
"1.56600","0.13070","0.00426"
"1.74000","0.14523","0.00443"
"1.91400","0.15976","0.00513"
"2.08800","0.17423","0.00530"
"2.26200","0.18870","0.00530"
"2.43600","0.20322","0.00554"
"2.61000","0.21769","0.00612"
"2.78600","0.23234","0.00620"
"2.96000","0.24693","0.00615"
"3.13400","0.26140","0.00569"
"3.30800","0.27581","0.00667"
"3.48200","0.29040","0.00604"
"3.65600","0.30493","0.00724"
"3.83000","0.31934","0.00688"
"4.00400","0.33386","0.00688"
"4.17800","0.34833","0.00681"
"4.35200","0.36280","0.00713"
"4.52600","0.37745","0.00726"
"4.70000","0.39186","0.00780"
"4.87400","0.40633","0.00770"
"5.04800","0.42092","0.00780"
"5.22200","0.43539","0.00744"
"5.39600","0.44986","0.00830"
"5.57000","0.46439","0.00784"
"5.74400","0.47891","0.00869"
"5.91800","0.49332","0.00857"
"6.09200","0.50785","0.00846"
"6.26600","0.52238","0.00813"
"6.44000","0.53685","0.00832"
"6.61400","0.55138","0.00877"
"6.78800","0.56591","0.00877"
"6.96200","0.58038","0.00867"
"7.13600","0.59491","0.00869"
"7.31000","0.60937","0.00825"
"7.48400","0.62378","0.00948"
"7.65800","0.63837","0.00962"
"7.83200","0.65290","0.00908"
"8.00600","0.66737","0.00978"
"8.18000","0.68184","0.01013"
"8.35400","0.69637","0.00973"
"8.52800","0.71090","0.00967"
"8.70200","0.72537","0.01010"
"8.87600","0.73990","0.01009"
"9.05000","0.75436","0.01031"
"9.22400","0.76883","0.01017"
"9.39800","0.78342","0.00950"
"9.57200","0.79789","0.01060"
"9.74600","0.81236","0.01079"
"9.92000","0.82689","0.01047"
"10.09400","0.84142","0.00978"
"10.26800","0.85583","0.01087"
"10.44200","0.87036","0.01114"
"10.61600","0.88489","0.01115"
"10.79000","0.89929","0.01104"
"10.96400","0.91394","0.01090"
"11.13800","0.92841","0.01079"
"11.31200","0.94282","0.01136"
"11.48600","0.95735","0.01119"
"11.66000","0.97188","0.01131"
"11.83400","0.98641","0.01174"
"12.00800","1.00088","0.01144"
"12.18200","1.01541","0.01141"
"12.35600","1.02981","0.01180"
"12.53000","1.04440","0.01114"
"12.70400","1.05893","0.01238"
"12.87800","1.07334","0.01217"
"13.05200","1.08787","0.01257"
"13.22600","1.10234","0.01218"
"13.40000","1.11681","0.01264"
"13.57400","1.13134","0.01246"
"13.74800","1.14587","0.01254"
"13.92200","1.16034","0.01254"
"14.09600","1.17486","0.01332"
"14.27000","1.18939","0.01296"
"14.44400","1.20386","0.01338"
"14.61800","1.21833","0.01335"
"14.79200","1.23286","0.01372"
"14.96600","1.24739","0.01342"
"15.14000","1.26186","0.01357"
"15.31400","1.27639","0.01354"
"15.48800","1.29086","0.01386"
"15.66200","1.30527","0.01370"
"15.83600","1.31991","0.01353"
"16.01000","1.33444","0.01372"
"16.18400","1.34879","0.01352"
"16.35800","1.36344","0.01334"
"16.53200","1.37791","0.01363"
"16.70600","1.39232","0.01417"
"16.88000","1.40691","0.01385"
"17.05400","1.42138","0.01415"
"17.22800","1.43585","0.01402"
"17.40200","1.45037","0.01418"
"17.57600","1.46490","0.01488"
"17.75000","1.47937","0.01414"
"17.92400","1.49384","0.01405"
"18.09800","1.50843","0.01449"
"18.27200","1.52284","0.01460"
"18.44600","1.53743","0.01409"
"18.62000","1.55190","0.01424"
"18.79400","1.56631","0.01482"
"18.96800","1.58084","0.01371"
"19.14200","1.59536","0.01452"
"19.31600","1.60989","0.01431"
"19.49000","1.62430","0.01480"
"19.66400","1.63883","0.01464"
"19.83800","1.65336","0.01486"
"20.01200","1.66789","0.01502"
"20.18600","1.68236","0.01429"
"20.36000","1.69683","0.01521"
"20.53400","1.71130","0.01508"
"20.70800","1.72588","0.01485"
"20.88200","1.74041","0.01482"
"21.05600","1.75482","0.01523"
"21.23000","1.76941","0.01551"
"21.40400","1.78388","0.01505"
"21.57800","1.79835","0.01495"
"21.75200","1.81294","0.01458"
"21.92600","1.82741","0.01479"
"22.10000","1.84182","0.01509"
"22.27400","1.85641","0.01570"
"22.44800","1.87087","0.01542"
"22.62200","1.88534","0.01543"
"22.79600","1.89987","0.01563"
"22.97000","1.91440","0.01523"
"23.14400","1.92881","0.01518"
"23.31800","1.94340","0.01564"
"23.49200","1.95787","0.01546"
"23.66600","1.97234","0.01537"
"23.84000","1.98687","0.01580"
"24.01400","2.00139","0.01653"
"24.18800","2.01580","0.01544"
"24.36200","2.03039","0.01562"
"24.53600","2.04486","0.01562"
"24.71000","2.05933","0.01533"
"24.88400","2.07392","0.01594"
"25.05800","2.08833","0.01608"
"25.23200","2.10286","0.01578"
"25.40600","2.11733","0.01619"
"25.58000","2.13192","0.01566"
"25.75400","2.14638","0.01610"
"25.92800","2.16085","0.01590"
"26.10200","2.17538","0.01637"
"26.27600","2.18985","0.01587"
"26.45000","2.20432","0.01651"
"26.62400","2.21891","0.01633"
"26.79800","2.23338","0.01624"
"26.97200","2.24779","0.01609"
"27.14600","2.26238","0.01560"
"27.32000","2.27690","0.01608"
"27.49400","2.29131","0.01595"
"27.66800","2.30590","0.01669"
"27.84200","2.32037","0.01644"
"28.01600","2.33484","0.01691"
"28.19000","2.34943","0.01669"
"28.36400","2.36390","0.01696"
"28.53800","2.37831","0.01696"
"28.71200","2.39290","0.01678"
"28.88600","2.40737","0.01636"
"29.06000","2.42189","0.01694"
"29.23400","2.43636","0.01650"
"29.40800","2.45083","0.01678"
"29.58200","2.46536","0.01640"
"29.75600","2.47989","0.01650"
"29.93000","2.49442","0.01647"
"30.10400","2.50883","0.01584"
"30.27800","2.52336","0.01619"
"30.45200","2.53789","0.01591"
"30.62600","2.55236","0.01681"
"30.80000","2.56688","0.01669"
"30.97400","2.58135","0.01659"
"31.14800","2.59582","0.01748"
"31.32200","2.61041","0.01585"
"31.49600","2.62494","0.01653"
"31.67000","2.63935","0.01644"
"31.84400","2.65382","0.01697"
"32.01800","2.66835","0.01637"
"32.19200","2.68288","0.01718"
"32.36600","2.69735","0.01703"
"32.54000","2.71187","0.01689"
"32.71400","2.72634","0.01696"
"32.88800","2.74075","0.01703"
"33.06200","2.75540","0.01710"
"33.23600","2.76987","0.01685"
"33.41000","2.78434","0.01755"
"33.58400","2.79887","0.01689"
"33.75800","2.81340","0.01704"
"33.93200","2.82787","0.01650"
"34.10600","2.84239","0.01770"
"34.28000","2.85692","0.01689"
"34.45400","2.87133","0.01710"
"34.62800","2.88586","0.01702"
"34.80200","2.90039","0.01779"
"34.97600","2.91486","0.01699"
"35.15000","2.92933","0.01730"
"35.32400","2.94392","0.01748"
"35.49800","2.95839","0.01708"
"35.67200","2.97291","0.01643"
"35.84600","2.98738","0.01772"
"36.02000","3.00179","0.01733"
"36.19400","3.01632","0.01819"
"36.36800","3.03091","0.01750"
"36.54200","3.04538","0.01722"
"36.71600","3.05985","0.01659"
"36.89000","3.07438","0.01702"
"37.06400","3.08885","0.01688"
"37.23800","3.10338","0.01704"
"37.41200","3.11790","0.01769"
"37.58600","3.13237","0.01773"
"37.76000","3.14684","0.01732"
"37.93400","3.16143","0.01763"
"38.10800","3.17584","0.01746"
"38.28200","3.19037","0.01727"
"38.45600","3.20490","0.01738"
"38.63000","3.21937","0.01705"
"38.80400","3.23384","0.01719"
"38.97800","3.24843","0.01763"
"39.15200","3.26283","0.01718"
"39.32600","3.27730","0.01716"
"39.50000","3.29189","0.01735"
"39.67400","3.30642","0.01716"
"39.84800","3.32089","0.01801"
"40.02200","3.33542","0.01722"
"40.19600","3.34989","0.01694"
"40.37000","3.36436","0.01700"
"40.54400","3.37889","0.01767"
"40.71800","3.39336","0.01748"
"40.89200","3.40782","0.01735"
"41.06600","3.42235","0.01773"
"41.24000","3.43688","0.01748"
"41.41400","3.45135","0.01716"
"41.58800","3.46588","0.01703"
"41.76200","3.48041","0.01798"
"41.93600","3.49488","0.01750"
"42.11000","3.50941","0.01757"
"42.28400","3.52388","0.01741"
"42.45800","3.53834","0.01754"
"42.63200","3.55281","0.01755"
"42.80600","3.56740","0.01777"
"42.98000","3.58193","0.01774"
"43.15400","3.59634","0.01778"
"43.32800","3.61087","0.01761"
"43.50200","3.62534","0.01795"
"43.67600","3.63987","0.01759"
"43.85000","3.65440","0.01774"
"44.02400","3.66887","0.01685"
"44.19800","3.68327","0.01700"
"44.37200","3.69786","0.01722"
"44.54600","3.71239","0.01761"
"44.72000","3.72686","0.01724"
"44.89400","3.74133","0.01782"
"45.06800","3.75592","0.01761"
"45.24200","3.77033","0.01731"
"45.41600","3.78492","0.01769"
"45.59000","3.79939","0.01742"
"45.76400","3.81380","0.01748"
"45.93800","3.82838","0.01734"
"46.11200","3.84285","0.01790"
"46.28600","3.85738","0.01748"
"46.46000","3.87191","0.01785"
"46.63400","3.88638","0.01788"
"46.80800","3.90085","0.01712"
"46.98200","3.91538","0.01777"
"47.15600","3.92985","0.01748"
"47.33000","3.94432","0.01766"
"47.50400","3.95884","0.01789"
"47.67800","3.97337","0.01774"
"47.85200","3.98784","0.01787"
"48.02600","4.00243","0.01771"
"48.20000","4.01684","0.01737"
"48.37400","4.03131","0.01780"
"48.54800","4.04590","0.01789"
"48.72200","4.06043","0.01742"
"48.89600","4.07490","0.01741"
"49.07000","4.08931","0.01709"
"49.24400","4.10389","0.01744"
"49.41800","4.11836","0.01723"
"49.59200","4.13283","0.01709"
"49.76600","4.14742","0.01710"
"49.94000","4.16195","0.01720"
"50.11400","4.17630","0.01752"
"50.28800","4.19089","0.01730"
"50.46200","4.20542","0.01734"
"50.63600","4.21977","0.01721"
"50.81000","4.23441","0.01780"
"50.98400","4.24888","0.01713"
"51.15800","4.26329","0.01811"
"51.33200","4.27788","0.01724"
"51.50600","4.29241","0.01744"
"51.68000","4.30682","0.01748"
"51.85400","4.32141","0.01743"
"52.02800","4.33588","0.01732"
"52.20200","4.35029","0.01770"
"52.37600","4.36488","0.01787"
"52.55000","4.37940","0.01755"
"52.72400","4.39387","0.01816"
"52.89800","4.40834","0.01707"
"53.07200","4.42287","0.01745"
"53.24600","4.43734","0.01745"
"53.42000","4.45187","0.01770"
"53.59400","4.46640","0.01781"
"53.76800","4.48081","0.01763"
"53.94200","4.49534","0.01809"
"54.11600","4.50986","0.01741"
"54.29000","4.52439","0.01794"
"54.46400","4.53886","0.01791"
"54.63800","4.55339","0.01736"
"54.81200","4.56786","0.01789"
"54.98600","4.58233","0.01819"
"55.16000","4.59686","0.01751"
"55.33400","4.61139","0.01786"
"55.50800","4.62586","0.01784"
"55.68200","4.64033","0.01784"
"55.85600","4.65485","0.01784"
"56.03000","4.66938","0.01751"
"56.20400","4.68391","0.01725"
"56.37800","4.69838","0.01818"
"56.55200","4.71279","0.01813"
"56.72600","4.72738","0.01774"
"56.90000","4.74191","0.01800"
"57.07400","4.75638","0.01727"
"57.24800","4.77091","0.01792"
"57.42200","4.78537","0.01763"
"57.59600","4.79978","0.01817"
"57.77000","4.81437","0.01762"
"57.94400","4.82890","0.01785"
"58.11800","4.84331","0.01825"
"58.29200","4.85790","0.01754"
"58.46600","4.87237","0.01776"
"58.64000","4.88678","0.01782"
"58.81400","4.90137","0.01738"
"58.98800","4.91590","0.01770"
"59.16200","4.93036","0.01837"
"59.33600","4.94489","0.01748"
"59.51000","4.95936","0.01810"
"59.68400","4.97383","0.01782"
"59.85800","4.98830","0.01864"
"60.03200","5.00295","0.01779"
"60.20600","5.01736","0.01820"
"60.38000","5.03183","0.01772"
"60.55400","5.04636","0.01787"
"60.72800","5.06083","0.01842"
"60.90200","5.07535","0.01780"
"61.07600","5.08988","0.01792"
"61.25000","5.10435","0.01810"
"61.42400","5.11882","0.01792"
"61.59800","5.13335","0.01822"
"61.77200","5.14794","0.01782"
"61.94600","5.16235","0.01822"
"62.12000","5.17688","0.01860"
"62.29400","5.19135","0.01850"
"62.46800","5.20581","0.01841"
"62.64200","5.22040","0.01786"
"62.81600","5.23487","0.01829"
"62.99000","5.24934","0.01882"
"63.16400","5.26387","0.01853"
"63.33800","5.27834","0.01778"
"63.51200","5.29281","0.01830"
"63.68600","5.30740","0.01793"
"63.86000","5.32187","0.01797"
"64.03400","5.33633","0.01804"
"64.20800","5.35092","0.01799"
"64.38200","5.36539","0.01844"
"64.55600","5.37986","0.01870"
"64.73000","5.39433","0.01876"
"64.90400","5.40892","0.01873"
"65.07800","5.42333","0.01784"
"65.25200","5.43786","0.01840"
"65.42600","5.45239","0.01888"
"65.60000","5.46686","0.01871"
"65.77400","5.48139","0.01909"
"65.94800","5.49591","0.01862"
"66.12200","5.51032","0.01783"
"66.29600","5.52485","0.01803"
"66.47000","5.53938","0.01762"
"66.64400","5.55385","0.01705"
"66.81800","5.56832","0.01749"
"66.99200","5.58291","0.01787"
"67.16600","5.59738","0.01791"
"67.34000","5.61185","0.01784"
"67.51400","5.62643","0.01820"
"67.68800","5.64090","0.01738"
"67.86200","5.65531","0.01805"
"68.03600","5.66990","0.01809"
"68.21000","5.68443","0.01778"
"68.38400","5.69884","0.01766"
"68.55800","5.71337","0.01771"
"68.73200","5.72784","0.01792"
"68.90600","5.74231","0.01745"
"69.08000","5.75690","0.01794"
"69.25400","5.77136","0.01814"
"69.42800","5.78577","0.01774"
"69.60200","5.80036","0.01805"
"69.77600","5.81489","0.01766"
"69.95000","5.82936","0.01661"
"70.12400","5.84389","0.01689"
"70.29800","5.85842","0.01658"
"70.47200","5.87283","0.01691"
"70.64600","5.88736","0.01735"
"70.82000","5.90188","0.01677"
"70.99400","5.91635","0.01737"
"71.16800","5.93088","0.01752"
"71.34200","5.94535","0.01696"
"71.51600","5.95988","0.01702"
"71.69000","5.97435","0.01695"
"71.86400","5.98888","0.01743"
"72.03800","6.00335","0.01691"
"72.21200","6.01782","0.01745"
"72.38600","6.03240","0.01744"
"72.56000","6.04687","0.01770"
"72.73400","6.06134","0.01708"
"72.90800","6.07587","0.01703"
"73.08200","6.09034","0.01709"
"73.25600","6.10487","0.01653"
"73.43000","6.11940","0.01554"
"73.60400","6.13381","0.01532"
"73.77800","6.14834","0.01549"
"73.95200","6.16293","0.01597"
"74.12600","6.17733","0.01613"
"74.30000","6.19186","0.01557"
"74.47400","6.20639","0.01569"
"74.64800","6.22086","0.01618"
"74.82200","6.23533","0.01644"
"74.99600","6.24992","0.01529"
"75.17000","6.26439","0.01558"
"75.34400","6.27880","0.01608"
"75.51800","6.29345","0.01634"
"75.69200","6.30786","0.01529"
"75.86600","6.32232","0.01649"
"76.04000","6.33685","0.01527"
"76.21400","6.35138","0.01586"
"76.38800","6.36585","0.01542"
"76.56200","6.38044","0.01534"
"76.73600","6.39491","0.01594"
"76.91000","6.40932","0.01549"
"77.08400","6.42385","0.01563"
"77.25800","6.43844","0.01501"
"77.43200","6.45285","0.01528"
"77.60600","6.46737","0.01573"
"77.78000","6.48190","0.01610"
"77.95400","6.49637","0.01530"
"78.12800","6.51084","0.01585"
"78.30200","6.52537","0.01584"
"78.47600","6.53984","0.01563"
"78.65000","6.55437","0.01639"
"78.82400","6.56890","0.01625"
"78.99800","6.58337","0.01504"
"79.17200","6.59783","0.01596"
"79.34600","6.61236","0.01600"
"79.52000","6.62689","0.01592"
"79.69400","6.64136","0.01583"
"79.86800","6.65589","0.01502"
"80.04200","6.67036","0.01534"
"80.21600","6.68477","0.01581"
"80.39000","6.69942","0.01571"
"80.56400","6.71389","0.01603"
"80.73800","6.72836","0.01538"
"80.91200","6.74282","0.01545"
"81.08600","6.75735","0.01508"
"81.26000","6.77188","0.01523"
"81.43400","6.78641","0.01535"
"81.60800","6.80088","0.01552"
"81.78200","6.81535","0.01595"
"81.95600","6.82988","0.01574"
"82.13000","6.84435","0.01607"
"82.30400","6.85888","0.01573"
"82.47800","6.87334","0.01556"
"82.65200","6.88787","0.01580"
"82.82600","6.90234","0.01578"
"83.00000","6.91687","0.01582"
"83.17400","6.93140","0.01566"
"83.34800","6.94587","0.01634"
"83.52200","6.96034","0.01596"
"83.69600","6.97487","0.01591"
"83.87000","6.98940","0.01658"
"84.04400","7.00387","0.01684"
"84.21800","7.01839","0.01646"
"84.39200","7.03280","0.01599"
"84.56600","7.04739","0.01642"
"84.74000","7.06192","0.01604"
"84.91400","7.07639","0.01637"
"85.08800","7.09080","0.01531"
"85.26200","7.10539","0.01573"
"85.43600","7.11992","0.01544"
"85.61000","7.13433","0.01542"
"85.78400","7.14897","0.01645"
"85.95800","7.16338","0.01622"
"86.13200","7.17785","0.01618"
"86.30600","7.19238","0.01625"
"86.48000","7.20691","0.01675"
"86.65400","7.22132","0.01612"
"86.82800","7.23585","0.01583"
"87.00200","7.25044","0.01665"
"87.17600","7.26479","0.01637"
"87.35000","7.27938","0.01627"
"87.52400","7.29390","0.01651"
"87.69800","7.30837","0.01685"
"87.87200","7.32290","0.01711"
"88.04600","7.33743","0.01656"
"88.22000","7.35184","0.01622"
"88.39400","7.36637","0.01652"
"88.56800","7.38084","0.01689"
"88.74200","7.39537","0.01646"
"88.91600","7.40990","0.01666"
"89.09000","7.42431","0.01659"
"89.26400","7.43883","0.01640"
"89.43800","7.45336","0.01728"
"89.61200","7.46789","0.01639"
"89.78600","7.48236","0.01655"
"89.96000","7.49683","0.01661"
"90.13400","7.51136","0.01738"
"90.30800","7.52589","0.01768"
"90.48200","7.54036","0.01723"
"90.65600","7.55489","0.01704"
"90.83000","7.56930","0.01689"
"91.00400","7.58382","0.01664"
"91.17800","7.59841","0.01690"
"91.35200","7.61288","0.01672"
"91.52600","7.62735","0.01673"
"91.70000","7.64188","0.01703"
"91.87400","7.65641","0.01716"
"92.04800","7.67082","0.01674"
"92.22200","7.68541","0.01741"
"92.39600","7.69988","0.01738"
"92.57000","7.71434","0.01742"
"92.74400","7.72893","0.01712"
"92.91800","7.74340","0.01718"
"93.09200","7.75781","0.01759"
"93.26600","7.77240","0.01760"
"93.44000","7.78693","0.01731"
"93.61400","7.80134","0.01729"
"93.78800","7.81587","0.01745"
"93.96200","7.83040","0.01766"
"94.13600","7.84487","0.01760"
"94.31000","7.85939","0.01796"
"94.48400","7.87392","0.01786"
"94.65800","7.88833","0.01771"
"94.83200","7.90280","0.01784"
"95.00600","7.91739","0.01833"
"95.18000","7.93180","0.01792"
"95.35400","7.94633","0.01841"
"95.52800","7.96092","0.01798"
"95.70200","7.97533","0.01809"
"95.87600","7.98979","0.01846"
"96.05000","8.00444","0.01872"
"96.22400","8.01891","0.01853"
"96.39800","8.03332","0.01821"
"96.57200","8.04785","0.01784"
"96.74600","8.06238","0.01898"
"96.92000","8.07685","0.01886"
"97.09400","8.09138","0.01864"
"97.26800","8.10585","0.01863"
"97.44200","8.12032","0.01882"
"97.61600","8.13490","0.01845"
"97.79000","8.14943","0.01882"
"97.96400","8.16384","0.01874"
"98.13800","8.17837","0.01856"
"98.31200","8.19284","0.01935"
"98.48600","8.20737","0.01893"
"98.66000","8.22184","0.01848"
"98.83400","8.23643","0.01879"
"99.00800","8.25090","0.01879"
"99.18200","8.26542","0.01930"
"99.35600","8.27989","0.01859"
"99.53000","8.29430","0.01889"
"99.70400","8.30889","0.01914"
"99.87800","8.32336","0.01867"
"100.05200","8.33783","0.01992"
"100.22600","8.35242","0.01899"
"100.40000","8.36689","0.01987"
"100.57400","8.38136","0.01946"
"100.74800","8.39589","0.01948"
"100.92200","8.41041","0.01894"
"101.09600","8.42488","0.01871"
"101.27000","8.43941","0.01886"
"101.44400","8.45388","0.01849"
"101.61800","8.46835","0.01877"
"101.79200","8.48282","0.01872"
"101.96600","8.49741","0.01849"
"102.14000","8.51188","0.01878"
"102.31400","8.52629","0.01860"
"102.48800","8.54093","0.01880"
"102.66200","8.55540","0.01912"
"102.83600","8.56981","0.01910"
"103.01000","8.58446","0.01981"
"103.18400","8.59887","0.01901"
"103.35800","8.61334","0.01952"
"103.53200","8.62793","0.01985"
"103.70600","8.64240","0.01859"
"103.88000","8.65681","0.01903"
"104.05400","8.67134","0.01911"
"104.22800","8.68592","0.01948"
"104.40200","8.70033","0.01857"
"104.57600","8.71492","0.01932"
"104.75000","8.72939","0.01932"
"104.92400","8.74380","0.01885"
"105.09800","8.75839","0.01853"
"105.27200","8.77292","0.01827"
"105.44600","8.78739","0.01733"
"105.62000","8.80186","0.01856"
"105.79400","8.81638","0.01892"
"105.96800","8.83085","0.01913"
"106.14200","8.84532","0.01897"
"106.31600","8.85985","0.01952"
"106.49000","8.87432","0.01948"
"106.66400","8.88885","0.01891"
"106.83800","8.90338","0.01895"
"107.01200","8.91791","0.01937"
"107.18600","8.93232","0.01925"
"107.36000","8.94691","0.01918"
"107.53400","8.96138","0.02000"
"107.70800","8.97584","0.01996"
"107.88200","8.99037","0.01996"
"108.05600","9.00484","0.01965"
"108.23000","9.01931","0.02050"
"108.40400","9.03396","0.01977"
"108.57800","9.04831","0.02026"
"108.75200","9.06284","0.01984"
"108.92600","9.07737","0.02021"
"109.10000","9.09190","0.02047"
"109.27400","9.10636","0.02052"
"109.44800","9.12095","0.02045"
"109.62200","9.13536","0.02075"
"109.79600","9.14983","0.02025"
"109.97000","9.16442","0.01999"
"110.14400","9.17889","0.01981"
"110.31800","9.19336","0.02007"
"110.49200","9.20789","0.02003"
"110.66600","9.22242","0.02053"
"110.84000","9.23683","0.02035"
"111.01400","9.25141","0.02030"
"111.18800","9.26588","0.02097"
"111.36200","9.28035","0.02045"
"111.53600","9.29488","0.02050"
"111.71000","9.30941","0.02111"
"111.88400","9.32382","0.02144"
"112.05800","9.33835","0.02151"
"112.23200","9.35288","0.02142"
"112.40600","9.36735","0.02083"
"112.58000","9.38187","0.02124"
"112.75400","9.39634","0.02144"
"112.92800","9.41081","0.02150"
"113.10200","9.42534","0.02153"
"113.27600","9.43993","0.02214"
"113.45000","9.45440","0.02070"
"113.62400","9.46887","0.02107"
"113.79800","9.48340","0.02118"
"113.97200","9.49793","0.02154"
"114.14600","9.51233","0.02197"
"114.32000","9.52687","0.02126"
"114.49400","9.54145","0.02171"
"114.66800","9.55574","0.02174"
"114.84200","9.57039","0.02183"
"115.01600","9.58492","0.02183"
"115.19000","9.59933","0.02173"
"115.36400","9.61392","0.02182"
"115.53800","9.62833","0.02179"
"115.71200","9.64286","0.02237"
"115.88600","9.65738","0.02203"
"116.06000","9.67191","0.02268"
"116.23400","9.68638","0.02245"
"116.40800","9.70091","0.02223"
"116.58200","9.71538","0.02243"
"116.75600","9.72985","0.02272"
"116.93000","9.74438","0.02308"
"117.10400","9.75885","0.02298"
"117.27800","9.77338","0.02304"
"117.45200","9.78790","0.02379"
"117.62600","9.80237","0.02346"
"117.80000","9.81678","0.02367"
"117.97400","9.83137","0.02477"
"118.14800","9.84590","0.02418"
"118.32200","9.86037","0.02403"
"118.49600","9.87484","0.02417"
"118.67000","9.88937","0.02424"
"118.84400","9.90384","0.02126"
"119.01800","9.91837","0.02073"
"119.19200","9.93290","0.02052"
"119.36600","9.94736","0.02102"
"119.54000","9.96183","0.02065"
"119.71400","9.97642","0.02124"
"119.88800","9.99089","0.02078"
"120.06200","10.00536","0.02114"
"120.23600","10.01989","0.02142"
"120.41000","10.03436","0.02204"
"120.58400","10.04889","0.02120"
"120.75800","10.06342","0.02113"
"120.93200","10.07788","0.02205"
"121.10600","10.09229","0.02198"
"121.28000","10.10688","0.02205"
"121.45400","10.12141","0.02281"
"121.62800","10.13582","0.02376"
"121.80200","10.15035","0.02233"
"121.97600","10.16488","0.02348"
"122.15000","10.17935","0.02347"
"122.32400","10.19388","0.02386"
"122.49800","10.20840","0.02406"
"122.67200","10.22281","0.02331"
"122.84600","10.23740","0.02455"
"123.02000","10.25193","0.02441"
"123.19400","10.26634","0.02473"
"123.36800","10.28087","0.02504"
"123.54200","10.29540","0.02544"
"123.71600","10.30987","0.02594"
"123.89000","10.32440","0.02497"
"124.06400","10.33892","0.02338"
"124.23800","10.35334","0.02345"
"124.41200","10.36780","0.02423"
"124.58600","10.38239","0.02318"
"124.76000","10.39692","0.02299"
"124.93400","10.41139","0.02371"
"125.10800","10.42586","0.02350"
"125.28200","10.44033","0.02457"
"125.45600","10.45486","0.02523"
"125.63000","10.46939","0.02453"
"125.80400","10.48386","0.02505"
"125.97800","10.49832","0.02578"
"126.15200","10.51285","0.02626"
"126.32600","10.52738","0.02667"
"126.50000","10.54185","0.02642"
"126.67400","10.55644","0.02740"
"126.84800","10.57085","0.02760"
"127.02200","10.58532","0.02710"
"127.19600","10.59991","0.02689"
"127.37000","10.61438","0.02696"
"127.54400","10.62885","0.02778"
"127.71800","10.64337","0.02812"
"127.89200","10.65790","0.02816"
"128.06600","10.67237","0.02868"
"128.24000","10.68684","0.02934"
"128.41400","10.70137","0.02983"
"128.58800","10.71584","0.02987"
"128.76200","10.73037","0.02998"
"128.93600","10.74490","0.03086"
"129.11000","10.75937","0.03104"
"129.28400","10.77383","0.03201"
"129.45800","10.78836","0.03205"
"129.63200","10.80283","0.03264"
"129.80600","10.81736","0.03278"
"129.98000","10.83189","0.03392"
"130.15400","10.84636","0.03350"
"130.32800","10.86083","0.03382"
"130.50200","10.87542","0.03414"
"130.67600","10.88989","0.03490"
"130.85000","10.90436","0.03555"
"131.02400","10.91888","0.03635"
"131.19800","10.93341","0.03575"
"131.37200","10.94788","0.03611"
"131.54600","10.96235","0.03683"
"131.72000","10.97688","0.03735"
"131.89400","10.99129","0.03744"
"132.06800","11.00588","0.03841"
"132.24200","11.02041","0.03841"
"132.41600","11.03482","0.03877"
"132.59000","11.04941","0.03974"
"132.76400","11.06387","0.03957"
"132.93800","11.07834","0.03968"
"133.11200","11.09287","0.04032"
"133.28600","11.10734","0.04156"
"133.46000","11.12181","0.04139"
"133.63400","11.13634","0.04212"
"133.80800","11.15087","0.04242"
"133.98200","11.16534","0.04251"
"134.15600","11.17986","0.04264"
"134.33000","11.19440","0.04289"
"134.50400","11.20886","0.04337"
"134.67800","11.22333","0.04316"
"134.85200","11.23786","0.04413"
"135.02600","11.25239","0.04399"
"135.20000","11.26686","0.04489"
"135.37400","11.28139","0.04494"
"135.54800","11.29586","0.04566"
"135.72200","11.31039","0.04571"
"135.89600","11.32486","0.04571"
"136.07000","11.33932","0.04620"
"136.24400","11.35391","0.04619"
"136.41800","11.36838","0.04682"
"136.59200","11.38285","0.04736"
"136.76600","11.39726","0.04731"
"136.94000","11.41197","0.04777"
"137.11400","11.42644","0.04822"
"137.28800","11.44079","0.04818"
"137.46200","11.45544","0.04862"
"137.63600","11.46990","0.04878"
"137.81000","11.48431","0.04923"
"137.98400","11.49890","0.04969"
"138.15800","11.51337","0.04985"
"138.33200","11.52778","0.04999"
"138.50600","11.54237","0.05019"
"138.68000","11.55690","0.04994"
"138.85400","11.57137","0.05024"
"139.02800","11.58590","0.05011"
"139.20200","11.60042","0.05082"
"139.37600","11.61483","0.05118"
"139.55000","11.62942","0.05158"
"139.72400","11.64389","0.05232"
"139.89800","11.65830","0.05277"
"140.07200","11.67289","0.05284"
"140.24600","11.68736","0.05386"
"140.42000","11.70183","0.05395"
"140.59400","11.71636","0.05455"
"140.76800","11.73083","0.05494"
"140.94200","11.74535","0.05536"
"141.11600","11.75988","0.05571"
"141.29000","11.77441","0.05563"
"141.46400","11.78888","0.05666"
"141.63800","11.80335","0.05690"
"141.81200","11.81788","0.05763"
"141.98600","11.83241","0.05871"
"142.16000","11.84688","0.05953"
"142.33400","11.86141","0.05900"
"142.50800","11.87582","0.06013"
"142.68200","11.89034","0.06053"
"142.85600","11.90487","0.06110"
"143.03000","11.91934","0.06206"
"143.20400","11.93387","0.06276"
"143.37800","11.94834","0.06413"
"143.55200","11.96293","0.06427"
"143.72600","11.97734","0.06501"
"143.90000","11.99187","0.06627"
"144.07400","12.00640","0.06704"
"144.24800","12.02081","0.06774"
"144.42200","12.03545","0.06861"
"144.59600","12.04986","0.06973"
"144.77000","12.06427","0.07072"
"144.94400","12.07892","0.07165"
"145.11800","12.09339","0.07153"
"145.29200","12.10786","0.07244"
"145.46600","12.12239","0.07335"
"145.64000","12.13686","0.07376"
"145.81400","12.15133","0.07518"
"145.98800","12.16591","0.07551"
"146.16200","12.18038","0.07690"
"146.33600","12.19485","0.07790"
"146.51000","12.20932","0.07839"
"146.68400","12.22391","0.07953"
"146.85800","12.23832","0.08016"
"147.03200","12.25285","0.08085"
"147.20600","12.26738","0.08213"
"147.38000","12.28185","0.08259"
"147.55400","12.29638","0.08414"
"147.72800","12.31090","0.08428"
"147.90200","12.32537","0.08114"
"148.07600","12.33984","0.07664"
"148.25000","12.35437","0.07832"
"148.42400","12.36890","0.08001"
"148.59800","12.38337","0.08257"
"148.77200","12.39790","0.08221"
"148.94600","12.41231","0.08459"
"149.12000","12.42678","0.08542"
"149.29400","12.44142","0.08551"
"149.46800","12.45589","0.08849"
"149.64200","12.47030","0.08779"
"149.81600","12.48489","0.08889"
"149.99000","12.49936","0.09121"
"150.16400","12.51383","0.09138"
"150.33800","12.52842","0.09190"
"150.51200","12.54289","0.09228"
"150.68600","12.55736","0.09311"
"150.86000","12.57189","0.09409"
"151.03400","12.58635","0.09423"
"151.20800","12.60082","0.09548"
"151.38200","12.61535","0.09528"
"151.55600","12.62988","0.09613"
"151.73000","12.64435","0.09706"
"151.90400","12.65888","0.09715"
"152.07800","12.67341","0.09810"
"152.25200","12.68782","0.09839"
"152.42600","12.70241","0.09893"
"152.60000","12.71687","0.09931"
"152.77400","12.73134","0.09948"
"152.94800","12.74581","0.10021"
"153.12200","12.76034","0.10053"
"153.29600","12.77487","0.10099"
"153.47000","12.78940","0.10196"
"153.64400","12.80393","0.10163"
"153.81800","12.81834","0.10336"
"153.99200","12.83281","0.10314"
"154.16600","12.84739","0.10469"
"154.34000","12.86187","0.10579"
"154.51400","12.87633","0.10622"
"154.68800","12.89092","0.10768"
"154.86200","12.90533","0.10815"
"155.03600","12.91986","0.10939"
"155.21000","12.93439","0.11062"
"155.38400","12.94886","0.11064"
"155.55800","12.96327","0.11307"
"155.73200","12.97792","0.11348"
"155.90600","12.99239","0.11300"
"156.08000","13.00686","0.11465"
"156.25400","13.02138","0.11529"
"156.42800","13.03585","0.11658"
"156.60200","13.05038","0.11733"
"156.77600","13.06491","0.11803"
"156.95000","13.07938","0.11925"
"157.12400","13.09385","0.11994"
"157.29800","13.10832","0.12107"
"157.47200","13.12290","0.12190"
"157.64600","13.13732","0.12357"
"157.82000","13.15190","0.12426"
"157.99400","13.16637","0.12468"
"158.16800","13.18090","0.12540"
"158.34200","13.19537","0.12633"
"158.51600","13.20990","0.12798"
"158.69000","13.22437","0.12803"
"158.86400","13.23884","0.12813"
"159.03800","13.25343","0.12456"
"159.21200","13.26790","0.12466"
"159.38600","13.28236","0.12681"
"159.56000","13.29689","0.12682"
"159.73400","13.31136","0.12878"
"159.90800","13.32583","0.12891"
"160.08200","13.34042","0.13035"
"160.25600","13.35483","0.13093"
"160.43000","13.36930","0.13218"
"160.60400","13.38389","0.13274"
"160.77800","13.39836","0.13323"
"160.95200","13.41288","0.13336"
"161.12600","13.42741","0.13416"
"161.30000","13.44188","0.13502"
"161.47400","13.45629","0.13534"
"161.64800","13.47094","0.13616"
"161.82200","13.48535","0.13702"
"161.99600","13.49982","0.13747"
"162.17000","13.51441","0.13763"
"162.34400","13.52894","0.13805"
"162.51800","13.54335","0.13841"
"162.69200","13.55788","0.13909"
"162.86600","13.57240","0.13950"
"163.04000","13.58681","0.13963"
"163.21400","13.60140","0.14049"
"163.38800","13.61587","0.14089"
"163.56200","13.63040","0.14084"
"163.73600","13.64487","0.14147"
"163.91000","13.65934","0.14191"
"164.08400","13.67381","0.14236"
"164.25800","13.68839","0.14324"
"164.43200","13.70286","0.14313"
"164.60600","13.71733","0.14403"
"164.78000","13.73186","0.14414"
"164.95400","13.74645","0.14493"
"165.12800","13.76086","0.14545"
"165.30200","13.77533","0.14575"
"165.47600","13.78986","0.14624"
"165.65000","13.80439","0.14659"
"165.82400","13.81886","0.14709"
"165.99800","13.83333","0.14788"
"166.17200","13.84785","0.14824"
"166.34600","13.86232","0.14860"
"166.52000","13.87697","0.14935"
"166.69400","13.89138","0.15003"
"166.86800","13.90579","0.15039"
"167.04200","13.92038","0.15132"
"167.21600","13.93491","0.15242"
"167.39000","13.94932","0.15314"
"167.56400","13.96391","0.15346"
"167.73800","13.97843","0.15477"
"167.91200","13.99284","0.15606"
"168.08600","14.00743","0.15718"
"168.26000","14.02190","0.15910"
"168.43400","14.03637","0.15948"
"168.60800","14.05084","0.16097"
"168.78200","14.06537","0.16237"
"168.95600","14.07984","0.16364"
"169.13000","14.09437","0.16383"
"169.30400","14.10889","0.16608"
"169.47800","14.12330","0.16833"
"169.65200","14.13789","0.16766"
"169.82600","14.15242","0.16923"
"170.00000","14.16683","0.17059"
"170.17400","14.18136","0.17230"
"170.34800","14.19583","0.17482"
"170.52200","14.21036","0.17728"
"170.69600","14.22489","0.17812"
"170.87000","14.23942","0.18138"
"171.04400","14.25388","0.18338"
"171.21800","14.26830","0.18534"
"171.39200","14.28288","0.18708"
"171.56600","14.29735","0.18971"
"171.74000","14.31176","0.14553"
"171.91400","14.32641","0.13940"
"172.08800","14.34088","0.13749"
"172.26200","14.35535","0.14175"
"172.43600","14.36988","0.13909"
"172.61000","14.38435","0.14305"
"172.78400","14.39882","0.14170"
"172.95800","14.41334","0.14308"
"173.13200","14.42793","0.14442"
"173.30600","14.44228","0.14425"
"173.48000","14.45687","0.14633"
"173.65400","14.47140","0.14537"
"173.82800","14.48587","0.14750"
"174.00200","14.50040","0.14690"
"174.17600","14.51493","0.14811"
"174.35000","14.52934","0.14864"
"174.52400","14.54386","0.14867"
"174.69800","14.55839","0.14525"
"174.87200","14.57280","0.14374"
"175.04600","14.58739","0.14630"
"175.22000","14.60186","0.14606"
"175.39400","14.61633","0.14760"
"175.56800","14.63092","0.14839"
"175.74200","14.64539","0.14872"
"175.91600","14.65986","0.15136"
"176.09000","14.67432","0.15083"
"176.26400","14.68891","0.15430"
"176.43800","14.70332","0.15291"
"176.61200","14.71785","0.15614"
"176.78600","14.73238","0.15597"
"176.96000","14.74685","0.15805"
"177.13400","14.76138","0.15917"
"177.30800","14.77591","0.16022"
"177.48200","14.79038","0.16295"
"177.65600","14.80484","0.16175"
"177.83000","14.81937","0.16625"
"178.00400","14.83396","0.16506"
"178.17800","14.84831","0.16857"
"178.35200","14.86290","0.16750"
"178.52600","14.87737","0.16987"
"178.70000","14.89178","0.17083"
"178.87400","14.90637","0.17174"
"179.04800","14.92090","0.17431"
"179.22200","14.93531","0.17431"
"179.39600","14.94990","0.17850"
"179.57000","14.96442","0.17512"
"179.74400","14.97883","0.17855"
"179.91800","14.99342","0.17737"
"180.09200","15.00789","0.18015"
"180.26600","15.02236","0.18083"
"180.44000","15.03689","0.18198"
"180.61400","15.05136","0.18355"
"180.78800","15.06589","0.18534"
"180.96200","15.08036","0.18688"
"181.13600","15.09488","0.18744"
"181.31000","15.10929","0.18904"
"181.48400","15.12388","0.18853"
"181.65800","15.13835","0.19076"
"181.83200","15.15282","0.18577"
"182.00600","15.16741","0.18739"
"182.18000","15.18188","0.18691"
"182.35400","15.19635","0.18978"
"182.52800","15.21088","0.19000"
"182.70200","15.22541","0.19186"
"182.87600","15.23987","0.19311"
"183.05000","15.25434","0.19324"
"183.22400","15.26887","0.19616"
"183.39800","15.28340","0.19623"
"183.57200","15.29787","0.19813"
"183.74600","15.31240","0.19815"
"183.92000","15.32687","0.20019"
"184.09400","15.34134","0.19979"
"184.26800","15.35587","0.20138"
"184.44200","15.37039","0.20146"
"184.61600","15.38486","0.20251"
"184.79000","15.39939","0.20264"
"184.96400","15.41386","0.20316"
"185.13800","15.42833","0.20336"
"185.31200","15.44292","0.20402"
"185.48600","15.45739","0.20291"
"185.66000","15.47180","0.20331"
"185.83400","15.48639","0.20386"
"186.00800","15.50085","0.20410"
"186.18200","15.51539","0.20491"
"186.35600","15.52985","0.20531"
"186.53000","15.54438","0.20600"
"186.70400","15.55885","0.20397"
"186.87800","15.57338","0.20372"
"187.05200","15.58791","0.20462"
"187.22600","15.60232","0.20456"
"187.40000","15.61691","0.20470"
"187.57400","15.63138","0.20499"
"187.74800","15.64584","0.20535"
"187.92200","15.66031","0.20553"
"188.09600","15.67490","0.20619"
"188.27000","15.68937","0.20642"
"188.44400","15.70384","0.20702"
"188.61800","15.71843","0.20730"
"188.79200","15.73290","0.20782"
"188.96600","15.74731","0.20792"
"189.14000","15.76190","0.20875"
"189.31400","15.77642","0.20811"
"189.48800","15.79083","0.20880"
"189.66200","15.80542","0.20930"
"189.83600","15.81983","0.20979"
"190.01000","15.83430","0.21044"
"190.18400","15.84889","0.21052"
"190.35800","15.86342","0.21112"
"190.53200","15.87783","0.21220"
"190.70600","15.89236","0.21267"
"190.88000","15.90689","0.21343"
"191.05400","15.92135","0.21369"
"191.22800","15.93588","0.21421"
"191.40200","15.95041","0.21479"
"191.57600","15.96482","0.21595"
"191.75000","15.97935","0.21691"
"191.92400","15.99388","0.21777"
"192.09800","16.00835","0.21835"
"192.27200","16.02288","0.21783"
"192.44600","16.03735","0.21859"
"192.62000","16.05182","0.21848"
"192.79400","16.06640","0.21991"
"192.96800","16.08087","0.22044"
"193.14200","16.09534","0.22124"
"193.31600","16.10987","0.22201"
"193.49000","16.12440","0.22106"
"193.66400","16.13887","0.22135"
"193.83800","16.15334","0.22212"
"194.01200","16.16787","0.22269"
"194.18600","16.18233","0.22353"
"194.36000","16.19686","0.22470"
"194.53400","16.21139","0.22393"
"194.70800","16.22580","0.22523"
"194.88200","16.24033","0.22516"
"195.05600","16.25492","0.22667"
"195.23000","16.26939","0.22631"
"195.40400","16.28386","0.22760"
"195.57800","16.29839","0.22782"
"195.75200","16.31286","0.22715"
"195.92600","16.32726","0.22715"
"196.10000","16.34191","0.22858"
"196.27400","16.35638","0.22846"
"196.44800","16.37079","0.22960"
"196.62200","16.38538","0.22966"
"196.79600","16.39991","0.23044"
"196.97000","16.41432","0.23114"
"197.14400","16.42891","0.23121"
"197.31800","16.44338","0.23172"
"197.49200","16.45785","0.23270"
"197.66600","16.47243","0.23227"
"197.84000","16.48690","0.23354"
"198.01400","16.50131","0.23446"
"198.18800","16.51584","0.23533"
"198.36200","16.53043","0.23679"
"198.53600","16.54484","0.23703"
"198.71000","16.55937","0.23838"
"198.88400","16.57384","0.23913"
"199.05800","16.58831","0.24009"
"199.23200","16.60290","0.24051"
"199.40600","16.61736","0.24137"
"199.58000","16.63189","0.24189"
"199.75400","16.64636","0.24238"
"199.92800","16.66089","0.24316"
"200.10200","16.67536","0.24352"
"200.27600","16.68983","0.24405"
"200.45000","16.70430","0.24447"
"200.62400","16.71883","0.24478"
"200.79800","16.73336","0.24523"
"200.97200","16.74794","0.24588"
"201.14600","16.76241","0.24598"
"201.32000","16.77682","0.24643"
"201.49400","16.79141","0.24655"
"201.66800","16.80588","0.24708"
"201.84200","16.82035","0.24736"
"202.01600","16.83488","0.24723"
"202.19000","16.84935","0.24746"
"202.36400","16.86382","0.24759"
"202.53800","16.87847","0.24780"
"202.71200","16.89287","0.24801"
"202.88600","16.90734","0.24827"
"203.06000","16.92187","0.24847"
"203.23600","16.93652","0.24870"
"203.41000","16.95099","0.24901"
"203.58400","16.96552","0.24925"
"203.75800","16.98005","0.24960"
"203.93200","16.99446","0.24968"
"204.10600","17.00911","0.24991"
"204.28000","17.02357","0.25010"
"204.45400","17.03798","0.25030"
"204.62800","17.05257","0.25048"
"204.80200","17.06704","0.25062"
"204.97600","17.08151","0.25107"
"205.15000","17.09604","0.25121"
"205.32400","17.11051","0.25158"
"205.49800","17.12498","0.25182"
"205.67200","17.13957","0.25198"
"205.84600","17.15410","0.25220"
"206.02000","17.16850","0.25250"
"206.19600","17.18315","0.25279"
"206.37000","17.19768","0.25292"
"206.54400","17.21221","0.25309"
"206.71800","17.22668","0.25341"
"206.89200","17.24121","0.25352"
"207.06600","17.25574","0.25390"
"207.24000","17.27015","0.25404"
"207.41400","17.28474","0.25414"
"207.58800","17.29921","0.25455"
"207.76200","17.31367","0.25457"
"207.93600","17.32820","0.25493"
"208.11000","17.34273","0.25519"
"208.28400","17.35720","0.25541"
"208.45800","17.37167","0.25586"
"208.63200","17.38620","0.25579"
"208.80600","17.40067","0.25596"
"208.98000","17.41520","0.25635"
"209.15400","17.42972","0.25654"
"209.32800","17.44413","0.25691"
"209.50200","17.45872","0.25717"
"209.67600","17.47319","0.25780"
"209.85000","17.48766","0.25776"
"210.02400","17.50213","0.25796"
"210.19800","17.51672","0.25791"
"210.37200","17.53113","0.25832"
"210.54600","17.54572","0.25911"
"210.72000","17.56019","0.25932"
"210.89400","17.57471","0.26026"
"211.06800","17.58918","0.26034"
"211.24200","17.60371","0.26034"
"211.41600","17.61818","0.26070"
"211.59000","17.63271","0.26153"
"211.76400","17.64718","0.26195"
"211.93800","17.66159","0.26363"
"212.11200","17.67618","0.26491"
"212.28600","17.69077","0.26526"
"212.46000","17.70524","0.26618"
"212.63400","17.71971","0.26649"
"212.80800","17.73423","0.26742"
"212.98200","17.74870","0.26796"
"213.15600","17.76317","0.26910"
"213.33000","17.77776","0.27000"
"213.50400","17.79217","0.27086"
"213.67800","17.80664","0.27105"
"213.85200","17.82123","0.27207"
"214.02600","17.83575","0.27331"
"214.20000","17.85016","0.27369"
"214.37400","17.86469","0.27395"
"214.54800","17.87922","0.27533"
"214.72200","17.89363","0.27599"
"214.89600","17.90822","0.27654"
"215.07000","17.92275","0.27776"
"215.24400","17.93716","0.27871"
"215.41800","17.95169","0.27960"
"215.59200","17.96628","0.28017"
"215.76600","17.98069","0.28149"
"215.94000","17.99516","0.28175"
"216.11400","18.00974","0.28287"
"216.28800","18.02415","0.28390"
"216.46200","18.03868","0.28506"
"216.63600","18.05321","0.28514"
"216.81000","18.06768","0.28689"
"216.98400","18.08221","0.28712"
"217.15800","18.09674","0.28827"
"217.33200","18.11121","0.28916"
"217.50600","18.12568","0.29045"
"217.68000","18.14014","0.29056"
"217.85400","18.15467","0.29237"
"218.02800","18.16920","0.29235"
"218.20200","18.18373","0.29348"
"218.37600","18.19820","0.29387"
"218.55000","18.21267","0.29495"
"218.72400","18.22720","0.29546"
"218.89800","18.24167","0.29581"
"219.07200","18.25614","0.29671"
"219.24600","18.27073","0.29704"
"219.42000","18.28519","0.29723"
"219.59400","18.29972","0.29811"
"219.76800","18.31425","0.29855"
"219.94200","18.32872","0.29870"
"220.11600","18.34313","0.29858"
"220.29000","18.35772","0.29962"
"220.46400","18.37219","0.29996"
"220.63800","18.38672","0.30116"
"220.81200","18.40125","0.30210"
"220.98600","18.41571","0.30274"
"221.16000","18.43012","0.30401"
"221.33400","18.44471","0.30436"
"221.50800","18.45924","0.30501"
"221.68200","18.47365","0.30607"
"221.85600","18.48818","0.30699"
"222.03000","18.50271","0.30880"
"222.20400","18.51718","0.30987"
"222.37800","18.53171","0.31146"
"222.55200","18.54623","0.31307"
"222.72600","18.56070","0.31512"
"222.90000","18.57517","0.31683"
"223.07400","18.58970","0.31845"
"223.24800","18.60423","0.32065"
"223.42200","18.61864","0.32211"
"223.59600","18.63323","0.32404"
"223.77000","18.64776","0.32602"
"223.94400","18.66217","0.32668"
"224.11800","18.67676","0.32877"
"224.29200","18.69117","0.32979"
"224.46600","18.70564","0.33205"
"224.64000","18.72022","0.33424"
"224.81400","18.73469","0.33515"
"224.98800","18.74916","0.33589"
"225.16200","18.76369","0.33700"
"225.33600","18.77828","0.33779"
"225.51000","18.79269","0.33810"
"225.68400","18.80721","0.33965"
"225.85800","18.82168","0.34018"
"226.03200","18.83615","0.34206"
"226.20600","18.85074","0.34264"
"226.38000","18.86521","0.34267"
"226.55400","18.87968","0.34444"
"226.72800","18.89421","0.34511"
"226.90200","18.90868","0.34602"
"227.07600","18.92321","0.34731"
"227.25000","18.93768","0.34755"
"227.42400","18.95221","0.34863"
"227.59800","18.96667","0.34971"
"227.77200","18.98120","0.35063"
"227.94600","18.99573","0.35139"
"228.12000","19.01020","0.35209"
"228.29400","19.02473","0.35250"
"228.46800","19.03920","0.35318"
"228.64200","19.05367","0.35302"
"228.81600","19.06820","0.35384"
"228.99000","19.08267","0.35417"
"229.16400","19.09714","0.35475"
"229.33800","19.11167","0.35497"
"229.51200","19.12625","0.35534"
"229.68600","19.14072","0.35593"
"229.86000","19.15519","0.35635"
"230.03400","19.16972","0.35662"
"230.20800","19.18425","0.35686"
"230.38200","19.19872","0.35703"
"230.55600","19.21325","0.35760"
"230.73000","19.22766","0.35749"
"230.90400","19.24212","0.35768"
"231.07800","19.25677","0.35795"
"231.25200","19.27130","0.35813"
"231.42600","19.28559","0.35824"
"231.60000","19.30024","0.35848"
"231.77400","19.31471","0.35856"
"231.94800","19.32912","0.35874"
"232.12200","19.34371","0.35894"
"232.29600","19.35824","0.35901"
"232.47000","19.37271","0.35934"
"232.64400","19.38717","0.35938"
"232.81800","19.40176","0.35942"
"232.99200","19.41623","0.35993"
"233.16600","19.43070","0.36002"
"233.34000","19.44523","0.36041"
"233.51400","19.45970","0.36039"
"233.68800","19.47423","0.36090"
"233.86200","19.48870","0.36111"
"234.03600","19.50317","0.36102"
"234.21000","19.51764","0.36156"
"234.38400","19.53222","0.36162"
"234.55800","19.54675","0.36193"
"234.73200","19.56116","0.36216"
"234.90600","19.57569","0.36237"
"235.08000","19.59016","0.36238"
"235.25400","19.60469","0.36267"
"235.42800","19.61922","0.36301"
"235.60200","19.63375","0.36348"
"235.77600","19.64822","0.36343"
"235.95000","19.66269","0.36393"
"236.12400","19.67721","0.36444"
"236.29800","19.69168","0.36511"
"236.47200","19.70621","0.36551"
"236.64600","19.72068","0.36632"
"236.82000","19.73521","0.36668"
"236.99400","19.74974","0.36738"
"237.16800","19.76421","0.36743"
"237.34200","19.77862","0.36809"
"237.51600","19.79321","0.36885"
"237.69000","19.80773","0.36913"
"237.86400","19.82220","0.37017"
"238.03800","19.83673","0.37058"
"238.21200","19.85120","0.37146"
"238.38600","19.86567","0.37223"
"238.56000","19.88026","0.37272"
"238.73400","19.89467","0.37371"
"238.90800","19.90920","0.37383"
"239.08200","19.92373","0.37477"
"239.25600","19.93819","0.37587"
"239.43000","19.95266","0.37569"
"239.60400","19.96719","0.37665"
"239.77800","19.98172","0.37776"
"239.95200","19.99619","0.37779"
"240.12600","20.01072","0.37926"
"240.30000","20.02525","0.38000"
"240.47400","20.03966","0.38069"
"240.64800","20.05413","0.38083"
"240.82200","20.06872","0.38171"
"240.99600","20.08319","0.38355"
"241.17000","20.09765","0.38416"
"241.34400","20.11218","0.38446"
"241.51800","20.12665","0.38518"
"241.69200","20.14118","0.38619"
"241.86600","20.15577","0.38691"
"242.04000","20.17018","0.38804"
"242.21400","20.18459","0.38862"
"242.38800","20.19923","0.38945"
"242.56200","20.21376","0.39035"
"242.73600","20.22817","0.39101"
"242.91000","20.24276","0.39168"
"243.08400","20.25723","0.39174"
"243.25800","20.27164","0.39136"
"243.43200","20.28623","0.39058"
"243.60600","20.30070","-0.01846"
"243.78000","20.31517","0.00524"
"243.95400","20.32969","0.00774"
"244.12800","20.34422","0.01105"
"244.30200","20.35869","0.01674"
"244.47600","20.37322","0.01199"
"244.65000","20.38769","0.01695"
"244.82400","20.40222","0.03181"
"244.99800","20.41675","0.02525"
"245.17200","20.43122","0.01421"
"245.34600","20.44569","0.02252"
"245.52000","20.46022","0.02540"
"245.69400","20.47469","0.01559"
"245.86800","20.48922","0.01998"
"246.04200","20.50368","0.02713"
"246.21600","20.51821","0.01901"
"246.39000","20.53262","0.01815"
"246.56400","20.54721","0.02527"
"246.73800","20.56174","0.02123"
"246.91200","20.57615","0.01831"
"247.08600","20.59074","0.02373"
"247.26000","20.60521","0.02297"
"247.43400","20.61974","0.01992"
"247.60800","20.63421","0.02332"
"247.78200","20.64874","0.02415"
"247.95600","20.66320","0.02087"
"248.13000","20.67761","0.02348"
"248.30400","20.69226","0.02466"
"248.47800","20.70673","0.02124"
"248.65200","20.72114","0.02315"
"248.82600","20.73573","0.02435"
"249.00000","20.75019","0.02192"
"249.17400","20.76467","0.02355"
"249.34800","20.77925","0.02502"
"249.52200","20.79372","0.02334"
"249.69600","20.80813","0.02430"
"249.87000","20.82272","0.02478"
"250.04400","20.83725","0.02410"
"250.21800","20.85166","0.02497"
"250.39200","20.86619","0.02570"
"250.56600","20.88072","0.02477"
"250.74000","20.89519","0.02506"
"250.91400","20.90966","0.02643"
"251.08800","20.92424","0.02545"
"251.26200","20.93865","0.02555"
"251.43600","20.95318","0.02741"
"251.61000","20.96771","0.02616"
"251.78400","20.98218","0.02541"
"251.95800","20.99665","0.02731"
"252.13200","21.01118","0.02637"
"252.30600","21.02571","0.02712"
"252.48000","21.04018","0.02823"
"252.65400","21.05470","0.02744"
"252.82800","21.06923","0.02801"
"253.00200","21.08364","0.02824"
"253.17600","21.09823","0.02830"
"253.35000","21.11270","0.02856"
"253.52400","21.12717","0.02859"
"253.69800","21.14170","0.02834"
"253.87200","21.15617","0.02888"
"254.04600","21.17070","0.02965"
"254.22000","21.18529","0.02919"
"254.39400","21.19963","0.02981"
"254.56800","21.21410","0.03016"
"254.74200","21.22869","0.02963"
"254.91600","21.24322","0.03042"
"255.09000","21.25763","0.03014"
"255.26400","21.27222","0.03016"
"255.43800","21.28669","0.03060"
"255.61200","21.30116","0.03051"
"255.78600","21.31575","0.03048"
"255.96000","21.33021","0.03133"
"256.13400","21.34468","0.03127"
"256.30800","21.35921","0.03155"
"256.48200","21.37368","0.03189"
"256.65600","21.38815","0.03206"
"256.83000","21.40274","0.03207"
"257.00400","21.41721","0.03180"
"257.17800","21.43168","0.03253"
"257.35200","21.44621","0.03224"
"257.52600","21.46074","0.03267"
"257.70000","21.47515","0.03273"
"257.87400","21.48967","0.03298"
"258.04800","21.50426","0.03368"
"258.22200","21.51873","0.03345"
"258.39600","21.53320","0.03358"
"258.57000","21.54773","0.03348"
"258.63200","21.55293","0.03305"