File: Force_trajectories/170212_1/Specimen_RawData_2.csv
End date,"2/12/2017"
Specimen label,"10BG_Unk2"
Maximum Load,"0.64592",N

Time,Extension,Load
(s),(mm),(N)
"0.00000","0.00000","-0.00043"
"0.19200","0.01309","0.00072"
"0.38400","0.03217","0.00154"
"0.57600","0.04825","0.00177"
"0.76800","0.06421","0.00270"
"0.96000","0.08024","0.00286"
"1.15200","0.09620","0.00344"
"1.34400","0.11228","0.00382"
"1.53600","0.12819","0.00338"
"1.72800","0.14421","0.00430"
"1.92000","0.16024","0.00470"
"2.11200","0.17620","0.00472"
"2.30400","0.19216","0.00543"
"2.49600","0.20819","0.00550"
"2.68800","0.22415","0.00523"
"2.88000","0.24023","0.00573"
"3.07200","0.25626","0.00586"
"3.26400","0.27222","0.00595"
"3.45600","0.28819","0.00641"
"3.64800","0.30427","0.00647"
"3.84000","0.32017","0.00682"
"4.03200","0.33620","0.00677"
"4.22400","0.35222","0.00727"
"4.41600","0.36812","0.00763"
"4.60800","0.38427","0.00758"
"4.80000","0.40023","0.00750"
"4.99200","0.41614","0.00830"
"5.18400","0.43228","0.00842"
"5.37600","0.44818","0.00833"
"5.56800","0.46415","0.00831"
"5.76000","0.48023","0.00862"
"5.95200","0.49613","0.00873"
"6.14400","0.51222","0.00893"
"6.33600","0.52824","0.00904"
"6.52800","0.54414","0.00902"
"6.72000","0.56023","0.00961"
"6.91200","0.57625","0.00941"
"7.10400","0.59222","0.00962"
"7.29600","0.60818","0.00996"
"7.48800","0.62420","0.00997"
"7.68000","0.64023","0.00976"
"7.87200","0.65619","0.01033"
"8.06400","0.67215","0.01004"
"8.25600","0.68824","0.01055"
"8.44800","0.70420","0.01064"
"8.64000","0.72016","0.01099"
"8.83200","0.73619","0.01113"
"9.02400","0.75221","0.01125"
"9.21600","0.76812","0.01112"
"9.40800","0.78426","0.01114"
"9.60000","0.80028","0.01091"
"9.79200","0.81613","0.01140"
"9.98400","0.83221","0.01173"
"10.17600","0.84823","0.01160"
"10.36800","0.86420","0.01198"
"10.56000","0.88016","0.01219"
"10.75200","0.89619","0.01194"
"10.94400","0.91221","0.01170"
"11.13600","0.92823","0.01201"
"11.32800","0.94420","0.01175"
"11.52000","0.96022","0.01313"
"11.71200","0.97624","0.01186"
"11.90400","0.99221","0.01262"
"12.09600","1.00823","0.01241"
"12.28800","1.02419","0.01229"
"12.48000","1.04016","0.01263"
"12.67200","1.05624","0.01280"
"12.86400","1.07221","0.01348"
"13.05600","1.08817","0.01306"
"13.24800","1.10419","0.01296"
"13.44000","1.12016","0.01272"
"13.63200","1.13624","0.01257"
"13.82400","1.15220","0.01360"
"14.01600","1.16817","0.01324"
"14.20800","1.18425","0.01351"
"14.40000","1.20022","0.01340"
"14.59200","1.21618","0.01398"
"14.78400","1.23220","0.01310"
"14.97600","1.24823","0.01380"
"15.16800","1.26413","0.01350"
"15.36000","1.28021","0.01406"
"15.55200","1.29618","0.01421"
"15.74400","1.31220","0.01437"
"15.93600","1.32822","0.01438"
"16.12800","1.34419","0.01388"
"16.32000","1.36015","0.01398"
"16.51200","1.37624","0.01462"
"16.70400","1.39220","0.01443"
"16.89600","1.40822","0.01421"
"17.08800","1.42425","0.01402"
"17.28000","1.44015","0.01482"
"17.47200","1.45623","0.01465"
"17.66400","1.47226","0.01428"
"17.85600","1.48810","0.01485"
"18.04800","1.50424","0.01476"
"18.24000","1.52027","0.01572"
"18.43200","1.53611","0.01461"
"18.62400","1.55220","0.01503"
"18.81600","1.56822","0.01462"
"19.00800","1.58418","0.01519"
"19.20000","1.60027","0.01543"
"19.39200","1.61617","0.01496"
"19.58400","1.63219","0.01521"
"19.77600","1.64822","0.01528"
"19.96800","1.66418","0.01533"
"20.16000","1.68027","0.01568"
"20.35200","1.69623","0.01559"
"20.54400","1.71219","0.01614"
"20.73600","1.72822","0.01509"
"20.92800","1.74418","0.01547"
"21.12000","1.76020","0.01610"
"21.31200","1.77617","0.01653"
"21.50400","1.79219","0.01601"
"21.69600","1.80821","0.01631"
"21.88800","1.82418","0.01583"
"22.08000","1.84020","0.01609"
"22.27200","1.85623","0.01636"
"22.46400","1.87219","0.01531"
"22.65600","1.88821","0.01682"
"22.84800","1.90418","0.01676"
"23.04000","1.92026","0.01534"
"23.23200","1.93616","0.01556"
"23.42400","1.95225","0.01671"
"23.61600","1.96815","0.01611"
"23.80800","1.98424","0.01597"
"24.00000","2.00026","0.01603"
"24.19200","2.01616","0.01606"
"24.38400","2.03219","0.01644"
"24.57600","2.04821","0.01676"
"24.76800","2.06417","0.01654"
"24.96000","2.08020","0.01672"
"25.15200","2.09616","0.01669"
"25.34400","2.11219","0.01716"
"25.53600","2.12827","0.01665"
"25.72800","2.14423","0.01706"
"25.92000","2.16008","0.01612"
"26.11200","2.17628","0.01676"
"26.30400","2.19224","0.01736"
"26.49600","2.20815","0.01610"
"26.68800","2.22423","0.01679"
"26.88000","2.24019","0.01699"
"27.07200","2.25616","0.01695"
"27.26400","2.27224","0.01703"
"27.45600","2.28821","0.01683"
"27.64800","2.30417","0.01678"
"27.84000","2.32019","0.01684"
"28.03200","2.33616","0.01685"
"28.22400","2.35218","0.01689"
"28.41600","2.36820","0.01682"
"28.60800","2.38417","0.01673"
"28.80000","2.40025","0.01675"
"28.99200","2.41627","0.01689"
"29.18400","2.43218","0.01709"
"29.37600","2.44820","0.01687"
"29.56800","2.46429","0.01709"
"29.76000","2.48019","0.01704"
"29.95200","2.49615","0.01720"
"30.14400","2.51218","0.01672"
"30.33600","2.52820","0.01703"
"30.52800","2.54422","0.01821"
"30.72000","2.56019","0.01778"
"30.91200","2.57621","0.01740"
"31.10400","2.59218","0.01725"
"31.29600","2.60820","0.01737"
"31.48800","2.62416","0.01744"
"31.68000","2.64019","0.01776"
"31.87200","2.65615","0.01808"
"32.06400","2.67223","0.01789"
"32.25600","2.68820","0.01728"
"32.44800","2.70416","0.01736"
"32.64000","2.72018","0.01734"
"32.83200","2.73615","0.01758"
"33.02400","2.75223","0.01734"
"33.21600","2.76820","0.01772"
"33.40800","2.78410","0.01757"
"33.60000","2.80018","0.01777"
"33.79200","2.81627","0.01762"
"33.98400","2.83217","0.01800"
"34.17600","2.84831","0.01810"
"34.36800","2.86422","0.01775"
"34.56000","2.88012","0.01804"
"34.75200","2.89620","0.01771"
"34.94400","2.91223","0.01806"
"35.13600","2.92819","0.01810"
"35.32800","2.94428","0.01799"
"35.52000","2.96018","0.01841"
"35.71200","2.97620","0.01776"
"35.90400","2.99223","0.01769"
"36.09600","3.00819","0.01776"
"36.28800","3.02421","0.01809"
"36.48000","3.04018","0.01781"
"36.67200","3.05614","0.01826"
"36.86400","3.07223","0.01889"
"37.05600","3.08825","0.01891"
"37.24800","3.10415","0.01887"
"37.44000","3.12024","0.01892"
"37.63200","3.13620","0.01806"
"37.82400","3.15216","0.01852"
"38.01600","3.16825","0.01818"
"38.20800","3.18415","0.01871"
"38.40000","3.20023","0.01821"
"38.59200","3.21620","0.01871"
"38.78400","3.23216","0.01832"
"38.97600","3.24819","0.01859"
"39.16800","3.26421","0.01850"
"39.36000","3.28017","0.01906"
"39.55200","3.29626","0.01856"
"39.74400","3.31222","0.01857"
"39.93600","3.32812","0.01867"
"40.12800","3.34421","0.01830"
"40.32000","3.36023","0.01909"
"40.51200","3.37620","0.01916"
"40.70400","3.39216","0.01886"
"40.89600","3.40818","0.01913"
"41.08800","3.42421","0.01913"
"41.28000","3.44017","0.01908"
"41.47200","3.45619","0.01863"
"41.66400","3.47222","0.01977"
"41.85600","3.48818","0.01911"
"42.04800","3.50420","0.01941"
"42.24000","3.52023","0.01878"
"42.43200","3.53625","0.01927"
"42.62400","3.55222","0.01937"
"42.81600","3.56818","0.01878"
"43.00800","3.58414","0.01913"
"43.20000","3.60017","0.01907"
"43.39200","3.61619","0.01915"
"43.58400","3.63221","0.01956"
"43.77600","3.64818","0.01944"
"43.96800","3.66420","0.01928"
"44.16000","3.68017","0.01942"
"44.35200","3.69625","0.01936"
"44.54400","3.71221","0.01975"
"44.73600","3.72818","0.01958"
"44.92800","3.74426","0.01950"
"45.12000","3.76022","0.01936"
"45.31200","3.77613","0.01991"
"45.50400","3.79221","0.01948"
"45.69600","3.80817","0.01980"
"45.88800","3.82420","0.01920"
"46.08000","3.84028","0.01958"
"46.27200","3.85619","0.01980"
"46.46400","3.87221","0.02048"
"46.65600","3.88823","0.01943"
"46.84800","3.90414","0.01994"
"47.04000","3.92022","0.01933"
"47.23200","3.93624","0.01996"
"47.42400","3.95215","0.01987"
"47.61600","3.96823","0.01989"
"47.80800","3.98420","0.01994"
"48.00000","4.00016","0.01967"
"48.19200","4.01624","0.01938"
"48.38400","4.03221","0.01994"
"48.57600","4.04817","0.01965"
"48.76800","4.06419","0.01996"
"48.96000","4.08022","0.01980"
"49.15200","4.09618","0.01984"
"49.34400","4.11220","0.01975"
"49.53600","4.12817","0.01971"
"49.72800","4.14425","0.02017"
"49.92000","4.16027","0.02009"
"50.11200","4.17624","0.01997"
"50.30400","4.19220","0.02018"
"50.49600","4.20823","0.02019"
"50.68800","4.22419","0.02026"
"50.88000","4.24021","0.02034"
"51.07200","4.25624","0.02049"
"51.26400","4.27220","0.02057"
"51.45600","4.28823","0.02037"
"51.64800","4.30419","0.02036"
"51.84000","4.32021","0.02013"
"52.03200","4.33624","0.02097"
"52.22400","4.35220","0.02015"
"52.41600","4.36822","0.02010"
"52.60800","4.38425","0.02030"
"52.80000","4.40015","0.01983"
"52.99200","4.41623","0.01965"
"53.18400","4.43220","0.01857"
"53.37600","4.44816","0.01884"
"53.56800","4.46425","0.01898"
"53.76000","4.48021","0.01925"
"53.95200","4.49623","0.01875"
"54.14400","4.51220","0.01917"
"54.33600","4.52816","0.01852"
"54.52800","4.54424","0.01903"
"54.72000","4.56021","0.01927"
"54.91200","4.57617","0.01931"
"55.10400","4.59219","0.01931"
"55.29600","4.60828","0.01940"
"55.48800","4.62418","0.01905"
"55.68000","4.64027","0.01899"
"55.87200","4.65623","0.01906"
"56.06400","4.67213","0.01909"
"56.25600","4.68828","0.01878"
"56.44800","4.70424","0.01940"
"56.64000","4.72020","0.01906"
"56.83200","4.73623","0.01931"
"57.02400","4.75219","0.01819"
"57.21600","4.76822","0.01837"
"57.40800","4.78430","0.01842"
"57.60000","4.80020","0.01845"
"57.79200","4.81623","0.01818"
"57.98400","4.83225","0.01806"
"58.17600","4.84815","0.01923"
"58.36800","4.86424","0.01855"
"58.56000","4.88020","0.01874"
"58.75200","4.89616","0.01862"
"58.94400","4.91219","0.01870"
"59.13600","4.92821","0.01885"
"59.32800","4.94418","0.01889"
"59.52000","4.96020","0.01898"
"59.71200","4.97622","0.01912"
"59.90400","4.99219","0.01857"
"60.09600","5.00815","0.01885"
"60.28800","5.02411","0.01941"
"60.48000","5.04020","0.01869"
"60.67200","5.05622","0.01920"
"60.86400","5.07213","0.01911"
"61.05600","5.08827","0.01857"
"61.24800","5.10423","0.01914"
"61.44000","5.12014","0.01874"
"61.63200","5.13622","0.01879"
"61.82400","5.15218","0.01867"
"62.01600","5.16821","0.01947"
"62.20800","5.18423","0.01916"
"62.40000","5.20014","0.01884"
"62.59200","5.21622","0.01924"
"62.78400","5.23224","0.01882"
"62.97600","5.24821","0.01909"
"63.16800","5.26423","0.01961"
"63.36000","5.28025","0.01957"
"63.55200","5.29616","0.01907"
"63.74400","5.31224","0.01941"
"63.93600","5.32820","0.01921"
"64.12800","5.34417","0.02004"
"64.32000","5.36019","0.02003"
"64.51200","5.37621","0.01887"
"64.70400","5.39212","0.01870"
"64.89600","5.40820","0.01863"
"65.08800","5.42417","0.01859"
"65.28000","5.44019","0.01830"
"65.47200","5.45621","0.01846"
"65.66400","5.47218","0.01859"
"65.85600","5.48820","0.01883"
"66.04800","5.50422","0.01873"
"66.24000","5.52019","0.01777"
"66.43200","5.53621","0.01887"
"66.62400","5.55218","0.01790"
"66.81600","5.56820","0.01870"
"67.00800","5.58422","0.01866"
"67.20000","5.60019","0.01892"
"67.39200","5.61615","0.01866"
"67.58400","5.63223","0.01823"
"67.77600","5.64820","0.01835"
"67.96800","5.66422","0.01880"
"68.16000","5.68019","0.01849"
"68.35200","5.69621","0.01877"
"68.54400","5.71223","0.01882"
"68.73600","5.72826","0.01839"
"68.92800","5.74416","0.01886"
"69.12000","5.76018","0.01871"
"69.31200","5.77627","0.01874"
"69.50400","5.79211","0.01839"
"69.69600","5.80825","0.01885"
"69.88800","5.82422","0.01893"
"70.08000","5.84018","0.01854"
"70.27200","5.85621","0.01896"
"70.46400","5.87223","0.01876"
"70.65600","5.88819","0.01878"
"70.84800","5.90422","0.01895"
"71.04000","5.92018","0.01921"
"71.23200","5.93614","0.01927"
"71.42400","5.95223","0.01890"
"71.61600","5.96819","0.01897"
"71.80800","5.98427","0.01850"
"72.00000","6.00024","0.01896"
"72.19200","6.01614","0.01895"
"72.38400","6.03229","0.01898"
"72.57600","6.04819","0.01936"
"72.76800","6.06421","0.01957"
"72.96000","6.08018","0.01921"
"73.15200","6.09620","0.01914"
"73.34400","6.11222","0.01863"
"73.53600","6.12819","0.01878"
"73.72800","6.14421","0.01861"
"73.92000","6.16024","0.01890"
"74.11200","6.17620","0.01887"
"74.30400","6.19216","0.01882"
"74.49600","6.20819","0.01901"
"74.68800","6.22421","0.01869"
"74.88000","6.24017","0.01872"
"75.07200","6.25632","0.01888"
"75.26400","6.27216","0.01898"
"75.45600","6.28819","0.01927"
"75.64800","6.30421","0.01906"
"75.84000","6.32017","0.01861"
"76.03200","6.33620","0.01911"
"76.22400","6.35216","0.01941"
"76.41600","6.36812","0.01945"
"76.60800","6.38421","0.01983"
"76.80000","6.40023","0.01886"
"76.99200","6.41613","0.01936"
"77.18400","6.43222","0.01939"
"77.37600","6.44818","0.01930"
"77.56800","6.46415","0.01924"
"77.76000","6.48023","0.01924"
"77.95200","6.49625","0.01917"
"78.14400","6.51210","0.01905"
"78.33600","6.52824","0.01884"
"78.52800","6.54420","0.01934"
"78.72000","6.56011","0.01903"
"78.91200","6.57619","0.01912"
"79.10400","6.59222","0.01895"
"79.29600","6.60818","0.01910"
"79.48800","6.62420","0.01924"
"79.68000","6.64017","0.01930"
"79.87200","6.65625","0.01881"
"80.06400","6.67221","0.01872"
"80.25600","6.68818","0.01886"
"80.44800","6.70420","0.01935"
"80.64000","6.72022","0.01938"
"80.83200","6.73619","0.01960"
"81.02400","6.75215","0.01887"
"81.21600","6.76824","0.01904"
"81.40800","6.78420","0.01941"
"81.60000","6.80016","0.01916"
"81.79200","6.81619","0.01968"
"81.98400","6.83221","0.01939"
"82.17600","6.84817","0.01890"
"82.36800","6.86420","0.01957"
"82.56000","6.88016","0.01953"
"82.75200","6.89618","0.02003"
"82.94400","6.91221","0.02048"
"83.13600","6.92823","0.01988"
"83.32800","6.94426","0.01990"
"83.52000","6.96022","0.02012"
"83.71200","6.97624","0.02013"
"83.90400","6.99221","0.02037"
"84.09600","7.00817","0.02002"
"84.28800","7.02419","0.02028"
"84.48000","7.04016","0.02039"
"84.67200","7.05624","0.02083"
"84.86400","7.07221","0.02045"
"85.05600","7.08817","0.02076"
"85.24800","7.10419","0.02067"
"85.44000","7.12028","0.02066"
"85.63200","7.13618","0.02069"
"85.82400","7.15226","0.02075"
"86.01600","7.16817","0.02108"
"86.20800","7.18413","0.02049"
"86.40000","7.20027","0.02104"
"86.59200","7.21618","0.02131"
"86.78400","7.23214","0.02132"
"86.97600","7.24823","0.02106"
"87.16800","7.26419","0.02105"
"87.36000","7.28015","0.02060"
"87.55200","7.29624","0.01957"
"87.74400","7.31220","0.01999"
"87.93600","7.32816","0.01994"
"88.12800","7.34425","0.02033"
"88.32000","7.36015","0.02103"
"88.51200","7.37617","0.02041"
"88.70400","7.39226","0.02108"
"88.89600","7.40816","0.02073"
"89.08800","7.42425","0.02129"
"89.28000","7.44021","0.02093"
"89.47200","7.45617","0.02055"
"89.66400","7.47220","0.02064"
"89.85600","7.48822","0.02051"
"90.04800","7.50418","0.02088"
"90.24000","7.52021","0.02166"
"90.43200","7.53617","0.02108"
"90.62400","7.55220","0.02140"
"90.81600","7.56822","0.02145"
"91.00800","7.58418","0.02089"
"91.20000","7.60021","0.02138"
"91.39200","7.61623","0.02209"
"91.58400","7.63219","0.02158"
"91.77600","7.64822","0.02138"
"91.96800","7.66418","0.02137"
"92.16000","7.68021","0.02195"
"92.35200","7.69617","0.02205"
"92.54400","7.71219","0.02164"
"92.73600","7.72822","0.02221"
"92.92800","7.74418","0.02273"
"93.12000","7.76020","0.02226"
"93.31200","7.77617","0.02193"
"93.50400","7.79219","0.02189"
"93.69600","7.80816","0.02204"
"93.88800","7.82424","0.02249"
"94.08000","7.84020","0.02284"
"94.27200","7.85622","0.02266"
"94.46400","7.87225","0.02267"
"94.65600","7.88815","0.02264"
"94.84800","7.90418","0.02274"
"95.04000","7.92020","0.02281"
"95.23200","7.93622","0.02350"
"95.42400","7.95219","0.02241"
"95.61600","7.96821","0.02235"
"95.80800","7.98417","0.02254"
"96.00000","8.00026","0.02300"
"96.19200","8.01622","0.02312"
"96.38400","8.03219","0.02336"
"96.57600","8.04815","0.02341"
"96.76800","8.06423","0.02301"
"96.96000","8.08014","0.02328"
"97.15200","8.09622","0.02376"
"97.34400","8.11218","0.02343"
"97.53600","8.12815","0.02338"
"97.72800","8.14423","0.02393"
"97.92000","8.16020","0.02392"
"98.11200","8.17616","0.02388"
"98.30400","8.19230","0.02399"
"98.49600","8.20809","0.02405"
"98.68800","8.22423","0.02423"
"98.88000","8.24025","0.02335"
"99.07200","8.25616","0.02428"
"99.26400","8.27224","0.02391"
"99.45600","8.28826","0.02482"
"99.64800","8.30417","0.02481"
"99.84000","8.32025","0.02443"
"100.03200","8.33622","0.02505"
"100.22400","8.35218","0.02506"
"100.41600","8.36820","0.02521"
"100.60800","8.38423","0.02554"
"100.80000","8.40025","0.02547"
"100.99200","8.41621","0.02547"
"101.18400","8.43218","0.02492"
"101.37600","8.44820","0.02630"
"101.56800","8.46422","0.02646"
"101.76000","8.48019","0.02655"
"101.95200","8.49621","0.02635"
"102.14400","8.51218","0.02629"
"102.33600","8.52820","0.02525"
"102.52800","8.54422","0.02549"
"102.72000","8.56019","0.02583"
"102.91200","8.57621","0.02603"
"103.10400","8.59223","0.02562"
"103.29600","8.60820","0.02593"
"103.48800","8.62422","0.02594"
"103.68000","8.64019","0.02686"
"103.87200","8.65621","0.02699"
"104.06400","8.67223","0.02676"
"104.25600","8.68826","0.02658"
"104.44800","8.70416","0.02704"
"104.64000","8.72018","0.02701"
"104.83200","8.73621","0.02672"
"105.02400","8.75217","0.02722"
"105.21600","8.76826","0.02756"
"105.40800","8.78416","0.02778"
"105.60000","8.80018","0.02780"
"105.79200","8.81621","0.02795"
"105.98400","8.83217","0.02798"
"106.17600","8.84819","0.02869"
"106.36800","8.86422","0.02822"
"106.56000","8.88012","0.02804"
"106.75200","8.89620","0.02769"
"106.94400","8.91223","0.02850"
"107.13600","8.92819","0.02809"
"107.32800","8.94421","0.02893"
"107.52000","8.96024","0.02857"
"107.71200","8.97614","0.02865"
"107.90400","8.99223","0.02918"
"108.09600","9.00819","0.02855"
"108.28800","9.02421","0.02804"
"108.48000","9.04018","0.02839"
"108.67200","9.05620","0.02858"
"108.86400","9.07216","0.02964"
"109.05600","9.08825","0.02880"
"109.24800","9.10421","0.02916"
"109.44000","9.12018","0.02888"
"109.63200","9.13620","0.02943"
"109.82400","9.15216","0.02923"
"110.01600","9.16819","0.02818"
"110.20800","9.18421","0.02822"
"110.40000","9.20017","0.02869"
"110.59200","9.21620","0.02788"
"110.78400","9.23222","0.02858"
"110.97600","9.24819","0.02857"
"111.16800","9.26421","0.02932"
"111.36000","9.28023","0.02888"
"111.55200","9.29620","0.02934"
"111.74400","9.31222","0.02931"
"111.93600","9.32818","0.02906"
"112.12800","9.34421","0.02962"
"112.32000","9.36023","0.02974"
"112.51200","9.37613","0.03029"
"112.70400","9.39222","0.02955"
"112.89600","9.40818","0.03045"
"113.08800","9.42421","0.02978"
"113.28000","9.44023","0.02996"
"113.47200","9.45625","0.02988"
"113.66400","9.47222","0.02968"
"113.85600","9.48824","0.03055"
"114.04800","9.50420","0.03039"
"114.24000","9.52023","0.03036"
"114.43200","9.53619","0.03059"
"114.62400","9.55216","0.03007"
"114.81600","9.56824","0.03034"
"115.00800","9.58420","0.03041"
"115.20000","9.60017","0.03040"
"115.39200","9.61625","0.03080"
"115.58400","9.63227","0.03026"
"115.77600","9.64818","0.03088"
"115.96800","9.66420","0.03066"
"116.16000","9.68028","0.03056"
"116.35200","9.69607","0.03113"
"116.54400","9.71221","0.03122"
"116.73600","9.72818","0.03135"
"116.92800","9.74420","0.03097"
"117.12000","9.76022","0.03154"
"117.31200","9.77619","0.03175"
"117.50400","9.79221","0.03124"
"117.69600","9.80823","0.03109"
"117.88800","9.82420","0.03142"
"118.08000","9.84022","0.03256"
"118.27200","9.85618","0.03205"
"118.46400","9.87215","0.03225"
"118.65600","9.88823","0.03280"
"118.84800","9.90420","0.03187"
"119.04000","9.92016","0.03170"
"119.23200","9.93624","0.03238"
"119.42400","9.95215","0.03268"
"119.61600","9.96823","0.03232"
"119.80800","9.98425","0.03219"
"120.00000","10.00016","0.03230"
"120.19200","10.01624","0.03252"
"120.38400","10.03221","0.03325"
"120.57600","10.04817","0.03331"
"120.76800","10.06419","0.03298"
"120.96000","10.08028","0.03345"
"121.15200","10.09618","0.03412"
"121.34400","10.11226","0.03362"
"121.53600","10.12823","0.03399"
"121.72800","10.14413","0.03414"
"121.92000","10.16022","0.03414"
"122.11200","10.17624","0.03393"
"122.30400","10.19220","0.03479"
"122.49600","10.20823","0.03482"
"122.68800","10.22419","0.03455"
"122.88000","10.24015","0.03473"
"123.07200","10.25618","0.03511"
"123.26400","10.27220","0.03495"
"123.45600","10.28822","0.03590"
"123.64800","10.30425","0.03535"
"123.84000","10.32015","0.03598"
"124.03200","10.33618","0.03592"
"124.22400","10.35220","0.03525"
"124.41600","10.36816","0.03503"
"124.60800","10.38419","0.03540"
"124.80000","10.40021","0.03552"
"124.99200","10.41617","0.03495"
"125.18400","10.43220","0.03512"
"125.37600","10.44822","0.03538"
"125.56800","10.46418","0.03586"
"125.76000","10.48021","0.03630"
"125.95200","10.49617","0.03619"
"126.14400","10.51226","0.03638"
"126.33600","10.52822","0.03637"
"126.52800","10.54418","0.03597"
"126.72000","10.56027","0.03626"
"126.91200","10.57617","0.03660"
"127.10400","10.59213","0.03685"
"127.29600","10.60822","0.03640"
"127.48800","10.62418","0.03709"
"127.68000","10.64015","0.03635"
"127.87200","10.65617","0.03696"
"128.06400","10.67213","0.03630"
"128.25600","10.68822","0.03667"
"128.44800","10.70424","0.03648"
"128.64000","10.72020","0.03610"
"128.83200","10.73623","0.03648"
"129.02400","10.75219","0.03651"
"129.21600","10.76821","0.03732"
"129.40800","10.78418","0.03719"
"129.60000","10.80020","0.03658"
"129.79200","10.81611","0.03727"
"129.98400","10.83225","0.03561"
"130.17600","10.84821","0.03629"
"130.36800","10.86412","0.03650"
"130.56000","10.88020","0.03651"
"130.75200","10.89622","0.03680"
"130.94400","10.91219","0.03750"
"131.13600","10.92821","0.03750"
"131.32800","10.94418","0.03797"
"131.52000","10.96020","0.03738"
"131.71200","10.97628","0.03787"
"131.90400","10.99219","0.03747"
"132.09600","11.00821","0.03787"
"132.28800","11.02423","0.03913"
"132.48000","11.04020","0.03782"
"132.67200","11.05622","0.03862"
"132.86400","11.07224","0.03886"
"133.05600","11.08821","0.03937"
"133.24800","11.10423","0.03868"
"133.44000","11.12020","0.03885"
"133.63200","11.13622","0.03902"
"133.82400","11.15218","0.03933"
"134.01600","11.16821","0.03933"
"134.20800","11.18423","0.03989"
"134.40000","11.20019","0.03933"
"134.59200","11.21622","0.03996"
"134.78400","11.23218","0.03974"
"134.97600","11.24815","0.04015"
"135.16800","11.26417","0.04032"
"135.36000","11.28025","0.04099"
"135.55200","11.29616","0.04104"
"135.74400","11.31218","0.04082"
"135.93600","11.32820","0.04094"
"136.12800","11.34417","0.04084"
"136.32000","11.36019","0.04011"
"136.51200","11.37621","0.04078"
"136.70400","11.39218","0.04036"
"136.89600","11.40820","0.04127"
"137.08800","11.42423","0.04108"
"137.28000","11.44019","0.04118"
"137.47200","11.45627","0.04133"
"137.66400","11.47224","0.04184"
"137.85600","11.48814","0.04130"
"138.04800","11.50428","0.04183"
"138.24000","11.52019","0.04161"
"138.43200","11.53615","0.04245"
"138.62400","11.55229","0.04222"
"138.81600","11.56826","0.04160"
"139.00800","11.58422","0.04233"
"139.20000","11.60025","0.04259"
"139.39200","11.61621","0.04230"
"139.58400","11.63217","0.04314"
"139.77600","11.64826","0.04336"
"139.96800","11.66410","0.04348"
"140.16000","11.68018","0.04315"
"140.35200","11.69621","0.04358"
"140.54400","11.71217","0.04355"
"140.73600","11.72820","0.04377"
"140.92800","11.74422","0.04353"
"141.12000","11.76012","0.04378"
"141.31200","11.77621","0.04421"
"141.50400","11.79223","0.04415"
"141.69600","11.80819","0.04453"
"141.88800","11.82422","0.04414"
"142.08000","11.84018","0.04465"
"142.27200","11.85620","0.04422"
"142.46400","11.87217","0.04442"
"142.65600","11.88819","0.04503"
"142.84800","11.90422","0.04496"
"143.04000","11.92018","0.04465"
"143.23200","11.93620","0.04525"
"143.42400","11.95223","0.04547"
"143.61600","11.96825","0.04523"
"143.80800","11.98421","0.04577"
"144.00000","12.00024","0.04505"
"144.19200","12.01614","0.04549"
"144.38400","12.03217","0.04508"
"144.57600","12.04825","0.04523"
"144.76800","12.06415","0.04559"
"144.96000","12.08018","0.04606"
"145.15200","12.09620","0.04605"
"145.34400","12.11216","0.04610"
"145.53600","12.12825","0.04566"
"145.72800","12.14421","0.04600"
"145.92000","12.16012","0.04629"
"146.11200","12.17626","0.04603"
"146.30400","12.19222","0.04645"
"146.49600","12.20813","0.04670"
"146.68800","12.22427","0.04675"
"146.88000","12.24023","0.04643"
"147.07200","12.25620","0.04728"
"147.26400","12.27222","0.04720"
"147.45600","12.28819","0.04723"
"147.64800","12.30421","0.04742"
"147.84000","12.32023","0.04742"
"148.03200","12.33619","0.04747"
"148.22400","12.35222","0.04707"
"148.41600","12.36818","0.04766"
"148.60800","12.38415","0.04746"
"148.80000","12.40023","0.04680"
"148.99200","12.41619","0.04735"
"149.18400","12.43216","0.04714"
"149.37600","12.44824","0.04743"
"149.56800","12.46420","0.04740"
"149.76000","12.48017","0.04748"
"149.95200","12.49625","0.04784"
"150.14400","12.51222","0.04781"
"150.33600","12.52818","0.04838"
"150.52800","12.54426","0.04855"
"150.72000","12.56017","0.04813"
"150.91200","12.57619","0.04777"
"151.10400","12.59221","0.04790"
"151.29600","12.60818","0.04854"
"151.48800","12.62420","0.04856"
"151.68000","12.64023","0.04860"
"151.87200","12.65619","0.04867"
"152.06400","12.67227","0.04920"
"152.25600","12.68824","0.04945"
"152.44800","12.70420","0.04939"
"152.64000","12.72022","0.04916"
"152.83200","12.73619","0.04947"
"153.02400","12.75215","0.04973"
"153.21600","12.76824","0.04954"
"153.40800","12.78420","0.04999"
"153.60000","12.80022","0.05023"
"153.79200","12.81625","0.04985"
"153.98400","12.83215","0.05012"
"154.17600","12.84823","0.05042"
"154.36800","12.86420","0.05045"
"154.56000","12.88022","0.05073"
"154.75200","12.89618","0.05065"
"154.94400","12.91215","0.04983"
"155.13600","12.92823","0.05015"
"155.32800","12.94420","0.05008"
"155.52000","12.96016","0.05032"
"155.71200","12.97624","0.05010"
"155.90400","12.99221","0.05021"
"156.09600","13.00817","0.05010"
"156.28800","13.02425","0.05007"
"156.48000","13.04022","0.05014"
"156.67200","13.05618","0.05009"
"156.86400","13.07226","0.05049"
"157.05600","13.08817","0.05055"
"157.24800","13.10413","0.05107"
"157.44000","13.12022","0.05121"
"157.63200","13.13624","0.05166"
"157.82400","13.15220","0.05183"
"158.01600","13.16823","0.05172"
"158.20800","13.18419","0.05202"
"158.40000","13.20021","0.05237"
"158.59200","13.21624","0.05226"
"158.78400","13.23220","0.05288"
"158.97600","13.24817","0.05280"
"159.16800","13.26425","0.05347"
"159.36000","13.28015","0.05348"
"159.55200","13.29624","0.05378"
"159.74400","13.31226","0.05377"
"159.93600","13.32822","0.05402"
"160.12800","13.34419","0.05439"
"160.32000","13.36021","0.05444"
"160.51200","13.37611","0.05489"
"160.70400","13.39220","0.05546"
"160.89600","13.40822","0.05550"
"161.08800","13.42419","0.05581"
"161.28000","13.44021","0.05639"
"161.47200","13.45617","0.05654"
"161.66400","13.47220","0.05724"
"161.85600","13.48822","0.05780"
"162.04800","13.50418","0.05822"
"162.24000","13.52021","0.05850"
"162.43200","13.53617","0.05860"
"162.62400","13.55220","0.05996"
"162.81600","13.56816","0.06065"
"163.00800","13.58424","0.06072"
"163.20000","13.60021","0.06141"
"163.39200","13.61617","0.06227"
"163.58400","13.63219","0.06239"
"163.77600","13.64816","0.06300"
"163.96800","13.66418","0.06294"
"164.16000","13.68020","0.06068"
"164.35200","13.69623","0.05997"
"164.54400","13.71225","0.06038"
"164.73600","13.72816","0.05858"
"164.92800","13.74424","0.05845"
"165.12000","13.76020","0.05753"
"165.31200","13.77617","0.05551"
"165.50400","13.79219","0.05583"
"165.69600","13.80821","0.05609"
"165.88800","13.82424","0.05627"
"166.08000","13.84020","0.05703"
"166.27200","13.85616","0.05650"
"166.46400","13.87225","0.05733"
"166.65600","13.88821","0.05768"
"166.84800","13.90418","0.05813"
"167.04000","13.92020","0.05816"
"167.23200","13.93628","0.05856"
"167.42400","13.95213","0.05899"
"167.61600","13.96821","0.05980"
"167.80800","13.98423","0.06022"
"168.00000","14.00014","0.06088"
"168.19200","14.01628","0.06141"
"168.38400","14.03219","0.06199"
"168.57600","14.04815","0.06203"
"168.76800","14.06423","0.06292"
"168.96000","14.08020","0.06336"
"169.15200","14.09616","0.06416"
"169.34400","14.11218","0.06461"
"169.53600","14.12821","0.06542"
"169.72800","14.14423","0.06649"
"169.92000","14.16026","0.06645"
"170.11200","14.17616","0.06752"
"170.30400","14.19218","0.06823"
"170.49600","14.20821","0.06902"
"170.68800","14.22411","0.06995"
"170.88000","14.24019","0.07050"
"171.07200","14.25628","0.07033"
"171.26400","14.27218","0.07211"
"171.45600","14.28820","0.07241"
"171.64800","14.30423","0.07224"
"171.84000","14.32019","0.07300"
"172.03200","14.33622","0.07315"
"172.22400","14.35218","0.07417"
"172.41600","14.36820","0.07466"
"172.60800","14.38423","0.07473"
"172.80000","14.40019","0.07497"
"172.99200","14.41627","0.07510"
"173.18400","14.43218","0.07640"
"173.37600","14.44814","0.07688"
"173.56800","14.46422","0.07700"
"173.76000","14.48025","0.07801"
"173.95200","14.49621","0.07799"
"174.14400","14.51218","0.07838"
"174.33600","14.52820","0.07904"
"174.52800","14.54416","0.07968"
"174.72000","14.56025","0.08008"
"174.91200","14.57615","0.08107"
"175.10400","14.59223","0.08115"
"175.29600","14.60826","0.08197"
"175.48800","14.62416","0.08251"
"175.68000","14.64025","0.08298"
"175.87200","14.65621","0.08317"
"176.06400","14.67217","0.08432"
"176.25600","14.68820","0.08460"
"176.44800","14.70422","0.08495"
"176.64000","14.72018","0.08567"
"176.83200","14.73621","0.08595"
"177.02400","14.75217","0.08672"
"177.21600","14.76820","0.08714"
"177.40800","14.78422","0.08777"
"177.60000","14.80018","0.08930"
"177.79200","14.81621","0.08953"
"177.98400","14.83223","0.08973"
"178.17600","14.84819","0.09035"
"178.36800","14.86422","0.09096"
"178.56000","14.88018","0.09083"
"178.75200","14.89614","0.09180"
"178.94400","14.91223","0.09216"
"179.13600","14.92819","0.09304"
"179.32800","14.94416","0.09427"
"179.52000","14.96024","0.09435"
"179.71200","14.97620","0.09478"
"179.90400","14.99223","0.09581"
"180.09600","15.00825","0.09697"
"180.28800","15.02421","0.09716"
"180.48000","15.04024","0.09770"
"180.67200","15.05620","0.09824"
"180.86400","15.07217","0.09855"
"181.05600","15.08825","0.09862"
"181.24800","15.10427","0.09960"
"181.44000","15.12012","0.09950"
"181.63200","15.13626","0.09872"
"181.82400","15.15222","0.09881"
"182.01600","15.16819","0.09955"
"182.20800","15.18421","0.09991"
"182.40000","15.20023","0.10045"
"182.59200","15.21620","0.10055"
"182.78400","15.23222","0.10125"
"182.97600","15.24813","0.10169"
"183.16800","15.26421","0.10168"
"183.36000","15.28023","0.10197"
"183.55200","15.29620","0.10233"
"183.74400","15.31222","0.10247"
"183.93600","15.32818","0.10291"
"184.12800","15.34421","0.10353"
"184.32000","15.36023","0.10416"
"184.51200","15.37619","0.10451"
"184.70400","15.39216","0.10481"
"184.89600","15.40818","0.10590"
"185.08800","15.42421","0.10631"
"185.28000","15.44023","0.10714"
"185.47200","15.45619","0.10782"
"185.66400","15.47216","0.10658"
"185.85600","15.48818","0.10813"
"186.04800","15.50420","0.10863"
"186.24000","15.52017","0.11037"
"186.43200","15.53619","0.11115"
"186.62400","15.55222","0.11183"
"186.81600","15.56818","0.11249"
"187.00800","15.58426","0.11377"
"187.20000","15.60017","0.11400"
"187.39200","15.61619","0.11586"
"187.58400","15.63227","0.11715"
"187.77600","15.64812","0.11815"
"187.96800","15.66420","0.11900"
"188.16000","15.68022","0.12055"
"188.35200","15.69619","0.12119"
"188.54400","15.71221","0.12195"
"188.73600","15.72823","0.12307"
"188.92800","15.74414","0.12486"
"189.12000","15.76028","0.12403"
"189.31200","15.77619","0.12493"
"189.50400","15.79215","0.12140"
"189.69600","15.80823","0.12176"
"189.88800","15.82426","0.12342"
"190.08000","15.84016","0.12406"
"190.27200","15.85624","0.12578"
"190.46400","15.87221","0.12699"
"190.65600","15.88817","0.12835"
"190.84800","15.90420","0.12941"
"191.04000","15.92016","0.13063"
"191.23200","15.93612","0.13143"
"191.42400","15.95226","0.13300"
"191.61600","15.96817","0.13371"
"191.80800","15.98419","0.13431"
"192.00000","16.00028","0.13143"
"192.19200","16.01612","0.13165"
"192.38400","16.03220","0.13295"
"192.57600","16.04829","0.13376"
"192.76800","16.06419","0.13530"
"192.96000","16.08016","0.13599"
"193.15200","16.09624","0.13636"
"193.34400","16.11220","0.13749"
"193.53600","16.12823","0.13825"
"193.72800","16.14413","0.13927"
"193.92000","16.16015","0.13993"
"194.11200","16.17624","0.14058"
"194.30400","16.19220","0.14150"
"194.49600","16.20816","0.14236"
"194.68800","16.22419","0.14271"
"194.88000","16.24021","0.14321"
"195.07200","16.25624","0.14388"
"195.26400","16.27220","0.14434"
"195.45600","16.28822","0.14477"
"195.64800","16.30425","0.14527"
"195.84000","16.32015","0.14610"
"196.03200","16.33617","0.14655"
"196.22400","16.35226","0.14718"
"196.41600","16.36816","0.14783"
"196.60800","16.38424","0.14868"
"196.80000","16.40021","0.14918"
"196.99200","16.41617","0.14989"
"197.18400","16.43225","0.15019"
"197.37600","16.44822","0.15101"
"197.56800","16.46412","0.15235"
"197.76000","16.48027","0.15366"
"197.95200","16.49623","0.15438"
"198.14400","16.51213","0.15542"
"198.33600","16.52828","0.15717"
"198.52800","16.54418","0.15836"
"198.72000","16.56015","0.16011"
"198.91200","16.57623","0.16093"
"199.10400","16.59213","0.16302"
"199.29600","16.60816","0.16425"
"199.48800","16.62430","0.16730"
"199.68000","16.64014","0.16937"
"199.87200","16.65623","0.17252"
"200.06400","16.67225","0.17556"
"200.25600","16.68815","0.17736"
"200.44800","16.70424","0.18088"
"200.64000","16.72020","0.18295"
"200.83200","16.73611","0.18647"
"201.02400","16.75225","0.18974"
"201.21600","16.76821","0.19256"
"201.40800","16.78418","0.19573"
"201.60000","16.80020","0.19765"
"201.79200","16.81617","0.20029"
"201.98400","16.83219","0.20237"
"202.17600","16.84821","0.20369"
"202.36800","16.86418","0.20481"
"202.56000","16.88020","0.20548"
"202.75200","16.89622","0.20657"
"202.94400","16.91219","0.20747"
"203.13600","16.92821","0.20735"
"203.32800","16.94423","0.20878"
"203.52000","16.96014","0.20814"
"203.71200","16.97616","0.20928"
"203.90400","16.99219","0.21141"
"204.09600","17.00815","0.21333"
"204.28800","17.02417","0.21534"
"204.48000","17.04020","0.21748"
"204.67200","17.05616","0.21965"
"204.86400","17.07224","0.22204"
"205.05600","17.08815","0.22478"
"205.24800","17.10423","0.22651"
"205.44000","17.12019","0.22902"
"205.63200","17.13616","0.23130"
"205.82400","17.15224","0.23363"
"206.01600","17.16821","0.23587"
"206.20800","17.18417","0.23792"
"206.40000","17.20025","0.23996"
"206.59200","17.21616","0.24190"
"206.78400","17.23218","0.24365"
"206.97600","17.24820","0.24503"
"207.16800","17.26417","0.24620"
"207.36000","17.28025","0.24746"
"207.55200","17.29627","0.24860"
"207.74400","17.31218","0.24969"
"207.93600","17.32826","0.25071"
"208.12800","17.34422","0.25133"
"208.32000","17.36019","0.25222"
"208.51200","17.37621","0.25288"
"208.70400","17.39224","0.25347"
"208.89600","17.40814","0.25450"
"209.08800","17.42422","0.25485"
"209.28000","17.44025","0.25578"
"209.47200","17.45621","0.25655"
"209.66400","17.47223","0.25741"
"209.85600","17.48814","0.25843"
"210.04800","17.50416","0.25961"
"210.24000","17.52031","0.25834"
"210.43200","17.53621","0.25984"
"210.62400","17.55223","0.26161"
"210.81600","17.56826","0.26368"
"211.00800","17.58410","0.26622"
"211.20000","17.60024","0.26873"
"211.39200","17.61621","0.27103"
"211.58400","17.63217","0.27345"
"211.77600","17.64820","0.27585"
"211.96800","17.66422","0.27802"
"212.16000","17.68012","0.28016"
"212.35200","17.69621","0.28261"
"212.54400","17.71223","0.28455"
"212.73600","17.72820","0.28738"
"212.92800","17.74422","0.28947"
"213.12000","17.76018","0.29171"
"213.31200","17.77621","0.29411"
"213.50400","17.79223","0.29624"
"213.69600","17.80819","0.29812"
"213.88800","17.82421","0.29963"
"214.08000","17.84024","0.30154"
"214.27200","17.85620","0.30289"
"214.46400","17.87223","0.30477"
"214.65600","17.88819","0.30765"
"214.84800","17.90421","0.30958"
"215.04000","17.92018","0.31353"
"215.23200","17.93620","0.31738"
"215.42400","17.95217","0.32256"
"215.61600","17.96825","0.32800"
"215.80800","17.98421","0.33157"
"216.00000","18.00018","0.33653"
"216.19200","18.01620","0.33884"
"216.38400","18.03217","0.34272"
"216.57600","18.04825","0.34516"
"216.76800","18.06421","0.34845"
"216.96000","18.08012","0.35152"
"217.15200","18.09626","0.35363"
"217.34400","18.11216","0.35559"
"217.53600","18.12819","0.35750"
"217.72800","18.14421","0.35868"
"217.92000","18.16017","0.35945"
"218.11200","18.17620","0.36020"
"218.30400","18.19222","0.36071"
"218.49600","18.20819","0.36122"
"218.68800","18.22421","0.36160"
"218.88000","18.24023","0.36227"
"219.07200","18.25614","0.36312"
"219.26400","18.27222","0.36393"
"219.45600","18.28824","0.36510"
"219.64800","18.30415","0.36675"
"219.84000","18.32023","0.36758"
"220.03200","18.33619","0.36930"
"220.22400","18.35216","0.37138"
"220.41600","18.36818","0.37357"
"220.60800","18.38420","0.37573"
"220.80000","18.40017","0.37880"
"220.99200","18.41625","0.38120"
"221.18400","18.43216","0.38470"
"221.37600","18.44818","0.38780"
"221.56800","18.46420","0.39195"
"221.76000","18.48017","0.39503"
"221.95200","18.49625","0.39969"
"222.14400","18.51221","0.40170"
"222.33600","18.52818","0.40426"
"222.52800","18.54420","0.40701"
"222.72000","18.56022","0.40843"
"222.91200","18.57613","0.41007"
"223.10400","18.59221","0.41169"
"223.29600","18.60824","0.41432"
"223.48800","18.62420","0.41649"
"223.68000","18.64022","0.41925"
"223.87200","18.65619","0.42238"
"224.06400","18.67221","0.42562"
"224.25600","18.68824","0.42913"
"224.44800","18.70414","0.43081"
"224.64000","18.72028","0.43306"
"224.83200","18.73619","0.43477"
"225.02400","18.75215","0.43529"
"225.21600","18.76823","0.43675"
"225.40800","18.78420","0.43858"
"225.60000","18.80016","0.43967"
"225.79200","18.81624","0.44132"
"225.98400","18.83215","0.44247"
"226.17600","18.84817","0.44417"
"226.36800","18.86419","0.44551"
"226.56000","18.88016","0.44634"
"226.75200","18.89618","0.44755"
"226.94400","18.91221","0.44834"
"227.13600","18.92817","0.44871"
"227.32800","18.94419","0.41964"
"227.52000","18.96022","0.41703"
"227.71200","18.97618","0.41799"
"227.90400","18.99227","0.42006"
"228.09600","19.00817","0.42316"
"228.28800","19.02419","0.42549"
"228.48000","19.04022","0.42783"
"228.67200","19.05618","0.42987"
"228.86400","19.07220","0.43235"
"229.05600","19.08823","0.43340"
"229.24800","19.10419","0.43515"
"229.44000","19.12016","0.43777"
"229.63200","19.13624","0.44019"
"229.82400","19.15220","0.44121"
"230.01600","19.16817","0.44254"
"230.20800","19.18419","0.44418"
"230.40000","19.20015","0.44539"
"230.59200","19.21624","0.44725"
"230.78400","19.23220","0.44867"
"230.97600","19.24816","0.44993"
"231.16800","19.26425","0.45110"
"231.36000","19.28021","0.45301"
"231.55200","19.29618","0.45491"
"231.74400","19.31226","0.45636"
"231.93600","19.32816","0.45791"
"232.12800","19.34425","0.45983"
"232.32000","19.36021","0.46147"
"232.51200","19.37617","0.46323"
"232.70400","19.39220","0.46537"
"232.89600","19.40828","0.46790"
"233.08800","19.42413","0.47044"
"233.28000","19.44021","0.47095"
"233.47200","19.45623","0.47287"
"233.66400","19.47214","0.47526"
"233.85600","19.48828","0.47824"
"234.04800","19.50424","0.48122"
"234.24000","19.52015","0.48332"
"234.43200","19.53623","0.48616"
"234.62400","19.55219","0.48898"
"234.81600","19.56822","0.49089"
"235.00800","19.58424","0.49372"
"235.20000","19.60020","0.49588"
"235.39200","19.61623","0.49779"
"235.58400","19.63219","0.49903"
"235.77600","19.64822","0.49929"
"235.96800","19.66424","0.50050"
"236.16000","19.68020","0.50249"
"236.35200","19.69623","0.50446"
"236.54400","19.71219","0.50629"
"236.73600","19.72815","0.50745"
"236.92800","19.74418","0.50889"
"237.12000","19.76020","0.50965"
"237.31200","19.77617","0.51042"
"237.50400","19.79219","0.51080"
"237.69600","19.80821","0.51075"
"237.88800","19.82418","0.51217"
"238.08000","19.84020","0.51443"
"238.27200","19.85622","0.51687"
"238.46400","19.87219","0.51914"
"238.65600","19.88827","0.51987"
"238.84800","19.90417","0.52054"
"239.04000","19.92014","0.52235"
"239.23200","19.93622","0.52567"
"239.42400","19.95213","0.52961"
"239.61600","19.96821","0.53406"
"239.80800","19.98423","0.53858"
"240.00000","20.00014","0.54239"
"240.19200","20.01622","0.54676"
"240.38400","20.03218","0.55100"
"240.57600","20.04815","0.55274"
"240.76800","20.06423","0.55627"
"240.96000","20.08026","0.55943"
"241.15200","20.09616","0.56238"
"241.34400","20.11224","0.56329"
"241.53600","20.12821","0.56604"
"241.72800","20.14417","0.56751"
"241.92000","20.16025","0.56898"
"242.11200","20.17622","0.57061"
"242.30400","20.19212","0.57128"
"242.49600","20.20820","0.57225"
"242.68800","20.22417","0.57355"
"242.88000","20.24019","0.57446"
"243.07200","20.25621","0.57522"
"243.26400","20.27218","0.57658"
"243.45600","20.28814","0.57807"
"243.64800","20.30429","0.58014"
"243.84000","20.32013","0.58362"
"244.03200","20.33621","0.58674"
"244.22400","20.35224","0.59088"
"244.41600","20.36814","0.59402"
"244.60800","20.38416","0.59822"
"244.80000","20.40019","0.60047"
"244.99200","20.41615","0.60419"
"245.18400","20.43218","0.60735"
"245.37600","20.44820","0.61009"
"245.56800","20.46422","0.61280"
"245.76000","20.48025","0.61541"
"245.95200","20.49621","0.61650"
"246.14400","20.51223","0.61713"
"246.33600","20.52820","0.61951"
"246.52800","20.54422","0.62242"
"246.72000","20.56025","0.62635"
"246.91200","20.57621","0.62952"
"247.10400","20.59217","0.63416"
"247.29600","20.60826","0.63595"
"247.48800","20.62416","0.63934"
"247.68000","20.64018","0.64239"
"247.87200","20.65621","0.64580"
"248.06400","20.67217","0.42660"
"248.25600","20.68825","0.42502"
"248.44800","20.70422","0.43153"
"248.64000","20.72012","0.43890"
"248.83200","20.73621","0.43592"
"249.02400","20.75229","0.43941"
"249.21600","20.76819","0.44978"
"249.40800","20.78428","0.44618"
"249.60000","20.80018","0.44684"
"249.79200","20.81609","0.45558"
"249.98400","20.83223","0.45606"
"250.17600","20.84825","0.45961"
"250.36800","20.86415","0.46605"
"250.56000","20.88024","0.46544"
"250.75200","20.89620","0.47139"
"250.94400","20.91217","0.48085"
"251.13600","20.92825","0.47518"
"251.32800","20.94415","0.47188"
"251.52000","20.96018","0.45826"
"251.71200","20.97620","0.36177"
"251.90400","20.99216","0.36089"
"252.09600","21.00819","0.36277"
"252.28800","21.02421","0.36124"
"252.48000","21.04012","0.36139"
"252.67200","21.05620","0.26280"
"252.86400","21.07216","0.25548"
"253.05600","21.08819","0.25743"
"253.24800","21.10421","0.25853"
"253.44000","21.12017","0.25852"
"253.63200","21.13620","0.26459"
"253.82400","21.15222","0.26606"
"254.01600","21.16818","0.27103"
"254.20800","21.18421","0.27303"
"254.40000","21.20023","0.27663"
"254.59200","21.21620","0.27857"
"254.78400","21.23222","0.28331"
"254.97600","21.24818","0.29070"
"255.16800","21.26414","0.29040"
"255.36000","21.28023","0.29570"
"255.55200","21.29620","0.29676"
"255.74400","21.31222","0.29851"
"255.93600","21.32818","0.30298"
"256.12800","21.34420","0.30337"
"256.32000","21.36017","0.30756"
"256.51200","21.37619","0.31167"
"256.70400","21.39215","0.31473"
"256.89600","21.40818","0.32498"
"257.08800","21.42426","0.32842"
"257.28000","21.44017","0.33485"
"257.47200","21.45625","0.33976"
"257.66400","21.47222","0.34205"
"257.85600","21.48812","0.34814"
"258.04800","21.50420","0.33093"
"258.24000","21.52017","0.32425"
"258.43200","21.53619","0.33278"
"258.62400","21.55221","0.33472"
"258.81600","21.56818","0.34082"
"259.00800","21.58420","0.34431"
"259.20000","21.60022","0.34719"
"259.39200","21.61613","0.35259"
"259.58400","21.63227","0.35407"
"259.77600","21.64824","0.35683"
"259.96800","21.66414","0.35819"
"260.16000","21.68022","0.35923"
"260.35200","21.69625","0.36059"
"260.54400","21.71215","0.36083"
"260.73600","21.72823","0.36162"
"260.92800","21.74420","0.36282"
"261.12000","21.76010","0.36349"
"261.31200","21.77624","0.36534"
"261.50400","21.79221","0.36717"
"261.69600","21.80817","0.36898"
"261.88800","21.82425","0.37211"
"262.08000","21.84022","0.37455"
"262.27200","21.85624","0.37803"
"262.46400","21.87221","0.38316"
"262.65600","21.88817","0.38725"
"262.84800","21.90419","0.39082"
"263.04000","21.92028","0.39810"
"263.23200","21.93618","0.40011"
"263.42400","21.95221","0.40456"
"263.61600","21.96823","0.40821"
"263.80800","21.98419","0.40948"
"264.00000","22.00022","0.41172"
"264.19200","22.01624","0.41487"
"264.38400","22.03214","0.41639"
"264.57600","22.04817","0.41944"
"264.76800","22.06413","0.42392"
"264.96000","22.08022","0.42671"
"265.15200","22.09624","0.42939"
"265.34400","22.11220","0.43384"
"265.53600","22.12823","0.43506"
"265.72800","22.14419","0.43652"
"265.92000","22.16009","0.43946"
"266.11200","22.17630","0.44053"
"266.30400","22.19220","0.44198"
"266.49600","22.20817","0.44433"
"266.68800","22.22419","0.44533"
"266.88000","22.24015","0.44601"
"267.07200","22.25624","0.44730"
"267.26400","22.27220","0.44849"
"267.45600","22.28816","0.44975"
"267.64800","22.30425","0.45157"
"267.84000","22.32021","0.45385"
"268.03200","22.33617","0.45563"
"268.22400","22.35226","0.45786"
"268.41600","22.36822","0.45962"
"268.60800","22.38419","0.46046"
"268.80000","22.40027","0.46219"
"268.99200","22.41617","0.46461"
"269.18400","22.43220","0.46639"
"269.37600","22.44822","0.46848"
"269.56800","22.46418","0.47213"
"269.76000","22.48021","0.47429"
"269.95200","22.49623","0.47691"
"270.14400","22.51219","0.48077"
"270.33600","22.52816","0.48322"
"270.52800","22.54424","0.48570"
"270.72000","22.56015","0.48910"
"270.91200","22.57623","0.49195"
"271.10400","22.59225","0.49370"
"271.29600","22.60816","0.49578"
"271.48800","22.62424","0.49910"
"271.68000","22.64020","0.50057"
"271.87200","22.65617","0.50259"
"272.06400","22.67225","0.50433"
"272.25600","22.68821","0.50611"
"272.44800","22.70418","0.50745"
"272.64000","22.72020","0.50824"
"272.83200","22.73617","0.50924"
"273.02400","22.75219","0.51010"
"273.21600","22.76821","0.51055"
"273.40800","22.78418","0.51259"
"273.60000","22.80026","0.51380"
"273.79200","22.81616","0.51476"
"273.98400","22.83219","0.51734"
"274.17600","22.84821","0.52059"
"274.36800","22.86423","0.52309"
"274.56000","22.88014","0.52511"
"274.75200","22.89622","0.52782"
"274.94400","22.91225","0.53217"
"275.13600","22.92821","0.53375"
"275.32800","22.94417","0.53488"
"275.52000","22.96020","0.53905"
"275.71200","22.97622","0.54079"
"275.90400","22.99218","0.54267"
"276.09600","23.00821","0.54480"
"276.28800","23.02423","0.54740"
"276.48000","23.04020","0.54840"
"276.67200","23.05616","0.54952"
"276.86400","23.07224","0.55141"
"277.05600","23.08821","0.36568"
"277.24800","23.10417","0.18407"
"277.44000","23.12025","0.19986"
"277.63200","23.13622","0.19372"
"277.82400","23.15218","0.20782"
"278.01600","23.16821","0.20153"
"278.20800","23.18417","0.20557"
"278.40000","23.20019","0.20152"
"278.59200","23.21622","0.20490"
"278.78400","23.23218","0.20721"
"278.97600","23.24821","0.20725"
"279.16800","23.26423","0.21060"
"279.36000","23.28019","0.20786"
"279.55200","23.29627","0.21622"
"279.74400","23.31218","0.21107"
"279.93600","23.32814","0.22058"
"280.12800","23.34423","0.21439"
"280.32000","23.36019","0.22428"
"280.51200","23.37615","0.21979"
"280.70400","23.39218","0.22588"
"280.89600","23.40820","0.04575"
"281.08800","23.42422","0.01184"
"281.28000","23.44019","0.02973"
"281.47200","23.45627","0.01692"
"281.66400","23.47218","0.01948"
"281.85600","23.48820","0.01606"
"282.04800","23.50416","0.01699"
"282.24000","23.52024","0.02197"
"282.43200","23.53615","0.01545"
"282.62400","23.55217","0.02077"
"282.81600","23.56820","0.01974"
"283.00800","23.58416","0.01641"
"283.20000","23.60018","0.02201"
"283.39200","23.61621","0.01771"
"283.58400","23.63217","0.01821"
"283.77600","23.64820","0.02060"
"283.96800","23.66422","0.01738"
"284.16000","23.68012","0.01939"
"284.35200","23.69621","0.02079"
"284.54400","23.71229","0.01844"
"284.73600","23.72813","0.02130"
"284.92800","23.74428","0.02023"
"285.12000","23.76018","0.01907"
"285.31200","23.77614","0.02111"
"285.50400","23.79223","0.01863"
"285.69600","23.80825","0.01950"
"285.88800","23.82422","0.02086"
"286.08000","23.84018","0.01890"
"286.27200","23.85620","0.02128"
"286.46400","23.87217","0.02086"
"286.65600","23.88825","0.01968"
"286.84800","23.90415","0.02121"
"287.04000","23.92024","0.01916"
"287.12800","23.92753","0.01936"