File: Force_trajectories/170108_0/Specimen_RawData_1.csv
End date,"1/8/2017"
Specimen label,"20CG_57"
Maximum Load,"0.01203",N

Time,Extension,Load
(s),(mm),(N)
"0.00000","0.00000","-0.00065"
"0.15600","0.00915","-0.00015"
"0.31200","0.02565","0.00065"
"0.46800","0.03934","0.00057"
"0.62400","0.05220","0.00146"
"0.78000","0.06529","0.00129"
"0.93600","0.07820","0.00129"
"1.09200","0.09124","0.00167"
"1.24800","0.10421","0.00124"
"1.40400","0.11719","0.00180"
"1.56000","0.13022","0.00207"
"1.71600","0.14314","0.00213"
"1.87200","0.15623","0.00210"
"2.02800","0.16920","0.00290"
"2.18400","0.18218","0.00256"
"2.34000","0.19521","0.00247"
"2.49600","0.20825","0.00265"
"2.65200","0.22122","0.00265"
"2.80800","0.23420","0.00297"
"2.96400","0.24723","0.00341"
"3.12000","0.26020","0.00312"
"3.27600","0.27318","0.00272"
"3.43200","0.28621","0.00328"
"3.58800","0.29925","0.00279"
"3.74400","0.31216","0.00268"
"3.90000","0.32520","0.00291"
"4.05600","0.33829","0.00341"
"4.21200","0.35126","0.00343"
"4.36800","0.36418","0.00350"
"4.52400","0.37721","0.00372"
"4.68000","0.39025","0.00364"
"4.83600","0.40322","0.00375"
"4.99200","0.41619","0.00396"
"5.14800","0.42923","0.00423"
"5.30400","0.44220","0.00426"
"5.46000","0.45512","0.00435"
"5.61600","0.46821","0.00447"
"5.77200","0.48119","0.00438"
"5.92800","0.49422","0.00418"
"6.08400","0.50719","0.00381"
"6.24000","0.52029","0.00416"
"6.39600","0.53326","0.00383"
"6.55200","0.54618","0.00404"
"6.70800","0.55927","0.00442"
"6.86400","0.57225","0.00411"
"7.02000","0.58522","0.00440"
"7.17600","0.59825","0.00419"
"7.33200","0.61123","0.00447"
"7.48800","0.62420","0.00443"
"7.64400","0.63718","0.00439"
"7.80000","0.65021","0.00387"
"7.95600","0.66325","0.00402"
"8.11200","0.67622","0.00425"
"8.26800","0.68925","0.00490"
"8.42400","0.70223","0.00428"
"8.58000","0.71526","0.00476"
"8.73600","0.72818","0.00454"
"8.89200","0.74127","0.00447"
"9.04800","0.75419","0.00447"
"9.20400","0.76716","0.00381"
"9.36000","0.78025","0.00460"
"9.51600","0.79323","0.00431"
"9.67200","0.80620","0.00446"
"9.82800","0.81924","0.00409"
"9.98400","0.83227","0.00469"
"10.14000","0.84524","0.00461"
"10.29600","0.85816","0.00484"
"10.45200","0.87119","0.00478"
"10.60800","0.88429","0.00457"
"10.76400","0.89720","0.00445"
"10.92000","0.91018","0.00454"
"11.07600","0.92327","0.00441"
"11.23200","0.93624","0.00475"
"11.38800","0.94922","0.00434"
"11.54400","0.96225","0.00422"
"11.70000","0.97529","0.00457"
"11.85600","0.98820","0.00403"
"12.01200","1.00118","0.00446"
"12.16800","1.01421","0.00469"
"12.32400","1.02724","0.00461"
"12.48000","1.04016","0.00445"
"12.63600","1.05325","0.00483"
"12.79200","1.06629","0.00473"
"12.94800","1.07920","0.00444"
"13.10400","1.09218","0.00443"
"13.26000","1.10527","0.00469"
"13.41600","1.11824","0.00505"
"13.57200","1.13122","0.00472"
"13.72800","1.14425","0.00476"
"13.88400","1.15729","0.00508"
"14.04000","1.17014","0.00476"
"14.19600","1.18323","0.00495"
"14.35200","1.19621","0.00435"
"14.50800","1.20918","0.00503"
"14.66400","1.22216","0.00493"
"14.82000","1.23525","0.00489"
"14.97600","1.24823","0.00508"
"15.13200","1.26120","0.00463"
"15.28800","1.27417","0.00457"
"15.44400","1.28721","0.00479"
"15.60000","1.30018","0.00459"
"15.75600","1.31316","0.00480"
"15.91200","1.32625","0.00492"
"16.06800","1.33923","0.00525"
"16.22400","1.35214","0.00484"
"16.38000","1.36523","0.00504"
"16.53600","1.37821","0.00514"
"16.69200","1.39118","0.00524"
"16.84800","1.40422","0.00519"
"17.00400","1.41725","0.00497"
"17.16000","1.43023","0.00507"
"17.31600","1.44314","0.00534"
"17.47200","1.45623","0.00542"
"17.62800","1.46921","0.00532"
"17.78400","1.48218","0.00506"
"17.94000","1.49522","0.00518"
"18.09600","1.50819","0.00482"
"18.25200","1.52117","0.00538"
"18.40800","1.53414","0.00548"
"18.56400","1.54723","0.00551"
"18.72000","1.56027","0.00490"
"18.87600","1.57318","0.00529"
"19.03200","1.58622","0.00501"
"19.18800","1.59925","0.00488"
"19.34400","1.61222","0.00561"
"19.50000","1.62514","0.00505"
"19.65600","1.63823","0.00524"
"19.81200","1.65121","0.00560"
"19.96800","1.66418","0.00523"
"20.12400","1.67722","0.00486"
"20.28000","1.69025","0.00525"
"20.43600","1.70316","0.00505"
"20.59200","1.71620","0.00518"
"20.74800","1.72923","0.00472"
"20.90400","1.74227","0.00550"
"21.06000","1.75518","0.00539"
"21.21600","1.76822","0.00511"
"21.37200","1.78125","0.00501"
"21.52800","1.79416","0.00563"
"21.68400","1.80714","0.00528"
"21.84000","1.82017","0.00488"
"21.99600","1.83315","0.00556"
"22.15200","1.84612","0.00509"
"22.30800","1.85928","0.00531"
"22.46400","1.87225","0.00492"
"22.62000","1.88522","0.00493"
"22.77600","1.89820","0.00532"
"22.93200","1.91123","0.00521"
"23.08800","1.92421","0.00538"
"23.24400","1.93712","0.00557"
"23.40000","1.95022","0.00506"
"23.55600","1.96319","0.00530"
"23.71200","1.97622","0.00517"
"23.86800","1.98920","0.00551"
"24.02400","2.00223","0.00499"
"24.18000","2.01521","0.00529"
"24.33600","2.02818","0.00574"
"24.49200","2.04127","0.00538"
"24.64800","2.05425","0.00471"
"24.80400","2.06716","0.00544"
"24.96000","2.08020","0.00546"
"25.11600","2.09317","0.00588"
"25.27200","2.10615","0.00615"
"25.42800","2.11918","0.00491"
"25.58400","2.13227","0.00515"
"25.74000","2.14525","0.00472"
"25.89600","2.15822","0.00503"
"26.05200","2.17126","0.00601"
"26.20800","2.18429","0.00604"
"26.36400","2.19721","0.00542"
"26.52000","2.21024","0.00586"
"26.67600","2.22321","0.00520"
"26.83200","2.23619","0.00567"
"26.98800","2.24910","0.00446"
"27.14400","2.26220","0.00501"
"27.30000","2.27523","0.00524"
"27.45600","2.28821","0.00527"
"27.61200","2.30124","0.00505"
"27.76800","2.31421","0.00480"
"27.92400","2.32719","0.00537"
"28.08000","2.34010","0.00461"
"28.23600","2.35326","0.00484"
"28.39200","2.36623","0.00508"
"28.54800","2.37920","0.00514"
"28.70400","2.39218","0.00488"
"28.86000","2.40527","0.00478"
"29.01600","2.41813","0.00483"
"29.17200","2.43116","0.00537"
"29.32800","2.44426","0.00469"
"29.48400","2.45729","0.00497"
"29.64000","2.47020","0.00476"
"29.79600","2.48324","0.00447"
"29.95200","2.49621","0.00453"
"30.10800","2.50919","0.00483"
"30.26400","2.52216","0.00508"
"30.42000","2.53520","0.00504"
"30.57600","2.54823","0.00469"
"30.73200","2.56114","0.00508"
"30.88800","2.57424","0.00511"
"31.04400","2.58721","0.00545"
"31.20000","2.60019","0.00487"
"31.35600","2.61322","0.00534"
"31.51200","2.62626","0.00501"
"31.66800","2.63923","0.00568"
"31.82400","2.65220","0.00488"
"31.98000","2.66524","0.00551"
"32.13600","2.67827","0.00515"
"32.29200","2.69119","0.00522"
"32.44800","2.70416","0.00547"
"32.60400","2.71720","0.00489"
"32.76000","2.73023","0.00521"
"32.91600","2.74320","0.00534"
"33.07200","2.75630","0.00501"
"33.22800","2.76927","0.00500"
"33.38400","2.78219","0.00541"
"33.54000","2.79516","0.00528"
"33.69600","2.80819","0.00481"
"33.85200","2.82117","0.00512"
"34.00800","2.83414","0.00474"
"34.16400","2.84724","0.00462"
"34.32000","2.86027","0.00484"
"34.47600","2.87319","0.00477"
"34.63200","2.88622","0.00508"
"34.78800","2.89919","0.00538"
"34.94400","2.91223","0.00533"
"35.10000","2.92520","0.00520"
"35.25600","2.93824","0.00506"
"35.41200","2.95127","0.00505"
"35.56800","2.96425","0.00538"
"35.72400","2.97728","0.00504"
"35.88000","2.99025","0.00527"
"36.03600","3.00323","0.00522"
"36.19200","3.01620","0.00563"
"36.34800","3.02924","0.00551"
"36.50400","3.04227","0.00470"
"36.66000","3.05519","0.00515"
"36.81600","3.06822","0.00450"
"36.97200","3.08125","0.00495"
"37.12800","3.09417","0.00557"
"37.28400","3.10720","0.00504"
"37.44000","3.12024","0.00536"
"37.59600","3.13321","0.00467"
"37.75200","3.14613","0.00510"
"37.90800","3.15916","0.00550"
"38.06400","3.17225","0.00497"
"38.22000","3.18517","0.00521"
"38.37600","3.19820","0.00485"
"38.53200","3.21130","0.00529"
"38.68800","3.22427","0.00518"
"38.84400","3.23718","0.00495"
"39.00000","3.25028","0.00527"
"39.15600","3.26325","0.00539"
"39.31200","3.27623","0.00468"
"39.46800","3.28920","0.00515"
"39.62400","3.30218","0.00511"
"39.78000","3.31521","0.00513"
"39.93600","3.32812","0.00522"
"40.09200","3.34128","0.00522"
"40.24800","3.35425","0.00452"
"40.40400","3.36723","0.00557"
"40.56000","3.38026","0.00510"
"40.71600","3.39318","0.00451"
"40.87200","3.40621","0.00435"
"41.02800","3.41918","0.00460"
"41.18400","3.43222","0.00494"
"41.34000","3.44519","0.00457"
"41.49600","3.45823","0.00513"
"41.65200","3.47126","0.00445"
"41.80800","3.48423","0.00457"
"41.96400","3.49721","0.00414"
"42.12000","3.51024","0.00482"
"42.27600","3.52322","0.00472"
"42.43200","3.53619","0.00455"
"42.58800","3.54917","0.00458"
"42.74400","3.56220","0.00472"
"42.90000","3.57523","0.00470"
"43.05600","3.58815","0.00453"
"43.21200","3.60124","0.00474"
"43.36800","3.61422","0.00445"
"43.52400","3.62725","0.00477"
"43.68000","3.64017","0.00452"
"43.83600","3.65326","0.00449"
"43.99200","3.66623","0.00453"
"44.14800","3.67921","0.00459"
"44.30400","3.69224","0.00452"
"44.46000","3.70522","0.00439"
"44.61600","3.71825","0.00434"
"44.77200","3.73117","0.00400"
"44.92800","3.74426","0.00465"
"45.08400","3.75723","0.00455"
"45.24000","3.77015","0.00439"
"45.39600","3.78324","0.00465"
"45.55200","3.79628","0.00420"
"45.70800","3.80925","0.00457"
"45.86400","3.82223","0.00480"
"46.02000","3.83526","0.00425"
"46.17600","3.84823","0.00440"
"46.33200","3.86115","0.00420"
"46.48800","3.87418","0.00456"
"46.64400","3.88722","0.00469"
"46.80000","3.90019","0.00496"
"46.95600","3.91322","0.00490"
"47.11200","3.92626","0.00492"
"47.26800","3.93923","0.00487"
"47.42400","3.95215","0.00508"
"47.58000","3.96518","0.00468"
"47.73600","3.97822","0.00451"
"47.89200","3.99119","0.00434"
"48.04800","4.00422","0.00453"
"48.20400","4.01720","0.00462"
"48.36000","4.03023","0.00440"
"48.51600","4.04315","0.00479"
"48.67200","4.05624","0.00469"
"48.82800","4.06922","0.00530"
"48.98400","4.08219","0.00499"
"49.14000","4.09522","0.00492"
"49.29600","4.10826","0.00456"
"49.45200","4.12123","0.00431"
"49.60800","4.13421","0.00410"
"49.76400","4.14724","0.00437"
"49.92000","4.16022","0.00429"
"50.07600","4.17319","0.00436"
"50.23200","4.18616","0.00501"
"50.38800","4.19920","0.00512"
"50.54400","4.21217","0.00420"
"50.70000","4.22515","0.00512"
"50.85600","4.23824","0.00483"
"51.01200","4.25127","0.00492"
"51.16800","4.26419","0.00457"
"51.32400","4.27722","0.00467"
"51.48000","4.29026","0.00472"
"51.63600","4.30317","0.00485"
"51.79200","4.31615","0.00456"
"51.94800","4.32918","0.00435"
"52.10400","4.34221","0.00495"
"52.26000","4.35519","0.00539"
"52.41600","4.36822","0.00492"
"52.57200","4.38120","0.00440"
"52.72800","4.39417","0.00483"
"52.88400","4.40715","0.00519"
"53.04000","4.42024","0.00530"
"53.19600","4.43327","0.00409"
"53.35200","4.44619","0.00499"
"53.50800","4.45922","0.00461"
"53.66400","4.47226","0.00499"
"53.82000","4.48517","0.00554"
"53.97600","4.49821","0.00450"
"54.13200","4.51124","0.00432"
"54.28800","4.52427","0.00469"
"54.44400","4.53719","0.00528"
"54.60000","4.55028","0.00466"
"54.75600","4.56326","0.00490"
"54.91200","4.57617","0.00492"
"55.06800","4.58921","0.00442"
"55.22400","4.60224","0.00449"
"55.38000","4.61521","0.00459"
"55.53600","4.62813","0.00434"
"55.69200","4.64122","0.00453"
"55.84800","4.65426","0.00494"
"56.00400","4.66717","0.00453"
"56.16000","4.68021","0.00466"
"56.31600","4.69324","0.00470"
"56.47200","4.70621","0.00503"
"56.62800","4.71919","0.00476"
"56.78400","4.73222","0.00538"
"56.94000","4.74520","0.00526"
"57.09600","4.75817","0.00517"
"57.25200","4.77120","0.00486"
"57.40800","4.78418","0.00510"
"57.56400","4.79721","0.00498"
"57.72000","4.81019","0.00489"
"57.87600","4.82322","0.00465"
"58.03200","4.83626","0.00505"
"58.18800","4.84923","0.00449"
"58.34400","4.86220","0.00538"
"58.50000","4.87524","0.00503"
"58.65600","4.88815","0.00487"
"58.81200","4.90119","0.00470"
"58.96800","4.91422","0.00503"
"59.12400","4.92720","0.00513"
"59.28000","4.94011","0.00484"
"59.43600","4.95320","0.00512"
"59.59200","4.96624","0.00529"
"59.74800","4.97921","0.00506"
"59.90400","4.99219","0.00508"
"60.06000","5.00522","0.00467"
"60.21600","5.01819","0.00470"
"60.37200","5.03111","0.00503"
"60.52800","5.04426","0.00540"
"60.68400","5.05730","0.00517"
"60.84000","5.07021","0.00565"
"60.99600","5.08325","0.00533"
"61.15200","5.09622","0.00522"
"61.30800","5.10919","0.00581"
"61.46400","5.12217","0.00580"
"61.62000","5.13526","0.00537"
"61.77600","5.14830","0.00513"
"61.93200","5.16121","0.00534"
"62.08800","5.17431","0.00536"
"62.24400","5.18722","0.00521"
"62.40000","5.20019","0.00476"
"62.55600","5.21311","0.00527"
"62.71200","5.22626","0.00485"
"62.86800","5.23924","0.00497"
"63.02400","5.25221","0.00527"
"63.18000","5.26519","0.00499"
"63.33600","5.27828","0.00529"
"63.49200","5.29119","0.00560"
"63.64800","5.30423","0.00541"
"63.80400","5.31726","0.00470"
"63.96000","5.33024","0.00505"
"64.11600","5.34321","0.00470"
"64.27200","5.35625","0.00507"
"64.42800","5.36928","0.00523"
"64.58400","5.38219","0.00526"
"64.74000","5.39517","0.00493"
"64.89600","5.40820","0.00509"
"65.05200","5.42124","0.00509"
"65.20800","5.43421","0.00540"
"65.36400","5.44725","0.00495"
"65.52000","5.46022","0.00557"
"65.67600","5.47319","0.00484"
"65.83200","5.48617","0.00569"
"65.98800","5.49920","0.00532"
"66.14400","5.51218","0.00524"
"66.30000","5.52515","0.00512"
"66.45600","5.53824","0.00555"
"66.61200","5.55122","0.00526"
"66.76800","5.56419","0.00475"
"66.92400","5.57723","0.00555"
"67.08000","5.59026","0.00526"
"67.23600","5.60324","0.00543"
"67.39200","5.61621","0.00543"
"67.54800","5.62924","0.00546"
"67.70400","5.64222","0.00529"
"67.86000","5.65519","0.00574"
"68.01600","5.66823","0.00503"
"68.17200","5.68120","0.00506"
"68.32800","5.69418","0.00473"
"68.48400","5.70721","0.00577"
"68.64000","5.72024","0.00513"
"68.79600","5.73328","0.00565"
"68.95200","5.74625","0.00503"
"69.10800","5.75929","0.00531"
"69.26400","5.77226","0.00549"
"69.42000","5.78518","0.00526"
"69.57600","5.79821","0.00525"
"69.73200","5.81124","0.00531"
"69.88800","5.82422","0.00582"
"70.04400","5.83713","0.00520"
"70.20000","5.85029","0.00535"
"70.35600","5.86326","0.00528"
"70.51200","5.87624","0.00569"
"70.66800","5.88927","0.00526"
"70.82400","5.90230","0.00496"
"70.98000","5.91528","0.00523"
"71.13600","5.92813","0.00560"
"71.29200","5.94129","0.00537"
"71.44800","5.95420","0.00498"
"71.60400","5.96723","0.00575"
"71.76000","5.98021","0.00577"
"71.91600","5.99324","0.00538"
"72.07200","6.00622","0.00510"
"72.22800","6.01919","0.00577"
"72.38400","6.03223","0.00540"
"72.54000","6.04526","0.00568"
"72.69600","6.05817","0.00548"
"72.85200","6.07121","0.00528"
"73.00800","6.08418","0.00607"
"73.16400","6.09716","0.00537"
"73.32000","6.11019","0.00530"
"73.47600","6.12317","0.00532"
"73.63200","6.13620","0.00543"
"73.78800","6.14917","0.00474"
"73.94400","6.16227","0.00559"
"74.10000","6.17524","0.00557"
"74.25600","6.18822","0.00549"
"74.41200","6.20119","0.00525"
"74.56800","6.21422","0.00500"
"74.72400","6.22726","0.00488"
"74.88000","6.24017","0.00533"
"75.03600","6.25321","0.00568"
"75.19200","6.26624","0.00570"
"75.34800","6.27922","0.00515"
"75.50400","6.29219","0.00541"
"75.66000","6.30528","0.00573"
"75.81600","6.31820","0.00516"
"75.97200","6.33123","0.00568"
"76.12800","6.34427","0.00501"
"76.28400","6.35724","0.00514"
"76.44000","6.37022","0.00482"
"76.59600","6.38319","0.00560"
"76.75200","6.39622","0.00481"
"76.90800","6.40920","0.00544"
"77.06400","6.42223","0.00527"
"77.22000","6.43527","0.00587"
"77.37600","6.44824","0.00532"
"77.53200","6.46116","0.00529"
"77.68800","6.47425","0.00554"
"77.84400","6.48722","0.00518"
"78.00000","6.50026","0.00544"
"78.15600","6.51323","0.00541"
"78.31200","6.52627","0.00557"
"78.46800","6.53924","0.00574"
"78.62400","6.55210","0.00508"
"78.78000","6.56525","0.00559"
"78.93600","6.57822","0.00550"
"79.09200","6.59120","0.00530"
"79.24800","6.60417","0.00500"
"79.40400","6.61727","0.00500"
"79.56000","6.63024","0.00467"
"79.71600","6.64316","0.00481"
"79.87200","6.65625","0.00523"
"80.02800","6.66922","0.00491"
"80.18400","6.68220","0.00456"
"80.34000","6.69517","0.00489"
"80.49600","6.70821","0.00477"
"80.65200","6.72118","0.00463"
"80.80800","6.73416","0.00528"
"80.96400","6.74719","0.00498"
"81.12000","6.76022","0.00487"
"81.27600","6.77320","0.00469"
"81.43200","6.78623","0.00471"
"81.58800","6.79927","0.00532"
"81.74400","6.81224","0.00573"
"81.90000","6.82516","0.00483"
"82.05600","6.83825","0.00525"
"82.21200","6.85122","0.00492"
"82.36800","6.86420","0.00503"
"82.52400","6.87717","0.00532"
"82.68000","6.89021","0.00520"
"82.83600","6.90318","0.00551"
"82.99200","6.91615","0.00500"
"83.14800","6.92925","0.00512"
"83.30400","6.94228","0.00555"
"83.46000","6.95526","0.00541"
"83.61600","6.96823","0.00492"
"83.77200","6.98121","0.00541"
"83.92800","6.99418","0.00518"
"84.08400","7.00715","0.00502"
"84.24000","7.02019","0.00553"
"84.39600","7.03322","0.00513"
"84.55200","7.04620","0.00489"
"84.70800","7.05923","0.00516"
"84.86400","7.07221","0.00482"
"85.02000","7.08518","0.00571"
"85.17600","7.09815","0.00541"
"85.33200","7.11125","0.00502"
"85.48800","7.12416","0.00507"
"85.64400","7.13720","0.00525"
"85.80000","7.15017","0.00522"
"85.95600","7.16320","0.00548"
"86.11200","7.17612","0.00555"
"86.26800","7.18921","0.00584"
"86.42400","7.20225","0.00553"
"86.58000","7.21528","0.00477"
"86.73600","7.22820","0.00509"
"86.89200","7.24129","0.00569"
"87.04800","7.25420","0.00562"
"87.20400","7.26718","0.00507"
"87.36000","7.28021","0.00583"
"87.51600","7.29325","0.00598"
"87.67200","7.30622","0.00524"
"87.82800","7.31914","0.00546"
"87.98400","7.33223","0.00571"
"88.14000","7.34520","0.00574"
"88.29600","7.35818","0.00579"
"88.45200","7.37121","0.00606"
"88.60800","7.38425","0.00579"
"88.76400","7.39722","0.00550"
"88.92000","7.41020","0.00590"
"89.07600","7.42323","0.00589"
"89.23200","7.43626","0.00610"
"89.38800","7.44918","0.00600"
"89.54400","7.46221","0.00547"
"89.70000","7.47525","0.00554"
"89.85600","7.48816","0.00562"
"90.01200","7.50119","0.00571"
"90.16800","7.51423","0.00600"
"90.32400","7.52726","0.00556"
"90.48000","7.54018","0.00559"
"90.63600","7.55321","0.00578"
"90.79200","7.56625","0.00591"
"90.94800","7.57916","0.00626"
"91.10400","7.59220","0.00562"
"91.26000","7.60517","0.00596"
"91.41600","7.61820","0.00540"
"91.57200","7.63112","0.00560"
"91.72800","7.64427","0.00638"
"91.88400","7.65725","0.00648"
"92.04000","7.67022","0.00603"
"92.19600","7.68319","0.00591"
"92.35200","7.69623","0.00576"
"92.50800","7.70920","0.00585"
"92.66400","7.72218","0.00563"
"92.82000","7.73527","0.00546"
"92.97600","7.74825","0.00602"
"93.13200","7.76122","0.00600"
"93.28800","7.77419","0.00561"
"93.44400","7.78723","0.00601"
"93.60000","7.80020","0.00587"
"93.75600","7.81318","0.00581"
"93.91200","7.82627","0.00580"
"94.06800","7.83924","0.00569"
"94.22400","7.85222","0.00631"
"94.38000","7.86525","0.00557"
"94.53600","7.87823","0.00577"
"94.69200","7.89120","0.00545"
"94.84800","7.90418","0.00582"
"95.00400","7.91721","0.00559"
"95.16000","7.93024","0.00569"
"95.31600","7.94316","0.00660"
"95.47200","7.95625","0.00600"
"95.62800","7.96923","0.00528"
"95.78400","7.98220","0.00530"
"95.94000","7.99524","0.00569"
"96.09600","8.00827","0.00616"
"96.25200","8.02124","0.00517"
"96.40800","8.03416","0.00549"
"96.56400","8.04725","0.00546"
"96.72000","8.06023","0.00633"
"96.87600","8.07314","0.00532"
"97.03200","8.08618","0.00554"
"97.18800","8.09927","0.00556"
"97.34400","8.11230","0.00546"
"97.50000","8.12522","0.00577"
"97.65600","8.13825","0.00540"
"97.81200","8.15129","0.00544"
"97.96800","8.16420","0.00560"
"98.12400","8.17718","0.00591"
"98.28000","8.19027","0.00570"
"98.43600","8.20318","0.00561"
"98.59200","8.21610","0.00566"
"98.74800","8.22919","0.00588"
"98.90400","8.24223","0.00531"
"99.06000","8.25520","0.00560"
"99.21600","8.26823","0.00585"
"99.37200","8.28127","0.00584"
"99.52800","8.29424","0.00553"
"99.68400","8.30722","0.00527"
"99.84000","8.32019","0.00548"
"99.99600","8.33323","0.00514"
"100.15200","8.34620","0.00526"
"100.30800","8.35923","0.00502"
"100.46400","8.37227","0.00522"
"100.62000","8.38524","0.00512"
"100.77600","8.39822","0.00485"
"100.93200","8.41125","0.00515"
"101.08800","8.42428","0.00544"
"101.24400","8.43720","0.00480"
"101.40000","8.45023","0.00501"
"101.55600","8.46327","0.00506"
"101.71200","8.47624","0.00481"
"101.86800","8.48916","0.00508"
"102.02400","8.50219","0.00478"
"102.18000","8.51517","0.00507"
"102.33600","8.52814","0.00554"
"102.49200","8.54123","0.00524"
"102.64800","8.55427","0.00486"
"102.80400","8.56724","0.00497"
"102.96000","8.58022","0.00475"
"103.11600","8.59319","0.00493"
"103.27200","8.60623","0.00453"
"103.42800","8.61914","0.00472"
"103.58400","8.63223","0.00467"
"103.74000","8.64527","0.00518"
"103.89600","8.65818","0.00470"
"104.05200","8.67122","0.00484"
"104.20800","8.68425","0.00486"
"104.36400","8.69722","0.00494"
"104.52000","8.71020","0.00477"
"104.67600","8.72323","0.00413"
"104.83200","8.73627","0.00492"
"104.98800","8.74918","0.00482"
"105.14400","8.76222","0.00483"
"105.30000","8.77525","0.00487"
"105.45600","8.78822","0.00438"
"105.61200","8.80120","0.00445"
"105.76800","8.81423","0.00418"
"105.92400","8.82721","0.00502"
"106.08000","8.84018","0.00480"
"106.23600","8.85322","0.00438"
"106.39200","8.86625","0.00511"
"106.54800","8.87916","0.00417"
"106.70400","8.89220","0.00498"
"106.86000","8.90523","0.00476"
"107.01600","8.91821","0.00507"
"107.17200","8.93118","0.00452"
"107.32800","8.94421","0.00441"
"107.48400","8.95725","0.00461"
"107.64000","8.97022","0.00491"
"107.79600","8.98320","0.00447"
"107.95200","8.99623","0.00458"
"108.10800","9.00921","0.00451"
"108.26400","9.02218","0.00461"
"108.42000","9.03521","0.00444"
"108.57600","9.04825","0.00516"
"108.73200","9.06122","0.00459"
"108.88800","9.07420","0.00473"
"109.04400","9.08723","0.00482"
"109.20000","9.10021","0.00420"
"109.35600","9.11318","0.00464"
"109.51200","9.12621","0.00464"
"109.66800","9.13919","0.00498"
"109.82400","9.15216","0.00441"
"109.98000","9.16526","0.00466"
"110.13600","9.17829","0.00461"
"110.29200","9.19127","0.00488"
"110.44800","9.20424","0.00502"
"110.60400","9.21727","0.00459"
"110.76000","9.23019","0.00435"
"110.91600","9.24316","0.00483"
"111.07200","9.25626","0.00434"
"111.22800","9.26917","0.00460"
"111.38400","9.28215","0.00471"
"111.54000","9.29518","0.00451"
"111.69600","9.30821","0.00473"
"111.85200","9.32125","0.00486"
"112.00800","9.33416","0.00447"
"112.16400","9.34726","0.00530"
"112.32000","9.36029","0.00483"
"112.47600","9.37315","0.00498"
"112.63200","9.38624","0.00500"
"112.78800","9.39921","0.00491"
"112.94400","9.41219","0.00493"
"113.10000","9.42510","0.00481"
"113.25600","9.43826","0.00467"
"113.41200","9.45129","0.00427"
"113.56800","9.46420","0.00519"
"113.72400","9.47724","0.00425"
"113.88000","9.49021","0.00486"
"114.03600","9.50325","0.00465"
"114.19200","9.51616","0.00519"
"114.34800","9.52926","0.00519"
"114.50400","9.54223","0.00471"
"114.66000","9.55520","0.00528"
"114.81600","9.56818","0.00452"
"114.97200","9.58127","0.00425"
"115.12800","9.59419","0.00465"
"115.28400","9.60722","0.00479"
"115.44000","9.62026","0.00513"
"115.59600","9.63329","0.00481"
"115.75200","9.64614","0.00476"
"115.90800","9.65918","0.00505"
"116.06400","9.67221","0.00469"
"116.22000","9.68519","0.00508"
"116.37600","9.69816","0.00489"
"116.53200","9.71120","0.00545"
"116.68800","9.72423","0.00536"
"116.84400","9.73714","0.00550"
"117.00000","9.75024","0.00490"
"117.15600","9.76321","0.00478"
"117.31200","9.77619","0.00537"
"117.46800","9.78916","0.00524"
"117.62400","9.80219","0.00488"
"117.78000","9.81523","0.00469"
"117.93600","9.82814","0.00548"
"118.09200","9.84124","0.00455"
"118.24800","9.85421","0.00469"
"118.40400","9.86719","0.00455"
"118.56000","9.88016","0.00455"
"118.71600","9.89325","0.00602"
"118.87200","9.90629","0.00537"
"119.02800","9.91926","0.00547"
"119.18400","9.93230","0.00514"
"119.34000","9.94521","0.00556"
"119.49600","9.95819","0.00497"
"119.65200","9.97122","0.00485"
"119.80800","9.98425","0.00546"
"119.96400","9.99717","0.00538"
"120.12000","10.01020","0.00537"
"120.27600","10.02324","0.00499"
"120.43200","10.03621","0.00561"
"120.58800","10.04919","0.00573"
"120.74400","10.06222","0.00575"
"120.90000","10.07519","0.00509"
"121.05600","10.08823","0.00495"
"121.21200","10.10120","0.00486"
"121.36800","10.11424","0.00514"
"121.52400","10.12721","0.00505"
"121.68000","10.14019","0.00503"
"121.83600","10.15322","0.00524"
"121.99200","10.16625","0.00523"
"122.14800","10.17917","0.00562"
"122.30400","10.19220","0.00494"
"122.46000","10.20524","0.00546"
"122.61600","10.21821","0.00515"
"122.77200","10.23118","0.00516"
"122.92800","10.24428","0.00598"
"123.08400","10.25725","0.00579"
"123.24000","10.27017","0.00534"
"123.39600","10.28314","0.00581"
"123.55200","10.29624","0.00581"
"123.70800","10.30921","0.00542"
"123.86400","10.32212","0.00566"
"124.02000","10.33516","0.00563"
"124.17600","10.34825","0.00554"
"124.33200","10.36117","0.00580"
"124.48800","10.37426","0.00596"
"124.64400","10.38724","0.00519"
"124.80000","10.40027","0.00499"
"124.95600","10.41318","0.00599"
"125.11200","10.42628","0.00531"
"125.26800","10.43925","0.00543"
"125.42400","10.45223","0.00566"
"125.58000","10.46514","0.00595"
"125.73600","10.47824","0.00541"
"125.89200","10.49121","0.00540"
"126.04800","10.50424","0.00568"
"126.20400","10.51728","0.00568"
"126.36000","10.53025","0.00544"
"126.51600","10.54323","0.00546"
"126.67200","10.55626","0.00523"
"126.82800","10.56923","0.00539"
"126.98400","10.58221","0.00509"
"127.14000","10.59518","0.00553"
"127.29600","10.60822","0.00538"
"127.45200","10.62119","0.00549"
"127.60800","10.63417","0.00573"
"127.76400","10.64726","0.00536"
"127.92000","10.66023","0.00571"
"128.07600","10.67321","0.00528"
"128.23199","10.68618","0.00562"
"128.38800","10.69922","0.00532"
"128.54401","10.71219","0.00595"
"128.70000","10.72523","0.00531"
"128.85600","10.73820","0.00592"
"129.01199","10.75123","0.00542"
"129.16800","10.76415","0.00553"
"129.32401","10.77724","0.00542"
"129.48000","10.79022","0.00538"
"129.63600","10.80325","0.00562"
"129.79201","10.81617","0.00561"
"129.94800","10.82926","0.00549"
"130.10400","10.84217","0.00572"
"130.25999","10.85515","0.00563"
"130.41600","10.86818","0.00537"
"130.57201","10.88122","0.00529"
"130.72800","10.89419","0.00558"
"130.88400","10.90717","0.00563"
"131.03999","10.92026","0.00566"
"131.19600","10.93323","0.00533"
"131.35201","10.94621","0.00577"
"131.50800","10.95924","0.00553"
"131.66400","10.97228","0.00570"
"131.82001","10.98525","0.00581"
"131.97600","10.99823","0.00552"
"132.13200","11.01126","0.00591"
"132.28799","11.02423","0.00595"
"132.44400","11.03715","0.00590"
"132.60001","11.05024","0.00560"
"132.75600","11.06328","0.00568"
"132.91200","11.07619","0.00598"
"133.06799","11.08922","0.00596"
"133.22400","11.10226","0.00593"
"133.38000","11.11529","0.00602"
"133.53600","11.12821","0.00580"
"133.69200","11.14124","0.00556"
"133.84801","11.15427","0.00597"
"134.00400","11.16719","0.00608"
"134.16000","11.18022","0.00623"
"134.31599","11.19320","0.00576"
"134.47200","11.20617","0.00630"
"134.62801","11.21915","0.00646"
"134.78400","11.23224","0.00593"
"134.94000","11.24527","0.00592"
"135.09599","11.25819","0.00571"
"135.25200","11.27116","0.00619"
"135.40800","11.28426","0.00614"
"135.56400","11.29723","0.00607"
"135.72000","11.31015","0.00607"
"135.87601","11.32324","0.00608"
"136.03200","11.33622","0.00642"
"136.18800","11.34925","0.00614"
"136.34399","11.36222","0.00635"
"136.50000","11.37520","0.00639"
"136.65601","11.38817","0.00593"
"136.81200","11.40115","0.00622"
"136.96800","11.41424","0.00614"
"137.12399","11.42722","0.00590"
"137.28000","11.44019","0.00612"
"137.43600","11.45322","0.00620"
"137.59200","11.46626","0.00600"
"137.74800","11.47923","0.00546"
"137.90401","11.49221","0.00578"
"138.06000","11.50524","0.00642"
"138.21600","11.51822","0.00672"
"138.37199","11.53113","0.00625"
"138.52800","11.54428","0.00628"
"138.68401","11.55726","0.00619"
"138.84000","11.57023","0.00605"
"138.99600","11.58321","0.00623"
"139.15199","11.59624","0.00612"
"139.30800","11.60921","0.00598"
"139.46400","11.62213","0.00629"
"139.62000","11.63522","0.00709"
"139.77600","11.64826","0.00650"
"139.93201","11.66117","0.00646"
"140.08800","11.67420","0.00611"
"140.24400","11.68724","0.00638"
"140.39999","11.70021","0.00651"
"140.55600","11.71319","0.00614"
"140.71201","11.72628","0.00652"
"140.86800","11.73926","0.00633"
"141.02400","11.75217","0.00664"
"141.17999","11.76515","0.00625"
"141.33600","11.77824","0.00607"
"141.49200","11.79121","0.00653"
"141.64799","11.80413","0.00631"
"141.80400","11.81722","0.00617"
"141.96001","11.83026","0.00598"
"142.11600","11.84317","0.00622"
"142.27200","11.85620","0.00593"
"142.42799","11.86930","0.00616"
"142.58400","11.88221","0.00593"
"142.74001","11.89525","0.00640"
"142.89600","11.90816","0.00560"
"143.05200","11.92120","0.00607"
"143.20799","11.93411","0.00638"
"143.36400","11.94720","0.00625"
"143.52000","11.96024","0.00650"
"143.67599","11.97321","0.00677"
"143.83200","11.98619","0.00708"
"143.98801","11.99922","0.00597"
"144.14400","12.01219","0.00695"
"144.30000","12.02517","0.00566"
"144.45599","12.03826","0.00575"
"144.61200","12.05124","0.00693"
"144.76801","12.06421","0.00671"
"144.92400","12.07719","0.00578"
"145.08000","12.09016","0.00639"
"145.23599","12.10314","0.00701"
"145.39200","12.11617","0.00646"
"145.54800","12.12926","0.00638"
"145.70399","12.14224","0.00649"
"145.86000","12.15521","0.00617"
"146.01601","12.16819","0.00595"
"146.17200","12.18122","0.00619"
"146.32800","12.19420","0.00599"
"146.48399","12.20717","0.00692"
"146.64000","12.22026","0.00673"
"146.79601","12.23324","0.00662"
"146.95200","12.24615","0.00622"
"147.10800","12.25919","0.00682"
"147.26401","12.27222","0.00652"
"147.42000","12.28520","0.00699"
"147.57600","12.29823","0.00629"
"147.73199","12.31126","0.00650"
"147.88800","12.32424","0.00658"
"148.04401","12.33715","0.00638"
"148.20000","12.35025","0.00617"
"148.35600","12.36322","0.00691"
"148.51199","12.37619","0.00566"
"148.66800","12.38917","0.00633"
"148.82401","12.40226","0.00631"
"148.98000","12.41524","0.00620"
"149.13600","12.42821","0.00657"
"149.29201","12.44118","0.00607"
"149.44800","12.45422","0.00632"
"149.60400","12.46713","0.00677"
"149.75999","12.48017","0.00611"
"149.91600","12.49320","0.00580"
"150.07201","12.50624","0.00633"
"150.22800","12.51915","0.00622"
"150.38400","12.53218","0.00620"
"150.53999","12.54522","0.00613"
"150.69600","12.55819","0.00599"
"150.85201","12.57117","0.00638"
"151.00800","12.58426","0.00596"
"151.16400","12.59724","0.00662"
"151.32001","12.61021","0.00672"
"151.47600","12.62324","0.00603"
"151.63200","12.63622","0.00655"
"151.78799","12.64919","0.00641"
"151.94400","12.66223","0.00691"
"152.10001","12.67520","0.00715"
"152.25600","12.68824","0.00656"
"152.41200","12.70115","0.00670"
"152.56799","12.71424","0.00623"
"152.72400","12.72722","0.00665"
"152.88000","12.74019","0.00658"
"153.03600","12.75323","0.00625"
"153.19200","12.76626","0.00621"
"153.34801","12.77918","0.00648"
"153.50400","12.79221","0.00654"
"153.66000","12.80524","0.00615"
"153.81599","12.81822","0.00579"
"153.97200","12.83113","0.00601"
"154.12801","12.84417","0.00555"
"154.28400","12.85720","0.00571"
"154.44000","12.87017","0.00529"
"154.59599","12.88321","0.00581"
"154.75200","12.89624","0.00508"
"154.90800","12.90922","0.00504"
"155.06400","12.92219","0.00533"
"155.22000","12.93529","0.00563"
"155.37601","12.94826","0.00529"
"155.53200","12.96117","0.00542"
"155.68800","12.97421","0.00493"
"155.84399","12.98718","0.00585"
"156.00000","13.00016","0.00534"
"156.15601","13.01313","0.00511"
"156.31200","13.02629","0.00577"
"156.46800","13.03926","0.00543"
"156.62399","13.05217","0.00503"
"156.78000","13.06521","0.00523"
"156.93600","13.07824","0.00576"
"157.09200","13.09122","0.00582"
"157.24800","13.10419","0.00556"
"157.40401","13.11729","0.00582"
"157.56000","13.13026","0.00563"
"157.71600","13.14317","0.00548"
"157.87199","13.15621","0.00522"
"158.02800","13.16924","0.00571"
"158.18401","13.18222","0.00554"
"158.34000","13.19519","0.00534"
"158.49600","13.20823","0.00538"
"158.65199","13.22126","0.00562"
"158.80800","13.23417","0.00556"
"158.96400","13.24727","0.00541"
"159.12000","13.26024","0.00502"
"159.27600","13.27316","0.00578"
"159.43201","13.28619","0.00512"
"159.58800","13.29923","0.00594"
"159.74400","13.31220","0.00535"
"159.89999","13.32517","0.00554"
"160.05600","13.33827","0.00561"
"160.21201","13.35124","0.00572"
"160.36800","13.36422","0.00542"
"160.52400","13.37719","0.00596"
"160.67999","13.39023","0.00564"
"160.83600","13.40320","0.00566"
"160.99200","13.41617","0.00533"
"161.14799","13.42921","0.00599"
"161.30400","13.44224","0.00540"
"161.46001","13.45522","0.00560"
"161.61600","13.46825","0.00605"
"161.77200","13.48128","0.00559"
"161.92799","13.49426","0.00540"
"162.08400","13.50723","0.00579"
"162.24001","13.52027","0.00581"
"162.39600","13.53318","0.00633"
"162.55200","13.54616","0.00550"
"162.70799","13.55919","0.00633"
"162.86400","13.57222","0.00564"
"163.02000","13.58514","0.00604"
"163.17599","13.59817","0.00564"
"163.33200","13.61121","0.00597"
"163.48801","13.62424","0.00591"
"163.64400","13.63722","0.00600"
"163.80000","13.65025","0.00552"
"163.95599","13.66322","0.00606"
"164.11200","13.67626","0.00561"
"164.26801","13.68917","0.00582"
"164.42400","13.70221","0.00583"
"164.58000","13.71524","0.00608"
"164.73599","13.72816","0.00615"
"164.89200","13.74125","0.00620"
"165.04800","13.75428","0.00614"
"165.20399","13.76720","0.00616"
"165.36000","13.78023","0.00587"
"165.51601","13.79327","0.00606"
"165.67200","13.80624","0.00585"
"165.82800","13.81916","0.00627"
"165.98399","13.83225","0.00566"
"166.14000","13.84528","0.00602"
"166.29601","13.85820","0.00624"
"166.45200","13.87117","0.00607"
"166.60800","13.88421","0.00600"
"166.76401","13.89718","0.00606"
"166.92000","13.91015","0.00600"
"167.07600","13.92319","0.00605"
"167.23199","13.93628","0.00641"
"167.38800","13.94920","0.00619"
"167.54401","13.96223","0.00598"
"167.70000","13.97527","0.00622"
"167.85600","13.98824","0.00627"
"168.01199","14.00115","0.00615"
"168.16800","14.01425","0.00620"
"168.32401","14.02722","0.00596"
"168.48000","14.04020","0.00619"
"168.63600","14.05323","0.00590"
"168.79201","14.06621","0.00609"
"168.94800","14.07918","0.00657"
"169.10400","14.09221","0.00586"
"169.25999","14.10531","0.00570"
"169.41600","14.11828","0.00651"
"169.57201","14.13120","0.00643"
"169.72800","14.14423","0.00627"
"169.88400","14.15721","0.00624"
"170.03999","14.17024","0.00604"
"170.19600","14.18321","0.00622"
"170.35201","14.19625","0.00629"
"170.50800","14.20922","0.00638"
"170.66400","14.22220","0.00629"
"170.82001","14.23523","0.00589"
"170.97600","14.24821","0.00677"
"171.13200","14.26118","0.00669"
"171.28799","14.27421","0.00677"
"171.44400","14.28725","0.00590"
"171.60001","14.30016","0.00631"
"171.75600","14.31320","0.00688"
"171.91200","14.32623","0.00616"
"172.06799","14.33926","0.00626"
"172.22400","14.35218","0.00659"
"172.38000","14.36521","0.00663"
"172.53600","14.37825","0.00681"
"172.69200","14.39122","0.00638"
"172.84801","14.40420","0.00659"
"173.00400","14.41729","0.00655"
"173.16000","14.43020","0.00647"
"173.31599","14.44318","0.00632"
"173.47200","14.45621","0.00687"
"173.62801","14.46925","0.00677"
"173.78400","14.48222","0.00632"
"173.94000","14.49514","0.00653"
"174.09599","14.50823","0.00633"
"174.25200","14.52120","0.00678"
"174.40800","14.53418","0.00685"
"174.56400","14.54727","0.00588"
"174.72000","14.56025","0.00732"
"174.87601","14.57322","0.00607"
"175.03200","14.58619","0.00649"
"175.18800","14.59917","0.00695"
"175.34399","14.61220","0.00680"
"175.50000","14.62512","0.00631"
"175.65601","14.63821","0.00608"
"175.81200","14.65125","0.00641"
"175.96800","14.66422","0.00649"
"176.12399","14.67725","0.00670"
"176.28000","14.69029","0.00664"
"176.43600","14.70326","0.00690"
"176.59200","14.71618","0.00642"
"176.74800","14.72921","0.00649"
"176.90401","14.74231","0.00664"
"177.06000","14.75516","0.00654"
"177.21600","14.76820","0.00665"
"177.37199","14.78123","0.00623"
"177.52800","14.79420","0.00632"
"177.68401","14.80718","0.00649"
"177.84000","14.82027","0.00629"
"177.99600","14.83325","0.00677"
"178.15199","14.84622","0.00684"
"178.30800","14.85919","0.00632"
"178.46400","14.87223","0.00683"
"178.62000","14.88520","0.00638"
"178.77600","14.89818","0.00667"
"178.93201","14.91127","0.00689"
"179.08800","14.92418","0.00687"
"179.24400","14.93716","0.00628"
"179.39999","14.95019","0.00669"
"179.55600","14.96323","0.00617"
"179.71201","14.97620","0.00665"
"179.86800","14.98924","0.00726"
"180.02400","15.00221","0.00688"
"180.17999","15.01518","0.00669"
"180.33600","15.02816","0.00651"
"180.49200","15.04119","0.00697"
"180.64799","15.05429","0.00712"
"180.80400","15.06720","0.00644"
"180.96001","15.08018","0.00707"
"181.11600","15.09321","0.00721"
"181.27200","15.10624","0.00619"
"181.42799","15.11916","0.00687"
"181.58400","15.13225","0.00703"
"181.74001","15.14523","0.00646"
"181.89600","15.15820","0.00636"
"182.05200","15.17124","0.00656"
"182.20799","15.18427","0.00678"
"182.36400","15.19724","0.00664"
"182.52000","15.21016","0.00694"
"182.67599","15.22325","0.00695"
"182.83200","15.23623","0.00699"
"182.98801","15.24914","0.00696"
"183.14400","15.26223","0.00686"
"183.30000","15.27527","0.00658"
"183.45599","15.28824","0.00716"
"183.61200","15.30122","0.00757"
"183.76801","15.31425","0.00724"
"183.92400","15.32723","0.00704"
"184.08000","15.34014","0.00669"
"184.23599","15.35318","0.00710"
"184.39200","15.36621","0.00748"
"184.54800","15.37918","0.00744"
"184.70399","15.39216","0.00713"
"184.86000","15.40525","0.00746"
"185.01601","15.41823","0.00720"
"185.17200","15.43120","0.00715"
"185.32800","15.44417","0.00728"
"185.48399","15.45727","0.00722"
"185.64000","15.47018","0.00704"
"185.79601","15.48322","0.00719"
"185.95200","15.49619","0.00755"
"186.10800","15.50923","0.00685"
"186.26401","15.52214","0.00741"
"186.42000","15.53523","0.00760"
"186.57600","15.54821","0.00738"
"186.73199","15.56124","0.00727"
"186.88800","15.57422","0.00698"
"187.04401","15.58725","0.00752"
"187.20000","15.60023","0.00730"
"187.35600","15.61320","0.00791"
"187.51199","15.62623","0.00780"
"187.66800","15.63927","0.00785"
"187.82401","15.65218","0.00753"
"187.98000","15.66516","0.00778"
"188.13600","15.67819","0.00750"
"188.29201","15.69116","0.00752"
"188.44800","15.70414","0.00763"
"188.60400","15.71723","0.00781"
"188.75999","15.73027","0.00639"
"188.91600","15.74318","0.00819"
"189.07201","15.75622","0.00774"
"189.22800","15.76919","0.00722"
"189.38400","15.78222","0.00756"
"189.53999","15.79520","0.00781"
"189.69600","15.80829","0.00696"
"189.85201","15.82121","0.00770"
"190.00800","15.83418","0.00765"
"190.16400","15.84722","0.00697"
"190.32001","15.86025","0.00771"
"190.47600","15.87322","0.00733"
"190.63200","15.88626","0.00746"
"190.78799","15.89929","0.00727"
"190.94400","15.91227","0.00718"
"191.10001","15.92518","0.00783"
"191.25600","15.93822","0.00783"
"191.41200","15.95119","0.00736"
"191.56799","15.96422","0.00816"
"191.72400","15.97720","0.00756"
"191.88000","15.99029","0.00792"
"192.03600","16.00327","0.00784"
"192.19200","16.01618","0.00760"
"192.34801","16.02927","0.00801"
"192.50400","16.04225","0.00821"
"192.66000","16.05516","0.00753"
"192.81599","16.06820","0.00798"
"192.97200","16.08123","0.00752"
"193.12801","16.09421","0.00808"
"193.28400","16.10718","0.00783"
"193.44000","16.12021","0.00783"
"193.59599","16.13325","0.00756"
"193.75200","16.14616","0.00820"
"193.90800","16.15920","0.00783"
"194.06400","16.17223","0.00788"
"194.22000","16.18521","0.00761"
"194.37601","16.19818","0.00749"
"194.53200","16.21121","0.00798"
"194.68800","16.22425","0.00750"
"194.84399","16.23722","0.00809"
"195.00000","16.25020","0.00769"
"195.15601","16.26317","0.00851"
"195.31200","16.27621","0.00797"
"195.46800","16.28918","0.00759"
"195.62399","16.30227","0.00766"
"195.78000","16.31525","0.00804"
"195.93600","16.32822","0.00838"
"196.09200","16.34126","0.00799"
"196.24800","16.35429","0.00815"
"196.40401","16.36720","0.00758"
"196.56000","16.38024","0.00861"
"196.71600","16.39321","0.00820"
"196.87199","16.40619","0.00832"
"197.02800","16.41916","0.00816"
"197.18401","16.43220","0.00839"
"197.34000","16.44523","0.00792"
"197.49600","16.45815","0.00813"
"197.65199","16.47118","0.00852"
"197.80800","16.48427","0.00881"
"197.96400","16.49725","0.00796"
"198.12000","16.51016","0.00812"
"198.27600","16.52325","0.00784"
"198.43201","16.53629","0.00877"
"198.58800","16.54914","0.00857"
"198.74400","16.56224","0.00781"
"198.89999","16.57521","0.00858"
"199.05600","16.58819","0.00895"
"199.21201","16.60116","0.00814"
"199.36800","16.61425","0.00862"
"199.52400","16.62729","0.00924"
"199.67999","16.64021","0.00896"
"199.83600","16.65324","0.00837"
"199.99200","16.66627","0.00849"
"200.14799","16.67925","0.00888"
"200.30400","16.69216","0.00874"
"200.46001","16.70526","0.00863"
"200.61600","16.71823","0.00864"
"200.77200","16.73114","0.00898"
"200.92799","16.74418","0.00797"
"201.08400","16.75721","0.00906"
"201.24001","16.77019","0.00831"
"201.39600","16.78322","0.00850"
"201.55200","16.79626","0.00893"
"201.70799","16.80929","0.00846"
"201.86400","16.82214","0.00882"
"202.02000","16.83524","0.00944"
"202.17599","16.84827","0.00888"
"202.33200","16.86119","0.00843"
"202.48801","16.87422","0.00888"
"202.64400","16.88720","0.00874"
"202.80000","16.90023","0.00862"
"202.95599","16.91320","0.00868"
"203.11200","16.92624","0.00854"
"203.26801","16.93927","0.00923"
"203.42400","16.95219","0.00863"
"203.58000","16.96522","0.00826"
"203.73599","16.97825","0.00887"
"203.89200","16.99123","0.00931"
"204.04800","17.00414","0.00873"
"204.20399","17.01724","0.00872"
"204.36000","17.03021","0.00873"
"204.51601","17.04325","0.00918"
"204.67200","17.05622","0.00919"
"204.82800","17.06925","0.00939"
"204.98399","17.08223","0.00965"
"205.14000","17.09520","0.00860"
"205.29601","17.10830","0.00868"
"205.45200","17.12121","0.00868"
"205.60800","17.13419","0.00902"
"205.76401","17.14722","0.00912"
"205.92000","17.16025","0.00905"
"206.07600","17.17317","0.00859"
"206.23199","17.18620","0.00925"
"206.38800","17.19924","0.00890"
"206.54401","17.21221","0.00906"
"206.70000","17.22519","0.00917"
"206.85600","17.23828","0.00917"
"207.01199","17.25119","0.00903"
"207.16800","17.26417","0.00932"
"207.32401","17.27720","0.00955"
"207.48000","17.29018","0.00929"
"207.63600","17.30321","0.00867"
"207.79201","17.31613","0.00887"
"207.94800","17.32922","0.00855"
"208.10400","17.34225","0.00915"
"208.25999","17.35517","0.00887"
"208.41600","17.36820","0.00938"
"208.57201","17.38130","0.00902"
"208.72800","17.39421","0.00906"
"208.88400","17.40718","0.00906"
"209.03999","17.42028","0.00940"
"209.19600","17.43325","0.00895"
"209.35201","17.44623","0.00854"
"209.50800","17.45920","0.00932"
"209.66400","17.47223","0.00887"
"209.82001","17.48521","0.00935"
"209.97600","17.49818","0.00908"
"210.13200","17.51122","0.00890"
"210.28799","17.52425","0.00844"
"210.44400","17.53717","0.00885"
"210.60001","17.55026","0.00846"
"210.75600","17.56323","0.00867"
"210.91200","17.57621","0.00907"
"211.06799","17.58918","0.00939"
"211.22400","17.60222","0.00886"
"211.38000","17.61525","0.00886"
"211.53600","17.62817","0.00885"
"211.69200","17.64120","0.00896"
"211.84801","17.65423","0.00918"
"212.00400","17.66721","0.00910"
"212.16000","17.68018","0.00906"
"212.31599","17.69328","0.00934"
"212.47200","17.70625","0.00878"
"212.62801","17.71917","0.00939"
"212.78400","17.73220","0.00900"
"212.94000","17.74517","0.00896"
"213.09599","17.75821","0.00929"
"213.25200","17.77118","0.00918"
"213.40800","17.78416","0.00892"
"213.56400","17.79719","0.00937"
"213.72000","17.81017","0.00935"
"213.87601","17.82320","0.00950"
"214.03200","17.83617","0.00946"
"214.18800","17.84921","0.00914"
"214.34399","17.86218","0.01004"
"214.50000","17.87522","0.00896"
"214.65601","17.88819","0.00876"
"214.81200","17.90117","0.00986"
"214.96800","17.91420","0.00916"
"215.12399","17.92723","0.00911"
"215.28000","17.94015","0.00958"
"215.43600","17.95324","0.00953"
"215.59200","17.96628","0.00941"
"215.74800","17.97925","0.00940"
"215.90401","17.99222","0.00949"
"216.06000","18.00526","0.00931"
"216.21600","18.01823","0.00924"
"216.37199","18.03115","0.00972"
"216.52800","18.04424","0.00995"
"216.68401","18.05722","0.00963"
"216.84000","18.07019","0.00971"
"216.99600","18.08316","0.00934"
"217.15199","18.09626","0.00958"
"217.30800","18.10923","0.00925"
"217.46400","18.12221","0.00987"
"217.62000","18.13524","0.00968"
"217.77600","18.14822","0.00956"
"217.93201","18.16119","0.01027"
"218.08800","18.17422","0.00955"
"218.24400","18.18720","0.01031"
"218.39999","18.20017","0.01024"
"218.55600","18.21315","0.01051"
"218.71201","18.22618","0.00956"
"218.86800","18.23927","0.01013"
"219.02400","18.25219","0.00963"
"219.17999","18.26522","0.01006"
"219.33600","18.27826","0.01023"
"219.49200","18.29123","0.01029"
"219.64799","18.30421","0.01007"
"219.80400","18.31724","0.01068"
"219.96001","18.33027","0.00972"
"220.11600","18.34319","0.01028"
"220.27200","18.35622","0.01039"
"220.42799","18.36920","0.01080"
"220.58400","18.38217","0.01078"
"220.74001","18.39515","0.01054"
"220.89600","18.40830","0.01025"
"221.05200","18.42128","0.01073"
"221.20799","18.43419","0.01052"
"221.36400","18.44716","0.01079"
"221.52000","18.46026","0.01110"
"221.67599","18.47323","0.01063"
"221.83200","18.48621","0.01100"
"221.98801","18.49924","0.01043"
"222.14400","18.51221","0.01084"
"222.30000","18.52519","0.01025"
"222.45599","18.53822","0.01076"
"222.61200","18.55120","0.01104"
"222.76801","18.56423","0.01029"
"222.92400","18.57721","0.01064"
"223.08000","18.59024","0.01092"
"223.23599","18.60321","0.01110"
"223.39200","18.61619","0.01112"
"223.54800","18.62922","0.01164"
"223.70399","18.64226","0.01088"
"223.86000","18.65517","0.01121"
"224.01601","18.66821","0.01087"
"224.17200","18.68118","0.01125"
"224.32800","18.69421","0.01128"
"224.48399","18.70713","0.01101"
"224.64000","18.72028","0.01165"
"224.79601","18.73326","0.01119"
"224.95200","18.74623","0.01138"
"225.10800","18.75921","0.01154"
"225.26401","18.77224","0.01082"
"225.42000","18.78521","0.01125"
"225.57600","18.79819","0.01137"
"225.73199","18.81128","0.01061"
"225.88800","18.82426","0.00987"
"226.04401","18.83717","0.00964"
"226.20000","18.85021","0.00779"
"226.35600","18.86330","0.00765"
"226.51199","18.87627","0.00819"
"226.66800","18.88919","0.00829"
"226.82401","18.90222","0.00894"
"226.98000","18.91526","0.00860"
"227.13600","18.92817","0.00911"
"227.29201","18.94120","0.00896"
"227.44800","18.95424","0.00859"
"227.60400","18.96715","0.00834"
"227.75999","18.98019","0.00848"
"227.91600","18.99322","0.00872"
"228.07201","19.00626","0.00842"
"228.22800","19.01923","0.00854"
"228.38400","19.03226","0.00838"
"228.53999","19.04530","0.00875"
"228.69600","19.05815","0.00839"
"228.85201","19.07119","0.00940"
"229.00800","19.08422","0.00895"
"229.16400","19.09726","0.00897"
"229.32001","19.11017","0.00944"
"229.47600","19.12326","0.00856"
"229.63200","19.13624","0.00924"
"229.78799","19.14921","0.00909"
"229.94400","19.16219","0.00989"
"230.10001","19.17528","0.00885"
"230.25600","19.18826","0.00874"
"230.41200","19.20123","0.00940"
"230.56799","19.21426","0.00960"
"230.72400","19.22730","0.00955"
"230.88000","19.24021","0.00938"
"231.03600","19.25319","0.00900"
"231.19200","19.26622","0.00946"
"231.25999","19.27190","0.00935"