File: Force_trajectories/170108_0/Specimen_RawData_3.csv
End date,"1/8/2017"
Specimen label,"20CG_63"
Maximum Load,"0.05759",N

Time,Extension,Load
(s),(mm),(N)
"0.00000","0.00000","0.00030"
"0.28800","0.02326","0.00026"
"0.57600","0.04819","0.00071"
"0.86400","0.07217","0.00129"
"1.15200","0.09620","0.00148"
"1.44000","0.12018","0.00162"
"1.72800","0.14415","0.00193"
"2.01600","0.16813","0.00231"
"2.30400","0.19216","0.00287"
"2.59200","0.21620","0.00303"
"2.88000","0.24011","0.00307"
"3.16800","0.26415","0.00215"
"3.45600","0.28813","0.00287"
"3.74400","0.31216","0.00302"
"4.03200","0.33608","0.00312"
"4.32000","0.36017","0.00310"
"4.60800","0.38415","0.00370"
"4.89600","0.40818","0.00401"
"5.18400","0.43216","0.00352"
"5.47200","0.45619","0.00450"
"5.76000","0.48017","0.00378"
"6.04800","0.50415","0.00370"
"6.33600","0.52818","0.00405"
"6.62400","0.55216","0.00411"
"6.91200","0.57625","0.00423"
"7.20000","0.60017","0.00472"
"7.48800","0.62420","0.00468"
"7.77600","0.64812","0.00403"
"8.06400","0.67221","0.00502"
"8.35200","0.69613","0.00493"
"8.64000","0.72022","0.00514"
"8.92800","0.74420","0.00458"
"9.21600","0.76818","0.00556"
"9.50400","0.79215","0.00434"
"9.79200","0.81619","0.00390"
"10.08000","0.84022","0.00389"
"10.36800","0.86420","0.00468"
"10.65600","0.88823","0.00448"
"10.94400","0.91215","0.00473"
"11.23200","0.93624","0.00448"
"11.52000","0.96016","0.00438"
"11.80800","0.98426","0.00476"
"12.09600","1.00817","0.00532"
"12.38400","1.03221","0.00470"
"12.67200","1.05618","0.00511"
"12.96000","1.08022","0.00542"
"13.24800","1.10419","0.00517"
"13.53600","1.12817","0.00522"
"13.82400","1.15214","0.00543"
"14.11200","1.17618","0.00570"
"14.40000","1.20027","0.00613"
"14.68800","1.22419","0.00639"
"14.97600","1.24823","0.00613"
"15.26400","1.27220","0.00535"
"15.55200","1.29624","0.00661"
"15.84000","1.32009","0.00594"
"16.12800","1.34419","0.00731"
"16.41600","1.36816","0.00646"
"16.70400","1.39220","0.00651"
"16.99200","1.41617","0.00683"
"17.28000","1.44021","0.00669"
"17.56800","1.46419","0.00687"
"17.85600","1.48822","0.00720"
"18.14400","1.51220","0.00729"
"18.43200","1.53617","0.00621"
"18.72000","1.56021","0.00631"
"19.00800","1.58412","0.00623"
"19.29600","1.60822","0.00619"
"19.58400","1.63213","0.00652"
"19.87200","1.65623","0.00671"
"20.16000","1.68015","0.00674"
"20.44800","1.70418","0.00677"
"20.73600","1.72816","0.00713"
"21.02400","1.75219","0.00735"
"21.31200","1.77617","0.00744"
"21.60000","1.80020","0.00734"
"21.88800","1.82418","0.00748"
"22.17600","1.84815","0.00769"
"22.46400","1.87225","0.00773"
"22.75200","1.89623","0.00834"
"23.04000","1.92026","0.00848"
"23.32800","1.94412","0.00869"
"23.61600","1.96815","0.00828"
"23.90400","1.99213","0.00871"
"24.19200","2.01622","0.00843"
"24.48000","2.04014","0.00837"
"24.76800","2.06417","0.00942"
"25.05600","2.08815","0.00971"
"25.34400","2.11219","0.00944"
"25.63200","2.13616","0.00982"
"25.92000","2.16020","0.00971"
"26.20800","2.18417","0.00983"
"26.49600","2.20815","0.00940"
"26.78400","2.23224","0.00985"
"27.07200","2.25616","0.00937"
"27.36000","2.28019","0.00939"
"27.64800","2.30417","0.00941"
"27.93600","2.32820","0.00944"
"28.22400","2.35212","0.01038"
"28.51200","2.37622","0.01038"
"28.80000","2.40019","0.01053"
"29.08800","2.42423","0.01042"
"29.37600","2.44820","0.01113"
"29.66400","2.47218","0.01066"
"29.95200","2.49615","0.01152"
"30.24000","2.52019","0.01100"
"30.52800","2.54422","0.01154"
"30.81600","2.56814","0.01158"
"31.10400","2.59218","0.01196"
"31.39200","2.61615","0.01186"
"31.68000","2.64013","0.01175"
"31.96800","2.66410","0.01180"
"32.25600","2.68814","0.01235"
"32.54400","2.71211","0.01233"
"32.83200","2.73615","0.01277"
"33.12000","2.76012","0.01294"
"33.40800","2.78422","0.01338"
"33.69600","2.80819","0.01300"
"33.98400","2.83217","0.01283"
"34.27200","2.85621","0.01335"
"34.56000","2.88018","0.01325"
"34.84800","2.90422","0.01334"
"35.13600","2.92813","0.01338"
"35.42400","2.95223","0.01379"
"35.71200","2.97614","0.01425"
"36.00000","3.00018","0.01448"
"36.28800","3.02410","0.01416"
"36.57600","3.04825","0.01427"
"36.86400","3.07217","0.01493"
"37.15200","3.09620","0.01474"
"37.44000","3.12012","0.01481"
"37.72800","3.14415","0.01535"
"38.01600","3.16819","0.01544"
"38.30400","3.19216","0.01574"
"38.59200","3.21620","0.01537"
"38.88000","3.24017","0.01586"
"39.16800","3.26421","0.01636"
"39.45600","3.28813","0.01648"
"39.74400","3.31216","0.01676"
"40.03200","3.33614","0.01675"
"40.32000","3.36017","0.01690"
"40.60800","3.38415","0.01708"
"40.89600","3.40818","0.01749"
"41.18400","3.43216","0.01731"
"41.47200","3.45619","0.01803"
"41.76000","3.48017","0.01816"
"42.04800","3.50420","0.01780"
"42.33600","3.52824","0.01850"
"42.62400","3.55216","0.01862"
"42.91200","3.57619","0.01878"
"43.20000","3.60017","0.01869"
"43.48800","3.62420","0.01950"
"43.77600","3.64812","0.01901"
"44.06400","3.67221","0.01939"
"44.35200","3.69613","0.01954"
"44.64000","3.72022","0.01995"
"44.92800","3.74414","0.02020"
"45.21600","3.76824","0.02087"
"45.50400","3.79221","0.02012"
"45.79200","3.81619","0.02086"
"46.08000","3.84016","0.02141"
"46.36800","3.86420","0.02150"
"46.65600","3.88817","0.02179"
"46.94400","3.91215","0.02234"
"47.23200","3.93624","0.02229"
"47.52000","3.96022","0.02247"
"47.80800","3.98425","0.02310"
"48.09600","4.00817","0.02293"
"48.38400","4.03221","0.02354"
"48.67200","4.05618","0.02353"
"48.96000","4.08022","0.02327"
"49.24800","4.10413","0.02384"
"49.53600","4.12823","0.02348"
"49.82400","4.15220","0.02350"
"50.11200","4.17618","0.02389"
"50.40000","4.20021","0.02400"
"50.68800","4.22419","0.02408"
"50.97600","4.24823","0.00513"
"51.26400","4.27214","0.00637"
"51.55200","4.29624","0.00935"
"51.84000","4.32015","0.01017"
"52.12800","4.34419","0.00899"
"52.41600","4.36816","0.00913"
"52.70400","4.39226","0.00991"
"52.99200","4.41617","0.01130"
"53.28000","4.44021","0.01147"
"53.56800","4.46419","0.01154"
"53.85600","4.48822","0.01226"
"54.14400","4.51220","0.01206"
"54.43200","4.53623","0.01361"
"54.72000","4.56021","0.01353"
"55.00800","4.58424","0.01364"
"55.29600","4.60822","0.01364"
"55.58400","4.63219","0.01429"
"55.87200","4.65623","0.01423"
"56.16000","4.68021","0.01474"
"56.44800","4.70424","0.01531"
"56.73600","4.72822","0.01555"
"57.02400","4.75225","0.01555"
"57.31200","4.77617","0.01589"
"57.60000","4.80014","0.01624"
"57.88800","4.82412","0.01565"
"58.17600","4.84815","0.01671"
"58.46400","4.87213","0.01685"
"58.75200","4.89616","0.01717"
"59.04000","4.92020","0.01731"
"59.32800","4.94418","0.01807"
"59.61600","4.96827","0.01776"
"59.90400","4.99213","0.01811"
"60.19200","5.01622","0.01820"
"60.48000","5.04014","0.01845"
"60.76800","5.06423","0.01894"
"61.05600","5.08815","0.01870"
"61.34400","5.11218","0.01934"
"61.63200","5.13616","0.01914"
"61.92000","5.16020","0.01951"
"62.20800","5.18417","0.02005"
"62.49600","5.20821","0.01928"
"62.78400","5.23218","0.01992"
"63.07200","5.25616","0.02050"
"63.36000","5.28019","0.02062"
"63.64800","5.30411","0.02006"
"63.93600","5.32814","0.02068"
"64.22400","5.35212","0.02068"
"64.51200","5.37621","0.02034"
"64.80000","5.40013","0.02127"
"65.08800","5.42417","0.02146"
"65.37600","5.44814","0.02266"
"65.66400","5.47224","0.02143"
"65.95200","5.49621","0.02193"
"66.24000","5.52013","0.02245"
"66.52800","5.54416","0.02262"
"66.81600","5.56820","0.02232"
"67.10400","5.59223","0.02288"
"67.39200","5.61615","0.02350"
"67.68000","5.64025","0.02314"
"67.96800","5.66416","0.02356"
"68.25600","5.68820","0.02359"
"68.54400","5.71211","0.02391"
"68.83200","5.73621","0.02408"
"69.12000","5.76018","0.02393"
"69.40800","5.78422","0.02384"
"69.69600","5.80814","0.02424"
"69.98400","5.83217","0.02445"
"70.27200","5.85615","0.02475"
"70.56000","5.88018","0.02502"
"70.84800","5.90416","0.02495"
"71.13600","5.92813","0.02552"
"71.42400","5.95217","0.02599"
"71.71200","5.97614","0.02553"
"72.00000","6.00018","0.02571"
"72.28800","6.02415","0.02587"
"72.57600","6.04813","0.02670"
"72.86400","6.07211","0.02665"
"73.15200","6.09620","0.02697"
"73.44000","6.12012","0.02748"
"73.72800","6.14415","0.02769"
"74.01600","6.16813","0.02749"
"74.30400","6.19222","0.02760"
"74.59200","6.21614","0.02802"
"74.88000","6.24011","0.02861"
"75.16800","6.26415","0.02853"
"75.45600","6.28812","0.02878"
"75.74400","6.31216","0.02911"
"76.03200","6.33614","0.02910"
"76.32000","6.36017","0.02967"
"76.60800","6.38421","0.03007"
"76.89600","6.40818","0.03038"
"77.18400","6.43210","0.02999"
"77.47200","6.45619","0.03022"
"77.76000","6.48005","0.03032"
"78.04800","6.50420","0.03099"
"78.33600","6.52818","0.03120"
"78.62400","6.55216","0.03131"
"78.91200","6.57613","0.03188"
"79.20000","6.60017","0.03124"
"79.48800","6.62414","0.03172"
"79.77600","6.64812","0.03162"
"80.06400","6.67215","0.03186"
"80.35200","6.69613","0.03235"
"80.64000","6.72016","0.03188"
"80.92800","6.74414","0.03202"
"81.21600","6.76818","0.03245"
"81.50400","6.79209","0.03316"
"81.79200","6.81619","0.03231"
"82.08000","6.84016","0.03302"
"82.36800","6.86420","0.03313"
"82.65600","6.88817","0.03225"
"82.94400","6.91221","0.03238"
"83.23200","6.93618","0.03340"
"83.52000","6.96016","0.03326"
"83.80800","6.98420","0.03351"
"84.09600","7.00811","0.03424"
"84.38400","7.03215","0.03435"
"84.67200","7.05612","0.03499"
"84.96000","7.08016","0.03496"
"85.24800","7.10413","0.03494"
"85.53600","7.12817","0.03531"
"85.82400","7.15208","0.03594"
"86.11200","7.17624","0.03675"
"86.40000","7.20015","0.03615"
"86.68800","7.22419","0.03702"
"86.97600","7.24817","0.03654"
"87.26400","7.27220","0.03673"
"87.55200","7.29618","0.03681"
"87.84000","7.32015","0.03641"
"88.12800","7.34419","0.03561"
"88.41600","7.36816","0.03592"
"88.70400","7.39220","0.03627"
"88.99200","7.41611","0.03722"
"89.28000","7.44021","0.03782"
"89.56800","7.46413","0.03831"
"89.85600","7.48822","0.03880"
"90.14400","7.51214","0.03884"
"90.43200","7.53617","0.03888"
"90.72000","7.56021","0.03820"
"91.00800","7.58418","0.03437"
"91.29600","7.60822","0.03476"
"91.58400","7.63225","0.03538"
"91.87200","7.65623","0.03618"
"92.16000","7.68015","0.03725"
"92.44800","7.70424","0.03809"
"92.73600","7.72816","0.03819"
"93.02400","7.75225","0.03672"
"93.31200","7.77611","0.03807"
"93.60000","7.80014","0.03867"
"93.88800","7.82412","0.03952"
"94.17600","7.84815","0.03984"
"94.46400","7.87219","0.03981"
"94.75200","7.89622","0.04123"
"95.04000","7.92020","0.04167"
"95.32800","7.94418","0.04163"
"95.61600","7.96821","0.04273"
"95.90400","7.99219","0.04287"
"96.19200","8.01622","0.04354"
"96.48000","8.04014","0.04360"
"96.76800","8.06423","0.04368"
"97.05600","8.08815","0.04424"
"97.34400","8.11218","0.04443"
"97.63200","8.13616","0.04390"
"97.92000","8.16020","0.04446"
"98.20800","8.18417","0.04503"
"98.49600","8.20821","0.04490"
"98.78400","8.23218","0.04582"
"99.07200","8.25622","0.04560"
"99.36000","8.28025","0.04685"
"99.64800","8.30423","0.04708"
"99.93600","8.32820","0.04747"
"100.22400","8.35218","0.04831"
"100.51200","8.37627","0.04850"
"100.80000","8.40019","0.04927"
"101.08800","8.42422","0.04980"
"101.37600","8.44814","0.05026"
"101.66400","8.47218","0.05051"
"101.95200","8.49615","0.05082"
"102.24000","8.52025","0.05171"
"102.52800","8.54416","0.05231"
"102.81600","8.56820","0.05298"
"103.10400","8.59217","0.05343"
"103.39200","8.61621","0.05339"
"103.68000","8.64019","0.05428"
"103.96800","8.66416","0.05457"
"104.25600","8.68826","0.05543"
"104.54400","8.71217","0.05558"
"104.83200","8.73621","0.05585"
"105.12000","8.76012","0.05575"
"105.40800","8.78422","0.05718"
"105.69600","8.80813","0.05632"
"105.98400","8.83217","0.05654"
"106.27200","8.85614","0.05752"
"106.56000","8.88024","0.05648"
"106.84800","8.90416","0.05709"
"107.13600","8.92819","0.04548"
"107.42400","8.95217","0.00392"
"107.71200","8.97620","0.00875"
"108.00000","9.00012","0.00847"
"108.28800","9.02415","0.00902"
"108.57600","9.04819","0.00843"
"108.86400","9.07216","0.00981"
"109.15200","9.09620","0.00859"
"109.44000","9.12018","0.00972"
"109.72800","9.14415","0.00873"
"110.01600","9.16813","0.00903"
"110.30400","9.19222","0.00941"
"110.59200","9.21620","0.01031"
"110.88000","9.24017","0.00961"
"111.16800","9.26415","0.00973"
"111.45600","9.28813","0.01059"
"111.74400","9.31216","0.01076"
"112.03200","9.33619","0.01109"
"112.32000","9.36017","0.01138"
"112.60800","9.38415","0.01147"
"112.89600","9.40824","0.01148"
"113.18400","9.43216","0.01206"
"113.47200","9.45619","0.01231"
"113.76000","9.48011","0.01293"
"114.04800","9.50420","0.01217"
"114.33600","9.52812","0.01249"
"114.62400","9.55222","0.01202"
"114.91200","9.57613","0.01287"
"115.20000","9.60017","0.01225"
"115.48800","9.62414","0.01265"
"115.77600","9.64818","0.01278"
"116.06400","9.67215","0.01311"
"116.35200","9.69619","0.01405"
"116.64000","9.72016","0.01233"
"116.92800","9.74420","0.01361"
"117.21600","9.76818","0.01363"
"117.50400","9.79215","0.01394"
"117.79200","9.81619","0.01441"
"118.08000","9.84010","0.01368"
"118.36800","9.86420","0.01404"
"118.65600","9.88811","0.01422"
"118.94400","9.91221","0.01404"
"119.23200","9.93612","0.01413"
"119.52000","9.96022","0.01394"
"119.80800","9.98413","0.01381"
"120.09600","10.00817","0.01373"
"120.38400","10.03215","0.01383"
"120.67200","10.05618","0.01417"
"120.96000","10.08022","0.01380"
"121.24800","10.10413","0.01444"
"121.53600","10.12823","0.01476"
"121.82400","10.15214","0.01439"
"122.11200","10.17618","0.01460"
"122.40000","10.20009","0.01424"
"122.68800","10.22419","0.01462"
"122.97600","10.24811","0.01480"
"123.26400","10.27220","0.01527"
"123.55200","10.29612","0.01492"
"123.84000","10.32015","0.01542"
"124.12800","10.34419","0.01519"
"124.41600","10.36816","0.01473"
"124.70400","10.39220","0.01503"
"124.99200","10.41617","0.01477"
"125.28000","10.44021","0.01440"
"125.56800","10.46413","0.01438"
"125.85600","10.48816","0.01499"
"126.14400","10.51214","0.01520"
"126.43200","10.53617","0.01520"
"126.72000","10.56015","0.01504"
"127.00800","10.58418","0.01574"
"127.29600","10.60816","0.01581"
"127.58400","10.63219","0.01565"
"127.87200","10.65617","0.01494"
"128.16000","10.68020","0.01532"
"128.44800","10.70424","0.01491"
"128.73599","10.72816","0.01494"
"129.02400","10.75225","0.01531"
"129.31200","10.77617","0.01542"
"129.60001","10.80020","0.01537"
"129.88800","10.82412","0.01529"
"130.17599","10.84821","0.01538"
"130.46400","10.87213","0.01516"
"130.75200","10.89622","0.01558"
"131.03999","10.92014","0.01545"
"131.32800","10.94423","0.01586"
"131.61600","10.96821","0.01559"
"131.90401","10.99225","0.01575"
"132.19200","11.01616","0.01581"
"132.48000","11.04020","0.01527"
"132.76801","11.06423","0.01591"
"133.05600","11.08815","0.01557"
"133.34399","11.11224","0.01617"
"133.63200","11.13616","0.01611"
"133.92000","11.16019","0.01605"
"134.20799","11.18417","0.01603"
"134.49600","11.20827","0.01646"
"134.78400","11.23218","0.01616"
"135.07201","11.25622","0.01659"
"135.36000","11.28019","0.01559"
"135.64799","11.30423","0.01587"
"135.93600","11.32820","0.01639"
"136.22400","11.35218","0.01627"
"136.51199","11.37621","0.01627"
"136.80000","11.40019","0.01672"
"137.08800","11.42423","0.01633"
"137.37601","11.44814","0.01682"
"137.66400","11.47218","0.01712"
"137.95200","11.49609","0.01694"
"138.24001","11.52025","0.01695"
"138.52800","11.54416","0.01698"
"138.81599","11.56820","0.01701"
"139.10400","11.59217","0.01717"
"139.39200","11.61621","0.01716"
"139.67999","11.64019","0.01725"
"139.96800","11.66422","0.01768"
"140.25600","11.68820","0.01757"
"140.54401","11.71223","0.01759"
"140.83200","11.73621","0.01773"
"141.12000","11.76018","0.01756"
"141.40800","11.78416","0.01705"
"141.69600","11.80814","0.01788"
"141.98399","11.83223","0.01752"
"142.27200","11.85614","0.01771"
"142.56000","11.88018","0.01775"
"142.84801","11.90416","0.01765"
"143.13600","11.92819","0.01796"
"143.42400","11.95217","0.01808"
"143.71201","11.97614","0.01771"
"144.00000","12.00018","0.01808"
"144.28799","12.02415","0.01818"
"144.57600","12.04819","0.01817"
"144.86400","12.07216","0.01817"
"145.15199","12.09620","0.01880"
"145.44000","12.12018","0.01883"
"145.72800","12.14421","0.01894"
"146.01601","12.16813","0.01885"
"146.30400","12.19216","0.01884"
"146.59200","12.21614","0.01918"
"146.88000","12.24023","0.01859"
"147.16800","12.26415","0.01886"
"147.45599","12.28824","0.01922"
"147.74400","12.31216","0.01896"
"148.03200","12.33619","0.01904"
"148.32001","12.36017","0.01942"
"148.60800","12.38421","0.01952"
"148.89600","12.40818","0.01951"
"149.18401","12.43216","0.01976"
"149.47200","12.45619","0.01955"
"149.75999","12.48017","0.01998"
"150.04800","12.50414","0.01988"
"150.33600","12.52812","0.01964"
"150.62399","12.55216","0.02000"
"150.91200","12.57613","0.01933"
"151.20000","12.60017","0.02058"
"151.48801","12.62414","0.01965"
"151.77600","12.64818","0.01930"
"152.06400","12.67215","0.01928"
"152.35201","12.69613","0.02012"
"152.64000","12.72016","0.01977"
"152.92799","12.74414","0.01993"
"153.21600","12.76817","0.01964"
"153.50400","12.79215","0.02000"
"153.79201","12.81619","0.01972"
"154.08000","12.84016","0.01942"
"154.36800","12.86420","0.01955"
"154.65601","12.88811","0.01992"
"154.94400","12.91221","0.01969"
"155.23199","12.93612","0.02033"
"155.52000","12.96022","0.02039"
"155.80800","12.98414","0.02014"
"156.09599","13.00817","0.02014"
"156.38400","13.03215","0.02036"
"156.67200","13.05612","0.02044"
"156.96001","13.08016","0.01962"
"157.24800","13.10413","0.02000"
"157.53600","13.12817","0.02013"
"157.82401","13.15214","0.01987"
"158.11200","13.17618","0.01987"
"158.39999","13.20015","0.01986"
"158.68800","13.22419","0.02042"
"158.97600","13.24811","0.02059"
"159.26401","13.27214","0.02038"
"159.55200","13.29611","0.02074"
"159.84000","13.32015","0.02117"
"160.12801","13.34413","0.02035"
"160.41600","13.36816","0.02055"
"160.70399","13.39214","0.02104"
"160.99200","13.41611","0.02108"
"161.28000","13.44015","0.02052"
"161.56799","13.46412","0.02098"
"161.85600","13.48816","0.02160"
"162.14400","13.51214","0.02113"
"162.43201","13.53617","0.02123"
"162.72000","13.56015","0.02121"
"163.00800","13.58418","0.02192"
"163.29601","13.60810","0.02157"
"163.58400","13.63219","0.02068"
"163.87199","13.65611","0.02163"
"164.16000","13.68015","0.02143"
"164.44800","13.70418","0.02089"
"164.73599","13.72816","0.02151"
"165.02400","13.75213","0.02111"
"165.31200","13.77611","0.02180"
"165.60001","13.80014","0.02165"
"165.88800","13.82418","0.02172"
"166.17599","13.84815","0.02206"
"166.46400","13.87219","0.02217"
"166.75200","13.89616","0.02172"
"167.03999","13.92008","0.02213"
"167.32800","13.94417","0.02261"
"167.61600","13.96809","0.02241"
"167.90401","13.99219","0.02253"
"168.19200","14.01616","0.02271"
"168.48000","14.04020","0.02319"
"168.76801","14.06417","0.02285"
"169.05600","14.08821","0.02103"
"169.34399","14.11218","0.02215"
"169.63200","14.13616","0.02253"
"169.92000","14.16020","0.02211"
"170.20799","14.18417","0.02262"
"170.49600","14.20821","0.02288"
"170.78400","14.23212","0.02329"
"171.07201","14.25622","0.02328"
"171.36000","14.28013","0.02321"
"171.64799","14.30417","0.02346"
"171.93600","14.32814","0.02399"
"172.22400","14.35224","0.02362"
"172.51199","14.37615","0.02367"
"172.80000","14.40019","0.02353"
"173.08800","14.42422","0.02384"
"173.37601","14.44820","0.02353"
"173.66400","14.47218","0.02379"
"173.95200","14.49615","0.02411"
"174.24001","14.52019","0.02384"
"174.52800","14.54416","0.02383"
"174.81599","14.56826","0.02375"
"175.10400","14.59217","0.02409"
"175.39200","14.61621","0.02394"
"175.67999","14.64013","0.02431"
"175.96800","14.66422","0.02437"
"176.25600","14.68820","0.02466"
"176.54401","14.71217","0.02446"
"176.83200","14.73621","0.02478"
"177.12000","14.76024","0.02506"
"177.40800","14.78422","0.02480"
"177.69600","14.80819","0.02490"
"177.98399","14.83223","0.02543"
"178.27200","14.85620","0.02560"
"178.56000","14.88024","0.02550"
"178.84801","14.90416","0.02609"
"179.13600","14.92819","0.02582"
"179.42400","14.95211","0.02567"
"179.71201","14.97620","0.02555"
"180.00000","15.00018","0.02577"
"180.28799","15.02421","0.02558"
"180.57600","15.04819","0.02559"
"180.86400","15.07222","0.02641"
"181.15199","15.09620","0.02620"
"181.44000","15.12018","0.02625"
"181.72800","15.14421","0.02628"
"182.01601","15.16819","0.02609"
"182.30400","15.19222","0.02634"
"182.59200","15.21614","0.02609"
"182.88000","15.24017","0.02595"
"183.16800","15.26415","0.02567"
"183.45599","15.28824","0.02594"
"183.74400","15.31216","0.02560"
"184.03200","15.33620","0.02656"
"184.32001","15.36017","0.02623"
"184.60800","15.38421","0.02710"
"184.89600","15.40818","0.02691"
"185.18401","15.43222","0.02748"
"185.47200","15.45619","0.02799"
"185.75999","15.48023","0.02789"
"186.04800","15.50420","0.02799"
"186.33600","15.52818","0.02628"
"186.62399","15.55222","0.02646"
"186.91200","15.57613","0.02718"
"187.20000","15.60017","0.02699"
"187.48801","15.62414","0.02745"
"187.77600","15.64824","0.02801"
"188.06400","15.67215","0.02734"
"188.35201","15.69625","0.02776"
"188.64000","15.72016","0.02821"
"188.92799","15.74420","0.02804"
"189.21600","15.76817","0.02875"
"189.50400","15.79221","0.02917"
"189.79201","15.81618","0.02980"
"190.08000","15.84016","0.02908"
"190.36800","15.86419","0.02882"
"190.65601","15.88817","0.02944"
"190.94400","15.91221","0.02953"
"191.23199","15.93612","0.02960"
"191.52000","15.96016","0.02905"
"191.80800","15.98413","0.00581"
"192.09599","16.00823","0.00993"
"192.38400","16.03214","0.00405"
"192.67200","16.05624","0.00715"
"192.96001","16.08016","0.00787"
"193.24800","16.10419","0.00703"
"193.53600","16.12817","0.00909"
"193.82401","16.15220","0.00703"
"194.11200","16.17618","0.00886"
"194.39999","16.20015","0.00783"
"194.68800","16.22419","0.00956"
"194.97600","16.24822","0.00834"
"195.26401","16.27220","0.01016"
"195.55200","16.29611","0.00981"
"195.84000","16.32015","0.00965"
"196.12801","16.34413","0.00980"
"196.41600","16.36822","0.01045"
"196.70399","16.39214","0.01056"
"196.99200","16.41617","0.01066"
"197.28000","16.44015","0.01075"
"197.56799","16.46412","0.01030"
"197.85600","16.48816","0.01143"
"198.14400","16.51220","0.01094"
"198.43201","16.53623","0.01139"
"198.72000","16.56015","0.01132"
"199.00800","16.58418","0.01234"
"199.29601","16.60816","0.01166"
"199.58400","16.63219","0.01205"
"199.87199","16.65617","0.01277"
"200.16000","16.68020","0.01272"
"200.44800","16.70412","0.01267"
"200.73599","16.72821","0.01309"
"201.02400","16.75213","0.01333"
"201.31200","16.77617","0.01373"
"201.60001","16.80020","0.01363"
"201.88800","16.82418","0.01310"
"202.17599","16.84821","0.01356"
"202.46400","16.87219","0.01451"
"202.75200","16.89616","0.01371"
"203.03999","16.92014","0.01466"
"203.32800","16.94417","0.01461"
"203.61600","16.96809","0.01439"
"203.90401","16.99219","0.01465"
"204.19200","17.01610","0.01472"
"204.48000","17.04014","0.01530"
"204.76801","17.06411","0.01559"
"205.05600","17.08821","0.01521"
"205.34399","17.11218","0.01515"
"205.63200","17.13616","0.01585"
"205.92000","17.16019","0.01581"
"206.20799","17.18417","0.01634"
"206.49600","17.20821","0.01636"
"206.78400","17.23212","0.01611"
"207.07201","17.25622","0.01606"
"207.36000","17.28019","0.01610"
"207.64799","17.30417","0.01524"
"207.93600","17.32814","0.01621"
"208.22400","17.35224","0.01675"
"208.51199","17.37609","0.01661"
"208.80000","17.40025","0.01695"
"209.08800","17.42416","0.01694"
"209.37601","17.44820","0.01755"
"209.66400","17.47218","0.01745"
"209.95200","17.49621","0.01741"
"210.24001","17.52019","0.01711"
"210.52800","17.54416","0.01757"
"210.81599","17.56820","0.01776"
"211.10400","17.59217","0.01779"
"211.39200","17.61621","0.01807"
"211.67999","17.64013","0.01809"
"211.96800","17.66416","0.01828"
"212.25600","17.68814","0.01862"
"212.54401","17.71223","0.01826"
"212.83200","17.73615","0.01897"
"213.12000","17.76018","0.01899"
"213.40800","17.78416","0.01890"
"213.69600","17.80819","0.01943"
"213.98399","17.83217","0.01980"
"214.27200","17.85620","0.01964"
"214.56000","17.88024","0.01996"
"214.84801","17.90416","0.02026"
"215.13600","17.92819","0.01969"
"215.42400","17.95217","0.02038"
"215.71201","17.97620","0.02086"
"216.00000","18.00018","0.02078"
"216.28799","18.02421","0.02094"
"216.57600","18.04819","0.02103"
"216.86400","18.07222","0.02111"
"217.15199","18.09620","0.02122"
"217.44000","18.12024","0.02134"
"217.72800","18.14415","0.02121"
"218.01601","18.16825","0.02136"
"218.30400","18.19222","0.02148"
"218.59200","18.21620","0.02054"
"218.88000","18.24017","0.02100"
"219.16800","18.26415","0.02101"
"219.45599","18.28818","0.02120"
"219.74400","18.31216","0.02131"
"220.03200","18.33625","0.02178"
"220.32001","18.36017","0.02196"
"220.60800","18.38420","0.02166"
"220.89600","18.40818","0.02216"
"221.18401","18.43222","0.02208"
"221.47200","18.45613","0.02227"
"221.75999","18.48017","0.02222"
"222.04800","18.50420","0.02245"
"222.33600","18.52824","0.02270"
"222.62399","18.55221","0.02265"
"222.91200","18.57619","0.02303"
"223.20000","18.60023","0.02226"
"223.48801","18.62414","0.02300"
"223.77600","18.64824","0.02322"
"224.06400","18.67215","0.02335"
"224.35201","18.69625","0.02329"
"224.64000","18.72010","0.02268"
"224.92799","18.74420","0.02331"
"225.21600","18.76818","0.02364"
"225.50400","18.79221","0.02373"
"225.79201","18.81612","0.02357"
"226.08000","18.84022","0.02348"
"226.36800","18.86419","0.02334"
"226.65601","18.88817","0.02368"
"226.94400","18.91221","0.02328"
"227.23199","18.93618","0.02359"
"227.52000","18.96022","0.02328"
"227.80800","18.98413","0.02376"
"228.09599","19.00817","0.02383"
"228.38400","19.03214","0.02376"
"228.67200","19.05618","0.02435"
"228.96001","19.08015","0.02201"
"229.24800","19.10419","0.02194"
"229.53600","19.12811","0.02229"
"229.82401","19.15214","0.02227"
"230.11200","19.17612","0.02233"
"230.39999","19.20015","0.02250"
"230.68800","19.22419","0.02224"
"230.97600","19.24816","0.02235"
"231.26401","19.27220","0.02212"
"231.55200","19.29612","0.02114"
"231.84000","19.32021","0.02211"
"232.12801","19.34413","0.02254"
"232.41600","19.36816","0.02193"
"232.70399","19.39208","0.02274"
"232.99200","19.41623","0.02290"
"233.28000","19.44009","0.02256"
"233.56799","19.46418","0.02269"
"233.85600","19.48822","0.02309"
"234.14400","19.51220","0.02299"
"234.43201","19.53617","0.02262"
"234.72000","19.56021","0.02293"
"235.00800","19.58424","0.02272"
"235.29601","19.60816","0.02279"
"235.58400","19.63219","0.02344"
"235.87199","19.65617","0.02354"
"236.16000","19.68014","0.02314"
"236.44800","19.70406","0.02356"
"236.73599","19.72815","0.02348"
"237.02400","19.75213","0.02426"
"237.31200","19.77617","0.02395"
"237.60001","19.80008","0.02361"
"237.88800","19.82418","0.02308"
"238.17599","19.84821","0.02255"
"238.46400","19.87219","0.02261"
"238.75200","19.89616","0.02312"
"239.03999","19.92014","0.02292"
"239.32800","19.94417","0.02295"
"239.61600","19.96815","0.02246"
"239.90401","19.99218","0.02278"
"240.19200","20.01616","0.02283"
"240.48000","20.04014","0.02303"
"240.76801","20.06411","0.02301"
"241.05600","20.08821","0.02296"
"241.34399","20.11212","0.02374"
"241.63200","20.13622","0.02338"
"241.92000","20.16014","0.02358"
"242.20799","20.18417","0.02415"
"242.49600","20.20815","0.02426"
"242.78400","20.23212","0.02409"
"243.07201","20.25616","0.02380"
"243.36000","20.28013","0.02408"
"243.64799","20.30423","0.02425"
"243.93600","20.32814","0.02409"
"244.22400","20.35217","0.02332"
"244.51199","20.37609","0.02387"
"244.80000","20.40013","0.02342"
"245.08800","20.42410","0.02422"
"245.37601","20.44820","0.02399"
"245.66400","20.47211","0.02400"
"245.95200","20.49621","0.02368"
"246.24001","20.52019","0.02414"
"246.52800","20.54416","0.02430"
"246.81599","20.56814","0.02398"
"247.10400","20.59211","0.02425"
"247.39200","20.61615","0.02393"
"247.67999","20.64012","0.02401"
"247.96800","20.66416","0.02454"
"248.25600","20.68814","0.02477"
"248.54401","20.71217","0.02463"
"248.83200","20.73615","0.02531"
"249.12000","20.76018","0.02519"
"249.40800","20.78410","0.02478"
"249.69600","20.80819","0.02426"
"249.98399","20.83211","0.02463"
"250.27200","20.85614","0.02481"
"250.56000","20.88018","0.02552"
"250.84801","20.90421","0.02507"
"251.13600","20.92819","0.02564"
"251.42400","20.95211","0.02613"
"251.71201","20.97620","0.02575"
"252.00000","21.00018","0.02577"
"252.28799","21.02421","0.02581"
"252.57600","21.04819","0.02529"
"252.86400","21.07222","0.02523"
"253.15199","21.09614","0.02539"
"253.44000","21.12017","0.02564"
"253.72800","21.14415","0.02600"
"254.01601","21.16825","0.02530"
"254.30400","21.19216","0.02501"
"254.59200","21.21620","0.02414"
"254.88000","21.24017","0.02458"
"255.16800","21.26414","0.02403"
"255.45599","21.28818","0.02443"
"255.74400","21.31216","0.02468"
"256.03201","21.33625","0.02481"
"256.32001","21.36017","0.02473"
"256.60800","21.38420","0.02460"
"256.89600","21.40818","0.02501"
"257.18399","21.43222","0.02530"
"257.47198","21.45613","0.02501"
"257.76001","21.48017","0.02532"
"258.04800","21.50420","0.02557"
"258.33600","21.52824","0.02568"
"258.62399","21.55221","0.02603"
"258.91199","21.57619","0.02622"
"259.20001","21.60016","0.02621"
"259.48801","21.62420","0.02598"
"259.77600","21.64824","0.02567"
"260.06400","21.67221","0.02584"
"260.35199","21.69619","0.02615"
"260.64001","21.72016","0.02685"
"260.92801","21.74426","0.02702"
"261.21600","21.76817","0.02693"
"261.50400","21.79221","0.02697"
"261.79199","21.81618","0.02690"
"262.07999","21.84022","0.02722"
"262.36801","21.86414","0.02719"
"262.65601","21.88817","0.02731"
"262.94400","21.91215","0.02732"
"263.23199","21.93618","0.02757"
"263.51999","21.96022","0.02822"
"263.80801","21.98419","0.02763"
"264.09601","22.00823","0.02794"
"264.38400","22.03214","0.02823"
"264.67200","22.05624","0.02866"
"264.95999","22.08015","0.02908"
"265.24799","22.10425","0.02896"
"265.53601","22.12817","0.02880"
"265.82401","22.15214","0.02844"
"266.11200","22.17618","0.02900"
"266.39999","22.20021","0.02853"
"266.68799","22.22413","0.02894"
"266.97601","22.24822","0.02916"
"267.26401","22.27220","0.02890"
"267.55200","22.29618","0.02939"
"267.84000","22.32021","0.02952"
"268.12799","22.34413","0.02998"
"268.41599","22.36822","0.02969"
"268.70401","22.39208","0.02943"
"268.99200","22.41617","0.03001"
"269.28000","22.44009","0.02999"
"269.56799","22.46418","0.03002"
"269.85599","22.48816","0.02494"
"270.14401","22.51219","0.02435"
"270.43201","22.53617","0.02473"
"270.72000","22.56021","0.02504"
"271.00800","22.58418","0.02520"
"271.29599","22.60822","0.02566"
"271.58401","22.63219","0.02649"
"271.87201","22.65617","0.02636"
"272.16000","22.68020","0.02670"
"272.44800","22.70412","0.02724"
"272.73599","22.72821","0.02747"
"273.02399","22.75213","0.02743"
"273.31201","22.77617","0.02808"
"273.60001","22.80014","0.02824"
"273.88800","22.82417","0.02860"
"274.17599","22.84815","0.02832"
"274.46399","22.87225","0.02876"
"274.75201","22.89616","0.02917"
"275.04001","22.92014","0.02863"
"275.32800","22.94417","0.02952"
"275.61600","22.96815","0.03005"
"275.90399","22.99218","0.02963"
"276.19199","23.01616","0.02998"
"276.48001","23.04020","0.02950"
"276.76801","23.06417","0.02914"
"277.05600","23.08815","0.02915"
"277.34399","23.11212","0.02993"
"277.63199","23.13616","0.03003"
"277.92001","23.16013","0.03044"
"278.20801","23.18423","0.02954"
"278.49600","23.20820","0.03038"
"278.78400","23.23224","0.03039"
"279.07199","23.25616","0.02977"
"279.35999","23.28019","0.02994"
"279.64801","23.30423","0.02987"
"279.93600","23.32820","0.03024"
"280.22400","23.35218","0.02874"
"280.51199","23.37615","0.02906"
"280.79999","23.40019","0.02921"
"281.08801","23.42416","0.02942"
"281.37601","23.44814","0.02897"
"281.66400","23.47211","0.02835"
"281.95200","23.49621","0.02880"
"282.23999","23.52012","0.02850"
"282.52802","23.54422","0.02897"
"282.81601","23.56814","0.02927"
"283.10400","23.59217","0.02960"
"283.39200","23.61621","0.02991"
"283.67999","23.64012","0.02930"
"283.96799","23.66422","0.02933"
"284.25601","23.68813","0.02913"
"284.54401","23.71217","0.02893"
"284.83200","23.73615","0.02854"
"285.12000","23.76018","0.02887"
"285.40799","23.78410","0.02937"
"285.69601","23.80819","0.02925"
"285.98401","23.83211","0.02961"
"286.27200","23.85620","0.03000"
"286.56000","23.88012","0.02949"
"286.84799","23.90421","0.03045"
"287.13599","23.92813","0.03068"
"287.42401","23.95222","0.03016"
"287.71201","23.97620","0.03041"
"288.00000","24.00018","0.03055"
"288.28799","24.02421","0.03016"
"288.57599","24.04819","0.02997"
"288.86401","24.07222","0.02961"
"289.15201","24.09620","0.03081"
"289.44000","24.12023","0.03049"
"289.72800","24.14415","0.03116"
"290.01599","24.16818","0.03107"
"290.30399","24.19210","0.03092"
"290.59201","24.21620","0.03131"
"290.88000","24.24017","0.03223"
"291.16800","24.26421","0.03204"
"291.45599","24.28818","0.03152"
"291.74399","24.31216","0.03172"
"292.03201","24.33619","0.03171"
"292.32001","24.36017","0.03234"
"292.60800","24.38420","0.03139"
"292.89600","24.40818","0.03185"
"293.18399","24.43221","0.03203"
"293.47198","24.45613","0.03214"
"293.76001","24.48022","0.03227"
"294.04800","24.50414","0.03241"
"294.33600","24.52824","0.03243"
"294.62399","24.55215","0.03260"
"294.91199","24.57619","0.03315"
"295.20001","24.60016","0.03266"
"295.48801","24.62420","0.03317"
"295.77600","24.64818","0.03388"
"296.06400","24.67221","0.03378"
"296.35199","24.69619","0.03383"
"296.64001","24.72016","0.03316"
"296.92801","24.74426","0.03359"
"297.21600","24.76817","0.03411"
"297.50400","24.79227","0.03395"
"297.79199","24.81612","0.03385"
"298.07999","24.84022","0.03426"
"298.36801","24.86419","0.03312"
"298.65601","24.88823","0.03311"
"298.94400","24.91221","0.03371"
"299.23199","24.93618","0.03259"
"299.51999","24.96022","0.03322"
"299.80801","24.98419","0.03272"
"300.09601","25.00823","0.03309"
"300.38400","25.03220","0.03373"
"300.67200","25.05624","0.03354"
"300.95999","25.08015","0.03440"
"301.24799","25.10425","0.03422"
"301.53601","25.12817","0.03414"
"301.82401","25.15226","0.03440"
"302.11200","25.17612","0.03475"
"302.39999","25.20021","0.03413"
"302.68799","25.22413","0.03483"
"302.97601","25.24817","0.03478"
"303.26401","25.27214","0.03502"
"303.55200","25.29623","0.03502"
"303.84000","25.32021","0.03435"
"304.12799","25.34418","0.03224"
"304.41599","25.36816","0.03296"
"304.70401","25.39219","0.03306"
"304.99200","25.41623","0.03379"
"305.28000","25.44015","0.03350"
"305.56799","25.46424","0.03303"
"305.85599","25.48816","0.03380"
"306.14401","25.51219","0.03345"
"306.43201","25.53617","0.03316"
"306.72000","25.56020","0.03324"
"307.00800","25.58418","0.03399"
"307.29599","25.60816","0.03375"
"307.58401","25.63213","0.03404"
"307.87201","25.65617","0.03454"
"308.16000","25.68014","0.03429"
"308.44800","25.70418","0.03513"
"308.73599","25.72821","0.03485"
"309.02399","25.75219","0.03507"
"309.31201","25.77622","0.03545"
"309.60001","25.80008","0.03590"
"309.88800","25.82423","0.03530"
"310.17599","25.84809","0.03560"
"310.46399","25.87219","0.03513"
"310.75201","25.89610","0.03544"
"311.04001","25.92020","0.03590"
"311.32800","25.94417","0.03625"
"311.61600","25.96821","0.03656"
"311.90399","25.99219","0.03727"
"312.19199","26.01622","0.03667"
"312.48001","26.04020","0.03578"
"312.76801","26.06417","0.03144"
"313.05600","26.08821","0.03175"
"313.34399","26.11218","0.03260"
"313.63199","26.13616","0.03306"
"313.92001","26.16013","0.03345"
"314.20801","26.18423","0.03409"
"314.49600","26.20814","0.03444"
"314.78400","26.23218","0.03273"
"315.07199","26.25615","0.03218"
"315.35999","26.28019","0.03033"
"315.64801","26.30416","0.02927"
"315.93600","26.32820","0.02860"
"316.22400","26.35218","0.02958"
"316.51199","26.37615","0.03038"
"316.79999","26.40013","0.03048"
"317.08801","26.42410","0.03145"
"317.37601","26.44814","0.03182"
"317.66400","26.47212","0.03198"
"317.95200","26.49615","0.03167"
"318.23999","26.52013","0.03266"
"318.52802","26.54416","0.03222"
"318.81601","26.56814","0.03270"
"319.10400","26.59217","0.03269"
"319.39200","26.61615","0.03285"
"319.67999","26.64024","0.03369"
"319.96799","26.66422","0.03386"
"320.25601","26.68814","0.03431"
"320.54401","26.71217","0.03488"
"320.83200","26.73615","0.03516"
"321.12000","26.76018","0.03485"
"321.40799","26.78416","0.03530"
"321.69601","26.80819","0.03591"
"321.98401","26.83211","0.03580"
"322.27200","26.85614","0.03587"
"322.56000","26.88012","0.03653"
"322.84799","26.90415","0.03722"
"323.13599","26.92813","0.03717"
"323.42401","26.95217","0.03816"
"323.71201","26.97614","0.03850"
"324.00000","27.00018","0.03855"
"324.28799","27.02421","0.03912"
"324.57599","27.04813","0.03908"
"324.86401","27.07216","0.03939"
"325.15201","27.09614","0.03960"
"325.44000","27.12017","0.04013"
"325.72800","27.14409","0.04099"
"326.01599","27.16819","0.04106"
"326.30399","27.19216","0.04144"
"326.59201","27.21614","0.04183"
"326.88000","27.24011","0.04240"
"327.16800","27.26421","0.04314"
"327.45599","27.28812","0.04274"
"327.74399","27.31222","0.04086"
"328.03201","27.33613","0.03908"
"328.32001","27.36017","0.03804"
"328.60800","27.38414","0.03886"
"328.89600","27.40812","0.03880"
"329.18399","27.43216","0.03930"
"329.47198","27.45613","0.03985"
"329.76001","27.48017","0.04041"
"330.04800","27.50414","0.04097"
"330.33600","27.52818","0.04071"
"330.62399","27.55209","0.04099"
"330.91199","27.57619","0.04122"
"331.20001","27.60011","0.04131"
"331.48801","27.62420","0.04212"
"331.77600","27.64817","0.04212"
"332.06400","27.67215","0.04072"
"332.35199","27.69618","0.04079"
"332.64001","27.72022","0.04098"
"332.92801","27.74420","0.04050"
"333.21600","27.76818","0.04001"
"333.50400","27.79221","0.04072"
"333.79199","27.81612","0.04091"
"334.07999","27.84022","0.04098"
"334.36801","27.86414","0.03690"
"334.65601","27.88817","0.03625"
"334.94400","27.91215","0.03600"
"335.23199","27.93618","0.03728"
"335.51999","27.96016","0.03784"
"335.80801","27.98425","0.03635"
"336.09601","28.00817","0.03728"
"336.38400","28.03220","0.03791"
"336.67200","28.05618","0.03873"
"336.95999","28.08021","0.03979"
"337.24799","28.10419","0.03977"
"337.53601","28.12817","0.03983"
"337.82401","28.15226","0.03920"
"338.11200","28.17618","0.03977"
"338.39999","28.20021","0.04019"
"338.68799","28.22413","0.03955"
"338.97601","28.24822","0.04018"
"339.26401","28.27214","0.04020"
"339.55200","28.29617","0.04037"
"339.84000","28.32015","0.03996"
"340.12799","28.34424","0.04004"
"340.41599","28.36816","0.03975"
"340.70401","28.39220","0.04020"
"340.99200","28.41617","0.04016"
"341.28000","28.44021","0.04110"
"341.56799","28.46424","0.04098"
"341.85599","28.48816","0.04192"
"342.14401","28.51225","0.04266"
"342.43201","28.53617","0.04228"
"342.72000","28.56021","0.04276"
"343.00800","28.58412","0.04078"
"343.29599","28.60822","0.04155"
"343.58401","28.63219","0.04233"
"343.87201","28.65617","0.04242"
"344.16000","28.68014","0.04395"
"344.44800","28.70424","0.04432"
"344.73599","28.72821","0.04480"
"345.02399","28.75225","0.04498"
"345.31201","28.77622","0.04549"
"345.60001","28.80020","0.04578"
"345.88800","28.82424","0.04656"
"346.17599","28.84815","0.04691"
"346.46399","28.87219","0.04788"
"346.75201","28.89610","0.04764"
"347.04001","28.92020","0.04748"
"347.32800","28.94417","0.04606"
"347.61600","28.96821","0.04566"
"347.90399","28.99213","0.04495"
"348.19199","29.01622","0.04490"
"348.48001","29.04014","0.04480"
"348.76801","29.06423","0.04380"
"349.05600","29.08821","0.04006"
"349.34399","29.11218","0.04063"
"349.63199","29.13622","0.04196"
"349.92001","29.16019","0.04275"
"350.20801","29.18423","0.04292"
"350.49600","29.20815","0.03939"
"350.78400","29.23218","0.03550"
"351.07199","29.25616","0.03475"
"351.35999","29.28019","0.03506"
"351.64801","29.30417","0.03562"
"351.93600","29.32820","0.03660"
"352.22400","29.35212","0.03673"
"352.51199","29.37621","0.03758"
"352.79999","29.40019","0.03800"
"353.08801","29.42422","0.03868"
"353.37601","29.44820","0.03971"
"353.66400","29.47218","0.03984"
"353.95200","29.49621","0.03985"
"354.23999","29.52013","0.04115"
"354.52802","29.54416","0.04180"
"354.81601","29.56814","0.04128"
"355.10400","29.59217","0.04184"
"355.39200","29.61609","0.04188"
"355.67999","29.64018","0.04161"
"355.96799","29.66416","0.04139"
"356.25601","29.68825","0.04067"
"356.54401","29.71211","0.04021"
"356.83200","29.73621","0.04004"
"357.12000","29.76018","0.04062"
"357.40799","29.78416","0.04057"
"357.69601","29.80819","0.04075"
"357.98401","29.83217","0.04190"
"358.27200","29.85620","0.04284"
"358.56000","29.88012","0.04294"
"358.84799","29.90415","0.04355"
"359.13599","29.92813","0.04341"
"359.42401","29.95217","0.04410"
"359.71201","29.97614","0.04471"
"360.00000","30.00024","0.04527"
"360.28799","30.02421","0.04552"
"360.57599","30.04819","0.04590"
"360.86401","30.07216","0.04653"
"361.15201","30.09614","0.04631"
"361.44000","30.12017","0.04687"
"361.72800","30.14415","0.04655"
"362.01599","30.16818","0.04705"
"362.30399","30.19216","0.04852"
"362.59201","30.21619","0.04872"
"362.88000","30.24017","0.04031"
"363.16800","30.26415","0.04090"
"363.45599","30.28812","0.03574"
"363.74399","30.31222","0.03662"
"364.03201","30.33613","0.03810"
"364.32001","30.36017","0.03762"
"364.60800","30.38415","0.03786"
"364.89600","30.40818","0.03782"
"365.18399","30.43216","0.03819"
"365.47198","30.45613","0.03950"
"365.76001","30.48023","0.04035"
"366.04800","30.50414","0.04140"
"366.33600","30.52818","0.04200"
"366.62399","30.55209","0.04263"
"366.91199","30.57619","0.04071"
"367.20001","30.60017","0.04054"
"367.48801","30.62420","0.04025"
"367.77600","30.64811","0.04073"
"368.06400","30.67221","0.04191"
"368.35199","30.69613","0.04209"
"368.64001","30.72022","0.04286"
"368.92801","30.74420","0.04232"
"369.21600","30.76818","0.03767"
"369.50400","30.79221","0.02721"
"369.79199","30.81612","0.02822"
"370.07999","30.84016","0.02957"
"370.36801","30.86413","0.02919"
"370.65601","30.88817","0.02987"
"370.94400","30.91215","0.03196"
"371.23199","30.93618","0.03172"
"371.51999","30.96010","0.02589"
"371.80801","30.98419","0.02543"
"372.09601","31.00811","0.02620"
"372.38400","31.03220","0.02686"
"372.67200","31.05618","0.02652"
"372.95999","31.08022","0.02696"
"373.24799","31.10419","0.02643"
"373.53601","31.12816","0.02673"
"373.82401","31.15220","0.02657"
"374.11200","31.17618","0.02696"
"374.39999","31.20021","0.02729"
"374.68799","31.22419","0.02841"
"374.97601","31.24822","0.02786"
"375.26401","31.27220","0.02692"
"375.55200","31.29623","0.02721"
"375.84000","31.32015","0.02774"
"376.12799","31.34418","0.02735"
"376.41599","31.36816","0.02763"
"376.70401","31.39219","0.02810"
"376.99200","31.41611","0.02868"
"377.28000","31.44021","0.02742"
"377.56799","31.46424","0.02749"
"377.85599","31.48822","0.02796"
"378.14401","31.51225","0.02809"
"378.43201","31.53617","0.02788"
"378.72000","31.56026","0.02758"
"379.00800","31.58412","0.02834"
"379.29599","31.60821","0.02873"
"379.58401","31.63213","0.02902"
"379.87201","31.65623","0.02909"
"380.16000","31.68014","0.02929"
"380.44800","31.70418","0.02874"
"380.73599","31.72815","0.02907"
"381.02399","31.75225","0.02879"
"381.31201","31.77616","0.02959"
"381.60001","31.80026","0.02968"
"381.88800","31.82417","0.02813"
"382.17599","31.84821","0.02763"
"382.46399","31.87225","0.02757"
"382.75201","31.89622","0.02705"
"383.04001","31.92025","0.02738"
"383.32800","31.94423","0.02754"
"383.61600","31.96821","0.02783"
"383.90399","31.99218","0.02782"
"384.19199","32.01622","0.02830"
"384.48001","32.04013","0.02838"
"384.76801","32.06417","0.02831"
"385.05600","32.08820","0.02946"
"385.34399","32.11218","0.02955"
"385.63199","32.13622","0.02915"
"385.92001","32.16019","0.02889"
"386.20801","32.18423","0.02953"
"386.49600","32.20820","0.02939"
"386.78400","32.23223","0.02791"
"387.07199","32.25615","0.02850"
"387.35999","32.28019","0.02977"
"387.64801","32.30410","0.02931"
"387.93600","32.32820","0.02952"
"388.22400","32.35212","0.02947"
"388.51199","32.37621","0.02973"
"388.79999","32.40019","0.03013"
"389.08801","32.42416","0.03035"
"389.37601","32.44814","0.03014"
"389.66400","32.47223","0.03052"
"389.95200","32.49621","0.03056"
"390.23999","32.52018","0.03049"
"390.52802","32.54416","0.03009"
"390.81601","32.56813","0.03010"
"391.10400","32.59217","0.03094"
"391.39200","32.61615","0.03000"
"391.67999","32.64018","0.03060"
"391.96799","32.66410","0.03081"
"392.25601","32.68819","0.03099"
"392.54401","32.71217","0.03133"
"392.83200","32.73621","0.03184"
"393.12000","32.76018","0.03172"
"393.40799","32.78416","0.03158"
"393.69601","32.80813","0.03188"
"393.98401","32.83216","0.03135"
"394.27200","32.85620","0.03121"
"394.56000","32.88018","0.03132"
"394.84799","32.90421","0.03194"
"395.13599","32.92813","0.03166"
"395.42401","32.95216","0.03157"
"395.71201","32.97614","0.03156"
"396.00000","33.00018","0.03139"
"396.28799","33.02415","0.03234"
"396.57599","33.04819","0.03094"
"396.86401","33.07210","0.03110"
"397.15201","33.09620","0.03145"
"397.44000","33.12011","0.03082"
"397.72800","33.14415","0.03147"
"398.01599","33.16818","0.03148"
"398.30399","33.19222","0.03178"
"398.59201","33.21619","0.03228"
"398.88000","33.24017","0.03172"
"399.16800","33.26421","0.03243"
"399.45599","33.28818","0.03299"
"399.74399","33.31216","0.03265"
"400.03201","33.33607","0.03329"
"400.32001","33.36017","0.03327"
"400.60800","33.38414","0.03327"
"400.89600","33.40818","0.03270"
"401.18399","33.43216","0.03266"
"401.47198","33.45619","0.03270"
"401.76001","33.48016","0.03288"
"402.04800","33.50414","0.03308"
"402.33600","33.52818","0.03214"
"402.62399","33.55209","0.03281"
"402.91199","33.57619","0.03204"
"403.20001","33.60010","0.03209"
"403.48801","33.62420","0.03188"
"403.77600","33.64817","0.03144"
"404.06400","33.67221","0.03048"
"404.35199","33.69613","0.03100"
"404.64001","33.72016","0.03097"
"404.92801","33.74413","0.03102"
"405.21600","33.76823","0.03037"
"405.50400","33.79214","0.03064"
"405.79199","33.81618","0.03033"
"406.07999","33.84016","0.03056"
"406.36801","33.86413","0.03074"
"406.65601","33.88817","0.03098"
"406.94400","33.91214","0.03168"
"407.23199","33.93618","0.03104"
"407.51999","33.96016","0.03168"
"407.80801","33.98419","0.03084"
"408.09601","34.00811","0.03057"
"408.38400","34.03214","0.03097"
"408.67200","34.05611","0.03112"
"408.95999","34.08021","0.03135"
"409.24799","34.10413","0.03144"
"409.53601","34.12816","0.03066"
"409.82401","34.15214","0.03070"
"410.11200","34.17617","0.03140"
"410.39999","34.20015","0.03098"
"410.68799","34.22412","0.03070"
"410.97601","34.24816","0.03102"
"411.26401","34.27214","0.03149"
"411.55200","34.29617","0.03153"
"411.84000","34.32015","0.03067"
"412.12799","34.34418","0.03078"
"412.41599","34.36810","0.03151"
"412.70401","34.39219","0.03091"
"412.99200","34.41611","0.03117"
"413.28000","34.44020","0.03161"
"413.56799","34.46412","0.03177"
"413.85599","34.48822","0.03142"
"414.14401","34.51219","0.03132"
"414.43201","34.53617","0.03041"
"414.72000","34.56020","0.02958"
"415.00800","34.58418","0.02937"
"415.29599","34.60815","0.02976"
"415.58401","34.63213","0.03035"
"415.87201","34.65623","0.02886"
"416.16000","34.68014","0.02833"
"416.44800","34.70417","0.02896"
"416.73599","34.72815","0.02950"
"417.02399","34.75225","0.02962"
"417.31201","34.77616","0.03010"
"417.60001","34.80020","0.03049"
"417.88800","34.82417","0.03084"
"418.17599","34.84821","0.03131"
"418.46399","34.87218","0.03033"
"418.75201","34.89622","0.03032"
"419.04001","34.92020","0.03084"
"419.32800","34.94417","0.03102"
"419.61600","34.96821","0.03143"
"419.90399","34.99218","0.03193"
"420.19199","35.01616","0.03188"
"420.48001","35.04007","0.03182"
"420.76801","35.06423","0.03076"
"421.05600","35.08814","0.03131"
"421.34399","35.11224","0.03095"
"421.63199","35.13615","0.03133"
"421.92001","35.16025","0.03184"
"422.20801","35.18423","0.03204"
"422.49600","35.20826","0.03181"
"422.78400","35.23224","0.03180"
"423.07199","35.25621","0.02577"
"423.35999","35.28025","0.02591"
"423.64801","35.30416","0.02553"
"423.93600","35.32820","0.02513"
"424.22400","35.35212","0.02517"
"424.30600","35.35899","0.02542"