File: Force_trajectories/170108_0/Specimen_RawData_2.csv
End date,"1/8/2017"
Specimen label,"20CG_61"
Maximum Load,"0.02239",N

Time,Extension,Load
(s),(mm),(N)
"0.00000","0.00000","-0.00013"
"0.28200","0.02266","-0.00052"
"0.56400","0.04729","-0.00029"
"0.84600","0.07073","0.00021"
"1.12800","0.09429","0.00025"
"1.41000","0.11773","-0.00070"
"1.69200","0.14122","-0.00018"
"1.97400","0.16472","-0.00007"
"2.25600","0.18828","0.00006"
"2.53800","0.21177","0.00071"
"2.82000","0.23527","0.00002"
"3.10200","0.25877","-0.00046"
"3.38400","0.28221","-0.00056"
"3.66600","0.30576","-0.00015"
"3.94800","0.32926","-0.00008"
"4.23000","0.35276","0.00015"
"4.51200","0.37620","-0.00032"
"4.79400","0.39975","0.00012"
"5.07600","0.42313","0.00007"
"5.35800","0.44675","-0.00010"
"5.64000","0.47013","-0.00015"
"5.92200","0.49374","0.00015"
"6.20400","0.51718","-0.00016"
"6.48600","0.54074","0.00006"
"6.76800","0.56417","-0.00017"
"7.05000","0.58773","-0.00010"
"7.33200","0.61117","0.00034"
"7.61400","0.63473","0.00020"
"7.89600","0.65822","0.00032"
"8.17800","0.68172","-0.00002"
"8.46000","0.70522","-0.00024"
"8.74200","0.72871","0.00007"
"9.02400","0.75221","-0.00015"
"9.30600","0.77571","0.00003"
"9.58800","0.79927","-0.00012"
"9.87000","0.82270","-0.00027"
"10.15200","0.84620","0.00003"
"10.43400","0.86976","-0.00039"
"10.71600","0.89326","0.00007"
"10.99800","0.91669","-0.00028"
"11.28000","0.94025","0.00033"
"11.56200","0.96375","-0.00005"
"11.84400","0.98724","0.00002"
"12.12600","1.01074","0.00060"
"12.40800","1.03424","-0.00016"
"12.69000","1.05774","-0.00001"
"12.97200","1.08123","0.00009"
"13.25400","1.10473","0.00015"
"13.53600","1.12823","0.00062"
"13.81800","1.15173","0.00132"
"14.10000","1.17522","0.00130"
"14.38200","1.19872","0.00081"
"14.66400","1.22216","0.00145"
"14.94600","1.24571","0.00127"
"15.22800","1.26915","0.00071"
"15.51000","1.29265","0.00076"
"15.79200","1.31609","0.00051"
"16.07400","1.33970","0.00100"
"16.35600","1.36320","0.00065"
"16.63800","1.38670","0.00049"
"16.92000","1.41020","0.00076"
"17.20200","1.43369","0.00024"
"17.48400","1.45719","0.00051"
"17.76600","1.48075","0.00025"
"18.04800","1.50419","0.00024"
"18.33000","1.52774","0.00012"
"18.61200","1.55124","0.00041"
"18.89400","1.57474","0.00048"
"19.17600","1.59823","0.00023"
"19.45800","1.62179","0.00048"
"19.74000","1.64523","-0.00045"
"20.02200","1.66879","-0.00021"
"20.30400","1.69228","0.00033"
"20.58600","1.71572","0.00050"
"20.86800","1.73922","0.00003"
"21.15000","1.76271","-0.00003"
"21.43200","1.78627","0.00063"
"21.71400","1.80971","0.00084"
"21.99600","1.83327","0.00025"
"22.27800","1.85670","0.00061"
"22.56000","1.88026","0.00077"
"22.84200","1.90364","0.00010"
"23.12400","1.92726","0.00065"
"23.40600","1.95063","0.00073"
"23.68800","1.97425","0.00054"
"23.97000","1.99769","0.00028"
"24.25200","2.02125","0.00046"
"24.53400","2.04468","0.00021"
"24.81600","2.06824","0.00048"
"25.09800","2.09168","0.00038"
"25.38000","2.11523","0.00084"
"25.66200","2.13867","-0.00009"
"25.94400","2.16223","0.00078"
"26.22600","2.18573","0.00151"
"26.50800","2.20922","0.00122"
"26.79000","2.23284","0.00088"
"27.07200","2.25622","0.00127"
"27.35400","2.27977","0.00062"
"27.63600","2.30321","0.00073"
"27.91800","2.32683","0.00119"
"28.20000","2.35021","0.00048"
"28.48200","2.37370","-0.00018"
"28.76400","2.39714","0.00069"
"29.04600","2.42076","0.00029"
"29.32800","2.44420","0.00021"
"29.61000","2.46775","0.00063"
"29.89200","2.49119","0.00035"
"30.17400","2.51469","0.00061"
"30.45600","2.53819","0.00038"
"30.73800","2.56174","-0.00023"
"31.02000","2.58524","0.00018"
"31.30200","2.60868","-0.00035"
"31.58400","2.63217","0.00027"
"31.86600","2.65573","0.00044"
"32.14800","2.67929","0.00039"
"32.43000","2.70273","-0.00049"
"32.71200","2.72622","0.00034"
"32.99400","2.74972","0.00032"
"33.27600","2.77322","-0.00017"
"33.55800","2.79666","-0.00017"
"33.84000","2.82027","0.00037"
"34.12200","2.84371","0.00094"
"34.40400","2.86721","0.00054"
"34.68600","2.89070","0.00081"
"34.96800","2.91426","0.00035"
"35.25000","2.93770","0.00033"
"35.53200","2.96126","0.00043"
"35.81400","2.98469","0.00049"
"36.09600","3.00825","0.00094"
"36.37800","3.03175","0.00022"
"36.66000","3.05525","0.00028"
"36.94200","3.07874","0.00070"
"37.22400","3.10224","0.00048"
"37.50600","3.12574","-0.00002"
"37.78800","3.14917","0.00076"
"38.07000","3.17273","0.00101"
"38.35200","3.19617","0.00049"
"38.63400","3.21979","0.00004"
"38.91600","3.24316","0.00038"
"39.19800","3.26672","0.00008"
"39.48000","3.29022","0.00004"
"39.76200","3.31372","0.00011"
"40.04400","3.33715","0.00070"
"40.32600","3.36071","0.00085"
"40.60800","3.38421","0.00048"
"40.89000","3.40776","0.00022"
"41.17200","3.43114","0.00077"
"41.45400","3.45476","0.00043"
"41.73600","3.47820","0.00065"
"42.01800","3.50175","0.00086"
"42.30000","3.52519","0.00094"
"42.58200","3.54875","0.00038"
"42.86400","3.57219","0.00018"
"43.14600","3.59574","0.00068"
"43.42800","3.61924","0.00086"
"43.71000","3.64274","0.00075"
"43.99200","3.66629","0.00075"
"44.27400","3.68973","0.00103"
"44.55600","3.71323","0.00057"
"44.83800","3.73667","0.00114"
"45.12000","3.76022","0.00047"
"45.40200","3.78366","0.00072"
"45.68400","3.80722","0.00063"
"45.96600","3.83066","0.00017"
"46.24800","3.85421","0.00050"
"46.53000","3.87765","0.00089"
"46.81200","3.90127","0.00033"
"47.09400","3.92464","0.00080"
"47.37600","3.94820","0.00066"
"47.65800","3.97164","0.00092"
"47.94000","3.99526","0.00050"
"48.22200","4.01869","0.00096"
"48.50400","4.04225","0.00089"
"48.78600","4.06569","0.00094"
"49.06800","4.08925","0.00048"
"49.35000","4.11274","0.00013"
"49.63200","4.13624","0.00110"
"49.91400","4.15974","0.00089"
"50.19600","4.18323","0.00037"
"50.47800","4.20673","0.00046"
"50.76000","4.23017","0.00020"
"51.04200","4.25379","0.00050"
"51.32400","4.27722","0.00057"
"51.60600","4.30078","0.00064"
"51.88800","4.32422","0.00052"
"52.17000","4.34777","0.00104"
"52.45200","4.37121","0.00055"
"52.73400","4.39471","0.00103"
"53.01600","4.41815","0.00066"
"53.29800","4.44176","0.00069"
"53.58000","4.46520","0.00053"
"53.86200","4.48876","0.00026"
"54.14400","4.51220","0.00077"
"54.42600","4.53575","0.00088"
"54.70800","4.55925","0.00089"
"54.99000","4.58269","0.00053"
"55.27200","4.60625","0.00086"
"55.55400","4.62968","0.00058"
"55.83600","4.65324","0.00056"
"56.11800","4.67674","0.00028"
"56.40000","4.70029","0.00100"
"56.68200","4.72373","0.00056"
"56.96400","4.74723","0.00078"
"57.24600","4.77061","0.00075"
"57.52800","4.79422","0.00041"
"57.81000","4.81772","0.00056"
"58.09200","4.84122","0.00083"
"58.37400","4.86466","0.00081"
"58.65600","4.88821","0.00103"
"58.93800","4.91171","0.00072"
"59.22000","4.93527","0.00120"
"59.50200","4.95870","0.00104"
"59.78400","4.98226","0.00050"
"60.06600","5.00570","0.00152"
"60.34800","5.02926","0.00050"
"60.63000","5.05275","0.00105"
"60.91200","5.07625","0.00100"
"61.19400","5.09975","0.00091"
"61.47600","5.12319","0.00073"
"61.75800","5.14674","0.00055"
"62.04000","5.17018","0.00065"
"62.32200","5.19374","0.00012"
"62.60400","5.21718","0.00069"
"62.88600","5.24073","0.00077"
"63.16800","5.26423","0.00097"
"63.45000","5.28773","0.00095"
"63.73200","5.31116","0.00092"
"64.01400","5.33472","0.00120"
"64.29600","5.35816","0.00115"
"64.57800","5.38172","0.00122"
"64.86000","5.40509","0.00045"
"65.14200","5.42871","0.00184"
"65.42400","5.45215","0.00111"
"65.70600","5.47570","0.00115"
"65.98800","5.49914","0.00088"
"66.27000","5.52270","0.00126"
"66.55200","5.54626","0.00072"
"66.83400","5.56975","0.00098"
"67.11600","5.59319","0.00124"
"67.39800","5.61675","0.00119"
"67.68000","5.64025","0.00131"
"67.96200","5.66368","0.00057"
"68.24400","5.68730","0.00073"
"68.52600","5.71074","0.00081"
"68.80800","5.73423","0.00146"
"69.09000","5.75773","0.00097"
"69.37200","5.78129","0.00128"
"69.65400","5.80473","0.00093"
"69.93600","5.82822","0.00135"
"70.21800","5.85166","0.00140"
"70.50000","5.87528","0.00039"
"70.78200","5.89872","0.00070"
"71.06400","5.92227","0.00060"
"71.34600","5.94571","0.00133"
"71.62800","5.96921","0.00064"
"71.91000","5.99265","0.00082"
"72.19200","6.01620","0.00149"
"72.47400","6.03970","0.00089"
"72.75600","6.06320","0.00087"
"73.03800","6.08675","0.00123"
"73.32000","6.11025","0.00152"
"73.60200","6.13375","0.00132"
"73.88400","6.15719","0.00128"
"74.16600","6.18074","0.00102"
"74.44800","6.20412","0.00079"
"74.73000","6.22774","0.00129"
"75.01200","6.25117","0.00061"
"75.29400","6.27473","0.00113"
"75.57600","6.29823","0.00114"
"75.85800","6.32179","0.00110"
"76.14000","6.34522","0.00071"
"76.42200","6.36878","0.00135"
"76.70400","6.39222","0.00114"
"76.98600","6.41578","0.00133"
"77.26800","6.43921","0.00126"
"77.55000","6.46271","0.00109"
"77.83200","6.48621","0.00092"
"78.11400","6.50971","0.00101"
"78.39600","6.53320","0.00155"
"78.67800","6.55670","0.00098"
"78.96000","6.58020","0.00135"
"79.24200","6.60369","0.00141"
"79.52400","6.62719","0.00142"
"79.80600","6.65063","0.00137"
"80.08800","6.67419","0.00068"
"80.37000","6.69768","0.00101"
"80.65200","6.72118","0.00149"
"80.93400","6.74468","0.00153"
"81.21600","6.76824","0.00132"
"81.49800","6.79167","0.00090"
"81.78000","6.81529","0.00101"
"82.06200","6.83867","0.00128"
"82.34400","6.86222","0.00096"
"82.62600","6.88572","0.00162"
"82.90800","6.90922","0.00128"
"83.19000","6.93272","0.00133"
"83.47200","6.95627","0.00101"
"83.75400","6.97971","0.00159"
"84.03600","7.00327","0.00109"
"84.31800","7.02671","0.00158"
"84.60000","7.05020","0.00161"
"84.88200","7.07370","0.00085"
"85.16400","7.09720","0.00135"
"85.44600","7.12075","0.00128"
"85.72800","7.14419","0.00179"
"86.01000","7.16775","0.00195"
"86.29200","7.19119","0.00140"
"86.57400","7.21474","0.00130"
"86.85600","7.23818","0.00204"
"87.13800","7.26168","0.00146"
"87.42000","7.28512","0.00174"
"87.70200","7.30873","0.00182"
"87.98400","7.33217","0.00165"
"88.26600","7.35573","0.00166"
"88.54800","7.37916","0.00182"
"88.83000","7.40278","0.00160"
"89.11200","7.42622","0.00160"
"89.39400","7.44972","0.00146"
"89.67600","7.47321","0.00204"
"89.95800","7.49677","0.00166"
"90.24000","7.52021","0.00133"
"90.52200","7.54371","0.00209"
"90.80400","7.56726","0.00078"
"91.08600","7.59076","0.00167"
"91.36800","7.61426","0.00135"
"91.65000","7.63769","0.00158"
"91.93200","7.66125","0.00166"
"92.21400","7.68469","0.00098"
"92.49600","7.70831","0.00107"
"92.77800","7.73168","0.00166"
"93.06000","7.75530","0.00158"
"93.34200","7.77874","0.00100"
"93.62400","7.80224","0.00197"
"93.90600","7.82567","0.00082"
"94.18800","7.84923","0.00142"
"94.47000","7.87273","0.00195"
"94.75200","7.89622","0.00154"
"95.03400","7.91972","0.00169"
"95.31600","7.94322","0.00105"
"95.59800","7.96666","0.00124"
"95.88000","7.99015","0.00132"
"96.16200","8.01371","0.00113"
"96.44400","8.03721","0.00131"
"96.72600","8.06071","0.00182"
"97.00800","8.08420","0.00180"
"97.29000","8.10776","0.00139"
"97.57200","8.13126","0.00158"
"97.85400","8.15475","0.00143"
"98.13600","8.17819","0.00134"
"98.41800","8.20169","0.00085"
"98.70000","8.22519","0.00141"
"98.98200","8.24874","0.00148"
"99.26400","8.27218","0.00094"
"99.54600","8.29574","0.00117"
"99.82800","8.31924","0.00175"
"100.11000","8.34273","0.00086"
"100.39200","8.36623","0.00136"
"100.67400","8.38979","0.00155"
"100.95600","8.41322","0.00120"
"101.23800","8.43678","0.00083"
"101.52000","8.46022","0.00069"
"101.80200","8.48372","0.00154"
"102.08400","8.50721","0.00081"
"102.36600","8.53071","0.00032"
"102.64800","8.55427","0.00082"
"102.93000","8.57771","0.00076"
"103.21200","8.60120","0.00080"
"103.49400","8.62470","0.00043"
"103.77600","8.64820","0.00113"
"104.05800","8.67169","0.00090"
"104.34000","8.69519","0.00089"
"104.62200","8.71863","0.00110"
"104.90400","8.74219","0.00070"
"105.18600","8.76568","0.00149"
"105.46800","8.78924","0.00085"
"105.75000","8.81268","0.00067"
"106.03200","8.83630","0.00107"
"106.31400","8.85973","0.00096"
"106.59600","8.88317","0.00140"
"106.87800","8.90673","0.00098"
"107.16000","8.93028","0.00124"
"107.44200","8.95372","0.00122"
"107.72400","8.97728","0.00054"
"108.00600","9.00078","0.00099"
"108.28800","9.02427","0.00124"
"108.57000","9.04777","0.00145"
"108.85200","9.07121","0.00117"
"109.13400","9.09477","0.00136"
"109.41600","9.11820","0.00149"
"109.69800","9.14170","0.00140"
"109.98000","9.16514","0.00103"
"110.26200","9.18869","0.00109"
"110.54400","9.21213","0.00179"
"110.82600","9.23569","0.00133"
"111.10800","9.25913","0.00126"
"111.39000","9.28274","0.00097"
"111.67200","9.30612","0.00137"
"111.95400","9.32974","0.00116"
"112.23600","9.35318","0.00099"
"112.51800","9.37673","0.00088"
"112.80000","9.40023","0.00077"
"113.08200","9.42367","0.00168"
"113.36400","9.44722","0.00173"
"113.64600","9.47066","0.00110"
"113.92800","9.49422","0.00125"
"114.21000","9.51772","0.00155"
"114.49200","9.54127","0.00147"
"114.77400","9.56471","0.00086"
"115.05600","9.58827","0.00087"
"115.33800","9.61171","0.00099"
"115.62000","9.63532","0.00121"
"115.90200","9.65870","0.00062"
"116.18400","9.68226","0.00167"
"116.46600","9.70569","0.00167"
"116.74800","9.72931","0.00112"
"117.03000","9.75275","0.00117"
"117.31200","9.77625","0.00129"
"117.59400","9.79974","0.00126"
"117.87600","9.82324","0.00065"
"118.15800","9.84668","0.00060"
"118.44000","9.87024","0.00154"
"118.72200","9.89373","0.00061"
"119.00400","9.91723","0.00116"
"119.28600","9.94067","0.00146"
"119.56800","9.96417","0.00120"
"119.85000","9.98772","0.00110"
"120.13200","10.01122","0.00145"
"120.41400","10.03478","0.00139"
"120.69600","10.05821","0.00130"
"120.97800","10.08171","0.00127"
"121.26000","10.10521","0.00103"
"121.54200","10.12877","0.00108"
"121.82400","10.15220","0.00159"
"122.10600","10.17576","0.00172"
"122.38800","10.19920","0.00135"
"122.67000","10.22269","0.00096"
"122.95200","10.24619","0.00090"
"123.23400","10.26975","0.00125"
"123.51600","10.29319","0.00140"
"123.79800","10.31668","0.00209"
"124.08000","10.34018","0.00166"
"124.36200","10.36380","0.00100"
"124.64400","10.38724","0.00092"
"124.92600","10.41073","0.00171"
"125.20800","10.43423","0.00130"
"125.49000","10.45773","0.00168"
"125.77200","10.48123","0.00142"
"126.05400","10.50472","0.00203"
"126.33600","10.52822","0.00145"
"126.61800","10.55172","0.00150"
"126.90000","10.57527","0.00112"
"127.18200","10.59871","0.00104"
"127.46400","10.62221","0.00200"
"127.74600","10.64571","0.00161"
"128.02800","10.66920","0.00115"
"128.31000","10.69264","0.00171"
"128.59200","10.71620","0.00212"
"128.87399","10.73970","0.00136"
"129.15601","10.76319","0.00121"
"129.43800","10.78663","0.00139"
"129.72000","10.81025","0.00165"
"130.00200","10.83374","0.00170"
"130.28400","10.85724","0.00163"
"130.56599","10.88068","0.00159"
"130.84801","10.90418","0.00162"
"131.13000","10.92773","0.00132"
"131.41200","10.95123","0.00086"
"131.69400","10.97479","0.00131"
"131.97600","10.99823","0.00142"
"132.25800","11.02178","0.00149"
"132.53999","11.04522","0.00182"
"132.82201","11.06878","0.00138"
"133.10400","11.09221","0.00135"
"133.38600","11.11577","0.00085"
"133.66800","11.13921","0.00134"
"133.95000","11.16277","0.00112"
"134.23199","11.18620","0.00156"
"134.51401","11.20976","0.00107"
"134.79601","11.23320","0.00163"
"135.07800","11.25675","0.00098"
"135.36000","11.28019","0.00143"
"135.64200","11.30375","0.00130"
"135.92400","11.32719","0.00232"
"136.20599","11.35074","0.00144"
"136.48801","11.37418","0.00126"
"136.77000","11.39768","0.00113"
"137.05200","11.42124","0.00136"
"137.33400","11.44473","0.00173"
"137.61600","11.46823","0.00132"
"137.89799","11.49173","0.00190"
"138.17999","11.51528","0.00168"
"138.46201","11.53866","0.00153"
"138.74400","11.56222","0.00107"
"139.02600","11.58566","0.00138"
"139.30800","11.60921","0.00141"
"139.59000","11.63271","0.00150"
"139.87199","11.65621","0.00127"
"140.15401","11.67965","0.00157"
"140.43600","11.70326","0.00172"
"140.71800","11.72670","0.00143"
"141.00000","11.75026","0.00127"
"141.28200","11.77375","0.00128"
"141.56400","11.79725","0.00136"
"141.84599","11.82069","0.00131"
"142.12801","11.84425","0.00156"
"142.41000","11.86774","0.00144"
"142.69200","11.89124","0.00154"
"142.97400","11.91468","0.00121"
"143.25600","11.93818","0.00122"
"143.53799","11.96173","0.00159"
"143.82001","11.98517","0.00130"
"144.10201","12.00873","0.00135"
"144.38400","12.03217","0.00083"
"144.66600","12.05572","0.00097"
"144.94800","12.07916","0.00147"
"145.23000","12.10266","0.00081"
"145.51199","12.12615","0.00144"
"145.79401","12.14971","0.00073"
"146.07600","12.17315","0.00109"
"146.35800","12.19671","0.00088"
"146.64000","12.22020","0.00071"
"146.92200","12.24376","0.00170"
"147.20399","12.26720","0.00118"
"147.48599","12.29076","0.00124"
"147.76801","12.31425","0.00073"
"148.05000","12.33775","0.00071"
"148.33200","12.36119","0.00106"
"148.61400","12.38474","0.00069"
"148.89600","12.40824","0.00067"
"149.17799","12.43174","0.00177"
"149.46001","12.45530","0.00126"
"149.74200","12.47873","0.00114"
"150.02400","12.50229","0.00134"
"150.30600","12.52567","0.00120"
"150.58800","12.54928","0.00097"
"150.87000","12.57272","0.00074"
"151.15199","12.59628","0.00126"
"151.43401","12.61966","0.00097"
"151.71600","12.64327","0.00080"
"151.99800","12.66665","0.00111"
"152.28000","12.69027","0.00016"
"152.56200","12.71365","0.00101"
"152.84399","12.73720","0.00118"
"153.12601","12.76064","0.00111"
"153.40800","12.78426","0.00112"
"153.69000","12.80770","0.00102"
"153.97200","12.83119","0.00051"
"154.25400","12.85469","0.00078"
"154.53600","12.87825","0.00103"
"154.81799","12.90174","0.00082"
"155.10001","12.92524","0.00142"
"155.38200","12.94874","0.00102"
"155.66400","12.97224","0.00138"
"155.94600","12.99579","0.00076"
"156.22800","13.01923","0.00054"
"156.50999","13.04279","0.00077"
"156.79201","13.06623","0.00100"
"157.07401","13.08978","0.00085"
"157.35600","13.11322","0.00088"
"157.63800","13.13672","0.00093"
"157.92000","13.16021","0.00163"
"158.20200","13.18371","0.00136"
"158.48399","13.20721","0.00097"
"158.76601","13.23077","0.00081"
"159.04800","13.25420","0.00118"
"159.33000","13.27770","0.00129"
"159.61200","13.30120","0.00076"
"159.89400","13.32476","0.00113"
"160.17599","13.34819","0.00109"
"160.45799","13.37169","0.00094"
"160.74001","13.39519","0.00090"
"161.02200","13.41868","0.00117"
"161.30400","13.44224","0.00109"
"161.58600","13.46568","0.00097"
"161.86800","13.48924","0.00110"
"162.14999","13.51273","0.00068"
"162.43201","13.53623","0.00061"
"162.71400","13.55967","0.00187"
"162.99600","13.58323","0.00135"
"163.27800","13.60666","0.00080"
"163.56000","13.63022","0.00073"
"163.84200","13.65372","0.00107"
"164.12399","13.67727","0.00085"
"164.40601","13.70071","0.00086"
"164.68800","13.72427","0.00094"
"164.97000","13.74771","0.00125"
"165.25200","13.77126","0.00069"
"165.53400","13.79476","0.00116"
"165.81599","13.81826","0.00085"
"166.09801","13.84175","0.00118"
"166.38000","13.86525","0.00120"
"166.66200","13.88875","0.00068"
"166.94400","13.91219","0.00104"
"167.22600","13.93574","0.00085"
"167.50800","13.95918","0.00114"
"167.78999","13.98274","0.00079"
"168.07201","14.00618","0.00107"
"168.35400","14.02973","0.00064"
"168.63600","14.05317","0.00108"
"168.91800","14.07673","0.00093"
"169.20000","14.10017","0.00109"
"169.48199","14.12372","0.00073"
"169.76401","14.14716","0.00082"
"170.04601","14.17072","0.00030"
"170.32800","14.19421","0.00107"
"170.61000","14.21777","0.00115"
"170.89200","14.24121","0.00107"
"171.17400","14.26477","0.00110"
"171.45599","14.28820","0.00069"
"171.73801","14.31170","0.00083"
"172.02000","14.33520","0.00072"
"172.30200","14.35870","0.00152"
"172.58400","14.38225","0.00152"
"172.86600","14.40575","0.00162"
"173.14799","14.42925","0.00124"
"173.42999","14.45274","0.00124"
"173.71201","14.47624","0.00143"
"173.99400","14.49968","0.00113"
"174.27600","14.52324","0.00118"
"174.55800","14.54673","0.00086"
"174.84000","14.57023","0.00103"
"175.12199","14.59367","0.00084"
"175.40401","14.61722","0.00115"
"175.68600","14.64066","0.00127"
"175.96800","14.66422","0.00147"
"176.25000","14.68766","0.00150"
"176.53200","14.71121","0.00132"
"176.81400","14.73471","0.00132"
"177.09599","14.75821","0.00122"
"177.37801","14.78171","0.00150"
"177.66000","14.80520","0.00077"
"177.94200","14.82870","0.00112"
"178.22400","14.85220","0.00155"
"178.50600","14.87570","0.00134"
"178.78799","14.89919","0.00130"
"179.07001","14.92275","0.00111"
"179.35201","14.94619","0.00120"
"179.63400","14.96974","0.00171"
"179.91600","14.99318","0.00154"
"180.19800","15.01674","0.00152"
"180.48000","15.04018","0.00114"
"180.76199","15.06373","0.00110"
"181.04401","15.08723","0.00162"
"181.32600","15.11079","0.00102"
"181.60800","15.13417","0.00112"
"181.89000","15.15772","0.00134"
"182.17200","15.18122","0.00170"
"182.45399","15.20478","0.00121"
"182.73599","15.22821","0.00137"
"183.01801","15.25177","0.00133"
"183.30000","15.27521","0.00144"
"183.58200","15.29877","0.00108"
"183.86400","15.32226","0.00129"
"184.14600","15.34570","0.00093"
"184.42799","15.36920","0.00132"
"184.71001","15.39270","0.00119"
"184.99200","15.41625","0.00156"
"185.27400","15.43969","0.00095"
"185.55600","15.46331","0.00157"
"185.83800","15.48668","0.00121"
"186.12000","15.51024","0.00111"
"186.40199","15.53362","0.00101"
"186.68401","15.55724","0.00121"
"186.96600","15.58067","0.00127"
"187.24800","15.60423","0.00136"
"187.53000","15.62767","0.00175"
"187.81200","15.65123","0.00099"
"188.09399","15.67472","0.00074"
"188.37601","15.69822","0.00055"
"188.65800","15.72172","0.00102"
"188.94000","15.74527","0.00149"
"189.22200","15.76871","0.00140"
"189.50400","15.79227","0.00171"
"189.78600","15.81577","0.00111"
"190.06799","15.83926","0.00117"
"190.35001","15.86276","0.00172"
"190.63200","15.88620","0.00113"
"190.91400","15.90976","0.00148"
"191.19600","15.93319","0.00144"
"191.47800","15.95675","0.00137"
"191.75999","15.98019","0.00152"
"192.04201","16.00374","0.00168"
"192.32401","16.02718","0.00195"
"192.60600","16.05074","0.00187"
"192.88800","16.07418","0.00142"
"193.17000","16.09773","0.00143"
"193.45200","16.12111","0.00139"
"193.73399","16.14473","0.00151"
"194.01601","16.16817","0.00142"
"194.29800","16.19172","0.00137"
"194.58000","16.21522","0.00135"
"194.86200","16.23872","0.00135"
"195.14400","16.26221","0.00132"
"195.42599","16.28571","0.00143"
"195.70799","16.30921","0.00098"
"195.99001","16.33271","0.00179"
"196.27200","16.35620","0.00134"
"196.55400","16.37976","0.00150"
"196.83600","16.40326","0.00196"
"197.11800","16.42669","0.00167"
"197.39999","16.45025","0.00160"
"197.68201","16.47375","0.00140"
"197.96400","16.49725","0.00130"
"198.24600","16.52074","0.00193"
"198.52800","16.54424","0.00161"
"198.81000","16.56768","0.00185"
"199.09200","16.59124","0.00214"
"199.37399","16.61467","0.00145"
"199.65601","16.63823","0.00173"
"199.93800","16.66167","0.00169"
"200.22000","16.68522","0.00209"
"200.50200","16.70872","0.00172"
"200.78400","16.73222","0.00161"
"201.06599","16.75572","0.00203"
"201.34801","16.77921","0.00206"
"201.63000","16.80271","0.00217"
"201.91200","16.82621","0.00168"
"202.19400","16.84977","0.00202"
"202.47600","16.87326","0.00167"
"202.75800","16.89676","0.00153"
"203.03999","16.92020","0.00204"
"203.32201","16.94370","0.00210"
"203.60400","16.96713","0.00185"
"203.88600","16.99069","0.00213"
"204.16800","17.01419","0.00149"
"204.45000","17.03775","0.00201"
"204.73199","17.06118","0.00176"
"205.01401","17.08480","0.00177"
"205.29601","17.10824","0.00208"
"205.57800","17.13179","0.00220"
"205.86000","17.15523","0.00146"
"206.14200","17.17873","0.00201"
"206.42400","17.20223","0.00228"
"206.70599","17.22572","0.00175"
"206.98801","17.24922","0.00178"
"207.27000","17.27272","0.00190"
"207.55200","17.29622","0.00180"
"207.83400","17.31971","0.00164"
"208.11600","17.34321","0.00184"
"208.39799","17.36665","0.00217"
"208.67999","17.39021","0.00221"
"208.96201","17.41364","0.00196"
"209.24400","17.43720","0.00251"
"209.52600","17.46064","0.00174"
"209.80800","17.48419","0.00166"
"210.09000","17.50769","0.00179"
"210.37199","17.53125","0.00190"
"210.65401","17.55463","0.00169"
"210.93600","17.57830","0.00225"
"211.21800","17.60168","0.00199"
"211.50000","17.62524","0.00206"
"211.78200","17.64867","0.00197"
"212.06400","17.67223","0.00163"
"212.34599","17.69573","0.00206"
"212.62801","17.71923","0.00198"
"212.91000","17.74272","0.00121"
"213.19200","17.76628","0.00188"
"213.47400","17.78972","0.00183"
"213.75600","17.81322","0.00167"
"214.03799","17.83671","0.00162"
"214.32001","17.86021","0.00173"
"214.60201","17.88377","0.00165"
"214.88400","17.90720","0.00198"
"215.16600","17.93076","0.00179"
"215.44800","17.95420","0.00199"
"215.73000","17.97770","0.00179"
"216.01199","18.00119","0.00177"
"216.29401","18.02469","0.00213"
"216.57600","18.04813","0.00154"
"216.85800","18.07174","0.00146"
"217.14000","18.09518","0.00227"
"217.42200","18.11874","0.00231"
"217.70399","18.14218","0.00209"
"217.98599","18.16573","0.00170"
"218.26801","18.18923","0.00214"
"218.55000","18.21267","0.00217"
"218.83200","18.23623","0.00214"
"219.11400","18.25972","0.00147"
"219.39600","18.28328","0.00144"
"219.67799","18.30672","0.00180"
"219.96001","18.33027","0.00115"
"220.24200","18.35365","0.00163"
"220.52400","18.37721","0.00188"
"220.80600","18.40071","0.00203"
"221.08800","18.42426","0.00166"
"221.37000","18.44770","0.00188"
"221.65199","18.47126","0.00161"
"221.93401","18.49470","0.00183"
"222.21600","18.51825","0.00172"
"222.49800","18.54175","0.00261"
"222.78000","18.56525","0.00216"
"223.06200","18.58869","0.00212"
"223.34399","18.61224","0.00238"
"223.62601","18.63568","0.00173"
"223.90800","18.65918","0.00206"
"224.19000","18.68274","0.00182"
"224.47200","18.70623","0.00229"
"224.75400","18.72967","0.00232"
"225.03600","18.75317","0.00182"
"225.31799","18.77672","0.00227"
"225.60001","18.80016","0.00185"
"225.88200","18.82372","0.00192"
"226.16400","18.84716","0.00227"
"226.44600","18.87071","0.00214"
"226.72800","18.89421","0.00199"
"227.00999","18.91777","0.00197"
"227.29201","18.94120","0.00232"
"227.57401","18.96470","0.00176"
"227.85600","18.98814","0.00177"
"228.13800","19.01176","0.00217"
"228.42000","19.03514","0.00225"
"228.70200","19.05875","0.00242"
"228.98399","19.08219","0.00169"
"229.26601","19.10575","0.00243"
"229.54800","19.12924","0.00231"
"229.83000","19.15280","0.00245"
"230.11200","19.17624","0.00183"
"230.39400","19.19979","0.00250"
"230.67599","19.22317","0.00159"
"230.95799","19.24667","0.00169"
"231.24001","19.27023","0.00185"
"231.52200","19.29372","0.00201"
"231.80400","19.31728","0.00221"
"232.08600","19.34072","0.00198"
"232.36800","19.36422","0.00200"
"232.64999","19.38771","0.00235"
"232.93201","19.41115","0.00254"
"233.21400","19.43465","0.00202"
"233.49600","19.45820","0.00215"
"233.77800","19.48164","0.00231"
"234.06000","19.50520","0.00280"
"234.34200","19.52870","0.00245"
"234.62399","19.55225","0.00225"
"234.90601","19.57569","0.00301"
"235.18800","19.59925","0.00174"
"235.47000","19.62275","0.00224"
"235.75200","19.64618","0.00203"
"236.03400","19.66968","0.00205"
"236.31599","19.69324","0.00270"
"236.59801","19.71673","0.00170"
"236.88000","19.74029","0.00234"
"237.16200","19.76379","0.00237"
"237.44400","19.78729","0.00225"
"237.72600","19.81079","0.00219"
"238.00800","19.83422","0.00233"
"238.28999","19.85772","0.00215"
"238.57201","19.88116","0.00223"
"238.85400","19.90471","0.00161"
"239.13600","19.92815","0.00187"
"239.41800","19.95177","0.00223"
"239.70000","19.97520","0.00245"
"239.98199","19.99870","0.00163"
"240.26401","20.02214","0.00221"
"240.54601","20.04576","0.00190"
"240.82800","20.06919","0.00216"
"241.11000","20.09275","0.00205"
"241.39200","20.11619","0.00171"
"241.67400","20.13975","0.00177"
"241.95599","20.16318","0.00236"
"242.23801","20.18668","0.00198"
"242.52000","20.21018","0.00224"
"242.80200","20.23367","0.00216"
"243.08400","20.25723","0.00232"
"243.36600","20.28067","0.00235"
"243.64799","20.30423","0.00267"
"243.92999","20.32772","0.00185"
"244.21201","20.35122","0.00229"
"244.49400","20.37466","0.00219"
"244.77600","20.39828","0.00231"
"245.05800","20.42171","0.00197"
"245.34000","20.44527","0.00222"
"245.62199","20.46865","0.00246"
"245.90401","20.49232","0.00225"
"246.18600","20.51576","0.00270"
"246.46800","20.53926","0.00208"
"246.75000","20.56270","0.00149"
"247.03200","20.58625","0.00270"
"247.31400","20.60975","0.00260"
"247.59599","20.63325","0.00190"
"247.87801","20.65675","0.00180"
"248.16000","20.68024","0.00222"
"248.44200","20.70368","0.00154"
"248.72400","20.72718","0.00220"
"249.00600","20.75073","0.00263"
"249.28799","20.77423","0.00246"
"249.57001","20.79773","0.00240"
"249.85201","20.82123","0.00276"
"250.13400","20.84472","0.00236"
"250.41600","20.86822","0.00293"
"250.69800","20.89172","0.00256"
"250.98000","20.91516","0.00254"
"251.26199","20.93871","0.00223"
"251.54401","20.96221","0.00244"
"251.82600","20.98577","0.00207"
"252.10800","21.00920","0.00240"
"252.39000","21.03276","0.00248"
"252.67200","21.05620","0.00293"
"252.95399","21.07970","0.00218"
"253.23599","21.10319","0.00226"
"253.51801","21.12681","0.00223"
"253.80000","21.15025","0.00223"
"254.08200","21.17375","0.00222"
"254.36400","21.19724","0.00244"
"254.64600","21.22074","0.00263"
"254.92799","21.24424","0.00235"
"255.21001","21.26768","0.00243"
"255.49200","21.29123","0.00260"
"255.77400","21.31473","0.00270"
"256.05600","21.33829","0.00225"
"256.33801","21.36166","0.00262"
"256.62000","21.38522","0.00304"
"256.90201","21.40866","0.00296"
"257.18399","21.43222","0.00315"
"257.46600","21.45559","0.00263"
"257.74799","21.47921","0.00234"
"258.03000","21.50265","0.00301"
"258.31201","21.52621","0.00287"
"258.59399","21.54964","0.00287"
"258.87601","21.57326","0.00303"
"259.15799","21.59676","0.00273"
"259.44000","21.62020","0.00269"
"259.72198","21.64369","0.00242"
"260.00400","21.66719","0.00320"
"260.28601","21.69075","0.00297"
"260.56799","21.71424","0.00311"
"260.85001","21.73774","0.00253"
"261.13199","21.76124","0.00322"
"261.41400","21.78479","0.00297"
"261.69601","21.80817","0.00279"
"261.97800","21.83179","0.00367"
"262.26001","21.85523","0.00238"
"262.54199","21.87878","0.00303"
"262.82401","21.90216","0.00318"
"263.10599","21.92572","0.00320"
"263.38800","21.94916","0.00370"
"263.67001","21.97277","0.00309"
"263.95200","21.99621","0.00283"
"264.23401","22.01977","0.00356"
"264.51599","22.04321","0.00309"
"264.79800","22.06676","0.00304"
"265.07999","22.09020","0.00308"
"265.36200","22.11376","0.00282"
"265.64401","22.13720","0.00366"
"265.92599","22.16069","0.00234"
"266.20801","22.18425","0.00314"
"266.48999","22.20774","0.00374"
"266.77200","22.23124","0.00287"
"267.05399","22.25474","0.00332"
"267.33600","22.27824","0.00362"
"267.61801","22.30168","0.00345"
"267.89999","22.32523","0.00408"
"268.18201","22.34867","0.00303"
"268.46399","22.37223","0.00299"
"268.74600","22.39572","0.00309"
"269.02802","22.41922","0.00318"
"269.31000","22.44266","0.00346"
"269.59201","22.46622","0.00301"
"269.87399","22.48971","0.00378"
"270.15601","22.51321","0.00299"
"270.43799","22.53671","0.00358"
"270.72000","22.56026","0.00328"
"271.00201","22.58370","0.00348"
"271.28400","22.60726","0.00307"
"271.56601","22.63076","0.00344"
"271.84799","22.65425","0.00354"
"272.13000","22.67775","0.00361"
"272.41199","22.70119","0.00375"
"272.69400","22.72475","0.00350"
"272.97601","22.74818","0.00364"
"273.25800","22.77174","0.00408"
"273.54001","22.79518","0.00351"
"273.82199","22.81867","0.00373"
"274.10400","22.84211","0.00413"
"274.38599","22.86567","0.00380"
"274.66800","22.88917","0.00359"
"274.95001","22.91273","0.00331"
"275.23199","22.93616","0.00405"
"275.51401","22.95972","0.00338"
"275.79599","22.98322","0.00351"
"276.07800","23.00677","0.00365"
"276.35999","23.03021","0.00386"
"276.64200","23.05371","0.00407"
"276.92401","23.07721","0.00306"
"277.20599","23.10070","0.00391"
"277.48801","23.12420","0.00346"
"277.76999","23.14776","0.00344"
"278.05200","23.17125","0.00366"
"278.33401","23.19475","0.00373"
"278.61600","23.21831","0.00345"
"278.89801","23.24175","0.00443"
"279.17999","23.26530","0.00398"
"279.46201","23.28874","0.00376"
"279.74399","23.31224","0.00382"
"280.02600","23.33568","0.00377"
"280.30801","23.35923","0.00415"
"280.59000","23.38267","0.00444"
"280.87201","23.40623","0.00370"
"281.15399","23.42967","0.00362"
"281.43600","23.45328","0.00396"
"281.71799","23.47666","0.00408"
"282.00000","23.50022","0.00395"
"282.28201","23.52365","0.00385"
"282.56400","23.54721","0.00413"
"282.84601","23.57071","0.00415"
"283.12799","23.59420","0.00398"
"283.41000","23.61770","0.00408"
"283.69199","23.64120","0.00408"
"283.97400","23.66476","0.00419"
"284.25601","23.68819","0.00366"
"284.53799","23.71175","0.00447"
"284.82001","23.73525","0.00486"
"285.10199","23.75875","0.00404"
"285.38400","23.78218","0.00389"
"285.66599","23.80574","0.00439"
"285.94800","23.82918","0.00423"
"286.23001","23.85279","0.00411"
"286.51199","23.87623","0.00463"
"286.79401","23.89973","0.00394"
"287.07599","23.92323","0.00426"
"287.35800","23.94672","0.00427"
"287.64001","23.97016","0.00438"
"287.92200","23.99378","0.00480"
"288.20401","24.01722","0.00430"
"288.48599","24.04071","0.00400"
"288.76801","24.06421","0.00462"
"289.04999","24.08771","0.00438"
"289.33200","24.11121","0.00481"
"289.61401","24.13470","0.00460"
"289.89600","24.15820","0.00448"
"290.17801","24.18170","0.00466"
"290.45999","24.20525","0.00466"
"290.74200","24.22869","0.00458"
"291.02399","24.25219","0.00481"
"291.30600","24.27575","0.00427"
"291.58801","24.29918","0.00481"
"291.87000","24.32268","0.00459"
"292.15201","24.34624","0.00490"
"292.43399","24.36968","0.00488"
"292.71600","24.39323","0.00511"
"292.99799","24.41667","0.00494"
"293.28000","24.44023","0.00463"
"293.56201","24.46372","0.00451"
"293.84399","24.48722","0.00447"
"294.12601","24.51072","0.00478"
"294.40799","24.53428","0.00417"
"294.69000","24.55778","0.00410"
"294.97198","24.58127","0.00418"
"295.25400","24.60471","0.00451"
"295.53601","24.62827","0.00439"
"295.81799","24.65176","0.00441"
"296.10001","24.67520","0.00475"
"296.38199","24.69882","0.00401"
"296.66400","24.72220","0.00488"
"296.94601","24.74575","0.00488"
"297.22800","24.76913","0.00464"
"297.51001","24.79275","0.00483"
"297.79199","24.81618","0.00476"
"298.07401","24.83974","0.00500"
"298.35599","24.86312","0.00465"
"298.63800","24.88674","0.00475"
"298.92001","24.91017","0.00512"
"299.20200","24.93379","0.00520"
"299.48401","24.95723","0.00508"
"299.76599","24.98078","0.00534"
"300.04800","25.00416","0.00496"
"300.32999","25.02772","0.00468"
"300.61200","25.05122","0.00497"
"300.89401","25.07477","0.00531"
"301.17599","25.09821","0.00592"
"301.45801","25.12171","0.00500"
"301.73999","25.14526","0.00553"
"302.02200","25.16876","0.00518"
"302.30399","25.19226","0.00536"
"302.58600","25.21570","0.00543"
"302.86801","25.23925","0.00554"
"303.14999","25.26269","0.00533"
"303.43201","25.28625","0.00562"
"303.71399","25.30969","0.00540"
"303.99600","25.33324","0.00495"
"304.27802","25.35668","0.00590"
"304.56000","25.38024","0.00553"
"304.84201","25.40368","0.00596"
"305.12399","25.42729","0.00549"
"305.40601","25.45067","0.00634"
"305.68799","25.47423","0.00567"
"305.97000","25.49767","0.00586"
"306.25201","25.52122","0.00568"
"306.53400","25.54472","0.00554"
"306.81601","25.56821","0.00577"
"307.09799","25.59165","0.00555"
"307.38000","25.61521","0.00588"
"307.66199","25.63871","0.00571"
"307.94400","25.66220","0.00583"
"308.22601","25.68576","0.00621"
"308.50800","25.70920","0.00649"
"308.79001","25.73270","0.00629"
"309.07199","25.75619","0.00584"
"309.35400","25.77969","0.00604"
"309.63599","25.80319","0.00600"
"309.91800","25.82675","0.00587"
"310.20001","25.85025","0.00633"
"310.48199","25.87380","0.00642"
"310.76401","25.89718","0.00594"
"311.04599","25.92074","0.00660"
"311.32800","25.94423","0.00634"
"311.60999","25.96779","0.00624"
"311.89200","25.99123","0.00567"
"312.17401","26.01478","0.00610"
"312.45599","26.03822","0.00653"
"312.73801","26.06172","0.00700"
"313.01999","26.08528","0.00597"
"313.30200","26.10866","0.00631"
"313.58401","26.13221","0.00650"
"313.86600","26.15571","0.00624"
"314.14801","26.17921","0.00649"
"314.42999","26.20271","0.00623"
"314.71201","26.22626","0.00725"
"314.99399","26.24970","0.00688"
"315.27600","26.27320","0.00647"
"315.55801","26.29663","0.00652"
"315.84000","26.32025","0.00675"
"316.12201","26.34369","0.00659"
"316.40399","26.36724","0.00637"
"316.68600","26.39068","0.00661"
"316.96799","26.41424","0.00691"
"317.25000","26.43768","0.00656"
"317.53201","26.46123","0.00686"
"317.81400","26.48467","0.00637"
"318.09601","26.50829","0.00695"
"318.37799","26.53172","0.00669"
"318.66000","26.55522","0.00764"
"318.94199","26.57872","0.00680"
"319.22400","26.60228","0.00707"
"319.50601","26.62571","0.00744"
"319.78799","26.64921","0.00714"
"320.07001","26.67271","0.00708"
"320.35199","26.69621","0.00682"
"320.63400","26.71976","0.00724"
"320.91599","26.74314","0.00754"
"321.19800","26.76670","0.00773"
"321.48001","26.79014","0.00763"
"321.76199","26.81369","0.00764"
"322.04401","26.83713","0.00763"
"322.32599","26.86069","0.00737"
"322.60800","26.88412","0.00801"
"322.89001","26.90774","0.00760"
"323.17200","26.93118","0.00762"
"323.45401","26.95474","0.00762"
"323.73599","26.97817","0.00747"
"324.01801","27.00173","0.00733"
"324.29999","27.02523","0.00826"
"324.58200","27.04873","0.00769"
"324.86401","27.07222","0.00813"
"325.14600","27.09572","0.00811"
"325.42801","27.11922","0.00770"
"325.70999","27.14272","0.00779"
"325.99200","27.16627","0.00811"
"326.27399","27.18971","0.00828"
"326.55600","27.21327","0.00742"
"326.83801","27.23670","0.00831"
"327.12000","27.26026","0.00835"
"327.40201","27.28370","0.00864"
"327.68399","27.30725","0.00809"
"327.96600","27.33069","0.00793"
"328.24799","27.35425","0.00821"
"328.53000","27.37769","0.00796"
"328.81201","27.40125","0.00846"
"329.09399","27.42474","0.00841"
"329.37601","27.44824","0.00770"
"329.65799","27.47174","0.00848"
"329.94000","27.49523","0.00900"
"330.22198","27.51873","0.00849"
"330.50400","27.54217","0.00852"
"330.78601","27.56573","0.00860"
"331.06799","27.58916","0.00856"
"331.35001","27.61278","0.00853"
"331.63199","27.63622","0.00870"
"331.91400","27.65977","0.00860"
"332.19601","27.68321","0.00877"
"332.47800","27.70671","0.00868"
"332.76001","27.73015","0.00909"
"333.04199","27.75370","0.00925"
"333.32401","27.77720","0.00870"
"333.60599","27.80070","0.00897"
"333.88800","27.82414","0.00930"
"334.17001","27.84775","0.00959"
"334.45200","27.87119","0.00881"
"334.73401","27.89475","0.00954"
"335.01599","27.91818","0.00907"
"335.29800","27.94174","0.00945"
"335.57999","27.96524","0.00975"
"335.86200","27.98874","0.00931"
"336.14401","28.01224","0.00912"
"336.42599","28.03573","0.00964"
"336.70801","28.05923","0.00978"
"336.98999","28.08273","0.00962"
"337.27200","28.10628","0.00954"
"337.55399","28.12972","0.01003"
"337.83600","28.15322","0.00965"
"338.11801","28.17665","0.00980"
"338.39999","28.20015","0.01029"
"338.68201","28.22365","0.00959"
"338.96399","28.24721","0.00998"
"339.24600","28.27064","0.00989"
"339.52802","28.29426","0.01023"
"339.81000","28.31764","0.00950"
"340.09201","28.34125","0.01054"
"340.37399","28.36469","0.01003"
"340.65601","28.38825","0.01046"
"340.93799","28.41175","0.01069"
"341.22000","28.43524","0.00962"
"341.50201","28.45868","0.01031"
"341.78400","28.48224","0.01012"
"342.06601","28.50574","0.01027"
"342.34799","28.52923","0.01097"
"342.63000","28.55273","0.01038"
"342.91199","28.57623","0.01054"
"343.19400","28.59972","0.01016"
"343.47601","28.62322","0.01048"
"343.75800","28.64678","0.01063"
"344.04001","28.67022","0.01086"
"344.32199","28.69371","0.01059"
"344.60400","28.71715","0.01031"
"344.88599","28.74071","0.01079"
"345.16800","28.76421","0.01128"
"345.45001","28.78770","0.01114"
"345.73199","28.81114","0.01015"
"346.01401","28.83476","0.01095"
"346.29599","28.85820","0.01125"
"346.57800","28.88175","0.01143"
"346.85999","28.90519","0.01139"
"347.14200","28.92875","0.01140"
"347.42401","28.95225","0.01154"
"347.70599","28.97562","0.01121"
"347.98801","28.99924","0.01127"
"348.26999","29.02274","0.01128"
"348.55200","29.04629","0.01184"
"348.83401","29.06967","0.01166"
"349.11600","29.09329","0.01147"
"349.39801","29.11673","0.01125"
"349.67999","29.14022","0.01129"
"349.96201","29.16372","0.01134"
"350.24399","29.18728","0.01139"
"350.52600","29.21066","0.01146"
"350.80801","29.23427","0.01220"
"351.09000","29.25771","0.01189"
"351.37201","29.28127","0.01207"
"351.65399","29.30470","0.01199"
"351.93600","29.32826","0.01255"
"352.21799","29.35170","0.01212"
"352.50000","29.37520","0.01218"
"352.78201","29.39869","0.01218"
"353.06400","29.42225","0.01207"
"353.34601","29.44569","0.01171"
"353.62799","29.46924","0.01213"
"353.91000","29.49268","0.01258"
"354.19199","29.51618","0.01220"
"354.47400","29.53968","0.01281"
"354.75601","29.56318","0.01296"
"355.03799","29.58673","0.01251"
"355.32001","29.61017","0.01315"
"355.60199","29.63372","0.01252"
"355.88400","29.65722","0.01272"
"356.16599","29.68078","0.01305"
"356.44800","29.70416","0.01316"
"356.73001","29.72771","0.01259"
"357.01199","29.75115","0.01256"
"357.29401","29.77471","0.01302"
"357.57599","29.79815","0.01286"
"357.85800","29.82176","0.01302"
"358.14001","29.84520","0.01323"
"358.42200","29.86876","0.01300"
"358.70401","29.89225","0.01342"
"358.98599","29.91575","0.01342"
"359.26801","29.93919","0.01328"
"359.54999","29.96275","0.01304"
"359.83200","29.98618","0.01359"
"360.11401","30.00974","0.01312"
"360.39600","30.03324","0.01373"
"360.67801","30.05667","0.01361"
"360.95999","30.08029","0.01351"
"361.24200","30.10373","0.01334"
"361.52399","30.12723","0.01358"
"361.80600","30.15067","0.01373"
"362.08801","30.17422","0.01353"
"362.37000","30.19766","0.01327"
"362.65201","30.22122","0.01388"
"362.93399","30.24465","0.01388"
"363.21600","30.26822","0.01384"
"363.49799","30.29171","0.01367"
"363.78000","30.31521","0.01401"
"364.06201","30.33871","0.01387"
"364.34399","30.36226","0.01347"
"364.62601","30.38570","0.01407"
"364.90799","30.40920","0.01427"
"365.19000","30.43270","0.01392"
"365.47198","30.45625","0.01357"
"365.75400","30.47975","0.01440"
"366.03601","30.50324","0.01447"
"366.31799","30.52680","0.01396"
"366.60001","30.55024","0.01395"
"366.88199","30.57380","0.01386"
"367.16400","30.59723","0.01414"
"367.44601","30.62073","0.01447"
"367.72800","30.64417","0.01472"
"368.01001","30.66773","0.01435"
"368.29199","30.69122","0.01457"
"368.57401","30.71478","0.01467"
"368.85599","30.73816","0.01457"
"369.13800","30.76171","0.01484"
"369.42001","30.78515","0.01473"
"369.70200","30.80871","0.01521"
"369.98401","30.83221","0.01480"
"370.26599","30.85570","0.01535"
"370.54800","30.87920","0.01462"
"370.82999","30.90270","0.01487"
"371.11200","30.92620","0.01484"
"371.39401","30.94969","0.01499"
"371.67599","30.97319","0.01519"
"371.95801","30.99669","0.01492"
"372.23999","31.02025","0.01524"
"372.52200","31.04368","0.01567"
"372.80399","31.06724","0.01562"
"373.08600","31.09068","0.01521"
"373.36801","31.11423","0.01524"
"373.64999","31.13767","0.01535"
"373.93201","31.16123","0.01603"
"374.21399","31.18467","0.01574"
"374.49600","31.20823","0.01588"
"374.77802","31.23166","0.01576"
"375.06000","31.25528","0.01620"
"375.34201","31.27872","0.01537"
"375.62399","31.30227","0.01600"
"375.90601","31.32571","0.01589"
"376.18799","31.34926","0.01619"
"376.47000","31.37270","0.01609"
"376.75201","31.39620","0.01647"
"377.03400","31.41970","0.01573"
"377.31601","31.44325","0.01612"
"377.59799","31.46669","0.01617"
"377.88000","31.49019","0.01635"
"378.16199","31.51375","0.01614"
"378.44400","31.53718","0.01669"
"378.72601","31.56074","0.01638"
"379.00800","31.58424","0.01708"
"379.29001","31.60774","0.01650"
"379.57199","31.63117","0.01665"
"379.85400","31.65467","0.01670"
"380.13599","31.67817","0.01706"
"380.41800","31.70173","0.01689"
"380.70001","31.72522","0.01667"
"380.98199","31.74878","0.01684"
"381.26401","31.77222","0.01710"
"381.54599","31.79577","0.01697"
"381.82800","31.81921","0.01715"
"382.10999","31.84271","0.01732"
"382.39200","31.86621","0.01734"
"382.67401","31.88976","0.01756"
"382.95599","31.91326","0.01793"
"383.23801","31.93676","0.01744"
"383.51999","31.96026","0.01753"
"383.80200","31.98375","0.01774"
"384.08401","32.00725","0.01814"
"384.36600","32.03069","0.01800"
"384.64801","32.05424","0.01805"
"384.92999","32.07768","0.01790"
"385.21201","32.10124","0.01836"
"385.49399","32.12474","0.01799"
"385.77600","32.14824","0.01826"
"386.05801","32.17167","0.01821"
"386.34000","32.19523","0.01863"
"386.62201","32.21861","0.01822"
"386.90399","32.24222","0.01873"
"387.18600","32.26566","0.01865"
"387.46799","32.28916","0.01840"
"387.75000","32.31265","0.01898"
"388.03201","32.33621","0.01930"
"388.31400","32.35971","0.01893"
"388.59601","32.38321","0.01916"
"388.87799","32.40670","0.01931"
"389.16000","32.43020","0.01898"
"389.44199","32.45376","0.01920"
"389.72400","32.47720","0.01959"
"390.00601","32.50075","0.01940"
"390.28799","32.52419","0.02002"
"390.57001","32.54774","0.01989"
"390.85199","32.57119","0.01944"
"391.13400","32.59474","0.02021"
"391.41599","32.61818","0.01963"
"391.69800","32.64174","0.02031"
"391.98001","32.66517","0.02007"
"392.26199","32.68873","0.01993"
"392.54401","32.71217","0.02047"
"392.82599","32.73578","0.02032"
"393.10800","32.75922","0.02085"
"393.39001","32.78278","0.02054"
"393.67200","32.80622","0.02099"
"393.95401","32.82971","0.02072"
"394.23599","32.85321","0.02089"
"394.51801","32.87671","0.02083"
"394.79999","32.90021","0.02104"
"395.08200","32.92370","0.02095"
"395.36401","32.94726","0.02097"
"395.64600","32.97070","0.02099"
"395.92801","32.99426","0.02110"
"396.20999","33.01775","0.02143"
"396.49200","33.04125","0.02154"
"396.77399","33.06469","0.02133"
"397.05600","33.08825","0.02121"
"397.33801","33.11168","0.02188"
"397.62000","33.13524","0.02175"
"397.90201","33.15868","0.02186"
"398.18399","33.18223","0.02195"
"398.46600","33.20567","0.02219"
"398.74799","33.22917","0.02134"
"399.03000","33.25267","0.00845"
"399.31201","33.27622","0.00530"
"399.59399","33.29972","0.00194"
"399.87601","33.32328","0.00033"
"400.15799","33.34672","0.00469"
"400.44000","33.37027","0.00207"
"400.72198","33.39377","0.00036"
"401.00400","33.41727","0.00442"
"401.28601","33.44070","0.00135"
"401.56799","33.46420","0.00090"
"401.85001","33.48770","0.00420"
"402.13199","33.51120","0.00116"
"402.41400","33.53476","0.00169"
"402.69601","33.55819","0.00214"
"402.97800","33.58175","0.00153"
"403.26001","33.60513","0.00220"
"403.54199","33.62868","0.00187"
"403.82401","33.65212","0.00197"
"404.10599","33.67574","0.00277"
"404.38800","33.69917","0.00114"
"404.67001","33.72273","0.00293"
"404.95200","33.74617","0.00190"
"405.23401","33.76979","0.00164"
"405.51599","33.79322","0.00211"
"405.79800","33.81672","0.00230"
"406.07999","33.84022","0.00333"
"406.36200","33.86372","0.00187"
"406.64401","33.88721","0.00245"
"406.92599","33.91071","0.00250"
"407.20801","33.93427","0.00207"
"407.48999","33.95771","0.00253"
"407.77200","33.98132","0.00271"
"408.05399","34.00470","0.00257"
"408.33600","34.02826","0.00258"
"408.61801","34.05169","0.00297"
"408.89999","34.07525","0.00239"
"409.18201","34.09869","0.00268"
"409.46399","34.12224","0.00252"
"409.74600","34.14568","0.00240"
"410.02802","34.16924","0.00308"
"410.31000","34.19268","0.00276"
"410.59201","34.21623","0.00314"
"410.87399","34.23973","0.00287"
"411.15601","34.26323","0.00314"
"411.43799","34.28667","0.00277"
"411.72000","34.31022","0.00300"
"412.00201","34.33366","0.00347"
"412.28400","34.35722","0.00321"
"412.56601","34.38071","0.00322"
"412.84799","34.40421","0.00334"
"413.13000","34.42771","0.00359"
"413.41199","34.45121","0.00336"
"413.69400","34.47477","0.00342"
"413.97601","34.49820","0.00322"
"414.25800","34.52170","0.00308"
"414.54001","34.54519","0.00296"
"414.82199","34.56870","0.00323"
"415.10400","34.59219","0.00330"
"415.38599","34.61575","0.00347"
"415.66800","34.63918","0.00359"
"415.95001","34.66274","0.00375"
"416.23199","34.68618","0.00332"
"416.51401","34.70974","0.00364"
"416.79599","34.73318","0.00357"
"417.07800","34.75673","0.00416"
"417.35999","34.78023","0.00345"
"417.64200","34.80373","0.00413"
"417.71799","34.81000","0.00392"