File: Force_trajectories/170225_1/Specimen_RawData_4.csv
End date,"2/25/2017"
Specimen label,"2AT_15"
Maximum Load,"0.04883",N

Time,Extension,Load
(s),(mm),(N)
"0.00000","0.00000","-0.00027"
"0.13200","0.00670","0.00078"
"0.26400","0.02087","0.00016"
"0.39600","0.03318","0.00041"
"0.52800","0.04424","0.00032"
"0.66000","0.05519","0.00019"
"0.79200","0.06619","0.00066"
"0.92400","0.07725","0.00098"
"1.05600","0.08819","0.00077"
"1.18800","0.09919","0.00101"
"1.32000","0.11019","0.00105"
"1.45200","0.12119","0.00139"
"1.58400","0.13213","0.00146"
"1.71600","0.14314","0.00122"
"1.84800","0.15414","0.00094"
"1.98000","0.16526","0.00162"
"2.11200","0.17620","0.00150"
"2.24400","0.18720","0.00126"
"2.37600","0.19820","0.00153"
"2.50800","0.20926","0.00145"
"2.64000","0.22020","0.00187"
"2.77200","0.23115","0.00170"
"2.90400","0.24215","0.00100"
"3.03600","0.25321","0.00196"
"3.16800","0.26421","0.00131"
"3.30000","0.27521","0.00194"
"3.43200","0.28615","0.00205"
"3.56400","0.29721","0.00163"
"3.69600","0.30822","0.00136"
"3.82800","0.31916","0.00158"
"3.96000","0.33022","0.00154"
"4.09200","0.34122","0.00158"
"4.22400","0.35222","0.00199"
"4.35600","0.36316","0.00201"
"4.48800","0.37416","0.00200"
"4.62000","0.38522","0.00200"
"4.75200","0.39623","0.00254"
"4.88400","0.40717","0.00219"
"5.01600","0.41817","0.00242"
"5.14800","0.42917","0.00261"
"5.28000","0.44023","0.00255"
"5.41200","0.45117","0.00157"
"5.54400","0.46217","0.00204"
"5.67600","0.47323","0.00182"
"5.80800","0.48418","0.00199"
"5.94000","0.49518","0.00170"
"6.07200","0.50612","0.00252"
"6.20400","0.51718","0.00165"
"6.33600","0.52818","0.00225"
"6.46800","0.53918","0.00205"
"6.60000","0.55012","0.00206"
"6.73200","0.56118","0.00247"
"6.86400","0.57219","0.00276"
"6.99600","0.58319","0.00249"
"7.12800","0.59419","0.00274"
"7.26000","0.60519","0.00234"
"7.39200","0.61619","0.00240"
"7.52400","0.62719","0.00237"
"7.65600","0.63819","0.00253"
"7.78800","0.64919","0.00246"
"7.92000","0.66020","0.00294"
"8.05200","0.67114","0.00251"
"8.18400","0.68214","0.00171"
"8.31600","0.69320","0.00258"
"8.44800","0.70420","0.00230"
"8.58000","0.71520","0.00250"
"8.71200","0.72614","0.00271"
"8.84400","0.73715","0.00244"
"8.97600","0.74821","0.00268"
"9.10800","0.75921","0.00244"
"9.24000","0.77015","0.00270"
"9.37200","0.78121","0.00295"
"9.50400","0.79221","0.00313"
"9.63600","0.80321","0.00285"
"9.76800","0.81415","0.00298"
"9.90000","0.82516","0.00246"
"10.03200","0.83622","0.00325"
"10.16400","0.84722","0.00321"
"10.29600","0.85816","0.00321"
"10.42800","0.86916","0.00324"
"10.56000","0.88022","0.00261"
"10.69200","0.89122","0.00297"
"10.82400","0.90216","0.00298"
"10.95600","0.91317","0.00327"
"11.08800","0.92423","0.00345"
"11.22000","0.93517","0.00336"
"11.35200","0.94617","0.00292"
"11.48400","0.95711","0.00296"
"11.61600","0.96823","0.00307"
"11.74800","0.97917","0.00315"
"11.88000","0.99017","0.00334"
"12.01200","1.00118","0.00338"
"12.14400","1.01218","0.00320"
"12.27600","1.02324","0.00291"
"12.40800","1.03412","0.00367"
"12.54000","1.04512","0.00360"
"12.67200","1.05618","0.00354"
"12.80400","1.06724","0.00363"
"12.93600","1.07818","0.00323"
"13.06800","1.08913","0.00418"
"13.20000","1.10013","0.00308"
"13.33200","1.11119","0.00361"
"13.46400","1.12219","0.00357"
"13.59600","1.13313","0.00326"
"13.72800","1.14419","0.00380"
"13.86000","1.15525","0.00336"
"13.99200","1.16619","0.00409"
"14.12400","1.17714","0.00301"
"14.25600","1.18820","0.00355"
"14.38800","1.19914","0.00332"
"14.52000","1.21014","0.00326"
"14.65200","1.22108","0.00434"
"14.78400","1.23220","0.00373"
"14.91600","1.24320","0.00369"
"15.04800","1.25420","0.00308"
"15.18000","1.26521","0.00326"
"15.31200","1.27621","0.00359"
"15.44400","1.28727","0.00412"
"15.57600","1.29821","0.00346"
"15.70800","1.30915","0.00388"
"15.84000","1.32015","0.00387"
"15.97200","1.33115","0.00415"
"16.10400","1.34222","0.00386"
"16.23600","1.35316","0.00414"
"16.36800","1.36422","0.00369"
"16.50000","1.37522","0.00338"
"16.63200","1.38616","0.00344"
"16.76400","1.39716","0.00287"
"16.89600","1.40816","0.00369"
"17.02800","1.41922","0.00361"
"17.16000","1.43023","0.00358"
"17.29200","1.44123","0.00396"
"17.42400","1.45223","0.00378"
"17.55600","1.46323","0.00388"
"17.68800","1.47423","0.00396"
"17.82000","1.48511","0.00399"
"17.95200","1.49617","0.00354"
"18.08400","1.50717","0.00419"
"18.21600","1.51818","0.00352"
"18.34800","1.52912","0.00376"
"18.48000","1.54018","0.00404"
"18.61200","1.55124","0.00350"
"18.74400","1.56224","0.00390"
"18.87600","1.57318","0.00381"
"19.00800","1.58412","0.00350"
"19.14000","1.59524","0.00522"
"19.27200","1.60619","0.00436"
"19.40400","1.61713","0.00422"
"19.53600","1.62813","0.00413"
"19.66800","1.63925","0.00333"
"19.80000","1.65025","0.00402"
"19.93200","1.66119","0.00417"
"20.06400","1.67213","0.00357"
"20.19600","1.68319","0.00388"
"20.32800","1.69420","0.00421"
"20.46000","1.70520","0.00404"
"20.59200","1.71620","0.00391"
"20.72400","1.72720","0.00354"
"20.85600","1.73820","0.00410"
"20.98800","1.74914","0.00432"
"21.12000","1.76008","0.00441"
"21.25200","1.77115","0.00407"
"21.38400","1.78215","0.00387"
"21.51600","1.79315","0.00428"
"21.64800","1.80409","0.00388"
"21.78000","1.81521","0.00364"
"21.91200","1.82621","0.00362"
"22.04400","1.83727","0.00427"
"22.17600","1.84815","0.00397"
"22.30800","1.85922","0.00451"
"22.44000","1.87022","0.00454"
"22.57200","1.88116","0.00439"
"22.70400","1.89216","0.00437"
"22.83600","1.90316","0.00409"
"22.96800","1.91416","0.00429"
"23.10000","1.92522","0.00385"
"23.23200","1.93616","0.00450"
"23.36400","1.94717","0.00396"
"23.49600","1.95823","0.00432"
"23.62800","1.96923","0.00439"
"23.76000","1.98017","0.00435"
"23.89200","1.99117","0.00440"
"24.02400","2.00217","0.00337"
"24.15600","2.01317","0.00380"
"24.28800","2.02417","0.00400"
"24.42000","2.03518","0.00401"
"24.55200","2.04618","0.00424"
"24.68400","2.05718","0.00425"
"24.81600","2.06818","0.00397"
"24.94800","2.07918","0.00415"
"25.08000","2.09024","0.00460"
"25.21200","2.10118","0.00431"
"25.34400","2.11219","0.00378"
"25.47600","2.12319","0.00390"
"25.60800","2.13425","0.00446"
"25.74000","2.14519","0.00438"
"25.87200","2.15619","0.00387"
"26.00400","2.16719","0.00451"
"26.13600","2.17819","0.00411"
"26.26800","2.18919","0.00398"
"26.40000","2.20014","0.00386"
"26.53200","2.21114","0.00378"
"26.66400","2.22220","0.00430"
"26.79600","2.23314","0.00426"
"26.92800","2.24420","0.00351"
"27.06000","2.25520","0.00460"
"27.19200","2.26620","0.00431"
"27.32400","2.27720","0.00399"
"27.45600","2.28815","0.00419"
"27.58800","2.29915","0.00406"
"27.72000","2.31021","0.00434"
"27.85200","2.32121","0.00444"
"27.98400","2.33221","0.00459"
"28.11600","2.34315","0.00424"
"28.24800","2.35421","0.00375"
"28.38000","2.36521","0.00410"
"28.51200","2.37622","0.00454"
"28.64400","2.38716","0.00454"
"28.77600","2.39822","0.00486"
"28.90800","2.40922","0.00431"
"29.04000","2.42016","0.00501"
"29.17200","2.43116","0.00424"
"29.30400","2.44216","0.00358"
"29.43600","2.45316","0.00395"
"29.56800","2.46417","0.00421"
"29.70000","2.47511","0.00451"
"29.83200","2.48617","0.00502"
"29.96400","2.49723","0.00472"
"30.09600","2.50823","0.00463"
"30.22800","2.51917","0.00456"
"30.36000","2.53023","0.00430"
"30.49200","2.54123","0.00511"
"30.62400","2.55224","0.00425"
"30.75600","2.56318","0.00477"
"30.88800","2.57418","0.00465"
"31.02000","2.58518","0.00404"
"31.15200","2.59624","0.00468"
"31.28400","2.60724","0.00420"
"31.41600","2.61818","0.00404"
"31.54800","2.62919","0.00422"
"31.68000","2.64025","0.00368"
"31.81200","2.65113","0.00446"
"31.94400","2.66219","0.00447"
"32.07600","2.67325","0.00494"
"32.20800","2.68419","0.00443"
"32.34000","2.69519","0.00417"
"32.47200","2.70613","0.00459"
"32.60400","2.71720","0.00405"
"32.73600","2.72814","0.00476"
"32.86800","2.73920","0.00442"
"33.00000","2.75014","0.00402"
"33.13200","2.76120","0.00486"
"33.26400","2.77220","0.00501"
"33.39600","2.78320","0.00458"
"33.52800","2.79420","0.00478"
"33.66000","2.80526","0.00442"
"33.79200","2.81621","0.00413"
"33.92400","2.82721","0.00454"
"34.05600","2.83815","0.00484"
"34.18800","2.84915","0.00444"
"34.32000","2.86021","0.00504"
"34.45200","2.87109","0.00491"
"34.58400","2.88215","0.00491"
"34.71600","2.89322","0.00501"
"34.84800","2.90422","0.00483"
"34.98000","2.91516","0.00467"
"35.11200","2.92616","0.00512"
"35.24400","2.93722","0.00475"
"35.37600","2.94822","0.00451"
"35.50800","2.95922","0.00484"
"35.64000","2.97016","0.00540"
"35.77200","2.98123","0.00409"
"35.90400","2.99217","0.00470"
"36.03600","3.00317","0.00459"
"36.16800","3.01411","0.00461"
"36.30000","3.02517","0.00473"
"36.43200","3.03617","0.00495"
"36.56400","3.04723","0.00498"
"36.69600","3.05817","0.00490"
"36.82800","3.06918","0.00456"
"36.96000","3.08024","0.00487"
"37.09200","3.09118","0.00440"
"37.22400","3.10212","0.00431"
"37.35600","3.11318","0.00524"
"37.48800","3.12418","0.00427"
"37.62000","3.13518","0.00524"
"37.75200","3.14618","0.00528"
"37.88400","3.15719","0.00514"
"38.01600","3.16819","0.00483"
"38.14800","3.17919","0.00519"
"38.28000","3.19019","0.00428"
"38.41200","3.20119","0.00511"
"38.54400","3.21225","0.00507"
"38.67600","3.22325","0.00554"
"38.80800","3.23414","0.00485"
"38.94000","3.24514","0.00515"
"39.07200","3.25620","0.00539"
"39.20400","3.26726","0.00471"
"39.33600","3.27814","0.00483"
"39.46800","3.28920","0.00523"
"39.60000","3.30020","0.00536"
"39.73200","3.31120","0.00532"
"39.86400","3.32215","0.00477"
"39.99600","3.33315","0.00500"
"40.12800","3.34421","0.00474"
"40.26000","3.35521","0.00524"
"40.39200","3.36615","0.00571"
"40.52400","3.37709","0.00486"
"40.65600","3.38821","0.00539"
"40.78800","3.39921","0.00505"
"40.92000","3.41022","0.00529"
"41.05200","3.42116","0.00492"
"41.18400","3.43222","0.00491"
"41.31600","3.44322","0.00462"
"41.44800","3.45416","0.00511"
"41.58000","3.46516","0.00470"
"41.71200","3.47622","0.00515"
"41.84400","3.48722","0.00546"
"41.97600","3.49823","0.00440"
"42.10800","3.50917","0.00439"
"42.24000","3.52023","0.00531"
"42.37200","3.53117","0.00507"
"42.50400","3.54217","0.00473"
"42.63600","3.55311","0.00541"
"42.76800","3.56417","0.00540"
"42.90000","3.57518","0.00538"
"43.03200","3.58618","0.00568"
"43.16400","3.59718","0.00505"
"43.29600","3.60818","0.00516"
"43.42800","3.61918","0.00523"
"43.56000","3.63024","0.00526"
"43.69200","3.64118","0.00553"
"43.82400","3.65218","0.00545"
"43.95600","3.66319","0.00485"
"44.08800","3.67419","0.00513"
"44.22000","3.68513","0.00565"
"44.35200","3.69625","0.00508"
"44.48400","3.70725","0.00583"
"44.61600","3.71819","0.00572"
"44.74800","3.72919","0.00564"
"44.88000","3.74019","0.00543"
"45.01200","3.75120","0.00593"
"45.14400","3.76220","0.00565"
"45.27600","3.77320","0.00559"
"45.40800","3.78420","0.00579"
"45.54000","3.79520","0.00531"
"45.67200","3.80620","0.00557"
"45.80400","3.81714","0.00511"
"45.93600","3.82814","0.00532"
"46.06800","3.83921","0.00549"
"46.20000","3.85021","0.00575"
"46.33200","3.86115","0.00531"
"46.46400","3.87221","0.00527"
"46.59600","3.88321","0.00537"
"46.72800","3.89421","0.00545"
"46.86000","3.90515","0.00580"
"46.99200","3.91615","0.00593"
"47.12400","3.92716","0.00570"
"47.25600","3.93822","0.00539"
"47.38800","3.94916","0.00504"
"47.52000","3.96010","0.00579"
"47.65200","3.97122","0.00523"
"47.78400","3.98222","0.00530"
"47.91600","3.99316","0.00567"
"48.04800","4.00416","0.00552"
"48.18000","4.01517","0.00509"
"48.31200","4.02623","0.00587"
"48.44400","4.03717","0.00519"
"48.57600","4.04817","0.00547"
"48.70800","4.05917","0.00545"
"48.84000","4.07023","0.00510"
"48.97200","4.08117","0.00528"
"49.10400","4.09211","0.00559"
"49.23600","4.10318","0.00590"
"49.36800","4.11418","0.00593"
"49.50000","4.12518","0.00541"
"49.63200","4.13612","0.00541"
"49.76400","4.14718","0.00542"
"49.89600","4.15818","0.00530"
"50.02800","4.16918","0.00593"
"50.16000","4.18018","0.00585"
"50.29200","4.19119","0.00536"
"50.42400","4.20219","0.00556"
"50.55600","4.21313","0.00587"
"50.68800","4.22413","0.00550"
"50.82000","4.23519","0.00548"
"50.95200","4.24619","0.00623"
"51.08400","4.25719","0.00512"
"51.21600","4.26814","0.00565"
"51.34800","4.27920","0.00529"
"51.48000","4.29020","0.00540"
"51.61200","4.30120","0.00615"
"51.74400","4.31220","0.00659"
"51.87600","4.32320","0.00532"
"52.00800","4.33420","0.00567"
"52.14000","4.34520","0.00561"
"52.27200","4.35621","0.00557"
"52.40400","4.36715","0.00555"
"52.53600","4.37827","0.00577"
"52.66800","4.38921","0.00568"
"52.80000","4.40015","0.00610"
"52.93200","4.41115","0.00538"
"53.06400","4.42221","0.00541"
"53.19600","4.43321","0.00640"
"53.32800","4.44416","0.00532"
"53.46000","4.45522","0.00580"
"53.59200","4.46628","0.00597"
"53.72400","4.47722","0.00564"
"53.85600","4.48816","0.00578"
"53.98800","4.49910","0.00600"
"54.12000","4.51022","0.00598"
"54.25200","4.52116","0.00562"
"54.38400","4.53217","0.00565"
"54.51600","4.54311","0.00558"
"54.64800","4.55423","0.00628"
"54.78000","4.56517","0.00578"
"54.91200","4.57617","0.00541"
"55.04400","4.58717","0.00592"
"55.17600","4.59823","0.00572"
"55.30800","4.60924","0.00570"
"55.44000","4.62018","0.00624"
"55.57200","4.63112","0.00585"
"55.70400","4.64218","0.00538"
"55.83600","4.65324","0.00574"
"55.96800","4.66418","0.00591"
"56.10000","4.67518","0.00551"
"56.23200","4.68618","0.00587"
"56.36400","4.69719","0.00544"
"56.49600","4.70819","0.00556"
"56.62800","4.71919","0.00580"
"56.76000","4.73019","0.00590"
"56.89200","4.74125","0.00568"
"57.02400","4.75219","0.00638"
"57.15600","4.76313","0.00570"
"57.28800","4.77419","0.00587"
"57.42000","4.78520","0.00631"
"57.55200","4.79620","0.00606"
"57.68400","4.80714","0.00542"
"57.81600","4.81814","0.00653"
"57.94800","4.82920","0.00599"
"58.08000","4.84020","0.00559"
"58.21200","4.85120","0.00626"
"58.34400","4.86220","0.00595"
"58.47600","4.87327","0.00604"
"58.60800","4.88421","0.00624"
"58.74000","4.89515","0.00624"
"58.87200","4.90615","0.00630"
"59.00400","4.91715","0.00575"
"59.13600","4.92821","0.00604"
"59.26800","4.93915","0.00614"
"59.40000","4.95015","0.00612"
"59.53200","4.96122","0.00577"
"59.66400","4.97222","0.00615"
"59.79600","4.98310","0.00610"
"59.92800","4.99416","0.00581"
"60.06000","5.00516","0.00568"
"60.19200","5.01616","0.00623"
"60.32400","5.02716","0.00589"
"60.45600","5.03816","0.00619"
"60.58800","5.04917","0.00666"
"60.72000","5.06017","0.00635"
"60.85200","5.07111","0.00599"
"60.98400","5.08211","0.00612"
"61.11600","5.09323","0.00634"
"61.24800","5.10423","0.00650"
"61.38000","5.11517","0.00658"
"61.51200","5.12618","0.00611"
"61.64400","5.13730","0.00652"
"61.77600","5.14824","0.00719"
"61.90800","5.15918","0.00645"
"62.04000","5.17012","0.00724"
"62.17200","5.18124","0.00615"
"62.30400","5.19218","0.00617"
"62.43600","5.20318","0.00681"
"62.56800","5.21407","0.00667"
"62.70000","5.22519","0.00643"
"62.83200","5.23619","0.00654"
"62.96400","5.24719","0.00679"
"63.09600","5.25813","0.00639"
"63.22800","5.26925","0.00639"
"63.36000","5.28025","0.00688"
"63.49200","5.29119","0.00671"
"63.62400","5.30214","0.00690"
"63.75600","5.31320","0.00686"
"63.88800","5.32420","0.00705"
"64.02000","5.33520","0.00707"
"64.15200","5.34614","0.00621"
"64.28400","5.35714","0.00638"
"64.41600","5.36814","0.00630"
"64.54800","5.37920","0.00723"
"64.68000","5.39015","0.00641"
"64.81200","5.40121","0.00642"
"64.94400","5.41221","0.00640"
"65.07600","5.42321","0.00677"
"65.20800","5.43415","0.00603"
"65.34000","5.44515","0.00662"
"65.47200","5.45615","0.00654"
"65.60400","5.46715","0.00641"
"65.73600","5.47816","0.00665"
"65.86800","5.48910","0.00622"
"66.00000","5.50016","0.00675"
"66.13200","5.51122","0.00701"
"66.26400","5.52216","0.00647"
"66.39600","5.53316","0.00608"
"66.52800","5.54422","0.00687"
"66.66000","5.55522","0.00654"
"66.79200","5.56623","0.00702"
"66.92400","5.57717","0.00573"
"67.05600","5.58823","0.00687"
"67.18800","5.59923","0.00672"
"67.32000","5.61017","0.00632"
"67.45200","5.62117","0.00694"
"67.58400","5.63223","0.00614"
"67.71600","5.64318","0.00648"
"67.84800","5.65418","0.00699"
"67.98000","5.66518","0.00671"
"68.11200","5.67624","0.00727"
"68.24400","5.68718","0.00742"
"68.37600","5.69818","0.00669"
"68.50800","5.70918","0.00679"
"68.64000","5.72024","0.00735"
"68.77200","5.73125","0.00653"
"68.90400","5.74219","0.00689"
"69.03600","5.75319","0.00716"
"69.16800","5.76419","0.00658"
"69.30000","5.77525","0.00705"
"69.43200","5.78619","0.00666"
"69.56400","5.79713","0.00671"
"69.69600","5.80825","0.00670"
"69.82800","5.81920","0.00695"
"69.96000","5.83026","0.00634"
"70.09200","5.84120","0.00723"
"70.22400","5.85220","0.00648"
"70.35600","5.86314","0.00697"
"70.48800","5.87414","0.00727"
"70.62000","5.88508","0.00686"
"70.75200","5.89620","0.00670"
"70.88400","5.90721","0.00702"
"71.01600","5.91815","0.00754"
"71.14800","5.92909","0.00669"
"71.28000","5.94021","0.00670"
"71.41200","5.95121","0.00682"
"71.54400","5.96221","0.00611"
"71.67600","5.97315","0.00586"
"71.80800","5.98416","0.00644"
"71.94000","5.99522","0.00670"
"72.07200","6.00616","0.00670"
"72.20400","6.01716","0.00666"
"72.33600","6.02810","0.00609"
"72.46800","6.03916","0.00630"
"72.60000","6.05016","0.00635"
"72.73200","6.06110","0.00725"
"72.86400","6.07217","0.00648"
"72.99600","6.08323","0.00650"
"73.12800","6.09423","0.00648"
"73.26000","6.10517","0.00654"
"73.39200","6.11617","0.00650"
"73.52400","6.12723","0.00695"
"73.65600","6.13823","0.00624"
"73.78800","6.14917","0.00712"
"73.92000","6.16012","0.00744"
"74.05200","6.17118","0.00600"
"74.18400","6.18218","0.00700"
"74.31600","6.19318","0.00723"
"74.44800","6.20418","0.00639"
"74.58000","6.21524","0.00722"
"74.71200","6.22624","0.00682"
"74.84400","6.23718","0.00665"
"74.97600","6.24819","0.00665"
"75.10800","6.25925","0.00662"
"75.24000","6.27019","0.00698"
"75.37200","6.28119","0.00585"
"75.50400","6.29219","0.00699"
"75.63600","6.30319","0.00682"
"75.76800","6.31419","0.00707"
"75.90000","6.32519","0.00653"
"76.03200","6.33614","0.00642"
"76.16400","6.34720","0.00643"
"76.29600","6.35826","0.00697"
"76.42800","6.36920","0.00676"
"76.56000","6.38014","0.00707"
"76.69200","6.39120","0.00706"
"76.82400","6.40220","0.00653"
"76.95600","6.41315","0.00674"
"77.08800","6.42415","0.00722"
"77.22000","6.43515","0.00732"
"77.35200","6.44621","0.00633"
"77.48400","6.45715","0.00646"
"77.61600","6.46815","0.00674"
"77.74800","6.47915","0.00721"
"77.88000","6.49021","0.00705"
"78.01200","6.50116","0.00672"
"78.14400","6.51216","0.00629"
"78.27600","6.52322","0.00698"
"78.40800","6.53416","0.00746"
"78.54000","6.54516","0.00743"
"78.67200","6.55610","0.00710"
"78.80400","6.56722","0.00709"
"78.93600","6.57816","0.00718"
"79.06800","6.58917","0.00717"
"79.20000","6.60011","0.00745"
"79.33200","6.61117","0.00712"
"79.46400","6.62217","0.00730"
"79.59600","6.63323","0.00738"
"79.72800","6.64417","0.00749"
"79.86000","6.65523","0.00725"
"79.99200","6.66623","0.00748"
"80.12400","6.67718","0.00752"
"80.25600","6.68812","0.00748"
"80.38800","6.69912","0.00756"
"80.52000","6.71018","0.00776"
"80.65200","6.72124","0.00715"
"80.78400","6.73218","0.00719"
"80.91600","6.74318","0.00697"
"81.04800","6.75418","0.00734"
"81.18000","6.76525","0.00713"
"81.31200","6.77619","0.00740"
"81.44400","6.78719","0.00726"
"81.57600","6.79825","0.00734"
"81.70800","6.80925","0.00791"
"81.84000","6.82013","0.00787"
"81.97200","6.83113","0.00753"
"82.10400","6.84219","0.00734"
"82.23600","6.85320","0.00737"
"82.36800","6.86414","0.00763"
"82.50000","6.87514","0.00742"
"82.63200","6.88620","0.00739"
"82.76400","6.89726","0.00765"
"82.89600","6.90820","0.00814"
"83.02800","6.91914","0.00763"
"83.16000","6.93020","0.00760"
"83.29200","6.94115","0.00758"
"83.42400","6.95215","0.00795"
"83.55600","6.96309","0.00826"
"83.68800","6.97421","0.00743"
"83.82000","6.98515","0.00775"
"83.95200","6.99615","0.00802"
"84.08400","7.00715","0.00760"
"84.21600","7.01822","0.00772"
"84.34800","7.02922","0.00808"
"84.48000","7.04022","0.00728"
"84.61200","7.05116","0.00809"
"84.74400","7.06216","0.00760"
"84.87600","7.07322","0.00798"
"85.00800","7.08416","0.00846"
"85.14000","7.09516","0.00854"
"85.27200","7.10617","0.00817"
"85.40400","7.11717","0.00846"
"85.53600","7.12811","0.00793"
"85.66800","7.13911","0.00857"
"85.80000","7.15017","0.00854"
"85.93200","7.16117","0.00852"
"86.06400","7.17223","0.00887"
"86.19600","7.18317","0.00860"
"86.32800","7.19418","0.00855"
"86.46000","7.20524","0.00832"
"86.59200","7.21624","0.00811"
"86.72400","7.22712","0.00844"
"86.85600","7.23818","0.00961"
"86.98800","7.24918","0.00905"
"87.12000","7.26018","0.00869"
"87.25200","7.27118","0.00851"
"87.38400","7.28219","0.00896"
"87.51600","7.29319","0.00905"
"87.64800","7.30419","0.00880"
"87.78000","7.31519","0.00875"
"87.91200","7.32619","0.00912"
"88.04400","7.33719","0.00923"
"88.17600","7.34819","0.00903"
"88.30800","7.35919","0.00918"
"88.44000","7.37014","0.00918"
"88.57200","7.38120","0.00907"
"88.70400","7.39226","0.00928"
"88.83600","7.40314","0.00880"
"88.96800","7.41408","0.00915"
"89.10000","7.42526","0.00982"
"89.23200","7.43620","0.00915"
"89.36400","7.44721","0.00919"
"89.49600","7.45821","0.00973"
"89.62800","7.46921","0.00924"
"89.76000","7.48021","0.00961"
"89.89200","7.49115","0.00931"
"90.02400","7.50215","0.00898"
"90.15600","7.51315","0.00896"
"90.28800","7.52421","0.00936"
"90.42000","7.53516","0.00992"
"90.55200","7.54610","0.00988"
"90.68400","7.55722","0.00958"
"90.81600","7.56822","0.01022"
"90.94800","7.57916","0.01017"
"91.08000","7.59016","0.00968"
"91.21200","7.60116","0.01031"
"91.34400","7.61222","0.00999"
"91.47600","7.62323","0.01054"
"91.60800","7.63417","0.01072"
"91.74000","7.64517","0.01005"
"91.87200","7.65617","0.01038"
"92.00400","7.66717","0.01075"
"92.13600","7.67811","0.01014"
"92.26800","7.68923","0.01004"
"92.40000","7.70018","0.00993"
"92.53200","7.71124","0.01061"
"92.66400","7.72218","0.01016"
"92.79600","7.73318","0.01075"
"92.92800","7.74424","0.01039"
"93.06000","7.75524","0.01072"
"93.19200","7.76618","0.01074"
"93.32400","7.77718","0.01025"
"93.45600","7.78819","0.01035"
"93.58800","7.79919","0.01024"
"93.72000","7.81013","0.01011"
"93.85200","7.82113","0.00969"
"93.98400","7.83219","0.01007"
"94.11600","7.84319","0.00948"
"94.24800","7.85419","0.00990"
"94.38000","7.86519","0.01002"
"94.51200","7.87625","0.00980"
"94.64400","7.88726","0.01002"
"94.77600","7.89820","0.00989"
"94.90800","7.90914","0.01040"
"95.04000","7.92020","0.00975"
"95.17200","7.93120","0.01033"
"95.30400","7.94214","0.01007"
"95.43600","7.95314","0.01087"
"95.56800","7.96420","0.01081"
"95.70000","7.97527","0.01113"
"95.83200","7.98615","0.01117"
"95.96400","7.99715","0.01058"
"96.09600","8.00821","0.01126"
"96.22800","8.01915","0.01052"
"96.36000","8.03015","0.01086"
"96.49200","8.04115","0.01106"
"96.62400","8.05221","0.01153"
"96.75600","8.06322","0.01130"
"96.88800","8.07416","0.01134"
"97.02000","8.08510","0.01092"
"97.15200","8.09622","0.01148"
"97.28400","8.10722","0.01125"
"97.41600","8.11816","0.01182"
"97.54800","8.12910","0.01112"
"97.68000","8.14023","0.01147"
"97.81200","8.15123","0.01168"
"97.94400","8.16223","0.01130"
"98.07600","8.17317","0.01196"
"98.20800","8.18417","0.01172"
"98.34000","8.19517","0.01186"
"98.47200","8.20617","0.01204"
"98.60400","8.21712","0.01188"
"98.73600","8.22818","0.01182"
"98.86800","8.23918","0.01266"
"99.00000","8.25018","0.01173"
"99.13200","8.26118","0.01199"
"99.26400","8.27212","0.01238"
"99.39600","8.28324","0.01232"
"99.52800","8.29418","0.01292"
"99.66000","8.30518","0.01226"
"99.79200","8.31619","0.01225"
"99.92400","8.32719","0.01263"
"100.05600","8.33819","0.01295"
"100.18800","8.34913","0.01245"
"100.32000","8.36019","0.01301"
"100.45200","8.37119","0.01256"
"100.58400","8.38219","0.01274"
"100.71600","8.39319","0.01337"
"100.84800","8.40420","0.01361"
"100.98000","8.41520","0.01283"
"101.11200","8.42620","0.01333"
"101.24400","8.43714","0.01350"
"101.37600","8.44814","0.01352"
"101.50800","8.45920","0.01371"
"101.64000","8.47014","0.01303"
"101.77200","8.48114","0.01373"
"101.90400","8.49215","0.01396"
"102.03600","8.50315","0.01421"
"102.16800","8.51421","0.01424"
"102.30000","8.52515","0.01387"
"102.43200","8.53615","0.01447"
"102.56400","8.54721","0.01438"
"102.69600","8.55821","0.01414"
"102.82800","8.56916","0.01422"
"102.96000","8.58016","0.01396"
"103.09200","8.59122","0.01497"
"103.22400","8.60222","0.01483"
"103.35600","8.61316","0.01518"
"103.48800","8.62416","0.01494"
"103.62000","8.63516","0.01526"
"103.75200","8.64622","0.01503"
"103.88400","8.65717","0.01527"
"104.01600","8.66817","0.01546"
"104.14800","8.67923","0.01523"
"104.28000","8.69023","0.01574"
"104.41200","8.70117","0.01580"
"104.54400","8.71217","0.01589"
"104.67600","8.72329","0.01578"
"104.80800","8.73417","0.01608"
"104.94000","8.74518","0.01563"
"105.07200","8.75612","0.01618"
"105.20400","8.76724","0.01623"
"105.33600","8.77824","0.01661"
"105.46800","8.78918","0.01622"
"105.60000","8.80012","0.01619"
"105.73200","8.81118","0.01634"
"105.86400","8.82218","0.01706"
"105.99600","8.83325","0.01692"
"106.12800","8.84413","0.01676"
"106.26000","8.85519","0.01682"
"106.39200","8.86625","0.01704"
"106.52400","8.87719","0.01803"
"106.65600","8.88813","0.01742"
"106.78800","8.89913","0.01761"
"106.92000","8.91020","0.01849"
"107.05200","8.92114","0.01771"
"107.18400","8.93214","0.01771"
"107.31600","8.94314","0.01783"
"107.44800","8.95420","0.01844"
"107.58000","8.96520","0.01895"
"107.71200","8.97614","0.01899"
"107.84400","8.98720","0.01861"
"107.97600","8.99821","0.01881"
"108.10800","9.00921","0.01865"
"108.24000","9.02015","0.01889"
"108.37200","9.03115","0.01963"
"108.50400","9.04215","0.01920"
"108.63600","9.05321","0.01925"
"108.76800","9.06421","0.01975"
"108.90000","9.07515","0.01990"
"109.03200","9.08615","0.02037"
"109.16400","9.09722","0.01966"
"109.29600","9.10810","0.01969"
"109.42800","9.11916","0.02072"
"109.56000","9.13022","0.02053"
"109.69200","9.14122","0.02065"
"109.82400","9.15216","0.02079"
"109.95600","9.16316","0.02096"
"110.08800","9.17417","0.02152"
"110.22000","9.18517","0.02186"
"110.35200","9.19617","0.02128"
"110.48400","9.20717","0.02133"
"110.61600","9.21823","0.02150"
"110.74800","9.22923","0.02221"
"110.88000","9.24017","0.02203"
"111.01200","9.25117","0.02246"
"111.14400","9.26224","0.02195"
"111.27600","9.27318","0.02248"
"111.40800","9.28418","0.02251"
"111.54000","9.29518","0.02265"
"111.67200","9.30624","0.02314"
"111.80400","9.31718","0.02321"
"111.93600","9.32812","0.02324"
"112.06800","9.33912","0.02263"
"112.20000","9.35019","0.02390"
"112.33200","9.36119","0.02263"
"112.46400","9.37219","0.02307"
"112.59600","9.38313","0.02170"
"112.72800","9.39425","0.02192"
"112.86000","9.40519","0.01962"
"112.99200","9.41619","0.01909"
"113.12400","9.42713","0.01909"
"113.25600","9.43820","0.01887"
"113.38800","9.44920","0.01835"
"113.52000","9.46020","0.01879"
"113.65200","9.47114","0.01921"
"113.78400","9.48220","0.01929"
"113.91600","9.49320","0.01941"
"114.04800","9.50420","0.01871"
"114.18000","9.51515","0.01921"
"114.31200","9.52621","0.01991"
"114.44400","9.53721","0.01973"
"114.57600","9.54821","0.01997"
"114.70800","9.55915","0.02009"
"114.84000","9.57015","0.02037"
"114.97200","9.58121","0.02053"
"115.10400","9.59215","0.02090"
"115.23600","9.60316","0.02068"
"115.36800","9.61416","0.02155"
"115.50000","9.62516","0.02101"
"115.63200","9.63616","0.02177"
"115.76400","9.64716","0.02185"
"115.89600","9.65822","0.02174"
"116.02800","9.66922","0.02242"
"116.16000","9.68022","0.02239"
"116.29200","9.69117","0.02216"
"116.42400","9.70217","0.02285"
"116.55600","9.71317","0.02295"
"116.68800","9.72423","0.02291"
"116.82000","9.73517","0.02310"
"116.95200","9.74617","0.02270"
"117.08400","9.75723","0.02279"
"117.21600","9.76823","0.02329"
"117.34800","9.77918","0.02405"
"117.48000","9.79018","0.02349"
"117.61200","9.80124","0.02325"
"117.74400","9.81224","0.02422"
"117.87600","9.82324","0.02391"
"118.00800","9.83412","0.02364"
"118.14000","9.84518","0.02378"
"118.27200","9.85618","0.02395"
"118.40400","9.86719","0.02435"
"118.53600","9.87813","0.02407"
"118.66800","9.88919","0.02399"
"118.80000","9.90019","0.02408"
"118.93200","9.91119","0.02368"
"119.06400","9.92213","0.02412"
"119.19600","9.93319","0.02400"
"119.32800","9.94425","0.02342"
"119.46000","9.95520","0.02344"
"119.59200","9.96614","0.02378"
"119.72400","9.97720","0.02402"
"119.85600","9.98820","0.02356"
"119.98800","9.99914","0.02405"
"120.12000","10.01014","0.02329"
"120.25200","10.02114","0.02389"
"120.38400","10.03221","0.02447"
"120.51600","10.04315","0.02426"
"120.64800","10.05415","0.02474"
"120.78000","10.06515","0.02440"
"120.91200","10.07615","0.02494"
"121.04400","10.08715","0.02508"
"121.17600","10.09815","0.02551"
"121.30800","10.10921","0.02564"
"121.44000","10.12016","0.02580"
"121.57200","10.13116","0.02537"
"121.70400","10.14210","0.02607"
"121.83600","10.15316","0.02605"
"121.96800","10.16422","0.02595"
"122.10000","10.17516","0.02669"
"122.23200","10.18610","0.02527"
"122.36400","10.19716","0.02498"
"122.49600","10.20823","0.02532"
"122.62800","10.21923","0.02563"
"122.76000","10.23017","0.02486"
"122.89200","10.24117","0.02612"
"123.02400","10.25223","0.02705"
"123.15600","10.26317","0.02636"
"123.28800","10.27411","0.02712"
"123.42000","10.28512","0.02681"
"123.55200","10.29618","0.02718"
"123.68400","10.30718","0.02800"
"123.81600","10.31818","0.02768"
"123.94800","10.32918","0.02886"
"124.08000","10.34018","0.02780"
"124.21200","10.35124","0.02898"
"124.34400","10.36212","0.02943"
"124.47600","10.37313","0.02932"
"124.60800","10.38413","0.02935"
"124.74000","10.39519","0.02940"
"124.87200","10.40613","0.03027"
"125.00400","10.41719","0.03030"
"125.13600","10.42819","0.03121"
"125.26800","10.43925","0.03089"
"125.40000","10.45013","0.03092"
"125.53200","10.46119","0.03162"
"125.66400","10.47220","0.03181"
"125.79600","10.48326","0.03191"
"125.92800","10.49420","0.03196"
"126.06000","10.50520","0.03236"
"126.19200","10.51620","0.03249"
"126.32400","10.52720","0.03306"
"126.45600","10.53820","0.03271"
"126.58800","10.54909","0.03339"
"126.72000","10.56021","0.03351"
"126.85200","10.57121","0.03320"
"126.98400","10.58221","0.03353"
"127.11600","10.59315","0.03387"
"127.24800","10.60415","0.03429"
"127.38000","10.61521","0.03463"
"127.51200","10.62621","0.03496"
"127.64400","10.63716","0.03497"
"127.77600","10.64822","0.03525"
"127.90800","10.65922","0.03509"
"128.04000","10.67022","0.03509"
"128.17200","10.68116","0.03580"
"128.30400","10.69216","0.03550"
"128.43600","10.70316","0.03628"
"128.56800","10.71416","0.03614"
"128.70000","10.72517","0.03705"
"128.83200","10.73617","0.03606"
"128.96400","10.74723","0.03632"
"129.09600","10.75823","0.03661"
"129.22800","10.76917","0.03637"
"129.36000","10.78017","0.03634"
"129.49200","10.79117","0.03746"
"129.62400","10.80217","0.03705"
"129.75600","10.81312","0.03669"
"129.88800","10.82418","0.03700"
"130.02000","10.83524","0.03697"
"130.15200","10.84624","0.03641"
"130.28400","10.85718","0.03640"
"130.41600","10.86818","0.03669"
"130.54800","10.87924","0.03720"
"130.68000","10.89024","0.03577"
"130.81200","10.90119","0.03690"
"130.94400","10.91219","0.03632"
"131.07600","10.92325","0.03609"
"131.20800","10.93419","0.03597"
"131.34000","10.94513","0.03623"
"131.47200","10.95607","0.03624"
"131.60400","10.96719","0.03689"
"131.73600","10.97820","0.03671"
"131.86800","10.98914","0.03721"
"132.00000","11.00014","0.03598"
"132.13200","11.01126","0.03657"
"132.26400","11.02220","0.03668"
"132.39600","11.03320","0.03747"
"132.52800","11.04414","0.03741"
"132.66000","11.05520","0.03667"
"132.79200","11.06626","0.03718"
"132.92400","11.07721","0.03716"
"133.05600","11.08815","0.03765"
"133.18800","11.09915","0.03733"
"133.32000","11.11021","0.03737"
"133.45200","11.12115","0.03767"
"133.58400","11.13209","0.03808"
"133.71600","11.14315","0.03807"
"133.84800","11.15422","0.03879"
"133.98000","11.16522","0.03837"
"134.11200","11.17616","0.03875"
"134.24400","11.18722","0.03883"
"134.37600","11.19822","0.03871"
"134.50800","11.20916","0.03858"
"134.64000","11.22010","0.03965"
"134.77200","11.23116","0.03960"
"134.90400","11.24211","0.04016"
"135.03600","11.25317","0.03991"
"135.16800","11.26411","0.04030"
"135.30000","11.27517","0.04026"
"135.43200","11.28617","0.04057"
"135.56400","11.29723","0.04094"
"135.69600","11.30817","0.04175"
"135.82800","11.31917","0.04105"
"135.96000","11.33018","0.04142"
"136.09200","11.34118","0.04216"
"136.22400","11.35218","0.04210"
"136.35600","11.36312","0.04240"
"136.48800","11.37418","0.04226"
"136.62000","11.38518","0.04274"
"136.75200","11.39612","0.04323"
"136.88400","11.40713","0.04306"
"137.01600","11.41825","0.04288"
"137.14800","11.42919","0.04368"
"137.28000","11.44013","0.04342"
"137.41200","11.45119","0.04305"
"137.54400","11.46219","0.04346"
"137.67600","11.47319","0.04369"
"137.80800","11.48419","0.04381"
"137.94000","11.49514","0.04446"
"138.07200","11.50620","0.04410"
"138.20400","11.51726","0.04367"
"138.33600","11.52820","0.04392"
"138.46800","11.53914","0.04349"
"138.60000","11.55026","0.03938"
"138.73200","11.56120","0.03598"
"138.86400","11.57220","0.03237"
"138.99600","11.58321","0.02800"
"139.12800","11.59427","0.02764"
"139.26000","11.60521","0.02682"
"139.39200","11.61615","0.02682"
"139.52400","11.62709","0.02693"
"139.65600","11.63821","0.02667"
"139.78800","11.64921","0.02781"
"139.92000","11.66021","0.02759"
"140.05200","11.67116","0.02721"
"140.18400","11.68222","0.02823"
"140.31600","11.69316","0.02865"
"140.44800","11.70422","0.02839"
"140.58000","11.71510","0.02784"
"140.71200","11.72622","0.02826"
"140.84400","11.73728","0.02915"
"140.97600","11.74816","0.02934"
"141.10800","11.75911","0.02920"
"141.24000","11.77017","0.02951"
"141.37200","11.78123","0.02872"
"141.50400","11.79217","0.02977"
"141.63600","11.80317","0.02955"
"141.76800","11.81417","0.03049"
"141.90000","11.82517","0.03044"
"142.03200","11.83617","0.03023"
"142.16400","11.84718","0.02939"
"142.29600","11.85818","0.03008"
"142.42800","11.86924","0.03004"
"142.56000","11.88024","0.03006"
"142.69200","11.89112","0.02984"
"142.82400","11.90212","0.03018"
"142.95600","11.91318","0.03182"
"143.08800","11.92418","0.03047"
"143.22000","11.93513","0.03080"
"143.35200","11.94619","0.03013"
"143.48400","11.95719","0.03019"
"143.61600","11.96819","0.03076"
"143.74800","11.97919","0.03020"
"143.88000","11.99019","0.03092"
"144.01200","12.00126","0.03115"
"144.14400","12.01225","0.03110"
"144.27600","12.02320","0.03195"
"144.40800","12.03414","0.03169"
"144.54000","12.04520","0.03100"
"144.67200","12.05614","0.03145"
"144.80400","12.06714","0.03137"
"144.93600","12.07814","0.03180"
"145.06800","12.08920","0.03195"
"145.20000","12.10027","0.03157"
"145.33200","12.11121","0.03247"
"145.46400","12.12215","0.03258"
"145.59600","12.13321","0.03206"
"145.72800","12.14421","0.03257"
"145.86000","12.15515","0.03310"
"145.99200","12.16615","0.03299"
"146.12400","12.17721","0.03232"
"146.25600","12.18816","0.03157"
"146.38800","12.19916","0.03067"
"146.52000","12.21010","0.03015"
"146.65200","12.22116","0.03003"
"146.78400","12.23222","0.02972"
"146.91600","12.24316","0.02914"
"147.04800","12.25410","0.02905"
"147.18000","12.26523","0.02906"
"147.31200","12.27623","0.02918"
"147.44400","12.28717","0.02996"
"147.57600","12.29811","0.02977"
"147.70800","12.30923","0.02999"
"147.84000","12.32017","0.03016"
"147.97200","12.33117","0.03060"
"148.10400","12.34212","0.03038"
"148.23600","12.35324","0.03025"
"148.36800","12.36418","0.03052"
"148.50000","12.37524","0.03156"
"148.63200","12.38612","0.03117"
"148.76400","12.39718","0.03130"
"148.89600","12.40818","0.03095"
"149.02800","12.41918","0.03000"
"149.16000","12.43013","0.03029"
"149.29200","12.44118","0.03010"
"149.42400","12.45219","0.03034"
"149.55600","12.46319","0.02856"
"149.68800","12.47419","0.02698"
"149.82000","12.48513","0.02552"
"149.95200","12.49619","0.02429"
"150.08400","12.50719","0.02379"
"150.21600","12.51814","0.02125"
"150.34800","12.52914","0.02092"
"150.48000","12.54020","0.02128"
"150.61200","12.55126","0.02146"
"150.74400","12.56214","0.02135"
"150.87600","12.57320","0.02188"
"151.00800","12.58420","0.02128"
"151.14000","12.59520","0.02121"
"151.27200","12.60614","0.02129"
"151.40400","12.61715","0.02146"
"151.53600","12.62821","0.02129"
"151.66800","12.63921","0.02100"
"151.80000","12.65021","0.02204"
"151.93200","12.66115","0.02164"
"152.06400","12.67221","0.02168"
"152.19600","12.68321","0.02180"
"152.32800","12.69415","0.02171"
"152.46000","12.70516","0.02240"
"152.59200","12.71622","0.02247"
"152.72400","12.72722","0.02265"
"152.85600","12.73816","0.02252"
"152.98800","12.74916","0.02255"
"153.12000","12.76022","0.02305"
"153.25200","12.77122","0.02235"
"153.38400","12.78216","0.02275"
"153.51600","12.79317","0.02173"
"153.64800","12.80423","0.02122"
"153.78000","12.81523","0.02221"
"153.91200","12.82623","0.02190"
"154.04400","12.83717","0.02109"
"154.17600","12.84823","0.02177"
"154.30800","12.85917","0.02248"
"154.44000","12.87017","0.02127"
"154.57200","12.88112","0.02223"
"154.70400","12.89218","0.02215"
"154.83600","12.90318","0.02139"
"154.96800","12.91412","0.02242"
"155.10000","12.92512","0.02251"
"155.23200","12.93618","0.02202"
"155.36400","12.94724","0.02253"
"155.49600","12.95819","0.02291"
"155.62800","12.96919","0.02291"
"155.76000","12.98025","0.02264"
"155.89200","12.99119","0.02297"
"156.02400","13.00219","0.02208"
"156.15600","13.01313","0.02178"
"156.28800","13.02419","0.02220"
"156.42000","13.03520","0.02316"
"156.55200","13.04620","0.02254"
"156.68400","13.05714","0.02222"
"156.81600","13.06814","0.02255"
"156.94800","13.07920","0.02263"
"157.08000","13.09020","0.02261"
"157.21200","13.10114","0.02206"
"157.34400","13.11220","0.02290"
"157.47600","13.12327","0.02273"
"157.60800","13.13421","0.02250"
"157.74000","13.14515","0.02147"
"157.87200","13.15615","0.02196"
"158.00400","13.16721","0.02188"
"158.13600","13.17821","0.02214"
"158.26800","13.18915","0.02170"
"158.40000","13.20015","0.02196"
"158.53200","13.21122","0.02272"
"158.66400","13.22222","0.02230"
"158.79600","13.23316","0.02231"
"158.92800","13.24422","0.02287"
"159.06000","13.25522","0.02258"
"159.19200","13.26622","0.02282"
"159.32400","13.27716","0.02250"
"159.45600","13.28816","0.02216"
"159.58800","13.29923","0.02244"
"159.72000","13.31017","0.02259"
"159.85200","13.32117","0.02263"
"159.98400","13.33211","0.02241"
"160.11600","13.34317","0.02241"
"160.24800","13.35423","0.02254"
"160.38000","13.36517","0.02158"
"160.51200","13.37611","0.02211"
"160.64400","13.38718","0.02250"
"160.77600","13.39818","0.02175"
"160.90800","13.40918","0.02150"
"161.04000","13.42012","0.02175"
"161.17200","13.43118","0.02179"
"161.30400","13.44224","0.02241"
"161.43600","13.45318","0.02238"
"161.56800","13.46412","0.02203"
"161.70000","13.47519","0.02240"
"161.83200","13.48619","0.02234"
"161.96400","13.49719","0.02219"
"162.09600","13.50819","0.02177"
"162.22800","13.51919","0.02196"
"162.36000","13.53019","0.02221"
"162.49200","13.54119","0.02208"
"162.62400","13.55214","0.02211"
"162.75600","13.56320","0.02207"
"162.88800","13.57420","0.02214"
"163.02000","13.58514","0.02242"
"163.15200","13.59614","0.02249"
"163.28400","13.60720","0.02216"
"163.41600","13.61820","0.02277"
"163.54800","13.62920","0.02303"
"163.68000","13.64021","0.02317"
"163.81200","13.65121","0.02272"
"163.94400","13.66227","0.02283"
"164.07600","13.67321","0.02321"
"164.20800","13.68415","0.02231"
"164.34000","13.69521","0.02226"
"164.47200","13.70621","0.02264"
"164.60400","13.71721","0.02197"
"164.73600","13.72816","0.02208"
"164.86800","13.73916","0.02162"
"165.00000","13.75022","0.02211"
"165.13200","13.76116","0.02162"
"165.26400","13.77216","0.02154"
"165.39600","13.78316","0.02192"
"165.52800","13.79422","0.02183"
"165.66000","13.80522","0.02183"
"165.79200","13.81623","0.02294"
"165.92400","13.82717","0.02266"
"166.05600","13.83823","0.02271"
"166.18800","13.84923","0.02194"
"166.32000","13.86017","0.02294"
"166.45200","13.87111","0.02306"
"166.58400","13.88223","0.02376"
"166.71600","13.89317","0.02411"
"166.84800","13.90418","0.02459"
"166.98000","13.91518","0.02529"
"167.11200","13.92618","0.02606"
"167.24400","13.93724","0.02545"
"167.37600","13.94812","0.02588"
"167.50800","13.95912","0.02665"
"167.64000","13.97018","0.02730"
"167.77200","13.98118","0.02733"
"167.90400","13.99213","0.02780"
"168.03600","14.00313","0.02827"
"168.16800","14.01419","0.02860"
"168.30000","14.02519","0.02937"
"168.43200","14.03619","0.02977"
"168.56400","14.04713","0.03039"
"168.69600","14.05813","0.02962"
"168.82800","14.06919","0.03071"
"168.96000","14.08020","0.03109"
"169.09200","14.09114","0.03108"
"169.22400","14.10220","0.03115"
"169.35600","14.11320","0.02980"
"169.48800","14.12420","0.03062"
"169.62000","14.13514","0.03218"
"169.75200","14.14620","0.03162"
"169.88400","14.15721","0.03210"
"170.01600","14.16821","0.03108"
"170.14800","14.17915","0.03196"
"170.28000","14.19015","0.03259"
"170.41200","14.20127","0.03384"
"170.54400","14.21227","0.03356"
"170.67600","14.22321","0.03368"
"170.80800","14.23421","0.03437"
"170.94000","14.24522","0.03583"
"171.07200","14.25616","0.03532"
"171.20400","14.26716","0.03477"
"171.33600","14.27816","0.03435"
"171.46800","14.28916","0.03496"
"171.60000","14.30016","0.03639"
"171.73200","14.31116","0.03681"
"171.86400","14.32216","0.03652"
"171.99600","14.33323","0.03759"
"172.12800","14.34423","0.03820"
"172.26000","14.35511","0.03927"
"172.39200","14.36617","0.03931"
"172.52400","14.37717","0.03829"
"172.65600","14.38823","0.03992"
"172.78800","14.39911","0.04026"
"172.92000","14.41012","0.04036"
"173.05200","14.42118","0.04003"
"173.18400","14.43218","0.03992"
"173.31600","14.44318","0.04055"
"173.44800","14.45418","0.04066"
"173.58000","14.46524","0.04051"
"173.71200","14.47618","0.04086"
"173.84400","14.48718","0.04204"
"173.97600","14.49813","0.04234"
"174.10800","14.50919","0.04275"
"174.24000","14.52025","0.04253"
"174.37200","14.53119","0.04244"
"174.50400","14.54213","0.04390"
"174.63600","14.55319","0.04416"
"174.76800","14.56419","0.04351"
"174.90000","14.57513","0.04389"
"175.03200","14.58614","0.04282"
"175.16400","14.59726","0.04330"
"175.29600","14.60826","0.04276"
"175.42800","14.61920","0.04260"
"175.56000","14.63020","0.04299"
"175.69200","14.64120","0.04335"
"175.82400","14.65220","0.04303"
"175.95600","14.66320","0.04302"
"176.08800","14.67415","0.04322"
"176.22000","14.68515","0.04410"
"176.35200","14.69621","0.04330"
"176.48400","14.70721","0.04266"
"176.61600","14.71815","0.04420"
"176.74800","14.72921","0.04429"
"176.88000","14.74021","0.04425"
"177.01200","14.75121","0.04480"
"177.14400","14.76216","0.04489"
"177.27600","14.77322","0.04587"
"177.40800","14.78416","0.04563"
"177.54000","14.79522","0.04559"
"177.67200","14.80616","0.04610"
"177.80400","14.81716","0.04601"
"177.93600","14.82816","0.04647"
"178.06800","14.83916","0.04653"
"178.20000","14.85011","0.04651"
"178.33200","14.86117","0.04667"
"178.46400","14.87223","0.04669"
"178.59600","14.88323","0.04721"
"178.72800","14.89417","0.04698"
"178.86000","14.90517","0.04710"
"178.99200","14.91623","0.04720"
"179.12400","14.92717","0.04746"
"179.25600","14.93818","0.04708"
"179.38800","14.94912","0.04711"
"179.52000","14.96018","0.04705"
"179.65200","14.97118","0.04698"
"179.78400","14.98212","0.04677"
"179.91600","14.99312","0.04705"
"180.04800","15.00424","0.04683"
"180.18000","15.01524","0.04684"
"180.31200","15.02619","0.04727"
"180.44400","15.03719","0.04695"
"180.57600","15.04819","0.04729"
"180.70800","15.05919","0.04772"
"180.84000","15.07013","0.04803"
"180.97200","15.08113","0.04759"
"181.10400","15.09219","0.04798"
"181.23600","15.10325","0.04837"
"181.36800","15.11420","0.04832"
"181.50000","15.12514","0.04839"
"181.63200","15.13620","0.04856"
"181.76400","15.14720","0.04805"
"181.89600","15.15820","0.04764"
"182.02800","15.16920","0.04769"
"182.16000","15.18026","0.04742"
"182.29200","15.19121","0.04563"
"182.42400","15.20215","0.04096"
"182.55600","15.21309","0.03751"
"182.68800","15.22421","0.03829"
"182.82000","15.23521","0.02911"
"182.95200","15.24615","0.02616"
"183.08400","15.25709","0.02765"
"183.21600","15.26821","0.02681"
"183.34800","15.27921","0.02709"
"183.48000","15.29022","0.02442"
"183.61200","15.30116","0.02565"
"183.74400","15.31222","0.02748"
"183.87600","15.32322","0.02604"
"184.00800","15.33416","0.02724"
"184.14000","15.34516","0.02627"
"184.27200","15.35616","0.02537"
"184.40400","15.36717","0.02710"
"184.53600","15.37817","0.02701"
"184.66800","15.38911","0.02671"
"184.80000","15.40017","0.02642"
"184.93200","15.41117","0.02669"
"185.06400","15.42223","0.02751"
"185.19600","15.43317","0.02889"
"185.32800","15.44417","0.02807"
"185.46000","15.45518","0.02847"
"185.59200","15.46618","0.02862"
"185.72400","15.47718","0.02868"
"185.85600","15.48812","0.02794"
"185.98800","15.49918","0.02766"
"186.12000","15.51018","0.02790"
"186.25200","15.52112","0.02827"
"186.38400","15.53218","0.02751"
"186.51600","15.54325","0.02831"
"186.64800","15.55425","0.02962"
"186.78000","15.56519","0.02929"
"186.91200","15.57619","0.02994"
"187.04400","15.58725","0.03028"
"187.17600","15.59819","0.03078"
"187.30800","15.60913","0.03101"
"187.44000","15.62013","0.03160"
"187.57200","15.63120","0.03070"
"187.70400","15.64220","0.02955"
"187.83600","15.65314","0.03082"
"187.96800","15.66414","0.03006"
"188.10000","15.67520","0.03174"
"188.23200","15.68626","0.03162"
"188.36400","15.69720","0.03224"
"188.49600","15.70820","0.03320"
"188.62800","15.71920","0.03401"
"188.76000","15.73021","0.03436"
"188.89200","15.74115","0.03538"
"189.02400","15.75215","0.03509"
"189.15600","15.76321","0.03617"
"189.28800","15.77427","0.03667"
"189.42000","15.78515","0.03674"
"189.55200","15.79615","0.03583"
"189.68400","15.80716","0.03568"
"189.81600","15.81822","0.03670"
"189.94800","15.82922","0.03682"
"190.08000","15.84016","0.03734"
"190.21200","15.85122","0.03756"
"190.34400","15.86222","0.03831"
"190.47600","15.87316","0.03861"
"190.60800","15.88410","0.03931"
"190.74000","15.89523","0.03901"
"190.87200","15.90617","0.03875"
"191.00400","15.91717","0.03927"
"191.13600","15.92811","0.03914"
"191.26800","15.93923","0.03837"
"191.40000","15.95017","0.03856"
"191.53200","15.96123","0.03964"
"191.66400","15.97217","0.03930"
"191.79600","15.98318","0.03991"
"191.92800","15.99424","0.03988"
"192.06000","16.00524","0.03964"
"192.19200","16.01618","0.04031"
"192.32400","16.02718","0.04071"
"192.45600","16.03818","0.04073"
"192.58800","16.04918","0.04161"
"192.72000","16.06019","0.04183"
"192.85200","16.07113","0.04183"
"192.98400","16.08219","0.04195"
"193.11600","16.09319","0.04246"
"193.24800","16.10413","0.04284"
"193.38000","16.11513","0.04294"
"193.51200","16.12619","0.04386"
"193.64400","16.13725","0.04347"
"193.77600","16.14814","0.04417"
"193.90800","16.15914","0.04403"
"194.04000","16.17020","0.04415"
"194.17200","16.18126","0.04392"
"194.30400","16.19220","0.04449"
"194.43600","16.20320","0.04450"
"194.56800","16.21426","0.04497"
"194.70000","16.22527","0.04491"
"194.83200","16.23621","0.04475"
"194.96400","16.24715","0.04496"
"195.09600","16.25821","0.04552"
"195.22800","16.26921","0.04508"
"195.36000","16.28015","0.04653"
"195.49200","16.29109","0.04604"
"195.62400","16.30221","0.04648"
"195.75600","16.31316","0.04630"
"195.88800","16.32416","0.04676"
"196.02000","16.33510","0.04678"
"196.15200","16.34622","0.04691"
"196.28400","16.35722","0.04750"
"196.41600","16.36822","0.04712"
"196.54800","16.37916","0.04766"
"196.68000","16.39022","0.04756"
"196.81200","16.40117","0.04783"
"196.94400","16.41217","0.04804"
"196.97600","16.41480","0.04797"