File: Force_trajectories/170225_1/Specimen_RawData_5.csv
End date,"2/25/2017"
Specimen label,"2AT_15"
Maximum Load,"0.21246",N

Time,Extension,Load
(s),(mm),(N)
"0.00000","0.00000","-0.00007"
"0.33600","0.02792","0.00042"
"0.67200","0.05626","0.00045"
"1.00800","0.08430","-0.00023"
"1.34400","0.11222","0.00044"
"1.68000","0.14021","0.00071"
"2.01600","0.16819","0.00108"
"2.35200","0.19617","0.00089"
"2.68800","0.22427","0.00040"
"3.02400","0.25219","0.00080"
"3.36000","0.28023","0.00094"
"3.69600","0.30827","0.00059"
"4.03200","0.33620","0.00098"
"4.36800","0.36424","0.00097"
"4.70400","0.39222","0.00089"
"5.04000","0.42020","0.00138"
"5.37600","0.44824","0.00092"
"5.71200","0.47616","0.00091"
"6.04800","0.50426","0.00104"
"6.38400","0.53219","0.00129"
"6.72000","0.56017","0.00121"
"7.05600","0.58827","0.00116"
"7.39200","0.61619","0.00063"
"7.72800","0.64423","0.00094"
"8.06400","0.67221","0.00133"
"8.40000","0.70014","0.00081"
"8.73600","0.72830","0.00065"
"9.07200","0.75622","0.00107"
"9.40800","0.78420","0.00103"
"9.74400","0.81224","0.00088"
"10.08000","0.84016","0.00091"
"10.41600","0.86820","0.00037"
"10.75200","0.89625","0.00105"
"11.08800","0.92417","0.00074"
"11.42400","0.95227","0.00026"
"11.76000","0.98025","0.00053"
"12.09600","1.00823","0.00130"
"12.43200","1.03621","0.00100"
"12.76800","1.06425","0.00070"
"13.10400","1.09224","0.00103"
"13.44000","1.12028","0.00130"
"13.77600","1.14814","0.00076"
"14.11200","1.17624","0.00088"
"14.44800","1.20422","0.00090"
"14.78400","1.23214","0.00051"
"15.12000","1.26030","0.00106"
"15.45600","1.28823","0.00045"
"15.79200","1.31621","0.00085"
"16.12800","1.34425","0.00065"
"16.46400","1.37217","0.00098"
"16.80000","1.40027","0.00078"
"17.13600","1.42819","0.00076"
"17.47200","1.45623","0.00063"
"17.80800","1.48422","0.00074"
"18.14400","1.51220","0.00123"
"18.48000","1.54024","0.00056"
"18.81600","1.56828","0.00101"
"19.15200","1.59614","0.00072"
"19.48800","1.62418","0.00111"
"19.82400","1.65222","0.00103"
"20.16000","1.68015","0.00146"
"20.49600","1.70825","0.00051"
"20.83200","1.73623","0.00110"
"21.16800","1.76421","0.00118"
"21.50400","1.79231","0.00134"
"21.84000","1.82011","0.00111"
"22.17600","1.84821","0.00102"
"22.51200","1.87626","0.00107"
"22.84800","1.90424","0.00091"
"23.18400","1.93228","0.00103"
"23.52000","1.96020","0.00069"
"23.85600","1.98818","0.00118"
"24.19200","2.01628","0.00066"
"24.52800","2.04420","0.00100"
"24.86400","2.07225","0.00131"
"25.20000","2.10023","0.00129"
"25.53600","2.12821","0.00130"
"25.87200","2.15619","0.00133"
"26.20800","2.18417","0.00193"
"26.54400","2.21227","0.00136"
"26.88000","2.24025","0.00153"
"27.21600","2.26818","0.00152"
"27.55200","2.29622","0.00119"
"27.88800","2.32420","0.00163"
"28.22400","2.35218","0.00133"
"28.56000","2.38022","0.00156"
"28.89600","2.40820","0.00123"
"29.23200","2.43624","0.00092"
"29.56800","2.46429","0.00095"
"29.90400","2.49215","0.00132"
"30.24000","2.52025","0.00169"
"30.57600","2.54823","0.00125"
"30.91200","2.57621","0.00117"
"31.24800","2.60425","0.00156"
"31.58400","2.63223","0.00153"
"31.92000","2.66022","0.00155"
"32.25600","2.68826","0.00204"
"32.59200","2.71618","0.00182"
"32.92800","2.74422","0.00193"
"33.26400","2.77226","0.00181"
"33.60000","2.80024","0.00200"
"33.93600","2.82816","0.00200"
"34.27200","2.85621","0.00187"
"34.60800","2.88425","0.00248"
"34.94400","2.91223","0.00198"
"35.28000","2.94021","0.00268"
"35.61600","2.96825","0.00217"
"35.95200","2.99623","0.00212"
"36.28800","3.02421","0.00240"
"36.62400","3.05220","0.00286"
"36.96000","3.08018","0.00291"
"37.29600","3.10822","0.00227"
"37.63200","3.13620","0.00228"
"37.96800","3.16418","0.00215"
"38.30400","3.19222","0.00218"
"38.64000","3.22020","0.00274"
"38.97600","3.24819","0.00214"
"39.31200","3.27629","0.00264"
"39.64800","3.30421","0.00261"
"39.98400","3.33219","0.00240"
"40.32000","3.36023","0.00212"
"40.65600","3.38821","0.00272"
"40.99200","3.41631","0.00292"
"41.32800","3.44424","0.00302"
"41.66400","3.47216","0.00292"
"42.00000","3.50026","0.00312"
"42.33600","3.52824","0.00258"
"42.67200","3.55622","0.00263"
"43.00800","3.58426","0.00310"
"43.34400","3.61218","0.00279"
"43.68000","3.64029","0.00372"
"44.01600","3.66821","0.00270"
"44.35200","3.69625","0.00367"
"44.68800","3.72417","0.00338"
"45.02400","3.75221","0.00322"
"45.36000","3.78019","0.00324"
"45.69600","3.80823","0.00333"
"46.03200","3.83622","0.00332"
"46.36800","3.86426","0.00317"
"46.70400","3.89224","0.00393"
"47.04000","3.92022","0.00337"
"47.37600","3.94826","0.00377"
"47.71200","3.97612","0.00377"
"48.04800","4.00422","0.00361"
"48.38400","4.03233","0.00398"
"48.72000","4.06019","0.00416"
"49.05600","4.08829","0.00373"
"49.39200","4.11615","0.00413"
"49.72800","4.14419","0.00426"
"50.06400","4.17229","0.00422"
"50.40000","4.20021","0.00519"
"50.73600","4.22820","0.00459"
"51.07200","4.25624","0.00407"
"51.40800","4.28422","0.00526"
"51.74400","4.31226","0.00532"
"52.08000","4.34024","0.00485"
"52.41600","4.36822","0.00524"
"52.75200","4.39620","0.00491"
"53.08800","4.42419","0.00524"
"53.42400","4.45223","0.00579"
"53.76000","4.48021","0.00610"
"54.09600","4.50825","0.00526"
"54.43200","4.53623","0.00605"
"54.76800","4.56421","0.00564"
"55.10400","4.59219","0.00608"
"55.44000","4.62024","0.00549"
"55.77600","4.64816","0.00594"
"56.11200","4.67626","0.00649"
"56.44800","4.70424","0.00648"
"56.78400","4.73222","0.00650"
"57.12000","4.76026","0.00691"
"57.45600","4.78819","0.00695"
"57.79200","4.81623","0.00686"
"58.12800","4.84421","0.00651"
"58.46400","4.87213","0.00779"
"58.80000","4.90023","0.00735"
"59.13600","4.92821","0.00720"
"59.47200","4.95619","0.00743"
"59.80800","4.98429","0.00782"
"60.14400","5.01222","0.00854"
"60.48000","5.04020","0.00825"
"60.81600","5.06824","0.00884"
"61.15200","5.09616","0.00818"
"61.48800","5.12420","0.00895"
"61.82400","5.15230","0.00897"
"62.16000","5.18017","0.00905"
"62.49600","5.20821","0.00930"
"62.83200","5.23625","0.00947"
"63.16800","5.26423","0.00949"
"63.50400","5.29221","0.00983"
"63.84000","5.32025","0.00988"
"64.17600","5.34817","0.01056"
"64.51200","5.37627","0.01068"
"64.84800","5.40420","0.01125"
"65.18400","5.43224","0.01061"
"65.52000","5.46022","0.01142"
"65.85600","5.48826","0.01184"
"66.19200","5.51624","0.01158"
"66.52800","5.54416","0.01168"
"66.86400","5.57227","0.01225"
"67.20000","5.60025","0.01241"
"67.53600","5.62817","0.01291"
"67.87200","5.65627","0.01287"
"68.20800","5.68419","0.01331"
"68.54400","5.71217","0.01326"
"68.88000","5.74021","0.01380"
"69.21600","5.76814","0.01368"
"69.55200","5.79624","0.01454"
"69.88800","5.82428","0.01488"
"70.22400","5.85220","0.01468"
"70.56000","5.88024","0.01519"
"70.89600","5.90816","0.01567"
"71.23200","5.93614","0.01566"
"71.56800","5.96425","0.01572"
"71.90400","5.99217","0.01600"
"72.24000","6.02027","0.01662"
"72.57600","6.04825","0.01705"
"72.91200","6.07617","0.01662"
"73.24800","6.10421","0.01779"
"73.58400","6.13225","0.01807"
"73.92000","6.16024","0.01773"
"74.25600","6.18822","0.01857"
"74.59200","6.21620","0.01884"
"74.92800","6.24424","0.01887"
"75.26400","6.27222","0.01931"
"75.60000","6.30020","0.01968"
"75.93600","6.32824","0.01970"
"76.27200","6.35623","0.01971"
"76.60800","6.38421","0.02035"
"76.94400","6.41219","0.02077"
"77.28000","6.44017","0.02188"
"77.61600","6.46827","0.02187"
"77.95200","6.49619","0.02187"
"78.28800","6.52423","0.02248"
"78.62400","6.55228","0.02279"
"78.96000","6.58020","0.02380"
"79.29600","6.60818","0.02415"
"79.63200","6.63628","0.02513"
"79.96800","6.66420","0.02536"
"80.30400","6.69224","0.02468"
"80.64000","6.72028","0.02550"
"80.97600","6.74815","0.02620"
"81.31200","6.77619","0.02630"
"81.64800","6.80423","0.02734"
"81.98400","6.83221","0.02801"
"82.32000","6.86025","0.02836"
"82.65600","6.88817","0.02909"
"82.99200","6.91621","0.02920"
"83.32800","6.94420","0.03089"
"83.66400","6.97218","0.03049"
"84.00000","7.00028","0.03205"
"84.33600","7.02820","0.03277"
"84.67200","7.05624","0.03357"
"85.00800","7.08422","0.03506"
"85.34400","7.11220","0.03517"
"85.68000","7.14025","0.03586"
"86.01600","7.16823","0.03637"
"86.35200","7.19621","0.03700"
"86.68800","7.22425","0.03789"
"87.02400","7.25217","0.03940"
"87.36000","7.28027","0.03902"
"87.69600","7.30825","0.04019"
"88.03200","7.33618","0.04104"
"88.36800","7.36428","0.04248"
"88.70400","7.39220","0.04293"
"89.04000","7.42018","0.04379"
"89.37600","7.44828","0.04433"
"89.71200","7.47620","0.04514"
"90.04800","7.50418","0.04537"
"90.38400","7.53229","0.04670"
"90.72000","7.56015","0.04710"
"91.05600","7.58825","0.04774"
"91.39200","7.61623","0.04815"
"91.72800","7.64421","0.04883"
"92.06400","7.67225","0.04922"
"92.40000","7.70023","0.04955"
"92.73600","7.72822","0.05040"
"93.07200","7.75626","0.05069"
"93.40800","7.78424","0.05087"
"93.74400","7.81222","0.05115"
"94.08000","7.84020","0.05176"
"94.41600","7.86818","0.05185"
"94.75200","7.89622","0.05244"
"95.08800","7.92421","0.05241"
"95.42400","7.95225","0.05267"
"95.76000","7.98023","0.05310"
"96.09600","8.00821","0.05314"
"96.43200","8.03625","0.05409"
"96.76800","8.06429","0.05384"
"97.10400","8.09221","0.05381"
"97.44000","8.12026","0.05423"
"97.77600","8.14818","0.05431"
"98.11200","8.17628","0.05473"
"98.44800","8.20426","0.05528"
"98.78400","8.23212","0.05517"
"99.12000","8.26022","0.05536"
"99.45600","8.28826","0.05555"
"99.79200","8.31619","0.05577"
"100.12800","8.34429","0.05606"
"100.46400","8.37215","0.05613"
"100.80000","8.40019","0.05657"
"101.13600","8.42823","0.05665"
"101.47200","8.45615","0.05701"
"101.80800","8.48425","0.05729"
"102.14400","8.51224","0.05742"
"102.48000","8.54016","0.05766"
"102.81600","8.56820","0.05789"
"103.15200","8.59624","0.05799"
"103.48800","8.62422","0.05842"
"103.82400","8.65220","0.05879"
"104.16000","8.68018","0.05886"
"104.49600","8.70829","0.05901"
"104.83200","8.73627","0.05984"
"105.16800","8.76419","0.06010"
"105.50400","8.79217","0.06015"
"105.84000","8.82015","0.06032"
"106.17600","8.84825","0.06046"
"106.51200","8.87623","0.06063"
"106.84800","8.90416","0.06129"
"107.18400","8.93226","0.06201"
"107.52000","8.96024","0.06254"
"107.85600","8.98822","0.06265"
"108.19200","9.01620","0.06333"
"108.52800","9.04418","0.06381"
"108.86400","9.07222","0.06432"
"109.20000","9.10033","0.06535"
"109.53600","9.12819","0.06569"
"109.87200","9.15623","0.06627"
"110.20800","9.18427","0.06706"
"110.54400","9.21219","0.06725"
"110.88000","9.24023","0.06875"
"111.21600","9.26822","0.06905"
"111.55200","9.29620","0.07032"
"111.88800","9.32424","0.07087"
"112.22400","9.35216","0.07128"
"112.56000","9.38020","0.07303"
"112.89600","9.40824","0.07305"
"113.23200","9.43622","0.07348"
"113.56800","9.46420","0.07434"
"113.90400","9.49225","0.07577"
"114.24000","9.52017","0.07566"
"114.57600","9.54821","0.07645"
"114.91200","9.57619","0.07710"
"115.24800","9.60417","0.07773"
"115.58400","9.63221","0.07823"
"115.92000","9.66019","0.07938"
"116.25600","9.68824","0.08013"
"116.59200","9.71616","0.08079"
"116.92800","9.74426","0.08129"
"117.26400","9.77230","0.08174"
"117.60000","9.80022","0.08247"
"117.93600","9.82826","0.08236"
"118.27200","9.85618","0.08261"
"118.60800","9.88417","0.08320"
"118.94400","9.91227","0.08393"
"119.28000","9.94013","0.08377"
"119.61600","9.96823","0.08401"
"119.95200","9.99621","0.08481"
"120.28800","10.02419","0.08446"
"120.62400","10.05223","0.08484"
"120.96000","10.08028","0.08509"
"121.29600","10.10820","0.08557"
"121.63200","10.13624","0.08554"
"121.96800","10.16422","0.08545"
"122.30400","10.19220","0.08604"
"122.64000","10.22024","0.08620"
"122.97600","10.24823","0.08720"
"123.31200","10.27627","0.08724"
"123.64800","10.30425","0.08777"
"123.98400","10.33223","0.08876"
"124.32000","10.36021","0.08953"
"124.65600","10.38819","0.09053"
"124.99200","10.41629","0.09126"
"125.32800","10.44427","0.09159"
"125.66400","10.47220","0.09286"
"126.00000","10.50024","0.09314"
"126.33600","10.52816","0.09391"
"126.67200","10.55620","0.09483"
"127.00800","10.58424","0.09477"
"127.34400","10.61222","0.09505"
"127.68000","10.64020","0.09566"
"128.01600","10.66825","0.09645"
"128.35200","10.69617","0.09723"
"128.68800","10.72427","0.09739"
"129.02400","10.75219","0.09805"
"129.36000","10.78023","0.09839"
"129.69600","10.80827","0.09928"
"130.03200","10.83613","0.09980"
"130.36800","10.86424","0.10047"
"130.70400","10.89228","0.10091"
"131.04000","10.92020","0.10057"
"131.37600","10.94824","0.10120"
"131.71200","10.97628","0.10146"
"132.04800","11.00420","0.10168"
"132.38400","11.03219","0.10188"
"132.72000","11.06017","0.10206"
"133.05600","11.08821","0.10256"
"133.39200","11.11625","0.10278"
"133.72800","11.14423","0.10297"
"134.06400","11.17227","0.10337"
"134.40000","11.20019","0.10376"
"134.73600","11.22824","0.10393"
"135.07200","11.25628","0.10438"
"135.40800","11.28414","0.10465"
"135.74400","11.31224","0.10444"
"136.08000","11.34022","0.10508"
"136.41600","11.36820","0.10514"
"136.75200","11.39624","0.10541"
"137.08800","11.42423","0.10554"
"137.42400","11.45221","0.10614"
"137.76000","11.48025","0.10698"
"138.09600","11.50817","0.10751"
"138.43200","11.53627","0.10826"
"138.76800","11.56419","0.10881"
"139.10400","11.59223","0.10938"
"139.44000","11.62022","0.11037"
"139.77600","11.64826","0.11197"
"140.11200","11.67618","0.11282"
"140.44800","11.70422","0.11276"
"140.78400","11.73220","0.11453"
"141.12000","11.76024","0.11487"
"141.45600","11.78828","0.11491"
"141.79200","11.81615","0.11572"
"142.12800","11.84425","0.11497"
"142.46400","11.87223","0.11392"
"142.80000","11.90027","0.11371"
"143.13600","11.92825","0.11465"
"143.47200","11.95617","0.11530"
"143.80800","11.98421","0.10993"
"144.14400","12.01225","0.08679"
"144.48000","12.04018","0.07859"
"144.81600","12.06822","0.07634"
"145.15200","12.09620","0.07635"
"145.48800","12.12424","0.07487"
"145.82400","12.15222","0.07457"
"146.16000","12.18014","0.07414"
"146.49600","12.20825","0.07421"
"146.83200","12.23623","0.07396"
"147.16800","12.26421","0.07225"
"147.50400","12.29231","0.07134"
"147.84000","12.32023","0.07161"
"148.17600","12.34815","0.07215"
"148.51200","12.37625","0.07316"
"148.84800","12.40423","0.07341"
"149.18400","12.43228","0.07163"
"149.52000","12.46026","0.07122"
"149.85600","12.48818","0.07238"
"150.19200","12.51622","0.07344"
"150.52800","12.54426","0.07511"
"150.86400","12.57224","0.07643"
"151.20000","12.60029","0.07719"
"151.53600","12.62815","0.07666"
"151.87200","12.65625","0.07738"
"152.20800","12.68423","0.07787"
"152.54400","12.71215","0.07866"
"152.88000","12.74025","0.07910"
"153.21600","12.76824","0.07876"
"153.55200","12.79622","0.07998"
"153.88800","12.82426","0.08108"
"154.22400","12.85218","0.08258"
"154.56000","12.88022","0.08385"
"154.89600","12.90820","0.08530"
"155.23200","12.93624","0.08682"
"155.56800","12.96422","0.08911"
"155.90400","12.99221","0.09071"
"156.24000","13.02019","0.09315"
"156.57600","13.04823","0.09462"
"156.91200","13.07615","0.09701"
"157.24800","13.10425","0.09936"
"157.58400","13.13223","0.10053"
"157.92000","13.16016","0.10135"
"158.25600","13.18826","0.10233"
"158.59200","13.21618","0.10292"
"158.92800","13.24422","0.10310"
"159.26400","13.27232","0.10348"
"159.60000","13.30012","0.10363"
"159.93600","13.32822","0.10341"
"160.27200","13.35627","0.10297"
"160.60800","13.38419","0.10264"
"160.94400","13.41223","0.10283"
"161.28000","13.44021","0.10312"
"161.61600","13.46825","0.10341"
"161.95200","13.49623","0.10394"
"162.28800","13.52421","0.10414"
"162.62400","13.55220","0.10411"
"162.96000","13.58018","0.10444"
"163.29600","13.60822","0.10476"
"163.63200","13.63626","0.10505"
"163.96800","13.66418","0.10540"
"164.30400","13.69222","0.10574"
"164.64000","13.72020","0.10630"
"164.97600","13.74819","0.10696"
"165.31200","13.77623","0.10668"
"165.64800","13.80421","0.10724"
"165.98400","13.83219","0.10717"
"166.32000","13.86029","0.10873"
"166.65600","13.88821","0.10913"
"166.99200","13.91625","0.11053"
"167.32800","13.94424","0.11056"
"167.66400","13.97210","0.11198"
"168.00000","14.00026","0.11382"
"168.33600","14.02824","0.11509"
"168.67200","14.05616","0.11689"
"169.00800","14.08426","0.11388"
"169.34400","14.11218","0.05805"
"169.68000","14.14022","0.04978"
"170.01600","14.16827","0.05564"
"170.35200","14.19613","0.06053"
"170.68800","14.22423","0.05327"
"171.02400","14.25221","0.05371"
"171.36000","14.28019","0.05545"
"171.69600","14.30823","0.05440"
"172.03200","14.33622","0.05822"
"172.36800","14.36420","0.05871"
"172.70400","14.39224","0.05921"
"173.04000","14.42016","0.06164"
"173.37600","14.44826","0.06018"
"173.71200","14.47624","0.06095"
"174.04800","14.50422","0.05935"
"174.38400","14.53220","0.06098"
"174.72000","14.56019","0.06154"
"175.05600","14.58829","0.06503"
"175.39200","14.61627","0.06738"
"175.72800","14.64419","0.06828"
"176.06400","14.67223","0.06694"
"176.40000","14.70027","0.06421"
"176.73600","14.72826","0.06688"
"177.07200","14.75624","0.07241"
"177.40800","14.78416","0.07215"
"177.74400","14.81226","0.07312"
"178.08000","14.84024","0.07024"
"178.41600","14.86816","0.07086"
"178.75200","14.89626","0.07156"
"179.08800","14.92424","0.07370"
"179.42400","14.95217","0.07788"
"179.76000","14.98027","0.07516"
"180.09600","15.00819","0.07393"
"180.43200","15.03623","0.07346"
"180.76800","15.06421","0.07491"
"181.10400","15.09219","0.07680"
"181.44000","15.12024","0.07300"
"181.77600","15.14822","0.07210"
"182.11200","15.17620","0.07093"
"182.44800","15.20424","0.07178"
"182.78400","15.23228","0.07570"
"183.12000","15.26020","0.07491"
"183.45600","15.28818","0.07705"
"183.79200","15.31617","0.07451"
"184.12800","15.34427","0.07497"
"184.46400","15.37225","0.07832"
"184.80000","15.40017","0.06488"
"185.13600","15.42821","0.06215"
"185.47200","15.45613","0.06128"
"185.80800","15.48429","0.06166"
"186.14400","15.51228","0.06262"
"186.48000","15.54020","0.06348"
"186.81600","15.56830","0.06449"
"187.15200","15.59622","0.06593"
"187.48800","15.62420","0.06792"
"187.82400","15.65224","0.06626"
"188.16000","15.68016","0.06626"
"188.49600","15.70820","0.06750"
"188.83200","15.73625","0.06747"
"189.16800","15.76417","0.06963"
"189.50400","15.79221","0.07039"
"189.84000","15.82019","0.07205"
"190.17600","15.84823","0.07044"
"190.51200","15.87621","0.07246"
"190.84800","15.90420","0.07482"
"191.18400","15.93218","0.07572"
"191.52000","15.96028","0.07865"
"191.85600","15.98826","0.07838"
"192.19200","16.01624","0.08002"
"192.52800","16.04422","0.08138"
"192.86400","16.07220","0.08164"
"193.20000","16.10019","0.08536"
"193.53600","16.12817","0.08482"
"193.87200","16.15627","0.08580"
"194.20800","16.18425","0.08718"
"194.54400","16.21217","0.08882"
"194.88000","16.24027","0.09316"
"195.21600","16.26819","0.09203"
"195.55200","16.29623","0.09271"
"195.88800","16.32422","0.09713"
"196.22400","16.35214","0.09791"
"196.56000","16.38030","0.09987"
"196.89600","16.40822","0.10022"
"197.23200","16.43620","0.10055"
"197.56800","16.46424","0.10272"
"197.90400","16.49223","0.10265"
"198.24000","16.52021","0.10313"
"198.57600","16.54825","0.10436"
"198.91200","16.57617","0.10403"
"199.24800","16.60421","0.10433"
"199.58400","16.63231","0.10566"
"199.92000","16.66023","0.10535"
"200.25600","16.68827","0.10601"
"200.59200","16.71626","0.10637"
"200.92800","16.74418","0.10671"
"201.26400","16.77222","0.10819"
"201.60000","16.80014","0.10897"
"201.93600","16.82818","0.10879"
"202.27200","16.85622","0.11201"
"202.60800","16.88415","0.11192"
"202.94400","16.91225","0.11340"
"203.28000","16.94017","0.11721"
"203.61600","16.96821","0.11687"
"203.95200","16.99619","0.11865"
"204.28800","17.02417","0.12382"
"204.62400","17.05227","0.12305"
"204.96000","17.08026","0.12528"
"205.29600","17.10818","0.12883"
"205.63200","17.13622","0.12821"
"205.96800","17.16420","0.12894"
"206.30400","17.19224","0.13241"
"206.64000","17.22028","0.13256"
"206.97600","17.24814","0.13313"
"207.31200","17.27625","0.13503"
"207.64800","17.30423","0.13555"
"207.98400","17.33221","0.13593"
"208.32000","17.36025","0.13787"
"208.65600","17.38817","0.13827"
"208.99200","17.41615","0.13907"
"209.32800","17.44425","0.13938"
"209.66400","17.47218","0.13927"
"210.00000","17.50022","0.13967"
"210.33600","17.52826","0.14103"
"210.67200","17.55618","0.14209"
"211.00800","17.58422","0.14227"
"211.34400","17.61226","0.14305"
"211.68000","17.64018","0.14444"
"212.01600","17.66822","0.14394"
"212.35200","17.69627","0.14305"
"212.68800","17.72425","0.14353"
"213.02400","17.75223","0.14417"
"213.36000","17.78015","0.14397"
"213.69600","17.80825","0.14449"
"214.03200","17.83617","0.14515"
"214.36800","17.86427","0.14569"
"214.70400","17.89220","0.14630"
"215.04000","17.92012","0.14735"
"215.37600","17.94828","0.14688"
"215.71200","17.97620","0.14716"
"216.04800","18.00418","0.14759"
"216.38400","18.03222","0.14770"
"216.72000","18.06021","0.14822"
"217.05600","18.08819","0.14865"
"217.39200","18.11623","0.14926"
"217.72800","18.14421","0.14927"
"218.06400","18.17225","0.14954"
"218.40000","18.20023","0.15016"
"218.73600","18.22821","0.15007"
"219.07200","18.25626","0.15032"
"219.40800","18.28424","0.15079"
"219.74400","18.31222","0.15134"
"220.08000","18.34026","0.15126"
"220.41600","18.36812","0.15194"
"220.75200","18.39622","0.15292"
"221.08800","18.42420","0.15316"
"221.42400","18.45219","0.15385"
"221.76000","18.48023","0.15484"
"222.09600","18.50821","0.15808"
"222.43200","18.53625","0.15714"
"222.76800","18.56423","0.15812"
"223.10400","18.59221","0.16047"
"223.44000","18.62025","0.16180"
"223.77600","18.64824","0.16136"
"224.11200","18.67622","0.16229"
"224.44800","18.70420","0.16545"
"224.78400","18.73218","0.16812"
"225.12000","18.76028","0.16838"
"225.45600","18.78826","0.17124"
"225.79200","18.81612","0.17431"
"226.12800","18.84423","0.17596"
"226.46400","18.87221","0.17658"
"226.80000","18.90013","0.18011"
"227.13600","18.92829","0.18482"
"227.47200","18.95615","0.18499"
"227.80800","18.98419","0.18606"
"228.14400","19.01224","0.18793"
"228.48000","19.04022","0.19274"
"228.81600","19.06820","0.19484"
"229.15200","19.09624","0.19535"
"229.48800","19.12422","0.19614"
"229.82400","19.15226","0.19941"
"230.16000","19.18024","0.20131"
"230.49600","19.20823","0.20186"
"230.83200","19.23627","0.20447"
"231.16800","19.26419","0.20565"
"231.50400","19.29223","0.16198"
"231.84000","19.32027","0.15674"
"232.17600","19.34825","0.15461"
"232.51200","19.37623","0.15568"
"232.84800","19.40421","0.15677"
"233.18400","19.43220","0.15748"
"233.52000","19.46024","0.15925"
"233.85600","19.48816","0.16151"
"234.19200","19.51620","0.16302"
"234.52800","19.54424","0.16400"
"234.86400","19.57222","0.16589"
"235.20000","19.60026","0.16709"
"235.53600","19.62818","0.16865"
"235.87200","19.65623","0.16977"
"236.20800","19.68427","0.17241"
"236.54400","19.71213","0.17353"
"236.88000","19.74029","0.17237"
"237.21600","19.76827","0.17403"
"237.55200","19.79619","0.17688"
"237.88800","19.82424","0.17740"
"238.22400","19.85222","0.17746"
"238.56000","19.88020","0.17501"
"238.89600","19.90824","0.17164"
"239.23200","19.93616","0.16096"
"239.56800","19.96426","0.16196"
"239.90400","19.99224","0.16280"
"240.24000","20.02022","0.16511"
"240.57600","20.04821","0.16450"
"240.91200","20.07619","0.16159"
"241.24800","20.10423","0.15841"
"241.58400","20.13221","0.16025"
"241.92000","20.16014","0.16094"
"242.25600","20.18823","0.16321"
"242.59200","20.21622","0.16715"
"242.92800","20.24426","0.16833"
"243.26400","20.27224","0.16331"
"243.60000","20.30022","0.15512"
"243.93600","20.32820","0.15533"
"244.27200","20.35624","0.15587"
"244.60800","20.38416","0.15634"
"244.94400","20.41226","0.15846"
"245.28000","20.44025","0.16000"
"245.61600","20.46817","0.16134"
"245.95200","20.49627","0.16461"
"246.28800","20.52413","0.16698"
"246.62400","20.55223","0.16869"
"246.96000","20.58022","0.17059"
"247.29600","20.60814","0.17419"
"247.63200","20.63630","0.17792"
"247.96800","20.66428","0.18075"
"248.30400","20.69220","0.18473"
"248.64000","20.72024","0.18969"
"248.97600","20.74817","0.19379"
"249.31200","20.77626","0.19600"
"249.64800","20.80430","0.19943"
"249.98400","20.83223","0.20148"
"250.32000","20.86021","0.20389"
"250.65600","20.88825","0.20451"
"250.99200","20.91623","0.20536"
"251.32800","20.94421","0.20653"
"251.66400","20.97219","0.20645"
"252.00000","21.00018","0.20473"
"252.33600","21.02822","0.20170"
"252.67200","21.05620","0.20076"
"253.00800","21.08424","0.19958"
"253.34400","21.11228","0.16827"
"253.68000","21.14021","0.17040"
"254.01600","21.16825","0.17500"
"254.35200","21.19617","0.17902"
"254.68800","21.22421","0.17973"
"255.02400","21.25231","0.18426"
"255.36000","21.28017","0.19146"
"255.69600","21.30827","0.19520"
"256.03200","21.33619","0.19850"
"256.36800","21.36423","0.20280"
"256.70400","21.39222","0.20610"
"257.04000","21.42026","0.20841"
"257.37600","21.44824","0.20928"
"257.71200","21.47622","0.21024"
"258.04800","21.50414","0.21137"
"258.38400","21.53225","0.21208"
"258.72000","21.56017","0.21195"
"259.05600","21.58821","0.20522"
"259.39200","21.61625","0.20649"
"259.72800","21.64423","0.19025"
"260.06400","21.67215","0.19116"
"260.40000","21.70025","0.19391"
"260.73600","21.72817","0.19830"
"261.07200","21.75628","0.19876"
"261.40800","21.78426","0.19458"
"261.74400","21.81218","0.17901"
"262.08000","21.84022","0.15782"
"262.41600","21.86820","0.15716"
"262.75200","21.89624","0.15223"
"263.08800","21.92422","0.15104"
"263.42400","21.95221","0.15129"
"263.76000","21.98025","0.15146"
"264.09600","22.00817","0.14283"
"264.43200","22.03621","0.14219"
"264.76800","22.06425","0.14258"
"265.10400","22.09211","0.14215"
"265.44000","22.12027","0.14320"
"265.77600","22.14825","0.14273"
"266.11200","22.17624","0.14353"
"266.44800","22.20422","0.14465"
"266.78400","22.23220","0.14511"
"267.12000","22.26024","0.14555"
"267.45600","22.28822","0.14672"
"267.79200","22.31620","0.14749"
"268.12800","22.34419","0.14788"
"268.46400","22.37229","0.14851"
"268.80000","22.40015","0.14875"
"269.13600","22.42825","0.14907"
"269.47200","22.45623","0.14923"
"269.80800","22.48421","0.14949"
"270.14400","22.51225","0.14970"
"270.48000","22.54023","0.15012"
"270.81600","22.56822","0.15015"
"271.15200","22.59620","0.15004"
"271.48800","22.62418","0.15027"
"271.82400","22.65222","0.15022"
"272.16000","22.68020","0.14978"
"272.49600","22.70824","0.15005"
"272.83200","22.73623","0.15050"
"273.16800","22.76421","0.15059"
"273.50400","22.79225","0.15058"
"273.84000","22.82023","0.15078"
"274.17600","22.84821","0.15100"
"274.51200","22.87625","0.15127"
"274.84800","22.90423","0.15110"
"275.18400","22.93222","0.15099"
"275.52000","22.96026","0.15096"
"275.85600","22.98818","0.15081"
"276.19200","23.01622","0.15081"
"276.52800","23.04420","0.14821"
"276.86400","23.07218","0.14848"
"277.20000","23.10023","0.14892"
"277.53600","23.12821","0.14956"
"277.87200","23.15619","0.14979"
"278.20800","23.18423","0.15014"
"278.54400","23.21221","0.15062"
"278.88000","23.24025","0.15080"
"279.21600","23.26829","0.15138"
"279.55200","23.29616","0.15167"
"279.88800","23.32420","0.15250"
"280.22400","23.35224","0.15173"
"280.56000","23.38022","0.15080"
"280.89600","23.40826","0.14887"
"281.23200","23.43618","0.14799"
"281.56800","23.46422","0.14753"
"281.90400","23.49220","0.14786"
"282.24000","23.52019","0.14821"
"282.57600","23.54829","0.14840"
"282.91200","23.57621","0.14839"
"283.24800","23.60425","0.14384"
"283.58400","23.63223","0.14271"
"283.92000","23.66015","0.08333"
"284.25600","23.68826","0.07749"
"284.59200","23.71624","0.07668"
"284.92800","23.74422","0.07692"
"285.26400","23.77220","0.08301"
"285.60000","23.80018","0.08003"
"285.93600","23.82816","0.08083"
"286.27200","23.85626","0.08563"
"286.60800","23.88418","0.08358"
"286.94400","23.91223","0.08615"
"287.28000","23.94027","0.08922"
"287.61600","23.96819","0.08843"
"287.95200","23.99623","0.09038"
"288.28800","24.02427","0.09460"
"288.62400","24.05219","0.09376"
"288.96000","24.08030","0.09570"
"289.29600","24.10816","0.09907"
"289.63200","24.13620","0.09875"
"289.96800","24.16424","0.10000"
"290.30400","24.19216","0.10110"
"290.64000","24.22026","0.10202"
"290.97600","24.24824","0.10213"
"291.31200","24.27622","0.10266"
"291.64800","24.30420","0.10362"
"291.98400","24.33219","0.10386"
"292.32000","24.36023","0.10426"
"292.65600","24.38827","0.10506"
"292.99200","24.41619","0.10571"
"293.32800","24.44423","0.10593"
"293.66400","24.47216","0.10707"
"294.00000","24.50026","0.10796"
"294.33600","24.52824","0.10993"
"294.67200","24.55616","0.11011"
"295.00800","24.58426","0.11140"
"295.34400","24.61218","0.11280"
"295.68000","24.64017","0.11452"
"296.01600","24.66826","0.11571"
"296.35200","24.69619","0.11797"
"296.68800","24.72417","0.11911"
"297.02400","24.75227","0.12159"
"297.36000","24.78019","0.12231"
"297.69600","24.80823","0.12406"
"298.03200","24.83621","0.12519"
"298.36800","24.86419","0.12711"
"298.70400","24.89224","0.12846"
"299.04000","24.92022","0.12950"
"299.37600","24.94820","0.13040"
"299.71200","24.97624","0.13187"
"300.04800","25.00422","0.13304"
"300.38400","25.03226","0.13399"
"300.72000","25.06024","0.13507"
"301.05600","25.08817","0.13612"
"301.39200","25.11621","0.13660"
"301.72800","25.14419","0.13750"
"302.06400","25.17223","0.13769"
"302.40000","25.20027","0.13896"
"302.73600","25.22820","0.13997"
"303.07200","25.25624","0.13995"
"303.40800","25.28416","0.14076"
"303.74400","25.31220","0.14171"
"304.08000","25.34024","0.14200"
"304.41600","25.36822","0.14268"
"304.75200","25.39626","0.14336"
"305.08800","25.42424","0.14397"
"305.42400","25.45217","0.14447"
"305.76000","25.48021","0.14475"
"306.09600","25.50825","0.14527"
"306.43200","25.53617","0.14547"
"306.76800","25.56427","0.14629"
"307.10400","25.59219","0.14648"
"307.44000","25.62017","0.14727"
"307.77600","25.64827","0.14767"
"308.11200","25.67614","0.14802"
"308.44800","25.70424","0.14841"
"308.78400","25.73222","0.14854"
"309.12000","25.76020","0.14882"
"309.45600","25.78818","0.14906"
"309.79200","25.81616","0.14940"
"310.12800","25.84427","0.14956"
"310.46400","25.87225","0.14993"
"310.80000","25.90023","0.14990"
"311.13600","25.92827","0.15003"
"311.47200","25.95619","0.15038"
"311.80800","25.98417","0.15050"
"312.14400","26.01221","0.15075"
"312.48000","26.04020","0.15135"
"312.81600","26.06824","0.15174"
"313.15200","26.09628","0.15234"
"313.48800","26.12420","0.15280"
"313.82400","26.15224","0.15300"
"314.16000","26.18028","0.15379"
"314.49600","26.20820","0.15432"
"314.83200","26.23624","0.15527"
"315.16800","26.26417","0.15645"
"315.50400","26.29221","0.15722"
"315.84000","26.32025","0.15802"
"316.17600","26.34811","0.15919"
"316.51200","26.37627","0.16042"
"316.84800","26.40419","0.16188"
"317.18400","26.43224","0.16355"
"317.52000","26.46021","0.16473"
"317.85600","26.48820","0.16635"
"318.19200","26.51618","0.16779"
"318.52800","26.54428","0.16958"
"318.86400","26.57214","0.17153"
"319.20000","26.60024","0.17280"
"319.53600","26.62823","0.17431"
"319.87200","26.65621","0.17595"
"320.20800","26.68419","0.17699"
"320.54400","26.71223","0.17943"
"320.88000","26.74021","0.18129"
"321.21600","26.76819","0.18168"
"321.55200","26.79617","0.18266"
"321.88800","26.82428","0.18526"
"322.22400","26.85225","0.18642"
"322.56000","26.88018","0.18874"
"322.89600","26.90822","0.19117"
"323.23200","26.93620","0.19180"
"323.56800","26.96424","0.19265"
"323.90400","26.99228","0.19418"
"324.24000","27.02020","0.19632"
"324.57600","27.04825","0.19821"
"324.91200","27.07617","0.19994"
"325.24800","27.10415","0.20044"
"325.58400","27.13225","0.20171"
"325.92000","27.16017","0.20297"
"326.25600","27.18827","0.20341"
"326.59200","27.21626","0.20527"
"326.92800","27.24424","0.20518"
"327.26400","27.27222","0.20627"
"327.60000","27.30026","0.20702"
"327.93600","27.32818","0.20780"
"328.27200","27.35622","0.20834"
"328.60800","27.38420","0.20823"
"328.94400","27.41219","0.20789"
"329.28000","27.44023","0.20841"
"329.61600","27.46821","0.20881"
"329.95200","27.49625","0.20938"
"330.28800","27.52423","0.20953"
"330.62400","27.55221","0.21019"
"330.96000","27.58020","0.21022"
"331.29600","27.60818","0.14587"
"331.63200","27.63622","0.02154"
"331.96800","27.66426","0.01272"
"332.30400","27.69218","0.00882"
"332.64000","27.72028","0.01376"
"332.97600","27.74821","0.00729"
"333.31200","27.77618","0.00817"
"333.64800","27.80423","0.01142"
"333.98400","27.83215","0.00819"
"334.32000","27.86025","0.00910"
"334.65600","27.88829","0.01049"
"334.99200","27.91621","0.00705"
"335.32800","27.94425","0.01193"
"335.66400","27.97224","0.00859"
"336.00000","28.00022","0.00928"
"336.33600","28.02826","0.01127"
"336.67200","28.05618","0.00898"
"337.00800","28.08422","0.01159"
"337.34400","28.11226","0.01193"
"337.68000","28.14018","0.01060"
"338.01600","28.16822","0.01177"
"338.35200","28.19621","0.01036"
"338.68800","28.22419","0.01282"
"339.02400","28.25223","0.01227"
"339.36000","28.28021","0.01164"
"339.69600","28.30819","0.01165"
"340.03200","28.33624","0.01184"
"340.36800","28.36421","0.01386"
"340.70400","28.39226","0.01286"
"341.04000","28.42018","0.01299"
"341.37600","28.44822","0.01349"
"341.71200","28.47620","0.01369"
"342.04800","28.50418","0.01451"
"342.38400","28.53222","0.01308"
"342.72000","28.56026","0.01280"
"343.05600","28.58818","0.01354"
"343.39200","28.61629","0.01412"
"343.72800","28.64421","0.01329"
"344.06400","28.67219","0.01342"
"344.40000","28.70023","0.01452"
"344.73600","28.72821","0.01467"
"345.07200","28.75625","0.01368"
"345.40800","28.78424","0.01340"
"345.74400","28.81222","0.01494"
"346.08000","28.84026","0.01529"
"346.41600","28.86818","0.01483"
"346.75200","28.89616","0.01437"
"347.08800","28.92420","0.01453"
"347.42400","28.95225","0.01512"
"347.76000","28.98022","0.01508"
"348.09600","29.00827","0.01447"
"348.43200","29.03619","0.01525"
"348.76800","29.06423","0.01526"
"349.10400","29.09221","0.01456"
"349.44000","29.12019","0.01478"
"349.77600","29.14824","0.01374"
"350.11200","29.17622","0.01408"
"350.44800","29.20426","0.01354"
"350.78400","29.23218","0.01373"
"351.12000","29.26016","0.01371"
"351.45600","29.28826","0.01431"
"351.79200","29.31618","0.01499"
"352.12800","29.34422","0.01374"
"352.46400","29.37221","0.01432"
"352.80000","29.40013","0.01425"
"353.13600","29.42829","0.01454"
"353.47200","29.45627","0.01473"
"353.80800","29.48419","0.01396"
"354.14400","29.51223","0.01380"
"354.48000","29.54016","0.01398"
"354.81600","29.56820","0.01316"
"355.15200","29.59624","0.01399"
"355.48800","29.62422","0.01379"
"355.82400","29.65226","0.01376"
"356.16000","29.68024","0.01327"
"356.49600","29.70817","0.01356"
"356.83200","29.73621","0.01348"
"357.16800","29.76419","0.01408"
"357.50400","29.79223","0.01433"
"357.84000","29.82027","0.01436"
"358.17600","29.84813","0.01374"
"358.51200","29.87623","0.01352"
"358.84800","29.90421","0.01321"
"359.18400","29.93220","0.01320"
"359.52000","29.96024","0.01357"
"359.85600","29.98822","0.01385"
"360.19200","30.01620","0.01434"
"360.52800","30.04418","0.01379"
"360.86400","30.07222","0.01390"
"361.20000","30.10021","0.01376"
"361.53600","30.12825","0.01465"
"361.87200","30.15623","0.01432"
"362.20800","30.18421","0.01417"
"362.54400","30.21219","0.01427"
"362.88000","30.24023","0.01439"
"363.21600","30.26827","0.01425"
"363.55200","30.29613","0.01454"
"363.88800","30.32424","0.01442"
"364.22400","30.35222","0.01457"
"364.56000","30.38020","0.01513"
"364.89600","30.40824","0.01460"
"365.23200","30.43622","0.01539"
"365.56800","30.46420","0.01518"
"365.90400","30.49230","0.01560"
"366.24000","30.52011","0.01527"
"366.57600","30.54821","0.01567"
"366.91200","30.57625","0.01549"
"367.24800","30.60417","0.01519"
"367.58400","30.63227","0.01513"
"367.92000","30.66019","0.01528"
"368.25600","30.68818","0.01533"
"368.59200","30.71622","0.01564"
"368.92800","30.74426","0.01468"
"369.26400","30.77224","0.01547"
"369.60000","30.80022","0.01531"
"369.93600","30.82814","0.01538"
"370.27200","30.85625","0.01464"
"370.60800","30.88422","0.01467"
"370.94400","30.91227","0.01496"
"371.28000","30.94025","0.01469"
"371.61600","30.96823","0.01595"
"371.95200","30.99621","0.01543"
"372.28800","31.02419","0.01591"
"372.62400","31.05223","0.01620"
"372.96000","31.08027","0.01637"
"373.29600","31.10819","0.01601"
"373.63200","31.13624","0.01638"
"373.96800","31.16422","0.01645"
"374.30400","31.19214","0.01642"
"374.64000","31.22024","0.01602"
"374.97600","31.24822","0.01632"
"375.31200","31.27620","0.01633"
"375.64800","31.30424","0.01686"
"375.98400","31.33222","0.01648"
"376.32000","31.36021","0.01690"
"376.65600","31.38825","0.01633"
"376.99200","31.41617","0.01686"
"377.32800","31.44421","0.01716"
"377.66400","31.47225","0.01707"
"378.00000","31.50023","0.01739"
"378.33600","31.52822","0.01770"
"378.67200","31.55620","0.01747"
"379.00800","31.58418","0.01760"
"379.34400","31.61222","0.01808"
"379.68000","31.64020","0.01734"
"380.01600","31.66824","0.01719"
"380.35200","31.69622","0.01726"
"380.68800","31.72421","0.01778"
"381.02400","31.75225","0.01755"
"381.36000","31.78023","0.01778"
"381.69600","31.80821","0.01706"
"382.03200","31.83625","0.01762"
"382.36800","31.86417","0.01747"
"382.70400","31.89221","0.01719"
"383.04000","31.92025","0.01798"
"383.37600","31.94824","0.01789"
"383.71200","31.97628","0.01801"
"384.04800","32.00420","0.01849"
"384.38400","32.03224","0.01843"
"384.72000","32.06023","0.01897"
"385.05600","32.08815","0.01878"
"385.39200","32.11631","0.01847"
"385.72800","32.14423","0.01874"
"386.06400","32.17221","0.01809"
"386.40000","32.20025","0.01683"
"386.73600","32.22817","0.01719"
"387.07200","32.25621","0.01694"
"387.40800","32.28426","0.01662"
"387.74400","32.31218","0.01646"
"388.08000","32.34022","0.01628"
"388.41600","32.36826","0.01604"
"388.75200","32.39618","0.01568"
"389.08800","32.42416","0.01590"
"389.42400","32.45220","0.01573"
"389.76000","32.48018","0.01590"
"390.09600","32.50823","0.01534"
"390.43200","32.53621","0.01553"
"390.76800","32.56425","0.01554"
"391.10400","32.59223","0.01553"
"391.44000","32.62021","0.01550"
"391.77600","32.64825","0.01491"
"392.11200","32.67617","0.01536"
"392.44800","32.70427","0.01530"
"392.78400","32.73225","0.01559"
"393.12000","32.76018","0.01623"
"393.45600","32.78822","0.01604"
"393.79200","32.81620","0.01678"
"394.12800","32.84418","0.01651"
"394.46400","32.87228","0.01650"
"394.80000","32.90021","0.01629"
"395.13600","32.92819","0.01632"
"395.47200","32.95623","0.01589"
"395.80800","32.98415","0.01625"
"396.14400","33.01225","0.01592"
"396.48000","33.04023","0.01602"
"396.81600","33.06821","0.01572"
"397.15200","33.09626","0.01632"
"397.48800","33.12418","0.01627"
"397.82400","33.15216","0.01645"
"398.16000","33.18026","0.01632"
"398.49600","33.20824","0.01626"
"398.83200","33.23623","0.01628"
"399.16800","33.26421","0.01571"
"399.50400","33.29219","0.01610"
"399.84000","33.32017","0.01623"
"400.17600","33.34821","0.01729"
"400.51200","33.37625","0.01722"
"400.84800","33.40423","0.01711"
"401.18400","33.43216","0.01686"
"401.52000","33.46025","0.01732"
"401.85600","33.48818","0.01752"
"402.19200","33.51616","0.01797"
"402.52800","33.54426","0.01755"
"402.86400","33.57218","0.01794"
"403.20000","33.60022","0.01788"
"403.53600","33.62826","0.01852"
"403.87200","33.65612","0.01845"
"404.20800","33.68429","0.01850"
"404.54400","33.71221","0.01875"
"404.88000","33.74019","0.01895"
"405.21600","33.76829","0.01895"
"405.55200","33.79615","0.01756"
"405.88800","33.82420","0.01766"
"406.22400","33.85229","0.01682"
"406.56000","33.88021","0.01722"
"406.89600","33.90820","0.01718"
"407.23200","33.93618","0.01732"
"407.56800","33.96416","0.01676"
"407.90400","33.99220","0.01698"
"408.24000","34.02019","0.01632"
"408.57600","34.04823","0.01680"
"408.91200","34.07627","0.01652"
"409.24800","34.10419","0.01649"
"409.58400","34.13223","0.01704"
"409.92000","34.16021","0.01717"
"410.25600","34.18819","0.01781"
"410.59200","34.21623","0.01794"
"410.92800","34.24416","0.01751"
"411.26400","34.27226","0.01769"
"411.60000","34.30024","0.01752"
"411.93600","34.32816","0.01765"
"412.27200","34.35626","0.01783"
"412.60800","34.38418","0.01764"
"412.94400","34.41222","0.01776"
"413.28000","34.44020","0.01796"
"413.61600","34.46812","0.01751"
"413.95200","34.49623","0.01790"
"414.28800","34.52427","0.01841"
"414.62400","34.55225","0.01800"
"414.96000","34.58023","0.01641"
"415.29600","34.60815","0.01684"
"415.63200","34.63620","0.01585"
"415.96800","34.66423","0.01643"
"416.30400","34.69216","0.01683"
"416.64000","34.72020","0.01641"
"416.97600","34.74824","0.01650"
"417.31200","34.77610","0.01655"
"417.64800","34.80426","0.01683"
"417.98400","34.83224","0.01708"
"418.32000","34.86023","0.01719"
"418.65600","34.88821","0.01661"
"418.99200","34.91625","0.01683"
"419.32800","34.94423","0.01702"
"419.66400","34.97221","0.01650"
"420.00000","35.00019","0.01664"
"420.33600","35.02823","0.01639"
"420.67200","35.05622","0.01695"
"421.00800","35.08426","0.01682"
"421.34400","35.11218","0.01727"
"421.68000","35.14016","0.01795"
"422.01600","35.16826","0.01704"
"422.35200","35.19630","0.01750"
"422.68800","35.22422","0.01713"
"423.02400","35.25227","0.01778"
"423.36000","35.28019","0.01834"
"423.69600","35.30817","0.01832"
"424.03200","35.33627","0.01863"
"424.36800","35.36419","0.01876"
"424.70400","35.39223","0.01954"
"425.04000","35.42028","0.01876"
"425.37600","35.44820","0.01880"
"425.71200","35.47624","0.01891"
"426.04800","35.50422","0.01866"
"426.38400","35.53220","0.01893"
"426.72000","35.56030","0.01923"
"427.05600","35.58817","0.01882"
"427.39200","35.61627","0.01945"
"427.72800","35.64419","0.01920"
"428.06400","35.67217","0.02022"
"428.40000","35.70021","0.01947"
"428.73600","35.72825","0.01943"
"429.07200","35.75618","0.01878"
"429.40800","35.78421","0.01917"
"429.74400","35.81219","0.01933"
"430.08000","35.84024","0.01954"
"430.41600","35.86822","0.01910"
"430.75200","35.89626","0.02016"
"431.08800","35.92424","0.02038"
"431.42400","35.95222","0.01950"
"431.76000","35.98027","0.02052"
"432.09600","36.00825","0.02008"
"432.43200","36.03617","0.02013"
"432.76800","36.06421","0.01968"
"433.10400","36.09225","0.01930"
"433.44000","36.12011","0.01870"
"433.77600","36.14821","0.01845"
"434.11200","36.17619","0.01854"
"434.44800","36.20418","0.01873"
"434.78400","36.23228","0.01882"
"435.12000","36.26026","0.01959"
"435.45600","36.28824","0.01964"
"435.79200","36.31628","0.01986"
"436.12800","36.34420","0.01943"
"436.46400","36.37225","0.01982"
"436.80000","36.40023","0.01973"
"437.13600","36.42821","0.02061"
"437.47200","36.45625","0.02017"
"437.80800","36.48417","0.02038"
"438.14400","36.51227","0.02092"
"438.48000","36.54020","0.02067"
"438.81600","36.56818","0.02090"
"439.15200","36.59622","0.02066"
"439.48800","36.62420","0.02149"
"439.82400","36.65224","0.02154"
"440.16000","36.68022","0.02236"
"440.49600","36.70814","0.02185"
"440.83200","36.73624","0.02145"
"441.16800","36.76423","0.02150"
"441.50400","36.79221","0.02109"
"441.84000","36.82025","0.02006"
"442.17600","36.84823","0.01902"
"442.51200","36.87627","0.01894"
"442.84800","36.90425","0.01962"
"443.18400","36.93211","0.01932"
"443.52000","36.96027","0.01883"
"443.85600","36.98826","0.01897"
"444.19200","37.01618","0.01871"
"444.52800","37.04428","0.01959"
"444.86400","37.07220","0.01897"
"445.20000","37.10018","0.01942"
"445.53600","37.12828","0.01963"
"445.87200","37.15620","0.01989"
"446.20800","37.18425","0.02043"
"446.54400","37.21223","0.01956"
"446.88000","37.24021","0.01938"
"447.21600","37.26819","0.01947"
"447.55200","37.29623","0.02003"
"447.88800","37.32427","0.01916"
"448.22400","37.35220","0.01898"
"448.56000","37.38018","0.01786"
"448.89600","37.40822","0.01804"
"449.23200","37.43620","0.01858"
"449.56800","37.46418","0.01872"
"449.90400","37.49222","0.01861"
"450.24000","37.52020","0.01864"
"450.57600","37.54818","0.01906"
"450.91200","37.57629","0.01963"
"451.24800","37.60415","0.01970"
"451.58400","37.63219","0.02010"
"451.92000","37.66023","0.01868"
"452.25600","37.68821","0.02029"
"452.59200","37.71626","0.01863"
"452.92800","37.74417","0.01973"
"453.26400","37.77222","0.01968"
"453.60000","37.80026","0.01940"
"453.93600","37.82812","0.01998"
"454.27200","37.85628","0.01864"
"454.60800","37.88420","0.01912"
"454.94400","37.91219","0.01979"
"455.28000","37.94028","0.01949"
"455.61600","37.96821","0.02025"
"455.95200","37.99625","0.01722"
"456.28800","38.02423","0.01862"
"456.62400","38.05215","0.01654"
"456.96000","38.08019","0.01892"
"457.29600","38.10823","0.01844"
"457.63200","38.13622","0.01884"
"457.96800","38.16426","0.01935"
"458.30400","38.19218","0.01872"
"458.64000","38.22016","0.01960"
"458.97600","38.24820","0.01685"
"459.31200","38.27618","0.01676"
"459.64800","38.30428","0.01645"
"459.98400","38.33226","0.01526"
"460.32000","38.36019","0.01512"
"460.65600","38.38823","0.01503"
"460.99200","38.41621","0.01612"
"461.32800","38.44425","0.01508"
"461.66400","38.47223","0.01517"
"462.00000","38.50016","0.01521"
"462.33600","38.52826","0.01563"
"462.67200","38.55624","0.01550"
"463.00800","38.58416","0.01555"
"463.34400","38.61220","0.01563"
"463.68000","38.64024","0.01557"
"464.01600","38.66822","0.01612"
"464.35200","38.69621","0.01542"
"464.68800","38.72413","0.01610"
"465.02400","38.75223","0.01648"
"465.36000","38.78021","0.01573"
"465.69600","38.80819","0.01627"
"466.03200","38.83624","0.01631"
"466.36800","38.86422","0.01731"
"466.70400","38.89214","0.01691"
"467.04000","38.92023","0.01744"
"467.37600","38.94822","0.01715"
"467.71200","38.97626","0.01733"
"468.04800","39.00424","0.01663"
"468.38400","39.03216","0.01621"
"468.72000","39.06020","0.01577"
"469.05600","39.08818","0.01581"
"469.39200","39.11622","0.01537"
"469.72800","39.14427","0.01583"
"470.06400","39.17219","0.01522"
"470.40000","39.20029","0.01575"
"470.73600","39.22821","0.01549"
"471.07200","39.25619","0.01569"
"471.40800","39.28423","0.01590"
"471.74400","39.31221","0.01578"
"472.08000","39.34020","0.01588"
"472.41600","39.36824","0.01610"
"472.75200","39.39616","0.01632"
"473.08800","39.42426","0.01669"
"473.42400","39.45224","0.01648"
"473.76000","39.48022","0.01587"
"474.09600","39.50826","0.01558"
"474.43200","39.53619","0.01500"
"474.76800","39.56422","0.01586"
"475.10400","39.59227","0.01509"
"475.44000","39.62019","0.01532"
"475.77600","39.64823","0.01568"
"476.11200","39.67621","0.01583"
"476.44800","39.70425","0.01570"
"476.78400","39.73223","0.01654"
"477.12000","39.76022","0.01727"
"477.45600","39.78814","0.01652"
"477.79200","39.81624","0.01638"
"478.12800","39.84416","0.01555"
"478.46400","39.87221","0.01607"
"478.80000","39.90025","0.01611"
"479.13600","39.92817","0.01642"
"479.47200","39.95620","0.01689"
"479.80800","39.98419","0.01543"
"480.14400","40.01223","0.01484"
"480.48000","40.04021","0.01439"
"480.81600","40.06820","0.01465"
"481.15200","40.09630","0.01579"
"481.48800","40.12421","0.01409"
"481.82400","40.15220","0.01520"
"482.16000","40.18018","0.01480"
"482.49600","40.20816","0.01602"
"482.83200","40.23626","0.01624"
"483.16800","40.26424","0.01669"
"483.50400","40.29217","0.01745"
"483.84000","40.32020","0.01685"
"484.17600","40.34825","0.01678"
"484.51200","40.37617","0.01625"
"484.84800","40.40421","0.01627"
"485.18400","40.43213","0.01576"
"485.52000","40.46023","0.01657"
"485.85600","40.48828","0.01647"
"486.19200","40.51620","0.01684"
"486.52800","40.54424","0.01731"
"486.86400","40.57222","0.01605"
"487.20000","40.60026","0.01411"
"487.53600","40.62824","0.01369"
"487.87200","40.65622","0.01275"
"488.20800","40.68421","0.01604"
"488.54400","40.71219","0.01432"
"488.88000","40.74023","0.01477"
"489.21600","40.76827","0.01554"
"489.55200","40.79620","0.01499"
"489.88800","40.82423","0.01600"
"490.22400","40.85215","0.01506"
"490.56000","40.88013","0.01539"
"490.89600","40.90824","0.01596"
"491.23200","40.93622","0.01522"
"491.56800","40.96420","0.01627"
"491.90400","40.99224","0.01531"
"492.24000","41.02022","0.01444"
"492.57600","41.04821","0.01446"
"492.91200","41.07625","0.01389"
"493.24800","41.10417","0.01598"
"493.58400","41.13227","0.01557"
"493.92000","41.16025","0.01587"
"494.25600","41.18817","0.01594"
"494.59200","41.21621","0.01556"
"494.92800","41.24426","0.01511"
"495.26400","41.27218","0.01390"
"495.60000","41.30028","0.01385"
"495.93600","41.32820","0.01227"
"496.27200","41.35624","0.01342"
"496.60800","41.38422","0.01308"
"496.94400","41.41220","0.01328"
"497.28000","41.44025","0.01445"
"497.61600","41.46822","0.01345"
"497.95200","41.49621","0.01366"
"498.28800","41.52419","0.01395"
"498.46800","41.53926","0.01351"