File: Force_trajectories/170225_1/Specimen_RawData_6.csv
End date,"2/25/2017"
Specimen label,"5CG_38"
Maximum Load,"0.28303",N

Time,Extension,Load
(s),(mm),(N)
"0.00000","0.00000","-0.00011"
"0.33000","0.02738","0.00046"
"0.66000","0.05519","0.00058"
"0.99000","0.08281","0.00121"
"1.32000","0.11019","0.00106"
"1.65000","0.13770","0.00105"
"1.98000","0.16526","0.00066"
"2.31000","0.19264","0.00185"
"2.64000","0.22020","0.00091"
"2.97000","0.24771","0.00207"
"3.30000","0.27521","0.00097"
"3.63000","0.30265","0.00168"
"3.96000","0.33016","0.00222"
"4.29000","0.35772","0.00171"
"4.62000","0.38522","0.00180"
"4.95000","0.41261","0.00251"
"5.28000","0.44023","0.00173"
"5.61000","0.46767","0.00258"
"5.94000","0.49518","0.00191"
"6.27000","0.52274","0.00253"
"6.60000","0.55018","0.00270"
"6.93000","0.57769","0.00230"
"7.26000","0.60519","0.00292"
"7.59000","0.63269","0.00284"
"7.92000","0.66020","0.00223"
"8.25000","0.68764","0.00316"
"8.58000","0.71526","0.00255"
"8.91000","0.74265","0.00310"
"9.24000","0.77015","0.00245"
"9.57000","0.79777","0.00272"
"9.90000","0.82516","0.00243"
"10.23000","0.85266","0.00280"
"10.56000","0.88022","0.00348"
"10.89000","0.90772","0.00282"
"11.22000","0.93523","0.00307"
"11.55000","0.96267","0.00351"
"11.88000","0.99017","0.00276"
"12.21000","1.01774","0.00407"
"12.54000","1.04512","0.00384"
"12.87000","1.07268","0.00256"
"13.20000","1.10019","0.00360"
"13.53000","1.12763","0.00363"
"13.86000","1.15519","0.00349"
"14.19000","1.18270","0.00364"
"14.52000","1.21014","0.00390"
"14.85000","1.23770","0.00392"
"15.18000","1.26521","0.00373"
"15.51000","1.29271","0.00356"
"15.84000","1.32015","0.00414"
"16.17000","1.34772","0.00417"
"16.50000","1.37522","0.00483"
"16.83000","1.40260","0.00424"
"17.16000","1.43023","0.00451"
"17.49000","1.45767","0.00379"
"17.82000","1.48511","0.00426"
"18.15000","1.51268","0.00452"
"18.48000","1.54018","0.00483"
"18.81000","1.56774","0.00410"
"19.14000","1.59524","0.00395"
"19.47000","1.62269","0.00513"
"19.80000","1.65019","0.00455"
"20.13000","1.67763","0.00505"
"20.46000","1.70520","0.00569"
"20.79000","1.73276","0.00492"
"21.12000","1.76014","0.00489"
"21.45000","1.78771","0.00608"
"21.78000","1.81521","0.00530"
"22.11000","1.84265","0.00540"
"22.44000","1.87022","0.00584"
"22.77000","1.89766","0.00563"
"23.10000","1.92516","0.00524"
"23.43000","1.95267","0.00533"
"23.76000","1.98017","0.00546"
"24.09000","2.00773","0.00559"
"24.42000","2.03512","0.00562"
"24.75000","2.06268","0.00603"
"25.08000","2.09024","0.00598"
"25.41000","2.11763","0.00610"
"25.74000","2.14519","0.00621"
"26.07000","2.17269","0.00585"
"26.40000","2.20025","0.00564"
"26.73000","2.22770","0.00610"
"27.06000","2.25514","0.00573"
"27.39000","2.28270","0.00591"
"27.72000","2.31021","0.00573"
"28.05000","2.33765","0.00600"
"28.38000","2.36521","0.00636"
"28.71000","2.39266","0.00644"
"29.04000","2.42022","0.00713"
"29.37000","2.44772","0.00690"
"29.70000","2.47517","0.00664"
"30.03000","2.50267","0.00671"
"30.36000","2.53017","0.00730"
"30.69000","2.55774","0.00694"
"31.02000","2.58524","0.00726"
"31.35000","2.61268","0.00652"
"31.68000","2.64025","0.00630"
"32.01000","2.66769","0.00695"
"32.34000","2.69519","0.00703"
"32.67000","2.72276","0.00689"
"33.00000","2.75014","0.00717"
"33.33000","2.77770","0.00734"
"33.66000","2.80515","0.00713"
"33.99000","2.83265","0.00755"
"34.32000","2.86021","0.00771"
"34.65000","2.88766","0.00753"
"34.98000","2.91522","0.00728"
"35.31000","2.94266","0.00727"
"35.64000","2.97010","0.00728"
"35.97000","2.99773","0.00673"
"36.30000","3.02517","0.00668"
"36.63000","3.05273","0.00693"
"36.96000","3.08024","0.00766"
"37.29000","3.10768","0.00687"
"37.62000","3.13518","0.00721"
"37.95000","3.16269","0.00748"
"38.28000","3.19025","0.00731"
"38.61000","3.21769","0.00695"
"38.94000","3.24514","0.00804"
"39.27000","3.27276","0.00748"
"39.60000","3.30020","0.00771"
"39.93000","3.32765","0.00751"
"40.26000","3.35521","0.00803"
"40.59000","3.38265","0.00663"
"40.92000","3.41016","0.00690"
"41.25000","3.43766","0.00745"
"41.58000","3.46516","0.00741"
"41.91000","3.49273","0.00717"
"42.24000","3.52017","0.00765"
"42.57000","3.54767","0.00734"
"42.90000","3.57518","0.00761"
"43.23000","3.60262","0.00734"
"43.56000","3.63024","0.00759"
"43.89000","3.65768","0.00728"
"44.22000","3.68519","0.00788"
"44.55000","3.71269","0.00720"
"44.88000","3.74019","0.00741"
"45.21000","3.76770","0.00825"
"45.54000","3.79520","0.00854"
"45.87000","3.82270","0.00842"
"46.20000","3.85027","0.00628"
"46.53000","3.87765","0.00622"
"46.86000","3.90515","0.00636"
"47.19000","3.93272","0.00703"
"47.52000","3.96016","0.00752"
"47.85000","3.98772","0.00819"
"48.18000","4.01523","0.00547"
"48.51000","4.04267","0.00607"
"48.84000","4.07017","0.00702"
"49.17000","4.09768","0.00684"
"49.50000","4.12524","0.00670"
"49.83000","4.15274","0.00830"
"50.16000","4.18018","0.00804"
"50.49000","4.20769","0.00783"
"50.82000","4.23513","0.00515"
"51.15000","4.26264","0.00744"
"51.48000","4.29026","0.00740"
"51.81000","4.31764","0.00620"
"52.14000","4.34526","0.00669"
"52.47000","4.37265","0.00698"
"52.80000","4.40015","0.00529"
"53.13000","4.42765","0.00386"
"53.46000","4.45510","0.00543"
"53.79000","4.48272","0.00607"
"54.12000","4.51016","0.00276"
"54.45000","4.53767","0.00301"
"54.78000","4.56523","0.00255"
"55.11000","4.59267","0.00373"
"55.44000","4.62018","0.00325"
"55.77000","4.64768","0.00458"
"56.10000","4.67518","0.00436"
"56.43000","4.70269","0.00499"
"56.76000","4.73019","0.00557"
"57.09000","4.75769","0.00388"
"57.42000","4.78520","0.00585"
"57.75000","4.81264","0.00548"
"58.08000","4.84026","0.00545"
"58.41000","4.86770","0.00608"
"58.74000","4.89515","0.00594"
"59.07000","4.92271","0.00635"
"59.40000","4.95015","0.00625"
"59.73000","4.97772","0.00635"
"60.06000","5.00516","0.00682"
"60.39000","5.03266","0.00632"
"60.72000","5.06023","0.00711"
"61.05000","5.08767","0.00715"
"61.38000","5.11523","0.00762"
"61.71000","5.14274","0.00809"
"62.04000","5.17012","0.00706"
"62.37000","5.19768","0.00748"
"62.70000","5.22519","0.00730"
"63.03000","5.25269","0.00738"
"63.36000","5.28019","0.00785"
"63.69000","5.30770","0.00704"
"64.02000","5.33520","0.00754"
"64.35000","5.36270","0.00845"
"64.68000","5.39021","0.00771"
"65.01000","5.41771","0.00804"
"65.34000","5.44515","0.00790"
"65.67000","5.47271","0.00799"
"66.00000","5.50022","0.00764"
"66.33000","5.52760","0.00698"
"66.66000","5.55522","0.00664"
"66.99000","5.58273","0.00666"
"67.32000","5.61017","0.00641"
"67.65000","5.63773","0.00702"
"67.98000","5.66518","0.00685"
"68.31000","5.69268","0.00667"
"68.64000","5.72018","0.00741"
"68.97000","5.74769","0.00736"
"69.30000","5.77525","0.00795"
"69.63000","5.80263","0.00890"
"69.96000","5.83020","0.00851"
"70.29000","5.85776","0.00771"
"70.62000","5.88514","0.00795"
"70.95000","5.91271","0.00816"
"71.28000","5.94015","0.00736"
"71.61000","5.96771","0.00605"
"71.94000","5.99516","0.00676"
"72.27000","6.02266","0.00738"
"72.60000","6.05016","0.00794"
"72.93000","6.07767","0.00767"
"73.26000","6.10517","0.00727"
"73.59000","6.13273","0.00733"
"73.92000","6.16017","0.00650"
"74.25000","6.18768","0.00768"
"74.58000","6.21524","0.00686"
"74.91000","6.24262","0.00960"
"75.24000","6.27019","0.00893"
"75.57000","6.29769","0.00888"
"75.90000","6.32519","0.00909"
"76.23000","6.35276","0.00978"
"76.56000","6.38014","0.00975"
"76.89000","6.40770","0.00827"
"77.22000","6.43521","0.00849"
"77.55000","6.46265","0.00935"
"77.88000","6.49021","0.00967"
"78.21000","6.51766","0.00859"
"78.54000","6.54522","0.00887"
"78.87000","6.57272","0.00826"
"79.20000","6.60017","0.00871"
"79.53000","6.62767","0.00865"
"79.86000","6.65511","0.00894"
"80.19000","6.68268","0.00927"
"80.52000","6.71024","0.00908"
"80.85000","6.73768","0.00939"
"81.18000","6.76525","0.00956"
"81.51000","6.79269","0.00944"
"81.84000","6.82013","0.00970"
"82.17000","6.84770","0.00951"
"82.50000","6.87514","0.00983"
"82.83000","6.90270","0.00965"
"83.16000","6.93020","0.00954"
"83.49000","6.95771","0.01029"
"83.82000","6.98521","0.01018"
"84.15000","7.01265","0.01066"
"84.48000","7.04016","0.01032"
"84.81000","7.06778","0.01035"
"85.14000","7.09516","0.01107"
"85.47000","7.12273","0.01093"
"85.80000","7.15017","0.01080"
"86.13000","7.17767","0.01087"
"86.46000","7.20524","0.01120"
"86.79000","7.23268","0.01165"
"87.12000","7.26024","0.01074"
"87.45000","7.28769","0.01148"
"87.78000","7.31519","0.01130"
"88.11000","7.34269","0.01127"
"88.44000","7.37014","0.01179"
"88.77000","7.39770","0.01157"
"89.10000","7.42520","0.01131"
"89.43000","7.45265","0.01118"
"89.76000","7.48021","0.01179"
"90.09000","7.50771","0.01190"
"90.42000","7.53516","0.01182"
"90.75000","7.56266","0.01181"
"91.08000","7.59016","0.01209"
"91.41000","7.61772","0.01222"
"91.74000","7.64523","0.01207"
"92.07000","7.67267","0.01179"
"92.40000","7.70018","0.01265"
"92.73000","7.72762","0.01272"
"93.06000","7.75518","0.01227"
"93.39000","7.78268","0.01227"
"93.72000","7.81013","0.01219"
"94.05000","7.83769","0.01264"
"94.38000","7.86519","0.01250"
"94.71000","7.89270","0.01239"
"95.04000","7.92020","0.01239"
"95.37000","7.94770","0.01290"
"95.70000","7.97521","0.01232"
"96.03000","8.00271","0.01230"
"96.36000","8.03021","0.01273"
"96.69000","8.05772","0.01274"
"97.02000","8.08516","0.01294"
"97.35000","8.11266","0.01218"
"97.68000","8.14017","0.01278"
"98.01000","8.16767","0.01305"
"98.34000","8.19517","0.01291"
"98.67000","8.22268","0.01278"
"99.00000","8.25024","0.01255"
"99.33000","8.27774","0.01273"
"99.66000","8.30513","0.01284"
"99.99000","8.33275","0.01300"
"100.32000","8.36019","0.01302"
"100.65000","8.38769","0.01342"
"100.98000","8.41526","0.01315"
"101.31000","8.44264","0.01286"
"101.64000","8.47020","0.01306"
"101.97000","8.49771","0.01321"
"102.30000","8.52521","0.01287"
"102.63000","8.55271","0.01315"
"102.96000","8.58016","0.01357"
"103.29000","8.60772","0.01319"
"103.62000","8.63516","0.01297"
"103.95000","8.66267","0.01336"
"104.28000","8.69023","0.01270"
"104.61000","8.71767","0.01274"
"104.94000","8.74524","0.01288"
"105.27000","8.77274","0.01294"
"105.60000","8.80018","0.01326"
"105.93000","8.82769","0.01342"
"106.26000","8.85513","0.01363"
"106.59000","8.88269","0.01333"
"106.92000","8.91020","0.01331"
"107.25000","8.93764","0.01310"
"107.58000","8.96520","0.01380"
"107.91000","8.99270","0.01325"
"108.24000","9.02015","0.01384"
"108.57000","9.04771","0.01377"
"108.90000","9.07515","0.01367"
"109.23000","9.10272","0.01377"
"109.56000","9.13016","0.01373"
"109.89000","9.15766","0.01354"
"110.22000","9.18517","0.01285"
"110.55000","9.21261","0.01339"
"110.88000","9.24023","0.01301"
"111.21000","9.26768","0.01350"
"111.54000","9.29512","0.01339"
"111.87000","9.32274","0.01402"
"112.20000","9.35019","0.01377"
"112.53000","9.37769","0.01406"
"112.86000","9.40519","0.01343"
"113.19000","9.43270","0.01358"
"113.52000","9.46020","0.01403"
"113.85000","9.48770","0.01395"
"114.18000","9.51521","0.01368"
"114.51000","9.54271","0.01358"
"114.84000","9.57015","0.01305"
"115.17000","9.59766","0.01404"
"115.50000","9.62528","0.01335"
"115.83000","9.65266","0.01333"
"116.16000","9.68022","0.01343"
"116.49000","9.70767","0.01351"
"116.82000","9.73517","0.01312"
"117.15000","9.76267","0.01310"
"117.48000","9.79018","0.01354"
"117.81000","9.81768","0.01215"
"118.14000","9.84518","0.01282"
"118.47000","9.87269","0.01267"
"118.80000","9.90025","0.01324"
"119.13000","9.92763","0.01314"
"119.46000","9.95520","0.01240"
"119.79000","9.98270","0.01241"
"120.12000","10.01014","0.01245"
"120.45000","10.03771","0.01248"
"120.78000","10.06521","0.01293"
"121.11000","10.09271","0.01301"
"121.44000","10.12016","0.01278"
"121.77000","10.14766","0.01301"
"122.10000","10.17522","0.01300"
"122.43000","10.20267","0.01278"
"122.76000","10.23017","0.01334"
"123.09000","10.25773","0.01353"
"123.42000","10.28512","0.01345"
"123.75000","10.31268","0.01332"
"124.08000","10.34018","0.01374"
"124.41000","10.36768","0.01364"
"124.74000","10.39519","0.01438"
"125.07000","10.42269","0.01412"
"125.40000","10.45019","0.01336"
"125.73000","10.47776","0.01410"
"126.06000","10.50514","0.01418"
"126.39000","10.53270","0.01418"
"126.72000","10.56021","0.01434"
"127.05000","10.58765","0.01457"
"127.38000","10.61527","0.01519"
"127.71200","10.64278","0.01495"
"128.04200","10.67034","0.01499"
"128.37200","10.69784","0.01484"
"128.70200","10.72534","0.01520"
"129.03200","10.75285","0.01503"
"129.36200","10.78035","0.01556"
"129.69200","10.80791","0.01572"
"130.02200","10.83536","0.01538"
"130.35200","10.86280","0.01609"
"130.68200","10.89036","0.01602"
"131.01200","10.91787","0.01671"
"131.34200","10.94537","0.01572"
"131.67200","10.97287","0.01593"
"132.00200","11.00032","0.01619"
"132.33200","11.02788","0.01604"
"132.66200","11.05532","0.01593"
"132.99200","11.08283","0.01638"
"133.32200","11.11033","0.01629"
"133.65200","11.13783","0.01622"
"133.98200","11.16540","0.01561"
"134.31200","11.19290","0.01472"
"134.64200","11.22034","0.01520"
"134.97200","11.24785","0.01558"
"135.30200","11.27535","0.01554"
"135.63200","11.30285","0.01538"
"135.96200","11.33042","0.01600"
"136.29200","11.35780","0.01581"
"136.62200","11.38536","0.01626"
"136.95200","11.41280","0.01639"
"137.28200","11.44031","0.01679"
"137.61200","11.46787","0.01703"
"137.94200","11.49525","0.01709"
"138.27200","11.52288","0.01698"
"138.60200","11.55038","0.01735"
"138.93200","11.57782","0.01738"
"139.26200","11.60533","0.01778"
"139.59200","11.63289","0.01787"
"139.92200","11.66033","0.01771"
"140.25200","11.68790","0.01855"
"140.58200","11.71534","0.01787"
"140.91200","11.74290","0.01839"
"141.24200","11.77035","0.01886"
"141.57200","11.79785","0.01863"
"141.90200","11.82541","0.01909"
"142.23200","11.85280","0.01893"
"142.56200","11.88036","0.01896"
"142.89200","11.90786","0.01837"
"143.22200","11.93531","0.01883"
"143.55200","11.96287","0.01893"
"143.88200","11.99037","0.01978"
"144.21200","12.01794","0.01895"
"144.54200","12.04538","0.01989"
"144.87200","12.07282","0.01863"
"145.20200","12.10039","0.01894"
"145.53200","12.12783","0.01917"
"145.86200","12.15533","0.01954"
"146.19200","12.18289","0.01925"
"146.52200","12.21028","0.01956"
"146.85200","12.23790","0.01943"
"147.18200","12.26534","0.01956"
"147.51200","12.29291","0.02007"
"147.84200","12.32029","0.02046"
"148.17200","12.34780","0.02104"
"148.50200","12.37536","0.02100"
"148.83200","12.40292","0.02132"
"149.16200","12.43030","0.02172"
"149.49200","12.45787","0.02210"
"149.82200","12.48531","0.02195"
"150.15200","12.51281","0.02210"
"150.48200","12.54044","0.02235"
"150.81200","12.56782","0.02082"
"151.14200","12.59538","0.02152"
"151.47200","12.62289","0.02279"
"151.80200","12.65039","0.02265"
"152.13200","12.67783","0.02259"
"152.46200","12.70528","0.02386"
"152.79200","12.73290","0.02326"
"153.12200","12.76040","0.02218"
"153.45200","12.78785","0.01963"
"153.78200","12.81541","0.01909"
"154.11200","12.84285","0.01868"
"154.44200","12.87036","0.01994"
"154.77200","12.89786","0.01998"
"155.10200","12.92536","0.02052"
"155.43200","12.95286","0.02131"
"155.76200","12.98031","0.02179"
"156.09200","13.00787","0.02216"
"156.42200","13.03537","0.02212"
"156.75200","13.06276","0.02233"
"157.08200","13.09038","0.02278"
"157.41200","13.11788","0.02266"
"157.74200","13.14533","0.02239"
"158.07200","13.17289","0.02238"
"158.40200","13.20033","0.02321"
"158.73200","13.22778","0.02367"
"159.06200","13.25534","0.02413"
"159.39200","13.28290","0.02430"
"159.72200","13.31041","0.02522"
"160.05200","13.33785","0.02561"
"160.38200","13.36541","0.02567"
"160.71200","13.39292","0.02589"
"161.04200","13.42024","0.02611"
"161.37200","13.44792","0.02574"
"161.70200","13.47537","0.02619"
"162.03200","13.50287","0.02605"
"162.36200","13.53037","0.02683"
"162.69200","13.55788","0.02753"
"163.02200","13.58532","0.02705"
"163.35200","13.61282","0.02841"
"163.68200","13.64032","0.02851"
"164.01200","13.66789","0.02888"
"164.34200","13.69533","0.02891"
"164.67200","13.72289","0.02885"
"165.00200","13.75040","0.02938"
"165.33200","13.77784","0.02888"
"165.66200","13.80534","0.02948"
"165.99200","13.83285","0.02940"
"166.32200","13.86035","0.02913"
"166.65200","13.88785","0.02909"
"166.98200","13.91536","0.02973"
"167.31200","13.94286","0.03044"
"167.64200","13.97030","0.02944"
"167.97200","13.99781","0.02889"
"168.30200","14.02537","0.02909"
"168.63200","14.05281","0.02801"
"168.96200","14.08038","0.02661"
"169.29200","14.10788","0.02750"
"169.62200","14.13538","0.02873"
"169.95200","14.16288","0.02928"
"170.28200","14.19039","0.02866"
"170.61200","14.21783","0.02941"
"170.94200","14.24539","0.02938"
"171.27200","14.27284","0.03010"
"171.60200","14.30040","0.03061"
"171.93200","14.32784","0.03067"
"172.26200","14.35535","0.03155"
"172.59200","14.38291","0.03202"
"172.92200","14.41035","0.03236"
"173.25200","14.43792","0.03315"
"173.58200","14.46536","0.03285"
"173.91200","14.49280","0.03308"
"174.24200","14.52031","0.03407"
"174.57200","14.54781","0.03362"
"174.90200","14.57537","0.03419"
"175.23200","14.60288","0.03554"
"175.56200","14.63032","0.03506"
"175.89200","14.65788","0.03496"
"176.22200","14.68533","0.03591"
"176.55200","14.71277","0.03609"
"176.88200","14.74033","0.03651"
"177.21200","14.76778","0.03745"
"177.54200","14.79540","0.03635"
"177.87200","14.82290","0.03573"
"178.20200","14.85034","0.03418"
"178.53200","14.87785","0.03561"
"178.86200","14.90529","0.03548"
"179.19200","14.93291","0.03584"
"179.52200","14.96042","0.03564"
"179.85200","14.98786","0.03717"
"180.18200","15.01542","0.03761"
"180.51200","15.04287","0.03613"
"180.84200","15.07037","0.03656"
"181.17200","15.09787","0.03584"
"181.50200","15.12532","0.03597"
"181.83200","15.15288","0.03665"
"182.16200","15.18038","0.03702"
"182.49200","15.20783","0.03823"
"182.82200","15.23539","0.03756"
"183.15200","15.26277","0.03839"
"183.48200","15.29040","0.03933"
"183.81200","15.31784","0.03948"
"184.14200","15.34534","0.03955"
"184.47200","15.37290","0.04008"
"184.80200","15.40035","0.04052"
"185.13200","15.42785","0.04137"
"185.46200","15.45535","0.04166"
"185.79200","15.48286","0.04166"
"186.12200","15.51036","0.04184"
"186.45200","15.53786","0.04309"
"186.78200","15.56537","0.04299"
"187.11200","15.59287","0.04323"
"187.44200","15.62025","0.04337"
"187.77200","15.64788","0.04425"
"188.10200","15.67544","0.04425"
"188.43200","15.70282","0.04373"
"188.76200","15.73039","0.04448"
"189.09200","15.75783","0.04444"
"189.42200","15.78533","0.04447"
"189.75200","15.81290","0.04562"
"190.08200","15.84034","0.04532"
"190.41200","15.86790","0.04542"
"190.74200","15.89529","0.04537"
"191.07200","15.92279","0.04565"
"191.40200","15.95041","0.04553"
"191.73200","15.97780","0.04619"
"192.06200","16.00536","0.04597"
"192.39200","16.03286","0.04594"
"192.72200","16.06031","0.04582"
"193.05200","16.08787","0.04644"
"193.38200","16.11537","0.04571"
"193.71200","16.14288","0.04546"
"194.04200","16.17038","0.04571"
"194.37200","16.19776","0.04648"
"194.70200","16.22538","0.04640"
"195.03200","16.25283","0.04637"
"195.36200","16.28033","0.04609"
"195.69200","16.30795","0.04620"
"196.02200","16.33528","0.04452"
"196.35200","16.36284","0.04558"
"196.68200","16.39034","0.04509"
"197.01200","16.41785","0.04568"
"197.34200","16.44535","0.04549"
"197.67200","16.47279","0.04553"
"198.00200","16.50035","0.04645"
"198.33200","16.52786","0.04646"
"198.66200","16.55530","0.04674"
"198.99200","16.58286","0.04682"
"199.32200","16.61031","0.04714"
"199.65200","16.63787","0.04711"
"199.98200","16.66537","0.04696"
"200.31200","16.69282","0.04719"
"200.64200","16.72032","0.04760"
"200.97200","16.74783","0.04741"
"201.30200","16.77539","0.04775"
"201.63200","16.80289","0.04784"
"201.96200","16.83027","0.04832"
"202.29200","16.85784","0.04851"
"202.62200","16.88534","0.04873"
"202.95200","16.91278","0.04905"
"203.28200","16.94041","0.04912"
"203.61200","16.96785","0.04926"
"203.94200","16.99529","0.04997"
"204.27200","17.02286","0.05005"
"204.60200","17.05036","0.05024"
"204.93200","17.07792","0.05030"
"205.26200","17.10531","0.03132"
"205.59200","17.13281","0.03006"
"205.92200","17.16037","0.03081"
"206.25200","17.18782","0.03205"
"206.58200","17.21544","0.03081"
"206.91200","17.24288","0.02797"
"207.24200","17.27033","0.02792"
"207.57200","17.29789","0.02806"
"207.90200","17.32533","0.02884"
"208.23200","17.35290","0.02864"
"208.56200","17.38040","0.02747"
"208.89200","17.40784","0.02714"
"209.22200","17.43541","0.02530"
"209.55200","17.46285","0.02330"
"209.88200","17.49035","0.02089"
"210.21200","17.51792","0.02044"
"210.54200","17.54530","0.02014"
"210.87200","17.57292","0.01946"
"211.20200","17.60036","0.01865"
"211.53200","17.62781","0.01928"
"211.86200","17.65531","0.01957"
"212.19200","17.68282","0.02007"
"212.52200","17.71038","0.02061"
"212.85200","17.73788","0.02047"
"213.18200","17.76532","0.02061"
"213.51200","17.79283","0.02073"
"213.84200","17.82027","0.02012"
"214.17200","17.84783","0.02100"
"214.50200","17.87539","0.02022"
"214.83200","17.90284","0.01912"
"215.16200","17.93040","0.01923"
"215.49200","17.95790","0.02060"
"215.82200","17.98535","0.01940"
"216.15200","18.01285","0.01940"
"216.48200","18.04036","0.01970"
"216.81200","18.06786","0.02030"
"217.14200","18.09536","0.02080"
"217.47200","18.12287","0.02076"
"217.80200","18.15043","0.02041"
"218.13200","18.17781","0.02053"
"218.46200","18.20537","0.02078"
"218.79200","18.23288","0.02154"
"219.12200","18.26032","0.02121"
"219.45200","18.28782","0.02170"
"219.78200","18.31533","0.02189"
"220.11200","18.34289","0.02213"
"220.44200","18.37039","0.02292"
"220.77200","18.39784","0.02374"
"221.10200","18.42534","0.02388"
"221.43200","18.45284","0.02409"
"221.76200","18.48035","0.02505"
"222.09200","18.50791","0.02473"
"222.42200","18.53529","0.02512"
"222.75200","18.56286","0.02609"
"223.08200","18.59036","0.02719"
"223.41200","18.61780","0.02637"
"223.74200","18.64537","0.02726"
"224.07200","18.67281","0.02759"
"224.40200","18.70037","0.02799"
"224.73200","18.72788","0.02798"
"225.06200","18.75532","0.02787"
"225.39200","18.78288","0.02803"
"225.72200","18.81032","0.02862"
"226.05200","18.83789","0.02908"
"226.38200","18.86539","0.02927"
"226.71200","18.89283","0.03034"
"227.04200","18.92040","0.03022"
"227.37200","18.94784","0.03031"
"227.70200","18.97534","0.03052"
"228.03200","19.00285","0.03136"
"228.36200","19.03035","0.03095"
"228.69200","19.05791","0.03100"
"229.02200","19.08542","0.03119"
"229.35200","19.11280","0.03161"
"229.68200","19.14036","0.03238"
"230.01200","19.16781","0.03364"
"230.34200","19.19537","0.03327"
"230.67200","19.22287","0.03314"
"231.00200","19.25032","0.03451"
"231.33200","19.27788","0.03471"
"231.66200","19.30532","0.03525"
"231.99200","19.33283","0.03532"
"232.32200","19.36033","0.03674"
"232.65200","19.38777","0.03737"
"232.98200","19.41540","0.03483"
"233.31200","19.44290","0.03610"
"233.64200","19.47040","0.03642"
"233.97200","19.49784","0.03749"
"234.30200","19.52535","0.03645"
"234.63200","19.55285","0.03642"
"234.96200","19.58035","0.03644"
"235.29200","19.60786","0.03740"
"235.62200","19.63542","0.03699"
"235.95200","19.66286","0.03669"
"236.28200","19.69031","0.03657"
"236.61200","19.71787","0.03733"
"236.94200","19.74531","0.03689"
"237.27200","19.77288","0.03688"
"237.60200","19.80038","0.03758"
"237.93200","19.82782","0.03678"
"238.26200","19.85539","0.03670"
"238.59200","19.88289","0.03529"
"238.92200","19.91039","0.02983"
"239.25200","19.93789","0.02724"
"239.58200","19.96534","0.02418"
"239.91200","19.99290","0.02554"
"240.24200","20.02029","0.02633"
"240.57200","20.04779","0.02635"
"240.90200","20.07541","0.01914"
"241.23200","20.10279","0.01983"
"241.56200","20.13042","0.01969"
"241.89200","20.15786","0.01908"
"242.22200","20.18536","0.01904"
"242.55200","20.21281","0.01991"
"242.88200","20.24031","0.02045"
"243.21200","20.26787","0.02133"
"243.54200","20.29538","0.02142"
"243.87200","20.32288","0.02133"
"244.20200","20.35038","0.02131"
"244.53200","20.37783","0.01977"
"244.86200","20.40533","0.01950"
"245.19200","20.43289","0.01981"
"245.52200","20.46034","0.01940"
"245.85200","20.48790","0.01770"
"246.18200","20.51540","0.01839"
"246.51200","20.54284","0.01921"
"246.84200","20.57035","0.01952"
"247.17200","20.59779","0.01898"
"247.50200","20.62542","0.01925"
"247.83200","20.65292","0.01995"
"248.16200","20.68030","0.01983"
"248.49200","20.70792","0.02038"
"248.82200","20.73537","0.01996"
"249.15200","20.76287","0.01854"
"249.48200","20.79038","0.01905"
"249.81200","20.81782","0.01963"
"250.14200","20.84538","0.01985"
"250.47200","20.87282","0.01942"
"250.80200","20.90039","0.02041"
"251.13200","20.92783","0.01990"
"251.46200","20.95528","0.02080"
"251.79200","20.98290","0.02056"
"252.12200","21.01028","0.02084"
"252.45200","21.03778","0.02113"
"252.78200","21.06535","0.02179"
"253.11200","21.09285","0.02097"
"253.44200","21.12035","0.02166"
"253.77200","21.14786","0.02144"
"254.10200","21.17536","0.02219"
"254.43200","21.20286","0.01904"
"254.76200","21.23037","0.01852"
"255.09200","21.25787","0.01836"
"255.42200","21.28543","0.01832"
"255.75200","21.31282","0.01852"
"256.08200","21.34044","0.01889"
"256.41200","21.36788","0.01889"
"256.74200","21.39532","0.01985"
"257.07200","21.42289","0.01873"
"257.40200","21.45033","0.01861"
"257.73200","21.47789","0.01897"
"258.06200","21.50534","0.01885"
"258.39200","21.53284","0.01948"
"258.72200","21.56034","0.01921"
"259.05200","21.58785","0.01880"
"259.38200","21.61535","0.01653"
"259.71200","21.64285","0.01625"
"260.04200","21.67024","0.01654"
"260.37200","21.69786","0.01564"
"260.70200","21.72536","0.01658"
"261.03200","21.75287","0.01638"
"261.36200","21.78037","0.01656"
"261.69200","21.80787","0.01581"
"262.02200","21.83538","0.01501"
"262.35200","21.86288","0.01533"
"262.68200","21.89032","0.01514"
"263.01200","21.91783","0.01518"
"263.34200","21.94533","0.01521"
"263.67200","21.97289","0.01549"
"264.00200","22.00046","0.01547"
"264.33200","22.02778","0.01562"
"264.66200","22.05540","0.01577"
"264.99200","22.08285","0.01547"
"265.32200","22.11035","0.01555"
"265.65200","22.13785","0.01569"
"265.98200","22.16529","0.01593"
"266.31200","22.19286","0.01538"
"266.64200","22.22036","0.01581"
"266.97200","22.24781","0.01612"
"267.30200","22.27537","0.01561"
"267.63200","22.30281","0.01638"
"267.96200","22.33031","0.01584"
"268.29200","22.35788","0.01568"
"268.62200","22.38532","0.01619"
"268.95200","22.41289","0.01616"
"269.28200","22.44033","0.01731"
"269.61200","22.46789","0.01728"
"269.94200","22.49539","0.01741"
"270.27200","22.52284","0.01726"
"270.60200","22.55034","0.01687"
"270.93200","22.57784","0.01770"
"271.26200","22.60529","0.01700"
"271.59200","22.63291","0.01704"
"271.92200","22.66035","0.01761"
"272.25200","22.68786","0.01735"
"272.58200","22.71536","0.01733"
"272.91200","22.74286","0.01832"
"273.24200","22.77036","0.01776"
"273.57200","22.79781","0.01762"
"273.90200","22.82537","0.01842"
"274.23200","22.85294","0.01879"
"274.56200","22.88032","0.01865"
"274.89200","22.90788","0.01925"
"275.22200","22.93533","0.01975"
"275.55200","22.96283","0.02058"
"275.88200","22.99039","0.02083"
"276.21200","23.01784","0.02170"
"276.54200","23.04540","0.02252"
"276.87200","23.07284","0.02320"
"277.20200","23.10034","0.02359"
"277.53200","23.12785","0.02386"
"277.86200","23.15535","0.02524"
"278.19200","23.18285","0.02555"
"278.52200","23.21036","0.02761"
"278.85200","23.23786","0.02758"
"279.18200","23.26536","0.02867"
"279.51200","23.29287","0.02922"
"279.84200","23.32031","0.03047"
"280.17200","23.34787","0.03181"
"280.50200","23.37532","0.03216"
"280.83200","23.40282","0.03283"
"281.16200","23.43032","0.03404"
"281.49200","23.45783","0.03069"
"281.82200","23.48539","0.03239"
"282.15200","23.51283","0.03180"
"282.48200","23.54040","0.03317"
"282.81200","23.56790","0.03388"
"283.14200","23.59534","0.03449"
"283.47200","23.62285","0.03553"
"283.80200","23.65035","0.03523"
"284.13200","23.67785","0.03712"
"284.46200","23.70535","0.03743"
"284.79200","23.73286","0.03888"
"285.12200","23.76042","0.03915"
"285.45200","23.78786","0.03987"
"285.78200","23.81531","0.03962"
"286.11200","23.84293","0.04038"
"286.44200","23.87031","0.04099"
"286.77200","23.89788","0.04232"
"287.10200","23.92538","0.03116"
"287.43200","23.95282","0.02545"
"287.76200","23.98033","0.02567"
"288.09200","24.00783","0.02537"
"288.42200","24.03533","0.02574"
"288.75200","24.06283","0.02724"
"289.08200","24.09028","0.02741"
"289.41200","24.11790","0.02754"
"289.74200","24.14535","0.02774"
"290.07200","24.17285","0.02700"
"290.40200","24.20041","0.02707"
"290.73200","24.22785","0.02730"
"291.06200","24.25536","0.02897"
"291.39200","24.28286","0.02914"
"291.72200","24.31037","0.03108"
"292.05200","24.33787","0.03118"
"292.38200","24.36531","0.03103"
"292.71200","24.39293","0.03183"
"293.04200","24.42038","0.03095"
"293.37200","24.44782","0.03226"
"293.70200","24.47538","0.03224"
"294.03200","24.50283","0.03272"
"294.36200","24.53033","0.03158"
"294.69200","24.55789","0.03288"
"295.02200","24.58534","0.03223"
"295.35200","24.61284","0.03398"
"295.68200","24.64034","0.03469"
"296.01200","24.66785","0.03532"
"296.34200","24.69535","0.03591"
"296.67200","24.72279","0.03611"
"297.00200","24.75042","0.03726"
"297.33200","24.77786","0.03887"
"297.66200","24.80530","0.03907"
"297.99200","24.83286","0.03916"
"298.32200","24.86031","0.04098"
"298.65200","24.88787","0.04241"
"298.98200","24.91537","0.04109"
"299.31200","24.94282","0.04146"
"299.64200","24.97038","0.04010"
"299.97200","24.99783","0.03876"
"300.30200","25.02539","0.03707"
"300.63200","25.05289","0.03673"
"300.96200","25.08027","0.03280"
"301.29200","25.10790","0.03254"
"301.62200","25.13540","0.03276"
"301.95200","25.16284","0.03401"
"302.28200","25.19035","0.03484"
"302.61200","25.21785","0.03527"
"302.94200","25.24535","0.03555"
"303.27200","25.27286","0.03665"
"303.60200","25.30036","0.03780"
"303.93200","25.32786","0.03865"
"304.26200","25.35530","0.03979"
"304.59200","25.38287","0.04071"
"304.92200","25.41043","0.04176"
"305.25200","25.43782","0.04249"
"305.58200","25.46538","0.04276"
"305.91200","25.49282","0.04424"
"306.24200","25.52038","0.04490"
"306.57200","25.54789","0.04299"
"306.90200","25.57533","0.04441"
"307.23200","25.60290","0.04630"
"307.56200","25.63040","0.04638"
"307.89200","25.65784","0.04721"
"308.22200","25.68540","0.04795"
"308.55200","25.71279","0.04815"
"308.88200","25.74035","0.04897"
"309.21200","25.76792","0.04928"
"309.54200","25.79530","0.04959"
"309.87200","25.82292","0.04982"
"310.20200","25.85030","0.05008"
"310.53200","25.87787","0.05026"
"310.86200","25.90537","0.05054"
"311.19200","25.93282","0.05066"
"311.52200","25.96037","0.05138"
"311.85200","25.98782","0.05137"
"312.18200","26.01532","0.05056"
"312.51200","26.04289","0.05133"
"312.84200","26.07033","0.05139"
"313.17200","26.09789","0.05130"
"313.50200","26.12539","0.05184"
"313.83200","26.15284","0.05214"
"314.16200","26.18040","0.05281"
"314.49200","26.20785","0.05315"
"314.82200","26.23541","0.05369"
"315.15200","26.26285","0.05369"
"315.48200","26.29030","0.05387"
"315.81200","26.31786","0.05480"
"316.14200","26.34536","0.05509"
"316.47200","26.37287","0.05571"
"316.80200","26.40037","0.05666"
"317.13200","26.42775","0.05725"
"317.46200","26.45537","0.05779"
"317.79200","26.48282","0.05804"
"318.12200","26.51032","0.02498"
"318.45200","26.53788","0.01317"
"318.78200","26.56533","0.01458"
"319.11200","26.59283","0.02008"
"319.44200","26.62039","0.01301"
"319.77200","26.64784","0.01855"
"320.10200","26.67540","0.01920"
"320.43200","26.70284","0.01799"
"320.76200","26.73034","0.01904"
"321.09200","26.75791","0.01642"
"321.42200","26.78535","0.02270"
"321.75200","26.81285","0.02239"
"322.08200","26.84036","0.01917"
"322.41200","26.86786","0.02334"
"322.74200","26.89537","0.02170"
"323.07200","26.92281","0.02365"
"323.40200","26.95037","0.02884"
"323.73200","26.97787","0.02468"
"324.06200","27.00526","0.02558"
"324.39200","27.03288","0.02564"
"324.72200","27.06039","0.02327"
"325.05200","27.08783","0.02798"
"325.38200","27.11539","0.02939"
"325.71200","27.14284","0.02640"
"326.04200","27.17039","0.03122"
"326.37200","27.19784","0.02812"
"326.70200","27.22534","0.02739"
"327.03200","27.25285","0.03266"
"327.36200","27.28029","0.03057"
"327.69200","27.30791","0.03087"
"328.02200","27.33542","0.03423"
"328.35200","27.36280","0.03259"
"328.68200","27.39036","0.03365"
"329.01200","27.41780","0.03375"
"329.34200","27.44537","0.03265"
"329.67200","27.47287","0.03407"
"330.00200","27.50032","0.03645"
"330.33200","27.52788","0.03417"
"330.66200","27.55538","0.03661"
"330.99200","27.58282","0.03850"
"331.32200","27.61039","0.03655"
"331.65200","27.63783","0.03937"
"331.98200","27.66534","0.04006"
"332.31200","27.69290","0.03897"
"332.64200","27.72034","0.04051"
"332.97200","27.74784","0.03823"
"333.30200","27.77535","0.03905"
"333.63200","27.80291","0.03529"
"333.96200","27.83041","0.03224"
"334.29200","27.85780","0.03106"
"334.62200","27.88536","0.03292"
"334.95200","27.91286","0.03147"
"335.28200","27.94037","0.03046"
"335.61200","27.96787","0.03308"
"335.94200","27.99531","0.03333"
"336.27200","28.02288","0.03121"
"336.60200","28.05038","0.03431"
"336.93200","28.07782","0.03434"
"337.26200","28.10533","0.03427"
"337.59200","28.13283","0.03699"
"337.92200","28.16039","0.03605"
"338.25200","28.18789","0.03622"
"338.58200","28.21534","0.03807"
"338.91200","28.24284","0.03584"
"339.24200","28.27035","0.03528"
"339.57200","28.29779","0.03729"
"339.90200","28.32535","0.03595"
"340.23200","28.35286","0.03526"
"340.56200","28.38036","0.03690"
"340.89200","28.40792","0.03432"
"341.22200","28.43536","0.03588"
"341.55200","28.46287","0.03659"
"341.88200","28.49025","0.03381"
"342.21200","28.51788","0.03424"
"342.54200","28.54538","0.03499"
"342.87200","28.57282","0.03235"
"343.20200","28.60039","0.03352"
"343.53200","28.62783","0.03438"
"343.86200","28.65533","0.03346"
"344.19200","28.68289","0.03541"
"344.52200","28.71028","0.03650"
"344.85200","28.73790","0.03676"
"345.18200","28.76534","0.03783"
"345.51200","28.79291","0.03796"
"345.84200","28.82035","0.03744"
"346.17200","28.84779","0.03872"
"346.50200","28.87536","0.03918"
"346.83200","28.90286","0.03920"
"347.16200","28.93036","0.04041"
"347.49200","28.95786","0.04114"
"347.82200","28.98531","0.04098"
"348.15200","29.01281","0.04228"
"348.48200","29.04037","0.04343"
"348.81200","29.06788","0.04269"
"349.14200","29.09532","0.04408"
"349.47200","29.12283","0.04460"
"349.80200","29.15039","0.04431"
"350.13200","29.17789","0.04563"
"350.46200","29.20534","0.04622"
"350.79200","29.23290","0.04598"
"351.12200","29.26040","0.04629"
"351.45200","29.28784","0.04668"
"351.78200","29.31535","0.04709"
"352.11200","29.34285","0.04710"
"352.44200","29.37035","0.04822"
"352.77200","29.39786","0.04803"
"353.10200","29.42536","0.04831"
"353.43200","29.45292","0.04888"
"353.76200","29.48037","0.04752"
"354.09200","29.50787","0.04608"
"354.42200","29.53537","0.04589"
"354.75200","29.56281","0.04527"
"355.08200","29.59038","0.04484"
"355.41200","29.61782","0.04616"
"355.74200","29.64539","0.04613"
"356.07200","29.67283","0.04597"
"356.40200","29.70033","0.04695"
"356.73200","29.72789","0.04689"
"357.06200","29.75534","0.04772"
"357.39200","29.78284","0.04819"
"357.72200","29.81040","0.04834"
"358.05200","29.83785","0.04824"
"358.38200","29.86535","0.04869"
"358.71200","29.89291","0.04963"
"359.04200","29.92030","0.04968"
"359.37200","29.94786","0.05026"
"359.70200","29.97536","0.05072"
"360.03200","30.00287","0.05068"
"360.36200","30.03037","0.05106"
"360.69200","30.05781","0.05093"
"361.02200","30.08538","0.05165"
"361.35200","30.11282","0.05214"
"361.68200","30.14032","0.05232"
"362.01200","30.16788","0.05291"
"362.34200","30.19533","0.05304"
"362.67200","30.22283","0.05324"
"363.00200","30.25034","0.05409"
"363.33200","30.27784","0.05386"
"363.66200","30.30540","0.05456"
"363.99200","30.33284","0.02583"
"364.32200","30.36035","0.03008"
"364.65200","30.38791","0.02463"
"364.98200","30.41536","0.01505"
"365.31200","30.44286","0.02416"
"365.64200","30.47030","0.03858"
"365.97200","30.49781","0.02671"
"366.30200","30.52543","0.02755"
"366.63200","30.55281","0.02261"
"366.96200","30.58038","0.02532"
"367.29200","30.60788","0.04147"
"367.62200","30.63532","0.02899"
"367.95200","30.66282","0.02845"
"368.28200","30.69033","0.03045"
"368.61200","30.71789","0.02770"
"368.94200","30.74539","0.03869"
"369.27200","30.77283","0.03870"
"369.60200","30.80040","0.03579"
"369.93200","30.82784","0.03249"
"370.26200","30.85535","0.03613"
"370.59200","30.88285","0.03487"
"370.92200","30.91029","0.03927"
"371.25200","30.93791","0.04600"
"371.58200","30.96530","0.03946"
"371.91200","30.99286","0.04406"
"372.24200","31.02036","0.04176"
"372.57200","31.04781","0.04013"
"372.90200","31.07537","0.04328"
"373.23200","31.10281","0.04470"
"373.56200","31.13032","0.04600"
"373.89200","31.15788","0.04654"
"374.22200","31.18533","0.04982"
"374.55200","31.21283","0.04677"
"374.88200","31.24039","0.04930"
"375.21200","31.26783","0.04865"
"375.54200","31.29540","0.04885"
"375.87200","31.32284","0.04790"
"376.20200","31.35034","0.05025"
"376.53200","31.37790","0.04905"
"376.86200","31.40529","0.04968"
"377.19200","31.43285","0.05043"
"377.52200","31.46041","0.05042"
"377.85200","31.48780","0.05009"
"378.18200","31.51536","0.05134"
"378.51200","31.54280","0.05159"
"378.84200","31.57037","0.05133"
"379.17400","31.59805","0.05205"
"379.50400","31.62549","0.05249"
"379.83400","31.65306","0.05182"
"380.16400","31.68056","0.05265"
"380.49400","31.70800","0.05304"
"380.82400","31.73557","0.05291"
"381.15400","31.76301","0.05305"
"381.48400","31.79051","0.05422"
"381.81400","31.81808","0.05435"
"382.14400","31.84552","0.05484"
"382.47400","31.87302","0.05513"
"382.80400","31.90052","0.05651"
"383.13400","31.92803","0.05591"
"383.46400","31.95553","0.05786"
"383.79400","31.98297","0.05803"
"384.12400","32.01054","0.05903"
"384.45400","32.03798","0.05908"
"384.78400","32.06548","0.06158"
"385.11400","32.09311","0.06181"
"385.44400","32.12049","0.06178"
"385.77400","32.14799","0.06261"
"386.10400","32.17556","0.06383"
"386.43400","32.20300","0.06559"
"386.76400","32.23056","0.06585"
"387.09400","32.25801","0.06922"
"387.42400","32.28557","0.06938"
"387.75400","32.31301","0.07062"
"388.08400","32.34045","0.07053"
"388.41400","32.36808","0.07296"
"388.74400","32.39552","0.07381"
"389.07400","32.42303","0.07426"
"389.40400","32.45059","0.07489"
"389.73400","32.47797","0.07524"
"390.06400","32.50554","0.07675"
"390.39400","32.53304","0.07674"
"390.72400","32.56054","0.07713"
"391.05400","32.58805","0.07905"
"391.38400","32.61549","0.07924"
"391.71400","32.64299","0.07981"
"392.04400","32.67056","0.08051"
"392.37400","32.69794","0.08219"
"392.70400","32.72556","0.08349"
"393.03400","32.75301","0.08389"
"393.36400","32.78045","0.08368"
"393.69400","32.80807","0.08365"
"394.02400","32.83551","0.08346"
"394.35400","32.86302","0.08550"
"394.68400","32.89052","0.08767"
"395.01400","32.91808","0.08874"
"395.34400","32.94553","0.06801"
"395.67400","32.97297","0.06945"
"396.00400","33.00059","0.07053"
"396.33400","33.02804","0.07126"
"396.66400","33.05548","0.07352"
"396.99400","33.08304","0.07462"
"397.32400","33.11055","0.07578"
"397.65400","33.13799","0.07688"
"397.98400","33.16555","0.07672"
"398.31400","33.19305","0.07701"
"398.64400","33.22050","0.07768"
"398.97400","33.24800","0.07921"
"399.30400","33.27551","0.06610"
"399.63400","33.30307","0.06122"
"399.96400","33.33045","0.06002"
"400.29400","33.35802","0.06168"
"400.62400","33.38552","0.06521"
"400.95400","33.41296","0.06642"
"401.28400","33.44052","0.06846"
"401.61400","33.46803","0.07041"
"401.94400","33.49553","0.07379"
"402.27400","33.52303","0.07534"
"402.60400","33.55054","0.07666"
"402.93400","33.57804","0.07922"
"403.26400","33.60548","0.08082"
"403.59400","33.63305","0.08234"
"403.92400","33.66061","0.08339"
"404.25400","33.68799","0.08610"
"404.58400","33.71556","0.08903"
"404.91400","33.74306","0.08948"
"405.24400","33.77050","0.09166"
"405.57400","33.79800","0.09349"
"405.90400","33.82551","0.09509"
"406.23400","33.85301","0.09711"
"406.56400","33.88052","0.09745"
"406.89400","33.90802","0.09865"
"407.22400","33.93552","0.09911"
"407.55400","33.96302","0.09937"
"407.88400","33.99053","0.10027"
"408.21400","34.01809","0.10074"
"408.54400","34.04548","0.10148"
"408.87400","34.07304","0.10221"
"409.20400","34.10054","0.10255"
"409.53400","34.12798","0.10284"
"409.86400","34.15555","0.10309"
"410.19400","34.18293","0.10309"
"410.52400","34.21056","0.10277"
"410.85400","34.23806","0.10359"
"411.18400","34.26550","0.10497"
"411.51400","34.29306","0.10751"
"411.84400","34.32045","0.10902"
"412.17400","34.34807","0.10989"
"412.50400","34.37551","0.11114"
"412.83400","34.40295","0.11403"
"413.16400","34.43052","0.11697"
"413.49400","34.45802","0.11937"
"413.82400","34.48553","0.12222"
"414.15400","34.51303","0.12360"
"414.48400","34.54053","0.12535"
"414.81400","34.56804","0.12653"
"415.14400","34.59554","0.12773"
"415.47400","34.62298","0.12861"
"415.80400","34.65060","0.12571"
"416.13400","34.67799","0.12775"
"416.46400","34.70555","0.12979"
"416.79400","34.73299","0.13109"
"417.12400","34.76050","0.13223"
"417.45400","34.78806","0.13305"
"417.78400","34.81551","0.13474"
"418.11400","34.84307","0.13519"
"418.44400","34.87057","0.13229"
"418.77400","34.89795","0.13420"
"419.10400","34.92558","0.13516"
"419.43400","34.95302","0.13529"
"419.76400","34.98053","0.13635"
"420.09400","35.00809","0.13736"
"420.42400","35.03547","0.13831"
"420.75400","35.06309","0.13899"
"421.08400","35.09048","0.13954"
"421.41400","35.11804","0.14059"
"421.74400","35.14554","0.14114"
"422.07400","35.17305","0.14191"
"422.40400","35.20055","0.14236"
"422.73400","35.22805","0.14269"
"423.06400","35.25544","0.14270"
"423.39400","35.28300","0.14300"
"423.72400","35.31050","0.14370"
"424.05400","35.33807","0.14396"
"424.38400","35.36551","0.14461"
"424.71400","35.39301","0.14503"
"425.04400","35.42051","0.14516"
"425.37400","35.44802","0.14555"
"425.70400","35.47552","0.14601"
"426.03400","35.50303","0.14650"
"426.36400","35.53047","0.14666"
"426.69400","35.55803","0.14704"
"427.02400","35.58553","0.14762"
"427.35400","35.61298","0.14828"
"427.68400","35.64054","0.14913"
"428.01400","35.66798","0.15076"
"428.34400","35.69555","0.14976"
"428.67400","35.72299","0.15089"
"429.00400","35.75049","0.15235"
"429.33600","35.77824","0.15411"
"429.66600","35.80568","0.15562"
"429.99600","35.83318","0.15772"
"430.32600","35.86068","0.15980"
"430.65600","35.88813","0.16038"
"430.98600","35.91569","0.16027"
"431.31600","35.94320","0.16113"
"431.64600","35.97064","0.16226"
"431.97600","35.99820","0.16510"
"432.30600","36.02570","0.16704"
"432.63600","36.05326","0.16981"
"432.96600","36.08071","0.17317"
"433.29600","36.10822","0.17627"
"433.62600","36.13572","0.17855"
"433.95600","36.16316","0.17901"
"434.28600","36.19066","0.18216"
"434.61600","36.21823","0.18553"
"434.94600","36.24567","0.18805"
"435.27600","36.27324","0.19075"
"435.60600","36.30074","0.19469"
"435.93600","36.32818","0.19269"
"436.26600","36.35568","0.19642"
"436.59600","36.38313","0.19830"
"436.92600","36.41075","0.20054"
"437.25600","36.43825","0.20141"
"437.58600","36.46564","0.20302"
"437.91600","36.49320","0.20280"
"438.24600","36.52064","0.20393"
"438.57600","36.54815","0.20398"
"438.90600","36.57571","0.20454"
"439.23600","36.60315","0.20503"
"439.56600","36.63071","0.20536"
"439.89600","36.65816","0.20622"
"440.22600","36.68572","0.20664"
"440.55600","36.71322","0.20734"
"440.88600","36.74067","0.20823"
"441.21600","36.76823","0.20906"
"441.54600","36.79568","0.20948"
"441.87600","36.82312","0.21076"
"442.20600","36.85074","0.21198"
"442.53600","36.87819","0.21329"
"442.86600","36.90569","0.21484"
"443.19600","36.93319","0.21604"
"443.52600","36.96069","0.21737"
"443.85600","36.98819","0.21919"
"444.18600","37.01570","0.22013"
"444.51600","37.04320","0.22119"
"444.84600","37.07071","0.22216"
"445.17600","37.09809","0.22352"
"445.50600","37.12577","0.22483"
"445.83600","37.15321","0.22563"
"446.16600","37.18066","0.22707"
"446.49600","37.20822","0.22872"
"446.82600","37.23566","0.22946"
"447.15600","37.26317","0.23071"
"447.48600","37.29067","0.23297"
"447.81600","37.31817","0.23436"
"448.14600","37.34568","0.23660"
"448.47600","37.37318","0.23753"
"448.80600","37.40075","0.23870"
"449.13600","37.42825","0.23927"
"449.46600","37.45557","0.24031"
"449.79600","37.48319","0.24127"
"450.12600","37.51070","0.24234"
"450.45600","37.53820","0.24286"
"450.78600","37.56577","0.24328"
"451.11600","37.59315","0.24422"
"451.44600","37.62065","0.24498"
"451.77600","37.64815","0.24605"
"452.10600","37.67566","0.24712"
"452.43600","37.70322","0.24785"
"452.76600","37.73066","0.24832"
"453.09600","37.75823","0.24924"
"453.42600","37.78573","0.24991"
"453.75600","37.81311","0.25098"
"454.08600","37.84074","0.25170"
"454.41600","37.86824","0.25279"
"454.74600","37.89568","0.25336"
"455.07600","37.92325","0.25411"
"455.40600","37.95069","0.25466"
"455.73600","37.97819","0.25563"
"456.06600","38.00570","0.25614"
"456.39600","38.03314","0.25784"
"456.72600","38.06070","0.25775"
"457.05600","38.08815","0.25874"
"457.38600","38.11571","0.26024"
"457.71600","38.14321","0.26139"
"458.04600","38.17065","0.26293"
"458.37600","38.19822","0.26473"
"458.70600","38.22572","0.26541"
"459.03600","38.25323","0.26657"
"459.36600","38.28067","0.26898"
"459.69600","38.30817","0.27068"
"460.02600","38.33567","0.27206"
"460.35600","38.36318","0.27445"
"460.68600","38.39068","0.27685"
"461.01600","38.41824","0.27817"
"461.34600","38.44569","0.27947"
"461.67600","38.47319","0.28074"
"462.00600","38.50075","0.28180"
"462.33600","38.52814","0.00177"
"462.66600","38.55570","0.01115"
"462.99600","38.58320","-0.00089"
"463.32600","38.61070","0.00182"
"463.65600","38.63821","0.00594"
"463.98600","38.66565","0.00633"
"464.31600","38.69321","0.00323"
"464.64600","38.72066","0.00255"
"464.97600","38.74816","0.00410"
"465.30600","38.77572","0.00430"
"465.63600","38.80317","0.00342"
"465.96600","38.83073","0.00321"
"466.29600","38.85818","0.00229"
"466.62600","38.88568","0.00392"
"466.95600","38.91318","0.00429"
"467.28600","38.94062","0.00459"
"467.61600","38.96813","0.00307"
"467.94600","38.99569","0.00336"
"468.27600","39.02319","0.00393"
"468.60600","39.05070","0.00459"
"468.93600","39.07820","0.00335"
"469.26600","39.10564","0.00234"
"469.59600","39.13321","0.00294"
"469.92600","39.16065","0.00481"
"470.25600","39.18821","0.00439"
"470.58600","39.21572","0.00362"
"470.91600","39.24322","0.00338"
"471.24600","39.27072","0.00522"
"471.57600","39.29816","0.00393"
"471.90600","39.32573","0.00296"
"472.23600","39.35323","0.00182"
"472.56600","39.38068","0.00329"
"472.89600","39.40817","0.00444"
"473.22600","39.43568","0.00353"
"473.55600","39.46318","0.00246"
"473.88600","39.49069","0.00357"
"474.21600","39.51819","0.00491"
"474.54600","39.54575","0.00377"
"474.87600","39.57320","0.00283"
"475.20600","39.60064","0.00373"
"475.53600","39.62820","0.00374"
"475.86600","39.65564","0.00366"
"476.19600","39.68321","0.00381"
"476.52600","39.71072","0.00353"
"476.85600","39.73816","0.00381"
"477.18600","39.76566","0.00312"
"477.51600","39.79316","0.00415"
"477.84600","39.82073","0.00410"
"478.17600","39.84817","0.00345"
"478.50600","39.87567","0.00342"
"478.83600","39.90323","0.00365"
"479.16600","39.93074","0.00326"
"479.49600","39.95818","0.00394"
"479.82600","39.98569","0.00334"
"480.15600","40.01313","0.00370"
"480.48600","40.04069","0.00408"
"480.81600","40.06820","0.00364"
"481.14600","40.09570","0.00287"
"481.47600","40.12320","0.00355"
"481.80600","40.15070","0.00403"
"482.13600","40.17821","0.00446"
"482.46600","40.20565","0.00283"
"482.79600","40.23315","0.00344"
"483.12600","40.26072","0.00416"
"483.45600","40.28822","0.00425"
"483.78600","40.31567","0.00361"
"484.11600","40.34322","0.00323"
"484.44600","40.37067","0.00400"
"484.77600","40.39817","0.00396"
"485.10600","40.42568","0.00377"
"485.43600","40.45318","0.00342"
"485.76600","40.48069","0.00402"
"486.09600","40.50812","0.00454"
"486.42600","40.53574","0.00370"
"486.75600","40.56319","0.00407"
"487.08600","40.59069","0.00348"
"487.41600","40.61820","0.00384"
"487.74600","40.64570","0.00351"
"488.07600","40.67315","0.00379"
"488.40600","40.70070","0.00404"
"488.73600","40.72815","0.00393"
"489.06600","40.75571","0.00357"
"489.39600","40.78316","0.00382"
"489.66400","40.80552","0.00391"