File: Force_trajectories/170225_1/Specimen_RawData_1.csv
End date,"2/25/2017"
Specimen label,"2AT_11"
Maximum Load,"0.12005",N

Time,Extension,Load
(s),(mm),(N)
"0.00000","0.00000","-0.00002"
"0.27000","0.02158","-0.00020"
"0.54000","0.04520","0.00056"
"0.81000","0.06768","0.00077"
"1.08000","0.09016","0.00063"
"1.35000","0.11270","0.00032"
"1.62000","0.13512","0.00103"
"1.89000","0.15766","0.00115"
"2.16000","0.18009","0.00104"
"2.43000","0.20269","0.00150"
"2.70000","0.22511","0.00111"
"2.97000","0.24765","0.00091"
"3.24000","0.27007","0.00161"
"3.51000","0.29267","0.00190"
"3.78000","0.31515","0.00161"
"4.05000","0.33769","0.00195"
"4.32000","0.36011","0.00180"
"4.59000","0.38265","0.00217"
"4.86000","0.40513","0.00225"
"5.13000","0.42761","0.00221"
"5.40000","0.45004","0.00237"
"5.67000","0.47264","0.00233"
"5.94000","0.49506","0.00261"
"6.21000","0.51766","0.00304"
"6.48000","0.54008","0.00314"
"6.75000","0.56256","0.00326"
"7.02000","0.58510","0.00343"
"7.29000","0.60758","0.00298"
"7.56000","0.63006","0.00348"
"7.83000","0.65266","0.00373"
"8.10000","0.67514","0.00366"
"8.37000","0.69762","0.00355"
"8.64000","0.72005","0.00349"
"8.91000","0.74259","0.00351"
"9.18000","0.76507","0.00387"
"9.45000","0.78761","0.00369"
"9.72000","0.81009","0.00408"
"9.99000","0.83263","0.00366"
"10.26000","0.85511","0.00386"
"10.53000","0.87759","0.00427"
"10.80000","0.90007","0.00432"
"11.07000","0.92261","0.00442"
"11.34000","0.94509","0.00452"
"11.61000","0.96757","0.00424"
"11.88000","0.99005","0.00449"
"12.15000","1.01266","0.00477"
"12.42000","1.03508","0.00507"
"12.69000","1.05762","0.00474"
"12.96000","1.08004","0.00481"
"13.23000","1.10264","0.00456"
"13.50000","1.12506","0.00479"
"13.77000","1.14766","0.00559"
"14.04000","1.17008","0.00484"
"14.31000","1.19262","0.00543"
"14.58000","1.21510","0.00555"
"14.85000","1.23764","0.00562"
"15.12000","1.26006","0.00550"
"15.39000","1.28266","0.00560"
"15.66000","1.30503","0.00596"
"15.93000","1.32757","0.00591"
"16.20000","1.35005","0.00618"
"16.47000","1.37259","0.00657"
"16.74000","1.39513","0.00616"
"17.01000","1.41767","0.00625"
"17.28000","1.44009","0.00643"
"17.55000","1.46269","0.00602"
"17.82000","1.48505","0.00613"
"18.09000","1.50759","0.00606"
"18.36000","1.53001","0.00642"
"18.63000","1.55261","0.00633"
"18.90000","1.57510","0.00650"
"19.17000","1.59764","0.00666"
"19.44000","1.62012","0.00617"
"19.71000","1.64266","0.00700"
"19.98000","1.66508","0.00663"
"20.25000","1.68762","0.00720"
"20.52000","1.71004","0.00620"
"20.79000","1.73264","0.00705"
"21.06000","1.75500","0.00722"
"21.33000","1.77760","0.00752"
"21.60000","1.80002","0.00741"
"21.87000","1.82268","0.00736"
"22.14000","1.84510","0.00742"
"22.41000","1.86765","0.00780"
"22.68000","1.89007","0.00783"
"22.95000","1.91261","0.00765"
"23.22000","1.93503","0.00835"
"23.49000","1.95763","0.00780"
"23.76000","1.98011","0.00787"
"24.03000","2.00265","0.00752"
"24.30000","2.02507","0.00853"
"24.57000","2.04761","0.00803"
"24.84000","2.07003","0.00826"
"25.11000","2.09269","0.00873"
"25.38000","2.11511","0.00848"
"25.65000","2.13766","0.00851"
"25.92000","2.16008","0.00856"
"26.19000","2.18262","0.00878"
"26.46000","2.20510","0.00839"
"26.73000","2.22764","0.00842"
"27.00000","2.25006","0.00797"
"27.27000","2.27266","0.00864"
"27.54000","2.29508","0.00872"
"27.81000","2.31762","0.00878"
"28.08000","2.34004","0.00898"
"28.35000","2.36258","0.00890"
"28.62000","2.38512","0.00960"
"28.89000","2.40760","0.00960"
"29.16000","2.43003","0.00955"
"29.43000","2.45263","0.00941"
"29.70000","2.47505","0.01014"
"29.97000","2.49765","0.00968"
"30.24000","2.52007","0.00957"
"30.51000","2.54267","0.00955"
"30.78000","2.56509","0.01043"
"31.05000","2.58757","0.01001"
"31.32000","2.61011","0.00947"
"31.59000","2.63265","0.01013"
"31.86000","2.65501","0.01054"
"32.13000","2.67761","0.01092"
"32.40000","2.70010","0.01014"
"32.67000","2.72264","0.01052"
"32.94000","2.74512","0.01087"
"33.21000","2.76766","0.01129"
"33.48000","2.79008","0.01102"
"33.75000","2.81262","0.01098"
"34.02000","2.83504","0.01131"
"34.29000","2.85758","0.00987"
"34.56000","2.88006","0.00984"
"34.83000","2.90260","0.00995"
"35.10000","2.92508","0.01031"
"35.37000","2.94762","0.01020"
"35.64000","2.97010","0.01025"
"35.91000","2.99265","0.01027"
"36.18000","3.01513","0.01099"
"36.45000","3.03761","0.01106"
"36.72000","3.06009","0.01079"
"36.99000","3.08263","0.01155"
"37.26000","3.10511","0.01117"
"37.53000","3.12765","0.01168"
"37.80000","3.15013","0.01148"
"38.07000","3.17267","0.01163"
"38.34000","3.19503","0.01195"
"38.61000","3.21763","0.01185"
"38.88000","3.24005","0.01188"
"39.15000","3.26265","0.01186"
"39.42000","3.28508","0.01224"
"39.69000","3.30768","0.01249"
"39.96000","3.33016","0.01225"
"40.23000","3.35270","0.01272"
"40.50000","3.37512","0.01265"
"40.77000","3.39766","0.01258"
"41.04000","3.42008","0.01245"
"41.31000","3.44268","0.01242"
"41.58000","3.46510","0.01246"
"41.85000","3.48764","0.01226"
"42.12000","3.51012","0.01327"
"42.39000","3.53266","0.01305"
"42.66000","3.55515","0.01310"
"42.93000","3.57763","0.01285"
"43.20000","3.60005","0.01307"
"43.47000","3.62259","0.01349"
"43.74000","3.64507","0.01447"
"44.01000","3.66755","0.01433"
"44.28000","3.69009","0.01432"
"44.55000","3.71263","0.01397"
"44.82000","3.73511","0.01419"
"45.09000","3.75765","0.01382"
"45.36000","3.78007","0.01376"
"45.63000","3.80261","0.01414"
"45.90000","3.82515","0.01408"
"46.17000","3.84764","0.01476"
"46.44000","3.87012","0.01520"
"46.71000","3.89266","0.01460"
"46.98000","3.91508","0.01433"
"47.25000","3.93762","0.01492"
"47.52000","3.96010","0.01543"
"47.79000","3.98258","0.01479"
"48.06000","4.00512","0.01500"
"48.33000","4.02766","0.01560"
"48.60000","4.05008","0.01553"
"48.87000","4.07262","0.01548"
"49.14000","4.09516","0.01549"
"49.41000","4.11765","0.01604"
"49.68000","4.14013","0.01637"
"49.95000","4.16261","0.01653"
"50.22000","4.18515","0.01641"
"50.49000","4.20763","0.01700"
"50.76000","4.23011","0.01703"
"51.03000","4.25265","0.01736"
"51.30000","4.27513","0.01681"
"51.57000","4.29761","0.01729"
"51.84000","4.32009","0.01776"
"52.11000","4.34257","0.01762"
"52.38000","4.36511","0.01749"
"52.65000","4.38760","0.01752"
"52.92000","4.41014","0.01812"
"53.19000","4.43262","0.01864"
"53.46000","4.45510","0.01822"
"53.73000","4.47764","0.01887"
"54.00000","4.50012","0.01937"
"54.27000","4.52260","0.01936"
"54.54000","4.54514","0.01932"
"54.81000","4.56756","0.02019"
"55.08000","4.59016","0.02066"
"55.35000","4.61264","0.01794"
"55.62000","4.63512","0.01852"
"55.89000","4.65766","0.01882"
"56.16000","4.68015","0.01954"
"56.43000","4.70263","0.01978"
"56.70000","4.72505","0.01988"
"56.97000","4.74759","0.01990"
"57.24000","4.77013","0.02026"
"57.51000","4.79261","0.02041"
"57.78000","4.81515","0.02110"
"58.05000","4.83763","0.02171"
"58.32000","4.86011","0.02166"
"58.59000","4.88265","0.02154"
"58.86000","4.90513","0.02191"
"59.13000","4.92761","0.02230"
"59.40000","4.95010","0.02240"
"59.67000","4.97258","0.02213"
"59.94000","4.99512","0.02276"
"60.21000","5.01760","0.02340"
"60.48000","5.04014","0.02356"
"60.75000","5.06262","0.02363"
"61.02000","5.08516","0.02312"
"61.29000","5.10758","0.02290"
"61.56000","5.13012","0.02376"
"61.83000","5.15260","0.02424"
"62.10000","5.17514","0.02449"
"62.37000","5.19762","0.02396"
"62.64000","5.22016","0.02469"
"62.91000","5.24265","0.02451"
"63.18000","5.26519","0.02566"
"63.45000","5.28755","0.02483"
"63.72000","5.31015","0.02599"
"63.99000","5.33263","0.02607"
"64.26000","5.35517","0.02656"
"64.53000","5.37765","0.02655"
"64.80000","5.40019","0.02623"
"65.07000","5.42267","0.02729"
"65.34000","5.44509","0.02774"
"65.61000","5.46757","0.02746"
"65.88000","5.49011","0.02795"
"66.15000","5.51260","0.02781"
"66.42000","5.53514","0.02801"
"66.69000","5.55762","0.02870"
"66.96000","5.58010","0.02877"
"67.23000","5.60258","0.02865"
"67.50000","5.62512","0.02915"
"67.77000","5.64760","0.02845"
"68.04000","5.67014","0.02862"
"68.31000","5.69262","0.02881"
"68.58000","5.71510","0.02930"
"68.85000","5.73764","0.02929"
"69.12000","5.76012","0.02937"
"69.39000","5.78260","0.03010"
"69.66000","5.80515","0.02969"
"69.93000","5.82763","0.02958"
"70.20000","5.85017","0.03020"
"70.47000","5.87259","0.03041"
"70.74000","5.89513","0.03006"
"71.01000","5.91761","0.03090"
"71.28000","5.94015","0.03168"
"71.55000","5.96263","0.03119"
"71.82000","5.98517","0.03111"
"72.09000","6.00759","0.03215"
"72.36000","6.03019","0.03241"
"72.63000","6.05255","0.03162"
"72.90000","6.07515","0.03296"
"73.17000","6.09764","0.03210"
"73.44000","6.12018","0.03286"
"73.71000","6.14260","0.03313"
"73.98000","6.16514","0.03390"
"74.25000","6.18756","0.03331"
"74.52000","6.21010","0.03364"
"74.79000","6.23258","0.03383"
"75.06000","6.25512","0.03415"
"75.33000","6.27760","0.03340"
"75.60000","6.30008","0.03309"
"75.87000","6.32262","0.03305"
"76.14000","6.34516","0.03417"
"76.41000","6.36759","0.03388"
"76.68000","6.39019","0.03474"
"76.95000","6.41261","0.03420"
"77.22000","6.43509","0.03480"
"77.49000","6.45757","0.03459"
"77.76000","6.48011","0.03482"
"78.03000","6.50259","0.03513"
"78.30000","6.52513","0.03547"
"78.57000","6.54761","0.03562"
"78.84000","6.57021","0.03631"
"79.11000","6.59257","0.03647"
"79.38000","6.61511","0.03644"
"79.65000","6.63754","0.03655"
"79.92000","6.66008","0.03654"
"80.19000","6.68256","0.03703"
"80.46000","6.70510","0.03677"
"80.73000","6.72758","0.03701"
"81.00000","6.75018","0.03710"
"81.27000","6.77260","0.03737"
"81.54000","6.79520","0.03720"
"81.81000","6.81756","0.03595"
"82.08000","6.84010","0.03499"
"82.35000","6.86264","0.03464"
"82.62000","6.88512","0.03525"
"82.89000","6.90760","0.03607"
"83.16000","6.93015","0.03568"
"83.43000","6.95257","0.03585"
"83.70000","6.97517","0.03589"
"83.97000","6.99759","0.03672"
"84.24000","7.02013","0.03691"
"84.51000","7.04255","0.03710"
"84.78000","7.06509","0.03726"
"85.05000","7.08751","0.03753"
"85.32000","7.11011","0.03758"
"85.59000","7.13265","0.03791"
"85.86000","7.15519","0.03739"
"86.13000","7.17761","0.03825"
"86.40000","7.20009","0.03799"
"86.67000","7.22258","0.03846"
"86.94000","7.24512","0.03835"
"87.21000","7.26760","0.03876"
"87.48000","7.29014","0.03882"
"87.75000","7.31262","0.03785"
"88.02000","7.33516","0.03844"
"88.29000","7.35758","0.03860"
"88.56000","7.38012","0.03928"
"88.83000","7.40260","0.03873"
"89.10000","7.42508","0.03897"
"89.37000","7.44762","0.03915"
"89.64000","7.47010","0.03937"
"89.91000","7.49259","0.03994"
"90.18000","7.51513","0.03962"
"90.45000","7.53755","0.03966"
"90.72000","7.56015","0.03979"
"90.99000","7.58257","0.04015"
"91.26000","7.60517","0.04021"
"91.53000","7.62753","0.03985"
"91.80000","7.65013","0.03997"
"92.07000","7.67255","0.03998"
"92.34000","7.69515","0.04036"
"92.61000","7.71757","0.04056"
"92.88000","7.74011","0.04060"
"93.15000","7.76254","0.04055"
"93.42000","7.78508","0.04056"
"93.69000","7.80756","0.04067"
"93.96000","7.83010","0.04119"
"94.23000","7.85258","0.04128"
"94.50000","7.87518","0.04133"
"94.77000","7.89760","0.04103"
"95.04000","7.92014","0.04143"
"95.31000","7.94256","0.04172"
"95.58000","7.96510","0.04181"
"95.85000","7.98758","0.04128"
"96.12000","8.01012","0.04159"
"96.39000","8.03260","0.04136"
"96.66000","8.05515","0.04136"
"96.93000","8.07757","0.04152"
"97.20000","8.10017","0.04190"
"97.47000","8.12253","0.04177"
"97.74000","8.14513","0.04169"
"98.01000","8.16755","0.04173"
"98.28000","8.19009","0.04175"
"98.55000","8.21257","0.04170"
"98.82000","8.23511","0.04183"
"99.09000","8.25753","0.04194"
"99.36000","8.28013","0.04199"
"99.63000","8.30255","0.04202"
"99.90000","8.32515","0.04249"
"100.17000","8.34758","0.04238"
"100.44000","8.37012","0.04236"
"100.71000","8.39254","0.04258"
"100.98000","8.41514","0.04271"
"101.25000","8.43762","0.04283"
"101.52000","8.46016","0.04251"
"101.79000","8.48258","0.04306"
"102.06000","8.50518","0.04287"
"102.33000","8.52754","0.04305"
"102.60000","8.55014","0.04316"
"102.87000","8.57256","0.04296"
"103.14000","8.59510","0.04315"
"103.41000","8.61758","0.04318"
"103.68000","8.64019","0.04342"
"103.95000","8.66267","0.04368"
"104.22000","8.68515","0.04349"
"104.49000","8.70757","0.04415"
"104.76000","8.73011","0.04369"
"105.03000","8.75259","0.04404"
"105.30000","8.77513","0.04408"
"105.57000","8.79755","0.04399"
"105.84000","8.82015","0.04414"
"106.11000","8.84263","0.04396"
"106.38000","8.86517","0.04402"
"106.65000","8.88759","0.04452"
"106.92000","8.91014","0.04398"
"107.19000","8.93256","0.04456"
"107.46000","8.95510","0.04449"
"107.73000","8.97752","0.04454"
"108.00000","9.00012","0.04471"
"108.27000","9.02260","0.04494"
"108.54000","9.04520","0.04482"
"108.81000","9.06762","0.04518"
"109.08000","9.09016","0.04522"
"109.35000","9.11258","0.04538"
"109.62000","9.13512","0.04551"
"109.89000","9.15760","0.04556"
"110.16000","9.18014","0.04552"
"110.43000","9.20257","0.04544"
"110.70000","9.22511","0.04584"
"110.97000","9.24759","0.04584"
"111.24000","9.27013","0.04597"
"111.51000","9.29255","0.04641"
"111.78000","9.31509","0.04612"
"112.05000","9.33757","0.04626"
"112.32000","9.36011","0.04643"
"112.59000","9.38259","0.04667"
"112.86000","9.40513","0.04629"
"113.13000","9.42761","0.04700"
"113.40000","9.45010","0.04670"
"113.67000","9.47258","0.04708"
"113.94000","9.49512","0.04703"
"114.21000","9.51760","0.04735"
"114.48000","9.54014","0.04709"
"114.75000","9.56262","0.04717"
"115.02000","9.58516","0.04732"
"115.29000","9.60764","0.04756"
"115.56000","9.63012","0.04762"
"115.83000","9.65260","0.04769"
"116.10000","9.67514","0.04782"
"116.37000","9.69756","0.04818"
"116.64000","9.72010","0.04813"
"116.91000","9.74259","0.04835"
"117.18000","9.76513","0.04852"
"117.45000","9.78761","0.04864"
"117.72000","9.81015","0.04878"
"117.99000","9.83263","0.04935"
"118.26000","9.85511","0.04905"
"118.53000","9.87759","0.04938"
"118.80000","9.90019","0.05007"
"119.07000","9.92261","0.04958"
"119.34000","9.94515","0.04977"
"119.61000","9.96763","0.05027"
"119.88000","9.99017","0.05032"
"120.15000","10.01265","0.05024"
"120.42000","10.03508","0.05044"
"120.69000","10.05756","0.05093"
"120.96000","10.08010","0.05138"
"121.23000","10.10258","0.05121"
"121.50000","10.12506","0.05149"
"121.77000","10.14760","0.05192"
"122.04000","10.17008","0.05231"
"122.31000","10.19262","0.05241"
"122.58000","10.21510","0.05287"
"122.85000","10.23764","0.05237"
"123.12000","10.26012","0.05172"
"123.39000","10.28260","0.05197"
"123.66000","10.30509","0.05196"
"123.93000","10.32763","0.05256"
"124.20000","10.35017","0.05296"
"124.47000","10.37265","0.05323"
"124.74000","10.39513","0.05375"
"125.01000","10.41755","0.05432"
"125.28000","10.44009","0.05480"
"125.55000","10.46257","0.05506"
"125.82000","10.48517","0.05561"
"126.09000","10.50759","0.05575"
"126.36000","10.53013","0.05625"
"126.63000","10.55255","0.05643"
"126.90000","10.57515","0.05728"
"127.17000","10.59764","0.05812"
"127.44000","10.62018","0.05854"
"127.71000","10.64260","0.05881"
"127.98000","10.66508","0.05921"
"128.25000","10.68762","0.05976"
"128.52000","10.71010","0.06001"
"128.79000","10.73252","0.06041"
"129.06000","10.75518","0.06058"
"129.33000","10.77760","0.06079"
"129.60000","10.80008","0.06150"
"129.87000","10.82262","0.06182"
"130.14000","10.84510","0.06221"
"130.41000","10.86758","0.06283"
"130.68000","10.89007","0.06338"
"130.95000","10.91261","0.06218"
"131.22000","10.93515","0.06095"
"131.49000","10.95757","0.06119"
"131.76000","10.98017","0.06221"
"132.03000","11.00265","0.06232"
"132.30000","11.02507","0.06285"
"132.57000","11.04761","0.06299"
"132.84000","11.07015","0.06414"
"133.11000","11.09263","0.06426"
"133.38000","11.11511","0.06489"
"133.65000","11.13765","0.06562"
"133.92000","11.16014","0.06536"
"134.19000","11.18262","0.06580"
"134.46000","11.20510","0.06630"
"134.73000","11.22758","0.06657"
"135.00000","11.25012","0.06721"
"135.27000","11.27260","0.06734"
"135.54000","11.29514","0.06703"
"135.81000","11.31762","0.06794"
"136.08000","11.34010","0.06778"
"136.35000","11.36258","0.06853"
"136.62000","11.38506","0.06870"
"136.89000","11.40760","0.06960"
"137.16000","11.43014","0.06960"
"137.43000","11.45262","0.07059"
"137.70000","11.47511","0.07066"
"137.97000","11.49759","0.07076"
"138.24000","11.52013","0.07146"
"138.51000","11.54261","0.07188"
"138.78000","11.56509","0.07255"
"139.05000","11.58763","0.07290"
"139.32000","11.61011","0.07344"
"139.59000","11.63265","0.07151"
"139.86000","11.65513","0.07237"
"140.13000","11.67767","0.07305"
"140.40000","11.70015","0.07330"
"140.67000","11.72264","0.07353"
"140.94000","11.74512","0.07428"
"141.21000","11.76766","0.07499"
"141.48000","11.79014","0.07476"
"141.75000","11.81268","0.07556"
"142.02000","11.83510","0.07612"
"142.29000","11.85770","0.07647"
"142.56000","11.88012","0.07694"
"142.83000","11.90260","0.07865"
"143.10000","11.92502","0.07864"
"143.37000","11.94762","0.07973"
"143.64000","11.97004","0.08071"
"143.91000","11.99259","0.08119"
"144.18000","12.01512","0.08182"
"144.45000","12.03767","0.08144"
"144.72000","12.06009","0.07971"
"144.99000","12.08269","0.07955"
"145.26000","12.10517","0.08038"
"145.53000","12.12765","0.08138"
"145.80000","12.15007","0.08169"
"146.07000","12.17261","0.08166"
"146.34000","12.19509","0.08276"
"146.61000","12.21763","0.08292"
"146.88000","12.24011","0.08396"
"147.15000","12.26265","0.08428"
"147.42000","12.28508","0.08393"
"147.69000","12.30762","0.08543"
"147.96000","12.33010","0.08114"
"148.23000","12.35258","0.08142"
"148.50000","12.37506","0.08198"
"148.77000","12.39760","0.07995"
"149.04000","12.42008","0.08059"
"149.31000","12.44268","0.07333"
"149.58000","12.46510","0.07382"
"149.85000","12.48770","0.07354"
"150.12000","12.51012","0.07140"
"150.39000","12.53266","0.07128"
"150.66000","12.55509","0.06958"
"150.93000","12.57763","0.06775"
"151.20000","12.60011","0.06661"
"151.47000","12.62271","0.06708"
"151.74000","12.64513","0.05503"
"152.01000","12.66761","0.05520"
"152.28000","12.69009","0.05523"
"152.55000","12.71263","0.05536"
"152.82000","12.73505","0.05577"
"153.09000","12.75759","0.05708"
"153.36000","12.78007","0.05747"
"153.63000","12.80261","0.05871"
"153.90000","12.82509","0.05962"
"154.17000","12.84763","0.06021"
"154.44000","12.87006","0.06016"
"154.71000","12.89260","0.06125"
"154.98000","12.91508","0.06208"
"155.25000","12.93762","0.06199"
"155.52000","12.96010","0.06320"
"155.79000","12.98264","0.06242"
"156.06000","13.00512","0.06353"
"156.33000","13.02766","0.06289"
"156.60000","13.05008","0.06328"
"156.87000","13.07262","0.06469"
"157.14000","13.09504","0.06495"
"157.41000","13.11765","0.06544"
"157.68000","13.14007","0.06593"
"157.95000","13.16261","0.06660"
"158.22000","13.18509","0.06775"
"158.49000","13.20763","0.06732"
"158.76000","13.23005","0.06774"
"159.03000","13.25265","0.06833"
"159.30000","13.27507","0.06909"
"159.57000","13.29761","0.06908"
"159.84000","13.32009","0.06599"
"160.11000","13.34263","0.06703"
"160.38000","13.36505","0.06765"
"160.65000","13.38765","0.06752"
"160.92000","13.41013","0.06836"
"161.19000","13.43268","0.06853"
"161.46000","13.45510","0.06919"
"161.73000","13.47758","0.06880"
"162.00000","13.50012","0.06941"
"162.27000","13.52260","0.07009"
"162.54000","13.54508","0.07031"
"162.81000","13.56762","0.07162"
"163.08000","13.59010","0.07151"
"163.35000","13.61264","0.07185"
"163.62000","13.63512","0.07230"
"163.89000","13.65760","0.07285"
"164.16000","13.68008","0.07384"
"164.43000","13.70262","0.07393"
"164.70000","13.72511","0.07451"
"164.97000","13.74765","0.07499"
"165.24000","13.77013","0.07534"
"165.51000","13.79273","0.07623"
"165.78000","13.81509","0.07673"
"166.05000","13.83763","0.07799"
"166.32000","13.86005","0.07746"
"166.59000","13.88259","0.07796"
"166.86000","13.90507","0.07894"
"167.13000","13.92761","0.07999"
"167.40000","13.95009","0.08112"
"167.67000","13.97269","0.08217"
"167.94000","13.99506","0.08308"
"168.21000","14.01760","0.08410"
"168.48000","14.04008","0.08434"
"168.75000","14.06262","0.08496"
"169.02000","14.08504","0.08615"
"169.29000","14.10758","0.08663"
"169.56000","14.13006","0.08691"
"169.83000","14.15260","0.08813"
"170.10000","14.17508","0.08831"
"170.37000","14.19762","0.08767"
"170.64000","14.22010","0.08768"
"170.91000","14.24264","0.08844"
"171.18000","14.26507","0.08645"
"171.45000","14.28761","0.08721"
"171.72000","14.31009","0.08778"
"171.99000","14.33263","0.08823"
"172.26000","14.35511","0.08863"
"172.53000","14.37765","0.08937"
"172.80000","14.40013","0.08955"
"173.07000","14.42261","0.08990"
"173.34000","14.44503","0.08474"
"173.61000","14.46763","0.08386"
"173.88000","14.49005","0.08140"
"174.15000","14.51265","0.06603"
"174.42000","14.53508","0.05537"
"174.69000","14.55762","0.05161"
"174.96000","14.58004","0.04757"
"175.23000","14.60264","0.04740"
"175.50000","14.62506","0.04731"
"175.77000","14.64766","0.04803"
"176.04000","14.67008","0.04758"
"176.31000","14.69262","0.04978"
"176.58000","14.71504","0.04823"
"176.85000","14.73770","0.05004"
"177.12000","14.76012","0.04905"
"177.39000","14.78266","0.04992"
"177.66000","14.80509","0.05057"
"177.93000","14.82768","0.05088"
"178.20000","14.85005","0.05225"
"178.47000","14.87265","0.05005"
"178.74000","14.89507","0.04942"
"179.01000","14.91761","0.04819"
"179.28000","14.94009","0.04919"
"179.55000","14.96257","0.04915"
"179.82000","14.98505","0.04848"
"180.09000","15.00759","0.04811"
"180.36000","15.03007","0.04707"
"180.63000","15.05261","0.04779"
"180.90000","15.07510","0.02350"
"181.17000","15.09769","0.02767"
"181.44000","15.12012","0.02056"
"181.71000","15.14260","0.02912"
"181.98000","15.16508","0.02273"
"182.25000","15.18762","0.02602"
"182.52000","15.21010","0.02806"
"182.79000","15.23264","0.02736"
"183.06000","15.25512","0.02833"
"183.33000","15.27766","0.03034"
"183.60000","15.30008","0.02942"
"183.87000","15.32262","0.03107"
"184.14000","15.34510","0.03139"
"184.41000","15.36764","0.03123"
"184.68000","15.39006","0.03239"
"184.95000","15.41261","0.03302"
"185.22000","15.43503","0.03341"
"185.49000","15.45763","0.03455"
"185.76000","15.48011","0.03504"
"186.03000","15.50265","0.03501"
"186.30000","15.52513","0.03562"
"186.57000","15.54767","0.03622"
"186.84000","15.57009","0.03635"
"187.11000","15.59263","0.02250"
"187.38000","15.61505","0.02270"
"187.65000","15.63765","0.02160"
"187.92000","15.66013","0.02268"
"188.19000","15.68268","0.02232"
"188.46000","15.70510","0.02373"
"188.73000","15.72764","0.02335"
"189.00000","15.75006","0.02463"
"189.27000","15.77260","0.02410"
"189.54000","15.79508","0.02277"
"189.81000","15.81768","0.02745"
"190.08000","15.84010","0.02698"
"190.35000","15.86264","0.02232"
"190.62000","15.88512","0.02263"
"190.89000","15.90766","0.02299"
"191.16000","15.93008","0.02275"
"191.43000","15.95262","0.02393"
"191.70000","15.97505","0.02328"
"191.97000","15.99765","0.02489"
"192.24000","16.02013","0.02371"
"192.51000","16.04261","0.02414"
"192.78000","16.06515","0.02511"
"193.05000","16.08763","0.02566"
"193.32000","16.11011","0.02629"
"193.59000","16.13265","0.02724"
"193.86000","16.15507","0.02726"
"194.13000","16.17761","0.02709"
"194.40000","16.20003","0.02794"
"194.67000","16.22263","0.02811"
"194.94000","16.24505","0.02882"
"195.21000","16.26766","0.02974"
"195.48000","16.29014","0.02962"
"195.75000","16.31268","0.03045"
"196.02000","16.33510","0.02979"
"196.29000","16.35764","0.03124"
"196.56000","16.38006","0.03168"
"196.83000","16.40260","0.03200"
"197.10000","16.42508","0.03250"
"197.37000","16.44762","0.03281"
"197.64000","16.47010","0.03276"
"197.91000","16.49265","0.03429"
"198.18000","16.51506","0.03349"
"198.45000","16.53761","0.03473"
"198.72000","16.56009","0.03468"
"198.99000","16.58263","0.03494"
"199.26000","16.60505","0.03558"
"199.53000","16.62765","0.03653"
"199.80000","16.65013","0.03686"
"200.07000","16.67261","0.03708"
"200.34000","16.69509","0.03721"
"200.61000","16.71763","0.03705"
"200.88000","16.74011","0.03779"
"201.15000","16.76265","0.03785"
"201.42000","16.78513","0.03873"
"201.69000","16.80767","0.03870"
"201.96000","16.83016","0.03910"
"202.23000","16.85264","0.03885"
"202.50000","16.87512","0.03927"
"202.77000","16.89760","0.03913"
"203.04000","16.92008","0.03994"
"203.31000","16.94262","0.04001"
"203.58000","16.96510","0.04035"
"203.85000","16.98764","0.04067"
"204.12000","17.01012","0.04063"
"204.39000","17.03266","0.04116"
"204.66000","17.05514","0.04100"
"204.93000","17.07763","0.04124"
"205.20000","17.10011","0.04115"
"205.47000","17.12259","0.04131"
"205.74000","17.14513","0.04212"
"206.01000","17.16767","0.04211"
"206.28000","17.19009","0.04228"
"206.55000","17.21263","0.04263"
"206.82000","17.23511","0.04282"
"207.09000","17.25759","0.04275"
"207.36000","17.28013","0.04293"
"207.63000","17.30261","0.04344"
"207.90000","17.32509","0.04349"
"208.17000","17.34757","0.04372"
"208.44000","17.37011","0.04408"
"208.71000","17.39260","0.04415"
"208.98000","17.41520","0.04435"
"209.25000","17.43762","0.04457"
"209.52000","17.46010","0.04467"
"209.79000","17.48258","0.04457"
"210.06000","17.50512","0.04485"
"210.33000","17.52760","0.04487"
"210.60000","17.55014","0.04525"
"210.87000","17.57262","0.04530"
"211.14000","17.59510","0.04562"
"211.41000","17.61758","0.04590"
"211.68000","17.64013","0.04614"
"211.95000","17.66261","0.04618"
"212.22000","17.68509","0.04643"
"212.49000","17.70757","0.04646"
"212.76000","17.73011","0.04661"
"213.03000","17.75259","0.04678"
"213.30000","17.77513","0.04710"
"213.57000","17.79761","0.04735"
"213.84000","17.82009","0.04697"
"214.11000","17.84263","0.04762"
"214.38000","17.86511","0.04784"
"214.65000","17.88759","0.04806"
"214.92000","17.91013","0.04823"
"215.19000","17.93261","0.04897"
"215.46000","17.95510","0.04904"
"215.73000","17.97764","0.04897"
"216.00000","18.00012","0.04991"
"216.27000","18.02260","0.05068"
"216.54000","18.04514","0.05060"
"216.81000","18.06762","0.05123"
"217.08000","18.09016","0.05152"
"217.35000","18.11258","0.05214"
"217.62000","18.13518","0.05236"
"217.89000","18.15760","0.05262"
"218.16000","18.18014","0.05339"
"218.43000","18.20256","0.05373"
"218.70000","18.22511","0.05421"
"218.97000","18.24764","0.05452"
"219.24000","18.27019","0.05551"
"219.51000","18.29261","0.05589"
"219.78000","18.31515","0.05433"
"220.05000","18.33763","0.05423"
"220.32000","18.36011","0.05458"
"220.59000","18.38259","0.02934"
"220.86000","18.40507","0.03685"
"221.13000","18.42755","0.03592"
"221.40000","18.45009","0.03885"
"221.67000","18.47257","0.03895"
"221.94000","18.49512","0.03840"
"222.21000","18.51760","0.03349"
"222.48000","18.54014","0.03663"
"222.75000","18.56256","0.03581"
"223.02000","18.58510","0.03676"
"223.29000","18.60764","0.03852"
"223.56000","18.63012","0.03746"
"223.83000","18.65260","0.03849"
"224.10000","18.67514","0.03923"
"224.37000","18.69762","0.03989"
"224.64000","18.72016","0.03957"
"224.91000","18.74258","0.03924"
"225.18000","18.76512","0.03964"
"225.45000","18.78755","0.04002"
"225.72000","18.81009","0.04027"
"225.99000","18.83257","0.04109"
"226.26000","18.85517","0.04127"
"226.53000","18.87759","0.04121"
"226.80000","18.90019","0.04146"
"227.07000","18.92255","0.04194"
"227.34000","18.94515","0.04271"
"227.61000","18.96757","0.04238"
"227.88000","18.99011","0.04315"
"228.15000","19.01259","0.04310"
"228.42000","19.03514","0.04376"
"228.69000","19.05762","0.04347"
"228.96000","19.08015","0.04421"
"229.23000","19.10258","0.04439"
"229.50000","19.12518","0.04445"
"229.77000","19.14760","0.04477"
"230.04000","19.17008","0.04550"
"230.31000","19.19256","0.04567"
"230.58000","19.21510","0.04593"
"230.85000","19.23758","0.04619"
"231.12000","19.26012","0.04638"
"231.39000","19.28260","0.04714"
"231.66000","19.30520","0.04729"
"231.93000","19.32762","0.04769"
"232.20000","19.35011","0.04789"
"232.47000","19.37265","0.04840"
"232.74000","19.39513","0.04873"
"233.01000","19.41761","0.04896"
"233.28000","19.44009","0.04935"
"233.55000","19.46257","0.04998"
"233.82000","19.48517","0.05049"
"234.09000","19.50765","0.05043"
"234.36000","19.53013","0.02470"
"234.63000","19.55261","0.02146"
"234.90000","19.57515","0.01837"
"235.17000","19.59751","0.02184"
"235.44000","19.62012","0.02259"
"235.71000","19.64254","0.02206"
"235.98000","19.66514","0.02263"
"236.25000","19.68762","0.02340"
"236.52000","19.71016","0.02534"
"236.79000","19.73258","0.02538"
"237.06000","19.75512","0.02949"
"237.33000","19.77760","0.02525"
"237.60000","19.80014","0.02988"
"237.87000","19.82256","0.02658"
"238.14000","19.84510","0.02866"
"238.41000","19.86753","0.03105"
"238.68000","19.89012","0.02888"
"238.95000","19.91261","0.03212"
"239.22000","19.93509","0.03135"
"239.49000","19.95763","0.03239"
"239.76000","19.98011","0.03166"
"240.03000","20.00253","0.03397"
"240.30000","20.02513","0.03256"
"240.57000","20.04761","0.03525"
"240.84000","20.07015","0.03329"
"241.11000","20.09263","0.03539"
"241.38000","20.11511","0.03565"
"241.65000","20.13759","0.03652"
"241.92000","20.16014","0.03586"
"242.19000","20.18262","0.03732"
"242.46000","20.20515","0.03651"
"242.73000","20.22764","0.03767"
"243.00000","20.25018","0.03789"
"243.27000","20.27260","0.03815"
"243.54000","20.29508","0.03788"
"243.81000","20.31756","0.03904"
"244.08000","20.34010","0.03878"
"244.35000","20.36258","0.03920"
"244.62000","20.38512","0.03952"
"244.89000","20.40754","0.04011"
"245.16000","20.43014","0.04024"
"245.43000","20.45256","0.04042"
"245.70000","20.47517","0.04085"
"245.97000","20.49753","0.04092"
"246.24000","20.52007","0.04121"
"246.51000","20.54255","0.04145"
"246.78000","20.56515","0.04174"
"247.05000","20.58757","0.04173"
"247.32000","20.61011","0.04194"
"247.59000","20.63253","0.04237"
"247.86000","20.65513","0.04222"
"248.13000","20.67755","0.04270"
"248.40000","20.70009","0.04303"
"248.67000","20.72251","0.04291"
"248.94000","20.74512","0.02646"
"249.21000","20.76760","0.01029"
"249.48000","20.79014","0.01848"
"249.75000","20.81262","0.01300"
"250.02000","20.83516","0.01569"
"250.29000","20.85758","0.01683"
"250.56000","20.88012","0.01331"
"250.83000","20.90254","0.01814"
"251.10000","20.92514","0.01344"
"251.37000","20.94756","0.01851"
"251.64000","20.97010","0.01417"
"251.91000","20.99258","0.01704"
"252.18000","21.01518","0.01718"
"252.45000","21.03761","0.01494"
"252.72000","21.06009","0.01734"
"252.99000","21.08251","0.01510"
"253.26000","21.10511","0.01805"
"253.53000","21.12753","0.01583"
"253.80000","21.15019","0.01818"
"254.07000","21.17255","0.01772"
"254.34000","21.19515","0.01678"
"254.61000","21.21763","0.01901"
"254.88000","21.24017","0.01758"
"255.15000","21.26253","0.01972"
"255.42000","21.28519","0.01847"
"255.69000","21.30755","0.01917"
"255.96000","21.33016","0.01916"
"256.23000","21.35257","0.01926"
"256.50000","21.37518","0.02025"
"256.77000","21.39760","0.01916"
"257.04000","21.42014","0.02047"
"257.31000","21.44256","0.02037"
"257.58000","21.46510","0.02072"
"257.85000","21.48758","0.02112"
"258.12000","21.51012","0.02106"
"258.39000","21.53254","0.02149"
"258.66000","21.55515","0.02136"
"258.93000","21.57756","0.02171"
"259.20000","21.60011","0.02200"
"259.47000","21.62259","0.02246"
"259.74000","21.64513","0.02294"
"260.01000","21.66755","0.02166"
"260.28000","21.69015","0.02245"
"260.55000","21.71263","0.02323"
"260.82000","21.73511","0.02305"
"261.09000","21.75759","0.02359"
"261.36000","21.78013","0.02386"
"261.63000","21.80261","0.02380"
"261.90000","21.82515","0.02307"
"262.17000","21.84757","0.02358"
"262.44000","21.87018","0.02403"
"262.71000","21.89254","0.02483"
"262.98000","21.91514","0.02430"
"263.25000","21.93762","0.02491"
"263.52000","21.96016","0.02472"
"263.79000","21.98258","0.02445"
"264.06000","22.00512","0.02512"
"264.33000","22.02754","0.02522"
"264.60000","22.05014","0.02618"
"264.87000","22.07262","0.02616"
"265.14000","22.09516","0.02625"
"265.41000","22.11758","0.02688"
"265.68000","22.14013","0.02757"
"265.95000","22.16261","0.02624"
"266.22000","22.18515","0.02731"
"266.49000","22.20757","0.02789"
"266.76000","22.23011","0.02792"
"267.03000","22.25259","0.02767"
"267.30000","22.27513","0.02776"
"267.57000","22.29761","0.02907"
"267.84000","22.32015","0.02890"
"268.11000","22.34263","0.02886"
"268.38000","22.36511","0.03035"
"268.65000","22.38754","0.02989"
"268.92000","22.41007","0.02980"
"269.19000","22.43255","0.03060"
"269.46000","22.45516","0.03148"
"269.73000","22.47758","0.03175"
"270.00000","22.50018","0.03191"
"270.27000","22.52260","0.03249"
"270.54000","22.54514","0.03273"
"270.81000","22.56756","0.03338"
"271.08000","22.59010","0.03376"
"271.35000","22.61252","0.03365"
"271.62000","22.63512","0.03418"
"271.89000","22.65754","0.03434"
"272.16000","22.68014","0.03506"
"272.43000","22.70263","0.03518"
"272.70000","22.72516","0.03553"
"272.97000","22.74764","0.03568"
"273.24000","22.77013","0.03620"
"273.51000","22.79255","0.03567"
"273.78000","22.81509","0.03639"
"274.05000","22.83757","0.03639"
"274.32000","22.86011","0.03673"
"274.59000","22.88259","0.03690"
"274.86000","22.90519","0.03729"
"275.13000","22.92761","0.03722"
"275.40000","22.95009","0.03750"
"275.67000","22.97263","0.03786"
"275.94000","22.99517","0.03801"
"276.21000","23.01766","0.03883"
"276.48000","23.04014","0.03879"
"276.75000","23.06262","0.03893"
"277.02000","23.08510","0.03899"
"277.29000","23.10764","0.03963"
"277.56000","23.13018","0.04007"
"277.83000","23.15266","0.04027"
"278.10000","23.17514","0.04043"
"278.37000","23.19762","0.04014"
"278.64000","23.22010","0.04002"
"278.91000","23.24264","0.04041"
"279.18000","23.26518","0.04062"
"279.45000","23.28766","0.04061"
"279.72000","23.31014","0.04087"
"279.99000","23.33263","0.04073"
"280.26000","23.35511","0.04085"
"280.53000","23.37759","0.04149"
"280.80000","23.40007","0.04162"
"281.07000","23.42261","0.04182"
"281.34000","23.44515","0.04169"
"281.61000","23.46763","0.04154"
"281.88000","23.49017","0.04196"
"282.15000","23.51259","0.04237"
"282.42000","23.53513","0.04276"
"282.69000","23.55762","0.04295"
"282.96000","23.58010","0.04296"
"283.23000","23.60264","0.04322"
"283.50000","23.62512","0.04343"
"283.77000","23.64760","0.04358"
"284.04000","23.67008","0.04365"
"284.31000","23.69262","0.04404"
"284.58000","23.71510","0.04439"
"284.85000","23.73758","0.04470"
"285.12000","23.76006","0.04480"
"285.39000","23.78260","0.04544"
"285.66000","23.80508","0.04551"
"285.93000","23.82763","0.04568"
"286.20000","23.85011","0.04584"
"286.47000","23.87265","0.04600"
"286.74000","23.89513","0.04626"
"287.01000","23.91761","0.04650"
"287.28000","23.94009","0.04680"
"287.55000","23.96263","0.04723"
"287.82000","23.98511","0.04763"
"288.09000","24.00765","0.04755"
"288.36000","24.03013","0.04815"
"288.63000","24.05261","0.04886"
"288.90000","24.07515","0.04881"
"289.17000","24.09757","0.04919"
"289.44000","24.12005","0.04981"
"289.71000","24.14254","0.05069"
"289.98000","24.16508","0.05114"
"290.25000","24.18762","0.05161"
"290.52000","24.21016","0.05290"
"290.79000","24.23264","0.05401"
"291.06000","24.25512","0.05429"
"291.33000","24.27760","0.05512"
"291.60000","24.30014","0.05627"
"291.87000","24.32262","0.05697"
"292.14000","24.34510","0.05781"
"292.41000","24.36764","0.05854"
"292.68000","24.39012","0.05931"
"292.95000","24.41261","0.05944"
"293.22000","24.43515","0.06027"
"293.49000","24.45763","0.06177"
"293.76000","24.48005","0.06200"
"294.03000","24.50259","0.06265"
"294.30000","24.52501","0.06489"
"294.57000","24.54761","0.06503"
"294.84000","24.57003","0.06547"
"295.11000","24.59263","0.06685"
"295.38000","24.61511","0.06794"
"295.65000","24.63765","0.06947"
"295.92000","24.66007","0.06987"
"296.19000","24.68267","0.07107"
"296.46000","24.70509","0.07166"
"296.73000","24.72764","0.07308"
"297.00000","24.75006","0.07388"
"297.27000","24.77266","0.07482"
"297.54000","24.79508","0.07545"
"297.81000","24.81762","0.07647"
"298.08000","24.84010","0.07674"
"298.35000","24.86264","0.07808"
"298.62000","24.88512","0.07864"
"298.89000","24.90760","0.08095"
"299.16000","24.93008","0.08143"
"299.43000","24.95262","0.08233"
"299.70000","24.97511","0.08382"
"299.97000","24.99765","0.08436"
"300.24000","25.02013","0.08556"
"300.51000","25.04267","0.08669"
"300.78000","25.06515","0.08754"
"301.05000","25.08763","0.08769"
"301.32000","25.11005","0.08819"
"301.59000","25.13265","0.08862"
"301.86000","25.15507","0.08881"
"302.13000","25.17767","0.08917"
"302.40000","25.20009","0.08983"
"302.67000","25.22264","0.09000"
"302.94000","25.24505","0.09081"
"303.21000","25.26759","0.09142"
"303.48000","25.29008","0.09208"
"303.75000","25.31262","0.09258"
"304.02000","25.33510","0.09289"
"304.29000","25.35764","0.09341"
"304.56000","25.38012","0.09453"
"304.83000","25.40266","0.09516"
"305.10000","25.42508","0.09588"
"305.37000","25.44762","0.09710"
"305.64000","25.47010","0.09838"
"305.91000","25.49264","0.09981"
"306.18000","25.51506","0.10272"
"306.45000","25.53767","0.10284"
"306.72000","25.56009","0.10517"
"306.99000","25.58263","0.10539"
"307.26000","25.60505","0.10766"
"307.53000","25.62765","0.10860"
"307.80000","25.65007","0.11021"
"308.07000","25.67261","0.11225"
"308.34000","25.69509","0.11308"
"308.61000","25.71757","0.11403"
"308.88000","25.74005","0.11502"
"309.15000","25.76265","0.11678"
"309.42000","25.78513","0.11621"
"309.69000","25.80762","0.11792"
"309.96000","25.83004","0.11904"
"310.23000","25.85257","0.11961"
"310.50000","25.87512","0.11977"
"310.77000","25.89766","0.01169"
"311.04000","25.92008","0.00833"
"311.31000","25.94268","0.01594"
"311.58000","25.96510","0.00025"
"311.85000","25.98758","0.01437"
"312.12000","26.01006","0.00902"
"312.39000","26.03266","0.00761"
"312.66000","26.05514","0.01660"
"312.93000","26.07763","0.00402"
"313.20000","26.10010","0.01402"
"313.47000","26.12265","0.00704"
"313.74000","26.14513","0.01005"
"314.01000","26.16767","0.00893"
"314.28000","26.19009","0.00853"
"314.55000","26.21263","0.01259"
"314.82000","26.23505","0.00575"
"315.09000","26.25759","0.01508"
"315.36000","26.28001","0.00808"
"315.63000","26.30261","0.00913"
"315.90000","26.32509","0.01487"
"316.17000","26.34763","0.00662"
"316.44000","26.37012","0.01327"
"316.71000","26.39259","0.01014"
"316.98000","26.41507","0.00996"
"317.25000","26.43762","0.01278"
"317.52000","26.46010","0.00948"
"317.79000","26.48264","0.01374"
"318.06000","26.50512","0.01061"
"318.33000","26.52766","0.01166"
"318.60000","26.55014","0.01185"
"318.87000","26.57262","0.01049"
"319.14000","26.59510","0.01440"
"319.41000","26.61765","0.01050"
"319.68000","26.64013","0.01279"
"319.95000","26.66260","0.01364"
"320.22000","26.68509","0.01051"
"320.49000","26.70763","0.01504"
"320.76000","26.73010","0.01195"
"321.03000","26.75265","0.01402"
"321.30000","26.77507","0.01473"
"321.57000","26.79761","0.01183"
"321.84000","26.82003","0.01530"
"322.11000","26.84257","0.01304"
"322.38000","26.86505","0.01364"
"322.65000","26.88765","0.01520"
"322.92000","26.91007","0.01270"
"323.19000","26.93268","0.01507"
"323.46000","26.95509","0.01417"
"323.73000","26.97764","0.01418"
"324.00000","27.00006","0.01599"
"324.27000","27.02260","0.01364"
"324.54000","27.04502","0.01619"
"324.81000","27.06762","0.01532"
"325.08000","27.09010","0.01458"
"325.35000","27.11264","0.01654"
"325.62000","27.13506","0.01400"
"325.89000","27.15760","0.01568"
"326.16000","27.18002","0.01608"
"326.43000","27.20263","0.01515"
"326.70000","27.22505","0.01666"
"326.97000","27.24759","0.01564"
"327.24000","27.27007","0.01631"
"327.51000","27.29261","0.01714"
"327.78000","27.31503","0.01566"
"328.05000","27.33763","0.01688"
"328.32000","27.36005","0.01635"
"328.59000","27.38265","0.01716"
"328.86000","27.40507","0.01694"
"329.13000","27.42761","0.01542"
"329.40000","27.45009","0.01639"
"329.67000","27.47263","0.01676"
"329.94000","27.49505","0.01554"
"330.21000","27.51760","0.01760"
"330.48000","27.54002","0.01715"
"330.75000","27.56262","0.01718"
"331.02000","27.58504","0.01720"
"331.29000","27.60764","0.01768"
"331.56000","27.63006","0.01854"
"331.83000","27.65266","0.01774"
"332.10000","27.67514","0.01791"
"332.37000","27.69762","0.01814"
"332.64000","27.72004","0.01759"
"332.91000","27.74264","0.01909"
"333.18000","27.76506","0.01905"
"333.45000","27.78766","0.01829"
"333.72000","27.81008","0.01922"
"333.99000","27.83263","0.01892"
"334.26000","27.85511","0.01919"
"334.53000","27.87765","0.01897"
"334.80000","27.90007","0.01847"
"335.07000","27.92261","0.01827"
"335.34000","27.94509","0.01857"
"335.61000","27.96757","0.01900"
"335.88000","27.99005","0.01920"
"336.15000","28.01265","0.01850"
"336.42000","28.03507","0.01867"
"336.69000","28.05761","0.01855"
"336.96000","28.08010","0.01912"
"337.23000","28.10264","0.01984"
"337.50000","28.12506","0.01987"
"337.77000","28.14766","0.02062"
"338.04000","28.17008","0.02041"
"338.31000","28.19268","0.01983"
"338.58000","28.21510","0.02057"
"338.85000","28.23764","0.02033"
"339.12000","28.26006","0.02083"
"339.39000","28.28260","0.02112"
"339.66000","28.30508","0.02098"
"339.93000","28.32763","0.02088"
"340.20000","28.35010","0.01995"
"340.47000","28.37258","0.02058"
"340.74000","28.39507","0.02074"
"341.01000","28.41761","0.02134"
"341.28000","28.44009","0.02112"
"341.55000","28.46269","0.02166"
"341.82000","28.48505","0.02111"
"342.09000","28.50759","0.02177"
"342.36000","28.53007","0.02135"
"342.63000","28.55267","0.02188"
"342.90000","28.57509","0.02212"
"343.17000","28.59763","0.02158"
"343.44000","28.62011","0.02201"
"343.71000","28.64266","0.02184"
"343.98000","28.66508","0.02222"
"344.25000","28.68761","0.02248"
"344.52000","28.71010","0.02148"
"344.79000","28.73264","0.02179"
"345.06000","28.75512","0.02181"
"345.33000","28.77760","0.02255"
"345.60000","28.80008","0.02290"
"345.87000","28.82262","0.02277"
"346.14000","28.84510","0.02356"
"346.41000","28.86764","0.02388"
"346.68000","28.89006","0.02484"
"346.95000","28.91260","0.02425"
"347.22000","28.93508","0.02539"
"347.49000","28.95763","0.02495"
"347.76000","28.98011","0.02527"
"348.03000","29.00265","0.02483"
"348.30000","29.02507","0.02565"
"348.57000","29.04761","0.02587"
"348.84000","29.07009","0.02665"
"349.11000","29.09263","0.02688"
"349.38000","29.11511","0.02778"
"349.65000","29.13765","0.02705"
"349.92000","29.16007","0.02757"
"350.19000","29.18267","0.02854"
"350.46000","29.20509","0.02832"
"350.73000","29.22764","0.02893"
"351.00000","29.25011","0.02920"
"351.27000","29.27260","0.02901"
"351.54000","29.29508","0.03023"
"351.81000","29.31762","0.03016"
"352.08000","29.34010","0.03064"
"352.35000","29.36264","0.03084"
"352.62000","29.38512","0.03087"
"352.89000","29.40766","0.03055"
"353.16000","29.43008","0.03019"
"353.43000","29.45256","0.02992"
"353.70000","29.47505","0.02971"
"353.97000","29.49758","0.02576"
"354.24000","29.52013","0.02242"
"354.51000","29.54267","0.02266"
"354.78000","29.56515","0.02540"
"355.05000","29.58769","0.02251"
"355.32000","29.61011","0.02298"
"355.59000","29.63259","0.02484"
"355.86000","29.65513","0.02183"
"356.13000","29.67767","0.02410"
"356.40000","29.70009","0.02377"
"356.67000","29.72264","0.02353"
"356.94000","29.74517","0.02535"
"357.21000","29.76765","0.02425"
"357.48000","29.79014","0.02338"
"357.75000","29.81256","0.02527"
"358.02000","29.83504","0.02475"
"358.29000","29.85764","0.02428"
"358.56000","29.88012","0.02610"
"358.83000","29.90266","0.02384"
"359.10000","29.92508","0.02573"
"359.37000","29.94768","0.02634"
"359.64000","29.97010","0.02533"
"359.91000","29.99264","0.02737"
"360.18000","30.01512","0.02731"
"360.45000","30.03760","0.02651"
"360.72000","30.06009","0.02765"
"360.99000","30.08262","0.02791"
"361.26000","30.10511","0.02784"
"361.53000","30.12765","0.02810"
"361.80000","30.15013","0.02812"
"362.07000","30.17261","0.02855"
"362.34000","30.19509","0.02954"
"362.61000","30.21757","0.02984"
"362.88000","30.24011","0.02939"
"363.15000","30.26259","0.02857"
"363.42000","30.28507","0.02924"
"363.69000","30.30761","0.03002"
"363.96000","30.33009","0.02637"
"364.23000","30.35264","0.02534"
"364.50000","30.37518","0.02533"
"364.77000","30.39760","0.02602"
"365.04000","30.42014","0.02650"
"365.31000","30.44262","0.02578"
"365.58000","30.46516","0.02695"
"365.85000","30.48764","0.02737"
"366.12000","30.51012","0.02760"
"366.39000","30.53266","0.02892"
"366.66000","30.55508","0.02841"
"366.93000","30.57756","0.02968"
"367.20000","30.60004","0.02975"
"367.47000","30.62259","0.03045"
"367.74000","30.64512","0.03105"
"368.01000","30.66761","0.03096"
"368.28000","30.69015","0.03157"
"368.55000","30.71263","0.03204"
"368.82000","30.73511","0.03292"
"369.09000","30.75759","0.03350"
"369.36000","30.78013","0.03378"
"369.63000","30.80261","0.03380"
"369.90000","30.82515","0.03480"
"370.17000","30.84764","0.03362"
"370.44000","30.87017","0.02824"
"370.71000","30.89265","0.02961"
"370.98000","30.91514","0.02965"
"371.25000","30.93756","0.02813"
"371.52000","30.96010","0.02964"
"371.79000","30.98258","0.02869"
"372.06000","31.00512","0.02871"
"372.33000","31.02760","0.03044"
"372.60000","31.05014","0.02897"
"372.87000","31.07262","0.02779"
"373.14000","31.09516","0.02745"
"373.41000","31.11758","0.02677"
"373.68000","31.14012","0.02809"
"373.95000","31.16254","0.02759"
"374.22000","31.18515","0.02707"
"374.49000","31.20762","0.02861"
"374.76000","31.23017","0.02782"
"375.03000","31.25258","0.02873"
"375.30000","31.27519","0.02864"
"375.57000","31.29761","0.02833"
"375.84000","31.32009","0.02848"
"376.11000","31.34257","0.02927"
"376.38000","31.36517","0.02940"
"376.65000","31.38765","0.03022"
"376.92000","31.41013","0.02998"
"377.19000","31.43261","0.03014"
"377.46000","31.45515","0.02922"
"377.73000","31.47763","0.03022"
"378.00000","31.50018","0.03006"
"378.27000","31.52259","0.03013"
"378.54000","31.54514","0.03054"
"378.81000","31.56762","0.03110"
"379.08000","31.59010","0.03103"
"379.35000","31.61258","0.03118"
"379.62000","31.63518","0.03118"
"379.89000","31.65760","0.03060"
"380.16000","31.68014","0.03163"
"380.43000","31.70256","0.03201"
"380.70000","31.72510","0.03165"
"380.97000","31.74758","0.03204"
"381.24000","31.77012","0.03228"
"381.51000","31.79260","0.03225"
"381.78000","31.81515","0.03241"
"382.05000","31.83757","0.03265"
"382.32000","31.86017","0.03286"
"382.59000","31.88259","0.03319"
"382.86000","31.90519","0.03351"
"383.13000","31.92755","0.03416"
"383.40000","31.95009","0.03440"
"383.67000","31.97257","0.03382"
"383.94000","31.99511","0.03348"
"384.21000","32.01759","0.03472"
"384.48000","32.04013","0.03459"
"384.75000","32.06256","0.03455"
"385.02000","32.08516","0.03502"
"385.29000","32.10758","0.03548"
"385.56000","32.13012","0.03585"
"385.83000","32.15260","0.03564"
"386.10000","32.17508","0.03591"
"386.37000","32.19756","0.03608"
"386.64000","32.22016","0.03652"
"386.91000","32.24264","0.03682"
"387.18000","32.26518","0.03669"
"387.45000","32.28760","0.03691"
"387.72000","32.31014","0.03678"
"387.99000","32.33263","0.03729"
"388.26000","32.35516","0.03726"
"388.53000","32.37759","0.03730"
"388.80000","32.40013","0.03760"
"389.07000","32.42261","0.03762"
"389.34000","32.44515","0.03795"
"389.61000","32.46757","0.03811"
"389.88000","32.49011","0.03794"
"390.15000","32.51259","0.03805"
"390.42000","32.53513","0.03853"
"390.69000","32.55761","0.03836"
"390.96000","32.58015","0.03878"
"391.23000","32.60263","0.03881"
"391.50000","32.62512","0.03920"
"391.77000","32.64753","0.03974"
"392.04000","32.67014","0.03932"
"392.31000","32.69262","0.03970"
"392.58000","32.71516","0.03972"
"392.85000","32.73758","0.03981"
"393.12000","32.76012","0.03996"
"393.39000","32.78254","0.04071"
"393.66000","32.80514","0.04025"
"393.93000","32.82756","0.04065"
"394.20000","32.85010","0.04072"
"394.47000","32.87259","0.04085"
"394.74000","32.89507","0.04117"
"395.01000","32.91755","0.04174"
"395.28000","32.94015","0.04134"
"395.55000","32.96257","0.04188"
"395.82000","32.98516","0.04168"
"396.09000","33.00759","0.04196"
"396.36000","33.03007","0.04213"
"396.63000","33.05255","0.04226"
"396.90000","33.07509","0.04225"
"397.17000","33.09757","0.04252"
"397.44000","33.12011","0.04255"
"397.71000","33.14259","0.04258"
"397.98000","33.16513","0.04273"
"398.25000","33.18755","0.04303"
"398.52000","33.21016","0.04316"
"398.79000","33.23258","0.04330"
"399.06000","33.25512","0.04345"
"399.33000","33.27754","0.04376"
"399.60000","33.30014","0.04365"
"399.87000","33.32256","0.04382"
"400.08200","33.34032","0.04437"