File: Force_trajectories/170225_1/Specimen_RawData_8.csv
End date,"2/25/2017"
Specimen label,"5CG_33"
Maximum Load,"0.06402",N

Time,Extension,Load
(s),(mm),(N)
"0.00000","0.00000","-0.00011"
"0.32400","0.02685","0.00065"
"0.64800","0.05423","0.00037"
"0.97200","0.08125","0.00074"
"1.29600","0.10828","0.00044"
"1.62000","0.13518","0.00087"
"1.94400","0.16227","0.00116"
"2.26800","0.18923","0.00121"
"2.59200","0.21626","0.00153"
"2.91600","0.24322","0.00145"
"3.24000","0.27019","0.00120"
"3.56400","0.29721","0.00144"
"3.88800","0.32424","0.00189"
"4.21200","0.35126","0.00204"
"4.53600","0.37823","0.00201"
"4.86000","0.40519","0.00191"
"5.18400","0.43228","0.00179"
"5.50800","0.45918","0.00218"
"5.83200","0.48621","0.00219"
"6.15600","0.51323","0.00240"
"6.48000","0.54020","0.00268"
"6.80400","0.56728","0.00291"
"7.12800","0.59419","0.00250"
"7.45200","0.62121","0.00271"
"7.77600","0.64824","0.00242"
"8.10000","0.67514","0.00253"
"8.42400","0.70223","0.00284"
"8.74800","0.72925","0.00301"
"9.07200","0.75622","0.00321"
"9.39600","0.78330","0.00325"
"9.72000","0.81021","0.00347"
"10.04400","0.83723","0.00393"
"10.36800","0.86420","0.00370"
"10.69200","0.89122","0.00333"
"11.01600","0.91825","0.00368"
"11.34000","0.94521","0.00370"
"11.66400","0.97224","0.00391"
"11.98800","0.99920","0.00361"
"12.31200","1.02623","0.00419"
"12.63600","1.05331","0.00417"
"12.96000","1.08010","0.00396"
"13.28400","1.10724","0.00510"
"13.60800","1.13421","0.00424"
"13.93200","1.16123","0.00545"
"14.25600","1.18820","0.00526"
"14.58000","1.21510","0.00500"
"14.90400","1.24225","0.00465"
"15.22800","1.26927","0.00507"
"15.55200","1.29624","0.00545"
"15.87600","1.32320","0.00531"
"16.20000","1.35017","0.00583"
"16.52400","1.37725","0.00600"
"16.84800","1.40422","0.00512"
"17.17200","1.43118","0.00546"
"17.49600","1.45821","0.00567"
"17.82000","1.48517","0.00576"
"18.14400","1.51220","0.00594"
"18.46800","1.53922","0.00681"
"18.79200","1.56619","0.00635"
"19.11600","1.59321","0.00602"
"19.44000","1.62018","0.00667"
"19.76400","1.64720","0.00641"
"20.08800","1.67423","0.00624"
"20.41200","1.70119","0.00650"
"20.73600","1.72822","0.00657"
"21.06000","1.75512","0.00702"
"21.38400","1.78227","0.00684"
"21.70800","1.80923","0.00698"
"22.03200","1.83620","0.00716"
"22.35600","1.86322","0.00711"
"22.68000","1.89019","0.00720"
"23.00400","1.91721","0.00787"
"23.32800","1.94418","0.00780"
"23.65200","1.97120","0.00798"
"23.97600","1.99829","0.00751"
"24.30000","2.02519","0.00767"
"24.62400","2.05228","0.00754"
"24.94800","2.07924","0.00828"
"25.27200","2.10615","0.00839"
"25.59600","2.13323","0.00794"
"25.92000","2.16014","0.00813"
"26.24400","2.18722","0.00862"
"26.56800","2.21425","0.00846"
"26.89200","2.24121","0.00875"
"27.21600","2.26818","0.00852"
"27.54000","2.29520","0.00867"
"27.86400","2.32223","0.00855"
"28.18800","2.34925","0.00878"
"28.51200","2.37616","0.00854"
"28.83600","2.40324","0.00868"
"29.16000","2.43021","0.00920"
"29.48400","2.45717","0.00905"
"29.80800","2.48426","0.00878"
"30.13200","2.51122","0.00925"
"30.45600","2.53819","0.00959"
"30.78000","2.56515","0.00887"
"31.10400","2.59224","0.00929"
"31.42800","2.61926","0.00962"
"31.75200","2.64616","0.00974"
"32.07600","2.67325","0.01007"
"32.40000","2.70021","0.00955"
"32.72400","2.72724","0.00988"
"33.04800","2.75420","0.01017"
"33.37200","2.78117","0.01030"
"33.69600","2.80825","0.01025"
"34.02000","2.83516","0.01098"
"34.34400","2.86224","0.01053"
"34.66800","2.88927","0.01058"
"34.99200","2.91623","0.01094"
"35.31600","2.94326","0.01091"
"35.64000","2.97016","0.01148"
"35.96400","2.99719","0.01069"
"36.28800","3.02427","0.01151"
"36.61200","3.05124","0.01173"
"36.93600","3.07826","0.01183"
"37.26000","3.10523","0.01181"
"37.58400","3.13225","0.01263"
"37.90800","3.15928","0.01245"
"38.23200","3.18618","0.01168"
"38.55600","3.21321","0.00991"
"38.88000","3.24023","0.01112"
"39.20400","3.26720","0.01094"
"39.52800","3.29428","0.01093"
"39.85200","3.32113","0.01048"
"40.17600","3.34827","0.01242"
"40.50000","3.37524","0.01186"
"40.82400","3.40220","0.01279"
"41.14800","3.42923","0.01183"
"41.47200","3.45625","0.01199"
"41.79600","3.48328","0.01260"
"42.12000","3.51024","0.01249"
"42.44400","3.53721","0.01204"
"42.76800","3.56423","0.01220"
"43.09200","3.59120","0.01318"
"43.41600","3.61816","0.01357"
"43.74000","3.64519","0.01340"
"44.06400","3.67221","0.01387"
"44.38800","3.69924","0.01411"
"44.71200","3.72614","0.01428"
"45.03600","3.75323","0.01529"
"45.36000","3.78019","0.01540"
"45.68400","3.80722","0.01541"
"46.00800","3.83424","0.01573"
"46.33200","3.86121","0.01605"
"46.65600","3.88823","0.01611"
"46.98000","3.91526","0.01656"
"47.30400","3.94222","0.01551"
"47.62800","3.96925","0.01567"
"47.95200","3.99615","0.01532"
"48.27600","4.02324","0.01366"
"48.60000","4.05020","0.01380"
"48.92400","4.07723","0.01378"
"49.24800","4.10425","0.01265"
"49.57200","4.13116","0.01376"
"49.89600","4.15824","0.01426"
"50.22000","4.18527","0.01441"
"50.54400","4.21223","0.01474"
"50.86800","4.23920","0.01522"
"51.19200","4.26610","0.01554"
"51.51600","4.29325","0.01573"
"51.84000","4.32021","0.01563"
"52.16400","4.34718","0.01634"
"52.48800","4.37420","0.01708"
"52.81200","4.40123","0.01703"
"53.13600","4.42825","0.01728"
"53.46000","4.45522","0.01741"
"53.78400","4.48218","0.01705"
"54.10800","4.50927","0.01727"
"54.43200","4.53617","0.01769"
"54.75600","4.56326","0.01812"
"55.08000","4.59028","0.01847"
"55.40400","4.61719","0.01864"
"55.72800","4.64421","0.01892"
"56.05200","4.67118","0.01958"
"56.37600","4.69826","0.01963"
"56.70000","4.72529","0.01982"
"57.02400","4.75219","0.02049"
"57.34800","4.77922","0.02044"
"57.67200","4.80618","0.02090"
"57.99600","4.83327","0.02094"
"58.32000","4.86029","0.02154"
"58.64400","4.88720","0.02176"
"58.96800","4.91422","0.02197"
"59.29200","4.94119","0.02200"
"59.61600","4.96821","0.02248"
"59.94000","4.99524","0.02219"
"60.26400","5.02226","0.02300"
"60.58800","5.04923","0.02302"
"60.91200","5.07613","0.02342"
"61.23600","5.10322","0.02417"
"61.56000","5.13030","0.02454"
"61.88400","5.15721","0.02462"
"62.20800","5.18423","0.02530"
"62.53200","5.21120","0.02600"
"62.85600","5.23822","0.02615"
"63.18000","5.26525","0.02706"
"63.50400","5.29215","0.02681"
"63.82800","5.31924","0.02737"
"64.15200","5.34620","0.02816"
"64.47600","5.37329","0.02801"
"64.80000","5.40025","0.02797"
"65.12400","5.42716","0.02846"
"65.44800","5.45424","0.02981"
"65.77200","5.48121","0.02975"
"66.09600","5.50817","0.03127"
"66.42000","5.53520","0.03111"
"66.74400","5.56216","0.03168"
"67.06800","5.58924","0.03267"
"67.39200","5.61621","0.03289"
"67.71600","5.64330","0.03305"
"68.04000","5.67026","0.03363"
"68.36400","5.69717","0.03474"
"68.68800","5.72419","0.03439"
"69.01200","5.75115","0.03340"
"69.33600","5.77824","0.03438"
"69.66000","5.80526","0.03571"
"69.98400","5.83217","0.03668"
"70.30800","5.85920","0.03701"
"70.63200","5.88622","0.03720"
"70.95600","5.91319","0.03765"
"71.28000","5.94021","0.03839"
"71.60400","5.96717","0.03846"
"71.92800","5.99426","0.03966"
"72.25200","6.02122","0.03900"
"72.57600","6.04819","0.03962"
"72.90000","6.07527","0.03959"
"73.22400","6.10218","0.04015"
"73.54800","6.12920","0.04121"
"73.87200","6.15623","0.04140"
"74.19600","6.18319","0.03995"
"74.52000","6.21028","0.04041"
"74.84400","6.23712","0.04018"
"75.16800","6.26427","0.04095"
"75.49200","6.29123","0.02872"
"75.81600","6.31820","0.02716"
"76.14000","6.34516","0.02415"
"76.46400","6.37219","0.02342"
"76.78800","6.39927","0.02398"
"77.11200","6.42624","0.02469"
"77.43600","6.45320","0.02531"
"77.76000","6.48023","0.02560"
"78.08400","6.50719","0.02668"
"78.40800","6.53422","0.02714"
"78.73200","6.56118","0.02739"
"79.05600","6.58821","0.02782"
"79.38000","6.61523","0.02859"
"79.70400","6.64220","0.02940"
"80.02800","6.66922","0.02946"
"80.35200","6.69625","0.03041"
"80.67600","6.72321","0.03176"
"81.00000","6.75018","0.03277"
"81.32400","6.77714","0.03339"
"81.64800","6.80423","0.03419"
"81.97200","6.83125","0.03499"
"82.29600","6.85822","0.03518"
"82.62000","6.88530","0.03556"
"82.94400","6.91221","0.03601"
"83.26800","6.93923","0.03439"
"83.59200","6.96620","0.03486"
"83.91600","6.99316","0.03548"
"84.24000","7.02025","0.03672"
"84.56400","7.04715","0.03793"
"84.88800","7.07424","0.03854"
"85.21200","7.10126","0.03826"
"85.53600","7.12823","0.03970"
"85.86000","7.15519","0.03919"
"86.18400","7.18216","0.04047"
"86.50800","7.20924","0.04097"
"86.83200","7.23621","0.04177"
"87.15600","7.26323","0.04239"
"87.48000","7.29026","0.04277"
"87.80400","7.31722","0.04230"
"88.12800","7.34425","0.04351"
"88.45200","7.37121","0.04469"
"88.77600","7.39818","0.04422"
"89.10000","7.42526","0.04549"
"89.42400","7.45223","0.04554"
"89.74800","7.47919","0.04587"
"90.07200","7.50622","0.04585"
"90.39600","7.53324","0.04706"
"90.72000","7.56021","0.04738"
"91.04400","7.58723","0.04797"
"91.36800","7.61426","0.04793"
"91.69200","7.64128","0.04890"
"92.01600","7.66819","0.04917"
"92.34000","7.69521","0.04956"
"92.66400","7.72224","0.05005"
"92.98800","7.74932","0.05009"
"93.31200","7.77623","0.04991"
"93.63600","7.80319","0.05005"
"93.96000","7.83022","0.04880"
"94.28400","7.85718","0.04885"
"94.60800","7.88421","0.04936"
"94.93200","7.91129","0.04841"
"95.25600","7.93820","0.04760"
"95.58000","7.96522","0.04719"
"95.90400","7.99219","0.04670"
"96.22800","8.01915","0.04778"
"96.55200","8.04624","0.04827"
"96.87600","8.07320","0.04856"
"97.20000","8.10023","0.04886"
"97.52400","8.12719","0.04901"
"97.84800","8.15428","0.04916"
"98.17200","8.18124","0.04873"
"98.49600","8.20821","0.04966"
"98.82000","8.23523","0.05047"
"99.14400","8.26220","0.05031"
"99.46800","8.28922","0.05109"
"99.79200","8.31625","0.05078"
"100.11600","8.34315","0.05150"
"100.44000","8.37024","0.05167"
"100.76400","8.39720","0.05181"
"101.08800","8.42422","0.05266"
"101.41200","8.45125","0.05244"
"101.73600","8.47822","0.05295"
"102.06000","8.50524","0.05332"
"102.38400","8.53221","0.05355"
"102.70800","8.55923","0.05404"
"103.03200","8.58626","0.05409"
"103.35600","8.61316","0.05443"
"103.68000","8.64019","0.05431"
"104.00400","8.66715","0.05456"
"104.32800","8.69423","0.05499"
"104.65200","8.72126","0.05490"
"104.97600","8.74817","0.05485"
"105.30000","8.77525","0.05513"
"105.62400","8.80227","0.05548"
"105.94800","8.82918","0.05577"
"106.27200","8.85627","0.05600"
"106.59600","8.88317","0.05617"
"106.92000","8.91020","0.05619"
"107.24400","8.93722","0.05518"
"107.56800","8.96418","0.05532"
"107.89200","8.99127","0.05529"
"108.21600","9.01817","0.05573"
"108.54000","9.04520","0.05560"
"108.86400","9.07216","0.05618"
"109.18800","9.09919","0.05620"
"109.51200","9.12621","0.05634"
"109.83600","9.15318","0.05643"
"110.16000","9.18026","0.05706"
"110.48400","9.20723","0.05705"
"110.80800","9.23419","0.05729"
"111.13200","9.26122","0.05773"
"111.45600","9.28813","0.05811"
"111.78000","9.31521","0.05841"
"112.10400","9.34223","0.05860"
"112.42800","9.36920","0.05841"
"112.75200","9.39622","0.05894"
"113.07600","9.42325","0.05935"
"113.40000","9.45021","0.05945"
"113.72400","9.47718","0.05995"
"114.04800","9.50414","0.06052"
"114.37200","9.53123","0.06103"
"114.69600","9.55819","0.06137"
"115.02000","9.58522","0.06165"
"115.34400","9.61224","0.06238"
"115.66800","9.63921","0.06265"
"115.99200","9.66623","0.06357"
"116.31600","9.69314","0.06132"
"116.64000","9.72022","0.06192"
"116.96400","9.74725","0.06306"
"117.28800","9.77421","0.06320"
"117.61200","9.80124","0.02397"
"117.93600","9.82820","0.01176"
"118.26000","9.85529","0.01220"
"118.58400","9.88225","0.01327"
"118.90800","9.90922","0.00904"
"119.23200","9.93624","0.01227"
"119.55600","9.96321","0.01630"
"119.88000","9.99017","0.01198"
"120.20400","10.01726","0.01213"
"120.52800","10.04422","0.01499"
"120.85200","10.07125","0.01388"
"121.17600","10.09815","0.01341"
"121.50000","10.12518","0.01344"
"121.82400","10.15226","0.01581"
"122.14800","10.17917","0.01480"
"122.47200","10.20619","0.01469"
"122.79600","10.23322","0.01596"
"123.12000","10.26024","0.01635"
"123.44400","10.28727","0.01631"
"123.76800","10.31423","0.01675"
"124.09200","10.34126","0.01766"
"124.41600","10.36822","0.01852"
"124.74000","10.39525","0.01756"
"125.06400","10.42227","0.01814"
"125.38800","10.44924","0.01865"
"125.71200","10.47626","0.01857"
"126.03600","10.50323","0.01916"
"126.36000","10.53019","0.01914"
"126.68400","10.55722","0.02034"
"127.00800","10.58418","0.02008"
"127.33200","10.61121","0.02060"
"127.65600","10.63817","0.02135"
"127.98000","10.66526","0.02128"
"128.30400","10.69228","0.02156"
"128.62800","10.71919","0.02196"
"128.95200","10.74621","0.02213"
"129.27600","10.77318","0.02308"
"129.60000","10.80026","0.02290"
"129.92400","10.82723","0.02319"
"130.24800","10.85419","0.02422"
"130.57200","10.88122","0.02435"
"130.89600","10.90824","0.02572"
"131.22000","10.93521","0.02586"
"131.54400","10.96223","0.02645"
"131.86800","10.98920","0.02674"
"132.19200","11.01622","0.02682"
"132.51600","11.04325","0.02748"
"132.84000","11.07021","0.02779"
"133.16400","11.09730","0.02794"
"133.48800","11.12414","0.02836"
"133.81200","11.15123","0.02935"
"134.13600","11.17819","0.02848"
"134.46000","11.20522","0.02870"
"134.78400","11.23224","0.02911"
"135.10800","11.25915","0.02974"
"135.43200","11.28629","0.03031"
"135.75600","11.31326","0.03029"
"136.08000","11.34022","0.03066"
"136.40400","11.36725","0.03088"
"136.72800","11.39415","0.03125"
"137.05200","11.42124","0.03172"
"137.37600","11.44820","0.03209"
"137.70000","11.47517","0.03211"
"138.02400","11.50225","0.03321"
"138.34800","11.52922","0.03364"
"138.67200","11.55624","0.03295"
"138.99600","11.58321","0.03409"
"139.32000","11.61017","0.03467"
"139.64400","11.63726","0.03531"
"139.96800","11.66416","0.03568"
"140.29200","11.69125","0.03618"
"140.61600","11.71827","0.03744"
"140.94000","11.74523","0.03704"
"141.26400","11.77220","0.03752"
"141.58800","11.79917","0.03787"
"141.91200","11.82625","0.03844"
"142.23600","11.85321","0.03895"
"142.56000","11.88024","0.03941"
"142.88400","11.90727","0.04014"
"143.20800","11.93423","0.03999"
"143.53200","11.96119","0.04035"
"143.85600","11.98822","0.04042"
"144.18000","12.01518","0.04090"
"144.50400","12.04227","0.04172"
"144.82800","12.06917","0.04217"
"145.15200","12.09620","0.04258"
"145.47600","12.12323","0.04272"
"145.80000","12.15019","0.04254"
"146.12400","12.17727","0.04327"
"146.44800","12.20424","0.04375"
"146.77200","12.23120","0.04437"
"147.09600","12.25823","0.04484"
"147.42000","12.28520","0.04477"
"147.74400","12.31222","0.04548"
"148.06800","12.33918","0.04540"
"148.39200","12.36621","0.04604"
"148.71600","12.39323","0.04637"
"149.04000","12.42014","0.04701"
"149.36400","12.44728","0.04729"
"149.68800","12.47425","0.04770"
"150.01200","12.50121","0.04794"
"150.33600","12.52824","0.04874"
"150.66000","12.55520","0.04865"
"150.98400","12.58229","0.04904"
"151.30800","12.60919","0.04922"
"151.63200","12.63622","0.04943"
"151.95600","12.66318","0.04986"
"152.28000","12.69021","0.04970"
"152.60400","12.71723","0.05020"
"152.92800","12.74414","0.05039"
"153.25200","12.77128","0.05048"
"153.57600","12.79825","0.05010"
"153.90000","12.82515","0.05057"
"154.22400","12.85224","0.05044"
"154.54800","12.87920","0.05073"
"154.87200","12.90623","0.05106"
"155.19600","12.93325","0.05120"
"155.52000","12.96022","0.05188"
"155.84400","12.98724","0.05170"
"156.16800","13.01421","0.05194"
"156.49200","13.04117","0.05192"
"156.81600","13.06826","0.05216"
"157.14000","13.09522","0.05253"
"157.46400","13.12225","0.05261"
"157.78800","13.14921","0.05294"
"158.11200","13.17624","0.05245"
"158.43600","13.20326","0.05259"
"158.76000","13.23017","0.05300"
"159.08400","13.25725","0.05334"
"159.40800","13.28416","0.05333"
"159.73200","13.31118","0.05354"
"160.05600","13.33827","0.05376"
"160.38000","13.36517","0.05417"
"160.70400","13.39226","0.05406"
"161.02800","13.41916","0.05441"
"161.35200","13.44619","0.05453"
"161.67600","13.47321","0.05449"
"162.00000","13.50024","0.05456"
"162.32400","13.52726","0.05496"
"162.64800","13.55417","0.05491"
"162.97200","13.58119","0.05493"
"163.29600","13.60822","0.05555"
"163.62000","13.63518","0.05550"
"163.94400","13.66221","0.05553"
"164.26800","13.68923","0.05584"
"164.59200","13.71626","0.05605"
"164.91600","13.74328","0.05642"
"165.24000","13.77013","0.05653"
"165.56400","13.79721","0.05663"
"165.88800","13.82424","0.05671"
"166.21200","13.85120","0.05691"
"166.53600","13.87823","0.05734"
"166.86000","13.90519","0.05744"
"167.18400","13.93222","0.05737"
"167.50800","13.95918","0.05783"
"167.83200","13.98621","0.05809"
"168.15600","14.01329","0.05828"
"168.48000","14.04014","0.05861"
"168.80400","14.06722","0.05870"
"169.12800","14.09419","0.05912"
"169.45200","14.12121","0.05914"
"169.77600","14.14824","0.05951"
"170.10000","14.17520","0.05949"
"170.42400","14.20223","0.05976"
"170.74800","14.22919","0.06032"
"171.07200","14.25616","0.06068"
"171.39600","14.28318","0.06074"
"171.72000","14.31015","0.06065"
"172.04400","14.33723","0.06031"
"172.36800","14.36420","0.06029"
"172.69200","14.39122","0.06063"
"173.01600","14.41819","0.06078"
"173.34000","14.44521","0.06125"
"173.66400","14.47218","0.06115"
"173.98800","14.49920","0.06181"
"174.31200","14.52617","0.05938"
"174.63600","14.55325","0.05986"
"174.96000","14.58022","0.06002"
"175.28400","14.60724","0.06001"
"175.60800","14.63427","0.06102"
"175.93200","14.66117","0.06123"
"176.25600","14.68826","0.06150"
"176.58000","14.71516","0.06192"
"176.90400","14.74224","0.06202"
"177.22800","14.76927","0.06243"
"177.55200","14.79618","0.06238"
"177.87600","14.82320","0.06286"
"178.20000","14.85017","0.06227"
"178.52400","14.87725","0.00860"
"178.84800","14.90422","0.01439"
"179.17200","14.93118","0.01206"
"179.49600","14.95827","0.00782"
"179.82000","14.98517","0.00874"
"180.14400","15.01225","0.01013"
"180.46800","15.03922","0.01226"
"180.79200","15.06625","0.01104"
"181.11600","15.09327","0.00993"
"181.44000","15.12018","0.01071"
"181.76400","15.14720","0.01312"
"182.08800","15.17429","0.01116"
"182.41200","15.20119","0.01002"
"182.73600","15.22827","0.01081"
"183.06000","15.25518","0.01347"
"183.38400","15.28227","0.01344"
"183.70800","15.30923","0.01206"
"184.03200","15.33620","0.01221"
"184.35600","15.36322","0.01352"
"184.68000","15.39025","0.01359"
"185.00400","15.41721","0.01346"
"185.32800","15.44423","0.01338"
"185.65200","15.47120","0.01457"
"185.97600","15.49828","0.01415"
"186.30000","15.52519","0.01370"
"186.62400","15.55216","0.01349"
"186.94800","15.57924","0.01454"
"187.27200","15.60620","0.01427"
"187.59600","15.63323","0.01449"
"187.92000","15.66019","0.01437"
"188.24400","15.68722","0.01509"
"188.56800","15.71424","0.01491"
"188.89200","15.74115","0.01496"
"189.21600","15.76823","0.01479"
"189.54000","15.79526","0.01485"
"189.86400","15.82222","0.01476"
"190.18800","15.84925","0.01488"
"190.51200","15.87615","0.01493"
"190.83600","15.90324","0.01532"
"191.16000","15.93020","0.01541"
"191.48400","15.95717","0.01496"
"191.80800","15.98419","0.01561"
"192.13200","16.01116","0.01640"
"192.45600","16.03830","0.01632"
"192.78000","16.06521","0.01647"
"193.10400","16.09217","0.01558"
"193.42800","16.11926","0.01666"
"193.75200","16.14616","0.01681"
"194.07600","16.17325","0.01676"
"194.40000","16.20021","0.01631"
"194.72400","16.22724","0.01638"
"195.04800","16.25426","0.01614"
"195.37200","16.28117","0.01625"
"195.69600","16.30825","0.01733"
"196.02000","16.33522","0.01602"
"196.34400","16.36218","0.01605"
"196.66800","16.38921","0.01622"
"196.99200","16.41617","0.01667"
"197.31600","16.44326","0.01660"
"197.64000","16.47022","0.01597"
"197.96400","16.49719","0.01583"
"198.28800","16.52427","0.01609"
"198.61200","16.55118","0.01564"
"198.93600","16.57820","0.01625"
"199.26000","16.60523","0.01632"
"199.58400","16.63219","0.01704"
"199.90800","16.65922","0.01683"
"200.23200","16.68618","0.01698"
"200.55600","16.71327","0.01708"
"200.88000","16.74023","0.01755"
"201.20400","16.76720","0.01735"
"201.52800","16.79422","0.01743"
"201.85200","16.82113","0.01555"
"202.17600","16.84827","0.01598"
"202.50000","16.87524","0.01648"
"202.82400","16.90220","0.01547"
"203.14800","16.92929","0.01653"
"203.47200","16.95619","0.01676"
"203.79600","16.98328","0.01606"
"204.12000","17.01018","0.01667"
"204.44400","17.03715","0.01640"
"204.76800","17.06423","0.01642"
"205.09200","17.09120","0.01594"
"205.41600","17.11822","0.01609"
"205.74000","17.14519","0.01611"
"206.06400","17.17221","0.01665"
"206.38800","17.19918","0.01671"
"206.71200","17.22614","0.01687"
"207.03600","17.25323","0.01683"
"207.36000","17.28019","0.01643"
"207.68400","17.30722","0.01673"
"208.00800","17.33424","0.01722"
"208.33200","17.36121","0.01745"
"208.65600","17.38823","0.01759"
"208.98000","17.41520","0.01683"
"209.30400","17.44216","0.01766"
"209.62800","17.46925","0.01680"
"209.95200","17.49621","0.01767"
"210.27600","17.52324","0.01797"
"210.60000","17.55026","0.01811"
"210.92400","17.57722","0.01818"
"211.24800","17.60425","0.01841"
"211.57200","17.63110","0.01871"
"211.89600","17.65818","0.01888"
"212.22000","17.68521","0.01908"
"212.54400","17.71217","0.01929"
"212.86800","17.73926","0.01981"
"213.19200","17.76616","0.01940"
"213.51600","17.79330","0.01975"
"213.84000","17.82021","0.02001"
"214.16400","17.84718","0.02001"
"214.48800","17.87420","0.01998"
"214.81200","17.90122","0.02015"
"215.13600","17.92825","0.02040"
"215.46000","17.95522","0.02024"
"215.78400","17.98218","0.02134"
"216.10800","18.00927","0.02168"
"216.43200","18.03623","0.02141"
"216.75600","18.06319","0.02136"
"217.08000","18.09022","0.02114"
"217.40400","18.11719","0.02147"
"217.72800","18.14421","0.02193"
"218.05200","18.17118","0.02192"
"218.37600","18.19826","0.02182"
"218.70000","18.22528","0.01975"
"219.02400","18.25219","0.02037"
"219.34800","18.27921","0.02031"
"219.67200","18.30618","0.01979"
"219.99600","18.33326","0.02045"
"220.32000","18.36029","0.01938"
"220.64400","18.38720","0.01867"
"220.96800","18.41428","0.01891"
"221.29200","18.44124","0.01884"
"221.61600","18.46821","0.01930"
"221.94000","18.49523","0.01946"
"222.26400","18.52220","0.01954"
"222.58800","18.54922","0.01950"
"222.91200","18.57619","0.01957"
"223.23600","18.60321","0.01965"
"223.56000","18.63024","0.02020"
"223.88400","18.65720","0.01975"
"224.20800","18.68429","0.01958"
"224.53200","18.71119","0.01951"
"224.85600","18.73822","0.02013"
"225.18000","18.76525","0.01990"
"225.50400","18.79215","0.02043"
"225.82800","18.81923","0.02021"
"226.15200","18.84626","0.02006"
"226.47600","18.87322","0.02042"
"226.80000","18.90025","0.02027"
"227.12400","18.92715","0.02031"
"227.44800","18.95424","0.02061"
"227.77200","18.98120","0.02071"
"228.09600","19.00823","0.02038"
"228.42000","19.03525","0.02030"
"228.74400","19.06216","0.02009"
"229.06800","19.08924","0.01975"
"229.39200","19.11621","0.02056"
"229.71600","19.14317","0.02014"
"230.04000","19.17026","0.02029"
"230.36400","19.19716","0.01958"
"230.68800","19.22425","0.02021"
"231.01200","19.25127","0.02100"
"231.33600","19.27824","0.02056"
"231.66000","19.30520","0.02012"
"231.98400","19.33211","0.02124"
"232.30800","19.35925","0.02051"
"232.63200","19.38622","0.02079"
"232.95600","19.41324","0.02152"
"233.28000","19.44027","0.02154"
"233.60400","19.46723","0.02156"
"233.92800","19.49420","0.02182"
"234.25200","19.52122","0.02168"
"234.57600","19.54813","0.02209"
"234.90000","19.57527","0.02239"
"235.22400","19.60218","0.02246"
"235.54800","19.62926","0.02290"
"235.87200","19.65623","0.02285"
"236.19600","19.68319","0.02338"
"236.52000","19.71022","0.02331"
"236.84400","19.73718","0.02384"
"237.16800","19.76421","0.02367"
"237.49200","19.79129","0.02417"
"237.81600","19.81820","0.02367"
"238.14000","19.84522","0.02367"
"238.46400","19.87219","0.02445"
"238.78800","19.89927","0.02472"
"239.11200","19.92624","0.02397"
"239.43600","19.95320","0.02456"
"239.76000","19.98023","0.02439"
"240.08400","20.00719","0.02522"
"240.40800","20.03422","0.02563"
"240.73200","20.06130","0.02542"
"241.05600","20.08821","0.02564"
"241.38000","20.11523","0.02616"
"241.70400","20.14214","0.02653"
"242.02800","20.16922","0.02660"
"242.35200","20.19624","0.02671"
"242.67600","20.22321","0.02727"
"243.00000","20.25023","0.02716"
"243.32400","20.27720","0.02735"
"243.64800","20.30429","0.02717"
"243.97200","20.33125","0.02474"
"244.29600","20.35822","0.02419"
"244.62000","20.38524","0.02302"
"244.94400","20.41221","0.02228"
"245.26800","20.43923","0.02132"
"245.59200","20.46626","0.02035"
"245.91600","20.49316","0.02099"
"246.24000","20.52031","0.02086"
"246.56400","20.54721","0.02032"
"246.88800","20.57424","0.02046"
"247.21200","20.60120","0.02106"
"247.53600","20.62817","0.02145"
"247.86000","20.65525","0.02049"
"248.18400","20.68222","0.02084"
"248.50800","20.70924","0.02127"
"248.83200","20.73621","0.02095"
"249.15600","20.76317","0.02145"
"249.48000","20.79020","0.02126"
"249.80400","20.81722","0.02156"
"250.12800","20.84425","0.02147"
"250.45200","20.87121","0.02274"
"250.77600","20.89817","0.02127"
"251.10000","20.92526","0.02187"
"251.42400","20.95223","0.02158"
"251.74800","20.97925","0.02232"
"252.07200","21.00622","0.02232"
"252.39600","21.03318","0.02289"
"252.72000","21.06020","0.02327"
"253.04400","21.08723","0.02332"
"253.36800","21.11420","0.02310"
"253.69200","21.14128","0.02358"
"254.01600","21.16818","0.02353"
"254.34000","21.19521","0.02410"
"254.66400","21.22223","0.02251"
"254.98800","21.24926","0.02297"
"255.31200","21.27622","0.02335"
"255.63600","21.30313","0.02358"
"255.96000","21.33027","0.02379"
"256.28400","21.35718","0.02438"
"256.60800","21.38420","0.02426"
"256.93200","21.41123","0.02483"
"257.25600","21.43814","0.02536"
"257.58000","21.46522","0.02495"
"257.90400","21.49219","0.02569"
"258.22800","21.51921","0.02630"
"258.55200","21.54623","0.02571"
"258.87600","21.57326","0.02588"
"259.20000","21.60029","0.02587"
"259.52400","21.62725","0.02672"
"259.84800","21.65416","0.02655"
"260.17200","21.68124","0.02686"
"260.49600","21.70821","0.02771"
"260.82000","21.73523","0.02788"
"261.14400","21.76225","0.02811"
"261.46800","21.78922","0.02792"
"261.79200","21.81618","0.02825"
"262.11600","21.84315","0.02824"
"262.44000","21.87023","0.02903"
"262.76400","21.89720","0.02826"
"263.08800","21.92416","0.02927"
"263.41200","21.95125","0.02883"
"263.73600","21.97815","0.02966"
"264.06000","22.00524","0.03001"
"264.38400","22.03221","0.03006"
"264.70800","22.05917","0.03007"
"265.03200","22.08625","0.03069"
"265.35600","22.11316","0.03067"
"265.68000","22.14024","0.03063"
"266.00400","22.16721","0.03019"
"266.32800","22.19417","0.03064"
"266.65200","22.22126","0.03104"
"266.97600","22.24816","0.03157"
"267.30000","22.27519","0.03141"
"267.62400","22.30221","0.03171"
"267.94800","22.32918","0.03210"
"268.27200","22.35620","0.03193"
"268.59600","22.38317","0.03184"
"268.92000","22.41025","0.03239"
"269.24400","22.43722","0.03188"
"269.56800","22.46418","0.03189"
"269.89200","22.49121","0.03282"
"270.21600","22.51823","0.03202"
"270.54000","22.54526","0.03260"
"270.86400","22.57222","0.03283"
"271.18800","22.59919","0.03262"
"271.51200","22.62621","0.03330"
"271.83600","22.65318","0.03346"
"272.16000","22.68020","0.03323"
"272.48400","22.70723","0.03392"
"272.80800","22.73419","0.03367"
"273.13200","22.76128","0.03403"
"273.45600","22.78818","0.03379"
"273.78000","22.81527","0.03366"
"274.10400","22.84229","0.03409"
"274.42800","22.86920","0.03481"
"274.75200","22.89622","0.03510"
"275.07600","22.92319","0.03426"
"275.40000","22.95021","0.03417"
"275.72400","22.97724","0.03494"
"276.04800","23.00420","0.03545"
"276.37200","23.03129","0.03533"
"276.69600","23.05819","0.03567"
"277.02000","23.08522","0.03598"
"277.34400","23.11224","0.03721"
"277.66800","23.13921","0.03621"
"277.99200","23.16623","0.03701"
"278.31600","23.19320","0.03740"
"278.64000","23.22022","0.03733"
"278.96400","23.24730","0.03806"
"279.28800","23.27415","0.03840"
"279.61200","23.30124","0.03877"
"279.93600","23.32820","0.03900"
"280.26000","23.35522","0.03965"
"280.58400","23.38225","0.03885"
"280.90800","23.40922","0.03988"
"281.23200","23.43624","0.03975"
"281.55600","23.46321","0.04002"
"281.88000","23.49017","0.04023"
"282.20400","23.51720","0.03960"
"282.52800","23.54422","0.03946"
"282.85200","23.57125","0.04040"
"283.17600","23.59821","0.04026"
"283.50000","23.62523","0.04063"
"283.82400","23.65232","0.03855"
"284.14800","23.67923","0.03901"
"284.47200","23.70625","0.03979"
"284.79600","23.73322","0.04032"
"285.12000","23.76024","0.03886"
"285.44400","23.78726","0.03802"
"285.76800","23.81417","0.03798"
"286.09200","23.84120","0.03875"
"286.41600","23.86822","0.03953"
"286.74000","23.89524","0.03983"
"287.06400","23.92221","0.03956"
"287.38800","23.94912","0.03999"
"287.71200","23.97626","0.03992"
"288.03600","24.00323","0.04009"
"288.36000","24.03025","0.04059"
"288.68400","24.05722","0.04072"
"289.00800","24.08418","0.04128"
"289.33200","24.11126","0.04102"
"289.65600","24.13817","0.04219"
"289.98000","24.16519","0.04212"
"290.30400","24.19222","0.04268"
"290.62800","24.21913","0.04266"
"290.95200","24.24627","0.04288"
"291.27600","24.27324","0.04256"
"291.60000","24.30026","0.04268"
"291.92400","24.32723","0.04343"
"292.24800","24.35419","0.04354"
"292.57200","24.38121","0.04385"
"292.89600","24.40824","0.04371"
"293.22000","24.43520","0.04419"
"293.54400","24.46217","0.04389"
"293.86800","24.48914","0.04346"
"294.19200","24.51622","0.04375"
"294.51600","24.54325","0.04361"
"294.84000","24.57015","0.04463"
"295.16400","24.59723","0.04442"
"295.48800","24.62420","0.04406"
"295.81200","24.65122","0.04500"
"296.13600","24.67825","0.04551"
"296.46000","24.70515","0.04532"
"296.78400","24.73224","0.04592"
"297.10800","24.75915","0.04568"
"297.43200","24.78623","0.04648"
"297.75600","24.81326","0.04572"
"298.08000","24.84016","0.04700"
"298.40400","24.86718","0.04712"
"298.72800","24.89421","0.04651"
"299.05200","24.92130","0.04675"
"299.37600","24.94820","0.04640"
"299.70000","24.97522","0.04243"
"300.02400","25.00225","0.04356"
"300.34800","25.02921","0.04162"
"300.67200","25.05624","0.04246"
"300.99600","25.08320","0.04436"
"301.32000","25.11017","0.04314"
"301.64400","25.13720","0.04469"
"301.96800","25.16416","0.04385"
"302.29200","25.19118","0.04474"
"302.61600","25.21827","0.04201"
"302.94000","25.24517","0.03936"
"303.26400","25.27220","0.04024"
"303.58800","25.29922","0.04104"
"303.91200","25.32625","0.04155"
"304.23600","25.35321","0.04076"
"304.56000","25.38018","0.04157"
"304.88400","25.40720","0.04184"
"305.20800","25.43417","0.04127"
"305.53200","25.46125","0.04259"
"305.85600","25.48822","0.04229"
"306.18000","25.51518","0.04105"
"306.50400","25.54227","0.03734"
"306.82800","25.56917","0.03816"
"307.15200","25.59620","0.03826"
"307.47600","25.62322","0.03858"
"307.80000","25.65019","0.03897"
"308.12400","25.67721","0.03881"
"308.44800","25.70418","0.03937"
"308.77200","25.73120","0.03885"
"309.09600","25.75823","0.03843"
"309.42000","25.78519","0.03871"
"309.74400","25.81228","0.03940"
"310.06800","25.83924","0.03978"
"310.39200","25.86627","0.03989"
"310.71600","25.89323","0.04103"
"311.04000","25.92020","0.04061"
"311.36400","25.94722","0.04075"
"311.68800","25.97419","0.04107"
"312.01200","26.00115","0.04158"
"312.33600","26.02824","0.04160"
"312.66000","26.05514","0.04184"
"312.98400","26.08223","0.04215"
"313.30800","26.10919","0.04287"
"313.63200","26.13622","0.04260"
"313.95600","26.16330","0.04286"
"314.28000","26.19015","0.04270"
"314.60400","26.21723","0.04319"
"314.92800","26.24420","0.04368"
"315.25200","26.27122","0.04426"
"315.57600","26.29825","0.04451"
"315.90000","26.32515","0.04491"
"316.22400","26.35224","0.04436"
"316.54800","26.37920","0.04508"
"316.87200","26.40623","0.04535"
"317.19600","26.43325","0.04485"
"317.52000","26.46016","0.04488"
"317.84400","26.48724","0.04494"
"318.16800","26.51421","0.04546"
"318.49200","26.54123","0.04606"
"318.81600","26.56826","0.04581"
"319.14000","26.59522","0.04555"
"319.46400","26.62225","0.04633"
"319.78800","26.64915","0.04655"
"320.11200","26.67618","0.04675"
"320.43600","26.70326","0.04690"
"320.76000","26.73017","0.04700"
"321.08400","26.75725","0.04701"
"321.40800","26.78428","0.04641"
"321.73200","26.81124","0.04677"
"322.05600","26.83827","0.04717"
"322.38000","26.86511","0.04675"
"322.70400","26.89226","0.04684"
"323.02800","26.91922","0.04666"
"323.35200","26.94619","0.04665"
"323.67600","26.97321","0.04778"
"324.00000","27.00018","0.04769"
"324.32400","27.02720","0.04798"
"324.64800","27.05422","0.04803"
"324.97200","27.08119","0.04834"
"325.29600","27.10828","0.04908"
"325.62000","27.13518","0.04918"
"325.94400","27.16227","0.04957"
"326.26800","27.18923","0.04986"
"326.59200","27.21620","0.04926"
"326.91600","27.24322","0.04914"
"327.24000","27.27019","0.04774"
"327.56400","27.29721","0.04794"
"327.88800","27.32424","0.04755"
"328.21200","27.35120","0.04698"
"328.53600","27.37822","0.04715"
"328.86000","27.40513","0.04682"
"329.18400","27.43227","0.04722"
"329.50800","27.45924","0.04750"
"329.83200","27.48621","0.04762"
"330.15600","27.51329","0.04807"
"330.48000","27.54020","0.04785"
"330.80400","27.56716","0.04634"
"331.12800","27.59418","0.04478"
"331.45200","27.62121","0.03365"
"331.77600","27.64824","0.02900"
"332.10000","27.67514","0.03158"
"332.42400","27.70216","0.02742"
"332.74800","27.72919","0.02890"
"333.07200","27.75622","0.03157"
"333.39600","27.78324","0.03087"
"333.72000","27.81015","0.03110"
"334.04400","27.83723","0.03110"
"334.36800","27.86419","0.03192"
"334.69200","27.89116","0.03248"
"335.01600","27.91818","0.03293"
"335.34000","27.94521","0.03280"
"335.66400","27.97229","0.03372"
"335.98800","27.99926","0.03348"
"336.31200","28.02622","0.03372"
"336.63600","28.05325","0.03479"
"336.96000","28.08021","0.03436"
"337.28400","28.10718","0.03524"
"337.60800","28.13427","0.03520"
"337.93200","28.16123","0.03592"
"338.25600","28.18826","0.03522"
"338.58000","28.21516","0.03555"
"338.90400","28.24224","0.03686"
"339.22800","28.26927","0.03704"
"339.55200","28.29617","0.03680"
"339.87600","28.32320","0.03693"
"340.20000","28.35022","0.03719"
"340.52400","28.37725","0.03768"
"340.84800","28.40428","0.03780"
"341.17200","28.43118","0.03756"
"341.49600","28.45827","0.03758"
"341.82000","28.48523","0.03701"
"342.14400","28.51220","0.03747"
"342.46800","28.53922","0.03718"
"342.79200","28.56618","0.03793"
"343.11600","28.59327","0.03728"
"343.44000","28.62017","0.03729"
"343.76400","28.64720","0.02958"
"344.08800","28.67428","0.02157"
"344.41200","28.70119","0.01677"
"344.73600","28.72821","0.02031"
"345.06000","28.75518","0.01806"
"345.38400","28.78220","0.01974"
"345.70800","28.80923","0.01991"
"346.03200","28.83613","0.01926"
"346.35600","28.86322","0.02143"
"346.68000","28.89024","0.01953"
"347.00400","28.91721","0.02007"
"347.32800","28.94423","0.02013"
"347.65200","28.97114","0.01988"
"347.97600","28.99822","0.02045"
"348.30000","29.02525","0.02040"
"348.62400","29.05222","0.02061"
"348.94800","29.07924","0.02125"
"349.27200","29.10614","0.02111"
"349.59600","29.13323","0.02182"
"349.92000","29.16019","0.02117"
"350.24400","29.18716","0.02130"
"350.56800","29.21424","0.02168"
"350.89200","29.24115","0.02163"
"351.21600","29.26823","0.02137"
"351.54000","29.29520","0.02207"
"351.86400","29.32222","0.02177"
"352.18800","29.34919","0.02105"
"352.51200","29.37615","0.02101"
"352.83600","29.40324","0.02125"
"353.16000","29.43020","0.02153"
"353.48400","29.45723","0.02145"
"353.80800","29.48425","0.02165"
"354.13200","29.51122","0.02195"
"354.45600","29.53824","0.02205"
"354.78000","29.56521","0.02240"
"355.10400","29.59217","0.02268"
"355.42800","29.61926","0.02224"
"355.75200","29.64622","0.02256"
"356.07600","29.67319","0.02265"
"356.40000","29.70021","0.02322"
"356.72400","29.72718","0.02319"
"357.04800","29.75420","0.02320"
"357.37200","29.78117","0.02402"
"357.69600","29.80819","0.02386"
"358.02000","29.83522","0.02322"
"358.34400","29.86218","0.02392"
"358.66800","29.88921","0.02461"
"358.99200","29.91617","0.02483"
"359.31600","29.94326","0.02439"
"359.64000","29.97028","0.02440"
"359.96400","29.99719","0.02463"
"360.28800","30.02421","0.02496"
"360.61200","30.05118","0.02517"
"360.93600","30.07826","0.02529"
"361.26000","30.10523","0.02566"
"361.58400","30.13225","0.02565"
"361.90800","30.15922","0.02542"
"362.23200","30.18618","0.02500"
"362.55600","30.21321","0.02538"
"362.88000","30.24023","0.02561"
"363.20400","30.26720","0.02581"
"363.52800","30.29422","0.02564"
"363.85200","30.32118","0.02503"
"364.17600","30.34821","0.02156"
"364.50000","30.37523","0.02152"
"364.82400","30.40220","0.02293"
"365.14800","30.42923","0.02107"
"365.47200","30.45619","0.02209"
"365.79600","30.48328","0.02229"
"366.12000","30.51024","0.02166"
"366.44400","30.53715","0.02187"
"366.76800","30.56423","0.02152"
"367.09200","30.59120","0.02113"
"367.41600","30.61822","0.02173"
"367.74000","30.64525","0.02167"
"368.06400","30.67221","0.02121"
"368.38800","30.69923","0.02198"
"368.71200","30.72620","0.02200"
"369.03600","30.75323","0.02243"
"369.36000","30.78025","0.02206"
"369.68400","30.80715","0.02180"
"370.00800","30.83424","0.02218"
"370.33200","30.86115","0.02227"
"370.65600","30.88823","0.02239"
"370.98000","30.91525","0.02244"
"371.30400","30.94216","0.02182"
"371.62800","30.96924","0.02198"
"371.95200","30.99621","0.02211"
"372.27600","31.02317","0.02186"
"372.60000","31.05020","0.02228"
"372.92400","31.07723","0.02232"
"373.24800","31.10425","0.02301"
"373.57200","31.13122","0.02285"
"373.89600","31.15818","0.02309"
"374.22000","31.18526","0.02344"
"374.54400","31.21223","0.02352"
"374.86800","31.23926","0.02380"
"375.19200","31.26616","0.02395"
"375.51600","31.29324","0.02418"
"375.84000","31.32027","0.02431"
"376.16400","31.34717","0.02392"
"376.48800","31.37426","0.02425"
"376.81200","31.40122","0.02403"
"377.13600","31.42819","0.02447"
"377.46000","31.45521","0.02444"
"377.78400","31.48218","0.02501"
"378.10800","31.50920","0.02528"
"378.43200","31.53623","0.02579"
"378.75600","31.56319","0.02573"
"379.08000","31.59022","0.02581"
"379.40400","31.61724","0.02677"
"379.72800","31.64427","0.02653"
"380.05200","31.67117","0.02664"
"380.37600","31.69814","0.02718"
"380.70000","31.72528","0.02723"
"381.02400","31.75225","0.02668"
"381.34800","31.77927","0.02696"
"381.67200","31.80624","0.02725"
"381.99600","31.83320","0.02745"
"382.32000","31.86023","0.02790"
"382.64400","31.88713","0.02748"
"382.96800","31.91427","0.02760"
"383.29200","31.94124","0.02800"
"383.61600","31.96821","0.02809"
"383.94000","31.99529","0.02815"
"384.26400","32.02220","0.02862"
"384.58800","32.04928","0.02885"
"384.91200","32.07619","0.02952"
"385.23600","32.10321","0.02977"
"385.56000","32.13024","0.03066"
"385.88400","32.15720","0.03036"
"386.20800","32.18423","0.03084"
"386.53200","32.21125","0.03114"
"386.85600","32.23822","0.03131"
"387.18000","32.26524","0.03154"
"387.50400","32.29214","0.03179"
"387.82800","32.31917","0.03126"
"388.15200","32.34626","0.03200"
"388.47600","32.37322","0.03225"
"388.80000","32.40025","0.03281"
"389.12400","32.42715","0.03261"
"389.44800","32.45418","0.03326"
"389.77200","32.48120","0.03363"
"390.09600","32.50816","0.03372"
"390.42000","32.53519","0.03485"
"390.74400","32.56221","0.03441"
"391.06800","32.58918","0.03475"
"391.39200","32.61621","0.03205"
"391.71600","32.64323","0.03409"
"392.04000","32.67026","0.03438"
"392.36400","32.69716","0.03414"
"392.68800","32.72425","0.03431"
"393.01200","32.75121","0.03505"
"393.33600","32.77818","0.03513"
"393.66000","32.80520","0.03513"
"393.98400","32.83216","0.03598"
"394.30800","32.85925","0.03608"
"394.63200","32.88622","0.03597"
"394.95600","32.91318","0.03603"
"395.28000","32.94020","0.03648"
"395.60400","32.96717","0.03726"
"395.92800","32.99426","0.03755"
"396.25200","33.02122","0.03724"
"396.57600","33.04824","0.03777"
"396.90000","33.07527","0.03787"
"397.22400","33.10218","0.03761"
"397.54800","33.12920","0.03758"
"397.87200","33.15622","0.03779"
"398.19600","33.18319","0.03738"
"398.52000","33.21021","0.03794"
"398.84400","33.23718","0.03772"
"399.16800","33.26421","0.03804"
"399.49200","33.29129","0.03854"
"399.81600","33.31813","0.03851"
"400.14000","33.34522","0.03343"
"400.46400","33.37218","0.02892"
"400.78800","33.39921","0.02887"
"401.11200","33.42624","0.02840"
"401.43600","33.45320","0.02936"
"401.76000","33.48022","0.02889"
"402.08400","33.50719","0.02930"
"402.40800","33.53421","0.02914"
"402.73200","33.56124","0.02791"
"403.05600","33.58820","0.02845"
"403.38000","33.61523","0.02843"
"403.70400","33.64220","0.02731"
"404.02800","33.66922","0.02749"
"404.35200","33.69625","0.02760"
"404.67600","33.72321","0.02697"
"405.00000","33.75024","0.02794"
"405.32400","33.77720","0.02803"
"405.64800","33.80422","0.02831"
"405.97200","33.83125","0.02834"
"406.29600","33.85815","0.02933"
"406.62000","33.88524","0.02845"
"406.94400","33.91226","0.02872"
"407.26800","33.93917","0.02975"
"407.59200","33.96619","0.02972"
"407.91600","33.99316","0.03048"
"408.24000","34.02024","0.03102"
"408.56400","34.04721","0.03046"
"408.88800","34.07423","0.03041"
"409.21200","34.10126","0.03118"
"409.53600","34.12816","0.03174"
"409.86000","34.15525","0.03157"
"410.18400","34.18221","0.03169"
"410.50800","34.20924","0.03151"
"410.83200","34.23626","0.03161"
"411.15600","34.26317","0.03150"
"411.48000","34.29025","0.03124"
"411.80400","34.31722","0.03224"
"412.12800","34.34425","0.03191"
"412.45200","34.37121","0.03188"
"412.77600","34.39811","0.03251"
"413.10000","34.42520","0.03174"
"413.42400","34.45216","0.03114"
"413.74800","34.47919","0.03219"
"414.07200","34.50627","0.03176"
"414.39600","34.53318","0.03206"
"414.72000","34.56026","0.03276"
"415.04400","34.58717","0.03266"
"415.36800","34.61419","0.03278"
"415.69200","34.64128","0.03306"
"416.01600","34.66819","0.03277"
"416.34000","34.69527","0.03350"
"416.66400","34.72223","0.03372"
"416.98800","34.74920","0.03329"
"417.31200","34.77622","0.03331"
"417.63600","34.80325","0.03453"
"417.96000","34.83027","0.03441"
"418.28400","34.85724","0.03501"
"418.60800","34.88420","0.03486"
"418.93200","34.91123","0.03496"
"419.25600","34.93819","0.03494"
"419.58000","34.96528","0.03418"
"419.90400","34.99224","0.03504"
"420.22800","35.01915","0.03462"
"420.55200","35.04623","0.03454"
"420.87600","35.07326","0.03193"
"421.20000","35.10022","0.03243"
"421.52400","35.12725","0.03096"
"421.84800","35.15421","0.03143"
"422.17200","35.18130","0.03172"
"422.49600","35.20820","0.03157"
"422.82000","35.23523","0.03085"
"423.14400","35.26219","0.03081"
"423.46800","35.28916","0.02997"
"423.79200","35.31618","0.03016"
"424.11600","35.34315","0.03011"
"424.44000","35.37029","0.02967"
"424.76400","35.39726","0.02936"
"425.08800","35.42422","0.02935"
"425.41200","35.45125","0.02889"
"425.73600","35.47815","0.02958"
"426.06000","35.50523","0.02927"
"426.38400","35.53220","0.03005"
"426.70800","35.55917","0.02949"
"427.03200","35.58625","0.02967"
"427.35600","35.61322","0.02928"
"427.68000","35.64018","0.02974"
"428.00400","35.66727","0.02991"
"428.32800","35.69423","0.02880"
"428.65200","35.72126","0.02930"
"428.97600","35.74816","0.02933"
"429.30000","35.77525","0.02981"
"429.62400","35.80227","0.02945"
"429.94800","35.82917","0.02944"
"430.27200","35.85626","0.02957"
"430.59600","35.88322","0.02925"
"430.92000","35.91019","0.02890"
"431.24400","35.93722","0.02871"
"431.56800","35.96418","0.02911"
"431.89200","35.99121","0.02836"
"432.21600","36.01823","0.02880"
"432.54000","36.04520","0.02895"
"432.86400","36.07222","0.02909"
"433.18800","36.09919","0.02927"
"433.51200","36.12627","0.02941"
"433.83600","36.15318","0.02957"
"434.16000","36.18020","0.02909"
"434.48400","36.20728","0.03014"
"434.80800","36.23419","0.02950"
"435.13200","36.26122","0.02956"
"435.45600","36.28818","0.03008"
"435.78000","36.31527","0.02968"
"436.10400","36.34229","0.03010"
"436.42800","36.36914","0.02950"
"436.75200","36.39628","0.02917"
"437.07600","36.42318","0.02915"
"437.40000","36.45021","0.02917"
"437.72400","36.47723","0.03005"
"438.04800","36.50420","0.03038"
"438.37200","36.53122","0.03025"
"438.69600","36.55819","0.03067"
"439.02000","36.58522","0.03089"
"439.34400","36.61224","0.03086"
"439.66800","36.63927","0.03058"
"439.99200","36.66623","0.03134"
"440.31600","36.69320","0.02929"
"440.64000","36.72016","0.02973"
"440.96400","36.74724","0.03015"
"441.28800","36.77421","0.02942"
"441.61200","36.80124","0.02913"
"441.93600","36.82826","0.02919"
"442.26000","36.85522","0.02836"
"442.58400","36.88225","0.02910"
"442.90800","36.90916","0.02875"
"443.23200","36.93624","0.02921"
"443.55600","36.96321","0.02941"
"443.88000","36.99017","0.02953"
"444.20400","37.01726","0.03042"
"444.52800","37.04416","0.03026"
"444.85200","37.07124","0.03005"
"445.17600","37.09821","0.03006"
"445.50000","37.12518","0.02925"
"445.82400","37.15226","0.02868"
"446.14800","37.17916","0.02795"
"446.47200","37.20625","0.02802"
"446.79600","37.23315","0.02856"
"447.12000","37.26024","0.02812"
"447.44400","37.28727","0.02802"
"447.76800","37.31417","0.02770"
"448.09200","37.34120","0.02885"
"448.41600","37.36822","0.02827"
"448.74000","37.39518","0.02864"
"449.06400","37.42221","0.02910"
"449.38800","37.44917","0.02942"
"449.71200","37.47620","0.02892"
"450.03600","37.50316","0.02915"
"450.36000","37.53019","0.02949"
"450.68400","37.55721","0.02940"
"451.00800","37.58418","0.02967"
"451.33200","37.61121","0.02986"
"451.65600","37.63823","0.03057"
"451.98000","37.66519","0.02995"
"452.30400","37.69228","0.03064"
"452.62800","37.71912","0.03063"
"452.95200","37.74621","0.03117"
"453.27600","37.77323","0.03131"
"453.60000","37.80020","0.03134"
"453.92400","37.82722","0.03121"
"454.24800","37.85419","0.03150"
"454.57200","37.88121","0.03221"
"454.89600","37.90824","0.03200"
"455.22000","37.93520","0.03294"
"455.54400","37.96217","0.03186"
"455.86800","37.98919","0.03233"
"456.19200","38.01628","0.03249"
"456.51600","38.04318","0.03294"
"456.84000","38.07015","0.03255"
"457.16400","38.09723","0.03249"
"457.48800","38.12420","0.03261"
"457.81200","38.15122","0.03278"
"458.13600","38.17819","0.03356"
"458.46000","38.20522","0.03413"
"458.78400","38.23224","0.03410"
"459.10800","38.25920","0.03451"
"459.43200","38.28623","0.03380"
"459.75600","38.31325","0.03432"
"460.08000","38.34022","0.03420"
"460.40400","38.36724","0.02985"
"460.72800","38.39421","0.02979"
"461.05200","38.42123","0.02945"
"461.37600","38.44826","0.03012"
"461.70000","38.47522","0.02948"
"462.02400","38.50225","0.02946"
"462.34800","38.52921","0.02968"
"462.67200","38.55618","0.02965"
"462.99600","38.58320","0.02941"
"463.32000","38.61023","0.02996"
"463.64400","38.63731","0.03044"
"463.96800","38.66422","0.03029"
"464.29200","38.69118","0.03051"
"464.61600","38.71827","0.03074"
"464.94000","38.74517","0.03099"
"465.26400","38.77219","0.03151"
"465.58800","38.79922","0.03063"
"465.91200","38.82624","0.03153"
"466.23600","38.85327","0.03157"
"466.56000","38.88018","0.03256"
"466.88400","38.90720","0.03167"
"467.20800","38.93417","0.03263"
"467.53200","38.96119","0.03222"
"467.85600","38.98828","0.03293"
"468.18000","39.01518","0.03263"
"468.50400","39.04227","0.03340"
"468.82800","39.06923","0.03280"
"469.15200","39.09626","0.03332"
"469.47600","39.12322","0.03397"
"469.80000","39.15012","0.03375"
"470.12400","39.17727","0.03359"
"470.44800","39.20418","0.01700"
"470.77200","39.23120","0.01250"
"471.09600","39.25829","0.01163"
"471.42000","39.28519","0.01365"
"471.74400","39.31221","0.01264"
"472.06800","39.33918","0.01462"
"472.39200","39.36621","0.01239"
"472.71600","39.39317","0.01438"
"473.04000","39.42013","0.01355"
"473.36400","39.44722","0.01376"
"473.68800","39.47424","0.01410"
"474.01200","39.50121","0.01388"
"474.33600","39.52818","0.01459"
"474.66000","39.55514","0.01458"
"474.98400","39.58222","0.01504"
"475.30800","39.60919","0.01482"
"475.63200","39.63616","0.01521"
"475.95600","39.66324","0.01526"
"476.28000","39.69020","0.01524"
"476.60400","39.71729","0.01557"
"476.92800","39.74425","0.01499"
"477.25200","39.77116","0.01519"
"477.57600","39.79824","0.01542"
"477.90000","39.82515","0.01549"
"478.22400","39.85223","0.01576"
"478.54800","39.87925","0.01632"
"478.87200","39.90623","0.01573"
"479.19600","39.93325","0.01535"
"479.52000","39.96015","0.01558"
"479.84400","39.98724","0.01598"
"480.16800","40.01427","0.01575"
"480.49200","40.04117","0.01577"
"480.81600","40.06820","0.01594"
"481.14000","40.09522","0.01671"
"481.46400","40.12224","0.01651"
"481.78800","40.14921","0.01632"
"482.11200","40.17617","0.01625"
"482.43600","40.20320","0.01661"
"482.76000","40.23016","0.01663"
"483.08400","40.25719","0.01617"
"483.40800","40.28421","0.01590"
"483.73200","40.31124","0.01590"
"483.86400","40.32224","0.01506"