File: Force_trajectories/170225_1/Specimen_RawData_10.csv
End date,"2/25/2017"
Specimen label,"1BG_5"
Maximum Load,"0.25051",N

Time,Extension,Load
(s),(mm),(N)
"0.00000","0.00000","-0.00026"
"0.24600","0.01901","-0.00023"
"0.49200","0.04125","0.00048"
"0.73800","0.06170","0.00046"
"0.98400","0.08221","-0.00005"
"1.23000","0.10272","0.00014"
"1.47600","0.12323","0.00068"
"1.72200","0.14367","0.00018"
"1.96800","0.16418","0.00021"
"2.21400","0.18469","0.00059"
"2.46000","0.20520","0.00063"
"2.70600","0.22571","0.00045"
"2.95200","0.24621","0.00091"
"3.19800","0.26666","0.00081"
"3.44400","0.28717","0.00020"
"3.69000","0.30768","0.00073"
"3.93600","0.32812","0.00089"
"4.18200","0.34869","0.00019"
"4.42800","0.36920","0.00079"
"4.67400","0.38971","0.00038"
"4.92000","0.41010","0.00072"
"5.16600","0.43072","0.00104"
"5.41200","0.45111","0.00093"
"5.65800","0.47168","0.00067"
"5.90400","0.49219","0.00084"
"6.15000","0.51264","0.00097"
"6.39600","0.53320","0.00043"
"6.64200","0.55365","0.00105"
"6.88800","0.57416","0.00070"
"7.13400","0.59461","0.00145"
"7.38000","0.61517","0.00107"
"7.62600","0.63562","0.00138"
"7.87200","0.65625","0.00123"
"8.11800","0.67664","0.00126"
"8.36400","0.69721","0.00107"
"8.61000","0.71771","0.00098"
"8.85600","0.73822","0.00108"
"9.10200","0.75861","0.00110"
"9.34800","0.77912","0.00116"
"9.59400","0.79969","0.00169"
"9.84000","0.82019","0.00154"
"10.08600","0.84070","0.00157"
"10.33200","0.86115","0.00108"
"10.57800","0.88172","0.00149"
"10.82400","0.90210","0.00126"
"11.07000","0.92273","0.00155"
"11.31600","0.94318","0.00163"
"11.56200","0.96369","0.00152"
"11.80800","0.98414","0.00168"
"12.05400","1.00470","0.00125"
"12.30000","1.02521","0.00181"
"12.54600","1.04566","0.00127"
"12.79200","1.06617","0.00159"
"13.03800","1.08667","0.00165"
"13.28400","1.10718","0.00213"
"13.53000","1.12763","0.00125"
"13.77600","1.14820","0.00129"
"14.02200","1.16865","0.00161"
"14.26800","1.18921","0.00197"
"14.51400","1.20966","0.00175"
"14.76000","1.23017","0.00187"
"15.00600","1.25068","0.00188"
"15.25200","1.27119","0.00179"
"15.49800","1.29169","0.00260"
"15.74400","1.31214","0.00235"
"15.99000","1.33265","0.00177"
"16.23600","1.35316","0.00138"
"16.48200","1.37372","0.00171"
"16.72800","1.39417","0.00211"
"16.97400","1.41462","0.00208"
"17.22000","1.43513","0.00170"
"17.46600","1.45570","0.00180"
"17.71200","1.47614","0.00234"
"17.95800","1.49665","0.00193"
"18.20400","1.51722","0.00216"
"18.45000","1.53767","0.00155"
"18.69600","1.55823","0.00240"
"18.94200","1.57862","0.00217"
"19.18800","1.59919","0.00269"
"19.43400","1.61964","0.00207"
"19.68000","1.64021","0.00159"
"19.92600","1.66065","0.00255"
"20.17200","1.68122","0.00188"
"20.41800","1.70167","0.00245"
"20.66400","1.72224","0.00202"
"20.91000","1.74275","0.00179"
"21.15600","1.76313","0.00261"
"21.40200","1.78370","0.00193"
"21.64800","1.80415","0.00216"
"21.89400","1.82472","0.00254"
"22.14000","1.84510","0.00226"
"22.38600","1.86567","0.00255"
"22.63200","1.88618","0.00251"
"22.87800","1.90669","0.00194"
"23.12400","1.92720","0.00278"
"23.37000","1.94770","0.00244"
"23.61600","1.96815","0.00267"
"23.86200","1.98866","0.00262"
"24.10800","2.00923","0.00209"
"24.35400","2.02962","0.00238"
"24.60000","2.05012","0.00256"
"24.84600","2.07063","0.00249"
"25.09200","2.09126","0.00230"
"25.33800","2.11165","0.00296"
"25.58400","2.13215","0.00272"
"25.83000","2.15266","0.00269"
"26.07600","2.17317","0.00228"
"26.32200","2.19362","0.00262"
"26.56800","2.21419","0.00254"
"26.81400","2.23469","0.00299"
"27.06000","2.25520","0.00228"
"27.30600","2.27571","0.00282"
"27.55200","2.29610","0.00279"
"27.79800","2.31672","0.00271"
"28.04400","2.33711","0.00298"
"28.29000","2.35768","0.00307"
"28.53600","2.37819","0.00289"
"28.78200","2.39870","0.00301"
"29.02800","2.41920","0.00285"
"29.27400","2.43971","0.00256"
"29.52000","2.46022","0.00336"
"29.76600","2.48061","0.00283"
"30.01200","2.50118","0.00277"
"30.25800","2.52162","0.00314"
"30.50400","2.54219","0.00320"
"30.75000","2.56264","0.00330"
"30.99600","2.58315","0.00273"
"31.24200","2.60365","0.00290"
"31.48800","2.62422","0.00325"
"31.73400","2.64467","0.00297"
"31.98000","2.66518","0.00251"
"32.22600","2.68569","0.00245"
"32.47200","2.70613","0.00313"
"32.71800","2.72670","0.00265"
"32.96400","2.74715","0.00346"
"33.21000","2.76766","0.00335"
"33.45600","2.78817","0.00315"
"33.70200","2.80873","0.00343"
"33.94800","2.82918","0.00290"
"34.19400","2.84975","0.00333"
"34.44000","2.87014","0.00348"
"34.68600","2.89070","0.00303"
"34.93200","2.91115","0.00326"
"35.17800","2.93166","0.00386"
"35.42400","2.95217","0.00320"
"35.67000","2.97268","0.00314"
"35.91600","2.99324","0.00299"
"36.16200","3.01363","0.00321"
"36.40800","3.03420","0.00391"
"36.65400","3.05465","0.00317"
"36.90000","3.07516","0.00313"
"37.14600","3.09566","0.00378"
"37.39200","3.11617","0.00348"
"37.63800","3.13662","0.00333"
"37.88400","3.15719","0.00376"
"38.13000","3.17769","0.00367"
"38.37600","3.19814","0.00303"
"38.62200","3.21871","0.00378"
"38.86800","3.23916","0.00377"
"39.11400","3.25967","0.00415"
"39.36000","3.28011","0.00393"
"39.60600","3.30068","0.00357"
"39.85200","3.32119","0.00433"
"40.09800","3.34170","0.00383"
"40.34400","3.36220","0.00357"
"40.59000","3.38271","0.00375"
"40.83600","3.40316","0.00409"
"41.08200","3.42367","0.00409"
"41.32800","3.44424","0.00443"
"41.57400","3.46468","0.00465"
"41.82000","3.48519","0.00488"
"42.06600","3.50564","0.00365"
"42.31200","3.52621","0.00373"
"42.55800","3.54666","0.00396"
"42.80400","3.56716","0.00411"
"43.05000","3.58767","0.00448"
"43.29600","3.60818","0.00430"
"43.54200","3.62869","0.00388"
"43.78800","3.64913","0.00448"
"44.03400","3.66970","0.00469"
"44.28000","3.69015","0.00384"
"44.52600","3.71066","0.00446"
"44.77200","3.73117","0.00419"
"45.01800","3.75167","0.00416"
"45.26400","3.77212","0.00449"
"45.51000","3.79269","0.00450"
"45.75600","3.81320","0.00413"
"46.00200","3.83371","0.00426"
"46.24800","3.85415","0.00477"
"46.49400","3.87472","0.00462"
"46.74000","3.89523","0.00456"
"46.98600","3.91562","0.00447"
"47.23200","3.93618","0.00443"
"47.47800","3.95669","0.00448"
"47.72400","3.97720","0.00474"
"47.97000","3.99759","0.00468"
"48.21600","4.01822","0.00395"
"48.46200","4.03866","0.00430"
"48.70800","4.05917","0.00485"
"48.95400","4.07968","0.00439"
"49.20000","4.10019","0.00434"
"49.44600","4.12069","0.00473"
"49.69200","4.14120","0.00366"
"49.93800","4.16171","0.00400"
"50.18400","4.18216","0.00443"
"50.43000","4.20267","0.00368"
"50.67600","4.22311","0.00449"
"50.92200","4.24374","0.00443"
"51.16800","4.26419","0.00435"
"51.41400","4.28470","0.00389"
"51.66000","4.30515","0.00452"
"51.90600","4.32571","0.00424"
"52.15200","4.34610","0.00440"
"52.39800","4.36667","0.00494"
"52.64400","4.38718","0.00452"
"52.89000","4.40762","0.00479"
"53.13600","4.42819","0.00363"
"53.38200","4.44864","0.00447"
"53.62800","4.46921","0.00427"
"53.87400","4.48966","0.00417"
"54.12000","4.51022","0.00487"
"54.36600","4.53067","0.00453"
"54.61200","4.55118","0.00444"
"54.85800","4.57169","0.00421"
"55.10400","4.59213","0.00458"
"55.35000","4.61270","0.00476"
"55.59600","4.63309","0.00448"
"55.84200","4.65366","0.00469"
"56.08800","4.67417","0.00463"
"56.33400","4.69473","0.00444"
"56.58000","4.71512","0.00408"
"56.82600","4.73569","0.00496"
"57.07200","4.75614","0.00413"
"57.31800","4.77665","0.00489"
"57.56400","4.79715","0.00461"
"57.81000","4.81766","0.00471"
"58.05600","4.83817","0.00457"
"58.30200","4.85868","0.00484"
"58.54800","4.87924","0.00478"
"58.79400","4.89963","0.00446"
"59.04000","4.92020","0.00459"
"59.28600","4.94065","0.00485"
"59.53200","4.96122","0.00497"
"59.77800","4.98166","0.00472"
"60.02400","5.00217","0.00473"
"60.27000","5.02268","0.00404"
"60.51600","5.04319","0.00499"
"60.76200","5.06364","0.00449"
"61.00800","5.08420","0.00518"
"61.25400","5.10471","0.00487"
"61.50000","5.12516","0.00505"
"61.74600","5.14567","0.00476"
"61.99200","5.16611","0.00535"
"62.23800","5.18674","0.00492"
"62.48400","5.20719","0.00491"
"62.73000","5.22770","0.00449"
"62.97600","5.24815","0.00465"
"63.22200","5.26871","0.00498"
"63.46800","5.28916","0.00479"
"63.71400","5.30973","0.00457"
"63.96000","5.33018","0.00448"
"64.20600","5.35063","0.00511"
"64.45200","5.37119","0.00501"
"64.69800","5.39164","0.00540"
"64.94400","5.41221","0.00431"
"65.19000","5.43260","0.00473"
"65.43600","5.45322","0.00493"
"65.68200","5.47367","0.00505"
"65.92800","5.49418","0.00457"
"66.17400","5.51469","0.00456"
"66.42000","5.53514","0.00502"
"66.66600","5.55570","0.00483"
"66.91200","5.57615","0.00529"
"67.15800","5.59672","0.00495"
"67.40400","5.61717","0.00503"
"67.65000","5.63767","0.00449"
"67.89600","5.65812","0.00479"
"68.14200","5.67869","0.00496"
"68.38800","5.69914","0.00486"
"68.63400","5.71965","0.00411"
"68.88000","5.74015","0.00440"
"69.12600","5.76072","0.00436"
"69.37200","5.78117","0.00525"
"69.61800","5.80168","0.00448"
"69.86400","5.82219","0.00506"
"70.11000","5.84269","0.00456"
"70.35600","5.86320","0.00484"
"70.60200","5.88365","0.00461"
"70.84800","5.90422","0.00506"
"71.09400","5.92460","0.00460"
"71.34000","5.94517","0.00444"
"71.58600","5.96568","0.00534"
"71.83200","5.98619","0.00433"
"72.07800","6.00670","0.00464"
"72.32400","6.02720","0.00466"
"72.57000","6.04771","0.00495"
"72.81600","6.06810","0.00502"
"73.06200","6.08873","0.00424"
"73.30800","6.10918","0.00520"
"73.55400","6.12968","0.00522"
"73.80000","6.15013","0.00501"
"74.04600","6.17070","0.00513"
"74.29200","6.19115","0.00461"
"74.53800","6.21165","0.00524"
"74.78400","6.23216","0.00550"
"75.03000","6.25267","0.00503"
"75.27600","6.27318","0.00535"
"75.52200","6.29363","0.00568"
"75.76800","6.31419","0.00567"
"76.01400","6.33464","0.00490"
"76.26000","6.35521","0.00560"
"76.50600","6.37560","0.00551"
"76.75200","6.39622","0.00516"
"76.99800","6.41667","0.00507"
"77.24400","6.43718","0.00541"
"77.49000","6.45769","0.00552"
"77.73600","6.47820","0.00571"
"77.98200","6.49864","0.00534"
"78.22800","6.51915","0.00573"
"78.47400","6.53966","0.00560"
"78.72000","6.56017","0.00507"
"78.96600","6.58068","0.00512"
"79.21200","6.60112","0.00526"
"79.45800","6.62169","0.00534"
"79.70400","6.64214","0.00533"
"79.95000","6.66271","0.00594"
"80.19600","6.68315","0.00577"
"80.44200","6.70366","0.00605"
"80.68800","6.72411","0.00584"
"80.93400","6.74468","0.00505"
"81.18000","6.76519","0.00529"
"81.42600","6.78563","0.00604"
"81.67200","6.80620","0.00558"
"81.91800","6.82671","0.00580"
"82.16400","6.84716","0.00559"
"82.41000","6.86761","0.00596"
"82.65600","6.88823","0.00590"
"82.90200","6.90868","0.00608"
"83.14800","6.92919","0.00591"
"83.39400","6.94970","0.00578"
"83.64000","6.97020","0.00550"
"83.88600","6.99071","0.00603"
"84.13200","7.01116","0.00544"
"84.37800","7.03173","0.00534"
"84.62400","7.05218","0.00606"
"84.87000","7.07268","0.00543"
"85.11600","7.09313","0.00583"
"85.36200","7.11370","0.00593"
"85.60800","7.13415","0.00646"
"85.85400","7.15465","0.00618"
"86.10000","7.17516","0.00606"
"86.34600","7.19573","0.00591"
"86.59200","7.21612","0.00638"
"86.83800","7.23663","0.00612"
"87.08400","7.25713","0.00615"
"87.33000","7.27764","0.00612"
"87.57600","7.29821","0.00613"
"87.82200","7.31866","0.00543"
"88.06800","7.33923","0.00508"
"88.31400","7.35961","0.00545"
"88.56000","7.38018","0.00548"
"88.80600","7.40063","0.00550"
"89.05200","7.42120","0.00526"
"89.29800","7.44164","0.00538"
"89.54400","7.46215","0.00575"
"89.79000","7.48272","0.00548"
"90.03600","7.50311","0.00532"
"90.28200","7.52368","0.00581"
"90.52800","7.54418","0.00606"
"90.77400","7.56469","0.00568"
"91.02000","7.58514","0.00541"
"91.26600","7.60565","0.00559"
"91.51200","7.62610","0.00624"
"91.75800","7.64666","0.00586"
"92.00400","7.66717","0.00540"
"92.25000","7.68774","0.00597"
"92.49600","7.70819","0.00632"
"92.74200","7.72869","0.00548"
"92.98800","7.74920","0.00605"
"93.23400","7.76965","0.00544"
"93.48000","7.79016","0.00625"
"93.72600","7.81067","0.00492"
"93.97200","7.83123","0.00594"
"94.21800","7.85168","0.00617"
"94.46400","7.87219","0.00545"
"94.71000","7.89270","0.00585"
"94.95600","7.91320","0.00619"
"95.20200","7.93365","0.00579"
"95.44800","7.95416","0.00541"
"95.69400","7.97473","0.00619"
"95.94000","7.99518","0.00587"
"96.18600","8.01568","0.00616"
"96.43200","8.03613","0.00546"
"96.67800","8.05670","0.00594"
"96.92400","8.07709","0.00590"
"97.17000","8.09771","0.00558"
"97.41600","8.11816","0.00575"
"97.66200","8.13867","0.00622"
"97.90800","8.15912","0.00622"
"98.15400","8.17969","0.00622"
"98.40000","8.20019","0.00549"
"98.64600","8.22064","0.00661"
"98.89200","8.24121","0.00614"
"99.13800","8.26166","0.00569"
"99.38400","8.28223","0.00567"
"99.63000","8.30261","0.00643"
"99.87600","8.32318","0.00594"
"100.12200","8.34363","0.00586"
"100.36800","8.36420","0.00641"
"100.61400","8.38465","0.00608"
"100.86000","8.40521","0.00570"
"101.10600","8.42566","0.00612"
"101.35200","8.44617","0.00586"
"101.59800","8.46674","0.00583"
"101.84400","8.48718","0.00618"
"102.09000","8.50769","0.00614"
"102.33600","8.52808","0.00611"
"102.58200","8.54871","0.00612"
"102.82800","8.56916","0.00632"
"103.07400","8.58972","0.00592"
"103.32000","8.61017","0.00638"
"103.56600","8.63068","0.00613"
"103.81200","8.65113","0.00633"
"104.05800","8.67169","0.00599"
"104.30400","8.69220","0.00573"
"104.55000","8.71265","0.00667"
"104.79600","8.73322","0.00578"
"105.04200","8.75367","0.00653"
"105.28800","8.77423","0.00632"
"105.53400","8.79462","0.00576"
"105.78000","8.81519","0.00621"
"106.02600","8.83564","0.00628"
"106.27200","8.85620","0.00665"
"106.51800","8.87671","0.00613"
"106.76400","8.89716","0.00604"
"107.01000","8.91773","0.00740"
"107.25600","8.93812","0.00639"
"107.50200","8.95868","0.00658"
"107.74800","8.97913","0.00678"
"107.99400","8.99970","0.00681"
"108.24000","9.02015","0.00687"
"108.48600","9.04066","0.00648"
"108.73200","9.06116","0.00619"
"108.97800","9.08167","0.00693"
"109.22400","9.10218","0.00636"
"109.47000","9.12269","0.00676"
"109.71600","9.14320","0.00702"
"109.96200","9.16364","0.00678"
"110.20800","9.18421","0.00666"
"110.45400","9.20466","0.00711"
"110.70000","9.22517","0.00708"
"110.94600","9.24561","0.00715"
"111.19200","9.26624","0.00710"
"111.43800","9.28663","0.00695"
"111.68400","9.30720","0.00628"
"111.93000","9.32765","0.00642"
"112.17600","9.34821","0.00667"
"112.42200","9.36866","0.00669"
"112.66800","9.38917","0.00733"
"112.91400","9.40974","0.00660"
"113.16000","9.43012","0.00707"
"113.40600","9.45069","0.00813"
"113.65200","9.47114","0.00659"
"113.89800","9.49171","0.00728"
"114.14400","9.51210","0.00727"
"114.39000","9.53272","0.00712"
"114.63600","9.55317","0.00756"
"114.88200","9.57368","0.00758"
"115.12800","9.59419","0.00753"
"115.37400","9.61469","0.00722"
"115.62000","9.63520","0.00726"
"115.86600","9.65565","0.00695"
"116.11200","9.67622","0.00715"
"116.35800","9.69667","0.00687"
"116.60400","9.71723","0.00767"
"116.85000","9.73762","0.00760"
"117.09600","9.75819","0.00725"
"117.34200","9.77864","0.00741"
"117.58800","9.79920","0.00733"
"117.83400","9.81965","0.00742"
"118.08000","9.84022","0.00729"
"118.32600","9.86067","0.00730"
"118.57200","9.88112","0.00770"
"118.81800","9.90168","0.00706"
"119.06400","9.92213","0.00715"
"119.31000","9.94270","0.00770"
"119.55600","9.96315","0.00761"
"119.80200","9.98366","0.00759"
"120.04800","10.00416","0.00733"
"120.29400","10.02473","0.00684"
"120.54000","10.04518","0.00766"
"120.78600","10.06575","0.00774"
"121.03200","10.08614","0.00818"
"121.27800","10.10664","0.00781"
"121.52400","10.12715","0.00797"
"121.77000","10.14766","0.00776"
"122.01600","10.16817","0.00766"
"122.26200","10.18867","0.00704"
"122.50800","10.20918","0.00808"
"122.75400","10.22963","0.00801"
"123.00000","10.25020","0.00799"
"123.24600","10.27065","0.00757"
"123.49200","10.29121","0.00725"
"123.73800","10.31166","0.00773"
"123.98400","10.33217","0.00819"
"124.23000","10.35268","0.00818"
"124.47600","10.37313","0.00790"
"124.72200","10.39375","0.00792"
"124.96800","10.41414","0.00727"
"125.21400","10.43471","0.00789"
"125.46000","10.45510","0.00855"
"125.70600","10.47572","0.00862"
"125.95200","10.49617","0.00781"
"126.19800","10.51668","0.00763"
"126.44400","10.53719","0.00777"
"126.69000","10.55770","0.00806"
"126.93600","10.57820","0.00800"
"127.18200","10.59865","0.00774"
"127.42800","10.61922","0.00815"
"127.67400","10.63967","0.00825"
"127.92000","10.66018","0.00790"
"128.16600","10.68062","0.00816"
"128.41200","10.70119","0.00805"
"128.65800","10.72164","0.00754"
"128.90400","10.74221","0.00767"
"129.15000","10.76265","0.00794"
"129.39600","10.78322","0.00708"
"129.64200","10.80361","0.00756"
"129.88800","10.82418","0.00751"
"130.13400","10.84468","0.00705"
"130.38000","10.86519","0.00770"
"130.62600","10.88570","0.00795"
"130.87200","10.90615","0.00811"
"131.11800","10.92672","0.00734"
"131.36400","10.94717","0.00818"
"131.61000","10.96767","0.00781"
"131.85600","10.98818","0.00795"
"132.10200","11.00869","0.00790"
"132.34800","11.02920","0.00788"
"132.59400","11.04970","0.00805"
"132.84000","11.07021","0.00798"
"133.08600","11.09066","0.00781"
"133.33200","11.11117","0.00748"
"133.57800","11.13167","0.00812"
"133.82400","11.15218","0.00773"
"134.07000","11.17263","0.00812"
"134.31600","11.19320","0.00824"
"134.56200","11.21365","0.00745"
"134.80800","11.23421","0.00809"
"135.05400","11.25466","0.00755"
"135.30000","11.27517","0.00825"
"135.54600","11.29568","0.00783"
"135.79200","11.31618","0.00815"
"136.03800","11.33669","0.00795"
"136.28400","11.35714","0.00801"
"136.53000","11.37771","0.00836"
"136.77600","11.39816","0.00812"
"137.02200","11.41872","0.00819"
"137.26800","11.43917","0.00807"
"137.51400","11.45968","0.00818"
"137.76000","11.48019","0.00825"
"138.00600","11.50070","0.00782"
"138.25200","11.52114","0.00833"
"138.49800","11.54165","0.00851"
"138.74400","11.56216","0.00831"
"138.99000","11.58267","0.00808"
"139.23600","11.60318","0.00846"
"139.48200","11.62362","0.00788"
"139.72800","11.64419","0.00872"
"139.97400","11.66464","0.00813"
"140.22000","11.68521","0.00839"
"140.46600","11.70566","0.00805"
"140.71200","11.72616","0.00870"
"140.95800","11.74667","0.00827"
"141.20400","11.76718","0.00800"
"141.45000","11.78769","0.00817"
"141.69600","11.80814","0.00844"
"141.94200","11.82870","0.00871"
"142.18800","11.84921","0.00792"
"142.43400","11.86972","0.00864"
"142.68000","11.89017","0.00855"
"142.92600","11.91067","0.00842"
"143.17200","11.93118","0.00920"
"143.41800","11.95169","0.00868"
"143.66400","11.97214","0.00856"
"143.91000","11.99270","0.00837"
"144.15600","12.01321","0.00788"
"144.40200","12.03366","0.00879"
"144.64800","12.05417","0.00852"
"144.89400","12.07468","0.00846"
"145.14000","12.09518","0.00936"
"145.38600","12.11563","0.00902"
"145.63200","12.13620","0.00829"
"145.87800","12.15665","0.00893"
"146.12400","12.17715","0.00853"
"146.37000","12.19766","0.00828"
"146.61600","12.21823","0.00837"
"146.86200","12.23862","0.00841"
"147.10800","12.25919","0.00868"
"147.35400","12.27969","0.00815"
"147.60000","12.30014","0.00816"
"147.84600","12.32071","0.00852"
"148.09200","12.34116","0.00838"
"148.33800","12.36167","0.00866"
"148.58400","12.38217","0.00908"
"148.83000","12.40274","0.00791"
"149.07600","12.42313","0.00827"
"149.32200","12.44370","0.00874"
"149.56800","12.46415","0.00857"
"149.81400","12.48471","0.00833"
"150.06000","12.50522","0.00960"
"150.30600","12.52567","0.00888"
"150.55200","12.54618","0.00816"
"150.79800","12.56668","0.00825"
"151.04400","12.58719","0.00867"
"151.29000","12.60758","0.00848"
"151.53600","12.62821","0.00836"
"151.78200","12.64865","0.00858"
"152.02800","12.66916","0.00916"
"152.27400","12.68967","0.00887"
"152.52000","12.71018","0.00900"
"152.76600","12.73069","0.00894"
"153.01200","12.75113","0.00877"
"153.25800","12.77170","0.00900"
"153.50400","12.79215","0.00907"
"153.75000","12.81266","0.00823"
"153.99600","12.83311","0.00865"
"154.24200","12.85373","0.00869"
"154.48800","12.87418","0.00884"
"154.73400","12.89469","0.00869"
"154.98000","12.91514","0.00879"
"155.22600","12.93571","0.00920"
"155.47200","12.95615","0.00843"
"155.71800","12.97672","0.00914"
"155.96400","12.99717","0.00931"
"156.21000","13.01768","0.00904"
"156.45600","13.03818","0.00904"
"156.70200","13.05863","0.00931"
"156.94800","13.07920","0.00931"
"157.19400","13.09959","0.00885"
"157.44000","13.12016","0.00904"
"157.68600","13.14066","0.00898"
"157.93200","13.16123","0.00931"
"158.17800","13.18168","0.00829"
"158.42400","13.20219","0.00881"
"158.67000","13.22269","0.00812"
"158.91600","13.24314","0.00867"
"159.16200","13.26371","0.00948"
"159.40800","13.28416","0.00934"
"159.65400","13.30473","0.00866"
"159.90000","13.32511","0.00882"
"160.14600","13.34568","0.00904"
"160.39200","13.36619","0.00904"
"160.63800","13.38670","0.00907"
"160.88400","13.40714","0.00926"
"161.13000","13.42765","0.00936"
"161.37600","13.44822","0.00890"
"161.62200","13.46861","0.00929"
"161.86800","13.48924","0.00987"
"162.11400","13.50962","0.00882"
"162.36000","13.53019","0.00876"
"162.60600","13.55064","0.00868"
"162.85200","13.57121","0.00929"
"163.09800","13.59166","0.00848"
"163.34400","13.61222","0.00873"
"163.59000","13.63267","0.00915"
"163.83600","13.65318","0.00897"
"164.08200","13.67363","0.00901"
"164.32800","13.69413","0.00873"
"164.57400","13.71470","0.00882"
"164.82000","13.73515","0.00848"
"165.06600","13.75572","0.00895"
"165.31200","13.77617","0.00874"
"165.55800","13.79673","0.00927"
"165.80400","13.81712","0.00921"
"166.05000","13.83769","0.00894"
"166.29600","13.85814","0.00908"
"166.54200","13.87871","0.00950"
"166.78800","13.89915","0.00905"
"167.03400","13.91966","0.00946"
"167.28000","13.94017","0.00930"
"167.52600","13.96062","0.00915"
"167.77200","13.98124","0.00912"
"168.01800","14.00163","0.00864"
"168.26400","14.02214","0.00916"
"168.51000","14.04259","0.00855"
"168.75600","14.06322","0.00925"
"169.00200","14.08366","0.00879"
"169.24800","14.10417","0.00918"
"169.49400","14.12468","0.00856"
"169.74000","14.14519","0.00924"
"169.98600","14.16570","0.00871"
"170.23200","14.18614","0.00860"
"170.47800","14.20671","0.00897"
"170.72400","14.22716","0.00959"
"170.97000","14.24773","0.00954"
"171.21600","14.26817","0.00920"
"171.46200","14.28868","0.00969"
"171.70800","14.30913","0.00884"
"171.95400","14.32970","0.00949"
"172.20000","14.35015","0.00962"
"172.44600","14.37071","0.00967"
"172.69200","14.39110","0.00883"
"172.93800","14.41167","0.00936"
"173.18400","14.43218","0.00899"
"173.43000","14.45268","0.00991"
"173.67600","14.47319","0.00964"
"173.92200","14.49370","0.00958"
"174.16800","14.51421","0.00896"
"174.41400","14.53460","0.00961"
"174.66000","14.55516","0.00954"
"174.90600","14.57561","0.00946"
"175.15200","14.59618","0.00915"
"175.39800","14.61669","0.00953"
"175.64400","14.63720","0.00996"
"175.89000","14.65770","0.00980"
"176.13600","14.67815","0.00940"
"176.38200","14.69872","0.00920"
"176.62800","14.71917","0.00877"
"176.87400","14.73967","0.00965"
"177.12000","14.76012","0.00934"
"177.36600","14.78069","0.00919"
"177.61200","14.80114","0.00904"
"177.85800","14.82165","0.00905"
"178.10400","14.84215","0.01022"
"178.35000","14.86266","0.00886"
"178.59600","14.88317","0.00949"
"178.84200","14.90368","0.00924"
"179.08800","14.92418","0.00966"
"179.33400","14.94469","0.00924"
"179.58000","14.96514","0.00915"
"179.82600","14.98559","0.00909"
"180.07200","15.00622","0.00926"
"180.31800","15.02667","0.00923"
"180.56400","15.04723","0.00932"
"180.81000","15.06768","0.00868"
"181.05600","15.08825","0.00959"
"181.30200","15.10864","0.00966"
"181.54800","15.12920","0.00960"
"181.79400","15.14971","0.00964"
"182.04000","15.17016","0.00922"
"182.28600","15.19067","0.00935"
"182.53200","15.21117","0.00865"
"182.77800","15.23168","0.00948"
"183.02400","15.25213","0.00934"
"183.27000","15.27264","0.00944"
"183.51600","15.29321","0.01005"
"183.76200","15.31371","0.00913"
"184.00800","15.33422","0.00917"
"184.25400","15.35467","0.00906"
"184.50000","15.37518","0.00930"
"184.74600","15.39563","0.00947"
"184.99200","15.41619","0.00935"
"185.23800","15.43670","0.00954"
"185.48400","15.45721","0.00895"
"185.73000","15.47760","0.00987"
"185.97600","15.49817","0.00966"
"186.22200","15.51867","0.00950"
"186.46800","15.53918","0.00981"
"186.71400","15.55963","0.00971"
"186.96000","15.58020","0.00982"
"187.20600","15.60070","0.00982"
"187.45200","15.62115","0.00940"
"187.69800","15.64166","0.00982"
"187.94400","15.66211","0.00983"
"188.19000","15.68268","0.00972"
"188.43600","15.70312","0.01003"
"188.68200","15.72375","0.00928"
"188.92800","15.74420","0.01021"
"189.17400","15.76471","0.01001"
"189.42000","15.78515","0.00987"
"189.66600","15.80572","0.01045"
"189.91200","15.82611","0.00986"
"190.15800","15.84668","0.01033"
"190.40400","15.86718","0.00967"
"190.65000","15.88763","0.01082"
"190.89600","15.90814","0.01042"
"191.14200","15.92865","0.01046"
"191.38800","15.94922","0.01067"
"191.63400","15.96966","0.01053"
"191.88000","15.99023","0.01001"
"192.12600","16.01062","0.01067"
"192.37200","16.03119","0.01007"
"192.61800","16.05164","0.01033"
"192.86400","16.07220","0.01024"
"193.11000","16.09271","0.01090"
"193.35600","16.11316","0.01055"
"193.60200","16.13373","0.01024"
"193.84800","16.15417","0.01098"
"194.09400","16.17468","0.01063"
"194.34000","16.19507","0.01006"
"194.58600","16.21570","0.01099"
"194.83200","16.23615","0.01126"
"195.07800","16.25665","0.01050"
"195.32400","16.27716","0.01067"
"195.57000","16.29767","0.01104"
"195.81600","16.31812","0.01064"
"196.06200","16.33869","0.01099"
"196.30800","16.35919","0.01092"
"196.55400","16.37970","0.01073"
"196.80000","16.40021","0.01096"
"197.04600","16.42066","0.01011"
"197.29200","16.44116","0.01107"
"197.53800","16.46167","0.01070"
"197.78400","16.48218","0.01066"
"198.03000","16.50269","0.01053"
"198.27600","16.52320","0.01046"
"198.52200","16.54358","0.01165"
"198.76800","16.56415","0.01126"
"199.01400","16.58472","0.01134"
"199.26000","16.60517","0.01155"
"199.50600","16.62574","0.01108"
"199.75200","16.64612","0.01168"
"199.99800","16.66669","0.01116"
"200.24400","16.68708","0.01161"
"200.49000","16.70765","0.01142"
"200.73600","16.72816","0.01139"
"200.98200","16.74872","0.01185"
"201.22800","16.76917","0.01171"
"201.47400","16.78974","0.01186"
"201.72000","16.81025","0.01203"
"201.96600","16.83064","0.01206"
"202.21200","16.85120","0.01252"
"202.45800","16.87165","0.01154"
"202.70400","16.89222","0.01236"
"202.95000","16.91261","0.01264"
"203.19600","16.93317","0.01275"
"203.44200","16.95362","0.01174"
"203.68800","16.97419","0.01233"
"203.93400","16.99464","0.01216"
"204.18000","17.01520","0.01279"
"204.42600","17.03571","0.01316"
"204.67200","17.05616","0.01219"
"204.91800","17.07667","0.01327"
"205.16400","17.09711","0.01308"
"205.41000","17.11768","0.01283"
"205.65600","17.13813","0.01267"
"205.90200","17.15870","0.01288"
"206.14800","17.17915","0.01260"
"206.39400","17.19965","0.01308"
"206.64000","17.22022","0.01271"
"206.88600","17.24073","0.01287"
"207.13200","17.26112","0.01168"
"207.37800","17.28163","0.01249"
"207.62400","17.30219","0.01214"
"207.87000","17.32264","0.01275"
"208.11600","17.34315","0.01182"
"208.36200","17.36366","0.01247"
"208.60800","17.38417","0.01246"
"208.85400","17.40461","0.01296"
"209.10000","17.42518","0.01293"
"209.34600","17.44563","0.01296"
"209.59200","17.46620","0.01357"
"209.83800","17.48664","0.01294"
"210.08400","17.50721","0.01298"
"210.33000","17.52772","0.01288"
"210.57600","17.54811","0.01332"
"210.82200","17.56868","0.01320"
"211.06800","17.58918","0.01346"
"211.31400","17.60969","0.01396"
"211.56000","17.63008","0.01378"
"211.80600","17.65071","0.01397"
"212.05200","17.67115","0.01385"
"212.29800","17.69172","0.01399"
"212.54400","17.71223","0.01444"
"212.79000","17.73268","0.01464"
"213.03600","17.75319","0.01431"
"213.28200","17.77363","0.01407"
"213.52800","17.79420","0.01417"
"213.77400","17.81471","0.01475"
"214.02000","17.83522","0.01490"
"214.26600","17.85560","0.01532"
"214.51200","17.87623","0.01547"
"214.75800","17.89668","0.01554"
"215.00400","17.91719","0.01502"
"215.25000","17.93770","0.01558"
"215.49600","17.95827","0.01559"
"215.74200","17.97865","0.01644"
"215.98800","17.99916","0.01564"
"216.23400","18.01967","0.01652"
"216.48000","18.04018","0.01595"
"216.72600","18.06068","0.01578"
"216.97200","18.08113","0.01570"
"217.21800","18.10170","0.01667"
"217.46400","18.12209","0.01635"
"217.71000","18.14272","0.01666"
"217.95600","18.16316","0.01631"
"218.20200","18.18373","0.01689"
"218.44800","18.20418","0.01712"
"218.69400","18.22469","0.01729"
"218.94000","18.24519","0.01790"
"219.18600","18.26564","0.01415"
"219.43200","18.28621","0.01484"
"219.67800","18.30666","0.01588"
"219.92400","18.32722","0.01653"
"220.17000","18.34767","0.01503"
"220.41600","18.36818","0.01695"
"220.66200","18.38863","0.01675"
"220.90800","18.40914","0.01599"
"221.15400","18.42964","0.01691"
"221.40000","18.45021","0.01642"
"221.64600","18.47066","0.01711"
"221.89200","18.49117","0.01702"
"222.13800","18.51168","0.01733"
"222.38400","18.53218","0.01796"
"222.63000","18.55269","0.01739"
"222.87600","18.57314","0.01784"
"223.12200","18.59371","0.01834"
"223.36800","18.61416","0.01871"
"223.61400","18.63466","0.01910"
"223.86000","18.65517","0.01911"
"224.10600","18.67568","0.01896"
"224.35200","18.69613","0.01894"
"224.59800","18.71663","0.01968"
"224.84400","18.73720","0.01998"
"225.09000","18.75765","0.02014"
"225.33600","18.77822","0.02090"
"225.58200","18.79867","0.02044"
"225.82800","18.81923","0.02067"
"226.07400","18.83962","0.01987"
"226.32000","18.86019","0.02087"
"226.56600","18.88064","0.02101"
"226.81200","18.90121","0.02179"
"227.05800","18.92165","0.02150"
"227.30400","18.94216","0.02188"
"227.55000","18.96267","0.02269"
"227.79600","18.98312","0.02318"
"228.04200","19.00368","0.02391"
"228.28800","19.02413","0.02334"
"228.53400","19.04470","0.02286"
"228.78000","19.06509","0.02322"
"229.02600","19.08572","0.02374"
"229.27200","19.10616","0.02427"
"229.51800","19.12673","0.02471"
"229.76400","19.14718","0.02562"
"230.01000","19.16769","0.02598"
"230.25600","19.18820","0.02577"
"230.50200","19.20864","0.02617"
"230.74800","19.22921","0.02591"
"230.99400","19.24966","0.02659"
"231.24000","19.27017","0.02556"
"231.48600","19.29062","0.02656"
"231.73200","19.31118","0.02566"
"231.97800","19.33169","0.02482"
"232.22400","19.35220","0.02469"
"232.47000","19.37265","0.02463"
"232.71600","19.39321","0.02483"
"232.96200","19.41366","0.02577"
"233.20800","19.43417","0.02547"
"233.45400","19.45468","0.02547"
"233.70000","19.47512","0.02570"
"233.94600","19.49569","0.02551"
"234.19200","19.51608","0.02598"
"234.43800","19.53671","0.02081"
"234.68400","19.55716","0.02082"
"234.93000","19.57766","0.02067"
"235.17600","19.59817","0.02113"
"235.42200","19.61868","0.02172"
"235.66800","19.63919","0.02212"
"235.91400","19.65970","0.02274"
"236.16000","19.68020","0.02275"
"236.40600","19.70065","0.02378"
"236.65200","19.72116","0.02406"
"236.89800","19.74166","0.02498"
"237.14400","19.76217","0.02507"
"237.39000","19.78262","0.02513"
"237.63600","19.80319","0.02525"
"237.88200","19.82364","0.02607"
"238.12800","19.84415","0.02686"
"238.37400","19.86465","0.02706"
"238.62000","19.88522","0.02715"
"238.86600","19.90567","0.02701"
"239.11200","19.92618","0.02805"
"239.35800","19.94669","0.02786"
"239.60400","19.96719","0.02843"
"239.85000","19.98770","0.02901"
"240.09600","20.00815","0.02961"
"240.34200","20.02872","0.02969"
"240.58800","20.04916","0.03078"
"240.83400","20.06967","0.03137"
"241.08000","20.09018","0.03102"
"241.32600","20.11069","0.03089"
"241.57200","20.13114","0.03170"
"241.81800","20.15170","0.03211"
"242.06400","20.17221","0.03370"
"242.31000","20.19266","0.03383"
"242.55600","20.21317","0.03438"
"242.80200","20.23362","0.03504"
"243.04800","20.25418","0.03519"
"243.29400","20.27457","0.03692"
"243.54000","20.29520","0.03696"
"243.78600","20.31565","0.03827"
"244.03200","20.33621","0.03908"
"244.27800","20.35666","0.03954"
"244.52400","20.37717","0.04086"
"244.77000","20.39768","0.04067"
"245.01600","20.41819","0.03977"
"245.26200","20.43869","0.04041"
"245.50800","20.45920","0.04201"
"245.75400","20.47971","0.04359"
"246.00000","20.50010","0.04358"
"246.24600","20.52066","0.04379"
"246.49200","20.54117","0.04393"
"246.73800","20.56168","0.04542"
"246.98400","20.58213","0.04522"
"247.23000","20.60270","0.04655"
"247.47600","20.62320","0.04605"
"247.72200","20.64365","0.04601"
"247.96800","20.66422","0.04726"
"248.21400","20.68467","0.04634"
"248.46000","20.70524","0.04552"
"248.70600","20.72562","0.04649"
"248.95200","20.74613","0.04711"
"249.19800","20.76664","0.04764"
"249.44400","20.78720","0.04833"
"249.69000","20.80766","0.04839"
"249.93600","20.82822","0.04903"
"250.18200","20.84861","0.04975"
"250.42800","20.86918","0.04915"
"250.67400","20.88969","0.04935"
"250.92000","20.91019","0.04985"
"251.16600","20.93070","0.05072"
"251.41200","20.95115","0.05082"
"251.65800","20.97166","0.05114"
"251.90400","20.99211","0.05184"
"252.15000","21.01267","0.05206"
"252.39600","21.03312","0.05223"
"252.64200","21.05369","0.05198"
"252.88800","21.07419","0.05261"
"253.13400","21.09470","0.05286"
"253.38000","21.11521","0.05283"
"253.62600","21.13566","0.04459"
"253.87200","21.15623","0.04140"
"254.11800","21.17662","0.04112"
"254.36400","21.19718","0.04133"
"254.61000","21.21757","0.04141"
"254.85600","21.23820","0.04185"
"255.10200","21.25865","0.04410"
"255.34800","21.27921","0.04389"
"255.59400","21.29966","0.04507"
"255.84000","21.32023","0.04516"
"256.08600","21.34068","0.04465"
"256.33200","21.36119","0.04559"
"256.57800","21.38169","0.04586"
"256.82400","21.40214","0.04659"
"257.07000","21.42271","0.04575"
"257.31600","21.44310","0.04737"
"257.56200","21.46373","0.04690"
"257.80800","21.48417","0.04805"
"258.05400","21.50474","0.04841"
"258.30000","21.52519","0.04938"
"258.54600","21.54576","0.04925"
"258.79200","21.56614","0.04553"
"259.03800","21.58665","0.04593"
"259.28400","21.60716","0.04566"
"259.53000","21.62767","0.04646"
"259.77600","21.64818","0.04619"
"260.02200","21.66862","0.04672"
"260.26800","21.68919","0.04684"
"260.51400","21.70964","0.04751"
"260.76000","21.73021","0.04696"
"261.00600","21.75065","0.04322"
"261.25200","21.77122","0.04347"
"261.49800","21.79167","0.04408"
"261.74400","21.81218","0.04539"
"261.99000","21.83269","0.04431"
"262.23600","21.85313","0.04557"
"262.48200","21.87370","0.04601"
"262.72800","21.89415","0.04647"
"262.97400","21.91472","0.04714"
"263.22000","21.93510","0.04742"
"263.46600","21.95567","0.04654"
"263.71200","21.97618","0.04479"
"263.95800","21.99669","0.04543"
"264.20400","22.01720","0.04605"
"264.45000","22.03765","0.04583"
"264.69600","22.05821","0.04688"
"264.94200","22.07866","0.04695"
"265.18800","22.09917","0.04728"
"265.43400","22.11968","0.04746"
"265.68000","22.14018","0.04888"
"265.92600","22.16063","0.04830"
"266.17200","22.18120","0.04888"
"266.41800","22.20165","0.04902"
"266.66400","22.22216","0.04882"
"266.91000","22.24266","0.04909"
"267.15600","22.26323","0.04935"
"267.40200","22.28362","0.04983"
"267.64800","22.30412","0.05044"
"267.89400","22.32469","0.05098"
"268.14000","22.34520","0.05061"
"268.38600","22.36571","0.04673"
"268.63200","22.38616","0.04744"
"268.87800","22.40672","0.04764"
"269.12400","22.42711","0.04859"
"269.37000","22.44768","0.04889"
"269.61600","22.46813","0.04836"
"269.86200","22.48870","0.04917"
"270.10800","22.50914","0.04967"
"270.35400","22.52971","0.04841"
"270.60000","22.55022","0.04931"
"270.84600","22.57067","0.04915"
"271.09200","22.59118","0.04743"
"271.33800","22.61168","0.04645"
"271.58400","22.63219","0.04626"
"271.83000","22.65264","0.04715"
"272.07600","22.67321","0.04466"
"272.32200","22.69366","0.04485"
"272.56800","22.71416","0.04341"
"272.81400","22.73467","0.04265"
"273.06000","22.75518","0.03797"
"273.30600","22.77569","0.03795"
"273.55200","22.79619","0.03794"
"273.79800","22.81670","0.03825"
"274.04400","22.83715","0.03636"
"274.29000","22.85766","0.03646"
"274.53600","22.87811","0.03697"
"274.78200","22.89867","0.03789"
"275.02800","22.91918","0.03924"
"275.27400","22.93969","0.03922"
"275.52000","22.96014","0.03930"
"275.76600","22.98070","0.03861"
"276.01200","23.00115","0.03900"
"276.25800","23.02166","0.03963"
"276.50400","23.04223","0.04034"
"276.75000","23.06268","0.04107"
"276.99600","23.08324","0.04094"
"277.24200","23.10363","0.04112"
"277.48800","23.12420","0.04124"
"277.73400","23.14465","0.04206"
"277.98000","23.16522","0.04243"
"278.22600","23.18567","0.04291"
"278.47200","23.20623","0.04345"
"278.71800","23.22668","0.04349"
"278.96400","23.24719","0.04337"
"279.21000","23.26776","0.04428"
"279.45600","23.28814","0.04395"
"279.70200","23.30871","0.04619"
"279.94800","23.32916","0.04535"
"280.19400","23.34973","0.04652"
"280.44000","23.37012","0.04660"
"280.68600","23.39068","0.04699"
"280.93200","23.41113","0.04785"
"281.17800","23.43170","0.04758"
"281.42400","23.45220","0.04796"
"281.67000","23.47271","0.04824"
"281.91600","23.49316","0.04850"
"282.16200","23.51367","0.04910"
"282.40800","23.53424","0.04983"
"282.65400","23.55468","0.05033"
"282.90000","23.57513","0.05057"
"283.14600","23.59564","0.05050"
"283.39200","23.61621","0.05095"
"283.63800","23.63665","0.05097"
"283.88400","23.65716","0.05129"
"284.13000","23.67767","0.05182"
"284.37600","23.69824","0.05168"
"284.62200","23.71863","0.05161"
"284.86800","23.73920","0.05175"
"285.11400","23.75964","0.05169"
"285.36000","23.78015","0.05209"
"285.60600","23.80066","0.05226"
"285.85200","23.82117","0.05254"
"286.09800","23.84174","0.05290"
"286.34400","23.86212","0.05278"
"286.59000","23.88263","0.05214"
"286.83600","23.90320","0.05199"
"287.08200","23.92370","0.05265"
"287.32800","23.94415","0.05176"
"287.57400","23.96472","0.05159"
"287.82000","23.98523","0.05199"
"288.06600","24.00562","0.05205"
"288.31200","24.02619","0.05241"
"288.55800","24.04663","0.05230"
"288.80400","24.06720","0.05199"
"289.05000","24.08765","0.05215"
"289.29600","24.10816","0.05229"
"289.54200","24.12866","0.05262"
"289.78800","24.14917","0.05294"
"290.03400","24.16968","0.05228"
"290.28000","24.19019","0.05300"
"290.52600","24.21070","0.05308"
"290.77200","24.23114","0.05295"
"291.01800","24.25171","0.05305"
"291.26400","24.27216","0.05330"
"291.51000","24.29267","0.05363"
"291.75600","24.31312","0.05340"
"292.00200","24.33368","0.05391"
"292.24800","24.35419","0.05421"
"292.49400","24.37476","0.05363"
"292.74000","24.39515","0.05403"
"292.98600","24.41571","0.05455"
"293.23200","24.43616","0.05453"
"293.47800","24.45667","0.05484"
"293.72400","24.47718","0.05527"
"293.97000","24.49769","0.05547"
"294.21600","24.51825","0.05567"
"294.46200","24.53864","0.05524"
"294.70800","24.55921","0.05573"
"294.95400","24.57960","0.05624"
"295.20000","24.60016","0.05619"
"295.44600","24.62067","0.05626"
"295.69200","24.64118","0.05682"
"295.93800","24.66163","0.05667"
"296.18400","24.68219","0.05693"
"296.43000","24.70270","0.05706"
"296.67600","24.72315","0.05747"
"296.92200","24.74372","0.05734"
"297.16800","24.76417","0.05775"
"297.41400","24.78467","0.05796"
"297.66000","24.80512","0.05783"
"297.90600","24.82569","0.05783"
"298.15200","24.84614","0.05829"
"298.39800","24.86670","0.05852"
"298.64400","24.88716","0.05912"
"298.89000","24.90772","0.05983"
"299.13600","24.92817","0.06028"
"299.38200","24.94862","0.06061"
"299.62800","24.96919","0.06121"
"299.87400","24.98969","0.06201"
"300.12000","25.01020","0.06244"
"300.36600","25.03065","0.06317"
"300.61200","25.05116","0.06386"
"300.85800","25.07166","0.06465"
"301.10400","25.09217","0.06517"
"301.35000","25.11268","0.06604"
"301.59600","25.13319","0.06705"
"301.84200","25.15364","0.06780"
"302.08800","25.17420","0.06833"
"302.33400","25.19465","0.06880"
"302.58000","25.21516","0.06987"
"302.82600","25.23567","0.07099"
"303.07200","25.25617","0.07172"
"303.31800","25.27674","0.07343"
"303.56400","25.29713","0.07387"
"303.81000","25.31770","0.07413"
"304.05600","25.33815","0.07625"
"304.30200","25.35872","0.07689"
"304.54800","25.37916","0.07744"
"304.79400","25.39967","0.07884"
"305.04000","25.42018","0.08001"
"305.28600","25.44063","0.07977"
"305.53200","25.46119","0.08072"
"305.77800","25.48164","0.08266"
"306.02400","25.50221","0.08333"
"306.27000","25.52260","0.08413"
"306.51600","25.54317","0.08533"
"306.76200","25.56367","0.08619"
"307.00800","25.58418","0.08673"
"307.25400","25.60463","0.08762"
"307.50000","25.62519","0.08907"
"307.74600","25.64570","0.09028"
"307.99200","25.66615","0.09151"
"308.23800","25.68672","0.09260"
"308.48400","25.70717","0.09374"
"308.73000","25.72767","0.09596"
"308.97600","25.74813","0.09654"
"309.22200","25.76869","0.09787"
"309.46800","25.78914","0.09815"
"309.71400","25.80971","0.09917"
"309.96000","25.83015","0.10004"
"310.20600","25.85072","0.10050"
"310.45200","25.87111","0.10090"
"310.69800","25.89162","0.10135"
"310.94400","25.91219","0.10184"
"311.19000","25.93269","0.10229"
"311.43600","25.95320","0.10307"
"311.68200","25.97365","0.10340"
"311.92800","25.99422","0.10383"
"312.17400","26.01461","0.10419"
"312.42000","26.03518","0.10047"
"312.66600","26.05568","0.10158"
"312.91200","26.07619","0.10194"
"313.15800","26.09670","0.10229"
"313.40400","26.11721","0.10283"
"313.65000","26.13765","0.10357"
"313.89600","26.15816","0.10344"
"314.14200","26.17867","0.10443"
"314.38800","26.19917","0.10526"
"314.63400","26.21974","0.10645"
"314.88000","26.24013","0.10688"
"315.12600","26.26070","0.10799"
"315.37200","26.28115","0.10932"
"315.61800","26.30171","0.11018"
"315.86400","26.32216","0.11126"
"316.11000","26.34267","0.11278"
"316.35600","26.36318","0.11457"
"316.60200","26.38369","0.11743"
"316.84800","26.40419","0.11604"
"317.09400","26.42464","0.11756"
"317.34000","26.44521","0.11940"
"317.58600","26.46560","0.12164"
"317.83200","26.48623","0.12408"
"318.07800","26.50667","0.12507"
"318.32400","26.52718","0.12666"
"318.57000","26.54763","0.12795"
"318.81600","26.56820","0.12925"
"319.06200","26.58864","0.13026"
"319.30800","26.60921","0.13174"
"319.55400","26.62972","0.13308"
"319.80000","26.65017","0.13418"
"320.04600","26.67068","0.13542"
"320.29200","26.69113","0.13627"
"320.53800","26.71169","0.13764"
"320.78400","26.73214","0.13796"
"321.03000","26.75271","0.13965"
"321.27600","26.77309","0.14101"
"321.52200","26.79372","0.14149"
"321.76800","26.81417","0.14211"
"322.01400","26.83474","0.14272"
"322.26000","26.85525","0.14374"
"322.50600","26.87563","0.14409"
"322.75200","26.89620","0.14447"
"322.99800","26.91665","0.14540"
"323.24400","26.93722","0.14580"
"323.49000","26.95755","0.14619"
"323.73600","26.97817","0.14615"
"323.98200","26.99868","0.14606"
"324.22800","27.01919","0.14568"
"324.47400","27.03970","0.14599"
"324.72000","27.06015","0.14613"
"324.96600","27.08071","0.14576"
"325.21200","27.10116","0.14678"
"325.45800","27.12167","0.14718"
"325.70400","27.14218","0.14743"
"325.95000","27.16268","0.14760"
"326.19600","27.18313","0.14813"
"326.44200","27.20364","0.14850"
"326.68800","27.22415","0.14860"
"326.93400","27.24460","0.14766"
"327.18000","27.26517","0.14759"
"327.42600","27.28573","0.14767"
"327.67200","27.30612","0.14803"
"327.91800","27.32669","0.14821"
"328.16400","27.34720","0.14783"
"328.41000","27.36770","0.14804"
"328.65600","27.38821","0.14833"
"328.90200","27.40866","0.14885"
"329.14800","27.42916","0.14925"
"329.39400","27.44962","0.14916"
"329.64000","27.47018","0.14939"
"329.88600","27.49063","0.14940"
"330.13200","27.51120","0.14998"
"330.37800","27.53170","0.15031"
"330.62400","27.55221","0.15089"
"330.87000","27.57272","0.15151"
"331.11600","27.59311","0.15255"
"331.36200","27.61368","0.15369"
"331.60800","27.63418","0.15447"
"331.85400","27.65469","0.15566"
"332.10000","27.67514","0.15741"
"332.34600","27.69571","0.15719"
"332.59200","27.71616","0.15867"
"332.83800","27.73667","0.16001"
"333.08400","27.75717","0.16146"
"333.33000","27.77768","0.16320"
"333.57600","27.79819","0.16467"
"333.82200","27.81864","0.16599"
"334.06800","27.83920","0.16808"
"334.31400","27.85965","0.17058"
"334.56000","27.88022","0.17340"
"334.80600","27.90061","0.17550"
"335.05200","27.92124","0.17611"
"335.29800","27.94168","0.17913"
"335.54400","27.96219","0.18001"
"335.79000","27.98270","0.18138"
"336.03600","28.00320","0.18363"
"336.28200","28.02365","0.18486"
"336.52800","28.04416","0.18536"
"336.77400","28.06467","0.18850"
"337.02000","28.08518","0.18966"
"337.26600","28.10569","0.19288"
"337.51200","28.12613","0.19450"
"337.75800","28.14664","0.19545"
"338.00400","28.16709","0.19822"
"338.25000","28.18765","0.19992"
"338.49600","28.20810","0.20189"
"338.74200","28.22867","0.20398"
"338.98800","28.24912","0.20456"
"339.23400","28.26975","0.20626"
"339.48000","28.29025","0.20730"
"339.72600","28.31064","0.20818"
"339.97200","28.33121","0.20857"
"340.21800","28.35166","0.20922"
"340.46400","28.37217","0.20938"
"340.71000","28.39262","0.21032"
"340.95600","28.41318","0.21045"
"341.20200","28.43363","0.21110"
"341.44800","28.45420","0.21118"
"341.69400","28.47470","0.21254"
"341.94000","28.49516","0.21278"
"342.18600","28.51566","0.21335"
"342.43200","28.53611","0.21378"
"342.67800","28.55674","0.21473"
"342.92400","28.57719","0.21577"
"343.17000","28.59769","0.21699"
"343.41600","28.61814","0.21813"
"343.66200","28.63871","0.21921"
"343.90800","28.65916","0.22135"
"344.15400","28.67966","0.22239"
"344.40000","28.70017","0.22316"
"344.64600","28.72074","0.22449"
"344.89200","28.74113","0.22533"
"345.13800","28.76163","0.22669"
"345.38400","28.78214","0.22770"
"345.63000","28.80265","0.22853"
"345.87600","28.82322","0.22978"
"346.12200","28.84367","0.23181"
"346.36800","28.86424","0.23413"
"346.61400","28.88462","0.23564"
"346.86000","28.90519","0.23737"
"347.10600","28.92564","0.23860"
"347.35200","28.94621","0.24047"
"347.59800","28.96666","0.24227"
"347.84400","28.98722","0.24366"
"348.09000","29.00773","0.24410"
"348.33600","29.02812","0.24571"
"348.58200","29.04869","0.24613"
"348.82800","29.06919","0.24737"
"349.07400","29.08970","0.24629"
"349.32000","29.11015","0.24747"
"349.56600","29.13066","0.24816"
"349.81200","29.15116","0.24878"
"350.05800","29.17173","0.24917"
"350.30400","29.19212","0.24984"
"350.55000","29.21269","0.24992"
"350.79600","29.23319","0.25015"
"351.04200","29.25370","0.18810"
"351.28800","29.27415","0.19224"
"351.53400","29.29466","0.19303"
"351.78000","29.31517","0.19055"
"352.02600","29.33562","0.20079"
"352.27200","29.35618","0.20506"
"352.51800","29.37663","0.20616"
"352.76400","29.39720","0.20881"
"353.01000","29.41771","0.20967"
"353.25600","29.43822","0.20994"
"353.50200","29.45866","0.21141"
"353.74800","29.47917","0.21113"
"353.99400","29.49968","0.21477"
"354.24000","29.52019","0.21325"
"354.48600","29.54070","0.21444"
"354.73200","29.56114","0.21717"
"354.97800","29.58171","0.21831"
"355.22400","29.60210","0.22026"
"355.47000","29.62267","0.22053"
"355.71600","29.64318","0.22486"
"355.96200","29.66368","0.22379"
"356.20800","29.68413","0.22534"
"356.45400","29.70470","0.22633"
"356.70000","29.72520","0.22884"
"356.94600","29.74565","0.23055"
"357.19200","29.76622","0.23012"
"357.43800","29.78667","0.23359"
"357.68400","29.80724","0.23466"
"357.93000","29.82763","0.23634"
"358.17600","29.84819","0.23513"
"358.42200","29.86864","0.01202"
"358.66800","29.88921","0.02493"
"358.91400","29.90965","0.00985"
"359.16000","29.93016","0.00906"
"359.40600","29.95067","0.00934"
"359.65200","29.97118","0.02012"
"359.89800","29.99169","0.00899"
"360.14400","30.01219","0.01190"
"360.39000","30.03270","0.01048"
"360.63600","30.05309","0.01040"
"360.83200","30.06953","0.01137"