File: Force_trajectories/170225_1/Specimen_RawData_2.csv
End date,"2/25/2017"
Specimen label,"2AT_11"
Maximum Load,"0.09713",N

Time,Extension,Load
(s),(mm),(N)
"0.00000","33.07342","0.03861"
"0.03000","33.07372","0.03843"
"0.06000","33.07449","0.03858"
"0.09000","33.07611","0.03874"
"0.12000","33.07832","0.03875"
"0.15000","33.08113","0.03862"
"0.18000","33.08436","0.03860"
"0.21000","33.08777","0.03885"
"0.24000","33.09123","0.03907"
"0.27000","33.09446","0.03873"
"0.30000","33.09763","0.03888"
"0.33000","33.10062","0.03906"
"0.36000","33.10349","0.03886"
"0.39000","33.10612","0.03902"
"0.42000","33.10875","0.03866"
"0.45000","33.11132","0.03895"
"0.48000","33.11383","0.03866"
"0.51000","33.11628","0.03926"
"0.54000","33.11874","0.03941"
"0.57000","33.12125","0.03923"
"0.60000","33.12370","0.03921"
"0.63000","33.12621","0.03952"
"0.66000","33.12866","0.03973"
"0.69000","33.13118","0.03934"
"0.72000","33.13369","0.03945"
"0.75000","33.13620","0.03966"
"0.78000","33.13865","0.03945"
"0.81000","33.14116","0.03946"
"0.84000","33.14367","0.03947"
"0.87000","33.14618","0.03923"
"0.90000","33.14869","0.03958"
"0.93000","33.15120","0.03957"
"0.96000","33.15365","0.03985"
"0.99000","33.15616","0.03962"
"1.02000","33.15874","0.03982"
"1.05000","33.16119","0.03972"
"1.08000","33.16370","0.03981"
"1.11000","33.16621","0.03999"
"1.14000","33.16872","0.03978"
"1.17000","33.17123","0.03975"
"1.20000","33.17368","0.03998"
"1.23000","33.17619","0.04009"
"1.26000","33.17865","0.03992"
"1.29000","33.18116","0.04037"
"1.32000","33.18361","0.04017"
"1.35000","33.18612","0.04021"
"1.38000","33.18857","0.04065"
"1.41000","33.19108","0.04064"
"1.44000","33.19359","0.04013"
"1.47000","33.19617","0.03995"
"1.50000","33.19868","0.04028"
"1.53000","33.20119","0.04061"
"1.56000","33.20370","0.04064"
"1.59000","33.20615","0.04047"
"1.62000","33.20866","0.04014"
"1.65000","33.21117","0.04038"
"1.68000","33.21368","0.04055"
"1.71000","33.21613","0.04061"
"1.74000","33.21864","0.04035"
"1.77000","33.22116","0.04003"
"1.80000","33.22372","0.04081"
"1.83000","33.22618","0.04052"
"1.86000","33.22863","0.04039"
"1.89000","33.23108","0.04062"
"1.92000","33.23359","0.04054"
"1.95000","33.23616","0.04043"
"1.98000","33.23862","0.04062"
"2.01000","33.24113","0.04083"
"2.04000","33.24364","0.04099"
"2.07000","33.24621","0.04055"
"2.10000","33.24872","0.04087"
"2.13000","33.25117","0.04111"
"2.16000","33.25362","0.04081"
"2.19000","33.25613","0.04095"
"2.22000","33.25864","0.04137"
"2.25000","33.26116","0.04087"
"2.28000","33.26367","0.04065"
"2.31000","33.26612","0.04062"
"2.34000","33.26863","0.04062"
"2.37000","33.27114","0.04082"
"2.40000","33.27359","0.04126"
"2.43000","33.27610","0.04094"
"2.46000","33.27855","0.04098"
"2.49000","33.28107","0.04114"
"2.52000","33.28363","0.04107"
"2.55000","33.28615","0.04105"
"2.58000","33.28866","0.04144"
"2.61000","33.29117","0.04103"
"2.64000","33.29368","0.04107"
"2.67000","33.29619","0.04140"
"2.70000","33.29865","0.04139"
"2.73000","33.30116","0.04140"
"2.76000","33.30367","0.04126"
"2.79000","33.30618","0.04151"
"2.82000","33.30869","0.04154"
"2.85000","33.31120","0.04164"
"2.88000","33.31371","0.04155"
"2.91000","33.31616","0.04170"
"2.94000","33.31861","0.04190"
"2.97000","33.32113","0.04176"
"3.00000","33.32364","0.04165"
"3.03000","33.32615","0.04148"
"3.06000","33.32860","0.04159"
"3.09000","33.33117","0.04148"
"3.12000","33.33368","0.04154"
"3.15000","33.33619","0.04176"
"3.18000","33.33870","0.04182"
"3.21000","33.34121","0.04214"
"3.24000","33.34367","0.04200"
"3.27000","33.34618","0.04189"
"3.30000","33.34863","0.04172"
"3.33000","33.35114","0.04166"
"3.36000","33.35365","0.04187"
"3.39000","33.35616","0.04203"
"3.42000","33.35867","0.04191"
"3.45000","33.36113","0.04177"
"3.48000","33.36364","0.04211"
"3.51000","33.36609","0.04193"
"3.54000","33.36854","0.04204"
"3.57000","33.37105","0.04198"
"3.60000","33.37356","0.04202"
"3.63000","33.37613","0.04221"
"3.66000","33.37870","0.04244"
"3.69000","33.38121","0.04236"
"3.72000","33.38372","0.04240"
"3.75000","33.38617","0.04219"
"3.78000","33.38869","0.04214"
"3.81000","33.39120","0.04227"
"3.84000","33.39371","0.04225"
"3.87000","33.39616","0.04215"
"3.90000","33.39861","0.04214"
"3.93000","33.40112","0.04245"
"3.96000","33.40369","0.04265"
"3.99000","33.40615","0.04259"
"4.02000","33.40866","0.04234"
"4.05000","33.41111","0.04217"
"4.08000","33.41362","0.04243"
"4.11000","33.41613","0.04253"
"4.14000","33.41864","0.04247"
"4.17000","33.42115","0.04244"
"4.20000","33.42360","0.04260"
"4.23000","33.42618","0.04253"
"4.26000","33.42869","0.04272"
"4.29000","33.43120","0.04273"
"4.32000","33.43365","0.04289"
"4.35000","33.43616","0.04272"
"4.38000","33.43867","0.04293"
"4.41000","33.44118","0.04311"
"4.44000","33.44363","0.04306"
"4.47000","33.44614","0.04297"
"4.50000","33.44860","0.04316"
"4.53000","33.45111","0.04312"
"4.56000","33.45362","0.04281"
"4.59000","33.45607","0.04266"
"4.62000","33.45858","0.04290"
"4.65000","33.46109","0.04306"
"4.68000","33.46360","0.04316"
"4.71000","33.46611","0.04299"
"4.74000","33.46863","0.04290"
"4.77000","33.47114","0.04304"
"4.80000","33.47365","0.04303"
"4.83000","33.47616","0.04317"
"4.86000","33.47861","0.04332"
"4.89000","33.48118","0.04308"
"4.92000","33.48369","0.04307"
"4.95000","33.48620","0.04307"
"4.98000","33.48866","0.04318"
"5.01000","33.49110","0.04336"
"5.04000","33.49362","0.04314"
"5.07000","33.49613","0.04336"
"5.10000","33.49864","0.04331"
"5.13000","33.50115","0.04327"
"5.16000","33.50360","0.04328"
"5.19000","33.50605","0.04353"
"5.22000","33.50863","0.04352"
"5.25000","33.51114","0.04356"
"5.28000","33.51359","0.04370"
"5.31000","33.51610","0.04345"
"5.34000","33.51867","0.04343"
"5.37000","33.52118","0.04360"
"5.40000","33.52369","0.04339"
"5.43000","33.52620","0.04334"
"5.46000","33.52866","0.04357"
"5.49000","33.53117","0.04366"
"5.52000","33.53368","0.04385"
"5.55000","33.53619","0.04345"
"5.58000","33.53864","0.04349"
"5.61000","33.54115","0.04374"
"5.64000","33.54360","0.04365"
"5.67000","33.54611","0.04376"
"5.70000","33.54862","0.04385"
"5.73000","33.55114","0.04414"
"5.76000","33.55359","0.04386"
"5.79000","33.55610","0.04361"
"5.82000","33.55867","0.04375"
"5.85000","33.56112","0.04378"
"5.88000","33.56363","0.04404"
"5.91000","33.56608","0.04408"
"5.94000","33.56865","0.04411"
"5.97000","33.57122","0.04411"
"6.00000","33.57368","0.04407"
"6.03000","33.57619","0.04442"
"6.06000","33.57864","0.04427"
"6.09000","33.58115","0.04445"
"6.12000","33.58366","0.04441"
"6.15000","33.58611","0.04423"
"6.18000","33.58856","0.04412"
"6.21000","33.59107","0.04431"
"6.24000","33.59365","0.04449"
"6.27000","33.59616","0.04416"
"6.30000","33.59861","0.04436"
"6.33000","33.60112","0.04455"
"6.36000","33.60363","0.04434"
"6.39000","33.60620","0.04439"
"6.42000","33.60871","0.04454"
"6.45000","33.61110","0.04458"
"6.48000","33.61361","0.04468"
"6.51000","33.61613","0.04465"
"6.54000","33.61869","0.04452"
"6.57000","33.62115","0.04463"
"6.60000","33.62360","0.04461"
"6.63000","33.62611","0.04471"
"6.66000","33.62862","0.04480"
"6.69000","33.63113","0.04458"
"6.72000","33.63359","0.04485"
"6.75000","33.63610","0.04494"
"6.78000","33.63855","0.04489"
"6.81000","33.64112","0.04482"
"6.84000","33.64363","0.04477"
"6.87000","33.64614","0.04489"
"6.90000","33.64865","0.04498"
"6.93000","33.65116","0.04479"
"6.96000","33.65373","0.04472"
"6.99000","33.65619","0.04489"
"7.02000","33.65864","0.04496"
"7.05000","33.66115","0.04489"
"7.08000","33.66366","0.04480"
"7.11000","33.66617","0.04502"
"7.14000","33.66868","0.04494"
"7.17000","33.67113","0.04494"
"7.20000","33.67365","0.04498"
"7.23000","33.67616","0.04522"
"7.26000","33.67867","0.04527"
"7.29000","33.68112","0.04520"
"7.32000","33.68357","0.04508"
"7.35000","33.68608","0.04513"
"7.38000","33.68865","0.04516"
"7.41000","33.69117","0.04505"
"7.44000","33.69361","0.04525"
"7.47000","33.69613","0.04564"
"7.50000","33.69870","0.04554"
"7.53000","33.70121","0.04551"
"7.56000","33.70366","0.04540"
"7.59000","33.70617","0.04560"
"7.62000","33.70862","0.04557"
"7.65000","33.71113","0.04548"
"7.68000","33.71364","0.04565"
"7.71000","33.71615","0.04553"
"7.74000","33.71861","0.04557"
"7.77000","33.72112","0.04570"
"7.80000","33.72363","0.04561"
"7.83000","33.72608","0.04577"
"7.86000","33.72859","0.04584"
"7.89000","33.73110","0.04587"
"7.92000","33.73361","0.04559"
"7.95000","33.73613","0.04562"
"7.98000","33.73864","0.04569"
"8.01000","33.74115","0.04593"
"8.04000","33.74366","0.04594"
"8.07000","33.74611","0.04586"
"8.10000","33.74868","0.04581"
"8.13000","33.75119","0.04610"
"8.16000","33.75370","0.04600"
"8.19000","33.75615","0.04607"
"8.22000","33.75860","0.04617"
"8.25000","33.76112","0.04606"
"8.28000","33.76363","0.04623"
"8.31000","33.76614","0.04622"
"8.34000","33.76865","0.04618"
"8.37000","33.77110","0.04632"
"8.40000","33.77361","0.04649"
"8.43000","33.77612","0.04630"
"8.46000","33.77869","0.04620"
"8.49000","33.78114","0.04615"
"8.52000","33.78366","0.04611"
"8.55000","33.78617","0.04626"
"8.58000","33.78868","0.04618"
"8.61000","33.79119","0.04597"
"8.64000","33.79364","0.04591"
"8.67000","33.79615","0.04615"
"8.70000","33.79866","0.04622"
"8.73000","33.80117","0.04598"
"8.76000","33.80363","0.04583"
"8.79000","33.80608","0.04625"
"8.82000","33.80865","0.04636"
"8.85000","33.81110","0.04650"
"8.88000","33.81361","0.04646"
"8.91000","33.81606","0.04622"
"8.94000","33.81857","0.04619"
"8.97000","33.82114","0.04660"
"9.00000","33.82359","0.04675"
"9.03000","33.82617","0.04670"
"9.06000","33.82862","0.04668"
"9.09000","33.83113","0.04647"
"9.12000","33.83370","0.04643"
"9.15000","33.83615","0.04667"
"9.18000","33.83860","0.04651"
"9.21000","33.84111","0.04666"
"9.24000","33.84362","0.04645"
"9.27000","33.84620","0.04651"
"9.30000","33.84865","0.04679"
"9.33000","33.85110","0.04721"
"9.36000","33.85361","0.04716"
"9.39000","33.85612","0.04696"
"9.42000","33.85863","0.04678"
"9.45000","33.86108","0.04679"
"9.48000","33.86360","0.04673"
"9.51000","33.86611","0.04710"
"9.54000","33.86868","0.04726"
"9.57000","33.87113","0.04724"
"9.60000","33.87364","0.04730"
"9.63000","33.87615","0.04753"
"9.66000","33.87866","0.04709"
"9.69000","33.88117","0.04718"
"9.72000","33.88368","0.04727"
"9.75000","33.88614","0.04740"
"9.78000","33.88865","0.04730"
"9.81000","33.89116","0.04742"
"9.84000","33.89373","0.04750"
"9.87000","33.89618","0.04732"
"9.90000","33.89863","0.04757"
"9.93000","33.90108","0.04749"
"9.96000","33.90359","0.04769"
"9.99000","33.90611","0.04797"
"10.02000","33.90856","0.04765"
"10.05000","33.91107","0.04727"
"10.08000","33.91364","0.04789"
"10.11000","33.91615","0.04782"
"10.14000","33.91866","0.04821"
"10.17000","33.92117","0.04837"
"10.20000","33.92362","0.04801"
"10.23000","33.92614","0.04787"
"10.26000","33.92871","0.04784"
"10.29000","33.93116","0.04813"
"10.32000","33.93367","0.04798"
"10.35000","33.93618","0.04777"
"10.38000","33.93863","0.04815"
"10.41000","33.94114","0.04817"
"10.44000","33.94359","0.04834"
"10.47000","33.94611","0.04819"
"10.50000","33.94855","0.04820"
"10.53000","33.95107","0.04826"
"10.56000","33.95364","0.04819"
"10.59000","33.95615","0.04847"
"10.62000","33.95866","0.04840"
"10.65000","33.96117","0.04820"
"10.68000","33.96368","0.04815"
"10.71000","33.96619","0.04822"
"10.74000","33.96870","0.04849"
"10.77000","33.97116","0.04857"
"10.80000","33.97367","0.04837"
"10.83000","33.97618","0.04881"
"10.86000","33.97863","0.04883"
"10.89000","33.98114","0.04887"
"10.92000","33.98359","0.04900"
"10.95000","33.98610","0.04908"
"10.98000","33.98861","0.04929"
"11.01000","33.99113","0.04912"
"11.04000","33.99364","0.04905"
"11.07000","33.99609","0.04891"
"11.10000","33.99860","0.04924"
"11.13000","34.00117","0.04898"
"11.16000","34.00368","0.04914"
"11.19000","34.00620","0.04922"
"11.22000","34.00871","0.04944"
"11.25000","34.01122","0.04929"
"11.28000","34.01373","0.04945"
"11.31000","34.01612","0.04924"
"11.34000","34.01863","0.04956"
"11.37000","34.02114","0.04950"
"11.40000","34.02371","0.04949"
"11.43000","34.02623","0.04970"
"11.46000","34.02868","0.04979"
"11.49000","34.03113","0.04976"
"11.52000","34.03364","0.04983"
"11.55000","34.03615","0.04989"
"11.58000","34.03860","0.05007"
"11.61000","34.04105","0.05020"
"11.64000","34.04356","0.05007"
"11.67000","34.04613","0.05001"
"11.70000","34.04870","0.05017"
"11.73000","34.05116","0.04991"
"11.76000","34.05367","0.04998"
"11.79000","34.05618","0.04996"
"11.82000","34.05869","0.04986"
"11.85000","34.06120","0.04992"
"11.88000","34.06365","0.04996"
"11.91000","34.06616","0.04962"
"11.94000","34.06867","0.04965"
"11.97000","34.07119","0.04981"
"12.00000","34.07364","0.05003"
"12.03000","34.07615","0.04978"
"12.06000","34.07866","0.05023"
"12.09000","34.08117","0.05030"
"12.12000","34.08362","0.04997"
"12.15000","34.08607","0.05044"
"12.18000","34.08858","0.05036"
"12.21000","34.09109","0.05031"
"12.24000","34.09361","0.05045"
"12.27000","34.09612","0.05032"
"12.30000","34.09863","0.05051"
"12.33000","34.10120","0.05087"
"12.36000","34.10365","0.05092"
"12.39000","34.10616","0.05083"
"12.42000","34.10867","0.05082"
"12.45000","34.11118","0.05054"
"12.48000","34.11364","0.05060"
"12.51000","34.11615","0.05107"
"12.54000","34.11866","0.05075"
"12.57000","34.12117","0.05054"
"12.60000","34.12362","0.05095"
"12.63000","34.12613","0.05103"
"12.66000","34.12859","0.05068"
"12.69000","34.13110","0.05073"
"12.72000","34.13361","0.05112"
"12.75000","34.13612","0.05122"
"12.78000","34.13857","0.05144"
"12.81000","34.14108","0.05125"
"12.84000","34.14365","0.05190"
"12.87000","34.14622","0.05161"
"12.90000","34.14861","0.05182"
"12.93000","34.15112","0.05166"
"12.96000","34.15363","0.05124"
"12.99000","34.15615","0.05174"
"13.02000","34.15866","0.05157"
"13.05000","34.16111","0.05166"
"13.08000","34.16362","0.05150"
"13.11000","34.16613","0.05148"
"13.14000","34.16864","0.05183"
"13.17000","34.17115","0.05234"
"13.20000","34.17360","0.05213"
"13.23000","34.17611","0.05206"
"13.26000","34.17863","0.05246"
"13.29000","34.18114","0.05212"
"13.32000","34.18365","0.05205"
"13.35000","34.18616","0.05213"
"13.38000","34.18861","0.05208"
"13.41000","34.19112","0.05226"
"13.44000","34.19363","0.05232"
"13.47000","34.19614","0.05238"
"13.50000","34.19866","0.05245"
"13.53000","34.20117","0.05280"
"13.56000","34.20368","0.05270"
"13.59000","34.20619","0.05295"
"13.62000","34.20864","0.05314"
"13.65000","34.21109","0.05342"
"13.68000","34.21360","0.05278"
"13.71000","34.21611","0.05304"
"13.74000","34.21856","0.05323"
"13.77000","34.22108","0.05334"
"13.80000","34.22359","0.05338"
"13.83000","34.22610","0.05346"
"13.86000","34.22867","0.05375"
"13.89000","34.23118","0.05394"
"13.92000","34.23363","0.05425"
"13.95000","34.23615","0.05423"
"13.98000","34.23866","0.05408"
"14.01000","34.24117","0.05406"
"14.04000","34.24368","0.05423"
"14.07000","34.24613","0.05365"
"14.10000","34.24864","0.05352"
"14.13000","34.25121","0.05254"
"14.16000","34.25366","0.05229"
"14.19000","34.25611","0.05238"
"14.22000","34.25863","0.05250"
"14.25000","34.26108","0.05208"
"14.28000","34.26365","0.05193"
"14.31000","34.26616","0.05226"
"14.34000","34.26861","0.05329"
"14.37000","34.27112","0.05360"
"14.40000","34.27363","0.05337"
"14.43000","34.27614","0.05375"
"14.46000","34.27865","0.05440"
"14.49000","34.28111","0.05457"
"14.52000","34.28362","0.05431"
"14.55000","34.28613","0.05371"
"14.58000","34.28864","0.05381"
"14.61000","34.29115","0.05402"
"14.64000","34.29366","0.05407"
"14.67000","34.29612","0.05358"
"14.70000","34.29863","0.05345"
"14.73000","34.30120","0.05434"
"14.76000","34.30365","0.05441"
"14.79000","34.30610","0.05470"
"14.82000","34.30855","0.05510"
"14.85000","34.31112","0.05534"
"14.88000","34.31363","0.05555"
"14.91000","34.31608","0.05593"
"14.94000","34.31859","0.05547"
"14.97000","34.32110","0.05515"
"15.00000","34.32368","0.05557"
"15.03000","34.32613","0.05536"
"15.06000","34.32864","0.05511"
"15.09000","34.33109","0.05507"
"15.12000","34.33360","0.05489"
"15.15000","34.33617","0.05514"
"15.18000","34.33862","0.05519"
"15.21000","34.34113","0.05588"
"15.24000","34.34359","0.05665"
"15.27000","34.34610","0.05655"
"15.30000","34.34861","0.05692"
"15.33000","34.35106","0.05664"
"15.36000","34.35357","0.05635"
"15.39000","34.35608","0.05607"
"15.42000","34.35859","0.05595"
"15.45000","34.36111","0.05629"
"15.48000","34.36362","0.05616"
"15.51000","34.36613","0.05639"
"15.54000","34.36864","0.05683"
"15.57000","34.37115","0.05704"
"15.60000","34.37366","0.05725"
"15.63000","34.37617","0.05768"
"15.66000","34.37868","0.05809"
"15.69000","34.38119","0.05791"
"15.72000","34.38364","0.05761"
"15.75000","34.38615","0.05758"
"15.78000","34.38867","0.05766"
"15.81000","34.39112","0.05774"
"15.84000","34.39363","0.05735"
"15.87000","34.39614","0.05744"
"15.90000","34.39865","0.05715"
"15.93000","34.40117","0.05746"
"15.96000","34.40368","0.05798"
"15.99000","34.40612","0.05832"
"16.02000","34.40864","0.05805"
"16.05000","34.41121","0.05856"
"16.08000","34.41372","0.05855"
"16.11000","34.41617","0.05883"
"16.14000","34.41868","0.05858"
"16.17000","34.42113","0.05921"
"16.20000","34.42365","0.05937"
"16.23000","34.42622","0.05894"
"16.26000","34.42867","0.05934"
"16.29000","34.43118","0.05915"
"16.32000","34.43363","0.05955"
"16.35000","34.43614","0.05970"
"16.38000","34.43865","0.06007"
"16.41000","34.44116","0.06000"
"16.44000","34.44361","0.06058"
"16.47000","34.44613","0.06049"
"16.50000","34.44864","0.06033"
"16.53000","34.45115","0.06017"
"16.56000","34.45366","0.06024"
"16.59000","34.45617","0.06057"
"16.62000","34.45868","0.06054"
"16.65000","34.46119","0.06069"
"16.68000","34.46370","0.06029"
"16.71000","34.46621","0.06070"
"16.74000","34.46867","0.06128"
"16.77000","34.47118","0.06186"
"16.80000","34.47363","0.06172"
"16.83000","34.47614","0.06183"
"16.86000","34.47865","0.06171"
"16.89000","34.48116","0.06196"
"16.92000","34.48367","0.06216"
"16.95000","34.48612","0.06233"
"16.98000","34.48864","0.06258"
"17.01000","34.49121","0.06232"
"17.04000","34.49366","0.06209"
"17.07000","34.49611","0.06190"
"17.10000","34.49862","0.06213"
"17.13000","34.50119","0.06218"
"17.16000","34.50370","0.06264"
"17.19000","34.50621","0.06267"
"17.22000","34.50866","0.06270"
"17.25000","34.51112","0.06273"
"17.28000","34.51369","0.06333"
"17.31000","34.51620","0.06324"
"17.34000","34.51865","0.06305"
"17.37000","34.52110","0.06339"
"17.40000","34.52361","0.06335"
"17.43000","34.52612","0.06282"
"17.46000","34.52864","0.06285"
"17.49000","34.53109","0.06349"
"17.52000","34.53360","0.06331"
"17.55000","34.53611","0.06315"
"17.58000","34.53868","0.06299"
"17.61000","34.54113","0.06308"
"17.64000","34.54364","0.06338"
"17.67000","34.54615","0.06373"
"17.70000","34.54866","0.06340"
"17.73000","34.55123","0.06409"
"17.76000","34.55369","0.06418"
"17.79000","34.55614","0.06398"
"17.82000","34.55865","0.06415"
"17.85000","34.56122","0.06373"
"17.88000","34.56367","0.06399"
"17.91000","34.56612","0.06430"
"17.94000","34.56863","0.06450"
"17.97000","34.57114","0.06422"
"18.00000","34.57365","0.06507"
"18.03000","34.57617","0.06554"
"18.06000","34.57862","0.06549"
"18.09000","34.58113","0.06579"
"18.12000","34.58364","0.06615"
"18.15000","34.58615","0.06643"
"18.18000","34.58867","0.06616"
"18.21000","34.59112","0.06612"
"18.24000","34.59363","0.06608"
"18.27000","34.59614","0.06606"
"18.30000","34.59871","0.06695"
"18.33000","34.60116","0.06626"
"18.36000","34.60367","0.06598"
"18.39000","34.60618","0.06626"
"18.42000","34.60869","0.06702"
"18.45000","34.61115","0.06690"
"18.48000","34.61366","0.06704"
"18.51000","34.61610","0.06758"
"18.54000","34.61861","0.06755"
"18.57000","34.62113","0.06735"
"18.60000","34.62364","0.06792"
"18.63000","34.62609","0.06824"
"18.66000","34.62860","0.06844"
"18.69000","34.63111","0.06794"
"18.72000","34.63369","0.06789"
"18.75000","34.63620","0.06782"
"18.78000","34.63871","0.06823"
"18.81000","34.64116","0.06863"
"18.84000","34.64367","0.06843"
"18.87000","34.64618","0.06861"
"18.90000","34.64863","0.06918"
"18.93000","34.65108","0.06917"
"18.96000","34.65366","0.06904"
"18.99000","34.65617","0.06899"
"19.02000","34.65868","0.06900"
"19.05000","34.66113","0.06871"
"19.08000","34.66364","0.06893"
"19.11000","34.66609","0.06983"
"19.14000","34.66860","0.06945"
"19.17000","34.67111","0.06885"
"19.20000","34.67362","0.06931"
"19.23000","34.67614","0.06969"
"19.26000","34.67865","0.06997"
"19.29000","34.68116","0.07032"
"19.32000","34.68373","0.07005"
"19.35000","34.68618","0.07004"
"19.38000","34.68863","0.06994"
"19.41000","34.69114","0.07016"
"19.44000","34.69365","0.07048"
"19.47000","34.69617","0.07029"
"19.50000","34.69862","0.07082"
"19.53000","34.70113","0.07046"
"19.56000","34.70364","0.07035"
"19.59000","34.70609","0.07088"
"19.62000","34.70860","0.07080"
"19.65000","34.71111","0.07086"
"19.68000","34.71356","0.07055"
"19.71000","34.71607","0.07108"
"19.74000","34.71864","0.07123"
"19.77000","34.72110","0.07104"
"19.80000","34.72367","0.07133"
"19.83000","34.72618","0.07134"
"19.86000","34.72869","0.07117"
"19.89000","34.73120","0.07192"
"19.92000","34.73365","0.07166"
"19.95000","34.73616","0.07216"
"19.98000","34.73867","0.07197"
"20.01000","34.74118","0.07195"
"20.04000","34.74370","0.07248"
"20.07000","34.74615","0.07272"
"20.10000","34.74860","0.07257"
"20.13000","34.75111","0.07320"
"20.16000","34.75362","0.07348"
"20.19000","34.75608","0.07285"
"20.22000","34.75859","0.07271"
"20.25000","34.76110","0.07265"
"20.28000","34.76361","0.07306"
"20.31000","34.76618","0.07337"
"20.34000","34.76869","0.07378"
"20.37000","34.77114","0.07390"
"20.40000","34.77365","0.07382"
"20.43000","34.77616","0.07370"
"20.46000","34.77868","0.07418"
"20.49000","34.78112","0.07432"
"20.52000","34.78363","0.07444"
"20.55000","34.78614","0.07450"
"20.58000","34.78866","0.07437"
"20.61000","34.79117","0.07503"
"20.64000","34.79362","0.07515"
"20.67000","34.79607","0.07486"
"20.70000","34.79858","0.07510"
"20.73000","34.80109","0.07517"
"20.76000","34.80361","0.07565"
"20.79000","34.80606","0.07566"
"20.82000","34.80857","0.07549"
"20.85000","34.81108","0.07555"
"20.88000","34.81365","0.07566"
"20.91000","34.81616","0.07636"
"20.94000","34.81867","0.07649"
"20.97000","34.82119","0.07698"
"21.00000","34.82364","0.07747"
"21.03000","34.82621","0.07651"
"21.06000","34.82866","0.07593"
"21.09000","34.83117","0.07635"
"21.12000","34.83368","0.07725"
"21.15000","34.83613","0.07760"
"21.18000","34.83864","0.07787"
"21.21000","34.84115","0.07790"
"21.24000","34.84361","0.07777"
"21.27000","34.84612","0.07766"
"21.30000","34.84863","0.07795"
"21.33000","34.85114","0.07824"
"21.36000","34.85359","0.07779"
"21.39000","34.85610","0.07811"
"21.42000","34.85862","0.07841"
"21.45000","34.86113","0.07806"
"21.48000","34.86370","0.07840"
"21.51000","34.86615","0.07890"
"21.54000","34.86866","0.07875"
"21.57000","34.87117","0.07920"
"21.60000","34.87368","0.07988"
"21.63000","34.87613","0.08013"
"21.66000","34.87864","0.07907"
"21.69000","34.88109","0.07956"
"21.72000","34.88360","0.08011"
"21.75000","34.88612","0.08010"
"21.78000","34.88857","0.08022"
"21.81000","34.89108","0.07981"
"21.84000","34.89359","0.08006"
"21.87000","34.89610","0.08038"
"21.90000","34.89861","0.08146"
"21.93000","34.90112","0.08196"
"21.96000","34.90358","0.08185"
"21.99000","34.90609","0.08211"
"22.02000","34.90866","0.08143"
"22.05000","34.91117","0.08170"
"22.08000","34.91362","0.08197"
"22.11000","34.91613","0.08206"
"22.14000","34.91864","0.08194"
"22.17000","34.92122","0.08193"
"22.20000","34.92366","0.08244"
"22.23000","34.92612","0.08245"
"22.26000","34.92857","0.08287"
"22.29000","34.93108","0.08259"
"22.32000","34.93365","0.08265"
"22.35000","34.93610","0.08261"
"22.38000","34.93855","0.08293"
"22.41000","34.94106","0.08375"
"22.44000","34.94363","0.08435"
"22.47000","34.94614","0.08423"
"22.50000","34.94865","0.08414"
"22.53000","34.95116","0.08451"
"22.56000","34.95368","0.08439"
"22.59000","34.95619","0.08471"
"22.62000","34.95870","0.08484"
"22.65000","34.96115","0.08506"
"22.68000","34.96367","0.08460"
"22.71000","34.96618","0.08509"
"22.74000","34.96869","0.08532"
"22.77000","34.97120","0.08474"
"22.80000","34.97365","0.08576"
"22.83000","34.97610","0.08549"
"22.86000","34.97861","0.08521"
"22.89000","34.98112","0.08554"
"22.92000","34.98363","0.08554"
"22.95000","34.98608","0.08619"
"22.98000","34.98860","0.08666"
"23.01000","34.99111","0.08596"
"23.04000","34.99362","0.08607"
"23.07000","34.99613","0.08626"
"23.10000","34.99864","0.08668"
"23.13000","35.00109","0.08676"
"23.16000","35.00366","0.08661"
"23.19000","35.00617","0.08698"
"23.22000","35.00868","0.08691"
"23.25000","35.01120","0.08720"
"23.28000","35.01365","0.08745"
"23.31000","35.01616","0.08741"
"23.34000","35.01867","0.08719"
"23.37000","35.02112","0.08762"
"23.40000","35.02369","0.08819"
"23.43000","35.02608","0.08779"
"23.46000","35.02859","0.08739"
"23.49000","35.03111","0.08825"
"23.52000","35.03362","0.08827"
"23.55000","35.03619","0.08847"
"23.58000","35.03864","0.08886"
"23.61000","35.04115","0.08904"
"23.64000","35.04366","0.08875"
"23.67000","35.04617","0.08854"
"23.70000","35.04862","0.08894"
"23.73000","35.05113","0.08909"
"23.76000","35.05365","0.08915"
"23.79000","35.05616","0.08896"
"23.82000","35.05873","0.08895"
"23.85000","35.06118","0.08929"
"23.88000","35.06363","0.08932"
"23.91000","35.06614","0.08949"
"23.94000","35.06859","0.08963"
"23.97000","35.07111","0.08972"
"24.00000","35.07355","0.08980"
"24.03000","35.07607","0.08936"
"24.06000","35.07864","0.08938"
"24.09000","35.08115","0.09006"
"24.12000","35.08366","0.09038"
"24.15000","35.08617","0.09001"
"24.18000","35.08868","0.09011"
"24.21000","35.09119","0.09018"
"24.24000","35.09370","0.09027"
"24.27000","35.09622","0.09028"
"24.30000","35.09867","0.09031"
"24.33000","35.10118","0.09080"
"24.36000","35.10369","0.09063"
"24.39000","35.10614","0.09028"
"24.42000","35.10865","0.09050"
"24.45000","35.11116","0.09070"
"24.48000","35.11367","0.09067"
"24.51000","35.11612","0.09084"
"24.54000","35.11858","0.09082"
"24.57000","35.12109","0.09092"
"24.60000","35.12366","0.09085"
"24.63000","35.12617","0.09101"
"24.66000","35.12862","0.09097"
"24.69000","35.13113","0.09097"
"24.72000","35.13364","0.09093"
"24.75000","35.13622","0.09097"
"24.78000","35.13867","0.09129"
"24.81000","35.14112","0.09125"
"24.84000","35.14363","0.09133"
"24.87000","35.14614","0.09133"
"24.90000","35.14865","0.09148"
"24.93000","35.15117","0.09151"
"24.96000","35.15362","0.09151"
"24.99000","35.15613","0.09158"
"25.02000","35.15864","0.09170"
"25.05000","35.16115","0.09175"
"25.08000","35.16360","0.09175"
"25.11000","35.16611","0.09185"
"25.14000","35.16862","0.09171"
"25.17000","35.17113","0.09165"
"25.20000","35.17365","0.09168"
"25.23000","35.17616","0.09187"
"25.26000","35.17867","0.09182"
"25.29000","35.18112","0.09190"
"25.32000","35.18363","0.09193"
"25.35000","35.18620","0.09206"
"25.38000","35.18865","0.09207"
"25.41000","35.19116","0.09216"
"25.44000","35.19361","0.09228"
"25.47000","35.19613","0.09214"
"25.50000","35.19864","0.09234"
"25.53000","35.20115","0.09243"
"25.56000","35.20360","0.09243"
"25.59000","35.20611","0.09247"
"25.62000","35.20862","0.09268"
"25.65000","35.21107","0.09277"
"25.68000","35.21358","0.09279"
"25.71000","35.21609","0.09273"
"25.74000","35.21861","0.09280"
"25.77000","35.22118","0.09289"
"25.80000","35.22369","0.09300"
"25.83000","35.22614","0.09310"
"25.86000","35.22865","0.09306"
"25.89000","35.23116","0.09324"
"25.92000","35.23367","0.09305"
"25.95000","35.23612","0.09332"
"25.98000","35.23857","0.09343"
"26.01000","35.24109","0.09372"
"26.04000","35.24360","0.09367"
"26.07000","35.24611","0.09361"
"26.10000","35.24862","0.09335"
"26.13000","35.25107","0.09370"
"26.16000","35.25359","0.09391"
"26.19000","35.25615","0.09376"
"26.22000","35.25867","0.09400"
"26.25000","35.26112","0.09398"
"26.28000","35.26363","0.09379"
"26.31000","35.26614","0.09384"
"26.34000","35.26871","0.09394"
"26.37000","35.27116","0.09419"
"26.40000","35.27367","0.09412"
"26.43000","35.27618","0.09452"
"26.46000","35.27869","0.09472"
"26.49000","35.28120","0.09421"
"26.52000","35.28365","0.09412"
"26.55000","35.28611","0.09394"
"26.58000","35.28862","0.09414"
"26.61000","35.29113","0.09413"
"26.64000","35.29364","0.09427"
"26.67000","35.29615","0.09450"
"26.70000","35.29860","0.09493"
"26.73000","35.30112","0.09475"
"26.76000","35.30368","0.09479"
"26.79000","35.30614","0.09509"
"26.82000","35.30865","0.09550"
"26.85000","35.31116","0.09502"
"26.88000","35.31367","0.09506"
"26.91000","35.31618","0.09507"
"26.94000","35.31870","0.09502"
"26.97000","35.32115","0.09519"
"27.00000","35.32366","0.09521"
"27.03000","35.32617","0.09579"
"27.06000","35.32868","0.09587"
"27.09000","35.33113","0.09587"
"27.12000","35.33358","0.09589"
"27.15000","35.33609","0.09617"
"27.18000","35.33860","0.09621"
"27.21000","35.34111","0.09643"
"27.24000","35.34362","0.09674"
"27.27000","35.34613","0.09620"
"27.30000","35.34865","0.09631"
"27.33000","35.35116","0.09685"
"27.36000","35.35367","0.09676"
"27.39000","35.35618","0.09713"
"27.42000","35.35869","0.09705"
"27.45000","35.36115","0.09673"
"27.48000","35.36366","0.09635"
"27.51000","35.36617","0.09663"
"27.54000","35.36868","0.09641"
"27.57000","35.37119","0.09583"
"27.60000","35.37364","0.09591"
"27.63000","35.37615","0.09590"
"27.66000","35.37860","0.09508"
"27.69000","35.38111","0.09429"
"27.72000","35.38356","0.09307"
"27.75000","35.38608","0.09215"
"27.78000","35.38859","0.04918"
"27.81000","35.39116","-0.00589"
"27.84000","35.39367","-0.01656"
"27.87000","35.39618","0.00680"
"27.90000","35.39869","-0.01317"
"27.93000","35.40120","-0.00343"
"27.96000","35.40365","0.00239"
"27.99000","35.40617","-0.01156"
"28.02000","35.40868","0.00541"
"28.05000","35.41119","-0.00267"
"28.08000","35.41364","-0.00573"
"28.11000","35.41615","0.00622"
"28.14000","35.41860","-0.00328"
"28.17000","35.42112","0.00027"
"28.20000","35.42363","0.00142"
"28.23000","35.42614","-0.00484"
"28.26000","35.42859","0.00191"
"28.29000","35.43104","0.00021"
"28.32000","35.43361","-0.00081"
"28.35000","35.43612","0.00315"
"28.38000","35.43863","-0.00341"
"28.41000","35.44114","0.00186"
"28.44000","35.44365","-0.00118"
"28.47000","35.44622","-0.00673"
"28.50000","35.44867","-0.00171"
"28.53000","35.45113","-0.00457"
"28.56000","35.45364","-0.00604"
"28.59000","35.45615","-0.00069"
"28.62000","35.45872","-0.00488"
"28.65000","35.46117","-0.00495"
"28.68000","35.46368","-0.00240"
"28.71000","35.46613","-0.00532"
"28.74000","35.46865","-0.00259"
"28.77000","35.47116","-0.00337"
"28.80000","35.47361","-0.00497"
"28.83000","35.47612","-0.00272"
"28.86000","35.47857","-0.00532"
"28.89000","35.48108","-0.00397"
"28.92000","35.48365","-0.00415"
"28.95000","35.48616","-0.00551"
"28.98000","35.48868","-0.00349"
"29.01000","35.49119","-0.00616"
"29.04000","35.49370","-0.00559"
"29.07000","35.49621","-0.00312"
"29.10000","35.49866","-0.00606"
"29.13000","35.50123","-0.00465"
"29.16000","35.50368","-0.00476"
"29.19000","35.50613","-0.00612"
"29.22000","35.50864","-0.00425"
"29.25000","35.51115","-0.00433"
"29.28000","35.51361","-0.00373"
"29.31000","35.51612","-0.00364"
"29.34000","35.51857","-0.00404"
"29.37000","35.52108","-0.00273"
"29.40000","35.52359","-0.00398"
"29.43000","35.52610","-0.00510"
"29.46000","35.52861","-0.00348"
"29.49000","35.53119","-0.00439"
"29.52000","35.53370","-0.00390"
"29.55000","35.53621","-0.00350"
"29.58000","35.53866","-0.00410"
"29.61000","35.54117","-0.00208"
"29.64000","35.54368","-0.00226"
"29.67000","35.54619","-0.00216"
"29.70000","35.54871","-0.00281"
"29.73000","35.55116","-0.00424"
"29.76000","35.55361","-0.00467"
"29.79000","35.55618","-0.00537"
"29.82000","35.55863","-0.00525"
"29.85000","35.56114","-0.00385"
"29.88000","35.56359","-0.00486"
"29.91000","35.56616","-0.00457"
"29.94000","35.56867","-0.00348"
"29.97000","35.57113","-0.00483"
"30.00000","35.57364","-0.00407"
"30.03000","35.57609","-0.00320"
"30.06000","35.57866","-0.00450"
"30.09000","35.58117","-0.00362"
"30.12000","35.58362","-0.00420"
"30.15000","35.58613","-0.00470"
"30.18000","35.58865","-0.00460"
"30.21000","35.59121","-0.00502"
"30.24000","35.59367","-0.00426"
"30.27000","35.59612","-0.00525"
"30.30000","35.59863","-0.00538"
"30.33000","35.60114","-0.00481"
"30.36000","35.60365","-0.00513"
"30.39000","35.60610","-0.00460"
"30.42000","35.60855","-0.00442"
"30.45000","35.61106","-0.00500"
"30.48000","35.61363","-0.00409"
"30.51000","35.61615","-0.00361"
"30.54000","35.61866","-0.00484"
"30.57000","35.62117","-0.00469"
"30.60000","35.62368","-0.00378"
"30.63000","35.62619","-0.00410"
"30.66000","35.62870","-0.00456"
"30.69000","35.63115","-0.00449"
"30.72000","35.63366","-0.00380"
"30.75000","35.63618","-0.00443"
"30.78000","35.63874","-0.00390"
"30.81000","35.64120","-0.00369"
"30.84000","35.64365","-0.00415"
"30.87000","35.64616","-0.00438"
"30.90000","35.64861","-0.00358"
"30.93000","35.65113","-0.00328"
"30.96000","35.65364","-0.00316"
"30.99000","35.65615","-0.00386"
"31.02000","35.65866","-0.00505"
"31.05000","35.66117","-0.00468"
"31.08000","35.66362","-0.00432"
"31.11000","35.66613","-0.00452"
"31.14000","35.66870","-0.00422"
"31.17000","35.67115","-0.00422"
"31.20000","35.67366","-0.00439"
"31.23000","35.67611","-0.00415"
"31.26000","35.67868","-0.00398"
"31.29000","35.68119","-0.00444"
"31.32000","35.68371","-0.00473"
"31.35000","35.68616","-0.00344"
"31.38000","35.68861","-0.00324"
"31.41000","35.69112","-0.00419"
"31.44000","35.69363","-0.00381"
"31.47000","35.69609","-0.00466"
"31.50000","35.69860","-0.00528"
"31.53000","35.70111","-0.00489"
"31.56000","35.70362","-0.00515"
"31.59000","35.70613","-0.00480"
"31.62000","35.70864","-0.00444"
"31.65000","35.71115","-0.00516"
"31.68000","35.71366","-0.00570"
"31.71000","35.71618","-0.00511"
"31.74000","35.71863","-0.00450"
"31.77000","35.72114","-0.00487"
"31.80000","35.72365","-0.00453"
"31.83000","35.72616","-0.00445"
"31.86000","35.72873","-0.00430"
"31.89000","35.73118","-0.00447"
"31.92000","35.73363","-0.00395"
"31.95000","35.73615","-0.00421"
"31.98000","35.73859","-0.00411"
"32.01000","35.74110","-0.00354"
"32.04000","35.74362","-0.00433"
"32.07000","35.74613","-0.00453"
"32.10000","35.74864","-0.00383"
"32.13000","35.75109","-0.00414"
"32.16000","35.75366","-0.00391"
"32.19000","35.75618","-0.00420"
"32.22000","35.75869","-0.00432"
"32.25000","35.76114","-0.00484"
"32.28000","35.76359","-0.00392"
"32.31000","35.76610","-0.00422"
"32.34000","35.76867","-0.00504"
"32.37000","35.77118","-0.00455"
"32.40000","35.77363","-0.00455"
"32.43000","35.77614","-0.00456"
"32.46000","35.77859","-0.00474"
"32.49000","35.78111","-0.00446"
"32.52000","35.78362","-0.00441"
"32.55000","35.78607","-0.00459"
"32.58000","35.78858","-0.00436"
"32.61000","35.79103","-0.00454"
"32.64000","35.79360","-0.00412"
"32.67000","35.79611","-0.00401"
"32.70000","35.79863","-0.00391"
"32.73000","35.80119","-0.00428"
"32.76000","35.80365","-0.00478"
"32.79000","35.80622","-0.00538"
"32.82000","35.80867","-0.00497"
"32.85000","35.81112","-0.00439"
"32.88000","35.81363","-0.00443"
"32.91000","35.81614","-0.00456"
"32.94000","35.81866","-0.00514"
"32.97000","35.82117","-0.00585"
"33.00000","35.82368","-0.00512"
"33.03000","35.82613","-0.00445"
"33.06000","35.82864","-0.00435"
"33.09000","35.83115","-0.00408"
"33.12000","35.83360","-0.00357"
"33.15000","35.83605","-0.00417"
"33.18000","35.83856","-0.00397"
"33.21000","35.84113","-0.00437"
"33.24000","35.84359","-0.00417"
"33.27000","35.84610","-0.00403"
"33.30000","35.84861","-0.00430"
"33.33000","35.85112","-0.00368"
"33.36000","35.85363","-0.00390"
"33.39000","35.85614","-0.00426"
"33.42000","35.85859","-0.00396"
"33.45000","35.86110","-0.00421"
"33.48000","35.86362","-0.00396"
"33.51000","35.86613","-0.00413"
"33.54000","35.86864","-0.00438"
"33.57000","35.87109","-0.00474"
"33.60000","35.87360","-0.00352"
"33.63000","35.87611","-0.00416"
"33.66000","35.87862","-0.00493"
"33.69000","35.88107","-0.00433"
"33.72000","35.88359","-0.00435"
"33.75000","35.88610","-0.00538"
"33.78000","35.88867","-0.00474"
"33.81000","35.89118","-0.00486"
"33.84000","35.89369","-0.00466"
"33.87000","35.89614","-0.00397"
"33.90000","35.89865","-0.00381"
"33.93000","35.90116","-0.00402"
"33.96000","35.90368","-0.00419"
"33.99000","35.90612","-0.00411"
"34.02000","35.90863","-0.00473"
"34.05000","35.91115","-0.00477"
"34.08000","35.91366","-0.00522"
"34.11000","35.91617","-0.00526"
"34.14000","35.91862","-0.00547"
"34.17000","35.92113","-0.00492"
"34.20000","35.92358","-0.00448"
"34.23000","35.92616","-0.00452"
"34.26000","35.92867","-0.00498"
"34.29000","35.93112","-0.00486"
"34.32000","35.93363","-0.00436"
"34.35000","35.93614","-0.00460"
"34.38000","35.93871","-0.00403"
"34.41000","35.94122","-0.00423"
"34.44000","35.94367","-0.00458"
"34.47000","35.94613","-0.00459"
"34.50000","35.94864","-0.00436"
"34.53000","35.95115","-0.00390"
"34.56000","35.95366","-0.00351"
"34.59000","35.95611","-0.00309"
"34.62000","35.95862","-0.00378"
"34.65000","35.96113","-0.00424"
"34.68000","35.96364","-0.00399"
"34.71000","35.96609","-0.00372"
"34.74000","35.96861","-0.00384"
"34.77000","35.97112","-0.00433"
"34.80000","35.97363","-0.00472"
"34.83000","35.97614","-0.00441"
"34.86000","35.97859","-0.00436"
"34.89000","35.98110","-0.00443"
"34.92000","35.98362","-0.00413"
"34.95000","35.98618","-0.00391"
"34.98000","35.98864","-0.00452"
"35.01000","35.99115","-0.00495"
"35.04000","35.99366","-0.00463"
"35.07000","35.99617","-0.00484"
"35.10000","35.99868","-0.00482"
"35.13000","36.00113","-0.00410"
"35.16000","36.00358","-0.00435"
"35.19000","36.00609","-0.00453"
"35.22000","36.00860","-0.00457"
"35.25000","36.01112","-0.00490"
"35.28000","36.01357","-0.00423"
"35.31000","36.01608","-0.00433"
"35.34000","36.01865","-0.00433"
"35.37000","36.02116","-0.00443"
"35.40000","36.02367","-0.00415"
"35.43000","36.02612","-0.00400"
"35.46000","36.02863","-0.00444"
"35.49000","36.03115","-0.00499"
"35.52000","36.03366","-0.00493"
"35.55000","36.03617","-0.00478"
"35.58000","36.03868","-0.00453"
"35.61000","36.04119","-0.00511"
"35.64000","36.04370","-0.00472"
"35.67000","36.04622","-0.00519"
"35.70000","36.04866","-0.00450"
"35.73000","36.05112","-0.00416"
"35.76000","36.05357","-0.00436"
"35.79000","36.05614","-0.00467"
"35.82000","36.05865","-0.00413"
"35.85000","36.06110","-0.00418"
"35.88000","36.06361","-0.00437"
"35.91000","36.06612","-0.00358"
"35.94000","36.06869","-0.00372"
"35.97000","36.07121","-0.00407"
"36.00000","36.07365","-0.00353"
"36.03000","36.07611","-0.00416"
"36.06000","36.07862","-0.00432"
"36.09000","36.08119","-0.00456"
"36.12000","36.08370","-0.00419"
"36.15000","36.08615","-0.00452"
"36.18000","36.08867","-0.00436"
"36.21000","36.09111","-0.00458"
"36.24000","36.09369","-0.00435"
"36.27000","36.09614","-0.00427"
"36.30000","36.09865","-0.00471"
"36.33000","36.10110","-0.00511"
"36.36000","36.10361","-0.00466"
"36.39000","36.10612","-0.00504"
"36.42000","36.10863","-0.00484"
"36.45000","36.11114","-0.00469"
"36.48000","36.11366","-0.00454"
"36.51000","36.11617","-0.00475"
"36.54000","36.11868","-0.00403"
"36.57000","36.12119","-0.00380"
"36.60000","36.12370","-0.00395"
"36.63000","36.12615","-0.00386"
"36.66000","36.12866","-0.00448"
"36.69000","36.13117","-0.00471"
"36.72000","36.13369","-0.00438"
"36.75000","36.13614","-0.00448"
"36.78000","36.13865","-0.00475"
"36.81000","36.14116","-0.00490"
"36.84000","36.14361","-0.00441"
"36.87000","36.14618","-0.00471"
"36.90000","36.14863","-0.00477"
"36.93000","36.15108","-0.00440"
"36.96000","36.15359","-0.00460"
"36.99000","36.15611","-0.00427"
"37.02000","36.15868","-0.00411"
"37.05000","36.16119","-0.00391"
"37.08000","36.16370","-0.00459"
"37.11000","36.16615","-0.00441"
"37.14000","36.16866","-0.00445"
"37.17000","36.17123","-0.00411"
"37.20000","36.17368","-0.00370"
"37.23000","36.17619","-0.00415"
"37.26000","36.17870","-0.00403"
"37.29000","36.18116","-0.00396"
"37.32000","36.18367","-0.00400"
"37.35000","36.18618","-0.00450"
"37.38000","36.18863","-0.00473"
"37.41000","36.19114","-0.00436"
"37.44000","36.19360","-0.00386"
"37.47000","36.19604","-0.00500"
"37.50000","36.19862","-0.00496"
"37.53000","36.20113","-0.00513"
"37.56000","36.20364","-0.00514"