File: Force_trajectories/170225_1/Specimen_RawData_9.csv
End date,"2/25/2017"
Specimen label,"1BG_8"
Maximum Load,"0.26037",N

Time,Extension,Load
(s),(mm),(N)
"0.00000","0.00000","0.00018"
"0.43800","0.03683","0.00269"
"0.87600","0.07324","0.00387"
"1.31400","0.10965","0.00516"
"1.75200","0.14625","0.00641"
"2.19000","0.18272","0.00740"
"2.62800","0.21925","0.00806"
"3.06600","0.25572","0.00912"
"3.50400","0.29213","0.00949"
"3.94200","0.32872","0.01128"
"4.38000","0.36525","0.01104"
"4.81800","0.40173","0.01205"
"5.25600","0.43820","0.01244"
"5.69400","0.47467","0.01300"
"6.13200","0.51114","0.01318"
"6.57000","0.54767","0.01386"
"7.00800","0.58420","0.01400"
"7.44600","0.62073","0.01461"
"7.88400","0.65721","0.01465"
"8.32200","0.69368","0.01478"
"8.76000","0.73015","0.01504"
"9.19800","0.76668","0.01556"
"9.63600","0.80321","0.01589"
"10.07400","0.83974","0.01620"
"10.51200","0.87616","0.01687"
"10.95000","0.91275","0.01663"
"11.38800","0.94928","0.01744"
"11.82600","0.98575","0.01777"
"12.26400","1.02228","0.01844"
"12.70200","1.05869","0.01826"
"13.14000","1.09516","0.01879"
"13.57800","1.13176","0.01910"
"14.01600","1.16823","0.01802"
"14.45400","1.20470","0.01855"
"14.89200","1.24117","0.01844"
"15.33000","1.27764","0.01859"
"15.76800","1.31417","0.01839"
"16.20600","1.35071","0.01815"
"16.64400","1.38718","0.01814"
"17.08200","1.42371","0.01866"
"17.52000","1.46012","0.01889"
"17.95800","1.49665","0.01870"
"18.39600","1.53324","0.01903"
"18.83400","1.56971","0.01880"
"19.27200","1.60625","0.01916"
"19.71000","1.64272","0.01925"
"20.14800","1.67919","0.01935"
"20.58600","1.71572","0.01946"
"21.02400","1.75225","0.01951"
"21.46200","1.78878","0.01966"
"21.90000","1.82520","0.02031"
"22.33800","1.86161","0.02064"
"22.77600","1.89820","0.02055"
"23.21400","1.93473","0.02083"
"23.65200","1.97120","0.02164"
"24.09000","2.00773","0.02148"
"24.52800","2.04420","0.02086"
"24.96600","2.08074","0.02086"
"25.40400","2.11721","0.02100"
"25.84200","2.15368","0.02161"
"26.28000","2.19021","0.02164"
"26.71800","2.22674","0.02103"
"27.15600","2.26315","0.02152"
"27.59400","2.29974","0.02207"
"28.03200","2.33622","0.02232"
"28.47000","2.37275","0.02220"
"28.90800","2.40928","0.02285"
"29.34600","2.44569","0.02263"
"29.78400","2.48216","0.02331"
"30.22200","2.51869","0.02315"
"30.66000","2.55523","0.02363"
"31.09800","2.59176","0.02423"
"31.53600","2.62817","0.02390"
"31.97400","2.66476","0.02401"
"32.41200","2.70129","0.02482"
"32.85000","2.73770","0.02501"
"33.28800","2.77423","0.02437"
"33.72600","2.81065","0.02486"
"34.16400","2.84718","0.02525"
"34.60200","2.88371","0.02487"
"35.04000","2.92018","0.02547"
"35.47800","2.95671","0.02574"
"35.91600","2.99318","0.02571"
"36.35400","3.02966","0.02620"
"36.79200","3.06619","0.02684"
"37.23000","3.10278","0.02667"
"37.66800","3.13925","0.02713"
"38.10600","3.17578","0.02668"
"38.54400","3.21219","0.02727"
"38.98200","3.24866","0.02806"
"39.42000","3.28520","0.02769"
"39.85800","3.32173","0.02834"
"40.29600","3.35820","0.02834"
"40.73400","3.39467","0.02881"
"41.17200","3.43114","0.02915"
"41.61000","3.46773","0.02919"
"42.04800","3.50420","0.02916"
"42.48600","3.54074","0.02870"
"42.92400","3.57721","0.02929"
"43.36200","3.61368","0.02967"
"43.80000","3.65015","0.02977"
"44.23800","3.68674","0.02914"
"44.67600","3.72327","0.02918"
"45.11400","3.75975","0.03021"
"45.55200","3.79622","0.03016"
"45.99000","3.83269","0.02982"
"46.42800","3.86922","0.03007"
"46.86600","3.90575","0.03096"
"47.30400","3.94222","0.03190"
"47.74200","3.97869","0.03188"
"48.18000","4.01517","0.03194"
"48.61800","4.05170","0.03222"
"49.05600","4.08823","0.03280"
"49.49400","4.12470","0.03334"
"49.93200","4.16123","0.03405"
"50.37000","4.19764","0.03444"
"50.80800","4.23418","0.03423"
"51.24600","4.27065","0.03541"
"51.68400","4.30718","0.03555"
"52.12200","4.34371","0.03457"
"52.56000","4.38018","0.03544"
"52.99800","4.41665","0.03586"
"53.43600","4.45318","0.03566"
"53.87400","4.48972","0.03612"
"54.31200","4.52625","0.03526"
"54.75000","4.56272","0.03648"
"55.18800","4.59913","0.03647"
"55.62600","4.63572","0.03638"
"56.06400","4.67225","0.03657"
"56.50200","4.70872","0.03648"
"56.94000","4.74526","0.03710"
"57.37800","4.78167","0.03747"
"57.81600","4.81814","0.03841"
"58.25400","4.85473","0.03814"
"58.69200","4.89120","0.03812"
"59.13000","4.92773","0.03867"
"59.56800","4.96415","0.03924"
"60.00600","5.00068","0.03953"
"60.44400","5.03715","0.03998"
"60.88200","5.07368","0.04075"
"61.32000","5.11027","0.04083"
"61.75800","5.14674","0.04195"
"62.19600","5.18321","0.04234"
"62.63400","5.21969","0.04244"
"63.07200","5.25628","0.04436"
"63.51000","5.29269","0.04368"
"63.94800","5.32928","0.04442"
"64.38600","5.36569","0.04500"
"64.82400","5.40216","0.04523"
"65.26200","5.43870","0.04634"
"65.70000","5.47523","0.04619"
"66.13800","5.51170","0.04718"
"66.57600","5.54817","0.04770"
"67.01400","5.58464","0.04722"
"67.45200","5.62117","0.04644"
"67.89000","5.65770","0.04770"
"68.32800","5.69424","0.04841"
"68.76600","5.73071","0.04881"
"69.20400","5.76718","0.04890"
"69.64200","5.80371","0.04971"
"70.08000","5.84024","0.04964"
"70.51800","5.87671","0.05042"
"70.95600","5.91324","0.05094"
"71.39400","5.94972","0.05162"
"71.83200","5.98613","0.05165"
"72.27000","6.02272","0.05157"
"72.70800","6.05925","0.05266"
"73.14600","6.09572","0.05253"
"73.58400","6.13219","0.05281"
"74.02200","6.16867","0.05297"
"74.46000","6.20520","0.05343"
"74.89800","6.24173","0.05362"
"75.33600","6.27820","0.05394"
"75.77400","6.31473","0.05436"
"76.21200","6.35114","0.05425"
"76.65000","6.38767","0.05439"
"77.08800","6.42421","0.05467"
"77.52600","6.46074","0.05531"
"77.96400","6.49727","0.05531"
"78.40200","6.53374","0.05565"
"78.84000","6.57015","0.05566"
"79.27800","6.60668","0.05617"
"79.71600","6.64321","0.05660"
"80.15400","6.67969","0.05663"
"80.59200","6.71622","0.05681"
"81.03000","6.75263","0.05715"
"81.46800","6.78922","0.05746"
"81.90600","6.82575","0.05760"
"82.34400","6.86222","0.05782"
"82.78200","6.89870","0.05805"
"83.22000","6.93517","0.05819"
"83.65800","6.97170","0.05835"
"84.09600","7.00817","0.05862"
"84.53400","7.04470","0.05902"
"84.97200","7.08123","0.05927"
"85.41000","7.11770","0.05968"
"85.84800","7.15418","0.06006"
"86.28600","7.19071","0.06015"
"86.72400","7.22724","0.06075"
"87.16200","7.26371","0.06083"
"87.60000","7.30024","0.06137"
"88.03800","7.33671","0.06160"
"88.47600","7.37319","0.06197"
"88.91400","7.40972","0.06247"
"89.35200","7.44625","0.06298"
"89.79000","7.48278","0.06345"
"90.22800","7.51919","0.06429"
"90.66600","7.55566","0.06448"
"91.10400","7.59220","0.06615"
"91.54200","7.62873","0.06563"
"91.98000","7.66520","0.06644"
"92.41800","7.70173","0.06736"
"92.85600","7.73814","0.06029"
"93.29400","7.77473","0.03966"
"93.73200","7.81120","0.03878"
"94.17000","7.84773","0.04199"
"94.60800","7.88421","0.03847"
"95.04600","7.92074","0.04263"
"95.48400","7.95721","0.04305"
"95.92200","7.99374","0.04290"
"96.36000","8.03027","0.04542"
"96.79800","8.06674","0.04450"
"97.23600","8.10322","0.04547"
"97.67400","8.13963","0.04707"
"98.11200","8.17622","0.04652"
"98.55000","8.21269","0.04823"
"98.98800","8.24922","0.04964"
"99.42600","8.28569","0.04940"
"99.86400","8.32210","0.05049"
"100.30200","8.35870","0.05023"
"100.74000","8.39523","0.05123"
"101.17800","8.43170","0.05150"
"101.61600","8.46823","0.05217"
"102.05400","8.50470","0.05286"
"102.49200","8.54117","0.05196"
"102.93000","8.57771","0.05341"
"103.36800","8.61424","0.05385"
"103.80600","8.65077","0.05416"
"104.24400","8.68718","0.04708"
"104.68200","8.72365","0.04272"
"105.12000","8.76018","0.04328"
"105.55800","8.79671","0.04373"
"105.99600","8.83325","0.04364"
"106.43400","8.86978","0.04489"
"106.87200","8.90613","0.04545"
"107.31000","8.94266","0.04577"
"107.74800","8.97919","0.04747"
"108.18600","9.01572","0.04760"
"108.62400","9.05219","0.04883"
"109.06200","9.08867","0.04930"
"109.50000","9.12514","0.04942"
"109.93800","9.16167","0.05013"
"110.37600","9.19820","0.05041"
"110.81400","9.23473","0.05082"
"111.25200","9.27126","0.05141"
"111.69000","9.30768","0.05218"
"112.12800","9.34421","0.05201"
"112.56600","9.38068","0.05291"
"113.00400","9.41727","0.05278"
"113.44200","9.45374","0.05340"
"113.88000","9.49021","0.05366"
"114.31800","9.52668","0.05426"
"114.75600","9.56322","0.05460"
"115.19400","9.59975","0.05481"
"115.63200","9.63622","0.05543"
"116.07000","9.67269","0.05563"
"116.50800","9.70916","0.05600"
"116.94600","9.74569","0.05646"
"117.38400","9.78223","0.05651"
"117.82200","9.81864","0.05651"
"118.26000","9.85523","0.05568"
"118.69800","9.89170","0.05627"
"119.13600","9.92823","0.05653"
"119.57400","9.96470","0.05646"
"120.01200","10.00124","0.05702"
"120.45000","10.03777","0.05714"
"120.88800","10.07424","0.05746"
"121.32600","10.11065","0.05778"
"121.76400","10.14718","0.05786"
"122.20200","10.18377","0.05835"
"122.64000","10.22024","0.05817"
"123.07800","10.25671","0.05886"
"123.51600","10.29313","0.05889"
"123.95400","10.32966","0.05965"
"124.39200","10.36619","0.05978"
"124.83000","10.40272","0.05983"
"125.26800","10.43919","0.06040"
"125.70600","10.47572","0.06080"
"126.14400","10.51220","0.06075"
"126.58200","10.54873","0.01386"
"127.02000","10.58520","0.01749"
"127.45800","10.62179","0.02126"
"127.89600","10.65820","0.02411"
"128.33400","10.69467","0.02458"
"128.77200","10.73127","0.02397"
"129.21000","10.76774","0.02204"
"129.64800","10.80421","0.02116"
"130.08600","10.84074","0.02296"
"130.52400","10.87715","0.02559"
"130.96200","10.91368","0.02803"
"131.40000","10.95021","0.02929"
"131.83800","10.98675","0.02940"
"132.27600","11.02322","0.03042"
"132.71400","11.05963","0.02909"
"133.15200","11.09616","0.02990"
"133.59000","11.13269","0.03110"
"134.02800","11.16922","0.03316"
"134.46600","11.20569","0.03457"
"134.90400","11.24217","0.03590"
"135.34200","11.27870","0.03680"
"135.78000","11.31523","0.03719"
"136.21800","11.35176","0.03865"
"136.65600","11.38823","0.03971"
"137.09400","11.42470","0.04127"
"137.53200","11.46124","0.04181"
"137.97000","11.49765","0.04378"
"138.40800","11.53424","0.04499"
"138.84600","11.57071","0.04663"
"139.28400","11.60724","0.04809"
"139.72200","11.64365","0.04913"
"140.16000","11.68013","0.05007"
"140.59800","11.71672","0.05080"
"141.03600","11.75319","0.05101"
"141.47400","11.78972","0.05136"
"141.91200","11.82619","0.05227"
"142.35000","11.86266","0.05281"
"142.78800","11.89913","0.05359"
"143.22600","11.93572","0.05380"
"143.66400","11.97226","0.05220"
"144.10200","12.00873","0.05136"
"144.54000","12.04520","0.05214"
"144.97800","12.08173","0.05301"
"145.41600","12.11826","0.05422"
"145.85400","12.15473","0.05397"
"146.29200","12.19127","0.05551"
"146.73000","12.22768","0.05548"
"147.16800","12.26421","0.05612"
"147.60600","12.30068","0.05643"
"148.04400","12.33721","0.05701"
"148.48200","12.37374","0.05774"
"148.92000","12.41021","0.05806"
"149.35800","12.44663","0.05830"
"149.79600","12.48322","0.05884"
"150.23400","12.51969","0.05916"
"150.67200","12.55622","0.05958"
"151.11000","12.59269","0.06031"
"151.54800","12.62922","0.06076"
"151.98600","12.66564","0.06166"
"152.42400","12.70223","0.06266"
"152.86200","12.73876","0.06304"
"153.30000","12.77523","0.06392"
"153.73800","12.81170","0.06564"
"154.17600","12.84817","0.06537"
"154.61400","12.88470","0.06658"
"155.05200","12.92124","0.06807"
"155.49000","12.95771","0.06930"
"155.92800","12.99424","0.07069"
"156.36600","13.03065","0.07212"
"156.80400","13.06718","0.07370"
"157.24200","13.10371","0.07490"
"157.68000","13.14024","0.07672"
"158.11800","13.17672","0.07846"
"158.55600","13.21313","0.07972"
"158.99400","13.24966","0.08123"
"159.43200","13.28619","0.08244"
"159.87000","13.32272","0.08358"
"160.30800","13.35925","0.08463"
"160.74600","13.39573","0.08622"
"161.18400","13.43214","0.08731"
"161.62200","13.46867","0.08875"
"162.06000","13.50526","0.09106"
"162.49800","13.54173","0.09199"
"162.93600","13.57820","0.09418"
"163.37400","13.61467","0.09600"
"163.81200","13.65121","0.09823"
"164.25000","13.68768","0.09854"
"164.68800","13.72421","0.10033"
"165.12600","13.76074","0.10151"
"165.56400","13.79721","0.10218"
"166.00200","13.83362","0.10282"
"166.44000","13.87022","0.10357"
"166.87800","13.90675","0.10398"
"167.31600","13.94322","0.10441"
"167.75400","13.97969","0.10462"
"168.19200","14.01616","0.10503"
"168.63000","14.05269","0.10592"
"169.06800","14.08922","0.10694"
"169.50600","14.12570","0.10823"
"169.94400","14.16229","0.11034"
"170.38200","14.19870","0.11193"
"170.82000","14.23523","0.11429"
"171.25800","14.27176","0.11715"
"171.69600","14.30823","0.12027"
"172.13400","14.34477","0.12162"
"172.57200","14.38118","0.12440"
"173.01000","14.41765","0.12626"
"173.44800","14.45418","0.12932"
"173.88600","14.49071","0.13122"
"174.32400","14.52724","0.13288"
"174.76200","14.56378","0.13456"
"175.20000","14.60013","0.13638"
"175.63800","14.63666","0.13791"
"176.07600","14.67319","0.13906"
"176.51400","14.70972","0.14042"
"176.95200","14.74619","0.14137"
"177.39000","14.78272","0.14262"
"177.82800","14.81920","0.14408"
"178.26600","14.85573","0.14482"
"178.70400","14.89226","0.14573"
"179.14200","14.92873","0.14698"
"179.58000","14.96526","0.14766"
"180.01800","15.00173","0.14843"
"180.45600","15.03820","0.14885"
"180.89400","15.07468","0.14978"
"181.33200","15.11121","0.15016"
"181.77000","15.14774","0.15030"
"182.20800","15.18421","0.15091"
"182.64600","15.22068","0.15184"
"183.08400","15.25721","0.15306"
"183.52200","15.29375","0.15380"
"183.96000","15.33022","0.15530"
"184.39800","15.36669","0.15646"
"184.83600","15.40322","0.15932"
"185.27400","15.43969","0.16138"
"185.71200","15.47628","0.16488"
"186.15000","15.51269","0.16718"
"186.58800","15.54923","0.17145"
"187.02600","15.58570","0.17518"
"187.46400","15.62223","0.17895"
"187.90200","15.65876","0.18300"
"188.34000","15.69523","0.18858"
"188.77800","15.73170","0.19330"
"189.21600","15.76823","0.19703"
"189.65400","15.80464","0.19926"
"190.09200","15.84124","0.20382"
"190.53000","15.87771","0.20565"
"190.96800","15.91418","0.20647"
"191.40600","15.95071","0.20597"
"191.84400","15.98712","0.19279"
"192.28200","16.02371","0.19300"
"192.72000","16.06025","0.18985"
"193.15800","16.09672","0.19005"
"193.59600","16.13319","0.17164"
"194.03400","16.16966","0.17375"
"194.47200","16.20619","0.17324"
"194.91000","16.24272","0.17573"
"195.34800","16.27925","0.17931"
"195.78600","16.31573","0.18586"
"196.22400","16.35220","0.19069"
"196.66200","16.38867","0.19378"
"197.10000","16.42520","0.19943"
"197.53800","16.46173","0.20304"
"197.97600","16.49821","0.20541"
"198.41400","16.53468","0.20753"
"198.85200","16.57115","0.20922"
"199.29000","16.60768","0.21089"
"199.72800","16.64421","0.21201"
"200.16600","16.68068","0.21301"
"200.60400","16.71721","0.21480"
"201.04200","16.75363","0.21650"
"201.48000","16.79022","0.21838"
"201.91800","16.82669","0.21677"
"202.35600","16.86322","0.21582"
"202.79400","16.89975","0.21817"
"203.23200","16.93622","0.22147"
"203.67000","16.97269","0.22456"
"204.10800","17.00928","0.22730"
"204.54600","17.04576","0.23094"
"204.98400","17.08223","0.23304"
"205.42200","17.11870","0.23735"
"205.86000","17.15523","0.24028"
"206.29800","17.19170","0.24350"
"206.73600","17.22817","0.24565"
"207.17400","17.26471","0.24869"
"207.61200","17.30124","0.25024"
"208.05000","17.33771","0.25147"
"208.48800","17.37412","0.25290"
"208.92600","17.41065","0.25425"
"209.36400","17.44718","0.25544"
"209.80200","17.48377","0.25642"
"210.24000","17.52019","0.25768"
"210.67800","17.55666","0.25910"
"211.11600","17.59319","0.16680"
"211.55400","17.62978","0.03675"
"211.99200","17.66625","0.04063"
"212.43000","17.70272","0.04216"
"212.86800","17.73919","0.04004"
"213.30600","17.77573","0.04236"
"213.74400","17.81220","0.04395"
"214.18200","17.84873","0.04608"
"214.62000","17.88526","0.04933"
"215.05800","17.92173","0.05105"
"215.49600","17.95820","0.05122"
"215.93400","17.99468","0.05293"
"216.37200","18.03121","0.05359"
"216.81000","18.06768","0.05376"
"217.24800","18.10421","0.05422"
"217.68600","18.14062","0.05487"
"218.12400","18.17721","0.05593"
"218.56200","18.21369","0.05688"
"219.00000","18.25022","0.05735"
"219.43800","18.28675","0.05861"
"219.87600","18.32322","0.05932"
"220.31400","18.35969","0.06021"
"220.75200","18.39622","0.06088"
"221.19000","18.43275","0.06166"
"221.62800","18.46922","0.06274"
"222.06600","18.50570","0.06387"
"222.50400","18.54217","0.06468"
"222.94200","18.57870","0.06692"
"223.38000","18.61523","0.06817"
"223.81800","18.65176","0.06867"
"224.25600","18.68824","0.06153"
"224.69400","18.72465","0.06236"
"225.13200","18.76118","0.06425"
"225.57000","18.79771","0.06623"
"226.00800","18.83424","0.06810"
"226.44600","18.87071","0.07008"
"226.88400","18.90718","0.07202"
"227.32200","18.94372","0.07413"
"227.76000","18.98025","0.07585"
"228.19800","19.01678","0.07735"
"228.63600","19.05325","0.07961"
"229.07400","19.08972","0.07914"
"229.51200","19.12619","0.08046"
"229.95000","19.16266","0.08172"
"230.38800","19.19925","0.08246"
"230.82600","19.23573","0.08456"
"231.26400","19.27220","0.08600"
"231.70200","19.30867","0.08715"
"232.14000","19.34520","0.08881"
"232.57800","19.38167","0.09107"
"233.01600","19.41821","0.09250"
"233.45400","19.45474","0.09401"
"233.89200","19.49121","0.09535"
"234.33000","19.52762","0.09787"
"234.76800","19.56421","0.09906"
"235.20600","19.60074","0.10048"
"235.64400","19.63727","0.10169"
"236.08200","19.67369","0.10235"
"236.52000","19.71016","0.10295"
"236.95800","19.74669","0.10349"
"237.39600","19.78322","0.10412"
"237.83400","19.81975","0.10522"
"238.27200","19.85622","0.10586"
"238.71000","19.89270","0.10711"
"239.14800","19.92917","0.10898"
"239.58600","19.96570","0.10930"
"240.02400","20.00223","0.10953"
"240.46200","20.03876","0.10158"
"240.90000","20.07517","0.10267"
"241.33800","20.11170","0.10356"
"241.77600","20.14818","0.10461"
"242.21400","20.18471","0.10571"
"242.65200","20.22124","0.10675"
"243.09000","20.25771","0.10795"
"243.52800","20.29418","0.10951"
"243.96600","20.33065","0.11044"
"244.40400","20.36724","0.11207"
"244.84200","20.40378","0.11400"
"245.28000","20.44025","0.11614"
"245.71800","20.47672","0.11868"
"246.15600","20.51319","0.12132"
"246.59400","20.54972","0.12274"
"247.03200","20.58619","0.12453"
"247.47000","20.62272","0.12618"
"247.90800","20.65919","0.12809"
"248.34600","20.69567","0.13017"
"248.78400","20.73220","0.13165"
"249.22200","20.76873","0.13311"
"249.66000","20.80520","0.13378"
"250.09800","20.84167","0.13475"
"250.53600","20.87815","0.13597"
"250.97400","20.91467","0.13641"
"251.41200","20.95121","0.11912"
"251.85000","20.98768","0.12205"
"252.28800","21.02421","0.12199"
"252.72600","21.06068","0.12674"
"253.16400","21.09722","0.12777"
"253.60200","21.13375","0.13056"
"254.04000","21.17028","0.13196"
"254.47800","21.20675","0.13456"
"254.91600","21.24316","0.13522"
"255.35400","21.27969","0.13663"
"255.79200","21.31623","0.13867"
"256.23000","21.35270","0.13965"
"256.66800","21.38923","0.14138"
"257.10600","21.42570","0.14232"
"257.54400","21.46211","0.14376"
"257.98200","21.49870","0.14463"
"258.42000","21.53517","0.14551"
"258.85800","21.57170","0.14642"
"259.29600","21.60824","0.14735"
"259.73400","21.64471","0.14805"
"260.17200","21.68118","0.14839"
"260.61000","21.71765","0.14908"
"261.04800","21.75424","0.14990"
"261.48600","21.79077","0.15013"
"261.92400","21.82724","0.15043"
"262.36200","21.86366","0.15089"
"262.80000","21.90019","0.15171"
"263.23800","21.93678","0.15251"
"263.67600","21.97325","0.15370"
"264.11400","22.00972","0.15525"
"264.55200","22.04620","0.15668"
"264.99000","22.08267","0.15950"
"265.42800","22.11920","0.16137"
"265.86600","22.15573","0.16254"
"266.30400","22.19226","0.16646"
"266.74200","22.22867","0.17096"
"267.18000","22.26514","0.17487"
"267.61800","22.30162","0.17991"
"268.05600","22.33821","0.18486"
"268.49400","22.37468","0.18837"
"268.93200","22.41127","0.19162"
"269.37000","22.44768","0.19548"
"269.80800","22.48421","0.19906"
"270.24600","22.52074","0.20225"
"270.68400","22.55728","0.20511"
"271.12200","22.59369","0.20766"
"271.56000","22.63022","0.20955"
"271.99800","22.66669","0.21069"
"272.43600","22.70322","0.21212"
"272.87400","22.73975","0.21336"
"273.31200","22.77622","0.21530"
"273.75000","22.81269","0.21744"
"274.18800","22.84917","0.21957"
"274.62600","22.88570","0.22296"
"275.06400","22.92223","0.22550"
"275.50200","22.95870","0.22779"
"275.94000","22.99517","0.22009"
"276.37800","23.03165","0.22297"
"276.81600","23.06818","0.22174"
"277.25400","23.10471","0.01958"
"277.69200","23.14124","0.01172"
"278.13000","23.17777","0.00814"
"278.56800","23.21424","0.00823"
"279.00600","23.25066","0.00812"
"279.44400","23.28725","0.00822"
"279.88200","23.32378","0.00800"
"280.32000","23.36025","0.00996"
"280.75800","23.39672","0.00988"
"281.19600","23.43319","0.01028"
"281.63400","23.46972","0.01022"
"282.07200","23.50620","0.01126"
"282.51000","23.54273","0.01120"
"282.94800","23.57926","0.01247"
"283.38600","23.61567","0.01169"
"283.82400","23.65220","0.01245"
"284.26200","23.68867","0.01282"
"284.70000","23.72520","0.01327"
"285.13800","23.76174","0.01378"
"285.57600","23.79821","0.01322"
"286.01400","23.83462","0.01474"
"286.45200","23.87121","0.01476"
"286.89000","23.90774","0.01451"
"287.32800","23.94427","0.01481"
"287.76600","23.98075","0.01568"
"288.20400","24.01722","0.01570"
"288.64200","24.05369","0.01565"
"289.08000","24.09022","0.01563"
"289.51800","24.12675","0.01596"
"289.95600","24.16328","0.01571"
"290.39400","24.19969","0.01653"
"290.83200","24.23616","0.01699"
"291.27000","24.27270","0.01665"
"291.70800","24.30923","0.01709"
"292.14600","24.34576","0.01776"
"292.58400","24.38217","0.01797"
"293.02200","24.41864","0.01835"
"293.46000","24.45517","0.01742"
"293.89800","24.49171","0.01741"
"294.33600","24.52824","0.01704"
"294.77400","24.56477","0.01804"
"295.21200","24.60118","0.01650"
"295.65000","24.63771","0.01621"
"296.08800","24.67418","0.01757"
"296.52600","24.71072","0.01778"
"296.96400","24.74725","0.01831"
"297.40200","24.78372","0.01807"
"297.84000","24.82019","0.01776"
"298.27800","24.85672","0.01848"
"298.71600","24.89325","0.01931"
"299.15400","24.92966","0.01907"
"299.59200","24.96626","0.01872"
"300.03000","25.00267","0.01826"
"300.46800","25.03920","0.01982"
"300.90600","25.07567","0.01943"
"301.34400","25.11220","0.01940"
"301.78200","25.14867","0.02003"
"302.22000","25.18521","0.02067"
"302.65800","25.22168","0.02155"
"303.09600","25.25821","0.02081"
"303.53400","25.29474","0.02202"
"303.97200","25.33127","0.02346"
"304.41000","25.36774","0.02304"
"304.84800","25.40415","0.02320"
"305.28600","25.44074","0.02373"
"305.72400","25.47721","0.02407"
"306.16200","25.51375","0.02486"
"306.60000","25.55022","0.02554"
"307.03800","25.58669","0.02535"
"307.47600","25.62322","0.02660"
"307.91400","25.65969","0.02673"
"308.35200","25.69617","0.02743"
"308.79000","25.73270","0.02817"
"309.22800","25.76917","0.02385"
"309.66600","25.80570","0.02266"
"310.10400","25.84217","0.02384"
"310.54200","25.87871","0.02495"
"310.98000","25.91518","0.02591"
"311.41800","25.95171","0.02707"
"311.85600","25.98818","0.02801"
"312.29400","26.02471","0.02976"
"312.73200","26.06124","0.03087"
"313.17000","26.09777","0.03280"
"313.60800","26.13424","0.03376"
"314.04600","26.17066","0.03491"
"314.48400","26.20713","0.03699"
"314.92200","26.24372","0.03921"
"315.36000","26.28025","0.04060"
"315.79800","26.31672","0.04161"
"316.23600","26.35320","0.04280"
"316.67400","26.38967","0.04427"
"317.11200","26.42620","0.04508"
"317.55000","26.46267","0.04617"
"317.98800","26.49920","0.04668"
"318.42600","26.53573","0.04808"
"318.86400","26.57214","0.04860"
"319.30200","26.60868","0.04927"
"319.74000","26.64520","0.05063"
"320.17800","26.68174","0.05119"
"320.61600","26.71827","0.05210"
"321.05400","26.75474","0.05278"
"321.49200","26.79115","0.05347"
"321.93000","26.82774","0.02688"
"322.36800","26.86421","0.02216"
"322.80600","26.90075","0.02397"
"323.24400","26.93722","0.02426"
"323.68200","26.97363","0.02522"
"324.12000","27.01022","0.02622"
"324.55800","27.04675","0.02780"
"324.99600","27.08317","0.02734"
"325.43400","27.11969","0.02845"
"325.87200","27.15611","0.02831"
"326.31000","27.19270","0.02892"
"326.74800","27.22917","0.03061"
"327.18600","27.26570","0.03153"
"327.62400","27.30223","0.03239"
"328.06200","27.33870","0.03304"
"328.50000","27.37518","0.03438"
"328.93800","27.41171","0.03605"
"329.37600","27.44824","0.03645"
"329.81400","27.48477","0.03742"
"330.25200","27.52124","0.03781"
"330.69000","27.55765","0.03883"
"331.12800","27.59418","0.03894"
"331.56600","27.63072","0.04079"
"332.00400","27.66719","0.04139"
"332.44200","27.70378","0.04196"
"332.88000","27.74019","0.04137"
"333.31800","27.77672","0.04309"
"333.75600","27.81319","0.02894"
"334.19400","27.84973","0.02186"
"334.63200","27.88620","0.02196"
"335.07000","27.92267","0.02059"
"335.50800","27.95914","0.02173"
"335.94600","27.99567","0.02294"
"336.38400","28.03220","0.02333"
"336.82200","28.06874","0.02394"
"337.26000","28.10527","0.02541"
"337.69800","28.14174","0.02608"
"338.13600","28.17821","0.02703"
"338.57400","28.21474","0.02765"
"339.01200","28.25127","0.01723"
"339.45000","28.28774","0.01523"
"339.88800","28.32422","0.01770"
"340.32600","28.36069","0.01845"
"340.76400","28.39722","0.01874"
"341.20200","28.43375","0.01913"
"341.64000","28.47022","0.02039"
"342.07800","28.50669","0.02078"
"342.51600","28.54310","0.01858"
"342.95400","28.57970","0.01823"
"343.39200","28.61623","0.01863"
"343.83000","28.65276","0.01836"
"344.26800","28.68923","0.01886"
"344.70600","28.72564","0.01919"
"345.14400","28.76217","0.02024"
"345.58200","28.79877","0.01922"
"346.02000","28.83524","0.01712"
"346.45800","28.87183","0.01720"
"346.89600","28.90818","0.01578"
"347.33400","28.94471","0.01735"
"347.77200","28.98118","0.01726"
"348.21000","29.01771","0.01685"
"348.64800","29.05425","0.01315"
"349.08600","29.09066","0.01332"
"349.52400","29.12713","0.01272"
"349.96200","29.16366","0.01301"
"350.40000","29.20025","0.01341"
"350.83800","29.23672","0.01147"
"351.27600","29.27326","0.01048"
"351.71400","29.30967","0.01108"
"352.15200","29.34620","0.01134"
"352.59000","29.38267","0.01211"
"353.02800","29.41920","0.01225"
"353.46600","29.45573","0.01275"
"353.90400","29.49220","0.01234"
"354.34200","29.52868","0.01012"
"354.78000","29.56521","0.01017"
"355.21800","29.60174","0.01064"
"355.65600","29.63821","0.01051"
"356.09400","29.67474","0.01117"
"356.53200","29.71115","0.01199"
"356.97000","29.74768","0.01145"
"357.40800","29.78422","0.01243"
"357.84600","29.82069","0.01250"
"358.28400","29.85722","0.01259"
"358.72200","29.89369","0.01314"
"359.16000","29.93022","0.01277"
"359.59800","29.96669","0.01373"
"360.03600","30.00323","0.01238"
"360.47400","30.03970","0.01237"
"360.91200","30.07623","0.01226"
"361.35000","30.11270","0.01248"
"361.78800","30.14917","0.01306"
"362.22600","30.18570","0.01355"
"362.66400","30.22217","0.01300"
"363.10200","30.25871","0.01290"
"363.54000","30.29524","0.01356"
"363.97800","30.33165","0.01403"
"364.41600","30.36824","0.01341"
"364.85400","30.40471","0.01381"
"365.29200","30.44124","0.01408"
"365.73000","30.47765","0.01372"
"366.16800","30.51419","0.01214"
"366.60600","30.55066","0.01140"
"367.04400","30.58725","0.01161"
"367.48200","30.62366","0.01203"
"367.92000","30.66019","0.01256"
"368.35800","30.69666","0.01227"
"368.79600","30.73320","0.01300"
"369.23400","30.76973","0.01348"
"369.67200","30.80626","0.01332"
"370.11000","30.84273","0.01304"
"370.54800","30.87914","0.01389"
"370.98600","30.91567","0.01385"
"371.42400","30.95226","0.01448"
"371.86200","30.98868","0.01422"
"372.30000","31.02527","0.01451"
"372.73800","31.06174","0.01463"
"373.17600","31.09815","0.01492"
"373.61400","31.13474","0.01466"
"374.05200","31.17122","0.01556"
"374.49000","31.20774","0.01505"
"374.92800","31.24416","0.01556"
"375.36600","31.28063","0.01636"
"375.80400","31.31722","0.01608"
"376.24200","31.35375","0.01590"
"376.68000","31.39022","0.01664"
"377.11800","31.42669","0.01594"
"377.55600","31.46317","0.01659"
"377.99400","31.49969","0.01732"
"378.43200","31.53623","0.01696"
"378.87000","31.57270","0.01642"
"379.30800","31.60929","0.01625"
"379.74600","31.64570","0.01682"
"380.18400","31.68217","0.01675"
"380.62200","31.71870","0.01737"
"381.06000","31.75517","0.01716"
"381.49800","31.79171","0.01739"
"381.93600","31.82824","0.01663"
"382.37400","31.86465","0.01640"
"382.81200","31.90118","0.01744"
"383.25000","31.93772","0.01776"
"383.68800","31.97430","0.01807"
"384.12600","32.01072","0.01696"
"384.56400","32.04719","0.01787"
"385.00200","32.08366","0.01662"
"385.44000","32.12019","0.01743"
"385.87800","32.15672","0.01771"
"386.31600","32.19326","0.01789"
"386.75400","32.22972","0.01786"
"387.19200","32.26620","0.01833"
"387.63000","32.30267","0.01935"
"388.06800","32.33926","0.01937"
"388.50600","32.37573","0.01950"
"388.94400","32.41220","0.01959"
"389.38200","32.44868","0.02075"
"389.82000","32.48521","0.02073"
"390.25800","32.52174","0.02116"
"390.69600","32.55827","0.02154"
"391.13400","32.59480","0.02169"
"391.57200","32.63121","0.02159"
"392.01000","32.66769","0.02087"
"392.44800","32.70415","0.02177"
"392.88600","32.74075","0.02220"
"393.32400","32.77722","0.02193"
"393.76200","32.81369","0.02145"
"394.20000","32.85016","0.02226"
"394.63800","32.88670","0.02251"
"395.07600","32.92323","0.02273"
"395.51400","32.95975","0.02139"
"395.95200","32.99623","0.02177"
"396.39000","33.03270","0.02259"
"396.82800","33.06923","0.02283"
"397.26600","33.10571","0.02330"
"397.70400","33.14223","0.02363"
"398.14200","33.17876","0.02451"
"398.58000","33.21524","0.02396"
"399.01800","33.25171","0.02342"
"399.45600","33.28824","0.02418"
"399.89400","33.32471","0.02386"
"400.33200","33.36124","0.02393"
"400.77000","33.39772","0.01674"
"401.20800","33.43413","0.01645"
"401.64600","33.47066","0.01584"
"402.08400","33.50719","0.01623"
"402.52200","33.54366","0.01665"
"402.96000","33.58025","0.01680"
"403.39800","33.61673","0.01785"
"403.83600","33.65319","0.01809"
"404.27400","33.68973","0.01880"
"404.71200","33.72620","0.01887"
"405.15000","33.76279","0.01943"
"405.58800","33.79926","0.01918"
"406.02600","33.83567","0.02010"
"406.46400","33.87215","0.01962"
"406.90200","33.90868","0.01994"
"407.34000","33.94521","0.01982"
"407.77800","33.98174","0.02031"
"408.21600","34.01815","0.02001"
"408.65400","34.05468","0.02004"
"409.09200","34.09116","0.01935"
"409.53000","34.12775","0.01866"
"409.96800","34.16422","0.01878"
"410.40600","34.20069","0.01914"
"410.84400","34.23716","0.01959"
"411.28200","34.27369","0.01954"
"411.72000","34.31022","0.01747"
"412.15800","34.34669","0.01724"
"412.59600","34.38322","0.01414"
"413.03400","34.41970","0.01380"
"413.47200","34.45623","0.01379"
"413.91000","34.49276","0.01367"
"414.34800","34.52923","0.01416"
"414.78600","34.56577","0.01399"
"415.22400","34.60218","0.01437"
"415.66200","34.63871","0.01455"
"416.10000","34.67524","0.01462"
"416.53800","34.71171","0.01464"
"416.97600","34.74824","0.01564"
"417.41400","34.78471","0.01608"
"417.85200","34.82113","0.01556"
"418.29000","34.85766","0.01582"
"418.72800","34.89419","0.01596"
"419.16600","34.93072","0.01582"
"419.60400","34.96719","0.01565"
"420.04200","35.00366","0.01590"
"420.48000","35.04025","0.01611"
"420.91800","35.07673","0.01743"
"421.35600","35.11320","0.01700"
"421.79400","35.14979","0.01718"
"422.23200","35.18620","0.01753"
"422.67000","35.22273","0.01736"
"423.10800","35.25920","0.01797"
"423.54600","35.29573","0.01737"
"423.98400","35.33221","0.01828"
"424.42200","35.36874","0.01876"
"424.86000","35.40515","0.01923"
"425.29800","35.44168","0.01958"
"425.73600","35.47821","0.02005"
"426.17400","35.51468","0.02062"
"426.61200","35.55122","0.01972"
"427.05000","35.58769","0.02022"
"427.48800","35.62416","0.02042"
"427.92600","35.66075","0.02093"
"428.36400","35.69722","0.02106"
"428.80200","35.73375","0.02127"
"429.24000","35.77016","0.02094"
"429.67800","35.80670","0.02113"
"430.11600","35.84323","0.02156"
"430.55400","35.87970","0.02174"
"430.99200","35.91623","0.02143"
"431.43000","35.95270","0.02228"
"431.86800","35.98917","0.02185"
"432.30600","36.02570","0.02229"
"432.74400","36.06224","0.02244"
"433.18200","36.09877","0.02262"
"433.62000","36.13518","0.02286"
"434.05800","36.17165","0.02319"
"434.49600","36.20818","0.02330"
"434.93400","36.24471","0.02338"
"435.37200","36.28125","0.02334"
"435.81000","36.31772","0.02375"
"436.24800","36.35419","0.02352"
"436.68600","36.39066","0.02451"
"437.12400","36.42719","0.02503"
"437.56200","36.46372","0.02540"
"438.00000","36.50025","0.02564"
"438.43800","36.53673","0.02565"
"438.87600","36.57320","0.02589"
"439.31400","36.60967","0.02681"
"439.75200","36.64626","0.02695"
"440.19000","36.68273","0.02722"
"440.62800","36.71926","0.02782"
"441.06600","36.75567","0.02878"
"441.50400","36.79215","0.02838"
"441.94200","36.82868","0.02871"
"442.38000","36.86521","0.02917"
"442.81800","36.90174","0.02859"
"443.25600","36.93815","0.02896"
"443.69400","36.97462","0.02941"
"444.13200","37.01122","0.03068"
"444.57000","37.04775","0.03058"
"445.00800","37.08428","0.03023"
"445.44600","37.12075","0.03136"
"445.88400","37.15722","0.03158"
"446.32200","37.19370","0.03163"
"446.76000","37.23022","0.03238"
"447.19800","37.26676","0.03307"
"447.63600","37.30329","0.03397"
"448.07400","37.33970","0.03410"
"448.51200","37.37623","0.03447"
"448.95000","37.41270","0.03488"
"449.38800","37.44923","0.03504"
"449.82600","37.48570","0.03499"
"450.26400","37.52224","0.03592"
"450.70200","37.55865","0.03680"
"451.14000","37.59518","0.03700"
"451.57800","37.63171","0.03754"
"452.01600","37.66824","0.03875"
"452.45400","37.70471","0.03978"
"452.89200","37.74119","0.03966"
"453.33000","37.77766","0.04116"
"453.76800","37.81425","0.04041"
"454.20600","37.85072","0.04134"
"454.64400","37.88725","0.04242"
"455.08200","37.92373","0.04262"
"455.52000","37.96019","0.04366"
"455.95800","37.99673","0.04449"
"456.39600","38.03320","0.04560"
"456.83400","38.06973","0.04569"
"457.27200","38.10620","0.04647"
"457.71000","38.14267","0.04718"
"458.14800","38.17920","0.04784"
"458.58600","38.21573","0.04860"
"459.02400","38.25221","0.04903"
"459.46200","38.28874","0.04943"
"459.90000","38.32515","0.04990"
"460.33800","38.36168","0.05083"
"460.77600","38.39821","0.05075"
"461.21400","38.43475","0.05139"
"461.65200","38.47122","0.05177"
"462.09000","38.50769","0.05233"
"462.52800","38.54416","0.05247"
"462.96600","38.58069","0.05308"
"463.40400","38.61722","0.05335"
"463.84200","38.65376","0.05385"
"464.28000","38.69022","0.05407"
"464.71800","38.72670","0.05443"
"465.15600","38.76317","0.05461"
"465.59400","38.79970","0.05499"
"466.03200","38.83624","0.05503"
"466.47000","38.87270","0.05543"
"466.90800","38.90923","0.05549"
"467.34600","38.94559","0.05582"
"467.78400","38.98218","0.05610"
"468.22200","39.01871","0.05657"
"468.66000","39.05524","0.05692"
"469.09800","39.09171","0.05722"
"469.53600","39.12818","0.05675"
"469.97400","39.16471","0.05714"
"470.41200","39.20125","0.05737"
"470.85000","39.23778","0.05782"
"471.28800","39.27419","0.05806"
"471.72600","39.31072","0.05847"
"472.16400","39.34719","0.05899"
"472.60200","39.38366","0.05944"
"473.04000","39.42025","0.05965"
"473.47800","39.45679","0.06024"
"473.91600","39.49314","0.06043"
"474.35400","39.52967","0.06095"
"474.79200","39.56614","0.06161"
"475.23000","39.60273","0.06196"
"475.66800","39.63921","0.06287"
"476.10600","39.67574","0.06320"
"476.54400","39.71221","0.06455"
"476.98200","39.74868","0.06542"
"477.42000","39.78521","0.06626"
"477.85800","39.82174","0.06724"
"478.29600","39.85822","0.06836"
"478.73400","39.89468","0.06965"
"479.17200","39.93122","0.07043"
"479.61000","39.96775","0.01980"
"480.04800","40.00422","0.02427"
"480.48600","40.04069","0.02904"
"480.92400","40.07722","0.02988"
"481.36200","40.11369","0.02976"
"481.80000","40.15017","0.02995"
"482.23800","40.18670","0.02882"
"482.67600","40.22323","0.02804"
"483.11400","40.25970","0.02941"
"483.55200","40.29617","0.03049"
"483.99000","40.33276","0.03016"
"484.42800","40.36929","0.03085"
"484.86600","40.40570","0.03143"
"485.30400","40.44224","0.03190"
"485.74200","40.47871","0.03378"
"486.18000","40.51518","0.03458"
"486.61800","40.55172","0.03583"
"487.05600","40.58830","0.03553"
"487.49400","40.62477","0.03662"
"487.93200","40.66119","0.03679"
"488.37000","40.69766","0.03745"
"488.80800","40.73419","0.03872"
"489.24600","40.77078","0.03964"
"489.68400","40.80719","0.03955"
"490.12200","40.84373","0.04003"
"490.56000","40.88020","0.04031"
"490.99800","40.91667","0.04102"
"491.43600","40.95320","0.03847"
"491.87400","40.98973","0.03810"
"492.31200","41.02626","0.03819"
"492.75000","41.06274","0.03918"
"493.18800","41.09915","0.04121"
"493.62600","41.13573","0.04131"
"494.06400","41.17221","0.04161"
"494.50200","41.20874","0.04162"
"494.94000","41.24515","0.04223"
"495.37800","41.28168","0.04343"
"495.81600","41.31821","0.04370"
"496.25400","41.35474","0.04391"
"496.69200","41.39128","0.04465"
"497.13000","41.42769","0.04560"
"497.56800","41.46422","0.04565"
"498.00600","41.50069","0.04546"
"498.44400","41.53722","0.04583"
"498.88200","41.57376","0.04710"
"499.32000","41.61023","0.04720"
"499.75800","41.64670","0.04809"
"500.19600","41.68317","0.04825"
"500.63400","41.71964","0.04894"
"501.07200","41.75623","0.04925"
"501.51000","41.79271","0.04999"
"501.94800","41.82924","0.05047"
"502.38600","41.86565","0.05089"
"502.82400","41.90218","0.05098"
"503.26200","41.93871","0.05083"
"503.70000","41.97524","0.05139"
"504.13800","42.01171","0.05141"
"504.57600","42.04824","0.05179"
"505.01400","42.08466","0.05240"
"505.45200","42.12119","0.05259"
"505.89000","42.15778","0.05266"
"506.32800","42.19425","0.05212"
"506.76600","42.23072","0.05311"
"507.20400","42.26720","0.05314"
"507.64200","42.30367","0.05305"
"508.08000","42.34014","0.05319"
"508.51800","42.37673","0.05328"
"508.95600","42.41326","0.05391"
"509.39400","42.44973","0.05363"
"509.83200","42.48614","0.05403"
"510.27000","42.52267","0.05433"
"510.70800","42.55921","0.05465"
"511.14600","42.59574","0.05507"
"511.58400","42.63221","0.05500"
"512.02200","42.66868","0.05505"
"512.46000","42.70515","0.05548"
"512.89800","42.74174","0.05563"
"513.33600","42.77822","0.05591"
"513.77400","42.81475","0.05583"
"514.21200","42.85122","0.05621"
"514.65000","42.88769","0.05632"
"515.08800","42.92428","0.05664"
"515.52600","42.96069","0.05672"
"515.96400","42.99723","0.05715"
"516.40200","43.03370","0.05731"
"516.84000","43.07017","0.05746"
"517.27800","43.10664","0.05754"
"517.71600","43.14323","0.05806"
"518.15400","43.17970","0.05830"
"518.59200","43.21624","0.05844"
"519.03000","43.25265","0.05866"
"519.46800","43.28918","0.05888"
"519.90600","43.32571","0.05934"
"520.34400","43.36224","0.05936"
"520.78200","43.39871","0.05951"
"521.22000","43.43524","0.05990"
"521.65800","43.47166","0.06026"
"522.09600","43.50825","0.06049"
"522.53400","43.54477","0.06032"
"522.97200","43.58125","0.06095"
"523.41000","43.61772","0.06130"
"523.84800","43.65413","0.06164"
"524.28600","43.69072","0.06180"
"524.72400","43.72726","0.06211"
"525.16200","43.76373","0.06261"
"525.60000","43.80025","0.06329"
"526.03800","43.83667","0.06358"
"526.47600","43.87314","0.06440"
"526.91400","43.90973","0.06492"
"527.35200","43.94621","0.06514"
"527.79000","43.98274","0.06589"
"528.22800","44.01915","0.06688"
"528.66600","44.05568","0.06742"
"529.10400","44.09221","0.06797"
"529.54200","44.12874","0.06920"
"529.98000","44.16527","0.07022"
"530.41800","44.20175","0.07075"
"530.85600","44.23816","0.07135"
"531.29400","44.27469","0.07219"
"531.73200","44.31122","0.07384"
"532.17000","44.34769","0.07446"
"532.60800","44.38416","0.07488"
"533.04600","44.42069","0.07576"
"533.48400","44.45723","0.07679"
"533.92200","44.49370","0.07753"
"534.36000","44.53017","0.07843"
"534.79800","44.56670","0.07942"
"535.23600","44.60323","0.08009"
"535.67400","44.63964","0.08064"
"536.11200","44.67617","0.08176"
"536.55000","44.71271","0.08232"
"536.98800","44.74923","0.08348"
"537.42600","44.78571","0.08487"
"537.86400","44.82218","0.08487"
"538.30200","44.85871","0.08553"
"538.74000","44.89524","0.08672"
"539.17800","44.93177","0.08855"
"539.61600","44.96824","0.08860"
"540.05400","45.00471","0.09019"
"540.49200","45.04118","0.09089"
"540.93000","45.07772","0.09207"
"541.36800","45.11419","0.09373"
"541.80600","45.15072","0.09508"
"542.24400","45.18720","0.09597"
"542.68200","45.22367","0.09767"
"543.12000","45.26014","0.09872"
"543.55800","45.29673","0.09953"
"543.99600","45.33320","0.10029"
"544.43400","45.36973","0.10096"
"544.87200","45.40614","0.10194"
"545.31000","45.44268","0.10227"
"545.74800","45.47921","0.10257"
"546.18600","45.51574","0.10288"
"546.62400","45.55221","0.10310"
"547.06200","45.58874","0.10326"
"547.50000","45.62521","0.10373"
"547.93800","45.66174","0.10373"
"548.37600","45.69828","0.10396"
"548.81400","45.73468","0.10458"
"549.25200","45.77122","0.10504"
"549.69000","45.80769","0.10523"
"550.12800","45.84422","0.10618"
"550.56600","45.88070","0.10661"
"551.00400","45.91722","0.10697"
"551.44200","45.95369","0.10780"
"551.88000","45.99017","0.10830"
"552.31800","46.02664","0.10927"
"552.75600","46.06323","0.11025"
"553.19400","46.09970","0.11274"
"553.63200","46.13623","0.11354"
"554.07000","46.17270","0.11450"
"554.50800","46.20912","0.11700"
"554.94600","46.24571","0.11844"
"555.38400","46.28224","0.12035"
"555.82200","46.31871","0.12147"
"556.26000","46.35518","0.12272"
"556.69800","46.39166","0.12489"
"557.13600","46.42813","0.12671"
"557.57400","46.46472","0.12771"
"558.01200","46.50125","0.12893"
"558.45000","46.53772","0.13035"
"558.88800","46.57413","0.13253"
"559.32600","46.61073","0.13292"
"559.76400","46.64714","0.13376"
"560.20200","46.68373","0.13550"
"560.64000","46.72020","0.13674"
"561.07800","46.75673","0.13748"
"561.51600","46.79314","0.13810"
"561.95400","46.82967","0.13869"
"562.39200","46.86627","0.13978"
"562.83000","46.90280","0.14026"
"563.26800","46.93927","0.14073"
"563.70600","46.97568","0.14194"
"564.14400","47.01215","0.14241"
"564.58200","47.04874","0.14277"
"565.02000","47.08527","0.14384"
"565.45800","47.12169","0.14415"
"565.89600","47.15822","0.14493"
"566.33400","47.19469","0.14561"
"566.77200","47.23122","0.14574"
"567.21000","47.26769","0.14676"
"567.64800","47.30422","0.14700"
"568.08600","47.34069","0.14766"
"568.52400","47.37711","0.14790"
"568.96200","47.41364","0.14817"
"569.40000","47.45023","0.14869"
"569.83800","47.48670","0.14930"
"570.27600","47.52323","0.14929"
"570.71400","47.55970","0.14976"
"571.15200","47.59617","0.14997"
"571.59000","47.63277","0.15046"
"572.02800","47.66924","0.15060"
"572.46600","47.70577","0.15109"
"572.90400","47.74224","0.15134"
"573.34200","47.77871","0.15202"
"573.78000","47.81518","0.15233"
"574.21800","47.85178","0.15323"
"574.65600","47.88819","0.15362"
"575.09400","47.92472","0.15464"
"575.53200","47.96119","0.15508"
"575.97000","47.99767","0.15645"
"576.40800","48.03425","0.15804"
"576.84600","48.07072","0.15909"
"577.28400","48.10726","0.16073"
"577.72200","48.14367","0.16212"
"578.16000","48.18014","0.16466"
"578.59800","48.21673","0.16727"
"579.03600","48.25326","0.16942"
"579.47400","48.28973","0.17092"
"579.91200","48.32620","0.17341"
"580.35000","48.36268","0.17493"
"580.78800","48.39921","0.17696"
"581.22600","48.43568","0.17951"
"581.66400","48.47221","0.18258"
"582.10200","48.50868","0.18379"
"582.54000","48.54515","0.18799"
"582.97800","48.58169","0.18993"
"583.41600","48.61822","0.19123"
"583.85400","48.65469","0.19411"
"584.29200","48.69122","0.19691"
"584.73000","48.72769","0.08856"
"585.16800","48.76422","0.08072"
"585.60600","48.80069","0.06244"
"586.04400","48.83723","0.05869"
"586.48200","48.87370","0.06018"
"586.92000","48.91023","0.06607"
"587.35800","48.94670","0.07549"
"587.79600","48.98317","0.07795"
"588.23400","49.01976","0.07508"
"588.67200","49.05624","0.07141"
"589.11000","49.09277","0.06898"
"589.54800","49.12924","0.02957"
"589.98600","49.16565","0.02309"
"590.42400","49.20218","0.01929"
"590.86200","49.23871","0.02158"
"591.30000","49.27524","0.02004"
"591.73800","49.31172","0.01960"
"592.17600","49.34813","0.01901"
"592.61400","49.38472","0.01748"
"593.05200","49.42119","0.01608"
"593.49000","49.45772","0.01610"
"593.92800","49.49419","0.01602"
"594.36600","49.53066","0.01607"
"594.80400","49.56714","0.01782"
"595.24200","49.60367","0.01828"
"595.68000","49.64026","0.01857"
"596.11800","49.67679","0.01762"
"596.55600","49.71320","0.01785"
"596.99400","49.74967","0.01822"
"597.43200","49.78620","0.01796"
"597.87000","49.82274","0.01818"
"598.30800","49.85921","0.01866"
"598.74600","49.89568","0.01943"
"599.18400","49.93215","0.01859"
"599.62200","49.96868","0.01923"
"600.06000","50.00528","0.01916"
"600.49800","50.04169","0.01882"
"600.93600","50.07822","0.01913"
"601.37400","50.11463","0.01996"
"601.81200","50.15122","0.01934"
"602.25000","50.18769","0.02005"
"602.68800","50.22422","0.01946"
"603.12600","50.26069","0.01988"
"603.56400","50.29723","0.02020"
"604.00200","50.33370","0.01997"
"604.44000","50.37023","0.02075"
"604.87800","50.40676","0.02027"
"605.31600","50.44323","0.02064"
"605.75400","50.47970","0.02096"
"606.19200","50.51611","0.02038"
"606.63000","50.55271","0.02112"
"607.06800","50.58924","0.02154"
"607.50600","50.62571","0.02129"
"607.94400","50.66224","0.02192"
"608.38200","50.69871","0.02179"
"608.82000","50.73518","0.02192"
"609.25800","50.77172","0.02201"
"609.69600","50.80819","0.02208"
"610.13400","50.84472","0.02253"
"610.57200","50.88119","0.02297"
"611.01000","50.91766","0.02268"
"611.44800","50.95419","0.02342"
"611.88600","50.99073","0.02306"
"612.32400","51.02726","0.02290"
"612.76200","51.06373","0.02308"
"613.20000","51.10014","0.02374"
"613.63800","51.13667","0.02343"
"614.07600","51.17327","0.02338"
"614.51400","51.20974","0.02392"
"614.95200","51.24627","0.02439"
"615.39000","51.28268","0.02461"
"615.82800","51.31909","0.02447"
"616.26600","51.35568","0.02452"
"616.70400","51.39221","0.02507"
"617.14200","51.42875","0.02572"
"617.58000","51.46522","0.01740"
"618.01800","51.50163","0.00679"
"618.45600","51.53822","0.00938"
"618.89400","51.57475","0.00958"
"619.33200","51.61122","0.00973"
"619.77000","51.64769","0.01091"
"620.20800","51.68416","0.01182"
"620.64600","51.72070","0.01132"
"621.08400","51.75717","0.01215"
"621.52200","51.79370","0.01206"
"621.96000","51.83029","0.01251"
"622.39800","51.86670","0.01283"
"622.83600","51.90317","0.01329"
"623.27400","51.93977","0.01236"
"623.71200","51.97624","0.01374"
"624.15000","52.01277","0.01322"
"624.58800","52.04918","0.01284"
"625.02600","52.08565","0.01368"
"625.46400","52.12218","0.01416"
"625.90200","52.15872","0.01323"
"626.34000","52.19525","0.01370"
"626.77800","52.23178","0.01374"
"627.21600","52.26813","0.01373"
"627.65400","52.30466","0.01380"
"628.09200","52.34119","0.01478"
"628.53000","52.37773","0.01428"
"628.96800","52.41426","0.01387"
"629.40600","52.45073","0.01484"
"629.84400","52.48720","0.01413"
"630.28200","52.52367","0.01498"
"630.72000","52.56026","0.01501"
"631.15800","52.59680","0.01481"
"631.59600","52.63327","0.01486"
"632.03400","52.66968","0.01534"
"632.47200","52.70615","0.01568"
"632.91000","52.74268","0.01529"
"633.34800","52.77921","0.01543"
"633.78600","52.81574","0.01536"
"634.22400","52.85222","0.01548"
"634.66200","52.88869","0.01552"
"635.10000","52.92522","0.01563"
"635.53800","52.96169","0.01588"
"635.97600","52.99822","0.01623"
"636.41400","53.03469","0.01562"
"636.85200","53.07116","0.01633"
"637.29000","53.10770","0.01589"
"637.72800","53.14423","0.01617"
"638.16600","53.18070","0.01632"
"638.60400","53.21723","0.01623"
"639.04200","53.25370","0.01589"
"639.48000","53.29017","0.01618"
"639.91800","53.32677","0.01653"
"640.35600","53.36324","0.01656"
"640.79400","53.39977","0.01653"
"641.23200","53.43618","0.01708"
"641.67000","53.47271","0.01700"
"642.10800","53.50924","0.01666"
"642.54600","53.54577","0.01676"
"642.98400","53.58219","0.01743"
"643.42200","53.61872","0.01705"
"643.86000","53.65507","0.01717"
"644.29800","53.69172","0.01766"
"644.73600","53.72819","0.01768"
"645.17400","53.76472","0.01729"
"645.61200","53.80125","0.01758"
"646.05000","53.83767","0.01770"
"646.48800","53.87420","0.01776"
"646.92600","53.91072","0.01820"
"647.36400","53.94726","0.01816"
"647.80200","53.98379","0.01844"
"648.24000","54.02020","0.01882"
"648.67800","54.05668","0.01831"
"649.11600","54.09321","0.01812"
"649.55400","54.12973","0.01825"
"649.99200","54.16621","0.01829"
"650.43000","54.20268","0.01838"
"650.86800","54.23915","0.01786"
"651.30600","54.27568","0.00650"
"651.74400","54.31222","0.00557"
"652.18200","54.34869","0.00587"
"652.62000","54.38522","0.00523"
"653.05800","54.42169","0.00503"
"653.49600","54.45822","0.00493"
"653.93400","54.49469","0.00510"
"654.37200","54.53122","0.00542"
"654.81000","54.56775","0.00568"
"655.24800","54.60423","0.00539"
"655.68600","54.64069","0.00534"
"655.75600","54.64650","0.00523"