File: Force_trajectories/170225_1/Specimen_RawData_7.csv
End date,"2/25/2017"
Specimen label,"5CG_36"
Maximum Load,"0.35865",N

Time,Extension,Load
(s),(mm),(N)
"0.00000","0.00000","-0.00123"
"0.47400","0.03976","-0.00137"
"0.94800","0.07922","-0.00031"
"1.42200","0.11862","-0.00054"
"1.89600","0.15820","-0.00036"
"2.37000","0.19772","-0.00012"
"2.84400","0.23719","0.00020"
"3.31800","0.27671","0.00014"
"3.79200","0.31629","0.00011"
"4.26600","0.35575","0.00004"
"4.74000","0.39521","0.00042"
"5.21400","0.43461","0.00072"
"5.68800","0.47419","0.00060"
"6.16200","0.51365","0.00091"
"6.63600","0.55323","0.00074"
"7.11000","0.59269","0.00091"
"7.58400","0.63215","0.00024"
"8.05800","0.67174","0.00110"
"8.53200","0.71120","0.00090"
"9.00600","0.75066","0.00021"
"9.48000","0.79012","0.00022"
"9.95400","0.82964","-0.00001"
"10.42800","0.86922","0.00081"
"10.90200","0.90874","0.00022"
"11.37600","0.94820","0.00110"
"11.85000","0.98772","0.00020"
"12.32400","1.02724","-0.00023"
"12.79800","1.06665","0.00042"
"13.27200","1.10617","-0.00059"
"13.74600","1.14569","0.00007"
"14.22000","1.18515","-0.00009"
"14.69400","1.22467","0.00037"
"15.16800","1.26419","0.00023"
"15.64200","1.30371","0.00045"
"16.11600","1.34317","0.00003"
"16.59000","1.38275","0.00075"
"17.06400","1.42215","0.00020"
"17.53800","1.46167","0.00054"
"18.01200","1.50114","0.00038"
"18.48600","1.54072","0.00063"
"18.96000","1.58018","0.00041"
"19.43400","1.61970","-0.00021"
"19.90800","1.65922","0.00079"
"20.38200","1.69874","0.00016"
"20.85600","1.73814","-0.00015"
"21.33000","1.77766","0.00030"
"21.80400","1.81718","0.00041"
"22.27800","1.85670","0.00014"
"22.75200","1.89623","0.00054"
"23.22600","1.93569","0.00019"
"23.70000","1.97521","0.00044"
"24.17400","2.01473","0.00019"
"24.64800","2.05419","0.00085"
"25.12200","2.09365","0.00053"
"25.59600","2.13311","0.00057"
"26.07000","2.17269","0.00075"
"26.54400","2.21215","-0.00011"
"27.01800","2.25173","0.00045"
"27.49200","2.29119","0.00073"
"27.96600","2.33072","0.00056"
"28.44000","2.37018","0.00082"
"28.91400","2.40964","0.00075"
"29.38800","2.44916","0.00096"
"29.86200","2.48868","0.00067"
"30.33600","2.52820","0.00117"
"30.81000","2.56766","0.00075"
"31.28400","2.60718","0.00034"
"31.75800","2.64670","0.00115"
"32.23200","2.68622","0.00127"
"32.70600","2.72569","0.00102"
"33.18000","2.76515","0.00083"
"33.65400","2.80467","0.00043"
"34.12800","2.84419","0.00070"
"34.60200","2.88371","0.00182"
"35.07600","2.92323","0.00050"
"35.55000","2.96269","0.00134"
"36.02400","3.00221","0.00130"
"36.49800","3.04167","0.00097"
"36.97200","3.08119","0.00110"
"37.44600","3.12065","0.00096"
"37.92000","3.16018","0.00083"
"38.39400","3.19970","0.00150"
"38.86800","3.23922","0.00186"
"39.34200","3.27868","0.00145"
"39.81600","3.31826","0.00119"
"40.29000","3.35772","0.00109"
"40.76400","3.39718","0.00133"
"41.23800","3.43664","0.00094"
"41.71200","3.47616","0.00152"
"42.18600","3.51568","0.00128"
"42.66000","3.55521","0.00121"
"43.13400","3.59473","0.00122"
"43.60800","3.63419","0.00144"
"44.08200","3.67371","0.00163"
"44.55600","3.71317","0.00167"
"45.03000","3.75263","0.00176"
"45.50400","3.79215","0.00221"
"45.97800","3.83167","0.00175"
"46.45200","3.87119","0.00127"
"46.92600","3.91071","0.00128"
"47.40000","3.95017","0.00145"
"47.87400","3.98976","0.00091"
"48.34800","4.02922","0.00134"
"48.82200","4.06868","0.00158"
"49.29600","4.10814","0.00171"
"49.77000","4.14766","0.00205"
"50.24400","4.18718","0.00159"
"50.71800","4.22676","0.00046"
"51.19200","4.26622","0.00085"
"51.66600","4.30574","0.00097"
"52.14000","4.34520","0.00093"
"52.61400","4.38467","0.00132"
"53.08800","4.42413","0.00087"
"53.56200","4.46365","0.00097"
"54.03600","4.50323","0.00132"
"54.51000","4.54269","0.00170"
"54.98400","4.58221","0.00139"
"55.45800","4.62173","0.00167"
"55.93200","4.66119","0.00234"
"56.40600","4.70065","0.00271"
"56.88000","4.74017","0.00202"
"57.35400","4.77963","0.00165"
"57.82800","4.81916","0.00221"
"58.30200","4.85868","0.00180"
"58.77600","4.89820","0.00119"
"59.25000","4.93772","0.00137"
"59.72400","4.97724","0.00182"
"60.19800","5.01670","0.00123"
"60.67200","5.05616","0.00229"
"61.14600","5.09562","0.00185"
"61.62000","5.13514","0.00156"
"62.09400","5.17472","0.00183"
"62.56800","5.21419","0.00196"
"63.04200","5.25371","0.00180"
"63.51600","5.29323","0.00215"
"63.99000","5.33269","0.00127"
"64.46400","5.37215","0.00151"
"64.93800","5.41167","0.00168"
"65.41200","5.45119","0.00189"
"65.88600","5.49065","0.00190"
"66.36000","5.53017","0.00209"
"66.83400","5.56975","0.00197"
"67.30800","5.60916","0.00191"
"67.78200","5.64874","0.00181"
"68.25600","5.68820","0.00227"
"68.73000","5.72766","0.00226"
"69.20400","5.76712","0.00239"
"69.67800","5.80664","0.00235"
"70.15200","5.84622","0.00223"
"70.62600","5.88568","0.00166"
"71.10000","5.92526","0.00242"
"71.57400","5.96466","0.00226"
"72.04800","6.00418","0.00110"
"72.52200","6.04371","0.00187"
"72.99600","6.08317","0.00218"
"73.47000","6.12269","0.00233"
"73.94400","6.16215","0.00202"
"74.41800","6.20173","0.00221"
"74.89200","6.24119","0.00164"
"75.36600","6.28065","0.00173"
"75.84000","6.32029","0.00251"
"76.31400","6.35969","0.00257"
"76.78800","6.39915","0.00183"
"77.26200","6.43862","0.00182"
"77.73600","6.47820","0.00164"
"78.21000","6.51766","0.00235"
"78.68400","6.55724","0.00261"
"79.15800","6.59676","0.00251"
"79.63200","6.63616","0.00265"
"80.10600","6.67568","0.00191"
"80.58000","6.71514","0.00203"
"81.05400","6.75466","0.00266"
"81.52800","6.79418","0.00274"
"82.00200","6.83370","0.00264"
"82.47600","6.87317","0.00294"
"82.95000","6.91269","0.00292"
"83.42400","6.95221","0.00355"
"83.89800","6.99173","0.00290"
"84.37200","7.03125","0.00309"
"84.84600","7.07065","0.00319"
"85.32000","7.11017","0.00251"
"85.79400","7.14969","0.00330"
"86.26800","7.18915","0.00394"
"86.74200","7.22873","0.00343"
"87.21600","7.26820","0.00417"
"87.69000","7.30766","0.00397"
"88.16400","7.34718","0.00397"
"88.63800","7.38664","0.00362"
"89.11200","7.42610","0.00374"
"89.58600","7.46568","0.00436"
"90.06000","7.50514","0.00450"
"90.53400","7.54472","0.00427"
"91.00800","7.58418","0.00436"
"91.48200","7.62376","0.00428"
"91.95600","7.66322","0.00495"
"92.43000","7.70269","0.00361"
"92.90400","7.74215","0.00461"
"93.37800","7.78167","0.00460"
"93.85200","7.82119","0.00483"
"94.32600","7.86071","0.00478"
"94.80000","7.90023","0.00473"
"95.27400","7.93969","0.00534"
"95.74800","7.97921","0.00481"
"96.22200","8.01867","0.00509"
"96.69600","8.05813","0.00556"
"97.17000","8.09766","0.00522"
"97.64400","8.13718","0.00595"
"98.11800","8.17670","0.00524"
"98.59200","8.21616","0.00517"
"99.06600","8.25574","0.00532"
"99.54000","8.29520","0.00522"
"100.01400","8.33466","0.00535"
"100.48800","8.37418","0.00609"
"100.96200","8.41364","0.00564"
"101.43600","8.45316","0.00573"
"101.91000","8.49269","0.00651"
"102.38400","8.53221","0.00634"
"102.85800","8.57173","0.00504"
"103.33200","8.61119","0.00556"
"103.80600","8.65071","0.00465"
"104.28000","8.69017","0.00530"
"104.75400","8.72963","0.00583"
"105.22800","8.76915","0.00560"
"105.70200","8.80867","0.00578"
"106.17600","8.84819","0.00628"
"106.65000","8.88771","0.00605"
"107.12400","8.92724","0.00609"
"107.59800","8.96670","0.00673"
"108.07200","9.00616","0.00665"
"108.54600","9.04568","0.00651"
"109.02000","9.08514","0.00656"
"109.49400","9.12460","0.00707"
"109.96800","9.16418","0.00671"
"110.44200","9.20370","0.00660"
"110.91600","9.24322","0.00728"
"111.39000","9.28274","0.00754"
"111.86400","9.32220","0.00719"
"112.33800","9.36167","0.00724"
"112.81200","9.40113","0.00744"
"113.28600","9.44065","0.00749"
"113.76000","9.48017","0.00778"
"114.23400","9.51969","0.00777"
"114.70800","9.55921","0.00840"
"115.18200","9.59873","0.00782"
"115.65600","9.63813","0.00848"
"116.13000","9.67765","0.00859"
"116.60400","9.71717","0.00809"
"117.07800","9.75670","0.00835"
"117.55200","9.79616","0.00819"
"118.02600","9.83574","0.00779"
"118.50000","9.87520","0.00870"
"118.97400","9.91466","0.00859"
"119.44800","9.95424","0.00873"
"119.92200","9.99370","0.00831"
"120.39600","10.03310","0.00864"
"120.87000","10.07262","0.00947"
"121.34400","10.11220","0.00851"
"121.81800","10.15166","0.00931"
"122.29200","10.19125","0.00907"
"122.76600","10.23071","0.00927"
"123.24000","10.27017","0.00984"
"123.71400","10.30969","0.00927"
"124.18800","10.34921","0.00991"
"124.66200","10.38861","0.00979"
"125.13600","10.42819","0.01025"
"125.61000","10.46765","0.00969"
"126.08400","10.50723","0.01010"
"126.55800","10.54669","0.00963"
"127.03200","10.58621","0.01019"
"127.50600","10.62574","0.01019"
"127.98000","10.66520","0.01006"
"128.45400","10.70466","0.01024"
"128.92800","10.74418","0.00972"
"129.40200","10.78364","0.01077"
"129.87600","10.82316","0.01059"
"130.35000","10.86274","0.01074"
"130.82400","10.90220","0.01045"
"131.29800","10.94166","0.01029"
"131.77200","10.98118","0.01058"
"132.24600","11.02071","0.01099"
"132.72000","11.06017","0.01087"
"133.19400","11.09963","0.01127"
"133.66800","11.13915","0.01104"
"134.14200","11.17873","0.01154"
"134.61600","11.21819","0.01142"
"135.09000","11.25771","0.01144"
"135.56400","11.29723","0.01145"
"136.03800","11.33669","0.01110"
"136.51200","11.37615","0.01220"
"136.98600","11.41568","0.01209"
"137.46000","11.45520","0.01192"
"137.93400","11.49472","0.01223"
"138.40800","11.53424","0.01176"
"138.88200","11.57370","0.01165"
"139.35600","11.61322","0.01165"
"139.83000","11.65268","0.01144"
"140.30400","11.69214","0.01158"
"140.77800","11.73160","0.01214"
"141.25200","11.77118","0.01199"
"141.72600","11.81071","0.01225"
"142.20000","11.85017","0.01193"
"142.67400","11.88969","0.01239"
"143.14800","11.92927","0.01145"
"143.62200","11.96867","0.01149"
"144.09600","12.00819","0.01164"
"144.57000","12.04771","0.01184"
"145.04400","12.08717","0.01161"
"145.51800","12.12669","0.01113"
"145.99200","12.16621","0.01116"
"146.46600","12.20574","0.01122"
"146.94000","12.24520","0.01212"
"147.41400","12.28472","0.01165"
"147.88800","12.32424","0.01175"
"148.36200","12.36364","0.01201"
"148.83600","12.40316","0.01245"
"149.31000","12.44268","0.01261"
"149.78400","12.48220","0.01264"
"150.25800","12.52166","0.01321"
"150.73200","12.56118","0.01280"
"151.20600","12.60076","0.01303"
"151.68000","12.64017","0.01262"
"152.15400","12.67969","0.01224"
"152.62800","12.71915","0.01197"
"153.10200","12.75867","0.01182"
"153.57600","12.79819","0.01259"
"154.05000","12.83771","0.00984"
"154.52400","12.87723","0.00977"
"154.99800","12.91669","0.01008"
"155.47200","12.95621","0.01016"
"155.94600","12.99567","0.01055"
"156.42000","13.03520","0.01004"
"156.89400","13.07466","0.01102"
"157.36800","13.11418","0.01015"
"157.84200","13.15370","0.01046"
"158.31600","13.19316","0.01056"
"158.79000","13.23274","0.01137"
"159.26400","13.27226","0.01122"
"159.73800","13.31172","0.01175"
"160.21200","13.35118","0.01181"
"160.68600","13.39064","0.01180"
"161.16000","13.43010","0.01117"
"161.63400","13.46969","0.01078"
"162.10800","13.50921","0.01153"
"162.58200","13.54873","0.01218"
"163.05600","13.58825","0.01256"
"163.53000","13.62771","0.01194"
"164.00400","13.66723","0.01206"
"164.47800","13.70663","0.01302"
"164.95200","13.74615","0.01278"
"165.42600","13.78567","0.01237"
"165.90000","13.82519","0.01332"
"166.37400","13.86466","0.01306"
"166.84800","13.90418","0.01273"
"167.32200","13.94370","0.01345"
"167.79600","13.98322","0.01347"
"168.27000","14.02268","0.01295"
"168.74400","14.06214","0.01350"
"169.21800","14.10166","0.01337"
"169.69200","14.14124","0.01313"
"170.16600","14.18076","0.01268"
"170.64000","14.22016","0.01230"
"171.11400","14.25980","0.01284"
"171.58800","14.29921","0.01310"
"172.06200","14.33867","0.01333"
"172.53600","14.37819","0.01304"
"173.01000","14.41765","0.01341"
"173.48400","14.45723","0.01316"
"173.95800","14.49669","0.01303"
"174.43200","14.53627","0.01224"
"174.90600","14.57573","0.01221"
"175.38000","14.61519","0.01150"
"175.85400","14.65471","0.00881"
"176.32800","14.69417","0.00951"
"176.80200","14.73364","0.00956"
"177.27600","14.77316","0.00951"
"177.75000","14.81268","0.00942"
"178.22400","14.85220","0.01007"
"178.69800","14.89166","0.00964"
"179.17200","14.93124","0.00941"
"179.64600","14.97070","0.00957"
"180.12000","15.01016","0.00938"
"180.59400","15.04968","0.00954"
"181.06800","15.08914","0.00931"
"181.54200","15.12866","0.00978"
"182.01600","15.16825","0.00968"
"182.49000","15.20771","0.01036"
"182.96400","15.24723","0.01021"
"183.43800","15.28669","0.01017"
"183.91200","15.32621","0.01098"
"184.38600","15.36561","0.01096"
"184.86000","15.40519","0.01161"
"185.33400","15.44465","0.01089"
"185.80800","15.48417","0.01117"
"186.28200","15.52369","0.01169"
"186.75600","15.56322","0.01125"
"187.23000","15.60274","0.01215"
"187.70400","15.64220","0.01212"
"188.17800","15.68166","0.01232"
"188.65200","15.72112","0.01223"
"189.12600","15.76070","0.01229"
"189.60000","15.80016","0.01148"
"190.07400","15.83968","0.01050"
"190.54800","15.87920","0.01121"
"191.02200","15.91872","0.01130"
"191.49600","15.95824","0.01104"
"191.97000","15.99765","0.01175"
"192.44400","16.03711","0.01181"
"192.91800","16.07669","0.01199"
"193.39200","16.11621","0.01182"
"193.86600","16.15567","0.01220"
"194.34000","16.19519","0.01295"
"194.81400","16.23471","0.01301"
"195.28800","16.27417","0.01380"
"195.76200","16.31369","0.01411"
"196.23600","16.35321","0.01423"
"196.71000","16.39261","0.01430"
"197.18400","16.43214","0.01546"
"197.65800","16.47172","0.01555"
"198.13200","16.51118","0.01505"
"198.60600","16.55070","0.01564"
"199.08000","16.59022","0.01588"
"199.55400","16.62968","0.01597"
"200.02800","16.66914","0.01492"
"200.50200","16.70866","0.01602"
"200.97600","16.74818","0.01570"
"201.45000","16.78770","0.01579"
"201.92400","16.82722","0.01417"
"202.39800","16.86669","0.01495"
"202.87200","16.90621","0.01574"
"203.34600","16.94567","0.01628"
"203.82000","16.98519","0.01615"
"204.29400","17.02465","0.01758"
"204.76800","17.06417","0.01702"
"205.24200","17.10363","0.01611"
"205.71600","17.14321","0.01629"
"206.19000","17.18273","0.01766"
"206.66400","17.22220","0.01827"
"207.13800","17.26171","0.01751"
"207.61200","17.30112","0.01840"
"208.08600","17.34064","0.01898"
"208.56000","17.38016","0.01965"
"209.03400","17.41968","0.01960"
"209.50800","17.45920","0.01927"
"209.98200","17.49872","0.01952"
"210.45600","17.53824","0.01982"
"210.93000","17.57770","0.01929"
"211.40400","17.61717","0.01961"
"211.87800","17.65668","0.02092"
"212.35200","17.69615","0.02086"
"212.82600","17.73567","0.01979"
"213.30000","17.77519","0.02085"
"213.77400","17.81471","0.02112"
"214.24800","17.85423","0.02171"
"214.72200","17.89375","0.02210"
"215.19600","17.93321","0.02276"
"215.67000","17.97267","0.02352"
"216.14400","18.01213","0.02350"
"216.61800","18.05172","0.02367"
"217.09200","18.09118","0.02439"
"217.56600","18.13070","0.02398"
"218.04000","18.17022","0.02425"
"218.51400","18.20974","0.02451"
"218.98800","18.24920","0.02469"
"219.46200","18.28872","0.02367"
"219.93600","18.32818","0.02430"
"220.41000","18.36758","0.02501"
"220.88400","18.40716","0.02452"
"221.35800","18.44669","0.02508"
"221.83200","18.48627","0.02652"
"222.30600","18.52567","0.02787"
"222.78000","18.56525","0.02723"
"223.25400","18.60471","0.02834"
"223.72800","18.64411","0.02931"
"224.20200","18.68369","0.02978"
"224.67600","18.72315","0.03104"
"225.15000","18.76267","0.03224"
"225.62400","18.80225","0.03198"
"226.09800","18.84171","0.03300"
"226.57200","18.88118","0.03357"
"227.04600","18.92070","0.03337"
"227.52000","18.96022","0.03410"
"227.99400","18.99968","0.03451"
"228.46800","19.03914","0.03465"
"228.94200","19.07866","0.03383"
"229.41600","19.11818","0.03473"
"229.89000","19.15770","0.03467"
"230.36400","19.19716","0.03490"
"230.83800","19.23674","0.03638"
"231.31200","19.27621","0.03631"
"231.78600","19.31567","0.03595"
"232.26000","19.35513","0.03644"
"232.73400","19.39465","0.03712"
"233.20800","19.43411","0.03757"
"233.68200","19.47375","0.03804"
"234.15600","19.51321","0.03930"
"234.63000","19.55267","0.03899"
"235.10400","19.59219","0.03924"
"235.57800","19.63171","0.03928"
"236.05200","19.67112","0.04043"
"236.52600","19.71070","0.04078"
"237.00000","19.75022","0.04199"
"237.47400","19.78962","0.04211"
"237.94800","19.82920","0.04262"
"238.42200","19.86872","0.04301"
"238.89600","19.90824","0.04367"
"239.37000","19.94770","0.04373"
"239.84400","19.98716","0.04321"
"240.31800","20.02662","0.04399"
"240.79200","20.06614","0.04450"
"241.26600","20.10572","0.04501"
"241.74000","20.14524","0.04501"
"242.21400","20.18477","0.04538"
"242.68800","20.22417","0.04622"
"243.16200","20.26375","0.04611"
"243.63600","20.30315","0.04649"
"244.11000","20.34261","0.04672"
"244.58400","20.38219","0.04667"
"245.05800","20.42165","0.04750"
"245.53200","20.46117","0.04803"
"246.00600","20.50069","0.04826"
"246.48000","20.54022","0.04895"
"246.95400","20.57973","0.05009"
"247.42800","20.61920","0.05066"
"247.90200","20.65866","0.05090"
"248.37600","20.69812","0.05140"
"248.85000","20.73764","0.05149"
"249.32400","20.77722","0.05260"
"249.79800","20.81674","0.05357"
"250.27200","20.85620","0.05469"
"250.74600","20.89572","0.05596"
"251.22000","20.93518","0.05686"
"251.69400","20.97471","0.05815"
"252.16800","21.01417","0.05990"
"252.64200","21.05363","0.06059"
"253.11600","21.09321","0.06302"
"253.59000","21.13267","0.06458"
"254.06400","21.17225","0.06662"
"254.53800","21.21171","0.06866"
"255.01200","21.25123","0.06987"
"255.48600","21.29063","0.07242"
"255.96000","21.33016","0.07375"
"256.43400","21.36968","0.07517"
"256.90800","21.40920","0.07695"
"257.38200","21.44872","0.06709"
"257.85600","21.48818","0.07045"
"258.33000","21.52770","0.07185"
"258.80400","21.56716","0.07415"
"259.27800","21.60668","0.07558"
"259.75200","21.64614","0.07785"
"260.22600","21.68566","0.07911"
"260.70000","21.72513","0.08173"
"261.17400","21.76471","0.08068"
"261.64800","21.80423","0.08248"
"262.12200","21.84375","0.08518"
"262.59600","21.88321","0.08672"
"263.07000","21.92267","0.08691"
"263.54400","21.96219","0.08867"
"264.01800","22.00165","0.08985"
"264.49200","22.04117","0.08039"
"264.96600","22.08069","0.08301"
"265.44000","22.12021","0.08605"
"265.91400","22.15968","0.08888"
"266.38800","22.19926","0.09081"
"266.86200","22.23872","0.09268"
"267.33600","22.27818","0.09402"
"267.81000","22.31764","0.09513"
"268.28400","22.35716","0.09613"
"268.75800","22.39668","0.09868"
"269.23200","22.43620","0.10274"
"269.70600","22.47572","0.10538"
"270.18000","22.51518","0.11014"
"270.65400","22.55470","0.10690"
"271.12800","22.59417","0.11020"
"271.60200","22.63369","0.11390"
"272.07600","22.67315","0.11722"
"272.55000","22.71273","0.12035"
"273.02400","22.75219","0.12321"
"273.49800","22.79171","0.12529"
"273.97200","22.83117","0.12794"
"274.44600","22.87069","0.13002"
"274.92000","22.91021","0.13176"
"275.39400","22.94967","0.13390"
"275.86800","22.98914","0.13562"
"276.34200","23.02860","0.13544"
"276.81600","23.06812","0.13533"
"277.29000","23.10776","0.13446"
"277.76400","23.14722","0.13405"
"278.23800","23.18668","0.13626"
"278.71200","23.22620","0.13715"
"279.18600","23.26572","0.13840"
"279.66000","23.30518","0.13198"
"280.13400","23.34464","0.12677"
"280.60800","23.38416","0.12961"
"281.08200","23.42363","0.13286"
"281.55600","23.46321","0.13556"
"282.03000","23.50273","0.13681"
"282.50400","23.54225","0.13775"
"282.97800","23.58171","0.13876"
"283.45200","23.62117","0.13962"
"283.92600","23.66063","0.14036"
"284.40000","23.70015","0.14127"
"284.87400","23.73967","0.14164"
"285.34800","23.77925","0.14385"
"285.82200","23.81871","0.14670"
"286.29600","23.85818","0.15052"
"286.77000","23.89770","0.15403"
"287.24400","23.93722","0.15640"
"287.71800","23.97662","0.16161"
"288.19200","24.01620","0.16827"
"288.66600","24.05572","0.17202"
"289.14000","24.09512","0.17905"
"289.61400","24.13470","0.18551"
"290.08800","24.17416","0.19046"
"290.56200","24.21375","0.19402"
"291.03600","24.25320","0.19678"
"291.51000","24.29267","0.19827"
"291.98400","24.33219","0.19971"
"292.45800","24.37165","0.20065"
"292.93200","24.41123","0.20107"
"293.40600","24.45075","0.20248"
"293.88000","24.49021","0.20653"
"294.35400","24.52967","0.20928"
"294.82800","24.56919","0.21178"
"295.30200","24.60865","0.21530"
"295.77600","24.64812","0.21874"
"296.25000","24.68769","0.22199"
"296.72400","24.72716","0.22823"
"297.19800","24.76668","0.23335"
"297.67200","24.80620","0.23810"
"298.14600","24.84572","0.24092"
"298.62000","24.88518","0.24332"
"299.09400","24.92470","0.24551"
"299.56800","24.96416","0.24744"
"300.04200","25.00363","0.24896"
"300.51600","25.04314","0.25097"
"300.99000","25.08272","0.25309"
"301.46400","25.12219","0.25617"
"301.93800","25.16165","0.26007"
"302.41200","25.20123","0.26385"
"302.88600","25.24069","0.26810"
"303.36000","25.28015","0.27200"
"303.83400","25.31967","0.27527"
"304.30800","25.35913","0.27840"
"304.78200","25.39865","0.28139"
"305.25600","25.43817","0.28458"
"305.73000","25.47775","0.28620"
"306.20400","25.51722","0.28892"
"306.67800","25.55668","0.29013"
"307.15200","25.59620","0.29159"
"307.62600","25.63566","0.29229"
"308.10000","25.67512","0.29388"
"308.57400","25.71464","0.29656"
"309.04800","25.75428","0.30031"
"309.52200","25.79368","0.30612"
"309.99600","25.83326","0.31679"
"310.47000","25.87267","0.32680"
"310.94400","25.91219","0.33713"
"311.41800","25.95165","0.34474"
"311.89200","25.99117","0.34933"
"312.36600","26.03069","0.35193"
"312.84000","26.07015","0.35315"
"313.31400","26.10973","0.35334"
"313.78800","26.14919","0.35383"
"314.26200","26.18877","0.35399"
"314.73600","26.22817","0.35471"
"315.21000","26.26769","0.35582"
"315.68400","26.30715","0.35788"
"316.15800","26.34668","0.09799"
"316.63200","26.38620","0.10123"
"317.10600","26.42572","0.10545"
"317.58000","26.46518","0.11003"
"318.05400","26.50476","0.11699"
"318.52800","26.54422","0.11722"
"319.00200","26.58362","0.12440"
"319.47600","26.62314","0.13197"
"319.95000","26.66266","0.13585"
"320.42400","26.70218","0.13725"
"320.89800","26.74171","0.13796"
"321.37200","26.78123","0.13884"
"321.84600","26.82075","0.13937"
"322.32000","26.86021","0.14018"
"322.79400","26.89973","0.14258"
"323.26800","26.93919","0.14697"
"323.74200","26.97865","0.15178"
"324.21600","27.01817","0.15477"
"324.69000","27.05763","0.15753"
"325.16400","27.09721","0.16458"
"325.63800","27.13667","0.17525"
"326.11200","27.17626","0.18263"
"326.58600","27.21572","0.18761"
"327.06000","27.25512","0.19127"
"327.53400","27.29464","0.19643"
"328.00800","27.33416","0.19876"
"328.48200","27.37362","0.20026"
"328.95600","27.41326","0.20138"
"329.43000","27.45272","0.20398"
"329.90400","27.49219","0.20740"
"330.37800","27.53176","0.21106"
"330.85200","27.57117","0.21266"
"331.32600","27.61069","0.18509"
"331.80000","27.65015","0.16073"
"332.27400","27.68967","0.16744"
"332.74800","27.72913","0.17639"
"333.22200","27.76871","0.18269"
"333.69600","27.80823","0.18691"
"334.17000","27.84775","0.19301"
"334.64400","27.88721","0.19687"
"335.11800","27.92668","0.19911"
"335.59200","27.96614","0.20014"
"336.06600","28.00566","0.20099"
"336.54000","28.04518","0.20320"
"337.01400","28.08476","0.20595"
"337.48800","28.12422","0.20874"
"337.96200","28.16368","0.21051"
"338.43600","28.20326","0.21220"
"338.91000","28.24266","0.21453"
"339.38400","28.28213","0.21707"
"339.85800","28.32170","0.21992"
"340.33200","28.36117","0.22248"
"340.80600","28.40069","0.22632"
"341.28000","28.44021","0.22844"
"341.75400","28.47973","0.23067"
"342.22800","28.51925","0.23245"
"342.70200","28.55871","0.23461"
"343.17600","28.59817","0.23611"
"343.65000","28.63763","0.23751"
"344.12400","28.67721","0.23898"
"344.59800","28.71668","0.24006"
"345.07200","28.75620","0.24167"
"345.54600","28.79566","0.24209"
"346.02000","28.83524","0.24317"
"346.49400","28.87470","0.24406"
"346.96800","28.91422","0.24480"
"347.44200","28.95362","0.24562"
"347.91600","28.99314","0.24643"
"348.39000","29.03272","0.24717"
"348.86400","29.07218","0.24825"
"349.33800","29.11170","0.24938"
"349.81200","29.15123","0.25069"
"350.28600","29.19069","0.25186"
"350.76000","29.23021","0.25326"
"351.23400","29.26973","0.25475"
"351.70800","29.30913","0.25717"
"352.18200","29.34871","0.25953"
"352.65600","29.38823","0.26284"
"353.13000","29.42769","0.26614"
"353.60400","29.46721","0.26865"
"354.07800","29.50673","0.27112"
"354.55200","29.54619","0.27395"
"355.02600","29.58566","0.27820"
"355.50000","29.62512","0.28056"
"355.97400","29.66463","0.27583"
"356.44800","29.70416","0.21030"
"356.92200","29.74368","0.21435"
"357.39600","29.78326","0.21688"
"357.87000","29.82272","0.21383"
"358.34400","29.86218","0.21506"
"358.81800","29.90170","0.21929"
"359.29200","29.94116","0.22146"
"359.76600","29.98062","0.22146"
"360.24000","30.02020","0.22164"
"360.71400","30.05967","0.22487"
"361.18800","30.09919","0.22736"
"361.66200","30.13877","0.22574"
"362.13600","30.17823","0.05463"
"362.61000","30.21769","0.06335"
"363.08400","30.25715","0.08023"
"363.55800","30.29661","0.07571"
"364.03200","30.33619","0.06027"
"364.50600","30.37565","0.05639"
"364.98000","30.41524","0.05679"
"365.45400","30.45469","0.05812"
"365.92800","30.49416","0.06152"
"366.40200","30.53374","0.06904"
"366.87600","30.57314","0.07667"
"367.35000","30.61266","0.07697"
"367.82400","30.65212","0.07362"
"368.29800","30.69170","0.07113"
"368.77200","30.73116","0.06996"
"369.24600","30.77068","0.07037"
"369.72000","30.81026","0.07089"
"370.19400","30.84973","0.07292"
"370.66800","30.88919","0.07503"
"371.14200","30.92865","0.07743"
"371.61600","30.96817","0.08151"
"372.09000","31.00763","0.08458"
"372.56400","31.04721","0.07695"
"373.03800","31.08667","0.07778"
"373.51200","31.12619","0.07630"
"373.98600","31.16571","0.07202"
"374.46000","31.20523","0.07219"
"374.93400","31.24470","0.07271"
"375.40800","31.28415","0.07308"
"375.88200","31.32368","0.07565"
"376.35600","31.36320","0.07752"
"376.83000","31.40272","0.07795"
"377.30400","31.44224","0.07898"
"377.77800","31.48176","0.08072"
"378.25200","31.52116","0.08229"
"378.72600","31.56068","0.08367"
"379.20000","31.60014","0.08464"
"379.67400","31.63967","0.08516"
"380.14800","31.67912","0.08587"
"380.62200","31.71870","0.08484"
"381.09600","31.75823","0.08468"
"381.57000","31.79763","0.08563"
"382.04400","31.83727","0.08559"
"382.51800","31.87673","0.07124"
"382.99200","31.91619","0.06815"
"383.46600","31.95565","0.07024"
"383.94000","31.99511","0.07308"
"384.41400","32.03469","0.07537"
"384.88800","32.07421","0.07595"
"385.36200","32.11374","0.07763"
"385.83600","32.15320","0.07788"
"386.31000","32.19272","0.07786"
"386.78400","32.23218","0.07937"
"387.25800","32.27164","0.08097"
"387.73200","32.31116","0.08290"
"388.20600","32.35062","0.08442"
"388.68000","32.39020","0.08599"
"389.15400","32.42972","0.08703"
"389.62800","32.46918","0.08794"
"390.10200","32.50877","0.08887"
"390.57600","32.54817","0.08871"
"391.05000","32.58762","0.08942"
"391.52400","32.62715","0.09014"
"391.99800","32.66667","0.09052"
"392.47200","32.70613","0.09118"
"392.94600","32.74571","0.09132"
"393.42000","32.78523","0.09007"
"393.89400","32.82469","0.09211"
"394.36800","32.86421","0.09258"
"394.84200","32.90374","0.09298"
"395.31600","32.94314","0.09293"
"395.79000","32.98265","0.09339"
"396.26400","33.02224","0.09238"
"396.73800","33.06170","0.09262"
"397.21200","33.10122","0.09341"
"397.68600","33.14068","0.09401"
"398.16000","33.18020","0.09438"
"398.63400","33.21966","0.09474"
"399.10800","33.25912","0.09499"
"399.58200","33.29871","0.09564"
"400.05600","33.33823","0.09605"
"400.53000","33.37769","0.09646"
"401.00400","33.41721","0.09652"
"401.47800","33.45673","0.09782"
"401.95200","33.49619","0.09807"
"402.42600","33.53571","0.09868"
"402.90000","33.57511","0.09911"
"403.37400","33.61463","0.09949"
"403.84800","33.65415","0.09922"
"404.32200","33.69373","0.10086"
"404.79600","33.73325","0.10128"
"405.27000","33.77266","0.10286"
"405.74400","33.81224","0.10298"
"406.21800","33.85170","0.10436"
"406.69200","33.89116","0.10433"
"407.16600","33.93062","0.10612"
"407.64000","33.97014","0.10652"
"408.11400","34.00966","0.10839"
"408.58800","34.04918","0.10875"
"409.06200","34.08870","0.10997"
"409.53600","34.12816","0.11097"
"410.01000","34.16774","0.11205"
"410.48400","34.20721","0.11332"
"410.95800","34.24667","0.11414"
"411.43200","34.28613","0.11502"
"411.90600","34.32565","0.11629"
"412.38000","34.36523","0.11729"
"412.85400","34.40469","0.11841"
"413.32800","34.44421","0.11831"
"413.80200","34.48367","0.11974"
"414.27600","34.52319","0.12130"
"414.75000","34.56271","0.12153"
"415.22400","34.60218","0.00358"
"415.69800","34.64164","-0.00200"
"416.17200","34.68116","-0.00233"
"416.64600","34.72068","0.00026"
"417.12000","34.76014","-0.00214"
"417.59400","34.79966","-0.00177"
"418.06800","34.83924","-0.00016"
"418.54200","34.87864","-0.00131"
"419.01600","34.91816","-0.00207"
"419.49000","34.95768","-0.00209"
"419.96400","34.99721","-0.00211"
"420.43800","35.03673","-0.00063"
"420.91200","35.07624","-0.00179"
"421.38600","35.11571","-0.00207"
"421.86000","35.15523","-0.00200"
"422.33400","35.19469","-0.00150"
"422.80800","35.23415","-0.00095"
"423.28200","35.27361","-0.00189"
"423.75600","35.31313","-0.00179"
"424.23000","35.35265","-0.00178"
"424.70400","35.39218","-0.00119"
"425.17800","35.43169","-0.00193"
"425.65200","35.47121","-0.00171"
"426.12600","35.51068","-0.00161"
"426.60000","35.55014","-0.00114"
"427.07400","35.58960","-0.00191"
"427.54800","35.62918","-0.00230"
"428.02200","35.66870","-0.00222"
"428.49600","35.70822","-0.00206"
"428.97000","35.74775","-0.00170"
"429.44400","35.78720","-0.00178"
"429.91800","35.82673","-0.00154"
"430.39200","35.86618","-0.00110"
"430.86600","35.90565","-0.00164"
"431.34000","35.94511","-0.00257"
"431.81400","35.98469","-0.00218"
"432.28800","36.02421","-0.00203"
"432.76200","36.06373","-0.00152"
"433.23600","36.10319","-0.00194"
"433.71000","36.14277","-0.00196"
"434.18400","36.18217","-0.00117"
"434.65800","36.22163","-0.00112"
"435.13200","36.26116","-0.00220"
"435.60600","36.30068","-0.00245"
"436.08000","36.34020","-0.00173"
"436.55400","36.37972","-0.00106"
"437.02800","36.41924","-0.00249"
"437.50200","36.45870","-0.00192"
"437.97600","36.49822","-0.00177"
"438.45000","36.53774","-0.00140"
"438.92400","36.57714","-0.00261"
"439.39800","36.61666","-0.00278"
"439.87200","36.65613","-0.00210"
"440.34600","36.69571","-0.00143"
"440.82000","36.73516","-0.00205"
"441.29400","36.77469","-0.00234"
"441.76800","36.81421","-0.00199"
"442.24200","36.85367","-0.00226"
"442.71600","36.89313","-0.00247"
"443.19000","36.93265","-0.00164"
"443.66400","36.97217","-0.00175"
"444.13800","37.01163","-0.00184"
"444.61200","37.05122","-0.00171"
"445.08600","37.09068","-0.00288"
"445.56000","37.13020","-0.00274"
"446.03400","37.16972","-0.00210"
"446.50800","37.20924","-0.00178"
"446.98200","37.24858","-0.00201"
"447.45600","37.28816","-0.00212"
"447.93000","37.32774","-0.00152"
"448.40400","37.36720","-0.00244"
"448.87800","37.40672","-0.00218"
"449.35200","37.44619","-0.00247"
"449.82600","37.48570","-0.00229"
"450.30000","37.52517","-0.00150"
"450.77400","37.56469","-0.00187"
"451.24800","37.60415","-0.00189"
"451.72200","37.64367","-0.00220"
"452.19600","37.68319","-0.00209"
"452.67000","37.72265","-0.00163"
"453.14400","37.76223","-0.00237"
"453.61800","37.80169","-0.00212"
"454.09200","37.84122","-0.00229"
"454.56600","37.88067","-0.00197"
"455.04000","37.92008","-0.00253"
"455.51400","37.95966","-0.00200"
"455.98800","37.99918","-0.00151"
"456.46200","38.03876","-0.00197"
"456.93600","38.07822","-0.00232"
"457.41000","38.11768","-0.00260"
"457.88400","38.15720","-0.00195"
"458.35800","38.19666","-0.00226"
"458.83200","38.23618","-0.00162"
"459.30600","38.27564","-0.00262"
"459.78000","38.31517","-0.00250"
"460.25400","38.35469","-0.00182"
"460.72800","38.39421","-0.00255"
"461.20200","38.43367","-0.00147"
"461.67600","38.47319","-0.00226"
"462.15000","38.51271","-0.00187"
"462.62400","38.55211","-0.00239"
"463.09800","38.59163","-0.00207"
"463.57200","38.63121","-0.00137"
"464.04600","38.67073","-0.00237"
"464.52000","38.71025","-0.00250"
"464.99400","38.74972","-0.00252"
"465.46800","38.78924","-0.00180"
"465.94200","38.82864","-0.00234"
"466.41600","38.86816","-0.00213"
"466.89000","38.90768","-0.00207"
"467.36400","38.94714","-0.00294"
"467.83800","38.98666","-0.00198"
"468.31200","39.02624","-0.00189"
"468.78600","39.06570","-0.00192"
"469.26000","39.10522","-0.00175"
"469.73400","39.14468","-0.00212"
"470.20800","39.18420","-0.00165"
"470.68200","39.22360","-0.00215"
"471.15600","39.26313","-0.00192"
"471.63000","39.30271","-0.00228"
"472.10400","39.34223","-0.00203"
"472.57800","39.38169","-0.00228"
"473.05200","39.42121","-0.00245"
"473.52600","39.46074","-0.00215"
"474.00000","39.50013","-0.00202"
"474.47400","39.53971","-0.00235"
"474.94800","39.57912","-0.00227"
"475.42200","39.61863","-0.00203"
"475.89600","39.65821","-0.00143"
"476.37000","39.69774","-0.00229"
"476.84400","39.73720","-0.00191"
"477.31800","39.77672","-0.00151"
"477.79200","39.81618","-0.00129"
"478.26600","39.85564","-0.00210"
"478.74000","39.89511","-0.00161"
"479.21400","39.93468","-0.00083"
"479.68800","39.97421","-0.00159"
"480.16200","40.01372","-0.00129"
"480.63600","40.05319","-0.00102"
"481.11000","40.09271","-0.00091"
"481.58400","40.13223","-0.00095"
"482.05800","40.17175","-0.00127"
"482.53200","40.21115","-0.00068"
"483.00600","40.25061","-0.00119"
"483.48000","40.29013","-0.00154"
"483.95400","40.32971","0.00010"
"484.42800","40.36924","-0.00126"
"484.90200","40.40869","-0.00092"
"485.37600","40.44822","-0.00046"
"485.85000","40.48768","-0.00071"
"486.32400","40.52714","-0.00005"
"486.79800","40.56666","-0.00072"
"487.27200","40.60618","-0.00127"
"487.74600","40.64564","0.00046"
"488.22000","40.68516","-0.00015"
"488.69400","40.72468","-0.00009"
"489.16800","40.76421","-0.00091"
"489.64200","40.80372","-0.00098"
"490.11600","40.84319","-0.00025"
"490.59000","40.88259","-0.00056"
"491.06400","40.92217","0.00001"
"491.53800","40.96169","-0.00060"
"492.01200","41.00121","0.00012"
"492.48600","41.04073","-0.00023"
"492.96000","41.08019","-0.00061"
"493.43400","41.11971","-0.00054"
"493.90800","41.15917","-0.00014"
"494.38200","41.19864","0.00010"
"494.85600","41.23815","-0.00001"
"495.33000","41.27767","0.00015"
"495.80400","41.31714","-0.00058"
"496.27800","41.35672","-0.00036"
"496.75200","41.39618","0.00003"
"497.22600","41.43570","-0.00011"
"497.70000","41.47528","0.00008"
"498.17400","41.51468","0.00038"
"498.64800","41.55408","0.00006"
"499.12200","41.59367","0.00037"
"499.59600","41.63318","0.00041"
"500.07000","41.67270","0.00000"
"500.54400","41.71223","0.00042"
"501.01800","41.75169","0.00049"
"501.49200","41.79115","0.00037"
"501.96600","41.83073","0.00069"
"502.44000","41.87019","0.00119"
"502.91400","41.90965","0.00056"
"503.38800","41.94912","0.00101"
"503.86200","41.98870","0.00017"
"504.33600","42.02821","0.00038"
"504.81000","42.06768","0.00101"
"505.28400","42.10720","0.00070"
"505.75800","42.14672","0.00088"
"506.23200","42.18618","0.00033"
"506.70600","42.22564","0.00110"
"507.18000","42.26522","0.00160"
"507.65400","42.30468","0.00058"
"508.12800","42.34420","0.00121"
"508.60200","42.38372","0.00095"
"509.07600","42.42318","0.00124"
"509.55000","42.46271","0.00091"
"510.02400","42.50217","0.00048"
"510.49800","42.54169","0.00128"
"510.97200","42.58109","0.00152"
"511.44600","42.62067","0.00133"
"511.92000","42.66025","0.00122"
"512.39400","42.69971","0.00128"
"512.86800","42.73917","0.00148"
"513.34200","42.77869","0.00186"
"513.81600","42.81815","0.00154"
"514.29000","42.85762","0.00217"
"514.76400","42.89714","0.00244"
"515.23800","42.93666","0.00159"
"515.71200","42.97624","0.00258"
"516.18600","43.01570","0.00191"
"516.66000","43.05528","0.00221"
"517.13400","43.09474","0.00206"
"517.60800","43.13420","0.00251"
"518.08200","43.17366","0.00230"
"518.55600","43.21313","0.00225"
"519.03000","43.25259","0.00256"
"519.50400","43.29216","0.00186"
"519.97800","43.33169","0.00174"
"520.45200","43.37121","0.00160"
"520.92600","43.41067","0.00205"
"521.40000","43.45019","0.00187"
"521.87400","43.48971","0.00176"
"522.34800","43.52911","0.00155"
"522.82200","43.56869","0.00175"
"523.29600","43.60815","0.00213"
"523.77000","43.64762","0.00153"
"524.24400","43.68719","0.00030"
"524.71800","43.72672","0.00049"
"525.19200","43.76624","0.00128"
"525.66600","43.80564","0.00122"
"526.14000","43.84516","0.00052"
"526.61400","43.88462","-0.00126"
"527.08800","43.92414","-0.00054"
"527.56200","43.96372","-0.00153"
"528.03600","44.00325","-0.00120"
"528.51000","44.04271","-0.00102"
"528.98400","44.08216","-0.00165"
"529.45800","44.12169","-0.00041"
"529.93200","44.16121","-0.00016"
"530.40600","44.20066","-0.00016"
"530.88000","44.24019","-0.00038"
"531.35400","44.27965","-0.00008"
"531.82800","44.31917","-0.00100"
"532.30200","44.35875","-0.00050"
"532.77600","44.39822","-0.00061"
"533.25000","44.43774","-0.00101"
"533.72400","44.47720","-0.00038"
"534.19800","44.51665","-0.00085"
"534.67200","44.55611","-0.00069"
"535.14600","44.59570","-0.00100"
"535.62000","44.63522","0.00029"
"536.09400","44.67474","-0.00038"
"536.56800","44.71414","-0.00050"
"537.04200","44.75372","-0.00093"
"537.51600","44.79319","0.00008"
"537.99000","44.83264","-0.00022"
"538.46400","44.87217","-0.00032"
"538.93800","44.91162","0.00006"
"539.41200","44.95109","0.00056"
"539.88600","44.99073","0.00020"
"540.36000","45.03019","0.00050"
"540.83400","45.06971","0.00155"
"541.30800","45.10923","0.00056"
"541.78200","45.14869","-0.00051"
"542.25600","45.18815","-0.00029"
"542.73000","45.22767","0.00020"
"543.20400","45.26719","-0.00034"
"543.67800","45.30672","-0.00045"
"544.15200","45.34624","0.00009"
"544.62600","45.38570","-0.00007"
"545.10000","45.42516","0.00077"
"545.57400","45.46474","0.00067"
"546.04800","45.50414","0.00037"
"546.52200","45.54366","0.00048"
"546.99600","45.58318","0.00023"
"547.47000","45.62264","0.00043"
"547.94400","45.66222","0.00009"
"548.41800","45.70168","0.00054"
"548.89200","45.74115","0.00061"
"549.36600","45.78073","0.00075"
"549.84000","45.82018","-0.00275"
"550.31400","45.85965","-0.00295"
"550.78800","45.89911","-0.00239"
"551.26200","45.93869","-0.00244"
"551.73600","45.97821","-0.00327"
"552.21000","46.01773","-0.00249"
"552.68400","46.05725","-0.00309"
"553.15800","46.09671","-0.00312"
"553.63200","46.13617","-0.00286"
"554.10600","46.17570","-0.00265"
"554.58000","46.21510","-0.00231"
"555.05400","46.25468","-0.00211"
"555.52800","46.29420","-0.00243"
"556.00200","46.33366","-0.00268"
"556.47600","46.37318","-0.00256"
"556.95000","46.41270","-0.00242"
"557.42400","46.45222","-0.00272"
"557.89800","46.49168","-0.00193"
"558.37200","46.53108","-0.00198"
"558.84600","46.57067","-0.00262"
"559.32000","46.61018","-0.00243"
"559.79400","46.64971","-0.00247"
"560.26800","46.68923","-0.00231"
"560.74200","46.72869","-0.00227"
"561.21600","46.76821","-0.00225"
"561.69000","46.80767","-0.00154"
"562.16400","46.84719","-0.00258"
"562.63800","46.88659","-0.00245"
"563.11200","46.92617","-0.00197"
"563.58600","46.96576","-0.00242"
"564.06000","47.00521","-0.00064"
"564.53400","47.04468","-0.00208"
"565.00800","47.08420","-0.00177"
"565.48200","47.12366","-0.00175"
"565.95600","47.16312","-0.00212"
"566.43000","47.20264","-0.00041"
"566.90400","47.24216","-0.00214"
"567.37800","47.28168","-0.00086"
"567.85200","47.32121","-0.00171"
"568.32600","47.36073","-0.00084"
"568.80000","47.40024","-0.00020"
"569.27400","47.43971","-0.00078"
"569.74800","47.47916","0.00019"
"570.22200","47.51863","-0.00112"
"570.69600","47.55815","0.00098"
"571.17000","47.59767","-0.00078"
"571.64400","47.63719","0.00119"
"572.11800","47.67671","0.00065"
"572.59200","47.71623","0.00131"
"573.06600","47.75576","0.00086"
"573.54000","47.79516","0.00163"
"574.01400","47.83467","0.00117"
"574.48800","47.87413","0.00159"
"574.96200","47.91366","0.00220"
"575.43600","47.95312","0.00237"
"575.91000","47.99276","0.00295"
"576.38400","48.03216","0.00269"
"576.85800","48.07174","0.00368"
"577.33200","48.11120","0.00348"
"577.80600","48.15066","0.00358"
"578.28000","48.19019","0.00339"
"578.75400","48.22964","0.00416"
"579.22800","48.26922","0.00423"
"579.70200","48.30869","0.00413"
"580.17600","48.34821","0.00386"
"580.65000","48.38767","0.00473"
"581.12400","48.42719","0.00413"
"581.59800","48.46671","0.00447"
"582.07200","48.50617","0.00415"
"582.54600","48.54569","0.00499"
"583.02000","48.58509","0.00506"
"583.49400","48.62467","0.00608"
"583.96800","48.66419","0.00534"
"584.44200","48.70366","0.00587"
"584.91600","48.74324","0.00597"
"585.39000","48.78270","0.00599"
"585.86400","48.82216","0.00607"
"586.33800","48.86162","0.00577"
"586.81200","48.90120","0.00595"
"587.28600","48.94067","0.00641"
"587.76000","48.98024","0.00676"
"588.23400","49.01970","0.00717"
"588.70800","49.05922","0.00721"
"589.18200","49.09869","0.00791"
"589.65600","49.13815","0.00817"
"590.13000","49.17773","-0.00224"
"590.60400","49.21713","-0.00083"
"591.07800","49.25665","-0.00127"
"591.55200","49.29623","-0.00049"
"592.02600","49.33569","-0.00136"
"592.50000","49.37515","-0.00122"
"592.97400","49.41473","-0.00128"
"593.44800","49.45420","-0.00065"
"593.92200","49.49366","-0.00088"
"594.39600","49.53312","-0.00044"
"594.87000","49.57270","-0.00079"
"595.34400","49.61216","-0.00113"
"595.81800","49.65168","-0.00020"
"596.29200","49.69126","-0.00058"
"596.76600","49.73066","-0.00004"
"597.24000","49.77018","-0.00039"
"597.71400","49.80965","-0.00076"
"598.18800","49.84917","-0.00018"
"598.66200","49.88869","-0.00002"
"599.13600","49.92815","0.00035"
"599.61000","49.96773","-0.00065"
"600.08400","50.00719","-0.00014"
"600.55800","50.04671","0.00023"
"601.03200","50.08623","0.00017"
"601.50600","50.12569","0.00059"
"601.98000","50.16510","0.00040"
"602.45400","50.20467","0.00030"
"602.92800","50.24420","0.00009"
"603.40200","50.28365","0.00066"
"603.87600","50.32323","0.00086"
"604.35000","50.36276","0.00082"
"604.82400","50.40222","0.00070"
"605.29800","50.44168","-0.00015"
"605.77200","50.48120","-0.00009"
"606.24600","50.52066","0.00115"
"606.72000","50.56018","0.00098"
"607.19400","50.59970","0.00134"
"607.66800","50.63917","0.00089"
"608.14200","50.67868","0.00147"
"608.61600","50.71815","0.00034"
"609.09000","50.75773","0.00110"
"609.56400","50.79719","0.00140"
"610.03800","50.83659","0.00119"
"610.51200","50.87617","0.00065"
"610.98600","50.91569","0.00154"
"611.46000","50.95515","0.00147"
"611.93400","50.99474","0.00127"
"612.40800","51.03419","0.00158"
"612.88200","51.07371","0.00105"
"613.35600","51.11318","0.00118"
"613.83000","51.15263","0.00147"
"614.30400","51.19216","0.00108"
"614.77800","51.23168","0.00183"
"615.25200","51.27120","0.00136"
"615.72600","51.31066","0.00198"
"616.20000","51.35019","0.00148"
"616.67400","51.38971","0.00165"
"617.14800","51.42922","0.00147"
"617.62200","51.46869","0.00201"
"618.09600","51.50808","0.00150"
"618.57000","51.54761","0.00210"
"619.04400","51.58713","0.00159"
"619.51800","51.62671","0.00210"
"619.99200","51.66623","0.00207"
"620.46600","51.70569","0.00169"
"620.94000","51.74516","0.00166"
"621.41400","51.78474","0.00195"
"621.88800","51.82413","0.00188"
"622.36200","51.86366","0.00182"
"622.83600","51.90317","0.00200"
"623.31000","51.94270","0.00162"
"623.78400","51.98216","0.00136"
"624.25800","52.02174","0.00102"
"624.73200","52.06126","0.00112"
"625.20600","52.10066","0.00130"
"625.68000","52.14018","0.00157"
"626.15400","52.17964","0.00106"
"626.62800","52.21916","0.00096"
"627.10200","52.25869","0.00073"
"627.57600","52.29820","0.00100"
"628.05000","52.33773","0.00080"
"628.52400","52.37719","0.00053"
"628.99800","52.41671","0.00083"
"629.47200","52.45617","-0.00019"
"629.94600","52.49569","0.00036"
"630.42000","52.53521","-0.00047"
"630.89400","52.57467","-0.00062"
"631.36800","52.61419","0.00050"
"631.84200","52.65371","0.00061"
"632.31600","52.69323","0.00044"
"632.79000","52.73270","-0.00041"
"633.26400","52.77222","0.00051"
"633.73800","52.81168","-0.00070"
"634.21200","52.85114","0.00012"
"634.68600","52.89072","-0.00013"
"635.16000","52.93024","-0.00016"
"635.63400","52.96970","0.00018"
"636.10800","53.00922","0.00021"
"636.58200","53.04869","0.00049"
"637.05600","53.08820","0.00057"
"637.53000","53.12772","0.00004"
"638.00400","53.16712","-0.00002"
"638.47800","53.20665","-0.00036"
"638.95200","53.24617","0.00047"
"639.42600","53.28569","0.00035"
"639.90000","53.32521","0.00034"
"640.37400","53.36473","0.00062"
"640.84800","53.40419","0.00073"
"641.32200","53.44365","0.00088"
"641.79600","53.48317","0.00148"
"642.27000","53.52269","0.00105"
"642.74400","53.56215","0.00146"
"643.21800","53.60173","0.00035"
"643.69200","53.64120","0.00162"
"644.16600","53.68066","0.00172"
"644.64000","53.72024","0.00145"
"645.11400","53.75970","0.00123"
"645.58800","53.79910","0.00217"
"646.06200","53.83862","0.00147"
"646.53600","53.87814","0.00215"
"647.01000","53.91766","0.00151"
"647.48400","53.95718","0.00230"
"647.95800","53.99677","0.00269"
"648.43200","54.03616","0.00232"
"648.90600","54.07568","0.00244"
"649.38000","54.11521","0.00258"
"649.85400","54.15467","0.00264"
"650.32800","54.19419","0.00163"
"650.80200","54.23365","-0.00026"
"651.27600","54.27317","0.00060"
"651.75000","54.31269","0.00030"
"652.22400","54.35221","0.00050"
"652.69800","54.39174","0.00073"
"653.17200","54.43119","-0.00021"
"653.64600","54.47065","0.00087"
"654.12000","54.51012","0.00112"
"654.59400","54.54964","0.00094"
"655.06800","54.58916","0.00100"
"655.54200","54.62874","0.00152"
"656.01600","54.66820","0.00104"
"656.49000","54.70766","0.00158"
"656.96400","54.74718","0.00162"
"657.43800","54.78671","0.00168"
"657.91200","54.82616","0.00152"
"658.38600","54.86568","0.00171"
"658.86000","54.90521","0.00205"
"659.33400","54.94467","0.00172"
"659.80800","54.98418","0.00225"
"660.28200","55.02371","0.00225"
"660.75600","55.06323","0.00263"
"661.23000","55.10269","0.00284"
"661.70400","55.14216","0.00265"
"662.17800","55.18161","0.00242"
"662.65200","55.22113","0.00315"
"663.12600","55.26072","0.00331"
"663.60000","55.30018","0.00398"
"664.07400","55.33970","0.00335"
"664.54800","55.37922","0.00368"
"665.02200","55.41874","0.00378"
"665.49600","55.45820","0.00366"
"665.97000","55.49760","0.00415"
"666.44400","55.53719","0.00423"
"666.91800","55.57671","0.00451"
"667.39200","55.61616","0.00426"
"667.86600","55.65569","0.00379"
"668.34000","55.69521","0.00385"
"668.81400","55.73466","0.00443"
"669.28800","55.77419","0.00455"
"669.76200","55.81365","0.00441"
"670.23600","55.85317","0.00417"
"670.71000","55.89269","0.00447"
"671.18400","55.93221","0.00490"
"671.65800","55.97173","0.00454"
"672.13200","56.01119","0.00457"
"672.60600","56.05072","0.00510"
"673.08000","56.09018","0.00468"
"673.55400","56.12969","0.00466"
"674.02800","56.16916","0.00474"
"674.50200","56.20868","0.00461"
"674.97600","56.24820","0.00518"
"675.45000","56.28767","0.00516"
"675.92400","56.32724","0.00503"
"676.39800","56.36676","0.00548"
"676.87200","56.40617","0.00480"
"677.34600","56.44569","0.00492"
"677.82000","56.48514","0.00494"
"678.29400","56.52467","0.00494"
"678.76800","56.56419","0.00586"
"679.24200","56.60371","0.00643"
"679.71600","56.64317","0.00543"
"680.19000","56.68269","0.00601"
"680.66400","56.72221","0.00613"
"681.13800","56.76167","0.00623"
"681.61200","56.80114","0.00650"
"682.08600","56.84066","0.00642"
"682.56000","56.88017","0.00673"
"683.03400","56.91970","0.00682"
"683.50800","56.95916","0.00644"
"683.98200","56.99874","0.00685"
"684.45600","57.03820","0.00687"
"684.93000","57.07766","0.00719"
"685.40400","57.11718","0.00719"
"685.87800","57.15670","0.00746"
"686.35200","57.19622","0.00646"
"686.82600","57.23575","0.00680"
"687.30000","57.27520","0.00727"
"687.77400","57.31467","0.00747"
"688.24800","57.35425","0.00759"
"688.72200","57.39371","0.00795"
"689.19600","57.43317","0.00782"
"689.67000","57.47263","0.00736"
"690.14400","57.51215","0.00778"
"690.61800","57.55167","0.00781"
"691.09200","57.59120","0.00816"
"691.56600","57.63065","0.00828"
"692.04000","57.67018","0.00880"
"692.51400","57.70970","0.00850"
"692.98800","57.74916","0.00882"
"693.46200","57.78868","0.00786"
"693.93600","57.82814","0.00832"
"694.41000","57.86766","0.00850"
"694.88400","57.90724","0.00867"
"695.35800","57.94670","0.00949"
"695.83200","57.98616","0.00899"
"696.30600","58.02574","0.00952"
"696.78000","58.06520","0.00923"
"697.25400","58.10460","0.00962"
"697.72800","58.14413","0.00923"
"698.20200","58.18365","0.00909"
"698.67600","58.22317","0.00906"
"699.15000","58.26269","0.00922"
"699.62400","58.30221","0.00931"
"700.09800","58.34167","0.00998"
"700.57200","58.38119","0.00968"
"701.04600","58.42071","0.00978"
"701.52000","58.46017","0.01012"
"701.99400","58.49976","0.01049"
"702.46800","58.53915","0.01063"
"702.94200","58.57868","0.01047"
"703.41600","58.61826","0.01037"
"703.89000","58.65772","0.01097"
"704.26600","58.68899","0.01086"