File: Force_trajectories/170225_1/Specimen_RawData_3.csv
End date,"2/25/2017"
Specimen label,"2AT_13"
Maximum Load,"0.10934",N

Time,Extension,Load
(s),(mm),(N)
"0.00000","0.00000","-0.00030"
"0.31200","0.02559","0.00025"
"0.62400","0.05226","0.00045"
"0.93600","0.07820","0.00062"
"1.24800","0.10427","0.00096"
"1.56000","0.13028","0.00136"
"1.87200","0.15617","0.00113"
"2.18400","0.18224","0.00149"
"2.49600","0.20819","0.00266"
"2.80800","0.23420","0.00125"
"3.12000","0.26020","0.00236"
"3.43200","0.28621","0.00236"
"3.74400","0.31222","0.00221"
"4.05600","0.33817","0.00236"
"4.36800","0.36424","0.00268"
"4.68000","0.39019","0.00276"
"4.99200","0.41619","0.00279"
"5.30400","0.44226","0.00243"
"5.61600","0.46821","0.00302"
"5.92800","0.49416","0.00307"
"6.24000","0.52011","0.00297"
"6.55200","0.54624","0.00355"
"6.86400","0.57225","0.00343"
"7.17600","0.59825","0.00323"
"7.48800","0.62426","0.00395"
"7.80000","0.65021","0.00368"
"8.11200","0.67622","0.00414"
"8.42400","0.70217","0.00481"
"8.73600","0.72830","0.00412"
"9.04800","0.75424","0.00474"
"9.36000","0.78019","0.00513"
"9.67200","0.80620","0.00452"
"9.98400","0.83221","0.00445"
"10.29600","0.85822","0.00499"
"10.60800","0.88423","0.00443"
"10.92000","0.91024","0.00464"
"11.23200","0.93618","0.00488"
"11.54400","0.96219","0.00510"
"11.85600","0.98820","0.00501"
"12.16800","1.01421","0.00510"
"12.48000","1.04022","0.00533"
"12.79200","1.06617","0.00528"
"13.10400","1.09218","0.00586"
"13.41600","1.11818","0.00577"
"13.72800","1.14419","0.00543"
"14.04000","1.17020","0.00592"
"14.35200","1.19621","0.00630"
"14.66400","1.22222","0.00606"
"14.97600","1.24823","0.00594"
"15.28800","1.27423","0.00615"
"15.60000","1.30024","0.00624"
"15.91200","1.32613","0.00651"
"16.22400","1.35226","0.00625"
"16.53600","1.37821","0.00695"
"16.84800","1.40416","0.00677"
"17.16000","1.43023","0.00670"
"17.47200","1.45617","0.00649"
"17.78400","1.48224","0.00739"
"18.09600","1.50819","0.00696"
"18.40800","1.53426","0.00705"
"18.72000","1.56021","0.00727"
"19.03200","1.58622","0.00739"
"19.34400","1.61228","0.00755"
"19.65600","1.63823","0.00656"
"19.96800","1.66424","0.00762"
"20.28000","1.69013","0.00722"
"20.59200","1.71620","0.00775"
"20.90400","1.74221","0.00732"
"21.21600","1.76822","0.00708"
"21.52800","1.79422","0.00769"
"21.84000","1.82017","0.00720"
"22.15200","1.84624","0.00790"
"22.46400","1.87219","0.00776"
"22.77600","1.89826","0.00765"
"23.08800","1.92427","0.00799"
"23.40000","1.95022","0.00772"
"23.71200","1.97622","0.00787"
"24.02400","2.00211","0.00787"
"24.33600","2.02824","0.00806"
"24.64800","2.05425","0.00768"
"24.96000","2.08026","0.00779"
"25.27200","2.10627","0.00824"
"25.58400","2.13215","0.00804"
"25.89600","2.15822","0.00782"
"26.20800","2.18417","0.00809"
"26.52000","2.21030","0.00793"
"26.83200","2.23619","0.00831"
"27.14400","2.26220","0.00643"
"27.45600","2.28821","0.00684"
"27.76800","2.31415","0.00766"
"28.08000","2.34022","0.00692"
"28.39200","2.36623","0.00722"
"28.70400","2.39224","0.00693"
"29.01600","2.41819","0.00697"
"29.32800","2.44420","0.00745"
"29.64000","2.47020","0.00784"
"29.95200","2.49621","0.00771"
"30.26400","2.52228","0.00717"
"30.57600","2.54823","0.00686"
"30.88800","2.57424","0.00735"
"31.20000","2.60025","0.00759"
"31.51200","2.62614","0.00765"
"31.82400","2.65226","0.00784"
"32.13600","2.67821","0.00717"
"32.44800","2.70422","0.00776"
"32.76000","2.73023","0.00738"
"33.07200","2.75624","0.00768"
"33.38400","2.78225","0.00768"
"33.69600","2.80819","0.00752"
"34.00800","2.83426","0.00770"
"34.32000","2.86021","0.00714"
"34.63200","2.88622","0.00740"
"34.94400","2.91223","0.00728"
"35.25600","2.93818","0.00704"
"35.56800","2.96431","0.00702"
"35.88000","2.99019","0.00751"
"36.19200","3.01626","0.00721"
"36.50400","3.04221","0.00746"
"36.81600","3.06816","0.00764"
"37.12800","3.09429","0.00703"
"37.44000","3.12024","0.00671"
"37.75200","3.14630","0.00736"
"38.06400","3.17219","0.00704"
"38.37600","3.19820","0.00694"
"38.68800","3.22421","0.00699"
"39.00000","3.25022","0.00705"
"39.31200","3.27623","0.00712"
"39.62400","3.30218","0.00709"
"39.93600","3.32824","0.00610"
"40.24800","3.35425","0.00649"
"40.56000","3.38020","0.00612"
"40.87200","3.40627","0.00665"
"41.18400","3.43216","0.00651"
"41.49600","3.45823","0.00692"
"41.80800","3.48412","0.00692"
"42.12000","3.51024","0.00713"
"42.43200","3.53619","0.00667"
"42.74400","3.56220","0.00719"
"43.05600","3.58821","0.00696"
"43.36800","3.61416","0.00679"
"43.68000","3.64029","0.00662"
"43.99200","3.66617","0.00762"
"44.30400","3.69224","0.00652"
"44.61600","3.71825","0.00713"
"44.92800","3.74414","0.00749"
"45.24000","3.77021","0.00724"
"45.55200","3.79616","0.00716"
"45.86400","3.82223","0.00689"
"46.17600","3.84823","0.00746"
"46.48800","3.87418","0.00702"
"46.80000","3.90025","0.00739"
"47.11200","3.92614","0.00757"
"47.42400","3.95227","0.00688"
"47.73600","3.97822","0.00640"
"48.04800","4.00428","0.00723"
"48.36000","4.03029","0.00692"
"48.67200","4.05618","0.00647"
"48.98400","4.08219","0.00635"
"49.29600","4.10814","0.00648"
"49.60800","4.13427","0.00591"
"49.92000","4.16027","0.00631"
"50.23200","4.18622","0.00601"
"50.54400","4.21229","0.00649"
"50.85600","4.23818","0.00674"
"51.16800","4.26419","0.00617"
"51.48000","4.29020","0.00625"
"51.79200","4.31627","0.00625"
"52.10400","4.34227","0.00572"
"52.41600","4.36822","0.00659"
"52.72800","4.39417","0.00628"
"53.04000","4.42018","0.00717"
"53.35200","4.44625","0.00630"
"53.66400","4.47220","0.00646"
"53.97600","4.49821","0.00662"
"54.28800","4.52421","0.00714"
"54.60000","4.55016","0.00659"
"54.91200","4.57623","0.00664"
"55.22400","4.60218","0.00671"
"55.53600","4.62825","0.00666"
"55.84800","4.65420","0.00700"
"56.16000","4.68015","0.00658"
"56.47200","4.70621","0.00739"
"56.78400","4.73216","0.00709"
"57.09600","4.75823","0.00690"
"57.40800","4.78418","0.00675"
"57.72000","4.81019","0.00730"
"58.03200","4.83626","0.00711"
"58.34400","4.86220","0.00706"
"58.65600","4.88827","0.00706"
"58.96800","4.91416","0.00681"
"59.28000","4.94023","0.00722"
"59.59200","4.96624","0.00730"
"59.90400","4.99219","0.00752"
"60.21600","5.01819","0.00770"
"60.52800","5.04420","0.00774"
"60.84000","5.07027","0.00727"
"61.15200","5.09622","0.00711"
"61.46400","5.12229","0.00769"
"61.77600","5.14824","0.00763"
"62.08800","5.17419","0.00714"
"62.40000","5.20025","0.00730"
"62.71200","5.22620","0.00742"
"63.02400","5.25227","0.00750"
"63.33600","5.27822","0.00718"
"63.64800","5.30423","0.00765"
"63.96000","5.33024","0.00655"
"64.27200","5.35619","0.00663"
"64.58400","5.38219","0.00736"
"64.89600","5.40814","0.00705"
"65.20800","5.43421","0.00700"
"65.52000","5.46022","0.00713"
"65.83200","5.48629","0.00746"
"66.14400","5.51230","0.00731"
"66.45600","5.53818","0.00687"
"66.76800","5.56425","0.00774"
"67.08000","5.59014","0.00780"
"67.39200","5.61621","0.00769"
"67.70400","5.64228","0.00761"
"68.01600","5.66823","0.00770"
"68.32800","5.69424","0.00790"
"68.64000","5.72012","0.00780"
"68.95200","5.74625","0.00761"
"69.26400","5.77220","0.00766"
"69.57600","5.79821","0.00791"
"69.88800","5.82422","0.00784"
"70.20000","5.85017","0.00836"
"70.51200","5.87624","0.00726"
"70.82400","5.90218","0.00796"
"71.13600","5.92825","0.00745"
"71.44800","5.95426","0.00782"
"71.76000","5.98021","0.00807"
"72.07200","6.00622","0.00805"
"72.38400","6.03217","0.00796"
"72.69600","6.05823","0.00830"
"73.00800","6.08424","0.00793"
"73.32000","6.11025","0.00843"
"73.63200","6.13620","0.00842"
"73.94400","6.16221","0.00821"
"74.25600","6.18822","0.00849"
"74.56800","6.21417","0.00864"
"74.88000","6.24023","0.00858"
"75.19200","6.26618","0.00873"
"75.50400","6.29225","0.00901"
"75.81600","6.31826","0.00860"
"76.12800","6.34421","0.00870"
"76.44000","6.37028","0.00900"
"76.75200","6.39616","0.00838"
"77.06400","6.42223","0.00868"
"77.37600","6.44824","0.00818"
"77.68800","6.47419","0.00888"
"78.00000","6.50020","0.00860"
"78.31200","6.52621","0.00845"
"78.62400","6.55228","0.00931"
"78.93600","6.57822","0.00888"
"79.24800","6.60423","0.00921"
"79.56000","6.63024","0.00828"
"79.87200","6.65619","0.00829"
"80.18400","6.68220","0.00882"
"80.49600","6.70815","0.00767"
"80.80800","6.73427","0.00740"
"81.12000","6.76016","0.00814"
"81.43200","6.78617","0.00832"
"81.74400","6.81224","0.00819"
"82.05600","6.83819","0.00816"
"82.36800","6.86420","0.00805"
"82.68000","6.89021","0.00863"
"82.99200","6.91621","0.00817"
"83.30400","6.94222","0.00879"
"83.61600","6.96823","0.00898"
"83.92800","6.99424","0.00913"
"84.24000","7.02019","0.00891"
"84.55200","7.04620","0.00915"
"84.86400","7.07214","0.00939"
"85.17600","7.09821","0.00938"
"85.48800","7.12422","0.00973"
"85.80000","7.15023","0.00944"
"86.11200","7.17624","0.00882"
"86.42400","7.20213","0.00892"
"86.73600","7.22826","0.00934"
"87.04800","7.25420","0.00966"
"87.36000","7.28027","0.00973"
"87.67200","7.30622","0.00978"
"87.98400","7.33217","0.01035"
"88.29600","7.35824","0.00993"
"88.60800","7.38413","0.01080"
"88.92000","7.41025","0.01004"
"89.23200","7.43626","0.01031"
"89.54400","7.46221","0.01048"
"89.85600","7.48822","0.01018"
"90.16800","7.51423","0.01082"
"90.48000","7.54024","0.01103"
"90.79200","7.56625","0.01099"
"91.10400","7.59225","0.01147"
"91.41600","7.61826","0.01121"
"91.72800","7.64421","0.01049"
"92.04000","7.67022","0.01082"
"92.35200","7.69611","0.01104"
"92.66400","7.72224","0.01122"
"92.97600","7.74825","0.01185"
"93.28800","7.77425","0.01132"
"93.60000","7.80026","0.01205"
"93.91200","7.82621","0.01246"
"94.22400","7.85222","0.01249"
"94.53600","7.87823","0.01268"
"94.84800","7.90424","0.01322"
"95.16000","7.93024","0.01334"
"95.47200","7.95625","0.01346"
"95.78400","7.98220","0.01437"
"96.09600","8.00815","0.01397"
"96.40800","8.03428","0.01388"
"96.72000","8.06023","0.01541"
"97.03200","8.08624","0.01550"
"97.34400","8.11218","0.01596"
"97.65600","8.13819","0.01663"
"97.96800","8.16426","0.01675"
"98.28000","8.19021","0.01763"
"98.59200","8.21616","0.01818"
"98.90400","8.24217","0.01851"
"99.21600","8.26818","0.01934"
"99.52800","8.29424","0.01985"
"99.84000","8.32019","0.02036"
"100.15200","8.34626","0.01901"
"100.46400","8.37221","0.02121"
"100.77600","8.39816","0.02109"
"101.08800","8.42422","0.02168"
"101.40000","8.45017","0.02281"
"101.71200","8.47630","0.02470"
"102.02400","8.50219","0.02455"
"102.33600","8.52826","0.02522"
"102.64800","8.55421","0.02658"
"102.96000","8.58022","0.02764"
"103.27200","8.60623","0.02915"
"103.58400","8.63217","0.02957"
"103.89600","8.65824","0.03097"
"104.20800","8.68419","0.03141"
"104.52000","8.71026","0.03259"
"104.83200","8.73621","0.03320"
"105.14400","8.76222","0.03492"
"105.45600","8.78828","0.03594"
"105.76800","8.81417","0.03735"
"106.08000","8.84024","0.03759"
"106.39200","8.86619","0.03903"
"106.70400","8.89220","0.03928"
"107.01600","8.91821","0.04053"
"107.32800","8.94421","0.04056"
"107.64000","8.97022","0.04017"
"107.95200","8.99617","0.03896"
"108.26400","9.02224","0.04010"
"108.57600","9.04819","0.04155"
"108.88800","9.07426","0.04247"
"109.20000","9.10027","0.04290"
"109.51200","9.12621","0.04360"
"109.82400","9.15222","0.04409"
"110.13600","9.17817","0.04422"
"110.44800","9.20424","0.04477"
"110.76000","9.23025","0.04561"
"111.07200","9.25620","0.04578"
"111.38400","9.28226","0.04620"
"111.69600","9.30815","0.04662"
"112.00800","9.33422","0.04703"
"112.32000","9.36023","0.04788"
"112.63200","9.38624","0.04783"
"112.94400","9.41219","0.04841"
"113.25600","9.43814","0.04864"
"113.56800","9.46414","0.04580"
"113.88000","9.49015","0.04607"
"114.19200","9.51628","0.04623"
"114.50400","9.54223","0.04747"
"114.81600","9.56824","0.04798"
"115.12800","9.59425","0.04854"
"115.44000","9.62014","0.04868"
"115.75200","9.64620","0.04926"
"116.06400","9.67221","0.05004"
"116.37600","9.69822","0.05020"
"116.68800","9.72423","0.05050"
"117.00000","9.75024","0.05153"
"117.31200","9.77625","0.05181"
"117.62400","9.80219","0.05258"
"117.93600","9.82820","0.05283"
"118.24800","9.85421","0.05165"
"118.56000","9.88022","0.05014"
"118.87200","9.90629","0.05181"
"119.18400","9.93218","0.05070"
"119.49600","9.95831","0.05264"
"119.80800","9.98419","0.05251"
"120.12000","10.01026","0.05254"
"120.43200","10.03621","0.05416"
"120.74400","10.06216","0.05420"
"121.05600","10.08823","0.05594"
"121.36800","10.11418","0.05551"
"121.68000","10.14031","0.05754"
"121.99200","10.16619","0.05805"
"122.30400","10.19220","0.05823"
"122.61600","10.21821","0.06129"
"122.92800","10.24422","0.06041"
"123.24000","10.27023","0.06302"
"123.55200","10.29618","0.06324"
"123.86400","10.32230","0.06443"
"124.17600","10.34825","0.06629"
"124.48800","10.37420","0.06621"
"124.80000","10.40027","0.06918"
"125.11200","10.42622","0.06895"
"125.42400","10.45223","0.07002"
"125.73600","10.47818","0.07143"
"126.04800","10.50418","0.07217"
"126.36000","10.53025","0.07335"
"126.67200","10.55620","0.07386"
"126.98400","10.58227","0.07520"
"127.29600","10.60816","0.07653"
"127.60800","10.63423","0.07624"
"127.92000","10.66018","0.07821"
"128.23200","10.68618","0.07813"
"128.54400","10.71225","0.07949"
"128.85600","10.73820","0.08068"
"129.16800","10.76421","0.08153"
"129.48000","10.79016","0.08372"
"129.79200","10.81623","0.08441"
"130.10400","10.84217","0.08546"
"130.41600","10.86824","0.08741"
"130.72800","10.89425","0.08843"
"131.04000","10.92014","0.08913"
"131.35200","10.94627","0.09066"
"131.66400","10.97222","0.09109"
"131.97600","10.99823","0.09271"
"132.28800","11.02423","0.09328"
"132.60000","11.05024","0.09353"
"132.91200","11.07619","0.09426"
"133.22400","11.10214","0.09472"
"133.53600","11.12821","0.09536"
"133.84800","11.15422","0.09548"
"134.16000","11.18022","0.09588"
"134.47200","11.20623","0.09627"
"134.78400","11.23218","0.09689"
"135.09600","11.25819","0.09769"
"135.40800","11.28414","0.09805"
"135.72000","11.31021","0.09900"
"136.03200","11.33622","0.09906"
"136.34400","11.36222","0.10018"
"136.65600","11.38823","0.10149"
"136.96800","11.41418","0.10272"
"137.28000","11.44019","0.10374"
"137.59200","11.46620","0.10582"
"137.90400","11.49227","0.10662"
"138.21600","11.51827","0.10807"
"138.52800","11.54416","0.10825"
"138.84000","11.57017","0.10879"
"139.15200","11.59618","0.10881"
"139.46400","11.62225","0.10787"
"139.77600","11.64820","0.00144"
"140.08800","11.67420","0.00338"
"140.40000","11.70021","0.00011"
"140.71200","11.72616","0.00079"
"141.02400","11.75223","0.00104"
"141.33600","11.77824","0.00050"
"141.64800","11.80419","0.00133"
"141.96000","11.83020","0.00248"
"142.27200","11.85614","0.00197"
"142.58400","11.88221","0.00193"
"142.89600","11.90816","0.00207"
"143.20800","11.93423","0.00194"
"143.52000","11.96018","0.00139"
"143.83200","11.98619","0.00248"
"144.14400","12.01225","0.00159"
"144.45600","12.03821","0.00179"
"144.76800","12.06427","0.00204"
"145.08000","12.09016","0.00152"
"145.39200","12.11623","0.00186"
"145.70400","12.14218","0.00248"
"146.01600","12.16819","0.00166"
"146.32800","12.19425","0.00217"
"146.64000","12.22014","0.00218"
"146.95200","12.24621","0.00172"
"147.26400","12.27222","0.00220"
"147.57600","12.29829","0.00226"
"147.88800","12.32424","0.00172"
"148.20000","12.35025","0.00253"
"148.51200","12.37625","0.00265"
"148.82400","12.40220","0.00293"
"149.13600","12.42821","0.00247"
"149.44800","12.45416","0.00240"
"149.76000","12.48023","0.00253"
"150.07200","12.50630","0.00261"
"150.38400","12.53218","0.00185"
"150.69600","12.55819","0.00155"
"151.00800","12.58420","0.00250"
"151.32000","12.61021","0.00202"
"151.63200","12.63622","0.00181"
"151.94400","12.66223","0.00273"
"152.25600","12.68824","0.00195"
"152.56800","12.71424","0.00189"
"152.88000","12.74025","0.00217"
"153.19200","12.76620","0.00257"
"153.50400","12.79227","0.00206"
"153.81600","12.81828","0.00184"
"154.12800","12.84423","0.00249"
"154.44000","12.87024","0.00278"
"154.75200","12.89618","0.00266"
"155.06400","12.92225","0.00308"
"155.37600","12.94826","0.00235"
"155.68800","12.97421","0.00200"
"156.00000","13.00022","0.00246"
"156.31200","13.02623","0.00224"
"156.62400","13.05217","0.00263"
"156.93600","13.07812","0.00275"
"157.24800","13.10425","0.00315"
"157.56000","13.13026","0.00267"
"157.87200","13.15621","0.00274"
"158.18400","13.18222","0.00276"
"158.49600","13.20817","0.00230"
"158.80800","13.23423","0.00240"
"159.12000","13.26024","0.00278"
"159.43200","13.28625","0.00252"
"159.74400","13.31220","0.00254"
"160.05600","13.33821","0.00293"
"160.36800","13.36422","0.00348"
"160.68000","13.39016","0.00268"
"160.99200","13.41623","0.00274"
"161.30400","13.44224","0.00283"
"161.61600","13.46819","0.00255"
"161.92800","13.49426","0.00215"
"162.24000","13.52021","0.00348"
"162.55200","13.54628","0.00335"
"162.86400","13.57222","0.00290"
"163.17600","13.59823","0.00318"
"163.48800","13.62418","0.00280"
"163.80000","13.65019","0.00294"
"164.11200","13.67620","0.00289"
"164.42400","13.70221","0.00368"
"164.73600","13.72827","0.00311"
"165.04800","13.75422","0.00237"
"165.36000","13.78023","0.00299"
"165.67200","13.80624","0.00251"
"165.98400","13.83219","0.00292"
"166.29600","13.85826","0.00364"
"166.60800","13.88421","0.00281"
"166.92000","13.91022","0.00325"
"167.23200","13.93622","0.00241"
"167.54400","13.96217","0.00359"
"167.85600","13.98824","0.00331"
"168.16800","14.01419","0.00300"
"168.48000","14.04026","0.00347"
"168.79200","14.06615","0.00355"
"169.10400","14.09221","0.00338"
"169.41600","14.11822","0.00343"
"169.72800","14.14417","0.00352"
"170.04000","14.17024","0.00282"
"170.35200","14.19613","0.00344"
"170.66400","14.22220","0.00370"
"170.97600","14.24815","0.00408"
"171.28800","14.27421","0.00411"
"171.60000","14.30022","0.00338"
"171.91200","14.32617","0.00379"
"172.22400","14.35218","0.00323"
"172.53600","14.37813","0.00312"
"172.84800","14.40425","0.00356"
"173.16000","14.43020","0.00321"
"173.47200","14.45621","0.00376"
"173.78400","14.48222","0.00345"
"174.09600","14.50811","0.00402"
"174.40800","14.53418","0.00367"
"174.72000","14.56019","0.00380"
"175.03200","14.58625","0.00397"
"175.34400","14.61220","0.00360"
"175.65600","14.63821","0.00361"
"175.96800","14.66428","0.00462"
"176.28000","14.69017","0.00408"
"176.59200","14.71624","0.00365"
"176.90400","14.74224","0.00365"
"177.21600","14.76820","0.00373"
"177.52800","14.79426","0.00353"
"177.84000","14.82021","0.00395"
"178.15200","14.84622","0.00418"
"178.46400","14.87217","0.00407"
"178.77600","14.89830","0.00377"
"179.08800","14.92418","0.00409"
"179.40000","14.95019","0.00381"
"179.71200","14.97626","0.00420"
"180.02400","15.00215","0.00385"
"180.33600","15.02822","0.00403"
"180.64800","15.05417","0.00381"
"180.96000","15.08024","0.00371"
"181.27200","15.10624","0.00352"
"181.58400","15.13219","0.00304"
"181.89600","15.15820","0.00280"
"182.20800","15.18421","0.00297"
"182.52000","15.21028","0.00325"
"182.83200","15.23623","0.00308"
"183.14400","15.26223","0.00343"
"183.45600","15.28824","0.00240"
"183.76800","15.31419","0.00263"
"184.08000","15.34026","0.00256"
"184.39200","15.36621","0.00268"
"184.70400","15.39216","0.00325"
"185.01600","15.41823","0.00284"
"185.32800","15.44417","0.00250"
"185.64000","15.47024","0.00311"
"185.95200","15.49619","0.00322"
"186.26400","15.52232","0.00362"
"186.57600","15.54821","0.00339"
"186.88800","15.57416","0.00240"
"187.20000","15.60023","0.00283"
"187.51200","15.62623","0.00337"
"187.82400","15.65230","0.00342"
"188.13600","15.67813","0.00367"
"188.44800","15.70426","0.00364"
"188.76000","15.73021","0.00322"
"189.07200","15.75622","0.00270"
"189.38400","15.78222","0.00403"
"189.69600","15.80817","0.00304"
"190.00800","15.83424","0.00312"
"190.32000","15.86019","0.00280"
"190.63200","15.88626","0.00315"
"190.94400","15.91221","0.00327"
"191.25600","15.93822","0.00305"
"191.56800","15.96422","0.00284"
"191.88000","15.99017","0.00287"
"192.19200","16.01624","0.00344"
"192.50400","16.04219","0.00378"
"192.81600","16.06820","0.00324"
"193.12800","16.09426","0.00368"
"193.44000","16.12021","0.00282"
"193.75200","16.14622","0.00326"
"194.06400","16.17217","0.00311"
"194.37600","16.19824","0.00318"
"194.68800","16.22425","0.00330"
"195.00000","16.25026","0.00360"
"195.31200","16.27626","0.00336"
"195.62400","16.30221","0.00267"
"195.93600","16.32828","0.00314"
"196.24800","16.35417","0.00291"
"196.56000","16.38024","0.00318"
"196.87200","16.40625","0.00338"
"197.18400","16.43220","0.00313"
"197.49600","16.45820","0.00360"
"197.80800","16.48415","0.00300"
"198.12000","16.51028","0.00279"
"198.43200","16.53623","0.00317"
"198.74400","16.56224","0.00347"
"199.05600","16.58819","0.00270"
"199.36800","16.61419","0.00260"
"199.68000","16.64021","0.00275"
"199.99200","16.66615","0.00347"
"200.30400","16.69222","0.00292"
"200.61600","16.71823","0.00309"
"200.92800","16.74418","0.00314"
"201.24000","16.77024","0.00305"
"201.55200","16.79620","0.00282"
"201.86400","16.82220","0.00310"
"202.17600","16.84821","0.00384"
"202.48800","16.87422","0.00264"
"202.80000","16.90017","0.00339"
"203.11200","16.92612","0.00327"
"203.42400","16.95225","0.00354"
"203.73600","16.97820","0.00293"
"204.04800","17.00420","0.00283"
"204.36000","17.03021","0.00335"
"204.67200","17.05622","0.00283"
"204.98400","17.08223","0.00343"
"205.29600","17.10818","0.00258"
"205.60800","17.13424","0.00284"
"205.92000","17.16019","0.00306"
"206.23200","17.18620","0.00353"
"206.54400","17.21221","0.00307"
"206.85600","17.23822","0.00238"
"207.16800","17.26423","0.00278"
"207.48000","17.29018","0.00353"
"207.79200","17.31624","0.00232"
"208.10400","17.34219","0.00272"
"208.41600","17.36820","0.00316"
"208.72800","17.39427","0.00337"
"209.04000","17.42022","0.00304"
"209.35200","17.44623","0.00263"
"209.66400","17.47218","0.00322"
"209.97600","17.49824","0.00315"
"210.28800","17.52419","0.00336"
"210.60000","17.55020","0.00284"
"210.91200","17.57627","0.00329"
"211.22400","17.60222","0.00307"
"211.53600","17.62829","0.00289"
"211.84800","17.65423","0.00286"
"212.16000","17.68024","0.00341"
"212.47200","17.70625","0.00301"
"212.78400","17.73220","0.00286"
"213.09600","17.75827","0.00359"
"213.40800","17.78416","0.00342"
"213.72000","17.81023","0.00359"
"214.03200","17.83617","0.00337"
"214.34400","17.86224","0.00320"
"214.65600","17.88831","0.00320"
"214.96800","17.91420","0.00350"
"215.28000","17.94021","0.00328"
"215.59200","17.96616","0.00323"
"215.90400","17.99222","0.00404"
"216.21600","18.01823","0.00361"
"216.52800","18.04424","0.00326"
"216.84000","18.07019","0.00332"
"217.15200","18.09614","0.00330"
"217.46400","18.12227","0.00376"
"217.77600","18.14822","0.00345"
"218.08800","18.17422","0.00333"
"218.40000","18.20023","0.00344"
"218.71200","18.22618","0.00358"
"219.02400","18.25225","0.00340"
"219.33600","18.27820","0.00371"
"219.64800","18.30427","0.00390"
"219.96000","18.33022","0.00345"
"220.27200","18.35622","0.00398"
"220.58400","18.38223","0.00356"
"220.89600","18.40818","0.00319"
"221.20800","18.43425","0.00353"
"221.52000","18.46020","0.00345"
"221.83200","18.48627","0.00362"
"222.14400","18.51221","0.00372"
"222.45600","18.53816","0.00307"
"222.76800","18.56423","0.00366"
"223.08000","18.59018","0.00329"
"223.39200","18.61625","0.00405"
"223.70400","18.64220","0.00420"
"224.01600","18.66827","0.00359"
"224.32800","18.69427","0.00367"
"224.64000","18.72022","0.00354"
"224.95200","18.74617","0.00394"
"225.26400","18.77218","0.00400"
"225.57600","18.79825","0.00329"
"225.88800","18.82420","0.00375"
"226.20000","18.85021","0.00369"
"226.51200","18.87627","0.00395"
"226.82400","18.90222","0.00362"
"227.13600","18.92823","0.00372"
"227.44800","18.95418","0.00368"
"227.76000","18.98019","0.00387"
"228.07200","19.00620","0.00398"
"228.38400","19.03214","0.00353"
"228.69600","19.05821","0.00355"
"229.00800","19.08416","0.00369"
"229.32000","19.11029","0.00353"
"229.63200","19.13618","0.00417"
"229.94400","19.16213","0.00404"
"230.25600","19.18826","0.00350"
"230.56800","19.21420","0.00388"
"230.88000","19.24027","0.00387"
"231.19200","19.26616","0.00325"
"231.50400","19.29223","0.00396"
"231.81600","19.31824","0.00328"
"232.12800","19.34419","0.00390"
"232.44000","19.37025","0.00399"
"232.75200","19.39614","0.00402"
"233.06400","19.42221","0.00395"
"233.37600","19.44816","0.00375"
"233.68800","19.47423","0.00395"
"234.00000","19.50024","0.00383"
"234.31200","19.52625","0.00364"
"234.62400","19.55225","0.00480"
"234.93600","19.57820","0.00347"
"235.24800","19.60421","0.00388"
"235.56000","19.63016","0.00392"
"235.87200","19.65623","0.00469"
"236.18400","19.68224","0.00416"
"236.49600","19.70819","0.00405"
"236.80800","19.73419","0.00383"
"237.12000","19.76020","0.00381"
"237.43200","19.78627","0.00355"
"237.74400","19.81222","0.00391"
"238.05600","19.83822","0.00326"
"238.36800","19.86423","0.00352"
"238.68000","19.89012","0.00345"
"238.99200","19.91625","0.00317"
"239.30400","19.94220","0.00294"
"239.61600","19.96821","0.00220"
"239.92800","19.99428","0.00215"
"240.24000","20.02022","0.00190"
"240.55200","20.04623","0.00206"
"240.86400","20.07212","0.00266"
"241.17600","20.09825","0.00166"
"241.48800","20.12420","0.00229"
"241.80000","20.15021","0.00214"
"242.11200","20.17622","0.00219"
"242.42400","20.20217","0.00145"
"242.73600","20.22817","0.00232"
"243.04800","20.25418","0.00252"
"243.36000","20.28025","0.00220"
"243.67200","20.30620","0.00190"
"243.98400","20.33221","0.00171"
"244.29600","20.35822","0.00202"
"244.60800","20.38423","0.00181"
"244.92000","20.41023","0.00213"
"245.23200","20.43624","0.00234"
"245.54400","20.46219","0.00221"
"245.85600","20.48820","0.00181"
"246.16800","20.51415","0.00215"
"246.48000","20.54028","0.00256"
"246.79200","20.56623","0.00175"
"247.10400","20.59223","0.00223"
"247.41600","20.61824","0.00258"
"247.72800","20.64425","0.00190"
"248.04000","20.67020","0.00218"
"248.35200","20.69615","0.00221"
"248.66400","20.72227","0.00242"
"248.97600","20.74817","0.00214"
"249.28800","20.77423","0.00156"
"249.60000","20.80024","0.00256"
"249.91200","20.82619","0.00246"
"250.22400","20.85226","0.00219"
"250.53600","20.87820","0.00201"
"250.84800","20.90427","0.00272"
"251.16000","20.93016","0.00240"
"251.47200","20.95617","0.00279"
"251.78400","20.98224","0.00248"
"252.09600","21.00825","0.00251"
"252.40800","21.03420","0.00274"
"252.72000","21.06020","0.00280"
"253.03200","21.08627","0.00276"
"253.34400","21.11222","0.00265"
"253.65600","21.13817","0.00265"
"253.96800","21.16424","0.00301"
"254.28000","21.19019","0.00227"
"254.59200","21.21626","0.00241"
"254.90400","21.24220","0.00270"
"255.21600","21.26821","0.00287"
"255.52800","21.29422","0.00243"
"255.84000","21.32023","0.00278"
"256.15200","21.34624","0.00213"
"256.46400","21.37213","0.00272"
"256.77600","21.39826","0.00176"
"257.08800","21.42420","0.00282"
"257.40000","21.45027","0.00227"
"257.71200","21.47628","0.00279"
"258.02400","21.50223","0.00264"
"258.33600","21.52818","0.00345"
"258.64800","21.55413","0.00233"
"258.96000","21.58026","0.00242"
"259.27200","21.60620","0.00248"
"259.58400","21.63227","0.00371"
"259.89600","21.65822","0.00298"
"260.20800","21.68417","0.00299"
"260.52000","21.71024","0.00308"
"260.83200","21.73619","0.00327"
"261.14400","21.76219","0.00338"
"261.45600","21.78826","0.00293"
"261.76800","21.81421","0.00306"
"262.08000","21.84022","0.00296"
"262.39200","21.86617","0.00299"
"262.70400","21.89224","0.00359"
"263.01600","21.91825","0.00331"
"263.32800","21.94419","0.00260"
"263.64000","21.97026","0.00284"
"263.95200","21.99615","0.00266"
"264.26400","22.02222","0.00229"
"264.57600","22.04817","0.00335"
"264.88800","22.07424","0.00348"
"265.20000","22.10025","0.00287"
"265.51200","22.12619","0.00347"
"265.82400","22.15226","0.00260"
"266.13600","22.17815","0.00359"
"266.44800","22.20422","0.00320"
"266.76000","22.23017","0.00355"
"267.07200","22.25617","0.00381"
"267.38400","22.28224","0.00339"
"267.69600","22.30819","0.00321"
"268.00800","22.33420","0.00317"
"268.32000","22.36015","0.00345"
"268.63200","22.38622","0.00325"
"268.94400","22.41223","0.00355"
"269.25600","22.43818","0.00310"
"269.56800","22.46424","0.00315"
"269.88000","22.49025","0.00325"
"270.19200","22.51626","0.00362"
"270.50400","22.54221","0.00306"
"270.81600","22.56816","0.00391"
"271.12800","22.59422","0.00329"
"271.44000","22.62017","0.00364"
"271.75200","22.64624","0.00374"
"272.06400","22.67219","0.00314"
"272.37600","22.69826","0.00350"
"272.68800","22.72421","0.00397"
"273.00000","22.75022","0.00430"
"273.31200","22.77629","0.00380"
"273.62400","22.80217","0.00363"
"273.93600","22.82824","0.00424"
"274.24800","22.85413","0.00426"
"274.56000","22.88020","0.00449"
"274.87200","22.90621","0.00412"
"275.18400","22.93222","0.00368"
"275.49600","22.95828","0.00412"
"275.80800","22.98417","0.00416"
"276.12000","23.01024","0.00444"
"276.43200","23.03625","0.00426"
"276.74400","23.06226","0.00390"
"277.05600","23.08821","0.00448"
"277.36800","23.11416","0.00390"
"277.68000","23.14022","0.00400"
"277.99200","23.16617","0.00383"
"278.30400","23.19218","0.00428"
"278.61600","23.21819","0.00420"
"278.92800","23.24420","0.00459"
"279.24000","23.27027","0.00455"
"279.55200","23.29616","0.00463"
"279.86400","23.32222","0.00446"
"280.17600","23.34817","0.00390"
"280.48800","23.37424","0.00432"
"280.80000","23.40025","0.00404"
"281.11200","23.42620","0.00421"
"281.42400","23.45220","0.00462"
"281.73600","23.47821","0.00422"
"282.04800","23.50422","0.00477"
"282.36000","23.53023","0.00446"
"282.67200","23.55624","0.00441"
"282.98400","23.58225","0.00431"
"283.29600","23.60820","0.00460"
"283.60800","23.63420","0.00511"
"283.92000","23.66015","0.00429"
"284.23200","23.68622","0.00459"
"284.54400","23.71223","0.00474"
"284.85600","23.73818","0.00477"
"285.16800","23.76425","0.00414"
"285.48000","23.79020","0.00419"
"285.79200","23.81621","0.00434"
"286.10400","23.84221","0.00475"
"286.41600","23.86828","0.00453"
"286.72800","23.89423","0.00485"
"287.04000","23.92018","0.00471"
"287.35200","23.94618","0.00424"
"287.66400","23.97220","0.00431"
"287.97600","23.99826","0.00427"
"288.28800","24.02421","0.00491"
"288.60000","24.05022","0.00501"
"288.91200","24.07623","0.00471"
"289.22400","24.10218","0.00458"
"289.53600","24.12825","0.00411"
"289.84800","24.15420","0.00471"
"290.16000","24.18026","0.00470"
"290.47200","24.20621","0.00474"
"290.78400","24.23216","0.00471"
"291.09600","24.25829","0.00414"
"291.40800","24.28418","0.00466"
"291.72000","24.31025","0.00422"
"292.03200","24.33613","0.00419"
"292.34400","24.36220","0.00425"
"292.65600","24.38821","0.00423"
"292.96800","24.41416","0.00410"
"293.28000","24.44023","0.00437"
"293.59200","24.46618","0.00487"
"293.90400","24.49224","0.00462"
"294.21600","24.51819","0.00418"
"294.52800","24.54420","0.00393"
"294.84000","24.57027","0.00407"
"295.15200","24.59622","0.00419"
"295.46400","24.62223","0.00393"
"295.77600","24.64818","0.00480"
"296.08800","24.67424","0.00426"
"296.40000","24.70025","0.00424"
"296.71200","24.72614","0.00440"
"297.02400","24.75221","0.00415"
"297.33600","24.77816","0.00440"
"297.64800","24.80423","0.00413"
"297.96000","24.83018","0.00403"
"298.27200","24.85624","0.00442"
"298.58400","24.88231","0.00375"
"298.89600","24.90820","0.00389"
"299.20800","24.93421","0.00398"
"299.52000","24.96010","0.00411"
"299.83200","24.98623","0.00347"
"300.14400","25.01223","0.00365"
"300.45600","25.03824","0.00454"
"300.76800","25.06425","0.00400"
"301.08000","25.09020","0.00418"
"301.39200","25.11627","0.00432"
"301.70400","25.14215","0.00423"
"302.01600","25.16822","0.00427"
"302.32800","25.19423","0.00358"
"302.64000","25.22024","0.00371"
"302.95200","25.24619","0.00405"
"303.26400","25.27214","0.00397"
"303.57600","25.29821","0.00433"
"303.88800","25.32422","0.00418"
"304.20000","25.35022","0.00423"
"304.51200","25.37623","0.00456"
"304.82400","25.40218","0.00403"
"305.13600","25.42819","0.00390"
"305.44800","25.45420","0.00391"
"305.76000","25.48027","0.00394"
"306.07200","25.50622","0.00446"
"306.38400","25.53216","0.00354"
"306.69600","25.55823","0.00417"
"307.00800","25.58412","0.00403"
"307.32000","25.61025","0.00330"
"307.63200","25.63620","0.00389"
"307.94400","25.66227","0.00349"
"308.25600","25.68828","0.00418"
"308.56800","25.71422","0.00335"
"308.88000","25.74023","0.00330"
"309.19200","25.76618","0.00412"
"309.50400","25.79219","0.00378"
"309.81600","25.81820","0.00331"
"310.12800","25.84421","0.00315"
"310.44000","25.87028","0.00354"
"310.75200","25.89622","0.00344"
"311.06400","25.92223","0.00295"
"311.37600","25.94824","0.00344"
"311.68800","25.97425","0.00363"
"312.00000","26.00020","0.00337"
"312.31200","26.02621","0.00364"
"312.62400","26.05221","0.00369"
"312.93600","26.07822","0.00282"
"313.24800","26.10429","0.00376"
"313.56000","26.13018","0.00391"
"313.87200","26.15619","0.00326"
"314.18400","26.18225","0.00414"
"314.49600","26.20820","0.00399"
"314.80800","26.23421","0.00346"
"315.12000","26.26022","0.00404"
"315.43200","26.28629","0.00405"
"315.74400","26.31224","0.00382"
"316.05600","26.33819","0.00357"
"316.36800","26.36425","0.00330"
"316.68000","26.39020","0.00395"
"316.99200","26.41627","0.00433"
"317.30400","26.44216","0.00407"
"317.61600","26.46823","0.00300"
"317.92800","26.49418","0.00350"
"318.24000","26.52019","0.00399"
"318.55200","26.54620","0.00387"
"318.86400","26.57214","0.00329"
"319.17600","26.59821","0.00323"
"319.48800","26.62416","0.00347"
"319.80000","26.65023","0.00295"
"320.11200","26.67624","0.00319"
"320.42400","26.70213","0.00290"
"320.73600","26.72825","0.00358"
"321.04800","26.75414","0.00340"
"321.36000","26.78021","0.00327"
"321.67200","26.80622","0.00337"
"321.98400","26.83223","0.00309"
"322.29600","26.85823","0.00334"
"322.60800","26.88412","0.00314"
"322.92000","26.91019","0.00343"
"323.23200","26.93620","0.00315"
"323.54400","26.96227","0.00329"
"323.85600","26.98828","0.00319"
"324.16800","27.01417","0.00321"
"324.48000","27.04023","0.00375"
"324.79200","27.06612","0.00293"
"325.10400","27.09225","0.00351"
"325.41600","27.11814","0.00335"
"325.72800","27.14421","0.00351"
"326.04000","27.17028","0.00257"
"326.35200","27.19617","0.00318"
"326.66400","27.22223","0.00278"
"326.97600","27.24818","0.00392"
"327.28800","27.27425","0.00312"
"327.60000","27.30026","0.00354"
"327.91200","27.32621","0.00352"
"328.22400","27.35222","0.00327"
"328.53600","27.37816","0.00321"
"328.84800","27.40423","0.00345"
"329.16000","27.43018","0.00386"
"329.47200","27.45625","0.00301"
"329.78400","27.48220","0.00344"
"330.09600","27.50821","0.00365"
"330.40800","27.53422","0.00338"
"330.72000","27.56016","0.00373"
"331.03200","27.58623","0.00375"
"331.34400","27.61224","0.00290"
"331.65600","27.63819","0.00408"
"331.96800","27.66420","0.00380"
"332.28000","27.69015","0.00335"
"332.59200","27.71622","0.00342"
"332.90400","27.74216","0.00335"
"333.21600","27.76823","0.00369"
"333.52800","27.79424","0.00358"
"333.84000","27.82019","0.00377"
"334.15200","27.84626","0.00390"
"334.46400","27.87221","0.00354"
"334.77600","27.89821","0.00369"
"335.08800","27.92416","0.00357"
"335.40000","27.95017","0.00379"
"335.71200","27.97624","0.00412"
"336.02400","28.00219","0.00293"
"336.33600","28.02826","0.00373"
"336.64800","28.05421","0.00390"
"336.96000","28.08027","0.00453"
"337.27200","28.10622","0.00336"
"337.58400","28.13217","0.00383"
"337.89600","28.15824","0.00388"
"338.20800","28.18419","0.00373"
"338.52000","28.21026","0.00304"
"338.83200","28.23621","0.00336"
"339.14400","28.26221","0.00417"
"339.45600","28.28822","0.00416"
"339.76800","28.31423","0.00344"
"340.08000","28.34024","0.00406"
"340.39200","28.36619","0.00350"
"340.70400","28.39226","0.00455"
"341.01600","28.41821","0.00426"
"341.32800","28.44421","0.00425"
"341.64000","28.47028","0.00372"
"341.95200","28.49617","0.00413"
"342.26400","28.52224","0.00360"
"342.57600","28.54819","0.00417"
"342.88800","28.57420","0.00438"
"343.20000","28.60020","0.00408"
"343.51200","28.62621","0.00403"
"343.82400","28.65228","0.00348"
"344.13600","28.67817","0.00432"
"344.44800","28.70424","0.00444"
"344.76000","28.73019","0.00384"
"345.07200","28.75625","0.00405"
"345.38400","28.78226","0.00391"
"345.69600","28.80821","0.00429"
"346.00800","28.83422","0.00495"
"346.32000","28.86011","0.00446"
"346.63200","28.88624","0.00437"
"346.94400","28.91225","0.00464"
"347.25600","28.93825","0.00423"
"347.56800","28.96426","0.00368"
"347.88000","28.99021","0.00426"
"348.19200","29.01622","0.00504"
"348.50400","29.04217","0.00433"
"348.81600","29.06824","0.00410"
"349.12800","29.09418","0.00430"
"349.44000","29.12013","0.00428"
"349.75200","29.14620","0.00457"
"350.06400","29.17215","0.00495"
"350.37600","29.19822","0.00465"
"350.68800","29.22423","0.00500"
"351.00000","29.25023","0.00480"
"351.31200","29.27625","0.00479"
"351.62400","29.30219","0.00420"
"351.93600","29.32826","0.00474"
"352.24800","29.35421","0.00420"
"352.56000","29.38028","0.00440"
"352.87200","29.40617","0.00408"
"353.18400","29.43218","0.00461"
"353.49600","29.45824","0.00451"
"353.80800","29.48419","0.00484"
"354.12000","29.51020","0.00421"
"354.43200","29.53621","0.00509"
"354.74400","29.56222","0.00460"
"355.05600","29.58823","0.00497"
"355.36800","29.61423","0.00449"
"355.68000","29.64024","0.00491"
"355.99200","29.66619","0.00468"
"356.30400","29.69226","0.00534"
"356.61600","29.71815","0.00508"
"356.92800","29.74416","0.00535"
"357.24000","29.77023","0.00510"
"357.55200","29.79618","0.00468"
"357.86400","29.82218","0.00472"
"358.17600","29.84819","0.00468"
"358.48800","29.87426","0.00494"
"358.80000","29.90021","0.00500"
"359.11200","29.92616","0.00464"
"359.42400","29.95228","0.00498"
"359.73600","29.97817","0.00510"
"360.04800","30.00424","0.00556"
"360.36000","30.03013","0.00515"
"360.67200","30.05620","0.00556"
"360.98400","30.08215","0.00525"
"361.29600","30.10816","0.00490"
"361.60800","30.13423","0.00455"
"361.92000","30.16017","0.00548"
"362.23200","30.18624","0.00489"
"362.54400","30.21219","0.00508"
"362.85600","30.23826","0.00603"
"363.16800","30.26427","0.00521"
"363.48000","30.29016","0.00520"
"363.79200","30.31623","0.00511"
"364.10400","30.34217","0.00472"
"364.41600","30.36818","0.00511"
"364.72800","30.39425","0.00543"
"365.04000","30.42026","0.00568"
"365.35200","30.44627","0.00541"
"365.66400","30.47216","0.00510"
"365.97600","30.49822","0.00597"
"366.28800","30.52417","0.00539"
"366.60000","30.55024","0.00552"
"366.91200","30.57619","0.00556"
"367.22400","30.60220","0.00600"
"367.53600","30.62820","0.00548"
"367.84800","30.65415","0.00483"
"368.16000","30.68028","0.00587"
"368.47200","30.70623","0.00526"
"368.78400","30.73218","0.00618"
"369.09600","30.75831","0.00538"
"369.40800","30.78425","0.00545"
"369.72000","30.81026","0.00557"
"370.03200","30.83621","0.00539"
"370.34400","30.86228","0.00611"
"370.65600","30.88823","0.00632"
"370.96800","30.91418","0.00569"
"371.28000","30.94019","0.00559"
"371.59200","30.96620","0.00610"
"371.90400","30.99226","0.00626"
"372.21600","31.01821","0.00558"
"372.52800","31.04422","0.00629"
"372.84000","31.07023","0.00547"
"373.15200","31.09624","0.00597"
"373.46400","31.12218","0.00576"
"373.77600","31.14820","0.00584"
"374.08800","31.17421","0.00582"
"374.40000","31.20021","0.00625"
"374.71200","31.22622","0.00635"
"375.02400","31.25223","0.00568"
"375.33600","31.27817","0.00574"
"375.64800","31.30424","0.00650"
"375.96000","31.33019","0.00674"
"376.27200","31.35620","0.00645"
"376.58400","31.38227","0.00617"
"376.89600","31.40822","0.00596"
"377.20800","31.43423","0.00613"
"377.52000","31.46018","0.00586"
"377.83200","31.48624","0.00644"
"378.14400","31.51219","0.00658"
"378.45600","31.53820","0.00606"
"378.76800","31.56421","0.00575"
"379.08000","31.59022","0.00722"
"379.39200","31.61629","0.00594"
"379.70400","31.64218","0.00665"
"380.01600","31.66824","0.00609"
"380.32800","31.69419","0.00664"
"380.64000","31.72020","0.00663"
"380.95200","31.74627","0.00633"
"381.26400","31.77222","0.00653"
"381.57600","31.79823","0.00616"
"381.88800","31.82417","0.00660"
"382.20000","31.85018","0.00621"
"382.51200","31.87619","0.00700"
"382.82400","31.90220","0.00607"
"383.13600","31.92821","0.00654"
"383.44800","31.95416","0.00635"
"383.76000","31.98022","0.00671"
"384.07200","32.00618","0.00640"
"384.38400","32.03224","0.00640"
"384.69600","32.05831","0.00706"
"385.00800","32.08420","0.00616"
"385.32000","32.11021","0.00739"
"385.63200","32.13616","0.00687"
"385.94400","32.16222","0.00661"
"386.25600","32.18823","0.00600"
"386.56800","32.21424","0.00682"
"386.88000","32.24025","0.00664"
"387.19200","32.26620","0.00680"
"387.50400","32.29227","0.00690"
"387.81600","32.31821","0.00626"
"388.12800","32.34428","0.00724"
"388.44000","32.37023","0.00687"
"388.75200","32.39618","0.00684"
"389.06400","32.42219","0.00667"
"389.37600","32.44808","0.00692"
"389.68800","32.47421","0.00713"
"390.00000","32.50021","0.00704"
"390.31200","32.52622","0.00694"
"390.62400","32.55229","0.00746"
"390.93600","32.57824","0.00733"
"391.24800","32.60419","0.00714"
"391.56000","32.63020","0.00754"
"391.87200","32.65627","0.00737"
"392.18400","32.68221","0.00743"
"392.49600","32.70816","0.00721"
"392.80800","32.73423","0.00763"
"393.12000","32.76012","0.00755"
"393.43200","32.78619","0.00777"
"393.74400","32.81220","0.00779"
"394.05600","32.83820","0.00765"
"394.36800","32.86421","0.00732"
"394.68000","32.89016","0.00742"
"394.99200","32.91623","0.00734"
"395.30400","32.94218","0.00754"
"395.61600","32.96819","0.00765"
"395.92800","32.99419","0.00720"
"396.24000","33.02014","0.00756"
"396.55200","33.04621","0.00802"
"396.86400","33.07222","0.00759"
"397.17600","33.09823","0.00760"
"397.48800","33.12418","0.00779"
"397.80000","33.15025","0.00804"
"398.11200","33.17625","0.00734"
"398.42400","33.20221","0.00741"
"398.73600","33.22827","0.00762"
"399.04800","33.25416","0.00792"
"399.36000","33.28023","0.00829"
"399.67200","33.30618","0.00813"
"399.98400","33.33219","0.00843"
"400.29600","33.35825","0.00811"
"400.60800","33.38420","0.00801"
"400.92000","33.41027","0.00837"
"401.23200","33.43616","0.00835"
"401.54400","33.46229","0.00784"
"401.85600","33.48824","0.00845"
"402.16800","33.51419","0.00800"
"402.48000","33.54025","0.00837"
"402.79200","33.56620","0.00813"
"403.10400","33.59227","0.00839"
"403.41600","33.61816","0.00836"
"403.72800","33.64417","0.00833"
"404.04000","33.67018","0.00899"
"404.35200","33.69619","0.00789"
"404.66400","33.72225","0.00833"
"404.97600","33.74820","0.00864"
"405.28800","33.77427","0.00876"
"405.60000","33.80022","0.00882"
"405.91200","33.82623","0.00847"
"406.22400","33.85223","0.00860"
"406.53600","33.87819","0.00871"
"406.84800","33.90419","0.00879"
"407.16000","33.93014","0.00908"
"407.47200","33.95621","0.00882"
"407.78400","33.98222","0.00856"
"408.09600","34.00823","0.00872"
"408.40800","34.03423","0.00920"
"408.72000","34.06012","0.00881"
"409.03200","34.08625","0.00912"
"409.34400","34.11220","0.00899"
"409.65600","34.13827","0.00903"
"409.96800","34.16428","0.00914"
"410.28000","34.19023","0.00926"
"410.59200","34.21623","0.00929"
"410.90400","34.24218","0.00922"
"411.21600","34.26825","0.00945"
"411.52800","34.29420","0.00929"
"411.84000","34.32021","0.00954"
"412.15200","34.34621","0.00923"
"412.46400","34.37217","0.00958"
"412.77600","34.39823","0.00939"
"413.08800","34.42418","0.00974"
"413.40000","34.45025","0.00985"
"413.71200","34.47626","0.01006"
"414.02400","34.50221","0.00939"
"414.33600","34.52821","0.00984"
"414.64800","34.55416","0.00966"
"414.96000","34.58023","0.00970"
"415.27200","34.60624","0.00973"
"415.58400","34.63225","0.01021"
"415.89600","34.65826","0.01023"
"416.20800","34.68421","0.00987"
"416.52000","34.71021","0.01023"
"416.83200","34.73623","0.01006"
"417.14400","34.76223","0.01051"
"417.45600","34.78824","0.01024"
"417.76800","34.81419","0.01021"
"418.08000","34.84026","0.01085"
"418.39200","34.86615","0.01090"
"418.70400","34.89222","0.01046"
"419.01600","34.91822","0.01055"
"419.32800","34.94423","0.01027"
"419.64000","34.97018","0.01066"
"419.95200","34.99619","0.01053"
"420.26400","35.02225","0.01065"
"420.57600","35.04815","0.01096"
"420.88800","35.07421","0.01092"
"421.20000","35.10016","0.01098"
"421.51200","35.12617","0.01057"
"421.82400","35.15224","0.01126"
"422.13600","35.17819","0.01018"
"422.44800","35.20420","0.01069"
"422.76000","35.23014","0.01135"
"423.07200","35.25621","0.01077"
"423.38400","35.28222","0.01064"
"423.69600","35.30823","0.01099"
"424.00800","35.33430","0.01109"
"424.32000","35.36019","0.01114"
"424.63200","35.38620","0.01140"
"424.94400","35.41214","0.01115"
"425.25600","35.43821","0.01132"
"425.56800","35.46422","0.01174"
"425.88000","35.49017","0.01197"
"426.19200","35.51618","0.01156"
"426.50400","35.54219","0.01188"
"426.81600","35.56820","0.01177"
"427.12800","35.59420","0.01104"
"427.44000","35.62021","0.01164"
"427.75200","35.64628","0.01178"
"428.06400","35.67217","0.01200"
"428.37600","35.69824","0.01185"
"428.68800","35.72412","0.01180"
"429.00000","35.75026","0.01223"
"429.31200","35.77626","0.01229"
"429.62400","35.80221","0.01192"
"429.93600","35.82822","0.01224"
"430.24800","35.85417","0.01202"
"430.56000","35.88024","0.01251"
"430.87200","35.90619","0.01219"
"431.18400","35.93225","0.01266"
"431.49600","35.95820","0.01250"
"431.80800","35.98421","0.01216"
"432.12000","36.01016","0.01194"
"432.43200","36.03611","0.01272"
"432.74400","36.06224","0.01247"
"433.05600","36.08824","0.01293"
"433.36800","36.11425","0.01276"
"433.68000","36.14032","0.01316"
"433.99200","36.16621","0.01264"
"434.30400","36.19222","0.01349"
"434.61600","36.21823","0.01327"
"434.92800","36.24424","0.01298"
"435.24000","36.27018","0.01330"
"435.55200","36.29619","0.01331"
"435.86400","36.32220","0.01361"
"436.17600","36.34815","0.01332"
"436.48800","36.37428","0.01359"
"436.80000","36.40023","0.01349"
"437.11200","36.42617","0.01415"
"437.42400","36.45224","0.01374"
"437.73600","36.47819","0.01382"
"438.04800","36.50426","0.01364"
"438.36000","36.53021","0.01363"
"438.67200","36.55622","0.01398"
"438.98400","36.58223","0.01408"
"439.29600","36.60823","0.01448"
"439.60800","36.63424","0.01427"
"439.92000","36.66019","0.01469"
"440.23200","36.68626","0.01491"
"440.54400","36.71221","0.01452"
"440.85600","36.73822","0.01455"
"441.16800","36.76423","0.01468"
"441.48000","36.79023","0.01508"
"441.79200","36.81624","0.01487"
"442.10400","36.84219","0.01524"
"442.41600","36.86820","0.01489"
"442.72800","36.89421","0.01564"
"443.04000","36.92015","0.01498"
"443.35200","36.94622","0.01497"
"443.66400","36.97223","0.01563"
"443.97600","36.99824","0.01530"
"444.28800","37.02419","0.01566"
"444.60000","37.05026","0.01635"
"444.91200","37.07621","0.01590"
"445.22400","37.10215","0.01607"
"445.53600","37.12828","0.01586"
"445.84800","37.15417","0.01600"
"446.16000","37.18024","0.01594"
"446.47200","37.20619","0.01647"
"446.78400","37.23220","0.01619"
"447.09600","37.25821","0.01609"
"447.40800","37.28415","0.01630"
"447.72000","37.31022","0.01646"
"448.03200","37.33611","0.01637"
"448.34400","37.36224","0.01588"
"448.65600","37.38825","0.01679"
"448.96800","37.41426","0.01696"
"449.28000","37.44021","0.01729"
"449.59200","37.46615","0.01764"
"449.90400","37.49216","0.01739"
"450.21600","37.51811","0.01778"
"450.52800","37.54418","0.01773"
"450.84000","37.57025","0.01761"
"451.15200","37.59626","0.01765"
"451.46400","37.62221","0.01786"
"451.77600","37.64815","0.01840"
"452.08800","37.67422","0.01834"
"452.40000","37.70023","0.01841"
"452.71200","37.72624","0.01825"
"453.02400","37.75225","0.01749"
"453.33600","37.77819","0.01829"
"453.64800","37.80421","0.01865"
"453.96000","37.83015","0.01867"
"454.27200","37.85622","0.01839"
"454.58400","37.88223","0.01863"
"454.89600","37.90818","0.01941"
"455.20800","37.93431","0.01914"
"455.52000","37.96019","0.01913"
"455.83200","37.98626","0.01925"
"456.14400","38.01221","0.01996"
"456.45600","38.03828","0.01948"
"456.76800","38.06423","0.01925"
"457.08000","38.09018","0.02034"
"457.39200","38.11619","0.02003"
"457.70400","38.14219","0.02023"
"458.01600","38.16820","0.01991"
"458.32800","38.19415","0.02078"
"458.64000","38.22022","0.02053"
"458.95200","38.24623","0.02075"
"459.26400","38.27217","0.02011"
"459.57600","38.29824","0.02092"
"459.88800","38.32420","0.02077"
"460.20000","38.35020","0.02129"
"460.51200","38.37621","0.02235"
"460.82400","38.40216","0.02229"
"461.13600","38.42823","0.02188"
"461.44800","38.45417","0.02255"
"461.76000","38.48024","0.02191"
"462.07200","38.50620","0.02194"
"462.38400","38.53226","0.02242"
"462.69600","38.55827","0.02255"
"463.00800","38.58416","0.02264"
"463.32000","38.61029","0.02339"
"463.63200","38.63612","0.02309"
"463.94400","38.66224","0.02314"
"464.25600","38.68819","0.02423"
"464.56800","38.71420","0.02398"
"464.88000","38.74027","0.02449"
"465.19200","38.76622","0.02391"
"465.50400","38.79222","0.02359"
"465.81600","38.81812","0.02379"
"466.12800","38.84424","0.02388"
"466.44000","38.87025","0.02435"
"466.75200","38.89620","0.02484"
"466.80800","38.90086","0.02445"