File: Force_trajectories/161104/Specimen_RawData_3.csv
End date,"11/4/2016"
Specimen label,""
Maximum Load,"0.01818",N

Time,Extension,Load
(s),(mm),(N)
"0.00000","0.00000","0.00016"
"0.09600","0.00311","0.00068"
"0.19200","0.01238","-0.00002"
"0.28800","0.02302","0.00057"
"0.38400","0.03217","-0.00013"
"0.48000","0.04036","0.00046"
"0.57600","0.04825","-0.00006"
"0.67200","0.05614","0.00005"
"0.76800","0.06415","0.00034"
"0.86400","0.07217","0.00031"
"0.96000","0.08024","0.00029"
"1.05600","0.08819","-0.00009"
"1.15200","0.09620","0.00053"
"1.24800","0.10415","0.00005"
"1.34400","0.11211","-0.00006"
"1.44000","0.12018","0.00036"
"1.53600","0.12825","0.00030"
"1.63200","0.13620","0.00018"
"1.72800","0.14415","0.00009"
"1.82400","0.15210","-0.00025"
"1.92000","0.16012","0.00064"
"2.01600","0.16819","0.00014"
"2.11200","0.17620","0.00056"
"2.20800","0.18415","0.00018"
"2.30400","0.19210","0.00014"
"2.40000","0.20012","0.00049"
"2.49600","0.20813","0.00067"
"2.59200","0.21614","0.00000"
"2.68800","0.22421","0.00083"
"2.78400","0.23216","0.00019"
"2.88000","0.24011","0.00060"
"2.97600","0.24819","0.00084"
"3.07200","0.25620","0.00042"
"3.16800","0.26421","0.00121"
"3.26400","0.27222","0.00105"
"3.36000","0.28011","0.00025"
"3.45600","0.28813","0.00013"
"3.55200","0.29614","0.00033"
"3.64800","0.30415","0.00032"
"3.74400","0.31222","0.00043"
"3.84000","0.32017","0.00065"
"3.93600","0.32812","0.00015"
"4.03200","0.33614","0.00005"
"4.12800","0.34415","0.00062"
"4.22400","0.35216","0.00003"
"4.32000","0.36011","0.00012"
"4.41600","0.36806","0.00028"
"4.51200","0.37602","0.00056"
"4.60800","0.38409","0.00037"
"4.70400","0.39216","0.00017"
"4.80000","0.40011","0.00065"
"4.89600","0.40806","0.00054"
"4.99200","0.41614","0.00006"
"5.08800","0.42409","0.00123"
"5.18400","0.43210","0.00069"
"5.28000","0.44017","0.00048"
"5.37600","0.44812","0.00021"
"5.47200","0.45613","0.00046"
"5.56800","0.46409","0.00040"
"5.66400","0.47210","0.00018"
"5.76000","0.48017","0.00060"
"5.85600","0.48818","0.00075"
"5.95200","0.49613","0.00062"
"6.04800","0.50409","0.00067"
"6.14400","0.51210","0.00060"
"6.24000","0.52017","0.00018"
"6.33600","0.52818","0.00091"
"6.43200","0.53613","0.00060"
"6.52800","0.54408","0.00062"
"6.62400","0.55204","0.00076"
"6.72000","0.56011","0.00042"
"6.81600","0.56812","0.00050"
"6.91200","0.57613","0.00034"
"7.00800","0.58420","0.00057"
"7.10400","0.59210","0.00058"
"7.20000","0.60005","0.00057"
"7.29600","0.60818","0.00062"
"7.39200","0.61619","0.00084"
"7.48800","0.62420","0.00077"
"7.58400","0.63215","0.00064"
"7.68000","0.64011","0.00070"
"7.77600","0.64812","0.00071"
"7.87200","0.65613","0.00047"
"7.96800","0.66414","0.00080"
"8.06400","0.67221","0.00076"
"8.16000","0.68017","0.00024"
"8.25600","0.68806","0.00054"
"8.35200","0.69607","0.00090"
"8.44800","0.70420","0.00057"
"8.54400","0.71215","0.00137"
"8.64000","0.72011","0.00018"
"8.73600","0.72812","0.00077"
"8.83200","0.73607","0.00121"
"8.92800","0.74408","0.00057"
"9.02400","0.75215","0.00061"
"9.12000","0.76016","0.00029"
"9.21600","0.76812","0.00046"
"9.31200","0.77607","0.00087"
"9.40800","0.78408","0.00135"
"9.50400","0.79215","0.00107"
"9.60000","0.80016","0.00079"
"9.69600","0.80818","0.00062"
"9.79200","0.81607","0.00051"
"9.88800","0.82414","0.00098"
"9.98400","0.83209","0.00066"
"10.08000","0.84016","0.00100"
"10.17600","0.84817","0.00058"
"10.27200","0.85613","0.00116"
"10.36800","0.86414","0.00057"
"10.46400","0.87209","0.00080"
"10.56000","0.88010","0.00100"
"10.65600","0.88811","0.00068"
"10.75200","0.89619","0.00044"
"10.84800","0.90414","0.00126"
"10.94400","0.91209","0.00065"
"11.04000","0.92010","0.00087"
"11.13600","0.92817","0.00069"
"11.23200","0.93618","0.00041"
"11.32800","0.94414","0.00089"
"11.42400","0.95215","0.00084"
"11.52000","0.96010","0.00088"
"11.61600","0.96811","0.00109"
"11.71200","0.97612","0.00064"
"11.80800","0.98420","0.00096"
"11.90400","0.99215","0.00045"
"12.00000","1.00016","0.00136"
"12.09600","1.00811","0.00062"
"12.19200","1.01612","0.00062"
"12.28800","1.02419","0.00120"
"12.38400","1.03215","0.00112"
"12.48000","1.04016","0.00083"
"12.57600","1.04811","0.00113"
"12.67200","1.05612","0.00089"
"12.76800","1.06413","0.00067"
"12.86400","1.07215","0.00081"
"12.96000","1.08010","0.00052"
"13.05600","1.08811","0.00067"
"13.15200","1.09612","0.00161"
"13.24800","1.10413","0.00026"
"13.34400","1.11215","0.00118"
"13.44000","1.12016","0.00077"
"13.53600","1.12811","0.00106"
"13.63200","1.13612","0.00079"
"13.72800","1.14413","0.00077"
"13.82400","1.15214","0.00103"
"13.92000","1.16016","0.00105"
"14.01600","1.16817","0.00053"
"14.11200","1.17606","0.00093"
"14.20800","1.18413","0.00081"
"14.30400","1.19214","0.00052"
"14.40000","1.20016","0.00071"
"14.49600","1.20817","0.00155"
"14.59200","1.21618","0.00120"
"14.68800","1.22407","0.00072"
"14.78400","1.23208","0.00075"
"14.88000","1.24015","0.00130"
"14.97600","1.24811","0.00140"
"15.07200","1.25612","0.00107"
"15.16800","1.26413","0.00098"
"15.26400","1.27208","0.00152"
"15.36000","1.28009","0.00100"
"15.45600","1.28817","0.00066"
"15.55200","1.29618","0.00064"
"15.64800","1.30419","0.00085"
"15.74400","1.31208","0.00107"
"15.84000","1.32009","0.00085"
"15.93600","1.32816","0.00145"
"16.03200","1.33618","0.00083"
"16.12800","1.34413","0.00126"
"16.22400","1.35214","0.00116"
"16.32000","1.36015","0.00099"
"16.41600","1.36810","0.00096"
"16.51200","1.37618","0.00121"
"16.60800","1.38419","0.00145"
"16.70400","1.39220","0.00064"
"16.80000","1.40009","0.00079"
"16.89600","1.40810","0.00101"
"16.99200","1.41606","0.00123"
"17.08800","1.42413","0.00150"
"17.18400","1.43214","0.00109"
"17.28000","1.44009","0.00073"
"17.37600","1.44804","0.00106"
"17.47200","1.45611","0.00096"
"17.56800","1.46413","0.00093"
"17.66400","1.47214","0.00138"
"17.76000","1.48021","0.00146"
"17.85600","1.48810","0.00072"
"17.95200","1.49605","0.00109"
"18.04800","1.50413","0.00073"
"18.14400","1.51214","0.00058"
"18.24000","1.52015","0.00091"
"18.33600","1.52822","0.00080"
"18.43200","1.53611","0.00094"
"18.52800","1.54412","0.00077"
"18.62400","1.55214","0.00090"
"18.72000","1.56015","0.00092"
"18.81600","1.56822","0.00105"
"18.91200","1.57617","0.00109"
"19.00800","1.58412","0.00111"
"19.10400","1.59214","0.00086"
"19.20000","1.60015","0.00077"
"19.29600","1.60810","0.00124"
"19.39200","1.61617","0.00123"
"19.48800","1.62412","0.00147"
"19.58400","1.63202","0.00130"
"19.68000","1.64015","0.00071"
"19.77600","1.64816","0.00106"
"19.87200","1.65611","0.00141"
"19.96800","1.66412","0.00075"
"20.06400","1.67213","0.00151"
"20.16000","1.68009","0.00106"
"20.25600","1.68816","0.00120"
"20.35200","1.69617","0.00133"
"20.44800","1.70412","0.00147"
"20.54400","1.71213","0.00160"
"20.64000","1.72014","0.00094"
"20.73600","1.72816","0.00134"
"20.83200","1.73617","0.00140"
"20.92800","1.74418","0.00161"
"21.02400","1.75213","0.00121"
"21.12000","1.76014","0.00174"
"21.21600","1.76816","0.00149"
"21.31200","1.77611","0.00137"
"21.40800","1.78412","0.00130"
"21.50400","1.79213","0.00090"
"21.60000","1.80014","0.00131"
"21.69600","1.80810","0.00140"
"21.79200","1.81611","0.00159"
"21.88800","1.82412","0.00127"
"21.98400","1.83213","0.00087"
"22.08000","1.84014","0.00117"
"22.17600","1.84809","0.00147"
"22.27200","1.85611","0.00133"
"22.36800","1.86412","0.00132"
"22.46400","1.87213","0.00183"
"22.56000","1.88014","0.00117"
"22.65600","1.88809","0.00106"
"22.75200","1.89611","0.00168"
"22.84800","1.90412","0.00176"
"22.94400","1.91213","0.00136"
"23.04000","1.92014","0.00162"
"23.13600","1.92815","0.00117"
"23.23200","1.93610","0.00196"
"23.32800","1.94406","0.00150"
"23.42400","1.95213","0.00169"
"23.52000","1.96020","0.00171"
"23.61600","1.96815","0.00059"
"23.71200","1.97610","0.00156"
"23.80800","1.98412","0.00137"
"23.90400","1.99213","0.00158"
"24.00000","2.00014","0.00112"
"24.09600","2.00815","0.00156"
"24.19200","2.01616","0.00127"
"24.28800","2.02411","0.00126"
"24.38400","2.03213","0.00112"
"24.48000","2.04014","0.00150"
"24.57600","2.04815","0.00173"
"24.67200","2.05616","0.00159"
"24.76800","2.06417","0.00185"
"24.86400","2.07207","0.00139"
"24.96000","2.08008","0.00140"
"25.05600","2.08815","0.00180"
"25.15200","2.09616","0.00149"
"25.24800","2.10417","0.00093"
"25.34400","2.11219","0.00147"
"25.44000","2.12008","0.00120"
"25.53600","2.12815","0.00150"
"25.63200","2.13610","0.00146"
"25.72800","2.14411","0.00138"
"25.82400","2.15218","0.00145"
"25.92000","2.16014","0.00233"
"26.01600","2.16803","0.00167"
"26.11200","2.17616","0.00171"
"26.20800","2.18417","0.00081"
"26.30400","2.19212","0.00143"
"26.40000","2.20020","0.00174"
"26.49600","2.20815","0.00149"
"26.59200","2.21610","0.00181"
"26.68800","2.22411","0.00194"
"26.78400","2.23218","0.00227"
"26.88000","2.24019","0.00140"
"26.97600","2.24815","0.00166"
"27.07200","2.25610","0.00202"
"27.16800","2.26411","0.00194"
"27.26400","2.27212","0.00205"
"27.36000","2.28019","0.00206"
"27.45600","2.28815","0.00166"
"27.55200","2.29610","0.00200"
"27.64800","2.30411","0.00142"
"27.74400","2.31212","0.00148"
"27.84000","2.32007","0.00147"
"27.93600","2.32814","0.00158"
"28.03200","2.33610","0.00202"
"28.12800","2.34405","0.00156"
"28.22400","2.35206","0.00232"
"28.32000","2.36019","0.00183"
"28.41600","2.36814","0.00192"
"28.51200","2.37616","0.00208"
"28.60800","2.38417","0.00233"
"28.70400","2.39212","0.00185"
"28.80000","2.40013","0.00152"
"28.89600","2.40814","0.00171"
"28.99200","2.41615","0.00223"
"29.08800","2.42417","0.00242"
"29.18400","2.43212","0.00220"
"29.28000","2.44007","0.00198"
"29.37600","2.44814","0.00140"
"29.47200","2.45609","0.00211"
"29.56800","2.46417","0.00245"
"29.66400","2.47218","0.00220"
"29.76000","2.48007","0.00190"
"29.85600","2.48808","0.00200"
"29.95200","2.49615","0.00179"
"30.04800","2.50411","0.00164"
"30.14400","2.51212","0.00215"
"30.24000","2.52013","0.00208"
"30.33600","2.52802","0.00220"
"30.43200","2.53609","0.00192"
"30.52800","2.54416","0.00165"
"30.62400","2.55218","0.00219"
"30.72000","2.56013","0.00177"
"30.81600","2.56814","0.00229"
"30.91200","2.57609","0.00168"
"31.00800","2.58416","0.00226"
"31.10400","2.59218","0.00222"
"31.20000","2.60019","0.00226"
"31.29600","2.60814","0.00231"
"31.39200","2.61615","0.00118"
"31.48800","2.62410","0.00208"
"31.58400","2.63217","0.00202"
"31.68000","2.64019","0.00160"
"31.77600","2.64814","0.00197"
"31.87200","2.65615","0.00195"
"31.96800","2.66410","0.00214"
"32.06400","2.67211","0.00249"
"32.16000","2.68013","0.00225"
"32.25600","2.68814","0.00145"
"32.35200","2.69609","0.00171"
"32.44800","2.70410","0.00211"
"32.54400","2.71211","0.00221"
"32.64000","2.72012","0.00164"
"32.73600","2.72814","0.00243"
"32.83200","2.73621","0.00210"
"32.92800","2.74410","0.00195"
"33.02400","2.75211","0.00218"
"33.12000","2.76018","0.00216"
"33.21600","2.76814","0.00167"
"33.31200","2.77615","0.00231"
"33.40800","2.78416","0.00184"
"33.50400","2.79211","0.00276"
"33.60000","2.80006","0.00226"
"33.69600","2.80819","0.00214"
"33.79200","2.81615","0.00219"
"33.88800","2.82416","0.00205"
"33.98400","2.83217","0.00204"
"34.08000","2.84006","0.00239"
"34.17600","2.84813","0.00224"
"34.27200","2.85621","0.00186"
"34.36800","2.86416","0.00219"
"34.46400","2.87217","0.00258"
"34.56000","2.88012","0.00244"
"34.65600","2.88807","0.00194"
"34.75200","2.89609","0.00184"
"34.84800","2.90416","0.00216"
"34.94400","2.91217","0.00221"
"35.04000","2.92012","0.00273"
"35.13600","2.92807","0.00182"
"35.23200","2.93608","0.00265"
"35.32800","2.94416","0.00204"
"35.42400","2.95223","0.00170"
"35.52000","2.96018","0.00229"
"35.61600","2.96813","0.00198"
"35.71200","2.97614","0.00248"
"35.80800","2.98410","0.00240"
"35.90400","2.99217","0.00223"
"36.00000","3.00012","0.00249"
"36.09600","3.00813","0.00184"
"36.19200","3.01614","0.00248"
"36.28800","3.02410","0.00248"
"36.38400","3.03211","0.00248"
"36.48000","3.04012","0.00173"
"36.57600","3.04813","0.00238"
"36.67200","3.05614","0.00211"
"36.76800","3.06409","0.00211"
"36.86400","3.07211","0.00245"
"36.96000","3.08012","0.00246"
"37.05600","3.08813","0.00212"
"37.15200","3.09620","0.00209"
"37.24800","3.10415","0.00165"
"37.34400","3.11205","0.00267"
"37.44000","3.12018","0.00248"
"37.53600","3.12813","0.00199"
"37.63200","3.13614","0.00231"
"37.72800","3.14415","0.00231"
"37.82400","3.15210","0.00293"
"37.92000","3.16006","0.00201"
"38.01600","3.16813","0.00238"
"38.11200","3.17614","0.00260"
"38.20800","3.18415","0.00216"
"38.30400","3.19210","0.00242"
"38.40000","3.20006","0.00264"
"38.49600","3.20813","0.00229"
"38.59200","3.21620","0.00277"
"38.68800","3.22421","0.00235"
"38.78400","3.23216","0.00276"
"38.88000","3.24011","0.00219"
"38.97600","3.24813","0.00227"
"39.07200","3.25614","0.00238"
"39.16800","3.26415","0.00264"
"39.26400","3.27216","0.00225"
"39.36000","3.28011","0.00278"
"39.45600","3.28813","0.00271"
"39.55200","3.29614","0.00218"
"39.64800","3.30415","0.00210"
"39.74400","3.31210","0.00259"
"39.84000","3.32017","0.00258"
"39.93600","3.32812","0.00260"
"40.03200","3.33608","0.00196"
"40.12800","3.34415","0.00226"
"40.22400","3.35216","0.00177"
"40.32000","3.36017","0.00225"
"40.41600","3.36812","0.00242"
"40.51200","3.37608","0.00251"
"40.60800","3.38409","0.00255"
"40.70400","3.39216","0.00287"
"40.80000","3.40011","0.00252"
"40.89600","3.40818","0.00294"
"40.99200","3.41614","0.00255"
"41.08800","3.42409","0.00221"
"41.18400","3.43210","0.00296"
"41.28000","3.44017","0.00240"
"41.37600","3.44818","0.00300"
"41.47200","3.45619","0.00240"
"41.56800","3.46415","0.00342"
"41.66400","3.47210","0.00271"
"41.76000","3.48017","0.00280"
"41.85600","3.48818","0.00257"
"41.95200","3.49613","0.00289"
"42.04800","3.50415","0.00273"
"42.14400","3.51210","0.00228"
"42.24000","3.52011","0.00292"
"42.33600","3.52818","0.00250"
"42.43200","3.53619","0.00301"
"42.52800","3.54414","0.00295"
"42.62400","3.55210","0.00217"
"42.72000","3.56005","0.00264"
"42.81600","3.56806","0.00268"
"42.91200","3.57619","0.00323"
"43.00800","3.58420","0.00252"
"43.10400","3.59210","0.00223"
"43.20000","3.60005","0.00258"
"43.29600","3.60812","0.00243"
"43.39200","3.61613","0.00244"
"43.48800","3.62414","0.00263"
"43.58400","3.63221","0.00271"
"43.68000","3.64017","0.00299"
"43.77600","3.64812","0.00348"
"43.87200","3.65607","0.00318"
"43.96800","3.66414","0.00263"
"44.06400","3.67215","0.00289"
"44.16000","3.68017","0.00260"
"44.25600","3.68812","0.00307"
"44.35200","3.69607","0.00297"
"44.44800","3.70414","0.00329"
"44.54400","3.71215","0.00304"
"44.64000","3.72016","0.00251"
"44.73600","3.72812","0.00280"
"44.83200","3.73601","0.00260"
"44.92800","3.74408","0.00271"
"45.02400","3.75215","0.00288"
"45.12000","3.76010","0.00249"
"45.21600","3.76818","0.00298"
"45.31200","3.77613","0.00347"
"45.40800","3.78408","0.00284"
"45.50400","3.79209","0.00319"
"45.60000","3.80022","0.00347"
"45.69600","3.80812","0.00291"
"45.79200","3.81613","0.00293"
"45.88800","3.82414","0.00291"
"45.98400","3.83203","0.00334"
"46.08000","3.84010","0.00317"
"46.17600","3.84817","0.00289"
"46.27200","3.85613","0.00292"
"46.36800","3.86414","0.00313"
"46.46400","3.87215","0.00314"
"46.56000","3.88016","0.00309"
"46.65600","3.88817","0.00288"
"46.75200","3.89625","0.00277"
"46.84800","3.90420","0.00361"
"46.94400","3.91209","0.00327"
"47.04000","3.92010","0.00291"
"47.13600","3.92811","0.00297"
"47.23200","3.93612","0.00323"
"47.32800","3.94414","0.00331"
"47.42400","3.95209","0.00329"
"47.52000","3.96010","0.00343"
"47.61600","3.96811","0.00309"
"47.71200","3.97612","0.00298"
"47.80800","3.98414","0.00353"
"47.90400","3.99215","0.00337"
"48.00000","4.00010","0.00311"
"48.09600","4.00811","0.00309"
"48.19200","4.01612","0.00294"
"48.28800","4.02413","0.00311"
"48.38400","4.03215","0.00294"
"48.48000","4.04016","0.00341"
"48.57600","4.04811","0.00307"
"48.67200","4.05606","0.00323"
"48.76800","4.06419","0.00250"
"48.86400","4.07215","0.00259"
"48.96000","4.08016","0.00310"
"49.05600","4.08811","0.00369"
"49.15200","4.09606","0.00316"
"49.24800","4.10413","0.00324"
"49.34400","4.11220","0.00348"
"49.44000","4.12016","0.00287"
"49.53600","4.12811","0.00307"
"49.63200","4.13612","0.00296"
"49.72800","4.14407","0.00332"
"49.82400","4.15214","0.00308"
"49.92000","4.16016","0.00339"
"50.01600","4.16817","0.00231"
"50.11200","4.17612","0.00297"
"50.20800","4.18407","0.00306"
"50.30400","4.19208","0.00305"
"50.40000","4.20015","0.00291"
"50.49600","4.20817","0.00347"
"50.59200","4.21618","0.00306"
"50.68800","4.22413","0.00388"
"50.78400","4.23208","0.00322"
"50.88000","4.24015","0.00350"
"50.97600","4.24817","0.00362"
"51.07200","4.25618","0.00304"
"51.16800","4.26413","0.00324"
"51.26400","4.27214","0.00324"
"51.36000","4.28009","0.00315"
"51.45600","4.28811","0.00277"
"51.55200","4.29618","0.00278"
"51.64800","4.30413","0.00322"
"51.74400","4.31214","0.00324"
"51.84000","4.32009","0.00340"
"51.93600","4.32810","0.00301"
"52.03200","4.33612","0.00309"
"52.12800","4.34413","0.00339"
"52.22400","4.35220","0.00322"
"52.32000","4.36009","0.00347"
"52.41600","4.36804","0.00312"
"52.51200","4.37612","0.00280"
"52.60800","4.38419","0.00322"
"52.70400","4.39214","0.00310"
"52.80000","4.40015","0.00348"
"52.89600","4.40816","0.00324"
"52.99200","4.41611","0.00387"
"53.08800","4.42413","0.00327"
"53.18400","4.43214","0.00369"
"53.28000","4.44015","0.00352"
"53.37600","4.44816","0.00340"
"53.47200","4.45605","0.00298"
"53.56800","4.46407","0.00346"
"53.66400","4.47214","0.00336"
"53.76000","4.48015","0.00378"
"53.85600","4.48810","0.00354"
"53.95200","4.49611","0.00369"
"54.04800","4.50413","0.00369"
"54.14400","4.51214","0.00348"
"54.24000","4.52015","0.00359"
"54.33600","4.52816","0.00344"
"54.43200","4.53611","0.00365"
"54.52800","4.54412","0.00326"
"54.62400","4.55214","0.00356"
"54.72000","4.56015","0.00341"
"54.81600","4.56816","0.00392"
"54.91200","4.57617","0.00366"
"55.00800","4.58412","0.00334"
"55.10400","4.59208","0.00302"
"55.20000","4.60015","0.00359"
"55.29600","4.60816","0.00334"
"55.39200","4.61611","0.00370"
"55.48800","4.62412","0.00384"
"55.58400","4.63207","0.00356"
"55.68000","4.64009","0.00358"
"55.77600","4.64816","0.00427"
"55.87200","4.65611","0.00328"
"55.96800","4.66412","0.00328"
"56.06400","4.67213","0.00414"
"56.16000","4.68003","0.00385"
"56.25600","4.68810","0.00378"
"56.35200","4.69623","0.00366"
"56.44800","4.70418","0.00388"
"56.54400","4.71213","0.00298"
"56.64000","4.72014","0.00411"
"56.73600","4.72810","0.00326"
"56.83200","4.73617","0.00354"
"56.92800","4.74418","0.00356"
"57.02400","4.75219","0.00405"
"57.12000","4.76014","0.00365"
"57.21600","4.76810","0.00431"
"57.31200","4.77617","0.00401"
"57.40800","4.78418","0.00394"
"57.50400","4.79213","0.00343"
"57.60000","4.80014","0.00427"
"57.69600","4.80809","0.00367"
"57.79200","4.81611","0.00374"
"57.88800","4.82412","0.00361"
"57.98400","4.83213","0.00358"
"58.08000","4.84014","0.00412"
"58.17600","4.84809","0.00378"
"58.27200","4.85605","0.00395"
"58.36800","4.86412","0.00393"
"58.46400","4.87213","0.00381"
"58.56000","4.88014","0.00452"
"58.65600","4.88821","0.00363"
"58.75200","4.89611","0.00373"
"58.84800","4.90406","0.00415"
"58.94400","4.91219","0.00398"
"59.04000","4.92020","0.00407"
"59.13600","4.92815","0.00399"
"59.23200","4.93616","0.00405"
"59.32800","4.94412","0.00396"
"59.42400","4.95213","0.00447"
"59.52000","4.96014","0.00399"
"59.61600","4.96815","0.00419"
"59.71200","4.97616","0.00435"
"59.80800","4.98418","0.00375"
"59.90400","4.99207","0.00395"
"60.00000","5.00008","0.00451"
"60.09600","5.00821","0.00395"
"60.19200","5.01616","0.00394"
"60.28800","5.02411","0.00436"
"60.38400","5.03213","0.00437"
"60.48000","5.04008","0.00501"
"60.57600","5.04809","0.00413"
"60.67200","5.05616","0.00426"
"60.76800","5.06411","0.00376"
"60.86400","5.07213","0.00425"
"60.96000","5.08008","0.00451"
"61.05600","5.08809","0.00448"
"61.15200","5.09616","0.00383"
"61.24800","5.10417","0.00423"
"61.34400","5.11212","0.00395"
"61.44000","5.12014","0.00432"
"61.53600","5.12815","0.00417"
"61.63200","5.13610","0.00461"
"61.72800","5.14417","0.00358"
"61.82400","5.15218","0.00471"
"61.92000","5.16014","0.00424"
"62.01600","5.16809","0.00392"
"62.11200","5.17616","0.00467"
"62.20800","5.18411","0.00401"
"62.30400","5.19212","0.00448"
"62.40000","5.20019","0.00451"
"62.49600","5.20815","0.00413"
"62.59200","5.21610","0.00422"
"62.68800","5.22411","0.00472"
"62.78400","5.23212","0.00418"
"62.88000","5.24013","0.00496"
"62.97600","5.24815","0.00431"
"63.07200","5.25610","0.00414"
"63.16800","5.26411","0.00437"
"63.26400","5.27212","0.00437"
"63.36000","5.28013","0.00400"
"63.45600","5.28808","0.00347"
"63.55200","5.29616","0.00484"
"63.64800","5.30411","0.00458"
"63.74400","5.31206","0.00406"
"63.84000","5.32013","0.00404"
"63.93600","5.32814","0.00394"
"64.03200","5.33616","0.00476"
"64.12800","5.34411","0.00422"
"64.22400","5.35206","0.00434"
"64.32000","5.36013","0.00460"
"64.41600","5.36820","0.00408"
"64.51200","5.37616","0.00437"
"64.60800","5.38411","0.00406"
"64.70400","5.39212","0.00455"
"64.80000","5.40007","0.00470"
"64.89600","5.40814","0.00406"
"64.99200","5.41615","0.00402"
"65.08800","5.42417","0.00475"
"65.18400","5.43212","0.00386"
"65.28000","5.44013","0.00461"
"65.37600","5.44814","0.00493"
"65.47200","5.45615","0.00422"
"65.56800","5.46417","0.00477"
"65.66400","5.47212","0.00508"
"65.76000","5.48007","0.00511"
"65.85600","5.48814","0.00419"
"65.95200","5.49615","0.00409"
"66.04800","5.50416","0.00458"
"66.14400","5.51218","0.00459"
"66.24000","5.52013","0.00530"
"66.33600","5.52808","0.00467"
"66.43200","5.53609","0.00468"
"66.52800","5.54416","0.00463"
"66.62400","5.55212","0.00417"
"66.72000","5.56013","0.00516"
"66.81600","5.56808","0.00470"
"66.91200","5.57609","0.00507"
"67.00800","5.58410","0.00474"
"67.10400","5.59218","0.00468"
"67.20000","5.60019","0.00466"
"67.29600","5.60820","0.00465"
"67.39200","5.61609","0.00452"
"67.48800","5.62404","0.00509"
"67.58400","5.63211","0.00453"
"67.68000","5.64019","0.00464"
"67.77600","5.64820","0.00486"
"67.87200","5.65615","0.00472"
"67.96800","5.66410","0.00502"
"68.06400","5.67205","0.00488"
"68.16000","5.68013","0.00502"
"68.25600","5.68814","0.00515"
"68.35200","5.69615","0.00471"
"68.44800","5.70410","0.00500"
"68.54400","5.71205","0.00493"
"68.64000","5.72012","0.00485"
"68.73600","5.72814","0.00494"
"68.83200","5.73615","0.00550"
"68.92800","5.74416","0.00516"
"69.02400","5.75211","0.00531"
"69.12000","5.76012","0.00533"
"69.21600","5.76814","0.00508"
"69.31200","5.77615","0.00504"
"69.40800","5.78422","0.00549"
"69.50400","5.79211","0.00475"
"69.60000","5.80012","0.00541"
"69.69600","5.80814","0.00497"
"69.79200","5.81615","0.00470"
"69.88800","5.82416","0.00510"
"69.98400","5.83217","0.00494"
"70.08000","5.84012","0.00476"
"70.17600","5.84813","0.00435"
"70.27200","5.85615","0.00541"
"70.36800","5.86410","0.00528"
"70.46400","5.87217","0.00518"
"70.56000","5.88012","0.00546"
"70.65600","5.88807","0.00476"
"70.75200","5.89614","0.00502"
"70.84800","5.90410","0.00556"
"70.94400","5.91211","0.00474"
"71.04000","5.92012","0.00522"
"71.13600","5.92813","0.00544"
"71.23200","5.93602","0.00501"
"71.32800","5.94410","0.00514"
"71.42400","5.95217","0.00508"
"71.52000","5.96012","0.00502"
"71.61600","5.96813","0.00574"
"71.71200","5.97614","0.00515"
"71.80800","5.98410","0.00550"
"71.90400","5.99211","0.00562"
"72.00000","6.00018","0.00503"
"72.09600","6.00819","0.00526"
"72.19200","6.01614","0.00531"
"72.28800","6.02409","0.00509"
"72.38400","6.03217","0.00548"
"72.48000","6.04018","0.00464"
"72.57600","6.04813","0.00501"
"72.67200","6.05614","0.00542"
"72.76800","6.06409","0.00495"
"72.86400","6.07211","0.00565"
"72.96000","6.08012","0.00574"
"73.05600","6.08813","0.00521"
"73.15200","6.09614","0.00503"
"73.24800","6.10409","0.00518"
"73.34400","6.11210","0.00513"
"73.44000","6.12012","0.00532"
"73.53600","6.12813","0.00581"
"73.63200","6.13614","0.00584"
"73.72800","6.14415","0.00534"
"73.82400","6.15210","0.00587"
"73.92000","6.16006","0.00493"
"74.01600","6.16813","0.00550"
"74.11200","6.17614","0.00544"
"74.20800","6.18415","0.00563"
"74.30400","6.19222","0.00493"
"74.40000","6.20011","0.00511"
"74.49600","6.20813","0.00576"
"74.59200","6.21620","0.00455"
"74.68800","6.22415","0.00539"
"74.78400","6.23216","0.00531"
"74.88000","6.24017","0.00567"
"74.97600","6.24807","0.00531"
"75.07200","6.25608","0.00593"
"75.16800","6.26421","0.00560"
"75.26400","6.27216","0.00556"
"75.36000","6.28011","0.00518"
"75.45600","6.28812","0.00612"
"75.55200","6.29608","0.00541"
"75.64800","6.30415","0.00560"
"75.74400","6.31216","0.00562"
"75.84000","6.32017","0.00583"
"75.93600","6.32812","0.00529"
"76.03200","6.33608","0.00600"
"76.12800","6.34409","0.00587"
"76.22400","6.35216","0.00592"
"76.32000","6.36011","0.00533"
"76.41600","6.36812","0.00576"
"76.51200","6.37608","0.00555"
"76.60800","6.38409","0.00561"
"76.70400","6.39210","0.00617"
"76.80000","6.40017","0.00598"
"76.89600","6.40818","0.00587"
"76.99200","6.41619","0.00585"
"77.08800","6.42409","0.00607"
"77.18400","6.43216","0.00550"
"77.28000","6.44017","0.00637"
"77.37600","6.44812","0.00586"
"77.47200","6.45619","0.00535"
"77.56800","6.46415","0.00536"
"77.66400","6.47210","0.00591"
"77.76000","6.48011","0.00587"
"77.85600","6.48812","0.00621"
"77.95200","6.49613","0.00572"
"78.04800","6.50420","0.00568"
"78.14400","6.51210","0.00598"
"78.24000","6.52005","0.00582"
"78.33600","6.52818","0.00579"
"78.43200","6.53613","0.00478"
"78.52800","6.54414","0.00579"
"78.62400","6.55216","0.00547"
"78.72000","6.56011","0.00587"
"78.81600","6.56812","0.00624"
"78.91200","6.57613","0.00604"
"79.00800","6.58414","0.00661"
"79.10400","6.59215","0.00627"
"79.20000","6.60011","0.00559"
"79.29600","6.60812","0.00561"
"79.39200","6.61613","0.00609"
"79.48800","6.62414","0.00630"
"79.58400","6.63215","0.00591"
"79.68000","6.64017","0.00572"
"79.77600","6.64812","0.00621"
"79.87200","6.65613","0.00597"
"79.96800","6.66414","0.00585"
"80.06400","6.67215","0.00607"
"80.16000","6.68016","0.00588"
"80.25600","6.68818","0.00684"
"80.35200","6.69613","0.00588"
"80.44800","6.70414","0.00627"
"80.54400","6.71215","0.00597"
"80.64000","6.72016","0.00566"
"80.73600","6.72818","0.00618"
"80.83200","6.73607","0.00633"
"80.92800","6.74408","0.00633"
"81.02400","6.75209","0.00622"
"81.12000","6.76010","0.00630"
"81.21600","6.76812","0.00631"
"81.31200","6.77613","0.00660"
"81.40800","6.78408","0.00572"
"81.50400","6.79209","0.00646"
"81.60000","6.80016","0.00649"
"81.69600","6.80817","0.00665"
"81.79200","6.81619","0.00553"
"81.88800","6.82414","0.00664"
"81.98400","6.83209","0.00619"
"82.08000","6.84016","0.00616"
"82.17600","6.84817","0.00608"
"82.27200","6.85613","0.00622"
"82.36800","6.86414","0.00617"
"82.46400","6.87215","0.00568"
"82.56000","6.88010","0.00631"
"82.65600","6.88817","0.00654"
"82.75200","6.89618","0.00677"
"82.84800","6.90414","0.00689"
"82.94400","6.91215","0.00693"
"83.04000","6.92010","0.00641"
"83.13600","6.92811","0.00631"
"83.23200","6.93612","0.00671"
"83.32800","6.94414","0.00671"
"83.42400","6.95215","0.00654"
"83.52000","6.96010","0.00601"
"83.61600","6.96811","0.00691"
"83.71200","6.97612","0.00658"
"83.80800","6.98413","0.00673"
"83.90400","6.99215","0.00624"
"84.00000","7.00016","0.00639"
"84.09600","7.00811","0.00637"
"84.19200","7.01612","0.00683"
"84.28800","7.02413","0.00671"
"84.38400","7.03215","0.00604"
"84.48000","7.04016","0.00641"
"84.57600","7.04811","0.00688"
"84.67200","7.05606","0.00618"
"84.76800","7.06419","0.00683"
"84.86400","7.07221","0.00757"
"84.96000","7.08016","0.00699"
"85.05600","7.08817","0.00660"
"85.15200","7.09612","0.00633"
"85.24800","7.10407","0.00683"
"85.34400","7.11214","0.00636"
"85.44000","7.12016","0.00676"
"85.53600","7.12817","0.00685"
"85.63200","7.13618","0.00673"
"85.72800","7.14413","0.00651"
"85.82400","7.15208","0.00722"
"85.92000","7.16016","0.00708"
"86.01600","7.16817","0.00677"
"86.11200","7.17618","0.00664"
"86.20800","7.18407","0.00667"
"86.30400","7.19202","0.00712"
"86.40000","7.20015","0.00737"
"86.49600","7.20823","0.00746"
"86.59200","7.21618","0.00723"
"86.68800","7.22413","0.00713"
"86.78400","7.23214","0.00679"
"86.88000","7.24009","0.00744"
"86.97600","7.24811","0.00654"
"87.07200","7.25618","0.00750"
"87.16800","7.26413","0.00702"
"87.26400","7.27214","0.00731"
"87.36000","7.28009","0.00704"
"87.45600","7.28811","0.00687"
"87.55200","7.29612","0.00646"
"87.64800","7.30419","0.00644"
"87.74400","7.31214","0.00729"
"87.84000","7.32009","0.00695"
"87.93600","7.32810","0.00732"
"88.03200","7.33612","0.00722"
"88.12800","7.34413","0.00725"
"88.22400","7.35220","0.00734"
"88.32000","7.36015","0.00702"
"88.41600","7.36810","0.00722"
"88.51200","7.37612","0.00712"
"88.60800","7.38413","0.00702"
"88.70400","7.39214","0.00702"
"88.80000","7.40015","0.00728"
"88.89600","7.40810","0.00734"
"88.99200","7.41605","0.00792"
"89.08800","7.42413","0.00718"
"89.18400","7.43214","0.00775"
"89.28000","7.44015","0.00769"
"89.37600","7.44810","0.00707"
"89.47200","7.45605","0.00727"
"89.56800","7.46407","0.00727"
"89.66400","7.47214","0.00757"
"89.76000","7.48009","0.00740"
"89.85600","7.48816","0.00754"
"89.95200","7.49617","0.00723"
"90.04800","7.50412","0.00747"
"90.14400","7.51214","0.00696"
"90.24000","7.52021","0.00738"
"90.33600","7.52810","0.00764"
"90.43200","7.53611","0.00686"
"90.52800","7.54412","0.00786"
"90.62400","7.55208","0.00796"
"90.72000","7.56015","0.00717"
"90.81600","7.56816","0.00772"
"90.91200","7.57617","0.00713"
"91.00800","7.58412","0.00777"
"91.10400","7.59213","0.00736"
"91.20000","7.60009","0.00721"
"91.29600","7.60810","0.00779"
"91.39200","7.61617","0.00773"
"91.48800","7.62412","0.00769"
"91.58400","7.63213","0.00801"
"91.68000","7.64009","0.00767"
"91.77600","7.64810","0.00790"
"91.87200","7.65617","0.00790"
"91.96800","7.66418","0.00733"
"92.06400","7.67213","0.00758"
"92.16000","7.68009","0.00778"
"92.25600","7.68816","0.00784"
"92.35200","7.69617","0.00791"
"92.44800","7.70412","0.00719"
"92.54400","7.71213","0.00785"
"92.64000","7.72014","0.00839"
"92.73600","7.72810","0.00717"
"92.83200","7.73611","0.00775"
"92.92800","7.74418","0.00776"
"93.02400","7.75219","0.00756"
"93.12000","7.76014","0.00807"
"93.21600","7.76810","0.00793"
"93.31200","7.77611","0.00832"
"93.40800","7.78412","0.00768"
"93.50400","7.79213","0.00791"
"93.60000","7.80014","0.00747"
"93.69600","7.80816","0.00765"
"93.79200","7.81611","0.00826"
"93.88800","7.82406","0.00808"
"93.98400","7.83219","0.00762"
"94.08000","7.84020","0.00827"
"94.17600","7.84815","0.00891"
"94.27200","7.85616","0.00818"
"94.36800","7.86406","0.00814"
"94.46400","7.87207","0.00861"
"94.56000","7.88020","0.00852"
"94.65600","7.88815","0.00792"
"94.75200","7.89610","0.00791"
"94.84800","7.90412","0.00791"
"94.94400","7.91207","0.00823"
"95.04000","7.92008","0.00815"
"95.13600","7.92815","0.00806"
"95.23200","7.93616","0.00761"
"95.32800","7.94412","0.00867"
"95.42400","7.95207","0.00801"
"95.52000","7.96014","0.00841"
"95.61600","7.96815","0.00749"
"95.71200","7.97616","0.00900"
"95.80800","7.98417","0.00808"
"95.90400","7.99207","0.00871"
"96.00000","8.00008","0.00854"
"96.09600","8.00809","0.00904"
"96.19200","8.01610","0.00797"
"96.28800","8.02417","0.00828"
"96.38400","8.03219","0.00778"
"96.48000","8.04014","0.00908"
"96.57600","8.04809","0.00804"
"96.67200","8.05616","0.00890"
"96.76800","8.06411","0.00878"
"96.86400","8.07218","0.00834"
"96.96000","8.08008","0.00881"
"97.05600","8.08809","0.00909"
"97.15200","8.09610","0.00858"
"97.24800","8.10417","0.00819"
"97.34400","8.11218","0.00843"
"97.44000","8.12014","0.00866"
"97.53600","8.12815","0.00848"
"97.63200","8.13610","0.00825"
"97.72800","8.14417","0.00841"
"97.82400","8.15218","0.00894"
"97.92000","8.16013","0.00935"
"98.01600","8.16815","0.00863"
"98.11200","8.17616","0.00871"
"98.20800","8.18411","0.00859"
"98.30400","8.19212","0.00861"
"98.40000","8.20019","0.00877"
"98.49600","8.20815","0.00841"
"98.59200","8.21610","0.00870"
"98.68800","8.22411","0.00850"
"98.78400","8.23212","0.00828"
"98.88000","8.24019","0.00925"
"98.97600","8.24815","0.00868"
"99.07200","8.25610","0.00888"
"99.16800","8.26411","0.00918"
"99.26400","8.27212","0.00890"
"99.36000","8.28013","0.00895"
"99.45600","8.28814","0.00863"
"99.55200","8.29616","0.00882"
"99.64800","8.30411","0.00855"
"99.74400","8.31206","0.00891"
"99.84000","8.32013","0.00928"
"99.93600","8.32814","0.00913"
"100.03200","8.33616","0.00936"
"100.12800","8.34417","0.00925"
"100.22400","8.35206","0.00905"
"100.32000","8.36013","0.00917"
"100.41600","8.36814","0.00936"
"100.51200","8.37615","0.00945"
"100.60800","8.38417","0.00934"
"100.70400","8.39218","0.00906"
"100.80000","8.40013","0.00839"
"100.89600","8.40814","0.00876"
"100.99200","8.41621","0.00944"
"101.08800","8.42417","0.00907"
"101.18400","8.43218","0.00927"
"101.28000","8.44013","0.00949"
"101.37600","8.44802","0.00926"
"101.47200","8.45615","0.00964"
"101.56800","8.46416","0.00882"
"101.66400","8.47218","0.00963"
"101.76000","8.48013","0.00878"
"101.85600","8.48808","0.00965"
"101.95200","8.49609","0.00916"
"102.04800","8.50416","0.00919"
"102.14400","8.51218","0.00925"
"102.24000","8.52013","0.00942"
"102.33600","8.52808","0.00960"
"102.43200","8.53609","0.00952"
"102.52800","8.54410","0.00966"
"102.62400","8.55217","0.00934"
"102.72000","8.56019","0.00934"
"102.81600","8.56814","0.00992"
"102.91200","8.57609","0.00967"
"103.00800","8.58410","0.00955"
"103.10400","8.59211","0.00954"
"103.20000","8.60013","0.00973"
"103.29600","8.60820","0.00907"
"103.39200","8.61609","0.00926"
"103.48800","8.62410","0.00916"
"103.58400","8.63211","0.00942"
"103.68000","8.64013","0.00957"
"103.77600","8.64814","0.00986"
"103.87200","8.65621","0.00946"
"103.96800","8.66410","0.00966"
"104.06400","8.67205","0.00989"
"104.16000","8.68013","0.00950"
"104.25600","8.68814","0.00952"
"104.35200","8.69621","0.00928"
"104.44800","8.70416","0.01025"
"104.54400","8.71211","0.00912"
"104.64000","8.72012","0.00952"
"104.73600","8.72814","0.00976"
"104.83200","8.73615","0.00969"
"104.92800","8.74422","0.00946"
"105.02400","8.75211","0.01060"
"105.12000","8.76006","0.01009"
"105.21600","8.76814","0.00965"
"105.31200","8.77615","0.00976"
"105.40800","8.78416","0.01008"
"105.50400","8.79217","0.00992"
"105.60000","8.80012","0.00994"
"105.69600","8.80807","0.01018"
"105.79200","8.81615","0.00980"
"105.88800","8.82416","0.00949"
"105.98400","8.83217","0.00979"
"106.08000","8.84012","0.00972"
"106.17600","8.84813","0.01006"
"106.27200","8.85608","0.01081"
"106.36800","8.86416","0.00998"
"106.46400","8.87211","0.01025"
"106.56000","8.88012","0.01025"
"106.65600","8.88807","0.00908"
"106.75200","8.89608","0.00979"
"106.84800","8.90410","0.00947"
"106.94400","8.91211","0.00951"
"107.04000","8.92018","0.00983"
"107.13600","8.92813","0.01012"
"107.23200","8.93608","0.00995"
"107.32800","8.94410","0.01043"
"107.42400","8.95217","0.00955"
"107.52000","8.96012","0.00987"
"107.61600","8.96813","0.00996"
"107.71200","8.97608","0.00922"
"107.80800","8.98409","0.00962"
"107.90400","8.99211","0.00972"
"108.00000","9.00018","0.01010"
"108.09600","9.00819","0.00956"
"108.19200","9.01614","0.00986"
"108.28800","9.02409","0.00975"
"108.38400","9.03211","0.00935"
"108.48000","9.04012","0.00933"
"108.57600","9.04813","0.00951"
"108.67200","9.05614","0.00960"
"108.76800","9.06409","0.01009"
"108.86400","9.07205","0.01005"
"108.96000","9.08012","0.01017"
"109.05600","9.08813","0.00996"
"109.15200","9.09614","0.00924"
"109.24800","9.10415","0.00978"
"109.34400","9.11210","0.01045"
"109.44000","9.12012","0.01015"
"109.53600","9.12813","0.00993"
"109.63200","9.13620","0.00999"
"109.72800","9.14415","0.00958"
"109.82400","9.15210","0.00979"
"109.92000","9.16006","0.01014"
"110.01600","9.16813","0.00970"
"110.11200","9.17614","0.01026"
"110.20800","9.18415","0.00997"
"110.30400","9.19216","0.01025"
"110.40000","9.20012","0.00955"
"110.49600","9.20807","0.01019"
"110.59200","9.21614","0.00984"
"110.68800","9.22415","0.00948"
"110.78400","9.23216","0.00999"
"110.88000","9.24017","0.01011"
"110.97600","9.24813","0.01006"
"111.07200","9.25608","0.00990"
"111.16800","9.26415","0.00955"
"111.26400","9.27210","0.00977"
"111.36000","9.28017","0.00982"
"111.45600","9.28818","0.00987"
"111.55200","9.29614","0.01033"
"111.64800","9.30415","0.00978"
"111.74400","9.31216","0.01060"
"111.84000","9.32017","0.00958"
"111.93600","9.32818","0.01039"
"112.03200","9.33613","0.01005"
"112.12800","9.34409","0.00992"
"112.22400","9.35210","0.01035"
"112.32000","9.36011","0.01013"
"112.41600","9.36812","0.01042"
"112.51200","9.37613","0.00988"
"112.60800","9.38409","0.01008"
"112.70400","9.39210","0.00967"
"112.80000","9.40011","0.01026"
"112.89600","9.40818","0.00996"
"112.99200","9.41613","0.00953"
"113.08800","9.42409","0.01082"
"113.18400","9.43210","0.01044"
"113.28000","9.44011","0.01010"
"113.37600","9.44812","0.01044"
"113.47200","9.45619","0.01044"
"113.56800","9.46414","0.01020"
"113.66400","9.47210","0.01076"
"113.76000","9.48011","0.01103"
"113.85600","9.48812","0.01055"
"113.95200","9.49613","0.01036"
"114.04800","9.50420","0.00970"
"114.14400","9.51216","0.00987"
"114.24000","9.52005","0.01027"
"114.33600","9.52812","0.00993"
"114.43200","9.53613","0.01022"
"114.52800","9.54414","0.01030"
"114.62400","9.55222","0.01086"
"114.72000","9.56017","0.01058"
"114.81600","9.56812","0.01057"
"114.91200","9.57613","0.01081"
"115.00800","9.58414","0.01044"
"115.10400","9.59215","0.01089"
"115.20000","9.60017","0.01048"
"115.29600","9.60812","0.01054"
"115.39200","9.61607","0.01094"
"115.48800","9.62414","0.01053"
"115.58400","9.63209","0.01074"
"115.68000","9.64017","0.01097"
"115.77600","9.64812","0.01072"
"115.87200","9.65613","0.01121"
"115.96800","9.66408","0.01116"
"116.06400","9.67215","0.01071"
"116.16000","9.68017","0.01051"
"116.25600","9.68818","0.01051"
"116.35200","9.69613","0.01118"
"116.44800","9.70408","0.01046"
"116.54400","9.71209","0.01113"
"116.64000","9.72016","0.01100"
"116.73600","9.72812","0.01085"
"116.83200","9.73607","0.01102"
"116.92800","9.74414","0.01118"
"117.02400","9.75209","0.01132"
"117.12000","9.76016","0.01107"
"117.21600","9.76812","0.01056"
"117.31200","9.77619","0.01081"
"117.40800","9.78414","0.01076"
"117.50400","9.79209","0.01047"
"117.60000","9.80010","0.01121"
"117.69600","9.80817","0.01102"
"117.79200","9.81619","0.01192"
"117.88800","9.82414","0.01128"
"117.98400","9.83209","0.01052"
"118.08000","9.84016","0.01137"
"118.17600","9.84817","0.01128"
"118.27200","9.85612","0.01143"
"118.36800","9.86420","0.01135"
"118.46400","9.87209","0.01149"
"118.56000","9.88010","0.01150"
"118.65600","9.88811","0.01132"
"118.75200","9.89612","0.01145"
"118.84800","9.90414","0.01156"
"118.94400","9.91215","0.01135"
"119.04000","9.92010","0.01105"
"119.13600","9.92805","0.01124"
"119.23200","9.93612","0.01168"
"119.32800","9.94414","0.01165"
"119.42400","9.95215","0.01201"
"119.52000","9.96016","0.01143"
"119.61600","9.96811","0.01119"
"119.71200","9.97606","0.01152"
"119.80800","9.98413","0.01219"
"119.90400","9.99215","0.01154"
"120.00000","10.00016","0.01184"
"120.09600","10.00817","0.01145"
"120.19200","10.01612","0.01200"
"120.28800","10.02419","0.01207"
"120.38400","10.03221","0.01195"
"120.48000","10.04016","0.01193"
"120.57600","10.04811","0.01218"
"120.67200","10.05612","0.01174"
"120.76800","10.06413","0.01195"
"120.86400","10.07209","0.01225"
"120.96000","10.08016","0.01207"
"121.05600","10.08817","0.01238"
"121.15200","10.09612","0.01196"
"121.24800","10.10407","0.01193"
"121.34400","10.11214","0.01186"
"121.44000","10.12016","0.01245"
"121.53600","10.12811","0.01183"
"121.63200","10.13612","0.01258"
"121.72800","10.14407","0.01210"
"121.82400","10.15208","0.01168"
"121.92000","10.16010","0.01188"
"122.01600","10.16811","0.01266"
"122.11200","10.17618","0.01225"
"122.20800","10.18413","0.01259"
"122.30400","10.19208","0.01229"
"122.40000","10.20015","0.01222"
"122.49600","10.20817","0.01252"
"122.59200","10.21612","0.01261"
"122.68800","10.22419","0.01183"
"122.78400","10.23214","0.01270"
"122.88000","10.24003","0.01196"
"122.97600","10.24811","0.01251"
"123.07200","10.25618","0.01284"
"123.16800","10.26413","0.01234"
"123.26400","10.27220","0.01208"
"123.36000","10.28015","0.01260"
"123.45600","10.28810","0.01312"
"123.55200","10.29612","0.01295"
"123.64800","10.30419","0.01209"
"123.74400","10.31214","0.01333"
"123.84000","10.32015","0.01271"
"123.93600","10.32810","0.01189"
"124.03200","10.33612","0.01231"
"124.12800","10.34413","0.01284"
"124.22400","10.35214","0.01298"
"124.32000","10.36015","0.01293"
"124.41600","10.36810","0.01296"
"124.51200","10.37612","0.01258"
"124.60800","10.38413","0.01299"
"124.70400","10.39214","0.01267"
"124.80000","10.40015","0.01279"
"124.89600","10.40810","0.01245"
"124.99200","10.41611","0.01321"
"125.08800","10.42413","0.01276"
"125.18400","10.43214","0.01320"
"125.28000","10.44015","0.01335"
"125.37600","10.44810","0.01336"
"125.47200","10.45611","0.01289"
"125.56800","10.46413","0.01351"
"125.66400","10.47214","0.01285"
"125.76000","10.48015","0.01320"
"125.85600","10.48810","0.01353"
"125.95200","10.49617","0.01364"
"126.04800","10.50406","0.01327"
"126.14400","10.51208","0.01296"
"126.24000","10.52015","0.01342"
"126.33600","10.52810","0.01342"
"126.43200","10.53611","0.01322"
"126.52800","10.54418","0.01298"
"126.62400","10.55208","0.01359"
"126.72000","10.56009","0.01346"
"126.81600","10.56822","0.01356"
"126.91200","10.57611","0.01328"
"127.00800","10.58412","0.01342"
"127.10400","10.59208","0.01317"
"127.20000","10.60003","0.01371"
"127.29600","10.60810","0.01319"
"127.39200","10.61617","0.01317"
"127.48800","10.62418","0.01367"
"127.58400","10.63213","0.01343"
"127.68000","10.64009","0.01349"
"127.77600","10.64810","0.01318"
"127.87200","10.65617","0.01343"
"127.96800","10.66418","0.01329"
"128.06400","10.67213","0.01346"
"128.16000","10.68014","0.01370"
"128.25600","10.68810","0.01367"
"128.35201","10.69611","0.01343"
"128.44800","10.70412","0.01369"
"128.54401","10.71219","0.01420"
"128.64000","10.72014","0.01336"
"128.73599","10.72810","0.01412"
"128.83200","10.73611","0.01365"
"128.92799","10.74412","0.01380"
"129.02400","10.75219","0.01369"
"129.12000","10.76014","0.01421"
"129.21600","10.76810","0.01413"
"129.31200","10.77611","0.01380"
"129.40800","10.78412","0.01381"
"129.50400","10.79213","0.01394"
"129.60001","10.80014","0.01362"
"129.69600","10.80815","0.01367"
"129.79201","10.81611","0.01381"
"129.88800","10.82406","0.01416"
"129.98399","10.83213","0.01386"
"130.08000","10.84014","0.01399"
"130.17599","10.84815","0.01444"
"130.27200","10.85617","0.01402"
"130.36800","10.86412","0.01456"
"130.46400","10.87207","0.01447"
"130.56000","10.88014","0.01403"
"130.65601","10.88815","0.01451"
"130.75200","10.89616","0.01383"
"130.84801","10.90418","0.01393"
"130.94400","10.91207","0.01397"
"131.03999","10.92014","0.01412"
"131.13600","10.92821","0.01410"
"131.23199","10.93616","0.01434"
"131.32800","10.94412","0.01497"
"131.42400","10.95213","0.01443"
"131.52000","10.96008","0.01400"
"131.61600","10.96815","0.01417"
"131.71201","10.97616","0.01424"
"131.80800","10.98411","0.01444"
"131.90401","10.99213","0.01442"
"132.00000","11.00014","0.01475"
"132.09599","11.00809","0.01465"
"132.19200","11.01610","0.01418"
"132.28799","11.02417","0.01521"
"132.38400","11.03213","0.01441"
"132.48000","11.04008","0.01475"
"132.57600","11.04809","0.01469"
"132.67200","11.05610","0.01476"
"132.76801","11.06417","0.01455"
"132.86400","11.07218","0.01490"
"132.96001","11.08014","0.01470"
"133.05600","11.08815","0.01497"
"133.15199","11.09610","0.01464"
"133.24800","11.10411","0.01490"
"133.34399","11.11218","0.01458"
"133.44000","11.12014","0.01491"
"133.53600","11.12809","0.01527"
"133.63200","11.13610","0.01489"
"133.72800","11.14411","0.01477"
"133.82401","11.15218","0.01533"
"133.92000","11.16014","0.01501"
"134.01601","11.16815","0.01553"
"134.11200","11.17616","0.01455"
"134.20799","11.18405","0.01536"
"134.30400","11.19212","0.01525"
"134.39999","11.20013","0.01563"
"134.49600","11.20815","0.01498"
"134.59200","11.21616","0.01534"
"134.68800","11.22411","0.01519"
"134.78400","11.23206","0.01494"
"134.88000","11.24013","0.01558"
"134.97600","11.24815","0.01539"
"135.07201","11.25616","0.01533"
"135.16800","11.26411","0.01643"
"135.26401","11.27206","0.01556"
"135.36000","11.28013","0.01549"
"135.45599","11.28820","0.01521"
"135.55200","11.29616","0.01508"
"135.64799","11.30411","0.01581"
"135.74400","11.31212","0.01500"
"135.84000","11.32007","0.01525"
"135.93600","11.32814","0.01507"
"136.03200","11.33615","0.01568"
"136.12801","11.34417","0.01493"
"136.22400","11.35212","0.01562"
"136.32001","11.36007","0.01563"
"136.41600","11.36814","0.01550"
"136.51199","11.37615","0.01582"
"136.60800","11.38411","0.01585"
"136.70399","11.39212","0.01504"
"136.80000","11.40013","0.01562"
"136.89600","11.40808","0.01483"
"136.99200","11.41609","0.01507"
"137.08800","11.42417","0.01541"
"137.18401","11.43218","0.01530"
"137.28000","11.44013","0.01578"
"137.37601","11.44814","0.01575"
"137.47200","11.45609","0.01581"
"137.56799","11.46416","0.01518"
"137.66400","11.47212","0.01585"
"137.75999","11.48013","0.01542"
"137.85600","11.48814","0.01551"
"137.95200","11.49603","0.01566"
"138.04800","11.50410","0.01500"
"138.14400","11.51212","0.01555"
"138.24001","11.52013","0.01555"
"138.33600","11.52814","0.01596"
"138.43201","11.53609","0.01615"
"138.52800","11.54404","0.01542"
"138.62399","11.55218","0.01616"
"138.72000","11.56019","0.01614"
"138.81599","11.56820","0.01563"
"138.91200","11.57615","0.01638"
"139.00800","11.58410","0.01640"
"139.10400","11.59211","0.01626"
"139.20000","11.60013","0.01584"
"139.29601","11.60814","0.01607"
"139.39200","11.61615","0.01606"
"139.48801","11.62410","0.01656"
"139.58400","11.63211","0.01607"
"139.67999","11.64013","0.01661"
"139.77600","11.64814","0.01621"
"139.87199","11.65615","0.01680"
"139.96800","11.66410","0.01650"
"140.06400","11.67205","0.01652"
"140.16000","11.68013","0.01678"
"140.25600","11.68814","0.01593"
"140.35201","11.69615","0.01634"
"140.44800","11.70416","0.01659"
"140.54401","11.71211","0.01656"
"140.64000","11.72012","0.01673"
"140.73599","11.72814","0.01657"
"140.83200","11.73615","0.01688"
"140.92799","11.74410","0.01690"
"141.02400","11.75211","0.01639"
"141.12000","11.76012","0.01673"
"141.21600","11.76808","0.01704"
"141.31200","11.77615","0.01739"
"141.40800","11.78410","0.01725"
"141.50400","11.79211","0.01677"
"141.60001","11.80018","0.01719"
"141.69600","11.80807","0.01699"
"141.79201","11.81615","0.01717"
"141.88800","11.82422","0.01735"
"141.98399","11.83211","0.01709"
"142.08000","11.84012","0.01713"
"142.17599","11.84813","0.01801"
"142.27200","11.85609","0.01716"
"142.36800","11.86410","0.01747"
"142.46400","11.87217","0.01736"
"142.56000","11.88018","0.01776"
"142.65601","11.88807","0.01753"
"142.75200","11.89608","0.01735"
"142.84801","11.90410","0.01802"
"142.94400","11.91217","0.01751"
"142.99001","11.91599","0.01795"