File: Force_trajectories/161104/Specimen_RawData_5.csv
End date,"11/4/2016"
Specimen label,""
Maximum Load,"1.49282",N

Time,Extension,Load
(s),(mm),(N)
"0.00000","0.00000","0.00006"
"0.13200","0.00622","-0.00022"
"0.26400","0.02045","0.00069"
"0.39600","0.03312","0.00077"
"0.52800","0.04424","0.00062"
"0.66000","0.05513","0.00070"
"0.79200","0.06613","0.00075"
"0.92400","0.07719","0.00057"
"1.05600","0.08819","0.00136"
"1.18800","0.09919","0.00109"
"1.32000","0.11013","0.00125"
"1.45200","0.12119","0.00106"
"1.58400","0.13213","0.00081"
"1.71600","0.14314","0.00068"
"1.84800","0.15414","0.00085"
"1.98000","0.16514","0.00085"
"2.11200","0.17614","0.00135"
"2.24400","0.18714","0.00104"
"2.37600","0.19808","0.00076"
"2.50800","0.20914","0.00122"
"2.64000","0.22015","0.00067"
"2.77200","0.23121","0.00111"
"2.90400","0.24215","0.00152"
"3.03600","0.25315","0.00101"
"3.16800","0.26415","0.00106"
"3.30000","0.27515","0.00100"
"3.43200","0.28609","0.00105"
"3.56400","0.29709","0.00106"
"3.69600","0.30816","0.00189"
"3.82800","0.31910","0.00109"
"3.96000","0.33010","0.00108"
"4.09200","0.34110","0.00118"
"4.22400","0.35216","0.00159"
"4.35600","0.36316","0.00148"
"4.48800","0.37410","0.00142"
"4.62000","0.38510","0.00179"
"4.75200","0.39617","0.00141"
"4.88400","0.40717","0.00081"
"5.01600","0.41805","0.00105"
"5.14800","0.42905","0.00103"
"5.28000","0.44017","0.00160"
"5.41200","0.45117","0.00076"
"5.54400","0.46211","0.00156"
"5.67600","0.47311","0.00116"
"5.80800","0.48418","0.00149"
"5.94000","0.49518","0.00106"
"6.07200","0.50612","0.00093"
"6.20400","0.51712","0.00167"
"6.33600","0.52812","0.00128"
"6.46800","0.53918","0.00156"
"6.60000","0.55012","0.00186"
"6.73200","0.56106","0.00158"
"6.86400","0.57213","0.00142"
"6.99600","0.58319","0.00171"
"7.12800","0.59413","0.00081"
"7.26000","0.60507","0.00139"
"7.39200","0.61607","0.00135"
"7.52400","0.62713","0.00146"
"7.65600","0.63807","0.00191"
"7.78800","0.64908","0.00137"
"7.92000","0.66014","0.00126"
"8.05200","0.67114","0.00176"
"8.18400","0.68208","0.00097"
"8.31600","0.69302","0.00166"
"8.44800","0.70414","0.00151"
"8.58000","0.71508","0.00162"
"8.71200","0.72614","0.00204"
"8.84400","0.73709","0.00155"
"8.97600","0.74815","0.00165"
"9.10800","0.75915","0.00160"
"9.24000","0.77015","0.00147"
"9.37200","0.78109","0.00145"
"9.50400","0.79215","0.00160"
"9.63600","0.80315","0.00202"
"9.76800","0.81409","0.00198"
"9.90000","0.82510","0.00162"
"10.03200","0.83610","0.00198"
"10.16400","0.84710","0.00137"
"10.29600","0.85810","0.00159"
"10.42800","0.86910","0.00208"
"10.56000","0.88010","0.00223"
"10.69200","0.89110","0.00233"
"10.82400","0.90210","0.00215"
"10.95600","0.91311","0.00233"
"11.08800","0.92411","0.00194"
"11.22000","0.93511","0.00223"
"11.35200","0.94617","0.00266"
"11.48400","0.95705","0.00219"
"11.61600","0.96805","0.00217"
"11.74800","0.97911","0.00162"
"11.88000","0.99011","0.00220"
"12.01200","1.00106","0.00184"
"12.14400","1.01206","0.00247"
"12.27600","1.02312","0.00227"
"12.40800","1.03412","0.00233"
"12.54000","1.04512","0.00250"
"12.67200","1.05612","0.00192"
"12.80400","1.06712","0.00252"
"12.93600","1.07812","0.00251"
"13.06800","1.08907","0.00226"
"13.20000","1.10007","0.00263"
"13.33200","1.11119","0.00258"
"13.46400","1.12213","0.00237"
"13.59600","1.13313","0.00299"
"13.72800","1.14401","0.00238"
"13.86000","1.15513","0.00242"
"13.99200","1.16614","0.00261"
"14.12400","1.17714","0.00270"
"14.25600","1.18814","0.00252"
"14.38800","1.19914","0.00220"
"14.52000","1.21020","0.00262"
"14.65200","1.22108","0.00303"
"14.78400","1.23202","0.00295"
"14.91600","1.24308","0.00320"
"15.04800","1.25415","0.00263"
"15.18000","1.26515","0.00279"
"15.31200","1.27609","0.00291"
"15.44400","1.28709","0.00309"
"15.57600","1.29815","0.00325"
"15.70800","1.30915","0.00323"
"15.84000","1.32009","0.00313"
"15.97200","1.33109","0.00262"
"16.10400","1.34216","0.00314"
"16.23600","1.35316","0.00326"
"16.36800","1.36404","0.00311"
"16.50000","1.37510","0.00281"
"16.63200","1.38610","0.00301"
"16.76400","1.39710","0.00260"
"16.89600","1.40804","0.00289"
"17.02800","1.41910","0.00298"
"17.16000","1.43011","0.00321"
"17.29200","1.44111","0.00338"
"17.42400","1.45211","0.00298"
"17.55600","1.46311","0.00310"
"17.68800","1.47417","0.00275"
"17.82000","1.48511","0.00319"
"17.95200","1.49605","0.00316"
"18.08400","1.50706","0.00333"
"18.21600","1.51806","0.00337"
"18.34800","1.52912","0.00360"
"18.48000","1.54012","0.00351"
"18.61200","1.55112","0.00325"
"18.74400","1.56212","0.00326"
"18.87600","1.57312","0.00384"
"19.00800","1.58412","0.00331"
"19.14000","1.59513","0.00349"
"19.27200","1.60619","0.00356"
"19.40400","1.61713","0.00351"
"19.53600","1.62813","0.00387"
"19.66800","1.63907","0.00422"
"19.80000","1.65013","0.00351"
"19.93200","1.66113","0.00373"
"20.06400","1.67207","0.00363"
"20.19600","1.68308","0.00406"
"20.32800","1.69408","0.00372"
"20.46000","1.70514","0.00428"
"20.59200","1.71608","0.00413"
"20.72400","1.72708","0.00366"
"20.85600","1.73820","0.00424"
"20.98800","1.74914","0.00443"
"21.12000","1.76008","0.00428"
"21.25200","1.77109","0.00390"
"21.38400","1.78215","0.00476"
"21.51600","1.79315","0.00440"
"21.64800","1.80409","0.00432"
"21.78000","1.81503","0.00466"
"21.91200","1.82615","0.00387"
"22.04400","1.83715","0.00472"
"22.17600","1.84815","0.00511"
"22.30800","1.85904","0.00434"
"22.44000","1.87010","0.00451"
"22.57200","1.88116","0.00432"
"22.70400","1.89210","0.00433"
"22.83600","1.90304","0.00432"
"22.96800","1.91410","0.00436"
"23.10000","1.92516","0.00474"
"23.23200","1.93610","0.00483"
"23.36400","1.94705","0.00460"
"23.49600","1.95811","0.00469"
"23.62800","1.96911","0.00530"
"23.76000","1.98011","0.00458"
"23.89200","1.99105","0.00497"
"24.02400","2.00217","0.00475"
"24.15600","2.01317","0.00554"
"24.28800","2.02417","0.00510"
"24.42000","2.03512","0.00575"
"24.55200","2.04606","0.00484"
"24.68400","2.05706","0.00502"
"24.81600","2.06812","0.00493"
"24.94800","2.07906","0.00529"
"25.08000","2.09006","0.00452"
"25.21200","2.10112","0.00488"
"25.34400","2.11219","0.00505"
"25.47600","2.12307","0.00564"
"25.60800","2.13413","0.00590"
"25.74000","2.14513","0.00535"
"25.87200","2.15613","0.00517"
"26.00400","2.16707","0.00531"
"26.13600","2.17807","0.00547"
"26.26800","2.18907","0.00578"
"26.40000","2.20014","0.00567"
"26.53200","2.21108","0.00535"
"26.66400","2.22208","0.00598"
"26.79600","2.23314","0.00557"
"26.92800","2.24408","0.00590"
"27.06000","2.25508","0.00577"
"27.19200","2.26614","0.00631"
"27.32400","2.27720","0.00592"
"27.45600","2.28815","0.00613"
"27.58800","2.29915","0.00587"
"27.72000","2.31009","0.00592"
"27.85200","2.32109","0.00584"
"27.98400","2.33215","0.00591"
"28.11600","2.34309","0.00625"
"28.24800","2.35403","0.00613"
"28.38000","2.36509","0.00598"
"28.51200","2.37616","0.00638"
"28.64400","2.38710","0.00624"
"28.77600","2.39810","0.00570"
"28.90800","2.40916","0.00645"
"29.04000","2.42016","0.00630"
"29.17200","2.43116","0.00634"
"29.30400","2.44204","0.00636"
"29.43600","2.45310","0.00641"
"29.56800","2.46411","0.00630"
"29.70000","2.47511","0.00670"
"29.83200","2.48605","0.00749"
"29.96400","2.49711","0.00646"
"30.09600","2.50811","0.00670"
"30.22800","2.51911","0.00666"
"30.36000","2.53005","0.00651"
"30.49200","2.54117","0.00665"
"30.62400","2.55218","0.00743"
"30.75600","2.56318","0.00644"
"30.88800","2.57412","0.00683"
"31.02000","2.58512","0.00717"
"31.15200","2.59612","0.00683"
"31.28400","2.60712","0.00680"
"31.41600","2.61806","0.00676"
"31.54800","2.62913","0.00723"
"31.68000","2.64013","0.00728"
"31.81200","2.65113","0.00683"
"31.94400","2.66207","0.00720"
"32.07600","2.67313","0.00684"
"32.20800","2.68419","0.00752"
"32.34000","2.69519","0.00692"
"32.47200","2.70613","0.00795"
"32.60400","2.71714","0.00789"
"32.73600","2.72820","0.00710"
"32.86800","2.73914","0.00787"
"33.00000","2.75008","0.00792"
"33.13200","2.76102","0.00859"
"33.26400","2.77208","0.00777"
"33.39600","2.78314","0.00825"
"33.52800","2.79408","0.00862"
"33.66000","2.80509","0.00826"
"33.79200","2.81615","0.00815"
"33.92400","2.82721","0.00830"
"34.05600","2.83809","0.00838"
"34.18800","2.84909","0.00885"
"34.32000","2.86015","0.00889"
"34.45200","2.87109","0.00916"
"34.58400","2.88209","0.00865"
"34.71600","2.89304","0.00866"
"34.84800","2.90416","0.00867"
"34.98000","2.91510","0.00867"
"35.11200","2.92616","0.00854"
"35.24400","2.93704","0.00908"
"35.37600","2.94810","0.00922"
"35.50800","2.95910","0.00902"
"35.64000","2.97010","0.00879"
"35.77200","2.98111","0.00931"
"35.90400","2.99211","0.00920"
"36.03600","3.00311","0.00964"
"36.16800","3.01405","0.00955"
"36.30000","3.02505","0.01008"
"36.43200","3.03611","0.00984"
"36.56400","3.04711","0.00956"
"36.69600","3.05806","0.00946"
"36.82800","3.06912","0.00972"
"36.96000","3.08012","0.01020"
"37.09200","3.09118","0.01028"
"37.22400","3.10212","0.01023"
"37.35600","3.11306","0.00999"
"37.48800","3.12412","0.01009"
"37.62000","3.13512","0.01034"
"37.75200","3.14613","0.01041"
"37.88400","3.15707","0.01069"
"38.01600","3.16813","0.01022"
"38.14800","3.17913","0.00997"
"38.28000","3.19013","0.01009"
"38.41200","3.20107","0.01019"
"38.54400","3.21207","0.00932"
"38.67600","3.22313","0.01012"
"38.80800","3.23419","0.01045"
"38.94000","3.24508","0.01055"
"39.07200","3.25614","0.01043"
"39.20400","3.26720","0.01039"
"39.33600","3.27814","0.01076"
"39.46800","3.28908","0.01078"
"39.60000","3.30002","0.01049"
"39.73200","3.31108","0.01138"
"39.86400","3.32215","0.01126"
"39.99600","3.33315","0.01108"
"40.12800","3.34415","0.01181"
"40.26000","3.35515","0.01137"
"40.39200","3.36615","0.01171"
"40.52400","3.37709","0.01209"
"40.65600","3.38809","0.01155"
"40.78800","3.39915","0.01165"
"40.92000","3.41016","0.01184"
"41.05200","3.42110","0.01161"
"41.18400","3.43210","0.01211"
"41.31600","3.44310","0.01175"
"41.44800","3.45416","0.01247"
"41.58000","3.46510","0.01229"
"41.71200","3.47610","0.01202"
"41.84400","3.48710","0.01350"
"41.97600","3.49817","0.01306"
"42.10800","3.50911","0.01247"
"42.24000","3.52011","0.01287"
"42.37200","3.53111","0.01274"
"42.50400","3.54211","0.01267"
"42.63600","3.55311","0.01306"
"42.76800","3.56399","0.01335"
"42.90000","3.57511","0.01292"
"43.03200","3.58612","0.01341"
"43.16400","3.59718","0.01360"
"43.29600","3.60806","0.01294"
"43.42800","3.61912","0.01342"
"43.56000","3.63012","0.01353"
"43.69200","3.64112","0.01357"
"43.82400","3.65212","0.01349"
"43.95600","3.66313","0.01409"
"44.08800","3.67413","0.01366"
"44.22000","3.68519","0.01435"
"44.35200","3.69607","0.01393"
"44.48400","3.70713","0.01408"
"44.61600","3.71807","0.01387"
"44.74800","3.72907","0.01420"
"44.88000","3.74007","0.01514"
"45.01200","3.75108","0.01453"
"45.14400","3.76214","0.01450"
"45.27600","3.77314","0.01456"
"45.40800","3.78408","0.01521"
"45.54000","3.79514","0.01462"
"45.67200","3.80614","0.01488"
"45.80400","3.81714","0.01464"
"45.93600","3.82808","0.01520"
"46.06800","3.83909","0.01554"
"46.20000","3.85009","0.01616"
"46.33200","3.86115","0.01624"
"46.46400","3.87209","0.01565"
"46.59600","3.88315","0.01586"
"46.72800","3.89415","0.01591"
"46.86000","3.90515","0.01596"
"46.99200","3.91609","0.01621"
"47.12400","3.92710","0.01652"
"47.25600","3.93816","0.01664"
"47.38800","3.94916","0.01661"
"47.52000","3.96010","0.01639"
"47.65200","3.97110","0.01628"
"47.78400","3.98216","0.01667"
"47.91600","3.99316","0.01702"
"48.04800","4.00405","0.01686"
"48.18000","4.01505","0.01681"
"48.31200","4.02617","0.01714"
"48.44400","4.03711","0.01744"
"48.57600","4.04811","0.01740"
"48.70800","4.05911","0.01782"
"48.84000","4.07017","0.01789"
"48.97200","4.08117","0.01764"
"49.10400","4.09211","0.01764"
"49.23600","4.10306","0.01844"
"49.36800","4.11406","0.01796"
"49.50000","4.12518","0.01855"
"49.63200","4.13612","0.01853"
"49.76400","4.14706","0.01839"
"49.89600","4.15812","0.01817"
"50.02800","4.16912","0.01829"
"50.16000","4.18013","0.01859"
"50.29200","4.19107","0.01865"
"50.42400","4.20207","0.01851"
"50.55600","4.21313","0.01855"
"50.68800","4.22413","0.01908"
"50.82000","4.23507","0.01939"
"50.95200","4.24613","0.01984"
"51.08400","4.25707","0.01997"
"51.21600","4.26808","0.01956"
"51.34800","4.27902","0.01954"
"51.48000","4.29008","0.01996"
"51.61200","4.30108","0.02000"
"51.74400","4.31214","0.02016"
"51.87600","4.32308","0.02002"
"52.00800","4.33414","0.01988"
"52.14000","4.34514","0.02063"
"52.27200","4.35615","0.02039"
"52.40400","4.36715","0.02063"
"52.53600","4.37809","0.02085"
"52.66800","4.38915","0.02064"
"52.80000","4.40009","0.02096"
"52.93200","4.41109","0.02072"
"53.06400","4.42209","0.02133"
"53.19600","4.43315","0.02127"
"53.32800","4.44410","0.02105"
"53.46000","4.45504","0.02123"
"53.59200","4.46610","0.02212"
"53.72400","4.47716","0.02121"
"53.85600","4.48816","0.02208"
"53.98800","4.49910","0.02196"
"54.12000","4.51010","0.02189"
"54.25200","4.52116","0.02230"
"54.38400","4.53217","0.02251"
"54.51600","4.54311","0.02262"
"54.64800","4.55411","0.02288"
"54.78000","4.56517","0.02205"
"54.91200","4.57617","0.02263"
"55.04400","4.58711","0.02307"
"55.17600","4.59811","0.02318"
"55.30800","4.60918","0.02304"
"55.44000","4.62018","0.02329"
"55.57200","4.63112","0.02334"
"55.70400","4.64212","0.02336"
"55.83600","4.65312","0.02368"
"55.96800","4.66412","0.02324"
"56.10000","4.67512","0.02406"
"56.23200","4.68606","0.02378"
"56.36400","4.69713","0.02406"
"56.49600","4.70813","0.02414"
"56.62800","4.71913","0.02380"
"56.76000","4.73001","0.02427"
"56.89200","4.74113","0.02422"
"57.02400","4.75219","0.02449"
"57.15600","4.76319","0.02458"
"57.28800","4.77407","0.02483"
"57.42000","4.78514","0.02463"
"57.55200","4.79614","0.02500"
"57.68400","4.80708","0.02454"
"57.81600","4.81802","0.02480"
"57.94800","4.82914","0.02503"
"58.08000","4.84014","0.02489"
"58.21200","4.85114","0.02554"
"58.34400","4.86208","0.02528"
"58.47600","4.87309","0.02579"
"58.60800","4.88409","0.02587"
"58.74000","4.89509","0.02633"
"58.87200","4.90609","0.02595"
"59.00400","4.91709","0.02594"
"59.13600","4.92815","0.02625"
"59.26800","4.93909","0.02620"
"59.40000","4.95004","0.02640"
"59.53200","4.96110","0.02683"
"59.66400","4.97210","0.02695"
"59.79600","4.98310","0.02665"
"59.92800","4.99410","0.02713"
"60.06000","5.00510","0.02726"
"60.19200","5.01616","0.02730"
"60.32400","5.02716","0.02778"
"60.45600","5.03811","0.02741"
"60.58800","5.04911","0.02815"
"60.72000","5.06017","0.02797"
"60.85200","5.07111","0.02782"
"60.98400","5.08205","0.02806"
"61.11600","5.09305","0.02859"
"61.24800","5.10411","0.02854"
"61.38000","5.11511","0.02938"
"61.51200","5.12612","0.02895"
"61.64400","5.13712","0.02938"
"61.77600","5.14818","0.02878"
"61.90800","5.15912","0.02934"
"62.04000","5.17006","0.02941"
"62.17200","5.18106","0.02971"
"62.30400","5.19212","0.02982"
"62.43600","5.20312","0.02940"
"62.56800","5.21413","0.02859"
"62.70000","5.22513","0.02847"
"62.83200","5.23613","0.02931"
"62.96400","5.24713","0.02889"
"63.09600","5.25813","0.02941"
"63.22800","5.26907","0.02971"
"63.36000","5.28013","0.02973"
"63.49200","5.29113","0.03014"
"63.62400","5.30214","0.02997"
"63.75600","5.31314","0.03046"
"63.88800","5.32414","0.03025"
"64.02000","5.33514","0.03092"
"64.15200","5.34608","0.03124"
"64.28400","5.35702","0.03133"
"64.41600","5.36814","0.03130"
"64.54800","5.37908","0.03166"
"64.68000","5.39015","0.03133"
"64.81200","5.40103","0.03175"
"64.94400","5.41215","0.03128"
"65.07600","5.42315","0.03127"
"65.20800","5.43415","0.03225"
"65.34000","5.44509","0.03269"
"65.47200","5.45615","0.03271"
"65.60400","5.46715","0.03258"
"65.73600","5.47816","0.03296"
"65.86800","5.48910","0.03229"
"66.00000","5.50010","0.03322"
"66.13200","5.51116","0.03386"
"66.26400","5.52216","0.03365"
"66.39600","5.53310","0.03435"
"66.52800","5.54404","0.03495"
"66.66000","5.55511","0.03494"
"66.79200","5.56617","0.03507"
"66.92400","5.57711","0.03557"
"67.05600","5.58811","0.03580"
"67.18800","5.59917","0.03548"
"67.32000","5.61017","0.03619"
"67.45200","5.62111","0.03616"
"67.58400","5.63205","0.03731"
"67.71600","5.64306","0.03693"
"67.84800","5.65412","0.03758"
"67.98000","5.66512","0.03778"
"68.11200","5.67606","0.03884"
"68.24400","5.68712","0.03835"
"68.37600","5.69818","0.03893"
"68.50800","5.70906","0.03896"
"68.64000","5.72012","0.04000"
"68.77200","5.73118","0.03970"
"68.90400","5.74213","0.04039"
"69.03600","5.75313","0.04161"
"69.16800","5.76407","0.04151"
"69.30000","5.77513","0.04151"
"69.43200","5.78613","0.04236"
"69.56400","5.79713","0.04184"
"69.69600","5.80814","0.04271"
"69.82800","5.81914","0.04369"
"69.96000","5.83014","0.04434"
"70.09200","5.84114","0.04374"
"70.22400","5.85214","0.04477"
"70.35600","5.86320","0.04487"
"70.48800","5.87414","0.04589"
"70.62000","5.88508","0.04585"
"70.75200","5.89603","0.04655"
"70.88400","5.90709","0.04715"
"71.01600","5.91815","0.04747"
"71.14800","5.92909","0.04797"
"71.28000","5.94009","0.04820"
"71.41200","5.95109","0.04831"
"71.54400","5.96209","0.04839"
"71.67600","5.97309","0.04976"
"71.80800","5.98404","0.05016"
"71.94000","5.99516","0.05013"
"72.07200","6.00616","0.05026"
"72.20400","6.01716","0.05132"
"72.33600","6.02810","0.05189"
"72.46800","6.03916","0.05213"
"72.60000","6.05010","0.05279"
"72.73200","6.06110","0.05371"
"72.86400","6.07199","0.05379"
"72.99600","6.08311","0.05469"
"73.12800","6.09417","0.05409"
"73.26000","6.10517","0.05446"
"73.39200","6.11605","0.05521"
"73.52400","6.12711","0.05588"
"73.65600","6.13811","0.05621"
"73.78800","6.14911","0.05630"
"73.92000","6.16012","0.05619"
"74.05200","6.17106","0.05677"
"74.18400","6.18212","0.05726"
"74.31600","6.19312","0.05740"
"74.44800","6.20412","0.05775"
"74.58000","6.21512","0.05847"
"74.71200","6.22612","0.05865"
"74.84400","6.23712","0.05877"
"74.97600","6.24807","0.05923"
"75.10800","6.25907","0.05915"
"75.24000","6.27019","0.06005"
"75.37200","6.28113","0.06063"
"75.50400","6.29213","0.06144"
"75.63600","6.30307","0.06081"
"75.76800","6.31413","0.06191"
"75.90000","6.32514","0.06120"
"76.03200","6.33608","0.06198"
"76.16400","6.34702","0.06254"
"76.29600","6.35814","0.06274"
"76.42800","6.36914","0.06333"
"76.56000","6.38014","0.06370"
"76.69200","6.39114","0.06361"
"76.82400","6.40214","0.06499"
"76.95600","6.41315","0.06501"
"77.08800","6.42415","0.06539"
"77.22000","6.43503","0.06614"
"77.35200","6.44609","0.06614"
"77.48400","6.45709","0.06636"
"77.61600","6.46809","0.06732"
"77.74800","6.47909","0.06763"
"77.88000","6.49009","0.06772"
"78.01200","6.50109","0.06723"
"78.14400","6.51210","0.06785"
"78.27600","6.52310","0.06826"
"78.40800","6.53410","0.06829"
"78.54000","6.54516","0.06886"
"78.67200","6.55616","0.06916"
"78.80400","6.56704","0.06939"
"78.93600","6.57810","0.07008"
"79.06800","6.58911","0.06977"
"79.20000","6.60011","0.07058"
"79.33200","6.61105","0.07098"
"79.46400","6.62211","0.07133"
"79.59600","6.63311","0.07179"
"79.72800","6.64411","0.07174"
"79.86000","6.65511","0.07185"
"79.99200","6.66611","0.07218"
"80.12400","6.67718","0.07262"
"80.25600","6.68812","0.07326"
"80.38800","6.69906","0.07318"
"80.52000","6.71012","0.07366"
"80.65200","6.72112","0.07395"
"80.78400","6.73212","0.07403"
"80.91600","6.74306","0.07434"
"81.04800","6.75412","0.07432"
"81.18000","6.76513","0.07498"
"81.31200","6.77613","0.07516"
"81.44400","6.78707","0.07549"
"81.57600","6.79813","0.07547"
"81.70800","6.80913","0.07607"
"81.84000","6.82019","0.07606"
"81.97200","6.83113","0.07575"
"82.10400","6.84208","0.07589"
"82.23600","6.85314","0.07631"
"82.36800","6.86414","0.07601"
"82.50000","6.87508","0.07608"
"82.63200","6.88608","0.07642"
"82.76400","6.89714","0.07672"
"82.89600","6.90814","0.07677"
"83.02800","6.91914","0.07696"
"83.16000","6.93015","0.07704"
"83.29200","6.94115","0.07700"
"83.42400","6.95215","0.07737"
"83.55600","6.96309","0.07735"
"83.68800","6.97409","0.07797"
"83.82000","6.98515","0.07776"
"83.95200","6.99615","0.07803"
"84.08400","7.00709","0.07824"
"84.21600","7.01804","0.07839"
"84.34800","7.02910","0.07842"
"84.48000","7.04016","0.07842"
"84.61200","7.05110","0.07854"
"84.74400","7.06210","0.07858"
"84.87600","7.07310","0.07908"
"85.00800","7.08416","0.07917"
"85.14000","7.09516","0.07914"
"85.27200","7.10611","0.07912"
"85.40400","7.11711","0.07953"
"85.53600","7.12817","0.07977"
"85.66800","7.13911","0.08038"
"85.80000","7.14999","0.07907"
"85.93200","7.16111","0.07973"
"86.06400","7.17211","0.07939"
"86.19600","7.18311","0.08002"
"86.32800","7.19406","0.08032"
"86.46000","7.20506","0.08132"
"86.59200","7.21612","0.08097"
"86.72400","7.22712","0.08157"
"86.85600","7.23806","0.08134"
"86.98800","7.24912","0.08185"
"87.12000","7.26012","0.08225"
"87.25200","7.27112","0.08265"
"87.38400","7.28207","0.08302"
"87.51600","7.29313","0.08346"
"87.64800","7.30413","0.08377"
"87.78000","7.31507","0.08383"
"87.91200","7.32607","0.08408"
"88.04400","7.33707","0.08535"
"88.17600","7.34813","0.08535"
"88.30800","7.35914","0.08577"
"88.44000","7.37014","0.08652"
"88.57200","7.38114","0.08638"
"88.70400","7.39214","0.08689"
"88.83600","7.40314","0.08750"
"88.96800","7.41402","0.08761"
"89.10000","7.42508","0.08788"
"89.23200","7.43614","0.08845"
"89.36400","7.44714","0.08892"
"89.49600","7.45809","0.08955"
"89.62800","7.46909","0.08981"
"89.76000","7.48015","0.09027"
"89.89200","7.49115","0.09065"
"90.02400","7.50209","0.09119"
"90.15600","7.51309","0.09114"
"90.28800","7.52415","0.09171"
"90.42000","7.53516","0.09195"
"90.55200","7.54610","0.09263"
"90.68400","7.55704","0.09303"
"90.81600","7.56816","0.09346"
"90.94800","7.57916","0.09424"
"91.08000","7.59010","0.09472"
"91.21200","7.60104","0.09461"
"91.34400","7.61216","0.09533"
"91.47600","7.62317","0.09547"
"91.60800","7.63417","0.09589"
"91.74000","7.64511","0.09663"
"91.87200","7.65617","0.09678"
"92.00400","7.66711","0.09740"
"92.13600","7.67805","0.09804"
"92.26800","7.68905","0.09871"
"92.40000","7.70006","0.09881"
"92.53200","7.71112","0.09929"
"92.66400","7.72212","0.10013"
"92.79600","7.73306","0.10117"
"92.92800","7.74412","0.10126"
"93.06000","7.75518","0.10212"
"93.19200","7.76612","0.10267"
"93.32400","7.77712","0.10356"
"93.45600","7.78813","0.10459"
"93.58800","7.79913","0.10466"
"93.72000","7.81013","0.10530"
"93.85200","7.82107","0.10645"
"93.98400","7.83213","0.10680"
"94.11600","7.84313","0.10781"
"94.24800","7.85413","0.10855"
"94.38000","7.86507","0.10948"
"94.51200","7.87607","0.11005"
"94.64400","7.88708","0.11086"
"94.77600","7.89808","0.11108"
"94.90800","7.90908","0.11229"
"95.04000","7.92008","0.11267"
"95.17200","7.93114","0.11385"
"95.30400","7.94214","0.11399"
"95.43600","7.95308","0.11532"
"95.56800","7.96408","0.11516"
"95.70000","7.97509","0.11659"
"95.83200","7.98615","0.11751"
"95.96400","7.99709","0.11755"
"96.09600","8.00809","0.11893"
"96.22800","8.01915","0.11990"
"96.36000","8.03015","0.12036"
"96.49200","8.04109","0.12077"
"96.62400","8.05210","0.12187"
"96.75600","8.06316","0.12293"
"96.88800","8.07410","0.12326"
"97.02000","8.08504","0.12421"
"97.15200","8.09604","0.12481"
"97.28400","8.10710","0.12532"
"97.41600","8.11810","0.12679"
"97.54800","8.12904","0.12671"
"97.68000","8.14005","0.12816"
"97.81200","8.15117","0.12832"
"97.94400","8.16217","0.12960"
"98.07600","8.17311","0.13011"
"98.20800","8.18411","0.13133"
"98.34000","8.19517","0.13204"
"98.47200","8.20611","0.13254"
"98.60400","8.21712","0.13331"
"98.73600","8.22806","0.13393"
"98.86800","8.23912","0.13431"
"99.00000","8.25012","0.13467"
"99.13200","8.26112","0.13516"
"99.26400","8.27200","0.13595"
"99.39600","8.28312","0.13611"
"99.52800","8.29412","0.13669"
"99.66000","8.30513","0.13692"
"99.79200","8.31607","0.13726"
"99.92400","8.32713","0.13794"
"100.05600","8.33819","0.13825"
"100.18800","8.34913","0.13846"
"100.32000","8.36007","0.13867"
"100.45200","8.37107","0.13878"
"100.58400","8.38213","0.13906"
"100.71600","8.39307","0.13929"
"100.84800","8.40408","0.13935"
"100.98000","8.41514","0.13966"
"101.11200","8.42614","0.13981"
"101.24400","8.43714","0.13987"
"101.37600","8.44808","0.13996"
"101.50800","8.45914","0.14036"
"101.64000","8.47014","0.14049"
"101.77200","8.48114","0.14029"
"101.90400","8.49209","0.14142"
"102.03600","8.50309","0.14216"
"102.16800","8.51409","0.14195"
"102.30000","8.52515","0.14253"
"102.43200","8.53609","0.14318"
"102.56400","8.54709","0.14380"
"102.69600","8.55809","0.14435"
"102.82800","8.56916","0.14527"
"102.96000","8.58010","0.14602"
"103.09200","8.59110","0.14666"
"103.22400","8.60216","0.14702"
"103.35600","8.61316","0.14789"
"103.48800","8.62410","0.14866"
"103.62000","8.63510","0.14973"
"103.75200","8.64610","0.15010"
"103.88400","8.65711","0.15152"
"104.01600","8.66811","0.15184"
"104.14800","8.67905","0.15330"
"104.28000","8.69011","0.15393"
"104.41200","8.70117","0.15389"
"104.54400","8.71211","0.15583"
"104.67600","8.72311","0.15585"
"104.80800","8.73417","0.15690"
"104.94000","8.74518","0.15741"
"105.07200","8.75612","0.15842"
"105.20400","8.76706","0.15899"
"105.33600","8.77812","0.15977"
"105.46800","8.78912","0.16055"
"105.60000","8.80012","0.16146"
"105.73200","8.81112","0.16210"
"105.86400","8.82213","0.16281"
"105.99600","8.83313","0.16342"
"106.12800","8.84413","0.16439"
"106.26000","8.85507","0.16536"
"106.39200","8.86613","0.16549"
"106.52400","8.87713","0.16629"
"106.65600","8.88813","0.16697"
"106.78800","8.89907","0.16757"
"106.92000","8.91014","0.16831"
"107.05200","8.92114","0.16882"
"107.18400","8.93208","0.16856"
"107.31600","8.94302","0.16791"
"107.44800","8.95414","0.16832"
"107.58000","8.96514","0.16928"
"107.71200","8.97614","0.17002"
"107.84400","8.98708","0.17091"
"107.97600","8.99815","0.17139"
"108.10800","9.00915","0.17220"
"108.24000","9.02021","0.17276"
"108.37200","9.03109","0.17357"
"108.50400","9.04209","0.17371"
"108.63600","9.05315","0.17477"
"108.76800","9.06415","0.17547"
"108.90000","9.07509","0.17587"
"109.03200","9.08610","0.17649"
"109.16400","9.09710","0.17669"
"109.29600","9.10810","0.17742"
"109.42800","9.11904","0.17772"
"109.56000","9.13010","0.17856"
"109.69200","9.14110","0.17943"
"109.82400","9.15216","0.18019"
"109.95600","9.16311","0.18031"
"110.08800","9.17411","0.18143"
"110.22000","9.18511","0.18232"
"110.35200","9.19611","0.18268"
"110.48400","9.20711","0.18318"
"110.61600","9.21805","0.18439"
"110.74800","9.22911","0.18545"
"110.88000","9.24017","0.18602"
"111.01200","9.25111","0.18699"
"111.14400","9.26212","0.18774"
"111.27600","9.27318","0.18861"
"111.40800","9.28418","0.18949"
"111.54000","9.29506","0.19025"
"111.67200","9.30606","0.19092"
"111.80400","9.31712","0.19237"
"111.93600","9.32812","0.19320"
"112.06800","9.33907","0.19402"
"112.20000","9.35001","0.19470"
"112.33200","9.36113","0.19574"
"112.46400","9.37213","0.19705"
"112.59600","9.38313","0.19760"
"112.72800","9.39413","0.19927"
"112.86000","9.40519","0.19972"
"112.99200","9.41619","0.20088"
"113.12400","9.42720","0.20223"
"113.25600","9.43814","0.20349"
"113.38800","9.44914","0.20470"
"113.52000","9.46014","0.20603"
"113.65200","9.47108","0.20702"
"113.78400","9.48208","0.20754"
"113.91600","9.49314","0.20923"
"114.04800","9.50414","0.21005"
"114.18000","9.51509","0.21109"
"114.31200","9.52609","0.21335"
"114.44400","9.53709","0.21451"
"114.57600","9.54815","0.21562"
"114.70800","9.55915","0.21728"
"114.84000","9.57003","0.21907"
"114.97200","9.58115","0.22035"
"115.10400","9.59215","0.22238"
"115.23600","9.60316","0.22431"
"115.36800","9.61410","0.22532"
"115.50000","9.62516","0.22744"
"115.63200","9.63616","0.22823"
"115.76400","9.64710","0.22972"
"115.89600","9.65804","0.23076"
"116.02800","9.66910","0.23225"
"116.16000","9.68017","0.23452"
"116.29200","9.69117","0.23511"
"116.42400","9.70211","0.23599"
"116.55600","9.71317","0.23699"
"116.68800","9.72417","0.23794"
"116.82000","9.73511","0.23876"
"116.95200","9.74611","0.24019"
"117.08400","9.75705","0.24081"
"117.21600","9.76812","0.24181"
"117.34800","9.77912","0.24336"
"117.48000","9.79012","0.24439"
"117.61200","9.80106","0.24561"
"117.74400","9.81212","0.24765"
"117.87600","9.82318","0.24974"
"118.00800","9.83406","0.25062"
"118.14000","9.84512","0.25210"
"118.27200","9.85612","0.25443"
"118.40400","9.86719","0.25558"
"118.53600","9.87813","0.25790"
"118.66800","9.88907","0.25948"
"118.80000","9.90013","0.26087"
"118.93200","9.91113","0.26257"
"119.06400","9.92213","0.26472"
"119.19600","9.93307","0.26626"
"119.32800","9.94414","0.26736"
"119.46000","9.95514","0.26872"
"119.59200","9.96614","0.27001"
"119.72400","9.97708","0.27080"
"119.85600","9.98814","0.27244"
"119.98800","9.99914","0.27443"
"120.12000","10.01008","0.27513"
"120.25200","10.02102","0.27629"
"120.38400","10.03209","0.27740"
"120.51600","10.04315","0.27815"
"120.64800","10.05409","0.27925"
"120.78000","10.06509","0.28009"
"120.91200","10.07615","0.28122"
"121.04400","10.08709","0.28218"
"121.17600","10.09815","0.28270"
"121.30800","10.10909","0.28302"
"121.44000","10.12016","0.28376"
"121.57200","10.13122","0.28481"
"121.70400","10.14210","0.28517"
"121.83600","10.15304","0.28560"
"121.96800","10.16410","0.28620"
"122.10000","10.17510","0.28675"
"122.23200","10.18604","0.28699"
"122.36400","10.19705","0.28725"
"122.49600","10.20805","0.28756"
"122.62800","10.21911","0.28778"
"122.76000","10.23011","0.28791"
"122.89200","10.24105","0.28798"
"123.02400","10.25205","0.28813"
"123.15600","10.26311","0.28809"
"123.28800","10.27411","0.28833"
"123.42000","10.28506","0.28838"
"123.55200","10.29612","0.28849"
"123.68400","10.30712","0.28879"
"123.81600","10.31812","0.28897"
"123.94800","10.32906","0.28916"
"124.08000","10.34012","0.28943"
"124.21200","10.35118","0.29008"
"124.34400","10.36212","0.29043"
"124.47600","10.37306","0.29117"
"124.60800","10.38413","0.29178"
"124.74000","10.39519","0.29231"
"124.87200","10.40613","0.29317"
"125.00400","10.41707","0.29392"
"125.13600","10.42807","0.29473"
"125.26800","10.43913","0.29546"
"125.40000","10.45013","0.29735"
"125.53200","10.46108","0.29777"
"125.66400","10.47208","0.29923"
"125.79600","10.48320","0.30041"
"125.92800","10.49414","0.30184"
"126.06000","10.50514","0.30325"
"126.19200","10.51614","0.30444"
"126.32400","10.52714","0.30638"
"126.45600","10.53820","0.30857"
"126.58800","10.54909","0.31073"
"126.72000","10.56003","0.31236"
"126.85200","10.57109","0.31363"
"126.98400","10.58215","0.31630"
"127.11600","10.59309","0.31864"
"127.24800","10.60409","0.32065"
"127.38000","10.61509","0.32279"
"127.51200","10.62615","0.32533"
"127.64400","10.63710","0.32728"
"127.77600","10.64810","0.32995"
"127.90800","10.65916","0.33171"
"128.03999","10.67016","0.33423"
"128.17200","10.68116","0.33526"
"128.30400","10.69204","0.33704"
"128.43600","10.70310","0.33829"
"128.56799","10.71410","0.33951"
"128.70000","10.72511","0.34042"
"128.83200","10.73599","0.34119"
"128.96400","10.74711","0.34258"
"129.09599","10.75811","0.34350"
"129.22800","10.76917","0.34449"
"129.36000","10.78011","0.34558"
"129.49200","10.79111","0.34773"
"129.62399","10.80217","0.35075"
"129.75600","10.81312","0.35136"
"129.88800","10.82412","0.35403"
"130.02000","10.83512","0.35675"
"130.15199","10.84612","0.35864"
"130.28400","10.85712","0.36200"
"130.41600","10.86812","0.36425"
"130.54800","10.87912","0.36685"
"130.67999","10.89012","0.36963"
"130.81200","10.90113","0.37212"
"130.94400","10.91207","0.37397"
"131.07600","10.92307","0.37647"
"131.20799","10.93413","0.37843"
"131.34000","10.94519","0.38005"
"131.47200","10.95613","0.38202"
"131.60400","10.96713","0.38387"
"131.73599","10.97814","0.38542"
"131.86800","10.98914","0.38623"
"132.00000","11.00008","0.38795"
"132.13200","11.01108","0.38880"
"132.26401","11.02214","0.39071"
"132.39600","11.03314","0.39154"
"132.52800","11.04414","0.39307"
"132.66000","11.05514","0.39378"
"132.79201","11.06621","0.39504"
"132.92400","11.07715","0.39591"
"133.05600","11.08809","0.39721"
"133.18800","11.09909","0.39776"
"133.32001","11.11015","0.39948"
"133.45200","11.12115","0.39984"
"133.58400","11.13209","0.40142"
"133.71600","11.14303","0.40222"
"133.84801","11.15410","0.40254"
"133.98000","11.16516","0.40397"
"134.11200","11.17610","0.40474"
"134.24400","11.18710","0.40531"
"134.37601","11.19816","0.40647"
"134.50800","11.20916","0.40753"
"134.64000","11.22016","0.40810"
"134.77200","11.23111","0.40917"
"134.90401","11.24211","0.41070"
"135.03600","11.25311","0.41172"
"135.16800","11.26405","0.41306"
"135.30000","11.27499","0.41497"
"135.43201","11.28605","0.41637"
"135.56400","11.29711","0.41787"
"135.69600","11.30811","0.41988"
"135.82800","11.31906","0.42159"
"135.96001","11.33012","0.42386"
"136.09200","11.34112","0.42523"
"136.22400","11.35212","0.42747"
"136.35600","11.36312","0.43042"
"136.48801","11.37412","0.43151"
"136.62000","11.38512","0.43387"
"136.75200","11.39612","0.43592"
"136.88400","11.40707","0.43725"
"137.01601","11.41813","0.43823"
"137.14799","11.42907","0.43897"
"137.28000","11.44013","0.44023"
"137.41200","11.45101","0.44129"
"137.54401","11.46213","0.44174"
"137.67599","11.47313","0.44247"
"137.80800","11.48419","0.44342"
"137.94000","11.49514","0.44392"
"138.07201","11.50608","0.44501"
"138.20399","11.51714","0.44650"
"138.33600","11.52814","0.44853"
"138.46800","11.53914","0.45017"
"138.60001","11.55014","0.45244"
"138.73199","11.56114","0.45435"
"138.86400","11.57214","0.45566"
"138.99600","11.58309","0.45796"
"139.12801","11.59409","0.45983"
"139.25999","11.60521","0.46189"
"139.39200","11.61615","0.46293"
"139.52400","11.62709","0.46527"
"139.65601","11.63809","0.46745"
"139.78799","11.64915","0.46948"
"139.92000","11.66009","0.47203"
"140.05200","11.67110","0.47385"
"140.18401","11.68204","0.47615"
"140.31599","11.69310","0.47750"
"140.44800","11.70410","0.48015"
"140.58000","11.71510","0.48160"
"140.71201","11.72604","0.48357"
"140.84399","11.73716","0.48486"
"140.97600","11.74816","0.48626"
"141.10800","11.75917","0.48724"
"141.24001","11.77011","0.48791"
"141.37199","11.78117","0.48855"
"141.50400","11.79211","0.48959"
"141.63600","11.80305","0.48979"
"141.76801","11.81399","0.49061"
"141.89999","11.82511","0.48943"
"142.03200","11.83611","0.49056"
"142.16400","11.84718","0.49073"
"142.29601","11.85806","0.49248"
"142.42799","11.86912","0.49350"
"142.56000","11.88012","0.49532"
"142.69200","11.89118","0.49674"
"142.82401","11.90206","0.49851"
"142.95599","11.91318","0.50088"
"143.08800","11.92418","0.50439"
"143.22000","11.93513","0.50743"
"143.35201","11.94607","0.50980"
"143.48399","11.95707","0.51192"
"143.61600","11.96813","0.51555"
"143.74800","11.97913","0.51825"
"143.88000","11.99007","0.52079"
"144.01199","12.00107","0.52302"
"144.14400","12.01214","0.52559"
"144.27600","12.02320","0.52811"
"144.40800","12.03414","0.53052"
"144.53999","12.04514","0.53349"
"144.67200","12.05614","0.53604"
"144.80400","12.06714","0.53867"
"144.93600","12.07808","0.54073"
"145.06799","12.08908","0.54265"
"145.20000","12.10009","0.54544"
"145.33200","12.11115","0.54689"
"145.46400","12.12209","0.54896"
"145.59599","12.13309","0.54990"
"145.72800","12.14409","0.55113"
"145.86000","12.15515","0.55257"
"145.99200","12.16609","0.55439"
"146.12399","12.17709","0.55708"
"146.25600","12.18816","0.55887"
"146.38800","12.19916","0.56109"
"146.52000","12.21010","0.56343"
"146.65199","12.22104","0.56588"
"146.78400","12.23210","0.56877"
"146.91600","12.24310","0.57101"
"147.04800","12.25410","0.57276"
"147.17999","12.26511","0.57310"
"147.31200","12.27611","0.57273"
"147.44400","12.28717","0.57318"
"147.57600","12.29811","0.56924"
"147.70799","12.30905","0.55742"
"147.84000","12.32011","0.54624"
"147.97200","12.33111","0.54166"
"148.10400","12.34205","0.52769"
"148.23599","12.35300","0.52584"
"148.36800","12.36412","0.52846"
"148.50000","12.37512","0.53050"
"148.63200","12.38606","0.53454"
"148.76401","12.39706","0.53813"
"148.89600","12.40812","0.54324"
"149.02800","12.41912","0.54652"
"149.16000","12.43013","0.54952"
"149.29201","12.44112","0.55160"
"149.42400","12.45213","0.55407"
"149.55600","12.46319","0.55693"
"149.68800","12.47413","0.56043"
"149.82001","12.48507","0.56454"
"149.95200","12.49613","0.56858"
"150.08400","12.50713","0.57210"
"150.21600","12.51807","0.57623"
"150.34801","12.52902","0.58014"
"150.48000","12.54014","0.58227"
"150.61200","12.55114","0.58585"
"150.74400","12.56220","0.58796"
"150.87601","12.57302","0.58974"
"151.00800","12.58414","0.59108"
"151.14000","12.59514","0.59237"
"151.27200","12.60614","0.59407"
"151.40401","12.61709","0.59510"
"151.53600","12.62809","0.59614"
"151.66800","12.63915","0.59708"
"151.80000","12.65015","0.59846"
"151.93201","12.66115","0.60073"
"152.06400","12.67209","0.60228"
"152.19600","12.68315","0.60445"
"152.32800","12.69409","0.60608"
"152.46001","12.70510","0.60821"
"152.59200","12.71610","0.60991"
"152.72400","12.72716","0.61249"
"152.85600","12.73816","0.61495"
"152.98801","12.74910","0.61735"
"153.12000","12.76010","0.62050"
"153.25200","12.77110","0.62315"
"153.38400","12.78216","0.62643"
"153.51601","12.79311","0.63033"
"153.64799","12.80411","0.63433"
"153.78000","12.81511","0.63738"
"153.91200","12.82611","0.64130"
"154.04401","12.83711","0.64497"
"154.17599","12.84811","0.64805"
"154.30800","12.85911","0.65035"
"154.44000","12.87012","0.65388"
"154.57201","12.88112","0.65602"
"154.70399","12.89206","0.65999"
"154.83600","12.90312","0.66304"
"154.96800","12.91418","0.66693"
"155.10001","12.92512","0.67100"
"155.23199","12.93612","0.67463"
"155.36400","12.94718","0.67784"
"155.49600","12.95813","0.68037"
"155.62801","12.96913","0.68341"
"155.75999","12.98007","0.68530"
"155.89200","12.99113","0.68761"
"156.02400","13.00213","0.68999"
"156.15601","13.01319","0.69197"
"156.28799","13.02407","0.69422"
"156.42000","13.03508","0.69568"
"156.55200","13.04613","0.69734"
"156.68401","13.05708","0.69886"
"156.81599","13.06808","0.69992"
"156.94800","13.07908","0.70113"
"157.08000","13.09014","0.70220"
"157.21201","13.10108","0.70315"
"157.34399","13.11208","0.70409"
"157.47600","13.12315","0.70524"
"157.60800","13.13415","0.70595"
"157.74001","13.14515","0.70672"
"157.87199","13.15609","0.70772"
"158.00400","13.16709","0.70911"
"158.13600","13.17815","0.71048"
"158.26801","13.18909","0.71296"
"158.39999","13.20010","0.71479"
"158.53200","13.21109","0.71715"
"158.66400","13.22210","0.72020"
"158.79601","13.23310","0.72279"
"158.92799","13.24404","0.72581"
"159.06000","13.25510","0.72848"
"159.19200","13.26610","0.73131"
"159.32401","13.27716","0.73460"
"159.45599","13.28811","0.73677"
"159.58800","13.29910","0.74020"
"159.72000","13.31011","0.74377"
"159.85201","13.32111","0.74623"
"159.98399","13.33211","0.74839"
"160.11600","13.34305","0.75022"
"160.24800","13.35417","0.75190"
"160.38000","13.36517","0.75377"
"160.51199","13.37611","0.75533"
"160.64400","13.38712","0.75742"
"160.77600","13.39812","0.76000"
"160.90800","13.40912","0.76331"
"161.03999","13.42006","0.76623"
"161.17200","13.43106","0.76949"
"161.30400","13.44212","0.77227"
"161.43600","13.45312","0.77525"
"161.56799","13.46412","0.77748"
"161.70000","13.47507","0.78056"
"161.83200","13.48613","0.78428"
"161.96400","13.49713","0.78696"
"162.09599","13.50813","0.78996"
"162.22800","13.51907","0.79330"
"162.36000","13.53013","0.79644"
"162.49200","13.54113","0.79919"
"162.62399","13.55214","0.80146"
"162.75600","13.56308","0.80379"
"162.88800","13.57414","0.80611"
"163.02000","13.58514","0.80815"
"163.15199","13.59614","0.81010"
"163.28400","13.60702","0.81226"
"163.41600","13.61814","0.81425"
"163.54800","13.62908","0.81623"
"163.67999","13.64009","0.81807"
"163.81200","13.65109","0.81955"
"163.94400","13.66215","0.82155"
"164.07600","13.67309","0.82427"
"164.20799","13.68415","0.82635"
"164.34000","13.69509","0.82907"
"164.47200","13.70609","0.83191"
"164.60400","13.71715","0.83589"
"164.73599","13.72816","0.83934"
"164.86800","13.73910","0.84243"
"165.00000","13.75010","0.84721"
"165.13200","13.76110","0.84964"
"165.26401","13.77210","0.85181"
"165.39600","13.78304","0.85417"
"165.52800","13.79410","0.85680"
"165.66000","13.80516","0.86040"
"165.79201","13.81610","0.86409"
"165.92400","13.82711","0.86789"
"166.05600","13.83811","0.87208"
"166.18800","13.84911","0.87747"
"166.32001","13.86011","0.88047"
"166.45200","13.87105","0.88399"
"166.58400","13.88211","0.88860"
"166.71600","13.89312","0.89196"
"166.84801","13.90418","0.89558"
"166.98000","13.91506","0.89899"
"167.11200","13.92606","0.90207"
"167.24400","13.93718","0.90448"
"167.37601","13.94812","0.90640"
"167.50800","13.95912","0.90740"
"167.64000","13.97012","0.90815"
"167.77200","13.98118","0.90857"
"167.90401","13.99213","0.90896"
"168.03600","14.00313","0.90939"
"168.16800","14.01407","0.90997"
"168.30000","14.02513","0.91151"
"168.43201","14.03619","0.91315"
"168.56400","14.04707","0.91577"
"168.69600","14.05807","0.91913"
"168.82800","14.06914","0.92235"
"168.96001","14.08014","0.92702"
"169.09200","14.09114","0.93058"
"169.22400","14.10214","0.93463"
"169.35600","14.11314","0.93858"
"169.48801","14.12414","0.94340"
"169.62000","14.13508","0.94776"
"169.75200","14.14603","0.95305"
"169.88400","14.15709","0.95784"
"170.01601","14.16815","0.96101"
"170.14799","14.17909","0.96411"
"170.28000","14.19003","0.96676"
"170.41200","14.20109","0.96907"
"170.54401","14.21209","0.97167"
"170.67599","14.22315","0.97449"
"170.80800","14.23409","0.97838"
"170.94000","14.24510","0.98158"
"171.07201","14.25610","0.98547"
"171.20399","14.26716","0.98871"
"171.33600","14.27804","0.99160"
"171.46800","14.28910","0.99419"
"171.60001","14.30004","0.99700"
"171.73199","14.31110","0.99939"
"171.86400","14.32205","1.00202"
"171.99600","14.33311","1.00430"
"172.12801","14.34411","1.00626"
"172.25999","14.35517","1.00866"
"172.39200","14.36611","1.01040"
"172.52400","14.37711","1.01286"
"172.65601","14.38817","1.01531"
"172.78799","14.39911","1.01791"
"172.92000","14.41006","1.02111"
"173.05200","14.42106","1.02468"
"173.18401","14.43212","1.02878"
"173.31599","14.44312","1.03393"
"173.44800","14.45406","1.03787"
"173.58000","14.46506","1.04199"
"173.71201","14.47612","1.04630"
"173.84399","14.48712","1.05046"
"173.97600","14.49813","1.05358"
"174.10800","14.50913","1.05613"
"174.24001","14.52013","1.05804"
"174.37199","14.53113","1.05966"
"174.50400","14.54207","1.06105"
"174.63600","14.55313","1.06446"
"174.76801","14.56413","1.06805"
"174.89999","14.57513","1.07349"
"175.03200","14.58608","1.07777"
"175.16400","14.59708","1.08313"
"175.29601","14.60820","1.08840"
"175.42799","14.61914","1.09159"
"175.56000","14.63014","1.09662"
"175.69200","14.64108","1.10052"
"175.82401","14.65214","1.10410"
"175.95599","14.66314","1.10717"
"176.08800","14.67409","1.10972"
"176.22000","14.68503","1.11169"
"176.35201","14.69609","1.11357"
"176.48399","14.70715","1.11490"
"176.61600","14.71809","1.11627"
"176.74800","14.72903","1.11764"
"176.88000","14.74015","1.11890"
"177.01199","14.75115","1.12061"
"177.14400","14.76216","1.12173"
"177.27600","14.77310","1.12370"
"177.40800","14.78416","1.12598"
"177.53999","14.79516","1.12903"
"177.67200","14.80616","1.13203"
"177.80400","14.81704","1.13711"
"177.93600","14.82810","1.14163"
"178.06799","14.83911","1.14757"
"178.20000","14.85011","1.15398"
"178.33200","14.86105","1.15904"
"178.46400","14.87205","1.16423"
"178.59599","14.88311","1.16775"
"178.72800","14.89417","1.17177"
"178.86000","14.90505","1.17626"
"178.99200","14.91611","1.18206"
"179.12399","14.92717","1.18736"
"179.25600","14.93818","1.19166"
"179.38800","14.94912","1.19678"
"179.52000","14.96012","1.20007"
"179.65199","14.97112","1.20359"
"179.78400","14.98218","1.20674"
"179.91600","14.99312","1.20946"
"180.04800","15.00412","1.21183"
"180.17999","15.01513","1.21489"
"180.31200","15.02613","1.21628"
"180.44400","15.03707","1.21826"
"180.57600","15.04813","1.21964"
"180.70799","15.05913","1.22123"
"180.84000","15.07019","1.22292"
"180.97200","15.08113","1.22499"
"181.10400","15.09207","1.22764"
"181.23599","15.10314","1.23101"
"181.36800","15.11408","1.23556"
"181.50000","15.12508","1.24026"
"181.63200","15.13608","1.24415"
"181.76401","15.14714","1.24992"
"181.89600","15.15814","1.25570"
"182.02800","15.16908","1.26025"
"182.16000","15.18008","1.26475"
"182.29201","15.19121","1.26749"
"182.42400","15.20215","1.26973"
"182.55600","15.21315","1.27160"
"182.68800","15.22409","1.27386"
"182.82001","15.23509","1.27755"
"182.95200","15.24609","1.28140"
"183.08400","15.25709","1.28497"
"183.21600","15.26809","1.28959"
"183.34801","15.27910","1.29378"
"183.48000","15.29016","1.29844"
"183.61200","15.30110","1.30328"
"183.74400","15.31204","1.30781"
"183.87601","15.32310","1.31200"
"184.00800","15.33416","1.31533"
"184.14000","15.34516","1.31777"
"184.27200","15.35604","1.32057"
"184.40401","15.36711","1.32282"
"184.53600","15.37811","1.32445"
"184.66800","15.38911","1.32658"
"184.80000","15.40005","1.32804"
"184.93201","15.41111","1.32971"
"185.06400","15.42211","1.33156"
"185.19600","15.43311","1.33380"
"185.32800","15.44406","1.33620"
"185.46001","15.45518","1.33962"
"185.59200","15.46618","1.34371"
"185.72400","15.47718","1.34805"
"185.85600","15.48812","1.35289"
"185.98801","15.49912","1.35836"
"186.12000","15.51012","1.36325"
"186.25200","15.52112","1.36801"
"186.38400","15.53207","1.37109"
"186.51601","15.54307","1.37321"
"186.64799","15.55413","1.37603"
"186.78000","15.56513","1.38005"
"186.91200","15.57607","1.38452"
"187.04401","15.58713","1.39081"
"187.17599","15.59813","1.39585"
"187.30800","15.60913","1.40108"
"187.44000","15.62008","1.40444"
"187.57201","15.63108","1.40790"
"187.70399","15.64214","1.41040"
"187.83600","15.65314","1.41271"
"187.96800","15.66408","1.41532"
"188.10001","15.67508","1.41736"
"188.23199","15.68614","1.41970"
"188.36400","15.69714","1.42201"
"188.49600","15.70809","1.42457"
"188.62801","15.71909","1.42835"
"188.75999","15.73015","1.43254"
"188.89200","15.74115","1.43873"
"189.02400","15.75209","1.44526"
"189.15601","15.76309","1.45257"
"189.28799","15.77415","1.46075"
"189.42000","15.78509","1.46774"
"189.55200","15.79609","1.47277"
"189.68401","15.80704","1.47626"
"189.81599","15.81810","1.47864"
"189.94800","15.82910","1.48119"
"190.08000","15.84010","1.48396"
"190.21201","15.85110","1.48636"
"190.34399","15.86216","1.48873"
"190.47600","15.87316","1.49105"
"190.60800","15.88416","1.49201"
"190.74001","15.89511","1.49242"
"190.87199","15.90611","1.49077"
"191.00400","15.91711","1.48281"
"191.13600","15.92811","-0.03419"
"191.26801","15.93911","0.01527"
"191.39999","15.95011","0.00546"
"191.53200","15.96111","0.00434"
"191.66400","15.97206","0.00256"
"191.79601","15.98312","0.00121"
"191.92799","15.99412","0.00175"
"192.06000","16.00512","0.00208"
"192.19200","16.01618","0.00170"
"192.32401","16.02712","0.00184"
"192.45599","16.03812","0.00113"
"192.58800","16.04912","0.00164"
"192.72000","16.06013","0.00135"
"192.85201","16.07107","0.00136"
"192.98399","16.08213","0.00135"
"193.11600","16.09313","0.00099"
"193.24800","16.10413","0.00122"
"193.38000","16.11507","0.00147"
"193.51199","16.12613","0.00160"
"193.64400","16.13713","0.00174"
"193.77600","16.14820","0.00150"
"193.90800","16.15908","0.00185"
"194.03999","16.17008","0.00133"
"194.17200","16.18114","0.00181"
"194.30400","16.19214","0.00122"
"194.43600","16.20308","0.00093"
"194.56799","16.21408","0.00121"
"194.70000","16.22514","0.00172"
"194.83200","16.23615","0.00131"
"194.96400","16.24709","0.00149"
"195.09599","16.25809","0.00167"
"195.22800","16.26915","0.00159"
"195.36000","16.28015","0.00137"
"195.49200","16.29109","0.00152"
"195.62399","16.30209","0.00163"
"195.75600","16.31316","0.00160"
"195.88800","16.32416","0.00114"
"196.02000","16.33510","0.00193"
"196.15199","16.34604","0.00131"
"196.28400","16.35716","0.00125"
"196.30800","16.35913","0.00096"