File: Force_trajectories/161104/Specimen_RawData_6.csv
End date,"11/4/2016"
Specimen label,"63G_21"
Maximum Load,"-0.00015",N

Time,Extension,Load
(s),(mm),(N)
"0.00000","-0.56860","-0.00761"
"0.01200","-0.56860","-0.00769"
"0.02400","-0.56842","-0.00771"
"0.03600","-0.56818","-0.00760"
"0.04800","-0.56776","-0.00752"
"0.06000","-0.56728","-0.00746"
"0.07200","-0.56680","-0.00743"
"0.08400","-0.56609","-0.00736"
"0.09600","-0.56531","-0.00735"
"0.10800","-0.56441","-0.00742"
"0.12000","-0.56340","-0.00737"
"0.13200","-0.56232","-0.00733"
"0.14400","-0.56118","-0.00732"
"0.15600","-0.55987","-0.00730"
"0.16800","-0.55855","-0.00727"
"0.18000","-0.55724","-0.00716"
"0.19200","-0.55592","-0.00704"
"0.20400","-0.55461","-0.00696"
"0.21600","-0.55323","-0.00689"
"0.22800","-0.55186","-0.00681"
"0.24000","-0.55054","-0.00683"
"0.25200","-0.54923","-0.00680"
"0.26400","-0.54797","-0.00667"
"0.27600","-0.54666","-0.00658"
"0.28800","-0.54540","-0.00651"
"0.30000","-0.54426","-0.00656"
"0.31200","-0.54307","-0.00664"
"0.32400","-0.54193","-0.00660"
"0.33600","-0.54080","-0.00645"
"0.34800","-0.53966","-0.00640"
"0.36000","-0.53852","-0.00643"
"0.37200","-0.53751","-0.00649"
"0.38400","-0.53643","-0.00640"
"0.39600","-0.53536","-0.00634"
"0.40800","-0.53434","-0.00641"
"0.42000","-0.53332","-0.00639"
"0.43200","-0.53231","-0.00638"
"0.44400","-0.53129","-0.00636"
"0.45600","-0.53027","-0.00625"
"0.46800","-0.52926","-0.00615"
"0.48000","-0.52830","-0.00618"
"0.49200","-0.52728","-0.00628"
"0.50400","-0.52633","-0.00620"
"0.51600","-0.52531","-0.00627"
"0.52800","-0.52429","-0.00639"
"0.54000","-0.52334","-0.00635"
"0.55200","-0.52232","-0.00608"
"0.56400","-0.52136","-0.00598"
"0.57600","-0.52035","-0.00602"
"0.58800","-0.51939","-0.00607"
"0.60000","-0.51838","-0.00613"
"0.61200","-0.51736","-0.00604"
"0.62400","-0.51634","-0.00599"
"0.63600","-0.51539","-0.00594"
"0.64800","-0.51437","-0.00592"
"0.66000","-0.51335","-0.00601"
"0.67200","-0.51234","-0.00603"
"0.68400","-0.51138","-0.00589"
"0.69600","-0.51036","-0.00585"
"0.70800","-0.50941","-0.00589"
"0.72000","-0.50839","-0.00580"
"0.73200","-0.50737","-0.00575"
"0.74400","-0.50636","-0.00579"
"0.75600","-0.50534","-0.00585"
"0.76800","-0.50432","-0.00594"
"0.78000","-0.50331","-0.00591"
"0.79200","-0.50235","-0.00579"
"0.80400","-0.50134","-0.00563"
"0.81600","-0.50038","-0.00534"
"0.82800","-0.49936","-0.00513"
"0.84000","-0.49841","-0.00508"
"0.85200","-0.49739","-0.00517"
"0.86400","-0.49637","-0.00531"
"0.87600","-0.49536","-0.00542"
"0.88800","-0.49434","-0.00548"
"0.90000","-0.49332","-0.00555"
"0.91200","-0.49237","-0.00560"
"0.92400","-0.49135","-0.00564"
"0.93600","-0.49033","-0.00561"
"0.94800","-0.48938","-0.00542"
"0.96000","-0.48836","-0.00542"
"0.97200","-0.48740","-0.00545"
"0.98400","-0.48639","-0.00541"
"0.99600","-0.48543","-0.00548"
"1.00800","-0.48441","-0.00548"
"1.02000","-0.48340","-0.00559"
"1.03200","-0.48244","-0.00562"
"1.04400","-0.48143","-0.00580"
"1.05600","-0.48041","-0.00576"
"1.06800","-0.47945","-0.00556"
"1.08000","-0.47844","-0.00540"
"1.09200","-0.47742","-0.00524"
"1.10400","-0.47646","-0.00520"
"1.11600","-0.47545","-0.00526"
"1.12800","-0.47443","-0.00527"
"1.14000","-0.47341","-0.00531"
"1.15200","-0.47240","-0.00522"
"1.16400","-0.47144","-0.00517"
"1.17600","-0.47042","-0.00520"
"1.18800","-0.46941","-0.00523"
"1.20000","-0.46839","-0.00525"
"1.21200","-0.46737","-0.00516"
"1.22400","-0.46636","-0.00526"
"1.23600","-0.46534","-0.00529"
"1.24800","-0.46439","-0.00521"
"1.26000","-0.46337","-0.00521"
"1.27200","-0.46235","-0.00518"
"1.28400","-0.46134","-0.00518"
"1.29600","-0.46038","-0.00515"
"1.30800","-0.45936","-0.00501"
"1.32000","-0.45835","-0.00490"
"1.33200","-0.45739","-0.00491"
"1.34400","-0.45637","-0.00487"
"1.35600","-0.45542","-0.00499"
"1.36800","-0.45440","-0.00510"
"1.38000","-0.45338","-0.00494"
"1.39200","-0.45237","-0.00499"
"1.40400","-0.45135","-0.00496"
"1.41600","-0.45033","-0.00503"
"1.42800","-0.44932","-0.00507"
"1.44000","-0.44836","-0.00493"
"1.45200","-0.44735","-0.00491"
"1.46400","-0.44639","-0.00501"
"1.47600","-0.44537","-0.00518"
"1.48800","-0.44442","-0.00528"
"1.50000","-0.44340","-0.00533"
"1.51200","-0.44244","-0.00534"
"1.52400","-0.44143","-0.00517"
"1.53600","-0.44041","-0.00504"
"1.54800","-0.43939","-0.00497"
"1.56000","-0.43838","-0.00483"
"1.57200","-0.43742","-0.00476"
"1.58400","-0.43640","-0.00462"
"1.59600","-0.43545","-0.00454"
"1.60800","-0.43449","-0.00472"
"1.62000","-0.43347","-0.00483"
"1.63200","-0.43246","-0.00486"
"1.64400","-0.43150","-0.00504"
"1.65600","-0.43048","-0.00510"
"1.66800","-0.42947","-0.00504"
"1.68000","-0.42851","-0.00501"
"1.69200","-0.42744","-0.00484"
"1.70400","-0.42648","-0.00466"
"1.71600","-0.42546","-0.00463"
"1.72800","-0.42445","-0.00462"
"1.74000","-0.42343","-0.00471"
"1.75200","-0.42247","-0.00467"
"1.76400","-0.42146","-0.00456"
"1.77600","-0.42044","-0.00448"
"1.78800","-0.41942","-0.00450"
"1.80000","-0.41841","-0.00453"
"1.81200","-0.41739","-0.00460"
"1.82400","-0.41637","-0.00460"
"1.83600","-0.41536","-0.00457"
"1.84800","-0.41434","-0.00451"
"1.86000","-0.41333","-0.00443"
"1.87200","-0.41237","-0.00446"
"1.88400","-0.41135","-0.00460"
"1.89600","-0.41040","-0.00476"
"1.90800","-0.40938","-0.00482"
"1.92000","-0.40842","-0.00477"
"1.93200","-0.40741","-0.00467"
"1.94400","-0.40639","-0.00448"
"1.95600","-0.40537","-0.00441"
"1.96800","-0.40436","-0.00444"
"1.98000","-0.40340","-0.00437"
"1.99200","-0.40238","-0.00444"
"2.00400","-0.40137","-0.00446"
"2.01600","-0.40041","-0.00450"
"2.02800","-0.39939","-0.00463"
"2.04000","-0.39844","-0.00467"
"2.05200","-0.39742","-0.00472"
"2.06400","-0.39646","-0.00470"
"2.07600","-0.39545","-0.00462"
"2.08800","-0.39443","-0.00453"
"2.10000","-0.39342","-0.00449"
"2.11200","-0.39240","-0.00448"
"2.12400","-0.39138","-0.00451"
"2.13600","-0.39043","-0.00457"
"2.14800","-0.38941","-0.00437"
"2.16000","-0.38839","-0.00428"
"2.17200","-0.38744","-0.00435"
"2.18400","-0.38642","-0.00447"
"2.19600","-0.38546","-0.00466"
"2.20800","-0.38445","-0.00456"
"2.22000","-0.38349","-0.00463"
"2.23200","-0.38247","-0.00457"
"2.24400","-0.38146","-0.00440"
"2.25600","-0.38044","-0.00440"
"2.26800","-0.37942","-0.00441"
"2.28000","-0.37841","-0.00450"
"2.29200","-0.37739","-0.00456"
"2.30400","-0.37638","-0.00436"
"2.31600","-0.37542","-0.00419"
"2.32800","-0.37440","-0.00431"
"2.34000","-0.37339","-0.00448"
"2.35200","-0.37243","-0.00457"
"2.36400","-0.37141","-0.00465"
"2.37600","-0.37040","-0.00460"
"2.38800","-0.36932","-0.00443"
"2.40000","-0.36836","-0.00446"
"2.41200","-0.36735","-0.00444"
"2.42400","-0.36633","-0.00442"
"2.43600","-0.36537","-0.00425"
"2.44800","-0.36436","-0.00395"
"2.46000","-0.36340","-0.00388"
"2.47200","-0.36238","-0.00391"
"2.48400","-0.36137","-0.00392"
"2.49600","-0.36041","-0.00408"
"2.50800","-0.35939","-0.00436"
"2.52000","-0.35838","-0.00445"
"2.53200","-0.35736","-0.00433"
"2.54400","-0.35635","-0.00418"
"2.55600","-0.35533","-0.00409"
"2.56800","-0.35431","-0.00405"
"2.58000","-0.35336","-0.00390"
"2.59200","-0.35234","-0.00363"
"2.60400","-0.35138","-0.00364"
"2.61600","-0.35043","-0.00405"
"2.62800","-0.34941","-0.00423"
"2.64000","-0.34845","-0.00414"
"2.65200","-0.34744","-0.00406"
"2.66400","-0.34642","-0.00388"
"2.67600","-0.34546","-0.00389"
"2.68800","-0.34445","-0.00390"
"2.70000","-0.34343","-0.00397"
"2.71200","-0.34241","-0.00409"
"2.72400","-0.34146","-0.00401"
"2.73600","-0.34044","-0.00389"
"2.74800","-0.33949","-0.00377"
"2.76000","-0.33847","-0.00371"
"2.77200","-0.33745","-0.00388"
"2.78400","-0.33650","-0.00403"
"2.79600","-0.33548","-0.00412"
"2.80800","-0.33446","-0.00411"
"2.82000","-0.33345","-0.00401"
"2.83200","-0.33243","-0.00389"
"2.84400","-0.33135","-0.00382"
"2.85600","-0.33040","-0.00395"
"2.86800","-0.32938","-0.00411"
"2.88000","-0.32842","-0.00433"
"2.89200","-0.32741","-0.00424"
"2.90400","-0.32639","-0.00414"
"2.91600","-0.32537","-0.00411"
"2.92800","-0.32436","-0.00406"
"2.94000","-0.32340","-0.00388"
"2.95200","-0.32239","-0.00372"
"2.96400","-0.32137","-0.00379"
"2.97600","-0.32035","-0.00396"
"2.98800","-0.31934","-0.00394"
"3.00000","-0.31832","-0.00390"
"3.01200","-0.31736","-0.00384"
"3.02400","-0.31635","-0.00390"
"3.03600","-0.31539","-0.00395"
"3.04800","-0.31437","-0.00390"
"3.06000","-0.31336","-0.00384"
"3.07200","-0.31240","-0.00378"
"3.08400","-0.31138","-0.00371"
"3.09600","-0.31037","-0.00378"
"3.10800","-0.30941","-0.00393"
"3.12000","-0.30839","-0.00403"
"3.13200","-0.30738","-0.00393"
"3.14400","-0.30636","-0.00377"
"3.15600","-0.30540","-0.00360"
"3.16800","-0.30439","-0.00352"
"3.18000","-0.30343","-0.00352"
"3.19200","-0.30242","-0.00362"
"3.20400","-0.30146","-0.00373"
"3.21600","-0.30044","-0.00377"
"3.22800","-0.29943","-0.00388"
"3.24000","-0.29841","-0.00396"
"3.25200","-0.29745","-0.00400"
"3.26400","-0.29644","-0.00408"
"3.27600","-0.29542","-0.00394"
"3.28800","-0.29440","-0.00375"
"3.30000","-0.29345","-0.00374"
"3.31200","-0.29249","-0.00374"
"3.32400","-0.29147","-0.00365"
"3.33600","-0.29046","-0.00378"
"3.34800","-0.28944","-0.00371"
"3.36000","-0.28842","-0.00379"
"3.37200","-0.28747","-0.00382"
"3.38400","-0.28645","-0.00372"
"3.39600","-0.28544","-0.00379"
"3.40800","-0.28442","-0.00367"
"3.42000","-0.28340","-0.00360"
"3.43200","-0.28239","-0.00352"
"3.44400","-0.28137","-0.00357"
"3.45600","-0.28035","-0.00358"
"3.46800","-0.27940","-0.00361"
"3.48000","-0.27838","-0.00357"
"3.49200","-0.27736","-0.00352"
"3.50400","-0.27641","-0.00362"
"3.51600","-0.27539","-0.00360"
"3.52800","-0.27437","-0.00371"
"3.54000","-0.27342","-0.00364"
"3.55200","-0.27234","-0.00352"
"3.56400","-0.27132","-0.00359"
"3.57600","-0.27037","-0.00359"
"3.58800","-0.26935","-0.00361"
"3.60000","-0.26840","-0.00357"
"3.61200","-0.26738","-0.00358"
"3.62400","-0.26636","-0.00365"
"3.63600","-0.26541","-0.00352"
"3.64800","-0.26439","-0.00333"
"3.66000","-0.26343","-0.00335"
"3.67200","-0.26242","-0.00333"
"3.68400","-0.26140","-0.00326"
"3.69600","-0.26038","-0.00309"
"3.70800","-0.25937","-0.00326"
"3.72000","-0.25841","-0.00347"
"3.73200","-0.25739","-0.00342"
"3.74400","-0.25644","-0.00329"
"3.75600","-0.25542","-0.00330"
"3.76800","-0.25446","-0.00357"
"3.78000","-0.25345","-0.00374"
"3.79200","-0.25243","-0.00380"
"3.80400","-0.25147","-0.00361"
"3.81600","-0.25046","-0.00342"
"3.82800","-0.24944","-0.00330"
"3.84000","-0.24843","-0.00327"
"3.85200","-0.24741","-0.00346"
"3.86400","-0.24645","-0.00359"
"3.87600","-0.24544","-0.00366"
"3.88800","-0.24442","-0.00359"
"3.90000","-0.24346","-0.00338"
"3.91200","-0.24245","-0.00335"
"3.92400","-0.24143","-0.00341"
"3.93600","-0.24047","-0.00321"
"3.94800","-0.23946","-0.00298"
"3.96000","-0.23844","-0.00278"
"3.97200","-0.23742","-0.00278"
"3.98400","-0.23641","-0.00268"
"3.99600","-0.23539","-0.00283"
"4.00800","-0.23438","-0.00303"
"4.02000","-0.23342","-0.00323"
"4.03200","-0.23240","-0.00326"
"4.04400","-0.23139","-0.00339"
"4.05600","-0.23043","-0.00333"
"4.06800","-0.22941","-0.00323"
"4.08000","-0.22840","-0.00329"
"4.09200","-0.22738","-0.00313"
"4.10400","-0.22636","-0.00308"
"4.11600","-0.22535","-0.00318"
"4.12800","-0.22439","-0.00322"
"4.14000","-0.22337","-0.00332"
"4.15200","-0.22236","-0.00334"
"4.16400","-0.22140","-0.00341"
"4.17600","-0.22038","-0.00331"
"4.18800","-0.21937","-0.00314"
"4.20000","-0.21841","-0.00315"
"4.21200","-0.21739","-0.00317"
"4.22400","-0.21644","-0.00317"
"4.23600","-0.21542","-0.00314"
"4.24800","-0.21441","-0.00317"
"4.26000","-0.21339","-0.00305"
"4.27200","-0.21243","-0.00309"
"4.28400","-0.21142","-0.00326"
"4.29600","-0.21046","-0.00335"
"4.30800","-0.20944","-0.00329"
"4.32000","-0.20843","-0.00334"
"4.33200","-0.20747","-0.00338"
"4.34400","-0.20645","-0.00344"
"4.35600","-0.20544","-0.00331"
"4.36800","-0.20448","-0.00315"
"4.38000","-0.20346","-0.00304"
"4.39200","-0.20245","-0.00308"
"4.40400","-0.20143","-0.00306"
"4.41600","-0.20041","-0.00310"
"4.42800","-0.19940","-0.00310"
"4.44000","-0.19844","-0.00332"
"4.45200","-0.19743","-0.00339"
"4.46400","-0.19641","-0.00324"
"4.47600","-0.19539","-0.00309"
"4.48800","-0.19444","-0.00319"
"4.50000","-0.19342","-0.00316"
"4.51200","-0.19240","-0.00314"
"4.52400","-0.19139","-0.00324"
"4.53600","-0.19043","-0.00330"
"4.54800","-0.18941","-0.00321"
"4.56000","-0.18840","-0.00302"
"4.57200","-0.18738","-0.00293"
"4.58400","-0.18642","-0.00295"
"4.59600","-0.18541","-0.00305"
"4.60800","-0.18439","-0.00298"
"4.62000","-0.18337","-0.00288"
"4.63200","-0.18236","-0.00273"
"4.64400","-0.18140","-0.00265"
"4.65600","-0.18039","-0.00274"
"4.66800","-0.17937","-0.00301"
"4.68000","-0.17841","-0.00325"
"4.69200","-0.17740","-0.00321"
"4.70400","-0.17638","-0.00314"
"4.71600","-0.17536","-0.00307"
"4.72800","-0.17435","-0.00298"
"4.74000","-0.17339","-0.00283"
"4.75200","-0.17237","-0.00287"
"4.76400","-0.17142","-0.00288"
"4.77600","-0.17040","-0.00294"
"4.78800","-0.16944","-0.00308"
"4.80000","-0.16843","-0.00308"
"4.81200","-0.16741","-0.00298"
"4.82400","-0.16645","-0.00285"
"4.83600","-0.16544","-0.00279"
"4.84800","-0.16442","-0.00299"
"4.86000","-0.16346","-0.00304"
"4.87200","-0.16245","-0.00299"
"4.88400","-0.16143","-0.00287"
"4.89600","-0.16048","-0.00262"
"4.90800","-0.15946","-0.00264"
"4.92000","-0.15844","-0.00282"
"4.93200","-0.15749","-0.00282"
"4.94400","-0.15647","-0.00291"
"4.95600","-0.15545","-0.00298"
"4.96800","-0.15444","-0.00282"
"4.98000","-0.15342","-0.00271"
"4.99200","-0.15240","-0.00262"
"5.00400","-0.15145","-0.00252"
"5.01600","-0.15043","-0.00277"
"5.02800","-0.14941","-0.00289"
"5.04000","-0.14846","-0.00267"
"5.05200","-0.14744","-0.00260"
"5.06400","-0.14642","-0.00261"
"5.07600","-0.14541","-0.00256"
"5.08800","-0.14445","-0.00262"
"5.10000","-0.14344","-0.00259"
"5.11200","-0.14242","-0.00282"
"5.12400","-0.14140","-0.00300"
"5.13600","-0.14039","-0.00294"
"5.14800","-0.13943","-0.00290"
"5.16000","-0.13841","-0.00287"
"5.17200","-0.13740","-0.00283"
"5.18400","-0.13644","-0.00281"
"5.19600","-0.13542","-0.00286"
"5.20800","-0.13441","-0.00292"
"5.22000","-0.13345","-0.00306"
"5.23200","-0.13243","-0.00289"
"5.24400","-0.13142","-0.00275"
"5.25600","-0.13046","-0.00267"
"5.26800","-0.12938","-0.00271"
"5.28000","-0.12837","-0.00255"
"5.29200","-0.12741","-0.00234"
"5.30400","-0.12640","-0.00225"
"5.31600","-0.12544","-0.00246"
"5.32800","-0.12442","-0.00275"
"5.34000","-0.12347","-0.00294"
"5.35200","-0.12245","-0.00294"
"5.36400","-0.12149","-0.00279"
"5.37600","-0.12048","-0.00241"
"5.38800","-0.11946","-0.00226"
"5.40000","-0.11844","-0.00241"
"5.41200","-0.11743","-0.00261"
"5.42400","-0.11641","-0.00273"
"5.43600","-0.11539","-0.00268"
"5.44800","-0.11444","-0.00268"
"5.46000","-0.11342","-0.00265"
"5.47200","-0.11246","-0.00269"
"5.48400","-0.11145","-0.00250"
"5.49600","-0.11043","-0.00244"
"5.50800","-0.10947","-0.00244"
"5.52000","-0.10846","-0.00238"
"5.53200","-0.10744","-0.00235"
"5.54400","-0.10643","-0.00244"
"5.55600","-0.10541","-0.00246"
"5.56800","-0.10439","-0.00242"
"5.58000","-0.10338","-0.00239"
"5.59200","-0.10242","-0.00249"
"5.60400","-0.10140","-0.00250"
"5.61600","-0.10045","-0.00252"
"5.62800","-0.09943","-0.00262"
"5.64000","-0.09841","-0.00266"
"5.65200","-0.09740","-0.00274"
"5.66400","-0.09644","-0.00265"
"5.67600","-0.09542","-0.00257"
"5.68800","-0.09441","-0.00256"
"5.70000","-0.09339","-0.00268"
"5.71200","-0.09237","-0.00264"
"5.72400","-0.09136","-0.00257"
"5.73600","-0.09034","-0.00247"
"5.74800","-0.08939","-0.00243"
"5.76000","-0.08837","-0.00234"
"5.77200","-0.08735","-0.00226"
"5.78400","-0.08640","-0.00232"
"5.79600","-0.08538","-0.00248"
"5.80800","-0.08436","-0.00245"
"5.82000","-0.08341","-0.00237"
"5.83200","-0.08239","-0.00234"
"5.84400","-0.08137","-0.00230"
"5.85600","-0.08042","-0.00221"
"5.86800","-0.07940","-0.00226"
"5.88000","-0.07844","-0.00212"
"5.89200","-0.07743","-0.00203"
"5.90400","-0.07647","-0.00215"
"5.91600","-0.07545","-0.00220"
"5.92800","-0.07444","-0.00223"
"5.94000","-0.07342","-0.00223"
"5.95200","-0.07246","-0.00235"
"5.96400","-0.07145","-0.00242"
"5.97600","-0.07049","-0.00239"
"5.98800","-0.06948","-0.00227"
"6.00000","-0.06846","-0.00224"
"6.01200","-0.06744","-0.00208"
"6.02400","-0.06643","-0.00191"
"6.03600","-0.06541","-0.00188"
"6.04800","-0.06445","-0.00208"
"6.06000","-0.06344","-0.00218"
"6.07200","-0.06242","-0.00236"
"6.08400","-0.06140","-0.00252"
"6.09600","-0.06045","-0.00254"
"6.10800","-0.05943","-0.00247"
"6.12000","-0.05841","-0.00243"
"6.13200","-0.05740","-0.00230"
"6.14400","-0.05638","-0.00219"
"6.15600","-0.05542","-0.00229"
"6.16800","-0.05441","-0.00216"
"6.18000","-0.05339","-0.00213"
"6.19200","-0.05244","-0.00222"
"6.20400","-0.05142","-0.00225"
"6.21600","-0.05040","-0.00213"
"6.22800","-0.04945","-0.00213"
"6.24000","-0.04843","-0.00210"
"6.25200","-0.04741","-0.00201"
"6.26400","-0.04640","-0.00206"
"6.27600","-0.04538","-0.00213"
"6.28800","-0.04436","-0.00214"
"6.30000","-0.04341","-0.00224"
"6.31200","-0.04239","-0.00238"
"6.32400","-0.04143","-0.00232"
"6.33600","-0.04042","-0.00211"
"6.34800","-0.03946","-0.00207"
"6.36000","-0.03844","-0.00219"
"6.37200","-0.03743","-0.00213"
"6.38400","-0.03647","-0.00196"
"6.39600","-0.03546","-0.00196"
"6.40800","-0.03444","-0.00215"
"6.42000","-0.03342","-0.00221"
"6.43200","-0.03241","-0.00208"
"6.44400","-0.03145","-0.00214"
"6.45600","-0.03049","-0.00212"
"6.46800","-0.02948","-0.00194"
"6.48000","-0.02852","-0.00165"
"6.49200","-0.02750","-0.00169"
"6.50400","-0.02655","-0.00159"
"6.51600","-0.02553","-0.00161"
"6.52800","-0.02457","-0.00170"
"6.54000","-0.02356","-0.00171"
"6.55200","-0.02254","-0.00190"
"6.56400","-0.02146","-0.00211"
"6.57600","-0.02045","-0.00199"
"6.58800","-0.01943","-0.00192"
"6.60000","-0.01842","-0.00169"
"6.61200","-0.01740","-0.00164"
"6.62400","-0.01644","-0.00193"
"6.63600","-0.01543","-0.00199"
"6.64800","-0.01441","-0.00202"
"6.66000","-0.01345","-0.00193"
"6.67200","-0.01244","-0.00184"
"6.68400","-0.01142","-0.00176"
"6.69600","-0.01040","-0.00171"
"6.70800","-0.00939","-0.00174"
"6.72000","-0.00837","-0.00195"
"6.73200","-0.00735","-0.00204"
"6.74400","-0.00640","-0.00208"
"6.75600","-0.00538","-0.00211"
"6.76800","-0.00442","-0.00205"
"6.78000","-0.00341","-0.00164"
"6.79200","-0.00245","-0.00140"
"6.80400","-0.00143","-0.00165"
"6.81600","-0.00042","-0.00177"
"6.82800","0.00054","-0.00172"
"6.84000","0.00161","-0.00168"
"6.85200","0.00263","-0.00152"
"6.86400","0.00365","-0.00152"
"6.87600","0.00466","-0.00167"
"6.88800","0.00562","-0.00174"
"6.90000","0.00664","-0.00166"
"6.91200","0.00759","-0.00173"
"6.92400","0.00861","-0.00183"
"6.93600","0.00957","-0.00160"
"6.94800","0.01058","-0.00143"
"6.96000","0.01154","-0.00155"
"6.97200","0.01256","-0.00172"
"6.98400","0.01357","-0.00169"
"6.99600","0.01459","-0.00166"
"7.00800","0.01555","-0.00164"
"7.02000","0.01656","-0.00162"
"7.03200","0.01758","-0.00169"
"7.04400","0.01853","-0.00163"
"7.05600","0.01955","-0.00158"
"7.06800","0.02051","-0.00164"
"7.08000","0.02152","-0.00174"
"7.09200","0.02254","-0.00186"
"7.10400","0.02356","-0.00166"
"7.11600","0.02451","-0.00159"
"7.12800","0.02553","-0.00172"
"7.14000","0.02655","-0.00170"
"7.15200","0.02756","-0.00175"
"7.16400","0.02858","-0.00177"
"7.17600","0.02954","-0.00183"
"7.18800","0.03055","-0.00194"
"7.20000","0.03157","-0.00188"
"7.21200","0.03259","-0.00166"
"7.22400","0.03354","-0.00147"
"7.23600","0.03456","-0.00154"
"7.24800","0.03557","-0.00176"
"7.26000","0.03659","-0.00187"
"7.27200","0.03761","-0.00195"
"7.28400","0.03862","-0.00180"
"7.29600","0.03964","-0.00169"
"7.30800","0.04060","-0.00177"
"7.32000","0.04161","-0.00176"
"7.33200","0.04263","-0.00190"
"7.34400","0.04359","-0.00184"
"7.35600","0.04460","-0.00164"
"7.36800","0.04556","-0.00157"
"7.38000","0.04658","-0.00139"
"7.39200","0.04759","-0.00143"
"7.40400","0.04855","-0.00149"
"7.41600","0.04957","-0.00156"
"7.42800","0.05058","-0.00163"
"7.44000","0.05160","-0.00163"
"7.45200","0.05261","-0.00172"
"7.46400","0.05357","-0.00157"
"7.47600","0.05459","-0.00169"
"7.48800","0.05554","-0.00177"
"7.50000","0.05650","-0.00166"
"7.51200","0.05752","-0.00151"
"7.52400","0.05853","-0.00145"
"7.53600","0.05955","-0.00150"
"7.54800","0.06057","-0.00144"
"7.56000","0.06158","-0.00132"
"7.57200","0.06260","-0.00124"
"7.58400","0.06356","-0.00137"
"7.59600","0.06457","-0.00135"
"7.60800","0.06553","-0.00121"
"7.62000","0.06655","-0.00113"
"7.63200","0.06750","-0.00117"
"7.64400","0.06852","-0.00144"
"7.65600","0.06954","-0.00169"
"7.66800","0.07055","-0.00187"
"7.68000","0.07157","-0.00185"
"7.69200","0.07258","-0.00147"
"7.70400","0.07360","-0.00132"
"7.71600","0.07462","-0.00126"
"7.72800","0.07563","-0.00098"
"7.74000","0.07665","-0.00101"
"7.75200","0.07761","-0.00119"
"7.76400","0.07862","-0.00135"
"7.77600","0.07964","-0.00150"
"7.78800","0.08060","-0.00154"
"7.80000","0.08161","-0.00140"
"7.81200","0.08257","-0.00125"
"7.82400","0.08359","-0.00116"
"7.83600","0.08460","-0.00115"
"7.84800","0.08556","-0.00138"
"7.86000","0.08658","-0.00162"
"7.87200","0.08759","-0.00173"
"7.88400","0.08861","-0.00160"
"7.89600","0.08956","-0.00141"
"7.90800","0.09058","-0.00120"
"7.92000","0.09160","-0.00112"
"7.93200","0.09261","-0.00120"
"7.94400","0.09363","-0.00124"
"7.95600","0.09459","-0.00120"
"7.96800","0.09560","-0.00132"
"7.98000","0.09656","-0.00133"
"7.99200","0.09758","-0.00111"
"8.00400","0.09859","-0.00113"
"8.01600","0.09961","-0.00117"
"8.02800","0.10063","-0.00125"
"8.04000","0.10158","-0.00138"
"8.05200","0.10260","-0.00144"
"8.06400","0.10356","-0.00142"
"8.07600","0.10457","-0.00149"
"8.08800","0.10559","-0.00153"
"8.10000","0.10654","-0.00137"
"8.11200","0.10756","-0.00123"
"8.12400","0.10852","-0.00117"
"8.13600","0.10953","-0.00130"
"8.14800","0.11055","-0.00127"
"8.16000","0.11157","-0.00133"
"8.17200","0.11252","-0.00133"
"8.18400","0.11354","-0.00119"
"8.19600","0.11456","-0.00123"
"8.20800","0.11557","-0.00144"
"8.22000","0.11659","-0.00143"
"8.23200","0.11761","-0.00125"
"8.24400","0.11856","-0.00105"
"8.25600","0.11958","-0.00126"
"8.26800","0.12060","-0.00136"
"8.28000","0.12161","-0.00136"
"8.29200","0.12263","-0.00126"
"8.30400","0.12358","-0.00123"
"8.31600","0.12460","-0.00123"
"8.32800","0.12562","-0.00104"
"8.34000","0.12663","-0.00085"
"8.35200","0.12759","-0.00088"
"8.36400","0.12861","-0.00103"
"8.37600","0.12962","-0.00123"
"8.38800","0.13064","-0.00128"
"8.40000","0.13166","-0.00132"
"8.41200","0.13261","-0.00131"
"8.42400","0.13363","-0.00135"
"8.43600","0.13459","-0.00117"
"8.44800","0.13560","-0.00105"
"8.46000","0.13662","-0.00118"
"8.47200","0.13764","-0.00115"
"8.48400","0.13859","-0.00107"
"8.49600","0.13961","-0.00113"
"8.50800","0.14062","-0.00099"
"8.52000","0.14158","-0.00102"
"8.53200","0.14260","-0.00087"
"8.54400","0.14361","-0.00078"
"8.55600","0.14457","-0.00092"
"8.56800","0.14559","-0.00088"
"8.58000","0.14660","-0.00090"
"8.59200","0.14762","-0.00102"
"8.60400","0.14858","-0.00118"
"8.61600","0.14959","-0.00128"
"8.62800","0.15061","-0.00129"
"8.64000","0.15157","-0.00125"
"8.65200","0.15258","-0.00106"
"8.66400","0.15360","-0.00083"
"8.67600","0.15456","-0.00081"
"8.68800","0.15557","-0.00105"
"8.70000","0.15653","-0.00126"
"8.71200","0.15755","-0.00126"
"8.72400","0.15856","-0.00121"
"8.73600","0.15958","-0.00121"
"8.74800","0.16059","-0.00114"
"8.76000","0.16155","-0.00095"
"8.77200","0.16257","-0.00083"
"8.78400","0.16358","-0.00075"
"8.79600","0.16454","-0.00085"
"8.80800","0.16556","-0.00095"
"8.82000","0.16657","-0.00105"
"8.83200","0.16759","-0.00101"
"8.84400","0.16855","-0.00097"
"8.85600","0.16956","-0.00096"
"8.86800","0.17064","-0.00091"
"8.88000","0.17166","-0.00092"
"8.89200","0.17261","-0.00100"
"8.90400","0.17357","-0.00107"
"8.91600","0.17459","-0.00100"
"8.92800","0.17560","-0.00080"
"8.94000","0.17656","-0.00071"
"8.95200","0.17757","-0.00075"
"8.96400","0.17859","-0.00083"
"8.97600","0.17961","-0.00093"
"8.98800","0.18062","-0.00099"
"9.00000","0.18164","-0.00094"
"9.01200","0.18260","-0.00091"
"9.02400","0.18361","-0.00084"
"9.03600","0.18463","-0.00068"
"9.04800","0.18559","-0.00067"
"9.06000","0.18654","-0.00073"
"9.07200","0.18756","-0.00095"
"9.08400","0.18852","-0.00096"
"9.09600","0.18953","-0.00096"
"9.10800","0.19055","-0.00111"
"9.12000","0.19151","-0.00127"
"9.13200","0.19252","-0.00109"
"9.14400","0.19360","-0.00093"
"9.15600","0.19461","-0.00094"
"9.16800","0.19557","-0.00093"
"9.18000","0.19659","-0.00075"
"9.19200","0.19754","-0.00056"
"9.20400","0.19856","-0.00052"
"9.21600","0.19952","-0.00052"
"9.22800","0.20053","-0.00062"
"9.24000","0.20155","-0.00086"
"9.25200","0.20257","-0.00118"
"9.26400","0.20352","-0.00134"
"9.27600","0.20454","-0.00135"
"9.28800","0.20562","-0.00115"
"9.30000","0.20663","-0.00102"
"9.31200","0.20759","-0.00095"
"9.32400","0.20861","-0.00077"
"9.33600","0.20962","-0.00068"
"9.34800","0.21058","-0.00074"
"9.36000","0.21160","-0.00065"
"9.37200","0.21261","-0.00067"
"9.38400","0.21357","-0.00060"
"9.39600","0.21458","-0.00068"
"9.40800","0.21560","-0.00110"
"9.42000","0.21662","-0.00106"
"9.43200","0.21757","-0.00090"
"9.44400","0.21859","-0.00078"
"9.45600","0.21961","-0.00086"
"9.46800","0.22056","-0.00079"
"9.48000","0.22158","-0.00077"
"9.49200","0.22260","-0.00093"
"9.50400","0.22361","-0.00096"
"9.51600","0.22463","-0.00076"
"9.52800","0.22559","-0.00050"
"9.54000","0.22660","-0.00036"
"9.55200","0.22762","-0.00044"
"9.56400","0.22864","-0.00066"
"9.57600","0.22965","-0.00061"
"9.58800","0.23061","-0.00058"
"9.60000","0.23162","-0.00082"
"9.61200","0.23258","-0.00069"
"9.62400","0.23360","-0.00069"
"9.63600","0.23455","-0.00049"
"9.64800","0.23557","-0.00062"
"9.66000","0.23659","-0.00060"
"9.67200","0.23754","-0.00071"
"9.68400","0.23856","-0.00077"
"9.69600","0.23958","-0.00072"
"9.70800","0.24053","-0.00077"
"9.72000","0.24155","-0.00078"
"9.73200","0.24257","-0.00066"
"9.74400","0.24352","-0.00072"
"9.75600","0.24454","-0.00084"
"9.76800","0.24556","-0.00076"
"9.78000","0.24657","-0.00084"
"9.79200","0.24753","-0.00087"
"9.80400","0.24855","-0.00090"
"9.81600","0.24956","-0.00087"
"9.82800","0.25058","-0.00084"
"9.84000","0.25153","-0.00077"
"9.85200","0.25255","-0.00082"
"9.86400","0.25357","-0.00083"
"9.87600","0.25458","-0.00080"
"9.88800","0.25560","-0.00064"
"9.90000","0.25656","-0.00059"
"9.91200","0.25757","-0.00063"
"9.92400","0.25859","-0.00064"
"9.93600","0.25961","-0.00060"
"9.94800","0.26062","-0.00058"
"9.96000","0.26158","-0.00048"
"9.97200","0.26260","-0.00055"
"9.98400","0.26361","-0.00053"
"9.99600","0.26463","-0.00062"
"10.00800","0.26559","-0.00070"
"10.02000","0.26660","-0.00056"
"10.03200","0.26762","-0.00037"
"10.04400","0.26857","-0.00029"
"10.05600","0.26959","-0.00031"
"10.06800","0.27061","-0.00043"
"10.08000","0.27156","-0.00055"
"10.09200","0.27258","-0.00059"
"10.10400","0.27360","-0.00045"
"10.11600","0.27455","-0.00030"
"10.12800","0.27557","-0.00024"
"10.14000","0.27659","-0.00015"
"10.15200","0.27760","-0.00029"
"10.16400","0.27862","-0.00053"
"10.17600","0.27958","-0.00048"
"10.18800","0.28059","-0.00049"
"10.20000","0.28155","-0.00049"
"10.21200","0.28257","-0.00056"
"10.22400","0.28358","-0.00064"
"10.23600","0.28454","-0.00058"
"10.24800","0.28555","-0.00050"
"10.26000","0.28651","-0.00035"