File: Force_trajectories/170212_2/Specimen_RawData_9.csv
End date,"2/12/2017"
Specimen label,"14AG_Unk"
Maximum Load,"0.65532",N

Time,Extension,Load
(s),(mm),(N)
"0.00000","0.00000","-0.00054"
"0.34200","0.02840","0.00084"
"0.68400","0.05722","0.00129"
"1.02600","0.08574","0.00138"
"1.36800","0.11420","0.00169"
"1.71000","0.14272","0.00197"
"2.05200","0.17118","0.00241"
"2.39400","0.19964","0.00260"
"2.73600","0.22816","0.00296"
"3.07800","0.25662","0.00338"
"3.42000","0.28520","0.00281"
"3.76200","0.31378","0.00301"
"4.10400","0.34212","0.00372"
"4.44600","0.37070","0.00353"
"4.78800","0.39915","0.00359"
"5.13000","0.42767","0.00390"
"5.47200","0.45619","0.00373"
"5.81400","0.48471","0.00460"
"6.15600","0.51317","0.00399"
"6.49800","0.54169","0.00453"
"6.84000","0.57015","0.00530"
"7.18200","0.59867","0.00532"
"7.52400","0.62719","0.00509"
"7.86600","0.65565","0.00495"
"8.20800","0.68417","0.00506"
"8.55000","0.71269","0.00542"
"8.89200","0.74115","0.00539"
"9.23400","0.76967","0.00572"
"9.57600","0.79819","0.00536"
"9.91800","0.82665","0.00575"
"10.26000","0.85517","0.00560"
"10.60200","0.88369","0.00559"
"10.94400","0.91215","0.00567"
"11.28600","0.94067","0.00583"
"11.62800","0.96919","0.00608"
"11.97000","0.99765","0.00627"
"12.31200","1.02623","0.00634"
"12.65400","1.05463","0.00607"
"12.99600","1.08315","0.00667"
"13.33800","1.11167","0.00648"
"13.68000","1.14013","0.00646"
"14.02200","1.16877","0.00685"
"14.36400","1.19711","0.00684"
"14.70600","1.22569","0.00702"
"15.04800","1.25420","0.00674"
"15.39000","1.28266","0.00664"
"15.73200","1.31124","0.00718"
"16.07400","1.33970","0.00723"
"16.41600","1.36816","0.00731"
"16.75800","1.39668","0.00736"
"17.10000","1.42514","0.00682"
"17.44200","1.45366","0.00721"
"17.78400","1.48218","0.00717"
"18.12600","1.51058","0.00691"
"18.46800","1.53916","0.00768"
"18.81000","1.56768","0.00679"
"19.15200","1.59614","0.00734"
"19.49400","1.62466","0.00755"
"19.83600","1.65318","0.00744"
"20.17800","1.68164","0.00756"
"20.52000","1.71022","0.00772"
"20.86200","1.73868","0.00751"
"21.20400","1.76720","0.00755"
"21.54600","1.79566","0.00756"
"21.88800","1.82412","0.00813"
"22.23000","1.85270","0.00797"
"22.57200","1.88122","0.00787"
"22.91400","1.90962","0.00774"
"23.25600","1.93820","0.00866"
"23.59800","1.96666","0.00813"
"23.94000","1.99512","0.00890"
"24.28200","2.02376","0.00852"
"24.62400","2.05216","0.00824"
"24.96600","2.08074","0.00814"
"25.30800","2.10920","0.00830"
"25.65000","2.13766","0.00899"
"25.99200","2.16617","0.00883"
"26.33400","2.19469","0.00833"
"26.67600","2.22315","0.00832"
"27.01800","2.25161","0.00861"
"27.36000","2.28013","0.00952"
"27.70200","2.30865","0.00867"
"28.04400","2.33717","0.00932"
"28.38600","2.36563","0.00842"
"28.72800","2.39415","0.00912"
"29.07000","2.42267","0.00850"
"29.41200","2.45113","0.00910"
"29.75400","2.47971","0.00938"
"30.09600","2.50829","0.00898"
"30.43800","2.53663","0.00817"
"30.78000","2.56521","0.00899"
"31.12200","2.59373","0.00845"
"31.46400","2.62213","0.00787"
"31.80600","2.65071","0.00751"
"32.14800","2.67917","0.00778"
"32.49000","2.70769","0.00842"
"32.83200","2.73621","0.00816"
"33.17400","2.76461","0.00769"
"33.51600","2.79319","0.00773"
"33.85800","2.82171","0.00737"
"34.20000","2.85017","0.00727"
"34.54200","2.87869","0.00760"
"34.88400","2.90715","0.00782"
"35.22600","2.93567","0.00838"
"35.56800","2.96419","0.00813"
"35.91000","2.99271","0.00840"
"36.25200","3.02122","0.00805"
"36.59400","3.04968","0.00803"
"36.93600","3.07808","0.00833"
"37.27800","3.10672","0.00861"
"37.62000","3.13518","0.00906"
"37.96200","3.16364","0.00888"
"38.30400","3.19216","0.00917"
"38.64600","3.22068","0.00959"
"38.98800","3.24920","0.00962"
"39.33000","3.27772","0.00939"
"39.67200","3.30612","0.00946"
"40.01400","3.33464","0.00922"
"40.35600","3.36322","0.00992"
"40.69800","3.39162","0.01042"
"41.04000","3.42020","0.00965"
"41.38200","3.44866","0.00965"
"41.72400","3.47718","0.01039"
"42.06600","3.50570","0.01040"
"42.40800","3.53416","0.01087"
"42.75000","3.56268","0.01095"
"43.09200","3.59120","0.01105"
"43.43400","3.61966","0.01062"
"43.77600","3.64824","0.01072"
"44.11800","3.67670","0.01060"
"44.46000","3.70516","0.01089"
"44.80200","3.73368","0.01129"
"45.14400","3.76220","0.01167"
"45.48600","3.79066","0.01129"
"45.82800","3.81918","0.01111"
"46.17000","3.84770","0.01184"
"46.51200","3.87616","0.01049"
"46.85400","3.90468","0.01083"
"47.19600","3.93319","0.01090"
"47.53800","3.96171","0.01075"
"47.88000","3.99023","0.01121"
"48.22200","4.01863","0.01110"
"48.56400","4.04715","0.01128"
"48.90600","4.07573","0.01106"
"49.24800","4.10413","0.01137"
"49.59000","4.13271","0.01073"
"49.93200","4.16117","0.01123"
"50.27400","4.18963","0.01146"
"50.61600","4.21827","0.01182"
"50.95800","4.24667","0.01159"
"51.30000","4.27519","0.01140"
"51.64200","4.30371","0.01110"
"51.98400","4.33211","0.01216"
"52.32600","4.36069","0.01249"
"52.66800","4.38915","0.01153"
"53.01000","4.41767","0.01205"
"53.35200","4.44625","0.01226"
"53.69400","4.47465","0.01155"
"54.03600","4.50317","0.01237"
"54.37800","4.53169","0.01217"
"54.72000","4.56015","0.01261"
"55.06200","4.58873","0.01307"
"55.40400","4.61725","0.01290"
"55.74600","4.64559","0.01302"
"56.08800","4.67417","0.01361"
"56.43000","4.70269","0.01308"
"56.77200","4.73115","0.01379"
"57.11400","4.75967","0.01247"
"57.45600","4.78813","0.01312"
"57.79800","4.81670","0.01285"
"58.14000","4.84516","0.01242"
"58.48200","4.87362","0.01249"
"58.82400","4.90220","0.01325"
"59.16600","4.93066","0.01280"
"59.50800","4.95918","0.01272"
"59.85000","4.98770","0.01393"
"60.19200","5.01616","0.01347"
"60.53400","5.04462","0.01320"
"60.87600","5.07320","0.01360"
"61.21800","5.10166","0.01352"
"61.56000","5.13018","0.01404"
"61.90200","5.15864","0.01340"
"62.24400","5.18716","0.01346"
"62.58600","5.21568","0.01365"
"62.92800","5.24420","0.01310"
"63.27000","5.27266","0.01381"
"63.61200","5.30118","0.01347"
"63.95400","5.32970","0.01423"
"64.29600","5.35816","0.01401"
"64.63800","5.38668","0.01380"
"64.98000","5.41520","0.01412"
"65.32200","5.44366","0.01426"
"65.66400","5.47224","0.01370"
"66.00600","5.50064","0.01341"
"66.34800","5.52916","0.01348"
"66.69000","5.55774","0.01393"
"67.03200","5.58614","0.01409"
"67.37400","5.61472","0.01426"
"67.71600","5.64324","0.01412"
"68.05800","5.67169","0.01397"
"68.40000","5.70015","0.01419"
"68.74200","5.72867","0.01485"
"69.08400","5.75713","0.01412"
"69.42600","5.78577","0.01462"
"69.76800","5.81411","0.01462"
"70.11000","5.84269","0.01479"
"70.45200","5.87115","0.01477"
"70.79400","5.89967","0.01545"
"71.13600","5.92819","0.01502"
"71.47800","5.95665","0.01518"
"71.82000","5.98511","0.01457"
"72.16200","6.01363","0.01464"
"72.50400","6.04215","0.01491"
"72.84600","6.07073","0.01440"
"73.18800","6.09919","0.01496"
"73.53000","6.12759","0.01476"
"73.87200","6.15623","0.01450"
"74.21400","6.18469","0.01558"
"74.55600","6.21315","0.01474"
"74.89800","6.24167","0.01521"
"75.24000","6.27013","0.01370"
"75.58200","6.29865","0.01508"
"75.92400","6.32723","0.01463"
"76.26600","6.35563","0.01530"
"76.60800","6.38421","0.01423"
"76.95000","6.41267","0.01483"
"77.29200","6.44113","0.01431"
"77.63400","6.46971","0.01449"
"77.97600","6.49823","0.01411"
"78.31800","6.52663","0.01477"
"78.66000","6.55520","0.01418"
"79.00200","6.58366","0.01488"
"79.34400","6.61218","0.01441"
"79.68600","6.64070","0.01403"
"80.02800","6.66916","0.01483"
"80.37000","6.69762","0.01444"
"80.71200","6.72620","0.01432"
"81.05400","6.75466","0.01499"
"81.39600","6.78318","0.01502"
"81.73800","6.81170","0.01517"
"82.08000","6.84016","0.01434"
"82.42200","6.86868","0.01452"
"82.76400","6.89720","0.01519"
"83.10600","6.92566","0.01523"
"83.44800","6.95424","0.01489"
"83.79000","6.98264","0.01486"
"84.13200","7.01116","0.01486"
"84.47400","7.03974","0.01495"
"84.81600","7.06814","0.01530"
"85.15800","7.09672","0.01536"
"85.50000","7.12518","0.01541"
"85.84200","7.15364","0.01590"
"86.18400","7.18222","0.01617"
"86.52600","7.21068","0.01593"
"86.86800","7.23914","0.01606"
"87.21000","7.26772","0.01583"
"87.55200","7.29618","0.01621"
"87.89400","7.32464","0.01604"
"88.23600","7.35322","0.01582"
"88.57800","7.38162","0.01608"
"88.92000","7.41020","0.01599"
"89.26200","7.43865","0.01677"
"89.60400","7.46712","0.01601"
"89.94600","7.49569","0.01677"
"90.28800","7.52415","0.01684"
"90.63000","7.55267","0.01617"
"90.97200","7.58119","0.01613"
"91.31400","7.60959","0.01662"
"91.65600","7.63817","0.01663"
"91.99800","7.66675","0.01642"
"92.34000","7.69509","0.01692"
"92.68200","7.72367","0.01648"
"93.02400","7.75219","0.01682"
"93.36600","7.78065","0.01562"
"93.70800","7.80923","0.01595"
"94.05000","7.83763","0.01592"
"94.39200","7.86621","0.01538"
"94.73400","7.89467","0.01501"
"95.07600","7.92313","0.01550"
"95.41800","7.95165","0.01563"
"95.76000","7.98017","0.01516"
"96.10200","8.00863","0.01528"
"96.44400","8.03721","0.01547"
"96.78600","8.06567","0.01552"
"97.12800","8.09413","0.01592"
"97.47000","8.12265","0.01615"
"97.81200","8.15117","0.01644"
"98.15400","8.17969","0.01638"
"98.49600","8.20815","0.01621"
"98.83800","8.23667","0.01584"
"99.18000","8.26513","0.01624"
"99.52200","8.29370","0.01637"
"99.86400","8.32210","0.01650"
"100.20600","8.35068","0.01630"
"100.54800","8.37920","0.01598"
"100.89000","8.40766","0.01655"
"101.23200","8.43618","0.01653"
"101.57400","8.46464","0.01633"
"101.91600","8.49316","0.01648"
"102.25800","8.52168","0.01672"
"102.60000","8.55014","0.01649"
"102.94200","8.57866","0.01690"
"103.28400","8.60724","0.01721"
"103.62600","8.63564","0.01698"
"103.96800","8.66416","0.01631"
"104.31000","8.69268","0.01691"
"104.65200","8.72120","0.01714"
"104.99400","8.74972","0.01716"
"105.33600","8.77812","0.01703"
"105.67800","8.80664","0.01686"
"106.02000","8.83522","0.01571"
"106.36200","8.86362","0.01646"
"106.70400","8.89220","0.01732"
"107.04600","8.92072","0.01697"
"107.38800","8.94912","0.01692"
"107.73000","8.97770","0.01690"
"108.07200","9.00622","0.01762"
"108.41400","9.03462","0.01745"
"108.75600","9.06320","0.01758"
"109.09800","9.09160","0.01789"
"109.44000","9.12018","0.01800"
"109.78200","9.14870","0.01826"
"110.12400","9.17710","0.01839"
"110.46600","9.20573","0.01714"
"110.80800","9.23419","0.01830"
"111.15000","9.26265","0.01822"
"111.49200","9.29123","0.01849"
"111.83400","9.31969","0.01584"
"112.17600","9.34815","0.01569"
"112.51800","9.37667","0.01616"
"112.86000","9.40513","0.01609"
"113.20200","9.43365","0.01647"
"113.54400","9.46217","0.01611"
"113.88600","9.49069","0.01690"
"114.22800","9.51915","0.01651"
"114.57000","9.54767","0.01685"
"114.91200","9.57619","0.01622"
"115.25400","9.60465","0.01666"
"115.59600","9.63323","0.01693"
"115.93800","9.66163","0.01742"
"116.28000","9.69015","0.01711"
"116.62200","9.71867","0.01698"
"116.96400","9.74719","0.01692"
"117.30600","9.77571","0.01759"
"117.64800","9.80417","0.01752"
"117.99000","9.83263","0.01799"
"118.33200","9.86121","0.01775"
"118.67400","9.88961","0.01862"
"119.01600","9.91819","0.01798"
"119.35800","9.94665","0.01836"
"119.70000","9.97517","0.01741"
"120.04200","10.00369","0.01628"
"120.38400","10.03221","0.01691"
"120.72600","10.06066","0.01750"
"121.06800","10.08924","0.01781"
"121.41000","10.11764","0.01808"
"121.75200","10.14616","0.01795"
"122.09400","10.17474","0.01784"
"122.43600","10.20314","0.01831"
"122.77800","10.23166","0.01810"
"123.12000","10.26012","0.01822"
"123.46200","10.28864","0.01829"
"123.80400","10.31722","0.01808"
"124.14600","10.34562","0.01811"
"124.48800","10.37420","0.01511"
"124.83000","10.40272","0.01481"
"125.17200","10.43112","0.01549"
"125.51400","10.45970","0.01558"
"125.85600","10.48816","0.01501"
"126.19800","10.51662","0.01529"
"126.54000","10.54520","0.01531"
"126.88200","10.57366","0.01559"
"127.22400","10.60218","0.01562"
"127.56600","10.63070","0.01593"
"127.90800","10.65910","0.01613"
"128.25000","10.68774","0.01552"
"128.59200","10.71620","0.01600"
"128.93400","10.74466","0.01572"
"129.27600","10.77318","0.01628"
"129.61800","10.80170","0.01608"
"129.96000","10.83022","0.01577"
"130.30200","10.85868","0.01589"
"130.64400","10.88713","0.01601"
"130.98600","10.91566","0.01716"
"131.32800","10.94418","0.01662"
"131.67000","10.97263","0.01684"
"132.01200","11.00121","0.01586"
"132.35400","11.02967","0.01576"
"132.69600","11.05807","0.01613"
"133.03800","11.08671","0.01623"
"133.38000","11.11517","0.01648"
"133.72200","11.14363","0.01700"
"134.06400","11.17215","0.01703"
"134.40600","11.20067","0.01709"
"134.74800","11.22919","0.01719"
"135.09000","11.25771","0.01700"
"135.43200","11.28617","0.01740"
"135.77400","11.31463","0.01818"
"136.11600","11.34315","0.01768"
"136.45800","11.37161","0.01830"
"136.80000","11.40019","0.01779"
"137.14200","11.42871","0.01850"
"137.48400","11.45711","0.01836"
"137.82600","11.48569","0.01873"
"138.16800","11.51415","0.01871"
"138.51000","11.54267","0.01881"
"138.85200","11.57125","0.01824"
"139.19400","11.59965","0.01858"
"139.53600","11.62817","0.01901"
"139.87800","11.65669","0.01844"
"140.22000","11.68515","0.01911"
"140.56200","11.71367","0.01901"
"140.90400","11.74213","0.01938"
"141.24600","11.77059","0.01941"
"141.58800","11.79922","0.01975"
"141.93000","11.82769","0.01921"
"142.27200","11.85614","0.01894"
"142.61400","11.88472","0.01858"
"142.95600","11.91306","0.01927"
"143.29800","11.94170","0.01911"
"143.64000","11.97022","0.01894"
"143.98200","11.99862","0.01872"
"144.32400","12.02720","0.01921"
"144.66600","12.05566","0.01899"
"145.00800","12.08412","0.01926"
"145.35000","12.11270","0.01927"
"145.69200","12.14116","0.01924"
"146.03400","12.16974","0.01951"
"146.37600","12.19820","0.01961"
"146.71800","12.22660","0.01993"
"147.06000","12.25518","0.01997"
"147.40200","12.28370","0.01993"
"147.74400","12.31216","0.02000"
"148.08600","12.34068","0.02029"
"148.42800","12.36914","0.02106"
"148.77000","12.39766","0.02036"
"149.11200","12.42618","0.02070"
"149.45400","12.45464","0.01870"
"149.79600","12.48316","0.01882"
"150.13800","12.51168","0.01936"
"150.48000","12.54014","0.01985"
"150.82200","12.56872","0.01941"
"151.16400","12.59718","0.02008"
"151.50600","12.62564","0.01992"
"151.84800","12.65421","0.02053"
"152.19000","12.68268","0.02116"
"152.53200","12.71114","0.02130"
"152.87400","12.73965","0.02169"
"153.21600","12.76817","0.02138"
"153.55800","12.79669","0.02185"
"153.90000","12.82521","0.02206"
"154.24200","12.85367","0.02239"
"154.58400","12.88219","0.02297"
"154.92600","12.91071","0.02257"
"155.26800","12.93911","0.02301"
"155.61000","12.96769","0.02337"
"155.95200","12.99615","0.02364"
"156.29400","13.02467","0.02403"
"156.63600","13.05319","0.02448"
"156.97800","13.08165","0.02434"
"157.32000","13.11017","0.02444"
"157.66200","13.13875","0.02393"
"158.00400","13.16715","0.02428"
"158.34600","13.19567","0.02419"
"158.68800","13.22425","0.02432"
"159.03000","13.25259","0.02536"
"159.37200","13.28117","0.02489"
"159.71400","13.30969","0.02545"
"160.05600","13.33815","0.02575"
"160.39800","13.36673","0.02563"
"160.74000","13.39513","0.02515"
"161.08200","13.42365","0.02611"
"161.42400","13.45217","0.02594"
"161.76600","13.48063","0.02659"
"162.10800","13.50927","0.02665"
"162.45000","13.53767","0.02697"
"162.79200","13.56612","0.02610"
"163.13400","13.59471","0.02633"
"163.47600","13.62316","0.02623"
"163.81800","13.65168","0.02636"
"164.16000","13.68020","0.02594"
"164.50200","13.70860","0.02671"
"164.84400","13.73718","0.02693"
"165.18600","13.76576","0.02649"
"165.52800","13.79416","0.02679"
"165.87000","13.82268","0.02710"
"166.21200","13.85114","0.02754"
"166.55400","13.87966","0.02770"
"166.89600","13.90818","0.02833"
"167.23800","13.93670","0.02823"
"167.58000","13.96522","0.02831"
"167.92200","13.99368","0.02890"
"168.26400","14.02214","0.02901"
"168.60600","14.05072","0.02927"
"168.94800","14.07918","0.02917"
"169.29000","14.10758","0.03001"
"169.63200","14.13616","0.03010"
"169.97400","14.16468","0.02980"
"170.31600","14.19314","0.03018"
"170.65800","14.22172","0.03015"
"171.00000","14.25018","0.03066"
"171.34200","14.27864","0.03066"
"171.68400","14.30722","0.03093"
"172.02600","14.33568","0.03136"
"172.36800","14.36420","0.03160"
"172.71000","14.39272","0.03125"
"173.05200","14.42112","0.03148"
"173.39400","14.44970","0.03183"
"173.73600","14.47822","0.03128"
"174.07800","14.50668","0.03038"
"174.42000","14.53513","0.02458"
"174.76200","14.56371","0.02504"
"175.10400","14.59211","0.02464"
"175.44600","14.62075","0.02572"
"175.78800","14.64915","0.02616"
"176.13000","14.67767","0.02589"
"176.47200","14.70625","0.02690"
"176.81400","14.73465","0.02692"
"177.15600","14.76317","0.02720"
"177.49800","14.79169","0.02763"
"177.84000","14.82015","0.02787"
"178.18200","14.84873","0.02817"
"178.52400","14.87713","0.02847"
"178.86600","14.90565","0.02862"
"179.20800","14.93423","0.02914"
"179.55000","14.96263","0.02983"
"179.89200","14.99121","0.02955"
"180.23400","15.01967","0.03024"
"180.57600","15.04813","0.03060"
"180.91800","15.07677","0.03008"
"181.26000","15.10517","0.03048"
"181.60200","15.13369","0.03050"
"181.94400","15.16221","0.03124"
"182.28600","15.19067","0.03121"
"182.62800","15.21919","0.03105"
"182.97000","15.24771","0.03160"
"183.31200","15.27611","0.03119"
"183.65400","15.30469","0.03101"
"183.99600","15.33321","0.03126"
"184.33800","15.36161","0.03120"
"184.68000","15.39018","0.03124"
"185.02200","15.41871","0.03139"
"185.36400","15.44716","0.03124"
"185.70600","15.47569","0.03150"
"186.04800","15.50414","0.03104"
"186.39000","15.53266","0.03110"
"186.73200","15.56118","0.03081"
"187.07400","15.58964","0.03089"
"187.41600","15.61816","0.03132"
"187.75800","15.64668","0.03158"
"188.10000","15.67514","0.03160"
"188.44200","15.70372","0.03191"
"188.78400","15.73218","0.03195"
"189.12600","15.76070","0.02939"
"189.46800","15.78916","0.03151"
"189.81000","15.81762","0.03083"
"190.15200","15.84614","0.03116"
"190.49400","15.87472","0.03263"
"190.83600","15.90312","0.03205"
"191.17800","15.93164","0.03280"
"191.52000","15.96022","0.03371"
"191.86200","15.98862","0.03374"
"192.20400","16.01720","0.03440"
"192.54600","16.04572","0.03422"
"192.88800","16.07412","0.03510"
"193.23000","16.10264","0.03552"
"193.57200","16.13116","0.03581"
"193.91400","16.15968","0.03608"
"194.25600","16.18826","0.03644"
"194.59800","16.21659","0.03644"
"194.94000","16.24517","0.03715"
"195.28200","16.27369","0.03806"
"195.62400","16.30215","0.03835"
"195.96600","16.33073","0.03884"
"196.30800","16.35913","0.03698"
"196.65000","16.38759","0.03695"
"196.99200","16.41617","0.03678"
"197.33400","16.44469","0.03756"
"197.67600","16.47315","0.03846"
"198.01800","16.50167","0.03880"
"198.36000","16.53007","0.03882"
"198.70200","16.55871","0.03896"
"199.04400","16.58717","0.03923"
"199.38600","16.61563","0.03953"
"199.72800","16.64421","0.04036"
"200.07000","16.67261","0.04064"
"200.41200","16.70119","0.04126"
"200.75400","16.72971","0.04171"
"201.09600","16.75817","0.04141"
"201.43800","16.78663","0.04095"
"201.78000","16.81521","0.03946"
"202.12200","16.84361","0.03911"
"202.46400","16.87219","0.03861"
"202.80600","16.90065","0.03854"
"203.14800","16.92917","0.03849"
"203.49000","16.95775","0.03904"
"203.83200","16.98615","0.03948"
"204.17400","17.01467","0.04340"
"204.51600","17.04319","0.03230"
"204.85800","17.07165","0.03285"
"205.20000","17.10016","0.03274"
"205.54200","17.12868","0.03347"
"205.88400","17.15714","0.03369"
"206.22600","17.18572","0.03420"
"206.56800","17.21418","0.03455"
"206.91000","17.24264","0.03489"
"207.25200","17.27116","0.03520"
"207.59400","17.29962","0.03586"
"207.93600","17.32808","0.03623"
"208.27800","17.35666","0.01535"
"208.62000","17.38512","0.01249"
"208.96200","17.41370","0.01633"
"209.30400","17.44216","0.01258"
"209.64600","17.47062","0.01350"
"209.98800","17.49920","0.01485"
"210.33000","17.52772","0.01586"
"210.67200","17.55612","0.01643"
"211.01400","17.58470","0.01500"
"211.35600","17.61316","0.01649"
"211.69800","17.64162","0.01710"
"212.04000","17.67020","0.01815"
"212.38200","17.69860","0.01715"
"212.72400","17.72718","0.01816"
"213.06600","17.75570","0.01874"
"213.40800","17.78410","0.01981"
"213.75000","17.81274","0.01993"
"214.09200","17.84114","0.02032"
"214.43400","17.86966","0.02162"
"214.77600","17.89824","0.02137"
"215.11800","17.92664","0.02099"
"215.46000","17.95516","0.02182"
"215.80200","17.98368","0.02260"
"216.14400","18.01213","0.02253"
"216.48600","18.04066","0.02274"
"216.82800","18.06917","0.02297"
"217.17000","18.09763","0.02362"
"217.51200","18.12615","0.02234"
"217.85400","18.15473","0.02198"
"218.19600","18.18313","0.02334"
"218.53800","18.21165","0.02403"
"218.88000","18.24011","0.02463"
"219.22200","18.26869","0.02513"
"219.56400","18.29715","0.02524"
"219.90600","18.32561","0.02582"
"220.24800","18.35419","0.02686"
"220.59000","18.38271","0.02702"
"220.93200","18.41111","0.02553"
"221.27400","18.43969","0.02466"
"221.61600","18.46815","0.02531"
"221.95800","18.49661","0.02506"
"222.30000","18.52519","0.02586"
"222.64200","18.55365","0.02635"
"222.98400","18.58223","0.02705"
"223.32600","18.61063","0.02763"
"223.66800","18.63915","0.02702"
"224.01000","18.66767","0.02743"
"224.35200","18.69619","0.02816"
"224.69400","18.72465","0.02839"
"225.03600","18.75317","0.02895"
"225.37800","18.78169","0.02891"
"225.72000","18.81015","0.02974"
"226.06200","18.83873","0.03005"
"226.40400","18.86719","0.02979"
"226.74600","18.89565","0.03018"
"227.08800","18.92422","0.02934"
"227.43000","18.95263","0.02889"
"227.77200","18.98120","0.02930"
"228.11400","19.00972","0.02924"
"228.45600","19.03812","0.03004"
"228.79800","19.06670","0.02999"
"229.14000","19.09522","0.03020"
"229.48200","19.12368","0.03045"
"229.82400","19.15220","0.03065"
"230.16600","19.18060","0.03065"
"230.50800","19.20912","0.03051"
"230.85000","19.23770","0.03071"
"231.19200","19.26610","0.03055"
"231.53400","19.29468","0.03098"
"231.87600","19.32320","0.03060"
"232.21800","19.35166","0.03034"
"232.56000","19.38024","0.03090"
"232.90200","19.40864","0.03114"
"233.24400","19.43716","0.03151"
"233.58600","19.46568","0.03170"
"233.92800","19.49414","0.03177"
"234.27000","19.52272","0.03179"
"234.61200","19.55124","0.03237"
"234.95400","19.57958","0.03254"
"235.29600","19.60822","0.03272"
"235.63800","19.63667","0.03288"
"235.98000","19.66514","0.03307"
"236.32200","19.69366","0.03364"
"236.66400","19.72217","0.03356"
"237.00600","19.75064","0.03377"
"237.34800","19.77915","0.03384"
"237.69000","19.80761","0.03404"
"238.03200","19.83619","0.03414"
"238.37400","19.86471","0.03466"
"238.71600","19.89311","0.03474"
"239.05800","19.92169","0.03480"
"239.40000","19.95015","0.03521"
"239.74200","19.97867","0.03540"
"240.08400","20.00719","0.03603"
"240.42600","20.03565","0.03603"
"240.76800","20.06417","0.03681"
"241.11000","20.09263","0.03655"
"241.45200","20.12115","0.03694"
"241.79400","20.14967","0.03724"
"242.13600","20.17819","0.03712"
"242.47800","20.20671","0.03736"
"242.82000","20.23523","0.03790"
"243.16200","20.26369","0.03895"
"243.50400","20.29215","0.03960"
"243.84600","20.32067","0.04055"
"244.18800","20.34919","0.04094"
"244.53000","20.37759","0.04111"
"244.87200","20.40617","0.04216"
"245.21400","20.43469","0.04299"
"245.55600","20.46315","0.04376"
"245.89800","20.49172","0.04485"
"246.24000","20.52013","0.04531"
"246.58200","20.54870","0.04732"
"246.92400","20.57723","0.04714"
"247.26600","20.60568","0.04783"
"247.60800","20.63421","0.04905"
"247.95000","20.66267","0.04996"
"248.29200","20.69112","0.05112"
"248.63400","20.71970","0.05241"
"248.97600","20.74817","0.05297"
"249.31800","20.77668","0.05440"
"249.66000","20.80520","0.05456"
"250.00200","20.83360","0.05604"
"250.34400","20.86218","0.05673"
"250.68600","20.89070","0.05843"
"251.02800","20.91916","0.05960"
"251.37000","20.94774","0.06064"
"251.71200","20.97614","0.06164"
"252.05400","21.00466","0.06278"
"252.39600","21.03318","0.06416"
"252.73800","21.06164","0.06513"
"253.08000","21.09022","0.06623"
"253.42200","21.11874","0.06747"
"253.76400","21.14708","0.06821"
"254.10600","21.17566","0.06998"
"254.44800","21.20424","0.07176"
"254.79000","21.23264","0.07301"
"255.13200","21.26122","0.07428"
"255.47400","21.28962","0.07580"
"255.81600","21.31820","0.07719"
"256.15800","21.34666","0.07860"
"256.50000","21.37512","0.07970"
"256.84200","21.40369","0.08056"
"257.18400","21.43216","0.08143"
"257.52600","21.46067","0.08234"
"257.86800","21.48919","0.08292"
"258.21000","21.51771","0.08335"
"258.55200","21.54618","0.08393"
"258.89400","21.57463","0.08424"
"259.23600","21.60315","0.08452"
"259.57800","21.63167","0.08546"
"259.92000","21.66019","0.08618"
"260.26200","21.68865","0.08709"
"260.60400","21.71717","0.08864"
"260.94600","21.74569","0.08997"
"261.28800","21.77415","0.09212"
"261.63000","21.80267","0.09414"
"261.97200","21.83119","0.09651"
"262.31400","21.85965","0.09803"
"262.65600","21.88817","0.10110"
"262.99800","21.91669","0.10327"
"263.34000","21.94515","0.10482"
"263.68200","21.97373","0.10725"
"264.02400","22.00207","0.10903"
"264.36600","22.03065","0.11122"
"264.70800","22.05923","0.11301"
"265.05000","22.08757","0.11460"
"265.39200","22.11621","0.11635"
"265.73400","22.14467","0.11727"
"266.07600","22.17319","0.11878"
"266.41800","22.20171","0.11992"
"266.76000","22.23017","0.12134"
"267.10200","22.25863","0.12224"
"267.44400","22.28720","0.12356"
"267.78600","22.31561","0.12450"
"268.12800","22.34419","0.12574"
"268.47000","22.37271","0.12665"
"268.81200","22.40117","0.12763"
"269.15400","22.42969","0.12855"
"269.49600","22.45820","0.12953"
"269.83800","22.48660","0.13026"
"270.18000","22.51518","0.13135"
"270.52200","22.54364","0.13219"
"270.86400","22.57216","0.13331"
"271.20600","22.60068","0.13430"
"271.54800","22.62908","0.13596"
"271.89000","22.65772","0.13666"
"272.23200","22.68618","0.13889"
"272.57400","22.71464","0.14051"
"272.91600","22.74316","0.14317"
"273.25800","22.77168","0.14706"
"273.60000","22.80014","0.14933"
"273.94200","22.82866","0.15335"
"274.28400","22.85712","0.15517"
"274.62600","22.88570","0.15817"
"274.96800","22.91416","0.16252"
"275.31000","22.94268","0.16801"
"275.65200","22.97120","0.17147"
"275.99400","22.99966","0.17699"
"276.33600","23.02818","0.18045"
"276.67800","23.05670","0.18306"
"277.02000","23.08522","0.18514"
"277.36200","23.11368","0.18734"
"277.70400","23.14220","0.18860"
"278.04600","23.17066","0.18918"
"278.38800","23.19912","0.19040"
"278.73000","23.22770","0.19155"
"279.07200","23.25616","0.19331"
"279.41400","23.28468","0.19587"
"279.75600","23.31319","0.19809"
"280.09800","23.34160","0.20202"
"280.44000","23.37017","0.20458"
"280.78200","23.39869","0.20855"
"281.12400","23.42721","0.11233"
"281.46600","23.45573","0.12702"
"281.80800","23.48419","0.12578"
"282.15000","23.51265","0.12475"
"282.49200","23.54117","0.12793"
"282.83400","23.56963","0.13246"
"283.17600","23.59815","0.14043"
"283.51800","23.62673","0.13720"
"283.86000","23.65513","0.14190"
"284.20200","23.68371","0.14761"
"284.54400","23.71217","0.16220"
"284.88600","23.74069","0.17641"
"285.22800","23.76921","0.17564"
"285.57000","23.79761","0.18085"
"285.91200","23.82619","0.18557"
"286.25400","23.85471","0.18806"
"286.59600","23.88317","0.19204"
"286.93800","23.91169","0.19604"
"287.28000","23.94015","0.19625"
"287.62200","23.96861","0.20014"
"287.96400","23.99725","0.20519"
"288.30600","24.02571","0.21002"
"288.64800","24.05411","0.21389"
"288.99000","24.08269","0.21969"
"289.33200","24.11108","0.22263"
"289.67400","24.13972","0.22484"
"290.01600","24.16825","0.22664"
"290.35800","24.19665","0.22937"
"290.70000","24.22516","0.23118"
"291.04200","24.25362","0.23243"
"291.38400","24.28214","0.23385"
"291.72600","24.31072","0.23536"
"292.06800","24.33912","0.23694"
"292.41000","24.36770","0.23808"
"292.75200","24.39616","0.23912"
"293.09400","24.42462","0.24082"
"293.43600","24.45320","0.24229"
"293.77800","24.48172","0.24465"
"294.12000","24.51012","0.24746"
"294.46200","24.53870","0.25129"
"294.80400","24.56716","0.25407"
"295.14600","24.59568","0.25827"
"295.48800","24.62420","0.26178"
"295.83000","24.65266","0.26514"
"296.17200","24.68118","0.26766"
"296.51400","24.70964","0.27078"
"296.85600","24.73816","0.27154"
"297.19800","24.76662","0.27277"
"297.54000","24.79520","0.08796"
"297.88200","24.82366","0.08640"
"298.22400","24.85224","0.08197"
"298.56600","24.88070","0.09161"
"298.90800","24.90910","0.10970"
"299.25000","24.93767","0.10034"
"299.59200","24.96614","0.09679"
"299.93400","24.99466","0.10297"
"300.27600","25.02318","0.11057"
"300.61800","25.05164","0.12100"
"300.96000","25.08015","0.12129"
"301.30200","25.10867","0.12308"
"301.64400","25.13713","0.12148"
"301.98600","25.16566","0.12524"
"302.32800","25.19417","0.12499"
"302.67000","25.22264","0.12854"
"303.01200","25.25121","0.13079"
"303.35400","25.27967","0.13283"
"303.69600","25.30813","0.13746"
"304.03800","25.33671","0.13918"
"304.38000","25.36511","0.14505"
"304.72200","25.39369","0.15166"
"305.06400","25.42221","0.15655"
"305.40600","25.45067","0.16611"
"305.74800","25.47919","0.17475"
"306.09000","25.50771","0.17940"
"306.43200","25.53617","0.18381"
"306.77400","25.56469","0.18759"
"307.11600","25.59315","0.18916"
"307.45800","25.62167","0.19088"
"307.80000","25.65019","0.19390"
"308.14200","25.67859","0.19816"
"308.48400","25.70723","0.20148"
"308.82600","25.73569","0.20553"
"309.16800","25.76415","0.21026"
"309.51000","25.79273","0.21451"
"309.85200","25.82119","0.21900"
"310.19400","25.84970","0.22275"
"310.53600","25.87817","0.22597"
"310.87800","25.90668","0.22901"
"311.22000","25.93521","0.23103"
"311.56200","25.96367","0.23317"
"311.90400","25.99219","0.23458"
"312.24600","26.02071","0.23571"
"312.58800","26.04917","0.23747"
"312.93000","26.07768","0.23881"
"313.27200","26.10620","0.24040"
"313.61400","26.13466","0.24305"
"313.95600","26.16318","0.24539"
"314.29800","26.19164","0.24929"
"314.64000","26.22016","0.25284"
"314.98200","26.24868","0.25714"
"315.32400","26.27720","0.26066"
"315.66600","26.30560","0.26368"
"316.00800","26.33418","0.26815"
"316.35000","26.36270","0.27139"
"316.69200","26.39116","0.27473"
"317.03400","26.41968","0.27779"
"317.37600","26.44820","0.27974"
"317.71800","26.47666","0.28190"
"318.06000","26.50518","0.28364"
"318.40200","26.53364","0.28627"
"318.74400","26.56222","0.28964"
"319.08600","26.59068","0.29359"
"319.42800","26.61914","0.29830"
"319.77000","26.64766","0.30484"
"320.11200","26.67624","0.31031"
"320.45400","26.70464","0.31620"
"320.79600","26.73316","0.32090"
"321.13800","26.76162","0.32684"
"321.48000","26.79014","0.33125"
"321.82200","26.81871","0.33483"
"322.16400","26.84711","0.33817"
"322.50600","26.87569","0.34014"
"322.84800","26.90421","0.34172"
"323.19000","26.93262","0.34259"
"323.53200","26.96125","0.34320"
"323.87400","26.98971","0.34385"
"324.21600","27.01811","0.34447"
"324.55800","27.04675","0.34534"
"324.90000","27.07515","0.34690"
"325.24200","27.10361","0.34888"
"325.58400","27.13219","0.35147"
"325.92600","27.16059","0.35473"
"326.26800","27.18917","0.35791"
"326.61000","27.21775","0.36150"
"326.95200","27.24615","0.36542"
"327.29400","27.27473","0.37045"
"327.63600","27.30319","0.37628"
"327.97800","27.33171","0.38154"
"328.32000","27.36017","0.38581"
"328.66200","27.38863","0.38976"
"329.00400","27.41721","0.39150"
"329.34600","27.44567","0.39368"
"329.68800","27.47413","0.39618"
"330.03000","27.50265","0.39970"
"330.37200","27.53123","0.40356"
"330.71400","27.55963","0.40881"
"331.05600","27.58821","0.41275"
"331.39800","27.61667","0.41616"
"331.74000","27.64513","0.41949"
"332.08200","27.67365","0.42230"
"332.42400","27.70216","0.42502"
"332.76600","27.73069","0.42738"
"333.10800","27.75915","0.42906"
"333.45000","27.78766","0.43116"
"333.79200","27.81618","0.43356"
"334.13400","27.84470","0.43588"
"334.47600","27.87316","0.43877"
"334.81800","27.90168","0.44157"
"335.16000","27.93020","0.44422"
"335.50200","27.95866","0.44759"
"335.84400","27.98718","0.44970"
"336.18600","28.01570","0.45326"
"336.52800","28.04416","0.44477"
"336.87000","28.07274","0.44153"
"337.21200","28.10108","0.43947"
"337.55400","28.12966","0.44271"
"337.89600","28.15824","0.44574"
"338.23800","28.18664","0.44898"
"338.58000","28.21516","0.45261"
"338.92200","28.24368","0.45583"
"339.26400","28.27214","0.46051"
"339.60600","28.30072","0.46395"
"339.94800","28.32918","0.46931"
"340.29000","28.35764","0.47347"
"340.63200","28.38622","0.47729"
"340.97400","28.41462","0.48168"
"341.31600","28.44320","0.48544"
"341.65800","28.47172","0.48801"
"342.00000","28.50012","0.49030"
"342.34200","28.52869","0.49151"
"342.68400","28.55716","0.49340"
"343.02600","28.58562","0.49440"
"343.36800","28.61419","0.49661"
"343.71000","28.64266","0.50113"
"344.05200","28.67118","0.50762"
"344.39400","28.69969","0.51454"
"344.73600","28.72810","0.51969"
"345.07800","28.75673","0.52574"
"345.42000","28.78519","0.52996"
"345.76200","28.81365","0.53423"
"346.10400","28.84223","0.53765"
"346.44600","28.87063","0.54104"
"346.78800","28.89915","0.54380"
"347.13000","28.92767","0.54692"
"347.47200","28.95619","0.54883"
"347.81400","28.98471","0.55123"
"348.15600","29.01317","0.55271"
"348.49800","29.04163","0.55345"
"348.84000","29.07015","0.55424"
"349.18200","29.09873","0.55523"
"349.52400","29.12713","0.55539"
"349.86600","29.15565","0.55571"
"350.20800","29.18423","0.55684"
"350.55000","29.21269","0.55941"
"350.89200","29.24121","0.56278"
"351.23400","29.26967","0.56764"
"351.57600","29.29819","0.57020"
"351.91800","29.32671","0.57569"
"352.26000","29.35517","0.58200"
"352.60200","29.38369","0.58805"
"352.94400","29.41221","0.59334"
"353.28600","29.44061","0.59683"
"353.62800","29.46919","0.60041"
"353.97000","29.49771","0.60398"
"354.31200","29.52617","0.61018"
"354.65400","29.55468","0.61662"
"354.99600","29.58315","0.62199"
"355.33800","29.61166","0.62758"
"355.68000","29.64024","0.63161"
"356.02200","29.66864","0.63537"
"356.36400","29.69716","0.63837"
"356.70600","29.72574","0.64052"
"357.04800","29.75414","0.64185"
"357.39000","29.78266","0.64294"
"357.73200","29.81118","0.64405"
"358.07400","29.83964","0.64510"
"358.41600","29.86822","0.64630"
"358.75800","29.89662","0.64779"
"359.10000","29.92514","0.65035"
"359.44200","29.95372","0.65313"
"359.78400","29.98212","0.65367"
"360.12600","30.01076","0.43492"
"360.46800","30.03922","0.43251"
"360.81000","30.06762","0.43492"
"361.15200","30.09620","0.43380"
"361.49400","30.12466","0.43816"
"361.83600","30.15318","0.43775"
"362.17800","30.18170","0.44280"
"362.52000","30.21016","0.44276"
"362.86200","30.23868","0.44809"
"363.20400","30.26726","0.44953"
"363.54600","30.29565","0.45239"
"363.88800","30.32418","0.45460"
"364.23000","30.35270","0.45871"
"364.57200","30.38116","0.46115"
"364.91400","30.40968","0.46658"
"365.25600","30.43819","0.47130"
"365.59800","30.46671","0.47531"
"365.94000","30.49517","0.47813"
"366.28200","30.52363","0.48197"
"366.62400","30.55221","0.48597"
"366.96600","30.58067","0.48865"
"367.30800","30.60913","0.49098"
"367.65000","30.63771","0.49199"
"367.99200","30.66617","0.49288"
"368.33400","30.69463","0.49421"
"368.67600","30.72315","0.49619"
"369.01800","30.75167","0.50014"
"369.36000","30.78019","0.50566"
"369.70200","30.80865","0.50944"
"370.04400","30.83717","0.51429"
"370.38600","30.86575","0.51808"
"370.72800","30.89421","0.52319"
"371.07000","30.92267","0.52685"
"371.41200","30.95119","0.53087"
"371.75400","30.97965","0.53435"
"372.09600","31.00817","0.53753"
"372.43800","31.03663","0.54078"
"372.78000","31.06521","0.54336"
"373.12200","31.09361","0.54548"
"373.46400","31.12218","0.54770"
"373.80600","31.15065","0.54983"
"374.14800","31.17923","0.55172"
"374.49000","31.20774","0.55308"
"374.83200","31.23615","0.55408"
"375.17400","31.26472","0.55542"
"375.51600","31.29318","0.55651"
"375.85800","31.32164","0.55783"
"376.20000","31.35022","0.55973"
"376.54200","31.37868","0.56202"
"376.88400","31.40714","0.56543"
"377.22600","31.43572","0.56901"
"377.56800","31.46412","0.57251"
"377.91000","31.49270","0.57668"
"378.25200","31.52116","0.58311"
"378.59400","31.54962","0.58683"
"378.93600","31.57820","0.59038"
"379.27800","31.60672","0.59373"
"379.62000","31.63518","0.59639"
"379.96200","31.66370","0.59881"
"380.30400","31.69210","0.60128"
"380.64600","31.72068","0.60465"
"380.98800","31.74920","0.40318"
"381.33000","31.77760","0.40299"
"381.67200","31.80618","0.40786"
"382.01400","31.83470","0.41477"
"382.35600","31.86316","0.41612"
"382.69800","31.89168","0.42045"
"383.04000","31.92019","0.42206"
"383.38200","31.94866","0.42532"
"383.72400","31.97718","0.42808"
"384.06600","32.00563","0.43200"
"384.40800","32.03421","0.43546"
"384.75000","32.06268","0.43833"
"385.09200","32.09113","0.43890"
"385.43400","32.11971","0.43918"
"385.77600","32.14817","0.44072"
"386.11800","32.17663","0.44241"
"386.46000","32.20521","0.44531"
"386.80200","32.23367","0.44837"
"387.14400","32.26213","0.45094"
"387.48600","32.29065","0.45623"
"387.82800","32.31917","0.46131"
"388.17000","32.34769","0.46288"
"388.51200","32.37621","0.46536"
"388.85400","32.40467","0.46700"
"389.19600","32.43319","0.46863"
"389.53800","32.46171","0.46986"
"389.88000","32.49011","0.47297"
"390.22200","32.51869","0.47726"
"390.56400","32.54715","0.48146"
"390.90600","32.57567","0.48641"
"391.24800","32.60419","0.48867"
"391.59000","32.63265","0.48982"
"391.93200","32.66117","0.49071"
"392.27400","32.68975","0.49171"
"392.61600","32.71809","0.49250"
"392.95800","32.74667","0.49475"
"393.30000","32.77518","0.49787"
"393.64200","32.80365","0.50053"
"393.98400","32.83223","0.50530"
"394.32600","32.86068","0.50924"
"394.66800","32.88914","0.51600"
"395.01000","32.91766","0.52163"
"395.35200","32.94613","0.52792"
"395.69400","32.97470","0.53228"
"396.03600","33.00322","0.53553"
"396.37800","33.03162","0.53784"
"396.72000","33.06020","0.54092"
"397.06200","33.08866","0.54426"
"397.40400","33.11712","0.54690"
"397.74600","33.14570","0.54947"
"398.08800","33.17416","0.55060"
"398.43000","33.20262","0.55229"
"398.77200","33.23120","0.55358"
"399.11400","33.25966","0.55526"
"399.45600","33.28818","0.55656"
"399.79800","33.31670","0.55747"
"400.14000","33.34510","0.55861"
"400.48200","33.37368","0.56038"
"400.82400","33.40220","0.56303"
"401.16600","33.43066","0.56691"
"401.50800","33.45918","0.57038"
"401.85000","33.48770","0.57570"
"402.19200","33.51616","0.58110"
"402.53400","33.54474","0.58636"
"402.87600","33.57314","0.59082"
"403.21800","33.60172","0.59372"
"403.56000","33.63018","0.59647"
"403.90200","33.65864","0.59880"
"404.24400","33.68721","0.60093"
"404.58600","33.71568","0.60407"
"404.92800","33.74413","0.60736"
"405.27000","33.77266","0.61212"
"405.61200","33.80117","0.62001"
"405.95400","33.82970","0.62366"
"406.29600","33.85822","0.62681"
"406.63800","33.88662","0.62960"
"406.98000","33.91513","0.63214"
"407.32200","33.94371","0.52936"
"407.66400","33.97211","0.19899"
"408.00600","34.00069","0.19978"
"408.34800","34.02921","0.20644"
"408.69000","34.05761","0.22221"
"409.03200","34.08613","0.23029"
"409.37400","34.11471","0.23315"
"409.71600","34.14311","0.23378"
"410.05800","34.17175","0.23407"
"410.40000","34.20009","0.23584"
"410.74200","34.22867","0.23869"
"411.08400","34.25725","0.24168"
"411.42600","34.28559","0.24579"
"411.76800","34.31417","0.25118"
"412.11000","34.34269","0.25621"
"412.45200","34.37115","0.25886"
"412.79400","34.39973","0.26156"
"413.13600","34.42813","0.26716"
"413.47800","34.45665","0.27446"
"413.82000","34.48517","0.27899"
"414.16200","34.51363","0.28125"
"414.50400","34.54221","0.28313"
"414.84600","34.57067","0.28165"
"415.18800","34.59912","0.28374"
"415.53000","34.62765","0.28577"
"415.87200","34.65623","0.29001"
"416.21400","34.68468","0.29560"
"416.55600","34.71320","0.30424"
"416.89800","34.74166","0.31180"
"417.24000","34.77018","0.31728"
"417.58200","34.79870","0.32148"
"417.92400","34.82710","0.32741"
"418.26600","34.85574","0.33359"
"418.60800","34.88420","0.33710"
"418.95000","34.91267","0.33942"
"419.29200","34.94118","0.34146"
"419.63400","34.96970","0.34250"
"419.97600","34.99816","0.34309"
"420.31800","35.02668","0.34365"
"420.66000","35.05514","0.34417"
"421.00200","35.08366","0.34534"
"421.34400","35.11212","0.34630"
"421.68600","35.14064","0.34743"
"422.02800","35.16916","0.34897"
"422.37000","35.19768","0.35090"
"422.71200","35.22620","0.35295"
"423.05400","35.25466","0.35569"
"423.39600","35.28318","0.35811"
"423.73800","35.31164","0.36035"
"424.08000","35.34016","0.36336"
"424.42200","35.36868","0.36711"
"424.76400","35.39714","0.36985"
"425.10600","35.42572","0.37361"
"425.44800","35.45412","0.37887"
"425.79000","35.48270","0.38167"
"426.13200","35.51122","0.38569"
"426.47400","35.53962","0.38852"
"426.81600","35.56820","0.38990"
"427.15800","35.59665","0.39093"
"427.50000","35.62518","0.39292"
"427.84200","35.65369","0.39446"
"428.18400","35.68215","0.39632"
"428.52600","35.71061","0.39797"
"428.86800","35.73925","0.40057"
"429.21000","35.76759","0.40125"
"429.55200","35.79617","0.40518"
"429.89400","35.82470","0.40797"
"430.23600","35.85315","0.41062"
"430.57800","35.88173","0.41364"
"430.92000","35.91019","0.41660"
"431.26200","35.93865","0.41973"
"431.60400","35.96723","0.42164"
"431.94600","35.99563","0.42295"
"432.28800","36.02415","0.42488"
"432.63000","36.05273","0.42647"
"432.97200","36.08107","0.42807"
"433.31400","36.10971","0.42931"
"433.65600","36.13817","0.43025"
"433.99800","36.16663","0.43193"
"434.34000","36.19521","0.43289"
"434.68200","36.22373","0.43523"
"435.02400","36.25212","0.43728"
"435.36600","36.28071","0.43921"
"435.70800","36.30911","0.44182"
"436.05000","36.33768","0.44432"
"436.39200","36.36621","0.44673"
"436.73400","36.39467","0.45010"
"437.07600","36.42318","0.45375"
"437.41800","36.45171","0.45795"
"437.76000","36.48017","0.46235"
"438.10200","36.50868","0.46710"
"438.44400","36.53714","0.47178"
"438.78600","36.56567","0.47552"
"439.12800","36.59412","0.47916"
"439.47000","36.62264","0.48257"
"439.81200","36.65122","0.26573"
"440.15400","36.67968","0.24182"
"440.49600","36.70814","0.24178"
"440.83800","36.73666","0.25164"
"441.18000","36.76518","0.25937"
"441.52200","36.79364","0.25745"
"441.86400","36.82216","0.25875"
"442.20600","36.85068","0.26226"
"442.54800","36.87920","0.26438"
"442.89000","36.90766","0.26541"
"443.23200","36.93618","0.27072"
"443.57400","36.96464","0.27626"
"443.91600","36.99322","0.28005"
"444.25800","37.02162","0.28213"
"444.60000","37.05020","0.28397"
"444.94200","37.07872","0.28478"
"445.28400","37.10712","0.28583"
"445.62600","37.13570","0.28969"
"445.96800","37.16416","0.29251"
"446.31000","37.19268","0.29795"
"446.65200","37.22120","0.30453"
"446.99400","37.24966","0.31108"
"447.33600","37.27818","0.31639"
"447.67800","37.30670","0.32304"
"448.02000","37.33516","0.32687"
"448.36200","37.36367","0.33024"
"448.70400","37.39220","0.33297"
"449.04600","37.42065","0.33483"
"449.38800","37.44923","0.33741"
"449.73000","37.47763","0.33862"
"450.07200","37.50615","0.34059"
"450.41400","37.53467","0.34171"
"450.75600","37.56313","0.34236"
"451.09800","37.59171","0.34279"
"451.44000","37.62023","0.07216"
"451.78200","37.64863","0.09571"
"452.12400","37.67721","0.12112"
"452.46600","37.70567","0.10686"
"452.80800","37.73413","0.11903"
"453.15000","37.76271","0.12784"
"453.49200","37.79111","0.11947"
"453.83400","37.81969","0.11494"
"454.17600","37.84821","0.12766"
"454.51800","37.87661","0.12538"
"454.86000","37.90519","0.11760"
"455.20200","37.93371","0.12449"
"455.54400","37.96211","0.13686"
"455.88600","37.99075","0.13514"
"456.22800","38.01915","0.13367"
"456.57000","38.04767","0.13682"
"456.91200","38.07619","0.13931"
"457.25400","38.10464","0.13250"
"457.59600","38.13317","0.13355"
"457.93800","38.16163","0.14434"
"458.28000","38.19014","0.16338"
"458.62200","38.21861","0.15648"
"458.96400","38.24719","0.15952"
"459.30600","38.27564","0.17051"
"459.64800","38.30423","0.17806"
"459.99000","38.33269","0.17492"
"460.33200","38.36115","0.17676"
"460.67400","38.38966","0.18399"
"461.01600","38.41819","0.18866"
"461.35800","38.44664","0.18876"
"461.70000","38.47522","0.18924"
"462.04200","38.50362","0.19007"
"462.38400","38.53214","0.19408"
"462.72600","38.56066","0.19733"
"463.06800","38.58912","0.19735"
"463.41000","38.61770","0.19802"
"463.75200","38.64616","0.20180"
"464.09400","38.67462","0.20734"
"464.43600","38.70320","0.21163"
"464.77800","38.73166","0.21298"
"465.12000","38.76012","0.21349"
"465.46200","38.78876","0.21712"
"465.80400","38.81716","0.22112"
"466.14600","38.84568","0.22386"
"466.48800","38.87420","0.22479"
"466.83000","38.90266","0.04673"
"467.17200","38.93118","0.03397"
"467.51400","38.95964","0.05359"
"467.85600","38.98810","0.08094"
"468.19800","39.01667","0.04068"
"468.54000","39.04520","0.04676"
"468.88200","39.07372","0.07151"
"469.22400","39.10223","0.05466"
"469.56600","39.13058","0.04153"
"469.90800","39.15921","0.06380"
"470.25000","39.18767","0.07401"
"470.59200","39.21613","0.05015"
"470.93400","39.24471","0.05071"
"471.27600","39.27317","0.07092"
"471.61800","39.30163","0.07368"
"471.96000","39.33015","0.06469"
"472.30200","39.35861","0.07355"
"472.64400","39.38719","0.08005"
"472.98600","39.41565","0.08307"
"473.32800","39.44411","0.07991"
"473.67000","39.47269","0.08323"
"474.01200","39.50121","0.08453"
"474.35400","39.52967","0.08437"
"474.69600","39.55819","0.08032"
"475.03800","39.58671","0.08201"
"475.38000","39.61517","0.08188"
"475.72200","39.64368","0.08192"
"476.06400","39.67215","0.08183"
"476.40600","39.70066","0.08242"
"476.74800","39.72919","0.08560"
"477.09000","39.75764","0.08730"
"477.43200","39.78617","0.09447"
"477.77400","39.81469","0.08902"
"478.11600","39.84314","0.08986"
"478.45800","39.87167","0.08573"
"478.80000","39.90019","0.08655"
"479.14200","39.92865","0.08726"
"479.48400","39.95723","0.09070"
"479.82600","39.98563","0.10079"
"480.16800","40.01420","0.09799"
"480.51000","40.04266","0.10366"
"480.85200","40.07113","0.09729"
"481.19400","40.09970","0.09683"
"481.53600","40.12822","0.09641"
"481.87800","40.15662","0.10146"
"482.22000","40.18520","0.10980"
"482.56200","40.21366","0.10880"
"482.90400","40.24218","0.11131"
"483.24600","40.27076","0.10653"
"483.58800","40.29916","0.10695"
"483.93000","40.32763","0.11255"
"484.27200","40.35620","0.11254"
"484.61400","40.38460","0.11769"
"484.95600","40.41318","0.11301"
"485.29800","40.44164","0.11425"
"485.64000","40.47010","0.11532"
"485.98200","40.49868","0.11679"
"486.32400","40.52719","0.12135"
"486.66600","40.55560","0.11836"
"487.00800","40.58418","0.11938"
"487.35000","40.61258","0.12035"
"487.69200","40.64122","0.12111"
"488.03400","40.66974","0.12502"
"488.37600","40.69813","0.12208"
"488.71800","40.72672","0.12249"
"489.06000","40.75518","0.12505"
"489.40200","40.78364","0.12509"
"489.74400","40.81222","0.12720"
"490.08600","40.84061","0.12529"
"490.42800","40.86919","0.12575"
"490.77000","40.89766","0.12919"
"491.11200","40.92611","0.12781"
"491.45400","40.95469","0.12886"
"491.79600","40.98322","0.12889"
"492.13800","41.01167","0.12937"
"492.48000","41.04019","0.13150"
"492.82200","41.06865","0.12956"
"493.16400","41.09717","0.12996"
"493.50600","41.12569","0.13274"
"493.84800","41.15421","0.13145"
"494.19000","41.18267","0.13203"
"494.53200","41.21119","0.13309"
"494.87400","41.23965","0.13279"
"495.21600","41.26817","0.13476"
"495.55800","41.29669","0.01197"
"495.90000","41.32509","0.00792"
"496.24200","41.35367","0.00357"
"496.58400","41.38219","0.00336"
"496.92600","41.41065","0.00319"
"497.26800","41.43916","0.00484"
"497.61000","41.46769","0.00467"
"497.95200","41.49615","0.00327"
"498.29400","41.52473","0.00433"
"498.63600","41.55312","0.00466"
"498.97800","41.58171","0.00438"
"499.32000","41.61016","0.00325"
"499.66200","41.63863","0.00402"
"500.00400","41.66721","0.00457"
"500.34600","41.69572","0.00476"
"500.68800","41.72419","0.00340"
"501.03000","41.75270","0.00420"
"501.37200","41.78117","0.00431"
"501.71400","41.80963","0.00501"
"502.05600","41.83821","0.00316"
"502.39800","41.86666","0.00454"
"502.74000","41.89518","0.00370"
"503.08200","41.92371","0.00431"
"503.42400","41.95216","0.00263"
"503.76600","41.98068","0.00464"
"504.10800","42.00914","0.00387"
"504.45000","42.03766","0.00414"
"504.79200","42.06624","0.00357"
"505.13400","42.09464","0.00419"
"505.47600","42.12322","0.00416"
"505.81800","42.15168","0.00392"
"506.02600","42.16896","0.00294"