File: Force_trajectories/170212_2/Specimen_RawData_1.csv
End date,"2/12/2017"
Specimen label,"12BT_91"
Maximum Load,"0.13297",N

Time,Extension,Load
(s),(mm),(N)
"0.00000","0.00000","0.00079"
"0.15600","0.00849","0.00084"
"0.31200","0.02553","0.00110"
"0.46800","0.03928","0.00236"
"0.62400","0.05214","0.00187"
"0.78000","0.06523","0.00315"
"0.93600","0.07826","0.00261"
"1.09200","0.09118","0.00312"
"1.24800","0.10415","0.00413"
"1.40400","0.11719","0.00376"
"1.56000","0.13016","0.00482"
"1.71600","0.14314","0.00465"
"1.87200","0.15617","0.00456"
"2.02800","0.16920","0.00492"
"2.18400","0.18212","0.00559"
"2.34000","0.19515","0.00560"
"2.49600","0.20825","0.00626"
"2.65200","0.22122","0.00644"
"2.80800","0.23414","0.00616"
"2.96400","0.24723","0.00700"
"3.12000","0.26014","0.00771"
"3.27600","0.27312","0.00733"
"3.43200","0.28615","0.00801"
"3.58800","0.29919","0.00806"
"3.74400","0.31216","0.00815"
"3.90000","0.32514","0.00880"
"4.05600","0.33817","0.00919"
"4.21200","0.35120","0.00923"
"4.36800","0.36412","0.00927"
"4.52400","0.37721","0.00970"
"4.68000","0.39019","0.00954"
"4.83600","0.40316","0.00996"
"4.99200","0.41614","0.01019"
"5.14800","0.42917","0.01019"
"5.30400","0.44214","0.01097"
"5.46000","0.45512","0.01069"
"5.61600","0.46809","0.01123"
"5.77200","0.48107","0.01096"
"5.92800","0.49410","0.01152"
"6.08400","0.50713","0.01171"
"6.24000","0.52023","0.01141"
"6.39600","0.53314","0.01219"
"6.55200","0.54612","0.01187"
"6.70800","0.55915","0.01230"
"6.86400","0.57213","0.01226"
"7.02000","0.58516","0.01343"
"7.17600","0.59819","0.01268"
"7.33200","0.61123","0.01286"
"7.48800","0.62414","0.01170"
"7.64400","0.63712","0.01192"
"7.80000","0.65015","0.01233"
"7.95600","0.66319","0.01212"
"8.11200","0.67616","0.01293"
"8.26800","0.68919","0.01187"
"8.42400","0.70217","0.01289"
"8.58000","0.71514","0.01281"
"8.73600","0.72812","0.01239"
"8.89200","0.74115","0.01234"
"9.04800","0.75419","0.01304"
"9.20400","0.76716","0.01328"
"9.36000","0.78013","0.01278"
"9.51600","0.79317","0.01300"
"9.67200","0.80620","0.01303"
"9.82800","0.81918","0.01409"
"9.98400","0.83221","0.01386"
"10.14000","0.84518","0.01380"
"10.29600","0.85810","0.01411"
"10.45200","0.87119","0.01421"
"10.60800","0.88417","0.01373"
"10.76400","0.89714","0.01401"
"10.92000","0.91006","0.01351"
"11.07600","0.92321","0.01418"
"11.23200","0.93612","0.01491"
"11.38800","0.94910","0.01404"
"11.54400","0.96219","0.01452"
"11.70000","0.97523","0.01477"
"11.85600","0.98820","0.01430"
"12.01200","1.00118","0.01505"
"12.16800","1.01421","0.01464"
"12.32400","1.02718","0.01545"
"12.48000","1.04010","0.01570"
"12.63600","1.05313","0.01482"
"12.79200","1.06617","0.01484"
"12.94800","1.07914","0.01504"
"13.10400","1.09212","0.01517"
"13.26000","1.10521","0.01536"
"13.41600","1.11818","0.01547"
"13.57200","1.13116","0.01499"
"13.72800","1.14419","0.01513"
"13.88400","1.15717","0.01567"
"14.04000","1.17014","0.01507"
"14.19600","1.18312","0.01597"
"14.35200","1.19615","0.01588"
"14.50800","1.20912","0.01565"
"14.66400","1.22210","0.01605"
"14.82000","1.23519","0.01500"
"14.97600","1.24817","0.01396"
"15.13200","1.26114","0.01454"
"15.28800","1.27411","0.01378"
"15.44400","1.28715","0.01441"
"15.60000","1.30018","0.01440"
"15.75600","1.31310","0.01419"
"15.91200","1.32613","0.01505"
"16.06800","1.33917","0.01459"
"16.22400","1.35214","0.01444"
"16.38000","1.36511","0.01399"
"16.53600","1.37815","0.01451"
"16.69200","1.39112","0.01520"
"16.84800","1.40410","0.01512"
"17.00400","1.41719","0.01558"
"17.16000","1.43017","0.01557"
"17.31600","1.44314","0.01541"
"17.47200","1.45617","0.01530"
"17.62800","1.46915","0.01540"
"17.78400","1.48212","0.01478"
"17.94000","1.49510","0.01407"
"18.09600","1.50813","0.01405"
"18.25200","1.52117","0.01459"
"18.40800","1.53408","0.01435"
"18.56400","1.54717","0.01391"
"18.72000","1.56015","0.01485"
"18.87600","1.57312","0.01503"
"19.03200","1.58610","0.01497"
"19.18800","1.59913","0.01440"
"19.34400","1.61216","0.01460"
"19.50000","1.62508","0.01545"
"19.65600","1.63817","0.01447"
"19.81200","1.65121","0.01487"
"19.96800","1.66412","0.01519"
"20.12400","1.67716","0.01496"
"20.28000","1.69019","0.01559"
"20.43600","1.70310","0.01515"
"20.59200","1.71614","0.01620"
"20.74800","1.72917","0.01592"
"20.90400","1.74215","0.01496"
"21.06000","1.75512","0.01524"
"21.21600","1.76816","0.01586"
"21.37200","1.78113","0.01540"
"21.52800","1.79410","0.01601"
"21.68400","1.80708","0.01558"
"21.84000","1.82017","0.01568"
"21.99600","1.83315","0.01576"
"22.15200","1.84612","0.01611"
"22.30800","1.85916","0.01632"
"22.46400","1.87219","0.01562"
"22.62000","1.88516","0.01577"
"22.77600","1.89814","0.01634"
"22.93200","1.91111","0.01656"
"23.08800","1.92415","0.01613"
"23.24400","1.93706","0.01614"
"23.40000","1.95016","0.01716"
"23.55600","1.96313","0.01681"
"23.71200","1.97616","0.01619"
"23.86800","1.98914","0.01710"
"24.02400","2.00217","0.01670"
"24.18000","2.01515","0.01656"
"24.33600","2.02812","0.01695"
"24.49200","2.04115","0.01696"
"24.64800","2.05419","0.01707"
"24.80400","2.06716","0.01743"
"24.96000","2.08014","0.01727"
"25.11600","2.09311","0.01737"
"25.27200","2.10609","0.01781"
"25.42800","2.11906","0.01789"
"25.58400","2.13215","0.01767"
"25.74000","2.14519","0.01730"
"25.89600","2.15816","0.01792"
"26.05200","2.17120","0.01838"
"26.20800","2.18417","0.01792"
"26.36400","2.19721","0.01774"
"26.52000","2.21012","0.01836"
"26.67600","2.22321","0.01791"
"26.83200","2.23619","0.01843"
"26.98800","2.24916","0.01818"
"27.14400","2.26214","0.01834"
"27.30000","2.27517","0.01891"
"27.45600","2.28815","0.01850"
"27.61200","2.30112","0.01841"
"27.76800","2.31421","0.01856"
"27.92400","2.32719","0.01845"
"28.08000","2.34010","0.01857"
"28.23600","2.35314","0.01907"
"28.39200","2.36617","0.01902"
"28.54800","2.37914","0.01874"
"28.70400","2.39206","0.01914"
"28.86000","2.40521","0.01876"
"29.01600","2.41813","0.01888"
"29.17200","2.43110","0.01918"
"29.32800","2.44420","0.01955"
"29.48400","2.45723","0.01942"
"29.64000","2.47014","0.01947"
"29.79600","2.48312","0.01971"
"29.95200","2.49615","0.01985"
"30.10800","2.50919","0.01943"
"30.26400","2.52210","0.01998"
"30.42000","2.53514","0.01994"
"30.57600","2.54817","0.01983"
"30.73200","2.56108","0.02032"
"30.88800","2.57412","0.01988"
"31.04400","2.58715","0.02085"
"31.20000","2.60019","0.02066"
"31.35600","2.61316","0.02075"
"31.51200","2.62620","0.02045"
"31.66800","2.63917","0.02055"
"31.82400","2.65208","0.02102"
"31.98000","2.66512","0.02049"
"32.13600","2.67815","0.02084"
"32.29200","2.69119","0.02076"
"32.44800","2.70410","0.02122"
"32.60400","2.71720","0.02099"
"32.76000","2.73017","0.02135"
"32.91600","2.74314","0.02133"
"33.07200","2.75618","0.02135"
"33.22800","2.76915","0.02140"
"33.38400","2.78213","0.02172"
"33.54000","2.79516","0.02179"
"33.69600","2.80819","0.02169"
"33.85200","2.82117","0.02196"
"34.00800","2.83408","0.02214"
"34.16400","2.84718","0.02243"
"34.32000","2.86015","0.02176"
"34.47600","2.87313","0.02269"
"34.63200","2.88616","0.02289"
"34.78800","2.89919","0.02237"
"34.94400","2.91223","0.02235"
"35.10000","2.92514","0.02347"
"35.25600","2.93818","0.02285"
"35.41200","2.95121","0.02297"
"35.56800","2.96413","0.02240"
"35.72400","2.97716","0.02297"
"35.88000","2.99019","0.02359"
"36.03600","3.00323","0.02396"
"36.19200","3.01608","0.02424"
"36.34800","3.02918","0.02400"
"36.50400","3.04221","0.02382"
"36.66000","3.05513","0.02420"
"36.81600","3.06822","0.02446"
"36.97200","3.08119","0.02455"
"37.12800","3.09417","0.02476"
"37.28400","3.10708","0.02505"
"37.44000","3.12018","0.02445"
"37.59600","3.13315","0.02458"
"37.75200","3.14613","0.02496"
"37.90800","3.15910","0.02515"
"38.06400","3.17219","0.02518"
"38.22000","3.18517","0.02506"
"38.37600","3.19814","0.02490"
"38.53200","3.21124","0.02578"
"38.68800","3.22421","0.02564"
"38.84400","3.23712","0.02552"
"39.00000","3.25016","0.02585"
"39.15600","3.26319","0.02611"
"39.31200","3.27611","0.02533"
"39.46800","3.28914","0.02628"
"39.62400","3.30218","0.02651"
"39.78000","3.31521","0.02647"
"39.93600","3.32812","0.02648"
"40.09200","3.34116","0.02671"
"40.24800","3.35419","0.02602"
"40.40400","3.36717","0.02691"
"40.56000","3.38014","0.02694"
"40.71600","3.39318","0.02636"
"40.87200","3.40615","0.02739"
"41.02800","3.41912","0.02643"
"41.18400","3.43216","0.02665"
"41.34000","3.44513","0.02682"
"41.49600","3.45811","0.02581"
"41.65200","3.47114","0.02571"
"41.80800","3.48412","0.02566"
"41.96400","3.49715","0.02643"
"42.12000","3.51018","0.02601"
"42.27600","3.52322","0.02634"
"42.43200","3.53619","0.02661"
"42.58800","3.54911","0.02647"
"42.74400","3.56214","0.02672"
"42.90000","3.57511","0.02638"
"43.05600","3.58809","0.02716"
"43.21200","3.60112","0.02741"
"43.36800","3.61416","0.02702"
"43.52400","3.62719","0.02726"
"43.68000","3.64011","0.02742"
"43.83600","3.65320","0.02783"
"43.99200","3.66617","0.02780"
"44.14800","3.67915","0.02741"
"44.30400","3.69218","0.02721"
"44.46000","3.70516","0.02747"
"44.61600","3.71813","0.02813"
"44.77200","3.73105","0.02813"
"44.92800","3.74414","0.02837"
"45.08400","3.75717","0.02814"
"45.24000","3.77015","0.02822"
"45.39600","3.78312","0.02877"
"45.55200","3.79622","0.02853"
"45.70800","3.80919","0.02838"
"45.86400","3.82211","0.02896"
"46.02000","3.83520","0.02890"
"46.17600","3.84817","0.02910"
"46.33200","3.86115","0.02909"
"46.48800","3.87406","0.02857"
"46.64400","3.88716","0.02906"
"46.80000","3.90013","0.02918"
"46.95600","3.91311","0.02944"
"47.11200","3.92614","0.02956"
"47.26800","3.93917","0.02967"
"47.42400","3.95215","0.03011"
"47.58000","3.96518","0.03020"
"47.73600","3.97816","0.03011"
"47.89200","3.99113","0.03027"
"48.04800","4.00411","0.03053"
"48.20400","4.01714","0.03052"
"48.36000","4.03017","0.03050"
"48.51600","4.04315","0.03056"
"48.67200","4.05612","0.03085"
"48.82800","4.06916","0.03105"
"48.98400","4.08213","0.03108"
"49.14000","4.09510","0.03138"
"49.29600","4.10820","0.03142"
"49.45200","4.12117","0.03175"
"49.60800","4.13415","0.03176"
"49.76400","4.14718","0.03151"
"49.92000","4.16016","0.03175"
"50.07600","4.17313","0.03154"
"50.23200","4.18610","0.03219"
"50.38800","4.19914","0.03203"
"50.54400","4.21211","0.03166"
"50.70000","4.22515","0.03192"
"50.85600","4.23818","0.03228"
"51.01200","4.25116","0.03199"
"51.16800","4.26413","0.03221"
"51.32400","4.27710","0.03284"
"51.48000","4.29020","0.03271"
"51.63600","4.30311","0.03327"
"51.79200","4.31609","0.03266"
"51.94800","4.32912","0.03307"
"52.10400","4.34221","0.03312"
"52.26000","4.35513","0.03327"
"52.41600","4.36816","0.03306"
"52.57200","4.38114","0.03310"
"52.72800","4.39417","0.03360"
"52.88400","4.40709","0.03381"
"53.04000","4.42024","0.03380"
"53.19600","4.43315","0.03385"
"53.35200","4.44613","0.03379"
"53.50800","4.45916","0.03424"
"53.66400","4.47214","0.03452"
"53.82000","4.48511","0.03342"
"53.97600","4.49809","0.03375"
"54.13200","4.51118","0.03379"
"54.28800","4.52415","0.03421"
"54.44400","4.53713","0.03396"
"54.60000","4.55022","0.03451"
"54.75600","4.56326","0.03461"
"54.91200","4.57617","0.03443"
"55.06800","4.58915","0.03505"
"55.22400","4.60218","0.03520"
"55.38000","4.61515","0.03485"
"55.53600","4.62807","0.03578"
"55.69200","4.64116","0.03460"
"55.84800","4.65420","0.03523"
"56.00400","4.66711","0.03503"
"56.16000","4.68015","0.03586"
"56.31600","4.69318","0.03554"
"56.47200","4.70615","0.03573"
"56.62800","4.71907","0.03555"
"56.78400","4.73216","0.03547"
"56.94000","4.74520","0.03593"
"57.09600","4.75817","0.03608"
"57.25200","4.77114","0.03598"
"57.40800","4.78412","0.03629"
"57.56400","4.79709","0.03699"
"57.72000","4.81007","0.03623"
"57.87600","4.82316","0.03699"
"58.03200","4.83620","0.03682"
"58.18800","4.84917","0.03682"
"58.34400","4.86220","0.03681"
"58.50000","4.87518","0.03749"
"58.65600","4.88815","0.03735"
"58.81200","4.90113","0.03719"
"58.96800","4.91416","0.03739"
"59.12400","4.92714","0.03771"
"59.28000","4.94011","0.03751"
"59.43600","4.95314","0.03739"
"59.59200","4.96612","0.03713"
"59.74800","4.97915","0.03746"
"59.90400","4.99213","0.03762"
"60.06000","5.00522","0.03827"
"60.21600","5.01814","0.03805"
"60.37200","5.03111","0.03791"
"60.52800","5.04414","0.03830"
"60.68400","5.05718","0.03811"
"60.84000","5.07009","0.03813"
"60.99600","5.08319","0.03900"
"61.15200","5.09616","0.03850"
"61.30800","5.10914","0.03893"
"61.46400","5.12211","0.03870"
"61.62000","5.13520","0.03901"
"61.77600","5.14818","0.03905"
"61.93200","5.16115","0.03939"
"62.08800","5.17413","0.03958"
"62.24400","5.18716","0.03981"
"62.40000","5.20019","0.03972"
"62.55600","5.21305","0.04001"
"62.71200","5.22620","0.04028"
"62.86800","5.23918","0.04027"
"63.02400","5.25209","0.04045"
"63.18000","5.26513","0.04062"
"63.33600","5.27816","0.04072"
"63.49200","5.29119","0.04098"
"63.64800","5.30417","0.04106"
"63.80400","5.31714","0.04132"
"63.96000","5.33018","0.04100"
"64.11600","5.34309","0.04151"
"64.27200","5.35613","0.03977"
"64.42800","5.36922","0.03967"
"64.58400","5.38213","0.03944"
"64.74000","5.39517","0.04033"
"64.89600","5.40814","0.04038"
"65.05200","5.42118","0.04102"
"65.20800","5.43415","0.04102"
"65.36400","5.44719","0.04077"
"65.52000","5.46022","0.04094"
"65.67600","5.47313","0.04128"
"65.83200","5.48617","0.04152"
"65.98800","5.49914","0.04103"
"66.14400","5.51218","0.04159"
"66.30000","5.52509","0.04123"
"66.45600","5.53818","0.04160"
"66.61200","5.55116","0.04190"
"66.76800","5.56413","0.04168"
"66.92400","5.57711","0.04152"
"67.08000","5.59020","0.04158"
"67.23600","5.60318","0.04152"
"67.39200","5.61615","0.04181"
"67.54800","5.62918","0.04177"
"67.70400","5.64216","0.04191"
"67.86000","5.65513","0.04203"
"68.01600","5.66817","0.04204"
"68.17200","5.68120","0.04273"
"68.32800","5.69418","0.04246"
"68.48400","5.70709","0.04279"
"68.64000","5.72012","0.04263"
"68.79600","5.73322","0.04314"
"68.95200","5.74613","0.04275"
"69.10800","5.75917","0.04257"
"69.26400","5.77214","0.04337"
"69.42000","5.78518","0.04338"
"69.57600","5.79815","0.04351"
"69.73200","5.81118","0.04363"
"69.88800","5.82416","0.04380"
"70.04400","5.83713","0.04408"
"70.20000","5.85017","0.04385"
"70.35600","5.86314","0.04421"
"70.51200","5.87611","0.04406"
"70.66800","5.88915","0.04418"
"70.82400","5.90224","0.04465"
"70.98000","5.91522","0.04467"
"71.13600","5.92813","0.04476"
"71.29200","5.94117","0.04491"
"71.44800","5.95420","0.04520"
"71.60400","5.96711","0.04540"
"71.76000","5.98009","0.04558"
"71.91600","5.99318","0.04570"
"72.07200","6.00610","0.04607"
"72.22800","6.01907","0.04632"
"72.38400","6.03217","0.04647"
"72.54000","6.04520","0.04645"
"72.69600","6.05811","0.04692"
"72.85200","6.07115","0.04689"
"73.00800","6.08418","0.04724"
"73.16400","6.09716","0.04726"
"73.32000","6.11013","0.04781"
"73.47600","6.12317","0.04801"
"73.63200","6.13620","0.04790"
"73.78800","6.14917","0.04800"
"73.94400","6.16215","0.04831"
"74.10000","6.17518","0.04920"
"74.25600","6.18816","0.04906"
"74.41200","6.20113","0.04937"
"74.56800","6.21417","0.04946"
"74.72400","6.22720","0.04976"
"74.88000","6.24005","0.05026"
"75.03600","6.25315","0.05011"
"75.19200","6.26612","0.05011"
"75.34800","6.27916","0.05067"
"75.50400","6.29207","0.05154"
"75.66000","6.30517","0.05129"
"75.81600","6.31814","0.05141"
"75.97200","6.33111","0.05152"
"76.12800","6.34415","0.05177"
"76.28400","6.35718","0.05181"
"76.44000","6.37016","0.04517"
"76.59600","6.38313","0.04021"
"76.75200","6.39616","0.03962"
"76.90800","6.40914","0.04014"
"77.06400","6.42205","0.04019"
"77.22000","6.43515","0.04047"
"77.37600","6.44812","0.04081"
"77.53200","6.46110","0.04076"
"77.68800","6.47413","0.04105"
"77.84400","6.48716","0.04098"
"78.00000","6.50020","0.04126"
"78.15600","6.51311","0.04179"
"78.31200","6.52621","0.04226"
"78.46800","6.53918","0.04228"
"78.62400","6.55216","0.04236"
"78.78000","6.56513","0.04258"
"78.93600","6.57816","0.04283"
"79.09200","6.59114","0.04315"
"79.24800","6.60405","0.04360"
"79.40400","6.61721","0.04354"
"79.56000","6.63018","0.04360"
"79.71600","6.64316","0.04422"
"79.87200","6.65619","0.04432"
"80.02800","6.66916","0.04439"
"80.18400","6.68220","0.04488"
"80.34000","6.69505","0.04492"
"80.49600","6.70821","0.04533"
"80.65200","6.72118","0.04531"
"80.80800","6.73416","0.04538"
"80.96400","6.74713","0.04558"
"81.12000","6.76016","0.04578"
"81.27600","6.77314","0.04623"
"81.43200","6.78611","0.04624"
"81.58800","6.79921","0.04598"
"81.74400","6.81218","0.04653"
"81.90000","6.82516","0.04704"
"82.05600","6.83813","0.04720"
"82.21200","6.85116","0.04695"
"82.36800","6.86414","0.04746"
"82.52400","6.87711","0.04725"
"82.68000","6.89015","0.04747"
"82.83600","6.90312","0.04685"
"82.99200","6.91609","0.04670"
"83.14800","6.92919","0.04687"
"83.30400","6.94222","0.04747"
"83.46000","6.95520","0.04769"
"83.61600","6.96817","0.04774"
"83.77200","6.98115","0.04813"
"83.92800","6.99412","0.04835"
"84.08400","7.00709","0.04786"
"84.24000","7.02013","0.04842"
"84.39600","7.03310","0.04855"
"84.55200","7.04614","0.04886"
"84.70800","7.05911","0.04915"
"84.86400","7.07221","0.04957"
"85.02000","7.08518","0.04931"
"85.17600","7.09809","0.04983"
"85.33200","7.11119","0.05010"
"85.48800","7.12416","0.05001"
"85.64400","7.13714","0.05033"
"85.80000","7.15017","0.05085"
"85.95600","7.16314","0.05069"
"86.11200","7.17612","0.05096"
"86.26800","7.18909","0.05111"
"86.42400","7.20219","0.05159"
"86.58000","7.21516","0.05193"
"86.73600","7.22814","0.05254"
"86.89200","7.24117","0.05264"
"87.04800","7.25420","0.05254"
"87.20400","7.26712","0.05213"
"87.36000","7.28015","0.05311"
"87.51600","7.29319","0.05326"
"87.67200","7.30610","0.05353"
"87.82800","7.31908","0.05397"
"87.98400","7.33217","0.05440"
"88.14000","7.34514","0.05463"
"88.29600","7.35812","0.05487"
"88.45200","7.37115","0.05506"
"88.60800","7.38419","0.05273"
"88.76400","7.39716","0.05304"
"88.92000","7.41008","0.05329"
"89.07600","7.42317","0.05319"
"89.23200","7.43614","0.05292"
"89.38800","7.44918","0.05350"
"89.54400","7.46209","0.05368"
"89.70000","7.47519","0.05396"
"89.85600","7.48810","0.05447"
"90.01200","7.50108","0.05445"
"90.16800","7.51417","0.05514"
"90.32400","7.52720","0.05527"
"90.48000","7.54012","0.05569"
"90.63600","7.55321","0.05593"
"90.79200","7.56619","0.05648"
"90.94800","7.57910","0.05630"
"91.10400","7.59213","0.05645"
"91.26000","7.60517","0.05616"
"91.41600","7.61820","0.05672"
"91.57200","7.63112","0.05713"
"91.72800","7.64415","0.05701"
"91.88400","7.65713","0.05715"
"92.04000","7.67016","0.05788"
"92.19600","7.68313","0.05763"
"92.35200","7.69617","0.05829"
"92.50800","7.70914","0.05889"
"92.66400","7.72212","0.05871"
"92.82000","7.73515","0.05915"
"92.97600","7.74819","0.05904"
"93.13200","7.76122","0.05915"
"93.28800","7.77413","0.05946"
"93.44400","7.78717","0.05995"
"93.60000","7.80014","0.05943"
"93.75600","7.81312","0.05984"
"93.91200","7.82621","0.05980"
"94.06800","7.83919","0.06014"
"94.22400","7.85216","0.05983"
"94.38000","7.86513","0.06016"
"94.53600","7.87817","0.06001"
"94.69200","7.89108","0.06045"
"94.84800","7.90412","0.05999"
"95.00400","7.91715","0.06053"
"95.16000","7.93018","0.06060"
"95.31600","7.94310","0.06038"
"95.47200","7.95619","0.06031"
"95.62800","7.96917","0.05983"
"95.78400","7.98220","0.05654"
"95.94000","7.99512","0.05159"
"96.09600","8.00821","0.05221"
"96.25200","8.02118","0.05203"
"96.40800","8.03410","0.05336"
"96.56400","8.04719","0.05388"
"96.72000","8.06017","0.05470"
"96.87600","8.07314","0.05510"
"97.03200","8.08612","0.05603"
"97.18800","8.09915","0.05688"
"97.34400","8.11218","0.05784"
"97.50000","8.12516","0.05853"
"97.65600","8.13819","0.05941"
"97.81200","8.15123","0.06024"
"97.96800","8.16414","0.06105"
"98.12400","8.17718","0.06171"
"98.28000","8.19021","0.06234"
"98.43600","8.20318","0.06335"
"98.59200","8.21610","0.06379"
"98.74800","8.22913","0.06420"
"98.90400","8.24217","0.06505"
"99.06000","8.25514","0.06432"
"99.21600","8.26818","0.06485"
"99.37200","8.28121","0.06588"
"99.52800","8.29418","0.06303"
"99.68400","8.30716","0.06430"
"99.84000","8.32019","0.06587"
"99.99600","8.33323","0.06661"
"100.15200","8.34620","0.06738"
"100.30800","8.35917","0.06794"
"100.46400","8.37215","0.06819"
"100.62000","8.38518","0.06914"
"100.77600","8.39804","0.04216"
"100.93200","8.41119","0.04295"
"101.08800","8.42417","0.04266"
"101.24400","8.43720","0.04343"
"101.40000","8.45017","0.04343"
"101.55600","8.46315","0.04366"
"101.71200","8.47612","0.04355"
"101.86800","8.48910","0.04431"
"102.02400","8.50219","0.04397"
"102.18000","8.51517","0.04446"
"102.33600","8.52814","0.04484"
"102.49200","8.54111","0.04484"
"102.64800","8.55415","0.04458"
"102.80400","8.56712","0.04543"
"102.96000","8.58016","0.04553"
"103.11600","8.59319","0.04515"
"103.27200","8.60616","0.04583"
"103.42800","8.61914","0.04604"
"103.58400","8.63217","0.04585"
"103.74000","8.64515","0.04648"
"103.89600","8.65812","0.04656"
"104.05200","8.67116","0.04596"
"104.20800","8.68419","0.04700"
"104.36400","8.69717","0.04717"
"104.52000","8.71014","0.04690"
"104.67600","8.72317","0.04730"
"104.83200","8.73621","0.04706"
"104.98800","8.74912","0.04611"
"105.14400","8.76216","0.04638"
"105.30000","8.77513","0.04627"
"105.45600","8.78817","0.04561"
"105.61200","8.80114","0.04659"
"105.76800","8.81423","0.04736"
"105.92400","8.82721","0.04673"
"106.08000","8.84012","0.04777"
"106.23600","8.85316","0.04812"
"106.39200","8.86619","0.04782"
"106.54800","8.87916","0.04819"
"106.70400","8.89220","0.04900"
"106.86000","8.90517","0.04874"
"107.01600","8.91821","0.04898"
"107.17200","8.93112","0.04973"
"107.32800","8.94416","0.04883"
"107.48400","8.95713","0.04861"
"107.64000","8.97010","0.04930"
"107.79600","8.98314","0.04965"
"107.95200","8.99617","0.04930"
"108.10800","9.00915","0.04973"
"108.26400","9.02212","0.04891"
"108.42000","9.03510","0.04917"
"108.57600","9.04813","0.04950"
"108.73200","9.06110","0.04954"
"108.88800","9.07414","0.04986"
"109.04400","9.08711","0.05041"
"109.20000","9.10015","0.05074"
"109.35600","9.11312","0.05024"
"109.51200","9.12621","0.05124"
"109.66800","9.13919","0.05072"
"109.82400","9.15216","0.05066"
"109.98000","9.16514","0.05100"
"110.13600","9.17817","0.05048"
"110.29200","9.19121","0.05055"
"110.44800","9.20412","0.05030"
"110.60400","9.21721","0.04988"
"110.76000","9.23019","0.04968"
"110.91600","9.24316","0.05058"
"111.07200","9.25614","0.05030"
"111.22800","9.26911","0.05024"
"111.38400","9.28209","0.05110"
"111.54000","9.29506","0.05101"
"111.69600","9.30815","0.05133"
"111.85200","9.32113","0.05181"
"112.00800","9.33410","0.05188"
"112.16400","9.34714","0.05186"
"112.32000","9.36017","0.05203"
"112.47600","9.37315","0.05253"
"112.63200","9.38612","0.05143"
"112.78800","9.39915","0.05288"
"112.94400","9.41219","0.05285"
"113.10000","9.42510","0.05289"
"113.25600","9.43820","0.05428"
"113.41200","9.45117","0.05386"
"113.56800","9.46414","0.05413"
"113.72400","9.47712","0.05479"
"113.88000","9.49015","0.05517"
"114.03600","9.50319","0.05490"
"114.19200","9.51616","0.05612"
"114.34800","9.52914","0.05599"
"114.50400","9.54217","0.05635"
"114.66000","9.55508","0.05712"
"114.81600","9.56812","0.05714"
"114.97200","9.58115","0.05723"
"115.12800","9.59419","0.05827"
"115.28400","9.60710","0.05837"
"115.44000","9.62020","0.05701"
"115.59600","9.63317","0.05745"
"115.75200","9.64608","0.05733"
"115.90800","9.65912","0.05729"
"116.06400","9.67221","0.05757"
"116.22000","9.68519","0.05679"
"116.37600","9.69810","0.05749"
"116.53200","9.71113","0.05786"
"116.68800","9.72417","0.05871"
"116.84400","9.73714","0.05808"
"117.00000","9.75018","0.05849"
"117.15600","9.76321","0.05780"
"117.31200","9.77613","0.05731"
"117.46800","9.78916","0.05596"
"117.62400","9.80219","0.05464"
"117.78000","9.81517","0.05371"
"117.93600","9.82808","0.05404"
"118.09200","9.84118","0.05441"
"118.24800","9.85415","0.05427"
"118.40400","9.86713","0.05544"
"118.56000","9.88010","0.05578"
"118.71600","9.89319","0.05573"
"118.87200","9.90617","0.05625"
"119.02800","9.91914","0.05602"
"119.18400","9.93218","0.05562"
"119.34000","9.94521","0.05547"
"119.49600","9.95813","0.05582"
"119.65200","9.97110","0.05542"
"119.80800","9.98413","0.05593"
"119.96400","9.99711","0.05546"
"120.12000","10.01008","0.05540"
"120.27600","10.02318","0.05591"
"120.43200","10.03615","0.05528"
"120.58800","10.04912","0.05564"
"120.74400","10.06216","0.05613"
"120.90000","10.07513","0.05572"
"121.05600","10.08817","0.05580"
"121.21200","10.10108","0.05635"
"121.36800","10.11418","0.05701"
"121.52400","10.12721","0.05729"
"121.68000","10.14012","0.05752"
"121.83600","10.15316","0.05813"
"121.99200","10.16613","0.05793"
"122.14800","10.17911","0.05876"
"122.30400","10.19208","0.05888"
"122.46000","10.20518","0.05940"
"122.61600","10.21821","0.05961"
"122.77200","10.23112","0.05966"
"122.92800","10.24416","0.06010"
"123.08400","10.25719","0.06017"
"123.24000","10.27017","0.06095"
"123.39600","10.28308","0.06161"
"123.55200","10.29624","0.06264"
"123.70800","10.30915","0.06273"
"123.86400","10.32212","0.06258"
"124.02000","10.33516","0.06344"
"124.17600","10.34819","0.06332"
"124.33200","10.36111","0.06346"
"124.48800","10.37414","0.06484"
"124.64400","10.38718","0.06569"
"124.80000","10.40015","0.06653"
"124.95600","10.41312","0.06682"
"125.11200","10.42616","0.06782"
"125.26800","10.43919","0.06608"
"125.42400","10.45217","0.06611"
"125.58000","10.46514","0.06622"
"125.73600","10.47812","0.06662"
"125.89200","10.49115","0.06689"
"126.04800","10.50412","0.06706"
"126.20400","10.51722","0.05132"
"126.36000","10.53019","0.04977"
"126.51600","10.54317","0.05000"
"126.67200","10.55614","0.05000"
"126.82800","10.56918","0.05128"
"126.98400","10.58215","0.05185"
"127.14000","10.59506","0.05144"
"127.29600","10.60816","0.05247"
"127.45200","10.62113","0.05290"
"127.60800","10.63417","0.05254"
"127.76400","10.64714","0.05404"
"127.92000","10.66018","0.05471"
"128.07600","10.67321","0.05407"
"128.23200","10.68612","0.05581"
"128.38800","10.69916","0.05660"
"128.54400","10.71213","0.05703"
"128.70000","10.72511","0.05766"
"128.85600","10.73820","0.05878"
"129.01200","10.75117","0.05843"
"129.16800","10.76409","0.06045"
"129.32400","10.77712","0.06087"
"129.48000","10.79016","0.06094"
"129.63600","10.80319","0.06296"
"129.79200","10.81611","0.06347"
"129.94800","10.82920","0.06289"
"130.10400","10.84217","0.06429"
"130.26000","10.85515","0.06527"
"130.41600","10.86812","0.06490"
"130.57200","10.88116","0.06569"
"130.72800","10.89413","0.06405"
"130.88400","10.90711","0.06312"
"131.04000","10.92020","0.06443"
"131.19600","10.93317","0.06526"
"131.35200","10.94615","0.06552"
"131.50800","10.95918","0.06707"
"131.66400","10.97222","0.06710"
"131.82000","10.98519","0.06750"
"131.97600","10.99811","0.06881"
"132.13200","11.01120","0.06900"
"132.28800","11.02417","0.06961"
"132.44400","11.03715","0.07102"
"132.60000","11.05012","0.06987"
"132.75600","11.06322","0.07144"
"132.91200","11.07613","0.07111"
"133.06800","11.08911","0.06750"
"133.22400","11.10220","0.06761"
"133.38000","11.11523","0.06607"
"133.53600","11.12815","0.05964"
"133.69200","11.14118","0.06160"
"133.84800","11.15422","0.06285"
"134.00400","11.16713","0.06317"
"134.16000","11.18010","0.06411"
"134.31600","11.19314","0.06526"
"134.47200","11.20617","0.06553"
"134.62800","11.21915","0.06658"
"134.78400","11.23218","0.06730"
"134.94000","11.24522","0.06801"
"135.09600","11.25813","0.04362"
"135.25200","11.27116","0.04155"
"135.40800","11.28420","0.04260"
"135.56400","11.29717","0.04310"
"135.72000","11.31009","0.04372"
"135.87600","11.32318","0.04416"
"136.03200","11.33615","0.04379"
"136.18800","11.34913","0.04478"
"136.34400","11.36216","0.04542"
"136.50000","11.37520","0.04499"
"136.65600","11.38817","0.04510"
"136.81200","11.40115","0.04571"
"136.96800","11.41418","0.04049"
"137.12400","11.42716","0.04142"
"137.28000","11.44013","0.04248"
"137.43600","11.45310","0.04225"
"137.59200","11.46620","0.04248"
"137.74800","11.47911","0.04344"
"137.90400","11.49215","0.04345"
"138.06000","11.50518","0.04388"
"138.21600","11.51822","0.04406"
"138.37200","11.53113","0.04339"
"138.52800","11.54422","0.04230"
"138.68400","11.55720","0.04280"
"138.84000","11.57017","0.04315"
"138.99600","11.58315","0.04309"
"139.15200","11.59618","0.04392"
"139.30800","11.60915","0.04448"
"139.46400","11.62207","0.04399"
"139.62000","11.63516","0.04456"
"139.77600","11.64814","0.04357"
"139.93200","11.66111","0.04349"
"140.08800","11.67409","0.04234"
"140.24400","11.68718","0.04261"
"140.40000","11.70015","0.04227"
"140.55600","11.71313","0.04287"
"140.71200","11.72616","0.04362"
"140.86800","11.73920","0.04329"
"141.02400","11.75217","0.04373"
"141.18000","11.76515","0.04407"
"141.33600","11.77812","0.04415"
"141.49200","11.79115","0.04398"
"141.64800","11.80407","0.04454"
"141.80400","11.81716","0.04455"
"141.96000","11.83020","0.04453"
"142.11600","11.84311","0.04528"
"142.27200","11.85614","0.04532"
"142.42800","11.86918","0.04543"
"142.58400","11.88221","0.04599"
"142.74000","11.89513","0.04628"
"142.89600","11.90816","0.04585"
"143.05200","11.92120","0.04692"
"143.20800","11.93417","0.04685"
"143.36400","11.94714","0.04717"
"143.52000","11.96012","0.04802"
"143.67600","11.97315","0.04804"
"143.83200","11.98607","0.04797"
"143.98800","11.99922","0.04924"
"144.14400","12.01219","0.04885"
"144.30000","12.02517","0.04972"
"144.45600","12.03814","0.05078"
"144.61200","12.05118","0.05115"
"144.76800","12.06415","0.05124"
"144.92400","12.07713","0.05259"
"145.08000","12.09016","0.05318"
"145.23600","12.10314","0.05283"
"145.39200","12.11611","0.05450"
"145.54800","12.12914","0.05473"
"145.70400","12.14212","0.05525"
"145.86000","12.15509","0.05627"
"146.01600","12.16813","0.05743"
"146.17200","12.18116","0.05762"
"146.32800","12.19413","0.05901"
"146.48400","12.20711","0.06023"
"146.64000","12.22014","0.06059"
"146.79600","12.23318","0.06183"
"146.95200","12.24603","0.06282"
"147.10800","12.25913","0.06364"
"147.26400","12.27216","0.06479"
"147.42000","12.28513","0.06538"
"147.57600","12.29811","0.06636"
"147.73200","12.31126","0.06720"
"147.88800","12.32418","0.06798"
"148.04400","12.33709","0.06860"
"148.20000","12.35013","0.06983"
"148.35600","12.36316","0.07120"
"148.51200","12.37613","0.07166"
"148.66800","12.38911","0.07191"
"148.82400","12.40220","0.07346"
"148.98000","12.41518","0.07433"
"149.13600","12.42815","0.07496"
"149.29200","12.44118","0.07579"
"149.44800","12.45416","0.07602"
"149.60400","12.46713","0.07698"
"149.76000","12.48011","0.07728"
"149.91600","12.49314","0.07861"
"150.07200","12.50618","0.07847"
"150.22800","12.51915","0.07884"
"150.38400","12.53213","0.08043"
"150.54000","12.54516","0.07723"
"150.69600","12.55813","0.07836"
"150.85200","12.57111","0.07975"
"151.00800","12.58420","0.08109"
"151.16400","12.59718","0.08163"
"151.32000","12.61015","0.02608"
"151.47600","12.62318","0.03017"
"151.63200","12.63616","0.03269"
"151.78800","12.64913","0.03439"
"151.94400","12.66217","0.03538"
"152.10000","12.67514","0.03651"
"152.25600","12.68818","0.03617"
"152.41200","12.70103","0.03638"
"152.56800","12.71418","0.03841"
"152.72400","12.72716","0.03711"
"152.88000","12.74013","0.03776"
"153.03600","12.75311","0.03905"
"153.19200","12.76620","0.03455"
"153.34800","12.77912","0.03434"
"153.50400","12.79209","0.03611"
"153.66000","12.80518","0.03599"
"153.81600","12.81822","0.03579"
"153.97200","12.83113","0.03666"
"154.12800","12.84411","0.03699"
"154.28400","12.85714","0.03608"
"154.44000","12.87012","0.03668"
"154.59600","12.88315","0.03683"
"154.75200","12.89618","0.03577"
"154.90800","12.90916","0.03703"
"155.06400","12.92213","0.03770"
"155.22000","12.93517","0.03703"
"155.37600","12.94820","0.03703"
"155.53200","12.96111","0.03751"
"155.68800","12.97415","0.03737"
"155.84400","12.98718","0.03744"
"156.00000","13.00016","0.03860"
"156.15600","13.01307","0.03841"
"156.31200","13.02617","0.03815"
"156.46800","13.03914","0.03846"
"156.62400","13.05217","0.03745"
"156.78000","13.06515","0.03661"
"156.93600","13.07818","0.03769"
"157.09200","13.09116","0.03832"
"157.24800","13.10413","0.03723"
"157.40400","13.11723","0.03724"
"157.56000","13.13020","0.03783"
"157.71600","13.14311","0.03692"
"157.87200","13.15609","0.03727"
"158.02800","13.16918","0.03802"
"158.18400","13.18216","0.03786"
"158.34000","13.19513","0.03773"
"158.49600","13.20823","0.03821"
"158.65200","13.22120","0.03826"
"158.80800","13.23411","0.03851"
"158.96400","13.24709","0.03886"
"159.12000","13.26018","0.03843"
"159.27600","13.27316","0.03876"
"159.43200","13.28607","0.03926"
"159.58800","13.29917","0.03901"
"159.74400","13.31220","0.03894"
"159.90000","13.32511","0.03939"
"160.05600","13.33815","0.03972"
"160.21200","13.35118","0.03997"
"160.36800","13.36422","0.03980"
"160.52400","13.37719","0.04034"
"160.68000","13.39016","0.04020"
"160.83600","13.40314","0.03989"
"160.99200","13.41611","0.04030"
"161.14800","13.42921","0.04041"
"161.30400","13.44218","0.04063"
"161.46000","13.45516","0.04110"
"161.61600","13.46813","0.04120"
"161.77200","13.48116","0.04112"
"161.92800","13.49420","0.04109"
"162.08400","13.50717","0.04106"
"162.24000","13.52015","0.04069"
"162.39600","13.53318","0.04067"
"162.55200","13.54616","0.04096"
"162.70800","13.55913","0.04101"
"162.86400","13.57216","0.04084"
"163.02000","13.58514","0.04170"
"163.17600","13.59805","0.04113"
"163.33200","13.61115","0.04098"
"163.48800","13.62418","0.04118"
"163.64400","13.63716","0.04138"
"163.80000","13.65019","0.04150"
"163.95600","13.66322","0.04124"
"164.11200","13.67620","0.04141"
"164.26800","13.68911","0.04126"
"164.42400","13.70221","0.04155"
"164.58000","13.71518","0.04179"
"164.73600","13.72816","0.04149"
"164.89200","13.74119","0.04160"
"165.04800","13.75416","0.04202"
"165.20400","13.76714","0.04190"
"165.36000","13.78011","0.04213"
"165.51600","13.79321","0.04247"
"165.67200","13.80618","0.04265"
"165.82800","13.81909","0.04257"
"165.98400","13.83219","0.04289"
"166.14000","13.84516","0.04224"
"166.29600","13.85820","0.04259"
"166.45200","13.87111","0.04280"
"166.60800","13.88421","0.04294"
"166.76400","13.89718","0.04323"
"166.92000","13.91015","0.04312"
"167.07600","13.92313","0.04311"
"167.23200","13.93622","0.04331"
"167.38800","13.94914","0.04301"
"167.54400","13.96217","0.04313"
"167.70000","13.97520","0.04360"
"167.85600","13.98818","0.04338"
"168.01200","14.00115","0.04363"
"168.16800","14.01413","0.04402"
"168.32400","14.02716","0.04370"
"168.48000","14.04014","0.04411"
"168.63600","14.05311","0.04416"
"168.79200","14.06615","0.04431"
"168.94800","14.07918","0.04459"
"169.10400","14.09209","0.04458"
"169.26000","14.10519","0.04409"
"169.41600","14.11822","0.04476"
"169.57200","14.13120","0.04453"
"169.72800","14.14417","0.04452"
"169.88400","14.15715","0.04402"
"170.04000","14.17012","0.04382"
"170.19600","14.18309","0.04414"
"170.35200","14.19619","0.04441"
"170.50800","14.20916","0.04468"
"170.66400","14.22214","0.04439"
"170.82000","14.23517","0.04462"
"170.97600","14.24821","0.04498"
"171.13200","14.26118","0.04546"
"171.28800","14.27415","0.04508"
"171.44400","14.28719","0.04528"
"171.60000","14.30016","0.04565"
"171.75600","14.31308","0.04580"
"171.91200","14.32617","0.04589"
"172.06800","14.33915","0.04536"
"172.22400","14.35212","0.04511"
"172.38000","14.36509","0.04521"
"172.53600","14.37813","0.04519"
"172.69200","14.39116","0.04552"
"172.84800","14.40408","0.04600"
"173.00400","14.41717","0.04601"
"173.16000","14.43020","0.04638"
"173.31600","14.44312","0.04646"
"173.47200","14.45615","0.04640"
"173.62800","14.46913","0.04645"
"173.78400","14.48216","0.04643"
"173.94000","14.49508","0.04705"
"174.09600","14.50817","0.04720"
"174.25200","14.52120","0.04654"
"174.40800","14.53412","0.04636"
"174.56400","14.54715","0.04665"
"174.72000","14.56019","0.04654"
"174.87600","14.57322","0.04638"
"175.03200","14.58608","0.04606"
"175.18800","14.59923","0.04685"
"175.34400","14.61214","0.04714"
"175.50000","14.62512","0.04739"
"175.65600","14.63809","0.04802"
"175.81200","14.65119","0.04781"
"175.96800","14.66410","0.04871"
"176.12400","14.67714","0.04889"
"176.28000","14.69017","0.04924"
"176.43600","14.70320","0.04951"
"176.59200","14.71612","0.04999"
"176.74800","14.72915","0.05023"
"176.90400","14.74219","0.05029"
"177.06000","14.75516","0.05061"
"177.21600","14.76814","0.05069"
"177.37200","14.78117","0.05102"
"177.52800","14.79414","0.05113"
"177.68400","14.80712","0.05180"
"177.84000","14.82015","0.05192"
"177.99600","14.83319","0.05255"
"178.15200","14.84610","0.05247"
"178.30800","14.85913","0.05262"
"178.46400","14.87217","0.05274"
"178.62000","14.88514","0.05287"
"178.77600","14.89812","0.05319"
"178.93200","14.91115","0.05339"
"179.08800","14.92413","0.05286"
"179.24400","14.93710","0.05327"
"179.40000","14.95014","0.05323"
"179.55600","14.96317","0.05378"
"179.71200","14.97614","0.05451"
"179.86800","14.98918","0.05401"
"180.02400","15.00221","0.05101"
"180.18000","15.01518","0.05129"
"180.33600","15.02810","0.05197"
"180.49200","15.04113","0.05183"
"180.64800","15.05417","0.05233"
"180.80400","15.06708","0.05126"
"180.96000","15.08012","0.05125"
"181.11600","15.09315","0.05195"
"181.27200","15.10618","0.05192"
"181.42800","15.11910","0.05223"
"181.58400","15.13219","0.05252"
"181.74000","15.14517","0.05294"
"181.89600","15.15814","0.05321"
"182.05200","15.17111","0.05302"
"182.20800","15.18421","0.05341"
"182.36400","15.19718","0.05352"
"182.52000","15.21010","0.05320"
"182.67600","15.22313","0.05327"
"182.83200","15.23617","0.05246"
"182.98800","15.24908","0.05183"
"183.14400","15.26212","0.05201"
"183.30000","15.27515","0.05260"
"183.45600","15.28818","0.05315"
"183.61200","15.30116","0.05353"
"183.76800","15.31419","0.05418"
"183.92400","15.32723","0.05481"
"184.08000","15.34014","0.05519"
"184.23600","15.35312","0.05511"
"184.39200","15.36615","0.05572"
"184.54800","15.37912","0.05592"
"184.70400","15.39210","0.05684"
"184.86000","15.40513","0.05698"
"185.01600","15.41817","0.05798"
"185.17200","15.43114","0.05840"
"185.32800","15.44417","0.05897"
"185.48400","15.45715","0.05900"
"185.64000","15.47018","0.05927"
"185.79600","15.48310","0.06008"
"185.95200","15.49619","0.06125"
"186.10800","15.50923","0.06127"
"186.26400","15.52214","0.06186"
"186.42000","15.53511","0.06244"
"186.57600","15.54815","0.06296"
"186.73200","15.56112","0.06396"
"186.88800","15.57416","0.06425"
"187.04400","15.58725","0.06367"
"187.20000","15.60023","0.06415"
"187.35600","15.61314","0.06461"
"187.51200","15.62617","0.06497"
"187.66800","15.63915","0.06550"
"187.82400","15.65212","0.06545"
"187.98000","15.66510","0.06658"
"188.13600","15.67813","0.06656"
"188.29200","15.69110","0.06740"
"188.44800","15.70414","0.06806"
"188.60400","15.71717","0.06850"
"188.76000","15.73015","0.06971"
"188.91600","15.74318","0.07055"
"189.07200","15.75616","0.07096"
"189.22800","15.76919","0.07133"
"189.38400","15.78210","0.07187"
"189.54000","15.79514","0.07236"
"189.69600","15.80817","0.07274"
"189.85200","15.82121","0.07373"
"190.00800","15.83412","0.07454"
"190.16400","15.84716","0.07527"
"190.32000","15.86013","0.07552"
"190.47600","15.87316","0.07706"
"190.63200","15.88614","0.07792"
"190.78800","15.89923","0.07827"
"190.94400","15.91215","0.07847"
"191.10000","15.92512","0.07917"
"191.25600","15.93816","0.07990"
"191.41200","15.95113","0.08070"
"191.56800","15.96410","0.08091"
"191.72400","15.97708","0.08223"
"191.88000","15.99017","0.08276"
"192.03600","16.00315","0.08249"
"192.19200","16.01612","0.08379"
"192.34800","16.02916","0.08424"
"192.50400","16.04219","0.08475"
"192.66000","16.05516","0.08563"
"192.81600","16.06814","0.08399"
"192.97200","16.08117","0.08471"
"193.12800","16.09415","0.08480"
"193.28400","16.10718","0.08583"
"193.44000","16.12016","0.08619"
"193.59600","16.13319","0.08605"
"193.75200","16.14610","0.08684"
"193.90800","16.15914","0.08721"
"194.06400","16.17217","0.06357"
"194.22000","16.18521","0.06314"
"194.37600","16.19812","0.06626"
"194.53200","16.21115","0.06661"
"194.68800","16.22419","0.06606"
"194.84400","16.23710","0.06882"
"195.00000","16.25014","0.06911"
"195.15600","16.26311","0.06790"
"195.31200","16.27615","0.07076"
"195.46800","16.28906","0.07060"
"195.62400","16.30221","0.07034"
"195.78000","16.31513","0.07146"
"195.93600","16.32816","0.07245"
"196.09200","16.34114","0.07108"
"196.24800","16.35417","0.07287"
"196.40400","16.36715","0.07352"
"196.56000","16.38012","0.07205"
"196.71600","16.39315","0.07349"
"196.87200","16.40619","0.07435"
"197.02800","16.41916","0.07337"
"197.18400","16.43220","0.07447"
"197.34000","16.44517","0.07530"
"197.49600","16.45815","0.07499"
"197.65200","16.47112","0.07664"
"197.80800","16.48421","0.07684"
"197.96400","16.49719","0.07678"
"198.12000","16.51016","0.07796"
"198.27600","16.52320","0.07838"
"198.43200","16.53617","0.07888"
"198.58800","16.54914","0.07949"
"198.74400","16.56218","0.07933"
"198.90000","16.57515","0.07997"
"199.05600","16.58813","0.07988"
"199.21200","16.60110","0.08010"
"199.36800","16.61419","0.08044"
"199.52400","16.62717","0.08131"
"199.68000","16.64014","0.08157"
"199.83600","16.65318","0.08169"
"199.99200","16.66621","0.08277"
"200.14800","16.67919","0.08327"
"200.30400","16.69210","0.08371"
"200.46000","16.70514","0.08431"
"200.61600","16.71817","0.08465"
"200.77200","16.73108","0.08486"
"200.92800","16.74412","0.08593"
"201.08400","16.75715","0.08603"
"201.24000","16.77013","0.08732"
"201.39600","16.78316","0.08706"
"201.55200","16.79620","0.08756"
"201.70800","16.80917","0.08798"
"201.86400","16.82214","0.08805"
"202.02000","16.83512","0.08897"
"202.17600","16.84815","0.08927"
"202.33200","16.86113","0.08960"
"202.48800","16.87410","0.09024"
"202.64400","16.88714","0.09037"
"202.80000","16.90017","0.09027"
"202.95600","16.91314","0.09005"
"203.11200","16.92618","0.09039"
"203.26800","16.93921","0.09079"
"203.42400","16.95219","0.09093"
"203.58000","16.96516","0.09138"
"203.73600","16.97814","0.09182"
"203.89200","16.99117","0.09145"
"204.04800","17.00408","0.09220"
"204.20400","17.01718","0.09192"
"204.36000","17.03015","0.09267"
"204.51600","17.04313","0.09266"
"204.67200","17.05616","0.09270"
"204.82800","17.06919","0.09294"
"204.98400","17.08217","0.09249"
"205.14000","17.09508","0.09242"
"205.29600","17.10812","0.09268"
"205.45200","17.12115","0.09309"
"205.60800","17.13413","0.09357"
"205.76400","17.14710","0.09355"
"205.92000","17.16014","0.09379"
"206.07600","17.17311","0.09391"
"206.23200","17.18608","0.09430"
"206.38800","17.19918","0.09491"
"206.54400","17.21215","0.09515"
"206.70000","17.22513","0.09537"
"206.85600","17.23810","0.09596"
"207.01200","17.25113","0.09608"
"207.16800","17.26417","0.09628"
"207.32400","17.27708","0.09673"
"207.48000","17.29018","0.09674"
"207.63600","17.30315","0.09739"
"207.79200","17.31613","0.09765"
"207.94800","17.32916","0.09856"
"208.10400","17.34213","0.09895"
"208.26000","17.35517","0.09987"
"208.41600","17.36814","0.10048"
"208.57200","17.38118","0.10092"
"208.72800","17.39415","0.10166"
"208.88400","17.40713","0.10171"
"209.04000","17.42016","0.10188"
"209.19600","17.43313","0.10327"
"209.35200","17.44617","0.10432"
"209.50800","17.45908","0.10461"
"209.66400","17.47218","0.10538"
"209.82000","17.48515","0.10598"
"209.97600","17.49813","0.10678"
"210.13200","17.51116","0.10682"
"210.28800","17.52419","0.10805"
"210.44400","17.53711","0.10855"
"210.60000","17.55014","0.10926"
"210.75600","17.56312","0.10959"
"210.91200","17.57615","0.11092"
"211.06800","17.58912","0.11171"
"211.22400","17.60216","0.11258"
"211.38000","17.61519","0.11378"
"211.53600","17.62817","0.11366"
"211.69200","17.64114","0.11392"
"211.84800","17.65417","0.11472"
"212.00400","17.66715","0.11573"
"212.16000","17.68012","0.11654"
"212.31600","17.69322","0.11699"
"212.47200","17.70619","0.11613"
"212.62800","17.71911","0.11664"
"212.78400","17.73214","0.10794"
"212.94000","17.74517","0.10959"
"213.09600","17.75815","0.10864"
"213.25200","17.77112","0.11019"
"213.40800","17.78416","0.11088"
"213.56400","17.79713","0.10999"
"213.72000","17.81011","0.11136"
"213.87600","17.82314","0.11153"
"214.03200","17.83617","0.11195"
"214.18800","17.84915","0.11315"
"214.34400","17.86212","0.11286"
"214.50000","17.87522","0.11319"
"214.65600","17.88819","0.11365"
"214.81200","17.90111","0.11450"
"214.96800","17.91414","0.11439"
"215.12400","17.92711","0.11579"
"215.28000","17.94015","0.11593"
"215.43600","17.95312","0.11585"
"215.59200","17.96622","0.11734"
"215.74800","17.97919","0.11755"
"215.90400","17.99216","0.11771"
"216.06000","18.00520","0.11829"
"216.21600","18.01823","0.11793"
"216.37200","18.03109","0.11888"
"216.52800","18.04418","0.11969"
"216.68400","18.05716","0.11952"
"216.84000","18.07013","0.12078"
"216.99600","18.08305","0.12126"
"217.15200","18.09620","0.12147"
"217.30800","18.10917","0.12262"
"217.46400","18.12215","0.12291"
"217.62000","18.13518","0.12318"
"217.77600","18.14816","0.12366"
"217.93200","18.16119","0.12373"
"218.08800","18.17410","0.12440"
"218.24400","18.18720","0.12492"
"218.40000","18.20017","0.12531"
"218.55600","18.21315","0.12571"
"218.71200","18.22612","0.12594"
"218.86800","18.23915","0.12632"
"219.02400","18.25213","0.12627"
"219.18000","18.26516","0.12588"
"219.33600","18.27820","0.12573"
"219.49200","18.29123","0.12608"
"219.64800","18.30409","0.12652"
"219.80400","18.31718","0.12699"
"219.96000","18.33015","0.12676"
"220.11600","18.34313","0.12741"
"220.27200","18.35610","0.12748"
"220.42800","18.36914","0.12792"
"220.58400","18.38217","0.12819"
"220.74000","18.39515","0.12874"
"220.89600","18.40818","0.12922"
"221.05200","18.42121","0.12906"
"221.20800","18.43413","0.12919"
"221.36400","18.44710","0.12916"
"221.52000","18.46014","0.12975"
"221.67600","18.47317","0.12943"
"221.83200","18.48615","0.12999"
"221.98800","18.49918","0.13023"
"222.14400","18.51215","0.12861"
"222.30000","18.52513","0.12867"
"222.45600","18.53816","0.12927"
"222.61200","18.55120","0.12915"
"222.76800","18.56423","0.12985"
"222.92400","18.57714","0.12957"
"223.08000","18.59024","0.13055"
"223.23600","18.60316","0.13016"
"223.39200","18.61613","0.13100"
"223.54800","18.62910","0.13052"
"223.70400","18.64214","0.13080"
"223.86000","18.65511","0.13159"
"224.01600","18.66814","0.13161"
"224.17200","18.68112","0.13165"
"224.32800","18.69415","0.13218"
"224.48400","18.70713","0.13191"
"224.64000","18.72022","0.13240"
"224.79600","18.73314","0.13259"
"224.95200","18.74617","0.13258"
"225.10800","18.75915","0.13216"
"225.26400","18.77218","0.13273"
"225.42000","18.78515","0.13293"
"225.57600","18.79813","0.01520"
"225.73200","18.81116","0.00049"
"225.88800","18.82420","0.02001"
"226.04400","18.83711","0.02640"
"226.20000","18.85015","0.00642"
"226.35600","18.86324","0.00763"
"226.51200","18.87621","0.01186"
"226.66800","18.88913","0.00782"
"226.82400","18.90216","0.01895"
"226.98000","18.91520","0.02065"
"227.13600","18.92811","0.00867"
"227.29200","18.94114","0.00833"
"227.44800","18.95418","0.00844"
"227.60400","18.96715","0.01052"
"227.76000","18.98007","0.01651"
"227.91600","18.99316","0.01503"
"228.07200","19.00620","0.00907"
"228.22800","19.01917","0.00816"
"228.38400","19.03214","0.00913"
"228.54000","19.04518","0.01194"
"228.69600","19.05815","0.01555"
"228.85200","19.07113","0.01380"
"229.00800","19.08416","0.00977"
"229.16400","19.09720","0.00872"
"229.32000","19.11017","0.01053"
"229.41600","19.11812","0.01349"