File: Force_trajectories/170212_2/Specimen_RawData_7.csv
End date,"2/12/2017"
Specimen label,"14AG_11"
Maximum Load,"0.17125",N

Time,Extension,Load
(s),(mm),(N)
"0.00000","0.00000","0.00029"
"0.21600","0.01584","0.00043"
"0.43200","0.03629","0.00090"
"0.64800","0.05423","0.00034"
"0.86400","0.07229","0.00096"
"1.08000","0.09022","0.00106"
"1.29600","0.10822","0.00060"
"1.51200","0.12622","0.00049"
"1.72800","0.14421","0.00134"
"1.94400","0.16227","0.00104"
"2.16000","0.18021","0.00167"
"2.37600","0.19820","0.00157"
"2.59200","0.21626","0.00121"
"2.80800","0.23420","0.00159"
"3.02400","0.25231","0.00159"
"3.24000","0.27019","0.00226"
"3.45600","0.28825","0.00147"
"3.67200","0.30624","0.00154"
"3.88800","0.32424","0.00160"
"4.10400","0.34224","0.00200"
"4.32000","0.36029","0.00238"
"4.53600","0.37817","0.00221"
"4.75200","0.39623","0.00183"
"4.96800","0.41416","0.00244"
"5.18400","0.43222","0.00206"
"5.40000","0.45016","0.00243"
"5.61600","0.46821","0.00204"
"5.83200","0.48621","0.00216"
"6.04800","0.50421","0.00225"
"6.26400","0.52226","0.00257"
"6.48000","0.54020","0.00202"
"6.69600","0.55820","0.00252"
"6.91200","0.57619","0.00207"
"7.12800","0.59413","0.00261"
"7.34400","0.61224","0.00221"
"7.56000","0.63018","0.00216"
"7.77600","0.64824","0.00245"
"7.99200","0.66623","0.00281"
"8.20800","0.68417","0.00284"
"8.42400","0.70223","0.00263"
"8.64000","0.72022","0.00312"
"8.85600","0.73822","0.00252"
"9.07200","0.75628","0.00298"
"9.28800","0.77415","0.00270"
"9.50400","0.79227","0.00303"
"9.72000","0.81015","0.00283"
"9.93600","0.82820","0.00278"
"10.15200","0.84620","0.00317"
"10.36800","0.86414","0.00369"
"10.58400","0.88225","0.00283"
"10.80000","0.90019","0.00298"
"11.01600","0.91819","0.00286"
"11.23200","0.93618","0.00321"
"11.44800","0.95412","0.00361"
"11.66400","0.97224","0.00276"
"11.88000","0.99017","0.00270"
"12.09600","1.00823","0.00297"
"12.31200","1.02623","0.00308"
"12.52800","1.04416","0.00343"
"12.74400","1.06222","0.00287"
"12.96000","1.08022","0.00370"
"13.17600","1.09815","0.00332"
"13.39200","1.11627","0.00342"
"13.60800","1.13415","0.00302"
"13.82400","1.15226","0.00318"
"14.04000","1.17020","0.00316"
"14.25600","1.18820","0.00304"
"14.47200","1.20619","0.00290"
"14.68800","1.22413","0.00280"
"14.90400","1.24225","0.00285"
"15.12000","1.26018","0.00334"
"15.33600","1.27824","0.00331"
"15.55200","1.29618","0.00397"
"15.76800","1.31417","0.00278"
"15.98400","1.33217","0.00274"
"16.20000","1.35017","0.00203"
"16.41600","1.36822","0.00267"
"16.63200","1.38622","0.00249"
"16.84800","1.40422","0.00206"
"17.06400","1.42227","0.00290"
"17.28000","1.44015","0.00249"
"17.49600","1.45827","0.00313"
"17.71200","1.47620","0.00209"
"17.92800","1.49414","0.00275"
"18.14400","1.51220","0.00289"
"18.36000","1.53019","0.00234"
"18.57600","1.54825","0.00301"
"18.79200","1.56625","0.00315"
"19.00800","1.58418","0.00267"
"19.22400","1.60224","0.00283"
"19.44000","1.62024","0.00286"
"19.65600","1.63823","0.00290"
"19.87200","1.65623","0.00308"
"20.08800","1.67423","0.00266"
"20.30400","1.69222","0.00333"
"20.52000","1.71022","0.00303"
"20.73600","1.72822","0.00346"
"20.95200","1.74621","0.00259"
"21.16800","1.76415","0.00268"
"21.38400","1.78227","0.00280"
"21.60000","1.80020","0.00306"
"21.81600","1.81826","0.00337"
"22.03200","1.83626","0.00335"
"22.24800","1.85425","0.00306"
"22.46400","1.87219","0.00289"
"22.68000","1.89025","0.00286"
"22.89600","1.90824","0.00268"
"23.11200","1.92618","0.00317"
"23.32800","1.94418","0.00285"
"23.54400","1.96223","0.00308"
"23.76000","1.98023","0.00333"
"23.97600","1.99829","0.00314"
"24.19200","2.01616","0.00330"
"24.40800","2.03422","0.00313"
"24.62400","2.05222","0.00283"
"24.84000","2.07021","0.00271"
"25.05600","2.08821","0.00310"
"25.27200","2.10627","0.00298"
"25.48800","2.12420","0.00293"
"25.70400","2.14226","0.00329"
"25.92000","2.16020","0.00294"
"26.13600","2.17831","0.00317"
"26.35200","2.19619","0.00300"
"26.56800","2.21419","0.00334"
"26.78400","2.23230","0.00300"
"27.00000","2.25018","0.00318"
"27.21600","2.26824","0.00360"
"27.43200","2.28623","0.00320"
"27.64800","2.30417","0.00349"
"27.86400","2.32229","0.00357"
"28.08000","2.34016","0.00300"
"28.29600","2.35828","0.00255"
"28.51200","2.37616","0.00302"
"28.72800","2.39415","0.00303"
"28.94400","2.41227","0.00349"
"29.16000","2.43015","0.00301"
"29.37600","2.44820","0.00348"
"29.59200","2.46620","0.00312"
"29.80800","2.48420","0.00324"
"30.02400","2.50225","0.00348"
"30.24000","2.52019","0.00343"
"30.45600","2.53819","0.00310"
"30.67200","2.55618","0.00300"
"30.88800","2.57418","0.00280"
"31.10400","2.59224","0.00277"
"31.32000","2.61017","0.00318"
"31.53600","2.62823","0.00312"
"31.75200","2.64622","0.00375"
"31.96800","2.66422","0.00324"
"32.18400","2.68222","0.00371"
"32.40000","2.70016","0.00333"
"32.61600","2.71827","0.00400"
"32.83200","2.73621","0.00322"
"33.04800","2.75426","0.00335"
"33.26400","2.77226","0.00334"
"33.48000","2.79020","0.00290"
"33.69600","2.80819","0.00323"
"33.91200","2.82619","0.00343"
"34.12800","2.84425","0.00339"
"34.34400","2.86224","0.00353"
"34.56000","2.88018","0.00333"
"34.77600","2.89830","0.00377"
"34.99200","2.91623","0.00330"
"35.20800","2.93423","0.00364"
"35.42400","2.95223","0.00321"
"35.64000","2.97016","0.00367"
"35.85600","2.98828","0.00343"
"36.07200","3.00622","0.00410"
"36.28800","3.02421","0.00391"
"36.50400","3.04221","0.00331"
"36.72000","3.06021","0.00308"
"36.93600","3.07820","0.00353"
"37.15200","3.09620","0.00311"
"37.36800","3.11420","0.00253"
"37.58400","3.13225","0.00297"
"37.80000","3.15019","0.00327"
"38.01600","3.16825","0.00303"
"38.23200","3.18618","0.00307"
"38.44800","3.20418","0.00338"
"38.66400","3.22230","0.00385"
"38.88000","3.24017","0.00250"
"39.09600","3.25823","0.00319"
"39.31200","3.27623","0.00340"
"39.52800","3.29422","0.00289"
"39.74400","3.31222","0.00318"
"39.96000","3.33016","0.00347"
"40.17600","3.34821","0.00311"
"40.39200","3.36621","0.00342"
"40.60800","3.38421","0.00254"
"40.82400","3.40226","0.00295"
"41.04000","3.42020","0.00294"
"41.25600","3.43820","0.00272"
"41.47200","3.45619","0.00269"
"41.68800","3.47419","0.00349"
"41.90400","3.49225","0.00296"
"42.12000","3.51024","0.00266"
"42.33600","3.52824","0.00300"
"42.55200","3.54624","0.00357"
"42.76800","3.56423","0.00331"
"42.98400","3.58223","0.00299"
"43.20000","3.60023","0.00348"
"43.41600","3.61816","0.00331"
"43.63200","3.63616","0.00284"
"43.84800","3.65422","0.00276"
"44.06400","3.67227","0.00311"
"44.28000","3.69015","0.00340"
"44.49600","3.70827","0.00295"
"44.71200","3.72620","0.00380"
"44.92800","3.74426","0.00310"
"45.14400","3.76220","0.00358"
"45.36000","3.78019","0.00358"
"45.57600","3.79825","0.00383"
"45.79200","3.81625","0.00318"
"46.00800","3.83418","0.00331"
"46.22400","3.85224","0.00312"
"46.44000","3.87018","0.00335"
"46.65600","3.88823","0.00318"
"46.87200","3.90617","0.00255"
"47.08800","3.92423","0.00286"
"47.30400","3.94222","0.00327"
"47.52000","3.96022","0.00371"
"47.73600","3.97822","0.00292"
"47.95200","3.99615","0.00408"
"48.16800","4.01421","0.00329"
"48.38400","4.03221","0.00400"
"48.60000","4.05014","0.00343"
"48.81600","4.06826","0.00303"
"49.03200","4.08620","0.00342"
"49.24800","4.10425","0.00327"
"49.46400","4.12219","0.00351"
"49.68000","4.14019","0.00373"
"49.89600","4.15818","0.00360"
"50.11200","4.17618","0.00375"
"50.32800","4.19424","0.00389"
"50.54400","4.21217","0.00362"
"50.76000","4.23017","0.00358"
"50.97600","4.24829","0.00378"
"51.19200","4.26616","0.00360"
"51.40800","4.28422","0.00398"
"51.62400","4.30222","0.00425"
"51.84000","4.32021","0.00403"
"52.05600","4.33821","0.00345"
"52.27200","4.35621","0.00292"
"52.48800","4.37420","0.00339"
"52.70400","4.39226","0.00323"
"52.92000","4.41020","0.00346"
"53.13600","4.42825","0.00293"
"53.35200","4.44619","0.00303"
"53.56800","4.46425","0.00335"
"53.78400","4.48218","0.00368"
"54.00000","4.50018","0.00316"
"54.21600","4.51818","0.00355"
"54.43200","4.53617","0.00337"
"54.64800","4.55423","0.00349"
"54.86400","4.57223","0.00375"
"55.08000","4.59016","0.00384"
"55.29600","4.60822","0.00373"
"55.51200","4.62616","0.00329"
"55.72800","4.64421","0.00328"
"55.94400","4.66221","0.00413"
"56.16000","4.68021","0.00370"
"56.37600","4.69820","0.00366"
"56.59200","4.71614","0.00373"
"56.80800","4.73425","0.00409"
"57.02400","4.75225","0.00394"
"57.24000","4.77019","0.00398"
"57.45600","4.78819","0.00411"
"57.67200","4.80618","0.00364"
"57.88800","4.82424","0.00339"
"58.10400","4.84218","0.00415"
"58.32000","4.86017","0.00344"
"58.53600","4.87823","0.00339"
"58.75200","4.89616","0.00369"
"58.96800","4.91422","0.00418"
"59.18400","4.93222","0.00394"
"59.40000","4.95021","0.00352"
"59.61600","4.96827","0.00383"
"59.83200","4.98615","0.00405"
"60.04800","5.00426","0.00424"
"60.26400","5.02226","0.00440"
"60.48000","5.04020","0.00429"
"60.69600","5.05819","0.00453"
"60.91200","5.07619","0.00413"
"61.12800","5.09425","0.00403"
"61.34400","5.11218","0.00458"
"61.56000","5.13024","0.00473"
"61.77600","5.14824","0.00457"
"61.99200","5.16617","0.00433"
"62.20800","5.18423","0.00435"
"62.42400","5.20223","0.00488"
"62.64000","5.22022","0.00375"
"62.85600","5.23822","0.00435"
"63.07200","5.25622","0.00400"
"63.28800","5.27421","0.00379"
"63.50400","5.29221","0.00424"
"63.72000","5.31021","0.00421"
"63.93600","5.32820","0.00418"
"64.15200","5.34620","0.00481"
"64.36800","5.36420","0.00468"
"64.58400","5.38225","0.00470"
"64.80000","5.40025","0.00450"
"65.01600","5.41825","0.00428"
"65.23200","5.43612","0.00451"
"65.44800","5.45424","0.00463"
"65.66400","5.47218","0.00506"
"65.88000","5.49017","0.00506"
"66.09600","5.50823","0.00514"
"66.31200","5.52623","0.00437"
"66.52800","5.54422","0.00487"
"66.74400","5.56222","0.00481"
"66.96000","5.58022","0.00500"
"67.17600","5.59821","0.00485"
"67.39200","5.61615","0.00447"
"67.60800","5.63427","0.00553"
"67.82400","5.65214","0.00510"
"68.04000","5.67020","0.00509"
"68.25600","5.68826","0.00525"
"68.47200","5.70619","0.00481"
"68.68800","5.72419","0.00535"
"68.90400","5.74225","0.00534"
"69.12000","5.76018","0.00518"
"69.33600","5.77824","0.00523"
"69.55200","5.79618","0.00547"
"69.76800","5.81429","0.00521"
"69.98400","5.83217","0.00537"
"70.20000","5.85023","0.00567"
"70.41600","5.86822","0.00497"
"70.63200","5.88616","0.00495"
"70.84800","5.90428","0.00529"
"71.06400","5.92221","0.00499"
"71.28000","5.94021","0.00539"
"71.49600","5.95827","0.00537"
"71.71200","5.97614","0.00541"
"71.92800","5.99420","0.00590"
"72.14400","6.01220","0.00557"
"72.36000","6.03019","0.00569"
"72.57600","6.04825","0.00542"
"72.79200","6.06619","0.00585"
"73.00800","6.08424","0.00550"
"73.22400","6.10218","0.00634"
"73.44000","6.12024","0.00538"
"73.65600","6.13823","0.00612"
"73.87200","6.15611","0.00645"
"74.08800","6.17423","0.00647"
"74.30400","6.19222","0.00615"
"74.52000","6.21022","0.00604"
"74.73600","6.22822","0.00587"
"74.95200","6.24615","0.00622"
"75.16800","6.26421","0.00591"
"75.38400","6.28221","0.00616"
"75.60000","6.30020","0.00642"
"75.81600","6.31820","0.00629"
"76.03200","6.33620","0.00642"
"76.24800","6.35419","0.00634"
"76.46400","6.37219","0.00698"
"76.68000","6.39025","0.00653"
"76.89600","6.40824","0.00614"
"77.11200","6.42618","0.00688"
"77.32800","6.44424","0.00675"
"77.54400","6.46223","0.00688"
"77.76000","6.48029","0.00706"
"77.97600","6.49823","0.00752"
"78.19200","6.51616","0.00684"
"78.40800","6.53422","0.00736"
"78.62400","6.55216","0.00717"
"78.84000","6.57027","0.00753"
"79.05600","6.58821","0.00792"
"79.27200","6.60609","0.00739"
"79.48800","6.62426","0.00725"
"79.70400","6.64220","0.00709"
"79.92000","6.66019","0.00799"
"80.13600","6.67825","0.00767"
"80.35200","6.69619","0.00816"
"80.56800","6.71424","0.00776"
"80.78400","6.73218","0.00695"
"81.00000","6.75024","0.00780"
"81.21600","6.76829","0.00746"
"81.43200","6.78617","0.00794"
"81.64800","6.80429","0.00808"
"81.86400","6.82217","0.00782"
"82.08000","6.84028","0.00798"
"82.29600","6.85822","0.00655"
"82.51200","6.87622","0.00651"
"82.72800","6.89421","0.00684"
"82.94400","6.91221","0.00706"
"83.16000","6.93020","0.00639"
"83.37600","6.94820","0.00717"
"83.59200","6.96620","0.00672"
"83.80800","6.98425","0.00623"
"84.02400","7.00225","0.00632"
"84.24000","7.02025","0.00666"
"84.45600","7.03818","0.00625"
"84.67200","7.05624","0.00758"
"84.88800","7.07418","0.00649"
"85.10400","7.09223","0.00712"
"85.32000","7.11023","0.00712"
"85.53600","7.12829","0.00798"
"85.75200","7.14616","0.00656"
"85.96800","7.16428","0.00733"
"86.18400","7.18216","0.00658"
"86.40000","7.20027","0.00668"
"86.61600","7.21821","0.00703"
"86.83200","7.23621","0.00663"
"87.04800","7.25420","0.00792"
"87.26400","7.27220","0.00762"
"87.48000","7.29026","0.00747"
"87.69600","7.30825","0.00791"
"87.91200","7.32619","0.00722"
"88.12800","7.34425","0.00753"
"88.34400","7.36218","0.00769"
"88.56000","7.38030","0.00823"
"88.77600","7.39812","0.00805"
"88.99200","7.41617","0.00774"
"89.20800","7.43423","0.00861"
"89.42400","7.45217","0.00805"
"89.64000","7.47022","0.00801"
"89.85600","7.48822","0.00821"
"90.07200","7.50616","0.00850"
"90.28800","7.52421","0.00859"
"90.50400","7.54221","0.00894"
"90.72000","7.56027","0.00853"
"90.93600","7.57820","0.00927"
"91.15200","7.59620","0.00891"
"91.36800","7.61426","0.00848"
"91.58400","7.63219","0.00974"
"91.80000","7.65019","0.00890"
"92.01600","7.66825","0.00851"
"92.23200","7.68624","0.00938"
"92.44800","7.70424","0.00803"
"92.66400","7.72218","0.00862"
"92.88000","7.74023","0.00895"
"93.09600","7.75817","0.00732"
"93.31200","7.77617","0.00764"
"93.52800","7.79428","0.00799"
"93.74400","7.81216","0.00820"
"93.96000","7.83022","0.00796"
"94.17600","7.84821","0.00796"
"94.39200","7.86621","0.00879"
"94.60800","7.88421","0.00815"
"94.82400","7.90214","0.00861"
"95.04000","7.92026","0.00812"
"95.25600","7.93820","0.00805"
"95.47200","7.95619","0.00869"
"95.68800","7.97425","0.00862"
"95.90400","7.99219","0.00818"
"96.12000","8.01024","0.00877"
"96.33600","8.02824","0.00885"
"96.55200","8.04624","0.00894"
"96.76800","8.06429","0.00875"
"96.98400","8.08217","0.00935"
"97.20000","8.10029","0.00872"
"97.41600","8.11822","0.00835"
"97.63200","8.13616","0.00938"
"97.84800","8.15422","0.00960"
"98.06400","8.17215","0.00847"
"98.28000","8.19027","0.00942"
"98.49600","8.20821","0.00895"
"98.71200","8.22626","0.00939"
"98.92800","8.24426","0.00903"
"99.14400","8.26220","0.00922"
"99.36000","8.28025","0.00952"
"99.57600","8.29819","0.00921"
"99.79200","8.31625","0.00996"
"100.00800","8.33424","0.00919"
"100.22400","8.35218","0.00952"
"100.44000","8.37024","0.00981"
"100.65600","8.38817","0.01024"
"100.87200","8.40623","0.01016"
"101.08800","8.42422","0.01033"
"101.30400","8.44222","0.01051"
"101.52000","8.46022","0.01001"
"101.73600","8.47822","0.01019"
"101.95200","8.49621","0.01010"
"102.16800","8.51421","0.01057"
"102.38400","8.53215","0.01059"
"102.60000","8.55026","0.01075"
"102.81600","8.56814","0.01031"
"103.03200","8.58626","0.01036"
"103.24800","8.60431","0.01029"
"103.46400","8.62219","0.01038"
"103.68000","8.64025","0.01083"
"103.89600","8.65818","0.01001"
"104.11200","8.67624","0.01067"
"104.32800","8.69429","0.01059"
"104.54400","8.71217","0.01085"
"104.76000","8.73029","0.01011"
"104.97600","8.74823","0.01089"
"105.19200","8.76628","0.01045"
"105.40800","8.78422","0.01044"
"105.62400","8.80221","0.01081"
"105.84000","8.82021","0.01087"
"106.05600","8.83821","0.01133"
"106.27200","8.85620","0.01105"
"106.48800","8.87426","0.01098"
"106.70400","8.89220","0.01123"
"106.92000","8.91020","0.01134"
"107.13600","8.92819","0.01101"
"107.35200","8.94619","0.01122"
"107.56800","8.96424","0.01138"
"107.78400","8.98224","0.01166"
"108.00000","9.00018","0.01118"
"108.21600","9.01817","0.01150"
"108.43200","9.03623","0.01128"
"108.64800","9.05423","0.01170"
"108.86400","9.07216","0.01205"
"109.08000","9.09028","0.01203"
"109.29600","9.10822","0.01256"
"109.51200","9.12627","0.01202"
"109.72800","9.14421","0.01209"
"109.94400","9.16227","0.01213"
"110.16000","9.18021","0.01263"
"110.37600","9.19820","0.01161"
"110.59200","9.21620","0.01270"
"110.80800","9.23419","0.01232"
"111.02400","9.25219","0.01234"
"111.24000","9.27025","0.01283"
"111.45600","9.28818","0.01347"
"111.67200","9.30624","0.01341"
"111.88800","9.32424","0.01330"
"112.10400","9.34223","0.01267"
"112.32000","9.36023","0.01282"
"112.53600","9.37823","0.01245"
"112.75200","9.39622","0.01257"
"112.96800","9.41428","0.01200"
"113.18400","9.43216","0.01264"
"113.40000","9.45027","0.01248"
"113.61600","9.46815","0.01188"
"113.83200","9.48627","0.01273"
"114.04800","9.50420","0.01301"
"114.26400","9.52220","0.01325"
"114.48000","9.54026","0.01319"
"114.69600","9.55819","0.01215"
"114.91200","9.57619","0.01193"
"115.12800","9.59425","0.01240"
"115.34400","9.61218","0.01225"
"115.56000","9.63024","0.01220"
"115.77600","9.64824","0.01232"
"115.99200","9.66623","0.01272"
"116.20800","9.68423","0.01268"
"116.42400","9.70223","0.01238"
"116.64000","9.72022","0.01343"
"116.85600","9.73816","0.01291"
"117.07200","9.75622","0.01284"
"117.28800","9.77421","0.01377"
"117.50400","9.79221","0.01330"
"117.72000","9.81021","0.01295"
"117.93600","9.82820","0.01366"
"118.15200","9.84620","0.01359"
"118.36800","9.86420","0.01339"
"118.58400","9.88219","0.01399"
"118.80000","9.90019","0.01379"
"119.01600","9.91819","0.01389"
"119.23200","9.93624","0.01444"
"119.44800","9.95418","0.01469"
"119.66400","9.97218","0.01358"
"119.88000","9.99023","0.01371"
"120.09600","10.00811","0.01426"
"120.31200","10.02629","0.01424"
"120.52800","10.04422","0.01397"
"120.74400","10.06222","0.01508"
"120.96000","10.08028","0.01469"
"121.17600","10.09815","0.01526"
"121.39200","10.11627","0.01550"
"121.60800","10.13421","0.01574"
"121.82400","10.15226","0.01574"
"122.04000","10.17020","0.01514"
"122.25600","10.18820","0.01500"
"122.47200","10.20625","0.01527"
"122.68800","10.22425","0.01509"
"122.90400","10.24219","0.01568"
"123.12000","10.26024","0.01637"
"123.33600","10.27812","0.01631"
"123.55200","10.29624","0.01614"
"123.76800","10.31423","0.01611"
"123.98400","10.33223","0.01579"
"124.20000","10.35029","0.01595"
"124.41600","10.36822","0.01585"
"124.63200","10.38622","0.01631"
"124.84800","10.40428","0.01575"
"125.06400","10.42221","0.01609"
"125.28000","10.44021","0.01625"
"125.49600","10.45815","0.01709"
"125.71200","10.47626","0.01623"
"125.92800","10.49420","0.01584"
"126.14400","10.51220","0.01684"
"126.36000","10.53019","0.01703"
"126.57600","10.54819","0.01667"
"126.79200","10.56619","0.01742"
"127.00800","10.58424","0.01681"
"127.22400","10.60218","0.01699"
"127.44000","10.62024","0.01724"
"127.65600","10.63817","0.01742"
"127.87200","10.65623","0.01723"
"128.08800","10.67417","0.01778"
"128.30400","10.69222","0.01731"
"128.52000","10.71022","0.01744"
"128.73600","10.72822","0.01601"
"128.95200","10.74621","0.01597"
"129.16800","10.76421","0.01652"
"129.38400","10.78226","0.01670"
"129.60000","10.80020","0.01725"
"129.81600","10.81814","0.01728"
"130.03200","10.83626","0.01737"
"130.24800","10.85419","0.01685"
"130.46400","10.87225","0.01806"
"130.68000","10.89024","0.01818"
"130.89600","10.90812","0.01765"
"131.11200","10.92624","0.01783"
"131.32800","10.94423","0.01850"
"131.54400","10.96223","0.01772"
"131.76000","10.98023","0.01826"
"131.97600","10.99817","0.01778"
"132.19200","11.01622","0.01818"
"132.40800","11.03416","0.01791"
"132.62400","11.05222","0.01867"
"132.84000","11.07021","0.01893"
"133.05600","11.08815","0.01871"
"133.27200","11.10620","0.01913"
"133.48800","11.12426","0.01897"
"133.70400","11.14220","0.01886"
"133.92000","11.16025","0.01934"
"134.13600","11.17813","0.01917"
"134.35200","11.19625","0.01979"
"134.56800","11.21418","0.01987"
"134.78400","11.23224","0.01904"
"135.00000","11.25024","0.01994"
"135.21600","11.26818","0.02021"
"135.43200","11.28629","0.01997"
"135.64800","11.30417","0.02063"
"135.86400","11.32222","0.02050"
"136.08000","11.34022","0.02091"
"136.29600","11.35816","0.02083"
"136.51200","11.37621","0.02052"
"136.72800","11.39421","0.02049"
"136.94400","11.41221","0.02081"
"137.16000","11.43020","0.02095"
"137.37600","11.44820","0.02071"
"137.59200","11.46626","0.02097"
"137.80800","11.48419","0.02123"
"138.02400","11.50225","0.02146"
"138.24000","11.52025","0.02196"
"138.45600","11.53818","0.02193"
"138.67200","11.55624","0.02136"
"138.88800","11.57412","0.02144"
"139.10400","11.59223","0.02178"
"139.32000","11.61023","0.02192"
"139.53600","11.62817","0.02175"
"139.75200","11.64628","0.02218"
"139.96800","11.66416","0.02265"
"140.18400","11.68222","0.02189"
"140.40000","11.70021","0.02209"
"140.61600","11.71821","0.02252"
"140.83200","11.73627","0.02204"
"141.04800","11.75420","0.02273"
"141.26400","11.77226","0.02284"
"141.48000","11.79026","0.02284"
"141.69600","11.80819","0.02254"
"141.91200","11.82625","0.02321"
"142.12800","11.84419","0.02322"
"142.34400","11.86224","0.02314"
"142.56000","11.88018","0.02332"
"142.77600","11.89818","0.02286"
"142.99200","11.91623","0.02345"
"143.20800","11.93423","0.02369"
"143.42400","11.95223","0.02397"
"143.64000","11.97022","0.02359"
"143.85600","11.98816","0.02434"
"144.07200","12.00628","0.02405"
"144.28800","12.02421","0.02418"
"144.50400","12.04227","0.02399"
"144.72000","12.06021","0.02424"
"144.93600","12.07820","0.02472"
"145.15200","12.09620","0.02480"
"145.36800","12.11420","0.02513"
"145.58400","12.13219","0.02487"
"145.80000","12.15025","0.02535"
"146.01600","12.16819","0.02514"
"146.23200","12.18630","0.02494"
"146.44800","12.20418","0.02512"
"146.66400","12.22230","0.02560"
"146.88000","12.24017","0.02231"
"147.09600","12.25823","0.02324"
"147.31200","12.27623","0.02394"
"147.52800","12.29422","0.02375"
"147.74400","12.31222","0.02380"
"147.96000","12.33022","0.02385"
"148.17600","12.34821","0.02334"
"148.39200","12.36627","0.02387"
"148.60800","12.38421","0.02378"
"148.82400","12.40220","0.02357"
"149.04000","12.42026","0.02370"
"149.25600","12.43826","0.02157"
"149.47200","12.45625","0.02273"
"149.68800","12.47419","0.02307"
"149.90400","12.49224","0.02297"
"150.12000","12.51024","0.02348"
"150.33600","12.52818","0.02372"
"150.55200","12.54624","0.02403"
"150.76800","12.56417","0.02380"
"150.98400","12.58223","0.02407"
"151.20000","12.60023","0.02400"
"151.41600","12.61822","0.02399"
"151.63200","12.63622","0.02447"
"151.84800","12.65421","0.02429"
"152.06400","12.67227","0.02427"
"152.28000","12.69021","0.02499"
"152.49600","12.70826","0.02454"
"152.71200","12.72626","0.02478"
"152.92800","12.74420","0.02541"
"153.14400","12.76226","0.02505"
"153.36000","12.78013","0.02500"
"153.57600","12.79819","0.02552"
"153.79200","12.81625","0.02593"
"154.00800","12.83418","0.02631"
"154.22400","12.85224","0.02631"
"154.44000","12.87024","0.02636"
"154.65600","12.88823","0.02653"
"154.87200","12.90623","0.02708"
"155.08800","12.92416","0.02672"
"155.30400","12.94228","0.02686"
"155.52000","12.96022","0.02712"
"155.73600","12.97822","0.02701"
"155.95200","12.99627","0.02738"
"156.16800","13.01421","0.02730"
"156.38400","13.03221","0.02742"
"156.60000","13.05020","0.02701"
"156.81600","13.06820","0.02785"
"157.03200","13.08626","0.02709"
"157.24800","13.10413","0.02786"
"157.46400","13.12225","0.02713"
"157.68000","13.14018","0.02751"
"157.89600","13.15818","0.02726"
"158.11200","13.17624","0.02722"
"158.32800","13.19418","0.02739"
"158.54400","13.21217","0.02813"
"158.76000","13.23023","0.02846"
"158.97600","13.24822","0.02718"
"159.19200","13.26628","0.02795"
"159.40800","13.28422","0.02785"
"159.62400","13.30222","0.02780"
"159.84000","13.32015","0.02813"
"160.05600","13.33821","0.02796"
"160.27200","13.35620","0.02799"
"160.48800","13.37414","0.02802"
"160.70400","13.39226","0.02842"
"160.92000","13.41019","0.02838"
"161.13600","13.42819","0.02849"
"161.35200","13.44625","0.02837"
"161.56800","13.46419","0.02737"
"161.78400","13.48224","0.02739"
"162.00000","13.50024","0.02729"
"162.21600","13.51823","0.02667"
"162.43200","13.53623","0.02743"
"162.64800","13.55417","0.02740"
"162.86400","13.57222","0.02767"
"163.08000","13.59022","0.02789"
"163.29600","13.60828","0.02841"
"163.51200","13.62627","0.02803"
"163.72800","13.64421","0.02825"
"163.94400","13.66227","0.02910"
"164.16000","13.68020","0.02813"
"164.37600","13.69826","0.02887"
"164.59200","13.71626","0.02788"
"164.80800","13.73413","0.02874"
"165.02400","13.75225","0.02645"
"165.24000","13.77025","0.02754"
"165.45600","13.78824","0.02794"
"165.67200","13.80624","0.02790"
"165.88800","13.82418","0.02819"
"166.10400","13.84223","0.02842"
"166.32000","13.86017","0.02844"
"166.53600","13.87823","0.02846"
"166.75200","13.89628","0.02837"
"166.96800","13.91416","0.02876"
"167.18400","13.93228","0.02895"
"167.40000","13.95021","0.02886"
"167.61600","13.96821","0.02894"
"167.83200","13.98627","0.02932"
"168.04800","14.00420","0.02914"
"168.26400","14.02220","0.02940"
"168.48000","14.04026","0.02938"
"168.69600","14.05819","0.03003"
"168.91200","14.07625","0.03005"
"169.12800","14.09419","0.03013"
"169.34400","14.11224","0.03007"
"169.56000","14.13024","0.03050"
"169.77600","14.14824","0.03057"
"169.99200","14.16623","0.03074"
"170.20800","14.18423","0.03017"
"170.42400","14.20217","0.03065"
"170.64000","14.22016","0.03055"
"170.85600","14.23822","0.03059"
"171.07200","14.25622","0.03082"
"171.28800","14.27415","0.03074"
"171.50400","14.29221","0.03122"
"171.72000","14.31015","0.03102"
"171.93600","14.32826","0.03068"
"172.15200","14.34620","0.03093"
"172.36800","14.36426","0.03110"
"172.58400","14.38219","0.03103"
"172.80000","14.40019","0.03093"
"173.01600","14.41825","0.03145"
"173.23200","14.43624","0.03163"
"173.44800","14.45418","0.03208"
"173.66400","14.47224","0.03216"
"173.88000","14.49017","0.03129"
"174.09600","14.50829","0.03153"
"174.31200","14.52623","0.03141"
"174.52800","14.54416","0.03174"
"174.74400","14.56222","0.03148"
"174.96000","14.58022","0.03160"
"175.17600","14.59821","0.03177"
"175.39200","14.61621","0.03169"
"175.60800","14.63421","0.03191"
"175.82400","14.65220","0.03218"
"176.04000","14.67020","0.02780"
"176.25600","14.68826","0.02822"
"176.47200","14.70625","0.02839"
"176.68800","14.72419","0.02775"
"176.90400","14.74219","0.02853"
"177.12000","14.76018","0.02868"
"177.33600","14.77824","0.02920"
"177.55200","14.79618","0.02897"
"177.76800","14.81417","0.02943"
"177.98400","14.83223","0.02969"
"178.20000","14.85017","0.03010"
"178.41600","14.86822","0.02983"
"178.63200","14.88622","0.02986"
"178.84800","14.90422","0.03030"
"179.06400","14.92221","0.03064"
"179.28000","14.94021","0.03040"
"179.49600","14.95820","0.03056"
"179.71200","14.97614","0.03053"
"179.92800","14.99426","0.03116"
"180.14400","15.01225","0.03118"
"180.36000","15.03019","0.03105"
"180.57600","15.04825","0.03152"
"180.79200","15.06625","0.03175"
"181.00800","15.08424","0.03143"
"181.22400","15.10224","0.03146"
"181.44000","15.12018","0.01480"
"181.65600","15.13829","0.01242"
"181.87200","15.15623","0.01133"
"182.08800","15.17422","0.01018"
"182.30400","15.19222","0.00953"
"182.52000","15.21022","0.00910"
"182.73600","15.22821","0.00993"
"182.95200","15.24621","0.01094"
"183.16800","15.26415","0.01064"
"183.38400","15.28227","0.01136"
"183.60000","15.30014","0.01132"
"183.81600","15.31826","0.01355"
"184.03200","15.33620","0.01173"
"184.24800","15.35425","0.01272"
"184.46400","15.37231","0.01302"
"184.68000","15.39018","0.01245"
"184.89600","15.40830","0.01433"
"185.11200","15.42624","0.01482"
"185.32800","15.44417","0.01510"
"185.54400","15.46229","0.01570"
"185.76000","15.48011","0.01564"
"185.97600","15.49828","0.01671"
"186.19200","15.51622","0.01695"
"186.40800","15.53428","0.01726"
"186.62400","15.55222","0.01832"
"186.84000","15.57021","0.01801"
"187.05600","15.58821","0.01912"
"187.27200","15.60620","0.01920"
"187.48800","15.62420","0.02013"
"187.70400","15.64220","0.02060"
"187.92000","15.66013","0.02112"
"188.13600","15.67825","0.02111"
"188.35200","15.69619","0.02132"
"188.56800","15.71418","0.02236"
"188.78400","15.73224","0.02155"
"189.00000","15.75018","0.02235"
"189.21600","15.76823","0.02267"
"189.43200","15.78623","0.02239"
"189.64800","15.80423","0.02369"
"189.86400","15.82222","0.02289"
"190.08000","15.84016","0.02362"
"190.29600","15.85822","0.02386"
"190.51200","15.87615","0.02423"
"190.72800","15.89427","0.02463"
"190.94400","15.91221","0.02450"
"191.16000","15.93020","0.02489"
"191.37600","15.94820","0.02534"
"191.59200","15.96626","0.02535"
"191.80800","15.98419","0.02604"
"192.02400","16.00225","0.02573"
"192.24000","16.02019","0.02598"
"192.45600","16.03824","0.02587"
"192.67200","16.05618","0.02648"
"192.88800","16.07424","0.02700"
"193.10400","16.09223","0.02698"
"193.32000","16.11023","0.02676"
"193.53600","16.12817","0.02695"
"193.75200","16.14622","0.02733"
"193.96800","16.16422","0.02761"
"194.18400","16.18228","0.02788"
"194.40000","16.20015","0.02790"
"194.61600","16.21827","0.02830"
"194.83200","16.23621","0.02875"
"195.04800","16.25414","0.02884"
"195.26400","16.27220","0.02880"
"195.48000","16.29020","0.02922"
"195.69600","16.30819","0.02968"
"195.91200","16.32619","0.03011"
"196.12800","16.34425","0.02975"
"196.34400","16.36218","0.03020"
"196.56000","16.38018","0.03038"
"196.77600","16.39818","0.03060"
"196.99200","16.41611","0.03063"
"197.20800","16.43423","0.03088"
"197.42400","16.45222","0.03135"
"197.64000","16.47022","0.03122"
"197.85600","16.48822","0.03163"
"198.07200","16.50622","0.03164"
"198.28800","16.52421","0.03199"
"198.50400","16.54221","0.03173"
"198.72000","16.56021","0.03172"
"198.93600","16.57826","0.03207"
"199.15200","16.59620","0.03246"
"199.36800","16.61419","0.03249"
"199.58400","16.63225","0.03258"
"199.80000","16.65019","0.03282"
"200.01600","16.66825","0.03285"
"200.23200","16.68618","0.03306"
"200.44800","16.70424","0.03345"
"200.66400","16.72224","0.03321"
"200.88000","16.74023","0.03355"
"201.09600","16.75823","0.03369"
"201.31200","16.77617","0.03400"
"201.52800","16.79422","0.03405"
"201.74400","16.81222","0.03390"
"201.96000","16.83022","0.03394"
"202.17600","16.84827","0.03423"
"202.39200","16.86621","0.03492"
"202.60800","16.88421","0.03478"
"202.82400","16.90220","0.03500"
"203.04000","16.92020","0.03498"
"203.25600","16.93819","0.03564"
"203.47200","16.95619","0.03546"
"203.68800","16.97425","0.03604"
"203.90400","16.99224","0.03601"
"204.12000","17.01018","0.03639"
"204.33600","17.02824","0.03681"
"204.55200","17.04618","0.03689"
"204.76800","17.06423","0.03722"
"204.98400","17.08217","0.03726"
"205.20000","17.10022","0.03794"
"205.41600","17.11822","0.03757"
"205.63200","17.13622","0.03849"
"205.84800","17.15421","0.03849"
"206.06400","17.17221","0.03826"
"206.28000","17.19015","0.03894"
"206.49600","17.20827","0.03856"
"206.71200","17.22620","0.03901"
"206.92800","17.24432","0.03931"
"207.14400","17.26219","0.03966"
"207.36000","17.28019","0.03955"
"207.57600","17.29825","0.04058"
"207.79200","17.31618","0.04018"
"208.00800","17.33430","0.03984"
"208.22400","17.35224","0.04023"
"208.44000","17.37011","0.04030"
"208.65600","17.38829","0.04033"
"208.87200","17.40623","0.03861"
"209.08800","17.42422","0.03933"
"209.30400","17.44222","0.03964"
"209.52000","17.46022","0.04016"
"209.73600","17.47821","0.04031"
"209.95200","17.49621","0.04017"
"210.16800","17.51421","0.03909"
"210.38400","17.53226","0.03888"
"210.60000","17.55014","0.03916"
"210.81600","17.56826","0.03954"
"211.03200","17.58613","0.03960"
"211.24800","17.60425","0.03919"
"211.46400","17.62219","0.03991"
"211.68000","17.64018","0.04027"
"211.89600","17.65824","0.04002"
"212.11200","17.67618","0.04018"
"212.32800","17.69423","0.04022"
"212.54400","17.71223","0.04076"
"212.76000","17.73023","0.04086"
"212.97600","17.74822","0.04169"
"213.19200","17.76622","0.04206"
"213.40800","17.78428","0.04246"
"213.62400","17.80215","0.03040"
"213.84000","17.82021","0.02549"
"214.05600","17.83821","0.02749"
"214.27200","17.85620","0.02614"
"214.48800","17.87420","0.02825"
"214.70400","17.89220","0.02823"
"214.92000","17.91019","0.02814"
"215.13600","17.92825","0.02854"
"215.35200","17.94613","0.02871"
"215.56800","17.96424","0.02969"
"215.78400","17.98218","0.02889"
"216.00000","18.00024","0.03003"
"216.21600","18.01823","0.03007"
"216.43200","18.03617","0.03034"
"216.64800","18.05423","0.03043"
"216.86400","18.07222","0.03057"
"217.08000","18.09022","0.03095"
"217.29600","18.10822","0.03099"
"217.51200","18.12615","0.03211"
"217.72800","18.14427","0.03149"
"217.94400","18.16215","0.03183"
"218.16000","18.18020","0.03219"
"218.37600","18.19826","0.03234"
"218.59200","18.21614","0.03265"
"218.80800","18.23425","0.03253"
"219.02400","18.25219","0.03262"
"219.24000","18.27019","0.03286"
"219.45600","18.28824","0.03362"
"219.67200","18.30618","0.03307"
"219.88800","18.32424","0.03394"
"220.10400","18.34217","0.03377"
"220.32000","18.36023","0.03449"
"220.53600","18.37823","0.03450"
"220.75200","18.39616","0.03433"
"220.96800","18.41422","0.03506"
"221.18400","18.43222","0.03474"
"221.40000","18.45021","0.03539"
"221.61600","18.46821","0.03458"
"221.83200","18.48621","0.03353"
"222.04800","18.50426","0.03349"
"222.26400","18.52220","0.03356"
"222.48000","18.54020","0.03421"
"222.69600","18.55825","0.03392"
"222.91200","18.57619","0.03432"
"223.12800","18.59425","0.03352"
"223.34400","18.61218","0.03450"
"223.56000","18.63024","0.03421"
"223.77600","18.64818","0.03440"
"223.99200","18.66617","0.03483"
"224.20800","18.68423","0.03426"
"224.42400","18.70217","0.03488"
"224.64000","18.72022","0.03421"
"224.85600","18.73828","0.03505"
"225.07200","18.75616","0.03456"
"225.28800","18.77427","0.03510"
"225.50400","18.79215","0.03519"
"225.72000","18.81026","0.03512"
"225.93600","18.82826","0.03518"
"226.15200","18.84620","0.03526"
"226.36800","18.86419","0.03583"
"226.58400","18.88219","0.03533"
"226.80000","18.90019","0.03590"
"227.01600","18.91825","0.03534"
"227.23200","18.93612","0.03603"
"227.44800","18.95430","0.03593"
"227.66400","18.97218","0.03579"
"227.88000","18.99023","0.03647"
"228.09600","19.00823","0.03593"
"228.31200","19.02617","0.03665"
"228.52800","19.04422","0.03609"
"228.74400","19.06216","0.03676"
"228.96000","19.08022","0.03659"
"229.17600","19.09827","0.03708"
"229.39200","19.11615","0.03671"
"229.60800","19.13426","0.03690"
"229.82400","19.15226","0.03722"
"230.04000","19.17020","0.03724"
"230.25600","19.18826","0.03779"
"230.47200","19.20619","0.03765"
"230.68800","19.22419","0.03784"
"230.90400","19.24218","0.03744"
"231.12000","19.26018","0.03860"
"231.33600","19.27824","0.03819"
"231.55200","19.29618","0.03799"
"231.76800","19.31423","0.03838"
"231.98400","19.33217","0.03857"
"232.20000","19.35023","0.03858"
"232.41600","19.36822","0.03878"
"232.63200","19.38622","0.03930"
"232.84800","19.40421","0.03896"
"233.06400","19.42221","0.03965"
"233.28000","19.44021","0.03936"
"233.49600","19.45826","0.03959"
"233.71200","19.47614","0.03992"
"233.92800","19.49426","0.04020"
"234.14400","19.51214","0.04109"
"234.36000","19.53031","0.04041"
"234.57600","19.54819","0.04124"
"234.79200","19.56625","0.04056"
"235.00800","19.58418","0.04112"
"235.22400","19.60218","0.04080"
"235.44000","19.62023","0.04132"
"235.65600","19.63823","0.04090"
"235.87200","19.65617","0.04115"
"236.08800","19.67422","0.04172"
"236.30400","19.69222","0.04153"
"236.52000","19.71022","0.04252"
"236.73600","19.72821","0.04208"
"236.95200","19.74621","0.04293"
"237.16800","19.76421","0.04134"
"237.38400","19.78214","0.04232"
"237.60000","19.80026","0.04216"
"237.81600","19.81826","0.04264"
"238.03200","19.83619","0.04271"
"238.24800","19.85425","0.04215"
"238.46400","19.87219","0.04277"
"238.68000","19.89030","0.04290"
"238.89600","19.90818","0.04312"
"239.11200","19.92618","0.04316"
"239.32800","19.94417","0.04383"
"239.54400","19.96217","0.04297"
"239.76000","19.98023","0.04399"
"239.97600","19.99816","0.04407"
"240.19200","20.01622","0.04402"
"240.40800","20.03422","0.04468"
"240.62400","20.05215","0.04478"
"240.84000","20.07027","0.04371"
"241.05600","20.08821","0.04290"
"241.27200","20.10620","0.04344"
"241.48800","20.12426","0.04324"
"241.70400","20.14220","0.04416"
"241.92000","20.16025","0.04349"
"242.13600","20.17825","0.04403"
"242.35200","20.19624","0.04428"
"242.56800","20.21424","0.04481"
"242.78400","20.23218","0.04483"
"243.00000","20.25030","0.04389"
"243.21600","20.26823","0.04468"
"243.43200","20.28623","0.04458"
"243.64800","20.30423","0.04512"
"243.86400","20.32216","0.04477"
"244.08000","20.34022","0.04424"
"244.29600","20.35822","0.04313"
"244.51200","20.37621","0.04435"
"244.72800","20.39421","0.04376"
"244.94400","20.41221","0.04403"
"245.16000","20.43026","0.04438"
"245.37600","20.44826","0.04415"
"245.59200","20.46626","0.04451"
"245.80800","20.48425","0.04401"
"246.02400","20.50213","0.04366"
"246.24000","20.52024","0.04441"
"246.45600","20.53824","0.04474"
"246.67200","20.55624","0.04439"
"246.88800","20.57424","0.04533"
"247.10400","20.59223","0.04548"
"247.32000","20.61023","0.04565"
"247.53600","20.62823","0.04618"
"247.75200","20.64616","0.04594"
"247.96800","20.66422","0.04682"
"248.18400","20.68216","0.04678"
"248.40000","20.70027","0.04718"
"248.61600","20.71821","0.04640"
"248.83200","20.73621","0.04702"
"249.04800","20.75426","0.04616"
"249.26400","20.77214","0.04652"
"249.48000","20.79026","0.04560"
"249.69600","20.80819","0.04581"
"249.91200","20.82619","0.04527"
"250.12800","20.84425","0.04556"
"250.34400","20.86212","0.04545"
"250.56000","20.88030","0.04553"
"250.77600","20.89817","0.04592"
"250.99200","20.91623","0.04591"
"251.20800","20.93423","0.04565"
"251.42400","20.95217","0.04376"
"251.64000","20.97022","0.04442"
"251.85600","20.98822","0.04445"
"252.07200","21.00616","0.04514"
"252.28800","21.02427","0.04537"
"252.50400","21.04215","0.04589"
"252.72000","21.06020","0.04670"
"252.93600","21.07820","0.04660"
"253.15200","21.09620","0.04746"
"253.36800","21.11426","0.04742"
"253.58400","21.13219","0.04812"
"253.80000","21.15019","0.04799"
"254.01600","21.16818","0.04904"
"254.23200","21.18624","0.04960"
"254.44800","21.20424","0.04951"
"254.66400","21.22211","0.04876"
"254.88000","21.24023","0.04933"
"255.09600","21.25817","0.05005"
"255.31200","21.27622","0.05044"
"255.52800","21.29422","0.05054"
"255.74400","21.31222","0.04627"
"255.96000","21.33021","0.04550"
"256.17600","21.34821","0.04391"
"256.39200","21.36621","0.04402"
"256.60800","21.38420","0.04379"
"256.82400","21.40214","0.04372"
"257.04000","21.42020","0.04417"
"257.25600","21.43814","0.04511"
"257.47200","21.45619","0.04526"
"257.68800","21.47419","0.04607"
"257.90400","21.49219","0.04680"
"258.12000","21.51018","0.04658"
"258.33600","21.52818","0.04621"
"258.55200","21.54623","0.04699"
"258.76800","21.56417","0.04706"
"258.98400","21.58211","0.04812"
"259.20000","21.60022","0.04804"
"259.41600","21.61822","0.04735"
"259.63200","21.63628","0.04774"
"259.84800","21.65421","0.04802"
"260.06400","21.67215","0.04832"
"260.28000","21.69027","0.04852"
"260.49600","21.70821","0.04846"
"260.71200","21.72620","0.04886"
"260.92800","21.74426","0.04886"
"261.14400","21.76219","0.04976"
"261.36000","21.78025","0.05003"
"261.57600","21.79819","0.05088"
"261.79200","21.81624","0.05073"
"262.00800","21.83424","0.05163"
"262.22400","21.85218","0.05204"
"262.44000","21.87023","0.05244"
"262.65600","21.88823","0.05271"
"262.87200","21.90623","0.05277"
"263.08800","21.92422","0.05318"
"263.30400","21.94216","0.05386"
"263.52000","21.96022","0.05385"
"263.73600","21.97821","0.05390"
"263.95200","21.99621","0.05447"
"264.16800","22.01427","0.05528"
"264.38400","22.03221","0.05535"
"264.60000","22.05026","0.05515"
"264.81600","22.06826","0.05563"
"265.03200","22.08625","0.05569"
"265.24800","22.10419","0.05633"
"265.46400","22.12219","0.05683"
"265.68000","22.14018","0.05664"
"265.89600","22.15818","0.05667"
"266.11200","22.17624","0.05703"
"266.32800","22.19423","0.05713"
"266.54400","22.21223","0.05780"
"266.76000","22.23022","0.05791"
"266.97600","22.24816","0.05836"
"267.19200","22.26628","0.05852"
"267.40800","22.28422","0.05914"
"267.62400","22.30221","0.05981"
"267.84000","22.32021","0.06073"
"268.05600","22.33821","0.06091"
"268.27200","22.35626","0.06116"
"268.48800","22.37426","0.06148"
"268.70400","22.39220","0.06146"
"268.92000","22.41025","0.06153"
"269.13600","22.42819","0.06156"
"269.35200","22.44625","0.06253"
"269.56800","22.46418","0.06380"
"269.78400","22.48218","0.06491"
"270.00000","22.50024","0.06539"
"270.21600","22.51817","0.06628"
"270.43200","22.53623","0.06741"
"270.64800","22.55429","0.06746"
"270.86400","22.57216","0.06823"
"271.08000","22.59028","0.06805"
"271.29600","22.60822","0.06863"
"271.51200","22.62627","0.06969"
"271.72800","22.64421","0.07025"
"271.94400","22.66221","0.07049"
"272.16000","22.68026","0.07156"
"272.37600","22.69820","0.07215"
"272.59200","22.71625","0.07290"
"272.80800","22.73425","0.07333"
"273.02400","22.75219","0.07436"
"273.24000","22.77024","0.07482"
"273.45600","22.78818","0.07113"
"273.67200","22.80624","0.07136"
"273.88800","22.82424","0.07140"
"274.10400","22.84217","0.07163"
"274.32000","22.86023","0.07185"
"274.53600","22.87823","0.07330"
"274.75200","22.89622","0.07387"
"274.96800","22.91422","0.07398"
"275.18400","22.93222","0.07415"
"275.40000","22.95027","0.07524"
"275.61600","22.96815","0.07483"
"275.83200","22.98627","0.07567"
"276.04800","23.00420","0.07645"
"276.26400","23.02220","0.07632"
"276.48000","23.04020","0.07638"
"276.69600","23.05819","0.07766"
"276.91200","23.07625","0.07763"
"277.12800","23.09418","0.07825"
"277.34400","23.11218","0.07788"
"277.56000","23.13024","0.07854"
"277.77600","23.14817","0.07845"
"277.99200","23.16623","0.07858"
"278.20800","23.18417","0.07881"
"278.42400","23.20217","0.07946"
"278.64000","23.22028","0.07995"
"278.85600","23.23816","0.08050"
"279.07200","23.25622","0.08041"
"279.28800","23.27421","0.08076"
"279.50400","23.29221","0.08088"
"279.72000","23.31027","0.08134"
"279.93600","23.32820","0.08141"
"280.15200","23.34620","0.08164"
"280.36800","23.36419","0.08166"
"280.58400","23.38219","0.08201"
"280.80000","23.40019","0.08207"
"281.01600","23.41818","0.08231"
"281.23200","23.43624","0.08245"
"281.44800","23.45418","0.08296"
"281.66400","23.47218","0.08321"
"281.88000","23.49023","0.08323"
"282.09600","23.50817","0.08357"
"282.31200","23.52622","0.08365"
"282.52800","23.54416","0.08338"
"282.74400","23.56222","0.08397"
"282.96000","23.58021","0.08404"
"283.17600","23.59821","0.08417"
"283.39200","23.61627","0.08472"
"283.60800","23.63420","0.08510"
"283.82400","23.65226","0.08587"
"284.04000","23.67020","0.08612"
"284.25600","23.68813","0.08684"
"284.47200","23.70625","0.08722"
"284.68800","23.72419","0.08745"
"284.90400","23.74224","0.08836"
"285.12000","23.76024","0.08847"
"285.33600","23.77824","0.08965"
"285.55200","23.79623","0.09076"
"285.76800","23.81423","0.09120"
"285.98400","23.83228","0.09178"
"286.20000","23.85016","0.09215"
"286.41600","23.86816","0.09363"
"286.63200","23.88622","0.09520"
"286.84800","23.90421","0.09606"
"287.06400","23.92221","0.09647"
"287.28000","23.94027","0.09731"
"287.49600","23.95814","0.09827"
"287.71200","23.97626","0.09942"
"287.92800","23.99420","0.10008"
"288.14400","24.01225","0.10066"
"288.36000","24.03025","0.10147"
"288.57600","24.04825","0.10163"
"288.79200","24.06618","0.10299"
"289.00800","24.08418","0.10324"
"289.22400","24.10224","0.10502"
"289.44000","24.12017","0.10549"
"289.65600","24.13817","0.10605"
"289.87200","24.15623","0.10597"
"290.08800","24.17416","0.10587"
"290.30400","24.19222","0.10673"
"290.52000","24.21022","0.10751"
"290.73600","24.22821","0.10691"
"290.95200","24.24621","0.10784"
"291.16800","24.26415","0.10769"
"291.38400","24.28220","0.10885"
"291.60000","24.30026","0.10878"
"291.81600","24.31820","0.10933"
"292.03200","24.33625","0.11044"
"292.24800","24.35419","0.11070"
"292.46400","24.37225","0.11181"
"292.68000","24.39024","0.11281"
"292.89600","24.40818","0.11310"
"293.11200","24.42624","0.11381"
"293.32800","24.44417","0.11453"
"293.54400","24.46223","0.11504"
"293.76000","24.48029","0.11541"
"293.97600","24.49816","0.11585"
"294.19200","24.51622","0.11700"
"294.40800","24.53422","0.11708"
"294.62400","24.55222","0.11610"
"294.84000","24.57021","0.11640"
"295.05600","24.58821","0.11722"
"295.27200","24.60620","0.11806"
"295.48800","24.62414","0.11820"
"295.70400","24.64220","0.11865"
"295.92000","24.66025","0.11924"
"296.13600","24.67813","0.11937"
"296.35200","24.69625","0.11969"
"296.56800","24.71418","0.12014"
"296.78400","24.73224","0.12050"
"297.00000","24.75023","0.12075"
"297.21600","24.76817","0.12115"
"297.43200","24.78623","0.12192"
"297.64800","24.80423","0.12194"
"297.86400","24.82222","0.12224"
"298.08000","24.84028","0.12322"
"298.29600","24.85822","0.12380"
"298.51200","24.87627","0.12426"
"298.72800","24.89421","0.12399"
"298.94400","24.91226","0.12453"
"299.16000","24.93020","0.12481"
"299.37600","24.94820","0.12566"
"299.59200","24.96620","0.12558"
"299.80800","24.98419","0.12622"
"300.02400","25.00225","0.12635"
"300.24000","25.02019","0.12726"
"300.45600","25.03818","0.12702"
"300.67200","25.05624","0.12754"
"300.88800","25.07417","0.12797"
"301.10400","25.09223","0.11694"
"301.32000","25.11023","0.11508"
"301.53600","25.12823","0.10665"
"301.75200","25.14622","0.10817"
"301.96800","25.16416","0.10857"
"302.18400","25.18221","0.11050"
"302.40000","25.20021","0.11110"
"302.61600","25.21821","0.11320"
"302.83200","25.23621","0.11247"
"303.04800","25.25420","0.11550"
"303.26400","25.27226","0.11310"
"303.48000","25.29020","0.11521"
"303.69600","25.30813","0.11477"
"303.91200","25.32625","0.11562"
"304.12800","25.34418","0.11434"
"304.34400","25.36224","0.11672"
"304.56000","25.38018","0.11639"
"304.77600","25.39824","0.11896"
"304.99200","25.41623","0.11582"
"305.20800","25.43417","0.11778"
"305.42400","25.45223","0.11807"
"305.64000","25.47022","0.11969"
"305.85600","25.48816","0.11969"
"306.07200","25.50622","0.12099"
"306.28800","25.52415","0.12170"
"306.50400","25.54221","0.12103"
"306.72000","25.56020","0.12196"
"306.93600","25.57820","0.12260"
"307.15200","25.59620","0.12391"
"307.36800","25.61426","0.12394"
"307.58400","25.63225","0.12492"
"307.80000","25.65025","0.12513"
"308.01600","25.66818","0.12644"
"308.23200","25.68624","0.12673"
"308.44800","25.70418","0.12738"
"308.66400","25.72223","0.12776"
"308.88000","25.74011","0.12842"
"309.09600","25.75823","0.12833"
"309.31200","25.77622","0.12878"
"309.52800","25.79416","0.12945"
"309.74400","25.81222","0.13039"
"309.96000","25.83021","0.13095"
"310.17600","25.84821","0.13123"
"310.39200","25.86627","0.13245"
"310.60800","25.88415","0.13273"
"310.82400","25.90226","0.13357"
"311.04000","25.92014","0.13397"
"311.25600","25.93826","0.13508"
"311.47200","25.95619","0.13475"
"311.68800","25.97419","0.13581"
"311.90400","25.99224","0.13570"
"312.12000","26.01024","0.13736"
"312.33600","26.02818","0.13807"
"312.55200","26.04630","0.14002"
"312.76800","26.06417","0.14149"
"312.98400","26.08223","0.14265"
"313.20000","26.10017","0.14472"
"313.41600","26.11822","0.14574"
"313.63200","26.13622","0.14846"
"313.84800","26.15416","0.14832"
"314.06400","26.17221","0.15142"
"314.28000","26.19021","0.15305"
"314.49600","26.20820","0.15591"
"314.71200","26.22626","0.15733"
"314.92800","26.24414","0.16065"
"315.14400","26.26225","0.16245"
"315.36000","26.28019","0.16441"
"315.57600","26.29825","0.16664"
"315.79200","26.31618","0.16903"
"315.92800","26.32754","0.17125"