File: Force_trajectories/170212_2/Specimen_RawData_6.csv
End date,"2/12/2017"
Specimen label,"9CG_76"
Maximum Load,"0.71948",N

Time,Extension,Load
(s),(mm),(N)
"0.00000","14.42925","0.01766"
"0.27600","14.45137","0.01840"
"0.55200","14.47552","0.01969"
"0.82800","14.49842","0.01940"
"1.10400","14.52144","0.01977"
"1.38000","14.54440","0.02040"
"1.65600","14.56748","0.02006"
"1.93200","14.59044","0.02064"
"2.20800","14.61352","0.02016"
"2.48400","14.63642","0.02147"
"2.76000","14.65944","0.02146"
"3.03600","14.68240","0.02222"
"3.31200","14.70548","0.02075"
"3.58800","14.72843","0.02156"
"3.86400","14.75145","0.02191"
"4.14000","14.77435","0.02182"
"4.41600","14.79743","0.02196"
"4.69200","14.82039","0.02214"
"4.96800","14.84347","0.02197"
"5.24400","14.86643","0.02303"
"5.52000","14.88951","0.02291"
"5.79600","14.91247","0.02272"
"6.07200","14.93548","0.02337"
"6.34800","14.95839","0.02356"
"6.62400","14.98146","0.02355"
"6.90000","15.00448","0.02304"
"7.17600","15.02750","0.02366"
"7.45200","15.05040","0.02406"
"7.72800","15.07342","0.02389"
"8.00400","15.09644","0.02401"
"8.28000","15.11946","0.02394"
"8.55600","15.14248","0.02402"
"8.83200","15.16550","0.02419"
"9.10800","15.18846","0.02501"
"9.38400","15.21147","0.02474"
"9.66000","15.23449","0.02422"
"9.93600","15.25739","0.02469"
"10.21200","15.28047","0.02508"
"10.48800","15.30343","0.02502"
"10.76400","15.32645","0.02531"
"11.04000","15.34941","0.02512"
"11.31600","15.37249","0.02493"
"11.59200","15.39545","0.02469"
"11.86800","15.41852","0.02598"
"12.14400","15.44143","0.02570"
"12.42000","15.46450","0.02588"
"12.69600","15.48740","0.02578"
"12.97200","15.51054","0.02639"
"13.24800","15.53338","0.02679"
"13.52400","15.55646","0.02594"
"13.80000","15.57942","0.02627"
"14.07600","15.60244","0.02638"
"14.35200","15.62540","0.02638"
"14.62800","15.64853","0.02604"
"14.90400","15.67143","0.02749"
"15.18000","15.69445","0.02676"
"15.45600","15.71741","0.02692"
"15.73200","15.74049","0.02726"
"16.00800","15.76345","0.02663"
"16.28400","15.78647","0.02655"
"16.56000","15.80943","0.02738"
"16.83600","15.83245","0.02709"
"17.11200","15.85541","0.02736"
"17.38800","15.87843","0.02727"
"17.66400","15.90139","0.02748"
"17.94000","15.92446","0.02780"
"18.21600","15.94742","0.02775"
"18.49200","15.97044","0.02719"
"18.76800","15.99340","0.02745"
"19.04400","16.01636","0.02681"
"19.32000","16.03944","0.02795"
"19.59600","16.06252","0.02699"
"19.87200","16.08548","0.02798"
"20.14800","16.10850","0.02787"
"20.42400","16.13152","0.02779"
"20.70000","16.15441","0.02768"
"20.97600","16.17743","0.02825"
"21.25200","16.20039","0.02840"
"21.52800","16.22347","0.02860"
"21.80400","16.24637","0.02828"
"22.08000","16.26951","0.02872"
"22.35600","16.29241","0.02920"
"22.63200","16.31549","0.02858"
"22.90800","16.33845","0.02860"
"23.18400","16.36147","0.02905"
"23.46000","16.38437","0.02932"
"23.73600","16.40744","0.02919"
"24.01200","16.43040","0.02905"
"24.28800","16.45348","0.02946"
"24.56400","16.47638","0.02907"
"24.84000","16.49940","0.02939"
"25.11600","16.52236","0.02951"
"25.39200","16.54544","0.02971"
"25.66800","16.56840","0.02977"
"25.94400","16.59142","0.02964"
"26.22000","16.61444","0.02932"
"26.49600","16.63745","0.02992"
"26.77200","16.66047","0.03030"
"27.04800","16.68343","0.02995"
"27.32400","16.70645","0.03016"
"27.60000","16.72947","0.03012"
"27.87600","16.75243","0.03018"
"28.15200","16.77545","0.03041"
"28.42800","16.79841","0.03067"
"28.70400","16.82142","0.03076"
"28.98000","16.84445","0.03003"
"29.25600","16.86746","0.03098"
"29.53200","16.89048","0.03066"
"29.80800","16.91344","0.03042"
"30.08400","16.93646","0.03039"
"30.36000","16.95948","0.03071"
"30.63600","16.98250","0.03092"
"30.91200","17.00552","0.03124"
"31.18800","17.02842","0.03101"
"31.46400","17.05144","0.03072"
"31.74000","17.07439","0.03107"
"32.01600","17.09742","0.03089"
"32.29200","17.12049","0.03128"
"32.56800","17.14345","0.03157"
"32.84400","17.16647","0.03158"
"33.12000","17.18937","0.03104"
"33.39600","17.21245","0.03132"
"33.67200","17.23541","0.03169"
"33.94800","17.25849","0.03163"
"34.22400","17.28145","0.03120"
"34.50000","17.30446","0.03104"
"34.77600","17.32743","0.03166"
"35.05200","17.35044","0.03108"
"35.32800","17.37340","0.03121"
"35.60400","17.39648","0.03112"
"35.88000","17.41938","0.03149"
"36.15600","17.44240","0.03074"
"36.43200","17.46536","0.03060"
"36.70800","17.48844","0.03134"
"36.98400","17.51140","0.03143"
"37.26000","17.53448","0.03164"
"37.53600","17.55743","0.03205"
"37.81200","17.58046","0.03169"
"38.08800","17.60347","0.03208"
"38.36400","17.62649","0.03231"
"38.64000","17.64939","0.03217"
"38.91600","17.67247","0.03191"
"39.19200","17.69543","0.03201"
"39.46800","17.71845","0.03276"
"39.74400","17.74141","0.03213"
"40.02000","17.76443","0.03224"
"40.29600","17.78745","0.03305"
"40.57200","17.81046","0.03243"
"40.84800","17.83348","0.03251"
"41.12400","17.85644","0.03296"
"41.40000","17.87946","0.03316"
"41.67600","17.90248","0.03330"
"41.95200","17.92544","0.03336"
"42.22800","17.94846","0.03290"
"42.50400","17.97148","0.03332"
"42.78000","17.99444","0.03330"
"43.05600","18.01746","0.03301"
"43.33200","18.04047","0.03380"
"43.60800","18.06350","0.03378"
"43.88400","18.08639","0.03344"
"44.16000","18.10947","0.03378"
"44.43600","18.13243","0.03316"
"44.71200","18.15545","0.03351"
"44.98800","18.17847","0.03434"
"45.26400","18.20149","0.03431"
"45.54000","18.22445","0.03395"
"45.81600","18.24747","0.03377"
"46.09200","18.27037","0.03447"
"46.36800","18.29344","0.03465"
"46.64400","18.31640","0.03546"
"46.92000","18.33948","0.03462"
"47.19600","18.36244","0.03491"
"47.47200","18.38546","0.03510"
"47.74800","18.40836","0.03526"
"48.02400","18.43150","0.03497"
"48.30000","18.45440","0.03543"
"48.57600","18.47748","0.03497"
"48.85200","18.50044","0.03525"
"49.12800","18.52351","0.03566"
"49.40400","18.54641","0.03536"
"49.68000","18.56943","0.03600"
"49.95600","18.59239","0.03533"
"50.23200","18.61547","0.03588"
"50.50800","18.63849","0.03598"
"50.78400","18.66151","0.03587"
"51.06000","18.68447","0.03616"
"51.33600","18.70743","0.03650"
"51.61200","18.73045","0.03658"
"51.88800","18.75347","0.03619"
"52.16400","18.77642","0.03661"
"52.44000","18.79950","0.03658"
"52.71600","18.82246","0.03638"
"52.99200","18.84542","0.03683"
"53.26800","18.86844","0.03681"
"53.54400","18.89140","0.03643"
"53.82000","18.91442","0.03654"
"54.09600","18.93738","0.03656"
"54.37200","18.96046","0.03669"
"54.64800","18.98342","0.03682"
"54.92400","19.00649","0.03643"
"55.20000","19.02939","0.03702"
"55.47600","19.05247","0.03706"
"55.75200","19.07543","0.03722"
"56.02800","19.09851","0.03701"
"56.30400","19.12141","0.03766"
"56.58000","19.14449","0.03720"
"56.85600","19.16745","0.03759"
"57.13200","19.19041","0.03754"
"57.40800","19.21337","0.03794"
"57.68400","19.23645","0.03758"
"57.96000","19.25941","0.03788"
"58.23600","19.28248","0.03811"
"58.51200","19.30538","0.03794"
"58.78800","19.32852","0.03815"
"59.06400","19.35148","0.03856"
"59.34000","19.37450","0.03800"
"59.61600","19.39740","0.03786"
"59.89200","19.42048","0.03824"
"60.16800","19.44344","0.03830"
"60.44400","19.46646","0.03841"
"60.72000","19.48941","0.03819"
"60.99600","19.51243","0.03854"
"61.27200","19.53545","0.03845"
"61.54800","19.55841","0.03862"
"61.82400","19.58143","0.03849"
"62.10000","19.60439","0.03881"
"62.37600","19.62747","0.03910"
"62.65200","19.65049","0.03892"
"62.92800","19.67351","0.03915"
"63.20400","19.69647","0.03938"
"63.48000","19.71948","0.03936"
"63.75600","19.74244","0.03953"
"64.03200","19.76546","0.03912"
"64.30800","19.78842","0.03961"
"64.58400","19.81144","0.03936"
"64.86000","19.83440","0.03967"
"65.13600","19.85748","0.03964"
"65.41200","19.88038","0.03972"
"65.68800","19.90346","0.03991"
"65.96400","19.92641","0.03967"
"66.24000","19.94950","0.03977"
"66.51600","19.97239","0.03995"
"66.79200","19.99553","0.03978"
"67.06800","20.01843","0.03987"
"67.34400","20.04145","0.04026"
"67.62000","20.06441","0.04020"
"67.89600","20.08743","0.04029"
"68.17200","20.11039","0.04019"
"68.44800","20.13341","0.03996"
"68.72400","20.15636","0.04038"
"69.00000","20.17945","0.04041"
"69.27600","20.20241","0.04011"
"69.55200","20.22548","0.04031"
"69.82800","20.24838","0.04066"
"70.10400","20.27146","0.04060"
"70.38000","20.29448","0.04062"
"70.65600","20.31744","0.04068"
"70.93200","20.34046","0.04118"
"71.20800","20.36342","0.04088"
"71.48400","20.38644","0.04107"
"71.76000","20.40945","0.04112"
"72.03600","20.43242","0.04096"
"72.31200","20.45543","0.04114"
"72.58800","20.47845","0.04122"
"72.86400","20.50147","0.04128"
"73.14000","20.52449","0.04130"
"73.41600","20.54745","0.04158"
"73.69200","20.57053","0.04165"
"73.96800","20.59349","0.04155"
"74.24400","20.61650","0.04146"
"74.52000","20.63940","0.04168"
"74.79600","20.66243","0.04204"
"75.07200","20.68545","0.04190"
"75.34800","20.70846","0.04213"
"75.62400","20.73142","0.04203"
"75.90000","20.75444","0.04231"
"76.17600","20.77740","0.04214"
"76.45200","20.80048","0.04229"
"76.72800","20.82344","0.04211"
"77.00400","20.84646","0.04232"
"77.28000","20.86942","0.04182"
"77.55600","20.89249","0.04093"
"77.83200","20.91546","0.04099"
"78.10800","20.93847","0.04097"
"78.38400","20.96143","0.04102"
"78.66000","20.98445","0.04146"
"78.93600","21.00741","0.04123"
"79.21200","21.03049","0.03841"
"79.48800","21.05345","0.03876"
"79.76400","21.07647","0.03883"
"80.04000","21.09937","0.03930"
"80.31600","21.12244","0.03872"
"80.59200","21.14546","0.03900"
"80.86800","21.16842","0.03910"
"81.14400","21.19144","0.03967"
"81.42000","21.21452","0.03915"
"81.69600","21.23742","0.03969"
"81.97200","21.26050","0.03975"
"82.24800","21.28340","0.03977"
"82.52400","21.30648","0.03988"
"82.80000","21.32944","0.03989"
"83.07600","21.35246","0.04015"
"83.35200","21.37542","0.04004"
"83.62800","21.39843","0.04003"
"83.90400","21.42146","0.04008"
"84.18000","21.44447","0.04039"
"84.45600","21.46749","0.04005"
"84.73200","21.49045","0.04010"
"85.00800","21.51347","0.04039"
"85.28400","21.53643","0.04019"
"85.56000","21.55945","0.04044"
"85.83600","21.58241","0.04032"
"86.11200","21.60543","0.04045"
"86.38800","21.62844","0.04062"
"86.66400","21.65153","0.04052"
"86.94000","21.67448","0.04087"
"87.21600","21.69750","0.04055"
"87.49200","21.72040","0.04062"
"87.76800","21.74348","0.04095"
"88.04400","21.76638","0.04079"
"88.32000","21.78946","0.04088"
"88.59600","21.81242","0.04106"
"88.87200","21.83544","0.04125"
"89.14800","21.85839","0.04120"
"89.42400","21.88141","0.04132"
"89.70000","21.90437","0.04136"
"89.97600","21.92745","0.04133"
"90.25200","21.95035","0.04157"
"90.52800","21.97349","0.04162"
"90.80400","21.99639","0.04142"
"91.08000","22.01947","0.04116"
"91.35600","22.04243","0.04136"
"91.63200","22.06544","0.04152"
"91.90800","22.08841","0.04155"
"92.18400","22.11143","0.04168"
"92.46000","22.13444","0.04176"
"92.73600","22.15746","0.04166"
"93.01200","22.18042","0.04132"
"93.28800","22.20344","0.04194"
"93.56400","22.22640","0.04185"
"93.84000","22.24942","0.04156"
"94.11600","22.27244","0.04226"
"94.39200","22.29546","0.04192"
"94.66800","22.31848","0.04229"
"94.94400","22.34150","0.04216"
"95.22000","22.36445","0.04225"
"95.49600","22.38747","0.04216"
"95.77200","22.41043","0.04179"
"96.04800","22.43345","0.04176"
"96.32400","22.45647","0.04167"
"96.60000","22.47943","0.04201"
"96.87600","22.50245","0.04203"
"97.15200","22.52535","0.04209"
"97.42800","22.54843","0.04198"
"97.70400","22.57139","0.04181"
"97.98000","22.59447","0.04213"
"98.25600","22.61736","0.04227"
"98.53200","22.64044","0.04236"
"98.80800","22.66340","0.04205"
"99.08400","22.68654","0.04226"
"99.36000","22.70938","0.04194"
"99.63600","22.73246","0.04194"
"99.91200","22.75542","0.04173"
"100.18800","22.77844","0.04187"
"100.46400","22.80140","0.04203"
"100.74000","22.82447","0.04213"
"101.01600","22.84737","0.04225"
"101.29200","22.87045","0.04218"
"101.56800","22.89341","0.04242"
"101.84400","22.91649","0.04252"
"102.12000","22.93945","0.04250"
"102.39600","22.96247","0.04275"
"102.67200","22.98549","0.04322"
"102.94800","23.00845","0.04297"
"103.22400","23.03141","0.04247"
"103.50000","23.05443","0.04272"
"103.77600","23.07745","0.04242"
"104.05200","23.10046","0.04236"
"104.32800","23.12348","0.04274"
"104.60400","23.14638","0.04256"
"104.88000","23.16940","0.04221"
"105.15600","23.19242","0.04226"
"105.43200","23.21544","0.04219"
"105.70800","23.23846","0.04215"
"105.98400","23.26154","0.04232"
"106.26000","23.28450","0.04253"
"106.53600","23.30751","0.04286"
"106.81200","23.33041","0.04285"
"107.08800","23.35349","0.04283"
"107.36400","23.37645","0.04324"
"107.64000","23.39947","0.04320"
"107.91600","23.42243","0.04352"
"108.19200","23.44545","0.04356"
"108.46800","23.46841","0.04340"
"108.74400","23.49143","0.04303"
"109.02000","23.51439","0.04331"
"109.29600","23.53746","0.04344"
"109.57200","23.56037","0.04363"
"109.84800","23.58350","0.04385"
"110.12400","23.60646","0.04410"
"110.40000","23.62948","0.04423"
"110.67600","23.65244","0.04464"
"110.95200","23.67546","0.04395"
"111.22800","23.69836","0.04385"
"111.50400","23.72144","0.04378"
"111.78000","23.74439","0.04364"
"112.05600","23.76748","0.04442"
"112.33200","23.79043","0.04430"
"112.60800","23.81351","0.04359"
"112.88400","23.83641","0.04326"
"113.16000","23.85943","0.04350"
"113.43600","23.88245","0.04370"
"113.71200","23.90547","0.04358"
"113.98800","23.92843","0.04368"
"114.26400","23.95151","0.04407"
"114.54000","23.97447","0.04423"
"114.81600","23.99743","0.04476"
"115.09200","24.02045","0.04441"
"115.36800","24.04352","0.04461"
"115.64400","24.06648","0.04478"
"115.92000","24.08944","0.04487"
"116.19600","24.11246","0.04475"
"116.47200","24.13542","0.04504"
"116.74800","24.15850","0.04555"
"117.02400","24.18146","0.04533"
"117.30000","24.20448","0.04508"
"117.57600","24.22738","0.04583"
"117.85200","24.25046","0.04552"
"118.12800","24.27341","0.04559"
"118.40400","24.29643","0.04622"
"118.68000","24.31945","0.04594"
"118.95600","24.34247","0.04617"
"119.23200","24.36543","0.04658"
"119.50800","24.38845","0.04679"
"119.78400","24.41141","0.04699"
"120.06000","24.43443","0.04699"
"120.33600","24.45739","0.04737"
"120.61200","24.48046","0.04798"
"120.88800","24.50343","0.04800"
"121.16400","24.52645","0.04843"
"121.44000","24.54940","0.04795"
"121.71600","24.57242","0.04814"
"121.99200","24.59538","0.04860"
"122.26800","24.61840","0.04870"
"122.54400","24.64142","0.04934"
"122.82000","24.66444","0.04879"
"123.09600","24.68740","0.04955"
"123.37200","24.71047","0.05024"
"123.64800","24.73343","0.05015"
"123.92400","24.75640","0.05018"
"124.20000","24.77941","0.05100"
"124.47600","24.80249","0.05097"
"124.75200","24.82545","0.05104"
"125.02800","24.84847","0.05152"
"125.30400","24.87143","0.05193"
"125.58000","24.89445","0.05217"
"125.85600","24.91741","0.05238"
"126.13200","24.94043","0.05274"
"126.40800","24.96338","0.05319"
"126.68400","24.98640","0.05316"
"126.96000","25.00942","0.05345"
"127.23600","25.03238","0.05431"
"127.51200","25.05546","0.05501"
"127.78800","25.07848","0.05506"
"128.06400","25.10144","0.05516"
"128.34000","25.12440","0.05627"
"128.61600","25.14748","0.05478"
"128.89200","25.17044","0.05516"
"129.16800","25.19346","0.05618"
"129.44400","25.21642","0.05599"
"129.72000","25.23943","0.05634"
"129.99600","25.26245","0.05658"
"130.27200","25.28547","0.05723"
"130.54800","25.30843","0.05638"
"130.82400","25.33145","0.05701"
"131.10000","25.35441","0.05750"
"131.37600","25.37749","0.05779"
"131.65200","25.40039","0.05885"
"131.92800","25.42341","0.05772"
"132.20400","25.44637","0.05816"
"132.48000","25.46944","0.05812"
"132.75600","25.49234","0.05712"
"133.03200","25.51548","0.05718"
"133.30800","25.53838","0.05545"
"133.58400","25.56146","0.05615"
"133.86000","25.58436","0.05712"
"134.13600","25.60744","0.05815"
"134.41200","25.63040","0.05916"
"134.68800","25.65348","0.06007"
"134.96400","25.67644","0.06108"
"135.24000","25.69946","0.06132"
"135.51600","25.72247","0.06142"
"135.79200","25.74543","0.06158"
"136.06800","25.76845","0.06204"
"136.34400","25.79147","0.06374"
"136.62000","25.81443","0.06343"
"136.89600","25.83739","0.06426"
"137.17200","25.86041","0.06383"
"137.44800","25.88343","0.06401"
"137.72400","25.90651","0.06357"
"138.00000","25.92946","0.06344"
"138.27600","25.95248","0.06381"
"138.55200","25.97544","0.06447"
"138.82800","25.99852","0.06462"
"139.10400","26.02142","0.06473"
"139.38000","26.04450","0.06511"
"139.65600","26.06746","0.06553"
"139.93200","26.09048","0.06611"
"140.20800","26.11338","0.06602"
"140.48400","26.13646","0.06630"
"140.76000","26.15942","0.06631"
"141.03600","26.18244","0.06612"
"141.31200","26.20539","0.06675"
"141.58800","26.22841","0.06657"
"141.86400","26.25143","0.06697"
"142.14000","26.27451","0.06779"
"142.41600","26.29741","0.06785"
"142.69200","26.32049","0.06868"
"142.96800","26.34345","0.06832"
"143.24400","26.36647","0.06907"
"143.52000","26.38937","0.06915"
"143.79600","26.41250","0.07009"
"144.07200","26.43546","0.07011"
"144.34800","26.45848","0.06995"
"144.62400","26.48138","0.07069"
"144.90000","26.50446","0.07130"
"145.17600","26.52742","0.07192"
"145.45200","26.55044","0.07264"
"145.72800","26.57346","0.07264"
"146.00400","26.59648","0.07261"
"146.28000","26.61944","0.07288"
"146.55600","26.64246","0.07340"
"146.83200","26.66541","0.07403"
"147.10800","26.68843","0.07378"
"147.38400","26.71145","0.07387"
"147.66000","26.73441","0.07485"
"147.93600","26.75743","0.07462"
"148.21200","26.78039","0.07523"
"148.48800","26.80347","0.07608"
"148.76400","26.82643","0.07617"
"149.04000","26.84945","0.07675"
"149.31600","26.87247","0.07693"
"149.59200","26.89548","0.07729"
"149.86800","26.91845","0.07685"
"150.14400","26.94152","0.07792"
"150.42000","26.96442","0.07838"
"150.69600","26.98750","0.07849"
"150.97200","27.01040","0.07849"
"151.24800","27.03348","0.07898"
"151.52400","27.05638","0.08033"
"151.80000","27.07946","0.08009"
"152.07600","27.10242","0.08027"
"152.35200","27.12544","0.08064"
"152.62800","27.14840","0.08084"
"152.90400","27.17147","0.08135"
"153.18000","27.19443","0.08149"
"153.45600","27.21751","0.08264"
"153.73200","27.24041","0.08318"
"154.00800","27.26343","0.08260"
"154.28400","27.28639","0.08305"
"154.56000","27.30941","0.08258"
"154.83600","27.33237","0.08371"
"155.11200","27.35550","0.08450"
"155.38800","27.37846","0.08495"
"155.66400","27.40149","0.08444"
"155.94000","27.42438","0.08508"
"156.21600","27.44740","0.08608"
"156.49200","27.47042","0.08494"
"156.76800","27.49344","0.08623"
"157.04400","27.51646","0.08554"
"157.32000","27.53948","0.08588"
"157.59600","27.56250","0.08675"
"157.87200","27.58546","0.08717"
"158.14800","27.60842","0.08725"
"158.42400","27.63137","0.08804"
"158.70000","27.65445","0.08867"
"158.97600","27.67747","0.08880"
"159.25200","27.70049","0.08936"
"159.52800","27.72345","0.08918"
"159.80400","27.74647","0.08967"
"160.08000","27.76943","0.08943"
"160.35600","27.79245","0.09004"
"160.63200","27.81540","0.09004"
"160.90800","27.83849","0.09017"
"161.18400","27.86145","0.09064"
"161.46000","27.88446","0.09058"
"161.73600","27.90742","0.09081"
"162.01200","27.93044","0.09075"
"162.28800","27.95340","0.09106"
"162.56400","27.97642","0.09152"
"162.84000","27.99938","0.09167"
"163.11600","28.02246","0.09173"
"163.39200","28.04548","0.09182"
"163.66800","28.06850","0.09160"
"163.94400","28.09139","0.09182"
"164.22000","28.11448","0.09209"
"164.49600","28.13737","0.09205"
"164.77200","28.16045","0.09209"
"165.04800","28.18335","0.09257"
"165.32400","28.20643","0.09311"
"165.60000","28.22939","0.09331"
"165.87600","28.25247","0.09289"
"166.15200","28.27543","0.09426"
"166.42800","28.29844","0.09365"
"166.70400","28.32146","0.09486"
"166.98000","28.34443","0.09434"
"167.25600","28.36750","0.09335"
"167.53200","28.39052","0.09332"
"167.80800","28.41348","0.09324"
"168.08400","28.43644","0.09342"
"168.36000","28.45946","0.09426"
"168.63600","28.48242","0.09443"
"168.91200","28.50538","0.09496"
"169.18800","28.52840","0.09478"
"169.46400","28.55142","0.09646"
"169.74000","28.57443","0.09769"
"170.01600","28.59745","0.09934"
"170.29200","28.62041","0.10038"
"170.56800","28.64343","0.10290"
"170.84400","28.66645","0.10361"
"171.12000","28.68947","0.10514"
"171.39600","28.71243","0.10708"
"171.67200","28.73545","0.10913"
"171.94800","28.75841","0.11010"
"172.22400","28.78143","0.11122"
"172.50000","28.80445","0.11204"
"172.77600","28.82747","0.11350"
"173.05200","28.85043","0.11394"
"173.32800","28.87344","0.11460"
"173.60400","28.89640","0.11444"
"173.88000","28.91942","0.11575"
"174.15600","28.94244","0.11704"
"174.43200","28.96552","0.11750"
"174.70800","28.98842","0.11874"
"174.98400","29.01144","0.11903"
"175.26000","29.03440","0.11923"
"175.53600","29.05741","0.11851"
"175.81200","29.08037","0.11898"
"176.08800","29.10345","0.11962"
"176.36400","29.12641","0.12105"
"176.64000","29.14943","0.12221"
"176.91600","29.17239","0.12260"
"177.19200","29.19547","0.12193"
"177.46800","29.21843","0.12241"
"177.74400","29.24145","0.12367"
"178.02000","29.26441","0.12432"
"178.29600","29.28749","0.12506"
"178.57200","29.31044","0.12566"
"178.84800","29.33347","0.12615"
"179.12400","29.35642","0.12642"
"179.40000","29.37944","0.12685"
"179.67600","29.40246","0.12789"
"179.95200","29.42548","0.12804"
"180.22800","29.44844","0.12883"
"180.50400","29.47146","0.12918"
"180.78000","29.49448","0.13037"
"181.05600","29.51744","0.13054"
"181.33200","29.54051","0.13090"
"181.60800","29.56347","0.13195"
"181.88400","29.58649","0.13241"
"182.16000","29.60945","0.13325"
"182.43600","29.63247","0.13393"
"182.71200","29.65543","0.13340"
"182.98800","29.67845","0.13437"
"183.26400","29.70141","0.13490"
"183.54000","29.72449","0.13552"
"183.81600","29.74739","0.13580"
"184.09200","29.77046","0.13609"
"184.36800","29.79336","0.13662"
"184.64400","29.81644","0.13679"
"184.92000","29.83940","0.13742"
"185.19600","29.86248","0.13765"
"185.47200","29.88538","0.13833"
"185.74800","29.90846","0.13834"
"186.02400","29.93142","0.13880"
"186.30000","29.95450","0.13959"
"186.57600","29.97740","0.14019"
"186.85200","30.00047","0.14057"
"187.12800","30.02344","0.14140"
"187.40400","30.04651","0.14169"
"187.68000","30.06947","0.14199"
"187.95600","30.09249","0.14279"
"188.23200","30.11539","0.14343"
"188.50800","30.13847","0.14378"
"188.78400","30.16143","0.14421"
"189.06000","30.18445","0.14588"
"189.33600","30.20741","0.14671"
"189.61200","30.23049","0.14767"
"189.88800","30.25345","0.14744"
"190.16400","30.27640","0.14850"
"190.44000","30.29942","0.14961"
"190.71600","30.32238","0.15176"
"190.99200","30.34540","0.15301"
"191.26800","30.36842","0.15274"
"191.54400","30.39144","0.15508"
"191.82000","30.41440","0.15807"
"192.09600","30.43748","0.15950"
"192.37200","30.46044","0.16264"
"192.64800","30.48351","0.16529"
"192.92400","30.50641","0.16702"
"193.20000","30.52949","0.17044"
"193.47600","30.55245","0.17257"
"193.75200","30.57547","0.17281"
"194.02800","30.59837","0.17341"
"194.30400","30.62145","0.17044"
"194.58000","30.64441","0.17219"
"194.85600","30.66743","0.17199"
"195.13200","30.69039","0.17433"
"195.40800","30.71346","0.17827"
"195.68400","30.73636","0.18126"
"195.96000","30.75950","0.18515"
"196.23600","30.78240","0.18840"
"196.51200","30.80548","0.19037"
"196.78800","30.82844","0.19236"
"197.06400","30.85146","0.19359"
"197.34000","30.87442","0.19438"
"197.61600","30.89744","0.19531"
"197.89200","30.92034","0.19596"
"198.16800","30.94342","0.19659"
"198.44400","30.96644","0.19711"
"198.72000","30.98945","0.19783"
"198.99600","31.01241","0.19895"
"199.27200","31.03543","0.20012"
"199.54800","31.05845","0.20143"
"199.82400","31.08147","0.20231"
"200.10000","31.10443","0.20467"
"200.37600","31.12745","0.20637"
"200.65200","31.15047","0.20857"
"200.92800","31.17343","0.21087"
"201.20400","31.19645","0.21298"
"201.48000","31.21940","0.21557"
"201.75600","31.24248","0.21735"
"202.03200","31.26544","0.21971"
"202.30800","31.28846","0.22086"
"202.58400","31.31142","0.22305"
"202.86000","31.33450","0.22467"
"203.13600","31.35746","0.22688"
"203.41200","31.38047","0.22880"
"203.68800","31.40337","0.23068"
"203.96400","31.42646","0.23242"
"204.24000","31.44942","0.23380"
"204.51600","31.47243","0.23433"
"204.79200","31.49545","0.23563"
"205.06800","31.51847","0.23674"
"205.34400","31.54137","0.23803"
"205.62000","31.56439","0.23860"
"205.89600","31.58741","0.23969"
"206.17200","31.61049","0.24013"
"206.44800","31.63338","0.24121"
"206.72400","31.65646","0.24179"
"207.00000","31.67943","0.24250"
"207.27600","31.70250","0.24317"
"207.55200","31.72540","0.24370"
"207.82800","31.74842","0.24453"
"208.10400","31.77138","0.24522"
"208.38000","31.79446","0.24599"
"208.65600","31.81742","0.24681"
"208.93200","31.84044","0.24766"
"209.20800","31.86340","0.24869"
"209.48400","31.88647","0.25005"
"209.76000","31.90943","0.25198"
"210.03600","31.93246","0.25348"
"210.31200","31.95547","0.25561"
"210.58800","31.97849","0.25786"
"210.86400","32.00145","0.26047"
"211.14000","32.02453","0.26240"
"211.41600","32.04749","0.26529"
"211.69200","32.07045","0.26669"
"211.96800","32.09341","0.26879"
"212.24400","32.11642","0.27038"
"212.52000","32.13944","0.27208"
"212.79600","32.16240","0.27385"
"213.07200","32.18548","0.27604"
"213.34800","32.20844","0.27884"
"213.62400","32.23146","0.28042"
"213.90000","32.25442","0.28248"
"214.17600","32.27750","0.28476"
"214.45200","32.30040","0.28640"
"214.72800","32.32347","0.28739"
"215.00400","32.34644","0.28825"
"215.28000","32.36945","0.28933"
"215.55600","32.39241","0.29041"
"215.83200","32.41549","0.29101"
"216.10800","32.43845","0.29223"
"216.38400","32.46147","0.29347"
"216.66000","32.48437","0.29525"
"216.93600","32.50745","0.29802"
"217.21200","32.53041","0.30187"
"217.48800","32.55343","0.29228"
"217.76400","32.57639","0.29194"
"218.04000","32.59946","0.29316"
"218.31600","32.62242","0.29455"
"218.59200","32.64550","0.29659"
"218.86800","32.66840","0.30001"
"219.14400","32.69148","0.30223"
"219.42000","32.71438","0.30595"
"219.69600","32.73746","0.30982"
"219.97200","32.76042","0.31523"
"220.24800","32.78344","0.31810"
"220.52400","32.80640","0.32181"
"220.80000","32.82948","0.32501"
"221.07600","32.85243","0.33047"
"221.35200","32.87545","0.33459"
"221.62800","32.89847","0.33848"
"221.90400","32.92149","0.34137"
"222.18000","32.94445","0.34401"
"222.45600","32.96747","0.34611"
"222.73200","32.99043","0.34772"
"223.00800","33.01339","0.34874"
"223.28400","33.03641","0.34945"
"223.56000","33.05943","0.34995"
"223.83600","33.08244","0.35044"
"224.11200","33.10546","0.35097"
"224.38800","33.12842","0.35143"
"224.66400","33.15138","0.35233"
"224.94000","33.17446","0.35324"
"225.21600","33.19742","0.35451"
"225.49200","33.22050","0.35587"
"225.76800","33.24346","0.35772"
"226.04400","33.26648","0.35904"
"226.32000","33.28938","0.36141"
"226.59600","33.31240","0.36317"
"226.87200","33.33535","0.36539"
"227.14800","33.35843","0.36678"
"227.42400","33.38139","0.36959"
"227.70000","33.40447","0.37248"
"227.97600","33.42743","0.37514"
"228.25200","33.45051","0.37899"
"228.52800","33.47341","0.38269"
"228.80400","33.49649","0.38614"
"229.08000","33.51939","0.38937"
"229.35600","33.54247","0.39261"
"229.63200","33.56543","0.37475"
"229.90800","33.58850","0.38163"
"230.18400","33.61140","0.38792"
"230.46000","33.63448","0.39342"
"230.73600","33.65738","0.39602"
"231.01200","33.68052","0.39811"
"231.28800","33.70342","0.39949"
"231.56400","33.72644","0.39962"
"231.84000","33.74946","0.40022"
"232.11600","33.77248","0.40057"
"232.39200","33.79544","0.40125"
"232.66800","33.81839","0.40338"
"232.94400","33.84141","0.40592"
"233.22000","33.86443","0.40900"
"233.49600","33.88745","0.41214"
"233.77200","33.91041","0.41513"
"234.04800","33.93343","0.41840"
"234.32400","33.95639","0.42150"
"234.60000","33.97947","0.42508"
"234.87600","34.00243","0.42734"
"235.15200","34.02551","0.42975"
"235.42800","34.04840","0.43145"
"235.70400","34.07148","0.43378"
"235.98000","34.09444","0.43545"
"236.25600","34.11746","0.43644"
"236.53200","34.14042","0.43781"
"236.80800","34.16350","0.43900"
"237.08400","34.18640","0.44050"
"237.36000","34.20948","0.44236"
"237.63600","34.23238","0.44478"
"237.91200","34.25546","0.44731"
"238.18800","34.27842","0.44966"
"238.46400","34.30149","0.45258"
"238.74000","34.32439","0.45423"
"239.01600","34.34747","0.45670"
"239.29200","34.37043","0.45851"
"239.56800","34.39351","0.45971"
"239.84400","34.41647","0.46314"
"240.12000","34.43949","0.46620"
"240.39600","34.46239","0.46924"
"240.67200","34.48547","0.47321"
"240.94800","34.50843","0.47542"
"241.22400","34.53138","0.47958"
"241.50000","34.55440","0.48234"
"241.77600","34.57748","0.48520"
"242.05200","34.60038","0.48872"
"242.32800","34.62340","0.49088"
"242.60400","34.64648","0.49356"
"242.88000","34.66950","0.49574"
"243.15600","34.69246","0.49716"
"243.43200","34.71548","0.49797"
"243.70800","34.73849","0.49899"
"243.98400","34.76146","0.49983"
"244.26000","34.78447","0.50149"
"244.53600","34.80749","0.50316"
"244.81200","34.83051","0.50731"
"245.08800","34.85341","0.51148"
"245.36400","34.87649","0.51618"
"245.64000","34.89945","0.52156"
"245.91600","34.92247","0.52749"
"246.19200","34.94543","0.53072"
"246.46800","34.96851","0.53485"
"246.74400","34.99141","0.53772"
"247.02000","35.01455","0.54070"
"247.29600","35.03744","0.54393"
"247.57200","35.06046","0.54625"
"247.84800","35.08342","0.54708"
"248.12400","35.10644","0.54930"
"248.40000","35.12940","0.55260"
"248.67600","35.15242","0.55518"
"248.95200","35.17538","0.55682"
"249.22800","35.19846","0.55863"
"249.50400","35.22142","0.55967"
"249.78000","35.24443","0.56084"
"250.05600","35.26740","0.56201"
"250.33200","35.29047","0.56267"
"250.60800","35.31343","0.56354"
"250.88400","35.33645","0.56459"
"251.16000","35.35947","0.56596"
"251.43600","35.38243","0.56803"
"251.71200","35.40545","0.57069"
"251.98800","35.42847","0.57358"
"252.26400","35.45143","0.57674"
"252.54000","35.47451","0.58165"
"252.81600","35.49746","0.58621"
"253.09200","35.52042","0.59122"
"253.36800","35.54344","0.59513"
"253.64400","35.56646","0.59960"
"253.92000","35.58948","0.60220"
"254.19600","35.61250","0.60446"
"254.47200","35.63546","0.60667"
"254.74800","35.65848","0.60900"
"255.02400","35.68138","0.61314"
"255.30000","35.70440","0.61745"
"255.57600","35.72742","0.62207"
"255.85200","35.75043","0.62630"
"256.12800","35.77345","0.63156"
"256.40400","35.79641","0.63578"
"256.68000","35.81949","0.64006"
"256.95600","35.84245","0.64241"
"257.23200","35.86547","0.64423"
"257.50800","35.88843","0.64618"
"257.78400","35.91145","0.64701"
"258.06000","35.93447","0.64812"
"258.33600","35.95749","0.64935"
"258.61200","35.98045","0.65022"
"258.88800","36.00346","0.65087"
"259.16400","36.02642","0.65123"
"259.44000","36.04944","0.65157"
"259.71600","36.07240","0.65281"
"259.99200","36.09542","0.65436"
"260.26800","36.11838","0.65547"
"260.54400","36.14146","0.65717"
"260.82000","36.16442","0.65849"
"261.09600","36.18744","0.66037"
"261.37200","36.21040","0.66229"
"261.64800","36.23347","0.66518"
"261.92400","36.25637","0.66794"
"262.20000","36.27945","0.66896"
"262.47600","36.30241","0.66929"
"262.75200","36.32543","0.67119"
"263.02800","36.34839","0.67374"
"263.30400","36.37147","0.67730"
"263.58000","36.39443","0.67914"
"263.85600","36.41745","0.68086"
"264.13200","36.44041","0.67883"
"264.40800","36.46349","0.67936"
"264.68400","36.48644","0.67644"
"264.96000","36.50946","0.67933"
"265.23600","36.53248","0.68169"
"265.51200","36.55544","0.68519"
"265.78800","36.57846","0.69117"
"266.06400","36.60142","0.69785"
"266.34000","36.62444","0.70380"
"266.61600","36.64740","0.70751"
"266.89200","36.67048","0.70968"
"267.16800","36.69344","0.71028"
"267.44400","36.71645","0.71111"
"267.72000","36.73941","0.71254"
"267.99600","36.76249","0.71392"
"268.27200","36.78545","0.71879"
"268.54800","36.80847","-0.00363"
"268.82400","36.83143","0.02955"
"269.10000","36.85445","0.01056"
"269.37600","36.87741","0.01162"
"269.65200","36.90043","0.01551"
"269.92800","36.92339","0.01073"
"270.20400","36.94640","0.02123"
"270.48000","36.96936","0.00945"
"270.75600","36.99244","0.01716"
"271.03200","37.01534","0.01569"
"271.30800","37.03848","0.01539"
"271.58400","37.06144","0.01467"
"271.86000","37.08446","0.01541"
"272.13600","37.10741","0.01744"
"272.41200","37.13044","0.01426"
"272.68800","37.15340","0.01541"
"272.96400","37.17648","0.01674"
"273.24000","37.19943","0.01597"
"273.51600","37.22245","0.01564"
"273.79200","37.24541","0.01465"
"274.06800","37.26849","0.01787"
"274.34400","37.29145","0.01488"
"274.62000","37.31441","0.01716"
"274.89600","37.33743","0.01552"
"275.17200","37.36051","0.01847"
"275.44800","37.38341","0.01484"
"275.72400","37.40649","0.01652"
"276.00000","37.42944","0.01666"
"276.27600","37.45246","0.01717"
"276.55200","37.47548","0.01726"
"276.82800","37.49844","0.01642"
"277.10400","37.52146","0.01881"
"277.38000","37.54436","0.01644"
"277.65600","37.56744","0.01785"
"277.93200","37.59040","0.01699"
"278.20800","37.61348","0.01831"
"278.48400","37.63644","0.01773"
"278.76000","37.65945","0.01735"
"279.03600","37.68242","0.01830"
"279.31200","37.70549","0.01774"
"279.58800","37.72845","0.01754"
"279.86400","37.75147","0.01779"
"280.14000","37.77443","0.01933"
"280.41600","37.79745","0.01767"
"280.69200","37.82035","0.01794"
"280.96800","37.84343","0.01907"
"281.24400","37.86638","0.01905"
"281.52000","37.88947","0.01843"
"281.79600","37.91236","0.01899"
"282.07200","37.93544","0.01973"
"282.34800","37.95840","0.01962"
"282.62400","37.98148","0.01984"
"282.90000","38.00444","0.01978"
"283.17600","38.02746","0.02018"
"283.45200","38.05042","0.01950"
"283.72800","38.07344","0.01987"
"284.00400","38.09639","0.02080"
"284.28000","38.11948","0.01983"
"284.55600","38.14249","0.02026"
"284.83200","38.16545","0.02168"
"285.10800","38.18841","0.02063"
"285.38400","38.21143","0.02107"
"285.66000","38.23445","0.02252"
"285.93600","38.25747","0.02226"
"286.21200","38.28043","0.02138"
"286.48800","38.30345","0.02296"
"286.76400","38.32652","0.02239"
"287.04000","38.34942","0.02242"
"287.31600","38.37251","0.02315"
"287.59200","38.39540","0.02248"
"287.86800","38.41848","0.02266"
"288.14400","38.44144","0.02320"
"288.42000","38.46452","0.02270"
"288.69600","38.48742","0.02261"
"288.97200","38.51050","0.02403"
"289.24800","38.53340","0.02448"
"289.52400","38.55648","0.02347"
"289.80000","38.57938","0.02449"
"290.07600","38.60246","0.02428"
"290.35200","38.62548","0.02492"
"290.62800","38.64849","0.02431"
"290.90400","38.67145","0.02476"
"291.18000","38.69447","0.02472"
"291.45600","38.71737","0.02488"
"291.73200","38.74039","0.02574"
"292.00800","38.76335","0.02620"
"292.28400","38.78643","0.02557"
"292.56000","38.80938","0.02621"
"292.83600","38.83246","0.02571"
"293.11200","38.85543","0.02629"
"293.38800","38.87844","0.02682"
"293.66400","38.90141","0.02689"
"293.94000","38.92448","0.02676"
"294.21600","38.94744","0.02715"
"294.49200","38.97046","0.02728"
"294.76800","38.99342","0.02762"
"295.04400","39.01644","0.02719"
"295.32000","39.03939","0.02755"
"295.59600","39.06247","0.02867"
"295.87200","39.08543","0.02888"
"296.14800","39.10839","0.02851"
"296.42400","39.13147","0.02872"
"296.70000","39.15449","0.02931"
"296.97600","39.17745","0.02950"
"297.25200","39.20047","0.03026"
"297.52800","39.22343","0.03053"
"297.80400","39.24645","0.03008"
"298.08000","39.26941","0.03029"
"298.35600","39.29242","0.03058"
"298.63200","39.31544","0.03060"
"298.90800","39.33840","0.03101"
"299.18400","39.36148","0.03174"
"299.46000","39.38438","0.03188"
"299.73600","39.40746","0.03185"
"300.01200","39.43042","0.03212"
"300.28800","39.45343","0.03306"
"300.56400","39.47640","0.03280"
"300.84000","39.49948","0.03351"
"301.11600","39.52243","0.03334"
"301.39200","39.54539","0.03302"
"301.66800","39.56841","0.03427"
"301.94400","39.59150","0.03444"
"302.22000","39.61440","0.03459"
"302.49600","39.63741","0.03497"
"302.77200","39.66037","0.03490"
"303.04800","39.68345","0.03518"
"303.32400","39.70641","0.03565"
"303.60000","39.72948","0.03520"
"303.87600","39.75239","0.03606"
"304.15200","39.77541","0.03628"
"304.42800","39.79842","0.03617"
"304.70400","39.82144","0.03634"
"304.98000","39.84440","0.03624"
"305.25600","39.86748","0.03716"
"305.53200","39.89044","0.03723"
"305.80800","39.91346","0.03717"
"306.08400","39.93636","0.03707"
"306.36000","39.95950","0.03714"
"306.63600","39.98240","0.03761"
"306.91200","40.00547","0.03801"
"307.18800","40.02843","0.03786"
"307.46400","40.05145","0.03821"
"307.74000","40.07447","0.03813"
"308.01600","40.09749","0.03847"
"308.29200","40.12045","0.03831"
"308.56800","40.14347","0.03879"
"308.84400","40.16643","0.03877"
"309.12000","40.18945","0.03903"
"309.39600","40.21246","0.03926"
"309.67200","40.23543","0.03920"
"309.94800","40.25845","0.03932"
"310.22400","40.28146","0.03971"
"310.50000","40.30448","0.03972"
"310.77600","40.32744","0.03986"
"311.05200","40.35052","0.04025"
"311.32800","40.37342","0.04012"
"311.60400","40.39650","0.04009"
"311.88000","40.41946","0.04024"
"312.15600","40.44248","0.04078"
"312.43200","40.46537","0.04064"
"312.70800","40.48845","0.04051"
"312.98400","40.51136","0.04093"
"313.26000","40.53443","0.04128"
"313.53600","40.55739","0.04106"
"313.81200","40.58041","0.04168"
"314.08800","40.60337","0.04157"
"314.36400","40.62651","0.04164"
"314.64000","40.64941","0.04213"
"314.91600","40.67249","0.04224"
"315.19200","40.69545","0.04239"
"315.46800","40.71847","0.04254"
"315.74400","40.74142","0.04255"
"316.02000","40.76444","0.04271"
"316.29600","40.78746","0.04310"
"316.57200","40.81048","0.04346"
"316.84800","40.83344","0.04352"
"317.12400","40.85646","0.04353"
"317.40000","40.87942","0.04397"
"317.67600","40.90244","0.04445"
"317.95200","40.92546","0.04450"
"318.22800","40.94847","0.04463"
"318.50400","40.97144","0.04512"
"318.78000","40.99445","0.04571"
"319.05600","41.01747","0.04568"
"319.33200","41.04043","0.04608"
"319.60800","41.06345","0.04626"
"319.88400","41.08641","0.04675"
"320.16000","41.10943","0.04730"
"320.43600","41.13239","0.04757"
"320.71200","41.15546","0.04877"
"320.98800","41.17837","0.04858"
"321.26400","41.20145","0.04957"
"321.54000","41.22440","0.04969"
"321.81600","41.24748","0.04993"
"322.09200","41.27044","0.05072"
"322.36800","41.29346","0.05078"
"322.64400","41.31642","0.05171"
"322.92000","41.33950","0.05221"
"323.19600","41.36240","0.05265"
"323.47200","41.38548","0.05325"
"323.74800","41.40837","0.05333"
"324.02400","41.43145","0.05379"
"324.30000","41.45436","0.05487"
"324.57600","41.47749","0.05501"
"324.85200","41.50039","0.05567"
"325.12800","41.52347","0.05640"
"325.40400","41.54637","0.05696"
"325.68000","41.56945","0.05632"
"325.95600","41.59241","0.05601"
"326.23200","41.61549","0.05707"
"326.50800","41.63845","0.05724"
"326.78400","41.66147","0.05764"
"327.06000","41.68443","0.05921"
"327.33600","41.70744","0.05963"
"327.61200","41.73046","0.05903"
"327.88800","41.75342","0.05963"
"328.16400","41.77644","0.06100"
"328.44000","41.79940","0.06121"
"328.71600","41.82242","0.06180"
"328.99200","41.84544","0.06235"
"329.26800","41.86846","0.06277"
"329.54400","41.89148","0.06256"
"329.82000","41.91444","0.06314"
"330.09600","41.93745","0.06348"
"330.37200","41.96048","0.06399"
"330.64800","41.98343","0.06432"
"330.92400","42.00645","0.06458"
"331.20000","42.02941","0.06486"
"331.47600","42.05249","0.06527"
"331.75200","42.07539","0.06583"
"332.02800","42.09846","0.06669"
"332.30400","42.12143","0.06656"
"332.58000","42.14451","0.06696"
"332.85600","42.16735","0.04451"
"333.13200","42.19043","0.04291"
"333.40800","42.21338","0.04371"
"333.68400","42.23646","0.04366"
"333.96000","42.25942","0.04427"
"334.23600","42.28250","0.04564"
"334.51200","42.30540","0.04622"
"334.78800","42.32842","0.04749"
"335.06400","42.35138","0.04773"
"335.34000","42.37440","0.04866"
"335.61600","42.39742","0.05046"
"335.89200","42.42044","0.05127"
"336.16800","42.44339","0.05229"
"336.44400","42.46647","0.05320"
"336.72000","42.48943","0.05435"
"336.99600","42.51245","0.05617"
"337.27200","42.53540","0.05641"
"337.54800","42.55843","0.05750"
"337.82400","42.58145","0.05842"
"338.10000","42.60441","0.05847"
"338.37600","42.62742","0.05931"
"338.65200","42.65044","0.05972"
"338.92800","42.67347","0.06063"
"339.20400","42.69642","0.06171"
"339.48000","42.71944","0.06250"
"339.75600","42.74246","0.06246"
"340.03200","42.76548","0.06366"
"340.30800","42.78850","0.06341"
"340.58400","42.81152","0.06482"
"340.86000","42.83442","0.06514"
"341.13600","42.85744","0.06597"
"341.41200","42.88046","0.06100"
"341.68800","42.90342","0.06122"
"341.96400","42.92638","0.06247"
"342.24000","42.94945","0.06305"
"342.51600","42.97241","0.06324"
"342.79200","42.99543","0.06385"
"343.06800","43.01844","0.06496"
"343.34400","43.04147","0.06544"
"343.62000","43.06443","0.06533"
"343.89600","43.08745","0.06500"
"344.17200","43.11040","0.06605"
"344.44800","43.13348","0.06639"
"344.72400","43.15644","0.06678"
"345.00000","43.17946","0.06690"
"345.27600","43.20242","0.06724"
"345.55200","43.22544","0.06762"
"345.82800","43.24834","0.06785"
"346.10400","43.27148","0.06852"
"346.38000","43.29438","0.06903"
"346.65600","43.31746","0.06909"
"346.93200","43.34042","0.06981"
"347.20800","43.36344","0.07039"
"347.48400","43.38645","0.07063"
"347.76000","43.40947","0.07097"
"348.03600","43.43243","0.07098"
"348.31200","43.45551","0.07108"
"348.58800","43.47841","0.07137"
"348.86400","43.50148","0.07179"
"349.14000","43.52445","0.07201"
"349.41600","43.54741","0.07230"
"349.69200","43.57037","0.07225"
"349.96800","43.59344","0.07237"
"350.24400","43.61641","0.07187"
"350.52000","43.63948","0.07236"
"350.79600","43.66250","0.07291"
"351.07200","43.68546","0.07317"
"351.34800","43.70848","0.07356"
"351.62400","43.73150","0.07370"
"351.90000","43.75446","0.07491"
"352.17600","43.77742","0.07552"
"352.45200","43.80044","0.07577"
"352.72800","43.82346","0.07692"
"353.00400","43.84648","0.07691"
"353.28000","43.86943","0.07741"
"353.55600","43.89246","0.07585"
"353.83200","43.91541","0.07522"
"354.10800","43.93843","0.07690"
"354.38400","43.96139","0.07692"
"354.66000","43.98447","0.07758"
"354.93600","44.00749","0.07902"
"355.21200","44.03051","0.07973"
"355.48800","44.05341","0.08014"
"355.76400","44.07643","0.08055"
"356.04000","44.09939","0.08158"
"356.31600","44.12241","0.08165"
"356.59200","44.14536","0.08205"
"356.86800","44.16844","0.08266"
"357.14400","44.19134","0.08380"
"357.42000","44.21448","0.08364"
"357.69600","44.23738","0.08441"
"357.97200","44.26046","0.08444"
"358.24800","44.28342","0.08566"
"358.52400","44.30644","0.08582"
"358.80000","44.32946","0.08599"
"359.07600","44.35253","0.08643"
"359.35200","44.37543","0.08702"
"359.62800","44.39845","0.08751"
"359.90400","44.42141","0.08793"
"360.18000","44.44448","0.08805"
"360.45600","44.46745","0.08827"
"360.73200","44.49041","0.08865"
"361.00800","44.51342","0.08864"
"361.28400","44.53645","0.08914"
"361.56000","44.55947","0.08962"
"361.83600","44.58243","0.08982"
"362.11200","44.60544","0.09004"
"362.38800","44.62846","0.09016"
"362.66400","44.65148","0.09031"
"362.94000","44.67444","0.09042"
"363.21600","44.69746","0.09078"
"363.49200","44.72042","0.09111"
"363.76800","44.74344","0.09096"
"364.04400","44.76640","0.09077"
"364.32000","44.78948","0.09072"
"364.59600","44.81244","0.09069"
"364.87200","44.83546","0.09086"
"365.14800","44.85841","0.09106"
"365.42400","44.88149","0.09155"
"365.70000","44.90439","0.09171"
"365.97600","44.92747","0.09202"
"366.25200","44.95037","0.09220"
"366.52800","44.97345","0.09203"
"366.80400","44.99635","0.09003"
"367.08000","45.01942","0.09017"
"367.35600","45.04238","0.09068"
"367.63200","45.06547","0.09097"
"367.90800","45.08837","0.09145"
"368.18400","45.11150","0.09142"
"368.46000","45.13446","0.09172"
"368.73600","45.15748","0.09203"
"369.01200","45.18044","0.09247"
"369.28800","45.20351","0.09300"
"369.56400","45.22642","0.09317"
"369.84000","45.24943","0.09403"
"370.11600","45.27245","0.09431"
"370.39200","45.29542","0.09499"
"370.66800","45.31844","0.09534"
"370.94400","45.34145","0.09518"
"371.22000","45.36441","0.09634"
"371.49600","45.38737","0.09700"
"371.77200","45.41045","0.09706"
"372.04800","45.43341","0.09760"
"372.32400","45.45642","0.09810"
"372.60000","45.47950","0.09884"
"372.87600","45.50246","0.09943"
"373.15200","45.52542","0.10183"
"373.42800","45.54845","0.10207"
"373.70400","45.57146","0.10305"
"373.98000","45.59448","0.10430"
"374.25600","45.61744","0.10482"
"374.53200","45.64046","0.10710"
"374.80800","45.66342","0.10713"
"375.08400","45.68650","0.10739"
"375.36000","45.70939","0.10880"
"375.63600","45.73248","0.10921"
"375.91200","45.75537","0.11072"
"376.18800","45.77846","0.11177"
"376.46400","45.80141","0.11269"
"376.74000","45.82449","0.11249"
"377.01600","45.84745","0.11332"
"377.29200","45.87047","0.11420"
"377.56800","45.89337","0.11432"
"377.84400","45.91639","0.11569"
"378.12000","45.93935","0.11658"
"378.39600","45.96243","0.11773"
"378.67200","45.98545","0.11773"
"378.94800","46.00846","0.11951"
"379.22400","46.03142","0.11994"
"379.50000","46.05444","0.12042"
"379.77600","46.07747","0.12127"
"380.05200","46.10048","0.12214"
"380.32800","46.12344","0.12178"
"380.60400","46.14646","0.12241"
"380.88000","46.16942","0.12293"
"381.15600","46.19244","0.12326"
"381.43200","46.21545","0.12416"
"381.70800","46.23841","0.12392"
"381.98400","46.26150","0.12484"
"382.26000","46.28445","0.12555"
"382.53600","46.30748","0.12607"
"382.81200","46.33049","0.12666"
"383.08800","46.35345","0.12700"
"383.36400","46.37647","0.12786"
"383.64000","46.39949","0.12764"
"383.91600","46.42245","0.12799"
"384.19200","46.44547","0.12855"
"384.46800","46.46842","0.12862"
"384.74400","46.49144","0.12934"
"385.02000","46.51440","0.12975"
"385.29600","46.53743","0.13029"
"385.57200","46.56044","0.13051"
"385.84800","46.58340","0.13088"
"386.12400","46.60642","0.13157"
"386.40000","46.62944","0.13183"
"386.67600","46.65240","0.13244"
"386.95200","46.67542","0.13264"
"387.22800","46.69844","0.13319"
"387.50400","46.72145","0.13308"
"387.78000","46.74442","0.13367"
"388.05600","46.76749","0.13411"
"388.33200","46.79045","0.13421"
"388.60800","46.81347","0.13456"
"388.88400","46.83643","0.13503"
"389.16000","46.85945","0.13541"
"389.43600","46.88240","0.13586"
"389.71200","46.90548","0.13593"
"389.98800","46.92845","0.13620"
"390.26400","46.95147","0.13607"
"390.54000","46.97442","0.13652"
"390.81600","46.99744","0.13660"
"391.09200","47.02047","0.13706"
"391.36800","47.04348","0.13720"
"391.64400","47.06644","0.13782"
"391.92000","47.08946","0.13772"
"392.19600","47.11242","0.13821"
"392.47200","47.13538","0.13810"
"392.74800","47.15839","0.13845"
"393.02400","47.18142","0.13864"
"393.30000","47.20443","0.13896"
"393.57600","47.22745","0.13927"
"393.85200","47.25047","0.13945"
"394.12800","47.27343","0.13981"
"394.40400","47.29645","0.13973"
"394.68000","47.31941","0.13986"
"394.95600","47.34249","0.13995"
"395.23200","47.36544","0.14070"
"395.50800","47.38847","0.14080"
"395.78400","47.41143","0.14127"
"396.06000","47.43450","0.14136"
"396.33600","47.45741","0.14189"
"396.61200","47.48048","0.14236"
"396.88800","47.50344","0.14239"
"397.16400","47.52646","0.14278"
"397.44000","47.54942","0.14297"
"397.71600","47.57250","0.14251"
"397.99200","47.59540","0.14304"
"398.26800","47.61842","0.14287"
"398.54400","47.64138","0.14317"
"398.82000","47.66446","0.14384"
"399.09600","47.68741","0.14414"
"399.37200","47.71043","0.14398"
"399.64800","47.73339","0.14486"
"399.92400","47.75641","0.14489"
"400.20000","47.77937","0.14599"
"400.47600","47.80245","0.14563"
"400.75200","47.82541","0.14686"
"401.02800","47.84843","0.14693"
"401.30400","47.87145","0.14722"
"401.58000","47.89446","0.14817"
"401.85600","47.91742","0.14821"
"402.13200","47.94044","0.14877"
"402.40800","47.96346","0.14961"
"402.68400","47.98648","0.14977"
"402.96000","48.00944","0.15009"
"403.23600","48.03246","0.15046"
"403.51200","48.05542","0.15060"
"403.78800","48.07844","0.15153"
"404.06400","48.10146","0.15049"
"404.34000","48.12442","0.15103"
"404.61600","48.14737","0.15164"
"404.89200","48.17046","0.15329"
"405.16800","48.19347","0.15442"
"405.44400","48.21643","0.15543"
"405.72000","48.23945","0.15581"
"405.99600","48.26247","0.15636"
"406.27200","48.28549","0.15668"
"406.54800","48.30839","0.15728"
"406.82400","48.33141","0.15868"
"407.10000","48.35442","0.16022"
"407.37600","48.37744","0.16219"
"407.65200","48.40041","0.16318"
"407.92800","48.42342","0.16517"
"408.20400","48.44638","0.16606"
"408.48000","48.46946","0.16707"
"408.75600","48.49242","0.16821"
"409.03200","48.51550","0.01034"
"409.30800","48.53840","0.00484"
"409.58400","48.56148","0.01421"
"409.86000","48.58438","0.02013"
"410.13600","48.60746","0.01074"
"410.41200","48.63035","0.01062"
"410.68800","48.65349","0.01129"
"410.96400","48.67640","0.01630"
"411.24000","48.69947","0.01201"
"411.51600","48.72237","0.01073"
"411.79200","48.74551","0.01100"
"412.06800","48.76847","0.01586"
"412.34400","48.79149","0.01025"
"412.50800","48.80506","0.01063"