File: Force_trajectories/170212_2/Specimen_RawData_2.csv
End date,"2/12/2017"
Specimen label,"9CG_75"
Maximum Load,"0.27909",N

Time,Extension,Load
(s),(mm),(N)
"0.00000","0.00000","0.00201"
"0.18000","0.01190","0.00308"
"0.36000","0.03007","0.00550"
"0.54000","0.04514","0.00655"
"0.72000","0.06021","0.00784"
"0.90000","0.07522","0.00910"
"1.08000","0.09016","0.01046"
"1.26000","0.10517","0.01129"
"1.44000","0.12012","0.01193"
"1.62000","0.13512","0.01291"
"1.80000","0.15019","0.01464"
"1.98000","0.16514","0.01603"
"2.16000","0.18009","0.01623"
"2.34000","0.19521","0.01838"
"2.52000","0.21022","0.01910"
"2.70000","0.22517","0.02057"
"2.88000","0.24017","0.02169"
"3.06000","0.25518","0.02293"
"3.24000","0.27013","0.02333"
"3.42000","0.28526","0.02517"
"3.60000","0.30014","0.02609"
"3.78000","0.31515","0.02691"
"3.96000","0.33022","0.02863"
"4.14000","0.34516","0.02756"
"4.32000","0.36011","0.02803"
"4.50000","0.37524","0.02940"
"4.68000","0.39019","0.03113"
"4.86000","0.40507","0.03134"
"5.04000","0.42020","0.03228"
"5.22000","0.43521","0.03315"
"5.40000","0.45010","0.03350"
"5.58000","0.46522","0.03454"
"5.76000","0.48017","0.03487"
"5.94000","0.49518","0.03498"
"6.12000","0.51018","0.03618"
"6.30000","0.52513","0.03655"
"6.48000","0.54014","0.03718"
"6.66000","0.55521","0.03796"
"6.84000","0.57021","0.03835"
"7.02000","0.58516","0.03868"
"7.20000","0.60017","0.03889"
"7.38000","0.61517","0.03966"
"7.56000","0.63012","0.03993"
"7.74000","0.64519","0.04064"
"7.92000","0.66014","0.04108"
"8.10000","0.67514","0.04204"
"8.28000","0.69015","0.04157"
"8.46000","0.70516","0.04181"
"8.64000","0.72011","0.04257"
"8.82000","0.73523","0.04254"
"9.00000","0.75018","0.04313"
"9.18000","0.76513","0.04318"
"9.36000","0.78025","0.04317"
"9.54000","0.79520","0.04156"
"9.72000","0.81015","0.04211"
"9.90000","0.82516","0.04282"
"10.08000","0.84022","0.04310"
"10.26000","0.85517","0.04235"
"10.44000","0.87018","0.04257"
"10.62000","0.88512","0.04356"
"10.80000","0.90013","0.04401"
"10.98000","0.91514","0.04408"
"11.16000","0.93015","0.04410"
"11.34000","0.94509","0.04460"
"11.52000","0.96016","0.04465"
"11.70000","0.97517","0.04444"
"11.88000","0.99005","0.04557"
"12.06000","1.00518","0.04542"
"12.24000","1.02019","0.04566"
"12.42000","1.03520","0.04526"
"12.60000","1.05014","0.04554"
"12.78000","1.06515","0.04580"
"12.96000","1.08016","0.04595"
"13.14000","1.09516","0.04582"
"13.32000","1.11017","0.04673"
"13.50000","1.12512","0.04642"
"13.68000","1.14025","0.04688"
"13.86000","1.15519","0.04621"
"14.04000","1.17008","0.04697"
"14.22000","1.18521","0.04698"
"14.40000","1.20016","0.04779"
"14.58000","1.21516","0.04809"
"14.76000","1.23023","0.04741"
"14.94000","1.24518","0.04702"
"15.12000","1.26018","0.04771"
"15.30000","1.27519","0.04740"
"15.48000","1.29014","0.04821"
"15.66000","1.30515","0.04872"
"15.84000","1.32021","0.04798"
"16.02000","1.33516","0.04876"
"16.20000","1.35017","0.04871"
"16.38000","1.36517","0.04887"
"16.56000","1.38018","0.04884"
"16.74000","1.39513","0.04916"
"16.92000","1.41014","0.04869"
"17.10000","1.42514","0.04930"
"17.28000","1.44015","0.04931"
"17.46000","1.45516","0.04919"
"17.64000","1.47011","0.04937"
"17.82000","1.48517","0.04907"
"18.00000","1.50018","0.04937"
"18.18000","1.51519","0.04894"
"18.36000","1.53013","0.04855"
"18.54000","1.54520","0.04885"
"18.72000","1.56015","0.04900"
"18.90000","1.57516","0.04826"
"19.08000","1.59016","0.04798"
"19.26000","1.60517","0.04860"
"19.44000","1.62018","0.04891"
"19.62000","1.63518","0.04740"
"19.80000","1.65013","0.04793"
"19.98000","1.66520","0.04810"
"20.16000","1.68015","0.04846"
"20.34000","1.69515","0.04858"
"20.52000","1.71016","0.04761"
"20.70000","1.72517","0.04784"
"20.88000","1.74017","0.04736"
"21.06000","1.75512","0.04802"
"21.24000","1.77013","0.04778"
"21.42000","1.78514","0.04833"
"21.60000","1.80020","0.04878"
"21.78000","1.81515","0.04954"
"21.96000","1.83010","0.04916"
"22.14000","1.84516","0.04892"
"22.32000","1.86017","0.04849"
"22.50000","1.87518","0.04818"
"22.68000","1.89013","0.04860"
"22.86000","1.90519","0.04862"
"23.04000","1.92014","0.04910"
"23.22000","1.93509","0.04901"
"23.40000","1.95016","0.04905"
"23.58000","1.96516","0.04913"
"23.76000","1.98017","0.04992"
"23.94000","1.99524","0.04881"
"24.12000","2.01012","0.04994"
"24.30000","2.02519","0.04939"
"24.48000","2.04020","0.04943"
"24.66000","2.05515","0.04977"
"24.84000","2.07015","0.04998"
"25.02000","2.08522","0.05011"
"25.20000","2.10017","0.05010"
"25.38000","2.11511","0.05081"
"25.56000","2.13018","0.04911"
"25.74000","2.14519","0.04889"
"25.92000","2.16020","0.04903"
"26.10000","2.17520","0.04946"
"26.28000","2.19015","0.04978"
"26.46000","2.20516","0.04979"
"26.64000","2.22016","0.04988"
"26.82000","2.23511","0.04988"
"27.00000","2.25012","0.05008"
"27.18000","2.26519","0.05027"
"27.36000","2.28013","0.05011"
"27.54000","2.29520","0.05045"
"27.72000","2.31021","0.05108"
"27.90000","2.32516","0.05027"
"28.08000","2.34016","0.05064"
"28.26000","2.35517","0.05079"
"28.44000","2.37012","0.05015"
"28.62000","2.38518","0.05020"
"28.80000","2.40019","0.05007"
"28.98000","2.41508","0.05034"
"29.16000","2.43021","0.05121"
"29.34000","2.44521","0.05113"
"29.52000","2.46010","0.05054"
"29.70000","2.47517","0.05077"
"29.88000","2.49017","0.05128"
"30.06000","2.50512","0.05183"
"30.24000","2.52013","0.05143"
"30.42000","2.53514","0.05082"
"30.60000","2.55014","0.05149"
"30.78000","2.56521","0.05141"
"30.96000","2.58022","0.05148"
"31.14000","2.59510","0.05250"
"31.32000","2.61017","0.05273"
"31.50000","2.62518","0.05182"
"31.68000","2.64019","0.05195"
"31.86000","2.65519","0.05220"
"32.04000","2.67020","0.05246"
"32.22000","2.68515","0.05249"
"32.40000","2.70016","0.05306"
"32.58000","2.71522","0.05292"
"32.76000","2.73017","0.05316"
"32.94000","2.74518","0.05308"
"33.12000","2.76018","0.05282"
"33.30000","2.77513","0.05304"
"33.48000","2.79020","0.05336"
"33.66000","2.80521","0.05357"
"33.84000","2.82015","0.05351"
"34.02000","2.83516","0.05335"
"34.20000","2.85023","0.05307"
"34.38000","2.86511","0.05381"
"34.56000","2.88018","0.05403"
"34.74000","2.89519","0.05372"
"34.92000","2.91020","0.05403"
"35.10000","2.92514","0.05386"
"35.28000","2.94021","0.05378"
"35.46000","2.95516","0.05380"
"35.64000","2.97016","0.05318"
"35.82000","2.98517","0.05436"
"36.00000","3.00018","0.05392"
"36.18000","3.01519","0.05416"
"36.36000","3.03019","0.05438"
"36.54000","3.04514","0.05429"
"36.72000","3.06015","0.05448"
"36.90000","3.07516","0.05468"
"37.08000","3.09016","0.05480"
"37.26000","3.10523","0.05449"
"37.44000","3.12018","0.05433"
"37.62000","3.13512","0.05452"
"37.80000","3.15019","0.05492"
"37.98000","3.16520","0.05464"
"38.16000","3.18015","0.05405"
"38.34000","3.19521","0.05409"
"38.52000","3.21016","0.05465"
"38.70000","3.22511","0.05465"
"38.88000","3.24017","0.05495"
"39.06000","3.25518","0.05507"
"39.24000","3.27013","0.05523"
"39.42000","3.28520","0.05516"
"39.60000","3.30020","0.05557"
"39.78000","3.31509","0.05574"
"39.96000","3.33022","0.05598"
"40.14000","3.34516","0.05604"
"40.32000","3.36011","0.05592"
"40.50000","3.37518","0.05637"
"40.68000","3.39019","0.05632"
"40.86000","3.40507","0.05631"
"41.04000","3.42014","0.05581"
"41.22000","3.43521","0.05633"
"41.40000","3.45010","0.05621"
"41.58000","3.46516","0.05648"
"41.76000","3.48017","0.05636"
"41.94000","3.49518","0.05628"
"42.12000","3.51018","0.05646"
"42.30000","3.52519","0.05660"
"42.48000","3.54014","0.05707"
"42.66000","3.55521","0.05665"
"42.84000","3.57021","0.05627"
"43.02000","3.58510","0.05624"
"43.20000","3.60017","0.05767"
"43.38000","3.61517","0.05767"
"43.56000","3.63012","0.05633"
"43.74000","3.64519","0.05674"
"43.92000","3.66014","0.05719"
"44.10000","3.67514","0.05714"
"44.28000","3.69015","0.05719"
"44.46000","3.70522","0.05708"
"44.64000","3.72010","0.05729"
"44.82000","3.73523","0.05741"
"45.00000","3.75018","0.05763"
"45.18000","3.76513","0.05754"
"45.36000","3.78019","0.05795"
"45.54000","3.79520","0.05783"
"45.72000","3.81015","0.05805"
"45.90000","3.82515","0.05828"
"46.08000","3.84016","0.05843"
"46.26000","3.85517","0.05825"
"46.44000","3.87018","0.05809"
"46.62000","3.88518","0.05738"
"46.80000","3.90013","0.05825"
"46.98000","3.91520","0.05850"
"47.16000","3.93021","0.05715"
"47.34000","3.94509","0.05763"
"47.52000","3.96022","0.05753"
"47.70000","3.97523","0.05760"
"47.88000","3.99011","0.05803"
"48.06000","4.00518","0.05803"
"48.24000","4.02019","0.05791"
"48.42000","4.03508","0.05862"
"48.60000","4.05020","0.05842"
"48.78000","4.06515","0.05933"
"48.96000","4.08016","0.05901"
"49.14000","4.09522","0.05901"
"49.32000","4.11017","0.05908"
"49.50000","4.12512","0.05865"
"49.68000","4.14019","0.05847"
"49.86000","4.15519","0.05823"
"50.04000","4.17014","0.05881"
"50.22000","4.18515","0.05829"
"50.40000","4.20015","0.05899"
"50.58000","4.21516","0.05847"
"50.76000","4.23017","0.05892"
"50.94000","4.24518","0.05910"
"51.12000","4.26012","0.05849"
"51.30000","4.27519","0.05881"
"51.48000","4.29020","0.05827"
"51.66000","4.30509","0.05889"
"51.84000","4.32021","0.05935"
"52.02000","4.33522","0.05925"
"52.20000","4.35017","0.05915"
"52.38000","4.36517","0.05967"
"52.56000","4.38018","0.05897"
"52.74000","4.39513","0.05897"
"52.92000","4.41020","0.05940"
"53.10000","4.42514","0.05998"
"53.28000","4.44015","0.05973"
"53.46000","4.45522","0.06006"
"53.64000","4.47010","0.05984"
"53.82000","4.48505","0.06008"
"54.00000","4.50024","0.05963"
"54.18000","4.51519","0.06025"
"54.36000","4.53013","0.06001"
"54.54000","4.54514","0.06008"
"54.72000","4.56015","0.06027"
"54.90000","4.57515","0.06074"
"55.08000","4.59022","0.06025"
"55.26000","4.60517","0.06022"
"55.44000","4.62018","0.05968"
"55.62000","4.63518","0.06045"
"55.80000","4.65013","0.06034"
"55.98000","4.66508","0.06078"
"56.16000","4.68021","0.06045"
"56.34000","4.69521","0.05999"
"56.52000","4.71010","0.05986"
"56.70000","4.72523","0.06024"
"56.88000","4.74023","0.06020"
"57.06000","4.75506","0.06040"
"57.24000","4.77019","0.06064"
"57.42000","4.78514","0.06017"
"57.60000","4.80014","0.06031"
"57.78000","4.81521","0.06029"
"57.96000","4.83010","0.06014"
"58.14000","4.84510","0.06042"
"58.32000","4.86017","0.06071"
"58.50000","4.87512","0.06036"
"58.68000","4.89013","0.06067"
"58.86000","4.90519","0.06091"
"59.04000","4.92020","0.06052"
"59.22000","4.93515","0.06073"
"59.40000","4.95015","0.06043"
"59.58000","4.96516","0.06108"
"59.76000","4.98017","0.06075"
"59.94000","4.99518","0.06057"
"60.12000","5.01012","0.06096"
"60.30000","5.02513","0.06091"
"60.48000","5.04020","0.06115"
"60.66000","5.05514","0.06094"
"60.84000","5.07009","0.06106"
"61.02000","5.08522","0.06118"
"61.20000","5.10017","0.06055"
"61.38000","5.11511","0.06105"
"61.56000","5.13012","0.06084"
"61.74000","5.14519","0.06101"
"61.92000","5.16014","0.06047"
"62.10000","5.17520","0.06122"
"62.28000","5.19009","0.06116"
"62.46000","5.20510","0.06122"
"62.64000","5.22016","0.06143"
"62.82000","5.23511","0.06143"
"63.00000","5.25012","0.06200"
"63.18000","5.26519","0.06194"
"63.36000","5.28013","0.06217"
"63.54000","5.29514","0.06173"
"63.72000","5.31015","0.06202"
"63.90000","5.32515","0.06195"
"64.08000","5.34016","0.06197"
"64.26000","5.35517","0.06098"
"64.44000","5.37018","0.06140"
"64.62000","5.38518","0.06147"
"64.80000","5.40019","0.06175"
"64.98000","5.41514","0.06233"
"65.16000","5.43015","0.06198"
"65.34000","5.44521","0.06166"
"65.52000","5.46016","0.06183"
"65.70000","5.47511","0.06202"
"65.88000","5.49017","0.06222"
"66.06000","5.50518","0.06204"
"66.24000","5.52013","0.06201"
"66.42000","5.53514","0.06209"
"66.60000","5.55008","0.06215"
"66.78000","5.56515","0.06209"
"66.96000","5.58016","0.06248"
"67.14000","5.59510","0.06283"
"67.32000","5.61011","0.06312"
"67.50000","5.62518","0.06311"
"67.68000","5.64019","0.06295"
"67.86000","5.65519","0.06309"
"68.04000","5.67014","0.06312"
"68.22000","5.68521","0.06331"
"68.40000","5.70015","0.06331"
"68.58000","5.71510","0.06322"
"68.76000","5.73017","0.06330"
"68.94000","5.74518","0.06361"
"69.12000","5.76018","0.06341"
"69.30000","5.77513","0.06376"
"69.48000","5.79014","0.06322"
"69.66000","5.80515","0.06330"
"69.84000","5.82015","0.06315"
"70.02000","5.83510","0.06331"
"70.20000","5.85017","0.06305"
"70.38000","5.86517","0.06375"
"70.56000","5.88012","0.06358"
"70.74000","5.89513","0.06357"
"70.92000","5.91014","0.06382"
"71.10000","5.92514","0.06341"
"71.28000","5.94015","0.06385"
"71.46000","5.95516","0.06346"
"71.64000","5.97016","0.06439"
"71.82000","5.98517","0.06441"
"72.00000","6.00012","0.06407"
"72.18000","6.01519","0.06396"
"72.36000","6.03019","0.06438"
"72.54000","6.04514","0.06446"
"72.72000","6.06015","0.06461"
"72.90000","6.07515","0.06453"
"73.08000","6.09016","0.06475"
"73.26000","6.10517","0.06502"
"73.44000","6.12012","0.06458"
"73.62000","6.13512","0.06501"
"73.80000","6.15019","0.06507"
"73.98000","6.16526","0.06460"
"74.16000","6.18014","0.06507"
"74.34000","6.19515","0.06557"
"74.52000","6.21022","0.06517"
"74.70000","6.22517","0.06502"
"74.88000","6.24017","0.06535"
"75.06000","6.25518","0.06517"
"75.24000","6.27013","0.06515"
"75.42000","6.28514","0.06553"
"75.60000","6.30020","0.06554"
"75.78000","6.31509","0.06525"
"75.96000","6.33016","0.06527"
"76.14000","6.34516","0.06560"
"76.32000","6.36011","0.06520"
"76.50000","6.37512","0.06556"
"76.68000","6.39019","0.06550"
"76.86000","6.40513","0.06551"
"77.04000","6.42014","0.06502"
"77.22000","6.43521","0.06525"
"77.40000","6.45015","0.06547"
"77.58000","6.46516","0.06541"
"77.76000","6.48017","0.06526"
"77.94000","6.49518","0.06558"
"78.12000","6.51012","0.06564"
"78.30000","6.52519","0.06592"
"78.48000","6.54014","0.06590"
"78.66000","6.55514","0.06592"
"78.84000","6.57021","0.06604"
"79.02000","6.58516","0.06621"
"79.20000","6.60023","0.06603"
"79.38000","6.61517","0.06609"
"79.56000","6.63018","0.06626"
"79.74000","6.64513","0.06611"
"79.92000","6.66019","0.06612"
"80.10000","6.67514","0.06672"
"80.28000","6.69015","0.06649"
"80.46000","6.70516","0.06620"
"80.64000","6.72010","0.06634"
"80.82000","6.73517","0.06639"
"81.00000","6.75018","0.06625"
"81.18000","6.76513","0.06683"
"81.36000","6.78013","0.06690"
"81.54000","6.79520","0.06638"
"81.72000","6.81015","0.06687"
"81.90000","6.82516","0.06697"
"82.08000","6.84016","0.06689"
"82.26000","6.85517","0.06722"
"82.44000","6.87018","0.06657"
"82.62000","6.88518","0.06709"
"82.80000","6.90013","0.06735"
"82.98000","6.91520","0.06694"
"83.16000","6.93020","0.06735"
"83.34000","6.94515","0.06750"
"83.52000","6.96016","0.06744"
"83.70000","6.97523","0.06723"
"83.88000","6.99011","0.06746"
"84.06000","7.00512","0.06784"
"84.24000","7.02019","0.06743"
"84.42000","7.03514","0.06774"
"84.60000","7.05014","0.06782"
"84.78000","7.06521","0.06800"
"84.96000","7.08016","0.06807"
"85.14000","7.09516","0.06809"
"85.32000","7.11023","0.06809"
"85.50000","7.12512","0.06796"
"85.68000","7.14019","0.06799"
"85.86000","7.15519","0.06808"
"86.04000","7.17014","0.06877"
"86.22000","7.18515","0.06834"
"86.40000","7.20009","0.06834"
"86.58000","7.21516","0.06866"
"86.76000","7.23017","0.06838"
"86.94000","7.24518","0.06857"
"87.12000","7.26012","0.06914"
"87.30000","7.27519","0.06896"
"87.48000","7.29020","0.06916"
"87.66000","7.30515","0.06927"
"87.84000","7.32015","0.06929"
"88.02000","7.33516","0.06961"
"88.20000","7.35011","0.06946"
"88.38000","7.36517","0.06953"
"88.56000","7.38018","0.06987"
"88.74000","7.39513","0.06965"
"88.92000","7.41020","0.06969"
"89.10000","7.42520","0.07006"
"89.28000","7.44015","0.07014"
"89.46000","7.45522","0.06992"
"89.64000","7.47016","0.06975"
"89.82000","7.48517","0.06920"
"90.00000","7.50024","0.06950"
"90.18000","7.51519","0.06959"
"90.36000","7.53007","0.06931"
"90.54000","7.54520","0.06954"
"90.72000","7.56021","0.06985"
"90.90000","7.57515","0.07006"
"91.08000","7.59022","0.06992"
"91.26000","7.60517","0.07012"
"91.44000","7.62012","0.07034"
"91.62000","7.63524","0.07018"
"91.80000","7.65019","0.07030"
"91.98000","7.66514","0.07054"
"92.16000","7.68015","0.07069"
"92.34000","7.69515","0.07082"
"92.52000","7.71010","0.07070"
"92.70000","7.72517","0.07097"
"92.88000","7.74017","0.07088"
"93.06000","7.75512","0.07143"
"93.24000","7.77019","0.07144"
"93.42000","7.78520","0.07171"
"93.60000","7.80014","0.07145"
"93.78000","7.81521","0.07148"
"93.96000","7.83016","0.07136"
"94.14000","7.84504","0.06486"
"94.32000","7.86023","0.06604"
"94.50000","7.87518","0.06611"
"94.68000","7.89013","0.06657"
"94.86000","7.90519","0.06692"
"95.04000","7.92020","0.06687"
"95.22000","7.93515","0.06695"
"95.40000","7.95015","0.06757"
"95.58000","7.96516","0.06756"
"95.76000","7.98011","0.06776"
"95.94000","7.99518","0.06794"
"96.12000","8.01018","0.06803"
"96.30000","8.02513","0.06827"
"96.48000","8.04020","0.06824"
"96.66000","8.05515","0.06833"
"96.84000","8.07009","0.06863"
"97.02000","8.08522","0.06893"
"97.20000","8.10017","0.06873"
"97.38000","8.11511","0.06901"
"97.56000","8.13018","0.06914"
"97.74000","8.14519","0.06915"
"97.92000","8.16013","0.06944"
"98.10000","8.17520","0.06958"
"98.28000","8.19021","0.06994"
"98.46000","8.20510","0.06996"
"98.64000","8.22022","0.07020"
"98.82000","8.23517","0.07008"
"99.00000","8.25006","0.07047"
"99.18000","8.26519","0.07046"
"99.36000","8.28025","0.07032"
"99.54000","8.29508","0.07049"
"99.72000","8.31021","0.07087"
"99.90000","8.32515","0.07122"
"100.08000","8.34010","0.07097"
"100.26000","8.35523","0.07124"
"100.44000","8.37018","0.07102"
"100.62000","8.38512","0.07145"
"100.80000","8.40019","0.07163"
"100.98000","8.41514","0.07180"
"101.16000","8.43009","0.07167"
"101.34000","8.44515","0.07150"
"101.52000","8.46022","0.07217"
"101.70000","8.47511","0.07193"
"101.88000","8.49017","0.07221"
"102.06000","8.50524","0.07272"
"102.24000","8.52013","0.07274"
"102.42000","8.53520","0.07267"
"102.60000","8.55014","0.07336"
"102.78000","8.56515","0.07276"
"102.96000","8.58022","0.07318"
"103.14000","8.59516","0.07286"
"103.32000","8.61005","0.07299"
"103.50000","8.62518","0.07295"
"103.68000","8.64013","0.07324"
"103.86000","8.65513","0.07340"
"104.04000","8.67014","0.07384"
"104.22000","8.68515","0.07387"
"104.40000","8.70015","0.07379"
"104.58000","8.71522","0.07412"
"104.76000","8.73017","0.07435"
"104.94000","8.74518","0.07406"
"105.12000","8.76024","0.07382"
"105.30000","8.77513","0.07398"
"105.48000","8.79008","0.07453"
"105.66000","8.80526","0.07453"
"105.84000","8.82015","0.07489"
"106.02000","8.83510","0.07542"
"106.20000","8.85017","0.07560"
"106.38000","8.86517","0.07610"
"106.56000","8.88012","0.07580"
"106.74000","8.89519","0.07586"
"106.92000","8.91014","0.07608"
"107.10000","8.92514","0.07589"
"107.28000","8.94021","0.07646"
"107.46000","8.95516","0.07682"
"107.64000","8.97010","0.07655"
"107.82000","8.98517","0.07662"
"108.00000","9.00018","0.07716"
"108.18000","9.01513","0.07718"
"108.36000","9.03019","0.07652"
"108.54000","9.04520","0.07691"
"108.72000","9.06009","0.07693"
"108.90000","9.07521","0.07736"
"109.08000","9.09016","0.07781"
"109.26000","9.10517","0.07807"
"109.44000","9.12024","0.07816"
"109.62000","9.13512","0.07788"
"109.80000","9.15013","0.07910"
"109.98000","9.16520","0.07883"
"110.16000","9.18014","0.07883"
"110.34000","9.19509","0.07948"
"110.52000","9.21022","0.07936"
"110.70000","9.22523","0.07938"
"110.88000","9.24017","0.07953"
"111.06000","9.25518","0.08018"
"111.24000","9.27019","0.07922"
"111.42000","9.28514","0.07967"
"111.60000","9.30020","0.08038"
"111.78000","9.31521","0.08051"
"111.96000","9.33010","0.07038"
"112.14000","9.34516","0.07008"
"112.32000","9.36017","0.07029"
"112.50000","9.37512","0.07064"
"112.68000","9.39025","0.07088"
"112.86000","9.40513","0.07088"
"113.04000","9.42008","0.07106"
"113.22000","9.43515","0.07171"
"113.40000","9.45015","0.07190"
"113.58000","9.46516","0.07203"
"113.76000","9.48017","0.07238"
"113.94000","9.49512","0.07254"
"114.12000","9.51012","0.07248"
"114.30000","9.52519","0.07268"
"114.48000","9.54014","0.07350"
"114.66000","9.55515","0.07304"
"114.84000","9.57021","0.07348"
"115.02000","9.58516","0.07430"
"115.20000","9.60017","0.07400"
"115.38000","9.61517","0.07449"
"115.56000","9.63018","0.07435"
"115.74000","9.64519","0.07424"
"115.92000","9.66014","0.07462"
"116.10000","9.67514","0.07523"
"116.28000","9.69015","0.07519"
"116.46000","9.70516","0.07471"
"116.64000","9.72016","0.07470"
"116.82000","9.73511","0.07520"
"117.00000","9.75024","0.07544"
"117.18000","9.76519","0.07557"
"117.36000","9.78013","0.07565"
"117.54000","9.79520","0.07587"
"117.72000","9.81021","0.07592"
"117.90000","9.82515","0.07654"
"118.08000","9.84016","0.07662"
"118.26000","9.85511","0.07661"
"118.44000","9.87018","0.07680"
"118.62000","9.88512","0.07614"
"118.80000","9.90013","0.07684"
"118.98000","9.91514","0.07747"
"119.16000","9.93014","0.07768"
"119.34000","9.94515","0.07732"
"119.52000","9.96016","0.07807"
"119.70000","9.97517","0.07798"
"119.88000","9.99017","0.07755"
"120.06000","10.00512","0.07796"
"120.24000","10.02013","0.07792"
"120.42000","10.03520","0.07774"
"120.60000","10.05014","0.07835"
"120.78000","10.06515","0.07872"
"120.96000","10.08016","0.07801"
"121.14000","10.09516","0.07820"
"121.32000","10.11017","0.07868"
"121.50000","10.12518","0.07876"
"121.68000","10.14012","0.07841"
"121.86000","10.15519","0.07934"
"122.04000","10.17020","0.07833"
"122.22000","10.18515","0.07851"
"122.40000","10.20009","0.07817"
"122.58000","10.21516","0.07896"
"122.76000","10.23017","0.07900"
"122.94000","10.24518","0.07961"
"123.12000","10.26006","0.07938"
"123.30000","10.27519","0.08032"
"123.48000","10.29020","0.07967"
"123.66000","10.30515","0.08041"
"123.84000","10.32015","0.08068"
"124.02000","10.33522","0.08128"
"124.20000","10.35017","0.08123"
"124.38000","10.36517","0.08192"
"124.56000","10.38018","0.08223"
"124.74000","10.39519","0.08244"
"124.92000","10.41014","0.08306"
"125.10000","10.42520","0.08329"
"125.28000","10.44015","0.08209"
"125.46000","10.45522","0.08243"
"125.64000","10.47022","0.08263"
"125.82000","10.48511","0.08314"
"126.00000","10.50012","0.08250"
"126.18000","10.51525","0.08285"
"126.36000","10.53013","0.08318"
"126.54000","10.54514","0.08377"
"126.72000","10.56015","0.08378"
"126.90000","10.57515","0.08442"
"127.08000","10.59010","0.08311"
"127.26000","10.60517","0.08307"
"127.44000","10.62012","0.08340"
"127.62000","10.63518","0.08381"
"127.80000","10.65019","0.08449"
"127.98000","10.66514","0.08440"
"128.16000","10.68014","0.08496"
"128.34000","10.69515","0.08564"
"128.52000","10.71016","0.08517"
"128.70000","10.72517","0.08551"
"128.88000","10.74017","0.08544"
"129.06000","10.75518","0.08591"
"129.24000","10.77013","0.08650"
"129.42000","10.78514","0.08655"
"129.60000","10.80014","0.08737"
"129.78000","10.81521","0.08772"
"129.96000","10.83016","0.08841"
"130.14000","10.84516","0.08856"
"130.32000","10.86017","0.08913"
"130.50000","10.87524","0.08967"
"130.68000","10.89012","0.09021"
"130.86000","10.90513","0.09024"
"131.04000","10.92014","0.09036"
"131.22000","10.93515","0.09026"
"131.40000","10.95015","0.09073"
"131.58000","10.96516","0.09126"
"131.76000","10.98017","0.09125"
"131.94000","10.99512","0.09183"
"132.12000","11.01018","0.09167"
"132.30000","11.02513","0.09159"
"132.48000","11.04014","0.09206"
"132.66000","11.05520","0.09297"
"132.84000","11.07015","0.09309"
"133.02000","11.08522","0.09076"
"133.20000","11.10023","0.08970"
"133.38000","11.11511","0.09021"
"133.56000","11.13018","0.09038"
"133.74000","11.14519","0.09104"
"133.92000","11.16014","0.09125"
"134.10000","11.17520","0.09158"
"134.28000","11.19015","0.09157"
"134.46000","11.20516","0.09191"
"134.64000","11.22022","0.09206"
"134.82000","11.23517","0.09220"
"135.00000","11.25012","0.09287"
"135.18000","11.26513","0.09251"
"135.36000","11.28019","0.09271"
"135.54000","11.29508","0.09323"
"135.72000","11.31015","0.09429"
"135.90000","11.32521","0.09531"
"136.08000","11.34016","0.09494"
"136.26000","11.35517","0.09523"
"136.44000","11.37017","0.09557"
"136.62000","11.38512","0.09619"
"136.80000","11.40019","0.09707"
"136.98000","11.41520","0.09792"
"137.16000","11.43008","0.09754"
"137.34000","11.44515","0.09837"
"137.52000","11.46022","0.09878"
"137.70000","11.47511","0.09908"
"137.88000","11.49017","0.09987"
"138.06000","11.50518","0.09977"
"138.24000","11.52019","0.10039"
"138.42000","11.53513","0.09929"
"138.60000","11.55014","0.09992"
"138.78000","11.56515","0.09960"
"138.96000","11.58022","0.09956"
"139.14000","11.59522","0.09990"
"139.32000","11.61011","0.10037"
"139.50000","11.62518","0.10135"
"139.68000","11.64019","0.10161"
"139.86000","11.65513","0.10208"
"140.04000","11.67020","0.10226"
"140.22000","11.68515","0.10219"
"140.40000","11.70015","0.10202"
"140.58000","11.71516","0.10189"
"140.76000","11.73017","0.10295"
"140.94000","11.74512","0.10277"
"141.12000","11.76024","0.10293"
"141.30000","11.77519","0.10384"
"141.48000","11.79014","0.10340"
"141.66000","11.80520","0.10331"
"141.84000","11.82015","0.10413"
"142.02000","11.83510","0.10429"
"142.20000","11.85017","0.10453"
"142.38000","11.86523","0.10210"
"142.56000","11.88012","0.10268"
"142.74000","11.89519","0.10187"
"142.92000","11.91019","0.10298"
"143.10000","11.92514","0.10353"
"143.28000","11.94021","0.10293"
"143.46000","11.95516","0.08926"
"143.64000","11.97016","0.08879"
"143.82000","11.98517","0.08937"
"144.00000","12.00018","0.08923"
"144.18000","12.01512","0.08939"
"144.36000","12.03013","0.09061"
"144.54000","12.04520","0.09140"
"144.72000","12.06009","0.09181"
"144.90000","12.07521","0.09229"
"145.08000","12.09022","0.09178"
"145.26000","12.10511","0.09242"
"145.44000","12.12018","0.09162"
"145.62000","12.13518","0.09260"
"145.80000","12.15013","0.09242"
"145.98000","12.16520","0.09308"
"146.16000","12.18020","0.09450"
"146.34000","12.19509","0.09403"
"146.52000","12.21016","0.09363"
"146.70000","12.22523","0.09450"
"146.88000","12.24011","0.09516"
"147.06000","12.25518","0.09525"
"147.24000","12.27019","0.09545"
"147.42000","12.28513","0.09571"
"147.60000","12.30020","0.09481"
"147.78000","12.31521","0.09544"
"147.96000","12.33010","0.09712"
"148.14000","12.34522","0.09646"
"148.32000","12.36017","0.09704"
"148.50000","12.37512","0.09789"
"148.68000","12.39019","0.09784"
"148.86000","12.40519","0.09896"
"149.04000","12.42014","0.09919"
"149.22000","12.43521","0.09972"
"149.40000","12.45021","0.09989"
"149.58000","12.46510","0.10058"
"149.76000","12.48017","0.10141"
"149.94000","12.49518","0.10132"
"150.12000","12.51012","0.10269"
"150.30000","12.52525","0.10313"
"150.48000","12.54020","0.10393"
"150.66000","12.55509","0.10443"
"150.84000","12.57021","0.10474"
"151.02000","12.58522","0.10571"
"151.20000","12.60011","0.10593"
"151.38000","12.61517","0.10669"
"151.56000","12.63018","0.10701"
"151.74000","12.64513","0.10804"
"151.92000","12.66019","0.10826"
"152.10000","12.67514","0.10833"
"152.28000","12.69015","0.10890"
"152.46000","12.70522","0.10890"
"152.64000","12.72016","0.11018"
"152.82000","12.73505","0.11037"
"153.00000","12.75018","0.11100"
"153.18000","12.76519","0.11137"
"153.36000","12.78013","0.11150"
"153.54000","12.79520","0.11221"
"153.72000","12.81021","0.11248"
"153.90000","12.82515","0.11253"
"154.08000","12.84016","0.11298"
"154.26000","12.85517","0.11305"
"154.44000","12.87012","0.11364"
"154.62000","12.88518","0.11398"
"154.80000","12.90019","0.11426"
"154.98000","12.91508","0.11445"
"155.16000","12.93020","0.11521"
"155.34000","12.94515","0.11534"
"155.52000","12.96016","0.11561"
"155.70000","12.97517","0.11617"
"155.88000","12.99017","0.11604"
"156.06000","13.00512","0.11656"
"156.24000","13.02019","0.11656"
"156.42000","13.03514","0.11692"
"156.60000","13.05014","0.11686"
"156.78000","13.06521","0.11738"
"156.96000","13.08016","0.11783"
"157.14000","13.09510","0.11785"
"157.32000","13.11023","0.11783"
"157.50000","13.12512","0.11825"
"157.68000","13.14012","0.10766"
"157.86000","13.15513","0.10647"
"158.04000","13.17014","0.10797"
"158.22000","13.18515","0.10825"
"158.40000","13.20015","0.10837"
"158.58000","13.21516","0.10972"
"158.76000","13.23017","0.11002"
"158.94000","13.24518","0.11044"
"159.12000","13.26012","0.11146"
"159.30000","13.27507","0.11206"
"159.48000","13.29020","0.11283"
"159.66000","13.30521","0.11308"
"159.84000","13.32009","0.11318"
"160.02000","13.33522","0.11346"
"160.20000","13.35023","0.11435"
"160.38000","13.36517","0.11425"
"160.56000","13.38018","0.11475"
"160.74000","13.39513","0.11520"
"160.92000","13.41013","0.11499"
"161.10000","13.42514","0.11613"
"161.28000","13.44015","0.11630"
"161.46000","13.45516","0.11639"
"161.64000","13.47022","0.11694"
"161.82000","13.48517","0.11733"
"162.00000","13.50012","0.11751"
"162.18000","13.51519","0.11757"
"162.36000","13.53019","0.11778"
"162.54000","13.54514","0.11836"
"162.72000","13.56015","0.11863"
"162.90000","13.57521","0.11897"
"163.08000","13.59016","0.11891"
"163.26000","13.60517","0.11922"
"163.44000","13.62018","0.11942"
"163.62000","13.63512","0.11970"
"163.80000","13.65019","0.11994"
"163.98000","13.66514","0.12025"
"164.16000","13.68008","0.12013"
"164.34000","13.69521","0.12068"
"164.52000","13.71016","0.12077"
"164.70000","13.72517","0.12133"
"164.88000","13.74017","0.12168"
"165.06000","13.75518","0.12168"
"165.24000","13.77019","0.12187"
"165.42000","13.78513","0.12274"
"165.60000","13.80014","0.12309"
"165.78000","13.81515","0.12250"
"165.96000","13.83016","0.12273"
"166.14000","13.84510","0.12348"
"166.32000","13.86011","0.12337"
"166.50000","13.87518","0.12376"
"166.68000","13.89018","0.12405"
"166.86000","13.90513","0.12423"
"167.04000","13.92014","0.12464"
"167.22000","13.93521","0.12471"
"167.40000","13.95015","0.12531"
"167.58000","13.96516","0.12610"
"167.76000","13.98011","0.12695"
"167.94000","13.99518","0.12713"
"168.12000","14.01018","0.12834"
"168.30000","14.02519","0.12832"
"168.48000","14.04008","0.12895"
"168.66000","14.05514","0.12933"
"168.84000","14.07015","0.13028"
"169.02000","14.08510","0.13059"
"169.20000","14.10017","0.13096"
"169.38000","14.11517","0.13185"
"169.56000","14.13012","0.13187"
"169.74000","14.14519","0.13274"
"169.92000","14.16014","0.13313"
"170.10000","14.17514","0.13385"
"170.28000","14.19015","0.13420"
"170.46000","14.20510","0.13493"
"170.64000","14.22010","0.13488"
"170.82000","14.23517","0.13524"
"171.00000","14.25012","0.13638"
"171.18000","14.26512","0.13678"
"171.36000","14.28019","0.13775"
"171.54000","14.29520","0.13735"
"171.72000","14.31015","0.13763"
"171.90000","14.32515","0.13867"
"172.08000","14.34016","0.13988"
"172.26000","14.35511","0.14068"
"172.44000","14.37012","0.14160"
"172.62000","14.38518","0.14187"
"172.80000","14.40013","0.14267"
"172.98000","14.41520","0.14315"
"173.16000","14.43015","0.14342"
"173.34000","14.44515","0.12746"
"173.52000","14.46022","0.12824"
"173.70000","14.47517","0.12804"
"173.88000","14.49011","0.12947"
"174.06000","14.50518","0.13014"
"174.24000","14.52013","0.13072"
"174.42000","14.53519","0.13204"
"174.60000","14.55014","0.13227"
"174.78000","14.56515","0.13294"
"174.96000","14.58022","0.13195"
"175.14000","14.59516","0.13206"
"175.32000","14.61017","0.13308"
"175.50000","14.62518","0.13130"
"175.68000","14.64019","0.11947"
"175.86000","14.65513","0.11919"
"176.04000","14.67020","0.11932"
"176.22000","14.68515","0.12030"
"176.40000","14.70015","0.12059"
"176.58000","14.71516","0.12115"
"176.76000","14.73017","0.12208"
"176.94000","14.74512","0.12239"
"177.12000","14.76018","0.12333"
"177.30000","14.77519","0.12332"
"177.48000","14.79020","0.12496"
"177.66000","14.80514","0.12547"
"177.84000","14.82021","0.12541"
"178.02000","14.83516","0.12688"
"178.20000","14.85011","0.12818"
"178.38000","14.86517","0.12752"
"178.56000","14.88012","0.12925"
"178.74000","14.89513","0.12624"
"178.92000","14.91013","0.12744"
"179.10000","14.92514","0.12817"
"179.28000","14.94015","0.12972"
"179.46000","14.95516","0.12989"
"179.64000","14.97016","0.13051"
"179.82000","14.98517","0.13140"
"180.00000","15.00018","0.13272"
"180.18000","15.01513","0.13333"
"180.36000","15.03019","0.13475"
"180.54000","15.04520","0.13365"
"180.72000","15.06021","0.13422"
"180.90000","15.07515","0.13514"
"181.08000","15.09016","0.13630"
"181.26000","15.10517","0.13633"
"181.44000","15.12018","0.13749"
"181.62000","15.13518","0.13903"
"181.80000","15.15019","0.13968"
"181.98000","15.16514","0.13963"
"182.16000","15.18020","0.14078"
"182.34000","15.19515","0.14135"
"182.52000","15.21016","0.14158"
"182.70000","15.22517","0.14118"
"182.88000","15.24011","0.14202"
"183.06000","15.25518","0.14260"
"183.24000","15.27013","0.14377"
"183.42000","15.28514","0.14392"
"183.60000","15.30014","0.14415"
"183.78000","15.31521","0.14512"
"183.96000","15.33010","0.14606"
"184.14000","15.34516","0.14646"
"184.32000","15.36017","0.14710"
"184.50000","15.37512","0.14750"
"184.68000","15.39018","0.14775"
"184.86000","15.40519","0.14828"
"185.04000","15.42014","0.14839"
"185.22000","15.43515","0.14998"
"185.40000","15.45021","0.14669"
"185.58000","15.46516","0.14758"
"185.76000","15.48017","0.14744"
"185.94000","15.49518","0.14812"
"186.12000","15.51012","0.14829"
"186.30000","15.52519","0.14946"
"186.48000","15.54020","0.15010"
"186.66000","15.55515","0.15020"
"186.84000","15.57009","0.15102"
"187.02000","15.58522","0.15133"
"187.20000","15.60017","0.15193"
"187.38000","15.61511","0.15250"
"187.56000","15.63018","0.15300"
"187.74000","15.64513","0.15326"
"187.92000","15.66019","0.15432"
"188.10000","15.67520","0.15470"
"188.28000","15.69015","0.15508"
"188.46000","15.70521","0.15523"
"188.64000","15.72022","0.15554"
"188.82000","15.73517","0.15565"
"189.00000","15.75012","0.15634"
"189.18000","15.76518","0.15683"
"189.36000","15.78013","0.15717"
"189.54000","15.79520","0.15744"
"189.72000","15.81015","0.15756"
"189.90000","15.82515","0.15773"
"190.08000","15.84016","0.15838"
"190.26000","15.85517","0.15893"
"190.44000","15.87017","0.15943"
"190.62000","15.88518","0.15960"
"190.80000","15.90019","0.15976"
"190.98000","15.91514","0.16037"
"191.16000","15.93020","0.16072"
"191.34000","15.94515","0.16087"
"191.52000","15.96010","0.16146"
"191.70000","15.97516","0.16124"
"191.88000","15.99017","0.16189"
"192.06000","16.00518","0.16225"
"192.24000","16.02013","0.16230"
"192.42000","16.03519","0.16219"
"192.60000","16.05014","0.16292"
"192.78000","16.06521","0.16270"
"192.96000","16.08022","0.16317"
"193.14000","16.09516","0.16342"
"193.32000","16.11017","0.16383"
"193.50000","16.12518","0.16412"
"193.68000","16.14006","0.16505"
"193.86000","16.15519","0.16521"
"194.04000","16.17020","0.16558"
"194.22000","16.18515","0.16592"
"194.40000","16.20021","0.16586"
"194.58000","16.21516","0.16651"
"194.76000","16.23011","0.16647"
"194.94000","16.24524","0.16649"
"195.12000","16.26018","0.16723"
"195.30000","16.27513","0.16750"
"195.48000","16.29020","0.16773"
"195.66000","16.30520","0.16806"
"195.84000","16.32015","0.16814"
"196.02000","16.33516","0.11846"
"196.20000","16.35016","0.11972"
"196.38000","16.36511","0.11878"
"196.56000","16.38024","0.11960"
"196.74000","16.39519","0.11988"
"196.92000","16.41014","0.11999"
"197.10000","16.42520","0.12074"
"197.28000","16.44021","0.12095"
"197.46000","16.45510","0.12213"
"197.64000","16.47016","0.12212"
"197.82000","16.48523","0.12183"
"198.00000","16.50006","0.12351"
"198.18000","16.51518","0.12397"
"198.36000","16.53025","0.12431"
"198.54000","16.54514","0.12634"
"198.72000","16.56015","0.12515"
"198.90000","16.57515","0.12704"
"199.08000","16.59016","0.12726"
"199.26000","16.60517","0.12794"
"199.44000","16.62017","0.12900"
"199.62000","16.63512","0.12786"
"199.80000","16.65025","0.12995"
"199.98000","16.66514","0.12907"
"200.16000","16.68008","0.12928"
"200.34000","16.69515","0.13140"
"200.52000","16.71010","0.13032"
"200.70000","16.72510","0.13135"
"200.88000","16.74017","0.13271"
"201.06000","16.75518","0.13086"
"201.24000","16.77013","0.13202"
"201.42000","16.78519","0.13274"
"201.60000","16.80014","0.13292"
"201.78000","16.81509","0.13437"
"201.96000","16.83022","0.13443"
"202.14000","16.84516","0.13410"
"202.32000","16.86005","0.13410"
"202.50000","16.87518","0.13422"
"202.68000","16.89025","0.13457"
"202.86000","16.90507","0.13605"
"203.04000","16.92020","0.13499"
"203.22000","16.93515","0.13619"
"203.40000","16.95009","0.13521"
"203.58000","16.96522","0.13601"
"203.76000","16.98017","0.13674"
"203.94000","16.99517","0.13665"
"204.12000","17.01018","0.13754"
"204.30000","17.02519","0.13714"
"204.48000","17.04014","0.13754"
"204.66000","17.05514","0.13897"
"204.84000","17.07015","0.13959"
"205.02000","17.08516","0.13995"
"205.20000","17.10016","0.14115"
"205.38000","17.11523","0.14110"
"205.56000","17.13012","0.14222"
"205.74000","17.14519","0.14304"
"205.92000","17.16014","0.14339"
"206.10000","17.17514","0.14421"
"206.28000","17.19015","0.14467"
"206.46000","17.20515","0.14463"
"206.64000","17.22010","0.14583"
"206.82000","17.23523","0.14666"
"207.00000","17.25018","0.14752"
"207.18000","17.26512","0.14764"
"207.36000","17.28019","0.14804"
"207.54000","17.29520","0.14946"
"207.72000","17.31009","0.14944"
"207.90000","17.32515","0.15025"
"208.08000","17.34016","0.15046"
"208.26000","17.35511","0.15166"
"208.44000","17.37017","0.15065"
"208.62000","17.38518","0.15155"
"208.80000","17.40013","0.15198"
"208.98000","17.41520","0.15247"
"209.16000","17.43008","0.15283"
"209.34000","17.44509","0.15332"
"209.52000","17.46016","0.15381"
"209.70000","17.47523","0.15407"
"209.88000","17.49017","0.15416"
"210.06000","17.50518","0.15462"
"210.24000","17.52019","0.15548"
"210.42000","17.53513","0.15533"
"210.60000","17.55020","0.15562"
"210.78000","17.56509","0.15590"
"210.96000","17.58010","0.14465"
"211.14000","17.59522","0.14463"
"211.32000","17.61017","0.14497"
"211.50000","17.62506","0.14619"
"211.68000","17.64018","0.14704"
"211.86000","17.65519","0.14779"
"212.04000","17.67008","0.14919"
"212.22000","17.68521","0.14944"
"212.40000","17.70015","0.15057"
"212.58000","17.71510","0.15085"
"212.76000","17.73023","0.15188"
"212.94000","17.74512","0.15235"
"213.12000","17.76018","0.15276"
"213.30000","17.77519","0.15357"
"213.48000","17.79014","0.15392"
"213.66000","17.80514","0.15445"
"213.84000","17.82021","0.15535"
"214.02000","17.83516","0.15575"
"214.20000","17.85016","0.15631"
"214.38000","17.86517","0.15634"
"214.56000","17.88018","0.15713"
"214.74000","17.89519","0.15754"
"214.92000","17.91013","0.15819"
"215.10000","17.92514","0.15815"
"215.28000","17.94015","0.15892"
"215.46000","17.95522","0.15924"
"215.64000","17.97016","0.15964"
"215.82000","17.98511","0.15973"
"216.00000","18.00018","0.16023"
"216.18000","18.01518","0.16063"
"216.36000","18.03013","0.16100"
"216.54000","18.04514","0.16154"
"216.72000","18.06021","0.16162"
"216.90000","18.07515","0.16246"
"217.08000","18.09016","0.16244"
"217.26000","18.10511","0.16279"
"217.44000","18.12017","0.16302"
"217.62000","18.13518","0.16309"
"217.80000","18.15013","0.16373"
"217.98000","18.16514","0.16371"
"218.16000","18.18014","0.16442"
"218.34000","18.19515","0.16404"
"218.52000","18.21010","0.16498"
"218.70000","18.22516","0.16503"
"218.88000","18.24017","0.16514"
"219.06000","18.25512","0.16561"
"219.24000","18.27019","0.16593"
"219.42000","18.28514","0.16600"
"219.60000","18.30020","0.16649"
"219.78000","18.31515","0.16683"
"219.96000","18.33015","0.16689"
"220.14000","18.34510","0.16734"
"220.32000","18.36017","0.16740"
"220.50000","18.37518","0.16755"
"220.68000","18.39013","0.16794"
"220.86000","18.40525","0.16815"
"221.04000","18.42020","0.16832"
"221.22000","18.43515","0.16873"
"221.40000","18.45021","0.16937"
"221.58000","18.46510","0.16927"
"221.76000","18.48017","0.17007"
"221.94000","18.49517","0.17046"
"222.12000","18.51012","0.17087"
"222.30000","18.52513","0.17007"
"222.48000","18.54020","0.16967"
"222.66000","18.55514","0.17028"
"222.84000","18.57009","0.17083"
"223.02000","18.58522","0.17125"
"223.20000","18.60017","0.17197"
"223.38000","18.61511","0.17293"
"223.56000","18.63012","0.17360"
"223.74000","18.64519","0.17431"
"223.92000","18.66013","0.17412"
"224.10000","18.67514","0.17520"
"224.28000","18.69015","0.17448"
"224.46000","18.70516","0.17313"
"224.64000","18.72016","0.17316"
"224.82000","18.73517","0.17365"
"225.00000","18.75012","0.16633"
"225.18000","18.76518","0.16727"
"225.36000","18.78013","0.16765"
"225.54000","18.79520","0.16751"
"225.72000","18.81015","0.16825"
"225.90000","18.82515","0.16883"
"226.08000","18.84016","0.16904"
"226.26000","18.85517","0.16988"
"226.44000","18.87012","0.16890"
"226.62000","18.88518","0.16930"
"226.80000","18.90019","0.17010"
"226.98000","18.91514","0.17078"
"227.16000","18.93014","0.17110"
"227.34000","18.94521","0.17145"
"227.52000","18.96016","0.17221"
"227.70000","18.97516","0.17242"
"227.88000","18.99017","0.17300"
"228.06000","19.00518","0.17410"
"228.24000","19.02019","0.17444"
"228.42000","19.03514","0.17534"
"228.60000","19.05014","0.17595"
"228.78000","19.06521","0.17670"
"228.96000","19.08015","0.17714"
"229.14000","19.09516","0.17822"
"229.32000","19.11017","0.17858"
"229.50000","19.12518","0.17961"
"229.68000","19.14013","0.18072"
"229.86000","19.15513","0.18154"
"230.04000","19.17020","0.18306"
"230.22000","19.18521","0.18310"
"230.40000","19.20015","0.18354"
"230.58000","19.21516","0.18476"
"230.76000","19.23011","0.18603"
"230.94000","19.24517","0.18446"
"231.12000","19.26018","0.18573"
"231.30000","19.27513","0.18388"
"231.48000","19.29014","0.18394"
"231.66000","19.30520","0.18585"
"231.84000","19.32015","0.18587"
"232.02000","19.33516","0.18604"
"232.20000","19.35017","0.18631"
"232.38000","19.36511","0.18694"
"232.56000","19.38012","0.17349"
"232.74000","19.39519","0.17424"
"232.92000","19.41013","0.17489"
"233.10000","19.42514","0.17493"
"233.28000","19.44015","0.17547"
"233.46000","19.45515","0.17560"
"233.64000","19.47016","0.17675"
"233.82000","19.48517","0.17825"
"234.00000","19.50012","0.17852"
"234.18000","19.51518","0.17873"
"234.36000","19.53019","0.18103"
"234.54000","19.54514","0.18216"
"234.72000","19.56014","0.18271"
"234.90000","19.57515","0.18353"
"235.08000","19.59016","0.18450"
"235.26000","19.60517","0.18597"
"235.44000","19.62017","0.18734"
"235.62000","19.63512","0.18853"
"235.80000","19.65019","0.19017"
"235.98000","19.66514","0.19245"
"236.16000","19.68014","0.19264"
"236.34000","19.69515","0.19409"
"236.52000","19.71016","0.19568"
"236.70000","19.72511","0.19765"
"236.88000","19.74017","0.19932"
"237.06000","19.75518","0.20218"
"237.24000","19.77013","0.20321"
"237.42000","19.78519","0.20281"
"237.60000","19.80014","0.20375"
"237.78000","19.81515","0.20564"
"237.96000","19.83016","0.20669"
"238.14000","19.84522","0.20679"
"238.32000","19.86017","0.20848"
"238.50000","19.87518","0.21008"
"238.68000","19.89018","0.20796"
"238.86000","19.90513","0.20564"
"239.04000","19.92014","0.20670"
"239.22000","19.93520","0.20760"
"239.40000","19.95015","0.20855"
"239.58000","19.96516","0.21054"
"239.76000","19.98017","0.21072"
"239.94000","19.99512","0.20852"
"240.12000","20.01018","0.21024"
"240.30000","20.02519","0.21086"
"240.48000","20.04020","0.21231"
"240.66000","20.05514","0.21236"
"240.84000","20.07015","0.21309"
"241.02000","20.08516","0.21396"
"241.20000","20.10016","0.21361"
"241.38000","20.11517","0.21514"
"241.56000","20.13018","0.21537"
"241.74000","20.14519","0.21438"
"241.92000","20.16019","0.21540"
"242.10000","20.17514","0.21606"
"242.28000","20.19021","0.21071"
"242.46000","20.20521","0.20657"
"242.64000","20.22016","0.20473"
"242.82000","20.23517","0.20217"
"243.00000","20.25018","0.20428"
"243.18000","20.26513","0.20629"
"243.36000","20.28019","0.20834"
"243.54000","20.29520","0.20966"
"243.72000","20.31014","0.20162"
"243.90000","20.32515","0.20260"
"244.08000","20.34016","0.20424"
"244.26000","20.35511","0.20580"
"244.44000","20.37017","0.20751"
"244.62000","20.38518","0.20885"
"244.80000","20.40013","0.21073"
"244.98000","20.41520","0.21171"
"245.16000","20.43014","0.21213"
"245.34000","20.44509","0.21375"
"245.52000","20.46016","0.21416"
"245.70000","20.47522","0.21537"
"245.88000","20.49011","0.21616"
"246.06000","20.50524","0.21676"
"246.24000","20.52019","0.21800"
"246.42000","20.53507","0.21854"
"246.60000","20.55020","0.21908"
"246.78000","20.56515","0.21982"
"246.96000","20.58010","0.22086"
"247.14000","20.59516","0.22077"
"247.32000","20.61017","0.22190"
"247.50000","20.62506","0.22202"
"247.68000","20.64018","0.22229"
"247.86000","20.65525","0.22274"
"248.04000","20.67014","0.22335"
"248.22000","20.68514","0.22376"
"248.40000","20.70015","0.22413"
"248.58000","20.71510","0.22464"
"248.76000","20.73017","0.22460"
"248.94000","20.74523","0.22496"
"249.12000","20.76012","0.22560"
"249.30000","20.77519","0.22591"
"249.48000","20.79020","0.22615"
"249.66000","20.80508","0.22690"
"249.84000","20.82021","0.22647"
"250.02000","20.83516","0.22749"
"250.20000","20.85016","0.22787"
"250.38000","20.86517","0.22902"
"250.56000","20.88012","0.22994"
"250.74000","20.89513","0.23004"
"250.92000","20.91019","0.23136"
"251.10000","20.92514","0.23218"
"251.28000","20.94009","0.23310"
"251.46000","20.95522","0.23446"
"251.64000","20.97010","0.23527"
"251.82000","20.98511","0.23642"
"252.00000","21.00018","0.23717"
"252.18000","21.01518","0.23830"
"252.36000","21.03013","0.23892"
"252.54000","21.04514","0.23991"
"252.72000","21.06015","0.24124"
"252.90000","21.07515","0.24158"
"253.08000","21.09022","0.24307"
"253.26000","21.10517","0.24377"
"253.44000","21.12011","0.24486"
"253.62000","21.13518","0.24578"
"253.80000","21.15019","0.24661"
"253.98000","21.16508","0.24782"
"254.16000","21.18020","0.24832"
"254.34000","21.19521","0.24937"
"254.52000","21.21010","0.25070"
"254.70000","21.22517","0.25163"
"254.88000","21.24023","0.25219"
"255.06000","21.25512","0.25345"
"255.24000","21.27024","0.25291"
"255.42000","21.28513","0.25317"
"255.60000","21.30014","0.25481"
"255.78000","21.31521","0.25536"
"255.96000","21.33021","0.25618"
"256.14000","21.34510","0.25693"
"256.32000","21.36017","0.25609"
"256.50000","21.37518","0.25707"
"256.68000","21.39007","0.25642"
"256.86000","21.40519","0.25762"
"257.04000","21.42020","0.25825"
"257.22000","21.43514","0.25923"
"257.40000","21.45015","0.25924"
"257.58000","21.46522","0.26005"
"257.76000","21.48011","0.26000"
"257.94000","21.49517","0.25971"
"258.12000","21.51018","0.25905"
"258.30000","21.52507","0.25953"
"258.48000","21.54020","0.26052"
"258.66000","21.55520","0.26075"
"258.84000","21.57009","0.26181"
"259.02000","21.58516","0.26269"
"259.20000","21.60016","0.26297"
"259.38000","21.61517","0.26374"
"259.56000","21.63018","0.26434"
"259.74000","21.64513","0.26539"
"259.92000","21.66013","0.26546"
"260.10000","21.67514","0.26604"
"260.28000","21.69009","0.26664"
"260.46000","21.70510","0.26692"
"260.64000","21.72022","0.26742"
"260.82000","21.73517","0.26781"
"261.00000","21.75012","0.26785"
"261.18000","21.76518","0.26836"
"261.36000","21.78019","0.26886"
"261.54000","21.79514","0.26919"
"261.72000","21.81021","0.26946"
"261.90000","21.82515","0.26970"
"262.08000","21.84016","0.27008"
"262.26000","21.85517","0.27002"
"262.44000","21.87012","0.27046"
"262.62000","21.88512","0.27097"
"262.80000","21.90025","0.27070"
"262.98000","21.91520","0.27111"
"263.16000","21.93008","0.27151"
"263.34000","21.94521","0.27200"
"263.52000","21.96022","0.27216"
"263.70000","21.97511","0.27239"
"263.88000","21.99023","0.27254"
"264.06000","22.00518","0.27301"
"264.24000","22.02013","0.27318"
"264.42000","22.03519","0.27312"
"264.60000","22.05014","0.27406"
"264.78000","22.06515","0.27421"
"264.96000","22.08015","0.27483"
"265.14000","22.09516","0.27468"
"265.32000","22.11011","0.27497"
"265.50000","22.12518","0.27585"
"265.68000","22.14013","0.27617"
"265.86000","22.15513","0.27709"
"266.04000","22.17014","0.27778"
"266.22000","22.18521","0.27707"
"266.40000","22.20015","0.27696"
"266.58000","22.21516","0.27733"
"266.76000","22.23017","0.27792"
"266.94000","22.24512","0.27800"
"267.12000","22.26018","0.27860"
"267.25800","22.27172","0.27901"