File: Force_trajectories/170212_2/Specimen_RawData_4.csv
End date,"2/12/2017"
Specimen label,"9CG_74"
Maximum Load,"0.06649",N

Time,Extension,Load
(s),(mm),(N)
"0.00000","7.26742","0.03015"
"0.34200","7.29588","0.02981"
"0.68400","7.32470","0.02987"
"1.02600","7.35310","0.02946"
"1.36800","7.38162","0.03062"
"1.71000","7.41014","0.03032"
"2.05200","7.43859","0.03026"
"2.39400","7.46712","0.03081"
"2.73600","7.49557","0.03079"
"3.07800","7.52409","0.03091"
"3.42000","7.55261","0.03074"
"3.76200","7.58107","0.03091"
"4.10400","7.60965","0.03077"
"4.44600","7.63817","0.03048"
"4.78800","7.66657","0.03118"
"5.13000","7.69515","0.03082"
"5.47200","7.72361","0.03114"
"5.81400","7.75207","0.03112"
"6.15600","7.78065","0.03108"
"6.49800","7.80905","0.03074"
"6.84000","7.83763","0.03124"
"7.18200","7.86609","0.03177"
"7.52400","7.89455","0.03141"
"7.86600","7.92313","0.03197"
"8.20800","7.95159","0.03117"
"8.55000","7.98011","0.03170"
"8.89200","8.00869","0.03193"
"9.23400","8.03715","0.03130"
"9.57600","8.06555","0.03186"
"9.91800","8.09413","0.03215"
"10.26000","8.12265","0.03141"
"10.60200","8.15111","0.03180"
"10.94400","8.17963","0.03164"
"11.28600","8.20809","0.03157"
"11.62800","8.23661","0.03247"
"11.97000","8.26519","0.03199"
"12.31200","8.29353","0.03236"
"12.65400","8.32216","0.03224"
"12.99600","8.35063","0.03217"
"13.33800","8.37908","0.03184"
"13.68000","8.40766","0.03188"
"14.02200","8.43612","0.03288"
"14.36400","8.46458","0.03250"
"14.70600","8.49316","0.03271"
"15.04800","8.52156","0.03203"
"15.39000","8.55014","0.03260"
"15.73200","8.57866","0.03238"
"16.07400","8.60706","0.03201"
"16.41600","8.63564","0.03217"
"16.75800","8.66410","0.03270"
"17.10000","8.69262","0.03274"
"17.44200","8.72114","0.03262"
"17.78400","8.74960","0.03269"
"18.12600","8.77806","0.03291"
"18.46800","8.80670","0.03287"
"18.81000","8.83504","0.03317"
"19.15200","8.86368","0.03245"
"19.49400","8.89214","0.03246"
"19.83600","8.92054","0.03240"
"20.17800","8.94918","0.03247"
"20.52000","8.97764","0.03308"
"20.86200","9.00604","0.03322"
"21.20400","9.03462","0.03231"
"21.54600","9.06308","0.03324"
"21.88800","9.09160","0.03275"
"22.23000","9.12018","0.03316"
"22.57200","9.14858","0.03324"
"22.91400","9.17715","0.03373"
"23.25600","9.20568","0.03327"
"23.59800","9.23413","0.03306"
"23.94000","9.26265","0.03272"
"24.28200","9.29111","0.03291"
"24.62400","9.31957","0.03340"
"24.96600","9.34815","0.03280"
"25.30800","9.37655","0.03278"
"25.65000","9.40513","0.03231"
"25.99200","9.43365","0.03274"
"26.33400","9.46211","0.03271"
"26.67600","9.49057","0.03227"
"27.01800","9.51915","0.03249"
"27.36000","9.54761","0.03330"
"27.70200","9.57613","0.03299"
"28.04400","9.60465","0.03312"
"28.38600","9.63311","0.03303"
"28.72800","9.66163","0.03300"
"29.07000","9.69015","0.03281"
"29.41200","9.71861","0.03344"
"29.75400","9.74719","0.03360"
"30.09600","9.77559","0.03292"
"30.43800","9.80411","0.03349"
"30.78000","9.83263","0.03364"
"31.12200","9.86109","0.03340"
"31.46400","9.88961","0.03296"
"31.80600","9.91813","0.03358"
"32.14800","9.94659","0.03326"
"32.49000","9.97511","0.03345"
"32.83200","10.00363","0.03322"
"33.17400","10.03215","0.03333"
"33.51600","10.06066","0.03303"
"33.85800","10.08906","0.03343"
"34.20000","10.11764","0.03344"
"34.54200","10.14616","0.03304"
"34.88400","10.17462","0.03318"
"35.22600","10.20308","0.03371"
"35.56800","10.23154","0.03309"
"35.91000","10.26006","0.03343"
"36.25200","10.28864","0.03313"
"36.59400","10.31710","0.03366"
"36.93600","10.34562","0.03364"
"37.27800","10.37414","0.03344"
"37.62000","10.40254","0.03411"
"37.96200","10.43118","0.03368"
"38.30400","10.45964","0.03334"
"38.64600","10.48804","0.03352"
"38.98800","10.51668","0.03322"
"39.33000","10.54508","0.03338"
"39.67200","10.57360","0.03269"
"40.01400","10.60218","0.03311"
"40.35600","10.63052","0.03337"
"40.69800","10.65916","0.03354"
"41.04000","10.68768","0.03350"
"41.38200","10.71608","0.03343"
"41.72400","10.74460","0.03317"
"42.06600","10.77312","0.03333"
"42.40800","10.80164","0.03338"
"42.75000","10.83016","0.03313"
"43.09200","10.85856","0.03386"
"43.43400","10.88713","0.03316"
"43.77600","10.91560","0.03308"
"44.11800","10.94406","0.03302"
"44.46000","10.97263","0.03346"
"44.80200","11.00115","0.03353"
"45.14400","11.02955","0.03368"
"45.48600","11.05819","0.03339"
"45.82800","11.08665","0.03331"
"46.17000","11.11505","0.03380"
"46.51200","11.14363","0.03382"
"46.85400","11.17209","0.03398"
"47.19600","11.20061","0.03402"
"47.53800","11.22913","0.03341"
"47.88000","11.25759","0.03386"
"48.22200","11.28611","0.03410"
"48.56400","11.31463","0.03421"
"48.90600","11.34309","0.03378"
"49.24800","11.37167","0.03394"
"49.59000","11.40013","0.03401"
"49.93200","11.42859","0.03338"
"50.27400","11.45711","0.03399"
"50.61600","11.48563","0.03321"
"50.95800","11.51409","0.03393"
"51.30000","11.54267","0.03417"
"51.64200","11.57107","0.03414"
"51.98400","11.59965","0.03407"
"52.32600","11.62817","0.03380"
"52.66800","11.65657","0.03371"
"53.01000","11.68515","0.03459"
"53.35200","11.71361","0.03459"
"53.69400","11.74207","0.03387"
"54.03600","11.77065","0.03380"
"54.37800","11.79911","0.03393"
"54.72000","11.82757","0.03426"
"55.06200","11.85614","0.03456"
"55.40400","11.88454","0.03433"
"55.74600","11.91312","0.03423"
"56.08800","11.94164","0.03415"
"56.43000","11.97010","0.03444"
"56.77200","11.99862","0.03388"
"57.11400","12.02708","0.03452"
"57.45600","12.05560","0.03473"
"57.79800","12.08418","0.03441"
"58.14000","12.11258","0.03468"
"58.48200","12.14116","0.03394"
"58.82400","12.16962","0.03442"
"59.16600","12.19802","0.03480"
"59.50800","12.22666","0.03438"
"59.85000","12.25512","0.03482"
"60.19200","12.28364","0.03428"
"60.53400","12.31210","0.03469"
"60.87600","12.34056","0.03468"
"61.21800","12.36908","0.03441"
"61.56000","12.39760","0.03459"
"61.90200","12.42612","0.03453"
"62.24400","12.45464","0.03468"
"62.58600","12.48310","0.03449"
"62.92800","12.51162","0.03431"
"63.27000","12.54014","0.03464"
"63.61200","12.56860","0.03473"
"63.95400","12.59706","0.03475"
"64.29600","12.62564","0.03454"
"64.63800","12.65416","0.03414"
"64.98000","12.68262","0.03445"
"65.32200","12.71108","0.03462"
"65.66400","12.73960","0.03443"
"66.00600","12.76812","0.03446"
"66.34800","12.79663","0.03473"
"66.69000","12.82509","0.03473"
"67.03200","12.85361","0.03416"
"67.37400","12.88213","0.03470"
"67.71600","12.91059","0.03473"
"68.05800","12.93911","0.03490"
"68.40000","12.96763","0.03483"
"68.74200","12.99609","0.03533"
"69.08400","13.02461","0.03501"
"69.42600","13.05307","0.03486"
"69.76800","13.08159","0.03522"
"70.11000","13.11017","0.03504"
"70.45200","13.13857","0.03512"
"70.79400","13.16709","0.03515"
"71.13600","13.19567","0.03521"
"71.47800","13.22407","0.03468"
"71.82000","13.25265","0.03496"
"72.16200","13.28111","0.03558"
"72.50400","13.30957","0.03482"
"72.84600","13.33821","0.03476"
"73.18800","13.36661","0.03552"
"73.53000","13.39513","0.03534"
"73.87200","13.42365","0.03532"
"74.21400","13.45205","0.03519"
"74.55600","13.48069","0.03542"
"74.89800","13.50915","0.03590"
"75.24000","13.53761","0.03536"
"75.58200","13.56618","0.03528"
"75.92400","13.59465","0.03563"
"76.26600","13.62311","0.03573"
"76.60800","13.65162","0.03508"
"76.95000","13.68003","0.03600"
"77.29200","13.70860","0.03562"
"77.63400","13.73718","0.03614"
"77.97600","13.76558","0.03561"
"78.31800","13.79410","0.03507"
"78.66000","13.82262","0.03597"
"79.00200","13.85108","0.03519"
"79.34400","13.87966","0.03545"
"79.68600","13.90812","0.03535"
"80.02800","13.93664","0.03570"
"80.37000","13.96510","0.03567"
"80.71200","13.99356","0.03547"
"81.05400","14.02214","0.03589"
"81.39600","14.05066","0.03589"
"81.73800","14.07906","0.03538"
"82.08000","14.10764","0.03514"
"82.42200","14.13610","0.03527"
"82.76400","14.16462","0.03530"
"83.10600","14.19314","0.03539"
"83.44800","14.22160","0.03518"
"83.79000","14.25006","0.03593"
"84.13200","14.27864","0.03608"
"84.47400","14.30716","0.03585"
"84.81600","14.33562","0.03570"
"85.15800","14.36414","0.03558"
"85.50000","14.39260","0.03505"
"85.84200","14.42112","0.03463"
"86.18400","14.44964","0.03490"
"86.52600","14.47810","0.03506"
"86.86800","14.50662","0.03486"
"87.21000","14.53513","0.03507"
"87.55200","14.56359","0.03511"
"87.89400","14.59217","0.03521"
"88.23600","14.62057","0.03576"
"88.57800","14.64909","0.03559"
"88.92000","14.67767","0.03514"
"89.26200","14.70607","0.03537"
"89.60400","14.73465","0.03598"
"89.94600","14.76317","0.03574"
"90.28800","14.79163","0.03532"
"90.63000","14.82015","0.03552"
"90.97200","14.84861","0.03503"
"91.31400","14.87713","0.03518"
"91.65600","14.90565","0.03575"
"91.99800","14.93405","0.03535"
"92.34000","14.96263","0.03581"
"92.68200","14.99109","0.03551"
"93.02400","15.01955","0.03554"
"93.36600","15.04819","0.03600"
"93.70800","15.07665","0.03587"
"94.05000","15.10511","0.03580"
"94.39200","15.13363","0.03573"
"94.73400","15.16209","0.03630"
"95.07600","15.19061","0.03581"
"95.41800","15.21913","0.03601"
"95.76000","15.24753","0.03587"
"96.10200","15.27617","0.03566"
"96.44400","15.30463","0.03527"
"96.78600","15.33303","0.03555"
"97.12800","15.36166","0.03509"
"97.47000","15.39013","0.03590"
"97.81200","15.41859","0.03531"
"98.15400","15.44710","0.03599"
"98.49600","15.47562","0.03644"
"98.83800","15.50414","0.03578"
"99.18000","15.53266","0.03602"
"99.52200","15.56106","0.03599"
"99.86400","15.58958","0.03650"
"100.20600","15.61810","0.03640"
"100.54800","15.64656","0.03566"
"100.89000","15.67514","0.03585"
"101.23200","15.70360","0.03629"
"101.57400","15.73212","0.03625"
"101.91600","15.76058","0.03658"
"102.25800","15.78910","0.03655"
"102.60000","15.81762","0.03630"
"102.94200","15.84614","0.03634"
"103.28400","15.87460","0.03686"
"103.62600","15.90312","0.03670"
"103.96800","15.93164","0.03659"
"104.31000","15.96010","0.03643"
"104.65200","15.98862","0.03659"
"104.99400","16.01714","0.03662"
"105.33600","16.04560","0.03670"
"105.67800","16.07412","0.03664"
"106.02000","16.10258","0.03634"
"106.36200","16.13110","0.03681"
"106.70400","16.15968","0.03732"
"107.04600","16.18802","0.03722"
"107.38800","16.21659","0.03673"
"107.73000","16.24517","0.03712"
"108.07200","16.27357","0.03726"
"108.41400","16.30215","0.03652"
"108.75600","16.33061","0.03728"
"109.09800","16.35907","0.03690"
"109.44000","16.38759","0.03691"
"109.78200","16.41611","0.03777"
"110.12400","16.44463","0.03713"
"110.46600","16.47309","0.03692"
"110.80800","16.50155","0.03744"
"111.15000","16.53013","0.03720"
"111.49200","16.55859","0.03731"
"111.83400","16.58711","0.03737"
"112.17600","16.61563","0.03779"
"112.51800","16.64409","0.03691"
"112.86000","16.67261","0.03719"
"113.20200","16.70113","0.03762"
"113.54400","16.72959","0.03708"
"113.88600","16.75811","0.03782"
"114.22800","16.78663","0.03801"
"114.57000","16.81509","0.03747"
"114.91200","16.84361","0.03706"
"115.25400","16.87213","0.03709"
"115.59600","16.90059","0.03746"
"115.93800","16.92917","0.03744"
"116.28000","16.95757","0.03739"
"116.62200","16.98615","0.03764"
"116.96400","17.01467","0.03773"
"117.30600","17.04307","0.03789"
"117.64800","17.07165","0.03792"
"117.99000","17.10011","0.03761"
"118.33200","17.12856","0.03783"
"118.67400","17.15714","0.03755"
"119.01600","17.18560","0.03710"
"119.35800","17.21406","0.03763"
"119.70000","17.24258","0.03760"
"120.04200","17.27110","0.03781"
"120.38400","17.29956","0.03747"
"120.72600","17.32808","0.03805"
"121.06800","17.35660","0.03724"
"121.41000","17.38512","0.03712"
"121.75200","17.41364","0.03704"
"122.09400","17.44210","0.03688"
"122.43600","17.47062","0.03727"
"122.77800","17.49914","0.03689"
"123.12000","17.52760","0.03731"
"123.46200","17.55612","0.03748"
"123.80400","17.58464","0.03742"
"124.14600","17.61310","0.03704"
"124.48800","17.64168","0.03758"
"124.83000","17.67002","0.03788"
"125.17200","17.69860","0.03728"
"125.51400","17.72718","0.03770"
"125.85600","17.75558","0.03775"
"126.19800","17.78416","0.03775"
"126.54000","17.81262","0.03763"
"126.88200","17.84108","0.03741"
"127.22400","17.86966","0.03675"
"127.56600","17.89812","0.03690"
"127.90800","17.92657","0.03661"
"128.25000","17.95516","0.03656"
"128.59200","17.98355","0.03711"
"128.93400","18.01213","0.03693"
"129.27600","18.04066","0.03730"
"129.61800","18.06906","0.03782"
"129.96000","18.09763","0.03700"
"130.30200","18.12615","0.03755"
"130.64400","18.15461","0.03728"
"130.98600","18.18313","0.03785"
"131.32800","18.21159","0.03790"
"131.67000","18.24017","0.03803"
"132.01200","18.26863","0.03767"
"132.35400","18.29703","0.03782"
"132.69600","18.32567","0.03772"
"133.03800","18.35419","0.03772"
"133.38000","18.38259","0.03755"
"133.72200","18.41111","0.03787"
"134.06400","18.43963","0.03768"
"134.40600","18.46809","0.03807"
"134.74800","18.49661","0.03785"
"135.09000","18.52513","0.03777"
"135.43200","18.55365","0.03806"
"135.77400","18.58211","0.03784"
"136.11600","18.61063","0.03796"
"136.45800","18.63915","0.03834"
"136.80000","18.66767","0.03817"
"137.14200","18.69613","0.03841"
"137.48400","18.72459","0.03840"
"137.82600","18.75311","0.03880"
"138.16800","18.78157","0.03808"
"138.51000","18.81015","0.03787"
"138.85200","18.83860","0.03817"
"139.19400","18.86707","0.03860"
"139.53600","18.89565","0.03869"
"139.87800","18.92410","0.03839"
"140.22000","18.95263","0.03828"
"140.56200","18.98114","0.03827"
"140.90400","19.00954","0.03803"
"141.24600","19.03812","0.03846"
"141.58800","19.06664","0.03883"
"141.93000","19.09516","0.03849"
"142.27200","19.12362","0.03899"
"142.61400","19.15208","0.03837"
"142.95600","19.18054","0.03937"
"143.29800","19.20912","0.03834"
"143.64000","19.23752","0.03900"
"143.98200","19.26616","0.03892"
"144.32400","19.29462","0.03850"
"144.66600","19.32308","0.03965"
"145.00800","19.35166","0.03921"
"145.35000","19.38012","0.03916"
"145.69200","19.40858","0.03954"
"146.03400","19.43710","0.03940"
"146.37600","19.46556","0.03907"
"146.71800","19.49414","0.03891"
"147.06000","19.52266","0.03929"
"147.40200","19.55100","0.03907"
"147.74400","19.57964","0.03917"
"148.08600","19.60810","0.03923"
"148.42800","19.63656","0.03976"
"148.77000","19.66508","0.03968"
"149.11200","19.69360","0.03988"
"149.45400","19.72211","0.03907"
"149.79600","19.75064","0.04000"
"150.13800","19.77909","0.03973"
"150.48000","19.80767","0.03999"
"150.82200","19.83614","0.03984"
"151.16400","19.86459","0.04048"
"151.50600","19.89311","0.04041"
"151.84800","19.92157","0.04055"
"152.19000","19.95009","0.03961"
"152.53200","19.97861","0.04005"
"152.87400","20.00713","0.04023"
"153.21600","20.03559","0.04006"
"153.55800","20.06405","0.04081"
"153.90000","20.09257","0.04043"
"154.24200","20.12115","0.04055"
"154.58400","20.14961","0.04100"
"154.92600","20.17813","0.04028"
"155.26800","20.20665","0.04037"
"155.61000","20.23511","0.04093"
"155.95200","20.26357","0.04081"
"156.29400","20.29209","0.04093"
"156.63600","20.32061","0.04054"
"156.97800","20.34907","0.04087"
"157.32000","20.37765","0.04063"
"157.66200","20.40611","0.04120"
"158.00400","20.43457","0.04095"
"158.34600","20.46315","0.04155"
"158.68800","20.49155","0.04102"
"159.03000","20.52013","0.04091"
"159.37200","20.54865","0.04135"
"159.71400","20.57711","0.04111"
"160.05600","20.60563","0.04073"
"160.39800","20.63414","0.04126"
"160.74000","20.66260","0.04121"
"161.08200","20.69112","0.04087"
"161.42400","20.71958","0.04107"
"161.76600","20.74817","0.04115"
"162.10800","20.77662","0.04188"
"162.45000","20.80502","0.04207"
"162.79200","20.83360","0.04138"
"163.13400","20.86212","0.04133"
"163.47600","20.89058","0.04203"
"163.81800","20.91916","0.04133"
"164.16000","20.94756","0.04214"
"164.50200","20.97608","0.04174"
"164.84400","21.00460","0.04169"
"165.18600","21.03306","0.04174"
"165.52800","21.06164","0.04215"
"165.87000","21.09016","0.04209"
"166.21200","21.11856","0.04258"
"166.55400","21.14714","0.04200"
"166.89600","21.17566","0.04257"
"167.23800","21.20412","0.04211"
"167.58000","21.23264","0.04259"
"167.92200","21.26110","0.04302"
"168.26400","21.28968","0.04284"
"168.60600","21.31814","0.04194"
"168.94800","21.34660","0.04275"
"169.29000","21.37518","0.04292"
"169.63200","21.40364","0.04325"
"169.97400","21.43210","0.04298"
"170.31600","21.46067","0.04294"
"170.65800","21.48913","0.04325"
"171.00000","21.51760","0.04249"
"171.34200","21.54606","0.04270"
"171.68400","21.57457","0.04281"
"172.02600","21.60309","0.04231"
"172.36800","21.63161","0.04252"
"172.71000","21.66013","0.04238"
"173.05200","21.68859","0.04290"
"173.39400","21.71711","0.04300"
"173.73600","21.74563","0.04276"
"174.07800","21.77415","0.04315"
"174.42000","21.80261","0.04292"
"174.76200","21.83107","0.04236"
"175.10400","21.85959","0.04295"
"175.44600","21.88811","0.04251"
"175.78800","21.91663","0.04272"
"176.13000","21.94515","0.04260"
"176.47200","21.97355","0.04276"
"176.81400","22.00213","0.04261"
"177.15600","22.03065","0.04309"
"177.49800","22.05905","0.04294"
"177.84000","22.08769","0.04332"
"178.18200","22.11609","0.04307"
"178.52400","22.14461","0.04350"
"178.86600","22.17319","0.04361"
"179.20800","22.20159","0.04321"
"179.55000","22.23011","0.04419"
"179.89200","22.25869","0.04382"
"180.23400","22.28709","0.04347"
"180.57600","22.31561","0.04370"
"180.91800","22.34413","0.04393"
"181.26000","22.37259","0.04405"
"181.60200","22.40110","0.04441"
"181.94400","22.42962","0.04380"
"182.28600","22.45808","0.04401"
"182.62800","22.48660","0.04405"
"182.97000","22.51506","0.04436"
"183.31200","22.54364","0.04407"
"183.65400","22.57216","0.04339"
"183.99600","22.60050","0.04354"
"184.33800","22.62920","0.04414"
"184.68000","22.65766","0.04426"
"185.02200","22.68612","0.04457"
"185.36400","22.71464","0.04476"
"185.70600","22.74310","0.04431"
"186.04800","22.77162","0.04459"
"186.39000","22.80014","0.04483"
"186.73200","22.82860","0.04463"
"187.07400","22.85712","0.04430"
"187.41600","22.88558","0.04470"
"187.75800","22.91410","0.04448"
"188.10000","22.94262","0.04524"
"188.44200","22.97108","0.04405"
"188.78400","22.99960","0.04377"
"189.12600","23.02812","0.04324"
"189.46800","23.05664","0.04358"
"189.81000","23.08510","0.04402"
"190.15200","23.11362","0.04395"
"190.49400","23.14214","0.04413"
"190.83600","23.17060","0.04428"
"191.17800","23.19912","0.04480"
"191.52000","23.22758","0.04496"
"191.86200","23.25610","0.04476"
"192.20400","23.28468","0.04453"
"192.54600","23.31301","0.04477"
"192.88800","23.34166","0.04482"
"193.23000","23.37017","0.04445"
"193.57200","23.39863","0.04541"
"193.91400","23.42715","0.04550"
"194.25600","23.45561","0.04513"
"194.59800","23.48413","0.04544"
"194.94000","23.51265","0.04528"
"195.28200","23.54111","0.04559"
"195.62400","23.56963","0.04515"
"195.96600","23.59815","0.04550"
"196.30800","23.62661","0.04440"
"196.65000","23.65513","0.04519"
"196.99200","23.68359","0.04526"
"197.33400","23.71211","0.04565"
"197.67600","23.74069","0.04556"
"198.01800","23.76909","0.04348"
"198.36000","23.79761","0.04279"
"198.70200","23.82613","0.04313"
"199.04400","23.85459","0.04223"
"199.38600","23.88311","0.04190"
"199.72800","23.91157","0.04266"
"200.07000","23.94003","0.04187"
"200.41200","23.96867","0.04276"
"200.75400","23.99713","0.04306"
"201.09600","24.02559","0.04353"
"201.43800","24.05411","0.04313"
"201.78000","24.08257","0.04375"
"202.12200","24.11115","0.04370"
"202.46400","24.13972","0.04367"
"202.80600","24.16806","0.04350"
"203.14800","24.19665","0.04405"
"203.49000","24.22511","0.04355"
"203.83200","24.25362","0.04247"
"204.17400","24.28214","0.04219"
"204.51600","24.31060","0.04185"
"204.85800","24.33912","0.04222"
"205.20000","24.36758","0.04175"
"205.54200","24.39604","0.04222"
"205.88400","24.42462","0.04222"
"206.22600","24.45314","0.04243"
"206.56800","24.48154","0.04261"
"206.91000","24.51012","0.04279"
"207.25200","24.53864","0.04273"
"207.59400","24.56710","0.04280"
"207.93600","24.59556","0.04312"
"208.27800","24.62414","0.04406"
"208.62000","24.65260","0.04363"
"208.96200","24.68112","0.04378"
"209.30400","24.70958","0.04386"
"209.64600","24.73810","0.04414"
"209.98800","24.76662","0.04356"
"210.33000","24.79508","0.04431"
"210.67200","24.82372","0.04493"
"211.01400","24.85218","0.04480"
"211.35600","24.88058","0.04502"
"211.69800","24.90910","0.04529"
"212.04000","24.93761","0.04438"
"212.38200","24.96608","0.04467"
"212.72400","24.99466","0.04472"
"213.06600","25.02311","0.04543"
"213.40800","25.05164","0.04569"
"213.75000","25.08015","0.04547"
"214.09200","25.10855","0.04606"
"214.43400","25.13713","0.04570"
"214.77600","25.16566","0.04717"
"215.11800","25.19411","0.04678"
"215.46000","25.22269","0.04761"
"215.80200","25.25109","0.04694"
"216.14400","25.27955","0.04771"
"216.48600","25.30813","0.04792"
"216.82800","25.33653","0.04801"
"217.17000","25.36511","0.04787"
"217.51200","25.39363","0.04883"
"217.85400","25.42209","0.04878"
"218.19600","25.45061","0.04861"
"218.53800","25.47913","0.04712"
"218.88000","25.50759","0.04795"
"219.22200","25.53611","0.04769"
"219.56400","25.56457","0.04762"
"219.90600","25.59315","0.04727"
"220.24800","25.62161","0.04720"
"220.59000","25.65001","0.04813"
"220.93200","25.67871","0.04784"
"221.27400","25.70711","0.04817"
"221.61600","25.73563","0.04833"
"221.95800","25.76415","0.04842"
"222.30000","25.79261","0.04874"
"222.64200","25.82113","0.04923"
"222.98400","25.84958","0.04859"
"223.32600","25.87811","0.04943"
"223.66800","25.90663","0.04902"
"224.01000","25.93508","0.04926"
"224.35200","25.96361","0.04924"
"224.69400","25.99212","0.04942"
"225.03600","26.02064","0.04975"
"225.37800","26.04910","0.04952"
"225.72000","26.07763","0.05015"
"226.06200","26.10614","0.05035"
"226.40400","26.13461","0.05033"
"226.74600","26.16306","0.05096"
"227.08800","26.19158","0.05066"
"227.43000","26.22010","0.05090"
"227.77200","26.24862","0.05108"
"228.11400","26.27708","0.05126"
"228.45600","26.30560","0.05143"
"228.79800","26.33412","0.05117"
"229.14000","26.36258","0.05127"
"229.48200","26.39116","0.05187"
"229.82400","26.41962","0.05281"
"230.16600","26.44808","0.05283"
"230.50800","26.47660","0.05242"
"230.85000","26.50512","0.05324"
"231.19200","26.53364","0.05292"
"231.53400","26.56216","0.05329"
"231.87600","26.59056","0.05373"
"232.21800","26.61914","0.05385"
"232.56000","26.64766","0.05408"
"232.90200","26.67612","0.05445"
"233.24400","26.70464","0.05466"
"233.58600","26.73304","0.05461"
"233.92800","26.76156","0.05432"
"234.27000","26.79019","0.05510"
"234.61200","26.81860","0.05440"
"234.95400","26.84711","0.05565"
"235.29600","26.87569","0.05552"
"235.63800","26.90404","0.05581"
"235.98000","26.93268","0.05610"
"236.32200","26.96119","0.05570"
"236.66400","26.98959","0.05628"
"237.00600","27.01817","0.05660"
"237.34800","27.04657","0.05638"
"237.69000","27.07509","0.05489"
"238.03200","27.10361","0.05602"
"238.37400","27.13207","0.05569"
"238.71600","27.16065","0.05621"
"239.05800","27.18917","0.05623"
"239.40000","27.21757","0.05639"
"239.74200","27.24615","0.05688"
"240.08400","27.27461","0.05695"
"240.42600","27.30313","0.05656"
"240.76800","27.33165","0.05632"
"241.11000","27.36011","0.05676"
"241.45200","27.38863","0.05613"
"241.79400","27.41715","0.05612"
"242.13600","27.44555","0.05671"
"242.47800","27.47413","0.05713"
"242.82000","27.50265","0.05697"
"243.16200","27.53105","0.05770"
"243.50400","27.55963","0.05679"
"243.84600","27.58815","0.05582"
"244.18800","27.61654","0.05631"
"244.53000","27.64513","0.05635"
"244.87200","27.67365","0.05554"
"245.21400","27.70211","0.05675"
"245.55600","27.73062","0.05684"
"245.89800","27.75908","0.05710"
"246.24000","27.78766","0.05688"
"246.58200","27.81612","0.05725"
"246.92400","27.84459","0.05697"
"247.26600","27.87316","0.05647"
"247.60800","27.90162","0.05691"
"247.95000","27.93008","0.05678"
"248.29200","27.95860","0.05720"
"248.63400","27.98712","0.05696"
"248.97600","28.01558","0.05701"
"249.31800","28.04416","0.05770"
"249.66000","28.07256","0.05659"
"250.00200","28.10114","0.05656"
"250.34400","28.12966","0.05647"
"250.68600","28.15806","0.05669"
"251.02800","28.18658","0.05738"
"251.37000","28.21516","0.05719"
"251.71200","28.24362","0.05688"
"252.05400","28.27214","0.05710"
"252.39600","28.30060","0.05691"
"252.73800","28.32906","0.05716"
"253.08000","28.35770","0.05778"
"253.42200","28.38604","0.05762"
"253.76400","28.41468","0.05739"
"254.10600","28.44314","0.05786"
"254.44800","28.47160","0.05809"
"254.79000","28.50012","0.05751"
"255.13200","28.52851","0.05768"
"255.47400","28.55710","0.05831"
"255.81600","28.58562","0.05809"
"256.15800","28.61408","0.05815"
"256.50000","28.64266","0.05744"
"256.84200","28.67112","0.05730"
"257.18400","28.69952","0.05714"
"257.52600","28.72815","0.05717"
"257.86800","28.75667","0.05797"
"258.21000","28.78513","0.05764"
"258.55200","28.81365","0.05829"
"258.89400","28.84205","0.05844"
"259.23600","28.87057","0.05816"
"259.57800","28.89909","0.05834"
"259.92000","28.92755","0.05813"
"260.26200","28.95613","0.05849"
"260.60400","28.98459","0.05887"
"260.94600","29.01311","0.05909"
"261.28800","29.04157","0.05893"
"261.63000","29.07015","0.05938"
"261.97200","29.09861","0.05950"
"262.31400","29.12707","0.05899"
"262.65600","29.15565","0.05899"
"262.99800","29.18411","0.05962"
"263.34000","29.21263","0.05950"
"263.68200","29.24109","0.05992"
"264.02400","29.26961","0.05969"
"264.36600","29.29813","0.05990"
"264.70800","29.32659","0.05937"
"265.05000","29.35511","0.06044"
"265.39200","29.38363","0.06045"
"265.73400","29.41209","0.06046"
"266.07600","29.44061","0.06000"
"266.41800","29.46913","0.05997"
"266.76000","29.49765","0.06046"
"267.10200","29.52610","0.06061"
"267.44400","29.55457","0.06048"
"267.78600","29.58309","0.06044"
"268.12800","29.61166","0.06020"
"268.47000","29.64007","0.06046"
"268.81200","29.66864","0.06041"
"269.15400","29.69716","0.06040"
"269.49600","29.72556","0.06108"
"269.83800","29.75414","0.06105"
"270.18000","29.78266","0.06087"
"270.52200","29.81106","0.06043"
"270.86400","29.83964","0.06033"
"271.20600","29.86810","0.06045"
"271.54800","29.89662","0.06076"
"271.89000","29.92514","0.06034"
"272.23200","29.95354","0.06068"
"272.57400","29.98218","0.06110"
"272.91600","30.01064","0.06095"
"273.25800","30.03910","0.06063"
"273.60000","30.06768","0.06134"
"273.94200","30.09608","0.06109"
"274.28400","30.12460","0.06082"
"274.62600","30.15312","0.06018"
"274.96800","30.18158","0.06028"
"275.31000","30.21010","0.06010"
"275.65200","30.23868","0.05997"
"275.99400","30.26708","0.05985"
"276.33600","30.29560","0.06012"
"276.67800","30.32411","0.05955"
"277.02000","30.35264","0.06020"
"277.36200","30.38116","0.05995"
"277.70400","30.40961","0.05997"
"278.04600","30.43814","0.05984"
"278.38800","30.46660","0.05968"
"278.73000","30.49505","0.05993"
"279.07200","30.52363","0.05982"
"279.41400","30.55215","0.06024"
"279.75600","30.58061","0.05642"
"280.09800","30.60919","0.05682"
"280.44000","30.63759","0.05746"
"280.78200","30.66605","0.05830"
"281.12400","30.69463","0.05914"
"281.46600","30.72309","0.05900"
"281.80800","30.75161","0.05941"
"282.15000","30.78013","0.05980"
"282.49200","30.80859","0.05931"
"282.83400","30.83717","0.06025"
"283.17600","30.86563","0.05999"
"283.51800","30.89409","0.06069"
"283.86000","30.92261","0.06032"
"284.20200","30.95113","0.06032"
"284.54400","30.97959","0.06026"
"284.88600","31.00811","0.06077"
"285.22800","31.03663","0.06025"
"285.57000","31.06503","0.06028"
"285.91200","31.09367","0.06013"
"286.25400","31.12207","0.05754"
"286.59600","31.15065","0.05917"
"286.93800","31.17917","0.05963"
"287.28000","31.20757","0.06065"
"287.62200","31.23615","0.06078"
"287.96400","31.26460","0.06099"
"288.30600","31.29306","0.06034"
"288.64800","31.32164","0.06033"
"288.99000","31.35010","0.06120"
"289.33200","31.37856","0.06118"
"289.67400","31.40714","0.06203"
"290.01600","31.43560","0.06122"
"290.35800","31.46412","0.06145"
"290.70000","31.49264","0.06086"
"291.04200","31.52104","0.06183"
"291.38400","31.54962","0.06148"
"291.72600","31.57814","0.06124"
"292.06800","31.60660","0.06163"
"292.41000","31.63512","0.06091"
"292.75200","31.66358","0.06110"
"293.09400","31.69216","0.06133"
"293.43600","31.72062","0.06165"
"293.77800","31.74902","0.06117"
"294.12000","31.77760","0.06136"
"294.46200","31.80612","0.06141"
"294.80400","31.83458","0.06173"
"295.14600","31.86316","0.06164"
"295.48800","31.89162","0.06107"
"295.83000","31.92007","0.06110"
"296.17200","31.94866","0.06092"
"296.51400","31.97712","0.06116"
"296.85600","32.00563","0.06145"
"297.19800","32.03416","0.06124"
"297.54000","32.06261","0.06115"
"297.88200","32.09113","0.06127"
"298.22400","32.11959","0.06138"
"298.56600","32.14812","0.06109"
"298.90800","32.17663","0.06081"
"299.25000","32.20509","0.06126"
"299.59200","32.23355","0.06138"
"299.93400","32.26213","0.06122"
"300.27600","32.29065","0.06125"
"300.61800","32.31911","0.06194"
"300.96000","32.34763","0.06095"
"301.30200","32.37615","0.06128"
"301.64400","32.40461","0.06133"
"301.98600","32.43313","0.06149"
"302.32800","32.46159","0.06148"
"302.67000","32.49011","0.06026"
"303.01200","32.51863","0.06065"
"303.35400","32.54715","0.06109"
"303.69600","32.57561","0.05919"
"304.03800","32.60407","0.05916"
"304.38000","32.63259","0.05873"
"304.72200","32.66123","0.05914"
"305.06400","32.68951","0.05941"
"305.40600","32.71809","0.05930"
"305.74800","32.74667","0.05964"
"306.09000","32.77507","0.05996"
"306.43200","32.80365","0.05963"
"306.77400","32.83210","0.05949"
"307.11600","32.86063","0.05913"
"307.45800","32.88914","0.06021"
"307.80000","32.91755","0.05950"
"308.14200","32.94613","0.05994"
"308.48400","32.97464","0.06020"
"308.82600","33.00304","0.05985"
"309.16800","33.03162","0.05966"
"309.51000","33.06009","0.05947"
"309.85200","33.08860","0.05943"
"310.19400","33.11712","0.05908"
"310.53600","33.14558","0.05963"
"310.87800","33.17404","0.05872"
"311.22000","33.20262","0.05880"
"311.56200","33.23114","0.05905"
"311.90400","33.25966","0.05903"
"312.24600","33.28812","0.05936"
"312.58800","33.31658","0.05915"
"312.93000","33.34510","0.06007"
"313.27200","33.37362","0.05990"
"313.61400","33.40208","0.05899"
"313.95600","33.43066","0.05938"
"314.29800","33.45912","0.05930"
"314.64000","33.48758","0.05926"
"314.98200","33.51616","0.05925"
"315.32400","33.54456","0.05965"
"315.66600","33.57314","0.05948"
"316.00800","33.60166","0.06018"
"316.35000","33.63012","0.05946"
"316.69200","33.65864","0.05938"
"317.03400","33.68710","0.05970"
"317.37600","33.71556","0.05965"
"317.71800","33.74408","0.06001"
"318.06000","33.77266","0.06081"
"318.40200","33.80117","0.06015"
"318.74400","33.82963","0.06015"
"319.08600","33.85809","0.06059"
"319.42800","33.88662","0.06093"
"319.77000","33.91513","0.06059"
"320.11200","33.94359","0.06007"
"320.45400","33.97218","0.06015"
"320.79600","34.00063","0.06071"
"321.13800","34.02909","0.06087"
"321.48000","34.05761","0.06033"
"321.82200","34.08613","0.06095"
"322.16400","34.11459","0.06075"
"322.50600","34.14317","0.06092"
"322.84800","34.17157","0.06096"
"323.19000","34.20009","0.06123"
"323.53200","34.22867","0.06126"
"323.87400","34.25707","0.06113"
"324.21600","34.28565","0.06155"
"324.55800","34.31411","0.06154"
"324.90000","34.34257","0.06162"
"325.24200","34.37115","0.06152"
"325.58400","34.39961","0.06140"
"325.92600","34.42813","0.06105"
"326.26800","34.45665","0.06169"
"326.61000","34.48511","0.06182"
"326.95200","34.51363","0.06206"
"327.29400","34.54209","0.06168"
"327.63600","34.57061","0.06182"
"327.97800","34.59912","0.06206"
"328.32000","34.62765","0.06175"
"328.66200","34.65611","0.06206"
"329.00400","34.68462","0.06193"
"329.34600","34.71309","0.06254"
"329.68800","34.74166","0.06202"
"330.03000","34.77012","0.06246"
"330.37200","34.79853","0.06233"
"330.71400","34.82716","0.06240"
"331.05600","34.85562","0.06235"
"331.39800","34.88408","0.06178"
"331.74000","34.91260","0.06295"
"332.08200","34.94112","0.06191"
"332.42400","34.96958","0.06287"
"332.76600","34.99810","0.06282"
"333.10800","35.02656","0.06282"
"333.45000","35.05514","0.06268"
"333.79200","35.08360","0.06310"
"334.13400","35.11206","0.06296"
"334.47600","35.14064","0.06297"
"334.81800","35.16916","0.06235"
"335.16000","35.19762","0.06007"
"335.50200","35.22614","0.05987"
"335.84400","35.25460","0.05978"
"336.18600","35.28312","0.06003"
"336.52800","35.31158","0.06002"
"336.87000","35.34010","0.05984"
"337.21200","35.36856","0.06073"
"337.55400","35.39714","0.06051"
"337.89600","35.42559","0.05995"
"338.23800","35.45412","0.06062"
"338.58000","35.48270","0.06045"
"338.92200","35.51110","0.06053"
"339.26400","35.53962","0.06074"
"339.60600","35.56808","0.06049"
"339.94800","35.59660","0.06042"
"340.29000","35.62511","0.06059"
"340.63200","35.65364","0.06095"
"340.97400","35.68209","0.06116"
"341.31600","35.71067","0.06059"
"341.65800","35.73907","0.06107"
"342.00000","35.76765","0.05833"
"342.34200","35.79611","0.05927"
"342.68400","35.82457","0.05914"
"343.02600","35.85315","0.06038"
"343.36800","35.88161","0.06023"
"343.71000","35.91013","0.06030"
"344.05200","35.93865","0.06082"
"344.39400","35.96705","0.06059"
"344.73600","35.99557","0.06071"
"345.07800","36.02415","0.06032"
"345.42000","36.05249","0.06074"
"345.76200","36.08113","0.06056"
"346.10400","36.10965","0.06102"
"346.44600","36.13805","0.06132"
"346.78800","36.16663","0.06047"
"347.13000","36.19515","0.06056"
"347.47200","36.22361","0.06061"
"347.81400","36.25212","0.06110"
"348.15600","36.28053","0.06147"
"348.49800","36.30917","0.06131"
"348.84000","36.33762","0.06152"
"349.18200","36.36609","0.06138"
"349.52400","36.39461","0.06166"
"349.86600","36.42313","0.06160"
"350.20800","36.45164","0.06196"
"350.55000","36.48011","0.06181"
"350.89200","36.50863","0.06169"
"351.23400","36.53714","0.06183"
"351.57600","36.56561","0.06174"
"351.91800","36.59406","0.06185"
"352.26000","36.62264","0.06214"
"352.60200","36.65110","0.06219"
"352.94400","36.67956","0.06186"
"353.28600","36.70814","0.06190"
"353.62800","36.73666","0.06245"
"353.97000","36.76506","0.06232"
"354.31200","36.79358","0.06244"
"354.65400","36.82210","0.06180"
"354.99600","36.85062","0.06208"
"355.33800","36.87914","0.06213"
"355.68000","36.90760","0.06279"
"356.02200","36.93612","0.06238"
"356.36400","36.96464","0.06219"
"356.70600","36.99304","0.06189"
"357.04800","37.02162","0.06224"
"357.39000","37.05014","0.06240"
"357.73200","37.07860","0.06186"
"358.07400","37.10712","0.06149"
"358.41600","37.13564","0.06172"
"358.75800","37.16410","0.06141"
"359.10000","37.19268","0.06145"
"359.44200","37.22108","0.06120"
"359.78400","37.24960","0.06182"
"360.12600","37.27811","0.06175"
"360.46800","37.30658","0.06095"
"360.81000","37.33516","0.06119"
"361.15200","37.36361","0.06161"
"361.49400","37.39214","0.06161"
"361.83600","37.42065","0.06140"
"362.17800","37.44912","0.06133"
"362.52000","37.47757","0.06217"
"362.86200","37.50615","0.06216"
"363.20400","37.53455","0.06227"
"363.54600","37.56313","0.06203"
"363.88800","37.59165","0.06222"
"364.23000","37.62005","0.06247"
"364.57200","37.64863","0.06323"
"364.91400","37.67709","0.06283"
"365.25600","37.70561","0.06248"
"365.59800","37.73413","0.06305"
"365.94000","37.76253","0.06344"
"366.28200","37.79111","0.06343"
"366.62400","37.81963","0.06332"
"366.96600","37.84809","0.06294"
"367.30800","37.87667","0.06298"
"367.65000","37.90513","0.06267"
"367.99200","37.93359","0.06272"
"368.33400","37.96217","0.06351"
"368.67600","37.99063","0.06309"
"369.01800","38.01909","0.06312"
"369.36000","38.04761","0.06395"
"369.70200","38.07607","0.06326"
"370.04400","38.10464","0.06361"
"370.38600","38.13311","0.06361"
"370.72800","38.16157","0.06358"
"371.07000","38.19003","0.06391"
"371.41200","38.21861","0.06408"
"371.75400","38.24706","0.06385"
"372.09600","38.27564","0.06211"
"372.43800","38.30416","0.06278"
"372.78000","38.33256","0.06317"
"373.12200","38.36108","0.06379"
"373.46400","38.38960","0.06333"
"373.80600","38.41812","0.06348"
"374.14800","38.44664","0.06395"
"374.49000","38.47511","0.06366"
"374.83200","38.50362","0.06376"
"375.17400","38.53208","0.06380"
"375.51600","38.56054","0.06417"
"375.85800","38.58912","0.06386"
"376.20000","38.61758","0.06442"
"376.54200","38.64604","0.06413"
"376.88400","38.67462","0.06433"
"377.22600","38.70308","0.06412"
"377.56800","38.73160","0.06469"
"377.91000","38.76024","0.06445"
"378.25200","38.78858","0.06464"
"378.59400","38.81710","0.06465"
"378.93600","38.84568","0.06450"
"379.27800","38.87408","0.06464"
"379.62000","38.90260","0.06494"
"379.96200","38.93112","0.06535"
"380.30400","38.95952","0.06480"
"380.64600","38.98816","0.06474"
"380.98800","39.01662","0.06471"
"381.33000","39.04514","0.06447"
"381.67200","39.07366","0.06464"
"382.01400","39.10205","0.06520"
"382.35600","39.13070","0.06517"
"382.69800","39.15910","0.06517"
"383.04000","39.18755","0.06413"
"383.38200","39.21613","0.05038"
"383.72400","39.24459","0.05470"
"384.06600","39.27311","0.05453"
"384.40800","39.30163","0.05397"
"384.75000","39.33009","0.05433"
"385.09200","39.35861","0.05420"
"385.43400","39.38707","0.05570"
"385.77600","39.41559","0.05624"
"386.11800","39.44417","0.05714"
"386.46000","39.47263","0.05675"
"386.80200","39.50109","0.05729"
"387.14400","39.52961","0.05751"
"387.48600","39.55813","0.05783"
"387.82800","39.58665","0.05974"
"388.17000","39.61511","0.05879"
"388.51200","39.64357","0.05932"
"388.85400","39.67209","0.05834"
"389.19600","39.70061","0.05878"
"389.53800","39.72907","0.05838"
"389.88000","39.75759","0.05426"
"390.22200","39.78610","0.05449"
"390.56400","39.81456","0.05309"
"390.90600","39.84314","0.05228"
"391.24800","39.87160","0.05152"
"391.59000","39.90013","0.05217"
"391.93200","39.92865","0.05187"
"392.27400","39.95711","0.05185"
"392.61600","39.98563","0.05206"
"392.95800","40.01408","0.05287"
"393.30000","40.04255","0.05055"
"393.64200","40.07113","0.04867"
"393.98400","40.09964","0.04919"
"394.32600","40.12804","0.04921"
"394.66800","40.15662","0.04930"
"395.01000","40.18508","0.04930"
"395.35200","40.21360","0.04988"
"395.69400","40.24218","0.04971"
"396.03600","40.27058","0.04984"
"396.37800","40.29910","0.05006"
"396.72000","40.32763","0.05039"
"397.06200","40.35602","0.05037"
"397.40400","40.38466","0.05074"
"397.74600","40.41312","0.05107"
"398.08800","40.44152","0.05067"
"398.43000","40.47016","0.05100"
"398.77200","40.49862","0.05153"
"399.11400","40.52708","0.05167"
"399.45600","40.55566","0.05166"
"399.79800","40.58406","0.05154"
"400.14000","40.61263","0.05214"
"400.48200","40.64116","0.05275"
"400.82400","40.66956","0.05299"
"401.16600","40.69813","0.05235"
"401.50800","40.72659","0.05306"
"401.85000","40.75512","0.05283"
"402.19200","40.78364","0.05351"
"402.53400","40.81210","0.05314"
"402.87600","40.84061","0.05344"
"403.21800","40.86908","0.05337"
"403.56000","40.89754","0.05425"
"403.90200","40.92611","0.05395"
"404.24400","40.95464","0.05413"
"404.58600","40.98310","0.05408"
"404.92800","41.01161","0.05491"
"405.27000","41.04013","0.05501"
"405.61200","41.06865","0.05404"
"405.95400","41.09711","0.05462"
"406.29600","41.12563","0.05462"
"406.63800","41.15409","0.05506"
"406.98000","41.18261","0.05489"
"407.32200","41.21107","0.05534"
"407.66400","41.23959","0.05579"
"408.00600","41.26811","0.05537"
"408.34800","41.29657","0.05462"
"408.69000","41.32509","0.05524"
"409.03200","41.35361","0.05534"
"409.37400","41.38207","0.05536"
"409.71600","41.41059","0.05561"
"410.05800","41.43916","0.05564"
"410.40000","41.46762","0.05606"
"410.74200","41.49615","0.05571"
"411.08400","41.52455","0.05576"
"411.42600","41.55312","0.05620"
"411.76800","41.58165","0.05602"
"412.11000","41.61004","0.05647"
"412.45200","41.63863","0.05651"
"412.79400","41.66715","0.05665"
"413.13600","41.69561","0.05678"
"413.47800","41.72412","0.05688"
"413.82000","41.75259","0.05706"
"414.16200","41.78104","0.05645"
"414.50400","41.80963","0.05705"
"414.84600","41.83809","0.05716"
"415.18800","41.86666","0.05729"
"415.53000","41.89512","0.05722"
"415.87200","41.92358","0.05785"
"416.21400","41.95216","0.05777"
"416.55600","41.98063","0.05789"
"416.89800","42.00908","0.05779"
"417.24000","42.03766","0.05776"
"417.58200","42.06606","0.05773"
"417.92400","42.09464","0.05782"
"418.26600","42.12310","0.05830"
"418.60800","42.15150","0.05813"
"418.95000","42.18014","0.05789"
"419.29200","42.20860","0.05812"
"419.63400","42.23706","0.05872"
"419.97600","42.26564","0.05830"
"420.31800","42.29410","0.05884"
"420.66000","42.32262","0.05847"
"421.00200","42.35114","0.05881"
"421.34400","42.37960","0.05904"
"421.68600","42.40812","0.05970"
"422.02800","42.43664","0.05917"
"422.37000","42.46510","0.05914"
"422.71200","42.49362","0.05907"
"423.05400","42.52207","0.06016"
"423.39600","42.55060","0.05948"
"423.73800","42.57912","0.06002"
"424.08000","42.60764","0.05975"
"424.42200","42.63610","0.05929"
"424.76400","42.66462","0.05986"
"425.10600","42.69307","0.06020"
"425.44800","42.72160","0.06048"
"425.79000","42.75011","0.06020"
"426.13200","42.77857","0.06083"
"426.47400","42.80709","0.06060"
"426.81600","42.83562","0.06037"
"427.15800","42.86407","0.06062"
"427.50000","42.89265","0.06081"
"427.84200","42.92117","0.06112"
"428.18400","42.94957","0.06054"
"428.52600","42.97809","0.06088"
"428.86800","43.00661","0.06118"
"429.21000","43.03513","0.06068"
"429.55200","43.06365","0.06107"
"429.89400","43.09205","0.06070"
"430.23600","43.12063","0.06091"
"430.57800","43.14915","0.06144"
"430.92000","43.17761","0.06091"
"431.26200","43.20607","0.06091"
"431.60400","43.23465","0.06047"
"431.94600","43.26310","0.05998"
"432.28800","43.29163","0.05930"
"432.63000","43.32009","0.06006"
"432.97200","43.34860","0.05977"
"433.31400","43.37719","0.06002"
"433.65600","43.40553","0.06006"
"433.99800","43.43417","0.06071"
"434.34000","43.46263","0.06006"
"434.68200","43.49109","0.05957"
"435.02400","43.51966","0.06042"
"435.36600","43.54807","0.05958"
"435.70800","43.57659","0.06028"
"436.05000","43.60510","0.05983"
"436.39200","43.63356","0.06073"
"436.73400","43.66215","0.05999"
"437.07600","43.69066","0.05988"
"437.41800","43.71906","0.05984"
"437.76000","43.74765","0.06042"
"438.10200","43.77610","0.06056"
"438.44400","43.80462","0.06050"
"438.78600","43.83315","0.06022"
"439.12800","43.86160","0.06105"
"439.47000","43.89012","0.06084"
"439.81200","43.91864","0.06090"
"440.15400","43.94704","0.06119"
"440.49600","43.97562","0.06066"
"440.83800","44.00414","0.06097"
"441.18000","44.03254","0.06109"
"441.52200","44.06112","0.06095"
"441.86400","44.08964","0.06032"
"442.20600","44.11810","0.06068"
"442.54800","44.14662","0.06092"
"442.89000","44.17508","0.06095"
"443.23200","44.20366","0.06111"
"443.57400","44.23212","0.06152"
"443.91600","44.26058","0.06163"
"444.25800","44.28910","0.06119"
"444.60000","44.31762","0.06115"
"444.94200","44.34608","0.06191"
"445.28400","44.37466","0.06174"
"445.62600","44.40312","0.06180"
"445.96800","44.43163","0.06216"
"446.31000","44.46009","0.06167"
"446.65200","44.48861","0.06194"
"446.99400","44.51707","0.06198"
"447.33600","44.54565","0.06170"
"447.67800","44.57405","0.06213"
"448.02000","44.60263","0.06207"
"448.36200","44.63115","0.06237"
"448.70400","44.65961","0.06291"
"449.04600","44.68813","0.06231"
"449.38800","44.71659","0.06213"
"449.73000","44.74505","0.06251"
"450.07200","44.77363","0.06295"
"450.41400","44.80209","0.06186"
"450.75600","44.83061","0.06175"
"451.09800","44.85918","0.06232"
"451.44000","44.88753","0.06237"
"451.78200","44.91611","0.06231"
"452.12400","44.94463","0.06259"
"452.46600","44.97309","0.06243"
"452.80800","45.00161","0.06265"
"453.15000","45.03012","0.06284"
"453.49200","45.05859","0.06278"
"453.83400","45.08711","0.06286"
"454.17600","45.11557","0.06344"
"454.51800","45.14415","0.06314"
"454.86000","45.17261","0.06312"
"455.20200","45.20100","0.06304"
"455.54400","45.22965","0.06320"
"455.88600","45.25816","0.06294"
"456.22800","45.28662","0.06346"
"456.57000","45.31514","0.06416"
"456.91200","45.34361","0.06342"
"457.25400","45.37207","0.06346"
"457.59600","45.40064","0.06375"
"457.93800","45.42910","0.06376"
"458.28000","45.45762","0.06389"
"458.62200","45.48615","0.06455"
"458.96400","45.51454","0.06426"
"459.30600","45.54312","0.06405"
"459.64800","45.57164","0.06423"
"459.99000","45.60010","0.06436"
"460.33200","45.62868","0.06426"
"460.67400","45.65708","0.06436"
"461.01600","45.68560","0.06510"
"461.35800","45.71412","0.06517"
"461.70000","45.74258","0.06454"
"462.04200","45.77110","0.06523"
"462.38400","45.79962","0.06532"
"462.72600","45.82808","0.06489"
"463.06800","45.85666","0.06519"
"463.41000","45.88512","0.06538"
"463.75200","45.91358","0.06550"
"464.09400","45.94210","0.06566"
"464.43600","45.97056","0.06504"
"464.77800","45.99914","0.06531"
"465.12000","46.02760","0.06545"
"465.46200","46.05612","0.06540"
"465.80400","46.08458","0.06563"
"466.14600","46.11316","0.06522"
"466.48800","46.14156","0.06543"
"466.83000","46.17014","0.06550"
"467.17200","46.19865","0.06551"
"467.51400","46.22711","0.06537"
"467.85600","46.25563","0.06501"
"468.19800","46.28409","0.06527"
"468.54000","46.31261","0.06513"
"468.88200","46.34114","0.06556"
"469.22400","46.36953","0.06548"
"469.56600","46.39811","0.06558"
"469.90800","46.42664","0.06572"
"470.25000","46.45509","0.06555"
"470.59200","46.48367","0.06576"
"470.93400","46.51213","0.06553"
"471.27600","46.54053","0.06602"
"471.61800","46.56917","0.06561"
"471.96000","46.59757","0.06606"
"472.30200","46.62609","0.06580"
"472.64400","46.65461","0.06616"
"472.98600","46.68307","0.06588"
"473.32800","46.71165","0.06607"
"473.67000","46.74011","0.06596"
"474.01200","46.76857","0.06604"
"474.35400","46.79709","0.06588"
"474.69600","46.82561","0.06507"
"475.03800","46.85406","0.06206"
"475.38000","46.88265","0.06374"
"475.72200","46.91111","0.06383"
"476.06400","46.93962","0.06330"
"476.40600","46.96814","0.06367"
"476.74800","46.99655","0.06399"
"477.09000","47.02512","0.06355"
"477.43200","47.05364","0.06430"
"477.77400","47.08204","0.06409"
"478.11600","47.11062","0.06445"
"478.45800","47.13908","0.06484"
"478.80000","47.16754","0.06486"
"479.14200","47.19612","0.06494"
"479.48400","47.22458","0.06479"
"479.82600","47.25311","0.06520"
"480.16800","47.28162","0.06521"
"480.51000","47.31009","0.06500"
"480.85200","47.33855","0.06430"
"481.19400","47.36718","0.06417"
"481.53600","47.39558","0.06444"
"481.87800","47.42410","0.06382"
"482.22000","47.45262","0.06327"
"482.56200","47.48108","0.06371"
"482.90400","47.50960","0.06331"
"483.24600","47.53812","0.06379"
"483.58800","47.56658","0.06260"
"483.93000","47.59516","0.06202"
"484.27200","47.62362","0.06311"
"484.61400","47.65208","0.06391"
"484.95600","47.68072","0.06331"
"485.29800","47.70906","0.06365"
"485.64000","47.73764","0.06365"
"485.98200","47.76616","0.06285"
"486.32400","47.79456","0.06313"
"486.66600","47.82314","0.06278"
"487.00800","47.85160","0.06302"
"487.35000","47.88006","0.06370"
"487.69200","47.90863","0.06191"
"488.03400","47.93709","0.06029"
"488.37600","47.96561","0.06016"
"488.71800","47.99414","0.06018"
"489.06000","48.02259","0.06044"
"489.40200","48.05111","0.06070"
"489.74400","48.07964","0.06179"
"490.08600","48.10809","0.06099"
"490.42800","48.13662","0.06142"
"490.77000","48.16508","0.06027"
"491.11200","48.19365","0.06092"
"491.45400","48.22217","0.06097"
"491.79600","48.25058","0.06106"
"492.13800","48.27909","0.06045"
"492.48000","48.30761","0.06013"
"492.82200","48.33607","0.05984"
"493.16400","48.36459","0.06024"
"493.50600","48.39317","0.06035"
"493.84800","48.42163","0.06047"
"494.19000","48.45015","0.06019"
"494.53200","48.47861","0.06059"
"494.87400","48.50713","0.06078"
"495.21600","48.53565","0.06060"
"495.55800","48.56404","0.06087"
"495.90000","48.59263","0.06095"
"496.24200","48.62109","0.06098"
"496.58400","48.64961","0.06108"
"496.92600","48.67813","0.06090"
"497.26800","48.70664","0.06096"
"497.61000","48.73510","0.06122"
"497.95200","48.76357","0.06125"
"498.29400","48.79208","0.06138"
"498.63600","48.82060","0.06192"
"498.97800","48.84913","0.06174"
"499.32000","48.87758","0.06181"
"499.66200","48.90610","0.06233"
"500.00400","48.93463","0.06258"
"500.34600","48.96309","0.06215"
"500.68800","48.99166","0.06228"
"501.03000","49.02013","0.06253"
"501.37200","49.04858","0.06265"
"501.71400","49.07711","0.06259"
"502.05600","49.10562","0.06240"
"502.39800","49.13408","0.06274"
"502.74000","49.16266","0.06309"
"503.08200","49.19106","0.06307"
"503.42400","49.21958","0.06275"
"503.76600","49.24816","0.06331"
"504.10800","49.27662","0.06311"
"504.45000","49.30514","0.06308"
"504.57000","49.31512","0.06317"