File: Force_trajectories/170225_2/Specimen_RawData_7.csv
End date,"2/25/2017"
Specimen label,"1DG_2"
Maximum Load,"0.09850",N

Time,Extension,Load
(s),(mm),(N)
"0.00000","0.00000","-0.00076"
"0.37200","0.03103","-0.00044"
"0.74400","0.06212","-0.00003"
"1.11600","0.09315","0.00048"
"1.48800","0.12418","0.00059"
"1.86000","0.15515","0.00062"
"2.23200","0.18612","0.00108"
"2.60400","0.21710","0.00158"
"2.97600","0.24807","0.00137"
"3.34800","0.27916","0.00086"
"3.72000","0.31013","0.00120"
"4.09200","0.34110","0.00181"
"4.46400","0.37213","0.00180"
"4.83600","0.40316","0.00176"
"5.20800","0.43407","0.00200"
"5.58000","0.46510","0.00162"
"5.95200","0.49619","0.00259"
"6.32400","0.52704","0.00172"
"6.69600","0.55814","0.00192"
"7.06800","0.58917","0.00248"
"7.44000","0.62008","0.00204"
"7.81200","0.65105","0.00193"
"8.18400","0.68220","0.00240"
"8.55600","0.71317","0.00261"
"8.92800","0.74414","0.00229"
"9.30000","0.77517","0.00277"
"9.67200","0.80620","0.00258"
"10.04400","0.83705","0.00247"
"10.41600","0.86814","0.00253"
"10.78800","0.89917","0.00306"
"11.16000","0.93009","0.00289"
"11.53200","0.96118","0.00255"
"11.90400","0.99209","0.00302"
"12.27600","1.02312","0.00352"
"12.64800","1.05409","0.00357"
"13.02000","1.08512","0.00289"
"13.39200","1.11621","0.00323"
"13.76400","1.14712","0.00364"
"14.13600","1.17815","0.00328"
"14.50800","1.20918","0.00268"
"14.88000","1.24003","0.00384"
"15.25200","1.27119","0.00339"
"15.62400","1.30216","0.00307"
"15.99600","1.33313","0.00377"
"16.36800","1.36416","0.00380"
"16.74000","1.39513","0.00385"
"17.11200","1.42616","0.00364"
"17.48400","1.45707","0.00341"
"17.85600","1.48810","0.00317"
"18.22800","1.51907","0.00330"
"18.60000","1.55010","0.00332"
"18.97200","1.58113","0.00359"
"19.34400","1.61216","0.00318"
"19.71600","1.64314","0.00379"
"20.08800","1.67411","0.00339"
"20.46000","1.70520","0.00363"
"20.83200","1.73611","0.00374"
"21.20400","1.76714","0.00318"
"21.57600","1.79817","0.00363"
"21.94800","1.82914","0.00448"
"22.32000","1.86017","0.00368"
"22.69200","1.89114","0.00387"
"23.06400","1.92217","0.00400"
"23.43600","1.95308","0.00339"
"23.80800","1.98418","0.00405"
"24.18000","2.01515","0.00350"
"24.55200","2.04612","0.00413"
"24.92400","2.07715","0.00372"
"25.29600","2.10818","0.00395"
"25.66800","2.13903","0.00361"
"26.04000","2.17018","0.00379"
"26.41200","2.20109","0.00358"
"26.78400","2.23212","0.00373"
"27.15600","2.26315","0.00384"
"27.52800","2.29418","0.00407"
"27.90000","2.32510","0.00359"
"28.27200","2.35607","0.00440"
"28.64400","2.38716","0.00369"
"29.01600","2.41813","0.00388"
"29.38800","2.44910","0.00411"
"29.76000","2.48013","0.00362"
"30.13200","2.51116","0.00414"
"30.50400","2.54213","0.00430"
"30.87600","2.57310","0.00411"
"31.24800","2.60413","0.00392"
"31.62000","2.63510","0.00364"
"31.99200","2.66613","0.00424"
"32.36400","2.69723","0.00352"
"32.73600","2.72808","0.00418"
"33.10800","2.75917","0.00402"
"33.48000","2.79020","0.00394"
"33.85200","2.82111","0.00368"
"34.22400","2.85214","0.00380"
"34.59600","2.88317","0.00338"
"34.96800","2.91414","0.00399"
"35.34000","2.94511","0.00370"
"35.71200","2.97614","0.00378"
"36.08400","3.00717","0.00425"
"36.45600","3.03809","0.00357"
"36.82800","3.06912","0.00410"
"37.20000","3.10015","0.00444"
"37.57200","3.13112","0.00366"
"37.94400","3.16215","0.00431"
"38.31600","3.19312","0.00407"
"38.68800","3.22415","0.00392"
"39.06000","3.25512","0.00371"
"39.43200","3.28615","0.00343"
"39.80400","3.31718","0.00384"
"40.17600","3.34803","0.00458"
"40.54800","3.37912","0.00458"
"40.92000","3.41016","0.00413"
"41.29200","3.44107","0.00397"
"41.66400","3.47216","0.00384"
"42.03600","3.50319","0.00460"
"42.40800","3.53410","0.00419"
"42.78000","3.56507","0.00390"
"43.15200","3.59616","0.00378"
"43.52400","3.62713","0.00368"
"43.89600","3.65810","0.00361"
"44.26800","3.68919","0.00447"
"44.64000","3.72016","0.00412"
"45.01200","3.75114","0.00384"
"45.38400","3.78217","0.00404"
"45.75600","3.81314","0.00396"
"46.12800","3.84411","0.00363"
"46.50000","3.87514","0.00327"
"46.87200","3.90611","0.00425"
"47.24400","3.93714","0.00398"
"47.61600","3.96811","0.00467"
"47.98800","3.99920","0.00380"
"48.36000","4.03017","0.00347"
"48.73200","4.06108","0.00437"
"49.10400","4.09218","0.00412"
"49.47600","4.12315","0.00398"
"49.84800","4.15406","0.00482"
"50.22000","4.18509","0.00422"
"50.59200","4.21618","0.00416"
"50.96400","4.24715","0.00453"
"51.33600","4.27812","0.00437"
"51.70800","4.30921","0.00367"
"52.08000","4.34012","0.00398"
"52.45200","4.37109","0.00438"
"52.82400","4.40212","0.00448"
"53.19600","4.43309","0.00428"
"53.56800","4.46413","0.00395"
"53.94000","4.49516","0.00381"
"54.31200","4.52613","0.00435"
"54.68400","4.55704","0.00391"
"55.05600","4.58813","0.00501"
"55.42800","4.61916","0.00472"
"55.80000","4.65013","0.00411"
"56.17200","4.68116","0.00498"
"56.54400","4.71213","0.00396"
"56.91600","4.74316","0.00431"
"57.28800","4.77413","0.00403"
"57.66000","4.80517","0.00431"
"58.03200","4.83614","0.00407"
"58.40400","4.86711","0.00433"
"58.77600","4.89814","0.00431"
"59.14800","4.92917","0.00447"
"59.52000","4.96008","0.00410"
"59.89200","4.99117","0.00448"
"60.26400","5.02214","0.00428"
"60.63600","5.05311","0.00484"
"61.00800","5.08414","0.00435"
"61.38000","5.11511","0.00421"
"61.75200","5.14609","0.00466"
"62.12400","5.17712","0.00455"
"62.49600","5.20815","0.00437"
"62.86800","5.23912","0.00472"
"63.24000","5.27009","0.00404"
"63.61200","5.30112","0.00388"
"63.98400","5.33215","0.00420"
"64.35600","5.36312","0.00485"
"64.72800","5.39415","0.00449"
"65.10000","5.42518","0.00454"
"65.47200","5.45603","0.00463"
"65.84400","5.48712","0.00437"
"66.21600","5.51821","0.00487"
"66.58800","5.54907","0.00415"
"66.96000","5.58010","0.00467"
"67.33200","5.61119","0.00392"
"67.70400","5.64210","0.00465"
"68.07600","5.67307","0.00491"
"68.44800","5.70416","0.00450"
"68.82000","5.73519","0.00454"
"69.19200","5.76610","0.00454"
"69.56400","5.79719","0.00440"
"69.93600","5.82816","0.00424"
"70.30800","5.85908","0.00420"
"70.68000","5.89017","0.00469"
"71.05200","5.92114","0.00427"
"71.42400","5.95211","0.00477"
"71.79600","5.98314","0.00506"
"72.16800","6.01411","0.00486"
"72.54000","6.04508","0.00454"
"72.91200","6.07611","0.00462"
"73.28400","6.10714","0.00458"
"73.65600","6.13817","0.00528"
"74.02800","6.16908","0.00475"
"74.40000","6.20011","0.00488"
"74.77200","6.23115","0.00508"
"75.14400","6.26206","0.00534"
"75.51600","6.29315","0.00456"
"75.88800","6.32412","0.00500"
"76.26000","6.35515","0.00510"
"76.63200","6.38612","0.00486"
"77.00400","6.41715","0.00484"
"77.37600","6.44812","0.00507"
"77.74800","6.47909","0.00506"
"78.12000","6.51018","0.00455"
"78.49200","6.54115","0.00497"
"78.86400","6.57212","0.00501"
"79.23600","6.60316","0.00509"
"79.60800","6.63407","0.00484"
"79.98000","6.66510","0.00512"
"80.35200","6.69613","0.00489"
"80.72400","6.72716","0.00477"
"81.09600","6.75813","0.00509"
"81.46800","6.78910","0.00482"
"81.84000","6.82013","0.00461"
"82.21200","6.85110","0.00542"
"82.58400","6.88213","0.00467"
"82.95600","6.91317","0.00480"
"83.32800","6.94414","0.00516"
"83.70000","6.97517","0.00552"
"84.07200","7.00614","0.00496"
"84.44400","7.03717","0.00501"
"84.81600","7.06808","0.00478"
"85.18800","7.09917","0.00549"
"85.56000","7.13014","0.00509"
"85.93200","7.16105","0.00460"
"86.30400","7.19214","0.00488"
"86.67600","7.22311","0.00517"
"87.04800","7.25415","0.00490"
"87.42000","7.28512","0.00508"
"87.79200","7.31609","0.00568"
"88.16400","7.34712","0.00508"
"88.53600","7.37815","0.00490"
"88.90800","7.40918","0.00511"
"89.28000","7.44015","0.00520"
"89.65200","7.47106","0.00513"
"90.02400","7.50215","0.00577"
"90.39600","7.53312","0.00512"
"90.76800","7.56409","0.00517"
"91.14000","7.59512","0.00521"
"91.51200","7.62610","0.00526"
"91.88400","7.65713","0.00511"
"92.25600","7.68810","0.00576"
"92.62800","7.71913","0.00461"
"93.00000","7.75016","0.00567"
"93.37200","7.78107","0.00548"
"93.74400","7.81216","0.00555"
"94.11600","7.84313","0.00540"
"94.48800","7.87410","0.00588"
"94.86000","7.90513","0.00559"
"95.23200","7.93616","0.00590"
"95.60400","7.96707","0.00573"
"95.97600","7.99817","0.00556"
"96.34800","8.02920","0.00544"
"96.72000","8.06005","0.00560"
"97.09200","8.09114","0.00586"
"97.46400","8.12217","0.00593"
"97.83600","8.15314","0.00536"
"98.20800","8.18411","0.00523"
"98.58000","8.21514","0.00588"
"98.95200","8.24611","0.00476"
"99.32400","8.27708","0.00561"
"99.69600","8.30811","0.00534"
"100.06800","8.33920","0.00521"
"100.44000","8.37000","0.00567"
"100.81200","8.40115","0.00584"
"101.18400","8.43218","0.00538"
"101.55600","8.46309","0.00545"
"101.92800","8.49418","0.00557"
"102.30000","8.52515","0.00541"
"102.67200","8.55612","0.00498"
"103.04400","8.58709","0.00574"
"103.41600","8.61812","0.00592"
"103.78800","8.64915","0.00578"
"104.16000","8.68013","0.00584"
"104.53200","8.71116","0.00547"
"104.90400","8.74213","0.00578"
"105.27600","8.77310","0.00594"
"105.64800","8.80413","0.00571"
"106.02000","8.83516","0.00560"
"106.39200","8.86613","0.00560"
"106.76400","8.89710","0.00554"
"107.13600","8.92813","0.00621"
"107.50800","8.95916","0.00561"
"107.88000","8.99007","0.00612"
"108.25200","9.02116","0.00587"
"108.62400","9.05214","0.00575"
"108.99600","9.08311","0.00566"
"109.36800","9.11414","0.00579"
"109.74000","9.14517","0.00580"
"110.11200","9.17608","0.00611"
"110.48400","9.20717","0.00593"
"110.85600","9.23820","0.00553"
"111.22800","9.26905","0.00609"
"111.60000","9.30014","0.00620"
"111.97200","9.33117","0.00589"
"112.34400","9.36208","0.00588"
"112.71600","9.39312","0.00583"
"113.08800","9.42415","0.00629"
"113.46000","9.45518","0.00562"
"113.83200","9.48615","0.00600"
"114.20400","9.51712","0.00582"
"114.57600","9.54815","0.00598"
"114.94800","9.57912","0.00678"
"115.32000","9.61009","0.00630"
"115.69200","9.64118","0.00615"
"116.06400","9.67209","0.00668"
"116.43600","9.70318","0.00591"
"116.80800","9.73415","0.00593"
"117.18000","9.76513","0.00669"
"117.55200","9.79610","0.00658"
"117.92400","9.82713","0.00699"
"118.29600","9.85810","0.00570"
"118.66800","9.88913","0.00689"
"119.04000","9.92016","0.00643"
"119.41200","9.95113","0.00656"
"119.78400","9.98204","0.00651"
"120.15600","10.01313","0.00629"
"120.52800","10.04416","0.00622"
"120.90000","10.07513","0.00681"
"121.27200","10.10616","0.00632"
"121.64400","10.13714","0.00663"
"122.01600","10.16811","0.00666"
"122.38800","10.19914","0.00659"
"122.76000","10.23017","0.00667"
"123.13200","10.26108","0.00666"
"123.50400","10.29211","0.00714"
"123.87600","10.32314","0.00686"
"124.24800","10.35411","0.00669"
"124.62000","10.38508","0.00689"
"124.99200","10.41611","0.00702"
"125.36400","10.44714","0.00669"
"125.73600","10.47806","0.00678"
"126.10800","10.50915","0.00691"
"126.48000","10.54018","0.00715"
"126.85200","10.57109","0.00676"
"127.22400","10.60212","0.00665"
"127.59600","10.63321","0.00665"
"127.96800","10.66412","0.00657"
"128.34000","10.69509","0.00718"
"128.71200","10.72618","0.00694"
"129.08400","10.75715","0.00668"
"129.45600","10.78813","0.00742"
"129.82800","10.81922","0.00746"
"130.20000","10.85013","0.00682"
"130.57200","10.88104","0.00683"
"130.94400","10.91219","0.00730"
"131.31600","10.94316","0.00752"
"131.68800","10.97413","0.00702"
"132.06000","11.00516","0.00709"
"132.43200","11.03613","0.00703"
"132.80400","11.06716","0.00728"
"133.17600","11.09807","0.00701"
"133.54800","11.12916","0.00693"
"133.92000","11.16014","0.00715"
"134.29200","11.19111","0.00659"
"134.66400","11.22214","0.00692"
"135.03600","11.25317","0.00718"
"135.40800","11.28408","0.00764"
"135.78000","11.31517","0.00724"
"136.15200","11.34620","0.00745"
"136.52400","11.37711","0.00751"
"136.89600","11.40808","0.00680"
"137.26800","11.43917","0.00772"
"137.64000","11.47008","0.00747"
"138.01200","11.50111","0.00792"
"138.38400","11.53221","0.00750"
"138.75600","11.56312","0.00692"
"139.12800","11.59415","0.00745"
"139.50000","11.62512","0.00770"
"139.87200","11.65615","0.00770"
"140.24400","11.68712","0.00770"
"140.61600","11.71815","0.00767"
"140.98800","11.74918","0.00800"
"141.36000","11.78009","0.00772"
"141.73200","11.81112","0.00792"
"142.10400","11.84215","0.00837"
"142.47600","11.87306","0.00769"
"142.84800","11.90410","0.00830"
"143.22000","11.93513","0.00842"
"143.59200","11.96616","0.00744"
"143.96400","11.99713","0.00799"
"144.33600","12.02816","0.00890"
"144.70800","12.05919","0.00821"
"145.08000","12.09010","0.00818"
"145.45200","12.12113","0.00826"
"145.82400","12.15216","0.00858"
"146.19600","12.18307","0.00835"
"146.56800","12.21416","0.00803"
"146.94000","12.24514","0.00912"
"147.31200","12.27611","0.00864"
"147.68400","12.30708","0.00862"
"148.05600","12.33811","0.00851"
"148.42800","12.36914","0.00873"
"148.80000","12.40011","0.00906"
"149.17200","12.43114","0.00890"
"149.54400","12.46211","0.00840"
"149.91600","12.49308","0.00907"
"150.28800","12.52417","0.00836"
"150.66000","12.55514","0.00924"
"151.03200","12.58606","0.00914"
"151.40400","12.61715","0.00897"
"151.77600","12.64818","0.00873"
"152.14800","12.67915","0.00902"
"152.52000","12.71012","0.00966"
"152.89200","12.74115","0.00945"
"153.26400","12.77212","0.00900"
"153.63600","12.80309","0.00958"
"154.00800","12.83412","0.00970"
"154.38000","12.86515","0.00939"
"154.75200","12.89606","0.00948"
"155.12400","12.92715","0.00957"
"155.49600","12.95813","0.00970"
"155.86800","12.98910","0.00931"
"156.24000","13.02013","0.00960"
"156.61200","13.05122","0.01008"
"156.98400","13.08213","0.01018"
"157.35600","13.11316","0.00997"
"157.72800","13.14413","0.01029"
"158.10000","13.17510","0.01002"
"158.47200","13.20607","0.01087"
"158.84400","13.23716","0.00969"
"159.21600","13.26813","0.01022"
"159.58800","13.29905","0.01051"
"159.96000","13.33020","0.01085"
"160.33200","13.36123","0.00985"
"160.70400","13.39202","0.01062"
"161.07600","13.42317","0.01089"
"161.44800","13.45414","0.01033"
"161.82000","13.48511","0.01075"
"162.19200","13.51614","0.01097"
"162.56400","13.54717","0.01093"
"162.93600","13.57814","0.01085"
"163.30800","13.60911","0.01050"
"163.68000","13.64015","0.01111"
"164.05200","13.67118","0.01102"
"164.42400","13.70209","0.01088"
"164.79600","13.73318","0.01158"
"165.16800","13.76415","0.01159"
"165.54000","13.79506","0.01144"
"165.91200","13.82609","0.01126"
"166.28400","13.85718","0.01131"
"166.65600","13.88815","0.01221"
"167.02800","13.91912","0.01197"
"167.40000","13.95015","0.01190"
"167.77200","13.98112","0.01210"
"168.14400","14.01210","0.01246"
"168.51600","14.04319","0.01189"
"168.88800","14.07416","0.01273"
"169.26000","14.10513","0.01305"
"169.63200","14.13616","0.01274"
"170.00400","14.16713","0.01230"
"170.37600","14.19804","0.01247"
"170.74800","14.22913","0.01309"
"171.12000","14.26016","0.01293"
"171.49200","14.29107","0.01309"
"171.86400","14.32210","0.01298"
"172.23600","14.35320","0.01291"
"172.60800","14.38411","0.01278"
"172.98000","14.41514","0.01355"
"173.35200","14.44611","0.01333"
"173.72400","14.47714","0.01357"
"174.09600","14.50811","0.01346"
"174.46800","14.53914","0.01423"
"174.84000","14.57017","0.01328"
"175.21200","14.60108","0.01398"
"175.58400","14.63211","0.01385"
"175.95600","14.66314","0.01360"
"176.32800","14.69405","0.01416"
"176.70000","14.72515","0.01369"
"177.07200","14.75612","0.01451"
"177.44400","14.78709","0.01397"
"177.81600","14.81812","0.01467"
"178.18800","14.84909","0.01468"
"178.56000","14.88018","0.01468"
"178.93200","14.91115","0.01465"
"179.30400","14.94212","0.01505"
"179.67600","14.97309","0.01471"
"180.04800","15.00406","0.01481"
"180.42000","15.03521","0.01477"
"180.79200","15.06607","0.01563"
"181.16400","15.09710","0.01583"
"181.53600","15.12813","0.01550"
"181.90800","15.15916","0.01561"
"182.28000","15.19013","0.01585"
"182.65200","15.22116","0.01577"
"183.02400","15.25213","0.01606"
"183.39600","15.28310","0.01545"
"183.76800","15.31407","0.01601"
"184.14000","15.34516","0.01622"
"184.51200","15.37613","0.01682"
"184.88400","15.40717","0.01677"
"185.25600","15.43814","0.01647"
"185.62800","15.46917","0.01715"
"186.00000","15.50008","0.01677"
"186.37200","15.53111","0.01714"
"186.74400","15.56214","0.01719"
"187.11600","15.59311","0.01737"
"187.48800","15.62414","0.01738"
"187.86000","15.65517","0.01770"
"188.23200","15.68608","0.01747"
"188.60400","15.71711","0.01798"
"188.97600","15.74814","0.01830"
"189.34800","15.77912","0.01781"
"189.72000","15.81015","0.01822"
"190.09200","15.84118","0.01843"
"190.46400","15.87215","0.01832"
"190.83600","15.90306","0.01875"
"191.20800","15.93415","0.01884"
"191.58000","15.96512","0.01892"
"191.95200","15.99609","0.01860"
"192.32400","16.02718","0.01876"
"192.69600","16.05815","0.01915"
"193.06800","16.08912","0.01927"
"193.44000","16.12009","0.01913"
"193.81200","16.15113","0.01982"
"194.18400","16.18216","0.02003"
"194.55600","16.21313","0.01960"
"194.92800","16.24416","0.01983"
"195.30000","16.27513","0.02086"
"195.67200","16.30604","0.02031"
"196.04400","16.33713","0.02036"
"196.41600","16.36816","0.02105"
"196.78800","16.39913","0.02102"
"197.16000","16.43010","0.02125"
"197.53200","16.46113","0.02140"
"197.90400","16.49211","0.02128"
"198.27600","16.52314","0.02162"
"198.64800","16.55417","0.02183"
"199.02000","16.58508","0.02225"
"199.39200","16.61611","0.02170"
"199.76400","16.64714","0.02224"
"200.13600","16.67817","0.02197"
"200.50800","16.70914","0.02215"
"200.88000","16.74011","0.02273"
"201.25200","16.77120","0.02265"
"201.62400","16.80205","0.02260"
"201.99600","16.83309","0.02315"
"202.36800","16.86411","0.02326"
"202.74000","16.89515","0.02384"
"203.11200","16.92612","0.02346"
"203.48400","16.95715","0.02383"
"203.85600","16.98812","0.02348"
"204.22800","17.01909","0.02465"
"204.60000","17.05018","0.02451"
"204.97200","17.08115","0.02460"
"205.34400","17.11212","0.02440"
"205.71600","17.14315","0.02500"
"206.08800","17.17418","0.02528"
"206.46000","17.20510","0.02518"
"206.83200","17.23619","0.02545"
"207.20400","17.26710","0.02576"
"207.57600","17.29813","0.02606"
"207.94800","17.32916","0.02622"
"208.32000","17.36013","0.02599"
"208.69200","17.39110","0.02583"
"209.06400","17.42207","0.02622"
"209.43600","17.45310","0.02671"
"209.80800","17.48413","0.02658"
"210.18000","17.51510","0.02714"
"210.55200","17.54614","0.02707"
"210.92400","17.57717","0.02737"
"211.29600","17.60808","0.02770"
"211.66800","17.63911","0.02729"
"212.04000","17.67020","0.02865"
"212.41200","17.70111","0.02805"
"212.78400","17.73208","0.02829"
"213.15600","17.76317","0.02906"
"213.52800","17.79408","0.02872"
"213.90000","17.82511","0.02883"
"214.27200","17.85614","0.02893"
"214.64400","17.88706","0.02887"
"215.01600","17.91809","0.02845"
"215.38800","17.94918","0.02856"
"215.76000","17.98015","0.02886"
"216.13200","18.01112","0.02904"
"216.50400","18.04215","0.02948"
"216.87600","18.07318","0.03000"
"217.24800","18.10409","0.02996"
"217.62000","18.13512","0.03035"
"217.99200","18.16615","0.02989"
"218.36400","18.19712","0.03071"
"218.73600","18.22809","0.03087"
"219.10800","18.25912","0.03113"
"219.48000","18.29010","0.03156"
"219.85200","18.32107","0.03167"
"220.22400","18.35216","0.03216"
"220.59600","18.38319","0.03307"
"220.96800","18.41404","0.03245"
"221.34000","18.44519","0.03298"
"221.71200","18.47616","0.03290"
"222.08400","18.50701","0.03397"
"222.45600","18.53816","0.03360"
"222.82800","18.56913","0.03398"
"223.20000","18.60017","0.03448"
"223.57200","18.63108","0.03428"
"223.94400","18.66217","0.03494"
"224.31600","18.69314","0.03479"
"224.68800","18.72405","0.03565"
"225.06000","18.75520","0.03549"
"225.43200","18.78617","0.03606"
"225.80400","18.81714","0.03562"
"226.17600","18.84811","0.03504"
"226.54800","18.87914","0.03642"
"226.92000","18.91011","0.03613"
"227.29200","18.94109","0.03675"
"227.66400","18.97218","0.03690"
"228.03600","19.00315","0.03759"
"228.40800","19.03412","0.03699"
"228.78000","19.06515","0.03724"
"229.15200","19.09612","0.03874"
"229.52400","19.12709","0.03818"
"229.89600","19.15818","0.03870"
"230.26800","19.18915","0.03808"
"230.64000","19.22006","0.03922"
"231.01200","19.25115","0.03962"
"231.38400","19.28218","0.03929"
"231.75600","19.31310","0.04044"
"232.12800","19.34413","0.04064"
"232.50000","19.37516","0.04107"
"232.87200","19.40607","0.04105"
"233.24400","19.43716","0.04157"
"233.61600","19.46813","0.04204"
"233.98800","19.49910","0.04249"
"234.36000","19.53007","0.04225"
"234.73200","19.56116","0.04266"
"235.10400","19.59213","0.04306"
"235.47600","19.62310","0.04364"
"235.84800","19.65413","0.04340"
"236.22000","19.68516","0.04380"
"236.59200","19.71608","0.04365"
"236.96400","19.74717","0.04361"
"237.33600","19.77814","0.04475"
"237.70800","19.80911","0.04506"
"238.08000","19.84008","0.04513"
"238.45200","19.87117","0.04560"
"238.82400","19.90214","0.04574"
"239.19600","19.93311","0.04594"
"239.56800","19.96420","0.04672"
"239.94000","19.99512","0.04702"
"240.31200","20.02603","0.04732"
"240.68400","20.05718","0.04750"
"241.05600","20.08815","0.04792"
"241.42800","20.11912","0.04802"
"241.80000","20.15015","0.04852"
"242.17200","20.18112","0.04875"
"242.54400","20.21209","0.04826"
"242.91600","20.24312","0.04880"
"243.28800","20.27415","0.04859"
"243.66000","20.30512","0.04890"
"244.03200","20.33610","0.04913"
"244.40400","20.36712","0.04905"
"244.77600","20.39810","0.04970"
"245.14800","20.42913","0.05004"
"245.52000","20.46016","0.05023"
"245.89200","20.49119","0.05002"
"246.26400","20.52210","0.05107"
"246.63600","20.55313","0.05089"
"247.00800","20.58422","0.05150"
"247.38000","20.61507","0.05104"
"247.75200","20.64610","0.05148"
"248.12400","20.67713","0.05170"
"248.49600","20.70811","0.05202"
"248.86800","20.73914","0.05223"
"249.24000","20.77017","0.05241"
"249.61200","20.80114","0.05284"
"249.98400","20.83211","0.05303"
"250.35600","20.86320","0.05286"
"250.72800","20.89417","0.05326"
"251.10000","20.92502","0.05364"
"251.47200","20.95617","0.05406"
"251.84400","20.98714","0.05423"
"252.21600","21.01805","0.05400"
"252.58800","21.04914","0.05446"
"252.96000","21.08012","0.05469"
"253.33200","21.11115","0.05463"
"253.70400","21.14212","0.05476"
"254.07600","21.17315","0.05483"
"254.44800","21.20418","0.05508"
"254.82000","21.23509","0.05460"
"255.19200","21.26612","0.05543"
"255.56400","21.29715","0.05516"
"255.93600","21.32812","0.05558"
"256.30800","21.35915","0.05593"
"256.68000","21.39018","0.05605"
"257.05200","21.42115","0.05647"
"257.42400","21.45213","0.05659"
"257.79600","21.48315","0.05680"
"258.16800","21.51413","0.05718"
"258.54000","21.54510","0.05728"
"258.91200","21.57613","0.05652"
"259.28400","21.60716","0.05616"
"259.65600","21.63807","0.05685"
"260.02800","21.66910","0.05721"
"260.40000","21.70013","0.05813"
"260.77200","21.73116","0.05874"
"261.14400","21.76213","0.05902"
"261.51600","21.79317","0.05971"
"261.88800","21.82408","0.06054"
"262.26000","21.85517","0.06124"
"262.63200","21.88614","0.06213"
"263.00400","21.91711","0.06238"
"263.37600","21.94814","0.06387"
"263.74800","21.97911","0.06462"
"264.12000","22.01014","0.06466"
"264.49200","22.04111","0.06548"
"264.86400","22.07214","0.06688"
"265.23600","22.10317","0.06661"
"265.60800","22.13408","0.06522"
"265.98000","22.16518","0.06414"
"266.35200","22.19615","0.06450"
"266.72400","22.22712","0.06478"
"267.09600","22.25815","0.06526"
"267.46800","22.28912","0.06272"
"267.84000","22.32009","0.06245"
"268.21200","22.35112","0.06309"
"268.58400","22.38215","0.06290"
"268.95600","22.41312","0.06286"
"269.32800","22.44415","0.06414"
"269.70000","22.47518","0.06345"
"270.07200","22.50616","0.06323"
"270.44400","22.53707","0.06417"
"270.81600","22.56810","0.06586"
"271.18800","22.59913","0.06660"
"271.56000","22.63010","0.06731"
"271.93200","22.66113","0.06813"
"272.30400","22.69216","0.06856"
"272.67600","22.72307","0.06901"
"273.04800","22.75410","0.06892"
"273.42000","22.78519","0.06893"
"273.79200","22.81610","0.06928"
"274.16400","22.84714","0.06974"
"274.53600","22.87816","0.06964"
"274.90800","22.90914","0.06961"
"275.28000","22.94011","0.06912"
"275.65200","22.97114","0.06872"
"276.02400","23.00217","0.06782"
"276.39600","23.03308","0.06893"
"276.76800","23.06411","0.06918"
"277.14000","23.09520","0.06889"
"277.51200","23.12605","0.06919"
"277.88400","23.15714","0.06997"
"278.25600","23.18817","0.07080"
"278.62800","23.21908","0.07089"
"279.00000","23.25012","0.07207"
"279.37200","23.28115","0.07389"
"279.74400","23.31212","0.07404"
"280.11600","23.34309","0.07411"
"280.48800","23.37412","0.07491"
"280.86000","23.40515","0.07587"
"281.23200","23.43600","0.07657"
"281.60400","23.46715","0.07731"
"281.97600","23.49818","0.07839"
"282.34800","23.52904","0.07924"
"282.72000","23.56012","0.07107"
"283.09200","23.59110","0.06925"
"283.46400","23.62213","0.06936"
"283.83600","23.65310","0.07074"
"284.20800","23.68413","0.07141"
"284.58000","23.71516","0.07212"
"284.95200","23.74613","0.07016"
"285.32400","23.77722","0.07099"
"285.69600","23.80813","0.07224"
"286.06800","23.83910","0.07313"
"286.44000","23.87008","0.07426"
"286.81200","23.90117","0.07588"
"287.18400","23.93208","0.07678"
"287.55600","23.96311","0.07746"
"287.92800","23.99414","0.07799"
"288.30000","24.02511","0.07970"
"288.67200","24.05608","0.08087"
"289.04400","24.08717","0.08190"
"289.41600","24.11814","0.08233"
"289.78800","24.14911","0.08297"
"290.16000","24.18014","0.08457"
"290.53200","24.21117","0.08456"
"290.90400","24.24208","0.08533"
"291.27600","24.27317","0.08617"
"291.64800","24.30409","0.08729"
"292.02000","24.33506","0.08859"
"292.39200","24.36615","0.08987"
"292.76400","24.39718","0.09071"
"293.13600","24.42809","0.09114"
"293.50800","24.45912","0.09245"
"293.88000","24.49015","0.09277"
"294.25200","24.52112","0.09391"
"294.62400","24.55215","0.09457"
"294.99600","24.58318","0.09545"
"295.36800","24.61415","0.09535"
"295.74000","24.64513","0.09630"
"296.11200","24.67616","0.09692"
"296.48400","24.70713","0.09773"
"296.85600","24.73810","0.09790"
"297.22800","24.76919","0.05229"
"297.60000","24.80010","0.05212"
"297.97200","24.83113","0.05113"
"298.34400","24.86210","0.05010"
"298.71600","24.89319","0.05020"
"299.08800","24.92410","0.05134"
"299.46000","24.95507","0.05080"
"299.83200","24.98616","0.05202"
"300.20400","25.01714","0.05287"
"300.57600","25.04811","0.05336"
"300.94800","25.07920","0.05381"
"301.32000","25.11017","0.05379"
"301.69200","25.14114","0.04433"
"302.06400","25.17211","0.04713"
"302.43600","25.20314","0.04649"
"302.80800","25.23411","0.04725"
"303.18000","25.26514","0.04707"
"303.55200","25.29617","0.04740"
"303.92400","25.32709","0.04580"
"304.29600","25.35812","0.04413"
"304.66800","25.38915","0.04405"
"305.04000","25.42018","0.04473"
"305.41200","25.45115","0.04389"
"305.78400","25.48212","0.04362"
"306.15600","25.51315","0.04284"
"306.52800","25.54406","0.04128"
"306.90000","25.57515","0.04071"
"307.27200","25.60618","0.04128"
"307.64400","25.63704","0.04294"
"308.01600","25.66813","0.04284"
"308.38800","25.69916","0.04327"
"308.76000","25.73007","0.04299"
"309.13200","25.76110","0.04144"
"309.50400","25.79213","0.04134"
"309.87600","25.82310","0.04223"
"310.24800","25.85413","0.04260"
"310.62000","25.88516","0.04297"
"310.99200","25.91613","0.04355"
"311.36400","25.94704","0.04372"
"311.73600","25.97813","0.04379"
"312.10800","26.00910","0.04539"
"312.48000","26.04013","0.04550"
"312.85200","26.07117","0.04603"
"313.22400","26.10214","0.04619"
"313.59600","26.13317","0.04704"
"313.96800","26.16408","0.04761"
"314.34000","26.19517","0.04757"
"314.71200","26.22614","0.04788"
"315.08400","26.25705","0.04817"
"315.45600","26.28815","0.04876"
"315.82800","26.31911","0.04862"
"316.20000","26.35008","0.04915"
"316.57200","26.38117","0.04761"
"316.94400","26.41214","0.03532"
"317.31600","26.44312","0.03705"
"317.68800","26.47409","0.03588"
"318.06000","26.50512","0.03278"
"318.43200","26.53609","0.03172"
"318.80400","26.56712","0.03298"
"319.17600","26.59815","0.03418"
"319.54800","26.62912","0.03586"
"319.92000","26.66009","0.03664"
"320.29200","26.69113","0.03688"
"320.66400","26.72215","0.03651"
"321.03600","26.75313","0.03724"
"321.40800","26.78410","0.03716"
"321.78000","26.81519","0.03787"
"322.15200","26.84610","0.03829"
"322.52400","26.87707","0.03843"
"322.89600","26.90816","0.03860"
"323.26800","26.93913","0.03953"
"323.64000","26.97016","0.03938"
"324.01200","27.00113","0.03936"
"324.38400","27.03210","0.04009"
"324.75600","27.06308","0.04001"
"325.12800","27.09417","0.03963"
"325.50000","27.12520","0.04050"
"325.87200","27.15611","0.04019"
"326.24400","27.18714","0.04083"
"326.61600","27.21811","0.03985"
"326.98800","27.24908","0.04106"
"327.36000","27.28017","0.04096"
"327.73200","27.31114","0.04046"
"328.10400","27.34211","0.04093"
"328.47600","27.37314","0.03969"
"328.84800","27.40411","0.03747"
"329.22000","27.43514","0.03847"
"329.59200","27.46612","0.03799"
"329.96400","27.49715","0.03806"
"330.33600","27.52812","0.03787"
"330.70800","27.55909","0.03808"
"331.08000","27.59012","0.03837"
"331.45200","27.62115","0.03875"
"331.82400","27.65206","0.03917"
"332.19600","27.68315","0.03859"
"332.56800","27.71418","0.03851"
"332.94000","27.74510","0.03948"
"333.31200","27.77612","0.03954"
"333.68400","27.80721","0.03977"
"334.05600","27.83807","0.04021"
"334.42800","27.86910","0.04031"
"334.80000","27.90013","0.04085"
"335.17200","27.93116","0.04003"
"335.54400","27.96207","0.03857"
"335.91600","27.99316","0.03339"
"336.28800","28.02413","0.03536"
"336.66000","28.05504","0.03494"
"337.03200","28.08607","0.03555"
"337.40400","28.11722","0.03565"
"337.77600","28.14808","0.03615"
"338.14800","28.17917","0.03662"
"338.52000","28.21014","0.03694"
"338.89200","28.24117","0.03719"
"339.26400","28.27208","0.03827"
"339.63600","28.30311","0.03879"
"340.00800","28.33414","0.03827"
"340.38000","28.36511","0.03902"
"340.75200","28.39614","0.03899"
"341.12400","28.42717","0.03874"
"341.49600","28.45808","0.03949"
"341.86800","28.48918","0.03961"
"342.24000","28.52015","0.04009"
"342.61200","28.55106","0.04136"
"342.98400","28.58215","0.04047"
"343.35600","28.61312","0.04089"
"343.72800","28.64415","0.04137"
"344.10000","28.67506","0.04142"
"344.47200","28.70615","0.04124"
"344.84400","28.73712","0.04195"
"345.21600","28.76809","0.04222"
"345.58800","28.79918","0.04220"
"345.96000","28.83015","0.04221"
"346.33200","28.86113","0.04281"
"346.70400","28.89216","0.04316"
"347.07600","28.92319","0.04321"
"347.44800","28.95410","0.04295"
"347.82000","28.98507","0.04156"
"348.19200","29.01616","0.04377"
"348.56400","29.04713","0.04429"
"348.93600","29.07810","0.04443"
"349.30800","29.10919","0.04485"
"349.68000","29.14011","0.04482"
"350.05200","29.17107","0.04464"
"350.42400","29.20217","0.04492"
"350.79600","29.23319","0.04486"
"351.16800","29.26405","0.04513"
"351.54000","29.29514","0.04531"
"351.91200","29.32611","0.04551"
"352.28400","29.35708","0.04560"
"352.65600","29.38811","0.04588"
"353.02800","29.41914","0.04593"
"353.40000","29.45011","0.04648"
"353.77200","29.48114","0.04652"
"354.14400","29.51211","0.04685"
"354.51600","29.54314","0.04707"
"354.88800","29.57412","0.04720"
"355.26000","29.60515","0.04796"
"355.63200","29.63612","0.04829"
"356.00400","29.66709","0.04855"
"356.37600","29.69812","0.04932"
"356.74800","29.72915","0.04896"
"357.12000","29.76006","0.04872"
"357.49200","29.79115","0.04886"
"357.86400","29.82212","0.04912"
"358.23600","29.85315","0.04610"
"358.60800","29.88413","0.04217"
"358.98000","29.91515","0.03983"
"359.35200","29.94613","0.04022"
"359.72400","29.97716","0.04180"
"360.09600","30.00813","0.04262"
"360.46800","30.03910","0.04358"
"360.84000","30.07013","0.04379"
"361.21200","30.10122","0.04477"
"361.58400","30.13213","0.04449"
"361.95600","30.16310","0.04058"
"362.32800","30.19413","0.03722"
"362.70000","30.22511","0.03814"
"363.07200","30.25607","0.03876"
"363.44400","30.28711","0.03904"
"363.81600","30.31814","0.03934"
"364.18800","30.34911","0.04063"
"364.56000","30.38014","0.03931"
"364.93200","30.41111","0.04025"
"365.30400","30.44214","0.03934"
"365.67600","30.47311","0.04054"
"366.04800","30.50414","0.04001"
"366.42000","30.53517","0.03965"
"366.79200","30.56602","0.04033"
"367.16400","30.59711","0.04044"
"367.53600","30.62815","0.04049"
"367.90800","30.65906","0.04102"
"368.28000","30.69015","0.04118"
"368.65200","30.72112","0.04171"
"369.02400","30.75209","0.04173"
"369.39600","30.78312","0.04217"
"369.76800","30.81415","0.04281"
"370.14000","30.84518","0.04232"
"370.51200","30.87609","0.04330"
"370.88400","30.90718","0.04312"
"371.25600","30.93815","0.04344"
"371.62800","30.96906","0.04337"
"372.00000","31.00016","0.04328"
"372.37200","31.03113","0.04333"
"372.74400","31.06210","0.04387"
"373.11600","31.09313","0.04343"
"373.48800","31.12416","0.04453"
"373.86000","31.15513","0.04502"
"374.23200","31.18604","0.04504"
"374.60400","31.21713","0.03463"
"374.97600","31.24816","0.03329"
"375.34800","31.27913","0.03470"
"375.72000","31.31016","0.03459"
"376.09200","31.34114","0.03464"
"376.46400","31.37210","0.03408"
"376.83600","31.40314","0.03278"
"377.20800","31.43423","0.03317"
"377.58000","31.46514","0.03398"
"377.95200","31.49611","0.03385"
"378.32400","31.52720","0.03440"
"378.69600","31.55811","0.03415"
"379.06800","31.58914","0.03441"
"379.44000","31.62017","0.03410"
"379.81200","31.65108","0.03445"
"380.18400","31.68212","0.03385"
"380.55600","31.71315","0.03391"
"380.92800","31.74412","0.03462"
"381.30000","31.77509","0.03406"
"381.67200","31.80612","0.03392"
"382.04400","31.83721","0.03455"
"382.41600","31.86806","0.03494"
"382.78800","31.89909","0.03427"
"383.16000","31.93018","0.03374"
"383.53200","31.96109","0.03260"
"383.90400","31.99212","0.03307"
"384.27600","32.02316","0.03287"
"384.64800","32.05413","0.03337"
"385.02000","32.08509","0.03372"
"385.39200","32.11613","0.03340"
"385.76400","32.14716","0.03355"
"386.13600","32.17807","0.03382"
"386.50800","32.20916","0.03439"
"386.88000","32.24013","0.03497"
"387.25200","32.27104","0.03424"
"387.62400","32.30219","0.03438"
"387.99600","32.33316","0.03485"
"388.36800","32.36407","0.03526"
"388.74000","32.39511","0.03450"
"389.11200","32.42613","0.03455"
"389.48400","32.45716","0.03512"
"389.85600","32.48814","0.03503"
"390.22800","32.51917","0.03522"
"390.60000","32.55008","0.03484"
"390.97200","32.58105","0.03536"
"391.34400","32.61220","0.03568"
"391.71600","32.64317","0.03603"
"392.08800","32.67408","0.03562"
"392.46000","32.70511","0.03570"
"392.83200","32.73621","0.03562"
"393.20400","32.76711","0.03626"
"393.57600","32.79808","0.03648"
"393.94800","32.82918","0.03629"
"394.32000","32.86009","0.03655"
"394.69200","32.89112","0.03695"
"395.06400","32.92215","0.03649"
"395.43600","32.95312","0.03621"
"395.80800","32.98409","0.03670"
"396.18000","33.01518","0.03686"
"396.55200","33.04615","0.03649"
"396.92400","33.07706","0.03627"
"397.29600","33.10815","0.03669"
"397.66800","33.13918","0.03701"
"398.04000","33.17004","0.03666"
"398.41200","33.20113","0.03783"
"398.78400","33.23210","0.03814"
"399.15600","33.26313","0.03828"
"399.52800","33.29410","0.03691"
"399.90000","33.32519","0.03714"
"400.27200","33.35610","0.03725"
"400.64400","33.38707","0.03770"
"401.01600","33.41816","0.03779"
"401.38800","33.44920","0.03759"
"401.76000","33.48005","0.03821"
"402.13200","33.51120","0.03749"
"402.50400","33.54217","0.03771"
"402.87600","33.57302","0.03844"
"403.24800","33.60411","0.03829"
"403.62000","33.63514","0.03790"
"403.99200","33.66611","0.03870"
"404.36400","33.69708","0.03858"
"404.73600","33.72817","0.03823"
"405.10800","33.75914","0.03807"
"405.48000","33.79012","0.03898"
"405.85200","33.82114","0.03856"
"406.22400","33.85212","0.03965"
"406.59600","33.88309","0.03876"
"406.96800","33.91412","0.03859"
"407.34000","33.94521","0.03927"
"407.71200","33.97612","0.03955"
"408.08400","34.00709","0.03981"
"408.45600","34.03818","0.03951"
"408.82800","34.06909","0.03880"
"409.20000","34.10012","0.03975"
"409.57200","34.13115","0.03845"
"409.94400","34.16212","0.03905"
"410.31600","34.19310","0.03918"
"410.68800","34.22412","0.03917"
"411.06000","34.25516","0.03985"
"411.43200","34.28607","0.03992"
"411.80400","34.31716","0.03995"
"412.17600","34.34819","0.03941"
"412.54800","34.37910","0.03993"
"412.92000","34.41013","0.03948"
"413.29200","34.44116","0.03943"
"413.66400","34.47207","0.03949"
"414.03600","34.50317","0.03988"
"414.40800","34.53407","0.03971"
"414.78000","34.56517","0.03960"
"415.15200","34.59614","0.04017"
"415.52400","34.62711","0.03989"
"415.89600","34.65814","0.04041"
"416.26800","34.68911","0.04022"
"416.64000","34.72008","0.04015"
"417.01200","34.75117","0.04121"
"417.38400","34.78208","0.04073"
"417.75600","34.81317","0.04117"
"418.12800","34.84409","0.04133"
"418.50000","34.87511","0.04114"
"418.87200","34.90609","0.04087"
"419.24400","34.93712","0.04127"
"419.61600","34.96815","0.04104"
"419.98800","34.99906","0.04056"
"420.36000","35.03015","0.04087"
"420.73200","35.06112","0.04082"
"421.10400","35.09209","0.04091"
"421.47600","35.12318","0.04150"
"421.84800","35.15415","0.04156"
"422.22000","35.18512","0.04168"
"422.59200","35.21615","0.04224"
"422.96400","35.24712","0.04157"
"423.33600","35.27810","0.04132"
"423.70800","35.30913","0.04148"
"424.08000","35.34016","0.04157"
"424.45200","35.37113","0.04134"
"424.82400","35.40216","0.04172"
"425.19600","35.43313","0.04181"
"425.56800","35.46410","0.04204"
"425.94000","35.49513","0.04180"
"426.31200","35.52617","0.04213"
"426.68400","35.55719","0.04261"
"427.05600","35.58804","0.04181"
"427.42800","35.61914","0.04194"
"427.80000","35.65017","0.04195"
"428.17200","35.68114","0.04221"
"428.54400","35.71211","0.04249"
"428.91600","35.74314","0.04191"
"429.28800","35.77411","0.04263"
"429.66000","35.80514","0.04334"
"430.03200","35.83617","0.04338"
"430.40400","35.86714","0.04382"
"430.77600","35.89806","0.04408"
"431.14800","35.92914","0.04366"
"431.52000","35.96012","0.04399"
"431.89200","35.99109","0.04338"
"432.26400","36.02212","0.04380"
"432.63600","36.05315","0.04428"
"433.00800","36.08412","0.04354"
"433.38000","36.11509","0.04295"
"433.75200","36.14612","0.04268"
"434.12400","36.17715","0.04275"
"434.49600","36.20812","0.04239"
"434.86800","36.23915","0.04292"
"435.24000","36.27018","0.04226"
"435.61200","36.30116","0.04236"
"435.98400","36.33213","0.04320"
"436.35600","36.36316","0.04243"
"436.72800","36.39407","0.04212"
"437.10000","36.42516","0.04326"
"437.47200","36.45619","0.04289"
"437.84400","36.48710","0.04350"
"438.21600","36.51813","0.04306"
"438.58800","36.54922","0.04276"
"438.96000","36.58007","0.04282"
"439.33200","36.61110","0.04305"
"439.70400","36.64214","0.04299"
"440.07600","36.67316","0.04269"
"440.44800","36.70414","0.04264"
"440.82000","36.73516","0.04279"
"441.19200","36.76614","0.04300"
"441.56400","36.79705","0.04256"
"441.93600","36.82814","0.04239"
"442.30800","36.85917","0.04258"
"442.68000","36.89002","0.04224"
"443.05200","36.92117","0.04265"
"443.42400","36.95214","0.04303"
"443.79600","36.98311","0.04271"
"444.16800","37.01414","0.04308"
"444.54000","37.04512","0.04325"
"444.91200","37.07608","0.04324"
"445.28400","37.10712","0.04351"
"445.65600","37.13815","0.04368"
"446.02800","37.16918","0.04292"
"446.40000","37.20009","0.04375"
"446.77200","37.23112","0.04334"
"447.14400","37.26209","0.04329"
"447.51600","37.29306","0.04369"
"447.88800","37.32415","0.04380"
"448.26000","37.35513","0.04274"
"448.63200","37.38610","0.04344"
"449.00400","37.41713","0.04256"
"449.37600","37.44816","0.04285"
"449.74800","37.47913","0.04275"
"450.12000","37.51010","0.04301"
"450.49200","37.54119","0.04318"
"450.86400","37.57216","0.04329"
"451.23600","37.60313","0.04365"
"451.60800","37.63411","0.04334"
"451.98000","37.66513","0.04278"
"452.35200","37.69604","0.04312"
"452.72400","37.72720","0.04334"
"453.09600","37.75817","0.04320"
"453.46800","37.78908","0.04310"
"453.84000","37.82011","0.04242"
"454.21200","37.85114","0.04284"
"454.58400","37.88205","0.04326"
"454.95600","37.91308","0.04334"
"455.32800","37.94411","0.04339"
"455.70000","37.97514","0.04316"
"456.07200","38.00611","0.04373"
"456.44400","38.03720","0.04381"
"456.81600","38.06812","0.04381"
"457.18800","38.09909","0.04382"
"457.56000","38.13012","0.04430"
"457.93200","38.16121","0.04338"
"458.30400","38.19206","0.04385"
"458.67600","38.22315","0.04406"
"459.04800","38.25412","0.04358"
"459.42000","38.28509","0.04444"
"459.79200","38.31612","0.04463"
"460.16400","38.34716","0.04430"
"460.53600","38.37806","0.04460"
"460.90800","38.40910","0.04490"
"461.28000","38.44019","0.04440"
"461.65200","38.47122","0.04429"
"462.02400","38.50207","0.04451"
"462.39600","38.53316","0.04425"
"462.76800","38.56413","0.04402"
"463.14000","38.59510","0.04423"
"463.51200","38.62613","0.04439"
"463.88400","38.65710","0.04399"
"464.25600","38.68813","0.04435"
"464.62800","38.71910","0.04467"
"465.00000","38.75013","0.04575"
"465.37200","38.78111","0.04436"
"465.74400","38.81208","0.04531"
"466.11600","38.84317","0.04438"
"466.48800","38.87414","0.04439"
"466.86000","38.90511","0.04465"
"467.23200","38.93608","0.04527"
"467.60400","38.96717","0.04553"
"467.97600","38.99808","0.04526"
"468.34800","39.02911","0.04550"
"468.72000","39.06020","0.04463"
"469.09200","39.09111","0.04539"
"469.46400","39.12215","0.04592"
"469.83600","39.15318","0.04598"
"470.20800","39.18409","0.04679"
"470.58000","39.21512","0.04622"
"470.95200","39.24615","0.04649"
"471.32400","39.27712","0.04725"
"471.69600","39.30809","0.04737"
"472.06800","39.33912","0.04698"
"472.44000","39.37015","0.04573"
"472.81200","39.40106","0.04607"
"473.18400","39.43215","0.04717"
"473.55600","39.46318","0.04659"
"473.92800","39.49410","0.04655"
"474.30000","39.52518","0.04652"
"474.67200","39.55610","0.04707"
"475.04400","39.58713","0.04682"
"475.41600","39.61810","0.04721"
"475.78800","39.64912","0.04749"
"476.16000","39.68016","0.04737"
"476.53200","39.71113","0.04778"
"476.90400","39.74216","0.04783"
"477.27600","39.77313","0.04787"
"477.64800","39.80410","0.04800"
"478.02000","39.83513","0.04795"
"478.39200","39.86610","0.04816"
"478.76400","39.89714","0.04889"
"479.13600","39.92811","0.04831"
"479.50800","39.95914","0.04871"
"479.88000","39.99010","0.04880"
"480.25200","40.02108","0.04941"
"480.62400","40.05217","0.04938"
"480.99600","40.08308","0.04951"
"481.36800","40.11411","0.04969"
"481.74000","40.14520","0.04947"
"482.11200","40.17612","0.05041"
"482.48400","40.20709","0.05051"
"482.85600","40.23811","0.05061"
"483.22800","40.26914","0.05013"
"483.60000","40.30006","0.05045"
"483.97200","40.33115","0.05067"
"484.34400","40.36218","0.05074"
"484.71600","40.39309","0.05057"
"485.08800","40.42412","0.05138"
"485.46000","40.45515","0.05125"
"485.83200","40.48618","0.05157"
"486.20400","40.51715","0.05171"
"486.57600","40.54813","0.05178"
"486.94800","40.57915","0.05215"
"487.32000","40.61007","0.05218"
"487.69200","40.64109","0.05257"
"488.06400","40.67219","0.05297"
"488.43600","40.70304","0.05302"
"488.80800","40.73413","0.04377"
"489.18000","40.76516","0.04496"
"489.55200","40.79613","0.04618"
"489.92400","40.82710","0.04616"
"490.29600","40.85813","0.04614"
"490.66800","40.88916","0.04544"
"491.04000","40.92007","0.04611"
"491.41200","40.95117","0.04613"
"491.78400","40.98214","0.04624"
"492.15600","41.01311","0.03913"
"492.52800","41.04408","0.03779"
"492.90000","41.07511","0.03757"
"493.27200","41.10608","0.03722"
"493.64400","41.13712","0.03864"
"494.01600","41.16814","0.03889"
"494.38800","41.19911","0.03928"
"494.76000","41.23008","0.03970"
"495.13200","41.26117","0.03970"
"495.50400","41.29214","0.03929"
"495.87600","41.32312","0.03991"
"496.24800","41.35415","0.04048"
"496.62000","41.38518","0.04074"
"496.99200","41.41609","0.04061"
"497.36400","41.44712","0.04074"
"497.73600","41.47821","0.04076"
"498.10800","41.50912","0.04090"
"498.48000","41.54009","0.04028"
"498.85200","41.57119","0.04008"
"499.22400","41.60210","0.04121"
"499.59600","41.63318","0.04085"
"499.96800","41.66415","0.04145"
"500.34000","41.69513","0.04093"
"500.71200","41.72610","0.04117"
"501.08400","41.75713","0.04124"
"501.45600","41.78816","0.04177"
"501.82800","41.81913","0.04173"
"502.20000","41.85010","0.04185"
"502.57200","41.88119","0.04111"
"502.94400","41.91204","0.04141"
"503.31600","41.94308","0.04084"
"503.68800","41.97416","0.04103"
"504.06000","42.00514","0.04093"
"504.43200","42.03617","0.04138"
"504.80400","42.06713","0.04134"
"505.17600","42.09817","0.04087"
"505.54800","42.12914","0.04068"
"505.92000","42.16017","0.04122"
"506.29200","42.19114","0.04162"
"506.66400","42.22211","0.04225"
"507.03600","42.25320","0.04142"
"507.40800","42.28411","0.04235"
"507.78000","42.31509","0.04198"
"508.15200","42.34618","0.04264"
"508.52400","42.37708","0.04223"
"508.89600","42.40812","0.04312"
"509.26800","42.43909","0.04325"
"509.64000","42.47012","0.04343"
"510.01200","42.50109","0.04328"
"510.38400","42.53206","0.04355"
"510.75600","42.56315","0.04347"
"511.12800","42.59412","0.04323"
"511.50000","42.62509","0.04405"
"511.87200","42.65612","0.04351"
"512.24400","42.68710","0.04328"
"512.61600","42.71813","0.04364"
"512.98800","42.74916","0.04370"
"513.36000","42.78019","0.04379"
"513.73200","42.81104","0.04374"
"514.10400","42.84213","0.04425"
"514.47600","42.87322","0.04428"
"514.84800","42.90407","0.04485"
"515.22000","42.93516","0.04486"
"515.59200","42.96613","0.04504"
"515.96400","42.99711","0.04522"
"516.33600","43.02808","0.04586"
"516.70800","43.05916","0.04615"
"517.08000","43.09014","0.04603"
"517.45200","43.12111","0.04660"
"517.82400","43.15214","0.04685"
"518.19600","43.18317","0.04661"
"518.56800","43.21402","0.04682"
"518.94000","43.24517","0.04739"
"519.31200","43.27608","0.04696"
"519.68400","43.30706","0.04749"
"520.05600","43.33809","0.04739"
"520.42800","43.36911","0.04817"
"520.80000","43.40015","0.04807"
"521.17200","43.43111","0.04822"
"521.54400","43.46215","0.04814"
"521.91600","43.49318","0.04849"
"522.28800","43.52409","0.04850"
"522.66000","43.55518","0.04891"
"523.03200","43.58615","0.04904"
"523.40400","43.61700","0.04933"
"523.77600","43.64815","0.04910"
"524.14800","43.67913","0.04918"
"524.52000","43.71016","0.04951"
"524.89200","43.74113","0.04964"
"525.26400","43.77216","0.04954"
"525.63600","43.80307","0.04977"
"526.00800","43.83410","0.05022"
"526.38000","43.86513","0.05013"
"526.75200","43.89610","0.05037"
"527.12400","43.92713","0.05025"
"527.49600","43.95810","0.05096"
"527.86800","43.98913","0.05062"
"528.24000","44.02010","0.05052"
"528.61200","44.05113","0.05071"
"528.98400","44.08216","0.05101"
"529.35600","44.11314","0.05122"
"529.72800","44.14417","0.05130"
"530.10000","44.17514","0.05129"
"530.47200","44.20617","0.05128"
"530.84400","44.23708","0.05094"
"531.21600","44.26811","0.05142"
"531.58800","44.29920","0.05179"
"531.96000","44.33011","0.05181"
"532.33200","44.36115","0.05170"
"532.70400","44.39212","0.05127"
"533.07600","44.42308","0.05098"
"533.44800","44.45417","0.05031"
"533.82000","44.48515","0.05050"
"534.19200","44.51612","0.05084"
"534.56400","44.54715","0.05078"
"534.93600","44.57806","0.05118"
"535.30800","44.60909","0.05078"
"535.68000","44.64012","0.05103"
"536.05200","44.67115","0.05085"
"536.42400","44.70213","0.05127"
"536.79600","44.73315","0.05147"
"537.16800","44.76412","0.05150"
"537.54000","44.79515","0.05177"
"537.91200","44.82612","0.05014"
"538.28400","44.85715","0.04910"
"538.65600","44.88813","0.04944"
"539.02800","44.91910","0.04992"
"539.40000","44.95013","0.05055"
"539.77200","44.98116","0.05087"
"540.14400","45.01213","0.05079"
"540.51600","45.04310","0.05089"
"540.88800","45.07413","0.05104"
"541.26000","45.10511","0.05103"
"541.63200","45.13607","0.05117"
"542.00400","45.16717","0.05172"
"542.37600","45.19820","0.05182"
"542.74800","45.22911","0.05155"
"543.12000","45.26014","0.05192"
"543.49200","45.29117","0.05172"
"543.86400","45.32208","0.05173"
"544.23600","45.35311","0.05188"
"544.60800","45.38414","0.05232"
"544.98000","45.41505","0.05217"
"545.35200","45.44614","0.05208"
"545.72400","45.47717","0.05248"
"546.09600","45.50815","0.05241"
"546.46800","45.53912","0.05255"
"546.84000","45.57015","0.05242"
"547.21200","45.60117","0.05255"
"547.58400","45.63209","0.05249"
"547.95600","45.66312","0.05259"
"548.32800","45.69415","0.05265"
"548.70000","45.72506","0.05303"
"549.07200","45.75615","0.05304"
"549.44400","45.78712","0.05325"
"549.81600","45.81809","0.05320"
"550.18800","45.84912","0.05329"
"550.56000","45.88010","0.05342"
"550.93200","45.91119","0.05361"
"551.30400","45.94210","0.05374"
"551.67600","45.97313","0.05337"
"552.04800","46.00410","0.05342"
"552.42000","46.03507","0.05354"
"552.79200","46.06616","0.05357"
"553.16400","46.09713","0.05385"
"553.53600","46.12811","0.05412"
"553.90800","46.15914","0.05405"
"554.28000","46.19010","0.05409"
"554.65200","46.22113","0.05417"
"555.02400","46.25205","0.05402"
"555.39600","46.28314","0.05436"
"555.76800","46.31417","0.05463"
"556.14000","46.34508","0.05440"
"556.46200","46.37193","0.05415"