File: Force_trajectories/170225_2/Specimen_RawData_8.csv
End date,"2/25/2017"
Specimen label,"1DG_unk"
Maximum Load,"0.41180",N

Time,Extension,Load
(s),(mm),(N)
"0.00000","0.00000","-0.00015"
"0.28800","0.02320","0.00055"
"0.57600","0.04819","0.00094"
"0.86400","0.07217","0.00156"
"1.15200","0.09620","0.00209"
"1.44000","0.12024","0.00241"
"1.72800","0.14415","0.00214"
"2.01600","0.16819","0.00285"
"2.30400","0.19216","0.00262"
"2.59200","0.21626","0.00326"
"2.88000","0.24017","0.00318"
"3.16800","0.26421","0.00373"
"3.45600","0.28819","0.00320"
"3.74400","0.31222","0.00335"
"4.03200","0.33614","0.00367"
"4.32000","0.36017","0.00434"
"4.60800","0.38409","0.00462"
"4.89600","0.40818","0.00441"
"5.18400","0.43216","0.00443"
"5.47200","0.45619","0.00478"
"5.76000","0.48017","0.00479"
"6.04800","0.50421","0.00502"
"6.33600","0.52818","0.00496"
"6.62400","0.55216","0.00560"
"6.91200","0.57619","0.00497"
"7.20000","0.60017","0.00566"
"7.48800","0.62426","0.00535"
"7.77600","0.64818","0.00597"
"8.06400","0.67221","0.00595"
"8.35200","0.69613","0.00615"
"8.64000","0.72022","0.00646"
"8.92800","0.74420","0.00593"
"9.21600","0.76818","0.00620"
"9.50400","0.79215","0.00648"
"9.79200","0.81619","0.00706"
"10.08000","0.84016","0.00669"
"10.36800","0.86420","0.00706"
"10.65600","0.88823","0.00663"
"10.94400","0.91221","0.00667"
"11.23200","0.93624","0.00712"
"11.52000","0.96016","0.00764"
"11.80800","0.98426","0.00696"
"12.09600","1.00817","0.00757"
"12.38400","1.03221","0.00697"
"12.67200","1.05618","0.00696"
"12.96000","1.08016","0.00782"
"13.24800","1.10413","0.00822"
"13.53600","1.12823","0.00822"
"13.82400","1.15220","0.00799"
"14.11200","1.17618","0.00814"
"14.40000","1.20022","0.00791"
"14.68800","1.22413","0.00802"
"14.97600","1.24823","0.00829"
"15.26400","1.27214","0.00802"
"15.55200","1.29624","0.00836"
"15.84000","1.32009","0.00822"
"16.12800","1.34419","0.00861"
"16.41600","1.36816","0.00859"
"16.70400","1.39220","0.00843"
"16.99200","1.41617","0.00859"
"17.28000","1.44021","0.00895"
"17.56800","1.46419","0.00940"
"17.85600","1.48816","0.00894"
"18.14400","1.51220","0.00923"
"18.43200","1.53617","0.00914"
"18.72000","1.56015","0.00905"
"19.00800","1.58418","0.00994"
"19.29600","1.60822","0.00967"
"19.58400","1.63219","0.00994"
"19.87200","1.65617","0.00944"
"20.16000","1.68015","0.00938"
"20.44800","1.70418","0.01041"
"20.73600","1.72816","0.00981"
"21.02400","1.75219","0.01047"
"21.31200","1.77617","0.01078"
"21.60000","1.80020","0.01105"
"21.88800","1.82418","0.01065"
"22.17600","1.84821","0.01124"
"22.46400","1.87219","0.01111"
"22.75200","1.89617","0.01147"
"23.04000","1.92020","0.01133"
"23.32800","1.94412","0.01116"
"23.61600","1.96815","0.01130"
"23.90400","1.99213","0.01122"
"24.19200","2.01616","0.01176"
"24.48000","2.04014","0.01240"
"24.76800","2.06423","0.01290"
"25.05600","2.08815","0.01242"
"25.34400","2.11224","0.01282"
"25.63200","2.13610","0.01302"
"25.92000","2.16014","0.01310"
"26.20800","2.18417","0.01268"
"26.49600","2.20821","0.01285"
"26.78400","2.23218","0.01305"
"27.07200","2.25616","0.01242"
"27.36000","2.28025","0.01305"
"27.64800","2.30411","0.01379"
"27.93600","2.32814","0.01382"
"28.22400","2.35212","0.01347"
"28.51200","2.37622","0.01359"
"28.80000","2.40013","0.01386"
"29.08800","2.42423","0.01408"
"29.37600","2.44814","0.01438"
"29.66400","2.47218","0.01439"
"29.95200","2.49615","0.01489"
"30.24000","2.52013","0.01492"
"30.52800","2.54416","0.01508"
"30.81600","2.56814","0.01493"
"31.10400","2.59218","0.01528"
"31.39200","2.61615","0.01521"
"31.68000","2.64019","0.01618"
"31.96800","2.66410","0.01540"
"32.25600","2.68814","0.01642"
"32.54400","2.71211","0.01634"
"32.83200","2.73621","0.01617"
"33.12000","2.76006","0.01643"
"33.40800","2.78422","0.01629"
"33.69600","2.80814","0.01754"
"33.98400","2.83223","0.01718"
"34.27200","2.85621","0.01718"
"34.56000","2.88018","0.01663"
"34.84800","2.90416","0.01693"
"35.13600","2.92813","0.01727"
"35.42400","2.95217","0.01725"
"35.71200","2.97614","0.01767"
"36.00000","3.00012","0.01804"
"36.28800","3.02415","0.01815"
"36.57600","3.04819","0.01810"
"36.86400","3.07211","0.01860"
"37.15200","3.09620","0.01802"
"37.44000","3.12012","0.01924"
"37.72800","3.14421","0.01895"
"38.01600","3.16819","0.01903"
"38.30400","3.19216","0.01924"
"38.59200","3.21620","0.01957"
"38.88000","3.24011","0.01911"
"39.16800","3.26421","0.01919"
"39.45600","3.28813","0.01993"
"39.74400","3.31222","0.01997"
"40.03200","3.33614","0.02022"
"40.32000","3.36017","0.02113"
"40.60800","3.38409","0.02019"
"40.89600","3.40818","0.02058"
"41.18400","3.43210","0.02004"
"41.47200","3.45625","0.02107"
"41.76000","3.48017","0.02062"
"42.04800","3.50420","0.02180"
"42.33600","3.52818","0.02117"
"42.62400","3.55216","0.02222"
"42.91200","3.57619","0.02182"
"43.20000","3.60017","0.02292"
"43.48800","3.62420","0.02245"
"43.77600","3.64818","0.02312"
"44.06400","3.67221","0.02210"
"44.35200","3.69619","0.02284"
"44.64000","3.72022","0.02292"
"44.92800","3.74414","0.02353"
"45.21600","3.76818","0.02243"
"45.50400","3.79215","0.02112"
"45.79200","3.81619","0.01944"
"46.08000","3.84016","0.01739"
"46.36800","3.86420","0.01692"
"46.65600","3.88823","0.01696"
"46.94400","3.91221","0.01482"
"47.23200","3.93624","0.01350"
"47.52000","3.96016","0.01216"
"47.80800","3.98425","0.01089"
"48.09600","4.00817","0.00928"
"48.38400","4.03221","0.00855"
"48.67200","4.05612","0.00801"
"48.96000","4.08022","0.00838"
"49.24800","4.10413","0.00879"
"49.53600","4.12823","0.00863"
"49.82400","4.15214","0.00763"
"50.11200","4.17624","0.00835"
"50.40000","4.20021","0.00902"
"50.68800","4.22419","0.00903"
"50.97600","4.24817","0.00906"
"51.26400","4.27220","0.00917"
"51.55200","4.29618","0.01027"
"51.84000","4.32015","0.00965"
"52.12800","4.34425","0.01062"
"52.41600","4.36816","0.01071"
"52.70400","4.39220","0.01061"
"52.99200","4.41617","0.01051"
"53.28000","4.44021","0.01076"
"53.56800","4.46419","0.01079"
"53.85600","4.48816","0.01116"
"54.14400","4.51220","0.01222"
"54.43200","4.53617","0.01173"
"54.72000","4.56021","0.01226"
"55.00800","4.58418","0.01202"
"55.29600","4.60822","0.01268"
"55.58400","4.63219","0.01288"
"55.87200","4.65623","0.01257"
"56.16000","4.68015","0.01327"
"56.44800","4.70424","0.01331"
"56.73600","4.72810","0.01427"
"57.02400","4.75219","0.01389"
"57.31200","4.77611","0.01412"
"57.60000","4.80020","0.01436"
"57.88800","4.82418","0.01484"
"58.17600","4.84821","0.01540"
"58.46400","4.87219","0.01443"
"58.75200","4.89616","0.01513"
"59.04000","4.92020","0.01520"
"59.32800","4.94418","0.01571"
"59.61600","4.96821","0.01565"
"59.90400","4.99219","0.01597"
"60.19200","5.01616","0.01582"
"60.48000","5.04014","0.01644"
"60.76800","5.06417","0.01612"
"61.05600","5.08815","0.01603"
"61.34400","5.11218","0.01664"
"61.63200","5.13616","0.01689"
"61.92000","5.16020","0.01707"
"62.20800","5.18417","0.01709"
"62.49600","5.20815","0.01693"
"62.78400","5.23212","0.01699"
"63.07200","5.25616","0.01752"
"63.36000","5.28013","0.01728"
"63.64800","5.30411","0.01757"
"63.93600","5.32814","0.01790"
"64.22400","5.35212","0.01741"
"64.51200","5.37621","0.01765"
"64.80000","5.40013","0.01845"
"65.08800","5.42417","0.01800"
"65.37600","5.44814","0.01875"
"65.66400","5.47224","0.01791"
"65.95200","5.49609","0.01804"
"66.24000","5.52019","0.01905"
"66.52800","5.54416","0.01926"
"66.81600","5.56820","0.01913"
"67.10400","5.59218","0.01985"
"67.39200","5.61615","0.01940"
"67.68000","5.64019","0.02020"
"67.96800","5.66416","0.01994"
"68.25600","5.68820","0.01983"
"68.54400","5.71211","0.02050"
"68.83200","5.73615","0.02066"
"69.12000","5.76006","0.02097"
"69.40800","5.78416","0.02010"
"69.69600","5.80814","0.01902"
"69.98400","5.83223","0.01890"
"70.27200","5.85615","0.01956"
"70.56000","5.88018","0.01975"
"70.84800","5.90416","0.02053"
"71.13600","5.92813","0.02061"
"71.42400","5.95217","0.02081"
"71.71200","5.97608","0.02143"
"72.00000","6.00018","0.02153"
"72.28800","6.02415","0.02200"
"72.57600","6.04819","0.02199"
"72.86400","6.07217","0.02236"
"73.15200","6.09614","0.02307"
"73.44000","6.12012","0.02262"
"73.72800","6.14421","0.02286"
"74.01600","6.16813","0.02298"
"74.30400","6.19222","0.02253"
"74.59200","6.21608","0.02338"
"74.88000","6.24017","0.02424"
"75.16800","6.26415","0.02407"
"75.45600","6.28812","0.02455"
"75.74400","6.31216","0.02387"
"76.03200","6.33614","0.02365"
"76.32000","6.36017","0.02438"
"76.60800","6.38415","0.02473"
"76.89600","6.40812","0.02487"
"77.18400","6.43210","0.02468"
"77.47200","6.45619","0.02538"
"77.76000","6.48011","0.02569"
"78.04800","6.50420","0.02628"
"78.33600","6.52818","0.02675"
"78.62400","6.55216","0.02621"
"78.91200","6.57613","0.02638"
"79.20000","6.60017","0.02716"
"79.48800","6.62414","0.02720"
"79.77600","6.64818","0.02726"
"80.06400","6.67215","0.02752"
"80.35200","6.69613","0.02754"
"80.64000","6.72016","0.02720"
"80.92800","6.74414","0.02813"
"81.21600","6.76818","0.02846"
"81.50400","6.79215","0.02843"
"81.79200","6.81619","0.02838"
"82.08000","6.84010","0.02913"
"82.36800","6.86420","0.02962"
"82.65600","6.88817","0.02935"
"82.94400","6.91215","0.02943"
"83.23200","6.93618","0.02979"
"83.52000","6.96016","0.03001"
"83.80800","6.98413","0.03015"
"84.09600","7.00811","0.03042"
"84.38400","7.03221","0.03096"
"84.67200","7.05612","0.03039"
"84.96000","7.08022","0.03105"
"85.24800","7.10413","0.03098"
"85.53600","7.12823","0.03113"
"85.82400","7.15214","0.03191"
"86.11200","7.17618","0.03161"
"86.40000","7.20015","0.03227"
"86.68800","7.22419","0.03198"
"86.97600","7.24817","0.03245"
"87.26400","7.27220","0.03181"
"87.55200","7.29618","0.03268"
"87.84000","7.32015","0.03263"
"88.12800","7.34425","0.03314"
"88.41600","7.36816","0.03282"
"88.70400","7.39226","0.03342"
"88.99200","7.41617","0.03339"
"89.28000","7.44021","0.03357"
"89.56800","7.46407","0.03346"
"89.85600","7.48822","0.03381"
"90.14400","7.51214","0.03411"
"90.43200","7.53617","0.03341"
"90.72000","7.56015","0.03436"
"91.00800","7.58418","0.03332"
"91.29600","7.60822","0.03445"
"91.58400","7.63225","0.03465"
"91.87200","7.65623","0.03465"
"92.16000","7.68021","0.03493"
"92.44800","7.70424","0.03550"
"92.73600","7.72822","0.03557"
"93.02400","7.75219","0.03600"
"93.31200","7.77611","0.03590"
"93.60000","7.80020","0.03578"
"93.88800","7.82418","0.03650"
"94.17600","7.84821","0.03641"
"94.46400","7.87213","0.03671"
"94.75200","7.89622","0.03714"
"95.04000","7.92014","0.03692"
"95.32800","7.94418","0.03780"
"95.61600","7.96821","0.03771"
"95.90400","7.99219","0.03717"
"96.19200","8.01622","0.03778"
"96.48000","8.04020","0.03790"
"96.76800","8.06423","0.03846"
"97.05600","8.08815","0.03840"
"97.34400","8.11218","0.03950"
"97.63200","8.13616","0.03886"
"97.92000","8.16020","0.03942"
"98.20800","8.18411","0.03979"
"98.49600","8.20821","0.03975"
"98.78400","8.23212","0.04019"
"99.07200","8.25622","0.03933"
"99.36000","8.28019","0.04016"
"99.64800","8.30417","0.03998"
"99.93600","8.32820","0.03920"
"100.22400","8.35218","0.03876"
"100.51200","8.37621","0.03835"
"100.80000","8.40019","0.03808"
"101.08800","8.42422","0.03805"
"101.37600","8.44814","0.03849"
"101.66400","8.47218","0.03845"
"101.95200","8.49615","0.03850"
"102.24000","8.52019","0.03820"
"102.52800","8.54410","0.03851"
"102.81600","8.56820","0.03902"
"103.10400","8.59217","0.03871"
"103.39200","8.61621","0.03949"
"103.68000","8.64019","0.03940"
"103.96800","8.66416","0.03968"
"104.25600","8.68820","0.03889"
"104.54400","8.71217","0.03964"
"104.83200","8.73615","0.03923"
"105.12000","8.76018","0.03974"
"105.40800","8.78422","0.04009"
"105.69600","8.80813","0.04000"
"105.98400","8.83217","0.04002"
"106.27200","8.85614","0.03933"
"106.56000","8.88024","0.03960"
"106.84800","8.90416","0.03958"
"107.13600","8.92819","0.03969"
"107.42400","8.95217","0.04031"
"107.71200","8.97614","0.04030"
"108.00000","9.00018","0.04084"
"108.28800","9.02415","0.04058"
"108.57600","9.04819","0.04132"
"108.86400","9.07216","0.04146"
"109.15200","9.09620","0.04169"
"109.44000","9.12012","0.04186"
"109.72800","9.14415","0.04221"
"110.01600","9.16813","0.04234"
"110.30400","9.19222","0.04234"
"110.59200","9.21614","0.04269"
"110.88000","9.24017","0.04215"
"111.16800","9.26415","0.04249"
"111.45600","9.28818","0.04263"
"111.74400","9.31216","0.04278"
"112.03200","9.33613","0.04318"
"112.32000","9.36017","0.04311"
"112.60800","9.38415","0.04353"
"112.89600","9.40812","0.04401"
"113.18400","9.43210","0.04370"
"113.47200","9.45619","0.04401"
"113.76000","9.48017","0.04466"
"114.04800","9.50420","0.04332"
"114.33600","9.52818","0.04397"
"114.62400","9.55222","0.04393"
"114.91200","9.57613","0.04457"
"115.20000","9.60017","0.04456"
"115.48800","9.62414","0.04438"
"115.77600","9.64818","0.04448"
"116.06400","9.67215","0.04472"
"116.35200","9.69613","0.04525"
"116.64000","9.72016","0.04507"
"116.92800","9.74414","0.04491"
"117.21600","9.76818","0.04527"
"117.50400","9.79209","0.04518"
"117.79200","9.81625","0.04536"
"118.08000","9.84010","0.04538"
"118.36800","9.86420","0.04569"
"118.65600","9.88811","0.04547"
"118.94400","9.91221","0.04552"
"119.23200","9.93612","0.04580"
"119.52000","9.96022","0.04596"
"119.80800","9.98413","0.04611"
"120.09600","10.00811","0.04586"
"120.38400","10.03215","0.04632"
"120.67200","10.05618","0.04623"
"120.96000","10.08022","0.04621"
"121.24800","10.10419","0.04632"
"121.53600","10.12823","0.04652"
"121.82400","10.15214","0.04656"
"122.11200","10.17618","0.04690"
"122.40000","10.20009","0.04718"
"122.68800","10.22413","0.04703"
"122.97600","10.24811","0.04747"
"123.26400","10.27220","0.04743"
"123.55200","10.29618","0.04800"
"123.84000","10.32021","0.04802"
"124.12800","10.34425","0.04795"
"124.41600","10.36822","0.04832"
"124.70400","10.39220","0.04847"
"124.99200","10.41617","0.04829"
"125.28000","10.44021","0.04862"
"125.56800","10.46413","0.04886"
"125.85600","10.48822","0.04901"
"126.14400","10.51214","0.04909"
"126.43200","10.53623","0.04937"
"126.72000","10.56009","0.04966"
"127.00800","10.58418","0.04990"
"127.29600","10.60816","0.04970"
"127.58400","10.63219","0.05022"
"127.87200","10.65617","0.05018"
"128.16000","10.68020","0.05046"
"128.44800","10.70418","0.05064"
"128.73600","10.72822","0.05068"
"129.02400","10.75225","0.05106"
"129.31200","10.77623","0.05081"
"129.60000","10.80020","0.05157"
"129.88800","10.82418","0.05163"
"130.17600","10.84821","0.05199"
"130.46400","10.87213","0.05233"
"130.75200","10.89622","0.05237"
"131.04000","10.92014","0.05284"
"131.32800","10.94418","0.05338"
"131.61600","10.96815","0.05370"
"131.90400","10.99219","0.05413"
"132.19200","11.01622","0.05441"
"132.48000","11.04020","0.05446"
"132.76800","11.06417","0.05510"
"133.05600","11.08821","0.05531"
"133.34400","11.11224","0.05562"
"133.63200","11.13616","0.05659"
"133.92000","11.16025","0.05606"
"134.20800","11.18417","0.05701"
"134.49600","11.20821","0.05740"
"134.78400","11.23212","0.05815"
"135.07200","11.25622","0.05874"
"135.36000","11.28019","0.05885"
"135.64800","11.30423","0.05980"
"135.93600","11.32814","0.06074"
"136.22400","11.35224","0.06035"
"136.51200","11.37621","0.06165"
"136.80000","11.40025","0.06189"
"137.08800","11.42417","0.06260"
"137.37600","11.44820","0.06333"
"137.66400","11.47224","0.06383"
"137.95200","11.49615","0.06308"
"138.24000","11.52019","0.06418"
"138.52800","11.54416","0.06467"
"138.81600","11.56814","0.06546"
"139.10400","11.59211","0.06544"
"139.39200","11.61621","0.06650"
"139.68000","11.64019","0.06689"
"139.96800","11.66416","0.06758"
"140.25600","11.68814","0.06827"
"140.54400","11.71211","0.06880"
"140.83200","11.73621","0.06962"
"141.12000","11.76018","0.06951"
"141.40800","11.78422","0.07094"
"141.69600","11.80814","0.07136"
"141.98400","11.83223","0.07212"
"142.27200","11.85614","0.07283"
"142.56000","11.88018","0.07317"
"142.84800","11.90410","0.07337"
"143.13600","11.92819","0.07398"
"143.42400","11.95217","0.07443"
"143.71200","11.97620","0.07498"
"144.00000","12.00018","0.07574"
"144.28800","12.02421","0.07549"
"144.57600","12.04819","0.07527"
"144.86400","12.07216","0.07480"
"145.15200","12.09620","0.07544"
"145.44000","12.12018","0.07647"
"145.72800","12.14421","0.07718"
"146.01600","12.16819","0.07791"
"146.30400","12.19216","0.07861"
"146.59200","12.21614","0.07971"
"146.88000","12.24017","0.07985"
"147.16800","12.26409","0.08139"
"147.45600","12.28812","0.08156"
"147.74400","12.31216","0.05876"
"148.03200","12.33619","0.05823"
"148.32000","12.36017","0.05809"
"148.60800","12.38415","0.05739"
"148.89600","12.40818","0.05952"
"149.18400","12.43210","0.06056"
"149.47200","12.45619","0.06056"
"149.76000","12.48011","0.06378"
"150.04800","12.50420","0.06355"
"150.33600","12.52818","0.06523"
"150.62400","12.55216","0.06692"
"150.91200","12.57607","0.06597"
"151.20000","12.60017","0.06860"
"151.48800","12.62408","0.06965"
"151.77600","12.64824","0.06878"
"152.06400","12.67215","0.07174"
"152.35200","12.69613","0.07158"
"152.64000","12.72016","0.07165"
"152.92800","12.74414","0.07387"
"153.21600","12.76817","0.07409"
"153.50400","12.79215","0.07495"
"153.79200","12.81619","0.07749"
"154.08000","12.84016","0.07698"
"154.36800","12.86420","0.07783"
"154.65600","12.88811","0.08025"
"154.94400","12.91215","0.07999"
"155.23200","12.93612","0.07989"
"155.52000","12.96022","0.08199"
"155.80800","12.98414","0.08166"
"156.09600","13.00817","0.08268"
"156.38400","13.03215","0.08460"
"156.67200","13.05612","0.08524"
"156.96000","13.08016","0.08600"
"157.24800","13.10413","0.08785"
"157.53600","13.12817","0.08716"
"157.82400","13.15214","0.08872"
"158.11200","13.17618","0.09025"
"158.40000","13.20010","0.08973"
"158.68800","13.22413","0.09072"
"158.97600","13.24811","0.09197"
"159.26400","13.27220","0.09241"
"159.55200","13.29611","0.09237"
"159.84000","13.32021","0.09352"
"160.12800","13.34413","0.09377"
"160.41600","13.36816","0.09380"
"160.70400","13.39214","0.09491"
"160.99200","13.41617","0.09508"
"161.28000","13.44015","0.09545"
"161.56800","13.46412","0.09631"
"161.85600","13.48810","0.09626"
"162.14400","13.51214","0.09668"
"162.43200","13.53617","0.09785"
"162.72000","13.56015","0.09880"
"163.00800","13.58418","0.09954"
"163.29600","13.60816","0.10022"
"163.58400","13.63219","0.10104"
"163.87200","13.65611","0.10070"
"164.16000","13.68015","0.10242"
"164.44800","13.70412","0.10426"
"164.73600","13.72822","0.10563"
"165.02400","13.75219","0.10546"
"165.31200","13.77617","0.10757"
"165.60000","13.80014","0.10876"
"165.88800","13.82418","0.03975"
"166.17600","13.84815","0.04364"
"166.46400","13.87213","0.04432"
"166.75200","13.89616","0.04338"
"167.04000","13.92014","0.04413"
"167.32800","13.94417","0.04503"
"167.61600","13.96815","0.04579"
"167.90400","13.99219","0.04672"
"168.19200","14.01616","0.04624"
"168.48000","14.04020","0.04674"
"168.76800","14.06417","0.04765"
"169.05600","14.08821","0.04769"
"169.34400","14.11224","0.04809"
"169.63200","14.13616","0.04815"
"169.92000","14.16020","0.04877"
"170.20800","14.18417","0.04926"
"170.49600","14.20821","0.04904"
"170.78400","14.23212","0.04944"
"171.07200","14.25616","0.04976"
"171.36000","14.28013","0.04976"
"171.64800","14.30423","0.05021"
"171.93600","14.32814","0.05078"
"172.22400","14.35218","0.05099"
"172.51200","14.37615","0.05164"
"172.80000","14.40019","0.05169"
"173.08800","14.42417","0.05227"
"173.37600","14.44820","0.05286"
"173.66400","14.47218","0.05293"
"173.95200","14.49621","0.05383"
"174.24000","14.52019","0.05391"
"174.52800","14.54410","0.05488"
"174.81600","14.56820","0.05518"
"175.10400","14.59217","0.05595"
"175.39200","14.61621","0.05671"
"175.68000","14.64013","0.05741"
"175.96800","14.66422","0.05728"
"176.25600","14.68814","0.05932"
"176.54400","14.71217","0.05878"
"176.83200","14.73621","0.05906"
"177.12000","14.76024","0.06038"
"177.40800","14.78422","0.06058"
"177.69600","14.80825","0.06024"
"177.98400","14.83223","0.06130"
"178.27200","14.85615","0.06151"
"178.56000","14.88018","0.06143"
"178.84800","14.90416","0.06198"
"179.13600","14.92819","0.06057"
"179.42400","14.95211","0.05887"
"179.71200","14.97620","0.05887"
"180.00000","15.00018","0.05725"
"180.28800","15.02421","0.05702"
"180.57600","15.04813","0.05650"
"180.86400","15.07222","0.05736"
"181.15200","15.09614","0.05741"
"181.44000","15.12018","0.05772"
"181.72800","15.14415","0.05888"
"182.01600","15.16819","0.05971"
"182.30400","15.19222","0.05959"
"182.59200","15.21614","0.06059"
"182.88000","15.24023","0.06136"
"183.16800","15.26415","0.06179"
"183.45600","15.28818","0.06288"
"183.74400","15.31210","0.06361"
"184.03200","15.33620","0.06456"
"184.32000","15.36017","0.06561"
"184.60800","15.38415","0.06691"
"184.89600","15.40812","0.06754"
"185.18400","15.43222","0.06845"
"185.47200","15.45619","0.06900"
"185.76000","15.48017","0.06976"
"186.04800","15.50420","0.07153"
"186.33600","15.52818","0.07202"
"186.62400","15.55222","0.07275"
"186.91200","15.57613","0.07370"
"187.20000","15.60017","0.07513"
"187.48800","15.62408","0.07620"
"187.77600","15.64824","0.07602"
"188.06400","15.67215","0.07796"
"188.35200","15.69619","0.07833"
"188.64000","15.72010","0.08004"
"188.92800","15.74420","0.08105"
"189.21600","15.76811","0.08118"
"189.50400","15.79215","0.08293"
"189.79200","15.81618","0.08323"
"190.08000","15.84016","0.08536"
"190.36800","15.86419","0.08652"
"190.65600","15.88817","0.08637"
"190.94400","15.91221","0.08663"
"191.23200","15.93618","0.08833"
"191.52000","15.96016","0.08935"
"191.80800","15.98413","0.08929"
"192.09600","16.00817","0.09041"
"192.38400","16.03214","0.09148"
"192.67200","16.05618","0.09242"
"192.96000","16.08016","0.09329"
"193.24800","16.10419","0.09409"
"193.53600","16.12817","0.09486"
"193.82400","16.15214","0.09603"
"194.11200","16.17618","0.09676"
"194.40000","16.20015","0.09771"
"194.68800","16.22419","0.09891"
"194.97600","16.24817","0.10027"
"195.26400","16.27220","0.10273"
"195.55200","16.29618","0.10482"
"195.84000","16.32021","0.10434"
"196.12800","16.34413","0.10794"
"196.41600","16.36816","0.10930"
"196.70400","16.39208","0.11184"
"196.99200","16.41617","0.11506"
"197.28000","16.44015","0.11798"
"197.56800","16.46424","0.11961"
"197.85600","16.48816","0.12202"
"198.14400","16.51220","0.12398"
"198.43200","16.53617","0.12491"
"198.72000","16.56015","0.12128"
"199.00800","16.58418","0.11597"
"199.29600","16.60816","0.09447"
"199.58400","16.63219","0.09517"
"199.87200","16.65617","0.09545"
"200.16000","16.68014","0.09749"
"200.44800","16.70412","0.10082"
"200.73600","16.72816","0.10112"
"201.02400","16.75213","0.10449"
"201.31200","16.77617","0.10984"
"201.60000","16.80014","0.11164"
"201.88800","16.82418","0.11295"
"202.17600","16.84815","0.11775"
"202.46400","16.87213","0.12033"
"202.75200","16.89622","0.11905"
"203.04000","16.92020","0.12265"
"203.32800","16.94417","0.12441"
"203.61600","16.96815","0.12644"
"203.90400","16.99219","0.12589"
"204.19200","17.01610","0.12798"
"204.48000","17.04020","0.12983"
"204.76800","17.06411","0.12978"
"205.05600","17.08821","0.13107"
"205.34400","17.11212","0.13361"
"205.63200","17.13622","0.13443"
"205.92000","17.16019","0.13485"
"206.20800","17.18417","0.13594"
"206.49600","17.20814","0.13755"
"206.78400","17.23218","0.13795"
"207.07200","17.25622","0.13892"
"207.36000","17.28019","0.13962"
"207.64800","17.30423","0.14052"
"207.93600","17.32820","0.14094"
"208.22400","17.35218","0.14164"
"208.51200","17.37615","0.14252"
"208.80000","17.40019","0.14330"
"209.08800","17.42416","0.14396"
"209.37600","17.44820","0.14498"
"209.66400","17.47218","0.14704"
"209.95200","17.49621","0.14969"
"210.24000","17.52025","0.15117"
"210.52800","17.54422","0.15383"
"210.81600","17.56820","0.15773"
"211.10400","17.59217","0.16075"
"211.39200","17.61621","0.16059"
"211.68000","17.64018","0.16324"
"211.96800","17.66428","0.16725"
"212.25600","17.68814","0.17145"
"212.54400","17.71223","0.17611"
"212.83200","17.73615","0.17871"
"213.12000","17.76024","0.18214"
"213.40800","17.78422","0.18632"
"213.69600","17.80825","0.19071"
"213.98400","17.83217","0.19385"
"214.27200","17.85620","0.19640"
"214.56000","17.88012","0.19864"
"214.84800","17.90416","0.19958"
"215.13600","17.92819","0.20091"
"215.42400","17.95223","0.20193"
"215.71200","17.97626","0.20295"
"216.00000","18.00018","0.20438"
"216.28800","18.02421","0.20440"
"216.57600","18.04813","0.20113"
"216.86400","18.07222","0.20080"
"217.15200","18.09614","0.20162"
"217.44000","18.12024","0.18731"
"217.72800","18.14421","0.14872"
"218.01600","18.16818","0.14303"
"218.30400","18.19216","0.14404"
"218.59200","18.21620","0.14444"
"218.88000","18.24017","0.14237"
"219.16800","18.26415","0.14253"
"219.45600","18.28824","0.14233"
"219.74400","18.31210","0.13544"
"220.03200","18.33619","0.12737"
"220.32000","18.36011","0.12805"
"220.60800","18.38420","0.13140"
"220.89600","18.40812","0.13313"
"221.18400","18.43222","0.13357"
"221.47200","18.45619","0.13582"
"221.76000","18.48017","0.13728"
"222.04800","18.50414","0.13746"
"222.33600","18.52818","0.13840"
"222.62400","18.55215","0.13958"
"222.91200","18.57619","0.14046"
"223.20000","18.60023","0.14105"
"223.48800","18.62420","0.14206"
"223.77600","18.64818","0.14336"
"224.06400","18.67215","0.14379"
"224.35200","18.69619","0.14503"
"224.64000","18.72016","0.14761"
"224.92800","18.74420","0.15112"
"225.21600","18.76811","0.15092"
"225.50400","18.79221","0.15390"
"225.79200","18.81612","0.15752"
"226.08000","18.84016","0.15041"
"226.36800","18.86414","0.14094"
"226.65600","18.88811","0.14164"
"226.94400","18.91215","0.14184"
"227.23200","18.93612","0.13479"
"227.52000","18.96022","0.11820"
"227.80800","18.98413","0.12109"
"228.09600","19.00817","0.12043"
"228.38400","19.03214","0.12449"
"228.67200","19.05618","0.12667"
"228.96000","19.08010","0.12796"
"229.24800","19.10419","0.12863"
"229.53600","19.12811","0.13113"
"229.82400","19.15220","0.13130"
"230.11200","19.17612","0.09394"
"230.40000","19.20015","0.09434"
"230.68800","19.22413","0.09550"
"230.97600","19.24816","0.09748"
"231.26400","19.27220","0.09819"
"231.55200","19.29618","0.10034"
"231.84000","19.32021","0.10352"
"232.12800","19.34419","0.10535"
"232.41600","19.36810","0.10827"
"232.70400","19.39208","0.11194"
"232.99200","19.41617","0.11311"
"233.28000","19.44009","0.11678"
"233.56800","19.46418","0.11961"
"233.85600","19.48810","0.12121"
"234.14400","19.51220","0.12360"
"234.43200","19.53611","0.12556"
"234.72000","19.56014","0.12673"
"235.00800","19.58418","0.12910"
"235.29600","19.60816","0.13052"
"235.58400","19.63219","0.13144"
"235.87200","19.65611","0.13261"
"236.16000","19.68014","0.13370"
"236.44800","19.70412","0.13486"
"236.73600","19.72815","0.13552"
"237.02400","19.75207","0.13645"
"237.31200","19.77617","0.13699"
"237.60000","19.80008","0.13719"
"237.88800","19.82418","0.13795"
"238.17600","19.84809","0.13836"
"238.46400","19.87219","0.13891"
"238.75200","19.89616","0.13945"
"239.04000","19.92020","0.13993"
"239.32800","19.94417","0.14034"
"239.61600","19.96815","0.14074"
"239.90400","19.99213","0.14131"
"240.19200","20.01610","0.14159"
"240.48000","20.04014","0.14197"
"240.76800","20.06411","0.14256"
"241.05600","20.08815","0.14308"
"241.34400","20.11206","0.14400"
"241.63200","20.13616","0.14508"
"241.92000","20.16014","0.14611"
"242.20800","20.18417","0.14723"
"242.49600","20.20815","0.14885"
"242.78400","20.23218","0.14980"
"243.07200","20.25616","0.15218"
"243.36000","20.28013","0.15386"
"243.64800","20.30416","0.15615"
"243.93600","20.32814","0.15760"
"244.22400","20.35217","0.15995"
"244.51200","20.37615","0.16213"
"244.80000","20.40019","0.16430"
"245.08800","20.42410","0.16702"
"245.37600","20.44814","0.16997"
"245.66400","20.47211","0.17238"
"245.95200","20.49621","0.17616"
"246.24000","20.52013","0.17903"
"246.52800","20.54416","0.18141"
"246.81600","20.56820","0.18420"
"247.10400","20.59217","0.18670"
"247.39200","20.61615","0.18923"
"247.68000","20.64012","0.19215"
"247.96800","20.66416","0.19343"
"248.25600","20.68814","0.19514"
"248.54400","20.71223","0.19683"
"248.83200","20.73615","0.19805"
"249.12000","20.76018","0.19973"
"249.40800","20.78416","0.20008"
"249.69600","20.80819","0.19537"
"249.98400","20.83217","0.19746"
"250.27200","20.85620","0.19933"
"250.56000","20.88018","0.19996"
"250.84800","20.90415","0.20072"
"251.13600","20.92819","0.20161"
"251.42400","20.95223","0.20244"
"251.71200","20.97620","0.20316"
"252.00000","21.00011","0.20409"
"252.28800","21.02421","0.20520"
"252.57600","21.04813","0.20620"
"252.86400","21.07216","0.20711"
"253.15200","21.09608","0.20872"
"253.44000","21.12024","0.21031"
"253.72800","21.14415","0.21162"
"254.01600","21.16818","0.21357"
"254.30400","21.19216","0.21529"
"254.59200","21.21620","0.21688"
"254.88000","21.24017","0.21689"
"255.16800","21.26421","0.21876"
"255.45600","21.28818","0.21981"
"255.74400","21.31222","0.22181"
"256.03200","21.33613","0.22417"
"256.32000","21.36017","0.22475"
"256.60800","21.38420","0.22648"
"256.89600","21.40818","0.22728"
"257.18400","21.43222","0.22936"
"257.47200","21.45613","0.23107"
"257.76000","21.48023","0.23281"
"258.04800","21.50414","0.23488"
"258.33600","21.52818","0.23632"
"258.62400","21.55215","0.23802"
"258.91200","21.57619","0.23859"
"259.20000","21.60016","0.23983"
"259.48800","21.62420","0.24090"
"259.77600","21.64818","0.24208"
"260.06400","21.67215","0.24297"
"260.35200","21.69619","0.24366"
"260.64000","21.72016","0.24442"
"260.92800","21.74420","0.24491"
"261.21600","21.76817","0.24581"
"261.50400","21.79221","0.24678"
"261.79200","21.81612","0.24723"
"262.08000","21.84022","0.24794"
"262.36800","21.86420","0.24908"
"262.65600","21.88817","0.24929"
"262.94400","21.91221","0.24918"
"263.23200","21.93624","0.23068"
"263.52000","21.96016","0.23124"
"263.80800","21.98419","0.23338"
"264.09600","22.00823","0.23447"
"264.38400","22.03221","0.23663"
"264.67200","22.05624","0.23806"
"264.96000","22.08015","0.23884"
"265.24800","22.10413","0.24055"
"265.53600","22.12811","0.24188"
"265.82400","22.15220","0.24271"
"266.11200","22.17618","0.24343"
"266.40000","22.20021","0.24418"
"266.68800","22.22413","0.24505"
"266.97600","22.24822","0.24601"
"267.26400","22.27214","0.24709"
"267.55200","22.29618","0.24760"
"267.84000","22.32021","0.24810"
"268.12800","22.34419","0.24900"
"268.41600","22.36822","0.24982"
"268.70400","22.39220","0.25047"
"268.99200","22.41617","0.25176"
"269.28000","22.44015","0.25238"
"269.56800","22.46418","0.25327"
"269.85600","22.48816","0.25376"
"270.14400","22.51219","0.25498"
"270.43200","22.53611","0.25561"
"270.72000","22.56015","0.25629"
"271.00800","22.58412","0.25786"
"271.29600","22.60816","0.25904"
"271.58400","22.63219","0.26016"
"271.87200","22.65617","0.26151"
"272.16000","22.68020","0.26268"
"272.44800","22.70412","0.26483"
"272.73600","22.72821","0.26617"
"273.02400","22.75213","0.26802"
"273.31200","22.77617","0.27003"
"273.60000","22.80008","0.27135"
"273.88800","22.82417","0.27281"
"274.17600","22.84809","0.27416"
"274.46400","22.87218","0.27462"
"274.75200","22.89610","0.27597"
"275.04000","22.92020","0.27739"
"275.32800","22.94417","0.27866"
"275.61600","22.96821","0.27924"
"275.90400","22.99218","0.28017"
"276.19200","23.01616","0.28123"
"276.48000","23.04020","0.28324"
"276.76800","23.06417","0.28519"
"277.05600","23.08821","0.28638"
"277.34400","23.11218","0.28771"
"277.63200","23.13616","0.28935"
"277.92000","23.16013","0.29013"
"278.20800","23.18417","0.29129"
"278.49600","23.20815","0.29211"
"278.78400","23.23218","0.29351"
"279.07200","23.25622","0.29484"
"279.36000","23.28025","0.29540"
"279.64800","23.30423","0.29657"
"279.93600","23.32814","0.29718"
"280.22400","23.35218","0.29839"
"280.51200","23.37615","0.29920"
"280.80000","23.40019","0.30092"
"281.08800","23.42411","0.30128"
"281.37600","23.44820","0.30272"
"281.66400","23.47211","0.30542"
"281.95200","23.49615","0.30609"
"282.24000","23.52007","0.30856"
"282.52800","23.54422","0.30989"
"282.81600","23.56814","0.31201"
"283.10400","23.59217","0.31411"
"283.39200","23.61615","0.31658"
"283.68000","23.64018","0.31870"
"283.96800","23.66416","0.32159"
"284.25600","23.68813","0.32461"
"284.54400","23.71223","0.32620"
"284.83200","23.73615","0.32905"
"285.12000","23.76018","0.33141"
"285.40800","23.78415","0.33250"
"285.69600","23.80819","0.33524"
"285.98400","23.83211","0.33724"
"286.27200","23.85614","0.33851"
"286.56000","23.88012","0.34110"
"286.84800","23.90415","0.34235"
"287.13600","23.92819","0.34400"
"287.42400","23.95222","0.34369"
"287.71200","23.97620","0.34320"
"288.00000","24.00018","0.34355"
"288.28800","24.02421","0.34368"
"288.57600","24.04813","0.34293"
"288.86400","24.07222","0.33631"
"289.15200","24.09620","0.33759"
"289.44000","24.12023","0.34023"
"289.72800","24.14415","0.34214"
"290.01600","24.16825","0.34454"
"290.30400","24.19216","0.34773"
"290.59200","24.21620","0.34828"
"290.88000","24.24011","0.34904"
"291.16800","24.26421","0.35071"
"291.45600","24.28818","0.35160"
"291.74400","24.31222","0.35219"
"292.03200","24.33619","0.35285"
"292.32000","24.36017","0.35351"
"292.60800","24.38414","0.35413"
"292.89600","24.40812","0.35440"
"293.18400","24.43221","0.35468"
"293.47200","24.45619","0.35474"
"293.76000","24.48022","0.35496"
"294.04800","24.50420","0.35499"
"294.33600","24.52824","0.35526"
"294.62400","24.55215","0.35527"
"294.91200","24.57619","0.35565"
"295.20000","24.60016","0.35572"
"295.48800","24.62420","0.35612"
"295.77600","24.64818","0.35640"
"296.06400","24.67221","0.35659"
"296.35200","24.69619","0.35689"
"296.64000","24.72016","0.35808"
"296.92800","24.74426","0.35865"
"297.21600","24.76817","0.35912"
"297.50400","24.79227","0.35977"
"297.79200","24.81618","0.36086"
"298.08000","24.84022","0.36175"
"298.36800","24.86413","0.36305"
"298.65600","24.88823","0.36469"
"298.94400","24.91215","0.36611"
"299.23200","24.93624","0.36771"
"299.52000","24.96022","0.36918"
"299.80800","24.98419","0.37094"
"300.09600","25.00811","0.37219"
"300.38400","25.03214","0.37405"
"300.67200","25.05618","0.37645"
"300.96000","25.08015","0.37763"
"301.24800","25.10419","0.38034"
"301.53600","25.12811","0.38258"
"301.82400","25.15220","0.38477"
"302.11200","25.17617","0.38763"
"302.40000","25.20021","0.39015"
"302.68800","25.22419","0.39089"
"302.97600","25.24822","0.39351"
"303.26400","25.27220","0.39527"
"303.55200","25.29617","0.39688"
"303.84000","25.32015","0.39856"
"304.12800","25.34413","0.40000"
"304.41600","25.36816","0.40118"
"304.70400","25.39219","0.40248"
"304.99200","25.41623","0.40314"
"305.28000","25.44015","0.40413"
"305.56800","25.46424","0.40528"
"305.85600","25.48816","0.40611"
"306.14400","25.51219","0.40685"
"306.43200","25.53611","0.40766"
"306.72000","25.56020","0.40924"
"307.00800","25.58406","0.41128"
"307.29600","25.60822","0.41139"
"307.58400","25.63213","0.37617"
"307.87200","25.65617","0.37353"
"308.16000","25.68014","0.37178"
"308.44800","25.70418","0.28688"
"308.73600","25.72821","0.28873"
"309.02400","25.75219","0.28826"
"309.31200","25.77622","0.28941"
"309.60000","25.80020","0.29004"
"309.88800","25.82418","0.29413"
"310.17600","25.84809","0.29410"
"310.46400","25.87219","0.29734"
"310.75200","25.89610","0.29851"
"311.04000","25.92020","0.30174"
"311.32800","25.94417","0.30561"
"311.61600","25.96815","0.30582"
"311.90400","25.99212","0.30806"
"312.19200","26.01616","0.30677"
"312.48000","26.04013","0.31220"
"312.76800","26.06417","0.31338"
"313.05600","26.08821","0.31718"
"313.34400","26.11212","0.32059"
"313.63200","26.13622","0.32355"
"313.92000","26.16013","0.32791"
"314.20800","26.18417","0.32968"
"314.49600","26.20809","0.33302"
"314.78400","26.23218","0.33518"
"315.07200","26.25610","0.33845"
"315.36000","26.28019","0.34032"
"315.64800","26.30416","0.34195"
"315.93600","26.32820","0.34378"
"316.22400","26.35212","0.34519"
"316.51200","26.37615","0.34770"
"316.80000","26.40019","0.34892"
"317.08800","26.42416","0.34973"
"317.37600","26.44820","0.35092"
"317.66400","26.47212","0.35145"
"317.95200","26.49615","0.35258"
"318.24000","26.52013","0.35334"
"318.52800","26.54416","0.35384"
"318.81600","26.56808","0.35389"
"319.10400","26.59217","0.35425"
"319.39200","26.61609","0.35440"
"319.68000","26.64013","0.35474"
"319.96800","26.66410","0.35507"
"320.25600","26.68814","0.35520"
"320.54400","26.71217","0.35521"
"320.83200","26.73615","0.35540"
"321.12000","26.76018","0.35552"
"321.40800","26.78410","0.35571"
"321.69600","26.80813","0.35598"
"321.98400","26.83211","0.35606"
"322.27200","26.85614","0.35636"
"322.56000","26.88012","0.35640"
"322.84800","26.90415","0.35680"
"323.13600","26.92807","0.35728"
"323.42400","26.95217","0.35800"
"323.71200","26.97614","0.35856"
"324.00000","27.00018","0.35855"
"324.28800","27.02415","0.35927"
"324.57600","27.04813","0.36031"
"324.86400","27.07216","0.36114"
"325.15200","27.09614","0.36204"
"325.44000","27.12017","0.36260"
"325.72800","27.14415","0.36334"
"326.01600","27.16819","0.36442"
"326.30400","27.19210","0.36564"
"326.59200","27.21614","0.36638"
"326.88000","27.24017","0.36811"
"327.16800","27.26421","0.36888"
"327.45600","27.28812","0.36997"
"327.74400","27.31216","0.37130"
"328.03200","27.33613","0.37285"
"328.32000","27.36017","0.37427"
"328.60800","27.38420","0.37637"
"328.89600","27.40818","0.37817"
"329.18400","27.43216","0.37922"
"329.47200","27.45613","0.38127"
"329.76000","27.48017","0.38295"
"330.04800","27.50414","0.38545"
"330.33600","27.52818","0.38586"
"330.62400","27.55215","0.38838"
"330.91200","27.57619","0.39019"
"331.20000","27.60011","0.39251"
"331.48800","27.62420","0.39364"
"331.77600","27.64812","0.39470"
"332.06400","27.67221","0.39650"
"332.35200","27.69613","0.39892"
"332.64000","27.72016","0.40037"
"332.92800","27.74420","0.40110"
"333.21600","27.76823","0.40159"
"333.50400","27.79221","0.40151"
"333.79200","27.81618","0.24498"
"334.08000","27.84022","0.23118"
"334.36800","27.86414","0.23511"
"334.65600","27.88823","0.23878"
"334.94400","27.91215","0.24258"
"335.23200","27.93618","0.24258"
"335.52000","27.96016","0.24460"
"335.80800","27.98419","0.24539"
"336.09600","28.00817","0.24698"
"336.38400","28.03220","0.24819"
"336.67200","28.05618","0.24930"
"336.96000","28.08021","0.25155"
"337.24800","28.10419","0.25211"
"337.53600","28.12817","0.25321"
"337.82400","28.15220","0.25410"
"338.11200","28.17618","0.25553"
"338.40000","28.20021","0.25724"
"338.68800","28.22413","0.25904"
"338.97600","28.24822","0.26021"
"339.26400","28.27214","0.26181"
"339.55200","28.29623","0.26330"
"339.84000","28.32015","0.26498"
"340.12800","28.34419","0.26573"
"340.41600","28.36816","0.26748"
"340.70400","28.39226","0.26887"
"340.99200","28.41623","0.26942"
"341.28000","28.44021","0.27088"
"341.56800","28.46418","0.27139"
"341.85600","28.48816","0.27316"
"342.14400","28.51220","0.27395"
"342.43200","28.53611","0.27424"
"342.72000","28.56021","0.27569"
"343.00800","28.58418","0.27684"
"343.29600","28.60822","0.27747"
"343.58400","28.63213","0.27834"
"343.87200","28.65623","0.27957"
"344.16000","28.68014","0.28032"
"344.44800","28.70424","0.28121"
"344.73600","28.72815","0.28189"
"345.02400","28.75219","0.28318"
"345.31200","28.77616","0.28466"
"345.60000","28.80020","0.28496"
"345.88800","28.82417","0.28611"
"346.17600","28.84815","0.28721"
"346.46400","28.87225","0.28842"
"346.75200","28.89610","0.28888"
"347.04000","28.92020","0.29009"
"347.32800","28.94417","0.29050"
"347.61600","28.96821","0.29157"
"347.90400","28.99213","0.29229"
"348.19200","29.01622","0.29310"
"348.48000","29.04020","0.29332"
"348.76800","29.06411","0.29393"
"349.05600","29.08815","0.29495"
"349.34400","29.11218","0.29546"
"349.63200","29.13622","0.29612"
"349.92000","29.16019","0.29688"
"350.20800","29.18423","0.29765"
"350.49600","29.20815","0.29859"
"350.78400","29.23224","0.29940"
"351.07200","29.25616","0.29963"
"351.36000","29.28019","0.30199"
"351.64800","29.30411","0.30269"
"351.93600","29.32820","0.30368"
"352.22400","29.35212","0.30479"
"352.51200","29.37621","0.30641"
"352.80000","29.40013","0.30696"
"353.08800","29.42422","0.30923"
"353.37600","29.44820","0.31082"
"353.66400","29.47211","0.31188"
"353.95200","29.49615","0.31339"
"354.24000","29.52013","0.31536"
"354.52800","29.54422","0.31691"
"354.81600","29.56814","0.31865"
"355.10400","29.59217","0.32068"
"355.39200","29.61615","0.32314"
"355.68000","29.64018","0.32374"
"355.96800","29.66410","0.32555"
"356.25600","29.68820","0.32736"
"356.54400","29.71217","0.32881"
"356.83200","29.73621","0.32998"
"357.12000","29.76018","0.33205"
"357.40800","29.78416","0.33313"
"357.69600","29.80819","0.33474"
"357.98400","29.83211","0.33730"
"358.27200","29.85620","0.33790"
"358.56000","29.88012","0.33947"
"358.84800","29.90421","0.34067"
"359.13600","29.92813","0.34218"
"359.42400","29.95217","0.34305"
"359.71200","29.97608","0.34427"
"360.00000","30.00018","0.34586"
"360.28800","30.02409","0.34674"
"360.57600","30.04825","0.34719"
"360.86400","30.07216","0.34835"
"361.15200","30.09620","0.34940"
"361.44000","30.12012","0.34991"
"361.72800","30.14415","0.35037"
"362.01600","30.16818","0.35116"
"362.30400","30.19216","0.35160"
"362.59200","30.21619","0.35238"
"362.88000","30.24017","0.35284"
"363.16800","30.26415","0.35324"
"363.45600","30.28812","0.35352"
"363.74400","30.31216","0.35376"
"364.03200","30.33607","0.35411"
"364.32000","30.36017","0.35435"
"364.60800","30.38415","0.35425"
"364.89600","30.40818","0.35480"
"365.18400","30.43216","0.35471"
"365.47200","30.45619","0.35465"
"365.76000","30.48017","0.35478"
"366.04800","30.50414","0.35502"
"366.33600","30.52824","0.35501"
"366.62400","30.55215","0.35512"
"366.91200","30.57625","0.35513"
"367.20000","30.60011","0.35505"
"367.48800","30.62414","0.35527"
"367.77600","30.64818","0.35525"
"368.06400","30.67215","0.35534"
"368.35200","30.69607","0.35542"
"368.64000","30.72016","0.35547"
"368.92800","30.74420","0.35559"
"369.21600","30.76818","0.35569"
"369.50400","30.79215","0.35590"
"369.79200","30.81618","0.35600"
"370.08000","30.84016","0.35589"
"370.36800","30.86413","0.35613"
"370.65600","30.88823","0.35606"
"370.94400","30.91221","0.35651"
"371.23200","30.93624","0.35649"
"371.52000","30.96016","0.35670"
"371.80800","30.98419","0.35705"
"372.09600","31.00817","0.35732"
"372.38400","31.03220","0.35747"
"372.67200","31.05612","0.35758"
"372.96000","31.08022","0.35789"
"373.24800","31.10419","0.35851"
"373.53600","31.12823","0.35878"
"373.82400","31.15220","0.35813"
"374.11200","31.17618","0.02104"
"374.40000","31.20021","0.01830"
"374.68800","31.22413","0.00647"
"374.97600","31.24822","0.00584"
"375.26400","31.27213","0.00480"
"375.55200","31.29623","0.00739"
"375.84000","31.32009","0.00685"
"376.12800","31.34418","0.00523"
"376.41600","31.36816","0.00877"
"376.70400","31.39225","0.00657"
"376.99200","31.41617","0.00668"
"377.28000","31.44021","0.00660"
"377.56800","31.46418","0.00673"
"377.85600","31.48822","0.00648"
"378.14400","31.51219","0.00634"
"378.43200","31.53617","0.00682"
"378.72000","31.56021","0.00660"
"379.00800","31.58418","0.00706"
"379.29600","31.60821","0.00714"
"379.58400","31.63219","0.00697"
"379.87200","31.65623","0.00671"
"380.16000","31.68014","0.00753"
"380.44800","31.70418","0.00661"
"380.73600","31.72815","0.00691"
"381.02400","31.75219","0.00750"
"381.31200","31.77616","0.00755"
"381.60000","31.80020","0.00760"
"381.88800","31.82417","0.00777"
"382.17600","31.84815","0.00788"
"382.46400","31.87225","0.00802"
"382.75200","31.89616","0.00788"
"383.04000","31.92025","0.00808"
"383.32800","31.94411","0.00796"
"383.61600","31.96821","0.00815"
"383.90400","31.99212","0.00842"
"384.19200","32.01616","0.00884"
"384.48000","32.04007","0.00878"
"384.76800","32.06423","0.00909"
"385.05600","32.08815","0.00950"
"385.34400","32.11218","0.00914"
"385.63200","32.13616","0.00924"
"385.92000","32.16019","0.00940"
"386.20800","32.18417","0.00970"
"386.49600","32.20820","0.01041"
"386.78400","32.23218","0.00985"
"387.07200","32.25615","0.01021"
"387.36000","32.28019","0.01080"
"387.64800","32.30410","0.01005"
"387.93600","32.32820","0.01036"
"388.22400","32.35212","0.01038"
"388.51200","32.37621","0.01122"
"388.80000","32.40013","0.01046"
"389.08800","32.42422","0.01120"
"389.37600","32.44814","0.01072"
"389.66400","32.47218","0.01111"
"389.95200","32.49615","0.01154"
"390.24000","32.52012","0.01192"
"390.52800","32.54416","0.01211"
"390.81600","32.56813","0.01249"
"391.10400","32.59217","0.01211"
"391.39200","32.61615","0.01279"
"391.68000","32.64024","0.01184"
"391.96800","32.66410","0.01176"
"392.25600","32.68819","0.01231"
"392.54400","32.71211","0.01131"
"392.83200","32.73621","0.01220"
"393.12000","32.76012","0.01151"
"393.40800","32.78416","0.01229"
"393.69600","32.80813","0.01231"
"393.98400","32.83216","0.01295"
"394.27200","32.85614","0.01248"
"394.56000","32.88018","0.01279"
"394.84800","32.90421","0.01355"
"395.13600","32.92813","0.01320"
"395.42400","32.95216","0.01362"
"395.71200","32.97614","0.01362"
"396.00000","33.00011","0.01418"
"396.28800","33.02409","0.01376"
"396.57600","33.04819","0.01402"
"396.86400","33.07216","0.01385"
"397.15200","33.09620","0.01414"
"397.44000","33.12017","0.01425"
"397.72800","33.14415","0.01413"
"398.01600","33.16812","0.01410"
"398.30400","33.19210","0.01401"
"398.59200","33.21619","0.01448"
"398.88000","33.24011","0.01406"
"399.16800","33.26421","0.01442"
"399.45600","33.28812","0.01469"
"399.74400","33.31222","0.01468"
"400.03200","33.33613","0.01500"
"400.32000","33.36017","0.01478"
"400.60800","33.38414","0.01454"
"400.89600","33.40824","0.01509"
"401.18400","33.43209","0.01501"
"401.47200","33.45619","0.01541"
"401.76000","33.48010","0.01493"
"402.04800","33.50420","0.01538"
"402.33600","33.52811","0.01545"
"402.62400","33.55209","0.01517"
"402.91200","33.57613","0.01586"
"403.20000","33.60016","0.01531"
"403.48800","33.62420","0.01534"
"403.77600","33.64811","0.01532"
"404.06400","33.67215","0.01540"
"404.35200","33.69613","0.01553"
"404.64000","33.72016","0.01534"
"404.92800","33.74408","0.01597"
"405.21600","33.76817","0.01624"
"405.50400","33.79214","0.01641"
"405.79200","33.81618","0.01606"
"406.08000","33.84016","0.01619"
"406.36800","33.86413","0.01616"
"406.65600","33.88817","0.01625"
"406.94400","33.91214","0.01637"
"407.23200","33.93618","0.01688"
"407.52000","33.96010","0.01662"
"407.80800","33.98419","0.01692"
"408.09600","34.00811","0.01723"
"408.38400","34.03220","0.01669"
"408.67200","34.05611","0.01702"
"408.96000","34.08015","0.01663"
"409.24800","34.10407","0.01785"
"409.53600","34.12822","0.01743"
"409.82400","34.15214","0.01738"
"410.11200","34.17617","0.01811"
"410.40000","34.20015","0.01736"
"410.68800","34.22419","0.01821"
"410.97600","34.24816","0.01762"
"411.26400","34.27214","0.01755"
"411.55200","34.29623","0.01756"
"411.84000","34.32015","0.01798"
"412.12800","34.34418","0.01758"
"412.41600","34.36810","0.01735"
"412.70400","34.39219","0.01793"
"412.99200","34.41611","0.01723"
"413.28000","34.44020","0.01738"
"413.56800","34.46412","0.01772"
"413.85600","34.48816","0.01729"
"414.14400","34.51213","0.01804"
"414.43200","34.53617","0.01773"
"414.72000","34.56020","0.01789"
"415.00800","34.58418","0.01838"
"415.29600","34.60822","0.01808"
"415.58400","34.63219","0.01821"
"415.87200","34.65623","0.01832"
"416.16000","34.68014","0.01868"
"416.44800","34.70424","0.01813"
"416.73600","34.72815","0.01873"
"417.02400","34.75219","0.01900"
"417.31200","34.77616","0.01903"
"417.60000","34.80020","0.01894"
"417.88800","34.82412","0.01908"
"418.17600","34.84821","0.01931"
"418.46400","34.87218","0.01950"
"418.75200","34.89622","0.01955"
"419.04000","34.92020","0.01913"
"419.32800","34.94423","0.01930"
"419.61600","34.96821","0.01923"
"419.90400","34.99218","0.01892"
"420.19200","35.01622","0.01907"
"420.48000","35.04013","0.01938"
"420.76800","35.06423","0.01960"
"421.05600","35.08814","0.01990"
"421.34400","35.11218","0.01950"
"421.63200","35.13610","0.01913"
"421.92000","35.16019","0.01947"
"422.20800","35.18417","0.01928"
"422.49600","35.20820","0.01891"
"422.78400","35.23218","0.01907"
"423.07200","35.25621","0.01903"
"423.36000","35.28019","0.01931"
"423.64800","35.30416","0.01948"
"423.93600","35.32820","0.01799"
"424.22400","35.35212","0.01785"
"424.31600","35.35977","0.01784"