File: Force_trajectories/170225_2/Specimen_RawData_4.csv
End date,"2/25/2017"
Specimen label,"1CT_3"
Maximum Load,"0.09211",N

Time,Extension,Load
(s),(mm),(N)
"0.00000","0.00000","-0.00026"
"0.16200","0.00993","0.00028"
"0.32400","0.02685","-0.00001"
"0.48600","0.04090","0.00038"
"0.64800","0.05417","0.00058"
"0.81000","0.06774","0.00059"
"0.97200","0.08125","0.00019"
"1.13400","0.09471","0.00095"
"1.29600","0.10816","0.00086"
"1.45800","0.12173","0.00102"
"1.62000","0.13530","0.00075"
"1.78200","0.14864","0.00133"
"1.94400","0.16221","0.00076"
"2.10600","0.17572","0.00185"
"2.26800","0.18917","0.00142"
"2.43000","0.20269","0.00143"
"2.59200","0.21620","0.00159"
"2.75400","0.22971","0.00155"
"2.91600","0.24316","0.00138"
"3.07800","0.25674","0.00155"
"3.24000","0.27019","0.00084"
"3.40200","0.28370","0.00147"
"3.56400","0.29721","0.00163"
"3.72600","0.31073","0.00237"
"3.88800","0.32418","0.00179"
"4.05000","0.33769","0.00237"
"4.21200","0.35114","0.00221"
"4.37400","0.36466","0.00219"
"4.53600","0.37817","0.00200"
"4.69800","0.39174","0.00186"
"4.86000","0.40525","0.00168"
"5.02200","0.41871","0.00156"
"5.18400","0.43222","0.00228"
"5.34600","0.44573","0.00243"
"5.50800","0.45918","0.00254"
"5.67000","0.47270","0.00232"
"5.83200","0.48621","0.00253"
"5.99400","0.49972","0.00246"
"6.15600","0.51317","0.00289"
"6.31800","0.52675","0.00228"
"6.48000","0.54020","0.00230"
"6.64200","0.55371","0.00264"
"6.80400","0.56722","0.00245"
"6.96600","0.58074","0.00261"
"7.12800","0.59419","0.00214"
"7.29000","0.60770","0.00235"
"7.45200","0.62121","0.00277"
"7.61400","0.63467","0.00367"
"7.77600","0.64818","0.00288"
"7.93800","0.66169","0.00252"
"8.10000","0.67520","0.00298"
"8.26200","0.68866","0.00342"
"8.42400","0.70223","0.00235"
"8.58600","0.71574","0.00304"
"8.74800","0.72919","0.00279"
"8.91000","0.74265","0.00310"
"9.07200","0.75622","0.00272"
"9.23400","0.76967","0.00320"
"9.39600","0.78318","0.00292"
"9.55800","0.79676","0.00323"
"9.72000","0.81027","0.00348"
"9.88200","0.82372","0.00346"
"10.04400","0.83717","0.00355"
"10.20600","0.85075","0.00328"
"10.36800","0.86420","0.00359"
"10.53000","0.87771","0.00308"
"10.69200","0.89122","0.00387"
"10.85400","0.90474","0.00363"
"11.01600","0.91825","0.00395"
"11.17800","0.93176","0.00314"
"11.34000","0.94527","0.00381"
"11.50200","0.95867","0.00361"
"11.66400","0.97224","0.00368"
"11.82600","0.98569","0.00378"
"11.98800","0.99920","0.00419"
"12.15000","1.01272","0.00394"
"12.31200","1.02629","0.00400"
"12.47400","1.03968","0.00368"
"12.63600","1.05319","0.00417"
"12.79800","1.06671","0.00401"
"12.96000","1.08016","0.00423"
"13.12200","1.09367","0.00401"
"13.28400","1.10724","0.00365"
"13.44600","1.12075","0.00441"
"13.60800","1.13421","0.00444"
"13.77000","1.14772","0.00403"
"13.93200","1.16123","0.00385"
"14.09400","1.17474","0.00410"
"14.25600","1.18820","0.00393"
"14.41800","1.20171","0.00417"
"14.58000","1.21522","0.00481"
"14.74200","1.22867","0.00353"
"14.90400","1.24225","0.00360"
"15.06600","1.25576","0.00355"
"15.22800","1.26915","0.00321"
"15.39000","1.28272","0.00395"
"15.55200","1.29624","0.00406"
"15.71400","1.30969","0.00392"
"15.87600","1.32320","0.00383"
"16.03800","1.33677","0.00395"
"16.20000","1.35023","0.00411"
"16.36200","1.36362","0.00450"
"16.52400","1.37725","0.00405"
"16.68600","1.39070","0.00450"
"16.84800","1.40416","0.00426"
"17.01000","1.41767","0.00422"
"17.17200","1.43124","0.00481"
"17.33400","1.44463","0.00414"
"17.49600","1.45821","0.00414"
"17.65800","1.47172","0.00447"
"17.82000","1.48523","0.00393"
"17.98200","1.49868","0.00396"
"18.14400","1.51226","0.00361"
"18.30600","1.52577","0.00417"
"18.46800","1.53916","0.00443"
"18.63000","1.55273","0.00419"
"18.79200","1.56625","0.00499"
"18.95400","1.57964","0.00460"
"19.11600","1.59321","0.00432"
"19.27800","1.60672","0.00393"
"19.44000","1.62024","0.00449"
"19.60200","1.63363","0.00525"
"19.76400","1.64726","0.00409"
"19.92600","1.66071","0.00464"
"20.08800","1.67417","0.00453"
"20.25000","1.68768","0.00533"
"20.41200","1.70119","0.00505"
"20.57400","1.71464","0.00459"
"20.73600","1.72816","0.00528"
"20.89800","1.74173","0.00518"
"21.06000","1.75524","0.00499"
"21.22200","1.76869","0.00520"
"21.38400","1.78221","0.00476"
"21.54600","1.79572","0.00520"
"21.70800","1.80917","0.00487"
"21.87000","1.82268","0.00545"
"22.03200","1.83620","0.00539"
"22.19400","1.84971","0.00540"
"22.35600","1.86322","0.00520"
"22.51800","1.87673","0.00549"
"22.68000","1.89019","0.00615"
"22.84200","1.90364","0.00535"
"23.00400","1.91721","0.00548"
"23.16600","1.93072","0.00565"
"23.32800","1.94418","0.00584"
"23.49000","1.95781","0.00581"
"23.65200","1.97126","0.00612"
"23.81400","1.98465","0.00572"
"23.97600","1.99823","0.00629"
"24.13800","2.01174","0.00578"
"24.30000","2.02519","0.00594"
"24.46200","2.03864","0.00539"
"24.62400","2.05228","0.00528"
"24.78600","2.06579","0.00509"
"24.94800","2.07918","0.00592"
"25.11000","2.09275","0.00565"
"25.27200","2.10621","0.00537"
"25.43400","2.11972","0.00582"
"25.59600","2.13317","0.00528"
"25.75800","2.14674","0.00549"
"25.92000","2.16020","0.00588"
"26.08200","2.17371","0.00587"
"26.24400","2.18722","0.00587"
"26.40600","2.20067","0.00630"
"26.56800","2.21413","0.00616"
"26.73000","2.22776","0.00570"
"26.89200","2.24121","0.00562"
"27.05400","2.25466","0.00577"
"27.21600","2.26818","0.00593"
"27.37800","2.28169","0.00611"
"27.54000","2.29520","0.00624"
"27.70200","2.30865","0.00662"
"27.86400","2.32217","0.00583"
"28.02600","2.33568","0.00589"
"28.18800","2.34913","0.00641"
"28.35000","2.36276","0.00637"
"28.51200","2.37622","0.00606"
"28.67400","2.38973","0.00610"
"28.83600","2.40324","0.00680"
"28.99800","2.41675","0.00657"
"29.16000","2.43027","0.00603"
"29.32200","2.44372","0.00604"
"29.48400","2.45723","0.00659"
"29.64600","2.47068","0.00608"
"29.80800","2.48420","0.00654"
"29.97000","2.49771","0.00667"
"30.13200","2.51122","0.00690"
"30.29400","2.52467","0.00743"
"30.45600","2.53819","0.00687"
"30.61800","2.55176","0.00664"
"30.78000","2.56515","0.00648"
"30.94200","2.57872","0.00751"
"31.10400","2.59224","0.00742"
"31.26600","2.60575","0.00721"
"31.42800","2.61920","0.00765"
"31.59000","2.63271","0.00758"
"31.75200","2.64622","0.00756"
"31.91400","2.65968","0.00749"
"32.07600","2.67325","0.00747"
"32.23800","2.68676","0.00774"
"32.40000","2.70016","0.00767"
"32.56200","2.71373","0.00824"
"32.72400","2.72724","0.00775"
"32.88600","2.74069","0.00773"
"33.04800","2.75414","0.00810"
"33.21000","2.76778","0.00856"
"33.37200","2.78123","0.00791"
"33.53400","2.79468","0.00781"
"33.69600","2.80825","0.00820"
"33.85800","2.82177","0.00832"
"34.02000","2.83516","0.00826"
"34.18200","2.84867","0.00842"
"34.34400","2.86218","0.00877"
"34.50600","2.87570","0.00853"
"34.66800","2.88915","0.00864"
"34.83000","2.90272","0.00844"
"34.99200","2.91623","0.00870"
"35.15400","2.92969","0.00837"
"35.31600","2.94326","0.00873"
"35.47800","2.95671","0.00882"
"35.64000","2.97016","0.00849"
"35.80200","2.98368","0.00932"
"35.96400","2.99725","0.00886"
"36.12600","3.01076","0.00821"
"36.28800","3.02421","0.00904"
"36.45000","3.03773","0.00941"
"36.61200","3.05124","0.00939"
"36.77400","3.06463","0.00950"
"36.93600","3.07820","0.00892"
"37.09800","3.09172","0.00877"
"37.26000","3.10517","0.00882"
"37.42200","3.11868","0.00855"
"37.58400","3.13219","0.00860"
"37.74600","3.14571","0.00881"
"37.90800","3.15916","0.00926"
"38.07000","3.17267","0.00955"
"38.23200","3.18618","0.00948"
"38.39400","3.19964","0.00931"
"38.55600","3.21321","0.00957"
"38.71800","3.22672","0.00893"
"38.88000","3.24017","0.00875"
"39.04200","3.25369","0.00908"
"39.20400","3.26720","0.00967"
"39.36600","3.28065","0.00944"
"39.52800","3.29416","0.00986"
"39.69000","3.30774","0.00961"
"39.85200","3.32125","0.00974"
"40.01400","3.33470","0.00952"
"40.17600","3.34821","0.00961"
"40.33800","3.36173","0.00970"
"40.50000","3.37512","0.00951"
"40.66200","3.38875","0.01003"
"40.82400","3.40220","0.01023"
"40.98600","3.41572","0.01005"
"41.14800","3.42917","0.01009"
"41.31000","3.44274","0.01063"
"41.47200","3.45625","0.01064"
"41.63400","3.46965","0.01029"
"41.79600","3.48322","0.01112"
"41.95800","3.49673","0.01064"
"42.12000","3.51012","0.01056"
"42.28200","3.52370","0.01027"
"42.44400","3.53721","0.01021"
"42.60600","3.55072","0.01068"
"42.76800","3.56423","0.01048"
"42.93000","3.57775","0.01074"
"43.09200","3.59120","0.01076"
"43.25400","3.60465","0.01050"
"43.41600","3.61822","0.01121"
"43.57800","3.63180","0.01117"
"43.74000","3.64519","0.01029"
"43.90200","3.65870","0.01121"
"44.06400","3.67221","0.01029"
"44.22600","3.68567","0.01086"
"44.38800","3.69918","0.01090"
"44.55000","3.71269","0.01070"
"44.71200","3.72620","0.01064"
"44.87400","3.73972","0.01071"
"45.03600","3.75323","0.01071"
"45.19800","3.76674","0.01078"
"45.36000","3.78013","0.01055"
"45.52200","3.79371","0.01030"
"45.68400","3.80716","0.00960"
"45.84600","3.82073","0.00974"
"46.00800","3.83418","0.00889"
"46.17000","3.84776","0.00791"
"46.33200","3.86121","0.00612"
"46.49400","3.87466","0.00510"
"46.65600","3.88823","0.00467"
"46.81800","3.90175","0.00429"
"46.98000","3.91520","0.00396"
"47.14200","3.92871","0.00396"
"47.30400","3.94222","0.00419"
"47.46600","3.95568","0.00420"
"47.62800","3.96919","0.00427"
"47.79000","3.98270","0.00441"
"47.95200","3.99615","0.00444"
"48.11400","4.00967","0.00540"
"48.27600","4.02318","0.00460"
"48.43800","4.03675","0.00517"
"48.60000","4.05020","0.00519"
"48.76200","4.06378","0.00527"
"48.92400","4.07723","0.00533"
"49.08600","4.09068","0.00535"
"49.24800","4.10419","0.00553"
"49.41000","4.11770","0.00537"
"49.57200","4.13116","0.00591"
"49.73400","4.14467","0.00626"
"49.89600","4.15824","0.00610"
"50.05800","4.17175","0.00654"
"50.22000","4.18521","0.00683"
"50.38200","4.19872","0.00707"
"50.54400","4.21229","0.00742"
"50.70600","4.22568","0.00741"
"50.86800","4.23920","0.00740"
"51.03000","4.25277","0.00746"
"51.19200","4.26622","0.00761"
"51.35400","4.27973","0.00798"
"51.51600","4.29325","0.00851"
"51.67800","4.30670","0.00859"
"51.84000","4.32015","0.00863"
"52.00200","4.33366","0.00824"
"52.16400","4.34724","0.00882"
"52.32600","4.36069","0.00900"
"52.48800","4.37426","0.00933"
"52.65000","4.38777","0.00887"
"52.81200","4.40117","0.00929"
"52.97400","4.41468","0.00971"
"53.13600","4.42813","0.00892"
"53.29800","4.44170","0.00984"
"53.46000","4.45516","0.00980"
"53.62200","4.46873","0.01024"
"53.78400","4.48224","0.01041"
"53.94600","4.49569","0.01078"
"54.10800","4.50921","0.01082"
"54.27000","4.52272","0.01114"
"54.43200","4.53623","0.01123"
"54.59400","4.54968","0.01135"
"54.75600","4.56326","0.01204"
"54.91800","4.57677","0.01192"
"55.08000","4.59016","0.01227"
"55.24200","4.60367","0.01228"
"55.40400","4.61719","0.01241"
"55.56600","4.63070","0.01238"
"55.72800","4.64415","0.01289"
"55.89000","4.65772","0.01316"
"56.05200","4.67118","0.01309"
"56.21400","4.68475","0.01355"
"56.37600","4.69826","0.01368"
"56.53800","4.71171","0.01369"
"56.70000","4.72517","0.01435"
"56.86200","4.73868","0.01454"
"57.02400","4.75219","0.01430"
"57.18600","4.76564","0.01480"
"57.34800","4.77922","0.01494"
"57.51000","4.79273","0.01534"
"57.67200","4.80618","0.01522"
"57.83400","4.81969","0.01610"
"57.99600","4.83327","0.01614"
"58.15800","4.84678","0.01569"
"58.32000","4.86011","0.01620"
"58.48200","4.87374","0.01640"
"58.64400","4.88726","0.01696"
"58.80600","4.90071","0.01674"
"58.96800","4.91422","0.01676"
"59.13000","4.92773","0.01782"
"59.29200","4.94125","0.01873"
"59.45400","4.95470","0.01877"
"59.61600","4.96821","0.01803"
"59.77800","4.98166","0.01963"
"59.94000","4.99518","0.01976"
"60.10200","5.00875","0.01925"
"60.26400","5.02220","0.02023"
"60.42600","5.03565","0.02042"
"60.58800","5.04923","0.02100"
"60.75000","5.06274","0.02135"
"60.91200","5.07619","0.02234"
"61.07400","5.08970","0.02183"
"61.23600","5.10328","0.02205"
"61.39800","5.11673","0.02282"
"61.56000","5.13018","0.02313"
"61.72200","5.14375","0.02333"
"61.88400","5.15727","0.02345"
"62.04600","5.17066","0.02436"
"62.20800","5.18423","0.02437"
"62.37000","5.19774","0.02456"
"62.53200","5.21126","0.02564"
"62.69400","5.22471","0.02610"
"62.85600","5.23822","0.02603"
"63.01800","5.25173","0.02682"
"63.18000","5.26519","0.02714"
"63.34200","5.27870","0.02753"
"63.50400","5.29221","0.02826"
"63.66600","5.30566","0.02827"
"63.82800","5.31924","0.02887"
"63.99000","5.33275","0.02934"
"64.15200","5.34620","0.03012"
"64.31400","5.35971","0.03004"
"64.47600","5.37317","0.03161"
"64.63800","5.38668","0.03171"
"64.80000","5.40013","0.03195"
"64.96200","5.41376","0.03236"
"65.12400","5.42722","0.03276"
"65.28600","5.44067","0.03355"
"65.44800","5.45424","0.03350"
"65.61000","5.46775","0.03424"
"65.77200","5.48121","0.03422"
"65.93400","5.49472","0.03483"
"66.09600","5.50823","0.03589"
"66.25800","5.52174","0.03594"
"66.42000","5.53520","0.03669"
"66.58200","5.54877","0.03733"
"66.74400","5.56222","0.03732"
"66.90600","5.57567","0.03829"
"67.06800","5.58924","0.03813"
"67.23000","5.60276","0.03899"
"67.39200","5.61621","0.03894"
"67.55400","5.62972","0.03979"
"67.71600","5.64324","0.03911"
"67.87800","5.65675","0.04023"
"68.04000","5.67014","0.04021"
"68.20200","5.68371","0.04100"
"68.36400","5.69717","0.04148"
"68.52600","5.71068","0.04165"
"68.68800","5.72425","0.04219"
"68.85000","5.73776","0.04193"
"69.01200","5.75122","0.04243"
"69.17400","5.76467","0.04250"
"69.33600","5.77824","0.04311"
"69.49800","5.79169","0.04319"
"69.66000","5.80515","0.04367"
"69.82200","5.81872","0.04394"
"69.98400","5.83223","0.04421"
"70.14600","5.84568","0.04417"
"70.30800","5.85925","0.04461"
"70.47000","5.87277","0.04463"
"70.63200","5.88622","0.04491"
"70.79400","5.89967","0.04524"
"70.95600","5.91319","0.04551"
"71.11800","5.92670","0.04584"
"71.28000","5.94015","0.04590"
"71.44200","5.95372","0.04607"
"71.60400","5.96723","0.04632"
"71.76600","5.98069","0.04660"
"71.92800","5.99420","0.04659"
"72.09000","6.00771","0.04706"
"72.25200","6.02116","0.04731"
"72.41400","6.03474","0.04740"
"72.57600","6.04825","0.04714"
"72.73800","6.06170","0.04756"
"72.90000","6.07515","0.04784"
"73.06200","6.08873","0.04823"
"73.22400","6.10218","0.04834"
"73.38600","6.11569","0.04834"
"73.54800","6.12920","0.04849"
"73.71000","6.14272","0.04860"
"73.87200","6.15617","0.04899"
"74.03400","6.16974","0.04884"
"74.19600","6.18319","0.04904"
"74.35800","6.19665","0.04932"
"74.52000","6.21022","0.04967"
"74.68200","6.22373","0.04985"
"74.84400","6.23718","0.04982"
"75.00600","6.25064","0.04992"
"75.16800","6.26427","0.05028"
"75.33000","6.27772","0.05026"
"75.49200","6.29117","0.04940"
"75.65400","6.30469","0.04886"
"75.81600","6.31820","0.04919"
"75.97800","6.33165","0.04950"
"76.14000","6.34522","0.04942"
"76.30200","6.35874","0.04942"
"76.46400","6.37225","0.04927"
"76.62600","6.38570","0.04923"
"76.78800","6.39921","0.04970"
"76.95000","6.41273","0.04995"
"77.11200","6.42618","0.04987"
"77.27400","6.43969","0.05040"
"77.43600","6.45320","0.05079"
"77.59800","6.46672","0.05079"
"77.76000","6.48023","0.05120"
"77.92200","6.49368","0.05138"
"78.08400","6.50719","0.05116"
"78.24600","6.52065","0.05109"
"78.40800","6.53422","0.05145"
"78.57000","6.54773","0.05183"
"78.73200","6.56112","0.05206"
"78.89400","6.57470","0.05236"
"79.05600","6.58821","0.05251"
"79.21800","6.60172","0.05249"
"79.38000","6.61517","0.05275"
"79.54200","6.62869","0.05258"
"79.70400","6.64214","0.05309"
"79.86600","6.65565","0.05018"
"80.02800","6.66928","0.04967"
"80.19000","6.68274","0.04996"
"80.35200","6.69619","0.04989"
"80.51400","6.70970","0.05040"
"80.67600","6.72315","0.05052"
"80.83800","6.73667","0.05109"
"81.00000","6.75018","0.05094"
"81.16200","6.76369","0.05135"
"81.32400","6.77720","0.05164"
"81.48600","6.79072","0.05156"
"81.64800","6.80429","0.05208"
"81.81000","6.81768","0.05212"
"81.97200","6.83119","0.05265"
"82.13400","6.84471","0.05284"
"82.29600","6.85822","0.05329"
"82.45800","6.87167","0.05399"
"82.62000","6.88518","0.04789"
"82.78200","6.89870","0.04403"
"82.94400","6.91215","0.04491"
"83.10600","6.92566","0.04479"
"83.26800","6.93923","0.04534"
"83.43000","6.95269","0.04558"
"83.59200","6.96614","0.04534"
"83.75400","6.97977","0.04578"
"83.91600","6.99322","0.04618"
"84.07800","7.00668","0.04616"
"84.24000","7.02019","0.04682"
"84.40200","7.03370","0.04399"
"84.56400","7.04715","0.04410"
"84.72600","7.06067","0.04454"
"84.88800","7.07424","0.04466"
"85.05000","7.08775","0.04487"
"85.21200","7.10120","0.04521"
"85.37400","7.11478","0.04531"
"85.53600","7.12823","0.04582"
"85.69800","7.14168","0.04618"
"85.86000","7.15519","0.04598"
"86.02200","7.16871","0.04600"
"86.18400","7.18222","0.04657"
"86.34600","7.19567","0.04666"
"86.50800","7.20924","0.04671"
"86.67000","7.22270","0.04723"
"86.83200","7.23615","0.04711"
"86.99400","7.24972","0.04733"
"87.15600","7.26323","0.04742"
"87.31800","7.27668","0.04748"
"87.48000","7.29026","0.04775"
"87.64200","7.30377","0.04819"
"87.80400","7.31722","0.04831"
"87.96600","7.33068","0.04846"
"88.12800","7.34419","0.04865"
"88.29000","7.35770","0.04887"
"88.45200","7.37109","0.04900"
"88.61400","7.38479","0.04935"
"88.77600","7.39824","0.04934"
"88.93800","7.41169","0.04957"
"89.10000","7.42514","0.04969"
"89.26200","7.43871","0.05016"
"89.42400","7.45217","0.05048"
"89.58600","7.46568","0.05056"
"89.74800","7.47919","0.05091"
"89.91000","7.49270","0.05100"
"90.07200","7.50616","0.05138"
"90.23400","7.51973","0.04988"
"90.39600","7.53318","0.04935"
"90.55800","7.54669","0.04913"
"90.72000","7.56021","0.04916"
"90.88200","7.57372","0.04936"
"91.04400","7.58717","0.04922"
"91.20600","7.60068","0.04956"
"91.36800","7.61426","0.04973"
"91.53000","7.62771","0.04946"
"91.69200","7.64116","0.04992"
"91.85400","7.65474","0.05012"
"92.01600","7.66825","0.04998"
"92.17800","7.68164","0.05042"
"92.34000","7.69521","0.05091"
"92.50200","7.70872","0.05080"
"92.66400","7.72224","0.05086"
"92.82600","7.73575","0.05114"
"92.98800","7.74920","0.05121"
"93.15000","7.76271","0.05162"
"93.31200","7.77611","0.05146"
"93.47400","7.78968","0.05184"
"93.63600","7.80319","0.05157"
"93.79800","7.81664","0.05178"
"93.96000","7.83022","0.05181"
"94.12200","7.84373","0.05193"
"94.28400","7.85718","0.05233"
"94.44600","7.87075","0.05223"
"94.60800","7.88421","0.05283"
"94.77000","7.89766","0.05297"
"94.93200","7.91117","0.05331"
"95.09400","7.92474","0.05349"
"95.25600","7.93826","0.05384"
"95.41800","7.95165","0.05427"
"95.58000","7.96522","0.05472"
"95.74200","7.97873","0.05452"
"95.90400","7.99219","0.05524"
"96.06600","8.00570","0.05560"
"96.22800","8.01921","0.05585"
"96.39000","8.03272","0.05607"
"96.55200","8.04618","0.05637"
"96.71400","8.05969","0.05688"
"96.87600","8.07320","0.05724"
"97.03800","8.08665","0.05729"
"97.20000","8.10023","0.05780"
"97.36200","8.11368","0.05680"
"97.52400","8.12719","0.05700"
"97.68600","8.14070","0.05780"
"97.84800","8.15422","0.05831"
"98.01000","8.16767","0.05892"
"98.17200","8.18118","0.05942"
"98.33400","8.19469","0.05955"
"98.49600","8.20821","0.06004"
"98.65800","8.22166","0.06024"
"98.82000","8.23523","0.06088"
"98.98200","8.24874","0.06095"
"99.14400","8.26220","0.06185"
"99.30600","8.27571","0.06224"
"99.46800","8.28922","0.06239"
"99.63000","8.30267","0.06282"
"99.79200","8.31619","0.06323"
"99.95400","8.32970","0.06413"
"100.11600","8.34327","0.06386"
"100.27800","8.35666","0.06467"
"100.44000","8.37024","0.06511"
"100.60200","8.38375","0.06552"
"100.76400","8.39720","0.06611"
"100.92600","8.41065","0.06661"
"101.08800","8.42422","0.06661"
"101.25000","8.43768","0.06721"
"101.41200","8.45119","0.06810"
"101.57400","8.46470","0.06679"
"101.73600","8.47822","0.06789"
"101.89800","8.49167","0.06789"
"102.06000","8.50530","0.06898"
"102.22200","8.51875","0.06924"
"102.38400","8.53221","0.06958"
"102.54600","8.54572","0.06966"
"102.70800","8.55929","0.07001"
"102.87000","8.57268","0.07055"
"103.03200","8.58614","0.07123"
"103.19400","8.59971","0.07190"
"103.35600","8.61322","0.07197"
"103.51800","8.62661","0.07177"
"103.68000","8.64019","0.07277"
"103.84200","8.65376","0.07316"
"104.00400","8.66721","0.07343"
"104.16600","8.68072","0.07375"
"104.32800","8.69423","0.07364"
"104.49000","8.70769","0.07488"
"104.65200","8.72114","0.07392"
"104.81400","8.73471","0.06493"
"104.97600","8.74823","0.05642"
"105.13800","8.76168","0.05617"
"105.30000","8.77531","0.05635"
"105.46200","8.78876","0.05789"
"105.62400","8.80221","0.04959"
"105.78600","8.81573","0.04997"
"105.94800","8.82924","0.04963"
"106.11000","8.84269","0.05019"
"106.27200","8.85620","0.04942"
"106.43400","8.86978","0.05039"
"106.59600","8.88323","0.04996"
"106.75800","8.89668","0.05115"
"106.92000","8.91025","0.05115"
"107.08200","8.92377","0.05222"
"107.24400","8.93716","0.05191"
"107.40600","8.95073","0.05307"
"107.56800","8.96424","0.05259"
"107.73000","8.97770","0.05374"
"107.89200","8.99121","0.05343"
"108.05400","9.00472","0.05422"
"108.21600","9.01817","0.05430"
"108.37800","9.03163","0.05191"
"108.54000","9.04520","0.05112"
"108.70200","9.05871","0.05159"
"108.86400","9.07216","0.05175"
"109.02600","9.08574","0.05177"
"109.18800","9.09925","0.05161"
"109.35000","9.11264","0.05238"
"109.51200","9.12621","0.05207"
"109.67400","9.13973","0.05283"
"109.83600","9.15318","0.05298"
"109.99800","9.16663","0.05310"
"110.16000","9.18026","0.05387"
"110.32200","9.19378","0.05447"
"110.48400","9.20711","0.05432"
"110.64600","9.22074","0.05518"
"110.80800","9.23425","0.05624"
"110.97000","9.24771","0.05651"
"111.13200","9.26122","0.05706"
"111.29400","9.27473","0.05825"
"111.45600","9.28818","0.05863"
"111.61800","9.30170","0.05942"
"111.78000","9.31527","0.06020"
"111.94200","9.32872","0.06075"
"112.10400","9.34217","0.06189"
"112.26600","9.35569","0.06229"
"112.42800","9.36926","0.06395"
"112.59000","9.38271","0.06396"
"112.75200","9.39622","0.06463"
"112.91400","9.40974","0.06387"
"113.07600","9.42319","0.06413"
"113.23800","9.43670","0.06423"
"113.40000","9.45021","0.06582"
"113.56200","9.46373","0.06536"
"113.72400","9.47712","0.06692"
"113.88600","9.49069","0.06694"
"114.04800","9.50426","0.06639"
"114.21000","9.51766","0.06722"
"114.37200","9.53117","0.06790"
"114.53400","9.54474","0.06807"
"114.69600","9.55819","0.06872"
"114.85800","9.57165","0.06908"
"115.02000","9.58516","0.07002"
"115.18200","9.59873","0.07049"
"115.34400","9.61218","0.07066"
"115.50600","9.62570","0.07136"
"115.66800","9.63921","0.07190"
"115.83000","9.65266","0.06481"
"115.99200","9.66617","0.05919"
"116.15400","9.67969","0.05812"
"116.31600","9.69320","0.05765"
"116.47800","9.70671","0.05550"
"116.64000","9.72028","0.05203"
"116.80200","9.73368","0.05044"
"116.96400","9.74713","0.04971"
"117.12600","9.76070","0.04991"
"117.28800","9.77421","0.04917"
"117.45000","9.78767","0.04953"
"117.61200","9.80130","0.04944"
"117.77400","9.81475","0.04949"
"117.93600","9.82820","0.04989"
"118.09800","9.84166","0.05018"
"118.26000","9.85523","0.05027"
"118.42200","9.86874","0.05029"
"118.58400","9.88219","0.05037"
"118.74600","9.89570","0.05011"
"118.90800","9.90922","0.05013"
"119.07000","9.92267","0.04984"
"119.23200","9.93624","0.04960"
"119.39400","9.94970","0.05009"
"119.55600","9.96321","0.05060"
"119.71800","9.97666","0.05076"
"119.88000","9.99023","0.05126"
"120.04200","10.00369","0.05120"
"120.20400","10.01720","0.05163"
"120.36600","10.03077","0.05228"
"120.52800","10.04422","0.05202"
"120.69000","10.05762","0.05250"
"120.85200","10.07119","0.05315"
"121.01400","10.08470","0.05301"
"121.17600","10.09815","0.05332"
"121.33800","10.11172","0.05392"
"121.50000","10.12530","0.05331"
"121.66200","10.13875","0.05376"
"121.82400","10.15214","0.05463"
"121.98600","10.16572","0.05448"
"122.14800","10.17923","0.05524"
"122.31000","10.19268","0.05524"
"122.47200","10.20619","0.05628"
"122.63400","10.21971","0.05639"
"122.79600","10.23316","0.05666"
"122.95800","10.24667","0.05752"
"123.12000","10.26024","0.05774"
"123.28200","10.27369","0.05867"
"123.44400","10.28715","0.05953"
"123.60600","10.30072","0.05998"
"123.76800","10.31417","0.06021"
"123.93000","10.32769","0.06099"
"124.09200","10.34120","0.06128"
"124.25400","10.35471","0.06162"
"124.41600","10.36822","0.06219"
"124.57800","10.38168","0.06297"
"124.74000","10.39525","0.06346"
"124.90200","10.40864","0.06415"
"125.06400","10.42215","0.06495"
"125.22600","10.43579","0.06504"
"125.38800","10.44924","0.06392"
"125.55000","10.46269","0.06162"
"125.71200","10.47620","0.06188"
"125.87400","10.48972","0.06134"
"126.03600","10.50317","0.06231"
"126.19800","10.51674","0.06220"
"126.36000","10.53025","0.06169"
"126.52200","10.54370","0.06120"
"126.68400","10.55716","0.06120"
"126.84600","10.57073","0.06175"
"127.00800","10.58418","0.06274"
"127.17000","10.59764","0.06357"
"127.33200","10.61121","0.06417"
"127.49400","10.62472","0.06482"
"127.65600","10.63823","0.06547"
"127.81800","10.65169","0.06659"
"127.98000","10.66526","0.06647"
"128.14200","10.67871","0.05948"
"128.30400","10.69216","0.05873"
"128.46600","10.70573","0.05808"
"128.62800","10.71919","0.06030"
"128.79000","10.73264","0.06056"
"128.95200","10.74621","0.06229"
"129.11400","10.75978","0.06265"
"129.27600","10.77318","0.06513"
"129.43800","10.78669","0.06496"
"129.60000","10.80020","0.06723"
"129.76200","10.81365","0.06782"
"129.92400","10.82717","0.06894"
"130.08600","10.84068","0.07027"
"130.24800","10.85419","0.07133"
"130.41000","10.86765","0.07148"
"130.57200","10.88122","0.07277"
"130.73400","10.89473","0.07302"
"130.89600","10.90818","0.07424"
"131.05800","10.92169","0.07466"
"131.22000","10.93521","0.07500"
"131.38200","10.94872","0.07585"
"131.54400","10.96217","0.07696"
"131.70600","10.97574","0.07791"
"131.86800","10.98920","0.07806"
"132.03000","11.00271","0.07913"
"132.19200","11.01622","0.07841"
"132.35400","11.02967","0.07891"
"132.51600","11.04319","0.07879"
"132.67800","11.05670","0.07996"
"132.84000","11.07027","0.08055"
"133.00200","11.08372","0.08138"
"133.16400","11.09724","0.08182"
"133.32600","11.11075","0.08368"
"133.48800","11.12414","0.08327"
"133.65000","11.13765","0.08418"
"133.81200","11.15117","0.08489"
"133.97400","11.16474","0.08556"
"134.13600","11.17819","0.08695"
"134.29800","11.19170","0.08747"
"134.46000","11.20522","0.08798"
"134.62200","11.21867","0.08854"
"134.78400","11.23218","0.08923"
"134.94600","11.24569","0.08998"
"135.10800","11.25921","0.09070"
"135.27000","11.27266","0.09123"
"135.43200","11.28629","0.09155"
"135.59400","11.29974","0.07801"
"135.75600","11.31320","0.01422"
"135.91800","11.32677","0.00909"
"136.08000","11.34028","0.01694"
"136.24200","11.35367","0.01407"
"136.40400","11.36718","0.01408"
"136.56600","11.38076","0.01636"
"136.72800","11.39427","0.01739"
"136.89000","11.40766","0.01673"
"137.05200","11.42124","0.01371"
"137.21400","11.43469","0.02002"
"137.37600","11.44814","0.02013"
"137.53800","11.46171","0.01495"
"137.70000","11.47523","0.01991"
"137.86200","11.48868","0.02220"
"138.02400","11.50219","0.01755"
"138.18600","11.51570","0.02060"
"138.34800","11.52922","0.02351"
"138.51000","11.54261","0.02041"
"138.67200","11.55618","0.02109"
"138.83400","11.56975","0.02495"
"138.99600","11.58321","0.02415"
"139.15800","11.59672","0.02240"
"139.32000","11.61023","0.02609"
"139.48200","11.62368","0.02669"
"139.64400","11.63720","0.02604"
"139.80600","11.65071","0.02697"
"139.96800","11.66422","0.02959"
"140.13000","11.67761","0.02860"
"140.29200","11.69125","0.02823"
"140.45400","11.70476","0.03088"
"140.61600","11.71821","0.02969"
"140.77800","11.73172","0.03055"
"140.94000","11.74523","0.03278"
"141.10200","11.75869","0.03254"
"141.26400","11.77220","0.03312"
"141.42600","11.78571","0.03404"
"141.58800","11.79922","0.03528"
"141.75000","11.81268","0.03375"
"141.91200","11.82625","0.03583"
"142.07400","11.83970","0.03714"
"142.23600","11.85316","0.03553"
"142.39800","11.86673","0.03682"
"142.56000","11.88018","0.03808"
"142.72200","11.89369","0.03761"
"142.88400","11.90721","0.03804"
"143.04600","11.92072","0.03917"
"143.20800","11.93423","0.03957"
"143.37000","11.94768","0.03938"
"143.53200","11.96126","0.04082"
"143.69400","11.97471","0.04089"
"143.85600","11.98816","0.04032"
"144.01800","12.00173","0.04166"
"144.18000","12.01524","0.04192"
"144.34200","12.02870","0.04179"
"144.50400","12.04221","0.04217"
"144.66600","12.05572","0.04251"
"144.82800","12.06917","0.04066"
"144.99000","12.08263","0.04121"
"145.15200","12.09626","0.04199"
"145.31400","12.10977","0.04216"
"145.47600","12.12317","0.04287"
"145.63800","12.13680","0.04396"
"145.80000","12.15025","0.04331"
"145.96200","12.16370","0.04430"
"146.12400","12.17715","0.04477"
"146.28600","12.19073","0.04458"
"146.44800","12.20418","0.04450"
"146.61000","12.21769","0.04546"
"146.77200","12.23120","0.04529"
"146.93400","12.24472","0.04575"
"147.09600","12.25817","0.04629"
"147.25800","12.27174","0.04623"
"147.42000","12.28525","0.04632"
"147.58200","12.29865","0.04689"
"147.74400","12.31216","0.04689"
"147.90600","12.32573","0.04706"
"148.06800","12.33924","0.04738"
"148.23000","12.35270","0.04756"
"148.39200","12.36621","0.04780"
"148.55400","12.37972","0.04834"
"148.71600","12.39318","0.04812"
"148.87800","12.40675","0.04811"
"149.04000","12.42026","0.04839"
"149.20200","12.43371","0.04841"
"149.36400","12.44716","0.04838"
"149.52600","12.46074","0.04909"
"149.68800","12.47419","0.04904"
"149.85000","12.48764","0.04959"
"150.01200","12.50115","0.04990"
"150.17400","12.51473","0.04976"
"150.33600","12.52818","0.05021"
"150.49800","12.54175","0.05039"
"150.66000","12.55520","0.05013"
"150.82200","12.56866","0.05006"
"150.98400","12.58223","0.04979"
"151.14600","12.59574","0.05033"
"151.30800","12.60919","0.05085"
"151.47000","12.62271","0.05099"
"151.63200","12.63622","0.05144"
"151.79400","12.64973","0.05184"
"151.95600","12.66312","0.05213"
"152.11800","12.67676","0.05221"
"152.28000","12.69021","0.05304"
"152.44200","12.70366","0.05336"
"152.60400","12.71723","0.05423"
"152.76600","12.73069","0.05467"
"152.92800","12.74420","0.05506"
"153.09000","12.75771","0.05577"
"153.25200","12.77122","0.05611"
"153.41400","12.78474","0.05711"
"153.57600","12.79813","0.05738"
"153.73800","12.81176","0.05792"
"153.90000","12.82521","0.05929"
"154.06200","12.83867","0.05954"
"154.22400","12.85224","0.05987"
"154.38600","12.86575","0.06067"
"154.54800","12.87920","0.06167"
"154.71000","12.89266","0.06169"
"154.87200","12.90629","0.06090"
"155.03400","12.91968","0.06127"
"155.19600","12.93313","0.06191"
"155.35800","12.94671","0.06254"
"155.52000","12.96028","0.06403"
"155.68200","12.97367","0.06406"
"155.84400","12.98724","0.06547"
"156.00600","13.00076","0.06612"
"156.16800","13.01421","0.06660"
"156.33000","13.02772","0.06767"
"156.49200","13.04123","0.06784"
"156.65400","13.05475","0.06841"
"156.81600","13.06820","0.06288"
"156.97800","13.08177","0.05312"
"157.14000","13.09522","0.05491"
"157.30200","13.10862","0.05527"
"157.46400","13.12219","0.05522"
"157.62600","13.13570","0.05635"
"157.78800","13.14921","0.05606"
"157.95000","13.16273","0.05795"
"158.11200","13.17624","0.05688"
"158.27400","13.18975","0.05910"
"158.43600","13.20320","0.05855"
"158.59800","13.21678","0.05947"
"158.76000","13.23023","0.06064"
"158.92200","13.24368","0.06122"
"159.08400","13.25725","0.06258"
"159.24600","13.27071","0.06241"
"159.40800","13.28416","0.06325"
"159.57000","13.29767","0.06328"
"159.73200","13.31118","0.06436"
"159.89400","13.32469","0.06356"
"160.05600","13.33821","0.06524"
"160.21800","13.35172","0.06614"
"160.38000","13.36523","0.06603"
"160.54200","13.37869","0.06722"
"160.70400","13.39226","0.06740"
"160.86600","13.40571","0.06825"
"161.02800","13.41916","0.06861"
"161.19000","13.43268","0.06961"
"161.35200","13.44619","0.06957"
"161.51400","13.45970","0.07088"
"161.67600","13.47321","0.07152"
"161.83800","13.48678","0.07155"
"162.00000","13.50024","0.07265"
"162.16200","13.51363","0.06947"
"162.32400","13.52726","0.05570"
"162.48600","13.54072","0.05629"
"162.64800","13.55423","0.05327"
"162.81000","13.56768","0.05458"
"162.97200","13.58125","0.05791"
"163.13400","13.59471","0.05561"
"163.29600","13.60822","0.05649"
"163.45800","13.62173","0.05621"
"163.62000","13.63518","0.05622"
"163.78200","13.64863","0.05836"
"163.94400","13.66221","0.05833"
"164.10600","13.67572","0.05774"
"164.26800","13.68917","0.05830"
"164.43000","13.70268","0.05795"
"164.59200","13.71626","0.06033"
"164.75400","13.72971","0.06045"
"164.91600","13.74310","0.06064"
"165.07800","13.75668","0.06228"
"165.24000","13.77019","0.06133"
"165.40200","13.78370","0.06260"
"165.56400","13.79727","0.06525"
"165.72600","13.81072","0.06266"
"165.88800","13.82418","0.06427"
"166.05000","13.83775","0.06647"
"166.21200","13.85126","0.06469"
"166.37400","13.86472","0.06556"
"166.53600","13.87823","0.06713"
"166.69800","13.89174","0.06640"
"166.86000","13.90525","0.06833"
"167.02200","13.91870","0.06852"
"167.18400","13.93222","0.06869"
"167.34600","13.94573","0.07013"
"167.50800","13.95918","0.07015"
"167.67000","13.97269","0.07050"
"167.83200","13.98621","0.07122"
"167.99400","13.99966","0.07168"
"168.15600","14.01317","0.07234"
"168.31800","14.02668","0.07198"
"168.48000","14.04020","0.07357"
"168.64200","14.05365","0.07382"
"168.80400","14.06722","0.01542"
"168.96600","14.08074","0.01327"
"169.12800","14.09419","0.00724"
"169.29000","14.10776","0.01001"
"169.45200","14.12127","0.01450"
"169.61400","14.13466","0.01109"
"169.77600","14.14818","0.01238"
"169.93800","14.16169","0.01244"
"170.10000","14.17514","0.01241"
"170.26200","14.18859","0.01347"
"170.42400","14.20229","0.01268"
"170.58600","14.21574","0.01339"
"170.74800","14.22919","0.01402"
"170.91000","14.24276","0.01235"
"171.07200","14.25628","0.01473"
"171.23400","14.26967","0.01437"
"171.39600","14.28318","0.01252"
"171.55800","14.29669","0.01476"
"171.72000","14.31021","0.01397"
"171.88200","14.32366","0.01398"
"172.04400","14.33723","0.01436"
"172.20600","14.35068","0.01393"
"172.36800","14.36414","0.01478"
"172.53000","14.37771","0.01443"
"172.69200","14.39122","0.01539"
"172.85400","14.40467","0.01570"
"173.01600","14.41825","0.01437"
"173.17800","14.43176","0.01592"
"173.34000","14.44521","0.01654"
"173.50200","14.45866","0.01541"
"173.66400","14.47218","0.01568"
"173.82600","14.48575","0.01647"
"173.98800","14.49914","0.01687"
"174.15000","14.51271","0.01614"
"174.31200","14.52623","0.01664"
"174.47400","14.53968","0.01732"
"174.63600","14.55319","0.01619"
"174.79800","14.56670","0.01692"
"174.96000","14.58022","0.01785"
"175.12200","14.59367","0.01785"
"175.28400","14.60724","0.01772"
"175.44600","14.62069","0.01826"
"175.60800","14.63415","0.01908"
"175.77000","14.64772","0.01865"
"175.93200","14.66123","0.01825"
"176.09400","14.67468","0.01983"
"176.25600","14.68820","0.01913"
"176.41800","14.70165","0.01905"
"176.58000","14.71522","0.01982"
"176.74200","14.72873","0.02040"
"176.90400","14.74224","0.01952"
"177.06600","14.75570","0.02012"
"177.22800","14.76915","0.02027"
"177.39000","14.78272","0.02088"
"177.55200","14.79618","0.02045"
"177.71400","14.80963","0.02168"
"177.87600","14.82320","0.02046"
"178.03800","14.83671","0.02039"
"178.20000","14.85023","0.02147"
"178.36200","14.86368","0.02197"
"178.52400","14.87719","0.02191"
"178.68600","14.89070","0.02208"
"178.84800","14.90416","0.02280"
"179.01000","14.91773","0.02314"
"179.17200","14.93124","0.02342"
"179.33400","14.94469","0.02374"
"179.49600","14.95820","0.02400"
"179.65800","14.97172","0.02418"
"179.82000","14.98517","0.02442"
"179.98200","14.99862","0.02511"
"180.14400","15.01225","0.02495"
"180.30600","15.02571","0.02610"
"180.46800","15.03916","0.02625"
"180.63000","15.05273","0.02642"
"180.79200","15.06625","0.02637"
"180.95400","15.07964","0.02631"
"181.11600","15.09315","0.02766"
"181.27800","15.10672","0.02737"
"181.44000","15.12018","0.02811"
"181.60200","15.13369","0.02817"
"181.76400","15.14726","0.02888"
"181.92600","15.16077","0.02908"
"182.08800","15.17422","0.02934"
"182.25000","15.18774","0.02931"
"182.41200","15.20125","0.02939"
"182.57400","15.21464","0.03021"
"182.73600","15.22821","0.03044"
"182.89800","15.24173","0.03112"
"183.06000","15.25518","0.03202"
"183.22200","15.26869","0.03209"
"183.38400","15.28220","0.03200"
"183.54600","15.29572","0.03226"
"183.70800","15.30917","0.03297"
"183.87000","15.32274","0.03345"
"184.03200","15.33620","0.03327"
"184.19400","15.34971","0.03383"
"184.35600","15.36322","0.03391"
"184.51800","15.37673","0.03431"
"184.68000","15.39018","0.03479"
"184.84200","15.40370","0.03458"
"185.00400","15.41721","0.03494"
"185.16600","15.43066","0.03532"
"185.32800","15.44417","0.03527"
"185.49000","15.45775","0.03529"
"185.65200","15.47120","0.03555"
"185.81400","15.48471","0.03606"
"185.97600","15.49817","0.03639"
"186.13800","15.51168","0.03667"
"186.30000","15.52513","0.03680"
"186.46200","15.53870","0.03729"
"186.62400","15.55222","0.03793"
"186.78600","15.56573","0.03754"
"186.94800","15.57918","0.03860"
"187.11000","15.59275","0.03853"
"187.27200","15.60620","0.03894"
"187.43400","15.61966","0.03901"
"187.59600","15.63323","0.03930"
"187.75800","15.64674","0.03948"
"187.92000","15.66019","0.03986"
"188.08200","15.67377","0.04010"
"188.24400","15.68722","0.04039"
"188.40600","15.70073","0.04079"
"188.56800","15.71412","0.04126"
"188.73000","15.72776","0.04155"
"188.89200","15.74121","0.04104"
"189.05400","15.75466","0.04222"
"189.21600","15.76823","0.04230"
"189.37800","15.78174","0.04198"
"189.54000","15.79514","0.04229"
"189.70200","15.80871","0.04232"
"189.86400","15.82216","0.04300"
"190.02600","15.83568","0.04274"
"190.18800","15.84913","0.04368"
"190.35000","15.86270","0.04365"
"190.51200","15.87621","0.04395"
"190.67400","15.88966","0.04355"
"190.83600","15.90318","0.04395"
"190.99800","15.91675","0.04476"
"191.16000","15.93014","0.04450"
"191.32200","15.94372","0.04502"
"191.48400","15.95717","0.04513"
"191.64600","15.97074","0.04513"
"191.80800","15.98419","0.04515"
"191.97000","15.99777","0.04551"
"192.13200","16.01128","0.04594"
"192.29400","16.02467","0.04593"
"192.45600","16.03818","0.04592"
"192.61800","16.05169","0.04594"
"192.78000","16.06521","0.04638"
"192.94200","16.07872","0.04645"
"193.10400","16.09223","0.04664"
"193.26600","16.10575","0.04678"
"193.42800","16.11920","0.04688"
"193.59000","16.13271","0.04700"
"193.75200","16.14616","0.04745"
"193.91400","16.15962","0.04733"
"194.07600","16.17325","0.04757"
"194.23800","16.18676","0.04785"
"194.40000","16.20021","0.04783"
"194.56200","16.21372","0.04807"
"194.72400","16.22724","0.04823"
"194.88600","16.24075","0.04857"
"195.04800","16.25420","0.04853"
"195.21000","16.26772","0.04915"
"195.37200","16.28123","0.04887"
"195.53400","16.29468","0.04908"
"195.69600","16.30831","0.04932"
"195.85800","16.32170","0.04941"
"196.02000","16.33516","0.05005"
"196.18200","16.34873","0.04979"
"196.34400","16.36224","0.05035"
"196.50600","16.37569","0.05020"
"196.66800","16.38921","0.05068"
"196.83000","16.40278","0.05094"
"196.99200","16.41629","0.05104"
"197.15400","16.42962","0.05146"
"197.31600","16.44326","0.05138"
"197.47800","16.45671","0.05205"
"197.64000","16.47016","0.05204"
"197.80200","16.48368","0.05241"
"197.96400","16.49725","0.05223"
"198.12600","16.51070","0.05267"
"198.28800","16.52421","0.05271"
"198.45000","16.53772","0.05348"
"198.61200","16.55124","0.05317"
"198.77400","16.56463","0.05378"
"198.93600","16.57820","0.05407"
"199.09800","16.59171","0.05468"
"199.26000","16.60517","0.05476"
"199.42200","16.61874","0.05507"
"199.58400","16.63225","0.05598"
"199.74600","16.64571","0.05604"
"199.90800","16.65922","0.05640"
"200.07000","16.67267","0.05672"
"200.23200","16.68618","0.05709"
"200.39400","16.69963","0.05754"
"200.55600","16.71321","0.05761"
"200.71800","16.72672","0.05843"
"200.88000","16.74017","0.05891"
"201.04200","16.75374","0.05912"
"201.20400","16.76720","0.05982"
"201.36600","16.78065","0.06016"
"201.52800","16.79416","0.06098"
"201.69000","16.80774","0.06161"
"201.85200","16.82125","0.06200"
"202.01400","16.83470","0.06209"
"202.17600","16.84827","0.06321"
"202.33800","16.86172","0.06317"
"202.50000","16.87518","0.06322"
"202.66200","16.88869","0.06428"
"202.82400","16.90220","0.06478"
"202.98600","16.91571","0.06513"
"203.14800","16.92923","0.06591"
"203.31000","16.94274","0.06659"
"203.47200","16.95619","0.06739"
"203.63400","16.96971","0.06736"
"203.79600","16.98322","0.06818"
"203.95800","16.99673","0.06833"
"204.12000","17.01018","0.06906"
"204.28200","17.02375","0.06917"
"204.44400","17.03721","0.06949"
"204.60600","17.05066","0.07063"
"204.76800","17.06423","0.07080"
"204.93000","17.07768","0.07109"
"205.09200","17.09114","0.07155"
"205.25400","17.10465","0.07231"
"205.41600","17.11822","0.07235"
"205.57800","17.13173","0.07303"
"205.74000","17.14519","0.07334"
"205.90200","17.15876","0.07344"
"206.06400","17.17221","0.07088"
"206.22600","17.18566","0.07159"
"206.38800","17.19918","0.07264"
"206.55000","17.21269","0.07295"
"206.71200","17.22620","0.07356"
"206.87400","17.23971","0.07381"
"207.03600","17.25328","0.07479"
"207.19800","17.26674","0.07554"
"207.36000","17.28019","0.07551"
"207.52200","17.29376","0.07584"
"207.68400","17.30728","0.07641"
"207.84600","17.32067","0.07690"
"208.00800","17.33418","0.07762"
"208.17000","17.34769","0.07777"
"208.33200","17.36121","0.07801"
"208.49400","17.37472","0.02412"
"208.65600","17.38817","0.02599"
"208.81800","17.40168","0.02356"
"208.98000","17.41514","0.01204"
"209.14200","17.42871","0.01153"
"209.30400","17.44228","0.02200"
"209.46600","17.45573","0.01573"
"209.62800","17.46925","0.01183"
"209.79000","17.48270","0.01638"
"209.95200","17.49621","0.01728"
"210.11400","17.50966","0.01533"
"210.27600","17.52324","0.01611"
"210.43800","17.53669","0.01465"
"210.60000","17.55014","0.01929"
"210.76200","17.56377","0.01674"
"210.92400","17.57722","0.01358"
"211.08600","17.59068","0.01916"
"211.24800","17.60419","0.01993"
"211.41000","17.61770","0.01422"
"211.57200","17.63116","0.01683"
"211.73400","17.64467","0.02066"
"211.89600","17.65824","0.01681"
"212.05800","17.67169","0.01734"
"212.22000","17.68514","0.01876"
"212.38200","17.69872","0.02038"
"212.54400","17.71223","0.01897"
"212.70600","17.72568","0.01728"
"212.86800","17.73919","0.02074"
"213.03000","17.75271","0.02129"
"213.19200","17.76616","0.01780"
"213.35400","17.77967","0.02017"
"213.51600","17.79325","0.02272"
"213.67800","17.80676","0.01989"
"213.84000","17.82015","0.01981"
"214.00200","17.83372","0.02197"
"214.16400","17.84724","0.02185"
"214.32600","17.86069","0.02083"
"214.48800","17.87420","0.02111"
"214.65000","17.88777","0.02399"
"214.81200","17.90122","0.02254"
"214.97400","17.91474","0.02137"
"215.13600","17.92825","0.02376"
"215.29800","17.94170","0.02439"
"215.46000","17.95516","0.02280"
"215.62200","17.96873","0.02365"
"215.78400","17.98224","0.02491"
"215.94600","17.99563","0.02447"
"216.10800","18.00920","0.02425"
"216.27000","18.02272","0.02613"
"216.43200","18.03617","0.02614"
"216.59400","18.04968","0.02447"
"216.75600","18.06319","0.02621"
"216.91800","18.07677","0.02753"
"217.08000","18.09022","0.02623"
"217.24200","18.10373","0.02513"
"217.40400","18.11719","0.02629"
"217.56600","18.13064","0.02670"
"217.72800","18.14421","0.02633"
"217.89000","18.15772","0.02772"
"218.05200","18.17123","0.02843"
"218.21400","18.18469","0.02656"
"218.37600","18.19826","0.02677"
"218.53800","18.21171","0.02904"
"218.70000","18.22511","0.02823"
"218.86200","18.23868","0.02814"
"219.02400","18.25219","0.02896"
"219.18600","18.26570","0.02909"
"219.34800","18.27921","0.02846"
"219.51000","18.29267","0.02860"
"219.67200","18.30618","0.03032"
"219.83400","18.31969","0.02894"
"219.99600","18.33320","0.02959"
"220.15800","18.34666","0.03062"
"220.32000","18.36017","0.02960"
"220.48200","18.37374","0.02927"
"220.64400","18.38725","0.03017"
"220.80600","18.40071","0.03051"
"220.96800","18.41422","0.03006"
"221.13000","18.42773","0.03084"
"221.29200","18.44118","0.03197"
"221.45400","18.45470","0.03184"
"221.61600","18.46815","0.03186"
"221.77800","18.48166","0.03317"
"221.94000","18.49523","0.03287"
"222.10200","18.50875","0.03260"
"222.26400","18.52226","0.03343"
"222.42600","18.53565","0.03380"
"222.58800","18.54922","0.03391"
"222.75000","18.56274","0.03361"
"222.91200","18.57613","0.03525"
"223.07400","18.58970","0.03421"
"223.23600","18.60321","0.03468"
"223.39800","18.61673","0.03506"
"223.56000","18.63018","0.03542"
"223.72200","18.64375","0.03481"
"223.88400","18.65720","0.03588"
"224.04600","18.67060","0.03657"
"224.20800","18.68417","0.03640"
"224.37000","18.69774","0.03575"
"224.53200","18.71113","0.03624"
"224.69400","18.72471","0.03416"
"224.85600","18.73822","0.03344"
"225.01800","18.75173","0.03499"
"225.18000","18.76518","0.03304"
"225.34200","18.77870","0.03416"
"225.50400","18.79221","0.03377"
"225.66600","18.80566","0.03451"
"225.82800","18.81923","0.03533"
"225.99000","18.83275","0.03503"
"226.15200","18.84614","0.03549"
"226.31400","18.85971","0.03582"
"226.47600","18.87317","0.03683"
"226.63800","18.88674","0.03672"
"226.80000","18.90019","0.03706"
"226.96200","18.91370","0.03773"
"227.12400","18.92722","0.03680"
"227.28600","18.94067","0.03711"
"227.44800","18.95424","0.03721"
"227.61000","18.96775","0.03795"
"227.77200","18.98120","0.03771"
"227.93400","18.99472","0.03825"
"228.09600","19.00823","0.03860"
"228.25800","19.02168","0.03835"
"228.42000","19.03519","0.03838"
"228.58200","19.04871","0.03944"
"228.74400","19.06216","0.04000"
"228.90600","19.07567","0.03964"
"229.06800","19.08918","0.04030"
"229.23000","19.10270","0.03998"
"229.39200","19.11615","0.04046"
"229.55400","19.12972","0.04073"
"229.71600","19.14329","0.00665"
"229.87800","19.15669","0.00251"
"230.04000","19.17014","0.00344"
"230.20200","19.18371","0.00167"
"230.36400","19.19716","-0.00041"
"230.52600","19.21062","-0.00006"
"230.68800","19.22425","0.00440"
"230.85000","19.23776","0.00429"
"231.01200","19.25115","-0.00095"
"231.17400","19.26473","0.00009"
"231.33600","19.27818","0.00109"
"231.49800","19.29169","0.00343"
"231.66000","19.30514","-0.00030"
"231.82200","19.31878","0.00296"
"231.98400","19.33223","0.00471"
"232.14600","19.34568","0.00024"
"232.30800","19.35919","0.00069"
"232.47000","19.37271","0.00315"
"232.63200","19.38622","0.00042"
"232.79400","19.39973","0.00058"
"232.95600","19.41324","0.00335"
"233.11800","19.42670","0.00269"
"233.28000","19.44021","-0.00046"
"233.44200","19.45378","0.00261"
"233.60400","19.46723","0.00418"
"233.76600","19.48063","0.00042"
"233.92800","19.49420","0.00109"
"234.09000","19.50771","0.00521"
"234.25200","19.52110","0.00363"
"234.41400","19.53473","0.00022"
"234.57600","19.54825","0.00272"
"234.73800","19.56170","0.00363"
"234.90000","19.57521","0.00053"
"235.06200","19.58872","0.00069"
"235.22400","19.60218","0.00366"
"235.38600","19.61563","0.00263"
"235.47200","19.62287","0.00112"