File: Force_trajectories/170225_2/Specimen_RawData_5.csv
End date,"2/25/2017"
Specimen label,"1CT_6"
Maximum Load,"0.03198",N

Time,Extension,Load
(s),(mm),(N)
"0.00000","0.00000","0.00076"
"0.34200","0.02846","0.00085"
"0.68400","0.05722","0.00144"
"1.02600","0.08568","0.00059"
"1.36800","0.11414","0.00055"
"1.71000","0.14266","0.00096"
"2.05200","0.17118","0.00089"
"2.39400","0.19970","0.00098"
"2.73600","0.22822","0.00158"
"3.07800","0.25668","0.00153"
"3.42000","0.28520","0.00153"
"3.76200","0.31366","0.00165"
"4.10400","0.34218","0.00204"
"4.44600","0.37070","0.00252"
"4.78800","0.39910","0.00190"
"5.13000","0.42767","0.00219"
"5.47200","0.45619","0.00296"
"5.81400","0.48459","0.00303"
"6.15600","0.51323","0.00398"
"6.49800","0.54163","0.00402"
"6.84000","0.57015","0.00393"
"7.18200","0.59867","0.00387"
"7.52400","0.62713","0.00484"
"7.86600","0.65565","0.00447"
"8.20800","0.68423","0.00462"
"8.55000","0.71263","0.00565"
"8.89200","0.74121","0.00509"
"9.23400","0.76973","0.00566"
"9.57600","0.79813","0.00521"
"9.91800","0.82671","0.00585"
"10.26000","0.85517","0.00549"
"10.60200","0.88363","0.00596"
"10.94400","0.91221","0.00632"
"11.28600","0.94061","0.00546"
"11.62800","0.96919","0.00554"
"11.97000","0.99771","0.00581"
"12.31200","1.02611","0.00573"
"12.65400","1.05475","0.00568"
"12.99600","1.08315","0.00625"
"13.33800","1.11161","0.00632"
"13.68000","1.14019","0.00659"
"14.02200","1.16865","0.00642"
"14.36400","1.19717","0.00638"
"14.70600","1.22569","0.00618"
"15.04800","1.25415","0.00677"
"15.39000","1.28266","0.00651"
"15.73200","1.31118","0.00682"
"16.07400","1.33964","0.00615"
"16.41600","1.36822","0.00646"
"16.75800","1.39668","0.00696"
"17.10000","1.42520","0.00668"
"17.44200","1.45366","0.00720"
"17.78400","1.48218","0.00663"
"18.12600","1.51064","0.00685"
"18.46800","1.53916","0.00698"
"18.81000","1.56768","0.00627"
"19.15200","1.59614","0.00698"
"19.49400","1.62466","0.00684"
"19.83600","1.65312","0.00710"
"20.17800","1.68170","0.00677"
"20.52000","1.71022","0.00688"
"20.86200","1.73862","0.00675"
"21.20400","1.76720","0.00693"
"21.54600","1.79572","0.00722"
"21.88800","1.82418","0.00746"
"22.23000","1.85270","0.00674"
"22.57200","1.88116","0.00743"
"22.91400","1.90962","0.00724"
"23.25600","1.93820","0.00757"
"23.59800","1.96666","0.00787"
"23.94000","1.99518","0.00736"
"24.28200","2.02370","0.00740"
"24.62400","2.05210","0.00791"
"24.96600","2.08068","0.00737"
"25.30800","2.10914","0.00738"
"25.65000","2.13760","0.00776"
"25.99200","2.16623","0.00799"
"26.33400","2.19463","0.00756"
"26.67600","2.22321","0.00751"
"27.01800","2.25173","0.00721"
"27.36000","2.28013","0.00773"
"27.70200","2.30865","0.00774"
"28.04400","2.33717","0.00740"
"28.38600","2.36563","0.00815"
"28.72800","2.39421","0.00767"
"29.07000","2.42273","0.00768"
"29.41200","2.45119","0.00787"
"29.75400","2.47965","0.00776"
"30.09600","2.50811","0.00781"
"30.43800","2.53675","0.00800"
"30.78000","2.56521","0.00779"
"31.12200","2.59367","0.00779"
"31.46400","2.62219","0.00823"
"31.80600","2.65065","0.00797"
"32.14800","2.67911","0.00862"
"32.49000","2.70769","0.00814"
"32.83200","2.73615","0.00781"
"33.17400","2.76467","0.00777"
"33.51600","2.79313","0.00823"
"33.85800","2.82165","0.00811"
"34.20000","2.85017","0.00826"
"34.54200","2.87869","0.00800"
"34.88400","2.90715","0.00788"
"35.22600","2.93573","0.00812"
"35.56800","2.96419","0.00779"
"35.91000","2.99271","0.00806"
"36.25200","3.02122","0.00819"
"36.59400","3.04968","0.00818"
"36.93600","3.07814","0.00847"
"37.27800","3.10666","0.00794"
"37.62000","3.13518","0.00839"
"37.96200","3.16364","0.00772"
"38.30400","3.19222","0.00835"
"38.64600","3.22062","0.00811"
"38.98800","3.24920","0.00854"
"39.33000","3.27766","0.00808"
"39.67200","3.30612","0.00861"
"40.01400","3.33464","0.00827"
"40.35600","3.36316","0.00819"
"40.69800","3.39168","0.00846"
"41.04000","3.42020","0.00847"
"41.38200","3.44866","0.00816"
"41.72400","3.47718","0.00780"
"42.06600","3.50576","0.00857"
"42.40800","3.53410","0.00788"
"42.75000","3.56268","0.00797"
"43.09200","3.59120","0.00819"
"43.43400","3.61966","0.00752"
"43.77600","3.64824","0.00698"
"44.11800","3.67664","0.00809"
"44.46000","3.70516","0.00776"
"44.80200","3.73368","0.00777"
"45.14400","3.76214","0.00762"
"45.48600","3.79072","0.00844"
"45.82800","3.81918","0.00797"
"46.17000","3.84758","0.00751"
"46.51200","3.87622","0.00795"
"46.85400","3.90468","0.00781"
"47.19600","3.93314","0.00739"
"47.53800","3.96171","0.00807"
"47.88000","3.99011","0.00775"
"48.22200","4.01863","0.00826"
"48.56400","4.04721","0.00841"
"48.90600","4.07561","0.00826"
"49.24800","4.10419","0.00830"
"49.59000","4.13265","0.00827"
"49.93200","4.16117","0.00824"
"50.27400","4.18975","0.00839"
"50.61600","4.21815","0.00868"
"50.95800","4.24661","0.00785"
"51.30000","4.27513","0.00784"
"51.64200","4.30365","0.00834"
"51.98400","4.33217","0.00807"
"52.32600","4.36069","0.00817"
"52.66800","4.38915","0.00823"
"53.01000","4.41761","0.00765"
"53.35200","4.44613","0.00835"
"53.69400","4.47465","0.00859"
"54.03600","4.50317","0.00839"
"54.37800","4.53169","0.00896"
"54.72000","4.56015","0.00875"
"55.06200","4.58867","0.00831"
"55.40400","4.61719","0.00835"
"55.74600","4.64571","0.00883"
"56.08800","4.67417","0.00851"
"56.43000","4.70257","0.00795"
"56.77200","4.73115","0.00818"
"57.11400","4.75973","0.00811"
"57.45600","4.78813","0.00797"
"57.79800","4.81670","0.00873"
"58.14000","4.84522","0.00888"
"58.48200","4.87362","0.00855"
"58.82400","4.90220","0.00876"
"59.16600","4.93066","0.00842"
"59.50800","4.95918","0.00855"
"59.85000","4.98770","0.00851"
"60.19200","5.01616","0.00890"
"60.53400","5.04468","0.00889"
"60.87600","5.07314","0.00951"
"61.21800","5.10166","0.00850"
"61.56000","5.13018","0.00845"
"61.90200","5.15870","0.00882"
"62.24400","5.18716","0.00836"
"62.58600","5.21568","0.00899"
"62.92800","5.24408","0.00940"
"63.27000","5.27272","0.00884"
"63.61200","5.30118","0.00869"
"63.95400","5.32958","0.00829"
"64.29600","5.35822","0.00881"
"64.63800","5.38674","0.00869"
"64.98000","5.41514","0.00931"
"65.32200","5.44372","0.00895"
"65.66400","5.47212","0.00865"
"66.00600","5.50064","0.00865"
"66.34800","5.52916","0.00916"
"66.69000","5.55762","0.00878"
"67.03200","5.58620","0.00847"
"67.37400","5.61472","0.00862"
"67.71600","5.64312","0.00884"
"68.05800","5.67169","0.00913"
"68.40000","5.70015","0.00903"
"68.74200","5.72861","0.00895"
"69.08400","5.75719","0.00879"
"69.42600","5.78565","0.00851"
"69.76800","5.81417","0.00898"
"70.11000","5.84263","0.00896"
"70.45200","5.87115","0.00887"
"70.79400","5.89961","0.00900"
"71.13600","5.92813","0.00824"
"71.47800","5.95659","0.00891"
"71.82000","5.98517","0.00876"
"72.16200","6.01375","0.00963"
"72.50400","6.04215","0.00882"
"72.84600","6.07073","0.00950"
"73.18800","6.09919","0.00911"
"73.53000","6.12771","0.00923"
"73.87200","6.15617","0.00825"
"74.21400","6.18469","0.00897"
"74.55600","6.21315","0.00898"
"74.89800","6.24167","0.00894"
"75.24000","6.27013","0.00886"
"75.58200","6.29865","0.00990"
"75.92400","6.32717","0.00881"
"76.26600","6.35569","0.00954"
"76.60800","6.38415","0.00900"
"76.95000","6.41261","0.00969"
"77.29200","6.44113","0.00968"
"77.63400","6.46971","0.00945"
"77.97600","6.49811","0.00914"
"78.31800","6.52663","0.00979"
"78.66000","6.55520","0.00923"
"79.00200","6.58366","0.00952"
"79.34400","6.61218","0.00957"
"79.68600","6.64070","0.00898"
"80.02800","6.66910","0.00968"
"80.37000","6.69768","0.00920"
"80.71200","6.72620","0.00951"
"81.05400","6.75466","0.00963"
"81.39600","6.78324","0.00994"
"81.73800","6.81158","0.00934"
"82.08000","6.84022","0.00972"
"82.42200","6.86868","0.00967"
"82.76400","6.89714","0.00970"
"83.10600","6.92572","0.01010"
"83.44800","6.95412","0.00934"
"83.79000","6.98264","0.01044"
"84.13200","7.01116","0.00944"
"84.47400","7.03968","0.00918"
"84.81600","7.06820","0.00939"
"85.15800","7.09666","0.00940"
"85.50000","7.12512","0.01015"
"85.84200","7.15370","0.01027"
"86.18400","7.18216","0.00955"
"86.52600","7.21062","0.00935"
"86.86800","7.23920","0.00978"
"87.21000","7.26766","0.00904"
"87.55200","7.29618","0.00951"
"87.89400","7.32470","0.00947"
"88.23600","7.35316","0.00968"
"88.57800","7.38162","0.01014"
"88.92000","7.41020","0.00939"
"89.26200","7.43865","0.00968"
"89.60400","7.46712","0.00951"
"89.94600","7.49569","0.00958"
"90.28800","7.52415","0.00921"
"90.63000","7.55273","0.01010"
"90.97200","7.58119","0.00968"
"91.31400","7.60965","0.00951"
"91.65600","7.63817","0.01010"
"91.99800","7.66663","0.00989"
"92.34000","7.69515","0.00988"
"92.68200","7.72367","0.01000"
"93.02400","7.75213","0.00948"
"93.36600","7.78071","0.01023"
"93.70800","7.80917","0.00924"
"94.05000","7.83757","0.00960"
"94.39200","7.86615","0.00979"
"94.73400","7.89461","0.00992"
"95.07600","7.92313","0.00968"
"95.41800","7.95171","0.00983"
"95.76000","7.98017","0.00992"
"96.10200","8.00869","0.01013"
"96.44400","8.03721","0.00988"
"96.78600","8.06561","0.01000"
"97.12800","8.09419","0.00997"
"97.47000","8.12271","0.01063"
"97.81200","8.15111","0.00949"
"98.15400","8.17969","0.00963"
"98.49600","8.20821","0.00985"
"98.83800","8.23667","0.00985"
"99.18000","8.26519","0.01022"
"99.52200","8.29358","0.01016"
"99.86400","8.32216","0.00981"
"100.20600","8.35074","0.01035"
"100.54800","8.37908","0.00992"
"100.89000","8.40772","0.00973"
"101.23200","8.43618","0.01021"
"101.57400","8.46464","0.01028"
"101.91600","8.49316","0.00998"
"102.25800","8.52162","0.01036"
"102.60000","8.55014","0.01065"
"102.94200","8.57866","0.01064"
"103.28400","8.60712","0.01028"
"103.62600","8.63564","0.01011"
"103.96800","8.66416","0.01074"
"104.31000","8.69262","0.01057"
"104.65200","8.72120","0.01059"
"104.99400","8.74972","0.01099"
"105.33600","8.77818","0.01044"
"105.67800","8.80670","0.01050"
"106.02000","8.83522","0.01061"
"106.36200","8.86368","0.01022"
"106.70400","8.89214","0.01065"
"107.04600","8.92066","0.01072"
"107.38800","8.94918","0.01072"
"107.73000","8.97770","0.01097"
"108.07200","9.00610","0.01113"
"108.41400","9.03468","0.01066"
"108.75600","9.06314","0.01080"
"109.09800","9.09160","0.01065"
"109.44000","9.12024","0.01078"
"109.78200","9.14870","0.01070"
"110.12400","9.17715","0.01061"
"110.46600","9.20573","0.01006"
"110.80800","9.23419","0.01114"
"111.15000","9.26265","0.01118"
"111.49200","9.29123","0.01058"
"111.83400","9.31963","0.01043"
"112.17600","9.34815","0.01089"
"112.51800","9.37667","0.01091"
"112.86000","9.40519","0.01165"
"113.20200","9.43371","0.01087"
"113.54400","9.46217","0.01084"
"113.88600","9.49063","0.01055"
"114.22800","9.51921","0.01086"
"114.57000","9.54761","0.01087"
"114.91200","9.57619","0.01134"
"115.25400","9.60477","0.01140"
"115.59600","9.63311","0.01144"
"115.93800","9.66169","0.01130"
"116.28000","9.69021","0.01132"
"116.62200","9.71867","0.01077"
"116.96400","9.74719","0.01116"
"117.30600","9.77565","0.01141"
"117.64800","9.80417","0.01163"
"117.99000","9.83269","0.01079"
"118.33200","9.86109","0.01103"
"118.67400","9.88973","0.01100"
"119.01600","9.91819","0.01160"
"119.35800","9.94665","0.01218"
"119.70000","9.97522","0.01161"
"120.04200","10.00369","0.01182"
"120.38400","10.03215","0.01149"
"120.72600","10.06066","0.01155"
"121.06800","10.08913","0.01171"
"121.41000","10.11770","0.01148"
"121.75200","10.14616","0.01140"
"122.09400","10.17462","0.01180"
"122.43600","10.20314","0.01169"
"122.77800","10.23166","0.01150"
"123.12000","10.26018","0.01182"
"123.46200","10.28864","0.01210"
"123.80400","10.31716","0.01176"
"124.14600","10.34562","0.01210"
"124.48800","10.37420","0.01151"
"124.83000","10.40266","0.01207"
"125.17200","10.43118","0.01162"
"125.51400","10.45970","0.01191"
"125.85600","10.48816","0.01200"
"126.19800","10.51668","0.01206"
"126.54000","10.54520","0.01146"
"126.88200","10.57366","0.01196"
"127.22400","10.60218","0.01199"
"127.56600","10.63070","0.01145"
"127.90800","10.65916","0.01247"
"128.25000","10.68768","0.01197"
"128.59200","10.71614","0.01143"
"128.93400","10.74466","0.01212"
"129.27600","10.77324","0.01263"
"129.61800","10.80164","0.01234"
"129.96000","10.83016","0.01238"
"130.30200","10.85874","0.01227"
"130.64400","10.88713","0.01244"
"130.98600","10.91566","0.01208"
"131.32800","10.94418","0.01282"
"131.67000","10.97263","0.01229"
"132.01200","11.00121","0.01211"
"132.35400","11.02967","0.01216"
"132.69600","11.05813","0.01260"
"133.03800","11.08671","0.01250"
"133.38000","11.11511","0.01244"
"133.72200","11.14369","0.01289"
"134.06400","11.17221","0.01367"
"134.40600","11.20061","0.01262"
"134.74800","11.22919","0.01316"
"135.09000","11.25765","0.01238"
"135.43200","11.28611","0.01335"
"135.77400","11.31469","0.01269"
"136.11600","11.34315","0.01322"
"136.45800","11.37167","0.01320"
"136.80000","11.40019","0.01373"
"137.14200","11.42859","0.01352"
"137.48400","11.45717","0.01379"
"137.82600","11.48569","0.01321"
"138.16800","11.51415","0.01339"
"138.51000","11.54267","0.01374"
"138.85200","11.57113","0.01390"
"139.19400","11.59971","0.01394"
"139.53600","11.62817","0.01378"
"139.87800","11.65663","0.01389"
"140.22000","11.68521","0.01421"
"140.56200","11.71367","0.01431"
"140.90400","11.74213","0.01451"
"141.24600","11.77071","0.01455"
"141.58800","11.79917","0.01434"
"141.93000","11.82769","0.01448"
"142.27200","11.85620","0.01480"
"142.61400","11.88466","0.01551"
"142.95600","11.91318","0.01535"
"143.29800","11.94164","0.01496"
"143.64000","11.97016","0.01513"
"143.98200","11.99868","0.01523"
"144.32400","12.02714","0.01547"
"144.66600","12.05566","0.01512"
"145.00800","12.08424","0.01526"
"145.35000","12.11264","0.01632"
"145.69200","12.14110","0.01535"
"146.03400","12.16968","0.01543"
"146.37600","12.19820","0.01579"
"146.71800","12.22666","0.01559"
"147.06000","12.25518","0.01642"
"147.40200","12.28364","0.01634"
"147.74400","12.31216","0.01663"
"148.08600","12.34068","0.01691"
"148.42800","12.36914","0.01663"
"148.77000","12.39772","0.01680"
"149.11200","12.42618","0.01673"
"149.45400","12.45464","0.01685"
"149.79600","12.48322","0.01800"
"150.13800","12.51168","0.01685"
"150.48000","12.54014","0.01709"
"150.82200","12.56878","0.01799"
"151.16400","12.59712","0.01736"
"151.50600","12.62570","0.01840"
"151.84800","12.65421","0.01756"
"152.19000","12.68262","0.01826"
"152.53200","12.71119","0.01826"
"152.87400","12.73965","0.01819"
"153.21600","12.76812","0.01921"
"153.55800","12.79675","0.01896"
"153.90000","12.82515","0.01904"
"154.24200","12.85367","0.01947"
"154.58400","12.88219","0.01931"
"154.92600","12.91059","0.01915"
"155.26800","12.93917","0.01943"
"155.61000","12.96769","0.01991"
"155.95200","12.99615","0.01977"
"156.29400","13.02467","0.02044"
"156.63600","13.05325","0.02089"
"156.97800","13.08165","0.02096"
"157.32000","13.11023","0.02016"
"157.66200","13.13863","0.01110"
"158.00400","13.16715","0.01205"
"158.34600","13.19567","0.01586"
"158.68800","13.22407","0.01091"
"159.03000","13.25271","0.01206"
"159.37200","13.28123","0.01558"
"159.71400","13.30963","0.01348"
"160.05600","13.33821","0.01157"
"160.39800","13.36667","0.01394"
"160.74000","13.39513","0.01442"
"161.08200","13.42365","0.01243"
"161.42400","13.45217","0.01325"
"161.76600","13.48069","0.01497"
"162.10800","13.50915","0.01471"
"162.45000","13.53767","0.01344"
"162.79200","13.56612","0.01469"
"163.13400","13.59471","0.01504"
"163.47600","13.62316","0.01428"
"163.81800","13.65168","0.01394"
"164.16000","13.68020","0.01533"
"164.50200","13.70866","0.01489"
"164.84400","13.73718","0.01401"
"165.18600","13.76564","0.01474"
"165.52800","13.79416","0.01591"
"165.87000","13.82268","0.01537"
"166.21200","13.85114","0.01476"
"166.55400","13.87966","0.01541"
"166.89600","13.90824","0.01645"
"167.23800","13.93658","0.01585"
"167.58000","13.96522","0.01574"
"167.92200","13.99368","0.01607"
"168.26400","14.02220","0.01608"
"168.60600","14.05072","0.01668"
"168.94800","14.07918","0.01664"
"169.29000","14.10764","0.01706"
"169.63200","14.13622","0.01743"
"169.97400","14.16462","0.01677"
"170.31600","14.19320","0.01750"
"170.65800","14.22172","0.01740"
"171.00000","14.25012","0.01831"
"171.34200","14.27870","0.01762"
"171.68400","14.30716","0.01893"
"172.02600","14.33568","0.01784"
"172.36800","14.36420","0.01834"
"172.71000","14.39260","0.01793"
"173.05200","14.42118","0.01835"
"173.39400","14.44970","0.01873"
"173.73600","14.47810","0.01851"
"174.07800","14.50668","0.01903"
"174.42000","14.53519","0.01916"
"174.76200","14.56365","0.01973"
"175.10400","14.59223","0.01990"
"175.44600","14.62069","0.01976"
"175.78800","14.64915","0.02060"
"176.13000","14.67767","0.02092"
"176.47200","14.70613","0.02162"
"176.81400","14.73471","0.02098"
"177.15600","14.76317","0.02161"
"177.49800","14.79163","0.02147"
"177.84000","14.82015","0.02274"
"178.18200","14.84861","0.02333"
"178.52400","14.87713","0.02410"
"178.86600","14.90571","0.02344"
"179.20800","14.93417","0.02372"
"179.55000","14.96263","0.02492"
"179.89200","14.99115","0.02578"
"180.23400","15.01967","0.02573"
"180.57600","15.04819","0.02599"
"180.91800","15.07671","0.02664"
"181.26000","15.10511","0.02698"
"181.60200","15.13369","0.02772"
"181.94400","15.16221","0.02878"
"182.28600","15.19067","0.02858"
"182.62800","15.21919","0.02949"
"182.97000","15.24771","0.03045"
"183.31200","15.27611","0.02992"
"183.65400","15.30463","0.03060"
"183.99600","15.33315","0.03114"
"184.33800","15.36161","0.03043"
"184.68000","15.39018","0.01595"
"185.02200","15.41864","0.00544"
"185.36400","15.44716","0.00536"
"185.70600","15.47569","0.00704"
"186.04800","15.50414","0.00474"
"186.39000","15.53266","0.00777"
"186.73200","15.56112","0.00441"
"187.07400","15.58964","0.00753"
"187.41600","15.61822","0.00540"
"187.75800","15.64668","0.00698"
"188.10000","15.67514","0.00606"
"188.44200","15.70366","0.00744"
"188.78400","15.73212","0.00645"
"189.12600","15.76070","0.00722"
"189.46800","15.78922","0.00568"
"189.81000","15.81768","0.00636"
"190.15200","15.84620","0.00655"
"190.49400","15.87460","0.00682"
"190.83600","15.90318","0.00702"
"191.17800","15.93170","0.00727"
"191.52000","15.96010","0.00729"
"191.86200","15.98874","0.00784"
"192.20400","16.01720","0.00766"
"192.54600","16.04560","0.00790"
"192.88800","16.07418","0.00724"
"193.23000","16.10270","0.00777"
"193.57200","16.13116","0.00709"
"193.91400","16.15968","0.00778"
"194.25600","16.18814","0.00798"
"194.59800","16.21671","0.00799"
"194.94000","16.24517","0.00790"
"195.28200","16.27363","0.00827"
"195.62400","16.30221","0.00847"
"195.96600","16.33068","0.00604"
"196.30800","16.35913","0.00639"
"196.65000","16.38771","0.00603"
"196.99200","16.41617","0.00667"
"197.33400","16.44469","0.00596"
"197.67600","16.47321","0.00596"
"198.01800","16.50167","0.00629"
"198.36000","16.53019","0.00659"
"198.70200","16.55865","0.00639"
"199.04400","16.58717","0.00606"
"199.38600","16.61563","0.00680"
"199.72800","16.64421","0.00602"
"200.07000","16.67267","0.00624"
"200.41200","16.70119","0.00717"
"200.75400","16.72971","0.00626"
"201.09600","16.75811","0.00568"
"201.43800","16.78663","0.00659"
"201.78000","16.81515","0.00668"
"202.12200","16.84367","0.00604"
"202.46400","16.87225","0.00636"
"202.80600","16.90059","0.00624"
"203.14800","16.92917","0.00694"
"203.49000","16.95775","0.00687"
"203.83200","16.98609","0.00689"
"204.17400","17.01467","0.00608"
"204.51600","17.04319","0.00627"
"204.85800","17.07165","0.00689"
"205.20000","17.10022","0.00655"
"205.54200","17.12862","0.00704"
"205.88400","17.15714","0.00731"
"206.22600","17.18566","0.00682"
"206.56800","17.21406","0.00642"
"206.91000","17.24270","0.00692"
"207.25200","17.27122","0.00622"
"207.59400","17.29962","0.00694"
"207.93600","17.32820","0.00742"
"208.27800","17.35666","0.00747"
"208.62000","17.38518","0.00744"
"208.96200","17.41370","0.00715"
"209.30400","17.44216","0.00750"
"209.64600","17.47068","0.00726"
"209.98800","17.49920","0.00732"
"210.33000","17.52760","0.00691"
"210.67200","17.55618","0.00758"
"211.01400","17.58470","0.00765"
"211.35600","17.61316","0.00730"
"211.69800","17.64174","0.00765"
"212.04000","17.67014","0.00754"
"212.38200","17.69866","0.00703"
"212.72400","17.72718","0.00744"
"213.06600","17.75564","0.00772"
"213.40800","17.78416","0.00782"
"213.75000","17.81268","0.00773"
"214.09200","17.84114","0.00731"
"214.43400","17.86972","0.00775"
"214.77600","17.89818","0.00751"
"215.11800","17.92669","0.00745"
"215.46000","17.95516","0.00826"
"215.80200","17.98368","0.00792"
"216.14400","18.01219","0.00708"
"216.48600","18.04066","0.00783"
"216.82800","18.06917","0.00776"
"217.17000","18.09763","0.00737"
"217.51200","18.12615","0.00776"
"217.85400","18.15461","0.00739"
"218.19600","18.18319","0.00758"
"218.53800","18.21171","0.00787"
"218.88000","18.24011","0.00838"
"219.22200","18.26863","0.00759"
"219.56400","18.29721","0.00751"
"219.90600","18.32561","0.00788"
"220.24800","18.35419","0.00769"
"220.59000","18.38265","0.00809"
"220.93200","18.41117","0.00758"
"221.27400","18.43969","0.00795"
"221.61600","18.46815","0.00806"
"221.95800","18.49667","0.00764"
"222.30000","18.52519","0.00767"
"222.64200","18.55365","0.00771"
"222.98400","18.58217","0.00806"
"223.32600","18.61069","0.00856"
"223.66800","18.63915","0.00803"
"224.01000","18.66773","0.00748"
"224.35200","18.69607","0.00746"
"224.69400","18.72465","0.00746"
"225.03600","18.75317","0.00696"
"225.37800","18.78163","0.00724"
"225.72000","18.81021","0.00722"
"226.06200","18.83873","0.00742"
"226.40400","18.86713","0.00681"
"226.74600","18.89570","0.00794"
"227.08800","18.92416","0.00762"
"227.43000","18.95263","0.00698"
"227.77200","18.98120","0.00798"
"228.11400","19.00960","0.00725"
"228.45600","19.03818","0.00720"
"228.79800","19.06676","0.00746"
"229.14000","19.09510","0.00690"
"229.48200","19.12368","0.00745"
"229.82400","19.15214","0.00700"
"230.16600","19.18066","0.00753"
"230.50800","19.20918","0.00675"
"230.85000","19.23764","0.00752"
"231.19200","19.26616","0.00753"
"231.53400","19.29462","0.00720"
"231.87600","19.32314","0.00715"
"232.21800","19.35166","0.00722"
"232.56000","19.38018","0.00705"
"232.90200","19.40864","0.00723"
"233.24400","19.43722","0.00720"
"233.58600","19.46568","0.00722"
"233.92800","19.49414","0.00766"
"234.27000","19.52266","0.00696"
"234.61200","19.55112","0.00755"
"234.95400","19.57964","0.00757"
"235.29600","19.60816","0.00744"
"235.63800","19.63667","0.00746"
"235.98000","19.66514","0.00762"
"236.32200","19.69371","0.00750"
"236.66400","19.72211","0.00751"
"237.00600","19.75070","0.00691"
"237.34800","19.77921","0.00785"
"237.69000","19.80767","0.00753"
"238.03200","19.83619","0.00782"
"238.37400","19.86465","0.00721"
"238.71600","19.89317","0.00774"
"239.05800","19.92169","0.00706"
"239.40000","19.95009","0.00695"
"239.74200","19.97867","0.00728"
"240.08400","20.00725","0.00691"
"240.42600","20.03565","0.00725"
"240.76800","20.06417","0.00721"
"241.11000","20.09269","0.00718"
"241.45200","20.12115","0.00716"
"241.79400","20.14973","0.00720"
"242.13600","20.17819","0.00762"
"242.47800","20.20665","0.00755"
"242.82000","20.23517","0.00725"
"243.16200","20.26363","0.00759"
"243.50400","20.29221","0.00675"
"243.84600","20.32073","0.00745"
"244.18800","20.34907","0.00794"
"244.53000","20.37771","0.00776"
"244.87200","20.40617","0.00729"
"245.21400","20.43463","0.00757"
"245.55600","20.46315","0.00770"
"245.89800","20.49167","0.00790"
"246.24000","20.52019","0.00772"
"246.58200","20.54870","0.00764"
"246.92400","20.57711","0.00795"
"247.26600","20.60568","0.00833"
"247.60800","20.63421","0.00782"
"247.95000","20.66260","0.00797"
"248.29200","20.69118","0.00799"
"248.63400","20.71964","0.00841"
"248.97600","20.74810","0.00792"
"249.31800","20.77668","0.00827"
"249.66000","20.80514","0.00848"
"250.00200","20.83366","0.00794"
"250.34400","20.86218","0.00843"
"250.68600","20.89070","0.00837"
"251.02800","20.91916","0.00797"
"251.37000","20.94768","0.00849"
"251.71200","20.97620","0.00848"
"252.05400","21.00472","0.00874"
"252.39600","21.03324","0.00835"
"252.73800","21.06164","0.00877"
"253.08000","21.09016","0.00834"
"253.42200","21.11862","0.00892"
"253.76400","21.14720","0.00889"
"254.10600","21.17572","0.00875"
"254.44800","21.20412","0.00896"
"254.79000","21.23270","0.00908"
"255.13200","21.26116","0.00907"
"255.47400","21.28962","0.00870"
"255.81600","21.31814","0.00839"
"256.15800","21.34672","0.00882"
"256.50000","21.37512","0.00947"
"256.84200","21.40369","0.00905"
"257.18400","21.43216","0.00899"
"257.52600","21.46067","0.00929"
"257.86800","21.48926","0.01009"
"258.21000","21.51760","0.00931"
"258.55200","21.54618","0.00951"
"258.89400","21.57470","0.00926"
"259.23600","21.60315","0.00973"
"259.57800","21.63173","0.00985"
"259.92000","21.66013","0.01035"
"260.26200","21.68859","0.01015"
"260.60400","21.71723","0.00971"
"260.94600","21.74569","0.01014"
"261.28800","21.77415","0.01004"
"261.63000","21.80273","0.01009"
"261.97200","21.83107","0.01049"
"262.31400","21.85971","0.00988"
"262.65600","21.88823","0.00977"
"262.99800","21.91657","0.00938"
"263.34000","21.94521","0.01025"
"263.68200","21.97361","0.01007"
"264.02400","22.00219","0.00997"
"264.36600","22.03071","0.01056"
"264.70800","22.05917","0.01075"
"265.05000","22.08769","0.01024"
"265.39200","22.11621","0.01025"
"265.73400","22.14461","0.01050"
"266.07600","22.17319","0.01040"
"266.41800","22.20171","0.01024"
"266.76000","22.23017","0.01058"
"267.10200","22.25869","0.01017"
"267.44400","22.28715","0.01035"
"267.78600","22.31566","0.01071"
"268.12800","22.34413","0.01023"
"268.47000","22.37264","0.00962"
"268.81200","22.40117","0.01071"
"269.15400","22.42969","0.01106"
"269.49600","22.45815","0.01074"
"269.83800","22.48666","0.01120"
"270.18000","22.51518","0.01053"
"270.52200","22.54364","0.01029"
"270.86400","22.57222","0.01053"
"271.20600","22.60068","0.01080"
"271.54800","22.62914","0.01027"
"271.89000","22.65772","0.01068"
"272.23200","22.68618","0.01074"
"272.57400","22.71464","0.01080"
"272.91600","22.74316","0.01109"
"273.25800","22.77162","0.01095"
"273.60000","22.80020","0.01096"
"273.94200","22.82866","0.01101"
"274.28400","22.85718","0.01136"
"274.62600","22.88564","0.01138"
"274.96800","22.91416","0.01126"
"275.31000","22.94268","0.01099"
"275.65200","22.97120","0.01114"
"275.99400","22.99960","0.01041"
"276.33600","23.02818","0.01026"
"276.67800","23.05676","0.01062"
"277.02000","23.08510","0.01046"
"277.36200","23.11368","0.01046"
"277.70400","23.14220","0.01069"
"278.04600","23.17066","0.01121"
"278.38800","23.19917","0.01058"
"278.73000","23.22770","0.01095"
"279.07200","23.25616","0.01118"
"279.41400","23.28473","0.01060"
"279.75600","23.31307","0.01150"
"280.09800","23.34171","0.01112"
"280.44000","23.37023","0.01108"
"280.78200","23.39863","0.01114"
"281.12400","23.42721","0.01100"
"281.46600","23.45567","0.01160"
"281.80800","23.48419","0.01129"
"282.15000","23.51265","0.01138"
"282.49200","23.54111","0.01135"
"282.83400","23.56969","0.01167"
"283.17600","23.59815","0.01195"
"283.51800","23.62661","0.01169"
"283.86000","23.65519","0.01213"
"284.20200","23.68371","0.01199"
"284.54400","23.71217","0.01172"
"284.88600","23.74075","0.01236"
"285.22800","23.76921","0.01191"
"285.57000","23.79761","0.01255"
"285.91200","23.82619","0.01261"
"286.25400","23.85465","0.01276"
"286.59600","23.88323","0.01271"
"286.93800","23.91169","0.01251"
"287.28000","23.94015","0.01295"
"287.62200","23.96867","0.01272"
"287.96400","23.99719","0.01290"
"288.30600","24.02564","0.01329"
"288.64800","24.05417","0.01282"
"288.99000","24.08269","0.01297"
"289.33200","24.11115","0.01328"
"289.67400","24.13972","0.01275"
"290.01600","24.16818","0.01304"
"290.35800","24.19665","0.01356"
"290.70000","24.22523","0.01302"
"291.04200","24.25362","0.01320"
"291.38400","24.28220","0.01346"
"291.72600","24.31066","0.01352"
"292.06800","24.33912","0.01393"
"292.41000","24.36764","0.01358"
"292.75200","24.39616","0.01418"
"293.09400","24.42468","0.01380"
"293.43600","24.45320","0.01452"
"293.77800","24.48166","0.01398"
"294.12000","24.51012","0.01375"
"294.46200","24.53876","0.01430"
"294.80400","24.56716","0.01383"
"295.14600","24.59568","0.01424"
"295.48800","24.62420","0.01472"
"295.83000","24.65260","0.01434"
"296.17200","24.68118","0.01449"
"296.51400","24.70970","0.01479"
"296.85600","24.73810","0.01488"
"297.19800","24.76668","0.01510"
"297.54000","24.79514","0.01485"
"297.88200","24.82372","0.01515"
"298.22400","24.85224","0.01502"
"298.56600","24.88058","0.01515"
"298.90800","24.90915","0.01539"
"299.25000","24.93774","0.01526"
"299.59200","24.96614","0.01530"
"299.93400","24.99471","0.01577"
"300.27600","25.02311","0.01592"
"300.61800","25.05169","0.01591"
"300.96000","25.08022","0.01628"
"301.30200","25.10862","0.01614"
"301.64400","25.13720","0.01605"
"301.98600","25.16566","0.01621"
"302.32800","25.19411","0.01610"
"302.67000","25.22264","0.01669"
"303.01200","25.25115","0.01590"
"303.35400","25.27967","0.01645"
"303.69600","25.30819","0.01634"
"304.03800","25.33671","0.01676"
"304.38000","25.36517","0.01663"
"304.72200","25.39369","0.01692"
"305.06400","25.42215","0.01683"
"305.40600","25.45067","0.01699"
"305.74800","25.47919","0.01614"
"306.09000","25.50759","0.01618"
"306.43200","25.53623","0.01549"
"306.77400","25.56463","0.01469"
"307.11600","25.59315","0.01458"
"307.45800","25.62167","0.01542"
"307.80000","25.65019","0.01492"
"308.14200","25.67865","0.01528"
"308.48400","25.70717","0.01584"
"308.82600","25.73569","0.01602"
"309.16800","25.76415","0.01551"
"309.51000","25.79273","0.01640"
"309.85200","25.82119","0.01531"
"310.19400","25.84970","0.01652"
"310.53600","25.87817","0.01627"
"310.87800","25.90668","0.01567"
"311.22000","25.93514","0.01565"
"311.56200","25.96367","0.01566"
"311.90400","25.99212","0.01576"
"312.24600","26.02071","0.01621"
"312.58800","26.04910","0.01597"
"312.93000","26.07768","0.01624"
"313.27200","26.10626","0.01596"
"313.61400","26.13461","0.01591"
"313.95600","26.16318","0.01633"
"314.29800","26.19164","0.01544"
"314.64000","26.22010","0.01427"
"314.98200","26.24874","0.01420"
"315.32400","26.27714","0.00932"
"315.66600","26.30566","0.01238"
"316.00800","26.33418","0.01029"
"316.35000","26.36258","0.01073"
"316.69200","26.39122","0.01195"
"317.03400","26.41968","0.00981"
"317.37600","26.44814","0.01033"
"317.71800","26.47672","0.01026"
"318.06000","26.50518","0.01098"
"318.40200","26.53364","0.01022"
"318.74400","26.56216","0.01102"
"319.08600","26.59062","0.01044"
"319.42800","26.61914","0.01048"
"319.77000","26.64772","0.01048"
"320.11200","26.67612","0.01062"
"320.45400","26.70470","0.01097"
"320.79600","26.73316","0.01030"
"321.13800","26.76162","0.01037"
"321.48000","26.79019","0.01059"
"321.82200","26.81865","0.01071"
"322.16400","26.84711","0.01008"
"322.50600","26.87569","0.01012"
"322.84800","26.90415","0.01065"
"323.19000","26.93268","0.01005"
"323.53200","26.96119","0.01027"
"323.87400","26.98965","0.01019"
"324.21600","27.01817","0.01008"
"324.55800","27.04669","0.00997"
"324.90000","27.07515","0.00966"
"325.24200","27.10373","0.00959"
"325.58400","27.13213","0.00928"
"325.92600","27.16065","0.01023"
"326.26800","27.18917","0.00920"
"326.61000","27.21769","0.00940"
"326.95200","27.24615","0.00975"
"327.29400","27.27467","0.00924"
"327.63600","27.30319","0.00976"
"327.97800","27.33165","0.00919"
"328.32000","27.36023","0.00953"
"328.66200","27.38863","0.00967"
"329.00400","27.41715","0.00975"
"329.34600","27.44567","0.01014"
"329.68800","27.47419","0.01013"
"330.03000","27.50271","0.00960"
"330.37200","27.53117","0.00942"
"330.71400","27.55963","0.00985"
"331.05600","27.58821","0.01016"
"331.39800","27.61661","0.00994"
"331.74000","27.64519","0.00944"
"332.08200","27.67371","0.00962"
"332.42400","27.70211","0.01025"
"332.76600","27.73074","0.01038"
"333.10800","27.75915","0.00992"
"333.45000","27.78766","0.00994"
"333.79200","27.81618","0.01024"
"334.13400","27.84464","0.01003"
"334.47600","27.87322","0.01061"
"334.81800","27.90168","0.01007"
"335.16000","27.93008","0.01047"
"335.50200","27.95866","0.01042"
"335.84400","27.98718","0.01066"
"336.18600","28.01564","0.01051"
"336.52800","28.04422","0.01047"
"336.87000","28.07268","0.01068"
"337.21200","28.10114","0.01098"
"337.55400","28.12972","0.01069"
"337.89600","28.15812","0.01024"
"338.23800","28.18670","0.01085"
"338.58000","28.21516","0.01076"
"338.92200","28.24356","0.01096"
"339.26400","28.27220","0.01054"
"339.60600","28.30066","0.01102"
"339.94800","28.32912","0.01124"
"340.29000","28.35770","0.01110"
"340.63200","28.38616","0.01114"
"340.97400","28.41468","0.01082"
"341.31600","28.44314","0.01089"
"341.65800","28.47166","0.01138"
"342.00000","28.50018","0.01104"
"342.34200","28.52869","0.01163"
"342.68400","28.55710","0.01167"
"343.02600","28.58574","0.01164"
"343.36800","28.61413","0.01137"
"343.71000","28.64266","0.01102"
"344.05200","28.67118","0.01134"
"344.39400","28.69969","0.01158"
"344.73600","28.72815","0.01189"
"345.07800","28.75667","0.01186"
"345.42000","28.78513","0.01115"
"345.76200","28.81359","0.01169"
"346.10400","28.84223","0.01135"
"346.44600","28.87063","0.01166"
"346.78800","28.89921","0.01083"
"347.13000","28.92773","0.01149"
"347.47200","28.95613","0.01163"
"347.81400","28.98465","0.01116"
"348.15600","29.01317","0.01109"
"348.49800","29.04163","0.01049"
"348.84000","29.07027","0.01138"
"349.18200","29.09861","0.01123"
"349.52400","29.12713","0.01076"
"349.86600","29.15571","0.01080"
"350.20800","29.18411","0.00969"
"350.55000","29.21269","0.01023"
"350.89200","29.24121","0.00758"
"351.23400","29.26961","0.00758"
"351.57600","29.29825","0.00675"
"351.91800","29.32665","0.00766"
"352.26000","29.35517","0.00675"
"352.60200","29.38369","0.00735"
"352.94400","29.41215","0.00731"
"353.28600","29.44073","0.00758"
"353.62800","29.46919","0.00793"
"353.97000","29.49765","0.00750"
"354.31200","29.52617","0.00796"
"354.65400","29.55463","0.00858"
"354.99600","29.58315","0.00773"
"355.33800","29.61166","0.00727"
"355.68000","29.64018","0.00762"
"356.02200","29.66870","0.00806"
"356.36400","29.69716","0.00749"
"356.70600","29.72562","0.00799"
"357.04800","29.75420","0.00828"
"357.39000","29.78266","0.00795"
"357.73200","29.81112","0.00832"
"358.07400","29.83970","0.00857"
"358.41600","29.86816","0.00846"
"358.75800","29.89668","0.00789"
"359.10000","29.92520","0.00843"
"359.44200","29.95366","0.00848"
"359.78400","29.98218","0.00817"
"360.12600","30.01064","0.00869"
"360.46800","30.03916","0.00888"
"360.81000","30.06768","0.00816"
"361.15200","30.09620","0.00861"
"361.49400","30.12466","0.00834"
"361.83600","30.15318","0.00863"
"362.17800","30.18164","0.00850"
"362.52000","30.21010","0.00883"
"362.86200","30.23862","0.00859"
"363.20400","30.26720","0.00913"
"363.54600","30.29565","0.00864"
"363.88800","30.32418","0.00876"
"364.23000","30.35264","0.00892"
"364.57200","30.38116","0.00929"
"364.91400","30.40973","0.00867"
"365.25600","30.43808","0.00931"
"365.59800","30.46665","0.00953"
"365.94000","30.49517","0.00957"
"366.28200","30.52363","0.00966"
"366.62400","30.55227","0.00984"
"366.96600","30.58061","0.01009"
"367.30800","30.60913","0.00963"
"367.65000","30.63771","0.00974"
"367.99200","30.66611","0.00927"
"368.33400","30.69469","0.01000"
"368.67600","30.72321","0.00953"
"369.01800","30.75161","0.00992"
"369.36000","30.78019","0.01001"
"369.70200","30.80865","0.00924"
"370.04400","30.83717","0.00985"
"370.38600","30.86569","0.01007"
"370.72800","30.89415","0.01035"
"371.07000","30.92267","0.01009"
"371.41200","30.95119","0.00986"
"371.75400","30.97959","0.00994"
"372.09600","31.00817","0.01020"
"372.43800","31.03669","0.00992"
"372.78000","31.06515","0.01058"
"373.12200","31.09373","0.00985"
"373.46400","31.12218","0.00999"
"373.80600","31.15065","0.01039"
"374.14800","31.17917","0.01029"
"374.49000","31.20762","0.00993"
"374.83200","31.23621","0.01050"
"375.17400","31.26472","0.01095"
"375.51600","31.29312","0.01064"
"375.85800","31.32170","0.01028"
"376.20000","31.35016","0.01063"
"376.54200","31.37862","0.01112"
"376.88400","31.40720","0.01067"
"377.22600","31.43566","0.01049"
"377.56800","31.46418","0.01048"
"377.91000","31.49264","0.01051"
"378.25200","31.52116","0.01081"
"378.59400","31.54968","0.01041"
"378.93600","31.57820","0.01135"
"379.27800","31.60666","0.01128"
"379.62000","31.63518","0.01144"
"379.96200","31.66370","0.01129"
"380.30400","31.69216","0.01110"
"380.64600","31.72068","0.01154"
"380.98800","31.74920","0.01155"
"381.33000","31.77766","0.01160"
"381.67200","31.80618","0.01096"
"382.01400","31.83464","0.01164"
"382.35600","31.86316","0.01177"
"382.69800","31.89174","0.01180"
"383.04000","31.92007","0.01180"
"383.38200","31.94866","0.01173"
"383.72400","31.97718","0.01167"
"384.06600","32.00563","0.01248"
"384.40800","32.03416","0.01175"
"384.75000","32.06268","0.01205"
"385.09200","32.09113","0.01231"
"385.43400","32.11971","0.01211"
"385.77600","32.14812","0.01249"
"386.11800","32.17669","0.01235"
"386.46000","32.20515","0.01248"
"386.80200","32.23362","0.01237"
"387.14400","32.26219","0.01280"
"387.48600","32.29071","0.01242"
"387.82800","32.31917","0.01295"
"388.17000","32.34769","0.01258"
"388.51200","32.37609","0.01326"
"388.85400","32.40461","0.01271"
"389.19600","32.43319","0.01276"
"389.53800","32.46165","0.01302"
"389.88000","32.49023","0.01336"
"390.22200","32.51869","0.01302"
"390.56400","32.54709","0.01311"
"390.90600","32.57567","0.01255"
"391.24800","32.60419","0.01308"
"391.59000","32.63265","0.01334"
"391.93200","32.66123","0.01343"
"392.27400","32.68963","0.01301"
"392.61600","32.71821","0.01261"
"392.95800","32.74667","0.01329"
"393.30000","32.77513","0.01298"
"393.64200","32.80371","0.01312"
"393.98400","32.83223","0.01329"
"394.32600","32.86063","0.01383"
"394.66800","32.88927","0.01424"
"395.01000","32.91766","0.01426"
"395.35200","32.94613","0.01370"
"395.69400","32.97470","0.01406"
"396.03600","33.00316","0.01417"
"396.37800","33.03162","0.01389"
"396.72000","33.06015","0.01386"
"397.06200","33.08866","0.01390"
"397.40400","33.11712","0.01436"
"397.74600","33.14565","0.01428"
"398.08800","33.17416","0.01474"
"398.43000","33.20268","0.01456"
"398.77200","33.23120","0.01454"
"399.11400","33.25966","0.01463"
"399.45600","33.28818","0.01467"
"399.79800","33.31664","0.01462"
"400.14000","33.34516","0.01547"
"400.48200","33.37368","0.01452"
"400.82400","33.40208","0.01520"
"401.16600","33.43066","0.01549"
"401.50800","33.45924","0.01514"
"401.85000","33.48764","0.01497"
"402.19200","33.51616","0.01518"
"402.53400","33.54474","0.01567"
"402.87600","33.57314","0.01544"
"403.21800","33.60166","0.01560"
"403.56000","33.63012","0.01472"
"403.90200","33.65864","0.01519"
"404.24400","33.68721","0.01561"
"404.58600","33.71562","0.01537"
"404.92800","33.74420","0.01545"
"405.27000","33.77266","0.01530"
"405.61200","33.80112","0.01524"
"405.95400","33.82970","0.01616"
"406.29600","33.85815","0.01552"
"406.63800","33.88662","0.01516"
"406.98000","33.91519","0.01541"
"407.32200","33.94365","0.01567"
"407.66400","33.97218","0.01514"
"408.00600","34.00069","0.01523"
"408.34800","34.02909","0.01540"
"408.69000","34.05773","0.01571"
"409.03200","34.08619","0.01522"
"409.37400","34.11465","0.01538"
"409.71600","34.14317","0.01516"
"410.05800","34.17163","0.01575"
"410.40000","34.20009","0.01444"
"410.74200","34.22867","0.01382"
"411.08400","34.25713","0.01270"
"411.42600","34.28565","0.01303"
"411.76800","34.31417","0.01259"
"412.11000","34.34263","0.01235"
"412.45200","34.37121","0.01330"
"412.79400","34.39967","0.01300"
"413.13600","34.42819","0.01339"
"413.47800","34.45665","0.01292"
"413.82000","34.48517","0.01336"
"414.16200","34.51369","0.01316"
"414.50400","34.54221","0.01340"
"414.84600","34.57067","0.01374"
"415.18800","34.59912","0.01330"
"415.53000","34.62765","0.01381"
"415.87200","34.65617","0.01350"
"416.21400","34.68468","0.01397"
"416.55600","34.71320","0.01403"
"416.89800","34.74166","0.01397"
"417.24000","34.77018","0.01395"
"417.58200","34.79870","0.01372"
"417.92400","34.82716","0.01438"
"418.26600","34.85568","0.01411"
"418.60800","34.88408","0.01411"
"418.95000","34.91267","0.01407"
"419.29200","34.94118","0.01431"
"419.63400","34.96958","0.01412"
"419.97600","34.99816","0.01396"
"420.31800","35.02668","0.01417"
"420.66000","35.05514","0.01448"
"421.00200","35.08366","0.01406"
"421.34400","35.11218","0.01453"
"421.68600","35.14064","0.01444"
"422.02800","35.16922","0.01420"
"422.37000","35.19768","0.01462"
"422.71200","35.22614","0.01421"
"423.05400","35.25471","0.01428"
"423.39600","35.28312","0.01414"
"423.73800","35.31170","0.01320"
"424.08000","35.34016","0.01393"
"424.42200","35.36862","0.01324"
"424.76400","35.39720","0.01383"
"425.10600","35.42566","0.01391"
"425.44800","35.45418","0.01370"
"425.79000","35.48270","0.01370"
"426.13200","35.51110","0.01405"
"426.47400","35.53968","0.01343"
"426.81600","35.56820","0.01437"
"427.15800","35.59665","0.01384"
"427.50000","35.62518","0.01431"
"427.84200","35.65364","0.01444"
"428.18400","35.68215","0.01403"
"428.52600","35.71067","0.01419"
"428.86800","35.73914","0.01468"
"429.21000","35.76771","0.01437"
"429.55200","35.79617","0.01464"
"429.89400","35.82463","0.01481"
"430.23600","35.85321","0.01492"
"430.57800","35.88167","0.01509"
"430.92000","35.91019","0.01457"
"431.26200","35.93865","0.01464"
"431.60400","35.96717","0.01501"
"431.94600","35.99563","0.01522"
"432.28800","36.02421","0.01527"
"432.63000","36.05267","0.01523"
"432.97200","36.08113","0.01551"
"433.31400","36.10965","0.01493"
"433.65600","36.13817","0.01578"
"433.99800","36.16663","0.01548"
"434.34000","36.19521","0.01582"
"434.68200","36.22367","0.01616"
"435.02400","36.25219","0.01557"
"435.36600","36.28065","0.01599"
"435.70800","36.30917","0.01587"
"436.05000","36.33768","0.01635"
"436.39200","36.36615","0.01611"
"436.73400","36.39467","0.01666"
"437.07600","36.42324","0.01627"
"437.41800","36.45164","0.01673"
"437.76000","36.48022","0.01704"
"438.10200","36.50868","0.01664"
"438.44400","36.53709","0.01524"
"438.78600","36.56567","0.01561"
"439.12800","36.59412","0.01444"
"439.47000","36.62270","0.01510"
"439.81200","36.65117","0.01447"
"440.15400","36.67968","0.01500"
"440.49600","36.70814","0.01444"
"440.83800","36.73672","0.01480"
"441.18000","36.76512","0.01460"
"441.52200","36.79376","0.01431"
"441.86400","36.82222","0.01455"
"442.20600","36.85062","0.01510"
"442.54800","36.87920","0.01483"
"442.89000","36.90772","0.01474"
"443.23200","36.93618","0.01485"
"443.57400","36.96470","0.01503"
"443.91600","36.99310","0.01502"
"444.25800","37.02174","0.01475"
"444.60000","37.05020","0.01533"
"444.94200","37.07860","0.01542"
"445.28400","37.10723","0.01552"
"445.62600","37.13570","0.01574"
"445.96800","37.16416","0.01511"
"446.31000","37.19274","0.01564"
"446.65200","37.22114","0.01610"
"446.99400","37.24966","0.01617"
"447.33600","37.27818","0.01589"
"447.67800","37.30664","0.01657"
"448.02000","37.33522","0.01600"
"448.36200","37.36367","0.01592"
"448.70400","37.39214","0.01639"
"449.04600","37.42065","0.01629"
"449.38800","37.44917","0.01635"
"449.73000","37.47770","0.01652"
"450.07200","37.50621","0.01593"
"450.41400","37.53473","0.01622"
"450.75600","37.56319","0.01706"
"451.09800","37.59171","0.01676"
"451.44000","37.62017","0.01725"
"451.78200","37.64869","0.01698"
"452.12400","37.67721","0.01709"
"452.46600","37.70561","0.01703"
"452.80800","37.73419","0.01660"
"453.15000","37.76265","0.01751"
"453.49200","37.79105","0.01741"
"453.83400","37.81969","0.01793"
"454.17600","37.84815","0.01731"
"454.51800","37.87661","0.01761"
"454.86000","37.90519","0.01789"
"455.20200","37.93365","0.01714"
"455.54400","37.96217","0.01676"
"455.88600","37.99075","0.01640"
"456.22800","38.01915","0.01683"
"456.57000","38.04767","0.01670"
"456.91200","38.07613","0.01686"
"457.25400","38.10464","0.01708"
"457.59600","38.13317","0.01744"
"457.93800","38.16169","0.01747"
"458.28000","38.19014","0.01817"
"458.62200","38.21867","0.01776"
"458.96400","38.24713","0.01804"
"459.30600","38.27564","0.01782"
"459.64800","38.30423","0.01809"
"459.99000","38.33256","0.01817"
"460.33200","38.36120","0.01830"
"460.67400","38.38972","0.01880"
"461.01600","38.41812","0.01840"
"461.35800","38.44670","0.01820"
"461.70000","38.47511","0.01859"
"462.04200","38.50362","0.01832"
"462.38400","38.53220","0.01848"
"462.72600","38.56060","0.01831"
"463.06800","38.58918","0.01894"
"463.41000","38.61770","0.01856"
"463.75200","38.64610","0.01854"
"464.09400","38.67468","0.01946"
"464.43600","38.70320","0.01896"
"464.77800","38.73166","0.01913"
"465.12000","38.76018","0.01909"
"465.46200","38.78864","0.01976"
"465.80400","38.81722","0.01916"
"466.14600","38.84568","0.01994"
"466.48800","38.87414","0.01989"
"466.83000","38.90266","0.02004"
"467.17200","38.93112","0.01962"
"467.51400","38.95964","0.01964"
"467.85600","38.98822","0.02041"
"468.19800","39.01667","0.01941"
"468.54000","39.04514","0.02020"
"468.88200","39.07372","0.02016"
"469.22400","39.10217","0.02057"
"469.56600","39.13063","0.01980"
"469.90800","39.15916","0.01640"
"470.25000","39.18767","0.01130"
"470.59200","39.21613","0.00961"
"470.93400","39.24471","0.01009"
"471.27600","39.27317","0.00855"
"471.61800","39.30169","0.01014"
"471.96000","39.33022","0.00861"
"472.30200","39.35867","0.00946"
"472.64400","39.38719","0.00896"
"472.98600","39.41571","0.00981"
"473.32800","39.44417","0.00909"
"473.67000","39.47269","0.00986"
"474.01200","39.50115","0.00945"
"474.35400","39.52961","0.01040"
"474.69600","39.55825","0.01016"
"475.03800","39.58665","0.01016"
"475.38000","39.61517","0.01023"
"475.72200","39.64363","0.01061"
"476.06400","39.67215","0.01031"
"476.40600","39.70073","0.01066"
"476.74800","39.72919","0.01042"
"477.09000","39.75764","0.01047"
"477.43200","39.78623","0.01044"
"477.77400","39.81456","0.01060"
"478.11600","39.84321","0.01128"
"478.45800","39.87173","0.01088"
"478.80000","39.90013","0.01090"
"479.14200","39.92870","0.01111"
"479.48400","39.95716","0.01112"
"479.82600","39.98563","0.01118"
"480.16800","40.01414","0.01165"
"480.51000","40.04261","0.01148"
"480.85200","40.07118","0.01129"
"481.19400","40.09964","0.01191"
"481.53600","40.12804","0.01108"
"481.87800","40.15675","0.01108"
"482.22000","40.18514","0.01131"
"482.56200","40.21366","0.01136"
"482.90400","40.24218","0.01185"
"483.24600","40.27070","0.01191"
"483.58800","40.29916","0.01189"
"483.93000","40.32768","0.01095"
"484.27200","40.35614","0.01128"
"484.61400","40.38466","0.01124"
"484.95600","40.41318","0.01151"
"485.29800","40.44164","0.01128"
"485.64000","40.47016","0.01188"
"485.98200","40.49868","0.01182"
"486.32400","40.52714","0.01159"
"486.66600","40.55572","0.01142"
"487.00800","40.58418","0.01159"
"487.35000","40.61263","0.01124"
"487.69200","40.64116","0.01154"
"488.03400","40.66968","0.01164"
"488.37600","40.69813","0.01077"
"488.71800","40.72672","0.01097"
"489.06000","40.75518","0.01077"
"489.40200","40.78370","0.01126"
"489.74400","40.81216","0.01087"
"490.08600","40.84061","0.01058"
"490.42800","40.86914","0.01146"
"490.77000","40.89771","0.01078"
"491.11200","40.92617","0.01037"
"491.45400","40.95469","0.01130"
"491.79600","40.98315","0.01047"
"492.13800","41.01161","0.01016"
"492.48000","41.04019","0.01058"
"492.82200","41.06865","0.01025"
"493.16400","41.09717","0.00994"
"493.50600","41.12575","0.01004"
"493.84800","41.15415","0.00959"
"494.19000","41.18273","0.00968"
"494.53200","41.21119","0.00942"
"494.87400","41.23965","0.00975"
"495.21600","41.26817","0.00958"
"495.55800","41.29657","0.01008"
"495.90000","41.32515","0.00975"
"496.24200","41.35367","0.00982"
"496.58400","41.38213","0.00967"
"496.92600","41.41077","0.01012"
"497.26800","41.43916","0.00978"
"497.61000","41.46762","0.00952"
"497.95200","41.49621","0.00906"
"498.29400","41.52466","0.00930"
"498.63600","41.55319","0.00918"
"498.97800","41.58171","0.00914"
"499.32000","41.61011","0.00893"
"499.66200","41.63869","0.00913"
"500.00400","41.66715","0.00914"
"500.34600","41.69561","0.00827"
"500.68800","41.72419","0.00830"
"501.03000","41.75265","0.00884"
"501.37200","41.78117","0.00862"
"501.71400","41.80968","0.00871"
"502.05600","41.83814","0.00859"
"502.39800","41.86666","0.00911"
"502.74000","41.89518","0.00932"
"503.08200","41.92358","0.00926"
"503.42400","41.95222","0.00884"
"503.76600","41.98068","0.00820"
"504.10800","42.00908","0.00817"
"504.45000","42.03772","0.00791"
"504.79200","42.06618","0.00846"
"505.13400","42.09464","0.00818"
"505.47600","42.12316","0.00848"
"505.81800","42.15168","0.00791"
"506.16000","42.18014","0.00796"
"506.50200","42.20866","0.00838"
"506.84400","42.23718","0.00860"
"507.18600","42.26569","0.00685"
"507.52800","42.29422","0.00794"
"507.87000","42.32262","0.00766"
"508.21200","42.35114","0.00819"
"508.55400","42.37965","0.00773"
"508.89600","42.40818","0.00806"
"509.23800","42.43670","0.00836"
"509.58000","42.46516","0.00832"
"509.92200","42.49362","0.00845"
"510.26400","42.52225","0.00842"
"510.56200","42.54695","0.00811"