File: Force_trajectories/170225_2/Specimen_RawData_1.csv
End date,"2/25/2017"
Specimen label,"1BG_5.2"
Maximum Load,"0.02768",N

Time,Extension,Load
(s),(mm),(N)
"0.00000","0.00000","-0.00047"
"0.13200","0.00640","0.00030"
"0.26400","0.02051","0.00008"
"0.39600","0.03318","0.00044"
"0.52800","0.04424","0.00023"
"0.66000","0.05513","0.00010"
"0.79200","0.06613","0.00099"
"0.92400","0.07719","0.00053"
"1.05600","0.08813","0.00071"
"1.18800","0.09913","0.00082"
"1.32000","0.11013","0.00042"
"1.45200","0.12119","0.00075"
"1.58400","0.13219","0.00078"
"1.71600","0.14314","0.00050"
"1.84800","0.15414","0.00026"
"1.98000","0.16520","0.00087"
"2.11200","0.17614","0.00050"
"2.24400","0.18714","0.00041"
"2.37600","0.19808","0.00083"
"2.50800","0.20914","0.00098"
"2.64000","0.22020","0.00053"
"2.77200","0.23115","0.00084"
"2.90400","0.24215","0.00068"
"3.03600","0.25321","0.00095"
"3.16800","0.26421","0.00072"
"3.30000","0.27515","0.00093"
"3.43200","0.28609","0.00085"
"3.56400","0.29715","0.00085"
"3.69600","0.30816","0.00096"
"3.82800","0.31916","0.00093"
"3.96000","0.33010","0.00071"
"4.09200","0.34116","0.00092"
"4.22400","0.35216","0.00123"
"4.35600","0.36310","0.00074"
"4.48800","0.37410","0.00062"
"4.62000","0.38516","0.00066"
"4.75200","0.39617","0.00113"
"4.88400","0.40717","0.00069"
"5.01600","0.41811","0.00039"
"5.14800","0.42917","0.00037"
"5.28000","0.44017","0.00071"
"5.41200","0.45117","0.00105"
"5.54400","0.46211","0.00133"
"5.67600","0.47311","0.00109"
"5.80800","0.48412","0.00079"
"5.94000","0.49512","0.00103"
"6.07200","0.50612","0.00111"
"6.20400","0.51712","0.00134"
"6.33600","0.52812","0.00119"
"6.46800","0.53912","0.00071"
"6.60000","0.55012","0.00068"
"6.73200","0.56112","0.00111"
"6.86400","0.57219","0.00097"
"6.99600","0.58313","0.00107"
"7.12800","0.59407","0.00130"
"7.26000","0.60513","0.00069"
"7.39200","0.61613","0.00107"
"7.52400","0.62713","0.00151"
"7.65600","0.63813","0.00095"
"7.78800","0.64913","0.00135"
"7.92000","0.66014","0.00102"
"8.05200","0.67114","0.00172"
"8.18400","0.68208","0.00175"
"8.31600","0.69320","0.00128"
"8.44800","0.70420","0.00135"
"8.58000","0.71514","0.00142"
"8.71200","0.72608","0.00159"
"8.84400","0.73715","0.00109"
"8.97600","0.74815","0.00110"
"9.10800","0.75915","0.00115"
"9.24000","0.77009","0.00136"
"9.37200","0.78109","0.00122"
"9.50400","0.79215","0.00134"
"9.63600","0.80315","0.00124"
"9.76800","0.81409","0.00121"
"9.90000","0.82516","0.00084"
"10.03200","0.83616","0.00145"
"10.16400","0.84716","0.00087"
"10.29600","0.85810","0.00126"
"10.42800","0.86910","0.00114"
"10.56000","0.88010","0.00171"
"10.69200","0.89116","0.00110"
"10.82400","0.90210","0.00130"
"10.95600","0.91305","0.00185"
"11.08800","0.92423","0.00176"
"11.22000","0.93517","0.00141"
"11.35200","0.94617","0.00104"
"11.48400","0.95711","0.00048"
"11.61600","0.96817","0.00187"
"11.74800","0.97917","0.00191"
"11.88000","0.99017","0.00165"
"12.01200","1.00112","0.00152"
"12.14400","1.01212","0.00124"
"12.27600","1.02312","0.00142"
"12.40800","1.03412","0.00100"
"12.54000","1.04506","0.00149"
"12.67200","1.05612","0.00131"
"12.80400","1.06712","0.00171"
"12.93600","1.07812","0.00096"
"13.06800","1.08913","0.00136"
"13.20000","1.10019","0.00122"
"13.33200","1.11119","0.00139"
"13.46400","1.12219","0.00150"
"13.59600","1.13313","0.00112"
"13.72800","1.14413","0.00141"
"13.86000","1.15513","0.00126"
"13.99200","1.16614","0.00096"
"14.12400","1.17714","0.00178"
"14.25600","1.18814","0.00141"
"14.38800","1.19920","0.00165"
"14.52000","1.21014","0.00147"
"14.65200","1.22114","0.00188"
"14.78400","1.23214","0.00167"
"14.91600","1.24314","0.00143"
"15.04800","1.25415","0.00118"
"15.18000","1.26509","0.00111"
"15.31200","1.27615","0.00128"
"15.44400","1.28715","0.00152"
"15.57600","1.29815","0.00134"
"15.70800","1.30909","0.00167"
"15.84000","1.32015","0.00178"
"15.97200","1.33115","0.00115"
"16.10400","1.34216","0.00153"
"16.23600","1.35310","0.00147"
"16.36800","1.36410","0.00103"
"16.50000","1.37522","0.00174"
"16.63200","1.38610","0.00119"
"16.76400","1.39710","0.00170"
"16.89600","1.40810","0.00144"
"17.02800","1.41916","0.00140"
"17.16000","1.43011","0.00138"
"17.29200","1.44111","0.00151"
"17.42400","1.45205","0.00183"
"17.55600","1.46317","0.00173"
"17.68800","1.47417","0.00120"
"17.82000","1.48511","0.00113"
"17.95200","1.49611","0.00154"
"18.08400","1.50717","0.00215"
"18.21600","1.51818","0.00163"
"18.34800","1.52918","0.00150"
"18.48000","1.54018","0.00189"
"18.61200","1.55118","0.00168"
"18.74400","1.56218","0.00155"
"18.87600","1.57312","0.00157"
"19.00800","1.58406","0.00216"
"19.14000","1.59518","0.00103"
"19.27200","1.60619","0.00176"
"19.40400","1.61713","0.00113"
"19.53600","1.62807","0.00163"
"19.66800","1.63913","0.00203"
"19.80000","1.65013","0.00175"
"19.93200","1.66119","0.00207"
"20.06400","1.67213","0.00157"
"20.19600","1.68314","0.00091"
"20.32800","1.69414","0.00104"
"20.46000","1.70514","0.00149"
"20.59200","1.71608","0.00112"
"20.72400","1.72714","0.00188"
"20.85600","1.73808","0.00129"
"20.98800","1.74914","0.00176"
"21.12000","1.76008","0.00176"
"21.25200","1.77115","0.00201"
"21.38400","1.78215","0.00171"
"21.51600","1.79321","0.00169"
"21.64800","1.80415","0.00162"
"21.78000","1.81515","0.00246"
"21.91200","1.82615","0.00195"
"22.04400","1.83715","0.00214"
"22.17600","1.84809","0.00177"
"22.30800","1.85910","0.00090"
"22.44000","1.87016","0.00150"
"22.57200","1.88116","0.00150"
"22.70400","1.89210","0.00200"
"22.83600","1.90310","0.00197"
"22.96800","1.91416","0.00139"
"23.10000","1.92510","0.00209"
"23.23200","1.93610","0.00141"
"23.36400","1.94711","0.00190"
"23.49600","1.95817","0.00167"
"23.62800","1.96911","0.00183"
"23.76000","1.98011","0.00262"
"23.89200","1.99111","0.00191"
"24.02400","2.00211","0.00193"
"24.15600","2.01317","0.00211"
"24.28800","2.02417","0.00207"
"24.42000","2.03512","0.00162"
"24.55200","2.04618","0.00168"
"24.68400","2.05718","0.00191"
"24.81600","2.06818","0.00181"
"24.94800","2.07912","0.00213"
"25.08000","2.09018","0.00175"
"25.21200","2.10112","0.00206"
"25.34400","2.11207","0.00179"
"25.47600","2.12307","0.00179"
"25.60800","2.13413","0.00190"
"25.74000","2.14513","0.00252"
"25.87200","2.15613","0.00195"
"26.00400","2.16707","0.00181"
"26.13600","2.17813","0.00222"
"26.26800","2.18919","0.00154"
"26.40000","2.20014","0.00205"
"26.53200","2.21108","0.00212"
"26.66400","2.22214","0.00247"
"26.79600","2.23320","0.00260"
"26.92800","2.24414","0.00243"
"27.06000","2.25508","0.00210"
"27.19200","2.26614","0.00279"
"27.32400","2.27714","0.00200"
"27.45600","2.28815","0.00231"
"27.58800","2.29909","0.00240"
"27.72000","2.31009","0.00202"
"27.85200","2.32115","0.00218"
"27.98400","2.33215","0.00185"
"28.11600","2.34309","0.00250"
"28.24800","2.35415","0.00216"
"28.38000","2.36521","0.00246"
"28.51200","2.37616","0.00160"
"28.64400","2.38710","0.00142"
"28.77600","2.39816","0.00233"
"28.90800","2.40916","0.00220"
"29.04000","2.42016","0.00290"
"29.17200","2.43110","0.00228"
"29.30400","2.44210","0.00218"
"29.43600","2.45310","0.00186"
"29.56800","2.46417","0.00188"
"29.70000","2.47511","0.00249"
"29.83200","2.48617","0.00235"
"29.96400","2.49717","0.00261"
"30.09600","2.50811","0.00255"
"30.22800","2.51911","0.00168"
"30.36000","2.53011","0.00232"
"30.49200","2.54117","0.00214"
"30.62400","2.55212","0.00246"
"30.75600","2.56312","0.00180"
"30.88800","2.57412","0.00230"
"31.02000","2.58518","0.00201"
"31.15200","2.59618","0.00238"
"31.28400","2.60712","0.00247"
"31.41600","2.61818","0.00230"
"31.54800","2.62919","0.00260"
"31.68000","2.64013","0.00220"
"31.81200","2.65113","0.00249"
"31.94400","2.66207","0.00237"
"32.07600","2.67313","0.00273"
"32.20800","2.68413","0.00253"
"32.34000","2.69507","0.00211"
"32.47200","2.70613","0.00209"
"32.60400","2.71714","0.00164"
"32.73600","2.72814","0.00191"
"32.86800","2.73914","0.00215"
"33.00000","2.75008","0.00230"
"33.13200","2.76120","0.00254"
"33.26400","2.77220","0.00248"
"33.39600","2.78320","0.00239"
"33.52800","2.79408","0.00265"
"33.66000","2.80515","0.00236"
"33.79200","2.81615","0.00213"
"33.92400","2.82709","0.00227"
"34.05600","2.83809","0.00249"
"34.18800","2.84915","0.00229"
"34.32000","2.86015","0.00234"
"34.45200","2.87115","0.00195"
"34.58400","2.88209","0.00242"
"34.71600","2.89316","0.00200"
"34.84800","2.90416","0.00233"
"34.98000","2.91522","0.00246"
"35.11200","2.92610","0.00235"
"35.24400","2.93716","0.00234"
"35.37600","2.94816","0.00234"
"35.50800","2.95910","0.00218"
"35.64000","2.97010","0.00263"
"35.77200","2.98111","0.00250"
"35.90400","2.99217","0.00253"
"36.03600","3.00317","0.00282"
"36.16800","3.01411","0.00274"
"36.30000","3.02517","0.00247"
"36.43200","3.03617","0.00268"
"36.56400","3.04717","0.00229"
"36.69600","3.05812","0.00266"
"36.82800","3.06912","0.00260"
"36.96000","3.08012","0.00210"
"37.09200","3.09112","0.00294"
"37.22400","3.10212","0.00293"
"37.35600","3.11306","0.00216"
"37.48800","3.12412","0.00301"
"37.62000","3.13518","0.00266"
"37.75200","3.14613","0.00328"
"37.88400","3.15713","0.00236"
"38.01600","3.16819","0.00315"
"38.14800","3.17919","0.00226"
"38.28000","3.19013","0.00287"
"38.41200","3.20107","0.00234"
"38.54400","3.21213","0.00308"
"38.67600","3.22313","0.00329"
"38.80800","3.23414","0.00288"
"38.94000","3.24508","0.00330"
"39.07200","3.25614","0.00248"
"39.20400","3.26714","0.00288"
"39.33600","3.27820","0.00366"
"39.46800","3.28914","0.00295"
"39.60000","3.30014","0.00353"
"39.73200","3.31120","0.00248"
"39.86400","3.32215","0.00291"
"39.99600","3.33309","0.00317"
"40.12800","3.34415","0.00294"
"40.26000","3.35515","0.00248"
"40.39200","3.36609","0.00334"
"40.52400","3.37709","0.00351"
"40.65600","3.38815","0.00264"
"40.78800","3.39915","0.00380"
"40.92000","3.41010","0.00321"
"41.05200","3.42116","0.00265"
"41.18400","3.43216","0.00323"
"41.31600","3.44316","0.00250"
"41.44800","3.45416","0.00318"
"41.58000","3.46516","0.00327"
"41.71200","3.47616","0.00309"
"41.84400","3.48710","0.00308"
"41.97600","3.49817","0.00333"
"42.10800","3.50905","0.00323"
"42.24000","3.52017","0.00289"
"42.37200","3.53117","0.00296"
"42.50400","3.54211","0.00345"
"42.63600","3.55311","0.00319"
"42.76800","3.56417","0.00375"
"42.90000","3.57518","0.00360"
"43.03200","3.58624","0.00350"
"43.16400","3.59712","0.00351"
"43.29600","3.60812","0.00342"
"43.42800","3.61918","0.00328"
"43.56000","3.63018","0.00309"
"43.69200","3.64112","0.00306"
"43.82400","3.65212","0.00376"
"43.95600","3.66319","0.00402"
"44.08800","3.67419","0.00322"
"44.22000","3.68513","0.00362"
"44.35200","3.69613","0.00382"
"44.48400","3.70719","0.00379"
"44.61600","3.71819","0.00413"
"44.74800","3.72913","0.00359"
"44.88000","3.74013","0.00381"
"45.01200","3.75114","0.00381"
"45.14400","3.76220","0.00344"
"45.27600","3.77308","0.00322"
"45.40800","3.78408","0.00363"
"45.54000","3.79514","0.00315"
"45.67200","3.80614","0.00377"
"45.80400","3.81708","0.00369"
"45.93600","3.82808","0.00364"
"46.06800","3.83915","0.00350"
"46.20000","3.85021","0.00376"
"46.33200","3.86121","0.00394"
"46.46400","3.87215","0.00381"
"46.59600","3.88315","0.00420"
"46.72800","3.89415","0.00373"
"46.86000","3.90509","0.00417"
"46.99200","3.91603","0.00373"
"47.12400","3.92716","0.00373"
"47.25600","3.93816","0.00388"
"47.38800","3.94916","0.00493"
"47.52000","3.96010","0.00355"
"47.65200","3.97116","0.00400"
"47.78400","3.98210","0.00339"
"47.91600","3.99316","0.00416"
"48.04800","4.00411","0.00391"
"48.18000","4.01511","0.00438"
"48.31200","4.02617","0.00411"
"48.44400","4.03711","0.00439"
"48.57600","4.04811","0.00361"
"48.70800","4.05911","0.00435"
"48.84000","4.07017","0.00403"
"48.97200","4.08111","0.00428"
"49.10400","4.09211","0.00420"
"49.23600","4.10312","0.00470"
"49.36800","4.11418","0.00404"
"49.50000","4.12512","0.00435"
"49.63200","4.13612","0.00416"
"49.76400","4.14718","0.00460"
"49.89600","4.15818","0.00469"
"50.02800","4.16918","0.00399"
"50.16000","4.18013","0.00419"
"50.29200","4.19113","0.00348"
"50.42400","4.20219","0.00441"
"50.55600","4.21313","0.00470"
"50.68800","4.22407","0.00411"
"50.82000","4.23507","0.00457"
"50.95200","4.24619","0.00427"
"51.08400","4.25713","0.00452"
"51.21600","4.26808","0.00439"
"51.34800","4.27908","0.00453"
"51.48000","4.29020","0.00404"
"51.61200","4.30120","0.00499"
"51.74400","4.31214","0.00479"
"51.87600","4.32308","0.00427"
"52.00800","4.33414","0.00475"
"52.14000","4.34514","0.00496"
"52.27200","4.35615","0.00498"
"52.40400","4.36709","0.00490"
"52.53600","4.37821","0.00420"
"52.66800","4.38921","0.00460"
"52.80000","4.40015","0.00493"
"52.93200","4.41115","0.00435"
"53.06400","4.42215","0.00481"
"53.19600","4.43315","0.00408"
"53.32800","4.44410","0.00451"
"53.46000","4.45510","0.00446"
"53.59200","4.46610","0.00418"
"53.72400","4.47710","0.00466"
"53.85600","4.48810","0.00428"
"53.98800","4.49904","0.00502"
"54.12000","4.51016","0.00482"
"54.25200","4.52116","0.00489"
"54.38400","4.53217","0.00527"
"54.51600","4.54311","0.00466"
"54.64800","4.55417","0.00481"
"54.78000","4.56517","0.00458"
"54.91200","4.57617","0.00484"
"55.04400","4.58705","0.00493"
"55.17600","4.59811","0.00470"
"55.30800","4.60912","0.00574"
"55.44000","4.62018","0.00453"
"55.57200","4.63112","0.00457"
"55.70400","4.64218","0.00524"
"55.83600","4.65318","0.00524"
"55.96800","4.66418","0.00530"
"56.10000","4.67512","0.00460"
"56.23200","4.68618","0.00496"
"56.36400","4.69719","0.00493"
"56.49600","4.70813","0.00491"
"56.62800","4.71919","0.00543"
"56.76000","4.73013","0.00475"
"56.89200","4.74119","0.00554"
"57.02400","4.75213","0.00515"
"57.15600","4.76313","0.00480"
"57.28800","4.77413","0.00541"
"57.42000","4.78520","0.00499"
"57.55200","4.79614","0.00527"
"57.68400","4.80714","0.00539"
"57.81600","4.81814","0.00561"
"57.94800","4.82920","0.00534"
"58.08000","4.84014","0.00507"
"58.21200","4.85108","0.00503"
"58.34400","4.86208","0.00513"
"58.47600","4.87315","0.00530"
"58.60800","4.88415","0.00492"
"58.74000","4.89503","0.00540"
"58.87200","4.90615","0.00567"
"59.00400","4.91721","0.00570"
"59.13600","4.92815","0.00502"
"59.26800","4.93909","0.00543"
"59.40000","4.95010","0.00607"
"59.53200","4.96122","0.00590"
"59.66400","4.97216","0.00550"
"59.79600","4.98310","0.00535"
"59.92800","4.99404","0.00623"
"60.06000","5.00516","0.00592"
"60.19200","5.01616","0.00561"
"60.32400","5.02710","0.00613"
"60.45600","5.03811","0.00546"
"60.58800","5.04917","0.00545"
"60.72000","5.06017","0.00589"
"60.85200","5.07111","0.00573"
"60.98400","5.08211","0.00609"
"61.11600","5.09317","0.00580"
"61.24800","5.10417","0.00587"
"61.38000","5.11517","0.00617"
"61.51200","5.12612","0.00600"
"61.64400","5.13712","0.00581"
"61.77600","5.14818","0.00597"
"61.90800","5.15912","0.00577"
"62.04000","5.17006","0.00615"
"62.17200","5.18112","0.00576"
"62.30400","5.19218","0.00568"
"62.43600","5.20318","0.00603"
"62.56800","5.21413","0.00573"
"62.70000","5.22513","0.00572"
"62.83200","5.23613","0.00594"
"62.96400","5.24713","0.00578"
"63.09600","5.25807","0.00614"
"63.22800","5.26913","0.00543"
"63.36000","5.28013","0.00586"
"63.49200","5.29119","0.00630"
"63.62400","5.30208","0.00611"
"63.75600","5.31314","0.00625"
"63.88800","5.32414","0.00647"
"64.02000","5.33514","0.00605"
"64.15200","5.34608","0.00610"
"64.28400","5.35714","0.00606"
"64.41600","5.36820","0.00641"
"64.54800","5.37915","0.00588"
"64.68000","5.39015","0.00571"
"64.81200","5.40115","0.00646"
"64.94400","5.41215","0.00617"
"65.07600","5.42309","0.00652"
"65.20800","5.43409","0.00630"
"65.34000","5.44509","0.00565"
"65.47200","5.45615","0.00626"
"65.60400","5.46715","0.00663"
"65.73600","5.47816","0.00560"
"65.86800","5.48916","0.00589"
"66.00000","5.50016","0.00645"
"66.13200","5.51116","0.00585"
"66.26400","5.52216","0.00603"
"66.39600","5.53310","0.00583"
"66.52800","5.54410","0.00554"
"66.66000","5.55516","0.00571"
"66.79200","5.56611","0.00605"
"66.92400","5.57711","0.00642"
"67.05600","5.58817","0.00598"
"67.18800","5.59917","0.00595"
"67.32000","5.61011","0.00627"
"67.45200","5.62111","0.00591"
"67.58400","5.63217","0.00574"
"67.71600","5.64318","0.00564"
"67.84800","5.65418","0.00635"
"67.98000","5.66512","0.00622"
"68.11200","5.67618","0.00610"
"68.24400","5.68712","0.00588"
"68.37600","5.69812","0.00573"
"68.50800","5.70912","0.00600"
"68.64000","5.72018","0.00636"
"68.77200","5.73118","0.00593"
"68.90400","5.74213","0.00664"
"69.03600","5.75313","0.00597"
"69.16800","5.76419","0.00639"
"69.30000","5.77519","0.00611"
"69.43200","5.78619","0.00678"
"69.56400","5.79713","0.00627"
"69.69600","5.80814","0.00659"
"69.82800","5.81914","0.00727"
"69.96000","5.83014","0.00659"
"70.09200","5.84108","0.00645"
"70.22400","5.85214","0.00606"
"70.35600","5.86314","0.00601"
"70.48800","5.87414","0.00622"
"70.62000","5.88508","0.00640"
"70.75200","5.89608","0.00582"
"70.88400","5.90715","0.00675"
"71.01600","5.91815","0.00608"
"71.14800","5.92909","0.00567"
"71.28000","5.94015","0.00625"
"71.41200","5.95115","0.00724"
"71.54400","5.96215","0.00579"
"71.67600","5.97315","0.00620"
"71.80800","5.98416","0.00628"
"71.94000","5.99516","0.00636"
"72.07200","6.00616","0.00620"
"72.20400","6.01710","0.00636"
"72.33600","6.02816","0.00700"
"72.46800","6.03916","0.00648"
"72.60000","6.05016","0.00694"
"72.73200","6.06110","0.00481"
"72.86400","6.07211","0.00504"
"72.99600","6.08317","0.00569"
"73.12800","6.09411","0.00580"
"73.26000","6.10511","0.00525"
"73.39200","6.11605","0.00508"
"73.52400","6.12711","0.00565"
"73.65600","6.13811","0.00538"
"73.78800","6.14911","0.00562"
"73.92000","6.16012","0.00564"
"74.05200","6.17112","0.00552"
"74.18400","6.18218","0.00610"
"74.31600","6.19318","0.00568"
"74.44800","6.20418","0.00537"
"74.58000","6.21518","0.00563"
"74.71200","6.22612","0.00555"
"74.84400","6.23712","0.00520"
"74.97600","6.24807","0.00519"
"75.10800","6.25913","0.00485"
"75.24000","6.27013","0.00525"
"75.37200","6.28113","0.00495"
"75.50400","6.29213","0.00524"
"75.63600","6.30313","0.00469"
"75.76800","6.31413","0.00485"
"75.90000","6.32514","0.00498"
"76.03200","6.33608","0.00514"
"76.16400","6.34714","0.00484"
"76.29600","6.35814","0.00484"
"76.42800","6.36914","0.00492"
"76.56000","6.38008","0.00444"
"76.69200","6.39114","0.00492"
"76.82400","6.40214","0.00494"
"76.95600","6.41315","0.00491"
"77.08800","6.42409","0.00465"
"77.22000","6.43515","0.00499"
"77.35200","6.44615","0.00520"
"77.48400","6.45721","0.00492"
"77.61600","6.46815","0.00534"
"77.74800","6.47915","0.00488"
"77.88000","6.49021","0.00531"
"78.01200","6.50116","0.00531"
"78.14400","6.51210","0.00505"
"78.27600","6.52310","0.00426"
"78.40800","6.53422","0.00515"
"78.54000","6.54516","0.00440"
"78.67200","6.55610","0.00511"
"78.80400","6.56710","0.00485"
"78.93600","6.57816","0.00541"
"79.06800","6.58917","0.00483"
"79.20000","6.60011","0.00558"
"79.33200","6.61117","0.00524"
"79.46400","6.62217","0.00500"
"79.59600","6.63317","0.00471"
"79.72800","6.64411","0.00537"
"79.86000","6.65511","0.00594"
"79.99200","6.66617","0.00500"
"80.12400","6.67718","0.00533"
"80.25600","6.68812","0.00476"
"80.38800","6.69912","0.00547"
"80.52000","6.71018","0.00518"
"80.65200","6.72124","0.00531"
"80.78400","6.73212","0.00534"
"80.91600","6.74312","0.00571"
"81.04800","6.75418","0.00460"
"81.18000","6.76513","0.00518"
"81.31200","6.77613","0.00566"
"81.44400","6.78707","0.00550"
"81.57600","6.79813","0.00543"
"81.70800","6.80913","0.00510"
"81.84000","6.82013","0.00517"
"81.97200","6.83107","0.00567"
"82.10400","6.84213","0.00466"
"82.23600","6.85314","0.00552"
"82.36800","6.86414","0.00559"
"82.50000","6.87514","0.00589"
"82.63200","6.88620","0.00566"
"82.76400","6.89714","0.00543"
"82.89600","6.90814","0.00574"
"83.02800","6.91908","0.00543"
"83.16000","6.93015","0.00465"
"83.29200","6.94115","0.00450"
"83.42400","6.95215","0.00510"
"83.55600","6.96309","0.00469"
"83.68800","6.97415","0.00446"
"83.82000","6.98515","0.00443"
"83.95200","6.99615","0.00474"
"84.08400","7.00709","0.00501"
"84.21600","7.01810","0.00413"
"84.34800","7.02916","0.00503"
"84.48000","7.04016","0.00476"
"84.61200","7.05110","0.00435"
"84.74400","7.06216","0.00494"
"84.87600","7.07316","0.00512"
"85.00800","7.08416","0.00521"
"85.14000","7.09510","0.00482"
"85.27200","7.10617","0.00516"
"85.40400","7.11717","0.00517"
"85.53600","7.12811","0.00479"
"85.66800","7.13911","0.00498"
"85.80000","7.15017","0.00488"
"85.93200","7.16117","0.00533"
"86.06400","7.17217","0.00448"
"86.19600","7.18311","0.00496"
"86.32800","7.19412","0.00627"
"86.46000","7.20518","0.00568"
"86.59200","7.21612","0.00482"
"86.72400","7.22712","0.00480"
"86.85600","7.23806","0.00516"
"86.98800","7.24918","0.00531"
"87.12000","7.26012","0.00551"
"87.25200","7.27112","0.00592"
"87.38400","7.28213","0.00595"
"87.51600","7.29313","0.00540"
"87.64800","7.30419","0.00547"
"87.78000","7.31513","0.00575"
"87.91200","7.32613","0.00528"
"88.04400","7.33713","0.00550"
"88.17600","7.34819","0.00587"
"88.30800","7.35914","0.00557"
"88.44000","7.37008","0.00521"
"88.57200","7.38114","0.00531"
"88.70400","7.39220","0.00516"
"88.83600","7.40314","0.00543"
"88.96800","7.41408","0.00546"
"89.10000","7.42514","0.00606"
"89.23200","7.43614","0.00552"
"89.36400","7.44714","0.00538"
"89.49600","7.45809","0.00600"
"89.62800","7.46915","0.00592"
"89.76000","7.48009","0.00529"
"89.89200","7.49109","0.00558"
"90.02400","7.50203","0.00578"
"90.15600","7.51315","0.00557"
"90.28800","7.52415","0.00588"
"90.42000","7.53516","0.00581"
"90.55200","7.54610","0.00600"
"90.68400","7.55716","0.00564"
"90.81600","7.56816","0.00589"
"90.94800","7.57916","0.00563"
"91.08000","7.59016","0.00534"
"91.21200","7.60116","0.00580"
"91.34400","7.61222","0.00502"
"91.47600","7.62311","0.00589"
"91.60800","7.63417","0.00635"
"91.74000","7.64517","0.00547"
"91.87200","7.65617","0.00532"
"92.00400","7.66711","0.00570"
"92.13600","7.67811","0.00580"
"92.26800","7.68911","0.00536"
"92.40000","7.70018","0.00617"
"92.53200","7.71118","0.00606"
"92.66400","7.72212","0.00619"
"92.79600","7.73312","0.00606"
"92.92800","7.74412","0.00576"
"93.06000","7.75518","0.00625"
"93.19200","7.76612","0.00584"
"93.32400","7.77712","0.00592"
"93.45600","7.78819","0.00580"
"93.58800","7.79913","0.00622"
"93.72000","7.81013","0.00636"
"93.85200","7.82113","0.00605"
"93.98400","7.83219","0.00602"
"94.11600","7.84319","0.00656"
"94.24800","7.85413","0.00682"
"94.38000","7.86513","0.00630"
"94.51200","7.87613","0.00674"
"94.64400","7.88714","0.00570"
"94.77600","7.89808","0.00612"
"94.90800","7.90908","0.00604"
"95.04000","7.92020","0.00601"
"95.17200","7.93120","0.00584"
"95.30400","7.94214","0.00654"
"95.43600","7.95308","0.00609"
"95.56800","7.96420","0.00639"
"95.70000","7.97521","0.00660"
"95.83200","7.98615","0.00581"
"95.96400","7.99715","0.00664"
"96.09600","8.00815","0.00662"
"96.22800","8.01915","0.00639"
"96.36000","8.03015","0.00705"
"96.49200","8.04109","0.00656"
"96.62400","8.05216","0.00594"
"96.75600","8.06316","0.00622"
"96.88800","8.07410","0.00648"
"97.02000","8.08510","0.00655"
"97.15200","8.09616","0.00648"
"97.28400","8.10716","0.00657"
"97.41600","8.11816","0.00659"
"97.54800","8.12910","0.00651"
"97.68000","8.14017","0.00667"
"97.81200","8.15117","0.00669"
"97.94400","8.16211","0.00684"
"98.07600","8.17311","0.00652"
"98.20800","8.18411","0.00695"
"98.34000","8.19511","0.00691"
"98.47200","8.20617","0.00653"
"98.60400","8.21705","0.00572"
"98.73600","8.22812","0.00693"
"98.86800","8.23918","0.00657"
"99.00000","8.25018","0.00697"
"99.13200","8.26112","0.00637"
"99.26400","8.27212","0.00687"
"99.39600","8.28312","0.00674"
"99.52800","8.29406","0.00635"
"99.66000","8.30513","0.00643"
"99.79200","8.31607","0.00677"
"99.92400","8.32713","0.00614"
"100.05600","8.33813","0.00677"
"100.18800","8.34913","0.00675"
"100.32000","8.36007","0.00682"
"100.45200","8.37119","0.00706"
"100.58400","8.38213","0.00692"
"100.71600","8.39314","0.00691"
"100.84800","8.40414","0.00701"
"100.98000","8.41514","0.00695"
"101.11200","8.42614","0.00670"
"101.24400","8.43708","0.00638"
"101.37600","8.44808","0.00679"
"101.50800","8.45914","0.00703"
"101.64000","8.47014","0.00708"
"101.77200","8.48108","0.00721"
"101.90400","8.49215","0.00693"
"102.03600","8.50321","0.00685"
"102.16800","8.51421","0.00750"
"102.30000","8.52515","0.00720"
"102.43200","8.53615","0.00722"
"102.56400","8.54721","0.00654"
"102.69600","8.55815","0.00738"
"102.82800","8.56910","0.00707"
"102.96000","8.58004","0.00692"
"103.09200","8.59116","0.00705"
"103.22400","8.60216","0.00736"
"103.35600","8.61316","0.00737"
"103.48800","8.62410","0.00713"
"103.62000","8.63516","0.00726"
"103.75200","8.64622","0.00719"
"103.88400","8.65717","0.00720"
"104.01600","8.66811","0.00758"
"104.14800","8.67911","0.00714"
"104.28000","8.69011","0.00748"
"104.41200","8.70111","0.00615"
"104.54400","8.71211","0.00659"
"104.67600","8.72317","0.00634"
"104.80800","8.73411","0.00601"
"104.94000","8.74512","0.00683"
"105.07200","8.75612","0.00657"
"105.20400","8.76712","0.00677"
"105.33600","8.77812","0.00665"
"105.46800","8.78918","0.00638"
"105.60000","8.80012","0.00673"
"105.73200","8.81118","0.00636"
"105.86400","8.82218","0.00720"
"105.99600","8.83313","0.00702"
"106.12800","8.84407","0.00644"
"106.26000","8.85513","0.00640"
"106.39200","8.86613","0.00690"
"106.52400","8.87719","0.00665"
"106.65600","8.88813","0.00658"
"106.78800","8.89913","0.00699"
"106.92000","8.91014","0.00670"
"107.05200","8.92114","0.00589"
"107.18400","8.93208","0.00617"
"107.31600","8.94314","0.00736"
"107.44800","8.95420","0.00698"
"107.58000","8.96514","0.00669"
"107.71200","8.97614","0.00686"
"107.84400","8.98708","0.00788"
"107.97600","8.99815","0.00753"
"108.10800","9.00915","0.00787"
"108.24000","9.02015","0.00751"
"108.37200","9.03109","0.00749"
"108.50400","9.04215","0.00597"
"108.63600","9.05315","0.00695"
"108.76800","9.06415","0.00934"
"108.90000","9.07515","0.00978"
"109.03200","9.08622","0.01212"
"109.16400","9.09716","0.00327"
"109.29600","9.10810","0.00482"
"109.42800","9.11910","0.00391"
"109.56000","9.13010","0.00467"
"109.69200","9.14116","0.00587"
"109.82400","9.15204","0.00460"
"109.95600","9.16311","0.00336"
"110.08800","9.17417","0.00371"
"110.22000","9.18517","0.00390"
"110.35200","9.19617","0.00414"
"110.48400","9.20717","0.00458"
"110.61600","9.21823","0.00506"
"110.74800","9.22917","0.00535"
"110.88000","9.24017","0.00469"
"111.01200","9.25106","0.00301"
"111.14400","9.26218","0.00287"
"111.27600","9.27312","0.00476"
"111.40800","9.28412","0.00473"
"111.54000","9.29512","0.00479"
"111.67200","9.30612","0.00570"
"111.80400","9.31718","0.00532"
"111.93600","9.32818","0.00587"
"112.06800","9.33912","0.00405"
"112.20000","9.35013","0.00374"
"112.33200","9.36113","0.00541"
"112.46400","9.37213","0.00468"
"112.59600","9.38307","0.00569"
"112.72800","9.39413","0.00548"
"112.86000","9.40519","0.00518"
"112.99200","9.41613","0.00473"
"113.12400","9.42713","0.00411"
"113.25600","9.43814","0.00462"
"113.38800","9.44920","0.00500"
"113.52000","9.46020","0.00500"
"113.65200","9.47108","0.00507"
"113.78400","9.48214","0.00453"
"113.91600","9.49320","0.00657"
"114.04800","9.50420","0.02768"
"114.18000","9.51509","0.00576"
"114.31200","9.52609","0.00410"
"114.44400","9.53715","0.00774"
"114.57600","9.54821","0.00879"
"114.70800","9.55909","0.00573"
"114.84000","9.57015","0.01513"
"114.97200","9.58115","0.01101"
"115.10400","9.59221","0.00642"
"115.23600","9.60316","0.00623"
"115.36800","9.61416","0.00128"
"115.50000","9.62516","0.00948"
"115.63200","9.63616","0.00399"
"115.76400","9.64710","0.00535"
"115.89600","9.65810","0.00193"
"116.02800","9.66916","0.00072"
"116.16000","9.68017","0.00089"
"116.29200","9.69117","0.00195"
"116.42400","9.70211","0.00363"
"116.55600","9.71317","0.00450"
"116.68800","9.72417","0.00566"
"116.82000","9.73511","0.00369"
"116.95200","9.74611","0.00273"
"117.08400","9.75711","0.00216"
"117.21600","9.76818","0.00205"
"117.34800","9.77912","0.00225"
"117.48000","9.79006","0.00382"
"117.61200","9.80112","0.00462"
"117.74400","9.81212","0.00451"
"117.87600","9.82312","0.00445"
"118.00800","9.83406","0.00411"
"118.14000","9.84518","0.00323"
"118.27200","9.85612","0.00222"
"118.40400","9.86713","0.00259"
"118.53600","9.87813","0.00410"
"118.66800","9.88913","0.00510"
"118.80000","9.90013","0.00501"
"118.93200","9.91119","0.00427"
"119.06400","9.92207","0.00401"
"119.19600","9.93319","0.00263"
"119.32800","9.94414","0.00264"
"119.46000","9.95514","0.00415"
"119.59200","9.96614","0.00484"
"119.72400","9.97720","0.00576"
"119.85600","9.98820","0.00460"
"119.98800","9.99914","0.00426"
"120.12000","10.01008","0.00407"
"120.25200","10.02114","0.00353"
"120.38400","10.03215","0.00394"
"120.51600","10.04321","0.00436"
"120.64800","10.05415","0.00452"
"120.78000","10.06515","0.00510"
"120.91200","10.07621","0.00477"
"121.04400","10.08715","0.00511"
"121.17600","10.09815","0.00398"
"121.30800","10.10909","0.00344"
"121.44000","10.12022","0.00428"
"121.57200","10.13116","0.00496"
"121.70400","10.14210","0.00606"
"121.83600","10.15310","0.00648"
"121.96800","10.16416","0.00433"
"122.10000","10.17516","0.00533"
"122.23200","10.18610","0.00417"
"122.36400","10.19716","0.00596"
"122.49600","10.20817","0.00543"
"122.62800","10.21917","0.00482"
"122.76000","10.23011","0.00970"
"122.89200","10.24111","0.00790"
"123.02400","10.25211","0.00685"
"123.15600","10.26317","0.00711"
"123.28800","10.27411","0.00408"
"123.42000","10.28512","0.00427"
"123.55200","10.29612","0.00472"
"123.68400","10.30718","0.00475"
"123.81600","10.31818","0.00446"
"123.94800","10.32906","0.00493"
"124.08000","10.34018","0.00450"
"124.21200","10.35112","0.00488"
"124.34400","10.36212","0.00507"
"124.47600","10.37306","0.00493"
"124.60800","10.38413","0.00548"
"124.74000","10.39513","0.00511"
"124.87200","10.40613","0.00520"
"125.00400","10.41707","0.00475"
"125.13600","10.42807","0.00571"
"125.26800","10.43913","0.00598"
"125.40000","10.45013","0.00585"
"125.53200","10.46108","0.00615"
"125.66400","10.47214","0.00621"
"125.79600","10.48314","0.00552"
"125.92800","10.49414","0.00525"
"126.06000","10.50508","0.00605"
"126.19200","10.51614","0.00611"
"126.32400","10.52714","0.00621"
"126.45600","10.53814","0.00571"
"126.58800","10.54909","0.00654"
"126.72000","10.56015","0.00586"
"126.85200","10.57115","0.00612"
"126.98400","10.58215","0.00602"
"127.11600","10.59315","0.00637"
"127.24800","10.60415","0.00632"
"127.38000","10.61515","0.00647"
"127.51200","10.62615","0.00646"
"127.64400","10.63710","0.00673"
"127.77600","10.64810","0.00669"
"127.90800","10.65916","0.00622"
"128.04000","10.67016","0.00695"
"128.17200","10.68110","0.00683"
"128.30400","10.69216","0.00601"
"128.43600","10.70322","0.00679"
"128.56800","10.71410","0.00638"
"128.70000","10.72511","0.00712"
"128.83200","10.73611","0.00755"
"128.96400","10.74717","0.00631"
"129.09600","10.75817","0.00576"
"129.22800","10.76911","0.00601"
"129.36000","10.78011","0.00721"
"129.49200","10.79117","0.00679"
"129.62400","10.80217","0.00739"
"129.75600","10.81312","0.00635"
"129.88800","10.82406","0.00632"
"130.02000","10.83518","0.00604"
"130.15200","10.84618","0.00642"
"130.28400","10.85718","0.00708"
"130.41600","10.86812","0.00663"
"130.54800","10.87918","0.00713"
"130.68000","10.89019","0.00717"
"130.81200","10.90113","0.00683"
"130.94400","10.91207","0.00667"
"131.07600","10.92313","0.00694"
"131.20800","10.93419","0.00770"
"131.34000","10.94513","0.00765"
"131.47200","10.95607","0.00733"
"131.60400","10.96713","0.00744"
"131.73600","10.97814","0.00726"
"131.86800","10.98914","0.00730"
"132.00000","11.00014","0.00682"
"132.13200","11.01114","0.00742"
"132.26400","11.02214","0.00788"
"132.39600","11.03314","0.00808"
"132.52800","11.04414","0.00748"
"132.66000","11.05514","0.00818"
"132.79200","11.06615","0.00835"
"132.92400","11.07715","0.00774"
"133.05600","11.08809","0.00720"
"133.18800","11.09915","0.00834"
"133.32000","11.11015","0.00779"
"133.45200","11.12115","0.00832"
"133.58400","11.13215","0.00778"
"133.71600","11.14315","0.00808"
"133.84800","11.15422","0.00745"
"133.98000","11.16516","0.00828"
"134.11200","11.17610","0.00820"
"134.24400","11.18710","0.00802"
"134.37600","11.19816","0.00889"
"134.50800","11.20916","0.00838"
"134.64000","11.22016","0.00874"
"134.77200","11.23111","0.00866"
"134.90400","11.24217","0.00864"
"135.03600","11.25311","0.00897"
"135.16800","11.26411","0.00860"
"135.30000","11.27511","0.00886"
"135.43200","11.28617","0.00878"
"135.56400","11.29717","0.00849"
"135.69600","11.30811","0.00970"
"135.82800","11.31912","0.00865"
"135.96000","11.33012","0.00864"
"136.09200","11.34118","0.00759"
"136.22400","11.35212","0.00860"
"136.35600","11.36312","0.00803"
"136.48800","11.37412","0.00857"
"136.62000","11.38512","0.00803"
"136.75200","11.39612","0.00874"
"136.88400","11.40707","0.00902"
"137.01600","11.41819","0.00891"
"137.14800","11.42913","0.00872"
"137.28000","11.44013","0.00923"
"137.41200","11.45107","0.00838"
"137.54400","11.46213","0.00893"
"137.67600","11.47313","0.00856"
"137.80800","11.48407","0.00895"
"137.94000","11.49502","0.00944"
"138.07200","11.50620","0.01003"
"138.20400","11.51714","0.00964"
"138.33600","11.52814","0.00941"
"138.46800","11.53914","0.00928"
"138.60000","11.55020","0.00953"
"138.73200","11.56120","0.00942"
"138.86400","11.57214","0.00968"
"138.99600","11.58309","0.00999"
"139.12800","11.59409","0.01024"
"139.26000","11.60515","0.00966"
"139.39200","11.61615","0.00951"
"139.52400","11.62709","0.01007"
"139.65600","11.63815","0.00989"
"139.78800","11.64915","0.00990"
"139.92000","11.66016","0.01004"
"140.05200","11.67110","0.01009"
"140.18400","11.68216","0.00980"
"140.31600","11.69316","0.00950"
"140.44800","11.70416","0.01013"
"140.58000","11.71510","0.01004"
"140.71200","11.72616","0.00637"
"140.84400","11.73710","0.00680"
"140.97600","11.74816","0.00701"
"141.10800","11.75911","0.00827"
"141.24000","11.77011","0.00891"
"141.37200","11.78111","0.00751"
"141.50400","11.79217","0.00698"
"141.63600","11.80311","0.00800"
"141.76800","11.81411","0.00816"
"141.90000","11.82517","0.00823"
"142.03200","11.83617","0.00839"
"142.16400","11.84718","0.00879"
"142.29600","11.85812","0.00907"
"142.42800","11.86918","0.00927"
"142.56000","11.88012","0.00955"
"142.69200","11.89112","0.00939"
"142.82400","11.90212","0.00944"
"142.95600","11.91312","0.00987"
"143.08800","11.92413","0.00977"
"143.22000","11.93513","0.01185"
"143.35200","11.94613","0.00854"
"143.48400","11.95719","0.00655"
"143.61600","11.96813","0.00703"
"143.74800","11.97913","0.00575"
"143.88000","11.99007","0.00790"
"144.01200","12.00113","0.00727"
"144.14400","12.01219","0.00853"
"144.27600","12.02308","0.00795"
"144.40800","12.03414","0.00738"
"144.54000","12.04514","0.00723"
"144.67200","12.05620","0.00794"
"144.80400","12.06714","0.00858"
"144.93600","12.07814","0.00948"
"145.06800","12.08920","0.01136"
"145.20000","12.10020","0.01008"
"145.33200","12.11121","0.00951"
"145.46400","12.12209","0.00828"
"145.59600","12.13315","0.01018"
"145.72800","12.14415","0.01121"
"145.86000","12.15509","0.00775"
"145.99200","12.16603","0.01004"
"146.12400","12.17715","0.01028"
"146.25600","12.18816","0.02350"
"146.38800","12.19916","0.00890"
"146.52000","12.21010","0.00649"
"146.65200","12.22116","0.00713"
"146.78400","12.23222","0.00391"
"146.91600","12.24316","0.00177"
"147.04800","12.25410","0.00157"
"147.18000","12.26511","0.00240"
"147.31200","12.27617","0.00307"
"147.44400","12.28711","0.00354"
"147.57600","12.29811","0.00307"
"147.70800","12.30911","0.00312"
"147.84000","12.32011","0.00220"
"147.97200","12.33111","0.00214"
"148.10400","12.34212","0.00184"
"148.23600","12.35312","0.00222"
"148.36800","12.36418","0.00254"
"148.50000","12.37518","0.00185"
"148.63200","12.38612","0.00193"
"148.76400","12.39712","0.00220"
"148.89600","12.40818","0.00263"
"149.02800","12.41918","0.00255"
"149.16000","12.43013","0.00199"
"149.29200","12.44106","0.00155"
"149.42400","12.45213","0.00225"
"149.55600","12.46319","0.00231"
"149.68800","12.47407","0.00203"
"149.82000","12.48513","0.00263"
"149.95200","12.49613","0.00268"
"150.08400","12.50719","0.00266"
"150.21600","12.51814","0.00242"
"150.34800","12.52914","0.00260"
"150.48000","12.54020","0.00221"
"150.61200","12.55114","0.00252"
"150.74400","12.56214","0.00228"
"150.87600","12.57308","0.00267"
"151.00800","12.58414","0.00270"
"151.14000","12.59514","0.00290"
"151.27200","12.60608","0.00240"
"151.40400","12.61709","0.00267"
"151.53600","12.62821","0.00192"
"151.66800","12.63915","0.00217"
"151.80000","12.65021","0.00282"
"151.93200","12.66115","0.00290"
"152.06400","12.67215","0.00267"
"152.19600","12.68315","0.00261"
"152.32800","12.69409","0.00275"
"152.46000","12.70510","0.00232"
"152.59200","12.71610","0.00287"
"152.72400","12.72710","0.00208"
"152.85600","12.73810","0.00216"
"152.98800","12.74910","0.00274"
"153.12000","12.76016","0.00258"
"153.25200","12.77116","0.00282"
"153.38400","12.78216","0.00272"
"153.51600","12.79311","0.00251"
"153.64800","12.80417","0.00208"
"153.78000","12.81517","0.00189"
"153.91200","12.82611","0.00256"
"154.04400","12.83705","0.00264"
"154.17600","12.84811","0.00171"
"154.30800","12.85911","0.00239"
"154.44000","12.87012","0.00208"
"154.57200","12.88112","0.00167"
"154.70400","12.89212","0.00223"
"154.83600","12.90318","0.00215"
"154.96800","12.91418","0.00166"
"155.10000","12.92512","0.00272"
"155.23200","12.93612","0.00361"
"155.36400","12.94718","0.00174"
"155.49600","12.95813","0.00281"
"155.62800","12.96907","0.00200"
"155.76000","12.98007","0.00254"
"155.89200","12.99119","0.00182"
"156.02400","13.00219","0.00191"
"156.15600","13.01313","0.00133"
"156.28800","13.02413","0.00129"
"156.42000","13.03520","0.00154"
"156.55200","13.04620","0.00164"
"156.68400","13.05714","0.00120"
"156.81600","13.06814","0.00155"
"156.94800","13.07914","0.00168"
"157.08000","13.09020","0.00184"
"157.21200","13.10108","0.00113"
"157.34400","13.11208","0.00217"
"157.47600","13.12315","0.00175"
"157.60800","13.13415","0.00196"
"157.74000","13.14515","0.00183"
"157.87200","13.15609","0.00255"
"158.00400","13.16715","0.00239"
"158.13600","13.17821","0.00139"
"158.26800","13.18915","0.00166"
"158.40000","13.20015","0.00165"
"158.53200","13.21115","0.00138"
"158.66400","13.22216","0.00187"
"158.79600","13.23316","0.00177"
"158.92800","13.24404","0.00178"
"159.06000","13.25510","0.00241"
"159.19200","13.26610","0.00233"
"159.32400","13.27716","0.00201"
"159.45600","13.28811","0.00241"
"159.58800","13.29917","0.00240"
"159.72000","13.31017","0.00378"
"159.85200","13.32117","0.00343"
"159.98400","13.33211","0.00248"
"160.11600","13.34317","0.00161"
"160.24800","13.35417","0.00162"
"160.38000","13.36511","0.00268"
"160.51200","13.37611","0.00245"
"160.64400","13.38712","0.00188"
"160.77600","13.39812","0.00148"
"160.90800","13.40912","0.00151"
"161.04000","13.42012","0.00181"
"161.17200","13.43118","0.00117"
"161.30400","13.44212","0.00194"
"161.43600","13.45312","0.00171"
"161.56800","13.46412","0.00180"
"161.70000","13.47513","0.00187"
"161.83200","13.48613","0.00129"
"161.96400","13.49719","0.00177"
"162.09600","13.50807","0.00128"
"162.22800","13.51913","0.00200"
"162.36000","13.53013","0.00279"
"162.49200","13.54113","0.00228"
"162.62400","13.55214","0.00264"
"162.75600","13.56314","0.00251"
"162.88800","13.57414","0.00321"
"163.02000","13.58514","0.00344"
"163.15200","13.59608","0.00355"
"163.28400","13.60714","0.00281"
"163.41600","13.61814","0.00217"
"163.54800","13.62914","0.00318"
"163.68000","13.64015","0.00233"
"163.81200","13.65115","0.00174"
"163.94400","13.66221","0.00197"
"164.07600","13.67315","0.00208"
"164.20800","13.68415","0.00254"
"164.34000","13.69503","0.00307"
"164.47200","13.70615","0.00401"
"164.60400","13.71715","0.00282"
"164.73600","13.72816","0.00208"
"164.86800","13.73910","0.00322"
"165.00000","13.75016","0.00346"
"165.13200","13.76116","0.00376"
"165.26400","13.77210","0.00238"
"165.39600","13.78304","0.00189"
"165.52800","13.79410","0.00137"
"165.66000","13.80516","0.00113"
"165.79200","13.81610","0.00033"
"165.92400","13.82711","0.00075"
"166.05600","13.83811","0.00544"
"166.18800","13.84917","0.00088"
"166.32000","13.86017","0.00105"
"166.45200","13.87111","0.00093"
"166.58400","13.88217","0.00145"
"166.71600","13.89317","0.00077"
"166.84800","13.90418","0.00111"
"166.98000","13.91506","0.00085"
"167.11200","13.92612","0.00102"
"167.24400","13.93706","0.00177"
"167.37600","13.94812","0.00119"
"167.50800","13.95906","0.00267"
"167.64000","13.97012","0.00054"
"167.77200","13.98112","0.00080"
"167.90400","13.99219","0.00012"
"168.03600","14.00313","0.00069"
"168.16800","14.01413","0.00026"
"168.30000","14.02519","0.00113"
"168.43200","14.03613","0.00073"
"168.56400","14.04713","0.00101"
"168.69600","14.05813","0.00029"
"168.82800","14.06908","0.00058"
"168.96000","14.08014","0.00018"
"169.09200","14.09114","0.00052"
"169.22400","14.10214","0.00055"
"169.35600","14.11314","0.00085"
"169.48800","14.12414","0.00064"
"169.62000","14.13508","0.00035"
"169.75200","14.14614","0.00023"
"169.88400","14.15721","0.00042"
"170.01600","14.16815","0.00084"
"170.14800","14.17915","0.00103"
"170.28000","14.19015","0.00102"
"170.41200","14.20115","0.00109"
"170.54400","14.21215","0.00037"
"170.67600","14.22309","0.00093"
"170.80800","14.23409","0.00068"
"170.94000","14.24516","0.00061"
"171.07200","14.25616","0.00055"
"171.20400","14.26710","0.00096"
"171.33600","14.27816","0.00030"
"171.46800","14.28922","0.00095"
"171.60000","14.30016","0.00174"
"171.73200","14.31116","0.00122"
"171.86400","14.32210","0.00106"
"171.99600","14.33317","0.00150"
"172.12800","14.34417","0.00103"
"172.26000","14.35511","0.00125"
"172.39200","14.36605","0.00079"
"172.52400","14.37717","0.00036"
"172.65600","14.38817","0.00101"
"172.78800","14.39917","0.00125"
"172.92000","14.41012","0.00054"
"173.05200","14.42112","0.00110"
"173.18400","14.43218","0.00089"
"173.31600","14.44318","0.00122"
"173.44800","14.45412","0.00103"
"173.58000","14.46512","0.00091"
"173.71200","14.47618","0.00117"
"173.84400","14.48712","0.00086"
"173.97600","14.49807","0.00136"
"174.10800","14.50913","0.00088"
"174.24000","14.52013","0.00165"
"174.37200","14.53113","0.00165"
"174.50400","14.54207","0.00155"
"174.63600","14.55319","0.00131"
"174.76800","14.56419","0.00244"
"174.90000","14.57519","0.00243"
"175.03200","14.58614","0.00269"
"175.16400","14.59714","0.00270"
"175.29600","14.60814","0.00221"
"175.42800","14.61914","0.00081"
"175.56000","14.63008","0.00049"
"175.69200","14.64108","0.00092"
"175.82400","14.65208","0.00003"
"175.95600","14.66314","0.00055"
"176.08800","14.67409","0.00107"
"176.22000","14.68515","0.00043"
"176.35200","14.69615","0.00134"
"176.48400","14.70715","0.00071"
"176.61600","14.71815","-0.00001"
"176.74800","14.72915","-0.00004"
"176.88000","14.74015","0.00004"
"177.01200","14.75115","0.00002"
"177.14400","14.76216","0.00001"
"177.27600","14.77316","0.00027"
"177.40800","14.78422","0.00161"
"177.54000","14.79516","0.00069"
"177.67200","14.80616","0.00000"
"177.80400","14.81710","0.00074"
"177.93600","14.82816","0.00062"
"178.06800","14.83916","0.00077"
"178.20000","14.85017","0.00040"
"178.33200","14.86117","-0.00007"
"178.46400","14.87217","0.00039"
"178.59600","14.88317","0.00031"
"178.72800","14.89411","0.00012"
"178.86000","14.90511","0.00018"
"178.99200","14.91611","-0.00069"
"179.12400","14.92717","-0.00024"
"179.25600","14.93812","0.00041"
"179.38800","14.94912","0.00012"
"179.52000","14.96018","-0.00020"
"179.65200","14.97112","-0.00032"
"179.78400","14.98218","0.00001"
"179.91600","14.99312","-0.00004"
"180.04800","15.00418","0.00050"
"180.18000","15.01513","0.00037"
"180.31200","15.02613","-0.00008"
"180.44400","15.03707","0.00071"
"180.57600","15.04813","-0.00026"
"180.70800","15.05919","-0.00002"
"180.84000","15.07013","0.00001"
"180.97200","15.08107","0.00066"
"181.10400","15.09213","0.00089"
"181.23600","15.10314","0.00048"
"181.36800","15.11420","0.00057"
"181.50000","15.12514","0.00058"
"181.63200","15.13614","0.00035"
"181.76400","15.14720","0.00008"
"181.89600","15.15814","0.00063"
"182.02800","15.16908","0.00065"
"182.16000","15.18014","0.00042"
"182.29200","15.19115","-0.00010"
"182.42400","15.20215","0.00034"
"182.55600","15.21303","0.00040"
"182.68800","15.22415","-0.00006"
"182.82000","15.23515","0.00036"
"182.95200","15.24621","0.00052"
"183.08400","15.25715","0.00072"
"183.21600","15.26815","0.00080"
"183.34800","15.27921","0.00110"
"183.48000","15.29016","0.00182"
"183.61200","15.30110","0.00138"
"183.74400","15.31210","0.00056"
"183.87600","15.32310","0.00048"
"184.00800","15.33416","0.00052"
"184.14000","15.34516","-0.00027"
"184.27200","15.35610","-0.00014"
"184.40400","15.36717","0.00056"
"184.53600","15.37817","0.00053"
"184.66800","15.38911","0.00014"
"184.80000","15.40011","0.00067"
"184.93200","15.41117","0.00099"
"185.06400","15.42217","0.00091"
"185.19600","15.43311","0.00035"
"185.32800","15.44406","0.00006"
"185.46000","15.45518","0.00014"
"185.59200","15.46612","0.00047"
"185.72400","15.47718","0.00067"
"185.85600","15.48812","0.00017"
"185.98800","15.49918","0.00047"
"186.12000","15.51018","0.00042"
"186.25200","15.52112","0.00084"
"186.38400","15.53212","0.00023"
"186.51600","15.54319","0.00073"
"186.64800","15.55413","-0.00002"
"186.78000","15.56513","0.00070"
"186.91200","15.57607","0.00212"
"187.04400","15.58713","0.00219"
"187.17600","15.59813","0.00162"
"187.30800","15.60907","0.00040"
"187.44000","15.62013","0.00050"
"187.57200","15.63114","0.00150"
"187.70400","15.64214","0.00010"
"187.83600","15.65314","0.00005"
"187.96800","15.66408","0.00091"
"188.10000","15.67514","0.00011"
"188.23200","15.68620","0.00068"
"188.36400","15.69714","-0.00014"
"188.49600","15.70809","0.00101"
"188.62800","15.71915","0.00048"
"188.76000","15.73015","0.00039"
"188.89200","15.74109","0.00051"
"189.02400","15.75209","0.00083"
"189.15600","15.76315","0.00015"
"189.28800","15.77415","0.00054"
"189.42000","15.78515","0.00069"
"189.55200","15.79609","0.00033"
"189.68400","15.80716","0.00028"
"189.81600","15.81822","0.00047"
"189.94800","15.82916","0.00029"
"190.08000","15.84010","0.00038"
"190.21200","15.85110","0.00042"
"190.34400","15.86216","0.00013"
"190.47600","15.87316","0.00066"
"190.60800","15.88410","0.00040"
"190.74000","15.89517","0.00050"
"190.87200","15.90617","0.00028"
"191.00400","15.91717","0.00063"
"191.13600","15.92811","0.00033"
"191.26800","15.93917","0.00052"
"191.40000","15.95023","0.00020"
"191.53200","15.96117","-0.00003"
"191.66400","15.97212","0.00132"
"191.79600","15.98312","0.00128"
"191.92800","15.99418","0.00088"
"192.06000","16.00518","0.00043"
"192.19200","16.01612","0.00028"
"192.32400","16.02718","0.00031"
"192.45600","16.03818","-0.00027"
"192.58800","16.04918","0.00084"
"192.72000","16.06013","-0.00031"
"192.85200","16.07113","0.00116"
"192.98400","16.08219","0.00105"
"193.11600","16.09319","0.00140"
"193.24800","16.10413","0.00067"
"193.38000","16.11507","0.00056"
"193.51200","16.12619","0.00059"
"193.64400","16.13713","0.00046"
"193.77600","16.14814","0.00060"
"193.90800","16.15908","0.00056"
"194.04000","16.17014","0.00075"
"194.17200","16.18114","0.00107"
"194.30400","16.19214","0.00079"
"194.43600","16.20314","0.00114"
"194.56800","16.21420","0.00043"
"194.70000","16.22521","0.00033"
"194.83200","16.23615","0.00079"
"194.95400","16.24625","-0.00035"