File: Force_trajectories/170225_2/Specimen_RawData_3.csv
End date,"2/25/2017"
Specimen label,"6BG_41"
Maximum Load,"1.72377",N

Time,Extension,Load
(s),(mm),(N)
"0.00000","0.00000","-0.00115"
"0.48000","0.04030","-0.00012"
"0.96000","0.08024","0.00034"
"1.44000","0.12024","0.00053"
"1.92000","0.16024","0.00021"
"2.40000","0.20018","0.00131"
"2.88000","0.24011","0.00128"
"3.36000","0.28017","0.00172"
"3.84000","0.32017","0.00168"
"4.32000","0.36023","0.00148"
"4.80000","0.40023","0.00204"
"5.28000","0.44023","0.00174"
"5.76000","0.48023","0.00251"
"6.24000","0.52017","0.00136"
"6.72000","0.56023","0.00202"
"7.20000","0.60017","0.00171"
"7.68000","0.64017","0.00224"
"8.16000","0.68023","0.00253"
"8.64000","0.72016","0.00201"
"9.12000","0.76022","0.00216"
"9.60000","0.80022","0.00247"
"10.08000","0.84022","0.00235"
"10.56000","0.88022","0.00280"
"11.04000","0.92022","0.00231"
"11.52000","0.96016","0.00299"
"12.00000","1.00016","0.00251"
"12.48000","1.04022","0.00249"
"12.96000","1.08016","0.00265"
"13.44000","1.12022","0.00284"
"13.92000","1.16028","0.00264"
"14.40000","1.20016","0.00256"
"14.88000","1.24021","0.00261"
"15.36000","1.28021","0.00253"
"15.84000","1.32015","0.00155"
"16.32000","1.36015","0.00206"
"16.80000","1.40021","0.00233"
"17.28000","1.44021","0.00206"
"17.76000","1.48015","0.00194"
"18.24000","1.52021","0.00199"
"18.72000","1.56027","0.00134"
"19.20000","1.60021","0.00286"
"19.68000","1.64021","0.00194"
"20.16000","1.68015","0.00270"
"20.64000","1.72020","0.00281"
"21.12000","1.76014","0.00248"
"21.60000","1.80020","0.00228"
"22.08000","1.84020","0.00252"
"22.56000","1.88026","0.00175"
"23.04000","1.92020","0.00166"
"23.52000","1.96026","0.00183"
"24.00000","2.00020","0.00243"
"24.48000","2.04020","0.00216"
"24.96000","2.08020","0.00190"
"25.44000","2.12014","0.00206"
"25.92000","2.16020","0.00184"
"26.40000","2.20020","0.00258"
"26.88000","2.24025","0.00314"
"27.36000","2.28019","0.00272"
"27.84000","2.32025","0.00246"
"28.32000","2.36019","0.00300"
"28.80000","2.40019","0.00287"
"29.28000","2.44019","0.00283"
"29.76000","2.48013","0.00389"
"30.24000","2.52019","0.00274"
"30.72000","2.56019","0.00295"
"31.20000","2.60019","0.00362"
"31.68000","2.64025","0.00376"
"32.16000","2.68019","0.00418"
"32.64000","2.72024","0.00412"
"33.12000","2.76018","0.00400"
"33.60000","2.80018","0.00396"
"34.08000","2.84018","0.00414"
"34.56000","2.88024","0.00392"
"35.04000","2.92018","0.00441"
"35.52000","2.96018","0.00405"
"36.00000","3.00024","0.00412"
"36.48000","3.04018","0.00421"
"36.96000","3.08018","0.00462"
"37.44000","3.12024","0.00500"
"37.92000","3.16024","0.00434"
"38.40000","3.20012","0.00531"
"38.88000","3.24017","0.00502"
"39.36000","3.28023","0.00499"
"39.84000","3.32017","0.00468"
"40.32000","3.36023","0.00531"
"40.80000","3.40017","0.00544"
"41.28000","3.44023","0.00558"
"41.76000","3.48023","0.00641"
"42.24000","3.52023","0.00584"
"42.72000","3.56017","0.00589"
"43.20000","3.60017","0.00615"
"43.68000","3.64017","0.00618"
"44.16000","3.68022","0.00669"
"44.64000","3.72022","0.00664"
"45.12000","3.76022","0.00629"
"45.60000","3.80022","0.00686"
"46.08000","3.84022","0.00688"
"46.56000","3.88022","0.00712"
"47.04000","3.92016","0.00724"
"47.52000","3.96016","0.00752"
"48.00000","4.00016","0.00818"
"48.48000","4.04022","0.00770"
"48.96000","4.08022","0.00786"
"49.44000","4.12022","0.00789"
"49.92000","4.16022","0.00867"
"50.40000","4.20021","0.00889"
"50.88000","4.24015","0.00871"
"51.36000","4.28015","0.00862"
"51.84000","4.32015","0.00908"
"52.32000","4.36015","0.00945"
"52.80000","4.40021","0.00940"
"53.28000","4.44021","0.00965"
"53.76000","4.48021","0.00956"
"54.24000","4.52027","0.00999"
"54.72000","4.56027","0.01012"
"55.20000","4.60027","0.01050"
"55.68000","4.64021","0.01105"
"56.16000","4.68009","0.01025"
"56.64000","4.72020","0.01096"
"57.12000","4.76020","0.01119"
"57.60000","4.80014","0.01127"
"58.08000","4.84026","0.01152"
"58.56000","4.88020","0.01113"
"59.04000","4.92020","0.01154"
"59.52000","4.96020","0.01179"
"60.00000","5.00020","0.01229"
"60.48000","5.04014","0.01178"
"60.96000","5.08020","0.01200"
"61.44000","5.12020","0.01241"
"61.92000","5.16014","0.01282"
"62.40000","5.20019","0.01329"
"62.88000","5.24019","0.01311"
"63.36000","5.28019","0.01341"
"63.84000","5.32025","0.01400"
"64.32000","5.36019","0.01385"
"64.80000","5.40013","0.01421"
"65.28000","5.44019","0.01425"
"65.76000","5.48019","0.01483"
"66.24000","5.52019","0.01514"
"66.72000","5.56025","0.01550"
"67.20000","5.60025","0.01534"
"67.68000","5.64019","0.01553"
"68.16000","5.68019","0.01594"
"68.64000","5.72024","0.01643"
"69.12000","5.76018","0.01630"
"69.60000","5.80018","0.01690"
"70.08000","5.84024","0.01710"
"70.56000","5.88018","0.01812"
"71.04000","5.92024","0.01775"
"71.52000","5.96024","0.01811"
"72.00000","6.00024","0.01843"
"72.48000","6.04024","0.01883"
"72.96000","6.08018","0.01933"
"73.44000","6.12024","0.02022"
"73.92000","6.16012","0.02011"
"74.40000","6.20017","0.02090"
"74.88000","6.24023","0.02103"
"75.36000","6.28017","0.02153"
"75.84000","6.32023","0.02123"
"76.32000","6.36023","0.02203"
"76.80000","6.40017","0.02237"
"77.28000","6.44023","0.02314"
"77.76000","6.48023","0.02345"
"78.24000","6.52017","0.02365"
"78.72000","6.56017","0.02473"
"79.20000","6.60017","0.02483"
"79.68000","6.64023","0.02592"
"80.16000","6.68022","0.02618"
"80.64000","6.72022","0.02647"
"81.12000","6.76022","0.02755"
"81.60000","6.80022","0.02748"
"82.08000","6.84022","0.02886"
"82.56000","6.88010","0.02906"
"83.04000","6.92016","0.02941"
"83.52000","6.96016","0.03072"
"84.00000","7.00016","0.03092"
"84.48000","7.04022","0.03114"
"84.96000","7.08028","0.03230"
"85.44000","7.12016","0.03323"
"85.92000","7.16022","0.03336"
"86.40000","7.20021","0.03448"
"86.88000","7.24021","0.03463"
"87.36000","7.28015","0.03551"
"87.84000","7.32021","0.03627"
"88.32000","7.36015","0.03714"
"88.80000","7.40021","0.03799"
"89.28000","7.44021","0.03853"
"89.76000","7.48021","0.03935"
"90.24000","7.52027","0.03999"
"90.72000","7.56027","0.04049"
"91.20000","7.60021","0.04054"
"91.68000","7.64021","0.04121"
"92.16000","7.68021","0.04143"
"92.64000","7.72020","0.04185"
"93.12000","7.76026","0.04211"
"93.60000","7.80026","0.04337"
"94.08000","7.84020","0.04323"
"94.56000","7.88026","0.04383"
"95.04000","7.92026","0.04450"
"95.52000","7.96020","0.04489"
"96.00000","8.00020","0.04533"
"96.48000","8.04014","0.04593"
"96.96000","8.08014","0.04631"
"97.44000","8.12020","0.04583"
"97.92000","8.16020","0.04552"
"98.40000","8.20025","0.04545"
"98.88000","8.24019","0.04548"
"99.36000","8.28025","0.04647"
"99.84000","8.32019","0.04609"
"100.32000","8.36019","0.04640"
"100.80000","8.40013","0.04686"
"101.28000","8.44019","0.04713"
"101.76000","8.48019","0.04763"
"102.24000","8.52019","0.04788"
"102.72000","8.56019","0.04812"
"103.20000","8.60025","0.04859"
"103.68000","8.64019","0.04863"
"104.16000","8.68018","0.04914"
"104.64000","8.72018","0.04939"
"105.12000","8.76012","0.04978"
"105.60000","8.80024","0.05034"
"106.08000","8.84018","0.05057"
"106.56000","8.88024","0.05106"
"107.04000","8.92024","0.05142"
"107.52000","8.96018","0.05197"
"108.00000","9.00024","0.05241"
"108.48000","9.04024","0.05322"
"108.96000","9.08018","0.05391"
"109.44000","9.12018","0.05427"
"109.92000","9.16018","0.05502"
"110.40000","9.20023","0.05606"
"110.88000","9.24023","0.05655"
"111.36000","9.28023","0.05797"
"111.84000","9.32023","0.05882"
"112.32000","9.36023","0.06000"
"112.80000","9.40023","0.06131"
"113.28000","9.44017","0.06254"
"113.76000","9.48017","0.06382"
"114.24000","9.52017","0.06567"
"114.72000","9.56017","0.06707"
"115.20000","9.60023","0.06899"
"115.68000","9.64023","0.07032"
"116.16000","9.68022","0.07197"
"116.64000","9.72028","0.07314"
"117.12000","9.76028","0.07459"
"117.60000","9.80016","0.07561"
"118.08000","9.84022","0.07743"
"118.56000","9.88016","0.07856"
"119.04000","9.92016","0.07993"
"119.52000","9.96022","0.08140"
"120.00000","10.00022","0.08320"
"120.48000","10.04016","0.08511"
"120.96000","10.08028","0.08730"
"121.44000","10.12022","0.08955"
"121.92000","10.16022","0.09055"
"122.40000","10.20021","0.09238"
"122.88000","10.24021","0.09320"
"123.36000","10.28015","0.09441"
"123.84000","10.32021","0.09516"
"124.32000","10.36021","0.09598"
"124.80000","10.40021","0.09693"
"125.28000","10.44027","0.09766"
"125.76000","10.48027","0.09853"
"126.24000","10.52021","0.09967"
"126.72000","10.56021","0.10057"
"127.20000","10.60015","0.10259"
"127.68000","10.64015","0.10541"
"128.16000","10.68014","0.10722"
"128.64000","10.72020","0.11061"
"129.12000","10.76020","0.11364"
"129.60000","10.80020","0.11620"
"130.08000","10.84020","0.11872"
"130.56000","10.88020","0.12218"
"131.04000","10.92020","0.12447"
"131.52000","10.96020","0.12611"
"132.00000","11.00020","0.12879"
"132.48000","11.04014","0.13050"
"132.96000","11.08020","0.13203"
"133.44000","11.12025","0.13349"
"133.92000","11.16019","0.13512"
"134.40000","11.20025","0.13661"
"134.88000","11.24019","0.13791"
"135.36000","11.28019","0.13824"
"135.84000","11.32019","0.13915"
"136.32000","11.36019","0.14035"
"136.80000","11.40025","0.14089"
"137.28000","11.44013","0.14175"
"137.76000","11.48025","0.14248"
"138.24000","11.52025","0.14328"
"138.72000","11.56025","0.14408"
"139.20000","11.60025","0.14444"
"139.68000","11.64019","0.14577"
"140.16000","11.68018","0.14742"
"140.64000","11.72018","0.14949"
"141.12000","11.76018","0.15228"
"141.60000","11.80018","0.15533"
"142.08000","11.84024","0.15932"
"142.56000","11.88024","0.16313"
"143.04000","11.92024","0.16794"
"143.52000","11.96024","0.17347"
"144.00000","12.00018","0.17941"
"144.48000","12.04024","0.18514"
"144.96000","12.08018","0.19066"
"145.44000","12.12018","0.19498"
"145.92000","12.16023","0.19781"
"146.40000","12.20023","0.20066"
"146.88000","12.24017","0.20249"
"147.36000","12.28029","0.20421"
"147.84000","12.32023","0.20569"
"148.32000","12.36017","0.20786"
"148.80000","12.40023","0.21154"
"149.28000","12.44023","0.21510"
"149.76000","12.48011","0.21879"
"150.24000","12.52017","0.22173"
"150.72000","12.56023","0.22608"
"151.20000","12.60023","0.23012"
"151.68000","12.64023","0.23457"
"152.16000","12.68022","0.23816"
"152.64000","12.72022","0.24126"
"153.12000","12.76022","0.24395"
"153.60000","12.80016","0.24589"
"154.08000","12.84016","0.24763"
"154.56000","12.88016","0.24953"
"155.04000","12.92022","0.25187"
"155.52000","12.96022","0.25372"
"156.00000","13.00022","0.25631"
"156.48000","13.04016","0.25935"
"156.96000","13.08022","0.26366"
"157.44000","13.12022","0.26760"
"157.92000","13.16021","0.27230"
"158.40000","13.20015","0.27658"
"158.88000","13.24021","0.27960"
"159.36000","13.28021","0.28242"
"159.84000","13.32021","0.28595"
"160.32000","13.36021","0.29018"
"160.80000","13.40021","0.29380"
"161.28000","13.44027","0.29682"
"161.76000","13.48021","0.30033"
"162.24000","13.52021","0.30553"
"162.72000","13.56021","0.31138"
"163.20000","13.60015","0.31970"
"163.68000","13.64021","0.32672"
"164.16000","13.68026","0.33576"
"164.64000","13.72026","0.34249"
"165.12000","13.76020","0.34912"
"165.60000","13.80026","0.35301"
"166.08000","13.84020","0.35538"
"166.56000","13.88026","0.35649"
"167.04000","13.92020","0.35689"
"167.52000","13.96014","0.35738"
"168.00000","14.00020","0.35851"
"168.48000","14.04020","0.35990"
"168.96000","14.08020","0.36401"
"169.44000","14.12026","0.36807"
"169.92000","14.16020","0.37335"
"170.40000","14.20019","0.38013"
"170.88000","14.24019","0.38738"
"171.36000","14.28019","0.39494"
"171.84000","14.32013","0.40175"
"172.32000","14.36019","0.40544"
"172.80000","14.40025","0.40911"
"173.28000","14.44019","0.41497"
"173.76000","14.48025","0.42133"
"174.24000","14.52019","0.42864"
"174.72000","14.56019","0.43287"
"175.20000","14.60025","0.43694"
"175.68000","14.64019","0.44046"
"176.16000","14.68013","0.44306"
"176.64000","14.72018","0.44590"
"177.12000","14.76018","0.45018"
"177.60000","14.80018","0.45462"
"178.08000","14.84024","0.45905"
"178.56000","14.88018","0.45051"
"179.04000","14.92024","0.45428"
"179.52000","14.96024","0.45736"
"180.00000","15.00018","0.46163"
"180.48000","15.04012","0.46749"
"180.96000","15.08018","0.47322"
"181.44000","15.12018","0.47896"
"181.92000","15.16023","0.48578"
"182.40000","15.20017","0.49266"
"182.88000","15.24023","0.49906"
"183.36000","15.28023","0.50332"
"183.84000","15.32023","0.50550"
"184.32000","15.36023","0.50818"
"184.80000","15.40023","0.51672"
"185.28000","15.44011","0.52806"
"185.76000","15.48017","0.53811"
"186.24000","15.52023","0.54652"
"186.72000","15.56023","0.55384"
"187.20000","15.60023","0.55967"
"187.68000","15.64022","0.56453"
"188.16000","15.68022","0.56730"
"188.64000","15.72016","0.56889"
"189.12000","15.76022","0.47112"
"189.60000","15.80016","0.47190"
"190.08000","15.84022","0.47831"
"190.56000","15.88022","0.48338"
"191.04000","15.92016","0.49193"
"191.52000","15.96022","0.50227"
"192.00000","16.00022","0.50520"
"192.48000","16.04021","0.50867"
"192.96000","16.08022","0.52092"
"193.44000","16.12021","0.53767"
"193.92000","16.16015","0.55126"
"194.40000","16.20015","0.56051"
"194.88000","16.24021","0.56581"
"195.36000","16.28021","0.56866"
"195.84000","16.32021","0.57242"
"196.32000","16.36021","0.58014"
"196.80000","16.40021","0.59426"
"197.28000","16.44021","0.60587"
"197.76000","16.48021","0.61249"
"198.24000","16.52021","0.62260"
"198.72000","16.56021","0.63455"
"199.20000","16.60015","0.60879"
"199.68000","16.64021","0.61283"
"200.16000","16.68020","0.62096"
"200.64000","16.72020","0.63292"
"201.12000","16.76020","0.64340"
"201.60000","16.80026","0.63776"
"202.08000","16.84020","0.43190"
"202.56000","16.88014","0.43341"
"203.04000","16.92014","0.28337"
"203.52000","16.96020","0.29148"
"204.00000","17.00020","0.29437"
"204.48000","17.04026","0.30430"
"204.96000","17.08026","0.31597"
"205.44000","17.12019","0.33895"
"205.92000","17.16025","0.34780"
"206.40000","17.20019","0.35605"
"206.88000","17.24019","0.35685"
"207.36000","17.28019","0.36001"
"207.84000","17.32019","0.36539"
"208.32000","17.36019","0.37638"
"208.80000","17.40019","0.39455"
"209.28000","17.44019","0.40235"
"209.76000","17.48025","0.41008"
"210.24000","17.52025","0.42332"
"210.72000","17.56025","0.43023"
"211.20000","17.60018","0.42555"
"211.68000","17.64007","0.43427"
"212.16000","17.68018","0.43895"
"212.64000","17.72018","0.44437"
"213.12000","17.76024","0.45225"
"213.60000","17.80018","0.45980"
"214.08000","17.84024","0.46775"
"214.56000","17.88018","0.47949"
"215.04000","17.92024","0.49234"
"215.52000","17.96024","0.50241"
"216.00000","18.00018","0.50491"
"216.48000","18.04018","0.51255"
"216.96000","18.08018","0.53100"
"217.44000","18.12017","0.54725"
"217.92000","18.16017","0.55767"
"218.40000","18.20023","0.56535"
"218.88000","18.24023","0.56815"
"219.36000","18.28023","0.57280"
"219.84000","18.32023","0.58344"
"220.32000","18.36017","0.59965"
"220.80000","18.40017","0.60937"
"221.28000","18.44023","0.61797"
"221.76000","18.48017","0.63010"
"222.24000","18.52023","0.64245"
"222.72000","18.56022","0.65106"
"223.20000","18.60017","0.65584"
"223.68000","18.64022","0.65764"
"224.16000","18.68022","0.66145"
"224.64000","18.72016","0.66830"
"225.12000","18.76022","0.67849"
"225.60000","18.80022","0.69024"
"226.08000","18.84016","0.70390"
"226.56000","18.88022","0.71371"
"227.04000","18.92022","0.71696"
"227.52000","18.96022","0.72322"
"228.00000","19.00022","0.73741"
"228.48000","19.04022","0.74972"
"228.96000","19.08015","0.75884"
"229.44000","19.12021","0.76403"
"229.92000","19.16009","0.76715"
"230.40000","19.20015","0.77053"
"230.88000","19.24027","0.77568"
"231.36000","19.28027","0.78520"
"231.84000","19.32021","0.79858"
"232.32000","19.36027","0.80770"
"232.80000","19.40021","0.81303"
"233.28000","19.44021","0.82541"
"233.76000","19.48021","0.84280"
"234.24000","19.52015","0.85655"
"234.72000","19.56021","0.86559"
"235.20000","19.60015","0.87030"
"235.68000","19.64026","0.64224"
"236.16000","19.68020","0.65287"
"236.64000","19.72026","0.65679"
"237.12000","19.76026","0.66193"
"237.60000","19.80020","0.67413"
"238.08000","19.84020","0.69219"
"238.56000","19.88014","0.71152"
"239.04000","19.92020","0.71781"
"239.52000","19.96020","0.73426"
"240.00000","20.00026","0.75333"
"240.48000","20.04025","0.76329"
"240.96000","20.08019","0.76853"
"241.44000","20.12019","0.77613"
"241.92000","20.16025","0.79415"
"242.40000","20.20013","0.80856"
"242.88000","20.24013","0.81269"
"243.36000","20.28019","0.82580"
"243.84000","20.32019","0.84666"
"244.32000","20.36019","0.86272"
"244.80000","20.40019","0.87020"
"245.28000","20.44025","0.87541"
"245.76000","20.48025","0.88021"
"246.24000","20.52024","0.88863"
"246.72000","20.56019","0.90076"
"247.20000","20.60012","0.91296"
"247.68000","20.64018","0.91846"
"248.16000","20.68018","0.93066"
"248.64000","20.72024","0.94988"
"249.12000","20.76024","0.95883"
"249.60000","20.80018","0.96413"
"250.08000","20.84024","0.97270"
"250.56000","20.88024","0.98127"
"251.04000","20.92018","0.99213"
"251.52000","20.96018","1.00699"
"252.00000","21.00024","1.02202"
"252.48000","21.04024","1.02884"
"252.96000","21.08023","1.03897"
"253.44000","21.12024","1.04927"
"253.92000","21.16023","1.05620"
"254.40000","21.20029","1.04549"
"254.88000","21.24023","1.05370"
"255.36000","21.28011","1.06170"
"255.84000","21.32023","1.06584"
"256.32000","21.36017","1.06771"
"256.80000","21.40017","1.06906"
"257.28000","21.44023","1.07262"
"257.76000","21.48023","1.08081"
"258.24000","21.52023","1.09216"
"258.72000","21.56023","1.10608"
"259.20000","21.60022","1.12033"
"259.68000","21.64022","1.12942"
"260.16000","21.68016","1.14025"
"260.64000","21.72016","1.16067"
"261.12000","21.76016","1.17456"
"261.60000","21.80022","1.18298"
"262.08000","21.84016","1.18651"
"262.56000","21.88022","1.18898"
"263.04000","21.92022","1.19310"
"263.52000","21.96022","1.20256"
"264.00000","22.00022","0.96136"
"264.48000","22.04022","0.96231"
"264.96000","22.08015","0.96964"
"265.44000","22.12016","0.97839"
"265.92000","22.16021","0.99485"
"266.40000","22.20015","1.01775"
"266.88000","22.24021","1.03100"
"267.36000","22.28021","1.04892"
"267.84000","22.32027","1.06119"
"268.32000","22.36021","1.06768"
"268.80000","22.40015","1.07156"
"269.28000","22.44015","1.08350"
"269.76000","22.48014","1.10175"
"270.24000","22.52015","1.12207"
"270.72000","22.56021","1.13129"
"271.20000","22.60027","1.15251"
"271.68000","22.64020","1.17084"
"272.16000","22.68026","1.18225"
"272.64000","22.72026","1.18686"
"273.12000","22.76020","1.18971"
"273.60000","22.80014","1.19591"
"274.08000","22.84020","1.21046"
"274.56000","22.88020","1.22118"
"275.04000","22.92020","1.23428"
"275.52000","22.96020","1.25261"
"276.00000","23.00020","1.26576"
"276.48000","23.04020","1.27707"
"276.96000","23.08026","1.28189"
"277.44000","23.12020","1.28974"
"277.92000","23.16019","1.30375"
"278.40000","23.20019","1.31737"
"278.88000","23.24013","1.33018"
"279.36000","23.28019","1.33653"
"279.84000","23.32025","1.33961"
"280.32000","23.36025","1.34796"
"280.80000","23.40019","1.35934"
"281.28000","23.44019","1.36800"
"281.76000","23.48019","1.30554"
"282.24000","23.52024","0.75485"
"282.72000","23.56018","0.76208"
"283.20000","23.60018","0.76813"
"283.68000","23.64018","0.77771"
"284.16000","23.68018","0.79794"
"284.64000","23.72024","0.81335"
"285.12000","23.76024","0.84115"
"285.60000","23.80018","0.86395"
"286.08000","23.84018","0.87339"
"286.56000","23.88024","0.88179"
"287.04000","23.92018","0.89695"
"287.52000","23.96012","0.91533"
"288.00000","24.00018","0.92980"
"288.48000","24.04017","0.94651"
"288.96000","24.08017","0.96119"
"289.44000","24.12023","0.96958"
"289.92000","24.16023","0.98459"
"290.40000","24.20017","1.00373"
"290.88000","24.24023","1.02644"
"291.36000","24.28017","1.04234"
"291.84000","24.32023","1.05861"
"292.32000","24.36017","1.06695"
"292.80000","24.40023","1.07254"
"293.28000","24.44023","1.08840"
"293.76000","24.48022","1.11128"
"294.24000","24.52017","1.12811"
"294.72000","24.56022","1.15041"
"295.20000","24.60023","1.17481"
"295.68000","24.64022","1.18487"
"296.16000","24.68016","1.18885"
"296.64000","24.72016","1.19539"
"297.12000","24.76022","1.21258"
"297.60000","24.80022","1.22612"
"298.08000","24.84022","1.24839"
"298.56000","24.88022","1.26658"
"299.04000","24.92028","1.10874"
"299.52000","24.96022","1.11474"
"300.00000","25.00022","1.12613"
"300.48000","25.04016","1.14333"
"300.96000","25.08015","1.16845"
"301.44000","25.12021","1.18367"
"301.92000","25.16021","1.18808"
"302.40000","25.20021","1.19488"
"302.88000","25.24021","1.21316"
"303.36000","25.28021","1.22699"
"303.84000","25.32021","1.25196"
"304.32000","25.36021","1.26863"
"304.80000","25.40021","1.27956"
"305.28000","25.44015","1.28634"
"305.76000","25.48021","1.30291"
"306.24000","25.52021","1.32253"
"306.72000","25.56020","1.33490"
"307.20000","25.60027","1.33932"
"307.68000","25.64021","1.35411"
"308.16000","25.68020","1.36504"
"308.64000","25.72026","1.37500"
"309.12000","25.76020","1.38696"
"309.60000","25.80014","1.40198"
"310.08000","25.84020","1.41497"
"310.56000","25.88020","1.43235"
"311.04000","25.92020","1.44807"
"311.52000","25.96020","1.31843"
"312.00000","26.00020","1.32006"
"312.48000","26.04020","1.33036"
"312.96000","26.08025","1.33666"
"313.44000","26.12019","1.34585"
"313.92000","26.16013","1.36199"
"314.40000","26.20019","1.37255"
"314.88000","26.24019","1.38427"
"315.36000","26.28019","1.40150"
"315.84000","26.32025","1.41799"
"316.32000","26.36019","1.43505"
"316.80000","26.40025","1.45159"
"317.28000","26.44019","1.47161"
"317.76000","26.48018","1.48447"
"318.24000","26.52019","1.48775"
"318.72000","26.56018","1.48798"
"319.20000","26.60018","1.49139"
"319.68000","26.64018","1.50110"
"320.16000","26.68018","1.46860"
"320.64000","26.72018","1.47782"
"321.12000","26.76018","1.48595"
"321.60000","26.80024","1.48783"
"322.08000","26.84024","1.48838"
"322.56000","26.88018","1.49543"
"323.04000","26.92012","1.51009"
"323.52000","26.96018","1.53077"
"324.00000","27.00023","1.54498"
"324.48000","27.04023","1.56270"
"324.96000","27.08023","1.57665"
"325.44000","27.12023","1.59089"
"325.92000","27.16023","1.60155"
"326.40000","27.20023","1.60955"
"326.88000","27.24023","1.61948"
"327.36000","27.28017","1.63237"
"327.84000","27.32017","1.63993"
"328.32000","27.36023","1.64438"
"328.80000","27.40023","1.65794"
"329.28000","27.44023","1.67527"
"329.76000","27.48023","1.68878"
"330.24000","27.52023","1.69533"
"330.72000","27.56023","1.70418"
"331.20000","27.60023","1.71705"
"331.68000","27.64016","1.49935"
"332.16000","27.68016","1.50092"
"332.64000","27.72022","1.51231"
"333.12000","27.76022","1.41266"
"333.60000","27.80028","0.50273"
"334.08000","27.84022","0.54300"
"334.56000","27.88016","0.55794"
"335.04000","27.92022","0.60628"
"335.52000","27.96022","0.63235"
"336.00000","28.00016","0.61930"
"336.48000","28.04016","0.62116"
"336.96000","28.08016","0.64276"
"337.44000","28.12015","0.65575"
"337.92000","28.16021","0.66025"
"338.40000","28.20021","0.67497"
"338.88000","28.24021","0.69842"
"339.36000","28.28027","0.71555"
"339.84000","28.32021","0.72879"
"340.32000","28.36015","0.75158"
"340.80000","28.40015","0.76317"
"341.28000","28.44021","0.76917"
"341.76000","28.48015","0.77835"
"342.24000","28.52021","0.79888"
"342.72000","28.56026","0.81343"
"343.20000","28.60026","0.74753"
"343.68000","28.64026","0.76041"
"344.16000","28.68020","0.76695"
"344.64000","28.72020","0.77356"
"345.12000","28.76014","0.79100"
"345.60000","28.80020","0.80883"
"346.08000","28.84020","0.82077"
"346.56000","28.88020","0.84432"
"347.04000","28.92020","0.86060"
"347.52000","28.96026","0.86939"
"348.00000","29.00026","0.87631"
"348.48000","29.04026","0.88494"
"348.96000","29.08025","0.90026"
"349.44000","29.12013","0.91460"
"349.92000","29.16019","0.92188"
"350.40000","29.20025","0.94158"
"350.88000","29.24019","0.95826"
"351.36000","29.28025","0.87465"
"351.84000","29.32025","0.88502"
"352.32000","29.36019","0.90086"
"352.80000","29.40019","0.91585"
"353.28000","29.44019","0.92177"
"353.76000","29.48019","0.93740"
"354.24000","29.52019","0.95587"
"354.72000","29.56019","0.96767"
"355.20000","29.60018","0.98493"
"355.68000","29.64024","0.99883"
"356.16000","29.68018","1.01119"
"356.64000","29.72018","1.02669"
"357.12000","29.76024","1.04339"
"357.60000","29.80024","0.71514"
"358.08000","29.84012","0.71786"
"358.56000","29.88018","0.73737"
"359.04000","29.92012","0.69731"
"359.52000","29.96018","0.71448"
"360.00000","30.00024","0.70929"
"360.48000","30.04024","0.71591"
"360.96000","30.08017","0.73206"
"361.44000","30.12029","0.76083"
"361.92000","30.16023","0.76691"
"362.40000","30.20017","0.77073"
"362.88000","30.24017","0.33434"
"363.36000","30.28017","0.29510"
"363.84000","30.32011","0.26882"
"364.32000","30.36023","0.29553"
"364.80000","30.40023","0.28446"
"365.28000","30.44023","0.30066"
"365.76000","30.48029","0.29482"
"366.24000","30.52023","0.19044"
"366.72000","30.56017","0.19514"
"367.20000","30.60022","0.19138"
"367.68000","30.64016","0.20539"
"368.16000","30.68016","0.20104"
"368.64000","30.72022","0.20625"
"369.12000","30.76028","0.22963"
"369.60000","30.80022","0.23360"
"370.08000","30.84022","0.23792"
"370.56000","30.88022","0.24136"
"371.04000","30.92022","0.23568"
"371.52000","30.96022","0.24415"
"372.00000","31.00016","0.24882"
"372.48000","31.04015","0.25341"
"372.96000","31.08022","0.25456"
"373.44000","31.12021","0.25384"
"373.92000","31.16021","0.25929"
"374.40000","31.20021","0.26813"
"374.88000","31.24021","0.27509"
"375.36000","31.28021","0.27485"
"375.84000","31.32021","0.27847"
"376.32000","31.36015","0.28720"
"376.80000","31.40015","0.29157"
"377.28000","31.44021","0.29368"
"377.76000","31.48020","0.29676"
"378.24000","31.52020","0.30374"
"378.72000","31.56021","0.30838"
"379.20000","31.60020","0.31238"
"379.68000","31.64020","0.32519"
"380.16000","31.68014","0.33448"
"380.64000","31.72014","0.33884"
"381.12000","31.76020","0.34509"
"381.60000","31.80020","0.35190"
"382.08000","31.84020","0.35365"
"382.56000","31.88026","0.35554"
"383.04000","31.92019","0.35653"
"383.52000","31.96026","0.35722"
"384.00000","32.00026","0.35877"
"384.48000","32.04013","0.35978"
"384.96000","32.08019","0.36111"
"385.44000","32.12013","0.36491"
"385.92000","32.16019","0.36956"
"386.40000","32.20025","0.37413"
"386.88000","32.24025","0.38133"
"387.36000","32.28019","0.38828"
"387.84000","32.32025","0.39482"
"388.32000","32.36019","0.40112"
"388.80000","32.40019","0.40465"
"389.28000","32.44019","0.40906"
"389.76000","32.48018","0.41353"
"390.24000","32.52012","0.41903"
"390.72000","32.56025","0.42496"
"391.20000","32.60018","0.42910"
"391.68000","32.64024","0.43257"
"392.16000","32.68024","0.43705"
"392.64000","32.72024","0.43942"
"393.12000","32.76018","0.44222"
"393.60000","32.80018","0.44439"
"394.08000","32.84012","0.44761"
"394.56000","32.88018","0.45144"
"395.04000","32.92024","0.45542"
"395.52000","32.96024","0.45900"
"396.00000","33.00018","0.46406"
"396.48000","33.04023","0.46729"
"396.96000","33.08029","0.47289"
"397.44000","33.12017","0.47790"
"397.92000","33.16017","0.48357"
"398.40000","33.20017","0.48884"
"398.88000","33.24017","0.49431"
"399.36000","33.28023","0.49893"
"399.84000","33.32017","0.50292"
"400.32000","33.36023","0.50429"
"400.80000","33.40023","0.50594"
"401.28000","33.44022","0.50828"
"401.76000","33.48022","0.51340"
"402.24000","33.52023","0.51989"
"402.72000","33.56017","0.52785"
"403.20000","33.60016","0.53622"
"403.68000","33.64022","0.54307"
"404.16000","33.68016","0.54993"
"404.64000","33.72022","0.55462"
"405.12000","33.76022","0.55972"
"405.60000","33.80022","0.56284"
"406.08000","33.84022","0.56526"
"406.56000","33.88015","0.56726"
"407.04000","33.92016","0.56882"
"407.52000","33.96016","0.57081"
"408.00000","34.00016","0.57153"
"408.48000","34.04015","0.18727"
"408.96000","34.08027","0.19597"
"409.44000","34.12027","0.19393"
"409.92000","34.16021","0.19563"
"410.40000","34.20021","0.19759"
"410.88000","34.24021","0.20068"
"411.36000","34.28021","0.20296"
"411.84000","34.32021","0.20608"
"412.32000","34.36015","0.20920"
"412.80000","34.40015","0.21168"
"413.28000","34.44020","0.21259"
"413.76000","34.48021","0.21169"
"414.24000","34.52021","0.20895"
"414.72000","34.56026","0.20772"
"415.20000","34.60014","0.20743"
"415.68000","34.64020","0.20713"
"416.16000","34.68014","0.20904"
"416.64000","34.72014","0.21097"
"417.12000","34.76020","0.21296"
"417.60000","34.80020","0.21625"
"418.08000","34.84026","0.21947"
"418.56000","34.88026","0.22454"
"419.04000","34.92020","0.22849"
"419.52000","34.96019","0.22882"
"420.00000","35.00025","0.22745"
"420.48000","35.04019","0.22604"
"420.96000","35.08014","0.22606"
"421.44000","35.12019","0.22645"
"421.92000","35.16025","0.22912"
"422.40000","35.20019","0.23245"
"422.88000","35.24025","0.23534"
"423.36000","35.28019","0.23920"
"423.84000","35.32019","0.24120"
"424.32000","35.36019","0.24165"
"424.80000","35.40018","0.24076"
"425.28000","35.44012","0.23980"
"425.76000","35.48019","0.24111"
"426.24000","35.52018","0.24185"
"426.72000","35.56024","0.24411"
"427.20000","35.60024","0.24591"
"427.68000","35.64018","0.24724"
"428.16000","35.68024","0.24763"
"428.64000","35.72018","0.24747"
"429.12000","35.76018","0.24741"
"429.60000","35.80018","0.24775"
"430.08000","35.84018","0.24875"
"430.56000","35.88024","0.24989"
"431.04000","35.92018","0.25163"
"431.52000","35.96024","0.25235"
"432.00000","36.00017","0.25228"
"432.48000","36.04029","0.25190"
"432.96000","36.08023","0.25237"
"433.44000","36.12017","0.25367"
"433.92000","36.16023","0.25559"
"434.40000","36.20011","0.25746"
"434.88000","36.24017","0.25827"
"435.36000","36.28023","0.25825"
"435.84000","36.32023","0.25839"
"436.32000","36.36023","0.25972"
"436.80000","36.40023","0.26258"
"437.28000","36.44023","0.26516"
"437.76000","36.48022","0.26669"
"438.24000","36.52016","0.26734"
"438.72000","36.56016","0.26764"
"439.20000","36.60022","0.26914"
"439.68000","36.64022","0.27185"
"440.16000","36.68022","0.27471"
"440.64000","36.72022","0.27578"
"441.12000","36.76022","0.27551"
"441.60000","36.80016","0.27666"
"442.08000","36.84022","0.27803"
"442.56000","36.88022","0.28017"
"443.04000","36.92015","0.28204"
"443.52000","36.96021","0.28163"
"444.00000","37.00021","0.28299"
"444.48000","37.04021","0.28441"
"444.96000","37.08027","0.28716"
"445.44000","37.12021","0.28891"
"445.92000","37.16021","0.28907"
"446.40000","37.20021","0.29025"
"446.88000","37.24015","0.29180"
"447.36000","37.28009","0.29327"
"447.84000","37.32021","0.29455"
"448.32000","37.36021","0.29572"
"448.80000","37.40015","0.29606"
"449.28000","37.44021","0.29705"
"449.76000","37.48021","0.29874"
"450.24000","37.52020","0.29957"
"450.72000","37.56026","0.30037"
"451.20000","37.60020","0.30143"
"451.68000","37.64014","0.30340"
"452.16000","37.68020","0.30565"
"452.64000","37.72014","0.30748"
"453.12000","37.76020","0.30845"
"453.60000","37.80020","0.31087"
"454.08000","37.84026","0.31456"
"454.56000","37.88020","0.31788"
"455.04000","37.92020","0.31914"
"455.52000","37.96019","0.32139"
"456.00000","38.00019","0.32610"
"456.48000","38.04020","0.32823"
"456.96000","38.08014","0.33030"
"457.44000","38.12025","0.33207"
"457.92000","38.16019","0.33575"
"458.40000","38.20019","0.33863"
"458.88000","38.24019","0.34003"
"459.36000","38.28025","0.34066"
"459.84000","38.32019","0.34324"
"460.32000","38.36019","0.34593"
"460.80000","38.40013","0.34783"
"461.28000","38.44019","0.34868"
"461.76000","38.48019","0.35045"
"462.24000","38.52024","0.35225"
"462.72000","38.56024","0.35361"
"463.20000","38.60024","0.35408"
"463.68000","38.64024","0.35481"
"464.16000","38.68018","0.35526"
"464.64000","38.72024","0.35571"
"465.12000","38.76012","0.35593"
"465.60000","38.80018","0.35640"
"466.08000","38.84024","0.35663"
"466.56000","38.88018","0.35671"
"467.04000","38.92017","0.35681"
"467.52000","38.96017","0.35708"
"468.00000","39.00024","0.35737"
"468.48000","39.04029","0.35755"
"468.96000","39.08023","0.35823"
"469.44000","39.12017","0.35822"
"469.92000","39.16017","0.35894"
"470.40000","39.20017","0.35954"
"470.88000","39.24017","0.35999"
"471.36000","39.28028","0.36165"
"471.84000","39.32022","0.36263"
"472.32000","39.36017","0.36305"
"472.80000","39.40029","0.36470"
"473.28000","39.44023","0.36627"
"473.76000","39.48016","0.36770"
"474.24000","39.52016","0.36961"
"474.72000","39.56017","0.37110"
"475.20000","39.60016","0.37298"
"475.68000","39.64022","0.37525"
"476.16000","39.68022","0.37752"
"476.64000","39.72016","0.38011"
"477.12000","39.76028","0.38286"
"477.60000","39.80022","0.38613"
"478.08000","39.84016","0.38787"
"478.56000","39.88016","0.39118"
"479.04000","39.92022","0.39461"
"479.52000","39.96015","0.39699"
"480.00000","40.00021","0.39903"
"480.48000","40.04021","0.40079"
"480.96000","40.08021","0.40226"
"481.44000","40.12020","0.40314"
"481.92000","40.16021","0.40482"
"482.40000","40.20015","0.40573"
"482.88000","40.24015","0.40690"
"483.36000","40.28021","0.40819"
"483.84000","40.32020","0.40905"
"484.32000","40.36015","0.41114"
"484.80000","40.40027","0.41246"
"485.28000","40.44020","0.41507"
"485.76000","40.48020","0.41786"
"486.24000","40.52020","0.41914"
"486.72000","40.56020","0.42235"
"487.20000","40.60014","0.42445"
"487.68000","40.64014","0.42618"
"488.16000","40.68020","0.42847"
"488.64000","40.72020","0.42963"
"489.12000","40.76020","0.43113"
"489.60000","40.80026","0.43296"
"490.08000","40.84019","0.43469"
"490.56000","40.88020","0.43561"
"491.04000","40.92026","0.43768"
"491.52000","40.96020","0.43842"
"492.00000","41.00019","0.43957"
"492.48000","41.04019","0.44068"
"492.96000","41.08013","0.44172"
"493.44000","41.12019","0.44247"
"493.92000","41.16025","0.44342"
"494.40000","41.20019","0.44464"
"494.88000","41.24025","0.00943"
"495.36000","41.28019","0.00562"
"495.84000","41.32019","0.00066"
"496.32000","41.36019","0.00674"
"496.80000","41.40019","0.00837"
"497.28000","41.44019","0.00679"
"497.76000","41.48024","0.00245"
"498.24000","41.52024","0.00262"
"498.72000","41.56018","0.00278"
"499.20000","41.60024","0.01040"
"499.68000","41.64018","0.00866"
"500.16000","41.68018","0.00463"
"500.64000","41.72024","0.00191"
"501.12000","41.76018","0.00252"
"501.60000","41.80018","0.00591"
"502.08000","41.84023","0.00713"
"502.56000","41.88018","0.00641"
"503.04000","41.92017","0.00330"
"503.52000","41.96024","0.00205"
"504.00000","42.00023","0.00356"
"504.48000","42.04017","0.00608"
"504.96000","42.08023","0.00731"
"505.44000","42.12011","0.00353"
"505.92000","42.16017","0.00177"
"506.40000","42.20023","0.00253"
"506.88000","42.24023","0.00414"
"507.36000","42.28023","0.00726"
"507.84000","42.32023","0.00543"
"508.32000","42.36023","0.00376"
"508.80000","42.40023","0.00360"
"509.28000","42.44017","0.00281"
"509.76000","42.48016","0.00539"
"510.24000","42.52023","0.00657"
"510.72000","42.56016","0.00566"
"511.20000","42.60022","0.00513"
"511.68000","42.64028","0.00491"
"512.16000","42.68022","0.00420"
"512.64000","42.72022","0.00467"
"513.12000","42.76022","0.00587"
"513.60000","42.80022","0.00501"
"514.08000","42.84015","0.00503"
"514.56000","42.88016","0.00498"
"515.04000","42.92022","0.00510"
"515.52000","42.96022","0.00590"
"516.00000","43.00021","0.00573"
"516.48000","43.04021","0.00507"
"516.96000","43.08027","0.00585"
"517.44000","43.12021","0.00485"
"517.92000","43.16021","0.00540"
"518.40000","43.20015","0.00592"
"518.88000","43.24021","0.00599"
"519.36000","43.28015","0.00554"
"519.84000","43.32021","0.00564"
"520.32000","43.36020","0.00595"
"520.80000","43.40021","0.00616"
"521.28000","43.44020","0.00616"
"521.76000","43.48027","0.00644"
"522.24000","43.52021","0.00585"
"522.72000","43.56014","0.00619"
"523.20000","43.60014","0.00670"
"523.68000","43.64014","0.00680"
"524.16000","43.68020","0.00689"
"524.64000","43.72026","0.00600"
"525.12000","43.76020","0.00686"
"525.60000","43.80025","0.00660"
"526.08000","43.84026","0.00727"
"526.56000","43.88020","0.00681"
"527.04000","43.92020","0.00685"
"527.52000","43.96014","0.00741"
"528.00000","44.00019","0.00737"
"528.48000","44.04020","0.00702"
"528.96000","44.08019","0.00758"
"529.44000","44.12019","0.00784"
"529.92000","44.16025","0.00737"
"530.40000","44.20025","0.00793"
"530.88000","44.24019","0.00786"
"531.36000","44.28019","0.00771"
"531.84000","44.32013","0.00777"
"532.32000","44.36018","0.00747"
"532.80000","44.40025","0.00874"
"533.28000","44.44019","0.00795"
"533.76000","44.48024","0.00818"
"534.24000","44.52018","0.00820"
"534.72000","44.56018","0.00816"
"535.20000","44.60018","0.00854"
"535.68000","44.64018","0.00839"
"536.16000","44.68018","0.00895"
"536.64000","44.72012","0.00878"
"537.12000","44.76018","0.00862"
"537.60000","44.80018","0.00925"
"538.08000","44.84024","0.00834"
"538.56000","44.88023","0.00939"
"539.04000","44.92023","0.00920"
"539.52000","44.96017","0.00940"
"540.00000","45.00017","0.00930"
"540.48000","45.04012","0.00935"
"540.96000","45.08017","0.00927"
"541.44000","45.12017","0.00931"
"541.92000","45.16022","0.00955"
"542.40000","45.20029","0.00958"
"542.88000","45.24023","0.00948"
"543.36000","45.28017","0.01003"
"543.84000","45.32028","0.01056"
"544.32000","45.36016","0.00974"
"544.80000","45.40017","0.01054"
"545.28000","45.44016","0.00971"
"545.76000","45.48017","0.01019"
"546.24000","45.52016","0.01000"
"546.72000","45.56022","0.00981"
"547.20000","45.60028","0.01032"
"547.68000","45.64022","0.01035"
"548.16000","45.68022","0.01042"
"548.64000","45.72016","0.01071"
"549.12000","45.76022","0.01098"
"549.60000","45.80022","0.01135"
"550.08000","45.84016","0.01091"
"550.56000","45.88021","0.01101"
"551.04000","45.92022","0.01134"
"551.52000","45.96016","0.01135"
"552.00000","46.00022","0.01176"
"552.48000","46.04021","0.01159"
"552.96000","46.08021","0.01184"
"553.44000","46.12021","0.01170"
"553.92000","46.16015","0.01155"
"554.40000","46.20015","0.01245"
"554.88000","46.24015","0.01239"
"555.36000","46.28021","0.01200"
"555.84000","46.32021","0.01203"
"556.32000","46.36027","0.01239"
"556.80000","46.40021","0.01304"
"557.28000","46.44020","0.01260"
"557.76000","46.48021","0.01291"
"558.24000","46.52020","0.01271"
"558.72000","46.56014","0.01320"
"559.20000","46.60020","0.01310"
"559.68000","46.64020","0.01364"
"560.16000","46.68020","0.01392"
"560.64000","46.72026","0.01383"
"561.12000","46.76020","0.01396"
"561.60000","46.80020","0.01388"
"562.08000","46.84020","0.01371"
"562.56000","46.88019","0.01384"
"563.04000","46.92014","0.01487"
"563.52000","46.96013","0.01443"
"564.00000","47.00019","0.01482"
"564.48000","47.04025","0.01509"
"564.96000","47.08025","0.01487"
"565.44000","47.12019","0.01524"
"565.92000","47.16025","0.01568"
"566.40000","47.20019","0.01518"
"566.88000","47.24013","0.01558"
"567.36000","47.28019","0.01531"
"567.84000","47.32018","0.01587"
"568.32000","47.36019","0.01612"
"568.80000","47.40024","0.01657"
"569.28000","47.44019","0.01637"
"569.76000","47.48019","0.01638"
"570.24000","47.52024","0.01739"
"570.72000","47.56024","0.01697"
"571.20000","47.60024","0.01713"
"571.68000","47.64012","0.01744"
"572.16000","47.68012","0.01741"
"572.64000","47.72018","0.01808"
"573.12000","47.76024","0.01815"
"573.60000","47.80017","0.01830"
"574.08000","47.84023","0.01812"
"574.56000","47.88023","0.01855"
"575.04000","47.92023","0.01846"
"575.52000","47.96024","0.01886"
"576.00000","48.00018","0.01896"
"576.48000","48.04012","0.01891"
"576.96000","48.08023","0.01982"
"577.44000","48.12023","0.01998"
"577.92000","48.16023","0.02004"
"578.40000","48.20023","0.01985"
"578.88000","48.24023","0.02020"
"579.36000","48.28023","0.02093"
"579.84000","48.32022","0.02112"
"580.32000","48.36023","0.02089"
"580.80000","48.40011","0.02238"
"581.28000","48.44017","0.02237"
"581.76000","48.48016","0.02214"
"582.24000","48.52016","0.02249"
"582.72000","48.56022","0.02234"
"583.20000","48.60022","0.02323"
"583.68000","48.64022","0.02339"
"584.16000","48.68022","0.02397"
"584.64000","48.72016","0.02358"
"585.12000","48.76010","0.02444"
"585.60000","48.80022","0.02465"
"586.08000","48.84016","0.02397"
"586.56000","48.88021","0.02512"
"587.04000","48.92022","0.02593"
"587.52000","48.96015","0.02562"
"588.00000","49.00021","0.02624"
"588.48000","49.04021","0.02665"
"588.96000","49.08021","0.02707"
"589.44000","49.12015","0.02708"
"589.92000","49.16021","0.02742"
"590.40000","49.20015","0.02817"
"590.88000","49.24021","0.02781"
"591.36000","49.28021","0.02851"
"591.84000","49.32027","0.02898"
"592.32000","49.36021","0.02886"
"592.80000","49.40020","0.02996"
"593.28000","49.44020","0.02968"
"593.76000","49.48020","0.03033"
"594.24000","49.52014","0.03081"
"594.72000","49.56020","0.03107"
"595.20000","49.60020","0.03147"
"595.68000","49.64026","0.03202"
"596.16000","49.68019","0.03249"
"596.64000","49.72026","0.03281"
"597.12000","49.76026","0.03270"
"597.60000","49.80020","0.03441"
"598.08000","49.84019","0.03434"
"598.56000","49.88013","0.03449"
"599.04000","49.92014","0.03521"
"599.52000","49.96020","0.03529"
"600.00000","50.00019","0.03565"
"600.48000","50.04025","0.03650"
"600.96000","50.08025","0.03707"
"601.44000","50.12019","0.03748"
"601.92000","50.16019","0.03738"
"602.40000","50.20024","0.03775"
"602.88000","50.24012","0.03907"
"603.36000","50.28019","0.03840"
"603.84000","50.32019","0.03927"
"604.32000","50.36019","0.03939"
"604.80000","50.40018","0.03966"
"605.28000","50.44019","0.04052"
"605.76000","50.48018","0.04055"
"606.24000","50.52024","0.04107"
"606.72000","50.56024","0.04149"
"607.20000","50.60012","0.04272"
"607.68000","50.64012","0.04221"
"608.16000","50.68018","0.04307"
"608.64000","50.72018","0.04341"
"609.12000","50.76024","0.04372"
"609.60000","50.80024","0.04430"
"610.08000","50.84017","0.04473"
"610.56000","50.88024","0.04481"
"611.04000","50.92023","0.04489"
"611.52000","50.96017","0.04581"
"612.00000","51.00018","0.04596"
"612.48000","51.04017","0.04589"
"612.96000","51.08017","0.04630"
"613.44000","51.12017","0.04682"
"613.92000","51.16023","0.04703"
"614.40000","51.20023","0.04722"
"614.88000","51.24023","0.04751"
"615.36000","51.28023","0.04762"
"615.84000","51.32016","0.04804"
"616.32000","51.36017","0.04846"
"616.80000","51.40016","0.04862"
"617.28000","51.44016","0.04931"
"617.76000","51.48022","0.04938"
"618.24000","51.52023","0.04964"
"618.72000","51.56022","0.05018"
"619.20000","51.60022","0.05022"
"619.68000","51.64022","0.05070"
"620.16000","51.68022","0.05121"
"620.64000","51.72016","0.05166"
"621.12000","51.76015","0.05196"
"621.60000","51.80022","0.05274"
"622.08000","51.84016","0.05346"
"622.56000","51.88022","0.05436"
"623.04000","51.92021","0.05447"
"623.52000","51.96022","0.05579"
"624.00000","52.00021","0.05624"
"624.48000","52.04021","0.05640"
"624.96000","52.08015","0.05814"
"625.44000","52.12015","0.05937"
"625.92000","52.16021","0.05921"
"626.40000","52.20021","0.06181"
"626.88000","52.24021","0.06228"
"627.36000","52.28020","0.06424"
"627.84000","52.32014","0.06524"
"628.32000","52.36026","0.06701"
"628.80000","52.40020","0.06797"
"629.28000","52.44015","0.06945"
"629.76000","52.48021","0.07123"
"630.24000","52.52020","0.07304"
"630.72000","52.56014","0.07434"
"631.20000","52.60020","0.07608"
"631.68000","52.64026","0.07667"
"632.16000","52.68020","0.07865"
"632.64000","52.72020","0.08070"
"633.12000","52.76020","0.08233"
"633.60000","52.80014","0.08317"
"634.08000","52.84019","0.08439"
"634.56000","52.88020","0.08714"
"635.04000","52.92019","0.08841"
"635.52000","52.96025","0.09016"
"636.00000","53.00026","0.09166"
"636.48000","53.04020","0.09297"
"636.96000","53.08025","0.09405"
"637.44000","53.12025","0.09492"
"637.92000","53.16019","0.09590"
"638.40000","53.20019","0.09676"
"638.88000","53.24013","0.09720"
"639.36000","53.28019","0.09879"
"639.84000","53.32025","0.09987"
"640.32000","53.36024","0.10141"
"640.80000","53.40019","0.10379"
"641.28000","53.44024","0.10607"
"641.76000","53.48024","0.10950"
"642.24000","53.52024","0.11238"
"642.72000","53.56018","0.11533"
"643.20000","53.60012","0.11852"
"643.68000","53.64018","0.12080"
"644.16000","53.68024","0.12295"
"644.64000","53.72024","0.09100"
"645.12000","53.76018","0.09443"
"645.60000","53.80024","0.09442"
"646.08000","53.84018","0.09243"
"646.56000","53.88018","0.09111"
"647.04000","53.92023","0.09159"
"647.52000","53.96017","0.09315"
"648.00000","54.00017","0.09536"
"648.48000","54.04018","0.09643"
"648.96000","54.08023","0.09721"
"649.44000","54.12023","0.09729"
"649.92000","54.16022","0.09731"
"650.40000","54.20023","0.09726"
"650.88000","54.24023","0.09753"
"651.36000","54.28017","0.09866"
"651.84000","54.32017","0.10049"
"652.32000","54.36016","0.10171"
"652.80000","54.40023","0.10286"
"653.28000","54.44022","0.10360"
"653.76000","54.48022","0.10438"
"654.24000","54.52022","0.10541"
"654.72000","54.56023","0.10674"
"655.20000","54.60022","0.10888"
"655.68000","54.64022","0.11081"
"656.16000","54.68016","0.11254"
"656.64000","54.72016","0.11432"
"657.12000","54.76016","0.11575"
"657.60000","54.80022","0.11727"
"658.08000","54.84022","0.11803"
"658.56000","54.88021","0.11898"
"659.04000","54.92028","0.12097"
"659.52000","54.96027","0.12199"
"660.00000","55.00015","0.12400"
"660.48000","55.04021","0.12449"
"660.96000","55.08015","0.12558"
"661.44000","55.12015","0.12684"
"661.92000","55.16027","0.12841"
"662.40000","55.20021","0.12923"
"662.88000","55.24021","0.12986"
"663.36000","55.28021","0.13124"
"663.84000","55.32021","0.13118"
"664.32000","55.36021","0.13264"
"664.80000","55.40015","0.13366"
"665.28000","55.44014","0.13446"
"665.76000","55.48014","0.13475"
"666.24000","55.52020","0.13553"
"666.72000","55.56020","0.13628"
"667.20000","55.60020","0.13712"
"667.68000","55.64026","0.13698"
"668.16000","55.68026","0.13822"
"668.64000","55.72020","0.13818"
"669.12000","55.76020","0.13884"
"669.60000","55.80014","0.13973"
"670.08000","55.84020","0.14005"
"670.56000","55.88019","0.14033"
"671.04000","55.92019","0.14076"
"671.52000","55.96019","0.14113"
"672.00000","56.00019","0.14148"
"672.48000","56.04025","0.14190"
"672.96000","56.08025","0.14208"
"673.44000","56.12019","0.14250"
"673.92000","56.16013","0.14272"
"674.40000","56.20019","0.14328"
"674.88000","56.24018","0.14379"
"675.36000","56.28012","0.14391"
"675.84000","56.32019","0.14438"
"676.32000","56.36025","0.14530"
"676.80000","56.40019","0.14543"
"677.28000","56.44024","0.14602"
"677.76000","56.48018","0.14652"
"678.24000","56.52012","0.14587"
"678.72000","56.56018","0.14622"
"679.20000","56.60018","0.14718"
"679.68000","56.64018","0.14781"
"680.16000","56.68018","0.14875"
"680.64000","56.72018","0.14957"
"681.12000","56.76023","0.15087"
"681.60000","56.80024","0.15244"
"682.08000","56.84024","0.15382"
"682.56000","56.88017","0.15547"
"683.04000","56.92018","0.15721"
"683.52000","56.96023","0.15858"
"684.00000","57.00018","0.16047"
"684.48000","57.04023","0.16172"
"684.96000","57.08023","0.16503"
"685.44000","57.12023","0.16743"
"685.92000","57.16023","0.16903"
"686.40000","57.20017","0.17142"
"686.88000","57.24023","0.17360"
"687.36000","57.28017","0.17616"
"687.84000","57.32017","0.17872"
"688.32000","57.36023","0.18174"
"688.80000","57.40022","0.18485"
"689.28000","57.44022","0.18635"
"689.76000","57.48022","0.18854"
"690.24000","57.52023","0.19043"
"690.72000","57.56022","0.19281"
"691.20000","57.60022","0.19345"
"691.68000","57.64016","0.19577"
"692.16000","57.68016","0.19735"
"692.64000","57.72016","0.19828"
"693.12000","57.76022","0.19906"
"693.60000","57.80022","0.20012"
"694.08000","57.84022","0.20120"
"694.56000","57.88021","0.20155"
"695.04000","57.92022","0.20251"
"695.52000","57.96021","0.20343"
"696.00000","58.00016","0.20399"
"696.48000","58.04015","0.20451"
"696.96000","58.08015","0.20560"
"697.44000","58.12016","0.20615"
"697.92000","58.16021","0.20731"
"698.40000","58.20027","0.20836"
"698.88000","58.24020","0.20983"
"699.36000","58.28021","0.21093"
"699.84000","58.32021","0.21209"
"700.32000","58.36021","0.21384"
"700.80000","58.40015","0.21473"
"701.28000","58.44014","0.21530"
"701.76000","58.48015","0.21731"
"702.24000","58.52021","0.21885"
"702.72000","58.56020","0.21991"
"703.20000","58.60020","0.22168"
"703.68000","58.64026","0.22283"
"704.16000","58.68026","0.22508"
"704.64000","58.72020","0.22584"
"705.12000","58.76020","0.22742"
"705.60000","58.80014","0.22897"
"706.08000","58.84019","0.23012"
"706.56000","58.88026","0.23189"
"707.04000","58.92025","0.23337"
"707.52000","58.96019","0.23491"
"708.00000","59.00025","0.23639"
"708.48000","59.04019","0.23748"
"708.96000","59.08020","0.23860"
"709.44000","59.12019","0.24042"
"709.92000","59.16013","0.24116"
"710.40000","59.20019","0.24205"
"710.88000","59.24018","0.24275"
"711.36000","59.28019","0.24371"
"711.84000","59.32025","0.24482"
"712.32000","59.36019","0.24563"
"712.80000","59.40018","0.24617"
"713.28000","59.44025","0.24687"
"713.76000","59.48018","0.24739"
"714.24000","59.52012","0.24779"
"714.72000","59.56024","0.24887"
"715.20000","59.60018","0.24918"
"715.68000","59.64018","-0.00268"
"716.16000","59.68024","0.00318"
"716.64000","59.72018","0.00040"
"717.12000","59.76023","0.00046"
"717.60000","59.80024","0.00109"
"718.08000","59.84024","-0.00018"
"718.56000","59.88012","0.00023"
"719.04000","59.92023","0.00109"
"719.07400","59.92299","0.00123"