File: Force_trajectories/170225_2/Specimen_RawData_2.csv
End date,"2/25/2017"
Specimen label,"1BG_6"
Maximum Load,"0.15376",N

Time,Extension,Load
(s),(mm),(N)
"0.00000","0.00000","0.00036"
"0.29400","0.02392","0.00092"
"0.58800","0.04921","0.00155"
"0.88200","0.07372","0.00101"
"1.17600","0.09817","0.00150"
"1.47000","0.12275","0.00172"
"1.76400","0.14720","0.00222"
"2.05800","0.17172","0.00217"
"2.35200","0.19617","0.00230"
"2.64600","0.22074","0.00205"
"2.94000","0.24526","0.00258"
"3.23400","0.26971","0.00242"
"3.52800","0.29428","0.00320"
"3.82200","0.31868","0.00272"
"4.11600","0.34325","0.00288"
"4.41000","0.36765","0.00332"
"4.70400","0.39222","0.00258"
"4.99800","0.41667","0.00326"
"5.29200","0.44119","0.00280"
"5.58600","0.46564","0.00377"
"5.88000","0.49015","0.00406"
"6.17400","0.51473","0.00383"
"6.46800","0.53918","0.00345"
"6.76200","0.56370","0.00377"
"7.05600","0.58815","0.00439"
"7.35000","0.61266","0.00393"
"7.64400","0.63712","0.00431"
"7.93800","0.66169","0.00431"
"8.23200","0.68620","0.00428"
"8.52600","0.71066","0.00404"
"8.82000","0.73517","0.00386"
"9.11400","0.75975","0.00445"
"9.40800","0.78426","0.00474"
"9.70200","0.80865","0.00470"
"9.99600","0.83317","0.00423"
"10.29000","0.85768","0.00512"
"10.58400","0.88219","0.00495"
"10.87800","0.90665","0.00495"
"11.17200","0.93122","0.00475"
"11.46600","0.95568","0.00498"
"11.76000","0.98019","0.00479"
"12.05400","1.00470","0.00510"
"12.34800","1.02922","0.00533"
"12.64200","1.05373","0.00558"
"12.93600","1.07818","0.00562"
"13.23000","1.10270","0.00520"
"13.52400","1.12715","0.00524"
"13.81800","1.15173","0.00549"
"14.11200","1.17618","0.00542"
"14.40600","1.20075","0.00586"
"14.70000","1.22521","0.00569"
"14.99400","1.24972","0.00567"
"15.28800","1.27417","0.00599"
"15.58200","1.29869","0.00566"
"15.87600","1.32326","0.00579"
"16.17000","1.34766","0.00546"
"16.46400","1.37217","0.00541"
"16.75800","1.39668","0.00529"
"17.05200","1.42120","0.00546"
"17.34600","1.44571","0.00562"
"17.64000","1.47028","0.00570"
"17.93400","1.49474","0.00582"
"18.22800","1.51919","0.00601"
"18.52200","1.54371","0.00608"
"18.81600","1.56816","0.00577"
"19.11000","1.59267","0.00621"
"19.40400","1.61719","0.00603"
"19.69800","1.64170","0.00629"
"19.99200","1.66615","0.00582"
"20.28600","1.69067","0.00638"
"20.58000","1.71518","0.00648"
"20.87400","1.73976","0.00621"
"21.16800","1.76421","0.00681"
"21.46200","1.78872","0.00588"
"21.75600","1.81324","0.00622"
"22.05000","1.83769","0.00675"
"22.34400","1.86226","0.00617"
"22.63800","1.88666","0.00713"
"22.93200","1.91117","0.00675"
"23.22600","1.93563","0.00661"
"23.52000","1.96020","0.00664"
"23.81400","1.98465","0.00627"
"24.10800","2.00923","0.00685"
"24.40200","2.03368","0.00669"
"24.69600","2.05819","0.00684"
"24.99000","2.08271","0.00694"
"25.28400","2.10716","0.00705"
"25.57800","2.13168","0.00698"
"25.87200","2.15613","0.00687"
"26.16600","2.18070","0.00695"
"26.46000","2.20516","0.00692"
"26.75400","2.22967","0.00679"
"27.04800","2.25418","0.00700"
"27.34200","2.27870","0.00673"
"27.63600","2.30321","0.00572"
"27.93000","2.32773","0.00609"
"28.22400","2.35224","0.00575"
"28.51800","2.37669","0.00530"
"28.81200","2.40121","0.00592"
"29.10600","2.42566","0.00560"
"29.40000","2.45023","0.00540"
"29.69400","2.47469","0.00558"
"29.98800","2.49920","0.00560"
"30.28200","2.52366","0.00574"
"30.57600","2.54823","0.00623"
"30.87000","2.57268","0.00573"
"31.16400","2.59714","0.00583"
"31.45800","2.62171","0.00557"
"31.75200","2.64616","0.00624"
"32.04600","2.67074","0.00603"
"32.34000","2.69513","0.00659"
"32.63400","2.71971","0.00605"
"32.92800","2.74416","0.00636"
"33.22200","2.76873","0.00658"
"33.51600","2.79319","0.00594"
"33.81000","2.81770","0.00591"
"34.10400","2.84222","0.00655"
"34.39800","2.86667","0.00644"
"34.69200","2.89118","0.00695"
"34.98600","2.91570","0.00674"
"35.28000","2.94027","0.00665"
"35.57400","2.96466","0.00658"
"35.86800","2.98918","0.00690"
"36.16200","3.01363","0.00618"
"36.45600","3.03820","0.00668"
"36.75000","3.06266","0.00697"
"37.04400","3.08717","0.00686"
"37.33800","3.11169","0.00646"
"37.63200","3.13620","0.00737"
"37.92600","3.16071","0.00660"
"38.22000","3.18517","0.00755"
"38.51400","3.20974","0.00718"
"38.80800","3.23414","0.00683"
"39.10200","3.25871","0.00704"
"39.39600","3.28322","0.00704"
"39.69000","3.30774","0.00750"
"39.98400","3.33219","0.00732"
"40.27800","3.35676","0.00728"
"40.57200","3.38122","0.00671"
"40.86600","3.40567","0.00727"
"41.16000","3.43024","0.00693"
"41.45400","3.45464","0.00767"
"41.74800","3.47915","0.00761"
"42.04200","3.50361","0.00738"
"42.33600","3.52824","0.00699"
"42.63000","3.55263","0.00708"
"42.92400","3.57721","0.00758"
"43.21800","3.60166","0.00726"
"43.51200","3.62618","0.00727"
"43.80600","3.65069","0.00801"
"44.10000","3.67520","0.00733"
"44.39400","3.69966","0.00791"
"44.68800","3.72417","0.00766"
"44.98200","3.74874","0.00780"
"45.27600","3.77320","0.00825"
"45.57000","3.79771","0.00742"
"45.86400","3.82217","0.00774"
"46.15800","3.84674","0.00770"
"46.45200","3.87119","0.00787"
"46.74600","3.89571","0.00787"
"47.04000","3.92022","0.00753"
"47.33400","3.94467","0.00759"
"47.62800","3.96925","0.00802"
"47.92200","3.99364","0.00793"
"48.21600","4.01822","0.00818"
"48.51000","4.04261","0.00778"
"48.80400","4.06724","0.00800"
"49.09800","4.09164","0.00822"
"49.39200","4.11621","0.00828"
"49.68600","4.14066","0.00853"
"49.98000","4.16518","0.00866"
"50.27400","4.18969","0.00853"
"50.56800","4.21421","0.00862"
"50.86200","4.23878","0.00846"
"51.15600","4.26323","0.00793"
"51.45000","4.28775","0.00813"
"51.74400","4.31220","0.00821"
"52.03800","4.33671","0.00889"
"52.33200","4.36117","0.00842"
"52.62600","4.38574","0.00847"
"52.92000","4.41020","0.00847"
"53.21400","4.43471","0.00839"
"53.50800","4.45922","0.00842"
"53.80200","4.48368","0.00835"
"54.09600","4.50825","0.00904"
"54.39000","4.53270","0.00867"
"54.68400","4.55716","0.00952"
"54.97800","4.58161","0.00898"
"55.27200","4.60619","0.00919"
"55.56600","4.63064","0.00884"
"55.86000","4.65521","0.00867"
"56.15400","4.67973","0.00895"
"56.44800","4.70418","0.00875"
"56.74200","4.72869","0.00869"
"57.03600","4.75315","0.00916"
"57.33000","4.77772","0.00932"
"57.62400","4.80218","0.00932"
"57.91800","4.82669","0.00915"
"58.21200","4.85114","0.00850"
"58.50600","4.87578","0.00983"
"58.80000","4.90017","0.00932"
"59.09400","4.92474","0.00959"
"59.38800","4.94914","0.00907"
"59.68200","4.97365","0.00942"
"59.97600","4.99817","0.00938"
"60.27000","5.02268","0.00962"
"60.56400","5.04719","0.00922"
"60.85800","5.07165","0.00910"
"61.15200","5.09622","0.00944"
"61.44600","5.12067","0.00977"
"61.74000","5.14519","0.00934"
"62.03400","5.16970","0.00941"
"62.32800","5.19422","0.00964"
"62.62200","5.21873","0.00975"
"62.91600","5.24324","0.00926"
"63.21000","5.26776","0.00972"
"63.50400","5.29221","0.01012"
"63.79800","5.31678","0.00957"
"64.09200","5.34118","0.00958"
"64.38600","5.36575","0.00935"
"64.68000","5.39009","0.00931"
"64.97400","5.41466","0.00981"
"65.26800","5.43917","0.00957"
"65.56200","5.46369","0.00976"
"65.85600","5.48814","0.01025"
"66.15000","5.51265","0.00964"
"66.44400","5.53723","0.00972"
"66.73800","5.56168","0.00984"
"67.03200","5.58614","0.01003"
"67.32600","5.61065","0.00970"
"67.62000","5.63516","0.01055"
"67.91400","5.65962","0.00980"
"68.20800","5.68419","0.00983"
"68.50200","5.70870","0.01022"
"68.79600","5.73322","0.01050"
"69.09000","5.75767","0.01015"
"69.38400","5.78219","0.01006"
"69.67800","5.80670","0.01027"
"69.97200","5.83121","0.01002"
"70.26600","5.85573","0.01041"
"70.56000","5.88018","0.01016"
"70.85400","5.90469","0.01071"
"71.14800","5.92915","0.01008"
"71.44200","5.95366","0.01077"
"71.73600","5.97818","0.01045"
"72.03000","6.00269","0.01045"
"72.32400","6.02720","0.01060"
"72.61800","6.05166","0.01033"
"72.91200","6.07623","0.01043"
"73.20600","6.10068","0.01084"
"73.50000","6.12520","0.01076"
"73.79400","6.14965","0.01024"
"74.08800","6.17417","0.01031"
"74.38200","6.19868","0.01031"
"74.67600","6.22325","0.01104"
"74.97000","6.24771","0.01089"
"75.26400","6.27228","0.01127"
"75.55800","6.29673","0.01083"
"75.85200","6.32125","0.01107"
"76.14600","6.34576","0.01034"
"76.44000","6.37016","0.01081"
"76.73400","6.39473","0.01110"
"77.02800","6.41918","0.01095"
"77.32200","6.44370","0.01112"
"77.61600","6.46815","0.01082"
"77.91000","6.49266","0.01111"
"78.20400","6.51718","0.01091"
"78.49800","6.54169","0.01086"
"78.79200","6.56621","0.01124"
"79.08600","6.59066","0.01112"
"79.38000","6.61517","0.01121"
"79.67400","6.63963","0.01101"
"79.96800","6.66414","0.01060"
"80.26200","6.68866","0.01150"
"80.55600","6.71323","0.01118"
"80.85000","6.73768","0.01107"
"81.14400","6.76226","0.01103"
"81.43800","6.78671","0.01121"
"81.73200","6.81122","0.01084"
"82.02600","6.83574","0.01086"
"82.32000","6.86013","0.01139"
"82.61400","6.88470","0.01087"
"82.90800","6.90916","0.01154"
"83.20200","6.93367","0.01192"
"83.49600","6.95813","0.01068"
"83.79000","6.98270","0.01145"
"84.08400","7.00715","0.01107"
"84.37800","7.03173","0.01177"
"84.67200","7.05618","0.01188"
"84.96600","7.08070","0.01127"
"85.26000","7.10521","0.01160"
"85.55400","7.12966","0.01160"
"85.84800","7.15424","0.01240"
"86.14200","7.17869","0.01215"
"86.43600","7.20320","0.01218"
"86.73000","7.22766","0.01144"
"87.02400","7.25217","0.01234"
"87.31800","7.27668","0.01184"
"87.61200","7.30120","0.01185"
"87.90600","7.32571","0.01176"
"88.20000","7.35023","0.01170"
"88.49400","7.37474","0.01194"
"88.78800","7.39919","0.01285"
"89.08200","7.42377","0.01258"
"89.37600","7.44816","0.01215"
"89.67000","7.47273","0.01224"
"89.96400","7.49719","0.01220"
"90.25800","7.52176","0.01245"
"90.55200","7.54610","0.01279"
"90.84600","7.57067","0.01259"
"91.14000","7.59518","0.01275"
"91.43400","7.61964","0.01254"
"91.72800","7.64415","0.01295"
"92.02200","7.66867","0.01327"
"92.31600","7.69324","0.01296"
"92.61000","7.71763","0.01276"
"92.90400","7.74221","0.01287"
"93.19800","7.76666","0.01298"
"93.49200","7.79123","0.01300"
"93.78600","7.81569","0.01329"
"94.08000","7.84020","0.01361"
"94.37400","7.86471","0.01356"
"94.66800","7.88917","0.01406"
"94.96200","7.91368","0.01302"
"95.25600","7.93820","0.01340"
"95.55000","7.96271","0.01332"
"95.84400","7.98716","0.01357"
"96.13800","8.01168","0.01368"
"96.43200","8.03613","0.01413"
"96.72600","8.06071","0.01379"
"97.02000","8.08516","0.01362"
"97.31400","8.10973","0.01405"
"97.60800","8.13419","0.01382"
"97.90200","8.15870","0.01422"
"98.19600","8.18321","0.01453"
"98.49000","8.20767","0.01397"
"98.78400","8.23224","0.01424"
"99.07800","8.25669","0.01456"
"99.37200","8.28127","0.01437"
"99.66600","8.30566","0.01462"
"99.96000","8.33024","0.01469"
"100.25400","8.35469","0.01402"
"100.54800","8.37920","0.01431"
"100.84200","8.40366","0.01469"
"101.13600","8.42817","0.01477"
"101.43000","8.45269","0.01448"
"101.72400","8.47714","0.01468"
"102.01800","8.50165","0.01472"
"102.31200","8.52611","0.01380"
"102.60600","8.55068","0.01422"
"102.90000","8.57513","0.01370"
"103.19400","8.59965","0.01435"
"103.48800","8.62416","0.01360"
"103.78200","8.64868","0.01402"
"104.07600","8.67319","0.01382"
"104.37000","8.69770","0.01390"
"104.66400","8.72222","0.01404"
"104.95800","8.74667","0.01336"
"105.25200","8.77124","0.01415"
"105.54600","8.79564","0.01362"
"105.84000","8.82021","0.01377"
"106.13400","8.84473","0.01393"
"106.42800","8.86918","0.01349"
"106.72200","8.89369","0.01383"
"107.01600","8.91821","0.01410"
"107.31000","8.94272","0.01416"
"107.60400","8.96717","0.01390"
"107.89800","8.99175","0.01411"
"108.19200","9.01614","0.01397"
"108.48600","9.04072","0.01387"
"108.78000","9.06511","0.01403"
"109.07400","9.08974","0.01450"
"109.36800","9.11414","0.01418"
"109.66200","9.13871","0.01456"
"109.95600","9.16316","0.01307"
"110.25000","9.18768","0.01405"
"110.54400","9.21219","0.01359"
"110.83800","9.23665","0.01463"
"111.13200","9.26122","0.01423"
"111.42600","9.28567","0.01469"
"111.72000","9.31025","0.01399"
"112.01400","9.33470","0.01461"
"112.30800","9.35921","0.01355"
"112.60200","9.38367","0.01472"
"112.89600","9.40818","0.01421"
"113.19000","9.43270","0.01434"
"113.48400","9.45715","0.01450"
"113.77800","9.48172","0.01465"
"114.07200","9.50612","0.01489"
"114.36600","9.53075","0.01450"
"114.66000","9.55520","0.01467"
"114.95400","9.57972","0.01473"
"115.24800","9.60411","0.01532"
"115.54200","9.62869","0.01498"
"115.83600","9.65314","0.01474"
"116.13000","9.67771","0.01507"
"116.42400","9.70217","0.01503"
"116.71800","9.72668","0.01503"
"117.01200","9.75119","0.01478"
"117.30600","9.77565","0.01507"
"117.60000","9.80022","0.01476"
"117.89400","9.82468","0.01564"
"118.18800","9.84919","0.01432"
"118.48200","9.87364","0.01562"
"118.77600","9.89822","0.01480"
"119.07000","9.92267","0.01547"
"119.36400","9.94724","0.01531"
"119.65800","9.97164","0.01517"
"119.95200","9.99621","0.01598"
"120.24600","10.02072","0.01547"
"120.54000","10.04518","0.01545"
"120.83400","10.06969","0.01545"
"121.12800","10.09415","0.01555"
"121.42200","10.11866","0.01526"
"121.71600","10.14311","0.01543"
"122.01000","10.16769","0.01511"
"122.30400","10.19220","0.01537"
"122.59800","10.21666","0.01564"
"122.89200","10.24123","0.01599"
"123.18600","10.26568","0.01586"
"123.48200","10.29044","0.01539"
"123.77600","10.31483","0.01601"
"124.07000","10.33940","0.01566"
"124.36400","10.36386","0.01589"
"124.65800","10.38843","0.01575"
"124.95200","10.41283","0.01602"
"125.24600","10.43740","0.01578"
"125.54000","10.46185","0.01654"
"125.83400","10.48637","0.01595"
"126.12800","10.51088","0.01589"
"126.42200","10.53539","0.01557"
"126.71600","10.55985","0.01598"
"127.01000","10.58430","0.01631"
"127.30400","10.60882","0.01603"
"127.59800","10.63333","0.01640"
"127.89200","10.65784","0.01638"
"128.18600","10.68224","0.01664"
"128.48000","10.70687","0.01661"
"128.77400","10.73132","0.01645"
"129.06800","10.75590","0.01666"
"129.36200","10.78041","0.01709"
"129.65600","10.80492","0.01679"
"129.95000","10.82944","0.01704"
"130.24400","10.85389","0.01625"
"130.53800","10.87841","0.01643"
"130.83200","10.90286","0.01650"
"131.12600","10.92737","0.01570"
"131.42000","10.95183","0.01635"
"131.71400","10.97634","0.01528"
"132.00800","11.00086","0.01605"
"132.30200","11.02531","0.01589"
"132.59600","11.04982","0.01427"
"132.89000","11.07434","0.01428"
"133.18400","11.09885","0.01353"
"133.47800","11.12331","0.01415"
"133.77200","11.14788","0.01426"
"134.06600","11.17233","0.01376"
"134.36000","11.19691","0.01408"
"134.65400","11.22136","0.01336"
"134.94800","11.24593","0.01426"
"135.24200","11.27039","0.01325"
"135.53600","11.29490","0.01405"
"135.83000","11.31936","0.01355"
"136.12400","11.34387","0.01338"
"136.41800","11.36838","0.01398"
"136.71200","11.39284","0.01383"
"137.00600","11.41735","0.01475"
"137.30000","11.44180","0.01385"
"137.59400","11.46638","0.01376"
"137.88800","11.49083","0.01478"
"138.18200","11.51534","0.01408"
"138.47600","11.53980","0.01426"
"138.77000","11.56431","0.01424"
"139.06400","11.58889","0.01433"
"139.35800","11.61334","0.01444"
"139.65200","11.63785","0.01408"
"139.94600","11.66231","0.01404"
"140.24000","11.68688","0.01519"
"140.53400","11.71134","0.01462"
"140.82800","11.73591","0.01394"
"141.12200","11.76036","0.01498"
"141.41600","11.78488","0.01475"
"141.71000","11.80939","0.01455"
"142.00400","11.83390","0.01475"
"142.29800","11.85842","0.01523"
"142.59200","11.88287","0.01500"
"142.88600","11.90738","0.01436"
"143.18000","11.93184","0.01474"
"143.47400","11.95635","0.01487"
"143.76800","11.98081","0.01463"
"144.06200","12.00538","0.01493"
"144.35600","12.02983","0.01482"
"144.65000","12.05435","0.01475"
"144.94400","12.07886","0.01506"
"145.23800","12.10338","0.01446"
"145.53200","12.12789","0.01477"
"145.82600","12.15234","0.01492"
"146.12000","12.17686","0.01477"
"146.41400","12.20131","0.01499"
"146.70800","12.22588","0.01548"
"147.00200","12.25034","0.01534"
"147.29600","12.27485","0.01522"
"147.59000","12.29936","0.01477"
"147.88400","12.32388","0.01485"
"148.17800","12.34839","0.01518"
"148.47200","12.37291","0.01389"
"148.76600","12.39736","0.01414"
"149.06000","12.42181","0.01375"
"149.35400","12.44639","0.01451"
"149.64800","12.47084","0.01449"
"149.94200","12.49535","0.01441"
"150.23600","12.51981","0.01465"
"150.53000","12.54438","0.01418"
"150.82400","12.56884","0.01436"
"151.11800","12.59335","0.01443"
"151.41200","12.61780","0.01425"
"151.70600","12.64232","0.01421"
"152.00000","12.66683","0.01486"
"152.29400","12.69135","0.01450"
"152.58800","12.71592","0.01454"
"152.88200","12.74031","0.01434"
"153.17600","12.76489","0.01526"
"153.47000","12.78934","0.01531"
"153.76400","12.81391","0.01473"
"154.05800","12.83837","0.01505"
"154.35200","12.86282","0.01517"
"154.64600","12.88733","0.01517"
"154.94000","12.91185","0.01504"
"155.23400","12.93636","0.01522"
"155.52800","12.96082","0.01443"
"155.82200","12.98539","0.01380"
"156.11600","13.00984","0.01419"
"156.41000","13.03436","0.01375"
"156.70400","13.05881","0.01397"
"156.99800","13.08339","0.01412"
"157.29200","13.10784","0.01380"
"157.58600","13.13235","0.01448"
"157.88000","13.15687","0.01412"
"158.17400","13.18138","0.01443"
"158.46800","13.20589","0.01442"
"158.76200","13.23035","0.01429"
"159.05600","13.25492","0.01517"
"159.35000","13.27931","0.01485"
"159.64400","13.30389","0.01491"
"159.93800","13.32834","0.01510"
"160.23200","13.35286","0.01438"
"160.52600","13.37737","0.01475"
"160.82000","13.40189","0.01507"
"161.11400","13.42640","0.01512"
"161.40800","13.45085","0.01487"
"161.70200","13.47537","0.01499"
"161.99600","13.49988","0.01536"
"162.29000","13.52439","0.01553"
"162.58400","13.54879","0.01478"
"162.87800","13.57336","0.01499"
"163.17200","13.59775","0.01503"
"163.46600","13.62233","0.01550"
"163.76000","13.64684","0.01532"
"164.05400","13.67135","0.01555"
"164.34800","13.69587","0.01547"
"164.64200","13.72032","0.01498"
"164.93600","13.74490","0.01519"
"165.23000","13.76935","0.01583"
"165.52400","13.79392","0.01540"
"165.81800","13.81832","0.01590"
"166.11200","13.84289","0.01603"
"166.40600","13.86735","0.01591"
"166.70000","13.89186","0.01621"
"166.99400","13.91637","0.01599"
"167.28800","13.94089","0.01607"
"167.58200","13.96540","0.01573"
"167.87600","13.98985","0.01593"
"168.17000","14.01443","0.01590"
"168.46400","14.03882","0.01634"
"168.75800","14.06334","0.01639"
"169.05200","14.08779","0.01627"
"169.34600","14.11236","0.01683"
"169.64000","14.13682","0.01666"
"169.93400","14.16139","0.01664"
"170.22800","14.18585","0.01653"
"170.52200","14.21042","0.01635"
"170.81600","14.23493","0.01655"
"171.11000","14.25939","0.01670"
"171.40400","14.28390","0.01657"
"171.69800","14.30835","0.01695"
"171.99200","14.33293","0.01704"
"172.28600","14.35732","0.01651"
"172.58000","14.38189","0.01683"
"172.87400","14.40635","0.01723"
"173.16800","14.43086","0.01693"
"173.46200","14.45532","0.01688"
"173.75600","14.47983","0.01664"
"174.05000","14.50434","0.01612"
"174.34400","14.52880","0.01643"
"174.63800","14.55337","0.01623"
"174.93200","14.57782","0.01665"
"175.22600","14.60240","0.01669"
"175.52000","14.62679","0.01604"
"175.81400","14.65143","0.01597"
"176.10800","14.67582","0.01609"
"176.40200","14.70039","0.01586"
"176.69600","14.72485","0.01636"
"176.99000","14.74942","0.01623"
"177.28400","14.77387","0.01599"
"177.57800","14.79839","0.01618"
"177.87200","14.82290","0.01650"
"178.16600","14.84735","0.01644"
"178.46000","14.87187","0.01668"
"178.75400","14.89632","0.01664"
"179.04800","14.92090","0.01693"
"179.34200","14.94535","0.01735"
"179.63600","14.96986","0.01679"
"179.93000","14.99432","0.01662"
"180.22400","15.01889","0.01715"
"180.51800","15.04341","0.01655"
"180.81200","15.06786","0.01736"
"181.10600","15.09231","0.01726"
"181.40000","15.11683","0.01751"
"181.69400","15.14134","0.01776"
"181.98800","15.16580","0.01787"
"182.28200","15.19037","0.01706"
"182.57600","15.21482","0.01750"
"182.87000","15.23940","0.01676"
"183.16400","15.26385","0.01682"
"183.45800","15.28836","0.01736"
"183.75200","15.31294","0.01743"
"184.04600","15.33733","0.01717"
"184.34000","15.36191","0.01708"
"184.63400","15.38636","0.01702"
"184.92800","15.41087","0.01730"
"185.22200","15.43527","0.01738"
"185.51600","15.45990","0.01719"
"185.81000","15.48435","0.01755"
"186.10400","15.50887","0.01761"
"186.39800","15.53332","0.01746"
"186.69200","15.55784","0.01726"
"186.98600","15.58235","0.01729"
"187.28000","15.60680","0.01792"
"187.57400","15.63132","0.01766"
"187.86800","15.65577","0.01713"
"188.16200","15.68034","0.01758"
"188.45600","15.70480","0.01788"
"188.75000","15.72937","0.01757"
"189.04400","15.75382","0.01801"
"189.33800","15.77840","0.01767"
"189.63200","15.80291","0.01792"
"189.92600","15.82736","0.01786"
"190.22000","15.85188","0.01768"
"190.51400","15.87633","0.01760"
"190.80800","15.90085","0.01750"
"191.10200","15.92536","0.01839"
"191.39600","15.94987","0.01807"
"191.69000","15.97433","0.01839"
"191.98400","15.99890","0.01796"
"192.27800","16.02336","0.01770"
"192.57200","16.04781","0.01777"
"192.86600","16.07238","0.01800"
"193.16000","16.09684","0.01839"
"193.45400","16.12141","0.01820"
"193.74800","16.14581","0.01886"
"194.04200","16.17038","0.01861"
"194.33600","16.19483","0.01829"
"194.63000","16.21941","0.01834"
"194.92400","16.24380","0.01860"
"195.21800","16.26837","0.01853"
"195.51200","16.29289","0.01844"
"195.80600","16.31740","0.01844"
"196.10000","16.34191","0.01802"
"196.39400","16.36637","0.01874"
"196.68800","16.39088","0.01838"
"196.98200","16.41533","0.01883"
"197.27600","16.43985","0.01920"
"197.57000","16.46430","0.01878"
"197.86400","16.48888","0.01936"
"198.15800","16.51333","0.01924"
"198.45200","16.53790","0.01940"
"198.74600","16.56236","0.01962"
"199.04000","16.58681","0.01934"
"199.33400","16.61133","0.01969"
"199.62800","16.63584","0.01957"
"199.92200","16.66035","0.01937"
"200.21600","16.68481","0.01830"
"200.51000","16.70938","0.01698"
"200.80400","16.73384","0.01732"
"201.09800","16.75841","0.01781"
"201.39200","16.78286","0.01833"
"201.68600","16.80744","0.01767"
"201.98000","16.83189","0.01791"
"202.27400","16.85640","0.01815"
"202.56800","16.88086","0.01865"
"202.86200","16.90537","0.01840"
"203.15600","16.92988","0.01826"
"203.45000","16.95428","0.01859"
"203.74400","16.97891","0.01830"
"204.03800","17.00331","0.01867"
"204.33200","17.02788","0.01877"
"204.62600","17.05233","0.01926"
"204.92000","17.07685","0.01902"
"205.21400","17.10130","0.01901"
"205.50800","17.12581","0.01955"
"205.80200","17.15039","0.01926"
"206.09600","17.17484","0.01913"
"206.39000","17.19936","0.01933"
"206.68400","17.22387","0.01963"
"206.97800","17.24838","0.01961"
"207.27200","17.27284","0.01962"
"207.56600","17.29735","0.02002"
"207.86000","17.32180","0.01992"
"208.15400","17.34632","0.02026"
"208.44800","17.37089","0.02005"
"208.74200","17.39535","0.01983"
"209.03600","17.41992","0.01981"
"209.33000","17.44431","0.01978"
"209.62400","17.46889","0.01967"
"209.91800","17.49328","0.01972"
"210.21200","17.51785","0.01993"
"210.50600","17.54225","0.02065"
"210.80000","17.56688","0.02078"
"211.09400","17.59134","0.02031"
"211.38800","17.61591","0.02031"
"211.68200","17.64042","0.02058"
"211.97600","17.66482","0.02025"
"212.27000","17.68939","0.02105"
"212.56400","17.71384","0.02040"
"212.85800","17.73842","0.02044"
"213.15200","17.76287","0.02026"
"213.44600","17.78745","0.02093"
"213.74000","17.81184","0.02072"
"214.03400","17.83641","0.02074"
"214.32800","17.86087","0.02078"
"214.62200","17.88538","0.02128"
"214.91600","17.90983","0.02071"
"215.21000","17.93435","0.02061"
"215.50400","17.95892","0.02151"
"215.79800","17.98332","0.02117"
"216.09200","18.00789","0.02126"
"216.38600","18.03234","0.02073"
"216.68000","18.05686","0.02078"
"216.97400","18.08131","0.02119"
"217.26800","18.10588","0.02159"
"217.56200","18.13034","0.02161"
"217.85600","18.15485","0.02141"
"218.15000","18.17937","0.02117"
"218.44400","18.20382","0.02176"
"218.73800","18.22839","0.02235"
"219.03200","18.25285","0.02287"
"219.32600","18.27736","0.02241"
"219.62000","18.30182","0.02239"
"219.91400","18.32645","0.02258"
"220.20800","18.35084","0.02279"
"220.50200","18.37542","0.02313"
"220.79600","18.39981","0.02347"
"221.09000","18.42439","0.02380"
"221.38400","18.44890","0.02353"
"221.67800","18.47335","0.02369"
"221.97200","18.49787","0.02427"
"222.26600","18.52232","0.02373"
"222.56000","18.54683","0.02435"
"222.85400","18.57129","0.02473"
"223.14800","18.59586","0.02542"
"223.44200","18.62031","0.02504"
"223.73600","18.64483","0.02528"
"224.03000","18.66934","0.02532"
"224.32400","18.69386","0.02542"
"224.61800","18.71837","0.02606"
"224.91200","18.74282","0.02616"
"225.20600","18.76740","0.02634"
"225.50000","18.79185","0.02711"
"225.79400","18.81636","0.02668"
"226.08800","18.84082","0.02596"
"226.38200","18.86539","0.02631"
"226.67600","18.88985","0.02623"
"226.97000","18.91436","0.02654"
"227.26400","18.93881","0.02665"
"227.55800","18.96339","0.02688"
"227.85200","18.98790","0.02828"
"228.14600","19.01235","0.02790"
"228.44000","19.03687","0.02754"
"228.73400","19.06138","0.02882"
"229.02800","19.08584","0.02921"
"229.32200","19.11029","0.02949"
"229.61600","19.13486","0.02931"
"229.91000","19.15926","0.03061"
"230.20400","19.18389","0.03005"
"230.49800","19.20834","0.03073"
"230.79200","19.23286","0.03092"
"231.08600","19.25737","0.03189"
"231.38000","19.28189","0.03205"
"231.67400","19.30640","0.03299"
"231.96800","19.33085","0.03365"
"232.26200","19.35537","0.03413"
"232.55600","19.37982","0.03465"
"232.85000","19.40439","0.03524"
"233.14400","19.42885","0.03544"
"233.43800","19.45336","0.03550"
"233.73200","19.47788","0.03686"
"234.02600","19.50233","0.03723"
"234.32000","19.52690","0.03800"
"234.61400","19.55136","0.03813"
"234.90800","19.57587","0.03856"
"235.20200","19.60026","0.04011"
"235.49600","19.62484","0.04033"
"235.79000","19.64929","0.04100"
"236.08400","19.67393","0.04190"
"236.37800","19.69832","0.04174"
"236.67200","19.72289","0.04253"
"236.96600","19.74735","0.04345"
"237.26000","19.77186","0.04245"
"237.55400","19.79638","0.04430"
"237.84800","19.82089","0.04412"
"238.14200","19.84540","0.04504"
"238.43600","19.86979","0.04584"
"238.73000","19.89437","0.04600"
"239.02400","19.91888","0.04652"
"239.31800","19.94340","0.04763"
"239.61200","19.96785","0.04831"
"239.90600","19.99236","0.04851"
"240.20000","20.01688","0.04853"
"240.49400","20.04133","0.04907"
"240.78800","20.06585","0.04941"
"241.08200","20.09030","0.05023"
"241.37600","20.11487","0.05046"
"241.67000","20.13933","0.05106"
"241.96400","20.16384","0.05191"
"242.25800","20.18829","0.05216"
"242.55200","20.21287","0.05255"
"242.84600","20.23738","0.05232"
"243.14000","20.26189","0.05326"
"243.43400","20.28641","0.05346"
"243.72800","20.31086","0.05371"
"244.02200","20.33537","0.05409"
"244.31600","20.35983","0.05441"
"244.61000","20.38441","0.05487"
"244.90400","20.40880","0.05500"
"245.19800","20.43337","0.05528"
"245.49200","20.45782","0.05571"
"245.78600","20.48240","0.05626"
"246.08000","20.50679","0.05656"
"246.37400","20.53137","0.05647"
"246.66800","20.55582","0.05665"
"246.96200","20.58033","0.05724"
"247.25600","20.60491","0.05739"
"247.55000","20.62936","0.05753"
"247.84400","20.65381","0.05777"
"248.13800","20.67833","0.05798"
"248.43200","20.70284","0.05829"
"248.72600","20.72729","0.05814"
"249.02000","20.75187","0.05813"
"249.31400","20.77638","0.05843"
"249.60800","20.80090","0.05882"
"249.90200","20.82535","0.05881"
"250.19600","20.84986","0.05932"
"250.49000","20.87444","0.05939"
"250.78400","20.89883","0.05980"
"251.07800","20.92335","0.05994"
"251.37200","20.94780","0.06016"
"251.66600","20.97237","0.06036"
"251.96000","20.99683","0.06084"
"252.25400","21.02140","0.06125"
"252.54800","21.04586","0.06200"
"252.84200","21.07031","0.06269"
"253.13600","21.09482","0.06331"
"253.43000","21.11934","0.06384"
"253.72400","21.14391","0.06484"
"254.01800","21.16830","0.06508"
"254.31200","21.19288","0.06616"
"254.60600","21.21733","0.06701"
"254.90000","21.24191","0.06755"
"255.19400","21.26630","0.06784"
"255.48800","21.29087","0.06898"
"255.78200","21.31533","0.06851"
"256.07600","21.33990","0.06982"
"256.37000","21.36436","0.07072"
"256.66400","21.38887","0.07230"
"256.95800","21.41338","0.07329"
"257.25200","21.43784","0.07435"
"257.54600","21.46235","0.07573"
"257.84000","21.48680","0.07732"
"258.13400","21.51138","0.07850"
"258.42800","21.53577","0.07957"
"258.72200","21.56034","0.07935"
"259.01600","21.58486","0.08061"
"259.31000","21.60931","0.08168"
"259.60400","21.63382","0.08307"
"259.89800","21.65828","0.08379"
"260.19200","21.68286","0.08524"
"260.48600","21.70731","0.08602"
"260.78000","21.73188","0.08642"
"261.07400","21.75628","0.08760"
"261.36800","21.78085","0.08859"
"261.66200","21.80536","0.09000"
"261.95600","21.82988","0.09118"
"262.25000","21.85439","0.09223"
"262.54400","21.87890","0.09298"
"262.83800","21.90342","0.09354"
"263.13200","21.92787","0.09471"
"263.42600","21.95238","0.09537"
"263.72000","21.97678","0.09697"
"264.01400","22.00135","0.09749"
"264.30800","22.02581","0.09816"
"264.60200","22.05044","0.09963"
"264.89600","22.07483","0.10026"
"265.19000","22.09935","0.10133"
"265.48400","22.12386","0.10222"
"265.77800","22.14832","0.10210"
"266.07200","22.17283","0.10300"
"266.36600","22.19734","0.10358"
"266.66000","22.22186","0.10395"
"266.95400","22.24631","0.10428"
"267.24800","22.27088","0.10483"
"267.54200","22.29534","0.10550"
"267.83600","22.31985","0.10571"
"268.13000","22.34437","0.10655"
"268.42400","22.36888","0.10683"
"268.71800","22.39333","0.10186"
"269.01200","22.41785","0.10339"
"269.30600","22.44242","0.10334"
"269.60000","22.46687","0.10386"
"269.89400","22.49139","0.10382"
"270.18800","22.51578","0.10434"
"270.48200","22.54036","0.10553"
"270.77600","22.56481","0.10554"
"271.07000","22.58932","0.10658"
"271.36400","22.61378","0.10740"
"271.65800","22.63835","0.10723"
"271.95200","22.66286","0.10935"
"272.24600","22.68732","0.10929"
"272.54000","22.71189","0.11016"
"272.83400","22.73635","0.11255"
"273.12800","22.76086","0.11316"
"273.42200","22.78537","0.11583"
"273.71600","22.80989","0.11685"
"274.01000","22.83434","0.11740"
"274.30400","22.85891","0.12062"
"274.59800","22.88337","0.12306"
"274.89200","22.90788","0.12329"
"275.18600","22.93240","0.12571"
"275.48000","22.95685","0.12653"
"275.77400","22.98136","0.12720"
"276.06800","23.00588","0.12887"
"276.36200","23.03039","0.12950"
"276.65600","23.05478","0.13161"
"276.95000","23.07936","0.13251"
"277.24400","23.10381","0.13375"
"277.53800","23.12839","0.13530"
"277.83200","23.15284","0.13540"
"278.12600","23.17735","0.13654"
"278.42000","23.20187","0.13765"
"278.71400","23.22632","0.13906"
"279.00800","23.25089","0.13903"
"279.30200","23.27535","0.13931"
"279.59600","23.29992","0.13990"
"279.89000","23.32431","0.14020"
"280.18400","23.34889","0.13741"
"280.47800","23.37334","0.04537"
"280.77200","23.39792","0.02644"
"281.06600","23.42237","0.04007"
"281.36000","23.44688","0.03072"
"281.65400","23.47134","0.03921"
"281.94800","23.49579","0.03493"
"282.24200","23.52036","0.04034"
"282.53600","23.54488","0.03813"
"282.83000","23.56933","0.04233"
"283.12400","23.59379","0.04045"
"283.41800","23.61842","0.04434"
"283.71200","23.64287","0.04270"
"284.00600","23.66733","0.04657"
"284.30000","23.69184","0.04498"
"284.59400","23.71635","0.04888"
"284.88800","23.74087","0.04644"
"285.18200","23.76532","0.04922"
"285.47600","23.78990","0.04908"
"285.77000","23.81435","0.05100"
"286.06400","23.83892","0.05000"
"286.35800","23.86332","0.05190"
"286.65200","23.88783","0.05140"
"286.94600","23.91234","0.05262"
"287.24000","23.93686","0.05255"
"287.53400","23.96137","0.05318"
"287.82800","23.98589","0.05328"
"288.12200","24.01040","0.05367"
"288.41600","24.03486","0.05397"
"288.71000","24.05943","0.05381"
"289.00400","24.08382","0.05420"
"289.29800","24.10834","0.05441"
"289.59200","24.13279","0.05490"
"289.88600","24.15736","0.05523"
"290.18000","24.18182","0.05540"
"290.47400","24.20639","0.05526"
"290.76800","24.23084","0.05602"
"291.06200","24.25536","0.05649"
"291.35600","24.27987","0.05672"
"291.65000","24.30433","0.05714"
"291.94400","24.32890","0.05697"
"292.23800","24.35335","0.05783"
"292.53200","24.37793","0.05759"
"292.82600","24.40238","0.05836"
"293.12000","24.42690","0.05821"
"293.41400","24.45135","0.05897"
"293.70800","24.47580","0.05943"
"294.00200","24.50031","0.05999"
"294.29600","24.52477","0.06064"
"294.59000","24.54935","0.06064"
"294.88400","24.57380","0.06120"
"295.17800","24.59837","0.06182"
"295.47200","24.62283","0.06233"
"295.76600","24.64734","0.06248"
"296.06000","24.67173","0.06350"
"296.35400","24.69637","0.06361"
"296.64800","24.72082","0.06408"
"296.94200","24.74533","0.06532"
"297.23600","24.76985","0.06510"
"297.53000","24.79436","0.06619"
"297.82400","24.81887","0.06635"
"298.11800","24.84333","0.06782"
"298.41200","24.86790","0.06884"
"298.70600","24.89235","0.06944"
"299.00000","24.91687","0.07124"
"299.29400","24.94132","0.07139"
"299.58800","24.96590","0.07291"
"299.88200","24.99035","0.07420"
"300.17600","25.01487","0.07547"
"300.47000","25.03938","0.07660"
"300.76400","25.06389","0.07683"
"301.05800","25.08841","0.07777"
"301.35200","25.11280","0.07990"
"301.64600","25.13737","0.08068"
"301.94000","25.16177","0.08187"
"302.23400","25.18634","0.08242"
"302.52800","25.21079","0.08379"
"302.82200","25.23537","0.08548"
"303.11600","25.25988","0.08612"
"303.41000","25.28440","0.08709"
"303.70400","25.30891","0.08774"
"303.99800","25.33336","0.08853"
"304.29200","25.35788","0.08979"
"304.58600","25.38233","0.09134"
"304.88000","25.40691","0.09297"
"305.17400","25.43136","0.09403"
"305.46800","25.45587","0.09432"
"305.76200","25.48032","0.09513"
"306.05600","25.50484","0.09699"
"306.35000","25.52935","0.09889"
"306.64400","25.55387","0.09951"
"306.93800","25.57832","0.10105"
"307.23200","25.60284","0.10157"
"307.52600","25.62735","0.10225"
"307.82000","25.65186","0.10304"
"308.11400","25.67638","0.10339"
"308.40800","25.70083","0.10408"
"308.70200","25.72534","0.10444"
"308.99600","25.74980","0.10480"
"309.29000","25.77437","0.10535"
"309.58400","25.79888","0.10609"
"309.87800","25.82334","0.10637"
"310.17200","25.84785","0.10703"
"310.46600","25.87243","0.10753"
"310.76000","25.89694","0.10825"
"311.05400","25.92133","0.11005"
"311.34800","25.94591","0.11112"
"311.64200","25.97036","0.11226"
"311.93600","25.99487","0.11468"
"312.23000","26.01933","0.11556"
"312.52400","26.04390","0.11191"
"312.81800","26.06836","0.10892"
"313.11200","26.09287","0.11134"
"313.40600","26.11738","0.11250"
"313.70000","26.14184","0.11448"
"313.99400","26.16641","0.11587"
"314.28800","26.19087","0.11694"
"314.58200","26.21538","0.11901"
"314.87600","26.23983","0.12092"
"315.17000","26.26440","0.12225"
"315.46400","26.28886","0.12433"
"315.75800","26.31337","0.12681"
"316.05200","26.33783","0.12886"
"316.34600","26.36240","0.13028"
"316.64000","26.38692","0.13218"
"316.93400","26.41137","0.13311"
"317.22800","26.43588","0.13409"
"317.52200","26.46034","0.13581"
"317.81600","26.48485","0.13633"
"318.11000","26.50931","0.13775"
"318.40400","26.53388","0.13908"
"318.69800","26.55833","0.13991"
"318.99200","26.58284","0.14032"
"319.28600","26.60736","0.14054"
"319.58000","26.63181","0.14092"
"319.87400","26.65639","0.14060"
"320.16800","26.68078","0.14035"
"320.46200","26.70535","0.14139"
"320.75600","26.72981","0.14194"
"321.05000","26.75438","0.14270"
"321.34400","26.77877","0.14384"
"321.63800","26.80335","0.14410"
"321.93200","26.82786","0.14493"
"322.22600","26.85243","0.14560"
"322.52000","26.87683","0.14583"
"322.81400","26.90140","0.14633"
"323.10800","26.92592","0.14691"
"323.40200","26.95031","0.14718"
"323.69600","26.97488","0.14753"
"323.99000","26.99934","0.14797"
"324.28400","27.02385","0.14804"
"324.57800","27.04831","0.14868"
"324.87200","27.07288","0.14886"
"325.16600","27.09733","0.14902"
"325.46000","27.12191","0.14957"
"325.75400","27.14630","0.14968"
"326.04800","27.17081","0.15003"
"326.34200","27.19533","0.15031"
"326.63600","27.21984","0.15036"
"326.93000","27.24436","0.15086"
"327.22400","27.26887","0.15097"
"327.51800","27.29339","0.15160"
"327.81200","27.31784","0.15159"
"328.10600","27.34235","0.15232"
"328.40000","27.36687","0.15298"
"328.69400","27.39132","0.15314"
"328.98800","27.41583","0.02775"
"329.28200","27.44035","0.02720"
"329.57600","27.46492","0.02519"
"329.87000","27.48932","0.02789"
"330.16400","27.51383","0.02193"
"330.45800","27.53828","0.02769"
"330.75200","27.56285","0.02539"
"331.04600","27.58731","0.02788"
"331.34000","27.61188","0.02791"
"331.63400","27.63634","0.02977"
"331.92800","27.66085","0.02958"
"332.22200","27.68530","0.03228"
"332.51600","27.70988","0.03182"
"332.81000","27.73433","0.03371"
"333.10400","27.75884","0.03497"
"333.39800","27.78336","0.03399"
"333.69200","27.80787","0.03594"
"333.98600","27.83239","0.03647"
"334.28000","27.85684","0.03808"
"334.57400","27.88141","0.03918"
"334.86800","27.90587","0.03966"
"335.16200","27.93038","0.04086"
"335.45600","27.95484","0.04116"
"335.75000","27.97935","0.04154"
"336.04400","28.00386","0.04149"
"336.33800","28.02832","0.04307"
"336.63200","28.05289","0.04290"
"336.92600","28.07734","0.04409"
"337.22000","28.10186","0.04443"
"337.51400","28.12631","0.04599"
"337.80800","28.15088","0.04696"
"338.10200","28.17534","0.04783"
"338.39600","28.19985","0.04880"
"338.69000","28.22437","0.04910"
"338.98400","28.24882","0.05017"
"339.27800","28.27340","0.05082"
"339.57200","28.29785","0.05148"
"339.86600","28.32242","0.05227"
"340.16000","28.34682","0.05269"
"340.45400","28.37139","0.05261"
"340.74800","28.39578","0.05286"
"341.04200","28.42036","0.05325"
"341.33600","28.44487","0.05289"
"341.63000","28.46939","0.05181"
"341.92400","28.49384","0.05224"
"342.21800","28.51835","0.05235"
"342.51200","28.54287","0.05325"
"342.80600","28.56732","0.05334"
"343.10000","28.59183","0.05456"
"343.39400","28.61629","0.05457"
"343.68800","28.64086","0.05514"
"343.98200","28.66532","0.05472"
"344.27600","28.68989","0.05530"
"344.57000","28.71434","0.05582"
"344.86400","28.73886","0.05597"
"345.15800","28.76337","0.05641"
"345.45200","28.78782","0.05682"
"345.74600","28.81240","0.05678"
"346.04000","28.83685","0.05726"
"346.33400","28.86143","0.05735"
"346.62800","28.88582","0.05802"
"346.92200","28.91039","0.05842"
"347.21600","28.93485","0.05845"
"347.51000","28.95936","0.05916"
"347.80400","28.98387","0.05947"
"348.09800","29.00839","0.05979"
"348.39200","29.03290","0.06025"
"348.68600","29.05736","0.06018"
"348.98000","29.08193","0.06067"
"349.27400","29.10633","0.06111"
"349.56800","29.13090","0.06175"
"349.86200","29.15529","0.06225"
"350.15600","29.17986","0.06238"
"350.45000","29.20432","0.06284"
"350.74400","29.22889","0.06400"
"351.03800","29.25335","0.06488"
"351.33200","29.27786","0.06623"
"351.62600","29.30243","0.06695"
"351.92000","29.32683","0.06780"
"352.21400","29.35140","0.06884"
"352.50800","29.37585","0.07063"
"352.80200","29.40043","0.07201"
"353.09600","29.42482","0.07378"
"353.39000","29.44934","0.07465"
"353.68400","29.47385","0.07644"
"353.97800","29.49836","0.07731"
"354.27200","29.52288","0.07874"
"354.56600","29.54733","0.07991"
"354.86000","29.57184","0.07973"
"355.15400","29.59636","0.07973"
"355.44800","29.62087","0.08084"
"355.74200","29.64532","0.08150"
"356.03600","29.66984","0.08159"
"356.33000","29.69429","0.08252"
"356.62400","29.71887","0.08417"
"356.91800","29.74332","0.08425"
"357.21200","29.76789","0.08504"
"357.50600","29.79235","0.08572"
"357.80000","29.81686","0.08689"
"358.09400","29.84138","0.08893"
"358.38800","29.86577","0.09006"
"358.68200","29.89040","0.09100"
"358.97600","29.91486","0.09191"
"359.27000","29.93937","0.09373"
"359.56400","29.96382","0.09471"
"359.85800","29.98840","0.09656"
"360.15200","30.01285","0.09728"
"360.44600","30.03736","0.09814"
"360.74000","30.06182","0.09958"
"361.03400","30.08633","0.10081"
"361.32800","30.11085","0.10142"
"361.62200","30.13536","0.10188"
"361.91600","30.15982","0.10290"
"362.21000","30.18433","0.10314"
"362.50400","30.20884","0.10372"
"362.79800","30.23330","0.10421"
"363.09200","30.25787","0.10436"
"363.38600","30.28238","0.10484"
"363.68000","30.30690","0.10577"
"363.97400","30.33141","0.10620"
"364.26800","30.35586","0.10686"
"364.56200","30.38044","0.10732"
"364.85600","30.40483","0.10838"
"365.15000","30.42934","0.10866"
"365.44400","30.45380","0.11023"
"365.73800","30.47837","0.11100"
"366.03200","30.50277","0.11226"
"366.32600","30.52740","0.11448"
"366.62000","30.55179","0.11615"
"366.91400","30.57637","0.11787"
"367.20800","30.60082","0.12040"
"367.50200","30.62533","0.12210"
"367.79600","30.64985","0.12429"
"368.09000","30.67430","0.12542"
"368.38400","30.69888","0.12751"
"368.67800","30.72333","0.12858"
"368.97200","30.74785","0.13021"
"369.26600","30.77230","0.13150"
"369.56000","30.79687","0.13277"
"369.85400","30.82138","0.13447"
"370.14800","30.84590","0.13557"
"370.44200","30.87041","0.13649"
"370.73600","30.89487","0.13760"
"371.03000","30.91944","0.13879"
"371.32400","30.94383","0.14026"
"371.61800","30.96835","0.14085"
"371.91200","30.99286","0.09395"
"372.20600","31.01737","0.09819"
"372.50000","31.04183","0.09962"
"372.79400","31.06640","0.10234"
"373.08800","31.09085","0.10153"
"373.38200","31.11537","0.10538"
"373.67600","31.13982","0.10419"
"373.97000","31.16428","0.10570"
"374.26400","31.18891","0.10667"
"374.55800","31.21331","0.10689"
"374.85200","31.23788","0.11118"
"375.14600","31.26233","0.10974"
"375.44000","31.28691","0.11291"
"375.73400","31.31136","0.02359"
"376.02800","31.33593","0.02720"
"376.32200","31.36039","0.02965"
"376.61600","31.38484","0.03130"
"376.91000","31.40935","0.03153"
"377.20400","31.43387","0.03329"
"377.49800","31.45838","0.03588"
"377.79200","31.48283","0.03282"
"378.08600","31.50735","0.03904"
"378.38000","31.53180","0.03369"
"378.67400","31.55632","0.03985"
"378.96800","31.58083","0.03567"
"379.26200","31.60534","0.04117"
"379.55600","31.62980","0.04000"
"379.85000","31.65431","0.04315"
"380.14400","31.67883","0.04151"
"380.43800","31.70334","0.04316"
"380.73200","31.72785","0.04307"
"381.02600","31.75231","0.04543"
"381.32000","31.77688","0.04611"
"381.61400","31.80134","0.04690"
"381.90800","31.82585","0.04652"
"382.20200","31.85036","0.04783"
"382.49600","31.87494","0.04844"
"382.79000","31.89939","0.05042"
"383.08400","31.92384","0.05072"
"383.37800","31.94842","0.05162"
"383.67200","31.97287","0.05180"
"383.96600","31.99738","0.05271"
"384.26000","32.02184","0.05279"
"384.55400","32.04641","0.05368"
"384.84800","32.07087","0.05365"
"385.14200","32.09538","0.05468"
"385.43600","32.11983","0.05493"
"385.73000","32.14441","0.05520"
"386.02400","32.16886","0.05555"
"386.31800","32.19331","0.05587"
"386.61200","32.21789","0.05646"
"386.90600","32.24234","0.05622"
"387.20000","32.26691","0.05687"
"387.49400","32.29137","0.05682"
"387.78800","32.31588","0.05753"
"388.08200","32.34034","0.05798"
"388.37600","32.36485","0.05789"
"388.67000","32.38937","0.05837"
"388.96400","32.41388","0.05866"
"389.25800","32.43839","0.05909"
"389.55200","32.46284","0.05934"
"389.84600","32.48742","0.05981"
"390.14000","32.51181","0.06028"
"390.43400","32.53639","0.06025"
"390.72800","32.56084","0.06086"
"391.02200","32.58536","0.06160"
"391.31600","32.60981","0.06170"
"391.61000","32.63438","0.06213"
"391.90400","32.65878","0.06290"
"392.19800","32.68335","0.06367"
"392.49200","32.70786","0.06428"
"392.78600","32.73232","0.06472"
"393.08000","32.75683","0.06579"
"393.37400","32.78135","0.06623"
"393.66800","32.80586","0.06693"
"393.96200","32.83031","0.06792"
"394.25600","32.85495","0.06875"
"394.55000","32.87934","0.06937"
"394.84400","32.90385","0.07013"
"395.13800","32.92837","0.07112"
"395.43200","32.95288","0.07235"
"395.72600","32.97734","0.07321"
"396.02000","33.00185","0.05529"
"396.31400","33.02636","0.05786"
"396.60800","33.05082","0.05865"
"396.90200","33.07533","0.05596"
"397.19600","33.09978","0.05855"
"397.49000","33.12436","0.05541"
"397.78400","33.14881","0.06112"
"398.07800","33.17332","0.05659"
"398.37200","33.19784","0.06226"
"398.66600","33.22235","0.05767"
"398.96000","33.24687","0.06218"
"399.25400","33.27132","0.05837"
"399.54800","33.29589","0.06101"
"399.84200","33.32035","0.05967"
"400.13600","33.34486","0.06009"
"400.43000","33.36931","0.06296"
"400.72400","33.39395","0.06116"
"401.01800","33.41834","0.06591"
"401.31200","33.44286","0.06245"
"401.60600","33.46731","0.06800"
"401.90000","33.49188","0.06317"
"402.19400","33.51633","0.06961"
"402.48800","33.54085","0.06458"
"402.78200","33.56536","0.07069"
"403.07600","33.58976","0.06746"
"403.37000","33.61433","0.07133"
"403.66400","33.63879","0.07032"
"403.95800","33.66336","0.07270"
"404.25200","33.68782","0.07298"
"404.54600","33.71233","0.07436"
"404.84000","33.73684","0.07560"
"405.13400","33.76136","0.07641"
"405.42800","33.78587","0.07645"
"405.72200","33.81032","0.07874"
"406.01600","33.83490","0.07811"
"406.31000","33.85935","0.08138"
"406.60400","33.88393","0.08068"
"406.89800","33.90832","0.08286"
"407.19200","33.93289","0.08351"
"407.48600","33.95734","0.08394"
"407.78000","33.98186","0.08564"
"408.07400","34.00637","0.08645"
"408.36800","34.03089","0.08804"
"408.66200","34.05540","0.08883"
"408.95600","34.07985","0.09025"
"409.25000","34.10443","0.09217"
"409.54400","34.12882","0.09175"
"409.83800","34.15334","0.09442"
"410.13200","34.17779","0.09539"
"410.42600","34.20236","0.09653"
"410.72000","34.22681","0.09859"
"411.01400","34.25139","0.09819"
"411.30800","34.27584","0.10005"
"411.60200","34.30036","0.10103"
"411.89600","34.32487","0.10211"
"412.19000","34.34933","0.10228"
"412.48400","34.37390","0.10342"
"412.77800","34.39835","0.10383"
"413.07200","34.42287","0.10394"
"413.36600","34.44732","0.10442"
"413.66000","34.47190","0.10499"
"413.95400","34.49635","0.10556"
"414.24800","34.52080","0.10638"
"414.54200","34.54532","0.10775"
"414.83600","34.56983","0.10781"
"415.13000","34.59434","0.04379"
"415.42400","34.61880","0.05189"
"415.71800","34.64337","0.05187"
"416.01200","34.66782","0.05018"
"416.30600","34.69234","0.05356"
"416.60000","34.71679","0.05061"
"416.89400","34.74136","0.05439"
"417.18800","34.76582","0.05303"
"417.48200","34.79039","0.05414"
"417.77600","34.81485","0.05481"
"418.07000","34.83936","0.05443"
"418.36400","34.86387","0.05613"
"418.65800","34.88833","0.05509"
"418.95200","34.91290","0.05647"
"419.24600","34.93736","0.05614"
"419.54000","34.96187","0.05686"
"419.83400","34.98632","0.05647"
"420.12800","35.01089","0.05690"
"420.42200","35.03535","0.05720"
"420.71600","35.05993","0.05727"
"421.01000","35.08438","0.05757"
"421.30400","35.10883","0.05788"
"421.59800","35.13335","0.05800"
"421.89200","35.15786","0.05786"
"422.18600","35.18237","0.05799"
"422.48000","35.20683","0.05842"
"422.77400","35.23134","0.05871"
"423.06800","35.25585","0.05914"
"423.36200","35.28037","0.05898"
"423.65600","35.30488","0.05930"
"423.95000","35.32933","0.05936"
"424.24400","35.35391","0.03866"
"424.53800","35.37836","0.01449"
"424.83200","35.40294","0.01383"
"425.12600","35.42733","0.01021"
"425.42000","35.45190","0.01096"
"425.71400","35.47630","0.01469"
"426.00800","35.50087","0.01129"
"426.30200","35.52533","0.01075"
"426.59600","35.54990","0.01266"
"426.89000","35.57436","0.01150"
"427.18400","35.59887","0.01078"
"427.47800","35.62332","0.01183"
"427.77200","35.64783","0.01355"
"428.06600","35.67241","0.01081"
"428.36000","35.69687","0.01185"
"428.65400","35.72138","0.01267"
"428.94800","35.74583","0.01136"
"429.24200","35.77034","0.01230"
"429.53600","35.79480","0.01318"
"429.83000","35.81937","0.01124"
"430.12400","35.84382","0.01142"
"430.41800","35.86840","0.01236"
"430.71200","35.89291","0.01258"
"431.00600","35.91737","0.01194"
"431.30000","35.94194","0.01272"
"431.59400","35.96633","0.01171"
"431.88800","35.99085","0.01233"
"432.18200","36.01530","0.01235"
"432.47600","36.03988","0.01230"
"432.77000","36.06433","0.01242"
"433.06400","36.08884","0.01197"
"433.35800","36.11335","0.01235"
"433.65200","36.13787","0.01274"
"433.94600","36.16238","0.01238"
"434.24000","36.18684","0.01263"
"434.53400","36.21135","0.01289"
"434.61400","36.21805","0.01248"