File: Force_trajectories/170225_2/Specimen_RawData_6.csv
End date,"2/25/2017"
Specimen label,"5DT_35"
Maximum Load,"0.17180",N

Time,Extension,Load
(s),(mm),(N)
"0.00000","0.00000","0.00043"
"0.36600","0.03061","0.00252"
"0.73200","0.06122","0.00337"
"1.09800","0.09172","0.00440"
"1.46400","0.12215","0.00490"
"1.83000","0.15270","0.00528"
"2.19600","0.18320","0.00619"
"2.56200","0.21363","0.00603"
"2.92800","0.24418","0.00692"
"3.29400","0.27473","0.00715"
"3.66000","0.30523","0.00765"
"4.02600","0.33572","0.00842"
"4.39200","0.36621","0.00899"
"4.75800","0.39664","0.00901"
"5.12400","0.42720","0.00988"
"5.49000","0.45775","0.00977"
"5.85600","0.48812","0.01025"
"6.22200","0.51879","0.00997"
"6.58800","0.54923","0.01041"
"6.95400","0.57966","0.01175"
"7.32000","0.61021","0.01161"
"7.68600","0.64070","0.01137"
"8.05200","0.67108","0.01240"
"8.41800","0.70175","0.01189"
"8.78400","0.73224","0.01326"
"9.15000","0.76268","0.01336"
"9.51600","0.79323","0.01379"
"9.88200","0.82366","0.01405"
"10.24800","0.85421","0.01383"
"10.61400","0.88471","0.01519"
"10.98000","0.91520","0.01468"
"11.34600","0.94569","0.01422"
"11.71200","0.97618","0.01494"
"12.07800","1.00674","0.01555"
"12.44400","1.03723","0.01561"
"12.81000","1.06772","0.01557"
"13.17600","1.09821","0.01573"
"13.54200","1.12877","0.01569"
"13.90800","1.15914","0.01635"
"14.27400","1.18975","0.01620"
"14.64000","1.22018","0.01644"
"15.00600","1.25068","0.01671"
"15.37200","1.28123","0.01700"
"15.73800","1.31172","0.01695"
"16.10400","1.34216","0.01758"
"16.47000","1.37271","0.01740"
"16.83600","1.40326","0.01731"
"17.20200","1.43363","0.01758"
"17.56800","1.46425","0.01808"
"17.93400","1.49468","0.01857"
"18.30000","1.52517","0.01878"
"18.66600","1.55566","0.01904"
"19.03200","1.58622","0.01886"
"19.39800","1.61671","0.01962"
"19.76400","1.64720","0.01914"
"20.13000","1.67775","0.01963"
"20.49600","1.70819","0.02003"
"20.86200","1.73868","0.01977"
"21.22800","1.76923","0.02085"
"21.59400","1.79972","0.02000"
"21.96000","1.83022","0.02013"
"22.32600","1.86071","0.02015"
"22.69200","1.89114","0.02065"
"23.05800","1.92164","0.02077"
"23.42400","1.95225","0.02123"
"23.79000","1.98274","0.02082"
"24.15600","2.01317","0.02093"
"24.52200","2.04373","0.02147"
"24.88800","2.07428","0.02081"
"25.25400","2.10465","0.02081"
"25.62000","2.13520","0.02147"
"25.98600","2.16570","0.02122"
"26.35200","2.19619","0.02094"
"26.71800","2.22674","0.02169"
"27.08400","2.25723","0.02155"
"27.45000","2.28767","0.02227"
"27.81600","2.31816","0.02215"
"28.18200","2.34877","0.02164"
"28.54800","2.37920","0.02198"
"28.91400","2.40970","0.02230"
"29.28000","2.44019","0.02158"
"29.64600","2.47074","0.02175"
"30.01200","2.50118","0.02252"
"30.37800","2.53173","0.02234"
"30.74400","2.56222","0.02211"
"31.11000","2.59271","0.02148"
"31.47600","2.62321","0.02142"
"31.84200","2.65370","0.02121"
"32.20800","2.68419","0.02200"
"32.57400","2.71474","0.02199"
"32.94000","2.74524","0.02242"
"33.30600","2.77567","0.02203"
"33.67200","2.80622","0.02230"
"34.03800","2.83671","0.02068"
"34.40400","2.86715","0.02081"
"34.77000","2.89776","0.02098"
"35.13600","2.92825","0.02135"
"35.50200","2.95868","0.02132"
"35.86800","2.98918","0.02150"
"36.23400","3.01979","0.02189"
"36.60000","3.05016","0.02239"
"36.96600","3.08072","0.02262"
"37.33200","3.11121","0.02216"
"37.69800","3.14170","0.02249"
"38.06400","3.17219","0.02249"
"38.43000","3.20269","0.02245"
"38.79600","3.23324","0.02312"
"39.16200","3.26373","0.02293"
"39.52800","3.29428","0.02356"
"39.89400","3.32466","0.02344"
"40.26000","3.35515","0.02382"
"40.62600","3.38570","0.02389"
"40.99200","3.41625","0.02418"
"41.35800","3.44669","0.02454"
"41.72400","3.47724","0.02499"
"42.09000","3.50773","0.02434"
"42.45600","3.53817","0.02426"
"42.82200","3.56872","0.02507"
"43.18800","3.59921","0.02515"
"43.55400","3.62970","0.02489"
"43.92000","3.66020","0.02601"
"44.28600","3.69075","0.02604"
"44.65200","3.72118","0.02595"
"45.01800","3.75167","0.02589"
"45.38400","3.78223","0.02659"
"45.75000","3.81266","0.02734"
"46.11600","3.84321","0.02733"
"46.48200","3.87370","0.02745"
"46.84800","3.90420","0.02823"
"47.21400","3.93469","0.02814"
"47.58000","3.96530","0.02831"
"47.94600","3.99567","0.02907"
"48.31200","4.02617","0.02930"
"48.67800","4.05672","0.02906"
"49.04400","4.08721","0.02899"
"49.41000","4.11770","0.02942"
"49.77600","4.14820","0.03005"
"50.14200","4.17875","0.03028"
"50.50800","4.20918","0.03056"
"50.87400","4.23974","0.03149"
"51.24000","4.27023","0.03158"
"51.60600","4.30072","0.02362"
"51.97200","4.33121","0.02153"
"52.33800","4.36177","0.02190"
"52.70400","4.39220","0.02349"
"53.07000","4.42269","0.02310"
"53.43600","4.45324","0.02423"
"53.80200","4.48368","0.02504"
"54.16800","4.51423","0.02517"
"54.53400","4.54466","0.02530"
"54.90000","4.57521","0.02553"
"55.26600","4.60565","0.02589"
"55.63200","4.63626","0.02583"
"55.99800","4.66669","0.02605"
"56.36400","4.69719","0.02699"
"56.73000","4.72774","0.02718"
"57.09600","4.75817","0.02822"
"57.46200","4.78872","0.02788"
"57.82800","4.81928","0.02724"
"58.19400","4.84977","0.02551"
"58.56000","4.88014","0.02204"
"58.92600","4.91075","0.02134"
"59.29200","4.94125","0.01988"
"59.65800","4.97168","0.01972"
"60.02400","5.00223","0.02090"
"60.39000","5.03272","0.02139"
"60.75600","5.06322","0.02254"
"61.12200","5.09371","0.02237"
"61.48800","5.12426","0.02326"
"61.85400","5.15464","0.02429"
"62.22000","5.18525","0.02547"
"62.58600","5.21568","0.02670"
"62.95200","5.24617","0.02747"
"63.31800","5.27673","0.02558"
"63.68400","5.30728","0.02554"
"64.05000","5.33765","0.02626"
"64.41600","5.36820","0.02661"
"64.78200","5.39876","0.02764"
"65.14800","5.42919","0.02687"
"65.51400","5.45968","0.02806"
"65.88000","5.49023","0.02827"
"66.24600","5.52073","0.02933"
"66.61200","5.55116","0.02966"
"66.97800","5.58171","0.03009"
"67.34400","5.61220","0.03105"
"67.71000","5.64270","0.03039"
"68.07600","5.67325","0.03026"
"68.44200","5.70374","0.03044"
"68.80800","5.73417","0.03091"
"69.17400","5.76467","0.03250"
"69.54000","5.79522","0.03063"
"69.90600","5.82565","0.03091"
"70.27200","5.85621","0.03070"
"70.63800","5.88676","0.03174"
"71.00400","5.91719","0.03217"
"71.37000","5.94774","0.03296"
"71.73600","5.97824","0.03266"
"72.10200","6.00873","0.03444"
"72.46800","6.03916","0.03402"
"72.83400","6.06971","0.03507"
"73.20000","6.10015","0.03681"
"73.56600","6.13070","0.03716"
"73.93200","6.16125","0.03790"
"74.29800","6.19168","0.03797"
"74.66400","6.22224","0.03944"
"75.03000","6.25273","0.04088"
"75.39600","6.28322","0.02201"
"75.76200","6.31365","0.01797"
"76.12800","6.34427","0.02156"
"76.49400","6.37470","0.02159"
"76.86000","6.40513","0.02114"
"77.22600","6.43575","0.02230"
"77.59200","6.46624","0.02345"
"77.95800","6.49673","0.02382"
"78.32400","6.52722","0.02485"
"78.69000","6.55778","0.02623"
"79.05600","6.58815","0.02663"
"79.42200","6.61870","0.02838"
"79.78800","6.64919","0.02969"
"80.15400","6.67969","0.02973"
"80.52000","6.71024","0.03214"
"80.88600","6.74073","0.03334"
"81.25200","6.77116","0.03386"
"81.61800","6.80166","0.03555"
"81.98400","6.83227","0.03660"
"82.35000","6.86264","0.03730"
"82.71600","6.89325","0.03881"
"83.08200","6.92369","0.04034"
"83.44800","6.95424","0.04110"
"83.81400","6.98467","0.04226"
"84.18000","7.01523","0.04275"
"84.54600","7.04572","0.04424"
"84.91200","7.07621","0.04527"
"85.27800","7.10676","0.04677"
"85.64400","7.13726","0.04661"
"86.01000","7.16775","0.04606"
"86.37600","7.19818","0.04651"
"86.74200","7.22873","0.04771"
"87.10800","7.25917","0.04810"
"87.47400","7.28972","0.04915"
"87.84000","7.32021","0.04140"
"88.20600","7.35071","0.04272"
"88.57200","7.38120","0.04481"
"88.93800","7.41175","0.04518"
"89.30400","7.44218","0.04588"
"89.67000","7.47268","0.04665"
"90.03600","7.50329","0.04734"
"90.40200","7.53360","0.03216"
"90.76800","7.56421","0.02991"
"91.13400","7.59471","0.03178"
"91.50000","7.62520","0.03184"
"91.86600","7.65569","0.03283"
"92.23200","7.68624","0.03451"
"92.59800","7.71668","0.03453"
"92.96400","7.74717","0.03534"
"93.33000","7.77778","0.03652"
"93.69600","7.80821","0.03729"
"94.06200","7.83871","0.03784"
"94.42800","7.86920","0.04010"
"94.79400","7.89963","0.04124"
"95.16000","7.93018","0.04163"
"95.52600","7.96074","0.04284"
"95.89200","7.99123","0.04424"
"96.25800","8.02172","0.04589"
"96.62400","8.05221","0.04641"
"96.99000","8.08271","0.04763"
"97.35600","8.11320","0.04847"
"97.72200","8.14369","0.04899"
"98.08800","8.17424","0.04864"
"98.45400","8.20468","0.04855"
"98.82000","8.23523","0.04944"
"99.18600","8.26572","0.05038"
"99.55200","8.29616","0.05046"
"99.91800","8.32671","0.05097"
"100.28400","8.35720","0.05179"
"100.65000","8.38769","0.05283"
"101.01600","8.41819","0.05387"
"101.38200","8.44874","0.05442"
"101.74800","8.47917","0.05519"
"102.11400","8.50966","0.05603"
"102.48000","8.54022","0.05657"
"102.84600","8.57071","0.05747"
"103.21200","8.60120","0.04299"
"103.57800","8.63169","0.04437"
"103.94400","8.66219","0.04455"
"104.31000","8.69268","0.04533"
"104.67600","8.72323","0.04664"
"105.04200","8.75373","0.04833"
"105.40800","8.78422","0.04941"
"105.77400","8.81477","0.05061"
"106.14000","8.84526","0.05111"
"106.50600","8.87570","0.05217"
"106.87200","8.90619","0.05280"
"107.23800","8.93674","0.05363"
"107.60400","8.96717","0.05421"
"107.97000","8.99773","0.05459"
"108.33600","9.02822","0.05530"
"108.70200","9.05865","0.05602"
"109.06800","9.08920","0.05639"
"109.43400","9.11970","0.05725"
"109.80000","9.15019","0.05779"
"110.16600","9.18068","0.05827"
"110.53200","9.21130","0.05895"
"110.89800","9.24167","0.05999"
"111.26400","9.27228","0.06091"
"111.63000","9.30271","0.06125"
"111.99600","9.33321","0.06198"
"112.36200","9.36370","0.06264"
"112.72800","9.39425","0.03966"
"113.09400","9.42468","0.02138"
"113.46000","9.45518","0.02251"
"113.82600","9.48573","0.02162"
"114.19200","9.51622","0.01984"
"114.55800","9.54671","0.01990"
"114.92400","9.57721","0.02173"
"115.29000","9.60782","0.02124"
"115.65600","9.63813","0.02107"
"116.02200","9.66881","0.02198"
"116.38800","9.69924","0.02320"
"116.75400","9.72967","0.02342"
"117.12000","9.76022","0.02281"
"117.48600","9.79078","0.02408"
"117.85200","9.82121","0.02359"
"118.21800","9.85170","0.02375"
"118.58400","9.88225","0.02401"
"118.95000","9.91269","0.02563"
"119.31600","9.94324","0.02647"
"119.68200","9.97367","0.02661"
"120.04800","10.00422","0.02719"
"120.41400","10.03466","0.02875"
"120.78000","10.06521","0.02832"
"121.14600","10.09570","0.02921"
"121.51200","10.12619","0.02923"
"121.87800","10.15675","0.02504"
"122.24400","10.18718","0.02585"
"122.61000","10.21767","0.02636"
"122.97600","10.24823","0.02726"
"123.34200","10.27878","0.02862"
"123.70800","10.30915","0.02845"
"124.07400","10.33970","0.02866"
"124.44000","10.37025","0.03006"
"124.80600","10.40063","0.03109"
"125.17200","10.43124","0.03209"
"125.53800","10.46173","0.03291"
"125.90400","10.49217","0.03366"
"126.27000","10.52266","0.03418"
"126.63600","10.55327","0.03537"
"127.00200","10.58364","0.03405"
"127.36800","10.61420","0.03284"
"127.73400","10.64469","0.03279"
"128.10000","10.67518","0.03274"
"128.46600","10.70568","0.03299"
"128.83200","10.73623","0.03345"
"129.19800","10.76672","0.03516"
"129.56400","10.79721","0.03422"
"129.93000","10.82776","0.03518"
"130.29600","10.85820","0.03632"
"130.66200","10.88869","0.03720"
"131.02800","10.91918","0.03823"
"131.39400","10.94968","0.03922"
"131.76000","10.98017","0.04035"
"132.12600","11.01078","0.04149"
"132.49200","11.04121","0.04079"
"132.85800","11.07165","0.04172"
"133.22400","11.10226","0.04319"
"133.59000","11.13275","0.04504"
"133.95600","11.16313","0.04558"
"134.32200","11.19368","0.04620"
"134.68800","11.22423","0.04736"
"135.05400","11.25460","0.04842"
"135.42000","11.28521","0.04963"
"135.78600","11.31571","0.05062"
"136.15200","11.34620","0.05137"
"136.51800","11.37675","0.05186"
"136.88400","11.40718","0.05271"
"137.25000","11.43768","0.05321"
"137.61600","11.46823","0.05372"
"137.98200","11.49872","0.05379"
"138.34800","11.52922","0.05407"
"138.71400","11.55971","0.05459"
"139.08000","11.59020","0.05528"
"139.44600","11.62063","0.05525"
"139.81200","11.65119","0.05544"
"140.17800","11.68174","0.05592"
"140.54400","11.71223","0.05597"
"140.91000","11.74266","0.05644"
"141.27600","11.77322","0.05740"
"141.64200","11.80371","0.05752"
"142.00800","11.83420","0.05781"
"142.37400","11.86469","0.05873"
"142.74000","11.89525","0.05979"
"143.10600","11.92568","0.06059"
"143.47200","11.95623","0.06173"
"143.83800","11.98673","0.06136"
"144.20400","12.01716","0.06218"
"144.57000","12.04771","0.06361"
"144.93600","12.07820","0.06513"
"145.30200","12.10870","0.06721"
"145.66800","12.13919","0.06917"
"146.03400","12.16968","0.07203"
"146.40000","12.20017","0.07376"
"146.76600","12.23073","0.07549"
"147.13200","12.26128","0.07708"
"147.49800","12.29171","0.07636"
"147.86400","12.32220","0.05479"
"148.23000","12.35270","0.05643"
"148.59600","12.38319","0.05755"
"148.96200","12.41368","0.05892"
"149.32800","12.44423","0.06072"
"149.69400","12.47473","0.06042"
"150.06000","12.50516","0.06045"
"150.42600","12.53577","0.06191"
"150.79200","12.56627","0.06344"
"151.15800","12.59664","0.06597"
"151.52400","12.62719","0.06979"
"151.89000","12.65780","0.07188"
"152.25600","12.68812","0.07546"
"152.62200","12.71873","0.07857"
"152.98800","12.74922","0.07922"
"153.35400","12.77965","0.08199"
"153.72000","12.81021","0.08475"
"154.08600","12.84070","0.08767"
"154.45200","12.87119","0.09093"
"154.81800","12.90168","0.09358"
"155.18400","12.93224","0.09092"
"155.55000","12.96267","0.08959"
"155.91600","12.99322","0.09275"
"156.28200","13.02372","0.09581"
"156.64800","13.05421","0.09670"
"157.01400","13.08470","0.09885"
"157.38000","13.11519","0.09988"
"157.74600","13.14574","0.10152"
"158.11200","13.17618","0.10298"
"158.47800","13.20673","0.10463"
"158.84400","13.23722","0.10651"
"159.21000","13.26766","0.10799"
"159.57600","13.29821","0.10850"
"159.94200","13.32876","0.10757"
"160.30800","13.35919","0.10869"
"160.67400","13.38969","0.10999"
"161.04000","13.42024","0.06165"
"161.40600","13.45061","0.06453"
"161.77200","13.48123","0.06562"
"162.13800","13.51172","0.06946"
"162.50400","13.54221","0.07614"
"162.87000","13.57264","0.07792"
"163.23600","13.60326","0.08191"
"163.60200","13.63369","0.08494"
"163.96800","13.66424","0.08668"
"164.33400","13.69473","0.09118"
"164.70000","13.72523","0.09385"
"165.06600","13.75566","0.09747"
"165.43200","13.78621","0.09909"
"165.79800","13.81670","0.10012"
"166.16400","13.84714","0.10176"
"166.53000","13.87769","0.10292"
"166.89600","13.90824","0.10458"
"167.26200","13.93861","0.10569"
"167.62800","13.96923","0.10769"
"167.99400","13.99972","0.11021"
"168.36000","14.03021","0.11253"
"168.72600","14.06070","0.11492"
"169.09200","14.09126","0.11690"
"169.45800","14.12163","0.11907"
"169.82400","14.15224","0.12303"
"170.19000","14.18273","0.12614"
"170.55600","14.21317","0.12858"
"170.92200","14.24372","0.13181"
"171.28800","14.27421","0.13420"
"171.65400","14.30465","0.13635"
"172.02000","14.33520","0.13775"
"172.38600","14.36575","0.13935"
"172.75200","14.39618","0.14025"
"173.11800","14.42674","0.14087"
"173.48400","14.45723","0.14171"
"173.85000","14.48766","0.14228"
"174.21600","14.51816","0.14346"
"174.58200","14.54877","0.14459"
"174.94800","14.57926","0.14516"
"175.31400","14.60963","0.14600"
"175.68000","14.64025","0.14633"
"176.04600","14.67074","0.14069"
"176.41200","14.70123","0.11116"
"176.77800","14.73172","0.10872"
"177.14400","14.76222","0.10868"
"177.51000","14.79271","0.11196"
"177.87600","14.82320","0.11635"
"178.24200","14.85369","0.12110"
"178.60800","14.88413","0.12402"
"178.97400","14.91474","0.12379"
"179.34000","14.94523","0.12630"
"179.70600","14.97572","0.12962"
"180.07200","15.00622","0.13260"
"180.43800","15.03677","0.13575"
"180.80400","15.06714","0.13703"
"181.17000","15.09769","0.13944"
"181.53600","15.12825","0.14041"
"181.90200","15.15868","0.14139"
"182.26800","15.18923","0.14266"
"182.63400","15.21972","0.14381"
"183.00000","15.25022","0.14429"
"183.36600","15.28065","0.14497"
"183.73200","15.31126","0.14522"
"184.09800","15.34170","0.14604"
"184.46400","15.37219","0.14676"
"184.83000","15.40274","0.14734"
"185.19600","15.43317","0.14814"
"185.56200","15.46367","0.14893"
"185.92800","15.49422","0.01922"
"186.29400","15.52471","0.02912"
"186.66000","15.55515","0.03047"
"187.02600","15.58576","0.03389"
"187.39200","15.61625","0.03806"
"187.75800","15.64674","0.04156"
"188.12400","15.67723","0.04464"
"188.49000","15.70773","0.04589"
"188.85600","15.73816","0.04716"
"189.22200","15.76871","0.04922"
"189.58800","15.79926","0.05114"
"189.95400","15.82970","0.05211"
"190.32000","15.86025","0.05312"
"190.68600","15.89074","0.05413"
"191.05200","15.92124","0.05503"
"191.41800","15.95167","0.05583"
"191.78400","15.98222","0.05675"
"192.15000","16.01271","0.05736"
"192.51600","16.04321","0.05843"
"192.88200","16.07370","0.05962"
"193.24800","16.10419","0.06071"
"193.61400","16.13468","0.06231"
"193.98000","16.16524","0.06476"
"194.34600","16.19573","0.06642"
"194.71200","16.22622","0.06883"
"195.07800","16.25671","0.07139"
"195.44400","16.28721","0.07382"
"195.81000","16.31770","0.07553"
"196.17600","16.34819","0.07733"
"196.54200","16.37874","0.07974"
"196.90800","16.40912","0.08212"
"197.27400","16.43973","0.08457"
"197.64000","16.47028","0.08690"
"198.00600","16.50066","0.08931"
"198.37200","16.53121","0.09139"
"198.73800","16.56164","0.09349"
"199.10400","16.59219","0.09538"
"199.47000","16.62268","0.09733"
"199.83600","16.65324","0.09888"
"200.20200","16.68367","0.10061"
"200.56800","16.71422","0.10187"
"200.93400","16.74472","0.10284"
"201.30000","16.77521","0.10435"
"201.66600","16.80570","0.10572"
"202.03200","16.83625","0.10807"
"202.39800","16.86675","0.11089"
"202.76400","16.89718","0.11292"
"203.13000","16.92773","0.11626"
"203.49600","16.95816","0.11902"
"203.86200","16.98866","0.12222"
"204.22800","17.01921","0.12511"
"204.59400","17.04970","0.12815"
"204.96000","17.08019","0.13047"
"205.32600","17.11075","0.13283"
"205.69200","17.14124","0.13478"
"206.05800","17.17161","0.13660"
"206.42400","17.20223","0.13890"
"206.79000","17.23272","0.13990"
"207.15600","17.26315","0.14132"
"207.52200","17.29370","0.14232"
"207.88800","17.32425","0.14359"
"208.25400","17.35469","0.14455"
"208.62000","17.38512","0.14525"
"208.98600","17.41573","0.14627"
"209.35200","17.44623","0.14687"
"209.71800","17.47672","0.14747"
"210.08400","17.50721","0.14827"
"210.45000","17.53771","0.14906"
"210.81600","17.56814","0.14994"
"211.18200","17.59869","0.15113"
"211.54800","17.62924","0.15276"
"211.91400","17.65968","0.15405"
"212.28000","17.69023","0.15640"
"212.64600","17.72072","0.15784"
"213.01200","17.75115","0.16021"
"213.37800","17.78177","0.16318"
"213.74400","17.81220","0.16548"
"214.11000","17.84269","0.16827"
"214.47600","17.87325","0.17122"
"214.84200","17.90374","0.16863"
"215.20800","17.93417","0.14288"
"215.57400","17.96472","0.14248"
"215.94000","17.99521","0.14383"
"216.30600","18.02571","0.14507"
"216.67200","18.05614","0.14584"
"217.03800","18.08675","0.14734"
"217.40400","18.11719","0.14875"
"217.77000","18.14768","0.14987"
"218.13600","18.17823","0.15145"
"218.50200","18.20872","0.15237"
"218.86800","18.23915","0.02750"
"219.23400","18.26971","0.02288"
"219.60000","18.30026","0.02277"
"219.96600","18.33063","0.02300"
"220.33200","18.36125","0.02968"
"220.69800","18.39168","0.02810"
"221.06400","18.42217","0.03290"
"221.43000","18.45272","0.03405"
"221.79600","18.48316","0.03630"
"222.16200","18.51365","0.04177"
"222.52800","18.54426","0.04323"
"222.89400","18.57475","0.04575"
"223.26000","18.60513","0.04742"
"223.62600","18.63580","0.04963"
"223.99200","18.66623","0.05121"
"224.35800","18.69667","0.05234"
"224.72400","18.72722","0.05344"
"225.09000","18.75771","0.05416"
"225.45600","18.78814","0.05516"
"225.82200","18.81870","0.05588"
"226.18800","18.84925","0.05629"
"226.55400","18.87968","0.05704"
"226.92000","18.91023","0.05821"
"227.28600","18.94067","0.05908"
"227.65200","18.97122","0.06048"
"228.01800","19.00171","0.06161"
"228.38400","19.03226","0.06315"
"228.75000","19.06270","0.06499"
"229.11600","19.09319","0.06654"
"229.48200","19.12374","0.06861"
"229.84800","19.15417","0.06979"
"230.21400","19.18467","0.07263"
"230.58000","19.21528","0.07344"
"230.94600","19.24571","0.07632"
"231.31200","19.27615","0.07735"
"231.67800","19.30676","0.07882"
"232.04400","19.33719","0.07874"
"232.41000","19.36768","0.08284"
"232.77600","19.39817","0.08659"
"233.14200","19.42873","0.08725"
"233.50800","19.45922","0.08861"
"233.87400","19.48965","0.09053"
"234.24000","19.52027","0.09241"
"234.60600","19.55070","0.09416"
"234.97200","19.58119","0.09540"
"235.33800","19.61168","0.09686"
"235.70400","19.64218","0.09811"
"236.07000","19.67273","0.09929"
"236.43600","19.70322","0.09994"
"236.80200","19.73365","0.10087"
"237.16800","19.76421","0.10124"
"237.53400","19.79476","0.10215"
"237.90000","19.82519","0.10266"
"238.26600","19.85569","0.10338"
"238.63200","19.88624","0.10387"
"238.99800","19.91673","0.10473"
"239.36400","19.94716","0.10564"
"239.73000","19.97772","0.10645"
"240.09600","20.00821","0.10707"
"240.46200","20.03864","0.10826"
"240.82800","20.06925","0.11068"
"241.19400","20.09975","0.11209"
"241.56000","20.13018","0.11282"
"241.92600","20.16073","0.11459"
"242.29200","20.19123","0.11590"
"242.65800","20.22160","0.11799"
"243.02400","20.25221","0.11925"
"243.39000","20.28270","0.12068"
"243.75600","20.31314","0.12248"
"244.12200","20.34375","0.12395"
"244.48800","20.37424","0.12581"
"244.85400","20.40473","0.12739"
"245.22000","20.43517","0.12868"
"245.58600","20.46572","0.12993"
"245.95200","20.49621","0.12796"
"246.31800","20.52670","0.13023"
"246.68400","20.55725","0.13153"
"247.05000","20.58769","0.13179"
"247.41600","20.61818","0.13411"
"247.78200","20.64874","0.13509"
"248.14800","20.67923","0.13658"
"248.51400","20.70972","0.13753"
"248.88000","20.74027","0.13832"
"249.24600","20.77070","0.13996"
"249.61200","20.80120","0.14053"
"249.97800","20.83175","0.14136"
"250.34400","20.86224","0.14213"
"250.71000","20.89268","0.14275"
"251.07600","20.92323","0.14316"
"251.44200","20.95378","0.14405"
"251.80800","20.98415","0.14447"
"252.17400","21.01476","0.14473"
"252.54000","21.04520","0.14551"
"252.90600","21.07569","0.14553"
"253.27200","21.10618","0.14668"
"253.63800","21.13674","0.14712"
"254.00400","21.16717","0.14762"
"254.37000","21.19772","0.14800"
"254.73600","21.22827","0.14822"
"255.10200","21.25871","0.03789"
"255.46800","21.28920","0.04752"
"255.83400","21.31969","0.04654"
"256.20000","21.35024","0.03990"
"256.56600","21.38068","0.03906"
"256.93200","21.41123","0.04286"
"257.29800","21.44172","0.04597"
"257.66400","21.47216","0.04939"
"258.03000","21.50271","0.05130"
"258.39600","21.53320","0.05313"
"258.76200","21.56369","0.05488"
"259.12800","21.59425","0.05655"
"259.49400","21.62480","0.05790"
"259.86000","21.65517","0.05967"
"260.22600","21.68572","0.06298"
"260.59200","21.71622","0.06533"
"260.95800","21.74665","0.06790"
"261.32400","21.77726","0.07130"
"261.69000","21.80775","0.07528"
"262.05600","21.83813","0.07763"
"262.42200","21.86874","0.08114"
"262.78800","21.89923","0.08465"
"263.15400","21.92966","0.08836"
"263.52000","21.96022","0.09050"
"263.88600","21.99071","0.09379"
"264.25200","22.02120","0.09632"
"264.61800","22.05169","0.09876"
"264.98400","22.08219","0.10048"
"265.35000","22.11268","0.10238"
"265.71600","22.14317","0.10432"
"266.08200","22.17379","0.10652"
"266.44800","22.20428","0.10882"
"266.81400","22.23471","0.11281"
"267.18000","22.26520","0.11622"
"267.54600","22.29575","0.12084"
"267.91200","22.32613","0.12391"
"268.27800","22.35668","0.12691"
"268.64400","22.38717","0.13043"
"269.01000","22.41767","0.13210"
"269.37600","22.44822","0.13217"
"269.74200","22.47877","0.13303"
"270.10800","22.50914","0.13483"
"270.47400","22.53970","0.13659"
"270.84000","22.57025","0.04637"
"271.20600","22.60062","0.02326"
"271.57200","22.63123","0.02124"
"271.93800","22.66173","0.02774"
"272.30400","22.69222","0.02745"
"272.67000","22.72271","0.02912"
"273.03600","22.75321","0.03136"
"273.40200","22.78370","0.03129"
"273.76800","22.81419","0.03223"
"274.13400","22.84475","0.03056"
"274.50000","22.87524","0.03331"
"274.86600","22.90567","0.03302"
"275.23200","22.93616","0.03343"
"275.59800","22.96671","0.03319"
"275.96400","22.99721","0.03438"
"276.33000","23.02776","0.03389"
"276.69600","23.05825","0.03316"
"277.06200","23.08869","0.03393"
"277.42800","23.11924","0.03301"
"277.79400","23.14973","0.03522"
"278.16000","23.18016","0.03556"
"278.52600","23.21072","0.03713"
"278.89200","23.24127","0.03813"
"279.25800","23.27164","0.03806"
"279.62400","23.30219","0.03983"
"279.99000","23.33274","0.04066"
"280.35600","23.36312","0.04052"
"280.72200","23.39373","0.04121"
"281.08800","23.42422","0.04214"
"281.45400","23.45472","0.04246"
"281.82000","23.48521","0.04290"
"282.18600","23.51570","0.04381"
"282.55200","23.54619","0.04495"
"282.91800","23.57669","0.04536"
"283.28400","23.60724","0.04656"
"283.65000","23.63767","0.04662"
"284.01600","23.66822","0.04708"
"284.38200","23.69872","0.04660"
"284.74800","23.72927","0.04623"
"285.11400","23.75970","0.04723"
"285.48000","23.79020","0.04589"
"285.84600","23.82075","0.04565"
"286.21200","23.85118","0.04741"
"286.57800","23.88167","0.04763"
"286.94400","23.91223","0.04847"
"287.31000","23.94266","0.04850"
"287.67600","23.97315","0.04889"
"288.04200","24.00376","0.04962"
"288.40800","24.03414","0.04949"
"288.77400","24.06475","0.04879"
"289.14000","24.09524","0.04842"
"289.50600","24.12567","0.04783"
"289.87200","24.15623","0.04393"
"290.23800","24.18672","0.04711"
"290.60400","24.21721","0.04538"
"290.97000","24.24771","0.04430"
"291.33600","24.27826","0.04362"
"291.70200","24.30869","0.04364"
"292.06800","24.33918","0.04157"
"292.43400","24.36968","0.04026"
"292.80000","24.40023","0.04157"
"293.16600","24.43072","0.03821"
"293.53200","24.46121","0.03902"
"293.89800","24.49171","0.04074"
"294.26400","24.52220","0.03943"
"294.63000","24.55275","0.04043"
"294.99600","24.58324","0.04165"
"295.36200","24.61368","0.04307"
"295.72800","24.64423","0.04210"
"296.09400","24.67478","0.04196"
"296.46000","24.70509","0.04433"
"296.82600","24.73577","0.04397"
"297.19200","24.76626","0.04312"
"297.55800","24.79663","0.04407"
"297.92400","24.82719","0.04398"
"298.29000","24.85768","0.04397"
"298.65600","24.88817","0.04474"
"299.02200","24.91872","0.04528"
"299.38800","24.94927","0.04614"
"299.75400","24.97965","0.04705"
"300.12000","25.01026","0.04793"
"300.48600","25.04069","0.04879"
"300.85200","25.07125","0.04826"
"301.21800","25.10168","0.04805"
"301.58400","25.13223","0.04931"
"301.95000","25.16273","0.04986"
"302.31600","25.19322","0.05017"
"302.68200","25.22371","0.05055"
"303.04800","25.25426","0.05094"
"303.41400","25.28470","0.05089"
"303.78000","25.31519","0.05172"
"304.14600","25.34574","0.05189"
"304.51200","25.37617","0.05247"
"304.87800","25.40672","0.05371"
"305.24400","25.43722","0.05390"
"305.61000","25.46765","0.05430"
"305.97600","25.49826","0.05472"
"306.34200","25.52876","0.05512"
"306.70800","25.55913","0.05521"
"307.07400","25.58974","0.05552"
"307.44000","25.62024","0.05632"
"307.80600","25.65067","0.05595"
"308.17200","25.68122","0.05494"
"308.53800","25.71171","0.05491"
"308.90400","25.74220","0.05558"
"309.27000","25.77270","0.05623"
"309.63600","25.80319","0.05676"
"310.00200","25.83368","0.05736"
"310.36800","25.86418","0.05791"
"310.73400","25.89473","0.05767"
"311.10000","25.92522","0.05925"
"311.46600","25.95565","0.05942"
"311.83200","25.98621","0.05977"
"312.19800","26.01676","0.06063"
"312.56400","26.04719","0.06133"
"312.93000","26.07774","0.06274"
"313.29600","26.10830","0.06405"
"313.66200","26.13867","0.06572"
"314.02800","26.16922","0.06634"
"314.39400","26.19971","0.06735"
"314.76000","26.23014","0.06883"
"315.12600","26.26070","0.06890"
"315.49200","26.29125","0.07122"
"315.85800","26.32162","0.07282"
"316.22400","26.35218","0.07392"
"316.59000","26.38273","0.07440"
"316.95600","26.41316","0.07577"
"317.32200","26.44371","0.07664"
"317.68800","26.47421","0.07825"
"318.05400","26.50464","0.07933"
"318.42000","26.53519","0.08042"
"318.78600","26.56574","0.08118"
"319.15200","26.59618","0.08212"
"319.51800","26.62667","0.08314"
"319.88400","26.65722","0.08423"
"320.25000","26.68772","0.08639"
"320.61600","26.71821","0.08705"
"320.98200","26.74870","0.08747"
"321.34800","26.77925","0.03483"
"321.71400","26.80968","0.03731"
"322.08000","26.84018","0.03801"
"322.44600","26.87073","0.03941"
"322.81200","26.90116","0.03956"
"323.17800","26.93172","0.04153"
"323.54400","26.96227","0.04304"
"323.91000","26.99270","0.04293"
"324.27600","27.02320","0.04348"
"324.64200","27.05381","0.04451"
"325.00800","27.08418","0.04524"
"325.37400","27.11473","0.04666"
"325.74000","27.14523","0.04786"
"326.10600","27.17572","0.04879"
"326.47200","27.20621","0.04893"
"326.83800","27.23670","0.05012"
"327.20400","27.26720","0.04958"
"327.57000","27.29769","0.05024"
"327.93600","27.32824","0.05089"
"328.30200","27.35867","0.05160"
"328.66800","27.38923","0.05181"
"329.03400","27.41972","0.05262"
"329.40000","27.45021","0.05251"
"329.76600","27.48064","0.05295"
"330.13200","27.51126","0.05314"
"330.49800","27.54175","0.05376"
"330.86400","27.57212","0.05383"
"331.23000","27.60273","0.05402"
"331.59600","27.63323","0.05402"
"331.96200","27.66366","0.05483"
"332.32800","27.69415","0.05475"
"332.69400","27.72482","0.05493"
"333.06000","27.75514","0.05510"
"333.42600","27.78569","0.05543"
"333.79200","27.81618","0.05567"
"334.15800","27.84668","0.05621"
"334.52400","27.87723","0.05652"
"334.89000","27.90772","0.05662"
"335.25600","27.93815","0.05675"
"335.62200","27.96871","0.05689"
"335.98800","27.99926","0.05737"
"336.35400","28.02969","0.05507"
"336.72000","28.06025","0.05415"
"337.08600","28.09074","0.05469"
"337.45200","28.12117","0.05507"
"337.81800","28.15166","0.05498"
"338.18400","28.18221","0.05529"
"338.55000","28.21271","0.01063"
"338.91600","28.24320","0.01217"
"339.28200","28.27375","0.00852"
"339.64800","28.30424","0.00893"
"340.01400","28.33468","0.00873"
"340.38000","28.36523","0.00847"
"340.74600","28.39573","0.00870"
"341.11200","28.42616","0.01034"
"341.47800","28.45671","0.01014"
"341.84400","28.48720","0.00956"
"342.21000","28.51764","0.00975"
"342.57600","28.54825","0.01060"
"342.94200","28.57868","0.01187"
"343.30800","28.60917","0.01206"
"343.67400","28.63967","0.01138"
"344.04000","28.67028","0.01160"
"344.40600","28.70065","0.01231"
"344.77200","28.73120","0.01319"
"345.13800","28.76170","0.01356"
"345.50400","28.79213","0.01331"
"345.87000","28.82274","0.01405"
"346.23600","28.85323","0.01461"
"346.60200","28.88367","0.01442"
"346.96800","28.91416","0.01398"
"347.33400","28.94477","0.01479"
"347.70000","28.97526","0.01345"
"348.06600","29.00564","0.01312"
"348.43200","29.03625","0.01457"
"348.79800","29.06674","0.01516"
"349.16400","29.09717","0.01576"
"349.53000","29.12773","0.01540"
"349.89600","29.15822","0.01633"
"350.26200","29.18865","0.01175"
"350.62800","29.21920","0.01259"
"350.99400","29.24976","0.01232"
"351.36000","29.28019","0.01367"
"351.72600","29.31068","0.01440"
"352.09200","29.34118","0.01475"
"352.45800","29.37161","0.01524"
"352.82400","29.40222","0.01578"
"353.19000","29.43277","0.01693"
"353.55600","29.46315","0.01692"
"353.92200","29.49376","0.01784"
"354.28800","29.52425","0.01881"
"354.65400","29.55468","0.01842"
"355.02000","29.58512","0.01954"
"355.38600","29.61573","0.01954"
"355.75200","29.64622","0.01947"
"356.11800","29.67672","0.02056"
"356.48400","29.70721","0.02007"
"356.85000","29.73770","0.01992"
"357.21600","29.76819","0.02094"
"357.58200","29.79875","0.02079"
"357.94800","29.82924","0.02089"
"358.31400","29.85967","0.02196"
"358.68000","29.89022","0.02086"
"359.04600","29.92072","0.02043"
"359.41200","29.95115","0.02189"
"359.77800","29.98170","0.02147"
"360.14400","30.01219","0.02109"
"360.51000","30.04269","0.02192"
"360.87600","30.07318","0.02178"
"361.24200","30.10379","0.02210"
"361.60800","30.13416","0.02223"
"361.97400","30.16472","0.02268"
"362.34000","30.19521","0.02291"
"362.70600","30.22570","0.02254"
"363.07200","30.25614","0.02278"
"363.43800","30.28669","0.02288"
"363.80400","30.31718","0.02312"
"364.17000","30.34767","0.02264"
"364.53600","30.37822","0.02353"
"364.90200","30.40872","0.02360"
"365.26800","30.43915","0.02393"
"365.63400","30.46970","0.02415"
"366.00000","30.50026","0.02468"
"366.36600","30.53069","0.02481"
"366.73200","30.56124","0.02537"
"367.09800","30.59167","0.02364"
"367.46400","30.62217","0.02276"
"367.83000","30.65278","0.02315"
"368.19600","30.68321","0.02300"
"368.56200","30.71371","0.02417"
"368.92800","30.74420","0.02337"
"369.29400","30.77475","0.02351"
"369.66000","30.80512","0.02318"
"370.02600","30.83568","0.02325"
"370.39200","30.86623","0.02350"
"370.75800","30.89672","0.02358"
"371.12400","30.92721","0.02300"
"371.49000","30.95770","0.02392"
"371.85600","30.98820","0.02361"
"372.22200","31.01863","0.02372"
"372.58800","31.04924","0.02346"
"372.95400","31.07968","0.02287"
"373.32000","31.11017","0.02284"
"373.68600","31.14072","0.02361"
"374.05200","31.17122","0.02389"
"374.41800","31.20171","0.02344"
"374.78400","31.23226","0.02391"
"375.15000","31.26269","0.02383"
"375.51600","31.29318","0.02398"
"375.88200","31.32373","0.02416"
"376.24800","31.35423","0.02486"
"376.61400","31.38466","0.02414"
"376.98000","31.41521","0.02494"
"377.34600","31.44570","0.02571"
"377.71200","31.47614","0.02628"
"378.07800","31.50669","0.02640"
"378.44400","31.53724","0.02662"
"378.81000","31.56768","0.02777"
"379.17600","31.59823","0.02776"
"379.54200","31.62872","0.02707"
"379.90800","31.65922","0.02719"
"380.27400","31.68965","0.02848"
"380.64000","31.72020","0.02763"
"381.00600","31.75075","0.02370"
"381.37200","31.78119","0.02266"
"381.73800","31.81174","0.02243"
"382.10400","31.84217","0.02308"
"382.47000","31.87266","0.02443"
"382.83600","31.90327","0.02422"
"383.20200","31.93371","0.02241"
"383.56800","31.96414","0.02196"
"383.93400","31.99475","0.02321"
"384.30000","32.02519","0.02247"
"384.66600","32.05562","0.02269"
"385.03200","32.08623","0.02316"
"385.39800","32.11673","0.02373"
"385.76400","32.14722","0.02361"
"386.13000","32.17771","0.02388"
"386.49600","32.20820","0.02340"
"386.86200","32.23864","0.02320"
"387.22800","32.26925","0.02358"
"387.59400","32.29974","0.02455"
"387.96000","32.33017","0.02443"
"388.32600","32.36066","0.02373"
"388.69200","32.39122","0.02377"
"389.05800","32.42171","0.02394"
"389.42400","32.45214","0.02376"
"389.79000","32.48275","0.02467"
"390.15600","32.51319","0.02419"
"390.52200","32.54368","0.02466"
"390.88800","32.57417","0.02540"
"391.25400","32.60473","0.02583"
"391.62000","32.63522","0.02555"
"391.98600","32.66577","0.02479"
"392.35200","32.69621","0.02494"
"392.71800","32.72670","0.02533"
"393.08400","32.75725","0.02483"
"393.45000","32.78769","0.02558"
"393.81600","32.81818","0.02535"
"394.18200","32.84879","0.02558"
"394.54800","32.87922","0.02554"
"394.91400","32.90965","0.02627"
"395.28000","32.94020","0.02614"
"395.64600","32.97076","0.02661"
"396.01200","33.00113","0.02685"
"396.37800","33.03174","0.02739"
"396.74400","33.06223","0.02758"
"397.11000","33.09273","0.02712"
"397.47600","33.12316","0.02810"
"397.84200","33.15371","0.02833"
"398.20800","33.18421","0.02891"
"398.57400","33.21470","0.02958"
"398.94000","33.24519","0.02933"
"399.30600","33.27575","0.03001"
"399.67200","33.30624","0.02970"
"400.03800","33.33673","0.02990"
"400.40400","33.36723","0.02959"
"400.77000","33.39766","0.03038"
"401.13600","33.42827","0.03067"
"401.50200","33.45870","0.03103"
"401.86800","33.48919","0.02410"
"402.23400","33.51974","0.02268"
"402.60000","33.55024","0.02288"
"402.96600","33.58067","0.02454"
"403.33200","33.61122","0.02530"
"403.69800","33.64172","0.02661"
"404.06400","33.67215","0.02715"
"404.43000","33.70276","0.02745"
"404.79600","33.73325","0.02844"
"405.16200","33.76369","0.02678"
"405.52800","33.79418","0.02714"
"405.89400","33.82473","0.02716"
"406.26000","33.85517","0.02680"
"406.62600","33.88572","0.02666"
"406.99200","33.91621","0.02602"
"407.35800","33.94670","0.02574"
"407.72400","33.97720","0.02525"
"408.09000","34.00769","0.02502"
"408.45600","34.03824","0.02457"
"408.82200","34.06867","0.02404"
"409.18800","34.09922","0.02328"
"409.55400","34.12972","0.02355"
"409.92000","34.16021","0.02392"
"410.28600","34.19076","0.02489"
"410.65200","34.22120","0.02471"
"411.01800","34.25169","0.02452"
"411.38400","34.28224","0.02312"
"411.75000","34.31273","0.02401"
"412.11600","34.34311","0.02149"
"412.48200","34.37378","0.02283"
"412.84800","34.40421","0.02242"
"413.21400","34.43471","0.02276"
"413.58000","34.46520","0.02171"
"413.94600","34.49569","0.02240"
"414.31200","34.52618","0.01990"
"414.67800","34.55674","0.01778"
"415.04400","34.58723","0.01927"
"415.41000","34.61772","0.01895"
"415.77600","34.64827","0.01964"
"416.14200","34.67870","0.01947"
"416.50800","34.70920","0.02002"
"416.87400","34.73969","0.02061"
"417.24000","34.77024","0.02031"
"417.60600","34.80074","0.02027"
"417.97200","34.83123","0.01913"
"418.33800","34.86178","0.01904"
"418.70400","34.89215","0.02020"
"419.07000","34.92271","0.01915"
"419.43600","34.95320","0.01856"
"419.80200","34.98375","0.01865"
"420.16800","35.01419","0.01941"
"420.53400","35.04474","0.01955"
"420.90000","35.07523","0.01921"
"421.26600","35.10566","0.01906"
"421.63200","35.13622","0.01877"
"421.99800","35.16671","0.01879"
"422.36400","35.19720","0.01842"
"422.73000","35.22775","0.01933"
"423.09600","35.25824","0.01961"
"423.46200","35.28862","0.02040"
"423.82800","35.31917","0.01945"
"424.19400","35.34972","0.02034"
"424.56000","35.38016","0.01997"
"424.92600","35.41077","0.02035"
"425.29200","35.44120","0.02028"
"425.65800","35.47176","0.02012"
"426.02400","35.50219","0.02050"
"426.39000","35.53274","0.02074"
"426.75600","35.56318","0.02054"
"427.12200","35.59367","0.02074"
"427.48800","35.62422","0.02114"
"427.85400","35.65471","0.02071"
"428.22000","35.68520","0.02095"
"428.58600","35.71569","0.02074"
"428.95200","35.74625","0.02088"
"429.31800","35.77668","0.02095"
"429.68400","35.80723","0.02078"
"430.05000","35.83773","0.02145"
"430.41600","35.86822","0.02165"
"430.78200","35.89871","0.02153"
"431.14800","35.92920","0.02131"
"431.51400","35.95964","0.02096"
"431.88000","35.99019","0.02200"
"432.24600","36.02074","0.02239"
"432.61200","36.05118","0.02351"
"432.97800","36.08173","0.02304"
"433.34400","36.11222","0.02327"
"433.71000","36.14272","0.02326"
"434.07600","36.17321","0.02315"
"434.44200","36.20370","0.02432"
"434.80800","36.23419","0.02336"
"435.17400","36.26468","0.02361"
"435.54000","36.29523","0.02398"
"435.90600","36.32573","0.02404"
"436.27200","36.35616","0.02445"
"436.63800","36.38671","0.02498"
"437.00400","36.41721","0.02589"
"437.37000","36.44764","0.02645"
"437.73600","36.47825","0.02641"
"438.10200","36.50874","0.02797"
"438.46800","36.53918","0.02767"
"438.83400","36.56973","0.02887"
"439.20000","36.60022","0.02885"
"439.56600","36.63066","0.02981"
"439.93200","36.66121","0.02999"
"440.29800","36.69176","0.03054"
"440.66400","36.72213","0.03163"
"441.03000","36.75275","0.03190"
"441.39600","36.78318","0.03249"
"441.76200","36.81367","0.03115"
"442.12800","36.84422","0.03251"
"442.49400","36.87471","0.03290"
"442.86000","36.90515","0.03257"
"443.22600","36.93576","0.03277"
"443.59200","36.96625","0.03288"
"443.95800","36.99662","0.03341"
"444.32400","37.02724","0.03320"
"444.69000","37.05773","0.03260"
"445.05600","37.08816","0.03278"
"445.42200","37.11866","0.03352"
"445.78800","37.14927","0.03318"
"446.15400","37.17970","0.03368"
"446.52000","37.21020","0.03350"
"446.88600","37.24075","0.03444"
"447.25200","37.27124","0.03466"
"447.61800","37.30167","0.03507"
"447.98400","37.33223","0.03488"
"448.35000","37.36272","0.03560"
"448.71600","37.39315","0.03564"
"449.08200","37.42370","0.03537"
"449.44800","37.45420","0.03545"
"449.81400","37.48469","0.03567"
"450.18000","37.51524","0.03554"
"450.54600","37.54573","0.03496"
"450.91200","37.57617","0.03586"
"451.27800","37.60678","0.03650"
"451.64400","37.63727","0.03633"
"452.01000","37.66765","0.03698"
"452.37600","37.69820","0.03747"
"452.74200","37.72875","0.03574"
"453.10800","37.75918","0.03581"
"453.47400","37.78968","0.03603"
"453.84000","37.82017","0.03616"
"454.20600","37.85072","0.03644"
"454.57200","37.88115","0.03668"
"454.93800","37.91171","0.03702"
"455.30400","37.94220","0.03728"
"455.67000","37.97269","0.03818"
"456.03600","38.00324","0.03842"
"456.40200","38.03373","0.03876"
"456.76800","38.06417","0.03829"
"457.13400","38.09472","0.03938"
"457.50000","38.12521","0.03930"
"457.86600","38.15565","0.04052"
"458.23200","38.18626","0.04062"
"458.59800","38.21669","0.04147"
"458.96400","38.24713","0.04164"
"459.33000","38.27774","0.04339"
"459.69600","38.30829","0.04365"
"460.06200","38.33860","0.04369"
"460.42800","38.36922","0.00633"
"460.79400","38.39977","0.00764"
"461.16000","38.43014","0.00667"
"461.52600","38.46069","0.00642"
"461.89200","38.49118","0.00645"
"462.25800","38.52174","0.00801"
"462.62400","38.55217","0.00551"
"462.99000","38.58272","0.00666"
"463.35600","38.61322","0.00963"
"463.72200","38.64371","0.00535"
"464.08800","38.67420","0.00598"
"464.45400","38.70469","0.00773"
"464.82000","38.73519","0.00631"
"465.18600","38.76568","0.00553"
"465.55200","38.79623","0.00725"
"465.91800","38.82667","0.00699"
"466.28400","38.85722","0.00604"
"466.65000","38.88771","0.00678"
"467.01600","38.91821","0.00833"
"467.38200","38.94870","0.00666"
"467.74800","38.97925","0.00616"
"468.11400","39.00968","0.00855"
"468.48000","39.04023","0.00609"
"468.84600","39.07079","0.00587"
"469.21200","39.10116","0.00864"
"469.57800","39.13177","0.00603"
"469.94400","39.16220","0.00587"
"470.31000","39.19270","0.00825"
"470.67600","39.22319","0.00652"
"471.04200","39.25374","0.00671"
"471.40800","39.28417","0.00897"
"471.77400","39.31472","0.00744"
"472.14000","39.34521","0.00644"
"472.50600","39.37571","0.00850"
"472.87200","39.40620","0.00757"
"473.23800","39.43670","0.00675"
"473.60400","39.46725","0.00924"
"473.97000","39.49768","0.00751"
"474.33600","39.52824","0.00722"
"474.70200","39.55867","0.00901"
"475.06800","39.58916","0.00691"
"475.43400","39.61971","0.00824"
"475.80000","39.65026","0.00878"
"476.16600","39.68064","0.00756"
"476.53200","39.71125","0.00946"
"476.89800","39.74180","0.00862"
"477.26400","39.77211","0.00773"
"477.63000","39.80279","0.01005"
"477.99600","39.83322","0.00854"
"478.36200","39.86366","0.00909"
"478.72800","39.89421","0.01023"
"479.09400","39.92470","0.00943"
"479.46000","39.95513","0.01000"
"479.82600","39.98569","0.01160"
"480.19200","40.01624","0.01044"
"480.55800","40.04667","0.01042"
"480.92400","40.07722","0.01140"
"481.29000","40.10765","0.01085"
"481.65600","40.13827","0.01106"
"482.02200","40.16870","0.01210"
"482.38800","40.19920","0.01137"
"482.75400","40.22969","0.01112"
"483.12000","40.26018","0.01242"
"483.48600","40.29073","0.01199"
"483.85200","40.32116","0.01232"
"484.21800","40.35172","0.01356"
"484.58400","40.38221","0.01147"
"484.95000","40.41270","0.01221"
"485.31600","40.44313","0.01295"
"485.68200","40.47369","0.01150"
"486.04800","40.50424","0.01259"
"486.41400","40.53468","0.01313"
"486.78000","40.56523","0.01250"
"487.14600","40.59578","0.01294"
"487.51200","40.62615","0.01351"
"487.87800","40.65670","0.01268"
"488.24400","40.68719","0.01371"
"488.61000","40.71769","0.01411"
"488.97600","40.74824","0.01323"
"489.34200","40.77873","0.01451"
"489.70800","40.80916","0.01450"
"490.07400","40.83966","0.01502"
"490.44000","40.87015","0.01503"
"490.80600","40.90070","0.01484"
"491.17200","40.93126","0.01505"
"491.53800","40.96175","0.01588"
"491.90400","40.99218","0.01568"
"492.27000","41.02268","0.01617"
"492.63600","41.05317","0.01106"
"493.00200","41.08366","0.01094"
"493.36800","41.11415","0.01180"
"493.73400","41.14471","0.01205"
"494.10000","41.17526","0.01240"
"494.46600","41.20563","0.01284"
"494.83200","41.23624","0.01289"
"495.19800","41.26674","0.00660"
"495.56400","41.29711","0.00575"
"495.93000","41.32772","0.00626"
"496.29600","41.35822","0.00645"
"496.66200","41.38865","0.00565"
"497.02800","41.41920","0.00543"
"497.39400","41.44975","0.00712"
"497.76000","41.48013","0.00604"
"498.12600","41.51068","0.00557"
"498.49200","41.54117","0.00612"
"498.85800","41.57172","0.00583"
"499.22400","41.60221","0.00552"
"499.59000","41.63271","0.00596"
"499.95600","41.66314","0.00686"
"500.32200","41.69370","0.00571"
"500.68800","41.72424","0.00633"
"501.05400","41.75473","0.00676"
"501.42000","41.78517","0.00534"
"501.78600","41.81572","0.00711"
"502.15200","41.84628","0.00618"
"502.51800","41.87665","0.00596"
"502.88400","41.90720","0.00654"
"503.25000","41.93769","0.00662"
"503.61600","41.96812","0.00629"
"503.98200","41.99874","0.00639"
"504.34800","42.02923","0.00719"
"504.71400","42.05966","0.00639"
"505.08000","42.09016","0.00684"
"505.44600","42.12077","0.00653"
"505.81200","42.15114","0.00757"
"506.17800","42.18176","0.00688"
"506.54400","42.21219","0.00587"
"506.91000","42.24268","0.00660"
"507.27600","42.27324","0.00629"
"507.64200","42.30373","0.00622"
"508.00800","42.33416","0.00641"
"508.37400","42.36471","0.00602"
"508.74000","42.39526","0.00587"
"509.10600","42.42570","0.00664"
"509.47200","42.45619","0.00601"
"509.83800","42.48674","0.00614"
"510.20400","42.51723","0.00555"
"510.57000","42.54766","0.00641"
"510.93600","42.57816","0.00519"
"511.30200","42.60871","0.00645"
"511.66800","42.63914","0.00579"
"512.03400","42.66976","0.00553"
"512.40000","42.70025","0.00591"
"512.76600","42.73062","0.00591"
"513.13200","42.76123","0.00554"
"513.49800","42.79173","0.00580"
"513.86400","42.82210","0.00614"
"514.23000","42.85271","0.00563"
"514.59600","42.88327","0.00614"
"514.96200","42.91364","0.00581"
"515.32800","42.94425","0.00614"
"515.69400","42.97469","0.00526"
"516.06000","43.00518","0.00519"
"516.42600","43.03567","0.00595"
"516.79200","43.06622","0.00520"
"517.15800","43.09665","0.00561"
"517.52400","43.12720","0.00596"
"517.89000","43.15770","0.00562"
"518.25600","43.18819","0.00581"
"518.62200","43.21869","0.00569"
"518.98800","43.24924","0.00591"
"519.35400","43.27973","0.00596"
"519.72000","43.31023","0.00579"
"520.08600","43.34077","0.00518"
"520.45200","43.37121","0.00556"
"520.81800","43.40170","0.00595"
"521.18400","43.43225","0.00565"
"521.55000","43.46274","0.00585"
"521.91600","43.49318","0.00548"
"522.28200","43.52373","0.00548"
"522.64800","43.55423","0.00535"
"523.01400","43.58465","0.00540"
"523.38000","43.61521","0.00540"
"523.74600","43.64570","0.00525"
"524.11200","43.67625","0.00539"
"524.47800","43.70669","0.00546"
"524.84400","43.73724","0.00600"
"525.21000","43.76767","0.00513"
"525.57600","43.79817","0.00537"
"525.94200","43.82872","0.00516"
"526.30800","43.85915","0.00543"
"526.67400","43.88970","0.00515"
"527.04000","43.92026","0.00537"
"527.40600","43.95075","0.00513"
"527.77200","43.98118","0.00519"
"528.13800","44.01173","0.00516"
"528.50400","44.04222","0.00541"
"528.87000","44.07266","0.00563"
"529.23600","44.10321","0.00512"
"529.60200","44.13371","0.00575"
"529.96800","44.16413","0.00539"
"530.33400","44.19469","0.00519"
"530.70000","44.22524","0.00526"
"531.06600","44.25562","0.00563"
"531.43200","44.28623","0.00517"
"531.79800","44.31672","0.00568"
"532.16400","44.34721","0.00481"
"532.53000","44.37771","0.00536"
"532.89600","44.40820","0.00496"
"533.26200","44.43869","0.00500"
"533.62800","44.46918","0.00595"
"533.99400","44.49973","0.00516"
"534.36000","44.53017","0.00471"
"534.72600","44.56072","0.00484"
"535.09200","44.59121","0.00545"
"535.45800","44.62170","0.00450"
"535.82400","44.65214","0.00502"
"536.19000","44.68269","0.00474"
"536.55600","44.71318","0.00508"
"536.92200","44.74368","0.00497"
"537.28800","44.77429","0.00492"
"537.65400","44.80472","0.00517"
"538.02000","44.83516","0.00504"
"538.38600","44.86570","0.00541"
"538.75200","44.89626","0.00491"
"539.11800","44.92669","0.00505"
"539.48400","44.95724","0.00553"
"539.85000","44.98768","0.00522"
"540.21600","45.01817","0.00468"
"540.58200","45.04873","0.00443"
"540.94800","45.07922","0.00514"
"541.21400","45.10134","0.00491"