File: Force_trajectories/170225_2/Specimen_RawData_9.csv
End date,"2/25/2017"
Specimen label,"1DG_3"
Maximum Load,"0.02647",N

Time,Extension,Load
(s),(mm),(N)
"0.00000","0.00000","0.00012"
"0.16200","0.01004","0.00080"
"0.32400","0.02691","0.00030"
"0.48600","0.04078","0.00103"
"0.64800","0.05417","0.00145"
"0.81000","0.06774","0.00068"
"0.97200","0.08119","0.00041"
"1.13400","0.09465","0.00195"
"1.29600","0.10816","0.00123"
"1.45800","0.12167","0.00075"
"1.62000","0.13518","0.00174"
"1.78200","0.14870","0.00145"
"1.94400","0.16221","0.00195"
"2.10600","0.17566","0.00248"
"2.26800","0.18911","0.00194"
"2.43000","0.20269","0.00152"
"2.59200","0.21620","0.00158"
"2.75400","0.22965","0.00214"
"2.91600","0.24316","0.00203"
"3.07800","0.25668","0.00223"
"3.24000","0.27013","0.00286"
"3.40200","0.28364","0.00289"
"3.56400","0.29721","0.00302"
"3.72600","0.31067","0.00279"
"3.88800","0.32412","0.00304"
"4.05000","0.33769","0.00293"
"4.21200","0.35120","0.00313"
"4.37400","0.36466","0.00370"
"4.53600","0.37817","0.00309"
"4.69800","0.39174","0.00372"
"4.86000","0.40513","0.00282"
"5.02200","0.41865","0.00342"
"5.18400","0.43216","0.00365"
"5.34600","0.44567","0.00350"
"5.50800","0.45918","0.00364"
"5.67000","0.47276","0.00339"
"5.83200","0.48621","0.00370"
"5.99400","0.49960","0.00405"
"6.15600","0.51317","0.00421"
"6.31800","0.52669","0.00447"
"6.48000","0.54014","0.00417"
"6.64200","0.55371","0.00407"
"6.80400","0.56722","0.00406"
"6.96600","0.58068","0.00445"
"7.12800","0.59413","0.00502"
"7.29000","0.60770","0.00470"
"7.45200","0.62115","0.00451"
"7.61400","0.63461","0.00504"
"7.77600","0.64818","0.00484"
"7.93800","0.66169","0.00490"
"8.10000","0.67514","0.00543"
"8.26200","0.68866","0.00435"
"8.42400","0.70223","0.00533"
"8.58600","0.71568","0.00521"
"8.74800","0.72907","0.00496"
"8.91000","0.74271","0.00556"
"9.07200","0.75622","0.00552"
"9.23400","0.76967","0.00519"
"9.39600","0.78324","0.00579"
"9.55800","0.79670","0.00559"
"9.72000","0.81021","0.00570"
"9.88200","0.82366","0.00587"
"10.04400","0.83717","0.00600"
"10.20600","0.85069","0.00570"
"10.36800","0.86414","0.00619"
"10.53000","0.87777","0.00613"
"10.69200","0.89122","0.00611"
"10.85400","0.90462","0.00624"
"11.01600","0.91819","0.00647"
"11.17800","0.93164","0.00622"
"11.34000","0.94515","0.00582"
"11.50200","0.95867","0.00602"
"11.66400","0.97224","0.00661"
"11.82600","0.98569","0.00667"
"11.98800","0.99914","0.00699"
"12.15000","1.01272","0.00642"
"12.31200","1.02617","0.00736"
"12.47400","1.03962","0.00742"
"12.63600","1.05319","0.00687"
"12.79800","1.06671","0.00746"
"12.96000","1.08016","0.00670"
"13.12200","1.09373","0.00734"
"13.28400","1.10718","0.00757"
"13.44600","1.12064","0.00743"
"13.60800","1.13415","0.00768"
"13.77000","1.14766","0.00757"
"13.93200","1.16117","0.00743"
"14.09400","1.17463","0.00758"
"14.25600","1.18826","0.00798"
"14.41800","1.20171","0.00791"
"14.58000","1.21516","0.00783"
"14.74200","1.22867","0.00773"
"14.90400","1.24219","0.00795"
"15.06600","1.25564","0.00848"
"15.22800","1.26915","0.00854"
"15.39000","1.28278","0.00871"
"15.55200","1.29624","0.00823"
"15.71400","1.30963","0.00834"
"15.87600","1.32320","0.00775"
"16.03800","1.33671","0.00893"
"16.20000","1.35023","0.00860"
"16.36200","1.36368","0.00859"
"16.52400","1.37725","0.00838"
"16.68600","1.39064","0.00888"
"16.84800","1.40416","0.00868"
"17.01000","1.41767","0.00950"
"17.17200","1.43118","0.00925"
"17.33400","1.44463","0.00920"
"17.49600","1.45821","0.00908"
"17.65800","1.47172","0.01009"
"17.82000","1.48517","0.00956"
"17.98200","1.49868","0.00941"
"18.14400","1.51220","0.00958"
"18.30600","1.52565","0.00945"
"18.46800","1.53916","0.00969"
"18.63000","1.55267","0.01000"
"18.79200","1.56619","0.00931"
"18.95400","1.57958","0.00989"
"19.11600","1.59321","0.00984"
"19.27800","1.60672","0.01026"
"19.44000","1.62018","0.01004"
"19.60200","1.63369","0.01018"
"19.76400","1.64720","0.01032"
"19.92600","1.66071","0.01024"
"20.08800","1.67417","0.01055"
"20.25000","1.68768","0.01088"
"20.41200","1.70119","0.01013"
"20.57400","1.71464","0.01080"
"20.73600","1.72822","0.01114"
"20.89800","1.74161","0.01083"
"21.06000","1.75512","0.01071"
"21.22200","1.76863","0.01098"
"21.38400","1.78221","0.01056"
"21.54600","1.79566","0.01121"
"21.70800","1.80923","0.01132"
"21.87000","1.82268","0.01102"
"22.03200","1.83620","0.01131"
"22.19400","1.84965","0.01127"
"22.35600","1.86322","0.01115"
"22.51800","1.87673","0.01141"
"22.68000","1.89013","0.01080"
"22.84200","1.90370","0.01154"
"23.00400","1.91721","0.01117"
"23.16600","1.93066","0.01144"
"23.32800","1.94418","0.01157"
"23.49000","1.95769","0.01212"
"23.65200","1.97120","0.01223"
"23.81400","1.98465","0.01160"
"23.97600","1.99823","0.01174"
"24.13800","2.01168","0.01182"
"24.30000","2.02513","0.01210"
"24.46200","2.03876","0.01175"
"24.62400","2.05222","0.01165"
"24.78600","2.06567","0.01189"
"24.94800","2.07918","0.01203"
"25.11000","2.09269","0.01218"
"25.27200","2.10615","0.01254"
"25.43400","2.11966","0.01194"
"25.59600","2.13323","0.01257"
"25.75800","2.14674","0.01248"
"25.92000","2.16014","0.01265"
"26.08200","2.17371","0.01225"
"26.24400","2.18722","0.01215"
"26.40600","2.20061","0.01182"
"26.56800","2.21413","0.01243"
"26.73000","2.22770","0.01277"
"26.89200","2.24121","0.01213"
"27.05400","2.25472","0.01273"
"27.21600","2.26818","0.01261"
"27.37800","2.28169","0.01269"
"27.54000","2.29514","0.01234"
"27.70200","2.30871","0.01277"
"27.86400","2.32223","0.01260"
"28.02600","2.33568","0.01318"
"28.18800","2.34925","0.01277"
"28.35000","2.36270","0.01345"
"28.51200","2.37616","0.01291"
"28.67400","2.38961","0.01302"
"28.83600","2.40318","0.01333"
"28.99800","2.41669","0.01315"
"29.16000","2.43015","0.01295"
"29.32200","2.44372","0.01317"
"29.48400","2.45723","0.01300"
"29.64600","2.47068","0.01338"
"29.80800","2.48420","0.01278"
"29.97000","2.49771","0.01408"
"30.13200","2.51116","0.01330"
"30.29400","2.52467","0.01356"
"30.45600","2.53819","0.01358"
"30.61800","2.55176","0.01344"
"30.78000","2.56515","0.01415"
"30.94200","2.57872","0.01367"
"31.10400","2.59224","0.01362"
"31.26600","2.60569","0.01356"
"31.42800","2.61920","0.01349"
"31.59000","2.63271","0.01308"
"31.75200","2.64616","0.01377"
"31.91400","2.65968","0.01286"
"32.07600","2.67319","0.01343"
"32.23800","2.68670","0.01334"
"32.40000","2.70010","0.01366"
"32.56200","2.71373","0.01370"
"32.72400","2.72718","0.01408"
"32.88600","2.74063","0.01379"
"33.04800","2.75420","0.01410"
"33.21000","2.76772","0.01403"
"33.37200","2.78117","0.01395"
"33.53400","2.79462","0.01470"
"33.69600","2.80819","0.01462"
"33.85800","2.82165","0.01406"
"34.02000","2.83510","0.01442"
"34.18200","2.84873","0.01408"
"34.34400","2.86224","0.01408"
"34.50600","2.87570","0.01411"
"34.66800","2.88915","0.01393"
"34.83000","2.90272","0.01452"
"34.99200","2.91617","0.01467"
"35.15400","2.92969","0.01403"
"35.31600","2.94320","0.01389"
"35.47800","2.95671","0.01469"
"35.64000","2.97016","0.01491"
"35.80200","2.98374","0.01479"
"35.96400","2.99719","0.01419"
"36.12600","3.01064","0.01479"
"36.28800","3.02415","0.01454"
"36.45000","3.03767","0.01532"
"36.61200","3.05118","0.01466"
"36.77400","3.06463","0.01515"
"36.93600","3.07820","0.01507"
"37.09800","3.09166","0.01508"
"37.26000","3.10517","0.01570"
"37.42200","3.11868","0.01524"
"37.58400","3.13219","0.01545"
"37.74600","3.14565","0.01527"
"37.90800","3.15922","0.01548"
"38.07000","3.17273","0.01528"
"38.23200","3.18618","0.01557"
"38.39400","3.19970","0.01611"
"38.55600","3.21321","0.01563"
"38.71800","3.22666","0.01620"
"38.88000","3.24017","0.01568"
"39.04200","3.25369","0.01603"
"39.20400","3.26720","0.01591"
"39.36600","3.28059","0.01639"
"39.52800","3.29422","0.01637"
"39.69000","3.30774","0.01612"
"39.85200","3.32113","0.01683"
"40.01400","3.33470","0.01597"
"40.17600","3.34815","0.01627"
"40.33800","3.36167","0.01581"
"40.50000","3.37512","0.01570"
"40.66200","3.38875","0.01671"
"40.82400","3.40220","0.01606"
"40.98600","3.41560","0.01609"
"41.14800","3.42923","0.01655"
"41.31000","3.44268","0.01662"
"41.47200","3.45613","0.01660"
"41.63400","3.46965","0.01730"
"41.79600","3.48322","0.01602"
"41.95800","3.49673","0.01666"
"42.12000","3.51018","0.01666"
"42.28200","3.52376","0.01709"
"42.44400","3.53715","0.01686"
"42.60600","3.55060","0.01674"
"42.76800","3.56417","0.01698"
"42.93000","3.57769","0.01674"
"43.09200","3.59114","0.01715"
"43.25400","3.60471","0.01748"
"43.41600","3.61822","0.01749"
"43.57800","3.63168","0.01730"
"43.74000","3.64513","0.01756"
"43.90200","3.65864","0.01801"
"44.06400","3.67215","0.01739"
"44.22600","3.68561","0.01720"
"44.38800","3.69918","0.01745"
"44.55000","3.71269","0.01774"
"44.71200","3.72614","0.01750"
"44.87400","3.73966","0.01744"
"45.03600","3.75323","0.01817"
"45.19800","3.76668","0.01845"
"45.36000","3.78013","0.01774"
"45.52200","3.79371","0.01826"
"45.68400","3.80722","0.01810"
"45.84600","3.82067","0.01809"
"46.00800","3.83424","0.01785"
"46.17000","3.84770","0.01860"
"46.33200","3.86115","0.01829"
"46.49400","3.87466","0.01837"
"46.65600","3.88817","0.01858"
"46.81800","3.90169","0.01818"
"46.98000","3.91520","0.01868"
"47.14200","3.92871","0.01841"
"47.30400","3.94210","0.01846"
"47.46600","3.95562","0.01907"
"47.62800","3.96919","0.01911"
"47.79000","3.98270","0.01899"
"47.95200","3.99615","0.01891"
"48.11400","4.00973","0.01865"
"48.27600","4.02318","0.01873"
"48.43800","4.03663","0.01871"
"48.60000","4.05020","0.01921"
"48.76200","4.06372","0.01873"
"48.92400","4.07717","0.01891"
"49.08600","4.09062","0.01943"
"49.24800","4.10419","0.01942"
"49.41000","4.11770","0.01939"
"49.57200","4.13116","0.01925"
"49.73400","4.14473","0.02027"
"49.89600","4.15818","0.02009"
"50.05800","4.17164","0.01946"
"50.22000","4.18509","0.01980"
"50.38200","4.19872","0.01925"
"50.54400","4.21217","0.01979"
"50.70600","4.22568","0.01991"
"50.86800","4.23920","0.01971"
"51.03000","4.25271","0.01886"
"51.19200","4.26610","0.02014"
"51.35400","4.27968","0.02005"
"51.51600","4.29319","0.02080"
"51.67800","4.30664","0.02029"
"51.84000","4.32015","0.02053"
"52.00200","4.33366","0.01987"
"52.16400","4.34718","0.02018"
"52.32600","4.36063","0.02043"
"52.48800","4.37420","0.02027"
"52.65000","4.38771","0.01961"
"52.81200","4.40117","0.02022"
"52.97400","4.41468","0.02010"
"53.13600","4.42825","0.02008"
"53.29800","4.44165","0.02021"
"53.46000","4.45516","0.02070"
"53.62200","4.46873","0.02023"
"53.78400","4.48218","0.02045"
"53.94600","4.49563","0.02094"
"54.10800","4.50921","0.02086"
"54.27000","4.52266","0.02069"
"54.43200","4.53617","0.02103"
"54.59400","4.54968","0.02109"
"54.75600","4.56326","0.02081"
"54.91800","4.57665","0.02107"
"55.08000","4.59016","0.02067"
"55.24200","4.60367","0.02052"
"55.40400","4.61713","0.02099"
"55.56600","4.63064","0.02117"
"55.72800","4.64421","0.01976"
"55.89000","4.65766","0.01995"
"56.05200","4.67118","0.02053"
"56.21400","4.68469","0.02075"
"56.37600","4.69826","0.02031"
"56.53800","4.71159","0.01974"
"56.70000","4.72523","0.02056"
"56.86200","4.73868","0.02072"
"57.02400","4.75219","0.02063"
"57.18600","4.76564","0.02082"
"57.34800","4.77922","0.02045"
"57.51000","4.79267","0.02113"
"57.67200","4.80612","0.02075"
"57.83400","4.81969","0.02114"
"57.99600","4.83321","0.02129"
"58.15800","4.84666","0.02097"
"58.32000","4.86023","0.02095"
"58.48200","4.87374","0.02110"
"58.64400","4.88714","0.02122"
"58.80600","4.90059","0.02191"
"58.96800","4.91416","0.02181"
"59.13000","4.92767","0.02139"
"59.29200","4.94113","0.02151"
"59.45400","4.95464","0.02213"
"59.61600","4.96821","0.02139"
"59.77800","4.98166","0.02195"
"59.94000","4.99518","0.02170"
"60.10200","5.00875","0.02213"
"60.26400","5.02214","0.02274"
"60.42600","5.03565","0.02225"
"60.58800","5.04923","0.02208"
"60.75000","5.06274","0.02251"
"60.91200","5.07619","0.02206"
"61.07400","5.08970","0.02273"
"61.23600","5.10322","0.02253"
"61.39800","5.11667","0.02304"
"61.56000","5.13018","0.02256"
"61.72200","5.14369","0.02245"
"61.88400","5.15715","0.02221"
"62.04600","5.17072","0.02259"
"62.20800","5.18423","0.02288"
"62.37000","5.19768","0.02266"
"62.53200","5.21114","0.02310"
"62.69400","5.22465","0.02306"
"62.85600","5.23816","0.02271"
"63.01800","5.25167","0.02307"
"63.18000","5.26519","0.02306"
"63.34200","5.27870","0.02353"
"63.50400","5.29221","0.02383"
"63.66600","5.30566","0.02272"
"63.82800","5.31918","0.02330"
"63.99000","5.33269","0.02330"
"64.15200","5.34614","0.02339"
"64.31400","5.35965","0.02374"
"64.47600","5.37323","0.02364"
"64.63800","5.38668","0.02342"
"64.80000","5.40019","0.02388"
"64.96200","5.41370","0.02397"
"65.12400","5.42716","0.02383"
"65.28600","5.44067","0.02373"
"65.44800","5.45418","0.02413"
"65.61000","5.46769","0.02429"
"65.77200","5.48121","0.02398"
"65.93400","5.49472","0.02435"
"66.09600","5.50817","0.02418"
"66.25800","5.52162","0.02376"
"66.42000","5.53520","0.02420"
"66.58200","5.54865","0.02345"
"66.74400","5.56216","0.02354"
"66.90600","5.57567","0.02322"
"67.06800","5.58924","0.02464"
"67.23000","5.60270","0.02447"
"67.39200","5.61609","0.02416"
"67.55400","5.62978","0.02371"
"67.71600","5.64318","0.02410"
"67.87800","5.65663","0.02407"
"68.04000","5.67020","0.02439"
"68.20200","5.68377","0.02428"
"68.36400","5.69717","0.02395"
"68.52600","5.71068","0.02429"
"68.68800","5.72419","0.02459"
"68.85000","5.73764","0.02470"
"69.01200","5.75115","0.02413"
"69.17400","5.76473","0.02477"
"69.33600","5.77824","0.02474"
"69.49800","5.79169","0.02445"
"69.66000","5.80520","0.02456"
"69.82200","5.81872","0.02426"
"69.98400","5.83217","0.02388"
"70.14600","5.84568","0.02475"
"70.30800","5.85913","0.02443"
"70.47000","5.87265","0.02457"
"70.63200","5.88616","0.02502"
"70.79400","5.89973","0.02446"
"70.95600","5.91319","0.02454"
"71.11800","5.92664","0.02462"
"71.28000","5.94021","0.02491"
"71.44200","5.95372","0.02480"
"71.60400","5.96717","0.02436"
"71.76600","5.98069","0.02452"
"71.92800","5.99420","0.02515"
"72.09000","6.00771","0.02493"
"72.25200","6.02116","0.02485"
"72.41400","6.03468","0.02500"
"72.57600","6.04813","0.02471"
"72.73800","6.06158","0.02463"
"72.90000","6.07521","0.02487"
"73.06200","6.08867","0.02447"
"73.22400","6.10218","0.02491"
"73.38600","6.11563","0.02482"
"73.54800","6.12920","0.02358"
"73.71000","6.14266","0.02369"
"73.87200","6.15611","0.01032"
"74.03400","6.16968","0.00382"
"74.19600","6.18319","0.00459"
"74.35800","6.19665","0.00642"
"74.52000","6.21022","0.00230"
"74.68200","6.22373","0.00127"
"74.84400","6.23712","0.00130"
"75.00600","6.25070","0.00194"
"75.16800","6.26421","0.00095"
"75.33000","6.27766","0.00112"
"75.49200","6.29111","0.00357"
"75.65400","6.30475","0.00229"
"75.81600","6.31826","0.00245"
"75.97800","6.33165","0.00332"
"76.14000","6.34522","0.00224"
"76.30200","6.35868","0.00161"
"76.46400","6.37219","0.00241"
"76.62600","6.38564","0.00355"
"76.78800","6.39921","0.00268"
"76.95000","6.41261","0.00419"
"77.11200","6.42618","0.00421"
"77.27400","6.43969","0.00254"
"77.43600","6.45320","0.00344"
"77.59800","6.46660","0.00366"
"77.76000","6.48017","0.00355"
"77.92200","6.49368","0.00373"
"78.08400","6.50713","0.00451"
"78.24600","6.52071","0.00320"
"78.40800","6.53428","0.00323"
"78.57000","6.54767","0.00391"
"78.73200","6.56118","0.00399"
"78.89400","6.57464","0.00386"
"79.05600","6.58821","0.00440"
"79.21800","6.60160","0.00360"
"79.38000","6.61523","0.00406"
"79.54200","6.62869","0.00472"
"79.70400","6.64220","0.00465"
"79.86600","6.65565","0.00389"
"80.02800","6.66916","0.00478"
"80.19000","6.68268","0.00451"
"80.35200","6.69619","0.00375"
"80.51400","6.70970","0.00429"
"80.67600","6.72315","0.00521"
"80.83800","6.73661","0.00461"
"81.00000","6.75024","0.00545"
"81.16200","6.76369","0.00439"
"81.32400","6.77714","0.00444"
"81.48600","6.79066","0.00475"
"81.64800","6.80417","0.00485"
"81.81000","6.81762","0.00435"
"81.97200","6.83119","0.00505"
"82.13400","6.84477","0.00543"
"82.29600","6.85822","0.00503"
"82.45800","6.87161","0.00466"
"82.62000","6.88518","0.00504"
"82.78200","6.89870","0.00499"
"82.94400","6.91209","0.00528"
"83.10600","6.92572","0.00502"
"83.26800","6.93917","0.00523"
"83.43000","6.95269","0.00509"
"83.59200","6.96620","0.00527"
"83.75400","6.97965","0.00558"
"83.91600","6.99316","0.00537"
"84.07800","7.00662","0.00545"
"84.24000","7.02025","0.00604"
"84.40200","7.03370","0.00604"
"84.56400","7.04709","0.00597"
"84.72600","7.06067","0.00609"
"84.88800","7.07418","0.00558"
"85.05000","7.08769","0.00584"
"85.21200","7.10114","0.00632"
"85.37400","7.11472","0.00601"
"85.53600","7.12811","0.00579"
"85.69800","7.14162","0.00672"
"85.86000","7.15519","0.00638"
"86.02200","7.16871","0.00603"
"86.18400","7.18210","0.00634"
"86.34600","7.19573","0.00644"
"86.50800","7.20918","0.00627"
"86.67000","7.22264","0.00653"
"86.83200","7.23615","0.00624"
"86.99400","7.24972","0.00597"
"87.15600","7.26323","0.00637"
"87.31800","7.27668","0.00629"
"87.48000","7.29020","0.00663"
"87.64200","7.30365","0.00673"
"87.80400","7.31710","0.00710"
"87.96600","7.33068","0.00698"
"88.12800","7.34419","0.00724"
"88.29000","7.35764","0.00663"
"88.45200","7.37115","0.00759"
"88.61400","7.38467","0.00700"
"88.77600","7.39818","0.00697"
"88.93800","7.41163","0.00703"
"89.10000","7.42520","0.00671"
"89.26200","7.43865","0.00759"
"89.42400","7.45211","0.00733"
"89.58600","7.46574","0.00663"
"89.74800","7.47919","0.00730"
"89.91000","7.49264","0.00759"
"90.07200","7.50616","0.00723"
"90.23400","7.51967","0.00742"
"90.39600","7.53312","0.00788"
"90.55800","7.54663","0.00770"
"90.72000","7.56021","0.00780"
"90.88200","7.57372","0.00791"
"91.04400","7.58717","0.00769"
"91.20600","7.60074","0.00770"
"91.36800","7.61420","0.00836"
"91.53000","7.62765","0.00754"
"91.69200","7.64116","0.00808"
"91.85400","7.65468","0.00755"
"92.01600","7.66819","0.00864"
"92.17800","7.68164","0.00854"
"92.34000","7.69521","0.00894"
"92.50200","7.70866","0.00807"
"92.66400","7.72212","0.00800"
"92.82600","7.73569","0.00799"
"92.98800","7.74920","0.00840"
"93.15000","7.76266","0.00874"
"93.31200","7.77623","0.00822"
"93.47400","7.78974","0.00815"
"93.63600","7.80319","0.00875"
"93.79800","7.81664","0.00825"
"93.96000","7.83016","0.00888"
"94.12200","7.84361","0.00884"
"94.28400","7.85706","0.00880"
"94.44600","7.87069","0.00826"
"94.60800","7.88427","0.00912"
"94.77000","7.89766","0.00889"
"94.93200","7.91123","0.00871"
"95.09400","7.92468","0.00915"
"95.25600","7.93814","0.00893"
"95.41800","7.95159","0.00914"
"95.58000","7.96516","0.00915"
"95.74200","7.97867","0.00927"
"95.90400","7.99213","0.00904"
"96.06600","8.00570","0.00902"
"96.22800","8.01921","0.00887"
"96.39000","8.03266","0.00922"
"96.55200","8.04624","0.00893"
"96.71400","8.05969","0.00951"
"96.87600","8.07320","0.00897"
"97.03800","8.08665","0.01001"
"97.20000","8.10023","0.00976"
"97.36200","8.11368","0.00957"
"97.52400","8.12713","0.00994"
"97.68600","8.14070","0.01000"
"97.84800","8.15422","0.00993"
"98.01000","8.16767","0.00964"
"98.17200","8.18118","0.01029"
"98.33400","8.19469","0.00978"
"98.49600","8.20815","0.00975"
"98.65800","8.22166","0.01003"
"98.82000","8.23517","0.01003"
"98.98200","8.24862","0.00952"
"99.14400","8.26214","0.00905"
"99.30600","8.27571","0.01012"
"99.46800","8.28922","0.00947"
"99.63000","8.30267","0.00971"
"99.79200","8.31619","0.00994"
"99.95400","8.32970","0.01018"
"100.11600","8.34315","0.01079"
"100.27800","8.35672","0.01082"
"100.44000","8.37018","0.01050"
"100.60200","8.38363","0.01064"
"100.76400","8.39714","0.01056"
"100.92600","8.41071","0.01006"
"101.08800","8.42422","0.01080"
"101.25000","8.43762","0.01057"
"101.41200","8.45119","0.01025"
"101.57400","8.46476","0.00996"
"101.73600","8.47816","0.01002"
"101.89800","8.49167","0.01044"
"102.06000","8.50518","0.01066"
"102.22200","8.51869","0.01116"
"102.38400","8.53221","0.01061"
"102.54600","8.54566","0.01048"
"102.70800","8.55917","0.01102"
"102.87000","8.57262","0.01105"
"103.03200","8.58614","0.01079"
"103.19400","8.59971","0.01149"
"103.35600","8.61316","0.01152"
"103.51800","8.62667","0.01104"
"103.68000","8.64019","0.01153"
"103.84200","8.65370","0.01056"
"104.00400","8.66721","0.01139"
"104.16600","8.68072","0.01103"
"104.32800","8.69423","0.01164"
"104.49000","8.70763","0.01141"
"104.65200","8.72120","0.01209"
"104.81400","8.73471","0.01132"
"104.97600","8.74811","0.01208"
"105.13800","8.76168","0.01177"
"105.30000","8.77519","0.01205"
"105.46200","8.78870","0.01167"
"105.62400","8.80216","0.01171"
"105.78600","8.81573","0.01207"
"105.94800","8.82924","0.01208"
"106.11000","8.84269","0.01200"
"106.27200","8.85627","0.01204"
"106.43400","8.86966","0.01117"
"106.59600","8.88317","0.01145"
"106.75800","8.89668","0.01182"
"106.92000","8.91014","0.01171"
"107.08200","8.92371","0.01170"
"107.24400","8.93722","0.01183"
"107.40600","8.95067","0.01247"
"107.56800","8.96412","0.01170"
"107.73000","8.97764","0.01197"
"107.89200","8.99121","0.01168"
"108.05400","9.00472","0.01208"
"108.21600","9.01812","0.01200"
"108.37800","9.03169","0.01200"
"108.54000","9.04520","0.01191"
"108.70200","9.05865","0.01191"
"108.86400","9.07216","0.01272"
"109.02600","9.08574","0.01218"
"109.18800","9.09919","0.01215"
"109.35000","9.11264","0.01240"
"109.51200","9.12621","0.01181"
"109.67400","9.13973","0.01164"
"109.83600","9.15318","0.01198"
"109.99800","9.16669","0.01226"
"110.16000","9.18021","0.01282"
"110.32200","9.19366","0.01260"
"110.48400","9.20711","0.01215"
"110.64600","9.22068","0.01225"
"110.80800","9.23419","0.01223"
"110.97000","9.24765","0.01303"
"111.13200","9.26122","0.01243"
"111.29400","9.27473","0.01222"
"111.45600","9.28818","0.01357"
"111.61800","9.30164","0.01303"
"111.78000","9.31521","0.01283"
"111.94200","9.32866","0.01263"
"112.10400","9.34217","0.01340"
"112.26600","9.35575","0.01292"
"112.42800","9.36920","0.01305"
"112.59000","9.38265","0.01357"
"112.75200","9.39622","0.01360"
"112.91400","9.40974","0.01310"
"113.07600","9.42319","0.01338"
"113.23800","9.43670","0.01333"
"113.40000","9.45015","0.01447"
"113.56200","9.46367","0.01363"
"113.72400","9.47718","0.01398"
"113.88600","9.49069","0.01372"
"114.04800","9.50420","0.01421"
"114.21000","9.51760","0.01410"
"114.37200","9.53123","0.01354"
"114.53400","9.54468","0.01398"
"114.69600","9.55819","0.01414"
"114.85800","9.57171","0.01443"
"115.02000","9.58522","0.01390"
"115.18200","9.59867","0.01358"
"115.34400","9.61218","0.01478"
"115.50600","9.62564","0.01357"
"115.66800","9.63915","0.01358"
"115.83000","9.65260","0.01398"
"115.99200","9.66617","0.01348"
"116.15400","9.67969","0.01405"
"116.31600","9.69320","0.01371"
"116.47800","9.70671","0.01346"
"116.64000","9.72022","0.01455"
"116.80200","9.73368","0.01337"
"116.96400","9.74719","0.01356"
"117.12600","9.76070","0.01402"
"117.28800","9.77421","0.01369"
"117.45000","9.78767","0.01397"
"117.61200","9.80124","0.01369"
"117.77400","9.81469","0.01394"
"117.93600","9.82808","0.01418"
"118.09800","9.84171","0.01470"
"118.26000","9.85517","0.01452"
"118.42200","9.86868","0.01423"
"118.58400","9.88225","0.01405"
"118.74600","9.89570","0.01376"
"118.90800","9.90922","0.01399"
"119.07000","9.92261","0.01465"
"119.23200","9.93624","0.01467"
"119.39400","9.94970","0.01461"
"119.55600","9.96315","0.01454"
"119.71800","9.97672","0.01386"
"119.88000","9.99023","0.01439"
"120.04200","10.00363","0.01433"
"120.20400","10.01714","0.01484"
"120.36600","10.03071","0.01470"
"120.52800","10.04416","0.01490"
"120.69000","10.05762","0.01431"
"120.85200","10.07119","0.01466"
"121.01400","10.08470","0.01525"
"121.17600","10.09815","0.01432"
"121.33800","10.11167","0.01398"
"121.50000","10.12524","0.01492"
"121.66200","10.13863","0.01441"
"121.82400","10.15214","0.01484"
"121.98600","10.16566","0.01407"
"122.14800","10.17917","0.01430"
"122.31000","10.19268","0.01481"
"122.47200","10.20625","0.01486"
"122.63400","10.21971","0.01511"
"122.79600","10.23310","0.01444"
"122.95800","10.24667","0.01491"
"123.12000","10.26018","0.01471"
"123.28200","10.27363","0.01514"
"123.44400","10.28721","0.01515"
"123.60600","10.30072","0.01447"
"123.76800","10.31417","0.01475"
"123.93000","10.32769","0.01474"
"124.09200","10.34120","0.01475"
"124.25400","10.35465","0.01470"
"124.41600","10.36810","0.01503"
"124.57800","10.38168","0.01513"
"124.74000","10.39519","0.01491"
"124.90200","10.40870","0.01491"
"125.06400","10.42221","0.01463"
"125.22600","10.43572","0.01508"
"125.38800","10.44918","0.01454"
"125.55000","10.46263","0.01518"
"125.71200","10.47614","0.01448"
"125.87400","10.48972","0.01455"
"126.03600","10.50311","0.01489"
"126.19800","10.51674","0.01450"
"126.36000","10.53019","0.01464"
"126.52200","10.54359","0.01499"
"126.68400","10.55722","0.01505"
"126.84600","10.57067","0.01506"
"127.00800","10.58418","0.01478"
"127.17000","10.59769","0.01494"
"127.33200","10.61127","0.01541"
"127.49400","10.62472","0.01522"
"127.65600","10.63811","0.01564"
"127.81800","10.65174","0.01560"
"127.98000","10.66520","0.01598"
"128.14200","10.67865","0.01509"
"128.30400","10.69216","0.01511"
"128.46600","10.70573","0.01581"
"128.62800","10.71913","0.01589"
"128.79000","10.73264","0.01521"
"128.95200","10.74615","0.01621"
"129.11400","10.75966","0.01574"
"129.27600","10.77312","0.01532"
"129.43800","10.78675","0.01571"
"129.60000","10.80020","0.01564"
"129.76200","10.81365","0.01518"
"129.92400","10.82723","0.01596"
"130.08600","10.84074","0.01666"
"130.24800","10.85419","0.01659"
"130.41000","10.86765","0.01609"
"130.57200","10.88116","0.01562"
"130.73400","10.89461","0.01650"
"130.89600","10.90812","0.01607"
"131.05800","10.92175","0.01563"
"131.22000","10.93521","0.01628"
"131.38200","10.94866","0.01629"
"131.54400","10.96217","0.01608"
"131.70600","10.97568","0.01597"
"131.86800","10.98914","0.01583"
"132.03000","11.00265","0.01658"
"132.19200","11.01622","0.01709"
"132.35400","11.02967","0.01638"
"132.51600","11.04319","0.01639"
"132.67800","11.05676","0.01615"
"132.84000","11.07015","0.01662"
"133.00200","11.08360","0.01663"
"133.16400","11.09718","0.01557"
"133.32600","11.11069","0.01642"
"133.48800","11.12414","0.01599"
"133.65000","11.13765","0.01628"
"133.81200","11.15117","0.01621"
"133.97400","11.16468","0.01647"
"134.13600","11.17813","0.01651"
"134.29800","11.19170","0.01653"
"134.46000","11.20522","0.01667"
"134.62200","11.21861","0.01675"
"134.78400","11.23224","0.01611"
"134.94600","11.24575","0.01666"
"135.10800","11.25915","0.01642"
"135.27000","11.27272","0.01672"
"135.43200","11.28617","0.01667"
"135.59400","11.29962","0.01693"
"135.75600","11.31314","0.01637"
"135.91800","11.32671","0.01655"
"136.08000","11.34016","0.01637"
"136.24200","11.35361","0.01654"
"136.40400","11.36718","0.01632"
"136.56600","11.38070","0.01672"
"136.72800","11.39415","0.01681"
"136.89000","11.40760","0.01623"
"137.05200","11.42118","0.01649"
"137.21400","11.43469","0.01701"
"137.37600","11.44814","0.01676"
"137.53800","11.46171","0.01671"
"137.70000","11.47517","0.01697"
"137.86200","11.48862","0.01675"
"138.02400","11.50219","0.01672"
"138.18600","11.51570","0.01646"
"138.34800","11.52915","0.01767"
"138.51000","11.54273","0.01693"
"138.67200","11.55624","0.01755"
"138.83400","11.56969","0.01695"
"138.99600","11.58315","0.01701"
"139.15800","11.59666","0.01693"
"139.32000","11.61017","0.01634"
"139.48200","11.62362","0.01695"
"139.64400","11.63720","0.01717"
"139.80600","11.65071","0.01686"
"139.96800","11.66416","0.01730"
"140.13000","11.67767","0.01704"
"140.29200","11.69119","0.01672"
"140.45400","11.70470","0.01739"
"140.61600","11.71815","0.01708"
"140.77800","11.73172","0.01692"
"140.94000","11.74518","0.01678"
"141.10200","11.75863","0.01732"
"141.26400","11.77220","0.01730"
"141.42600","11.78565","0.01715"
"141.58800","11.79917","0.01689"
"141.75000","11.81268","0.01759"
"141.91200","11.82619","0.01785"
"142.07400","11.83964","0.01774"
"142.23600","11.85316","0.01776"
"142.39800","11.86673","0.01779"
"142.56000","11.88018","0.01808"
"142.72200","11.89363","0.01823"
"142.88400","11.90721","0.01801"
"143.04600","11.92072","0.01804"
"143.20800","11.93411","0.01792"
"143.37000","11.94774","0.01720"
"143.53200","11.96119","0.01765"
"143.69400","11.97465","0.01753"
"143.85600","11.98816","0.01808"
"144.01800","12.00167","0.01776"
"144.18000","12.01518","0.01779"
"144.34200","12.02858","0.01768"
"144.50400","12.04221","0.01724"
"144.66600","12.05572","0.01773"
"144.82800","12.06912","0.01773"
"144.99000","12.08269","0.01780"
"145.15200","12.09620","0.01757"
"145.31400","12.10971","0.01782"
"145.47600","12.12323","0.01748"
"145.63800","12.13668","0.01768"
"145.80000","12.15019","0.01788"
"145.96200","12.16364","0.01759"
"146.12400","12.17721","0.01769"
"146.28600","12.19073","0.01808"
"146.44800","12.20412","0.01779"
"146.61000","12.21769","0.01792"
"146.77200","12.23120","0.01783"
"146.93400","12.24466","0.01882"
"147.09600","12.25817","0.01799"
"147.25800","12.27168","0.01816"
"147.42000","12.28520","0.01797"
"147.58200","12.29865","0.01840"
"147.74400","12.31216","0.01824"
"147.90600","12.32573","0.01806"
"148.06800","12.33913","0.01786"
"148.23000","12.35270","0.01813"
"148.39200","12.36615","0.01844"
"148.55400","12.37966","0.01878"
"148.71600","12.39318","0.01861"
"148.87800","12.40669","0.01907"
"149.04000","12.42020","0.01852"
"149.20200","12.43365","0.01865"
"149.36400","12.44722","0.01806"
"149.52600","12.46068","0.01824"
"149.68800","12.47413","0.01802"
"149.85000","12.48770","0.01774"
"150.01200","12.50121","0.01781"
"150.17400","12.51467","0.01787"
"150.33600","12.52818","0.01793"
"150.49800","12.54169","0.01785"
"150.66000","12.55514","0.01834"
"150.82200","12.56866","0.01763"
"150.98400","12.58223","0.01829"
"151.14600","12.59574","0.01798"
"151.30800","12.60913","0.01785"
"151.47000","12.62271","0.01851"
"151.63200","12.63616","0.01813"
"151.79400","12.64967","0.01863"
"151.95600","12.66318","0.01805"
"152.11800","12.67670","0.01860"
"152.28000","12.69015","0.01842"
"152.44200","12.70366","0.01878"
"152.60400","12.71723","0.01863"
"152.76600","12.73069","0.01875"
"152.92800","12.74420","0.01824"
"153.09000","12.75771","0.01874"
"153.25200","12.77122","0.01800"
"153.41400","12.78462","0.01866"
"153.57600","12.79819","0.01810"
"153.73800","12.81170","0.01822"
"153.90000","12.82521","0.01882"
"154.06200","12.83867","0.01991"
"154.22400","12.85218","0.01567"
"154.38600","12.86569","0.01379"
"154.54800","12.87914","0.01451"
"154.71000","12.89266","0.01636"
"154.87200","12.90623","0.01627"
"155.03400","12.91968","0.01482"
"155.19600","12.93319","0.01662"
"155.35800","12.94671","0.01763"
"155.52000","12.96016","0.01552"
"155.68200","12.97367","0.01715"
"155.84400","12.98718","0.01821"
"156.00600","13.00070","0.01723"
"156.16800","13.01415","0.01709"
"156.33000","13.02766","0.01838"
"156.49200","13.04117","0.01706"
"156.65400","13.05463","0.01750"
"156.81600","13.06820","0.01848"
"156.97800","13.08171","0.01767"
"157.14000","13.09516","0.01784"
"157.30200","13.10868","0.01881"
"157.46400","13.12225","0.01840"
"157.62600","13.13570","0.01793"
"157.78800","13.14915","0.01939"
"157.95000","13.16267","0.01919"
"158.11200","13.17618","0.01869"
"158.27400","13.18963","0.01914"
"158.43600","13.20320","0.01996"
"158.59800","13.21666","0.01915"
"158.76000","13.23017","0.01895"
"158.92200","13.24368","0.01980"
"159.08400","13.25719","0.01901"
"159.24600","13.27065","0.01954"
"159.40800","13.28410","0.01955"
"159.57000","13.29767","0.01973"
"159.73200","13.31118","0.01944"
"159.89400","13.32464","0.01984"
"160.05600","13.33821","0.01969"
"160.21800","13.35172","0.01944"
"160.38000","13.36517","0.01916"
"160.54200","13.37875","0.01981"
"160.70400","13.39220","0.01977"
"160.86600","13.40565","0.02032"
"161.02800","13.41910","0.02008"
"161.19000","13.43274","0.01962"
"161.35200","13.44625","0.01994"
"161.51400","13.45964","0.01933"
"161.67600","13.47321","0.01954"
"161.83800","13.48666","0.02001"
"162.00000","13.50018","0.01978"
"162.16200","13.51363","0.02008"
"162.32400","13.52720","0.02055"
"162.48600","13.54072","0.01981"
"162.64800","13.55417","0.01948"
"162.81000","13.56774","0.02058"
"162.97200","13.58119","0.01979"
"163.13400","13.59459","0.02001"
"163.29600","13.60816","0.01983"
"163.45800","13.62173","0.02000"
"163.62000","13.63518","0.01938"
"163.78200","13.64869","0.02047"
"163.94400","13.66221","0.02040"
"164.10600","13.67566","0.02071"
"164.26800","13.68911","0.02040"
"164.43000","13.70268","0.02008"
"164.59200","13.71620","0.02051"
"164.75400","13.72965","0.02015"
"164.91600","13.74322","0.02115"
"165.07800","13.75673","0.02004"
"165.24000","13.77019","0.02083"
"165.40200","13.78364","0.02028"
"165.56400","13.79721","0.02021"
"165.72600","13.81067","0.02060"
"165.88800","13.82412","0.02037"
"166.05000","13.83769","0.02079"
"166.21200","13.85120","0.02092"
"166.37400","13.86466","0.02098"
"166.53600","13.87823","0.02091"
"166.69800","13.89174","0.02088"
"166.86000","13.90513","0.02113"
"167.02200","13.91864","0.02063"
"167.18400","13.93216","0.02131"
"167.34600","13.94567","0.02064"
"167.50800","13.95918","0.02142"
"167.67000","13.97275","0.02101"
"167.83200","13.98621","0.02061"
"167.99400","13.99966","0.02068"
"168.15600","14.01317","0.02000"
"168.31800","14.02668","0.02031"
"168.48000","14.04014","0.02052"
"168.64200","14.05371","0.02050"
"168.80400","14.06722","0.02013"
"168.96600","14.08068","0.02075"
"169.12800","14.09419","0.02048"
"169.29000","14.10770","0.02089"
"169.45200","14.12115","0.02027"
"169.61400","14.13460","0.02062"
"169.77600","14.14824","0.02030"
"169.93800","14.16169","0.02047"
"170.10000","14.17514","0.02129"
"170.26200","14.18871","0.02031"
"170.42400","14.20217","0.02074"
"170.58600","14.21568","0.02120"
"170.74800","14.22913","0.02106"
"170.91000","14.24271","0.02073"
"171.07200","14.25616","0.02106"
"171.23400","14.26961","0.02096"
"171.39600","14.28324","0.01974"
"171.55800","14.29669","0.02009"
"171.72000","14.31015","0.01949"
"171.88200","14.32366","0.02008"
"172.04400","14.33717","0.02075"
"172.20600","14.35062","0.02036"
"172.36800","14.36414","0.02030"
"172.53000","14.37771","0.02018"
"172.69200","14.39122","0.02021"
"172.85400","14.40467","0.02046"
"173.01600","14.41819","0.02031"
"173.17800","14.43170","0.02073"
"173.34000","14.44515","0.02027"
"173.50200","14.45866","0.02065"
"173.66400","14.47218","0.02093"
"173.82600","14.48563","0.02089"
"173.98800","14.49914","0.02038"
"174.15000","14.51271","0.02047"
"174.31200","14.52617","0.02066"
"174.47400","14.53962","0.02056"
"174.63600","14.55319","0.02091"
"174.79800","14.56670","0.02144"
"174.96000","14.58016","0.02136"
"175.12200","14.59373","0.02041"
"175.28400","14.60724","0.02128"
"175.44600","14.62069","0.02150"
"175.60800","14.63415","0.02126"
"175.77000","14.64772","0.02074"
"175.93200","14.66117","0.02159"
"176.09400","14.67462","0.02144"
"176.25600","14.68820","0.02150"
"176.41800","14.70171","0.02147"
"176.58000","14.71516","0.02064"
"176.74200","14.72867","0.02101"
"176.90400","14.74219","0.02128"
"177.06600","14.75564","0.02076"
"177.22800","14.76921","0.02129"
"177.39000","14.78266","0.02110"
"177.55200","14.79618","0.02146"
"177.71400","14.80963","0.02163"
"177.87600","14.82326","0.02159"
"178.03800","14.83671","0.02127"
"178.20000","14.85011","0.02165"
"178.36200","14.86368","0.02151"
"178.52400","14.87719","0.02141"
"178.68600","14.89064","0.02149"
"178.84800","14.90422","0.02184"
"179.01000","14.91773","0.02194"
"179.17200","14.93118","0.02167"
"179.33400","14.94457","0.02136"
"179.49600","14.95820","0.02161"
"179.65800","14.97166","0.02129"
"179.82000","14.98511","0.02177"
"179.98200","14.99868","0.02126"
"180.14400","15.01220","0.02172"
"180.30600","15.02565","0.02201"
"180.46800","15.03916","0.02155"
"180.63000","15.05267","0.02200"
"180.79200","15.06613","0.02179"
"180.95400","15.07964","0.02183"
"181.11600","15.09321","0.02181"
"181.27800","15.10672","0.02218"
"181.44000","15.12012","0.02133"
"181.60200","15.13369","0.02219"
"181.76400","15.14720","0.02248"
"181.92600","15.16071","0.02145"
"182.08800","15.17410","0.02225"
"182.25000","15.18768","0.02227"
"182.41200","15.20119","0.02207"
"182.57400","15.21470","0.02171"
"182.73600","15.22827","0.02166"
"182.89800","15.24167","0.02177"
"183.06000","15.25512","0.02165"
"183.22200","15.26869","0.02199"
"183.38400","15.28215","0.02190"
"183.54600","15.29566","0.02205"
"183.70800","15.30917","0.02187"
"183.87000","15.32274","0.02195"
"184.03200","15.33620","0.02549"
"184.19400","15.34965","0.00914"
"184.35600","15.36322","0.01672"
"184.51800","15.37661","0.00710"
"184.68000","15.39013","0.00836"
"184.84200","15.40370","0.01088"
"185.00400","15.41715","0.00925"
"185.16600","15.43060","0.00975"
"185.32800","15.44411","0.01095"
"185.49000","15.45769","0.00907"
"185.65200","15.47114","0.00744"
"185.81400","15.48465","0.00870"
"185.97600","15.49817","0.00880"
"186.13800","15.51168","0.01141"
"186.30000","15.52513","0.00345"
"186.46200","15.53876","0.00620"
"186.62400","15.55216","0.00300"
"186.78600","15.56561","0.00236"
"186.94800","15.57918","0.00225"
"187.11000","15.59269","0.00185"
"187.27200","15.60614","0.00174"
"187.43400","15.61966","0.00322"
"187.59600","15.63329","0.00164"
"187.75800","15.64674","0.00179"
"187.92000","15.66013","0.00506"
"188.08200","15.67377","0.00307"
"188.24400","15.68722","0.00576"
"188.40600","15.70067","0.00596"
"188.56800","15.71418","0.00387"
"188.73000","15.72776","0.00436"
"188.89200","15.74115","0.00595"
"189.05400","15.75466","0.00651"
"189.21600","15.76817","0.00605"
"189.37800","15.78169","0.00355"
"189.54000","15.79514","0.00367"
"189.70200","15.80865","0.00666"
"189.86400","15.82216","0.00612"
"190.02600","15.83568","0.00358"
"190.18800","15.84919","0.00561"
"190.35000","15.86270","-0.00055"
"190.51200","15.87615","0.00679"
"190.67400","15.88966","0.00521"
"190.83600","15.90318","0.00272"
"190.99800","15.91669","0.00563"
"191.16000","15.93008","0.00531"
"191.32200","15.94378","0.00386"
"191.48400","15.95723","0.00526"
"191.64600","15.97068","0.00436"
"191.80800","15.98419","0.00339"
"191.97000","15.99771","0.00549"
"192.13200","16.01110","0.00473"
"192.29400","16.02461","0.00394"
"192.45600","16.03818","0.00577"
"192.61800","16.05169","0.00564"
"192.78000","16.06515","0.00457"
"192.94200","16.07872","0.00585"
"193.10400","16.09217","0.00456"
"193.26600","16.10569","0.00504"
"193.42800","16.11920","0.00544"
"193.59000","16.13271","0.00433"
"193.75200","16.14616","0.00564"
"193.91400","16.15968","0.00482"
"194.07600","16.17319","0.00500"
"194.23800","16.18670","0.00506"
"194.40000","16.20015","0.00520"
"194.56200","16.21372","0.00564"
"194.72400","16.22718","0.00579"
"194.88600","16.24063","0.00533"
"195.04800","16.25420","0.00493"
"195.21000","16.26772","0.00621"
"195.37200","16.28117","0.00546"
"195.53400","16.29468","0.00524"
"195.69600","16.30819","0.00515"
"195.85800","16.32165","0.00579"
"196.02000","16.33516","0.00578"
"196.18200","16.34873","0.00598"
"196.34400","16.36218","0.00584"
"196.50600","16.37564","0.00589"
"196.66800","16.38921","0.00559"
"196.83000","16.40272","0.00597"
"196.99200","16.41617","0.00637"
"197.15400","16.42969","0.00547"
"197.31600","16.44320","0.00663"
"197.47800","16.45665","0.00626"
"197.64000","16.47016","0.00624"
"197.80200","16.48374","0.00632"
"197.96400","16.49719","0.00650"
"198.12600","16.51064","0.00606"
"198.28800","16.52421","0.00598"
"198.45000","16.53772","0.00669"
"198.61200","16.55118","0.00634"
"198.77400","16.56469","0.00605"
"198.93600","16.57826","0.00631"
"199.09800","16.59166","0.00686"
"199.26000","16.60517","0.00607"
"199.42200","16.61862","0.00669"
"199.58400","16.63213","0.00577"
"199.74600","16.64558","0.00635"
"199.90800","16.65922","0.00630"
"200.07000","16.67267","0.00660"
"200.23200","16.68618","0.00669"
"200.39400","16.69969","0.00686"
"200.55600","16.71321","0.00669"
"200.71800","16.72666","0.00672"
"200.88000","16.74017","0.00643"
"201.04200","16.75368","0.00684"
"201.20400","16.76720","0.00706"
"201.36600","16.78071","0.00669"
"201.52800","16.79422","0.00721"
"201.69000","16.80767","0.00687"
"201.85200","16.82113","0.00727"
"202.01400","16.83476","0.00703"
"202.17600","16.84821","0.00650"
"202.33800","16.86160","0.00710"
"202.50000","16.87512","0.00682"
"202.66200","16.88869","0.00749"
"202.82400","16.90220","0.00728"
"202.98600","16.91560","0.00709"
"203.14800","16.92923","0.00765"
"203.31000","16.94268","0.00696"
"203.47200","16.95613","0.00702"
"203.63400","16.96971","0.00701"
"203.79600","16.98322","0.00704"
"203.95800","16.99667","0.00722"
"204.12000","17.01018","0.00727"
"204.28200","17.02369","0.00702"
"204.44400","17.03721","0.00724"
"204.60600","17.05066","0.00753"
"204.76800","17.06423","0.00759"
"204.93000","17.07768","0.00756"
"205.09200","17.09114","0.00754"
"205.25400","17.10471","0.00785"
"205.41600","17.11822","0.00768"
"205.57800","17.13167","0.00782"
"205.74000","17.14513","0.00753"
"205.90200","17.15870","0.00762"
"206.06400","17.17215","0.00800"
"206.22600","17.18560","0.00794"
"206.38800","17.19918","0.00794"
"206.55000","17.21275","0.00822"
"206.71200","17.22620","0.00824"
"206.87400","17.23965","0.00816"
"207.03600","17.25323","0.00811"
"207.19800","17.26668","0.00791"
"207.36000","17.28013","0.00803"
"207.52200","17.29370","0.00842"
"207.68400","17.30722","0.00803"
"207.84600","17.32067","0.00875"
"208.00800","17.33424","0.00832"
"208.17000","17.34769","0.00858"
"208.33200","17.36115","0.00814"
"208.49400","17.37472","0.00841"
"208.65600","17.38817","0.00844"
"208.81800","17.40168","0.00911"
"208.98000","17.41520","0.00833"
"209.14200","17.42871","0.00584"
"209.30400","17.44222","0.00746"
"209.46600","17.45567","0.00713"
"209.62800","17.46919","0.00744"
"209.79000","17.48270","0.00741"
"209.95200","17.49615","0.00773"
"210.11400","17.50966","0.00497"
"210.27600","17.52317","0.00814"
"210.43800","17.53663","0.00779"
"210.60000","17.55020","0.00785"
"210.76200","17.56365","0.00805"
"210.92400","17.57711","0.00744"
"211.08600","17.59062","0.00758"
"211.24800","17.60419","0.00816"
"211.41000","17.61770","0.00845"
"211.57200","17.63116","0.00752"
"211.73400","17.64473","0.00735"
"211.89600","17.65818","0.00509"
"212.05800","17.67163","0.00350"
"212.22000","17.68521","0.00093"
"212.38200","17.69866","-0.00160"
"212.54400","17.71217","-0.00011"
"212.70600","17.72568","-0.00075"
"212.86800","17.73919","0.00230"
"213.03000","17.75271","0.00263"
"213.19200","17.76610","0.00592"
"213.35400","17.77973","0.00603"
"213.51600","17.79325","0.00633"
"213.67800","17.80664","0.00617"
"213.84000","17.82021","0.00594"
"214.00200","17.83372","0.00489"
"214.16400","17.84718","0.00569"
"214.32600","17.86063","0.00666"
"214.48800","17.87420","0.00591"
"214.65000","17.88765","0.00631"
"214.81200","17.90111","0.00621"
"214.97400","17.91468","0.00236"
"215.13600","17.92825","0.00091"
"215.29800","17.94164","0.00090"
"215.46000","17.95522","0.00030"
"215.62200","17.96873","0.00482"
"215.78400","17.98212","0.00611"
"215.94600","17.99563","0.00608"
"216.10800","18.00920","0.00617"
"216.27000","18.02272","0.00608"
"216.43200","18.03617","0.00661"
"216.59400","18.04974","0.00640"
"216.75600","18.06326","0.00668"
"216.91800","18.07665","0.00665"
"217.08000","18.09016","0.00659"
"217.24200","18.10373","0.00649"
"217.40400","18.11719","0.00661"
"217.56600","18.13064","0.00667"
"217.72800","18.14415","0.00726"
"217.89000","18.15766","0.00728"
"218.05200","18.17111","0.00733"
"218.21400","18.18475","0.00702"
"218.37600","18.19820","0.00750"
"218.53800","18.21165","0.00710"
"218.70000","18.22516","0.00787"
"218.86200","18.23868","0.00733"
"219.02400","18.25219","0.00693"
"219.18600","18.26564","0.00731"
"219.34800","18.27921","0.00736"
"219.51000","18.29267","0.00822"
"219.67200","18.30612","0.00773"
"219.83400","18.31969","0.00744"
"219.99600","18.33320","0.00731"
"220.15800","18.34666","0.00809"
"220.32000","18.36023","0.00785"
"220.48200","18.37368","0.00788"
"220.64400","18.38720","0.00806"
"220.80600","18.40065","0.00796"
"220.96800","18.41416","0.00777"
"221.13000","18.42767","0.00805"
"221.29200","18.44113","0.00786"
"221.45400","18.45470","0.00842"
"221.61600","18.46821","0.00836"
"221.77800","18.48166","0.00839"
"221.94000","18.49517","0.00833"
"222.10200","18.50869","0.00840"
"222.26400","18.52214","0.00891"
"222.42600","18.53565","0.00850"
"222.58800","18.54922","0.00874"
"222.75000","18.56268","0.00867"
"222.91200","18.57619","0.00891"
"223.07400","18.58970","0.00859"
"223.23600","18.60316","0.00821"
"223.39800","18.61655","0.00903"
"223.56000","18.63018","0.00863"
"223.72200","18.64369","0.00921"
"223.88400","18.65714","0.00871"
"224.04600","18.67072","0.00863"
"224.20800","18.68423","0.00864"
"224.37000","18.69768","0.00916"
"224.53200","18.71113","0.00945"
"224.69400","18.72465","0.00903"
"224.85600","18.73816","0.00977"
"225.01800","18.75161","0.00945"
"225.18000","18.76518","0.00953"
"225.34200","18.77870","0.00953"
"225.50400","18.79215","0.00962"
"225.66600","18.80572","0.00928"
"225.82800","18.81923","0.00978"
"225.99000","18.83263","0.00889"
"226.15200","18.84608","0.00934"
"226.31400","18.85971","0.01019"
"226.47600","18.87322","0.00989"
"226.63800","18.88668","0.00945"
"226.80000","18.90019","0.00977"
"226.96200","18.91370","0.00992"
"227.12400","18.92715","0.00963"
"227.28600","18.94067","0.00962"
"227.44800","18.95418","0.00963"
"227.61000","18.96763","0.01002"
"227.77200","18.98114","0.01014"
"227.93400","18.99472","0.00946"
"228.09600","19.00811","0.01021"
"228.25800","19.02162","0.01017"
"228.42000","19.03514","0.01001"
"228.58200","19.04871","0.00957"
"228.74400","19.06210","0.00967"
"228.90600","19.07573","0.01004"
"229.06800","19.08918","0.01034"
"229.23000","19.10270","0.01019"
"229.39200","19.11621","0.01028"
"229.55400","19.12972","0.01023"
"229.71600","19.14317","0.01024"
"229.87800","19.15657","0.01023"
"230.04000","19.17020","0.01042"
"230.20200","19.18371","0.01116"
"230.36400","19.19716","0.01094"
"230.52600","19.21074","0.01133"
"230.68800","19.22425","0.01049"
"230.85000","19.23764","0.01068"
"231.01200","19.25115","0.01059"
"231.17400","19.26467","0.01120"
"231.33600","19.27818","0.01088"
"231.49800","19.29169","0.01117"
"231.66000","19.30520","0.01114"
"231.82200","19.31872","0.01077"
"231.98400","19.33211","0.01064"
"232.14600","19.34568","0.01121"
"232.30800","19.35919","0.01185"
"232.47000","19.37265","0.01111"
"232.63200","19.38616","0.01140"
"232.79400","19.39973","0.01200"
"232.95600","19.41318","0.01179"
"233.11800","19.42664","0.01110"
"233.28000","19.44021","0.01175"
"233.44200","19.45372","0.01160"
"233.60400","19.46711","0.01172"
"233.76600","19.48068","0.01125"
"233.92800","19.49420","0.01170"
"234.09000","19.50771","0.01176"
"234.25200","19.52116","0.01151"
"234.41400","19.53473","0.01166"
"234.57600","19.54819","0.01160"
"234.73800","19.56164","0.01202"
"234.90000","19.57521","0.01238"
"235.06200","19.58867","0.01224"
"235.22400","19.60218","0.01240"
"235.38600","19.61569","0.01268"
"235.54800","19.62920","0.01226"
"235.71000","19.64265","0.01247"
"235.87200","19.65617","0.01249"
"236.03400","19.66962","0.01255"
"236.19600","19.68313","0.01273"
"236.35800","19.69659","0.01289"
"236.52000","19.71022","0.01312"
"236.68200","19.72367","0.01236"
"236.76200","19.73031","0.01219"