File: Force_trajectories/170212_3/Specimen_RawData_8.csv
End date,"2/12/2017"
Specimen label,"17DG_34"
Maximum Load,"0.10603",N

Time,Extension,Load
(s),(mm),(N)
"0.00000","0.00000","0.00060"
"0.34200","0.02852","0.00217"
"0.68400","0.05728","0.00282"
"1.02600","0.08574","0.00423"
"1.36800","0.11426","0.00501"
"1.71000","0.14272","0.00539"
"2.05200","0.17124","0.00666"
"2.39400","0.19976","0.00751"
"2.73600","0.22822","0.00802"
"3.07800","0.25668","0.00826"
"3.42000","0.28520","0.00964"
"3.76200","0.31366","0.00998"
"4.10400","0.34224","0.01052"
"4.44600","0.37070","0.01105"
"4.78800","0.39921","0.01172"
"5.13000","0.42773","0.01238"
"5.47200","0.45619","0.01301"
"5.81400","0.48465","0.01401"
"6.15600","0.51329","0.01406"
"6.49800","0.54163","0.01476"
"6.84000","0.57021","0.01555"
"7.18200","0.59873","0.01565"
"7.52400","0.62719","0.01591"
"7.86600","0.65577","0.01629"
"8.20800","0.68423","0.01647"
"8.55000","0.71275","0.01746"
"8.89200","0.74121","0.01746"
"9.23400","0.76967","0.01746"
"9.57600","0.79825","0.01835"
"9.91800","0.82677","0.01784"
"10.26000","0.85517","0.01836"
"10.60200","0.88375","0.01941"
"10.94400","0.91221","0.01890"
"11.28600","0.94073","0.01991"
"11.62800","0.96925","0.02073"
"11.97000","0.99771","0.02016"
"12.31200","1.02617","0.02072"
"12.65400","1.05469","0.02032"
"12.99600","1.08321","0.02102"
"13.33800","1.11179","0.02158"
"13.68000","1.14025","0.02149"
"14.02200","1.16865","0.02152"
"14.36400","1.19723","0.02129"
"14.70600","1.22575","0.02190"
"15.04800","1.25420","0.02256"
"15.39000","1.28272","0.02220"
"15.73200","1.31118","0.02337"
"16.07400","1.33970","0.02312"
"16.41600","1.36828","0.02333"
"16.75800","1.39668","0.02380"
"17.10000","1.42526","0.02383"
"17.44200","1.45378","0.02335"
"17.78400","1.48218","0.02354"
"18.12600","1.51076","0.02379"
"18.46800","1.53922","0.02376"
"18.81000","1.56768","0.02399"
"19.15200","1.59620","0.02417"
"19.49400","1.62472","0.02487"
"19.83600","1.65324","0.02438"
"20.17800","1.68176","0.02572"
"20.52000","1.71016","0.02482"
"20.86200","1.73868","0.02521"
"21.20400","1.76726","0.02490"
"21.54600","1.79566","0.02489"
"21.88800","1.82424","0.02457"
"22.23000","1.85276","0.02537"
"22.57200","1.88116","0.02540"
"22.91400","1.90974","0.02583"
"23.25600","1.93826","0.02598"
"23.59800","1.96666","0.02610"
"23.94000","1.99530","0.02566"
"24.28200","2.02364","0.02684"
"24.62400","2.05222","0.02584"
"24.96600","2.08080","0.02652"
"25.30800","2.10914","0.02641"
"25.65000","2.13772","0.02661"
"25.99200","2.16623","0.02721"
"26.33400","2.19469","0.02693"
"26.67600","2.22327","0.02697"
"27.01800","2.25167","0.02701"
"27.36000","2.28019","0.02763"
"27.70200","2.30877","0.02693"
"28.04400","2.33717","0.02812"
"28.38600","2.36569","0.02756"
"28.72800","2.39421","0.02786"
"29.07000","2.42267","0.02750"
"29.41200","2.45119","0.02791"
"29.75400","2.47971","0.02812"
"30.09600","2.50817","0.02830"
"30.43800","2.53675","0.02861"
"30.78000","2.56521","0.02879"
"31.12200","2.59373","0.02867"
"31.46400","2.62225","0.02847"
"31.80600","2.65059","0.02873"
"32.14800","2.67929","0.02860"
"32.49000","2.70775","0.02961"
"32.83200","2.73615","0.02945"
"33.17400","2.76473","0.02938"
"33.51600","2.79325","0.02910"
"33.85800","2.82171","0.02975"
"34.20000","2.85023","0.02933"
"34.54200","2.87869","0.02969"
"34.88400","2.90721","0.02970"
"35.22600","2.93567","0.03006"
"35.56800","2.96419","0.03005"
"35.91000","2.99277","0.03061"
"36.25200","3.02122","0.02980"
"36.59400","3.04974","0.03058"
"36.93600","3.07826","0.03003"
"37.27800","3.10672","0.03017"
"37.62000","3.13518","0.03081"
"37.96200","3.16370","0.02996"
"38.30400","3.19222","0.03058"
"38.64600","3.22068","0.03011"
"38.98800","3.24920","0.03070"
"39.33000","3.27766","0.03125"
"39.67200","3.30624","0.03122"
"40.01400","3.33476","0.03129"
"40.35600","3.36322","0.03129"
"40.69800","3.39174","0.03113"
"41.04000","3.42020","0.03167"
"41.38200","3.44872","0.03146"
"41.72400","3.47730","0.03147"
"42.06600","3.50576","0.03195"
"42.40800","3.53416","0.03203"
"42.75000","3.56274","0.03182"
"43.09200","3.59114","0.03233"
"43.43400","3.61972","0.03277"
"43.77600","3.64824","0.03262"
"44.11800","3.67670","0.03211"
"44.46000","3.70528","0.03272"
"44.80200","3.73368","0.03277"
"45.14400","3.76226","0.03257"
"45.48600","3.79078","0.03296"
"45.82800","3.81918","0.03282"
"46.17000","3.84770","0.03326"
"46.51200","3.87628","0.03301"
"46.85400","3.90468","0.03374"
"47.19600","3.93325","0.03334"
"47.53800","3.96171","0.03386"
"47.88000","3.99017","0.03370"
"48.22200","4.01875","0.03298"
"48.56400","4.04727","0.03365"
"48.90600","4.07567","0.03399"
"49.24800","4.10425","0.03374"
"49.59000","4.13265","0.03325"
"49.93200","4.16129","0.03404"
"50.27400","4.18975","0.03420"
"50.61600","4.21815","0.03385"
"50.95800","4.24673","0.03415"
"51.30000","4.27519","0.03412"
"51.64200","4.30371","0.03432"
"51.98400","4.33223","0.03494"
"52.32600","4.36069","0.03464"
"52.66800","4.38921","0.03456"
"53.01000","4.41773","0.03449"
"53.35200","4.44619","0.03443"
"53.69400","4.47477","0.03535"
"54.03600","4.50323","0.03498"
"54.37800","4.53169","0.03503"
"54.72000","4.56027","0.03503"
"55.06200","4.58873","0.03542"
"55.40400","4.61719","0.03552"
"55.74600","4.64571","0.03583"
"56.08800","4.67423","0.03585"
"56.43000","4.70275","0.03570"
"56.77200","4.73121","0.03532"
"57.11400","4.75973","0.03479"
"57.45600","4.78819","0.03464"
"57.79800","4.81676","0.03491"
"58.14000","4.84516","0.03455"
"58.48200","4.87374","0.03534"
"58.82400","4.90226","0.03508"
"59.16600","4.93066","0.03502"
"59.50800","4.95924","0.03518"
"59.85000","4.98770","0.03528"
"60.19200","5.01622","0.03516"
"60.53400","5.04474","0.03562"
"60.87600","5.07320","0.03571"
"61.21800","5.10172","0.03505"
"61.56000","5.13024","0.03525"
"61.90200","5.15870","0.03567"
"62.24400","5.18722","0.03567"
"62.58600","5.21574","0.03567"
"62.92800","5.24420","0.03589"
"63.27000","5.27278","0.03607"
"63.61200","5.30118","0.03597"
"63.95400","5.32970","0.03582"
"64.29600","5.35822","0.03634"
"64.63800","5.38668","0.03566"
"64.98000","5.41526","0.03697"
"65.32200","5.44378","0.03633"
"65.66400","5.47218","0.03672"
"66.00600","5.50076","0.03637"
"66.34800","5.52922","0.03670"
"66.69000","5.55768","0.03691"
"67.03200","5.58626","0.03653"
"67.37400","5.61466","0.03642"
"67.71600","5.64324","0.03613"
"68.05800","5.67169","0.03683"
"68.40000","5.70015","0.03675"
"68.74200","5.72873","0.03681"
"69.08400","5.75725","0.03695"
"69.42600","5.78565","0.03685"
"69.76800","5.81423","0.03696"
"70.11000","5.84269","0.03673"
"70.45200","5.87121","0.03720"
"70.79400","5.89973","0.03701"
"71.13600","5.92819","0.03646"
"71.47800","5.95671","0.03660"
"71.82000","5.98523","0.03693"
"72.16200","6.01369","0.03681"
"72.50400","6.04215","0.03710"
"72.84600","6.07073","0.03717"
"73.18800","6.09913","0.03716"
"73.53000","6.12777","0.03713"
"73.87200","6.15623","0.03722"
"74.21400","6.18469","0.03771"
"74.55600","6.21321","0.03765"
"74.89800","6.24173","0.03755"
"75.24000","6.27019","0.03782"
"75.58200","6.29877","0.03763"
"75.92400","6.32717","0.03747"
"76.26600","6.35569","0.03785"
"76.60800","6.38421","0.03816"
"76.95000","6.41267","0.03830"
"77.29200","6.44125","0.03852"
"77.63400","6.46971","0.03870"
"77.97600","6.49817","0.03867"
"78.31800","6.52675","0.03812"
"78.66000","6.55520","0.03865"
"79.00200","6.58372","0.03878"
"79.34400","6.61230","0.03880"
"79.68600","6.64064","0.03923"
"80.02800","6.66922","0.03874"
"80.37000","6.69780","0.03937"
"80.71200","6.72620","0.03897"
"81.05400","6.75472","0.03898"
"81.39600","6.78318","0.03895"
"81.73800","6.81164","0.03916"
"82.08000","6.84022","0.03944"
"82.42200","6.86868","0.03948"
"82.76400","6.89726","0.03952"
"83.10600","6.92578","0.03936"
"83.44800","6.95418","0.03943"
"83.79000","6.98276","0.03932"
"84.13200","7.01122","0.03863"
"84.47400","7.03968","0.03937"
"84.81600","7.06826","0.03952"
"85.15800","7.09678","0.03984"
"85.50000","7.12524","0.03948"
"85.84200","7.15370","0.03976"
"86.18400","7.18216","0.04019"
"86.52600","7.21074","0.03942"
"86.86800","7.23926","0.04008"
"87.21000","7.26772","0.03994"
"87.55200","7.29630","0.04028"
"87.89400","7.32470","0.04005"
"88.23600","7.35322","0.04041"
"88.57800","7.38168","0.04073"
"88.92000","7.41020","0.04032"
"89.26200","7.43871","0.04000"
"89.60400","7.46717","0.04035"
"89.94600","7.49569","0.04014"
"90.28800","7.52421","0.04050"
"90.63000","7.55273","0.04052"
"90.97200","7.58119","0.04030"
"91.31400","7.60971","0.04023"
"91.65600","7.63823","0.04069"
"91.99800","7.66669","0.04030"
"92.34000","7.69521","0.04062"
"92.68200","7.72373","0.04116"
"93.02400","7.75219","0.04006"
"93.36600","7.78077","0.04011"
"93.70800","7.80917","0.04044"
"94.05000","7.83769","0.04039"
"94.39200","7.86621","0.04008"
"94.73400","7.89467","0.04036"
"95.07600","7.92325","0.03960"
"95.41800","7.95177","0.03948"
"95.76000","7.98017","0.03954"
"96.10200","8.00875","0.04047"
"96.44400","8.03721","0.04040"
"96.78600","8.06567","0.04034"
"97.12800","8.09425","0.04013"
"97.47000","8.12271","0.04084"
"97.81200","8.15123","0.04027"
"98.15400","8.17975","0.04083"
"98.49600","8.20815","0.04081"
"98.83800","8.23673","0.04071"
"99.18000","8.26519","0.04072"
"99.52200","8.29365","0.04066"
"99.86400","8.32228","0.04098"
"100.20600","8.35074","0.04072"
"100.54800","8.37920","0.04138"
"100.89000","8.40772","0.04131"
"101.23200","8.43612","0.04164"
"101.57400","8.46476","0.04140"
"101.91600","8.49328","0.04094"
"102.25800","8.52168","0.04156"
"102.60000","8.55026","0.04074"
"102.94200","8.57872","0.04151"
"103.28400","8.60718","0.04110"
"103.62600","8.63576","0.04052"
"103.96800","8.66416","0.04117"
"104.31000","8.69274","0.04177"
"104.65200","8.72120","0.04142"
"104.99400","8.74966","0.04176"
"105.33600","8.77824","0.04134"
"105.67800","8.80676","0.04210"
"106.02000","8.83516","0.04162"
"106.36200","8.86374","0.04210"
"106.70400","8.89220","0.04177"
"107.04600","8.92072","0.04219"
"107.38800","8.94924","0.04173"
"107.73000","8.97776","0.04221"
"108.07200","9.00622","0.04237"
"108.41400","9.03474","0.04237"
"108.75600","9.06320","0.04212"
"109.09800","9.09178","0.04188"
"109.44000","9.12024","0.04209"
"109.78200","9.14864","0.04249"
"110.12400","9.17722","0.04231"
"110.46600","9.20573","0.04248"
"110.80800","9.23419","0.04242"
"111.15000","9.26271","0.04283"
"111.49200","9.29123","0.04286"
"111.83400","9.31969","0.04302"
"112.17600","9.34827","0.04284"
"112.51800","9.37667","0.04358"
"112.86000","9.40525","0.04340"
"113.20200","9.43377","0.04379"
"113.54400","9.46217","0.04298"
"113.88600","9.49075","0.04322"
"114.22800","9.51921","0.04356"
"114.57000","9.54773","0.04350"
"114.91200","9.57625","0.04333"
"115.25400","9.60465","0.04321"
"115.59600","9.63317","0.04338"
"115.93800","9.66175","0.04363"
"116.28000","9.69021","0.04371"
"116.62200","9.71873","0.04353"
"116.96400","9.74725","0.04354"
"117.30600","9.77571","0.04360"
"117.64800","9.80423","0.04344"
"117.99000","9.83275","0.04353"
"118.33200","9.86121","0.04430"
"118.67400","9.88979","0.04405"
"119.01600","9.91819","0.04414"
"119.35800","9.94671","0.04419"
"119.70000","9.97522","0.04414"
"120.04200","10.00363","0.04427"
"120.38400","10.03226","0.04436"
"120.72600","10.06073","0.04431"
"121.06800","10.08918","0.04440"
"121.41000","10.11776","0.04406"
"121.75200","10.14622","0.04486"
"122.09400","10.17474","0.04450"
"122.43600","10.20320","0.04438"
"122.77800","10.23166","0.04485"
"123.12000","10.26024","0.04422"
"123.46200","10.28876","0.04433"
"123.80400","10.31716","0.04451"
"124.14600","10.34574","0.04470"
"124.48800","10.37420","0.04466"
"124.83000","10.40266","0.04484"
"125.17200","10.43124","0.04472"
"125.51400","10.45970","0.04490"
"125.85600","10.48822","0.04459"
"126.19800","10.51674","0.04483"
"126.54000","10.54520","0.04462"
"126.88200","10.57372","0.04420"
"127.22400","10.60224","0.04417"
"127.56600","10.63070","0.04406"
"127.90800","10.65922","0.04416"
"128.25000","10.68774","0.04391"
"128.59200","10.71620","0.04475"
"128.93400","10.74478","0.04437"
"129.27600","10.77324","0.04470"
"129.61800","10.80170","0.04448"
"129.96000","10.83022","0.04466"
"130.30200","10.85868","0.04446"
"130.64400","10.88720","0.04472"
"130.98600","10.91578","0.04535"
"131.32800","10.94418","0.04471"
"131.67000","10.97269","0.04487"
"132.01200","11.00121","0.04480"
"132.35400","11.02967","0.04520"
"132.69600","11.05819","0.04516"
"133.03800","11.08671","0.04485"
"133.38000","11.11517","0.04483"
"133.72200","11.14375","0.04476"
"134.06400","11.17221","0.04508"
"134.40600","11.20073","0.04514"
"134.74800","11.22931","0.04555"
"135.09000","11.25765","0.04546"
"135.43200","11.28623","0.04531"
"135.77400","11.31475","0.04569"
"136.11600","11.34321","0.04539"
"136.45800","11.37179","0.04586"
"136.80000","11.40019","0.04587"
"137.14200","11.42871","0.04573"
"137.48400","11.45723","0.04615"
"137.82600","11.48569","0.04652"
"138.16800","11.51427","0.04653"
"138.51000","11.54273","0.04642"
"138.85200","11.57113","0.04667"
"139.19400","11.59977","0.04693"
"139.53600","11.62823","0.04676"
"139.87800","11.65675","0.04712"
"140.22000","11.68521","0.04724"
"140.56200","11.71373","0.04723"
"140.90400","11.74225","0.04710"
"141.24600","11.77077","0.04654"
"141.58800","11.79917","0.04728"
"141.93000","11.82775","0.04686"
"142.27200","11.85620","0.04735"
"142.61400","11.88466","0.04720"
"142.95600","11.91324","0.04743"
"143.29800","11.94176","0.04748"
"143.64000","11.97016","0.04763"
"143.98200","11.99874","0.04718"
"144.32400","12.02720","0.04803"
"144.66600","12.05572","0.04751"
"145.00800","12.08424","0.04741"
"145.35000","12.11270","0.04780"
"145.69200","12.14122","0.04793"
"146.03400","12.16974","0.04759"
"146.37600","12.19814","0.04803"
"146.71800","12.22672","0.04793"
"147.06000","12.25524","0.04834"
"147.40200","12.28376","0.04830"
"147.74400","12.31222","0.04892"
"148.08600","12.34074","0.04851"
"148.42800","12.36920","0.04845"
"148.77000","12.39778","0.04850"
"149.11200","12.42618","0.04855"
"149.45400","12.45470","0.04896"
"149.79600","12.48322","0.04902"
"150.13800","12.51168","0.04934"
"150.48000","12.54026","0.04926"
"150.82200","12.56872","0.04914"
"151.16400","12.59718","0.04883"
"151.50600","12.62576","0.04928"
"151.84800","12.65416","0.04888"
"152.19000","12.68268","0.04917"
"152.53200","12.71131","0.04931"
"152.87400","12.73965","0.04952"
"153.21600","12.76824","0.04944"
"153.55800","12.79675","0.04959"
"153.90000","12.82515","0.04950"
"154.24200","12.85373","0.04982"
"154.58400","12.88219","0.04975"
"154.92600","12.91071","0.04981"
"155.26800","12.93923","0.05034"
"155.61000","12.96769","0.04985"
"155.95200","12.99627","0.04999"
"156.29400","13.02473","0.05022"
"156.63600","13.05313","0.05037"
"156.97800","13.08171","0.05003"
"157.32000","13.11023","0.05079"
"157.66200","13.13869","0.05067"
"158.00400","13.16727","0.05070"
"158.34600","13.19573","0.05100"
"158.68800","13.22419","0.05112"
"159.03000","13.25271","0.05071"
"159.37200","13.28117","0.05121"
"159.71400","13.30975","0.05138"
"160.05600","13.33821","0.05159"
"160.39800","13.36667","0.05194"
"160.74000","13.39519","0.05188"
"161.08200","13.42377","0.05203"
"161.42400","13.45223","0.05204"
"161.76600","13.48075","0.05235"
"162.10800","13.50921","0.05177"
"162.45000","13.53767","0.05153"
"162.79200","13.56625","0.05156"
"163.13400","13.59471","0.05193"
"163.47600","13.62322","0.05222"
"163.81800","13.65168","0.05235"
"164.16000","13.68020","0.05265"
"164.50200","13.70878","0.05249"
"164.84400","13.73718","0.05272"
"165.18600","13.76570","0.05310"
"165.52800","13.79422","0.05329"
"165.87000","13.82268","0.05309"
"166.21200","13.85120","0.05324"
"166.55400","13.87972","0.05362"
"166.89600","13.90824","0.05373"
"167.23800","13.93664","0.05402"
"167.58000","13.96528","0.05405"
"167.92200","13.99368","0.05429"
"168.26400","14.02226","0.05481"
"168.60600","14.05078","0.05459"
"168.94800","14.07918","0.05481"
"169.29000","14.10776","0.05503"
"169.63200","14.13622","0.05518"
"169.97400","14.16474","0.05526"
"170.31600","14.19320","0.05496"
"170.65800","14.22166","0.05546"
"171.00000","14.25018","0.05553"
"171.34200","14.27870","0.05503"
"171.68400","14.30716","0.05514"
"172.02600","14.33580","0.05436"
"172.36800","14.36426","0.05447"
"172.71000","14.39266","0.05473"
"173.05200","14.42130","0.05517"
"173.39400","14.44970","0.05517"
"173.73600","14.47822","0.05530"
"174.07800","14.50673","0.05536"
"174.42000","14.53519","0.05583"
"174.76200","14.56378","0.05569"
"175.10400","14.59223","0.05589"
"175.44600","14.62069","0.05616"
"175.78800","14.64921","0.05661"
"176.13000","14.67773","0.05715"
"176.47200","14.70619","0.05723"
"176.81400","14.73471","0.05756"
"177.15600","14.76323","0.05770"
"177.49800","14.79169","0.05835"
"177.84000","14.82027","0.05788"
"178.18200","14.84867","0.05837"
"178.52400","14.87725","0.05874"
"178.86600","14.90577","0.05893"
"179.20800","14.93417","0.05899"
"179.55000","14.96275","0.05951"
"179.89200","14.99121","0.06014"
"180.23400","15.01967","0.05989"
"180.57600","15.04819","0.06013"
"180.91800","15.07671","0.06047"
"181.26000","15.10517","0.06028"
"181.60200","15.13375","0.06094"
"181.94400","15.16215","0.06070"
"182.28600","15.19073","0.06080"
"182.62800","15.21925","0.06162"
"182.97000","15.24771","0.06130"
"183.31200","15.27623","0.05740"
"183.65400","15.30474","0.05767"
"183.99600","15.33321","0.05753"
"184.33800","15.36166","0.05748"
"184.68000","15.39025","0.05805"
"185.02200","15.41864","0.05823"
"185.36400","15.44722","0.05875"
"185.70600","15.47569","0.05863"
"186.04800","15.50420","0.05909"
"186.39000","15.53278","0.05947"
"186.73200","15.56118","0.05990"
"187.07400","15.58976","0.05959"
"187.41600","15.61822","0.05967"
"187.75800","15.64668","0.05997"
"188.10000","15.67526","0.05986"
"188.44200","15.70366","0.06082"
"188.78400","15.73218","0.06051"
"189.12600","15.76076","0.06109"
"189.46800","15.78916","0.06143"
"189.81000","15.81774","0.06176"
"190.15200","15.84626","0.06099"
"190.49400","15.87472","0.06136"
"190.83600","15.90324","0.06167"
"191.17800","15.93170","0.06179"
"191.52000","15.96022","0.06222"
"191.86200","15.98874","0.06237"
"192.20400","16.01720","0.06329"
"192.54600","16.04578","0.06301"
"192.88800","16.07424","0.06343"
"193.23000","16.10270","0.06386"
"193.57200","16.13121","0.06395"
"193.91400","16.15973","0.06422"
"194.25600","16.18819","0.06392"
"194.59800","16.21671","0.06454"
"194.94000","16.24524","0.06538"
"195.28200","16.27369","0.06503"
"195.62400","16.30221","0.06540"
"195.96600","16.33068","0.06567"
"196.30800","16.35925","0.06624"
"196.65000","16.38771","0.06722"
"196.99200","16.41617","0.06677"
"197.33400","16.44469","0.06709"
"197.67600","16.47321","0.06744"
"198.01800","16.50167","0.06799"
"198.36000","16.53025","0.06794"
"198.70200","16.55871","0.06876"
"199.04400","16.58717","0.06867"
"199.38600","16.61563","0.06925"
"199.72800","16.64421","0.06889"
"200.07000","16.67273","0.06969"
"200.41200","16.70125","0.07004"
"200.75400","16.72971","0.07056"
"201.09600","16.75823","0.07082"
"201.43800","16.78675","0.07128"
"201.78000","16.81521","0.07105"
"202.12200","16.84373","0.07152"
"202.46400","16.87219","0.07210"
"202.80600","16.90065","0.07235"
"203.14800","16.92923","0.07284"
"203.49000","16.95769","0.07297"
"203.83200","16.98615","0.07336"
"204.17400","17.01478","0.07360"
"204.51600","17.04313","0.07390"
"204.85800","17.07170","0.07427"
"205.20000","17.10022","0.07467"
"205.54200","17.12868","0.07476"
"205.88400","17.15726","0.07533"
"206.22600","17.18572","0.07564"
"206.56800","17.21418","0.07571"
"206.91000","17.24276","0.07610"
"207.25200","17.27116","0.07702"
"207.59400","17.29974","0.07713"
"207.93600","17.32820","0.07747"
"208.27800","17.35666","0.07772"
"208.62000","17.38524","0.07843"
"208.96200","17.41364","0.07836"
"209.30400","17.44216","0.07922"
"209.64600","17.47074","0.07952"
"209.98800","17.49920","0.08026"
"210.33000","17.52772","0.08051"
"210.67200","17.55624","0.08013"
"211.01400","17.58464","0.08066"
"211.35600","17.61328","0.08169"
"211.69800","17.64174","0.08164"
"212.04000","17.67014","0.08215"
"212.38200","17.69872","0.08251"
"212.72400","17.72724","0.08260"
"213.06600","17.75570","0.08312"
"213.40800","17.78428","0.08327"
"213.75000","17.81268","0.08379"
"214.09200","17.84120","0.08427"
"214.43400","17.86972","0.08487"
"214.77600","17.89818","0.08501"
"215.11800","17.92676","0.08531"
"215.46000","17.95522","0.08578"
"215.80200","17.98373","0.08610"
"216.14400","18.01225","0.08619"
"216.48600","18.04071","0.08673"
"216.82800","18.06917","0.08717"
"217.17000","18.09769","0.08772"
"217.51200","18.12621","0.08798"
"217.85400","18.15473","0.08829"
"218.19600","18.18325","0.08849"
"218.53800","18.21171","0.08924"
"218.88000","18.24017","0.08880"
"219.22200","18.26875","0.08967"
"219.56400","18.29721","0.09029"
"219.90600","18.32567","0.09041"
"220.24800","18.35425","0.09085"
"220.59000","18.38271","0.09103"
"220.93200","18.41123","0.09096"
"221.27400","18.43975","0.09160"
"221.61600","18.46821","0.09216"
"221.95800","18.49673","0.09235"
"222.30000","18.52513","0.09262"
"222.64200","18.55371","0.09297"
"222.98400","18.58223","0.09344"
"223.32600","18.61069","0.09382"
"223.66800","18.63927","0.09348"
"224.01000","18.66773","0.09376"
"224.35200","18.69619","0.09437"
"224.69400","18.72477","0.09415"
"225.03600","18.75317","0.09467"
"225.37800","18.78169","0.09440"
"225.72000","18.81026","0.09523"
"226.06200","18.83867","0.09543"
"226.40400","18.86724","0.09576"
"226.74600","18.89570","0.09592"
"227.08800","18.92422","0.09635"
"227.43000","18.95274","0.09637"
"227.77200","18.98126","0.09654"
"228.11400","19.00972","0.09705"
"228.45600","19.03824","0.09738"
"228.79800","19.06670","0.09699"
"229.14000","19.09522","0.09758"
"229.48200","19.12374","0.09765"
"229.82400","19.15208","0.09802"
"230.16600","19.18078","0.09814"
"230.50800","19.20930","0.09851"
"230.85000","19.23764","0.09854"
"231.19200","19.26622","0.09879"
"231.53400","19.29468","0.09895"
"231.87600","19.32320","0.09935"
"232.21800","19.35172","0.09947"
"232.56000","19.38018","0.10025"
"232.90200","19.40876","0.10015"
"233.24400","19.43722","0.10042"
"233.58600","19.46568","0.10017"
"233.92800","19.49426","0.10117"
"234.27000","19.52272","0.10120"
"234.61200","19.55118","0.10143"
"234.95400","19.57976","0.10207"
"235.29600","19.60822","0.10197"
"235.63800","19.63674","0.10274"
"235.98000","19.66526","0.10320"
"236.32200","19.69371","0.10290"
"236.66400","19.72217","0.10343"
"237.00600","19.75070","0.10469"
"237.34800","19.77921","0.10487"
"237.69000","19.80767","0.10440"
"238.03200","19.83625","0.02173"
"238.37400","19.86471","0.02483"
"238.71600","19.89323","0.03166"
"239.05800","19.92175","0.02923"
"239.40000","19.95021","0.02801"
"239.74200","19.97873","0.03056"
"240.08400","20.00719","0.02974"
"240.42600","20.03571","0.02768"
"240.76800","20.06423","0.02920"
"241.11000","20.09263","0.03045"
"241.45200","20.12121","0.02939"
"241.79400","20.14973","0.02891"
"242.13600","20.17825","0.02949"
"242.47800","20.20671","0.02928"
"242.82000","20.23523","0.02975"
"243.16200","20.26369","0.02920"
"243.50400","20.29227","0.02960"
"243.84600","20.32067","0.02906"
"244.18800","20.34925","0.02878"
"244.53000","20.37783","0.02873"
"244.87200","20.40617","0.02918"
"245.21400","20.43475","0.02888"
"245.55600","20.46321","0.02928"
"245.89800","20.49167","0.02951"
"246.24000","20.52024","0.02963"
"246.58200","20.54877","0.02985"
"246.92400","20.57716","0.03000"
"247.26600","20.60575","0.02952"
"247.60800","20.63414","0.03012"
"247.95000","20.66273","0.02959"
"248.29200","20.69124","0.03057"
"248.63400","20.71970","0.02995"
"248.97600","20.74822","0.02991"
"249.31800","20.77668","0.03022"
"249.66000","20.80520","0.03014"
"250.00200","20.83372","0.03019"
"250.34400","20.86218","0.03082"
"250.68600","20.89070","0.03070"
"251.02800","20.91916","0.03007"
"251.37000","20.94768","0.03020"
"251.71200","20.97620","0.03066"
"252.05400","21.00472","0.03040"
"252.39600","21.03324","0.03027"
"252.73800","21.06170","0.03009"
"253.08000","21.09022","0.02967"
"253.42200","21.11868","0.03033"
"253.76400","21.14726","0.03049"
"254.10600","21.17572","0.02980"
"254.44800","21.20418","0.03010"
"254.79000","21.23270","0.03017"
"255.13200","21.26116","0.03071"
"255.47400","21.28974","0.03062"
"255.81600","21.31825","0.03074"
"256.15800","21.34672","0.03007"
"256.50000","21.37523","0.03123"
"256.84200","21.40376","0.03150"
"257.18400","21.43216","0.03110"
"257.52600","21.46074","0.03105"
"257.86800","21.48919","0.03136"
"258.21000","21.51771","0.03184"
"258.55200","21.54630","0.03138"
"258.89400","21.57470","0.03173"
"259.23600","21.60328","0.03163"
"259.57800","21.63173","0.03124"
"259.92000","21.66013","0.03098"
"260.26200","21.68871","0.03085"
"260.60400","21.71723","0.03086"
"260.94600","21.74569","0.03070"
"261.28800","21.77427","0.03049"
"261.63000","21.80267","0.03120"
"261.97200","21.83113","0.03098"
"262.31400","21.85977","0.03078"
"262.65600","21.88817","0.03122"
"262.99800","21.91675","0.03146"
"263.34000","21.94527","0.03106"
"263.68200","21.97367","0.03080"
"264.02400","22.00225","0.03086"
"264.36600","22.03071","0.03170"
"264.70800","22.05917","0.03182"
"265.05000","22.08775","0.03146"
"265.39200","22.11621","0.03165"
"265.73400","22.14479","0.03131"
"266.07600","22.17325","0.03059"
"266.41800","22.20165","0.03069"
"266.76000","22.23029","0.03057"
"267.10200","22.25875","0.03031"
"267.44400","22.28720","0.02932"
"267.78600","22.31578","0.02919"
"268.12800","22.34419","0.02934"
"268.47000","22.37271","0.02949"
"268.81200","22.40122","0.02939"
"269.15400","22.42969","0.02974"
"269.49600","22.45820","0.03011"
"269.83800","22.48672","0.03008"
"270.18000","22.51525","0.03063"
"270.52200","22.54370","0.02961"
"270.86400","22.57222","0.03027"
"271.20600","22.60068","0.02681"
"271.54800","22.62920","0.02770"
"271.89000","22.65772","0.02682"
"272.23200","22.68618","0.02701"
"272.57400","22.71470","0.02690"
"272.91600","22.74322","0.02742"
"273.25800","22.77174","0.02758"
"273.60000","22.80026","0.02667"
"273.94200","22.82866","0.02764"
"274.28400","22.85724","0.02743"
"274.62600","22.88570","0.02756"
"274.96800","22.91422","0.02692"
"275.31000","22.94274","0.02790"
"275.65200","22.97126","0.02722"
"275.99400","22.99972","0.02787"
"276.33600","23.02824","0.02833"
"276.67800","23.05670","0.02807"
"277.02000","23.08522","0.02778"
"277.36200","23.11380","0.02768"
"277.70400","23.14214","0.02823"
"278.04600","23.17078","0.02741"
"278.38800","23.19924","0.02843"
"278.73000","23.22775","0.02772"
"279.07200","23.25622","0.02755"
"279.41400","23.28468","0.02850"
"279.75600","23.31319","0.02864"
"280.09800","23.34171","0.02810"
"280.44000","23.37023","0.02759"
"280.78200","23.39869","0.02731"
"281.12400","23.42727","0.02765"
"281.46600","23.45561","0.02830"
"281.80800","23.48431","0.02808"
"282.15000","23.51277","0.02823"
"282.49200","23.54123","0.02731"
"282.83400","23.56975","0.02750"
"283.17600","23.59815","0.02791"
"283.51800","23.62667","0.02815"
"283.86000","23.65519","0.02834"
"284.20200","23.68365","0.02832"
"284.54400","23.71229","0.02772"
"284.88600","23.74075","0.02863"
"285.22800","23.76915","0.02790"
"285.57000","23.79779","0.02823"
"285.91200","23.82625","0.02804"
"286.25400","23.85471","0.02827"
"286.59600","23.88323","0.02876"
"286.93800","23.91169","0.02871"
"287.28000","23.94020","0.02871"
"287.62200","23.96873","0.02916"
"287.96400","23.99719","0.02832"
"288.30600","24.02571","0.02806"
"288.64800","24.05423","0.02852"
"288.99000","24.08269","0.02849"
"289.33200","24.11126","0.02901"
"289.67400","24.13972","0.02888"
"290.01600","24.16818","0.02934"
"290.35800","24.19676","0.02955"
"290.70000","24.22523","0.02939"
"291.04200","24.25368","0.02934"
"291.38400","24.28220","0.02922"
"291.72600","24.31066","0.02945"
"292.06800","24.33924","0.02974"
"292.41000","24.36776","0.02908"
"292.75200","24.39616","0.02898"
"293.09400","24.42474","0.02869"
"293.43600","24.45326","0.02818"
"293.77800","24.48172","0.02702"
"294.12000","24.51024","0.02820"
"294.46200","24.53876","0.02810"
"294.80400","24.56722","0.02819"
"295.14600","24.59574","0.02755"
"295.48800","24.62420","0.02702"
"295.83000","24.65272","0.02750"
"296.17200","24.68130","0.02796"
"296.51400","24.70964","0.02790"
"296.85600","24.73822","0.02789"
"297.19800","24.76674","0.02705"
"297.54000","24.79520","0.02816"
"297.88200","24.82378","0.02783"
"298.22400","24.85218","0.02734"
"298.56600","24.88070","0.02767"
"298.90800","24.90922","0.02731"
"299.25000","24.93767","0.02761"
"299.59200","24.96626","0.02746"
"299.93400","24.99478","0.02775"
"300.27600","25.02318","0.02744"
"300.61800","25.05176","0.02748"
"300.96000","25.08022","0.02782"
"301.30200","25.10867","0.02715"
"301.64400","25.13725","0.02754"
"301.98600","25.16571","0.02806"
"302.32800","25.19423","0.02824"
"302.67000","25.22269","0.02781"
"303.01200","25.25115","0.02847"
"303.35400","25.27967","0.02855"
"303.69600","25.30825","0.02803"
"304.03800","25.33671","0.02907"
"304.38000","25.36523","0.02822"
"304.72200","25.39369","0.02807"
"305.06400","25.42221","0.02905"
"305.40600","25.45073","0.02879"
"305.74800","25.47919","0.02864"
"306.09000","25.50771","0.02857"
"306.43200","25.53623","0.02849"
"306.77400","25.56469","0.02843"
"307.11600","25.59321","0.02860"
"307.45800","25.62173","0.02896"
"307.80000","25.65019","0.02918"
"308.14200","25.67877","0.02913"
"308.48400","25.70723","0.02868"
"308.82600","25.73575","0.02943"
"309.16800","25.76421","0.02994"
"309.51000","25.79273","0.02940"
"309.85200","25.82119","0.02964"
"310.19400","25.84977","0.02958"
"310.53600","25.87817","0.02968"
"310.87800","25.90675","0.02929"
"311.22000","25.93527","0.02998"
"311.56200","25.96367","0.02959"
"311.90400","25.99224","0.03052"
"312.24600","26.02071","0.03019"
"312.58800","26.04922","0.02938"
"312.93000","26.07774","0.03036"
"313.27200","26.10620","0.03028"
"313.61400","26.13466","0.03002"
"313.95600","26.16324","0.03071"
"314.29800","26.19170","0.03002"
"314.64000","26.22022","0.03050"
"314.98200","26.24874","0.03086"
"315.32400","26.27720","0.03096"
"315.66600","26.30572","0.03087"
"316.00800","26.33424","0.03037"
"316.35000","26.36270","0.03097"
"316.69200","26.39128","0.03129"
"317.03400","26.41962","0.03127"
"317.37600","26.44826","0.03166"
"317.71800","26.47678","0.03101"
"318.06000","26.50512","0.03144"
"318.40200","26.53376","0.03136"
"318.74400","26.56222","0.03140"
"319.08600","26.59068","0.03148"
"319.42800","26.61926","0.03137"
"319.77000","26.64772","0.03239"
"320.11200","26.67618","0.03213"
"320.45400","26.70470","0.03241"
"320.79600","26.73316","0.03214"
"321.13800","26.76174","0.03211"
"321.48000","26.79026","0.03217"
"321.82200","26.81871","0.03196"
"322.16400","26.84724","0.03155"
"322.50600","26.87575","0.03197"
"322.84800","26.90421","0.03214"
"323.19000","26.93273","0.03104"
"323.53200","26.96125","0.03138"
"323.87400","26.98971","0.03035"
"324.21600","27.01823","0.03095"
"324.55800","27.04669","0.03090"
"324.90000","27.07521","0.03079"
"325.24200","27.10373","0.03100"
"325.58400","27.13219","0.03159"
"325.92600","27.16071","0.03145"
"326.26800","27.18917","0.03239"
"326.61000","27.21769","0.03192"
"326.95200","27.24621","0.03176"
"327.29400","27.27473","0.03200"
"327.63600","27.30325","0.03141"
"327.97800","27.33171","0.03152"
"328.32000","27.36023","0.03163"
"328.66200","27.38869","0.03185"
"329.00400","27.41727","0.03211"
"329.34600","27.44567","0.03253"
"329.68800","27.47419","0.03204"
"330.03000","27.50271","0.03208"
"330.37200","27.53123","0.03299"
"330.71400","27.55975","0.03271"
"331.05600","27.58821","0.03258"
"331.39800","27.61667","0.03284"
"331.74000","27.64519","0.03309"
"332.08200","27.67371","0.03276"
"332.42400","27.70222","0.03280"
"332.76600","27.73080","0.03263"
"333.10800","27.75915","0.03272"
"333.45000","27.78778","0.03267"
"333.79200","27.81624","0.03321"
"334.13400","27.84470","0.03362"
"334.47600","27.87328","0.03308"
"334.81800","27.90168","0.03314"
"335.16000","27.93020","0.03298"
"335.50200","27.95872","0.03324"
"335.84400","27.98718","0.03373"
"336.18600","28.01576","0.03366"
"336.52800","28.04422","0.03372"
"336.87000","28.07268","0.03420"
"337.21200","28.10126","0.03441"
"337.55400","28.12972","0.03441"
"337.89600","28.15818","0.03440"
"338.23800","28.18676","0.03428"
"338.58000","28.21516","0.03467"
"338.92200","28.24374","0.03471"
"339.26400","28.27226","0.03519"
"339.60600","28.30066","0.03244"
"339.94800","28.32924","0.03307"
"340.29000","28.35776","0.03261"
"340.63200","28.38616","0.03325"
"340.97400","28.41474","0.03345"
"341.31600","28.44320","0.03325"
"341.65800","28.47172","0.03346"
"342.00000","28.50024","0.03395"
"342.34200","28.52869","0.03300"
"342.68400","28.55722","0.03422"
"343.02600","28.58579","0.03413"
"343.36800","28.61413","0.03354"
"343.71000","28.64277","0.03389"
"344.05200","28.67118","0.03440"
"344.39400","28.69963","0.03444"
"344.73600","28.72828","0.03465"
"345.07800","28.75673","0.03463"
"345.42000","28.78519","0.03431"
"345.76200","28.81371","0.03468"
"346.10400","28.84223","0.03436"
"346.44600","28.87069","0.03465"
"346.78800","28.89921","0.03537"
"347.13000","28.92767","0.03527"
"347.47200","28.95625","0.03500"
"347.81400","28.98477","0.03466"
"348.15600","29.01317","0.03471"
"348.49800","29.04169","0.03561"
"348.84000","29.07021","0.03550"
"349.18200","29.09867","0.03564"
"349.52400","29.12725","0.03546"
"349.86600","29.15571","0.03555"
"350.20800","29.18417","0.03578"
"350.55000","29.21275","0.03551"
"350.89200","29.24121","0.03619"
"351.23400","29.26973","0.03574"
"351.57600","29.29825","0.03582"
"351.91800","29.32671","0.03591"
"352.26000","29.35523","0.03648"
"352.60200","29.38369","0.03624"
"352.94400","29.41221","0.03682"
"353.28600","29.44078","0.03631"
"353.62800","29.46919","0.03619"
"353.97000","29.49771","0.03670"
"354.31200","29.52622","0.03639"
"354.65400","29.55463","0.03601"
"354.99600","29.58326","0.03552"
"355.33800","29.61172","0.03557"
"355.68000","29.64018","0.03596"
"356.02200","29.66876","0.03605"
"356.36400","29.69722","0.03406"
"356.70600","29.72568","0.03501"
"357.04800","29.75420","0.03453"
"357.39000","29.78266","0.03481"
"357.73200","29.81124","0.03466"
"358.07400","29.83976","0.03533"
"358.41600","29.86816","0.03500"
"358.75800","29.89674","0.03554"
"359.10000","29.92520","0.03481"
"359.44200","29.95372","0.03513"
"359.78400","29.98224","0.03547"
"360.12600","30.01070","0.03536"
"360.46800","30.03922","0.03564"
"360.81000","30.06774","0.03568"
"361.15200","30.09620","0.03502"
"361.49400","30.12472","0.03467"
"361.83600","30.15324","0.03461"
"362.17800","30.18170","0.03441"
"362.52000","30.21022","0.03465"
"362.86200","30.23874","0.03494"
"363.20400","30.26720","0.03506"
"363.54600","30.29577","0.03466"
"363.88800","30.32418","0.03520"
"364.23000","30.35270","0.03490"
"364.57200","30.38127","0.03540"
"364.91400","30.40973","0.03576"
"365.25600","30.43819","0.03543"
"365.59800","30.46677","0.03557"
"365.94000","30.49517","0.03645"
"366.28200","30.52375","0.03589"
"366.62400","30.55227","0.03581"
"366.96600","30.58067","0.03547"
"367.30800","30.60919","0.03569"
"367.65000","30.63771","0.03562"
"367.99200","30.66623","0.03597"
"368.33400","30.69475","0.03590"
"368.67600","30.72315","0.03617"
"369.01800","30.75173","0.03578"
"369.36000","30.78025","0.03556"
"369.70200","30.80865","0.03591"
"370.04400","30.83723","0.03611"
"370.38600","30.86575","0.03683"
"370.72800","30.89421","0.03629"
"371.07000","30.92273","0.03639"
"371.41200","30.95119","0.03669"
"371.75400","30.97971","0.03613"
"372.09600","31.00823","0.03634"
"372.43800","31.03669","0.03660"
"372.78000","31.06527","0.03650"
"373.12200","31.09379","0.03693"
"373.46400","31.12218","0.03568"
"373.80600","31.15077","0.03608"
"374.14800","31.17923","0.03613"
"374.49000","31.20769","0.03675"
"374.83200","31.23627","0.03660"
"375.17400","31.26472","0.03657"
"375.51600","31.29318","0.03662"
"375.85800","31.32170","0.03643"
"376.20000","31.35016","0.03680"
"376.54200","31.37874","0.03688"
"376.88400","31.40726","0.03703"
"377.22600","31.43566","0.03735"
"377.56800","31.46424","0.03716"
"377.91000","31.49264","0.03747"
"378.25200","31.52116","0.03776"
"378.59400","31.54974","0.03689"
"378.93600","31.57820","0.03678"
"379.27800","31.60672","0.03705"
"379.62000","31.63524","0.03773"
"379.96200","31.66370","0.03724"
"380.30400","31.69222","0.03781"
"380.64600","31.72074","0.03621"
"380.98800","31.74920","0.03697"
"381.33000","31.77772","0.03650"
"381.67200","31.80624","0.03753"
"382.01400","31.83470","0.03699"
"382.35600","31.86316","0.03673"
"382.69800","31.89174","0.03679"
"383.04000","31.92014","0.03656"
"383.38200","31.94872","0.03693"
"383.72400","31.97718","0.03701"
"384.06600","32.00570","0.03683"
"384.40800","32.03428","0.03571"
"384.75000","32.06268","0.03543"
"385.09200","32.09125","0.03592"
"385.43400","32.11971","0.03558"
"385.77600","32.14817","0.03523"
"386.11800","32.17675","0.03545"
"386.46000","32.20521","0.03542"
"386.80200","32.23367","0.03505"
"387.14400","32.26225","0.03596"
"387.48600","32.29059","0.03566"
"387.82800","32.31923","0.03550"
"388.17000","32.34769","0.03585"
"388.51200","32.37621","0.03622"
"388.85400","32.40473","0.03581"
"389.19600","32.43325","0.03663"
"389.53800","32.46171","0.03590"
"389.88000","32.49023","0.03657"
"390.22200","32.51869","0.03617"
"390.56400","32.54721","0.03616"
"390.90600","32.57573","0.03684"
"391.24800","32.60413","0.03657"
"391.59000","32.63277","0.03660"
"391.93200","32.66123","0.03694"
"392.27400","32.68969","0.03695"
"392.61600","32.71821","0.03695"
"392.95800","32.74667","0.03689"
"393.30000","32.77518","0.03715"
"393.64200","32.80371","0.03671"
"393.98400","32.83216","0.03726"
"394.32600","32.86074","0.03759"
"394.66800","32.88927","0.03746"
"395.01000","32.91766","0.03787"
"395.35200","32.94624","0.03754"
"395.69400","32.97470","0.03717"
"396.03600","33.00322","0.03806"
"396.37800","33.03174","0.03830"
"396.72000","33.06020","0.03831"
"397.06200","33.08872","0.03843"
"397.40400","33.11718","0.03834"
"397.74600","33.14570","0.03868"
"398.08800","33.17422","0.03892"
"398.43000","33.20274","0.03933"
"398.77200","33.23120","0.03940"
"399.11400","33.25972","0.03980"
"399.45600","33.28824","0.04034"
"399.79800","33.31670","0.04043"
"400.14000","33.34522","0.04064"
"400.48200","33.37374","0.04049"
"400.82400","33.40220","0.03774"
"401.16600","33.43072","0.03801"
"401.50800","33.45918","0.03708"
"401.85000","33.48770","0.03654"
"402.19200","33.51628","0.03610"
"402.53400","33.54468","0.03661"
"402.87600","33.57320","0.03686"
"403.21800","33.60178","0.03668"
"403.56000","33.63024","0.03724"
"403.90200","33.65876","0.03764"
"404.24400","33.68721","0.03755"
"404.58600","33.71568","0.03750"
"404.92800","33.74426","0.03788"
"405.27000","33.77271","0.03810"
"405.61200","33.80117","0.03805"
"405.95400","33.82976","0.03824"
"406.29600","33.85815","0.03883"
"406.63800","33.88673","0.03856"
"406.98000","33.91526","0.03824"
"407.32200","33.94371","0.03918"
"407.66400","33.97223","0.03930"
"408.00600","34.00069","0.03948"
"408.34800","34.02915","0.03951"
"408.69000","34.05773","0.03956"
"409.03200","34.08619","0.03993"
"409.37400","34.11477","0.03954"
"409.71600","34.14323","0.03951"
"410.05800","34.17163","0.03985"
"410.40000","34.20021","0.04039"
"410.74200","34.22873","0.03996"
"411.08400","34.25719","0.04067"
"411.42600","34.28571","0.04030"
"411.76800","34.31417","0.04028"
"412.11000","34.34275","0.04071"
"412.45200","34.37121","0.04138"
"412.79400","34.39967","0.04158"
"413.13600","34.42825","0.04163"
"413.47800","34.45677","0.04195"
"413.82000","34.48523","0.04215"
"414.16200","34.51374","0.04223"
"414.50400","34.54221","0.04232"
"414.84600","34.57073","0.04182"
"415.18800","34.59924","0.04276"
"415.53000","34.62770","0.04309"
"415.87200","34.65623","0.04308"
"416.21400","34.68468","0.04347"
"416.55600","34.71320","0.04343"
"416.89800","34.74173","0.04419"
"417.24000","34.77024","0.04397"
"417.58200","34.79870","0.04417"
"417.92400","34.82722","0.04436"
"418.26600","34.85574","0.04500"
"418.60800","34.88420","0.04494"
"418.95000","34.91272","0.04499"
"419.29200","34.94118","0.04543"
"419.63400","34.96970","0.04535"
"419.97600","34.99828","0.04580"
"420.31800","35.02668","0.04513"
"420.66000","35.05526","0.04565"
"421.00200","35.08372","0.04586"
"421.34400","35.11218","0.04612"
"421.68600","35.14076","0.04594"
"422.02800","35.16922","0.04624"
"422.37000","35.19768","0.04630"
"422.71200","35.22626","0.04650"
"423.05400","35.25471","0.04630"
"423.39600","35.28324","0.04689"
"423.73800","35.31182","0.04649"
"424.08000","35.34016","0.04673"
"424.42200","35.36868","0.04705"
"424.76400","35.39720","0.04714"
"425.10600","35.42572","0.04736"
"425.44800","35.45424","0.04762"
"425.79000","35.48270","0.04768"
"426.13200","35.51115","0.04787"
"426.47400","35.53973","0.04851"
"426.81600","35.56820","0.04849"
"427.15800","35.59677","0.04887"
"427.50000","35.62523","0.04920"
"427.84200","35.65364","0.04878"
"428.18400","35.68221","0.04964"
"428.52600","35.71073","0.04990"
"428.86800","35.73919","0.05023"
"429.21000","35.76771","0.05070"
"429.55200","35.79617","0.05125"
"429.89400","35.82475","0.05147"
"430.23600","35.85321","0.05182"
"430.57800","35.88167","0.05246"
"430.92000","35.91025","0.05337"
"431.26200","35.93871","0.05372"
"431.60400","35.96717","0.05406"
"431.94600","35.99575","0.05504"
"432.28800","36.02421","0.05566"
"432.63000","36.05267","0.05633"
"432.97200","36.08119","0.05608"
"433.31400","36.10971","0.05683"
"433.65600","36.13823","0.05207"
"433.99800","36.16669","0.03847"
"434.34000","36.19521","0.03818"
"434.68200","36.22373","0.04003"
"435.02400","36.25225","0.04046"
"435.36600","36.28065","0.04007"
"435.70800","36.30923","0.04040"
"436.05000","36.33775","0.03999"
"436.39200","36.36615","0.03961"
"436.73400","36.39473","0.04198"
"437.07600","36.42324","0.04199"
"437.41800","36.45171","0.04216"
"437.76000","36.48022","0.04338"
"438.10200","36.50874","0.04136"
"438.44400","36.53720","0.04354"
"438.78600","36.56578","0.04307"
"439.12800","36.59418","0.04290"
"439.47000","36.62270","0.04426"
"439.81200","36.65122","0.04218"
"440.15400","36.67968","0.04380"
"440.49600","36.70820","0.04337"
"440.83800","36.73672","0.04364"
"441.18000","36.76524","0.04409"
"441.52200","36.79370","0.04237"
"441.86400","36.82216","0.04422"
"442.20600","36.85068","0.04322"
"442.54800","36.87926","0.04486"
"442.89000","36.90766","0.04428"
"443.23200","36.93624","0.04483"
"443.57400","36.96470","0.04487"
"443.91600","36.99316","0.04489"
"444.25800","37.02174","0.04538"
"444.60000","37.05026","0.04478"
"444.94200","37.07872","0.04551"
"445.28400","37.10723","0.04490"
"445.62600","37.13570","0.04610"
"445.96800","37.16428","0.04531"
"446.31000","37.19279","0.04620"
"446.65200","37.22120","0.04592"
"446.99400","37.24972","0.04668"
"447.33600","37.27818","0.04705"
"447.67800","37.30670","0.04695"
"448.02000","37.33522","0.04758"
"448.36200","37.36367","0.04760"
"448.70400","37.39225","0.04759"
"449.04600","37.42072","0.04736"
"449.38800","37.44917","0.04797"
"449.73000","37.47775","0.04788"
"450.07200","37.50621","0.04800"
"450.41400","37.53473","0.04819"
"450.75600","37.56325","0.04762"
"451.09800","37.59171","0.04795"
"451.44000","37.62017","0.04791"
"451.78200","37.64875","0.04830"
"452.12400","37.67721","0.04828"
"452.46600","37.70567","0.04881"
"452.80800","37.73425","0.04884"
"453.15000","37.76265","0.04914"
"453.49200","37.79123","0.04934"
"453.83400","37.81975","0.04945"
"454.17600","37.84821","0.04955"
"454.51800","37.87667","0.04994"
"454.86000","37.90525","0.05014"
"455.20200","37.93371","0.05052"
"455.54400","37.96223","0.05133"
"455.88600","37.99075","0.05146"
"456.22800","38.01915","0.05163"
"456.57000","38.04773","0.05240"
"456.91200","38.07619","0.05243"
"457.25400","38.10477","0.05296"
"457.59600","38.13329","0.05357"
"457.93800","38.16169","0.05422"
"458.28000","38.19020","0.05451"
"458.62200","38.21873","0.05526"
"458.96400","38.24719","0.05614"
"459.30600","38.27576","0.05659"
"459.64800","38.30416","0.05636"
"459.99000","38.33263","0.05704"
"460.33200","38.36126","0.05757"
"460.67400","38.38966","0.05908"
"461.01600","38.41824","0.05934"
"461.35800","38.44670","0.06050"
"461.70000","38.47516","0.06061"
"462.04200","38.50374","0.06026"
"462.38400","38.53226","0.05922"
"462.72600","38.56066","0.06079"
"463.06800","38.58930","0.06059"
"463.41000","38.61770","0.06304"
"463.75200","38.64622","0.06358"
"464.09400","38.67474","0.06470"
"464.43600","38.70314","0.06529"
"464.77800","38.73172","0.06600"
"465.12000","38.76018","0.06783"
"465.46200","38.78870","0.06834"
"465.80400","38.81728","0.07023"
"466.14600","38.84574","0.05263"
"466.48800","38.87426","0.05282"
"466.83000","38.90272","0.05160"
"467.17200","38.93118","0.05295"
"467.51400","38.95975","0.05239"
"467.85600","38.98822","0.05447"
"468.19800","39.01667","0.05343"
"468.54000","39.04520","0.05464"
"468.88200","39.07372","0.05437"
"469.22400","39.10217","0.05528"
"469.56600","39.13075","0.05573"
"469.90800","39.15921","0.05540"
"470.25000","39.18773","0.05583"
"470.59200","39.21619","0.05572"
"470.93400","39.24471","0.05664"
"471.27600","39.27317","0.05677"
"471.61800","39.30175","0.05659"
"471.96000","39.33015","0.05638"
"472.30200","39.35873","0.05819"
"472.64400","39.38719","0.05810"
"472.98600","39.41565","0.05921"
"473.32800","39.44423","0.05991"
"473.67000","39.47269","0.06089"
"474.01200","39.50121","0.06145"
"474.35400","39.52973","0.06305"
"474.69600","39.55819","0.06358"
"475.03800","39.58671","0.06435"
"475.38000","39.61523","0.06562"
"475.72200","39.64363","0.06633"
"476.06400","39.67221","0.06686"
"476.40600","39.70073","0.05917"
"476.74800","39.72919","0.05819"
"477.09000","39.75771","0.05952"
"477.43200","39.78623","0.06028"
"477.77400","39.81469","0.06140"
"478.11600","39.84321","0.06227"
"478.45800","39.87167","0.06277"
"478.80000","39.90019","0.06428"
"479.14200","39.92876","0.06501"
"479.48400","39.95716","0.06562"
"479.82600","39.98574","0.06606"
"480.16800","40.01427","0.06675"
"480.51000","40.04266","0.06815"
"480.85200","40.07124","0.06864"
"481.19400","40.09970","0.06959"
"481.53600","40.12816","0.07067"
"481.87800","40.15668","0.07128"
"482.22000","40.18514","0.07270"
"482.56200","40.21378","0.07272"
"482.90400","40.24224","0.07416"
"483.24600","40.27064","0.07476"
"483.58800","40.29922","0.07594"
"483.93000","40.32774","0.07667"
"484.27200","40.35626","0.07787"
"484.61400","40.38472","0.07824"
"484.95600","40.41318","0.08021"
"485.29800","40.44170","0.08103"
"485.64000","40.47021","0.08167"
"485.98200","40.49868","0.08283"
"486.32400","40.52719","0.08433"
"486.66600","40.55572","0.08554"
"487.00800","40.58418","0.08631"
"487.35000","40.61276","0.08698"
"487.69200","40.64128","0.08811"
"488.03400","40.66968","0.08928"
"488.37600","40.69820","0.09039"
"488.71800","40.72672","0.09140"
"489.06000","40.75524","0.09223"
"489.40200","40.78376","0.09304"
"489.74400","40.81222","0.09372"
"490.08600","40.84068","0.09452"
"490.42800","40.86925","0.09515"
"490.77000","40.89766","0.09604"
"491.11200","40.92623","0.09711"
"491.45400","40.95475","0.09746"
"491.79600","40.98322","0.09828"
"492.13800","41.01173","0.09869"
"492.48000","41.04025","0.09942"
"492.82200","41.06871","0.09998"
"493.16400","41.09717","0.10106"
"493.50600","41.12569","0.10174"
"493.84800","41.15421","0.10387"
"494.19000","41.18279","0.10466"
"494.53200","41.21119","0.10450"
"494.87400","41.23971","0.10518"
"495.21600","41.26823","0.09857"
"495.55800","41.29669","0.08255"
"495.90000","41.32527","0.05801"
"496.24200","41.35367","0.02182"
"496.58400","41.38219","0.01949"
"496.92600","41.41071","0.02202"
"497.26800","41.43916","0.02123"
"497.61000","41.46775","0.02168"
"497.95200","41.49627","0.01956"
"498.29400","41.52473","0.02136"
"498.63600","41.55325","0.02098"
"498.97800","41.58171","0.02062"
"499.32000","41.61016","0.01979"
"499.66200","41.63875","0.02137"
"500.00400","41.66715","0.02032"
"500.34600","41.69572","0.02067"
"500.68800","41.72424","0.02021"
"501.03000","41.75265","0.02104"
"501.37200","41.78128","0.02099"
"501.71400","41.80975","0.01988"
"502.05600","41.83821","0.02008"
"502.39800","41.86672","0.02072"
"502.74000","41.89518","0.02097"
"503.08200","41.92371","0.02019"
"503.42400","41.95222","0.02092"
"503.76600","41.98068","0.02048"
"504.10800","42.00920","0.02067"
"504.45000","42.03772","0.02054"
"504.64800","42.05423","0.02091"