File: Force_trajectories/170212_3/Specimen_RawData_4.csv
End date,"2/12/2017"
Specimen label,"13BG_3"
Maximum Load,"0.01368",N

Time,Extension,Load
(s),(mm),(N)
"0.00000","0.00000","-0.00001"
"0.26400","0.02099","0.00080"
"0.52800","0.04430","0.00040"
"0.79200","0.06625","0.00061"
"1.05600","0.08825","0.00017"
"1.32000","0.11019","-0.00008"
"1.58400","0.13225","0.00009"
"1.84800","0.15420","0.00049"
"2.11200","0.17626","-0.00005"
"2.37600","0.19820","0.00019"
"2.64000","0.22020","0.00029"
"2.90400","0.24215","0.00018"
"3.16800","0.26421","0.00067"
"3.43200","0.28615","0.00022"
"3.69600","0.30827","0.00060"
"3.96000","0.33022","0.00074"
"4.22400","0.35222","0.00059"
"4.48800","0.37422","0.00012"
"4.75200","0.39623","0.00073"
"5.01600","0.41817","0.00057"
"5.28000","0.44023","0.00077"
"5.54400","0.46223","0.00080"
"5.80800","0.48430","0.00055"
"6.07200","0.50618","0.00033"
"6.33600","0.52818","0.00066"
"6.60000","0.55018","0.00107"
"6.86400","0.57225","0.00090"
"7.12800","0.59419","0.00109"
"7.39200","0.61631","0.00086"
"7.65600","0.63819","0.00051"
"7.92000","0.66026","0.00124"
"8.18400","0.68226","0.00098"
"8.44800","0.70426","0.00065"
"8.71200","0.72620","0.00075"
"8.97600","0.74827","0.00118"
"9.24000","0.77021","0.00093"
"9.50400","0.79221","0.00067"
"9.76800","0.81415","0.00069"
"10.03200","0.83622","0.00112"
"10.29600","0.85828","0.00102"
"10.56000","0.88028","0.00106"
"10.82400","0.90228","0.00100"
"11.08800","0.92423","0.00120"
"11.35200","0.94617","0.00133"
"11.61600","0.96823","0.00125"
"11.88000","0.99023","0.00057"
"12.14400","1.01224","0.00090"
"12.40800","1.03424","0.00143"
"12.67200","1.05624","0.00111"
"12.93600","1.07818","0.00115"
"13.20000","1.10019","0.00162"
"13.46400","1.12225","0.00145"
"13.72800","1.14419","0.00097"
"13.99200","1.16625","0.00066"
"14.25600","1.18820","0.00067"
"14.52000","1.21026","0.00152"
"14.78400","1.23220","0.00092"
"15.04800","1.25426","0.00115"
"15.31200","1.27621","0.00122"
"15.57600","1.29827","0.00120"
"15.84000","1.32015","0.00185"
"16.10400","1.34222","0.00118"
"16.36800","1.36422","0.00149"
"16.63200","1.38628","0.00172"
"16.89600","1.40822","0.00109"
"17.16000","1.43023","0.00077"
"17.42400","1.45217","0.00147"
"17.68800","1.47423","0.00145"
"17.95200","1.49617","0.00152"
"18.21600","1.51824","0.00160"
"18.48000","1.54024","0.00127"
"18.74400","1.56224","0.00105"
"19.00800","1.58418","0.00192"
"19.27200","1.60625","0.00171"
"19.53600","1.62825","0.00176"
"19.80000","1.65025","0.00157"
"20.06400","1.67219","0.00176"
"20.32800","1.69426","0.00129"
"20.59200","1.71620","0.00116"
"20.85600","1.73826","0.00114"
"21.12000","1.76020","0.00128"
"21.38400","1.78227","0.00179"
"21.64800","1.80421","0.00183"
"21.91200","1.82627","0.00156"
"22.17600","1.84821","0.00124"
"22.44000","1.87022","0.00105"
"22.70400","1.89216","0.00181"
"22.96800","1.91422","0.00126"
"23.23200","1.93622","0.00147"
"23.49600","1.95823","0.00141"
"23.76000","1.98023","0.00172"
"24.02400","2.00223","0.00141"
"24.28800","2.02423","0.00201"
"24.55200","2.04624","0.00157"
"24.81600","2.06824","0.00232"
"25.08000","2.09024","0.00145"
"25.34400","2.11224","0.00187"
"25.60800","2.13419","0.00159"
"25.87200","2.15619","0.00184"
"26.13600","2.17819","0.00179"
"26.40000","2.20020","0.00164"
"26.66400","2.22226","0.00154"
"26.92800","2.24426","0.00232"
"27.19200","2.26620","0.00164"
"27.45600","2.28821","0.00166"
"27.72000","2.31021","0.00182"
"27.98400","2.33221","0.00148"
"28.24800","2.35421","0.00218"
"28.51200","2.37622","0.00158"
"28.77600","2.39822","0.00181"
"29.04000","2.42028","0.00150"
"29.30400","2.44216","0.00157"
"29.56800","2.46423","0.00197"
"29.83200","2.48611","0.00171"
"30.09600","2.50823","0.00175"
"30.36000","2.53017","0.00204"
"30.62400","2.55224","0.00168"
"30.88800","2.57412","0.00117"
"31.15200","2.59624","0.00170"
"31.41600","2.61818","0.00153"
"31.68000","2.64025","0.00172"
"31.94400","2.66225","0.00206"
"32.20800","2.68425","0.00194"
"32.47200","2.70619","0.00178"
"32.73600","2.72820","0.00217"
"33.00000","2.75020","0.00228"
"33.26400","2.77220","0.00255"
"33.52800","2.79420","0.00185"
"33.79200","2.81627","0.00193"
"34.05600","2.83821","0.00260"
"34.32000","2.86021","0.00137"
"34.58400","2.88221","0.00208"
"34.84800","2.90428","0.00230"
"35.11200","2.92616","0.00203"
"35.37600","2.94822","0.00247"
"35.64000","2.97022","0.00233"
"35.90400","2.99223","0.00189"
"36.16800","3.01417","0.00228"
"36.43200","3.03629","0.00248"
"36.69600","3.05823","0.00162"
"36.96000","3.08024","0.00210"
"37.22400","3.10218","0.00298"
"37.48800","3.12424","0.00252"
"37.75200","3.14618","0.00225"
"38.01600","3.16825","0.00212"
"38.28000","3.19025","0.00203"
"38.54400","3.21225","0.00238"
"38.80800","3.23419","0.00235"
"39.07200","3.25620","0.00218"
"39.33600","3.27820","0.00226"
"39.60000","3.30020","0.00218"
"39.86400","3.32227","0.00279"
"40.12800","3.34427","0.00198"
"40.39200","3.36621","0.00165"
"40.65600","3.38821","0.00249"
"40.92000","3.41028","0.00234"
"41.18400","3.43222","0.00283"
"41.44800","3.45428","0.00266"
"41.71200","3.47622","0.00245"
"41.97600","3.49829","0.00286"
"42.24000","3.52023","0.00287"
"42.50400","3.54217","0.00220"
"42.76800","3.56417","0.00255"
"43.03200","3.58624","0.00252"
"43.29600","3.60818","0.00256"
"43.56000","3.63024","0.00229"
"43.82400","3.65218","0.00247"
"44.08800","3.67425","0.00294"
"44.35200","3.69619","0.00286"
"44.61600","3.71825","0.00267"
"44.88000","3.74019","0.00303"
"45.14400","3.76226","0.00219"
"45.40800","3.78420","0.00335"
"45.67200","3.80620","0.00319"
"45.93600","3.82814","0.00323"
"46.20000","3.85021","0.00244"
"46.46400","3.87221","0.00284"
"46.72800","3.89427","0.00263"
"46.99200","3.91615","0.00268"
"47.25600","3.93822","0.00248"
"47.52000","3.96022","0.00253"
"47.78400","3.98228","0.00292"
"48.04800","4.00422","0.00271"
"48.31200","4.02623","0.00299"
"48.57600","4.04817","0.00271"
"48.84000","4.07023","0.00269"
"49.10400","4.09218","0.00329"
"49.36800","4.11418","0.00278"
"49.63200","4.13618","0.00307"
"49.89600","4.15824","0.00313"
"50.16000","4.18024","0.00288"
"50.42400","4.20231","0.00252"
"50.68800","4.22419","0.00290"
"50.95200","4.24619","0.00336"
"51.21600","4.26820","0.00240"
"51.48000","4.29026","0.00303"
"51.74400","4.31226","0.00291"
"52.00800","4.33426","0.00311"
"52.27200","4.35621","0.00309"
"52.53600","4.37821","0.00275"
"52.80000","4.40015","0.00355"
"53.06400","4.42221","0.00280"
"53.32800","4.44428","0.00318"
"53.59200","4.46622","0.00281"
"53.85600","4.48822","0.00337"
"54.12000","4.51022","0.00286"
"54.38400","4.53223","0.00325"
"54.64800","4.55423","0.00291"
"54.91200","4.57629","0.00280"
"55.17600","4.59823","0.00319"
"55.44000","4.62024","0.00396"
"55.70400","4.64218","0.00345"
"55.96800","4.66424","0.00295"
"56.23200","4.68618","0.00379"
"56.49600","4.70825","0.00315"
"56.76000","4.73025","0.00314"
"57.02400","4.75225","0.00333"
"57.28800","4.77419","0.00396"
"57.55200","4.79626","0.00340"
"57.81600","4.81820","0.00281"
"58.08000","4.84026","0.00340"
"58.34400","4.86220","0.00364"
"58.60800","4.88427","0.00316"
"58.87200","4.90615","0.00405"
"59.13600","4.92821","0.00340"
"59.40000","4.95015","0.00374"
"59.66400","4.97222","0.00354"
"59.92800","4.99416","0.00305"
"60.19200","5.01622","0.00326"
"60.45600","5.03816","0.00415"
"60.72000","5.06023","0.00351"
"60.98400","5.08217","0.00366"
"61.24800","5.10423","0.00372"
"61.51200","5.12624","0.00314"
"61.77600","5.14824","0.00363"
"62.04000","5.17018","0.00380"
"62.30400","5.19218","0.00348"
"62.56800","5.21419","0.00308"
"62.83200","5.23625","0.00331"
"63.09600","5.25819","0.00312"
"63.36000","5.28025","0.00396"
"63.62400","5.30220","0.00326"
"63.88800","5.32426","0.00320"
"64.15200","5.34620","0.00293"
"64.41600","5.36826","0.00359"
"64.68000","5.39021","0.00318"
"64.94400","5.41221","0.00312"
"65.20800","5.43415","0.00305"
"65.47200","5.45621","0.00313"
"65.73600","5.47822","0.00344"
"66.00000","5.50022","0.00338"
"66.26400","5.52222","0.00382"
"66.52800","5.54422","0.00344"
"66.79200","5.56623","0.00285"
"67.05600","5.58823","0.00319"
"67.32000","5.61023","0.00298"
"67.58400","5.63223","0.00265"
"67.84800","5.65424","0.00334"
"68.11200","5.67624","0.00255"
"68.37600","5.69824","0.00362"
"68.64000","5.72024","0.00299"
"68.90400","5.74225","0.00318"
"69.16800","5.76425","0.00345"
"69.43200","5.78625","0.00305"
"69.69600","5.80825","0.00332"
"69.96000","5.83026","0.00307"
"70.22400","5.85220","0.00290"
"70.48800","5.87420","0.00314"
"70.75200","5.89620","0.00350"
"71.01600","5.91827","0.00311"
"71.28000","5.94021","0.00286"
"71.54400","5.96221","0.00374"
"71.80800","5.98416","0.00286"
"72.07200","6.00622","0.00294"
"72.33600","6.02816","0.00304"
"72.60000","6.05022","0.00271"
"72.86400","6.07217","0.00329"
"73.12800","6.09423","0.00328"
"73.39200","6.11617","0.00393"
"73.65600","6.13823","0.00297"
"73.92000","6.16012","0.00253"
"74.18400","6.18224","0.00304"
"74.44800","6.20418","0.00292"
"74.71200","6.22630","0.00236"
"74.97600","6.24819","0.00308"
"75.24000","6.27025","0.00329"
"75.50400","6.29219","0.00356"
"75.76800","6.31419","0.00309"
"76.03200","6.33620","0.00294"
"76.29600","6.35826","0.00297"
"76.56000","6.38020","0.00274"
"76.82400","6.40220","0.00268"
"77.08800","6.42421","0.00313"
"77.35200","6.44627","0.00271"
"77.61600","6.46821","0.00271"
"77.88000","6.49027","0.00341"
"78.14400","6.51222","0.00354"
"78.40800","6.53422","0.00278"
"78.67200","6.55622","0.00305"
"78.93600","6.57822","0.00342"
"79.20000","6.60023","0.00255"
"79.46400","6.62229","0.00263"
"79.72800","6.64429","0.00296"
"79.99200","6.66623","0.00326"
"80.25600","6.68824","0.00282"
"80.52000","6.71024","0.00256"
"80.78400","6.73224","0.00303"
"81.04800","6.75424","0.00321"
"81.31200","6.77625","0.00315"
"81.57600","6.79825","0.00310"
"81.84000","6.82025","0.00323"
"82.10400","6.84219","0.00281"
"82.36800","6.86426","0.00262"
"82.63200","6.88620","0.00294"
"82.89600","6.90826","0.00285"
"83.16000","6.93026","0.00272"
"83.42400","6.95227","0.00294"
"83.68800","6.97421","0.00291"
"83.95200","6.99627","0.00275"
"84.21600","7.01822","0.00236"
"84.48000","7.04028","0.00271"
"84.74400","7.06222","0.00252"
"85.00800","7.08428","0.00266"
"85.27200","7.10617","0.00252"
"85.53600","7.12823","0.00314"
"85.80000","7.15017","0.00314"
"86.06400","7.17223","0.00293"
"86.32800","7.19424","0.00256"
"86.59200","7.21624","0.00285"
"86.85600","7.23818","0.00342"
"87.12000","7.26024","0.00330"
"87.38400","7.28219","0.00311"
"87.64800","7.30425","0.00316"
"87.91200","7.32619","0.00246"
"88.17600","7.34825","0.00255"
"88.44000","7.37020","0.00365"
"88.70400","7.39220","0.00291"
"88.96800","7.41414","0.00243"
"89.23200","7.43620","0.00257"
"89.49600","7.45821","0.00278"
"89.76000","7.48027","0.00301"
"90.02400","7.50215","0.00274"
"90.28800","7.52421","0.00284"
"90.55200","7.54622","0.00288"
"90.81600","7.56822","0.00233"
"91.08000","7.59022","0.00297"
"91.34400","7.61222","0.00372"
"91.60800","7.63423","0.00309"
"91.87200","7.65623","0.00241"
"92.13600","7.67817","0.00253"
"92.40000","7.70023","0.00203"
"92.66400","7.72224","0.00246"
"92.92800","7.74424","0.00286"
"93.19200","7.76624","0.00281"
"93.45600","7.78824","0.00282"
"93.72000","7.81025","0.00275"
"93.98400","7.83225","0.00284"
"94.24800","7.85419","0.00266"
"94.51200","7.87625","0.00256"
"94.77600","7.89826","0.00262"
"95.04000","7.92026","0.00262"
"95.30400","7.94220","0.00289"
"95.56800","7.96420","0.00234"
"95.83200","7.98621","0.00243"
"96.09600","8.00821","0.00346"
"96.36000","8.03027","0.00240"
"96.62400","8.05221","0.00268"
"96.88800","8.07422","0.00271"
"97.15200","8.09622","0.00314"
"97.41600","8.11822","0.00242"
"97.68000","8.14023","0.00266"
"97.94400","8.16229","0.00269"
"98.20800","8.18423","0.00259"
"98.47200","8.20623","0.00233"
"98.73600","8.22818","0.00190"
"99.00000","8.25024","0.00256"
"99.26400","8.27224","0.00298"
"99.52800","8.29424","0.00231"
"99.79200","8.31619","0.00161"
"100.05600","8.33825","0.00127"
"100.32000","8.36013","0.00121"
"100.58400","8.38225","0.00100"
"100.84800","8.40420","0.00153"
"101.11200","8.42626","0.00146"
"101.37600","8.44820","0.00139"
"101.64000","8.47026","0.00144"
"101.90400","8.49215","0.00133"
"102.16800","8.51421","0.00173"
"102.43200","8.53621","0.00161"
"102.69600","8.55827","0.00185"
"102.96000","8.58022","0.00122"
"103.22400","8.60222","0.00162"
"103.48800","8.62422","0.00129"
"103.75200","8.64622","0.00129"
"104.01600","8.66817","0.00128"
"104.28000","8.69023","0.00092"
"104.54400","8.71223","0.00158"
"104.80800","8.73423","0.00128"
"105.07200","8.75618","0.00122"
"105.33600","8.77830","0.00091"
"105.60000","8.80024","0.00096"
"105.86400","8.82230","0.00186"
"106.12800","8.84419","0.00159"
"106.39200","8.86625","0.00165"
"106.65600","8.88819","0.00150"
"106.92000","8.91025","0.00162"
"107.18400","8.93220","0.00111"
"107.44800","8.95426","0.00139"
"107.71200","8.97626","0.00176"
"107.97600","8.99826","0.00165"
"108.24000","9.02021","0.00173"
"108.50400","9.04221","0.00091"
"108.76800","9.06427","0.00159"
"109.03200","9.08622","0.00119"
"109.29600","9.10822","0.00109"
"109.56000","9.13022","0.00144"
"109.82400","9.15222","0.00155"
"110.08800","9.17423","0.00189"
"110.35200","9.19623","0.00157"
"110.61600","9.21823","0.00151"
"110.88000","9.24029","0.00106"
"111.14400","9.26224","0.00161"
"111.40800","9.28424","0.00100"
"111.67200","9.30618","0.00122"
"111.93600","9.32824","0.00158"
"112.20000","9.35025","0.00127"
"112.46400","9.37219","0.00090"
"112.72800","9.39419","0.00153"
"112.99200","9.41625","0.00086"
"113.25600","9.43820","0.00122"
"113.52000","9.46020","0.00048"
"113.78400","9.48214","0.00087"
"114.04800","9.50426","0.00158"
"114.31200","9.52621","0.00173"
"114.57600","9.54821","0.00148"
"114.84000","9.57015","0.00137"
"115.10400","9.59221","0.00179"
"115.36800","9.61416","0.00132"
"115.63200","9.63622","0.00150"
"115.89600","9.65816","0.00186"
"116.16000","9.68028","0.00126"
"116.42400","9.70217","0.00174"
"116.68800","9.72429","0.00148"
"116.95200","9.74617","0.00177"
"117.21600","9.76823","0.00135"
"117.48000","9.79018","0.00204"
"117.74400","9.81224","0.00163"
"118.00800","9.83418","0.00181"
"118.27200","9.85618","0.00118"
"118.53600","9.87825","0.00106"
"118.80000","9.90025","0.00171"
"119.06400","9.92219","0.00134"
"119.32800","9.94425","0.00141"
"119.59200","9.96620","0.00126"
"119.85600","9.98826","0.00203"
"120.12000","10.01026","0.00139"
"120.38400","10.03226","0.00171"
"120.64800","10.05421","0.00094"
"120.91200","10.07627","0.00121"
"121.17600","10.09821","0.00106"
"121.44000","10.12022","0.00139"
"121.70400","10.14222","0.00074"
"121.96800","10.16428","0.00160"
"122.23200","10.18622","0.00106"
"122.49600","10.20828","0.00178"
"122.76000","10.23029","0.00199"
"123.02400","10.25223","0.00170"
"123.28800","10.27417","0.00134"
"123.55200","10.29624","0.00136"
"123.81600","10.31824","0.00198"
"124.08000","10.34024","0.00169"
"124.34400","10.36224","0.00117"
"124.60800","10.38425","0.00115"
"124.87200","10.40619","0.00175"
"125.13600","10.42819","0.00180"
"125.40000","10.45025","0.00112"
"125.66400","10.47220","0.00145"
"125.92800","10.49426","0.00179"
"126.19200","10.51620","0.00158"
"126.45600","10.53826","0.00141"
"126.72000","10.56021","0.00160"
"126.98400","10.58221","0.00240"
"127.24800","10.60421","0.00119"
"127.51200","10.62627","0.00130"
"127.77600","10.64816","0.00220"
"128.04000","10.67022","0.00143"
"128.30400","10.69222","0.00188"
"128.56800","10.71422","0.00110"
"128.83200","10.73623","0.00117"
"129.09600","10.75829","0.00130"
"129.36000","10.78023","0.00171"
"129.62400","10.80223","0.00144"
"129.88800","10.82418","0.00162"
"130.15200","10.84624","0.00107"
"130.41600","10.86818","0.00157"
"130.68000","10.89024","0.00097"
"130.94400","10.91219","0.00162"
"131.20800","10.93425","0.00140"
"131.47200","10.95613","0.00145"
"131.73600","10.97820","0.00214"
"132.00000","11.00014","0.00170"
"132.26400","11.02226","0.00123"
"132.52800","11.04420","0.00151"
"132.79200","11.06626","0.00154"
"133.05600","11.08821","0.00185"
"133.32000","11.11027","0.00192"
"133.58400","11.13221","0.00167"
"133.84800","11.15422","0.00182"
"134.11200","11.17622","0.00137"
"134.37600","11.19828","0.00196"
"134.64000","11.22016","0.00185"
"134.90400","11.24223","0.00189"
"135.16800","11.26417","0.00151"
"135.43200","11.28623","0.00221"
"135.69600","11.30817","0.00168"
"135.96000","11.33024","0.00147"
"136.22400","11.35224","0.00142"
"136.48800","11.37424","0.00168"
"136.75200","11.39618","0.00215"
"137.01600","11.41825","0.00174"
"137.28000","11.44019","0.00143"
"137.54400","11.46219","0.00169"
"137.80800","11.48425","0.00213"
"138.07200","11.50620","0.00165"
"138.33600","11.52820","0.00143"
"138.60000","11.55020","0.00193"
"138.86400","11.57226","0.00170"
"139.12800","11.59427","0.00116"
"139.39200","11.61627","0.00178"
"139.65600","11.63821","0.00178"
"139.92000","11.66021","0.00200"
"140.18400","11.68222","0.00229"
"140.44800","11.70428","0.00151"
"140.71200","11.72622","0.00187"
"140.97600","11.74829","0.00120"
"141.24000","11.77017","0.00213"
"141.50400","11.79229","0.00201"
"141.76800","11.81417","0.00191"
"142.03200","11.83623","0.00119"
"142.29600","11.85824","0.00122"
"142.56000","11.88024","0.00169"
"142.82400","11.90218","0.00176"
"143.08800","11.92424","0.00189"
"143.35200","11.94613","0.00185"
"143.61600","11.96825","0.00184"
"143.88000","11.99019","0.00244"
"144.14400","12.01231","0.00161"
"144.40800","12.03420","0.00129"
"144.67200","12.05620","0.00144"
"144.93600","12.07814","0.00156"
"145.20000","12.10020","0.00186"
"145.46400","12.12221","0.00118"
"145.72800","12.14427","0.00164"
"145.99200","12.16621","0.00168"
"146.25600","12.18822","0.00189"
"146.52000","12.21022","0.00174"
"146.78400","12.23228","0.00135"
"147.04800","12.25422","0.00177"
"147.31200","12.27629","0.00154"
"147.57600","12.29823","0.00117"
"147.84000","12.32023","0.00173"
"148.10400","12.34217","0.00130"
"148.36800","12.36424","0.00168"
"148.63200","12.38624","0.00138"
"148.89600","12.40824","0.00161"
"149.16000","12.43018","0.00139"
"149.42400","12.45225","0.00193"
"149.68800","12.47419","0.00128"
"149.95200","12.49625","0.00182"
"150.21600","12.51826","0.00175"
"150.48000","12.54026","0.00186"
"150.74400","12.56226","0.00173"
"151.00800","12.58420","0.00149"
"151.27200","12.60620","0.00172"
"151.53600","12.62821","0.00150"
"151.80000","12.65021","0.00107"
"152.06400","12.67221","0.00221"
"152.32800","12.69427","0.00151"
"152.59200","12.71622","0.00119"
"152.85600","12.73822","0.00179"
"153.12000","12.76022","0.00148"
"153.38400","12.78223","0.00150"
"153.64800","12.80423","0.00137"
"153.91200","12.82629","0.00189"
"154.17600","12.84823","0.00154"
"154.44000","12.87024","0.00190"
"154.70400","12.89218","0.00180"
"154.96800","12.91424","0.00158"
"155.23200","12.93624","0.00118"
"155.49600","12.95825","0.00224"
"155.76000","12.98019","0.00167"
"156.02400","13.00219","0.00164"
"156.28800","13.02419","0.00156"
"156.55200","13.04626","0.00197"
"156.81600","13.06820","0.00205"
"157.08000","13.09026","0.00172"
"157.34400","13.11220","0.00153"
"157.60800","13.13421","0.00169"
"157.87200","13.15615","0.00102"
"158.13600","13.17827","0.00105"
"158.40000","13.20015","0.00154"
"158.66400","13.22222","0.00162"
"158.92800","13.24422","0.00148"
"159.19200","13.26622","0.00167"
"159.45600","13.28816","0.00135"
"159.72000","13.31023","0.00162"
"159.98400","13.33217","0.00133"
"160.24800","13.35423","0.00113"
"160.51200","13.37617","0.00165"
"160.77600","13.39824","0.00112"
"161.04000","13.42018","0.00133"
"161.30400","13.44218","0.00163"
"161.56800","13.46424","0.00151"
"161.83200","13.48625","0.00135"
"162.09600","13.50819","0.00166"
"162.36000","13.53025","0.00134"
"162.62400","13.55220","0.00168"
"162.88800","13.57420","0.00099"
"163.15200","13.59620","0.00161"
"163.41600","13.61826","0.00098"
"163.68000","13.64026","0.00169"
"163.94400","13.66227","0.00156"
"164.20800","13.68421","0.00098"
"164.47200","13.70621","0.00150"
"164.73600","13.72816","0.00159"
"165.00000","13.75022","0.00096"
"165.26400","13.77228","0.00116"
"165.52800","13.79428","0.00182"
"165.79200","13.81623","0.00180"
"166.05600","13.83823","0.00112"
"166.32000","13.86023","0.00124"
"166.58400","13.88223","0.00216"
"166.84800","13.90430","0.00120"
"167.11200","13.92624","0.00089"
"167.37600","13.94824","0.00133"
"167.64000","13.97018","0.00171"
"167.90400","13.99219","0.00179"
"168.16800","14.01419","0.00139"
"168.43200","14.03625","0.00143"
"168.69600","14.05825","0.00139"
"168.96000","14.08026","0.00150"
"169.22400","14.10214","0.00103"
"169.48800","14.12426","0.00180"
"169.75200","14.14626","0.00082"
"170.01600","14.16827","0.00128"
"170.28000","14.19021","0.00110"
"170.54400","14.21227","0.00127"
"170.80800","14.23415","0.00120"
"171.07200","14.25628","0.00066"
"171.33600","14.27816","0.00170"
"171.60000","14.30022","0.00162"
"171.86400","14.32222","0.00166"
"172.12800","14.34429","0.00171"
"172.39200","14.36617","0.00129"
"172.65600","14.38823","0.00092"
"172.92000","14.41018","0.00167"
"173.18400","14.43224","0.00139"
"173.44800","14.45418","0.00135"
"173.71200","14.47624","0.00130"
"173.97600","14.49819","0.00202"
"174.24000","14.52025","0.00168"
"174.50400","14.54219","0.00145"
"174.76800","14.56425","0.00079"
"175.03200","14.58619","0.00152"
"175.29600","14.60826","0.00142"
"175.56000","14.63020","0.00163"
"175.82400","14.65226","0.00111"
"176.08800","14.67421","0.00168"
"176.35200","14.69627","0.00198"
"176.61600","14.71821","0.00120"
"176.88000","14.74027","0.00135"
"177.14400","14.76222","0.00168"
"177.40800","14.78422","0.00145"
"177.67200","14.80622","0.00169"
"177.93600","14.82822","0.00171"
"178.20000","14.85023","0.00168"
"178.46400","14.87223","0.00126"
"178.72800","14.89423","0.00131"
"178.99200","14.91623","0.00147"
"179.25600","14.93818","0.00126"
"179.52000","14.96024","0.00146"
"179.78400","14.98224","0.00132"
"180.04800","15.00418","0.00134"
"180.31200","15.02625","0.00145"
"180.57600","15.04825","0.00200"
"180.84000","15.07019","0.00107"
"181.10400","15.09225","0.00083"
"181.36800","15.11420","0.00198"
"181.63200","15.13620","0.00096"
"181.89600","15.15820","0.00184"
"182.16000","15.18026","0.00210"
"182.42400","15.20227","0.00184"
"182.68800","15.22421","0.00179"
"182.95200","15.24627","0.00156"
"183.21600","15.26821","0.00168"
"183.48000","15.29028","0.00146"
"183.74400","15.31222","0.00190"
"184.00800","15.33422","0.00140"
"184.27200","15.35616","0.00208"
"184.53600","15.37823","0.00197"
"184.80000","15.40017","0.00199"
"185.06400","15.42223","0.00194"
"185.32800","15.44417","0.00187"
"185.59200","15.46624","0.00128"
"185.85600","15.48818","0.00166"
"186.12000","15.51024","0.00166"
"186.38400","15.53218","0.00117"
"186.64800","15.55425","0.00182"
"186.91200","15.57625","0.00151"
"187.17600","15.59825","0.00170"
"187.44000","15.62020","0.00233"
"187.70400","15.64220","0.00175"
"187.96800","15.66414","0.00128"
"188.23200","15.68626","0.00162"
"188.49600","15.70820","0.00182"
"188.76000","15.73021","0.00179"
"189.02400","15.75221","0.00214"
"189.28800","15.77421","0.00129"
"189.55200","15.79621","0.00227"
"189.81600","15.81828","0.00167"
"190.08000","15.84016","0.00189"
"190.34400","15.86228","0.00183"
"190.60800","15.88422","0.00169"
"190.87200","15.90623","0.00145"
"191.13600","15.92817","0.00134"
"191.40000","15.95029","0.00155"
"191.66400","15.97224","0.00089"
"191.92800","15.99430","0.00124"
"192.19200","16.01624","0.00171"
"192.45600","16.03824","0.00197"
"192.72000","16.06025","0.00154"
"192.98400","16.08225","0.00114"
"193.24800","16.10425","0.00152"
"193.51200","16.12625","0.00177"
"193.77600","16.14826","0.00130"
"194.04000","16.17020","0.00153"
"194.30400","16.19226","0.00180"
"194.56800","16.21420","0.00180"
"194.83200","16.23627","0.00166"
"195.09600","16.25821","0.00158"
"195.36000","16.28027","0.00122"
"195.62400","16.30221","0.00208"
"195.88800","16.32422","0.00156"
"196.15200","16.34622","0.00089"
"196.41600","16.36822","0.00104"
"196.68000","16.39022","0.00184"
"196.94400","16.41223","0.00167"
"197.20800","16.43417","0.00126"
"197.47200","16.45623","0.00169"
"197.73600","16.47824","0.00150"
"198.00000","16.50024","0.00190"
"198.26400","16.52218","0.00166"
"198.52800","16.54424","0.00165"
"198.79200","16.56618","0.00177"
"199.05600","16.58819","0.00198"
"199.32000","16.61019","0.00169"
"199.58400","16.63225","0.00238"
"199.84800","16.65420","0.00164"
"200.11200","16.67626","0.00126"
"200.37600","16.69814","0.00225"
"200.64000","16.72020","0.00183"
"200.90400","16.74215","0.00153"
"201.16800","16.76421","0.00167"
"201.43200","16.78615","0.00142"
"201.69600","16.80821","0.00153"
"201.96000","16.83016","0.00156"
"202.22400","16.85228","0.00221"
"202.48800","16.87422","0.00195"
"202.75200","16.89622","0.00210"
"203.01600","16.91822","0.00149"
"203.28000","16.94023","0.00184"
"203.54400","16.96223","0.00135"
"203.80800","16.98423","0.00174"
"204.07200","17.00618","0.00161"
"204.33600","17.02824","0.00203"
"204.60000","17.05024","0.00148"
"204.86400","17.07230","0.00139"
"205.12800","17.09418","0.00205"
"205.39200","17.11625","0.00152"
"205.65600","17.13819","0.00175"
"205.92000","17.16025","0.00120"
"206.18400","17.18225","0.00222"
"206.44800","17.20426","0.00136"
"206.71200","17.22626","0.00149"
"206.97600","17.24826","0.00130"
"207.24000","17.27015","0.00146"
"207.50400","17.29221","0.00123"
"207.76800","17.31415","0.00170"
"208.03200","17.33621","0.00159"
"208.29600","17.35828","0.00153"
"208.56000","17.38028","0.00165"
"208.82400","17.40222","0.00168"
"209.08800","17.42422","0.00205"
"209.35200","17.44623","0.00170"
"209.61600","17.46823","0.00203"
"209.88000","17.49023","0.00149"
"210.14400","17.51223","0.00191"
"210.40800","17.53418","0.00133"
"210.67200","17.55612","0.00206"
"210.93600","17.57824","0.00194"
"211.20000","17.60018","0.00139"
"211.46400","17.62225","0.00207"
"211.72800","17.64419","0.00169"
"211.99200","17.66625","0.00139"
"212.25600","17.68814","0.00176"
"212.52000","17.71026","0.00209"
"212.78400","17.73220","0.00152"
"213.04800","17.75426","0.00142"
"213.31200","17.77621","0.00108"
"213.57600","17.79821","0.00167"
"213.84000","17.82015","0.00171"
"214.10400","17.84227","0.00159"
"214.36800","17.86422","0.00174"
"214.63200","17.88622","0.00222"
"214.89600","17.90822","0.00169"
"215.16000","17.93022","0.00229"
"215.42400","17.95217","0.00169"
"215.68800","17.97423","0.00178"
"215.95200","17.99617","0.00221"
"216.21600","18.01823","0.00148"
"216.48000","18.04024","0.00189"
"216.74400","18.06224","0.00144"
"217.00800","18.08418","0.00164"
"217.27200","18.10625","0.00165"
"217.53600","18.12819","0.00185"
"217.80000","18.15025","0.00212"
"218.06400","18.17219","0.00241"
"218.32800","18.19425","0.00197"
"218.59200","18.21620","0.00219"
"218.85600","18.23826","0.00192"
"219.12000","18.26020","0.00187"
"219.38400","18.28226","0.00206"
"219.64800","18.30421","0.00200"
"219.91200","18.32627","0.00180"
"220.17600","18.34821","0.00170"
"220.44000","18.37021","0.00208"
"220.70400","18.39222","0.00143"
"220.96800","18.41422","0.00176"
"221.23200","18.43622","0.00214"
"221.49600","18.45823","0.00197"
"221.76000","18.48023","0.00182"
"222.02400","18.50223","0.00154"
"222.28800","18.52423","0.00181"
"222.55200","18.54623","0.00246"
"222.81600","18.56824","0.00154"
"223.08000","18.59024","0.00251"
"223.34400","18.61224","0.00220"
"223.60800","18.63419","0.00169"
"223.87200","18.65619","0.00233"
"224.13600","18.67819","0.00206"
"224.40000","18.70019","0.00150"
"224.66400","18.72219","0.00212"
"224.92800","18.74426","0.00218"
"225.19200","18.76620","0.00222"
"225.45600","18.78820","0.00204"
"225.72000","18.81021","0.00211"
"225.98400","18.83227","0.00149"
"226.24800","18.85421","0.00195"
"226.51200","18.87621","0.00158"
"226.77600","18.89816","0.00199"
"227.04000","18.92022","0.00236"
"227.30400","18.94216","0.00208"
"227.56800","18.96428","0.00188"
"227.83200","18.98617","0.00207"
"228.09600","19.00829","0.00203"
"228.36000","19.03017","0.00166"
"228.62400","19.05223","0.00155"
"228.88800","19.07418","0.00215"
"229.15200","19.09624","0.00215"
"229.41600","19.11818","0.00187"
"229.68000","19.14030","0.00227"
"229.94400","19.16219","0.00265"
"230.20800","19.18425","0.00233"
"230.47200","19.20625","0.00235"
"230.73600","19.22825","0.00224"
"231.00000","19.25020","0.00224"
"231.26400","19.27226","0.00247"
"231.52800","19.29426","0.00178"
"231.79200","19.31626","0.00290"
"232.05600","19.33821","0.00197"
"232.32000","19.36021","0.00228"
"232.58400","19.38221","0.00218"
"232.84800","19.40428","0.00188"
"233.11200","19.42622","0.00173"
"233.37600","19.44822","0.00210"
"233.64000","19.47016","0.00208"
"233.90400","19.49223","0.00175"
"234.16800","19.51423","0.00190"
"234.43200","19.53629","0.00207"
"234.69600","19.55823","0.00256"
"234.96000","19.58030","0.00181"
"235.22400","19.60218","0.00190"
"235.48800","19.62424","0.00218"
"235.75200","19.64624","0.00219"
"236.01600","19.66825","0.00194"
"236.28000","19.69025","0.00259"
"236.54400","19.71225","0.00203"
"236.80800","19.73425","0.00188"
"237.07200","19.75620","0.00211"
"237.33600","19.77820","0.00154"
"237.60000","19.80020","0.00224"
"237.86400","19.82220","0.00198"
"238.12800","19.84420","0.00167"
"238.39200","19.86621","0.00204"
"238.65600","19.88821","0.00229"
"238.92000","19.91027","0.00257"
"239.18400","19.93221","0.00229"
"239.44800","19.95422","0.00198"
"239.71200","19.97622","0.00196"
"239.97600","19.99822","0.00229"
"240.24000","20.02017","0.00219"
"240.50400","20.04223","0.00156"
"240.76800","20.06417","0.00234"
"241.03200","20.08624","0.00225"
"241.29600","20.10823","0.00241"
"241.56000","20.13024","0.00208"
"241.82400","20.15218","0.00200"
"242.08800","20.17424","0.00118"
"242.35200","20.19619","0.00212"
"242.61600","20.21825","0.00205"
"242.88000","20.24019","0.00135"
"243.14400","20.26225","0.00227"
"243.40800","20.28414","0.00172"
"243.67200","20.30620","0.00257"
"243.93600","20.32814","0.00224"
"244.20000","20.35026","0.00220"
"244.46400","20.37221","0.00173"
"244.72800","20.39427","0.00275"
"244.99200","20.41621","0.00217"
"245.25600","20.43827","0.00217"
"245.52000","20.46022","0.00248"
"245.78400","20.48228","0.00275"
"246.04800","20.50416","0.00299"
"246.31200","20.52629","0.00227"
"246.57600","20.54823","0.00312"
"246.84000","20.57023","0.00230"
"247.10400","20.59217","0.00195"
"247.36800","20.61423","0.00173"
"247.63200","20.63624","0.00223"
"247.89600","20.65824","0.00202"
"248.16000","20.68018","0.00177"
"248.42400","20.70218","0.00186"
"248.68800","20.72419","0.00192"
"248.95200","20.74625","0.00185"
"249.21600","20.76825","0.00189"
"249.48000","20.79020","0.00191"
"249.74400","20.81220","0.00244"
"250.00800","20.83420","0.00209"
"250.27200","20.85620","0.00201"
"250.53600","20.87820","0.00209"
"250.80000","20.90021","0.00189"
"251.06400","20.92221","0.00230"
"251.32800","20.94427","0.00257"
"251.59200","20.96622","0.00237"
"251.85600","20.98822","0.00243"
"252.12000","21.01016","0.00269"
"252.38400","21.03222","0.00273"
"252.64800","21.05423","0.00267"
"252.91200","21.07629","0.00186"
"253.17600","21.09817","0.00234"
"253.44000","21.12024","0.00220"
"253.70400","21.14218","0.00247"
"253.96800","21.16424","0.00242"
"254.23200","21.18624","0.00193"
"254.49600","21.20825","0.00208"
"254.76000","21.23019","0.00260"
"255.02400","21.25225","0.00256"
"255.28800","21.27413","0.00239"
"255.55200","21.29626","0.00189"
"255.81600","21.31820","0.00270"
"256.08000","21.34026","0.00288"
"256.34400","21.36220","0.00217"
"256.60800","21.38420","0.00256"
"256.87200","21.40615","0.00277"
"257.13600","21.42827","0.00295"
"257.40000","21.45021","0.00253"
"257.66400","21.47227","0.00252"
"257.92800","21.49422","0.00344"
"258.19200","21.51622","0.00270"
"258.45600","21.53816","0.00247"
"258.72000","21.56023","0.00251"
"258.98400","21.58217","0.00235"
"259.24800","21.60429","0.00285"
"259.51200","21.62623","0.00202"
"259.77600","21.64824","0.00282"
"260.04000","21.67012","0.00260"
"260.30400","21.69224","0.00261"
"260.56800","21.71418","0.00248"
"260.83200","21.73631","0.00242"
"261.09600","21.75819","0.00227"
"261.36000","21.78025","0.00244"
"261.62400","21.80219","0.00237"
"261.88800","21.82425","0.00234"
"262.15200","21.84620","0.00254"
"262.41600","21.86826","0.00287"
"262.68000","21.89020","0.00266"
"262.94400","21.91221","0.00288"
"263.20800","21.93421","0.00255"
"263.47200","21.95621","0.00279"
"263.73600","21.97821","0.00276"
"264.00000","22.00022","0.00340"
"264.26400","22.02228","0.00316"
"264.52800","22.04422","0.00236"
"264.79200","22.06623","0.00296"
"265.05600","22.08823","0.00320"
"265.32000","22.11023","0.00292"
"265.58400","22.13223","0.00331"
"265.84800","22.15423","0.00337"
"266.11200","22.17618","0.00331"
"266.37600","22.19824","0.00275"
"266.64000","22.22024","0.00357"
"266.90400","22.24224","0.00294"
"267.16800","22.26419","0.00315"
"267.43200","22.28625","0.00320"
"267.69600","22.30819","0.00276"
"267.96000","22.33025","0.00368"
"268.22400","22.35220","0.00346"
"268.48800","22.37426","0.00325"
"268.75200","22.39620","0.00349"
"269.01600","22.41827","0.00345"
"269.28000","22.44021","0.00277"
"269.54400","22.46221","0.00378"
"269.80800","22.48415","0.00401"
"270.07200","22.50628","0.00313"
"270.33600","22.52822","0.00355"
"270.60000","22.55022","0.00382"
"270.86400","22.57216","0.00348"
"271.12800","22.59429","0.00327"
"271.39200","22.61617","0.00345"
"271.65600","22.63823","0.00317"
"271.92000","22.66017","0.00379"
"272.18400","22.68223","0.00334"
"272.44800","22.70418","0.00326"
"272.71200","22.72630","0.00366"
"272.97600","22.74818","0.00314"
"273.24000","22.77019","0.00425"
"273.50400","22.79219","0.00356"
"273.76800","22.81419","0.00341"
"274.03200","22.83613","0.00359"
"274.29600","22.85826","0.00362"
"274.56000","22.88020","0.00341"
"274.82400","22.90226","0.00379"
"275.08800","22.92421","0.00316"
"275.35200","22.94626","0.00383"
"275.61600","22.96821","0.00369"
"275.88000","22.99027","0.00328"
"276.14400","23.01221","0.00400"
"276.40800","23.03422","0.00373"
"276.67200","23.05622","0.00384"
"276.93600","23.07822","0.00359"
"277.20000","23.10023","0.00408"
"277.46400","23.12223","0.00403"
"277.72800","23.14423","0.00405"
"277.99200","23.16623","0.00461"
"278.25600","23.18830","0.00417"
"278.52000","23.21024","0.00414"
"278.78400","23.23224","0.00444"
"279.04800","23.25424","0.00411"
"279.31200","23.27625","0.00379"
"279.57600","23.29819","0.00426"
"279.84000","23.32019","0.00446"
"280.10400","23.34219","0.00419"
"280.36800","23.36426","0.00450"
"280.63200","23.38626","0.00398"
"280.89600","23.40826","0.00443"
"281.16000","23.43020","0.00514"
"281.42400","23.45226","0.00459"
"281.68800","23.47421","0.00475"
"281.95200","23.49627","0.00472"
"282.21600","23.51821","0.00465"
"282.48000","23.54028","0.00490"
"282.74400","23.56222","0.00467"
"283.00800","23.58422","0.00504"
"283.27200","23.60622","0.00430"
"283.53600","23.62829","0.00497"
"283.80000","23.65023","0.00507"
"284.06400","23.67229","0.00486"
"284.32800","23.69423","0.00481"
"284.59200","23.71624","0.00502"
"284.85600","23.73818","0.00478"
"285.12000","23.76024","0.00485"
"285.38400","23.78218","0.00544"
"285.64800","23.80425","0.00440"
"285.91200","23.82619","0.00470"
"286.17600","23.84825","0.00562"
"286.44000","23.87019","0.00577"
"286.70400","23.89220","0.00570"
"286.96800","23.91414","0.00566"
"287.23200","23.93626","0.00553"
"287.49600","23.95820","0.00572"
"287.76000","23.98027","0.00527"
"288.02400","24.00221","0.00556"
"288.28800","24.02427","0.00569"
"288.55200","24.04615","0.00543"
"288.81600","24.06828","0.00537"
"289.08000","24.09022","0.00604"
"289.34400","24.11222","0.00630"
"289.60800","24.13423","0.00571"
"289.87200","24.15623","0.00613"
"290.13600","24.17817","0.00691"
"290.40000","24.20023","0.00627"
"290.66400","24.22229","0.00630"
"290.92800","24.24424","0.00641"
"291.19200","24.26618","0.00616"
"291.45600","24.28824","0.00670"
"291.72000","24.31018","0.00652"
"291.98400","24.33224","0.00669"
"292.24800","24.35425","0.00611"
"292.51200","24.37625","0.00630"
"292.77600","24.39820","0.00647"
"293.04000","24.42020","0.00714"
"293.30400","24.44220","0.00700"
"293.56800","24.46414","0.00706"
"293.83200","24.48620","0.00660"
"294.09600","24.50821","0.00661"
"294.36000","24.53027","0.00710"
"294.62400","24.55222","0.00734"
"294.88800","24.57428","0.00663"
"295.15200","24.59622","0.00699"
"295.41600","24.61822","0.00714"
"295.68000","24.64022","0.00675"
"295.94400","24.66229","0.00768"
"296.20800","24.68417","0.00718"
"296.47200","24.70623","0.00707"
"296.73600","24.72818","0.00783"
"297.00000","24.75030","0.00720"
"297.26400","24.77224","0.00722"
"297.52800","24.79424","0.00795"
"297.79200","24.81612","0.00774"
"298.05600","24.83825","0.00838"
"298.32000","24.86019","0.00829"
"298.58400","24.88225","0.00725"
"298.84800","24.90413","0.00825"
"299.11200","24.92620","0.00770"
"299.37600","24.94820","0.00814"
"299.64000","24.97014","0.00831"
"299.90400","24.99214","0.00786"
"300.16800","25.01427","0.00832"
"300.43200","25.03621","0.00861"
"300.69600","25.05827","0.00865"
"300.96000","25.08022","0.00895"
"301.22400","25.10222","0.00913"
"301.48800","25.12422","0.00943"
"301.75200","25.14628","0.00865"
"302.01600","25.16822","0.00904"
"302.28000","25.19029","0.00887"
"302.54400","25.21217","0.00920"
"302.80800","25.23423","0.00943"
"303.07200","25.25617","0.00853"
"303.33600","25.27824","0.00878"
"303.60000","25.30024","0.00883"
"303.86400","25.32230","0.00994"
"304.12800","25.34418","0.00950"
"304.39200","25.36625","0.00976"
"304.65600","25.38819","0.00986"
"304.92000","25.41025","0.00982"
"305.18400","25.43220","0.00980"
"305.44800","25.45426","0.01002"
"305.71200","25.47626","0.00976"
"305.97600","25.49820","0.01000"
"306.24000","25.52021","0.00930"
"306.50400","25.54227","0.00998"
"306.76800","25.56421","0.01018"
"307.03200","25.58621","0.01051"
"307.29600","25.60828","0.01068"
"307.56000","25.63022","0.00997"
"307.82400","25.65222","0.00994"
"308.08800","25.67422","0.01066"
"308.35200","25.69623","0.01088"
"308.61600","25.71823","0.01096"
"308.88000","25.74029","0.01126"
"309.14400","25.76217","0.01101"
"309.40800","25.78418","0.01062"
"309.67200","25.80612","0.01097"
"309.93600","25.82824","0.01093"
"310.20000","25.85025","0.01079"
"310.46400","25.87219","0.01142"
"310.72800","25.89419","0.01134"
"310.99200","25.91619","0.01151"
"311.25600","25.93819","0.01153"
"311.52000","25.96025","0.01146"
"311.78400","25.98220","0.01171"
"312.04800","26.00426","0.01201"
"312.31200","26.02621","0.01184"
"312.57600","26.04821","0.01198"
"312.84000","26.07015","0.01272"
"313.10400","26.09221","0.01236"
"313.36800","26.11421","0.01182"
"313.63200","26.13628","0.01214"
"313.89600","26.15816","0.01223"
"314.16000","26.18022","0.01194"
"314.42400","26.20216","0.01265"
"314.68800","26.22423","0.01269"
"314.95200","26.24617","0.01277"
"315.21600","26.26823","0.01266"
"315.48000","26.29017","0.01268"
"315.74400","26.31224","0.01305"
"316.00800","26.33424","0.01285"
"316.27200","26.35624","0.01316"
"316.53600","26.37819","0.00248"
"316.80000","26.40025","0.00273"
"317.06400","26.42219","0.00178"
"317.32800","26.44425","0.00029"
"317.59200","26.46619","0.00114"
"317.85600","26.48826","0.00108"
"318.12000","26.51026","0.00221"
"318.38400","26.53226","0.00152"
"318.64800","26.55426","0.00114"
"318.91200","26.57627","0.00112"
"319.17600","26.59815","0.00151"
"319.44000","26.62027","0.00167"
"319.70400","26.64221","0.00057"
"319.96800","26.66422","0.00085"
"320.23200","26.68628","0.00112"
"320.49600","26.70828","0.00123"
"320.76000","26.73023","0.00085"
"321.02400","26.75223","0.00130"
"321.28800","26.77423","0.00166"
"321.55200","26.79623","0.00178"
"321.81600","26.81824","0.00116"
"322.08000","26.84024","0.00163"
"322.34400","26.86224","0.00188"
"322.60800","26.88418","0.00151"
"322.87200","26.90625","0.00148"
"323.13600","26.92819","0.00175"
"323.40000","26.95025","0.00193"
"323.66400","26.97219","0.00174"
"323.92800","26.99426","0.00126"
"324.19200","27.01614","0.00096"
"324.45600","27.03826","0.00156"
"324.72000","27.06020","0.00207"
"324.98400","27.08227","0.00118"
"325.24800","27.10421","0.00119"
"325.51200","27.12621","0.00121"
"325.77600","27.14816","0.00118"
"326.04000","27.17022","0.00102"
"326.30400","27.19222","0.00172"
"326.56800","27.21422","0.00138"
"326.83200","27.23617","0.00158"
"327.09600","27.25823","0.00145"
"327.36000","27.28017","0.00125"
"327.62400","27.30223","0.00159"
"327.88800","27.32417","0.00082"
"328.15200","27.34624","0.00113"
"328.41600","27.36824","0.00109"
"328.68000","27.39030","0.00165"
"328.94400","27.41219","0.00147"
"329.20800","27.43419","0.00156"
"329.47200","27.45613","0.00127"
"329.73600","27.47825","0.00146"
"330.00000","27.50019","0.00173"
"330.26400","27.52232","0.00141"
"330.52800","27.54420","0.00169"
"330.79200","27.56626","0.00197"
"331.05600","27.58821","0.00142"
"331.32000","27.61027","0.00142"
"331.58400","27.63221","0.00123"
"331.84800","27.65427","0.00141"
"332.11200","27.67622","0.00196"
"332.37600","27.69822","0.00205"
"332.64000","27.72022","0.00162"
"332.90400","27.74223","0.00148"
"333.16800","27.76423","0.00191"
"333.43200","27.78623","0.00127"
"333.69600","27.80823","0.00185"
"333.96000","27.83017","0.00181"
"334.22400","27.85218","0.00161"
"334.48800","27.87424","0.00117"
"334.75200","27.89624","0.00154"
"335.01600","27.91818","0.00177"
"335.28000","27.94019","0.00226"
"335.54400","27.96225","0.00188"
"335.80800","27.98419","0.00161"
"336.07200","28.00620","0.00201"
"336.33600","28.02820","0.00187"
"336.60000","28.05020","0.00170"
"336.86400","28.07226","0.00182"
"337.12800","28.09426","0.00163"
"337.39200","28.11627","0.00202"
"337.65600","28.13821","0.00178"
"337.92000","28.16021","0.00177"
"338.18400","28.18221","0.00126"
"338.44800","28.20422","0.00156"
"338.71200","28.22616","0.00160"
"338.97600","28.24828","0.00144"
"339.24000","28.27017","0.00209"
"339.50400","28.29223","0.00196"
"339.76800","28.31417","0.00116"
"340.03200","28.33624","0.00175"
"340.29600","28.35818","0.00179"
"340.56000","28.38024","0.00159"
"340.82400","28.40212","0.00156"
"341.08800","28.42424","0.00136"
"341.35200","28.44613","0.00158"
"341.61600","28.46825","0.00177"
"341.88000","28.49019","0.00175"
"342.14400","28.51220","0.00221"
"342.40800","28.53420","0.00166"
"342.67200","28.55620","0.00196"
"342.93600","28.57820","0.00220"
"343.20000","28.60026","0.00149"
"343.46400","28.62227","0.00253"
"343.72800","28.64427","0.00131"
"343.99200","28.66627","0.00200"
"344.25600","28.68827","0.00241"
"344.52000","28.71022","0.00194"
"344.78400","28.73228","0.00211"
"345.04800","28.75422","0.00205"
"345.31200","28.77629","0.00192"
"345.57600","28.79817","0.00203"
"345.84000","28.82023","0.00187"
"346.10400","28.84217","0.00197"
"346.36800","28.86424","0.00180"
"346.63200","28.88624","0.00233"
"346.89600","28.90824","0.00215"
"347.16000","28.93018","0.00202"
"347.42400","28.95225","0.00217"
"347.68800","28.97425","0.00200"
"347.95200","28.99625","0.00216"
"348.21600","29.01825","0.00172"
"348.48000","29.04026","0.00205"
"348.74400","29.06220","0.00212"
"349.00800","29.08420","0.00123"
"349.27200","29.10620","0.00150"
"349.53600","29.12820","0.00172"
"349.80000","29.15027","0.00166"
"350.06400","29.17221","0.00195"
"350.32800","29.19427","0.00181"
"350.59200","29.21622","0.00182"
"350.85600","29.23828","0.00209"
"351.12000","29.26016","0.00163"
"351.38400","29.28222","0.00166"
"351.64800","29.30423","0.00201"
"351.91200","29.32623","0.00192"
"352.17600","29.34817","0.00160"
"352.44000","29.37024","0.00228"
"352.70400","29.39218","0.00193"
"352.96800","29.41424","0.00203"
"353.23200","29.43624","0.00187"
"353.49600","29.45824","0.00188"
"353.76000","29.48019","0.00177"
"354.02400","29.50225","0.00143"
"354.28800","29.52419","0.00160"
"354.55200","29.54626","0.00238"
"354.81600","29.56820","0.00218"
"355.08000","29.59026","0.00175"
"355.34400","29.61214","0.00172"
"355.60800","29.63427","0.00181"
"355.87200","29.65621","0.00174"
"356.13600","29.67827","0.00224"
"356.40000","29.70021","0.00224"
"356.66400","29.72227","0.00151"
"356.92800","29.74416","0.00198"
"357.19200","29.76622","0.00268"
"357.45600","29.78816","0.00210"
"357.72000","29.81022","0.00179"
"357.98400","29.83217","0.00208"
"358.24800","29.85429","0.00157"
"358.51200","29.87617","0.00193"
"358.77600","29.89823","0.00178"
"359.04000","29.92018","0.00225"
"359.30400","29.94224","0.00236"
"359.56800","29.96418","0.00219"
"359.83200","29.98624","0.00186"
"360.09600","30.00825","0.00198"
"360.36000","30.03025","0.00213"
"360.62400","30.05219","0.00200"
"360.88800","30.07426","0.00199"
"361.15200","30.09626","0.00222"
"361.41600","30.11826","0.00190"
"361.68000","30.14026","0.00276"
"361.94400","30.16221","0.00195"
"362.20800","30.18421","0.00177"
"362.47200","30.20621","0.00149"
"362.73600","30.22821","0.00114"
"363.00000","30.25022","0.00154"
"363.26400","30.27228","0.00121"
"363.52800","30.29422","0.00106"
"363.79200","30.31623","0.00142"
"364.05600","30.33823","0.00121"
"364.32000","30.36023","0.00153"
"364.58400","30.38223","0.00192"
"364.84800","30.40429","0.00171"
"365.11200","30.42624","0.00140"
"365.37600","30.44824","0.00101"
"365.64000","30.47018","0.00178"
"365.90400","30.49224","0.00171"
"366.16800","30.51419","0.00162"
"366.43200","30.53625","0.00156"
"366.69600","30.55819","0.00156"
"366.96000","30.58026","0.00143"
"367.22400","30.60220","0.00099"
"367.48800","30.62426","0.00181"
"367.75200","30.64620","0.00164"
"368.01600","30.66832","0.00132"
"368.28000","30.69021","0.00176"
"368.54400","30.71221","0.00178"
"368.80800","30.73415","0.00125"
"369.07200","30.75622","0.00119"
"369.33600","30.77816","0.00103"
"369.60000","30.80022","0.00157"
"369.86400","30.82222","0.00195"
"370.12800","30.84423","0.00131"
"370.39200","30.86617","0.00122"
"370.65600","30.88823","0.00161"
"370.92000","30.91017","0.00130"
"371.18400","30.93224","0.00199"
"371.44800","30.95424","0.00168"
"371.71200","30.97624","0.00152"
"371.97600","30.99818","0.00187"
"372.24000","31.02025","0.00212"
"372.50400","31.04219","0.00140"
"372.76800","31.06425","0.00168"
"373.03200","31.08625","0.00190"
"373.29600","31.10826","0.00158"
"373.56000","31.13020","0.00221"
"373.82400","31.15226","0.00149"
"374.08800","31.17421","0.00155"
"374.35200","31.19627","0.00131"
"374.61600","31.21821","0.00149"
"374.88000","31.24021","0.00182"
"375.14400","31.26221","0.00142"
"375.40800","31.28421","0.00180"
"375.67200","31.30622","0.00076"
"375.93600","31.32828","0.00146"
"376.20000","31.35022","0.00199"
"376.46400","31.37222","0.00158"
"376.72800","31.39423","0.00154"
"376.99200","31.41617","0.00130"
"377.25600","31.43823","0.00149"
"377.52000","31.46018","0.00205"
"377.78400","31.48224","0.00161"
"378.04800","31.50424","0.00152"
"378.31200","31.52624","0.00158"
"378.57600","31.54819","0.00104"
"378.84000","31.57025","0.00147"
"379.10400","31.59219","0.00177"
"379.36800","31.61419","0.00133"
"379.63200","31.63626","0.00125"
"379.89600","31.65826","0.00182"
"380.16000","31.68020","0.00163"
"380.42400","31.70226","0.00174"
"380.68800","31.72421","0.00130"
"380.95200","31.74621","0.00185"
"381.21600","31.76821","0.00200"
"381.48000","31.79028","0.00170"
"381.74400","31.81216","0.00199"
"382.00800","31.83422","0.00130"
"382.27200","31.85616","0.00137"
"382.53600","31.87823","0.00133"
"382.80000","31.90017","0.00152"
"383.06400","31.92229","0.00156"
"383.32800","31.94417","0.00129"
"383.59200","31.96624","0.00189"
"383.85600","31.98818","0.00175"
"384.12000","32.01024","0.00139"
"384.38400","32.03218","0.00165"
"384.64800","32.05424","0.00211"
"384.91200","32.07619","0.00178"
"385.17600","32.09819","0.00163"
"385.44000","32.12019","0.00235"
"385.70400","32.14220","0.00109"
"385.96800","32.16420","0.00152"
"386.23200","32.18626","0.00201"
"386.49600","32.20820","0.00185"
"386.76000","32.23027","0.00179"
"387.02400","32.25221","0.00227"
"387.28800","32.27421","0.00134"
"387.55200","32.29622","0.00186"
"387.81600","32.31828","0.00196"
"388.08000","32.34022","0.00120"
"388.34400","32.36222","0.00152"
"388.60800","32.38422","0.00173"
"388.87200","32.40623","0.00181"
"389.13600","32.42823","0.00194"
"389.40000","32.45023","0.00178"
"389.66400","32.47223","0.00126"
"389.92800","32.49424","0.00154"
"390.19200","32.51618","0.00139"
"390.45600","32.53824","0.00201"
"390.72000","32.56025","0.00170"
"390.98400","32.58224","0.00164"
"391.24800","32.60425","0.00199"
"391.51200","32.62619","0.00159"
"391.77600","32.64825","0.00209"
"392.04000","32.67026","0.00231"
"392.30400","32.69226","0.00196"
"392.56800","32.71420","0.00178"
"392.83200","32.73632","0.00161"
"393.09600","32.75821","0.00135"
"393.36000","32.78021","0.00158"
"393.62400","32.80215","0.00152"
"393.88800","32.82428","0.00181"
"394.15200","32.84621","0.00172"
"394.41600","32.86822","0.00182"
"394.68000","32.89022","0.00169"
"394.94400","32.91222","0.00185"
"395.20800","32.93417","0.00147"
"395.47200","32.95623","0.00156"
"395.73600","32.97817","0.00219"
"395.75800","32.98003","0.00199"