File: Force_trajectories/170212_3/Specimen_RawData_10.csv
End date,"2/12/2017"
Specimen label,"12DT_92"
Maximum Load,"0.01519",N

Time,Extension,Load
(s),(mm),(N)
"0.00000","0.00000","0.00001"
"0.19200","0.01315","0.00014"
"0.38400","0.03217","0.00015"
"0.57600","0.04825","0.00081"
"0.76800","0.06421","0.00078"
"0.96000","0.08018","0.00006"
"1.15200","0.09620","0.00041"
"1.34400","0.11222","0.00114"
"1.53600","0.12819","0.00019"
"1.72800","0.14421","0.00095"
"1.92000","0.16018","0.00107"
"2.11200","0.17614","0.00049"
"2.30400","0.19222","0.00154"
"2.49600","0.20819","0.00102"
"2.68800","0.22415","0.00107"
"2.88000","0.24017","0.00123"
"3.07200","0.25614","0.00097"
"3.26400","0.27216","0.00122"
"3.45600","0.28813","0.00160"
"3.64800","0.30415","0.00106"
"3.84000","0.32011","0.00108"
"4.03200","0.33620","0.00071"
"4.22400","0.35216","0.00111"
"4.41600","0.36818","0.00144"
"4.60800","0.38421","0.00185"
"4.80000","0.40011","0.00177"
"4.99200","0.41619","0.00182"
"5.18400","0.43216","0.00172"
"5.37600","0.44818","0.00183"
"5.56800","0.46415","0.00144"
"5.76000","0.48017","0.00125"
"5.95200","0.49619","0.00183"
"6.14400","0.51222","0.00090"
"6.33600","0.52812","0.00141"
"6.52800","0.54420","0.00111"
"6.72000","0.56017","0.00253"
"6.91200","0.57613","0.00207"
"7.10400","0.59216","0.00151"
"7.29600","0.60818","0.00174"
"7.48800","0.62408","0.00149"
"7.68000","0.64023","0.00176"
"7.87200","0.65619","0.00122"
"8.06400","0.67215","0.00182"
"8.25600","0.68818","0.00160"
"8.44800","0.70414","0.00168"
"8.64000","0.72016","0.00270"
"8.83200","0.73619","0.00175"
"9.02400","0.75209","0.00213"
"9.21600","0.76818","0.00226"
"9.40800","0.78420","0.00160"
"9.60000","0.80010","0.00174"
"9.79200","0.81619","0.00201"
"9.98400","0.83215","0.00181"
"10.17600","0.84811","0.00250"
"10.36800","0.86420","0.00128"
"10.56000","0.88022","0.00210"
"10.75200","0.89613","0.00201"
"10.94400","0.91221","0.00181"
"11.13600","0.92823","0.00232"
"11.32800","0.94414","0.00163"
"11.52000","0.96016","0.00235"
"11.71200","0.97618","0.00228"
"11.90400","0.99215","0.00223"
"12.09600","1.00823","0.00125"
"12.28800","1.02419","0.00216"
"12.48000","1.04022","0.00216"
"12.67200","1.05618","0.00223"
"12.86400","1.07221","0.00205"
"13.05600","1.08823","0.00228"
"13.24800","1.10419","0.00247"
"13.44000","1.12016","0.00220"
"13.63200","1.13624","0.00213"
"13.82400","1.15214","0.00199"
"14.01600","1.16817","0.00192"
"14.20800","1.18419","0.00182"
"14.40000","1.20016","0.00256"
"14.59200","1.21618","0.00205"
"14.78400","1.23220","0.00169"
"14.97600","1.24811","0.00247"
"15.16800","1.26425","0.00242"
"15.36000","1.28021","0.00237"
"15.55200","1.29612","0.00231"
"15.74400","1.31226","0.00231"
"15.93600","1.32816","0.00224"
"16.12800","1.34413","0.00247"
"16.32000","1.36021","0.00200"
"16.51200","1.37612","0.00225"
"16.70400","1.39214","0.00300"
"16.89600","1.40822","0.00194"
"17.08800","1.42419","0.00254"
"17.28000","1.44021","0.00240"
"17.47200","1.45617","0.00290"
"17.66400","1.47220","0.00280"
"17.85600","1.48816","0.00199"
"18.04800","1.50419","0.00274"
"18.24000","1.52015","0.00230"
"18.43200","1.53623","0.00261"
"18.62400","1.55226","0.00244"
"18.81600","1.56810","0.00264"
"19.00800","1.58424","0.00170"
"19.20000","1.60021","0.00213"
"19.39200","1.61611","0.00242"
"19.58400","1.63219","0.00270"
"19.77600","1.64816","0.00266"
"19.96800","1.66418","0.00230"
"20.16000","1.68021","0.00216"
"20.35200","1.69617","0.00276"
"20.54400","1.71219","0.00276"
"20.73600","1.72822","0.00257"
"20.92800","1.74418","0.00256"
"21.12000","1.76020","0.00326"
"21.31200","1.77623","0.00245"
"21.50400","1.79213","0.00237"
"21.69600","1.80821","0.00253"
"21.88800","1.82418","0.00228"
"22.08000","1.84014","0.00291"
"22.27200","1.85617","0.00329"
"22.46400","1.87219","0.00275"
"22.65600","1.88815","0.00276"
"22.84800","1.90418","0.00293"
"23.04000","1.92014","0.00243"
"23.23200","1.93622","0.00254"
"23.42400","1.95219","0.00265"
"23.61600","1.96815","0.00264"
"23.80800","1.98424","0.00246"
"24.00000","2.00014","0.00269"
"24.19200","2.01616","0.00287"
"24.38400","2.03219","0.00252"
"24.57600","2.04815","0.00277"
"24.76800","2.06417","0.00280"
"24.96000","2.08020","0.00295"
"25.15200","2.09616","0.00282"
"25.34400","2.11219","0.00310"
"25.53600","2.12821","0.00306"
"25.72800","2.14417","0.00298"
"25.92000","2.16020","0.00314"
"26.11200","2.17616","0.00286"
"26.30400","2.19212","0.00265"
"26.49600","2.20827","0.00306"
"26.68800","2.22423","0.00355"
"26.88000","2.24013","0.00322"
"27.07200","2.25622","0.00282"
"27.26400","2.27218","0.00305"
"27.45600","2.28815","0.00326"
"27.64800","2.30423","0.00329"
"27.84000","2.32019","0.00326"
"28.03200","2.33616","0.00275"
"28.22400","2.35224","0.00313"
"28.41600","2.36814","0.00351"
"28.60800","2.38417","0.00299"
"28.80000","2.40019","0.00379"
"28.99200","2.41615","0.00309"
"29.18400","2.43218","0.00297"
"29.37600","2.44820","0.00290"
"29.56800","2.46417","0.00275"
"29.76000","2.48019","0.00272"
"29.95200","2.49621","0.00344"
"30.14400","2.51212","0.00318"
"30.33600","2.52814","0.00381"
"30.52800","2.54416","0.00265"
"30.72000","2.56019","0.00319"
"30.91200","2.57621","0.00313"
"31.10400","2.59218","0.00256"
"31.29600","2.60820","0.00316"
"31.48800","2.62422","0.00333"
"31.68000","2.64013","0.00322"
"31.87200","2.65621","0.00290"
"32.06400","2.67223","0.00345"
"32.25600","2.68808","0.00367"
"32.44800","2.70422","0.00315"
"32.64000","2.72018","0.00285"
"32.83200","2.73615","0.00382"
"33.02400","2.75223","0.00288"
"33.21600","2.76820","0.00290"
"33.40800","2.78416","0.00277"
"33.60000","2.80018","0.00368"
"33.79200","2.81615","0.00329"
"33.98400","2.83223","0.00343"
"34.17600","2.84819","0.00350"
"34.36800","2.86416","0.00365"
"34.56000","2.88018","0.00296"
"34.75200","2.89615","0.00347"
"34.94400","2.91217","0.00304"
"35.13600","2.92819","0.00324"
"35.32800","2.94416","0.00272"
"35.52000","2.96018","0.00356"
"35.71200","2.97620","0.00359"
"35.90400","2.99217","0.00339"
"36.09600","3.00819","0.00300"
"36.28800","3.02421","0.00395"
"36.48000","3.04018","0.00410"
"36.67200","3.05614","0.00311"
"36.86400","3.07217","0.00379"
"37.05600","3.08819","0.00381"
"37.24800","3.10421","0.00375"
"37.44000","3.12018","0.00326"
"37.63200","3.13614","0.00307"
"37.82400","3.15222","0.00325"
"38.01600","3.16813","0.00349"
"38.20800","3.18415","0.00391"
"38.40000","3.20023","0.00373"
"38.59200","3.21614","0.00410"
"38.78400","3.23216","0.00350"
"38.97600","3.24819","0.00361"
"39.16800","3.26415","0.00408"
"39.36000","3.28017","0.00403"
"39.55200","3.29626","0.00346"
"39.74400","3.31210","0.00395"
"39.93600","3.32818","0.00342"
"40.12800","3.34427","0.00313"
"40.32000","3.36011","0.00361"
"40.51200","3.37620","0.00356"
"40.70400","3.39216","0.00392"
"40.89600","3.40812","0.00340"
"41.08800","3.42421","0.00376"
"41.28000","3.44023","0.00367"
"41.47200","3.45613","0.00371"
"41.66400","3.47216","0.00391"
"41.85600","3.48812","0.00310"
"42.04800","3.50420","0.00386"
"42.24000","3.52023","0.00330"
"42.43200","3.53613","0.00357"
"42.62400","3.55222","0.00363"
"42.81600","3.56818","0.00347"
"43.00800","3.58414","0.00344"
"43.20000","3.60023","0.00401"
"43.39200","3.61619","0.00371"
"43.58400","3.63215","0.00366"
"43.77600","3.64812","0.00355"
"43.96800","3.66414","0.00324"
"44.16000","3.68017","0.00351"
"44.35200","3.69619","0.00337"
"44.54400","3.71215","0.00319"
"44.73600","3.72818","0.00337"
"44.92800","3.74414","0.00386"
"45.12000","3.76016","0.00409"
"45.31200","3.77613","0.00387"
"45.50400","3.79215","0.00409"
"45.69600","3.80812","0.00350"
"45.88800","3.82426","0.00369"
"46.08000","3.84016","0.00367"
"46.27200","3.85613","0.00361"
"46.46400","3.87221","0.00397"
"46.65600","3.88817","0.00327"
"46.84800","3.90420","0.00349"
"47.04000","3.92022","0.00398"
"47.23200","3.93612","0.00373"
"47.42400","3.95221","0.00358"
"47.61600","3.96823","0.00374"
"47.80800","3.98414","0.00345"
"48.00000","4.00022","0.00392"
"48.19200","4.01618","0.00364"
"48.38400","4.03209","0.00378"
"48.57600","4.04817","0.00391"
"48.76800","4.06419","0.00377"
"48.96000","4.08010","0.00395"
"49.15200","4.09624","0.00364"
"49.34400","4.11220","0.00415"
"49.53600","4.12811","0.00382"
"49.72800","4.14419","0.00326"
"49.92000","4.16016","0.00391"
"50.11200","4.17618","0.00357"
"50.30400","4.19220","0.00326"
"50.49600","4.20817","0.00358"
"50.68800","4.22413","0.00393"
"50.88000","4.24027","0.00356"
"51.07200","4.25618","0.00338"
"51.26400","4.27220","0.00404"
"51.45600","4.28823","0.00389"
"51.64800","4.30413","0.00346"
"51.84000","4.32015","0.00420"
"52.03200","4.33618","0.00366"
"52.22400","4.35214","0.00383"
"52.41600","4.36816","0.00412"
"52.60800","4.38419","0.00365"
"52.80000","4.40015","0.00400"
"52.99200","4.41617","0.00409"
"53.18400","4.43220","0.00384"
"53.37600","4.44822","0.00359"
"53.56800","4.46419","0.00366"
"53.76000","4.48009","0.00366"
"53.95200","4.49623","0.00355"
"54.14400","4.51220","0.00335"
"54.33600","4.52816","0.00337"
"54.52800","4.54418","0.00400"
"54.72000","4.56015","0.00353"
"54.91200","4.57617","0.00370"
"55.10400","4.59219","0.00419"
"55.29600","4.60816","0.00382"
"55.48800","4.62418","0.00405"
"55.68000","4.64021","0.00351"
"55.87200","4.65611","0.00394"
"56.06400","4.67225","0.00413"
"56.25600","4.68822","0.00367"
"56.44800","4.70412","0.00359"
"56.64000","4.72026","0.00375"
"56.83200","4.73611","0.00382"
"57.02400","4.75213","0.00376"
"57.21600","4.76822","0.00436"
"57.40800","4.78418","0.00384"
"57.60000","4.80014","0.00464"
"57.79200","4.81617","0.00387"
"57.98400","4.83213","0.00386"
"58.17600","4.84821","0.00364"
"58.36800","4.86424","0.00364"
"58.56000","4.88014","0.00383"
"58.75200","4.89616","0.00389"
"58.94400","4.91219","0.00346"
"59.13600","4.92815","0.00323"
"59.32800","4.94418","0.00328"
"59.52000","4.96026","0.00364"
"59.71200","4.97610","0.00435"
"59.90400","4.99219","0.00439"
"60.09600","5.00815","0.00367"
"60.28800","5.02417","0.00406"
"60.48000","5.04020","0.00328"
"60.67200","5.05616","0.00361"
"60.86400","5.07219","0.00405"
"61.05600","5.08821","0.00373"
"61.24800","5.10417","0.00426"
"61.44000","5.12020","0.00443"
"61.63200","5.13622","0.00421"
"61.82400","5.15218","0.00356"
"62.01600","5.16821","0.00396"
"62.20800","5.18423","0.00359"
"62.40000","5.20014","0.00390"
"62.59200","5.21616","0.00378"
"62.78400","5.23218","0.00396"
"62.97600","5.24815","0.00391"
"63.16800","5.26417","0.00393"
"63.36000","5.28019","0.00415"
"63.55200","5.29622","0.00361"
"63.74400","5.31218","0.00345"
"63.93600","5.32814","0.00380"
"64.12800","5.34417","0.00308"
"64.32000","5.36019","0.00351"
"64.51200","5.37616","0.00336"
"64.70400","5.39224","0.00340"
"64.89600","5.40820","0.00325"
"65.08800","5.42411","0.00327"
"65.28000","5.44025","0.00382"
"65.47200","5.45621","0.00304"
"65.66400","5.47218","0.00430"
"65.85600","5.48820","0.00327"
"66.04800","5.50410","0.00297"
"66.24000","5.52025","0.00375"
"66.43200","5.53621","0.00340"
"66.62400","5.55218","0.00332"
"66.81600","5.56820","0.00426"
"67.00800","5.58416","0.00340"
"67.20000","5.60013","0.00379"
"67.39200","5.61621","0.00358"
"67.58400","5.63217","0.00400"
"67.77600","5.64814","0.00367"
"67.96800","5.66422","0.00387"
"68.16000","5.68013","0.00359"
"68.35200","5.69609","0.00404"
"68.54400","5.71223","0.00386"
"68.73600","5.72814","0.00411"
"68.92800","5.74416","0.00414"
"69.12000","5.76024","0.00396"
"69.31200","5.77615","0.00352"
"69.50400","5.79217","0.00377"
"69.69600","5.80825","0.00405"
"69.88800","5.82410","0.00426"
"70.08000","5.84018","0.00399"
"70.27200","5.85621","0.00396"
"70.46400","5.87217","0.00382"
"70.65600","5.88819","0.00343"
"70.84800","5.90416","0.00414"
"71.04000","5.92018","0.00371"
"71.23200","5.93614","0.00381"
"71.42400","5.95217","0.00356"
"71.61600","5.96819","0.00439"
"71.80800","5.98416","0.00399"
"72.00000","6.00012","0.00396"
"72.19200","6.01620","0.00385"
"72.38400","6.03217","0.00395"
"72.57600","6.04819","0.00384"
"72.76800","6.06421","0.00390"
"72.96000","6.08018","0.00352"
"73.15200","6.09614","0.00376"
"73.34400","6.11216","0.00421"
"73.53600","6.12819","0.00428"
"73.72800","6.14421","0.00361"
"73.92000","6.16017","0.00408"
"74.11200","6.17614","0.00352"
"74.30400","6.19216","0.00405"
"74.49600","6.20825","0.00389"
"74.68800","6.22415","0.00333"
"74.88000","6.24017","0.00312"
"75.07200","6.25620","0.00389"
"75.26400","6.27216","0.00361"
"75.45600","6.28824","0.00322"
"75.64800","6.30415","0.00387"
"75.84000","6.32017","0.00378"
"76.03200","6.33626","0.00328"
"76.22400","6.35216","0.00439"
"76.41600","6.36818","0.00374"
"76.60800","6.38415","0.00346"
"76.80000","6.40017","0.00365"
"76.99200","6.41619","0.00381"
"77.18400","6.43222","0.00327"
"77.37600","6.44812","0.00361"
"77.56800","6.46421","0.00353"
"77.76000","6.48023","0.00369"
"77.95200","6.49613","0.00400"
"78.14400","6.51222","0.00256"
"78.33600","6.52818","0.00293"
"78.52800","6.54408","0.00264"
"78.72000","6.56023","0.00287"
"78.91200","6.57619","0.00271"
"79.10400","6.59209","0.00261"
"79.29600","6.60824","0.00239"
"79.48800","6.62414","0.00231"
"79.68000","6.64017","0.00237"
"79.87200","6.65619","0.00265"
"80.06400","6.67215","0.00286"
"80.25600","6.68818","0.00274"
"80.44800","6.70420","0.00243"
"80.64000","6.72016","0.00290"
"80.83200","6.73619","0.00304"
"81.02400","6.75215","0.00247"
"81.21600","6.76812","0.00266"
"81.40800","6.78420","0.00264"
"81.60000","6.80022","0.00233"
"81.79200","6.81619","0.00244"
"81.98400","6.83215","0.00257"
"82.17600","6.84817","0.00282"
"82.36800","6.86420","0.00301"
"82.56000","6.88022","0.00203"
"82.75200","6.89612","0.00286"
"82.94400","6.91215","0.00232"
"83.13600","6.92817","0.00264"
"83.32800","6.94414","0.00256"
"83.52000","6.96022","0.00241"
"83.71200","6.97618","0.00267"
"83.90400","6.99215","0.00296"
"84.09600","7.00817","0.00264"
"84.28800","7.02413","0.00280"
"84.48000","7.04016","0.00259"
"84.67200","7.05618","0.00216"
"84.86400","7.07214","0.00210"
"85.05600","7.08817","0.00243"
"85.24800","7.10419","0.00249"
"85.44000","7.12016","0.00241"
"85.63200","7.13618","0.00206"
"85.82400","7.15220","0.00245"
"86.01600","7.16811","0.00275"
"86.20800","7.18419","0.00242"
"86.40000","7.20021","0.00256"
"86.59200","7.21618","0.00288"
"86.78400","7.23220","0.00263"
"86.97600","7.24817","0.00250"
"87.16800","7.26413","0.00238"
"87.36000","7.28021","0.00260"
"87.55200","7.29618","0.00251"
"87.74400","7.31220","0.00310"
"87.93600","7.32816","0.00249"
"88.12800","7.34413","0.00256"
"88.32000","7.36015","0.00263"
"88.51200","7.37624","0.00239"
"88.70400","7.39214","0.00270"
"88.89600","7.40822","0.00311"
"89.08800","7.42413","0.00312"
"89.28000","7.44009","0.00256"
"89.47200","7.45623","0.00240"
"89.66400","7.47214","0.00302"
"89.85600","7.48816","0.00309"
"90.04800","7.50418","0.00295"
"90.24000","7.52015","0.00278"
"90.43200","7.53617","0.00240"
"90.62400","7.55220","0.00275"
"90.81600","7.56816","0.00314"
"91.00800","7.58418","0.00260"
"91.20000","7.60015","0.00282"
"91.39200","7.61611","0.00278"
"91.58400","7.63219","0.00311"
"91.77600","7.64822","0.00307"
"91.96800","7.66412","0.00323"
"92.16000","7.68021","0.00311"
"92.35200","7.69623","0.00247"
"92.54400","7.71213","0.00273"
"92.73600","7.72816","0.00336"
"92.92800","7.74424","0.00259"
"93.12000","7.76014","0.00320"
"93.31200","7.77623","0.00331"
"93.50400","7.79219","0.00325"
"93.69600","7.80816","0.00303"
"93.88800","7.82418","0.00308"
"94.08000","7.84014","0.00315"
"94.27200","7.85616","0.00335"
"94.46400","7.87219","0.00270"
"94.65600","7.88815","0.00299"
"94.84800","7.90418","0.00327"
"95.04000","7.92020","0.00320"
"95.23200","7.93616","0.00250"
"95.42400","7.95219","0.00290"
"95.61600","7.96815","0.00294"
"95.80800","7.98417","0.00368"
"96.00000","8.00014","0.00278"
"96.19200","8.01616","0.00341"
"96.38400","8.03213","0.00309"
"96.57600","8.04815","0.00288"
"96.76800","8.06417","0.00244"
"96.96000","8.08026","0.00355"
"97.15200","8.09622","0.00294"
"97.34400","8.11218","0.00259"
"97.53600","8.12821","0.00327"
"97.72800","8.14417","0.00291"
"97.92000","8.16013","0.00225"
"98.11200","8.17622","0.00341"
"98.30400","8.19212","0.00238"
"98.49600","8.20815","0.00271"
"98.68800","8.22417","0.00247"
"98.88000","8.24019","0.00278"
"99.07200","8.25616","0.00338"
"99.26400","8.27224","0.00311"
"99.45600","8.28814","0.00298"
"99.64800","8.30417","0.00301"
"99.84000","8.32019","0.00292"
"100.03200","8.33616","0.00278"
"100.22400","8.35218","0.00267"
"100.41600","8.36820","0.00327"
"100.60800","8.38411","0.00296"
"100.80000","8.40025","0.00295"
"100.99200","8.41615","0.00313"
"101.18400","8.43212","0.00272"
"101.37600","8.44820","0.00356"
"101.56800","8.46416","0.00245"
"101.76000","8.48019","0.00341"
"101.95200","8.49621","0.00309"
"102.14400","8.51218","0.00326"
"102.33600","8.52814","0.00272"
"102.52800","8.54422","0.00315"
"102.72000","8.56013","0.00322"
"102.91200","8.57621","0.00297"
"103.10400","8.59223","0.00305"
"103.29600","8.60814","0.00365"
"103.48800","8.62416","0.00346"
"103.68000","8.64019","0.00288"
"103.87200","8.65615","0.00329"
"104.06400","8.67211","0.00315"
"104.25600","8.68820","0.00341"
"104.44800","8.70416","0.00327"
"104.64000","8.72012","0.00389"
"104.83200","8.73621","0.00332"
"105.02400","8.75217","0.00313"
"105.21600","8.76819","0.00266"
"105.40800","8.78416","0.00317"
"105.60000","8.80018","0.00379"
"105.79200","8.81615","0.00259"
"105.98400","8.83217","0.00348"
"106.17600","8.84819","0.00395"
"106.36800","8.86416","0.00396"
"106.56000","8.88018","0.00340"
"106.75200","8.89620","0.00354"
"106.94400","8.91217","0.00378"
"107.13600","8.92819","0.00345"
"107.32800","8.94416","0.00364"
"107.52000","8.96012","0.00339"
"107.71200","8.97626","0.00349"
"107.90400","8.99217","0.00354"
"108.09600","9.00813","0.00377"
"108.28800","9.02427","0.00303"
"108.48000","9.04018","0.00343"
"108.67200","9.05608","0.00373"
"108.86400","9.07222","0.00384"
"109.05600","9.08819","0.00315"
"109.24800","9.10415","0.00372"
"109.44000","9.12018","0.00339"
"109.63200","9.13614","0.00351"
"109.82400","9.15216","0.00327"
"110.01600","9.16825","0.00346"
"110.20800","9.18415","0.00345"
"110.40000","9.20017","0.00300"
"110.59200","9.21620","0.00354"
"110.78400","9.23216","0.00331"
"110.97600","9.24819","0.00372"
"111.16800","9.26421","0.00374"
"111.36000","9.28011","0.00362"
"111.55200","9.29620","0.00365"
"111.74400","9.31222","0.00365"
"111.93600","9.32812","0.00379"
"112.12800","9.34421","0.00396"
"112.32000","9.36017","0.00323"
"112.51200","9.37613","0.00399"
"112.70400","9.39222","0.00325"
"112.89600","9.40818","0.00402"
"113.08800","9.42421","0.00394"
"113.28000","9.44017","0.00354"
"113.47200","9.45619","0.00389"
"113.66400","9.47216","0.00428"
"113.85600","9.48818","0.00355"
"114.04800","9.50414","0.00406"
"114.24000","9.52017","0.00389"
"114.43200","9.53619","0.00366"
"114.62400","9.55216","0.00417"
"114.81600","9.56818","0.00346"
"115.00800","9.58414","0.00384"
"115.20000","9.60017","0.00408"
"115.39200","9.61613","0.00401"
"115.58400","9.63215","0.00421"
"115.77600","9.64818","0.00423"
"115.96800","9.66420","0.00412"
"116.16000","9.68017","0.00422"
"116.35200","9.69625","0.00361"
"116.54400","9.71221","0.00403"
"116.73600","9.72812","0.00346"
"116.92800","9.74426","0.00399"
"117.12000","9.76010","0.00381"
"117.31200","9.77613","0.00414"
"117.50400","9.79221","0.00362"
"117.69600","9.80811","0.00395"
"117.88800","9.82420","0.00419"
"118.08000","9.84022","0.00415"
"118.27200","9.85618","0.00428"
"118.46400","9.87221","0.00445"
"118.65600","9.88817","0.00412"
"118.84800","9.90414","0.00462"
"119.04000","9.92022","0.00472"
"119.23200","9.93618","0.00433"
"119.42400","9.95209","0.00543"
"119.61600","9.96823","0.00436"
"119.80800","9.98419","0.00415"
"120.00000","10.00010","0.00418"
"120.19200","10.01624","0.00379"
"120.38400","10.03215","0.00401"
"120.57600","10.04811","0.00434"
"120.76800","10.06425","0.00434"
"120.96000","10.08016","0.00460"
"121.15200","10.09618","0.00473"
"121.34400","10.11220","0.00457"
"121.53600","10.12811","0.00434"
"121.72800","10.14419","0.00406"
"121.92000","10.16015","0.00440"
"122.11200","10.17612","0.00458"
"122.30400","10.19220","0.00429"
"122.49600","10.20817","0.00463"
"122.68800","10.22419","0.00444"
"122.88000","10.24021","0.00486"
"123.07200","10.25618","0.00416"
"123.26400","10.27214","0.00441"
"123.45600","10.28816","0.00478"
"123.64800","10.30419","0.00404"
"123.84000","10.32015","0.00433"
"124.03200","10.33618","0.00371"
"124.22400","10.35214","0.00399"
"124.41600","10.36816","0.00411"
"124.60800","10.38419","0.00469"
"124.80000","10.40015","0.00398"
"124.99200","10.41623","0.00415"
"125.18400","10.43220","0.00415"
"125.37600","10.44816","0.00479"
"125.56800","10.46418","0.00459"
"125.76000","10.48021","0.00434"
"125.95200","10.49617","0.00475"
"126.14400","10.51220","0.00426"
"126.33600","10.52816","0.00425"
"126.52800","10.54418","0.00476"
"126.72000","10.56015","0.00407"
"126.91200","10.57617","0.00434"
"127.10400","10.59219","0.00451"
"127.29600","10.60822","0.00455"
"127.48800","10.62412","0.00501"
"127.68000","10.64027","0.00432"
"127.87200","10.65617","0.00481"
"128.06400","10.67219","0.00454"
"128.25600","10.68822","0.00469"
"128.44800","10.70412","0.00521"
"128.64000","10.72020","0.00454"
"128.83200","10.73623","0.00470"
"129.02400","10.75213","0.00463"
"129.21600","10.76821","0.00464"
"129.40800","10.78418","0.00511"
"129.60000","10.80020","0.00489"
"129.79200","10.81617","0.00494"
"129.98400","10.83225","0.00489"
"130.17600","10.84809","0.00522"
"130.36800","10.86424","0.00484"
"130.56000","10.88020","0.00505"
"130.75200","10.89610","0.00451"
"130.94400","10.91219","0.00442"
"131.13600","10.92815","0.00523"
"131.32800","10.94412","0.00590"
"131.52000","10.96020","0.00533"
"131.71200","10.97616","0.00482"
"131.90400","10.99219","0.00535"
"132.09600","11.00821","0.00525"
"132.28800","11.02417","0.00518"
"132.48000","11.04020","0.00495"
"132.67200","11.05622","0.00503"
"132.86400","11.07213","0.00490"
"133.05600","11.08821","0.00524"
"133.24800","11.10423","0.00505"
"133.44000","11.12014","0.00582"
"133.63200","11.13622","0.00526"
"133.82400","11.15218","0.00518"
"134.01600","11.16821","0.00523"
"134.20800","11.18417","0.00491"
"134.40000","11.20013","0.00506"
"134.59200","11.21616","0.00543"
"134.78400","11.23218","0.00495"
"134.97600","11.24815","0.00563"
"135.16800","11.26423","0.00549"
"135.36000","11.28019","0.00534"
"135.55200","11.29616","0.00560"
"135.74400","11.31224","0.00563"
"135.93600","11.32814","0.00574"
"136.12800","11.34423","0.00595"
"136.32000","11.36019","0.00571"
"136.51200","11.37615","0.00578"
"136.70400","11.39218","0.00512"
"136.89600","11.40820","0.00609"
"137.08800","11.42417","0.00568"
"137.28000","11.44019","0.00545"
"137.47200","11.45621","0.00617"
"137.66400","11.47218","0.00549"
"137.85600","11.48820","0.00649"
"138.04800","11.50422","0.00517"
"138.24000","11.52013","0.00590"
"138.43200","11.53621","0.00552"
"138.62400","11.55218","0.00587"
"138.81600","11.56808","0.00563"
"139.00800","11.58422","0.00588"
"139.20000","11.60019","0.00594"
"139.39200","11.61615","0.00665"
"139.58400","11.63217","0.00579"
"139.77600","11.64814","0.00638"
"139.96800","11.66416","0.00579"
"140.16000","11.68018","0.00655"
"140.35200","11.69615","0.00576"
"140.54400","11.71217","0.00643"
"140.73600","11.72820","0.00656"
"140.92800","11.74410","0.00632"
"141.12000","11.76018","0.00610"
"141.31200","11.77615","0.00615"
"141.50400","11.79211","0.00604"
"141.69600","11.80819","0.00647"
"141.88800","11.82416","0.00654"
"142.08000","11.84012","0.00612"
"142.27200","11.85620","0.00664"
"142.46400","11.87217","0.00655"
"142.65600","11.88819","0.00613"
"142.84800","11.90422","0.00629"
"143.04000","11.92018","0.00634"
"143.23200","11.93620","0.00638"
"143.42400","11.95223","0.00677"
"143.61600","11.96819","0.00642"
"143.80800","11.98415","0.00645"
"144.00000","12.00024","0.00677"
"144.19200","12.01614","0.00705"
"144.38400","12.03217","0.00681"
"144.57600","12.04819","0.00652"
"144.76800","12.06415","0.00670"
"144.96000","12.08018","0.00585"
"145.15200","12.09614","0.00682"
"145.34400","12.11216","0.00652"
"145.53600","12.12819","0.00690"
"145.72800","12.14415","0.00609"
"145.92000","12.16018","0.00693"
"146.11200","12.17620","0.00630"
"146.30400","12.19216","0.00666"
"146.49600","12.20819","0.00640"
"146.68800","12.22421","0.00692"
"146.88000","12.24011","0.00616"
"147.07200","12.25620","0.00664"
"147.26400","12.27216","0.00674"
"147.45600","12.28819","0.00701"
"147.64800","12.30415","0.00680"
"147.84000","12.32017","0.00640"
"148.03200","12.33619","0.00674"
"148.22400","12.35222","0.00700"
"148.41600","12.36818","0.00667"
"148.60800","12.38421","0.00720"
"148.80000","12.40017","0.00699"
"148.99200","12.41613","0.00665"
"149.18400","12.43222","0.00676"
"149.37600","12.44818","0.00640"
"149.56800","12.46409","0.00664"
"149.76000","12.48023","0.00635"
"149.95200","12.49613","0.00723"
"150.14400","12.51210","0.00647"
"150.33600","12.52818","0.00631"
"150.52800","12.54414","0.00660"
"150.72000","12.56017","0.00692"
"150.91200","12.57619","0.00676"
"151.10400","12.59215","0.00729"
"151.29600","12.60818","0.00701"
"151.48800","12.62420","0.00689"
"151.68000","12.64011","0.00689"
"151.87200","12.65619","0.00708"
"152.06400","12.67221","0.00682"
"152.25600","12.68806","0.00674"
"152.44800","12.70420","0.00683"
"152.64000","12.72022","0.00687"
"152.83200","12.73613","0.00654"
"153.02400","12.75221","0.00658"
"153.21600","12.76817","0.00674"
"153.40800","12.78414","0.00627"
"153.60000","12.80016","0.00717"
"153.79200","12.81613","0.00680"
"153.98400","12.83215","0.00681"
"154.17600","12.84823","0.00685"
"154.36800","12.86414","0.00727"
"154.56000","12.88022","0.00732"
"154.75200","12.89624","0.00640"
"154.94400","12.91215","0.00682"
"155.13600","12.92817","0.00749"
"155.32800","12.94420","0.00722"
"155.52000","12.96016","0.00709"
"155.71200","12.97612","0.00728"
"155.90400","12.99221","0.00720"
"156.09600","13.00817","0.00714"
"156.28800","13.02413","0.00705"
"156.48000","13.04016","0.00730"
"156.67200","13.05612","0.00663"
"156.86400","13.07215","0.00690"
"157.05600","13.08817","0.00669"
"157.24800","13.10419","0.00735"
"157.44000","13.12016","0.00774"
"157.63200","13.13618","0.00731"
"157.82400","13.15220","0.00741"
"158.01600","13.16817","0.00725"
"158.20800","13.18419","0.00776"
"158.40000","13.20015","0.00705"
"158.59200","13.21612","0.00719"
"158.78400","13.23214","0.00723"
"158.97600","13.24817","0.00781"
"159.16800","13.26413","0.00760"
"159.36000","13.28021","0.00730"
"159.55200","13.29618","0.00757"
"159.74400","13.31214","0.00787"
"159.93600","13.32822","0.00749"
"160.12800","13.34413","0.00769"
"160.32000","13.36009","0.00740"
"160.51200","13.37623","0.00757"
"160.70400","13.39220","0.00769"
"160.89600","13.40810","0.00711"
"161.08800","13.42425","0.00774"
"161.28000","13.44015","0.00766"
"161.47200","13.45617","0.00755"
"161.66400","13.47226","0.00752"
"161.85600","13.48816","0.00741"
"162.04800","13.50418","0.00787"
"162.24000","13.52021","0.00780"
"162.43200","13.53617","0.00763"
"162.62400","13.55220","0.00754"
"162.81600","13.56822","0.00768"
"163.00800","13.58412","0.00740"
"163.20000","13.60021","0.00782"
"163.39200","13.61623","0.00822"
"163.58400","13.63219","0.00810"
"163.77600","13.64816","0.00797"
"163.96800","13.66418","0.00772"
"164.16000","13.68015","0.00817"
"164.35200","13.69617","0.00854"
"164.54400","13.71213","0.00819"
"164.73600","13.72816","0.00800"
"164.92800","13.74418","0.00779"
"165.12000","13.76014","0.00752"
"165.31200","13.77617","0.00744"
"165.50400","13.79219","0.00816"
"165.69600","13.80815","0.00824"
"165.88800","13.82424","0.00786"
"166.08000","13.84014","0.00720"
"166.27200","13.85616","0.00795"
"166.46400","13.87219","0.00791"
"166.65600","13.88815","0.00787"
"166.84800","13.90418","0.00796"
"167.04000","13.92020","0.00756"
"167.23200","13.93616","0.00768"
"167.42400","13.95219","0.00728"
"167.61600","13.96821","0.00749"
"167.80800","13.98411","0.00754"
"168.00000","14.00026","0.00773"
"168.19200","14.01616","0.00701"
"168.38400","14.03213","0.00779"
"168.57600","14.04821","0.00720"
"168.76800","14.06417","0.00696"
"168.96000","14.08014","0.00676"
"169.15200","14.09622","0.00652"
"169.34400","14.11212","0.00735"
"169.53600","14.12815","0.00694"
"169.72800","14.14417","0.00697"
"169.92000","14.16020","0.00745"
"170.11200","14.17616","0.00703"
"170.30400","14.19218","0.00686"
"170.49600","14.20815","0.00702"
"170.68800","14.22423","0.00714"
"170.88000","14.24019","0.00732"
"171.07200","14.25610","0.00704"
"171.26400","14.27218","0.00717"
"171.45600","14.28820","0.00737"
"171.64800","14.30411","0.00720"
"171.84000","14.32019","0.00694"
"172.03200","14.33622","0.00691"
"172.22400","14.35212","0.00695"
"172.41600","14.36820","0.00676"
"172.60800","14.38423","0.00689"
"172.80000","14.40013","0.00654"
"172.99200","14.41621","0.00723"
"173.18400","14.43212","0.00715"
"173.37600","14.44820","0.00707"
"173.56800","14.46416","0.00684"
"173.76000","14.48013","0.00733"
"173.95200","14.49615","0.00624"
"174.14400","14.51218","0.00692"
"174.33600","14.52814","0.00641"
"174.52800","14.54416","0.00593"
"174.72000","14.56019","0.00627"
"174.91200","14.57615","0.00610"
"175.10400","14.59217","0.00607"
"175.29600","14.60814","0.00607"
"175.48800","14.62416","0.00668"
"175.68000","14.64013","0.00587"
"175.87200","14.65615","0.00589"
"176.06400","14.67217","0.00611"
"176.25600","14.68814","0.00594"
"176.44800","14.70416","0.00623"
"176.64000","14.72018","0.00664"
"176.83200","14.73615","0.00658"
"177.02400","14.75217","0.00617"
"177.21600","14.76820","0.00616"
"177.40800","14.78416","0.00690"
"177.60000","14.80018","0.00663"
"177.79200","14.81621","0.00674"
"177.98400","14.83217","0.00650"
"178.17600","14.84819","0.00662"
"178.36800","14.86422","0.00660"
"178.56000","14.88012","0.00726"
"178.75200","14.89620","0.00651"
"178.94400","14.91223","0.00685"
"179.13600","14.92813","0.00679"
"179.32800","14.94416","0.00644"
"179.52000","14.96018","0.00691"
"179.71200","14.97614","0.00648"
"179.90400","14.99223","0.00674"
"180.09600","15.00813","0.00637"
"180.28800","15.02415","0.00610"
"180.48000","15.04024","0.00654"
"180.67200","15.05614","0.00696"
"180.86400","15.07217","0.00681"
"181.05600","15.08819","0.00648"
"181.24800","15.10409","0.00666"
"181.44000","15.12018","0.00714"
"181.63200","15.13620","0.00690"
"181.82400","15.15210","0.00664"
"182.01600","15.16825","0.00697"
"182.20800","15.18421","0.00681"
"182.40000","15.20012","0.00660"
"182.59200","15.21620","0.00638"
"182.78400","15.23216","0.00654"
"182.97600","15.24819","0.00673"
"183.16800","15.26421","0.00654"
"183.36000","15.28017","0.00698"
"183.55200","15.29620","0.00679"
"183.74400","15.31216","0.00687"
"183.93600","15.32812","0.00658"
"184.12800","15.34415","0.00663"
"184.32000","15.36023","0.00647"
"184.51200","15.37613","0.00600"
"184.70400","15.39216","0.00642"
"184.89600","15.40824","0.00658"
"185.08800","15.42415","0.00649"
"185.28000","15.44017","0.00617"
"185.47200","15.45619","0.00591"
"185.66400","15.47216","0.00628"
"185.85600","15.48818","0.00686"
"186.04800","15.50420","0.00665"
"186.24000","15.52017","0.00647"
"186.43200","15.53625","0.00644"
"186.62400","15.55216","0.00712"
"186.81600","15.56818","0.00619"
"187.00800","15.58420","0.00645"
"187.20000","15.60011","0.00638"
"187.39200","15.61625","0.00629"
"187.58400","15.63215","0.00602"
"187.77600","15.64818","0.00674"
"187.96800","15.66420","0.00642"
"188.16000","15.68016","0.00648"
"188.35200","15.69619","0.00627"
"188.54400","15.71221","0.00719"
"188.73600","15.72811","0.00642"
"188.92800","15.74420","0.00615"
"189.12000","15.76022","0.00698"
"189.31200","15.77613","0.00613"
"189.50400","15.79221","0.00696"
"189.69600","15.80823","0.00644"
"189.88800","15.82414","0.00656"
"190.08000","15.84016","0.00660"
"190.27200","15.85618","0.00648"
"190.46400","15.87209","0.00662"
"190.65600","15.88817","0.00605"
"190.84800","15.90420","0.00669"
"191.04000","15.92016","0.00659"
"191.23200","15.93624","0.00591"
"191.42400","15.95215","0.00622"
"191.61600","15.96817","0.00653"
"191.80800","15.98419","0.00639"
"192.00000","16.00016","0.00661"
"192.19200","16.01618","0.00642"
"192.38400","16.03220","0.00670"
"192.57600","16.04817","0.00624"
"192.76800","16.06419","0.00607"
"192.96000","16.08022","0.00602"
"193.15200","16.09612","0.00620"
"193.34400","16.11220","0.00695"
"193.53600","16.12823","0.00610"
"193.72800","16.14413","0.00663"
"193.92000","16.16021","0.00684"
"194.11200","16.17618","0.00644"
"194.30400","16.19220","0.00676"
"194.49600","16.20816","0.00643"
"194.68800","16.22413","0.00661"
"194.88000","16.24021","0.00647"
"195.07200","16.25624","0.00687"
"195.26400","16.27214","0.00634"
"195.45600","16.28822","0.00620"
"195.64800","16.30419","0.00673"
"195.84000","16.32015","0.00617"
"196.03200","16.33624","0.00598"
"196.22400","16.35220","0.00644"
"196.41600","16.36816","0.00621"
"196.60800","16.38418","0.00676"
"196.80000","16.40015","0.00576"
"196.99200","16.41617","0.00647"
"197.18400","16.43214","0.00667"
"197.37600","16.44816","0.00610"
"197.56800","16.46418","0.00629"
"197.76000","16.48021","0.00595"
"197.95200","16.49617","0.00674"
"198.14400","16.51220","0.00615"
"198.33600","16.52822","0.00640"
"198.52800","16.54412","0.00661"
"198.72000","16.56021","0.00643"
"198.91200","16.57617","0.00648"
"199.10400","16.59219","0.00558"
"199.29600","16.60822","0.00612"
"199.48800","16.62418","0.00617"
"199.68000","16.64021","0.00668"
"199.87200","16.65623","0.00604"
"200.06400","16.67219","0.00665"
"200.25600","16.68822","0.00656"
"200.44800","16.70424","0.00628"
"200.64000","16.72014","0.00633"
"200.83200","16.73623","0.00629"
"201.02400","16.75219","0.00652"
"201.21600","16.76810","0.00641"
"201.40800","16.78424","0.00610"
"201.60000","16.80014","0.00642"
"201.79200","16.81617","0.00618"
"201.98400","16.83219","0.00617"
"202.17600","16.84815","0.00633"
"202.36800","16.86418","0.00659"
"202.56000","16.88020","0.00635"
"202.75200","16.89610","0.00646"
"202.94400","16.91219","0.00668"
"203.13600","16.92821","0.00625"
"203.32800","16.94411","0.00578"
"203.52000","16.96020","0.00629"
"203.71200","16.97622","0.00663"
"203.90400","16.99213","0.00563"
"204.09600","17.00821","0.00602"
"204.28800","17.02423","0.00568"
"204.48000","17.04008","0.00685"
"204.67200","17.05622","0.00630"
"204.86400","17.07224","0.00583"
"205.05600","17.08809","0.00670"
"205.24800","17.10417","0.00636"
"205.44000","17.12019","0.00604"
"205.63200","17.13616","0.00659"
"205.82400","17.15218","0.00587"
"206.01600","17.16815","0.00634"
"206.20800","17.18417","0.00653"
"206.40000","17.20019","0.00597"
"206.59200","17.21616","0.00637"
"206.78400","17.23218","0.00671"
"206.97600","17.24814","0.00603"
"207.16800","17.26417","0.00592"
"207.36000","17.28019","0.00611"
"207.55200","17.29616","0.00626"
"207.74400","17.31218","0.00677"
"207.93600","17.32820","0.00631"
"208.12800","17.34417","0.00597"
"208.32000","17.36019","0.00659"
"208.51200","17.37615","0.00560"
"208.70400","17.39218","0.00604"
"208.89600","17.40820","0.00608"
"209.08800","17.42416","0.00620"
"209.28000","17.44013","0.00649"
"209.47200","17.45621","0.00610"
"209.66400","17.47212","0.00635"
"209.85600","17.48814","0.00625"
"210.04800","17.50422","0.00575"
"210.24000","17.52013","0.00556"
"210.43200","17.53621","0.00578"
"210.62400","17.55223","0.00601"
"210.81600","17.56814","0.00557"
"211.00800","17.58422","0.00485"
"211.20000","17.60018","0.00561"
"211.39200","17.61615","0.00565"
"211.58400","17.63223","0.00604"
"211.77600","17.64820","0.00557"
"211.96800","17.66410","0.00535"
"212.16000","17.68024","0.00540"
"212.35200","17.69621","0.00566"
"212.54400","17.71211","0.00506"
"212.73600","17.72825","0.00588"
"212.92800","17.74416","0.00588"
"213.12000","17.76012","0.00588"
"213.31200","17.77627","0.00575"
"213.50400","17.79211","0.00614"
"213.69600","17.80813","0.00603"
"213.88800","17.82421","0.00615"
"214.08000","17.84012","0.00539"
"214.27200","17.85614","0.00596"
"214.46400","17.87223","0.00611"
"214.65600","17.88813","0.00610"
"214.84800","17.90421","0.00611"
"215.04000","17.92018","0.00553"
"215.23200","17.93614","0.00571"
"215.42400","17.95217","0.00631"
"215.61600","17.96819","0.00620"
"215.80800","17.98415","0.00600"
"216.00000","18.00012","0.00605"
"216.19200","18.01620","0.00618"
"216.38400","18.03217","0.00537"
"216.57600","18.04819","0.00656"
"216.76800","18.06421","0.00560"
"216.96000","18.08018","0.00538"
"217.15200","18.09614","0.00631"
"217.34400","18.11216","0.00614"
"217.53600","18.12819","0.00582"
"217.72800","18.14415","0.00584"
"217.92000","18.16017","0.00593"
"218.11200","18.17620","0.00586"
"218.30400","18.19216","0.00580"
"218.49600","18.20819","0.00547"
"218.68800","18.22421","0.00607"
"218.88000","18.24011","0.00590"
"219.07200","18.25614","0.00576"
"219.26400","18.27222","0.00639"
"219.45600","18.28812","0.00624"
"219.64800","18.30421","0.00624"
"219.84000","18.32017","0.00596"
"220.03200","18.33613","0.00638"
"220.22400","18.35228","0.00627"
"220.41600","18.36812","0.00586"
"220.60800","18.38409","0.00622"
"220.80000","18.40023","0.00647"
"220.99200","18.41613","0.00571"
"221.18400","18.43216","0.00596"
"221.37600","18.44824","0.00568"
"221.56800","18.46414","0.00543"
"221.76000","18.48017","0.00578"
"221.95200","18.49619","0.00635"
"222.14400","18.51215","0.00583"
"222.33600","18.52818","0.00584"
"222.52800","18.54420","0.00535"
"222.72000","18.56017","0.00565"
"222.91200","18.57619","0.00555"
"223.10400","18.59221","0.00589"
"223.29600","18.60812","0.00544"
"223.48800","18.62420","0.00593"
"223.68000","18.64016","0.00557"
"223.87200","18.65613","0.00542"
"224.06400","18.67221","0.00606"
"224.25600","18.68818","0.00582"
"224.44800","18.70414","0.00560"
"224.64000","18.72022","0.00535"
"224.83200","18.73613","0.00596"
"225.02400","18.75221","0.00574"
"225.21600","18.76823","0.00591"
"225.40800","18.78414","0.00575"
"225.60000","18.80016","0.00586"
"225.79200","18.81618","0.00597"
"225.98400","18.83209","0.00599"
"226.17600","18.84817","0.00559"
"226.36800","18.86414","0.00588"
"226.56000","18.88016","0.00574"
"226.75200","18.89618","0.00567"
"226.94400","18.91215","0.00644"
"227.13600","18.92817","0.00543"
"227.32800","18.94414","0.00632"
"227.52000","18.96016","0.00611"
"227.71200","18.97618","0.00583"
"227.90400","18.99220","0.00642"
"228.09600","19.00817","0.00599"
"228.28800","19.02425","0.00626"
"228.48000","19.04016","0.00608"
"228.67200","19.05612","0.00588"
"228.86400","19.07220","0.00588"
"229.05600","19.08811","0.00584"
"229.24800","19.10419","0.00555"
"229.44000","19.12021","0.00596"
"229.63200","19.13612","0.00564"
"229.82400","19.15220","0.00631"
"230.01600","19.16823","0.00619"
"230.20800","19.18413","0.00576"
"230.40000","19.20021","0.00581"
"230.59200","19.21618","0.00580"
"230.78400","19.23214","0.00617"
"230.97600","19.24822","0.00571"
"231.16800","19.26419","0.00583"
"231.36000","19.28015","0.00614"
"231.55200","19.29623","0.00598"
"231.74400","19.31214","0.00566"
"231.93600","19.32816","0.00676"
"232.12800","19.34419","0.00583"
"232.32000","19.36015","0.00575"
"232.51200","19.37617","0.00618"
"232.70400","19.39226","0.00598"
"232.89600","19.40816","0.00632"
"233.08800","19.42418","0.00580"
"233.28000","19.44021","0.00618"
"233.47200","19.45611","0.00607"
"233.66400","19.47219","0.00585"
"233.85600","19.48822","0.00610"
"234.04800","19.50412","0.00599"
"234.24000","19.52021","0.00627"
"234.43200","19.53617","0.00624"
"234.62400","19.55213","0.00604"
"234.81600","19.56816","0.00615"
"235.00800","19.58418","0.00634"
"235.20000","19.60015","0.00624"
"235.39200","19.61617","0.00611"
"235.58400","19.63213","0.00646"
"235.77600","19.64822","0.00670"
"235.96800","19.66418","0.00615"
"236.16000","19.68014","0.00602"
"236.35200","19.69617","0.00683"
"236.54400","19.71219","0.00659"
"236.73600","19.72809","0.00682"
"236.92800","19.74418","0.00608"
"237.12000","19.76020","0.00608"
"237.31200","19.77617","0.00663"
"237.50400","19.79213","0.00667"
"237.69600","19.80815","0.00644"
"237.88800","19.82418","0.00635"
"238.08000","19.84020","0.00582"
"238.27200","19.85616","0.00678"
"238.46400","19.87219","0.00688"
"238.65600","19.88815","0.00671"
"238.84800","19.90411","0.00653"
"239.04000","19.92020","0.00667"
"239.23200","19.93616","0.00729"
"239.42400","19.95213","0.00649"
"239.61600","19.96821","0.00693"
"239.80800","19.98417","0.00647"
"240.00000","20.00014","0.00692"
"240.19200","20.01616","0.00667"
"240.38400","20.03213","0.00646"
"240.57600","20.04821","0.00680"
"240.76800","20.06423","0.00670"
"240.96000","20.08014","0.00670"
"241.15200","20.09622","0.00747"
"241.34400","20.11218","0.00687"
"241.53600","20.12809","0.00703"
"241.72800","20.14423","0.00624"
"241.92000","20.16019","0.00605"
"242.11200","20.17610","0.00647"
"242.30400","20.19224","0.00674"
"242.49600","20.20820","0.00616"
"242.68800","20.22411","0.00652"
"242.88000","20.24025","0.00672"
"243.07200","20.25616","0.00676"
"243.26400","20.27218","0.00701"
"243.45600","20.28820","0.00695"
"243.64800","20.30416","0.00716"
"243.84000","20.32019","0.00675"
"244.03200","20.33621","0.00670"
"244.22400","20.35212","0.00740"
"244.41600","20.36820","0.00671"
"244.60800","20.38423","0.00665"
"244.80000","20.40013","0.00672"
"244.99200","20.41621","0.00686"
"245.18400","20.43223","0.00700"
"245.37600","20.44814","0.00684"
"245.56800","20.46416","0.00635"
"245.76000","20.48019","0.00654"
"245.95200","20.49615","0.00705"
"246.14400","20.51217","0.00703"
"246.33600","20.52814","0.00644"
"246.52800","20.54422","0.00709"
"246.72000","20.56019","0.00647"
"246.91200","20.57615","0.00662"
"247.10400","20.59223","0.00663"
"247.29600","20.60820","0.00660"
"247.48800","20.62410","0.00647"
"247.68000","20.64024","0.00664"
"247.87200","20.65615","0.00702"
"248.06400","20.67217","0.00667"
"248.25600","20.68819","0.00688"
"248.44800","20.70416","0.00679"
"248.64000","20.72018","0.00680"
"248.83200","20.73621","0.00730"
"249.02400","20.75217","0.00677"
"249.21600","20.76819","0.00748"
"249.40800","20.78416","0.00728"
"249.60000","20.80012","0.00709"
"249.79200","20.81621","0.00686"
"249.98400","20.83217","0.00682"
"250.17600","20.84813","0.00708"
"250.36800","20.86421","0.00729"
"250.56000","20.88018","0.00748"
"250.75200","20.89614","0.00726"
"250.94400","20.91217","0.00708"
"251.13600","20.92819","0.00731"
"251.32800","20.94415","0.00704"
"251.52000","20.96018","0.00773"
"251.71200","20.97620","0.00737"
"251.90400","20.99216","0.00729"
"252.09600","21.00819","0.00695"
"252.28800","21.02415","0.00707"
"252.48000","21.04024","0.00692"
"252.67200","21.05614","0.00714"
"252.86400","21.07211","0.00731"
"253.05600","21.08825","0.00678"
"253.24800","21.10415","0.00673"
"253.44000","21.12011","0.00722"
"253.63200","21.13626","0.00719"
"253.82400","21.15216","0.00737"
"254.01600","21.16813","0.00692"
"254.20800","21.18421","0.00733"
"254.40000","21.20017","0.00716"
"254.59200","21.21620","0.00704"
"254.78400","21.23222","0.00718"
"254.97600","21.24813","0.00701"
"255.16800","21.26421","0.00728"
"255.36000","21.28023","0.00708"
"255.55200","21.29614","0.00681"
"255.74400","21.31222","0.00648"
"255.93600","21.32824","0.00710"
"256.12800","21.34409","0.00660"
"256.32000","21.36017","0.00662"
"256.51200","21.37619","0.00666"
"256.70400","21.39215","0.00706"
"256.89600","21.40818","0.00709"
"257.08800","21.42420","0.00703"
"257.28000","21.44017","0.00759"
"257.47200","21.45619","0.00726"
"257.66400","21.47216","0.00725"
"257.85600","21.48824","0.00663"
"258.04800","21.50414","0.00683"
"258.24000","21.52017","0.00749"
"258.43200","21.53619","0.00675"
"258.62400","21.55215","0.00710"
"258.81600","21.56812","0.00694"
"259.00800","21.58414","0.00737"
"259.20000","21.60016","0.00713"
"259.39200","21.61619","0.00701"
"259.58400","21.63221","0.00709"
"259.77600","21.64818","0.00768"
"259.96800","21.66420","0.00671"
"260.16000","21.68016","0.00719"
"260.35200","21.69619","0.00733"
"260.54400","21.71221","0.00688"
"260.73600","21.72823","0.00720"
"260.92800","21.74414","0.00681"
"261.12000","21.76028","0.00721"
"261.31200","21.77612","0.00756"
"261.50400","21.79215","0.00744"
"261.69600","21.80823","0.00746"
"261.88800","21.82414","0.00726"
"262.08000","21.84016","0.00614"
"262.27200","21.85618","0.00695"
"262.46400","21.87209","0.00667"
"262.65600","21.88823","0.00321"
"262.84800","21.90419","0.00585"
"263.04000","21.92016","0.00536"
"263.23200","21.93624","0.00475"
"263.42400","21.95221","0.00611"
"263.61600","21.96811","0.00428"
"263.80800","21.98425","0.00565"
"264.00000","22.00022","0.00602"
"264.19200","22.01612","0.00989"
"264.38400","22.03221","0.00583"
"264.57600","22.04817","0.00621"
"264.76800","22.06413","0.00614"
"264.96000","22.08022","0.00532"
"265.15200","22.09618","0.00550"
"265.34400","22.11214","0.01495"
"265.53600","22.12823","0.00466"
"265.72800","22.14413","0.00614"
"265.92000","22.16015","0.00655"
"266.11200","22.17624","0.00890"
"266.30400","22.19214","0.00433"
"266.49600","22.20817","0.00606"
"266.68800","22.22419","0.00653"
"266.88000","22.24015","0.00179"
"267.07200","22.25617","0.00269"
"267.26400","22.27220","0.00364"
"267.45600","22.28816","0.00280"
"267.64800","22.30419","0.00254"
"267.84000","22.32021","0.00232"
"268.03200","22.33617","0.00146"
"268.22400","22.35220","0.00348"
"268.41600","22.36822","0.00448"
"268.60800","22.38419","0.00396"
"268.80000","22.40015","0.00434"
"268.99200","22.41617","0.00497"
"269.18400","22.43226","0.00440"
"269.37600","22.44816","0.00107"
"269.56800","22.46418","0.00254"
"269.76000","22.48021","0.00166"
"269.95200","22.49611","0.00173"
"270.14400","22.51219","0.00203"
"270.33600","22.52816","0.00221"
"270.52800","22.54412","0.00193"
"270.72000","22.56021","0.00189"
"270.91200","22.57617","0.00305"
"271.10400","22.59213","0.00430"
"271.29600","22.60822","0.00393"
"271.48800","22.62418","0.00437"
"271.68000","22.64014","0.00438"
"271.87200","22.65623","0.00445"
"272.06400","22.67219","0.00253"
"272.25600","22.68810","0.00306"
"272.44800","22.70424","0.00234"
"272.64000","22.72020","0.00292"
"272.83200","22.73617","0.00362"
"273.02400","22.75225","0.00435"
"273.21600","22.76815","0.00374"
"273.40800","22.78418","0.00399"
"273.60000","22.80020","0.00406"
"273.79200","22.81610","0.00374"
"273.98400","22.83219","0.00404"
"274.17600","22.84821","0.00370"
"274.36800","22.86412","0.00369"
"274.56000","22.88014","0.00422"
"274.75200","22.89622","0.00406"
"274.94400","22.91207","0.00335"
"275.13600","22.92821","0.00372"
"275.32800","22.94417","0.00417"
"275.52000","22.96014","0.00384"
"275.71200","22.97616","0.00390"
"275.90400","22.99218","0.00414"
"276.09600","23.00821","0.00382"
"276.28800","23.02417","0.00389"
"276.48000","23.04014","0.00410"
"276.67200","23.05616","0.00409"
"276.86400","23.07212","0.00351"
"277.05600","23.08815","0.00430"
"277.24800","23.10417","0.00415"
"277.44000","23.12020","0.00439"
"277.63200","23.13616","0.00401"
"277.82400","23.15218","0.00406"
"278.01600","23.16821","0.00412"
"278.20800","23.18417","0.00428"
"278.40000","23.20013","0.00411"
"278.59200","23.21616","0.00390"
"278.78400","23.23218","0.00420"
"278.97600","23.24814","0.00411"
"279.16800","23.26417","0.00366"
"279.36000","23.28019","0.00414"
"279.55200","23.29622","0.00461"
"279.74400","23.31212","0.00392"
"279.93600","23.32820","0.00399"
"280.12800","23.34423","0.00375"
"280.32000","23.36013","0.00391"
"280.51200","23.37621","0.00356"
"280.70400","23.39211","0.00442"
"280.89600","23.40820","0.00382"
"281.08800","23.42416","0.00440"
"281.28000","23.44013","0.00391"
"281.31800","23.44336","0.00430"