File: Force_trajectories/170212_3/Specimen_RawData_3.csv
End date,"2/12/2017"
Specimen label,"13BG_2"
Maximum Load,"0.49497",N

Time,Extension,Load
(s),(mm),(N)
"0.00000","0.00000","-0.00020"
"0.16800","0.01034","0.00034"
"0.33600","0.02798","0.00066"
"0.50400","0.04233","0.00034"
"0.67200","0.05620","0.00053"
"0.84000","0.07025","0.00087"
"1.00800","0.08424","0.00093"
"1.17600","0.09823","0.00085"
"1.34400","0.11222","0.00147"
"1.51200","0.12622","0.00106"
"1.68000","0.14021","0.00167"
"1.84800","0.15420","0.00187"
"2.01600","0.16819","0.00178"
"2.18400","0.18218","0.00164"
"2.35200","0.19617","0.00178"
"2.52000","0.21022","0.00214"
"2.68800","0.22415","0.00227"
"2.85600","0.23814","0.00208"
"3.02400","0.25219","0.00248"
"3.19200","0.26630","0.00185"
"3.36000","0.28017","0.00252"
"3.52800","0.29422","0.00266"
"3.69600","0.30822","0.00239"
"3.86400","0.32215","0.00288"
"4.03200","0.33626","0.00259"
"4.20000","0.35025","0.00299"
"4.36800","0.36424","0.00217"
"4.53600","0.37823","0.00258"
"4.70400","0.39228","0.00300"
"4.87200","0.40621","0.00276"
"5.04000","0.42020","0.00251"
"5.20800","0.43419","0.00287"
"5.37600","0.44818","0.00317"
"5.54400","0.46211","0.00265"
"5.71200","0.47622","0.00336"
"5.88000","0.49021","0.00339"
"6.04800","0.50415","0.00289"
"6.21600","0.51826","0.00305"
"6.38400","0.53225","0.00307"
"6.55200","0.54618","0.00330"
"6.72000","0.56017","0.00358"
"6.88800","0.57422","0.00378"
"7.05600","0.58815","0.00349"
"7.22400","0.60226","0.00337"
"7.39200","0.61625","0.00363"
"7.56000","0.63018","0.00337"
"7.72800","0.64417","0.00374"
"7.89600","0.65822","0.00409"
"8.06400","0.67221","0.00368"
"8.23200","0.68620","0.00341"
"8.40000","0.70020","0.00422"
"8.56800","0.71425","0.00430"
"8.73600","0.72812","0.00377"
"8.90400","0.74223","0.00401"
"9.07200","0.75622","0.00423"
"9.24000","0.77021","0.00451"
"9.40800","0.78420","0.00460"
"9.57600","0.79825","0.00468"
"9.74400","0.81218","0.00433"
"9.91200","0.82617","0.00401"
"10.08000","0.84022","0.00444"
"10.24800","0.85421","0.00445"
"10.41600","0.86814","0.00414"
"10.58400","0.88219","0.00382"
"10.75200","0.89619","0.00453"
"10.92000","0.91018","0.00410"
"11.08800","0.92423","0.00459"
"11.25600","0.93828","0.00426"
"11.42400","0.95215","0.00401"
"11.59200","0.96620","0.00474"
"11.76000","0.98019","0.00446"
"11.92800","0.99418","0.00403"
"12.09600","1.00829","0.00447"
"12.26400","1.02222","0.00407"
"12.43200","1.03621","0.00462"
"12.60000","1.05026","0.00481"
"12.76800","1.06419","0.00443"
"12.93600","1.07818","0.00462"
"13.10400","1.09218","0.00447"
"13.27200","1.10623","0.00456"
"13.44000","1.12022","0.00477"
"13.60800","1.13415","0.00435"
"13.77600","1.14826","0.00491"
"13.94400","1.16225","0.00437"
"14.11200","1.17618","0.00490"
"14.28000","1.19023","0.00452"
"14.44800","1.20422","0.00464"
"14.61600","1.21815","0.00433"
"14.78400","1.23220","0.00424"
"14.95200","1.24625","0.00474"
"15.12000","1.26012","0.00473"
"15.28800","1.27417","0.00463"
"15.45600","1.28817","0.00547"
"15.62400","1.30216","0.00491"
"15.79200","1.31615","0.00417"
"15.96000","1.33026","0.00473"
"16.12800","1.34425","0.00457"
"16.29600","1.35818","0.00452"
"16.46400","1.37223","0.00481"
"16.63200","1.38622","0.00432"
"16.80000","1.40015","0.00483"
"16.96800","1.41426","0.00514"
"17.13600","1.42825","0.00444"
"17.30400","1.44218","0.00476"
"17.47200","1.45623","0.00449"
"17.64000","1.47022","0.00506"
"17.80800","1.48422","0.00463"
"17.97600","1.49821","0.00450"
"18.14400","1.51220","0.00453"
"18.31200","1.52619","0.00462"
"18.48000","1.54018","0.00523"
"18.64800","1.55417","0.00543"
"18.81600","1.56822","0.00440"
"18.98400","1.58221","0.00529"
"19.15200","1.59626","0.00428"
"19.32000","1.61019","0.00511"
"19.48800","1.62412","0.00488"
"19.65600","1.63823","0.00524"
"19.82400","1.65222","0.00511"
"19.99200","1.66621","0.00465"
"20.16000","1.68021","0.00547"
"20.32800","1.69426","0.00530"
"20.49600","1.70819","0.00494"
"20.66400","1.72218","0.00506"
"20.83200","1.73623","0.00490"
"21.00000","1.75022","0.00488"
"21.16800","1.76421","0.00528"
"21.33600","1.77820","0.00488"
"21.50400","1.79213","0.00498"
"21.67200","1.80612","0.00459"
"21.84000","1.82023","0.00499"
"22.00800","1.83422","0.00396"
"22.17600","1.84815","0.00465"
"22.34400","1.86226","0.00477"
"22.51200","1.87620","0.00470"
"22.68000","1.89019","0.00468"
"22.84800","1.90424","0.00507"
"23.01600","1.91823","0.00507"
"23.18400","1.93222","0.00382"
"23.35200","1.94615","0.00477"
"23.52000","1.96020","0.00525"
"23.68800","1.97419","0.00508"
"23.85600","1.98818","0.00502"
"24.02400","2.00223","0.00441"
"24.19200","2.01622","0.00488"
"24.36000","2.03015","0.00529"
"24.52800","2.04420","0.00467"
"24.69600","2.05819","0.00530"
"24.86400","2.07219","0.00485"
"25.03200","2.08624","0.00531"
"25.20000","2.10023","0.00501"
"25.36800","2.11422","0.00521"
"25.53600","2.12821","0.00531"
"25.70400","2.14220","0.00482"
"25.87200","2.15613","0.00488"
"26.04000","2.17018","0.00517"
"26.20800","2.18423","0.00548"
"26.37600","2.19816","0.00491"
"26.54400","2.21215","0.00541"
"26.71200","2.22626","0.00497"
"26.88000","2.24025","0.00571"
"27.04800","2.25418","0.00523"
"27.21600","2.26824","0.00522"
"27.38400","2.28217","0.00462"
"27.55200","2.29616","0.00536"
"27.72000","2.31021","0.00542"
"27.88800","2.32420","0.00533"
"28.05600","2.33819","0.00524"
"28.22400","2.35218","0.00505"
"28.39200","2.36623","0.00540"
"28.56000","2.38016","0.00472"
"28.72800","2.39421","0.00503"
"28.89600","2.40826","0.00456"
"29.06400","2.42219","0.00501"
"29.23200","2.43618","0.00501"
"29.40000","2.45023","0.00483"
"29.56800","2.46423","0.00515"
"29.73600","2.47816","0.00543"
"29.90400","2.49227","0.00494"
"30.07200","2.50620","0.00572"
"30.24000","2.52019","0.00499"
"30.40800","2.53424","0.00546"
"30.57600","2.54823","0.00501"
"30.74400","2.56216","0.00493"
"30.91200","2.57621","0.00529"
"31.08000","2.59020","0.00513"
"31.24800","2.60419","0.00521"
"31.41600","2.61812","0.00540"
"31.58400","2.63223","0.00493"
"31.75200","2.64622","0.00524"
"31.92000","2.66022","0.00504"
"32.08800","2.67421","0.00505"
"32.25600","2.68820","0.00473"
"32.42400","2.70213","0.00529"
"32.59200","2.71624","0.00548"
"32.76000","2.73023","0.00437"
"32.92800","2.74416","0.00523"
"33.09600","2.75827","0.00539"
"33.26400","2.77226","0.00475"
"33.43200","2.78619","0.00510"
"33.60000","2.80018","0.00540"
"33.76800","2.81423","0.00500"
"33.93600","2.82822","0.00558"
"34.10400","2.84222","0.00542"
"34.27200","2.85615","0.00531"
"34.44000","2.87020","0.00486"
"34.60800","2.88419","0.00473"
"34.77600","2.89830","0.00555"
"34.94400","2.91223","0.00590"
"35.11200","2.92616","0.00549"
"35.28000","2.94021","0.00624"
"35.44800","2.95420","0.00516"
"35.61600","2.96819","0.00540"
"35.78400","2.98218","0.00578"
"35.95200","2.99623","0.00569"
"36.12000","3.01016","0.00572"
"36.28800","3.02415","0.00565"
"36.45600","3.03820","0.00556"
"36.62400","3.05220","0.00532"
"36.79200","3.06619","0.00547"
"36.96000","3.08018","0.00524"
"37.12800","3.09417","0.00557"
"37.29600","3.10816","0.00582"
"37.46400","3.12221","0.00520"
"37.63200","3.13620","0.00555"
"37.80000","3.15019","0.00552"
"37.96800","3.16424","0.00547"
"38.13600","3.17823","0.00571"
"38.30400","3.19216","0.00531"
"38.47200","3.20621","0.00615"
"38.64000","3.22020","0.00597"
"38.80800","3.23419","0.00559"
"38.97600","3.24819","0.00551"
"39.14400","3.26218","0.00520"
"39.31200","3.27617","0.00559"
"39.48000","3.29022","0.00561"
"39.64800","3.30427","0.00542"
"39.81600","3.31820","0.00552"
"39.98400","3.33213","0.00554"
"40.15200","3.34618","0.00543"
"40.32000","3.36017","0.00558"
"40.48800","3.37422","0.00628"
"40.65600","3.38821","0.00526"
"40.82400","3.40220","0.00503"
"40.99200","3.41619","0.00548"
"41.16000","3.43024","0.00606"
"41.32800","3.44418","0.00590"
"41.49600","3.45817","0.00515"
"41.66400","3.47216","0.00567"
"41.83200","3.48621","0.00542"
"42.00000","3.50014","0.00558"
"42.16800","3.51413","0.00561"
"42.33600","3.52818","0.00596"
"42.50400","3.54223","0.00546"
"42.67200","3.55622","0.00588"
"42.84000","3.57021","0.00584"
"43.00800","3.58420","0.00537"
"43.17600","3.59813","0.00586"
"43.34400","3.61224","0.00558"
"43.51200","3.62624","0.00536"
"43.68000","3.64017","0.00558"
"43.84800","3.65416","0.00561"
"44.01600","3.66821","0.00611"
"44.18400","3.68214","0.00533"
"44.35200","3.69619","0.00594"
"44.52000","3.71024","0.00552"
"44.68800","3.72423","0.00595"
"44.85600","3.73822","0.00607"
"45.02400","3.75221","0.00580"
"45.19200","3.76620","0.00587"
"45.36000","3.78013","0.00630"
"45.52800","3.79424","0.00598"
"45.69600","3.80817","0.00578"
"45.86400","3.82217","0.00594"
"46.03200","3.83622","0.00580"
"46.20000","3.85021","0.00556"
"46.36800","3.86420","0.00613"
"46.53600","3.87819","0.00562"
"46.70400","3.89224","0.00584"
"46.87200","3.90623","0.00608"
"47.04000","3.92022","0.00582"
"47.20800","3.93421","0.00544"
"47.37600","3.94820","0.00579"
"47.54400","3.96225","0.00577"
"47.71200","3.97624","0.00581"
"47.88000","3.99023","0.00577"
"48.04800","4.00411","0.00576"
"48.21600","4.01822","0.00655"
"48.38400","4.03221","0.00632"
"48.55200","4.04614","0.00614"
"48.72000","4.06025","0.00540"
"48.88800","4.07424","0.00575"
"49.05600","4.08817","0.00542"
"49.22400","4.10216","0.00585"
"49.39200","4.11627","0.00515"
"49.56000","4.13020","0.00598"
"49.72800","4.14413","0.00569"
"49.89600","4.15824","0.00605"
"50.06400","4.17217","0.00538"
"50.23200","4.18616","0.00562"
"50.40000","4.20021","0.00583"
"50.56800","4.21421","0.00569"
"50.73600","4.22820","0.00588"
"50.90400","4.24219","0.00596"
"51.07200","4.25624","0.00644"
"51.24000","4.27017","0.00623"
"51.40800","4.28422","0.00582"
"51.57600","4.29827","0.00599"
"51.74400","4.31214","0.00540"
"51.91200","4.32619","0.00568"
"52.08000","4.34018","0.00619"
"52.24800","4.35423","0.00590"
"52.41600","4.36822","0.00549"
"52.58400","4.38221","0.00617"
"52.75200","4.39620","0.00563"
"52.92000","4.41020","0.00511"
"53.08800","4.42419","0.00542"
"53.25600","4.43824","0.00576"
"53.42400","4.45223","0.00602"
"53.59200","4.46628","0.00578"
"53.76000","4.48021","0.00583"
"53.92800","4.49414","0.00585"
"54.09600","4.50825","0.00580"
"54.26400","4.52218","0.00532"
"54.43200","4.53617","0.00561"
"54.60000","4.55016","0.00635"
"54.76800","4.56421","0.00590"
"54.93600","4.57814","0.00594"
"55.10400","4.59219","0.00601"
"55.27200","4.60625","0.00620"
"55.44000","4.62024","0.00551"
"55.60800","4.63417","0.00572"
"55.77600","4.64822","0.00584"
"55.94400","4.66215","0.00539"
"56.11200","4.67614","0.00609"
"56.28000","4.69025","0.00623"
"56.44800","4.70424","0.00609"
"56.61600","4.71817","0.00533"
"56.78400","4.73228","0.00597"
"56.95200","4.74621","0.00543"
"57.12000","4.76020","0.00522"
"57.28800","4.77425","0.00553"
"57.45600","4.78824","0.00559"
"57.62400","4.80218","0.00634"
"57.79200","4.81617","0.00551"
"57.96000","4.83022","0.00575"
"58.12800","4.84415","0.00570"
"58.29600","4.85820","0.00545"
"58.46400","4.87225","0.00582"
"58.63200","4.88618","0.00558"
"58.80000","4.90011","0.00564"
"58.96800","4.91422","0.00592"
"59.13600","4.92821","0.00633"
"59.30400","4.94214","0.00569"
"59.47200","4.95625","0.00634"
"59.64000","4.97024","0.00588"
"59.80800","4.98412","0.00591"
"59.97600","4.99823","0.00629"
"60.14400","5.01222","0.00629"
"60.31200","5.02621","0.00573"
"60.48000","5.04020","0.00570"
"60.64800","5.05419","0.00587"
"60.81600","5.06818","0.00581"
"60.98400","5.08217","0.00588"
"61.15200","5.09622","0.00559"
"61.32000","5.11021","0.00561"
"61.48800","5.12414","0.00555"
"61.65600","5.13825","0.00601"
"61.82400","5.15224","0.00544"
"61.99200","5.16617","0.00579"
"62.16000","5.18023","0.00646"
"62.32800","5.19422","0.00580"
"62.49600","5.20821","0.00550"
"62.66400","5.22220","0.00629"
"62.83200","5.23619","0.00603"
"63.00000","5.25018","0.00568"
"63.16800","5.26423","0.00547"
"63.33600","5.27822","0.00531"
"63.50400","5.29221","0.00555"
"63.67200","5.30620","0.00556"
"63.84000","5.32019","0.00548"
"64.00800","5.33418","0.00563"
"64.17600","5.34817","0.00520"
"64.34400","5.36228","0.00513"
"64.51200","5.37616","0.00571"
"64.68000","5.39015","0.00577"
"64.84800","5.40420","0.00582"
"65.01600","5.41825","0.00557"
"65.18400","5.43218","0.00563"
"65.35200","5.44623","0.00542"
"65.52000","5.46022","0.00584"
"65.68800","5.47421","0.00573"
"65.85600","5.48820","0.00576"
"66.02400","5.50225","0.00573"
"66.19200","5.51624","0.00564"
"66.36000","5.53017","0.00557"
"66.52800","5.54422","0.00544"
"66.69600","5.55815","0.00569"
"66.86400","5.57215","0.00586"
"67.03200","5.58620","0.00550"
"67.20000","5.60025","0.00572"
"67.36800","5.61418","0.00510"
"67.53600","5.62823","0.00606"
"67.70400","5.64222","0.00558"
"67.87200","5.65615","0.00569"
"68.04000","5.67020","0.00605"
"68.20800","5.68425","0.00558"
"68.37600","5.69824","0.00582"
"68.54400","5.71217","0.00562"
"68.71200","5.72616","0.00551"
"68.88000","5.74015","0.00540"
"69.04800","5.75414","0.00557"
"69.21600","5.76826","0.00555"
"69.38400","5.78219","0.00572"
"69.55200","5.79618","0.00603"
"69.72000","5.81023","0.00554"
"69.88800","5.82416","0.00570"
"70.05600","5.83821","0.00537"
"70.22400","5.85226","0.00601"
"70.39200","5.86625","0.00568"
"70.56000","5.88018","0.00623"
"70.72800","5.89417","0.00605"
"70.89600","5.90822","0.00583"
"71.06400","5.92221","0.00567"
"71.23200","5.93620","0.00578"
"71.40000","5.95019","0.00597"
"71.56800","5.96413","0.00590"
"71.73600","5.97818","0.00601"
"71.90400","5.99223","0.00598"
"72.07200","6.00622","0.00594"
"72.24000","6.02021","0.00619"
"72.40800","6.03426","0.00553"
"72.57600","6.04819","0.00625"
"72.74400","6.06212","0.00563"
"72.91200","6.07623","0.00568"
"73.08000","6.09022","0.00547"
"73.24800","6.10415","0.00551"
"73.41600","6.11820","0.00634"
"73.58400","6.13225","0.00608"
"73.75200","6.14618","0.00645"
"73.92000","6.16017","0.00553"
"74.08800","6.17423","0.00624"
"74.25600","6.18822","0.00625"
"74.42400","6.20215","0.00623"
"74.59200","6.21620","0.00591"
"74.76000","6.23019","0.00589"
"74.92800","6.24418","0.00606"
"75.09600","6.25823","0.00601"
"75.26400","6.27222","0.00600"
"75.43200","6.28615","0.00621"
"75.60000","6.30020","0.00601"
"75.76800","6.31425","0.00593"
"75.93600","6.32818","0.00653"
"76.10400","6.34223","0.00638"
"76.27200","6.35623","0.00615"
"76.44000","6.37022","0.00643"
"76.60800","6.38415","0.00589"
"76.77600","6.39820","0.00661"
"76.94400","6.41225","0.00629"
"77.11200","6.42618","0.00606"
"77.28000","6.44023","0.00579"
"77.44800","6.45428","0.00640"
"77.61600","6.46809","0.00584"
"77.78400","6.48220","0.00612"
"77.95200","6.49625","0.00635"
"78.12000","6.51024","0.00617"
"78.28800","6.52423","0.00634"
"78.45600","6.53822","0.00620"
"78.62400","6.55222","0.00626"
"78.79200","6.56621","0.00662"
"78.96000","6.58020","0.00630"
"79.12800","6.59419","0.00678"
"79.29600","6.60818","0.00572"
"79.46400","6.62217","0.00641"
"79.63200","6.63616","0.00579"
"79.80000","6.65015","0.00667"
"79.96800","6.66426","0.00609"
"80.13600","6.67819","0.00640"
"80.30400","6.69218","0.00593"
"80.47200","6.70617","0.00586"
"80.64000","6.72022","0.00661"
"80.80800","6.73416","0.00644"
"80.97600","6.74821","0.00635"
"81.14400","6.76226","0.00661"
"81.31200","6.77619","0.00670"
"81.48000","6.79024","0.00655"
"81.64800","6.80423","0.00589"
"81.81600","6.81816","0.00612"
"81.98400","6.83221","0.00649"
"82.15200","6.84620","0.00628"
"82.32000","6.86019","0.00645"
"82.48800","6.87412","0.00619"
"82.65600","6.88823","0.00621"
"82.82400","6.90222","0.00640"
"82.99200","6.91615","0.00623"
"83.16000","6.93026","0.00629"
"83.32800","6.94420","0.00672"
"83.49600","6.95819","0.00690"
"83.66400","6.97218","0.00639"
"83.83200","6.98629","0.00624"
"84.00000","7.00022","0.00623"
"84.16800","7.01421","0.00646"
"84.33600","7.02820","0.00645"
"84.50400","7.04219","0.00652"
"84.67200","7.05618","0.00605"
"84.84000","7.07017","0.00630"
"85.00800","7.08422","0.00694"
"85.17600","7.09815","0.00581"
"85.34400","7.11220","0.00658"
"85.51200","7.12625","0.00612"
"85.68000","7.14019","0.00645"
"85.84800","7.15424","0.00683"
"86.01600","7.16823","0.00644"
"86.18400","7.18216","0.00678"
"86.35200","7.19621","0.00672"
"86.52000","7.21020","0.00634"
"86.68800","7.22419","0.00652"
"86.85600","7.23818","0.00707"
"87.02400","7.25223","0.00656"
"87.19200","7.26616","0.00645"
"87.36000","7.28015","0.00676"
"87.52800","7.29420","0.00674"
"87.69600","7.30825","0.00682"
"87.86400","7.32224","0.00666"
"88.03200","7.33630","0.00743"
"88.20000","7.35017","0.00672"
"88.36800","7.36410","0.00685"
"88.53600","7.37821","0.00674"
"88.70400","7.39220","0.00712"
"88.87200","7.40619","0.00677"
"89.04000","7.42018","0.00684"
"89.20800","7.43423","0.00703"
"89.37600","7.44816","0.00679"
"89.54400","7.46221","0.00693"
"89.71200","7.47626","0.00717"
"89.88000","7.49019","0.00673"
"90.04800","7.50418","0.00721"
"90.21600","7.51823","0.00700"
"90.38400","7.53217","0.00676"
"90.55200","7.54616","0.00682"
"90.72000","7.56027","0.00720"
"90.88800","7.57426","0.00706"
"91.05600","7.58819","0.00736"
"91.22400","7.60224","0.00686"
"91.39200","7.61623","0.00748"
"91.56000","7.63016","0.00714"
"91.72800","7.64421","0.00741"
"91.89600","7.65826","0.00752"
"92.06400","7.67219","0.00712"
"92.23200","7.68618","0.00747"
"92.40000","7.70018","0.00685"
"92.56800","7.71417","0.00770"
"92.73600","7.72822","0.00742"
"92.90400","7.74227","0.00734"
"93.07200","7.75620","0.00759"
"93.24000","7.77013","0.00739"
"93.40800","7.78418","0.00759"
"93.57600","7.79823","0.00786"
"93.74400","7.81222","0.00748"
"93.91200","7.82621","0.00753"
"94.08000","7.84026","0.00787"
"94.24800","7.85419","0.00720"
"94.41600","7.86824","0.00758"
"94.58400","7.88223","0.00747"
"94.75200","7.89622","0.00793"
"94.92000","7.91021","0.00817"
"95.08800","7.92421","0.00806"
"95.25600","7.93820","0.00743"
"95.42400","7.95213","0.00814"
"95.59200","7.96624","0.00766"
"95.76000","7.98023","0.00775"
"95.92800","7.99422","0.00772"
"96.09600","8.00821","0.00828"
"96.26400","8.02220","0.00759"
"96.43200","8.03619","0.00829"
"96.60000","8.05024","0.00828"
"96.76800","8.06423","0.00768"
"96.93600","8.07816","0.00816"
"97.10400","8.09221","0.00833"
"97.27200","8.10620","0.00847"
"97.44000","8.12014","0.00824"
"97.60800","8.13419","0.00810"
"97.77600","8.14818","0.00813"
"97.94400","8.16223","0.00853"
"98.11200","8.17622","0.00870"
"98.28000","8.19021","0.00866"
"98.44800","8.20420","0.00806"
"98.61600","8.21819","0.00789"
"98.78400","8.23230","0.00900"
"98.95200","8.24623","0.00806"
"99.12000","8.26010","0.00856"
"99.28800","8.27421","0.00862"
"99.45600","8.28820","0.00835"
"99.62400","8.30219","0.00876"
"99.79200","8.31625","0.00866"
"99.96000","8.33024","0.00842"
"100.12800","8.34417","0.00904"
"100.29600","8.35822","0.00826"
"100.46400","8.37227","0.00864"
"100.63200","8.38626","0.00863"
"100.80000","8.40019","0.00862"
"100.96800","8.41418","0.00882"
"101.13600","8.42817","0.00809"
"101.30400","8.44216","0.00895"
"101.47200","8.45621","0.00896"
"101.64000","8.47026","0.00939"
"101.80800","8.48413","0.00908"
"101.97600","8.49819","0.00923"
"102.14400","8.51224","0.00860"
"102.31200","8.52617","0.00857"
"102.48000","8.54022","0.00939"
"102.64800","8.55427","0.00914"
"102.81600","8.56820","0.00899"
"102.98400","8.58219","0.00941"
"103.15200","8.59618","0.00906"
"103.32000","8.61017","0.00855"
"103.48800","8.62422","0.00918"
"103.65600","8.63827","0.00862"
"103.82400","8.65220","0.00930"
"103.99200","8.66613","0.00882"
"104.16000","8.68024","0.00829"
"104.32800","8.69418","0.00946"
"104.49600","8.70823","0.00938"
"104.66400","8.72222","0.00874"
"104.83200","8.73627","0.00941"
"105.00000","8.75020","0.00946"
"105.16800","8.76419","0.00917"
"105.33600","8.77818","0.00943"
"105.50400","8.79217","0.00953"
"105.67200","8.80616","0.00918"
"105.84000","8.82021","0.00906"
"106.00800","8.83414","0.00965"
"106.17600","8.84819","0.00952"
"106.34400","8.86224","0.00906"
"106.51200","8.87623","0.01021"
"106.68000","8.89017","0.00916"
"106.84800","8.90422","0.00934"
"107.01600","8.91827","0.00927"
"107.18400","8.93214","0.00978"
"107.35200","8.94625","0.00986"
"107.52000","8.96024","0.00921"
"107.68800","8.97417","0.00945"
"107.85600","8.98822","0.00947"
"108.02400","9.00221","0.00968"
"108.19200","9.01620","0.01007"
"108.36000","9.03019","0.00967"
"108.52800","9.04424","0.00922"
"108.69600","9.05823","0.01005"
"108.86400","9.07211","0.00977"
"109.03200","9.08622","0.00995"
"109.20000","9.10021","0.01015"
"109.36800","9.11414","0.00997"
"109.53600","9.12825","0.01056"
"109.70400","9.14218","0.00957"
"109.87200","9.15617","0.01044"
"110.04000","9.17016","0.01019"
"110.20800","9.18421","0.01009"
"110.37600","9.19820","0.01039"
"110.54400","9.21225","0.01080"
"110.71200","9.22624","0.01021"
"110.88000","9.24017","0.01034"
"111.04800","9.25416","0.01038"
"111.21600","9.26822","0.01051"
"111.38400","9.28226","0.01003"
"111.55200","9.29620","0.01039"
"111.72000","9.31025","0.01059"
"111.88800","9.32418","0.01035"
"112.05600","9.33811","0.01078"
"112.22400","9.35222","0.01054"
"112.39200","9.36621","0.01065"
"112.56000","9.38014","0.01026"
"112.72800","9.39425","0.01118"
"112.89600","9.40824","0.01096"
"113.06400","9.42223","0.01112"
"113.23200","9.43622","0.01109"
"113.40000","9.45021","0.01067"
"113.56800","9.46420","0.01128"
"113.73600","9.47820","0.01158"
"113.90400","9.49225","0.01144"
"114.07200","9.50618","0.01095"
"114.24000","9.52017","0.01130"
"114.40800","9.53428","0.01154"
"114.57600","9.54821","0.01108"
"114.74400","9.56220","0.01116"
"114.91200","9.57625","0.01150"
"115.08000","9.59024","0.01170"
"115.24800","9.60417","0.01136"
"115.41600","9.61822","0.01160"
"115.58400","9.63221","0.01172"
"115.75200","9.64620","0.01189"
"115.92000","9.66019","0.01168"
"116.08800","9.67419","0.01191"
"116.25600","9.68818","0.01223"
"116.42400","9.70223","0.01163"
"116.59200","9.71628","0.01202"
"116.76000","9.73015","0.01176"
"116.92800","9.74414","0.01239"
"117.09600","9.75825","0.01176"
"117.26400","9.77224","0.01184"
"117.43200","9.78617","0.01226"
"117.60000","9.80022","0.01205"
"117.76800","9.81421","0.01263"
"117.93600","9.82814","0.01251"
"118.10400","9.84219","0.01234"
"118.27200","9.85618","0.01191"
"118.44000","9.87018","0.01230"
"118.60800","9.88422","0.01258"
"118.77600","9.89828","0.01263"
"118.94400","9.91221","0.01267"
"119.11200","9.92620","0.01301"
"119.28000","9.94025","0.01265"
"119.44800","9.95424","0.01285"
"119.61600","9.96817","0.01289"
"119.78400","9.98222","0.01351"
"119.95200","9.99621","0.01191"
"120.12000","10.01014","0.01191"
"120.28800","10.02425","0.01246"
"120.45600","10.03824","0.01263"
"120.62400","10.05218","0.01202"
"120.79200","10.06623","0.01255"
"120.96000","10.08022","0.01272"
"121.12800","10.09421","0.01271"
"121.29600","10.10820","0.01267"
"121.46400","10.12219","0.01328"
"121.63200","10.13618","0.01262"
"121.80000","10.15011","0.01264"
"121.96800","10.16422","0.01269"
"122.13600","10.17821","0.01288"
"122.30400","10.19220","0.01343"
"122.47200","10.20625","0.01371"
"122.64000","10.22018","0.01340"
"122.80800","10.23417","0.01385"
"122.97600","10.24823","0.01345"
"123.14400","10.26222","0.01371"
"123.31200","10.27621","0.01414"
"123.48000","10.29020","0.01367"
"123.64800","10.30419","0.01344"
"123.81600","10.31812","0.01381"
"123.98400","10.33223","0.01356"
"124.15200","10.34628","0.01395"
"124.32000","10.36021","0.01429"
"124.48800","10.37420","0.01429"
"124.65600","10.38819","0.01420"
"124.82400","10.40212","0.01432"
"124.99200","10.41611","0.01442"
"125.16000","10.43028","0.01485"
"125.32800","10.44427","0.01427"
"125.49600","10.45815","0.01451"
"125.66400","10.47226","0.01464"
"125.83200","10.48625","0.01458"
"126.00000","10.50018","0.01531"
"126.16800","10.51423","0.01478"
"126.33600","10.52822","0.01549"
"126.50400","10.54215","0.01502"
"126.67200","10.55620","0.01546"
"126.84000","10.57019","0.01532"
"127.00800","10.58418","0.01615"
"127.17600","10.59823","0.01537"
"127.34400","10.61222","0.01584"
"127.51200","10.62621","0.01592"
"127.68000","10.64015","0.01659"
"127.84800","10.65420","0.01623"
"128.01600","10.66825","0.01647"
"128.18400","10.68218","0.01664"
"128.35200","10.69623","0.01661"
"128.52000","10.71028","0.01669"
"128.68800","10.72415","0.01620"
"128.85600","10.73820","0.01748"
"129.02400","10.75225","0.01737"
"129.19200","10.76618","0.01758"
"129.36000","10.78023","0.01811"
"129.52800","10.79416","0.01762"
"129.69600","10.80821","0.01747"
"129.86400","10.82215","0.01807"
"130.03200","10.83626","0.01877"
"130.20000","10.85019","0.01822"
"130.36800","10.86418","0.01821"
"130.53600","10.87823","0.01821"
"130.70400","10.89222","0.01848"
"130.87200","10.90615","0.01899"
"131.04000","10.92026","0.01900"
"131.20800","10.93419","0.01942"
"131.37600","10.94818","0.01912"
"131.54400","10.96217","0.01968"
"131.71200","10.97622","0.01949"
"131.88000","10.99015","0.01980"
"132.04800","11.00420","0.02011"
"132.21600","11.01826","0.01968"
"132.38400","11.03219","0.01991"
"132.55200","11.04618","0.02052"
"132.72000","11.06017","0.02081"
"132.88800","11.07422","0.02091"
"133.05600","11.08821","0.02119"
"133.22400","11.10226","0.02093"
"133.39200","11.11619","0.02146"
"133.56000","11.13018","0.02177"
"133.72800","11.14423","0.02154"
"133.89600","11.15822","0.02243"
"134.06400","11.17221","0.02234"
"134.23200","11.18620","0.02241"
"134.40000","11.20025","0.02296"
"134.56800","11.21418","0.02269"
"134.73600","11.22818","0.02308"
"134.90400","11.24223","0.02416"
"135.07200","11.25622","0.02370"
"135.24000","11.27021","0.02393"
"135.40800","11.28420","0.02471"
"135.57600","11.29819","0.02420"
"135.74400","11.31212","0.02489"
"135.91200","11.32623","0.02512"
"136.08000","11.34028","0.02494"
"136.24800","11.35415","0.02575"
"136.41600","11.36820","0.02634"
"136.58400","11.38225","0.02674"
"136.75200","11.39618","0.02678"
"136.92000","11.41023","0.02639"
"137.08800","11.42428","0.02691"
"137.25600","11.43816","0.02725"
"137.42400","11.45221","0.02782"
"137.59200","11.46620","0.02777"
"137.76000","11.48019","0.02777"
"137.92800","11.49418","0.02837"
"138.09600","11.50817","0.02816"
"138.26400","11.52222","0.02921"
"138.43200","11.53615","0.02943"
"138.60000","11.55020","0.02991"
"138.76800","11.56419","0.02968"
"138.93600","11.57818","0.03018"
"139.10400","11.59223","0.03036"
"139.27200","11.60628","0.03024"
"139.44000","11.62015","0.03046"
"139.60800","11.63415","0.03097"
"139.77600","11.64820","0.03095"
"139.94400","11.66219","0.03150"
"140.11200","11.67624","0.03157"
"140.28000","11.69023","0.03141"
"140.44800","11.70416","0.03191"
"140.61600","11.71815","0.03224"
"140.78400","11.73220","0.03240"
"140.95200","11.74625","0.03265"
"141.12000","11.76018","0.03143"
"141.28800","11.77423","0.03191"
"141.45600","11.78822","0.03220"
"141.62400","11.80216","0.03236"
"141.79200","11.81621","0.03297"
"141.96000","11.83020","0.03351"
"142.12800","11.84413","0.03351"
"142.29600","11.85824","0.03401"
"142.46400","11.87223","0.03429"
"142.63200","11.88616","0.03488"
"142.80000","11.90021","0.03493"
"142.96800","11.91426","0.03483"
"143.13600","11.92819","0.03504"
"143.30400","11.94218","0.03555"
"143.47200","11.95623","0.03573"
"143.64000","11.97016","0.03586"
"143.80800","11.98421","0.03636"
"143.97600","11.99827","0.03625"
"144.14400","12.01219","0.03654"
"144.31200","12.02613","0.03709"
"144.48000","12.04018","0.03690"
"144.64800","12.05423","0.03748"
"144.81600","12.06822","0.03782"
"144.98400","12.08221","0.03775"
"145.15200","12.09626","0.03805"
"145.32000","12.11019","0.03801"
"145.48800","12.12418","0.03856"
"145.65600","12.13817","0.03892"
"145.82400","12.15216","0.03911"
"145.99200","12.16615","0.03918"
"146.16000","12.18020","0.03968"
"146.32800","12.19420","0.03999"
"146.49600","12.20813","0.04019"
"146.66400","12.22224","0.04084"
"146.83200","12.23623","0.04071"
"147.00000","12.25016","0.04149"
"147.16800","12.26421","0.04221"
"147.33600","12.27820","0.04255"
"147.50400","12.29219","0.04342"
"147.67200","12.30618","0.04341"
"147.84000","12.32023","0.04432"
"148.00800","12.33422","0.04477"
"148.17600","12.34815","0.04597"
"148.34400","12.36220","0.04619"
"148.51200","12.37619","0.04747"
"148.68000","12.39019","0.04863"
"148.84800","12.40429","0.04902"
"149.01600","12.41823","0.05008"
"149.18400","12.43216","0.05053"
"149.35200","12.44621","0.05207"
"149.52000","12.46020","0.05266"
"149.68800","12.47419","0.05467"
"149.85600","12.48824","0.05502"
"150.02400","12.50223","0.05622"
"150.19200","12.51616","0.05742"
"150.36000","12.53021","0.05829"
"150.52800","12.54420","0.05948"
"150.69600","12.55819","0.06106"
"150.86400","12.57218","0.06157"
"151.03200","12.58623","0.06289"
"151.20000","12.60023","0.06419"
"151.36800","12.61416","0.06492"
"151.53600","12.62827","0.06635"
"151.70400","12.64226","0.06740"
"151.87200","12.65613","0.06861"
"152.04000","12.67024","0.06969"
"152.20800","12.68423","0.07087"
"152.37600","12.69816","0.07194"
"152.54400","12.71215","0.07314"
"152.71200","12.72626","0.07410"
"152.88000","12.74019","0.07536"
"153.04800","12.75418","0.07688"
"153.21600","12.76824","0.07815"
"153.38400","12.78216","0.07923"
"153.55200","12.79616","0.08005"
"153.72000","12.81021","0.08196"
"153.88800","12.82420","0.08200"
"154.05600","12.83819","0.08328"
"154.22400","12.85218","0.08373"
"154.39200","12.86617","0.08475"
"154.56000","12.88016","0.08535"
"154.72800","12.89421","0.08606"
"154.89600","12.90826","0.08661"
"155.06400","12.92219","0.08719"
"155.23200","12.93624","0.08755"
"155.40000","12.95023","0.08802"
"155.56800","12.96422","0.08860"
"155.73600","12.97822","0.08932"
"155.90400","12.99221","0.09032"
"156.07200","13.00620","0.09053"
"156.24000","13.02013","0.09121"
"156.40800","13.03418","0.09153"
"156.57600","13.04823","0.09313"
"156.74400","13.06222","0.09460"
"156.91200","13.07621","0.09629"
"157.08000","13.09020","0.09851"
"157.24800","13.10419","0.10017"
"157.41600","13.11818","0.10223"
"157.58400","13.13223","0.10412"
"157.75200","13.14622","0.10584"
"157.92000","13.16021","0.10762"
"158.08800","13.17420","0.10978"
"158.25600","13.18820","0.11055"
"158.42400","13.20225","0.11249"
"158.59200","13.21618","0.11458"
"158.76000","13.23017","0.11552"
"158.92800","13.24416","0.11749"
"159.09600","13.25821","0.11846"
"159.26400","13.27220","0.11933"
"159.43200","13.28613","0.12096"
"159.60000","13.30030","0.12195"
"159.76800","13.31423","0.12317"
"159.93600","13.32810","0.12402"
"160.10400","13.34221","0.12511"
"160.27200","13.35620","0.12572"
"160.44000","13.37020","0.12658"
"160.60800","13.38425","0.12762"
"160.77600","13.39824","0.12852"
"160.94400","13.41217","0.12910"
"161.11200","13.42616","0.12970"
"161.28000","13.44021","0.13060"
"161.44800","13.45414","0.13124"
"161.61600","13.46819","0.13189"
"161.78400","13.48224","0.13247"
"161.95200","13.49617","0.13270"
"162.12000","13.51010","0.13339"
"162.28800","13.52421","0.13443"
"162.45600","13.53826","0.13540"
"162.62400","13.55214","0.13630"
"162.79200","13.56618","0.13731"
"162.96000","13.58024","0.13794"
"163.12800","13.59423","0.13943"
"163.29600","13.60816","0.14034"
"163.46400","13.62221","0.14220"
"163.63200","13.63620","0.14482"
"163.80000","13.65019","0.14594"
"163.96800","13.66424","0.14949"
"164.13600","13.67823","0.15127"
"164.30400","13.69216","0.15399"
"164.47200","13.70627","0.15691"
"164.64000","13.72020","0.16094"
"164.80800","13.73419","0.16402"
"164.97600","13.74819","0.16679"
"165.14400","13.76218","0.17173"
"165.31200","13.77617","0.17470"
"165.48000","13.79028","0.17939"
"165.64800","13.80421","0.18250"
"165.81600","13.81820","0.18522"
"165.98400","13.83219","0.18717"
"166.15200","13.84624","0.18943"
"166.32000","13.86017","0.19079"
"166.48800","13.87416","0.19174"
"166.65600","13.88821","0.19271"
"166.82400","13.90214","0.19337"
"166.99200","13.91619","0.19399"
"167.16000","13.93018","0.19502"
"167.32800","13.94424","0.19648"
"167.49600","13.95817","0.19828"
"167.66400","13.97228","0.20033"
"167.83200","13.98621","0.20338"
"168.00000","14.00014","0.20544"
"168.16800","14.01425","0.20792"
"168.33600","14.02824","0.21005"
"168.50400","14.04217","0.21349"
"168.67200","14.05622","0.21534"
"168.84000","14.07027","0.21725"
"169.00800","14.08414","0.21979"
"169.17600","14.09819","0.22232"
"169.34400","14.11224","0.22439"
"169.51200","14.12624","0.22629"
"169.68000","14.14022","0.22841"
"169.84800","14.15422","0.22981"
"170.01600","14.16821","0.23075"
"170.18400","14.18214","0.23187"
"170.35200","14.19619","0.23344"
"170.52000","14.21024","0.23463"
"170.68800","14.22417","0.23558"
"170.85600","14.23822","0.23648"
"171.02400","14.25221","0.23751"
"171.19200","14.26614","0.23842"
"171.36000","14.28019","0.23903"
"171.52800","14.29424","0.23969"
"171.69600","14.30817","0.24092"
"171.86400","14.32216","0.24172"
"172.03200","14.33622","0.24278"
"172.20000","14.35021","0.24331"
"172.36800","14.36420","0.24468"
"172.53600","14.37825","0.24581"
"172.70400","14.39218","0.24769"
"172.87200","14.40617","0.24943"
"173.04000","14.42022","0.25222"
"173.20800","14.43421","0.25463"
"173.37600","14.44820","0.25729"
"173.54400","14.46225","0.25915"
"173.71200","14.47618","0.26230"
"173.88000","14.49017","0.26493"
"174.04800","14.50422","0.26693"
"174.21600","14.51821","0.26979"
"174.38400","14.53215","0.27264"
"174.55200","14.54614","0.27540"
"174.72000","14.56019","0.27732"
"174.88800","14.57412","0.27941"
"175.05600","14.58817","0.28193"
"175.22400","14.60222","0.28368"
"175.39200","14.61627","0.28527"
"175.56000","14.63020","0.28716"
"175.72800","14.64425","0.28882"
"175.89600","14.65824","0.29138"
"176.06400","14.67217","0.29459"
"176.23200","14.68622","0.29823"
"176.40000","14.70027","0.30216"
"176.56800","14.71420","0.30729"
"176.73600","14.72820","0.31117"
"176.90400","14.74219","0.31607"
"177.07200","14.75618","0.32046"
"177.24000","14.77023","0.32518"
"177.40800","14.78428","0.32898"
"177.57600","14.79821","0.33184"
"177.74400","14.81214","0.33517"
"177.91200","14.82625","0.33739"
"178.08000","14.84018","0.33975"
"178.24800","14.85417","0.34134"
"178.41600","14.86822","0.34323"
"178.58400","14.88221","0.34420"
"178.75200","14.89614","0.34513"
"178.92000","14.91020","0.34611"
"179.08800","14.92424","0.34659"
"179.25600","14.93818","0.34704"
"179.42400","14.95217","0.34773"
"179.59200","14.96622","0.34844"
"179.76000","14.98021","0.34915"
"179.92800","14.99420","0.35023"
"180.09600","15.00825","0.35158"
"180.26400","15.02224","0.35278"
"180.43200","15.03623","0.35533"
"180.60000","15.05016","0.35750"
"180.76800","15.06421","0.35986"
"180.93600","15.07808","0.36263"
"181.10400","15.09225","0.36564"
"181.27200","15.10624","0.36879"
"181.44000","15.12018","0.37286"
"181.60800","15.13423","0.37586"
"181.77600","15.14822","0.38047"
"181.94400","15.16221","0.38388"
"182.11200","15.17620","0.38708"
"182.28000","15.19025","0.38979"
"182.44800","15.20424","0.22155"
"182.61600","15.21817","0.23059"
"182.78400","15.23216","0.22238"
"182.95200","15.24615","0.23318"
"183.12000","15.26020","0.23013"
"183.28800","15.27419","0.23571"
"183.45600","15.28818","0.23517"
"183.62400","15.30217","0.23738"
"183.79200","15.31623","0.23701"
"183.96000","15.33022","0.23894"
"184.12800","15.34415","0.23988"
"184.29600","15.35826","0.24289"
"184.46400","15.37225","0.24437"
"184.63200","15.38618","0.24583"
"184.80000","15.40017","0.25221"
"184.96800","15.41422","0.24990"
"185.13600","15.42821","0.26448"
"185.30400","15.44220","0.25750"
"185.47200","15.45619","0.27089"
"185.64000","15.47024","0.26639"
"185.80800","15.48417","0.27782"
"185.97600","15.49822","0.27631"
"186.14400","15.51222","0.28369"
"186.31200","15.52615","0.28163"
"186.48000","15.54026","0.29002"
"186.64800","15.55419","0.28607"
"186.81600","15.56818","0.29747"
"186.98400","15.58217","0.29160"
"187.15200","15.59628","0.30646"
"187.32000","15.61015","0.30447"
"187.48800","15.62420","0.31805"
"187.65600","15.63819","0.31486"
"187.82400","15.65218","0.32929"
"187.99200","15.66617","0.32657"
"188.16000","15.68028","0.33639"
"188.32800","15.69421","0.33760"
"188.49600","15.70815","0.34091"
"188.66400","15.72219","0.34313"
"188.83200","15.73619","0.34486"
"189.00000","15.75018","0.34613"
"189.16800","15.76429","0.34647"
"189.33600","15.77822","0.34788"
"189.50400","15.79215","0.34761"
"189.67200","15.80626","0.35068"
"189.84000","15.82019","0.34983"
"190.00800","15.83424","0.35459"
"190.17600","15.84823","0.35303"
"190.34400","15.86222","0.35938"
"190.51200","15.87621","0.35777"
"190.68000","15.89014","0.36474"
"190.84800","15.90420","0.36424"
"191.01600","15.91819","0.36934"
"191.18400","15.93218","0.37322"
"191.35200","15.94623","0.37618"
"191.52000","15.96022","0.38383"
"191.68800","15.97415","0.38322"
"191.85600","15.98826","0.39178"
"192.02400","16.00225","0.39010"
"192.19200","16.01618","0.39583"
"192.36000","16.03017","0.39532"
"192.52800","16.04422","0.39883"
"192.69600","16.05815","0.40012"
"192.86400","16.07220","0.40306"
"193.03200","16.08625","0.40828"
"193.20000","16.10019","0.40842"
"193.36800","16.11423","0.41604"
"193.53600","16.12823","0.41588"
"193.70400","16.14216","0.42123"
"193.87200","16.15615","0.42161"
"194.04000","16.17026","0.42538"
"194.20800","16.18425","0.42691"
"194.37600","16.19812","0.42723"
"194.54400","16.21223","0.42849"
"194.71200","16.22622","0.42864"
"194.88000","16.24015","0.43196"
"195.04800","16.25420","0.43167"
"195.21600","16.26825","0.43462"
"195.38400","16.28218","0.43554"
"195.55200","16.29618","0.43757"
"195.72000","16.31023","0.44135"
"195.88800","16.32416","0.44051"
"196.05600","16.33821","0.44468"
"196.22400","16.35220","0.44546"
"196.39200","16.36619","0.44902"
"196.56000","16.38012","0.45106"
"196.72800","16.39423","0.45318"
"196.89600","16.40828","0.45826"
"197.06400","16.42221","0.45881"
"197.23200","16.43620","0.46406"
"197.40000","16.45019","0.46587"
"197.56800","16.46418","0.46923"
"197.73600","16.47818","0.47363"
"197.90400","16.49223","0.47473"
"198.07200","16.50616","0.47955"
"198.24000","16.52021","0.48085"
"198.40800","16.53420","0.48478"
"198.57600","16.54819","0.48751"
"198.74400","16.56218","0.48893"
"198.91200","16.57617","0.49292"
"199.08000","16.59022","0.49316"
"199.24800","16.60415","0.49492"
"199.41600","16.61820","0.36796"
"199.58400","16.63219","0.30326"
"199.75200","16.64618","0.33385"
"199.92000","16.66023","0.30370"
"200.08800","16.67422","0.33663"
"200.25600","16.68815","0.31468"
"200.42400","16.70221","0.34258"
"200.59200","16.71626","0.33043"
"200.76000","16.73019","0.34601"
"200.92800","16.74424","0.33901"
"201.09600","16.75829","0.34755"
"201.26400","16.77216","0.34440"
"201.43200","16.78615","0.34910"
"201.60000","16.80020","0.34631"
"201.76800","16.81425","0.35124"
"201.93600","16.82818","0.34822"
"202.10400","16.84223","0.35474"
"202.27200","16.85622","0.35072"
"202.44000","16.87015","0.36011"
"202.60800","16.88421","0.35547"
"202.77600","16.89826","0.36359"
"202.94400","16.91219","0.36244"
"203.11200","16.92624","0.37017"
"203.28000","16.94023","0.36918"
"203.44800","16.95416","0.37531"
"203.61600","16.96815","0.37933"
"203.78400","16.98226","0.38124"
"203.95200","16.99619","0.38860"
"204.12000","17.01018","0.38811"
"204.28800","17.02423","0.39500"
"204.45600","17.03816","0.39296"
"204.62400","17.05215","0.39980"
"204.79200","17.06627","0.39646"
"204.96000","17.08026","0.40441"
"205.12800","17.09413","0.40080"
"205.29600","17.10824","0.40947"
"205.46400","17.12223","0.40591"
"205.63200","17.13622","0.41332"
"205.80000","17.15021","0.41456"
"205.96800","17.16420","0.41614"
"206.13600","17.17819","0.42155"
"206.30400","17.19218","0.42079"
"206.47200","17.20617","0.42735"
"206.64000","17.22022","0.42509"
"206.80800","17.23415","0.43114"
"206.97600","17.24826","0.42971"
"207.14400","17.26219","0.43397"
"207.31200","17.27612","0.43355"
"207.48000","17.29024","0.43610"
"207.64800","17.30423","0.43790"
"207.81600","17.31822","0.43738"
"207.98400","17.33221","0.44186"
"208.15200","17.34626","0.22099"
"208.32000","17.36019","0.21448"
"208.48800","17.37418","0.24024"
"208.65600","17.38823","0.21193"
"208.82400","17.40216","0.23885"
"208.99200","17.41621","0.22200"
"209.16000","17.43020","0.23036"
"209.32800","17.44413","0.23340"
"209.49600","17.45819","0.22971"
"209.66400","17.47223","0.24511"
"209.83200","17.48623","0.23253"
"210.00000","17.50016","0.24730"
"210.16800","17.51427","0.23595"
"210.33600","17.52826","0.09055"
"210.50400","17.54219","0.10333"
"210.67200","17.55624","0.08994"
"210.84000","17.57023","0.09594"
"211.00800","17.58416","0.09878"
"211.17600","17.59821","0.09420"
"211.34400","17.61220","0.11203"
"211.51200","17.62619","0.10421"
"211.68000","17.64018","0.09372"
"211.84800","17.65423","0.11414"
"212.01600","17.66817","0.11342"
"212.18400","17.68216","0.10277"
"212.35200","17.69621","0.11461"
"212.52000","17.71020","0.11134"
"212.68800","17.72425","0.11324"
"212.85600","17.73824","0.12069"
"213.02400","17.75223","0.11373"
"213.19200","17.76610","0.11239"
"213.36000","17.78021","0.12250"
"213.52800","17.79426","0.11978"
"213.69600","17.80819","0.11866"
"213.86400","17.82218","0.12314"
"214.03200","17.83623","0.11909"
"214.20000","17.85016","0.12341"
"214.36800","17.86422","0.12703"
"214.53600","17.87821","0.12283"
"214.70400","17.89220","0.12612"
"214.87200","17.90619","0.12486"
"215.04000","17.92018","0.12473"
"215.20800","17.93423","0.12954"
"215.37600","17.94810","0.12782"
"215.54400","17.96227","0.12763"
"215.71200","17.97620","0.12972"
"215.88000","17.99019","0.12811"
"216.04800","18.00424","0.13052"
"216.21600","18.01817","0.13232"
"216.38400","18.03217","0.13098"
"216.55200","18.04622","0.13202"
"216.72000","18.06026","0.13218"
"216.88800","18.07420","0.13149"
"217.05600","18.08819","0.13407"
"217.22400","18.10218","0.13423"
"217.39200","18.11617","0.13404"
"217.56000","18.13016","0.13584"
"217.72800","18.14421","0.13411"
"217.89600","18.15820","0.13615"
"218.06400","18.17219","0.13756"
"218.23200","18.18624","0.13684"
"218.40000","18.20023","0.14048"
"218.56800","18.21422","0.13896"
"218.73600","18.22827","0.13974"
"218.90400","18.24220","0.14149"
"219.07200","18.25620","0.14005"
"219.24000","18.27019","0.14348"
"219.40800","18.28418","0.14558"
"219.57600","18.29817","0.14600"
"219.74400","18.31216","0.14914"
"219.91200","18.32621","0.14954"
"220.08000","18.34020","0.14895"
"220.24800","18.35413","0.15344"
"220.41600","18.36824","0.15188"
"220.58400","18.38229","0.15585"
"220.75200","18.39616","0.15881"
"220.92000","18.41027","0.15972"
"221.08800","18.42420","0.16541"
"221.25600","18.43814","0.16297"
"221.42400","18.45225","0.16780"
"221.59200","18.46624","0.16962"
"221.76000","18.48017","0.16954"
"221.92800","18.49416","0.17456"
"222.09600","18.50821","0.17442"
"222.26400","18.52220","0.17809"
"222.43200","18.53619","0.18180"
"222.60000","18.55030","0.18264"
"222.76800","18.56423","0.18407"
"222.93600","18.57816","0.18639"
"223.10400","18.59221","0.18649"
"223.27200","18.60626","0.18908"
"223.44000","18.62020","0.18840"
"223.60800","18.63424","0.18961"
"223.77600","18.64824","0.19034"
"223.94400","18.66217","0.19108"
"224.11200","18.67622","0.19213"
"224.28000","18.69015","0.19268"
"224.44800","18.70420","0.19333"
"224.61600","18.71825","0.19421"
"224.78400","18.73224","0.19504"
"224.95200","18.74617","0.19588"
"225.12000","18.76016","0.19687"
"225.28800","18.77421","0.19794"
"225.45600","18.78820","0.19946"
"225.62400","18.80219","0.19958"
"225.79200","18.81624","0.20201"
"225.96000","18.83018","0.20191"
"226.12800","18.84411","0.20384"
"226.29600","18.85822","0.20538"
"226.46400","18.87221","0.20659"
"226.63200","18.88620","0.20909"
"226.80000","18.90019","0.20991"
"226.96800","18.91424","0.21224"
"227.13600","18.92817","0.21222"
"227.30400","18.94222","0.21398"
"227.47200","18.95621","0.21540"
"227.64000","18.97020","0.21662"
"227.80800","18.98419","0.21798"
"227.97600","18.99818","0.21993"
"228.14400","19.01217","0.22050"
"228.31200","19.02617","0.22319"
"228.48000","19.04028","0.22352"
"228.64800","19.05427","0.22515"
"228.81600","19.06814","0.22587"
"228.98400","19.08225","0.22745"
"229.15200","19.09624","0.22805"
"229.32000","19.11017","0.22922"
"229.48800","19.12422","0.23018"
"229.65600","19.13821","0.23080"
"229.82400","19.15220","0.23165"
"229.99200","19.16613","0.23268"
"230.16000","19.18018","0.23278"
"230.32800","19.19417","0.23401"
"230.49600","19.20823","0.23443"
"230.66400","19.22222","0.23498"
"230.83200","19.23621","0.23571"
"231.00000","19.25020","0.23634"
"231.16800","19.26419","0.23677"
"231.33600","19.27824","0.23744"
"231.50400","19.29217","0.23785"
"231.67200","19.30622","0.23837"
"231.84000","19.32021","0.23874"
"232.00800","19.33414","0.23924"
"232.17600","19.34819","0.23950"
"232.34400","19.36218","0.24029"
"232.51200","19.37617","0.24049"
"232.68000","19.39016","0.24127"
"232.84800","19.40421","0.24175"
"233.01600","19.41821","0.24226"
"233.18400","19.43214","0.24268"
"233.35200","19.44625","0.24361"
"233.52000","19.46024","0.24411"
"233.68800","19.47417","0.24461"
"233.85600","19.48822","0.24589"
"234.02400","19.50221","0.24646"
"234.19200","19.51620","0.24735"
"234.36000","19.53025","0.24856"
"234.52800","19.54418","0.25025"
"234.69600","19.55817","0.25123"
"234.86400","19.57228","0.25375"
"235.03200","19.58621","0.25456"
"235.20000","19.60015","0.25587"
"235.36800","19.61419","0.25848"
"235.53600","19.62818","0.25990"
"235.70400","19.64218","0.26173"
"235.87200","19.65617","0.26356"
"236.04000","19.67016","0.26540"
"236.20800","19.68421","0.26640"
"236.37600","19.69820","0.26719"
"236.54400","19.71225","0.26843"
"236.71200","19.72618","0.26955"
"236.88000","19.74011","0.27173"
"237.04800","19.75422","0.27273"
"237.21600","19.76827","0.27532"
"237.38400","19.78220","0.27634"
"237.55200","19.79625","0.27829"
"237.72000","19.81025","0.27948"
"237.88800","19.82418","0.28053"
"238.05600","19.83817","0.28144"
"238.22400","19.85228","0.28272"
"238.39200","19.86621","0.28384"
"238.56000","19.88014","0.28443"
"238.72800","19.89425","0.28584"
"238.89600","19.90824","0.28663"
"239.06400","19.92217","0.28737"
"239.23200","19.93628","0.28823"
"239.40000","19.95027","0.28966"
"239.56800","19.96414","0.29078"
"239.73600","19.97825","0.29203"
"239.90400","19.99224","0.29335"
"240.07200","20.00618","0.29535"
"240.24000","20.02022","0.29721"
"240.40800","20.03422","0.29904"
"240.57600","20.04821","0.30213"
"240.74400","20.06220","0.30360"
"240.91200","20.07619","0.30708"
"241.08000","20.09018","0.31023"
"241.24800","20.10417","0.31303"
"241.41600","20.11822","0.31592"
"241.58400","20.13215","0.31880"
"241.75200","20.14608","0.32081"
"241.92000","20.16019","0.32290"
"242.08800","20.17424","0.32543"
"242.25600","20.18818","0.32711"
"242.42400","20.20222","0.32917"
"242.59200","20.21622","0.33072"
"242.76000","20.23021","0.33236"
"242.92800","20.24420","0.33398"
"243.09600","20.25825","0.33363"
"243.26400","20.27218","-0.00995"
"243.43200","20.28617","-0.00412"
"243.60000","20.30022","0.00094"
"243.76800","20.31415","0.00120"
"243.93600","20.32820","0.00197"
"244.10400","20.34225","0.00374"
"244.27200","20.35624","0.00464"
"244.44000","20.37017","0.00387"
"244.60800","20.38423","0.00395"
"244.77600","20.39822","0.00511"
"244.94400","20.41215","0.00422"
"245.11200","20.42625","0.00444"
"245.28000","20.44025","0.00465"
"245.44800","20.45412","0.00481"
"245.61600","20.46823","0.00435"
"245.78400","20.48222","0.00432"
"245.95200","20.49615","0.00519"
"246.12000","20.51020","0.00446"
"246.28800","20.52425","0.00467"
"246.45600","20.53824","0.00448"
"246.62400","20.55217","0.00422"
"246.79200","20.56623","0.00372"
"246.96000","20.58022","0.00425"
"247.12800","20.59421","0.00473"
"247.29600","20.60826","0.00444"
"247.46400","20.62219","0.00432"
"247.63200","20.63612","0.00481"
"247.80000","20.65017","0.00455"
"247.86200","20.65537","0.00464"