File: Force_trajectories/170212_3/Specimen_RawData_1.csv
End date,"2/12/2017"
Specimen label,"13BG_8"
Maximum Load,"0.33378",N

Time,Extension,Load
(s),(mm),(N)
"0.00000","0.00000","0.00053"
"0.25800","0.02039","0.00175"
"0.51600","0.04323","0.00191"
"0.77400","0.06469","0.00287"
"1.03200","0.08616","0.00273"
"1.29000","0.10774","0.00295"
"1.54800","0.12915","0.00312"
"1.80600","0.15073","0.00380"
"2.06400","0.17219","0.00427"
"2.32200","0.19372","0.00424"
"2.58000","0.21524","0.00448"
"2.83800","0.23671","0.00481"
"3.09600","0.25817","0.00519"
"3.35400","0.27970","0.00479"
"3.61200","0.30116","0.00516"
"3.87000","0.32268","0.00564"
"4.12800","0.34421","0.00572"
"4.38600","0.36561","0.00594"
"4.64400","0.38720","0.00529"
"4.90200","0.40866","0.00662"
"5.16000","0.43019","0.00654"
"5.41800","0.45165","0.00641"
"5.67600","0.47311","0.00618"
"5.93400","0.49458","0.00696"
"6.19200","0.51616","0.00609"
"6.45000","0.53763","0.00679"
"6.70800","0.55921","0.00655"
"6.96600","0.58068","0.00694"
"7.22400","0.60220","0.00704"
"7.48200","0.62366","0.00760"
"7.74000","0.64519","0.00749"
"7.99800","0.66665","0.00724"
"8.25600","0.68818","0.00696"
"8.51400","0.70964","0.00763"
"8.77200","0.73117","0.00793"
"9.03000","0.75269","0.00766"
"9.28800","0.77421","0.00756"
"9.54600","0.79568","0.00844"
"9.80400","0.81714","0.00853"
"10.06200","0.83867","0.00790"
"10.32000","0.86019","0.00870"
"10.57800","0.88172","0.00872"
"10.83600","0.90312","0.00848"
"11.09400","0.92470","0.00866"
"11.35200","0.94611","0.00921"
"11.61000","0.96775","0.00883"
"11.86800","0.98916","0.00893"
"12.12600","1.01068","0.00891"
"12.38400","1.03209","0.00926"
"12.64200","1.05373","0.00882"
"12.90000","1.07514","0.00931"
"13.15800","1.09672","0.00907"
"13.41600","1.11812","0.00949"
"13.67400","1.13971","0.00939"
"13.93200","1.16117","0.01013"
"14.19000","1.18270","0.01034"
"14.44800","1.20416","0.01024"
"14.70600","1.22563","0.01020"
"14.96400","1.24715","0.00995"
"15.22200","1.26867","0.00975"
"15.48000","1.29020","0.00990"
"15.73800","1.31166","0.01041"
"15.99600","1.33319","0.01004"
"16.25400","1.35465","0.01010"
"16.51200","1.37618","0.00973"
"16.77000","1.39764","0.01063"
"17.02800","1.41916","0.01088"
"17.28600","1.44063","0.01076"
"17.54400","1.46221","0.01038"
"17.80200","1.48368","0.01008"
"18.06000","1.50526","0.01059"
"18.31800","1.52661","0.01072"
"18.57600","1.54819","0.01092"
"18.83400","1.56959","0.01137"
"19.09200","1.59118","0.01098"
"19.35000","1.61264","0.01091"
"19.60800","1.63423","0.01082"
"19.86600","1.65563","0.01130"
"20.12400","1.67722","0.01100"
"20.38200","1.69862","0.01067"
"20.64000","1.72014","0.01169"
"20.89800","1.74167","0.01118"
"21.15600","1.76313","0.01125"
"21.41400","1.78466","0.01126"
"21.67200","1.80618","0.01140"
"21.93000","1.82771","0.01151"
"22.18800","1.84917","0.01132"
"22.44600","1.87069","0.01107"
"22.70400","1.89216","0.01105"
"22.96200","1.91368","0.01120"
"23.22000","1.93521","0.01091"
"23.47800","1.95667","0.01130"
"23.73600","1.97814","0.01162"
"23.99400","1.99972","0.01097"
"24.25200","2.02113","0.01203"
"24.51000","2.04271","0.01108"
"24.76800","2.06411","0.01108"
"25.02600","2.08564","0.01092"
"25.28400","2.10710","0.01193"
"25.54200","2.12869","0.01126"
"25.80000","2.15015","0.01199"
"26.05800","2.17168","0.01201"
"26.31600","2.19314","0.01172"
"26.57400","2.21472","0.01170"
"26.83200","2.23619","0.01148"
"27.09000","2.25771","0.01220"
"27.34800","2.27912","0.01184"
"27.60600","2.30070","0.01183"
"27.86400","2.32223","0.01180"
"28.12200","2.34369","0.01139"
"28.38000","2.36515","0.01212"
"28.63800","2.38668","0.01144"
"28.89600","2.40814","0.01114"
"29.15400","2.42967","0.01116"
"29.41200","2.45119","0.01145"
"29.67000","2.47266","0.01142"
"29.92800","2.49418","0.01185"
"30.18600","2.51558","0.01145"
"30.44400","2.53723","0.01130"
"30.70200","2.55863","0.01155"
"30.96000","2.58022","0.01147"
"31.21800","2.60162","0.01234"
"31.47600","2.62315","0.01199"
"31.73400","2.64461","0.01196"
"31.99200","2.66613","0.01206"
"32.25000","2.68766","0.01222"
"32.50800","2.70918","0.01241"
"32.76600","2.73065","0.01170"
"33.02400","2.75217","0.01228"
"33.28200","2.77364","0.01243"
"33.54000","2.79522","0.01303"
"33.79800","2.81662","0.01249"
"34.05600","2.83821","0.01265"
"34.31400","2.85967","0.01240"
"34.57200","2.88120","0.01303"
"34.83000","2.90272","0.01310"
"35.08800","2.92419","0.01326"
"35.34600","2.94571","0.01355"
"35.60400","2.96718","0.01371"
"35.86200","2.98870","0.01279"
"36.12000","3.01016","0.01333"
"36.37800","3.03169","0.01350"
"36.63600","3.05309","0.01289"
"36.89400","3.07468","0.01366"
"37.15200","3.09608","0.01378"
"37.41000","3.11773","0.01201"
"37.66800","3.13913","0.01301"
"37.92600","3.16065","0.01304"
"38.18400","3.18212","0.01269"
"38.44200","3.20370","0.01308"
"38.70000","3.22517","0.01352"
"38.95800","3.24669","0.01389"
"39.21600","3.26816","0.01364"
"39.47400","3.28968","0.01396"
"39.73200","3.31114","0.01403"
"39.99000","3.33267","0.01349"
"40.24800","3.35413","0.01422"
"40.50600","3.37566","0.01368"
"40.76400","3.39718","0.01390"
"41.02200","3.41865","0.01444"
"41.28000","3.44017","0.01389"
"41.53800","3.46163","0.01478"
"41.79600","3.48322","0.01452"
"42.05400","3.50468","0.01483"
"42.31200","3.52621","0.01478"
"42.57000","3.54767","0.01553"
"42.82800","3.56920","0.01486"
"43.08600","3.59066","0.01487"
"43.34400","3.61218","0.01523"
"43.60200","3.63359","0.01520"
"43.86000","3.65517","0.01518"
"44.11800","3.67664","0.01611"
"44.37600","3.69816","0.01611"
"44.63400","3.71957","0.01580"
"44.89200","3.74121","0.01543"
"45.15000","3.76262","0.01561"
"45.40800","3.78420","0.01571"
"45.66600","3.80566","0.01563"
"45.92400","3.82725","0.01628"
"46.18200","3.84871","0.01649"
"46.44000","3.87018","0.01692"
"46.69800","3.89164","0.01714"
"46.95600","3.91317","0.01696"
"47.21400","3.93469","0.01696"
"47.47200","3.95615","0.01671"
"47.73000","3.97768","0.01616"
"47.98800","3.99914","0.01668"
"48.24600","4.02073","0.01696"
"48.50400","4.04213","0.01682"
"48.76200","4.06372","0.01719"
"49.02000","4.08512","0.01738"
"49.27800","4.10670","0.01687"
"49.53600","4.12811","0.01786"
"49.79400","4.14969","0.01742"
"50.05200","4.17116","0.01731"
"50.31000","4.19268","0.01789"
"50.56800","4.21415","0.01841"
"50.82600","4.23573","0.01787"
"51.08400","4.25713","0.01878"
"51.34200","4.27872","0.01863"
"51.60000","4.30012","0.01855"
"51.85800","4.32165","0.01824"
"52.11600","4.34311","0.01893"
"52.37400","4.36470","0.01751"
"52.63200","4.38616","0.01789"
"52.89000","4.40768","0.01845"
"53.14800","4.42915","0.01796"
"53.40600","4.45067","0.01895"
"53.66400","4.47220","0.01935"
"53.92200","4.49366","0.01883"
"54.18000","4.51519","0.01901"
"54.43800","4.53659","0.02011"
"54.69600","4.55817","0.01936"
"54.95400","4.57970","0.01938"
"55.21200","4.60122","0.02021"
"55.47000","4.62263","0.01962"
"55.72800","4.64415","0.02009"
"55.98600","4.66562","0.01990"
"56.24400","4.68714","0.01962"
"56.50200","4.70860","0.02003"
"56.76000","4.73019","0.02022"
"57.01800","4.75165","0.02059"
"57.27600","4.77318","0.02053"
"57.53400","4.79464","0.02040"
"57.79200","4.81623","0.02079"
"58.05000","4.83769","0.02109"
"58.30800","4.85916","0.02062"
"58.56600","4.88068","0.02184"
"58.82400","4.90214","0.02087"
"59.08200","4.92367","0.02176"
"59.34000","4.94513","0.02112"
"59.59800","4.96660","0.02163"
"59.85600","4.98812","0.02172"
"60.11400","5.00964","0.02185"
"60.37200","5.03117","0.02225"
"60.63000","5.05263","0.02194"
"60.88800","5.07416","0.02203"
"61.14600","5.09574","0.02238"
"61.40400","5.11715","0.02188"
"61.66200","5.13867","0.02198"
"61.92000","5.16008","0.02235"
"62.17800","5.18166","0.02195"
"62.43600","5.20312","0.02243"
"62.69400","5.22471","0.02199"
"62.95200","5.24611","0.02161"
"63.21000","5.26764","0.02241"
"63.46800","5.28916","0.02204"
"63.72600","5.31069","0.02162"
"63.98400","5.33215","0.02089"
"64.24200","5.35367","0.02164"
"64.50000","5.37514","0.02180"
"64.75800","5.39666","0.02107"
"65.01600","5.41813","0.02033"
"65.27400","5.43971","0.02139"
"65.53200","5.46118","0.02150"
"65.79000","5.48270","0.02118"
"66.04800","5.50416","0.02137"
"66.30600","5.52569","0.02194"
"66.56400","5.54721","0.02154"
"66.82200","5.56862","0.02070"
"67.08000","5.59014","0.02167"
"67.33800","5.61161","0.02245"
"67.59600","5.63319","0.02194"
"67.85400","5.65465","0.02178"
"68.11200","5.67618","0.02244"
"68.37000","5.69764","0.02289"
"68.62800","5.71917","0.02347"
"68.88600","5.74063","0.02342"
"69.14400","5.76222","0.02328"
"69.40200","5.78362","0.02381"
"69.66000","5.80515","0.02358"
"69.91800","5.82667","0.02422"
"70.17600","5.84825","0.02449"
"70.43400","5.86966","0.02513"
"70.69200","5.89118","0.02521"
"70.95000","5.91265","0.02506"
"71.20800","5.93417","0.02508"
"71.46600","5.95564","0.02530"
"71.72400","5.97722","0.02612"
"71.98200","5.99862","0.02641"
"72.24000","6.02015","0.02642"
"72.49800","6.04173","0.02622"
"72.75600","6.06314","0.02657"
"73.01400","6.08472","0.02621"
"73.27200","6.10613","0.02613"
"73.53000","6.12771","0.02732"
"73.78800","6.14917","0.02612"
"74.04600","6.17076","0.02680"
"74.30400","6.19216","0.02750"
"74.56200","6.21369","0.02801"
"74.82000","6.23509","0.02736"
"75.07800","6.25668","0.02844"
"75.33600","6.27814","0.02848"
"75.59400","6.29966","0.02889"
"75.85200","6.32113","0.02878"
"76.11000","6.34265","0.02883"
"76.36800","6.36412","0.02880"
"76.62600","6.38570","0.02883"
"76.88400","6.40711","0.02904"
"77.14200","6.42869","0.02925"
"77.40000","6.45015","0.02835"
"77.65800","6.47168","0.02827"
"77.91600","6.49320","0.02875"
"78.17400","6.51473","0.02898"
"78.43200","6.53619","0.02886"
"78.69000","6.55766","0.02919"
"78.94800","6.57918","0.02872"
"79.20600","6.60065","0.02901"
"79.46400","6.62217","0.02978"
"79.72200","6.64363","0.03003"
"79.98000","6.66522","0.03064"
"80.23800","6.68656","0.03077"
"80.49600","6.70821","0.03046"
"80.75400","6.72961","0.03154"
"81.01200","6.75119","0.03163"
"81.27000","6.77266","0.03143"
"81.52800","6.79418","0.03173"
"81.78600","6.81565","0.03164"
"82.04400","6.83723","0.03208"
"82.30200","6.85864","0.03201"
"82.56000","6.88016","0.03179"
"82.81800","6.90157","0.03216"
"83.07600","6.92321","0.03256"
"83.33400","6.94473","0.03291"
"83.59200","6.96620","0.03313"
"83.85000","6.98766","0.03288"
"84.10800","7.00919","0.03360"
"84.36600","7.03065","0.03368"
"84.62400","7.05218","0.03395"
"84.88200","7.07364","0.03335"
"85.14000","7.09522","0.03307"
"85.39800","7.11669","0.03285"
"85.65600","7.13821","0.03324"
"85.91400","7.15968","0.03364"
"86.17200","7.18114","0.03360"
"86.43000","7.20267","0.03386"
"86.68800","7.22413","0.03390"
"86.94600","7.24571","0.03417"
"87.20400","7.26712","0.03423"
"87.46200","7.28870","0.03452"
"87.72000","7.31011","0.03506"
"87.97800","7.33163","0.03488"
"88.23600","7.35310","0.03484"
"88.49400","7.37474","0.03537"
"88.75200","7.39614","0.03548"
"89.01000","7.41773","0.03528"
"89.26800","7.43913","0.03529"
"89.52600","7.46072","0.03574"
"89.78400","7.48218","0.03587"
"90.04200","7.50365","0.03577"
"90.30000","7.52517","0.03631"
"90.55800","7.54669","0.03644"
"90.81600","7.56822","0.03651"
"91.07400","7.58968","0.03682"
"91.33200","7.61121","0.03686"
"91.59000","7.63261","0.03724"
"91.84800","7.65420","0.03716"
"92.10600","7.67566","0.03747"
"92.36400","7.69712","0.03739"
"92.62200","7.71865","0.03759"
"92.88000","7.74023","0.03797"
"93.13800","7.76164","0.03771"
"93.39600","7.78322","0.03815"
"93.65400","7.80463","0.03813"
"93.91200","7.82615","0.03857"
"94.17000","7.84762","0.03879"
"94.42800","7.86914","0.03825"
"94.68600","7.89066","0.03840"
"94.94400","7.91219","0.03889"
"95.20200","7.93359","0.03924"
"95.46000","7.95524","0.03880"
"95.71800","7.97664","0.03921"
"95.97600","7.99823","0.03953"
"96.23400","8.01963","0.03958"
"96.49200","8.04121","0.03989"
"96.75000","8.06268","0.03998"
"97.00800","8.08420","0.04019"
"97.26600","8.10573","0.04049"
"97.52400","8.12719","0.04090"
"97.78200","8.14865","0.04110"
"98.04000","8.17018","0.04130"
"98.29800","8.19170","0.04194"
"98.55600","8.21317","0.04235"
"98.81400","8.23469","0.04233"
"99.07200","8.25610","0.04288"
"99.33000","8.27768","0.04317"
"99.58800","8.29915","0.04386"
"99.84600","8.32073","0.04399"
"100.10400","8.34213","0.04426"
"100.36200","8.36366","0.04510"
"100.62000","8.38512","0.04524"
"100.87800","8.40671","0.04586"
"101.13600","8.42823","0.04630"
"101.39400","8.44970","0.04658"
"101.65200","8.47116","0.04693"
"101.91000","8.49269","0.04760"
"102.16800","8.51415","0.04845"
"102.42600","8.53573","0.04846"
"102.68400","8.55714","0.04960"
"102.94200","8.57866","0.04969"
"103.20000","8.60013","0.05065"
"103.45800","8.62165","0.05166"
"103.71600","8.64317","0.05172"
"103.97400","8.66470","0.05305"
"104.23200","8.68622","0.05335"
"104.49000","8.70769","0.05431"
"104.74800","8.72915","0.05384"
"105.00600","8.75068","0.05497"
"105.26400","8.77220","0.05534"
"105.52200","8.79361","0.05541"
"105.78000","8.81525","0.05713"
"106.03800","8.83665","0.05762"
"106.29600","8.85818","0.05822"
"106.55400","8.87964","0.05868"
"106.81200","8.90117","0.05966"
"107.07000","8.92263","0.06035"
"107.32800","8.94416","0.06063"
"107.58600","8.96562","0.06138"
"107.84400","8.98714","0.06232"
"108.10200","9.00861","0.06328"
"108.36000","9.03019","0.06315"
"108.61800","9.05166","0.06380"
"108.87600","9.07318","0.06504"
"109.13400","9.09465","0.06527"
"109.39200","9.11617","0.06577"
"109.65000","9.13769","0.06663"
"109.90800","9.15916","0.06744"
"110.16600","9.18074","0.06811"
"110.42400","9.20215","0.06853"
"110.68200","9.22367","0.06956"
"110.94000","9.24514","0.06989"
"111.19800","9.26666","0.07168"
"111.45600","9.28813","0.07260"
"111.71400","9.30965","0.07312"
"111.97200","9.33111","0.07384"
"112.23000","9.35270","0.07460"
"112.48800","9.37416","0.07602"
"112.74600","9.39569","0.07633"
"113.00400","9.41709","0.07779"
"113.26200","9.43873","0.07859"
"113.52000","9.46020","0.07935"
"113.77800","9.48172","0.08025"
"114.03600","9.50319","0.08129"
"114.29400","9.52465","0.08234"
"114.55200","9.54612","0.08287"
"114.81000","9.56770","0.08416"
"115.06800","9.58922","0.08434"
"115.32600","9.61069","0.08512"
"115.58400","9.63209","0.08506"
"115.84200","9.65362","0.08592"
"116.10000","9.67520","0.08639"
"116.35800","9.69673","0.08671"
"116.61600","9.71819","0.08731"
"116.87400","9.73966","0.08779"
"117.13200","9.76124","0.08776"
"117.39000","9.78270","0.08845"
"117.64800","9.80423","0.08874"
"117.90600","9.82563","0.08884"
"118.16400","9.84716","0.08922"
"118.42200","9.86862","0.08981"
"118.68000","9.89020","0.09026"
"118.93800","9.91167","0.08990"
"119.19600","9.93319","0.09028"
"119.45400","9.95466","0.09090"
"119.71200","9.97612","0.09124"
"119.97000","9.99765","0.09231"
"120.22800","10.01923","0.09340"
"120.48600","10.04064","0.09396"
"120.74400","10.06216","0.09535"
"121.00200","10.08368","0.09623"
"121.26000","10.10521","0.09649"
"121.51800","10.12667","0.09854"
"121.77600","10.14820","0.09919"
"122.03400","10.16960","0.10060"
"122.29200","10.19118","0.10110"
"122.55000","10.21265","0.10319"
"122.80800","10.23423","0.10436"
"123.06600","10.25570","0.10466"
"123.32400","10.27716","0.10684"
"123.58200","10.29869","0.10750"
"123.84000","10.32015","0.10835"
"124.09800","10.34174","0.10949"
"124.35600","10.36308","0.11122"
"124.61400","10.38472","0.11156"
"124.87200","10.40613","0.11253"
"125.13000","10.42771","0.11315"
"125.38800","10.44918","0.11449"
"125.64600","10.47070","0.11607"
"125.90400","10.49211","0.11672"
"126.16200","10.51363","0.11746"
"126.42000","10.53515","0.11888"
"126.67800","10.55674","0.11969"
"126.93600","10.57814","0.12054"
"127.19400","10.59967","0.12126"
"127.45200","10.62113","0.12174"
"127.71000","10.64272","0.12256"
"127.96800","10.66418","0.12349"
"128.22600","10.68565","0.12430"
"128.48400","10.70711","0.12504"
"128.74200","10.72869","0.12599"
"129.00000","10.75016","0.12602"
"129.25800","10.77168","0.12709"
"129.51600","10.79315","0.12718"
"129.77400","10.81461","0.12791"
"130.03200","10.83619","0.12867"
"130.29000","10.85766","0.12878"
"130.54800","10.87918","0.12968"
"130.80600","10.90059","0.12998"
"131.06400","10.92217","0.13055"
"131.32200","10.94358","0.13081"
"131.58000","10.96522","0.13112"
"131.83800","10.98669","0.13207"
"132.09600","11.00821","0.13239"
"132.35400","11.02967","0.13316"
"132.61200","11.05120","0.13365"
"132.87000","11.07260","0.13425"
"133.12800","11.09419","0.13469"
"133.38600","11.11565","0.13514"
"133.64400","11.13724","0.13544"
"133.90200","11.15864","0.13607"
"134.16000","11.18016","0.13632"
"134.41800","11.20169","0.13686"
"134.67600","11.22315","0.13749"
"134.93400","11.24468","0.13785"
"135.19200","11.26614","0.13887"
"135.45000","11.28767","0.13932"
"135.70800","11.30919","0.14029"
"135.96600","11.33071","0.14057"
"136.22400","11.35218","0.14185"
"136.48200","11.37370","0.14201"
"136.74000","11.39517","0.14289"
"136.99800","11.41669","0.14401"
"137.25600","11.43810","0.14486"
"137.51400","11.45968","0.14596"
"137.77200","11.48115","0.14744"
"138.03000","11.50267","0.14917"
"138.28800","11.52413","0.15056"
"138.54600","11.54566","0.15246"
"138.80400","11.56712","0.15450"
"139.06200","11.58871","0.15648"
"139.32000","11.61017","0.15880"
"139.57800","11.63175","0.16065"
"139.83600","11.65310","0.16268"
"140.09400","11.67468","0.16571"
"140.35200","11.69621","0.16698"
"140.61000","11.71767","0.16971"
"140.86800","11.73920","0.17207"
"141.12600","11.76060","0.17481"
"141.38400","11.78212","0.17631"
"141.64200","11.80365","0.17887"
"141.90000","11.82517","0.18082"
"142.15800","11.84664","0.18304"
"142.41600","11.86816","0.18241"
"142.67400","11.88963","0.18376"
"142.93200","11.91121","0.18592"
"143.19000","11.93267","0.18800"
"143.44800","11.95420","0.18886"
"143.70600","11.97561","0.18993"
"143.96400","11.99719","0.19114"
"144.22200","12.01865","0.19208"
"144.48000","12.04018","0.19231"
"144.73800","12.06164","0.19304"
"144.99600","12.08317","0.19373"
"145.25400","12.10469","0.19445"
"145.51200","12.12621","0.19482"
"145.77000","12.14762","0.19586"
"146.02800","12.16920","0.19655"
"146.28600","12.19061","0.19786"
"146.54400","12.21219","0.19910"
"146.80200","12.23366","0.20110"
"147.06000","12.25524","0.20244"
"147.31800","12.27670","0.20331"
"147.57600","12.29817","0.20524"
"147.83400","12.31963","0.20618"
"148.09200","12.34116","0.20786"
"148.35000","12.36274","0.20939"
"148.60800","12.38415","0.21036"
"148.86600","12.40567","0.21229"
"149.12400","12.42714","0.21452"
"149.38200","12.44866","0.21609"
"149.64000","12.47012","0.21722"
"149.89800","12.49165","0.21816"
"150.15600","12.51311","0.21976"
"150.41400","12.53470","0.22184"
"150.67200","12.55616","0.22361"
"150.93000","12.57774","0.22513"
"151.18800","12.59915","0.22685"
"151.44600","12.62061","0.22806"
"151.70400","12.64214","0.22965"
"151.96200","12.66366","0.23084"
"152.22000","12.68519","0.23156"
"152.47800","12.70671","0.23258"
"152.73600","12.72818","0.23306"
"152.99400","12.74970","0.23397"
"153.25200","12.77116","0.23482"
"153.51000","12.79269","0.00928"
"153.76800","12.81415","0.01538"
"154.02600","12.83568","0.02568"
"154.28400","12.85714","0.02082"
"154.54200","12.87866","0.02888"
"154.80000","12.90019","0.02272"
"155.05800","12.92165","0.02841"
"155.31600","12.94318","0.02465"
"155.57400","12.96464","0.02973"
"155.83200","12.98617","0.02599"
"156.09000","13.00763","0.02952"
"156.34800","13.02922","0.02825"
"156.60600","13.05062","0.02909"
"156.86400","13.07220","0.03052"
"157.12200","13.09367","0.02934"
"157.38000","13.11519","0.03162"
"157.63800","13.13666","0.03028"
"157.89600","13.15818","0.03276"
"158.15400","13.17965","0.02971"
"158.41200","13.20117","0.03419"
"158.67000","13.22269","0.03057"
"158.92800","13.24410","0.03476"
"159.18600","13.26562","0.03136"
"159.44400","13.28721","0.03547"
"159.70200","13.30867","0.03209"
"159.96000","13.33020","0.03596"
"160.21800","13.35166","0.03285"
"160.47600","13.37313","0.03578"
"160.73400","13.39471","0.03332"
"160.99200","13.41611","0.03532"
"161.25000","13.43770","0.03424"
"161.50800","13.45916","0.03586"
"161.76600","13.48069","0.03527"
"162.02400","13.50215","0.03599"
"162.28200","13.52367","0.03622"
"162.54000","13.54514","0.03552"
"162.79800","13.56666","0.03680"
"163.05600","13.58813","0.03573"
"163.31400","13.60965","0.03712"
"163.57200","13.63118","0.03624"
"163.83000","13.65270","0.03798"
"164.08800","13.67411","0.03720"
"164.34600","13.69569","0.03785"
"164.60400","13.71715","0.03745"
"164.86200","13.73874","0.03859"
"165.12000","13.76014","0.03779"
"165.37800","13.78167","0.03866"
"165.63600","13.80313","0.03873"
"165.89400","13.82472","0.03887"
"166.15200","13.84618","0.03892"
"166.41000","13.86764","0.03942"
"166.66800","13.88917","0.03947"
"166.92600","13.91063","0.03971"
"167.18400","13.93222","0.04005"
"167.44200","13.95368","0.03995"
"167.70000","13.97520","0.04048"
"167.95800","13.99661","0.04039"
"168.21600","14.01819","0.04108"
"168.47400","14.03966","0.04072"
"168.73200","14.06118","0.04132"
"168.99000","14.08259","0.04126"
"169.24800","14.10417","0.04170"
"169.50600","14.12564","0.04155"
"169.76400","14.14722","0.04199"
"170.02200","14.16862","0.04264"
"170.28000","14.19015","0.04262"
"170.53800","14.21167","0.04289"
"170.79600","14.23320","0.04268"
"171.05400","14.25466","0.04375"
"171.31200","14.27625","0.04382"
"171.57000","14.29765","0.04431"
"171.82800","14.31918","0.04392"
"172.08600","14.34058","0.04551"
"172.34400","14.36216","0.04560"
"172.60200","14.38369","0.04693"
"172.86000","14.40521","0.04651"
"173.11800","14.42668","0.04745"
"173.37600","14.44820","0.04826"
"173.63400","14.46967","0.04832"
"173.89200","14.49113","0.04846"
"174.15000","14.51271","0.04864"
"174.40800","14.53412","0.05012"
"174.66600","14.55570","0.05046"
"174.92400","14.57711","0.05158"
"175.18200","14.59869","0.05157"
"175.44000","14.62010","0.05155"
"175.69800","14.64168","0.05238"
"175.95600","14.66314","0.05364"
"176.21400","14.68467","0.05503"
"176.47200","14.70613","0.05555"
"176.73000","14.72766","0.05694"
"176.98800","14.74912","0.05800"
"177.24600","14.77071","0.05866"
"177.50400","14.79217","0.05895"
"177.76200","14.81369","0.05950"
"178.02000","14.83510","0.06077"
"178.27800","14.85668","0.06113"
"178.53600","14.87815","0.06222"
"178.79400","14.89967","0.06361"
"179.05200","14.92120","0.06446"
"179.31000","14.94266","0.06504"
"179.56800","14.96412","0.06583"
"179.82600","14.98565","0.06695"
"180.08400","15.00717","0.06703"
"180.34200","15.02864","0.06867"
"180.60000","15.05016","0.06940"
"180.85800","15.07163","0.07052"
"181.11600","15.09321","0.07063"
"181.37400","15.11462","0.07259"
"181.63200","15.13614","0.07330"
"181.89000","15.15760","0.07461"
"182.14800","15.17919","0.07565"
"182.40600","15.20059","0.07737"
"182.66400","15.22224","0.07847"
"182.92200","15.24364","0.07951"
"183.18000","15.26517","0.08058"
"183.43800","15.28663","0.08150"
"183.69600","15.30821","0.08240"
"183.95400","15.32968","0.08334"
"184.21200","15.35120","0.08447"
"184.47000","15.37261","0.08537"
"184.72800","15.39413","0.08611"
"184.98600","15.41566","0.08672"
"185.24400","15.43718","0.08753"
"185.50200","15.45870","0.08808"
"185.76000","15.48017","0.08885"
"186.01800","15.50169","0.08915"
"186.27600","15.52316","0.08958"
"186.53400","15.54468","0.09038"
"186.79200","15.56621","0.09053"
"187.05000","15.58767","0.09165"
"187.30800","15.60907","0.09278"
"187.56600","15.63066","0.09311"
"187.82400","15.65212","0.09505"
"188.08200","15.67371","0.09657"
"188.34000","15.69511","0.09757"
"188.59800","15.71663","0.09977"
"188.85600","15.73816","0.09503"
"189.11400","15.75974","0.09876"
"189.37200","15.78115","0.09939"
"189.63000","15.80267","0.10168"
"189.88800","15.82414","0.10448"
"190.14600","15.84572","0.10502"
"190.40400","15.86718","0.10872"
"190.66200","15.88871","0.10906"
"190.92000","15.91011","0.11161"
"191.17800","15.93164","0.11229"
"191.43600","15.95322","0.11379"
"191.69400","15.97469","0.11599"
"191.95200","15.99621","0.11675"
"192.21000","16.01762","0.11862"
"192.46800","16.03920","0.11901"
"192.72600","16.06072","0.12114"
"192.98400","16.08219","0.12210"
"193.24200","16.10359","0.12263"
"193.50000","16.12518","0.12416"
"193.75800","16.14664","0.12493"
"194.01600","16.16817","0.12599"
"194.27400","16.18963","0.12712"
"194.53200","16.21121","0.12776"
"194.79000","16.23262","0.12897"
"195.04800","16.25414","0.12985"
"195.30600","16.27567","0.13022"
"195.56400","16.29725","0.13096"
"195.82200","16.31866","0.13149"
"196.08000","16.34018","0.13199"
"196.33800","16.36164","0.13291"
"196.59600","16.38323","0.13375"
"196.85400","16.40469","0.13455"
"197.11200","16.42616","0.13501"
"197.37000","16.44762","0.13539"
"197.62800","16.46915","0.13614"
"197.88600","16.49061","0.13699"
"198.14400","16.51220","0.13770"
"198.40200","16.53372","0.13838"
"198.66000","16.55518","0.13931"
"198.91800","16.57665","0.14043"
"199.17600","16.59817","0.14197"
"199.43400","16.61970","0.14294"
"199.69200","16.64110","0.14403"
"199.95000","16.66269","0.14573"
"200.20800","16.68409","0.14772"
"200.46600","16.70573","0.14948"
"200.72400","16.72714","0.15194"
"200.98200","16.74866","0.15435"
"201.24000","16.77013","0.15601"
"201.49800","16.79171","0.15821"
"201.75600","16.81318","0.16182"
"202.01400","16.83476","0.16603"
"202.27200","16.85616","0.16702"
"202.53000","16.87769","0.17047"
"202.78800","16.89915","0.17675"
"203.04600","16.92068","0.17741"
"203.30400","16.94220","0.18148"
"203.56200","16.96367","0.18425"
"203.82000","16.98513","0.18716"
"204.07800","17.00665","0.18941"
"204.33600","17.02818","0.19118"
"204.59400","17.04964","0.19221"
"204.85200","17.07117","0.19317"
"205.11000","17.09263","0.19442"
"205.36800","17.11415","0.19557"
"205.62600","17.13568","0.19683"
"205.88400","17.15714","0.19856"
"206.14200","17.17861","0.20126"
"206.40000","17.20019","0.20237"
"206.65800","17.22166","0.20489"
"206.91600","17.24318","0.20752"
"207.17400","17.26459","0.21070"
"207.43200","17.28617","0.21333"
"207.69000","17.30764","0.21568"
"207.94800","17.32916","0.21822"
"208.20600","17.35062","0.22069"
"208.46400","17.37221","0.22253"
"208.72200","17.39367","0.22451"
"208.98000","17.41525","0.22706"
"209.23800","17.43666","0.22912"
"209.49600","17.45819","0.23094"
"209.75400","17.47971","0.23272"
"210.01200","17.50117","0.23440"
"210.27000","17.52270","0.23562"
"210.52800","17.54416","0.23638"
"210.78600","17.56569","0.23768"
"211.04400","17.58721","0.23840"
"211.30200","17.60868","0.23916"
"211.56000","17.63014","0.23983"
"211.81800","17.65172","0.24054"
"212.07600","17.67319","0.24170"
"212.33400","17.69471","0.24189"
"212.59200","17.71612","0.24318"
"212.85000","17.73764","0.24425"
"213.10800","17.75916","0.24510"
"213.36600","17.78069","0.24666"
"213.62400","17.80215","0.24685"
"213.88200","17.82368","0.24728"
"214.14000","17.84520","0.24903"
"214.39800","17.86673","0.25121"
"214.65600","17.88813","0.25245"
"214.91400","17.90972","0.25490"
"215.17200","17.93112","0.25815"
"215.43000","17.95264","0.26002"
"215.68800","17.97417","0.26236"
"215.94600","17.99569","0.26468"
"216.20400","18.01716","0.26738"
"216.46200","18.03868","0.26957"
"216.72000","18.06015","0.27132"
"216.97800","18.08167","0.27392"
"217.23600","18.10325","0.27688"
"217.49400","18.12466","0.27833"
"217.75200","18.14618","0.28089"
"218.01000","18.16765","0.28281"
"218.26800","18.18917","0.28434"
"218.52600","18.21064","0.28578"
"218.78400","18.23222","0.28732"
"219.04200","18.25362","0.28855"
"219.30000","18.27515","0.28945"
"219.55800","18.29661","0.29080"
"219.81600","18.31820","0.29280"
"220.07400","18.33966","0.29477"
"220.33200","18.36113","0.29674"
"220.59000","18.38265","0.30083"
"220.84800","18.40417","0.30468"
"221.10600","18.42564","0.30944"
"221.36400","18.44722","0.31209"
"221.62200","18.46863","0.31733"
"221.88000","18.49021","0.32224"
"222.13800","18.51168","0.32616"
"222.39600","18.53320","0.32895"
"222.65400","18.55473","0.33193"
"222.91200","18.57619","0.17263"
"223.17000","18.59765","0.17067"
"223.42800","18.61912","0.17954"
"223.68600","18.64070","0.17783"
"223.94400","18.66217","0.18472"
"224.20200","18.68369","0.18869"
"224.46000","18.70516","0.18739"
"224.71800","18.72662","0.19158"
"224.97600","18.74814","0.19304"
"225.23400","18.76967","0.19334"
"225.49200","18.79113","0.19603"
"225.75000","18.81272","0.19642"
"226.00800","18.83412","0.19791"
"226.26600","18.85571","0.20188"
"226.52400","18.87717","0.20364"
"226.78200","18.89869","0.20597"
"227.04000","18.92016","0.21008"
"227.29800","18.94174","0.21134"
"227.55600","18.96315","0.21369"
"227.81400","18.98467","0.21736"
"228.07200","19.00614","0.21854"
"228.33000","19.02772","0.22004"
"228.58800","19.04918","0.22333"
"228.84600","19.07071","0.22515"
"229.10400","19.09217","0.22660"
"229.36200","19.11370","0.23002"
"229.62000","19.13522","0.23155"
"229.87800","19.15669","0.23241"
"230.13600","19.17821","0.23434"
"230.39400","19.19962","0.23576"
"230.65200","19.22114","0.23613"
"230.91000","19.24266","0.23752"
"231.16800","19.26419","0.23855"
"231.42600","19.28565","0.23937"
"231.68400","19.30718","0.24032"
"231.94200","19.32864","0.24138"
"232.20000","19.35017","0.24229"
"232.45800","19.37169","0.24347"
"232.71600","19.39321","0.24455"
"232.97400","19.41462","0.24594"
"233.23200","19.43620","0.24733"
"233.49000","19.45767","0.24906"
"233.74800","19.47925","0.25130"
"234.00600","19.50066","0.00739"
"234.26400","19.52218","0.00745"
"234.52200","19.54364","0.00981"
"234.78000","19.56523","0.00710"
"235.03800","19.58669","0.01706"
"235.29600","19.60822","0.01488"
"235.55400","19.62962","0.00907"
"235.81200","19.65114","0.01891"
"236.07000","19.67267","0.01495"
"236.32800","19.69419","0.00909"
"236.58600","19.71572","0.01632"
"236.84400","19.73718","0.01388"
"237.10200","19.75871","0.01109"
"237.36000","19.78017","0.01690"
"237.61800","19.80169","0.01444"
"237.87600","19.82316","0.01217"
"238.13400","19.84468","0.01636"
"238.39200","19.86609","0.01524"
"238.65000","19.88767","0.01396"
"238.90800","19.90920","0.01681"
"239.16600","19.93072","0.01576"
"239.42400","19.95213","0.01526"
"239.68200","19.97371","0.01507"
"239.94000","19.99517","0.01603"
"240.19800","20.01676","0.01607"
"240.45600","20.03816","0.01495"
"240.71400","20.05963","0.01555"
"240.97200","20.08109","0.01668"
"241.23000","20.10267","0.01552"
"241.48800","20.12420","0.01668"
"241.74600","20.14573","0.01744"
"242.00400","20.16719","0.01608"
"242.26200","20.18865","0.01613"
"242.52000","20.21018","0.01687"
"242.77800","20.23164","0.01747"
"243.03600","20.25323","0.01734"
"243.29400","20.27463","0.01725"
"243.55200","20.29615","0.01818"
"243.81000","20.31762","0.01732"
"244.06800","20.33920","0.01730"
"244.32600","20.36067","0.01836"
"244.58400","20.38219","0.01818"
"244.84200","20.40360","0.01768"
"245.10000","20.42524","0.01768"
"245.35800","20.44665","0.01876"
"245.61600","20.46823","0.01877"
"245.87400","20.48964","0.01841"
"246.13200","20.51122","0.01876"
"246.39000","20.53268","0.01844"
"246.64800","20.55421","0.01907"
"246.90600","20.57567","0.01870"
"247.16400","20.59719","0.01918"
"247.42200","20.61866","0.01855"
"247.68000","20.64018","0.01993"
"247.93800","20.66171","0.01938"
"248.19600","20.68317","0.02026"
"248.45400","20.70464","0.01984"
"248.71200","20.72616","0.01970"
"248.97000","20.74762","0.02049"
"249.22800","20.76915","0.02021"
"249.48600","20.79067","0.02045"
"249.74400","20.81214","0.02024"
"250.00200","20.83372","0.02007"
"250.26000","20.85507","0.02078"
"250.51800","20.87665","0.02037"
"250.77600","20.89812","0.02089"
"251.03400","20.91964","0.02070"
"251.29200","20.94110","0.02119"
"251.55000","20.96269","0.02123"
"251.80800","20.98415","0.02116"
"252.06600","21.00574","0.02164"
"252.32400","21.02714","0.02168"
"252.58200","21.04873","0.02225"
"252.84000","21.07019","0.02246"
"253.09800","21.09171","0.02187"
"253.35600","21.11312","0.02208"
"253.61400","21.13464","0.02244"
"253.87200","21.15617","0.02203"
"254.13000","21.17763","0.02308"
"254.38800","21.19921","0.02299"
"254.64600","21.22062","0.02302"
"254.90400","21.24215","0.02277"
"255.16200","21.26367","0.02326"
"255.42000","21.28519","0.02364"
"255.67800","21.30666","0.02345"
"255.93600","21.32818","0.02363"
"256.19400","21.34958","0.02355"
"256.45200","21.37117","0.02364"
"256.71000","21.39270","0.02374"
"256.96800","21.41422","0.02373"
"257.22600","21.43562","0.02360"
"257.48400","21.45721","0.02429"
"257.74200","21.47861","0.02423"
"258.00000","21.50020","0.02434"
"258.25800","21.52166","0.02496"
"258.51600","21.54319","0.02441"
"258.77400","21.56459","0.02502"
"259.03200","21.58617","0.02537"
"259.29000","21.60764","0.02507"
"259.54800","21.62922","0.02473"
"259.80600","21.65063","0.02539"
"260.06400","21.67215","0.02521"
"260.32200","21.69368","0.02576"
"260.58000","21.71520","0.02546"
"260.83800","21.73672","0.02562"
"261.09600","21.75813","0.02537"
"261.35400","21.77971","0.02584"
"261.61200","21.80112","0.02620"
"261.87000","21.82270","0.02663"
"262.12800","21.84416","0.02617"
"262.38600","21.86569","0.02665"
"262.64400","21.88710","0.02647"
"262.90200","21.90868","0.02660"
"263.16000","21.93014","0.02599"
"263.41800","21.95167","0.02594"
"263.67600","21.97313","0.02626"
"263.93400","21.99466","0.02652"
"264.19200","22.01612","0.02566"
"264.45000","22.03770","0.02601"
"264.70800","22.05917","0.02639"
"264.96600","22.08069","0.02629"
"265.22400","22.10216","0.02602"
"265.48200","22.12374","0.02599"
"265.74000","22.14515","0.02699"
"265.99800","22.16673","0.02652"
"266.25600","22.18814","0.02724"
"266.51400","22.20966","0.02674"
"266.77200","22.23112","0.02678"
"267.03000","22.25265","0.02695"
"267.28800","22.27423","0.02647"
"267.54600","22.29570","0.02707"
"267.80400","22.31716","0.02737"
"268.06200","22.33862","0.02775"
"268.32000","22.36021","0.02797"
"268.57800","22.38161","0.02818"
"268.83600","22.40314","0.02823"
"269.09400","22.42460","0.02800"
"269.35200","22.44619","0.02826"
"269.61000","22.46759","0.02819"
"269.86800","22.48923","0.02830"
"270.12600","22.51064","0.02839"
"270.38400","22.53217","0.02860"
"270.64200","22.55363","0.02894"
"270.90000","22.57515","0.02860"
"271.15800","22.59662","0.02898"
"271.41600","22.61820","0.02951"
"271.67400","22.63967","0.02875"
"271.93200","22.66119","0.02834"
"272.19000","22.68271","0.02838"
"272.44800","22.70418","0.02841"
"272.70600","22.72564","0.02884"
"272.96400","22.74717","0.02831"
"273.22200","22.76869","0.02884"
"273.48000","22.79015","0.02946"
"273.73800","22.81168","0.02886"
"273.99600","22.83315","0.02903"
"274.25400","22.85467","0.02946"
"274.51200","22.87613","0.02919"
"274.77000","22.89766","0.02970"
"275.02800","22.91912","0.02968"
"275.28600","22.94071","0.02989"
"275.54400","22.96217","0.03021"
"275.80200","22.98369","0.03002"
"276.06000","23.00516","0.03059"
"276.31800","23.02668","0.03036"
"276.57600","23.04809","0.03021"
"276.83400","23.06967","0.03052"
"277.09200","23.09114","0.03092"
"277.35000","23.11272","0.03075"
"277.60800","23.13412","0.03123"
"277.86600","23.15571","0.03110"
"278.12400","23.17718","0.03091"
"278.38200","23.19870","0.03130"
"278.64000","23.22016","0.03175"
"278.89800","23.24169","0.03176"
"279.15600","23.26315","0.03155"
"279.41400","23.28468","0.03164"
"279.67200","23.30620","0.03182"
"279.93000","23.32766","0.03201"
"280.18800","23.34919","0.03232"
"280.44600","23.37065","0.03217"
"280.70400","23.39224","0.03213"
"280.96200","23.41364","0.03280"
"281.22000","23.43517","0.03213"
"281.47800","23.45657","0.03226"
"281.73600","23.47815","0.03245"
"281.99400","23.49962","0.03286"
"282.25200","23.52120","0.03300"
"282.51000","23.54260","0.03299"
"282.76800","23.56419","0.03316"
"283.02600","23.58566","0.03320"
"283.28400","23.60718","0.03285"
"283.54200","23.62864","0.03358"
"283.80000","23.65023","0.03351"
"284.05800","23.67163","0.03316"
"284.31600","23.69316","0.03385"
"284.57400","23.71462","0.03391"
"284.83200","23.73627","0.03404"
"285.09000","23.75767","0.03383"
"285.34800","23.77919","0.03390"
"285.60600","23.80060","0.03371"
"285.86400","23.82218","0.03374"
"286.12200","23.84365","0.03399"
"286.38000","23.86517","0.03392"
"286.63800","23.88670","0.03449"
"286.89600","23.90810","0.03451"
"287.15400","23.92968","0.03422"
"287.41200","23.95121","0.03424"
"287.67000","23.97273","0.03516"
"287.92800","23.99414","0.03507"
"288.18600","24.01566","0.03462"
"288.44400","24.03707","0.03520"
"288.70200","24.05871","0.03503"
"288.96000","24.08017","0.03540"
"289.21800","24.10164","0.03526"
"289.47600","24.12310","0.03528"
"289.73400","24.14463","0.03539"
"289.99200","24.16609","0.03519"
"290.25000","24.18768","0.03520"
"290.50800","24.20914","0.03556"
"290.76600","24.23067","0.03579"
"291.02400","24.25219","0.03552"
"291.28200","24.27371","0.03560"
"291.54000","24.29518","0.03609"
"291.79800","24.31664","0.03641"
"292.05600","24.33811","0.03648"
"292.31400","24.35969","0.03641"
"292.57200","24.38121","0.03700"
"292.83000","24.40268","0.03676"
"293.08800","24.42414","0.03707"
"293.34600","24.44561","0.03697"
"293.60400","24.46719","0.03722"
"293.86200","24.48866","0.03706"
"294.12000","24.51018","0.03756"
"294.37800","24.53159","0.03731"
"294.63600","24.55317","0.03772"
"294.89400","24.57463","0.03788"
"295.15200","24.59622","0.03782"
"295.41000","24.61762","0.03828"
"295.66800","24.63915","0.03765"
"295.92600","24.66067","0.03743"
"296.18400","24.68219","0.03708"
"296.44200","24.70360","0.03741"
"296.70000","24.72518","0.03737"
"296.95800","24.74665","0.03729"
"297.21600","24.76817","0.03749"
"297.47400","24.78964","0.03815"
"297.73200","24.81116","0.03777"
"297.99000","24.83269","0.03788"
"298.24800","24.85421","0.03837"
"298.50600","24.87568","0.03848"
"298.76400","24.89714","0.03842"
"299.02200","24.91872","0.03853"
"299.28000","24.94019","0.03816"
"299.53800","24.96165","0.03790"
"299.79600","24.98318","0.03839"
"300.05400","25.00470","0.03866"
"300.31200","25.02617","0.03857"
"300.57000","25.04769","0.03897"
"300.82800","25.06910","0.03896"
"301.08600","25.09068","0.03941"
"301.34400","25.11214","0.03921"
"301.60200","25.13367","0.03930"
"301.86000","25.15513","0.03961"
"302.11800","25.17665","0.03972"
"302.37600","25.19812","0.04022"
"302.63400","25.21970","0.04025"
"302.89200","25.24111","0.04033"
"303.15000","25.26269","0.04075"
"303.40800","25.28416","0.04057"
"303.66600","25.30568","0.04061"
"303.92400","25.32721","0.04085"
"304.18200","25.34873","0.04104"
"304.44000","25.37020","0.04156"
"304.69800","25.39160","0.04162"
"304.95600","25.41318","0.04183"
"305.21400","25.43465","0.04245"
"305.47200","25.45623","0.04237"
"305.73000","25.47763","0.04268"
"305.98800","25.49922","0.04280"
"306.24600","25.52062","0.04285"
"306.50400","25.54221","0.04290"
"306.76200","25.56367","0.04342"
"307.02000","25.58520","0.04357"
"307.27800","25.60660","0.04384"
"307.53600","25.62819","0.04422"
"307.79400","25.64965","0.04406"
"308.05200","25.67123","0.04442"
"308.31000","25.69264","0.04409"
"308.56800","25.71416","0.04401"
"308.82600","25.73569","0.04458"
"309.08400","25.75727","0.04454"
"309.34200","25.77862","0.04476"
"309.60000","25.80014","0.04486"
"309.85800","25.82161","0.04586"
"310.11600","25.84319","0.04561"
"310.37400","25.86471","0.04668"
"310.63200","25.88618","0.04690"
"310.89000","25.90764","0.04729"
"311.14800","25.92923","0.04811"
"311.40600","25.95069","0.04792"
"311.66400","25.97221","0.04888"
"311.92200","25.99374","0.04894"
"312.18000","26.01514","0.04928"
"312.43800","26.03667","0.04964"
"312.69600","26.05807","0.04936"
"312.95400","26.07972","0.04987"
"313.21200","26.10118","0.05026"
"313.47000","26.12270","0.05118"
"313.72800","26.14411","0.05183"
"313.98600","26.16563","0.05206"
"314.24400","26.18716","0.05214"
"314.50200","26.20868","0.05281"
"314.76000","26.23014","0.05292"
"315.01800","26.25167","0.05373"
"315.27600","26.27320","0.05408"
"315.53400","26.29466","0.05493"
"315.79200","26.31618","0.05450"
"316.05000","26.33765","0.05497"
"316.30800","26.35917","0.05531"
"316.56600","26.38070","0.05602"
"316.82400","26.40222","0.05618"
"317.08200","26.42369","0.05594"
"317.34000","26.44515","0.05639"
"317.59800","26.46661","0.05468"
"317.85600","26.48814","0.05448"
"318.11400","26.50966","0.05559"
"318.37200","26.53113","0.05545"
"318.63000","26.55265","0.05166"
"318.88800","26.57417","0.05269"
"319.14600","26.59564","0.05352"
"319.40400","26.61723","0.05487"
"319.66200","26.63863","0.05535"
"319.92000","26.66015","0.05572"
"320.17800","26.68162","0.05646"
"320.43600","26.70314","0.05722"
"320.69400","26.72466","0.05742"
"320.95200","26.74625","0.05809"
"321.21000","26.76765","0.05779"
"321.46800","26.78918","0.05920"
"321.72600","26.81064","0.06017"
"321.98400","26.83217","0.06054"
"322.24200","26.85363","0.06007"
"322.50000","26.87516","0.06090"
"322.75800","26.89668","0.06170"
"323.01600","26.91821","0.06245"
"323.27400","26.93973","0.06306"
"323.53200","26.96119","0.06354"
"323.79000","26.98266","0.06249"
"324.04800","27.00418","0.06326"
"324.30600","27.02565","0.06466"
"324.56400","27.04717","0.06568"
"324.82200","27.06870","0.06632"
"325.08000","27.09010","0.06741"
"325.33800","27.11168","0.06802"
"325.59600","27.13309","0.06925"
"325.85400","27.15467","0.06985"
"326.11200","27.17614","0.07092"
"326.37000","27.19766","0.07205"
"326.62800","27.21912","0.07294"
"326.88600","27.24065","0.07336"
"327.14400","27.26217","0.07468"
"327.40200","27.28370","0.07402"
"327.66000","27.30516","0.07417"
"327.91800","27.32669","0.07501"
"328.17600","27.34815","0.07592"
"328.43400","27.36974","0.07480"
"328.69200","27.39108","0.07513"
"328.95000","27.41266","0.07434"
"329.20800","27.43413","0.07456"
"329.46600","27.45571","0.07595"
"329.72400","27.47718","0.07663"
"329.98200","27.49864","0.07794"
"330.24000","27.52016","0.07789"
"330.49800","27.54169","0.07975"
"330.75600","27.56322","0.08062"
"331.01400","27.58468","0.08169"
"331.27200","27.60620","0.08179"
"331.53000","27.62761","0.08300"
"331.78800","27.64919","0.08390"
"332.04600","27.67066","0.08515"
"332.30400","27.69224","0.08487"
"332.56200","27.71365","0.08550"
"332.82000","27.73511","0.08641"
"333.07800","27.75657","0.08703"
"333.33600","27.77822","0.08722"
"333.59400","27.79968","0.08819"
"333.85200","27.82121","0.08841"
"334.11000","27.84267","0.08891"
"334.36800","27.86419","0.08935"
"334.62600","27.88566","0.08996"
"334.88400","27.90725","0.09012"
"335.14200","27.92865","0.09036"
"335.40000","27.95017","0.09098"
"335.65800","27.97164","0.09097"
"335.91600","27.99316","0.09049"
"336.17400","28.01469","0.09132"
"336.43200","28.03621","0.09209"
"336.69000","28.05767","0.09316"
"336.94800","28.07914","0.09397"
"337.20600","28.10066","0.09584"
"337.46400","28.12213","0.09650"
"337.72200","28.14371","0.09735"
"337.98000","28.16518","0.09876"
"338.23800","28.18664","0.10009"
"338.49600","28.20810","0.10046"
"338.75400","28.22975","0.10244"
"339.01200","28.25115","0.10406"
"339.27000","28.27268","0.10588"
"339.52800","28.29414","0.10632"
"339.78600","28.31567","0.10777"
"340.04400","28.33713","0.10926"
"340.30200","28.35865","0.10875"
"340.56000","28.38012","0.10714"
"340.81800","28.40170","0.10853"
"341.07600","28.42317","0.10945"
"341.33400","28.44469","0.11094"
"341.59200","28.46616","0.11143"
"341.85000","28.48768","0.11279"
"342.10800","28.50920","0.11436"
"342.36600","28.53067","0.11373"
"342.62400","28.55219","0.11347"
"342.88200","28.57366","0.11560"
"343.14000","28.59518","0.11525"
"343.39800","28.61665","0.11575"
"343.65600","28.63817","0.11787"
"343.91400","28.65964","0.11870"
"344.17200","28.68116","0.11973"
"344.43000","28.70262","0.12076"
"344.68800","28.72415","0.12226"
"344.94600","28.74567","0.12291"
"345.20400","28.76719","0.12355"
"345.46200","28.78860","0.12400"
"345.72000","28.81018","0.12465"
"345.97800","28.83165","0.12513"
"346.23600","28.85323","0.12567"
"346.49400","28.87464","0.12689"
"346.75200","28.89622","0.12660"
"347.01000","28.91769","0.12777"
"347.26800","28.93921","0.12869"
"347.52600","28.96068","0.13005"
"347.78400","28.98214","0.13069"
"348.04200","29.00360","0.13179"
"348.30000","29.02519","0.13256"
"348.55800","29.04671","0.13329"
"348.81600","29.06818","0.13349"
"349.07400","29.08970","0.13492"
"349.33200","29.11117","0.13567"
"349.59000","29.13269","0.13617"
"349.84800","29.15416","0.13678"
"350.10600","29.17568","0.13607"
"350.36400","29.19714","0.13470"
"350.62200","29.21873","0.13571"
"350.88000","29.24013","0.13606"
"351.13800","29.26165","0.13617"
"351.39600","29.28312","0.13612"
"351.65400","29.30470","0.11225"
"351.91200","29.32617","0.09920"
"352.17000","29.34769","0.10086"
"352.42800","29.36916","0.09640"
"352.68600","29.39074","0.10864"
"352.94400","29.41215","0.10619"
"353.20200","29.43367","0.10664"
"353.46000","29.45514","0.10587"
"353.71800","29.47672","0.11101"
"353.97600","29.49824","0.11465"
"354.23400","29.51965","0.11422"
"354.49200","29.54111","0.11594"
"354.75000","29.56269","0.11624"
"355.00800","29.58416","0.11933"
"355.26600","29.60568","0.11977"
"355.52400","29.62715","0.12051"
"355.78200","29.64861","0.12083"
"356.04000","29.67020","0.12041"
"356.29800","29.69166","0.12000"
"356.55600","29.71319","0.12036"
"356.81400","29.73459","0.12197"
"357.07200","29.75618","0.12238"
"357.33000","29.77758","0.12328"
"357.58800","29.79922","0.12423"
"357.84600","29.82063","0.12515"
"358.10400","29.84215","0.12565"
"358.36200","29.86368","0.12687"
"358.62000","29.88520","0.12760"
"358.87800","29.90660","0.12771"
"359.13600","29.92825","0.12917"
"359.39400","29.94966","0.12997"
"359.65200","29.97118","0.13102"
"359.91000","29.99270","0.13093"
"360.16800","30.01417","0.13193"
"360.42600","30.03569","0.13285"
"360.68400","30.05715","0.13392"
"360.94200","30.07862","0.13418"
"361.20000","30.10015","0.13511"
"361.45800","30.12167","0.13598"
"361.71600","30.14319","0.13640"
"361.97400","30.16466","0.13701"
"362.23200","30.18618","0.13790"
"362.49000","30.20771","0.13861"
"362.74800","30.22917","0.13922"
"363.00600","30.25069","0.14078"
"363.26400","30.27210","0.14209"
"363.52200","30.29368","0.14304"
"363.78000","30.31515","0.14485"
"364.03800","30.33673","0.14681"
"364.29600","30.35814","0.14765"
"364.55400","30.37966","0.14900"
"364.81200","30.40112","0.15184"
"365.07000","30.42265","0.15302"
"365.32800","30.44417","0.06960"
"365.58600","30.46576","0.05508"
"365.84400","30.48716","0.05666"
"366.10200","30.50869","0.06166"
"366.36000","30.53015","0.05715"
"366.61800","30.55162","0.05452"
"366.87600","30.57320","0.06354"
"367.13400","30.59466","0.06397"
"367.39200","30.61619","0.05930"
"367.65000","30.63765","0.06025"
"367.90800","30.65918","0.06677"
"368.16600","30.68064","0.06601"
"368.42400","30.70217","0.06421"
"368.68200","30.72363","0.06514"
"368.94000","30.74515","0.06875"
"369.19800","30.76668","0.06959"
"369.45600","30.78814","0.06908"
"369.71400","30.80960","0.06932"
"369.97200","30.83119","0.07237"
"370.23000","30.85266","0.07277"
"370.48800","30.87418","0.07325"
"370.74600","30.89564","0.01133"
"371.00400","30.91717","0.01791"
"371.26200","30.93863","0.01237"
"371.52000","30.96022","0.00645"
"371.77800","30.98162","0.00995"
"372.03600","31.00321","0.00874"
"372.29400","31.02467","0.01187"
"372.55200","31.04613","0.00635"
"372.81000","31.06766","0.01136"
"373.06800","31.08919","0.00632"
"373.32600","31.11071","0.00990"
"373.58400","31.13217","0.00998"
"373.84200","31.15370","0.00767"
"374.10000","31.17516","0.00785"
"374.35800","31.19674","0.00949"
"374.61600","31.21815","0.00823"
"374.87400","31.23967","0.01024"
"375.13200","31.26114","0.00774"
"375.39000","31.28272","0.00922"
"375.64800","31.30412","0.01029"
"375.90600","31.32571","0.00694"
"376.16400","31.34711","0.01028"
"376.42200","31.36864","0.00723"
"376.68000","31.39016","0.00835"
"376.93800","31.41169","0.00944"
"377.19600","31.43321","0.00707"
"377.45400","31.45468","0.00949"
"377.71200","31.47614","0.00805"
"377.97000","31.49767","0.00927"
"378.22800","31.51913","0.00867"
"378.48600","31.54071","0.00785"
"378.74400","31.56212","0.00901"
"379.00200","31.58370","0.00929"
"379.26000","31.60517","0.00838"
"379.51800","31.62669","0.00888"
"379.77600","31.64816","0.00789"
"380.03400","31.66968","0.00904"
"380.29200","31.69114","0.00968"
"380.55000","31.71267","0.00925"
"380.80800","31.73425","0.00955"
"381.06600","31.75566","0.00859"
"381.26000","31.77186","0.00959"