File: Force_trajectories/170212_3/Specimen_RawData_2.csv
End date,"2/12/2017"
Specimen label,"13BG_6"
Maximum Load,"0.00360",N

Time,Extension,Load
(s),(mm),(N)
"0.00000","0.00000","-0.00006"
"0.07200","0.00185","0.00031"
"0.14400","0.00783","0.00029"
"0.21600","0.01584","0.00036"
"0.28800","0.02332","0.00009"
"0.36000","0.03001","-0.00011"
"0.43200","0.03635","-0.00010"
"0.50400","0.04233","0.00024"
"0.57600","0.04831","0.00019"
"0.64800","0.05423","0.00019"
"0.72000","0.06027","0.00068"
"0.79200","0.06625","0.00028"
"0.86400","0.07223","0.00031"
"0.93600","0.07820","-0.00031"
"1.00800","0.08424","0.00049"
"1.08000","0.09028","0.00039"
"1.15200","0.09626","-0.00035"
"1.22400","0.10224","0.00033"
"1.29600","0.10822","0.00056"
"1.36800","0.11426","-0.00012"
"1.44000","0.12018","0.00050"
"1.51200","0.12622","0.00044"
"1.58400","0.13219","0.00035"
"1.65600","0.13829","-0.00027"
"1.72800","0.14421","0.00034"
"1.80000","0.15025","0.00055"
"1.87200","0.15623","0.00026"
"1.94400","0.16221","-0.00027"
"2.01600","0.16819","0.00001"
"2.08800","0.17423","0.00000"
"2.16000","0.18027","-0.00003"
"2.23200","0.18630","-0.00010"
"2.30400","0.19228","-0.00028"
"2.37600","0.19826","0.00037"
"2.44800","0.20424","0.00048"
"2.52000","0.21016","0.00027"
"2.59200","0.21620","0.00078"
"2.66400","0.22224","-0.00032"
"2.73600","0.22828","0.00062"
"2.80800","0.23426","0.00060"
"2.88000","0.24023","0.00046"
"2.95200","0.24621","0.00031"
"3.02400","0.25219","0.00019"
"3.09600","0.25817","-0.00012"
"3.16800","0.26421","0.00035"
"3.24000","0.27019","0.00116"
"3.31200","0.27623","0.00033"
"3.38400","0.28227","0.00033"
"3.45600","0.28819","0.00054"
"3.52800","0.29422","0.00031"
"3.60000","0.30014","0.00015"
"3.67200","0.30624","-0.00015"
"3.74400","0.31222","0.00012"
"3.81600","0.31832","0.00057"
"3.88800","0.32424","0.00007"
"3.96000","0.33028","0.00021"
"4.03200","0.33620","0.00038"
"4.10400","0.34218","0.00018"
"4.17600","0.34815","0.00032"
"4.24800","0.35419","-0.00016"
"4.32000","0.36023","0.00075"
"4.39200","0.36627","0.00022"
"4.46400","0.37225","0.00057"
"4.53600","0.37823","0.00002"
"4.60800","0.38421","0.00001"
"4.68000","0.39019","0.00053"
"4.75200","0.39623","0.00064"
"4.82400","0.40220","0.00109"
"4.89600","0.40824","0.00028"
"4.96800","0.41422","0.00045"
"5.04000","0.42026","0.00000"
"5.11200","0.42624","-0.00010"
"5.18400","0.43216","0.00026"
"5.25600","0.43820","0.00022"
"5.32800","0.44418","0.00020"
"5.40000","0.45022","0.00042"
"5.47200","0.45619","0.00035"
"5.54400","0.46229","0.00000"
"5.61600","0.46821","0.00021"
"5.68800","0.47419","0.00050"
"5.76000","0.48017","0.00033"
"5.83200","0.48621","0.00039"
"5.90400","0.49225","0.00062"
"5.97600","0.49829","0.00039"
"6.04800","0.50426","0.00050"
"6.12000","0.51024","0.00076"
"6.19200","0.51628","0.00016"
"6.26400","0.52226","0.00029"
"6.33600","0.52818","0.00082"
"6.40800","0.53422","0.00099"
"6.48000","0.54026","0.00014"
"6.55200","0.54630","0.00034"
"6.62400","0.55228","0.00049"
"6.69600","0.55825","0.00069"
"6.76800","0.56417","0.00087"
"6.84000","0.57021","0.00069"
"6.91200","0.57619","0.00027"
"6.98400","0.58229","0.00043"
"7.05600","0.58827","0.00001"
"7.12800","0.59425","0.00063"
"7.20000","0.60023","-0.00002"
"7.27200","0.60627","0.00050"
"7.34400","0.61219","0.00057"
"7.41600","0.61822","0.00107"
"7.48800","0.62420","0.00086"
"7.56000","0.63030","0.00042"
"7.63200","0.63616","0.00009"
"7.70400","0.64226","0.00032"
"7.77600","0.64818","0.00042"
"7.84800","0.65422","0.00043"
"7.92000","0.66014","0.00051"
"7.99200","0.66623","0.00035"
"8.06400","0.67221","0.00021"
"8.13600","0.67825","0.00045"
"8.20800","0.68423","0.00023"
"8.28000","0.69021","0.00068"
"8.35200","0.69619","0.00089"
"8.42400","0.70223","0.00063"
"8.49600","0.70821","0.00056"
"8.56800","0.71425","0.00051"
"8.64000","0.72022","0.00041"
"8.71200","0.72626","-0.00025"
"8.78400","0.73230","0.00051"
"8.85600","0.73828","0.00065"
"8.92800","0.74420","0.00054"
"9.00000","0.75024","0.00171"
"9.07200","0.75622","0.00055"
"9.14400","0.76226","0.00025"
"9.21600","0.76824","0.00038"
"9.28800","0.77427","0.00086"
"9.36000","0.78025","0.00092"
"9.43200","0.78623","0.00099"
"9.50400","0.79221","0.00035"
"9.57600","0.79819","0.00060"
"9.64800","0.80423","0.00065"
"9.72000","0.81027","0.00028"
"9.79200","0.81625","0.00025"
"9.86400","0.82223","0.00079"
"9.93600","0.82820","0.00106"
"10.00800","0.83424","0.00019"
"10.08000","0.84022","0.00037"
"10.15200","0.84620","0.00073"
"10.22400","0.85224","-0.00008"
"10.29600","0.85828","0.00031"
"10.36800","0.86426","0.00055"
"10.44000","0.87030","0.00117"
"10.51200","0.87622","0.00052"
"10.58400","0.88225","0.00013"
"10.65600","0.88817","0.00047"
"10.72800","0.89427","0.00128"
"10.80000","0.90025","0.00138"
"10.87200","0.90629","0.00047"
"10.94400","0.91221","0.00048"
"11.01600","0.91825","0.00037"
"11.08800","0.92417","0.00045"
"11.16000","0.93021","0.00077"
"11.23200","0.93618","0.00077"
"11.30400","0.94228","0.00137"
"11.37600","0.94826","0.00088"
"11.44800","0.95430","0.00087"
"11.52000","0.96022","0.00091"
"11.59200","0.96626","0.00070"
"11.66400","0.97218","0.00082"
"11.73600","0.97822","0.00072"
"11.80800","0.98420","0.00065"
"11.88000","0.99029","0.00104"
"11.95200","0.99621","0.00027"
"12.02400","1.00225","0.00043"
"12.09600","1.00823","0.00062"
"12.16800","1.01421","0.00034"
"12.24000","1.02013","0.00097"
"12.31200","1.02623","0.00065"
"12.38400","1.03215","0.00074"
"12.45600","1.03825","0.00082"
"12.52800","1.04422","0.00056"
"12.60000","1.05026","0.00032"
"12.67200","1.05618","0.00067"
"12.74400","1.06222","0.00041"
"12.81600","1.06814","0.00093"
"12.88800","1.07424","0.00028"
"12.96000","1.08022","0.00062"
"13.03200","1.08626","0.00045"
"13.10400","1.09224","0.00062"
"13.17600","1.09821","0.00069"
"13.24800","1.10419","0.00026"
"13.32000","1.11017","-0.00020"
"13.39200","1.11621","0.00054"
"13.46400","1.12219","0.00062"
"13.53600","1.12823","0.00058"
"13.60800","1.13427","0.00083"
"13.68000","1.14025","0.00057"
"13.75200","1.14617","0.00029"
"13.82400","1.15220","0.00092"
"13.89600","1.15824","0.00032"
"13.96800","1.16422","0.00055"
"14.04000","1.17026","0.00069"
"14.11200","1.17624","0.00036"
"14.18400","1.18228","0.00055"
"14.25600","1.18826","0.00063"
"14.32800","1.19418","0.00069"
"14.40000","1.20016","0.00041"
"14.47200","1.20619","0.00083"
"14.54400","1.21223","0.00087"
"14.61600","1.21827","0.00032"
"14.68800","1.22419","0.00133"
"14.76000","1.23029","0.00071"
"14.83200","1.23621","0.00036"
"14.90400","1.24219","0.00024"
"14.97600","1.24817","0.00058"
"15.04800","1.25426","0.00096"
"15.12000","1.26024","0.00031"
"15.19200","1.26628","0.00050"
"15.26400","1.27220","0.00030"
"15.33600","1.27824","0.00032"
"15.40800","1.28422","0.00018"
"15.48000","1.29020","0.00066"
"15.55200","1.29618","0.00050"
"15.62400","1.30222","0.00066"
"15.69600","1.30820","0.00053"
"15.76800","1.31423","0.00071"
"15.84000","1.32021","0.00080"
"15.91200","1.32619","0.00052"
"15.98400","1.33217","0.00064"
"16.05600","1.33821","0.00113"
"16.12800","1.34425","0.00061"
"16.20000","1.35029","0.00042"
"16.27200","1.35621","0.00065"
"16.34400","1.36224","0.00055"
"16.41600","1.36822","0.00048"
"16.48800","1.37420","0.00035"
"16.56000","1.38018","0.00122"
"16.63200","1.38622","0.00011"
"16.70400","1.39226","0.00096"
"16.77600","1.39824","0.00042"
"16.84800","1.40422","0.00109"
"16.92000","1.41026","0.00032"
"16.99200","1.41617","0.00101"
"17.06400","1.42221","0.00076"
"17.13600","1.42819","0.00083"
"17.20800","1.43423","0.00059"
"17.28000","1.44021","0.00104"
"17.35200","1.44625","0.00069"
"17.42400","1.45223","0.00063"
"17.49600","1.45821","0.00047"
"17.56800","1.46419","0.00069"
"17.64000","1.47016","0.00078"
"17.71200","1.47620","0.00010"
"17.78400","1.48230","0.00064"
"17.85600","1.48822","0.00027"
"17.92800","1.49420","0.00018"
"18.00000","1.50018","0.00062"
"18.07200","1.50622","0.00091"
"18.14400","1.51220","0.00065"
"18.21600","1.51824","0.00061"
"18.28800","1.52427","0.00133"
"18.36000","1.53025","0.00035"
"18.43200","1.53623","0.00081"
"18.50400","1.54227","0.00079"
"18.57600","1.54819","0.00015"
"18.64800","1.55417","0.00059"
"18.72000","1.56015","0.00039"
"18.79200","1.56625","0.00047"
"18.86400","1.57223","0.00038"
"18.93600","1.57820","0.00094"
"19.00800","1.58424","0.00067"
"19.08000","1.59022","0.00074"
"19.15200","1.59620","0.00028"
"19.22400","1.60218","0.00102"
"19.29600","1.60822","0.00077"
"19.36800","1.61426","0.00058"
"19.44000","1.62024","0.00072"
"19.51200","1.62622","0.00058"
"19.58400","1.63225","0.00091"
"19.65600","1.63823","0.00066"
"19.72800","1.64421","0.00015"
"19.80000","1.65013","0.00102"
"19.87200","1.65623","0.00053"
"19.94400","1.66227","0.00088"
"20.01600","1.66825","0.00089"
"20.08800","1.67423","0.00080"
"20.16000","1.68021","0.00061"
"20.23200","1.68618","0.00030"
"20.30400","1.69216","0.00057"
"20.37600","1.69820","0.00121"
"20.44800","1.70418","0.00082"
"20.52000","1.71022","0.00071"
"20.59200","1.71626","0.00018"
"20.66400","1.72224","0.00018"
"20.73600","1.72816","0.00020"
"20.80800","1.73414","0.00032"
"20.88000","1.74017","0.00060"
"20.95200","1.74621","0.00012"
"21.02400","1.75225","0.00073"
"21.09600","1.75823","0.00078"
"21.16800","1.76427","0.00087"
"21.24000","1.77025","0.00128"
"21.31200","1.77623","0.00060"
"21.38400","1.78221","0.00079"
"21.45600","1.78825","0.00036"
"21.52800","1.79428","0.00113"
"21.60000","1.80026","0.00063"
"21.67200","1.80624","0.00053"
"21.74400","1.81228","0.00065"
"21.81600","1.81826","0.00000"
"21.88800","1.82424","0.00093"
"21.96000","1.83022","0.00066"
"22.03200","1.83620","0.00057"
"22.10400","1.84224","0.00069"
"22.17600","1.84827","-0.00014"
"22.24800","1.85425","0.00069"
"22.32000","1.86023","0.00061"
"22.39200","1.86615","0.00097"
"22.46400","1.87219","0.00076"
"22.53600","1.87823","0.00039"
"22.60800","1.88427","0.00053"
"22.68000","1.89025","0.00085"
"22.75200","1.89628","0.00049"
"22.82400","1.90226","0.00059"
"22.89600","1.90824","0.00087"
"22.96800","1.91422","0.00037"
"23.04000","1.92020","-0.00008"
"23.11200","1.92624","0.00037"
"23.18400","1.93228","0.00124"
"23.25600","1.93826","0.00049"
"23.32800","1.94424","0.00055"
"23.40000","1.95022","0.00049"
"23.47200","1.95625","0.00084"
"23.54400","1.96217","0.00044"
"23.61600","1.96821","0.00091"
"23.68800","1.97425","0.00089"
"23.76000","1.98029","0.00031"
"23.83200","1.98627","0.00054"
"23.90400","1.99225","0.00048"
"23.97600","1.99823","0.00036"
"24.04800","2.00420","0.00007"
"24.12000","2.01018","0.00042"
"24.19200","2.01622","0.00027"
"24.26400","2.02220","0.00085"
"24.33600","2.02824","0.00041"
"24.40800","2.03422","0.00052"
"24.48000","2.04026","0.00046"
"24.55200","2.04618","0.00018"
"24.62400","2.05222","0.00042"
"24.69600","2.05825","0.00059"
"24.76800","2.06429","0.00075"
"24.84000","2.07021","0.00059"
"24.91200","2.07625","0.00037"
"24.98400","2.08223","0.00036"
"25.05600","2.08815","0.00034"
"25.12800","2.09419","0.00054"
"25.20000","2.10023","0.00063"
"25.27200","2.10627","0.00061"
"25.34400","2.11224","0.00045"
"25.41600","2.11828","0.00051"
"25.48800","2.12420","0.00038"
"25.56000","2.13018","0.00121"
"25.63200","2.13622","0.00082"
"25.70400","2.14220","0.00076"
"25.77600","2.14824","0.00041"
"25.84800","2.15422","0.00078"
"25.92000","2.16026","0.00044"
"25.99200","2.16623","-0.00015"
"26.06400","2.17227","0.00063"
"26.13600","2.17819","0.00081"
"26.20800","2.18417","0.00011"
"26.28000","2.19015","0.00081"
"26.35200","2.19625","0.00041"
"26.42400","2.20223","0.00051"
"26.49600","2.20827","0.00065"
"26.56800","2.21425","0.00056"
"26.64000","2.22028","0.00153"
"26.71200","2.22620","0.00048"
"26.78400","2.23218","0.00088"
"26.85600","2.23828","0.00078"
"26.92800","2.24432","0.00020"
"27.00000","2.25024","0.00050"
"27.07200","2.25628","0.00125"
"27.14400","2.26220","0.00097"
"27.21600","2.26824","0.00062"
"27.28800","2.27415","0.00061"
"27.36000","2.28025","0.00010"
"27.43200","2.28623","0.00016"
"27.50400","2.29227","0.00124"
"27.57600","2.29825","0.00085"
"27.64800","2.30429","0.00061"
"27.72000","2.31021","0.00056"
"27.79200","2.31625","0.00012"
"27.86400","2.32217","0.00058"
"27.93600","2.32826","0.00040"
"28.00800","2.33424","0.00079"
"28.08000","2.34028","0.00038"
"28.15200","2.34626","0.00035"
"28.22400","2.35230","0.00073"
"28.29600","2.35822","0.00105"
"28.36800","2.36420","0.00103"
"28.44000","2.37018","0.00038"
"28.51200","2.37628","0.00139"
"28.58400","2.38225","0.00096"
"28.65600","2.38823","0.00057"
"28.72800","2.39427","0.00092"
"28.80000","2.40025","0.00051"
"28.87200","2.40623","0.00087"
"28.94400","2.41221","0.00052"
"29.01600","2.41825","0.00065"
"29.08800","2.42423","0.00111"
"29.16000","2.43027","0.00114"
"29.23200","2.43624","0.00072"
"29.30400","2.44228","0.00080"
"29.37600","2.44820","0.00076"
"29.44800","2.45418","0.00064"
"29.52000","2.46022","0.00045"
"29.59200","2.46620","0.00047"
"29.66400","2.47230","0.00084"
"29.73600","2.47822","0.00096"
"29.80800","2.48426","0.00059"
"29.88000","2.49017","0.00049"
"29.95200","2.49621","0.00063"
"30.02400","2.50213","0.00096"
"30.09600","2.50829","0.00043"
"30.16800","2.51427","0.00070"
"30.24000","2.52025","0.00126"
"30.31200","2.52629","0.00087"
"30.38400","2.53227","0.00061"
"30.45600","2.53819","0.00053"
"30.52800","2.54422","0.00065"
"30.60000","2.55020","0.00018"
"30.67200","2.55624","0.00032"
"30.74400","2.56222","0.00065"
"30.81600","2.56826","0.00039"
"30.88800","2.57424","0.00043"
"30.96000","2.58022","0.00063"
"31.03200","2.58620","0.00073"
"31.10400","2.59218","0.00100"
"31.17600","2.59815","0.00085"
"31.24800","2.60425","0.00079"
"31.32000","2.61017","0.00057"
"31.39200","2.61627","0.00095"
"31.46400","2.62219","0.00086"
"31.53600","2.62823","0.00095"
"31.60800","2.63415","0.00119"
"31.68000","2.64025","0.00096"
"31.75200","2.64622","0.00032"
"31.82400","2.65226","0.00051"
"31.89600","2.65818","0.00085"
"31.96800","2.66428","0.00053"
"32.04000","2.67020","0.00089"
"32.11200","2.67624","0.00065"
"32.18400","2.68216","0.00088"
"32.25600","2.68826","0.00081"
"32.32800","2.69424","0.00069"
"32.40000","2.70027","0.00087"
"32.47200","2.70625","0.00080"
"32.54400","2.71223","0.00077"
"32.61600","2.71821","0.00008"
"32.68800","2.72419","0.00100"
"32.76000","2.73023","0.00042"
"32.83200","2.73627","0.00065"
"32.90400","2.74231","0.00091"
"32.97600","2.74823","0.00078"
"33.04800","2.75420","0.00049"
"33.12000","2.76018","0.00045"
"33.19200","2.76622","0.00091"
"33.26400","2.77220","0.00073"
"33.33600","2.77818","0.00048"
"33.40800","2.78428","0.00063"
"33.48000","2.79020","0.00105"
"33.55200","2.79624","0.00017"
"33.62400","2.80216","0.00080"
"33.69600","2.80819","0.00081"
"33.76800","2.81417","0.00070"
"33.84000","2.82021","0.00044"
"33.91200","2.82619","0.00039"
"33.98400","2.83223","0.00096"
"34.05600","2.83821","0.00013"
"34.12800","2.84419","0.00061"
"34.20000","2.85017","0.00101"
"34.27200","2.85621","-0.00002"
"34.34400","2.86218","0.00067"
"34.41600","2.86822","0.00066"
"34.48800","2.87426","0.00039"
"34.56000","2.88024","0.00073"
"34.63200","2.88628","0.00065"
"34.70400","2.89220","0.00152"
"34.77600","2.89818","0.00116"
"34.84800","2.90416","0.00071"
"34.92000","2.91020","0.00042"
"34.99200","2.91623","0.00032"
"35.06400","2.92221","0.00093"
"35.13600","2.92819","0.00007"
"35.20800","2.93423","0.00043"
"35.28000","2.94021","0.00094"
"35.35200","2.94613","0.00054"
"35.42400","2.95223","0.00038"
"35.49600","2.95827","0.00083"
"35.56800","2.96431","0.00086"
"35.64000","2.97022","0.00068"
"35.71200","2.97626","0.00108"
"35.78400","2.98218","0.00106"
"35.85600","2.98816","0.00082"
"35.92800","2.99414","0.00053"
"36.00000","3.00024","0.00052"
"36.07200","3.00622","0.00070"
"36.14400","3.01226","0.00116"
"36.21600","3.01824","0.00063"
"36.28800","3.02427","0.00066"
"36.36000","3.03019","0.00125"
"36.43200","3.03617","0.00093"
"36.50400","3.04221","0.00087"
"36.57600","3.04825","0.00050"
"36.64800","3.05423","0.00096"
"36.72000","3.06021","0.00031"
"36.79200","3.06625","0.00049"
"36.86400","3.07223","0.00080"
"36.93600","3.07820","0.00088"
"37.00800","3.08418","0.00096"
"37.08000","3.09022","0.00149"
"37.15200","3.09626","0.00083"
"37.22400","3.10224","0.00064"
"37.29600","3.10822","0.00087"
"37.36800","3.11420","0.00064"
"37.44000","3.12024","0.00105"
"37.51200","3.12622","0.00031"
"37.58400","3.13225","0.00066"
"37.65600","3.13823","0.00086"
"37.72800","3.14427","0.00062"
"37.80000","3.15019","0.00136"
"37.87200","3.15623","0.00020"
"37.94400","3.16221","0.00066"
"38.01600","3.16819","0.00053"
"38.08800","3.17417","0.00047"
"38.16000","3.18021","0.00066"
"38.23200","3.18618","0.00065"
"38.30400","3.19222","0.00082"
"38.37600","3.19826","0.00004"
"38.44800","3.20424","0.00073"
"38.52000","3.21022","0.00078"
"38.59200","3.21620","0.00102"
"38.66400","3.22218","0.00035"
"38.73600","3.22828","0.00066"
"38.80800","3.23426","0.00104"
"38.88000","3.24023","0.00077"
"38.95200","3.24627","0.00022"
"39.02400","3.25225","0.00091"
"39.09600","3.25823","0.00082"
"39.16800","3.26421","0.00034"
"39.24000","3.27019","0.00111"
"39.31200","3.27623","0.00107"
"39.38400","3.28227","0.00060"
"39.45600","3.28824","0.00092"
"39.52800","3.29422","0.00079"
"39.60000","3.30026","0.00091"
"39.67200","3.30618","0.00057"
"39.74400","3.31222","0.00097"
"39.81600","3.31820","0.00099"
"39.88800","3.32424","0.00106"
"39.96000","3.33022","0.00036"
"40.03200","3.33626","0.00079"
"40.10400","3.34224","0.00056"
"40.17600","3.34815","0.00069"
"40.24800","3.35419","0.00012"
"40.32000","3.36023","0.00044"
"40.39200","3.36627","0.00109"
"40.46400","3.37225","0.00039"
"40.53600","3.37823","0.00066"
"40.60800","3.38427","0.00073"
"40.68000","3.39025","0.00081"
"40.75200","3.39622","0.00089"
"40.82400","3.40220","0.00122"
"40.89600","3.40824","0.00073"
"40.96800","3.41428","0.00074"
"41.04000","3.42020","0.00085"
"41.11200","3.42624","0.00075"
"41.18400","3.43222","0.00070"
"41.25600","3.43820","0.00048"
"41.32800","3.44418","0.00082"
"41.40000","3.45021","0.00082"
"41.47200","3.45619","0.00033"
"41.54400","3.46223","0.00086"
"41.61600","3.46821","0.00076"
"41.68800","3.47425","0.00059"
"41.76000","3.48023","0.00065"
"41.83200","3.48621","0.00069"
"41.90400","3.49225","0.00046"
"41.97600","3.49829","0.00074"
"42.04800","3.50426","0.00014"
"42.12000","3.51024","0.00081"
"42.19200","3.51622","0.00130"
"42.26400","3.52220","0.00013"
"42.33600","3.52818","0.00133"
"42.40800","3.53416","0.00101"
"42.48000","3.54020","0.00082"
"42.55200","3.54624","0.00065"
"42.62400","3.55222","0.00072"
"42.69600","3.55825","0.00087"
"42.76800","3.56417","0.00038"
"42.84000","3.57021","0.00102"
"42.91200","3.57619","0.00099"
"42.98400","3.58223","0.00115"
"43.05600","3.58821","0.00102"
"43.12800","3.59425","0.00089"
"43.20000","3.60023","0.00052"
"43.27200","3.60627","0.00050"
"43.34400","3.61218","0.00077"
"43.41600","3.61816","0.00110"
"43.48800","3.62420","0.00075"
"43.56000","3.63024","0.00049"
"43.63200","3.63622","0.00113"
"43.70400","3.64226","0.00158"
"43.77600","3.64824","0.00112"
"43.84800","3.65428","0.00066"
"43.92000","3.66020","0.00102"
"43.99200","3.66623","0.00094"
"44.06400","3.67221","0.00039"
"44.13600","3.67831","0.00065"
"44.20800","3.68423","0.00077"
"44.28000","3.69027","0.00040"
"44.35200","3.69625","0.00015"
"44.42400","3.70223","0.00107"
"44.49600","3.70821","0.00068"
"44.56800","3.71419","0.00094"
"44.64000","3.72022","0.00102"
"44.71200","3.72626","0.00048"
"44.78400","3.73224","0.00098"
"44.85600","3.73828","0.00041"
"44.92800","3.74420","0.00011"
"45.00000","3.75024","0.00030"
"45.07200","3.75616","0.00094"
"45.14400","3.76226","0.00058"
"45.21600","3.76830","0.00046"
"45.28800","3.77427","0.00096"
"45.36000","3.78025","0.00081"
"45.43200","3.78629","0.00036"
"45.50400","3.79221","0.00111"
"45.57600","3.79819","0.00097"
"45.64800","3.80417","0.00079"
"45.72000","3.81027","0.00113"
"45.79200","3.81631","0.00044"
"45.86400","3.82223","0.00079"
"45.93600","3.82826","0.00086"
"46.00800","3.83418","0.00065"
"46.08000","3.84022","0.00067"
"46.15200","3.84620","0.00118"
"46.22400","3.85224","0.00088"
"46.29600","3.85822","0.00098"
"46.36800","3.86426","0.00101"
"46.44000","3.87024","0.00082"
"46.51200","3.87622","0.00103"
"46.58400","3.88219","0.00038"
"46.65600","3.88817","0.00078"
"46.72800","3.89421","0.00089"
"46.80000","3.90019","0.00102"
"46.87200","3.90629","0.00091"
"46.94400","3.91221","0.00065"
"47.01600","3.91831","0.00035"
"47.08800","3.92423","0.00105"
"47.16000","3.93027","0.00057"
"47.23200","3.93618","0.00092"
"47.30400","3.94222","0.00032"
"47.37600","3.94820","0.00103"
"47.44800","3.95430","0.00075"
"47.52000","3.96022","0.00087"
"47.59200","3.96626","0.00098"
"47.66400","3.97218","0.00047"
"47.73600","3.97822","0.00099"
"47.80800","3.98414","0.00081"
"47.88000","3.99023","0.00097"
"47.95200","3.99621","0.00090"
"48.02400","4.00225","0.00097"
"48.09600","4.00823","0.00102"
"48.16800","4.01427","0.00018"
"48.24000","4.02019","0.00116"
"48.31200","4.02623","0.00089"
"48.38400","4.03227","0.00053"
"48.45600","4.03824","0.00061"
"48.52800","4.04422","0.00066"
"48.60000","4.05026","0.00104"
"48.67200","4.05624","0.00085"
"48.74400","4.06222","0.00058"
"48.81600","4.06814","0.00084"
"48.88800","4.07424","0.00068"
"48.96000","4.08022","0.00063"
"49.03200","4.08632","0.00113"
"49.10400","4.09223","0.00105"
"49.17600","4.09827","0.00063"
"49.24800","4.10419","0.00113"
"49.32000","4.11023","0.00089"
"49.39200","4.11615","0.00058"
"49.46400","4.12219","0.00138"
"49.53600","4.12829","0.00053"
"49.60800","4.13427","0.00082"
"49.68000","4.14025","0.00090"
"49.75200","4.14622","0.00087"
"49.82400","4.15226","0.00126"
"49.89600","4.15818","0.00060"
"49.96800","4.16422","0.00101"
"50.04000","4.17026","0.00096"
"50.11200","4.17630","0.00110"
"50.18400","4.18222","0.00118"
"50.25600","4.18826","0.00023"
"50.32800","4.19424","0.00116"
"50.40000","4.20021","0.00103"
"50.47200","4.20625","0.00086"
"50.54400","4.21223","0.00106"
"50.61600","4.21833","0.00099"
"50.68800","4.22419","0.00087"
"50.76000","4.23023","0.00116"
"50.83200","4.23615","0.00077"
"50.90400","4.24219","0.00122"
"50.97600","4.24817","0.00052"
"51.04800","4.25420","0.00108"
"51.12000","4.26018","0.00070"
"51.19200","4.26628","0.00043"
"51.26400","4.27220","0.00107"
"51.33600","4.27824","0.00116"
"51.40800","4.28416","0.00137"
"51.48000","4.29020","0.00052"
"51.55200","4.29618","0.00033"
"51.62400","4.30228","0.00102"
"51.69600","4.30819","0.00117"
"51.76800","4.31423","0.00088"
"51.84000","4.32027","0.00092"
"51.91200","4.32631","0.00076"
"51.98400","4.33217","0.00112"
"52.05600","4.33821","0.00098"
"52.12800","4.34419","0.00087"
"52.20000","4.35029","0.00107"
"52.27200","4.35621","0.00121"
"52.34400","4.36224","0.00092"
"52.41600","4.36822","0.00117"
"52.48800","4.37426","0.00109"
"52.56000","4.38018","0.00117"
"52.63200","4.38622","0.00096"
"52.70400","4.39226","0.00082"
"52.77600","4.39830","0.00109"
"52.84800","4.40422","0.00114"
"52.92000","4.41026","0.00107"
"52.99200","4.41617","0.00147"
"53.06400","4.42221","0.00104"
"53.13600","4.42813","0.00074"
"53.20800","4.43423","0.00082"
"53.28000","4.44021","0.00147"
"53.35200","4.44625","0.00124"
"53.42400","4.45223","0.00170"
"53.49600","4.45821","0.00094"
"53.56800","4.46425","0.00086"
"53.64000","4.47016","0.00116"
"53.71200","4.47620","0.00145"
"53.78400","4.48218","0.00139"
"53.85600","4.48822","0.00102"
"53.92800","4.49426","0.00127"
"54.00000","4.50024","0.00162"
"54.07200","4.50622","0.00106"
"54.14400","4.51220","0.00060"
"54.21600","4.51818","0.00126"
"54.28800","4.52415","0.00114"
"54.36000","4.53031","0.00136"
"54.43200","4.53623","0.00161"
"54.50400","4.54227","0.00074"
"54.57600","4.54825","0.00107"
"54.64800","4.55423","0.00041"
"54.72000","4.56021","0.00089"
"54.79200","4.56625","0.00069"
"54.86400","4.57223","0.00107"
"54.93600","4.57826","0.00075"
"55.00800","4.58424","0.00130"
"55.08000","4.59028","0.00106"
"55.15200","4.59620","0.00139"
"55.22400","4.60218","0.00109"
"55.29600","4.60816","0.00149"
"55.36800","4.61420","0.00103"
"55.44000","4.62018","0.00125"
"55.51200","4.62621","0.00153"
"55.58400","4.63225","0.00097"
"55.65600","4.63829","0.00132"
"55.72800","4.64415","0.00122"
"55.80000","4.65019","0.00061"
"55.87200","4.65617","0.00105"
"55.94400","4.66227","0.00099"
"56.01600","4.66825","0.00099"
"56.08800","4.67429","0.00030"
"56.16000","4.68026","0.00085"
"56.23200","4.68624","0.00119"
"56.30400","4.69216","0.00046"
"56.37600","4.69820","0.00144"
"56.44800","4.70418","0.00103"
"56.52000","4.71022","0.00095"
"56.59200","4.71620","0.00161"
"56.66400","4.72230","0.00073"
"56.73600","4.72822","0.00035"
"56.80800","4.73419","0.00107"
"56.88000","4.74017","0.00099"
"56.95200","4.74621","0.00127"
"57.02400","4.75225","0.00078"
"57.09600","4.75823","0.00131"
"57.16800","4.76427","0.00090"
"57.24000","4.77025","0.00101"
"57.31200","4.77623","0.00179"
"57.38400","4.78221","0.00107"
"57.45600","4.78819","0.00122"
"57.52800","4.79422","0.00107"
"57.60000","4.80026","0.00143"
"57.67200","4.80624","0.00099"
"57.74400","4.81222","0.00113"
"57.81600","4.81826","0.00091"
"57.88800","4.82424","0.00123"
"57.96000","4.83022","0.00137"
"58.03200","4.83620","0.00094"
"58.10400","4.84223","0.00141"
"58.17600","4.84827","0.00118"
"58.24800","4.85425","0.00102"
"58.32000","4.86023","0.00177"
"58.39200","4.86621","0.00082"
"58.46400","4.87219","0.00068"
"58.53600","4.87817","0.00151"
"58.60800","4.88421","0.00127"
"58.68000","4.89025","0.00164"
"58.75200","4.89622","0.00057"
"58.82400","4.90226","0.00170"
"58.89600","4.90824","0.00124"
"58.96800","4.91422","0.00098"
"59.04000","4.92020","0.00165"
"59.11200","4.92624","0.00143"
"59.18400","4.93222","0.00086"
"59.25600","4.93826","0.00112"
"59.32800","4.94424","0.00113"
"59.40000","4.95021","0.00162"
"59.47200","4.95619","0.00187"
"59.54400","4.96223","0.00083"
"59.61600","4.96815","0.00045"
"59.68800","4.97425","0.00169"
"59.76000","4.98023","0.00178"
"59.83200","4.98621","0.00128"
"59.90400","4.99225","0.00133"
"59.97600","4.99823","0.00129"
"60.04800","5.00420","0.00110"
"60.12000","5.01018","0.00071"
"60.19200","5.01622","0.00127"
"60.26400","5.02220","0.00101"
"60.33600","5.02824","0.00054"
"60.40800","5.03422","0.00163"
"60.48000","5.04026","0.00069"
"60.55200","5.04624","0.00116"
"60.62400","5.05216","0.00113"
"60.69600","5.05819","0.00108"
"60.76800","5.06423","0.00056"
"60.84000","5.07027","0.00113"
"60.91200","5.07625","0.00114"
"60.98400","5.08229","0.00140"
"61.05600","5.08821","0.00132"
"61.12800","5.09425","0.00124"
"61.20000","5.10017","0.00104"
"61.27200","5.10627","0.00082"
"61.34400","5.11224","0.00079"
"61.41600","5.11828","0.00139"
"61.48800","5.12420","0.00118"
"61.56000","5.13024","0.00123"
"61.63200","5.13622","0.00118"
"61.70400","5.14220","0.00145"
"61.77600","5.14818","0.00095"
"61.84800","5.15422","0.00170"
"61.92000","5.16026","0.00112"
"61.99200","5.16623","0.00127"
"62.06400","5.17227","0.00093"
"62.13600","5.17825","0.00094"
"62.20800","5.18423","0.00138"
"62.28000","5.19015","0.00118"
"62.35200","5.19625","0.00125"
"62.42400","5.20223","0.00094"
"62.49600","5.20827","0.00164"
"62.56800","5.21424","0.00081"
"62.64000","5.22028","0.00111"
"62.71200","5.22620","0.00091"
"62.78400","5.23218","0.00110"
"62.85600","5.23816","0.00110"
"62.92800","5.24426","0.00149"
"63.00000","5.25024","0.00136"
"63.07200","5.25628","0.00090"
"63.14400","5.26226","0.00099"
"63.21600","5.26824","0.00114"
"63.28800","5.27421","0.00092"
"63.36000","5.28019","0.00155"
"63.43200","5.28617","0.00135"
"63.50400","5.29221","0.00141"
"63.57600","5.29825","0.00096"
"63.64800","5.30429","0.00127"
"63.72000","5.31021","0.00061"
"63.79200","5.31619","0.00160"
"63.86400","5.32217","0.00156"
"63.93600","5.32820","0.00087"
"64.00800","5.33424","0.00094"
"64.08000","5.34028","0.00116"
"64.15200","5.34620","0.00137"
"64.22400","5.35230","0.00138"
"64.29600","5.35822","0.00137"
"64.36800","5.36420","0.00083"
"64.44000","5.37018","0.00128"
"64.51200","5.37621","0.00139"
"64.58400","5.38219","0.00139"
"64.65600","5.38829","0.00103"
"64.72800","5.39427","0.00150"
"64.80000","5.40025","0.00142"
"64.87200","5.40623","0.00126"
"64.94400","5.41221","0.00136"
"65.01600","5.41819","0.00120"
"65.08800","5.42423","0.00097"
"65.16000","5.43026","0.00147"
"65.23200","5.43624","0.00092"
"65.30400","5.44228","0.00126"
"65.37600","5.44826","0.00159"
"65.44800","5.45418","0.00150"
"65.52000","5.46016","0.00105"
"65.59200","5.46626","0.00116"
"65.66400","5.47230","0.00119"
"65.73600","5.47822","0.00147"
"65.80800","5.48431","0.00141"
"65.88000","5.49023","0.00129"
"65.95200","5.49621","0.00119"
"66.02400","5.50219","0.00199"
"66.09600","5.50823","0.00168"
"66.16800","5.51421","0.00149"
"66.24000","5.52031","0.00143"
"66.31200","5.52623","0.00156"
"66.38400","5.53227","0.00182"
"66.45600","5.53824","0.00166"
"66.52800","5.54422","0.00152"
"66.60000","5.55020","0.00180"
"66.67200","5.55624","0.00155"
"66.74400","5.56222","0.00117"
"66.81600","5.56826","0.00118"
"66.88800","5.57424","0.00126"
"66.96000","5.58022","0.00168"
"67.03200","5.58620","0.00109"
"67.10400","5.59218","0.00152"
"67.17600","5.59821","0.00203"
"67.24800","5.60425","0.00171"
"67.32000","5.61023","0.00160"
"67.39200","5.61627","0.00165"
"67.46400","5.62225","0.00159"
"67.53600","5.62829","0.00197"
"67.60800","5.63421","0.00122"
"67.68000","5.64025","0.00174"
"67.75200","5.64622","0.00144"
"67.82400","5.65232","0.00135"
"67.89600","5.65824","0.00146"
"67.96800","5.66428","0.00130"
"68.04000","5.67020","0.00101"
"68.11200","5.67624","0.00171"
"68.18400","5.68216","0.00113"
"68.25600","5.68826","0.00123"
"68.32800","5.69424","0.00091"
"68.40000","5.70027","0.00133"
"68.47200","5.70619","0.00169"
"68.54400","5.71223","0.00118"
"68.61600","5.71815","0.00141"
"68.68800","5.72425","0.00162"
"68.76000","5.73023","0.00075"
"68.83200","5.73621","0.00187"
"68.90400","5.74225","0.00157"
"68.97600","5.74823","0.00129"
"69.04800","5.75426","0.00062"
"69.12000","5.76024","0.00090"
"69.19200","5.76622","0.00154"
"69.26400","5.77214","0.00147"
"69.33600","5.77818","0.00078"
"69.40800","5.78428","0.00147"
"69.48000","5.79026","0.00166"
"69.55200","5.79630","0.00121"
"69.62400","5.80222","0.00083"
"69.69600","5.80819","0.00151"
"69.76800","5.81417","0.00143"
"69.84000","5.82021","0.00127"
"69.91200","5.82625","0.00169"
"69.98400","5.83235","0.00195"
"70.05600","5.83821","0.00149"
"70.12800","5.84425","0.00130"
"70.20000","5.85017","0.00178"
"70.27200","5.85621","0.00138"
"70.34400","5.86212","0.00134"
"70.41600","5.86822","0.00097"
"70.48800","5.87426","0.00154"
"70.56000","5.88024","0.00160"
"70.63200","5.88628","0.00146"
"70.70400","5.89226","0.00110"
"70.77600","5.89824","0.00124"
"70.84800","5.90416","0.00139"
"70.92000","5.91020","0.00159"
"70.99200","5.91623","0.00118"
"71.06400","5.92227","0.00153"
"71.13600","5.92825","0.00180"
"71.20800","5.93423","0.00154"
"71.28000","5.94027","0.00163"
"71.35200","5.94619","0.00113"
"71.42400","5.95217","0.00220"
"71.49600","5.95815","0.00085"
"71.56800","5.96431","0.00193"
"71.64000","5.97022","0.00152"
"71.71200","5.97626","0.00121"
"71.78400","5.98224","0.00157"
"71.85600","5.98822","0.00090"
"71.92800","5.99420","0.00158"
"72.00000","6.00024","0.00192"
"72.07200","6.00616","0.00190"
"72.14400","6.01232","0.00179"
"72.21600","6.01823","0.00157"
"72.28800","6.02427","0.00122"
"72.36000","6.03019","0.00094"
"72.43200","6.03623","0.00131"
"72.50400","6.04215","0.00185"
"72.57600","6.04825","0.00170"
"72.64800","6.05423","0.00126"
"72.72000","6.06027","0.00115"
"72.79200","6.06625","0.00161"
"72.86400","6.07223","0.00155"
"72.93600","6.07820","0.00154"
"73.00800","6.08418","0.00142"
"73.08000","6.09016","0.00121"
"73.15200","6.09620","0.00125"
"73.22400","6.10224","0.00162"
"73.29600","6.10822","0.00133"
"73.36800","6.11426","0.00124"
"73.44000","6.12024","0.00130"
"73.51200","6.12616","0.00115"
"73.58400","6.13219","0.00114"
"73.65600","6.13817","0.00144"
"73.72800","6.14427","0.00134"
"73.80000","6.15025","0.00119"
"73.87200","6.15629","0.00136"
"73.94400","6.16227","0.00139"
"74.01600","6.16825","0.00122"
"74.08800","6.17423","0.00158"
"74.16000","6.18020","0.00095"
"74.23200","6.18624","0.00129"
"74.30400","6.19222","0.00136"
"74.37600","6.19820","0.00134"
"74.44800","6.20424","0.00175"
"74.52000","6.21022","0.00149"
"74.59200","6.21614","0.00107"
"74.66400","6.22218","0.00180"
"74.73600","6.22822","0.00124"
"74.80800","6.23425","0.00099"
"74.88000","6.24023","0.00188"
"74.95200","6.24627","0.00190"
"75.02400","6.25225","0.00197"
"75.09600","6.25817","0.00119"
"75.16800","6.26421","0.00135"
"75.24000","6.27019","0.00141"
"75.31200","6.27623","0.00171"
"75.38400","6.28221","0.00169"
"75.45600","6.28824","0.00134"
"75.52800","6.29422","0.00148"
"75.60000","6.30026","0.00166"
"75.67200","6.30618","0.00131"
"75.74400","6.31222","0.00096"
"75.81600","6.31820","0.00114"
"75.88800","6.32424","0.00166"
"75.96000","6.33022","0.00162"
"76.03200","6.33626","0.00164"
"76.10400","6.34217","0.00183"
"76.17600","6.34821","0.00136"
"76.24800","6.35419","0.00154"
"76.32000","6.36023","0.00102"
"76.39200","6.36621","0.00168"
"76.46400","6.37225","0.00137"
"76.53600","6.37823","0.00124"
"76.60800","6.38421","0.00103"
"76.68000","6.39019","0.00140"
"76.75200","6.39616","0.00191"
"76.82400","6.40214","0.00135"
"76.89600","6.40818","0.00128"
"76.96800","6.41422","0.00158"
"77.04000","6.42026","0.00163"
"77.11200","6.42624","0.00160"
"77.18400","6.43216","0.00115"
"77.25600","6.43820","0.00152"
"77.32800","6.44418","0.00158"
"77.40000","6.45021","0.00171"
"77.47200","6.45625","0.00137"
"77.54400","6.46223","0.00175"
"77.61600","6.46827","0.00109"
"77.68800","6.47425","0.00133"
"77.76000","6.48023","0.00172"
"77.83200","6.48621","0.00176"
"77.90400","6.49219","0.00134"
"77.97600","6.49823","0.00193"
"78.04800","6.50426","0.00126"
"78.12000","6.51024","0.00193"
"78.19200","6.51622","0.00136"
"78.26400","6.52220","0.00123"
"78.33600","6.52818","0.00163"
"78.40800","6.53416","0.00176"
"78.48000","6.54020","0.00134"
"78.55200","6.54624","0.00150"
"78.62400","6.55228","0.00204"
"78.69600","6.55825","0.00145"
"78.76800","6.56423","0.00212"
"78.84000","6.57021","0.00158"
"78.91200","6.57619","0.00132"
"78.98400","6.58217","0.00136"
"79.05600","6.58821","0.00070"
"79.12800","6.59425","0.00126"
"79.20000","6.60029","0.00192"
"79.27200","6.60627","0.00127"
"79.34400","6.61224","0.00191"
"79.41600","6.61816","0.00180"
"79.48800","6.62414","0.00179"
"79.56000","6.63018","0.00144"
"79.63200","6.63628","0.00138"
"79.70400","6.64226","0.00157"
"79.77600","6.64824","0.00154"
"79.84800","6.65422","0.00153"
"79.92000","6.66025","0.00191"
"79.99200","6.66623","0.00194"
"80.06400","6.67215","0.00202"
"80.13600","6.67819","0.00148"
"80.20800","6.68429","0.00184"
"80.28000","6.69027","0.00148"
"80.35200","6.69625","0.00128"
"80.42400","6.70223","0.00114"
"80.49600","6.70821","0.00153"
"80.56800","6.71419","0.00159"
"80.64000","6.72016","0.00133"
"80.71200","6.72620","0.00175"
"80.78400","6.73224","0.00174"
"80.85600","6.73822","0.00214"
"80.92800","6.74420","0.00188"
"81.00000","6.75018","0.00148"
"81.07200","6.75616","0.00169"
"81.14400","6.76220","0.00141"
"81.21600","6.76818","0.00178"
"81.28800","6.77421","0.00167"
"81.36000","6.78025","0.00118"
"81.43200","6.78623","0.00185"
"81.50400","6.79221","0.00143"
"81.57600","6.79819","0.00143"
"81.64800","6.80417","0.00197"
"81.72000","6.81021","0.00171"
"81.79200","6.81625","0.00154"
"81.86400","6.82222","0.00243"
"81.93600","6.82826","0.00134"
"82.00800","6.83424","0.00177"
"82.08000","6.84022","0.00186"
"82.15200","6.84620","0.00147"
"82.22400","6.85218","0.00181"
"82.29600","6.85822","0.00161"
"82.36800","6.86426","0.00173"
"82.44000","6.87024","0.00203"
"82.51200","6.87628","0.00184"
"82.58400","6.88225","0.00240"
"82.65600","6.88823","0.00129"
"82.72800","6.89421","0.00219"
"82.80000","6.90025","0.00211"
"82.87200","6.90623","0.00155"
"82.94400","6.91221","0.00102"
"83.01600","6.91825","0.00205"
"83.08800","6.92423","0.00168"
"83.16000","6.93020","0.00125"
"83.23200","6.93618","0.00184"
"83.30400","6.94222","0.00242"
"83.37600","6.94820","0.00171"
"83.44800","6.95430","0.00148"
"83.52000","6.96022","0.00199"
"83.59200","6.96626","0.00204"
"83.66400","6.97224","0.00212"
"83.73600","6.97822","0.00213"
"83.80800","6.98420","0.00227"
"83.88000","6.99023","0.00213"
"83.95200","6.99621","0.00192"
"84.02400","7.00225","0.00170"
"84.09600","7.00823","0.00153"
"84.16800","7.01421","0.00195"
"84.24000","7.02019","0.00171"
"84.31200","7.02623","0.00155"
"84.38400","7.03215","0.00190"
"84.45600","7.03824","0.00205"
"84.52800","7.04422","0.00167"
"84.60000","7.05026","0.00223"
"84.67200","7.05624","0.00226"
"84.74400","7.06222","0.00179"
"84.81600","7.06820","0.00181"
"84.88800","7.07418","0.00195"
"84.96000","7.08016","0.00226"
"85.03200","7.08626","0.00230"
"85.10400","7.09223","0.00181"
"85.17600","7.09821","0.00215"
"85.24800","7.10419","0.00167"
"85.32000","7.11023","0.00182"
"85.39200","7.11621","0.00166"
"85.46400","7.12219","0.00207"
"85.53600","7.12823","0.00154"
"85.60800","7.13427","0.00191"
"85.68000","7.14025","0.00227"
"85.75200","7.14622","0.00204"
"85.82400","7.15220","0.00244"
"85.89600","7.15818","0.00211"
"85.96800","7.16422","0.00217"
"86.04000","7.17020","0.00174"
"86.11200","7.17624","0.00208"
"86.18400","7.18222","0.00185"
"86.25600","7.18826","0.00184"
"86.32800","7.19424","0.00209"
"86.40000","7.20015","0.00220"
"86.47200","7.20619","0.00193"
"86.54400","7.21223","0.00155"
"86.61600","7.21827","0.00204"
"86.68800","7.22425","0.00178"
"86.76000","7.23029","0.00241"
"86.83200","7.23627","0.00156"
"86.90400","7.24225","0.00158"
"86.97600","7.24817","0.00175"
"87.04800","7.25420","0.00205"
"87.12000","7.26018","0.00184"
"87.19200","7.26628","0.00202"
"87.26400","7.27220","0.00198"
"87.33600","7.27824","0.00275"
"87.40800","7.28422","0.00162"
"87.48000","7.29020","0.00193"
"87.55200","7.29618","0.00264"
"87.62400","7.30222","0.00223"
"87.69600","7.30825","0.00212"
"87.76800","7.31429","0.00217"
"87.84000","7.32021","0.00166"
"87.91200","7.32625","0.00221"
"87.98400","7.33223","0.00233"
"88.05600","7.33821","0.00159"
"88.12800","7.34419","0.00176"
"88.20000","7.35023","0.00251"
"88.27200","7.35627","0.00182"
"88.34400","7.36230","0.00217"
"88.41600","7.36828","0.00209"
"88.48800","7.37426","0.00174"
"88.56000","7.38018","0.00225"
"88.63200","7.38622","0.00220"
"88.70400","7.39214","0.00226"
"88.77600","7.39824","0.00138"
"88.84800","7.40422","0.00229"
"88.92000","7.41025","0.00215"
"88.99200","7.41623","0.00246"
"89.06400","7.42221","0.00234"
"89.13600","7.42819","0.00265"
"89.20800","7.43423","0.00227"
"89.28000","7.44021","0.00285"
"89.35200","7.44625","0.00235"
"89.42400","7.45223","0.00226"
"89.49600","7.45827","0.00231"
"89.56800","7.46425","0.00206"
"89.64000","7.47016","0.00236"
"89.71200","7.47620","0.00186"
"89.78400","7.48218","0.00232"
"89.85600","7.48828","0.00232"
"89.92800","7.49420","0.00256"
"90.00000","7.50030","0.00239"
"90.07200","7.50622","0.00204"
"90.14400","7.51220","0.00214"
"90.21600","7.51818","0.00187"
"90.28800","7.52421","0.00182"
"90.36000","7.53019","0.00260"
"90.43200","7.53623","0.00206"
"90.50400","7.54227","0.00279"
"90.57600","7.54825","0.00188"
"90.64800","7.55429","0.00209"
"90.72000","7.56015","0.00193"
"90.79200","7.56619","0.00244"
"90.86400","7.57216","0.00208"
"90.93600","7.57826","0.00258"
"91.00800","7.58418","0.00227"
"91.08000","7.59028","0.00224"
"91.15200","7.59626","0.00232"
"91.22400","7.60224","0.00193"
"91.29600","7.60822","0.00217"
"91.36800","7.61420","0.00235"
"91.44000","7.62024","0.00264"
"91.51200","7.62627","0.00226"
"91.58400","7.63225","0.00207"
"91.65600","7.63829","0.00216"
"91.72800","7.64421","0.00206"
"91.80000","7.65025","0.00239"
"91.87200","7.65617","0.00191"
"91.94400","7.66227","0.00220"
"92.01600","7.66825","0.00201"
"92.08800","7.67429","0.00305"
"92.16000","7.68021","0.00204"
"92.23200","7.68624","0.00238"
"92.30400","7.69222","0.00238"
"92.37600","7.69820","0.00213"
"92.44800","7.70418","0.00236"
"92.52000","7.71022","0.00228"
"92.59200","7.71620","0.00242"
"92.66400","7.72224","0.00235"
"92.73600","7.72822","0.00239"
"92.80800","7.73425","0.00248"
"92.88000","7.74017","0.00265"
"92.95200","7.74621","0.00246"
"93.02400","7.75219","0.00227"
"93.09600","7.75829","0.00227"
"93.16800","7.76421","0.00231"
"93.24000","7.77025","0.00286"
"93.31200","7.77623","0.00220"
"93.38400","7.78227","0.00265"
"93.45600","7.78824","0.00239"
"93.52800","7.79422","0.00229"
"93.60000","7.80026","0.00237"
"93.67200","7.80630","0.00221"
"93.74400","7.81222","0.00281"
"93.81600","7.81820","0.00233"
"93.88800","7.82424","0.00208"
"93.96000","7.83022","0.00289"
"94.03200","7.83620","0.00259"
"94.10400","7.84223","0.00201"
"94.17600","7.84821","0.00190"
"94.24800","7.85425","0.00254"
"94.32000","7.86023","0.00253"
"94.39200","7.86627","0.00264"
"94.46400","7.87213","0.00223"
"94.53600","7.87823","0.00253"
"94.60800","7.88415","0.00277"
"94.68000","7.89024","0.00257"
"94.75200","7.89622","0.00238"
"94.82400","7.90226","0.00222"
"94.89600","7.90824","0.00230"
"94.96800","7.91428","0.00280"
"95.04000","7.92020","0.00286"
"95.11200","7.92618","0.00266"
"95.18400","7.93222","0.00241"
"95.25600","7.93826","0.00268"
"95.32800","7.94423","0.00248"
"95.40000","7.95027","0.00250"
"95.47200","7.95625","0.00216"
"95.54400","7.96223","0.00214"
"95.61600","7.96815","0.00255"
"95.68800","7.97425","0.00275"
"95.76000","7.98023","0.00308"
"95.83200","7.98627","0.00264"
"95.90400","7.99219","0.00238"
"95.97600","7.99823","0.00273"
"96.04800","8.00414","0.00250"
"96.12000","8.01018","0.00246"
"96.19200","8.01616","0.00318"
"96.26400","8.02226","0.00277"
"96.33600","8.02824","0.00261"
"96.40800","8.03428","0.00291"
"96.48000","8.04026","0.00248"
"96.55200","8.04624","0.00287"
"96.62400","8.05221","0.00250"
"96.69600","8.05819","0.00241"
"96.76800","8.06417","0.00304"
"96.84000","8.07021","0.00270"
"96.91200","8.07625","0.00226"
"96.98400","8.08223","0.00198"
"97.05600","8.08821","0.00265"
"97.12800","8.09419","0.00280"
"97.20000","8.10017","0.00272"
"97.27200","8.10614","0.00293"
"97.34400","8.11218","0.00252"
"97.41600","8.11828","0.00251"
"97.48800","8.12426","0.00284"
"97.56000","8.13024","0.00260"
"97.63200","8.13622","0.00304"
"97.70400","8.14226","0.00254"
"97.77600","8.14818","0.00277"
"97.84800","8.15422","0.00222"
"97.92000","8.16025","0.00231"
"97.99200","8.16629","0.00323"
"98.06400","8.17227","0.00277"
"98.13600","8.17825","0.00278"
"98.20800","8.18423","0.00259"
"98.28000","8.19021","0.00271"
"98.35200","8.19619","0.00247"
"98.42400","8.20217","0.00275"
"98.49600","8.20821","0.00245"
"98.56800","8.21424","0.00289"
"98.64000","8.22028","0.00219"
"98.71200","8.22626","0.00280"
"98.78400","8.23218","0.00310"
"98.85600","8.23816","0.00272"
"98.92800","8.24420","0.00279"
"99.00000","8.25018","0.00253"
"99.07200","8.25622","0.00213"
"99.14400","8.26220","0.00308"
"99.21600","8.26823","0.00292"
"99.28800","8.27421","0.00252"
"99.36000","8.28019","0.00224"
"99.43200","8.28623","0.00342"
"99.50400","8.29221","0.00262"
"99.57600","8.29819","0.00257"
"99.64800","8.30423","0.00293"
"99.72000","8.31027","0.00277"
"99.79200","8.31619","0.00267"
"99.86400","8.32216","0.00296"
"99.93600","8.32820","0.00280"
"100.00800","8.33418","0.00301"
"100.08000","8.34022","0.00303"
"100.15200","8.34620","0.00296"
"100.22400","8.35224","0.00272"
"100.29600","8.35828","0.00283"
"100.36800","8.36420","0.00315"
"100.44000","8.37018","0.00297"
"100.51200","8.37615","0.00325"
"100.58400","8.38219","0.00296"
"100.65600","8.38823","0.00262"
"100.72800","8.39421","0.00233"
"100.80000","8.40019","0.00208"
"100.87200","8.40623","0.00134"
"100.94400","8.41221","0.00066"
"101.01600","8.41819","0.00028"
"101.08800","8.42422","-0.00020"
"101.16000","8.43026","0.00039"
"101.23200","8.43624","-0.00004"
"101.30400","8.44222","0.00082"
"101.37600","8.44820","0.00067"
"101.44800","8.45424","0.00048"
"101.52000","8.46022","0.00000"
"101.59200","8.46620","-0.00007"
"101.66400","8.47224","0.00030"
"101.73600","8.47822","-0.00038"
"101.80800","8.48425","-0.00087"
"101.88000","8.49023","-0.00040"
"101.95200","8.49621","-0.00045"
"102.02400","8.50219","0.00023"
"102.09600","8.50817","-0.00002"
"102.16800","8.51421","0.00022"
"102.24000","8.52025","0.00030"
"102.31200","8.52629","0.00048"
"102.38400","8.53221","-0.00001"
"102.45600","8.53824","0.00032"
"102.52800","8.54416","0.00006"
"102.60000","8.55020","0.00023"
"102.67200","8.55618","0.00008"
"102.74400","8.56222","-0.00008"
"102.81600","8.56826","0.00001"
"102.88800","8.57424","0.00060"
"102.96000","8.58022","-0.00034"
"103.03200","8.58619","0.00001"
"103.10400","8.59217","0.00048"
"103.17600","8.59821","-0.00010"
"103.24800","8.60419","0.00031"
"103.32000","8.61023","0.00026"
"103.39200","8.61621","0.00055"
"103.46400","8.62225","-0.00001"
"103.53600","8.62829","0.00042"
"103.60800","8.63421","0.00068"
"103.68000","8.64019","0.00078"
"103.75200","8.64616","0.00100"
"103.82400","8.65226","0.00076"
"103.89600","8.65824","0.00039"
"103.96800","8.66428","0.00063"
"104.04000","8.67026","0.00047"
"104.11200","8.67630","0.00063"
"104.18400","8.68222","0.00064"
"104.25600","8.68820","0.00080"
"104.32800","8.69423","0.00040"
"104.40000","8.70033","0.00073"
"104.47200","8.70625","0.00067"
"104.54400","8.71229","0.00081"
"104.61600","8.71821","0.00106"
"104.68800","8.72425","0.00097"
"104.76000","8.73017","0.00059"
"104.83200","8.73621","0.00076"
"104.90400","8.74225","0.00060"
"104.90800","8.74260","0.00057"