File: Force_trajectories/170212_3/Specimen_RawData_7.csv
End date,"2/12/2017"
Specimen label,"5AG_34"
Maximum Load,"0.03571",N

Time,Extension,Load
(s),(mm),(N)
"0.00000","0.00000","-0.00001"
"0.45000","0.03785","0.00045"
"0.90000","0.07528","0.00031"
"1.35000","0.11270","0.00063"
"1.80000","0.15025","0.00086"
"2.25000","0.18774","0.00104"
"2.70000","0.22529","0.00120"
"3.15000","0.26272","0.00092"
"3.60000","0.30020","0.00111"
"4.05000","0.33769","0.00109"
"4.50000","0.37524","0.00085"
"4.95000","0.41273","0.00103"
"5.40000","0.45022","0.00104"
"5.85000","0.48776","0.00174"
"6.30000","0.52519","0.00167"
"6.75000","0.56268","0.00169"
"7.20000","0.60023","0.00171"
"7.65000","0.63777","0.00168"
"8.10000","0.67526","0.00174"
"8.55000","0.71269","0.00169"
"9.00000","0.75018","0.00161"
"9.45000","0.78767","0.00165"
"9.90000","0.82516","0.00085"
"10.35000","0.86276","0.00191"
"10.80000","0.90025","0.00168"
"11.25000","0.93780","0.00072"
"11.70000","0.97523","0.00128"
"12.15000","1.01266","0.00175"
"12.60000","1.05020","0.00186"
"13.05000","1.08769","0.00129"
"13.50000","1.12524","0.00168"
"13.95000","1.16279","0.00153"
"14.40000","1.20022","0.00213"
"14.85000","1.23770","0.00204"
"15.30000","1.27519","0.00155"
"15.75000","1.31274","0.00140"
"16.20000","1.35023","0.00135"
"16.65000","1.38777","0.00142"
"17.10000","1.42526","0.00151"
"17.55000","1.46275","0.00160"
"18.00000","1.50018","0.00186"
"18.45000","1.53773","0.00179"
"18.90000","1.57522","0.00199"
"19.35000","1.61270","0.00165"
"19.80000","1.65025","0.00170"
"20.25000","1.68768","0.00181"
"20.70000","1.72523","0.00156"
"21.15000","1.76277","0.00235"
"21.60000","1.80026","0.00156"
"22.05000","1.83781","0.00201"
"22.50000","1.87524","0.00196"
"22.95000","1.91267","0.00150"
"23.40000","1.95022","0.00171"
"23.85000","1.98776","0.00235"
"24.30000","2.02525","0.00199"
"24.75000","2.06274","0.00226"
"25.20000","2.10023","0.00208"
"25.65000","2.13772","0.00221"
"26.10000","2.17520","0.00166"
"26.55000","2.21269","0.00212"
"27.00000","2.25030","0.00239"
"27.45000","2.28773","0.00246"
"27.90000","2.32527","0.00219"
"28.35000","2.36270","0.00247"
"28.80000","2.40013","0.00208"
"29.25000","2.43768","0.00217"
"29.70000","2.47523","0.00226"
"30.15000","2.51277","0.00241"
"30.60000","2.55026","0.00175"
"31.05000","2.58769","0.00273"
"31.50000","2.62518","0.00186"
"31.95000","2.66273","0.00224"
"32.40000","2.70021","0.00192"
"32.85000","2.73770","0.00258"
"33.30000","2.77525","0.00231"
"33.75000","2.81268","0.00271"
"34.20000","2.85023","0.00202"
"34.65000","2.88771","0.00272"
"35.10000","2.92520","0.00213"
"35.55000","2.96269","0.00300"
"36.00000","3.00024","0.00289"
"36.45000","3.03773","0.00288"
"36.90000","3.07522","0.00241"
"37.35000","3.11270","0.00266"
"37.80000","3.15025","0.00264"
"38.25000","3.18780","0.00316"
"38.70000","3.22529","0.00292"
"39.15000","3.26277","0.00340"
"39.60000","3.30014","0.00289"
"40.05000","3.33769","0.00254"
"40.50000","3.37530","0.00277"
"40.95000","3.41279","0.00263"
"41.40000","3.45021","0.00303"
"41.85000","3.48770","0.00295"
"42.30000","3.52519","0.00298"
"42.75000","3.56274","0.00321"
"43.20000","3.60023","0.00276"
"43.65000","3.63771","0.00306"
"44.10000","3.67526","0.00287"
"44.55000","3.71275","0.00299"
"45.00000","3.75018","0.00294"
"45.45000","3.78773","0.00322"
"45.90000","3.82515","0.00302"
"46.35000","3.86276","0.00347"
"46.80000","3.90025","0.00260"
"47.25000","3.93780","0.00327"
"47.70000","3.97523","0.00373"
"48.15000","4.01271","0.00333"
"48.60000","4.05020","0.00330"
"49.05000","4.08775","0.00358"
"49.50000","4.12518","0.00326"
"49.95000","4.16273","0.00293"
"50.40000","4.20015","0.00382"
"50.85000","4.23770","0.00332"
"51.30000","4.27525","0.00236"
"51.75000","4.31274","0.00302"
"52.20000","4.35023","0.00345"
"52.65000","4.38771","0.00343"
"53.10000","4.42520","0.00333"
"53.55000","4.46269","0.00368"
"54.00000","4.50024","0.00317"
"54.45000","4.53773","0.00395"
"54.90000","4.57521","0.00392"
"55.35000","4.61276","0.00390"
"55.80000","4.65019","0.00319"
"56.25000","4.68768","0.00402"
"56.70000","4.72523","0.00443"
"57.15000","4.76277","0.00413"
"57.60000","4.80026","0.00401"
"58.05000","4.83775","0.00368"
"58.50000","4.87524","0.00411"
"58.95000","4.91267","0.00272"
"59.40000","4.95021","0.00308"
"59.85000","4.98770","0.00254"
"60.30000","5.02525","0.00374"
"60.75000","5.06280","0.00357"
"61.20000","5.10023","0.00390"
"61.65000","5.13771","0.00339"
"62.10000","5.17526","0.00370"
"62.55000","5.21275","0.00375"
"63.00000","5.25024","0.00431"
"63.45000","5.28773","0.00353"
"63.90000","5.32527","0.00380"
"64.35000","5.36264","0.00428"
"64.80000","5.40019","0.00477"
"65.25000","5.43774","0.00439"
"65.70000","5.47529","0.00443"
"66.15000","5.51271","0.00396"
"66.60000","5.55020","0.00431"
"67.05000","5.58769","0.00501"
"67.50000","5.62518","0.00377"
"67.95000","5.66273","0.00498"
"68.40000","5.70021","0.00440"
"68.85000","5.73770","0.00549"
"69.30000","5.77519","0.00401"
"69.75000","5.81268","0.00522"
"70.20000","5.85023","0.00518"
"70.65000","5.88777","0.00537"
"71.10000","5.92520","0.00563"
"71.55000","5.96275","0.00558"
"72.00000","6.00024","0.00527"
"72.45000","6.03767","0.00494"
"72.90000","6.07521","0.00579"
"73.35000","6.11270","0.00542"
"73.80000","6.15025","0.00567"
"74.25000","6.18774","0.00570"
"74.70000","6.22529","0.00551"
"75.15000","6.26271","0.00585"
"75.60000","6.30026","0.00580"
"76.05000","6.33769","0.00599"
"76.50000","6.37524","0.00579"
"76.95000","6.41279","0.00668"
"77.40000","6.45021","0.00624"
"77.85000","6.48770","0.00577"
"78.30000","6.52519","0.00660"
"78.75000","6.56274","0.00623"
"79.20000","6.60023","0.00619"
"79.65000","6.63771","0.00619"
"80.10000","6.67526","0.00615"
"80.55000","6.71269","0.00662"
"81.00000","6.75018","0.00748"
"81.45000","6.78773","0.00695"
"81.90000","6.82521","0.00704"
"82.35000","6.86270","0.00637"
"82.80000","6.90019","0.00703"
"83.25000","6.93768","0.00766"
"83.70000","6.97523","0.00716"
"84.15000","7.01271","0.00706"
"84.60000","7.05026","0.00809"
"85.05000","7.08769","0.00774"
"85.50000","7.12524","0.00779"
"85.95000","7.16273","0.00813"
"86.40000","7.20021","0.00825"
"86.85000","7.23770","0.00838"
"87.30000","7.27525","0.00803"
"87.75000","7.31274","0.00834"
"88.20000","7.35029","0.00900"
"88.65000","7.38771","0.00850"
"89.10000","7.42514","0.00790"
"89.55000","7.46269","0.00783"
"90.00000","7.50024","0.00695"
"90.45000","7.53773","0.00749"
"90.90000","7.57527","0.00731"
"91.35000","7.61264","0.00806"
"91.80000","7.65019","0.00778"
"92.25000","7.68768","0.00805"
"92.70000","7.72523","0.00793"
"93.15000","7.76277","0.00847"
"93.60000","7.80026","0.00821"
"94.05000","7.83775","0.00878"
"94.50000","7.87518","0.00832"
"94.95000","7.91273","0.00888"
"95.40000","7.95021","0.00941"
"95.85000","7.98770","0.00917"
"96.30000","8.02519","0.01026"
"96.75000","8.06280","0.00966"
"97.20000","8.10023","0.01028"
"97.65000","8.13765","0.01022"
"98.10000","8.17520","0.01082"
"98.55000","8.21275","0.01058"
"99.00000","8.25024","0.01095"
"99.45000","8.28773","0.01061"
"99.90000","8.32515","0.01018"
"100.35000","8.36270","0.01064"
"100.80000","8.40025","0.01123"
"101.25000","8.43780","0.01117"
"101.70000","8.47517","0.01163"
"102.15000","8.51271","0.01228"
"102.60000","8.55014","0.01244"
"103.05000","8.58769","0.01176"
"103.50000","8.62524","0.01230"
"103.95000","8.66273","0.01285"
"104.40000","8.70021","0.01287"
"104.85000","8.73770","0.01367"
"105.30000","8.77519","0.01312"
"105.75000","8.81268","0.01347"
"106.20000","8.85023","0.01342"
"106.65000","8.88777","0.01355"
"107.10000","8.92526","0.01379"
"107.55000","8.96275","0.01426"
"108.00000","9.00018","0.01414"
"108.45000","9.03767","0.01399"
"108.90000","9.07515","0.01480"
"109.35000","9.11276","0.01461"
"109.80000","9.15025","0.01361"
"110.25000","9.18774","0.01459"
"110.70000","9.22523","0.01446"
"111.15000","9.26271","0.01500"
"111.60000","9.30026","0.01556"
"112.05000","9.33769","0.01568"
"112.50000","9.37524","0.01559"
"112.95000","9.41279","0.01632"
"113.40000","9.45027","0.01603"
"113.85000","9.48770","0.01633"
"114.30000","9.52519","0.01618"
"114.75000","9.56274","0.01689"
"115.20000","9.60023","0.01660"
"115.65000","9.63771","0.01641"
"116.10000","9.67520","0.01668"
"116.55000","9.71269","0.01655"
"117.00000","9.75024","0.01474"
"117.45000","9.78779","0.01604"
"117.90000","9.82521","0.01584"
"118.35000","9.86276","0.01661"
"118.80000","9.90025","0.01603"
"119.25000","9.93762","0.01684"
"119.70000","9.97522","0.01713"
"120.15000","10.01271","0.01675"
"120.60000","10.05020","0.01706"
"121.05000","10.08775","0.01766"
"121.50000","10.12524","0.01790"
"121.95000","10.16267","0.01713"
"122.40000","10.20021","0.01787"
"122.85000","10.23776","0.01752"
"123.30000","10.27525","0.01764"
"123.75000","10.31274","0.01862"
"124.20000","10.35029","0.01860"
"124.65000","10.38771","0.01879"
"125.10000","10.42520","0.01903"
"125.55000","10.46269","0.01936"
"126.00000","10.50024","0.01950"
"126.45000","10.53772","0.01935"
"126.90000","10.57521","0.01961"
"127.35000","10.61270","0.01998"
"127.80000","10.65019","0.01907"
"128.25000","10.68774","0.01934"
"128.70000","10.72523","0.01987"
"129.15000","10.76277","0.02019"
"129.60000","10.80026","0.02033"
"130.05000","10.83775","0.01948"
"130.50000","10.87518","0.02066"
"130.95000","10.91273","0.02049"
"131.40000","10.95021","0.02079"
"131.85000","10.98776","0.02147"
"132.30000","11.02525","0.02125"
"132.75000","11.06274","0.02091"
"133.20000","11.10017","0.02172"
"133.65000","11.13777","0.02140"
"134.10000","11.17526","0.02168"
"134.55000","11.21275","0.02138"
"135.00000","11.25024","0.02239"
"135.45000","11.28773","0.02195"
"135.90000","11.32521","0.02226"
"136.35000","11.36270","0.02188"
"136.80000","11.40031","0.02244"
"137.25000","11.43774","0.02150"
"137.70000","11.47523","0.02213"
"138.15000","11.51271","0.02158"
"138.60000","11.55014","0.02146"
"139.05000","11.58769","0.02117"
"139.50000","11.62524","0.02128"
"139.95000","11.66273","0.02145"
"140.40000","11.70027","0.02192"
"140.85000","11.73776","0.02203"
"141.30000","11.77513","0.02151"
"141.75000","11.81274","0.02289"
"142.20000","11.85022","0.02325"
"142.65000","11.88777","0.02323"
"143.10000","11.92526","0.02305"
"143.55000","11.96269","0.02277"
"144.00000","12.00018","0.02260"
"144.45000","12.03767","0.02270"
"144.90000","12.07521","0.02298"
"145.35000","12.11270","0.02149"
"145.80000","12.15025","0.02093"
"146.25000","12.18780","0.02097"
"146.70000","12.22523","0.02165"
"147.15000","12.26271","0.02232"
"147.60000","12.30020","0.02224"
"148.05000","12.33775","0.02301"
"148.50000","12.37524","0.02283"
"148.95000","12.41273","0.02353"
"149.40000","12.45015","0.02322"
"149.85000","12.48770","0.02344"
"150.30000","12.52525","0.02390"
"150.75000","12.56274","0.02330"
"151.20000","12.60029","0.02380"
"151.65000","12.63771","0.02319"
"152.10000","12.67520","0.02341"
"152.55000","12.71269","0.02381"
"153.00000","12.75030","0.02354"
"153.45000","12.78779","0.02399"
"153.90000","12.82521","0.02362"
"154.35000","12.86276","0.02364"
"154.80000","12.90025","0.02370"
"155.25000","12.93774","0.02418"
"155.70000","12.97523","0.02415"
"156.15000","13.01277","0.02415"
"156.60000","13.05020","0.02422"
"157.05000","13.08775","0.02440"
"157.50000","13.12518","0.02418"
"157.95000","13.16267","0.02473"
"158.40000","13.20015","0.02407"
"158.85000","13.23776","0.02395"
"159.30000","13.27525","0.02424"
"159.75000","13.31274","0.02402"
"160.20000","13.35023","0.02436"
"160.65000","13.38771","0.02228"
"161.10000","13.42520","0.01574"
"161.55000","13.46275","0.01662"
"162.00000","13.50018","0.01593"
"162.45000","13.53773","0.01676"
"162.90000","13.57521","0.01746"
"163.35000","13.61270","0.01717"
"163.80000","13.65019","0.01778"
"164.25000","13.68774","0.01823"
"164.70000","13.72523","0.01843"
"165.15000","13.76271","0.01831"
"165.60000","13.80020","0.01909"
"166.05000","13.83769","0.01922"
"166.50000","13.87524","0.01889"
"166.95000","13.91279","0.02002"
"167.40000","13.95027","0.01997"
"167.85000","13.98776","0.02083"
"168.30000","14.02525","0.02148"
"168.75000","14.06268","0.02115"
"169.20000","14.10023","0.02095"
"169.65000","14.13777","0.02128"
"170.10000","14.17526","0.02165"
"170.55000","14.21269","0.02225"
"171.00000","14.25024","0.02265"
"171.45000","14.28767","0.02311"
"171.90000","14.32521","0.02146"
"172.35000","14.36276","0.02172"
"172.80000","14.40025","0.02225"
"173.25000","14.43774","0.02272"
"173.70000","14.47523","0.02233"
"174.15000","14.51271","0.02126"
"174.60000","14.55020","0.02089"
"175.05000","14.58769","0.02177"
"175.50000","14.62524","0.02147"
"175.95000","14.66272","0.02227"
"176.40000","14.70027","0.02242"
"176.85000","14.73770","0.02298"
"177.30000","14.77519","0.02359"
"177.75000","14.81274","0.02313"
"178.20000","14.85023","0.02332"
"178.65000","14.88771","0.02349"
"179.10000","14.92526","0.02319"
"179.55000","14.96269","0.02322"
"180.00000","15.00018","0.02344"
"180.45000","15.03773","0.02400"
"180.90000","15.07527","0.02377"
"181.35000","15.11270","0.02315"
"181.80000","15.15025","0.02279"
"182.25000","15.18774","0.02274"
"182.70000","15.22523","0.02268"
"183.15000","15.26271","0.02278"
"183.60000","15.30020","0.02228"
"184.05000","15.33775","0.02257"
"184.50000","15.37524","0.02307"
"184.95000","15.41267","0.02328"
"185.40000","15.45021","0.02358"
"185.85000","15.48770","0.02385"
"186.30000","15.52525","0.02370"
"186.75000","15.56274","0.02334"
"187.20000","15.60029","0.02320"
"187.65000","15.63771","0.02362"
"188.10000","15.67514","0.02355"
"188.55000","15.71275","0.02382"
"189.00000","15.75024","0.02377"
"189.45000","15.78772","0.02383"
"189.90000","15.82527","0.02373"
"190.35000","15.86270","0.02432"
"190.80000","15.90019","0.02456"
"191.25000","15.93774","0.02449"
"191.70000","15.97522","0.02444"
"192.15000","16.01271","0.02473"
"192.60000","16.05026","0.02500"
"193.05000","16.08775","0.02493"
"193.50000","16.12512","0.02519"
"193.95000","16.16273","0.02507"
"194.40000","16.20021","0.02573"
"194.85000","16.23776","0.02516"
"195.30000","16.27519","0.02558"
"195.75000","16.31274","0.02504"
"196.20000","16.35023","0.02564"
"196.65000","16.38765","0.02582"
"197.10000","16.42520","0.02628"
"197.55000","16.46275","0.02581"
"198.00000","16.50024","0.02523"
"198.45000","16.53772","0.02558"
"198.90000","16.57515","0.02561"
"199.35000","16.61270","0.02550"
"199.80000","16.65031","0.02601"
"200.25000","16.68774","0.02620"
"200.70000","16.72523","0.02587"
"201.15000","16.76277","0.02642"
"201.60000","16.80014","0.02633"
"202.05000","16.83769","0.02627"
"202.50000","16.87524","0.02576"
"202.95000","16.91278","0.02622"
"203.40000","16.95027","0.02625"
"203.85000","16.98776","0.02641"
"204.30000","17.02525","0.02634"
"204.75000","17.06274","0.02643"
"205.20000","17.10016","0.02609"
"205.65000","17.13777","0.02610"
"206.10000","17.17526","0.02682"
"206.55000","17.21275","0.02650"
"207.00000","17.25018","0.02557"
"207.45000","17.28766","0.02587"
"207.90000","17.32521","0.02600"
"208.35000","17.36270","0.02619"
"208.80000","17.40025","0.02644"
"209.25000","17.43780","0.02624"
"209.70000","17.47523","0.02674"
"210.15000","17.51271","0.02676"
"210.60000","17.55020","0.02679"
"211.05000","17.58775","0.02710"
"211.50000","17.62524","0.02722"
"211.95000","17.66272","0.02641"
"212.40000","17.70021","0.02726"
"212.85000","17.73770","0.02697"
"213.30000","17.77519","0.02697"
"213.75000","17.81274","0.02711"
"214.20000","17.85022","0.02735"
"214.65000","17.88771","0.02716"
"215.10000","17.92520","0.02779"
"215.55000","17.96269","0.02690"
"216.00000","18.00018","0.02749"
"216.45000","18.03773","0.02762"
"216.90000","18.07527","0.02728"
"217.35000","18.11276","0.02719"
"217.80000","18.15019","0.02789"
"218.25000","18.18768","0.02806"
"218.70000","18.22523","0.02793"
"219.15000","18.26271","0.02867"
"219.60000","18.30026","0.02871"
"220.05000","18.33775","0.02888"
"220.50000","18.37518","0.02854"
"220.95000","18.41266","0.02844"
"221.40000","18.45021","0.02880"
"221.85000","18.48770","0.02871"
"222.30000","18.52525","0.02943"
"222.75000","18.56280","0.02946"
"223.20000","18.60023","0.02982"
"223.65000","18.63771","0.02960"
"224.10000","18.67520","0.03019"
"224.55000","18.71269","0.03024"
"225.00000","18.75024","0.03030"
"225.45000","18.78773","0.03107"
"225.90000","18.82527","0.03108"
"226.35000","18.86276","0.03097"
"226.80000","18.90019","0.03132"
"227.25000","18.93774","0.03135"
"227.70000","18.97522","0.03209"
"228.15000","19.01271","0.03223"
"228.60000","19.05020","0.02839"
"229.05000","19.08769","0.02821"
"229.50000","19.12524","0.02899"
"229.95000","19.16278","0.02902"
"230.40000","19.20027","0.02874"
"230.85000","19.23770","0.02909"
"231.30000","19.27525","0.02960"
"231.75000","19.31268","0.02927"
"232.20000","19.35023","0.03001"
"232.65000","19.38771","0.02983"
"233.10000","19.42526","0.03023"
"233.55000","19.46275","0.03025"
"234.00000","19.50024","0.03036"
"234.45000","19.53773","0.03008"
"234.90000","19.57515","0.03047"
"235.35000","19.61270","0.03087"
"235.80000","19.65031","0.03094"
"236.25000","19.68773","0.03117"
"236.70000","19.72528","0.03125"
"237.15000","19.76265","0.03175"
"237.60000","19.80014","0.03108"
"238.05000","19.83769","0.03153"
"238.50000","19.87524","0.03178"
"238.95000","19.91278","0.03210"
"239.40000","19.95033","0.03188"
"239.85000","19.98770","0.03208"
"240.30000","20.02519","0.03219"
"240.75000","20.06274","0.03239"
"241.20000","20.10023","0.03256"
"241.65000","20.13771","0.03240"
"242.10000","20.17526","0.03258"
"242.55000","20.21275","0.03303"
"243.00000","20.25023","0.03298"
"243.45000","20.28772","0.03254"
"243.90000","20.32521","0.03294"
"244.35000","20.36276","0.03306"
"244.80000","20.40025","0.03321"
"245.25000","20.43774","0.03388"
"245.70000","20.47522","0.03366"
"246.15000","20.51271","0.03270"
"246.60000","20.55026","0.03329"
"247.05000","20.58775","0.03314"
"247.50000","20.62524","0.03350"
"247.95000","20.66273","0.03353"
"248.40000","20.70015","0.03389"
"248.85000","20.73776","0.03391"
"249.30000","20.77525","0.03461"
"249.75000","20.81273","0.03466"
"250.20000","20.85022","0.03442"
"250.65000","20.88771","0.03462"
"251.10000","20.92514","0.03488"
"251.55000","20.96269","0.03512"
"252.00000","21.00024","0.03487"
"252.45000","21.03778","0.03485"
"252.90000","21.07527","0.03469"
"253.35000","21.11276","0.03519"
"253.80000","21.15019","0.03539"
"254.25000","21.18768","0.03488"
"254.70000","21.22517","0.03519"
"255.15000","21.26277","0.03501"
"255.60000","21.30026","0.02058"
"256.05000","21.33769","0.02133"
"256.50000","21.37523","0.02210"
"256.95000","21.41266","0.02255"
"257.40000","21.45027","0.02136"
"257.85000","21.48770","0.02252"
"258.30000","21.52525","0.02333"
"258.75000","21.56280","0.02428"
"259.20000","21.60022","0.02478"
"259.65000","21.63765","0.02494"
"260.10000","21.67520","0.00900"
"260.55000","21.71275","0.00936"
"261.00000","21.75024","0.00822"
"261.45000","21.78773","0.00855"
"261.90000","21.82521","0.01099"
"262.35000","21.86270","0.00959"
"262.80000","21.90025","0.00993"
"263.25000","21.93773","0.01123"
"263.70000","21.97523","0.01128"
"264.15000","22.01271","0.01105"
"264.60000","22.05020","0.01130"
"265.05000","22.08769","0.01162"
"265.50000","22.12524","0.01137"
"265.95000","22.16278","0.01131"
"266.40000","22.20027","0.01236"
"266.85000","22.23776","0.01254"
"267.30000","22.27519","0.01275"
"267.75000","22.31262","0.01292"
"268.20000","22.35023","0.01321"
"268.65000","22.38771","0.01341"
"269.10000","22.42526","0.01332"
"269.55000","22.46281","0.01344"
"270.00000","22.50024","0.01393"
"270.45000","22.53766","0.01376"
"270.90000","22.57521","0.01324"
"271.35000","22.61270","0.01318"
"271.80000","22.65025","0.01324"
"272.25000","22.68774","0.01450"
"272.70000","22.72516","0.01389"
"273.15000","22.76265","0.01454"
"273.60000","22.80020","0.01472"
"274.05000","22.83769","0.01540"
"274.50000","22.87518","0.01434"
"274.95000","22.91278","0.01441"
"275.40000","22.95027","0.01481"
"275.85000","22.98776","0.01420"
"276.30000","23.02519","0.01344"
"276.75000","23.06268","0.01353"
"277.20000","23.10023","0.01420"
"277.65000","23.13771","0.01436"
"278.10000","23.17526","0.01375"
"278.55000","23.21269","0.01430"
"279.00000","23.25024","0.01492"
"279.45000","23.28778","0.01466"
"279.90000","23.32527","0.01481"
"280.35000","23.36276","0.01490"
"280.80000","23.40025","0.01490"
"281.25000","23.43768","0.01522"
"281.70000","23.47522","0.01535"
"282.15000","23.51277","0.01522"
"282.60000","23.55026","0.01604"
"283.05000","23.58775","0.01520"
"283.50000","23.62523","0.01562"
"283.95000","23.66273","0.01543"
"284.40000","23.70021","0.01518"
"284.85000","23.73770","0.01562"
"285.30000","23.77525","0.01188"
"285.75000","23.81273","0.01268"
"286.20000","23.85028","0.01285"
"286.65000","23.88771","0.01214"
"287.10000","23.92514","0.01214"
"287.55000","23.96269","0.01267"
"288.00000","24.00024","0.01270"
"288.45000","24.03778","0.01304"
"288.90000","24.07527","0.01317"
"289.35000","24.11270","0.01296"
"289.80000","24.15019","0.01250"
"290.25000","24.18773","0.01345"
"290.70000","24.22523","0.01322"
"291.15000","24.26271","0.01327"
"291.60000","24.30026","0.01405"
"292.05000","24.33769","0.01329"
"292.50000","24.37524","0.01306"
"292.95000","24.41272","0.01385"
"293.40000","24.45021","0.01398"
"293.85000","24.48776","0.01393"
"294.30000","24.52519","0.01355"
"294.75000","24.56274","0.01409"
"295.20000","24.60023","0.01368"
"295.65000","24.63771","0.01418"
"296.10000","24.67526","0.01447"
"296.55000","24.71281","0.01494"
"297.00000","24.75030","0.01528"
"297.45000","24.78773","0.01548"
"297.90000","24.82515","0.01543"
"298.35000","24.86270","0.01537"
"298.80000","24.90025","0.01576"
"299.25000","24.93780","0.01618"
"299.70000","24.97517","0.01622"
"300.15000","25.01271","0.01623"
"300.60000","25.05014","0.01681"
"301.05000","25.08769","0.01676"
"301.50000","25.12524","0.01675"
"301.95000","25.16273","0.01574"
"302.40000","25.20027","0.01546"
"302.85000","25.23776","0.01526"
"303.30000","25.27519","0.01614"
"303.75000","25.31268","0.01664"
"304.20000","25.35016","0.01648"
"304.65000","25.38777","0.01632"
"305.10000","25.42526","0.01483"
"305.55000","25.46275","0.01488"
"306.00000","25.50024","0.01512"
"306.45000","25.53772","0.01571"
"306.90000","25.57521","0.01548"
"307.35000","25.61276","0.01552"
"307.80000","25.65025","0.01582"
"308.25000","25.68774","0.01597"
"308.70000","25.72516","0.01607"
"309.15000","25.76265","0.01642"
"309.60000","25.80026","0.01632"
"310.05000","25.83775","0.01640"
"310.50000","25.87523","0.01632"
"310.95000","25.91272","0.01682"
"311.40000","25.95021","0.01768"
"311.85000","25.98770","0.01716"
"312.30000","26.02519","0.01690"
"312.75000","26.06274","0.01663"
"313.20000","26.10022","0.01652"
"313.65000","26.13777","0.01679"
"314.10000","26.17520","0.01669"
"314.55000","26.21269","0.01682"
"315.00000","26.25018","0.01672"
"315.45000","26.28778","0.01797"
"315.90000","26.32527","0.01769"
"316.35000","26.36276","0.01787"
"316.80000","26.40025","0.01727"
"317.25000","26.43768","0.01723"
"317.70000","26.47523","0.01761"
"318.15000","26.51271","0.01673"
"318.60000","26.55026","0.01650"
"319.05000","26.58781","0.01657"
"319.50000","26.62524","0.01691"
"319.95000","26.66272","0.01592"
"320.40000","26.70021","0.01678"
"320.85000","26.73770","0.01779"
"321.30000","26.77525","0.01645"
"321.75000","26.81280","0.01729"
"322.20000","26.85028","0.01734"
"322.65000","26.88765","0.01738"
"323.10000","26.92520","0.01751"
"323.55000","26.96269","0.01696"
"324.00000","27.00023","0.01696"
"324.45000","27.03773","0.01631"
"324.90000","27.07521","0.01644"
"325.35000","27.11270","0.01591"
"325.80000","27.15019","0.01689"
"326.25000","27.18774","0.01618"
"326.70000","27.22522","0.01723"
"327.15000","27.26271","0.01709"
"327.60000","27.30020","0.01717"
"328.05000","27.33769","0.01660"
"328.50000","27.37524","0.01681"
"328.95000","27.41273","0.01678"
"329.40000","27.45027","0.01586"
"329.85000","27.48776","0.01638"
"330.30000","27.52525","0.01626"
"330.75000","27.56268","0.01730"
"331.20000","27.60016","0.01659"
"331.65000","27.63777","0.01709"
"332.10000","27.67526","0.01574"
"332.55000","27.71275","0.01515"
"333.00000","27.75029","0.01664"
"333.45000","27.78772","0.01641"
"333.90000","27.82521","0.01653"
"334.35000","27.86270","0.01716"
"334.80000","27.90025","0.01664"
"335.25000","27.93780","0.01617"
"335.70000","27.97523","0.01706"
"336.15000","28.01265","0.01711"
"336.60000","28.05020","0.01642"
"337.05000","28.08769","0.01752"
"337.50000","28.12524","0.01745"
"337.95000","28.16273","0.01799"
"338.40000","28.20027","0.01793"
"338.85000","28.23770","0.01792"
"339.30000","28.27519","0.01797"
"339.75000","28.31268","0.01758"
"340.20000","28.35022","0.01748"
"340.65000","28.38771","0.01768"
"341.10000","28.42526","0.01845"
"341.55000","28.46275","0.01848"
"342.00000","28.50024","0.01779"
"342.45000","28.53772","0.01867"
"342.90000","28.57521","0.01933"
"343.35000","28.61270","0.01924"
"343.80000","28.65025","0.02021"
"344.25000","28.68768","0.02004"
"344.70000","28.72523","0.02025"
"345.15000","28.76271","0.02016"
"345.60000","28.80020","0.02043"
"346.05000","28.83775","0.02136"
"346.50000","28.87530","0.02059"
"346.95000","28.91272","0.02075"
"347.40000","28.95015","0.01974"
"347.85000","28.98770","0.01827"
"348.30000","29.02525","0.01807"
"348.75000","29.06274","0.01849"
"349.20000","29.10028","0.01883"
"349.65000","29.13765","0.01958"
"350.10000","29.17514","0.02079"
"350.55000","29.21269","0.02022"
"351.00000","29.25023","0.02065"
"351.45000","29.28773","0.02103"
"351.90000","29.32527","0.02119"
"352.35000","29.36276","0.02190"
"352.80000","29.40025","0.02210"
"353.25000","29.43774","0.02226"
"353.70000","29.47517","0.02249"
"354.15000","29.51271","0.02306"
"354.60000","29.55020","0.02287"
"355.05000","29.58781","0.02092"
"355.50000","29.62524","0.02100"
"355.95000","29.66266","0.02104"
"356.40000","29.70027","0.02164"
"356.85000","29.73770","0.02143"
"357.30000","29.77525","0.02118"
"357.75000","29.81273","0.02138"
"358.20000","29.85016","0.02137"
"358.65000","29.88771","0.02166"
"359.10000","29.92526","0.02181"
"359.55000","29.96275","0.02250"
"360.00000","30.00018","0.02212"
"360.45000","30.03778","0.02252"
"360.90000","30.07521","0.02241"
"361.35000","30.11270","0.02223"
"361.80000","30.15019","0.02300"
"362.25000","30.18774","0.02294"
"362.70000","30.22523","0.02251"
"363.15000","30.26271","0.02140"
"363.60000","30.30020","0.02290"
"364.05000","30.33769","0.02152"
"364.50000","30.37518","0.01240"
"364.95000","30.41279","0.01112"
"365.40000","30.45021","0.01349"
"365.85000","30.48776","0.01281"
"366.30000","30.52519","0.01425"
"366.75000","30.56268","0.01494"
"367.20000","30.60022","0.01394"
"367.65000","30.63777","0.01426"
"368.10000","30.67526","0.01492"
"368.55000","30.71275","0.01475"
"369.00000","30.75024","0.01508"
"369.45000","30.78773","0.01551"
"369.90000","30.82527","0.01555"
"370.35000","30.86270","0.01596"
"370.80000","30.90025","0.01633"
"371.25000","30.93779","0.01656"
"371.70000","30.97522","0.01737"
"372.15000","31.01271","0.01767"
"372.60000","31.05020","0.01744"
"373.05000","31.08769","0.01792"
"373.50000","31.12530","0.01782"
"373.95000","31.16272","0.01801"
"374.40000","31.20021","0.01801"
"374.85000","31.23770","0.01804"
"375.30000","31.27519","0.01882"
"375.75000","31.31273","0.01870"
"376.20000","31.35022","0.01863"
"376.65000","31.38771","0.01915"
"377.10000","31.42520","0.01931"
"377.55000","31.46263","0.01840"
"378.00000","31.50030","0.01863"
"378.45000","31.53772","0.01884"
"378.90000","31.57521","0.01841"
"379.35000","31.61276","0.01899"
"379.80000","31.65025","0.01953"
"380.25000","31.68767","0.01967"
"380.70000","31.72516","0.01942"
"381.15000","31.76271","0.01940"
"381.60000","31.80026","0.02018"
"382.05000","31.83775","0.01973"
"382.50000","31.87523","0.02089"
"382.95000","31.91272","0.02055"
"383.40000","31.95021","0.02131"
"383.85000","31.98770","0.02160"
"384.30000","32.02525","0.02164"
"384.75000","32.06274","0.02193"
"385.20000","32.10022","0.02183"
"385.65000","32.13771","0.02232"
"386.10000","32.17520","0.02071"
"386.55000","32.21275","0.02106"
"387.00000","32.25023","0.02194"
"387.45000","32.28772","0.02112"
"387.90000","32.32527","0.02164"
"388.35000","32.36270","0.02180"
"388.80000","32.40019","0.02227"
"389.25000","32.43773","0.02266"
"389.70000","32.47522","0.02267"
"390.15000","32.51271","0.02288"
"390.60000","32.55025","0.02261"
"391.05000","32.58775","0.02346"
"391.50000","32.62518","0.02337"
"391.95000","32.66272","0.02357"
"392.40000","32.70027","0.02338"
"392.85000","32.73776","0.02354"
"393.30000","32.77525","0.02409"
"393.75000","32.81273","0.02363"
"394.20000","32.85016","0.02430"
"394.65000","32.88771","0.02412"
"395.10000","32.92526","0.02482"
"395.55000","32.96275","0.02476"
"396.00000","33.00023","0.02475"
"396.45000","33.03772","0.02394"
"396.90000","33.07515","0.02473"
"397.35000","33.11270","0.02493"
"397.80000","33.15025","0.02474"
"398.25000","33.18774","0.02512"
"398.70000","33.22528","0.02468"
"399.15000","33.26271","0.02576"
"399.60000","33.30014","0.02535"
"400.05000","33.33768","0.02603"
"400.50000","33.37523","0.02599"
"400.95000","33.41272","0.02622"
"401.40000","33.45021","0.02618"
"401.85000","33.48770","0.02627"
"402.30000","33.52519","0.02651"
"402.75000","33.56268","0.02673"
"403.20000","33.60022","0.02646"
"403.65000","33.63771","0.02680"
"404.10000","33.67526","0.02681"
"404.55000","33.71275","0.02677"
"405.00000","33.75024","0.02761"
"405.45000","33.78772","0.02776"
"405.90000","33.82521","0.02822"
"406.35000","33.86270","0.02809"
"406.80000","33.90025","0.02748"
"407.25000","33.93773","0.02817"
"407.70000","33.97522","0.02809"
"408.15000","34.01271","0.02770"
"408.60000","34.05026","0.02802"
"409.05000","34.08775","0.02882"
"409.50000","34.12529","0.02861"
"409.95000","34.16272","0.02881"
"410.40000","34.20021","0.02904"
"410.85000","34.23770","0.02900"
"411.30000","34.27525","0.02920"
"411.75000","34.31273","0.02852"
"412.20000","34.35022","0.02802"
"412.65000","34.38771","0.02666"
"413.10000","34.42526","0.02699"
"413.55000","34.46269","0.02785"
"414.00000","34.50018","0.02767"
"414.45000","34.53772","0.02735"
"414.90000","34.57521","0.02750"
"415.35000","34.61276","0.02824"
"415.80000","34.65019","0.02833"
"416.25000","34.68768","0.02873"
"416.70000","34.72516","0.02922"
"417.15000","34.76271","0.02945"
"417.60000","34.80026","0.02976"
"418.05000","34.83780","0.02907"
"418.50000","34.87523","0.02996"
"418.95000","34.91267","0.02973"
"419.40000","34.95021","0.02880"
"419.85000","34.98770","0.02836"
"420.30000","35.02525","0.02429"
"420.75000","35.06273","0.01619"
"421.20000","35.10022","0.01808"
"421.65000","35.13771","0.01852"
"422.10000","35.17520","0.01941"
"422.55000","35.21269","0.01933"
"423.00000","35.25024","0.01990"
"423.45000","35.28772","0.02088"
"423.90000","35.32527","0.02024"
"424.35000","35.36270","0.02081"
"424.80000","35.40018","0.01920"
"425.25000","35.43773","0.01984"
"425.70000","35.47528","0.02068"
"426.15000","35.51277","0.02121"
"426.60000","35.55026","0.02165"
"427.05000","35.58769","0.02118"
"427.50000","35.62523","0.02209"
"427.95000","35.66278","0.01916"
"428.40000","35.70027","0.01893"
"428.85000","35.73770","0.01931"
"429.30000","35.77525","0.02030"
"429.75000","35.81268","0.02081"
"430.20000","35.85022","0.02091"
"430.65000","35.88771","0.02110"
"431.10000","35.92526","0.02055"
"431.55000","35.96275","0.02048"
"432.00000","36.00023","0.02067"
"432.45000","36.03766","0.02081"
"432.90000","36.07515","0.02121"
"433.35000","36.11264","0.02134"
"433.80000","36.15025","0.02185"
"434.25000","36.18773","0.02157"
"434.70000","36.22528","0.02211"
"435.15000","36.26271","0.02206"
"435.60000","36.30020","0.02256"
"436.05000","36.33768","0.02270"
"436.50000","36.37524","0.02221"
"436.95000","36.41272","0.02335"
"437.40000","36.45027","0.02361"
"437.85000","36.48770","0.02356"
"438.30000","36.52518","0.02360"
"438.75000","36.56273","0.02359"
"439.20000","36.60028","0.02332"
"439.65000","36.63771","0.02370"
"440.10000","36.67526","0.02388"
"440.55000","36.71269","0.02402"
"441.00000","36.75018","0.02340"
"441.45000","36.78772","0.02377"
"441.90000","36.82527","0.02407"
"442.35000","36.86270","0.02401"
"442.80000","36.90025","0.02420"
"443.25000","36.93774","0.02440"
"443.70000","36.97522","0.02420"
"444.15000","37.01271","0.02474"
"444.60000","37.05026","0.02488"
"445.05000","37.08775","0.02512"
"445.50000","37.12529","0.02499"
"445.95000","37.16272","0.02411"
"446.40000","37.20015","0.02362"
"446.85000","37.23770","0.02411"
"447.30000","37.27525","0.02425"
"447.75000","37.31274","0.02398"
"448.20000","37.35028","0.02380"
"448.65000","37.38771","0.02411"
"449.10000","37.42520","0.02447"
"449.55000","37.46268","0.02390"
"450.00000","37.50024","0.02458"
"450.45000","37.53772","0.02458"
"450.90000","37.57527","0.02459"
"451.35000","37.61276","0.02531"
"451.80000","37.65013","0.02492"
"452.25000","37.68773","0.02536"
"452.70000","37.72516","0.02528"
"453.15000","37.76277","0.02528"
"453.60000","37.80026","0.02542"
"454.05000","37.83775","0.02524"
"454.50000","37.87518","0.02546"
"454.95000","37.91266","0.02581"
"455.40000","37.95021","0.02583"
"455.85000","37.98770","0.02601"
"456.30000","38.02525","0.02602"
"456.75000","38.06273","0.02601"
"457.20000","38.10022","0.02570"
"457.65000","38.13771","0.02611"
"458.10000","38.17520","0.02625"
"458.55000","38.21275","0.02615"
"459.00000","38.25023","0.02569"
"459.45000","38.28772","0.02587"
"459.90000","38.32521","0.02659"
"460.35000","38.36270","0.02606"
"460.80000","38.40025","0.02614"
"461.25000","38.43779","0.02633"
"461.70000","38.47528","0.02284"
"462.15000","38.51277","0.02177"
"462.60000","38.55026","0.02276"
"463.05000","38.58768","0.02310"
"463.50000","38.62523","0.02338"
"463.95000","38.66272","0.02374"
"464.40000","38.70027","0.02328"
"464.85000","38.73770","0.02383"
"465.30000","38.77519","0.02308"
"465.75000","38.81268","0.02394"
"466.20000","38.85016","0.02303"
"466.65000","38.88771","0.02381"
"467.10000","38.92520","0.02369"
"467.55000","38.96281","0.02418"
"468.00000","39.00024","0.02406"
"468.45000","39.03766","0.02421"
"468.90000","39.07521","0.02384"
"469.35000","39.11270","0.02423"
"469.80000","39.15025","0.02475"
"470.25000","39.18773","0.02467"
"470.70000","39.22522","0.02443"
"471.15000","39.26271","0.02439"
"471.60000","39.30020","0.02473"
"472.05000","39.33769","0.02436"
"472.50000","39.37523","0.02486"
"472.95000","39.41272","0.02435"
"473.40000","39.45021","0.02528"
"473.85000","39.48770","0.02524"
"474.30000","39.52518","0.02511"
"474.75000","39.56274","0.02532"
"475.20000","39.60022","0.02513"
"475.65000","39.63777","0.02501"
"476.10000","39.67520","0.02524"
"476.55000","39.71268","0.02519"
"477.00000","39.75023","0.02497"
"477.45000","39.78772","0.02498"
"477.90000","39.82521","0.02530"
"478.35000","39.86276","0.02547"
"478.80000","39.90019","0.02559"
"479.25000","39.93768","0.02595"
"479.70000","39.97522","0.02561"
"480.15000","40.01271","0.02533"
"480.60000","40.05026","0.02606"
"481.05000","40.08775","0.02586"
"481.50000","40.12524","0.02557"
"481.95000","40.16272","0.02557"
"482.40000","40.20021","0.02521"
"482.85000","40.23770","0.02530"
"483.30000","40.27525","0.02596"
"483.75000","40.31279","0.02545"
"484.20000","40.35028","0.02607"
"484.65000","40.38771","0.02616"
"485.10000","40.42514","0.02594"
"485.55000","40.46275","0.02556"
"486.00000","40.50024","0.02568"
"486.45000","40.53778","0.02561"
"486.90000","40.57521","0.02598"
"487.35000","40.61270","0.02518"
"487.80000","40.65024","0.02567"
"488.25000","40.68774","0.02523"
"488.70000","40.72528","0.02533"
"489.15000","40.76265","0.02522"
"489.60000","40.80026","0.02550"
"490.05000","40.83768","0.02599"
"490.50000","40.87518","0.02594"
"490.95000","40.91272","0.02592"
"491.40000","40.95021","0.02584"
"491.85000","40.98770","0.02646"
"492.30000","41.02525","0.02592"
"492.75000","41.06268","0.02603"
"493.20000","41.10016","0.02655"
"493.65000","41.13771","0.02632"
"494.10000","41.17526","0.02663"
"494.55000","41.21274","0.02652"
"495.00000","41.25029","0.02679"
"495.45000","41.28766","0.02655"
"495.90000","41.32515","0.02692"
"496.35000","41.36270","0.02716"
"496.80000","41.40025","0.02720"
"497.25000","41.43773","0.02778"
"497.70000","41.47528","0.02774"
"498.15000","41.51271","0.02740"
"498.60000","41.55020","0.02729"
"499.05000","41.58775","0.02800"
"499.50000","41.62517","0.02773"
"499.95000","41.66272","0.02735"
"500.40000","41.70027","0.02755"
"500.85000","41.73776","0.02771"
"501.30000","41.77518","0.02781"
"501.75000","41.81273","0.02768"
"502.20000","41.85022","0.02753"
"502.65000","41.88777","0.02732"
"503.10000","41.92526","0.02768"
"503.55000","41.96275","0.02763"
"504.00000","42.00018","0.02820"
"504.45000","42.03766","0.02795"
"504.90000","42.07521","0.02800"
"505.35000","42.11270","0.02751"
"505.80000","42.15019","0.02789"
"506.25000","42.18774","0.02809"
"506.70000","42.22516","0.02838"
"507.15000","42.26271","0.02812"
"507.60000","42.30026","0.02831"
"508.05000","42.33768","0.02819"
"508.50000","42.37523","0.02783"
"508.95000","42.41272","0.02792"
"509.40000","42.45021","0.02810"
"509.85000","42.48770","0.02791"
"510.30000","42.52525","0.02804"
"510.75000","42.56273","0.02836"
"511.20000","42.60022","0.02827"
"511.65000","42.63777","0.02859"
"512.10000","42.67520","0.02873"
"512.55000","42.71269","0.02852"
"513.00000","42.75017","0.02580"
"513.45000","42.78778","0.02429"
"513.90000","42.82527","0.02482"
"514.35000","42.86270","0.02514"
"514.80000","42.90018","0.02476"
"515.25000","42.93768","0.02475"
"515.70000","42.97522","0.02517"
"516.15000","43.01271","0.02500"
"516.60000","43.05026","0.02430"
"517.05000","43.08781","0.02484"
"517.50000","43.12523","0.02504"
"517.95000","43.16266","0.02477"
"518.40000","43.20021","0.02435"
"518.85000","43.23770","0.02493"
"519.30000","43.27525","0.02365"
"519.75000","43.31274","0.02401"
"520.20000","43.35022","0.02017"
"520.65000","43.38765","0.01679"
"521.10000","43.42519","0.01907"
"521.55000","43.46274","0.01756"
"522.00000","43.50023","0.01612"
"522.45000","43.53772","0.01630"
"522.90000","43.57521","0.01592"
"523.35000","43.61270","0.01603"
"523.80000","43.65025","0.01545"
"524.25000","43.68779","0.01591"
"524.70000","43.72522","0.01543"
"525.15000","43.76277","0.01602"
"525.60000","43.80020","0.01517"
"526.05000","43.83762","0.01493"
"526.50000","43.87524","0.01491"
"526.95000","43.91278","0.01594"
"527.40000","43.95021","0.01534"
"527.85000","43.98776","0.01593"
"528.30000","44.02524","0.01617"
"528.75000","44.06261","0.01624"
"529.20000","44.10022","0.01673"
"529.65000","44.13777","0.01579"
"530.10000","44.17526","0.01624"
"530.55000","44.21275","0.01627"
"531.00000","44.25018","0.01676"
"531.45000","44.28766","0.01706"
"531.90000","44.32515","0.01655"
"532.35000","44.36270","0.01644"
"532.80000","44.40025","0.01647"
"533.25000","44.43780","0.01648"
"533.70000","44.47528","0.01710"
"534.15000","44.51271","0.01666"
"534.60000","44.55019","0.01705"
"535.05000","44.58769","0.01737"
"535.50000","44.62523","0.01714"
"535.95000","44.66272","0.01743"
"536.40000","44.70026","0.01708"
"536.85000","44.73770","0.01719"
"537.30000","44.77519","0.01776"
"537.75000","44.81273","0.01776"
"538.20000","44.85022","0.01778"
"538.65000","44.88777","0.01808"
"539.10000","44.92525","0.01786"
"539.55000","44.96268","0.01819"
"540.00000","45.00017","0.01789"
"540.45000","45.03778","0.01802"
"540.90000","45.07527","0.01856"
"541.35000","45.11276","0.01860"
"541.80000","45.15024","0.01823"
"542.25000","45.18773","0.01895"
"542.70000","45.22522","0.01896"
"543.15000","45.26271","0.01819"
"543.60000","45.30020","0.01858"
"544.05000","45.33775","0.01923"
"544.50000","45.37523","0.01905"
"544.95000","45.41266","0.01930"
"545.40000","45.45015","0.01962"
"545.85000","45.48770","0.01977"
"546.30000","45.52525","0.01952"
"546.75000","45.56279","0.01931"
"547.20000","45.60028","0.01965"
"547.65000","45.63771","0.01936"
"548.10000","45.67520","0.02034"
"548.55000","45.71269","0.02003"
"549.00000","45.75023","0.02025"
"549.45000","45.78772","0.01983"
"549.90000","45.82526","0.02004"
"550.35000","45.86270","0.02016"
"550.80000","45.90019","0.01984"
"551.25000","45.93768","0.01977"
"551.70000","45.97522","0.02005"
"552.15000","46.01271","0.01992"
"552.60000","46.05025","0.02054"
"553.05000","46.08775","0.02064"
"553.50000","46.12523","0.02021"
"553.95000","46.16266","0.02076"
"554.40000","46.20021","0.02026"
"554.85000","46.23776","0.02076"
"555.30000","46.27524","0.02054"
"555.75000","46.31273","0.02070"
"556.20000","46.35016","0.02045"
"556.65000","46.38771","0.02087"
"557.10000","46.42526","0.02145"
"557.55000","46.46281","0.02082"
"558.00000","46.50018","0.02091"
"558.45000","46.53772","0.02125"
"558.90000","46.57515","0.02091"
"559.35000","46.61270","0.02109"
"559.80000","46.65025","0.02099"
"560.25000","46.68773","0.02083"
"560.70000","46.72522","0.02081"
"561.15000","46.76271","0.02086"
"561.60000","46.80020","0.02095"
"562.05000","46.83769","0.02126"
"562.50000","46.87518","0.02128"
"562.95000","46.91278","0.02168"
"563.40000","46.95026","0.02153"
"563.85000","46.98776","0.02132"
"564.30000","47.02518","0.02127"
"564.75000","47.06267","0.02026"
"565.20000","47.10016","0.02108"
"565.65000","47.13777","0.02124"
"566.10000","47.17525","0.02133"
"566.55000","47.21275","0.02170"
"567.00000","47.25017","0.02132"
"567.45000","47.28766","0.02119"
"567.90000","47.32521","0.02103"
"568.35000","47.36276","0.02113"
"568.80000","47.40018","0.02183"
"569.25000","47.43774","0.02081"
"569.70000","47.47522","0.02149"
"570.15000","47.51271","0.02135"
"570.60000","47.55020","0.02087"
"571.05000","47.58775","0.02092"
"571.50000","47.62523","0.02142"
"571.95000","47.66272","0.02113"
"572.40000","47.70021","0.02138"
"572.85000","47.73769","0.02174"
"573.30000","47.77519","0.02123"
"573.75000","47.81273","0.02170"
"574.20000","47.85022","0.02099"
"574.65000","47.88777","0.02119"
"575.10000","47.92526","0.02118"
"575.55000","47.96263","0.02171"
"576.00000","48.00024","0.02158"
"576.45000","48.03772","0.02156"
"576.90000","48.07527","0.02151"
"577.35000","48.11276","0.02147"
"577.80000","48.15024","0.02208"
"578.25000","48.18773","0.02204"
"578.70000","48.22517","0.02170"
"579.15000","48.26271","0.02212"
"579.60000","48.30025","0.02168"
"580.05000","48.33775","0.02198"
"580.50000","48.37523","0.02221"
"580.95000","48.41266","0.02217"
"581.40000","48.45021","0.02221"
"581.85000","48.48770","0.02196"
"582.30000","48.52525","0.02192"
"582.75000","48.56274","0.02214"
"583.20000","48.60022","0.02260"
"583.65000","48.63771","0.02231"
"584.10000","48.67520","0.02235"
"584.55000","48.71268","0.02300"
"585.00000","48.75023","0.02244"
"585.45000","48.78772","0.02215"
"585.90000","48.82527","0.02182"
"586.35000","48.86269","0.02166"
"586.80000","48.90025","0.02200"
"587.25000","48.93773","0.02233"
"587.70000","48.97522","0.02233"
"588.15000","49.01271","0.02286"
"588.60000","49.05019","0.02256"
"589.05000","49.08768","0.02216"
"589.50000","49.12524","0.02202"
"589.95000","49.16272","0.02317"
"590.40000","49.20027","0.02324"
"590.85000","49.23776","0.02273"
"591.30000","49.27524","0.02255"
"591.75000","49.31273","0.02289"
"592.20000","49.35017","0.02339"
"592.65000","49.38771","0.02312"
"593.10000","49.42525","0.02374"
"593.55000","49.46275","0.02342"
"594.00000","49.50023","0.02379"
"594.45000","49.53772","0.02372"
"594.90000","49.57515","0.02314"
"595.35000","49.61269","0.02373"
"595.80000","49.65025","0.02312"
"596.25000","49.68774","0.02288"
"596.70000","49.72528","0.02308"
"597.15000","49.76271","0.02389"
"597.60000","49.80014","0.02369"
"598.05000","49.83768","0.02383"
"598.50000","49.87523","0.02408"
"598.95000","49.91272","0.02366"
"599.40000","49.95021","0.02368"
"599.85000","49.98770","0.02434"
"600.30000","50.02519","0.02398"
"600.75000","50.06267","0.02431"
"601.20000","50.10022","0.02467"
"601.65000","50.13771","0.02471"
"602.10000","50.17526","0.02460"
"602.55000","50.21268","0.02504"
"603.00000","50.25018","0.02418"
"603.45000","50.28772","0.02391"
"603.90000","50.32521","0.02410"
"604.35000","50.36276","0.02446"
"604.80000","50.40024","0.02461"
"605.25000","50.43773","0.02421"
"605.70000","50.47516","0.02396"
"606.15000","50.51271","0.02459"
"606.60000","50.55025","0.02414"
"607.05000","50.58775","0.02455"
"607.50000","50.62524","0.02465"
"607.95000","50.66266","0.02462"
"608.40000","50.70021","0.02456"
"608.85000","50.73769","0.02496"
"609.30000","50.77525","0.02484"
"609.75000","50.81279","0.02488"
"610.20000","50.85028","0.02475"
"610.65000","50.88771","0.02518"
"611.10000","50.92520","0.02495"
"611.55000","50.96268","0.02443"
"612.00000","51.00018","0.02469"
"612.45000","51.03772","0.02481"
"612.90000","51.07521","0.02499"
"613.35000","51.11275","0.02526"
"613.80000","51.15019","0.02506"
"614.25000","51.18767","0.02558"
"614.70000","51.22522","0.02539"
"615.15000","51.26271","0.02506"
"615.60000","51.30026","0.02578"
"616.05000","51.33774","0.02506"
"616.50000","51.37524","0.02471"
"616.95000","51.41272","0.02470"
"617.40000","51.45021","0.02357"
"617.85000","51.48776","0.02455"
"618.30000","51.52518","0.02407"
"618.75000","51.56273","0.02433"
"619.20000","51.60022","0.02422"
"619.65000","51.63771","0.02441"
"620.10000","51.67520","0.02452"
"620.55000","51.71269","0.02421"
"621.00000","51.75017","0.02473"
"621.45000","51.78772","0.02470"
"621.90000","51.82521","0.02541"
"622.35000","51.86269","0.02550"
"622.80000","51.90024","0.02501"
"623.25000","51.93779","0.02530"
"623.70000","51.97522","0.02527"
"624.15000","52.01277","0.02549"
"624.60000","52.05020","0.02518"
"625.05000","52.08762","0.02517"
"625.50000","52.12518","0.02490"
"625.95000","52.16278","0.02539"
"626.40000","52.20026","0.02605"
"626.85000","52.23775","0.02590"
"627.30000","52.27525","0.02560"
"627.75000","52.31267","0.02596"
"628.20000","52.35016","0.02621"
"628.65000","52.38771","0.02654"
"629.10000","52.42526","0.02624"
"629.55000","52.46280","0.02622"
"630.00000","52.50023","0.02615"
"630.45000","52.53766","0.02627"
"630.90000","52.57521","0.02641"
"631.35000","52.61270","0.02660"
"631.80000","52.65024","0.02633"
"632.25000","52.68773","0.02611"
"632.70000","52.72528","0.02677"
"633.15000","52.76271","0.02660"
"633.60000","52.80020","0.02651"
"634.05000","52.83775","0.02706"
"634.50000","52.87524","0.02666"
"634.95000","52.91272","0.02635"
"635.40000","52.95021","0.02647"
"635.85000","52.98764","0.02665"
"636.30000","53.02524","0.02686"
"636.75000","53.06273","0.02676"
"637.20000","53.10022","0.02688"
"637.65000","53.13771","0.02708"
"638.10000","53.17520","0.02594"
"638.55000","53.21268","0.02468"
"639.00000","53.25018","0.02474"
"639.45000","53.28772","0.02499"
"639.90000","53.32526","0.02502"
"640.35000","53.36275","0.02428"
"640.80000","53.40025","0.02460"
"641.25000","53.43767","0.02493"
"641.70000","53.47516","0.02544"
"642.15000","53.51271","0.02507"
"642.60000","53.55026","0.02462"
"643.05000","53.58768","0.02426"
"643.50000","53.62523","0.02443"
"643.95000","53.66272","0.02447"
"644.40000","53.70015","0.02414"
"644.85000","53.73770","0.02424"
"645.30000","53.77524","0.02427"
"645.75000","53.81279","0.02463"
"646.20000","53.85028","0.02390"
"646.65000","53.88771","0.02297"
"647.10000","53.92520","0.02243"
"647.55000","53.96268","0.02139"
"648.00000","54.00024","0.02137"
"648.45000","54.03772","0.02111"
"648.90000","54.07527","0.02137"
"649.35000","54.11275","0.02137"
"649.80000","54.15018","0.02103"
"650.25000","54.18773","0.02034"
"650.70000","54.22522","0.02028"
"651.15000","54.26277","0.02026"
"651.60000","54.30020","0.02061"
"652.05000","54.33768","0.02104"
"652.50000","54.37518","0.02043"
"652.95000","54.41272","0.02065"
"653.40000","54.45027","0.01964"
"653.85000","54.48775","0.02077"
"654.30000","54.52525","0.02000"
"654.75000","54.56273","0.02053"
"655.20000","54.60016","0.02093"
"655.65000","54.63771","0.02033"
"656.10000","54.67526","0.02102"
"656.55000","54.71274","0.02047"
"657.00000","54.75029","0.02109"
"657.45000","54.78772","0.02108"
"657.90000","54.82515","0.02115"
"658.35000","54.86270","0.02106"
"658.80000","54.90025","0.02142"
"659.25000","54.93779","0.02066"
"659.70000","54.97528","0.02142"
"660.15000","55.01271","0.02089"
"660.60000","55.05020","0.02078"
"661.05000","55.08768","0.02054"
"661.50000","55.12517","0.02065"
"661.95000","55.16272","0.02120"
"662.40000","55.20027","0.02104"
"662.85000","55.23775","0.02116"
"663.30000","55.27524","0.02165"
"663.75000","55.31267","0.02150"
"664.20000","55.35016","0.02140"
"664.65000","55.38765","0.02222"
"665.10000","55.42526","0.02160"
"665.55000","55.46281","0.02217"
"666.00000","55.50023","0.02209"
"666.45000","55.53766","0.02196"
"666.90000","55.57527","0.01956"
"667.35000","55.61275","0.01825"
"667.80000","55.65025","0.01644"
"668.25000","55.68773","0.01686"
"668.70000","55.72522","0.01637"
"668.82200","55.73539","0.01699"