File: Force_trajectories/170212_3/Specimen_RawData_9.csv
End date,"2/12/2017"
Specimen label,"4AT_30"
Maximum Load,"0.08356",N

Time,Extension,Load
(s),(mm),(N)
"0.00000","0.00000","-0.00003"
"0.34200","0.02852","0.00011"
"0.68400","0.05722","0.00019"
"1.02600","0.08574","0.00062"
"1.36800","0.11420","0.00105"
"1.71000","0.14272","0.00043"
"2.05200","0.17118","0.00092"
"2.39400","0.19964","0.00089"
"2.73600","0.22822","0.00057"
"3.07800","0.25674","0.00035"
"3.42000","0.28514","0.00121"
"3.76200","0.31372","0.00039"
"4.10400","0.34224","0.00102"
"4.44600","0.37070","0.00124"
"4.78800","0.39921","0.00097"
"5.13000","0.42761","0.00144"
"5.47200","0.45625","0.00135"
"5.81400","0.48471","0.00115"
"6.15600","0.51311","0.00170"
"6.49800","0.54175","0.00148"
"6.84000","0.57021","0.00196"
"7.18200","0.59867","0.00134"
"7.52400","0.62725","0.00192"
"7.86600","0.65571","0.00150"
"8.20800","0.68417","0.00196"
"8.55000","0.71269","0.00177"
"8.89200","0.74121","0.00158"
"9.23400","0.76967","0.00156"
"9.57600","0.79819","0.00150"
"9.91800","0.82665","0.00138"
"10.26000","0.85517","0.00144"
"10.60200","0.88369","0.00223"
"10.94400","0.91221","0.00201"
"11.28600","0.94073","0.00133"
"11.62800","0.96925","0.00163"
"11.97000","0.99771","0.00169"
"12.31200","1.02623","0.00219"
"12.65400","1.05469","0.00213"
"12.99600","1.08321","0.00158"
"13.33800","1.11173","0.00227"
"13.68000","1.14013","0.00277"
"14.02200","1.16871","0.00244"
"14.36400","1.19723","0.00206"
"14.70600","1.22563","0.00248"
"15.04800","1.25426","0.00241"
"15.39000","1.28272","0.00234"
"15.73200","1.31118","0.00252"
"16.07400","1.33970","0.00254"
"16.41600","1.36816","0.00198"
"16.75800","1.39668","0.00229"
"17.10000","1.42526","0.00236"
"17.44200","1.45366","0.00298"
"17.78400","1.48218","0.00234"
"18.12600","1.51070","0.00258"
"18.46800","1.53916","0.00266"
"18.81000","1.56774","0.00281"
"19.15200","1.59620","0.00293"
"19.49400","1.62466","0.00207"
"19.83600","1.65324","0.00230"
"20.17800","1.68170","0.00223"
"20.52000","1.71022","0.00293"
"20.86200","1.73874","0.00273"
"21.20400","1.76714","0.00261"
"21.54600","1.79572","0.00270"
"21.88800","1.82424","0.00239"
"22.23000","1.85264","0.00258"
"22.57200","1.88122","0.00186"
"22.91400","1.90968","0.00270"
"23.25600","1.93820","0.00328"
"23.59800","1.96672","0.00251"
"23.94000","1.99518","0.00266"
"24.28200","2.02376","0.00276"
"24.62400","2.05222","0.00194"
"24.96600","2.08068","0.00281"
"25.30800","2.10926","0.00282"
"25.65000","2.13772","0.00249"
"25.99200","2.16617","0.00259"
"26.33400","2.19469","0.00262"
"26.67600","2.22315","0.00275"
"27.01800","2.25173","0.00254"
"27.36000","2.28019","0.00272"
"27.70200","2.30865","0.00287"
"28.04400","2.33711","0.00269"
"28.38600","2.36569","0.00275"
"28.72800","2.39415","0.00296"
"29.07000","2.42273","0.00250"
"29.41200","2.45125","0.00243"
"29.75400","2.47971","0.00305"
"30.09600","2.50823","0.00270"
"30.43800","2.53675","0.00271"
"30.78000","2.56521","0.00298"
"31.12200","2.59373","0.00343"
"31.46400","2.62219","0.00345"
"31.80600","2.65065","0.00319"
"32.14800","2.67923","0.00313"
"32.49000","2.70769","0.00309"
"32.83200","2.73621","0.00348"
"33.17400","2.76467","0.00284"
"33.51600","2.79325","0.00321"
"33.85800","2.82171","0.00299"
"34.20000","2.85017","0.00277"
"34.54200","2.87869","0.00255"
"34.88400","2.90727","0.00346"
"35.22600","2.93567","0.00357"
"35.56800","2.96419","0.00305"
"35.91000","2.99277","0.00240"
"36.25200","3.02117","0.00259"
"36.59400","3.04968","0.00315"
"36.93600","3.07820","0.00333"
"37.27800","3.10666","0.00341"
"37.62000","3.13530","0.00275"
"37.96200","3.16370","0.00321"
"38.30400","3.19216","0.00295"
"38.64600","3.22074","0.00355"
"38.98800","3.24914","0.00328"
"39.33000","3.27772","0.00293"
"39.67200","3.30624","0.00320"
"40.01400","3.33464","0.00299"
"40.35600","3.36322","0.00373"
"40.69800","3.39174","0.00238"
"41.04000","3.42014","0.00375"
"41.38200","3.44872","0.00380"
"41.72400","3.47718","0.00330"
"42.06600","3.50576","0.00286"
"42.40800","3.53422","0.00359"
"42.75000","3.56262","0.00300"
"43.09200","3.59120","0.00224"
"43.43400","3.61966","0.00289"
"43.77600","3.64818","0.00301"
"44.11800","3.67670","0.00321"
"44.46000","3.70522","0.00321"
"44.80200","3.73368","0.00317"
"45.14400","3.76220","0.00350"
"45.48600","3.79072","0.00334"
"45.82800","3.81918","0.00326"
"46.17000","3.84770","0.00326"
"46.51200","3.87616","0.00315"
"46.85400","3.90468","0.00323"
"47.19600","3.93319","0.00321"
"47.53800","3.96165","0.00333"
"47.88000","3.99023","0.00325"
"48.22200","4.01869","0.00357"
"48.56400","4.04721","0.00327"
"48.90600","4.07567","0.00308"
"49.24800","4.10419","0.00272"
"49.59000","4.13271","0.00338"
"49.93200","4.16117","0.00343"
"50.27400","4.18969","0.00273"
"50.61600","4.21821","0.00290"
"50.95800","4.24673","0.00284"
"51.30000","4.27513","0.00361"
"51.64200","4.30371","0.00372"
"51.98400","4.33217","0.00324"
"52.32600","4.36069","0.00339"
"52.66800","4.38921","0.00344"
"53.01000","4.41761","0.00396"
"53.35200","4.44613","0.00380"
"53.69400","4.47471","0.00361"
"54.03600","4.50317","0.00324"
"54.37800","4.53175","0.00394"
"54.72000","4.56027","0.00310"
"55.06200","4.58867","0.00268"
"55.40400","4.61725","0.00305"
"55.74600","4.64571","0.00336"
"56.08800","4.67417","0.00364"
"56.43000","4.70269","0.00271"
"56.77200","4.73115","0.00355"
"57.11400","4.75967","0.00385"
"57.45600","4.78824","0.00364"
"57.79800","4.81664","0.00396"
"58.14000","4.84528","0.00386"
"58.48200","4.87368","0.00338"
"58.82400","4.90220","0.00370"
"59.16600","4.93078","0.00347"
"59.50800","4.95918","0.00372"
"59.85000","4.98776","0.00354"
"60.19200","5.01622","0.00364"
"60.53400","5.04462","0.00381"
"60.87600","5.07320","0.00301"
"61.21800","5.10172","0.00328"
"61.56000","5.13018","0.00389"
"61.90200","5.15870","0.00387"
"62.24400","5.18722","0.00367"
"62.58600","5.21568","0.00388"
"62.92800","5.24420","0.00379"
"63.27000","5.27272","0.00366"
"63.61200","5.30118","0.00399"
"63.95400","5.32970","0.00347"
"64.29600","5.35816","0.00408"
"64.63800","5.38674","0.00337"
"64.98000","5.41526","0.00372"
"65.32200","5.44360","0.00336"
"65.66400","5.47224","0.00345"
"66.00600","5.50070","0.00385"
"66.34800","5.52922","0.00413"
"66.69000","5.55768","0.00423"
"67.03200","5.58626","0.00391"
"67.37400","5.61466","0.00381"
"67.71600","5.64324","0.00353"
"68.05800","5.67169","0.00365"
"68.40000","5.70015","0.00416"
"68.74200","5.72873","0.00395"
"69.08400","5.75719","0.00345"
"69.42600","5.78571","0.00397"
"69.76800","5.81423","0.00361"
"70.11000","5.84269","0.00351"
"70.45200","5.87121","0.00395"
"70.79400","5.89967","0.00417"
"71.13600","5.92813","0.00430"
"71.47800","5.95677","0.00375"
"71.82000","5.98517","0.00425"
"72.16200","6.01369","0.00420"
"72.50400","6.04227","0.00378"
"72.84600","6.07067","0.00395"
"73.18800","6.09925","0.00446"
"73.53000","6.12771","0.00500"
"73.87200","6.15617","0.00465"
"74.21400","6.18475","0.00415"
"74.55600","6.21315","0.00453"
"74.89800","6.24167","0.00406"
"75.24000","6.27025","0.00406"
"75.58200","6.29865","0.00441"
"75.92400","6.32729","0.00448"
"76.26600","6.35575","0.00460"
"76.60800","6.38421","0.00484"
"76.95000","6.41273","0.00514"
"77.29200","6.44125","0.00464"
"77.63400","6.46971","0.00470"
"77.97600","6.49817","0.00452"
"78.31800","6.52669","0.00474"
"78.66000","6.55520","0.00458"
"79.00200","6.58372","0.00467"
"79.34400","6.61212","0.00478"
"79.68600","6.64070","0.00509"
"80.02800","6.66922","0.00500"
"80.37000","6.69768","0.00508"
"80.71200","6.72626","0.00464"
"81.05400","6.75472","0.00514"
"81.39600","6.78318","0.00534"
"81.73800","6.81170","0.00509"
"82.08000","6.84016","0.00490"
"82.42200","6.86868","0.00555"
"82.76400","6.89720","0.00500"
"83.10600","6.92572","0.00471"
"83.44800","6.95418","0.00534"
"83.79000","6.98270","0.00542"
"84.13200","7.01116","0.00528"
"84.47400","7.03974","0.00537"
"84.81600","7.06820","0.00565"
"85.15800","7.09666","0.00551"
"85.50000","7.12518","0.00546"
"85.84200","7.15370","0.00579"
"86.18400","7.18222","0.00505"
"86.52600","7.21074","0.00569"
"86.86800","7.23920","0.00616"
"87.21000","7.26772","0.00619"
"87.55200","7.29624","0.00566"
"87.89400","7.32464","0.00546"
"88.23600","7.35322","0.00570"
"88.57800","7.38168","0.00559"
"88.92000","7.41020","0.00573"
"89.26200","7.43871","0.00550"
"89.60400","7.46717","0.00541"
"89.94600","7.49569","0.00532"
"90.28800","7.52421","0.00613"
"90.63000","7.55267","0.00625"
"90.97200","7.58125","0.00619"
"91.31400","7.60977","0.00609"
"91.65600","7.63811","0.00589"
"91.99800","7.66675","0.00566"
"92.34000","7.69515","0.00610"
"92.68200","7.72367","0.00600"
"93.02400","7.75225","0.00595"
"93.36600","7.78071","0.00654"
"93.70800","7.80923","0.00641"
"94.05000","7.83769","0.00608"
"94.39200","7.86609","0.00678"
"94.73400","7.89473","0.00633"
"95.07600","7.92325","0.00650"
"95.41800","7.95171","0.00642"
"95.76000","7.98023","0.00600"
"96.10200","8.00869","0.00601"
"96.44400","8.03721","0.00628"
"96.78600","8.06567","0.00665"
"97.12800","8.09413","0.00584"
"97.47000","8.12271","0.00669"
"97.81200","8.15129","0.00635"
"98.15400","8.17969","0.00612"
"98.49600","8.20821","0.00582"
"98.83800","8.23673","0.00660"
"99.18000","8.26519","0.00692"
"99.52200","8.29370","0.00656"
"99.86400","8.32222","0.00669"
"100.20600","8.35074","0.00654"
"100.54800","8.37920","0.00729"
"100.89000","8.40772","0.00690"
"101.23200","8.43624","0.00662"
"101.57400","8.46470","0.00725"
"101.91600","8.49316","0.00694"
"102.25800","8.52174","0.00577"
"102.60000","8.55020","0.00654"
"102.94200","8.57872","0.00546"
"103.28400","8.60718","0.00606"
"103.62600","8.63570","0.00625"
"103.96800","8.66416","0.00608"
"104.31000","8.69268","0.00700"
"104.65200","8.72120","0.00683"
"104.99400","8.74966","0.00640"
"105.33600","8.77824","0.00636"
"105.67800","8.80670","0.00632"
"106.02000","8.83516","0.00602"
"106.36200","8.86374","0.00571"
"106.70400","8.89214","0.00628"
"107.04600","8.92072","0.00672"
"107.38800","8.94924","0.00675"
"107.73000","8.97770","0.00661"
"108.07200","9.00628","0.00585"
"108.41400","9.03462","0.00622"
"108.75600","9.06326","0.00617"
"109.09800","9.09172","0.00592"
"109.44000","9.12018","0.00631"
"109.78200","9.14876","0.00635"
"110.12400","9.17727","0.00617"
"110.46600","9.20568","0.00590"
"110.80800","9.23419","0.00671"
"111.15000","9.26265","0.00650"
"111.49200","9.29117","0.00611"
"111.83400","9.31969","0.00629"
"112.17600","9.34809","0.00622"
"112.51800","9.37673","0.00605"
"112.86000","9.40531","0.00630"
"113.20200","9.43365","0.00627"
"113.54400","9.46217","0.00702"
"113.88600","9.49069","0.00617"
"114.22800","9.51915","0.00703"
"114.57000","9.54773","0.00666"
"114.91200","9.57619","0.00699"
"115.25400","9.60471","0.00637"
"115.59600","9.63317","0.00691"
"115.93800","9.66169","0.00687"
"116.28000","9.69021","0.00611"
"116.62200","9.71873","0.00651"
"116.96400","9.74713","0.00700"
"117.30600","9.77571","0.00647"
"117.64800","9.80417","0.00642"
"117.99000","9.83269","0.00661"
"118.33200","9.86127","0.00718"
"118.67400","9.88967","0.00671"
"119.01600","9.91825","0.00707"
"119.35800","9.94671","0.00718"
"119.70000","9.97522","0.00705"
"120.04200","10.00369","0.00710"
"120.38400","10.03226","0.00643"
"120.72600","10.06066","0.00678"
"121.06800","10.08913","0.00600"
"121.41000","10.11770","0.00735"
"121.75200","10.14616","0.00645"
"122.09400","10.17468","0.00681"
"122.43600","10.20314","0.00715"
"122.77800","10.23166","0.00692"
"123.12000","10.26024","0.00746"
"123.46200","10.28870","0.00695"
"123.80400","10.31716","0.00708"
"124.14600","10.34574","0.00681"
"124.48800","10.37414","0.00745"
"124.83000","10.40272","0.00764"
"125.17200","10.43124","0.00719"
"125.51400","10.45964","0.00756"
"125.85600","10.48822","0.00689"
"126.19800","10.51668","0.00802"
"126.54000","10.54520","0.00756"
"126.88200","10.57372","0.00752"
"127.22400","10.60212","0.00775"
"127.56600","10.63070","0.00821"
"127.90800","10.65922","0.00733"
"128.25000","10.68762","0.00777"
"128.59200","10.71620","0.00750"
"128.93400","10.74472","0.00774"
"129.27600","10.77318","0.00744"
"129.61800","10.80170","0.00785"
"129.96000","10.83022","0.00758"
"130.30200","10.85868","0.00827"
"130.64400","10.88720","0.00823"
"130.98600","10.91566","0.00794"
"131.32800","10.94423","0.00823"
"131.67000","10.97269","0.00844"
"132.01200","11.00115","0.00838"
"132.35400","11.02973","0.00799"
"132.69600","11.05819","0.00743"
"133.03800","11.08671","0.00786"
"133.38000","11.11523","0.00820"
"133.72200","11.14363","0.00775"
"134.06400","11.17221","0.00788"
"134.40600","11.20073","0.00809"
"134.74800","11.22919","0.00792"
"135.09000","11.25771","0.00781"
"135.43200","11.28617","0.00796"
"135.77400","11.31469","0.00792"
"136.11600","11.34327","0.00789"
"136.45800","11.37173","0.00831"
"136.80000","11.40019","0.00822"
"137.14200","11.42871","0.00726"
"137.48400","11.45717","0.00721"
"137.82600","11.48569","0.00700"
"138.16800","11.51421","0.00707"
"138.51000","11.54273","0.00708"
"138.85200","11.57125","0.00700"
"139.19400","11.59971","0.00722"
"139.53600","11.62817","0.00749"
"139.87800","11.65669","0.00770"
"140.22000","11.68521","0.00751"
"140.56200","11.71367","0.00827"
"140.90400","11.74225","0.00846"
"141.24600","11.77065","0.00866"
"141.58800","11.79922","0.00791"
"141.93000","11.82775","0.00904"
"142.27200","11.85614","0.00843"
"142.61400","11.88472","0.00871"
"142.95600","11.91324","0.00912"
"143.29800","11.94170","0.00857"
"143.64000","11.97022","0.00891"
"143.98200","11.99868","0.00937"
"144.32400","12.02714","0.00913"
"144.66600","12.05578","0.00868"
"145.00800","12.08418","0.00803"
"145.35000","12.11270","0.00824"
"145.69200","12.14122","0.00793"
"146.03400","12.16968","0.00869"
"146.37600","12.19826","0.00802"
"146.71800","12.22672","0.00834"
"147.06000","12.25518","0.00871"
"147.40200","12.28376","0.00858"
"147.74400","12.31216","0.00784"
"148.08600","12.34068","0.00788"
"148.42800","12.36926","0.00842"
"148.77000","12.39766","0.00832"
"149.11200","12.42624","0.00838"
"149.45400","12.45476","0.00763"
"149.79600","12.48310","0.00788"
"150.13800","12.51168","0.00804"
"150.48000","12.54026","0.00787"
"150.82200","12.56872","0.00831"
"151.16400","12.59724","0.00825"
"151.50600","12.62564","0.00891"
"151.84800","12.65421","0.00865"
"152.19000","12.68274","0.00902"
"152.53200","12.71114","0.00882"
"152.87400","12.73972","0.00906"
"153.21600","12.76824","0.00911"
"153.55800","12.79669","0.00885"
"153.90000","12.82527","0.00966"
"154.24200","12.85367","0.00900"
"154.58400","12.88219","0.00905"
"154.92600","12.91071","0.00994"
"155.26800","12.93917","0.00993"
"155.61000","12.96769","0.00982"
"155.95200","12.99621","0.00991"
"156.29400","13.02473","0.00976"
"156.63600","13.05319","0.01029"
"156.97800","13.08171","0.00991"
"157.32000","13.11017","0.01037"
"157.66200","13.13869","0.00996"
"158.00400","13.16721","0.01028"
"158.34600","13.19567","0.01005"
"158.68800","13.22425","0.01060"
"159.03000","13.25271","0.01077"
"159.37200","13.28117","0.01070"
"159.71400","13.30975","0.01089"
"160.05600","13.33815","0.01083"
"160.39800","13.36667","0.01178"
"160.74000","13.39525","0.01164"
"161.08200","13.42365","0.01186"
"161.42400","13.45223","0.01195"
"161.76600","13.48075","0.01206"
"162.10800","13.50921","0.01199"
"162.45000","13.53773","0.01183"
"162.79200","13.56618","0.01180"
"163.13400","13.59465","0.01180"
"163.47600","13.62328","0.01194"
"163.81800","13.65162","0.01211"
"164.16000","13.68020","0.01185"
"164.50200","13.70872","0.01122"
"164.84400","13.73718","0.01102"
"165.18600","13.76570","0.01196"
"165.52800","13.79416","0.01168"
"165.87000","13.82262","0.01143"
"166.21200","13.85120","0.01224"
"166.55400","13.87966","0.01262"
"166.89600","13.90824","0.01231"
"167.23800","13.93676","0.01273"
"167.58000","13.96510","0.01294"
"167.92200","13.99374","0.01301"
"168.26400","14.02226","0.01317"
"168.60600","14.05066","0.01304"
"168.94800","14.07924","0.01302"
"169.29000","14.10770","0.01392"
"169.63200","14.13616","0.01401"
"169.97400","14.16474","0.01431"
"170.31600","14.19320","0.01412"
"170.65800","14.22172","0.01439"
"171.00000","14.25018","0.01393"
"171.34200","14.27870","0.01123"
"171.68400","14.30722","0.01169"
"172.02600","14.33574","0.01116"
"172.36800","14.36420","0.01151"
"172.71000","14.39272","0.01245"
"173.05200","14.42118","0.01162"
"173.39400","14.44970","0.01202"
"173.73600","14.47822","0.01256"
"174.07800","14.50668","0.01289"
"174.42000","14.53513","0.01249"
"174.76200","14.56371","0.01394"
"175.10400","14.59223","0.01327"
"175.44600","14.62075","0.01367"
"175.78800","14.64927","0.01365"
"176.13000","14.67767","0.01408"
"176.47200","14.70619","0.01416"
"176.81400","14.73471","0.01438"
"177.15600","14.76317","0.01487"
"177.49800","14.79175","0.01545"
"177.84000","14.82021","0.01577"
"178.18200","14.84867","0.01531"
"178.52400","14.87725","0.01517"
"178.86600","14.90565","0.01555"
"179.20800","14.93423","0.01600"
"179.55000","14.96275","0.01635"
"179.89200","14.99115","0.01542"
"180.23400","15.01973","0.01606"
"180.57600","15.04819","0.01686"
"180.91800","15.07671","0.01725"
"181.26000","15.10523","0.01735"
"181.60200","15.13369","0.01746"
"181.94400","15.16221","0.01794"
"182.28600","15.19079","0.01799"
"182.62800","15.21913","0.01825"
"182.97000","15.24771","0.01887"
"183.31200","15.27623","0.01851"
"183.65400","15.30463","0.01862"
"183.99600","15.33327","0.01940"
"184.33800","15.36166","0.01940"
"184.68000","15.39018","0.01955"
"185.02200","15.41871","0.02029"
"185.36400","15.44716","0.02079"
"185.70600","15.47574","0.02061"
"186.04800","15.50426","0.02116"
"186.39000","15.53266","0.02120"
"186.73200","15.56124","0.02207"
"187.07400","15.58970","0.02252"
"187.41600","15.61822","0.02216"
"187.75800","15.64674","0.02258"
"188.10000","15.67514","0.02355"
"188.44200","15.70372","0.02343"
"188.78400","15.73218","0.02396"
"189.12600","15.76070","0.02350"
"189.46800","15.78922","0.02445"
"189.81000","15.81774","0.02473"
"190.15200","15.84620","0.02517"
"190.49400","15.87478","0.02550"
"190.83600","15.90318","0.02302"
"191.17800","15.93164","0.02319"
"191.52000","15.96016","0.02340"
"191.86200","15.98874","0.02451"
"192.20400","16.01720","0.02420"
"192.54600","16.04572","0.02416"
"192.88800","16.07418","0.02434"
"193.23000","16.10264","0.02455"
"193.57200","16.13121","0.02315"
"193.91400","16.15962","0.02362"
"194.25600","16.18826","0.02355"
"194.59800","16.21671","0.02427"
"194.94000","16.24517","0.02510"
"195.28200","16.27369","0.02529"
"195.62400","16.30221","0.02540"
"195.96600","16.33068","0.02454"
"196.30800","16.35925","0.02567"
"196.65000","16.38765","0.02535"
"196.99200","16.41617","0.02494"
"197.33400","16.44475","0.02520"
"197.67600","16.47315","0.02573"
"198.01800","16.50173","0.02626"
"198.36000","16.53019","0.02610"
"198.70200","16.55871","0.02619"
"199.04400","16.58723","0.02624"
"199.38600","16.61569","0.02721"
"199.72800","16.64415","0.02754"
"200.07000","16.67273","0.02779"
"200.41200","16.70113","0.02828"
"200.75400","16.72971","0.02896"
"201.09600","16.75823","0.02926"
"201.43800","16.78663","0.02653"
"201.78000","16.81527","0.02398"
"202.12200","16.84373","0.02440"
"202.46400","16.87219","0.02583"
"202.80600","16.90071","0.02589"
"203.14800","16.92911","0.02628"
"203.49000","16.95769","0.02697"
"203.83200","16.98627","0.02742"
"204.17400","17.01467","0.02678"
"204.51600","17.04325","0.02734"
"204.85800","17.07170","0.02734"
"205.20000","17.10016","0.02826"
"205.54200","17.12875","0.02864"
"205.88400","17.15720","0.02845"
"206.22600","17.18566","0.02918"
"206.56800","17.21424","0.02925"
"206.91000","17.24264","0.02961"
"207.25200","17.27122","0.03008"
"207.59400","17.29974","0.02944"
"207.93600","17.32820","0.03035"
"208.27800","17.35666","0.03094"
"208.62000","17.38518","0.03048"
"208.96200","17.41370","0.03112"
"209.30400","17.44216","0.03142"
"209.64600","17.47074","0.03210"
"209.98800","17.49920","0.03244"
"210.33000","17.52772","0.03310"
"210.67200","17.55624","0.03356"
"211.01400","17.58470","0.03374"
"211.35600","17.61322","0.03463"
"211.69800","17.64168","0.03505"
"212.04000","17.67020","0.03515"
"212.38200","17.69872","0.03628"
"212.72400","17.72712","0.03713"
"213.06600","17.75570","0.03734"
"213.40800","17.78416","0.03741"
"213.75000","17.81268","0.03466"
"214.09200","17.84120","0.02230"
"214.43400","17.86972","0.02174"
"214.77600","17.89818","0.02312"
"215.11800","17.92676","0.02261"
"215.46000","17.95516","0.02322"
"215.80200","17.98368","0.02400"
"216.14400","18.01225","0.02415"
"216.48600","18.04066","0.02464"
"216.82800","18.06917","0.02528"
"217.17000","18.09763","0.02589"
"217.51200","18.12615","0.02578"
"217.85400","18.15473","0.02671"
"218.19600","18.18319","0.02686"
"218.53800","18.21171","0.02653"
"218.88000","18.24023","0.02252"
"219.22200","18.26863","0.02277"
"219.56400","18.29727","0.02338"
"219.90600","18.32573","0.02366"
"220.24800","18.35413","0.02436"
"220.59000","18.38277","0.02405"
"220.93200","18.41117","0.02499"
"221.27400","18.43969","0.02578"
"221.61600","18.46827","0.02631"
"221.95800","18.49661","0.02497"
"222.30000","18.52525","0.02606"
"222.64200","18.55371","0.02609"
"222.98400","18.58217","0.02577"
"223.32600","18.61075","0.02688"
"223.66800","18.63921","0.02682"
"224.01000","18.66773","0.02676"
"224.35200","18.69619","0.02715"
"224.69400","18.72465","0.02772"
"225.03600","18.75323","0.02765"
"225.37800","18.78169","0.02834"
"225.72000","18.81015","0.02890"
"226.06200","18.83873","0.02860"
"226.40400","18.86719","0.02874"
"226.74600","18.89559","0.02927"
"227.08800","18.92422","0.02894"
"227.43000","18.95274","0.02948"
"227.77200","18.98120","0.02992"
"228.11400","19.00972","0.02982"
"228.45600","19.03824","0.03032"
"228.79800","19.06670","0.03064"
"229.14000","19.09522","0.03025"
"229.48200","19.12368","0.03068"
"229.82400","19.15220","0.03107"
"230.16600","19.18072","0.03129"
"230.50800","19.20918","0.03148"
"230.85000","19.23776","0.03155"
"231.19200","19.26622","0.03210"
"231.53400","19.29468","0.03229"
"231.87600","19.32320","0.03234"
"232.21800","19.35166","0.03166"
"232.56000","19.38018","0.03186"
"232.90200","19.40876","0.03222"
"233.24400","19.43716","0.03259"
"233.58600","19.46574","0.03300"
"233.92800","19.49426","0.03339"
"234.27000","19.52266","0.03299"
"234.61200","19.55118","0.03372"
"234.95400","19.57970","0.03298"
"235.29600","19.60816","0.03337"
"235.63800","19.63680","0.03406"
"235.98000","19.66520","0.03440"
"236.32200","19.69366","0.03473"
"236.66400","19.72223","0.03450"
"237.00600","19.75058","0.03468"
"237.34800","19.77927","0.03512"
"237.69000","19.80773","0.03494"
"238.03200","19.83619","0.03522"
"238.37400","19.86471","0.03538"
"238.71600","19.89323","0.03600"
"239.05800","19.92169","0.03649"
"239.40000","19.95021","0.03711"
"239.74200","19.97867","0.03690"
"240.08400","20.00725","0.03776"
"240.42600","20.03571","0.03805"
"240.76800","20.06411","0.03758"
"241.11000","20.09275","0.03825"
"241.45200","20.12121","0.03861"
"241.79400","20.14973","0.03879"
"242.13600","20.17819","0.03722"
"242.47800","20.20671","0.03675"
"242.82000","20.23517","0.03747"
"243.16200","20.26369","0.03771"
"243.50400","20.29221","0.03860"
"243.84600","20.32073","0.03851"
"244.18800","20.34919","0.03907"
"244.53000","20.37771","0.03953"
"244.87200","20.40623","0.03792"
"245.21400","20.43469","0.03888"
"245.55600","20.46315","0.03981"
"245.89800","20.49172","0.04025"
"246.24000","20.52024","0.04081"
"246.58200","20.54870","0.04133"
"246.92400","20.57716","0.04131"
"247.26600","20.60568","0.04166"
"247.60800","20.63421","0.04201"
"247.95000","20.66273","0.04150"
"248.29200","20.69118","0.04228"
"248.63400","20.71970","0.04317"
"248.97600","20.74822","0.04399"
"249.31800","20.77662","0.04461"
"249.66000","20.80520","0.04492"
"250.00200","20.83366","0.04410"
"250.34400","20.86218","0.04403"
"250.68600","20.89076","0.04331"
"251.02800","20.91916","0.04273"
"251.37000","20.94768","0.04306"
"251.71200","20.97626","0.04385"
"252.05400","21.00466","0.04372"
"252.39600","21.03318","0.04519"
"252.73800","21.06176","0.04508"
"253.08000","21.09016","0.04605"
"253.42200","21.11874","0.04696"
"253.76400","21.14720","0.04898"
"254.10600","21.17566","0.04970"
"254.44800","21.20430","0.05002"
"254.79000","21.23270","0.05097"
"255.13200","21.26122","0.05155"
"255.47400","21.28974","0.05250"
"255.81600","21.31814","0.05359"
"256.15800","21.34678","0.05449"
"256.50000","21.37518","0.05512"
"256.84200","21.40369","0.05483"
"257.18400","21.43228","0.05535"
"257.52600","21.46067","0.05559"
"257.86800","21.48919","0.05677"
"258.21000","21.51771","0.05773"
"258.55200","21.54611","0.05838"
"258.89400","21.57470","0.05930"
"259.23600","21.60328","0.06010"
"259.57800","21.63167","0.06181"
"259.92000","21.66019","0.06305"
"260.26200","21.68865","0.06423"
"260.60400","21.71717","0.06489"
"260.94600","21.74569","0.06490"
"261.28800","21.77421","0.05279"
"261.63000","21.80273","0.05426"
"261.97200","21.83119","0.05505"
"262.31400","21.85965","0.05650"
"262.65600","21.88823","0.05835"
"262.99800","21.91675","0.05915"
"263.34000","21.94515","0.06064"
"263.68200","21.97367","0.05992"
"264.02400","22.00219","0.06180"
"264.36600","22.03065","0.06234"
"264.70800","22.05923","0.06335"
"265.05000","22.08775","0.06576"
"265.39200","22.11615","0.06637"
"265.73400","22.14473","0.06781"
"266.07600","22.17325","0.06861"
"266.41800","22.20171","0.06896"
"266.76000","22.23022","0.06929"
"267.10200","22.25863","0.07030"
"267.44400","22.28715","0.07110"
"267.78600","22.31573","0.07108"
"268.12800","22.34419","0.07144"
"268.47000","22.37271","0.07172"
"268.81200","22.40122","0.07246"
"269.15400","22.42969","0.07307"
"269.49600","22.45820","0.07407"
"269.83800","22.48666","0.07448"
"270.18000","22.51518","0.07472"
"270.52200","22.54376","0.07567"
"270.86400","22.57216","0.07644"
"271.20600","22.60074","0.07733"
"271.54800","22.62926","0.07742"
"271.89000","22.65772","0.07773"
"272.23200","22.68624","0.07851"
"272.57400","22.71464","0.07903"
"272.91600","22.74316","0.07982"
"273.25800","22.77174","0.07968"
"273.60000","22.80014","0.07698"
"273.94200","22.82872","0.07826"
"274.28400","22.85724","0.07888"
"274.62600","22.88570","0.07944"
"274.96800","22.91428","0.07962"
"275.31000","22.94268","0.08044"
"275.65200","22.97120","0.08089"
"275.99400","22.99972","0.08121"
"276.33600","23.02824","0.08181"
"276.67800","23.05676","0.08182"
"277.02000","23.08522","0.08146"
"277.36200","23.11362","0.08192"
"277.70400","23.14220","0.08241"
"278.04600","23.17072","0.08315"
"278.38800","23.19912","0.08280"
"278.73000","23.22775","-0.00351"
"279.07200","23.25622","0.00075"
"279.41400","23.28468","-0.00181"
"279.75600","23.31319","0.00071"
"280.09800","23.34171","0.00076"
"280.44000","23.37023","0.00148"
"280.78200","23.39869","0.00077"
"281.12400","23.42715","-0.00034"
"281.46600","23.45567","0.00064"
"281.80800","23.48419","-0.00025"
"282.15000","23.51265","0.00016"
"282.49200","23.54123","0.00053"
"282.83400","23.56969","0.00103"
"283.17600","23.59821","0.00023"
"283.51800","23.62667","0.00034"
"283.86000","23.65519","0.00001"
"284.20200","23.68365","0.00153"
"284.54400","23.71223","0.00015"
"284.88600","23.74069","0.00000"
"285.22800","23.76921","0.00005"
"285.57000","23.79773","0.00006"
"285.91200","23.82613","0.00013"
"286.25400","23.85471","0.00063"
"286.59600","23.88323","0.00006"
"286.93800","23.91169","0.00043"
"287.28000","23.94015","0.00022"
"287.62200","23.96867","0.00055"
"287.96400","23.99719","0.00063"
"288.30600","24.02577","-0.00003"
"288.64800","24.05411","0.00013"
"288.99000","24.08274","0.00028"
"289.33200","24.11126","0.00084"
"289.67400","24.13967","0.00083"
"290.01600","24.16825","0.00065"
"290.35800","24.19670","-0.00009"
"290.70000","24.22516","0.00056"
"291.04200","24.25374","0.00037"
"291.38400","24.28220","0.00020"
"291.72600","24.31072","0.00053"
"292.06800","24.33918","0.00024"
"292.41000","24.36758","0.00038"
"292.75200","24.39622","0.00036"
"293.09400","24.42474","0.00052"
"293.43600","24.45320","0.00048"
"293.77800","24.48172","-0.00011"
"294.12000","24.51012","0.00029"
"294.46200","24.53870","0.00064"
"294.80400","24.56722","-0.00019"
"295.14600","24.59568","0.00022"
"295.48800","24.62420","0.00004"
"295.83000","24.65272","0.00032"
"296.17200","24.68112","0.00022"
"296.51400","24.70970","-0.00005"
"296.85600","24.73822","0.00063"
"297.19800","24.76668","-0.00014"
"297.54000","24.79526","0.00033"
"297.88200","24.82366","0.00032"
"298.22400","24.85224","0.00074"
"298.56600","24.88070","-0.00014"
"298.90800","24.90915","0.00069"
"299.25000","24.93767","0.00003"
"299.59200","24.96620","0.00007"
"299.93400","24.99471","-0.00009"
"300.27600","25.02324","0.00027"
"300.61800","25.05176","0.00058"
"300.96000","25.08015","-0.00024"
"301.30200","25.10867","-0.00031"
"301.64400","25.13720","0.00039"
"301.98600","25.16566","0.00023"
"302.32800","25.19417","0.00061"
"302.67000","25.22269","0.00025"
"303.01200","25.25121","0.00030"
"303.35400","25.27967","0.00030"
"303.69600","25.30819","-0.00008"
"304.03800","25.33671","0.00044"
"304.38000","25.36523","-0.00012"
"304.72200","25.39369","0.00075"
"305.06400","25.42221","0.00008"
"305.40600","25.45067","0.00004"
"305.74800","25.47919","0.00025"
"306.09000","25.50777","0.00030"
"306.43200","25.53611","0.00034"
"306.77400","25.56469","0.00027"
"307.11600","25.59327","0.00007"
"307.45800","25.62161","0.00010"
"307.80000","25.65025","0.00086"
"308.14200","25.67871","0.00025"
"308.48400","25.70717","0.00040"
"308.82600","25.73575","0.00037"
"309.16800","25.76415","0.00014"
"309.51000","25.79267","0.00036"
"309.85200","25.82119","0.00022"
"310.19400","25.84965","-0.00016"
"310.53600","25.87823","-0.00004"
"310.87800","25.90675","0.00041"
"311.22000","25.93514","-0.00044"
"311.56200","25.96373","0.00017"
"311.90400","25.99224","-0.00041"
"312.24600","26.02071","0.00062"
"312.58800","26.04922","0.00017"
"312.93000","26.07768","0.00021"
"313.27200","26.10620","0.00005"
"313.61400","26.13472","0.00080"
"313.95600","26.16312","0.00028"
"314.29800","26.19176","0.00040"
"314.64000","26.22028","0.00033"
"314.98200","26.24868","0.00045"
"315.32400","26.27720","-0.00006"
"315.66600","26.30572","0.00008"
"316.00800","26.33412","-0.00002"
"316.35000","26.36270","0.00044"
"316.69200","26.39122","0.00069"
"317.03400","26.41974","0.00012"
"317.37600","26.44820","-0.00007"
"317.71800","26.47666","0.00018"
"318.06000","26.50518","0.00006"
"318.40200","26.53376","0.00004"
"318.74400","26.56222","0.00053"
"319.08600","26.59068","-0.00002"
"319.42800","26.61920","0.00048"
"319.77000","26.64766","0.00048"
"320.11200","26.67624","0.00015"
"320.45400","26.70470","-0.00001"
"320.79600","26.73316","0.00037"
"321.13800","26.76174","0.00022"
"321.48000","26.79014","0.00043"
"321.82200","26.81871","0.00033"
"322.16400","26.84729","-0.00036"
"322.50600","26.87563","0.00052"
"322.84800","26.90421","-0.00014"
"323.19000","26.93273","-0.00018"
"323.53200","26.96119","0.00047"
"323.87400","26.98971","0.00063"
"324.21600","27.01817","-0.00036"
"324.55800","27.04663","0.00002"
"324.90000","27.07521","0.00089"
"325.24200","27.10361","0.00005"
"325.58400","27.13225","0.00012"
"325.92600","27.16071","0.00040"
"326.26800","27.18917","0.00125"
"326.61000","27.21769","0.00052"
"326.95200","27.24621","0.00018"
"327.29400","27.27467","-0.00007"
"327.63600","27.30319","0.00106"
"327.97800","27.33171","-0.00008"
"328.32000","27.36023","0.00092"
"328.66200","27.38869","0.00056"
"329.00400","27.41715","0.00009"
"329.34600","27.44573","0.00011"
"329.68800","27.47419","0.00071"
"330.03000","27.50265","0.00098"
"330.37200","27.53117","0.00051"
"330.71400","27.55969","-0.00022"
"331.05600","27.58815","0.00010"
"331.39800","27.61672","0.00082"
"331.74000","27.64519","0.00003"
"332.08200","27.67371","-0.00017"
"332.42400","27.70222","0.00060"
"332.76600","27.73069","0.00053"
"333.10800","27.75920","0.00031"
"333.45000","27.78766","0.00058"
"333.79200","27.81618","0.00187"
"334.13400","27.84470","0.00032"
"334.47600","27.87322","-0.00058"
"334.81800","27.90174","0.00127"
"335.16000","27.93020","0.00039"
"335.50200","27.95866","0.00007"
"335.84400","27.98718","0.00097"
"336.18600","28.01570","0.00196"
"336.52800","28.04422","0.00016"
"336.87000","28.07274","0.00056"
"337.21200","28.10120","0.00165"
"337.55400","28.12972","0.00022"
"337.89600","28.15824","0.00029"
"338.23800","28.18670","0.00136"
"338.58000","28.21516","0.00236"
"338.92200","28.24374","0.00055"
"339.26400","28.27220","0.00046"
"339.60600","28.30066","0.00142"
"339.94800","28.32930","0.00122"
"340.29000","28.35764","0.00069"
"340.63200","28.38622","0.00093"
"340.97400","28.41474","0.00194"
"341.31600","28.44320","0.00026"
"341.65800","28.47172","0.00055"
"342.00000","28.50024","0.00254"
"342.34200","28.52869","0.00086"
"342.68400","28.55722","0.00017"
"343.02600","28.58568","0.00222"
"343.36800","28.61419","0.00083"
"343.71000","28.64266","0.00009"
"344.05200","28.67118","0.00199"
"344.39400","28.69969","0.00169"
"344.73600","28.72821","0.00093"
"345.07800","28.75667","0.00115"
"345.42000","28.78525","0.00205"
"345.76200","28.81371","0.00059"
"346.10400","28.84217","0.00125"
"346.44600","28.87069","0.00250"
"346.78800","28.89915","0.00081"
"347.13000","28.92773","0.00091"
"347.47200","28.95625","0.00239"
"347.81400","28.98465","0.00103"
"348.15600","29.01323","0.00078"
"348.49800","29.04175","0.00293"
"348.84000","29.07021","0.00109"
"349.18200","29.09873","0.00093"
"349.52400","29.12713","0.00298"
"349.86600","29.15571","0.00124"
"350.20800","29.18423","0.00159"
"350.55000","29.21263","0.00270"
"350.89200","29.24127","0.00202"
"351.23400","29.26973","0.00189"
"351.57600","29.29819","0.00227"
"351.91800","29.32677","0.00221"
"352.26000","29.35523","0.00184"
"352.60200","29.38369","0.00267"
"352.94400","29.41221","0.00168"
"353.28600","29.44067","0.00260"
"353.62800","29.46919","0.00318"
"353.97000","29.49771","0.00242"
"354.31200","29.52617","0.00331"
"354.65400","29.55468","0.00230"
"354.99600","29.58320","0.00204"
"355.33800","29.61172","0.00235"
"355.68000","29.64024","0.00283"
"356.02200","29.66870","0.00158"
"356.36400","29.69716","0.00212"
"356.70600","29.72568","0.00340"
"357.04800","29.75420","0.00234"
"357.39000","29.78266","0.00309"
"357.73200","29.81130","0.00257"
"358.07400","29.83964","0.00262"
"358.41600","29.86816","0.00295"
"358.75800","29.89674","0.00283"
"359.10000","29.92514","0.00283"
"359.44200","29.95378","0.00196"
"359.78400","29.98218","0.00263"
"360.12600","30.01070","0.00261"
"360.46800","30.03928","0.00288"
"360.81000","30.06768","0.00291"
"361.15200","30.09620","0.00298"
"361.49400","30.12478","0.00264"
"361.83600","30.15318","0.00322"
"362.17800","30.18170","0.00268"
"362.52000","30.21022","0.00291"
"362.86200","30.23868","0.00299"
"363.20400","30.26720","0.00287"
"363.54600","30.29572","0.00295"
"363.88800","30.32418","0.00329"
"364.23000","30.35275","0.00339"
"364.57200","30.38116","0.00384"
"364.91400","30.40973","0.00353"
"365.25600","30.43819","0.00349"
"365.59800","30.46665","0.00344"
"365.94000","30.49523","0.00316"
"366.28200","30.52375","0.00356"
"366.62400","30.55221","0.00404"
"366.96600","30.58073","0.00343"
"367.30800","30.60919","0.00328"
"367.65000","30.63771","0.00351"
"367.99200","30.66623","0.00300"
"368.33400","30.69469","0.00310"
"368.67600","30.72321","0.00261"
"369.01800","30.75173","0.00320"
"369.36000","30.78019","0.00364"
"369.70200","30.80871","0.00319"
"370.04400","30.83717","0.00290"
"370.38600","30.86569","0.00281"
"370.72800","30.89421","0.00271"
"371.07000","30.92273","0.00310"
"371.41200","30.95119","0.00325"
"371.75400","30.97971","0.00315"
"372.09600","31.00817","0.00277"
"372.43800","31.03669","0.00281"
"372.78000","31.06521","0.00299"
"373.12200","31.09367","0.00313"
"373.46400","31.12225","0.00312"
"373.80600","31.15077","0.00253"
"374.14800","31.17911","0.00340"
"374.49000","31.20774","0.00377"
"374.83200","31.23621","0.00307"
"375.17400","31.26472","0.00340"
"375.51600","31.29324","0.00347"
"375.85800","31.32170","0.00346"
"376.20000","31.35022","0.00314"
"376.54200","31.37874","0.00386"
"376.88400","31.40720","0.00315"
"377.22600","31.43572","0.00319"
"377.56800","31.46424","0.00329"
"377.91000","31.49270","0.00384"
"378.25200","31.52122","0.00401"
"378.59400","31.54968","0.00383"
"378.93600","31.57820","0.00312"
"379.27800","31.60672","0.00324"
"379.62000","31.63518","0.00331"
"379.96200","31.66370","0.00316"
"380.30400","31.69222","0.00303"
"380.64600","31.72068","0.00290"
"380.98800","31.74926","0.00332"
"381.33000","31.77772","0.00323"
"381.67200","31.80612","0.00363"
"382.01400","31.83475","0.00332"
"382.35600","31.86322","0.00347"
"382.69800","31.89168","0.00325"
"383.04000","31.92019","0.00306"
"383.38200","31.94860","0.00348"
"383.72400","31.97724","0.00397"
"384.06600","32.00575","0.00339"
"384.40800","32.03416","0.00315"
"384.75000","32.06274","0.00370"
"385.09200","32.09119","0.00364"
"385.43400","32.11971","0.00413"
"385.77600","32.14824","0.00357"
"386.11800","32.17669","0.00428"
"386.46000","32.20521","0.00360"
"386.80200","32.23367","0.00380"
"387.14400","32.26213","0.00377"
"387.48600","32.29071","0.00374"
"387.82800","32.31923","0.00408"
"388.17000","32.34763","0.00354"
"388.51200","32.37621","0.00371"
"388.85400","32.40473","0.00394"
"389.19600","32.43319","0.00371"
"389.53800","32.46171","0.00363"
"389.88000","32.49017","0.00299"
"390.22200","32.51869","0.00372"
"390.56400","32.54721","0.00439"
"390.90600","32.57567","0.00345"
"391.24800","32.60419","0.00407"
"391.59000","32.63271","0.00364"
"391.93200","32.66117","0.00359"
"392.27400","32.68975","0.00371"
"392.61600","32.71821","0.00394"
"392.95800","32.74667","0.00277"
"393.30000","32.77525","0.00360"
"393.64200","32.80371","0.00302"
"393.98400","32.83216","0.00323"
"394.32600","32.86074","0.00330"
"394.66800","32.88921","0.00367"
"395.01000","32.91772","0.00299"
"395.35200","32.94624","0.00290"
"395.69400","32.97470","0.00315"
"396.03600","33.00322","0.00381"
"396.37800","33.03168","0.00322"
"396.72000","33.06020","0.00293"
"397.06200","33.08878","0.00333"
"397.40400","33.11718","0.00260"
"397.74600","33.14558","0.00331"
"398.08800","33.17428","0.00261"
"398.43000","33.20262","0.00344"
"398.77200","33.23120","0.00320"
"399.11400","33.25972","0.00376"
"399.45600","33.28818","0.00322"
"399.79800","33.31670","0.00309"
"400.14000","33.34522","0.00320"
"400.48200","33.37368","0.00233"
"400.82400","33.40226","0.00325"
"401.16600","33.43066","0.00228"
"401.50800","33.45924","0.00290"
"401.85000","33.48770","0.00210"
"402.19200","33.51616","0.00266"
"402.53400","33.54474","0.00273"
"402.87600","33.57320","0.00299"
"403.21800","33.60166","0.00299"
"403.56000","33.63024","0.00310"
"403.90200","33.65870","0.00278"
"404.24400","33.68721","0.00289"
"404.58600","33.71574","0.00280"
"404.92800","33.74420","0.00292"
"405.27000","33.77271","0.00352"
"405.61200","33.80117","0.00277"
"405.95400","33.82970","0.00277"
"406.29600","33.85822","0.00347"
"406.63800","33.88673","0.00373"
"406.98000","33.91519","0.00278"
"407.32200","33.94371","0.00295"
"407.66400","33.97223","0.00298"
"408.00600","34.00069","0.00320"
"408.34800","34.02921","0.00342"
"408.69000","34.05767","0.00348"
"409.03200","34.08619","0.00310"
"409.37400","34.11477","0.00345"
"409.71600","34.14317","0.00326"
"410.05800","34.17169","0.00329"
"410.40000","34.20021","0.00262"
"410.74200","34.22867","0.00296"
"411.08400","34.25725","0.00305"
"411.42600","34.28571","0.00263"
"411.76800","34.31417","0.00259"
"412.11000","34.34275","0.00299"
"412.45200","34.37115","0.00338"
"412.79400","34.39973","0.00341"
"413.13600","34.42825","0.00300"
"413.47800","34.45665","0.00277"
"413.82000","34.48517","0.00223"
"414.16200","34.51374","0.00248"
"414.50400","34.54221","0.00198"
"414.84600","34.57073","0.00261"
"415.18800","34.59919","0.00294"
"415.53000","34.62765","0.00318"
"415.87200","34.65623","0.00255"
"416.21400","34.68468","0.00255"
"416.55600","34.71320","0.00305"
"416.89800","34.74173","0.00261"
"417.24000","34.77012","0.00274"
"417.58200","34.79876","0.00253"
"417.92400","34.82722","0.00322"
"418.26600","34.85562","0.00284"
"418.60800","34.88426","0.00252"
"418.95000","34.91267","0.00261"
"419.29200","34.94118","0.00324"
"419.63400","34.96970","0.00255"
"419.97600","34.99816","0.00308"
"420.31800","35.02668","0.00243"
"420.66000","35.05526","0.00234"
"421.00200","35.08366","0.00236"
"421.34400","35.11224","0.00203"
"421.68600","35.14070","0.00303"
"422.02800","35.16922","0.00194"
"422.37000","35.19768","0.00202"
"422.71200","35.22614","0.00223"
"423.05400","35.25471","0.00265"
"423.39600","35.28318","0.00215"
"423.73800","35.31164","0.00189"
"424.08000","35.34016","0.00223"
"424.42200","35.36874","0.00233"
"424.76400","35.39714","0.00171"
"425.10600","35.42572","0.00235"
"425.44800","35.45424","0.00190"
"425.79000","35.48264","0.00238"
"426.13200","35.51122","0.00260"
"426.47400","35.53968","0.00262"
"426.81600","35.56820","0.00262"
"427.15800","35.59671","0.00257"
"427.50000","35.62518","0.00260"
"427.84200","35.65376","0.00203"
"428.18400","35.68221","0.00220"
"428.52600","35.71067","0.00211"
"428.86800","35.73919","0.00231"
"429.21000","35.76771","0.00241"
"429.55200","35.79617","0.00225"
"429.89400","35.82470","0.00235"
"430.23600","35.85321","0.00203"
"430.57800","35.88167","0.00231"
"430.92000","35.91025","0.00302"
"431.26200","35.93865","0.00266"
"431.60400","35.96717","0.00289"
"431.94600","35.99575","0.00264"
"432.28800","36.02421","0.00294"
"432.63000","36.05273","0.00281"
"432.97200","36.08125","0.00243"
"433.31400","36.10971","0.00253"
"433.65600","36.13823","0.00248"
"433.99800","36.16669","0.00251"
"434.34000","36.19515","0.00262"
"434.68200","36.22379","0.00276"
"435.02400","36.25212","0.00265"
"435.36600","36.28071","0.00240"
"435.70800","36.30929","0.00287"
"436.05000","36.33762","0.00302"
"436.39200","36.36621","0.00156"
"436.73400","36.39467","0.00066"
"437.07600","36.42318","0.00106"
"437.41800","36.45171","0.00064"
"437.76000","36.48017","0.00176"
"438.10200","36.50874","0.00124"
"438.44400","36.53720","0.00029"
"438.78600","36.56561","0.00185"
"439.12800","36.59424","0.00112"
"439.47000","36.62270","0.00127"
"439.81200","36.65117","0.00129"
"440.15400","36.67974","0.00121"
"440.49600","36.70814","0.00108"
"440.83800","36.73666","0.00093"
"441.18000","36.76524","0.00116"
"441.52200","36.79370","0.00126"
"441.86400","36.82222","0.00086"
"442.20600","36.85068","0.00086"
"442.54800","36.87920","0.00067"
"442.89000","36.90772","0.00090"
"443.23200","36.93624","0.00144"
"443.57400","36.96464","0.00152"
"443.91600","36.99322","0.00074"
"444.25800","37.02174","0.00125"
"444.60000","37.05020","0.00147"
"444.94200","37.07872","0.00138"
"445.28400","37.10718","0.00082"
"445.62600","37.13570","0.00109"
"445.96800","37.16422","0.00154"
"446.31000","37.19268","0.00102"
"446.65200","37.22120","0.00130"
"446.99400","37.24972","0.00142"
"447.33600","37.27818","0.00107"
"447.67800","37.30670","0.00129"
"448.02000","37.33522","0.00136"
"448.36200","37.36367","0.00083"
"448.70400","37.39220","0.00093"
"449.04600","37.42065","0.00117"
"449.38800","37.44917","0.00102"
"449.73000","37.47775","0.00067"
"450.07200","37.50615","0.00146"
"450.41400","37.53473","0.00112"
"450.75600","37.56325","0.00117"
"451.09800","37.59165","0.00108"
"451.44000","37.62017","0.00098"
"451.78200","37.64869","0.00124"
"452.12400","37.67715","0.00115"
"452.46600","37.70573","0.00140"
"452.80800","37.73419","0.00121"
"453.15000","37.76271","0.00141"
"453.49200","37.79123","0.00147"
"453.83400","37.81963","0.00142"
"454.17600","37.84827","0.00082"
"454.51800","37.87673","0.00209"
"454.86000","37.90519","0.00171"
"455.20200","37.93371","0.00168"
"455.54400","37.96217","0.00135"
"455.88600","37.99069","0.00164"
"456.22800","38.01921","0.00175"
"456.57000","38.04767","0.00158"
"456.91200","38.07619","0.00117"
"457.25400","38.10477","0.00091"
"457.59600","38.13317","0.00114"
"457.93800","38.16169","0.00154"
"458.28000","38.19020","0.00080"
"458.62200","38.21873","0.00124"
"458.96400","38.24725","0.00049"
"459.30600","38.27570","0.00033"
"459.64800","38.30423","0.00054"
"459.99000","38.33269","0.00106"
"460.33200","38.36115","0.00065"
"460.67400","38.38972","0.00048"
"461.01600","38.41824","0.00058"
"461.35800","38.44664","0.00072"
"461.70000","38.47522","0.00083"
"462.04200","38.50368","0.00041"
"462.38400","38.53214","0.00120"
"462.72600","38.56072","0.00011"
"463.06800","38.58918","0.00039"
"463.41000","38.61770","0.00082"
"463.75200","38.64616","0.00067"
"464.09400","38.67468","0.00095"
"464.43600","38.70326","0.00081"
"464.77800","38.73172","0.00068"
"465.12000","38.76018","-0.00022"
"465.46200","38.78870","0.00081"
"465.80400","38.81716","0.00047"
"466.14600","38.84568","0.00039"
"466.48800","38.87420","0.00077"
"466.83000","38.90266","0.00078"
"467.17200","38.93112","0.00089"
"467.51400","38.95975","0.00084"
"467.85600","38.98816","0.00046"
"468.19800","39.01674","0.00119"
"468.54000","39.04525","0.00099"
"468.88200","39.07366","0.00138"
"469.22400","39.10223","0.00100"
"469.56600","39.13070","0.00054"
"469.90800","39.15916","0.00089"
"470.25000","39.18773","0.00055"
"470.59200","39.21619","-0.00013"
"470.93400","39.24471","0.00021"
"471.27600","39.27323","-0.00003"
"471.61800","39.30169","0.00076"
"471.96000","39.33022","0.00001"
"472.30200","39.35873","0.00039"
"472.64400","39.38719","0.00025"
"472.98600","39.41571","0.00090"
"473.32800","39.44423","0.00045"
"473.67000","39.47269","0.00108"
"474.01200","39.50121","0.00055"
"474.35400","39.52967","-0.00002"
"474.69600","39.55819","0.00023"
"475.03800","39.58671","0.00043"
"475.38000","39.61511","0.00050"
"475.72200","39.64368","0.00049"
"476.06400","39.67221","0.00008"
"476.40600","39.70066","0.00034"
"476.74800","39.72919","0.00065"
"477.09000","39.75771","0.00057"
"477.43200","39.78617","0.00047"
"477.77400","39.81475","0.00082"
"478.11600","39.84314","0.00000"
"478.45800","39.87173","0.00092"
"478.80000","39.90025","0.00034"
"479.14200","39.92870","0.00016"
"479.48400","39.95723","-0.00003"
"479.82600","39.98563","0.00043"
"480.16800","40.01420","0.00071"
"480.51000","40.04272","0.00051"
"480.85200","40.07118","0.00041"
"481.19400","40.09964","0.00030"
"481.53600","40.12822","0.00019"
"481.87800","40.15675","0.00023"
"482.22000","40.18520","-0.00009"
"482.56200","40.21372","0.00006"
"482.90400","40.24218","0.00057"
"483.24600","40.27070","0.00014"
"483.58800","40.29922","0.00021"
"483.93000","40.32763","0.00038"
"484.27200","40.35620","0.00039"
"484.61400","40.38472","0.00002"
"484.95600","40.41318","0.00060"
"485.29800","40.44170","0.00052"
"485.64000","40.47016","0.00031"
"485.98200","40.49868","0.00043"
"486.32400","40.52726","0.00028"
"486.66600","40.55560","0.00002"
"487.00800","40.58424","0.00046"
"487.35000","40.61276","0.00037"
"487.69200","40.64116","0.00030"
"488.03400","40.66974","0.00046"
"488.37600","40.69820","0.00028"
"488.71800","40.72672","0.00036"
"489.06000","40.75524","0.00023"
"489.40200","40.78370","-0.00011"
"489.74400","40.81222","0.00068"
"490.08600","40.84073","-0.00008"
"490.42800","40.86914","0.00095"
"490.77000","40.89777","0.00016"
"491.11200","40.92623","0.00023"
"491.45400","40.95469","-0.00046"
"491.79600","40.98328","0.00070"
"492.13800","41.01173","0.00063"
"492.48000","41.04019","0.00058"
"492.82200","41.06871","0.00045"
"493.16400","41.09724","0.00064"
"493.50600","41.12575","0.00080"
"493.84800","41.15421","0.00087"
"494.19000","41.18267","0.00027"
"494.53200","41.21119","0.00025"
"494.87400","41.23971","0.00083"
"495.21600","41.26817","0.00054"
"495.55800","41.29675","0.00045"
"495.90000","41.32515","-0.00004"
"496.24200","41.35373","0.00081"
"496.58400","41.38224","-0.00024"
"496.92600","41.41065","0.00024"
"497.26800","41.43923","0.00012"
"497.61000","41.46775","0.00025"
"497.95200","41.49621","0.00032"
"498.29400","41.52473","0.00087"
"498.63600","41.55319","-0.00007"
"498.97800","41.58165","0.00061"
"499.32000","41.61016","0.00046"
"499.66200","41.63869","-0.00007"
"500.00400","41.66721","-0.00088"
"500.34600","41.69572","0.00033"
"500.68800","41.72419","0.00078"
"501.03000","41.75265","0.00029"
"501.37200","41.78122","-0.00008"
"501.71400","41.80968","0.00036"
"502.05600","41.83826","0.00046"
"502.39800","41.86678","-0.00033"
"502.74000","41.89518","0.00034"
"503.08200","41.92371","0.00062"
"503.42400","41.95222","-0.00010"
"503.76600","41.98068","-0.00011"
"504.10800","42.00927","0.00004"
"504.45000","42.03760","0.00001"
"504.79200","42.06618","-0.00001"
"505.13400","42.09476","-0.00003"
"505.47600","42.12310","-0.00017"
"505.81800","42.15174","0.00056"
"506.16000","42.18020","0.00004"
"506.50200","42.20866","0.00041"
"506.84400","42.23724","0.00069"
"507.18600","42.26569","0.00031"
"507.52800","42.29416","0.00034"
"507.81000","42.31772","0.00008"