File: Force_trajectories/170121_1/Specimen_RawData_10.csv
End date,"1/21/2017"
Specimen label,"4DG_32"
Maximum Load,"0.96321",N

Time,Extension,Load
(s),(mm),(N)
"0.00000","0.00000","-0.00108"
"0.36000","0.03007","0.00675"
"0.72000","0.06021","0.01166"
"1.08000","0.09022","0.01401"
"1.44000","0.12024","0.01482"
"1.80000","0.15013","0.01578"
"2.16000","0.18027","0.01616"
"2.52000","0.21022","0.01616"
"2.88000","0.24017","0.01657"
"3.24000","0.27025","0.01734"
"3.60000","0.30026","0.01758"
"3.96000","0.33016","0.01744"
"4.32000","0.36017","0.01728"
"4.68000","0.39019","0.01785"
"5.04000","0.42014","0.01734"
"5.40000","0.45022","0.01716"
"5.76000","0.48023","0.01712"
"6.12000","0.51018","0.01712"
"6.48000","0.54020","0.01732"
"6.84000","0.57021","0.01728"
"7.20000","0.60011","0.01712"
"7.56000","0.63024","0.01692"
"7.92000","0.66026","0.01632"
"8.28000","0.69021","0.01705"
"8.64000","0.72022","0.01638"
"9.00000","0.75024","0.01640"
"9.36000","0.78019","0.01654"
"9.72000","0.81021","0.01622"
"10.08000","0.84016","0.01666"
"10.44000","0.87018","0.01656"
"10.80000","0.90019","0.01644"
"11.16000","0.93021","0.01677"
"11.52000","0.96016","0.01663"
"11.88000","0.99023","0.01695"
"12.24000","1.02019","0.01703"
"12.60000","1.05020","0.01731"
"12.96000","1.08016","0.01689"
"13.32000","1.11023","0.01730"
"13.68000","1.14013","0.01709"
"14.04000","1.17026","0.01692"
"14.40000","1.20022","0.01704"
"14.76000","1.23023","0.01683"
"15.12000","1.26024","0.01711"
"15.48000","1.29026","0.01726"
"15.84000","1.32015","0.01747"
"16.20000","1.35023","0.01739"
"16.56000","1.38024","0.01761"
"16.92000","1.41020","0.01700"
"17.28000","1.44015","0.01751"
"17.64000","1.47028","0.01776"
"18.00000","1.50012","0.01774"
"18.36000","1.53019","0.01764"
"18.72000","1.56015","0.01813"
"19.08000","1.59016","0.01765"
"19.44000","1.62018","0.01800"
"19.80000","1.65025","0.01787"
"20.16000","1.68021","0.01798"
"20.52000","1.71022","0.01803"
"20.88000","1.74023","0.01807"
"21.24000","1.77019","0.01877"
"21.60000","1.80014","0.01785"
"21.96000","1.83016","0.01811"
"22.32000","1.86017","0.01854"
"22.68000","1.89019","0.01854"
"23.04000","1.92020","0.01857"
"23.40000","1.95022","0.01845"
"23.76000","1.98017","0.01812"
"24.12000","2.01024","0.01841"
"24.48000","2.04020","0.01882"
"24.84000","2.07021","0.01868"
"25.20000","2.10023","0.01876"
"25.56000","2.13018","0.01890"
"25.92000","2.16020","0.01882"
"26.28000","2.19021","0.01867"
"26.64000","2.22016","0.01891"
"27.00000","2.25024","0.01832"
"27.36000","2.28019","0.01811"
"27.72000","2.31021","0.01859"
"28.08000","2.34022","0.01893"
"28.44000","2.37024","0.01917"
"28.80000","2.40025","0.01870"
"29.16000","2.43015","0.01902"
"29.52000","2.46022","0.01898"
"29.88000","2.49017","0.01878"
"30.24000","2.52019","0.01913"
"30.60000","2.55026","0.01904"
"30.96000","2.58028","0.01951"
"31.32000","2.61017","0.01925"
"31.68000","2.64025","0.01934"
"32.04000","2.67020","0.01952"
"32.40000","2.70016","0.01949"
"32.76000","2.73023","0.01927"
"33.12000","2.76024","0.01978"
"33.48000","2.79020","0.01946"
"33.84000","2.82021","0.01970"
"34.20000","2.85017","0.01930"
"34.56000","2.88018","0.01949"
"34.92000","2.91026","0.01973"
"35.28000","2.94027","0.01981"
"35.64000","2.97022","0.01943"
"36.00000","3.00024","0.02012"
"36.36000","3.03019","0.02029"
"36.72000","3.06021","0.01938"
"37.08000","3.09022","0.02001"
"37.44000","3.12018","0.01981"
"37.80000","3.15019","0.01997"
"38.16000","3.18021","0.02001"
"38.52000","3.21016","0.02012"
"38.88000","3.24023","0.02023"
"39.24000","3.27025","0.01998"
"39.60000","3.30020","0.01994"
"39.96000","3.33016","0.02054"
"40.32000","3.36017","0.02025"
"40.68000","3.39025","0.02018"
"41.04000","3.42020","0.02007"
"41.40000","3.45021","0.02041"
"41.76000","3.48023","0.01990"
"42.12000","3.51018","0.02026"
"42.48000","3.54026","0.02062"
"42.84000","3.57021","0.02051"
"43.20000","3.60017","0.02048"
"43.56000","3.63024","0.02051"
"43.92000","3.66026","0.02036"
"44.28000","3.69015","0.02028"
"44.64000","3.72022","0.02059"
"45.00000","3.75018","0.02030"
"45.36000","3.78013","0.02060"
"45.72000","3.81021","0.02058"
"46.08000","3.84028","0.02017"
"46.44000","3.87018","0.01999"
"46.80000","3.90019","0.02069"
"47.16000","3.93021","0.02030"
"47.52000","3.96016","0.02048"
"47.88000","3.99023","0.02039"
"48.24000","4.02025","0.02032"
"48.60000","4.05014","0.02051"
"48.96000","4.08022","0.02052"
"49.32000","4.11023","0.02098"
"49.68000","4.14013","0.02070"
"50.04000","4.17026","0.02068"
"50.40000","4.20021","0.02078"
"50.76000","4.23017","0.02094"
"51.12000","4.26024","0.02096"
"51.48000","4.29020","0.02099"
"51.84000","4.32015","0.02038"
"52.20000","4.35029","0.02112"
"52.56000","4.38024","0.02113"
"52.92000","4.41020","0.02074"
"53.28000","4.44021","0.02098"
"53.64000","4.47028","0.02064"
"54.00000","4.50012","0.02072"
"54.36000","4.53025","0.02102"
"54.72000","4.56021","0.02121"
"55.08000","4.59022","0.02125"
"55.44000","4.62018","0.02079"
"55.80000","4.65025","0.02090"
"56.16000","4.68015","0.02025"
"56.52000","4.71022","0.02099"
"56.88000","4.74023","0.02030"
"57.24000","4.77019","0.02101"
"57.60000","4.80014","0.02091"
"57.96000","4.83028","0.02057"
"58.32000","4.86011","0.02068"
"58.68000","4.89025","0.02098"
"59.04000","4.92026","0.02056"
"59.40000","4.95021","0.02117"
"59.76000","4.98017","0.02057"
"60.12000","5.01018","0.02072"
"60.48000","5.04020","0.02068"
"60.84000","5.07021","0.02067"
"61.20000","5.10023","0.02113"
"61.56000","5.13018","0.02131"
"61.92000","5.16020","0.02149"
"62.28000","5.19021","0.02083"
"62.64000","5.22016","0.02088"
"63.00000","5.25018","0.02125"
"63.36000","5.28019","0.02106"
"63.72000","5.31021","0.02060"
"64.08000","5.34016","0.02069"
"64.44000","5.37024","0.02080"
"64.80000","5.40019","0.02109"
"65.16000","5.43020","0.02088"
"65.52000","5.46022","0.02053"
"65.88000","5.49017","0.02109"
"66.24000","5.52019","0.02069"
"66.60000","5.55020","0.02125"
"66.96000","5.58022","0.02139"
"67.32000","5.61017","0.02099"
"67.68000","5.64025","0.02175"
"68.04000","5.67014","0.02125"
"68.40000","5.70015","0.02102"
"68.76000","5.73023","0.02113"
"69.12000","5.76024","0.02147"
"69.48000","5.79020","0.02117"
"69.84000","5.82021","0.02107"
"70.20000","5.85017","0.02115"
"70.56000","5.88018","0.02146"
"70.92000","5.91020","0.02181"
"71.28000","5.94021","0.02143"
"71.64000","5.97022","0.02169"
"72.00000","6.00024","0.02194"
"72.36000","6.03019","0.02231"
"72.72000","6.06021","0.02211"
"73.08000","6.09022","0.02216"
"73.44000","6.12024","0.02236"
"73.80000","6.15019","0.02201"
"74.16000","6.18026","0.02198"
"74.52000","6.21016","0.02196"
"74.88000","6.24017","0.02186"
"75.24000","6.27019","0.02222"
"75.60000","6.30026","0.02176"
"75.96000","6.33022","0.02185"
"76.32000","6.36029","0.02192"
"76.68000","6.39013","0.02278"
"77.04000","6.42020","0.02257"
"77.40000","6.45027","0.02259"
"77.76000","6.48023","0.02244"
"78.12000","6.51018","0.02242"
"78.48000","6.54026","0.02284"
"78.84000","6.57015","0.02277"
"79.20000","6.60023","0.02300"
"79.56000","6.63024","0.02313"
"79.92000","6.66019","0.02321"
"80.28000","6.69021","0.02316"
"80.64000","6.72022","0.02324"
"81.00000","6.75018","0.02307"
"81.36000","6.78013","0.02338"
"81.72000","6.81021","0.02298"
"82.08000","6.84022","0.02301"
"82.44000","6.87012","0.02326"
"82.80000","6.90025","0.02356"
"83.16000","6.93020","0.02293"
"83.52000","6.96016","0.02299"
"83.88000","6.99023","0.02301"
"84.24000","7.02025","0.02365"
"84.60000","7.05014","0.02304"
"84.96000","7.08022","0.02317"
"85.32000","7.11017","0.02332"
"85.68000","7.14013","0.02347"
"86.04000","7.17026","0.02342"
"86.40000","7.20021","0.02352"
"86.76000","7.23017","0.02346"
"87.12000","7.26024","0.02325"
"87.48000","7.29020","0.02316"
"87.84000","7.32015","0.02317"
"88.20000","7.35023","0.02339"
"88.56000","7.38024","0.02315"
"88.92000","7.41020","0.02260"
"89.28000","7.44021","0.02272"
"89.64000","7.47022","0.02248"
"90.00000","7.50018","0.02347"
"90.36000","7.53025","0.02293"
"90.72000","7.56021","0.02306"
"91.08000","7.59016","0.02286"
"91.44000","7.62024","0.02355"
"91.80000","7.65025","0.02348"
"92.16000","7.68015","0.02364"
"92.52000","7.71022","0.02321"
"92.88000","7.74023","0.02331"
"93.24000","7.77019","0.02354"
"93.60000","7.80020","0.02345"
"93.96000","7.83022","0.02337"
"94.32000","7.86017","0.02371"
"94.68000","7.89030","0.02372"
"95.04000","7.92020","0.02430"
"95.40000","7.95021","0.02354"
"95.76000","7.98023","0.02384"
"96.12000","8.01024","0.02372"
"96.48000","8.04014","0.02332"
"96.84000","8.07021","0.02336"
"97.20000","8.10023","0.02326"
"97.56000","8.13018","0.02370"
"97.92000","8.16020","0.02371"
"98.28000","8.19021","0.02433"
"98.64000","8.22010","0.02406"
"99.00000","8.25024","0.02356"
"99.36000","8.28019","0.02358"
"99.72000","8.31021","0.02383"
"100.08000","8.34022","0.02428"
"100.44000","8.37024","0.02406"
"100.80000","8.40013","0.02480"
"101.16000","8.43026","0.02447"
"101.52000","8.46022","0.02442"
"101.88000","8.49017","0.02421"
"102.24000","8.52019","0.02477"
"102.60000","8.55026","0.02466"
"102.96000","8.58016","0.02448"
"103.32000","8.61023","0.02467"
"103.68000","8.64019","0.02472"
"104.04000","8.67014","0.02410"
"104.40000","8.70021","0.02435"
"104.76000","8.73023","0.02466"
"105.12000","8.76018","0.02488"
"105.48000","8.79026","0.02531"
"105.84000","8.82021","0.02433"
"106.20000","8.85017","0.02496"
"106.56000","8.88024","0.02495"
"106.92000","8.91020","0.02520"
"107.28000","8.94015","0.02378"
"107.64000","8.97022","0.02374"
"108.00000","9.00024","0.02424"
"108.36000","9.03019","0.02435"
"108.72000","9.06021","0.02431"
"109.08000","9.09022","0.02413"
"109.44000","9.12018","0.02453"
"109.80000","9.15025","0.02442"
"110.16000","9.18026","0.02477"
"110.52000","9.21010","0.02509"
"110.88000","9.24023","0.02507"
"111.24000","9.27019","0.02549"
"111.60000","9.30020","0.02530"
"111.96000","9.33022","0.02540"
"112.32000","9.36023","0.02572"
"112.68000","9.39019","0.02527"
"113.04000","9.42020","0.02594"
"113.40000","9.45021","0.02600"
"113.76000","9.48017","0.02646"
"114.12000","9.51018","0.02670"
"114.48000","9.54026","0.02651"
"114.84000","9.57021","0.02649"
"115.20000","9.60029","0.02670"
"115.56000","9.63024","0.02598"
"115.92000","9.66019","0.02621"
"116.28000","9.69015","0.02638"
"116.64000","9.72028","0.02631"
"117.00000","9.75018","0.02700"
"117.36000","9.78019","0.02701"
"117.72000","9.81021","0.02739"
"118.08000","9.84022","0.02770"
"118.44000","9.87018","0.02796"
"118.80000","9.90025","0.02699"
"119.16000","9.93014","0.02732"
"119.52000","9.96022","0.02775"
"119.88000","9.99017","0.02739"
"120.24000","10.02025","0.02749"
"120.60000","10.05020","0.02765"
"120.96000","10.08022","0.02716"
"121.32000","10.11023","0.02724"
"121.68000","10.14019","0.02724"
"122.04000","10.17020","0.02752"
"122.40000","10.20021","0.02779"
"122.76000","10.23023","0.02734"
"123.12000","10.26024","0.02852"
"123.48000","10.29014","0.02812"
"123.84000","10.32021","0.02829"
"124.20000","10.35017","0.02828"
"124.56000","10.38018","0.02906"
"124.92000","10.41019","0.02989"
"125.28000","10.44021","0.02918"
"125.64000","10.47022","0.03017"
"126.00000","10.50018","0.02982"
"126.36000","10.53019","0.03071"
"126.72000","10.56021","0.03107"
"127.08000","10.59016","0.03104"
"127.44000","10.62024","0.03092"
"127.80000","10.65019","0.03161"
"128.16000","10.68020","0.03166"
"128.52000","10.71028","0.03116"
"128.88000","10.74023","0.03199"
"129.24000","10.77019","0.03074"
"129.60000","10.80026","0.03171"
"129.96000","10.83022","0.03147"
"130.32000","10.86017","0.03160"
"130.68000","10.89024","0.03195"
"131.04000","10.92020","0.03212"
"131.40000","10.95015","0.03244"
"131.76000","10.98023","0.03320"
"132.12000","11.01018","0.03408"
"132.48000","11.04020","0.03317"
"132.84000","11.07021","0.03248"
"133.20000","11.10023","0.03342"
"133.56000","11.13024","0.03353"
"133.92000","11.16025","0.03270"
"134.28000","11.19021","0.03309"
"134.64000","11.22016","0.03251"
"135.00000","11.25024","0.03354"
"135.36000","11.28019","0.03392"
"135.72000","11.31021","0.03297"
"136.08000","11.34022","0.03318"
"136.44000","11.37024","0.03342"
"136.80000","11.40019","0.03373"
"137.16000","11.43026","0.03434"
"137.52000","11.46016","0.03540"
"137.88000","11.49017","0.03428"
"138.24000","11.52025","0.03437"
"138.60000","11.55020","0.03386"
"138.96000","11.58016","0.03424"
"139.32000","11.61023","0.03396"
"139.68000","11.64019","0.03435"
"140.04000","11.67020","0.03467"
"140.40000","11.70021","0.03477"
"140.76000","11.73023","0.03547"
"141.12000","11.76012","0.03446"
"141.48000","11.79020","0.03576"
"141.84000","11.82021","0.03565"
"142.20000","11.85022","0.03532"
"142.56000","11.88018","0.03547"
"142.92000","11.91026","0.03643"
"143.28000","11.94015","0.03630"
"143.64000","11.97022","0.03596"
"144.00000","12.00024","0.03525"
"144.36000","12.03019","0.03667"
"144.72000","12.06021","0.03536"
"145.08000","12.09022","0.03581"
"145.44000","12.12018","0.03594"
"145.80000","12.15019","0.03604"
"146.16000","12.18020","0.03708"
"146.52000","12.21022","0.03626"
"146.88000","12.24023","0.03692"
"147.24000","12.27019","0.03587"
"147.60000","12.30014","0.03601"
"147.96000","12.33022","0.03697"
"148.32000","12.36023","0.03679"
"148.68000","12.39019","0.03830"
"149.04000","12.42020","0.03819"
"149.40000","12.45021","0.03813"
"149.76000","12.48011","0.03833"
"150.12000","12.51018","0.03953"
"150.48000","12.54026","0.03927"
"150.84000","12.57015","0.04060"
"151.20000","12.60023","0.03943"
"151.56000","12.63024","0.04157"
"151.92000","12.66013","0.04126"
"152.28000","12.69015","0.04166"
"152.64000","12.72022","0.04052"
"153.00000","12.75012","0.04177"
"153.36000","12.78019","0.04228"
"153.72000","12.81027","0.04251"
"154.08000","12.84022","0.04266"
"154.44000","12.87017","0.04343"
"154.80000","12.90025","0.04424"
"155.16000","12.93014","0.04353"
"155.52000","12.96028","0.04459"
"155.88000","12.99023","0.04488"
"156.24000","13.02019","0.04451"
"156.60000","13.05020","0.04550"
"156.96000","13.08022","0.04589"
"157.32000","13.11017","0.04582"
"157.68000","13.14018","0.04731"
"158.04000","13.17020","0.04727"
"158.40000","13.20021","0.04830"
"158.76000","13.23017","0.04768"
"159.12000","13.26030","0.04857"
"159.48000","13.29020","0.04901"
"159.84000","13.32021","0.05001"
"160.20000","13.35023","0.05014"
"160.56000","13.38018","0.04938"
"160.92000","13.41019","0.05073"
"161.28000","13.44021","0.05051"
"161.64000","13.47016","0.05123"
"162.00000","13.50024","0.05188"
"162.36000","13.53019","0.05229"
"162.72000","13.56021","0.05261"
"163.08000","13.59016","0.05299"
"163.44000","13.62024","0.05294"
"163.80000","13.65019","0.05394"
"164.16000","13.68020","0.05375"
"164.52000","13.71022","0.05439"
"164.88000","13.74017","0.05501"
"165.24000","13.77019","0.05526"
"165.60000","13.80026","0.05668"
"165.96000","13.83016","0.05668"
"166.32000","13.86017","0.05674"
"166.68000","13.89018","0.05748"
"167.04000","13.92020","0.05880"
"167.40000","13.95015","0.05897"
"167.76000","13.98017","0.05923"
"168.12000","14.01018","0.06057"
"168.48000","14.04014","0.06024"
"168.84000","14.07021","0.06059"
"169.20000","14.10023","0.06157"
"169.56000","14.13018","0.06031"
"169.92000","14.16020","0.06066"
"170.28000","14.19015","0.06250"
"170.64000","14.22016","0.06318"
"171.00000","14.25024","0.06491"
"171.36000","14.28019","0.06460"
"171.72000","14.31021","0.06578"
"172.08000","14.34022","0.06679"
"172.44000","14.37018","0.06742"
"172.80000","14.40019","0.06825"
"173.16000","14.43020","0.06819"
"173.52000","14.46022","0.06931"
"173.88000","14.49023","0.06908"
"174.24000","14.52025","0.06988"
"174.60000","14.55020","0.07037"
"174.96000","14.58016","0.07079"
"175.32000","14.61023","0.07157"
"175.68000","14.64019","0.07212"
"176.04000","14.67020","0.07248"
"176.40000","14.70021","0.07241"
"176.76000","14.73023","0.07289"
"177.12000","14.76012","0.07207"
"177.48000","14.79026","0.07324"
"177.84000","14.82021","0.07385"
"178.20000","14.85017","0.07456"
"178.56000","14.88024","0.07534"
"178.92000","14.91025","0.07594"
"179.28000","14.94015","0.07647"
"179.64000","14.97028","0.07637"
"180.00000","15.00018","0.07710"
"180.36000","15.03019","0.07771"
"180.72000","15.06021","0.07817"
"181.08000","15.09022","0.07888"
"181.44000","15.12018","0.07888"
"181.80000","15.15025","0.07934"
"182.16000","15.18020","0.07980"
"182.52000","15.21016","0.08019"
"182.88000","15.24017","0.08069"
"183.24000","15.27025","0.08078"
"183.60000","15.30014","0.08079"
"183.96000","15.33022","0.08122"
"184.32000","15.36023","0.08162"
"184.68000","15.39018","0.08257"
"185.04000","15.42020","0.08332"
"185.40000","15.45021","0.08358"
"185.76000","15.48017","0.08314"
"186.12000","15.51024","0.08420"
"186.48000","15.54026","0.08452"
"186.84000","15.57015","0.08519"
"187.20000","15.60023","0.08632"
"187.56000","15.63024","0.08745"
"187.92000","15.66013","0.08858"
"188.28000","15.69027","0.08970"
"188.64000","15.72016","0.09113"
"189.00000","15.75012","0.09276"
"189.36000","15.78025","0.09476"
"189.72000","15.81021","0.09561"
"190.08000","15.84016","0.09783"
"190.44000","15.87023","0.09868"
"190.80000","15.90019","0.09945"
"191.16000","15.93020","0.09969"
"191.52000","15.96022","0.10137"
"191.88000","15.99017","0.10251"
"192.24000","16.02019","0.10413"
"192.60000","16.05020","0.10553"
"192.96000","16.08022","0.10734"
"193.32000","16.11017","0.10847"
"193.68000","16.14018","0.11038"
"194.04000","16.17020","0.11068"
"194.40000","16.20021","0.11223"
"194.76000","16.23023","0.11355"
"195.12000","16.26024","0.11522"
"195.48000","16.29014","0.11754"
"195.84000","16.32021","0.11899"
"196.20000","16.35023","0.12100"
"196.56000","16.38018","0.12264"
"196.92000","16.41025","0.12495"
"197.28000","16.44021","0.12709"
"197.64000","16.47016","0.12844"
"198.00000","16.50030","0.12995"
"198.36000","16.53019","0.13137"
"198.72000","16.56021","0.12846"
"199.08000","16.59022","0.12884"
"199.44000","16.62023","0.12939"
"199.80000","16.65013","0.13077"
"200.16000","16.68020","0.13200"
"200.52000","16.71022","0.13265"
"200.88000","16.74017","0.13175"
"201.24000","16.77019","0.13191"
"201.60000","16.80026","0.13256"
"201.96000","16.83016","0.13321"
"202.32000","16.86023","0.13356"
"202.68000","16.89025","0.13353"
"203.04000","16.92014","0.13411"
"203.40000","16.95021","0.13495"
"203.76000","16.98023","0.13623"
"204.12000","17.01012","0.13897"
"204.48000","17.04026","0.14029"
"204.84000","17.07021","0.14316"
"205.20000","17.10016","0.14632"
"205.56000","17.13018","0.15026"
"205.92000","17.16025","0.15318"
"206.28000","17.19015","0.15527"
"206.64000","17.22022","0.15733"
"207.00000","17.25024","0.16011"
"207.36000","17.28019","0.16182"
"207.72000","17.31021","0.16382"
"208.08000","17.34022","0.16541"
"208.44000","17.37011","0.16701"
"208.80000","17.40019","0.16849"
"209.16000","17.43020","0.16940"
"209.52000","17.46016","0.17087"
"209.88000","17.49023","0.17223"
"210.24000","17.52025","0.17273"
"210.60000","17.55014","0.17402"
"210.96000","17.58015","0.17543"
"211.32000","17.61023","0.17687"
"211.68000","17.64018","0.17787"
"212.04000","17.67026","0.17973"
"212.40000","17.70021","0.18117"
"212.76000","17.73017","0.18272"
"213.12000","17.76024","0.18418"
"213.48000","17.79026","0.18598"
"213.84000","17.82015","0.18781"
"214.20000","17.85022","0.19049"
"214.56000","17.88024","0.19311"
"214.92000","17.91019","0.19685"
"215.28000","17.94021","0.20250"
"215.64000","17.97022","0.20710"
"216.00000","18.00018","0.21178"
"216.36000","18.03025","0.21933"
"216.72000","18.06015","0.22490"
"217.08000","18.09022","0.22615"
"217.44000","18.12024","0.23261"
"217.80000","18.15025","0.23464"
"218.16000","18.18014","0.23594"
"218.52000","18.21022","0.23674"
"218.88000","18.24017","0.23860"
"219.24000","18.27019","0.23901"
"219.60000","18.30014","0.24435"
"219.96000","18.33027","0.23464"
"220.32000","18.36017","0.23435"
"220.68000","18.39024","0.23444"
"221.04000","18.42020","0.23422"
"221.40000","18.45015","0.23278"
"221.76000","18.48023","0.23312"
"222.12000","18.51018","0.23041"
"222.48000","18.54014","0.22864"
"222.84000","18.57027","0.23140"
"223.20000","18.60023","0.23427"
"223.56000","18.63018","0.23620"
"223.92000","18.66013","0.23772"
"224.28000","18.69027","0.23898"
"224.64000","18.72016","0.23993"
"225.00000","18.75018","0.23979"
"225.36000","18.78019","0.24112"
"225.72000","18.81015","0.24283"
"226.08000","18.84022","0.24583"
"226.44000","18.87024","0.25076"
"226.80000","18.90019","0.25515"
"227.16000","18.93020","0.25919"
"227.52000","18.96022","0.26253"
"227.88000","18.99023","0.26637"
"228.24000","19.02019","0.27015"
"228.60000","19.05020","0.27294"
"228.96000","19.08022","0.27569"
"229.32000","19.11017","0.27811"
"229.68000","19.14018","0.27995"
"230.04000","19.17020","0.28136"
"230.40000","19.20021","0.28222"
"230.76000","19.23023","0.28305"
"231.12000","19.26018","0.28398"
"231.48000","19.29020","0.28515"
"231.84000","19.32021","0.28646"
"232.20000","19.35023","0.28775"
"232.56000","19.38018","0.28932"
"232.92000","19.41019","0.29185"
"233.28000","19.44021","0.29454"
"233.64000","19.47016","0.29056"
"234.00000","19.50024","0.28698"
"234.36000","19.53019","0.28798"
"234.72000","19.56021","0.28757"
"235.08000","19.59022","0.28839"
"235.44000","19.62023","0.29091"
"235.80000","19.65019","0.29424"
"236.16000","19.68026","0.29618"
"236.52000","19.71022","0.30080"
"236.88000","19.74023","0.30586"
"237.24000","19.77025","0.31089"
"237.60000","19.80020","0.31475"
"237.96000","19.83016","0.31942"
"238.32000","19.86023","0.32363"
"238.68000","19.89024","0.32733"
"239.04000","19.92014","0.32993"
"239.40000","19.95021","0.33189"
"239.76000","19.98029","0.33367"
"240.12000","20.01018","0.33547"
"240.48000","20.04025","0.33943"
"240.84000","20.07015","0.34410"
"241.20000","20.10016","0.35080"
"241.56000","20.13024","0.35849"
"241.92000","20.16025","0.35966"
"242.28000","20.19015","0.36623"
"242.64000","20.22022","0.37150"
"243.00000","20.25023","0.37687"
"243.36000","20.28019","0.38060"
"243.72000","20.31021","0.38427"
"244.08000","20.34022","0.38709"
"244.44000","20.37017","0.38906"
"244.80000","20.40019","0.39047"
"245.16000","20.43020","0.39154"
"245.52000","20.46022","0.39314"
"245.88000","20.49023","0.39417"
"246.24000","20.52024","0.39548"
"246.60000","20.55014","0.39752"
"246.96000","20.58022","0.39866"
"247.32000","20.61023","0.40090"
"247.68000","20.64018","0.40327"
"248.04000","20.67020","0.40577"
"248.40000","20.70021","0.40895"
"248.76000","20.73017","0.41256"
"249.12000","20.76018","0.41604"
"249.48000","20.79020","0.42063"
"249.84000","20.82015","0.42285"
"250.20000","20.85022","0.39638"
"250.56000","20.88024","0.39600"
"250.92000","20.91013","0.39852"
"251.28000","20.94021","0.40153"
"251.64000","20.97022","0.40516"
"252.00000","21.00018","0.40982"
"252.36000","21.03019","0.41461"
"252.72000","21.06027","0.42148"
"253.08000","21.09016","0.42829"
"253.44000","21.12017","0.43301"
"253.80000","21.15025","0.43608"
"254.16000","21.18014","0.43892"
"254.52000","21.21022","0.44070"
"254.88000","21.24023","0.44362"
"255.24000","21.27019","0.44693"
"255.60000","21.30020","0.45123"
"255.96000","21.33027","0.45576"
"256.32000","21.36011","0.46022"
"256.68000","21.39024","0.46420"
"257.04000","21.42020","0.46756"
"257.40000","21.45021","0.47097"
"257.76000","21.48023","0.47340"
"258.12000","21.51018","0.46558"
"258.48000","21.54020","0.46670"
"258.84000","21.57027","0.47054"
"259.20000","21.60022","0.47377"
"259.56000","21.63018","0.47622"
"259.92000","21.66019","0.47824"
"260.28000","21.69027","0.48009"
"260.64000","21.72016","0.48143"
"261.00000","21.75024","0.48366"
"261.36000","21.78019","0.48719"
"261.72000","21.81014","0.48914"
"262.08000","21.84016","0.49148"
"262.44000","21.87023","0.49453"
"262.80000","21.90013","0.49799"
"263.16000","21.93026","0.50198"
"263.52000","21.96022","0.50570"
"263.88000","21.99023","0.51121"
"264.24000","22.02013","0.51639"
"264.60000","22.05026","0.52130"
"264.96000","22.08015","0.52485"
"265.32000","22.11023","0.52917"
"265.68000","22.14024","0.53295"
"266.04000","22.17020","0.53615"
"266.40000","22.20015","0.53877"
"266.76000","22.23022","0.54067"
"267.12000","22.26018","0.54208"
"267.48000","22.29020","0.54385"
"267.84000","22.32021","0.54635"
"268.20000","22.35023","0.55216"
"268.56000","22.38018","0.55740"
"268.92000","22.41019","0.56314"
"269.28000","22.44015","0.56912"
"269.64000","22.47022","0.57430"
"270.00000","22.50024","0.57822"
"270.36000","22.53019","0.58206"
"270.72000","22.56015","0.58604"
"271.08000","22.59022","0.58880"
"271.44000","22.62017","0.59117"
"271.80000","22.65019","0.59387"
"272.16000","22.68020","0.59574"
"272.52000","22.71016","0.59743"
"272.88000","22.74017","0.59933"
"273.24000","22.77024","0.59846"
"273.60000","22.80020","0.60001"
"273.96000","22.83022","0.60181"
"274.32000","22.86029","0.60347"
"274.68000","22.89018","0.60524"
"275.04000","22.92014","0.60668"
"275.40000","22.95021","0.60962"
"275.76000","22.98023","0.61307"
"276.12000","23.01018","0.61785"
"276.48000","23.04025","0.62291"
"276.84000","23.07021","0.62962"
"277.20000","23.10023","0.63589"
"277.56000","23.13018","0.64102"
"277.92000","23.16019","0.64476"
"278.28000","23.19015","0.64727"
"278.64000","23.22022","0.65127"
"279.00000","23.25024","0.65481"
"279.36000","23.28019","0.66089"
"279.72000","23.31021","0.66811"
"280.08000","23.34022","0.67151"
"280.44000","23.37017","0.67665"
"280.80000","23.40025","0.68081"
"281.16000","23.43026","0.68364"
"281.52000","23.46022","0.68644"
"281.88000","23.49023","0.68903"
"282.24000","23.52024","0.69052"
"282.60000","23.55020","0.69181"
"282.96000","23.58021","0.69271"
"283.32000","23.61017","0.69418"
"283.68000","23.64018","0.69634"
"284.04000","23.67020","0.69806"
"284.40000","23.70027","0.70069"
"284.76000","23.73017","0.70329"
"285.12000","23.76024","0.70635"
"285.48000","23.79020","0.70914"
"285.84000","23.82015","0.71267"
"286.20000","23.85022","0.71752"
"286.56000","23.88024","0.72267"
"286.92000","23.91019","0.72805"
"287.28000","23.94020","0.73312"
"287.64000","23.97016","0.73997"
"288.00000","24.00018","0.74547"
"288.36000","24.03025","0.74992"
"288.72000","24.06026","0.75152"
"289.08000","24.09016","0.75209"
"289.44000","24.12017","0.75394"
"289.80000","24.15019","0.75734"
"290.16000","24.18014","0.76322"
"290.52000","24.21022","0.76886"
"290.88000","24.24023","0.77452"
"291.24000","24.27018","0.78098"
"291.60000","24.30026","0.78614"
"291.96000","24.33022","0.79120"
"292.32000","24.36011","0.79528"
"292.68000","24.39024","0.79893"
"293.04000","24.42026","0.80126"
"293.40000","24.45021","0.80416"
"293.76000","24.48022","0.80539"
"294.12000","24.51024","0.80739"
"294.48000","24.54014","0.80939"
"294.84000","24.57021","0.81225"
"295.20000","24.60023","0.81551"
"295.56000","24.63018","0.81993"
"295.92000","24.66019","0.82344"
"296.28000","24.69021","0.82790"
"296.64000","24.72016","0.82863"
"297.00000","24.75023","0.83373"
"297.36000","24.78019","0.83857"
"297.72000","24.81014","0.84174"
"298.08000","24.84022","0.84456"
"298.44000","24.87023","0.84858"
"298.80000","24.90013","0.85287"
"299.16000","24.93026","0.86043"
"299.52000","24.96028","0.86905"
"299.88000","24.99017","0.87498"
"300.24000","25.02019","0.88203"
"300.60000","25.05026","0.88745"
"300.96000","25.08015","0.89213"
"301.32000","25.11029","0.89817"
"301.68000","25.14024","0.90128"
"302.04000","25.17020","0.90333"
"302.40000","25.20021","0.90445"
"302.76000","25.23017","0.90502"
"303.12000","25.26012","0.90617"
"303.48000","25.29020","0.90786"
"303.84000","25.32021","0.91010"
"304.20000","25.35016","0.91290"
"304.56000","25.38018","0.91580"
"304.92000","25.41025","0.81540"
"305.28000","25.44015","0.81546"
"305.64000","25.47022","0.81752"
"306.00000","25.50018","0.81991"
"306.36000","25.53019","0.82210"
"306.72000","25.56020","0.82619"
"307.08000","25.59028","0.82759"
"307.44000","25.62011","0.83213"
"307.80000","25.65025","0.83552"
"308.16000","25.68020","0.83982"
"308.52000","25.71016","0.84207"
"308.88000","25.74017","0.84460"
"309.24000","25.77024","0.84656"
"309.60000","25.80014","0.84976"
"309.96000","25.83021","0.85261"
"310.32000","25.86023","0.85393"
"310.68000","25.89018","0.85640"
"311.04000","25.92020","0.85992"
"311.40000","25.95021","0.86433"
"311.76000","25.98017","0.86997"
"312.12000","26.01024","0.87573"
"312.48000","26.04025","0.88260"
"312.84000","26.07021","0.88920"
"313.20000","26.10022","0.89476"
"313.56000","26.13018","0.89990"
"313.92000","26.16019","0.90330"
"314.28000","26.19021","0.90388"
"314.64000","26.22022","0.90466"
"315.00000","26.25018","0.90494"
"315.36000","26.28019","0.90584"
"315.72000","26.31021","0.90702"
"316.08000","26.34022","0.90770"
"316.44000","26.37023","0.90908"
"316.80000","26.40025","0.91025"
"317.16000","26.43014","0.91169"
"317.52000","26.46028","0.90728"
"317.88000","26.49017","0.90677"
"318.24000","26.52019","0.90756"
"318.60000","26.55020","0.90902"
"318.96000","26.58022","0.91129"
"319.32000","26.61017","0.91269"
"319.68000","26.64024","0.91497"
"320.04000","26.67020","0.91784"
"320.40000","26.70021","0.92136"
"320.76000","26.73017","0.92464"
"321.12000","26.76024","0.92894"
"321.48000","26.79014","0.93313"
"321.84000","26.82027","0.93735"
"322.20000","26.85023","0.94256"
"322.56000","26.88024","0.94748"
"322.92000","26.91019","0.95131"
"323.28000","26.94027","0.95433"
"323.64000","26.97016","0.95634"
"324.00000","27.00018","0.95839"
"324.36000","27.03019","0.96251"
"324.72000","27.06020","0.88202"
"325.08000","27.09022","0.88414"
"325.44000","27.12023","0.88423"
"325.80000","27.15013","0.88868"
"326.16000","27.18020","0.89228"
"326.52000","27.21022","0.89580"
"326.88000","27.24017","0.89669"
"327.24000","27.27019","0.90057"
"327.60000","27.30020","0.90187"
"327.96000","27.33015","0.90363"
"328.32000","27.36017","0.90421"
"328.68000","27.39018","0.90455"
"329.04000","27.42020","0.90510"
"329.40000","27.45021","0.90568"
"329.76000","27.48023","0.90671"
"330.12000","27.51018","0.73024"
"330.48000","27.54020","0.72481"
"330.84000","27.57021","0.72230"
"331.20000","27.60016","0.71921"
"331.56000","27.63018","0.72217"
"331.92000","27.66025","0.71971"
"332.28000","27.69021","0.72109"
"332.64000","27.72022","0.72021"
"333.00000","27.75024","0.70933"
"333.36000","27.78025","0.71072"
"333.72000","27.81015","0.70961"
"334.08000","27.84022","0.71005"
"334.44000","27.87017","0.71315"
"334.80000","27.90019","0.71289"
"335.16000","27.93020","0.54275"
"335.52000","27.96022","0.53839"
"335.88000","27.99017","0.53785"
"336.24000","28.02018","0.53835"
"336.60000","28.05020","0.53773"
"336.96000","28.08021","0.53804"
"337.32000","28.11029","0.53634"
"337.68000","28.14018","0.02111"
"338.04000","28.17020","0.02051"
"338.40000","28.20021","0.01676"
"338.76000","28.23023","0.01845"
"339.12000","28.26018","0.02020"
"339.48000","28.29020","0.02005"
"339.84000","28.32021","0.01767"
"340.20000","28.35022","0.02117"
"340.56000","28.38024","0.02069"
"340.92000","28.41025","0.01787"
"341.28000","28.44015","0.01977"
"341.64000","28.47022","0.02171"
"342.00000","28.50024","0.01885"
"342.36000","28.53019","0.01999"
"342.72000","28.56021","0.02183"
"343.08000","28.59022","0.01922"
"343.44000","28.62017","0.01940"
"343.80000","28.65025","0.02198"
"344.16000","28.68020","0.02021"
"344.52000","28.71022","0.01957"
"344.88000","28.74023","0.02137"
"345.24000","28.77025","0.02064"
"345.60000","28.80014","0.02051"
"345.96000","28.83022","0.02053"
"346.32000","28.86023","0.02089"
"346.68000","28.89018","0.02198"
"347.04000","28.92020","0.01998"
"347.40000","28.95021","0.02075"
"347.76000","28.98017","0.02207"
"348.12000","29.01024","0.02152"
"348.48000","29.04020","0.02077"
"348.84000","29.07021","0.02207"
"349.20000","29.10022","0.02224"
"349.56000","29.13024","0.02178"
"349.92000","29.16019","0.02153"
"350.28000","29.19021","0.02246"
"350.64000","29.22022","0.02297"
"351.00000","29.25018","0.02203"
"351.36000","29.28019","0.02189"
"351.72000","29.31027","0.02297"
"352.08000","29.34016","0.02253"
"352.44000","29.37024","0.02309"
"352.80000","29.40019","0.02331"
"353.16000","29.43014","0.02339"
"353.52000","29.46022","0.02299"
"353.88000","29.49017","0.02347"
"354.24000","29.52019","0.02434"
"354.60000","29.55020","0.02363"
"354.96000","29.58021","0.02414"
"355.32000","29.61017","0.02432"
"355.68000","29.64024","0.02453"
"356.04000","29.67020","0.02499"
"356.40000","29.70015","0.02450"
"356.76000","29.73017","0.02647"
"357.12000","29.76024","0.02524"
"357.48000","29.79020","0.02575"
"357.84000","29.82027","0.02618"
"358.20000","29.85023","0.02657"
"358.56000","29.88018","0.02690"
"358.92000","29.91025","0.02732"
"359.28000","29.94027","0.02781"
"359.64000","29.97010","0.02730"
"360.00000","30.00024","0.02753"
"360.36000","30.03025","0.02856"
"360.72000","30.06021","0.02840"
"361.08000","30.09022","0.02882"
"361.44000","30.12024","0.02942"
"361.80000","30.15013","0.02937"
"362.16000","30.18020","0.02971"
"362.52000","30.21022","0.03034"
"362.88000","30.24017","0.03015"
"363.24000","30.27019","0.03133"
"363.60000","30.30026","0.03070"
"363.96000","30.33022","0.03170"
"364.32000","30.36017","0.03131"
"364.68000","30.39013","0.03241"
"365.04000","30.42020","0.03340"
"365.40000","30.45015","0.03309"
"365.76000","30.48023","0.03374"
"366.12000","30.51018","0.03477"
"366.48000","30.54019","0.03462"
"366.84000","30.57021","0.03488"
"367.20000","30.60022","0.03615"
"367.56000","30.63018","0.03551"
"367.92000","30.66019","0.03707"
"368.28000","30.69015","0.03788"
"368.64000","30.72028","0.03751"
"369.00000","30.75024","0.03744"
"369.36000","30.78019","0.03820"
"369.72000","30.81014","0.03892"
"370.08000","30.84022","0.03893"
"370.44000","30.87017","0.03930"
"370.80000","30.90019","0.03941"
"371.16000","30.93020","0.03972"
"371.52000","30.96016","0.04048"
"371.88000","30.99017","0.04097"
"372.24000","31.02025","0.04059"
"372.60000","31.05020","0.04192"
"372.96000","31.08022","0.04136"
"373.32000","31.11023","0.04272"
"373.68000","31.14018","0.04306"
"374.04000","31.17014","0.04351"
"374.40000","31.20021","0.04361"
"374.76000","31.23023","0.04359"
"375.12000","31.26012","0.04391"
"375.48000","31.29019","0.04353"
"375.84000","31.32021","0.04469"
"376.20000","31.35022","0.04434"
"376.56000","31.38024","0.04487"
"376.92000","31.41019","0.04438"
"377.28000","31.44015","0.04464"
"377.64000","31.47028","0.04526"
"378.00000","31.50018","0.04496"
"378.36000","31.53019","0.04502"
"378.72000","31.56021","0.04531"
"379.08000","31.59016","0.04577"
"379.44000","31.62017","0.04639"
"379.80000","31.65018","0.04666"
"380.16000","31.68014","0.04696"
"380.52000","31.71021","0.04783"
"380.88000","31.74023","0.04805"
"381.24000","31.77024","0.04811"
"381.60000","31.80020","0.04869"
"381.96000","31.83027","0.04941"
"382.32000","31.86017","0.04845"
"382.68000","31.89018","0.04980"
"383.04000","31.92025","0.05089"
"383.40000","31.95021","0.05054"
"383.76000","31.98016","0.05129"
"384.12000","32.01024","0.05157"
"384.48000","32.04020","0.05208"
"384.84000","32.07015","0.05207"
"385.20000","32.10022","0.05328"
"385.56000","32.13024","0.05369"
"385.92000","32.16019","0.05478"
"386.28000","32.19027","0.05459"
"386.64000","32.22022","0.05477"
"387.00000","32.25017","0.05568"
"387.36000","32.28025","0.05596"
"387.72000","32.31020","0.05645"
"388.08000","32.34016","0.05754"
"388.44000","32.37029","0.05794"
"388.80000","32.40019","0.05867"
"389.16000","32.43014","0.05802"
"389.52000","32.46016","0.05746"
"389.88000","32.49011","0.05740"
"390.24000","32.52018","0.05836"
"390.60000","32.55020","0.05853"
"390.96000","32.58021","0.05917"
"391.32000","32.61017","0.05909"
"391.68000","32.64024","0.05744"
"392.04000","32.67020","0.05857"
"392.40000","32.70015","0.05906"
"392.76000","32.73022","0.05848"
"393.12000","32.76024","0.05925"
"393.48000","32.79020","0.06059"
"393.84000","32.82021","0.06083"
"394.20000","32.85022","0.06179"
"394.56000","32.88018","0.06223"
"394.92000","32.91025","0.06269"
"395.28000","32.94020","0.06321"
"395.64000","32.97016","0.06287"
"396.00000","33.00023","0.06133"
"396.36000","33.03019","0.06045"
"396.72000","33.06020","0.06059"
"397.08000","33.09022","0.06133"
"397.44000","33.12024","0.06155"
"397.80000","33.15012","0.06303"
"398.16000","33.18020","0.06307"
"398.52000","33.21021","0.06380"
"398.88000","33.24017","0.06413"
"399.24000","33.27018","0.06397"
"399.60000","33.30026","0.06475"
"399.96000","33.33015","0.06519"
"400.32000","33.36023","0.06587"
"400.68000","33.39018","0.06606"
"401.04000","33.42014","0.06158"
"401.40000","33.45021","0.05995"
"401.76000","33.48028","0.06117"
"402.12000","33.51012","0.06147"
"402.48000","33.54025","0.06257"
"402.84000","33.57027","0.06243"
"403.20000","33.60016","0.06322"
"403.56000","33.63018","0.06286"
"403.92000","33.66019","0.06318"
"404.28000","33.69015","0.06501"
"404.64000","33.72028","0.06531"
"405.00000","33.75017","0.06531"
"405.36000","33.78019","0.06630"
"405.72000","33.81020","0.06670"
"406.08000","33.84022","0.06651"
"406.44000","33.87011","0.06727"
"406.80000","33.90018","0.06725"
"407.16000","33.93020","0.06820"
"407.52000","33.96016","0.06855"
"407.88000","33.99017","0.06833"
"408.24000","34.02024","0.06959"
"408.60000","34.05014","0.06863"
"408.96000","34.08021","0.07004"
"409.32000","34.11023","0.07013"
"409.68000","34.14018","0.07072"
"410.04000","34.17020","0.07119"
"410.40000","34.20027","0.07193"
"410.76000","34.23011","0.07214"
"411.12000","34.26024","0.07234"
"411.48000","34.29025","0.07256"
"411.84000","34.32015","0.07331"
"412.20000","34.35022","0.07352"
"412.56000","34.38024","0.07391"
"412.92000","34.41013","0.07421"
"413.28000","34.44020","0.07432"
"413.64000","34.47022","0.07495"
"414.00000","34.50018","0.07497"
"414.36000","34.53019","0.07410"
"414.72000","34.56020","0.07389"
"415.08000","34.59016","0.07517"
"415.44000","34.62017","0.07535"
"415.80000","34.65019","0.07564"
"416.16000","34.68020","0.07613"
"416.52000","34.71021","0.07591"
"416.88000","34.74023","0.07672"
"417.24000","34.77018","0.07685"
"417.60000","34.80014","0.07658"
"417.96000","34.83027","0.07642"
"418.32000","34.86017","0.07680"
"418.68000","34.89024","0.07717"
"419.04000","34.92020","0.07748"
"419.40000","34.95015","0.07773"
"419.76000","34.98022","0.07771"
"420.12000","35.01024","0.07760"
"420.48000","35.04013","0.07822"
"420.84000","35.07021","0.07857"
"421.20000","35.10022","0.07858"
"421.56000","35.13024","0.07819"
"421.92000","35.16019","0.07865"
"422.28000","35.19027","0.07899"
"422.64000","35.22016","0.07906"
"423.00000","35.25024","0.07980"
"423.36000","35.28019","0.07974"
"423.72000","35.31020","0.07976"
"424.08000","35.34016","0.08010"
"424.44000","35.37023","0.08042"
"424.80000","35.40018","0.08003"
"425.16000","35.43020","0.08046"
"425.52000","35.46022","0.08037"
"425.88000","35.49017","0.08064"
"426.24000","35.52013","0.08113"
"426.60000","35.55026","0.08109"
"426.96000","35.58022","0.08138"
"427.32000","35.61017","0.08153"
"427.68000","35.64024","0.08186"
"428.04000","35.67020","0.08176"
"428.40000","35.70015","0.08037"
"428.76000","35.73028","0.08051"
"429.12000","35.76018","0.08050"
"429.48000","35.79020","0.08125"
"429.84000","35.82021","0.08095"
"430.20000","35.85016","0.08137"
"430.56000","35.88018","0.08176"
"430.92000","35.91019","0.08139"
"431.28000","35.94021","0.08187"
"431.64000","35.97016","0.08227"
"432.00000","36.00017","0.08224"
"432.36000","36.03019","0.08259"
"432.72000","36.06020","0.08247"
"433.08000","36.09022","0.08308"
"433.44000","36.12017","0.08310"
"433.80000","36.15025","0.08357"
"434.16000","36.18020","0.08350"
"434.52000","36.21016","0.08316"
"434.88000","36.24017","0.08314"
"435.24000","36.27018","0.08300"
"435.60000","36.30026","0.08365"
"435.96000","36.33021","0.08338"
"436.32000","36.36017","0.08286"
"436.68000","36.39024","0.08336"
"437.04000","36.42020","0.08357"
"437.40000","36.45027","0.08433"
"437.76000","36.48022","0.08424"
"438.12000","36.51018","0.08411"
"438.48000","36.54026","0.08457"
"438.84000","36.57015","0.08453"
"439.20000","36.60016","0.08439"
"439.56000","36.63023","0.07681"
"439.92000","36.66019","0.07700"
"440.28000","36.69020","0.07866"
"440.64000","36.72022","0.07884"
"441.00000","36.75024","0.07860"
"441.36000","36.78019","0.07846"
"441.72000","36.81020","0.07839"
"442.08000","36.84022","0.07954"
"442.44000","36.87017","0.07957"
"442.80000","36.90025","0.07956"
"443.16000","36.93020","0.07956"
"443.52000","36.96021","0.07901"
"443.88000","36.99029","0.07933"
"444.24000","37.02024","0.07941"
"444.60000","37.05020","0.08015"
"444.96000","37.08027","0.08008"
"445.32000","37.11023","0.08037"
"445.68000","37.14018","0.08038"
"446.04000","37.17020","0.08057"
"446.40000","37.20021","0.08080"
"446.76000","37.23016","0.08105"
"447.12000","37.26024","0.08114"
"447.48000","37.29019","0.08161"
"447.84000","37.32015","0.08164"
"448.20000","37.35022","0.08222"
"448.56000","37.38018","0.08239"
"448.92000","37.41013","0.08271"
"449.28000","37.44021","0.08226"
"449.64000","37.47022","0.08263"
"450.00000","37.50024","0.08227"
"450.36000","37.53019","0.08235"
"450.72000","37.56020","0.08270"
"451.08000","37.59016","0.08246"
"451.44000","37.62023","0.08222"
"451.80000","37.65025","0.08257"
"452.16000","37.68020","0.08259"
"452.52000","37.71022","0.08271"
"452.88000","37.74023","0.08282"
"453.24000","37.77013","0.08279"
"453.60000","37.80020","0.08276"
"453.96000","37.83021","0.08276"
"454.32000","37.86011","0.08274"
"454.68000","37.89024","0.08277"
"455.04000","37.92025","0.08300"
"455.40000","37.95015","0.08358"
"455.76000","37.98016","0.08329"
"456.12000","38.01018","0.08330"
"456.48000","38.04013","0.08342"
"456.84000","38.07021","0.08323"
"457.20000","38.10022","0.08338"
"457.56000","38.13018","0.08349"
"457.92000","38.16019","0.08410"
"458.28000","38.19027","0.08400"
"458.64000","38.22016","0.08431"
"459.00000","38.25023","0.08319"
"459.36000","38.28025","0.08279"
"459.72000","38.31020","0.08299"
"460.08000","38.34022","0.08290"
"460.44000","38.37029","0.08328"
"460.80000","38.40019","0.08327"
"461.16000","38.43026","0.08369"
"461.52000","38.46021","0.08453"
"461.88000","38.49017","0.08475"
"462.24000","38.52018","0.08466"
"462.60000","38.55026","0.08499"
"462.96000","38.58015","0.08518"
"463.32000","38.61023","0.08540"
"463.68000","38.64024","0.08567"
"464.04000","38.67020","0.08578"
"464.40000","38.70021","0.08571"
"464.76000","38.73022","0.08654"
"465.12000","38.76018","0.08714"
"465.48000","38.79025","0.08758"
"465.84000","38.82021","0.08778"
"466.20000","38.85022","0.08799"
"466.56000","38.88018","0.08868"
"466.92000","38.91025","0.08883"
"467.28000","38.94015","0.08926"
"467.64000","38.97022","0.09038"
"468.00000","39.00024","0.09004"
"468.36000","39.03019","0.08999"
"468.72000","39.06014","0.08919"
"469.08000","39.09022","0.08461"
"469.44000","39.12017","0.08404"
"469.80000","39.15018","0.08440"
"470.16000","39.18020","0.08436"
"470.52000","39.21016","0.08540"
"470.88000","39.24017","0.08606"
"471.24000","39.27018","0.08568"
"471.60000","39.30014","0.08618"
"471.96000","39.33022","0.08680"
"472.32000","39.36023","0.08711"
"472.68000","39.39024","0.08783"
"473.04000","39.42020","0.08783"
"473.40000","39.45021","0.08861"
"473.76000","39.48016","0.08906"
"474.12000","39.51017","0.08871"
"474.48000","39.54020","0.08942"
"474.84000","39.57015","0.08978"
"475.20000","39.60022","0.08953"
"475.56000","39.63024","0.09066"
"475.92000","39.66019","0.09102"
"476.28000","39.69020","0.09179"
"476.64000","39.72022","0.09208"
"477.00000","39.75018","0.09311"
"477.36000","39.78019","0.09392"
"477.72000","39.81020","0.09464"
"478.08000","39.84021","0.09069"
"478.44000","39.87017","0.08867"
"478.80000","39.90025","0.08870"
"479.16000","39.93020","0.08783"
"479.52000","39.96015","0.08860"
"479.88000","39.99023","0.08835"
"480.24000","40.02018","0.08776"
"480.60000","40.05019","0.08897"
"480.96000","40.08027","0.08866"
"481.32000","40.11017","0.08963"
"481.68000","40.14018","0.08924"
"482.04000","40.17020","0.09013"
"482.40000","40.20021","0.09043"
"482.76000","40.23016","0.09191"
"483.12000","40.26024","0.09225"
"483.48000","40.29019","0.09217"
"483.84000","40.32020","0.09268"
"484.20000","40.35022","0.09337"
"484.56000","40.38018","0.09424"
"484.92000","40.41019","0.09496"
"485.28000","40.44027","0.09506"
"485.64000","40.47016","0.09598"
"486.00000","40.50017","0.09695"
"486.36000","40.53019","0.09791"
"486.72000","40.56026","0.09798"
"487.08000","40.59016","0.09921"
"487.44000","40.62024","0.09947"
"487.80000","40.65024","0.10135"
"488.16000","40.68020","0.10132"
"488.52000","40.71021","0.10259"
"488.88000","40.74023","0.10352"
"489.24000","40.77018","0.10350"
"489.60000","40.80020","0.10455"
"489.96000","40.83015","0.10528"
"490.32000","40.86010","0.10634"
"490.68000","40.89024","0.10657"
"491.04000","40.92019","0.10706"
"491.40000","40.95021","0.10733"
"491.76000","40.98022","0.10766"
"492.12000","41.01018","0.10833"
"492.48000","41.04019","0.10822"
"492.84000","41.07027","0.10787"
"493.20000","41.10022","0.10766"
"493.56000","41.13018","0.10866"
"493.92000","41.16025","0.10918"
"494.28000","41.19020","0.10935"
"494.64000","41.22016","0.10968"
"495.00000","41.25024","0.11000"
"495.36000","41.28024","0.11046"
"495.72000","41.31020","0.11135"
"496.08000","41.34027","0.11167"
"496.44000","41.37023","0.11290"
"496.80000","41.40012","0.11339"
"497.16000","41.43026","0.11347"
"497.52000","41.46021","0.11335"
"497.88000","41.49017","0.11316"
"498.24000","41.52024","0.11288"
"498.60000","41.55020","0.11205"
"498.96000","41.58015","0.10767"
"499.32000","41.61023","0.10769"
"499.68000","41.64018","0.10488"
"500.04000","41.67020","0.10335"
"500.40000","41.70021","0.10279"
"500.76000","41.73022","0.10109"
"501.12000","41.76018","0.10162"
"501.48000","41.79020","0.10171"
"501.84000","41.82021","0.10269"
"502.20000","41.85022","0.10281"
"502.56000","41.88018","0.10397"
"502.92000","41.91025","0.10417"
"503.28000","41.94020","0.10403"
"503.64000","41.97022","0.10567"
"504.00000","42.00018","0.10498"
"504.36000","42.03012","0.10581"
"504.72000","42.06026","0.10649"
"505.08000","42.09021","0.10748"
"505.44000","42.12017","0.10727"
"505.80000","42.15025","0.10678"
"506.16000","42.18020","0.10745"
"506.52000","42.21015","0.10807"
"506.88000","42.24017","0.10691"
"507.24000","42.27024","0.10518"
"507.60000","42.30014","0.10661"
"507.96000","42.33027","0.10688"
"508.32000","42.36023","0.10852"
"508.68000","42.39012","0.10873"
"509.04000","42.42020","0.10841"
"509.40000","42.45027","0.10871"
"509.76000","42.48010","0.10903"
"510.12000","42.51024","0.10977"
"510.48000","42.54025","0.11043"
"510.84000","42.57020","0.11154"
"511.20000","42.60022","0.11279"
"511.56000","42.63029","0.11297"
"511.92000","42.66013","0.11234"
"512.28000","42.69020","0.11192"
"512.64000","42.72022","0.11146"
"513.00000","42.75017","0.11169"
"513.36000","42.78019","0.11159"
"513.72000","42.81026","0.11068"
"514.08000","42.84010","0.10666"
"514.44000","42.87023","0.10586"
"514.80000","42.90024","0.10693"
"515.16000","42.93014","0.10736"
"515.52000","42.96016","0.10897"
"515.88000","42.99023","0.11008"
"516.24000","43.02018","0.11085"
"516.60000","43.05026","0.11239"
"516.96000","43.08027","0.11311"
"517.32000","43.11017","0.11321"
"517.68000","43.14018","0.11436"
"518.04000","43.17020","0.11421"
"518.40000","43.20015","0.11471"
"518.76000","43.23022","0.11574"
"519.12000","43.26023","0.11694"
"519.48000","43.29013","0.11725"
"519.84000","43.32021","0.11607"
"520.20000","43.35022","0.11571"
"520.56000","43.38018","0.11388"
"520.92000","43.41013","0.11367"
"521.28000","43.44020","0.11403"
"521.64000","43.47015","0.11466"
"522.00000","43.50023","0.11567"
"522.36000","43.53019","0.11601"
"522.72000","43.56020","0.11512"
"523.08000","43.59016","0.11524"
"523.44000","43.62029","0.11450"
"523.80000","43.65012","0.11465"
"524.16000","43.68026","0.11441"
"524.52000","43.71016","0.11337"
"524.88000","43.74023","0.11388"
"525.24000","43.77018","0.11377"
"525.60000","43.80020","0.11423"
"525.96000","43.83015","0.11479"
"526.32000","43.86023","0.11533"
"526.68000","43.89018","0.11620"
"527.04000","43.92026","0.11721"
"527.40000","43.95021","0.11776"
"527.76000","43.98022","0.11784"
"528.12000","44.01018","0.11933"
"528.48000","44.04020","0.11946"
"528.84000","44.07021","0.12065"
"529.20000","44.10022","0.11925"
"529.56000","44.13018","0.12083"
"529.92000","44.16019","0.12096"
"530.28000","44.19020","0.12123"
"530.64000","44.22022","0.12180"
"531.00000","44.25018","0.12171"
"531.36000","44.28019","0.12339"
"531.72000","44.31020","0.12280"
"532.08000","44.34021","0.12403"
"532.44000","44.37017","0.12568"
"532.80000","44.40018","0.12589"
"533.16000","44.43026","0.12714"
"533.52000","44.46015","0.12785"
"533.88000","44.49017","0.12878"
"534.24000","44.52024","0.12661"
"534.60000","44.55014","0.12577"
"534.96000","44.58015","0.12688"
"535.32000","44.61017","0.12842"
"535.68000","44.64018","0.12984"
"536.04000","44.67020","0.13024"
"536.40000","44.70021","0.13055"
"536.76000","44.73016","0.13010"
"537.12000","44.76018","0.12983"
"537.48000","44.79019","0.13034"
"537.84000","44.82021","0.13070"
"538.20000","44.85016","0.12947"
"538.56000","44.88018","0.13061"
"538.92000","44.91019","0.13119"
"539.28000","44.94015","0.13214"
"539.33600","44.94481","0.13196"