File: Force_trajectories/170121_1/Specimen_RawData_6.csv
End date,"1/21/2017"
Specimen label,"19CG_45"
Maximum Load,"0.25120",N

Time,Extension,Load
(s),(mm),(N)
"0.00000","0.00006","0.00049"
"0.30600","0.02511","0.00225"
"0.61200","0.05124","0.00380"
"0.91800","0.07677","0.00584"
"1.22400","0.10224","0.00779"
"1.53000","0.12765","0.00906"
"1.83600","0.15324","0.01041"
"2.14200","0.17865","0.01213"
"2.44800","0.20418","0.01392"
"2.75400","0.22959","0.01532"
"3.06000","0.25518","0.01520"
"3.36600","0.28065","0.01631"
"3.67200","0.30618","0.01808"
"3.97800","0.33171","0.01913"
"4.28400","0.35712","0.01921"
"4.59000","0.38265","0.01972"
"4.89600","0.40812","0.02017"
"5.20200","0.43371","0.02099"
"5.50800","0.45912","0.02097"
"5.81400","0.48465","0.02139"
"6.12000","0.51018","0.02238"
"6.42600","0.53571","0.02280"
"6.73200","0.56124","0.02277"
"7.03800","0.58665","0.02370"
"7.34400","0.61219","0.02340"
"7.65000","0.63766","0.02316"
"7.95600","0.66313","0.02342"
"8.26200","0.68872","0.02394"
"8.56800","0.71419","0.02414"
"8.87400","0.73972","0.02428"
"9.18000","0.76513","0.02488"
"9.48600","0.79066","0.02448"
"9.79200","0.81619","0.02509"
"10.09800","0.84166","0.02480"
"10.40400","0.86719","0.02552"
"10.71000","0.89266","0.02529"
"11.01600","0.91825","0.02539"
"11.32200","0.94366","0.02581"
"11.62800","0.96925","0.02596"
"11.93400","0.99466","0.02618"
"12.24000","1.02019","0.02592"
"12.54600","1.04566","0.02598"
"12.85200","1.07113","0.02582"
"13.15800","1.09666","0.02640"
"13.46400","1.12213","0.02636"
"13.77000","1.14772","0.02674"
"14.07600","1.17319","0.02681"
"14.38200","1.19872","0.02665"
"14.68800","1.22419","0.02684"
"14.99400","1.24966","0.02705"
"15.30000","1.27519","0.02756"
"15.60600","1.30066","0.02745"
"15.91200","1.32625","0.02742"
"16.21800","1.35166","0.02755"
"16.52400","1.37713","0.02723"
"16.83000","1.40266","0.02703"
"17.13600","1.42819","0.02765"
"17.44200","1.45366","0.02736"
"17.74800","1.47907","0.02703"
"18.05400","1.50472","0.02736"
"18.36000","1.53019","0.02787"
"18.66600","1.55566","0.02729"
"18.97200","1.58119","0.02757"
"19.27800","1.60666","0.02773"
"19.58400","1.63219","0.02775"
"19.89000","1.65766","0.02759"
"20.19600","1.68319","0.02800"
"20.50200","1.70867","0.02725"
"20.80800","1.73420","0.02790"
"21.11400","1.75967","0.02782"
"21.42000","1.78520","0.02783"
"21.72600","1.81067","0.02736"
"22.03200","1.83614","0.02782"
"22.33800","1.86173","0.02786"
"22.64400","1.88720","0.02796"
"22.95000","1.91273","0.02803"
"23.25600","1.93820","0.02814"
"23.56200","1.96367","0.02766"
"23.86800","1.98914","0.02765"
"24.17400","2.01461","0.02841"
"24.48000","2.04014","0.02772"
"24.78600","2.06567","0.02787"
"25.09200","2.09120","0.02811"
"25.39800","2.11667","0.02822"
"25.70400","2.14208","0.02789"
"26.01000","2.16767","0.02781"
"26.31600","2.19314","0.02828"
"26.62200","2.21867","0.02780"
"26.92800","2.24414","0.02836"
"27.23400","2.26973","0.02783"
"27.54000","2.29520","0.02835"
"27.84600","2.32067","0.02782"
"28.15200","2.34614","0.02826"
"28.45800","2.37161","0.02799"
"28.76400","2.39720","0.02825"
"29.07000","2.42261","0.02828"
"29.37600","2.44820","0.02820"
"29.68200","2.47367","0.02800"
"29.98800","2.49920","0.02778"
"30.29400","2.52467","0.02829"
"30.60000","2.55014","0.02842"
"30.90600","2.57567","0.02838"
"31.21200","2.60114","0.02845"
"31.51800","2.62667","0.02822"
"31.82400","2.65220","0.02834"
"32.13000","2.67773","0.02822"
"32.43600","2.70314","0.02783"
"32.74200","2.72867","0.02827"
"33.04800","2.75414","0.02821"
"33.35400","2.77962","0.02834"
"33.66000","2.80515","0.02837"
"33.96600","2.83068","0.02833"
"34.27200","2.85615","0.02821"
"34.57800","2.88168","0.02828"
"34.88400","2.90721","0.02807"
"35.19000","2.93268","0.02828"
"35.49600","2.95815","0.02813"
"35.80200","2.98368","0.02795"
"36.10800","3.00915","0.02803"
"36.41400","3.03474","0.02857"
"36.72000","3.06015","0.02877"
"37.02600","3.08574","0.02820"
"37.33200","3.11121","0.02868"
"37.63800","3.13668","0.02837"
"37.94400","3.16221","0.02862"
"38.25000","3.18762","0.02841"
"38.55600","3.21321","0.02853"
"38.86200","3.23868","0.02865"
"39.16800","3.26421","0.02810"
"39.47400","3.28968","0.02821"
"39.78000","3.31515","0.02844"
"40.08600","3.34062","0.02820"
"40.39200","3.36615","0.02857"
"40.69800","3.39168","0.02870"
"41.00400","3.41721","0.02866"
"41.31000","3.44268","0.02852"
"41.61600","3.46815","0.02871"
"41.92200","3.49368","0.02840"
"42.22800","3.51921","0.02856"
"42.53400","3.54462","0.02864"
"42.84000","3.57015","0.02878"
"43.14600","3.59562","0.02821"
"43.45200","3.62121","0.02808"
"43.75800","3.64668","0.02864"
"44.06400","3.67215","0.02844"
"44.37000","3.69768","0.02853"
"44.67600","3.72309","0.02840"
"44.98200","3.74868","0.02870"
"45.28800","3.77415","0.02892"
"45.59400","3.79968","0.02859"
"45.90000","3.82515","0.02877"
"46.20600","3.85069","0.02848"
"46.51200","3.87622","0.02871"
"46.81800","3.90163","0.02860"
"47.12400","3.92716","0.02889"
"47.43000","3.95263","0.02879"
"47.73600","3.97822","0.02865"
"48.04200","4.00369","0.02852"
"48.34800","4.02922","0.02884"
"48.65400","4.05469","0.02864"
"48.96000","4.08016","0.02884"
"49.26600","4.10569","0.02869"
"49.57200","4.13116","0.02897"
"49.87800","4.15669","0.02862"
"50.18400","4.18222","0.02849"
"50.49000","4.20775","0.02876"
"50.79600","4.23322","0.02879"
"51.10200","4.25863","0.02876"
"51.40800","4.28416","0.02879"
"51.71400","4.30963","0.02904"
"52.02000","4.33522","0.02929"
"52.32600","4.36075","0.02891"
"52.63200","4.38622","0.02888"
"52.93800","4.41169","0.02935"
"53.24400","4.43716","0.02855"
"53.55000","4.46269","0.02867"
"53.85600","4.48810","0.02818"
"54.16200","4.51369","0.02889"
"54.46800","4.53916","0.02881"
"54.77400","4.56469","0.02867"
"55.08000","4.59022","0.02873"
"55.38600","4.61563","0.02892"
"55.69200","4.64116","0.02850"
"55.99800","4.66657","0.02826"
"56.30400","4.69222","0.02845"
"56.61000","4.71769","0.02895"
"56.91600","4.74322","0.02857"
"57.22200","4.76869","0.02866"
"57.52800","4.79416","0.02877"
"57.83400","4.81969","0.02831"
"58.14000","4.84510","0.02899"
"58.44600","4.87064","0.02846"
"58.75200","4.89616","0.02871"
"59.05800","4.92170","0.02884"
"59.36400","4.94723","0.02859"
"59.67000","4.97264","0.02902"
"59.97600","4.99817","0.02860"
"60.28200","5.02364","0.02868"
"60.58800","5.04917","0.02869"
"60.89400","5.07470","0.02828"
"61.20000","5.10023","0.02884"
"61.50600","5.12570","0.02891"
"61.81200","5.15117","0.02879"
"62.11800","5.17670","0.02875"
"62.42400","5.20217","0.02836"
"62.73000","5.22776","0.02849"
"63.03600","5.25317","0.02860"
"63.34200","5.27870","0.02872"
"63.64800","5.30417","0.02875"
"63.95400","5.32964","0.02850"
"64.26000","5.35517","0.02896"
"64.56600","5.38064","0.02916"
"64.87200","5.40623","0.02901"
"65.17800","5.43170","0.02897"
"65.48400","5.45723","0.02900"
"65.79000","5.48270","0.02858"
"66.09600","5.50817","0.02891"
"66.40200","5.53370","0.02913"
"66.70800","5.55917","0.02889"
"67.01400","5.58470","0.02883"
"67.32000","5.61011","0.02871"
"67.62600","5.63564","0.02904"
"67.93200","5.66117","0.02938"
"68.23800","5.68664","0.02871"
"68.54400","5.71211","0.02858"
"68.85000","5.73764","0.02895"
"69.15600","5.76317","0.02860"
"69.46200","5.78864","0.02903"
"69.76800","5.81417","0.02919"
"70.07400","5.83970","0.02883"
"70.38000","5.86511","0.02885"
"70.68600","5.89064","0.02878"
"70.99200","5.91617","0.02891"
"71.29800","5.94170","0.02893"
"71.60400","5.96711","0.02899"
"71.91000","5.99270","0.02893"
"72.21600","6.01817","0.02890"
"72.52200","6.04365","0.02864"
"72.82800","6.06912","0.02864"
"73.13400","6.09465","0.02915"
"73.44000","6.12024","0.02874"
"73.74600","6.14565","0.02883"
"74.05200","6.17118","0.02895"
"74.35800","6.19671","0.02911"
"74.66400","6.22218","0.02907"
"74.97000","6.24771","0.02889"
"75.27600","6.27318","0.02903"
"75.58200","6.29871","0.02940"
"75.88800","6.32418","0.02918"
"76.19400","6.34977","0.02927"
"76.50000","6.37512","0.02906"
"76.80600","6.40059","0.02911"
"77.11200","6.42618","0.02897"
"77.41800","6.45165","0.02905"
"77.72400","6.47718","0.02943"
"78.03000","6.50259","0.02878"
"78.33600","6.52818","0.02903"
"78.64200","6.55371","0.02906"
"78.94800","6.57918","0.02931"
"79.25400","6.60471","0.02930"
"79.56000","6.63012","0.02950"
"79.86600","6.65571","0.02939"
"80.17200","6.68118","0.02937"
"80.47800","6.70671","0.02895"
"80.78400","6.73218","0.02902"
"81.09000","6.75771","0.02851"
"81.39600","6.78312","0.02936"
"81.70200","6.80865","0.02922"
"82.00800","6.83418","0.02948"
"82.31400","6.85965","0.02934"
"82.62000","6.88524","0.02947"
"82.92600","6.91065","0.02929"
"83.23200","6.93618","0.02918"
"83.53800","6.96165","0.02864"
"83.84400","6.98718","0.02895"
"84.15000","7.01271","0.02870"
"84.45600","7.03813","0.02934"
"84.76200","7.06371","0.02914"
"85.06800","7.08919","0.02929"
"85.37400","7.11466","0.02909"
"85.68000","7.14019","0.02902"
"85.98600","7.16566","0.02913"
"86.29200","7.19119","0.02871"
"86.59800","7.21666","0.02926"
"86.90400","7.24219","0.02901"
"87.21000","7.26766","0.02870"
"87.51600","7.29319","0.02952"
"87.82200","7.31872","0.02872"
"88.12800","7.34419","0.02927"
"88.43400","7.36972","0.02882"
"88.74000","7.39513","0.02885"
"89.04600","7.42072","0.02879"
"89.35200","7.44613","0.02875"
"89.65800","7.47166","0.02893"
"89.96400","7.49713","0.02920"
"90.27000","7.52266","0.02903"
"90.57600","7.54819","0.02956"
"90.88200","7.57366","0.02909"
"91.18800","7.59913","0.02920"
"91.49400","7.62466","0.02860"
"91.80000","7.65025","0.02889"
"92.10600","7.67566","0.02927"
"92.41200","7.70119","0.02886"
"92.71800","7.72672","0.02896"
"93.02400","7.75219","0.02892"
"93.33000","7.77772","0.02904"
"93.63600","7.80319","0.02912"
"93.94200","7.82866","0.02888"
"94.24800","7.85419","0.02900"
"94.55400","7.87966","0.02896"
"94.86000","7.90513","0.02914"
"95.16600","7.93066","0.02928"
"95.47200","7.95619","0.02875"
"95.77800","7.98160","0.02912"
"96.08400","8.00719","0.02917"
"96.39000","8.03266","0.02905"
"96.69600","8.05825","0.02898"
"97.00200","8.08366","0.02916"
"97.30800","8.10919","0.02945"
"97.61400","8.13472","0.02928"
"97.92000","8.16013","0.02909"
"98.22600","8.18567","0.02927"
"98.53200","8.21114","0.02861"
"98.83800","8.23667","0.02924"
"99.14400","8.26220","0.02932"
"99.45000","8.28767","0.02912"
"99.75600","8.31320","0.02920"
"100.06200","8.33867","0.02954"
"100.36800","8.36414","0.02871"
"100.67400","8.38961","0.02945"
"100.98000","8.41520","0.02924"
"101.28600","8.44067","0.02940"
"101.59200","8.46620","0.02930"
"101.89800","8.49167","0.02911"
"102.20400","8.51714","0.02915"
"102.51000","8.54267","0.02904"
"102.81600","8.56808","0.02906"
"103.12200","8.59367","0.02925"
"103.42800","8.61920","0.02927"
"103.73400","8.64467","0.02933"
"104.04000","8.67020","0.02903"
"104.34600","8.69561","0.02943"
"104.65200","8.72114","0.02888"
"104.95800","8.74661","0.02923"
"105.26400","8.77220","0.02902"
"105.57000","8.79767","0.02954"
"105.87600","8.82320","0.02906"
"106.18200","8.84873","0.02914"
"106.48800","8.87414","0.02941"
"106.79400","8.89967","0.02940"
"107.10000","8.92508","0.02954"
"107.40600","8.95067","0.02937"
"107.71200","8.97614","0.02907"
"108.01800","9.00173","0.03006"
"108.32400","9.02720","0.02953"
"108.63000","9.05267","0.02950"
"108.93600","9.07814","0.02962"
"109.24200","9.10361","0.02936"
"109.54800","9.12914","0.02966"
"109.85400","9.15462","0.02989"
"110.16000","9.18014","0.02949"
"110.46600","9.20568","0.02934"
"110.77200","9.23120","0.02912"
"111.07800","9.25674","0.02970"
"111.38400","9.28215","0.02955"
"111.69000","9.30768","0.02956"
"111.99600","9.33315","0.02943"
"112.30200","9.35874","0.02947"
"112.60800","9.38421","0.02946"
"112.91400","9.40968","0.02927"
"113.22000","9.43521","0.02944"
"113.52600","9.46062","0.02968"
"113.83200","9.48621","0.02969"
"114.13800","9.51162","0.02995"
"114.44400","9.53715","0.02993"
"114.75000","9.56268","0.02924"
"115.05600","9.58821","0.02979"
"115.36200","9.61368","0.02957"
"115.66800","9.63915","0.02984"
"115.97400","9.66468","0.02937"
"116.28000","9.69009","0.02941"
"116.58600","9.71574","0.02904"
"116.89200","9.74115","0.02953"
"117.19800","9.76674","0.02950"
"117.50400","9.79221","0.03018"
"117.81000","9.81762","0.02970"
"118.11600","9.84315","0.02987"
"118.42200","9.86862","0.03003"
"118.72800","9.89415","0.03020"
"119.03400","9.91968","0.03019"
"119.34000","9.94521","0.02967"
"119.64600","9.97068","0.02982"
"119.95200","9.99615","0.02970"
"120.25800","10.02168","0.02983"
"120.56400","10.04715","0.02980"
"120.87000","10.07268","0.02965"
"121.17600","10.09821","0.02974"
"121.48200","10.12368","0.02948"
"121.78800","10.14921","0.02971"
"122.09400","10.17462","0.02956"
"122.40000","10.20021","0.02951"
"122.70600","10.22556","0.03022"
"123.01200","10.25121","0.03001"
"123.31800","10.27662","0.02981"
"123.62400","10.30216","0.02991"
"123.93000","10.32769","0.03002"
"124.23600","10.35316","0.02952"
"124.54200","10.37869","0.02979"
"124.84800","10.40416","0.02953"
"125.15400","10.42969","0.02955"
"125.46000","10.45516","0.02993"
"125.76600","10.48069","0.02980"
"126.07200","10.50616","0.02961"
"126.37800","10.53169","0.02995"
"126.68400","10.55728","0.03004"
"126.99000","10.58269","0.02963"
"127.29600","10.60816","0.02951"
"127.60200","10.63363","0.02965"
"127.90800","10.65916","0.02983"
"128.21400","10.68463","0.03008"
"128.52000","10.71016","0.02993"
"128.82600","10.73575","0.02937"
"129.13200","10.76116","0.02950"
"129.43800","10.78669","0.02996"
"129.74400","10.81216","0.02956"
"130.05000","10.83769","0.02981"
"130.35600","10.86322","0.02967"
"130.66200","10.88863","0.03059"
"130.96800","10.91422","0.02985"
"131.27400","10.93963","0.02965"
"131.58000","10.96522","0.02991"
"131.88600","10.99057","0.02994"
"132.19200","11.01616","0.03004"
"132.49800","11.04163","0.03001"
"132.80400","11.06716","0.02999"
"133.11000","11.09269","0.02983"
"133.41600","11.11816","0.02953"
"133.72200","11.14369","0.02972"
"134.02800","11.16916","0.03019"
"134.33400","11.19469","0.02957"
"134.64000","11.22016","0.02980"
"134.94600","11.24563","0.02977"
"135.25200","11.27116","0.03003"
"135.55800","11.29669","0.03029"
"135.86400","11.32222","0.03015"
"136.17000","11.34770","0.02996"
"136.47600","11.37322","0.03005"
"136.78200","11.39863","0.03010"
"137.08800","11.42417","0.03033"
"137.39400","11.44969","0.03001"
"137.70000","11.47517","0.03028"
"138.00600","11.50070","0.02998"
"138.31200","11.52611","0.03049"
"138.61800","11.55170","0.03038"
"138.92400","11.57717","0.03009"
"139.23000","11.60270","0.03003"
"139.53600","11.62817","0.03030"
"139.84200","11.65364","0.02989"
"140.14800","11.67923","0.03018"
"140.45400","11.70464","0.03018"
"140.76000","11.73023","0.03033"
"141.06600","11.75564","0.03026"
"141.37200","11.78117","0.03063"
"141.67800","11.80664","0.02990"
"141.98400","11.83211","0.03033"
"142.29000","11.85770","0.03018"
"142.59600","11.88317","0.03007"
"142.90200","11.90870","0.03051"
"143.20800","11.93417","0.03020"
"143.51400","11.95970","0.03047"
"143.82000","11.98517","0.03013"
"144.12600","12.01064","0.03085"
"144.43200","12.03623","0.03014"
"144.73800","12.06170","0.03047"
"145.04400","12.08723","0.03040"
"145.35000","12.11264","0.03079"
"145.65600","12.13817","0.03053"
"145.96200","12.16364","0.03038"
"146.26800","12.18917","0.03024"
"146.57400","12.21470","0.03040"
"146.88000","12.24011","0.03028"
"147.18600","12.26570","0.03072"
"147.49200","12.29117","0.03089"
"147.79800","12.31664","0.03053"
"148.10400","12.34217","0.03094"
"148.41000","12.36764","0.03030"
"148.71600","12.39318","0.03111"
"149.02200","12.41865","0.03063"
"149.32800","12.44423","0.03093"
"149.63400","12.46971","0.03044"
"149.94000","12.49518","0.03100"
"150.24600","12.52065","0.03100"
"150.55200","12.54618","0.03091"
"150.85800","12.57171","0.03136"
"151.16400","12.59712","0.03102"
"151.47000","12.62271","0.03104"
"151.77600","12.64812","0.03059"
"152.08200","12.67371","0.03064"
"152.38800","12.69918","0.03093"
"152.69400","12.72465","0.03086"
"153.00000","12.75012","0.03056"
"153.30600","12.77559","0.03088"
"153.61200","12.80118","0.03081"
"153.91800","12.82665","0.03103"
"154.22400","12.85218","0.03102"
"154.53000","12.87771","0.03108"
"154.83600","12.90318","0.03102"
"155.14200","12.92871","0.03088"
"155.44800","12.95418","0.03086"
"155.75400","12.97971","0.03070"
"156.06000","13.00512","0.03070"
"156.36600","13.03071","0.03058"
"156.67200","13.05618","0.03090"
"156.97800","13.08171","0.03084"
"157.28400","13.10718","0.03080"
"157.59000","13.13265","0.03111"
"157.89600","13.15824","0.03084"
"158.20200","13.18359","0.03107"
"158.50800","13.20924","0.03117"
"158.81400","13.23471","0.03129"
"159.12000","13.26024","0.03108"
"159.42600","13.28565","0.03116"
"159.73200","13.31118","0.03164"
"160.03800","13.33665","0.03118"
"160.34400","13.36212","0.03118"
"160.65000","13.38771","0.03127"
"160.95600","13.41318","0.03099"
"161.26200","13.43871","0.03116"
"161.56800","13.46419","0.03103"
"161.87400","13.48965","0.03090"
"162.18000","13.51519","0.03135"
"162.48600","13.54066","0.03089"
"162.79200","13.56612","0.03124"
"163.09800","13.59166","0.03111"
"163.40400","13.61719","0.03125"
"163.71000","13.64266","0.03131"
"164.01600","13.66819","0.03107"
"164.32200","13.69372","0.03147"
"164.62800","13.71913","0.03162"
"164.93400","13.74466","0.03141"
"165.24000","13.77013","0.03126"
"165.54600","13.79572","0.03132"
"165.85200","13.82119","0.03190"
"166.15800","13.84666","0.03149"
"166.46400","13.87219","0.03189"
"166.77000","13.89772","0.03179"
"167.07600","13.92325","0.03201"
"167.38200","13.94860","0.03178"
"167.68800","13.97419","0.03149"
"167.99400","13.99966","0.03222"
"168.30000","14.02519","0.03164"
"168.60600","14.05066","0.03198"
"168.91200","14.07613","0.03164"
"169.21800","14.10166","0.03129"
"169.52400","14.12713","0.03261"
"169.83000","14.15272","0.03175"
"170.13600","14.17819","0.03185"
"170.44200","14.20372","0.03184"
"170.74800","14.22913","0.03156"
"171.05400","14.25466","0.03229"
"171.36000","14.28019","0.03220"
"171.66600","14.30560","0.03217"
"171.97200","14.33113","0.03212"
"172.27800","14.35666","0.03210"
"172.58400","14.38219","0.03244"
"172.89000","14.40772","0.03180"
"173.19600","14.43319","0.03204"
"173.50200","14.45872","0.03254"
"173.80800","14.48407","0.03236"
"174.11400","14.50966","0.03232"
"174.42000","14.53513","0.03279"
"174.72600","14.56073","0.03231"
"175.03200","14.58619","0.03231"
"175.33800","14.61166","0.03274"
"175.64400","14.63720","0.03259"
"175.95000","14.66267","0.03492"
"176.25600","14.68820","0.03373"
"176.56200","14.71361","0.03215"
"176.86800","14.73920","0.03232"
"177.17400","14.76467","0.03240"
"177.48000","14.79020","0.03204"
"177.78600","14.81573","0.03202"
"178.09200","14.84114","0.03301"
"178.39800","14.86667","0.03173"
"178.70400","14.89214","0.03179"
"179.01000","14.91761","0.03172"
"179.31600","14.94314","0.03163"
"179.62200","14.96873","0.03196"
"179.92800","14.99426","0.03217"
"180.23400","15.01967","0.03224"
"180.54000","15.04520","0.03251"
"180.84600","15.07067","0.03211"
"181.15200","15.09620","0.03246"
"181.45800","15.12167","0.03238"
"181.76400","15.14720","0.03263"
"182.07000","15.17273","0.03275"
"182.37600","15.19814","0.03251"
"182.68200","15.22367","0.03245"
"182.98800","15.24914","0.03227"
"183.29400","15.27467","0.03168"
"183.60000","15.30014","0.03178"
"183.90600","15.32567","0.03219"
"184.21200","15.35120","0.03170"
"184.51800","15.37667","0.03170"
"184.82400","15.40220","0.03131"
"185.13000","15.42761","0.03054"
"185.43600","15.45314","0.03095"
"185.74200","15.47861","0.03121"
"186.04800","15.50420","0.03076"
"186.35400","15.52967","0.03087"
"186.66000","15.55515","0.03117"
"186.96600","15.58073","0.03095"
"187.27200","15.60614","0.03124"
"187.57800","15.63167","0.03117"
"187.88400","15.65714","0.03115"
"188.19000","15.68268","0.03104"
"188.49600","15.70820","0.03156"
"188.80200","15.73367","0.03117"
"189.10800","15.75921","0.03127"
"189.41400","15.78468","0.03126"
"189.72000","15.81021","0.03156"
"190.02600","15.83568","0.03137"
"190.33200","15.86121","0.03156"
"190.63800","15.88674","0.03166"
"190.94400","15.91215","0.03171"
"191.25000","15.93774","0.03111"
"191.55600","15.96315","0.03202"
"191.86200","15.98868","0.03181"
"192.16800","16.01415","0.03179"
"192.47400","16.03968","0.03181"
"192.78000","16.06515","0.03221"
"193.08600","16.09068","0.03237"
"193.39200","16.11621","0.03155"
"193.69800","16.14168","0.03244"
"194.00400","16.16715","0.03190"
"194.31000","16.19268","0.03185"
"194.61600","16.21827","0.03181"
"194.92200","16.24368","0.03220"
"195.22800","16.26915","0.03208"
"195.53400","16.29474","0.03245"
"195.84000","16.32015","0.03206"
"196.14600","16.34568","0.03216"
"196.45200","16.37109","0.03186"
"196.75800","16.39668","0.03202"
"197.06400","16.42215","0.03196"
"197.37000","16.44762","0.03237"
"197.67600","16.47315","0.03215"
"197.98200","16.49868","0.03232"
"198.28800","16.52421","0.03220"
"198.59400","16.54968","0.03193"
"198.90000","16.57515","0.03213"
"199.20600","16.60068","0.03273"
"199.51200","16.62615","0.03218"
"199.81800","16.65168","0.03256"
"200.12400","16.67715","0.03244"
"200.43000","16.70274","0.03230"
"200.73600","16.72816","0.03280"
"201.04200","16.75368","0.03233"
"201.34800","16.77915","0.03280"
"201.65400","16.80469","0.03268"
"201.96000","16.83016","0.03242"
"202.26600","16.85563","0.03280"
"202.57200","16.88122","0.03271"
"202.87800","16.90669","0.03304"
"203.18400","16.93221","0.03310"
"203.49000","16.95769","0.03276"
"203.79600","16.98316","0.03270"
"204.10200","17.00869","0.03274"
"204.40800","17.03416","0.03284"
"204.71400","17.05969","0.03257"
"205.02000","17.08516","0.03264"
"205.32600","17.11075","0.03277"
"205.63200","17.13616","0.03272"
"205.93800","17.16169","0.03305"
"206.24400","17.18716","0.03301"
"206.55000","17.21263","0.03314"
"206.85600","17.23816","0.03327"
"207.16200","17.26357","0.03293"
"207.46800","17.28922","0.03349"
"207.77400","17.31469","0.03349"
"208.08000","17.34022","0.03319"
"208.38600","17.36569","0.03337"
"208.69200","17.39116","0.03312"
"208.99800","17.41669","0.03344"
"209.30400","17.44216","0.03355"
"209.61000","17.46775","0.03363"
"209.91600","17.49316","0.03365"
"210.22200","17.51869","0.03364"
"210.52800","17.54416","0.03384"
"210.83400","17.56969","0.03373"
"211.14000","17.59516","0.03359"
"211.44600","17.62063","0.03359"
"211.75200","17.64616","0.03323"
"212.05800","17.67163","0.03360"
"212.36400","17.69716","0.03414"
"212.67000","17.72264","0.03454"
"212.97600","17.74816","0.03391"
"213.28200","17.77369","0.03409"
"213.58800","17.79917","0.03361"
"213.89400","17.82463","0.03437"
"214.20000","17.85016","0.03379"
"214.50600","17.87570","0.03431"
"214.81200","17.90117","0.03416"
"215.11800","17.92664","0.03401"
"215.42400","17.95217","0.03448"
"215.73000","17.97764","0.03456"
"216.03600","18.00317","0.03439"
"216.34200","18.02864","0.03422"
"216.64800","18.05417","0.03420"
"216.95400","18.07970","0.03426"
"217.26000","18.10517","0.03420"
"217.56600","18.13070","0.03479"
"217.87200","18.15617","0.03441"
"218.17800","18.18170","0.03434"
"218.48400","18.20717","0.03449"
"218.79000","18.23270","0.03443"
"219.09600","18.25817","0.03433"
"219.40200","18.28370","0.03423"
"219.70800","18.30917","0.03470"
"220.01400","18.33464","0.03463"
"220.32000","18.36017","0.03476"
"220.62600","18.38564","0.03447"
"220.93200","18.41117","0.03445"
"221.23800","18.43664","0.03470"
"221.54400","18.46217","0.03494"
"221.85000","18.48764","0.03427"
"222.15600","18.51317","0.03466"
"222.46200","18.53876","0.03503"
"222.76800","18.56417","0.03507"
"223.07400","18.58970","0.03577"
"223.38000","18.61517","0.03510"
"223.68600","18.64070","0.03524"
"223.99200","18.66617","0.03506"
"224.29800","18.69164","0.03448"
"224.60400","18.71717","0.03517"
"224.91000","18.74264","0.03557"
"225.21600","18.76818","0.03599"
"225.52200","18.79364","0.03496"
"225.82800","18.81923","0.03604"
"226.13400","18.84471","0.03568"
"226.44000","18.87017","0.03585"
"226.74600","18.89570","0.03560"
"227.05200","18.92118","0.03621"
"227.35800","18.94665","0.03597"
"227.66400","18.97212","0.03558"
"227.97000","18.99771","0.03610"
"228.27600","19.02318","0.03650"
"228.58200","19.04871","0.03592"
"228.88800","19.07418","0.03557"
"229.19400","19.09965","0.03634"
"229.50000","19.12518","0.03684"
"229.80600","19.15059","0.03701"
"230.11200","19.17618","0.03621"
"230.41800","19.20165","0.03705"
"230.72400","19.22718","0.03754"
"231.03000","19.25271","0.03756"
"231.33600","19.27812","0.03755"
"231.64200","19.30371","0.03747"
"231.94800","19.32912","0.03841"
"232.25400","19.35471","0.03704"
"232.56000","19.38018","0.03788"
"232.86600","19.40571","0.03822"
"233.17200","19.43124","0.03830"
"233.47800","19.45665","0.03799"
"233.78400","19.48218","0.03859"
"234.09000","19.50759","0.03897"
"234.39600","19.53318","0.03875"
"234.70200","19.55865","0.03883"
"235.00800","19.58418","0.03913"
"235.31400","19.60971","0.03863"
"235.62000","19.63512","0.03952"
"235.92600","19.66071","0.03864"
"236.23200","19.68612","0.03694"
"236.53800","19.71165","0.03581"
"236.84400","19.73712","0.03728"
"237.15000","19.76271","0.03757"
"237.45600","19.78818","0.03732"
"237.76200","19.81365","0.03762"
"238.06800","19.83912","0.03763"
"238.37400","19.86459","0.03797"
"238.68000","19.89018","0.03790"
"238.98600","19.91560","0.03815"
"239.29200","19.94118","0.03881"
"239.59800","19.96665","0.03837"
"239.90400","19.99218","0.03828"
"240.21000","20.01772","0.03819"
"240.51600","20.04313","0.03853"
"240.82200","20.06866","0.03893"
"241.12800","20.09412","0.03892"
"241.43400","20.11971","0.03922"
"241.74000","20.14519","0.03836"
"242.04600","20.17072","0.03941"
"242.35200","20.19624","0.03928"
"242.65800","20.22166","0.03944"
"242.96400","20.24719","0.03940"
"243.27000","20.27260","0.03969"
"243.57600","20.29819","0.03998"
"243.88200","20.32366","0.04021"
"244.18800","20.34919","0.04011"
"244.49400","20.37472","0.04041"
"244.80000","20.40013","0.04074"
"245.10600","20.42566","0.04102"
"245.41200","20.45107","0.04085"
"245.71800","20.47672","0.04147"
"246.02400","20.50213","0.04138"
"246.33000","20.52772","0.04092"
"246.63600","20.55319","0.04133"
"246.94200","20.57866","0.04146"
"247.24800","20.60413","0.04283"
"247.55400","20.62960","0.04197"
"247.86000","20.65519","0.04198"
"248.16600","20.68066","0.04300"
"248.47200","20.70619","0.04319"
"248.77800","20.73172","0.04324"
"249.08400","20.75713","0.04341"
"249.39000","20.78272","0.04310"
"249.69600","20.80813","0.04280"
"250.00200","20.83366","0.04427"
"250.30800","20.85913","0.04365"
"250.61400","20.88466","0.04365"
"250.92000","20.91019","0.04111"
"251.22600","20.93566","0.04253"
"251.53200","20.96119","0.04029"
"251.83800","20.98660","0.03805"
"252.14400","21.01219","0.03796"
"252.45000","21.03766","0.03797"
"252.75600","21.06319","0.03894"
"253.06200","21.08867","0.03729"
"253.36800","21.11414","0.03907"
"253.67400","21.13973","0.03827"
"253.98000","21.16520","0.03886"
"254.28600","21.19066","0.03828"
"254.59200","21.21614","0.03892"
"254.89800","21.24173","0.03919"
"255.20400","21.26720","0.04006"
"255.51000","21.29267","0.03965"
"255.81600","21.31820","0.03936"
"256.12200","21.34367","0.04000"
"256.42800","21.36920","0.03963"
"256.73400","21.39467","0.04015"
"257.04000","21.42020","0.04003"
"257.34600","21.44567","0.04023"
"257.65200","21.47114","0.04073"
"257.95800","21.49673","0.04116"
"258.26400","21.52220","0.04127"
"258.57000","21.54767","0.04087"
"258.87600","21.57314","0.04116"
"259.18200","21.59873","0.04089"
"259.48800","21.62420","0.04157"
"259.79400","21.64967","0.04214"
"260.10000","21.67514","0.04152"
"260.40600","21.70061","0.04160"
"260.71200","21.72620","0.04135"
"261.01800","21.75161","0.04122"
"261.32400","21.77720","0.03976"
"261.63000","21.80261","0.04040"
"261.93600","21.82814","0.03929"
"262.24200","21.85367","0.03959"
"262.54800","21.87914","0.04065"
"262.85400","21.90473","0.04021"
"263.16000","21.93014","0.04056"
"263.46600","21.95567","0.03986"
"263.77200","21.98114","0.04162"
"264.07800","22.00667","0.04143"
"264.38400","22.03221","0.04125"
"264.69000","22.05767","0.04106"
"264.99600","22.08320","0.04152"
"265.30200","22.10868","0.04101"
"265.60800","22.13420","0.04153"
"265.91400","22.15968","0.04136"
"266.22000","22.18515","0.04079"
"266.52600","22.21068","0.04194"
"266.83200","22.23615","0.04218"
"267.13800","22.26174","0.04164"
"267.44400","22.28715","0.04119"
"267.75000","22.31268","0.04020"
"268.05600","22.33815","0.03987"
"268.36200","22.36368","0.03953"
"268.66800","22.38914","0.04014"
"268.97400","22.41462","0.04053"
"269.28000","22.44021","0.04070"
"269.58600","22.46568","0.04015"
"269.89200","22.49121","0.04089"
"270.19800","22.51668","0.04156"
"270.50400","22.54221","0.04016"
"270.81000","22.56762","0.04129"
"271.11600","22.59315","0.04087"
"271.42200","22.61868","0.04112"
"271.72800","22.64415","0.03973"
"272.03400","22.66968","0.03742"
"272.34000","22.69515","0.03919"
"272.64600","22.72074","0.03658"
"272.95200","22.74615","0.03807"
"273.25800","22.77168","0.03780"
"273.56400","22.79721","0.03804"
"273.87000","22.82268","0.03904"
"274.17600","22.84821","0.03830"
"274.48200","22.87368","0.03888"
"274.78800","22.89915","0.03935"
"275.09400","22.92462","0.03870"
"275.40000","22.95015","0.03865"
"275.70600","22.97568","0.03944"
"276.01200","23.00109","0.03910"
"276.31800","23.02668","0.03987"
"276.62400","23.05215","0.04019"
"276.93000","23.07768","0.03992"
"277.23600","23.10315","0.04069"
"277.54200","23.12868","0.04046"
"277.84800","23.15421","0.04039"
"278.15400","23.17962","0.04053"
"278.46000","23.20522","0.04019"
"278.76600","23.23068","0.04072"
"279.07200","23.25622","0.04101"
"279.37800","23.28169","0.04222"
"279.68400","23.30721","0.04124"
"279.99000","23.33269","0.04138"
"280.29600","23.35816","0.04086"
"280.60200","23.38363","0.04105"
"280.90800","23.40910","0.04185"
"281.21400","23.43468","0.04237"
"281.52000","23.46022","0.04119"
"281.82600","23.48575","0.03365"
"282.13200","23.51116","0.03401"
"282.43800","23.53663","0.03493"
"282.74400","23.56216","0.03387"
"283.05000","23.58769","0.03489"
"283.35600","23.61316","0.03473"
"283.66200","23.63863","0.03386"
"283.96800","23.66422","0.03556"
"284.27400","23.68969","0.03386"
"284.58000","23.71516","0.03546"
"284.88600","23.74069","0.03470"
"285.19200","23.76616","0.03466"
"285.49800","23.79169","0.03464"
"285.80400","23.81716","0.03542"
"286.11000","23.84269","0.03435"
"286.41600","23.86816","0.03536"
"286.72200","23.89369","0.03586"
"287.02800","23.91922","0.03515"
"287.33400","23.94463","0.03569"
"287.64000","23.97016","0.03586"
"287.94600","23.99563","0.03612"
"288.25200","24.02122","0.03619"
"288.55800","24.04663","0.03613"
"288.86400","24.07216","0.03665"
"289.17000","24.09769","0.03654"
"289.47600","24.12316","0.03601"
"289.78200","24.14863","0.03675"
"290.08800","24.17410","0.03744"
"290.39400","24.19969","0.03720"
"290.70000","24.22516","0.03721"
"291.00600","24.25069","0.03690"
"291.31200","24.27622","0.03665"
"291.61800","24.30170","0.03723"
"291.92400","24.32717","0.03773"
"292.23000","24.35263","0.03768"
"292.53600","24.37817","0.03733"
"292.84200","24.40370","0.03801"
"293.14800","24.42922","0.03795"
"293.45400","24.45476","0.03753"
"293.76000","24.48017","0.03801"
"294.06600","24.50564","0.03549"
"294.37200","24.53111","0.03483"
"294.67800","24.55670","0.03478"
"294.98400","24.58217","0.03474"
"295.29000","24.60770","0.03517"
"295.59600","24.63323","0.03524"
"295.90200","24.65864","0.03495"
"296.20800","24.68417","0.03537"
"296.51400","24.70958","0.03505"
"296.82000","24.73523","0.03563"
"297.12600","24.76070","0.03567"
"297.43200","24.78623","0.03620"
"297.73800","24.81170","0.03620"
"298.04400","24.83717","0.03651"
"298.35000","24.86264","0.03681"
"298.65600","24.88811","0.03697"
"298.96200","24.91364","0.03664"
"299.26800","24.93911","0.03694"
"299.57400","24.96470","0.03751"
"299.88000","24.99017","0.03690"
"300.18600","25.01564","0.03727"
"300.49200","25.04123","0.03717"
"300.79800","25.06664","0.03689"
"301.10400","25.09217","0.03728"
"301.41000","25.11764","0.03715"
"301.71600","25.14323","0.03738"
"302.02200","25.16870","0.03792"
"302.32800","25.19417","0.03784"
"302.63400","25.21970","0.03837"
"302.94000","25.24512","0.03941"
"303.24600","25.27065","0.03826"
"303.55200","25.29612","0.03770"
"303.85800","25.32170","0.03891"
"304.16400","25.34717","0.03852"
"304.47000","25.37271","0.03835"
"304.77600","25.39824","0.03888"
"305.08200","25.42365","0.03868"
"305.38800","25.44917","0.03938"
"305.69400","25.47459","0.03927"
"306.00000","25.50018","0.03961"
"306.30600","25.52565","0.03958"
"306.61200","25.55118","0.03927"
"306.91800","25.57671","0.03965"
"307.22400","25.60212","0.04007"
"307.53000","25.62771","0.03992"
"307.83600","25.65318","0.04027"
"308.14200","25.67871","0.04024"
"308.44800","25.70418","0.03961"
"308.75400","25.72971","0.04047"
"309.06000","25.75524","0.04014"
"309.36600","25.78065","0.04047"
"309.67200","25.80618","0.04035"
"309.97800","25.83165","0.04027"
"310.28400","25.85718","0.04042"
"310.59000","25.88265","0.04104"
"310.89600","25.90818","0.04071"
"311.20200","25.93371","0.04052"
"311.50800","25.95912","0.04134"
"311.81400","25.98471","0.04134"
"312.12000","26.01012","0.04203"
"312.42600","26.03565","0.04168"
"312.73200","26.06112","0.04239"
"313.03800","26.08671","0.04201"
"313.34400","26.11218","0.04220"
"313.65000","26.13765","0.04291"
"313.95600","26.16318","0.04287"
"314.26200","26.18859","0.04259"
"314.56800","26.21418","0.04336"
"314.87400","26.23959","0.04222"
"315.18000","26.26518","0.04355"
"315.48600","26.29071","0.04324"
"315.79200","26.31618","0.04352"
"316.09800","26.34171","0.04335"
"316.40400","26.36719","0.04423"
"316.71000","26.39266","0.04461"
"317.01600","26.41812","0.04482"
"317.32200","26.44366","0.04402"
"317.62800","26.46918","0.04355"
"317.93400","26.49466","0.04472"
"318.24000","26.52025","0.04445"
"318.54600","26.54572","0.04468"
"318.85200","26.57119","0.04470"
"319.15800","26.59666","0.04432"
"319.46400","26.62219","0.04408"
"319.77000","26.64766","0.04383"
"320.07600","26.67313","0.04467"
"320.38200","26.69872","0.04572"
"320.68800","26.72413","0.04471"
"320.99400","26.74972","0.04526"
"321.30000","26.77513","0.04590"
"321.60600","26.80072","0.04559"
"321.91200","26.82613","0.04604"
"322.21800","26.85166","0.04659"
"322.52400","26.87719","0.04693"
"322.83000","26.90266","0.04695"
"323.13600","26.92819","0.04692"
"323.44200","26.95366","0.04744"
"323.74800","26.97925","0.04717"
"324.05400","27.00466","0.04757"
"324.36000","27.03013","0.04785"
"324.66600","27.05572","0.04831"
"324.97200","27.08119","0.04777"
"325.27800","27.10672","0.04901"
"325.58400","27.13213","0.04905"
"325.89000","27.15766","0.04911"
"326.19600","27.18313","0.05007"
"326.50200","27.20860","0.04917"
"326.80800","27.23413","0.04916"
"327.11400","27.25960","0.04974"
"327.42000","27.28519","0.05021"
"327.72600","27.31066","0.04980"
"328.03200","27.33619","0.05072"
"328.33800","27.36166","0.05102"
"328.64400","27.38719","0.05108"
"328.95000","27.41273","0.05207"
"329.25600","27.43820","0.05185"
"329.56200","27.46372","0.05249"
"329.86800","27.48914","0.05236"
"330.17400","27.51472","0.05279"
"330.48000","27.54020","0.05279"
"330.78600","27.56567","0.05340"
"331.09200","27.59114","0.05332"
"331.39800","27.61667","0.05419"
"331.70400","27.64220","0.05409"
"332.01000","27.66761","0.05379"
"332.31600","27.69320","0.05552"
"332.62200","27.71867","0.05513"
"332.92800","27.74420","0.05546"
"333.23400","27.76967","0.05509"
"333.54000","27.79514","0.05625"
"333.84600","27.82067","0.05654"
"334.15200","27.84620","0.05641"
"334.45800","27.87173","0.05681"
"334.76400","27.89714","0.05663"
"335.07000","27.92267","0.05702"
"335.37600","27.94814","0.05730"
"335.68200","27.97367","0.05802"
"335.98800","27.99920","0.05820"
"336.29400","28.02461","0.05838"
"336.60000","28.05020","0.05837"
"336.90600","28.07567","0.05915"
"337.21200","28.10120","0.05950"
"337.51800","28.12667","0.05987"
"337.82400","28.15214","0.06024"
"338.13000","28.17767","0.05971"
"338.43600","28.20314","0.06052"
"338.74200","28.22873","0.06085"
"339.04800","28.25414","0.06067"
"339.35400","28.27967","0.06158"
"339.66000","28.30514","0.06082"
"339.96600","28.33068","0.06207"
"340.27200","28.35620","0.06210"
"340.57800","28.38167","0.06297"
"340.88400","28.40720","0.06240"
"341.19000","28.43262","0.06301"
"341.49600","28.45820","0.06332"
"341.80200","28.48367","0.06395"
"342.10800","28.50920","0.06381"
"342.41400","28.53467","0.06477"
"342.72000","28.56014","0.06441"
"343.02600","28.58568","0.06497"
"343.33200","28.61114","0.06576"
"343.63800","28.63668","0.06576"
"343.94400","28.66215","0.06628"
"344.25000","28.68768","0.06675"
"344.55600","28.71321","0.06719"
"344.86200","28.73862","0.06728"
"345.16800","28.76415","0.06846"
"345.47400","28.78962","0.06758"
"345.78000","28.81521","0.06841"
"346.08600","28.84068","0.06919"
"346.39200","28.86621","0.06952"
"346.69800","28.89174","0.06978"
"347.00400","28.91715","0.06900"
"347.31000","28.94268","0.06832"
"347.61600","28.96815","0.06915"
"347.92200","28.99368","0.06749"
"348.22800","29.01915","0.06833"
"348.53400","29.04474","0.07024"
"348.84000","29.07021","0.07118"
"349.14600","29.09568","0.07124"
"349.45200","29.12115","0.07158"
"349.75800","29.14662","0.07220"
"350.06400","29.17215","0.07273"
"350.37000","29.19762","0.07322"
"350.67600","29.22321","0.07396"
"350.98200","29.24868","0.07423"
"351.28800","29.27421","0.07435"
"351.59400","29.29974","0.07515"
"351.90000","29.32521","0.07509"
"352.20600","29.35068","0.07617"
"352.51200","29.37615","0.07644"
"352.81800","29.40168","0.07688"
"353.12400","29.42715","0.07768"
"353.43000","29.45268","0.07842"
"353.73600","29.47821","0.07873"
"354.04200","29.50362","0.07967"
"354.34800","29.52916","0.07953"
"354.65400","29.55457","0.08075"
"354.96000","29.58027","0.08039"
"355.26600","29.60568","0.08117"
"355.57200","29.63116","0.08166"
"355.87800","29.65668","0.08193"
"356.18400","29.68216","0.08245"
"356.49000","29.70769","0.08281"
"356.79600","29.73310","0.08338"
"357.10200","29.75869","0.08400"
"357.40800","29.78422","0.08462"
"357.71400","29.80969","0.08508"
"358.02000","29.83516","0.08540"
"358.32600","29.86069","0.08569"
"358.63200","29.88616","0.08564"
"358.93800","29.91163","0.08604"
"359.24400","29.93722","0.08622"
"359.55000","29.96269","0.08663"
"359.85600","29.98822","0.08703"
"360.16200","30.01369","0.08734"
"360.46800","30.03916","0.08772"
"360.77400","30.06469","0.08838"
"361.08000","30.09016","0.08877"
"361.38600","30.11569","0.08926"
"361.69200","30.14116","0.08952"
"361.99800","30.16669","0.08947"
"362.30400","30.19222","0.08963"
"362.61000","30.21769","0.09058"
"362.91600","30.24316","0.09059"
"363.22200","30.26857","0.09060"
"363.52800","30.29416","0.09102"
"363.83400","30.31963","0.09153"
"364.14000","30.34522","0.09153"
"364.44600","30.37069","0.09208"
"364.75200","30.39616","0.09214"
"365.05800","30.42169","0.09249"
"365.36400","30.44711","0.09283"
"365.67000","30.47269","0.09318"
"365.97600","30.49810","0.09306"
"366.28200","30.52369","0.09352"
"366.58800","30.54922","0.09383"
"366.89400","30.57469","0.06147"
"367.20000","30.60017","0.06388"
"367.50600","30.62563","0.03994"
"367.81200","30.65117","0.06147"
"368.11800","30.67664","0.04407"
"368.42400","30.70217","0.05670"
"368.73000","30.72764","0.04964"
"369.03600","30.75323","0.05329"
"369.34200","30.77876","0.05427"
"369.64800","30.80416","0.05079"
"369.95400","30.82964","0.05758"
"370.26000","30.85511","0.04999"
"370.56600","30.88064","0.05879"
"370.87200","30.90617","0.05246"
"371.17800","30.93170","0.05853"
"371.48400","30.95723","0.05577"
"371.79000","30.98264","0.05812"
"372.09600","31.00817","0.05863"
"372.40200","31.03364","0.05665"
"372.70800","31.05923","0.05953"
"373.01400","31.08464","0.05782"
"373.32000","31.11017","0.05969"
"373.62600","31.13570","0.05935"
"373.93200","31.16117","0.06112"
"374.23800","31.18670","0.06025"
"374.54400","31.21211","0.06268"
"374.85000","31.23770","0.06080"
"375.15600","31.26311","0.06324"
"375.46200","31.28870","0.06248"
"375.76800","31.31423","0.06311"
"376.07400","31.33964","0.06440"
"376.38000","31.36517","0.06319"
"376.68600","31.39064","0.06562"
"376.99200","31.41617","0.06438"
"377.29800","31.44164","0.06639"
"377.60400","31.46717","0.06607"
"377.91000","31.49264","0.06646"
"378.21600","31.51811","0.06724"
"378.52200","31.54370","0.06756"
"378.82800","31.56917","0.06904"
"379.13400","31.59470","0.06881"
"379.44000","31.62011","0.06993"
"379.74600","31.64570","0.07027"
"380.05200","31.67117","0.07123"
"380.35800","31.69670","0.07126"
"380.66400","31.72223","0.07254"
"380.97000","31.74764","0.07314"
"381.27600","31.77317","0.07347"
"381.58200","31.79864","0.07479"
"381.88800","31.82417","0.07450"
"382.19400","31.84965","0.07529"
"382.50000","31.87517","0.07626"
"382.80600","31.90070","0.07690"
"383.11200","31.92617","0.07706"
"383.41800","31.95164","0.07719"
"383.72400","31.97712","0.07772"
"384.03000","32.00270","0.07832"
"384.33600","32.02818","0.07915"
"384.64200","32.05365","0.07954"
"384.94800","32.07917","0.08063"
"385.25400","32.10464","0.08046"
"385.56000","32.13018","0.08132"
"385.86600","32.15565","0.08228"
"386.17200","32.18118","0.08216"
"386.47800","32.20665","0.08274"
"386.78400","32.23218","0.08285"
"387.09000","32.25771","0.08311"
"387.39600","32.28318","0.08336"
"387.70200","32.30865","0.08391"
"388.00800","32.33412","0.08384"
"388.31400","32.35971","0.08429"
"388.62000","32.38518","0.08439"
"388.92600","32.41065","0.08250"
"389.23200","32.43618","0.08299"
"389.53800","32.46165","0.08324"
"389.84400","32.48724","0.08326"
"390.15000","32.51265","0.08229"
"390.45600","32.53818","0.08254"
"390.76200","32.56359","0.08395"
"391.06800","32.58912","0.08345"
"391.37400","32.61465","0.08386"
"391.68000","32.64012","0.08333"
"391.98600","32.66571","0.08565"
"392.29200","32.69118","0.08490"
"392.59800","32.71671","0.08619"
"392.90400","32.74212","0.08660"
"393.21000","32.76771","0.08735"
"393.51600","32.79318","0.08763"
"393.82200","32.81865","0.08842"
"394.12800","32.84418","0.08900"
"394.43400","32.86972","0.08981"
"394.74000","32.89524","0.08920"
"395.04600","32.92072","0.08861"
"395.35200","32.94613","0.08550"
"395.65800","32.97165","0.08552"
"395.96400","32.99712","0.08549"
"396.27000","33.02266","0.08652"
"396.57600","33.04813","0.08718"
"396.88200","33.07366","0.08792"
"397.18800","33.09912","0.08795"
"397.49400","33.12471","0.08834"
"397.80000","33.15018","0.08863"
"398.10600","33.17566","0.08919"
"398.41200","33.20119","0.08973"
"398.71800","33.22666","0.09008"
"399.02400","33.25225","0.09025"
"399.33000","33.27772","0.09095"
"399.63600","33.30318","0.09123"
"399.94200","33.32866","0.09174"
"400.24800","33.35413","0.09139"
"400.55400","33.37966","0.09160"
"400.86000","33.40513","0.09195"
"401.16600","33.43066","0.09272"
"401.47200","33.45613","0.09280"
"401.77800","33.48172","0.09322"
"402.08400","33.50713","0.09368"
"402.39000","33.53266","0.09384"
"402.69600","33.55819","0.09423"
"403.00200","33.58366","0.09461"
"403.30800","33.60913","0.09522"
"403.61400","33.63466","0.09547"
"403.92000","33.66019","0.09686"
"404.22600","33.68566","0.09731"
"404.53200","33.71119","0.08723"
"404.83800","33.73672","0.08776"
"405.14400","33.76213","0.09055"
"405.45000","33.78766","0.09123"
"405.75600","33.81313","0.09168"
"406.06200","33.83867","0.09132"
"406.36800","33.86419","0.09169"
"406.67400","33.88972","0.09180"
"406.98000","33.91519","0.09273"
"407.28600","33.94067","0.09288"
"407.59200","33.96619","0.09340"
"407.89800","33.99166","0.09383"
"408.20400","34.01719","0.09408"
"408.51000","34.04266","0.09429"
"408.81600","34.06819","0.09518"
"409.12200","34.09367","0.09564"
"409.42800","34.11914","0.09658"
"409.73400","34.14466","0.09626"
"410.04000","34.17014","0.09783"
"410.34600","34.19572","0.09793"
"410.65200","34.22120","0.09984"
"410.95800","34.24673","0.09961"
"411.26400","34.27208","0.10075"
"411.57000","34.29761","0.10183"
"411.87600","34.32320","0.10137"
"412.18200","34.34867","0.10376"
"412.48800","34.37420","0.10396"
"412.79400","34.39967","0.10687"
"413.10000","34.42520","0.10688"
"413.40600","34.45067","0.10887"
"413.71200","34.47614","0.10749"
"414.01800","34.50167","0.10976"
"414.32400","34.52714","0.11011"
"414.63000","34.55267","0.11233"
"414.93600","34.57814","0.11348"
"415.24200","34.60373","0.11489"
"415.54800","34.62920","0.11667"
"415.85400","34.65467","0.11667"
"416.16000","34.68026","0.11909"
"416.46600","34.70567","0.12021"
"416.77200","34.73120","0.12183"
"417.07800","34.75661","0.12289"
"417.38400","34.78226","0.12389"
"417.69000","34.80767","0.12462"
"417.99600","34.83320","0.12522"
"418.30200","34.85867","0.12733"
"418.60800","34.88414","0.12810"
"418.91400","34.90961","0.13043"
"419.22000","34.93508","0.13021"
"419.52600","34.96067","0.13294"
"419.83200","34.98615","0.13419"
"420.13800","35.01168","0.13600"
"420.44400","35.03720","0.13828"
"420.75000","35.06268","0.13843"
"421.05600","35.08814","0.13988"
"421.36200","35.11361","0.14090"
"421.66800","35.13915","0.14156"
"421.97400","35.16462","0.14213"
"422.28000","35.19020","0.14296"
"422.58600","35.21574","0.14348"
"422.89200","35.24115","0.14348"
"423.19800","35.26667","0.14401"
"423.50400","35.29208","0.14419"
"423.81000","35.31768","0.14441"
"424.11600","35.34315","0.14531"
"424.42200","35.36868","0.14532"
"424.72800","35.39421","0.14654"
"425.03400","35.41968","0.14828"
"425.34000","35.44521","0.14840"
"425.64600","35.47062","0.15010"
"425.95200","35.49621","0.15232"
"426.25800","35.52162","0.15449"
"426.56400","35.54721","0.15592"
"426.87000","35.57268","0.15848"
"427.17600","35.59821","0.15953"
"427.48200","35.62368","0.16112"
"427.78800","35.64909","0.16424"
"428.09400","35.67468","0.16538"
"428.40000","35.70015","0.16709"
"428.70600","35.72568","0.16853"
"429.01200","35.75115","0.17009"
"429.31800","35.77668","0.17147"
"429.62400","35.80221","0.17285"
"429.93000","35.82762","0.17415"
"430.23600","35.85315","0.17532"
"430.54200","35.87862","0.17651"
"430.84800","35.90421","0.17747"
"431.15400","35.92968","0.17846"
"431.46000","35.95521","0.17902"
"431.76600","35.98074","0.18027"
"432.07200","36.00615","0.18076"
"432.37800","36.03168","0.18150"
"432.68400","36.05709","0.18252"
"432.99000","36.08274","0.18337"
"433.29600","36.10822","0.18372"
"433.60200","36.13369","0.18514"
"433.90800","36.15921","0.18648"
"434.21400","36.18468","0.18781"
"434.52000","36.21016","0.18836"
"434.82600","36.23557","0.18961"
"435.13200","36.26116","0.19060"
"435.43800","36.28662","0.19135"
"435.74400","36.31221","0.19246"
"436.05000","36.33768","0.19355"
"436.35600","36.36316","0.19398"
"436.66200","36.38869","0.19522"
"436.96800","36.41416","0.19593"
"437.27400","36.43969","0.19716"
"437.58000","36.46516","0.19851"
"437.88600","36.49068","0.19988"
"438.19200","36.51622","0.20148"
"438.49800","36.54169","0.20305"
"438.80400","36.56722","0.20525"
"439.11000","36.59263","0.20668"
"439.41600","36.61822","0.20912"
"439.72200","36.64369","0.21156"
"440.02800","36.66916","0.21439"
"440.33400","36.69469","0.21813"
"440.64000","36.72016","0.22009"
"440.94600","36.74569","0.22406"
"441.25200","36.77116","0.22795"
"441.55800","36.79669","0.23198"
"441.86400","36.82210","0.23319"
"442.17000","36.84769","0.23680"
"442.47600","36.87316","0.23829"
"442.78200","36.89863","0.23883"
"443.08800","36.92422","0.24151"
"443.39400","36.94963","0.24224"
"443.70000","36.97516","0.24300"
"444.00600","37.00063","0.24385"
"444.31200","37.02622","0.24492"
"444.61800","37.05169","0.24572"
"444.92400","37.07716","0.24657"
"445.23000","37.10270","0.24719"
"445.53600","37.12817","0.24782"
"445.84200","37.15364","0.24848"
"446.14800","37.17916","0.24898"
"446.45400","37.20469","0.24990"
"446.76000","37.23016","0.25070"
"447.06600","37.25563","0.25120"
"447.37200","37.28117","0.04132"
"447.67800","37.30670","0.02617"
"447.98400","37.33223","0.02898"
"448.29000","37.35764","0.02798"
"448.59600","37.38322","0.02881"
"448.90200","37.40870","0.02849"
"449.20800","37.43417","0.02871"
"449.51400","37.45970","0.02880"
"449.82000","37.48517","0.02885"
"450.12600","37.51070","0.02892"
"450.43200","37.53611","0.02835"
"450.73800","37.56170","0.02919"
"451.04400","37.58717","0.02900"
"451.35000","37.61264","0.02917"
"451.65600","37.63817","0.02883"
"451.96200","37.66370","0.02878"
"452.26800","37.68917","0.02900"
"452.57400","37.71464","0.02871"
"452.88000","37.74023","0.02849"
"453.11600","37.75984","0.02851"