File: Force_trajectories/170121_1/Specimen_RawData_9.csv
End date,"1/21/2017"
Specimen label,"4DG_25"
Maximum Load,"0.99007",N

Time,Extension,Load
(s),(mm),(N)
"0.00000","0.00000","-0.00002"
"0.31800","0.02619","0.00155"
"0.63600","0.05315","0.00265"
"0.95400","0.07964","0.00329"
"1.27200","0.10613","0.00417"
"1.59000","0.13267","0.00406"
"1.90800","0.15916","0.00471"
"2.22600","0.18565","0.00511"
"2.54400","0.21207","0.00489"
"2.86200","0.23862","0.00589"
"3.18000","0.26517","0.00587"
"3.49800","0.29159","0.00622"
"3.81600","0.31808","0.00657"
"4.13400","0.34457","0.00698"
"4.45200","0.37111","0.00715"
"4.77000","0.39766","0.00724"
"5.08800","0.42409","0.00758"
"5.40600","0.45063","0.00708"
"5.72400","0.47706","0.00736"
"6.04200","0.50367","0.00764"
"6.36000","0.53009","0.00834"
"6.67800","0.55658","0.00828"
"6.99600","0.58313","0.00788"
"7.31400","0.60955","0.00867"
"7.63200","0.63616","0.00870"
"7.95000","0.66259","0.00870"
"8.26800","0.68913","0.00893"
"8.58600","0.71556","0.00893"
"8.90400","0.74205","0.00872"
"9.22200","0.76865","0.00921"
"9.54000","0.79508","0.00941"
"9.85800","0.82157","0.00910"
"10.17600","0.84811","0.00900"
"10.49400","0.87460","0.00901"
"10.81200","0.90109","0.00903"
"11.13000","0.92757","0.00945"
"11.44800","0.95412","0.00989"
"11.76600","0.98067","0.00929"
"12.08400","1.00709","0.00998"
"12.40200","1.03358","0.00961"
"12.72000","1.06007","0.00991"
"13.03800","1.08661","0.00984"
"13.35600","1.11316","0.01007"
"13.67400","1.13965","0.00998"
"13.99200","1.16614","0.01052"
"14.31000","1.19256","0.01044"
"14.62800","1.21911","0.01063"
"14.94600","1.24560","0.01065"
"15.26400","1.27208","0.01080"
"15.58200","1.29863","0.01100"
"15.90000","1.32506","0.01106"
"16.21800","1.35160","0.01161"
"16.53600","1.37809","0.01101"
"16.85400","1.40464","0.01114"
"17.17200","1.43112","0.01132"
"17.49000","1.45761","0.01104"
"17.80800","1.48416","0.01117"
"18.12600","1.51058","0.01147"
"18.44400","1.53707","0.01151"
"18.76200","1.56362","0.01160"
"19.08000","1.59010","0.01129"
"19.39800","1.61671","0.01153"
"19.71600","1.64308","0.01101"
"20.03400","1.66962","0.01090"
"20.35200","1.69611","0.01120"
"20.67000","1.72260","0.01152"
"20.98800","1.74914","0.01132"
"21.30600","1.77551","0.01148"
"21.62400","1.80212","0.01180"
"21.94200","1.82860","0.01163"
"22.26000","1.85515","0.01179"
"22.57800","1.88164","0.01196"
"22.89600","1.90806","0.01179"
"23.21400","1.93461","0.01228"
"23.53200","1.96110","0.01164"
"23.85000","1.98758","0.01182"
"24.16800","2.01413","0.01219"
"24.48600","2.04062","0.01147"
"24.80400","2.06710","0.01204"
"25.12200","2.09359","0.01146"
"25.44000","2.12014","0.01194"
"25.75800","2.14662","0.01202"
"26.07600","2.17305","0.01194"
"26.39400","2.19960","0.01209"
"26.71200","2.22608","0.01213"
"27.03000","2.25263","0.01170"
"27.34800","2.27912","0.01183"
"27.66600","2.30560","0.01184"
"27.98400","2.33209","0.01167"
"28.30200","2.35858","0.01058"
"28.62000","2.38512","0.01111"
"28.93800","2.41161","0.01051"
"29.25600","2.43810","0.01045"
"29.57400","2.46464","0.01081"
"29.89200","2.49107","0.01098"
"30.21000","2.51768","0.01061"
"30.52800","2.54404","0.01107"
"30.84600","2.57059","0.01138"
"31.16400","2.59714","0.01053"
"31.48200","2.62356","0.01051"
"31.80000","2.65017","0.01093"
"32.11800","2.67660","0.01057"
"32.43600","2.70314","0.01085"
"32.75400","2.72963","0.01050"
"33.07200","2.75606","0.01080"
"33.39000","2.78260","0.01127"
"33.70800","2.80903","0.01137"
"34.02600","2.83564","0.01094"
"34.34400","2.86207","0.01133"
"34.66200","2.88861","0.01099"
"34.98000","2.91510","0.01127"
"35.29800","2.94159","0.01129"
"35.61600","2.96813","0.01081"
"35.93400","2.99456","0.01165"
"36.25200","3.02105","0.01154"
"36.57000","3.04759","0.01176"
"36.88800","3.07408","0.01148"
"37.20600","3.10063","0.01197"
"37.52400","3.12711","0.01146"
"37.84200","3.15354","0.01073"
"38.16000","3.18015","0.01110"
"38.47800","3.20657","0.01107"
"38.79600","3.23312","0.01035"
"39.11400","3.25955","0.01115"
"39.43200","3.28609","0.01132"
"39.75000","3.31264","0.01134"
"40.06800","3.33913","0.01108"
"40.38600","3.36561","0.01177"
"40.70400","3.39210","0.01154"
"41.02200","3.41865","0.01161"
"41.34000","3.44513","0.01204"
"41.65800","3.47162","0.01189"
"41.97600","3.49811","0.01184"
"42.29400","3.52453","0.01203"
"42.61200","3.55114","0.01203"
"42.93000","3.57763","0.01218"
"43.24800","3.60411","0.01264"
"43.56600","3.63060","0.01322"
"43.88400","3.65703","0.01292"
"44.20200","3.68363","0.01250"
"44.52000","3.71012","0.01284"
"44.83800","3.73661","0.01279"
"45.15600","3.76315","0.01343"
"45.47400","3.78958","0.01316"
"45.79200","3.81613","0.01343"
"46.11000","3.84261","0.01360"
"46.42800","3.86910","0.01386"
"46.74600","3.89559","0.01403"
"47.06400","3.92207","0.01396"
"47.38200","3.94862","0.01413"
"47.70000","3.97505","0.01426"
"48.01800","4.00159","0.01480"
"48.33600","4.02808","0.01477"
"48.65400","4.05457","0.01523"
"48.97200","4.08111","0.01569"
"49.29000","4.10754","0.01563"
"49.60800","4.13415","0.01444"
"49.92600","4.16057","0.01259"
"50.24400","4.18712","0.01229"
"50.56200","4.21361","0.01299"
"50.88000","4.24009","0.01343"
"51.19800","4.26664","0.01338"
"51.51600","4.29307","0.01298"
"51.83400","4.31967","0.01336"
"52.15200","4.34610","0.01367"
"52.47000","4.37265","0.01356"
"52.78800","4.39913","0.01438"
"53.10600","4.42562","0.01446"
"53.42400","4.45211","0.01418"
"53.74200","4.47859","0.01447"
"54.06000","4.50502","0.01477"
"54.37800","4.53163","0.01507"
"54.69600","4.55806","0.01598"
"55.01400","4.58460","0.01500"
"55.33200","4.61109","0.01558"
"55.65000","4.63758","0.01621"
"55.96800","4.66412","0.01524"
"56.28600","4.69055","0.01603"
"56.60400","4.71715","0.01657"
"56.92200","4.74358","0.01601"
"57.24000","4.77007","0.01775"
"57.55800","4.79662","0.01764"
"57.87600","4.82304","0.01720"
"58.19400","4.84965","0.01792"
"58.51200","4.87608","0.01814"
"58.83000","4.90262","0.01864"
"59.14800","4.92917","0.01859"
"59.46600","4.95554","0.01858"
"59.78400","4.98214","0.01811"
"60.10200","5.00857","0.01838"
"60.42000","5.03512","0.01912"
"60.73800","5.06166","0.01880"
"61.05600","5.08809","0.01893"
"61.37400","5.11458","0.02057"
"61.69200","5.14106","0.02032"
"62.01000","5.16761","0.01996"
"62.32800","5.19410","0.02064"
"62.64600","5.22058","0.02052"
"62.96400","5.24713","0.02112"
"63.28200","5.27356","0.02190"
"63.60000","5.30016","0.02229"
"63.91800","5.32659","0.02070"
"64.23600","5.35314","0.02170"
"64.55400","5.37962","0.02152"
"64.87200","5.40611","0.02253"
"65.19000","5.43266","0.02205"
"65.50800","5.45908","0.02262"
"65.82600","5.48563","0.02245"
"66.14400","5.51212","0.02240"
"66.46200","5.53860","0.02300"
"66.78000","5.56515","0.02332"
"67.09800","5.59158","0.02367"
"67.41600","5.61812","0.02417"
"67.73400","5.64461","0.02466"
"68.05200","5.67110","0.02514"
"68.37000","5.69764","0.02571"
"68.68800","5.72407","0.02559"
"69.00600","5.75062","0.02648"
"69.32400","5.77710","0.02607"
"69.64200","5.80365","0.02675"
"69.96000","5.83014","0.02738"
"70.27800","5.85656","0.02667"
"70.59600","5.88311","0.02746"
"70.91400","5.90966","0.02789"
"71.23200","5.93608","0.02853"
"71.55000","5.96263","0.02963"
"71.86800","5.98906","0.02894"
"72.18600","6.01560","0.02933"
"72.50400","6.04215","0.03012"
"72.82200","6.06864","0.03038"
"73.14000","6.09512","0.03058"
"73.45800","6.12161","0.03113"
"73.77600","6.14816","0.03158"
"74.09400","6.17464","0.03147"
"74.41200","6.20107","0.03187"
"74.73000","6.22756","0.03224"
"75.04800","6.25411","0.03175"
"75.36600","6.28065","0.03288"
"75.68400","6.30708","0.03362"
"76.00200","6.33368","0.03318"
"76.32000","6.36011","0.03351"
"76.63800","6.38660","0.03396"
"76.95600","6.41308","0.03445"
"77.27400","6.43957","0.03515"
"77.59200","6.46612","0.03463"
"77.91000","6.49261","0.03498"
"78.22800","6.51915","0.03484"
"78.54600","6.54570","0.03556"
"78.86400","6.57207","0.03586"
"79.18200","6.59861","0.03552"
"79.50000","6.62510","0.03633"
"79.81800","6.65165","0.03609"
"80.13600","6.67813","0.03632"
"80.45400","6.70456","0.03635"
"80.77200","6.73111","0.03646"
"81.09000","6.75759","0.03632"
"81.40800","6.78414","0.03703"
"81.72600","6.81057","0.03640"
"82.04400","6.83705","0.03728"
"82.36200","6.86366","0.03679"
"82.68000","6.89009","0.03756"
"82.99800","6.91663","0.03795"
"83.31600","6.94306","0.03801"
"83.63400","6.96955","0.03867"
"83.95200","6.99615","0.03890"
"84.27000","7.02258","0.03903"
"84.58800","7.04919","0.03959"
"84.90600","7.07561","0.03957"
"85.22400","7.10210","0.04016"
"85.54200","7.12865","0.04072"
"85.86000","7.15513","0.04033"
"86.17800","7.18162","0.04075"
"86.49600","7.20805","0.04042"
"86.81400","7.23459","0.04102"
"87.13200","7.26114","0.04131"
"87.45000","7.28757","0.04174"
"87.76800","7.31411","0.04209"
"88.08600","7.34060","0.04215"
"88.40400","7.36715","0.04321"
"88.72200","7.39363","0.04296"
"89.04000","7.42012","0.04330"
"89.35800","7.44661","0.04337"
"89.67600","7.47303","0.04215"
"89.99400","7.49964","0.04303"
"90.31200","7.52613","0.04291"
"90.63000","7.55261","0.04326"
"90.94800","7.57916","0.04294"
"91.26600","7.60559","0.04368"
"91.58400","7.63219","0.04416"
"91.90200","7.65856","0.04459"
"92.22000","7.68511","0.04444"
"92.53800","7.71159","0.04466"
"92.85600","7.73808","0.04553"
"93.17400","7.76469","0.04560"
"93.49200","7.79111","0.04562"
"93.81000","7.81760","0.04662"
"94.12800","7.84415","0.04628"
"94.44600","7.87063","0.04690"
"94.76400","7.89712","0.04790"
"95.08200","7.92355","0.04772"
"95.40000","7.95009","0.04735"
"95.71800","7.97664","0.04795"
"96.03600","8.00313","0.04849"
"96.35400","8.02961","0.04857"
"96.67200","8.05610","0.04822"
"96.99000","8.08259","0.04919"
"97.30800","8.10913","0.04905"
"97.62600","8.13556","0.04983"
"97.94400","8.16211","0.05019"
"98.26200","8.18854","0.05068"
"98.58000","8.21514","0.05102"
"98.89800","8.24163","0.05097"
"99.21600","8.26818","0.05160"
"99.53400","8.29460","0.05178"
"99.85200","8.32109","0.05210"
"100.17000","8.34764","0.05238"
"100.48800","8.37406","0.05296"
"100.80600","8.40061","0.05333"
"101.12400","8.42716","0.05355"
"101.44200","8.45358","0.05432"
"101.76000","8.48013","0.05463"
"102.07800","8.50662","0.05462"
"102.39600","8.53310","0.05560"
"102.71400","8.55959","0.05446"
"103.03200","8.58614","0.05423"
"103.35000","8.61262","0.05440"
"103.66800","8.63911","0.05353"
"103.98600","8.66566","0.05389"
"104.30400","8.69208","0.05496"
"104.62200","8.71857","0.05520"
"104.94000","8.74512","0.05596"
"105.25800","8.77160","0.05552"
"105.57600","8.79815","0.05671"
"105.89400","8.82464","0.05619"
"106.21200","8.85118","0.05607"
"106.53000","8.87767","0.05649"
"106.84800","8.90404","0.05741"
"107.16600","8.93064","0.05767"
"107.48400","8.95707","0.05748"
"107.80200","8.98362","0.05728"
"108.12000","9.01016","0.05502"
"108.43800","9.03659","0.05263"
"108.75600","9.06308","0.05139"
"109.07400","9.08962","0.05045"
"109.39200","9.11611","0.05095"
"109.71000","9.14266","0.05087"
"110.02800","9.16908","0.05180"
"110.34600","9.19563","0.05214"
"110.66400","9.22212","0.05217"
"110.98200","9.24866","0.05233"
"111.30000","9.27509","0.05202"
"111.61800","9.30164","0.05118"
"111.93600","9.32818","0.05204"
"112.25400","9.35461","0.05236"
"112.57200","9.38110","0.05231"
"112.89000","9.40758","0.03855"
"113.20800","9.43407","0.03851"
"113.52600","9.46068","0.03853"
"113.84400","9.48710","0.03933"
"114.16200","9.51365","0.03919"
"114.48000","9.54008","0.03979"
"114.79800","9.56662","0.04010"
"115.11600","9.59317","0.04026"
"115.43400","9.61954","0.03997"
"115.75200","9.64614","0.04072"
"116.07000","9.67257","0.04131"
"116.38800","9.69912","0.04141"
"116.70600","9.72561","0.04182"
"117.02400","9.75209","0.04171"
"117.34200","9.77858","0.04228"
"117.66000","9.80506","0.04264"
"117.97800","9.83167","0.04314"
"118.29600","9.85810","0.04390"
"118.61400","9.88458","0.04367"
"118.93200","9.91107","0.04421"
"119.25000","9.93762","0.04368"
"119.56800","9.96410","0.04472"
"119.88600","9.99065","0.04485"
"120.20400","10.01714","0.04556"
"120.52200","10.04363","0.04597"
"120.84000","10.07011","0.04641"
"121.15800","10.09660","0.04623"
"121.47600","10.12309","0.04689"
"121.79400","10.14957","0.04690"
"122.11200","10.17612","0.04770"
"122.43000","10.20261","0.04743"
"122.74800","10.22909","0.04822"
"123.06600","10.25558","0.04912"
"123.38400","10.28213","0.04967"
"123.70200","10.30867","0.04975"
"124.02000","10.33510","0.04987"
"124.33800","10.36165","0.05088"
"124.65600","10.38807","0.05025"
"124.97400","10.41462","0.05106"
"125.29200","10.44110","0.05180"
"125.61000","10.46759","0.05194"
"125.92800","10.49408","0.05307"
"126.24600","10.52057","0.05302"
"126.56400","10.54717","0.05350"
"126.88200","10.57366","0.05367"
"127.20000","10.60009","0.05414"
"127.51800","10.62663","0.05490"
"127.83600","10.65306","0.05514"
"128.15400","10.67961","0.05548"
"128.47200","10.70609","0.05547"
"128.79000","10.73270","0.05663"
"129.10800","10.75913","0.05656"
"129.42600","10.78561","0.05691"
"129.74400","10.81216","0.05734"
"130.06200","10.83859","0.05752"
"130.38000","10.86507","0.05817"
"130.69800","10.89156","0.05840"
"131.01600","10.91811","0.05821"
"131.33400","10.94465","0.05904"
"131.65200","10.97108","0.05951"
"131.97000","10.99763","0.05973"
"132.28800","11.02411","0.06021"
"132.60600","11.05060","0.06053"
"132.92400","11.07715","0.06083"
"133.24200","11.10351","0.06090"
"133.56000","11.13012","0.06155"
"133.87800","11.15661","0.06143"
"134.19600","11.18315","0.06187"
"134.51400","11.20964","0.06203"
"134.83200","11.23607","0.06237"
"135.15000","11.26261","0.06310"
"135.46800","11.28910","0.06314"
"135.78600","11.31565","0.06351"
"136.10400","11.34207","0.06379"
"136.42200","11.36856","0.06410"
"136.74000","11.39511","0.06450"
"137.05800","11.42165","0.06461"
"137.37600","11.44814","0.06459"
"137.69400","11.47463","0.06509"
"138.01200","11.50111","0.06511"
"138.33000","11.52760","0.06518"
"138.64800","11.55409","0.06589"
"138.96600","11.58057","0.06564"
"139.28400","11.60712","0.06612"
"139.60200","11.63355","0.06593"
"139.92000","11.66009","0.06611"
"140.23800","11.68658","0.06682"
"140.55600","11.71319","0.06727"
"140.87400","11.73961","0.06756"
"141.19200","11.76610","0.06759"
"141.51000","11.79265","0.06767"
"141.82800","11.81907","0.06775"
"142.14600","11.84562","0.06820"
"142.46400","11.87205","0.06786"
"142.78200","11.89866","0.06818"
"143.10000","11.92520","0.06857"
"143.41800","11.95157","0.06887"
"143.73600","11.97818","0.06919"
"144.05400","12.00460","0.06923"
"144.37200","12.03115","0.06927"
"144.69000","12.05764","0.06917"
"145.00800","12.08412","0.06937"
"145.32600","12.11061","0.06969"
"145.64400","12.13704","0.06985"
"145.96200","12.16364","0.07016"
"146.28000","12.19013","0.07027"
"146.59800","12.21656","0.07057"
"146.91600","12.24310","0.07105"
"147.23400","12.26959","0.07113"
"147.55200","12.29614","0.07125"
"147.87000","12.32262","0.07173"
"148.18800","12.34911","0.07170"
"148.50600","12.37560","0.07202"
"148.82400","12.40208","0.07242"
"149.14200","12.42863","0.07279"
"149.46000","12.45512","0.07283"
"149.77800","12.48160","0.07321"
"150.09600","12.50815","0.07208"
"150.41400","12.53458","0.07288"
"150.73200","12.56112","0.07305"
"151.05000","12.58749","0.07328"
"151.36800","12.61410","0.07367"
"151.68600","12.64064","0.07369"
"152.00400","12.66707","0.07457"
"152.32200","12.69362","0.07489"
"152.64000","12.72005","0.07564"
"152.95800","12.74665","0.07557"
"153.27600","12.77314","0.07602"
"153.59400","12.79962","0.07662"
"153.91200","12.82605","0.07703"
"154.23000","12.85254","0.07831"
"154.54800","12.87914","0.03003"
"154.86600","12.90563","0.03970"
"155.18400","12.93212","0.03965"
"155.50200","12.95860","0.04121"
"155.82000","12.98509","0.04048"
"156.13800","13.01164","0.04153"
"156.45600","13.03806","0.04281"
"156.77400","13.06461","0.04263"
"157.09200","13.09116","0.04303"
"157.41000","13.11753","0.04364"
"157.72800","13.14419","0.04370"
"158.04600","13.17062","0.04484"
"158.36400","13.19704","0.04505"
"158.68200","13.22359","0.04456"
"159.00000","13.25008","0.04544"
"159.31800","13.27668","0.04557"
"159.63600","13.30305","0.04612"
"159.95400","13.32960","0.04722"
"160.27200","13.35609","0.04655"
"160.59000","13.38257","0.04682"
"160.90800","13.40912","0.04809"
"161.22600","13.43561","0.04761"
"161.54400","13.46215","0.04816"
"161.86200","13.48864","0.04789"
"162.18000","13.51513","0.04848"
"162.49800","13.54161","0.04982"
"162.81600","13.56804","0.04907"
"163.13400","13.59459","0.04947"
"163.45200","13.62107","0.05065"
"163.77000","13.64762","0.04989"
"164.08800","13.67411","0.05073"
"164.40600","13.70059","0.05209"
"164.72400","13.72714","0.05119"
"165.04200","13.75363","0.05145"
"165.36000","13.78011","0.05212"
"165.67800","13.80660","0.05210"
"165.99600","13.83309","0.05266"
"166.31400","13.85963","0.05336"
"166.63200","13.88606","0.05344"
"166.95000","13.91261","0.05445"
"167.26800","13.93909","0.05427"
"167.58600","13.96558","0.05488"
"167.90400","13.99219","0.05526"
"168.22200","14.01855","0.05551"
"168.54000","14.04516","0.05387"
"168.85800","14.07159","0.05553"
"169.17600","14.09807","0.05512"
"169.49400","14.12468","0.05610"
"169.81200","14.15105","0.05626"
"170.13000","14.17765","0.05667"
"170.44800","14.20408","0.05713"
"170.76600","14.23063","0.05743"
"171.08400","14.25717","0.05754"
"171.40200","14.28354","0.05718"
"171.72000","14.31009","0.05791"
"172.03800","14.33657","0.05831"
"172.35600","14.36312","0.05897"
"172.67400","14.38961","0.05966"
"172.99200","14.41609","0.05978"
"173.31000","14.44258","0.05992"
"173.62800","14.46907","0.05959"
"173.94600","14.49561","0.06054"
"174.26400","14.52210","0.06071"
"174.58200","14.54859","0.06018"
"174.90000","14.57507","0.06081"
"175.21800","14.60162","0.06091"
"175.53600","14.62817","0.06107"
"175.85400","14.65459","0.06117"
"176.17200","14.68114","0.06159"
"176.49000","14.70763","0.06158"
"176.80800","14.73405","0.06194"
"177.12600","14.76066","0.06182"
"177.44400","14.78709","0.06149"
"177.76200","14.81357","0.06144"
"178.08000","14.84012","0.06159"
"178.39800","14.86661","0.06169"
"178.71600","14.89315","0.06227"
"179.03400","14.91952","0.06236"
"179.35200","14.94607","0.06231"
"179.67000","14.97261","0.06273"
"179.98800","14.99910","0.06180"
"180.30600","15.02559","0.06264"
"180.62400","15.05207","0.06271"
"180.94200","15.07862","0.06282"
"181.26000","15.10511","0.06357"
"181.57800","15.13159","0.06384"
"181.89600","15.15814","0.06355"
"182.21400","15.18457","0.06374"
"182.53200","15.21111","0.06389"
"182.85000","15.23760","0.06424"
"183.16800","15.26409","0.06178"
"183.48600","15.29058","0.06213"
"183.80400","15.31706","0.06297"
"184.12200","15.34361","0.06338"
"184.44000","15.37010","0.06393"
"184.75800","15.39664","0.06398"
"185.07600","15.42313","0.06443"
"185.39400","15.44962","0.06439"
"185.71200","15.47616","0.06498"
"186.03000","15.50259","0.06427"
"186.34800","15.52908","0.06468"
"186.66600","15.55562","0.06507"
"186.98400","15.58211","0.06468"
"187.30200","15.60865","0.06593"
"187.62000","15.63502","0.06580"
"187.93800","15.66163","0.06620"
"188.25600","15.68812","0.06643"
"188.57400","15.71460","0.06658"
"188.89200","15.74109","0.06701"
"189.21000","15.76758","0.06699"
"189.52800","15.79406","0.06714"
"189.84600","15.82061","0.06747"
"190.16400","15.84716","0.06726"
"190.48200","15.87364","0.06744"
"190.80000","15.90007","0.06820"
"191.11800","15.92668","0.06865"
"191.43600","15.95316","0.06849"
"191.75400","15.97959","0.06880"
"192.07200","16.00614","0.06911"
"192.39000","16.03256","0.06918"
"192.70800","16.05911","0.06923"
"193.02600","16.08560","0.06972"
"193.34400","16.11214","0.06963"
"193.66200","16.13863","0.06990"
"193.98000","16.16506","0.07025"
"194.29800","16.19160","0.07044"
"194.61600","16.21809","0.07066"
"194.93400","16.24464","0.07082"
"195.25200","16.27106","0.07074"
"195.57000","16.29755","0.07118"
"195.88800","16.32416","0.07113"
"196.20600","16.35058","0.07193"
"196.52400","16.37713","0.07221"
"196.84200","16.40362","0.07201"
"197.16000","16.43010","0.07292"
"197.47800","16.45671","0.07334"
"197.79600","16.48308","0.07290"
"198.11400","16.50962","0.07402"
"198.43200","16.53611","0.07437"
"198.75000","16.56266","0.07511"
"199.06800","16.58920","0.07610"
"199.38600","16.61557","0.07684"
"199.70400","16.64212","0.07722"
"200.02200","16.66860","0.07795"
"200.34000","16.69509","0.07931"
"200.65800","16.72164","0.08010"
"200.97600","16.74813","0.08081"
"201.29400","16.77461","0.08154"
"201.61200","16.80104","0.08243"
"201.93000","16.82764","0.08383"
"202.24800","16.85413","0.08498"
"202.56600","16.88056","0.08607"
"202.88400","16.90710","0.08728"
"203.20200","16.93365","0.08602"
"203.52000","16.96014","0.08658"
"203.83800","16.98663","0.08723"
"204.15600","17.01311","0.08817"
"204.47400","17.03966","0.08970"
"204.79200","17.06609","0.09050"
"205.11000","17.09263","0.09131"
"205.42800","17.11912","0.09150"
"205.74600","17.14561","0.09260"
"206.06400","17.17215","0.09352"
"206.38200","17.19858","0.09475"
"206.70000","17.22513","0.09508"
"207.01800","17.25155","0.09620"
"207.33600","17.27810","0.09750"
"207.65400","17.30465","0.09844"
"207.97200","17.33107","0.09931"
"208.29000","17.35762","0.10052"
"208.60800","17.38405","0.10127"
"208.92600","17.41059","0.10200"
"209.24400","17.43720","0.10284"
"209.56200","17.46357","0.10373"
"209.88000","17.49011","0.10294"
"210.19800","17.51654","0.10321"
"210.51600","17.54315","0.10384"
"210.83400","17.56963","0.10517"
"211.15200","17.59612","0.10511"
"211.47000","17.62261","0.10634"
"211.78800","17.64903","0.10634"
"212.10600","17.67564","0.10786"
"212.42400","17.70206","0.10853"
"212.74200","17.72861","0.10870"
"213.06000","17.75510","0.11010"
"213.37800","17.78159","0.11012"
"213.69600","17.80813","0.11112"
"214.01400","17.83462","0.11177"
"214.33200","17.86111","0.11313"
"214.65000","17.88759","0.11530"
"214.96800","17.91408","0.11433"
"215.28600","17.94063","0.11528"
"215.60400","17.96711","0.11682"
"215.92200","17.99360","0.11699"
"216.24000","18.02015","0.11876"
"216.55800","18.04663","0.11927"
"216.87600","18.07312","0.11933"
"217.19400","18.09961","0.12011"
"217.51200","18.12609","0.12040"
"217.83000","18.15264","0.12084"
"218.14800","18.17913","0.12094"
"218.46600","18.20568","0.12113"
"218.78400","18.23204","0.12134"
"219.10200","18.25865","0.12117"
"219.42000","18.28514","0.12107"
"219.73800","18.31162","0.12127"
"220.05600","18.33817","0.12147"
"220.37400","18.36459","0.12177"
"220.69200","18.39114","0.12224"
"221.01000","18.41763","0.12243"
"221.32800","18.44411","0.12335"
"221.64600","18.47060","0.12338"
"221.96400","18.49709","0.12513"
"222.28200","18.52364","0.12569"
"222.60000","18.55012","0.12751"
"222.91800","18.57667","0.12897"
"223.23600","18.60309","0.13025"
"223.55400","18.62958","0.13300"
"223.87200","18.65619","0.13080"
"224.19000","18.68261","0.13181"
"224.50800","18.70916","0.13238"
"224.82600","18.73565","0.13351"
"225.14400","18.76207","0.13476"
"225.46200","18.78862","0.13583"
"225.78000","18.81511","0.13771"
"226.09800","18.84159","0.13950"
"226.41600","18.86808","0.14074"
"226.73400","18.89463","0.14370"
"227.05200","18.92118","0.14554"
"227.37000","18.94760","0.14715"
"227.68800","18.97409","0.14780"
"228.00600","19.00057","0.15004"
"228.32400","19.02712","0.15130"
"228.64200","19.05367","0.15296"
"228.96000","19.08010","0.15321"
"229.27800","19.10664","0.15399"
"229.59600","19.13307","0.15497"
"229.91400","19.15968","0.15608"
"230.23200","19.18610","0.15688"
"230.55000","19.21259","0.15827"
"230.86800","19.23907","0.15914"
"231.18600","19.26562","0.15993"
"231.50400","19.29217","0.16075"
"231.82200","19.31860","0.16138"
"232.14000","19.34508","0.16204"
"232.45800","19.37157","0.16271"
"232.77600","19.39806","0.16405"
"233.09400","19.42460","0.16584"
"233.41200","19.45109","0.16664"
"233.73000","19.47758","0.16793"
"234.04800","19.50412","0.16853"
"234.36600","19.53055","0.16947"
"234.68400","19.55710","0.17072"
"235.00200","19.58358","0.17182"
"235.32000","19.61007","0.17241"
"235.63800","19.63667","0.17413"
"235.95600","19.66304","0.17500"
"236.27400","19.68965","0.17675"
"236.59200","19.71608","0.17835"
"236.91000","19.74262","0.17887"
"237.22800","19.76911","0.18142"
"237.54600","19.79560","0.18291"
"237.86400","19.82208","0.18553"
"238.18200","19.84857","0.18844"
"238.50000","19.87511","0.18890"
"238.81800","19.90166","0.19188"
"239.13600","19.92809","0.19240"
"239.45400","19.95457","0.19237"
"239.77200","19.98106","0.19347"
"240.09000","20.00767","0.19690"
"240.40800","20.03410","0.20206"
"240.72600","20.06058","0.20259"
"241.04400","20.08713","0.19364"
"241.36200","20.11362","0.16942"
"241.68000","20.14016","0.16735"
"241.99800","20.16659","0.16074"
"242.31600","20.19314","0.15813"
"242.63400","20.21962","0.15909"
"242.95200","20.24611","0.16053"
"243.27000","20.27260","0.16189"
"243.58800","20.29908","0.16297"
"243.90600","20.32563","0.16528"
"244.22400","20.35212","0.16612"
"244.54200","20.37860","0.16774"
"244.86000","20.40509","0.16917"
"245.17800","20.43152","0.16992"
"245.49600","20.45812","0.16916"
"245.81400","20.48461","0.17007"
"246.13200","20.51110","0.17178"
"246.45000","20.53765","0.17231"
"246.76800","20.56407","0.17374"
"247.08600","20.59062","0.17504"
"247.40400","20.61711","0.17650"
"247.72200","20.64359","0.17781"
"248.04000","20.67008","0.17849"
"248.35800","20.69657","0.18195"
"248.67600","20.72311","0.17454"
"248.99400","20.74966","0.17684"
"249.31200","20.77615","0.17970"
"249.63000","20.80263","0.18301"
"249.94800","20.82912","0.18590"
"250.26600","20.85561","0.18813"
"250.58400","20.88209","0.19054"
"250.90200","20.90858","0.19535"
"251.22000","20.93507","0.19979"
"251.53800","20.96155","0.20493"
"251.85600","20.98816","0.21076"
"252.17400","21.01459","0.21321"
"252.49200","21.04113","0.21720"
"252.81000","21.06762","0.22089"
"253.12800","21.09410","0.22251"
"253.44600","21.12065","0.22341"
"253.76400","21.14708","0.22442"
"254.08200","21.17369","0.22575"
"254.40000","21.20011","0.22696"
"254.71800","21.22666","0.22812"
"255.03600","21.25315","0.22954"
"255.35400","21.27957","0.23224"
"255.67200","21.30612","0.23504"
"255.99000","21.33255","0.23939"
"256.30800","21.35915","0.24248"
"256.62600","21.38564","0.24609"
"256.94400","21.41207","0.24904"
"257.26200","21.43861","0.25145"
"257.58000","21.46504","0.25470"
"257.89800","21.49159","0.25811"
"258.21600","21.51813","0.26115"
"258.53400","21.54462","0.26423"
"258.85200","21.57111","0.26614"
"259.17000","21.59759","0.26777"
"259.48800","21.62414","0.26905"
"259.80600","21.65063","0.26969"
"260.12400","21.67706","0.27042"
"260.44200","21.70360","0.27097"
"260.76000","21.73009","0.27162"
"261.07800","21.75663","0.27237"
"261.39600","21.78312","0.27318"
"261.71400","21.80967","0.27418"
"262.03200","21.83615","0.27530"
"262.35000","21.86258","0.27595"
"262.66800","21.88913","0.27710"
"262.98600","21.91562","0.27883"
"263.30400","21.94210","0.28035"
"263.62200","21.96865","0.28293"
"263.94000","21.99502","0.28616"
"264.25800","22.02162","0.28918"
"264.57600","22.04805","0.29349"
"264.89400","22.07459","0.29681"
"265.21200","22.10108","0.30062"
"265.53000","22.12757","0.30411"
"265.84800","22.15412","0.30689"
"266.16600","22.18054","0.30973"
"266.48400","22.20715","0.31259"
"266.80200","22.23358","0.29850"
"267.12000","22.26012","0.29747"
"267.43800","22.28661","0.30065"
"267.75600","22.31309","0.30143"
"268.07400","22.33970","0.30470"
"268.39200","22.36613","0.30849"
"268.71000","22.39255","0.31166"
"269.02800","22.41910","0.31425"
"269.34600","22.44559","0.31600"
"269.66400","22.47214","0.31758"
"269.98200","22.49862","0.31884"
"270.30000","22.52511","0.32043"
"270.61800","22.55160","0.32220"
"270.93600","22.57808","0.32471"
"271.25400","22.60463","0.32834"
"271.57200","22.63106","0.33377"
"271.89000","22.65760","0.34125"
"272.20800","22.68409","0.34859"
"272.52600","22.71064","0.35640"
"272.84400","22.73712","0.36200"
"273.16200","22.76355","0.36596"
"273.48000","22.79015","0.36894"
"273.79800","22.81658","0.37114"
"274.11600","22.84313","0.37372"
"274.43400","22.86962","0.37614"
"274.75200","22.89610","0.37748"
"275.07000","22.92259","0.37920"
"275.38800","22.94914","0.37990"
"275.70600","22.97562","0.38077"
"276.02400","23.00211","0.38248"
"276.34200","23.02860","0.38359"
"276.66000","23.05508","0.38482"
"276.97800","23.08157","0.38684"
"277.29600","23.10806","0.38782"
"277.61400","23.13460","0.38111"
"277.93200","23.16103","0.27231"
"278.25000","23.18758","0.27414"
"278.56800","23.21406","0.27657"
"278.88600","23.24061","0.27661"
"279.20400","23.26710","0.28140"
"279.52200","23.29358","0.29023"
"279.84000","23.32019","0.29058"
"280.15800","23.34656","0.29806"
"280.47600","23.37310","0.30636"
"280.79400","23.39959","0.30687"
"281.11200","23.42608","0.31420"
"281.43000","23.45262","0.31845"
"281.74800","23.47905","0.31919"
"282.06600","23.50566","0.32270"
"282.38400","23.53214","0.32762"
"282.70200","23.55863","0.33051"
"283.02000","23.58512","0.34389"
"283.33800","23.61154","0.35065"
"283.65600","23.63815","0.35823"
"283.97400","23.66458","0.36686"
"284.29200","23.69112","0.36860"
"284.61000","23.71761","0.37219"
"284.92800","23.74410","0.37419"
"285.24600","23.77058","0.37551"
"285.56400","23.79707","0.37778"
"285.88200","23.82362","0.37783"
"286.20000","23.85011","0.37922"
"286.51800","23.87653","0.37997"
"286.83600","23.90314","0.38064"
"287.15400","23.92957","0.38170"
"287.47200","23.95611","0.38297"
"287.79000","23.98260","0.38448"
"288.10800","24.00909","0.38558"
"288.42600","24.03569","0.38794"
"288.74400","24.06206","0.39036"
"289.06200","24.08867","0.39300"
"289.38000","24.11509","0.39632"
"289.69800","24.14158","0.39858"
"290.01600","24.16813","0.40333"
"290.33400","24.19461","0.40554"
"290.65200","24.22116","0.41075"
"290.97000","24.24759","0.41455"
"291.28800","24.27413","0.41949"
"291.60600","24.30062","0.42334"
"291.92400","24.32705","0.42585"
"292.24200","24.35359","0.42796"
"292.56000","24.38008","0.42974"
"292.87800","24.40663","0.43128"
"293.19600","24.43317","0.43354"
"293.51400","24.45960","0.43755"
"293.83200","24.48615","0.44137"
"294.15000","24.51251","0.44510"
"294.46800","24.53912","0.44968"
"294.78600","24.56561","0.45435"
"295.10400","24.59209","0.45781"
"295.42200","24.61864","0.46067"
"295.74000","24.64507","0.46320"
"296.05800","24.67167","0.46382"
"296.37600","24.69810","0.46530"
"296.69400","24.72459","0.46693"
"297.01200","24.75113","0.46895"
"297.33000","24.77756","0.47096"
"297.64800","24.80411","0.47167"
"297.96600","24.83060","0.47429"
"298.28400","24.85708","0.47767"
"298.60200","24.88357","0.48072"
"298.92000","24.91006","0.48553"
"299.23800","24.93660","0.48924"
"299.55600","24.96309","0.49268"
"299.87400","24.98957","0.49212"
"300.19200","25.01612","0.49396"
"300.51000","25.04261","0.49977"
"300.82800","25.06910","0.50548"
"301.14600","25.09552","0.48674"
"301.46400","25.12213","0.49140"
"301.78200","25.14861","0.49705"
"302.10000","25.17516","0.50250"
"302.41800","25.20165","0.50869"
"302.73600","25.22808","0.51233"
"303.05400","25.25462","0.51622"
"303.37200","25.28111","0.51933"
"303.69000","25.30766","0.52308"
"304.00800","25.33414","0.52562"
"304.32600","25.36057","0.52779"
"304.64400","25.38712","0.52877"
"304.96200","25.41360","0.53008"
"305.28000","25.44015","0.53155"
"305.59800","25.46670","0.53341"
"305.91600","25.49312","0.53816"
"306.23400","25.51967","0.54715"
"306.55200","25.54609","0.55212"
"306.87000","25.57258","0.55654"
"307.18800","25.59913","0.56209"
"307.50600","25.62562","0.56763"
"307.82400","25.65216","0.57161"
"308.14200","25.67859","0.57456"
"308.46000","25.70514","0.57813"
"308.77800","25.73162","0.58118"
"309.09600","25.75811","0.58370"
"309.41400","25.78465","0.58452"
"309.73200","25.81108","0.58715"
"310.05000","25.83763","0.58896"
"310.36800","25.86411","0.58904"
"310.68600","25.89060","0.58910"
"311.00400","25.91715","0.59058"
"311.32200","25.94357","0.59186"
"311.64000","25.97012","0.59367"
"311.95800","25.99661","0.59565"
"312.27600","26.02316","0.59863"
"312.59400","26.04964","0.60369"
"312.91200","26.07607","0.60932"
"313.23000","26.10262","0.61686"
"313.54800","26.12910","0.62440"
"313.86600","26.15565","0.62948"
"314.18400","26.18214","0.63302"
"314.50200","26.20862","0.63595"
"314.82000","26.23517","0.64020"
"315.13800","26.26160","0.64697"
"315.45600","26.28815","0.65304"
"315.77400","26.31457","0.66064"
"316.09200","26.34112","0.66576"
"316.41000","26.36761","0.43490"
"316.72800","26.39409","0.34768"
"317.04600","26.42058","0.37500"
"317.36400","26.44706","0.37166"
"317.68200","26.47361","0.37407"
"318.00000","26.50016","0.37681"
"318.31800","26.52665","0.37914"
"318.63600","26.55313","0.38150"
"318.95400","26.57956","0.38221"
"319.27200","26.60610","0.38442"
"319.59000","26.63265","0.38818"
"319.90800","26.65907","0.39281"
"320.22600","26.68562","0.39886"
"320.54400","26.71211","0.39652"
"320.86200","26.73866","0.40440"
"321.18000","26.76515","0.41345"
"321.49800","26.79157","0.42097"
"321.81600","26.81806","0.42509"
"322.13400","26.84454","0.42740"
"322.45200","26.87115","0.42947"
"322.77000","26.89764","0.43376"
"323.08800","26.92406","0.44040"
"323.40600","26.95061","0.44813"
"323.72400","26.97710","0.45585"
"324.04200","27.00364","0.46141"
"324.36000","27.03007","0.46374"
"324.67800","27.05656","0.46555"
"324.99600","27.08310","0.46603"
"325.31400","27.10959","0.46779"
"325.63200","27.13614","0.47077"
"325.95000","27.16262","0.47497"
"326.26800","27.18917","0.48024"
"326.58600","27.21560","0.48256"
"326.90400","27.24214","0.48571"
"327.22200","27.26857","0.48567"
"327.54000","27.29506","0.49164"
"327.85800","27.32161","0.50057"
"328.17600","27.34809","0.50747"
"328.49400","27.37458","0.51068"
"328.81200","27.40112","0.51423"
"329.13000","27.42755","0.51824"
"329.44800","27.45416","0.52376"
"329.76600","27.48064","0.52760"
"330.08400","27.50707","0.52907"
"330.40200","27.53362","0.53017"
"330.72000","27.56004","0.53462"
"331.03800","27.58665","0.54151"
"331.35600","27.61308","0.54994"
"331.67400","27.63962","0.55463"
"331.99200","27.66617","0.55923"
"332.31000","27.69254","0.56567"
"332.62800","27.71914","0.57223"
"332.94600","27.74563","0.57537"
"333.26400","27.77212","0.57722"
"333.58200","27.79860","0.57762"
"333.90000","27.82509","0.58117"
"334.21800","27.85164","0.58603"
"334.53600","27.87813","0.58794"
"334.85400","27.90461","0.58976"
"335.17200","27.93116","0.59156"
"335.49000","27.95759","0.59335"
"335.80800","27.98413","0.59415"
"336.12600","28.01056","0.59580"
"336.44400","28.03711","0.59864"
"336.76200","28.06359","0.60191"
"337.08000","28.09008","0.60554"
"337.39800","28.11663","0.61304"
"337.71600","28.14305","0.62329"
"338.03400","28.16966","0.62874"
"338.35200","28.19614","0.63131"
"338.67000","28.22263","0.63422"
"338.98800","28.24918","0.63982"
"339.30600","28.27561","0.64333"
"339.62400","28.30215","0.65120"
"339.94200","28.32864","0.66005"
"340.26000","28.35519","0.65857"
"340.57800","28.38167","0.66127"
"340.89600","28.40804","0.66400"
"341.21400","28.43459","0.63714"
"341.53200","28.46107","0.63470"
"341.85000","28.48768","0.62520"
"342.16800","28.51411","0.62969"
"342.48600","28.54059","0.63176"
"342.80400","28.56708","0.63448"
"343.12200","28.59357","0.63861"
"343.44000","28.62011","0.64479"
"343.75800","28.64660","0.65170"
"344.07600","28.67309","0.65170"
"344.39400","28.69963","0.64588"
"344.71200","28.72612","0.65257"
"345.03000","28.75267","0.66031"
"345.34800","28.77909","0.66561"
"345.66600","28.80558","0.67187"
"345.98400","28.83213","0.67551"
"346.30200","28.85861","0.67721"
"346.62000","28.88516","0.67905"
"346.93800","28.91159","0.67964"
"347.25600","28.93813","0.68061"
"347.57400","28.96468","0.68238"
"347.89200","28.99105","0.68489"
"348.21000","29.01759","0.68708"
"348.52800","29.04402","0.69000"
"348.84600","29.07063","0.69203"
"349.16400","29.09712","0.69797"
"349.48200","29.12360","0.70574"
"349.80000","29.15009","0.71173"
"350.11800","29.17651","0.71728"
"350.43600","29.20312","0.72253"
"350.75400","29.22961","0.72482"
"351.07200","29.25609","0.73169"
"351.39000","29.28264","0.73415"
"351.70800","29.30907","0.73849"
"352.02600","29.33567","0.74007"
"352.34400","29.36210","0.74084"
"352.66200","29.38859","0.74325"
"352.98000","29.41513","0.74682"
"353.29800","29.44156","0.74888"
"353.61600","29.46817","0.75606"
"353.93400","29.49459","0.76372"
"354.25200","29.52108","0.76871"
"354.57000","29.54763","0.77058"
"354.88800","29.57412","0.77647"
"355.20600","29.60066","0.78066"
"355.52400","29.62703","0.78509"
"355.84200","29.65364","0.78835"
"356.16000","29.68018","0.79195"
"356.47800","29.70661","0.78086"
"356.79600","29.73310","0.78546"
"357.11400","29.75952","0.78952"
"357.43200","29.78613","0.79240"
"357.75000","29.81261","0.79406"
"358.06800","29.83910","0.79625"
"358.38600","29.86565","0.79945"
"358.70400","29.89208","0.80589"
"359.02200","29.91862","0.81148"
"359.34000","29.94517","0.81704"
"359.65800","29.97160","0.82377"
"359.97600","29.99809","0.82618"
"360.29400","30.02457","0.82832"
"360.61200","30.05112","0.83141"
"360.93000","30.07760","0.83360"
"361.24800","30.10409","0.83816"
"361.56600","30.13064","0.84727"
"361.88400","30.15712","0.85918"
"362.20200","30.18367","0.86759"
"362.52000","30.21010","0.87378"
"362.83800","30.23658","0.88186"
"363.15600","30.26307","0.88824"
"363.47400","30.28956","0.89071"
"363.79200","30.31610","0.89168"
"364.11000","30.34259","0.80180"
"364.42800","30.36914","0.80371"
"364.74600","30.39562","0.81272"
"365.06400","30.42211","0.81850"
"365.38200","30.44872","0.82703"
"365.70000","30.47503","0.83324"
"366.01800","30.50163","0.83847"
"366.33600","30.52806","0.84483"
"366.65400","30.55466","0.84102"
"366.97200","30.58115","0.85346"
"367.29000","30.60752","0.86117"
"367.60800","30.63418","0.82638"
"367.92600","30.66061","0.83048"
"368.24400","30.68710","0.82995"
"368.56200","30.71358","0.83218"
"368.88000","30.74013","0.83655"
"369.19800","30.76662","0.84582"
"369.51600","30.79310","0.85683"
"369.83400","30.81965","0.86825"
"370.15200","30.84614","0.87811"
"370.47000","30.87263","0.88652"
"370.78800","30.89911","0.89043"
"371.10600","30.92560","0.89240"
"371.42400","30.95209","0.89353"
"371.74200","30.97863","0.89538"
"372.06000","31.00506","0.89799"
"372.37800","31.03167","0.90055"
"372.69600","31.05809","0.90369"
"373.01400","31.08464","0.90817"
"373.33200","31.11113","0.91337"
"373.65000","31.13755","0.92021"
"373.96800","31.16416","0.92677"
"374.28600","31.19059","0.93154"
"374.60400","31.21713","0.94000"
"374.92200","31.24356","0.94426"
"375.24000","31.27011","0.94724"
"375.55800","31.29659","0.95125"
"375.87600","31.32308","0.95724"
"376.19400","31.34957","0.96514"
"376.51200","31.37605","0.90212"
"376.83000","31.40266","0.90710"
"377.14800","31.42915","0.91201"
"377.46600","31.45557","0.91674"
"377.78400","31.48206","0.92334"
"378.10200","31.50849","0.93095"
"378.42000","31.53515","0.93745"
"378.73800","31.56158","0.94189"
"379.05600","31.58813","0.94590"
"379.37400","31.61467","0.94981"
"379.69200","31.64110","0.95736"
"380.01000","31.66765","0.96449"
"380.32800","31.69407","0.97000"
"380.64600","31.72056","0.97436"
"380.96400","31.74711","0.97801"
"381.28200","31.77359","0.98107"
"381.60000","31.80014","0.98360"
"381.91800","31.82663","0.98548"
"382.23600","31.85305","0.98725"
"382.55400","31.87960","0.98735"
"382.87200","31.90609","0.98926"
"383.19000","31.93263","0.92611"
"383.50800","31.95906","0.92824"
"383.82600","31.98561","0.93315"
"384.14400","32.01215","0.93788"
"384.46200","32.03858","0.94168"
"384.78000","32.06513","0.94475"
"385.09800","32.09155","0.77553"
"385.41600","32.11810","0.75941"
"385.73400","32.14459","0.75876"
"386.05200","32.17113","0.76113"
"386.37000","32.19762","0.75790"
"386.68800","32.22405","0.76236"
"387.00600","32.25065","0.76219"
"387.32400","32.27714","0.76541"
"387.64200","32.30363","0.73309"
"387.96000","32.33012","0.73143"
"388.27800","32.35654","0.69468"
"388.59600","32.38315","0.69883"
"388.91400","32.40963","0.43566"
"389.23200","32.43612","0.42417"
"389.55000","32.46261","0.41532"
"389.86800","32.48904","0.41032"
"390.18600","32.51564","0.39959"
"390.50400","32.54207","0.40095"
"390.82200","32.56868","0.39801"
"391.14000","32.59516","0.39671"
"391.45800","32.62159","0.39932"
"391.77600","32.64814","0.39889"
"392.09400","32.67456","0.40143"
"392.41200","32.70111","0.40513"
"392.73000","32.72760","0.40626"
"393.04800","32.75408","0.41123"
"393.36600","32.78069","0.41360"
"393.68400","32.80706","0.41666"
"394.00200","32.83360","0.41891"
"394.32000","32.86009","0.42343"
"394.63800","32.88663","0.42590"
"394.95600","32.91312","0.42785"
"395.27400","32.93955","0.43004"
"395.59200","32.96616","0.43257"
"395.91000","32.99264","0.43778"
"396.22800","33.01913","0.44327"
"396.54600","33.04562","0.44765"
"396.86400","33.07204","0.44497"
"397.18200","33.09859","0.45225"
"397.50000","33.12514","0.45432"
"397.81800","33.15162","0.45894"
"398.13600","33.17811","0.46111"
"398.45400","33.20454","0.46428"
"398.77200","33.23114","0.46547"
"399.09000","33.25763","0.46691"
"399.40800","33.28411","0.46675"
"399.72600","33.31060","0.46651"
"400.04400","33.33709","0.46795"
"400.36200","33.36364","0.47046"
"400.68000","33.39006","0.47459"
"400.99800","33.41661","0.47836"
"401.31600","33.44304","0.48181"
"401.63400","33.46959","0.48362"
"401.95200","33.49613","0.48729"
"402.27000","33.52256","0.49039"
"402.58800","33.54916","0.49575"
"402.90600","33.57553","0.50008"
"403.22400","33.60214","0.50498"
"403.54200","33.62862","0.50629"
"403.86000","33.65505","0.50930"
"404.17800","33.68166","0.51295"
"404.49600","33.70802","0.51630"
"404.81400","33.73463","0.52054"
"405.13200","33.76118","0.52350"
"405.45000","33.78761","0.52586"
"405.76800","33.81415","0.52759"
"406.08600","33.84058","0.52886"
"406.40400","33.86712","0.53045"
"406.72200","33.89361","0.53408"
"407.04000","33.92004","0.53708"
"407.35800","33.94659","0.54217"
"407.67600","33.97307","0.54828"
"407.99400","33.99968","0.55461"
"408.31200","34.02610","0.55984"
"408.63000","34.05259","0.56327"
"408.94800","34.07914","0.56584"
"409.26600","34.10556","0.56918"
"409.58400","34.13217","0.57277"
"409.90200","34.15860","0.57587"
"410.22000","34.18509","0.57756"
"410.53800","34.21163","0.57969"
"410.85600","34.23812","0.58122"
"411.17400","34.26461","0.58188"
"411.49200","34.29109","0.58414"
"411.81000","34.31764","0.58676"
"412.12800","34.34412","0.58908"
"412.44600","34.37061","0.59066"
"412.76400","34.39710","0.59132"
"413.08200","34.42359","0.59256"
"413.40000","34.45007","0.59464"
"413.71800","34.47662","0.59661"
"414.03600","34.50311","0.59883"
"414.35400","34.52959","0.60306"
"414.67200","34.55602","0.60557"
"414.99000","34.58263","0.60636"
"415.30800","34.60911","0.61274"
"415.62600","34.63560","0.61910"
"415.94400","34.66209","0.62445"
"416.26200","34.68857","0.62893"
"416.58000","34.71512","0.63074"
"416.89800","34.74161","0.63311"
"417.21600","34.76809","0.63615"
"417.53400","34.79464","0.57709"
"417.85200","34.82106","0.58052"
"418.17000","34.84767","0.58058"
"418.48800","34.87410","0.58144"
"418.80600","34.90059","0.58337"
"419.12400","34.92713","0.58399"
"419.44200","34.95356","0.58554"
"419.76000","34.98011","0.58595"
"420.07800","35.00659","0.58775"
"420.39600","35.03314","0.58866"
"420.71400","35.05963","0.58939"
"421.03200","35.08611","0.59017"
"421.35000","35.11266","0.59081"
"421.66800","35.13902","0.59123"
"421.98600","35.16557","0.59189"
"422.30400","35.19206","0.59269"
"422.62200","35.21867","0.59355"
"422.94000","35.24516","0.59485"
"423.25800","35.27158","0.59523"
"423.57600","35.29812","0.59638"
"423.89400","35.32455","0.59700"
"424.21200","35.35110","0.59913"
"424.53000","35.37765","0.49644"
"424.84800","35.40407","0.48361"
"425.16600","35.43062","0.48807"
"425.48400","35.45710","0.49418"
"425.80200","35.48365","0.49091"
"426.12000","35.51014","0.50229"
"426.43800","35.53656","0.49907"
"426.75600","35.56311","0.50601"
"427.07400","35.58960","0.50986"
"427.39200","35.61615","0.51036"
"427.71000","35.64257","0.51551"
"428.02800","35.66906","0.51497"
"428.34600","35.69561","0.51997"
"428.66400","35.72209","0.52126"
"428.98200","35.74864","0.52489"
"429.30000","35.77507","0.52630"
"429.61800","35.80161","0.52715"
"429.93600","35.82816","0.52787"
"430.25400","35.85458","0.52857"
"430.57200","35.88113","0.52935"
"430.89000","35.90762","0.52969"
"431.20800","35.93410","0.53136"
"431.52600","35.96065","0.53208"
"431.84400","35.98708","0.53515"
"432.16200","36.01363","0.53758"
"432.48000","36.04005","0.54236"
"432.79800","36.06666","0.54671"
"433.11600","36.09315","0.55125"
"433.43400","36.11957","0.55481"
"433.75200","36.14606","0.55913"
"434.07000","36.17255","0.56195"
"434.38800","36.19915","0.56540"
"434.70600","36.22558","0.56838"
"435.02400","36.25212","0.57190"
"435.34200","36.27861","0.57475"
"435.66000","36.30510","-0.00398"
"435.97800","36.33165","0.01097"
"436.29600","36.35807","0.00636"
"436.61400","36.38456","0.00530"
"436.93200","36.41111","0.01517"
"437.25000","36.43759","0.00765"
"437.56800","36.46414","0.03445"
"437.88600","36.49057","0.02569"
"438.20400","36.51711","0.00905"
"438.52200","36.54360","0.03450"
"438.84000","36.57015","0.01437"
"439.15800","36.59663","0.02221"
"439.47600","36.62306","0.02124"
"439.79400","36.64961","0.02906"
"440.11200","36.67609","0.01993"
"440.43000","36.70258","0.02007"
"440.74800","36.72913","0.03091"
"441.06600","36.75555","0.02018"
"441.38400","36.78210","0.03287"
"441.70200","36.80865","0.01895"
"442.02000","36.83508","0.03096"
"442.33800","36.86162","0.02402"
"442.65600","36.88805","0.02848"
"442.97400","36.91465","0.02892"
"443.29200","36.94114","0.02505"
"443.61000","36.96763","0.03277"
"443.92800","36.99417","0.02518"
"444.24600","37.02054","0.03270"
"444.56400","37.04715","0.02851"
"444.88200","37.07357","0.03119"
"445.20000","37.10006","0.03161"
"445.51800","37.12661","0.03037"
"445.83600","37.15310","0.03404"
"446.15400","37.17964","0.03088"
"446.47200","37.20607","0.03499"
"446.79000","37.23262","0.03262"
"447.10800","37.25910","0.03426"
"447.42600","37.28559","0.03468"
"447.74400","37.31208","0.03461"
"448.06200","37.33856","0.03675"
"448.38000","37.36511","0.03543"
"448.69800","37.39159","0.03659"
"449.01600","37.41808","0.03688"
"449.33400","37.44463","0.03753"
"449.65200","37.47105","0.03831"
"449.97000","37.49760","0.03803"
"450.28800","37.52415","0.03934"
"450.60600","37.55064","0.03850"
"450.92400","37.57712","0.03995"
"451.24200","37.60355","0.03958"
"451.56000","37.63016","0.04014"
"451.87800","37.65658","0.04164"
"452.19600","37.68313","0.04195"
"452.51400","37.70962","0.04203"
"452.83200","37.73610","0.04228"
"453.15000","37.76259","0.04348"
"453.46800","37.78913","0.04394"
"453.78600","37.81562","0.04438"
"454.10400","37.84217","0.04534"
"454.42200","37.86854","0.04529"
"454.74000","37.89514","0.04684"
"455.05800","37.92157","0.04708"
"455.37600","37.94812","0.04702"
"455.69400","37.97460","0.04777"
"456.01200","38.00109","0.04885"
"456.33000","38.02764","0.04945"
"456.64800","38.05412","0.05049"
"456.96600","38.08061","0.05128"
"457.28400","38.10710","0.05195"
"457.60200","38.13358","0.05271"
"457.92000","38.16013","0.05343"
"458.23800","38.18662","0.05370"
"458.55600","38.21317","0.05541"
"458.87400","38.23965","0.05540"
"459.19200","38.26614","0.05596"
"459.51000","38.29268","0.05722"
"459.82800","38.31905","0.05698"
"460.14600","38.34560","0.05789"
"460.46400","38.37209","0.05871"
"460.78200","38.39863","0.05794"
"461.10000","38.42518","0.05785"
"461.41800","38.45160","0.05890"
"461.73600","38.47809","0.05894"
"462.05400","38.50458","0.05941"
"462.37200","38.53112","0.05950"
"462.69000","38.55761","0.06068"
"463.00800","38.58410","0.06042"
"463.32600","38.61058","0.06176"
"463.64400","38.63707","0.06211"
"463.96200","38.66362","0.06285"
"464.28000","38.69011","0.06323"
"464.59800","38.71665","0.06354"
"464.91600","38.74314","0.06468"
"465.23400","38.76963","0.06489"
"465.55200","38.79611","0.06519"
"465.87000","38.82260","0.06526"
"466.18800","38.84903","0.06564"
"466.50600","38.87563","0.06620"
"466.82400","38.90212","0.06667"
"467.14200","38.92860","0.06674"
"467.46000","38.95509","0.06705"
"467.77800","38.98164","0.06773"
"468.09600","39.00813","0.06756"
"468.41400","39.03461","0.06820"
"468.73200","39.06116","0.06881"
"469.05000","39.08753","0.06914"
"469.36800","39.11413","0.06941"
"469.68600","39.14062","0.06943"
"470.00400","39.16711","0.06996"
"470.32200","39.19359","0.07033"
"470.64000","39.22002","0.07044"
"470.65800","39.22152","0.07063"