File: Force_trajectories/170121_1/Specimen_RawData_5.csv
End date,"1/21/2017"
Specimen label,"14DT_NoLabel"
Maximum Load,"0.00887",N

Time,Extension,Load
(s),(mm),(N)
"0.00000","0.00000","0.00004"
"0.22200","0.01644","0.00019"
"0.44400","0.03731","0.00026"
"0.66600","0.05566","0.00036"
"0.88800","0.07426","0.00014"
"1.11000","0.09273","0.00026"
"1.33200","0.11127","0.00045"
"1.55400","0.12974","-0.00022"
"1.77600","0.14822","0.00051"
"1.99800","0.16669","0.00018"
"2.22000","0.18517","0.00014"
"2.44200","0.20376","-0.00003"
"2.66400","0.22218","0.00018"
"2.88600","0.24071","0.00051"
"3.10800","0.25925","0.00006"
"3.33000","0.27766","0.00021"
"3.55200","0.29614","0.00041"
"3.77400","0.31467","-0.00017"
"3.99600","0.33321","-0.00023"
"4.21800","0.35174","0.00010"
"4.44000","0.37016","0.00032"
"4.66200","0.38869","0.00004"
"4.88400","0.40723","0.00007"
"5.10600","0.42570","0.00030"
"5.32800","0.44424","0.00008"
"5.55000","0.46265","0.00009"
"5.77200","0.48119","0.00004"
"5.99400","0.49972","0.00024"
"6.21600","0.51820","0.00014"
"6.43800","0.53673","0.00047"
"6.66000","0.55515","0.00009"
"6.88200","0.57374","-0.00001"
"7.10400","0.59216","0.00014"
"7.32600","0.61075","-0.00053"
"7.54800","0.62917","-0.00036"
"7.77000","0.64776","-0.00053"
"7.99200","0.66623","-0.00039"
"8.21400","0.68465","-0.00023"
"8.43600","0.70318","-0.00039"
"8.65800","0.72166","-0.00051"
"8.88000","0.74019","0.00013"
"9.10200","0.75873","-0.00032"
"9.32400","0.77714","-0.00042"
"9.54600","0.79574","-0.00065"
"9.76800","0.81415","-0.00029"
"9.99000","0.83269","-0.00062"
"10.21200","0.85122","-0.00022"
"10.43400","0.86964","-0.00026"
"10.65600","0.88823","-0.00054"
"10.87800","0.90671","-0.00057"
"11.10000","0.92524","-0.00050"
"11.32200","0.94372","0.00017"
"11.54400","0.96213","-0.00027"
"11.76600","0.98073","-0.00042"
"11.98800","0.99914","-0.00034"
"12.21000","1.01780","-0.00046"
"12.43200","1.03615","-0.00017"
"12.65400","1.05469","0.00013"
"12.87600","1.07322","-0.00012"
"13.09800","1.09164","-0.00044"
"13.32000","1.11017","-0.00048"
"13.54200","1.12865","-0.00039"
"13.76400","1.14718","0.00006"
"13.98600","1.16572","-0.00045"
"14.20800","1.18419","-0.00024"
"14.43000","1.20273","-0.00010"
"14.65200","1.22114","-0.00031"
"14.87400","1.23968","-0.00027"
"15.09600","1.25821","-0.00038"
"15.31800","1.27669","-0.00054"
"15.54000","1.29522","-0.00061"
"15.76200","1.31370","-0.00059"
"15.98400","1.33217","-0.00067"
"16.20600","1.35071","-0.00051"
"16.42800","1.36918","0.00022"
"16.65000","1.38771","-0.00042"
"16.87200","1.40613","-0.00040"
"17.09400","1.42466","-0.00075"
"17.31600","1.44314","-0.00015"
"17.53800","1.46173","-0.00050"
"17.76000","1.48021","-0.00001"
"17.98200","1.49868","-0.00072"
"18.20400","1.51722","-0.00029"
"18.42600","1.53563","-0.00035"
"18.64800","1.55423","-0.00020"
"18.87000","1.57270","-0.00033"
"19.09200","1.59124","-0.00026"
"19.31400","1.60971","-0.00016"
"19.53600","1.62813","-0.00025"
"19.75800","1.64672","0.00002"
"19.98000","1.66520","-0.00008"
"20.20200","1.68367","-0.00001"
"20.42400","1.70215","0.00000"
"20.64600","1.72068","-0.00046"
"20.86800","1.73922","-0.00020"
"21.09000","1.75769","-0.00003"
"21.31200","1.77617","0.00007"
"21.53400","1.79470","0.00003"
"21.75600","1.81318","0.00002"
"21.97800","1.83171","-0.00021"
"22.20000","1.85013","-0.00026"
"22.42200","1.86872","-0.00057"
"22.64400","1.88720","-0.00049"
"22.86600","1.90567","-0.00058"
"23.08800","1.92421","-0.00015"
"23.31000","1.94262","0.00007"
"23.53200","1.96128","0.00010"
"23.75400","1.97969","0.00011"
"23.97600","1.99823","-0.00002"
"24.19800","2.01664","-0.00007"
"24.42000","2.03518","0.00050"
"24.64200","2.05371","0.00003"
"24.86400","2.07219","-0.00025"
"25.08600","2.09072","-0.00039"
"25.30800","2.10914","-0.00023"
"25.53000","2.12773","-0.00008"
"25.75200","2.14621","-0.00016"
"25.97400","2.16468","-0.00028"
"26.19600","2.18321","-0.00035"
"26.41800","2.20169","-0.00030"
"26.64000","2.22022","0.00003"
"26.86200","2.23870","-0.00005"
"27.08400","2.25711","0.00009"
"27.30600","2.27571","-0.00064"
"27.52800","2.29412","0.00021"
"27.75000","2.31272","0.00002"
"27.97200","2.33125","-0.00043"
"28.19400","2.34961","-0.00036"
"28.41600","2.36826","-0.00016"
"28.63800","2.38668","-0.00003"
"28.86000","2.40521","0.00020"
"29.08200","2.42363","-0.00040"
"29.30400","2.44216","-0.00010"
"29.52600","2.46070","-0.00027"
"29.74800","2.47911","-0.00008"
"29.97000","2.49771","0.00007"
"30.19200","2.51624","-0.00018"
"30.41400","2.53472","-0.00022"
"30.63600","2.55325","-0.00043"
"30.85800","2.57167","-0.00014"
"31.08000","2.59014","0.00026"
"31.30200","2.60868","0.00018"
"31.52400","2.62721","-0.00025"
"31.74600","2.64569","-0.00004"
"31.96800","2.66416","-0.00017"
"32.19000","2.68270","-0.00033"
"32.41200","2.70117","0.00014"
"32.63400","2.71971","-0.00042"
"32.85600","2.73824","-0.00029"
"33.07800","2.75666","-0.00033"
"33.30000","2.77519","-0.00012"
"33.52200","2.79367","0.00017"
"33.74400","2.81220","-0.00025"
"33.96600","2.83068","-0.00006"
"34.18800","2.84915","-0.00001"
"34.41000","2.86769","-0.00039"
"34.63200","2.88616","-0.00007"
"34.85400","2.90470","0.00006"
"35.07600","2.92317","0.00004"
"35.29800","2.94176","-0.00025"
"35.52000","2.96018","-0.00038"
"35.74200","2.97871","-0.00018"
"35.96400","2.99719","-0.00044"
"36.18600","3.01566","0.00000"
"36.40800","3.03420","-0.00045"
"36.63000","3.05267","-0.00032"
"36.85200","3.07115","-0.00010"
"37.07400","3.08968","-0.00017"
"37.29600","3.10822","-0.00013"
"37.51800","3.12669","0.00004"
"37.74000","3.14517","-0.00003"
"37.96200","3.16370","-0.00049"
"38.18400","3.18224","0.00008"
"38.40600","3.20065","-0.00024"
"38.62800","3.21925","0.00005"
"38.85000","3.23766","-0.00015"
"39.07200","3.25620","-0.00048"
"39.29400","3.27473","-0.00055"
"39.51600","3.29321","0.00002"
"39.73800","3.31174","-0.00046"
"39.96000","3.33010","-0.00054"
"40.18200","3.34875","0.00039"
"40.40400","3.36717","-0.00005"
"40.62600","3.38564","-0.00007"
"40.84800","3.40418","-0.00041"
"41.07000","3.42265","-0.00025"
"41.29200","3.44119","0.00042"
"41.51400","3.45966","-0.00001"
"41.73600","3.47820","-0.00017"
"41.95800","3.49667","-0.00009"
"42.18000","3.51515","-0.00018"
"42.40200","3.53368","-0.00006"
"42.62400","3.55222","0.00035"
"42.84600","3.57069","0.00006"
"43.06800","3.58923","-0.00009"
"43.29000","3.60764","0.00003"
"43.51200","3.62624","-0.00018"
"43.73400","3.64465","-0.00014"
"43.95600","3.66325","-0.00021"
"44.17800","3.68172","-0.00002"
"44.40000","3.70019","0.00008"
"44.62200","3.71873","-0.00004"
"44.84400","3.73709","0.00007"
"45.06600","3.75574","-0.00007"
"45.28800","3.77415","0.00010"
"45.51000","3.79275","-0.00040"
"45.73200","3.81116","-0.00004"
"45.95400","3.82970","-0.00021"
"46.17600","3.84823","-0.00001"
"46.39800","3.86665","-0.00005"
"46.62000","3.88518","-0.00003"
"46.84200","3.90366","0.00028"
"47.06400","3.92219","-0.00030"
"47.28600","3.94073","-0.00001"
"47.50800","3.95920","0.00000"
"47.73000","3.97768","0.00027"
"47.95200","3.99621","0.00004"
"48.17400","4.01469","0.00002"
"48.39600","4.03322","-0.00015"
"48.61800","4.05164","-0.00009"
"48.84000","4.07017","0.00038"
"49.06200","4.08871","0.00036"
"49.28400","4.10724","0.00023"
"49.50600","4.12572","0.00014"
"49.72800","4.14419","0.00052"
"49.95000","4.16273","-0.00007"
"50.17200","4.18114","0.00008"
"50.39400","4.19974","0.00045"
"50.61600","4.21815","0.00017"
"50.83800","4.23669","-0.00010"
"51.06000","4.25516","0.00016"
"51.28200","4.27364","0.00027"
"51.50400","4.29217","0.00027"
"51.72600","4.31071","-0.00004"
"51.94800","4.32924","-0.00011"
"52.17000","4.34766","0.00037"
"52.39200","4.36619","0.00014"
"52.61400","4.38473","-0.00003"
"52.83600","4.40314","0.00040"
"53.05800","4.42173","0.00023"
"53.28000","4.44021","0.00018"
"53.50200","4.45868","0.00008"
"53.72400","4.47722","0.00014"
"53.94600","4.49563","0.00038"
"54.16800","4.51423","0.00016"
"54.39000","4.53270","0.00009"
"54.61200","4.55118","0.00049"
"54.83400","4.56971","0.00049"
"55.05600","4.58813","0.00025"
"55.27800","4.60666","-0.00003"
"55.50000","4.62514","0.00036"
"55.72200","4.64367","0.00000"
"55.94400","4.66227","0.00032"
"56.16600","4.68068","0.00017"
"56.38800","4.69928","0.00032"
"56.61000","4.71763","0.00045"
"56.83200","4.73623","0.00061"
"57.05400","4.75470","0.00012"
"57.27600","4.77318","-0.00017"
"57.49800","4.79171","0.00035"
"57.72000","4.81019","0.00048"
"57.94200","4.82872","0.00043"
"58.16400","4.84720","0.00069"
"58.38600","4.86567","0.00030"
"58.60800","4.88427","0.00022"
"58.83000","4.90268","0.00002"
"59.05200","4.92122","0.00032"
"59.27400","4.93969","0.00043"
"59.49600","4.95817","0.00076"
"59.71800","4.97670","0.00035"
"59.94000","4.99512","0.00049"
"60.16200","5.01371","0.00047"
"60.38400","5.03219","0.00024"
"60.60600","5.05072","0.00033"
"60.82800","5.06920","0.00010"
"61.05000","5.08773","0.00064"
"61.27200","5.10620","0.00087"
"61.49400","5.12462","0.00049"
"61.71600","5.14322","0.00034"
"61.93800","5.16169","0.00083"
"62.16000","5.18023","0.00022"
"62.38200","5.19870","0.00042"
"62.60400","5.21718","0.00054"
"62.82600","5.23571","0.00028"
"63.04800","5.25418","0.00057"
"63.27000","5.27272","0.00092"
"63.49200","5.29119","0.00078"
"63.71400","5.30973","0.00056"
"63.93600","5.32820","0.00029"
"64.15800","5.34668","0.00058"
"64.38000","5.36521","0.00029"
"64.60200","5.38369","0.00038"
"64.82400","5.40216","0.00077"
"65.04600","5.42070","0.00050"
"65.26800","5.43917","0.00026"
"65.49000","5.45765","0.00049"
"65.71200","5.47618","0.00056"
"65.93400","5.49472","0.00018"
"66.15600","5.51319","0.00077"
"66.37800","5.53167","0.00077"
"66.60000","5.55020","0.00044"
"66.82200","5.56868","0.00044"
"67.04400","5.58721","0.00081"
"67.26600","5.60569","0.00011"
"67.48800","5.62416","0.00065"
"67.71000","5.64270","0.00089"
"67.93200","5.66111","0.00067"
"68.15400","5.67977","0.00088"
"68.37600","5.69812","0.00084"
"68.59800","5.71672","0.00082"
"68.82000","5.73525","0.00057"
"69.04200","5.75367","0.00068"
"69.26400","5.77220","0.00064"
"69.48600","5.79068","0.00105"
"69.70800","5.80921","0.00073"
"69.93000","5.82769","0.00106"
"70.15200","5.84616","0.00066"
"70.37400","5.86470","0.00069"
"70.59600","5.88317","0.00020"
"70.81800","5.90170","0.00085"
"71.04000","5.92024","0.00124"
"71.26200","5.93866","0.00125"
"71.48400","5.95725","0.00065"
"71.70600","5.97566","0.00097"
"71.92800","5.99426","0.00058"
"72.15000","6.01267","0.00065"
"72.37200","6.03115","0.00086"
"72.59400","6.04974","0.00070"
"72.81600","6.06810","0.00055"
"73.03800","6.08675","0.00050"
"73.26000","6.10517","0.00097"
"73.48200","6.12370","0.00089"
"73.70400","6.14224","0.00062"
"73.92600","6.16065","0.00118"
"74.14800","6.17919","0.00079"
"74.37000","6.19766","0.00076"
"74.59200","6.21626","0.00098"
"74.81400","6.23467","0.00083"
"75.03600","6.25321","0.00093"
"75.25800","6.27168","0.00132"
"75.48000","6.29016","0.00126"
"75.70200","6.30869","0.00087"
"75.92400","6.32723","0.00142"
"76.14600","6.34570","0.00088"
"76.36800","6.36418","0.00138"
"76.59000","6.38265","0.00125"
"76.81200","6.40119","0.00124"
"77.03400","6.41966","0.00151"
"77.25600","6.43820","0.00102"
"77.47800","6.45673","0.00140"
"77.70000","6.47521","0.00108"
"77.92200","6.49368","0.00130"
"78.14400","6.51216","0.00137"
"78.36600","6.53075","0.00136"
"78.58800","6.54917","0.00103"
"78.81000","6.56770","0.00128"
"79.03200","6.58624","0.00139"
"79.25400","6.60465","0.00113"
"79.47600","6.62325","0.00114"
"79.69800","6.64172","0.00126"
"79.92000","6.66019","0.00151"
"80.14200","6.67867","0.00104"
"80.36400","6.69721","0.00120"
"80.58600","6.71568","0.00174"
"80.80800","6.73416","0.00130"
"81.03000","6.75269","0.00129"
"81.25200","6.77116","0.00117"
"81.47400","6.78970","0.00113"
"81.69600","6.80823","0.00117"
"81.91800","6.82665","0.00130"
"82.14000","6.84524","0.00152"
"82.36200","6.86372","0.00161"
"82.58400","6.88219","0.00166"
"82.80600","6.90073","0.00135"
"83.02800","6.91914","0.00168"
"83.25000","6.93768","0.00143"
"83.47200","6.95621","0.00138"
"83.69400","6.97469","0.00150"
"83.91600","6.99322","0.00101"
"84.13800","7.01164","0.00131"
"84.36000","7.03023","0.00144"
"84.58200","7.04871","0.00123"
"84.80400","7.06724","0.00155"
"85.02600","7.08566","0.00189"
"85.24800","7.10419","0.00118"
"85.47000","7.12267","0.00150"
"85.69200","7.14114","0.00186"
"85.91400","7.15968","0.00171"
"86.13600","7.17815","0.00160"
"86.35800","7.19675","0.00179"
"86.58000","7.21522","0.00145"
"86.80200","7.23364","0.00117"
"87.02400","7.25223","0.00164"
"87.24600","7.27071","0.00156"
"87.46800","7.28918","0.00170"
"87.69000","7.30772","0.00173"
"87.91200","7.32613","0.00137"
"88.13400","7.34473","0.00175"
"88.35600","7.36314","0.00199"
"88.57800","7.38174","0.00174"
"88.80000","7.40027","0.00169"
"89.02200","7.41868","0.00154"
"89.24400","7.43722","0.00152"
"89.46600","7.45564","0.00185"
"89.68800","7.47423","0.00187"
"89.91000","7.49264","0.00171"
"90.13200","7.51124","0.00212"
"90.35400","7.52972","0.00181"
"90.57600","7.54819","0.00163"
"90.79800","7.56672","0.00179"
"91.02000","7.58520","0.00190"
"91.24200","7.60367","0.00178"
"91.46400","7.62221","0.00200"
"91.68600","7.64068","0.00234"
"91.90800","7.65916","0.00215"
"92.13000","7.67769","0.00209"
"92.35200","7.69623","0.00164"
"92.57400","7.71476","0.00170"
"92.79600","7.73318","0.00195"
"93.01800","7.75171","0.00211"
"93.24000","7.77013","0.00151"
"93.46200","7.78866","0.00157"
"93.68400","7.80714","0.00189"
"93.90600","7.82567","0.00222"
"94.12800","7.84427","0.00227"
"94.35000","7.86268","0.00201"
"94.57200","7.88122","0.00189"
"94.79400","7.89969","0.00188"
"95.01600","7.91823","0.00208"
"95.23800","7.93670","0.00190"
"95.46000","7.95518","0.00202"
"95.68200","7.97371","0.00230"
"95.90400","7.99213","0.00235"
"96.12600","8.01072","0.00204"
"96.34800","8.02920","0.00223"
"96.57000","8.04773","0.00205"
"96.79200","8.06621","0.00196"
"97.01400","8.08468","0.00189"
"97.23600","8.10322","0.00219"
"97.45800","8.12169","0.00190"
"97.68000","8.14017","0.00198"
"97.90200","8.15870","0.00159"
"98.12400","8.17712","0.00170"
"98.34600","8.19565","0.00055"
"98.56800","8.21418","0.00090"
"98.79000","8.23272","0.00092"
"99.01200","8.25119","0.00002"
"99.23400","8.26967","0.00035"
"99.45600","8.28826","-0.00025"
"99.67800","8.30662","-0.00052"
"99.90000","8.32521","-0.00022"
"100.12200","8.34369","0.00015"
"100.34400","8.36216","-0.00014"
"100.56600","8.38070","-0.00045"
"100.78800","8.39911","-0.00032"
"101.01000","8.41777","-0.00036"
"101.23200","8.43618","-0.00033"
"101.45400","8.45472","-0.00022"
"101.67600","8.47319","-0.00010"
"101.89800","8.49173","-0.00046"
"102.12000","8.51020","-0.00038"
"102.34200","8.52868","-0.00001"
"102.56400","8.54721","-0.00062"
"102.78600","8.56569","-0.00008"
"103.00800","8.58416","0.00011"
"103.23000","8.60270","0.00009"
"103.45200","8.62117","0.00013"
"103.67400","8.63971","-0.00019"
"103.89600","8.65824","-0.00025"
"104.11800","8.67672","-0.00026"
"104.34000","8.69519","-0.00029"
"104.56200","8.71361","0.00014"
"104.78400","8.73220","0.00034"
"105.00600","8.75068","-0.00006"
"105.22800","8.76927","0.00024"
"105.45000","8.78775","0.00017"
"105.67200","8.80610","-0.00006"
"105.89400","8.82476","0.00004"
"106.11600","8.84323","0.00011"
"106.33800","8.86171","-0.00010"
"106.56000","8.88018","0.00006"
"106.78200","8.89866","0.00002"
"107.00400","8.91725","0.00020"
"107.22600","8.93567","0.00014"
"107.44800","8.95426","0.00027"
"107.67000","8.97267","0.00004"
"107.89200","8.99121","0.00012"
"108.11400","9.00974","-0.00031"
"108.33600","9.02816","0.00026"
"108.55800","9.04663","0.00003"
"108.78000","9.06517","-0.00015"
"109.00200","9.08370","0.00012"
"109.22400","9.10218","0.00042"
"109.44600","9.12065","-0.00020"
"109.66800","9.13925","0.00028"
"109.89000","9.15772","0.00022"
"110.11200","9.17626","0.00018"
"110.33400","9.19467","0.00023"
"110.55600","9.21321","0.00019"
"110.77800","9.23168","-0.00008"
"111.00000","9.25010","0.00002"
"111.22200","9.26875","0.00043"
"111.44400","9.28717","0.00042"
"111.66600","9.30570","0.00021"
"111.88800","9.32424","-0.00039"
"112.11000","9.34265","0.00023"
"112.33200","9.36125","0.00031"
"112.55400","9.37966","0.00025"
"112.77600","9.39826","0.00012"
"112.99800","9.41667","0.00008"
"113.22000","9.43521","0.00016"
"113.44200","9.45368","0.00044"
"113.66400","9.47216","0.00012"
"113.88600","9.49075","0.00000"
"114.10800","9.50923","0.00000"
"114.33000","9.52770","0.00069"
"114.55200","9.54624","0.00016"
"114.77400","9.56471","0.00045"
"114.99600","9.58319","0.00016"
"115.21800","9.60166","0.00070"
"115.44000","9.62020","0.00047"
"115.66200","9.63873","0.00037"
"115.88400","9.65709","0.00018"
"116.10600","9.67574","0.00084"
"116.32800","9.69416","0.00056"
"116.55000","9.71269","0.00065"
"116.77200","9.73123","0.00047"
"116.99400","9.74964","0.00035"
"117.21600","9.76818","0.00049"
"117.43800","9.78665","0.00068"
"117.66000","9.80524","0.00037"
"117.88200","9.82372","0.00010"
"118.10400","9.84219","0.00041"
"118.32600","9.86067","0.00030"
"118.54800","9.87920","0.00043"
"118.77000","9.89768","0.00034"
"118.99200","9.91615","0.00043"
"119.21400","9.93469","0.00006"
"119.43600","9.95316","0.00045"
"119.65800","9.97164","-0.00001"
"119.88000","9.99023","0.00010"
"120.10200","10.00871","0.00038"
"120.32400","10.02718","-0.00021"
"120.54600","10.04572","-0.00002"
"120.76800","10.06419","0.00040"
"120.99000","10.08279","0.00024"
"121.21200","10.10114","0.00036"
"121.43400","10.11968","0.00015"
"121.65600","10.13815","-0.00030"
"121.87800","10.15669","0.00061"
"122.10000","10.17522","0.00010"
"122.32200","10.19364","0.00027"
"122.54400","10.21229","0.00008"
"122.76600","10.23065","0.00005"
"122.98800","10.24924","0.00016"
"123.21000","10.26772","0.00036"
"123.43200","10.28619","0.00019"
"123.65400","10.30467","0.00017"
"123.87600","10.32314","0.00013"
"124.09800","10.34168","0.00029"
"124.32000","10.36021","-0.00002"
"124.54200","10.37869","0.00040"
"124.76400","10.39722","0.00027"
"124.98600","10.41570","0.00033"
"125.20800","10.43417","-0.00005"
"125.43000","10.45270","0.00021"
"125.65200","10.47118","-0.00043"
"125.87400","10.48972","0.00029"
"126.09600","10.50813","-0.00007"
"126.31800","10.52666","0.00027"
"126.54000","10.54520","0.00047"
"126.76200","10.56374","0.00063"
"126.98400","10.58221","-0.00010"
"127.20600","10.60068","0.00078"
"127.42800","10.61922","0.00041"
"127.65000","10.63769","0.00022"
"127.87200","10.65623","0.00033"
"128.09400","10.67464","0.00019"
"128.31600","10.69318","0.00036"
"128.53800","10.71171","0.00048"
"128.76000","10.73013","0.00058"
"128.98200","10.74872","0.00042"
"129.20400","10.76714","-0.00001"
"129.42600","10.78573","0.00016"
"129.64800","10.80421","0.00039"
"129.87000","10.82268","0.00025"
"130.09200","10.84116","0.00027"
"130.31400","10.85969","0.00038"
"130.53600","10.87823","0.00059"
"130.75800","10.89670","0.00050"
"130.98000","10.91512","0.00043"
"131.20200","10.93371","0.00041"
"131.42400","10.95213","0.00052"
"131.64600","10.97072","0.00045"
"131.86800","10.98926","0.00059"
"132.09000","11.00767","0.00045"
"132.31200","11.02621","0.00085"
"132.53400","11.04462","0.00071"
"132.75600","11.06322","0.00053"
"132.97800","11.08163","0.00085"
"133.20000","11.10023","0.00072"
"133.42200","11.11870","0.00094"
"133.64400","11.13718","0.00050"
"133.86600","11.15577","0.00020"
"134.08800","11.17419","0.00056"
"134.31000","11.19272","0.00030"
"134.53200","11.21119","0.00067"
"134.75400","11.22967","0.00036"
"134.97600","11.24821","0.00061"
"135.19800","11.26668","0.00055"
"135.42000","11.28521","0.00087"
"135.64200","11.30369","0.00046"
"135.86400","11.32222","0.00063"
"136.08600","11.34076","0.00062"
"136.30800","11.35917","0.00053"
"136.53000","11.37771","0.00056"
"136.75200","11.39618","0.00074"
"136.97400","11.41466","0.00078"
"137.19600","11.43325","0.00032"
"137.41800","11.45167","0.00100"
"137.64000","11.47020","0.00060"
"137.86200","11.48868","0.00064"
"138.08400","11.50727","0.00058"
"138.30600","11.52569","0.00100"
"138.52800","11.54422","0.00074"
"138.75000","11.56270","0.00065"
"138.97200","11.58111","0.00095"
"139.19400","11.59971","0.00040"
"139.41600","11.61818","0.00051"
"139.63800","11.63678","0.00069"
"139.86000","11.65519","0.00079"
"140.08200","11.67367","0.00090"
"140.30400","11.69220","0.00083"
"140.52600","11.71068","0.00056"
"140.74800","11.72921","0.00076"
"140.97000","11.74769","0.00044"
"141.19200","11.76622","0.00042"
"141.41400","11.78470","0.00070"
"141.63600","11.80317","0.00083"
"141.85800","11.82171","0.00107"
"142.08000","11.84024","0.00102"
"142.30200","11.85866","0.00080"
"142.52400","11.87725","0.00080"
"142.74600","11.89561","0.00105"
"142.96800","11.91414","0.00117"
"143.19000","11.93267","0.00124"
"143.41200","11.95121","0.00074"
"143.63400","11.96974","0.00070"
"143.85600","11.98816","0.00074"
"144.07800","12.00669","0.00079"
"144.30000","12.02517","0.00026"
"144.52200","12.04370","0.00024"
"144.74400","12.06218","0.00110"
"144.96600","12.08072","0.00044"
"145.18800","12.09919","0.00095"
"145.41000","12.11760","0.00050"
"145.63200","12.13626","0.00053"
"145.85400","12.15467","0.00067"
"146.07600","12.17321","0.00039"
"146.29800","12.19168","0.00064"
"146.52000","12.21016","0.00093"
"146.74200","12.22869","0.00092"
"146.96400","12.24717","0.00058"
"147.18600","12.26570","0.00084"
"147.40800","12.28418","0.00075"
"147.63000","12.30265","0.00076"
"147.85200","12.32125","0.00023"
"148.07400","12.33972","0.00029"
"148.29600","12.35826","0.00037"
"148.51800","12.37673","0.00043"
"148.74000","12.39515","0.00078"
"148.96200","12.41374","0.00066"
"149.18400","12.43216","0.00080"
"149.40600","12.45075","0.00025"
"149.62800","12.46917","0.00032"
"149.85000","12.48764","0.00122"
"150.07200","12.50624","0.00022"
"150.29400","12.52465","0.00046"
"150.51600","12.54325","0.00054"
"150.73800","12.56166","0.00052"
"150.96000","12.58020","0.00013"
"151.18200","12.59873","0.00061"
"151.40400","12.61715","0.00030"
"151.62600","12.63568","0.00055"
"151.84800","12.65416","0.00072"
"152.07000","12.67269","0.00059"
"152.29200","12.69116","0.00033"
"152.51400","12.70970","0.00006"
"152.73600","12.72818","0.00035"
"152.95800","12.74671","0.00050"
"153.18000","12.76525","0.00099"
"153.40200","12.78372","0.00055"
"153.62400","12.80219","0.00042"
"153.84600","12.82073","0.00033"
"154.06800","12.83914","0.00079"
"154.29000","12.85774","0.00043"
"154.51200","12.87621","0.00092"
"154.73400","12.89469","0.00073"
"154.95600","12.91322","0.00060"
"155.17800","12.93170","0.00064"
"155.40000","12.95017","0.00033"
"155.62200","12.96865","0.00079"
"155.84400","12.98724","0.00104"
"156.06600","13.00572","0.00063"
"156.28800","13.02425","0.00002"
"156.51000","13.04273","0.00022"
"156.73200","13.06114","0.00062"
"156.95400","13.07974","0.00031"
"157.17600","13.09815","0.00048"
"157.39800","13.11675","0.00019"
"157.62000","13.13516","0.00076"
"157.84200","13.15370","0.00051"
"158.06400","13.17217","0.00004"
"158.28600","13.19065","0.00071"
"158.50800","13.20918","0.00056"
"158.73000","13.22772","0.00059"
"158.95200","13.24613","0.00052"
"159.17400","13.26473","0.00025"
"159.39600","13.28314","0.00070"
"159.61800","13.30174","0.00036"
"159.84000","13.32021","0.00102"
"160.06200","13.33869","0.00067"
"160.28400","13.35728","0.00105"
"160.50600","13.37564","0.00021"
"160.72800","13.39429","0.00032"
"160.95000","13.41271","0.00084"
"161.17200","13.43124","0.00075"
"161.39400","13.44966","0.00056"
"161.61600","13.46819","0.00081"
"161.83800","13.48672","0.00065"
"162.06000","13.50520","0.00082"
"162.28200","13.52374","0.00024"
"162.50400","13.54215","0.00069"
"162.72600","13.56069","0.00097"
"162.94800","13.57922","0.00017"
"163.17000","13.59764","0.00052"
"163.39200","13.61623","0.00086"
"163.61400","13.63465","0.00086"
"163.83600","13.65318","0.00127"
"164.05800","13.67177","0.00050"
"164.28000","13.69019","0.00072"
"164.50200","13.70866","0.00074"
"164.72400","13.72714","0.00080"
"164.94600","13.74567","0.00030"
"165.16800","13.76427","0.00082"
"165.39000","13.78262","0.00069"
"165.61200","13.80128","0.00073"
"165.83400","13.81963","0.00102"
"166.05600","13.83829","0.00056"
"166.27800","13.85670","0.00067"
"166.50000","13.87524","0.00038"
"166.72200","13.89377","0.00052"
"166.94400","13.91219","0.00039"
"167.16600","13.93072","0.00049"
"167.38800","13.94920","0.00066"
"167.61000","13.96767","0.00054"
"167.83200","13.98621","0.00046"
"168.05400","14.00468","0.00024"
"168.27600","14.02316","0.00051"
"168.49800","14.04169","-0.00007"
"168.72000","14.06023","0.00053"
"168.94200","14.07870","0.00053"
"169.16400","14.09718","0.00056"
"169.38600","14.11565","0.00022"
"169.60800","14.13419","0.00040"
"169.83000","14.15266","0.00028"
"170.05200","14.17120","0.00049"
"170.27400","14.18961","0.00022"
"170.49600","14.20821","0.00017"
"170.71800","14.22668","0.00041"
"170.94000","14.24522","0.00047"
"171.16200","14.26369","0.00063"
"171.38400","14.28217","0.00067"
"171.60600","14.30076","0.00060"
"171.82800","14.31911","0.00069"
"172.05000","14.33771","0.00075"
"172.27200","14.35618","0.00066"
"172.49400","14.37472","0.00017"
"172.71600","14.39319","0.00050"
"172.93800","14.41167","0.00085"
"173.16000","14.43020","0.00033"
"173.38200","14.44868","0.00084"
"173.60400","14.46727","0.00065"
"173.82600","14.48569","0.00061"
"174.04800","14.50422","0.00064"
"174.27000","14.52276","0.00066"
"174.49200","14.54117","0.00073"
"174.71400","14.55971","0.00039"
"174.93600","14.57818","0.00048"
"175.15800","14.59666","0.00075"
"175.38000","14.61519","0.00109"
"175.60200","14.63367","0.00041"
"175.82400","14.65220","0.00010"
"176.04600","14.67068","0.00022"
"176.26800","14.68921","0.00057"
"176.49000","14.70769","0.00061"
"176.71200","14.72616","0.00064"
"176.93400","14.74476","0.00046"
"177.15600","14.76317","0.00109"
"177.37800","14.78177","0.00020"
"177.60000","14.80018","0.00042"
"177.82200","14.81872","0.00088"
"178.04400","14.83719","0.00035"
"178.26600","14.85567","0.00032"
"178.48800","14.87420","0.00052"
"178.71000","14.89274","0.00051"
"178.93200","14.91121","0.00061"
"179.15400","14.92969","0.00037"
"179.37600","14.94822","0.00097"
"179.59800","14.96663","0.00046"
"179.82000","14.98517","0.00034"
"180.04200","15.00371","0.00023"
"180.26400","15.02224","0.00063"
"180.48600","15.04066","0.00076"
"180.70800","15.05925","0.00045"
"180.93000","15.07767","0.00069"
"181.15200","15.09620","0.00075"
"181.37400","15.11473","0.00084"
"181.59600","15.13321","0.00057"
"181.81800","15.15174","0.00034"
"182.04000","15.17010","0.00058"
"182.26200","15.18869","0.00054"
"182.48400","15.20717","0.00038"
"182.70600","15.22570","0.00035"
"182.92800","15.24418","0.00046"
"183.15000","15.26259","0.00050"
"183.37200","15.28125","0.00076"
"183.59400","15.29972","0.00058"
"183.81600","15.31820","0.00077"
"184.03800","15.33667","0.00107"
"184.26000","15.35521","0.00078"
"184.48200","15.37374","0.00070"
"184.70400","15.39216","0.00044"
"184.92600","15.41069","0.00039"
"185.14800","15.42923","0.00064"
"185.37000","15.44764","0.00039"
"185.59200","15.46618","0.00038"
"185.81400","15.48471","0.00071"
"186.03600","15.50319","0.00050"
"186.25800","15.52172","0.00037"
"186.48000","15.54020","0.00082"
"186.70200","15.55873","0.00000"
"186.92400","15.57715","0.00084"
"187.14600","15.59568","0.00077"
"187.36800","15.61416","0.00059"
"187.59000","15.63269","0.00063"
"187.81200","15.65117","0.00086"
"188.03400","15.66970","0.00072"
"188.25600","15.68824","0.00083"
"188.47800","15.70665","0.00107"
"188.70000","15.72524","0.00067"
"188.92200","15.74366","0.00114"
"189.14400","15.76219","0.00067"
"189.36600","15.78073","0.00060"
"189.58800","15.79914","0.00069"
"189.81000","15.81768","0.00057"
"190.03200","15.83615","0.00102"
"190.25400","15.85475","0.00089"
"190.47600","15.87316","0.00064"
"190.69800","15.89170","0.00073"
"190.92000","15.91017","0.00050"
"191.14200","15.92865","0.00070"
"191.36400","15.94724","0.00090"
"191.58600","15.96572","0.00037"
"191.80800","15.98419","0.00050"
"192.03000","16.00273","0.00042"
"192.25200","16.02114","0.00100"
"192.47400","16.03974","0.00073"
"192.69600","16.05821","0.00053"
"192.91800","16.07669","0.00104"
"193.14000","16.09522","0.00047"
"193.36200","16.11358","0.00038"
"193.58400","16.13223","0.00077"
"193.80600","16.15065","0.00050"
"194.02800","16.16924","0.00029"
"194.25000","16.18772","0.00059"
"194.47200","16.20619","0.00085"
"194.69400","16.22473","0.00072"
"194.91600","16.24314","0.00072"
"195.13800","16.26168","0.00083"
"195.36000","16.28021","0.00049"
"195.58200","16.29869","0.00085"
"195.80400","16.31716","0.00036"
"196.02600","16.33564","0.00055"
"196.24800","16.35423","0.00041"
"196.47000","16.37271","0.00086"
"196.69200","16.39124","0.00066"
"196.91400","16.40972","0.00056"
"197.13600","16.42819","0.00098"
"197.35800","16.44672","0.00100"
"197.58000","16.46520","0.00086"
"197.80200","16.48368","0.00061"
"198.02400","16.50221","0.00076"
"198.24600","16.52069","0.00053"
"198.46800","16.53922","0.00054"
"198.69000","16.55763","0.00094"
"198.91200","16.57623","0.00060"
"199.13400","16.59470","0.00098"
"199.35600","16.61318","0.00111"
"199.57800","16.63171","0.00063"
"199.80000","16.65013","0.00036"
"200.02200","16.66872","0.00074"
"200.24400","16.68714","0.00070"
"200.46600","16.70573","0.00050"
"200.68800","16.72421","0.00094"
"200.91000","16.74268","0.00086"
"201.13200","16.76122","0.00084"
"201.35400","16.77963","0.00115"
"201.57600","16.79817","0.00109"
"201.79800","16.81670","0.00100"
"202.02000","16.83518","0.00098"
"202.24200","16.85371","0.00115"
"202.46400","16.87219","0.00105"
"202.68600","16.89066","0.00096"
"202.90800","16.90920","0.00104"
"203.13000","16.92767","0.00106"
"203.35200","16.94621","0.00117"
"203.57400","16.96462","0.00121"
"203.79600","16.98322","0.00098"
"204.01800","17.00169","0.00125"
"204.24000","17.02023","0.00095"
"204.46200","17.03870","0.00129"
"204.68400","17.05718","0.00144"
"204.90600","17.07577","0.00155"
"205.12800","17.09418","0.00081"
"205.35000","17.11278","0.00076"
"205.57200","17.13114","0.00147"
"205.79400","17.14967","0.00117"
"206.01600","17.16821","0.00150"
"206.23800","17.18668","0.00150"
"206.46000","17.20522","0.00131"
"206.68200","17.22363","0.00122"
"206.90400","17.24223","0.00115"
"207.12600","17.26076","0.00151"
"207.34800","17.27917","0.00141"
"207.57000","17.29771","0.00126"
"207.79200","17.31618","0.00163"
"208.01400","17.33472","0.00150"
"208.23600","17.35325","0.00157"
"208.45800","17.37161","0.00129"
"208.68000","17.39021","0.00165"
"208.90200","17.40862","0.00141"
"209.12400","17.42727","0.00162"
"209.34600","17.44575","0.00194"
"209.56800","17.46422","0.00196"
"209.79000","17.48276","0.00191"
"210.01200","17.50111","0.00173"
"210.23400","17.51971","0.00179"
"210.45600","17.53818","0.00184"
"210.67800","17.55672","0.00154"
"210.90000","17.57525","0.00171"
"211.12200","17.59367","0.00168"
"211.34400","17.61220","0.00161"
"211.56600","17.63068","0.00162"
"211.78800","17.64921","0.00167"
"212.01000","17.66769","0.00199"
"212.23200","17.68616","0.00127"
"212.45400","17.70470","0.00193"
"212.67600","17.72317","0.00184"
"212.89800","17.74171","0.00180"
"213.12000","17.76018","0.00176"
"213.34200","17.77866","0.00188"
"213.56400","17.79719","0.00208"
"213.78600","17.81567","0.00213"
"214.00800","17.83420","0.00162"
"214.23000","17.85274","0.00187"
"214.45200","17.87115","0.00242"
"214.67400","17.88975","0.00178"
"214.89600","17.90816","0.00179"
"215.11800","17.92669","0.00191"
"215.34000","17.94511","0.00234"
"215.56200","17.96371","0.00229"
"215.78400","17.98224","0.00241"
"216.00600","18.00072","0.00214"
"216.22800","18.01919","0.00213"
"216.45000","18.03767","0.00236"
"216.67200","18.05620","0.00195"
"216.89400","18.07467","0.00271"
"217.11600","18.09321","0.00192"
"217.33800","18.11168","0.00263"
"217.56000","18.13016","0.00236"
"217.78200","18.14869","0.00207"
"218.00400","18.16717","0.00242"
"218.22600","18.18570","0.00232"
"218.44800","18.20424","0.00245"
"218.67000","18.22265","0.00255"
"218.89200","18.24125","0.00242"
"219.11400","18.25966","0.00224"
"219.33600","18.27820","0.00278"
"219.55800","18.29673","0.00239"
"219.78000","18.31515","0.00210"
"220.00200","18.33374","0.00210"
"220.22400","18.35216","0.00261"
"220.44600","18.37069","0.00260"
"220.66800","18.38917","0.00223"
"220.89000","18.40770","0.00260"
"221.11200","18.42624","0.00224"
"221.33400","18.44459","0.00233"
"221.55600","18.46319","0.00249"
"221.77800","18.48166","0.00252"
"222.00000","18.50020","0.00250"
"222.22200","18.51867","0.00214"
"222.44400","18.53721","0.00205"
"222.66600","18.55568","0.00255"
"222.88800","18.57416","0.00218"
"223.11000","18.59275","0.00189"
"223.33200","18.61117","0.00202"
"223.55400","18.62970","0.00183"
"223.77600","18.64824","0.00208"
"223.99800","18.66659","0.00163"
"224.22000","18.68525","0.00238"
"224.44200","18.70372","0.00232"
"224.66400","18.72226","0.00192"
"224.88600","18.74073","0.00227"
"225.10800","18.75915","0.00177"
"225.33000","18.77768","0.00220"
"225.55200","18.79622","0.00213"
"225.77400","18.81469","0.00197"
"225.99600","18.83323","0.00231"
"226.21800","18.85164","0.00208"
"226.44000","18.87024","0.00259"
"226.66200","18.88865","0.00205"
"226.88400","18.90724","0.00266"
"227.10600","18.92566","0.00263"
"227.32800","18.94419","0.00233"
"227.55000","18.96273","0.00254"
"227.77200","18.98114","0.00238"
"227.99400","18.99968","0.00247"
"228.21600","19.01815","0.00237"
"228.43800","19.03669","0.00227"
"228.66000","19.05522","0.00207"
"228.88200","19.07370","0.00250"
"229.10400","19.09217","0.00193"
"229.32600","19.11065","0.00257"
"229.54800","19.12918","0.00229"
"229.77000","19.14772","0.00209"
"229.99200","19.16619","0.00200"
"230.21400","19.18473","0.00225"
"230.43600","19.20320","0.00240"
"230.65800","19.22168","0.00223"
"230.88000","19.24021","0.00248"
"231.10200","19.25869","0.00238"
"231.32400","19.27716","0.00225"
"231.54600","19.29564","0.00255"
"231.76800","19.31423","0.00205"
"231.99000","19.33265","0.00211"
"232.21200","19.35118","0.00288"
"232.43400","19.36972","0.00250"
"232.65600","19.38813","0.00280"
"232.87800","19.40673","0.00273"
"233.10000","19.42514","0.00212"
"233.32200","19.44379","0.00240"
"233.54400","19.46215","0.00282"
"233.76600","19.48075","0.00255"
"233.98800","19.49922","0.00293"
"234.21000","19.51764","0.00293"
"234.43200","19.53623","0.00287"
"234.65400","19.55470","0.00261"
"234.87600","19.57324","0.00266"
"235.09800","19.59171","0.00255"
"235.32000","19.61019","0.00278"
"235.54200","19.62872","0.00294"
"235.76400","19.64714","0.00299"
"235.98600","19.66568","0.00268"
"236.20800","19.68427","0.00213"
"236.43000","19.70263","0.00259"
"236.65200","19.72122","0.00264"
"236.87400","19.73963","0.00298"
"237.09600","19.75823","0.00296"
"237.31800","19.77676","0.00259"
"237.54000","19.79518","0.00220"
"237.76200","19.81371","0.00281"
"237.98400","19.83213","0.00135"
"238.20600","19.85072","0.00156"
"238.42800","19.86913","0.00165"
"238.65000","19.88767","0.00060"
"238.87200","19.90621","0.00131"
"239.09400","19.92468","0.00140"
"239.31600","19.94321","0.00076"
"239.53800","19.96175","0.00178"
"239.76000","19.98023","0.00103"
"239.98200","19.99870","0.00102"
"240.20400","20.01723","0.00128"
"240.42600","20.03571","0.00116"
"240.64800","20.05419","0.00090"
"240.87000","20.07272","0.00149"
"241.09200","20.09120","0.00097"
"241.31400","20.10967","0.00149"
"241.53600","20.12815","0.00173"
"241.75800","20.14662","0.00125"
"241.98000","20.16516","0.00175"
"242.20200","20.18369","0.00126"
"242.42400","20.20222","0.00149"
"242.64600","20.22076","0.00141"
"242.86800","20.23911","0.00165"
"243.09000","20.25771","0.00166"
"243.31200","20.27619","0.00163"
"243.53400","20.29472","0.00158"
"243.75600","20.31320","0.00144"
"243.97800","20.33167","0.00156"
"244.20000","20.35020","0.00164"
"244.42200","20.36862","0.00138"
"244.64400","20.38721","0.00188"
"244.86600","20.40569","0.00156"
"245.08800","20.42422","0.00134"
"245.31000","20.44270","0.00185"
"245.53200","20.46117","0.00146"
"245.75400","20.47971","0.00119"
"245.97600","20.49824","0.00199"
"246.19800","20.51666","0.00195"
"246.42000","20.53519","0.00180"
"246.64200","20.55367","0.00202"
"246.86400","20.57220","0.00175"
"247.08600","20.59068","0.00206"
"247.30800","20.60921","0.00204"
"247.53000","20.62775","0.00193"
"247.75200","20.64616","0.00205"
"247.97400","20.66475","0.00203"
"248.19600","20.68317","0.00200"
"248.41800","20.70171","0.00180"
"248.64000","20.72012","0.00268"
"248.86200","20.73866","0.00174"
"249.08400","20.75719","0.00205"
"249.30600","20.77567","0.00228"
"249.52800","20.79420","0.00179"
"249.75000","20.81262","0.00215"
"249.97200","20.83127","0.00224"
"250.19400","20.84969","0.00172"
"250.41600","20.86822","0.00177"
"250.63800","20.88670","0.00224"
"250.86000","20.90517","0.00225"
"251.08200","20.92371","0.00178"
"251.30400","20.94218","0.00240"
"251.52600","20.96072","0.00236"
"251.74800","20.97925","0.00187"
"251.97000","20.99767","0.00196"
"252.19200","21.01626","0.00210"
"252.41400","21.03468","0.00222"
"252.63600","21.05321","0.00206"
"252.85800","21.07174","0.00240"
"253.08000","21.09016","0.00221"
"253.30200","21.10869","0.00222"
"253.52400","21.12717","0.00214"
"253.74600","21.14570","0.00190"
"253.96800","21.16424","0.00271"
"254.19000","21.18266","0.00215"
"254.41200","21.20125","0.00210"
"254.63400","21.21967","0.00201"
"254.85600","21.23820","0.00215"
"255.07800","21.25667","0.00226"
"255.30000","21.27521","0.00222"
"255.52200","21.29368","0.00168"
"255.74400","21.31216","0.00226"
"255.96600","21.33075","0.00213"
"256.18800","21.34923","0.00225"
"256.41000","21.36770","0.00211"
"256.63200","21.38624","0.00163"
"256.85400","21.40471","0.00194"
"257.07600","21.42319","0.00215"
"257.29800","21.44166","0.00226"
"257.52000","21.46014","0.00237"
"257.74200","21.47867","0.00272"
"257.96400","21.49714","0.00210"
"258.18600","21.51568","0.00214"
"258.40800","21.53416","0.00263"
"258.63000","21.55269","0.00268"
"258.85200","21.57123","0.00290"
"259.07400","21.58970","0.00221"
"259.29600","21.60824","0.00242"
"259.51800","21.62659","0.00236"
"259.74000","21.64519","0.00194"
"259.96200","21.66366","0.00275"
"260.18400","21.68220","0.00273"
"260.40600","21.70073","0.00239"
"260.62800","21.71915","0.00272"
"260.85000","21.73774","0.00247"
"261.07200","21.75615","0.00258"
"261.29400","21.77475","0.00240"
"261.51600","21.79317","0.00259"
"261.73800","21.81170","0.00255"
"261.96000","21.83018","0.00250"
"262.18200","21.84865","0.00277"
"262.40400","21.86719","0.00234"
"262.62600","21.88572","0.00254"
"262.84800","21.90419","0.00196"
"263.07000","21.92273","0.00255"
"263.29200","21.94121","0.00200"
"263.51400","21.95968","0.00246"
"263.73600","21.97815","0.00277"
"263.95800","21.99669","0.00218"
"264.18000","22.01516","0.00281"
"264.40200","22.03364","0.00209"
"264.62400","22.05223","0.00251"
"264.84600","22.07065","0.00267"
"265.06800","22.08918","0.00248"
"265.29000","22.10772","0.00286"
"265.51200","22.12619","0.00247"
"265.73400","22.14473","0.00271"
"265.95600","22.16314","0.00242"
"266.17800","22.18174","0.00241"
"266.40000","22.20015","0.00268"
"266.62200","22.21869","0.00257"
"266.84400","22.23722","0.00264"
"267.06600","22.25564","0.00255"
"267.28800","22.27417","0.00249"
"267.51000","22.29271","0.00283"
"267.73200","22.31124","0.00274"
"267.95400","22.32972","0.00294"
"268.17600","22.34819","0.00305"
"268.39800","22.36673","0.00301"
"268.62000","22.38520","0.00227"
"268.84200","22.40374","0.00327"
"269.06400","22.42221","0.00281"
"269.28600","22.44069","0.00317"
"269.50800","22.45922","0.00305"
"269.73000","22.47770","0.00298"
"269.95200","22.49623","0.00332"
"270.17400","22.51465","0.00305"
"270.39600","22.53318","0.00296"
"270.61800","22.55177","0.00292"
"270.84000","22.57013","0.00290"
"271.06200","22.58873","0.00373"
"271.28400","22.60720","0.00337"
"271.50600","22.62567","0.00356"
"271.72800","22.64421","0.00361"
"271.95000","22.66268","0.00343"
"272.17200","22.68116","0.00383"
"272.39400","22.69963","0.00298"
"272.61600","22.71823","0.00362"
"272.83800","22.73670","0.00365"
"273.06000","22.75518","0.00397"
"273.28200","22.77371","0.00385"
"273.50400","22.79219","0.00358"
"273.72600","22.81066","0.00353"
"273.94800","22.82920","0.00390"
"274.17000","22.84767","0.00420"
"274.39200","22.86621","0.00391"
"274.61400","22.88462","0.00413"
"274.83600","22.90322","0.00446"
"275.05800","22.92169","0.00421"
"275.28000","22.94023","0.00480"
"275.50200","22.95870","0.00456"
"275.72400","22.97718","0.00490"
"275.94600","22.99571","0.00447"
"276.16800","23.01413","0.00445"
"276.39000","23.03278","0.00457"
"276.61200","23.05120","0.00444"
"276.83400","23.06967","0.00477"
"277.05600","23.08821","0.00455"
"277.27800","23.10662","0.00501"
"277.50000","23.12522","0.00469"
"277.72200","23.14369","0.00471"
"277.94400","23.16223","0.00546"
"278.16600","23.18070","0.00549"
"278.38800","23.19917","0.00497"
"278.61000","23.21771","0.00517"
"278.83200","23.23619","0.00508"
"279.05400","23.25466","0.00516"
"279.27600","23.27319","0.00556"
"279.49800","23.29167","0.00515"
"279.72000","23.31021","0.00508"
"279.94200","23.32868","0.00618"
"280.16400","23.34716","0.00543"
"280.38600","23.36569","0.00610"
"280.60800","23.38416","0.00596"
"280.83000","23.40270","0.00667"
"281.05200","23.42112","0.00708"
"281.27400","23.43971","0.00675"
"281.49600","23.45818","0.00612"
"281.71800","23.47672","0.00638"
"281.94000","23.49519","0.00695"
"282.16200","23.51367","0.00608"
"282.38400","23.53226","0.00713"
"282.60600","23.55068","0.00685"
"282.82800","23.56927","0.00782"
"283.05000","23.58763","0.00747"
"283.27200","23.60616","0.00797"
"283.49400","23.62470","0.00699"
"283.71600","23.64317","0.00797"
"283.93800","23.66171","0.00846"
"284.16000","23.68018","0.00773"
"284.38200","23.69872","0.00780"
"284.60400","23.71725","0.00329"
"284.82600","23.73561","0.00437"
"285.04800","23.75420","0.00156"
"285.27000","23.77262","0.00147"
"285.49200","23.79121","0.00168"
"285.71400","23.80975","0.00245"
"285.93600","23.82816","0.00177"
"286.15800","23.84676","0.00155"
"286.38000","23.86517","0.00161"
"286.60200","23.88371","0.00190"
"286.82400","23.90218","0.00185"
"287.04600","23.92066","0.00209"
"287.26800","23.93925","0.00152"
"287.49000","23.95761","0.00183"
"287.71200","23.97626","0.00195"
"287.93400","23.99468","0.00196"
"288.15600","24.01321","0.00170"
"288.37800","24.03168","0.00220"
"288.60000","24.05016","0.00201"
"288.82200","24.06870","0.00218"
"289.04400","24.08717","0.00215"
"289.26600","24.10570","0.00252"
"289.48800","24.12418","0.00204"
"289.71000","24.14271","0.00271"
"289.93200","24.16119","0.00248"
"290.15400","24.17972","0.00234"
"290.37600","24.19820","0.00238"
"290.59800","24.21673","0.00204"
"290.82000","24.23515","0.00200"
"291.04200","24.25374","0.00257"
"291.26400","24.27216","0.00222"
"291.48600","24.29075","0.00284"
"291.70800","24.30917","0.00246"
"291.93000","24.32770","0.00266"
"292.15200","24.34618","0.00273"
"292.37400","24.36465","0.00275"
"292.59600","24.38319","0.00233"
"292.81800","24.40166","0.00275"
"293.04000","24.42020","0.00256"
"293.26200","24.43873","0.00269"
"293.48400","24.45721","0.00260"
"293.70600","24.47568","0.00315"
"293.92800","24.49416","0.00316"
"294.15000","24.51275","0.00293"
"294.37200","24.53117","0.00300"
"294.59400","24.54970","0.00313"
"294.81600","24.56818","0.00312"
"295.03800","24.58665","0.00297"
"295.26000","24.60519","0.00307"
"295.48200","24.62372","0.00339"
"295.70400","24.64220","0.00296"
"295.92600","24.66067","0.00297"
"296.14800","24.67914","0.00329"
"296.37000","24.69774","0.00355"
"296.59200","24.71616","0.00311"
"296.81400","24.73475","0.00297"
"297.03600","24.75322","-0.00064"
"297.25800","24.77164","0.00093"
"297.48000","24.79024","0.00109"
"297.70200","24.80865","-0.00024"
"297.92400","24.82719","-0.00051"
"298.14600","24.84572","0.00101"
"298.36800","24.86419","0.00035"
"298.59000","24.88273","-0.00046"
"298.81200","24.90114","0.00002"
"299.03400","24.91974","0.00102"
"299.25600","24.93815","0.00004"
"299.47800","24.95675","-0.00056"
"299.70000","24.97517","0.00053"
"299.92200","24.99370","0.00074"
"300.14400","25.01223","0.00003"
"300.36600","25.03065","-0.00042"
"300.58800","25.04918","0.00117"
"300.81000","25.06766","0.00052"
"301.03200","25.08619","0.00026"
"301.25400","25.10473","0.00086"
"301.47600","25.12314","0.00076"
"301.69800","25.14168","0.00090"
"301.92000","25.16021","0.00072"
"302.14200","25.17869","0.00064"
"302.36400","25.19716","0.00091"
"302.58600","25.21564","0.00079"
"302.80800","25.23417","0.00162"
"303.03000","25.25265","0.00077"
"303.25200","25.27118","0.00027"
"303.47400","25.28972","0.00127"
"303.69600","25.30813","0.00106"
"303.91800","25.32673","0.00073"
"304.14000","25.34520","0.00115"
"304.36200","25.36374","0.00121"
"304.58400","25.38215","0.00130"
"304.80600","25.40063","0.00130"
"305.02800","25.41922","0.00160"
"305.25000","25.43764","0.00141"
"305.47200","25.45623","0.00099"
"305.69400","25.47471","0.00181"
"305.91600","25.49318","0.00148"
"306.13800","25.51172","0.00176"
"306.36000","25.53019","0.00149"
"306.58200","25.54866","0.00143"
"306.80400","25.56714","0.00188"
"307.02600","25.58568","0.00195"
"307.24800","25.60421","0.00168"
"307.47000","25.62269","0.00149"
"307.69200","25.64122","0.00201"
"307.91400","25.65969","0.00259"
"308.13600","25.67823","0.00206"
"308.35800","25.69676","0.00231"
"308.58000","25.71518","0.00201"
"308.80200","25.73371","0.00219"
"309.02400","25.75213","0.00279"
"309.24600","25.77066","0.00231"
"309.46800","25.78914","0.00226"
"309.69000","25.80767","0.00233"
"309.91200","25.82621","0.00296"
"310.13400","25.84462","0.00330"
"310.35600","25.86322","0.00317"
"310.57800","25.88169","0.00280"
"310.80000","25.90029","0.00260"
"311.02200","25.91864","0.00339"
"311.24400","25.93718","0.00319"
"311.46600","25.95572","0.00352"
"311.68800","25.97419","0.00340"
"311.91000","25.99272","0.00329"
"312.13200","26.01120","0.00389"
"312.35400","26.02967","0.00234"
"312.57600","26.04821","0.00157"
"312.79800","26.06668","0.00177"
"313.02000","26.08522","0.00023"
"313.24200","26.10363","0.00067"
"313.46400","26.12217","0.00199"
"313.68600","26.14076","0.00111"
"313.90800","26.15912","0.00135"
"314.13000","26.17771","0.00145"
"314.35200","26.19619","0.00153"
"314.57400","26.21472","0.00117"
"314.79600","26.23320","0.00121"
"315.01800","26.25167","0.00101"
"315.24000","26.27021","0.00108"
"315.46200","26.28862","0.00120"
"315.68400","26.30727","0.00095"
"315.90600","26.32569","0.00175"
"316.12800","26.34423","0.00144"
"316.35000","26.36270","0.00050"
"316.57200","26.38117","0.00135"
"316.79400","26.39971","0.00136"
"317.01600","26.41818","0.00140"
"317.23800","26.43672","0.00120"
"317.46000","26.45520","0.00135"
"317.68200","26.47367","0.00140"
"317.90400","26.49214","0.00161"
"318.12600","26.51068","0.00156"
"318.34800","26.52921","0.00177"
"318.57000","26.54775","0.00130"
"318.79200","26.56616","0.00173"
"319.01400","26.58476","0.00182"
"319.23600","26.60312","0.00174"
"319.45800","26.62171","0.00153"
"319.68000","26.64018","0.00182"
"319.90200","26.65872","0.00196"
"320.12400","26.67725","0.00224"
"320.34600","26.69561","0.00198"
"320.56800","26.71420","0.00213"
"320.79000","26.73268","0.00210"
"321.01200","26.75121","0.00238"
"321.23400","26.76969","0.00271"
"321.45600","26.78816","0.00238"
"321.67800","26.80670","0.00234"
"321.90000","26.82517","0.00255"
"322.12200","26.84371","0.00238"
"322.34400","26.86218","0.00266"
"322.56600","26.88072","0.00214"
"322.78800","26.89919","0.00213"
"323.01000","26.91767","0.00204"
"323.23200","26.93614","0.00208"
"323.45400","26.95474","0.00202"
"323.67600","26.97315","0.00192"
"323.89800","26.99169","0.00207"
"324.12000","27.01010","0.00226"
"324.34200","27.02869","0.00153"
"324.56400","27.04723","0.00199"
"324.78600","27.06577","0.00175"
"325.00800","27.08418","0.00188"
"325.23000","27.10266","0.00256"
"325.45200","27.12125","0.00223"
"325.67400","27.13966","0.00190"
"325.89600","27.15826","0.00230"
"326.11800","27.17662","0.00220"
"326.34000","27.19515","0.00230"
"326.56200","27.21375","0.00232"
"326.78400","27.23216","0.00265"
"327.00600","27.25076","0.00272"
"327.22800","27.26917","0.00335"
"327.45000","27.28776","0.00297"
"327.67200","27.30618","0.00314"
"327.89400","27.32472","0.00332"
"328.11600","27.34319","0.00258"
"328.12600","27.34403","0.00263"