File: Force_trajectories/170121_1/Specimen_RawData_1.csv
End date,"1/21/2017"
Specimen label,"19DT_NT"
Maximum Load,"0.07495",N

Time,Extension,Load
(s),(mm),(N)
"0.00000","0.00000","-0.00688"
"0.15600","0.00825","-0.00704"
"0.31200","0.02541","-0.00634"
"0.46800","0.03934","-0.00627"
"0.62400","0.05220","-0.00609"
"0.78000","0.06511","-0.00584"
"0.93600","0.07820","-0.00662"
"1.09200","0.09124","-0.00601"
"1.24800","0.10415","-0.00646"
"1.40400","0.11713","-0.00577"
"1.56000","0.13022","-0.00587"
"1.71600","0.14314","-0.00568"
"1.87200","0.15617","-0.00522"
"2.02800","0.16926","-0.00510"
"2.18400","0.18224","-0.00508"
"2.34000","0.19515","-0.00486"
"2.49600","0.20819","-0.00491"
"2.65200","0.22122","-0.00503"
"2.80800","0.23414","-0.00464"
"2.96400","0.24711","-0.00506"
"3.12000","0.26014","-0.00490"
"3.27600","0.27318","-0.00476"
"3.43200","0.28615","-0.00467"
"3.58800","0.29919","-0.00379"
"3.74400","0.31222","-0.00457"
"3.90000","0.32520","-0.00407"
"4.05600","0.33817","-0.00395"
"4.21200","0.35120","-0.00451"
"4.36800","0.36418","-0.00453"
"4.52400","0.37715","-0.00382"
"4.68000","0.39019","-0.00355"
"4.83600","0.40316","-0.00428"
"4.99200","0.41619","-0.00358"
"5.14800","0.42917","-0.00378"
"5.30400","0.44214","-0.00362"
"5.46000","0.45518","-0.00374"
"5.61600","0.46815","-0.00374"
"5.77200","0.48119","-0.00323"
"5.92800","0.49422","-0.00303"
"6.08400","0.50713","-0.00335"
"6.24000","0.52017","-0.00346"
"6.39600","0.53314","-0.00309"
"6.55200","0.54618","-0.00297"
"6.70800","0.55909","-0.00302"
"6.86400","0.57219","-0.00323"
"7.02000","0.58516","-0.00262"
"7.17600","0.59813","-0.00353"
"7.33200","0.61111","-0.00286"
"7.48800","0.62414","-0.00252"
"7.64400","0.63712","-0.00289"
"7.80000","0.65009","-0.00235"
"7.95600","0.66319","-0.00299"
"8.11200","0.67622","-0.00267"
"8.26800","0.68907","-0.00272"
"8.42400","0.70223","-0.00251"
"8.58000","0.71514","-0.00203"
"8.73600","0.72818","-0.00234"
"8.89200","0.74109","-0.00274"
"9.04800","0.75419","-0.00228"
"9.20400","0.76722","-0.00233"
"9.36000","0.78013","-0.00245"
"9.51600","0.79323","-0.00146"
"9.67200","0.80620","-0.00241"
"9.82800","0.81918","-0.00183"
"9.98400","0.83209","-0.00236"
"10.14000","0.84518","-0.00200"
"10.29600","0.85816","-0.00151"
"10.45200","0.87113","-0.00213"
"10.60800","0.88411","-0.00196"
"10.76400","0.89720","-0.00162"
"10.92000","0.91018","-0.00187"
"11.07600","0.92315","-0.00179"
"11.23200","0.93618","-0.00075"
"11.38800","0.94922","-0.00128"
"11.54400","0.96213","-0.00140"
"11.70000","0.97517","-0.00137"
"11.85600","0.98820","-0.00118"
"12.01200","1.00112","-0.00161"
"12.16800","1.01415","-0.00086"
"12.32400","1.02712","-0.00118"
"12.48000","1.04022","-0.00110"
"12.63600","1.05313","-0.00108"
"12.79200","1.06617","-0.00098"
"12.94800","1.07914","-0.00059"
"13.10400","1.09212","-0.00076"
"13.26000","1.10515","-0.00106"
"13.41600","1.11818","-0.00078"
"13.57200","1.13116","-0.00096"
"13.72800","1.14413","-0.00101"
"13.88400","1.15717","-0.00043"
"14.04000","1.17020","-0.00067"
"14.19600","1.18318","-0.00029"
"14.35200","1.19621","-0.00038"
"14.50800","1.20924","-0.00070"
"14.66400","1.22222","-0.00007"
"14.82000","1.23519","-0.00076"
"14.97600","1.24823","-0.00049"
"15.13200","1.26114","-0.00058"
"15.28800","1.27417","-0.00066"
"15.44400","1.28715","-0.00013"
"15.60000","1.30018","0.00020"
"15.75600","1.31316","0.00025"
"15.91200","1.32613","-0.00030"
"16.06800","1.33917","-0.00015"
"16.22400","1.35226","-0.00013"
"16.38000","1.36511","0.00032"
"16.53600","1.37821","0.00014"
"16.69200","1.39118","0.00034"
"16.84800","1.40416","0.00005"
"17.00400","1.41719","0.00019"
"17.16000","1.43023","0.00036"
"17.31600","1.44320","0.00019"
"17.47200","1.45605","0.00040"
"17.62800","1.46915","0.00036"
"17.78400","1.48218","0.00068"
"17.94000","1.49516","0.00082"
"18.09600","1.50819","0.00067"
"18.25200","1.52123","0.00048"
"18.40800","1.53420","-0.00008"
"18.56400","1.54711","0.00059"
"18.72000","1.56021","0.00014"
"18.87600","1.57318","0.00079"
"19.03200","1.58616","0.00022"
"19.18800","1.59913","0.00050"
"19.34400","1.61216","0.00103"
"19.50000","1.62514","-0.00006"
"19.65600","1.63811","0.00024"
"19.81200","1.65121","0.00133"
"19.96800","1.66424","0.00071"
"20.12400","1.67716","0.00127"
"20.28000","1.69019","0.00102"
"20.43600","1.70316","0.00094"
"20.59200","1.71620","0.00108"
"20.74800","1.72917","0.00081"
"20.90400","1.74221","0.00108"
"21.06000","1.75518","0.00052"
"21.21600","1.76816","0.00116"
"21.37200","1.78119","0.00063"
"21.52800","1.79422","0.00167"
"21.68400","1.80720","0.00068"
"21.84000","1.82017","0.00115"
"21.99600","1.83321","0.00209"
"22.15200","1.84618","0.00096"
"22.30800","1.85916","0.00157"
"22.46400","1.87219","0.00154"
"22.62000","1.88516","0.00150"
"22.77600","1.89814","0.00102"
"22.93200","1.91111","0.00091"
"23.08800","1.92415","0.00135"
"23.24400","1.93718","0.00142"
"23.40000","1.95016","0.00184"
"23.55600","1.96325","0.00176"
"23.71200","1.97622","0.00172"
"23.86800","1.98920","0.00174"
"24.02400","2.00217","0.00163"
"24.18000","2.01521","0.00206"
"24.33600","2.02818","0.00154"
"24.49200","2.04115","0.00116"
"24.64800","2.05419","0.00230"
"24.80400","2.06722","0.00165"
"24.96000","2.08014","0.00151"
"25.11600","2.09317","0.00178"
"25.27200","2.10621","0.00209"
"25.42800","2.11918","0.00217"
"25.58400","2.13215","0.00246"
"25.74000","2.14519","0.00161"
"25.89600","2.15816","0.00188"
"26.05200","2.17108","0.00168"
"26.20800","2.18417","0.00204"
"26.36400","2.19715","0.00198"
"26.52000","2.21012","0.00193"
"26.67600","2.22315","0.00198"
"26.83200","2.23619","0.00211"
"26.98800","2.24916","0.00247"
"27.14400","2.26214","0.00184"
"27.30000","2.27517","0.00213"
"27.45600","2.28821","0.00219"
"27.61200","2.30118","0.00222"
"27.76800","2.31415","0.00205"
"27.92400","2.32719","0.00224"
"28.08000","2.34022","0.00243"
"28.23600","2.35308","0.00213"
"28.39200","2.36617","0.00277"
"28.54800","2.37920","0.00244"
"28.70400","2.39212","0.00259"
"28.86000","2.40515","0.00239"
"29.01600","2.41819","0.00276"
"29.17200","2.43116","0.00259"
"29.32800","2.44414","0.00279"
"29.48400","2.45717","0.00279"
"29.64000","2.47020","0.00267"
"29.79600","2.48318","0.00310"
"29.95200","2.49615","0.00250"
"30.10800","2.50919","0.00346"
"30.26400","2.52222","0.00266"
"30.42000","2.53514","0.00295"
"30.57600","2.54823","0.00205"
"30.73200","2.56120","0.00278"
"30.88800","2.57418","0.00184"
"31.04400","2.58709","0.00219"
"31.20000","2.60019","0.00303"
"31.35600","2.61316","0.00215"
"31.51200","2.62614","0.00256"
"31.66800","2.63917","0.00279"
"31.82400","2.65220","0.00155"
"31.98000","2.66518","0.00198"
"32.13600","2.67815","0.00227"
"32.29200","2.69119","0.00239"
"32.44800","2.70416","0.00239"
"32.60400","2.71714","0.00187"
"32.76000","2.73017","0.00225"
"32.91600","2.74314","0.00259"
"33.07200","2.75612","0.00282"
"33.22800","2.76915","0.00284"
"33.38400","2.78219","0.00332"
"33.54000","2.79516","0.00268"
"33.69600","2.80814","0.00230"
"33.85200","2.82123","0.00240"
"34.00800","2.83420","0.00224"
"34.16400","2.84712","0.00319"
"34.32000","2.86021","0.00308"
"34.47600","2.87319","0.00225"
"34.63200","2.88616","0.00278"
"34.78800","2.89913","0.00297"
"34.94400","2.91217","0.00304"
"35.10000","2.92514","0.00283"
"35.25600","2.93812","0.00294"
"35.41200","2.95115","0.00270"
"35.56800","2.96419","0.00312"
"35.72400","2.97716","0.00367"
"35.88000","2.99019","0.00327"
"36.03600","3.00323","0.00325"
"36.19200","3.01614","0.00328"
"36.34800","3.02918","0.00295"
"36.50400","3.04221","0.00318"
"36.66000","3.05519","0.00350"
"36.81600","3.06810","0.00346"
"36.97200","3.08113","0.00317"
"37.12800","3.09423","0.00326"
"37.28400","3.10714","0.00366"
"37.44000","3.12012","0.00334"
"37.59600","3.13321","0.00352"
"37.75200","3.14625","0.00316"
"37.90800","3.15916","0.00366"
"38.06400","3.17219","0.00333"
"38.22000","3.18523","0.00360"
"38.37600","3.19814","0.00379"
"38.53200","3.21112","0.00366"
"38.68800","3.22415","0.00366"
"38.84400","3.23718","0.00334"
"39.00000","3.25010","0.00419"
"39.15600","3.26319","0.00352"
"39.31200","3.27617","0.00404"
"39.46800","3.28920","0.00375"
"39.62400","3.30218","0.00392"
"39.78000","3.31521","0.00377"
"39.93600","3.32818","0.00393"
"40.09200","3.34110","0.00422"
"40.24800","3.35419","0.00392"
"40.40400","3.36717","0.00429"
"40.56000","3.38014","0.00491"
"40.71600","3.39318","0.00402"
"40.87200","3.40615","0.00464"
"41.02800","3.41918","0.00440"
"41.18400","3.43216","0.00438"
"41.34000","3.44519","0.00359"
"41.49600","3.45817","0.00495"
"41.65200","3.47114","0.00492"
"41.80800","3.48418","0.00419"
"41.96400","3.49721","0.00453"
"42.12000","3.51018","0.00473"
"42.27600","3.52310","0.00457"
"42.43200","3.53613","0.00459"
"42.58800","3.54917","0.00519"
"42.74400","3.56214","0.00481"
"42.90000","3.57518","0.00477"
"43.05600","3.58821","0.00547"
"43.21200","3.60118","0.00516"
"43.36800","3.61416","0.00486"
"43.52400","3.62719","0.00452"
"43.68000","3.64023","0.00499"
"43.83600","3.65314","0.00439"
"43.99200","3.66623","0.00515"
"44.14800","3.67921","0.00449"
"44.30400","3.69218","0.00430"
"44.46000","3.70516","0.00428"
"44.61600","3.71825","0.00482"
"44.77200","3.73117","0.00511"
"44.92800","3.74414","0.00496"
"45.08400","3.75717","0.00498"
"45.24000","3.77021","0.00498"
"45.39600","3.78312","0.00454"
"45.55200","3.79616","0.00499"
"45.70800","3.80913","0.00496"
"45.86400","3.82211","0.00556"
"46.02000","3.83508","0.00498"
"46.17600","3.84817","0.00563"
"46.33200","3.86121","0.00551"
"46.48800","3.87412","0.00585"
"46.64400","3.88716","0.00547"
"46.80000","3.90025","0.00571"
"46.95600","3.91317","0.00561"
"47.11200","3.92614","0.00577"
"47.26800","3.93917","0.00552"
"47.42400","3.95221","0.00561"
"47.58000","3.96512","0.00629"
"47.73600","3.97822","0.00611"
"47.89200","3.99119","0.00613"
"48.04800","4.00416","0.00596"
"48.20400","4.01714","0.00586"
"48.36000","4.03023","0.00586"
"48.51600","4.04321","0.00610"
"48.67200","4.05618","0.00620"
"48.82800","4.06916","0.00661"
"48.98400","4.08225","0.00660"
"49.14000","4.09516","0.00617"
"49.29600","4.10820","0.00660"
"49.45200","4.12123","0.00657"
"49.60800","4.13415","0.00663"
"49.76400","4.14712","0.00699"
"49.92000","4.16016","0.00659"
"50.07600","4.17319","0.00692"
"50.23200","4.18616","0.00684"
"50.38800","4.19920","0.00648"
"50.54400","4.21223","0.00751"
"50.70000","4.22521","0.00692"
"50.85600","4.23812","0.00714"
"51.01200","4.25116","0.00684"
"51.16800","4.26419","0.00696"
"51.32400","4.27710","0.00733"
"51.48000","4.29020","0.00752"
"51.63600","4.30317","0.00729"
"51.79200","4.31615","0.00788"
"51.94800","4.32912","0.00772"
"52.10400","4.34221","0.00829"
"52.26000","4.35525","0.00777"
"52.41600","4.36810","0.00833"
"52.57200","4.38120","0.00842"
"52.72800","4.39417","0.00765"
"52.88400","4.40715","0.00738"
"53.04000","4.42018","0.00812"
"53.19600","4.43321","0.00812"
"53.35200","4.44619","0.00881"
"53.50800","4.45916","0.00848"
"53.66400","4.47214","0.00876"
"53.82000","4.48523","0.00857"
"53.97600","4.49821","0.00918"
"54.13200","4.51118","0.00816"
"54.28800","4.52415","0.00687"
"54.44400","4.53719","0.00799"
"54.60000","4.55010","0.00738"
"54.75600","4.56320","0.00779"
"54.91200","4.57617","0.00792"
"55.06800","4.58915","0.00858"
"55.22400","4.60212","0.00739"
"55.38000","4.61515","0.00743"
"55.53600","4.62819","0.00801"
"55.69200","4.64116","0.00773"
"55.84800","4.65420","0.00785"
"56.00400","4.66723","0.00805"
"56.16000","4.68015","0.00827"
"56.31600","4.69312","0.00798"
"56.47200","4.70621","0.00853"
"56.62800","4.71919","0.00898"
"56.78400","4.73216","0.00928"
"56.94000","4.74520","0.00868"
"57.09600","4.75817","0.00929"
"57.25200","4.77114","0.00887"
"57.40800","4.78418","0.00931"
"57.56400","4.79721","0.00895"
"57.72000","4.81019","0.00956"
"57.87600","4.82316","0.00929"
"58.03200","4.83620","0.00882"
"58.18800","4.84917","0.00971"
"58.34400","4.86214","0.01014"
"58.50000","4.87512","0.00973"
"58.65600","4.88821","0.01023"
"58.81200","4.90113","0.01000"
"58.96800","4.91416","0.01015"
"59.12400","4.92720","0.01059"
"59.28000","4.94023","0.01054"
"59.43600","4.95314","0.01085"
"59.59200","4.96624","0.01087"
"59.74800","4.97915","0.01049"
"59.90400","4.99219","0.01025"
"60.06000","5.00516","0.01071"
"60.21600","5.01819","0.01095"
"60.37200","5.03117","0.01134"
"60.52800","5.04408","0.01095"
"60.68400","5.05718","0.01177"
"60.84000","5.07021","0.01183"
"60.99600","5.08313","0.01171"
"61.15200","5.09622","0.01235"
"61.30800","5.10919","0.01248"
"61.46400","5.12223","0.01235"
"61.62000","5.13514","0.01270"
"61.77600","5.14824","0.01254"
"61.93200","5.16121","0.01263"
"62.08800","5.17413","0.01246"
"62.24400","5.18716","0.01346"
"62.40000","5.20019","0.01317"
"62.55600","5.21317","0.01324"
"62.71200","5.22614","0.01326"
"62.86800","5.23918","0.01416"
"63.02400","5.25221","0.01416"
"63.18000","5.26513","0.01446"
"63.33600","5.27822","0.01463"
"63.49200","5.29119","0.01449"
"63.64800","5.30417","0.01501"
"63.80400","5.31714","0.01495"
"63.96000","5.33012","0.01540"
"64.11600","5.34321","0.01505"
"64.27200","5.35613","0.01567"
"64.42800","5.36916","0.01579"
"64.58400","5.38219","0.01612"
"64.74000","5.39517","0.01564"
"64.89600","5.40814","0.01646"
"65.05200","5.42118","0.01660"
"65.20800","5.43421","0.01708"
"65.36400","5.44712","0.01742"
"65.52000","5.46022","0.01750"
"65.67600","5.47313","0.01778"
"65.83200","5.48617","0.01784"
"65.98800","5.49914","0.01785"
"66.14400","5.51218","0.01724"
"66.30000","5.52521","0.01744"
"66.45600","5.53818","0.01844"
"66.61200","5.55122","0.01864"
"66.76800","5.56419","0.01975"
"66.92400","5.57711","0.01906"
"67.08000","5.59014","0.01980"
"67.23600","5.60318","0.02029"
"67.39200","5.61615","0.01996"
"67.54800","5.62913","0.02071"
"67.70400","5.64216","0.02115"
"67.86000","5.65519","0.02163"
"68.01600","5.66811","0.02219"
"68.17200","5.68120","0.02257"
"68.32800","5.69418","0.02244"
"68.48400","5.70715","0.02321"
"68.64000","5.72018","0.02353"
"68.79600","5.73322","0.02433"
"68.95200","5.74613","0.02506"
"69.10800","5.75905","0.02529"
"69.26400","5.77220","0.02540"
"69.42000","5.78518","0.02600"
"69.57600","5.79815","0.02574"
"69.73200","5.81112","0.02550"
"69.88800","5.82422","0.02650"
"70.04400","5.83719","0.02717"
"70.20000","5.85011","0.02843"
"70.35600","5.86320","0.02910"
"70.51200","5.87617","0.02873"
"70.66800","5.88915","0.02998"
"70.82400","5.90218","0.03043"
"70.98000","5.91516","0.03033"
"71.13600","5.92813","0.03119"
"71.29200","5.94111","0.03224"
"71.44800","5.95414","0.03249"
"71.60400","5.96717","0.03336"
"71.76000","5.98015","0.03355"
"71.91600","5.99318","0.03517"
"72.07200","6.00616","0.03558"
"72.22800","6.01919","0.03588"
"72.38400","6.03217","0.03738"
"72.54000","6.04520","0.03730"
"72.69600","6.05823","0.03842"
"72.85200","6.07109","0.03978"
"73.00800","6.08418","0.04004"
"73.16400","6.09716","0.04091"
"73.32000","6.11013","0.04137"
"73.47600","6.12311","0.04285"
"73.63200","6.13620","0.04302"
"73.78800","6.14917","0.04467"
"73.94400","6.16215","0.04502"
"74.10000","6.17518","0.04589"
"74.25600","6.18822","0.04670"
"74.41200","6.20113","0.04737"
"74.56800","6.21411","0.04779"
"74.72400","6.22720","0.04911"
"74.88000","6.24017","0.04958"
"75.03600","6.25315","0.05015"
"75.19200","6.26624","0.05091"
"75.34800","6.27922","0.05173"
"75.50400","6.29219","0.05247"
"75.66000","6.30517","0.05290"
"75.81600","6.31820","0.05411"
"75.97200","6.33111","0.05459"
"76.12800","6.34415","0.05568"
"76.28400","6.35718","0.05594"
"76.44000","6.37022","0.05704"
"76.59600","6.38313","0.05755"
"76.75200","6.39616","0.05838"
"76.90800","6.40920","0.05826"
"77.06400","6.42217","0.05904"
"77.22000","6.43515","0.05984"
"77.37600","6.44824","0.06039"
"77.53200","6.46116","0.06050"
"77.68800","6.47413","0.06135"
"77.84400","6.48716","0.06184"
"78.00000","6.50020","0.06230"
"78.15600","6.51317","0.06237"
"78.31200","6.52609","0.06308"
"78.46800","6.53918","0.06382"
"78.62400","6.55216","0.06424"
"78.78000","6.56513","0.06543"
"78.93600","6.57822","0.06600"
"79.09200","6.59126","0.06693"
"79.24800","6.60417","0.06555"
"79.40400","6.61715","0.06701"
"79.56000","6.63018","0.06727"
"79.71600","6.64316","0.06872"
"79.87200","6.65613","0.06894"
"80.02800","6.66916","0.06945"
"80.18400","6.68220","0.07023"
"80.34000","6.69511","0.07059"
"80.49600","6.70815","0.07129"
"80.65200","6.72124","0.07156"
"80.80800","6.73421","0.07202"
"80.96400","6.74719","0.07262"
"81.12000","6.76016","0.07226"
"81.27600","6.77320","0.07303"
"81.43200","6.78617","0.07313"
"81.58800","6.79921","0.07348"
"81.74400","6.81218","0.07322"
"81.90000","6.82516","0.07398"
"82.05600","6.83813","0.07429"
"82.21200","6.85116","0.07419"
"82.36800","6.86420","0.07490"
"82.52400","6.87717","0.02726"
"82.68000","6.89021","0.02638"
"82.83600","6.90318","0.02369"
"82.99200","6.91621","0.02199"
"83.14800","6.92919","0.02239"
"83.30400","6.94216","0.02355"
"83.46000","6.95520","0.02325"
"83.61600","6.96811","0.02453"
"83.77200","6.98115","0.02552"
"83.92800","6.99412","0.02584"
"84.08400","7.00709","0.02704"
"84.24000","7.02013","0.02678"
"84.39600","7.03322","0.02764"
"84.55200","7.04620","0.02748"
"84.70800","7.05917","0.02817"
"84.86400","7.07214","0.02853"
"85.02000","7.08518","0.02944"
"85.17600","7.09815","0.02946"
"85.33200","7.11113","0.02997"
"85.48800","7.12422","0.03060"
"85.64400","7.13720","0.03125"
"85.80000","7.15011","0.03149"
"85.95600","7.16320","0.03018"
"86.11200","7.17624","0.03167"
"86.26800","7.18915","0.03142"
"86.42400","7.20219","0.03218"
"86.58000","7.21516","0.03220"
"86.73600","7.22814","0.03255"
"86.89200","7.24111","0.03297"
"87.04800","7.25420","0.03367"
"87.20400","7.26718","0.03285"
"87.36000","7.28015","0.03420"
"87.51600","7.29319","0.03437"
"87.67200","7.30622","0.03541"
"87.82800","7.31920","0.03460"
"87.98400","7.33217","0.03590"
"88.14000","7.34526","0.03543"
"88.29600","7.35818","0.03537"
"88.45200","7.37109","0.03513"
"88.60800","7.38413","0.03515"
"88.76400","7.39716","0.03560"
"88.92000","7.41020","0.03522"
"89.07600","7.42311","0.03544"
"89.23200","7.43614","0.03526"
"89.38800","7.44918","0.03525"
"89.54400","7.46215","0.03398"
"89.70000","7.47519","0.03348"
"89.85600","7.48822","0.03427"
"90.01200","7.50119","0.03410"
"90.16800","7.51417","0.02860"
"90.32400","7.52720","0.02852"
"90.48000","7.54024","0.02963"
"90.63600","7.55315","0.03077"
"90.79200","7.56619","0.03204"
"90.94800","7.57916","0.03165"
"91.10400","7.59213","0.03261"
"91.26000","7.60517","0.03179"
"91.41600","7.61820","0.03309"
"91.57200","7.63118","0.03360"
"91.72800","7.64415","0.03435"
"91.88400","7.65719","0.03442"
"92.04000","7.67022","0.03515"
"92.19600","7.68313","0.03587"
"92.35200","7.69617","0.03595"
"92.50800","7.70920","0.03567"
"92.66400","7.72212","0.03614"
"92.82000","7.73509","0.03630"
"92.97600","7.74819","0.03631"
"93.13200","7.76122","0.03606"
"93.28800","7.77413","0.03591"
"93.44400","7.78717","0.03660"
"93.60000","7.80020","0.03503"
"93.75600","7.81324","0.03472"
"93.91200","7.82615","0.03582"
"94.06800","7.83919","0.03661"
"94.22400","7.85222","0.03598"
"94.38000","7.86513","0.03621"
"94.53600","7.87823","0.03673"
"94.69200","7.89114","0.03597"
"94.84800","7.90418","0.03642"
"95.00400","7.91715","0.03745"
"95.16000","7.93024","0.03663"
"95.31600","7.94328","0.03739"
"95.47200","7.95613","0.03781"
"95.62800","7.96923","0.03730"
"95.78400","7.98220","0.03787"
"95.94000","7.99512","0.03776"
"96.09600","8.00809","0.03690"
"96.25200","8.02118","0.03771"
"96.40800","8.03416","0.03720"
"96.56400","8.04713","0.03637"
"96.72000","8.06011","0.03457"
"96.87600","8.07314","0.03505"
"97.03200","8.08612","0.03411"
"97.18800","8.09915","0.03407"
"97.34400","8.11218","0.03287"
"97.50000","8.12516","0.03209"
"97.65600","8.13813","0.03172"
"97.81200","8.15117","0.03139"
"97.96800","8.16420","0.03068"
"98.12400","8.17712","0.02996"
"98.28000","8.19015","0.02598"
"98.43600","8.20312","0.02454"
"98.59200","8.21622","0.02426"
"98.74800","8.22913","0.02366"
"98.90400","8.24223","0.02187"
"99.06000","8.25520","0.02146"
"99.21600","8.26812","0.02089"
"99.37200","8.28115","0.02010"
"99.52800","8.29412","0.01927"
"99.68400","8.30716","0.01932"
"99.84000","8.32007","0.01893"
"99.99600","8.33323","0.01875"
"100.15200","8.34620","0.01920"
"100.30800","8.35917","0.01928"
"100.46400","8.37215","0.01925"
"100.62000","8.38518","0.01931"
"100.77600","8.39816","0.01911"
"100.93200","8.41119","0.01955"
"101.08800","8.42422","0.01956"
"101.24400","8.43714","0.02015"
"101.40000","8.45011","0.01949"
"101.55600","8.46315","0.01969"
"101.71200","8.47618","0.01997"
"101.86800","8.48916","0.02013"
"102.02400","8.50219","0.01980"
"102.18000","8.51517","0.02056"
"102.33600","8.52820","0.02053"
"102.49200","8.54111","0.02067"
"102.64800","8.55421","0.02053"
"102.80400","8.56718","0.02157"
"102.96000","8.58016","0.02143"
"103.11600","8.59313","0.02156"
"103.27200","8.60616","0.02243"
"103.42800","8.61920","0.02206"
"103.58400","8.63211","0.02231"
"103.74000","8.64521","0.02321"
"103.89600","8.65824","0.02289"
"104.05200","8.67116","0.02354"
"104.20800","8.68419","0.02374"
"104.36400","8.69717","0.02459"
"104.52000","8.71020","0.02423"
"104.67600","8.72311","0.02459"
"104.83200","8.73621","0.02447"
"104.98800","8.74918","0.02596"
"105.14400","8.76216","0.02566"
"105.30000","8.77513","0.02639"
"105.45600","8.78817","0.02634"
"105.61200","8.80114","0.02623"
"105.76800","8.81417","0.02748"
"105.92400","8.82721","0.02748"
"106.08000","8.84018","0.02792"
"106.23600","8.85316","0.02819"
"106.39200","8.86619","0.02893"
"106.54800","8.87922","0.02879"
"106.70400","8.89214","0.02922"
"106.86000","8.90511","0.02934"
"107.01600","8.91815","0.02979"
"107.17200","8.93118","0.03003"
"107.32800","8.94416","0.03087"
"107.48400","8.95719","0.03139"
"107.64000","8.97022","0.03093"
"107.79600","8.98314","0.03139"
"107.95200","8.99617","0.03044"
"108.10800","9.00921","0.02982"
"108.26400","9.02218","0.02957"
"108.42000","9.03516","0.02792"
"108.57600","9.04819","0.02638"
"108.73200","9.06116","0.02433"
"108.88800","9.07414","0.02263"
"109.04400","9.08711","0.02194"
"109.20000","9.10015","0.02167"
"109.35600","9.11318","0.02200"
"109.51200","9.12615","0.02177"
"109.66800","9.13919","0.02250"
"109.82400","9.15210","0.02164"
"109.98000","9.16514","0.02217"
"110.13600","9.17817","0.02203"
"110.29200","9.19121","0.02226"
"110.44800","9.20412","0.02236"
"110.60400","9.21715","0.02301"
"110.76000","9.23019","0.02316"
"110.91600","9.24316","0.02296"
"111.07200","9.25614","0.02300"
"111.22800","9.26923","0.02259"
"111.38400","9.28226","0.02332"
"111.54000","9.29518","0.02216"
"111.69600","9.30815","0.02292"
"111.85200","9.32119","0.02238"
"112.00800","9.33416","0.02261"
"112.16400","9.34708","0.02296"
"112.32000","9.36017","0.02266"
"112.47600","9.37321","0.02321"
"112.63200","9.38618","0.02374"
"112.78800","9.39915","0.02252"
"112.94400","9.41225","0.02239"
"113.10000","9.42522","0.02275"
"113.25600","9.43814","0.02328"
"113.41200","9.45117","0.02236"
"113.56800","9.46420","0.02294"
"113.72400","9.47718","0.02289"
"113.88000","9.49015","0.02309"
"114.03600","9.50319","0.02269"
"114.19200","9.51616","0.02289"
"114.34800","9.52908","0.02312"
"114.50400","9.54217","0.02344"
"114.66000","9.55526","0.02310"
"114.81600","9.56818","0.02301"
"114.97200","9.58121","0.02224"
"115.12800","9.59419","0.02220"
"115.28400","9.60716","0.02157"
"115.44000","9.62014","0.02125"
"115.59600","9.63317","0.02098"
"115.75200","9.64620","0.02130"
"115.90800","9.65912","0.02142"
"116.06400","9.67215","0.02157"
"116.22000","9.68513","0.02202"
"116.37600","9.69816","0.02169"
"116.53200","9.71120","0.02160"
"116.68800","9.72423","0.02191"
"116.84400","9.73720","0.02208"
"117.00000","9.75018","0.02183"
"117.15600","9.76315","0.02223"
"117.31200","9.77619","0.02248"
"117.46800","9.78916","0.02246"
"117.62400","9.80213","0.02241"
"117.78000","9.81517","0.02277"
"117.93600","9.82820","0.02291"
"118.09200","9.84118","0.02250"
"118.24800","9.85421","0.02245"
"118.40400","9.86725","0.02246"
"118.56000","9.88016","0.02215"
"118.71600","9.89313","0.02242"
"118.87200","9.90617","0.02226"
"119.02800","9.91914","0.02311"
"119.18400","9.93212","0.02281"
"119.34000","9.94515","0.02278"
"119.49600","9.95819","0.02376"
"119.65200","9.97110","0.02318"
"119.80800","9.98419","0.02295"
"119.96400","9.99717","0.02342"
"120.12000","10.01020","0.02384"
"120.27600","10.02318","0.02334"
"120.43200","10.03627","0.02363"
"120.58800","10.04919","0.02387"
"120.74400","10.06216","0.02381"
"120.90000","10.07519","0.02357"
"121.05600","10.08823","0.02327"
"121.21200","10.10120","0.02381"
"121.36800","10.11412","0.02373"
"121.52400","10.12721","0.02381"
"121.68000","10.14012","0.02462"
"121.83600","10.15310","0.02408"
"121.99200","10.16619","0.02387"
"122.14800","10.17923","0.02383"
"122.30400","10.19214","0.02383"
"122.46000","10.20512","0.02342"
"122.61600","10.21815","0.02359"
"122.77200","10.23112","0.02281"
"122.92800","10.24410","0.02272"
"123.08400","10.25713","0.02245"
"123.24000","10.27023","0.02325"
"123.39600","10.28314","0.02398"
"123.55200","10.29618","0.02413"
"123.70800","10.30921","0.02431"
"123.86400","10.32218","0.02458"
"124.02000","10.33516","0.02479"
"124.17600","10.34819","0.02535"
"124.33200","10.36123","0.02538"
"124.48800","10.37414","0.02645"
"124.64400","10.38712","0.02631"
"124.80000","10.40015","0.02663"
"124.95600","10.41318","0.02685"
"125.11200","10.42610","0.02665"
"125.26800","10.43919","0.02711"
"125.42400","10.45217","0.02718"
"125.58000","10.46520","0.02704"
"125.73600","10.47824","0.02646"
"125.89200","10.49121","0.02575"
"126.04800","10.50418","0.02546"
"126.20400","10.51716","0.02536"
"126.36000","10.53019","0.02429"
"126.51600","10.54323","0.02323"
"126.67200","10.55614","0.02241"
"126.82800","10.56918","0.02216"
"126.98400","10.58215","0.02179"
"127.14000","10.59512","0.02170"
"127.29600","10.60816","0.02211"
"127.45200","10.62119","0.02247"
"127.60800","10.63423","0.02117"
"127.76400","10.64714","0.02072"
"127.92000","10.66018","0.02106"
"128.07600","10.67321","0.02103"
"128.23200","10.68612","0.02135"
"128.38800","10.69916","0.02067"
"128.54400","10.71219","0.02044"
"128.70000","10.72517","0.01897"
"128.85600","10.73814","0.01808"
"129.01200","10.75123","0.01843"
"129.16800","10.76415","0.01824"
"129.32400","10.77712","0.01754"
"129.48000","10.79016","0.01523"
"129.63600","10.80319","0.01476"
"129.79200","10.81623","0.01485"
"129.94800","10.82908","0.01516"
"130.10400","10.84217","0.01515"
"130.26000","10.85521","0.01558"
"130.41600","10.86818","0.01514"
"130.57200","10.88116","0.01497"
"130.72800","10.89425","0.01523"
"130.88400","10.90723","0.01457"
"131.04000","10.92020","0.01510"
"131.19600","10.93323","0.01514"
"131.35200","10.94621","0.01451"
"131.50800","10.95912","0.01526"
"131.66400","10.97216","0.01564"
"131.82000","10.98519","0.01561"
"131.97600","10.99817","0.01576"
"132.13200","11.01114","0.01588"
"132.28800","11.02417","0.01622"
"132.44400","11.03721","0.01594"
"132.60000","11.05012","0.01541"
"132.75600","11.06316","0.01595"
"132.91200","11.07619","0.01593"
"133.06800","11.08916","0.01572"
"133.22400","11.10214","0.01634"
"133.38000","11.11511","0.01568"
"133.53600","11.12815","0.01618"
"133.69200","11.14112","0.01599"
"133.84800","11.15416","0.01587"
"134.00400","11.16719","0.01638"
"134.16000","11.18016","0.01642"
"134.31600","11.19314","0.01656"
"134.47200","11.20617","0.01639"
"134.62800","11.21915","0.01676"
"134.78400","11.23212","0.01763"
"134.94000","11.24516","0.01697"
"135.09600","11.25819","0.01704"
"135.25200","11.27110","0.01666"
"135.40800","11.28414","0.01655"
"135.56400","11.29711","0.01670"
"135.72000","11.31015","0.01678"
"135.87600","11.32312","0.01721"
"136.03200","11.33622","0.01732"
"136.18800","11.34925","0.01728"
"136.34400","11.36216","0.01690"
"136.50000","11.37520","0.01675"
"136.65600","11.38817","0.01733"
"136.81200","11.40115","0.01744"
"136.96800","11.41412","0.01733"
"137.12400","11.42722","0.01753"
"137.28000","11.44019","0.01736"
"137.43600","11.45310","0.01754"
"137.59200","11.46620","0.01759"
"137.74800","11.47917","0.01762"
"137.90400","11.49215","0.01794"
"138.06000","11.50518","0.01816"
"138.21600","11.51822","0.01871"
"138.37200","11.53125","0.01777"
"138.52800","11.54410","0.01762"
"138.68400","11.55720","0.01789"
"138.84000","11.57017","0.01802"
"138.99600","11.58315","0.01771"
"139.15200","11.59612","0.01795"
"139.30800","11.60915","0.01817"
"139.46400","11.62219","0.01847"
"139.62000","11.63510","0.01841"
"139.77600","11.64820","0.01851"
"139.93200","11.66123","0.01915"
"140.08800","11.67420","0.01858"
"140.24400","11.68718","0.01898"
"140.40000","11.70015","0.01792"
"140.55600","11.71319","0.01905"
"140.71200","11.72610","0.01882"
"140.86800","11.73920","0.01846"
"141.02400","11.75217","0.01910"
"141.18000","11.76515","0.01924"
"141.33600","11.77812","0.01930"
"141.49200","11.79121","0.01894"
"141.64800","11.80419","0.01961"
"141.80400","11.81710","0.01952"
"141.96000","11.83020","0.01967"
"142.11600","11.84317","0.01976"
"142.27200","11.85609","0.01883"
"142.42800","11.86918","0.01940"
"142.58400","11.88221","0.01954"
"142.74000","11.89513","0.01969"
"142.89600","11.90810","0.01902"
"143.05200","11.92120","0.01968"
"143.20800","11.93417","0.01977"
"143.36400","11.94720","0.02017"
"143.52000","11.96018","0.01976"
"143.67600","11.97321","0.02004"
"143.83200","11.98619","0.02067"
"143.98800","11.99916","0.02072"
"144.14400","12.01219","0.02102"
"144.30000","12.02517","0.02065"
"144.45600","12.03814","0.02051"
"144.61200","12.05118","0.02073"
"144.76800","12.06421","0.02106"
"144.92400","12.07719","0.02071"
"145.08000","12.09016","0.02127"
"145.23600","12.10319","0.02125"
"145.39200","12.11623","0.02107"
"145.54800","12.12914","0.02091"
"145.70400","12.14218","0.02133"
"145.86000","12.15521","0.02122"
"146.01600","12.16819","0.02176"
"146.17200","12.18122","0.02162"
"146.32800","12.19420","0.02185"
"146.48400","12.20717","0.02236"
"146.64000","12.22008","0.02116"
"146.79600","12.23324","0.02204"
"146.95200","12.24621","0.02184"
"147.10800","12.25913","0.02254"
"147.26400","12.27222","0.02228"
"147.42000","12.28520","0.02226"
"147.57600","12.29817","0.02250"
"147.73200","12.31108","0.02291"
"147.88800","12.32418","0.02288"
"148.04400","12.33715","0.02269"
"148.20000","12.35013","0.02261"
"148.35600","12.36316","0.02354"
"148.51200","12.37619","0.02295"
"148.66800","12.38917","0.02310"
"148.82400","12.40220","0.02383"
"148.98000","12.41524","0.02381"
"149.13600","12.42821","0.02405"
"149.29200","12.44112","0.02456"
"149.44800","12.45422","0.02407"
"149.60400","12.46719","0.02435"
"149.76000","12.48017","0.02448"
"149.91600","12.49320","0.02505"
"150.07200","12.50612","0.02514"
"150.22800","12.51915","0.02460"
"150.38400","12.53213","0.02482"
"150.54000","12.54516","0.02458"
"150.69600","12.55825","0.02546"
"150.85200","12.57117","0.02531"
"151.00800","12.58414","0.02613"
"151.16400","12.59718","0.02557"
"151.32000","12.61021","0.02567"
"151.47600","12.62313","0.02623"
"151.63200","12.63622","0.02608"
"151.78800","12.64913","0.02689"
"151.94400","12.66217","0.02664"
"152.10000","12.67514","0.02651"
"152.25600","12.68818","0.02731"
"152.41200","12.70115","0.02699"
"152.56800","12.71413","0.02721"
"152.72400","12.72722","0.02772"
"152.88000","12.74013","0.02782"
"153.03600","12.75311","0.02791"
"153.19200","12.76614","0.02897"
"153.34800","12.77918","0.02800"
"153.50400","12.79215","0.02875"
"153.66000","12.80518","0.02871"
"153.81600","12.81816","0.02920"
"153.97200","12.83119","0.02923"
"154.12800","12.84411","0.02972"
"154.28400","12.85720","0.02957"
"154.44000","12.87024","0.02995"
"154.59600","12.88315","0.03036"
"154.75200","12.89612","0.03060"
"154.90800","12.90922","0.03054"
"155.06400","12.92213","0.03053"
"155.22000","12.93511","0.03060"
"155.37600","12.94820","0.03068"
"155.53200","12.96117","0.03173"
"155.68800","12.97415","0.03132"
"155.84400","12.98718","0.03155"
"156.00000","13.00022","0.03244"
"156.15600","13.01319","0.03215"
"156.31200","13.02611","0.03260"
"156.46800","13.03920","0.03328"
"156.62400","13.05223","0.03263"
"156.78000","13.06515","0.03258"
"156.93600","13.07818","0.03335"
"157.09200","13.09122","0.03314"
"157.24800","13.10413","0.01505"
"157.40400","13.11711","0.02448"
"157.56000","13.13020","0.01647"
"157.71600","13.14317","0.01431"
"157.87200","13.15615","0.02117"
"158.02800","13.16912","0.01656"
"158.18400","13.18216","0.01609"
"158.34000","13.19513","0.02041"
"158.49600","13.20811","0.01612"
"158.65200","13.22114","0.01863"
"158.80800","13.23417","0.01814"
"158.96400","13.24715","0.01627"
"159.12000","13.26018","0.02000"
"159.27600","13.27322","0.01710"
"159.43200","13.28619","0.01784"
"159.58800","13.29917","0.02032"
"159.74400","13.31226","0.01745"
"159.90000","13.32523","0.01989"
"160.05600","13.33815","0.01885"
"160.21200","13.35112","0.01801"
"160.36800","13.36416","0.02040"
"160.52400","13.37707","0.01828"
"160.68000","13.39011","0.01996"
"160.83600","13.40314","0.01951"
"160.99200","13.41617","0.01830"
"161.14800","13.42909","0.02006"
"161.30400","13.44218","0.01864"
"161.46000","13.45516","0.01906"
"161.61600","13.46819","0.02009"
"161.77200","13.48116","0.01871"
"161.92800","13.49420","0.01981"
"162.08400","13.50711","0.01977"
"162.24000","13.52015","0.01942"
"162.39600","13.53318","0.01993"
"162.55200","13.54622","0.01845"
"162.70800","13.55913","0.01964"
"162.86400","13.57216","0.01913"
"163.02000","13.58520","0.01829"
"163.17600","13.59817","0.01952"
"163.33200","13.61115","0.01873"
"163.48800","13.62424","0.01924"
"163.64400","13.63716","0.01905"
"163.80000","13.65013","0.01852"
"163.95600","13.66316","0.01911"
"164.11200","13.67620","0.01852"
"164.26800","13.68917","0.01856"
"164.42400","13.70215","0.01885"
"164.58000","13.71518","0.01933"
"164.73600","13.72816","0.01920"
"164.89200","13.74113","0.01946"
"165.04800","13.75416","0.01926"
"165.20400","13.76720","0.01944"
"165.36000","13.78017","0.01895"
"165.51600","13.79315","0.01962"
"165.67200","13.80618","0.01965"
"165.82800","13.81916","0.01933"
"165.98400","13.83213","0.02010"
"166.14000","13.84516","0.02014"
"166.29600","13.85820","0.01964"
"166.45200","13.87111","0.01967"
"166.60800","13.88415","0.02026"
"166.76400","13.89718","0.02040"
"166.92000","13.91015","0.02099"
"167.07600","13.92313","0.01965"
"167.23200","13.93616","0.01999"
"167.38800","13.94920","0.02070"
"167.54400","13.96211","0.02038"
"167.70000","13.97515","0.02031"
"167.85600","13.98812","0.02034"
"168.01200","14.00115","0.02044"
"168.16800","14.01413","0.02027"
"168.32400","14.02722","0.02066"
"168.48000","14.04020","0.02045"
"168.63600","14.05317","0.02076"
"168.79200","14.06621","0.02041"
"168.94800","14.07918","0.02068"
"169.10400","14.09215","0.02020"
"169.26000","14.10519","0.02090"
"169.41600","14.11822","0.02086"
"169.57200","14.13120","0.02092"
"169.72800","14.14417","0.02143"
"169.88400","14.15715","0.02124"
"170.04000","14.17018","0.02086"
"170.19600","14.18309","0.02136"
"170.35200","14.19619","0.02137"
"170.50800","14.20916","0.02099"
"170.66400","14.22220","0.02143"
"170.82000","14.23517","0.02126"
"170.97600","14.24821","0.02090"
"171.13200","14.26118","0.02138"
"171.28800","14.27415","0.02164"
"171.44400","14.28713","0.02174"
"171.60000","14.30016","0.02217"
"171.75600","14.31320","0.02202"
"171.91200","14.32611","0.02249"
"172.06800","14.33926","0.02159"
"172.22400","14.35218","0.02233"
"172.38000","14.36515","0.02242"
"172.53600","14.37819","0.02210"
"172.69200","14.39116","0.02266"
"172.84800","14.40420","0.02223"
"173.00400","14.41711","0.02234"
"173.16000","14.43020","0.02212"
"173.31600","14.44312","0.02249"
"173.47200","14.45609","0.02251"
"173.62800","14.46919","0.02294"
"173.78400","14.48222","0.02255"
"173.94000","14.49520","0.02274"
"174.09600","14.50817","0.02262"
"174.25200","14.52120","0.02291"
"174.40800","14.53418","0.02341"
"174.56400","14.54715","0.02261"
"174.72000","14.56019","0.02303"
"174.87600","14.57322","0.02298"
"175.03200","14.58614","0.02299"
"175.18800","14.59911","0.02328"
"175.34400","14.61220","0.02330"
"175.50000","14.62524","0.02349"
"175.65600","14.63815","0.02323"
"175.81200","14.65119","0.02396"
"175.96800","14.66422","0.02374"
"176.12400","14.67714","0.02300"
"176.28000","14.69011","0.02384"
"176.43600","14.70314","0.02364"
"176.59200","14.71618","0.02404"
"176.74800","14.72909","0.02423"
"176.90400","14.74219","0.02462"
"177.06000","14.75516","0.02454"
"177.21600","14.76820","0.02429"
"177.37200","14.78117","0.02450"
"177.52800","14.79420","0.02483"
"177.68400","14.80718","0.02493"
"177.84000","14.82009","0.02395"
"177.99600","14.83313","0.02459"
"178.15200","14.84622","0.02435"
"178.30800","14.85919","0.02501"
"178.46400","14.87217","0.02480"
"178.62000","14.88520","0.02535"
"178.77600","14.89812","0.02568"
"178.93200","14.91109","0.02555"
"179.08800","14.92418","0.02486"
"179.24400","14.93722","0.02561"
"179.40000","14.95019","0.02603"
"179.55600","14.96317","0.02577"
"179.71200","14.97614","0.02612"
"179.86800","14.98918","0.02617"
"180.02400","15.00215","0.02585"
"180.18000","15.01518","0.02634"
"180.33600","15.02822","0.02580"
"180.49200","15.04113","0.02639"
"180.64800","15.05423","0.02676"
"180.80400","15.06714","0.02647"
"180.96000","15.08018","0.02709"
"181.11600","15.09315","0.02755"
"181.27200","15.10618","0.02744"
"181.42800","15.11922","0.02738"
"181.58400","15.13207","0.02792"
"181.74000","15.14523","0.02774"
"181.89600","15.15820","0.02828"
"182.05200","15.17118","0.02794"
"182.20800","15.18415","0.02849"
"182.36400","15.19718","0.02856"
"182.52000","15.21016","0.02899"
"182.67600","15.22319","0.02939"
"182.83200","15.23623","0.02937"
"182.98800","15.24920","0.02926"
"183.14400","15.26218","0.02940"
"183.30000","15.27515","0.02944"
"183.45600","15.28818","0.03017"
"183.61200","15.30116","0.02924"
"183.76800","15.31407","0.02975"
"183.92400","15.32717","0.03004"
"184.08000","15.34020","0.03009"
"184.23600","15.35312","0.03022"
"184.39200","15.36615","0.03060"
"184.54800","15.37918","0.03049"
"184.70400","15.39222","0.03022"
"184.86000","15.40519","0.03147"
"185.01600","15.41823","0.03109"
"185.17200","15.43120","0.03050"
"185.32800","15.44411","0.03165"
"185.48400","15.45715","0.03176"
"185.64000","15.47018","0.03109"
"185.79600","15.48316","0.03148"
"185.95200","15.49613","0.03203"
"186.10800","15.50911","0.03162"
"186.26400","15.52208","0.03210"
"186.42000","15.53511","0.03212"
"186.57600","15.54815","0.03289"
"186.73200","15.56118","0.03235"
"186.88800","15.57416","0.03211"
"187.04400","15.58719","0.03220"
"187.20000","15.60023","0.03239"
"187.35600","15.61314","0.03258"
"187.51200","15.62611","0.03248"
"187.66800","15.63915","0.03342"
"187.82400","15.65224","0.03361"
"187.98000","15.66516","0.03347"
"188.13600","15.67819","0.03363"
"188.29200","15.69122","0.03349"
"188.44800","15.70420","0.03398"
"188.60400","15.71717","0.03407"
"188.76000","15.73021","0.03469"
"188.91600","15.74318","0.03477"
"189.07200","15.75616","0.03496"
"189.22800","15.76913","0.03479"
"189.38400","15.78216","0.03595"
"189.54000","15.79514","0.03581"
"189.69600","15.80811","0.03653"
"189.85200","15.82121","0.03587"
"190.00800","15.83424","0.03300"
"190.16400","15.84716","0.03424"
"190.32000","15.86019","0.03362"
"190.47600","15.87316","0.03498"
"190.63200","15.88614","0.03660"
"190.78800","15.89911","0.03601"
"190.94400","15.91221","0.03563"
"191.10000","15.92524","0.03632"
"191.25600","15.93816","0.03728"
"191.41200","15.95119","0.03664"
"191.56800","15.96416","0.03728"
"191.72400","15.97714","0.03858"
"191.88000","15.99017","0.03832"
"192.03600","16.00321","0.03827"
"192.19200","16.01618","0.03982"
"192.34800","16.02909","0.03931"
"192.50400","16.04219","0.03943"
"192.66000","16.05516","0.04037"
"192.81600","16.06814","0.03685"
"192.97200","16.08111","0.03709"
"193.12800","16.09415","0.03783"
"193.28400","16.10718","0.03734"
"193.44000","16.12009","0.03784"
"193.59600","16.13313","0.03935"
"193.75200","16.14616","0.03865"
"193.90800","16.15914","0.03897"
"194.06400","16.17217","0.03991"
"194.22000","16.18521","0.03882"
"194.37600","16.19818","0.03829"
"194.53200","16.21109","0.03949"
"194.68800","16.22419","0.03871"
"194.84400","16.23716","0.03891"
"195.00000","16.25020","0.03929"
"195.15600","16.26317","0.03925"
"195.31200","16.27621","0.03960"
"195.46800","16.28918","0.03983"
"195.62400","16.30215","0.03885"
"195.78000","16.31525","0.03975"
"195.93600","16.32816","0.03997"
"196.09200","16.34114","0.04038"
"196.24800","16.35417","0.04146"
"196.40400","16.36715","0.04129"
"196.56000","16.38012","0.04149"
"196.71600","16.39315","0.04203"
"196.87200","16.40619","0.04213"
"197.02800","16.41916","0.04330"
"197.18400","16.43214","0.04238"
"197.34000","16.44517","0.04322"
"197.49600","16.45820","0.04262"
"197.65200","16.47118","0.03605"
"197.80800","16.48415","0.02645"
"197.96400","16.49719","0.03055"
"198.12000","16.51016","0.02410"
"198.27600","16.52308","0.02778"
"198.43200","16.53623","0.02784"
"198.58800","16.54920","0.02423"
"198.74400","16.56218","0.03092"
"198.90000","16.57515","0.02573"
"199.05600","16.58819","0.02571"
"199.21200","16.60116","0.03119"
"199.36800","16.61408","0.02574"
"199.52400","16.62723","0.02712"
"199.68000","16.64021","0.03148"
"199.83600","16.65318","0.02473"
"199.99200","16.66615","0.03082"
"200.14800","16.67919","0.02827"
"200.30400","16.69216","0.02506"
"200.46000","16.70514","0.03365"
"200.61600","16.71817","0.02634"
"200.77200","16.73120","0.02917"
"200.92800","16.74412","0.03183"
"201.08400","16.75715","0.02658"
"201.24000","16.77019","0.03339"
"201.39600","16.78316","0.03135"
"201.55200","16.79620","0.02790"
"201.70800","16.80917","0.03370"
"201.86400","16.82220","0.02765"
"202.02000","16.83512","0.03288"
"202.17600","16.84821","0.03392"
"202.33200","16.86119","0.02940"
"202.48800","16.87416","0.03575"
"202.64400","16.88714","0.03122"
"202.80000","16.90023","0.03386"
"202.95600","16.91320","0.03478"
"203.11200","16.92612","0.03074"
"203.26800","16.93921","0.03569"
"203.42400","16.95219","0.03441"
"203.58000","16.96510","0.03282"
"203.73600","16.97814","0.03529"
"203.89200","16.99117","0.03243"
"204.04800","17.00420","0.03476"
"204.20400","17.01718","0.03456"
"204.36000","17.03021","0.03461"
"204.51600","17.04319","0.03675"
"204.67200","17.05616","0.03472"
"204.82800","17.06914","0.03524"
"204.98400","17.08217","0.03698"
"205.14000","17.09514","0.03480"
"205.29600","17.10812","0.03631"
"205.45200","17.12115","0.03730"
"205.60800","17.13419","0.03636"
"205.76400","17.14716","0.03814"
"205.92000","17.16019","0.03668"
"206.07600","17.17317","0.03787"
"206.23200","17.18620","0.03744"
"206.38800","17.19912","0.03670"
"206.54400","17.21221","0.03798"
"206.70000","17.22519","0.03808"
"206.85600","17.23816","0.03825"
"207.01200","17.25119","0.03930"
"207.16800","17.26423","0.03781"
"207.32400","17.27714","0.03809"
"207.48000","17.29012","0.03809"
"207.63600","17.30321","0.03893"
"207.79200","17.31618","0.03928"
"207.94800","17.32916","0.03922"
"208.10400","17.34219","0.03933"
"208.26000","17.35523","0.03950"
"208.41600","17.36814","0.03997"
"208.57200","17.38118","0.04024"
"208.72800","17.39421","0.04163"
"208.88400","17.40718","0.04096"
"209.04000","17.42016","0.04130"
"209.19600","17.43313","0.04075"
"209.35200","17.44623","0.04033"
"209.50800","17.45914","0.04117"
"209.66400","17.47218","0.04159"
"209.82000","17.48521","0.04147"
"209.97600","17.49818","0.04192"
"210.13200","17.51116","0.04225"
"210.28800","17.52419","0.04279"
"210.44400","17.53723","0.04244"
"210.60000","17.55020","0.04303"
"210.75600","17.56318","0.04256"
"210.91200","17.57621","0.04414"
"211.06800","17.58918","0.04348"
"211.22400","17.60216","0.04468"
"211.38000","17.61519","0.04477"
"211.53600","17.62823","0.04356"
"211.69200","17.64114","0.04416"
"211.84800","17.65417","0.04587"
"212.00400","17.66715","0.04441"
"212.16000","17.68012","0.04631"
"212.31600","17.69310","0.04591"
"212.47200","17.70619","0.04541"
"212.62800","17.71917","0.04655"
"212.78400","17.73214","0.04708"
"212.94000","17.74517","0.04682"
"213.09600","17.75821","0.04738"
"213.25200","17.77118","0.04761"
"213.40800","17.78416","0.04782"
"213.56400","17.79719","0.04867"
"213.72000","17.81017","0.04752"
"213.87600","17.82314","0.04842"
"214.03200","17.83617","0.04860"
"214.18800","17.84921","0.04748"
"214.34400","17.86212","0.04760"
"214.50000","17.87516","0.04818"
"214.65600","17.88819","0.04836"
"214.81200","17.90117","0.04788"
"214.96800","17.91414","0.04853"
"215.12400","17.92723","0.04901"
"215.28000","17.94021","0.04916"
"215.43600","17.95312","0.04952"
"215.59200","17.96616","0.04987"
"215.74800","17.97919","0.04999"
"215.90400","17.99216","0.04951"
"216.06000","18.00508","0.05030"
"216.21600","18.01817","0.05102"
"216.37200","18.03115","0.05115"
"216.52800","18.04412","0.05169"
"216.68400","18.05722","0.05218"
"216.84000","18.07019","0.05289"
"216.99600","18.08322","0.05265"
"217.15200","18.09620","0.05295"
"217.30800","18.10923","0.05306"
"217.46400","18.12221","0.05397"
"217.62000","18.13512","0.05426"
"217.77600","18.14816","0.05397"
"217.93200","18.16119","0.05490"
"218.08800","18.17416","0.05512"
"218.24400","18.18714","0.05479"
"218.40000","18.20017","0.05530"
"218.55600","18.21321","0.05609"
"218.71200","18.22618","0.05606"
"218.86800","18.23915","0.05653"
"219.02400","18.25219","0.05627"
"219.18000","18.26510","0.05625"
"219.33600","18.27814","0.05647"
"219.49200","18.29111","0.05712"
"219.64800","18.30415","0.05737"
"219.80400","18.31712","0.05790"
"219.96000","18.33015","0.05863"
"220.11600","18.34319","0.05751"
"220.27200","18.35616","0.05762"
"220.42800","18.36920","0.05825"
"220.58400","18.38223","0.05863"
"220.74000","18.39521","0.05875"
"220.89600","18.40812","0.05941"
"221.05200","18.42115","0.05962"
"221.20800","18.43419","0.06068"
"221.36400","18.44716","0.06065"
"221.52000","18.46020","0.06047"
"221.67600","18.47317","0.06158"
"221.83200","18.48615","0.06205"
"221.98800","18.49912","0.06185"
"222.14400","18.51221","0.06242"
"222.30000","18.52513","0.06297"
"222.45600","18.53816","0.06274"
"222.61200","18.55114","0.06369"
"222.76800","18.56417","0.06357"
"222.92400","18.57714","0.06429"
"223.08000","18.59012","0.06460"
"223.23600","18.60316","0.06424"
"223.39200","18.61619","0.06506"
"223.54800","18.62910","0.06479"
"223.70400","18.64220","0.06512"
"223.86000","18.65517","0.06528"
"224.01600","18.66814","0.06508"
"224.17200","18.68118","0.06578"
"224.32800","18.69421","0.06642"
"224.48400","18.70719","0.06167"
"224.64000","18.72010","0.01227"
"224.79600","18.73320","0.01875"
"224.95200","18.74617","0.02001"
"225.10800","18.75915","0.01745"
"225.26400","18.77212","0.01633"
"225.42000","18.78521","0.01656"
"225.57600","18.79819","0.01584"
"225.73200","18.81116","0.01610"
"225.88800","18.82420","0.01621"
"226.04400","18.83717","0.01677"
"226.20000","18.85015","0.01640"
"226.35600","18.86312","0.01607"
"226.51200","18.87615","0.01631"
"226.66800","18.88913","0.01644"
"226.82400","18.90210","0.01575"
"226.98000","18.91520","0.01615"
"227.13600","18.92817","0.01567"
"227.29200","18.94114","0.01611"
"227.44800","18.95418","0.01667"
"227.60400","18.96721","0.01718"
"227.76000","18.98019","0.01662"
"227.91600","18.99316","0.01622"
"228.07200","19.00620","0.01610"
"228.22800","19.01917","0.01607"
"228.38400","19.03214","0.01628"
"228.54000","19.04518","0.01591"
"228.69600","19.05815","0.01673"
"228.85200","19.07113","0.01666"
"229.00800","19.08410","0.01636"
"229.16400","19.09720","0.01659"
"229.32000","19.11017","0.01672"
"229.47600","19.12314","0.01654"
"229.63200","19.13618","0.01586"
"229.78800","19.14915","0.01594"
"229.94400","19.16213","0.01647"
"230.10000","19.17516","0.01597"
"230.25600","19.18820","0.01720"
"230.41200","19.20117","0.01620"
"230.56800","19.21408","0.01630"
"230.72400","19.22718","0.01665"
"230.88000","19.24021","0.01614"
"231.03600","19.25319","0.01593"
"231.19200","19.26616","0.01608"
"231.34800","19.27920","0.01649"
"231.50400","19.29217","0.01648"
"231.66000","19.30514","0.01635"
"231.72000","19.31017","0.01642"