File: Force_trajectories/170121_1/Specimen_RawData_3.csv
End date,"1/21/2017"
Specimen label,"14DT_NT1"
Maximum Load,"0.28781",N

Time,Extension,Load
(s),(mm),(N)
"0.00000","0.00000","-0.00006"
"0.45000","0.03773","0.00014"
"0.90000","0.07522","0.00083"
"1.35000","0.11270","0.00096"
"1.80000","0.15019","0.00093"
"2.25000","0.18774","0.00140"
"2.70000","0.22517","0.00133"
"3.15000","0.26266","0.00185"
"3.60000","0.30014","0.00145"
"4.05000","0.33775","0.00153"
"4.50000","0.37518","0.00191"
"4.95000","0.41273","0.00204"
"5.40000","0.45016","0.00215"
"5.85000","0.48764","0.00208"
"6.30000","0.52519","0.00206"
"6.75000","0.56268","0.00213"
"7.20000","0.60023","0.00248"
"7.65000","0.63772","0.00185"
"8.10000","0.67520","0.00317"
"8.55000","0.71269","0.00245"
"9.00000","0.75018","0.00210"
"9.45000","0.78773","0.00249"
"9.90000","0.82522","0.00279"
"10.35000","0.86270","0.00275"
"10.80000","0.90019","0.00245"
"11.25000","0.93762","0.00299"
"11.70000","0.97517","0.00236"
"12.15000","1.01277","0.00246"
"12.60000","1.05020","0.00240"
"13.05000","1.08775","0.00334"
"13.50000","1.12524","0.00261"
"13.95000","1.16261","0.00251"
"14.40000","1.20022","0.00243"
"14.85000","1.23770","0.00266"
"15.30000","1.27525","0.00277"
"15.75000","1.31274","0.00198"
"16.20000","1.35017","0.00175"
"16.65000","1.38766","0.00196"
"17.10000","1.42514","0.00137"
"17.55000","1.46269","0.00151"
"18.00000","1.50024","0.00155"
"18.45000","1.53767","0.00152"
"18.90000","1.57522","0.00145"
"19.35000","1.61276","0.00079"
"19.80000","1.65013","0.00049"
"20.25000","1.68768","0.00101"
"20.70000","1.72517","0.00052"
"21.15000","1.76271","0.00094"
"21.60000","1.80026","0.00051"
"22.05000","1.83769","0.00116"
"22.50000","1.87518","0.00083"
"22.95000","1.91273","0.00106"
"23.40000","1.95022","0.00093"
"23.85000","1.98770","0.00118"
"24.30000","2.02519","0.00084"
"24.75000","2.06268","0.00099"
"25.20000","2.10017","0.00098"
"25.65000","2.13772","0.00124"
"26.10000","2.17520","0.00141"
"26.55000","2.21269","0.00116"
"27.00000","2.25018","0.00154"
"27.45000","2.28767","0.00154"
"27.90000","2.32516","0.00143"
"28.35000","2.36270","0.00207"
"28.80000","2.40019","0.00090"
"29.25000","2.43774","0.00138"
"29.70000","2.47523","0.00116"
"30.15000","2.51272","0.00163"
"30.60000","2.55014","0.00141"
"31.05000","2.58763","0.00154"
"31.50000","2.62524","0.00201"
"31.95000","2.66279","0.00185"
"32.40000","2.70027","0.00208"
"32.85000","2.73770","0.00145"
"33.30000","2.77513","0.00150"
"33.75000","2.81268","0.00180"
"34.20000","2.85023","0.00198"
"34.65000","2.88771","0.00172"
"35.10000","2.92526","0.00134"
"35.55000","2.96275","0.00184"
"36.00000","3.00018","0.00231"
"36.45000","3.03773","0.00214"
"36.90000","3.07516","0.00245"
"37.35000","3.11270","0.00165"
"37.80000","3.15019","0.00238"
"38.25000","3.18774","0.00209"
"38.70000","3.22517","0.00226"
"39.15000","3.26265","0.00206"
"39.60000","3.30026","0.00261"
"40.05000","3.33775","0.00264"
"40.50000","3.37518","0.00217"
"40.95000","3.41267","0.00249"
"41.40000","3.45016","0.00261"
"41.85000","3.48764","0.00262"
"42.30000","3.52525","0.00296"
"42.75000","3.56274","0.00264"
"43.20000","3.60023","0.00219"
"43.65000","3.63771","0.00284"
"44.10000","3.67514","0.00263"
"44.55000","3.71269","0.00281"
"45.00000","3.75024","0.00246"
"45.45000","3.78767","0.00259"
"45.90000","3.82515","0.00259"
"46.35000","3.86270","0.00294"
"46.80000","3.90019","0.00243"
"47.25000","3.93768","0.00294"
"47.70000","3.97517","0.00258"
"48.15000","4.01277","0.00259"
"48.60000","4.05026","0.00258"
"49.05000","4.08775","0.00235"
"49.50000","4.12518","0.00280"
"49.95000","4.16267","0.00305"
"50.40000","4.20021","0.00280"
"50.85000","4.23776","0.00287"
"51.30000","4.27519","0.00319"
"51.75000","4.31274","0.00261"
"52.20000","4.35023","0.00292"
"52.65000","4.38765","0.00244"
"53.10000","4.42520","0.00249"
"53.55000","4.46269","0.00285"
"54.00000","4.50018","0.00257"
"54.45000","4.53773","0.00318"
"54.90000","4.57521","0.00266"
"55.35000","4.61264","0.00312"
"55.80000","4.65025","0.00291"
"56.25000","4.68774","0.00216"
"56.70000","4.72523","0.00253"
"57.15000","4.76277","0.00245"
"57.60000","4.80020","0.00254"
"58.05000","4.83763","0.00203"
"58.50000","4.87518","0.00226"
"58.95000","4.91273","0.00209"
"59.40000","4.95021","0.00291"
"59.85000","4.98770","0.00233"
"60.30000","5.02519","0.00242"
"60.75000","5.06262","0.00212"
"61.20000","5.10017","0.00216"
"61.65000","5.13771","0.00283"
"62.10000","5.17526","0.00273"
"62.55000","5.21275","0.00249"
"63.00000","5.25018","0.00244"
"63.45000","5.28761","0.00270"
"63.90000","5.32515","0.00217"
"64.35000","5.36270","0.00252"
"64.80000","5.40025","0.00283"
"65.25000","5.43774","0.00307"
"65.70000","5.47523","0.00250"
"66.15000","5.51265","0.00268"
"66.60000","5.55020","0.00283"
"67.05000","5.58763","0.00318"
"67.50000","5.62524","0.00303"
"67.95000","5.66273","0.00339"
"68.40000","5.70021","0.00266"
"68.85000","5.73770","0.00308"
"69.30000","5.77513","0.00288"
"69.75000","5.81268","0.00325"
"70.20000","5.85023","0.00280"
"70.65000","5.88771","0.00307"
"71.10000","5.92520","0.00349"
"71.55000","5.96269","0.00304"
"72.00000","6.00018","0.00327"
"72.45000","6.03773","0.00264"
"72.90000","6.07521","0.00294"
"73.35000","6.11270","0.00295"
"73.80000","6.15025","0.00301"
"74.25000","6.18768","0.00274"
"74.70000","6.22517","0.00315"
"75.15000","6.26271","0.00292"
"75.60000","6.30026","0.00333"
"76.05000","6.33769","0.00342"
"76.50000","6.37524","0.00321"
"76.95000","6.41267","0.00338"
"77.40000","6.45015","0.00341"
"77.85000","6.48770","0.00363"
"78.30000","6.52525","0.00350"
"78.75000","6.56268","0.00352"
"79.20000","6.60023","0.00369"
"79.65000","6.63765","0.00407"
"80.10000","6.67514","0.00471"
"80.55000","6.71263","0.00398"
"81.00000","6.75018","0.00400"
"81.45000","6.78773","0.00404"
"81.90000","6.82527","0.00431"
"82.35000","6.86270","0.00381"
"82.80000","6.90019","0.00427"
"83.25000","6.93768","0.00432"
"83.70000","6.97517","0.00423"
"84.15000","7.01277","0.00439"
"84.60000","7.05020","0.00500"
"85.05000","7.08769","0.00480"
"85.50000","7.12518","0.00548"
"85.95000","7.16267","0.00455"
"86.40000","7.20021","0.00541"
"86.85000","7.23770","0.00448"
"87.30000","7.27519","0.00530"
"87.75000","7.31274","0.00527"
"88.20000","7.35023","0.00541"
"88.65000","7.38771","0.00529"
"89.10000","7.42514","0.00611"
"89.55000","7.46269","0.00529"
"90.00000","7.50024","0.00613"
"90.45000","7.53773","0.00559"
"90.90000","7.57515","0.00565"
"91.35000","7.61270","0.00558"
"91.80000","7.65025","0.00555"
"92.25000","7.68774","0.00596"
"92.70000","7.72523","0.00631"
"93.15000","7.76266","0.00704"
"93.60000","7.80014","0.00627"
"94.05000","7.83769","0.00700"
"94.50000","7.87524","0.00650"
"94.95000","7.91273","0.00705"
"95.40000","7.95021","0.00585"
"95.85000","7.98776","0.00655"
"96.30000","8.02519","0.00676"
"96.75000","8.06268","0.00672"
"97.20000","8.10017","0.00682"
"97.65000","8.13771","0.00624"
"98.10000","8.17520","0.00685"
"98.55000","8.21275","0.00636"
"99.00000","8.25018","0.00604"
"99.45000","8.28761","0.00732"
"99.90000","8.32515","0.00729"
"100.35000","8.36270","0.00734"
"100.80000","8.40025","0.00735"
"101.25000","8.43774","0.00683"
"101.70000","8.47523","0.00685"
"102.15000","8.51265","0.00763"
"102.60000","8.55020","0.00749"
"103.05000","8.58775","0.00817"
"103.50000","8.62518","0.00823"
"103.95000","8.66273","0.00843"
"104.40000","8.70021","0.00798"
"104.85000","8.73770","0.00789"
"105.30000","8.77525","0.00797"
"105.75000","8.81274","0.00869"
"106.20000","8.85023","0.00912"
"106.65000","8.88765","0.00970"
"107.10000","8.92520","0.00940"
"107.55000","8.96263","0.00963"
"108.00000","9.00018","0.00993"
"108.45000","9.03779","0.01025"
"108.90000","9.07521","0.01079"
"109.35000","9.11276","0.01029"
"109.80000","9.15019","0.01085"
"110.25000","9.18762","0.01049"
"110.70000","9.22517","0.01055"
"111.15000","9.26277","0.01132"
"111.60000","9.30020","0.01145"
"112.05000","9.33775","0.01069"
"112.50000","9.37518","0.01066"
"112.95000","9.41267","0.01138"
"113.40000","9.45021","0.01126"
"113.85000","9.48770","0.01149"
"114.30000","9.52519","0.01245"
"114.75000","9.56274","0.01345"
"115.20000","9.60017","0.01318"
"115.65000","9.63765","0.01358"
"116.10000","9.67520","0.01457"
"116.55000","9.71269","0.01465"
"117.00000","9.75018","0.01523"
"117.45000","9.78773","0.01442"
"117.90000","9.82521","0.01593"
"118.35000","9.86270","0.01569"
"118.80000","9.90013","0.01502"
"119.25000","9.93774","0.01562"
"119.70000","9.97522","0.01549"
"120.15000","10.01265","0.01563"
"120.60000","10.05020","0.01646"
"121.05000","10.08769","0.01626"
"121.50000","10.12524","0.01654"
"121.95000","10.16273","0.01751"
"122.40000","10.20021","0.01799"
"122.85000","10.23770","0.01842"
"123.30000","10.27519","0.01866"
"123.75000","10.31268","0.01966"
"124.20000","10.35017","0.02024"
"124.65000","10.38771","0.02034"
"125.10000","10.42520","0.02150"
"125.55000","10.46269","0.02224"
"126.00000","10.50024","0.02285"
"126.45000","10.53767","0.02285"
"126.90000","10.57515","0.02330"
"127.35000","10.61264","0.02322"
"127.80000","10.65025","0.02432"
"128.25000","10.68774","0.02209"
"128.70000","10.72523","0.02366"
"129.15000","10.76271","0.02433"
"129.60000","10.80008","0.02583"
"130.05000","10.83769","0.02616"
"130.50000","10.87518","0.02743"
"130.95000","10.91273","0.02764"
"131.40000","10.95027","0.02805"
"131.85000","10.98770","0.02881"
"132.30000","11.02519","0.02839"
"132.75000","11.06268","0.02922"
"133.20000","11.10023","0.02982"
"133.65000","11.13771","0.02995"
"134.10000","11.17520","0.03100"
"134.55000","11.21269","0.03185"
"135.00000","11.25012","0.03341"
"135.45000","11.28767","0.03337"
"135.90000","11.32515","0.03472"
"136.35000","11.36270","0.03600"
"136.80000","11.40019","0.03642"
"137.25000","11.43774","0.03748"
"137.70000","11.47523","0.03792"
"138.15000","11.51265","0.03861"
"138.60000","11.55020","0.03923"
"139.05000","11.58769","0.03973"
"139.50000","11.62524","0.04015"
"139.95000","11.66267","0.04044"
"140.40000","11.70015","0.04162"
"140.85000","11.73770","0.03320"
"141.30000","11.77525","0.03592"
"141.75000","11.81274","0.03517"
"142.20000","11.85022","0.03790"
"142.65000","11.88771","0.03852"
"143.10000","11.92508","0.03937"
"143.55000","11.96269","0.04027"
"144.00000","12.00024","0.04172"
"144.45000","12.03779","0.04272"
"144.90000","12.07521","0.04426"
"145.35000","12.11264","0.04533"
"145.80000","12.15013","0.04602"
"146.25000","12.18768","0.04758"
"146.70000","12.22517","0.04925"
"147.15000","12.26271","0.05052"
"147.60000","12.30026","0.05109"
"148.05000","12.33769","0.05220"
"148.50000","12.37518","0.05263"
"148.95000","12.41267","0.05247"
"149.40000","12.45015","0.05447"
"149.85000","12.48770","0.05114"
"150.30000","12.52519","0.05065"
"150.75000","12.56274","0.05191"
"151.20000","12.60017","0.05415"
"151.65000","12.63765","0.05428"
"152.10000","12.67520","0.05607"
"152.55000","12.71269","0.05664"
"153.00000","12.75018","0.05813"
"153.45000","12.78767","0.05865"
"153.90000","12.82521","0.05949"
"154.35000","12.86270","0.06064"
"154.80000","12.90019","0.06129"
"155.25000","12.93774","0.06222"
"155.70000","12.97523","0.06267"
"156.15000","13.01271","0.06317"
"156.60000","13.05014","0.06368"
"157.05000","13.08769","0.06452"
"157.50000","13.12518","0.06503"
"157.95000","13.16267","0.06589"
"158.40000","13.20021","0.06660"
"158.85000","13.23776","0.06795"
"159.30000","13.27519","0.06873"
"159.75000","13.31262","0.06972"
"160.20000","13.35017","0.06729"
"160.65000","13.38771","0.06835"
"161.10000","13.42526","0.06986"
"161.55000","13.46275","0.07130"
"162.00000","13.50018","0.07264"
"162.45000","13.53761","0.06350"
"162.90000","13.57521","0.06493"
"163.35000","13.61270","0.06466"
"163.80000","13.65019","0.06679"
"164.25000","13.68774","0.06712"
"164.70000","13.72523","0.06873"
"165.15000","13.76271","0.06943"
"165.60000","13.80020","0.07080"
"166.05000","13.83763","0.07274"
"166.50000","13.87524","0.07428"
"166.95000","13.91273","0.07582"
"167.40000","13.95021","0.07743"
"167.85000","13.98770","0.07920"
"168.30000","14.02513","0.08110"
"168.75000","14.06274","0.08332"
"169.20000","14.10023","0.08563"
"169.65000","14.13771","0.08717"
"170.10000","14.17520","0.08916"
"170.55000","14.21263","0.09091"
"171.00000","14.25018","0.09315"
"171.45000","14.28773","0.09406"
"171.90000","14.32521","0.09545"
"172.35000","14.36270","0.09692"
"172.80000","14.40025","0.09838"
"173.25000","14.43768","0.10005"
"173.70000","14.47517","0.10213"
"174.15000","14.51271","0.10456"
"174.60000","14.55020","0.10640"
"175.05000","14.58775","0.10764"
"175.50000","14.62524","0.10956"
"175.95000","14.66267","0.11119"
"176.40000","14.70015","0.11175"
"176.85000","14.73764","0.11285"
"177.30000","14.77525","0.11359"
"177.75000","14.81274","0.11426"
"178.20000","14.85023","0.11465"
"178.65000","14.88771","0.11502"
"179.10000","14.92514","0.11554"
"179.55000","14.96269","0.11600"
"180.00000","15.00024","0.11689"
"180.45000","15.03773","0.11791"
"180.90000","15.07521","0.11866"
"181.35000","15.11270","0.11977"
"181.80000","15.15013","0.12138"
"182.25000","15.18774","0.12205"
"182.70000","15.22523","0.12476"
"183.15000","15.26265","0.12639"
"183.60000","15.30020","0.12907"
"184.05000","15.33769","0.13124"
"184.50000","15.37518","0.13350"
"184.95000","15.41273","0.13554"
"185.40000","15.45021","0.13694"
"185.85000","15.48776","0.13939"
"186.30000","15.52525","0.14084"
"186.75000","15.56274","0.14315"
"187.20000","15.60017","0.14486"
"187.65000","15.63765","0.14608"
"188.10000","15.67520","0.15057"
"188.55000","15.71275","0.13616"
"189.00000","15.75018","0.13584"
"189.45000","15.78766","0.13802"
"189.90000","15.82509","0.14016"
"190.35000","15.86270","0.14375"
"190.80000","15.90025","0.14547"
"191.25000","15.93774","0.14801"
"191.70000","15.97522","0.14877"
"192.15000","16.01271","0.13236"
"192.60000","16.05014","0.12669"
"193.05000","16.08763","0.12750"
"193.50000","16.12518","0.13261"
"193.95000","16.16273","0.13288"
"194.40000","16.20021","0.13510"
"194.85000","16.23770","0.13814"
"195.30000","16.27519","0.13882"
"195.75000","16.31274","0.14130"
"196.20000","16.35016","0.14117"
"196.65000","16.38771","0.14329"
"197.10000","16.42526","0.14512"
"197.55000","16.46275","0.14611"
"198.00000","16.50018","0.14766"
"198.45000","16.53766","0.14877"
"198.90000","16.57521","0.15007"
"199.35000","16.61270","0.15118"
"199.80000","16.65019","0.15279"
"200.25000","16.68774","0.15359"
"200.70000","16.72523","0.15407"
"201.15000","16.76271","0.15513"
"201.60000","16.80020","0.15599"
"202.05000","16.83769","0.15748"
"202.50000","16.87524","0.15884"
"202.95000","16.91273","0.15967"
"203.40000","16.95015","0.16030"
"203.85000","16.98764","0.16176"
"204.30000","17.02519","0.16206"
"204.75000","17.06274","0.16304"
"205.20000","17.10022","0.16370"
"205.65000","17.13771","0.16508"
"206.10000","17.17514","0.16593"
"206.55000","17.21263","0.16764"
"207.00000","17.25018","0.16898"
"207.45000","17.28773","0.17150"
"207.90000","17.32521","0.17237"
"208.35000","17.36276","0.17429"
"208.80000","17.40019","0.17341"
"209.25000","17.43768","0.00478"
"209.70000","17.47517","0.01850"
"210.15000","17.51271","0.01272"
"210.60000","17.55020","0.00937"
"211.05000","17.58781","0.00865"
"211.50000","17.62524","0.00581"
"211.95000","17.66261","0.00645"
"212.40000","17.70015","0.00734"
"212.85000","17.73770","0.00808"
"213.30000","17.77525","0.01076"
"213.75000","17.81274","0.01335"
"214.20000","17.85022","0.01565"
"214.65000","17.88765","0.01744"
"215.10000","17.92514","0.01732"
"215.55000","17.96269","0.01784"
"216.00000","18.00024","0.01751"
"216.45000","18.03773","0.01752"
"216.90000","18.07521","0.01616"
"217.35000","18.11270","0.01619"
"217.80000","18.15019","0.01577"
"218.25000","18.18768","0.01743"
"218.70000","18.22523","0.01674"
"219.15000","18.26271","0.01769"
"219.60000","18.30020","0.01699"
"220.05000","18.33763","0.01782"
"220.50000","18.37518","0.01946"
"220.95000","18.41272","0.02038"
"221.40000","18.45021","0.02092"
"221.85000","18.48770","0.02111"
"222.30000","18.52519","0.02313"
"222.75000","18.56262","0.02302"
"223.20000","18.60017","0.02294"
"223.65000","18.63771","0.02461"
"224.10000","18.67526","0.02518"
"224.55000","18.71269","0.02586"
"225.00000","18.75024","0.02692"
"225.45000","18.78766","0.02822"
"225.90000","18.82521","0.02912"
"226.35000","18.86270","0.02975"
"226.80000","18.90025","0.03079"
"227.25000","18.93768","0.03201"
"227.70000","18.97522","0.03269"
"228.15000","19.01271","0.03251"
"228.60000","19.05014","0.03435"
"229.05000","19.08769","0.03432"
"229.50000","19.12518","0.03575"
"229.95000","19.16273","0.03495"
"230.40000","19.20027","0.03236"
"230.85000","19.23770","0.03422"
"231.30000","19.27519","0.03431"
"231.75000","19.31268","0.03611"
"232.20000","19.35023","0.03788"
"232.65000","19.38765","0.03863"
"233.10000","19.42520","0.04084"
"233.55000","19.46269","0.04257"
"234.00000","19.50018","0.04488"
"234.45000","19.53766","0.04667"
"234.90000","19.57521","0.04892"
"235.35000","19.61276","0.05058"
"235.80000","19.65019","0.05237"
"236.25000","19.68768","0.05359"
"236.70000","19.72516","0.05550"
"237.15000","19.76271","0.05697"
"237.60000","19.80026","0.05717"
"238.05000","19.83769","0.05900"
"238.50000","19.87524","0.06063"
"238.95000","19.91272","0.06214"
"239.40000","19.95015","0.06324"
"239.85000","19.98770","0.06422"
"240.30000","20.02519","0.06317"
"240.75000","20.06274","0.06404"
"241.20000","20.10023","0.06537"
"241.65000","20.13771","0.06773"
"242.10000","20.17508","0.06958"
"242.55000","20.21269","0.07228"
"243.00000","20.25018","0.07527"
"243.45000","20.28772","0.07834"
"243.90000","20.32527","0.08247"
"244.35000","20.36270","0.08571"
"244.80000","20.40019","0.08865"
"245.25000","20.43768","0.09158"
"245.70000","20.47517","0.09411"
"246.15000","20.51271","0.09623"
"246.60000","20.55026","0.09893"
"247.05000","20.58775","0.10243"
"247.50000","20.62524","0.10492"
"247.95000","20.66267","0.10940"
"248.40000","20.70021","0.07941"
"248.85000","20.73770","0.08222"
"249.30000","20.77519","0.08599"
"249.75000","20.81268","0.08968"
"250.20000","20.85016","0.09345"
"250.65000","20.88765","0.09663"
"251.10000","20.92526","0.09889"
"251.55000","20.96275","0.10402"
"252.00000","21.00024","0.10741"
"252.45000","21.03772","0.11058"
"252.90000","21.07521","0.11288"
"253.35000","21.11264","0.11428"
"253.80000","21.15025","0.11538"
"254.25000","21.18768","0.11619"
"254.70000","21.22517","0.11798"
"255.15000","21.26271","0.12102"
"255.60000","21.30014","0.12592"
"256.05000","21.33769","0.13067"
"256.50000","21.37518","0.13467"
"256.95000","21.41278","0.13798"
"257.40000","21.45021","0.14167"
"257.85000","21.48770","0.14569"
"258.30000","21.52519","0.14846"
"258.75000","21.56262","0.15076"
"259.20000","21.60022","0.15366"
"259.65000","21.63771","0.15683"
"260.10000","21.67520","0.15951"
"260.55000","21.71281","0.16206"
"261.00000","21.75017","0.16395"
"261.45000","21.78767","0.16591"
"261.90000","21.82515","0.16899"
"262.35000","21.86270","0.17241"
"262.80000","21.90025","0.17727"
"263.25000","21.93773","0.18280"
"263.70000","21.97516","0.19125"
"264.15000","22.01265","0.19955"
"264.60000","22.05014","0.20749"
"265.05000","22.08769","0.21211"
"265.50000","22.12524","0.20080"
"265.95000","22.16272","0.20362"
"266.40000","22.20021","0.21204"
"266.85000","22.23770","0.21608"
"267.30000","22.27519","0.21884"
"267.75000","22.31268","0.22175"
"268.20000","22.35023","0.22476"
"268.65000","22.38771","0.22928"
"269.10000","22.42520","0.23396"
"269.55000","22.46269","0.23308"
"270.00000","22.50018","0.23707"
"270.45000","22.53773","0.23918"
"270.90000","22.57521","0.24250"
"271.35000","22.61276","0.24659"
"271.80000","22.65025","0.25171"
"272.25000","22.68762","0.25485"
"272.70000","22.72516","0.25811"
"273.15000","22.76271","0.26071"
"273.60000","22.80026","0.26242"
"274.05000","22.83775","0.26357"
"274.50000","22.87518","0.26442"
"274.95000","22.91266","0.26507"
"275.40000","22.95015","0.26613"
"275.85000","22.98770","0.26752"
"276.30000","23.02519","0.26940"
"276.75000","23.06274","0.27175"
"277.20000","23.10023","0.27331"
"277.65000","23.13771","0.27705"
"278.10000","23.17514","0.27940"
"278.55000","23.21263","0.28408"
"279.00000","23.25024","0.12411"
"279.45000","23.28772","0.01654"
"279.90000","23.32527","0.00893"
"280.35000","23.36270","0.00315"
"280.80000","23.40013","0.00754"
"281.25000","23.43774","0.01289"
"281.70000","23.47516","0.00844"
"282.15000","23.51271","0.00728"
"282.60000","23.55014","0.01287"
"283.05000","23.58769","0.01606"
"283.50000","23.62518","0.01454"
"283.95000","23.66273","0.01436"
"284.40000","23.70021","0.02116"
"284.85000","23.73770","0.02411"
"285.30000","23.77519","0.02481"
"285.75000","23.81268","0.02366"
"286.20000","23.85016","0.02528"
"286.65000","23.88771","0.02895"
"287.10000","23.92520","0.03195"
"287.55000","23.96275","0.03268"
"288.00000","24.00024","0.03378"
"288.45000","24.03772","0.03590"
"288.90000","24.07509","0.03830"
"289.35000","24.11270","0.04101"
"289.80000","24.15025","0.04339"
"290.25000","24.18773","0.04446"
"290.70000","24.22523","0.04609"
"291.15000","24.26265","0.04953"
"291.60000","24.30014","0.05073"
"292.05000","24.33769","0.05302"
"292.50000","24.37524","0.05457"
"292.95000","24.41272","0.05655"
"293.40000","24.45027","0.05734"
"293.85000","24.48770","0.05864"
"294.30000","24.52519","0.06001"
"294.75000","24.56268","0.06075"
"295.20000","24.60016","0.06163"
"295.65000","24.63771","0.06250"
"296.10000","24.67520","0.06367"
"296.55000","24.71275","0.06443"
"297.00000","24.75018","0.06560"
"297.45000","24.78766","0.06685"
"297.90000","24.82521","0.06826"
"298.35000","24.86270","0.07035"
"298.80000","24.90019","0.07193"
"299.25000","24.93767","0.07429"
"299.70000","24.97517","0.07541"
"300.15000","25.01265","0.07778"
"300.60000","25.05026","0.08060"
"301.05000","25.08775","0.08376"
"301.50000","25.12518","0.08589"
"301.95000","25.16273","0.08812"
"302.40000","25.20015","0.09110"
"302.85000","25.23770","0.09361"
"303.30000","25.27525","0.09596"
"303.75000","25.31268","0.09802"
"304.20000","25.35016","0.10011"
"304.65000","25.38771","0.10272"
"305.10000","25.42520","0.10632"
"305.55000","25.46263","0.10791"
"306.00000","25.50011","0.10873"
"306.45000","25.53778","0.11026"
"306.90000","25.57527","0.11254"
"307.35000","25.61276","0.11339"
"307.80000","25.65019","0.11450"
"308.25000","25.68762","0.11505"
"308.70000","25.72516","0.11561"
"309.15000","25.76271","0.11627"
"309.60000","25.80020","0.11704"
"310.05000","25.83775","0.11897"
"310.50000","25.87523","0.12224"
"310.95000","25.91266","0.12433"
"311.40000","25.95021","0.12763"
"311.85000","25.98770","0.12991"
"312.30000","26.02519","0.13300"
"312.75000","26.06268","0.13663"
"313.20000","26.10022","0.13988"
"313.65000","26.13765","0.14207"
"314.10000","26.17520","0.14426"
"314.55000","26.21269","0.14639"
"315.00000","26.25024","0.14854"
"315.45000","26.28773","0.14989"
"315.90000","26.32521","0.15123"
"316.35000","26.36270","0.15255"
"316.80000","26.40013","0.15434"
"317.25000","26.43773","0.15590"
"317.70000","26.47523","0.15765"
"318.15000","26.51271","0.15970"
"318.60000","26.55020","0.16121"
"319.05000","26.58763","0.16298"
"319.50000","26.62524","0.16474"
"319.95000","26.66272","0.16636"
"320.40000","26.70021","0.16855"
"320.85000","26.73770","0.17088"
"321.30000","26.77519","0.17357"
"321.75000","26.81262","0.17929"
"322.20000","26.85016","0.18460"
"322.65000","26.88771","0.19058"
"323.10000","26.92520","0.19748"
"323.55000","26.96275","0.20317"
"324.00000","27.00023","0.20822"
"324.45000","27.03766","0.21158"
"324.90000","27.07521","0.02913"
"325.35000","27.11264","0.03680"
"325.80000","27.15025","0.04335"
"326.25000","27.18774","0.04233"
"326.70000","27.22522","0.04978"
"327.15000","27.26265","0.04835"
"327.60000","27.30014","0.05329"
"328.05000","27.33775","0.05470"
"328.50000","27.37524","0.05538"
"328.95000","27.41273","0.05651"
"329.40000","27.45021","0.05668"
"329.85000","27.48770","0.05851"
"330.30000","27.52519","0.06004"
"330.75000","27.56268","0.06059"
"331.20000","27.60023","0.06149"
"331.65000","27.63765","0.03556"
"332.10000","27.67526","0.03699"
"332.55000","27.71269","0.03993"
"333.00000","27.75018","0.04177"
"333.45000","27.78766","0.04125"
"333.90000","27.82521","0.04411"
"334.35000","27.86270","0.04538"
"334.80000","27.90019","0.04715"
"335.25000","27.93768","0.04865"
"335.70000","27.97516","0.04972"
"336.15000","28.01271","0.05154"
"336.60000","28.05026","0.05287"
"337.05000","28.08769","0.05394"
"337.50000","28.12524","0.05433"
"337.95000","28.16266","0.05480"
"338.40000","28.20015","0.00339"
"338.85000","28.23770","0.00307"
"339.30000","28.27525","0.00300"
"339.75000","28.31268","0.00329"
"340.20000","28.35022","0.00367"
"340.65000","28.38771","0.00416"
"341.10000","28.42514","0.00429"
"341.55000","28.46269","0.00509"
"342.00000","28.50018","0.00569"
"342.45000","28.53772","0.00569"
"342.90000","28.57527","0.00622"
"343.35000","28.61270","0.00622"
"343.80000","28.65019","0.00724"
"344.25000","28.68768","0.00695"
"344.70000","28.72516","0.00794"
"345.15000","28.76271","0.00892"
"345.60000","28.80020","0.00881"
"346.05000","28.83775","0.00968"
"346.50000","28.87518","0.00902"
"346.95000","28.91266","0.00999"
"347.40000","28.95015","0.00989"
"347.85000","28.98776","0.01040"
"348.30000","29.02519","0.01081"
"348.75000","29.06274","0.01127"
"349.20000","29.10016","0.01365"
"349.65000","29.13771","0.01282"
"350.10000","29.17526","0.01359"
"350.55000","29.21275","0.01367"
"351.00000","29.25023","0.01395"
"351.45000","29.28766","0.01482"
"351.90000","29.32515","0.01553"
"352.35000","29.36264","0.01588"
"352.80000","29.40019","0.01707"
"353.25000","29.43774","0.01600"
"353.70000","29.47522","0.01691"
"354.15000","29.51271","0.01734"
"354.60000","29.55014","0.01891"
"355.05000","29.58763","0.01864"
"355.50000","29.62518","0.02019"
"355.95000","29.66273","0.02144"
"356.40000","29.70021","0.02256"
"356.85000","29.73776","0.02405"
"357.30000","29.77519","0.02541"
"357.75000","29.81261","0.02596"
"358.20000","29.85016","0.02811"
"358.65000","29.88771","0.02897"
"359.10000","29.92526","0.03021"
"359.55000","29.96275","0.03120"
"360.00000","30.00024","0.03210"
"360.45000","30.03767","0.03284"
"360.90000","30.07521","0.03467"
"361.35000","30.11270","0.03555"
"361.80000","30.15019","0.03674"
"362.25000","30.18774","0.03854"
"362.70000","30.22523","0.03959"
"363.15000","30.26271","0.04093"
"363.60000","30.30020","0.04291"
"364.05000","30.33775","0.04383"
"364.50000","30.37529","0.04507"
"364.95000","30.41272","0.04684"
"365.40000","30.45021","0.04798"
"365.85000","30.48764","0.04935"
"366.30000","30.52519","0.05143"
"366.75000","30.56274","0.05250"
"367.20000","30.60022","0.05357"
"367.65000","30.63771","0.05488"
"368.10000","30.67520","0.05566"
"368.55000","30.71263","0.05651"
"369.00000","30.75024","0.05727"
"369.45000","30.78773","0.05876"
"369.90000","30.82521","0.05934"
"370.35000","30.86270","0.05990"
"370.80000","30.90019","0.06072"
"371.25000","30.93762","0.06100"
"371.70000","30.97522","0.06196"
"372.15000","31.01271","0.06248"
"372.60000","31.05020","0.06262"
"373.05000","31.08775","0.03216"
"373.50000","31.12518","0.02924"
"373.95000","31.16267","0.01970"
"374.40000","31.20015","0.00566"
"374.85000","31.23770","0.00500"
"375.30000","31.27525","0.00348"
"375.75000","31.31273","0.00441"
"376.20000","31.35022","0.00537"
"376.65000","31.38771","0.00536"
"377.10000","31.42514","0.00547"
"377.55000","31.46275","0.00825"
"378.00000","31.50018","0.00673"
"378.45000","31.53766","0.00836"
"378.90000","31.57521","0.00759"
"379.35000","31.61270","0.00889"
"379.80000","31.65018","0.00866"
"380.25000","31.68773","0.00903"
"380.70000","31.72522","0.00958"
"381.15000","31.76271","0.00948"
"381.60000","31.80020","0.00611"
"382.05000","31.83769","0.00546"
"382.50000","31.87517","0.00429"
"382.95000","31.91272","0.00495"
"383.40000","31.95021","0.00480"
"383.85000","31.98770","0.00530"
"384.30000","32.02525","0.00612"
"384.75000","32.06261","0.00575"
"385.20000","32.10016","0.00608"
"385.65000","32.13765","0.00706"
"386.10000","32.17526","0.00641"
"386.55000","32.21275","0.00580"
"387.00000","32.25023","0.00509"
"387.45000","32.28766","0.00512"
"387.90000","32.32509","0.00555"
"388.35000","32.36270","0.00502"
"388.80000","32.40019","0.00599"
"389.25000","32.43773","0.00546"
"389.70000","32.47528","0.00628"
"390.15000","32.51271","0.00646"
"390.60000","32.55014","0.00667"
"391.05000","32.58762","0.00661"
"391.50000","32.62524","0.00743"
"391.95000","32.66272","0.00731"
"392.40000","32.70021","0.00796"
"392.85000","32.73770","0.00741"
"393.30000","32.77513","0.00848"
"393.75000","32.81268","0.00902"
"394.20000","32.85016","0.00975"
"394.65000","32.88777","0.00996"
"395.10000","32.92520","0.01017"
"395.55000","32.96269","0.01060"
"396.00000","33.00023","0.01154"
"396.45000","33.03766","0.01217"
"396.90000","33.07521","0.01257"
"397.35000","33.11270","0.01230"
"397.80000","33.15018","0.01415"
"398.25000","33.18768","0.01447"
"398.70000","33.22516","0.01390"
"399.15000","33.26271","0.01411"
"399.60000","33.30026","0.01514"
"400.05000","33.33775","0.01657"
"400.50000","33.37523","0.01731"
"400.95000","33.41272","0.01737"
"401.40000","33.45009","0.01809"
"401.85000","33.48770","0.01866"
"402.30000","33.52525","0.01920"
"402.75000","33.56274","0.01983"
"403.20000","33.60022","0.02122"
"403.65000","33.63765","0.02180"
"404.10000","33.67514","0.02283"
"404.55000","33.71268","0.02270"
"405.00000","33.75017","0.02354"
"405.45000","33.78778","0.02458"
"405.90000","33.82521","0.02445"
"406.35000","33.86270","0.02407"
"406.80000","33.90018","0.02403"
"407.25000","33.93768","0.02554"
"407.70000","33.97516","0.02658"
"408.15000","34.01265","0.02731"
"408.60000","34.05020","0.02808"
"409.05000","34.08781","0.02845"
"409.50000","34.12518","0.02974"
"409.95000","34.16266","0.02937"
"410.40000","34.20021","0.03101"
"410.85000","34.23770","0.03123"
"411.30000","34.27518","0.03171"
"411.75000","34.31267","0.03283"
"412.20000","34.35022","0.03388"
"412.65000","34.38771","0.03375"
"413.10000","34.42520","0.03368"
"413.55000","34.46275","0.03462"
"414.00000","34.50023","0.03542"
"414.45000","34.53772","0.03691"
"414.90000","34.57515","0.03646"
"415.35000","34.61270","0.03709"
"415.80000","34.65019","0.03828"
"416.25000","34.68768","0.03918"
"416.70000","34.72516","0.04050"
"417.15000","34.76277","0.04096"
"417.60000","34.80020","0.04187"
"418.05000","34.83763","0.04142"
"418.50000","34.87517","0.04211"
"418.95000","34.91272","0.04307"
"419.40000","34.95027","0.04393"
"419.85000","34.98776","0.04508"
"420.30000","35.02519","0.04710"
"420.75000","35.06261","0.04809"
"421.20000","35.10016","0.04943"
"421.65000","35.13771","0.05049"
"422.10000","35.17526","0.05148"
"422.55000","35.21281","0.05248"
"423.00000","35.25024","0.05353"
"423.45000","35.28766","0.05513"
"423.90000","35.32521","0.05567"
"424.35000","35.36264","0.05686"
"424.80000","35.40018","0.05805"
"425.25000","35.43773","0.05858"
"425.70000","35.47528","0.05930"
"426.15000","35.51271","0.06023"
"426.60000","35.55014","0.06075"
"427.05000","35.58775","0.06142"
"427.50000","35.62523","0.06189"
"427.95000","35.66272","0.06239"
"428.40000","35.70021","0.06279"
"428.85000","35.73770","0.06335"
"429.30000","35.77512","0.06414"
"429.75000","35.81268","0.06441"
"430.20000","35.85022","0.06490"
"430.65000","35.88771","0.06577"
"431.10000","35.92526","0.06668"
"431.55000","35.96263","0.06778"
"432.00000","36.00017","0.06876"
"432.45000","36.03772","0.06926"
"432.90000","36.07521","0.07006"
"433.35000","36.11270","0.07175"
"433.80000","36.15019","0.07283"
"434.25000","36.18768","0.07428"
"434.70000","36.22516","0.07574"
"435.15000","36.26265","0.07635"
"435.60000","36.30026","0.07833"
"436.05000","36.33775","0.07930"
"436.50000","36.37529","0.08086"
"436.95000","36.41272","0.08265"
"437.40000","36.45015","0.08176"
"437.85000","36.48764","0.08398"
"438.30000","36.52525","0.08564"
"438.75000","36.56273","0.08659"
"439.20000","36.60022","0.08813"
"439.65000","36.63771","0.08919"
"440.10000","36.67514","0.09055"
"440.55000","36.71269","0.09184"
"441.00000","36.75018","0.09329"
"441.45000","36.78766","0.09484"
"441.90000","36.82521","0.01224"
"442.35000","36.86264","0.00608"
"442.80000","36.90012","0.00067"
"443.25000","36.93768","0.00144"
"443.70000","36.97522","0.00094"
"444.15000","37.01271","0.00051"
"444.60000","37.05020","0.00205"
"445.05000","37.08775","0.00051"
"445.50000","37.12518","0.00196"
"445.95000","37.16266","0.00052"
"446.40000","37.20021","0.00072"
"446.85000","37.23770","0.00091"
"447.30000","37.27519","0.00076"
"447.75000","37.31268","0.00140"
"448.20000","37.35010","0.00031"
"448.65000","37.38771","0.00141"
"449.10000","37.42520","0.00051"
"449.55000","37.46275","0.00106"
"450.00000","37.50024","0.00085"
"450.45000","37.53772","0.00117"
"450.90000","37.57515","0.00093"
"451.35000","37.61264","0.00113"
"451.80000","37.65025","0.00130"
"452.25000","37.68768","0.00208"
"452.70000","37.72522","0.00130"
"453.15000","37.76271","0.00141"
"453.60000","37.80020","0.00154"
"454.05000","37.83769","0.00146"
"454.50000","37.87511","0.00162"
"454.95000","37.91272","0.00128"
"455.40000","37.95027","0.00132"
"455.85000","37.98776","0.00195"
"456.30000","38.02518","0.00131"
"456.75000","38.06267","0.00221"
"457.20000","38.10022","0.00167"
"457.65000","38.13771","0.00182"
"458.10000","38.17520","0.00195"
"458.55000","38.21281","0.00220"
"459.00000","38.25023","0.00199"
"459.45000","38.28766","0.00206"
"459.90000","38.32515","0.00195"
"460.35000","38.36270","0.00234"
"460.80000","38.40019","0.00283"
"461.25000","38.43774","0.00229"
"461.70000","38.47522","0.00253"
"462.15000","38.51265","0.00250"
"462.60000","38.55014","0.00291"
"463.05000","38.58768","0.00283"
"463.50000","38.62517","0.00252"
"463.95000","38.66272","0.00250"
"464.40000","38.70015","0.00232"
"464.85000","38.73764","0.00254"
"465.30000","38.77519","0.00274"
"465.75000","38.81273","0.00294"
"466.20000","38.85022","0.00284"
"466.65000","38.88771","0.00291"
"467.10000","38.92520","0.00328"
"467.55000","38.96263","0.00296"
"468.00000","39.00018","0.00328"
"468.45000","39.03772","0.00300"
"468.90000","39.07521","0.00303"
"469.35000","39.11276","0.00311"
"469.80000","39.15018","0.00286"
"470.25000","39.18767","0.00319"
"470.70000","39.22516","0.00298"
"471.15000","39.26271","0.00275"
"471.60000","39.30025","0.00300"
"472.05000","39.33775","0.00305"
"472.50000","39.37517","0.00343"
"472.95000","39.41266","0.00324"
"473.40000","39.45015","0.00312"
"473.85000","39.48770","0.00300"
"474.30000","39.52525","0.00320"
"474.75000","39.56268","0.00368"
"475.20000","39.60022","0.00297"
"475.65000","39.63771","0.00304"
"476.10000","39.67520","0.00328"
"476.55000","39.71268","0.00350"
"477.00000","39.75023","0.00335"
"477.45000","39.78766","0.00312"
"477.90000","39.82521","0.00312"
"478.35000","39.86270","0.00368"
"478.80000","39.90019","0.00302"
"479.25000","39.93774","0.00351"
"479.70000","39.97522","0.00319"
"480.15000","40.01265","0.00338"
"480.60000","40.05013","0.00307"
"481.05000","40.08762","0.00289"
"481.50000","40.12518","0.00380"
"481.95000","40.16266","0.00299"
"482.40000","40.20027","0.00310"
"482.85000","40.23770","0.00308"
"483.30000","40.27525","0.00357"
"483.75000","40.31268","0.00373"
"484.20000","40.35016","0.00369"
"484.65000","40.38765","0.00395"
"485.10000","40.42525","0.00301"
"485.55000","40.46269","0.00289"
"486.00000","40.50024","0.00352"
"486.45000","40.53766","0.00403"
"486.90000","40.57515","0.00327"
"487.35000","40.61270","0.00328"
"487.80000","40.65024","0.00320"
"488.25000","40.68774","0.00358"
"488.70000","40.72528","0.00305"
"489.15000","40.76271","0.00330"
"489.60000","40.80014","0.00343"
"490.05000","40.83768","0.00340"
"490.50000","40.87518","0.00312"
"490.95000","40.91266","0.00355"
"491.40000","40.95021","0.00313"
"491.85000","40.98770","0.00314"
"492.30000","41.02519","0.00262"
"492.75000","41.06268","0.00284"
"493.20000","41.10022","0.00327"
"493.65000","41.13771","0.00295"
"494.10000","41.17526","0.00292"
"494.55000","41.21268","0.00256"
"495.00000","41.25017","0.00257"
"495.45000","41.28766","0.00257"
"495.90000","41.32527","0.00263"
"496.35000","41.36270","0.00295"
"496.80000","41.40025","0.00298"
"497.25000","41.43773","0.00269"
"497.70000","41.47510","0.00343"
"498.15000","41.51271","0.00338"
"498.60000","41.55020","0.00248"
"499.05000","41.58775","0.00265"
"499.50000","41.62524","0.00312"
"499.95000","41.66272","0.00227"
"500.40000","41.70009","0.00259"
"500.85000","41.73770","0.00323"
"501.30000","41.77518","0.00324"
"501.75000","41.81273","0.00356"
"502.20000","41.85028","0.00330"
"502.65000","41.88771","0.00339"
"503.10000","41.92520","0.00356"
"503.55000","41.96268","0.00364"
"504.00000","42.00018","0.00323"
"504.45000","42.03778","0.00307"
"504.90000","42.07521","0.00337"
"505.35000","42.11270","0.00271"
"505.80000","42.15019","0.00277"
"506.25000","42.18761","0.00337"
"506.70000","42.22522","0.00252"
"507.15000","42.26271","0.00305"
"507.60000","42.30019","0.00351"
"508.05000","42.33774","0.00367"
"508.50000","42.37517","0.00342"
"508.95000","42.41266","0.00311"
"509.40000","42.45021","0.00357"
"509.85000","42.48770","0.00317"
"510.30000","42.52519","0.00272"
"510.75000","42.56273","0.00296"
"511.20000","42.60022","0.00263"
"511.65000","42.63765","0.00292"
"512.10000","42.67520","0.00286"
"512.55000","42.71269","0.00262"
"513.00000","42.75017","0.00295"
"513.45000","42.78772","0.00246"
"513.90000","42.82515","0.00247"
"514.35000","42.86270","0.00291"
"514.80000","42.90018","0.00295"
"515.25000","42.93773","0.00298"
"515.70000","42.97528","0.00311"
"516.15000","43.01271","0.00276"
"516.60000","43.05020","0.00232"
"517.05000","43.08757","0.00214"
"517.50000","43.12523","0.00251"
"517.95000","43.16266","0.00281"
"518.40000","43.20021","0.00227"
"518.85000","43.23775","0.00256"
"519.30000","43.27518","0.00230"
"519.75000","43.31268","0.00249"
"520.20000","43.35016","0.00260"
"520.65000","43.38771","0.00234"
"521.10000","43.42519","0.00256"
"521.55000","43.46274","0.00248"
"522.00000","43.50018","0.00285"
"522.45000","43.53766","0.00279"
"522.90000","43.57515","0.00282"
"523.35000","43.61264","0.00271"
"523.80000","43.65025","0.00302"
"524.25000","43.68773","0.00262"
"524.70000","43.72522","0.00299"
"525.15000","43.76271","0.00287"
"525.60000","43.80020","0.00260"
"526.05000","43.83768","0.00239"
"526.50000","43.87517","0.00290"
"526.95000","43.91266","0.00251"
"527.40000","43.95021","0.00319"
"527.85000","43.98770","0.00325"
"528.30000","44.02518","0.00356"
"528.75000","44.06273","0.00319"
"529.20000","44.10022","0.00366"
"529.65000","44.13777","0.00314"
"530.10000","44.17526","0.00366"
"530.55000","44.21262","0.00386"
"531.00000","44.25018","0.00380"
"531.45000","44.28772","0.00436"
"531.90000","44.32521","0.00377"
"532.35000","44.36275","0.00374"
"532.80000","44.40018","0.00438"
"533.25000","44.43768","0.00450"
"533.70000","44.47516","0.00463"
"534.15000","44.51271","0.00484"
"534.60000","44.55019","0.00440"
"535.05000","44.58774","0.00536"
"535.50000","44.62523","0.00480"
"535.95000","44.66266","0.00551"
"536.40000","44.70015","0.00562"
"536.85000","44.73764","0.00551"
"537.30000","44.77519","0.00594"
"537.75000","44.81273","0.00564"
"538.20000","44.85028","0.00608"
"538.65000","44.88771","0.00574"
"539.10000","44.92514","0.00632"
"539.55000","44.96268","0.00639"
"540.00000","45.00023","0.00627"
"540.45000","45.03772","0.00710"
"540.90000","45.07521","0.00728"
"541.35000","45.11270","0.00717"
"541.80000","45.15019","0.00700"
"542.25000","45.18768","0.00766"
"542.70000","45.22522","0.00770"
"543.15000","45.26271","0.00762"
"543.60000","45.30026","0.00750"
"544.05000","45.33768","0.00755"
"544.50000","45.37518","0.00829"
"544.95000","45.41266","0.00815"
"545.40000","45.45021","0.00838"
"545.85000","45.48770","0.00892"
"546.30000","45.52525","0.00911"
"546.75000","45.56273","0.00949"
"547.20000","45.60017","0.00976"
"547.65000","45.63765","0.00912"
"548.10000","45.67520","0.00986"
"548.55000","45.71274","0.01057"
"549.00000","45.75023","0.01084"
"549.45000","45.78766","0.01003"
"549.90000","45.82515","0.01102"
"550.35000","45.86270","0.01172"
"550.80000","45.90019","0.01167"
"551.25000","45.93773","0.01101"
"551.70000","45.97528","0.01177"
"552.15000","46.01271","0.01268"
"552.60000","46.05020","0.01304"
"553.05000","46.08775","0.01297"
"553.50000","46.12511","0.01283"
"553.95000","46.16272","0.01374"
"554.40000","46.20021","0.01402"
"554.85000","46.23770","0.01301"
"555.30000","46.27519","0.01398"
"555.75000","46.31268","0.01457"
"556.20000","46.35016","0.01460"
"556.65000","46.38771","0.01322"
"557.10000","46.42520","0.01411"
"557.55000","46.46275","0.01464"
"558.00000","46.50018","0.01420"
"558.45000","46.53766","0.01446"
"558.90000","46.57521","0.01413"
"559.35000","46.61270","0.01558"
"559.80000","46.65018","0.01475"
"560.25000","46.68773","0.01595"
"560.70000","46.72516","0.01566"
"561.15000","46.76265","0.01620"
"561.60000","46.80020","0.01689"
"562.05000","46.83769","0.01660"
"562.50000","46.87518","0.01689"
"562.95000","46.91272","0.01675"
"563.40000","46.95015","0.01838"
"563.85000","46.98764","0.01888"
"564.30000","47.02518","0.01885"
"564.75000","47.06273","0.01952"
"565.20000","47.10022","0.01937"
"565.65000","47.13777","0.01841"
"566.10000","47.17519","0.01895"
"566.55000","47.21262","0.01832"
"567.00000","47.25017","0.01902"
"567.45000","47.28772","0.02071"
"567.90000","47.32521","0.02018"
"568.35000","47.36276","0.02031"
"568.80000","47.40024","0.02051"
"569.25000","47.43761","0.02117"
"569.70000","47.47516","0.02104"
"570.15000","47.51265","0.02118"
"570.60000","47.55020","0.02166"
"571.05000","47.58768","0.02198"
"571.50000","47.62523","0.02223"
"571.95000","47.66266","0.02249"
"572.40000","47.70015","0.02288"
"572.85000","47.73769","0.02335"
"573.30000","47.77525","0.02383"
"573.75000","47.81273","0.02323"
"574.20000","47.85022","0.02383"
"574.65000","47.88771","0.02473"
"575.10000","47.92514","0.02436"
"575.55000","47.96268","0.02442"
"576.00000","48.00024","0.02324"
"576.45000","48.03766","0.02351"
"576.90000","48.07521","0.02448"
"577.35000","48.11258","0.02402"
"577.80000","48.15024","0.02389"
"578.25000","48.18773","0.02379"
"578.70000","48.22528","0.02427"
"579.15000","48.26271","0.02353"
"579.60000","48.30019","0.02268"
"580.05000","48.33762","0.02344"
"580.50000","48.37511","0.02328"
"580.95000","48.41272","0.02071"
"581.40000","48.45021","0.01056"
"581.85000","48.48770","0.00301"
"582.30000","48.52518","0.00490"
"582.75000","48.56268","0.00532"
"583.20000","48.60016","0.00399"
"583.65000","48.63765","0.00515"
"584.10000","48.67526","0.00554"
"584.55000","48.71275","0.00484"
"585.00000","48.75023","0.00504"
"585.45000","48.78767","0.00511"
"585.90000","48.82515","0.00532"
"586.35000","48.86269","0.00394"
"586.80000","48.90019","0.00190"
"587.25000","48.93773","0.00362"
"587.70000","48.97528","0.00279"
"588.15000","49.01271","0.00324"
"588.60000","49.05013","0.00280"
"589.05000","49.08768","0.00278"
"589.50000","49.12518","0.00318"
"589.95000","49.16272","0.00298"
"590.40000","49.20021","0.00294"
"590.85000","49.23770","0.00356"
"591.30000","49.27518","0.00371"
"591.75000","49.31267","0.00337"
"592.20000","49.35022","0.00362"
"592.65000","49.38765","0.00371"
"593.10000","49.42520","0.00365"
"593.55000","49.46269","0.00403"
"594.00000","49.50017","0.00337"
"594.45000","49.53766","0.00371"
"594.90000","49.57527","0.00370"
"595.35000","49.61269","0.00399"
"595.80000","49.65025","0.00337"
"596.25000","49.68774","0.00338"
"596.70000","49.72510","0.00389"
"597.15000","49.76271","0.00401"
"597.60000","49.80026","0.00391"
"598.05000","49.83768","0.00323"
"598.50000","49.87523","0.00238"
"598.95000","49.91272","0.00230"
"599.40000","49.95015","0.00299"
"599.85000","49.98764","0.00251"
"600.30000","50.02519","0.00258"
"600.75000","50.06279","0.00302"
"601.20000","50.10022","0.00247"
"601.65000","50.13771","0.00257"
"602.10000","50.17513","0.00260"
"602.55000","50.21262","0.00275"
"603.00000","50.25018","0.00196"
"603.45000","50.28772","0.00192"
"603.90000","50.32521","0.00166"
"604.35000","50.36276","0.00184"
"604.80000","50.40024","0.00164"
"605.25000","50.43768","0.00209"
"605.70000","50.47516","0.00166"
"606.15000","50.51271","0.00167"
"606.60000","50.55020","0.00200"
"607.05000","50.58775","0.00157"
"607.50000","50.62517","0.00176"
"607.95000","50.66266","0.00196"
"608.40000","50.70021","0.00187"
"608.85000","50.73775","0.00165"
"609.30000","50.77525","0.00186"
"609.75000","50.81268","0.00161"
"610.20000","50.85016","0.00139"
"610.65000","50.88765","0.00175"
"611.10000","50.92520","0.00229"
"611.55000","50.96275","0.00164"
"612.00000","51.00018","0.00214"
"612.45000","51.03772","0.00181"
"612.90000","51.07515","0.00202"
"613.35000","51.11264","0.00233"
"613.80000","51.15019","0.00227"
"614.25000","51.18773","0.00271"
"614.70000","51.22516","0.00226"
"615.15000","51.26271","0.00217"
"615.60000","51.30019","0.00179"
"616.05000","51.33763","0.00187"
"616.50000","51.37518","0.00189"
"616.95000","51.41272","0.00189"
"617.40000","51.45021","0.00151"
"617.85000","51.48776","0.00200"
"618.30000","51.52518","0.00186"
"618.75000","51.56268","0.00213"
"619.20000","51.60016","0.00164"
"619.65000","51.63771","0.00181"
"620.10000","51.67520","0.00186"
"620.55000","51.71269","0.00206"
"621.00000","51.75017","0.00162"
"621.45000","51.78766","0.00259"
"621.90000","51.82521","0.00245"
"622.35000","51.86269","0.00190"
"622.80000","51.90024","0.00172"
"623.25000","51.93767","0.00199"
"623.70000","51.97522","0.00201"
"624.15000","52.01271","0.00263"
"624.60000","52.05020","0.00188"
"625.05000","52.08775","0.00190"
"625.50000","52.12518","0.00185"
"625.95000","52.16272","0.00182"
"626.40000","52.20021","0.00178"
"626.85000","52.23764","0.00238"
"627.30000","52.27519","0.00199"
"627.75000","52.31273","0.00234"
"628.20000","52.35022","0.00205"
"628.65000","52.38771","0.00232"
"629.10000","52.42519","0.00288"
"629.55000","52.46263","0.00249"
"630.00000","52.50017","0.00206"
"630.45000","52.53772","0.00262"
"630.90000","52.57521","0.00200"
"631.35000","52.61276","0.00313"
"631.80000","52.65018","0.00269"
"632.25000","52.68768","0.00242"
"632.70000","52.72516","0.00319"
"633.15000","52.76271","0.00326"
"633.60000","52.80026","0.00305"
"634.05000","52.83775","0.00262"
"634.50000","52.87524","0.00279"
"634.95000","52.91266","0.00341"
"635.40000","52.95015","0.00302"
"635.85000","52.98769","0.00308"
"636.30000","53.02518","0.00317"
"636.75000","53.06273","0.00302"
"637.20000","53.10022","0.00317"
"637.65000","53.13771","0.00326"
"638.10000","53.17520","0.00339"
"638.55000","53.21268","0.00341"
"639.00000","53.25023","0.00394"
"639.45000","53.28772","0.00374"
"639.90000","53.32521","0.00367"
"640.35000","53.36270","0.00339"
"640.80000","53.40019","0.00324"
"641.25000","53.43773","0.00337"
"641.70000","53.47516","0.00337"
"642.15000","53.51271","0.00391"
"642.60000","53.55026","0.00304"
"643.05000","53.58768","0.00335"
"643.50000","53.62518","0.00323"
"643.95000","53.66266","0.00364"
"644.40000","53.70027","0.00321"
"644.85000","53.73776","0.00317"
"645.30000","53.77518","0.00369"
"645.75000","53.81268","0.00346"
"646.20000","53.85010","0.00321"
"646.65000","53.88765","0.00343"
"647.10000","53.92520","0.00311"
"647.55000","53.96268","0.00335"
"648.00000","54.00024","0.00319"
"648.45000","54.03772","0.00372"
"648.90000","54.07515","0.00369"
"649.35000","54.11264","0.00350"
"649.80000","54.15024","0.00408"
"650.25000","54.18773","0.00383"
"650.70000","54.22522","0.00395"
"651.15000","54.26265","0.00412"
"651.60000","54.30014","0.00410"
"652.05000","54.33768","0.00420"
"652.50000","54.37518","0.00396"
"652.95000","54.41272","0.00438"
"653.40000","54.45021","0.00380"
"653.85000","54.48770","0.00388"
"654.30000","54.52518","0.00386"
"654.75000","54.56267","0.00447"
"655.20000","54.60028","0.00460"
"655.65000","54.63771","0.00449"
"656.10000","54.67519","0.00415"
"656.55000","54.71269","0.00407"
"657.00000","54.75018","0.00436"
"657.45000","54.78772","0.00389"
"657.90000","54.82527","0.00433"
"658.35000","54.86270","0.00385"
"658.80000","54.90025","0.00358"
"659.25000","54.93773","0.00417"
"659.70000","54.97510","0.00419"
"660.15000","55.01271","0.00402"
"660.60000","55.05025","0.00394"
"661.05000","55.08775","0.00374"
"661.50000","55.12524","0.00425"
"661.95000","55.16267","0.00487"
"662.40000","55.20015","0.00481"
"662.85000","55.23764","0.00477"
"663.30000","55.27519","0.00439"
"663.75000","55.31273","0.00493"
"664.20000","55.35022","0.00436"
"664.65000","55.38771","0.00491"
"665.10000","55.42520","0.00533"
"665.55000","55.46262","0.00520"
"666.00000","55.50011","0.00480"
"666.45000","55.53772","0.00491"
"666.90000","55.57521","0.00486"
"667.35000","55.61275","0.00522"
"667.80000","55.65018","0.00488"
"668.25000","55.68767","0.00467"
"668.70000","55.72517","0.00472"
"669.15000","55.76271","0.00312"
"669.52800","55.79428","0.00336"