File: Force_trajectories/170121_1/Specimen_RawData_8.csv
End date,"1/21/2017"
Specimen label,"19CG_NoLabel2"
Maximum Load,"0.01001",N

Time,Extension,Load
(s),(mm),(N)
"0.00000","0.00000","-0.00028"
"0.28800","0.02326","0.00012"
"0.57600","0.04825","-0.00026"
"0.86400","0.07217","0.00021"
"1.15200","0.09626","0.00047"
"1.44000","0.12024","0.00059"
"1.72800","0.14421","0.00047"
"2.01600","0.16819","0.00077"
"2.30400","0.19216","0.00042"
"2.59200","0.21614","0.00035"
"2.88000","0.24017","0.00047"
"3.16800","0.26421","0.00087"
"3.45600","0.28813","0.00092"
"3.74400","0.31222","0.00081"
"4.03200","0.33614","0.00136"
"4.32000","0.36017","0.00092"
"4.60800","0.38409","0.00075"
"4.89600","0.40818","0.00083"
"5.18400","0.43210","0.00092"
"5.47200","0.45619","0.00094"
"5.76000","0.48017","0.00073"
"6.04800","0.50415","0.00140"
"6.33600","0.52812","0.00155"
"6.62400","0.55216","0.00123"
"6.91200","0.57619","0.00082"
"7.20000","0.60011","0.00114"
"7.48800","0.62414","0.00113"
"7.77600","0.64818","0.00120"
"8.06400","0.67215","0.00117"
"8.35200","0.69613","0.00099"
"8.64000","0.72016","0.00079"
"8.92800","0.74414","0.00096"
"9.21600","0.76818","0.00132"
"9.50400","0.79215","0.00101"
"9.79200","0.81619","0.00044"
"10.08000","0.84010","0.00076"
"10.36800","0.86414","0.00056"
"10.65600","0.88817","0.00039"
"10.94400","0.91215","0.00065"
"11.23200","0.93618","0.00037"
"11.52000","0.96016","0.00074"
"11.80800","0.98420","0.00070"
"12.09600","1.00817","0.00097"
"12.38400","1.03221","0.00058"
"12.67200","1.05612","0.00054"
"12.96000","1.08016","0.00049"
"13.24800","1.10407","0.00099"
"13.53600","1.12817","0.00083"
"13.82400","1.15208","0.00069"
"14.11200","1.17618","0.00049"
"14.40000","1.20016","0.00097"
"14.68800","1.22413","0.00083"
"14.97600","1.24811","0.00073"
"15.26400","1.27214","0.00091"
"15.55200","1.29618","0.00074"
"15.84000","1.32021","0.00078"
"16.12800","1.34419","0.00069"
"16.41600","1.36816","0.00116"
"16.70400","1.39214","0.00088"
"16.99200","1.41612","0.00103"
"17.28000","1.44021","0.00106"
"17.56800","1.46413","0.00116"
"17.85600","1.48816","0.00090"
"18.14400","1.51214","0.00098"
"18.43200","1.53617","0.00117"
"18.72000","1.56015","0.00113"
"19.00800","1.58412","0.00137"
"19.29600","1.60816","0.00128"
"19.58400","1.63213","0.00124"
"19.87200","1.65617","0.00139"
"20.16000","1.68009","0.00119"
"20.44800","1.70418","0.00091"
"20.73600","1.72810","0.00123"
"21.02400","1.75219","0.00129"
"21.31200","1.77611","0.00168"
"21.60000","1.80014","0.00124"
"21.88800","1.82412","0.00094"
"22.17600","1.84815","0.00163"
"22.46400","1.87213","0.00115"
"22.75200","1.89617","0.00162"
"23.04000","1.92014","0.00169"
"23.32800","1.94418","0.00132"
"23.61600","1.96815","0.00160"
"23.90400","1.99213","0.00096"
"24.19200","2.01616","0.00132"
"24.48000","2.04014","0.00106"
"24.76800","2.06417","0.00132"
"25.05600","2.08815","0.00156"
"25.34400","2.11219","0.00126"
"25.63200","2.13610","0.00151"
"25.92000","2.16020","0.00184"
"26.20800","2.18411","0.00119"
"26.49600","2.20815","0.00145"
"26.78400","2.23218","0.00131"
"27.07200","2.25622","0.00174"
"27.36000","2.28019","0.00174"
"27.64800","2.30417","0.00195"
"27.93600","2.32814","0.00159"
"28.22400","2.35212","0.00161"
"28.51200","2.37616","0.00173"
"28.80000","2.40013","0.00147"
"29.08800","2.42423","0.00146"
"29.37600","2.44814","0.00198"
"29.66400","2.47224","0.00193"
"29.95200","2.49615","0.00154"
"30.24000","2.52025","0.00166"
"30.52800","2.54416","0.00196"
"30.81600","2.56820","0.00141"
"31.10400","2.59218","0.00152"
"31.39200","2.61621","0.00207"
"31.68000","2.64019","0.00183"
"31.96800","2.66416","0.00179"
"32.25600","2.68820","0.00143"
"32.54400","2.71211","0.00146"
"32.83200","2.73621","0.00144"
"33.12000","2.76018","0.00127"
"33.40800","2.78422","0.00131"
"33.69600","2.80819","0.00108"
"33.98400","2.83223","0.00103"
"34.27200","2.85621","0.00105"
"34.56000","2.88024","0.00163"
"34.84800","2.90422","0.00163"
"35.13600","2.92819","0.00147"
"35.42400","2.95217","0.00116"
"35.71200","2.97620","0.00106"
"36.00000","3.00024","0.00150"
"36.28800","3.02415","0.00140"
"36.57600","3.04819","0.00149"
"36.86400","3.07217","0.00133"
"37.15200","3.09620","0.00140"
"37.44000","3.12012","0.00167"
"37.72800","3.14421","0.00150"
"38.01600","3.16819","0.00146"
"38.30400","3.19222","0.00178"
"38.59200","3.21614","0.00133"
"38.88000","3.24017","0.00176"
"39.16800","3.26415","0.00146"
"39.45600","3.28824","0.00130"
"39.74400","3.31222","0.00164"
"40.03200","3.33620","0.00174"
"40.32000","3.36017","0.00148"
"40.60800","3.38409","0.00156"
"40.89600","3.40812","0.00168"
"41.18400","3.43216","0.00186"
"41.47200","3.45619","0.00160"
"41.76000","3.48017","0.00164"
"42.04800","3.50426","0.00154"
"42.33600","3.52818","0.00193"
"42.62400","3.55222","0.00150"
"42.91200","3.57619","0.00165"
"43.20000","3.60017","0.00203"
"43.48800","3.62414","0.00178"
"43.77600","3.64818","0.00163"
"44.06400","3.67215","0.00148"
"44.35200","3.69613","0.00146"
"44.64000","3.72022","0.00181"
"44.92800","3.74414","0.00170"
"45.21600","3.76818","0.00173"
"45.50400","3.79209","0.00208"
"45.79200","3.81619","0.00178"
"46.08000","3.84010","0.00188"
"46.36800","3.86420","0.00194"
"46.65600","3.88817","0.00214"
"46.94400","3.91215","0.00187"
"47.23200","3.93618","0.00163"
"47.52000","3.96022","0.00192"
"47.80800","3.98420","0.00206"
"48.09600","4.00817","0.00190"
"48.38400","4.03221","0.00187"
"48.67200","4.05618","0.00168"
"48.96000","4.08022","0.00235"
"49.24800","4.10413","0.00189"
"49.53600","4.12817","0.00210"
"49.82400","4.15208","0.00191"
"50.11200","4.17618","0.00188"
"50.40000","4.20015","0.00173"
"50.68800","4.22419","0.00174"
"50.97600","4.24817","0.00203"
"51.26400","4.27220","0.00201"
"51.55200","4.29618","0.00193"
"51.84000","4.32015","0.00250"
"52.12800","4.34425","0.00218"
"52.41600","4.36822","0.00207"
"52.70400","4.39226","0.00211"
"52.99200","4.41611","0.00212"
"53.28000","4.44021","0.00194"
"53.56800","4.46413","0.00175"
"53.85600","4.48816","0.00234"
"54.14400","4.51214","0.00231"
"54.43200","4.53617","0.00228"
"54.72000","4.56015","0.00229"
"55.00800","4.58418","0.00263"
"55.29600","4.60816","0.00246"
"55.58400","4.63219","0.00209"
"55.87200","4.65623","0.00238"
"56.16000","4.68015","0.00272"
"56.44800","4.70418","0.00245"
"56.73600","4.72816","0.00266"
"57.02400","4.75219","0.00268"
"57.31200","4.77617","0.00242"
"57.60000","4.80020","0.00270"
"57.88800","4.82412","0.00264"
"58.17600","4.84815","0.00252"
"58.46400","4.87207","0.00240"
"58.75200","4.89616","0.00287"
"59.04000","4.92014","0.00250"
"59.32800","4.94418","0.00268"
"59.61600","4.96815","0.00240"
"59.90400","4.99219","0.00263"
"60.19200","5.01616","0.00264"
"60.48000","5.04014","0.00233"
"60.76800","5.06417","0.00252"
"61.05600","5.08815","0.00228"
"61.34400","5.11218","0.00278"
"61.63200","5.13616","0.00241"
"61.92000","5.16014","0.00259"
"62.20800","5.18411","0.00301"
"62.49600","5.20815","0.00278"
"62.78400","5.23212","0.00258"
"63.07200","5.25616","0.00280"
"63.36000","5.28019","0.00245"
"63.64800","5.30417","0.00319"
"63.93600","5.32820","0.00269"
"64.22400","5.35212","0.00290"
"64.51200","5.37621","0.00245"
"64.80000","5.40019","0.00249"
"65.08800","5.42423","0.00290"
"65.37600","5.44814","0.00266"
"65.66400","5.47218","0.00261"
"65.95200","5.49615","0.00308"
"66.24000","5.52025","0.00293"
"66.52800","5.54410","0.00252"
"66.81600","5.56820","0.00261"
"67.10400","5.59218","0.00270"
"67.39200","5.61621","0.00285"
"67.68000","5.64019","0.00280"
"67.96800","5.66422","0.00281"
"68.25600","5.68820","0.00281"
"68.54400","5.71217","0.00288"
"68.83200","5.73621","0.00310"
"69.12000","5.76018","0.00282"
"69.40800","5.78422","0.00285"
"69.69600","5.80819","0.00265"
"69.98400","5.83223","0.00307"
"70.27200","5.85621","0.00299"
"70.56000","5.88018","0.00298"
"70.84800","5.90416","0.00269"
"71.13600","5.92813","0.00316"
"71.42400","5.95217","0.00304"
"71.71200","5.97620","0.00269"
"72.00000","6.00024","0.00272"
"72.28800","6.02421","0.00291"
"72.57600","6.04819","0.00296"
"72.86400","6.07217","0.00252"
"73.15200","6.09620","0.00283"
"73.44000","6.12018","0.00261"
"73.72800","6.14421","0.00287"
"74.01600","6.16813","0.00297"
"74.30400","6.19222","0.00286"
"74.59200","6.21620","0.00271"
"74.88000","6.24023","0.00276"
"75.16800","6.26415","0.00322"
"75.45600","6.28824","0.00256"
"75.74400","6.31222","0.00251"
"76.03200","6.33620","0.00300"
"76.32000","6.36017","0.00336"
"76.60800","6.38415","0.00272"
"76.89600","6.40818","0.00303"
"77.18400","6.43216","0.00296"
"77.47200","6.45619","0.00318"
"77.76000","6.48017","0.00300"
"78.04800","6.50420","0.00297"
"78.33600","6.52818","0.00288"
"78.62400","6.55222","0.00300"
"78.91200","6.57619","0.00324"
"79.20000","6.60017","0.00278"
"79.48800","6.62420","0.00302"
"79.77600","6.64818","0.00296"
"80.06400","6.67215","0.00256"
"80.35200","6.69619","0.00280"
"80.64000","6.72022","0.00293"
"80.92800","6.74420","0.00326"
"81.21600","6.76824","0.00289"
"81.50400","6.79215","0.00274"
"81.79200","6.81619","0.00330"
"82.08000","6.84016","0.00298"
"82.36800","6.86420","0.00317"
"82.65600","6.88811","0.00286"
"82.94400","6.91221","0.00344"
"83.23200","6.93618","0.00290"
"83.52000","6.96022","0.00295"
"83.80800","6.98413","0.00261"
"84.09600","7.00817","0.00393"
"84.38400","7.03215","0.00327"
"84.67200","7.05618","0.00313"
"84.96000","7.08022","0.00325"
"85.24800","7.10413","0.00329"
"85.53600","7.12817","0.00328"
"85.82400","7.15214","0.00319"
"86.11200","7.17618","0.00360"
"86.40000","7.20015","0.00327"
"86.68800","7.22419","0.00319"
"86.97600","7.24817","0.00350"
"87.26400","7.27220","0.00272"
"87.55200","7.29618","0.00351"
"87.84000","7.32021","0.00325"
"88.12800","7.34419","0.00336"
"88.41600","7.36816","0.00330"
"88.70400","7.39220","0.00318"
"88.99200","7.41617","0.00375"
"89.28000","7.44021","0.00320"
"89.56800","7.46413","0.00298"
"89.85600","7.48816","0.00381"
"90.14400","7.51208","0.00367"
"90.43200","7.53617","0.00309"
"90.72000","7.56009","0.00308"
"91.00800","7.58418","0.00320"
"91.29600","7.60810","0.00339"
"91.58400","7.63219","0.00335"
"91.87200","7.65611","0.00339"
"92.16000","7.68015","0.00339"
"92.44800","7.70412","0.00344"
"92.73600","7.72816","0.00341"
"93.02400","7.75219","0.00382"
"93.31200","7.77617","0.00368"
"93.60000","7.80020","0.00345"
"93.88800","7.82418","0.00350"
"94.17600","7.84815","0.00336"
"94.46400","7.87207","0.00365"
"94.75200","7.89616","0.00338"
"95.04000","7.92014","0.00355"
"95.32800","7.94418","0.00334"
"95.61600","7.96821","0.00307"
"95.90400","7.99219","0.00321"
"96.19200","8.01616","0.00318"
"96.48000","8.04014","0.00331"
"96.76800","8.06417","0.00378"
"97.05600","8.08815","0.00325"
"97.34400","8.11218","0.00353"
"97.63200","8.13616","0.00346"
"97.92000","8.16020","0.00338"
"98.20800","8.18411","0.00314"
"98.49600","8.20815","0.00318"
"98.78400","8.23206","0.00278"
"99.07200","8.25616","0.00322"
"99.36000","8.28013","0.00279"
"99.64800","8.30417","0.00255"
"99.93600","8.32814","0.00280"
"100.22400","8.35218","0.00299"
"100.51200","8.37615","0.00296"
"100.80000","8.40013","0.00293"
"101.08800","8.42417","0.00262"
"101.37600","8.44814","0.00258"
"101.66400","8.47218","0.00312"
"101.95200","8.49615","0.00270"
"102.24000","8.52013","0.00291"
"102.52800","8.54416","0.00258"
"102.81600","8.56814","0.00274"
"103.10400","8.59211","0.00263"
"103.39200","8.61621","0.00252"
"103.68000","8.64013","0.00309"
"103.96800","8.66416","0.00279"
"104.25600","8.68814","0.00272"
"104.54400","8.71217","0.00285"
"104.83200","8.73615","0.00283"
"105.12000","8.76012","0.00317"
"105.40800","8.78422","0.00296"
"105.69600","8.80813","0.00316"
"105.98400","8.83217","0.00321"
"106.27200","8.85608","0.00269"
"106.56000","8.88018","0.00305"
"106.84800","8.90410","0.00310"
"107.13600","8.92813","0.00318"
"107.42400","8.95205","0.00326"
"107.71200","8.97620","0.00308"
"108.00000","9.00018","0.00296"
"108.28800","9.02421","0.00326"
"108.57600","9.04819","0.00293"
"108.86400","9.07216","0.00328"
"109.15200","9.09614","0.00320"
"109.44000","9.12012","0.00316"
"109.72800","9.14421","0.00336"
"110.01600","9.16819","0.00303"
"110.30400","9.19222","0.00298"
"110.59200","9.21614","0.00352"
"110.88000","9.24023","0.00316"
"111.16800","9.26415","0.00319"
"111.45600","9.28818","0.00326"
"111.74400","9.31216","0.00339"
"112.03200","9.33619","0.00346"
"112.32000","9.36017","0.00361"
"112.60800","9.38415","0.00337"
"112.89600","9.40818","0.00331"
"113.18400","9.43222","0.00338"
"113.47200","9.45625","0.00346"
"113.76000","9.48017","0.00308"
"114.04800","9.50420","0.00339"
"114.33600","9.52818","0.00352"
"114.62400","9.55222","0.00363"
"114.91200","9.57619","0.00348"
"115.20000","9.60017","0.00331"
"115.48800","9.62414","0.00391"
"115.77600","9.64824","0.00350"
"116.06400","9.67215","0.00370"
"116.35200","9.69619","0.00372"
"116.64000","9.72016","0.00357"
"116.92800","9.74420","0.00355"
"117.21600","9.76823","0.00377"
"117.50400","9.79221","0.00335"
"117.79200","9.81619","0.00385"
"118.08000","9.84016","0.00376"
"118.36800","9.86420","0.00327"
"118.65600","9.88817","0.00363"
"118.94400","9.91221","0.00376"
"119.23200","9.93618","0.00432"
"119.52000","9.96022","0.00372"
"119.80800","9.98419","0.00377"
"120.09600","10.00817","0.00397"
"120.38400","10.03215","0.00430"
"120.67200","10.05618","0.00424"
"120.96000","10.08022","0.00420"
"121.24800","10.10419","0.00424"
"121.53600","10.12817","0.00417"
"121.82400","10.15214","0.00434"
"122.11200","10.17624","0.00419"
"122.40000","10.20015","0.00433"
"122.68800","10.22419","0.00452"
"122.97600","10.24817","0.00394"
"123.26400","10.27220","0.00431"
"123.55200","10.29612","0.00426"
"123.84000","10.32021","0.00384"
"124.12800","10.34419","0.00404"
"124.41600","10.36816","0.00392"
"124.70400","10.39214","0.00372"
"124.99200","10.41617","0.00369"
"125.28000","10.44021","0.00412"
"125.56800","10.46418","0.00359"
"125.85600","10.48822","0.00397"
"126.14400","10.51220","0.00340"
"126.43200","10.53617","0.00365"
"126.72000","10.56009","0.00395"
"127.00800","10.58418","0.00407"
"127.29600","10.60816","0.00353"
"127.58400","10.63219","0.00390"
"127.87200","10.65611","0.00447"
"128.16000","10.68020","0.00431"
"128.44800","10.70412","0.00416"
"128.73600","10.72822","0.00436"
"129.02400","10.75219","0.00411"
"129.31200","10.77623","0.00419"
"129.60000","10.80020","0.00368"
"129.88800","10.82418","0.00373"
"130.17600","10.84815","0.00362"
"130.46400","10.87213","0.00401"
"130.75200","10.89616","0.00378"
"131.04000","10.92014","0.00369"
"131.32800","10.94418","0.00389"
"131.61600","10.96815","0.00382"
"131.90400","10.99219","0.00409"
"132.19200","11.01616","0.00355"
"132.48000","11.04020","0.00361"
"132.76800","11.06417","0.00356"
"133.05600","11.08815","0.00419"
"133.34400","11.11218","0.00369"
"133.63200","11.13622","0.00391"
"133.92000","11.16019","0.00411"
"134.20800","11.18417","0.00407"
"134.49600","11.20821","0.00408"
"134.78400","11.23212","0.00432"
"135.07200","11.25616","0.00436"
"135.36000","11.28013","0.00445"
"135.64800","11.30417","0.00395"
"135.93600","11.32814","0.00392"
"136.22400","11.35218","0.00441"
"136.51200","11.37615","0.00471"
"136.80000","11.40019","0.00384"
"137.08800","11.42417","0.00457"
"137.37600","11.44820","0.00417"
"137.66400","11.47218","0.00409"
"137.95200","11.49615","0.00445"
"138.24000","11.52019","0.00403"
"138.52800","11.54416","0.00453"
"138.81600","11.56820","0.00433"
"139.10400","11.59217","0.00481"
"139.39200","11.61621","0.00411"
"139.68000","11.64013","0.00524"
"139.96800","11.66422","0.00479"
"140.25600","11.68814","0.00480"
"140.54400","11.71217","0.00469"
"140.83200","11.73621","0.00475"
"141.12000","11.76018","0.00501"
"141.40800","11.78422","0.00446"
"141.69600","11.80814","0.00519"
"141.98400","11.83223","0.00504"
"142.27200","11.85614","0.00497"
"142.56000","11.88018","0.00481"
"142.84800","11.90416","0.00550"
"143.13600","11.92819","0.00553"
"143.42400","11.95211","0.00551"
"143.71200","11.97614","0.00594"
"144.00000","12.00012","0.00546"
"144.28800","12.02421","0.00602"
"144.57600","12.04813","0.00528"
"144.86400","12.07222","0.00521"
"145.15200","12.09620","0.00528"
"145.44000","12.12018","0.00497"
"145.72800","12.14415","0.00393"
"146.01600","12.16819","0.00328"
"146.30400","12.19222","0.00382"
"146.59200","12.21620","0.00353"
"146.88000","12.24023","0.00316"
"147.16800","12.26421","0.00325"
"147.45600","12.28819","0.00316"
"147.74400","12.31210","0.00330"
"148.03200","12.33619","0.00362"
"148.32000","12.36011","0.00334"
"148.60800","12.38421","0.00383"
"148.89600","12.40818","0.00389"
"149.18400","12.43216","0.00356"
"149.47200","12.45619","0.00351"
"149.76000","12.48017","0.00391"
"150.04800","12.50420","0.00369"
"150.33600","12.52812","0.00370"
"150.62400","12.55221","0.00402"
"150.91200","12.57613","0.00338"
"151.20000","12.60023","0.00417"
"151.48800","12.62414","0.00376"
"151.77600","12.64824","0.00386"
"152.06400","12.67215","0.00425"
"152.35200","12.69625","0.00399"
"152.64000","12.72016","0.00437"
"152.92800","12.74420","0.00383"
"153.21600","12.76817","0.00401"
"153.50400","12.79221","0.00389"
"153.79200","12.81619","0.00382"
"154.08000","12.84022","0.00409"
"154.36800","12.86420","0.00399"
"154.65600","12.88817","0.00386"
"154.94400","12.91221","0.00418"
"155.23200","12.93618","0.00395"
"155.52000","12.96022","0.00427"
"155.80800","12.98414","0.00408"
"156.09600","13.00817","0.00407"
"156.38400","13.03215","0.00458"
"156.67200","13.05618","0.00374"
"156.96000","13.08016","0.00388"
"157.24800","13.10419","0.00396"
"157.53600","13.12817","0.00411"
"157.82400","13.15220","0.00375"
"158.11200","13.17618","0.00366"
"158.40000","13.20021","0.00386"
"158.68800","13.22425","0.00326"
"158.97600","13.24817","0.00389"
"159.26400","13.27226","0.00373"
"159.55200","13.29618","0.00409"
"159.84000","13.32021","0.00402"
"160.12800","13.34413","0.00377"
"160.41600","13.36816","0.00344"
"160.70400","13.39214","0.00401"
"160.99200","13.41623","0.00318"
"161.28000","13.44015","0.00380"
"161.56800","13.46424","0.00359"
"161.85600","13.48816","0.00377"
"162.14400","13.51220","0.00387"
"162.43200","13.53617","0.00389"
"162.72000","13.56021","0.00392"
"163.00800","13.58418","0.00385"
"163.29600","13.60810","0.00386"
"163.58400","13.63219","0.00408"
"163.87200","13.65617","0.00392"
"164.16000","13.68015","0.00406"
"164.44800","13.70412","0.00390"
"164.73600","13.72822","0.00367"
"165.02400","13.75219","0.00422"
"165.31200","13.77617","0.00411"
"165.60000","13.80020","0.00371"
"165.88800","13.82418","0.00415"
"166.17600","13.84821","0.00439"
"166.46400","13.87219","0.00404"
"166.75200","13.89622","0.00389"
"167.04000","13.92020","0.00398"
"167.32800","13.94424","0.00374"
"167.61600","13.96815","0.00406"
"167.90400","13.99219","0.00428"
"168.19200","14.01610","0.00388"
"168.48000","14.04014","0.00402"
"168.76800","14.06405","0.00396"
"169.05600","14.08821","0.00415"
"169.34400","14.11212","0.00428"
"169.63200","14.13616","0.00451"
"169.92000","14.16014","0.00456"
"170.20800","14.18417","0.00433"
"170.49600","14.20815","0.00425"
"170.78400","14.23218","0.00477"
"171.07200","14.25616","0.00450"
"171.36000","14.28013","0.00493"
"171.64800","14.30417","0.00461"
"171.93600","14.32814","0.00485"
"172.22400","14.35218","0.00493"
"172.51200","14.37615","0.00457"
"172.80000","14.40019","0.00494"
"173.08800","14.42417","0.00467"
"173.37600","14.44826","0.00474"
"173.66400","14.47218","0.00453"
"173.95200","14.49615","0.00477"
"174.24000","14.52019","0.00454"
"174.52800","14.54416","0.00467"
"174.81600","14.56814","0.00468"
"175.10400","14.59211","0.00450"
"175.39200","14.61615","0.00470"
"175.68000","14.64013","0.00433"
"175.96800","14.66416","0.00440"
"176.25600","14.68808","0.00409"
"176.54400","14.71217","0.00436"
"176.83200","14.73609","0.00422"
"177.12000","14.76024","0.00400"
"177.40800","14.78416","0.00455"
"177.69600","14.80819","0.00465"
"177.98400","14.83217","0.00511"
"178.27200","14.85615","0.00444"
"178.56000","14.88012","0.00461"
"178.84800","14.90410","0.00512"
"179.13600","14.92819","0.00478"
"179.42400","14.95211","0.00496"
"179.71200","14.97614","0.00507"
"180.00000","15.00012","0.00518"
"180.28800","15.02415","0.00541"
"180.57600","15.04807","0.00544"
"180.86400","15.07222","0.00542"
"181.15200","15.09614","0.00568"
"181.44000","15.12012","0.00545"
"181.72800","15.14409","0.00529"
"182.01600","15.16819","0.00571"
"182.30400","15.19216","0.00610"
"182.59200","15.21614","0.00576"
"182.88000","15.24017","0.00589"
"183.16800","15.26415","0.00617"
"183.45600","15.28813","0.00635"
"183.74400","15.31210","0.00632"
"184.03200","15.33620","0.00609"
"184.32000","15.36011","0.00585"
"184.60800","15.38415","0.00664"
"184.89600","15.40812","0.00640"
"185.18400","15.43222","0.00627"
"185.47200","15.45613","0.00580"
"185.76000","15.48017","0.00581"
"186.04800","15.50414","0.00422"
"186.33600","15.52818","0.00448"
"186.62400","15.55216","0.00422"
"186.91200","15.57613","0.00449"
"187.20000","15.60017","0.00432"
"187.48800","15.62414","0.00389"
"187.77600","15.64818","0.00372"
"188.06400","15.67215","0.00341"
"188.35200","15.69619","0.00368"
"188.64000","15.72010","0.00364"
"188.92800","15.74414","0.00354"
"189.21600","15.76811","0.00364"
"189.50400","15.79221","0.00376"
"189.79200","15.81618","0.00355"
"190.08000","15.84016","0.00394"
"190.36800","15.86419","0.00395"
"190.65600","15.88817","0.00404"
"190.94400","15.91221","0.00410"
"191.23200","15.93612","0.00390"
"191.52000","15.96022","0.00412"
"191.80800","15.98413","0.00406"
"192.09600","16.00817","0.00440"
"192.38400","16.03214","0.00413"
"192.67200","16.05618","0.00432"
"192.96000","16.08016","0.00433"
"193.24800","16.10419","0.00448"
"193.53600","16.12817","0.00485"
"193.82400","16.15220","0.00454"
"194.11200","16.17612","0.00447"
"194.40000","16.20015","0.00407"
"194.68800","16.22419","0.00444"
"194.97600","16.24822","0.00459"
"195.26400","16.27220","0.00462"
"195.55200","16.29618","0.00421"
"195.84000","16.32021","0.00418"
"196.12800","16.34413","0.00395"
"196.41600","16.36816","0.00392"
"196.70400","16.39214","0.00393"
"196.99200","16.41623","0.00376"
"197.28000","16.44021","0.00393"
"197.56800","16.46424","0.00412"
"197.85600","16.48816","0.00423"
"198.14400","16.51220","0.00416"
"198.43200","16.53617","0.00393"
"198.72000","16.56021","0.00426"
"199.00800","16.58418","0.00387"
"199.29600","16.60822","0.00444"
"199.58400","16.63225","0.00456"
"199.87200","16.65617","0.00378"
"200.16000","16.68020","0.00459"
"200.44800","16.70412","0.00469"
"200.73600","16.72816","0.00438"
"201.02400","16.75219","0.00467"
"201.31200","16.77622","0.00392"
"201.60000","16.80014","0.00441"
"201.88800","16.82418","0.00432"
"202.17600","16.84815","0.00460"
"202.46400","16.87225","0.00457"
"202.75200","16.89616","0.00472"
"203.04000","16.92020","0.00480"
"203.32800","16.94423","0.00480"
"203.61600","16.96821","0.00495"
"203.90400","16.99224","0.00423"
"204.19200","17.01610","0.00482"
"204.48000","17.04020","0.00495"
"204.76800","17.06411","0.00467"
"205.05600","17.08821","0.00413"
"205.34400","17.11218","0.00443"
"205.63200","17.13622","0.00394"
"205.92000","17.16019","0.00458"
"206.20800","17.18417","0.00444"
"206.49600","17.20814","0.00453"
"206.78400","17.23218","0.00509"
"207.07200","17.25622","0.00495"
"207.36000","17.28019","0.00522"
"207.64800","17.30417","0.00524"
"207.93600","17.32814","0.00490"
"208.22400","17.35224","0.00481"
"208.51200","17.37615","0.00433"
"208.80000","17.40019","0.00446"
"209.08800","17.42416","0.00457"
"209.37600","17.44820","0.00445"
"209.66400","17.47212","0.00484"
"209.95200","17.49621","0.00474"
"210.24000","17.52019","0.00504"
"210.52800","17.54416","0.00518"
"210.81600","17.56814","0.00471"
"211.10400","17.59217","0.00438"
"211.39200","17.61621","0.00512"
"211.68000","17.64013","0.00546"
"211.96800","17.66422","0.00502"
"212.25600","17.68819","0.00544"
"212.54400","17.71217","0.00491"
"212.83200","17.73609","0.00510"
"213.12000","17.76018","0.00494"
"213.40800","17.78416","0.00509"
"213.69600","17.80819","0.00489"
"213.98400","17.83217","0.00541"
"214.27200","17.85620","0.00556"
"214.56000","17.88018","0.00570"
"214.84800","17.90421","0.00567"
"215.13600","17.92813","0.00594"
"215.42400","17.95217","0.00599"
"215.71200","17.97620","0.00685"
"216.00000","18.00018","0.00636"
"216.28800","18.02415","0.00627"
"216.57600","18.04813","0.00662"
"216.86400","18.07216","0.00668"
"217.15200","18.09614","0.00711"
"217.44000","18.12017","0.00419"
"217.72800","18.14415","0.00457"
"218.01600","18.16818","0.00455"
"218.30400","18.19216","0.00472"
"218.59200","18.21620","0.00474"
"218.88000","18.24023","0.00513"
"219.16800","18.26415","0.00533"
"219.45600","18.28818","0.00556"
"219.74400","18.31216","0.00617"
"220.03200","18.33619","0.00567"
"220.32000","18.36011","0.00591"
"220.60800","18.38420","0.00659"
"220.89600","18.40818","0.00657"
"221.18400","18.43222","0.00687"
"221.47200","18.45613","0.00714"
"221.76000","18.48017","0.00737"
"222.04800","18.50408","0.00727"
"222.33600","18.52818","0.00758"
"222.62400","18.55215","0.00765"
"222.91200","18.57619","0.00819"
"223.20000","18.60017","0.00787"
"223.48800","18.62414","0.00871"
"223.77600","18.64818","0.00809"
"224.06400","18.67209","0.00829"
"224.35200","18.69619","0.00451"
"224.64000","18.72016","0.00529"
"224.92800","18.74420","0.00476"
"225.21600","18.76818","0.00513"
"225.50400","18.79221","0.00447"
"225.79200","18.81612","0.00493"
"226.08000","18.84022","0.00576"
"226.36800","18.86414","0.00570"
"226.65600","18.88817","0.00562"
"226.94400","18.91215","0.00630"
"227.23200","18.93618","0.00593"
"227.52000","18.96016","0.00619"
"227.80800","18.98419","0.00641"
"228.09600","19.00817","0.00622"
"228.38400","19.03214","0.00628"
"228.67200","19.05618","0.00592"
"228.96000","19.08015","0.00619"
"229.24800","19.10419","0.00548"
"229.53600","19.12811","0.00556"
"229.82400","19.15220","0.00408"
"230.11200","19.17612","0.00453"
"230.40000","19.20015","0.00421"
"230.68800","19.22413","0.00414"
"230.97600","19.24822","0.00424"
"231.26400","19.27220","0.00457"
"231.55200","19.29618","0.00428"
"231.84000","19.32015","0.00434"
"232.12800","19.34419","0.00500"
"232.41600","19.36816","0.00478"
"232.70400","19.39214","0.00528"
"232.99200","19.41617","0.00521"
"233.28000","19.44021","0.00538"
"233.56800","19.46424","0.00497"
"233.85600","19.48816","0.00508"
"234.14400","19.51220","0.00432"
"234.43200","19.53617","0.00461"
"234.72000","19.56021","0.00364"
"235.00800","19.58418","0.00327"
"235.29600","19.60822","0.00378"
"235.58400","19.63225","0.00288"
"235.87200","19.65623","0.00332"
"236.16000","19.68026","0.00355"
"236.44800","19.70418","0.00340"
"236.73600","19.72821","0.00370"
"237.02400","19.75213","0.00393"
"237.31200","19.77623","0.00385"
"237.60000","19.80014","0.00343"
"237.88800","19.82418","0.00376"
"238.17600","19.84815","0.00444"
"238.46400","19.87219","0.00397"
"238.75200","19.89616","0.00392"
"239.04000","19.92026","0.00385"
"239.32800","19.94417","0.00383"
"239.61600","19.96821","0.00406"
"239.90400","19.99218","0.00323"
"240.19200","20.01616","0.00354"
"240.48000","20.04020","0.00403"
"240.76800","20.06417","0.00379"
"241.05600","20.08821","0.00419"
"241.34400","20.11218","0.00450"
"241.63200","20.13622","0.00419"
"241.92000","20.16014","0.00394"
"242.20800","20.18417","0.00369"
"242.49600","20.20820","0.00433"
"242.78400","20.23218","0.00449"
"243.07200","20.25616","0.00460"
"243.36000","20.28019","0.00425"
"243.64800","20.30416","0.00430"
"243.93600","20.32820","0.00470"
"244.22400","20.35224","0.00534"
"244.51200","20.37621","0.00505"
"244.80000","20.40025","0.00530"
"245.08800","20.42417","0.00517"
"245.37600","20.44820","0.00509"
"245.66400","20.47211","0.00554"
"245.95200","20.49615","0.00659"
"246.24000","20.52013","0.00650"
"246.52800","20.54422","0.00617"
"246.81600","20.56820","0.00607"
"247.10400","20.59217","0.00698"
"247.39200","20.61615","0.00719"
"247.68000","20.64018","0.00729"
"247.96800","20.66416","0.00680"
"248.25600","20.68819","0.00748"
"248.54400","20.71217","0.00810"
"248.83200","20.73615","0.00705"
"249.12000","20.76018","0.00824"
"249.40800","20.78410","0.00776"
"249.69600","20.80813","0.00776"
"249.98400","20.83211","0.00743"
"250.27200","20.85620","0.00717"
"250.56000","20.88018","0.00710"
"250.84800","20.90421","0.00758"
"251.13600","20.92813","0.00774"
"251.42400","20.95217","0.00458"
"251.71200","20.97620","0.00451"
"252.00000","21.00018","0.00415"
"252.28800","21.02415","0.00440"
"252.57600","21.04819","0.00399"
"252.86400","21.07222","0.00421"
"253.15200","21.09614","0.00394"
"253.44000","21.12024","0.00396"
"253.72800","21.14415","0.00441"
"254.01600","21.16818","0.00487"
"254.30400","21.19210","0.00458"
"254.59200","21.21620","0.00499"
"254.88000","21.24011","0.00468"
"255.16800","21.26421","0.00470"
"255.45600","21.28812","0.00549"
"255.74400","21.31216","0.00526"
"256.03200","21.33619","0.00500"
"256.32000","21.36017","0.00563"
"256.60800","21.38415","0.00479"
"256.89600","21.40812","0.00538"
"257.18400","21.43222","0.00564"
"257.47200","21.45613","0.00555"
"257.76000","21.48017","0.00582"
"258.04800","21.50408","0.00673"
"258.33600","21.52818","0.00702"
"258.62400","21.55215","0.00646"
"258.91200","21.57619","0.00625"
"259.20000","21.60016","0.00602"
"259.48800","21.62420","0.00657"
"259.77600","21.64818","0.00689"
"260.06400","21.67215","0.00678"
"260.35200","21.69619","0.00739"
"260.64000","21.72010","0.00691"
"260.92800","21.74414","0.00764"
"261.21600","21.76817","0.00737"
"261.50400","21.79221","0.00772"
"261.79200","21.81612","0.00864"
"262.08000","21.84016","0.00802"
"262.36800","21.86407","0.00753"
"262.65600","21.88817","0.00782"
"262.94400","21.91208","0.00764"
"263.23200","21.93618","0.00757"
"263.52000","21.96010","0.00620"
"263.80800","21.98413","0.00546"
"264.09600","22.00811","0.00566"
"264.38400","22.03214","0.00532"
"264.67200","22.05618","0.00574"
"264.96000","22.08015","0.00577"
"265.24800","22.10419","0.00621"
"265.53600","22.12811","0.00682"
"265.82400","22.15214","0.00668"
"266.11200","22.17612","0.00689"
"266.40000","22.20015","0.00771"
"266.68800","22.22407","0.00817"
"266.97600","22.24816","0.00831"
"267.26400","22.27214","0.00870"
"267.55200","22.29618","0.00865"
"267.84000","22.32015","0.00884"
"268.12800","22.34413","0.00915"
"268.41600","22.36816","0.00890"
"268.70400","22.39214","0.00935"
"268.99200","22.41617","0.00880"
"269.28000","22.44015","0.00888"
"269.56800","22.46418","0.00717"
"269.85600","22.48810","0.00782"
"270.14400","22.51213","0.00735"
"270.43200","22.53611","0.00755"
"270.72000","22.56015","0.00852"
"271.00800","22.58412","0.00845"
"271.29600","22.60822","0.00815"
"271.58400","22.63219","0.00883"
"271.87200","22.65617","0.00633"
"272.16000","22.68020","0.00508"
"272.44800","22.70418","0.00575"
"272.73600","22.72816","0.00567"
"273.02400","22.75213","0.00681"
"273.31200","22.77617","0.00682"
"273.60000","22.80014","0.00665"
"273.88800","22.82417","0.00736"
"274.17600","22.84815","0.00776"
"274.46400","22.87218","0.00736"
"274.75200","22.89610","0.00773"
"275.04000","22.92020","0.00752"
"275.32800","22.94411","0.00845"
"275.61600","22.96821","0.00831"
"275.90400","22.99218","0.00795"
"276.19200","23.01622","0.00821"
"276.48000","23.04020","0.00837"
"276.76800","23.06423","0.00904"
"277.05600","23.08827","0.00955"
"277.34400","23.11218","0.00987"
"277.63200","23.13622","0.00926"
"277.92000","23.16013","0.00847"
"278.20800","23.18417","0.00845"
"278.49600","23.20809","0.00753"
"278.78400","23.23224","0.00261"
"279.07200","23.25616","0.00283"
"279.36000","23.28019","0.00267"
"279.64800","23.30417","0.00254"
"279.93600","23.32826","0.00314"
"280.22400","23.35218","0.00273"
"280.51200","23.37621","0.00296"
"280.80000","23.40019","0.00302"
"281.08800","23.42416","0.00310"
"281.37600","23.44820","0.00294"
"281.66400","23.47211","0.00320"
"281.95200","23.49615","0.00280"
"282.24000","23.52012","0.00279"
"282.52800","23.54422","0.00324"
"282.81600","23.56814","0.00322"
"283.10400","23.59223","0.00320"
"283.39200","23.61615","0.00296"
"283.68000","23.64018","0.00334"
"283.96800","23.66416","0.00356"
"284.25600","23.68826","0.00350"
"284.54400","23.71217","0.00322"
"284.83200","23.73621","0.00343"
"285.12000","23.76024","0.00349"
"285.40800","23.78415","0.00330"
"285.69600","23.80819","0.00316"
"285.98400","23.83217","0.00375"
"286.27200","23.85620","0.00333"
"286.56000","23.88018","0.00325"
"286.84800","23.90421","0.00345"
"287.13600","23.92813","0.00330"
"287.42400","23.95216","0.00373"
"287.71200","23.97620","0.00337"
"288.00000","24.00018","0.00349"
"288.28800","24.02415","0.00391"
"288.57600","24.04819","0.00325"
"288.86400","24.07216","0.00364"
"289.15200","24.09614","0.00359"
"289.44000","24.12023","0.00352"
"289.72800","24.14415","0.00366"
"290.01600","24.16818","0.00344"
"290.30400","24.19216","0.00330"
"290.59200","24.21620","0.00374"
"290.88000","24.24011","0.00351"
"291.16800","24.26421","0.00351"
"291.45600","24.28812","0.00326"
"291.74400","24.31222","0.00323"
"292.03200","24.33619","0.00356"
"292.32000","24.36017","0.00402"
"292.60800","24.38414","0.00371"
"292.89600","24.40818","0.00334"
"293.18400","24.43216","0.00371"
"293.47200","24.45619","0.00385"
"293.76000","24.48022","0.00358"
"294.04800","24.50414","0.00353"
"294.33600","24.52818","0.00362"
"294.62400","24.55215","0.00411"
"294.91200","24.57619","0.00376"
"295.20000","24.60016","0.00411"
"295.48800","24.62420","0.00390"
"295.77600","24.64812","0.00391"
"296.06400","24.67215","0.00389"
"296.35200","24.69613","0.00402"
"296.64000","24.72016","0.00390"
"296.92800","24.74420","0.00413"
"297.21600","24.76817","0.00365"
"297.50400","24.79221","0.00415"
"297.79200","24.81612","0.00377"
"298.08000","24.84022","0.00397"
"298.36800","24.86419","0.00402"
"298.65600","24.88817","0.00414"
"298.94400","24.91215","0.00392"
"299.23200","24.93618","0.00431"
"299.52000","24.96010","0.00403"
"299.80800","24.98419","0.00368"
"300.09600","25.00811","0.00327"
"300.38400","25.03220","0.00330"
"300.67200","25.05618","0.00335"
"300.96000","25.08015","0.00308"
"301.24800","25.10419","0.00343"
"301.53600","25.12817","0.00356"
"301.82400","25.15220","0.00390"
"302.11200","25.17612","0.00351"
"302.40000","25.20015","0.00363"
"302.68800","25.22419","0.00344"
"302.97600","25.24822","0.00336"
"303.26400","25.27208","0.00364"
"303.55200","25.29617","0.00337"
"303.84000","25.32009","0.00383"
"304.12800","25.34418","0.00346"
"304.41600","25.36816","0.00373"
"304.70400","25.39219","0.00313"
"304.99200","25.41623","0.00324"
"305.28000","25.44015","0.00386"
"305.56800","25.46418","0.00316"
"305.85600","25.48816","0.00346"
"306.14400","25.51219","0.00321"
"306.43200","25.53617","0.00361"
"306.72000","25.56020","0.00402"
"307.00800","25.58412","0.00359"
"307.29600","25.60822","0.00349"
"307.58400","25.63213","0.00342"
"307.87200","25.65623","0.00353"
"308.16000","25.68014","0.00353"
"308.44800","25.70418","0.00341"
"308.73600","25.72816","0.00358"
"309.02400","25.75213","0.00332"
"309.31200","25.77610","0.00320"
"309.60000","25.80014","0.00350"
"309.88800","25.82418","0.00323"
"310.17600","25.84815","0.00316"
"310.46400","25.87219","0.00320"
"310.75200","25.89616","0.00335"
"311.04000","25.92020","0.00336"
"311.32800","25.94411","0.00316"
"311.61600","25.96815","0.00318"
"311.90400","25.99212","0.00300"
"312.19200","26.01622","0.00333"
"312.48000","26.04020","0.00385"
"312.76800","26.06423","0.00332"
"313.05600","26.08821","0.00352"
"313.34400","26.11218","0.00335"
"313.63200","26.13616","0.00348"
"313.92000","26.16013","0.00365"
"314.20800","26.18417","0.00366"
"314.49600","26.20814","0.00344"
"314.78400","26.23224","0.00354"
"315.07200","26.25615","0.00334"
"315.36000","26.28019","0.00387"
"315.64800","26.30411","0.00345"
"315.93600","26.32820","0.00373"
"316.22400","26.35218","0.00367"
"316.51200","26.37621","0.00336"
"316.80000","26.40019","0.00401"
"317.08800","26.42422","0.00364"
"317.37600","26.44820","0.00391"
"317.66400","26.47217","0.00361"
"317.95200","26.49621","0.00395"
"318.24000","26.52013","0.00437"
"318.52800","26.54422","0.00388"
"318.81600","26.56820","0.00378"
"319.10400","26.59223","0.00398"
"319.39200","26.61615","0.00397"
"319.68000","26.64018","0.00443"
"319.96800","26.66416","0.00420"
"320.25600","26.68819","0.00418"
"320.54400","26.71217","0.00429"
"320.83200","26.73620","0.00432"
"321.12000","26.76018","0.00395"
"321.40800","26.78422","0.00414"
"321.69600","26.80819","0.00381"
"321.98400","26.83217","0.00400"
"322.27200","26.85620","0.00389"
"322.56000","26.88018","0.00412"
"322.84800","26.90421","0.00419"
"323.13600","26.92813","0.00387"
"323.42400","26.95222","0.00277"
"323.71200","26.97614","0.00271"
"324.00000","27.00023","0.00232"
"324.28800","27.02415","0.00242"
"324.57600","27.04819","0.00212"
"324.86400","27.07216","0.00213"
"325.15200","27.09620","0.00221"
"325.44000","27.12017","0.00202"
"325.72800","27.14421","0.00237"
"326.01600","27.16819","0.00162"
"326.30400","27.19216","0.00182"
"326.59200","27.21620","0.00197"
"326.88000","27.24011","0.00231"
"327.16800","27.26421","0.00201"
"327.45600","27.28818","0.00171"
"327.74400","27.31222","0.00216"
"328.03200","27.33613","0.00186"
"328.32000","27.36017","0.00221"
"328.60800","27.38420","0.00208"
"328.89600","27.40818","0.00184"
"329.18400","27.43216","0.00258"
"329.47200","27.45613","0.00228"
"329.76000","27.48017","0.00221"
"330.04800","27.50414","0.00263"
"330.33600","27.52818","0.00246"
"330.62400","27.55215","0.00209"
"330.91200","27.57619","0.00236"
"331.20000","27.60016","0.00265"
"331.48800","27.62420","0.00232"
"331.77600","27.64817","0.00221"
"332.06400","27.67221","0.00196"
"332.35200","27.69613","0.00206"
"332.64000","27.72016","0.00200"
"332.92800","27.74420","0.00226"
"333.21600","27.76818","0.00232"
"333.50400","27.79215","0.00202"
"333.79200","27.81618","0.00224"
"334.08000","27.84016","0.00237"
"334.36800","27.86414","0.00215"
"334.65600","27.88817","0.00153"
"334.94400","27.91215","0.00163"
"335.23200","27.93618","0.00181"
"335.52000","27.96010","0.00193"
"335.80800","27.98419","0.00176"
"336.09600","28.00811","0.00169"
"336.38400","28.03220","0.00195"
"336.67200","28.05618","0.00188"
"336.96000","28.08016","0.00204"
"337.24800","28.10413","0.00220"
"337.53600","28.12817","0.00210"
"337.82400","28.15220","0.00205"
"338.11200","28.17618","0.00240"
"338.40000","28.20021","0.00192"
"338.68800","28.22419","0.00191"
"338.97600","28.24822","0.00170"
"339.26400","28.27214","0.00202"
"339.55200","28.29617","0.00178"
"339.84000","28.32009","0.00156"
"340.12800","28.34419","0.00171"
"340.41600","28.36810","0.00150"
"340.70400","28.39220","0.00179"
"340.99200","28.41611","0.00171"
"341.28000","28.44015","0.00147"
"341.56800","28.46412","0.00179"
"341.85600","28.48810","0.00163"
"342.14400","28.51220","0.00178"
"342.43200","28.53617","0.00176"
"342.72000","28.56021","0.00172"
"343.00800","28.58418","0.00161"
"343.29600","28.60815","0.00209"
"343.58400","28.63213","0.00200"
"343.87200","28.65617","0.00172"
"344.16000","28.68014","0.00179"
"344.44800","28.70418","0.00191"
"344.73600","28.72810","0.00163"
"345.02400","28.75219","0.00187"
"345.31200","28.77611","0.00158"
"345.60000","28.80014","0.00168"
"345.88800","28.82417","0.00127"
"346.17600","28.84815","0.00157"
"346.46400","28.87219","0.00148"
"346.75200","28.89616","0.00137"
"347.04000","28.92020","0.00153"
"347.32800","28.94411","0.00107"
"347.61600","28.96815","0.00138"
"347.90400","28.99213","0.00136"
"348.19200","29.01616","0.00127"
"348.48000","29.04008","0.00141"
"348.76800","29.06417","0.00146"
"349.05600","29.08809","0.00136"
"349.34400","29.11218","0.00161"
"349.63200","29.13616","0.00134"
"349.92000","29.16019","0.00168"
"350.20800","29.18417","0.00088"
"350.49600","29.20815","0.00115"
"350.78400","29.23218","0.00164"
"351.07200","29.25616","0.00142"
"351.36000","29.28019","0.00102"
"351.64800","29.30417","0.00140"
"351.93600","29.32814","0.00149"
"352.22400","29.35212","0.00121"
"352.51200","29.37615","0.00158"
"352.80000","29.40007","0.00106"
"353.08800","29.42416","0.00130"
"353.37600","29.44814","0.00123"
"353.66400","29.47218","0.00125"
"353.95200","29.49621","0.00161"
"354.24000","29.52019","0.00141"
"354.52800","29.54416","0.00111"
"354.81600","29.56814","0.00166"
"355.10400","29.59217","0.00143"
"355.39200","29.61615","0.00168"
"355.68000","29.64018","0.00122"
"355.96800","29.66416","0.00159"
"356.25600","29.68820","0.00135"
"356.54400","29.71217","0.00149"
"356.83200","29.73621","0.00164"
"357.12000","29.76018","0.00207"
"357.40800","29.78422","0.00168"
"357.69600","29.80819","0.00159"
"357.98400","29.83217","0.00179"
"358.27200","29.85614","0.00168"
"358.56000","29.88024","0.00177"
"358.84800","29.90421","0.00182"
"359.13600","29.92813","0.00149"
"359.42400","29.95217","0.00170"
"359.71200","29.97614","0.00160"
"360.00000","30.00018","0.00146"
"360.28800","30.02415","0.00190"
"360.57600","30.04819","0.00157"
"360.86400","30.07216","0.00186"
"361.15200","30.09626","0.00202"
"361.44000","30.12017","0.00135"
"361.72800","30.14421","0.00154"
"362.01600","30.16818","0.00148"
"362.30400","30.19222","0.00154"
"362.59200","30.21619","0.00138"
"362.88000","30.24017","0.00155"
"363.16800","30.26415","0.00167"
"363.45600","30.28818","0.00140"
"363.74400","30.31222","0.00146"
"364.03200","30.33619","0.00180"
"364.32000","30.36023","0.00138"
"364.60800","30.38415","0.00175"
"364.89600","30.40824","0.00106"
"365.18400","30.43216","0.00140"
"365.47200","30.45619","0.00159"
"365.76000","30.48017","0.00134"
"366.04800","30.50420","0.00164"
"366.33600","30.52818","0.00125"
"366.62400","30.55215","0.00152"
"366.91200","30.57619","0.00167"
"367.20000","30.60017","0.00178"
"367.48800","30.62414","0.00145"
"367.77600","30.64811","0.00107"
"368.06400","30.67221","0.00106"
"368.35200","30.69613","0.00188"
"368.64000","30.72022","0.00160"
"368.92800","30.74414","0.00154"
"369.21600","30.76823","0.00124"
"369.50400","30.79215","0.00144"
"369.79200","30.81618","0.00128"
"370.08000","30.84016","0.00158"
"370.36800","30.86420","0.00139"
"370.65600","30.88817","0.00127"
"370.94400","30.91215","0.00169"
"371.23200","30.93618","0.00174"
"371.52000","30.96022","0.00145"
"371.80800","30.98425","0.00130"
"372.09600","31.00817","0.00143"
"372.38400","31.03220","0.00184"
"372.67200","31.05618","0.00153"
"372.96000","31.08015","0.00156"
"373.24800","31.10413","0.00180"
"373.53600","31.12816","0.00143"
"373.82400","31.15214","0.00178"
"374.11200","31.17618","0.00166"
"374.40000","31.20015","0.00164"
"374.68800","31.22419","0.00182"
"374.97600","31.24822","0.00177"
"375.26400","31.27213","0.00183"
"375.55200","31.29623","0.00152"
"375.84000","31.32015","0.00189"
"376.12800","31.34418","0.00167"
"376.41600","31.36816","0.00191"
"376.70400","31.39219","0.00181"
"376.99200","31.41611","0.00154"
"377.28000","31.44021","0.00135"
"377.56800","31.46412","0.00156"
"377.85600","31.48822","0.00177"
"378.14400","31.51213","0.00217"
"378.43200","31.53617","0.00212"
"378.72000","31.56021","0.00173"
"379.00800","31.58424","0.00148"
"379.29600","31.60821","0.00187"
"379.58400","31.63213","0.00168"
"379.87200","31.65616","0.00203"
"380.16000","31.68014","0.00240"
"380.44800","31.70418","0.00164"
"380.73600","31.72809","0.00181"
"381.02400","31.75219","0.00172"
"381.31200","31.77610","0.00161"
"381.60000","31.80020","0.00175"
"381.88800","31.82412","0.00216"
"382.17600","31.84821","0.00154"
"382.46400","31.87219","0.00137"
"382.75200","31.89622","0.00190"
"383.04000","31.92019","0.00143"
"383.32800","31.94417","0.00210"
"383.61600","31.96821","0.00211"
"383.90400","31.99218","0.00184"
"384.19200","32.01622","0.00179"
"384.48000","32.04020","0.00224"
"384.76800","32.06417","0.00175"
"385.05600","32.08809","0.00187"
"385.34400","32.11218","0.00197"
"385.63200","32.13610","0.00224"
"385.92000","32.16019","0.00183"
"386.20800","32.18417","0.00202"
"386.49600","32.20820","0.00168"
"386.78400","32.23218","0.00193"
"387.07200","32.25615","0.00180"
"387.36000","32.28019","0.00175"
"387.64800","32.30416","0.00207"
"387.93600","32.32820","0.00205"
"388.22400","32.35212","0.00192"
"388.51200","32.37609","0.00155"
"388.80000","32.40013","0.00189"
"389.08800","32.42416","0.00189"
"389.37600","32.44808","0.00213"
"389.66400","32.47218","0.00165"
"389.95200","32.49615","0.00204"
"390.24000","32.52018","0.00181"
"390.52800","32.54416","0.00227"
"390.81600","32.56820","0.00139"
"391.10400","32.59223","0.00180"
"391.39200","32.61615","0.00218"
"391.68000","32.64018","0.00224"
"391.96800","32.66416","0.00176"
"392.25600","32.68819","0.00160"
"392.54400","32.71217","0.00198"
"392.83200","32.73621","0.00211"
"393.12000","32.76018","0.00177"
"393.40800","32.78422","0.00179"
"393.69600","32.80807","0.00143"
"393.98400","32.83223","0.00173"
"394.27200","32.85614","0.00172"
"394.56000","32.88018","0.00140"
"394.84800","32.90415","0.00188"
"395.13600","32.92819","0.00151"
"395.42400","32.95216","0.00118"
"395.71200","32.97614","0.00193"
"396.00000","33.00018","0.00157"
"396.28800","33.02415","0.00172"
"396.57600","33.04824","0.00167"
"396.86400","33.07222","0.00145"
"397.15200","33.09620","0.00170"
"397.44000","33.12017","0.00176"
"397.72800","33.14415","0.00168"
"398.01600","33.16812","0.00139"
"398.30400","33.19216","0.00193"
"398.59200","33.21619","0.00107"
"398.88000","33.24017","0.00140"
"399.16800","33.26421","0.00126"
"399.45600","33.28818","0.00176"
"399.74400","33.31222","0.00119"
"400.03200","33.33619","0.00164"
"400.32000","33.36029","0.00113"
"400.60800","33.38414","0.00155"
"400.89600","33.40824","0.00151"
"401.18400","33.43216","0.00092"
"401.47200","33.45625","0.00081"
"401.76000","33.48016","0.00140"
"402.04800","33.50426","0.00093"
"402.33600","33.52818","0.00140"
"402.62400","33.55221","0.00122"
"402.91200","33.57619","0.00134"
"403.20000","33.60016","0.00085"
"403.48800","33.62420","0.00106"
"403.77600","33.64817","0.00096"
"404.06400","33.67221","0.00125"
"404.35200","33.69619","0.00121"
"404.64000","33.72022","0.00108"
"404.92800","33.74413","0.00106"
"405.21600","33.76817","0.00120"
"405.50400","33.79214","0.00082"
"405.79200","33.81624","0.00073"
"406.08000","33.84016","0.00091"
"406.36800","33.86419","0.00123"
"406.65600","33.88817","0.00086"
"406.94400","33.91214","0.00149"
"407.23200","33.93618","0.00097"
"407.52000","33.96016","0.00113"
"407.80800","33.98419","0.00098"
"408.09600","34.00817","0.00092"
"408.38400","34.03226","0.00138"
"408.67200","34.05611","0.00085"
"408.96000","34.08021","0.00095"
"409.24800","34.10413","0.00110"
"409.53600","34.12822","0.00132"
"409.82400","34.15214","0.00111"
"410.11200","34.17624","0.00096"
"410.40200","34.20033","0.00084"
"410.69000","34.22437","0.00121"
"410.97800","34.24834","0.00098"
"411.26600","34.27232","0.00094"
"411.55400","34.29629","0.00122"
"411.84200","34.32033","0.00162"
"412.13000","34.34436","0.00115"
"412.41800","34.36828","0.00125"
"412.70600","34.39231","0.00155"
"412.99400","34.41629","0.00127"
"413.28200","34.44032","0.00112"
"413.57000","34.46424","0.00092"
"413.85800","34.48833","0.00111"
"414.14600","34.51225","0.00121"
"414.43400","34.53635","0.00103"
"414.72200","34.56032","0.00147"
"415.01000","34.58436","0.00088"
"415.29800","34.60833","0.00128"
"415.58600","34.63231","0.00120"
"415.87400","34.65635","0.00107"
"416.16200","34.68032","0.00105"
"416.45000","34.70442","0.00107"
"416.73800","34.72833","0.00078"
"417.02600","34.75237","0.00103"
"417.31400","34.77628","0.00084"
"417.60200","34.80032","0.00150"
"417.89000","34.82429","0.00099"
"418.17800","34.84839","0.00070"
"418.46600","34.87225","0.00084"
"418.75400","34.89634","0.00122"
"419.04200","34.92031","0.00120"
"419.33000","34.94435","0.00065"
"419.61800","34.96833","0.00103"
"419.90600","34.99230","0.00098"
"420.19400","35.01634","0.00097"
"420.48200","35.04031","0.00111"
"420.77000","35.06435","0.00073"
"421.05800","35.08832","0.00130"
"421.34600","35.11230","0.00151"
"421.63400","35.13628","0.00098"
"421.92200","35.16031","0.00122"
"422.21000","35.18429","0.00075"
"422.49800","35.20838","0.00076"
"422.78600","35.23236","0.00093"
"423.07400","35.25633","0.00099"
"423.36200","35.28031","0.00092"
"423.65000","35.30429","0.00108"
"423.93800","35.32838","0.00069"
"424.22600","35.35229","0.00087"
"424.51400","35.37633","0.00240"
"424.80200","35.40031","0.00151"
"425.09000","35.42434","0.00128"
"425.37800","35.44826","0.00054"
"425.66600","35.47229","0.00067"
"425.95400","35.49627","0.00106"
"426.24200","35.52036","0.00064"
"426.53000","35.54428","0.00042"
"426.81800","35.56837","0.00089"
"427.10600","35.59229","0.00097"
"427.39400","35.61633","0.00082"
"427.68200","35.64030","0.00081"
"427.97000","35.66434","0.00083"
"428.25800","35.68831","0.00088"
"428.54600","35.71229","0.00106"
"428.83400","35.73632","0.00120"
"429.12200","35.76030","0.00136"
"429.41000","35.78433","0.00075"
"429.69800","35.80825","0.00039"
"429.98600","35.83234","0.00093"
"430.27400","35.85626","0.00050"
"430.56200","35.88036","0.00042"
"430.85000","35.90427","0.00090"
"431.13800","35.92831","0.00103"
"431.33000","35.94427","0.00044"