File: Force_trajectories/170121_1/Specimen_RawData_4.csv
End date,"1/21/2017"
Specimen label,"14DT_NT2"
Maximum Load,"0.34318",N

Time,Extension,Load
(s),(mm),(N)
"0.00000","0.00000","0.00038"
"0.17400","0.01106","0.00025"
"0.34800","0.02900","-0.00032"
"0.52200","0.04371","0.00020"
"0.69600","0.05824","0.00045"
"0.87000","0.07276","0.00035"
"1.04400","0.08723","0.00012"
"1.21800","0.10170","0.00017"
"1.39200","0.11623","0.00058"
"1.56600","0.13070","0.00024"
"1.74000","0.14517","0.00075"
"1.91400","0.15982","0.00019"
"2.08800","0.17423","0.00084"
"2.26200","0.18864","0.00085"
"2.43600","0.20322","0.00050"
"2.61000","0.21775","0.00034"
"2.78400","0.23216","0.00094"
"2.95800","0.24675","0.00072"
"3.13200","0.26122","0.00024"
"3.30600","0.27569","0.00142"
"3.48000","0.29022","0.00091"
"3.65400","0.30469","0.00091"
"3.82800","0.31916","0.00103"
"4.00200","0.33363","0.00100"
"4.17600","0.34827","0.00060"
"4.35000","0.36268","0.00069"
"4.52400","0.37715","0.00071"
"4.69800","0.39168","0.00118"
"4.87200","0.40615","0.00073"
"5.04600","0.42068","0.00076"
"5.22000","0.43515","0.00103"
"5.39400","0.44962","0.00067"
"5.56800","0.46415","0.00105"
"5.74200","0.47868","0.00087"
"5.91600","0.49320","0.00128"
"6.09000","0.50761","0.00140"
"6.26400","0.52220","0.00100"
"6.43800","0.53667","0.00118"
"6.61200","0.55114","0.00059"
"6.78600","0.56567","0.00105"
"6.96000","0.58020","0.00153"
"7.13400","0.59461","0.00107"
"7.30800","0.60920","0.00120"
"7.48200","0.62372","0.00117"
"7.65600","0.63819","0.00144"
"7.83000","0.65272","0.00118"
"8.00400","0.66719","0.00136"
"8.17800","0.68166","0.00149"
"8.35200","0.69619","0.00119"
"8.52600","0.71072","0.00143"
"8.70000","0.72519","0.00146"
"8.87400","0.73972","0.00152"
"9.04800","0.75419","0.00160"
"9.22200","0.76871","0.00143"
"9.39600","0.78318","0.00118"
"9.57000","0.79771","0.00162"
"9.74400","0.81212","0.00179"
"9.91800","0.82671","0.00180"
"10.09200","0.84118","0.00140"
"10.26600","0.85565","0.00127"
"10.44000","0.87018","0.00110"
"10.61400","0.88471","0.00145"
"10.78800","0.89917","0.00163"
"10.96200","0.91370","0.00149"
"11.13600","0.92817","0.00143"
"11.31000","0.94264","0.00210"
"11.48400","0.95717","0.00144"
"11.65800","0.97170","0.00136"
"11.83200","0.98623","0.00205"
"12.00600","1.00064","0.00186"
"12.18000","1.01523","0.00167"
"12.35400","1.02970","0.00197"
"12.52800","1.04416","0.00190"
"12.70200","1.05869","0.00192"
"12.87600","1.07316","0.00175"
"13.05000","1.08763","0.00164"
"13.22400","1.10222","0.00218"
"13.39800","1.11669","0.00210"
"13.57200","1.13110","0.00194"
"13.74600","1.14569","0.00228"
"13.92000","1.16022","0.00210"
"14.09400","1.17463","0.00206"
"14.26800","1.18921","0.00204"
"14.44200","1.20374","0.00213"
"14.61600","1.21815","0.00208"
"14.79000","1.23274","0.00231"
"14.96400","1.24727","0.00174"
"15.13800","1.26162","0.00231"
"15.31200","1.27621","0.00189"
"15.48600","1.29068","0.00240"
"15.66000","1.30521","0.00220"
"15.83400","1.31973","0.00237"
"16.00800","1.33414","0.00211"
"16.18200","1.34867","0.00239"
"16.35600","1.36314","0.00219"
"16.53000","1.37773","0.00212"
"16.70400","1.39220","0.00241"
"16.87800","1.40667","0.00249"
"17.05200","1.42120","0.00247"
"17.22600","1.43567","0.00272"
"17.40000","1.45020","0.00230"
"17.57400","1.46466","0.00259"
"17.74800","1.47919","0.00244"
"17.92200","1.49366","0.00254"
"18.09600","1.50819","0.00263"
"18.27000","1.52266","0.00249"
"18.44400","1.53713","0.00204"
"18.61800","1.55166","0.00272"
"18.79200","1.56619","0.00287"
"18.96600","1.58066","0.00243"
"19.14000","1.59524","0.00233"
"19.31400","1.60965","0.00249"
"19.48800","1.62412","0.00291"
"19.66200","1.63871","0.00276"
"19.83600","1.65324","0.00272"
"20.01000","1.66765","0.00272"
"20.18400","1.68218","0.00219"
"20.35800","1.69671","0.00230"
"20.53200","1.71118","0.00264"
"20.70600","1.72571","0.00287"
"20.88000","1.74023","0.00268"
"21.05400","1.75464","0.00290"
"21.22800","1.76917","0.00277"
"21.40200","1.78370","0.00233"
"21.57600","1.79817","0.00311"
"21.75000","1.81270","0.00293"
"21.92400","1.82723","0.00231"
"22.09800","1.84164","0.00273"
"22.27200","1.85623","0.00275"
"22.44600","1.87069","0.00264"
"22.62000","1.88516","0.00298"
"22.79400","1.89963","0.00264"
"22.96800","1.91422","0.00238"
"23.14200","1.92869","0.00228"
"23.31600","1.94316","0.00242"
"23.49000","1.95769","0.00299"
"23.66400","1.97222","0.00263"
"23.83800","1.98669","0.00318"
"24.01200","2.00122","0.00278"
"24.18600","2.01568","0.00295"
"24.36000","2.03015","0.00286"
"24.53400","2.04468","0.00239"
"24.70800","2.05921","0.00284"
"24.88200","2.07368","0.00266"
"25.05600","2.08821","0.00330"
"25.23000","2.10268","0.00282"
"25.40400","2.11715","0.00278"
"25.57800","2.13174","0.00335"
"25.75200","2.14615","0.00302"
"25.92600","2.16061","0.00340"
"26.10000","2.17514","0.00252"
"26.27400","2.18967","0.00254"
"26.44800","2.20414","0.00220"
"26.62200","2.21867","0.00212"
"26.79600","2.23320","0.00263"
"26.97000","2.24767","0.00217"
"27.14400","2.26220","0.00237"
"27.31800","2.27673","0.00245"
"27.49200","2.29119","0.00256"
"27.66600","2.30566","0.00277"
"27.84000","2.32019","0.00283"
"28.01400","2.33466","0.00269"
"28.18800","2.34919","0.00290"
"28.36200","2.36372","0.00291"
"28.53600","2.37819","0.00260"
"28.71000","2.39272","0.00310"
"28.88400","2.40725","0.00300"
"29.05800","2.42172","0.00267"
"29.23200","2.43612","0.00298"
"29.40600","2.45071","0.00317"
"29.58000","2.46518","0.00269"
"29.75400","2.47971","0.00346"
"29.92800","2.49424","0.00364"
"30.10200","2.50865","0.00313"
"30.27600","2.52318","0.00292"
"30.45000","2.53771","0.00309"
"30.62400","2.55218","0.00320"
"30.79800","2.56664","0.00359"
"30.97200","2.58117","0.00360"
"31.14600","2.59570","0.00312"
"31.32000","2.61017","0.00278"
"31.49400","2.62470","0.00272"
"31.66800","2.63917","0.00336"
"31.84200","2.65364","0.00305"
"32.01600","2.66823","0.00378"
"32.19000","2.68276","0.00298"
"32.36400","2.69711","0.00334"
"32.53800","2.71169","0.00358"
"32.71200","2.72616","0.00364"
"32.88600","2.74069","0.00336"
"33.06000","2.75516","0.00376"
"33.23400","2.76969","0.00309"
"33.40800","2.78416","0.00406"
"33.58200","2.79869","0.00314"
"33.75600","2.81322","0.00347"
"33.93000","2.82769","0.00411"
"34.10400","2.84216","0.00379"
"34.27800","2.85668","0.00338"
"34.45200","2.87115","0.00342"
"34.62600","2.88568","0.00407"
"34.80000","2.90015","0.00322"
"34.97400","2.91468","0.00364"
"35.14800","2.92915","0.00404"
"35.32200","2.94368","0.00409"
"35.49600","2.95821","0.00364"
"35.67000","2.97262","0.00432"
"35.84400","2.98714","0.00429"
"36.01800","3.00173","0.00422"
"36.19200","3.01620","0.00407"
"36.36600","3.03073","0.00409"
"36.54000","3.04514","0.00375"
"36.71400","3.05961","0.00398"
"36.88800","3.07420","0.00463"
"37.06200","3.08873","0.00442"
"37.23600","3.10314","0.00436"
"37.41000","3.11773","0.00454"
"37.58400","3.13219","0.00453"
"37.75800","3.14666","0.00393"
"37.93200","3.16125","0.00447"
"38.10600","3.17566","0.00441"
"38.28000","3.19019","0.00500"
"38.45400","3.20466","0.00438"
"38.62800","3.21919","0.00459"
"38.80200","3.23366","0.00499"
"38.97600","3.24819","0.00467"
"39.15000","3.26271","0.00442"
"39.32400","3.27712","0.00440"
"39.49800","3.29171","0.00474"
"39.67200","3.30624","0.00453"
"39.84600","3.32065","0.00405"
"40.02000","3.33512","0.00456"
"40.19400","3.34977","0.00425"
"40.36800","3.36418","0.00415"
"40.54200","3.37865","0.00420"
"40.71600","3.39312","0.00374"
"40.89000","3.40770","0.00394"
"41.06400","3.42217","0.00443"
"41.23800","3.43670","0.00423"
"41.41200","3.45117","0.00414"
"41.58600","3.46564","0.00438"
"41.76000","3.48023","0.00383"
"41.93400","3.49470","0.00402"
"42.10800","3.50917","0.00394"
"42.28200","3.52370","0.00444"
"42.45600","3.53817","0.00440"
"42.63000","3.55263","0.00435"
"42.80400","3.56722","0.00425"
"42.97800","3.58169","0.00465"
"43.15200","3.59610","0.00449"
"43.32600","3.61069","0.00513"
"43.50000","3.62522","0.00475"
"43.67400","3.63963","0.00455"
"43.84800","3.65416","0.00455"
"44.02200","3.66869","0.00470"
"44.19600","3.68315","0.00457"
"44.37000","3.69768","0.00473"
"44.54400","3.71221","0.00459"
"44.71800","3.72662","0.00502"
"44.89200","3.74121","0.00570"
"45.06600","3.75574","0.00562"
"45.24000","3.77021","0.00553"
"45.41400","3.78468","0.00541"
"45.58800","3.79921","0.00581"
"45.76200","3.81368","0.00500"
"45.93600","3.82820","0.00569"
"46.11000","3.84267","0.00572"
"46.28400","3.85720","0.00568"
"46.45800","3.87167","0.00547"
"46.63200","3.88620","0.00580"
"46.80600","3.90067","0.00574"
"46.98000","3.91514","0.00624"
"47.15400","3.92973","0.00578"
"47.32800","3.94414","0.00604"
"47.50200","3.95866","0.00639"
"47.67600","3.97319","0.00657"
"47.85000","3.98772","0.00653"
"48.02400","4.00213","0.00521"
"48.19800","4.01672","0.00500"
"48.37200","4.03125","0.00537"
"48.54600","4.04566","0.00503"
"48.72000","4.06019","0.00498"
"48.89400","4.07472","0.00541"
"49.06800","4.08913","0.00528"
"49.24200","4.10371","0.00538"
"49.41600","4.11824","0.00566"
"49.59000","4.13265","0.00645"
"49.76400","4.14718","0.00540"
"49.93800","4.16165","0.00570"
"50.11200","4.17612","0.00579"
"50.28600","4.19065","0.00624"
"50.46000","4.20524","0.00596"
"50.63400","4.21971","0.00633"
"50.80800","4.23418","0.00591"
"50.98200","4.24870","0.00603"
"51.15600","4.26317","0.00600"
"51.33000","4.27764","0.00639"
"51.50400","4.29217","0.00613"
"51.67800","4.30670","0.00617"
"51.85200","4.32117","0.00654"
"52.02600","4.33570","0.00666"
"52.20000","4.35011","0.00643"
"52.37400","4.36470","0.00591"
"52.54800","4.37922","0.00613"
"52.72200","4.39369","0.00657"
"52.89600","4.40816","0.00683"
"53.07000","4.42269","0.00668"
"53.24400","4.43722","0.00632"
"53.41800","4.45169","0.00647"
"53.59200","4.46622","0.00757"
"53.76600","4.48069","0.00695"
"53.94000","4.49516","0.00634"
"54.11400","4.50969","0.00672"
"54.28800","4.52421","0.00710"
"54.46200","4.53862","0.00705"
"54.63600","4.55321","0.00784"
"54.81000","4.56768","0.00760"
"54.98400","4.58215","0.00708"
"55.15800","4.59674","0.00738"
"55.33200","4.61127","0.00799"
"55.50600","4.62568","0.00724"
"55.68000","4.64021","0.00719"
"55.85400","4.65474","0.00800"
"56.02800","4.66914","0.00795"
"56.20200","4.68367","0.00857"
"56.37600","4.69820","0.00825"
"56.55000","4.71267","0.00823"
"56.72400","4.72720","0.00809"
"56.89800","4.74167","0.00818"
"57.07200","4.75614","0.00866"
"57.24600","4.77067","0.00868"
"57.42000","4.78526","0.00834"
"57.59400","4.79972","0.00834"
"57.76800","4.81419","0.00868"
"57.94200","4.82866","0.00805"
"58.11600","4.84319","0.00861"
"58.29000","4.85766","0.00938"
"58.46400","4.87225","0.00943"
"58.63800","4.88672","0.00921"
"58.81200","4.90113","0.00880"
"58.98600","4.91572","0.00943"
"59.16000","4.93018","0.00888"
"59.33400","4.94459","0.00935"
"59.50800","4.95918","0.00958"
"59.68200","4.97365","0.00890"
"59.85600","4.98818","0.00957"
"60.03000","5.00277","0.00989"
"60.20400","5.01718","0.00921"
"60.37800","5.03165","0.01065"
"60.55200","5.04618","0.01010"
"60.72600","5.06071","0.00966"
"60.90000","5.07517","0.00999"
"61.07400","5.08970","0.01030"
"61.24800","5.10417","0.01003"
"61.42200","5.11864","0.00973"
"61.59600","5.13323","0.01064"
"61.77000","5.14770","0.01074"
"61.94400","5.16217","0.01036"
"62.11800","5.17670","0.01209"
"62.29200","5.19123","0.01120"
"62.46600","5.20564","0.01182"
"62.64000","5.22016","0.01216"
"62.81400","5.23469","0.01151"
"62.98800","5.24922","0.01118"
"63.16200","5.26369","0.01177"
"63.33600","5.27822","0.01210"
"63.51000","5.29269","0.01200"
"63.68400","5.30716","0.01203"
"63.85800","5.32169","0.01191"
"64.03200","5.33622","0.01265"
"64.20600","5.35069","0.01214"
"64.38000","5.36515","0.01296"
"64.55400","5.37962","0.01281"
"64.72800","5.39415","0.01264"
"64.90200","5.40868","0.01292"
"65.07600","5.42321","0.01311"
"65.25000","5.43768","0.01312"
"65.42400","5.45221","0.01350"
"65.59800","5.46674","0.01370"
"65.77200","5.48115","0.01439"
"65.94600","5.49573","0.01376"
"66.12000","5.51026","0.01490"
"66.29400","5.52467","0.01485"
"66.46800","5.53920","0.01517"
"66.64200","5.55373","0.01479"
"66.81600","5.56814","0.01545"
"66.99000","5.58273","0.01571"
"67.16400","5.59720","0.01574"
"67.33800","5.61167","0.01632"
"67.51200","5.62619","0.01580"
"67.68600","5.64072","0.01607"
"67.86000","5.65519","0.01704"
"68.03400","5.66972","0.01628"
"68.20800","5.68419","0.01686"
"68.38200","5.69872","0.01631"
"68.55600","5.71319","0.01767"
"68.73000","5.72766","0.01691"
"68.90400","5.74219","0.01802"
"69.07800","5.75666","0.01777"
"69.25200","5.77118","0.01750"
"69.42600","5.78565","0.01817"
"69.60000","5.80018","0.01848"
"69.77400","5.81471","0.01791"
"69.94800","5.82918","0.01883"
"70.12200","5.84365","0.01882"
"70.29600","5.85818","0.01853"
"70.47000","5.87271","0.01867"
"70.64400","5.88718","0.01900"
"70.81800","5.90170","0.02033"
"70.99200","5.91617","0.01985"
"71.16600","5.93064","0.01974"
"71.34000","5.94517","0.02036"
"71.51400","5.95970","0.02036"
"71.68800","5.97411","0.02117"
"71.86200","5.98870","0.02143"
"72.03600","6.00323","0.02101"
"72.21000","6.01764","0.02158"
"72.38400","6.03223","0.02129"
"72.55800","6.04670","0.02259"
"72.73200","6.06116","0.02259"
"72.90600","6.07569","0.02205"
"73.08000","6.09022","0.02203"
"73.25400","6.10469","0.02296"
"73.42800","6.11916","0.02356"
"73.60200","6.13375","0.02324"
"73.77600","6.14816","0.02306"
"73.95000","6.16269","0.02444"
"74.12400","6.17722","0.02397"
"74.29800","6.19168","0.02447"
"74.47200","6.20615","0.02433"
"74.64600","6.22068","0.02513"
"74.82000","6.23515","0.02499"
"74.99400","6.24974","0.02514"
"75.16800","6.26421","0.02553"
"75.34200","6.27868","0.02559"
"75.51600","6.29321","0.02609"
"75.69000","6.30768","0.02676"
"75.86400","6.32220","0.02650"
"76.03800","6.33661","0.02644"
"76.21200","6.35120","0.02701"
"76.38600","6.36573","0.02724"
"76.56000","6.38014","0.02766"
"76.73400","6.39467","0.02729"
"76.90800","6.40920","0.02840"
"77.08200","6.42367","0.02810"
"77.25600","6.43820","0.02873"
"77.43000","6.45267","0.02855"
"77.60400","6.46708","0.02947"
"77.77800","6.48172","0.02932"
"77.95200","6.49619","0.02934"
"78.12600","6.51066","0.03001"
"78.30000","6.52525","0.02950"
"78.47400","6.53972","0.03031"
"78.64800","6.55413","0.03021"
"78.82200","6.56872","0.03012"
"78.99600","6.58325","0.03095"
"79.17000","6.59766","0.03088"
"79.34400","6.61218","0.03116"
"79.51800","6.62671","0.03125"
"79.69200","6.64112","0.03191"
"79.86600","6.65565","0.03127"
"80.04000","6.67018","0.03216"
"80.21400","6.68465","0.03210"
"80.38800","6.69924","0.03220"
"80.56200","6.71371","0.03234"
"80.73600","6.72818","0.03232"
"80.91000","6.74265","0.03302"
"81.08400","6.75723","0.03327"
"81.25800","6.77170","0.03342"
"81.43200","6.78617","0.03269"
"81.60600","6.80064","0.03219"
"81.78000","6.81511","0.03154"
"81.95400","6.82964","0.03143"
"82.12800","6.84417","0.03036"
"82.30200","6.85870","0.02921"
"82.47600","6.87317","0.03000"
"82.65000","6.88769","0.02953"
"82.82400","6.90222","0.02968"
"82.99800","6.91669","0.02995"
"83.17200","6.93122","0.03020"
"83.34600","6.94569","0.03030"
"83.52000","6.96016","0.03063"
"83.69400","6.97469","0.03113"
"83.86800","6.98922","0.02942"
"84.04200","7.00363","0.03016"
"84.21600","7.01816","0.02980"
"84.39000","7.03268","0.03042"
"84.56400","7.04715","0.03023"
"84.73800","7.06168","0.03044"
"84.91200","7.07615","0.03080"
"85.08600","7.09068","0.03114"
"85.26000","7.10521","0.03086"
"85.43400","7.11974","0.03132"
"85.60800","7.13415","0.03203"
"85.78200","7.14868","0.03198"
"85.95600","7.16320","0.03186"
"86.13000","7.17767","0.03169"
"86.30400","7.19220","0.03178"
"86.47800","7.20673","0.03242"
"86.65200","7.22114","0.03222"
"86.82600","7.23567","0.03280"
"87.00000","7.25020","0.03287"
"87.17400","7.26467","0.03311"
"87.34800","7.27914","0.03303"
"87.52200","7.29367","0.03306"
"87.69600","7.30819","0.03367"
"87.87000","7.32266","0.03390"
"88.04400","7.33719","0.03361"
"88.21800","7.35166","0.03424"
"88.39200","7.36613","0.03424"
"88.56600","7.38078","0.03521"
"88.74000","7.39525","0.03499"
"88.91400","7.40960","0.03533"
"89.08800","7.42425","0.03510"
"89.26200","7.43871","0.03532"
"89.43600","7.45312","0.03544"
"89.61000","7.46771","0.03526"
"89.78400","7.48218","0.03566"
"89.95800","7.49665","0.03567"
"90.13200","7.51118","0.03591"
"90.30600","7.52565","0.03676"
"90.48000","7.54012","0.03688"
"90.65400","7.55465","0.03711"
"90.82800","7.56924","0.03662"
"91.00200","7.58365","0.03758"
"91.17600","7.59823","0.03770"
"91.35000","7.61270","0.03761"
"91.52400","7.62717","0.03815"
"91.69800","7.64170","0.03850"
"91.87200","7.65623","0.03933"
"92.04600","7.67070","0.03867"
"92.22000","7.68517","0.03845"
"92.39400","7.69964","0.03920"
"92.56800","7.71417","0.03965"
"92.74200","7.72869","0.03950"
"92.91600","7.74316","0.03974"
"93.09000","7.75763","0.04002"
"93.26400","7.77216","0.04008"
"93.43800","7.78675","0.04049"
"93.61200","7.80122","0.04141"
"93.78600","7.81569","0.04138"
"93.96000","7.83028","0.04176"
"94.13400","7.84469","0.04216"
"94.30800","7.85915","0.04197"
"94.48200","7.87374","0.04272"
"94.65600","7.88815","0.04235"
"94.83000","7.90262","0.04271"
"95.00400","7.91721","0.04289"
"95.17800","7.93168","0.04373"
"95.35200","7.94615","0.04389"
"95.52600","7.96068","0.04389"
"95.70000","7.97521","0.04423"
"95.87400","7.98962","0.04487"
"96.04800","8.00420","0.04567"
"96.22200","8.01867","0.04468"
"96.39600","8.03314","0.04603"
"96.57000","8.04773","0.04602"
"96.74400","8.06220","0.04610"
"96.91800","8.07661","0.04627"
"97.09200","8.09120","0.04658"
"97.26600","8.10567","0.04660"
"97.44000","8.12014","0.04712"
"97.61400","8.13472","0.04751"
"97.78800","8.14919","0.04772"
"97.96200","8.16372","0.04790"
"98.13600","8.17819","0.04851"
"98.31000","8.19272","0.04841"
"98.48400","8.20719","0.04850"
"98.65800","8.22166","0.04882"
"98.83200","8.23619","0.04904"
"99.00600","8.25066","0.04904"
"99.18000","8.26519","0.04995"
"99.35400","8.27971","0.04991"
"99.52800","8.29418","0.04998"
"99.70200","8.30859","0.05013"
"99.87600","8.32318","0.05115"
"100.05000","8.33771","0.05088"
"100.22400","8.35212","0.05148"
"100.39800","8.36671","0.05153"
"100.57200","8.38118","0.05182"
"100.74600","8.39565","0.05208"
"100.92000","8.41024","0.05221"
"101.09400","8.42470","0.05236"
"101.26800","8.43911","0.05304"
"101.44200","8.45370","0.05300"
"101.61600","8.46823","0.05379"
"101.79000","8.48270","0.05319"
"101.96400","8.49723","0.05392"
"102.13800","8.51170","0.05413"
"102.31200","8.52617","0.05423"
"102.48600","8.54070","0.05427"
"102.66000","8.55516","0.05510"
"102.83400","8.56963","0.05454"
"103.00800","8.58416","0.05541"
"103.18200","8.59869","0.05515"
"103.35600","8.61316","0.05516"
"103.53000","8.62769","0.05565"
"103.70400","8.64222","0.05562"
"103.87800","8.65663","0.05568"
"104.05200","8.67122","0.05593"
"104.22600","8.68575","0.05619"
"104.40000","8.70009","0.05686"
"104.57400","8.71468","0.05696"
"104.74800","8.72921","0.05700"
"104.92200","8.74374","0.05713"
"105.09600","8.75815","0.05776"
"105.27000","8.77268","0.05771"
"105.44400","8.78715","0.05723"
"105.61800","8.80162","0.05793"
"105.79200","8.81621","0.05841"
"105.96600","8.83073","0.05847"
"106.14000","8.84514","0.05851"
"106.31400","8.85973","0.05884"
"106.48800","8.87420","0.05886"
"106.66200","8.88867","0.05883"
"106.83600","8.90326","0.05954"
"107.01000","8.91773","0.05923"
"107.18400","8.93214","0.05931"
"107.35800","8.94667","0.05967"
"107.53200","8.96119","0.05997"
"107.70600","8.97561","0.05993"
"107.88000","8.99013","0.05995"
"108.05400","9.00472","0.06028"
"108.22800","9.01919","0.06027"
"108.40200","9.03366","0.06058"
"108.57600","9.04819","0.06039"
"108.75000","9.06266","0.06055"
"108.92400","9.07725","0.06080"
"109.09800","9.09172","0.06097"
"109.27200","9.10613","0.06126"
"109.44600","9.12071","0.06103"
"109.62000","9.13518","0.06146"
"109.79400","9.14965","0.06157"
"109.96800","9.16424","0.06199"
"110.14200","9.17865","0.06152"
"110.31600","9.19318","0.06182"
"110.49000","9.20765","0.06192"
"110.66400","9.22224","0.05671"
"110.83800","9.23671","0.05524"
"111.01200","9.25117","0.05584"
"111.18600","9.26570","0.05586"
"111.36000","9.28023","0.05609"
"111.53400","9.29470","0.05636"
"111.70800","9.30923","0.05637"
"111.88200","9.32364","0.05661"
"112.05600","9.33811","0.05739"
"112.23000","9.35270","0.05776"
"112.40400","9.36717","0.05754"
"112.57800","9.38163","0.05822"
"112.75200","9.39616","0.05798"
"112.92600","9.41075","0.05828"
"113.10000","9.42516","0.05909"
"113.27400","9.43975","0.05930"
"113.44800","9.45422","0.05941"
"113.62200","9.46863","0.05972"
"113.79600","9.48322","0.05969"
"113.97000","9.49769","0.05996"
"114.14400","9.51216","0.06001"
"114.31800","9.52668","0.06065"
"114.49200","9.54121","0.06063"
"114.66600","9.55568","0.06080"
"114.84000","9.57015","0.06041"
"115.01400","9.58468","0.06129"
"115.18800","9.59915","0.06101"
"115.36200","9.61368","0.06151"
"115.53600","9.62821","0.06168"
"115.71000","9.64268","0.06147"
"115.88400","9.65715","0.06174"
"116.05800","9.67167","0.06182"
"116.23200","9.68614","0.06227"
"116.40600","9.70067","0.06234"
"116.58000","9.71520","0.06257"
"116.75400","9.72967","0.06250"
"116.92800","9.74414","0.06305"
"117.10200","9.75873","0.06341"
"117.27600","9.77320","0.06326"
"117.45000","9.78767","0.06313"
"117.62400","9.80219","0.06360"
"117.79800","9.81666","0.06382"
"117.97200","9.83119","0.06379"
"118.14600","9.84572","0.06403"
"118.32000","9.86019","0.06419"
"118.49400","9.87466","0.06479"
"118.66800","9.88919","0.06487"
"118.84200","9.90372","0.06443"
"119.01600","9.91819","0.06517"
"119.19000","9.93271","0.06557"
"119.36400","9.94718","0.06570"
"119.53800","9.96171","0.06589"
"119.71200","9.97618","0.06622"
"119.88600","9.99071","0.06661"
"120.06000","10.00518","0.06657"
"120.23400","10.01965","0.06708"
"120.40800","10.03418","0.06722"
"120.58200","10.04865","0.06755"
"120.75600","10.06324","0.06769"
"120.93000","10.07771","0.06837"
"121.10400","10.09217","0.06805"
"121.27800","10.10670","0.06881"
"121.45200","10.12117","0.06915"
"121.62600","10.13564","0.06946"
"121.80000","10.15017","0.06990"
"121.97400","10.16470","0.07065"
"122.14800","10.17917","0.07000"
"122.32200","10.19364","0.07075"
"122.49600","10.20823","0.07101"
"122.67000","10.22269","0.07198"
"122.84400","10.23716","0.07235"
"123.01800","10.25169","0.07246"
"123.19200","10.26616","0.07326"
"123.36600","10.28057","0.07334"
"123.54000","10.29522","0.07371"
"123.71400","10.30975","0.07414"
"123.88800","10.32416","0.07525"
"124.06200","10.33875","0.07542"
"124.23600","10.35322","0.07583"
"124.41000","10.36768","0.07633"
"124.58400","10.38227","0.07728"
"124.75800","10.39674","0.07788"
"124.93200","10.41115","0.07835"
"125.10600","10.42568","0.07862"
"125.28000","10.44027","0.07926"
"125.45400","10.45468","0.08000"
"125.62800","10.46915","0.08029"
"125.80200","10.48374","0.08113"
"125.97600","10.49815","0.08151"
"126.15000","10.51267","0.08226"
"126.32400","10.52720","0.08280"
"126.49800","10.54161","0.08354"
"126.67200","10.55620","0.08409"
"126.84600","10.57067","0.08422"
"127.02000","10.58520","0.08519"
"127.19400","10.59967","0.08530"
"127.36800","10.61420","0.08625"
"127.54200","10.62872","0.08675"
"127.71600","10.64319","0.08690"
"127.89000","10.65766","0.08786"
"128.06400","10.67219","0.08895"
"128.23800","10.68666","0.08913"
"128.41200","10.70113","0.09007"
"128.58600","10.71566","0.09047"
"128.76000","10.73019","0.09084"
"128.93400","10.74466","0.09127"
"129.10800","10.75913","0.09232"
"129.28200","10.77360","0.09240"
"129.45600","10.78824","0.09276"
"129.63000","10.80271","0.09307"
"129.80400","10.81718","0.09341"
"129.97800","10.83171","0.09394"
"130.15200","10.84624","0.09544"
"130.32600","10.86065","0.09536"
"130.50000","10.87524","0.09631"
"130.67400","10.88971","0.09659"
"130.84800","10.90412","0.09710"
"131.02200","10.91876","0.09830"
"131.19600","10.93317","0.09816"
"131.37000","10.94764","0.09914"
"131.54400","10.96223","0.09989"
"131.71800","10.97670","0.10003"
"131.89200","10.99117","0.10041"
"132.06600","11.00570","0.10139"
"132.24000","11.02023","0.10200"
"132.41400","11.03464","0.10292"
"132.58800","11.04923","0.10362"
"132.76200","11.06369","0.10381"
"132.93600","11.07816","0.10422"
"133.11000","11.09263","0.10512"
"133.28400","11.10722","0.10580"
"133.45800","11.12163","0.10630"
"133.63200","11.13622","0.10675"
"133.80600","11.15069","0.10765"
"133.98000","11.16516","0.10806"
"134.15400","11.17969","0.10910"
"134.32800","11.19421","0.10918"
"134.50200","11.20868","0.11057"
"134.67600","11.22315","0.11095"
"134.85000","11.23768","0.11185"
"135.02400","11.25221","0.11216"
"135.19800","11.26662","0.11227"
"135.37200","11.28121","0.11279"
"135.54600","11.29568","0.11294"
"135.72000","11.31009","0.11322"
"135.89400","11.32473","0.11357"
"136.06800","11.33921","0.11390"
"136.24200","11.35367","0.11387"
"136.41600","11.36820","0.11399"
"136.59000","11.38267","0.11411"
"136.76400","11.39720","0.11453"
"136.93800","11.41173","0.11461"
"137.11200","11.42620","0.11453"
"137.28600","11.44067","0.11484"
"137.46000","11.45520","0.11495"
"137.63400","11.46973","0.11508"
"137.80800","11.48419","0.11550"
"137.98200","11.49872","0.11539"
"138.15600","11.51319","0.11592"
"138.33000","11.52766","0.11575"
"138.50400","11.54219","0.11583"
"138.67800","11.55672","0.11624"
"138.85200","11.57113","0.11486"
"139.02600","11.58566","0.10859"
"139.20000","11.60019","0.10983"
"139.37400","11.61471","0.10972"
"139.54800","11.62918","0.11095"
"139.72200","11.64371","0.11113"
"139.89600","11.65818","0.11138"
"140.07000","11.67271","0.11228"
"140.24400","11.68724","0.11248"
"140.41800","11.70165","0.11330"
"140.59200","11.71606","0.11315"
"140.76600","11.73071","0.11369"
"140.94000","11.74523","0.11399"
"141.11400","11.75964","0.11405"
"141.28800","11.77417","0.11439"
"141.46200","11.78864","0.11460"
"141.63600","11.80317","0.11479"
"141.81000","11.81770","0.11503"
"141.98400","11.83217","0.11508"
"142.15800","11.84664","0.11550"
"142.33200","11.86117","0.11526"
"142.50600","11.87576","0.11521"
"142.68000","11.89017","0.11455"
"142.85400","11.90475","0.11401"
"143.02800","11.91922","0.10952"
"143.20200","11.93363","0.07141"
"143.37600","11.94816","0.07030"
"143.55000","11.96269","0.07125"
"143.72400","11.97716","0.07228"
"143.89800","11.99163","0.07376"
"144.07200","12.00622","0.07328"
"144.24600","12.02069","0.07358"
"144.42000","12.03515","0.06683"
"144.59400","12.04974","0.06626"
"144.76800","12.06415","0.06558"
"144.94200","12.07868","0.06598"
"145.11600","12.09321","0.06565"
"145.29000","12.10768","0.06436"
"145.46400","12.12215","0.06414"
"145.63800","12.13668","0.06348"
"145.81200","12.15121","0.06358"
"145.98600","12.16568","0.06332"
"146.16000","12.18020","0.06407"
"146.33400","12.19461","0.06388"
"146.50800","12.20914","0.06400"
"146.68200","12.22373","0.06423"
"146.85600","12.23814","0.06469"
"147.03000","12.25267","0.06444"
"147.20400","12.26720","0.06450"
"147.37800","12.28167","0.06471"
"147.55200","12.29614","0.06489"
"147.72600","12.31072","0.06485"
"147.90000","12.32519","0.06514"
"148.07400","12.33960","0.06523"
"148.24800","12.35425","0.06528"
"148.42200","12.36866","0.06607"
"148.59600","12.38313","0.06623"
"148.77000","12.39766","0.06642"
"148.94400","12.41219","0.06628"
"149.11800","12.42666","0.06646"
"149.29200","12.44118","0.06688"
"149.46600","12.45571","0.06700"
"149.64000","12.47012","0.06674"
"149.81400","12.48471","0.06696"
"149.98800","12.49924","0.06650"
"150.16200","12.51371","0.06694"
"150.33600","12.52818","0.06701"
"150.51000","12.54271","0.06634"
"150.68400","12.55718","0.06701"
"150.85800","12.57165","0.06621"
"151.03200","12.58623","0.06653"
"151.20600","12.60070","0.06615"
"151.38000","12.61517","0.06580"
"151.55400","12.62970","0.06582"
"151.72800","12.64423","0.06567"
"151.90200","12.65864","0.06468"
"152.07600","12.67317","0.06333"
"152.25000","12.68770","0.04990"
"152.42400","12.70223","0.04728"
"152.59800","12.71670","0.05085"
"152.77200","12.73117","0.05159"
"152.94600","12.74563","0.05277"
"153.12000","12.76022","0.05342"
"153.29400","12.77475","0.05377"
"153.46800","12.78916","0.05449"
"153.64200","12.80369","0.05589"
"153.81600","12.81816","0.05583"
"153.99000","12.83263","0.05609"
"154.16400","12.84722","0.05694"
"154.33800","12.86169","0.05752"
"154.51200","12.87615","0.05797"
"154.68600","12.89068","0.05867"
"154.86000","12.90515","0.05905"
"155.03400","12.91968","0.05959"
"155.20800","12.93415","0.05998"
"155.38200","12.94868","0.06024"
"155.55600","12.96315","0.06093"
"155.73000","12.97768","0.06144"
"155.90400","12.99221","0.06139"
"156.07800","13.00667","0.06181"
"156.25200","13.02120","0.06222"
"156.42600","13.03573","0.06251"
"156.60000","13.05020","0.06294"
"156.77400","13.06467","0.06335"
"156.94800","13.07914","0.06352"
"157.12200","13.09367","0.06364"
"157.29600","13.10820","0.06393"
"157.47000","13.12273","0.06448"
"157.64400","13.13720","0.06478"
"157.81800","13.15161","0.06501"
"157.99200","13.16619","0.06571"
"158.16600","13.18072","0.06639"
"158.34000","13.19513","0.06652"
"158.51400","13.20972","0.06702"
"158.68800","13.22413","0.06793"
"158.86200","13.23866","0.06815"
"159.03600","13.25325","0.06861"
"159.21000","13.26772","0.06947"
"159.38400","13.28213","0.07082"
"159.55800","13.29665","0.07124"
"159.73200","13.31124","0.07171"
"159.90600","13.32559","0.07302"
"160.08000","13.34018","0.07344"
"160.25400","13.35471","0.07432"
"160.42800","13.36918","0.07564"
"160.60200","13.38371","0.07590"
"160.77600","13.39824","0.07722"
"160.95000","13.41265","0.07817"
"161.12400","13.42718","0.07884"
"161.29800","13.44170","0.08004"
"161.47200","13.45617","0.08074"
"161.64600","13.47070","0.08147"
"161.82000","13.48517","0.08260"
"161.99400","13.49970","0.08361"
"162.16800","13.51417","0.08417"
"162.34200","13.52870","0.08572"
"162.51600","13.54323","0.08605"
"162.69000","13.55770","0.08770"
"162.86400","13.57222","0.08848"
"163.03800","13.58675","0.08915"
"163.21200","13.60116","0.09028"
"163.38600","13.61569","0.09076"
"163.56000","13.63010","0.09184"
"163.73400","13.64469","0.09294"
"163.90800","13.65922","0.09336"
"164.08200","13.67369","0.09461"
"164.25600","13.68816","0.09517"
"164.43000","13.70268","0.09612"
"164.60400","13.71721","0.09713"
"164.77800","13.73162","0.09700"
"164.95200","13.74621","0.09901"
"165.12600","13.76068","0.09953"
"165.30000","13.77515","0.09997"
"165.47400","13.78974","0.10101"
"165.64800","13.80421","0.10174"
"165.82200","13.81862","0.10343"
"165.99600","13.83321","0.10518"
"166.17000","13.84773","0.10592"
"166.34400","13.86214","0.10782"
"166.51800","13.87667","0.10812"
"166.69200","13.89114","0.10871"
"166.86600","13.90561","0.10966"
"167.04000","13.92020","0.11033"
"167.21400","13.93473","0.11083"
"167.38800","13.94920","0.11173"
"167.56200","13.96367","0.11242"
"167.73600","13.97826","0.11283"
"167.91000","13.99266","0.11312"
"168.08400","14.00719","0.11356"
"168.25800","14.02166","0.11370"
"168.43200","14.03619","0.11424"
"168.60600","14.05066","0.11437"
"168.78000","14.06519","0.11448"
"168.95400","14.07972","0.11474"
"169.12800","14.09413","0.11493"
"169.30200","14.10866","0.11497"
"169.47600","14.12319","0.11530"
"169.65000","14.13771","0.11550"
"169.82400","14.15218","0.11600"
"169.99800","14.16665","0.11633"
"170.17200","14.18112","0.11688"
"170.34600","14.19577","0.11729"
"170.52000","14.21018","0.11823"
"170.69400","14.22465","0.11889"
"170.86800","14.23918","0.11979"
"171.04200","14.25364","0.12005"
"171.21600","14.26811","0.12159"
"171.39000","14.28264","0.12272"
"171.56400","14.29723","0.12336"
"171.73800","14.31164","0.12396"
"171.91200","14.32617","0.12532"
"172.08600","14.34070","0.12616"
"172.26000","14.35511","0.12704"
"172.43400","14.36970","0.12837"
"172.60800","14.38417","0.12972"
"172.78200","14.39869","0.13186"
"172.95600","14.41317","0.13235"
"173.13000","14.42769","0.13381"
"173.30400","14.44216","0.13454"
"173.47800","14.45669","0.13611"
"173.65200","14.47122","0.13715"
"173.82600","14.48569","0.13808"
"174.00000","14.50016","0.13899"
"174.17400","14.51469","0.13974"
"174.34800","14.52916","0.14102"
"174.52200","14.54368","0.14152"
"174.69600","14.55821","0.14235"
"174.87000","14.57268","0.14313"
"175.04400","14.58715","0.14389"
"175.21800","14.60174","0.14469"
"175.39200","14.61621","0.14518"
"175.56600","14.63062","0.14614"
"175.74000","14.64527","0.14692"
"175.91400","14.65968","0.14732"
"176.08800","14.67421","0.14789"
"176.26200","14.68874","0.14848"
"176.43600","14.70314","0.14889"
"176.61000","14.71761","0.14910"
"176.78400","14.73220","0.14940"
"176.95800","14.74673","0.15008"
"177.13200","14.76114","0.15035"
"177.30600","14.77573","0.15103"
"177.48000","14.79020","0.15150"
"177.65400","14.80467","0.15171"
"177.82800","14.81920","0.15184"
"178.00200","14.83372","0.15216"
"178.17600","14.84813","0.15252"
"178.35000","14.86266","0.15238"
"178.52400","14.87719","0.15216"
"178.69800","14.89166","0.15240"
"178.87200","14.90613","0.15252"
"179.04600","14.92072","0.15042"
"179.22000","14.93513","0.15108"
"179.39400","14.94966","0.15077"
"179.56800","14.96412","0.15108"
"179.74200","14.97865","0.15123"
"179.91600","14.99312","0.15165"
"180.09000","15.00771","0.15207"
"180.26400","15.02224","0.15296"
"180.43800","15.03671","0.15308"
"180.61200","15.05118","0.15358"
"180.78600","15.06565","0.15362"
"180.96000","15.08018","0.15464"
"181.13400","15.09476","0.15505"
"181.30800","15.10917","0.15559"
"181.48200","15.12364","0.15618"
"181.65600","15.13817","0.15662"
"181.83000","15.15270","0.15709"
"182.00400","15.16717","0.15778"
"182.17800","15.18176","0.15829"
"182.35200","15.19617","0.15894"
"182.52600","15.21064","0.15972"
"182.70000","15.22528","0.16054"
"182.87400","15.23970","0.16117"
"183.04800","15.25416","0.16133"
"183.22200","15.26869","0.16173"
"183.39600","15.28322","0.16246"
"183.57000","15.29763","0.16273"
"183.74400","15.31222","0.16343"
"183.91800","15.32669","0.16388"
"184.09200","15.34116","0.16451"
"184.26600","15.35569","0.16499"
"184.44000","15.37022","0.16531"
"184.61400","15.38462","0.16604"
"184.78800","15.39915","0.16653"
"184.96200","15.41368","0.16736"
"185.13600","15.42815","0.16783"
"185.31000","15.44268","0.16859"
"185.48400","15.45715","0.16927"
"185.65800","15.47162","0.17030"
"185.83200","15.48621","0.17104"
"186.00600","15.50074","0.17193"
"186.18000","15.51515","0.17339"
"186.35400","15.52961","0.17415"
"186.52800","15.54414","0.17555"
"186.70200","15.55867","0.17700"
"186.87600","15.57314","0.17789"
"187.05000","15.58767","0.17934"
"187.22400","15.60220","0.18097"
"187.39800","15.61661","0.18172"
"187.57200","15.63126","0.18397"
"187.74600","15.64572","0.18635"
"187.92000","15.66013","0.18728"
"188.09400","15.67472","0.18915"
"188.26800","15.68919","0.19150"
"188.44200","15.70366","0.19370"
"188.61600","15.71819","0.19696"
"188.79000","15.73272","0.19773"
"188.96400","15.74719","0.20087"
"189.13800","15.76172","0.20287"
"189.31200","15.77619","0.20369"
"189.48600","15.79065","0.20564"
"189.66000","15.80518","0.20804"
"189.83400","15.81971","0.20871"
"190.00800","15.83418","0.21030"
"190.18200","15.84871","0.21101"
"190.35600","15.86318","0.21230"
"190.53000","15.87765","0.21368"
"190.70400","15.89224","0.21449"
"190.87800","15.90671","0.21541"
"191.05200","15.92118","0.21592"
"191.22600","15.93570","0.21643"
"191.40000","15.95017","0.21715"
"191.57400","15.96464","0.21727"
"191.74800","15.97923","0.21810"
"191.92200","15.99370","0.21823"
"192.09600","16.00817","0.21931"
"192.27000","16.02264","0.21964"
"192.44400","16.03717","0.22033"
"192.61800","16.05169","0.22079"
"192.79200","16.06616","0.22125"
"192.96600","16.08069","0.22149"
"193.14000","16.09516","0.22241"
"193.31400","16.10969","0.22379"
"193.48800","16.12422","0.22451"
"193.66200","16.13869","0.22534"
"193.83600","16.15310","0.22648"
"194.01000","16.16769","0.22773"
"194.18400","16.18222","0.22910"
"194.35800","16.19662","0.23086"
"194.53200","16.21121","0.23283"
"194.70600","16.22568","0.23375"
"194.88000","16.24015","0.23442"
"195.05400","16.25468","0.23661"
"195.22800","16.26927","0.23770"
"195.40200","16.28362","0.23835"
"195.57600","16.29821","0.23904"
"195.75000","16.31274","0.24054"
"195.92400","16.32715","0.24175"
"196.09800","16.34173","0.24285"
"196.27200","16.35620","0.24419"
"196.44600","16.37067","0.24578"
"196.62000","16.38514","0.24699"
"196.79400","16.39967","0.24830"
"196.96800","16.41414","0.24919"
"197.14200","16.42861","0.25116"
"197.31600","16.44320","0.25240"
"197.49000","16.45773","0.25356"
"197.66400","16.47214","0.19260"
"197.83800","16.48667","0.16822"
"198.01200","16.50113","0.16485"
"198.18600","16.51572","0.15821"
"198.36000","16.53019","0.15895"
"198.53400","16.54466","0.16071"
"198.70800","16.55913","0.16039"
"198.88200","16.57366","0.16347"
"199.05600","16.58819","0.16280"
"199.23000","16.60266","0.16467"
"199.40400","16.61718","0.16416"
"199.57800","16.63165","0.16542"
"199.75200","16.64612","0.16686"
"199.92600","16.66071","0.16673"
"200.10000","16.67518","0.16999"
"200.27400","16.68965","0.16901"
"200.44800","16.70418","0.17326"
"200.62200","16.71871","0.17221"
"200.79600","16.73318","0.17571"
"200.97000","16.74771","0.17634"
"201.14400","16.76223","0.17801"
"201.31800","16.77664","0.18282"
"201.49200","16.79123","0.18144"
"201.66600","16.80570","0.19046"
"201.84000","16.82011","0.18770"
"202.01400","16.83464","0.19448"
"202.18800","16.84923","0.19297"
"202.36200","16.86364","0.19735"
"202.53600","16.87817","0.19926"
"202.71000","16.89270","0.19976"
"202.88400","16.90717","0.20706"
"203.05800","16.92169","0.20594"
"203.23200","16.93622","0.21182"
"203.40600","16.95069","0.20987"
"203.58000","16.96516","0.21369"
"203.75400","16.97969","0.21338"
"203.92800","16.99422","0.21556"
"204.10200","17.00869","0.21570"
"204.27600","17.02316","0.21689"
"204.45000","17.03768","0.21791"
"204.62400","17.05215","0.21805"
"204.79800","17.06674","0.21938"
"204.97200","17.08121","0.21933"
"205.14600","17.09562","0.22123"
"205.32000","17.11015","0.22038"
"205.49400","17.12468","0.22243"
"205.66800","17.13921","0.22204"
"205.84200","17.15368","0.22432"
"206.01600","17.16821","0.22526"
"206.19000","17.18267","0.22586"
"206.36400","17.19726","0.22862"
"206.53800","17.21173","0.22916"
"206.71200","17.22614","0.23330"
"206.88600","17.24067","0.23314"
"207.06000","17.25520","0.23657"
"207.23400","17.26967","0.23733"
"207.40800","17.28420","0.24010"
"207.58200","17.29873","0.24035"
"207.75600","17.31314","0.24326"
"207.93000","17.32772","0.24195"
"208.10400","17.34219","0.24469"
"208.27800","17.35666","0.24451"
"208.45200","17.37119","0.24690"
"208.62600","17.38566","0.24820"
"208.80000","17.40019","0.24930"
"208.97400","17.41472","0.25092"
"209.14800","17.42919","0.25164"
"209.32200","17.44366","0.25327"
"209.49600","17.45812","0.25360"
"209.67000","17.47271","0.25578"
"209.84400","17.48718","0.25596"
"210.01800","17.50159","0.25711"
"210.19200","17.51624","0.25700"
"210.36600","17.53071","0.25878"
"210.54000","17.54518","0.25884"
"210.71400","17.55977","0.26027"
"210.88800","17.57418","0.26006"
"211.06200","17.58865","0.26132"
"211.23600","17.60317","0.26110"
"211.41000","17.61770","0.26198"
"211.58400","17.63217","0.26213"
"211.75800","17.64670","0.26266"
"211.93200","17.66123","0.26291"
"212.10600","17.67564","0.26339"
"212.28000","17.69017","0.26356"
"212.45400","17.70470","0.26380"
"212.62800","17.71911","0.26395"
"212.80200","17.73369","0.26433"
"212.97600","17.74822","0.26459"
"213.15000","17.76269","0.26491"
"213.32400","17.77716","0.26519"
"213.49800","17.79169","0.26548"
"213.67200","17.80622","0.26567"
"213.84600","17.82069","0.26607"
"214.02000","17.83522","0.26645"
"214.19400","17.84969","0.26670"
"214.36800","17.86416","0.26721"
"214.54200","17.87874","0.26750"
"214.71600","17.89321","0.26802"
"214.89000","17.90768","0.26828"
"215.06400","17.92215","0.26910"
"215.23800","17.93662","0.26936"
"215.41200","17.95115","0.27059"
"215.58600","17.96568","0.27085"
"215.76000","17.98015","0.27194"
"215.93400","17.99468","0.27186"
"216.10800","18.00920","0.27366"
"216.28200","18.02374","0.27405"
"216.45600","18.03814","0.27594"
"216.63000","18.05273","0.27624"
"216.80400","18.06720","0.27800"
"216.97800","18.08161","0.27883"
"217.15200","18.09626","0.28071"
"217.32600","18.11067","0.28185"
"217.50000","18.12508","0.28380"
"217.67400","18.13972","0.28398"
"217.84800","18.15419","0.28608"
"218.02200","18.16866","0.28635"
"218.19600","18.18319","0.28819"
"218.37000","18.19766","0.28851"
"218.54400","18.21219","0.29064"
"218.71800","18.22672","0.28995"
"218.89200","18.24119","0.29246"
"219.06600","18.25572","0.29340"
"219.24000","18.27019","0.29426"
"219.41400","18.28472","0.29579"
"219.58800","18.29913","0.29721"
"219.76200","18.31365","0.29752"
"219.93600","18.32818","0.30014"
"220.11000","18.34265","0.30095"
"220.28400","18.35718","0.30292"
"220.45800","18.37171","0.30323"
"220.63200","18.38618","0.30513"
"220.80600","18.40065","0.30575"
"220.98000","18.41517","0.30743"
"221.15400","18.42971","0.30784"
"221.32800","18.44418","0.30852"
"221.50200","18.45864","0.30953"
"221.67600","18.47317","0.31048"
"221.85000","18.48764","0.31044"
"222.02400","18.50223","0.31132"
"222.19800","18.51664","0.31161"
"222.37200","18.53111","0.31214"
"222.54600","18.54564","0.31278"
"222.72000","18.56017","0.31336"
"222.89400","18.57463","0.31429"
"223.06800","18.58922","0.31501"
"223.24200","18.60369","0.31485"
"223.41600","18.61816","0.31543"
"223.59000","18.63275","0.31598"
"223.76400","18.64722","0.31586"
"223.93800","18.66163","0.31701"
"224.11200","18.67616","0.31668"
"224.28600","18.69075","0.31567"
"224.46000","18.70516","0.31576"
"224.63400","18.71968","0.31606"
"224.80800","18.73421","0.31674"
"224.98200","18.74862","0.31690"
"225.15600","18.76321","0.31821"
"225.33000","18.77768","0.31850"
"225.50400","18.79215","0.32051"
"225.67800","18.80668","0.32157"
"225.85200","18.82115","0.32336"
"226.02600","18.83568","0.32485"
"226.20000","18.85021","0.32604"
"226.37400","18.86467","0.32775"
"226.54800","18.87914","0.32865"
"226.72200","18.89367","0.33039"
"226.89600","18.90820","0.33140"
"227.07000","18.92273","0.33407"
"227.24400","18.93714","0.33365"
"227.41800","18.95167","0.33635"
"227.59200","18.96620","0.33664"
"227.76600","18.98067","0.33726"
"227.94000","18.99519","0.33755"
"228.11400","19.00966","0.34001"
"228.28800","19.02413","0.33936"
"228.46200","19.03872","0.34124"
"228.63600","19.05319","0.34038"
"228.81000","19.06766","0.34191"
"228.98400","19.08225","0.34133"
"229.15800","19.09672","0.34231"
"229.33200","19.11119","0.34210"
"229.50600","19.12572","0.34266"
"229.68000","19.14018","0.34119"
"229.85400","19.15465","0.33997"
"230.02800","19.16918","0.33861"
"230.20200","19.18371","0.33603"
"230.37600","19.19812","0.33436"
"230.55000","19.21265","0.33244"
"230.72400","19.22718","0.32802"
"230.89800","19.24165","0.32267"
"231.07200","19.25618","0.31572"
"231.24600","19.27065","-0.02987"
"231.42000","19.28517","-0.00265"
"231.59400","19.29970","0.00219"
"231.76800","19.31423","0.00211"
"231.94200","19.32870","-0.00143"
"232.11600","19.34317","-0.00237"
"232.29000","19.35770","-0.00116"
"232.46400","19.37217","-0.00078"
"232.63800","19.38664","-0.00099"
"232.81200","19.40123","-0.00099"
"232.98600","19.41563","-0.00096"
"233.16000","19.43016","-0.00056"
"233.33400","19.44469","-0.00061"
"233.50800","19.45922","-0.00093"
"233.68200","19.47369","-0.00045"
"233.85600","19.48816","-0.00074"
"234.03000","19.50269","-0.00103"
"234.20400","19.51716","-0.00098"
"234.37800","19.53175","-0.00063"
"234.55200","19.54615","-0.00064"
"234.72600","19.56062","-0.00125"
"234.90000","19.57515","-0.00094"
"235.07400","19.58968","-0.00042"
"235.24800","19.60409","-0.00095"
"235.42200","19.61868","-0.00063"
"235.59600","19.63321","-0.00063"
"235.77000","19.64768","-0.00127"
"235.94400","19.66220","-0.00135"
"236.11800","19.67673","-0.00093"
"236.29200","19.69120","-0.00070"
"236.46600","19.70567","-0.00061"
"236.64000","19.72020","-0.00075"
"236.81400","19.73467","-0.00091"
"236.98800","19.74920","-0.00109"
"237.16200","19.76367","-0.00116"
"237.33600","19.77814","-0.00096"
"237.51000","19.79273","-0.00071"
"237.68400","19.80720","-0.00092"
"237.85800","19.82167","-0.00103"
"238.03200","19.83614","-0.00049"
"238.20600","19.85066","-0.00120"
"238.38000","19.86519","-0.00081"
"238.55400","19.87966","-0.00117"
"238.72800","19.89413","-0.00074"
"238.90200","19.90866","-0.00084"
"239.07600","19.92319","-0.00141"
"239.25000","19.93772","-0.00093"
"239.42400","19.95218","-0.00090"
"239.59800","19.96659","-0.00061"
"239.77200","19.98118","-0.00071"
"239.94600","19.99565","-0.00085"
"240.12000","20.01012","-0.00105"
"240.29400","20.02471","-0.00090"
"240.46800","20.03918","-0.00117"
"240.64200","20.05365","-0.00101"
"240.81600","20.06824","-0.00075"
"240.99000","20.08271","-0.00036"
"241.16400","20.09711","-0.00073"
"241.33800","20.11164","-0.00086"
"241.51200","20.12617","-0.00117"
"241.68600","20.14064","-0.00085"
"241.86000","20.15523","-0.00093"
"242.03400","20.16970","-0.00138"
"242.20800","20.18417","-0.00095"
"242.38200","20.19876","-0.00060"
"242.55600","20.21323","-0.00094"
"242.73000","20.22764","-0.00082"
"242.90400","20.24217","-0.00074"
"243.07800","20.25669","-0.00087"
"243.25200","20.27116","-0.00125"
"243.42600","20.28569","-0.00090"
"243.60000","20.30022","-0.00085"
"243.77400","20.31469","-0.00090"
"243.94800","20.32916","-0.00119"
"244.12200","20.34369","-0.00131"
"244.29600","20.35822","-0.00111"
"244.47000","20.37263","-0.00124"
"244.64400","20.38721","-0.00084"
"244.81800","20.40174","-0.00110"
"244.99200","20.41621","-0.00080"
"245.16600","20.43068","-0.00068"
"245.34000","20.44515","-0.00075"
"245.51400","20.45962","-0.00055"
"245.68800","20.47421","-0.00115"
"245.86200","20.48868","-0.00112"
"246.03600","20.50309","-0.00105"
"246.21000","20.51767","-0.00054"
"246.38400","20.53220","-0.00078"
"246.55800","20.54667","-0.00083"
"246.73200","20.56120","-0.00113"
"246.90600","20.57573","-0.00081"
"247.08000","20.59014","-0.00123"
"247.25400","20.60473","-0.00091"
"247.42800","20.61920","-0.00112"
"247.60200","20.63367","-0.00114"
"247.77600","20.64820","-0.00090"
"247.95000","20.66267","-0.00103"
"248.12400","20.67713","-0.00095"
"248.29800","20.69172","-0.00110"
"248.47200","20.70619","-0.00118"
"248.64600","20.72066","-0.00071"
"248.82000","20.73519","-0.00147"
"248.99400","20.74972","-0.00120"
"249.16800","20.76419","-0.00047"
"249.34200","20.77866","-0.00102"
"249.51600","20.79318","-0.00051"
"249.69000","20.80766","-0.00081"
"249.86400","20.82224","-0.00112"
"250.03800","20.83665","-0.00044"
"250.21200","20.85112","-0.00103"
"250.38600","20.86565","-0.00095"
"250.56000","20.88018","-0.00018"
"250.73400","20.89471","-0.00064"
"250.90800","20.90911","-0.00140"
"251.08200","20.92365","-0.00100"
"251.25600","20.93817","-0.00137"
"251.43000","20.95264","-0.00094"
"251.60400","20.96723","-0.00092"
"251.77800","20.98176","-0.00093"
"251.95200","20.99611","-0.00104"
"252.12600","21.01070","-0.00109"
"252.20800","21.01751","-0.00121"