File: Force_trajectories/170121_1/Specimen_RawData_7.csv
End date,"1/21/2017"
Specimen label,"19CG_NoLabel1"
Maximum Load,"0.03045",N

Time,Extension,Load
(s),(mm),(N)
"0.00000","0.00000","-0.00038"
"0.07200","0.00191","-0.00067"
"0.14400","0.00789","0.00038"
"0.21600","0.01584","0.00110"
"0.28800","0.02332","0.00132"
"0.36000","0.03001","0.00194"
"0.43200","0.03623","0.00236"
"0.50400","0.04227","0.00277"
"0.57600","0.04825","0.00367"
"0.64800","0.05423","0.00276"
"0.72000","0.06021","0.00409"
"0.79200","0.06625","0.00391"
"0.86400","0.07223","0.00470"
"0.93600","0.07820","0.00506"
"1.00800","0.08418","0.00494"
"1.08000","0.09028","0.00560"
"1.15200","0.09626","0.00681"
"1.22400","0.10224","0.00623"
"1.29600","0.10822","0.00655"
"1.36800","0.11420","0.00689"
"1.44000","0.12018","0.00721"
"1.51200","0.12616","0.00795"
"1.58400","0.13219","0.00823"
"1.65600","0.13817","0.00867"
"1.72800","0.14427","0.00876"
"1.80000","0.15019","0.00814"
"1.87200","0.15623","0.00912"
"1.94400","0.16215","0.00850"
"2.01600","0.16813","0.00965"
"2.08800","0.17411","0.01022"
"2.16000","0.18021","0.01013"
"2.23200","0.18618","0.01014"
"2.30400","0.19222","0.01053"
"2.37600","0.19820","0.01123"
"2.44800","0.20424","0.01082"
"2.52000","0.21016","0.01149"
"2.59200","0.21620","0.01160"
"2.66400","0.22212","0.01171"
"2.73600","0.22822","0.01178"
"2.80800","0.23420","0.01243"
"2.88000","0.24023","0.01243"
"2.95200","0.24615","0.01255"
"3.02400","0.25219","0.01215"
"3.09600","0.25817","0.01269"
"3.16800","0.26421","0.01313"
"3.24000","0.27019","0.01330"
"3.31200","0.27623","0.01319"
"3.38400","0.28221","0.01411"
"3.45600","0.28825","0.01388"
"3.52800","0.29416","0.01413"
"3.60000","0.30014","0.01392"
"3.67200","0.30612","0.01425"
"3.74400","0.31216","0.01457"
"3.81600","0.31814","0.01448"
"3.88800","0.32424","0.01484"
"3.96000","0.33016","0.01587"
"4.03200","0.33620","0.01471"
"4.10400","0.34212","0.01530"
"4.17600","0.34815","0.01549"
"4.24800","0.35407","0.01571"
"4.32000","0.36023","0.01573"
"4.39200","0.36621","0.01564"
"4.46400","0.37219","0.01610"
"4.53600","0.37817","0.01593"
"4.60800","0.38421","0.01616"
"4.68000","0.39013","0.01624"
"4.75200","0.39611","0.01724"
"4.82400","0.40220","0.01715"
"4.89600","0.40818","0.01669"
"4.96800","0.41416","0.01724"
"5.04000","0.42026","0.01758"
"5.11200","0.42618","0.01711"
"5.18400","0.43222","0.01735"
"5.25600","0.43814","0.01732"
"5.32800","0.44418","0.01755"
"5.40000","0.45016","0.01819"
"5.47200","0.45619","0.01797"
"5.54400","0.46217","0.01779"
"5.61600","0.46821","0.01846"
"5.68800","0.47413","0.01852"
"5.76000","0.48017","0.01834"
"5.83200","0.48609","0.01836"
"5.90400","0.49219","0.01854"
"5.97600","0.49817","0.01921"
"6.04800","0.50421","0.01914"
"6.12000","0.51018","0.01818"
"6.19200","0.51622","0.01887"
"6.26400","0.52220","0.01854"
"6.33600","0.52818","0.01915"
"6.40800","0.53410","0.01961"
"6.48000","0.54020","0.01954"
"6.55200","0.54618","0.01991"
"6.62400","0.55216","0.01971"
"6.69600","0.55814","0.01973"
"6.76800","0.56417","0.01977"
"6.84000","0.57015","0.01986"
"6.91200","0.57613","0.01949"
"6.98400","0.58211","0.02004"
"7.05600","0.58821","0.01982"
"7.12800","0.59419","0.02029"
"7.20000","0.60023","0.02010"
"7.27200","0.60615","0.01971"
"7.34400","0.61219","0.02019"
"7.41600","0.61816","0.02037"
"7.48800","0.62414","0.02070"
"7.56000","0.63018","0.02048"
"7.63200","0.63628","0.02051"
"7.70400","0.64214","0.01995"
"7.77600","0.64818","0.02032"
"7.84800","0.65416","0.02076"
"7.92000","0.66014","0.02105"
"7.99200","0.66612","0.02052"
"8.06400","0.67215","0.02070"
"8.13600","0.67819","0.02083"
"8.20800","0.68417","0.02128"
"8.28000","0.69021","0.02072"
"8.35200","0.69619","0.02082"
"8.42400","0.70217","0.02129"
"8.49600","0.70815","0.02116"
"8.56800","0.71419","0.02116"
"8.64000","0.72016","0.02120"
"8.71200","0.72620","0.02142"
"8.78400","0.73218","0.02126"
"8.85600","0.73816","0.02114"
"8.92800","0.74414","0.02136"
"9.00000","0.75012","0.02096"
"9.07200","0.75616","0.02238"
"9.14400","0.76220","0.02155"
"9.21600","0.76818","0.02121"
"9.28800","0.77415","0.02205"
"9.36000","0.78019","0.02127"
"9.43200","0.78623","0.02165"
"9.50400","0.79215","0.02185"
"9.57600","0.79813","0.02115"
"9.64800","0.80417","0.02148"
"9.72000","0.81021","0.02134"
"9.79200","0.81625","0.02183"
"9.86400","0.82217","0.02173"
"9.93600","0.82814","0.02233"
"10.00800","0.83412","0.02117"
"10.08000","0.84016","0.02214"
"10.15200","0.84608","0.02170"
"10.22400","0.85218","0.02182"
"10.29600","0.85822","0.02227"
"10.36800","0.86414","0.02244"
"10.44000","0.87018","0.02233"
"10.51200","0.87622","0.02194"
"10.58400","0.88213","0.02187"
"10.65600","0.88811","0.02225"
"10.72800","0.89415","0.02230"
"10.80000","0.90019","0.02233"
"10.87200","0.90623","0.02223"
"10.94400","0.91221","0.02229"
"11.01600","0.91819","0.02182"
"11.08800","0.92417","0.02184"
"11.16000","0.93015","0.02217"
"11.23200","0.93612","0.02188"
"11.30400","0.94216","0.02176"
"11.37600","0.94820","0.02226"
"11.44800","0.95418","0.02209"
"11.52000","0.96022","0.02241"
"11.59200","0.96620","0.02155"
"11.66400","0.97218","0.02207"
"11.73600","0.97816","0.02231"
"11.80800","0.98420","0.02221"
"11.88000","0.99017","0.02252"
"11.95200","0.99621","0.02246"
"12.02400","1.00225","0.02260"
"12.09600","1.00823","0.02260"
"12.16800","1.01415","0.02197"
"12.24000","1.02019","0.02234"
"12.31200","1.02617","0.02243"
"12.38400","1.03221","0.02249"
"12.45600","1.03819","0.02270"
"12.52800","1.04422","0.02260"
"12.60000","1.05020","0.02185"
"12.67200","1.05618","0.02264"
"12.74400","1.06216","0.02231"
"12.81600","1.06814","0.02254"
"12.88800","1.07418","0.02309"
"12.96000","1.08016","0.02219"
"13.03200","1.08620","0.02260"
"13.10400","1.09224","0.02222"
"13.17600","1.09821","0.02231"
"13.24800","1.10413","0.02268"
"13.32000","1.11017","0.02261"
"13.39200","1.11615","0.02275"
"13.46400","1.12219","0.02259"
"13.53600","1.12817","0.02263"
"13.60800","1.13421","0.02264"
"13.68000","1.14019","0.02323"
"13.75200","1.14623","0.02277"
"13.82400","1.15214","0.02270"
"13.89600","1.15812","0.02299"
"13.96800","1.16416","0.02295"
"14.04000","1.17020","0.02331"
"14.11200","1.17618","0.02288"
"14.18400","1.18222","0.02242"
"14.25600","1.18820","0.02306"
"14.32800","1.19418","0.02305"
"14.40000","1.20010","0.02219"
"14.47200","1.20613","0.02260"
"14.54400","1.21217","0.02313"
"14.61600","1.21827","0.02324"
"14.68800","1.22419","0.02313"
"14.76000","1.23023","0.02292"
"14.83200","1.23615","0.02310"
"14.90400","1.24219","0.02271"
"14.97600","1.24811","0.02287"
"15.04800","1.25415","0.02305"
"15.12000","1.26012","0.02319"
"15.19200","1.26622","0.02303"
"15.26400","1.27220","0.02310"
"15.33600","1.27818","0.02318"
"15.40800","1.28416","0.02306"
"15.48000","1.29020","0.02337"
"15.55200","1.29612","0.02273"
"15.62400","1.30222","0.02298"
"15.69600","1.30820","0.02322"
"15.76800","1.31423","0.02351"
"15.84000","1.32021","0.02332"
"15.91200","1.32619","0.02284"
"15.98400","1.33217","0.02309"
"16.05600","1.33815","0.02354"
"16.12800","1.34419","0.02327"
"16.20000","1.35023","0.02323"
"16.27200","1.35621","0.02332"
"16.34400","1.36219","0.02353"
"16.41600","1.36822","0.02253"
"16.48800","1.37414","0.02307"
"16.56000","1.38018","0.02307"
"16.63200","1.38616","0.02378"
"16.70400","1.39214","0.02337"
"16.77600","1.39818","0.02274"
"16.84800","1.40416","0.02296"
"16.92000","1.41020","0.02321"
"16.99200","1.41612","0.02326"
"17.06400","1.42215","0.02365"
"17.13600","1.42813","0.02274"
"17.20800","1.43417","0.02348"
"17.28000","1.44015","0.02307"
"17.35200","1.44619","0.02349"
"17.42400","1.45217","0.02322"
"17.49600","1.45821","0.02350"
"17.56800","1.46419","0.02244"
"17.64000","1.47016","0.02337"
"17.71200","1.47614","0.02329"
"17.78400","1.48218","0.02382"
"17.85600","1.48822","0.02348"
"17.92800","1.49420","0.02290"
"18.00000","1.50018","0.02342"
"18.07200","1.50622","0.02309"
"18.14400","1.51214","0.02307"
"18.21600","1.51818","0.02344"
"18.28800","1.52415","0.02304"
"18.36000","1.53025","0.02322"
"18.43200","1.53617","0.02359"
"18.50400","1.54221","0.02328"
"18.57600","1.54813","0.02350"
"18.64800","1.55417","0.02295"
"18.72000","1.56009","0.02349"
"18.79200","1.56619","0.02397"
"18.86400","1.57217","0.02372"
"18.93600","1.57826","0.02318"
"19.00800","1.58418","0.02371"
"19.08000","1.59022","0.02364"
"19.15200","1.59614","0.02328"
"19.22400","1.60218","0.02340"
"19.29600","1.60810","0.02382"
"19.36800","1.61420","0.02320"
"19.44000","1.62018","0.02364"
"19.51200","1.62622","0.02350"
"19.58400","1.63219","0.02380"
"19.65600","1.63817","0.02346"
"19.72800","1.64415","0.02378"
"19.80000","1.65013","0.02358"
"19.87200","1.65611","0.02369"
"19.94400","1.66221","0.02294"
"20.01600","1.66825","0.02329"
"20.08800","1.67423","0.02316"
"20.16000","1.68021","0.02351"
"20.23200","1.68618","0.02380"
"20.30400","1.69216","0.02382"
"20.37600","1.69814","0.02353"
"20.44800","1.70418","0.02365"
"20.52000","1.71022","0.02371"
"20.59200","1.71620","0.02366"
"20.66400","1.72224","0.02292"
"20.73600","1.72816","0.02390"
"20.80800","1.73420","0.02382"
"20.88000","1.74011","0.02358"
"20.95200","1.74621","0.02361"
"21.02400","1.75213","0.02351"
"21.09600","1.75823","0.02398"
"21.16800","1.76421","0.02355"
"21.24000","1.77025","0.02341"
"21.31200","1.77617","0.02386"
"21.38400","1.78215","0.02351"
"21.45600","1.78813","0.02390"
"21.52800","1.79416","0.02370"
"21.60000","1.80020","0.02395"
"21.67200","1.80618","0.02364"
"21.74400","1.81222","0.02365"
"21.81600","1.81820","0.02372"
"21.88800","1.82418","0.02319"
"21.96000","1.83016","0.02357"
"22.03200","1.83614","0.02367"
"22.10400","1.84218","0.02370"
"22.17600","1.84815","0.02399"
"22.24800","1.85425","0.02338"
"22.32000","1.86017","0.02371"
"22.39200","1.86621","0.02339"
"22.46400","1.87213","0.02388"
"22.53600","1.87817","0.02367"
"22.60800","1.88415","0.02402"
"22.68000","1.89025","0.02360"
"22.75200","1.89617","0.02337"
"22.82400","1.90226","0.02384"
"22.89600","1.90818","0.02374"
"22.96800","1.91416","0.02350"
"23.04000","1.92008","0.02352"
"23.11200","1.92624","0.02359"
"23.18400","1.93222","0.02430"
"23.25600","1.93826","0.02353"
"23.32800","1.94418","0.02397"
"23.40000","1.95022","0.02381"
"23.47200","1.95619","0.02397"
"23.54400","1.96217","0.02374"
"23.61600","1.96815","0.02427"
"23.68800","1.97419","0.02378"
"23.76000","1.98023","0.02362"
"23.83200","1.98615","0.02357"
"23.90400","1.99219","0.02403"
"23.97600","1.99817","0.02343"
"24.04800","2.00415","0.02390"
"24.12000","2.01012","0.02390"
"24.19200","2.01616","0.02395"
"24.26400","2.02214","0.02410"
"24.33600","2.02818","0.02381"
"24.40800","2.03416","0.02430"
"24.48000","2.04014","0.02341"
"24.55200","2.04618","0.02388"
"24.62400","2.05216","0.02363"
"24.69600","2.05819","0.02384"
"24.76800","2.06417","0.02347"
"24.84000","2.07021","0.02396"
"24.91200","2.07613","0.02354"
"24.98400","2.08217","0.02430"
"25.05600","2.08815","0.02387"
"25.12800","2.09413","0.02344"
"25.20000","2.10011","0.02375"
"25.27200","2.10621","0.02345"
"25.34400","2.11219","0.02325"
"25.41600","2.11816","0.02344"
"25.48800","2.12414","0.02443"
"25.56000","2.13018","0.02417"
"25.63200","2.13610","0.02372"
"25.70400","2.14214","0.02380"
"25.77600","2.14812","0.02409"
"25.84800","2.15416","0.02372"
"25.92000","2.16020","0.02410"
"25.99200","2.16617","0.02415"
"26.06400","2.17221","0.02431"
"26.13600","2.17819","0.02382"
"26.20800","2.18411","0.02415"
"26.28000","2.19015","0.02433"
"26.35200","2.19613","0.02401"
"26.42400","2.20223","0.02362"
"26.49600","2.20815","0.02375"
"26.56800","2.21419","0.02394"
"26.64000","2.22016","0.02387"
"26.71200","2.22620","0.02395"
"26.78400","2.23212","0.02386"
"26.85600","2.23816","0.02428"
"26.92800","2.24420","0.02381"
"27.00000","2.25024","0.02425"
"27.07200","2.25616","0.02412"
"27.14400","2.26220","0.02398"
"27.21600","2.26818","0.02380"
"27.28800","2.27415","0.02374"
"27.36000","2.28013","0.02380"
"27.43200","2.28617","0.02376"
"27.50400","2.29221","0.02355"
"27.57600","2.29819","0.02406"
"27.64800","2.30423","0.02383"
"27.72000","2.31021","0.02412"
"27.79200","2.31619","0.02391"
"27.86400","2.32211","0.02399"
"27.93600","2.32814","0.02384"
"28.00800","2.33424","0.02394"
"28.08000","2.34022","0.02434"
"28.15200","2.34620","0.02399"
"28.22400","2.35218","0.02380"
"28.29600","2.35822","0.02385"
"28.36800","2.36414","0.02400"
"28.44000","2.37012","0.02413"
"28.51200","2.37616","0.02391"
"28.58400","2.38225","0.02412"
"28.65600","2.38823","0.02424"
"28.72800","2.39421","0.02440"
"28.80000","2.40019","0.02373"
"28.87200","2.40617","0.02440"
"28.94400","2.41215","0.02385"
"29.01600","2.41813","0.02431"
"29.08800","2.42417","0.02454"
"29.16000","2.43021","0.02414"
"29.23200","2.43618","0.02447"
"29.30400","2.44222","0.02374"
"29.37600","2.44814","0.02375"
"29.44800","2.45412","0.02446"
"29.52000","2.46010","0.02393"
"29.59200","2.46614","0.02427"
"29.66400","2.47212","0.02381"
"29.73600","2.47816","0.02389"
"29.80800","2.48420","0.02378"
"29.88000","2.49017","0.02410"
"29.95200","2.49615","0.02403"
"30.02400","2.50213","0.02399"
"30.09600","2.50811","0.02418"
"30.16800","2.51415","0.02434"
"30.24000","2.52019","0.02391"
"30.31200","2.52623","0.02433"
"30.38400","2.53221","0.02404"
"30.45600","2.53819","0.02418"
"30.52800","2.54416","0.02432"
"30.60000","2.55014","0.02419"
"30.67200","2.55618","0.02408"
"30.74400","2.56222","0.02381"
"30.81600","2.56820","0.02416"
"30.88800","2.57424","0.02383"
"30.96000","2.58022","0.02400"
"31.03200","2.58614","0.02428"
"31.10400","2.59212","0.02432"
"31.17600","2.59815","0.02420"
"31.24800","2.60419","0.02421"
"31.32000","2.61017","0.02403"
"31.39200","2.61621","0.02435"
"31.46400","2.62219","0.02398"
"31.53600","2.62817","0.02437"
"31.60800","2.63415","0.02450"
"31.68000","2.64013","0.02394"
"31.75200","2.64616","0.02444"
"31.82400","2.65220","0.02443"
"31.89600","2.65818","0.02443"
"31.96800","2.66422","0.02387"
"32.04000","2.67014","0.02409"
"32.11200","2.67618","0.02446"
"32.18400","2.68216","0.02356"
"32.25600","2.68814","0.02395"
"32.32800","2.69418","0.02484"
"32.40000","2.70021","0.02418"
"32.47200","2.70619","0.02448"
"32.54400","2.71217","0.02428"
"32.61600","2.71815","0.02385"
"32.68800","2.72413","0.02457"
"32.76000","2.73017","0.02400"
"32.83200","2.73615","0.02465"
"32.90400","2.74219","0.02461"
"32.97600","2.74817","0.02428"
"33.04800","2.75426","0.02435"
"33.12000","2.76018","0.02421"
"33.19200","2.76616","0.02425"
"33.26400","2.77214","0.02460"
"33.33600","2.77818","0.02438"
"33.40800","2.78416","0.02431"
"33.48000","2.79020","0.02435"
"33.55200","2.79624","0.02390"
"33.62400","2.80222","0.02364"
"33.69600","2.80819","0.02444"
"33.76800","2.81417","0.02412"
"33.84000","2.82015","0.02450"
"33.91200","2.82619","0.02378"
"33.98400","2.83223","0.02432"
"34.05600","2.83815","0.02427"
"34.12800","2.84419","0.02454"
"34.20000","2.85011","0.02412"
"34.27200","2.85615","0.02404"
"34.34400","2.86212","0.02428"
"34.41600","2.86816","0.02435"
"34.48800","2.87414","0.02434"
"34.56000","2.88018","0.02390"
"34.63200","2.88616","0.02468"
"34.70400","2.89220","0.02441"
"34.77600","2.89812","0.02456"
"34.84800","2.90416","0.02411"
"34.92000","2.91014","0.02440"
"34.99200","2.91617","0.02435"
"35.06400","2.92215","0.02447"
"35.13600","2.92819","0.02403"
"35.20800","2.93423","0.02430"
"35.28000","2.94021","0.02483"
"35.35200","2.94613","0.02481"
"35.42400","2.95217","0.02434"
"35.49600","2.95821","0.02443"
"35.56800","2.96425","0.02419"
"35.64000","2.97022","0.02433"
"35.71200","2.97620","0.02494"
"35.78400","2.98218","0.02438"
"35.85600","2.98816","0.02466"
"35.92800","2.99414","0.02437"
"36.00000","3.00018","0.02390"
"36.07200","3.00622","0.02466"
"36.14400","3.01226","0.02385"
"36.21600","3.01818","0.02394"
"36.28800","3.02421","0.02362"
"36.36000","3.03019","0.02380"
"36.43200","3.03617","0.02351"
"36.50400","3.04209","0.02393"
"36.57600","3.04819","0.02352"
"36.64800","3.05423","0.02402"
"36.72000","3.06021","0.02440"
"36.79200","3.06625","0.02394"
"36.86400","3.07223","0.02421"
"36.93600","3.07820","0.02362"
"37.00800","3.08412","0.02392"
"37.08000","3.09016","0.02423"
"37.15200","3.09620","0.02372"
"37.22400","3.10224","0.02326"
"37.29600","3.10822","0.02459"
"37.36800","3.11420","0.02380"
"37.44000","3.12018","0.02359"
"37.51200","3.12616","0.02350"
"37.58400","3.13219","0.02380"
"37.65600","3.13811","0.02425"
"37.72800","3.14421","0.02388"
"37.80000","3.15019","0.02369"
"37.87200","3.15623","0.02421"
"37.94400","3.16215","0.02390"
"38.01600","3.16819","0.02288"
"38.08800","3.17411","0.02357"
"38.16000","3.18015","0.02391"
"38.23200","3.18612","0.02390"
"38.30400","3.19222","0.02401"
"38.37600","3.19814","0.02363"
"38.44800","3.20418","0.02408"
"38.52000","3.21016","0.02415"
"38.59200","3.21614","0.02391"
"38.66400","3.22212","0.02397"
"38.73600","3.22822","0.02394"
"38.80800","3.23419","0.02428"
"38.88000","3.24023","0.02412"
"38.95200","3.24621","0.02378"
"39.02400","3.25225","0.02407"
"39.09600","3.25811","0.02383"
"39.16800","3.26415","0.02358"
"39.24000","3.27013","0.02384"
"39.31200","3.27623","0.02410"
"39.38400","3.28221","0.02429"
"39.45600","3.28824","0.02383"
"39.52800","3.29422","0.02430"
"39.60000","3.30020","0.02392"
"39.67200","3.30618","0.02391"
"39.74400","3.31216","0.02381"
"39.81600","3.31814","0.02448"
"39.88800","3.32424","0.02382"
"39.96000","3.33016","0.02382"
"40.03200","3.33626","0.02413"
"40.10400","3.34218","0.02405"
"40.17600","3.34815","0.02426"
"40.24800","3.35407","0.02355"
"40.32000","3.36017","0.02443"
"40.39200","3.36615","0.02406"
"40.46400","3.37219","0.02399"
"40.53600","3.37823","0.02417"
"40.60800","3.38415","0.02392"
"40.68000","3.39019","0.02450"
"40.75200","3.39617","0.02407"
"40.82400","3.40214","0.02425"
"40.89600","3.40818","0.02403"
"40.96800","3.41422","0.02417"
"41.04000","3.42020","0.02442"
"41.11200","3.42624","0.02426"
"41.18400","3.43222","0.02425"
"41.25600","3.43820","0.02409"
"41.32800","3.44418","0.02424"
"41.40000","3.45021","0.02389"
"41.47200","3.45619","0.02428"
"41.54400","3.46223","0.02420"
"41.61600","3.46821","0.02403"
"41.68800","3.47419","0.02423"
"41.76000","3.48023","0.02395"
"41.83200","3.48615","0.02433"
"41.90400","3.49219","0.02394"
"41.97600","3.49817","0.02396"
"42.04800","3.50426","0.02432"
"42.12000","3.51018","0.02388"
"42.19200","3.51622","0.02415"
"42.26400","3.52214","0.02400"
"42.33600","3.52818","0.02409"
"42.40800","3.53410","0.02454"
"42.48000","3.54014","0.02426"
"42.55200","3.54618","0.02451"
"42.62400","3.55222","0.02426"
"42.69600","3.55819","0.02380"
"42.76800","3.56417","0.02440"
"42.84000","3.57009","0.02397"
"42.91200","3.57613","0.02425"
"42.98400","3.58211","0.02429"
"43.05600","3.58815","0.02436"
"43.12800","3.59419","0.02467"
"43.20000","3.60023","0.02442"
"43.27200","3.60621","0.02404"
"43.34400","3.61218","0.02402"
"43.41600","3.61816","0.02407"
"43.48800","3.62420","0.02436"
"43.56000","3.63018","0.02377"
"43.63200","3.63622","0.02416"
"43.70400","3.64220","0.02459"
"43.77600","3.64818","0.02360"
"43.84800","3.65416","0.02425"
"43.92000","3.66020","0.02460"
"43.99200","3.66612","0.02437"
"44.06400","3.67215","0.02413"
"44.13600","3.67819","0.02407"
"44.20800","3.68417","0.02409"
"44.28000","3.69015","0.02416"
"44.35200","3.69619","0.02397"
"44.42400","3.70217","0.02412"
"44.49600","3.70815","0.02373"
"44.56800","3.71413","0.02435"
"44.64000","3.72016","0.02388"
"44.71200","3.72620","0.02459"
"44.78400","3.73218","0.02419"
"44.85600","3.73822","0.02424"
"44.92800","3.74420","0.02455"
"45.00000","3.75018","0.02449"
"45.07200","3.75610","0.02415"
"45.14400","3.76214","0.02425"
"45.21600","3.76818","0.02390"
"45.28800","3.77421","0.02426"
"45.36000","3.78019","0.02415"
"45.43200","3.78617","0.02417"
"45.50400","3.79221","0.02360"
"45.57600","3.79819","0.02432"
"45.64800","3.80417","0.02436"
"45.72000","3.81015","0.02428"
"45.79200","3.81625","0.02400"
"45.86400","3.82223","0.02427"
"45.93600","3.82820","0.02407"
"46.00800","3.83418","0.02442"
"46.08000","3.84016","0.02385"
"46.15200","3.84614","0.02432"
"46.22400","3.85218","0.02410"
"46.29600","3.85816","0.02449"
"46.36800","3.86426","0.02394"
"46.44000","3.87018","0.02426"
"46.51200","3.87622","0.02438"
"46.58400","3.88213","0.02478"
"46.65600","3.88811","0.02411"
"46.72800","3.89415","0.02414"
"46.80000","3.90019","0.02400"
"46.87200","3.90617","0.02429"
"46.94400","3.91221","0.02423"
"47.01600","3.91819","0.02401"
"47.08800","3.92423","0.02443"
"47.16000","3.93015","0.02392"
"47.23200","3.93612","0.02455"
"47.30400","3.94210","0.02407"
"47.37600","3.94820","0.02398"
"47.44800","3.95418","0.02435"
"47.52000","3.96022","0.02401"
"47.59200","3.96620","0.02460"
"47.66400","3.97224","0.02440"
"47.73600","3.97816","0.02430"
"47.80800","3.98420","0.02429"
"47.88000","3.99017","0.02440"
"47.95200","3.99621","0.02429"
"48.02400","4.00219","0.02440"
"48.09600","4.00823","0.02453"
"48.16800","4.01421","0.02407"
"48.24000","4.02019","0.02475"
"48.31200","4.02617","0.02431"
"48.38400","4.03215","0.02441"
"48.45600","4.03819","0.02401"
"48.52800","4.04416","0.02385"
"48.60000","4.05020","0.02409"
"48.67200","4.05624","0.02402"
"48.74400","4.06222","0.02408"
"48.81600","4.06814","0.02434"
"48.88800","4.07406","0.02410"
"48.96000","4.08022","0.02415"
"49.03200","4.08620","0.02403"
"49.10400","4.09223","0.02443"
"49.17600","4.09821","0.02429"
"49.24800","4.10425","0.02466"
"49.32000","4.11017","0.02451"
"49.39200","4.11615","0.02460"
"49.46400","4.12213","0.02435"
"49.53600","4.12817","0.02417"
"49.60800","4.13421","0.02430"
"49.68000","4.14013","0.02413"
"49.75200","4.14616","0.02414"
"49.82400","4.15214","0.02450"
"49.89600","4.15812","0.02446"
"49.96800","4.16410","0.02420"
"50.04000","4.17014","0.02404"
"50.11200","4.17618","0.02383"
"50.18400","4.18216","0.02412"
"50.25600","4.18820","0.02440"
"50.32800","4.19418","0.02461"
"50.40000","4.20015","0.02428"
"50.47200","4.20613","0.02383"
"50.54400","4.21217","0.02446"
"50.61600","4.21821","0.02417"
"50.68800","4.22425","0.02410"
"50.76000","4.23017","0.02453"
"50.83200","4.23615","0.02465"
"50.90400","4.24213","0.02460"
"50.97600","4.24817","0.02394"
"51.04800","4.25414","0.02443"
"51.12000","4.26012","0.02465"
"51.19200","4.26616","0.02413"
"51.26400","4.27214","0.02433"
"51.33600","4.27818","0.02446"
"51.40800","4.28416","0.02424"
"51.48000","4.29014","0.02459"
"51.55200","4.29618","0.02426"
"51.62400","4.30216","0.02474"
"51.69600","4.30813","0.02416"
"51.76800","4.31417","0.02400"
"51.84000","4.32015","0.02425"
"51.91200","4.32619","0.02451"
"51.98400","4.33211","0.02407"
"52.05600","4.33815","0.02385"
"52.12800","4.34413","0.02443"
"52.20000","4.35023","0.02460"
"52.27200","4.35621","0.02486"
"52.34400","4.36218","0.02374"
"52.41600","4.36822","0.02468"
"52.48800","4.37420","0.02434"
"52.56000","4.38012","0.02467"
"52.63200","4.38610","0.02426"
"52.70400","4.39220","0.02431"
"52.77600","4.39818","0.02444"
"52.84800","4.40422","0.02461"
"52.92000","4.41020","0.02408"
"52.99200","4.41617","0.02394"
"53.06400","4.42215","0.02431"
"53.13600","4.42813","0.02450"
"53.20800","4.43411","0.02465"
"53.28000","4.44015","0.02421"
"53.35200","4.44619","0.02439"
"53.42400","4.45217","0.02450"
"53.49600","4.45821","0.02423"
"53.56800","4.46425","0.02466"
"53.64000","4.47022","0.02434"
"53.71200","4.47614","0.02449"
"53.78400","4.48218","0.02432"
"53.85600","4.48822","0.02462"
"53.92800","4.49426","0.02480"
"54.00000","4.50024","0.02409"
"54.07200","4.50616","0.02457"
"54.14400","4.51214","0.02434"
"54.21600","4.51812","0.02427"
"54.28800","4.52415","0.02431"
"54.36000","4.53019","0.02402"
"54.43200","4.53623","0.02468"
"54.50400","4.54221","0.02471"
"54.57600","4.54819","0.02450"
"54.64800","4.55417","0.02399"
"54.72000","4.56015","0.02468"
"54.79200","4.56619","0.02404"
"54.86400","4.57217","0.02423"
"54.93600","4.57820","0.02477"
"55.00800","4.58418","0.02464"
"55.08000","4.59022","0.02442"
"55.15200","4.59614","0.02449"
"55.22400","4.60218","0.02447"
"55.29600","4.60810","0.02469"
"55.36800","4.61414","0.02442"
"55.44000","4.62018","0.02406"
"55.51200","4.62621","0.02428"
"55.58400","4.63213","0.02440"
"55.65600","4.63823","0.02435"
"55.72800","4.64415","0.02467"
"55.80000","4.65019","0.02507"
"55.87200","4.65617","0.02422"
"55.94400","4.66221","0.02472"
"56.01600","4.66819","0.02467"
"56.08800","4.67423","0.02453"
"56.16000","4.68021","0.02486"
"56.23200","4.68624","0.02432"
"56.30400","4.69216","0.02421"
"56.37600","4.69814","0.02471"
"56.44800","4.70418","0.02469"
"56.52000","4.71016","0.02452"
"56.59200","4.71620","0.02461"
"56.66400","4.72218","0.02464"
"56.73600","4.72822","0.02418"
"56.80800","4.73419","0.02456"
"56.88000","4.74011","0.02488"
"56.95200","4.74615","0.02445"
"57.02400","4.75219","0.02401"
"57.09600","4.75823","0.02458"
"57.16800","4.76415","0.02471"
"57.24000","4.77025","0.02459"
"57.31200","4.77617","0.02431"
"57.38400","4.78221","0.02431"
"57.45600","4.78813","0.02470"
"57.52800","4.79410","0.02460"
"57.60000","4.80020","0.02419"
"57.67200","4.80624","0.02472"
"57.74400","4.81222","0.02414"
"57.81600","4.81820","0.02444"
"57.88800","4.82418","0.02497"
"57.96000","4.83016","0.02423"
"58.03200","4.83614","0.02477"
"58.10400","4.84218","0.02431"
"58.17600","4.84821","0.02439"
"58.24800","4.85419","0.02432"
"58.32000","4.86017","0.02488"
"58.39200","4.86621","0.02447"
"58.46400","4.87219","0.02472"
"58.53600","4.87817","0.02493"
"58.60800","4.88415","0.02444"
"58.68000","4.89019","0.02509"
"58.75200","4.89622","0.02480"
"58.82400","4.90220","0.02427"
"58.89600","4.90818","0.02439"
"58.96800","4.91422","0.02446"
"59.04000","4.92020","0.02426"
"59.11200","4.92624","0.02448"
"59.18400","4.93216","0.02459"
"59.25600","4.93826","0.02440"
"59.32800","4.94418","0.02513"
"59.40000","4.95021","0.02395"
"59.47200","4.95613","0.02480"
"59.54400","4.96217","0.02480"
"59.61600","4.96815","0.02477"
"59.68800","4.97419","0.02439"
"59.76000","4.98011","0.02446"
"59.83200","4.98621","0.02484"
"59.90400","4.99219","0.02433"
"59.97600","4.99823","0.02450"
"60.04800","5.00414","0.02480"
"60.12000","5.01012","0.02520"
"60.19200","5.01610","0.02442"
"60.26400","5.02220","0.02459"
"60.33600","5.02818","0.02454"
"60.40800","5.03422","0.02447"
"60.48000","5.04020","0.02484"
"60.55200","5.04624","0.02443"
"60.62400","5.05216","0.02470"
"60.69600","5.05819","0.02483"
"60.76800","5.06411","0.02461"
"60.84000","5.07021","0.02490"
"60.91200","5.07619","0.02460"
"60.98400","5.08223","0.02497"
"61.05600","5.08821","0.02422"
"61.12800","5.09419","0.02447"
"61.20000","5.10017","0.02465"
"61.27200","5.10615","0.02451"
"61.34400","5.11218","0.02446"
"61.41600","5.11822","0.02462"
"61.48800","5.12420","0.02487"
"61.56000","5.13018","0.02466"
"61.63200","5.13616","0.02446"
"61.70400","5.14214","0.02474"
"61.77600","5.14812","0.02472"
"61.84800","5.15416","0.02501"
"61.92000","5.16020","0.02458"
"61.99200","5.16617","0.02458"
"62.06400","5.17221","0.02494"
"62.13600","5.17819","0.02469"
"62.20800","5.18417","0.02493"
"62.28000","5.19015","0.02429"
"62.35200","5.19607","0.02454"
"62.42400","5.20217","0.02438"
"62.49600","5.20815","0.02451"
"62.56800","5.21424","0.02462"
"62.64000","5.22016","0.02466"
"62.71200","5.22620","0.02491"
"62.78400","5.23212","0.02502"
"62.85600","5.23816","0.02436"
"62.92800","5.24414","0.02452"
"63.00000","5.25024","0.02417"
"63.07200","5.25622","0.02442"
"63.14400","5.26226","0.02447"
"63.21600","5.26818","0.02431"
"63.28800","5.27421","0.02454"
"63.36000","5.28013","0.02490"
"63.43200","5.28617","0.02481"
"63.50400","5.29215","0.02450"
"63.57600","5.29825","0.02447"
"63.64800","5.30417","0.02461"
"63.72000","5.31021","0.02466"
"63.79200","5.31613","0.02471"
"63.86400","5.32211","0.02488"
"63.93600","5.32808","0.02460"
"64.00800","5.33418","0.02486"
"64.08000","5.34016","0.02466"
"64.15200","5.34620","0.02501"
"64.22400","5.35224","0.02513"
"64.29600","5.35822","0.02484"
"64.36800","5.36414","0.02460"
"64.44000","5.37018","0.02459"
"64.51200","5.37609","0.02480"
"64.58400","5.38219","0.02485"
"64.65600","5.38817","0.02500"
"64.72800","5.39421","0.02487"
"64.80000","5.40019","0.02479"
"64.87200","5.40623","0.02466"
"64.94400","5.41215","0.02468"
"65.01600","5.41819","0.02485"
"65.08800","5.42417","0.02458"
"65.16000","5.43020","0.02469"
"65.23200","5.43618","0.02475"
"65.30400","5.44222","0.02489"
"65.37600","5.44826","0.02489"
"65.44800","5.45418","0.02503"
"65.52000","5.46016","0.02503"
"65.59200","5.46620","0.02503"
"65.66400","5.47224","0.02477"
"65.73600","5.47822","0.02462"
"65.80800","5.48419","0.02514"
"65.88000","5.49023","0.02466"
"65.95200","5.49621","0.02480"
"66.02400","5.50219","0.02485"
"66.09600","5.50811","0.02447"
"66.16800","5.51421","0.02454"
"66.24000","5.52019","0.02431"
"66.31200","5.52623","0.02471"
"66.38400","5.53221","0.02465"
"66.45600","5.53824","0.02500"
"66.52800","5.54416","0.02427"
"66.60000","5.55014","0.02473"
"66.67200","5.55612","0.02469"
"66.74400","5.56222","0.02516"
"66.81600","5.56820","0.02516"
"66.88800","5.57424","0.02509"
"66.96000","5.58022","0.02526"
"67.03200","5.58620","0.02545"
"67.10400","5.59218","0.02476"
"67.17600","5.59821","0.02471"
"67.24800","5.60419","0.02497"
"67.32000","5.61017","0.02489"
"67.39200","5.61615","0.02463"
"67.46400","5.62219","0.02481"
"67.53600","5.62817","0.02487"
"67.60800","5.63415","0.02487"
"67.68000","5.64013","0.02479"
"67.75200","5.64616","0.02504"
"67.82400","5.65214","0.02475"
"67.89600","5.65818","0.02482"
"67.96800","5.66416","0.02493"
"68.04000","5.67014","0.02434"
"68.11200","5.67612","0.02481"
"68.18400","5.68210","0.02484"
"68.25600","5.68808","0.02476"
"68.32800","5.69418","0.02472"
"68.40000","5.70015","0.02422"
"68.47200","5.70619","0.02458"
"68.54400","5.71217","0.02486"
"68.61600","5.71815","0.02440"
"68.68800","5.72413","0.02503"
"68.76000","5.73017","0.02468"
"68.83200","5.73615","0.02516"
"68.90400","5.74219","0.02482"
"68.97600","5.74817","0.02489"
"69.04800","5.75414","0.02481"
"69.12000","5.76018","0.02489"
"69.19200","5.76616","0.02446"
"69.26400","5.77214","0.02488"
"69.33600","5.77812","0.02470"
"69.40800","5.78416","0.02477"
"69.48000","5.79020","0.02484"
"69.55200","5.79618","0.02493"
"69.62400","5.80222","0.02494"
"69.69600","5.80819","0.02492"
"69.76800","5.81417","0.02460"
"69.84000","5.82015","0.02502"
"69.91200","5.82619","0.02451"
"69.98400","5.83223","0.02482"
"70.05600","5.83821","0.02479"
"70.12800","5.84419","0.02493"
"70.20000","5.85023","0.02480"
"70.27200","5.85615","0.02503"
"70.34400","5.86212","0.02459"
"70.41600","5.86810","0.02474"
"70.48800","5.87420","0.02438"
"70.56000","5.88018","0.02514"
"70.63200","5.88616","0.02494"
"70.70400","5.89220","0.02490"
"70.77600","5.89818","0.02470"
"70.84800","5.90416","0.02434"
"70.92000","5.91014","0.02478"
"70.99200","5.91611","0.02517"
"71.06400","5.92221","0.02475"
"71.13600","5.92825","0.02455"
"71.20800","5.93417","0.02533"
"71.28000","5.94021","0.02488"
"71.35200","5.94619","0.02486"
"71.42400","5.95217","0.02474"
"71.49600","5.95809","0.02447"
"71.56800","5.96419","0.02496"
"71.64000","5.97022","0.02475"
"71.71200","5.97620","0.02513"
"71.78400","5.98224","0.02480"
"71.85600","5.98816","0.02470"
"71.92800","5.99420","0.02474"
"72.00000","6.00018","0.02482"
"72.07200","6.00616","0.02464"
"72.14400","6.01214","0.02503"
"72.21600","6.01817","0.02515"
"72.28800","6.02421","0.02483"
"72.36000","6.03019","0.02480"
"72.43200","6.03617","0.02543"
"72.50400","6.04209","0.02495"
"72.57600","6.04813","0.02441"
"72.64800","6.05417","0.02517"
"72.72000","6.06015","0.02451"
"72.79200","6.06619","0.02497"
"72.86400","6.07223","0.02464"
"72.93600","6.07820","0.02505"
"73.00800","6.08418","0.02499"
"73.08000","6.09016","0.02478"
"73.15200","6.09614","0.02469"
"73.22400","6.10218","0.02506"
"73.29600","6.10816","0.02483"
"73.36800","6.11420","0.02490"
"73.44000","6.12018","0.02538"
"73.51200","6.12616","0.02486"
"73.58400","6.13213","0.02501"
"73.65600","6.13817","0.02490"
"73.72800","6.14415","0.02462"
"73.80000","6.15019","0.02481"
"73.87200","6.15623","0.02478"
"73.94400","6.16221","0.02496"
"74.01600","6.16819","0.02522"
"74.08800","6.17417","0.02447"
"74.16000","6.18014","0.02507"
"74.23200","6.18618","0.02431"
"74.30400","6.19222","0.02549"
"74.37600","6.19820","0.02471"
"74.44800","6.20418","0.02524"
"74.52000","6.21022","0.02470"
"74.59200","6.21614","0.02452"
"74.66400","6.22218","0.02516"
"74.73600","6.22816","0.02524"
"74.80800","6.23414","0.02486"
"74.88000","6.24023","0.02485"
"74.95200","6.24615","0.02507"
"75.02400","6.25219","0.02520"
"75.09600","6.25817","0.02540"
"75.16800","6.26421","0.02533"
"75.24000","6.27013","0.02536"
"75.31200","6.27617","0.02500"
"75.38400","6.28221","0.02500"
"75.45600","6.28824","0.02549"
"75.52800","6.29416","0.02519"
"75.60000","6.30020","0.02493"
"75.67200","6.30618","0.02519"
"75.74400","6.31216","0.02454"
"75.81600","6.31814","0.02476"
"75.88800","6.32418","0.02470"
"75.96000","6.33022","0.02510"
"76.03200","6.33620","0.02467"
"76.10400","6.34223","0.02511"
"76.17600","6.34821","0.02524"
"76.24800","6.35413","0.02494"
"76.32000","6.36017","0.02538"
"76.39200","6.36621","0.02513"
"76.46400","6.37225","0.02479"
"76.53600","6.37823","0.02506"
"76.60800","6.38421","0.02521"
"76.68000","6.39019","0.02498"
"76.75200","6.39616","0.02454"
"76.82400","6.40214","0.02434"
"76.89600","6.40818","0.02454"
"76.96800","6.41422","0.02496"
"77.04000","6.42020","0.02502"
"77.11200","6.42624","0.02408"
"77.18400","6.43222","0.02488"
"77.25600","6.43814","0.02498"
"77.32800","6.44418","0.02502"
"77.40000","6.45015","0.02501"
"77.47200","6.45619","0.02484"
"77.54400","6.46217","0.02511"
"77.61600","6.46821","0.02513"
"77.68800","6.47419","0.02507"
"77.76000","6.48023","0.02493"
"77.83200","6.48615","0.02506"
"77.90400","6.49219","0.02506"
"77.97600","6.49817","0.02499"
"78.04800","6.50420","0.02510"
"78.12000","6.51018","0.02531"
"78.19200","6.51622","0.02497"
"78.26400","6.52220","0.02496"
"78.33600","6.52824","0.02517"
"78.40800","6.53416","0.02518"
"78.48000","6.54014","0.02525"
"78.55200","6.54618","0.02477"
"78.62400","6.55222","0.02539"
"78.69600","6.55819","0.02479"
"78.76800","6.56423","0.02514"
"78.84000","6.57015","0.02482"
"78.91200","6.57619","0.02480"
"78.98400","6.58211","0.02491"
"79.05600","6.58821","0.02521"
"79.12800","6.59419","0.02517"
"79.20000","6.60029","0.02521"
"79.27200","6.60621","0.02494"
"79.34400","6.61224","0.02505"
"79.41600","6.61822","0.02519"
"79.48800","6.62414","0.02510"
"79.56000","6.63012","0.02498"
"79.63200","6.63622","0.02554"
"79.70400","6.64226","0.02528"
"79.77600","6.64824","0.02514"
"79.84800","6.65422","0.02499"
"79.92000","6.66025","0.02479"
"79.99200","6.66617","0.02509"
"80.06400","6.67215","0.02428"
"80.13600","6.67807","0.02469"
"80.20800","6.68423","0.02507"
"80.28000","6.69021","0.02520"
"80.35200","6.69625","0.02505"
"80.42400","6.70217","0.02510"
"80.49600","6.70821","0.02529"
"80.56800","6.71419","0.02531"
"80.64000","6.72016","0.02523"
"80.71200","6.72614","0.02484"
"80.78400","6.73218","0.02522"
"80.85600","6.73822","0.02501"
"80.92800","6.74414","0.02512"
"81.00000","6.75018","0.02494"
"81.07200","6.75610","0.02479"
"81.14400","6.76214","0.02535"
"81.21600","6.76818","0.02501"
"81.28800","6.77415","0.02543"
"81.36000","6.78019","0.02533"
"81.43200","6.78623","0.02507"
"81.50400","6.79227","0.02500"
"81.57600","6.79813","0.02515"
"81.64800","6.80417","0.02520"
"81.72000","6.81009","0.02502"
"81.79200","6.81625","0.02520"
"81.86400","6.82222","0.02507"
"81.93600","6.82820","0.02537"
"82.00800","6.83418","0.02572"
"82.08000","6.84022","0.02513"
"82.15200","6.84614","0.02506"
"82.22400","6.85218","0.02465"
"82.29600","6.85816","0.02533"
"82.36800","6.86420","0.02536"
"82.44000","6.87018","0.02545"
"82.51200","6.87622","0.02542"
"82.58400","6.88219","0.02570"
"82.65600","6.88823","0.02532"
"82.72800","6.89415","0.02529"
"82.80000","6.90013","0.02569"
"82.87200","6.90617","0.02478"
"82.94400","6.91221","0.02519"
"83.01600","6.91813","0.02517"
"83.08800","6.92423","0.02515"
"83.16000","6.93015","0.02518"
"83.23200","6.93612","0.02541"
"83.30400","6.94210","0.02542"
"83.37600","6.94820","0.02550"
"83.44800","6.95418","0.02540"
"83.52000","6.96022","0.02521"
"83.59200","6.96620","0.02542"
"83.66400","6.97224","0.02538"
"83.73600","6.97816","0.02495"
"83.80800","6.98420","0.02525"
"83.88000","6.99011","0.02508"
"83.95200","6.99621","0.02512"
"84.02400","7.00219","0.02551"
"84.09600","7.00823","0.02526"
"84.16800","7.01421","0.02531"
"84.24000","7.02025","0.02490"
"84.31200","7.02617","0.02523"
"84.38400","7.03221","0.02564"
"84.45600","7.03818","0.02558"
"84.52800","7.04422","0.02516"
"84.60000","7.05026","0.02507"
"84.67200","7.05624","0.02529"
"84.74400","7.06222","0.02498"
"84.81600","7.06820","0.02533"
"84.88800","7.07418","0.02550"
"84.96000","7.08016","0.02498"
"85.03200","7.08620","0.02515"
"85.10400","7.09223","0.02517"
"85.17600","7.09815","0.02537"
"85.24800","7.10419","0.02527"
"85.32000","7.11011","0.02495"
"85.39200","7.11615","0.02537"
"85.46400","7.12207","0.02525"
"85.53600","7.12817","0.02516"
"85.60800","7.13415","0.02502"
"85.68000","7.14019","0.02540"
"85.75200","7.14622","0.02488"
"85.82400","7.15220","0.02530"
"85.89600","7.15812","0.02542"
"85.96800","7.16416","0.02533"
"86.04000","7.17014","0.02521"
"86.11200","7.17618","0.02551"
"86.18400","7.18216","0.02539"
"86.25600","7.18820","0.02528"
"86.32800","7.19418","0.02547"
"86.40000","7.20015","0.02522"
"86.47200","7.20613","0.02529"
"86.54400","7.21211","0.02519"
"86.61600","7.21815","0.02510"
"86.68800","7.22425","0.02517"
"86.76000","7.23017","0.02508"
"86.83200","7.23615","0.02555"
"86.90400","7.24219","0.02518"
"86.97600","7.24823","0.02544"
"87.04800","7.25409","0.02508"
"87.12000","7.26018","0.02505"
"87.19200","7.26616","0.02496"
"87.26400","7.27220","0.02527"
"87.33600","7.27818","0.02534"
"87.40800","7.28422","0.02514"
"87.48000","7.29014","0.02486"
"87.55200","7.29612","0.02536"
"87.62400","7.30210","0.02535"
"87.69600","7.30819","0.02489"
"87.76800","7.31417","0.02557"
"87.84000","7.32021","0.02535"
"87.91200","7.32619","0.02520"
"87.98400","7.33217","0.02540"
"88.05600","7.33809","0.02517"
"88.12800","7.34413","0.02516"
"88.20000","7.35011","0.02491"
"88.27200","7.35620","0.02519"
"88.34400","7.36218","0.02513"
"88.41600","7.36816","0.02539"
"88.48800","7.37420","0.02573"
"88.56000","7.38018","0.02544"
"88.63200","7.38616","0.02510"
"88.70400","7.39214","0.02515"
"88.77600","7.39818","0.02548"
"88.84800","7.40422","0.02500"
"88.92000","7.41020","0.02526"
"88.99200","7.41623","0.02531"
"89.06400","7.42215","0.02511"
"89.13600","7.42819","0.02535"
"89.20800","7.43417","0.02511"
"89.28000","7.44015","0.02495"
"89.35200","7.44613","0.02544"
"89.42400","7.45223","0.02530"
"89.49600","7.45821","0.02565"
"89.56800","7.46418","0.02512"
"89.64000","7.47016","0.02528"
"89.71200","7.47614","0.02427"
"89.78400","7.48212","0.02521"
"89.85600","7.48816","0.02527"
"89.92800","7.49414","0.02503"
"90.00000","7.50018","0.02504"
"90.07200","7.50622","0.02491"
"90.14400","7.51220","0.02509"
"90.21600","7.51818","0.02574"
"90.28800","7.52415","0.02559"
"90.36000","7.53013","0.02514"
"90.43200","7.53623","0.02509"
"90.50400","7.54221","0.02529"
"90.57600","7.54819","0.02539"
"90.64800","7.55417","0.02514"
"90.72000","7.56021","0.02543"
"90.79200","7.56613","0.02513"
"90.86400","7.57210","0.02540"
"90.93600","7.57814","0.02522"
"91.00800","7.58418","0.02529"
"91.08000","7.59022","0.02496"
"91.15200","7.59620","0.02476"
"91.22400","7.60218","0.02541"
"91.29600","7.60816","0.02492"
"91.36800","7.61414","0.02538"
"91.44000","7.62018","0.02539"
"91.51200","7.62616","0.02530"
"91.58400","7.63213","0.02538"
"91.65600","7.63817","0.02495"
"91.72800","7.64421","0.02565"
"91.80000","7.65019","0.02530"
"91.87200","7.65611","0.02488"
"91.94400","7.66215","0.02493"
"92.01600","7.66819","0.02513"
"92.08800","7.67417","0.02543"
"92.16000","7.68021","0.02500"
"92.23200","7.68618","0.02528"
"92.30400","7.69222","0.02523"
"92.37600","7.69820","0.02542"
"92.44800","7.70412","0.02545"
"92.52000","7.71016","0.02539"
"92.59200","7.71620","0.02535"
"92.66400","7.72218","0.02554"
"92.73600","7.72816","0.02541"
"92.80800","7.73420","0.02544"
"92.88000","7.74017","0.02537"
"92.95200","7.74615","0.02519"
"93.02400","7.75213","0.02521"
"93.09600","7.75817","0.02516"
"93.16800","7.76421","0.02529"
"93.24000","7.77019","0.02525"
"93.31200","7.77617","0.02531"
"93.38400","7.78215","0.02555"
"93.45600","7.78813","0.02534"
"93.52800","7.79410","0.02533"
"93.60000","7.80014","0.02532"
"93.67200","7.80618","0.02569"
"93.74400","7.81216","0.02513"
"93.81600","7.81814","0.02541"
"93.88800","7.82412","0.02559"
"93.96000","7.83016","0.02530"
"94.03200","7.83614","0.02525"
"94.10400","7.84211","0.02518"
"94.17600","7.84815","0.02533"
"94.24800","7.85419","0.02497"
"94.32000","7.86017","0.02496"
"94.39200","7.86621","0.02565"
"94.46400","7.87213","0.02504"
"94.53600","7.87817","0.02532"
"94.60800","7.88415","0.02555"
"94.68000","7.89019","0.02538"
"94.75200","7.89616","0.02564"
"94.82400","7.90220","0.02545"
"94.89600","7.90818","0.02558"
"94.96800","7.91422","0.02590"
"95.04000","7.92014","0.02488"
"95.11200","7.92612","0.02547"
"95.18400","7.93216","0.02538"
"95.25600","7.93820","0.02543"
"95.32800","7.94418","0.02574"
"95.40000","7.95021","0.02541"
"95.47200","7.95625","0.02558"
"95.54400","7.96223","0.02529"
"95.61600","7.96815","0.02540"
"95.68800","7.97413","0.02519"
"95.76000","7.98017","0.02583"
"95.83200","7.98627","0.02571"
"95.90400","7.99219","0.02522"
"95.97600","7.99817","0.02517"
"96.04800","8.00420","0.02542"
"96.12000","8.01018","0.02522"
"96.19200","8.01610","0.02563"
"96.26400","8.02214","0.02532"
"96.33600","8.02818","0.02508"
"96.40800","8.03422","0.02515"
"96.48000","8.04020","0.02571"
"96.55200","8.04624","0.02585"
"96.62400","8.05221","0.02558"
"96.69600","8.05819","0.02552"
"96.76800","8.06411","0.02544"
"96.84000","8.07021","0.02542"
"96.91200","8.07619","0.02553"
"96.98400","8.08223","0.02573"
"97.05600","8.08821","0.02595"
"97.12800","8.09425","0.02556"
"97.20000","8.10017","0.02491"
"97.27200","8.10614","0.02564"
"97.34400","8.11218","0.02532"
"97.41600","8.11816","0.02541"
"97.48800","8.12426","0.02565"
"97.56000","8.13018","0.02557"
"97.63200","8.13622","0.02526"
"97.70400","8.14220","0.02571"
"97.77600","8.14818","0.02556"
"97.84800","8.15416","0.02544"
"97.92000","8.16020","0.02547"
"97.99200","8.16617","0.02545"
"98.06400","8.17221","0.02568"
"98.13600","8.17819","0.02604"
"98.20800","8.18417","0.02536"
"98.28000","8.19015","0.02522"
"98.35200","8.19613","0.02559"
"98.42400","8.20217","0.02558"
"98.49600","8.20815","0.02564"
"98.56800","8.21418","0.02559"
"98.64000","8.22016","0.02565"
"98.71200","8.22626","0.02530"
"98.78400","8.23212","0.02561"
"98.85600","8.23816","0.02567"
"98.92800","8.24408","0.02580"
"99.00000","8.25018","0.02527"
"99.07200","8.25616","0.02541"
"99.14400","8.26226","0.02573"
"99.21600","8.26823","0.02558"
"99.28800","8.27421","0.02546"
"99.36000","8.28013","0.02613"
"99.43200","8.28617","0.02536"
"99.50400","8.29215","0.02537"
"99.57600","8.29819","0.02579"
"99.64800","8.30417","0.02564"
"99.72000","8.31021","0.02577"
"99.79200","8.31625","0.02552"
"99.86400","8.32222","0.02539"
"99.93600","8.32814","0.02574"
"100.00800","8.33418","0.02619"
"100.08000","8.34016","0.02616"
"100.15200","8.34620","0.02613"
"100.22400","8.35212","0.02545"
"100.29600","8.35822","0.02460"
"100.36800","8.36420","0.02680"
"100.44000","8.37012","0.02667"
"100.51200","8.37603","0.02545"
"100.58400","8.38219","0.02550"
"100.65600","8.38817","0.02539"
"100.72800","8.39427","0.02570"
"100.80000","8.40013","0.02618"
"100.87200","8.40623","0.02541"
"100.94400","8.41221","0.02525"
"101.01600","8.41819","0.02719"
"101.08800","8.42411","0.02905"
"101.16000","8.43014","0.02699"
"101.23200","8.43618","0.02511"
"101.30400","8.44222","0.02540"
"101.37600","8.44820","0.02839"
"101.44800","8.45418","0.03034"
"101.52000","8.46022","0.02395"
"101.59200","8.46614","0.02577"
"101.66400","8.47218","0.02498"
"101.73600","8.47822","0.02372"
"101.80800","8.48425","0.02471"
"101.88000","8.49017","0.02547"
"101.95200","8.49621","0.02562"
"102.02400","8.50219","0.02519"
"102.09600","8.50817","0.02497"
"102.16800","8.51421","0.02519"
"102.24000","8.52019","0.02474"
"102.31200","8.52629","0.02454"
"102.38400","8.53215","0.02426"
"102.45600","8.53819","0.02459"
"102.52800","8.54416","0.02487"
"102.60000","8.55020","0.02427"
"102.67200","8.55612","0.02415"
"102.74400","8.56222","0.02467"
"102.81600","8.56814","0.02454"
"102.88800","8.57418","0.02449"
"102.96000","8.58016","0.02473"
"103.03200","8.58619","0.02438"
"103.10400","8.59211","0.02442"
"103.17600","8.59815","0.02444"
"103.24800","8.60413","0.02485"
"103.32000","8.61023","0.02465"
"103.39200","8.61621","0.02495"
"103.46400","8.62225","0.02481"
"103.53600","8.62817","0.02461"
"103.60800","8.63421","0.02457"
"103.68000","8.64013","0.02476"
"103.75200","8.64616","0.02520"
"103.82400","8.65214","0.02488"
"103.89600","8.65824","0.02518"
"103.96800","8.66416","0.02519"
"104.04000","8.67020","0.02487"
"104.11200","8.67618","0.02489"
"104.18400","8.68222","0.02521"
"104.25600","8.68814","0.02500"
"104.32800","8.69418","0.02506"
"104.40000","8.70015","0.02485"
"104.47200","8.70625","0.02434"
"104.54400","8.71211","0.02470"
"104.61600","8.71821","0.02466"
"104.68800","8.72413","0.02477"
"104.76000","8.73017","0.02457"
"104.83200","8.73609","0.02519"
"104.90400","8.74219","0.02472"
"104.97600","8.74817","0.02479"
"105.04800","8.75420","0.02453"
"105.12000","8.76024","0.02482"
"105.19200","8.76616","0.02543"
"105.26400","8.77220","0.02520"
"105.33600","8.77818","0.02502"
"105.40800","8.78410","0.02488"
"105.48000","8.79014","0.02487"
"105.55200","8.79618","0.02496"
"105.62400","8.80216","0.02511"
"105.69600","8.80819","0.02512"
"105.76800","8.81417","0.02507"
"105.84000","8.82015","0.02493"
"105.91200","8.82613","0.02477"
"105.98400","8.83211","0.02520"
"106.02000","8.83516","0.02538"