File: Force_trajectories/170121_1/Specimen_RawData_2.csv
End date,"1/21/2017"
Specimen label,"19AG_56"
Maximum Load,"0.16689",N

Time,Extension,Load
(s),(mm),(N)
"0.00000","0.00000","-0.00031"
"0.45000","0.03779","0.00161"
"0.90000","0.07522","0.00291"
"1.35000","0.11264","0.00494"
"1.80000","0.15025","0.00490"
"2.25000","0.18774","0.00540"
"2.70000","0.22523","0.00647"
"3.15000","0.26272","0.00699"
"3.60000","0.30014","0.00744"
"4.05000","0.33769","0.00716"
"4.50000","0.37518","0.00716"
"4.95000","0.41273","0.00791"
"5.40000","0.45027","0.00795"
"5.85000","0.48764","0.00813"
"6.30000","0.52519","0.00850"
"6.75000","0.56268","0.00837"
"7.20000","0.60023","0.00880"
"7.65000","0.63766","0.00879"
"8.10000","0.67514","0.00865"
"8.55000","0.71275","0.00888"
"9.00000","0.75018","0.00898"
"9.45000","0.78767","0.00949"
"9.90000","0.82516","0.00943"
"10.35000","0.86270","0.00939"
"10.80000","0.90019","0.00981"
"11.25000","0.93768","0.00988"
"11.70000","0.97523","0.01021"
"12.15000","1.01272","0.01004"
"12.60000","1.05020","0.00975"
"13.05000","1.08769","0.01011"
"13.50000","1.12518","0.00962"
"13.95000","1.16273","0.01035"
"14.40000","1.20016","0.01007"
"14.85000","1.23764","0.01043"
"15.30000","1.27513","0.01031"
"15.75000","1.31274","0.01057"
"16.20000","1.35023","0.01078"
"16.65000","1.38771","0.01020"
"17.10000","1.42520","0.01026"
"17.55000","1.46263","0.01087"
"18.00000","1.50018","0.01115"
"18.45000","1.53779","0.01105"
"18.90000","1.57522","0.01097"
"19.35000","1.61276","0.01096"
"19.80000","1.65019","0.01080"
"20.25000","1.68762","0.01119"
"20.70000","1.72517","0.01139"
"21.15000","1.76271","0.01116"
"21.60000","1.80026","0.01129"
"22.05000","1.83775","0.01155"
"22.50000","1.87524","0.01148"
"22.95000","1.91267","0.01141"
"23.40000","1.95022","0.01150"
"23.85000","1.98770","0.01161"
"24.30000","2.02519","0.01149"
"24.75000","2.06274","0.01159"
"25.20000","2.10023","0.01134"
"25.65000","2.13766","0.01165"
"26.10000","2.17514","0.01184"
"26.55000","2.21269","0.01181"
"27.00000","2.25024","0.01189"
"27.45000","2.28767","0.01142"
"27.90000","2.32521","0.01184"
"28.35000","2.36264","0.01157"
"28.80000","2.40019","0.01163"
"29.25000","2.43768","0.01181"
"29.70000","2.47523","0.01234"
"30.15000","2.51272","0.01217"
"30.60000","2.55020","0.01240"
"31.05000","2.58769","0.01205"
"31.50000","2.62518","0.01225"
"31.95000","2.66273","0.01277"
"32.40000","2.70021","0.01218"
"32.85000","2.73770","0.01239"
"33.30000","2.77513","0.01178"
"33.75000","2.81262","0.01197"
"34.20000","2.85017","0.01223"
"34.65000","2.88766","0.01227"
"35.10000","2.92520","0.01192"
"35.55000","2.96269","0.01211"
"36.00000","3.00024","0.01219"
"36.45000","3.03773","0.01133"
"36.90000","3.07516","0.01163"
"37.35000","3.11264","0.01196"
"37.80000","3.15019","0.01130"
"38.25000","3.18774","0.01191"
"38.70000","3.22523","0.01223"
"39.15000","3.26265","0.01183"
"39.60000","3.30014","0.01221"
"40.05000","3.33769","0.01194"
"40.50000","3.37518","0.01237"
"40.95000","3.41267","0.01204"
"41.40000","3.45021","0.01236"
"41.85000","3.48770","0.01232"
"42.30000","3.52513","0.01259"
"42.75000","3.56268","0.01200"
"43.20000","3.60017","0.01265"
"43.65000","3.63771","0.01223"
"44.10000","3.67520","0.01265"
"44.55000","3.71269","0.01301"
"45.00000","3.75018","0.01252"
"45.45000","3.78767","0.01315"
"45.90000","3.82521","0.01295"
"46.35000","3.86270","0.01302"
"46.80000","3.90025","0.01315"
"47.25000","3.93768","0.01296"
"47.70000","3.97511","0.01286"
"48.15000","4.01265","0.01335"
"48.60000","4.05026","0.01317"
"49.05000","4.08775","0.01325"
"49.50000","4.12518","0.01336"
"49.95000","4.16273","0.01347"
"50.40000","4.20015","0.01342"
"50.85000","4.23770","0.01399"
"51.30000","4.27519","0.01408"
"51.75000","4.31274","0.01389"
"52.20000","4.35023","0.01403"
"52.65000","4.38765","0.01358"
"53.10000","4.42514","0.01410"
"53.55000","4.46263","0.01429"
"54.00000","4.50018","0.01398"
"54.45000","4.53773","0.01467"
"54.90000","4.57521","0.01497"
"55.35000","4.61270","0.01462"
"55.80000","4.65013","0.01497"
"56.25000","4.68768","0.01528"
"56.70000","4.72517","0.01535"
"57.15000","4.76271","0.01504"
"57.60000","4.80020","0.01519"
"58.05000","4.83775","0.01586"
"58.50000","4.87518","0.01567"
"58.95000","4.91267","0.01580"
"59.40000","4.95015","0.01521"
"59.85000","4.98770","0.01581"
"60.30000","5.02519","0.01617"
"60.75000","5.06268","0.01594"
"61.20000","5.10023","0.01642"
"61.65000","5.13771","0.01593"
"62.10000","5.17520","0.01712"
"62.55000","5.21275","0.01631"
"63.00000","5.25018","0.01703"
"63.45000","5.28773","0.01675"
"63.90000","5.32515","0.01689"
"64.35000","5.36264","0.01777"
"64.80000","5.40019","0.01743"
"65.25000","5.43774","0.01771"
"65.70000","5.47523","0.01785"
"66.15000","5.51271","0.01836"
"66.60000","5.55020","0.01904"
"67.05000","5.58757","0.01884"
"67.50000","5.62518","0.01835"
"67.95000","5.66273","0.01887"
"68.40000","5.70021","0.01890"
"68.85000","5.73776","0.01860"
"69.30000","5.77519","0.01963"
"69.75000","5.81268","0.01885"
"70.20000","5.85011","0.01974"
"70.65000","5.88771","0.01938"
"71.10000","5.92520","0.01883"
"71.55000","5.96275","0.01921"
"72.00000","6.00024","0.01975"
"72.45000","6.03767","0.02035"
"72.90000","6.07515","0.01977"
"73.35000","6.11264","0.01996"
"73.80000","6.15019","0.02009"
"74.25000","6.18774","0.02025"
"74.70000","6.22517","0.02048"
"75.15000","6.26271","0.02042"
"75.60000","6.30014","0.02123"
"76.05000","6.33775","0.02203"
"76.50000","6.37524","0.02142"
"76.95000","6.41273","0.02145"
"77.40000","6.45021","0.02178"
"77.85000","6.48764","0.02197"
"78.30000","6.52519","0.02238"
"78.75000","6.56274","0.02215"
"79.20000","6.60023","0.02271"
"79.65000","6.63771","0.02290"
"80.10000","6.67520","0.02244"
"80.55000","6.71263","0.02244"
"81.00000","6.75018","0.02307"
"81.45000","6.78773","0.02347"
"81.90000","6.82521","0.02410"
"82.35000","6.86270","0.02367"
"82.80000","6.90019","0.02382"
"83.25000","6.93768","0.02466"
"83.70000","6.97517","0.02472"
"84.15000","7.01265","0.02442"
"84.60000","7.05026","0.02465"
"85.05000","7.08775","0.02478"
"85.50000","7.12518","0.02522"
"85.95000","7.16267","0.02535"
"86.40000","7.20009","0.02516"
"86.85000","7.23764","0.02562"
"87.30000","7.27525","0.02560"
"87.75000","7.31268","0.02611"
"88.20000","7.35023","0.02588"
"88.65000","7.38771","0.02613"
"89.10000","7.42514","0.02606"
"89.55000","7.46269","0.02709"
"90.00000","7.50018","0.02646"
"90.45000","7.53773","0.02668"
"90.90000","7.57521","0.02610"
"91.35000","7.61264","0.02714"
"91.80000","7.65013","0.02729"
"92.25000","7.68768","0.02779"
"92.70000","7.72523","0.02786"
"93.15000","7.76271","0.02761"
"93.60000","7.80020","0.02790"
"94.05000","7.83769","0.02773"
"94.50000","7.87518","0.02873"
"94.95000","7.91267","0.02906"
"95.40000","7.95021","0.02935"
"95.85000","7.98770","0.02952"
"96.30000","8.02519","0.02956"
"96.75000","8.06274","0.03000"
"97.20000","8.10011","0.02955"
"97.65000","8.13771","0.02992"
"98.10000","8.17526","0.02948"
"98.55000","8.21275","0.03033"
"99.00000","8.25024","0.03041"
"99.45000","8.28767","0.03089"
"99.90000","8.32515","0.03107"
"100.35000","8.36264","0.03063"
"100.80000","8.40019","0.03031"
"101.25000","8.43774","0.03109"
"101.70000","8.47523","0.03112"
"102.15000","8.51271","0.03090"
"102.60000","8.55020","0.03073"
"103.05000","8.58769","0.03135"
"103.50000","8.62518","0.03194"
"103.95000","8.66273","0.03196"
"104.40000","8.70021","0.03053"
"104.85000","8.73776","0.03068"
"105.30000","8.77519","0.02988"
"105.75000","8.81262","0.03151"
"106.20000","8.85017","0.03149"
"106.65000","8.88771","0.03202"
"107.10000","8.92520","0.03175"
"107.55000","8.96269","0.03257"
"108.00000","9.00018","0.03167"
"108.45000","9.03767","0.03179"
"108.90000","9.07521","0.03162"
"109.35000","9.11270","0.03068"
"109.80000","9.15013","0.03145"
"110.25000","9.18768","0.03219"
"110.70000","9.22523","0.03131"
"111.15000","9.26271","0.03211"
"111.60000","9.30020","0.03202"
"112.05000","9.33763","0.03166"
"112.50000","9.37518","0.03258"
"112.95000","9.41273","0.03322"
"113.40000","9.45021","0.03250"
"113.85000","9.48764","0.03044"
"114.30000","9.52519","0.03081"
"114.75000","9.56274","0.03119"
"115.20000","9.60029","0.03008"
"115.65000","9.63777","0.02895"
"116.10000","9.67520","0.03051"
"116.55000","9.71263","0.03002"
"117.00000","9.75018","0.02998"
"117.45000","9.78773","0.03014"
"117.90000","9.82521","0.03083"
"118.35000","9.86270","0.03070"
"118.80000","9.90019","0.03098"
"119.25000","9.93762","0.03105"
"119.70000","9.97522","0.03130"
"120.15000","10.01271","0.03116"
"120.60000","10.05020","0.03117"
"121.05000","10.08769","0.03162"
"121.50000","10.12524","0.03145"
"121.95000","10.16267","0.03177"
"122.40000","10.20015","0.03197"
"122.85000","10.23770","0.03096"
"123.30000","10.27525","0.03213"
"123.75000","10.31274","0.03170"
"124.20000","10.35023","0.03206"
"124.65000","10.38765","0.03251"
"125.10000","10.42514","0.03333"
"125.55000","10.46275","0.03294"
"126.00000","10.50024","0.03084"
"126.45000","10.53767","0.03094"
"126.90000","10.57515","0.03165"
"127.35000","10.61264","0.03207"
"127.80000","10.65019","0.03307"
"128.25000","10.68774","0.03309"
"128.70000","10.72523","0.03263"
"129.15000","10.76271","0.03324"
"129.60000","10.80020","0.03339"
"130.05000","10.83763","0.03276"
"130.50000","10.87518","0.03334"
"130.95000","10.91273","0.03343"
"131.40000","10.95021","0.03374"
"131.85000","10.98770","0.03294"
"132.30000","11.02525","0.03347"
"132.75000","11.06262","0.03388"
"133.20000","11.10017","0.03360"
"133.65000","11.13771","0.03393"
"134.10000","11.17526","0.03359"
"134.55000","11.21275","0.03361"
"135.00000","11.25018","0.03303"
"135.45000","11.28767","0.03248"
"135.90000","11.32515","0.03128"
"136.35000","11.36270","0.03273"
"136.80000","11.40019","0.03184"
"137.25000","11.43768","0.03221"
"137.70000","11.47523","0.03111"
"138.15000","11.51271","0.03124"
"138.60000","11.55020","0.03087"
"139.05000","11.58769","0.03101"
"139.50000","11.62524","0.03132"
"139.95000","11.66267","0.03168"
"140.40000","11.70021","0.03208"
"140.85000","11.73770","0.03217"
"141.30000","11.77519","0.03251"
"141.75000","11.81268","0.03327"
"142.20000","11.85017","0.03346"
"142.65000","11.88771","0.03306"
"143.10000","11.92520","0.03401"
"143.55000","11.96263","0.03392"
"144.00000","12.00012","0.03449"
"144.45000","12.03761","0.03512"
"144.90000","12.07521","0.03512"
"145.35000","12.11270","0.03399"
"145.80000","12.15019","0.03393"
"146.25000","12.18768","0.03298"
"146.70000","12.22517","0.03292"
"147.15000","12.26265","0.03443"
"147.60000","12.30026","0.03354"
"148.05000","12.33769","0.03398"
"148.50000","12.37524","0.03437"
"148.95000","12.41273","0.03380"
"149.40000","12.45009","0.03446"
"149.85000","12.48764","0.03553"
"150.30000","12.52519","0.03546"
"150.75000","12.56274","0.03599"
"151.20000","12.60029","0.03601"
"151.65000","12.63771","0.03635"
"152.10000","12.67520","0.03579"
"152.55000","12.71269","0.03609"
"153.00000","12.75018","0.03668"
"153.45000","12.78772","0.03700"
"153.90000","12.82521","0.03654"
"154.35000","12.86270","0.03722"
"154.80000","12.90019","0.03692"
"155.25000","12.93768","0.03733"
"155.70000","12.97523","0.03701"
"156.15000","13.01271","0.03733"
"156.60000","13.05020","0.03777"
"157.05000","13.08775","0.03757"
"157.50000","13.12518","0.03741"
"157.95000","13.16267","0.03778"
"158.40000","13.20021","0.03875"
"158.85000","13.23770","0.03846"
"159.30000","13.27525","0.03859"
"159.75000","13.31268","0.03903"
"160.20000","13.35017","0.03897"
"160.65000","13.38771","0.03966"
"161.10000","13.42526","0.03947"
"161.55000","13.46275","0.03931"
"162.00000","13.50024","0.04005"
"162.45000","13.53767","0.03941"
"162.90000","13.57515","0.03913"
"163.35000","13.61270","0.03995"
"163.80000","13.65019","0.03941"
"164.25000","13.68774","0.03989"
"164.70000","13.72517","0.04023"
"165.15000","13.76271","0.04027"
"165.60000","13.80020","0.04070"
"166.05000","13.83763","0.04132"
"166.50000","13.87518","0.04120"
"166.95000","13.91273","0.04139"
"167.40000","13.95021","0.04104"
"167.85000","13.98770","0.04158"
"168.30000","14.02513","0.04185"
"168.75000","14.06262","0.04218"
"169.20000","14.10017","0.04148"
"169.65000","14.13771","0.04186"
"170.10000","14.17520","0.04254"
"170.55000","14.21275","0.04121"
"171.00000","14.25018","0.04161"
"171.45000","14.28767","0.04143"
"171.90000","14.32515","0.04173"
"172.35000","14.36270","0.04205"
"172.80000","14.40025","0.04232"
"173.25000","14.43768","0.04253"
"173.70000","14.47523","0.04249"
"174.15000","14.51271","0.04301"
"174.60000","14.55014","0.04293"
"175.05000","14.58775","0.04290"
"175.50000","14.62518","0.04335"
"175.95000","14.66272","0.04327"
"176.40000","14.70015","0.04410"
"176.85000","14.73764","0.04298"
"177.30000","14.77519","0.04325"
"177.75000","14.81274","0.04340"
"178.20000","14.85023","0.04323"
"178.65000","14.88765","0.04357"
"179.10000","14.92520","0.04288"
"179.55000","14.96263","0.04426"
"180.00000","15.00018","0.04412"
"180.45000","15.03767","0.04516"
"180.90000","15.07521","0.04449"
"181.35000","15.11276","0.04334"
"181.80000","15.15019","0.04320"
"182.25000","15.18768","0.04412"
"182.70000","15.22511","0.04355"
"183.15000","15.26265","0.04379"
"183.60000","15.30026","0.04423"
"184.05000","15.33769","0.04396"
"184.50000","15.37524","0.04486"
"184.95000","15.41267","0.04455"
"185.40000","15.45015","0.04509"
"185.85000","15.48764","0.04521"
"186.30000","15.52519","0.04535"
"186.75000","15.56274","0.04564"
"187.20000","15.60023","0.04573"
"187.65000","15.63765","0.04530"
"188.10000","15.67514","0.04581"
"188.55000","15.71263","0.04558"
"189.00000","15.75018","0.04514"
"189.45000","15.78772","0.04568"
"189.90000","15.82521","0.04617"
"190.35000","15.86276","0.04686"
"190.80000","15.90019","0.04613"
"191.25000","15.93774","0.04650"
"191.70000","15.97522","0.04658"
"192.15000","16.01271","0.04646"
"192.60000","16.05020","0.04695"
"193.05000","16.08769","0.04726"
"193.50000","16.12512","0.04682"
"193.95000","16.16267","0.04675"
"194.40000","16.20027","0.04705"
"194.85000","16.23770","0.04749"
"195.30000","16.27519","0.04714"
"195.75000","16.31268","0.04714"
"196.20000","16.35011","0.04769"
"196.65000","16.38771","0.04791"
"197.10000","16.42520","0.04799"
"197.55000","16.46275","0.04836"
"198.00000","16.50024","0.04825"
"198.45000","16.53766","0.04657"
"198.90000","16.57515","0.04147"
"199.35000","16.61264","0.04134"
"199.80000","16.65025","0.04069"
"200.25000","16.68774","0.03960"
"200.70000","16.72523","0.03944"
"201.15000","16.76265","0.03758"
"201.60000","16.80014","0.03362"
"202.05000","16.83769","0.03326"
"202.50000","16.87518","0.03512"
"202.95000","16.91273","0.03502"
"203.40000","16.95021","0.03607"
"203.85000","16.98770","0.03703"
"204.30000","17.02519","0.03812"
"204.75000","17.06268","0.03689"
"205.20000","17.10022","0.03730"
"205.65000","17.13771","0.03823"
"206.10000","17.17520","0.03873"
"206.55000","17.21269","0.03923"
"207.00000","17.25018","0.03953"
"207.45000","17.28766","0.03964"
"207.90000","17.32521","0.04071"
"208.35000","17.36270","0.04095"
"208.80000","17.40019","0.04120"
"209.25000","17.43774","0.04229"
"209.70000","17.47517","0.04281"
"210.15000","17.51265","0.04319"
"210.60000","17.55026","0.04280"
"211.05000","17.58775","0.04297"
"211.50000","17.62518","0.04365"
"211.95000","17.66272","0.04327"
"212.40000","17.70015","0.04311"
"212.85000","17.73770","0.04238"
"213.30000","17.77519","0.03700"
"213.75000","17.81274","0.03719"
"214.20000","17.85022","0.03755"
"214.65000","17.88771","0.03927"
"215.10000","17.92520","0.03949"
"215.55000","17.96263","0.03994"
"216.00000","18.00012","0.03869"
"216.45000","18.03773","0.03910"
"216.90000","18.07521","0.03828"
"217.35000","18.11276","0.03791"
"217.80000","18.15019","0.03824"
"218.25000","18.18762","0.03960"
"218.70000","18.22516","0.04000"
"219.15000","18.26271","0.04050"
"219.60000","18.30020","0.04110"
"220.05000","18.33769","0.04141"
"220.50000","18.37518","0.04169"
"220.95000","18.41261","0.04266"
"221.40000","18.45015","0.04301"
"221.85000","18.48770","0.04372"
"222.30000","18.52519","0.04417"
"222.75000","18.56274","0.04461"
"223.20000","18.60023","0.04444"
"223.65000","18.63765","0.04456"
"224.10000","18.67514","0.04469"
"224.55000","18.71269","0.04487"
"225.00000","18.75024","0.04558"
"225.45000","18.78773","0.04606"
"225.90000","18.82521","0.04614"
"226.35000","18.86264","0.04549"
"226.80000","18.90019","0.04533"
"227.25000","18.93774","0.04576"
"227.70000","18.97522","0.04651"
"228.15000","19.01271","0.04716"
"228.60000","19.05020","0.04707"
"229.05000","19.08763","0.04730"
"229.50000","19.12518","0.04762"
"229.95000","19.16273","0.04812"
"230.40000","19.20027","0.04741"
"230.85000","19.23776","0.04736"
"231.30000","19.27519","0.04519"
"231.75000","19.31268","0.04408"
"232.20000","19.35023","0.04389"
"232.65000","19.38765","0.04384"
"233.10000","19.42526","0.04434"
"233.55000","19.46269","0.04493"
"234.00000","19.50024","0.04450"
"234.45000","19.53773","0.04424"
"234.90000","19.57509","0.04401"
"235.35000","19.61264","0.04249"
"235.80000","19.65019","0.04218"
"236.25000","19.68768","0.04329"
"236.70000","19.72522","0.04339"
"237.15000","19.76271","0.04386"
"237.60000","19.80014","0.04426"
"238.05000","19.83769","0.04447"
"238.50000","19.87524","0.04471"
"238.95000","19.91267","0.04441"
"239.40000","19.95015","0.04478"
"239.85000","19.98764","0.04591"
"240.30000","20.02519","0.04512"
"240.75000","20.06274","0.04554"
"241.20000","20.10016","0.04584"
"241.65000","20.13771","0.04621"
"242.10000","20.17520","0.04604"
"242.55000","20.21269","0.04617"
"243.00000","20.25018","0.04643"
"243.45000","20.28766","0.04539"
"243.90000","20.32527","0.04508"
"244.35000","20.36276","0.04632"
"244.80000","20.40025","0.04536"
"245.25000","20.43774","0.04555"
"245.70000","20.47511","0.04599"
"246.15000","20.51265","0.04618"
"246.60000","20.55020","0.04609"
"247.05000","20.58775","0.04682"
"247.50000","20.62518","0.04695"
"247.95000","20.66267","0.04676"
"248.40000","20.70015","0.04696"
"248.85000","20.73770","0.04531"
"249.30000","20.77519","0.04481"
"249.75000","20.81273","0.04512"
"250.20000","20.85022","0.04539"
"250.65000","20.88771","0.04466"
"251.10000","20.92514","0.04476"
"251.55000","20.96263","0.04520"
"252.00000","21.00018","0.04320"
"252.45000","21.03772","0.04465"
"252.90000","21.07521","0.04449"
"253.35000","21.11276","0.04415"
"253.80000","21.15019","0.04410"
"254.25000","21.18768","0.04467"
"254.70000","21.22517","0.04487"
"255.15000","21.26271","0.04517"
"255.60000","21.30014","0.04565"
"256.05000","21.33769","0.04536"
"256.50000","21.37518","0.04582"
"256.95000","21.41266","0.04552"
"257.40000","21.45021","0.04535"
"257.85000","21.48776","0.04636"
"258.30000","21.52519","0.04625"
"258.75000","21.56268","0.04630"
"259.20000","21.60016","0.04603"
"259.65000","21.63765","0.04699"
"260.10000","21.67520","0.04647"
"260.55000","21.71269","0.04645"
"261.00000","21.75024","0.04723"
"261.45000","21.78773","0.04673"
"261.90000","21.82515","0.04713"
"262.35000","21.86270","0.04765"
"262.80000","21.90019","0.04810"
"263.25000","21.93773","0.04825"
"263.70000","21.97523","0.04827"
"264.15000","22.01271","0.04838"
"264.60000","22.05020","0.04833"
"265.05000","22.08763","0.04856"
"265.50000","22.12518","0.04705"
"265.95000","22.16266","0.04683"
"266.40000","22.20021","0.04754"
"266.85000","22.23776","0.04813"
"267.30000","22.27519","0.04818"
"267.75000","22.31268","0.04855"
"268.20000","22.35023","0.04840"
"268.65000","22.38771","0.04823"
"269.10000","22.42520","0.04719"
"269.55000","22.46269","0.04727"
"270.00000","22.50024","0.04632"
"270.45000","22.53766","0.04623"
"270.90000","22.57521","0.04669"
"271.35000","22.61270","0.04637"
"271.80000","22.65025","0.04593"
"272.25000","22.68768","0.04632"
"272.70000","22.72516","0.04596"
"273.15000","22.76265","0.04674"
"273.60000","22.80014","0.04616"
"274.05000","22.83775","0.04689"
"274.50000","22.87518","0.04672"
"274.95000","22.91273","0.04734"
"275.40000","22.95021","0.04729"
"275.85000","22.98764","0.04653"
"276.30000","23.02519","0.04705"
"276.75000","23.06274","0.04668"
"277.20000","23.10016","0.04725"
"277.65000","23.13771","0.04699"
"278.10000","23.17520","0.04734"
"278.55000","23.21263","0.04863"
"279.00000","23.25018","0.04816"
"279.45000","23.28772","0.04841"
"279.90000","23.32527","0.04928"
"280.35000","23.36276","0.04950"
"280.80000","23.40025","0.04936"
"281.25000","23.43768","0.04940"
"281.70000","23.47522","0.05008"
"282.15000","23.51265","0.04991"
"282.60000","23.55020","0.04700"
"283.05000","23.58775","0.04660"
"283.50000","23.62518","0.04728"
"283.95000","23.66266","0.04770"
"284.40000","23.70015","0.04744"
"284.85000","23.73770","0.04798"
"285.30000","23.77525","0.04902"
"285.75000","23.81268","0.04843"
"286.20000","23.85022","0.04855"
"286.65000","23.88771","0.04861"
"287.10000","23.92514","0.04913"
"287.55000","23.96269","0.04859"
"288.00000","24.00024","0.04866"
"288.45000","24.03772","0.04791"
"288.90000","24.07521","0.04827"
"289.35000","24.11270","0.04843"
"289.80000","24.15019","0.04838"
"290.25000","24.18773","0.04711"
"290.70000","24.22516","0.04789"
"291.15000","24.26271","0.04678"
"291.60000","24.30020","0.04472"
"292.05000","24.33763","0.04490"
"292.50000","24.37518","0.04528"
"292.95000","24.41267","0.04567"
"293.40000","24.45021","0.04614"
"293.85000","24.48770","0.04515"
"294.30000","24.52525","0.04604"
"294.75000","24.56268","0.04637"
"295.20000","24.60010","0.04665"
"295.65000","24.63765","0.04732"
"296.10000","24.67520","0.04697"
"296.55000","24.71275","0.04772"
"297.00000","24.75023","0.04822"
"297.45000","24.78761","0.04809"
"297.90000","24.82515","0.04836"
"298.35000","24.86264","0.04866"
"298.80000","24.90019","0.04896"
"299.25000","24.93774","0.04841"
"299.70000","24.97522","0.04889"
"300.15000","25.01271","0.04926"
"300.60000","25.05014","0.04876"
"301.05000","25.08769","0.04957"
"301.50000","25.12518","0.04961"
"301.95000","25.16266","0.04972"
"302.40000","25.20021","0.04986"
"302.85000","25.23776","0.05046"
"303.30000","25.27519","0.05000"
"303.75000","25.31262","0.05064"
"304.20000","25.35022","0.05059"
"304.65000","25.38771","0.05045"
"305.10000","25.42526","0.05099"
"305.55000","25.46269","0.05144"
"306.00000","25.50011","0.05142"
"306.45000","25.53767","0.05065"
"306.90000","25.57521","0.05175"
"307.35000","25.61276","0.05177"
"307.80000","25.65013","0.05215"
"308.25000","25.68774","0.05225"
"308.70000","25.72516","0.05143"
"309.15000","25.76265","0.05206"
"309.60000","25.80020","0.05233"
"310.05000","25.83769","0.05205"
"310.50000","25.87523","0.05203"
"310.95000","25.91266","0.05168"
"311.40000","25.95015","0.05276"
"311.85000","25.98764","0.05271"
"312.30000","26.02519","0.05306"
"312.75000","26.06274","0.05386"
"313.20000","26.10022","0.05407"
"313.65000","26.13771","0.05494"
"314.10000","26.17514","0.05517"
"314.55000","26.21263","0.05593"
"315.00000","26.25018","0.05711"
"315.45000","26.28773","0.05697"
"315.90000","26.32521","0.05731"
"316.35000","26.36270","0.05786"
"316.80000","26.40019","0.05841"
"317.25000","26.43768","0.05885"
"317.70000","26.47523","0.05897"
"318.15000","26.51271","0.05844"
"318.60000","26.55020","0.05859"
"319.05000","26.58769","0.05907"
"319.50000","26.62524","0.05930"
"319.95000","26.66266","0.06027"
"320.40000","26.70021","0.06041"
"320.85000","26.73770","0.06075"
"321.30000","26.77525","0.06113"
"321.75000","26.81274","0.06138"
"322.20000","26.85016","0.06205"
"322.65000","26.88765","0.06192"
"323.10000","26.92514","0.06215"
"323.55000","26.96275","0.06302"
"324.00000","27.00018","0.06341"
"324.45000","27.03773","0.06351"
"324.90000","27.07521","0.06364"
"325.35000","27.11258","0.06194"
"325.80000","27.15019","0.06246"
"326.25000","27.18774","0.06207"
"326.70000","27.22522","0.06256"
"327.15000","27.26277","0.06263"
"327.60000","27.30014","0.06081"
"328.05000","27.33769","0.06175"
"328.50000","27.37512","0.06176"
"328.95000","27.41266","0.06256"
"329.40000","27.45021","0.06209"
"329.85000","27.48776","0.06311"
"330.30000","27.52519","0.03262"
"330.75000","27.56268","0.03236"
"331.20000","27.60016","0.03380"
"331.65000","27.63765","0.03580"
"332.10000","27.67526","0.03659"
"332.55000","27.71275","0.03624"
"333.00000","27.75018","0.03635"
"333.45000","27.78766","0.03636"
"333.90000","27.82515","0.03813"
"334.35000","27.86276","0.03765"
"334.80000","27.90019","0.03797"
"335.25000","27.93768","0.03728"
"335.70000","27.97523","0.03811"
"336.15000","28.01271","0.03888"
"336.60000","28.05014","0.03926"
"337.05000","28.08769","0.04085"
"337.50000","28.12524","0.04108"
"337.95000","28.16273","0.04235"
"338.40000","28.20021","0.04211"
"338.85000","28.23770","0.04297"
"339.30000","28.27519","0.04233"
"339.75000","28.31274","0.04260"
"340.20000","28.35022","0.04372"
"340.65000","28.38771","0.04411"
"341.10000","28.42520","0.04480"
"341.55000","28.46263","0.04571"
"342.00000","28.50012","0.04642"
"342.45000","28.53772","0.04657"
"342.90000","28.57527","0.04680"
"343.35000","28.61270","0.04789"
"343.80000","28.65019","0.04812"
"344.25000","28.68768","0.04916"
"344.70000","28.72511","0.04912"
"345.15000","28.76265","0.04994"
"345.60000","28.80026","0.05055"
"346.05000","28.83769","0.05121"
"346.50000","28.87524","0.05161"
"346.95000","28.91266","0.05263"
"347.40000","28.95009","0.05324"
"347.85000","28.98770","0.05409"
"348.30000","29.02519","0.05468"
"348.75000","29.06274","0.05503"
"349.20000","29.10022","0.05398"
"349.65000","29.13765","0.05511"
"350.10000","29.17514","0.05544"
"350.55000","29.21269","0.05616"
"351.00000","29.25023","0.05641"
"351.45000","29.28773","0.05740"
"351.90000","29.32521","0.05737"
"352.35000","29.36270","0.05764"
"352.80000","29.40019","0.05864"
"353.25000","29.43768","0.05921"
"353.70000","29.47522","0.05948"
"354.15000","29.51271","0.05952"
"354.60000","29.55020","0.06001"
"355.05000","29.58775","0.06146"
"355.50000","29.62512","0.06136"
"355.95000","29.66266","0.06173"
"356.40000","29.70027","0.06247"
"356.85000","29.73770","0.06274"
"357.30000","29.77525","0.06230"
"357.75000","29.81268","0.06185"
"358.20000","29.85016","0.06326"
"358.65000","29.88765","0.06355"
"359.10000","29.92526","0.06467"
"359.55000","29.96275","0.06496"
"360.00000","30.00024","0.06560"
"360.45000","30.03772","0.06607"
"360.90000","30.07521","0.06635"
"361.35000","30.11270","0.06672"
"361.80000","30.15019","0.06652"
"362.25000","30.18774","0.06731"
"362.70000","30.22516","0.06789"
"363.15000","30.26271","0.06850"
"363.60000","30.30020","0.06848"
"364.05000","30.33757","0.06919"
"364.50000","30.37518","0.06916"
"364.95000","30.41272","0.06914"
"365.40000","30.45021","0.07010"
"365.85000","30.48770","0.06980"
"366.30000","30.52519","0.07052"
"366.75000","30.56268","0.07074"
"367.20000","30.60017","0.07089"
"367.65000","30.63771","0.07156"
"368.10000","30.67520","0.07206"
"368.55000","30.71269","0.07286"
"369.00000","30.75018","0.07262"
"369.45000","30.78766","0.06405"
"369.90000","30.82521","0.06361"
"370.35000","30.86270","0.06425"
"370.80000","30.90025","0.06466"
"371.25000","30.93768","0.06574"
"371.70000","30.97516","0.06625"
"372.15000","31.01265","0.06657"
"372.60000","31.05020","0.06627"
"373.05000","31.08775","0.06428"
"373.50000","31.12524","0.06379"
"373.95000","31.16278","0.06391"
"374.40000","31.20021","0.06390"
"374.85000","31.23758","0.06309"
"375.30000","31.27519","0.06360"
"375.75000","31.31273","0.06453"
"376.20000","31.35028","0.06514"
"376.65000","31.38765","0.06620"
"377.10000","31.42520","0.06723"
"377.55000","31.46263","0.06684"
"378.00000","31.50018","0.06686"
"378.45000","31.53772","0.06827"
"378.90000","31.57521","0.06902"
"379.35000","31.61270","0.06932"
"379.80000","31.65018","0.06905"
"380.25000","31.68761","0.06886"
"380.70000","31.72516","0.06988"
"381.15000","31.76265","0.07040"
"381.60000","31.80020","0.07114"
"382.05000","31.83769","0.07116"
"382.50000","31.87523","0.07115"
"382.95000","31.91272","0.07156"
"383.40000","31.95021","0.07203"
"383.85000","31.98770","0.07255"
"384.30000","32.02525","0.07242"
"384.75000","32.06261","0.07250"
"385.20000","32.10022","0.07224"
"385.65000","32.13765","0.07297"
"386.10000","32.17520","0.07298"
"386.55000","32.21268","0.07311"
"387.00000","32.25023","0.07185"
"387.45000","32.28772","0.07269"
"387.90000","32.32521","0.07278"
"388.35000","32.36264","0.07318"
"388.80000","32.40019","0.07269"
"389.25000","32.43773","0.07312"
"389.70000","32.47522","0.07358"
"390.15000","32.51271","0.07369"
"390.60000","32.55020","0.07269"
"391.05000","32.58768","0.07253"
"391.50000","32.62518","0.07282"
"391.95000","32.66266","0.07311"
"392.40000","32.70027","0.07270"
"392.85000","32.73770","0.07178"
"393.30000","32.77518","0.07141"
"393.75000","32.81268","0.07097"
"394.20000","32.85010","0.07148"
"394.65000","32.88771","0.07213"
"395.10000","32.92520","0.07180"
"395.55000","32.96269","0.07235"
"396.00000","33.00023","0.07187"
"396.45000","33.03772","0.06993"
"396.90000","33.07521","0.06993"
"397.35000","33.11270","0.07027"
"397.80000","33.15018","0.07039"
"398.25000","33.18768","0.07145"
"398.70000","33.22522","0.07189"
"399.15000","33.26271","0.07230"
"399.60000","33.30014","0.07306"
"400.05000","33.33768","0.07265"
"400.50000","33.37518","0.07318"
"400.95000","33.41272","0.07423"
"401.40000","33.45021","0.07495"
"401.85000","33.48770","0.07550"
"402.30000","33.52513","0.07509"
"402.75000","33.56261","0.07618"
"403.20000","33.60022","0.07693"
"403.65000","33.63771","0.07774"
"404.10000","33.67520","0.07826"
"404.55000","33.71268","0.07794"
"405.00000","33.75017","0.07807"
"405.45000","33.78766","0.07799"
"405.90000","33.82521","0.07884"
"406.35000","33.86270","0.08007"
"406.80000","33.90025","0.08052"
"407.25000","33.93773","0.08116"
"407.70000","33.97510","0.08168"
"408.15000","34.01265","0.08252"
"408.60000","34.05020","0.08215"
"409.05000","34.08775","0.08006"
"409.50000","34.12524","0.08101"
"409.95000","34.16272","0.08167"
"410.40000","34.20015","0.08272"
"410.85000","34.23770","0.08160"
"411.30000","34.27518","0.08265"
"411.75000","34.31273","0.08314"
"412.20000","34.35022","0.08479"
"412.65000","34.38771","0.08624"
"413.10000","34.42514","0.08654"
"413.55000","34.46269","0.08686"
"414.00000","34.50018","0.08779"
"414.45000","34.53772","0.08924"
"414.90000","34.57515","0.08559"
"415.35000","34.61276","0.08704"
"415.80000","34.65019","0.08886"
"416.25000","34.68768","0.08995"
"416.70000","34.72516","0.09132"
"417.15000","34.76271","0.09241"
"417.60000","34.80020","0.09202"
"418.05000","34.83768","0.08750"
"418.50000","34.87517","0.08658"
"418.95000","34.91267","0.08685"
"419.40000","34.95021","0.08669"
"419.85000","34.98770","0.08803"
"420.30000","35.02519","0.08797"
"420.75000","35.06268","0.08782"
"421.20000","35.10016","0.08846"
"421.65000","35.13765","0.08997"
"422.10000","35.17520","0.09026"
"422.55000","35.21275","0.08953"
"423.00000","35.25018","0.09105"
"423.45000","35.28772","0.09264"
"423.90000","35.32521","0.09286"
"424.35000","35.36264","0.09414"
"424.80000","35.40018","0.09406"
"425.25000","35.43773","0.09544"
"425.70000","35.47522","0.09632"
"426.15000","35.51271","0.09642"
"426.60000","35.55014","0.09625"
"427.05000","35.58763","0.09616"
"427.50000","35.62518","0.09713"
"427.95000","35.66272","0.09818"
"428.40000","35.70021","0.09964"
"428.85000","35.73775","0.10112"
"429.30000","35.77525","0.10247"
"429.75000","35.81268","0.10105"
"430.20000","35.85016","0.09779"
"430.65000","35.88765","0.09738"
"431.10000","35.92514","0.09775"
"431.55000","35.96268","0.09586"
"432.00000","36.00023","0.09633"
"432.45000","36.03772","0.09567"
"432.90000","36.07515","0.09632"
"433.35000","36.11270","0.09612"
"433.80000","36.15019","0.09449"
"434.25000","36.18773","0.09264"
"434.70000","36.22516","0.09017"
"435.15000","36.26265","0.08728"
"435.60000","36.30020","0.08786"
"436.05000","36.33775","0.08587"
"436.50000","36.37524","0.08502"
"436.95000","36.41266","0.08521"
"437.40000","36.45021","0.08657"
"437.85000","36.48764","0.08959"
"438.30000","36.52518","0.09147"
"438.75000","36.56268","0.09383"
"439.20000","36.60022","0.09539"
"439.65000","36.63771","0.09765"
"440.10000","36.67520","0.09745"
"440.55000","36.71263","0.09873"
"441.00000","36.75011","0.09801"
"441.45000","36.78766","0.09992"
"441.90000","36.82527","0.10254"
"442.35000","36.86270","0.10406"
"442.80000","36.90025","0.10526"
"443.25000","36.93768","0.10751"
"443.70000","36.97511","0.10959"
"444.15000","37.01259","0.11082"
"444.60000","37.05020","0.11120"
"445.05000","37.08768","0.11314"
"445.50000","37.12523","0.11424"
"445.95000","37.16266","0.11491"
"446.40000","37.20015","0.11581"
"446.85000","37.23770","0.11699"
"447.30000","37.27519","0.11745"
"447.75000","37.31274","0.11841"
"448.20000","37.35022","0.11940"
"448.65000","37.38771","0.11940"
"449.10000","37.42514","0.11970"
"449.55000","37.46268","0.12060"
"450.00000","37.50017","0.12170"
"450.45000","37.53772","0.12235"
"450.90000","37.57521","0.12259"
"451.35000","37.61270","0.12327"
"451.80000","37.65019","0.12363"
"452.25000","37.68768","0.12374"
"452.70000","37.72528","0.12419"
"453.15000","37.76271","0.12452"
"453.60000","37.80020","0.12472"
"454.05000","37.83769","0.12521"
"454.50000","37.87511","0.12588"
"454.95000","37.91272","0.12654"
"455.40000","37.95021","0.12733"
"455.85000","37.98770","0.12809"
"456.30000","38.02525","0.12878"
"456.75000","38.06267","0.12868"
"457.20000","38.10016","0.12906"
"457.65000","38.13765","0.13044"
"458.10000","38.17520","0.13180"
"458.55000","38.21275","0.13332"
"459.00000","38.25023","0.13480"
"459.45000","38.28772","0.13570"
"459.90000","38.32515","0.13767"
"460.35000","38.36270","0.13960"
"460.80000","38.40019","0.13987"
"461.25000","38.43774","0.14100"
"461.70000","38.47522","0.14043"
"462.15000","38.51265","0.14116"
"462.60000","38.55020","0.13805"
"463.05000","38.58763","0.13897"
"463.50000","38.62523","0.13988"
"463.95000","38.66272","0.14241"
"464.40000","38.70021","0.14457"
"464.85000","38.73776","0.14664"
"465.30000","38.77525","0.14725"
"465.75000","38.81268","0.14839"
"466.20000","38.85016","0.14837"
"466.65000","38.88771","0.14988"
"467.10000","38.92525","0.15120"
"467.55000","38.96275","0.15196"
"468.00000","39.00018","0.15277"
"468.45000","39.03766","0.15387"
"468.90000","39.07521","0.15389"
"469.35000","39.11270","0.15436"
"469.80000","39.15018","0.15346"
"470.25000","39.18773","0.15343"
"470.70000","39.22516","0.15388"
"471.15000","39.26265","0.15056"
"471.60000","39.30020","0.14799"
"472.05000","39.33775","0.14423"
"472.50000","39.37523","0.14153"
"472.95000","39.41266","0.13792"
"473.40000","39.45015","0.13723"
"473.85000","39.48763","0.13465"
"474.30000","39.52512","0.13433"
"474.75000","39.56274","0.13496"
"475.20000","39.60016","0.13651"
"475.65000","39.63777","0.13667"
"476.10000","39.67520","0.13698"
"476.55000","39.71262","0.13847"
"477.00000","39.75018","0.13982"
"477.45000","39.78772","0.14198"
"477.90000","39.82521","0.13759"
"478.35000","39.86270","0.13860"
"478.80000","39.90019","0.13937"
"479.25000","39.93761","0.13963"
"479.70000","39.97516","0.14048"
"480.15000","40.01271","0.13924"
"480.60000","40.05019","0.13948"
"481.05000","40.08775","0.14004"
"481.50000","40.12518","0.13947"
"481.95000","40.16266","0.14075"
"482.40000","40.20015","0.14059"
"482.85000","40.23770","0.14018"
"483.30000","40.27525","0.13956"
"483.75000","40.31268","0.14235"
"484.20000","40.35022","0.14405"
"484.65000","40.38765","0.14591"
"485.10000","40.42520","0.14742"
"485.55000","40.46275","0.14681"
"486.00000","40.50024","0.14812"
"486.45000","40.53772","0.14913"
"486.90000","40.57515","0.15001"
"487.35000","40.61263","0.15165"
"487.80000","40.65018","0.14894"
"488.25000","40.68774","0.14989"
"488.70000","40.72522","0.15035"
"489.15000","40.76271","0.15165"
"489.60000","40.80020","0.15298"
"490.05000","40.83768","0.15436"
"490.50000","40.87523","0.15537"
"490.95000","40.91266","0.15610"
"491.40000","40.95021","0.15693"
"491.85000","40.98770","0.15784"
"492.30000","41.02525","0.15857"
"492.75000","41.06268","0.15940"
"493.20000","41.10011","0.16017"
"493.65000","41.13765","0.16090"
"494.10000","41.17519","0.16099"
"494.55000","41.21268","0.16145"
"495.00000","41.25017","0.16201"
"495.45000","41.28772","0.16284"
"495.90000","41.32515","0.16351"
"496.35000","41.36270","0.16450"
"496.80000","41.40019","0.16468"
"497.25000","41.43768","0.16585"
"497.70000","41.47522","0.16672"
"498.15000","41.51265","0.16430"
"498.60000","41.55020","0.16396"
"499.05000","41.58769","0.16469"
"499.50000","41.62517","0.16558"
"499.95000","41.66272","0.15482"
"500.40000","41.70015","0.15069"
"500.85000","41.73770","0.13842"
"501.30000","41.77513","0.06391"
"501.75000","41.81267","0.06189"
"502.20000","41.85022","0.06078"
"502.65000","41.88771","0.06327"
"503.10000","41.92526","0.06273"
"503.55000","41.96275","0.06246"
"504.00000","42.00018","0.06347"
"504.45000","42.03766","0.05364"
"504.90000","42.07521","0.05141"
"505.35000","42.11270","0.05321"
"505.80000","42.15019","0.05251"
"506.25000","42.18768","0.05217"
"506.70000","42.22516","0.05298"
"507.15000","42.26271","0.05096"
"507.60000","42.30014","0.05027"
"508.05000","42.33768","0.05087"
"508.50000","42.37523","0.05111"
"508.95000","42.41272","0.05127"
"509.40000","42.45015","0.05413"
"509.85000","42.48770","0.05469"
"510.30000","42.52512","0.05505"
"510.75000","42.56273","0.05641"
"511.20000","42.60022","0.05701"
"511.65000","42.63771","0.05864"
"512.10000","42.67520","0.05970"
"512.55000","42.71262","0.06016"
"513.00000","42.75017","0.06171"
"513.45000","42.78772","0.06173"
"513.90000","42.82515","0.06318"
"514.35000","42.86270","0.06368"
"514.80000","42.90013","0.06444"
"515.25000","42.93768","0.06498"
"515.70000","42.97522","0.06548"
"516.15000","43.01271","0.06611"
"516.60000","43.05020","0.06468"
"517.05000","43.08768","0.06214"
"517.50000","43.12518","0.06315"
"517.95000","43.16266","0.06420"
"518.40000","43.20021","0.06412"
"518.85000","43.23770","0.06531"
"519.30000","43.27525","0.06590"
"519.75000","43.31274","0.06659"
"520.20000","43.35016","0.06674"
"520.65000","43.38765","0.06699"
"521.10000","43.42519","0.06746"
"521.55000","43.46274","0.06785"
"522.00000","43.50023","0.06852"
"522.45000","43.53772","0.06831"
"522.90000","43.57521","0.06842"
"523.35000","43.61264","0.06869"
"523.80000","43.65019","0.06852"
"524.25000","43.68773","0.06881"
"524.70000","43.72522","0.06864"
"525.15000","43.76277","0.06906"
"525.60000","43.80020","0.06917"
"526.05000","43.83768","0.06995"
"526.50000","43.87524","0.07018"
"526.95000","43.91272","0.07115"
"527.40000","43.95021","0.07142"
"527.85000","43.98776","0.07201"
"528.30000","44.02524","0.07259"
"528.75000","44.06261","0.07288"
"529.20000","44.10022","0.07353"
"529.65000","44.13771","0.07399"
"530.10000","44.17520","0.07458"
"530.55000","44.21268","0.07519"
"531.00000","44.25018","0.07546"
"531.45000","44.28766","0.07591"
"531.90000","44.32515","0.07684"
"532.35000","44.36270","0.07742"
"532.80000","44.40018","0.07791"
"533.25000","44.43768","0.07882"
"533.70000","44.47516","0.07899"
"534.15000","44.51271","0.07993"
"534.60000","44.55019","0.08049"
"535.05000","44.58774","0.08180"
"535.50000","44.62518","0.08254"
"535.95000","44.66272","0.08304"
"536.40000","44.70021","0.08404"
"536.85000","44.73764","0.08348"
"537.30000","44.77519","0.08434"
"537.75000","44.81268","0.08504"
"538.20000","44.85028","0.08560"
"538.65000","44.88771","0.08678"
"539.10000","44.92525","0.08802"
"539.55000","44.96268","0.08846"
"540.00000","45.00017","0.08931"
"540.45000","45.03767","0.09041"
"540.90000","45.07521","0.09099"
"541.35000","45.11276","0.09173"
"541.80000","45.15024","0.09289"
"542.25000","45.18768","0.09369"
"542.70000","45.22516","0.09432"
"543.15000","45.26271","0.09476"
"543.60000","45.30026","0.09625"
"544.05000","45.33768","0.09773"
"544.50000","45.37523","0.09803"
"544.95000","45.41266","0.09876"
"545.40000","45.45015","0.09947"
"545.85000","45.48764","0.09976"
"546.30000","45.52518","0.09978"
"546.75000","45.56273","0.10144"
"547.20000","45.60022","0.10217"
"547.65000","45.63771","0.10246"
"548.10000","45.67520","0.10284"
"548.55000","45.71269","0.10374"
"549.00000","45.75023","0.10430"
"549.45000","45.78772","0.10429"
"549.90000","45.82521","0.10286"
"550.35000","45.86264","0.09940"
"550.80000","45.90012","0.09285"
"551.25000","45.93768","0.09194"
"551.70000","45.97522","0.09127"
"552.15000","46.01265","0.09173"
"552.60000","46.05020","0.09316"
"553.05000","46.08768","0.09476"
"553.50000","46.12511","0.09616"
"553.95000","46.16266","0.09724"
"554.40000","46.20021","0.09828"
"554.85000","46.23776","0.09975"
"555.30000","46.27524","0.10049"
"555.75000","46.31261","0.10183"
"556.20000","46.35010","0.10276"
"556.65000","46.38765","0.10359"
"557.10000","46.42520","0.10484"
"557.55000","46.46275","0.10621"
"558.00000","46.50023","0.10661"
"558.45000","46.53772","0.10794"
"558.90000","46.57509","0.10830"
"559.35000","46.61264","0.10960"
"559.80000","46.65018","0.10984"
"560.25000","46.68767","0.11161"
"560.70000","46.72522","0.11130"
"561.15000","46.76277","0.11255"
"561.60000","46.80020","0.11279"
"562.05000","46.83769","0.11405"
"562.50000","46.87524","0.11432"
"562.95000","46.91272","0.11437"
"563.40000","46.95021","0.11369"
"563.85000","46.98770","0.11289"
"564.30000","47.02512","0.11143"
"564.75000","47.06267","0.10872"
"565.20000","47.10022","0.10627"
"565.65000","47.13771","0.10548"
"566.10000","47.17514","0.10646"
"566.55000","47.21268","0.10822"
"567.00000","47.25017","0.10927"
"567.45000","47.28772","0.11078"
"567.90000","47.32521","0.11174"
"568.35000","47.36270","0.11342"
"568.80000","47.40018","0.11508"
"569.25000","47.43768","0.11634"
"569.70000","47.47516","0.11775"
"570.15000","47.51265","0.11930"
"570.60000","47.55020","0.12025"
"571.05000","47.58775","0.12085"
"571.50000","47.62517","0.12104"
"571.95000","47.66272","0.12177"
"572.40000","47.70015","0.12236"
"572.85000","47.73764","0.12291"
"573.30000","47.77513","0.12306"
"573.75000","47.81273","0.12345"
"574.20000","47.85022","0.12348"
"574.65000","47.88777","0.12344"
"575.10000","47.92520","0.12281"
"575.55000","47.96268","0.11899"
"576.00000","48.00024","0.10237"
"576.45000","48.03766","0.10119"
"576.90000","48.07521","0.10233"
"577.35000","48.11270","0.10360"
"577.80000","48.15018","0.10535"
"578.25000","48.18767","0.10678"
"578.70000","48.22517","0.10877"
"579.15000","48.26265","0.11085"
"579.60000","48.30025","0.11296"
"580.05000","48.33775","0.11475"
"580.50000","48.37517","0.11596"
"580.95000","48.41266","0.11740"
"581.40000","48.45015","0.11783"
"581.85000","48.48776","0.11900"
"582.30000","48.52518","0.12045"
"582.75000","48.56274","0.12139"
"583.20000","48.60022","0.12173"
"583.65000","48.63759","0.12204"
"584.10000","48.67520","0.12247"
"584.55000","48.71268","0.12324"
"585.00000","48.75023","0.12348"
"585.45000","48.78778","0.12388"
"585.90000","48.82515","0.12410"
"586.35000","48.86264","0.12457"
"586.80000","48.90013","0.12531"
"587.25000","48.93767","0.12576"
"587.70000","48.97522","0.12577"
"588.15000","49.01271","0.12616"
"588.60000","49.05019","0.12665"
"589.05000","49.08763","0.12694"
"589.50000","49.12518","0.12466"
"589.95000","49.16266","0.11551"
"590.40000","49.20027","0.11729"
"590.85000","49.23770","0.11967"
"591.30000","49.27518","0.12076"
"591.75000","49.31267","0.12256"
"592.20000","49.35010","0.12260"
"592.65000","49.38771","0.12363"
"593.10000","49.42520","0.12422"
"593.55000","49.46269","0.12461"
"594.00000","49.50023","0.12515"
"594.45000","49.53772","0.12584"
"594.90000","49.57515","0.12673"
"595.35000","49.61269","0.12808"
"595.80000","49.65025","0.12887"
"596.25000","49.68774","0.13119"
"596.70000","49.72522","0.13310"
"597.15000","49.76265","0.13584"
"597.60000","49.80014","0.13721"
"598.05000","49.83775","0.13870"
"598.50000","49.87523","0.13982"
"598.95000","49.91272","0.14196"
"599.40000","49.95015","0.14382"
"599.85000","49.98770","0.14586"
"600.30000","50.02513","0.14736"
"600.75000","50.06267","0.14925"
"601.20000","50.10022","0.15071"
"601.65000","50.13771","0.15243"
"602.10000","50.17519","0.15335"
"602.55000","50.21268","0.15420"
"603.00000","50.25011","0.15542"
"603.45000","50.28766","0.15608"
"603.90000","50.32521","0.15696"
"604.35000","50.36270","0.15753"
"604.80000","50.40024","0.15851"
"605.25000","50.43768","0.15945"
"605.70000","50.47510","0.15958"
"606.15000","50.51271","0.16026"
"606.60000","50.55020","0.16128"
"607.05000","50.58775","0.16164"
"607.50000","50.62524","0.16271"
"607.95000","50.66266","0.16334"
"608.40000","50.70015","0.16403"
"608.85000","50.73763","0.16473"
"609.30000","50.77518","0.16484"
"609.75000","50.81268","0.03313"
"610.20000","50.85022","0.01568"
"610.65000","50.88771","0.01333"
"611.10000","50.92520","0.01336"
"611.55000","50.96262","0.01462"
"612.00000","51.00018","0.01336"
"612.45000","51.03766","0.01481"
"612.90000","51.07521","0.01335"
"613.35000","51.11275","0.01405"
"613.80000","51.15013","0.01427"
"614.25000","51.18767","0.01483"
"614.70000","51.22522","0.01476"
"615.15000","51.26271","0.01430"
"615.60000","51.30019","0.01394"
"616.05000","51.33768","0.01422"
"616.50000","51.37511","0.01430"
"616.95000","51.41266","0.01509"
"617.40000","51.45021","0.01475"
"617.85000","51.48770","0.01452"
"618.30000","51.52524","0.01463"
"618.75000","51.56273","0.01489"
"619.20000","51.60016","0.01586"
"619.65000","51.63771","0.01464"
"620.10000","51.67520","0.01536"
"620.55000","51.71275","0.01567"
"621.00000","51.75017","0.01548"
"621.45000","51.78778","0.01565"
"621.90000","51.82515","0.01511"
"622.35000","51.86258","0.01571"
"622.80000","51.90013","0.01616"
"623.25000","51.93774","0.01550"
"623.70000","51.97522","0.01600"
"624.15000","52.01277","0.01657"
"624.60000","52.05020","0.01630"
"625.05000","52.08768","0.01632"
"625.50000","52.12518","0.01690"
"625.95000","52.16272","0.01662"
"626.40000","52.20021","0.01769"
"626.85000","52.23770","0.01656"
"627.30000","52.27519","0.01741"
"627.75000","52.31267","0.01743"
"628.20000","52.35016","0.01704"
"628.65000","52.38771","0.01736"
"629.10000","52.42519","0.01800"
"629.55000","52.46268","0.01831"
"630.00000","52.50023","0.01760"
"630.45000","52.53766","0.01879"
"630.90000","52.57521","0.01914"
"631.35000","52.61276","0.01840"
"631.80000","52.65024","0.01898"
"632.25000","52.68779","0.01954"
"632.70000","52.72522","0.01996"
"633.15000","52.76265","0.01927"
"633.60000","52.80014","0.02086"
"634.05000","52.83775","0.01956"
"634.50000","52.87524","0.01955"
"634.95000","52.91266","0.02014"
"635.40000","52.95021","0.01951"
"635.85000","52.98758","0.02068"
"636.30000","53.02518","0.01984"
"636.75000","53.06267","0.02105"
"637.20000","53.10022","0.02010"
"637.65000","53.13771","0.02039"
"638.10000","53.17520","0.02066"
"638.55000","53.21262","0.02102"
"639.00000","53.25018","0.02064"
"639.45000","53.28760","0.02139"
"639.90000","53.32521","0.02208"
"640.35000","53.36270","0.02122"
"640.80000","53.40025","0.02177"
"641.25000","53.43773","0.02152"
"641.70000","53.47516","0.02153"
"642.15000","53.51265","0.02179"
"642.60000","53.55026","0.02124"
"643.05000","53.58768","0.02051"
"643.50000","53.62523","0.02135"
"643.95000","53.66266","0.02114"
"644.40000","53.70015","0.02113"
"644.85000","53.73770","0.02124"
"645.30000","53.77524","0.02153"
"645.75000","53.81268","0.02108"
"646.20000","53.85022","0.02134"
"646.65000","53.88765","0.02165"
"647.10000","53.92520","0.02152"
"647.55000","53.96268","0.02205"
"648.00000","54.00017","0.02228"
"648.45000","54.03766","0.02148"
"648.90000","54.07521","0.02113"
"649.35000","54.11264","0.02192"
"649.80000","54.15018","0.02203"
"650.25000","54.18767","0.02245"
"650.70000","54.22522","0.02167"
"651.15000","54.26271","0.02202"
"651.60000","54.30020","0.02201"
"652.05000","54.33768","0.02248"
"652.50000","54.37511","0.02172"
"652.95000","54.41266","0.02255"
"653.40000","54.45021","0.02273"
"653.85000","54.48775","0.02366"
"654.30000","54.52525","0.02280"
"654.75000","54.56273","0.02301"
"655.20000","54.60016","0.02413"
"655.65000","54.63771","0.02276"
"656.10000","54.67519","0.02344"
"656.55000","54.71269","0.02459"
"657.00000","54.75023","0.02381"
"657.45000","54.78772","0.02354"
"657.90000","54.82515","0.02386"
"658.35000","54.86270","0.02471"
"658.80000","54.90012","0.02398"
"659.25000","54.93773","0.02395"
"659.70000","54.97522","0.02446"
"660.15000","55.01271","0.02460"
"660.60000","55.05014","0.02328"
"661.05000","55.08762","0.02413"
"661.50000","55.12517","0.02409"
"661.95000","55.16272","0.02394"
"662.40000","55.20021","0.02486"
"662.85000","55.23769","0.02396"
"663.30000","55.27513","0.02396"
"663.75000","55.31267","0.02367"
"664.20000","55.35022","0.02444"
"664.65000","55.38771","0.02377"
"665.10000","55.42520","0.02421"
"665.55000","55.46268","0.02417"
"666.00000","55.50011","0.02396"
"666.45000","55.53766","0.02485"
"666.90000","55.57521","0.02520"
"667.35000","55.61275","0.02531"
"667.80000","55.65025","0.02463"
"668.00600","55.66735","0.02526"