File: Force_trajectories/161223/Specimen_RawData_9.csv
End date,"12/23/2016"
Specimen label,"17BC_40"
Maximum Load,"2.05197",N

Time,Extension,Load
(s),(mm),(N)
"0.00000","0.00000","-0.00065"
"0.31200","0.02565","-0.00041"
"0.62400","0.05220","-0.00046"
"0.93600","0.07826","0.00046"
"1.24800","0.10421","0.00112"
"1.56000","0.13022","0.00173"
"1.87200","0.15623","0.00191"
"2.18400","0.18218","0.00208"
"2.49600","0.20819","0.00225"
"2.80800","0.23420","0.00289"
"3.12000","0.26020","0.00296"
"3.43200","0.28621","0.00309"
"3.74400","0.31216","0.00355"
"4.05600","0.33823","0.00321"
"4.36800","0.36418","0.00365"
"4.68000","0.39025","0.00455"
"4.99200","0.41614","0.00456"
"5.30400","0.44214","0.00506"
"5.61600","0.46821","0.00462"
"5.92800","0.49422","0.00541"
"6.24000","0.52023","0.00558"
"6.55200","0.54618","0.00605"
"6.86400","0.57225","0.00624"
"7.17600","0.59819","0.00599"
"7.48800","0.62420","0.00636"
"7.80000","0.65027","0.00623"
"8.11200","0.67622","0.00658"
"8.42400","0.70217","0.00709"
"8.73600","0.72818","0.00727"
"9.04800","0.75419","0.00761"
"9.36000","0.78019","0.00772"
"9.67200","0.80614","0.00773"
"9.98400","0.83221","0.00854"
"10.29600","0.85822","0.00888"
"10.60800","0.88417","0.00874"
"10.92000","0.91018","0.00810"
"11.23200","0.93618","0.00789"
"11.54400","0.96225","0.00827"
"11.85600","0.98820","0.00800"
"12.16800","1.01421","0.00791"
"12.48000","1.04010","0.00827"
"12.79200","1.06623","0.00904"
"13.10400","1.09218","0.00758"
"13.41600","1.11824","0.00744"
"13.72800","1.14425","0.00799"
"14.04000","1.17014","0.00852"
"14.35200","1.19621","0.00827"
"14.66400","1.22216","0.00853"
"14.97600","1.24823","0.00892"
"15.28800","1.27417","0.00919"
"15.60000","1.30024","0.00899"
"15.91200","1.32619","0.00955"
"16.22400","1.35208","0.01006"
"16.53600","1.37821","0.00999"
"16.84800","1.40422","0.01081"
"17.16000","1.43023","0.00985"
"17.47200","1.45623","0.01050"
"17.78400","1.48218","0.01044"
"18.09600","1.50819","0.01102"
"18.40800","1.53420","0.01069"
"18.72000","1.56021","0.01119"
"19.03200","1.58622","0.01135"
"19.34400","1.61216","0.01106"
"19.65600","1.63823","0.01136"
"19.96800","1.66412","0.01114"
"20.28000","1.69025","0.01161"
"20.59200","1.71620","0.01183"
"20.90400","1.74221","0.01142"
"21.21600","1.76822","0.01190"
"21.52800","1.79422","0.01176"
"21.84000","1.82023","0.01073"
"22.15200","1.84618","0.01100"
"22.46400","1.87219","0.01115"
"22.77600","1.89820","0.01182"
"23.08800","1.92421","0.01190"
"23.40000","1.95022","0.01245"
"23.71200","1.97616","0.01194"
"24.02400","2.00229","0.01263"
"24.33600","2.02818","0.01267"
"24.64800","2.05419","0.01273"
"24.96000","2.08020","0.01273"
"25.27200","2.10621","0.01243"
"25.58400","2.13221","0.01271"
"25.89600","2.15822","0.01312"
"26.20800","2.18423","0.01341"
"26.52000","2.21018","0.01342"
"26.83200","2.23619","0.01341"
"27.14400","2.26220","0.01334"
"27.45600","2.28815","0.01368"
"27.76800","2.31427","0.01306"
"28.08000","2.34016","0.01364"
"28.39200","2.36623","0.01374"
"28.70400","2.39224","0.01408"
"29.01600","2.41819","0.01425"
"29.32800","2.44426","0.01489"
"29.64000","2.47020","0.01517"
"29.95200","2.49627","0.01460"
"30.26400","2.52216","0.01486"
"30.57600","2.54823","0.01488"
"30.88800","2.57418","0.01517"
"31.20000","2.60019","0.01498"
"31.51200","2.62626","0.01548"
"31.82400","2.65214","0.01555"
"32.13600","2.67821","0.01571"
"32.44800","2.70416","0.01617"
"32.76000","2.73023","0.01613"
"33.07200","2.75624","0.01618"
"33.38400","2.78219","0.01670"
"33.69600","2.80819","0.01672"
"34.00800","2.83414","0.01738"
"34.32000","2.86021","0.01729"
"34.63200","2.88616","0.01769"
"34.94400","2.91217","0.01775"
"35.25600","2.93824","0.01814"
"35.56800","2.96419","0.01856"
"35.88000","2.99019","0.01788"
"36.19200","3.01620","0.01779"
"36.50400","3.04227","0.01839"
"36.81600","3.06828","0.01891"
"37.12800","3.09417","0.01878"
"37.44000","3.12018","0.01951"
"37.75200","3.14613","0.01978"
"38.06400","3.17225","0.02006"
"38.37600","3.19814","0.02085"
"38.68800","3.22421","0.02053"
"39.00000","3.25028","0.02135"
"39.31200","3.27617","0.02181"
"39.62400","3.30224","0.02169"
"39.93600","3.32818","0.02237"
"40.24800","3.35425","0.02194"
"40.56000","3.38020","0.02253"
"40.87200","3.40615","0.02321"
"41.18400","3.43222","0.02306"
"41.49600","3.45817","0.02300"
"41.80800","3.48423","0.02366"
"42.12000","3.51018","0.02412"
"42.43200","3.53625","0.02458"
"42.74400","3.56220","0.02546"
"43.05600","3.58821","0.02582"
"43.36800","3.61422","0.02602"
"43.68000","3.64017","0.02644"
"43.99200","3.66623","0.02703"
"44.30400","3.69224","0.02729"
"44.61600","3.71819","0.02751"
"44.92800","3.74420","0.02770"
"45.24000","3.77015","0.02827"
"45.55200","3.79622","0.02850"
"45.86400","3.82217","0.02844"
"46.17600","3.84823","0.02885"
"46.48800","3.87418","0.02968"
"46.80000","3.90013","0.03001"
"47.11200","3.92626","0.03038"
"47.42400","3.95215","0.03089"
"47.73600","3.97822","0.03120"
"48.04800","4.00416","0.03125"
"48.36000","4.03017","0.03166"
"48.67200","4.05618","0.03235"
"48.98400","4.08219","0.03302"
"49.29600","4.10826","0.03331"
"49.60800","4.13421","0.03354"
"49.92000","4.16027","0.03400"
"50.23200","4.18622","0.03445"
"50.54400","4.21223","0.03445"
"50.85600","4.23830","0.03511"
"51.16800","4.26419","0.03519"
"51.48000","4.29020","0.03560"
"51.79200","4.31615","0.03596"
"52.10400","4.34221","0.03624"
"52.41600","4.36822","0.03644"
"52.72800","4.39417","0.03710"
"53.04000","4.42024","0.03744"
"53.35200","4.44619","0.03768"
"53.66400","4.47220","0.03824"
"53.97600","4.49815","0.03872"
"54.28800","4.52421","0.03912"
"54.60000","4.55028","0.03925"
"54.91200","4.57617","0.04048"
"55.22400","4.60224","0.04056"
"55.53600","4.62819","0.04075"
"55.84800","4.65426","0.04142"
"56.16000","4.68021","0.04176"
"56.47200","4.70621","0.04258"
"56.78400","4.73228","0.04269"
"57.09600","4.75817","0.04326"
"57.40800","4.78424","0.04458"
"57.72000","4.81019","0.04432"
"58.03200","4.83626","0.04487"
"58.34400","4.86220","0.04596"
"58.65600","4.88821","0.04568"
"58.96800","4.91422","0.04730"
"59.28000","4.94011","0.04769"
"59.59200","4.96624","0.04843"
"59.90400","4.99225","0.04891"
"60.21600","5.01819","0.05003"
"60.52800","5.04420","0.05031"
"60.84000","5.07015","0.05128"
"61.15200","5.09622","0.05166"
"61.46400","5.12217","0.05248"
"61.77600","5.14824","0.05283"
"62.08800","5.17419","0.05317"
"62.40000","5.20019","0.05365"
"62.71200","5.22620","0.05471"
"63.02400","5.25215","0.05518"
"63.33600","5.27822","0.05566"
"63.64800","5.30423","0.05528"
"63.96000","5.33018","0.05535"
"64.27200","5.35625","0.05658"
"64.58400","5.38213","0.05734"
"64.89600","5.40826","0.05736"
"65.20800","5.43421","0.05791"
"65.52000","5.46022","0.05878"
"65.83200","5.48617","0.05889"
"66.14400","5.51218","0.05946"
"66.45600","5.53824","0.05976"
"66.76800","5.56419","0.06025"
"67.08000","5.59026","0.06019"
"67.39200","5.61621","0.06060"
"67.70400","5.64222","0.06124"
"68.01600","5.66823","0.06194"
"68.32800","5.69418","0.06254"
"68.64000","5.72024","0.06284"
"68.95200","5.74619","0.06311"
"69.26400","5.77226","0.06363"
"69.57600","5.79815","0.06450"
"69.88800","5.82416","0.06509"
"70.20000","5.85023","0.06572"
"70.51200","5.87617","0.06612"
"70.82400","5.90218","0.06644"
"71.13600","5.92819","0.06799"
"71.44800","5.95426","0.06852"
"71.76000","5.98021","0.06928"
"72.07200","6.00616","0.06974"
"72.38400","6.03229","0.07144"
"72.69600","6.05817","0.07196"
"73.00800","6.08424","0.07237"
"73.32000","6.11013","0.07322"
"73.63200","6.13620","0.07360"
"73.94400","6.16221","0.07410"
"74.25600","6.18816","0.07527"
"74.56800","6.21422","0.07570"
"74.88000","6.24017","0.07677"
"75.19200","6.26624","0.07745"
"75.50400","6.29219","0.07795"
"75.81600","6.31820","0.07925"
"76.12800","6.34421","0.07981"
"76.44000","6.37016","0.08058"
"76.75200","6.39616","0.08141"
"77.06400","6.42211","0.08209"
"77.37600","6.44818","0.08192"
"77.68800","6.47419","0.08264"
"78.00000","6.50020","0.08303"
"78.31200","6.52621","0.08364"
"78.62400","6.55216","0.08388"
"78.93600","6.57822","0.08465"
"79.24800","6.60417","0.08488"
"79.56000","6.63024","0.08553"
"79.87200","6.65625","0.08581"
"80.18400","6.68220","0.08625"
"80.49600","6.70821","0.08697"
"80.80800","6.73410","0.08706"
"81.12000","6.76022","0.08782"
"81.43200","6.78623","0.08794"
"81.74400","6.81224","0.08873"
"82.05600","6.83825","0.08941"
"82.36800","6.86414","0.08974"
"82.68000","6.89021","0.09013"
"82.99200","6.91621","0.09098"
"83.30400","6.94222","0.09058"
"83.61600","6.96817","0.09158"
"83.92800","6.99418","0.09230"
"84.24000","7.02025","0.09259"
"84.55200","7.04614","0.09332"
"84.86400","7.07227","0.09367"
"85.17600","7.09821","0.09485"
"85.48800","7.12422","0.09517"
"85.80000","7.15023","0.09533"
"86.11200","7.17624","0.09602"
"86.42400","7.20225","0.09670"
"86.73600","7.22820","0.09727"
"87.04800","7.25420","0.09825"
"87.36000","7.28021","0.09885"
"87.67200","7.30616","0.09893"
"87.98400","7.33217","0.09975"
"88.29600","7.35818","0.10076"
"88.60800","7.38425","0.10165"
"88.92000","7.41020","0.10183"
"89.23200","7.43620","0.10307"
"89.54400","7.46221","0.10389"
"89.85600","7.48816","0.10420"
"90.16800","7.51423","0.10532"
"90.48000","7.54012","0.10616"
"90.79200","7.56625","0.10669"
"91.10400","7.59220","0.10721"
"91.41600","7.61820","0.10855"
"91.72800","7.64415","0.10899"
"92.04000","7.67016","0.11003"
"92.35200","7.69623","0.11114"
"92.66400","7.72218","0.11144"
"92.97600","7.74819","0.11219"
"93.28800","7.77419","0.11325"
"93.60000","7.80020","0.11454"
"93.91200","7.82627","0.11527"
"94.22400","7.85216","0.11636"
"94.53600","7.87823","0.11719"
"94.84800","7.90418","0.11877"
"95.16000","7.93018","0.12007"
"95.47200","7.95619","0.12090"
"95.78400","7.98220","0.11968"
"96.09600","8.00821","0.12183"
"96.40800","8.03416","0.12298"
"96.72000","8.06017","0.12388"
"97.03200","8.08618","0.12685"
"97.34400","8.11224","0.12725"
"97.65600","8.13825","0.12848"
"97.96800","8.16420","0.12950"
"98.28000","8.19021","0.13096"
"98.59200","8.21610","0.13218"
"98.90400","8.24223","0.13371"
"99.21600","8.26818","0.13478"
"99.52800","8.29418","0.13561"
"99.84000","8.32025","0.13633"
"100.15200","8.34614","0.13754"
"100.46400","8.37221","0.13853"
"100.77600","8.39822","0.13996"
"101.08800","8.42422","0.14063"
"101.40000","8.45023","0.14084"
"101.71200","8.47618","0.14162"
"102.02400","8.50219","0.14309"
"102.33600","8.52814","0.14378"
"102.64800","8.55421","0.14483"
"102.96000","8.58016","0.14678"
"103.27200","8.60623","0.14748"
"103.58400","8.63223","0.15028"
"103.89600","8.65818","0.15129"
"104.20800","8.68419","0.15253"
"104.52000","8.71020","0.15471"
"104.83200","8.73615","0.15657"
"105.14400","8.76222","0.15809"
"105.45600","8.78817","0.15969"
"105.76800","8.81417","0.16042"
"106.08000","8.84012","0.16159"
"106.39200","8.86625","0.16359"
"106.70400","8.89220","0.16438"
"107.01600","8.91821","0.16520"
"107.32800","8.94421","0.16606"
"107.64000","8.97016","0.16696"
"107.95200","8.99623","0.16820"
"108.26400","9.02218","0.16943"
"108.57600","9.04825","0.17002"
"108.88800","9.07420","0.17178"
"109.20000","9.10015","0.17287"
"109.51200","9.12621","0.17423"
"109.82400","9.15222","0.17490"
"110.13600","9.17823","0.17734"
"110.44800","9.20418","0.17893"
"110.76000","9.23025","0.17956"
"111.07200","9.25620","0.18031"
"111.38400","9.28215","0.18187"
"111.69600","9.30827","0.18346"
"112.00800","9.33422","0.18453"
"112.32000","9.36023","0.18577"
"112.63200","9.38618","0.18665"
"112.94400","9.41213","0.18821"
"113.25600","9.43820","0.18953"
"113.56800","9.46420","0.19068"
"113.88000","9.49021","0.19205"
"114.19200","9.51622","0.19316"
"114.50400","9.54229","0.19514"
"114.81600","9.56824","0.19559"
"115.12800","9.59419","0.19736"
"115.44000","9.62026","0.19826"
"115.75200","9.64614","0.19883"
"116.06400","9.67227","0.19981"
"116.37600","9.69816","0.20072"
"116.68800","9.72417","0.20192"
"117.00000","9.75024","0.20314"
"117.31200","9.77619","0.20401"
"117.62400","9.80219","0.20521"
"117.93600","9.82814","0.20630"
"118.24800","9.85421","0.20723"
"118.56000","9.88016","0.20870"
"118.87200","9.90623","0.21037"
"119.18400","9.93218","0.21194"
"119.49600","9.95813","0.21325"
"119.80800","9.98419","0.21330"
"120.12000","10.01014","0.21470"
"120.43200","10.03621","0.21615"
"120.74400","10.06222","0.21696"
"121.05600","10.08823","0.21830"
"121.36800","10.11424","0.22005"
"121.68000","10.14012","0.22097"
"121.99200","10.16625","0.22247"
"122.30400","10.19220","0.22521"
"122.61600","10.21821","0.22651"
"122.92800","10.24422","0.22791"
"123.24000","10.27017","0.22991"
"123.55200","10.29624","0.23166"
"123.86400","10.32212","0.23295"
"124.17600","10.34825","0.23451"
"124.48800","10.37420","0.23573"
"124.80000","10.40021","0.23762"
"125.11200","10.42622","0.23821"
"125.42400","10.45217","0.24061"
"125.73600","10.47824","0.24135"
"126.04800","10.50418","0.23977"
"126.36000","10.53025","0.24047"
"126.67200","10.55620","0.24208"
"126.98400","10.58221","0.24329"
"127.29600","10.60822","0.24400"
"127.60800","10.63417","0.24598"
"127.92000","10.66023","0.24765"
"128.23200","10.68618","0.24956"
"128.54400","10.71219","0.25248"
"128.85600","10.73820","0.25490"
"129.16800","10.76421","0.25764"
"129.48000","10.79028","0.26037"
"129.79200","10.81623","0.26119"
"130.10400","10.84217","0.26304"
"130.41600","10.86818","0.26442"
"130.72800","10.89413","0.26693"
"131.04000","10.92020","0.26860"
"131.35200","10.94615","0.27124"
"131.66400","10.97222","0.27412"
"131.97600","10.99823","0.27684"
"132.28800","11.02417","0.27954"
"132.60000","11.05018","0.28221"
"132.91200","11.07619","0.28497"
"133.22400","11.10226","0.28703"
"133.53600","11.12815","0.28958"
"133.84800","11.15422","0.29120"
"134.16000","11.18016","0.29288"
"134.47200","11.20617","0.29419"
"134.78400","11.23218","0.29568"
"135.09600","11.25813","0.29742"
"135.40800","11.28420","0.29857"
"135.72000","11.31015","0.30056"
"136.03200","11.33622","0.30180"
"136.34400","11.36222","0.30329"
"136.65600","11.38817","0.30513"
"136.96800","11.41424","0.30619"
"137.28000","11.44019","0.30750"
"137.59200","11.46620","0.30923"
"137.90400","11.49221","0.29409"
"138.21600","11.51822","0.29502"
"138.52800","11.54422","0.29574"
"138.84000","11.57017","0.29755"
"139.15200","11.59624","0.29959"
"139.46400","11.62219","0.30095"
"139.77600","11.64820","0.30285"
"140.08800","11.67420","0.30434"
"140.40000","11.70021","0.30596"
"140.71200","11.72622","0.30753"
"141.02400","11.75217","0.30984"
"141.33600","11.77818","0.31186"
"141.64800","11.80413","0.31345"
"141.96000","11.83026","0.31564"
"142.27200","11.85626","0.31733"
"142.58400","11.88221","0.31919"
"142.89600","11.90822","0.32046"
"143.20800","11.93417","0.32276"
"143.52000","11.96024","0.32408"
"143.83200","11.98625","0.32594"
"144.14400","12.01225","0.32906"
"144.45600","12.03821","0.33174"
"144.76800","12.06421","0.33478"
"145.08000","12.09016","0.33771"
"145.39200","12.11611","0.34082"
"145.70400","12.14224","0.34283"
"146.01600","12.16825","0.34566"
"146.32800","12.19420","0.34667"
"146.64000","12.22026","0.34939"
"146.95200","12.24621","0.35234"
"147.26400","12.27222","0.35526"
"147.57600","12.29823","0.35883"
"147.88800","12.32418","0.36252"
"148.20000","12.35018","0.36495"
"148.51200","12.37619","0.36720"
"148.82400","12.40220","0.36993"
"149.13600","12.42815","0.37105"
"149.44800","12.45422","0.37261"
"149.76000","12.48023","0.37454"
"150.07200","12.50618","0.37713"
"150.38400","12.53224","0.37901"
"150.69600","12.55819","0.38182"
"151.00800","12.58426","0.38644"
"151.32000","12.61021","0.38957"
"151.63200","12.63622","0.39212"
"151.94400","12.66217","0.39315"
"152.25600","12.68818","0.39539"
"152.56800","12.71424","0.39638"
"152.88000","12.74019","0.39808"
"153.19200","12.76626","0.39982"
"153.50400","12.79215","0.40107"
"153.81600","12.81822","0.40314"
"154.12800","12.84417","0.40481"
"154.44000","12.87017","0.40667"
"154.75200","12.89624","0.40833"
"155.06400","12.92219","0.41011"
"155.37600","12.94820","0.41214"
"155.68800","12.97421","0.41458"
"156.00000","13.00016","0.41706"
"156.31200","13.02623","0.41998"
"156.62400","13.05223","0.42033"
"156.93600","13.07824","0.40268"
"157.24800","13.10419","0.40409"
"157.56000","13.13020","0.40518"
"157.87200","13.15621","0.39963"
"158.18400","13.18222","0.40158"
"158.49600","13.20823","0.40349"
"158.80800","13.23417","0.40519"
"159.12000","13.26024","0.40732"
"159.43200","13.28613","0.40916"
"159.74400","13.31220","0.41116"
"160.05600","13.33815","0.41321"
"160.36800","13.36416","0.41618"
"160.68000","13.39023","0.41898"
"160.99200","13.41611","0.42252"
"161.30400","13.44224","0.42328"
"161.61600","13.46819","0.33720"
"161.92800","13.49420","0.33460"
"162.24000","13.52021","0.33665"
"162.55200","13.54610","0.34034"
"162.86400","13.57216","0.34291"
"163.17600","13.59817","0.34580"
"163.48800","13.62418","0.34882"
"163.80000","13.65019","0.35153"
"164.11200","13.67620","0.35580"
"164.42400","13.70221","0.35941"
"164.73600","13.72810","0.36378"
"165.04800","13.75422","0.36596"
"165.36000","13.78023","0.36925"
"165.67200","13.80624","0.37056"
"165.98400","13.83225","0.37335"
"166.29600","13.85814","0.37542"
"166.60800","13.88421","0.37914"
"166.92000","13.91015","0.38199"
"167.23200","13.93622","0.38630"
"167.54400","13.96217","0.38915"
"167.85600","13.98818","0.39253"
"168.16800","14.01425","0.39442"
"168.48000","14.04014","0.39681"
"168.79200","14.06627","0.39847"
"169.10400","14.09221","0.40093"
"169.41600","14.11822","0.40297"
"169.72800","14.14423","0.40667"
"170.04000","14.17018","0.40862"
"170.35200","14.19619","0.41193"
"170.66400","14.22220","0.41654"
"170.97600","14.24821","0.41912"
"171.28800","14.27415","0.42207"
"171.60000","14.30022","0.42375"
"171.91200","14.32623","0.42672"
"172.22400","14.35218","0.43003"
"172.53600","14.37825","0.43406"
"172.84800","14.40420","0.43716"
"173.16000","14.43020","0.44072"
"173.47200","14.45621","0.44289"
"173.78400","14.48216","0.44511"
"174.09600","14.50823","0.44744"
"174.40800","14.53418","0.44949"
"174.72000","14.56025","0.45281"
"175.03200","14.58619","0.45860"
"175.34400","14.61220","0.46422"
"175.65600","14.63821","0.46891"
"175.96800","14.66422","0.47212"
"176.28000","14.69029","0.47440"
"176.59200","14.71612","0.47716"
"176.90400","14.74224","0.48116"
"177.21600","14.76814","0.48462"
"177.52800","14.79420","0.48796"
"177.84000","14.82027","0.49167"
"178.15200","14.84622","0.49443"
"178.46400","14.87223","0.49761"
"178.77600","14.89818","0.50128"
"179.08800","14.92424","0.50374"
"179.40000","14.95019","0.50693"
"179.71200","14.97620","0.50898"
"180.02400","15.00227","0.51092"
"180.33600","15.02822","0.51274"
"180.64800","15.05423","0.51500"
"180.96000","15.08018","0.51716"
"181.27200","15.10618","0.51957"
"181.58400","15.13225","0.52197"
"181.89600","15.15814","0.52563"
"182.20800","15.18421","0.52855"
"182.52000","15.21016","0.53217"
"182.83200","15.23623","0.53864"
"183.14400","15.26218","0.54366"
"183.45600","15.28824","0.54648"
"183.76800","15.31425","0.55053"
"184.08000","15.34014","0.55231"
"184.39200","15.36627","0.55509"
"184.70400","15.39216","0.55755"
"185.01600","15.41829","0.56242"
"185.32800","15.44423","0.56572"
"185.64000","15.47018","0.56926"
"185.95200","15.49625","0.57279"
"186.26400","15.52214","0.57571"
"186.57600","15.54827","0.57829"
"186.88800","15.57422","0.58124"
"187.20000","15.60023","0.58477"
"187.51200","15.62623","0.58823"
"187.82400","15.65218","0.59211"
"188.13600","15.67819","0.59594"
"188.44800","15.70414","0.59835"
"188.76000","15.73021","0.60052"
"189.07200","15.75622","0.60308"
"189.38400","15.78222","0.60806"
"189.69600","15.80823","0.61225"
"190.00800","15.83418","0.61463"
"190.32000","15.86019","0.61734"
"190.63200","15.88620","0.62008"
"190.94400","15.91215","0.62233"
"191.25600","15.93816","0.62651"
"191.56800","15.96416","0.63136"
"191.88000","15.99017","0.63643"
"192.19200","16.01612","0.64195"
"192.50400","16.04225","0.64457"
"192.81600","16.06820","0.64793"
"193.12800","16.09421","0.65231"
"193.44000","16.12021","0.65745"
"193.75200","16.14616","0.66259"
"194.06400","16.17229","0.66854"
"194.37600","16.19818","0.67349"
"194.68800","16.22419","0.67642"
"195.00000","16.25014","0.67920"
"195.31200","16.27615","0.68190"
"195.62400","16.30227","0.68471"
"195.93600","16.32816","0.68899"
"196.24800","16.35423","0.69497"
"196.56000","16.38018","0.70024"
"196.87200","16.40619","0.70408"
"197.18400","16.43220","0.70799"
"197.49600","16.45820","0.71104"
"197.80800","16.48427","0.71317"
"198.12000","16.51022","0.71603"
"198.43200","16.53623","0.72006"
"198.74400","16.56218","0.72525"
"199.05600","16.58813","0.72874"
"199.36800","16.61425","0.73101"
"199.68000","16.64014","0.73413"
"199.99200","16.66621","0.73817"
"200.30400","16.69222","0.74280"
"200.61600","16.71823","0.74705"
"200.92800","16.74424","0.75111"
"201.24000","16.77019","0.75549"
"201.55200","16.79626","0.76011"
"201.86400","16.82214","0.76618"
"202.17600","16.84821","0.77366"
"202.48800","16.87416","0.78040"
"202.80000","16.90023","0.78388"
"203.11200","16.92624","0.78746"
"203.42400","16.95213","0.79154"
"203.73600","16.97820","0.79844"
"204.04800","17.00420","0.80396"
"204.36000","17.03021","0.80881"
"204.67200","17.05622","0.81288"
"204.98400","17.08223","0.81724"
"205.29600","17.10824","0.82040"
"205.60800","17.13413","0.82312"
"205.92000","17.16019","0.82536"
"206.23200","17.18614","0.82695"
"206.54400","17.21221","0.82895"
"206.85600","17.23822","0.83087"
"207.16800","17.26423","0.83319"
"207.48000","17.29024","0.83654"
"207.79200","17.31613","0.83951"
"208.10400","17.34225","0.84224"
"208.41600","17.36826","0.84654"
"208.72800","17.39421","0.85141"
"209.04000","17.42028","0.85548"
"209.35200","17.44617","0.86024"
"209.66400","17.47218","0.86563"
"209.97600","17.49818","0.87042"
"210.28800","17.52425","0.87578"
"210.60000","17.55020","0.88085"
"210.91200","17.57621","0.88511"
"211.22400","17.60222","0.88866"
"211.53600","17.62811","0.89419"
"211.84800","17.65423","0.89940"
"212.16000","17.68018","0.90284"
"212.47200","17.70619","0.90792"
"212.78400","17.73220","0.91340"
"213.09600","17.75821","0.91860"
"213.40800","17.78422","0.92356"
"213.72000","17.81017","0.92551"
"214.03200","17.83623","0.92984"
"214.34400","17.86218","0.93387"
"214.65600","17.88819","0.93830"
"214.96800","17.91426","0.94213"
"215.28000","17.94021","0.94723"
"215.59200","17.96622","0.95323"
"215.90400","17.99222","0.96004"
"216.21600","18.01817","0.96453"
"216.52800","18.04424","0.96908"
"216.84000","18.07019","0.97495"
"217.15200","18.09626","0.95327"
"217.46400","18.12215","0.96102"
"217.77600","18.14822","0.96512"
"218.08800","18.17416","0.96971"
"218.40000","18.20017","0.97339"
"218.71200","18.22624","0.98025"
"219.02400","18.25219","0.98541"
"219.33600","18.27820","0.99092"
"219.64800","18.30409","0.99420"
"219.96000","18.33022","0.99802"
"220.27200","18.35622","1.00282"
"220.58400","18.38217","1.00763"
"220.89600","18.40818","1.01140"
"221.20800","18.43419","1.01459"
"221.52000","18.46026","1.01755"
"221.83200","18.48615","1.01977"
"222.14400","18.51221","1.02241"
"222.45600","18.53822","1.02464"
"222.76800","18.56417","1.02716"
"223.08000","18.59024","1.03572"
"223.39200","18.61619","1.04228"
"223.70400","18.64220","1.04932"
"224.01600","18.66821","1.05728"
"224.32800","18.69421","1.05682"
"224.64000","18.72022","1.06397"
"224.95200","18.74617","1.06924"
"225.26400","18.77218","1.07462"
"225.57600","18.79813","1.07858"
"225.88800","18.82420","1.08611"
"226.20000","18.85021","1.09265"
"226.51200","18.87621","1.10080"
"226.82400","18.90228","1.10793"
"227.13600","18.92817","1.11444"
"227.44800","18.95418","1.11921"
"227.76000","18.98019","1.12415"
"228.07200","19.00620","1.12935"
"228.38400","19.03220","1.13398"
"228.69600","19.05821","1.13687"
"229.00800","19.08422","1.13922"
"229.32000","19.11011","1.14219"
"229.63200","19.13624","0.67657"
"229.94400","19.16225","0.69416"
"230.25600","19.18820","0.69953"
"230.56800","19.21420","0.70740"
"230.88000","19.24015","0.71606"
"231.19200","19.26616","0.72211"
"231.50400","19.29217","0.73057"
"231.81600","19.31824","0.73870"
"232.12800","19.34425","0.74242"
"232.44000","19.37020","0.74934"
"232.75200","19.39620","0.75673"
"233.06400","19.42215","0.76359"
"233.37600","19.44822","0.77805"
"233.68800","19.47417","0.78373"
"234.00000","19.50018","0.79277"
"234.31200","19.52619","0.80642"
"234.62400","19.55213","0.81286"
"234.93600","19.57820","0.82096"
"235.24800","19.60415","0.82455"
"235.56000","19.63022","0.82745"
"235.87200","19.65617","0.83320"
"236.18400","19.68224","0.83681"
"236.49600","19.70824","0.84436"
"236.80800","19.73419","0.85028"
"237.12000","19.76026","0.85712"
"237.43200","19.78621","0.86211"
"237.74400","19.81222","0.86863"
"238.05600","19.83817","0.88004"
"238.36800","19.86418","0.88379"
"238.68000","19.89024","0.89322"
"238.99200","19.91619","0.89874"
"239.30400","19.94226","0.90735"
"239.61600","19.96821","0.91211"
"239.92800","19.99422","0.92101"
"240.24000","20.02017","0.92487"
"240.55200","20.04623","0.92941"
"240.86400","20.07218","0.93420"
"241.17600","20.09819","0.94166"
"241.48800","20.12426","0.95080"
"241.80000","20.15015","0.96045"
"242.11200","20.17616","0.96648"
"242.42400","20.20229","0.97240"
"242.73600","20.22824","0.98113"
"243.04800","20.25424","0.98925"
"243.36000","20.28019","0.99368"
"243.67200","20.30626","1.00016"
"243.98400","20.33221","1.00620"
"244.29600","20.35822","1.01259"
"244.60800","20.38423","1.01600"
"244.92000","20.41018","1.02056"
"245.23200","20.43624","1.02339"
"245.54400","20.46219","1.02894"
"245.85600","20.48820","1.03250"
"246.16800","20.51421","1.03905"
"246.48000","20.54015","1.04279"
"246.79200","20.56623","1.05196"
"247.10400","20.59217","1.06137"
"247.41600","20.61824","1.06627"
"247.72800","20.64419","1.07225"
"248.04000","20.67020","1.07488"
"248.35200","20.69621","1.08564"
"248.66400","20.72215","1.08933"
"248.97600","20.74822","1.09613"
"249.28800","20.77417","1.10371"
"249.60000","20.80024","1.10878"
"249.91200","20.82625","1.11876"
"250.22400","20.85220","1.12264"
"250.53600","20.87815","1.12902"
"250.84800","20.90415","1.13388"
"251.16000","20.93022","1.13719"
"251.47200","20.95617","1.14082"
"251.78400","20.98218","1.14360"
"252.09600","21.00825","1.14885"
"252.40800","21.03414","1.15429"
"252.72000","21.06020","1.16105"
"253.03200","21.08615","1.16724"
"253.34400","21.11228","1.17455"
"253.65600","21.13817","1.18356"
"253.96800","21.16418","1.19262"
"254.28000","21.19019","1.19727"
"254.59200","21.21614","1.20660"
"254.90400","21.24226","1.21512"
"255.21600","21.26821","1.21935"
"255.52800","21.29422","1.22654"
"255.84000","21.32017","1.23482"
"256.15200","21.34618","1.23895"
"256.46400","21.37225","1.24429"
"256.77600","21.39813","1.24971"
"257.08800","21.42420","1.25534"
"257.40000","21.45021","1.26514"
"257.71200","21.47622","1.27341"
"258.02400","21.50217","1.27738"
"258.33600","21.52824","1.28226"
"258.64800","21.55431","1.29078"
"258.96000","21.58013","1.29546"
"259.27200","21.60620","1.29981"
"259.58400","21.63221","1.30705"
"259.89600","21.65816","1.31438"
"260.20800","21.68423","1.31935"
"260.52000","21.71018","1.32548"
"260.83200","21.73625","1.33291"
"261.14400","21.76213","1.34025"
"261.45600","21.78814","1.34573"
"261.76800","21.81421","1.35130"
"262.08000","21.84016","1.35926"
"262.39200","21.86623","1.36755"
"262.70400","21.89212","1.37794"
"263.01600","21.91818","1.38430"
"263.32800","21.94413","1.39269"
"263.64000","21.97014","1.40139"
"263.95200","21.99621","1.41109"
"264.26400","22.02216","1.42083"
"264.57600","22.04823","1.42897"
"264.88800","22.07417","1.43354"
"265.20000","22.10018","1.43870"
"265.51200","22.12625","1.44199"
"265.82400","22.15220","1.44615"
"266.13600","22.17821","1.45097"
"266.44800","22.20416","1.45636"
"266.76000","22.23022","1.46486"
"267.07200","22.25617","1.47378"
"267.38400","22.28224","1.48409"
"267.69600","22.30825","1.49425"
"268.00800","22.33420","1.50194"
"268.32000","22.36021","1.51119"
"268.63200","22.38622","1.52296"
"268.94400","22.41223","1.53205"
"269.25600","22.43824","1.53877"
"269.56800","22.46418","1.54549"
"269.88000","22.49019","1.55267"
"270.19200","22.51614","1.56066"
"270.50400","22.54221","1.56811"
"270.81600","22.56816","1.57630"
"271.12800","22.59422","1.58338"
"271.44000","22.62024","1.58814"
"271.75200","22.64618","1.59548"
"272.06400","22.67225","1.60677"
"272.37600","22.69814","1.62375"
"272.68800","22.72427","1.63552"
"273.00000","22.75022","1.64159"
"273.31200","22.77622","1.64946"
"273.62400","22.80223","1.65764"
"273.93600","22.82818","1.66656"
"274.24800","22.85419","1.67943"
"274.56000","22.88020","1.68932"
"274.87200","22.90621","1.69688"
"275.18400","22.93222","1.70731"
"275.49600","22.95822","1.71546"
"275.80800","22.98429","1.72263"
"276.12000","23.01018","1.73123"
"276.43200","23.03619","1.73693"
"276.74400","23.06220","1.74316"
"277.05600","23.08821","1.74685"
"277.36800","23.11422","1.75234"
"277.68000","23.14016","1.76040"
"277.99200","23.16623","1.76832"
"278.30400","23.19218","1.77882"
"278.61600","23.21825","1.79027"
"278.92800","23.24420","1.80167"
"279.24000","23.27020","1.81202"
"279.55200","23.29622","1.82352"
"279.86400","23.32216","1.83765"
"280.17600","23.34829","1.84472"
"280.48800","23.37418","1.84984"
"280.80000","23.40019","1.85192"
"281.11200","23.42620","1.84993"
"281.42400","23.45220","1.84759"
"281.73600","23.47827","1.84114"
"282.04800","23.50422","1.84460"
"282.36000","23.53023","1.84902"
"282.67200","23.55612","1.82010"
"282.98400","23.58219","1.83780"
"283.29600","23.60820","1.84587"
"283.60800","23.63420","1.83754"
"283.92000","23.66021","1.84664"
"284.23200","23.68616","1.85149"
"284.54400","23.71217","1.85727"
"284.85600","23.73818","1.86081"
"285.16800","23.76418","1.86788"
"285.48000","23.79025","1.87737"
"285.79200","23.81621","1.88895"
"286.10400","23.84221","1.90041"
"286.41600","23.86816","1.91126"
"286.72800","23.89417","1.92108"
"287.04000","23.92024","1.93601"
"287.35200","23.94618","1.94833"
"287.66400","23.97220","1.95569"
"287.97600","23.99814","1.96371"
"288.28800","24.02421","1.97426"
"288.60000","24.05016","1.98632"
"288.91200","24.07617","1.99753"
"289.22400","24.10218","2.00936"
"289.53600","24.12819","2.02182"
"289.84800","24.15420","2.03307"
"290.16000","24.18014","2.04552"
"290.47200","24.20621","1.84781"
"290.78400","24.23222","1.85650"
"291.09600","24.25817","1.86268"
"291.40800","24.28418","1.86925"
"291.72000","24.31013","1.88061"
"292.03200","24.33619","1.89052"
"292.34400","24.36220","1.90292"
"292.65600","24.38815","1.91425"
"292.96800","24.41422","1.92453"
"293.28000","24.44023","1.94032"
"293.59200","24.46624","1.95065"
"293.90400","24.49213","1.70130"
"294.21600","24.51825","0.83391"
"294.52800","24.54420","0.84149"
"294.84000","24.57021","0.82874"
"295.15200","24.59622","0.84761"
"295.46400","24.62217","0.83056"
"295.77600","24.64823","0.84607"
"296.08800","24.67418","0.84999"
"296.40000","24.70019","0.84064"
"296.71200","24.72620","0.85230"
"297.02400","24.75215","0.84338"
"297.33600","24.77822","0.86200"
"297.64800","24.80416","0.71711"
"297.96000","24.83023","0.72363"
"298.27200","24.85618","0.73151"
"298.58400","24.88219","0.72862"
"298.89600","24.90820","0.73813"
"299.20800","24.93415","0.75737"
"299.52000","24.96022","0.75060"
"299.83200","24.98623","0.75929"
"300.14400","25.01223","0.78142"
"300.45600","25.03824","0.77905"
"300.76800","25.06425","0.79283"
"301.08000","25.09020","0.79761"
"301.39200","25.11621","0.80593"
"301.70400","25.14227","0.82205"
"302.01600","25.16816","0.81952"
"302.32800","25.19417","0.82865"
"302.64000","25.22018","0.83283"
"302.95200","25.24619","0.83623"
"303.26400","25.27226","0.85275"
"303.57600","25.29821","0.84989"
"303.88800","25.32427","0.86598"
"304.20000","25.35022","0.87022"
"304.51200","25.37623","0.88409"
"304.82400","25.40224","0.88791"
"305.13600","25.42819","0.89386"
"305.44800","25.45420","0.90578"
"305.76000","25.48015","0.90577"
"306.07200","25.50622","0.92551"
"306.38400","25.53216","0.92389"
"306.69600","25.55817","0.94012"
"307.00800","25.58430","0.93690"
"307.32000","25.61019","0.96033"
"307.63200","25.63620","0.95760"
"307.94400","25.66220","0.97400"
"308.25600","25.68821","0.97078"
"308.56800","25.71422","0.99171"
"308.88000","25.74017","0.99053"
"309.19200","25.76624","1.00694"
"309.50400","25.79219","1.00453"
"309.81600","25.81820","1.01856"
"310.12800","25.84421","0.86162"
"310.44000","25.87028","0.87390"
"310.75200","25.89628","0.87296"
"311.06400","25.92217","0.88065"
"311.37600","25.94818","0.88867"
"311.68800","25.97419","0.89685"
"312.00000","26.00020","0.90944"
"312.31200","26.02621","0.90951"
"312.62400","26.05215","0.26019"
"312.93600","26.07822","0.25966"
"313.24800","26.10411","0.27606"
"313.56000","26.13024","0.28606"
"313.87200","26.15619","0.28669"
"314.18400","26.18225","0.28837"
"314.49600","26.20827","0.29359"
"314.80800","26.23415","0.29842"
"315.12000","26.26022","0.30603"
"315.43200","26.28611","0.31308"
"315.74400","26.31224","0.32036"
"316.05600","26.33819","0.32800"
"316.36800","26.36420","0.33693"
"316.68000","26.39020","0.34570"
"316.99200","26.41615","0.35226"
"317.30400","26.44222","0.35943"
"317.61600","26.46817","0.36520"
"317.92800","26.49424","0.37007"
"318.24000","26.52019","0.37512"
"318.55200","26.54620","0.38411"
"318.86400","26.57220","0.39294"
"319.17600","26.59815","0.40109"
"319.48800","26.62422","0.40846"
"319.80000","26.65017","0.41505"
"320.11200","26.67612","0.42099"
"320.42400","26.70218","0.42607"
"320.73600","26.72813","0.43670"
"321.04800","26.75420","0.45125"
"321.36000","26.78015","0.46859"
"321.67200","26.80616","0.47414"
"321.98400","26.83223","0.47142"
"322.29600","26.85818","0.47270"
"322.60800","26.88424","0.48299"
"322.92000","26.91019","0.49579"
"323.23200","26.93626","0.50239"
"323.54400","26.96215","0.51217"
"323.85600","26.98822","0.52685"
"324.16800","27.01417","0.53117"
"324.48000","27.04018","0.52932"
"324.79200","27.06624","0.53685"
"325.10400","27.09213","0.54520"
"325.41600","27.11826","0.55620"
"325.72800","27.14415","0.57798"
"326.04000","27.17016","0.57971"
"326.35200","27.19622","0.58085"
"326.66400","27.22223","0.59009"
"326.97600","27.24818","0.59885"
"327.28800","27.27419","0.61382"
"327.60000","27.30020","0.61319"
"327.91200","27.32615","0.61675"
"328.22400","27.35222","0.62258"
"328.53600","27.37822","0.64212"
"328.84800","27.40417","0.64704"
"329.16000","27.43024","0.65073"
"329.47200","27.45619","0.65851"
"329.78400","27.48220","0.68057"
"330.09600","27.50827","0.68228"
"330.40800","27.53416","0.68517"
"330.72000","27.56016","0.69757"
"331.03200","27.58611","0.71158"
"331.34400","27.61224","0.71115"
"331.65600","27.63819","0.71608"
"331.96800","27.66426","0.72802"
"332.28000","27.69021","0.72944"
"332.59200","27.71616","0.73430"
"332.90400","27.74223","0.75068"
"333.21600","27.76818","0.75406"
"333.52800","27.79424","0.76020"
"333.84000","27.82019","0.78058"
"334.15200","27.84620","0.78415"
"334.46400","27.87215","0.79040"
"334.77600","27.89810","0.81070"
"335.08800","27.92416","0.81188"
"335.40000","27.95017","0.81925"
"335.71200","27.97624","0.63481"
"336.02400","28.00225","0.63899"
"336.33600","28.02820","0.63953"
"336.64800","28.05421","0.65244"
"336.96000","28.08016","0.67152"
"337.27200","28.10622","0.67930"
"337.58400","28.13223","0.68299"
"337.89600","28.15818","0.69308"
"338.20800","28.18425","0.71178"
"338.52000","28.21014","0.71332"
"338.83200","28.23621","0.71768"
"339.14400","28.26221","0.72819"
"339.45600","28.28822","0.73731"
"339.76800","28.31417","0.74183"
"340.08000","28.34018","0.75503"
"340.39200","28.36625","0.77644"
"340.70400","28.39214","0.77905"
"341.01600","28.41826","0.78889"
"341.32800","28.44415","0.80704"
"341.64000","28.47022","0.80999"
"341.95200","28.49623","0.81994"
"342.26400","28.52218","0.82681"
"342.57600","28.54825","0.82934"
"342.88800","28.57420","0.83958"
"343.20000","28.60026","0.84377"
"343.51200","28.62621","0.85210"
"343.82400","28.65222","0.86428"
"344.13600","28.67823","0.86686"
"344.44800","28.70418","0.87940"
"344.76000","28.73025","0.88757"
"345.07200","28.75613","0.89412"
"345.38400","28.78220","0.90645"
"345.69600","28.80821","0.75247"
"346.00800","28.83416","0.64595"
"346.32000","28.86023","0.65261"
"346.63200","28.88618","0.65397"
"346.94400","28.91225","0.67251"
"347.25600","28.93813","0.66332"
"347.56800","28.96414","0.67986"
"347.88000","28.99027","0.68244"
"348.19200","29.01616","0.69900"
"348.50400","29.04217","0.70191"
"348.81600","29.06812","0.70939"
"349.12800","29.09425","0.71654"
"349.44000","29.12019","0.72263"
"349.75200","29.14614","0.72861"
"350.06400","29.17221","0.73457"
"350.37600","29.19816","0.40289"
"350.68800","29.22423","0.40799"
"351.00000","29.25011","0.41086"
"351.31200","29.27618","0.42231"
"351.62400","29.30225","0.43224"
"351.93600","29.32820","0.43830"
"352.24800","29.35421","0.44778"
"352.56000","29.38016","0.45625"
"352.87200","29.40617","0.46510"
"353.18400","29.43218","0.47665"
"353.49600","29.45818","0.48318"
"353.80800","29.48419","0.49262"
"354.12000","29.51014","0.50415"
"354.43200","29.53621","0.50730"
"354.74400","29.56216","0.51193"
"355.05600","29.58823","0.51435"
"355.36800","29.61423","0.51881"
"355.68000","29.64018","0.52660"
"355.99200","29.66625","0.53138"
"356.30400","29.69208","0.54005"
"356.61600","29.71821","0.54411"
"356.92800","29.74422","0.39413"
"357.24000","29.77023","0.39608"
"357.55200","29.79623","0.39955"
"357.86400","29.82218","0.40291"
"358.17600","29.84825","0.40718"
"358.48800","29.87414","0.41180"
"358.80000","29.90027","0.41827"
"359.11200","29.92622","0.42238"
"359.42400","29.95217","0.42809"
"359.73600","29.97817","0.43527"
"360.04800","30.00412","0.43967"
"360.36000","30.03025","0.44503"
"360.67200","30.05620","0.44947"
"360.98400","30.08221","0.45491"
"361.29600","30.10822","0.46463"
"361.60800","30.13416","0.47121"
"361.92000","30.16017","0.47608"
"362.23200","30.18618","0.48331"
"362.54400","30.21225","0.49004"
"362.85600","30.23814","0.49547"
"363.16800","30.26415","0.50139"
"363.48000","30.29021","0.50613"
"363.79200","30.31616","0.50985"
"364.10400","30.34223","0.51251"
"364.41600","30.36818","0.51590"
"364.72800","30.39419","0.52092"
"365.04000","30.42020","0.52619"
"365.35200","30.44621","0.53226"
"365.66400","30.47221","0.53627"
"365.97600","30.49816","0.54089"
"366.28800","30.52423","0.54497"
"366.60000","30.55018","0.55020"
"366.91200","30.57619","0.55595"
"367.22400","30.60220","0.56397"
"367.53600","30.62820","0.57260"
"367.84800","30.65428","0.57954"
"368.16000","30.68016","0.58600"
"368.47200","30.70623","0.59212"
"368.78400","30.73218","0.59609"
"369.09600","30.75819","0.60025"
"369.40800","30.78425","0.60566"
"369.72000","30.81020","0.61163"
"370.03200","30.83621","0.61629"
"370.34400","30.86216","0.62035"
"370.65600","30.88823","0.62507"
"370.96800","30.91424","0.63111"
"371.28000","30.94019","0.63986"
"371.59200","30.96625","0.64664"
"371.90400","30.99221","0.65169"
"372.21600","31.01821","0.65540"
"372.52800","31.04422","0.66049"
"372.84000","31.07023","0.48156"
"373.15200","31.09624","0.47865"
"373.46400","31.12218","0.48099"
"373.77600","31.14820","0.48463"
"374.08800","31.17414","0.49100"
"374.40000","31.20021","0.49593"
"374.71200","31.22622","0.50107"
"375.02400","31.25223","0.50532"
"375.33600","31.27823","0.50931"
"375.64800","31.30412","0.51264"
"375.96000","31.33019","0.51618"
"376.27200","31.35620","0.52264"
"376.58400","31.38221","0.52819"
"376.89600","31.40822","0.53293"
"377.20800","31.43417","0.53885"
"377.52000","31.46018","0.54469"
"377.83200","31.48612","0.54971"
"378.14400","31.51225","0.55447"
"378.45600","31.53820","0.56137"
"378.76800","31.56421","0.56898"
"379.08000","31.59028","0.57543"
"379.39200","31.61617","0.57822"
"379.70400","31.64218","0.58417"
"380.01600","31.66818","0.59089"
"380.32800","31.69419","0.59567"
"380.64000","31.72014","0.59952"
"380.95200","31.74615","0.60403"
"381.26400","31.77222","0.61025"
"381.57600","31.79816","0.61472"
"381.88800","31.82423","0.61890"
"382.20000","31.85018","0.62361"
"382.51200","31.87625","0.62856"
"382.82400","31.90220","0.36113"
"383.13600","31.92815","0.37223"
"383.44800","31.95422","0.36073"
"383.76000","31.98016","0.35918"
"384.07200","32.00623","0.34883"
"384.38400","32.03212","0.36039"
"384.69600","32.05819","0.35286"
"385.00800","32.08420","0.36711"
"385.32000","32.11015","0.36811"
"385.63200","32.13622","0.37372"
"385.94400","32.16216","0.38183"
"386.25600","32.18823","0.38653"
"386.56800","32.21418","0.39428"
"386.88000","32.24019","0.40035"
"387.19200","32.26626","0.40466"
"387.50400","32.29221","0.40981"
"387.81600","32.31821","0.41732"
"388.12800","32.34416","0.42480"
"388.44000","32.37017","0.43248"
"388.75200","32.39618","0.43747"
"389.06400","32.42219","0.44369"
"389.37600","32.44820","0.44707"
"389.68800","32.47414","0.44973"
"390.00000","32.50027","0.45569"
"390.31200","32.52616","0.46180"
"390.62400","32.55217","0.46749"
"390.93600","32.57824","0.46929"
"391.24800","32.60419","0.47211"
"391.56000","32.63020","0.47573"
"391.87200","32.65609","0.47899"
"392.18400","32.68216","0.48394"
"392.49600","32.70816","0.48366"
"392.80800","32.73417","0.48859"
"393.12000","32.76018","0.49387"
"393.43200","32.78619","0.49933"
"393.74400","32.81226","0.50428"
"394.05600","32.83820","0.50770"
"394.36800","32.86421","0.51114"
"394.68000","32.89022","0.51566"
"394.99200","32.91617","0.52069"
"395.30400","32.94218","0.52722"
"395.61600","32.96812","0.53247"
"395.92800","32.99419","0.54001"
"396.24000","33.02021","0.54500"
"396.55200","33.04621","0.54848"
"396.86400","33.07222","0.55136"
"397.17600","33.09817","0.55369"
"397.48800","33.12418","0.55670"
"397.80000","33.15018","0.56113"
"398.11200","33.17625","0.56698"
"398.42400","33.20221","0.57279"
"398.73600","33.22815","0.54409"
"399.04800","33.25422","0.54812"
"399.36000","33.28011","0.55407"
"399.67200","33.30624","0.55991"
"399.98400","33.33225","0.56687"
"400.29600","33.35825","0.56883"
"400.60800","33.38426","0.57162"
"400.92000","33.41021","0.57342"
"401.23200","33.43622","0.57779"
"401.54400","33.46217","0.57359"
"401.85600","33.48824","0.56546"
"402.16800","33.51425","0.57079"
"402.48000","33.54019","0.57666"
"402.79200","33.56620","0.58232"
"403.10400","33.59215","0.58831"
"403.41600","33.61822","0.47863"
"403.72800","33.64423","0.48154"
"404.04000","33.67018","0.47928"
"404.35200","33.69619","0.48274"
"404.66400","33.72219","0.49163"
"404.97600","33.74820","0.49687"
"405.28800","33.77415","0.50258"
"405.60000","33.80022","0.50431"
"405.91200","33.82617","0.50748"
"406.22400","33.85218","0.51030"
"406.53600","33.87819","0.51185"
"406.84800","33.90413","0.51424"
"407.16000","33.93026","0.51552"
"407.47200","33.95621","0.51879"
"407.78400","33.98222","0.52136"
"408.09600","34.00817","0.52415"
"408.40800","34.03417","0.52718"
"408.72000","34.06024","0.52877"
"409.03200","34.08613","0.53176"
"409.34400","34.11226","0.53420"
"409.65600","34.13815","0.53822"
"409.96800","34.16416","0.54054"
"410.28000","34.19017","0.54560"
"410.59200","34.21617","0.54828"
"410.90400","34.24224","0.55248"
"411.21600","34.26813","0.55667"
"411.52800","34.29420","0.56256"
"411.84000","34.32015","0.56862"
"412.15200","34.34616","0.57291"
"412.46400","34.37223","0.57581"
"412.77600","34.39817","0.57820"
"413.08800","34.42418","0.58059"
"413.40000","34.45013","0.58111"
"413.71200","34.47620","0.58441"
"414.02400","34.50221","0.58782"
"414.33600","34.52816","0.59261"
"414.64800","34.55423","0.59608"
"414.96000","34.58017","0.59915"
"415.27200","34.60624","0.60195"
"415.58400","34.63219","0.60504"
"415.89600","34.65820","0.60841"
"416.20800","34.68427","0.61000"
"416.52000","34.71016","0.61167"
"416.83200","34.73623","0.61421"
"417.14400","34.76217","0.60801"
"417.45600","34.78818","0.61043"
"417.76800","34.81419","0.61319"
"418.08000","34.84019","0.61667"
"418.39200","34.86621","0.56047"
"418.70400","34.89215","0.56680"
"419.01600","34.91822","0.57330"
"419.32800","34.94417","0.57642"
"419.64000","34.97024","0.57965"
"419.95200","34.99619","0.58229"
"420.26400","35.02214","0.58620"
"420.57600","35.04815","0.59072"
"420.88800","35.07410","0.59509"
"421.20000","35.10022","0.59789"
"421.51200","35.12617","0.60080"
"421.82400","35.15218","0.60421"
"422.13600","35.17825","0.60961"
"422.44800","35.20420","0.61415"
"422.76000","35.23014","0.61697"
"423.07200","35.25615","0.61859"
"423.38400","35.28222","0.61962"
"423.69600","35.30823","0.61738"
"424.00800","35.33412","0.60389"
"424.32000","35.36019","0.59293"
"424.63200","35.38614","0.58021"
"424.94400","35.41226","0.55787"
"425.25600","35.43821","0.54438"
"425.56800","35.46422","0.53145"
"425.88000","35.49023","0.52041"
"426.19200","35.51612","0.51396"
"426.50400","35.54225","0.50845"
"426.81600","35.56814","0.50070"
"427.12800","35.59420","0.49080"
"427.44000","35.62015","0.48000"
"427.75200","35.64616","0.47422"
"428.06400","35.67223","0.46745"
"428.37600","35.69818","0.45399"
"428.68800","35.72424","0.44471"
"429.00000","35.75019","0.43821"
"429.31200","35.77620","0.43381"
"429.62400","35.80221","0.43136"
"429.93600","35.82822","0.43114"
"430.24800","35.85423","0.43149"
"430.56000","35.88018","0.43354"
"430.87200","35.90624","0.43390"
"431.18400","35.93214","0.43524"
"431.49600","35.95814","0.43693"
"431.80800","35.98421","0.43924"
"432.12000","36.01022","0.44051"
"432.43200","36.03623","0.44330"
"432.74400","36.06218","0.44570"
"433.05600","36.08824","0.44748"
"433.36800","36.11419","0.45138"
"433.68000","36.14021","0.45351"
"433.99200","36.16627","0.45753"
"434.30400","36.19216","0.46110"
"434.61600","36.21823","0.46562"
"434.92800","36.24417","0.46887"
"435.24000","36.27018","0.47179"
"435.55200","36.29619","0.47399"
"435.86400","36.32214","0.47643"
"436.17600","36.34821","0.47955"
"436.48800","36.37416","0.48329"
"436.80000","36.40023","0.48681"
"437.11200","36.42617","0.49101"
"437.42400","36.45224","0.49496"
"437.73600","36.47825","0.49937"
"438.04800","36.50414","0.50230"
"438.36000","36.53021","0.50612"
"438.67200","36.55616","0.50881"
"438.98400","36.58223","0.51077"
"439.29600","36.60823","0.51317"
"439.60800","36.63419","0.51519"
"439.92000","36.66019","0.51748"
"440.23200","36.68614","0.52044"
"440.54400","36.71221","0.52456"
"440.85600","36.73822","0.52692"
"441.16800","36.76423","0.52977"
"441.48000","36.79023","0.53249"
"441.79200","36.81612","0.53598"
"442.10400","36.84219","0.53909"
"442.41600","36.86814","0.54327"
"442.72800","36.89427","0.54642"
"443.04000","36.92022","0.54983"
"443.35200","36.94622","0.55226"
"443.66400","36.97223","0.55550"
"443.97600","36.99818","0.55898"
"444.28800","37.02419","0.56358"
"444.60000","37.05014","0.56792"
"444.91200","37.07621","0.57178"
"445.22400","37.10215","0.57539"
"445.53600","37.12822","0.57785"
"445.84800","37.15417","0.58113"
"446.16000","37.18018","0.58415"
"446.47200","37.20625","0.58648"
"446.78400","37.23220","0.59051"
"447.09600","37.25821","0.59333"
"447.40800","37.28421","0.59586"
"447.72000","37.31017","0.59812"
"448.03200","37.33623","0.59949"
"448.34400","37.36218","0.60149"
"448.65600","37.38819","0.27918"
"448.96800","37.41414","0.27137"
"449.28000","37.44015","0.27793"
"449.59200","37.46615","0.27874"
"449.90400","37.49216","0.27316"
"450.21600","37.51817","0.27105"
"450.52800","37.54418","0.27384"
"450.84000","37.57019","0.27816"
"451.15200","37.59620","0.28490"
"451.46400","37.62215","0.28880"
"451.77600","37.64827","0.28883"
"452.08800","37.67416","0.28842"
"452.40000","37.70023","0.29105"
"452.71200","37.72618","0.29212"
"453.02400","37.75219","0.29195"
"453.33600","37.77819","-0.03079"
"453.64800","37.80421","-0.00106"
"453.96000","37.83021","-0.01205"
"454.27200","37.85616","-0.00114"
"454.58400","37.88223","-0.00234"
"454.89600","37.90818","-0.01223"
"455.20800","37.93419","0.00306"
"455.52000","37.96025","-0.01029"
"455.83200","37.98620","-0.00355"
"456.14400","38.01215","-0.00082"
"456.45600","38.03816","-0.01016"
"456.76800","38.06417","-0.00049"
"457.08000","38.09024","0.00025"
"457.39200","38.11619","-0.00982"
"457.70400","38.14225","0.00026"
"458.01600","38.16820","-0.00278"
"458.32800","38.19427","-0.00770"
"458.64000","38.22022","0.00196"
"458.95200","38.24623","-0.00572"
"459.26400","38.27230","-0.00425"
"459.57600","38.29819","0.00052"
"459.88800","38.32420","-0.00760"
"460.20000","38.35014","-0.00137"
"460.51200","38.37621","-0.00208"
"460.82400","38.40222","-0.00579"
"461.13600","38.42817","-0.00105"
"461.44800","38.45417","-0.00381"
"461.71600","38.47648","-0.00264"