File: Force_trajectories/161223/Specimen_RawData_1.csv
End date,"12/23/2016"
Specimen label,"22DT_76"
Maximum Load,"0.26583",N

Time,Extension,Load
(s),(mm),(N)
"0.00000","-0.00006","0.00010"
"0.39000","0.03265","-0.00008"
"0.78000","0.06517","0.00040"
"1.17000","0.09764","0.00044"
"1.56000","0.13022","0.00022"
"1.95000","0.16263","0.00101"
"2.34000","0.19515","0.00075"
"2.73000","0.22762","0.00144"
"3.12000","0.26014","0.00056"
"3.51000","0.29267","0.00134"
"3.90000","0.32514","0.00121"
"4.29000","0.35760","0.00132"
"4.68000","0.39013","0.00098"
"5.07000","0.42265","0.00106"
"5.46000","0.45512","0.00073"
"5.85000","0.48770","0.00122"
"6.24000","0.52017","0.00138"
"6.63000","0.55263","0.00139"
"7.02000","0.58510","0.00062"
"7.41000","0.61763","0.00115"
"7.80000","0.65009","0.00118"
"8.19000","0.68262","0.00120"
"8.58000","0.71520","0.00152"
"8.97000","0.74767","0.00155"
"9.36000","0.78013","0.00130"
"9.75000","0.81260","0.00171"
"10.14000","0.84513","0.00102"
"10.53000","0.87765","0.00164"
"10.92000","0.91006","0.00171"
"11.31000","0.94264","0.00115"
"11.70000","0.97511","0.00155"
"12.09000","1.00769","0.00121"
"12.48000","1.04010","0.00103"
"12.87000","1.07262","0.00123"
"13.26000","1.10515","0.00169"
"13.65000","1.13762","0.00125"
"14.04000","1.17014","0.00138"
"14.43000","1.20267","0.00185"
"14.82000","1.23513","0.00184"
"15.21000","1.26760","0.00213"
"15.60000","1.30012","0.00173"
"15.99000","1.33265","0.00171"
"16.38000","1.36517","0.00194"
"16.77000","1.39764","0.00165"
"17.16000","1.43017","0.00206"
"17.55000","1.46269","0.00247"
"17.94000","1.49510","0.00184"
"18.33000","1.52762","0.00206"
"18.72000","1.56015","0.00179"
"19.11000","1.59267","0.00201"
"19.50000","1.62508","0.00210"
"19.89000","1.65766","0.00208"
"20.28000","1.69025","0.00178"
"20.67000","1.72260","0.00226"
"21.06000","1.75512","0.00197"
"21.45000","1.78765","0.00206"
"21.84000","1.82017","0.00187"
"22.23000","1.85258","0.00214"
"22.62000","1.88516","0.00221"
"23.01000","1.91769","0.00272"
"23.40000","1.95016","0.00247"
"23.79000","1.98262","0.00243"
"24.18000","2.01515","0.00259"
"24.57000","2.04773","0.00213"
"24.96000","2.08008","0.00220"
"25.35000","2.11260","0.00243"
"25.74000","2.14519","0.00200"
"26.13000","2.17765","0.00330"
"26.52000","2.21012","0.00298"
"26.91000","2.24259","0.00312"
"27.30000","2.27517","0.00320"
"27.69000","2.30764","0.00310"
"28.08000","2.34004","0.00325"
"28.47000","2.37263","0.00320"
"28.86000","2.40521","0.00360"
"29.25000","2.43756","0.00430"
"29.64000","2.47014","0.00398"
"30.03000","2.50267","0.00349"
"30.42000","2.53508","0.00374"
"30.81000","2.56754","0.00347"
"31.20000","2.60019","0.00354"
"31.59000","2.63271","0.00413"
"31.98000","2.66506","0.00382"
"32.37000","2.69758","0.00408"
"32.76000","2.73017","0.00434"
"33.15000","2.76270","0.00460"
"33.54000","2.79504","0.00427"
"33.93000","2.82763","0.00458"
"34.32000","2.86015","0.00505"
"34.71000","2.89262","0.00494"
"35.10000","2.92514","0.00501"
"35.49000","2.95767","0.00484"
"35.88000","2.99013","0.00556"
"36.27000","3.02260","0.00492"
"36.66000","3.05513","0.00504"
"37.05000","3.08765","0.00513"
"37.44000","3.12012","0.00569"
"37.83000","3.15264","0.00581"
"38.22000","3.18517","0.00625"
"38.61000","3.21769","0.00670"
"39.00000","3.25010","0.00440"
"39.39000","3.28262","0.00404"
"39.78000","3.31521","0.00424"
"40.17000","3.34762","0.00515"
"40.56000","3.38014","0.00530"
"40.95000","3.41267","0.00566"
"41.34000","3.44513","0.00536"
"41.73000","3.47766","0.00605"
"42.12000","3.51012","0.00629"
"42.51000","3.54271","0.00571"
"42.90000","3.57518","0.00588"
"43.29000","3.60758","0.00700"
"43.68000","3.64011","0.00732"
"44.07000","3.67269","0.00677"
"44.46000","3.70516","0.00737"
"44.85000","3.73762","0.00802"
"45.24000","3.77015","0.00807"
"45.63000","3.80267","0.00338"
"46.02000","3.83514","0.00222"
"46.41000","3.86761","0.00237"
"46.80000","3.90019","0.00186"
"47.19000","3.93266","0.00238"
"47.58000","3.96512","0.00163"
"47.97000","3.99759","0.00199"
"48.36000","4.03017","0.00258"
"48.75000","4.06264","0.00228"
"49.14000","4.09510","0.00224"
"49.53000","4.12763","0.00269"
"49.92000","4.16010","0.00210"
"50.31000","4.19262","0.00230"
"50.70000","4.22515","0.00273"
"51.09000","4.25761","0.00218"
"51.48000","4.29014","0.00224"
"51.87000","4.32260","0.00200"
"52.26000","4.35519","0.00229"
"52.65000","4.38765","0.00214"
"53.04000","4.42006","0.00203"
"53.43000","4.45259","0.00213"
"53.82000","4.48517","0.00235"
"54.21000","4.51764","0.00216"
"54.60000","4.55010","0.00268"
"54.99000","4.58263","0.00228"
"55.38000","4.61515","0.00183"
"55.77000","4.64768","0.00185"
"56.16000","4.68009","0.00211"
"56.55000","4.71261","0.00243"
"56.94000","4.74520","0.00252"
"57.33000","4.77760","0.00265"
"57.72000","4.81013","0.00280"
"58.11000","4.84259","0.00250"
"58.50000","4.87512","0.00257"
"58.89000","4.90758","0.00231"
"59.28000","4.94011","0.00269"
"59.67000","4.97264","0.00237"
"60.06000","5.00516","0.00282"
"60.45000","5.03769","0.00304"
"60.84000","5.07009","0.00212"
"61.23000","5.10262","0.00285"
"61.62000","5.13514","0.00296"
"62.01000","5.16761","0.00264"
"62.40000","5.20019","0.00255"
"62.79000","5.23266","0.00301"
"63.18000","5.26519","0.00198"
"63.57000","5.29759","0.00249"
"63.96000","5.33012","0.00262"
"64.35000","5.36270","0.00273"
"64.74000","5.39511","0.00253"
"65.13000","5.42763","0.00249"
"65.52000","5.46016","0.00244"
"65.91000","5.49262","0.00241"
"66.30000","5.52515","0.00266"
"66.69000","5.55768","0.00232"
"67.08000","5.59014","0.00259"
"67.47000","5.62267","0.00253"
"67.86000","5.65513","0.00313"
"68.25000","5.68766","0.00307"
"68.64000","5.72012","0.00272"
"69.03000","5.75259","0.00270"
"69.42000","5.78506","0.00316"
"69.81000","5.81764","0.00307"
"70.20000","5.85011","0.00274"
"70.59000","5.88257","0.00295"
"70.98000","5.91516","0.00307"
"71.37000","5.94768","0.00316"
"71.76000","5.98009","0.00278"
"72.15000","6.01261","0.00337"
"72.54000","6.04520","0.00305"
"72.93000","6.07767","0.00321"
"73.32000","6.11007","0.00344"
"73.71000","6.14266","0.00297"
"74.10000","6.17518","0.00367"
"74.49000","6.20765","0.00398"
"74.88000","6.24011","0.00369"
"75.27000","6.27264","0.00370"
"75.66000","6.30517","0.00376"
"76.05000","6.33757","0.00442"
"76.44000","6.37010","0.00444"
"76.83000","6.40262","0.00396"
"77.22000","6.43515","0.00453"
"77.61000","6.46767","0.00502"
"78.00000","6.50014","0.00466"
"78.39000","6.53272","0.00450"
"78.78000","6.56507","0.00472"
"79.17000","6.59760","0.00566"
"79.56000","6.63018","0.00522"
"79.95000","6.66271","0.00550"
"80.34000","6.69505","0.00577"
"80.73000","6.72764","0.00589"
"81.12000","6.76016","0.00600"
"81.51000","6.79263","0.00607"
"81.90000","6.82510","0.00602"
"82.29000","6.85768","0.00617"
"82.68000","6.89015","0.00667"
"83.07000","6.92261","0.00693"
"83.46000","6.95514","0.00687"
"83.85000","6.98766","0.00737"
"84.24000","7.02013","0.00716"
"84.63000","7.05253","0.00698"
"85.02000","7.08518","0.00746"
"85.41000","7.11764","0.00763"
"85.80000","7.15011","0.00618"
"86.19000","7.18264","0.00636"
"86.58000","7.21516","0.00633"
"86.97000","7.24763","0.00724"
"87.36000","7.28009","0.00736"
"87.75000","7.31268","0.00816"
"88.14000","7.34520","0.00683"
"88.53000","7.37761","0.00780"
"88.92000","7.41008","0.00822"
"89.31000","7.44266","0.00832"
"89.70000","7.47519","0.00859"
"90.09000","7.50759","0.00951"
"90.48000","7.54018","0.00987"
"90.87000","7.57270","0.01063"
"91.26000","7.60511","0.01136"
"91.65000","7.63758","0.01215"
"92.04000","7.67016","0.01215"
"92.43000","7.70269","0.01240"
"92.82000","7.73515","0.01278"
"93.21000","7.76762","0.01310"
"93.60000","7.80020","0.01420"
"93.99000","7.83267","0.01486"
"94.38000","7.86507","0.01572"
"94.77000","7.89766","0.01589"
"95.16000","7.93018","0.01684"
"95.55000","7.96265","0.01714"
"95.94000","7.99512","0.01756"
"96.33000","8.02770","0.01848"
"96.72000","8.06011","0.01915"
"97.11000","8.09263","0.01952"
"97.50000","8.12516","0.01987"
"97.89000","8.15768","0.02107"
"98.28000","8.19015","0.02204"
"98.67000","8.22262","0.02275"
"99.06000","8.25514","0.02320"
"99.45000","8.28767","0.02376"
"99.84000","8.32013","0.02424"
"100.23000","8.35260","0.02127"
"100.62000","8.38518","0.01807"
"101.01000","8.41765","0.01904"
"101.40000","8.45011","0.02064"
"101.79000","8.48258","0.02114"
"102.18000","8.51517","0.02227"
"102.57000","8.54763","0.02346"
"102.96000","8.58010","0.02469"
"103.35000","8.61268","0.02538"
"103.74000","8.64515","0.02616"
"104.13000","8.67755","0.02689"
"104.52000","8.71014","0.02800"
"104.91000","8.74267","0.02935"
"105.30000","8.77513","0.03077"
"105.69000","8.80760","0.03140"
"106.08000","8.84012","0.03238"
"106.47000","8.87271","0.03361"
"106.86000","8.90517","0.03497"
"107.25000","8.93758","0.03618"
"107.64000","8.97016","0.03774"
"108.03000","9.00263","0.03944"
"108.42000","9.03510","0.04032"
"108.81000","9.06762","0.04194"
"109.20000","9.10015","0.04290"
"109.59000","9.13261","0.04367"
"109.98000","9.16514","0.04371"
"110.37000","9.19766","0.04493"
"110.76000","9.23013","0.04594"
"111.15000","9.26265","0.04553"
"111.54000","9.29512","0.04223"
"111.93000","9.32765","0.04477"
"112.32000","9.36011","0.04645"
"112.71000","9.39264","0.04759"
"113.10000","9.42516","0.04862"
"113.49000","9.45763","0.05041"
"113.88000","9.49015","0.05241"
"114.27000","9.52262","0.05321"
"114.66000","9.55508","0.05488"
"115.05000","9.58761","0.05639"
"115.44000","9.62014","0.05806"
"115.83000","9.65260","0.05928"
"116.22000","9.68513","0.06144"
"116.61000","9.71765","0.06391"
"117.00000","9.75012","0.06521"
"117.39000","9.78264","0.06715"
"117.78000","9.81517","0.06917"
"118.17000","9.84764","0.06983"
"118.56000","9.88016","0.07121"
"118.95000","9.91263","0.07231"
"119.34000","9.94515","0.07410"
"119.73000","9.97762","0.07595"
"120.12000","10.01008","0.07772"
"120.51000","10.04261","0.08010"
"120.90000","10.07519","0.08384"
"121.29000","10.10766","0.08554"
"121.68000","10.14012","0.08849"
"122.07000","10.17265","0.09086"
"122.46000","10.20518","0.09198"
"122.85000","10.23758","0.07590"
"123.24000","10.27011","0.07782"
"123.63000","10.30263","0.07876"
"124.02000","10.33516","0.08025"
"124.41000","10.36762","0.08210"
"124.80000","10.40015","0.08366"
"125.19000","10.43268","0.08660"
"125.58000","10.46514","0.08886"
"125.97000","10.49761","0.09153"
"126.36000","10.53013","0.09274"
"126.75000","10.56266","0.09449"
"127.14000","10.59512","0.09533"
"127.53000","10.62765","0.09688"
"127.92000","10.66011","0.09779"
"128.31000","10.69264","0.09902"
"128.70000","10.72511","0.09982"
"129.09000","10.75769","0.10138"
"129.48000","10.79016","0.10218"
"129.87000","10.82256","0.10333"
"130.26000","10.85509","0.10487"
"130.65000","10.88761","0.10618"
"131.04000","10.92014","0.10716"
"131.43000","10.95261","0.10833"
"131.82000","10.98513","0.11003"
"132.21000","11.01772","0.11187"
"132.60000","11.05012","0.11348"
"132.99000","11.08265","0.11597"
"133.38000","11.11517","0.11734"
"133.77000","11.14770","0.11956"
"134.16000","11.18004","0.12116"
"134.55000","11.21263","0.12338"
"134.94000","11.24510","0.12536"
"135.33000","11.27762","0.12757"
"135.72000","11.31003","0.13081"
"136.11000","11.34267","0.13483"
"136.50000","11.37520","0.13835"
"136.89000","11.40754","0.14355"
"137.28000","11.44013","0.14689"
"137.67000","11.47266","0.14978"
"138.06000","11.50518","0.15281"
"138.45000","11.53759","0.15474"
"138.84000","11.57011","0.15786"
"139.23000","11.60270","0.16030"
"139.62000","11.63516","0.16283"
"140.01000","11.66763","0.16595"
"140.40000","11.70015","0.16928"
"140.79000","11.73268","0.17221"
"141.18000","11.76503","0.17495"
"141.57000","11.79767","0.17755"
"141.96000","11.83020","0.17928"
"142.35000","11.86260","0.18139"
"142.74000","11.89507","0.18481"
"143.13000","11.92771","0.18824"
"143.52000","11.96018","0.19131"
"143.91000","11.99259","0.19417"
"144.30000","12.02517","0.05781"
"144.69000","12.05769","0.05759"
"145.08000","12.09016","0.06178"
"145.47000","12.12257","0.06064"
"145.86000","12.15515","0.06292"
"146.25000","12.18768","0.06640"
"146.64000","12.22014","0.06771"
"147.03000","12.25261","0.07032"
"147.42000","12.28513","0.07561"
"147.81000","12.31766","0.08178"
"148.20000","12.35013","0.08360"
"148.59000","12.38259","0.08390"
"148.98000","12.41518","0.08560"
"149.37000","12.44764","0.08573"
"149.76000","12.48005","0.07616"
"150.15000","12.51263","0.07758"
"150.54000","12.54516","0.08058"
"150.93000","12.57757","0.08497"
"151.32000","12.61009","0.08874"
"151.71000","12.64268","0.09047"
"152.10000","12.67520","0.08984"
"152.49000","12.70761","0.09016"
"152.88000","12.74019","0.08984"
"153.27000","12.77266","0.00764"
"153.66000","12.80512","0.01189"
"154.05000","12.83759","0.01115"
"154.44000","12.87017","0.00873"
"154.83000","12.90264","0.01415"
"155.22000","12.93511","0.01317"
"155.61000","12.96757","0.01621"
"156.00000","13.00016","0.01413"
"156.39000","13.03262","0.01301"
"156.78000","13.06515","0.01740"
"157.17000","13.09767","0.01830"
"157.56000","13.13014","0.01798"
"157.95000","13.16267","0.01914"
"158.34000","13.19507","0.01860"
"158.73000","13.22766","0.02072"
"159.12000","13.26018","0.02459"
"159.51000","13.29265","0.02421"
"159.90000","13.32511","0.02371"
"160.29000","13.35764","0.02481"
"160.68000","13.39016","0.02645"
"161.07000","13.42263","0.02840"
"161.46000","13.45516","0.03067"
"161.85000","13.48762","0.03218"
"162.24000","13.52015","0.03172"
"162.63000","13.55267","0.03226"
"163.02000","13.58514","0.03467"
"163.41000","13.61766","0.03672"
"163.80000","13.65013","0.03997"
"164.19000","13.68266","0.04262"
"164.58000","13.71518","0.04503"
"164.97000","13.74765","0.04571"
"165.36000","13.78011","0.04706"
"165.75000","13.81264","0.04869"
"166.14000","13.84510","0.05031"
"166.53000","13.87763","0.05282"
"166.92000","13.91015","0.05491"
"167.31000","13.94268","0.05718"
"167.70000","13.97520","0.06070"
"168.09000","14.00761","0.06398"
"168.48000","14.04014","0.06618"
"168.87000","14.07266","0.06920"
"169.26000","14.10513","0.07086"
"169.65000","14.13765","0.07323"
"170.04000","14.17012","0.07537"
"170.43000","14.20265","0.07778"
"170.82000","14.23511","0.08150"
"171.21000","14.26764","0.08454"
"171.60000","14.30010","0.08843"
"171.99000","14.33263","0.09182"
"172.38000","14.36515","0.09458"
"172.77000","14.39756","0.09650"
"173.16000","14.43015","0.09790"
"173.55000","14.46261","0.10014"
"173.94000","14.49508","0.10196"
"174.33000","14.52766","0.10413"
"174.72000","14.56019","0.10610"
"175.11000","14.59265","0.10869"
"175.50000","14.62512","0.11075"
"175.89000","14.65764","0.11301"
"176.28000","14.69017","0.11566"
"176.67000","14.72264","0.11881"
"177.06000","14.75510","0.12143"
"177.45000","14.78763","0.12490"
"177.84000","14.82015","0.12161"
"178.23000","14.85262","0.12313"
"178.62000","14.88520","0.12456"
"179.01000","14.91767","0.12635"
"179.40000","14.95014","0.13035"
"179.79000","14.98266","0.13591"
"180.18000","15.01518","0.14181"
"180.57000","15.04765","0.14624"
"180.96000","15.08006","0.15043"
"181.35000","15.11258","0.15408"
"181.74000","15.14517","0.15743"
"182.13000","15.17763","0.16105"
"182.52000","15.21010","0.16505"
"182.91000","15.24268","0.16893"
"183.30000","15.27521","0.17369"
"183.69000","15.30756","0.17478"
"184.08000","15.34014","0.17827"
"184.47000","15.37267","0.18100"
"184.86000","15.40519","0.18321"
"185.25000","15.43760","0.18666"
"185.64000","15.47012","0.19001"
"186.03000","15.50265","0.19361"
"186.42000","15.53511","0.19614"
"186.81000","15.56764","0.19916"
"187.20000","15.60017","0.20325"
"187.59000","15.63263","0.20648"
"187.98000","15.66504","0.20932"
"188.37000","15.69762","0.21160"
"188.76000","15.73015","0.21400"
"189.15000","15.76267","0.21568"
"189.54000","15.79508","0.21844"
"189.93000","15.82760","0.21848"
"190.32000","15.86019","0.22044"
"190.71000","15.89265","0.21998"
"191.10000","15.92512","0.22187"
"191.49000","15.95765","0.22441"
"191.88000","15.99017","0.22848"
"192.27000","16.02258","0.11884"
"192.66000","16.05516","0.12036"
"193.05000","16.08769","0.12493"
"193.44000","16.12009","0.12646"
"193.83000","16.15262","0.13195"
"194.22000","16.18515","0.13491"
"194.61000","16.21767","0.14130"
"195.00000","16.25008","0.14506"
"195.39000","16.28266","0.12499"
"195.78000","16.31519","0.12728"
"196.17000","16.34765","0.12939"
"196.56000","16.38006","0.03206"
"196.95000","16.41265","0.03085"
"197.34000","16.44523","0.02582"
"197.73000","16.47758","0.02749"
"198.12000","16.51016","0.03434"
"198.51000","16.54263","0.03221"
"198.90000","16.57515","0.03234"
"199.29000","16.60762","0.03418"
"199.68000","16.64008","0.03445"
"200.07000","16.67267","0.03693"
"200.46000","16.70514","0.04114"
"200.85000","16.73760","0.04558"
"201.24000","16.77019","0.04675"
"201.63000","16.80271","0.04661"
"202.02000","16.83506","0.04725"
"202.41000","16.86764","0.04890"
"202.80000","16.90017","0.05049"
"203.19000","16.93263","0.05219"
"203.58000","16.96510","0.05366"
"203.97000","16.99769","0.05610"
"204.36000","17.03015","0.05863"
"204.75000","17.06262","0.06191"
"205.14000","17.09502","0.06391"
"205.53000","17.12773","0.06612"
"205.92000","17.16014","0.06828"
"206.31000","17.19254","0.07052"
"206.70000","17.22519","0.07172"
"207.09000","17.25765","0.07328"
"207.48000","17.29012","0.07470"
"207.87000","17.32258","0.07614"
"208.26000","17.35517","0.07885"
"208.65000","17.38769","0.08129"
"209.04000","17.42010","0.08450"
"209.43000","17.45262","0.08773"
"209.82000","17.48521","0.08996"
"210.21000","17.51768","0.09178"
"210.60000","17.55008","0.09385"
"210.99000","17.58267","0.09548"
"211.38000","17.61513","0.09661"
"211.77000","17.64760","0.09829"
"212.16000","17.68006","0.09969"
"212.55000","17.71265","0.10109"
"212.94000","17.74512","0.10278"
"213.33000","17.77764","0.10346"
"213.72000","17.81011","0.10557"
"214.11000","17.84263","0.10684"
"214.50000","17.87516","0.10811"
"214.89000","17.90762","0.11005"
"215.28000","17.94021","0.11156"
"215.67000","17.97261","0.11375"
"216.06000","18.00520","0.11530"
"216.45000","18.03767","0.11764"
"216.84000","18.07019","0.11959"
"217.23000","18.10266","0.12172"
"217.62000","18.13512","0.12418"
"218.01000","18.16765","0.12671"
"218.40000","18.20017","0.12998"
"218.79000","18.23270","0.13249"
"219.18000","18.26505","0.13755"
"219.57000","18.29763","0.14103"
"219.96000","18.33022","0.14452"
"220.35000","18.36262","0.14828"
"220.74000","18.39515","0.15061"
"221.13000","18.42767","0.15305"
"221.52000","18.46014","0.15522"
"221.91000","18.49260","0.15792"
"222.30000","18.52513","0.16038"
"222.69000","18.55766","0.16300"
"223.08000","18.59018","0.16642"
"223.47000","18.62259","0.16877"
"223.86000","18.65511","0.17188"
"224.25000","18.68758","0.17422"
"224.64000","18.72016","0.17620"
"225.03000","18.75263","0.17859"
"225.42000","18.78515","0.18018"
"225.81000","18.81762","0.18164"
"226.20000","18.85015","0.18474"
"226.59000","18.88261","0.18733"
"226.98000","18.91514","0.19041"
"227.37000","18.94766","0.19312"
"227.76000","18.98007","0.19610"
"228.15000","19.01265","0.19815"
"228.54000","19.04512","0.20105"
"228.93000","19.07764","0.20270"
"229.32000","19.11011","0.20579"
"229.71000","19.14264","0.20802"
"230.10000","19.17510","0.21041"
"230.49000","19.20763","0.21222"
"230.88000","19.24009","0.21360"
"231.27000","19.27268","0.21557"
"231.66000","19.30514","0.21695"
"232.05000","19.33761","0.21503"
"232.44000","19.37013","0.21602"
"232.83000","19.40266","0.21795"
"233.22000","19.43513","0.21934"
"233.61000","19.46759","0.22252"
"234.00000","19.50018","0.22449"
"234.39000","19.53270","0.22608"
"234.78000","19.56511","0.22870"
"235.17000","19.59764","0.23072"
"235.56000","19.63016","0.23288"
"235.95000","19.66269","0.23451"
"236.34000","19.69509","0.23728"
"236.73000","19.72768","0.24001"
"237.12000","19.76014","0.24390"
"237.51000","19.79267","0.24686"
"237.90000","19.82507","0.24958"
"238.29000","19.85766","0.25178"
"238.68000","19.89018","0.25453"
"239.07000","19.92259","0.25755"
"239.46000","19.95517","0.25131"
"239.85000","19.98764","0.25401"
"240.24000","20.02017","0.25582"
"240.63000","20.05263","0.25884"
"241.02000","20.08516","0.26149"
"241.41000","20.11774","0.26552"
"241.80000","20.15003","0.24660"
"242.19000","20.18255","0.10647"
"242.58000","20.21514","0.09287"
"242.97000","20.24766","0.07673"
"243.36000","20.28007","0.09170"
"243.75000","20.31266","0.08812"
"244.14000","20.34518","0.08991"
"244.53000","20.37759","0.10103"
"244.92000","20.41005","0.10655"
"245.31000","20.44270","0.10479"
"245.70000","20.47517","0.10286"
"246.09000","20.50757","0.10464"
"246.48000","20.54015","0.10735"
"246.87000","20.57268","0.11017"
"247.26000","20.60515","0.11241"
"247.65000","20.63755","0.11623"
"248.04000","20.67014","0.12224"
"248.43000","20.70266","0.09211"
"248.82000","20.73513","0.05209"
"249.21000","20.76760","0.06199"
"249.60000","20.80012","0.04660"
"249.99000","20.83265","0.04809"
"250.38000","20.86505","0.06163"
"250.77000","20.89764","0.06419"
"251.16000","20.93016","0.05717"
"251.55000","20.96263","0.05631"
"251.94000","20.99510","0.06545"
"252.33000","21.02762","0.06805"
"252.72000","21.06015","0.06400"
"253.11000","21.09255","0.06709"
"253.50000","21.12514","0.07108"
"253.89000","21.15766","0.07720"
"254.28000","21.19013","0.07279"
"254.67000","21.22253","0.07077"
"255.06000","21.25518","0.07283"
"255.45000","21.28771","0.07653"
"255.84000","21.32011","0.08760"
"256.23000","21.35264","0.08865"
"256.62000","21.38516","0.08319"
"257.01000","21.41768","0.08267"
"257.40000","21.45003","0.08531"
"257.79000","21.48262","0.08983"
"258.18000","21.51520","0.09539"
"258.57000","21.54761","0.09883"
"258.96000","21.58008","0.09965"
"259.35000","21.61266","0.09908"
"259.74000","21.64513","0.09906"
"260.13000","21.67759","0.09993"
"260.52000","21.71012","0.10146"
"260.91000","21.74270","0.10304"
"261.30000","21.77517","0.10471"
"261.69000","21.80757","0.10694"
"262.08000","21.84016","0.10677"
"262.47000","21.87269","0.10783"
"262.86000","21.90503","0.10970"
"263.25000","21.93756","0.11159"
"263.64000","21.97014","0.11337"
"264.03000","22.00267","0.11564"
"264.42000","22.03513","0.03967"
"264.81000","22.06766","0.04258"
"265.20000","22.10012","0.04677"
"265.59000","22.13265","0.04910"
"265.98000","22.16506","0.04862"
"266.37000","22.19764","0.05075"
"266.76000","22.23011","0.05429"
"267.15000","22.26263","0.05577"
"267.54000","22.29510","0.05710"
"267.93000","22.32762","0.05798"
"268.32000","22.36015","0.06050"
"268.71000","22.39262","0.06345"
"269.10000","22.42514","0.01093"
"269.49000","22.45767","0.00632"
"269.88000","22.49013","0.00559"
"270.27000","22.52254","0.00597"
"270.66000","22.55518","0.00559"
"271.05000","22.58765","0.00829"
"271.44000","22.62011","0.00636"
"271.83000","22.65258","0.01121"
"272.22000","22.68517","0.00632"
"272.61000","22.71763","0.01133"
"273.00000","22.75010","0.00671"
"273.39000","22.78268","0.01159"
"273.78000","22.81509","0.00705"
"274.17000","22.84761","0.01206"
"274.56000","22.88014","0.00795"
"274.95000","22.91266","0.01233"
"275.34000","22.94519","0.00927"
"275.73000","22.97766","0.01152"
"276.12000","23.01012","0.01160"
"276.51000","23.04264","0.01167"
"276.90000","23.07517","0.01311"
"277.29000","23.10764","0.01257"
"277.68000","23.14016","0.01512"
"278.07000","23.17257","0.01410"
"278.46000","23.20515","0.01562"
"278.85000","23.23762","0.01531"
"279.24000","23.27015","0.01685"
"279.63000","23.30267","0.01774"
"280.02000","23.33514","0.01786"
"280.41000","23.36760","0.01860"
"280.80000","23.40019","0.01922"
"281.19000","23.43266","0.02053"
"281.58000","23.46512","0.02069"
"281.97000","23.49764","0.02200"
"282.36000","23.53011","0.02297"
"282.75000","23.56264","0.02427"
"283.14000","23.59510","0.02433"
"283.53000","23.62757","0.02546"
"283.92000","23.66015","0.02629"
"284.31000","23.69262","0.02705"
"284.70000","23.72515","0.02795"
"285.09000","23.75767","0.02873"
"285.48000","23.79013","0.02996"
"285.87000","23.82260","0.03127"
"286.26000","23.85513","0.03179"
"286.65000","23.88765","0.03372"
"287.04000","23.92012","0.03581"
"287.43000","23.95264","0.03667"
"287.82000","23.98517","0.03933"
"288.21000","24.01769","0.04070"
"288.60000","24.05010","0.04204"
"288.99000","24.08257","0.04373"
"289.38000","24.11515","0.04563"
"289.77000","24.14762","0.04636"
"290.16000","24.18014","0.04828"
"290.55000","24.21267","0.04887"
"290.94000","24.24514","0.05039"
"291.33000","24.27766","0.05190"
"291.72000","24.31013","0.05340"
"292.11000","24.34265","0.05508"
"292.50000","24.37511","0.05608"
"292.89000","24.40758","0.05828"
"293.28000","24.44011","0.05934"
"293.67000","24.47263","0.06191"
"294.06000","24.50516","0.06295"
"294.45000","24.53757","0.06456"
"294.84000","24.57021","0.06577"
"295.23000","24.60267","0.06770"
"295.62000","24.63508","0.06951"
"296.01000","24.66761","0.07108"
"296.40000","24.70019","0.07191"
"296.79000","24.73272","0.07334"
"297.18000","24.76506","0.07441"
"297.57000","24.79765","0.07488"
"297.96000","24.83018","0.07759"
"298.35000","24.86264","0.07813"
"298.74000","24.89511","0.08045"
"299.13000","24.92769","0.08280"
"299.52000","24.96016","0.08518"
"299.91000","24.99256","0.08802"
"300.30000","25.02515","0.09027"
"300.69000","25.05762","0.09207"
"301.08000","25.09014","0.09342"
"301.47000","25.12260","0.09462"
"301.86000","25.15507","0.09607"
"302.25000","25.18772","0.09737"
"302.64000","25.22012","0.09806"
"303.03000","25.25259","0.09946"
"303.42000","25.28517","0.09993"
"303.81000","25.31764","0.10121"
"304.20000","25.35004","0.10237"
"304.59000","25.38263","0.10337"
"304.98000","25.41516","0.10450"
"305.37000","25.44762","0.10547"
"305.76000","25.48015","0.10615"
"306.15000","25.51267","0.03415"
"306.54000","25.54520","0.03301"
"306.93000","25.57755","0.02584"
"307.32000","25.61013","0.02843"
"307.71000","25.64265","0.03781"
"308.10000","25.67518","0.03807"
"308.49000","25.70753","0.03309"
"308.88000","25.74017","0.03472"
"309.27000","25.77270","0.04035"
"309.66000","25.80511","0.04566"
"310.05000","25.83763","0.04570"
"310.44000","25.87016","0.04478"
"310.83000","25.90268","0.04691"
"311.22000","25.93508","0.05017"
"311.61000","25.96767","0.05400"
"312.00000","26.00020","0.05527"
"312.39000","26.03266","0.05542"
"312.78000","26.06507","0.05657"
"313.17000","26.09765","0.05964"
"313.56000","26.13018","0.06385"
"313.95000","26.16258","0.06692"
"314.34000","26.19511","0.06856"
"314.73000","26.22769","0.06956"
"315.12000","26.26016","0.07094"
"315.51000","26.29257","0.07175"
"315.90000","26.32515","0.07442"
"316.29000","26.35768","0.07700"
"316.68000","26.39009","0.08011"
"317.07000","26.42261","0.08144"
"317.46000","26.45520","0.08362"
"317.85000","26.48766","0.08597"
"318.24000","26.52013","0.08784"
"318.63000","26.55265","0.09026"
"319.02000","26.58518","0.09347"
"319.41000","26.61765","0.09518"
"319.80000","26.65011","0.09637"
"320.19000","26.68263","0.09501"
"320.58000","26.71516","0.09648"
"320.97000","26.74769","0.09801"
"321.36000","26.78003","0.09906"
"321.75000","26.81267","0.10013"
"322.14000","26.84514","0.10054"
"322.53000","26.87755","0.10183"
"322.92000","26.91013","0.10282"
"323.31000","26.94266","0.10433"
"323.70000","26.97512","0.10478"
"324.09000","27.00759","0.10558"
"324.48000","27.04018","0.10673"
"324.87000","27.07264","0.10751"
"325.26000","27.10511","0.10889"
"325.65000","27.13763","0.11085"
"326.04000","27.17016","0.11259"
"326.43000","27.20263","0.11397"
"326.82000","27.23515","0.11592"
"327.21000","27.26767","0.11697"
"327.60000","27.30014","0.11852"
"327.99000","27.33261","0.11981"
"328.38000","27.36507","0.12125"
"328.77000","27.39766","0.12350"
"329.16000","27.43012","0.12523"
"329.55000","27.46265","0.12597"
"329.94000","27.49511","0.12830"
"330.33000","27.52764","0.12993"
"330.72000","27.56016","0.13225"
"331.11000","27.59257","0.13488"
"331.50000","27.62515","0.13804"
"331.89000","27.65762","0.14066"
"332.28000","27.69015","0.14380"
"332.67000","27.72261","0.14646"
"333.06000","27.75520","0.14828"
"333.45000","27.78766","0.15072"
"333.84000","27.82007","0.15170"
"334.23000","27.85260","0.15337"
"334.62000","27.88512","0.15460"
"335.01000","27.91759","0.15590"
"335.40000","27.95011","0.15805"
"335.79000","27.98264","0.15950"
"336.18000","28.01516","0.16197"
"336.57000","28.04763","0.16347"
"336.96000","28.08016","0.16539"
"337.35000","28.11268","0.16655"
"337.74000","28.14520","0.16868"
"338.13000","28.17761","0.17014"
"338.52000","28.21014","0.17137"
"338.91000","28.24266","0.17339"
"339.30000","28.27513","0.17525"
"339.69000","28.30759","0.17639"
"340.08000","28.34012","0.17769"
"340.47000","28.37265","0.17866"
"340.86000","28.40511","0.18007"
"341.25000","28.43764","0.18118"
"341.64000","28.47022","0.18309"
"342.03000","28.50263","0.18447"
"342.42000","28.53515","0.18649"
"342.81000","28.56762","0.18805"
"343.20000","28.60009","0.18974"
"343.59000","28.63261","0.19157"
"343.98000","28.66514","0.19256"
"344.37000","28.69766","0.19399"
"344.76000","28.73019","0.19600"
"345.15000","28.76265","0.19747"
"345.54000","28.79512","0.19880"
"345.93000","28.82764","0.19979"
"346.32000","28.86017","0.20109"
"346.71000","28.89258","0.20250"
"347.10000","28.92510","0.20386"
"347.49000","28.95769","0.20565"
"347.88000","28.99015","0.20681"
"348.27000","29.02262","0.20849"
"348.66000","29.05514","0.20963"
"349.05000","29.08767","0.21030"
"349.44000","29.12007","0.21117"
"349.83000","29.15260","0.21217"
"350.22000","29.18518","0.21337"
"350.61000","29.21765","0.21382"
"351.00000","29.25006","0.21487"
"351.39000","29.28264","0.21572"
"351.78000","29.31511","0.21642"
"352.17000","29.34763","0.21762"
"352.56000","29.38010","0.21874"
"352.95000","29.41269","0.22026"
"353.34000","29.44521","0.22163"
"353.73000","29.47762","0.22327"
"354.12000","29.51008","0.22506"
"354.51000","29.54267","0.22632"
"354.90000","29.57519","0.22712"
"355.29000","29.60754","0.07696"
"355.68000","29.64012","0.06733"
"356.07000","29.67265","0.07441"
"356.46000","29.70511","0.09822"
"356.85000","29.73764","0.07405"
"357.24000","29.77017","0.07251"
"357.63000","29.80269","0.08304"
"358.02000","29.83510","0.08621"
"358.41000","29.86762","0.08285"
"358.80000","29.90015","0.08734"
"359.19000","29.93262","0.08993"
"359.58000","29.96508","0.08087"
"359.97000","29.99767","0.08787"
"360.36000","30.03019","0.09950"
"360.75000","30.06260","0.08721"
"361.14000","30.09512","0.08463"
"361.53000","30.12765","0.10020"
"361.92000","30.16017","0.09166"
"362.31000","30.19258","0.09387"
"362.70000","30.22511","0.09924"
"363.09000","30.25769","0.09906"
"363.48000","30.29016","0.09428"
"363.87000","30.32262","0.09506"
"364.26000","30.35515","0.10335"
"364.65000","30.38767","0.09738"
"365.04000","30.42008","0.09850"
"365.43000","30.45261","0.10231"
"365.82000","30.48519","0.10357"
"366.21000","30.51765","0.01673"
"366.60000","30.55006","0.01524"
"366.99000","30.58265","0.00934"
"367.38000","30.61523","0.01626"
"367.77000","30.64758","0.01712"
"368.16000","30.68016","0.00898"
"368.55000","30.71269","0.00747"
"368.94000","30.74515","0.01008"
"369.33000","30.77756","0.01866"
"369.72000","30.81014","0.01834"
"370.11000","30.84267","0.01105"
"370.50000","30.87514","0.01053"
"370.89000","30.90760","0.01117"
"371.28000","30.94013","0.01651"
"371.67000","30.97271","0.01689"
"372.06000","31.00512","0.01408"
"372.45000","31.03758","0.01344"
"372.84000","31.07017","0.01279"
"373.23000","31.10263","0.01670"
"373.62000","31.13504","0.01739"
"374.01000","31.16769","0.01869"
"374.40000","31.20015","0.01621"
"374.79000","31.23262","0.01472"
"375.18000","31.26508","0.01506"
"375.57000","31.29773","0.01469"
"375.96000","31.33014","0.01788"
"376.35000","31.36266","0.01860"
"376.74000","31.39513","0.02156"
"377.13000","31.42765","0.02028"
"377.52000","31.46018","0.02077"
"377.91000","31.49258","0.01920"
"378.30000","31.52517","0.01931"
"378.69000","31.55763","0.01995"
"379.08000","31.59010","0.02045"
"379.47000","31.62262","0.02225"
"379.86000","31.65515","0.02220"
"380.25000","31.68761","0.02350"
"380.64000","31.72008","0.02369"
"381.03000","31.75266","0.02451"
"381.42000","31.78513","0.02448"
"381.81000","31.81766","0.02590"
"382.20000","31.85012","0.02582"
"382.59000","31.88271","0.02774"
"382.98000","31.91511","0.02718"
"383.37000","31.94758","0.02841"
"383.76000","31.98010","0.02877"
"384.15000","32.01269","0.02949"
"384.54000","32.04515","0.02981"
"384.93000","32.07762","0.03055"
"385.32000","32.11009","0.03200"
"385.71000","32.14261","0.03226"
"386.10000","32.17514","0.03363"
"386.49000","32.20760","0.03348"
"386.88000","32.24019","0.03564"
"387.27000","32.27266","0.03503"
"387.66000","32.30512","0.03774"
"388.05000","32.33765","0.03774"
"388.44000","32.37017","0.03917"
"388.83000","32.40264","0.04049"
"389.22000","32.43504","0.04115"
"389.61000","32.46763","0.04199"
"390.00000","32.50010","0.04223"
"390.39000","32.53262","0.04452"
"390.78000","32.56515","0.04396"
"391.17000","32.59767","0.04562"
"391.56000","32.63020","0.04570"
"391.95000","32.66261","0.04550"
"392.34000","32.69513","0.04700"
"392.73000","32.72771","0.04708"
"393.12000","32.76012","0.04716"
"393.51000","32.79259","0.04793"
"393.90000","32.82517","0.00016"
"394.29000","32.85764","0.00119"
"394.68000","32.89010","0.00197"
"395.07000","32.92269","0.00184"
"395.46000","32.95515","0.00153"
"395.85000","32.98762","0.00178"
"396.24000","33.02014","0.00211"
"396.63000","33.05261","0.00172"
"397.02000","33.08519","0.00157"
"397.41000","33.11766","0.00239"
"397.80000","33.15007","0.00158"
"398.19000","33.18265","0.00185"
"398.58000","33.21518","0.00221"
"398.97000","33.24764","0.00166"
"399.36000","33.28011","0.00157"
"399.75000","33.31263","0.00205"
"400.14000","33.34516","0.00168"
"400.53000","33.37757","0.00178"
"400.92000","33.41015","0.00124"
"401.31000","33.44262","0.00210"
"401.70000","33.47514","0.00115"
"402.09000","33.50761","0.00123"
"402.48000","33.54013","0.00186"
"402.87000","33.57266","0.00151"
"403.26000","33.60513","0.00173"
"403.65000","33.63759","0.00206"
"404.04000","33.67012","0.00139"
"404.43000","33.70264","0.00178"
"404.82000","33.73511","0.00167"
"405.21000","33.76757","0.00189"
"405.60000","33.80016","0.00178"
"405.99000","33.83263","0.00173"
"406.38000","33.86509","0.00197"
"406.77000","33.89767","0.00160"
"407.16000","33.93020","0.00170"
"407.55000","33.96261","0.00220"
"407.94000","33.99513","0.00157"
"408.33000","34.02766","0.00109"
"408.72000","34.06018","0.00194"
"409.11000","34.09259","0.00134"
"409.50000","34.12511","0.00112"
"409.89000","34.15770","0.00171"
"410.28000","34.19017","0.00164"
"410.67000","34.22257","0.00134"
"411.06000","34.25516","0.00212"
"411.45000","34.28769","0.00154"
"411.84000","34.32009","0.00177"
"412.23000","34.35262","0.00147"
"412.62000","34.38514","0.00124"
"413.01000","34.41767","0.00166"
"413.40000","34.45013","0.00151"
"413.79000","34.48266","0.00162"
"414.18000","34.51518","0.00141"
"414.57000","34.54765","0.00163"
"414.96000","34.58005","0.00152"
"415.35000","34.61270","0.00143"
"415.74000","34.64523","0.00178"
"416.13000","34.67757","0.00150"
"416.52000","34.71016","0.00183"
"416.91000","34.74268","0.00205"
"417.30000","34.77515","0.00218"
"417.69000","34.80761","0.00191"
"418.08000","34.84014","0.00172"
"418.47000","34.87266","0.00184"
"418.86000","34.90507","0.00198"
"419.25000","34.93760","0.00155"
"419.64000","34.97018","0.00194"
"420.03000","35.00264","0.00221"
"420.42000","35.03505","0.00133"
"420.81000","35.06764","0.00221"
"421.20000","35.10016","0.00151"
"421.59000","35.13263","0.00152"
"421.98000","35.16515","0.00197"
"422.37000","35.19762","0.00190"
"422.76000","35.23021","0.00248"
"423.15000","35.26255","0.00181"
"423.54000","35.29508","0.00236"
"423.93000","35.32766","0.00213"
"424.32000","35.36019","0.00243"
"424.71000","35.39259","0.00302"
"425.10000","35.42518","0.00161"
"425.49000","35.45770","0.00189"
"425.88000","35.49005","0.00296"
"426.27000","35.52264","0.00188"
"426.66000","35.55516","0.00210"
"427.05000","35.58763","0.00250"
"427.44000","35.62009","0.00189"
"427.83000","35.65262","0.00215"
"428.22000","35.68520","0.00261"
"428.61000","35.71761","0.00265"
"429.00000","35.75014","0.00248"
"429.39000","35.78260","0.00236"
"429.78000","35.81519","0.00331"
"430.17000","35.84759","0.00227"
"430.56000","35.88012","0.00208"
"430.95000","35.91270","0.00329"
"431.34000","35.94511","0.00208"
"431.73000","35.97763","0.00190"
"432.12000","36.01016","0.00340"
"432.51000","36.04263","0.00252"
"432.90000","36.07515","0.00222"
"433.29000","36.10762","0.00338"
"433.68000","36.14021","0.00282"
"434.07000","36.17266","0.00237"
"434.46000","36.20507","0.00340"
"434.85000","36.23766","0.00302"
"435.24000","36.27018","0.00255"
"435.63000","36.30265","0.00349"
"436.02000","36.33511","0.00268"
"436.41000","36.36764","0.00283"
"436.80000","36.40017","0.00330"
"437.19000","36.43263","0.00350"
"437.58000","36.46510","0.00295"
"437.97000","36.49768","0.00287"
"438.36000","36.53015","0.00396"
"438.75000","36.56261","0.00286"
"439.14000","36.59514","0.00310"
"439.53000","36.62761","0.00405"
"439.92000","36.66013","0.00262"
"440.31000","36.69266","0.00380"
"440.70000","36.72518","0.00419"
"441.09000","36.75759","0.00346"
"441.48000","36.79012","0.00415"
"441.87000","36.82258","0.00478"
"442.26000","36.85516","0.00321"
"442.65000","36.88769","0.00493"
"443.04000","36.92004","0.00426"
"443.43000","36.95268","0.00362"
"443.82000","36.98515","0.00640"
"444.21000","37.01761","0.00434"
"444.60000","37.05014","0.00421"
"444.99000","37.08266","0.00683"
"445.38000","37.11513","0.00430"
"445.77000","37.14760","0.00476"
"446.16000","37.18012","0.00740"
"446.55000","37.21265","0.00431"
"446.94000","37.24511","0.00544"
"447.33000","37.27764","0.00707"
"447.72000","37.31017","0.00477"
"448.11000","37.34263","0.00754"
"448.50000","37.37510","0.00641"
"448.89000","37.40762","0.00596"
"449.28000","37.44015","0.00839"
"449.67000","37.47267","0.00599"
"450.06000","37.50508","0.00691"
"450.45000","37.53761","0.00859"
"450.84000","37.57013","0.00658"
"451.23000","37.60266","0.00925"
"451.62000","37.63512","0.00770"
"452.01000","37.66758","0.00818"
"452.40000","37.70011","0.01004"
"452.79000","37.73264","0.00820"
"453.18000","37.76510","0.01044"
"453.57000","37.79763","0.00980"
"453.96000","37.83015","0.01019"
"454.35000","37.86262","0.01170"
"454.74000","37.89514","0.01037"
"455.13000","37.92767","0.01221"
"455.52000","37.96019","0.01092"
"455.91000","37.99266","0.01216"
"456.30000","38.02513","0.01247"
"456.69000","38.05765","0.01213"
"457.08000","38.09012","0.01388"
"457.47000","38.12258","0.01305"
"457.86000","38.15517","0.01446"
"458.25000","38.18763","0.01380"
"458.64000","38.22010","0.01433"
"459.03000","38.25262","0.01468"
"459.42000","38.28509","0.01482"
"459.81000","38.31768","0.01569"
"460.20000","38.35008","0.01550"
"460.59000","38.38261","0.01664"
"460.98000","38.41519","0.01628"
"461.37000","38.44760","0.01730"
"461.76000","38.48006","0.01731"
"462.15000","38.51265","0.01747"
"462.54000","38.54512","0.01828"
"462.93000","38.57758","0.01863"
"463.32000","38.61017","0.01916"
"463.71000","38.64264","0.01950"
"464.10000","38.67510","0.01967"
"464.49000","38.70757","0.01996"
"464.88000","38.74015","0.02085"
"465.27000","38.77267","0.02035"
"465.66000","38.80514","0.02098"
"466.05000","38.83761","0.02125"
"466.44000","38.87013","0.02181"
"466.83000","38.90266","0.01828"
"467.22000","38.93507","0.01844"
"467.61000","38.96759","0.01848"
"468.00000","39.00018","0.01882"
"468.39000","39.03264","0.01913"
"468.78000","39.06511","0.01955"
"469.17000","39.09769","0.02000"
"469.56000","39.13015","0.01152"
"469.95000","39.16256","0.00784"
"470.34000","39.19515","0.01022"
"470.73000","39.22768","0.00871"
"471.12000","39.26014","0.01053"
"471.51000","39.29260","0.00995"
"471.90000","39.32513","0.01010"
"472.29000","39.35765","0.00925"
"472.68000","39.39012","0.01024"
"473.07000","39.42265","0.00944"
"473.46000","39.45517","0.01125"
"473.85000","39.48770","0.00975"
"474.24000","39.52004","0.01090"
"474.63000","39.55263","0.01078"
"475.02000","39.58516","0.01163"
"475.41000","39.61762","0.01115"
"475.80000","39.65009","0.01146"
"476.19000","39.68267","0.01188"
"476.58000","39.71519","0.01253"
"476.97000","39.74760","0.01260"
"477.36000","39.78012","0.01242"
"477.75000","39.81271","0.01287"
"478.14000","39.84512","0.01257"
"478.53000","39.87759","0.01356"
"478.92000","39.91017","0.01353"
"479.31000","39.94270","0.01392"
"479.70000","39.97510","0.01374"
"480.09000","40.00757","0.01409"
"480.48000","40.04015","0.01416"
"480.87000","40.07268","0.01480"
"481.26000","40.10508","0.01460"
"481.65000","40.13761","0.00458"
"482.04000","40.17020","0.00587"
"482.43000","40.20260","0.00264"
"482.82000","40.23507","0.00210"
"483.21000","40.26765","0.00265"
"483.60000","40.30017","0.00238"
"483.99000","40.33258","0.00242"
"484.38000","40.36505","0.00307"
"484.77000","40.39764","0.00233"
"485.16000","40.43016","0.00243"
"485.55000","40.46257","0.00251"
"485.94000","40.49516","0.00233"
"486.33000","40.52768","0.00263"
"486.72000","40.56009","0.00273"
"487.11000","40.59261","0.00256"
"487.50000","40.62519","0.00279"
"487.89000","40.65766","0.00251"
"488.28000","40.69012","0.00287"
"488.67000","40.72265","0.00255"
"489.06000","40.75518","0.00318"
"489.45000","40.78764","0.00286"
"489.84000","40.82011","0.00256"
"490.23000","40.85263","0.00318"
"490.62000","40.88516","0.00304"
"491.01000","40.91763","0.00297"
"491.40000","40.95015","0.00310"
"491.79000","40.98267","0.00250"
"492.18000","41.01508","0.00246"
"492.57000","41.04760","0.00311"
"492.96000","41.08013","0.00227"
"493.35000","41.11266","0.00279"
"493.74000","41.14512","0.00219"
"494.13000","41.17759","0.00246"
"494.52000","41.21017","0.00214"
"494.91000","41.24264","0.00254"
"495.30000","41.27510","0.00285"
"495.69000","41.30763","0.00245"
"496.08000","41.34016","0.00268"
"496.47000","41.37268","0.00292"
"496.86000","41.40509","0.00256"
"497.25000","41.43768","0.00257"
"497.64000","41.47014","0.00224"
"498.03000","41.50266","0.00307"
"498.42000","41.53513","0.00273"
"498.81000","41.56765","0.00293"
"499.20000","41.60018","0.00270"
"499.59000","41.63265","0.00229"
"499.98000","41.66505","0.00266"
"500.37000","41.69764","0.00241"
"500.76000","41.73011","0.00258"
"501.15000","41.76257","0.00243"
"501.54000","41.79515","0.00273"
"501.93000","41.82762","0.00298"
"502.32000","41.86015","0.00318"
"502.71000","41.89261","0.00285"
"503.10000","41.92514","0.00262"
"503.49000","41.95766","0.00310"
"503.88000","41.99013","0.00304"
"504.27000","42.02266","0.00284"
"504.66000","42.05512","0.00314"
"505.05000","42.08764","0.00295"
"505.44000","42.12011","0.00274"
"505.83000","42.15264","0.00296"
"506.22000","42.18510","0.00307"
"506.61000","42.21763","0.00327"
"507.00000","42.25016","0.00315"
"507.39000","42.28262","0.00317"
"507.78000","42.31515","0.00293"
"508.17000","42.34761","0.00305"
"508.56000","42.38013","0.00295"
"508.95000","42.41266","0.00329"
"509.34000","42.44512","0.00297"
"509.73000","42.47765","0.00307"
"510.12000","42.51018","0.00319"
"510.51000","42.54264","0.00337"
"510.90000","42.57511","0.00319"
"511.29000","42.60764","0.00327"
"511.68000","42.64016","0.00343"
"512.07000","42.67268","0.00305"
"512.46000","42.70515","0.00336"
"512.85000","42.73756","0.00337"
"513.24000","42.77014","0.00331"
"513.63000","42.80267","0.00316"
"514.02000","42.83514","0.00388"
"514.41000","42.86766","0.00319"
"514.80000","42.90013","0.00317"
"515.19000","42.93265","0.00349"
"515.58000","42.96512","0.00340"
"515.97000","42.99764","0.00341"
"516.36000","43.03017","0.00361"
"516.75000","43.06263","0.00352"
"517.14000","43.09510","0.00326"
"517.53000","43.12762","0.00342"
"517.92000","43.16009","0.00343"
"518.31000","43.19262","0.00365"
"518.70000","43.22514","0.00332"
"519.09000","43.25766","0.00391"
"519.48000","43.29013","0.00398"
"519.87000","43.32260","0.00393"
"520.26000","43.35512","0.00332"
"520.65000","43.38765","0.00382"
"521.04000","43.42012","0.00361"
"521.43000","43.45264","0.00335"
"521.82000","43.48517","0.00383"
"522.21000","43.51757","0.00375"
"522.60000","43.55016","0.00365"
"522.99000","43.58268","0.00403"
"523.38000","43.61521","0.00363"
"523.77000","43.64762","0.00310"
"524.16000","43.68014","0.00356"
"524.55000","43.71267","0.00397"
"524.94000","43.74519","0.00328"
"525.33000","43.77760","0.00390"
"525.72000","43.81013","0.00380"
"526.11000","43.84265","0.00383"
"526.50000","43.87511","0.00379"
"526.89000","43.90758","0.00387"
"527.28000","43.94017","0.00357"
"527.67000","43.97269","0.00332"
"528.06000","44.00503","0.00364"
"528.45000","44.03762","0.00397"
"528.84000","44.07015","0.00349"
"529.23000","44.10267","0.00411"
"529.62000","44.13514","0.00385"
"530.01000","44.16760","0.00415"
"530.40000","44.20019","0.00435"
"530.79000","44.23259","0.00380"
"531.18000","44.26512","0.00406"
"531.57000","44.29765","0.00414"
"531.96000","44.33017","0.00368"
"532.35000","44.36251","0.00345"
"532.74000","44.39510","0.00359"
"533.13000","44.42768","0.00321"
"533.52000","44.46009","0.00377"
"533.91000","44.49268","0.00390"
"534.30000","44.52515","0.00364"
"534.69000","44.55767","0.00379"
"535.08000","44.59008","0.00377"
"535.47000","44.62260","0.00379"
"535.86000","44.65519","0.00379"
"536.25000","44.68766","0.00374"
"536.64000","44.72006","0.00396"
"537.03000","44.75264","0.00424"
"537.42000","44.78517","0.00369"
"537.81000","44.81763","0.00388"
"538.20000","44.85011","0.00392"
"538.59000","44.88263","0.00365"
"538.98000","44.91515","0.00407"
"539.37000","44.94756","0.00384"
"539.76000","44.98014","0.00400"
"540.15000","45.01267","0.00432"
"540.54000","45.04508","0.00423"
"540.93000","45.07760","0.00457"
"541.32000","45.11013","0.00416"
"541.71000","45.14265","0.00423"
"542.10000","45.17512","0.00399"
"542.49000","45.20765","0.00387"
"542.88000","45.24011","0.00372"
"543.27000","45.27264","0.00381"
"543.66000","45.30510","0.00392"
"544.05000","45.33762","0.00434"
"544.44000","45.37016","0.00370"
"544.83000","45.40261","0.00416"
"545.22000","45.43508","0.00442"
"545.61000","45.46767","0.00431"
"546.00000","45.50013","0.00444"
"546.39000","45.53260","0.00394"
"546.78000","45.56512","0.00400"
"547.17000","45.59771","0.00353"
"547.56000","45.63012","0.00389"
"547.95000","45.66258","0.00395"
"548.34000","45.69516","0.00309"
"548.73000","45.72763","0.00274"
"549.12000","45.76016","0.00287"
"549.51000","45.79263","0.00182"
"549.90000","45.82515","0.00228"
"550.29000","45.85767","0.00220"
"550.68000","45.89014","0.00238"
"551.07000","45.92261","0.00230"
"551.46000","45.95513","0.00246"
"551.85000","45.98759","0.00183"
"552.24000","46.02012","0.00226"
"552.63000","46.05271","0.00194"
"553.02000","46.08512","0.00202"
"553.41000","46.11758","0.00224"
"553.80000","46.15011","0.00238"
"554.19000","46.18263","0.00223"
"554.58000","46.21515","0.00234"
"554.97000","46.24756","0.00224"
"555.36000","46.28021","0.00207"
"555.75000","46.31268","0.00196"
"556.14000","46.34508","0.00196"
"556.53000","46.37761","0.00225"
"556.92000","46.41013","0.00239"
"557.31000","46.44260","0.00223"
"557.70000","46.47512","0.00217"
"558.09000","46.50759","0.00201"
"558.48000","46.54017","0.00162"
"558.87000","46.57264","0.00208"
"559.26000","46.60510","0.00212"
"559.65000","46.63763","0.00204"
"560.04000","46.67010","0.00227"
"560.43000","46.70262","0.00188"
"560.82000","46.73515","0.00189"
"561.21000","46.76767","0.00224"
"561.60000","46.80014","0.00203"
"561.99000","46.83260","0.00229"
"562.38000","46.86513","0.00204"
"562.77000","46.89766","0.00196"
"563.16000","46.93018","0.00238"
"563.55000","46.96259","0.00183"
"563.94000","46.99511","0.00208"
"564.33000","47.02764","0.00181"
"564.72000","47.06016","0.00185"
"565.11000","47.09262","0.00180"
"565.50000","47.12515","0.00198"
"565.89000","47.15768","0.00193"
"566.28000","47.19008","0.00182"
"566.67000","47.22261","0.00153"
"567.06000","47.25513","0.00223"
"567.45000","47.28766","0.00210"
"567.84000","47.32013","0.00239"
"568.23000","47.35259","0.00145"
"568.62000","47.38512","0.00188"
"569.01000","47.41764","0.00212"
"569.40000","47.45011","0.00206"
"569.79000","47.48263","0.00182"
"570.18000","47.51516","0.00187"
"570.57000","47.54763","0.00196"
"570.96000","47.58009","0.00217"
"571.35000","47.61267","0.00199"
"571.74000","47.64514","0.00218"
"572.13000","47.67760","0.00201"
"572.52000","47.71013","0.00211"
"572.91000","47.74266","0.00213"
"573.30000","47.77513","0.00220"
"573.69000","47.80759","0.00219"
"574.08000","47.84018","0.00194"
"574.47000","47.87264","0.00155"
"574.86000","47.90511","0.00187"
"575.25000","47.93763","0.00184"
"575.64000","47.97016","0.00194"
"576.03000","48.00268","0.00195"
"576.21200","48.01788","0.00170"