File: Force_trajectories/161223/Specimen_RawData_5.csv
End date,"12/23/2016"
Specimen label,"22CG_76"
Maximum Load,"0.01683",N

Time,Extension,Load
(s),(mm),(N)
"0.00000","0.00000","-0.00026"
"0.31800","0.02619","-0.00033"
"0.63600","0.05321","0.00096"
"0.95400","0.07976","0.00105"
"1.27200","0.10625","0.00147"
"1.59000","0.13267","0.00201"
"1.90800","0.15922","0.00216"
"2.22600","0.18577","0.00243"
"2.54400","0.21225","0.00239"
"2.86200","0.23868","0.00247"
"3.18000","0.26517","0.00281"
"3.49800","0.29171","0.00303"
"3.81600","0.31820","0.00319"
"4.13400","0.34475","0.00362"
"4.45200","0.37123","0.00324"
"4.77000","0.39766","0.00369"
"5.08800","0.42427","0.00332"
"5.40600","0.45063","0.00398"
"5.72400","0.47724","0.00412"
"6.04200","0.50367","0.00431"
"6.36000","0.53021","0.00350"
"6.67800","0.55676","0.00403"
"6.99600","0.58319","0.00414"
"7.31400","0.60973","0.00443"
"7.63200","0.63622","0.00462"
"7.95000","0.66271","0.00433"
"8.26800","0.68919","0.00475"
"8.58600","0.71568","0.00443"
"8.90400","0.74223","0.00467"
"9.22200","0.76871","0.00486"
"9.54000","0.79526","0.00481"
"9.85800","0.82169","0.00511"
"10.17600","0.84817","0.00450"
"10.49400","0.87472","0.00497"
"10.81200","0.90115","0.00493"
"11.13000","0.92769","0.00497"
"11.44800","0.95418","0.00542"
"11.76600","0.98067","0.00553"
"12.08400","1.00721","0.00509"
"12.40200","1.03370","0.00525"
"12.72000","1.06019","0.00545"
"13.03800","1.08667","0.00551"
"13.35600","1.11322","0.00562"
"13.67400","1.13971","0.00506"
"13.99200","1.16619","0.00547"
"14.31000","1.19274","0.00585"
"14.62800","1.21917","0.00567"
"14.94600","1.24571","0.00596"
"15.26400","1.27220","0.00550"
"15.58200","1.29863","0.00547"
"15.90000","1.32523","0.00569"
"16.21800","1.35166","0.00606"
"16.53600","1.37821","0.00568"
"16.85400","1.40470","0.00581"
"17.17200","1.43112","0.00577"
"17.49000","1.45773","0.00607"
"17.80800","1.48416","0.00618"
"18.12600","1.51070","0.00626"
"18.44400","1.53725","0.00658"
"18.76200","1.56374","0.00627"
"19.08000","1.59022","0.00657"
"19.39800","1.61665","0.00633"
"19.71600","1.64320","0.00635"
"20.03400","1.66974","0.00636"
"20.35200","1.69617","0.00621"
"20.67000","1.72272","0.00582"
"20.98800","1.74914","0.00637"
"21.30600","1.77575","0.00647"
"21.62400","1.80224","0.00685"
"21.94200","1.82866","0.00632"
"22.26000","1.85521","0.00642"
"22.57800","1.88170","0.00649"
"22.89600","1.90830","0.00652"
"23.21400","1.93467","0.00647"
"23.53200","1.96122","0.00661"
"23.85000","1.98770","0.00674"
"24.16800","2.01413","0.00685"
"24.48600","2.04074","0.00719"
"24.80400","2.06716","0.00701"
"25.12200","2.09371","0.00675"
"25.44000","2.12020","0.00685"
"25.75800","2.14668","0.00695"
"26.07600","2.17323","0.00695"
"26.39400","2.19966","0.00670"
"26.71200","2.22620","0.00650"
"27.03000","2.25275","0.00705"
"27.34800","2.27924","0.00696"
"27.66600","2.30572","0.00708"
"27.98400","2.33215","0.00706"
"28.30200","2.35870","0.00656"
"28.62000","2.38518","0.00708"
"28.93800","2.41167","0.00700"
"29.25600","2.43822","0.00690"
"29.57400","2.46464","0.00699"
"29.89200","2.49119","0.00717"
"30.21000","2.51774","0.00729"
"30.52800","2.54422","0.00708"
"30.84600","2.57071","0.00741"
"31.16400","2.59720","0.00657"
"31.48200","2.62374","0.00723"
"31.80000","2.65023","0.00737"
"32.11800","2.67672","0.00752"
"32.43600","2.70320","0.00748"
"32.75400","2.72969","0.00767"
"33.07200","2.75624","0.00744"
"33.39000","2.78266","0.00778"
"33.70800","2.80921","0.00712"
"34.02600","2.83570","0.00722"
"34.34400","2.86224","0.00727"
"34.66200","2.88879","0.00758"
"34.98000","2.91516","0.00739"
"35.29800","2.94170","0.00732"
"35.61600","2.96819","0.00780"
"35.93400","2.99474","0.00772"
"36.25200","3.02122","0.00723"
"36.57000","3.04771","0.00784"
"36.88800","3.07420","0.00786"
"37.20600","3.10069","0.00765"
"37.52400","3.12729","0.00762"
"37.84200","3.15372","0.00772"
"38.16000","3.18021","0.00746"
"38.47800","3.20669","0.00771"
"38.79600","3.23318","0.00748"
"39.11400","3.25973","0.00793"
"39.43400","3.28639","0.00728"
"39.75200","3.31282","0.00759"
"40.07000","3.33942","0.00756"
"40.38800","3.36585","0.00774"
"40.70600","3.39240","0.00786"
"41.02400","3.41883","0.00758"
"41.34200","3.44537","0.00812"
"41.66000","3.47192","0.00766"
"41.97800","3.49835","0.00810"
"42.29600","3.52489","0.00751"
"42.61400","3.55138","0.00723"
"42.93200","3.57781","0.00750"
"43.25000","3.60441","0.00785"
"43.56800","3.63084","0.00731"
"43.88600","3.65739","0.00790"
"44.20400","3.68387","0.00751"
"44.52200","3.71036","0.00787"
"44.84000","3.73691","0.00777"
"45.15800","3.76333","0.00761"
"45.47600","3.78988","0.00791"
"45.79400","3.81637","0.00807"
"46.11200","3.84291","0.00787"
"46.43000","3.86940","0.00773"
"46.74800","3.89583","0.00794"
"47.06600","3.92237","0.00769"
"47.38400","3.94880","0.00791"
"47.70200","3.97541","0.00795"
"48.02000","4.00189","0.00772"
"48.33800","4.02838","0.00777"
"48.65600","4.05487","0.00787"
"48.97400","4.08135","0.00776"
"49.29200","4.10790","0.00798"
"49.61000","4.13433","0.00818"
"49.92800","4.16081","0.00854"
"50.24600","4.18736","0.00785"
"50.56400","4.21391","0.00817"
"50.88200","4.24045","0.00797"
"51.20000","4.26682","0.00843"
"51.51800","4.29337","0.00808"
"51.83600","4.31985","0.00808"
"52.15400","4.34640","0.00798"
"52.47200","4.37289","0.00829"
"52.79000","4.39937","0.00846"
"53.10800","4.42592","0.00808"
"53.42600","4.45241","0.00809"
"53.74400","4.47889","0.00820"
"54.06200","4.50538","0.00787"
"54.38000","4.53181","0.00803"
"54.69800","4.55835","0.00768"
"55.01600","4.58490","0.00820"
"55.33400","4.61139","0.00794"
"55.65200","4.63793","0.00847"
"55.97000","4.66430","0.00806"
"56.28800","4.69091","0.00811"
"56.60600","4.71739","0.00844"
"56.92400","4.74388","0.00802"
"57.24200","4.77043","0.00836"
"57.56000","4.79685","0.00842"
"57.87800","4.82340","0.00853"
"58.19600","4.84989","0.00831"
"58.51400","4.87637","0.00821"
"58.83200","4.90286","0.00832"
"59.15000","4.92935","0.00812"
"59.46800","4.95589","0.00799"
"59.78600","4.98238","0.00817"
"60.10400","5.00887","0.00813"
"60.42200","5.03535","0.00812"
"60.74000","5.06184","0.00818"
"61.05800","5.08839","0.00836"
"61.37600","5.11488","0.00869"
"61.69400","5.14136","0.00850"
"62.01200","5.16785","0.00853"
"62.33000","5.19440","0.00854"
"62.64800","5.22094","0.00835"
"62.96600","5.24737","0.00847"
"63.28400","5.27391","0.00838"
"63.60200","5.30040","0.00825"
"63.92000","5.32689","0.00864"
"64.23800","5.35338","0.00847"
"64.55600","5.37986","0.00838"
"64.87400","5.40641","0.00870"
"65.19200","5.43284","0.00879"
"65.51000","5.45944","0.00882"
"65.82800","5.48593","0.00824"
"66.14600","5.51236","0.00826"
"66.46400","5.53884","0.00855"
"66.78200","5.56539","0.00840"
"67.10000","5.59194","0.00863"
"67.41800","5.61836","0.00846"
"67.73600","5.64485","0.00854"
"68.05400","5.67140","0.00841"
"68.37200","5.69782","0.00865"
"68.69000","5.72443","0.00884"
"69.00800","5.75092","0.00845"
"69.32600","5.77734","0.00808"
"69.64400","5.80389","0.00844"
"69.96200","5.83038","0.00859"
"70.28000","5.85692","0.00825"
"70.59800","5.88335","0.00854"
"70.91600","5.90984","0.00857"
"71.23400","5.93644","0.00840"
"71.55200","5.96287","0.00852"
"71.87000","5.98936","0.00863"
"72.18800","6.01590","0.00827"
"72.50600","6.04239","0.00861"
"72.82400","6.06888","0.00872"
"73.14200","6.09536","0.00884"
"73.46000","6.12185","0.00840"
"73.77800","6.14834","0.00838"
"74.09600","6.17488","0.00842"
"74.41400","6.20143","0.00830"
"74.73200","6.22786","0.00847"
"75.05000","6.25434","0.00874"
"75.36800","6.28077","0.00845"
"75.68600","6.30744","0.00830"
"76.00400","6.33386","0.00846"
"76.32200","6.36035","0.00830"
"76.64000","6.38684","0.00826"
"76.95800","6.41332","0.00836"
"77.27600","6.43993","0.00844"
"77.59400","6.46636","0.00825"
"77.91200","6.49290","0.00861"
"78.23000","6.51939","0.00859"
"78.54800","6.54588","0.00823"
"78.86600","6.57242","0.00807"
"79.18400","6.59885","0.00861"
"79.50200","6.62534","0.00844"
"79.82000","6.65182","0.00841"
"80.13800","6.67831","0.00854"
"80.45600","6.70486","0.00844"
"80.77400","6.73135","0.00820"
"81.09200","6.75789","0.00863"
"81.41000","6.78438","0.00881"
"81.72800","6.81086","0.00836"
"82.04600","6.83741","0.00850"
"82.36400","6.86378","0.00861"
"82.68200","6.89039","0.00846"
"83.00000","6.91687","0.00847"
"83.31800","6.94342","0.00836"
"83.63600","6.96991","0.00815"
"83.95400","6.99633","0.00851"
"84.27200","7.02288","0.00849"
"84.59000","7.04943","0.00844"
"84.90800","7.07591","0.00893"
"85.22600","7.10240","0.00850"
"85.54400","7.12889","0.00863"
"85.86200","7.15537","0.00814"
"86.18000","7.18186","0.00842"
"86.49800","7.20841","0.00841"
"86.81600","7.23489","0.00857"
"87.13400","7.26132","0.00876"
"87.45200","7.28793","0.00862"
"87.77000","7.31435","0.00857"
"88.08800","7.34084","0.00852"
"88.40600","7.36739","0.00877"
"88.72400","7.39387","0.00862"
"89.04200","7.42036","0.00811"
"89.36000","7.44685","0.00834"
"89.67800","7.47339","0.00873"
"89.99600","7.49988","0.00839"
"90.31400","7.52637","0.00865"
"90.63200","7.55291","0.00852"
"90.95000","7.57928","0.00861"
"91.26800","7.60589","0.00840"
"91.58600","7.63237","0.00871"
"91.90400","7.65892","0.00850"
"92.22200","7.68541","0.00847"
"92.54000","7.71177","0.00829"
"92.85800","7.73844","0.00865"
"93.17600","7.76481","0.00845"
"93.49400","7.79135","0.00844"
"93.81200","7.81784","0.00837"
"94.13000","7.84433","0.00835"
"94.44800","7.87087","0.00843"
"94.76600","7.89736","0.00856"
"95.08400","7.92391","0.00871"
"95.40200","7.95033","0.00893"
"95.72000","7.97688","0.00844"
"96.03800","8.00337","0.00924"
"96.35600","8.02985","0.00877"
"96.67400","8.05640","0.00867"
"96.99200","8.08289","0.00920"
"97.31000","8.10931","0.00865"
"97.62800","8.13586","0.00878"
"97.94600","8.16235","0.00863"
"98.26400","8.18889","0.00906"
"98.58200","8.21538","0.00931"
"98.90000","8.24187","0.00891"
"99.21800","8.26841","0.00849"
"99.53600","8.29484","0.00895"
"99.85400","8.32139","0.00879"
"100.17200","8.34781","0.00875"
"100.49000","8.37442","0.00897"
"100.80800","8.40085","0.00880"
"101.12600","8.42733","0.00898"
"101.44400","8.45388","0.00854"
"101.76200","8.48031","0.00849"
"102.08000","8.50691","0.00886"
"102.39800","8.53340","0.00866"
"102.71600","8.55989","0.00881"
"103.03400","8.58631","0.00883"
"103.35200","8.61280","0.00848"
"103.67000","8.63941","0.00896"
"103.98800","8.66590","0.00874"
"104.30600","8.69238","0.00872"
"104.62400","8.71893","0.00897"
"104.94200","8.74536","0.00865"
"105.26000","8.77190","0.00795"
"105.57800","8.79833","0.00892"
"105.89600","8.82481","0.00900"
"106.21400","8.85136","0.00870"
"106.53200","8.87785","0.00876"
"106.85000","8.90434","0.00901"
"107.16800","8.93082","0.00857"
"107.48600","8.95737","0.00895"
"107.80400","8.98386","0.00933"
"108.12200","9.01034","0.00892"
"108.44000","9.03689","0.00871"
"108.75800","9.06332","0.00860"
"109.07600","9.08986","0.00877"
"109.39400","9.11641","0.00863"
"109.71200","9.14284","0.00894"
"110.03000","9.16938","0.00884"
"110.34800","9.19581","0.00878"
"110.66600","9.22236","0.00886"
"110.98400","9.24890","0.00898"
"111.30200","9.27539","0.00897"
"111.62000","9.30188","0.00906"
"111.93800","9.32830","0.00901"
"112.25600","9.35491","0.00908"
"112.57400","9.38140","0.00895"
"112.89200","9.40788","0.00905"
"113.21000","9.43437","0.00901"
"113.52800","9.46080","0.00904"
"113.84600","9.48734","0.00894"
"114.16400","9.51377","0.00894"
"114.48200","9.54032","0.00872"
"114.80000","9.56686","0.00898"
"115.11800","9.59329","0.00920"
"115.43600","9.61996","0.00837"
"115.75400","9.64638","0.00873"
"116.07200","9.67287","0.00909"
"116.39000","9.69942","0.00918"
"116.70800","9.72584","0.00914"
"117.02600","9.75245","0.00889"
"117.34400","9.77888","0.00957"
"117.66200","9.80542","0.00870"
"117.98000","9.83185","0.00901"
"118.29800","9.85834","0.00938"
"118.61600","9.88488","0.00906"
"118.93400","9.91131","0.00918"
"119.25200","9.93792","0.00908"
"119.57000","9.96434","0.00886"
"119.88800","9.99089","0.00963"
"120.20600","10.01738","0.00912"
"120.52400","10.04380","0.00903"
"120.84200","10.07035","0.00890"
"121.16000","10.09684","0.00898"
"121.47800","10.12332","0.00919"
"121.79600","10.14993","0.00937"
"122.11400","10.17636","0.00936"
"122.43200","10.20284","0.00956"
"122.75000","10.22933","0.00940"
"123.06800","10.25588","0.00917"
"123.38600","10.28236","0.00977"
"123.70400","10.30885","0.00915"
"124.02200","10.33534","0.00911"
"124.34000","10.36189","0.00949"
"124.65800","10.38837","0.00934"
"124.97600","10.41486","0.00985"
"125.29400","10.44140","0.00947"
"125.61200","10.46795","0.00925"
"125.93000","10.49432","0.00941"
"126.24800","10.52086","0.00980"
"126.56600","10.54735","0.00965"
"126.88400","10.57384","0.00960"
"127.20200","10.60038","0.00963"
"127.52000","10.62681","0.00927"
"127.83800","10.65342","0.00954"
"128.15600","10.67984","0.00960"
"128.47400","10.70639","0.00943"
"128.79200","10.73288","0.00944"
"129.11000","10.75931","0.00958"
"129.42800","10.78585","0.00921"
"129.74600","10.81234","0.00918"
"130.06400","10.83895","0.00930"
"130.38200","10.86537","0.00969"
"130.70000","10.89180","0.00944"
"131.01800","10.91835","0.00949"
"131.33600","10.94477","0.00934"
"131.65400","10.97138","0.00963"
"131.97200","10.99787","0.00934"
"132.29000","11.02435","0.00939"
"132.60800","11.05084","0.00972"
"132.92600","11.07733","0.00957"
"133.24400","11.10387","0.00949"
"133.56200","11.13036","0.00920"
"133.88000","11.15685","0.00923"
"134.19800","11.18339","0.00960"
"134.51600","11.20988","0.00958"
"134.83400","11.23643","0.00964"
"135.15200","11.26285","0.00934"
"135.47000","11.28934","0.00948"
"135.78800","11.31589","0.00984"
"136.10600","11.34237","0.00961"
"136.42400","11.36892","0.00969"
"136.74200","11.39535","0.00929"
"137.06000","11.42189","0.00961"
"137.37800","11.44838","0.00965"
"137.69600","11.47487","0.00941"
"138.01400","11.50135","0.00935"
"138.33200","11.52784","0.00958"
"138.65000","11.55439","0.00905"
"138.96800","11.58087","0.00948"
"139.28600","11.60736","0.00979"
"139.60400","11.63391","0.00943"
"139.92200","11.66028","0.00967"
"140.24000","11.68688","0.00974"
"140.55800","11.71337","0.00954"
"140.87600","11.73985","0.00999"
"141.19400","11.76640","0.00962"
"141.51200","11.79277","0.00991"
"141.83000","11.81937","0.00993"
"142.14800","11.84586","0.01038"
"142.46600","11.87241","0.00982"
"142.78400","11.89889","0.00940"
"143.10200","11.92532","0.01010"
"143.42000","11.95193","0.01004"
"143.73800","11.97835","0.00962"
"144.05600","12.00484","0.00998"
"144.37400","12.03133","0.00970"
"144.69200","12.05788","0.00914"
"145.01000","12.08442","0.00947"
"145.32800","12.11085","0.00965"
"145.64600","12.13739","0.00928"
"145.96400","12.16382","0.00936"
"146.28200","12.19037","0.00947"
"146.60000","12.21686","0.00903"
"146.91800","12.24328","0.00933"
"147.23600","12.26989","0.00890"
"147.55400","12.29632","0.00943"
"147.87200","12.32292","0.00916"
"148.19000","12.34941","0.00925"
"148.50800","12.37584","0.00914"
"148.82600","12.40238","0.00919"
"149.14400","12.42893","0.00921"
"149.46200","12.45541","0.00921"
"149.78000","12.48190","0.00961"
"150.09800","12.50833","0.00953"
"150.41600","12.53488","0.00953"
"150.73400","12.56136","0.01041"
"151.05200","12.58791","0.01055"
"151.37000","12.61440","0.01079"
"151.68800","12.64082","0.01028"
"152.00600","12.66737","0.01049"
"152.32400","12.69386","0.01022"
"152.64200","12.72040","0.00910"
"152.96000","12.74683","0.00970"
"153.27800","12.77332","0.00924"
"153.59600","12.79992","0.00924"
"153.91400","12.82635","0.00952"
"154.23200","12.85296","0.00973"
"154.55000","12.87932","0.00954"
"154.86800","12.90581","0.00964"
"155.18600","12.93242","0.00967"
"155.50400","12.95884","0.00975"
"155.82200","12.98539","0.00937"
"156.14000","13.01182","0.00933"
"156.45800","13.03836","0.00912"
"156.77600","13.06491","0.00947"
"157.09400","13.09134","0.00949"
"157.41200","13.11788","0.00941"
"157.73000","13.14437","0.00959"
"158.04800","13.17086","0.00946"
"158.36600","13.19740","0.00916"
"158.68400","13.22383","0.00926"
"159.00200","13.25032","0.00968"
"159.32000","13.27680","0.00952"
"159.63800","13.30341","0.00929"
"159.95600","13.32990","0.00939"
"160.27400","13.35632","0.00952"
"160.59200","13.38287","0.00949"
"160.91000","13.40936","0.00973"
"161.22800","13.43590","0.00973"
"161.54600","13.46233","0.00959"
"161.86400","13.48888","0.00965"
"162.18200","13.51542","0.00946"
"162.50000","13.54185","0.00956"
"162.81800","13.56846","0.00968"
"163.13600","13.59488","0.00943"
"163.45400","13.62131","0.00942"
"163.77200","13.64792","0.00901"
"164.09000","13.67434","0.00965"
"164.40800","13.70089","0.00935"
"164.72600","13.72732","0.00953"
"165.04400","13.75387","0.00991"
"165.36200","13.78041","0.00977"
"165.68000","13.80684","0.00964"
"165.99800","13.83338","0.00960"
"166.31600","13.85981","0.00935"
"166.63400","13.88642","0.00960"
"166.95200","13.91291","0.00961"
"167.27000","13.93939","0.00948"
"167.58800","13.96588","0.00962"
"167.90600","13.99231","0.00950"
"168.22400","14.01891","0.00960"
"168.54200","14.04540","0.00929"
"168.86000","14.07188","0.00960"
"169.17800","14.09843","0.00952"
"169.49600","14.12480","0.00947"
"169.81400","14.15140","0.00931"
"170.13200","14.17783","0.00909"
"170.45000","14.20438","0.00905"
"170.76800","14.23087","0.00951"
"171.08600","14.25735","0.00946"
"171.40400","14.28396","0.00954"
"171.72200","14.31039","0.00942"
"172.04000","14.33687","0.00997"
"172.35800","14.36336","0.00970"
"172.67600","14.38985","0.00945"
"172.99400","14.41639","0.00937"
"173.31200","14.44282","0.00970"
"173.63000","14.46937","0.00978"
"173.94800","14.49585","0.00975"
"174.26600","14.52234","0.00933"
"174.58400","14.54889","0.00973"
"174.90200","14.57537","0.01022"
"175.22000","14.60186","0.00988"
"175.53800","14.62841","0.00944"
"175.85600","14.65489","0.00986"
"176.17400","14.68138","0.00974"
"176.49200","14.70781","0.00985"
"176.81000","14.73441","0.00986"
"177.12800","14.76090","0.00972"
"177.44600","14.78739","0.00966"
"177.76400","14.81393","0.00973"
"178.08200","14.84036","0.01006"
"178.40000","14.86691","0.00968"
"178.71800","14.89333","0.00966"
"179.03600","14.91988","0.00957"
"179.35400","14.94637","0.00967"
"179.67200","14.97285","0.00955"
"179.99000","14.99940","0.00966"
"180.30800","15.02589","0.00987"
"180.62600","15.05237","0.00995"
"180.94400","15.07886","0.01005"
"181.26200","15.10535","0.00975"
"181.58000","15.13195","0.00973"
"181.89800","15.15832","0.00997"
"182.21600","15.18493","0.01012"
"182.53400","15.21136","0.01019"
"182.85200","15.23784","0.01015"
"183.17000","15.26445","0.01042"
"183.48800","15.29082","0.01036"
"183.80600","15.31736","0.00971"
"184.12400","15.34385","0.01005"
"184.44200","15.37039","0.01015"
"184.76000","15.39694","0.00952"
"185.07800","15.42331","0.01006"
"185.39600","15.44985","0.00956"
"185.71400","15.47634","0.01001"
"186.03200","15.50289","0.00974"
"186.35000","15.52938","0.00988"
"186.66800","15.55586","0.00949"
"186.98600","15.58235","0.00954"
"187.30400","15.60884","0.00968"
"187.62200","15.63544","0.00970"
"187.94000","15.66187","0.00967"
"188.25800","15.68835","0.00946"
"188.57600","15.71484","0.00979"
"188.89400","15.74133","0.00956"
"189.21200","15.76787","0.00944"
"189.53000","15.79436","0.00977"
"189.84800","15.82091","0.00989"
"190.16600","15.84733","0.00992"
"190.48400","15.87382","0.00970"
"190.80200","15.90043","0.00972"
"191.12000","15.92686","0.00971"
"191.43800","15.95334","0.00978"
"191.75600","15.97989","0.00982"
"192.07400","16.00637","0.00983"
"192.39200","16.03292","0.00976"
"192.71000","16.05935","0.00939"
"193.02800","16.08590","0.00971"
"193.34600","16.11238","0.00984"
"193.66400","16.13881","0.00990"
"193.98200","16.16541","0.00991"
"194.30000","16.19184","0.00976"
"194.61800","16.21839","0.00971"
"194.93600","16.24487","0.00964"
"195.25400","16.27136","0.00954"
"195.57200","16.29785","0.00965"
"195.89000","16.32428","0.01003"
"196.20800","16.35094","0.00943"
"196.52600","16.37737","0.00970"
"196.84400","16.40386","0.00928"
"197.16200","16.43040","0.01006"
"197.48000","16.45683","0.00987"
"197.79800","16.48338","0.00981"
"198.11600","16.50986","0.00987"
"198.43400","16.53635","0.00982"
"198.75200","16.56290","0.01003"
"199.07000","16.58938","0.01003"
"199.38800","16.61587","0.01037"
"199.70600","16.64236","0.00964"
"200.02400","16.66878","0.00981"
"200.34200","16.69533","0.00982"
"200.66000","16.72188","0.01008"
"200.97800","16.74842","0.00995"
"201.29600","16.77485","0.00994"
"201.61400","16.80146","0.00999"
"201.93200","16.82788","0.00981"
"202.25000","16.85437","0.00985"
"202.56800","16.88092","0.00980"
"202.88600","16.90734","0.00923"
"203.20400","16.93389","0.00983"
"203.52200","16.96038","0.00991"
"203.84000","16.98692","0.00989"
"204.15800","17.01335","0.00983"
"204.47600","17.03984","0.01012"
"204.79400","17.06638","0.00985"
"205.11200","17.09287","0.00999"
"205.43000","17.11942","0.00950"
"205.74800","17.14590","0.00988"
"206.06600","17.17227","0.00990"
"206.38400","17.19888","0.00955"
"206.70200","17.22531","0.00997"
"207.02000","17.25191","0.00989"
"207.33800","17.27840","0.00982"
"207.65600","17.30482","0.01006"
"207.97400","17.33137","0.00996"
"208.29200","17.35792","0.00990"
"208.61000","17.38434","0.01010"
"208.92800","17.41083","0.01009"
"209.24600","17.43732","0.01026"
"209.56400","17.46387","0.00997"
"209.88200","17.49035","0.00999"
"210.20000","17.51690","0.00995"
"210.51800","17.54338","0.01009"
"210.83600","17.56981","0.00988"
"211.15400","17.59642","0.00988"
"211.47200","17.62284","0.01009"
"211.79000","17.64939","0.01012"
"212.10800","17.67582","0.01003"
"212.42600","17.70237","0.01010"
"212.74400","17.72891","0.01029"
"213.06200","17.75534","0.01014"
"213.38000","17.78189","0.01028"
"213.69800","17.80831","0.01047"
"214.01600","17.83492","0.01047"
"214.33400","17.86135","0.01008"
"214.65200","17.88783","0.00993"
"214.97000","17.91438","0.01020"
"215.28800","17.94081","0.01011"
"215.60600","17.96741","0.01067"
"215.92400","17.99390","0.01017"
"216.24200","18.02033","0.01085"
"216.56000","18.04687","0.01030"
"216.87800","18.07336","0.01021"
"217.19600","18.09985","0.01071"
"217.51400","18.12639","0.01041"
"217.83200","18.15282","0.01027"
"218.15000","18.17937","0.01044"
"218.46800","18.20579","0.01022"
"218.78600","18.23240","0.01041"
"219.10400","18.25883","0.01036"
"219.42200","18.28531","0.01031"
"219.74000","18.31192","0.01003"
"220.05800","18.33835","0.01030"
"220.37600","18.36489","0.01014"
"220.69400","18.39126","0.01015"
"221.01200","18.41787","0.01036"
"221.33000","18.44435","0.01034"
"221.64800","18.47078","0.01031"
"221.96600","18.49739","0.01067"
"222.28400","18.52381","0.01130"
"222.60200","18.55042","0.01059"
"222.92000","18.57691","0.01070"
"223.23800","18.60333","0.01023"
"223.55600","18.62982","0.01040"
"223.87400","18.65631","0.01065"
"224.19200","18.68291","0.01030"
"224.51000","18.70934","0.01037"
"224.82800","18.73589","0.01052"
"225.14600","18.76237","0.01063"
"225.46400","18.78886","0.01032"
"225.78200","18.81541","0.01011"
"226.10000","18.84184","0.01041"
"226.41800","18.86832","0.01036"
"226.73600","18.89487","0.01055"
"227.05400","18.92135","0.01060"
"227.37200","18.94790","0.01048"
"227.69000","18.97433","0.01025"
"228.00800","19.00088","0.01036"
"228.32600","19.02736","0.01044"
"228.64400","19.05385","0.01055"
"228.96200","19.08039","0.01073"
"229.28000","19.10682","0.01020"
"229.59800","19.13337","0.01038"
"229.91600","19.15985","0.01039"
"230.23400","19.18634","0.01039"
"230.55200","19.21289","0.01036"
"230.87000","19.23932","0.01043"
"231.18800","19.26586","0.01077"
"231.50600","19.29235","0.01067"
"231.82400","19.31890","0.01026"
"232.14200","19.34538","0.01092"
"232.46000","19.37181","0.01081"
"232.77800","19.39836","0.01088"
"233.09600","19.42490","0.01003"
"233.41400","19.45139","0.01069"
"233.73200","19.47794","0.01044"
"234.05000","19.50436","0.01068"
"234.36800","19.53085","0.01099"
"234.68600","19.55739","0.01101"
"235.00400","19.58388","0.01079"
"235.32200","19.61037","0.01094"
"235.64000","19.63680","0.01065"
"235.95800","19.66340","0.01055"
"236.27600","19.68989","0.01037"
"236.59400","19.71638","0.01073"
"236.91200","19.74286","0.01054"
"237.23000","19.76935","0.01089"
"237.54800","19.79590","0.01077"
"237.86600","19.82226","0.01060"
"238.18400","19.84887","0.01086"
"238.50200","19.87536","0.01067"
"238.82000","19.90184","0.01080"
"239.13800","19.92839","0.01093"
"239.45600","19.95488","0.01093"
"239.77400","19.98136","0.01080"
"240.09200","20.00785","0.01085"
"240.41000","20.03440","0.01094"
"240.72800","20.06088","0.01067"
"241.04600","20.08731","0.01079"
"241.36400","20.11386","0.01063"
"241.68200","20.14028","0.01088"
"242.00000","20.16689","0.01075"
"242.31800","20.19338","0.01086"
"242.63600","20.21986","0.01092"
"242.95400","20.24641","0.01082"
"243.27200","20.27284","0.01097"
"243.59000","20.29939","0.01132"
"243.90800","20.32587","0.01107"
"244.22600","20.35230","0.01116"
"244.54400","20.37885","0.01087"
"244.86200","20.40533","0.01082"
"245.18000","20.43188","0.01105"
"245.49800","20.45836","0.01083"
"245.81600","20.48485","0.01121"
"246.13400","20.51140","0.01115"
"246.45200","20.53782","0.01094"
"246.77000","20.56437","0.01097"
"247.08800","20.59086","0.01098"
"247.40600","20.61734","0.01092"
"247.72400","20.64389","0.01086"
"248.04200","20.67038","0.01078"
"248.36000","20.69687","0.01073"
"248.67800","20.72329","0.01117"
"248.99600","20.74990","0.01060"
"249.31400","20.77633","0.01105"
"249.63200","20.80281","0.01109"
"249.95000","20.82936","0.01138"
"250.26800","20.85584","0.01087"
"250.58600","20.88239","0.01075"
"250.90400","20.90888","0.01123"
"251.22200","20.93537","0.01102"
"251.54000","20.96185","0.01102"
"251.85800","20.98828","0.01123"
"252.17600","21.01489","0.01129"
"252.49400","21.04143","0.01108"
"252.81200","21.06786","0.01125"
"253.13000","21.09440","0.01121"
"253.44800","21.12083","0.01118"
"253.76600","21.14744","0.01117"
"254.08400","21.17386","0.01119"
"254.40200","21.20041","0.01105"
"254.72000","21.22690","0.01138"
"255.03800","21.25332","0.01149"
"255.35600","21.27993","0.01099"
"255.67400","21.30636","0.01126"
"255.99200","21.33285","0.01144"
"256.31000","21.35933","0.01084"
"256.62800","21.38582","0.01123"
"256.94600","21.41243","0.01159"
"257.26400","21.43885","0.01121"
"257.58200","21.46540","0.01094"
"257.90000","21.49189","0.01128"
"258.21800","21.51831","0.01146"
"258.53600","21.54480","0.01107"
"258.85400","21.57135","0.01142"
"259.17200","21.59783","0.01159"
"259.49000","21.62438","0.01164"
"259.80800","21.65087","0.01156"
"260.12600","21.67741","0.01192"
"260.44400","21.70378","0.01157"
"260.76200","21.73038","0.01116"
"261.08000","21.75687","0.01132"
"261.39800","21.78342","0.01123"
"261.71600","21.80991","0.01138"
"262.03400","21.83633","0.01129"
"262.35200","21.86288","0.01171"
"262.67000","21.88937","0.01162"
"262.98800","21.91591","0.01182"
"263.30600","21.94240","0.01136"
"263.62400","21.96883","0.01149"
"263.94200","21.99543","0.01186"
"264.26000","22.02186","0.01179"
"264.57800","22.04841","0.01151"
"264.89600","22.07490","0.01189"
"265.21400","22.10132","0.01155"
"265.53200","22.12793","0.01176"
"265.85000","22.15435","0.01159"
"266.16800","22.18096","0.01178"
"266.48600","22.20739","0.01133"
"266.80400","22.23381","0.01168"
"267.12200","22.26042","0.01154"
"267.44000","22.28685","0.01195"
"267.75800","22.31339","0.01172"
"268.07600","22.33982","0.01151"
"268.39400","22.36643","0.01171"
"268.71200","22.39292","0.01162"
"269.03000","22.41934","0.01189"
"269.34800","22.44583","0.01149"
"269.66600","22.47237","0.01182"
"269.98400","22.49892","0.01207"
"270.30200","22.52541","0.01165"
"270.62000","22.55177","0.01190"
"270.93800","22.57838","0.01168"
"271.25600","22.60481","0.01217"
"271.57400","22.63141","0.01210"
"271.89200","22.65790","0.01212"
"272.21000","22.68433","0.01169"
"272.52800","22.71087","0.01213"
"272.84600","22.73736","0.01258"
"273.16400","22.76391","0.01231"
"273.48200","22.79033","0.01249"
"273.80000","22.81688","0.01234"
"274.11800","22.84337","0.01203"
"274.43600","22.86986","0.01219"
"274.75400","22.89640","0.01249"
"275.07200","22.92283","0.01206"
"275.39000","22.94937","0.01237"
"275.70800","22.97592","0.01265"
"276.02600","23.00235","0.01235"
"276.34400","23.02889","0.01208"
"276.66200","23.05532","0.01246"
"276.98000","23.08187","0.01197"
"277.29800","23.10842","0.01231"
"277.61600","23.13484","0.01193"
"277.93400","23.16139","0.01275"
"278.25200","23.18782","0.01238"
"278.57000","23.21436","0.01231"
"278.88800","23.24091","0.01196"
"279.20600","23.26734","0.01224"
"279.52400","23.29388","0.01255"
"279.84200","23.32031","0.01256"
"280.16000","23.34692","0.01209"
"280.47800","23.37340","0.01237"
"280.79600","23.39983","0.01252"
"281.11400","23.42638","0.01255"
"281.43200","23.45286","0.01256"
"281.75000","23.47941","0.01234"
"282.06800","23.50584","0.01225"
"282.38600","23.53238","0.01272"
"282.70400","23.55887","0.01281"
"283.02200","23.58536","0.01254"
"283.34000","23.61190","0.01250"
"283.65800","23.63833","0.01251"
"283.97600","23.66488","0.01254"
"284.29400","23.69136","0.01248"
"284.61200","23.71785","0.01248"
"284.93000","23.74439","0.01245"
"285.24800","23.77082","0.01273"
"285.56600","23.79737","0.01247"
"285.88400","23.82386","0.01287"
"286.20200","23.85034","0.01288"
"286.52000","23.87689","0.01263"
"286.83800","23.90332","0.01278"
"287.15600","23.92992","0.01255"
"287.47400","23.95641","0.01306"
"287.79200","23.98290","0.01326"
"288.11000","24.00938","0.01275"
"288.42800","24.03581","0.01346"
"288.74600","24.06236","0.01324"
"289.06400","24.08884","0.01319"
"289.38200","24.11539","0.01320"
"289.70000","24.14194","0.01313"
"290.01800","24.16830","0.01279"
"290.33600","24.19491","0.01303"
"290.65400","24.22134","0.01278"
"290.97200","24.24788","0.01324"
"291.29000","24.27437","0.01300"
"291.60800","24.30086","0.01334"
"291.92600","24.32740","0.01312"
"292.24400","24.35383","0.01310"
"292.56200","24.38032","0.01281"
"292.88000","24.40686","0.01345"
"293.19800","24.43335","0.01350"
"293.51600","24.45990","0.01300"
"293.83400","24.48632","0.01314"
"294.15200","24.51287","0.01318"
"294.47000","24.53942","0.01303"
"294.78800","24.56585","0.01361"
"295.10600","24.59239","0.01322"
"295.42400","24.61882","0.01353"
"295.74200","24.64537","0.01346"
"296.06000","24.67185","0.01373"
"296.37800","24.69840","0.01379"
"296.69600","24.72495","0.01383"
"297.01400","24.75131","0.01333"
"297.33200","24.77786","0.01357"
"297.65000","24.80434","0.01372"
"297.96800","24.83089","0.01396"
"298.28600","24.85744","0.01351"
"298.60400","24.88387","0.01384"
"298.92200","24.91035","0.01367"
"299.24000","24.93684","0.01336"
"299.55800","24.96345","0.01361"
"299.87600","24.98987","0.01356"
"300.19400","25.01636","0.01367"
"300.51200","25.04284","0.01331"
"300.83000","25.06939","0.01376"
"301.14800","25.09594","0.01391"
"301.46600","25.12237","0.01403"
"301.78400","25.14885","0.01399"
"302.10200","25.17540","0.01409"
"302.42000","25.20183","0.01390"
"302.73800","25.22837","0.01397"
"303.05600","25.25480","0.01401"
"303.37400","25.28135","0.01407"
"303.69200","25.30789","0.01395"
"304.01000","25.33438","0.01357"
"304.32800","25.36086","0.01384"
"304.64600","25.38735","0.01430"
"304.96400","25.41384","0.01402"
"305.28200","25.44039","0.01396"
"305.60000","25.46681","0.01435"
"305.91800","25.49342","0.01427"
"306.23600","25.51979","0.01435"
"306.55400","25.54639","0.01435"
"306.87200","25.57294","0.01412"
"307.19000","25.59937","0.01369"
"307.50800","25.62591","0.01433"
"307.82600","25.65234","0.01402"
"308.14400","25.67889","0.01403"
"308.46200","25.70538","0.01434"
"308.78000","25.73186","0.01443"
"309.09800","25.75835","0.01415"
"309.41600","25.78477","0.01412"
"309.73400","25.81144","0.01402"
"310.05200","25.83787","0.01405"
"310.37000","25.86436","0.01423"
"310.68800","25.89090","0.01449"
"311.00600","25.91733","0.01412"
"311.32400","25.94387","0.01409"
"311.64200","25.97036","0.01442"
"311.96000","25.99685","0.01393"
"312.27800","26.02340","0.01409"
"312.59600","26.04988","0.01406"
"312.91400","26.07637","0.01407"
"313.23200","26.10286","0.01452"
"313.55000","26.12934","0.01464"
"313.86800","26.15589","0.01427"
"314.18600","26.18237","0.01454"
"314.50400","26.20886","0.01448"
"314.82200","26.23529","0.01488"
"315.14000","26.26190","0.01428"
"315.45800","26.28838","0.01482"
"315.77600","26.31487","0.01407"
"316.09400","26.34142","0.01462"
"316.41200","26.36778","0.01439"
"316.73000","26.39439","0.01462"
"317.04800","26.42093","0.01462"
"317.36600","26.44736","0.01457"
"317.68400","26.47385","0.01424"
"318.00200","26.50028","0.01421"
"318.32000","26.52688","0.01435"
"318.63800","26.55337","0.01493"
"318.95600","26.57992","0.01493"
"319.27400","26.60640","0.01425"
"319.59200","26.63289","0.01433"
"319.91000","26.65944","0.01434"
"320.22800","26.68586","0.01453"
"320.54600","26.71235","0.01389"
"320.86400","26.73884","0.01423"
"321.18200","26.76532","0.01417"
"321.50000","26.79193","0.01424"
"321.81800","26.81836","0.01411"
"322.13600","26.84484","0.01433"
"322.45400","26.87133","0.01450"
"322.77200","26.89782","0.01478"
"323.09000","26.92436","0.01456"
"323.40800","26.95085","0.01460"
"323.72600","26.97740","0.01450"
"324.04400","27.00382","0.01455"
"324.36200","27.03037","0.01435"
"324.68000","27.05692","0.01448"
"324.99800","27.08328","0.01463"
"325.31600","27.10989","0.01449"
"325.63400","27.13638","0.01486"
"325.95200","27.16292","0.01422"
"326.27000","27.18935","0.01484"
"326.58800","27.21590","0.01472"
"326.90600","27.24238","0.01470"
"327.22400","27.26881","0.01468"
"327.54200","27.29542","0.01506"
"327.86000","27.32190","0.01501"
"328.17800","27.34839","0.01498"
"328.49600","27.37488","0.01474"
"328.81400","27.40136","0.01460"
"329.13200","27.42785","0.01506"
"329.45000","27.45434","0.01471"
"329.76800","27.48082","0.01486"
"330.08600","27.50737","0.01470"
"330.40400","27.53380","0.01446"
"330.72200","27.56035","0.01427"
"331.04000","27.58689","0.01393"
"331.35800","27.61338","0.01427"
"331.67600","27.63992","0.01435"
"331.99400","27.66635","0.01465"
"332.31200","27.69296","0.01484"
"332.63000","27.71933","0.01433"
"332.94800","27.74587","0.01448"
"333.26600","27.77242","0.01452"
"333.58400","27.79885","0.01458"
"333.90200","27.82533","0.01475"
"334.22000","27.85182","0.01435"
"334.53800","27.87842","0.01425"
"334.85600","27.90491","0.01432"
"335.17400","27.93134","0.01430"
"335.49200","27.95783","0.01476"
"335.81000","27.98425","0.01404"
"336.12800","28.01092","0.01446"
"336.44600","28.03735","0.01462"
"336.76400","28.06383","0.01462"
"337.08200","28.09038","0.01426"
"337.40000","28.11681","0.01481"
"337.71800","28.14341","0.01451"
"338.03600","28.16984","0.01457"
"338.35400","28.19639","0.01478"
"338.67200","28.22287","0.01444"
"338.99000","28.24936","0.01433"
"339.30800","28.27591","0.01491"
"339.62600","28.30239","0.01451"
"339.94400","28.32882","0.01485"
"340.26200","28.35537","0.01421"
"340.58000","28.38185","0.01380"
"340.89800","28.40846","0.01394"
"341.21600","28.43483","0.01388"
"341.53400","28.46137","0.01369"
"341.85200","28.48786","0.01367"
"342.17000","28.51435","0.01337"
"342.48800","28.54089","0.01360"
"342.80600","28.56732","0.01388"
"343.12400","28.59387","0.01376"
"343.44200","28.62035","0.01394"
"343.76000","28.64684","0.01395"
"344.07800","28.67339","0.01418"
"344.39600","28.69981","0.01368"
"344.71400","28.72636","0.01361"
"345.03200","28.75291","0.01367"
"345.35000","28.77939","0.01425"
"345.66800","28.80588","0.01364"
"345.98600","28.83231","0.01362"
"346.30400","28.85886","0.01335"
"346.62200","28.88540","0.01355"
"346.94000","28.91189","0.01385"
"347.25800","28.93837","0.01307"
"347.57600","28.96486","0.01360"
"347.89400","28.99135","0.01343"
"348.21200","29.01789","0.01345"
"348.53000","29.04438","0.01370"
"348.84800","29.07087","0.01381"
"349.16600","29.09736","0.01367"
"349.48400","29.12390","0.01353"
"349.80200","29.15027","0.01382"
"350.12000","29.17687","0.01416"
"350.43800","29.20330","0.01382"
"350.75600","29.22985","0.01397"
"351.07400","29.25640","0.01376"
"351.39200","29.28282","0.01376"
"351.71000","29.30943","0.01376"
"352.02800","29.33586","0.01352"
"352.34600","29.36240","0.01358"
"352.66400","29.38889","0.01334"
"352.98200","29.41532","0.01398"
"353.30000","29.44186","0.01344"
"353.61800","29.46835","0.01410"
"353.93600","29.49489","0.01363"
"354.25400","29.52138","0.01393"
"354.57200","29.54781","0.01389"
"354.89000","29.57435","0.01425"
"355.20800","29.60084","0.01362"
"355.52600","29.62739","0.01370"
"355.84400","29.65388","0.01362"
"356.16200","29.68030","0.01387"
"356.48000","29.70685","0.01420"
"356.79800","29.73334","0.01426"
"357.11600","29.75988","0.01444"
"357.43400","29.78637","0.01429"
"357.75200","29.81285","0.01400"
"358.07000","29.83940","0.01451"
"358.38800","29.86583","0.01471"
"358.70600","29.89238","0.01415"
"359.02400","29.91887","0.01418"
"359.34200","29.94535","0.01428"
"359.66000","29.97190","0.01431"
"359.97800","29.99838","0.01434"
"360.29600","30.02493","0.01444"
"360.61400","30.05129","0.01437"
"360.93200","30.07790","0.01456"
"361.25000","30.10439","0.01446"
"361.56800","30.13082","0.01458"
"361.88600","30.15736","0.01478"
"362.20400","30.18379","0.01448"
"362.52200","30.21040","0.01513"
"362.84000","30.23689","0.01419"
"363.15800","30.26337","0.01445"
"363.47600","30.28985","0.01441"
"363.79400","30.31628","0.01476"
"364.11200","30.34289","0.01508"
"364.43000","30.36932","0.01518"
"364.74800","30.39586","0.01472"
"365.06600","30.42235","0.01488"
"365.38400","30.44884","0.01486"
"365.70200","30.47538","0.01486"
"366.02000","30.50187","0.01488"
"366.33800","30.52835","0.01467"
"366.65600","30.55490","0.01504"
"366.97400","30.58133","0.01505"
"367.29200","30.60794","0.01509"
"367.61000","30.63430","0.01480"
"367.92800","30.66085","0.01521"
"368.24600","30.68734","0.01525"
"368.56400","30.71388","0.01474"
"368.88200","30.74043","0.01496"
"369.20000","30.76680","0.01510"
"369.51800","30.79334","0.01504"
"369.83600","30.81989","0.01493"
"370.15400","30.84638","0.01541"
"370.47200","30.87292","0.01531"
"370.79000","30.89935","0.01500"
"371.10800","30.92584","0.01485"
"371.42600","30.95238","0.01543"
"371.74400","30.97887","0.01507"
"372.06200","31.00542","0.01509"
"372.38000","31.03185","0.01535"
"372.69800","31.05839","0.01523"
"373.01600","31.08488","0.01580"
"373.33400","31.11131","0.01518"
"373.65200","31.13785","0.01541"
"373.97000","31.16428","0.01537"
"374.28800","31.19089","0.01535"
"374.60600","31.21731","0.01530"
"374.92400","31.24386","0.01552"
"375.24200","31.27040","0.01533"
"375.56000","31.29683","0.01510"
"375.87800","31.32338","0.01562"
"376.19600","31.34986","0.01548"
"376.51400","31.37641","0.01576"
"376.83200","31.40284","0.01578"
"377.15000","31.42933","0.01500"
"377.46800","31.45593","0.01494"
"377.78600","31.48236","0.01486"
"378.10400","31.50890","0.01465"
"378.42200","31.53539","0.01437"
"378.74000","31.56188","0.01435"
"379.05800","31.58848","0.01481"
"379.37600","31.61479","0.01474"
"379.69400","31.64140","0.01508"
"380.01200","31.66788","0.01531"
"380.33000","31.69437","0.01474"
"380.64800","31.72092","0.01472"
"380.96600","31.74734","0.01485"
"381.28400","31.77389","0.01506"
"381.60200","31.80038","0.01508"
"381.92000","31.82693","0.01509"
"382.23800","31.85341","0.01481"
"382.55600","31.87984","0.01519"
"382.87400","31.90639","0.01514"
"383.19200","31.93287","0.01533"
"383.51000","31.95942","0.01552"
"383.82800","31.98590","0.01521"
"384.14600","32.01233","0.01567"
"384.46400","32.03888","0.01532"
"384.78200","32.06536","0.01560"
"385.10000","32.09191","0.01485"
"385.41800","32.11834","0.01540"
"385.73600","32.14482","0.01552"
"386.05400","32.17143","0.01531"
"386.37200","32.19786","0.01606"
"386.69000","32.22441","0.01571"
"387.00800","32.25083","0.01570"
"387.32600","32.27738","0.01559"
"387.64400","32.30387","0.01552"
"387.96200","32.33029","0.01551"
"388.28000","32.35690","0.01561"
"388.59800","32.38333","0.01536"
"388.91600","32.40987","0.01529"
"389.23400","32.43642","0.01564"
"389.55200","32.46284","0.01565"
"389.87000","32.48933","0.01564"
"390.18800","32.51582","0.01513"
"390.50600","32.54243","0.01527"
"390.82400","32.56891","0.01578"
"391.14200","32.59540","0.01555"
"391.46000","32.62189","0.01578"
"391.77800","32.64832","0.01581"
"392.09600","32.67492","0.01562"
"392.41400","32.70141","0.01608"
"392.73200","32.72789","0.01536"
"393.05000","32.75444","0.01558"
"393.36800","32.78081","0.01573"
"393.68600","32.80742","0.01582"
"394.00400","32.83390","0.01590"
"394.32200","32.86033","0.01592"
"394.64000","32.88688","0.01539"
"394.95800","32.91336","0.01589"
"395.27600","32.93991","0.01583"
"395.59400","32.96634","0.01625"
"395.91200","32.99282","0.01605"
"396.23000","33.01937","0.01575"
"396.54800","33.04585","0.01601"
"396.86600","33.07240","0.01582"
"397.18400","33.09883","0.01599"
"397.50200","33.12537","0.01589"
"397.82000","33.15186","0.01634"
"398.13800","33.17835","0.01634"
"398.45600","33.20490","0.01647"
"398.77400","33.23132","0.01659"
"399.09200","33.25787","0.01592"
"399.41000","33.28436","0.01592"
"399.72800","33.31084","0.01639"
"400.04600","33.33739","0.01602"
"400.36400","33.36382","0.01618"
"400.68200","33.39042","0.01677"
"401.00000","33.41691","0.01593"
"401.31800","33.44339","0.01572"
"401.63600","33.46988","0.01574"
"401.95400","33.49631","0.01644"
"402.27200","33.52291","0.01547"
"402.59000","33.54934","0.01619"
"402.90800","33.57589","0.01635"
"403.22600","33.60238","0.01629"
"403.54400","33.62886","0.01617"
"403.86200","33.65541","0.01607"
"404.18000","33.68190","0.01603"
"404.49800","33.70844","0.01612"
"404.81600","33.73487","0.01605"
"405.13400","33.76142","0.01599"
"405.45200","33.78796","0.01607"
"405.77000","33.81433","0.01594"
"406.08800","33.84088","0.01624"
"406.40600","33.86736","0.01516"
"406.72400","33.89385","0.01326"
"407.04200","33.92039","0.01240"
"407.36000","33.94682","0.01215"
"407.67800","33.97343","0.01240"
"407.99600","33.99986","0.01161"
"408.31400","34.02634","0.01247"
"408.63200","34.05289","0.01220"
"408.95000","34.07932","0.01239"
"409.26800","34.10586","0.01249"
"409.58600","34.13235","0.01266"
"409.90400","34.15890","0.01242"
"410.22200","34.18538","0.01239"
"410.54000","34.21187","0.01248"
"410.85800","34.23836","0.01209"
"411.17600","34.26484","0.01275"
"411.49400","34.29139","0.01277"
"411.81200","34.31794","0.01247"
"412.13000","34.34436","0.01198"
"412.44800","34.37085","0.01218"
"412.76600","34.39734","0.01214"
"413.08400","34.42389","0.01192"
"413.40200","34.45037","0.01216"
"413.72000","34.47686","0.01235"
"414.03800","34.50346","0.01187"
"414.35600","34.52989","0.01267"
"414.67400","34.55644","0.01208"
"414.99200","34.58286","0.01233"
"415.31000","34.60929","0.01200"
"415.62800","34.63590","0.01236"
"415.94600","34.66233","0.01188"
"416.26400","34.68893","0.01227"
"416.58200","34.71536","0.01229"
"416.90000","34.74184","0.01259"
"417.21800","34.76845","0.01273"
"417.53600","34.79482","0.01234"
"417.85400","34.82137","0.01216"
"418.17200","34.84779","0.01253"
"418.49000","34.87440","0.01205"
"418.80800","34.90089","0.01252"
"419.12600","34.92737","0.01249"
"419.44400","34.95386","0.01244"
"419.76200","34.98035","0.01271"
"420.08000","35.00689","0.01244"
"420.39800","35.03338","0.01239"
"420.71600","35.05986","0.01272"
"421.03400","35.08635","0.01263"
"421.35200","35.11284","0.01281"
"421.67000","35.13939","0.01268"
"421.98800","35.16587","0.01231"
"422.30600","35.19236","0.01283"
"422.62400","35.21885","0.01245"
"422.94200","35.24533","0.01277"
"423.26000","35.27188","0.01287"
"423.57800","35.29837","0.01276"
"423.89600","35.32485","0.01221"
"424.21400","35.35134","0.01288"
"424.53200","35.37789","0.01246"
"424.85000","35.40437","0.01289"
"425.16800","35.43080","0.01298"
"425.48600","35.45735","0.01242"
"425.80400","35.48389","0.01278"
"426.12200","35.51038","0.01244"
"426.44000","35.53687","0.01250"
"426.75800","35.56329","0.01281"
"427.07600","35.58990","0.01271"
"427.39400","35.61639","0.01265"
"427.71200","35.64287","0.01292"
"428.03000","35.66936","0.01258"
"428.34800","35.69579","0.01266"
"428.66600","35.72245","0.01281"
"428.98400","35.74888","0.01289"
"429.30200","35.77537","0.01297"
"429.62000","35.80185","0.01275"
"429.93800","35.82834","0.01264"
"430.25600","35.85489","0.01304"
"430.57400","35.88137","0.01303"
"430.89200","35.90786","0.01318"
"431.21000","35.93441","0.01317"
"431.52800","35.96090","0.01278"
"431.84600","35.98738","0.01235"
"432.16400","36.01387","0.01234"
"432.48200","36.04036","0.01217"
"432.80000","36.06684","0.01257"
"433.11800","36.09333","0.01220"
"433.43600","36.11987","0.01251"
"433.75400","36.14630","0.01238"
"434.07200","36.17285","0.01238"
"434.39000","36.19939","0.01197"
"434.70800","36.22588","0.01208"
"435.02600","36.25237","0.01238"
"435.34400","36.27885","0.01223"
"435.66200","36.30534","0.01221"
"435.98000","36.33183","0.01225"
"436.29800","36.35844","0.01208"
"436.61600","36.38492","0.01221"
"436.93400","36.41135","0.01242"
"437.25200","36.43790","0.01206"
"437.57000","36.46438","0.01168"
"437.88800","36.49093","0.01198"
"438.20600","36.51736","0.01215"
"438.52400","36.54378","0.01199"
"438.84200","36.57033","0.01178"
"439.16000","36.59682","0.01182"
"439.47800","36.62336","0.01185"
"439.79600","36.64985","0.01229"
"440.11400","36.67633","0.01203"
"440.43200","36.70288","0.01195"
"440.75000","36.72931","0.01225"
"441.06800","36.75586","0.01223"
"441.38600","36.78234","0.01252"
"441.70400","36.80883","0.01238"
"442.02200","36.83538","0.01213"
"442.34000","36.86180","0.01205"
"442.65800","36.88841","0.01197"
"442.97600","36.91490","0.01200"
"443.29400","36.94132","0.01188"
"443.61200","36.96793","0.01221"
"443.93000","36.99430","0.01262"
"444.24800","37.02090","0.01277"
"444.56600","37.04739","0.01229"
"444.88400","37.07388","0.01244"
"445.20200","37.10042","0.01234"
"445.52000","37.12685","0.01245"
"445.83800","37.15334","0.01243"
"446.15600","37.17982","0.01266"
"446.47400","37.20643","0.01270"
"446.79200","37.23286","0.01228"
"447.11000","37.25934","0.01227"
"447.42800","37.28583","0.01228"
"447.74600","37.31232","0.01228"
"448.06400","37.33886","0.01270"
"448.38200","37.36535","0.01260"
"448.70000","37.39184","0.01255"
"449.01800","37.41838","0.01285"
"449.33600","37.44487","0.01243"
"449.65400","37.47142","0.01274"
"449.97200","37.49784","0.01305"
"450.29000","37.52433","0.01284"
"450.60800","37.55082","0.01248"
"450.92600","37.57737","0.01248"
"451.24400","37.60385","0.01244"
"451.56200","37.63034","0.01267"
"451.88000","37.65688","0.01281"
"452.19800","37.68337","0.01267"
"452.51600","37.70979","0.01248"
"452.83400","37.73634","0.01263"
"453.15200","37.76277","0.01293"
"453.47000","37.78938","0.01291"
"453.78800","37.81586","0.01305"
"454.10600","37.84235","0.01279"
"454.42400","37.86890","0.01289"
"454.74200","37.89526","0.01276"
"455.06000","37.92187","0.01298"
"455.37800","37.94836","0.01279"
"455.69600","37.97491","0.01318"
"456.01400","38.00133","0.01284"
"456.33200","38.02776","0.01337"
"456.65000","38.05437","0.01313"
"456.96800","38.08091","0.01291"
"457.28600","38.10740","0.01281"
"457.60400","38.13395","0.01295"
"457.92200","38.16037","0.01247"
"458.24000","38.18686","0.01253"
"458.55800","38.21334","0.01271"
"458.87600","38.23983","0.01304"
"459.19400","38.26638","0.01260"
"459.51200","38.29280","0.01285"
"459.83000","38.31935","0.01299"
"460.14800","38.34590","0.01300"
"460.46600","38.37239","0.01289"
"460.78400","38.39887","0.01293"
"461.10200","38.42536","0.01328"
"461.42000","38.45191","0.01257"
"461.73800","38.47833","0.01325"
"462.05600","38.50488","0.01331"
"462.37400","38.53137","0.01284"
"462.69200","38.55791","0.01315"
"463.01000","38.58440","0.01300"
"463.32800","38.61082","0.01352"
"463.64600","38.63737","0.01367"
"463.96400","38.66386","0.01303"
"464.28200","38.69041","0.01302"
"464.60000","38.71683","0.01320"
"464.91800","38.74332","0.01379"
"465.23600","38.76993","0.01312"
"465.55400","38.79635","0.01296"
"465.87200","38.82290","0.01316"
"466.19000","38.84945","0.01316"
"466.50800","38.87581","0.01312"
"466.82600","38.90236","0.01344"
"467.14400","38.92891","0.01300"
"467.46200","38.95533","0.01336"
"467.78000","38.98188","0.01302"
"468.09800","39.00830","0.01307"
"468.41600","39.03492","0.01353"
"468.73400","39.06134","0.01297"
"469.05200","39.08788","0.01293"
"469.37000","39.11437","0.01235"
"469.68800","39.14086","0.01264"
"470.00600","39.16740","0.01219"
"470.32400","39.19383","0.01288"
"470.64200","39.22038","0.01231"
"470.96000","39.24686","0.01238"
"471.27800","39.27329","0.01287"
"471.59600","39.29990","0.01315"
"471.91400","39.32632","0.01247"
"472.23200","39.35293","0.01274"
"472.55000","39.37936","0.01247"
"472.86800","39.40590","0.01295"
"473.18600","39.43233","0.01247"
"473.50400","39.45882","0.01282"
"473.82200","39.48536","0.01241"
"474.14000","39.51179","0.01279"
"474.45800","39.53840","0.01297"
"474.77600","39.56488","0.01251"
"474.97800","39.58169","0.01278"