File: Force_trajectories/161223/Specimen_RawData_2.csv
End date,"12/23/2016"
Specimen label,"22DT_77"
Maximum Load,"0.02078",N

Time,Extension,Load
(s),(mm),(N)
"0.00000","0.00000","-0.00038"
"0.42600","0.03575","0.00020"
"0.85200","0.07121","-0.00041"
"1.27800","0.10666","-0.00005"
"1.70400","0.14218","-0.00050"
"2.13000","0.17769","-0.00032"
"2.55600","0.21321","-0.00034"
"2.98200","0.24860","-0.00007"
"3.40800","0.28418","-0.00037"
"3.83400","0.31969","-0.00010"
"4.26000","0.35521","-0.00034"
"4.68600","0.39066","-0.00038"
"5.11200","0.42618","-0.00041"
"5.53800","0.46163","-0.00055"
"5.96400","0.49721","0.00013"
"6.39000","0.53272","-0.00021"
"6.81600","0.56818","-0.00033"
"7.24200","0.60369","-0.00021"
"7.66800","0.63927","-0.00017"
"8.09400","0.67472","-0.00036"
"8.52000","0.71024","-0.00021"
"8.94600","0.74570","-0.00005"
"9.37200","0.78121","-0.00020"
"9.79800","0.81673","-0.00052"
"10.22400","0.85218","-0.00056"
"10.65000","0.88776","-0.00036"
"11.07600","0.92321","-0.00039"
"11.50200","0.95867","-0.00026"
"11.92800","0.99424","-0.00022"
"12.35400","1.02970","0.00000"
"12.78000","1.06521","-0.00044"
"13.20600","1.10061","-0.00014"
"13.63200","1.13612","-0.00002"
"14.05800","1.17170","-0.00027"
"14.48400","1.20721","-0.00042"
"14.91000","1.24273","-0.00021"
"15.33600","1.27812","-0.00013"
"15.76200","1.31370","-0.00001"
"16.18800","1.34921","0.00020"
"16.61400","1.38473","-0.00046"
"17.04000","1.42018","-0.00077"
"17.46600","1.45570","-0.00062"
"17.89200","1.49121","-0.00042"
"18.31800","1.52667","-0.00053"
"18.74400","1.56218","-0.00024"
"19.17000","1.59770","-0.00004"
"19.59600","1.63315","-0.00092"
"20.02200","1.66867","-0.00050"
"20.44800","1.70424","-0.00032"
"20.87400","1.73976","-0.00055"
"21.30000","1.77521","-0.00050"
"21.72600","1.81067","-0.00068"
"22.15200","1.84624","-0.00067"
"22.57800","1.88176","-0.00071"
"23.00400","1.91721","-0.00053"
"23.43000","1.95267","-0.00038"
"23.85600","1.98818","-0.00057"
"24.28200","2.02370","-0.00075"
"24.70800","2.05915","-0.00069"
"25.13400","2.09467","-0.00053"
"25.56000","2.13012","-0.00072"
"25.98600","2.16564","-0.00060"
"26.41200","2.20115","-0.00071"
"26.83800","2.23667","-0.00076"
"27.26400","2.27224","-0.00112"
"27.69000","2.30764","-0.00034"
"28.11600","2.34321","-0.00092"
"28.54200","2.37873","-0.00098"
"28.96800","2.41424","-0.00105"
"29.39400","2.44970","-0.00089"
"29.82000","2.48515","-0.00066"
"30.24600","2.52067","-0.00094"
"30.67200","2.55624","-0.00036"
"31.09800","2.59170","-0.00058"
"31.52400","2.62715","-0.00081"
"31.95000","2.66267","-0.00078"
"32.37600","2.69818","-0.00110"
"32.80200","2.73370","-0.00073"
"33.22800","2.76921","-0.00041"
"33.65400","2.80467","-0.00072"
"34.08000","2.84018","-0.00059"
"34.50600","2.87570","-0.00080"
"34.93200","2.91121","-0.00073"
"35.35800","2.94679","-0.00070"
"35.78400","2.98218","-0.00080"
"36.21000","3.01770","-0.00077"
"36.63600","3.05321","-0.00075"
"37.06200","3.08873","-0.00097"
"37.48800","3.12424","-0.00067"
"37.91400","3.15964","-0.00097"
"38.34000","3.19521","-0.00063"
"38.76600","3.23073","-0.00075"
"39.19200","3.26618","-0.00062"
"39.61800","3.30164","-0.00100"
"40.04400","3.33715","-0.00069"
"40.47000","3.37267","-0.00089"
"40.89600","3.40824","-0.00108"
"41.32200","3.44370","-0.00084"
"41.74800","3.47915","-0.00085"
"42.17400","3.51467","-0.00091"
"42.60000","3.55012","-0.00097"
"43.02600","3.58570","-0.00098"
"43.45200","3.62121","-0.00096"
"43.87800","3.65667","-0.00080"
"44.30400","3.69218","-0.00053"
"44.73000","3.72770","-0.00087"
"45.15600","3.76321","-0.00103"
"45.58200","3.79873","-0.00089"
"46.00800","3.83418","-0.00055"
"46.43400","3.86970","-0.00080"
"46.86000","3.90521","-0.00074"
"47.28600","3.94073","-0.00073"
"47.71200","3.97618","-0.00070"
"48.13800","4.01170","-0.00072"
"48.56400","4.04715","-0.00098"
"48.99000","4.08273","-0.00096"
"49.41600","4.11824","-0.00059"
"49.84200","4.15370","-0.00063"
"50.26800","4.18915","-0.00100"
"50.69400","4.22473","-0.00078"
"51.12000","4.26024","-0.00084"
"51.54600","4.29576","-0.00091"
"51.97200","4.33115","-0.00121"
"52.39800","4.36667","-0.00113"
"52.82400","4.40218","-0.00067"
"53.25000","4.43770","-0.00112"
"53.67600","4.47321","-0.00100"
"54.10200","4.50867","-0.00084"
"54.52800","4.54412","-0.00072"
"54.95400","4.57970","-0.00088"
"55.38000","4.61521","-0.00085"
"55.80600","4.65067","-0.00037"
"56.23200","4.68612","-0.00052"
"56.65800","4.72170","-0.00094"
"57.08400","4.75721","-0.00063"
"57.51000","4.79273","-0.00094"
"57.93600","4.82818","-0.00055"
"58.36200","4.86364","-0.00089"
"58.78800","4.89921","-0.00078"
"59.21400","4.93473","-0.00047"
"59.64000","4.97024","-0.00084"
"60.06600","5.00564","-0.00045"
"60.49200","5.04121","-0.00062"
"60.91800","5.07673","-0.00042"
"61.34400","5.11218","-0.00043"
"61.77000","5.14770","-0.00069"
"62.19600","5.18321","-0.00075"
"62.62200","5.21867","-0.00073"
"63.04800","5.25424","-0.00029"
"63.47400","5.28976","-0.00032"
"63.90000","5.32521","-0.00095"
"64.32600","5.36067","-0.00070"
"64.75200","5.39612","-0.00041"
"65.17800","5.43170","-0.00037"
"65.60400","5.46721","-0.00068"
"66.03000","5.50267","-0.00073"
"66.45600","5.53812","-0.00033"
"66.88200","5.57370","-0.00053"
"67.30800","5.60916","-0.00041"
"67.73400","5.64467","-0.00064"
"68.16000","5.68019","-0.00108"
"68.58600","5.71564","-0.00049"
"69.01200","5.75115","-0.00043"
"69.43800","5.78673","-0.00089"
"69.86400","5.82219","-0.00085"
"70.29000","5.85770","-0.00049"
"70.71600","5.89316","-0.00026"
"71.14200","5.92873","-0.00040"
"71.56800","5.96425","-0.00059"
"71.99400","5.99976","-0.00040"
"72.42000","6.03516","-0.00022"
"72.84600","6.07067","-0.00009"
"73.27200","6.10625","-0.00005"
"73.69800","6.14176","-0.00015"
"74.12400","6.17722","-0.00020"
"74.55000","6.21267","-0.00048"
"74.97600","6.24819","-0.00026"
"75.40200","6.28376","-0.00062"
"75.82800","6.31922","0.00015"
"76.25400","6.35473","-0.00012"
"76.68000","6.39019","0.00009"
"77.10600","6.42570","0.00018"
"77.53200","6.46122","0.00026"
"77.95800","6.49673","-0.00004"
"78.38400","6.53225","0.00025"
"78.81000","6.56764","-0.00004"
"79.23600","6.60316","0.00067"
"79.66200","6.63873","-0.00030"
"80.08800","6.67419","0.00021"
"80.51400","6.70964","0.00006"
"80.94000","6.74516","0.00018"
"81.36600","6.78067","0.00048"
"81.79200","6.81625","0.00027"
"82.21800","6.85170","0.00029"
"82.64400","6.88716","0.00033"
"83.07000","6.92267","0.00067"
"83.49600","6.95819","0.00043"
"83.92200","6.99364","0.00087"
"84.34800","7.02922","0.00035"
"84.77400","7.06467","0.00064"
"85.20000","7.10019","0.00020"
"85.62600","7.13570","0.00046"
"86.05200","7.17122","0.00047"
"86.47800","7.20673","0.00048"
"86.90400","7.24213","0.00025"
"87.33000","7.27770","0.00078"
"87.75600","7.31322","0.00092"
"88.18200","7.34873","0.00066"
"88.60800","7.38419","0.00065"
"89.03400","7.41964","0.00076"
"89.46000","7.45522","0.00095"
"89.88600","7.49073","0.00084"
"90.31200","7.52619","0.00077"
"90.73800","7.56170","0.00070"
"91.16400","7.59722","0.00110"
"91.59000","7.63273","0.00079"
"92.01600","7.66819","0.00097"
"92.44200","7.70370","0.00112"
"92.86800","7.73916","0.00067"
"93.29400","7.77467","0.00085"
"93.72000","7.81019","0.00117"
"94.14600","7.84570","0.00119"
"94.57200","7.88122","0.00099"
"94.99800","7.91661","0.00112"
"95.42400","7.95219","0.00105"
"95.85000","7.98770","0.00115"
"96.27600","8.02322","0.00102"
"96.70200","8.05867","0.00082"
"97.12800","8.09413","0.00131"
"97.55400","8.12970","0.00068"
"97.98000","8.16522","0.00090"
"98.40600","8.20073","0.00103"
"98.83200","8.23619","0.00092"
"99.25800","8.27164","0.00121"
"99.68400","8.30716","0.00122"
"100.11000","8.34273","0.00077"
"100.53600","8.37825","0.00110"
"100.96200","8.41370","0.00122"
"101.38800","8.44916","0.00132"
"101.81400","8.48467","0.00096"
"102.24000","8.52025","0.00079"
"102.66600","8.55576","0.00113"
"103.09200","8.59116","0.00097"
"103.51800","8.62667","0.00164"
"103.94400","8.66225","0.00107"
"104.37000","8.69770","0.00106"
"104.79600","8.73322","0.00095"
"105.22200","8.76867","0.00104"
"105.64800","8.80419","0.00134"
"106.07400","8.83970","0.00158"
"106.50000","8.87522","0.00140"
"106.92600","8.91067","0.00169"
"107.35200","8.94613","0.00140"
"107.77800","8.98164","0.00148"
"108.20400","9.01722","0.00152"
"108.63000","9.05267","0.00157"
"109.05600","9.08813","0.00165"
"109.48200","9.12358","0.00122"
"109.90800","9.15916","0.00126"
"110.33400","9.19467","0.00174"
"110.76000","9.23025","0.00183"
"111.18600","9.26564","0.00132"
"111.61200","9.30116","0.00166"
"112.03800","9.33667","0.00162"
"112.46400","9.37219","0.00153"
"112.89000","9.40770","0.00157"
"113.31600","9.44316","0.00190"
"113.74200","9.47867","0.00157"
"114.16800","9.51425","0.00188"
"114.59400","9.54976","0.00212"
"115.02000","9.58528","0.00218"
"115.44600","9.62067","0.00152"
"115.87200","9.65613","0.00130"
"116.29800","9.69176","0.00188"
"116.72400","9.72722","0.00119"
"117.15000","9.76267","0.00164"
"117.57600","9.79819","0.00177"
"118.00200","9.83370","0.00118"
"118.42800","9.86916","0.00189"
"118.85400","9.90473","0.00182"
"119.28000","9.94019","0.00162"
"119.70600","9.97564","0.00180"
"120.13200","10.01116","0.00150"
"120.55800","10.04673","0.00125"
"120.98400","10.08219","0.00098"
"121.41000","10.11764","0.00090"
"121.83600","10.15316","0.00111"
"122.26200","10.18861","0.00117"
"122.68800","10.22419","0.00145"
"123.11400","10.25970","0.00128"
"123.54000","10.29516","0.00136"
"123.96600","10.33061","0.00098"
"124.39200","10.36619","0.00123"
"124.81800","10.40171","0.00130"
"125.24400","10.43716","0.00122"
"125.67000","10.47268","0.00126"
"126.09600","10.50819","0.00127"
"126.52200","10.54370","0.00145"
"126.94800","10.57916","0.00167"
"127.37400","10.61473","0.00124"
"127.80000","10.65019","0.00087"
"128.22600","10.68571","0.00134"
"128.65200","10.72116","0.00131"
"129.07800","10.75673","0.00118"
"129.50400","10.79219","0.00068"
"129.93000","10.82765","0.00155"
"130.35600","10.86322","0.00109"
"130.78200","10.89874","0.00111"
"131.20800","10.93425","0.00124"
"131.63400","10.96970","0.00065"
"132.06000","11.00516","0.00115"
"132.48600","11.04074","0.00111"
"132.91200","11.07625","0.00126"
"133.33800","11.11165","0.00138"
"133.76400","11.14716","0.00147"
"134.19000","11.18268","0.00110"
"134.61600","11.21819","0.00122"
"135.04200","11.25365","0.00146"
"135.46800","11.28916","0.00153"
"135.89400","11.32462","0.00128"
"136.32000","11.36019","0.00120"
"136.74600","11.39571","0.00167"
"137.17200","11.43116","0.00165"
"137.59800","11.46674","0.00177"
"138.02400","11.50219","0.00169"
"138.45000","11.53765","0.00202"
"138.87600","11.57322","0.00146"
"139.30200","11.60868","0.00186"
"139.72800","11.64419","0.00133"
"140.15400","11.67959","0.00076"
"140.58000","11.71522","0.00078"
"141.00600","11.75074","0.00110"
"141.43200","11.78619","0.00122"
"141.85800","11.82165","0.00121"
"142.28400","11.85716","0.00150"
"142.71000","11.89274","0.00117"
"143.13600","11.92825","0.00138"
"143.56200","11.96371","0.00159"
"143.98800","11.99916","0.00079"
"144.41400","12.03468","0.00158"
"144.84000","12.07025","0.00133"
"145.26600","12.10577","0.00141"
"145.69200","12.14122","0.00145"
"146.11800","12.17668","0.00131"
"146.54400","12.21219","0.00144"
"146.97000","12.24771","0.00118"
"147.39600","12.28322","0.00101"
"147.82200","12.31868","0.00167"
"148.24800","12.35413","0.00097"
"148.67400","12.38965","0.00147"
"149.10000","12.42522","0.00080"
"149.52600","12.46074","0.00080"
"149.95200","12.49619","0.00081"
"150.37800","12.53165","0.00100"
"150.80400","12.56716","0.00146"
"151.23000","12.60268","0.00113"
"151.65600","12.63819","0.00148"
"152.08200","12.67365","0.00109"
"152.50800","12.70910","0.00134"
"152.93400","12.74468","0.00126"
"153.36000","12.78019","0.00118"
"153.78600","12.81571","0.00148"
"154.21200","12.85116","0.00153"
"154.63800","12.88662","0.00126"
"155.06400","12.92219","0.00131"
"155.49000","12.95771","0.00084"
"155.91600","12.99322","0.00181"
"156.34200","13.02868","0.00158"
"156.76800","13.06419","0.00169"
"157.19400","13.09977","0.00145"
"157.62000","13.13528","0.00171"
"158.04600","13.17074","0.00146"
"158.47200","13.20619","0.00171"
"158.89800","13.24165","0.00160"
"159.32400","13.27722","0.00188"
"159.75000","13.31274","0.00172"
"160.17600","13.34819","0.00162"
"160.60200","13.38365","0.00180"
"161.02800","13.41916","0.00166"
"161.45400","13.45468","0.00225"
"161.88000","13.49025","0.00198"
"162.30600","13.52571","0.00156"
"162.73200","13.56116","0.00164"
"163.15800","13.59662","0.00171"
"163.58400","13.63219","0.00182"
"164.01000","13.66765","0.00189"
"164.43600","13.70316","0.00139"
"164.86200","13.73868","0.00174"
"165.28800","13.77413","0.00189"
"165.71400","13.80971","0.00182"
"166.14000","13.84528","0.00201"
"166.56600","13.88062","0.00191"
"166.99200","13.91613","0.00181"
"167.41800","13.95171","0.00233"
"167.84400","13.98722","0.00159"
"168.27000","14.02268","0.00207"
"168.69600","14.05819","0.00160"
"169.12200","14.09371","0.00211"
"169.54800","14.12922","0.00201"
"169.97400","14.16468","0.00219"
"170.40000","14.20019","0.00180"
"170.82600","14.23571","0.00198"
"171.25200","14.27122","0.00196"
"171.67800","14.30674","0.00198"
"172.10400","14.34225","0.00159"
"172.53000","14.37771","0.00156"
"172.95600","14.41317","0.00181"
"173.38200","14.44874","0.00190"
"173.80800","14.48419","0.00173"
"174.23400","14.51971","0.00189"
"174.66000","14.55516","0.00236"
"175.08600","14.59068","0.00230"
"175.51200","14.62619","0.00238"
"175.93800","14.66171","0.00228"
"176.36400","14.69716","0.00184"
"176.79000","14.73262","0.00229"
"177.21600","14.76820","0.00214"
"177.64200","14.80371","0.00224"
"178.06800","14.83916","0.00185"
"178.49400","14.87468","0.00189"
"178.92000","14.91020","0.00199"
"179.34600","14.94571","0.00249"
"179.77200","14.98117","0.00239"
"180.19800","15.01668","0.00235"
"180.62400","15.05219","0.00213"
"181.05000","15.08771","0.00237"
"181.47600","15.12323","0.00221"
"181.90200","15.15874","0.00171"
"182.32800","15.19425","0.00233"
"182.75400","15.22965","0.00203"
"183.18000","15.26511","0.00214"
"183.60600","15.30074","0.00217"
"184.03200","15.33626","0.00232"
"184.45800","15.37177","0.00244"
"184.88400","15.40717","0.00190"
"185.31000","15.44268","0.00235"
"185.73600","15.47826","0.00209"
"186.16200","15.51371","0.00262"
"186.58800","15.54923","0.00227"
"187.01400","15.58462","0.00218"
"187.44000","15.62020","0.00228"
"187.86600","15.65571","0.00175"
"188.29200","15.69122","0.00240"
"188.71800","15.72668","0.00282"
"189.14400","15.76214","0.00217"
"189.57000","15.79765","0.00212"
"189.99600","15.83323","0.00202"
"190.42200","15.86868","0.00266"
"190.84800","15.90420","0.00233"
"191.27400","15.93965","0.00216"
"191.70000","15.97516","0.00278"
"192.12600","16.01068","0.00246"
"192.55200","16.04619","0.00262"
"192.97800","16.08165","0.00226"
"193.40400","16.11716","0.00263"
"193.83000","16.15268","0.00238"
"194.25600","16.18826","0.00262"
"194.68200","16.22377","0.00219"
"195.10800","16.25916","0.00279"
"195.53400","16.29462","0.00250"
"195.96000","16.33020","0.00291"
"196.38600","16.36571","0.00242"
"196.81200","16.40123","0.00272"
"197.23800","16.43668","0.00270"
"197.66400","16.47220","0.00220"
"198.09000","16.50765","0.00255"
"198.51600","16.54317","0.00256"
"198.94200","16.57874","0.00231"
"199.36800","16.61419","0.00259"
"199.79400","16.64971","0.00258"
"200.22000","16.68522","0.00238"
"200.64600","16.72074","0.00204"
"201.07200","16.75620","0.00211"
"201.49800","16.79171","0.00186"
"201.92400","16.82717","0.00244"
"202.35000","16.86274","0.00215"
"202.77600","16.89826","0.00265"
"203.20200","16.93365","0.00192"
"203.62800","16.96917","0.00209"
"204.05400","17.00468","0.00212"
"204.48000","17.04020","0.00200"
"204.90600","17.07565","0.00177"
"205.33200","17.11110","0.00203"
"205.75800","17.14668","0.00213"
"206.18400","17.18220","0.00200"
"206.61000","17.21771","0.00212"
"207.03600","17.25323","0.00233"
"207.46200","17.28868","0.00243"
"207.88800","17.32414","0.00246"
"208.31400","17.35965","0.00232"
"208.74000","17.39523","0.00243"
"209.16600","17.43068","0.00214"
"209.59200","17.46614","0.00273"
"210.01800","17.50171","0.00277"
"210.44400","17.53723","0.00262"
"210.87000","17.57274","0.00272"
"211.29600","17.60820","0.00235"
"211.72200","17.64365","0.00218"
"212.14800","17.67923","0.00249"
"212.57400","17.71474","0.00273"
"213.00000","17.75026","0.00263"
"213.42600","17.78571","0.00268"
"213.85200","17.82117","0.00272"
"214.27800","17.85674","0.00232"
"214.70400","17.89214","0.00211"
"215.13000","17.92771","0.00207"
"215.55600","17.96317","0.00213"
"215.98200","17.99862","0.00169"
"216.40800","18.03420","0.00202"
"216.83400","18.06965","0.00196"
"217.26000","18.10517","0.00230"
"217.68600","18.14068","0.00180"
"218.11200","18.17614","0.00254"
"218.53800","18.21171","0.00201"
"218.96400","18.24723","0.00243"
"219.39000","18.28268","0.00253"
"219.81600","18.31814","0.00223"
"220.24200","18.35365","0.00229"
"220.66800","18.38923","0.00275"
"221.09400","18.42462","0.00234"
"221.52000","18.46020","0.00251"
"221.94600","18.49565","0.00251"
"222.37200","18.53123","0.00265"
"222.79800","18.56674","0.00300"
"223.22400","18.60220","0.00268"
"223.65000","18.63771","0.00293"
"224.07600","18.67317","0.00300"
"224.50200","18.70874","0.00239"
"224.92800","18.74426","0.00251"
"225.35400","18.77977","0.00222"
"225.78000","18.81523","0.00303"
"226.20600","18.85068","0.00262"
"226.63200","18.88620","0.00272"
"227.05800","18.92171","0.00264"
"227.48400","18.95717","0.00296"
"227.91000","18.99268","0.00286"
"228.33600","19.02820","0.00270"
"228.76200","19.06371","0.00273"
"229.18800","19.09923","0.00269"
"229.61400","19.13468","0.00268"
"230.04000","19.17014","0.00269"
"230.46600","19.20571","0.00240"
"230.89200","19.24117","0.00315"
"231.31800","19.27668","0.00296"
"231.74400","19.31220","0.00287"
"232.17000","19.34765","0.00316"
"232.59600","19.38317","0.00334"
"233.02200","19.41868","0.00321"
"233.44800","19.45420","0.00305"
"233.87400","19.48965","0.00291"
"234.30000","19.52517","0.00277"
"234.72600","19.56074","0.00357"
"235.15200","19.59620","0.00235"
"235.57800","19.63171","0.00284"
"236.00400","19.66717","0.00294"
"236.43000","19.70263","0.00272"
"236.85600","19.73820","0.00278"
"237.28200","19.77371","0.00281"
"237.70800","19.80923","0.00299"
"238.13400","19.84468","0.00290"
"238.56000","19.88020","0.00307"
"238.98600","19.91571","0.00282"
"239.41200","19.95123","0.00303"
"239.83800","19.98668","0.00291"
"240.26400","20.02220","0.00340"
"240.69000","20.05765","0.00323"
"241.11600","20.09323","0.00313"
"241.54200","20.12874","0.00314"
"241.96800","20.16420","0.00336"
"242.39400","20.19965","0.00350"
"242.82000","20.23517","0.00350"
"243.24600","20.27074","0.00344"
"243.67200","20.30620","0.00397"
"244.09800","20.34165","0.00335"
"244.52400","20.37717","0.00325"
"244.95000","20.41263","0.00377"
"245.37600","20.44820","0.00338"
"245.80200","20.48372","0.00249"
"246.22800","20.51917","0.00328"
"246.65400","20.55462","0.00323"
"247.08000","20.59020","0.00301"
"247.50600","20.62571","0.00283"
"247.93200","20.66123","0.00285"
"248.35800","20.69662","0.00323"
"248.78400","20.73220","0.00293"
"249.21000","20.76765","0.00260"
"249.63600","20.80317","0.00237"
"250.06200","20.83869","0.00254"
"250.48800","20.87414","0.00280"
"250.91400","20.90972","0.00237"
"251.34000","20.94517","0.00256"
"251.76600","20.98074","0.00246"
"252.19200","21.01620","0.00285"
"252.61800","21.05165","0.00273"
"253.04400","21.08723","0.00259"
"253.47000","21.12275","0.00273"
"253.89600","21.15820","0.00242"
"254.32200","21.19372","0.00271"
"254.74800","21.22917","0.00303"
"255.17400","21.26468","0.00275"
"255.60000","21.30020","0.00304"
"256.02600","21.33572","0.00292"
"256.45200","21.37111","0.00327"
"256.87800","21.40668","0.00326"
"257.30400","21.44220","0.00342"
"257.73000","21.47772","0.00350"
"258.15600","21.51317","0.00302"
"258.58200","21.54863","0.00343"
"259.00800","21.58420","0.00325"
"259.43400","21.61966","0.00339"
"259.86000","21.65517","0.00409"
"260.28600","21.69069","0.00409"
"260.71200","21.72614","0.00403"
"261.13800","21.76166","0.00429"
"261.56400","21.79723","0.00242"
"261.99000","21.83269","0.00192"
"262.41600","21.86814","0.00220"
"262.84200","21.90366","0.00171"
"263.26800","21.93923","0.00245"
"263.69400","21.97474","0.00183"
"264.12000","22.01020","0.00215"
"264.54600","22.04565","0.00252"
"264.97200","22.08117","0.00191"
"265.39800","22.11669","0.00143"
"265.82400","22.15226","0.00131"
"266.25000","22.18772","0.00145"
"266.67600","22.22317","0.00200"
"267.10200","22.25869","0.00177"
"267.52800","22.29426","0.00154"
"267.95400","22.32972","0.00141"
"268.38000","22.36523","0.00179"
"268.80600","22.40068","0.00163"
"269.23200","22.43614","0.00145"
"269.65800","22.47172","0.00185"
"270.08400","22.50723","0.00194"
"270.51000","22.54268","0.00147"
"270.93600","22.57814","0.00155"
"271.36200","22.61366","0.00191"
"271.78800","22.64923","0.00154"
"272.21400","22.68469","0.00207"
"272.64000","22.72014","0.00141"
"273.06600","22.75566","0.00196"
"273.49200","22.79117","0.00195"
"273.91800","22.82669","0.00190"
"274.34400","22.86220","0.00164"
"274.77000","22.89766","0.00189"
"275.19600","22.93311","0.00186"
"275.62200","22.96869","0.00216"
"276.04800","23.00420","0.00226"
"276.47400","23.03972","0.00231"
"276.90000","23.07517","0.00188"
"277.32600","23.11063","0.00193"
"277.75200","23.14620","0.00224"
"278.17800","23.18172","0.00232"
"278.60400","23.21723","0.00260"
"279.03000","23.25269","0.00257"
"279.45600","23.28814","0.00203"
"279.88200","23.32372","0.00217"
"280.30800","23.35923","0.00237"
"280.73400","23.39469","0.00235"
"281.16000","23.43020","0.00190"
"281.58600","23.46572","0.00178"
"282.01200","23.50117","0.00157"
"282.43800","23.53675","0.00224"
"282.86400","23.57220","0.00234"
"283.29000","23.60766","0.00179"
"283.71600","23.64317","0.00193"
"284.14200","23.67869","0.00219"
"284.56800","23.71420","0.00205"
"284.99400","23.74966","0.00221"
"285.42000","23.78511","0.00205"
"285.84600","23.82069","0.00212"
"286.27200","23.85620","0.00234"
"286.69800","23.89166","0.00221"
"287.12400","23.92711","0.00217"
"287.55000","23.96269","0.00263"
"287.97600","23.99821","0.00240"
"288.40200","24.03372","0.00268"
"288.82800","24.06923","0.00188"
"289.25400","24.10469","0.00254"
"289.68000","24.14014","0.00280"
"290.10600","24.17566","0.00256"
"290.53200","24.21117","0.00249"
"290.95800","24.24669","0.00253"
"291.38400","24.28214","0.00263"
"291.81000","24.31772","0.00244"
"292.23600","24.35317","0.00241"
"292.66200","24.38875","0.00243"
"293.08800","24.42420","0.00217"
"293.51400","24.45966","0.00206"
"293.94000","24.49524","0.00221"
"294.36600","24.53075","0.00215"
"294.79200","24.56620","0.00210"
"295.21800","24.60166","0.00199"
"295.64400","24.63717","0.00259"
"296.07000","24.67275","0.00212"
"296.49600","24.70820","0.00279"
"296.92200","24.74366","0.00221"
"297.34800","24.77917","0.00246"
"297.77400","24.81469","0.00253"
"298.20000","24.85020","0.00251"
"298.62600","24.88572","0.00273"
"299.05200","24.92123","0.00279"
"299.47800","24.95663","0.00273"
"299.90400","24.99220","0.00287"
"300.33000","25.02772","0.00268"
"300.75600","25.06318","0.00254"
"301.18200","25.09869","0.00288"
"301.60800","25.13414","0.00290"
"302.03400","25.16966","0.00269"
"302.46000","25.20524","0.00267"
"302.88600","25.24069","0.00228"
"303.31200","25.27621","0.00248"
"303.73800","25.31166","0.00220"
"304.16400","25.34717","0.00237"
"304.59000","25.38269","0.00222"
"305.01600","25.41821","0.00214"
"305.44200","25.45372","0.00189"
"305.86800","25.48923","0.00231"
"306.29400","25.52469","0.00221"
"306.72000","25.56020","0.00246"
"307.14600","25.59572","0.00249"
"307.57200","25.63117","0.00236"
"307.99800","25.66669","0.00218"
"308.42400","25.70220","0.00233"
"308.85000","25.73772","0.00211"
"309.27600","25.77324","0.00207"
"309.70200","25.80869","0.00227"
"310.12800","25.84421","0.00236"
"310.55400","25.87966","0.00234"
"310.98000","25.91523","0.00246"
"311.40600","25.95075","0.00231"
"311.83200","25.98615","0.00208"
"312.25800","26.02172","0.00208"
"312.68400","26.05723","0.00261"
"313.11000","26.09269","0.00236"
"313.53600","26.12815","0.00207"
"313.96200","26.16360","0.00258"
"314.38800","26.19917","0.00298"
"314.81400","26.23475","0.00184"
"315.24000","26.27021","0.00203"
"315.66600","26.30566","0.00216"
"316.09200","26.34118","0.00232"
"316.51800","26.37669","0.00261"
"316.94400","26.41221","0.00257"
"317.37000","26.44772","0.00253"
"317.79600","26.48318","0.00235"
"318.22200","26.51869","0.00278"
"318.64800","26.55415","0.00291"
"319.07400","26.58972","0.00270"
"319.50000","26.62524","0.00147"
"319.92600","26.66063","0.00161"
"320.35200","26.69609","0.00148"
"320.77800","26.73172","0.00155"
"321.20400","26.76723","0.00157"
"321.63000","26.80275","0.00165"
"322.05600","26.83821","0.00143"
"322.48200","26.87372","0.00173"
"322.90800","26.90924","0.00122"
"323.33400","26.94475","0.00158"
"323.76000","26.98021","0.00134"
"324.18600","27.01566","0.00112"
"324.61200","27.05118","0.00119"
"325.03800","27.08669","0.00154"
"325.46400","27.12221","0.00172"
"325.89000","27.15766","0.00160"
"326.31600","27.19318","0.00179"
"326.74200","27.22863","0.00181"
"327.16800","27.26421","0.00212"
"327.59400","27.29972","0.00194"
"328.02000","27.33518","0.00186"
"328.44600","27.37063","0.00199"
"328.87200","27.40615","0.00152"
"329.29800","27.44166","0.00161"
"329.72400","27.47718","0.00185"
"330.15000","27.51263","0.00196"
"330.57600","27.54815","0.00216"
"331.00200","27.58372","0.00241"
"331.42800","27.61924","0.00217"
"331.85400","27.65469","0.00228"
"332.28000","27.69021","0.00226"
"332.70600","27.72566","0.00272"
"333.13200","27.76118","0.00274"
"333.55800","27.79675","0.00264"
"333.98400","27.83215","0.00217"
"334.41000","27.86766","0.00187"
"334.83600","27.90318","0.00216"
"335.26200","27.93869","0.00232"
"335.68800","27.97421","0.00201"
"336.11400","28.00966","0.00202"
"336.54000","28.04518","0.00215"
"336.96600","28.08075","0.00246"
"337.39200","28.11621","0.00168"
"337.81800","28.15172","0.00233"
"338.24400","28.18718","0.00174"
"338.67000","28.22263","0.00215"
"339.09600","28.25821","0.00193"
"339.52200","28.29366","0.00215"
"339.94800","28.32918","0.00217"
"340.37400","28.36463","0.00197"
"340.80000","28.40015","0.00217"
"341.22600","28.43566","0.00243"
"341.65200","28.47118","0.00252"
"342.07800","28.50669","0.00270"
"342.50400","28.54215","0.00232"
"342.93000","28.57772","0.00249"
"343.35600","28.61324","0.00275"
"343.78200","28.64869","0.00267"
"344.20800","28.68421","0.00276"
"344.63400","28.71966","0.00231"
"345.06000","28.75518","0.00221"
"345.48600","28.79069","0.00287"
"345.91200","28.82621","0.00243"
"346.33800","28.86172","0.00279"
"346.76400","28.89712","0.00280"
"347.19000","28.93275","0.00265"
"347.61600","28.96827","0.00274"
"348.04200","29.00366","0.00243"
"348.46800","29.03918","0.00241"
"348.89400","29.07470","0.00276"
"349.32000","29.11027","0.00245"
"349.74600","29.14578","0.00272"
"350.17200","29.18124","0.00214"
"350.59800","29.21663","0.00237"
"351.02400","29.25221","0.00236"
"351.45000","29.28766","0.00286"
"351.87600","29.32318","0.00241"
"352.30200","29.35870","0.00260"
"352.72800","29.39409","0.00263"
"353.15400","29.42966","0.00280"
"353.58000","29.46524","0.00269"
"354.00600","29.50063","0.00253"
"354.43200","29.53621","0.00286"
"354.85800","29.57161","0.00320"
"355.28400","29.60718","0.00289"
"355.71000","29.64275","0.00269"
"356.13600","29.67827","0.00320"
"356.56200","29.71367","0.00269"
"356.98800","29.74918","0.00226"
"357.41400","29.78469","0.00208"
"357.84000","29.82021","0.00282"
"358.26600","29.85567","0.00283"
"358.69200","29.89112","0.00294"
"359.11800","29.92669","0.00298"
"359.54400","29.96221","0.00299"
"359.97000","29.99772","0.00281"
"360.39600","30.03324","0.00338"
"360.82200","30.06870","0.00321"
"361.24800","30.10421","0.00366"
"361.67400","30.13972","0.00354"
"362.10000","30.17530","0.00380"
"362.52600","30.21075","0.00362"
"362.95200","30.24615","0.00387"
"363.37800","30.28166","0.00349"
"363.80400","30.31724","0.00441"
"364.23000","30.35275","0.00419"
"364.65600","30.38821","0.00358"
"365.08200","30.42367","0.00366"
"365.50800","30.45918","0.00392"
"365.93400","30.49470","0.00413"
"366.36000","30.53021","0.00437"
"366.78600","30.56566","0.00478"
"367.21200","30.60118","0.00503"
"367.63800","30.63669","0.00527"
"368.06400","30.67221","0.00530"
"368.49000","30.70773","0.00544"
"368.91600","30.74318","0.00546"
"369.34200","30.77869","0.00504"
"369.76800","30.81415","0.00515"
"370.19400","30.84967","0.00559"
"370.62000","30.88518","0.00514"
"371.04600","30.92070","0.00431"
"371.47200","30.95609","0.00511"
"371.89800","30.99173","0.00329"
"372.32400","31.02718","0.00405"
"372.75000","31.06270","0.00246"
"373.17600","31.09815","0.00292"
"373.60200","31.13367","0.00265"
"374.02800","31.16924","0.00221"
"374.45400","31.20475","0.00298"
"374.88000","31.24021","0.00315"
"375.30600","31.27572","0.00145"
"375.73200","31.31124","0.00187"
"376.15800","31.34669","0.00103"
"376.58400","31.38221","0.00141"
"377.01000","31.41766","0.00137"
"377.43600","31.45318","0.00127"
"377.86200","31.48875","0.00147"
"378.28800","31.52415","0.00179"
"378.71400","31.55967","0.00205"
"379.14000","31.59518","0.00184"
"379.56600","31.63063","0.00227"
"379.99200","31.66621","0.00247"
"380.41800","31.70173","0.00239"
"380.84400","31.73718","0.00156"
"381.27000","31.77264","0.00124"
"381.69600","31.80815","0.00121"
"382.12200","31.84367","0.00125"
"382.54800","31.87918","0.00143"
"382.97400","31.91464","0.00136"
"383.40000","31.95009","0.00174"
"383.82600","31.98567","0.00179"
"384.25200","32.02118","0.00189"
"384.67800","32.05670","0.00221"
"385.10400","32.09215","0.00195"
"385.53000","32.12761","0.00263"
"385.95600","32.16318","0.00235"
"386.38200","32.19870","0.00224"
"386.80800","32.23421","0.00305"
"387.23400","32.26966","0.00297"
"387.66000","32.30518","0.00299"
"388.08600","32.34069","0.00309"
"388.51200","32.37621","0.00328"
"388.93800","32.41172","0.00342"
"389.36400","32.44718","0.00335"
"389.79000","32.48270","0.00359"
"390.21600","32.51821","0.00358"
"390.64200","32.55378","0.00380"
"391.06800","32.58924","0.00427"
"391.49400","32.62464","0.00410"
"391.92000","32.66021","0.00420"
"392.34600","32.69572","0.00457"
"392.77200","32.73124","0.00471"
"393.19800","32.76670","0.00470"
"393.62400","32.80209","0.00437"
"394.05000","32.83767","0.00506"
"394.47600","32.87318","0.00491"
"394.90200","32.90864","0.00372"
"395.32800","32.94415","0.00363"
"395.75400","32.97961","0.00404"
"396.18000","33.01512","0.00438"
"396.60600","33.05070","0.00396"
"397.03200","33.08621","0.00440"
"397.45800","33.12173","0.00475"
"397.88400","33.15712","0.00494"
"398.31000","33.19270","0.00528"
"398.73600","33.22821","0.00564"
"399.16200","33.26373","0.00581"
"399.58800","33.29912","0.00517"
"400.01400","33.33464","0.00521"
"400.44000","33.37021","0.00455"
"400.86600","33.40573","0.00408"
"401.29200","33.44118","0.00480"
"401.71800","33.47663","0.00496"
"402.14400","33.51215","0.00555"
"402.57000","33.54766","0.00584"
"402.99600","33.58324","0.00616"
"403.42200","33.61869","0.00600"
"403.84800","33.65415","0.00591"
"404.27400","33.68973","0.00601"
"404.70000","33.72524","0.00656"
"405.12600","33.76070","0.00658"
"405.55200","33.79622","0.00633"
"405.97800","33.83167","0.00682"
"406.40400","33.86718","0.00710"
"406.83000","33.90270","0.00695"
"407.25600","33.93821","0.00733"
"407.68200","33.97367","0.00762"
"408.10800","34.00919","0.00764"
"408.53400","34.04464","0.00801"
"408.96000","34.08021","0.00856"
"409.38600","34.11573","0.00925"
"409.81200","34.15112","0.00926"
"410.23800","34.18670","0.00992"
"410.66400","34.22221","0.00996"
"411.09000","34.25773","0.01031"
"411.51600","34.29318","0.01042"
"411.94200","34.32864","0.01153"
"412.36800","34.36415","0.01186"
"412.79400","34.39967","0.01185"
"413.22000","34.43518","0.01208"
"413.64600","34.47070","0.01181"
"414.07200","34.50615","0.01160"
"414.49800","34.54167","0.01237"
"414.92400","34.57718","0.01272"
"415.35000","34.61270","0.01290"
"415.77600","34.64821","0.01293"
"416.20200","34.68367","0.01309"
"416.62800","34.71918","0.01304"
"417.05400","34.75476","0.01101"
"417.48000","34.79021","0.01134"
"417.90600","34.82573","0.01085"
"418.33200","34.86118","0.01207"
"418.75800","34.89670","0.01197"
"419.18400","34.93222","0.01249"
"419.61000","34.96773","0.01264"
"420.03600","35.00312","0.01281"
"420.46200","35.03870","0.01325"
"420.88800","35.07421","0.00356"
"421.31400","35.10967","0.00247"
"421.74000","35.14519","0.00160"
"422.16600","35.18064","0.00348"
"422.59200","35.21609","0.00395"
"423.01800","35.25173","0.00330"
"423.44400","35.28718","0.00300"
"423.87000","35.32270","0.00401"
"424.29600","35.35815","0.00439"
"424.72200","35.39367","0.00417"
"425.14800","35.42918","0.00390"
"425.57400","35.46470","0.00481"
"426.00000","35.50015","0.00515"
"426.42600","35.53561","0.00526"
"426.85200","35.57118","0.00514"
"427.27800","35.60670","0.00573"
"427.70400","35.64222","0.00547"
"428.13000","35.67761","0.00595"
"428.55600","35.71312","0.00610"
"428.98200","35.74876","0.00594"
"429.40800","35.78428","0.00616"
"429.83400","35.81973","0.00661"
"430.26000","35.85519","0.00708"
"430.68600","35.89070","0.00697"
"431.11200","35.92627","0.00708"
"431.53800","35.96173","0.00703"
"431.96400","35.99725","0.00713"
"432.39000","36.03264","0.00698"
"432.81600","36.06816","0.00743"
"433.24200","36.10373","0.00729"
"433.66800","36.13925","0.00765"
"434.09400","36.17464","0.00765"
"434.52000","36.21016","0.00750"
"434.94600","36.24567","0.00745"
"435.37200","36.28119","0.00765"
"435.79800","36.31670","0.00773"
"436.22400","36.35222","0.00828"
"436.65000","36.38761","0.00843"
"437.07600","36.42318","0.00823"
"437.50200","36.45870","0.00878"
"437.92800","36.49416","0.00847"
"438.35400","36.52967","0.00851"
"438.78000","36.56512","0.00855"
"439.20600","36.60064","0.00837"
"439.63200","36.63622","0.00870"
"440.05800","36.67173","0.00901"
"440.48400","36.70718","0.00917"
"440.91000","36.74264","0.00918"
"441.33600","36.77821","0.00936"
"441.76200","36.81367","0.00878"
"442.18800","36.84925","0.00891"
"442.61400","36.88464","0.00976"
"443.04000","36.92015","0.01013"
"443.46600","36.95573","0.01017"
"443.89200","36.99125","0.01026"
"444.31800","37.02670","0.01050"
"444.74400","37.06216","0.01129"
"445.17000","37.09767","0.01103"
"445.59600","37.13319","0.01113"
"446.02200","37.16876","0.01161"
"446.44800","37.20422","0.01173"
"446.87400","37.23967","0.01171"
"447.30000","37.27519","0.01099"
"447.72600","37.31070","0.01135"
"448.15200","37.34616","0.01147"
"448.57800","37.38167","0.01173"
"449.00400","37.41719","0.01166"
"449.43000","37.45270","0.01162"
"449.85600","37.48822","0.01221"
"450.28200","37.52367","0.01224"
"450.70800","37.55907","0.01237"
"451.13400","37.59470","0.01240"
"451.56000","37.63021","0.01222"
"451.98600","37.66567","0.01266"
"452.41200","37.70124","0.01318"
"452.83800","37.73664","0.01326"
"453.26400","37.77222","0.01373"
"453.69000","37.80773","0.01359"
"454.11600","37.84319","0.01426"
"454.54200","37.87870","0.01484"
"454.96800","37.91416","0.01448"
"455.39400","37.94973","0.01511"
"455.82000","37.98513","0.01524"
"456.24600","38.02070","0.01550"
"456.67200","38.05616","0.01624"
"457.09800","38.09161","0.01596"
"457.52400","38.12719","0.01648"
"457.95000","38.16270","0.01578"
"458.37600","38.19822","0.01533"
"458.80200","38.23373","0.01588"
"459.22800","38.26913","0.01663"
"459.65400","38.30470","0.01650"
"460.08000","38.34028","0.01665"
"460.50600","38.37567","0.01726"
"460.93200","38.41119","0.01789"
"461.35800","38.44670","0.01799"
"461.78400","38.48222","0.01879"
"462.21000","38.51767","0.01873"
"462.63600","38.55319","0.01919"
"463.06200","38.58864","0.01945"
"463.48800","38.62410","0.01982"
"463.91400","38.65973","0.02031"
"464.34000","38.69525","0.01990"
"464.76600","38.73070","0.00216"
"465.19200","38.76616","-0.00054"
"465.61800","38.80167","-0.00065"
"466.04400","38.83719","-0.00021"
"466.47000","38.87270","-0.00048"
"466.89600","38.90816","-0.00086"
"467.32200","38.94368","0.00046"
"467.74800","38.97919","-0.00064"
"468.17400","39.01471","-0.00067"
"468.60000","39.05022","0.00076"
"469.02600","39.08567","-0.00071"
"469.45200","39.12113","-0.00028"
"469.87800","39.15670","0.00062"
"470.30400","39.19228","-0.00063"
"470.73000","39.22773","-0.00044"
"471.15600","39.26318","0.00136"
"471.58200","39.29870","-0.00052"
"472.00800","39.33416","-0.00038"
"472.43400","39.36973","0.00147"
"472.86000","39.40525","-0.00012"
"473.28600","39.44070","-0.00054"
"473.71200","39.47616","0.00074"
"474.13800","39.51173","0.00009"
"474.56400","39.54719","-0.00005"
"474.99000","39.58270","0.00033"
"475.41600","39.61810","0.00015"
"475.84200","39.65367","0.00017"
"476.26800","39.68919","-0.00004"
"476.69400","39.72470","0.00001"
"477.12000","39.76022","-0.00022"
"477.54600","39.79567","-0.00017"
"477.97200","39.83119","-0.00021"
"478.39800","39.86670","0.00028"
"478.82400","39.90216","0.00005"
"479.25000","39.93768","-0.00021"
"479.67600","39.97313","0.00108"
"480.10200","40.00871","0.00000"
"480.52800","40.04422","-0.00002"
"480.95400","40.07973","0.00172"
"481.38000","40.11519","-0.00014"
"481.80600","40.15064","0.00018"
"482.23200","40.18622","0.00112"
"482.65800","40.22168","-0.00052"
"483.08400","40.25724","0.00002"
"483.51000","40.29271","0.00033"
"483.93600","40.32816","0.00019"
"484.36200","40.36380","0.00040"
"484.78800","40.39919","-0.00036"
"485.21400","40.43471","0.00027"
"485.64000","40.47021","0.00216"
"486.06600","40.50567","-0.00020"
"486.49200","40.54125","-0.00006"
"486.91800","40.57676","0.00116"
"487.34400","40.61222","-0.00003"
"487.77000","40.64767","0.00074"
"488.19600","40.68319","0.00022"
"488.62200","40.71870","-0.00020"
"489.04800","40.75416","0.00145"
"489.47400","40.78962","-0.00003"
"489.90000","40.82513","0.00072"
"490.32600","40.86065","0.00069"
"490.75200","40.89622","-0.00007"
"491.17800","40.93167","0.00185"
"491.60400","40.96719","0.00023"
"492.03000","41.00265","0.00075"
"492.45600","41.03822","0.00135"
"492.88200","41.07373","0.00060"
"493.30800","41.10919","0.00158"
"493.73400","41.14459","0.00065"
"494.16000","41.18016","0.00166"
"494.58600","41.21568","0.00132"
"495.01200","41.25125","0.00151"
"495.43800","41.28671","0.00185"
"495.86400","41.32215","0.00122"
"496.29000","41.35767","0.00210"
"496.71600","41.39325","0.00181"
"497.14200","41.42877","0.00197"
"497.56800","41.46422","0.00176"
"497.99400","41.49968","0.00173"
"498.42000","41.53525","0.00237"
"498.84600","41.57071","0.00206"
"499.27200","41.60622","0.00221"
"499.69800","41.64174","0.00239"
"500.12400","41.67713","0.00218"
"500.55000","41.71270","0.00276"
"500.97600","41.74822","0.00260"
"501.40200","41.78373","0.00238"
"501.82800","41.81913","0.00285"
"502.25400","41.85459","0.00266"
"502.68000","41.89016","0.00238"
"503.10600","41.92567","0.00241"
"503.53200","41.96119","0.00240"
"503.95800","41.99665","0.00212"
"504.38400","42.03216","0.00211"
"504.81000","42.06768","0.00245"
"505.23600","42.10320","0.00233"
"505.66200","42.13877","0.00217"
"506.08800","42.17416","0.00187"
"506.51400","42.20968","0.00201"
"506.94000","42.24519","0.00192"
"507.36600","42.28071","0.00203"
"507.79200","42.31616","0.00189"
"508.21800","42.35162","0.00167"
"508.64400","42.38719","0.00167"
"509.07000","42.42271","0.00232"
"509.49600","42.45822","0.00142"
"509.92200","42.49368","0.00213"
"510.34800","42.52919","0.00270"
"510.77400","42.56470","0.00239"
"511.20000","42.60028","0.00226"
"511.62600","42.63574","0.00225"
"512.05200","42.67119","0.00188"
"512.47800","42.70665","0.00200"
"512.90400","42.74222","0.00152"
"513.33000","42.77768","0.00187"
"513.75600","42.81319","0.00162"
"514.18200","42.84870","0.00195"
"514.60800","42.88416","0.00185"
"515.03400","42.91967","0.00157"
"515.46000","42.95519","0.00199"
"515.88600","42.99071","0.00177"
"516.31200","43.02610","0.00243"
"516.73800","43.06162","0.00207"
"517.16400","43.09719","0.00243"
"517.59000","43.13271","0.00246"
"518.01600","43.16816","0.00233"
"518.44200","43.20361","0.00202"
"518.86800","43.23919","0.00236"
"519.29400","43.27471","0.00239"
"519.72000","43.31023","0.00237"
"520.14600","43.34562","0.00241"
"520.57200","43.38113","0.00229"
"520.99800","43.41671","0.00222"
"521.42400","43.45222","0.00297"
"521.85000","43.48768","0.00278"
"522.27600","43.52319","0.00246"
"522.70200","43.55870","0.00258"
"523.12800","43.59422","0.00260"
"523.55400","43.62974","0.00294"
"523.98000","43.66519","0.00263"
"524.40600","43.70071","0.00214"
"524.83200","43.73610","0.00234"
"525.25800","43.77168","0.00206"
"525.68400","43.80725","0.00125"
"526.11000","43.84271","0.00173"
"526.53600","43.87816","0.00137"
"526.96200","43.91368","0.00129"
"527.38800","43.94925","0.00149"
"527.81400","43.98471","0.00148"
"528.24000","44.02016","0.00170"
"528.66600","44.05568","0.00206"
"529.09200","44.09119","0.00164"
"529.51800","44.12671","0.00107"
"529.94400","44.16222","0.00106"
"530.37000","44.19762","0.00101"
"530.79600","44.23313","0.00125"
"531.22200","44.26865","0.00110"
"531.64800","44.30416","0.00125"
"532.07400","44.33968","0.00154"
"532.50000","44.37514","0.00144"
"532.92600","44.41071","0.00179"
"533.35200","44.44616","0.00186"
"533.77800","44.48174","0.00228"
"534.20400","44.51720","0.00175"
"534.63000","44.55271","0.00171"
"535.05600","44.58817","0.00192"
"535.48200","44.62368","0.00233"
"535.90800","44.65919","0.00209"
"536.33400","44.69471","0.00219"
"536.76000","44.73011","0.00152"
"537.18600","44.76568","0.00100"
"537.61200","44.80119","0.00078"
"538.03800","44.83671","0.00083"
"538.46400","44.87222","0.00104"
"538.89000","44.90768","0.00085"
"539.31600","44.94325","0.00058"
"539.74200","44.97877","0.00097"
"540.16800","45.01429","0.00078"
"540.59400","45.04968","0.00121"
"541.02000","45.08519","0.00107"
"541.44600","45.12071","0.00118"
"541.87200","45.15622","0.00102"
"542.29800","45.19168","0.00130"
"542.72400","45.22719","0.00132"
"543.15000","45.26259","0.00167"
"543.57600","45.29817","0.00151"
"544.00200","45.33368","0.00122"
"544.42800","45.36920","0.00179"
"544.85400","45.40465","0.00177"
"545.28000","45.44016","0.00181"
"545.70600","45.47574","0.00130"
"546.13200","45.51120","0.00115"
"546.55800","45.54665","0.00096"
"546.98400","45.58211","0.00105"
"547.41000","45.61768","0.00127"
"547.83600","45.65319","0.00134"
"548.26200","45.68865","0.00097"
"548.68800","45.72423","0.00085"
"549.11400","45.75962","0.00157"
"549.54000","45.79520","0.00172"
"549.96600","45.83071","0.00144"
"550.39200","45.86623","0.00072"
"550.81800","45.90168","0.00065"
"551.24400","45.93719","0.00098"
"551.67000","45.97271","0.00080"
"552.09600","46.00822","0.00092"
"552.52200","46.04374","0.00083"
"552.94800","46.07920","0.00121"
"553.37400","46.11471","0.00056"
"553.80000","46.15022","0.00102"
"554.22600","46.18574","0.00107"
"554.65200","46.22120","0.00090"
"555.07800","46.25665","0.00081"
"555.50400","46.29217","0.00086"
"555.93000","46.32767","0.00111"
"556.35600","46.36320","0.00137"
"556.78200","46.39871","0.00136"
"557.20800","46.43411","0.00096"
"557.63400","46.46968","0.00119"
"558.06000","46.50520","0.00156"
"558.48600","46.54071","0.00136"
"558.91200","46.57617","0.00136"
"559.33800","46.61162","0.00123"
"559.76400","46.64714","0.00084"
"560.19000","46.68271","0.00102"
"560.61600","46.71823","0.00106"
"561.04200","46.75368","0.00115"
"561.46800","46.78920","0.00114"
"561.89400","46.82471","0.00097"
"562.32000","46.86023","0.00093"
"562.74600","46.89574","0.00110"
"563.17200","46.93113","0.00094"
"563.59800","46.96665","0.00070"
"564.02400","47.00217","0.00052"
"564.45000","47.03768","0.00060"
"564.87600","47.07320","0.00119"
"565.30200","47.10865","0.00123"
"565.72800","47.14422","0.00116"
"566.15400","47.17974","0.00092"
"566.58000","47.21519","0.00083"
"567.00600","47.25077","0.00087"
"567.43200","47.28617","0.00098"
"567.85800","47.32169","0.00133"
"568.28400","47.35719","0.00125"
"568.71000","47.39272","0.00158"
"569.13600","47.42817","0.00163"
"569.56200","47.46362","0.00147"
"569.98800","47.49920","0.00163"
"570.41400","47.53471","0.00179"
"570.84000","47.57022","0.00115"
"571.26600","47.60568","0.00180"
"571.69200","47.64120","0.00108"
"572.11800","47.67665","0.00017"
"572.54400","47.71223","0.00017"
"572.97000","47.74768","-0.00009"
"573.39600","47.78314","0.00029"
"573.82200","47.81871","0.00034"
"574.24800","47.85423","0.00025"
"574.67400","47.88968","0.00027"
"575.10000","47.92520","0.00036"
"575.52600","47.96066","0.00008"
"575.95200","47.99617","0.00008"
"576.37800","48.03168","0.00019"
"576.80400","48.06726","-0.00008"
"577.23000","48.10271","0.00040"
"577.65600","48.13816","0.00001"
"578.08200","48.17368","0.00049"
"578.50800","48.20920","0.00058"
"578.93400","48.24477","0.00095"
"579.36000","48.28023","0.00030"
"579.78600","48.31568","0.00041"
"580.21200","48.35120","0.00096"
"580.63800","48.38671","0.00065"
"581.06400","48.42223","0.00040"
"581.49000","48.45768","0.00039"
"581.91600","48.49314","0.00055"
"582.34200","48.52872","0.00074"
"582.76800","48.56422","0.00042"
"583.19400","48.59975","0.00064"
"583.62000","48.63514","0.00052"
"584.04600","48.67071","0.00028"
"584.47200","48.70617","0.00061"
"584.89800","48.74168","0.00063"
"585.32400","48.77720","0.00029"
"585.75000","48.81265","0.00055"
"586.17600","48.84811","0.00057"
"586.60200","48.88374","0.00063"
"587.02800","48.91920","0.00047"
"587.45400","48.95471","0.00072"
"587.88000","48.99011","0.00074"
"588.30600","49.02562","0.00117"
"588.73200","49.06120","0.00094"
"589.15800","49.09671","0.00110"
"589.58400","49.13217","0.00075"
"590.01000","49.16769","0.00065"
"590.43600","49.20320","0.00072"
"590.86200","49.23871","0.00060"
"591.28800","49.27417","0.00084"
"591.71400","49.30968","0.00058"
"592.14000","49.34520","0.00058"
"592.56600","49.38071","0.00102"
"592.99200","49.41616","0.00037"
"593.41800","49.45174","0.00061"
"593.84400","49.48720","0.00045"
"594.27000","49.52271","0.00018"
"594.69600","49.55823","0.00112"
"595.12200","49.59375","0.00077"
"595.54800","49.62926","0.00076"
"595.97400","49.66466","0.00079"
"596.40000","49.70017","0.00078"
"596.82600","49.73568","0.00080"
"597.25200","49.77120","0.00101"
"597.67800","49.80665","0.00108"
"598.10400","49.84217","0.00097"
"598.53000","49.87769","0.00093"
"598.95600","49.91320","0.00083"
"599.38200","49.94865","0.00134"
"599.80800","49.98417","0.00130"
"600.23400","50.01962","0.00088"
"600.66000","50.05520","0.00066"
"601.08600","50.09071","0.00095"
"601.51200","50.12617","0.00051"
"601.93800","50.16169","0.00083"
"602.36400","50.19714","0.00112"
"602.79000","50.23271","0.00085"
"603.21600","50.26823","0.00068"
"603.64200","50.30375","0.00084"
"604.06800","50.33914","0.00071"
"604.49400","50.37466","0.00081"
"604.92000","50.41022","0.00086"
"605.34600","50.44568","0.00082"
"605.77200","50.48126","0.00084"
"606.19800","50.51665","0.00081"
"606.62400","50.55211","0.00082"
"607.05000","50.58769","0.00072"
"607.47600","50.62326","0.00109"
"607.90200","50.65871","0.00096"
"608.32800","50.69417","0.00122"
"608.75400","50.72974","0.00102"
"609.18000","50.76520","0.00117"
"609.60600","50.80078","-0.00103"
"610.03200","50.83617","-0.00092"
"610.45800","50.87163","-0.00099"
"610.88400","50.90720","-0.00081"
"611.31000","50.94271","-0.00081"
"611.73600","50.97823","-0.00069"
"612.16200","51.01368","-0.00026"
"612.58800","51.04908","-0.00066"
"613.01400","51.08465","-0.00076"
"613.44000","51.12017","-0.00093"
"613.86600","51.15574","-0.00097"
"614.29200","51.19114","-0.00059"
"614.71800","51.22665","-0.00100"
"615.14400","51.26217","-0.00061"
"615.57000","51.29769","-0.00043"
"615.99600","51.33320","-0.00039"
"616.42200","51.36866","-0.00134"
"616.84800","51.40417","-0.00095"
"617.27400","51.43968","-0.00081"
"617.70000","51.47520","-0.00040"
"618.12600","51.51072","-0.00069"
"618.55200","51.54617","-0.00100"
"618.97800","51.58169","-0.00038"
"619.40400","51.61720","-0.00074"
"619.83000","51.65271","-0.00077"
"620.25600","51.68823","-0.00048"
"620.68200","51.72369","-0.00077"
"621.10800","51.75920","-0.00068"
"621.53400","51.79472","-0.00047"
"621.96000","51.83017","-0.00069"
"622.38600","51.86569","-0.00096"
"622.81200","51.90120","-0.00064"
"623.23800","51.93671","-0.00045"
"623.66400","51.97217","-0.00082"
"624.09000","52.00769","-0.00077"
"624.51600","52.04314","-0.00043"
"624.94200","52.07866","-0.00104"
"625.36800","52.11423","-0.00030"
"625.79400","52.14969","-0.00038"
"626.22000","52.18520","-0.00039"
"626.64600","52.22060","-0.00090"
"627.07200","52.25618","-0.00049"
"627.49800","52.29168","-0.00077"
"627.92400","52.32720","-0.00080"
"628.35000","52.36266","-0.00069"
"628.77600","52.39817","-0.00106"
"629.20200","52.43363","-0.00041"
"629.62800","52.46926","-0.00010"
"630.05400","52.50472","-0.00075"
"630.48000","52.54017","-0.00046"
"630.90600","52.57569","-0.00062"
"631.33200","52.61120","-0.00031"
"631.75800","52.64672","-0.00080"
"632.18400","52.68217","-0.00043"
"632.61000","52.71769","-0.00034"
"633.03600","52.75314","-0.00045"
"633.46200","52.78872","-0.00048"
"633.88800","52.82423","-0.00014"
"634.31400","52.85975","-0.00015"
"634.74000","52.89514","-0.00040"
"634.92200","52.91039","-0.00073"