File: Force_trajectories/161223/Specimen_RawData_10.csv
End date,"12/23/2016"
Specimen label,"17BC_36"
Maximum Load,"1.60068",N

Time,Extension,Load
(s),(mm),(N)
"0.00000","0.00000","-0.00063"
"0.22800","0.01710","0.00000"
"0.45600","0.03833","0.00076"
"0.68400","0.05722","0.00192"
"0.91200","0.07629","0.00198"
"1.14000","0.09524","0.00199"
"1.36800","0.11426","0.00290"
"1.59600","0.13321","0.00361"
"1.82400","0.15222","0.00346"
"2.05200","0.17124","0.00433"
"2.28000","0.19019","0.00497"
"2.50800","0.20920","0.00527"
"2.73600","0.22822","0.00566"
"2.96400","0.24723","0.00603"
"3.19200","0.26618","0.00677"
"3.42000","0.28526","0.00703"
"3.64800","0.30427","0.00748"
"3.87600","0.32322","0.00787"
"4.10400","0.34218","0.00853"
"4.33200","0.36119","0.00843"
"4.56000","0.38026","0.00943"
"4.78800","0.39915","0.00958"
"5.01600","0.41823","0.00954"
"5.24400","0.43718","0.00985"
"5.47200","0.45613","0.01052"
"5.70000","0.47521","0.01060"
"5.92800","0.49416","0.01130"
"6.15600","0.51323","0.01180"
"6.38400","0.53219","0.01148"
"6.61200","0.55126","0.01262"
"6.84000","0.57021","0.01247"
"7.06800","0.58917","0.01294"
"7.29600","0.60824","0.01311"
"7.52400","0.62719","0.01363"
"7.75200","0.64627","0.01370"
"7.98000","0.66522","0.01369"
"8.20800","0.68417","0.01424"
"8.43600","0.70324","0.01467"
"8.66400","0.72220","0.01530"
"8.89200","0.74121","0.01533"
"9.12000","0.76016","0.01553"
"9.34800","0.77924","0.01603"
"9.57600","0.79825","0.01505"
"9.80400","0.81720","0.01591"
"10.03200","0.83628","0.01596"
"10.26000","0.85523","0.01627"
"10.48800","0.87430","0.01700"
"10.71600","0.89320","0.01682"
"10.94400","0.91221","0.01699"
"11.17200","0.93122","0.01750"
"11.40000","0.95018","0.01815"
"11.62800","0.96925","0.01861"
"11.85600","0.98820","0.01761"
"12.08400","1.00727","0.01760"
"12.31200","1.02623","0.01780"
"12.54000","1.04518","0.01775"
"12.76800","1.06425","0.01823"
"12.99600","1.08315","0.01875"
"13.22400","1.10228","0.01848"
"13.45200","1.12117","0.01904"
"13.68000","1.14025","0.01997"
"13.90800","1.15920","0.02014"
"14.13600","1.17821","0.02021"
"14.36400","1.19723","0.02043"
"14.59200","1.21618","0.02115"
"14.82000","1.23525","0.01920"
"15.04800","1.25420","0.01943"
"15.27600","1.27322","0.01964"
"15.50400","1.29229","0.01995"
"15.73200","1.31118","0.02048"
"15.96000","1.33020","0.02066"
"16.18800","1.34915","0.02140"
"16.41600","1.36828","0.02166"
"16.64400","1.38724","0.02225"
"16.87200","1.40619","0.02169"
"17.10000","1.42526","0.02057"
"17.32800","1.44416","0.02040"
"17.55600","1.46323","0.02100"
"17.78400","1.48224","0.02187"
"18.01200","1.50126","0.02185"
"18.24000","1.52027","0.02228"
"18.46800","1.53922","0.02275"
"18.69600","1.55823","0.02331"
"18.92400","1.57719","0.02312"
"19.15200","1.59620","0.02373"
"19.38000","1.61521","0.02427"
"19.60800","1.63423","0.02492"
"19.83600","1.65324","0.02545"
"20.06400","1.67219","0.02497"
"20.29200","1.69121","0.02562"
"20.52000","1.71022","0.02541"
"20.74800","1.72923","0.02615"
"20.97600","1.74819","0.02663"
"21.20400","1.76720","0.02621"
"21.43200","1.78621","0.02713"
"21.66000","1.80517","0.02785"
"21.88800","1.82424","0.02769"
"22.11600","1.84319","0.02846"
"22.34400","1.86220","0.02873"
"22.57200","1.88116","0.02894"
"22.80000","1.90023","0.02931"
"23.02800","1.91924","0.02914"
"23.25600","1.93820","0.02933"
"23.48400","1.95721","0.02989"
"23.71200","1.97616","0.03008"
"23.94000","1.99524","0.03053"
"24.16800","2.01425","0.03047"
"24.39600","2.03326","0.03112"
"24.62400","2.05222","0.03127"
"24.85200","2.07117","0.03158"
"25.08000","2.09024","0.03225"
"25.30800","2.10920","0.03241"
"25.53600","2.12821","0.03291"
"25.76400","2.14716","0.03306"
"25.99200","2.16623","0.03307"
"26.22000","2.18525","0.03346"
"26.44800","2.20414","0.03391"
"26.67600","2.22327","0.03394"
"26.90400","2.24217","0.03430"
"27.13200","2.26124","0.03471"
"27.36000","2.28019","0.03423"
"27.58800","2.29921","0.03472"
"27.81600","2.31822","0.03556"
"28.04400","2.33717","0.03547"
"28.27200","2.35631","0.03595"
"28.50000","2.37520","0.03629"
"28.72800","2.39421","0.03667"
"28.95600","2.41323","0.03717"
"29.18400","2.43224","0.03750"
"29.41200","2.45125","0.03761"
"29.64000","2.47020","0.03791"
"29.86800","2.48928","0.03762"
"30.09600","2.50823","0.03859"
"30.32400","2.52718","0.03891"
"30.55200","2.54626","0.03924"
"30.78000","2.56515","0.03981"
"31.00800","2.58422","0.04065"
"31.23600","2.60318","0.04061"
"31.46400","2.62225","0.04059"
"31.69200","2.64126","0.04119"
"31.92000","2.66016","0.04185"
"32.14800","2.67923","0.04226"
"32.37600","2.69818","0.04262"
"32.60400","2.71725","0.04267"
"32.83200","2.73621","0.04372"
"33.06000","2.75522","0.04402"
"33.28800","2.77423","0.04444"
"33.51600","2.79313","0.04475"
"33.74400","2.81226","0.04535"
"33.97200","2.83115","0.04577"
"34.20000","2.85023","0.04606"
"34.42800","2.86918","0.04679"
"34.65600","2.88819","0.04761"
"34.88400","2.90733","0.04811"
"35.11200","2.92616","0.04840"
"35.34000","2.94523","0.04889"
"35.56800","2.96425","0.05024"
"35.79600","2.98320","0.04932"
"36.02400","3.00227","0.05088"
"36.25200","3.02117","0.05114"
"36.48000","3.04024","0.05103"
"36.70800","3.05919","0.05177"
"36.93600","3.07820","0.05255"
"37.16400","3.09722","0.05259"
"37.39200","3.11623","0.05255"
"37.62000","3.13524","0.05338"
"37.84800","3.15420","0.05384"
"38.07600","3.17327","0.05423"
"38.30400","3.19222","0.05457"
"38.53200","3.21118","0.05452"
"38.76000","3.23019","0.05491"
"38.98800","3.24920","0.05584"
"39.21600","3.26822","0.05621"
"39.44400","3.28723","0.05624"
"39.67200","3.30624","0.05699"
"39.90000","3.32520","0.05729"
"40.12800","3.34421","0.05683"
"40.35600","3.36322","0.05778"
"40.58400","3.38223","0.05774"
"40.81200","3.40125","0.05826"
"41.04000","3.42020","0.05814"
"41.26800","3.43921","0.05847"
"41.49600","3.45817","0.05922"
"41.72400","3.47724","0.05903"
"41.95200","3.49619","0.05950"
"42.18000","3.51521","0.06005"
"42.40800","3.53428","0.06031"
"42.63600","3.55317","0.06052"
"42.86400","3.57225","0.06073"
"43.09200","3.59114","0.06130"
"43.32000","3.61027","0.06102"
"43.54800","3.62916","0.06142"
"43.77600","3.64818","0.06167"
"44.00400","3.66725","0.06210"
"44.23200","3.68620","0.06237"
"44.46000","3.70522","0.06250"
"44.68800","3.72417","0.06305"
"44.91600","3.74324","0.06377"
"45.14400","3.76226","0.06390"
"45.37200","3.78121","0.06432"
"45.60000","3.80022","0.06466"
"45.82800","3.81918","0.06545"
"46.05600","3.83825","0.06590"
"46.28400","3.85720","0.06646"
"46.51200","3.87622","0.06617"
"46.74000","3.89523","0.06670"
"46.96800","3.91418","0.06854"
"47.19600","3.93325","0.06872"
"47.42400","3.95215","0.06949"
"47.65200","3.97128","0.06993"
"47.88000","3.99017","0.07020"
"48.10800","4.00919","0.07077"
"48.33600","4.02820","0.07195"
"48.56400","4.04715","0.07235"
"48.79200","4.06629","0.07249"
"49.02000","4.08518","0.07358"
"49.24800","4.10425","0.07460"
"49.47600","4.12321","0.07506"
"49.70400","4.14222","0.07550"
"49.93200","4.16123","0.07482"
"50.16000","4.18018","0.07537"
"50.38800","4.19920","0.07565"
"50.61600","4.21815","0.07596"
"50.84400","4.23728","0.07768"
"51.07200","4.25624","0.07751"
"51.30000","4.27513","0.07849"
"51.52800","4.29426","0.07864"
"51.75600","4.31316","0.07928"
"51.98400","4.33223","0.07975"
"52.21200","4.35118","0.08040"
"52.44000","4.37026","0.08054"
"52.66800","4.38927","0.08050"
"52.89600","4.40816","0.08129"
"53.12400","4.42724","0.08190"
"53.35200","4.44619","0.08199"
"53.58000","4.46526","0.08216"
"53.80800","4.48416","0.08245"
"54.03600","4.50323","0.08306"
"54.26400","4.52224","0.08343"
"54.49200","4.54119","0.08376"
"54.72000","4.56021","0.08406"
"54.94800","4.57922","0.08399"
"55.17600","4.59823","0.08434"
"55.40400","4.61725","0.08491"
"55.63200","4.63620","0.08511"
"55.86000","4.65521","0.08565"
"56.08800","4.67417","0.08576"
"56.31600","4.69324","0.08588"
"56.54400","4.71225","0.08585"
"56.77200","4.73121","0.08672"
"57.00000","4.75022","0.08680"
"57.22800","4.76923","0.08697"
"57.45600","4.78824","0.08747"
"57.68400","4.80714","0.08761"
"57.91200","4.82627","0.08789"
"58.14000","4.84516","0.08784"
"58.36800","4.86424","0.08838"
"58.59600","4.88319","0.08863"
"58.82400","4.90220","0.08906"
"59.05200","4.92122","0.08915"
"59.28000","4.94023","0.08938"
"59.50800","4.95924","0.09032"
"59.73600","4.97820","0.09027"
"59.96400","4.99721","0.09074"
"60.19200","5.01622","0.09100"
"60.42000","5.03524","0.09142"
"60.64800","5.05419","0.09154"
"60.87600","5.07314","0.09235"
"61.10400","5.09221","0.09228"
"61.33200","5.11123","0.09264"
"61.56000","5.13024","0.09292"
"61.78800","5.14919","0.09338"
"62.01600","5.16821","0.09359"
"62.24400","5.18722","0.09373"
"62.47200","5.20617","0.09425"
"62.70000","5.22525","0.09492"
"62.92800","5.24420","0.09489"
"63.15600","5.26327","0.09509"
"63.38400","5.28223","0.09557"
"63.61200","5.30118","0.09633"
"63.84000","5.32025","0.09653"
"64.06800","5.33921","0.09714"
"64.29600","5.35834","0.09694"
"64.52400","5.37717","0.09761"
"64.75200","5.39618","0.09811"
"64.98000","5.41526","0.09842"
"65.20800","5.43421","0.09885"
"65.43600","5.45322","0.09873"
"65.66400","5.47218","0.09988"
"65.89200","5.49125","0.10021"
"66.12000","5.51020","0.09995"
"66.34800","5.52922","0.10093"
"66.57600","5.54823","0.10127"
"66.80400","5.56712","0.10199"
"67.03200","5.58626","0.10238"
"67.26000","5.60515","0.10230"
"67.48800","5.62422","0.10368"
"67.71600","5.64324","0.10381"
"67.94400","5.66219","0.10386"
"68.17200","5.68126","0.10521"
"68.40000","5.70021","0.10522"
"68.62800","5.71923","0.10531"
"68.85600","5.73818","0.10634"
"69.08400","5.75719","0.10606"
"69.31200","5.77627","0.10673"
"69.54000","5.79516","0.10733"
"69.76800","5.81423","0.10767"
"69.99600","5.83319","0.10838"
"70.22400","5.85220","0.10902"
"70.45200","5.87121","0.10843"
"70.68000","5.89023","0.10914"
"70.90800","5.90924","0.10993"
"71.13600","5.92813","0.11009"
"71.36400","5.94720","0.11020"
"71.59200","5.96622","0.11103"
"71.82000","5.98523","0.11134"
"72.04800","6.00424","0.11184"
"72.27600","6.02320","0.11231"
"72.50400","6.04221","0.11259"
"72.73200","6.06122","0.11345"
"72.96000","6.08024","0.11434"
"73.18800","6.09919","0.11512"
"73.41600","6.11820","0.11593"
"73.64400","6.13716","0.11667"
"73.87200","6.15623","0.11696"
"74.10000","6.17524","0.11760"
"74.32800","6.19420","0.11870"
"74.55600","6.21321","0.11950"
"74.78400","6.23222","0.12018"
"75.01200","6.25124","0.12063"
"75.24000","6.27019","0.12093"
"75.46800","6.28920","0.12218"
"75.69600","6.30821","0.12319"
"75.92400","6.32723","0.12426"
"76.15200","6.34618","0.12558"
"76.38000","6.36525","0.12545"
"76.60800","6.38421","0.12644"
"76.83600","6.40322","0.12819"
"77.06400","6.42223","0.12893"
"77.29200","6.44119","0.12996"
"77.52000","6.46020","0.13037"
"77.74800","6.47921","0.13191"
"77.97600","6.49823","0.13198"
"78.20400","6.51718","0.13361"
"78.43200","6.53625","0.13395"
"78.66000","6.55520","0.13511"
"78.88800","6.57422","0.13583"
"79.11600","6.59317","0.13622"
"79.34400","6.61224","0.13711"
"79.57200","6.63120","0.13758"
"79.80000","6.65021","0.13811"
"80.02800","6.66922","0.13916"
"80.25600","6.68818","0.13979"
"80.48400","6.70725","0.14085"
"80.71200","6.72620","0.14107"
"80.94000","6.74522","0.14161"
"81.16800","6.76423","0.14222"
"81.39600","6.78318","0.14286"
"81.62400","6.80220","0.14319"
"81.85200","6.82115","0.14413"
"82.08000","6.84028","0.14484"
"82.30800","6.85917","0.14521"
"82.53600","6.87819","0.14630"
"82.76400","6.89726","0.14673"
"82.99200","6.91615","0.14788"
"83.22000","6.93529","0.14879"
"83.44800","6.95418","0.14892"
"83.67600","6.97325","0.15045"
"83.90400","6.99215","0.15048"
"84.13200","7.01122","0.15123"
"84.36000","7.03023","0.15275"
"84.58800","7.04919","0.15345"
"84.81600","7.06826","0.15370"
"85.04400","7.08721","0.15494"
"85.27200","7.10623","0.15560"
"85.50000","7.12524","0.15668"
"85.72800","7.14419","0.15715"
"85.95600","7.16326","0.15802"
"86.18400","7.18216","0.15978"
"86.41200","7.20117","0.15965"
"86.64000","7.22018","0.16093"
"86.86800","7.23920","0.16083"
"87.09600","7.25827","0.16277"
"87.32400","7.27716","0.16308"
"87.55200","7.29630","0.16341"
"87.78000","7.31513","0.16374"
"88.00800","7.33420","0.16425"
"88.23600","7.35328","0.16496"
"88.46400","7.37223","0.16542"
"88.69200","7.39124","0.16578"
"88.92000","7.41014","0.16647"
"89.14800","7.42921","0.16714"
"89.37600","7.44822","0.16775"
"89.60400","7.46717","0.16866"
"89.83200","7.48619","0.16909"
"90.06000","7.50520","0.17019"
"90.28800","7.52421","0.17020"
"90.51600","7.54317","0.17114"
"90.74400","7.56218","0.17201"
"90.97200","7.58119","0.17270"
"91.20000","7.60021","0.17361"
"91.42800","7.61922","0.17235"
"91.65600","7.63817","0.17354"
"91.88400","7.65725","0.17438"
"92.11200","7.67620","0.17524"
"92.34000","7.69521","0.17612"
"92.56800","7.71422","0.17685"
"92.79600","7.73324","0.17776"
"93.02400","7.75225","0.17868"
"93.25200","7.77120","0.17952"
"93.48000","7.79028","0.17987"
"93.70800","7.80911","0.18051"
"93.93600","7.82824","0.18159"
"94.16400","7.84720","0.18258"
"94.39200","7.86621","0.18282"
"94.62000","7.88522","0.18306"
"94.84800","7.90424","0.18505"
"95.07600","7.92325","0.18556"
"95.30400","7.94220","0.18567"
"95.53200","7.96122","0.18650"
"95.76000","7.98017","0.18705"
"95.98800","7.99924","0.18775"
"96.21600","8.01825","0.18813"
"96.44400","8.03721","0.18935"
"96.67200","8.05622","0.18970"
"96.90000","8.07517","0.19012"
"97.12800","8.09425","0.19138"
"97.35600","8.11320","0.19170"
"97.58400","8.13221","0.19288"
"97.81200","8.15123","0.19381"
"98.04000","8.17018","0.19424"
"98.26800","8.18925","0.19485"
"98.49600","8.20821","0.19637"
"98.72400","8.22728","0.19690"
"98.95200","8.24617","0.19715"
"99.18000","8.26519","0.19798"
"99.40800","8.28420","0.19879"
"99.63600","8.30321","0.19941"
"99.86400","8.32228","0.19923"
"100.09200","8.34118","0.20001"
"100.32000","8.36025","0.20014"
"100.54800","8.37920","0.20047"
"100.77600","8.39816","0.20102"
"101.00400","8.41723","0.20144"
"101.23200","8.43618","0.20173"
"101.46000","8.45520","0.20242"
"101.68800","8.47421","0.20338"
"101.91600","8.49322","0.20370"
"102.14400","8.51224","0.20413"
"102.37200","8.53113","0.20465"
"102.60000","8.55026","0.20575"
"102.82800","8.56922","0.20624"
"103.05600","8.58829","0.20770"
"103.28400","8.60718","0.20783"
"103.51200","8.62619","0.20864"
"103.74000","8.64527","0.20990"
"103.96800","8.66416","0.21004"
"104.19600","8.68323","0.21106"
"104.42400","8.70219","0.21171"
"104.65200","8.72126","0.21233"
"104.88000","8.74027","0.21318"
"105.10800","8.75917","0.21373"
"105.33600","8.77830","0.21439"
"105.56400","8.79713","0.21508"
"105.79200","8.81627","0.21603"
"106.02000","8.83522","0.21712"
"106.24800","8.85423","0.21775"
"106.47600","8.87324","0.21873"
"106.70400","8.89220","0.21930"
"106.93200","8.91127","0.21994"
"107.16000","8.93016","0.22080"
"107.38800","8.94924","0.22196"
"107.61600","8.96819","0.22291"
"107.84400","8.98720","0.22322"
"108.07200","9.00622","0.22449"
"108.30000","9.02517","0.22527"
"108.52800","9.04424","0.22622"
"108.75600","9.06320","0.22707"
"108.98400","9.08227","0.22782"
"109.21200","9.10116","0.22911"
"109.44000","9.12024","0.23068"
"109.66800","9.13919","0.23183"
"109.89600","9.15820","0.23295"
"110.12400","9.17722","0.23395"
"110.35200","9.19617","0.23385"
"110.58000","9.21524","0.23211"
"110.80800","9.23419","0.23390"
"111.03600","9.25321","0.23472"
"111.26400","9.27222","0.23594"
"111.49200","9.29123","0.23689"
"111.72000","9.31025","0.23751"
"111.94800","9.32914","0.23840"
"112.17600","9.34821","0.23964"
"112.40400","9.36723","0.24056"
"112.63200","9.38624","0.24210"
"112.86000","9.40525","0.24259"
"113.08800","9.42421","0.24402"
"113.31600","9.44322","0.24500"
"113.54400","9.46217","0.24646"
"113.77200","9.48125","0.24788"
"114.00000","9.50020","0.24972"
"114.22800","9.51915","0.24945"
"114.45600","9.53822","0.25105"
"114.68400","9.55718","0.25199"
"114.91200","9.57619","0.25356"
"115.14000","9.59520","0.25508"
"115.36800","9.61428","0.25600"
"115.59600","9.63323","0.25771"
"115.82400","9.65224","0.25806"
"116.05200","9.67120","0.26003"
"116.28000","9.69015","0.26029"
"116.50800","9.70922","0.26131"
"116.73600","9.72818","0.26223"
"116.96400","9.74719","0.26275"
"117.19200","9.76626","0.26395"
"117.42000","9.78521","0.26485"
"117.64800","9.80423","0.26638"
"117.87600","9.82318","0.26743"
"118.10400","9.84225","0.26845"
"118.33200","9.86121","0.26975"
"118.56000","9.88022","0.27113"
"118.78800","9.89923","0.27262"
"119.01600","9.91819","0.27521"
"119.24400","9.93732","0.27651"
"119.47200","9.95615","0.27888"
"119.70000","9.97522","0.28065"
"119.92800","9.99424","0.28294"
"120.15600","10.01319","0.28471"
"120.38400","10.03226","0.28633"
"120.61200","10.05116","0.28637"
"120.84000","10.07023","0.28888"
"121.06800","10.08918","0.29001"
"121.29600","10.10820","0.29121"
"121.52400","10.12727","0.29218"
"121.75200","10.14622","0.29265"
"121.98000","10.16524","0.29406"
"122.20800","10.18419","0.29466"
"122.43600","10.20320","0.29535"
"122.66400","10.22222","0.29669"
"122.89200","10.24123","0.29765"
"123.12000","10.26024","0.29841"
"123.34800","10.27914","0.29903"
"123.57600","10.29821","0.29995"
"123.80400","10.31722","0.30078"
"124.03200","10.33624","0.30154"
"124.26000","10.35525","0.30249"
"124.48800","10.37420","0.30378"
"124.71600","10.39321","0.30427"
"124.94400","10.41211","0.30535"
"125.17200","10.43124","0.30569"
"125.40000","10.45019","0.30657"
"125.62800","10.46921","0.30776"
"125.85600","10.48822","0.30839"
"126.08400","10.50723","0.30900"
"126.31200","10.52625","0.30966"
"126.54000","10.54520","0.31044"
"126.76800","10.56421","0.31138"
"126.99600","10.58322","0.31046"
"127.22400","10.60218","0.31044"
"127.45200","10.62125","0.31158"
"127.68000","10.64020","0.31223"
"127.90800","10.65922","0.31366"
"128.13600","10.67817","0.31368"
"128.36400","10.69724","0.31477"
"128.59200","10.71626","0.31546"
"128.82000","10.73521","0.31639"
"129.04800","10.75422","0.31752"
"129.27600","10.77318","0.31827"
"129.50400","10.79225","0.31885"
"129.73200","10.81114","0.31806"
"129.96000","10.83022","0.31878"
"130.18800","10.84923","0.31920"
"130.41600","10.86818","0.32009"
"130.64400","10.88725","0.32071"
"130.87200","10.90621","0.32186"
"131.10000","10.92516","0.32337"
"131.32800","10.94418","0.32425"
"131.55600","10.96325","0.32576"
"131.78400","10.98220","0.32668"
"132.01200","11.00121","0.32849"
"132.24000","11.02023","0.32974"
"132.46800","11.03924","0.33119"
"132.69600","11.05819","0.33337"
"132.92400","11.07721","0.33505"
"133.15200","11.09622","0.33674"
"133.38000","11.11517","0.33829"
"133.60800","11.13419","0.31978"
"133.83600","11.15320","0.32091"
"134.06400","11.17221","0.32205"
"134.29200","11.19123","0.32351"
"134.52000","11.21018","0.32558"
"134.74800","11.22925","0.32666"
"134.97600","11.24826","0.32218"
"135.20400","11.26722","0.32256"
"135.43200","11.28623","0.31620"
"135.66000","11.30519","0.31670"
"135.88800","11.32432","0.31773"
"136.11600","11.34321","0.31890"
"136.34400","11.36222","0.31954"
"136.57200","11.38124","0.32113"
"136.80000","11.40013","0.32211"
"137.02800","11.41926","0.32383"
"137.25600","11.43822","0.32497"
"137.48400","11.45723","0.32770"
"137.71200","11.47618","0.32931"
"137.94000","11.49519","0.33091"
"138.16800","11.51427","0.33461"
"138.39600","11.53316","0.33719"
"138.62400","11.55229","0.33963"
"138.85200","11.57119","0.34092"
"139.08000","11.59026","0.34278"
"139.30800","11.60921","0.34399"
"139.53600","11.62817","0.34586"
"139.76400","11.64730","0.34767"
"139.99200","11.66613","0.34971"
"140.22000","11.68527","0.35114"
"140.44800","11.70422","0.35291"
"140.67600","11.72323","0.35472"
"140.90400","11.74225","0.35672"
"141.13200","11.76120","0.35850"
"141.36000","11.78027","0.35964"
"141.58800","11.79922","0.36178"
"141.81600","11.81830","0.36454"
"142.04400","11.83725","0.36627"
"142.27200","11.85620","0.36789"
"142.50000","11.87522","0.36920"
"142.72800","11.89417","0.37052"
"142.95600","11.91324","0.37195"
"143.18400","11.93214","0.37245"
"143.41200","11.95121","0.37337"
"143.64000","11.97028","0.37443"
"143.86800","11.98918","0.37539"
"144.09600","12.00825","0.37680"
"144.32400","12.02714","0.35912"
"144.55200","12.04622","0.35879"
"144.78000","12.06517","0.36053"
"145.00800","12.08430","0.36233"
"145.23600","12.10326","0.36397"
"145.46400","12.12221","0.36583"
"145.69200","12.14122","0.36727"
"145.92000","12.16023","0.36867"
"146.14800","12.17919","0.37064"
"146.37600","12.19820","0.37169"
"146.60400","12.21721","0.37261"
"146.83200","12.23623","0.37347"
"147.06000","12.25518","0.37525"
"147.28800","12.27425","0.37696"
"147.51600","12.29321","0.37831"
"147.74400","12.31222","0.38008"
"147.97200","12.33123","0.38152"
"148.20000","12.35018","0.38329"
"148.42800","12.36920","0.38539"
"148.65600","12.38821","0.38686"
"148.88400","12.40722","0.38785"
"149.11200","12.42624","0.38891"
"149.34000","12.44525","0.38993"
"149.56800","12.46420","0.39115"
"149.79600","12.48322","0.39286"
"150.02400","12.50223","0.39362"
"150.25200","12.52118","0.39407"
"150.48000","12.54020","0.39167"
"150.70800","12.55915","0.39309"
"150.93600","12.57822","0.39427"
"151.16400","12.59718","0.39537"
"151.39200","12.61625","0.39611"
"151.62000","12.63520","0.39725"
"151.84800","12.65421","0.39830"
"152.07600","12.67323","0.39928"
"152.30400","12.69218","0.40009"
"152.53200","12.71131","0.40100"
"152.76000","12.73021","0.40219"
"152.98800","12.74922","0.40299"
"153.21600","12.76824","0.40420"
"153.44400","12.78713","0.40575"
"153.67200","12.80632","0.40834"
"153.90000","12.82515","0.41001"
"154.12800","12.84423","0.41188"
"154.35600","12.86324","0.41377"
"154.58400","12.88219","0.41591"
"154.81200","12.90127","0.41716"
"155.04000","12.92016","0.41874"
"155.26800","12.93929","0.41984"
"155.49600","12.95819","0.42111"
"155.72400","12.97720","0.42228"
"155.95200","12.99621","0.42388"
"156.18000","13.01517","0.42543"
"156.40800","13.03424","0.42698"
"156.63600","13.05319","0.42863"
"156.86400","13.07220","0.42977"
"157.09200","13.09122","0.43062"
"157.32000","13.11017","0.43224"
"157.54800","13.12924","0.43345"
"157.77600","13.14814","0.43459"
"158.00400","13.16721","0.43627"
"158.23200","13.18622","0.43813"
"158.46000","13.20524","0.43953"
"158.68800","13.22425","0.44096"
"158.91600","13.24320","0.43675"
"159.14400","13.26221","0.43468"
"159.37200","13.28117","0.43585"
"159.60000","13.30024","0.43779"
"159.82800","13.31919","0.43974"
"160.05600","13.33821","0.44125"
"160.28400","13.35728","0.44258"
"160.51200","13.37623","0.44398"
"160.74000","13.39525","0.44556"
"160.96800","13.41414","0.44656"
"161.19600","13.43321","0.44768"
"161.42400","13.45223","0.44836"
"161.65200","13.47124","0.44999"
"161.88000","13.49019","0.45165"
"162.10800","13.50915","0.45338"
"162.33600","13.52828","0.45415"
"162.56400","13.54717","0.45575"
"162.79200","13.56625","0.45731"
"163.02000","13.58526","0.45990"
"163.24800","13.60421","0.46173"
"163.47600","13.62322","0.46288"
"163.70400","13.64218","0.46547"
"163.93200","13.66125","0.46732"
"164.16000","13.68020","0.46886"
"164.38800","13.69922","0.46988"
"164.61600","13.71823","0.47076"
"164.84400","13.73718","0.47272"
"165.07200","13.75626","0.47416"
"165.30000","13.77521","0.47581"
"165.52800","13.79422","0.47729"
"165.75600","13.81318","0.47927"
"165.98400","13.83219","0.48114"
"166.21200","13.85120","0.48340"
"166.44000","13.87022","0.48614"
"166.66800","13.88923","0.48799"
"166.89600","13.90824","0.49017"
"167.12400","13.92719","0.49181"
"167.35200","13.94621","0.49417"
"167.58000","13.96522","0.49589"
"167.80800","13.98417","0.49814"
"168.03600","14.00325","0.49986"
"168.26400","14.02220","0.50182"
"168.49200","14.04121","0.50353"
"168.72000","14.06023","0.50509"
"168.94800","14.07918","0.50593"
"169.17600","14.09825","0.50780"
"169.40400","14.11721","0.50873"
"169.63200","14.13622","0.50995"
"169.86000","14.15523","0.51081"
"170.08800","14.17418","0.51157"
"170.31600","14.19326","0.51286"
"170.54400","14.21221","0.51369"
"170.77200","14.23128","0.51468"
"171.00000","14.25024","0.51566"
"171.22800","14.26913","0.51725"
"171.45600","14.28826","0.51824"
"171.68400","14.30722","0.51891"
"171.91200","14.32629","0.52039"
"172.14000","14.34518","0.52160"
"172.36800","14.36420","0.52367"
"172.59600","14.38327","0.52503"
"172.82400","14.40216","0.52644"
"173.05200","14.42130","0.52771"
"173.28000","14.44019","0.52905"
"173.50800","14.45920","0.53055"
"173.73600","14.47822","0.53200"
"173.96400","14.49717","0.53336"
"174.19200","14.51624","0.53507"
"174.42000","14.53513","0.53811"
"174.64800","14.55427","0.53953"
"174.87600","14.57322","0.54058"
"175.10400","14.59223","0.54306"
"175.33200","14.61125","0.54449"
"175.56000","14.63020","0.54634"
"175.78800","14.64927","0.54760"
"176.01600","14.66817","0.54897"
"176.24400","14.68724","0.55114"
"176.47200","14.70619","0.55257"
"176.70000","14.72521","0.55469"
"176.92800","14.74422","0.55510"
"177.15600","14.76317","0.53817"
"177.38400","14.78225","0.54095"
"177.61200","14.80120","0.54433"
"177.84000","14.82027","0.54625"
"178.06800","14.83922","0.54769"
"178.29600","14.85824","0.54979"
"178.52400","14.87719","0.55297"
"178.75200","14.89614","0.55422"
"178.98000","14.91522","0.55549"
"179.20800","14.93423","0.55754"
"179.43600","14.95324","0.56049"
"179.66400","14.97226","0.56192"
"179.89200","14.99121","0.56378"
"180.12000","15.01022","0.56427"
"180.34800","15.02918","0.56663"
"180.57600","15.04825","0.54104"
"180.80400","15.06720","0.54233"
"181.03200","15.08622","0.54320"
"181.26000","15.10523","0.54473"
"181.48800","15.12418","0.54689"
"181.71600","15.14325","0.55003"
"181.94400","15.16221","0.55144"
"182.17200","15.18122","0.55335"
"182.40000","15.20023","0.55475"
"182.62800","15.21919","0.55880"
"182.85600","15.23826","0.56272"
"183.08400","15.25715","0.56694"
"183.31200","15.27623","0.57020"
"183.54000","15.29524","0.57264"
"183.76800","15.31419","0.57490"
"183.99600","15.33321","0.57644"
"184.22400","15.35222","0.57846"
"184.45200","15.37123","0.57992"
"184.68000","15.39025","0.58195"
"184.90800","15.40920","0.58326"
"185.13600","15.42821","0.58594"
"185.36400","15.44722","0.58894"
"185.59200","15.46618","0.59270"
"185.82000","15.48525","0.59578"
"186.04800","15.50426","0.59712"
"186.27600","15.52316","0.59910"
"186.50400","15.54223","0.60013"
"186.73200","15.56118","0.60280"
"186.96000","15.58026","0.60313"
"187.18800","15.59921","0.60507"
"187.41600","15.61822","0.60675"
"187.64400","15.63723","0.60825"
"187.87200","15.65619","0.60977"
"188.10000","15.67526","0.61062"
"188.32800","15.69421","0.61211"
"188.55600","15.71323","0.61361"
"188.78400","15.73218","0.61452"
"189.01200","15.75119","0.61532"
"189.24000","15.77027","0.61639"
"189.46800","15.78916","0.61783"
"189.69600","15.80823","0.61927"
"189.92400","15.82719","0.62081"
"190.15200","15.84626","0.62281"
"190.38000","15.86527","0.62401"
"190.60800","15.88422","0.62542"
"190.83600","15.90324","0.62793"
"191.06400","15.92219","0.62908"
"191.29200","15.94126","0.63087"
"191.52000","15.96016","0.63221"
"191.74800","15.97917","0.63515"
"191.97600","15.99824","0.63739"
"192.20400","16.01720","0.64053"
"192.43200","16.03627","0.64245"
"192.66000","16.05522","0.64438"
"192.88800","16.07424","0.64735"
"193.11600","16.09319","0.64940"
"193.34400","16.11214","0.65168"
"193.57200","16.13121","0.65350"
"193.80000","16.15011","0.65542"
"194.02800","16.16924","0.65684"
"194.25600","16.18819","0.65954"
"194.48400","16.20721","0.66145"
"194.71200","16.22622","0.66301"
"194.94000","16.24524","0.66541"
"195.16800","16.26431","0.66829"
"195.39600","16.28314","0.67098"
"195.62400","16.30227","0.67221"
"195.85200","16.32123","0.67404"
"196.08000","16.34018","0.67629"
"196.30800","16.35925","0.67846"
"196.53600","16.37815","0.67965"
"196.76400","16.39728","0.68122"
"196.99200","16.41617","0.68304"
"197.22000","16.43525","0.68510"
"197.44800","16.45426","0.68649"
"197.67600","16.47321","0.68845"
"197.90400","16.49223","0.69082"
"198.13200","16.51118","0.69295"
"198.36000","16.53025","0.69630"
"198.58800","16.54920","0.69881"
"198.81600","16.56822","0.70034"
"199.04400","16.58723","0.70247"
"199.27200","16.60618","0.70423"
"199.50000","16.62526","0.70614"
"199.72800","16.64421","0.70774"
"199.95600","16.66322","0.70918"
"200.18400","16.68218","0.71054"
"200.41200","16.70125","0.71186"
"200.64000","16.72026","0.71273"
"200.86800","16.73922","0.71411"
"201.09600","16.75823","0.71546"
"201.32400","16.77718","0.71691"
"201.55200","16.79620","0.71789"
"201.78000","16.81521","0.71882"
"202.00800","16.83422","0.72034"
"202.23600","16.85323","0.72182"
"202.46400","16.87219","0.72390"
"202.69200","16.89120","0.72504"
"202.92000","16.91021","0.72668"
"203.14800","16.92923","0.72841"
"203.37600","16.94824","0.73016"
"203.60400","16.96725","0.73176"
"203.83200","16.98621","0.73342"
"204.06000","17.00522","0.73409"
"204.28800","17.02417","0.73487"
"204.51600","17.04319","0.73650"
"204.74400","17.06226","0.73822"
"204.97200","17.08121","0.74062"
"205.20000","17.10022","0.74316"
"205.42800","17.11924","0.74595"
"205.65600","17.13813","0.74784"
"205.88400","17.15726","0.75152"
"206.11200","17.17622","0.75365"
"206.34000","17.19523","0.75541"
"206.56800","17.21418","0.75404"
"206.79600","17.23320","0.75534"
"207.02400","17.25227","0.75848"
"207.25200","17.27116","0.76256"
"207.48000","17.29024","0.76664"
"207.70800","17.30919","0.76849"
"207.93600","17.32820","0.77192"
"208.16400","17.34722","0.77546"
"208.39200","17.36623","0.77769"
"208.62000","17.38524","0.78024"
"208.84800","17.40413","0.78139"
"209.07600","17.42327","0.78382"
"209.30400","17.44222","0.78624"
"209.53200","17.46124","0.78846"
"209.76000","17.48025","0.79047"
"209.98800","17.49920","0.79285"
"210.21600","17.51827","0.79618"
"210.44400","17.53723","0.80001"
"210.67200","17.55630","0.80231"
"210.90000","17.57519","0.80533"
"211.12800","17.59421","0.80769"
"211.35600","17.61322","0.80941"
"211.58400","17.63223","0.81188"
"211.81200","17.65125","0.81370"
"212.04000","17.67014","0.81591"
"212.26800","17.68927","0.81787"
"212.49600","17.70823","0.81957"
"212.72400","17.72718","0.82078"
"212.95200","17.74625","0.82225"
"213.18000","17.76514","0.82347"
"213.40800","17.78422","0.82497"
"213.63600","17.80323","0.82634"
"213.86400","17.82224","0.82761"
"214.09200","17.84126","0.82903"
"214.32000","17.86015","0.83037"
"214.54800","17.87922","0.83221"
"214.77600","17.89824","0.83425"
"215.00400","17.91725","0.83607"
"215.23200","17.93620","0.83743"
"215.46000","17.95522","0.83952"
"215.68800","17.97423","0.84116"
"215.91600","17.99318","0.84368"
"216.14400","18.01225","0.84620"
"216.37200","18.03121","0.84869"
"216.60000","18.05022","0.85080"
"216.82800","18.06923","0.85316"
"217.05600","18.08819","0.85556"
"217.28400","18.10720","0.85785"
"217.51200","18.12615","0.85943"
"217.74000","18.14523","0.86061"
"217.96800","18.16424","0.86283"
"218.19600","18.18325","0.86424"
"218.42400","18.20226","0.86740"
"218.65200","18.22122","0.86937"
"218.88000","18.24029","0.87188"
"219.10800","18.25918","0.87420"
"219.33600","18.27820","0.87669"
"219.56400","18.29715","0.87868"
"219.79200","18.31623","0.88120"
"220.02000","18.33518","0.88330"
"220.24800","18.35419","0.88521"
"220.47600","18.37321","0.88773"
"220.70400","18.39222","0.89005"
"220.93200","18.41123","0.89355"
"221.16000","18.43018","0.89628"
"221.38800","18.44926","0.89945"
"221.61600","18.46821","0.90096"
"221.84400","18.48722","0.90396"
"222.07200","18.50624","0.90648"
"222.30000","18.52513","0.90809"
"222.52800","18.54426","0.91060"
"222.75600","18.56322","0.91300"
"222.98400","18.58223","0.91595"
"223.21200","18.60124","0.91863"
"223.44000","18.62020","0.92059"
"223.66800","18.63921","0.92265"
"223.89600","18.65822","0.92431"
"224.12400","18.67723","0.92566"
"224.35200","18.69619","0.92714"
"224.58000","18.71526","0.92893"
"224.80800","18.73421","0.93018"
"225.03600","18.75323","0.93216"
"225.26400","18.77224","0.93414"
"225.49200","18.79119","0.93721"
"225.72000","18.81021","0.93895"
"225.94800","18.82916","0.94169"
"226.17600","18.84817","0.94493"
"226.40400","18.86724","0.94801"
"226.63200","18.88620","0.95205"
"226.86000","18.90521","0.95570"
"227.08800","18.92416","0.95864"
"227.31600","18.94324","0.96087"
"227.54400","18.96219","0.96326"
"227.77200","18.98120","0.96584"
"228.00000","19.00022","0.96760"
"228.22800","19.01917","0.96972"
"228.45600","19.03830","0.97326"
"228.68400","19.05720","0.97563"
"228.91200","19.07621","0.97764"
"229.14000","19.09528","0.91283"
"229.36800","19.11418","0.91700"
"229.59600","19.13325","0.91841"
"229.82400","19.15214","0.92117"
"230.05200","19.17122","0.92176"
"230.28000","19.19017","0.92477"
"230.50800","19.20918","0.92538"
"230.73600","19.22825","0.92830"
"230.96400","19.24715","0.92864"
"231.19200","19.26622","0.93282"
"231.42000","19.28517","0.93357"
"231.64800","19.30425","0.93793"
"231.87600","19.32326","0.94000"
"232.10400","19.34215","0.94534"
"232.33200","19.36123","0.94707"
"232.56000","19.38012","0.95385"
"232.78800","19.39925","0.95605"
"233.01600","19.41821","0.96178"
"233.24400","19.43722","0.96268"
"233.47200","19.45629","0.96660"
"233.70000","19.47518","0.96841"
"233.92800","19.49426","0.97252"
"234.15600","19.51321","0.97371"
"234.38400","19.53222","0.97952"
"234.61200","19.55118","0.98170"
"234.84000","19.57019","0.98601"
"235.06800","19.58926","0.98748"
"235.29600","19.60822","0.99124"
"235.52400","19.62723","0.99246"
"235.75200","19.64618","0.99483"
"235.98000","19.66526","0.99608"
"236.20800","19.68421","0.99992"
"236.43600","19.70322","1.00238"
"236.66400","19.72217","1.00519"
"236.89200","19.74119","1.00773"
"237.12000","19.76020","1.00962"
"237.34800","19.77927","1.01158"
"237.57600","19.79823","1.01369"
"237.80400","19.81718","1.01574"
"238.03200","19.83625","1.01706"
"238.26000","19.85527","1.01841"
"238.48800","19.87416","1.01935"
"238.71600","19.89323","1.02146"
"238.94400","19.91219","1.02351"
"239.17200","19.93126","1.02584"
"239.40000","19.95021","1.02744"
"239.62800","19.96917","1.02988"
"239.85600","19.98824","1.03234"
"240.08400","20.00719","1.02373"
"240.31200","20.02620","1.02473"
"240.54000","20.04522","1.02739"
"240.76800","20.06423","1.02883"
"240.99600","20.08319","1.03170"
"241.22400","20.10225","1.03389"
"241.45200","20.12121","1.03560"
"241.68000","20.14016","1.03795"
"241.90800","20.15924","1.03979"
"242.13600","20.17819","1.04347"
"242.36400","20.19720","1.04603"
"242.59200","20.21622","1.05052"
"242.82000","20.23523","1.05353"
"243.04800","20.25424","1.05777"
"243.27600","20.27320","1.06202"
"243.50400","20.29227","1.06514"
"243.73200","20.31128","1.06674"
"243.96000","20.33018","1.06842"
"244.18800","20.34919","1.07098"
"244.41600","20.36814","1.07350"
"244.64400","20.38728","1.07654"
"244.87200","20.40617","1.07929"
"245.10000","20.42530","1.08377"
"245.32800","20.44413","1.08632"
"245.55600","20.46315","1.09016"
"245.78400","20.48222","1.09275"
"246.01200","20.50117","1.09537"
"246.24000","20.52024","1.09950"
"246.46800","20.53920","1.10331"
"246.69600","20.55821","1.10796"
"246.92400","20.57723","1.11030"
"247.15200","20.59624","1.11279"
"247.38000","20.61525","1.11622"
"247.60800","20.63414","1.11707"
"247.83600","20.65322","1.11902"
"248.06400","20.67217","1.12150"
"248.29200","20.69124","1.12343"
"248.52000","20.71026","1.12687"
"248.74800","20.72915","1.12898"
"248.97600","20.74828","1.13097"
"249.20400","20.76712","1.13247"
"249.43200","20.78625","1.13397"
"249.66000","20.80520","1.13519"
"249.88800","20.82416","1.13667"
"250.11600","20.84329","1.13785"
"250.34400","20.86212","1.13880"
"250.57200","20.88126","1.14034"
"250.80000","20.90021","1.14224"
"251.02800","20.91922","1.14401"
"251.25600","20.93817","1.14587"
"251.48400","20.95725","1.14772"
"251.71200","20.97626","1.15046"
"251.94000","20.99516","1.15331"
"252.16800","21.01417","1.15640"
"252.39600","21.03324","1.16020"
"252.62400","21.05219","1.16280"
"252.85200","21.07121","1.16548"
"253.08000","21.09016","1.16756"
"253.30800","21.10923","1.17070"
"253.53600","21.12819","1.17391"
"253.76400","21.14720","1.17752"
"253.99200","21.16621","1.18246"
"254.22000","21.18522","1.18698"
"254.44800","21.20424","1.18931"
"254.67600","21.22319","1.19216"
"254.90400","21.24226","1.19423"
"255.13200","21.26116","1.19689"
"255.36000","21.28023","1.18890"
"255.58800","21.29918","1.19237"
"255.81600","21.31825","1.19517"
"256.04400","21.33721","1.19885"
"256.27200","21.35622","1.20364"
"256.50000","21.37523","1.20974"
"256.72800","21.39419","1.21181"
"256.95600","21.41326","1.21462"
"257.18400","21.43222","1.21665"
"257.41200","21.45123","1.21944"
"257.64000","21.47024","1.22294"
"257.86800","21.48919","1.22576"
"258.09600","21.50821","1.22825"
"258.32400","21.52716","1.23092"
"258.55200","21.54623","1.23320"
"258.78000","21.56525","1.23538"
"259.00800","21.58414","1.23697"
"259.23600","21.60328","1.23937"
"259.46400","21.62217","1.24179"
"259.69200","21.64124","1.24365"
"259.92000","21.66019","1.24746"
"260.14800","21.67927","1.25108"
"260.37600","21.69822","1.25487"
"260.60400","21.71723","1.26075"
"260.83200","21.73619","1.26539"
"261.06000","21.75520","1.26977"
"261.28800","21.77427","1.27260"
"261.51600","21.79323","1.27513"
"261.74400","21.81224","1.27747"
"261.97200","21.83119","1.27944"
"262.20000","21.85020","1.27466"
"262.42800","21.86922","1.27699"
"262.65600","21.88817","1.26773"
"262.88400","21.90724","1.27216"
"263.11200","21.92614","1.27440"
"263.34000","21.94521","1.27676"
"263.56800","21.96422","1.27911"
"263.79600","21.98318","1.28039"
"264.02400","22.00225","1.28361"
"264.25200","22.02120","1.28697"
"264.48000","22.04027","1.28862"
"264.70800","22.05917","1.29196"
"264.93600","22.07818","1.29456"
"265.16400","22.09726","1.29586"
"265.39200","22.11609","1.29663"
"265.62000","22.13528","1.29508"
"265.84800","22.15417","1.29257"
"266.07600","22.17325","1.29519"
"266.30400","22.19226","1.29595"
"266.53200","22.21121","1.29776"
"266.76000","22.23022","1.29930"
"266.98800","22.24918","1.30223"
"267.21600","22.26826","1.30556"
"267.44400","22.28720","1.30783"
"267.67200","22.30622","1.31159"
"267.90000","22.32523","1.31450"
"268.12800","22.34419","1.31598"
"268.35600","22.36326","1.31976"
"268.58400","22.38215","1.32401"
"268.81200","22.40122","1.32704"
"269.04000","22.42024","1.33035"
"269.26800","22.43919","1.33229"
"269.49600","22.45827","1.33465"
"269.72400","22.47716","1.33050"
"269.95200","22.49623","1.31602"
"270.18000","22.51525","1.31812"
"270.40800","22.53432","1.32007"
"270.63600","22.55321","1.32301"
"270.86400","22.57216","1.32508"
"271.09200","22.59124","1.32728"
"271.32000","22.61019","1.32961"
"271.54800","22.62926","1.33390"
"271.77600","22.64822","1.33610"
"272.00400","22.66723","1.34168"
"272.23200","22.68624","1.32910"
"272.46000","22.70520","1.32635"
"272.68800","22.72427","1.32877"
"272.91600","22.74322","1.33351"
"273.14400","22.76218","1.33704"
"273.37200","22.78119","1.34074"
"273.60000","22.80026","1.34482"
"273.82800","22.81921","1.34748"
"274.05600","22.83823","1.35053"
"274.28400","22.85724","1.35283"
"274.51200","22.87613","1.35736"
"274.74000","22.89527","1.36165"
"274.96800","22.91422","1.36629"
"275.19600","22.93323","1.37201"
"275.42400","22.95224","1.37639"
"275.65200","22.97120","1.37722"
"275.88000","22.99027","1.38069"
"276.10800","23.00916","1.38384"
"276.33600","23.02824","1.38702"
"276.56400","23.04719","1.39209"
"276.79200","23.06620","1.39763"
"277.02000","23.08522","1.40229"
"277.24800","23.10423","1.40696"
"277.47600","23.12324","1.40897"
"277.70400","23.14220","1.41438"
"277.93200","23.16121","1.41972"
"278.16000","23.18016","1.42308"
"278.38800","23.19924","1.42714"
"278.61600","23.21819","1.43016"
"278.84400","23.23720","1.43095"
"279.07200","23.25622","1.43375"
"279.30000","23.27523","1.43610"
"279.52800","23.29424","1.43804"
"279.75600","23.31319","1.43955"
"279.98400","23.33215","1.44004"
"280.21200","23.35122","1.44148"
"280.44000","23.37017","1.44317"
"280.66800","23.38925","1.44454"
"280.89600","23.40814","1.44722"
"281.12400","23.42727","1.45039"
"281.35200","23.44622","1.45122"
"281.58000","23.46518","1.45323"
"281.80800","23.48425","1.45700"
"282.03600","23.50321","1.46303"
"282.26400","23.52222","1.46473"
"282.49200","23.54117","1.46896"
"282.72000","23.56018","1.47364"
"282.94800","23.57926","1.47743"
"283.17600","23.59821","1.48063"
"283.40400","23.61722","1.48348"
"283.63200","23.63618","1.47107"
"283.86000","23.65525","1.47880"
"284.08800","23.67420","1.48396"
"284.31600","23.69322","1.48949"
"284.54400","23.71229","1.49566"
"284.77200","23.73112","1.50146"
"285.00000","23.75026","1.50578"
"285.22800","23.76921","1.51052"
"285.45600","23.78822","1.51238"
"285.68400","23.80724","1.52031"
"285.91200","23.82619","1.52571"
"286.14000","23.84526","1.52916"
"286.36800","23.86410","1.53218"
"286.59600","23.88323","1.53581"
"286.82400","23.90224","1.53856"
"287.05200","23.92125","1.54197"
"287.28000","23.94020","1.54517"
"287.50800","23.95922","1.54830"
"287.73600","23.97823","1.43128"
"287.96400","23.99719","1.43805"
"288.19200","24.01626","1.43925"
"288.42000","24.03521","1.44058"
"288.64800","24.05417","1.44186"
"288.87600","24.07324","1.44354"
"289.10400","24.09219","1.44617"
"289.33200","24.11126","1.44871"
"289.56000","24.13022","1.45143"
"289.78800","24.14923","1.45557"
"290.01600","24.16825","1.45606"
"290.24400","24.18720","1.46092"
"290.47200","24.20621","1.46669"
"290.70000","24.22516","1.46914"
"290.92800","24.24424","1.47377"
"291.15600","24.26319","1.47984"
"291.38400","24.28226","1.48388"
"291.61200","24.30122","1.48319"
"291.84000","24.32023","1.48467"
"292.06800","24.33918","1.48703"
"292.29600","24.35819","1.46596"
"292.52400","24.37721","1.44026"
"292.75200","24.39622","1.44162"
"292.98000","24.41518","1.44210"
"293.20800","24.43425","1.44403"
"293.43600","24.45320","1.44519"
"293.66400","24.47221","1.44833"
"293.89200","24.49123","1.45068"
"294.12000","24.51018","1.45332"
"294.34800","24.52919","1.45759"
"294.57600","24.54821","1.46307"
"294.80400","24.56728","1.46667"
"295.03200","24.58617","1.47138"
"295.26000","24.60525","1.47636"
"295.48800","24.62420","1.48168"
"295.71600","24.64322","1.48631"
"295.94400","24.66222","1.49272"
"296.17200","24.68124","1.49175"
"296.40000","24.70019","1.49653"
"296.62800","24.71920","1.50155"
"296.85600","24.73816","1.50489"
"297.08400","24.75717","1.50687"
"297.31200","24.77625","1.51299"
"297.54000","24.79520","1.51711"
"297.76800","24.81421","1.52305"
"297.99600","24.83322","1.52794"
"298.22400","24.85218","1.53133"
"298.45200","24.87125","1.53530"
"298.68000","24.89020","1.53291"
"298.90800","24.90928","1.53758"
"299.13600","24.92823","1.54112"
"299.36400","24.94724","1.54458"
"299.59200","24.96626","1.54779"
"299.82000","24.98515","1.55082"
"300.04800","25.00428","1.55421"
"300.27600","25.02324","1.55843"
"300.50400","25.04225","1.56175"
"300.73200","25.06120","1.56503"
"300.96000","25.08015","1.56797"
"301.18800","25.09923","1.56619"
"301.41600","25.11812","1.56943"
"301.64400","25.13731","1.57355"
"301.87200","25.15621","1.57868"
"302.10000","25.17522","1.58279"
"302.32800","25.19423","1.58452"
"302.55600","25.21319","1.58780"
"302.78400","25.23226","1.59096"
"303.01200","25.25121","1.59393"
"303.24000","25.27023","1.59714"
"303.46800","25.28918","1.60021"
"303.69600","25.30819","1.41602"
"303.92400","25.32726","1.42442"
"304.15200","25.34616","1.43101"
"304.38000","25.36523","1.43078"
"304.60800","25.38418","1.42959"
"304.83600","25.40320","1.43419"
"305.06400","25.42227","1.43708"
"305.29200","25.44122","1.43604"
"305.52000","25.46024","1.43825"
"305.74800","25.47913","1.44025"
"305.97600","25.49820","1.44203"
"306.20400","25.51722","1.44318"
"306.43200","25.53623","1.44360"
"306.66000","25.55524","1.44888"
"306.88800","25.57419","1.44866"
"307.11600","25.59327","1.45046"
"307.34400","25.61216","1.45908"
"307.57200","25.63124","1.45964"
"307.80000","25.65019","1.46101"
"308.02800","25.66920","1.47211"
"308.25600","25.68821","1.47464"
"308.48400","25.70717","1.47493"
"308.71200","25.72624","1.48685"
"308.94000","25.74519","1.49046"
"309.16800","25.76427","1.48522"
"309.39600","25.78322","1.49536"
"309.62400","25.80217","1.49883"
"309.85200","25.82119","1.50168"
"310.08000","25.84020","1.50810"
"310.30800","25.85927","1.51273"
"310.53600","25.87817","1.51550"
"310.76400","25.89724","1.52721"
"310.99200","25.91619","1.52812"
"311.22000","25.93521","1.53096"
"311.44800","25.95422","1.53744"
"311.67600","25.97317","1.53806"
"311.90400","25.99219","1.54155"
"312.13200","26.01114","1.54741"
"312.36000","26.03021","1.54406"
"312.58800","26.04922","1.54761"
"312.81600","26.06824","1.55466"
"313.04400","26.08719","1.55654"
"313.27200","26.10620","1.55795"
"313.50000","26.12522","0.63859"
"313.72800","26.14423","0.23503"
"313.95600","26.16324","0.23134"
"314.18400","26.18220","0.26315"
"314.41200","26.20121","0.24572"
"314.64000","26.22022","0.25614"
"314.86800","26.23918","0.25928"
"315.09600","26.25825","0.26185"
"315.32400","26.27720","0.26243"
"315.55200","26.29627","0.27445"
"315.78000","26.31523","0.27381"
"316.00800","26.33418","0.27989"
"316.23600","26.35325","0.27197"
"316.46400","26.37215","0.28778"
"316.69200","26.39128","0.29224"
"316.92000","26.41017","0.28184"
"317.14800","26.42925","0.29773"
"317.37600","26.44820","0.29194"
"317.60400","26.46715","0.29490"
"317.83200","26.48628","0.30301"
"318.06000","26.50518","0.30165"
"318.28800","26.52425","0.30145"
"318.51600","26.54321","0.30189"
"318.74400","26.56216","0.30853"
"318.97200","26.58129","0.30511"
"319.20000","26.60013","0.30984"
"319.42800","26.61926","0.31284"
"319.65600","26.63821","0.31223"
"319.88400","26.65722","0.31488"
"320.11200","26.67624","0.31402"
"320.34000","26.69519","0.32046"
"320.56800","26.71432","0.31779"
"320.79600","26.73316","0.32136"
"321.02400","26.75223","0.32171"
"321.25200","26.77124","0.32860"
"321.48000","26.79026","0.32641"
"321.70800","26.80927","0.32928"
"321.93600","26.82816","0.33437"
"322.16400","26.84724","0.33893"
"322.39200","26.86619","0.33910"
"322.62000","26.88526","0.33961"
"322.84800","26.90421","0.33922"
"323.07600","26.92323","0.33973"
"323.30400","26.94218","0.34009"
"323.53200","26.96119","0.34064"
"323.76000","26.98021","0.34630"
"323.98800","26.99916","0.34020"
"324.21600","27.01823","0.34169"
"324.44400","27.03724","0.34272"
"324.67200","27.05620","0.35112"
"324.90000","27.07521","0.34993"
"325.12800","27.09417","0.35186"
"325.35600","27.11324","0.35365"
"325.58400","27.13219","0.36266"
"325.81200","27.15127","0.36124"
"326.04000","27.17022","0.36323"
"326.26800","27.18917","0.36562"
"326.49600","27.20824","0.36990"
"326.72400","27.22720","0.37063"
"326.95200","27.24621","0.37137"
"327.18000","27.26517","0.37290"
"327.40800","27.28424","0.37656"
"327.63600","27.30325","0.37996"
"327.86400","27.32220","0.37998"
"328.09200","27.34122","0.38255"
"328.32000","27.36023","0.38447"
"328.54800","27.37918","0.38957"
"328.77600","27.39820","0.38779"
"329.00400","27.41721","0.39053"
"329.23200","27.43616","0.39245"
"329.46000","27.45523","0.39603"
"329.68800","27.47419","0.39707"
"329.91600","27.49320","0.39751"
"330.14400","27.51221","0.39950"
"330.37200","27.53117","0.40135"
"330.60000","27.55024","0.40313"
"330.82800","27.56925","0.40359"
"331.05600","27.58821","0.40541"
"331.28400","27.60728","0.40551"
"331.51200","27.62623","0.40754"
"331.74000","27.64525","0.40532"
"331.96800","27.66414","0.40478"
"332.19600","27.68321","0.40662"
"332.42400","27.70222","0.40869"
"332.65200","27.72118","0.41196"
"332.88000","27.74025","0.41449"
"333.10800","27.75920","0.41555"
"333.33600","27.77828","0.41849"
"333.56400","27.79717","0.41985"
"333.79200","27.81618","0.42445"
"334.02000","27.83526","0.42613"
"334.24800","27.85415","0.42033"
"334.47600","27.87328","0.42259"
"334.70400","27.89218","0.42468"
"334.93200","27.91125","0.42875"
"335.16000","27.93020","0.43103"
"335.38800","27.94921","0.43185"
"335.61600","27.96823","0.43395"
"335.84400","27.98712","0.43742"
"336.07200","28.00626","0.44087"
"336.30000","28.02521","0.44385"
"336.52800","28.04416","0.44484"
"336.75600","28.06324","0.44686"
"336.88000","28.07352","0.44862"