File: Force_trajectories/161223/Specimen_RawData_3.csv
End date,"12/23/2016"
Specimen label,"22DT_78"
Maximum Load,"0.12982",N

Time,Extension,Load
(s),(mm),(N)
"0.00000","0.00006","-0.00039"
"0.50400","0.04227","0.00002"
"1.00800","0.08430","-0.00041"
"1.51200","0.12628","-0.00006"
"2.01600","0.16825","-0.00030"
"2.52000","0.21022","-0.00028"
"3.02400","0.25225","-0.00022"
"3.52800","0.29428","-0.00007"
"4.03200","0.33620","-0.00022"
"4.53600","0.37817","-0.00002"
"5.04000","0.42026","-0.00033"
"5.54400","0.46217","-0.00023"
"6.04800","0.50421","-0.00005"
"6.55200","0.54618","0.00030"
"7.05600","0.58821","0.00001"
"7.56000","0.63018","-0.00011"
"8.06400","0.67221","-0.00021"
"8.56800","0.71419","-0.00014"
"9.07200","0.75622","-0.00028"
"9.57600","0.79831","0.00022"
"10.08000","0.84028","-0.00016"
"10.58400","0.88219","-0.00011"
"11.08800","0.92429","-0.00022"
"11.59200","0.96626","0.00007"
"12.09600","1.00823","0.00000"
"12.60000","1.05020","0.00004"
"13.10400","1.09224","-0.00021"
"13.60800","1.13415","-0.00014"
"14.11200","1.17618","0.00008"
"14.61600","1.21821","-0.00034"
"15.12000","1.26018","-0.00020"
"15.62400","1.30222","0.00003"
"16.12800","1.34425","0.00007"
"16.63200","1.38622","0.00029"
"17.13600","1.42825","-0.00016"
"17.64000","1.47022","-0.00002"
"18.14400","1.51220","-0.00033"
"18.64800","1.55423","0.00004"
"19.15200","1.59626","0.00035"
"19.65600","1.63823","0.00056"
"20.16000","1.68021","-0.00020"
"20.66400","1.72224","0.00030"
"21.16800","1.76421","-0.00024"
"21.67200","1.80618","-0.00023"
"22.17600","1.84821","-0.00003"
"22.68000","1.89025","-0.00036"
"23.18400","1.93216","-0.00011"
"23.68800","1.97425","0.00041"
"24.19200","2.01622","-0.00021"
"24.69600","2.05819","0.00027"
"25.20000","2.10029","0.00018"
"25.70400","2.14220","-0.00007"
"26.20800","2.18423","-0.00009"
"26.71200","2.22626","0.00016"
"27.21600","2.26830","-0.00028"
"27.72000","2.31027","0.00012"
"28.22400","2.35224","-0.00012"
"28.72800","2.39421","0.00019"
"29.23200","2.43618","0.00019"
"29.73600","2.47822","-0.00003"
"30.24000","2.52019","-0.00011"
"30.74400","2.56222","-0.00018"
"31.24800","2.60413","0.00037"
"31.75200","2.64622","0.00017"
"32.25600","2.68826","0.00032"
"32.76000","2.73023","0.00041"
"33.26400","2.77226","0.00034"
"33.76800","2.81429","0.00022"
"34.27200","2.85621","0.00008"
"34.77600","2.89824","0.00042"
"35.28000","2.94021","0.00040"
"35.78400","2.98224","0.00021"
"36.28800","3.02421","0.00053"
"36.79200","3.06619","0.00051"
"37.29600","3.10816","0.00028"
"37.80000","3.15019","0.00043"
"38.30400","3.19222","0.00000"
"38.80800","3.23414","0.00021"
"39.31200","3.27617","0.00012"
"39.81600","3.31826","0.00032"
"40.32000","3.36023","0.00056"
"40.82400","3.40226","0.00071"
"41.32800","3.44430","0.00043"
"41.83200","3.48627","0.00085"
"42.33600","3.52824","0.00081"
"42.84000","3.57021","0.00044"
"43.34400","3.61224","0.00078"
"43.84800","3.65422","0.00079"
"44.35200","3.69625","0.00048"
"44.85600","3.73822","0.00100"
"45.36000","3.78019","0.00084"
"45.86400","3.82217","0.00090"
"46.36800","3.86420","0.00033"
"46.87200","3.90617","0.00045"
"47.37600","3.94826","0.00037"
"47.88000","3.99023","0.00038"
"48.38400","4.03227","0.00020"
"48.88800","4.07424","0.00051"
"49.39200","4.11627","0.00062"
"49.89600","4.15824","0.00048"
"50.40000","4.20033","0.00049"
"50.90400","4.24225","0.00067"
"51.40800","4.28428","0.00082"
"51.91200","4.32619","0.00089"
"52.41600","4.36828","0.00101"
"52.92000","4.41026","0.00071"
"53.42400","4.45217","0.00082"
"53.92800","4.49420","0.00084"
"54.43200","4.53617","0.00114"
"54.93600","4.57820","0.00108"
"55.44000","4.62024","0.00133"
"55.94400","4.66221","0.00070"
"56.44800","4.70424","0.00154"
"56.95200","4.74627","0.00142"
"57.45600","4.78824","0.00178"
"57.96000","4.83022","0.00138"
"58.46400","4.87225","0.00117"
"58.96800","4.91422","0.00112"
"59.47200","4.95619","0.00150"
"59.97600","4.99823","0.00117"
"60.48000","5.04020","0.00172"
"60.98400","5.08217","0.00141"
"61.48800","5.12420","0.00125"
"61.99200","5.16617","0.00152"
"62.49600","5.20821","0.00129"
"63.00000","5.25018","0.00160"
"63.50400","5.29221","0.00138"
"64.00800","5.33424","0.00150"
"64.51200","5.37627","0.00111"
"65.01600","5.41831","0.00130"
"65.52000","5.46028","0.00164"
"66.02400","5.50225","0.00148"
"66.52800","5.54422","0.00145"
"67.03200","5.58632","0.00169"
"67.53600","5.62817","0.00128"
"68.04000","5.67026","0.00141"
"68.54400","5.71223","0.00199"
"69.04800","5.75420","0.00191"
"69.55200","5.79618","0.00155"
"70.05600","5.83821","0.00204"
"70.56000","5.88018","0.00135"
"71.06400","5.92221","0.00204"
"71.56800","5.96419","0.00181"
"72.07200","6.00628","0.00218"
"72.57600","6.04825","0.00163"
"73.08000","6.09028","0.00189"
"73.58400","6.13225","0.00208"
"74.08800","6.17423","0.00224"
"74.59200","6.21620","0.00149"
"75.09600","6.25823","0.00182"
"75.60000","6.30020","0.00173"
"76.10400","6.34217","0.00203"
"76.60800","6.38421","0.00239"
"77.11200","6.42624","0.00189"
"77.61600","6.46815","0.00197"
"78.12000","6.51024","0.00167"
"78.62400","6.55216","0.00124"
"79.12800","6.59425","0.00129"
"79.63200","6.63622","0.00146"
"80.13600","6.67825","0.00208"
"80.64000","6.72028","0.00165"
"81.14400","6.76226","0.00134"
"81.64800","6.80429","0.00143"
"82.15200","6.84620","0.00018"
"82.65600","6.88823","0.00040"
"83.16000","6.93020","0.00070"
"83.66400","6.97224","0.00081"
"84.16800","7.01421","0.00037"
"84.67200","7.05624","0.00040"
"85.17600","7.09821","0.00059"
"85.68000","7.14019","0.00116"
"86.18400","7.18222","0.00093"
"86.68800","7.22419","0.00102"
"87.19200","7.26616","0.00099"
"87.69600","7.30825","0.00069"
"88.20000","7.35017","0.00098"
"88.70400","7.39232","0.00109"
"89.20800","7.43429","0.00141"
"89.71200","7.47626","0.00106"
"90.21600","7.51823","0.00118"
"90.72000","7.56027","0.00153"
"91.22400","7.60224","0.00101"
"91.72800","7.64421","0.00100"
"92.23200","7.68618","0.00137"
"92.73600","7.72822","0.00170"
"93.24000","7.77019","0.00162"
"93.74400","7.81222","0.00169"
"94.24800","7.85419","0.00125"
"94.75200","7.89622","0.00117"
"95.25600","7.93820","0.00164"
"95.76000","7.98029","0.00185"
"96.26400","8.02220","0.00160"
"96.76800","8.06423","0.00154"
"97.27200","8.10626","0.00194"
"97.77600","8.14824","0.00191"
"98.28000","8.19027","0.00204"
"98.78400","8.23230","0.00199"
"99.28800","8.27421","0.00164"
"99.79200","8.31625","0.00197"
"100.29600","8.35822","0.00213"
"100.80000","8.40019","0.00200"
"101.30400","8.44216","0.00205"
"101.80800","8.48419","0.00167"
"102.31200","8.52623","0.00217"
"102.81600","8.56820","0.00205"
"103.32000","8.61017","0.00182"
"103.82400","8.65220","0.00252"
"104.32800","8.69423","0.00201"
"104.83200","8.73627","0.00239"
"105.33600","8.77824","0.00280"
"105.84000","8.82021","0.00268"
"106.34400","8.86230","0.00208"
"106.84800","8.90428","0.00258"
"107.35200","8.94625","0.00292"
"107.85600","8.98822","0.00309"
"108.36000","9.03025","0.00213"
"108.86400","9.07222","0.00262"
"109.36800","9.11426","0.00228"
"109.87200","9.15617","0.00180"
"110.37600","9.19820","0.00119"
"110.88000","9.24017","0.00124"
"111.38400","9.28226","0.00127"
"111.88800","9.32418","0.00132"
"112.39200","9.36621","0.00135"
"112.89600","9.40824","0.00124"
"113.40000","9.45027","0.00115"
"113.90400","9.49219","0.00130"
"114.40800","9.53428","0.00176"
"114.91200","9.57625","0.00189"
"115.41600","9.61828","0.00167"
"115.92000","9.66026","0.00111"
"116.42400","9.70223","0.00131"
"116.92800","9.74414","0.00154"
"117.43200","9.78617","0.00141"
"117.93600","9.82820","0.00173"
"118.44000","9.87018","0.00231"
"118.94400","9.91221","0.00181"
"119.44800","9.95424","0.00184"
"119.95200","9.99621","0.00183"
"120.45600","10.03818","0.00228"
"120.96000","10.08022","0.00206"
"121.46400","10.12225","0.00221"
"121.96800","10.16422","0.00229"
"122.47200","10.20625","0.00193"
"122.97600","10.24823","0.00220"
"123.48000","10.29026","0.00237"
"123.98400","10.33223","0.00238"
"124.48800","10.37420","0.00243"
"124.99200","10.41617","0.00285"
"125.49600","10.45821","0.00273"
"126.00000","10.50018","0.00257"
"126.50400","10.54215","0.00277"
"127.00800","10.58424","0.00276"
"127.51200","10.62621","0.00315"
"128.01600","10.66825","0.00310"
"128.52000","10.71022","0.00297"
"129.02400","10.75225","0.00295"
"129.52800","10.79422","0.00314"
"130.03200","10.83632","0.00304"
"130.53600","10.87823","0.00326"
"131.04000","10.92026","0.00354"
"131.54400","10.96223","0.00337"
"132.04800","11.00426","0.00321"
"132.55200","11.04618","0.00339"
"133.05600","11.08821","0.00334"
"133.56000","11.13018","0.00380"
"134.06400","11.17221","0.00386"
"134.56800","11.21418","0.00408"
"135.07200","11.25628","0.00339"
"135.57600","11.29819","0.00392"
"136.08000","11.34022","0.00359"
"136.58400","11.38225","0.00373"
"137.08800","11.42423","0.00406"
"137.59200","11.46620","0.00362"
"138.09600","11.50823","0.00410"
"138.60000","11.55020","0.00395"
"139.10400","11.59229","0.00401"
"139.60800","11.63421","0.00434"
"140.11200","11.67624","0.00436"
"140.61600","11.71821","0.00478"
"141.12000","11.76012","0.00406"
"141.62400","11.80216","0.00437"
"142.12800","11.84419","0.00447"
"142.63200","11.88622","0.00438"
"143.13600","11.92825","0.00455"
"143.64000","11.97022","0.00523"
"144.14400","12.01225","0.00511"
"144.64800","12.05423","0.00552"
"145.15200","12.09620","0.00531"
"145.65600","12.13823","0.00587"
"146.16000","12.18020","0.00572"
"146.66400","12.22224","0.00579"
"147.16800","12.26421","0.00591"
"147.67200","12.30630","0.00551"
"148.17600","12.34821","0.00543"
"148.68000","12.39019","0.00627"
"149.18400","12.43216","0.00621"
"149.68800","12.47419","0.00632"
"150.19200","12.51622","0.00620"
"150.69600","12.55819","0.00637"
"151.20000","12.60023","0.00649"
"151.70400","12.64226","0.00625"
"152.20800","12.68423","0.00646"
"152.71200","12.72626","0.00662"
"153.21600","12.76817","0.00684"
"153.72000","12.81027","0.00652"
"154.22400","12.85224","0.00704"
"154.72800","12.89433","0.00673"
"155.23200","12.93618","0.00681"
"155.73600","12.97827","0.00689"
"156.24000","13.02019","0.00763"
"156.74400","13.06222","0.00696"
"157.24800","13.10419","0.00767"
"157.75200","13.14622","0.00779"
"158.25600","13.18820","0.00673"
"158.76000","13.23023","0.00700"
"159.26400","13.27220","0.00674"
"159.76800","13.31429","0.00686"
"160.27200","13.35627","0.00710"
"160.77600","13.39830","0.00670"
"161.28000","13.44027","0.00693"
"161.78400","13.48218","0.00730"
"162.28800","13.52427","0.00763"
"162.79200","13.56625","0.00751"
"163.29600","13.60822","0.00759"
"163.80000","13.65025","0.00768"
"164.30400","13.69222","0.00753"
"164.80800","13.73419","0.00762"
"165.31200","13.77617","0.00795"
"165.81600","13.81820","0.00857"
"166.32000","13.86023","0.00863"
"166.82400","13.90220","0.00829"
"167.32800","13.94424","0.00833"
"167.83200","13.98621","0.00266"
"168.33600","14.02830","0.00267"
"168.84000","14.07027","0.00251"
"169.34400","14.11224","0.00298"
"169.84800","14.15422","0.00280"
"170.35200","14.19625","0.00320"
"170.85600","14.23822","0.00305"
"171.36000","14.28025","0.00351"
"171.86400","14.32222","0.00340"
"172.36800","14.36426","0.00363"
"172.87200","14.40617","0.00321"
"173.37600","14.44820","0.00390"
"173.88000","14.49017","0.00376"
"174.38400","14.53215","0.00415"
"174.88800","14.57424","0.00347"
"175.39200","14.61627","0.00393"
"175.89600","14.65818","0.00400"
"176.40000","14.70027","0.00371"
"176.90400","14.74224","0.00396"
"177.40800","14.78422","0.00450"
"177.91200","14.82619","0.00453"
"178.41600","14.86828","0.00361"
"178.92000","14.91025","0.00365"
"179.42400","14.95223","0.00424"
"179.92800","14.99420","0.00433"
"180.43200","15.03623","0.00390"
"180.93600","15.07814","0.00444"
"181.44000","15.12024","0.00476"
"181.94400","15.16215","0.00431"
"182.44800","15.20418","0.00426"
"182.95200","15.24621","0.00472"
"183.45600","15.28824","0.00486"
"183.96000","15.33028","0.00489"
"184.46400","15.37219","0.00475"
"184.96800","15.41422","0.00559"
"185.47200","15.45619","0.00485"
"185.97600","15.49828","0.00502"
"186.48000","15.54026","0.00547"
"186.98400","15.58223","0.00496"
"187.48800","15.62420","0.00528"
"187.99200","15.66623","0.00551"
"188.49600","15.70826","0.00556"
"189.00000","15.75018","0.00596"
"189.50400","15.79215","0.00595"
"190.00800","15.83418","0.00619"
"190.51200","15.87621","0.00558"
"191.01600","15.91825","0.00649"
"191.52000","15.96016","0.00614"
"192.02400","16.00231","0.00679"
"192.52800","16.04428","0.00694"
"193.03200","16.08625","0.00699"
"193.53600","16.12823","0.00648"
"194.04000","16.17026","0.00685"
"194.54400","16.21223","0.00708"
"195.04800","16.25426","0.00742"
"195.55200","16.29623","0.00704"
"196.05600","16.33827","0.00761"
"196.56000","16.38018","0.00798"
"197.06400","16.42215","0.00772"
"197.56800","16.46424","0.00756"
"198.07200","16.50622","0.00779"
"198.57600","16.54819","0.00771"
"199.08000","16.59022","0.00782"
"199.58400","16.63219","0.00801"
"200.08800","16.67422","0.00821"
"200.59200","16.71626","0.00805"
"201.09600","16.75829","0.00852"
"201.60000","16.80026","0.00841"
"202.10400","16.84229","0.00758"
"202.60800","16.88421","0.00785"
"203.11200","16.92624","0.00815"
"203.61600","16.96821","0.00832"
"204.12000","17.01024","0.00837"
"204.62400","17.05215","0.00792"
"205.12800","17.09413","0.00862"
"205.63200","17.13622","0.00815"
"206.13600","17.17819","0.00879"
"206.64000","17.22016","0.00877"
"207.14400","17.26225","0.00927"
"207.64800","17.30429","0.00933"
"208.15200","17.34626","0.00984"
"208.65600","17.38823","0.00974"
"209.16000","17.43026","0.00976"
"209.66400","17.47230","0.00938"
"210.16800","17.51427","0.00960"
"210.67200","17.55624","0.01020"
"211.17600","17.59821","0.00954"
"211.68000","17.64024","0.01053"
"212.18400","17.68216","0.01067"
"212.68800","17.72419","0.01074"
"213.19200","17.76616","0.01023"
"213.69600","17.80825","0.01064"
"214.20000","17.85016","0.01129"
"214.70400","17.89220","0.01080"
"215.20800","17.93417","0.01168"
"215.71200","17.97626","0.01150"
"216.21600","18.01823","0.01125"
"216.72000","18.06026","0.01168"
"217.22400","18.10224","0.01235"
"217.72800","18.14427","0.01262"
"218.23200","18.18630","0.01180"
"218.73600","18.22821","0.01155"
"219.24000","18.27019","0.01194"
"219.74400","18.31222","0.01141"
"220.24800","18.35419","0.01197"
"220.75200","18.39622","0.01175"
"221.25600","18.43820","0.01221"
"221.76000","18.48023","0.01248"
"222.26400","18.52220","0.01229"
"222.76800","18.56423","0.01323"
"223.27200","18.60620","0.01335"
"223.77600","18.64824","0.01317"
"224.28000","18.69027","0.01343"
"224.78400","18.73224","0.01394"
"225.28800","18.77427","0.01370"
"225.79200","18.81624","0.01330"
"226.29600","18.85828","0.01407"
"226.80000","18.90025","0.01422"
"227.30400","18.94222","0.01407"
"227.80800","18.98419","0.01484"
"228.31200","19.02623","0.01511"
"228.81600","19.06814","0.01491"
"229.32000","19.11023","0.01518"
"229.82400","19.15226","0.01530"
"230.32800","19.19423","0.01527"
"230.83200","19.23621","0.01604"
"231.33600","19.27824","0.01592"
"231.84000","19.32027","0.01646"
"232.34400","19.36224","0.01577"
"232.84800","19.40421","0.01650"
"233.35200","19.44631","0.01619"
"233.85600","19.48828","0.01648"
"234.36000","19.53025","0.01699"
"234.86400","19.57222","0.01586"
"235.36800","19.61419","0.01622"
"235.87200","19.65617","0.01661"
"236.37600","19.69826","0.01742"
"236.88000","19.74017","0.01872"
"237.38400","19.78220","0.00558"
"237.88800","19.82418","0.00664"
"238.39200","19.86621","0.00680"
"238.89600","19.90824","0.00702"
"239.40000","19.95021","0.00689"
"239.90400","19.99224","0.00752"
"240.40800","20.03422","0.00765"
"240.91200","20.07619","0.00818"
"241.41600","20.11822","0.00826"
"241.92000","20.16019","0.00834"
"242.42400","20.20229","0.00880"
"242.92800","20.24426","0.00946"
"243.43200","20.28623","0.00938"
"243.93600","20.32820","0.00980"
"244.44000","20.37017","0.01013"
"244.94400","20.41221","0.01074"
"245.44800","20.45418","0.01003"
"245.95200","20.49621","0.01045"
"246.45600","20.53818","0.01008"
"246.96000","20.58022","0.00885"
"247.46400","20.62225","0.00979"
"247.96800","20.66422","0.00735"
"248.47200","20.70625","0.00793"
"248.97600","20.74828","0.00840"
"249.48000","20.79020","0.00825"
"249.98400","20.83229","0.00883"
"250.48800","20.87426","0.00878"
"250.99200","20.91623","0.00926"
"251.49600","20.95821","0.00891"
"252.00000","21.00024","0.00853"
"252.50400","21.04215","0.00896"
"253.00800","21.08418","0.00465"
"253.51200","21.12621","0.00531"
"254.01600","21.16818","0.00538"
"254.52000","21.21028","0.00632"
"255.02400","21.25225","0.00668"
"255.52800","21.29422","0.00661"
"256.03200","21.33625","0.00727"
"256.53600","21.37823","0.00750"
"257.04000","21.42032","0.00750"
"257.54400","21.46223","0.00788"
"258.04800","21.50426","0.00823"
"258.55200","21.54623","0.00855"
"259.05600","21.58821","0.00897"
"259.56000","21.63018","0.00917"
"260.06400","21.67221","0.00963"
"260.56800","21.71412","0.00999"
"261.07200","21.75615","0.01015"
"261.57600","21.79819","0.01056"
"262.08000","21.84022","0.01155"
"262.58400","21.88225","0.01150"
"263.08800","21.92422","0.01177"
"263.59200","21.96626","0.01186"
"264.09600","22.00823","0.01194"
"264.60000","22.05020","0.01206"
"265.10400","22.09223","0.01236"
"265.60800","22.13426","0.00774"
"266.11200","22.17624","0.00794"
"266.61600","22.21821","0.00888"
"267.12000","22.26018","0.00919"
"267.62400","22.30221","0.00921"
"268.12800","22.34425","0.00812"
"268.63200","22.38616","0.00434"
"269.13600","22.42813","0.00476"
"269.64000","22.47022","0.00469"
"270.14400","22.51219","0.00582"
"270.64800","22.55423","0.00563"
"271.15200","22.59620","0.00541"
"271.65600","22.63823","0.00545"
"272.16000","22.68026","0.00594"
"272.66400","22.72229","0.00657"
"273.16800","22.76421","0.00630"
"273.67200","22.80630","0.00656"
"274.17600","22.84821","0.00683"
"274.68000","22.89024","0.00696"
"275.18400","22.93222","0.00684"
"275.68800","22.97419","0.00791"
"276.19200","23.01616","0.00759"
"276.69600","23.05819","0.00746"
"277.20000","23.10016","0.00766"
"277.70400","23.14220","0.00796"
"278.20800","23.18423","0.00819"
"278.71200","23.22626","0.00793"
"279.21600","23.26823","0.00898"
"279.72000","23.31027","0.00863"
"280.22400","23.35224","0.00887"
"280.72800","23.39427","0.00955"
"281.23200","23.43624","0.00896"
"281.73600","23.47821","0.00978"
"282.24000","23.52024","0.01034"
"282.74400","23.56222","0.01088"
"283.24800","23.60419","0.01030"
"283.75200","23.64622","0.01073"
"284.25600","23.68813","0.01137"
"284.76000","23.73023","0.01144"
"285.26400","23.77214","0.01170"
"285.76800","23.81423","0.01227"
"286.27200","23.85620","0.01256"
"286.77600","23.89824","0.01293"
"287.28000","23.94027","0.01315"
"287.78400","23.98224","0.01408"
"288.28800","24.02427","0.01431"
"288.79200","24.06624","0.01462"
"289.29600","24.10827","0.01436"
"289.80000","24.15019","0.00887"
"290.30400","24.19222","0.00970"
"290.80800","24.23419","0.01010"
"291.31200","24.27622","0.01045"
"291.81600","24.31820","0.01113"
"292.32000","24.36017","0.01194"
"292.82400","24.40214","0.01164"
"293.32800","24.44417","0.01267"
"293.83200","24.48620","0.01322"
"294.33600","24.52824","0.01354"
"294.84000","24.57027","0.01388"
"295.34400","24.61230","0.01428"
"295.84800","24.65427","0.01475"
"296.35200","24.69625","0.01520"
"296.85600","24.73822","0.01564"
"297.36000","24.78031","0.01625"
"297.86400","24.82222","0.01617"
"298.36800","24.86419","0.01747"
"298.87200","24.90623","0.01773"
"299.37600","24.94820","0.01793"
"299.88000","24.99017","0.01860"
"300.38400","25.03220","0.01475"
"300.88800","25.07417","0.01234"
"301.39200","25.11621","0.01306"
"301.89600","25.15818","0.01381"
"302.40000","25.20021","0.01435"
"302.90400","25.24224","0.01494"
"303.40800","25.28422","0.01555"
"303.91200","25.32625","0.01615"
"304.41600","25.36822","0.01531"
"304.92000","25.41025","0.01623"
"305.42400","25.45228","0.01653"
"305.92800","25.49426","0.01758"
"306.43200","25.53623","0.01797"
"306.93600","25.57820","0.01864"
"307.44000","25.62017","0.01912"
"307.94400","25.66215","0.01980"
"308.44800","25.70418","0.02004"
"308.95200","25.74621","0.02082"
"309.45600","25.78824","0.02110"
"309.96000","25.83021","0.02167"
"310.46400","25.87219","0.02231"
"310.96800","25.91428","0.02274"
"311.47200","25.95631","0.02378"
"311.97600","25.99822","0.02420"
"312.48000","26.04025","0.02484"
"312.98400","26.08229","0.02407"
"313.48800","26.12426","0.02384"
"313.99200","26.16623","0.02454"
"314.49600","26.20820","0.02472"
"315.00000","26.25024","0.02507"
"315.50400","26.29221","0.02632"
"316.00800","26.33424","0.02641"
"316.51200","26.37615","0.02695"
"317.01600","26.41825","0.02811"
"317.52000","26.46021","0.02813"
"318.02400","26.50225","0.02855"
"318.52800","26.54416","0.02920"
"319.03200","26.58619","0.03009"
"319.53600","26.62823","0.03032"
"320.04000","26.67026","0.03126"
"320.54400","26.71223","0.03223"
"321.04800","26.75426","0.03249"
"321.55200","26.79623","0.03346"
"322.05600","26.83827","0.03388"
"322.56000","26.88018","0.03520"
"323.06400","26.92221","0.03564"
"323.56800","26.96418","0.03601"
"324.07200","27.00621","0.03666"
"324.57600","27.04819","0.03782"
"325.08000","27.09016","0.03675"
"325.58400","27.13219","0.01238"
"326.08800","27.17417","0.00952"
"326.59200","27.21626","0.01091"
"327.09600","27.25823","0.01223"
"327.60000","27.30026","0.00998"
"328.10400","27.34223","0.01249"
"328.60800","27.38426","0.01261"
"329.11200","27.42624","0.01205"
"329.61600","27.46827","0.01440"
"330.12000","27.51024","0.01404"
"330.62400","27.55227","0.01482"
"331.12800","27.59418","0.01607"
"331.63200","27.63622","0.01598"
"332.13600","27.67819","0.01641"
"332.64000","27.72022","0.01771"
"333.14400","27.76220","0.01745"
"333.64800","27.80423","0.01883"
"334.15200","27.84626","0.01931"
"334.65600","27.88823","0.01985"
"335.16000","27.93026","0.02063"
"335.66400","27.97224","0.02171"
"336.16800","28.01427","0.02200"
"336.67200","28.05624","0.02300"
"337.17600","28.09821","0.02341"
"337.68000","28.14030","0.02434"
"338.18400","28.18221","0.02475"
"338.68800","28.22419","0.02574"
"339.19200","28.26616","0.02622"
"339.69600","28.30819","0.02720"
"340.20000","28.35016","0.02770"
"340.70400","28.39220","0.02843"
"341.20800","28.43417","0.02845"
"341.71200","28.47620","0.00371"
"342.21600","28.51823","0.00185"
"342.72000","28.56026","0.00135"
"343.22400","28.60224","0.00149"
"343.72800","28.64427","0.00141"
"344.23200","28.68618","0.00201"
"344.73600","28.72821","0.00164"
"345.24000","28.77025","0.00135"
"345.74400","28.81222","0.00111"
"346.24800","28.85425","0.00144"
"346.75200","28.89622","0.00161"
"347.25600","28.93819","0.00152"
"347.76000","28.98017","0.00160"
"348.26400","29.02214","0.00176"
"348.76800","29.06417","0.00164"
"349.27200","29.10620","0.00186"
"349.77600","29.14824","0.00225"
"350.28000","29.19021","0.00157"
"350.78400","29.23224","0.00141"
"351.28800","29.27427","0.00207"
"351.79200","29.31624","0.00211"
"352.29600","29.35828","0.00165"
"352.80000","29.40025","0.00233"
"353.30400","29.44228","0.00202"
"353.80800","29.48419","0.00276"
"354.31200","29.52629","0.00179"
"354.81600","29.56820","0.00280"
"355.32000","29.61017","0.00220"
"355.82400","29.65220","0.00258"
"356.32800","29.69417","0.00234"
"356.83200","29.73621","0.00248"
"357.33600","29.77824","0.00292"
"357.84000","29.82021","0.00256"
"358.34400","29.86230","0.00303"
"358.84800","29.90421","0.00264"
"359.35200","29.94625","0.00226"
"359.85600","29.98822","0.00306"
"360.36000","30.03025","0.00279"
"360.86400","30.07222","0.00276"
"361.36800","30.11432","0.00289"
"361.87200","30.15617","0.00325"
"362.37600","30.19820","0.00302"
"362.88000","30.24023","0.00301"
"363.38400","30.28221","0.00349"
"363.88800","30.32418","0.00340"
"364.39200","30.36621","0.00310"
"364.89600","30.40818","0.00319"
"365.40000","30.45021","0.00335"
"365.90400","30.49218","0.00351"
"366.40800","30.53428","0.00313"
"366.91200","30.57625","0.00254"
"367.41600","30.61828","0.00302"
"367.92000","30.66019","0.00279"
"368.42400","30.70222","0.00293"
"368.92800","30.74426","0.00289"
"369.43200","30.78629","0.00285"
"369.93600","30.82826","0.00301"
"370.44000","30.87017","0.00324"
"370.94400","30.91221","0.00321"
"371.44800","30.95418","0.00365"
"371.95200","30.99621","0.00344"
"372.45600","31.03818","0.00308"
"372.96000","31.08022","0.00388"
"373.46400","31.12218","0.00338"
"373.96800","31.16428","0.00373"
"374.47200","31.20619","0.00373"
"374.97600","31.24829","0.00421"
"375.48000","31.29025","0.00392"
"375.98400","31.33222","0.00398"
"376.48800","31.37420","0.00393"
"376.99200","31.41629","0.00394"
"377.49600","31.45820","0.00367"
"378.00000","31.50023","0.00374"
"378.50400","31.54221","0.00425"
"379.00800","31.58424","0.00439"
"379.51200","31.62615","0.00429"
"380.01600","31.66818","0.00463"
"380.52000","31.71016","0.00473"
"381.02400","31.75219","0.00498"
"381.52800","31.79422","0.00508"
"382.03200","31.83625","0.00502"
"382.53600","31.87823","0.00523"
"383.04000","31.92025","0.00499"
"383.54400","31.96229","0.00539"
"384.04800","32.00426","0.00510"
"384.55200","32.04623","0.00548"
"385.05600","32.08826","0.00562"
"385.56000","32.13024","0.00530"
"386.06400","32.17221","0.00583"
"386.56800","32.21418","0.00611"
"387.07200","32.25621","0.00599"
"387.57600","32.29818","0.00583"
"388.08000","32.34022","0.00640"
"388.58400","32.38219","0.00665"
"389.08800","32.42422","0.00652"
"389.59200","32.46619","0.00673"
"390.09600","32.50829","0.00683"
"390.60000","32.55025","0.00694"
"391.10400","32.59223","0.00704"
"391.60800","32.63426","0.00659"
"392.11200","32.67624","0.00610"
"392.61600","32.71827","0.00649"
"393.12000","32.76024","0.00590"
"393.62400","32.80221","0.00647"
"394.12800","32.84418","0.00662"
"394.63200","32.88622","0.00623"
"395.13600","32.92819","0.00624"
"395.64000","32.97022","0.00708"
"396.14400","33.01219","0.00679"
"396.64800","33.05416","0.00642"
"397.15200","33.09620","0.00418"
"397.65600","33.13823","0.00318"
"398.16000","33.18020","0.00342"
"398.66400","33.22229","0.00238"
"399.16800","33.26426","0.00246"
"399.67200","33.30630","0.00275"
"400.17600","33.34821","0.00293"
"400.68000","33.39024","0.00277"
"401.18400","33.43227","0.00398"
"401.68800","33.47424","0.00337"
"402.19200","33.51622","0.00416"
"402.69600","33.55825","0.00322"
"403.20000","33.60016","0.00483"
"403.70400","33.64220","0.00348"
"404.20800","33.68417","0.00479"
"404.71200","33.72620","0.00399"
"405.21600","33.76817","0.00473"
"405.72000","33.81020","0.00383"
"406.22400","33.85218","0.00418"
"406.72800","33.89421","0.00418"
"407.23200","33.93624","0.00469"
"407.73600","33.97827","0.00462"
"408.24000","34.02024","0.00436"
"408.74400","34.06222","0.00521"
"409.24800","34.10419","0.00464"
"409.75200","34.14622","0.00518"
"410.25600","34.18819","0.00545"
"410.76000","34.23022","0.00531"
"411.26400","34.27220","0.00589"
"411.76800","34.31417","0.00581"
"412.27200","34.35620","0.00558"
"412.77600","34.39823","0.00600"
"413.28000","34.44027","0.00542"
"413.78400","34.48218","0.00594"
"414.28800","34.52427","0.00554"
"414.79200","34.56624","0.00609"
"415.29600","34.60828","0.00617"
"415.80000","34.65025","0.00637"
"416.30400","34.69222","0.00693"
"416.80800","34.73425","0.00629"
"417.31200","34.77622","0.00603"
"417.81600","34.81820","0.00513"
"418.32000","34.86029","0.00485"
"418.82400","34.90220","0.00546"
"419.32800","34.94423","0.00532"
"419.83200","34.98621","0.00540"
"420.33600","35.02818","0.00632"
"420.84000","35.07021","0.00555"
"421.34400","35.11224","0.00588"
"421.84800","35.15415","0.00605"
"422.35200","35.19624","0.00626"
"422.85600","35.23822","0.00673"
"423.36000","35.28025","0.00641"
"423.86400","35.32222","0.00359"
"424.36800","35.36431","0.00344"
"424.87200","35.40622","0.00409"
"425.37600","35.44826","0.00386"
"425.88000","35.49017","0.00451"
"426.38400","35.53220","0.00439"
"426.88800","35.57412","0.00465"
"427.39200","35.61615","0.00414"
"427.89600","35.65818","0.00408"
"428.40000","35.70021","0.00440"
"428.90400","35.74224","0.00421"
"429.40800","35.78421","0.00476"
"429.91200","35.82625","0.00416"
"430.41600","35.86822","0.00433"
"430.92000","35.91025","0.00456"
"431.42400","35.95222","0.00495"
"431.92800","35.99426","0.00473"
"432.43200","36.03623","0.00523"
"432.93600","36.07826","0.00544"
"433.44000","36.12029","0.00547"
"433.94400","36.16227","0.00572"
"434.44800","36.20418","0.00615"
"434.95200","36.24621","0.00582"
"435.45600","36.28818","0.00597"
"435.96000","36.33021","0.00571"
"436.46400","36.37225","0.00618"
"436.96800","36.41416","0.00599"
"437.47200","36.45619","0.00674"
"437.97600","36.49828","0.00554"
"438.48000","36.54020","0.00544"
"438.98400","36.58223","0.00504"
"439.48800","36.62426","0.00535"
"439.99200","36.66629","0.00458"
"440.49600","36.70826","0.00488"
"441.00000","36.75024","0.00478"
"441.50400","36.79227","0.00496"
"442.00800","36.83424","0.00498"
"442.51200","36.87615","0.00495"
"443.01600","36.91824","0.00499"
"443.52000","36.96016","0.00483"
"444.02400","37.00219","0.00506"
"444.52800","37.04422","0.00502"
"445.03200","37.08625","0.00498"
"445.53600","37.12817","0.00501"
"446.04000","37.17026","0.00508"
"446.54400","37.21223","0.00514"
"447.04800","37.25426","0.00484"
"447.55200","37.29623","0.00577"
"448.05600","37.33820","0.00546"
"448.56000","37.38024","0.00556"
"449.06400","37.42221","0.00539"
"449.56800","37.46430","0.00572"
"450.07200","37.50621","0.00554"
"450.57600","37.54818","0.00598"
"451.08000","37.59016","0.00567"
"451.58400","37.63225","0.00563"
"452.08800","37.67422","0.00590"
"452.59200","37.71619","0.00596"
"453.09600","37.75823","0.00559"
"453.60000","37.80026","0.00545"
"454.10400","37.84223","0.00594"
"454.60800","37.88426","0.00641"
"455.11200","37.92624","0.00601"
"455.61600","37.96821","0.00617"
"456.12000","38.01024","0.00587"
"456.62400","38.05227","0.00626"
"457.12800","38.09425","0.00642"
"457.63200","38.13622","0.00644"
"458.13600","38.17819","0.00654"
"458.64000","38.22022","0.00505"
"459.14400","38.26213","0.00635"
"459.64800","38.30416","0.00622"
"460.15200","38.34620","0.00631"
"460.65600","38.38823","0.00626"
"461.16000","38.43020","0.00582"
"461.66400","38.47223","0.00620"
"462.16800","38.51426","0.00552"
"462.67200","38.55630","0.00588"
"463.17600","38.59821","0.00620"
"463.68000","38.64024","0.00614"
"464.18400","38.68227","0.00625"
"464.68800","38.72431","0.00634"
"465.19200","38.76622","0.00622"
"465.69600","38.80819","0.00656"
"466.20000","38.85022","0.00650"
"466.70400","38.89219","0.00654"
"467.20800","38.93417","0.00699"
"467.71200","38.97620","0.00671"
"468.21600","39.01823","0.00696"
"468.72000","39.06020","0.00689"
"469.22400","39.10223","0.00753"
"469.72800","39.14420","0.00763"
"470.23200","39.18624","0.00734"
"470.73600","39.22827","0.00744"
"471.24000","39.27018","0.00773"
"471.74400","39.31221","0.00801"
"472.24800","39.35425","0.00747"
"472.75200","39.39621","0.00834"
"473.25600","39.43819","0.00804"
"473.76000","39.48022","0.00788"
"474.26400","39.52225","0.00819"
"474.76800","39.56417","0.00826"
"475.27200","39.60620","0.00897"
"475.77600","39.64817","0.00860"
"476.28000","39.69020","0.00873"
"476.78400","39.73223","0.00868"
"477.28800","39.77427","0.00911"
"477.79200","39.81618","0.00959"
"478.29600","39.85827","0.00977"
"478.80000","39.90025","0.00941"
"479.30400","39.94228","0.00916"
"479.80800","39.98419","0.00974"
"480.31200","40.02628","0.00990"
"480.81600","40.06820","0.00927"
"481.32000","40.11022","0.00888"
"481.82400","40.15220","0.00854"
"482.32800","40.19423","0.00887"
"482.83200","40.23615","0.00894"
"483.33600","40.27823","0.00927"
"483.84000","40.32014","0.01000"
"484.34400","40.36212","0.00992"
"484.84800","40.40421","0.00921"
"485.35200","40.44624","0.00883"
"485.85600","40.48821","0.00961"
"486.36000","40.53025","0.00976"
"486.86400","40.57222","0.01033"
"487.36800","40.61425","0.00980"
"487.87200","40.65622","0.00943"
"488.37600","40.69826","0.00988"
"488.88000","40.74023","0.01015"
"489.38400","40.78226","0.00369"
"489.88800","40.82423","0.00167"
"490.39200","40.86621","0.00061"
"490.89600","40.90812","0.00143"
"491.40000","40.95021","0.00115"
"491.90400","40.99218","0.00049"
"492.40800","41.03421","0.00111"
"492.91200","41.07619","0.00114"
"493.41600","41.11828","0.00164"
"493.92000","41.16025","0.00067"
"494.42400","41.20222","0.00098"
"494.92800","41.24431","0.00108"
"495.43200","41.28622","0.00064"
"495.93600","41.32826","0.00123"
"496.44000","41.37023","0.00109"
"496.94400","41.41227","0.00073"
"497.44800","41.45424","0.00061"
"497.95200","41.49621","0.00056"
"498.45600","41.53818","0.00111"
"498.96000","41.58021","0.00063"
"499.46400","41.62218","0.00094"
"499.96800","41.66421","0.00121"
"500.47200","41.70619","0.00123"
"500.97600","41.74828","0.00122"
"501.48000","41.79020","0.00079"
"501.98400","41.83229","0.00095"
"502.48800","41.87426","0.00098"
"502.99200","41.91629","0.00105"
"503.49600","41.95820","0.00103"
"504.00000","42.00029","0.00088"
"504.50400","42.04221","0.00084"
"505.00800","42.08418","0.00115"
"505.51200","42.12621","0.00082"
"506.01600","42.16824","0.00107"
"506.52000","42.21015","0.00108"
"507.02400","42.25219","0.00141"
"507.52800","42.29422","0.00103"
"508.03200","42.33619","0.00101"
"508.53600","42.37816","0.00105"
"509.04000","42.42026","0.00106"
"509.54400","42.46223","0.00126"
"510.04800","42.50426","0.00097"
"510.55200","42.54623","0.00107"
"511.05600","42.58826","0.00144"
"511.56000","42.63023","0.00110"
"512.06400","42.67227","0.00123"
"512.56800","42.71424","0.00105"
"513.07200","42.75621","0.00097"
"513.57600","42.79824","0.00116"
"514.08000","42.84021","0.00102"
"514.58400","42.88219","0.00073"
"515.08800","42.92422","0.00097"
"515.59200","42.96619","0.00105"
"516.09600","43.00822","0.00124"
"516.60000","43.05020","0.00103"
"517.10400","43.09217","0.00104"
"517.60800","43.13427","0.00114"
"518.11200","43.17629","0.00101"
"518.61600","43.21827","0.00108"
"519.12000","43.26023","0.00108"
"519.62400","43.30227","0.00080"
"520.12800","43.34424","0.00107"
"520.63200","43.38622","0.00085"
"521.13600","43.42825","0.00086"
"521.64000","43.47022","0.00080"
"522.14400","43.51219","0.00088"
"522.64800","43.55423","0.00115"
"523.15200","43.59614","0.00123"
"523.65600","43.63816","0.00118"
"524.16000","43.68020","0.00075"
"524.66400","43.72223","0.00085"
"525.16800","43.76420","0.00113"
"525.67200","43.80623","0.00076"
"526.17600","43.84827","0.00094"
"526.68000","43.89024","0.00137"
"527.18400","43.93221","0.00093"
"527.68800","43.97424","0.00096"
"528.19200","44.01628","0.00066"
"528.69600","44.05825","0.00102"
"529.20000","44.10016","0.00087"
"529.70400","44.14219","0.00095"
"530.20800","44.18416","0.00115"
"530.71200","44.22614","0.00079"
"531.21600","44.26817","0.00065"
"531.72000","44.31020","0.00074"
"532.22400","44.35223","0.00067"
"532.72800","44.39426","0.00112"
"533.23200","44.43623","0.00132"
"533.73600","44.47821","0.00100"
"534.24000","44.52024","0.00080"
"534.74400","44.56222","0.00135"
"535.24800","44.60424","0.00097"
"535.75200","44.64622","0.00101"
"536.25600","44.68825","0.00119"
"536.76000","44.73022","0.00126"
"537.26400","44.77225","0.00098"
"537.76800","44.81423","0.00105"
"538.27200","44.85620","0.00113"
"538.77600","44.89817","0.00128"
"539.28000","44.94021","0.00116"
"539.78400","44.98218","0.00135"
"540.28800","45.02421","0.00084"
"540.79200","45.06618","0.00112"
"541.29600","45.10822","0.00134"
"541.80000","45.15024","0.00132"
"542.30400","45.19222","0.00139"
"542.80800","45.23419","0.00151"
"543.31200","45.27628","0.00126"
"543.81600","45.31820","0.00128"
"544.32000","45.36029","0.00096"
"544.82400","45.40220","0.00127"
"545.32800","45.44417","0.00110"
"545.83200","45.48621","0.00164"
"546.33600","45.52818","0.00126"
"546.84000","45.57015","0.00122"
"547.34400","45.61218","0.00144"
"547.84800","45.65415","0.00134"
"548.35200","45.69618","0.00110"
"548.85600","45.73822","0.00133"
"549.36000","45.78025","0.00147"
"549.86400","45.82222","0.00129"
"550.36800","45.86425","0.00134"
"550.87200","45.90623","0.00147"
"551.37600","45.94820","0.00149"
"551.88000","45.99023","0.00142"
"552.38400","46.03226","0.00152"
"552.88800","46.07423","0.00146"
"553.39200","46.11621","0.00144"
"553.89600","46.15824","0.00159"
"554.40000","46.20015","0.00132"
"554.90400","46.24218","0.00149"
"555.40800","46.28415","0.00152"
"555.91200","46.32619","0.00156"
"556.41600","46.36822","0.00150"
"556.92000","46.41025","0.00124"
"557.42400","46.45222","0.00151"
"557.92800","46.49425","0.00142"
"558.43200","46.53623","0.00126"
"558.93600","46.57826","0.00138"
"559.44000","46.62023","0.00170"
"559.94400","46.66226","0.00124"
"560.44800","46.70417","0.00147"
"560.95200","46.74627","0.00126"
"561.45600","46.78824","0.00136"
"561.96000","46.83022","0.00147"
"562.46400","46.87218","0.00174"
"562.96800","46.91422","0.00153"
"563.47200","46.95618","0.00146"
"563.97600","46.99822","0.00236"
"564.48000","47.04019","0.00187"
"564.98400","47.08229","0.00162"
"565.48800","47.12426","0.00157"
"565.99200","47.16629","0.00170"
"566.49600","47.20826","0.00157"
"567.00000","47.25029","0.00150"
"567.50400","47.29221","0.00165"
"568.00800","47.33424","0.00170"
"568.51200","47.37621","0.00181"
"569.01600","47.41824","0.00148"
"569.52000","47.46027","0.00126"
"570.02400","47.50218","0.00144"
"570.52800","47.54416","0.00132"
"571.03200","47.58613","0.00166"
"571.53600","47.62817","0.00150"
"572.04000","47.67019","0.00133"
"572.54400","47.71223","0.00188"
"573.04800","47.75426","0.00182"
"573.55200","47.79623","0.00189"
"574.05600","47.83826","0.00177"
"574.56000","47.88023","0.00179"
"575.06400","47.92226","0.00206"
"575.56800","47.96430","0.00179"
"576.07200","48.00621","0.00170"
"576.57600","48.04824","0.00150"
"577.08000","48.09022","0.00214"
"577.58400","48.13218","0.00165"
"578.08800","48.17422","0.00194"
"578.59200","48.21619","0.00148"
"579.09600","48.25816","0.00220"
"579.60000","48.30019","0.00177"
"580.10400","48.34217","0.00202"
"580.60800","48.38426","0.00219"
"581.11200","48.42624","0.00178"
"581.61600","48.46826","0.00199"
"582.12000","48.51024","0.00204"
"582.62400","48.55227","0.00186"
"583.12800","48.59418","0.00201"
"583.63200","48.63633","0.00172"
"584.13600","48.67818","0.00231"
"584.64000","48.72028","0.00218"
"585.14400","48.76225","0.00241"
"585.64800","48.80416","0.00236"
"586.15200","48.84614","0.00233"
"586.65600","48.88823","0.00249"
"587.16000","48.93014","0.00222"
"587.66400","48.97218","0.00246"
"588.16800","49.01415","0.00271"
"588.67200","49.05624","0.00217"
"589.17600","49.09821","0.00220"
"589.68000","49.14024","0.00188"
"590.18400","49.18227","0.00236"
"590.68800","49.22424","0.00250"
"591.19200","49.26622","0.00244"
"591.69600","49.30825","0.00237"
"592.20000","49.35028","0.00246"
"592.70400","49.39219","0.00251"
"593.20800","49.43423","0.00303"
"593.71200","49.47620","0.00255"
"594.21600","49.51817","0.00288"
"594.72000","49.56020","0.00291"
"595.22400","49.60217","0.00283"
"595.72800","49.64421","0.00310"
"596.23200","49.68624","0.00297"
"596.73600","49.72827","0.00301"
"597.24000","49.77030","0.00256"
"597.74400","49.81222","0.00301"
"598.24800","49.85425","0.00340"
"598.75200","49.89622","0.00356"
"599.25600","49.93826","0.00314"
"599.76000","49.98023","0.00342"
"600.26400","50.02225","0.00313"
"600.76800","50.06423","0.00311"
"601.27200","50.10626","0.00402"
"601.77600","50.14824","0.00335"
"602.28000","50.19020","0.00344"
"602.78400","50.23218","0.00360"
"603.28800","50.27421","0.00359"
"603.79200","50.31618","0.00401"
"604.29600","50.35827","0.00381"
"604.80000","50.40018","0.00415"
"605.30400","50.44233","0.00378"
"605.80800","50.48425","0.00361"
"606.31200","50.52622","0.00377"
"606.81600","50.56825","0.00372"
"607.32000","50.61023","0.00419"
"607.82400","50.65226","0.00381"
"608.32800","50.69423","0.00388"
"608.83200","50.73620","0.00419"
"609.33600","50.77824","0.00421"
"609.84000","50.82021","0.00443"
"610.34400","50.86218","0.00458"
"610.84800","50.90416","0.00453"
"611.35200","50.94618","0.00444"
"611.85600","50.98822","0.00449"
"612.36000","51.03025","0.00467"
"612.86400","51.07222","0.00499"
"613.36800","51.11425","0.00477"
"613.87200","51.15623","0.00501"
"614.37600","51.19826","0.00489"
"614.88000","51.24023","0.00484"
"615.38400","51.28226","0.00510"
"615.88800","51.32423","0.00551"
"616.39200","51.36626","0.00515"
"616.89600","51.40824","0.00533"
"617.40000","51.45021","0.00550"
"617.90400","51.49218","0.00532"
"618.40800","51.53415","0.00582"
"618.91200","51.57624","0.00601"
"619.41600","51.61822","0.00526"
"619.92000","51.66019","0.00604"
"620.42400","51.70216","0.00582"
"620.92800","51.74425","0.00605"
"621.43200","51.78623","0.00578"
"621.93600","51.82826","0.00627"
"622.44000","51.87023","0.00632"
"622.94400","51.91232","0.00670"
"623.44800","51.95424","0.00636"
"623.95200","51.99627","0.00657"
"624.45600","52.03818","0.00668"
"624.96000","52.08021","0.00697"
"625.46400","52.12218","0.00721"
"625.96800","52.16428","0.00712"
"626.47200","52.20612","0.00729"
"626.97600","52.24822","0.00738"
"627.48000","52.29019","0.00766"
"627.98400","52.33223","0.00794"
"628.48800","52.37420","0.00757"
"628.99200","52.41623","0.00802"
"629.49600","52.45826","0.00807"
"630.00000","52.50023","0.00800"
"630.50400","52.54226","0.00735"
"631.00800","52.58424","0.00802"
"631.51200","52.62621","0.00825"
"632.01600","52.66824","0.00836"
"632.52000","52.71021","0.00888"
"633.02400","52.75219","0.00869"
"633.52800","52.79416","0.00877"
"634.03200","52.83619","0.00856"
"634.53600","52.87816","0.00932"
"635.04000","52.92019","0.00952"
"635.54400","52.96223","0.00955"
"636.04800","53.00420","0.00928"
"636.55200","53.04623","0.00959"
"637.05600","53.08820","0.00972"
"637.56000","53.13023","0.01024"
"638.06400","53.17226","0.01054"
"638.56800","53.21424","0.01131"
"639.07200","53.25621","0.01062"
"639.57600","53.29831","0.01137"
"640.08000","53.34027","0.01156"
"640.58400","53.38225","0.01179"
"641.08800","53.42416","0.01233"
"641.59200","53.46619","0.01216"
"642.09600","53.50817","0.01245"
"642.60000","53.55019","0.01327"
"643.10400","53.59217","0.01328"
"643.60800","53.63420","0.01366"
"644.11200","53.67618","0.01360"
"644.61600","53.71827","0.01384"
"645.12000","53.76024","0.01477"
"645.62400","53.80227","0.01454"
"646.12800","53.84424","0.01538"
"646.63200","53.88627","0.01605"
"647.13600","53.92819","0.01358"
"647.64000","53.97028","0.01344"
"648.14400","54.01225","0.01385"
"648.64800","54.05422","0.01338"
"649.15200","54.09619","0.01384"
"649.65600","54.13817","0.01386"
"650.16000","54.18014","0.01461"
"650.66400","54.22218","0.01552"
"651.16800","54.26420","0.01514"
"651.67200","54.30624","0.01588"
"652.17600","54.34821","0.01566"
"652.68000","54.39018","0.01651"
"653.18400","54.43221","0.01729"
"653.68800","54.47425","0.01743"
"654.19200","54.51622","0.01740"
"654.69600","54.55825","0.01854"
"655.20000","54.60028","0.01813"
"655.70400","54.64226","0.01863"
"656.20800","54.68428","0.01908"
"656.71200","54.72620","0.01920"
"657.21600","54.76823","0.01987"
"657.72000","54.81020","0.02026"
"658.22400","54.85224","0.02073"
"658.72800","54.89415","0.02111"
"659.23200","54.93618","0.02136"
"659.73600","54.97821","0.02164"
"660.24000","55.02030","0.02254"
"660.74400","55.06227","0.02288"
"661.24800","55.10425","0.02277"
"661.75200","55.14622","0.02355"
"662.25600","55.18826","0.02386"
"662.76000","55.23022","0.02495"
"663.26400","55.27226","0.02489"
"663.76800","55.31423","0.02511"
"664.27200","55.35626","0.02603"
"664.77600","55.39823","0.02672"
"665.28000","55.44020","0.02765"
"665.78400","55.48218","0.02805"
"666.28800","55.52415","0.02844"
"666.79200","55.56618","0.02888"
"667.29600","55.60821","0.02967"
"667.80000","55.65018","0.03027"
"668.30400","55.69228","0.03104"
"668.80800","55.73425","0.03123"
"669.31200","55.77628","0.03208"
"669.81600","55.81819","0.03346"
"670.32000","55.86023","0.03391"
"670.82400","55.90226","0.03424"
"671.32800","55.94429","0.03494"
"671.83200","55.98620","0.03511"
"672.33600","56.02824","0.03628"
"672.84000","56.07021","0.03801"
"673.34400","56.11218","0.03814"
"673.84800","56.15415","0.03978"
"674.35200","56.19619","0.04121"
"674.85600","56.23816","0.04210"
"675.36000","56.28019","0.04323"
"675.86400","56.32222","0.04440"
"676.36800","56.36425","0.04499"
"676.87200","56.40622","0.04554"
"677.37600","56.44826","0.04731"
"677.88000","56.49023","0.04717"
"678.38400","56.53220","0.04724"
"678.88800","56.57423","0.04842"
"679.39200","56.61620","0.04981"
"679.89600","56.65824","0.05021"
"680.40000","56.70027","0.05136"
"680.90400","56.74224","0.05223"
"681.40800","56.78415","0.05398"
"681.91200","56.82619","0.05528"
"682.41600","56.86816","0.05709"
"682.92000","56.91019","0.05828"
"683.42400","56.95222","0.06084"
"683.92800","56.99426","0.06282"
"684.43200","57.03622","0.06416"
"684.93600","57.07826","0.06688"
"685.44000","57.12023","0.06786"
"685.94400","57.16227","0.06885"
"686.44800","57.20424","0.06044"
"686.95200","57.24627","0.05876"
"687.45600","57.28824","0.05760"
"687.96000","57.33021","0.05709"
"688.46400","57.37218","0.05680"
"688.96800","57.41422","0.05577"
"689.47200","57.45619","0.05512"
"689.97600","57.49821","0.05554"
"690.48000","57.54013","0.05751"
"690.98400","57.58216","0.05805"
"691.48800","57.62420","0.06100"
"691.99200","57.66629","0.06154"
"692.49600","57.70820","0.06390"
"693.00000","57.75023","0.06548"
"693.50400","57.79227","0.06664"
"694.00800","57.83424","0.06807"
"694.51200","57.87621","0.06987"
"695.01600","57.91824","0.07117"
"695.52000","57.96027","0.07245"
"696.02400","58.00225","0.07321"
"696.52800","58.04422","0.07449"
"697.03200","58.08619","0.07587"
"697.53600","58.12816","0.07686"
"698.04000","58.17019","0.07889"
"698.54400","58.21217","0.08011"
"699.04800","58.25420","0.08219"
"699.55200","58.29623","0.08517"
"700.05600","58.33820","0.08689"
"700.56000","58.38029","0.08902"
"701.06400","58.42220","0.09144"
"701.56800","58.46424","0.09316"
"702.07200","58.50621","0.09466"
"702.57600","58.54824","0.09620"
"703.08000","58.59021","0.09721"
"703.58400","58.63225","0.09847"
"704.08800","58.67422","0.09967"
"704.59200","58.71626","0.10063"
"705.09600","58.75822","0.10154"
"705.60000","58.80020","0.10323"
"706.10400","58.84217","0.10442"
"706.60800","58.88414","0.10504"
"707.11200","58.92618","0.10657"
"707.61600","58.96827","0.10812"
"708.12000","59.01018","0.10963"
"708.62400","59.05233","0.11152"
"709.12800","59.09424","0.11294"
"709.63200","59.13627","0.11444"
"710.13600","59.17825","0.11573"
"710.64000","59.22022","0.11668"
"711.14400","59.26220","0.11808"
"711.64800","59.30428","0.11926"
"712.15200","59.34619","0.11748"
"712.65600","59.38823","0.11671"
"713.16000","59.43020","0.11714"
"713.66400","59.47217","0.11519"
"714.16800","59.51420","0.11351"
"714.67200","59.55624","0.10756"
"715.17600","59.59821","0.10824"
"715.68000","59.64024","0.10773"
"716.18400","59.68227","0.10754"
"716.68800","59.72419","0.10791"
"717.19200","59.76621","0.10995"
"717.69600","59.80825","0.11195"
"718.20000","59.85022","0.11320"
"718.70400","59.89220","0.11416"
"719.20800","59.93422","0.11431"
"719.71200","59.97626","0.11491"
"720.21600","60.01823","0.11566"
"720.72000","60.06014","0.11731"
"721.22400","60.10223","0.11937"
"721.72800","60.14421","0.12117"
"722.23200","60.18618","0.12186"
"722.73600","60.22821","0.12209"
"723.24000","60.27019","0.12281"
"723.74400","60.31221","0.12359"
"724.24800","60.35431","0.12433"
"724.75200","60.39622","0.12656"
"725.25600","60.43825","0.12736"
"725.76000","60.48022","0.12951"
"726.26400","60.52226","-0.00143"
"726.76800","60.56423","-0.00019"
"727.27200","60.60620","0.00001"
"727.77600","60.64823","0.00064"
"728.28000","60.69020","0.00100"
"728.78400","60.73218","0.00056"
"729.28800","60.77421","0.00108"
"729.79200","60.81618","0.00121"
"730.29600","60.85821","0.00115"
"730.80000","60.90019","0.00077"
"731.30400","60.94221","0.00072"
"731.80800","60.98419","0.00094"
"732.31200","61.02622","0.00086"
"732.81600","61.06826","0.00042"
"733.32000","61.11029","0.00077"
"733.82400","61.15220","0.00065"
"734.32800","61.19423","0.00076"
"734.83200","61.23626","0.00099"
"735.33600","61.27823","0.00018"
"735.84000","61.32021","0.00116"
"736.34400","61.36218","0.00104"
"736.84800","61.40421","0.00078"
"737.35200","61.44619","0.00056"
"737.85600","61.48816","0.00059"
"738.36000","61.53019","0.00092"
"738.86400","61.57222","0.00099"
"739.36800","61.61419","0.00079"
"739.87200","61.65622","0.00053"
"740.37600","61.69820","0.00122"
"740.88000","61.74029","0.00115"
"741.38400","61.78226","0.00110"
"741.88800","61.82429","0.00074"
"742.39200","61.86620","0.00122"
"742.89600","61.90823","0.00131"
"743.40000","61.95027","0.00062"
"743.90400","61.99224","0.00108"
"744.40800","62.03415","0.00076"
"744.91200","62.07624","0.00099"
"745.41600","62.11816","0.00139"
"745.92000","62.16025","0.00068"
"746.42400","62.20222","0.00129"
"746.92800","62.24419","0.00121"
"747.43200","62.28616","0.00088"
"747.93600","62.32826","0.00123"
"748.44000","62.37023","0.00127"
"748.94400","62.41220","0.00129"
"749.44800","62.45417","0.00074"
"749.95200","62.49627","0.00078"
"750.45600","62.53823","0.00145"
"750.96000","62.58027","0.00082"
"751.46400","62.62224","0.00061"
"751.96800","62.66421","0.00089"
"752.47200","62.70619","0.00080"
"752.97600","62.74821","0.00127"
"753.48000","62.79013","0.00143"
"753.98400","62.83222","0.00044"
"754.48800","62.87419","0.00125"
"754.97600","62.91491","0.00109"