File: Force_trajectories/161223/Specimen_RawData_8.csv
End date,"12/23/2016"
Specimen label,"24DG_90"
Maximum Load,"1.01062",N

Time,Extension,Load
(s),(mm),(N)
"0.00000","0.00000","0.00002"
"0.31800","0.02595","0.00096"
"0.63600","0.05321","0.00210"
"0.95400","0.07964","0.00207"
"1.27200","0.10619","0.00233"
"1.59000","0.13267","0.00314"
"1.90800","0.15910","0.00317"
"2.22600","0.18565","0.00372"
"2.54400","0.21207","0.00377"
"2.86200","0.23874","0.00439"
"3.18000","0.26517","0.00432"
"3.49800","0.29159","0.00453"
"3.81600","0.31820","0.00476"
"4.13400","0.34463","0.00526"
"4.45200","0.37111","0.00579"
"4.77000","0.39760","0.00586"
"5.08800","0.42409","0.00601"
"5.40600","0.45063","0.00583"
"5.72400","0.47712","0.00631"
"6.04200","0.50367","0.00640"
"6.36000","0.53009","0.00673"
"6.67800","0.55658","0.00657"
"6.99600","0.58313","0.00703"
"7.31400","0.60961","0.00744"
"7.63200","0.63616","0.00660"
"7.95000","0.66259","0.00724"
"8.26800","0.68913","0.00714"
"8.58600","0.71562","0.00729"
"8.90400","0.74217","0.00778"
"9.22200","0.76865","0.00795"
"9.54000","0.79514","0.00838"
"9.85800","0.82169","0.00797"
"10.17600","0.84817","0.00814"
"10.49400","0.87466","0.00833"
"10.81200","0.90109","0.00843"
"11.13000","0.92752","0.00828"
"11.44800","0.95418","0.00855"
"11.76600","0.98061","0.00873"
"12.08400","1.00715","0.00887"
"12.40200","1.03370","0.00871"
"12.72000","1.06007","0.00856"
"13.03800","1.08667","0.00884"
"13.35600","1.11310","0.00903"
"13.67400","1.13965","0.00931"
"13.99200","1.16619","0.00938"
"14.31000","1.19262","0.00921"
"14.62800","1.21923","0.00928"
"14.94600","1.24560","0.00921"
"15.26400","1.27214","0.00916"
"15.58200","1.29863","0.00943"
"15.90000","1.32512","0.00981"
"16.21800","1.35166","0.00961"
"16.53600","1.37809","0.00973"
"16.85400","1.40464","0.00977"
"17.17200","1.43112","0.00974"
"17.49000","1.45761","0.00998"
"17.80800","1.48416","0.01001"
"18.12600","1.51058","0.01006"
"18.44400","1.53713","0.01049"
"18.76200","1.56362","0.01033"
"19.08000","1.59016","0.01004"
"19.39800","1.61665","0.01015"
"19.71600","1.64308","0.01022"
"20.03400","1.66968","0.01064"
"20.35200","1.69611","0.01019"
"20.67000","1.72266","0.00997"
"20.98800","1.74914","0.01035"
"21.30600","1.77557","0.01056"
"21.62400","1.80212","0.01030"
"21.94200","1.82866","0.01056"
"22.26000","1.85521","0.01045"
"22.57800","1.88164","0.01069"
"22.89600","1.90812","0.01062"
"23.21400","1.93461","0.01051"
"23.53200","1.96110","0.01049"
"23.85000","1.98764","0.01034"
"24.16800","2.01413","0.01070"
"24.48600","2.04062","0.01079"
"24.80400","2.06716","0.01059"
"25.12200","2.09359","0.01068"
"25.44000","2.12014","0.01081"
"25.75800","2.14662","0.01038"
"26.07600","2.17311","0.01073"
"26.39400","2.19966","0.01069"
"26.71200","2.22608","0.01060"
"27.03000","2.25263","0.01079"
"27.34800","2.27912","0.01096"
"27.66600","2.30566","0.01102"
"27.98400","2.33221","0.01104"
"28.30200","2.35864","0.01097"
"28.62000","2.38512","0.01077"
"28.93800","2.41161","0.01099"
"29.25600","2.43816","0.01040"
"29.57400","2.46470","0.01075"
"29.89200","2.49113","0.01081"
"30.21000","2.51762","0.01160"
"30.52800","2.54404","0.01134"
"30.84600","2.57071","0.01106"
"31.16400","2.59714","0.01077"
"31.48200","2.62362","0.01098"
"31.80000","2.65011","0.01131"
"32.11800","2.67660","0.01128"
"32.43600","2.70314","0.01091"
"32.75400","2.72957","0.01166"
"33.07200","2.75618","0.01091"
"33.39000","2.78266","0.01111"
"33.70800","2.80915","0.01123"
"34.02600","2.83570","0.01112"
"34.34400","2.86207","0.01135"
"34.66200","2.88861","0.01127"
"34.98000","2.91510","0.01138"
"35.29800","2.94165","0.01092"
"35.61600","2.96813","0.01136"
"35.93400","2.99462","0.01129"
"36.25200","3.02111","0.01144"
"36.57000","3.04765","0.01147"
"36.88800","3.07408","0.01136"
"37.20600","3.10063","0.01153"
"37.52400","3.12705","0.01140"
"37.84200","3.15366","0.01164"
"38.16000","3.18015","0.01161"
"38.47800","3.20663","0.01132"
"38.79600","3.23318","0.01146"
"39.11400","3.25955","0.01128"
"39.43200","3.28615","0.01142"
"39.75000","3.31264","0.01130"
"40.06800","3.33913","0.01131"
"40.38600","3.36567","0.01142"
"40.70400","3.39210","0.01175"
"41.02200","3.41865","0.01143"
"41.34000","3.44513","0.01156"
"41.65800","3.47162","0.01148"
"41.97600","3.49811","0.01171"
"42.29400","3.52465","0.01196"
"42.61200","3.55120","0.01183"
"42.93000","3.57763","0.01151"
"43.24800","3.60411","0.01146"
"43.56600","3.63060","0.01170"
"43.88400","3.65709","0.01130"
"44.20200","3.68363","0.01173"
"44.52000","3.71012","0.01183"
"44.83800","3.73667","0.01237"
"45.15600","3.76315","0.01197"
"45.47400","3.78964","0.01205"
"45.79200","3.81613","0.01189"
"46.11000","3.84255","0.01187"
"46.42800","3.86916","0.01209"
"46.74600","3.89559","0.01196"
"47.06400","3.92219","0.01226"
"47.38200","3.94868","0.01198"
"47.70000","3.97511","0.01192"
"48.01800","4.00165","0.01201"
"48.33600","4.02814","0.01194"
"48.65400","4.05469","0.01203"
"48.97200","4.08111","0.01196"
"49.29000","4.10760","0.01203"
"49.60800","4.13415","0.01232"
"49.92600","4.16057","0.01213"
"50.24400","4.18718","0.01216"
"50.56200","4.21361","0.01199"
"50.88000","4.24009","0.01209"
"51.19800","4.26658","0.01230"
"51.51600","4.29313","0.01242"
"51.83400","4.31961","0.01201"
"52.15200","4.34610","0.01224"
"52.47000","4.37259","0.01251"
"52.78800","4.39913","0.01257"
"53.10600","4.42556","0.01213"
"53.42400","4.45217","0.01200"
"53.74200","4.47865","0.01274"
"54.06000","4.50514","0.01215"
"54.37800","4.53169","0.01245"
"54.69600","4.55812","0.01286"
"55.01400","4.58460","0.01263"
"55.33200","4.61103","0.01283"
"55.65000","4.63763","0.01294"
"55.96800","4.66418","0.01281"
"56.28600","4.69061","0.01264"
"56.60400","4.71715","0.01273"
"56.92200","4.74352","0.01313"
"57.24000","4.77019","0.01295"
"57.55800","4.79662","0.01234"
"57.87600","4.82316","0.01316"
"58.19400","4.84959","0.01311"
"58.51200","4.87608","0.01288"
"58.83000","4.90268","0.01286"
"59.14800","4.92911","0.01294"
"59.46600","4.95566","0.01274"
"59.78400","4.98214","0.01318"
"60.10200","5.00857","0.01301"
"60.42000","5.03512","0.01334"
"60.73800","5.06160","0.01274"
"61.05600","5.08815","0.01327"
"61.37400","5.11464","0.01338"
"61.69200","5.14106","0.01348"
"62.01000","5.16767","0.01353"
"62.32800","5.19410","0.01356"
"62.64600","5.22058","0.01341"
"62.96400","5.24713","0.01329"
"63.28200","5.27362","0.01391"
"63.60000","5.30022","0.01339"
"63.91800","5.32659","0.01362"
"64.23600","5.35314","0.01372"
"64.55400","5.37962","0.01409"
"64.87200","5.40611","0.01402"
"65.19000","5.43266","0.01365"
"65.50800","5.45908","0.01391"
"65.82600","5.48563","0.01457"
"66.14400","5.51212","0.01373"
"66.46200","5.53860","0.01385"
"66.78000","5.56509","0.01434"
"67.09800","5.59152","0.01395"
"67.41600","5.61812","0.01405"
"67.73400","5.64461","0.01399"
"68.05200","5.67110","0.01406"
"68.37000","5.69764","0.01401"
"68.68800","5.72413","0.01394"
"69.00600","5.75062","0.01397"
"69.32400","5.77710","0.01446"
"69.64200","5.80359","0.01438"
"69.96000","5.83014","0.01433"
"70.27800","5.85662","0.01443"
"70.59600","5.88317","0.01474"
"70.91400","5.90966","0.01472"
"71.23200","5.93608","0.01469"
"71.55000","5.96263","0.01475"
"71.86800","5.98912","0.01437"
"72.18600","6.01566","0.01460"
"72.50400","6.04209","0.01441"
"72.82200","6.06864","0.01422"
"73.14000","6.09512","0.01440"
"73.45800","6.12167","0.01487"
"73.77600","6.14816","0.01458"
"74.09400","6.17458","0.01453"
"74.41200","6.20119","0.01453"
"74.73000","6.22762","0.01494"
"75.04800","6.25416","0.01458"
"75.36600","6.28065","0.01495"
"75.68400","6.30702","0.01523"
"76.00200","6.33362","0.01524"
"76.32000","6.36011","0.01485"
"76.63800","6.38660","0.01533"
"76.95600","6.41315","0.01523"
"77.27400","6.43963","0.01501"
"77.59200","6.46612","0.01504"
"77.91000","6.49261","0.01555"
"78.22800","6.51915","0.01510"
"78.54600","6.54564","0.01548"
"78.86400","6.57207","0.01614"
"79.18200","6.59867","0.01542"
"79.50000","6.62516","0.01593"
"79.81800","6.65165","0.01551"
"80.13600","6.67813","0.01530"
"80.45400","6.70462","0.01567"
"80.77200","6.73117","0.01546"
"81.09000","6.75759","0.01540"
"81.40800","6.78414","0.01546"
"81.72600","6.81063","0.01574"
"82.04400","6.83711","0.01546"
"82.36200","6.86360","0.01524"
"82.68000","6.89009","0.01583"
"82.99800","6.91663","0.01623"
"83.31600","6.94306","0.01615"
"83.63400","6.96961","0.01627"
"83.95200","6.99615","0.01560"
"84.27000","7.02258","0.01628"
"84.58800","7.04913","0.01628"
"84.90600","7.07555","0.01600"
"85.22400","7.10216","0.01625"
"85.54200","7.12859","0.01596"
"85.86000","7.15513","0.01630"
"86.17800","7.18162","0.01668"
"86.49600","7.20811","0.01650"
"86.81400","7.23465","0.01661"
"87.13200","7.26114","0.01667"
"87.45000","7.28763","0.01665"
"87.76800","7.31411","0.01645"
"88.08600","7.34054","0.01687"
"88.40400","7.36715","0.01667"
"88.72200","7.39363","0.01657"
"89.04000","7.42012","0.01716"
"89.35800","7.44667","0.01713"
"89.67600","7.47303","0.01636"
"89.99400","7.49964","0.01699"
"90.31200","7.52607","0.01650"
"90.63000","7.55261","0.01650"
"90.94800","7.57910","0.01613"
"91.26600","7.60559","0.01627"
"91.58400","7.63213","0.01636"
"91.90200","7.65856","0.01657"
"92.22000","7.68517","0.01690"
"92.53800","7.71165","0.01736"
"92.85600","7.73814","0.01691"
"93.17400","7.76463","0.01729"
"93.49200","7.79111","0.01708"
"93.81000","7.81760","0.01691"
"94.12800","7.84415","0.01718"
"94.44600","7.87063","0.01682"
"94.76400","7.89718","0.01686"
"95.08200","7.92361","0.01737"
"95.40000","7.95015","0.01736"
"95.71800","7.97670","0.01731"
"96.03600","8.00313","0.01714"
"96.35400","8.02967","0.01714"
"96.67200","8.05610","0.01746"
"96.99000","8.08265","0.01773"
"97.30800","8.10907","0.01794"
"97.62600","8.13568","0.01828"
"97.94400","8.16217","0.01801"
"98.26200","8.18859","0.01781"
"98.58000","8.21520","0.01756"
"98.89800","8.24163","0.01768"
"99.21600","8.26818","0.01807"
"99.53400","8.29460","0.01806"
"99.85200","8.32109","0.01790"
"100.17000","8.34769","0.01856"
"100.48800","8.37406","0.01857"
"100.80600","8.40067","0.01829"
"101.12400","8.42710","0.01857"
"101.44200","8.45364","0.01893"
"101.76000","8.48019","0.01874"
"102.07800","8.50656","0.01945"
"102.39600","8.53316","0.01910"
"102.71400","8.55965","0.01957"
"103.03200","8.58619","0.01930"
"103.35000","8.61268","0.01989"
"103.66800","8.63911","0.01940"
"103.98600","8.66560","0.01951"
"104.30400","8.69214","0.02025"
"104.62200","8.71863","0.02016"
"104.94000","8.74518","0.02036"
"105.25800","8.77160","0.02058"
"105.57600","8.79815","0.02094"
"105.89400","8.82464","0.02133"
"106.21200","8.85118","0.02116"
"106.53000","8.87767","0.02152"
"106.84800","8.90410","0.02105"
"107.16600","8.93064","0.02123"
"107.48400","8.95713","0.02170"
"107.80200","8.98368","0.02142"
"108.12000","9.01010","0.02203"
"108.43800","9.03659","0.02211"
"108.75600","9.06314","0.02257"
"109.07400","9.08962","0.02259"
"109.39200","9.11617","0.02229"
"109.71000","9.14260","0.02290"
"110.02800","9.16914","0.02320"
"110.34600","9.19569","0.02342"
"110.66400","9.22212","0.02349"
"110.98200","9.24866","0.02337"
"111.30000","9.27509","0.02338"
"111.61800","9.30164","0.02372"
"111.93600","9.32818","0.02431"
"112.25400","9.35461","0.02421"
"112.57200","9.38116","0.02484"
"112.89000","9.40758","0.02487"
"113.20800","9.43413","0.02513"
"113.52600","9.46068","0.02464"
"113.84400","9.48710","0.02543"
"114.16200","9.51365","0.02547"
"114.48000","9.54008","0.02571"
"114.79800","9.56668","0.02577"
"115.11600","9.59311","0.02627"
"115.43400","9.61960","0.02669"
"115.75200","9.64614","0.02561"
"116.07000","9.67257","0.02611"
"116.38800","9.69918","0.02684"
"116.70600","9.72561","0.02665"
"117.02400","9.75209","0.02673"
"117.34200","9.77864","0.02696"
"117.66000","9.80512","0.02772"
"117.97800","9.83167","0.02766"
"118.29600","9.85816","0.02760"
"118.61400","9.88458","0.02825"
"118.93200","9.91113","0.02843"
"119.25000","9.93768","0.02836"
"119.56800","9.96410","0.02883"
"119.88600","9.99059","0.02863"
"120.20400","10.01714","0.02932"
"120.52200","10.04363","0.02920"
"120.84000","10.07005","0.02958"
"121.15800","10.09660","0.02943"
"121.47600","10.12309","0.02994"
"121.79400","10.14969","0.03002"
"122.11200","10.17618","0.02945"
"122.43000","10.20267","0.02975"
"122.74800","10.22915","0.03036"
"123.06600","10.25552","0.03022"
"123.38400","10.28218","0.03091"
"123.70200","10.30867","0.03075"
"124.02000","10.33516","0.03080"
"124.33800","10.36165","0.03109"
"124.65600","10.38807","0.03145"
"124.97400","10.41468","0.03182"
"125.29200","10.44110","0.03192"
"125.61000","10.46765","0.03104"
"125.92800","10.49414","0.03124"
"126.24600","10.52057","0.03160"
"126.56400","10.54717","0.03172"
"126.88200","10.57360","0.03232"
"127.20000","10.60015","0.03233"
"127.51800","10.62663","0.03236"
"127.83600","10.65312","0.03252"
"128.15400","10.67967","0.03213"
"128.47200","10.70609","0.03221"
"128.79000","10.73264","0.03269"
"129.10800","10.75913","0.03311"
"129.42600","10.78561","0.03293"
"129.74400","10.81216","0.03334"
"130.06200","10.83865","0.03343"
"130.38000","10.86513","0.03400"
"130.69800","10.89162","0.03390"
"131.01600","10.91817","0.03331"
"131.33400","10.94465","0.03424"
"131.65200","10.97108","0.03371"
"131.97000","10.99763","0.03372"
"132.28800","11.02411","0.03429"
"132.60600","11.05072","0.03409"
"132.92400","11.07715","0.03456"
"133.24200","11.10363","0.03419"
"133.56000","11.13018","0.03383"
"133.87800","11.15661","0.03268"
"134.19600","11.18315","0.03382"
"134.51400","11.20964","0.03362"
"134.83200","11.23613","0.03392"
"135.15000","11.26267","0.03350"
"135.46800","11.28910","0.03392"
"135.78600","11.31565","0.03350"
"136.10400","11.34207","0.03390"
"136.42200","11.36856","0.03428"
"136.74000","11.39517","0.03477"
"137.05800","11.42165","0.03534"
"137.37600","11.44814","0.03511"
"137.69400","11.47463","0.03537"
"138.01200","11.50111","0.03629"
"138.33000","11.52772","0.03598"
"138.64800","11.55409","0.03615"
"138.96600","11.58069","0.03636"
"139.28400","11.60712","0.03653"
"139.60200","11.63367","0.03691"
"139.92000","11.66016","0.03723"
"140.23800","11.68652","0.03741"
"140.55600","11.71313","0.03819"
"140.87400","11.73961","0.03848"
"141.19200","11.76616","0.03883"
"141.51000","11.79265","0.03879"
"141.82800","11.81914","0.03893"
"142.14600","11.84562","0.03947"
"142.46400","11.87205","0.03859"
"142.78200","11.89866","0.03949"
"143.10000","11.92520","0.03958"
"143.41800","11.95163","0.04029"
"143.73600","11.97812","0.04031"
"144.05400","12.00460","0.04130"
"144.37200","12.03121","0.04184"
"144.69000","12.05764","0.04181"
"145.00800","12.08412","0.04190"
"145.32600","12.11067","0.04337"
"145.64400","12.13715","0.04372"
"145.96200","12.16364","0.04449"
"146.28000","12.19007","0.04408"
"146.59800","12.21662","0.04542"
"146.91600","12.24316","0.04592"
"147.23400","12.26965","0.04638"
"147.55200","12.29614","0.04648"
"147.87000","12.32262","0.04768"
"148.18800","12.34911","0.04799"
"148.50600","12.37566","0.04892"
"148.82400","12.40208","0.04892"
"149.14200","12.42863","0.04968"
"149.46000","12.45506","0.05114"
"149.77800","12.48166","0.05145"
"150.09600","12.50815","0.05194"
"150.41400","12.53464","0.05295"
"150.73200","12.56112","0.05383"
"151.05000","12.58755","0.05442"
"151.36800","12.61416","0.05507"
"151.68600","12.64064","0.05600"
"152.00400","12.66713","0.05658"
"152.32200","12.69362","0.05751"
"152.64000","12.72010","0.05814"
"152.95800","12.74665","0.05888"
"153.27600","12.77314","0.05937"
"153.59400","12.79962","0.06012"
"153.91200","12.82617","0.06094"
"154.23000","12.85260","0.06177"
"154.54800","12.87914","0.06293"
"154.86600","12.90563","0.06257"
"155.18400","12.93212","0.06358"
"155.50200","12.95860","0.06443"
"155.82000","12.98509","0.06582"
"156.13800","13.01164","0.06683"
"156.45600","13.03813","0.06801"
"156.77400","13.06467","0.06917"
"157.09200","13.09110","0.06981"
"157.41000","13.11765","0.07051"
"157.72800","13.14413","0.07247"
"158.04600","13.17062","0.07316"
"158.36400","13.19716","0.07403"
"158.68200","13.22365","0.07470"
"159.00000","13.25014","0.07668"
"159.31800","13.27663","0.07755"
"159.63600","13.30311","0.07840"
"159.95400","13.32966","0.07955"
"160.27200","13.35614","0.08044"
"160.59000","13.38263","0.08117"
"160.90800","13.40912","0.08232"
"161.22600","13.43561","0.08225"
"161.54400","13.46215","0.08415"
"161.86200","13.48858","0.08438"
"162.18000","13.51513","0.08529"
"162.49800","13.54167","0.08526"
"162.81600","13.56810","0.08593"
"163.13400","13.59471","0.08713"
"163.45200","13.62113","0.08791"
"163.77000","13.64762","0.08911"
"164.08800","13.67411","0.08998"
"164.40600","13.70059","0.09083"
"164.72400","13.72714","0.09227"
"165.04200","13.75357","0.09310"
"165.36000","13.78017","0.09433"
"165.67800","13.80660","0.09565"
"165.99600","13.83315","0.09773"
"166.31400","13.85969","0.09934"
"166.63200","13.88606","0.10175"
"166.95000","13.91267","0.10206"
"167.26800","13.93909","0.10421"
"167.58600","13.96564","0.10551"
"167.90400","13.99219","0.10640"
"168.22200","14.01855","0.10713"
"168.54000","14.04510","0.10823"
"168.85800","14.07159","0.10899"
"169.17600","14.09813","0.10972"
"169.49400","14.12462","0.11102"
"169.81200","14.15111","0.11174"
"170.13000","14.17765","0.11313"
"170.44800","14.20408","0.11394"
"170.76600","14.23069","0.11474"
"171.08400","14.25711","0.11582"
"171.40200","14.28360","0.11680"
"171.72000","14.31009","0.11739"
"172.03800","14.33663","0.11833"
"172.35600","14.36318","0.11914"
"172.67400","14.38961","0.12017"
"172.99200","14.41609","0.12185"
"173.31000","14.44264","0.12309"
"173.62800","14.46907","0.12399"
"173.94600","14.49567","0.12557"
"174.26400","14.52210","0.12713"
"174.58200","14.54859","0.12886"
"174.90000","14.57513","0.12986"
"175.21800","14.60156","0.13180"
"175.53600","14.62811","0.13265"
"175.85400","14.65453","0.13409"
"176.17200","14.68108","0.13539"
"176.49000","14.70763","0.13735"
"176.80800","14.73411","0.13942"
"177.12600","14.76066","0.14139"
"177.44400","14.78709","0.14403"
"177.76200","14.81363","0.13818"
"178.08000","14.84012","0.13984"
"178.39800","14.86667","0.14194"
"178.71600","14.89315","0.14544"
"179.03400","14.91952","0.14866"
"179.35200","14.94613","0.15186"
"179.67000","14.97268","0.15451"
"179.98800","14.99910","0.15727"
"180.30600","15.02565","0.15898"
"180.62400","15.05207","0.16119"
"180.94200","15.07862","0.16313"
"181.26000","15.10511","0.16498"
"181.57800","15.13159","0.16650"
"181.89600","15.15814","0.16807"
"182.21400","15.18457","0.16987"
"182.53200","15.21111","0.17248"
"182.85000","15.23760","0.17516"
"183.16800","15.26415","0.17894"
"183.48600","15.29064","0.18203"
"183.80400","15.31712","0.18491"
"184.12200","15.34367","0.18711"
"184.44000","15.37004","0.18921"
"184.75800","15.39664","0.19114"
"185.07600","15.42307","0.19322"
"185.39400","15.44962","0.19617"
"185.71200","15.47616","0.19836"
"186.03000","15.50259","0.20055"
"186.34800","15.52919","0.20251"
"186.66600","15.55562","0.20460"
"186.98400","15.58217","0.20688"
"187.30200","15.60860","0.20859"
"187.62000","15.63508","0.21074"
"187.93800","15.66163","0.21343"
"188.25600","15.68818","0.21520"
"188.57400","15.71466","0.21714"
"188.89200","15.74115","0.21914"
"189.21000","15.76758","0.22099"
"189.52800","15.79412","0.22253"
"189.84600","15.82061","0.22430"
"190.16400","15.84710","0.22548"
"190.48200","15.87364","0.22695"
"190.80000","15.90007","0.22884"
"191.11800","15.92668","0.23042"
"191.43600","15.95310","0.23261"
"191.75400","15.97959","0.23515"
"192.07200","16.00614","0.23703"
"192.39000","16.03256","0.23913"
"192.70800","16.05917","0.24156"
"193.02600","16.08560","0.24387"
"193.34400","16.11214","0.24663"
"193.66200","16.13857","0.24967"
"193.98000","16.16512","0.25384"
"194.29800","16.19166","0.25676"
"194.61600","16.21809","0.26014"
"194.93400","16.24464","0.26227"
"195.25200","16.27106","0.26376"
"195.57000","16.29767","0.26608"
"195.88800","16.32416","0.26867"
"196.20600","16.35052","0.27173"
"196.52400","16.37713","0.27579"
"196.84200","16.40356","0.27852"
"197.16000","16.43016","0.28189"
"197.47800","16.45665","0.28527"
"197.79600","16.48314","0.28837"
"198.11400","16.50968","0.29125"
"198.43200","16.53611","0.29599"
"198.75000","16.56266","0.30062"
"199.06800","16.58914","0.30601"
"199.38600","16.61563","0.31080"
"199.70400","16.64212","0.31454"
"200.02200","16.66860","0.31685"
"200.34000","16.69515","0.31898"
"200.65800","16.72158","0.32082"
"200.97600","16.74813","0.32200"
"201.29400","16.77467","0.32428"
"201.61200","16.80110","0.32641"
"201.93000","16.82764","0.32821"
"202.24800","16.85413","0.33030"
"202.56600","16.88062","0.33256"
"202.88400","16.90717","0.33446"
"203.20200","16.93359","0.33710"
"203.52000","16.96014","0.33939"
"203.83800","16.98663","0.34146"
"204.15600","17.01311","0.34356"
"204.47400","17.03966","0.34532"
"204.79200","17.06609","0.34773"
"205.11000","17.09257","0.35026"
"205.42800","17.11906","0.35387"
"205.74600","17.14567","0.35833"
"206.06400","17.17215","0.36135"
"206.38200","17.19864","0.36454"
"206.70000","17.22513","0.36718"
"207.01800","17.25155","0.37026"
"207.33600","17.27816","0.37398"
"207.65400","17.30465","0.37785"
"207.97200","17.33113","0.38278"
"208.29000","17.35762","0.38709"
"208.60800","17.38411","0.39060"
"208.92600","17.41065","0.39362"
"209.24400","17.43714","0.39538"
"209.56200","17.46363","0.39782"
"209.88000","17.49017","0.40102"
"210.19800","17.51660","0.40440"
"210.51600","17.54321","0.40859"
"210.83400","17.56957","0.41234"
"211.15200","17.59612","0.41519"
"211.47000","17.62261","0.41819"
"211.78800","17.64915","0.42031"
"212.10600","17.67570","0.42279"
"212.42400","17.70206","0.42474"
"212.74200","17.72861","0.42671"
"213.06000","17.75510","0.42933"
"213.37800","17.78165","0.43235"
"213.69600","17.80813","0.43493"
"214.01400","17.83462","0.43790"
"214.33200","17.86111","0.44218"
"214.65000","17.88765","0.44471"
"214.96800","17.91414","0.44862"
"215.28600","17.94063","0.45168"
"215.60400","17.96705","0.45549"
"215.92200","17.99360","0.45900"
"216.24000","18.02015","0.46264"
"216.55800","18.04663","0.46679"
"216.87600","18.07318","0.46929"
"217.19400","18.09955","0.47157"
"217.51200","18.12615","0.47454"
"217.83000","18.15264","0.47869"
"218.14800","18.17919","0.48306"
"218.46600","18.20568","0.48822"
"218.78400","18.23210","0.49220"
"219.10200","18.25865","0.49648"
"219.42000","18.28514","0.49915"
"219.73800","18.31162","0.50176"
"220.05600","18.33811","0.50527"
"220.37400","18.36459","0.50863"
"220.69200","18.39120","0.51372"
"221.01000","18.41763","0.51799"
"221.32800","18.44418","0.52295"
"221.64600","18.47060","0.52657"
"221.96400","18.49709","0.52997"
"222.28200","18.52364","0.53301"
"222.60000","18.55012","0.53447"
"222.91800","18.57661","0.53678"
"223.23600","18.60309","0.53986"
"223.55400","18.62964","0.54165"
"223.87200","18.65619","0.54453"
"224.19000","18.68261","0.54780"
"224.50800","18.70916","0.55190"
"224.82600","18.73565","0.55455"
"225.14400","18.76220","0.55861"
"225.46200","18.78868","0.56221"
"225.78000","18.81511","0.56682"
"226.09800","18.84166","0.57065"
"226.41600","18.86808","0.57389"
"226.73400","18.89463","0.57728"
"227.05200","18.92111","0.58105"
"227.37000","18.94760","0.58721"
"227.68800","18.97415","0.59303"
"228.00600","19.00057","0.59735"
"228.32400","19.02718","0.60143"
"228.64200","19.05361","0.60525"
"228.96000","19.08010","0.60917"
"229.27800","19.10670","0.61402"
"229.59600","19.13313","0.61769"
"229.91400","19.15968","0.62106"
"230.23200","19.18610","0.62356"
"230.55000","19.21265","0.62633"
"230.86800","19.23920","0.63013"
"231.18600","19.26568","0.63388"
"231.50400","19.29211","0.63700"
"231.82200","19.31866","0.63971"
"232.14000","19.34514","0.64261"
"232.45800","19.37163","0.64557"
"232.77600","19.39812","0.64840"
"233.09400","19.42460","0.65207"
"233.41200","19.45109","0.65524"
"233.73000","19.47764","0.66071"
"234.04800","19.50412","0.66507"
"234.36600","19.53061","0.67087"
"234.68400","19.55716","0.67553"
"235.00200","19.58358","0.67838"
"235.32000","19.61019","0.68239"
"235.63800","19.63662","0.68790"
"235.95600","19.66310","0.69427"
"236.27400","19.68965","0.70163"
"236.59200","19.71608","0.70570"
"236.91000","19.74268","0.70894"
"237.22800","19.76911","0.71304"
"237.54600","19.79560","0.71855"
"237.86400","19.82214","0.72369"
"238.18200","19.84863","0.72456"
"238.50000","19.87518","0.70004"
"238.81800","19.90160","0.70695"
"239.13600","19.92815","0.71332"
"239.45400","19.95464","0.72092"
"239.77200","19.98112","0.72762"
"240.09000","20.00761","0.73374"
"240.40800","20.03403","0.73758"
"240.72600","20.06064","0.74146"
"241.04400","20.08713","0.74464"
"241.36200","20.11362","0.74832"
"241.68000","20.14010","0.75290"
"241.99800","20.16659","0.75624"
"242.31600","20.19320","0.75997"
"242.63400","20.21968","0.76516"
"242.95200","20.24611","0.77009"
"243.27000","20.27266","0.77565"
"243.58800","20.29908","0.78272"
"243.90600","20.32563","0.78871"
"244.22400","20.35212","0.79808"
"244.54200","20.37866","0.80520"
"244.86000","20.40515","0.80904"
"245.17800","20.43158","0.81369"
"245.49600","20.45818","0.82019"
"245.81400","20.48467","0.82742"
"246.13200","20.51116","0.83323"
"246.45000","20.53765","0.83800"
"246.76800","20.56413","0.84277"
"247.08600","20.59068","0.84660"
"247.40400","20.61711","0.84971"
"247.72200","20.64365","0.85242"
"248.04000","20.67014","0.85856"
"248.35800","20.69662","0.86264"
"248.67600","20.72317","0.86622"
"248.99400","20.74960","0.87038"
"249.31200","20.77615","0.87473"
"249.63000","20.80263","0.88002"
"249.94800","20.82912","0.88357"
"250.26600","20.85567","0.88795"
"250.58400","20.88209","0.89257"
"250.90200","20.90864","0.89950"
"251.22000","20.93513","0.90509"
"251.53800","20.96167","0.90975"
"251.85600","20.98822","0.85455"
"252.17400","21.01459","0.85220"
"252.49200","21.04113","0.85272"
"252.81000","21.06762","0.85831"
"253.12800","21.09417","0.85835"
"253.44600","21.12065","0.86602"
"253.76400","21.14708","0.86788"
"254.08200","21.17363","0.87620"
"254.40000","21.20011","0.88164"
"254.71800","21.22666","0.88538"
"255.03600","21.25309","0.89655"
"255.35400","21.27963","0.90102"
"255.67200","21.30612","0.91018"
"255.99000","21.33261","0.91328"
"256.30800","21.35915","0.92368"
"256.62600","21.38558","0.92719"
"256.94400","21.41213","0.93507"
"257.26200","21.43867","0.93948"
"257.58000","21.46510","0.94595"
"257.89800","21.49165","0.94987"
"258.21600","21.51813","0.95347"
"258.53400","21.54462","0.95785"
"258.85200","21.57111","0.96513"
"259.17000","21.59765","0.97572"
"259.48800","21.62414","0.98496"
"259.80600","21.65057","0.98956"
"260.12400","21.67711","0.99478"
"260.44200","21.70372","1.00134"
"260.76000","21.73015","1.00947"
"261.07800","21.75663","0.78404"
"261.39600","21.78300","0.77772"
"261.71400","21.80967","0.77847"
"262.03200","21.83615","0.51294"
"262.35000","21.86258","0.51419"
"262.66800","21.88919","0.51534"
"262.98600","21.91555","0.51270"
"263.30400","21.94216","0.51445"
"263.62200","21.96865","0.51811"
"263.94000","21.99513","0.52390"
"264.25800","22.02162","0.53083"
"264.57600","22.04805","0.53461"
"264.89400","22.07466","0.53521"
"265.21200","22.10114","0.53658"
"265.53000","22.12763","0.53932"
"265.84800","22.15412","0.54424"
"266.16600","22.18066","0.54886"
"266.48400","22.20715","0.55100"
"266.80200","22.23363","0.55264"
"267.12000","22.26006","0.55587"
"267.43800","22.28661","0.56061"
"267.75600","22.31309","0.56479"
"268.07400","22.33964","0.56602"
"268.39200","22.36607","0.56710"
"268.71000","22.39262","0.57081"
"269.02800","22.41916","0.57472"
"269.34600","22.44559","0.57738"
"269.66400","22.47214","0.57802"
"269.98200","22.49856","0.58073"
"270.30000","22.52517","0.58456"
"270.61800","22.55160","0.58949"
"270.93600","22.57814","0.58996"
"271.25400","22.60463","0.59204"
"271.57200","22.63106","0.59455"
"271.89000","22.65766","0.59825"
"272.20800","22.68415","0.60024"
"272.52600","22.71064","0.60014"
"272.84400","22.73712","0.60234"
"273.16200","22.76361","0.60530"
"273.48000","22.79015","0.60679"
"273.79800","22.81664","0.60773"
"274.11600","22.84313","0.61030"
"274.43400","22.86962","0.60156"
"274.75200","22.89610","0.59949"
"275.07000","22.92265","0.59636"
"275.38800","22.94914","0.59481"
"275.70600","22.97562","0.59385"
"276.02400","23.00211","0.59393"
"276.34200","23.02860","0.59319"
"276.66000","23.05520","0.59216"
"276.97800","23.08163","0.58822"
"277.29600","23.10818","0.19594"
"277.61400","23.13466","0.20079"
"277.93200","23.16115","0.19144"
"278.25000","23.18764","0.19948"
"278.56800","23.21406","0.20323"
"278.88600","23.24067","0.20636"
"279.20400","23.26710","0.22312"
"279.52200","23.29364","0.22910"
"279.84000","23.32013","0.23551"
"280.15800","23.34656","0.23194"
"280.47600","23.37316","0.23090"
"280.79400","23.39959","0.23266"
"281.11200","23.42620","0.23690"
"281.43000","23.45262","0.24082"
"281.74800","23.47905","0.24441"
"282.06600","23.50560","0.25142"
"282.38400","23.53208","0.25801"
"282.70200","23.55869","0.26728"
"283.02000","23.58512","0.27380"
"283.33800","23.61166","0.27996"
"283.65600","23.63815","0.28475"
"283.97400","23.66458","0.28706"
"284.29200","23.69112","0.28915"
"284.61000","23.71755","0.29120"
"284.92800","23.74410","0.29450"
"285.24600","23.77065","0.29919"
"285.56400","23.79713","0.30560"
"285.88200","23.82368","0.31191"
"286.20000","23.85011","0.31613"
"286.51800","23.87659","0.31915"
"286.83600","23.90314","0.32156"
"287.15400","23.92963","0.32428"
"287.47200","23.95617","0.31132"
"287.79000","23.98254","0.31700"
"288.10800","24.00914","0.32021"
"288.42600","24.03563","0.32330"
"288.74400","24.06212","0.32585"
"289.06200","24.08867","0.32891"
"289.38000","24.11503","0.33243"
"289.69800","24.14164","0.33482"
"290.01600","24.16813","0.33744"
"290.33400","24.19461","0.34043"
"290.65200","24.22116","0.34220"
"290.97000","24.24759","0.34418"
"291.28800","24.27413","0.34622"
"291.60600","24.30062","0.34872"
"291.92400","24.32710","0.35186"
"292.24200","24.35359","0.35519"
"292.56000","24.38008","0.35945"
"292.87800","24.40663","0.36341"
"293.19600","24.43317","0.36670"
"293.51400","24.45960","0.36953"
"293.83200","24.48609","0.37222"
"294.15000","24.51257","0.37595"
"294.46800","24.53918","0.37753"
"294.78600","24.56561","0.38100"
"295.10400","24.59215","0.38476"
"295.42200","24.61864","0.38663"
"295.74000","24.64513","0.38908"
"296.05800","24.67161","0.39067"
"296.37600","24.69810","0.39167"
"296.69400","24.72465","0.39278"
"297.01200","24.75113","0.39390"
"297.33000","24.77756","0.39527"
"297.64800","24.80416","0.39595"
"297.96600","24.83053","0.39758"
"298.28400","24.85714","0.39881"
"298.60200","24.88363","0.40075"
"298.92000","24.91011","0.40285"
"299.23800","24.93660","0.40405"
"299.55600","24.96303","0.40682"
"299.87400","24.98964","0.40842"
"300.19200","25.01612","0.40917"
"300.51000","25.04267","0.41036"
"300.82800","25.06910","0.41248"
"301.14600","25.09558","0.41417"
"301.46400","25.12213","0.41519"
"301.78200","25.14867","0.01632"
"302.10000","25.17510","0.02089"
"302.41800","25.20165","0.01777"
"302.73600","25.22808","0.01292"
"303.05400","25.25468","0.02051"
"303.37200","25.28117","0.01247"
"303.69000","25.30759","0.01352"
"304.00800","25.33414","0.01618"
"304.32600","25.36063","0.01751"
"304.64400","25.38717","0.01748"
"304.96200","25.41354","0.01361"
"305.28000","25.44015","0.01487"
"305.59800","25.46658","0.01860"
"305.91600","25.49312","0.01906"
"306.23400","25.51967","0.01736"
"306.55200","25.54609","0.01601"
"306.87000","25.57264","0.01770"
"307.18800","25.59907","0.01961"
"307.50600","25.62568","0.01851"
"307.82400","25.65216","0.01798"
"308.14200","25.67859","0.01885"
"308.46000","25.70514","0.02155"
"308.77800","25.73162","0.02071"
"309.09600","25.75817","0.01987"
"309.41400","25.78465","0.02037"
"309.73200","25.81114","0.02256"
"310.05000","25.83763","0.02145"
"310.36800","25.86411","0.02128"
"310.68600","25.89066","0.02210"
"311.00400","25.91715","0.02389"
"311.32200","25.94357","0.02362"
"311.64000","25.97012","0.02333"
"311.95800","25.99655","0.02417"
"312.27600","26.02316","0.02524"
"312.59400","26.04964","0.02524"
"312.91200","26.07607","0.02511"
"313.23000","26.10268","0.02577"
"313.54800","26.12910","0.02645"
"313.86600","26.15565","0.02653"
"314.18400","26.18208","0.02699"
"314.50200","26.20856","0.02748"
"314.82000","26.23517","0.02863"
"315.13800","26.26160","0.02867"
"315.45600","26.28815","0.02874"
"315.77400","26.31463","0.02917"
"316.09200","26.34118","0.02970"
"316.41000","26.36766","0.03028"
"316.72800","26.39409","0.03071"
"317.04600","26.42064","0.03143"
"317.36400","26.44706","0.03191"
"317.68200","26.47361","0.03207"
"318.00000","26.50016","0.03283"
"318.31800","26.52658","0.03303"
"318.63600","26.55313","0.03366"
"318.95400","26.57956","0.03394"
"319.27200","26.60610","0.03453"
"319.59000","26.63259","0.03472"
"319.90800","26.65907","0.03587"
"320.22600","26.68562","0.03599"
"320.54400","26.71211","0.03692"
"320.86200","26.73866","0.03698"
"321.18000","26.76515","0.03794"
"321.49800","26.79163","0.03801"
"321.81600","26.81818","0.03894"
"322.13400","26.84460","0.03937"
"322.45200","26.87121","0.03975"
"322.77000","26.89758","0.04012"
"323.08800","26.92412","0.04063"
"323.40600","26.95061","0.04111"
"323.72400","26.97710","0.04238"
"324.04200","27.00364","0.04227"
"324.36000","27.03007","0.04394"
"324.67800","27.05668","0.04428"
"324.99600","27.08310","0.04565"
"325.31400","27.10959","0.04569"
"325.63200","27.13614","0.04606"
"325.95000","27.16256","0.04723"
"326.26800","27.18911","0.04795"
"326.58600","27.21566","0.04930"
"326.90400","27.24214","0.04987"
"327.22200","27.26869","0.05030"
"327.54000","27.29506","0.05140"
"327.85800","27.32167","0.05223"
"328.17600","27.34815","0.05362"
"328.49400","27.37464","0.05376"
"328.81200","27.40119","0.05452"
"329.13000","27.42755","0.05539"
"329.44800","27.45416","0.05596"
"329.76600","27.48064","0.05654"
"330.08400","27.50713","0.05758"
"330.40200","27.53362","0.05776"
"330.72000","27.56004","0.05866"
"331.03800","27.58665","0.05887"
"331.35600","27.61314","0.05958"
"331.67400","27.63962","0.05992"
"331.99200","27.66611","0.06024"
"332.31000","27.69260","0.06124"
"332.62800","27.71914","0.06219"
"332.94600","27.74563","0.06239"
"333.26400","27.77218","0.06361"
"333.58200","27.79860","0.06361"
"333.90000","27.82515","0.06402"
"334.21800","27.85164","0.06500"
"334.53600","27.87807","0.06515"
"334.85400","27.90467","0.06630"
"335.17200","27.93116","0.06758"
"335.49000","27.95764","0.06826"
"335.80800","27.98419","0.06964"
"336.12600","28.01056","0.07033"
"336.44400","28.03711","0.07129"
"336.76200","28.06359","0.07117"
"337.08000","28.09020","0.07252"
"337.39800","28.11668","0.07218"
"337.71600","28.14311","0.06882"
"338.03400","28.16960","0.06930"
"338.35200","28.19614","0.07045"
"338.67000","28.22269","0.07207"
"338.98800","28.24912","0.07224"
"339.30600","28.27561","0.07169"
"339.62400","28.30215","0.07088"
"339.94200","28.32858","0.07146"
"340.26000","28.35513","0.07326"
"340.57800","28.38161","0.07363"
"340.89600","28.40810","0.07460"
"341.21400","28.43465","0.07567"
"341.53200","28.46113","0.07530"
"341.85000","28.48768","0.07478"
"342.16800","28.51411","0.07599"
"342.48600","28.54065","0.07592"
"342.80400","28.56720","0.07660"
"343.12200","28.59363","0.07578"
"343.44000","28.62011","0.07655"
"343.75800","28.64660","0.07674"
"344.07600","28.67309","0.07759"
"344.39400","28.69963","0.07814"
"344.71200","28.72612","0.07741"
"345.03000","28.75261","0.07789"
"345.34800","28.77909","0.07846"
"345.66600","28.80564","0.07937"
"345.98400","28.83213","0.08011"
"346.30200","28.85855","0.08074"
"346.62000","28.88510","0.08134"
"346.93800","28.91153","0.08192"
"347.25600","28.93819","0.08203"
"347.57400","28.96462","0.08298"
"347.89200","28.99117","0.08306"
"348.21000","29.01765","0.08395"
"348.52800","29.04408","0.08381"
"348.84600","29.07069","0.08463"
"349.16400","29.09712","0.08523"
"349.48200","29.12360","0.08597"
"349.80000","29.15015","0.08616"
"350.11800","29.17663","0.08657"
"350.43600","29.20318","0.08654"
"350.75400","29.22961","0.08679"
"351.07200","29.25609","0.08790"
"351.39000","29.28264","0.08861"
"351.70800","29.30913","0.08869"
"352.02600","29.33562","0.08978"
"352.34400","29.36210","0.09002"
"352.66200","29.38859","0.09040"
"352.98000","29.41513","0.09150"
"353.29800","29.44162","0.09235"
"353.61600","29.46811","0.09211"
"353.93400","29.49459","0.09205"
"354.25200","29.52114","0.09392"
"354.57000","29.54769","0.09453"
"354.88800","29.57418","0.09608"
"355.20600","29.60066","0.09691"
"355.52400","29.62709","0.09453"
"355.84200","29.65364","0.09092"
"356.16000","29.68012","0.08975"
"356.47800","29.70667","0.08829"
"356.79600","29.73315","0.08953"
"357.11400","29.75958","0.08645"
"357.43200","29.78613","0.08781"
"357.75000","29.81261","0.08765"
"358.06800","29.83916","0.08877"
"358.38600","29.86565","0.08843"
"358.70400","29.89208","0.08805"
"359.02200","29.91868","0.08911"
"359.34000","29.94511","0.08993"
"359.65800","29.97172","0.09104"
"359.97600","29.99814","0.09226"
"360.29400","30.02463","0.09358"
"360.61200","30.05118","0.09553"
"360.93000","30.07760","0.09691"
"361.24800","30.10415","0.09746"
"361.56600","30.13064","0.09601"
"361.88400","30.15712","0.09754"
"362.20200","30.18367","0.09823"
"362.52000","30.21010","0.09961"
"362.83800","30.23664","0.10109"
"363.15600","30.26313","0.10210"
"363.47400","30.28956","0.10321"
"363.79200","30.31616","0.10488"
"364.11000","30.34259","0.10572"
"364.42800","30.36914","0.10639"
"364.74600","30.39562","0.10744"
"365.06400","30.42217","0.10766"
"365.38200","30.44872","0.10823"
"365.70000","30.47508","0.10901"
"366.01800","30.50163","0.10915"
"366.33600","30.52812","0.10985"
"366.65400","30.55466","0.11044"
"366.97200","30.58115","0.11198"
"367.29000","30.60764","0.11203"
"367.60800","30.63412","0.11291"
"367.92600","30.66067","0.11259"
"368.24400","30.68710","0.11188"
"368.56200","30.71364","0.11074"
"368.88000","30.74013","0.11096"
"369.19800","30.76668","0.11169"
"369.51600","30.79310","0.11196"
"369.83400","30.81965","0.11262"
"370.15200","30.84608","0.11358"
"370.47000","30.87263","0.11409"
"370.78800","30.89917","0.11557"
"371.10600","30.92560","0.11598"
"371.42400","30.95214","0.11557"
"371.74200","30.97863","0.11579"
"372.06000","31.00518","0.11688"
"372.37800","31.03167","0.11746"
"372.69600","31.05815","0.11874"
"373.01400","31.08464","0.11984"
"373.33200","31.11106","0.12088"
"373.65000","31.13767","0.12158"
"373.96800","31.16416","0.12345"
"374.28600","31.19059","0.12396"
"374.60400","31.21713","0.12390"
"374.92200","31.24356","0.12421"
"375.24000","31.27023","0.12368"
"375.55800","31.29665","0.12489"
"375.87600","31.32314","0.12576"
"376.19400","31.34962","0.12689"
"376.51200","31.37611","0.12811"
"376.83000","31.40266","0.12919"
"377.14800","31.42909","0.12927"
"377.46600","31.45563","0.12977"
"377.78400","31.48212","0.13079"
"378.10200","31.50867","0.13227"
"378.42000","31.53515","0.13262"
"378.73800","31.56158","0.13166"
"379.05600","31.58813","0.13211"
"379.37400","31.61461","0.13316"
"379.69200","31.64116","0.13389"
"380.01000","31.66765","0.13537"
"380.32800","31.69413","0.13593"
"380.64600","31.72062","0.13792"
"380.96400","31.74717","0.10865"
"381.28200","31.77359","0.10835"
"381.60000","31.80014","0.10883"
"381.91800","31.82657","0.10986"
"382.23600","31.85317","0.11095"
"382.55400","31.87966","0.11161"
"382.87200","31.90615","0.11249"
"383.19000","31.93263","0.11299"
"383.50800","31.95906","0.11428"
"383.82600","31.98567","0.11549"
"384.14400","32.01209","0.11591"
"384.46200","32.03864","0.11716"
"384.78000","32.06513","0.11757"
"385.09800","32.09155","0.11795"
"385.41600","32.11816","0.11899"
"385.73400","32.14465","0.11947"
"386.05200","32.17113","0.12001"
"386.37000","32.19768","0.12047"
"386.68800","32.22411","0.12041"
"387.00600","32.25065","0.11367"
"387.32400","32.27714","0.11204"
"387.64200","32.30363","0.11197"
"387.96000","32.33012","0.11128"
"388.27800","32.35660","0.11137"
"388.59600","32.38315","0.10755"
"388.91400","32.40952","0.10686"
"389.23200","32.43618","0.10588"
"389.55000","32.46267","0.10652"
"389.86800","32.48909","0.10682"
"390.18600","32.51564","0.10669"
"390.50400","32.54207","0.10717"
"390.82200","32.56868","0.10711"
"391.14000","32.59510","0.10729"
"391.45800","32.62165","0.10822"
"391.77600","32.64814","0.10893"
"392.09400","32.67462","0.10959"
"392.41200","32.70117","0.11021"
"392.73000","32.72765","0.11058"
"393.04800","32.75414","0.10815"
"393.36600","32.78063","0.10824"
"393.68400","32.80711","0.10871"
"394.00200","32.83360","0.10902"
"394.32000","32.86015","0.10901"
"394.63800","32.88663","0.10908"
"394.95600","32.91312","0.10985"
"395.27400","32.93961","0.11045"
"395.59200","32.96616","0.11055"
"395.91000","32.99264","0.11156"
"396.22800","33.01913","0.11217"
"396.54600","33.04562","0.11283"
"396.86400","33.07210","0.11394"
"397.18200","33.09865","0.11443"
"397.50000","33.12508","0.11472"
"397.81800","33.15162","0.11524"
"398.13600","33.17811","0.11665"
"398.45400","33.20460","0.11765"
"398.77200","33.23120","0.11827"
"399.09000","33.25757","0.11868"
"399.40800","33.28418","0.11921"
"399.72600","33.31060","0.11978"
"400.04400","33.33715","0.11928"
"400.36200","33.36370","0.11980"
"400.68000","33.39006","0.12122"
"400.99800","33.41667","0.12281"
"401.31600","33.44310","0.12353"
"401.63400","33.46964","0.12464"
"401.95200","33.49613","0.12524"
"402.27000","33.52262","0.12636"
"402.58800","33.54910","0.12741"
"402.90600","33.57559","0.12882"
"403.22400","33.60220","0.12996"
"403.54200","33.62862","0.13111"
"403.86000","33.65511","0.13164"
"404.17800","33.68160","0.13191"
"404.49600","33.70808","0.13287"
"404.81400","33.73457","0.13350"
"405.13200","33.76106","0.13418"
"405.45000","33.78761","0.13537"
"405.76800","33.81415","0.13304"
"406.08600","33.84058","0.13341"
"406.40400","33.86718","0.13439"
"406.72200","33.89361","0.13560"
"407.04000","33.92016","0.13684"
"407.35800","33.94664","0.13795"
"407.67600","33.97307","0.13984"
"407.99400","33.99968","0.12673"
"408.31200","34.02610","0.12834"
"408.63000","34.05265","0.12938"
"408.94800","34.07914","0.13041"
"409.26600","34.10556","0.13232"
"409.58400","34.13211","0.13243"
"409.90200","34.15854","0.13217"
"410.22000","34.18515","0.13346"
"410.53800","34.21163","0.13531"
"410.85600","34.23812","0.13661"
"411.17400","34.26461","0.13802"
"411.49200","34.29103","0.13974"
"411.81000","34.31764","0.14173"
"412.12800","34.34407","0.14454"
"412.44600","34.37061","0.14633"
"412.76400","34.39716","0.14822"
"413.08200","34.42359","0.15036"
"413.40000","34.45013","0.15254"
"413.71800","34.47662","0.15519"
"414.03600","34.50311","0.15767"
"414.35400","34.52959","0.15914"
"414.67200","34.55608","0.16064"
"414.99000","34.58269","0.16223"
"415.30800","34.60911","0.16334"
"415.62600","34.63560","0.16477"
"415.94400","34.66215","0.16607"
"416.26200","34.68863","0.16750"
"416.58000","34.71518","0.16841"
"416.89800","34.74154","0.16891"
"417.21600","34.76809","0.16985"
"417.53400","34.79464","0.17128"
"417.85200","34.82113","0.17266"
"418.17000","34.84761","0.17088"
"418.48800","34.87404","0.16899"
"418.80600","34.90065","0.17172"
"419.12400","34.92713","0.17504"
"419.44200","34.95362","0.17499"
"419.76000","34.98011","0.17416"
"420.07800","35.00659","0.17091"
"420.39600","35.03314","0.13458"
"420.71400","35.05963","0.13232"
"421.03200","35.08617","0.13299"
"421.35000","35.11266","0.13270"
"421.66800","35.13908","0.13460"
"421.98600","35.16563","0.13638"
"422.30400","35.19218","0.13776"
"422.62200","35.21867","0.14053"
"422.94000","35.24516","0.14312"
"423.25800","35.27158","0.14497"
"423.57600","35.29819","0.14839"
"423.89400","35.32461","0.15044"
"424.21200","35.35116","0.15358"
"424.53000","35.37765","0.15737"
"424.84800","35.40407","0.15919"
"425.16600","35.43068","0.16057"
"425.48400","35.45705","0.16238"
"425.80200","35.48365","0.16343"
"426.12000","35.51008","0.16468"
"426.43800","35.53662","0.16577"
"426.75600","35.56323","0.16666"
"427.07400","35.58960","0.16611"
"427.39200","35.61615","0.16861"
"427.71000","35.64263","0.17087"
"428.02800","35.66918","0.17326"
"428.34600","35.69567","0.17496"
"428.66400","35.72209","0.17731"
"428.98200","35.74864","0.17929"
"429.30000","35.77512","0.18177"
"429.61800","35.80161","0.18337"
"429.93600","35.82816","0.18585"
"430.25400","35.85458","0.18647"
"430.57200","35.88113","0.18633"
"430.89000","35.90756","0.18682"
"431.20800","35.93417","0.18961"
"431.52600","35.96065","0.19149"
"431.84400","35.98714","0.18920"
"432.16200","36.01363","0.18852"
"432.48000","36.04011","0.18904"
"432.79800","36.06660","0.18932"
"433.11600","36.09309","0.19051"
"433.43400","36.11963","0.19273"
"433.75200","36.14612","0.19429"
"434.07000","36.17261","0.19599"
"434.38800","36.19915","0.19660"
"434.70600","36.22558","0.19793"
"435.02400","36.25207","0.19954"
"435.34200","36.27861","0.20203"
"435.66000","36.30510","0.20316"
"435.97800","36.33165","0.20396"
"436.29600","36.35807","0.20610"
"436.61400","36.38462","0.20793"
"436.93200","36.41111","0.20859"
"437.25000","36.43759","0.21072"
"437.56800","36.46414","0.21249"
"437.88600","36.49057","0.21414"
"438.20400","36.51711","0.21576"
"438.52200","36.54366","0.21770"
"438.84000","36.57015","0.21956"
"439.15800","36.59663","0.22149"
"439.47600","36.62306","0.22099"
"439.79400","36.64967","0.22246"
"440.11200","36.67616","0.22290"
"440.43000","36.70264","0.22327"
"440.74800","36.72919","0.22426"
"441.06600","36.75562","0.22549"
"441.38400","36.78216","0.22682"
"441.70200","36.80865","0.22861"
"442.02000","36.83513","0.23029"
"442.33800","36.86162","0.09902"
"442.65600","36.88811","0.09364"
"442.97400","36.91465","0.09873"
"443.29200","36.94108","0.10513"
"443.61000","36.96763","0.10926"
"443.92800","36.99411","0.11093"
"444.24600","37.02060","0.11164"
"444.56400","37.04715","0.11127"
"444.88200","37.07357","0.11074"
"445.20000","37.10012","0.11107"
"445.51800","37.12661","0.11215"
"445.83600","37.15316","0.11333"
"446.15400","37.17964","0.11436"
"446.47200","37.20607","0.11637"
"446.79000","37.23262","0.11777"
"447.10800","37.25910","0.11960"
"447.42600","37.28565","0.12175"
"447.74400","37.31219","0.12374"
"448.06200","37.33856","0.12453"
"448.38000","37.36517","0.12594"
"448.69800","37.39159","0.12635"
"449.01600","37.41808","0.12663"
"449.33400","37.44463","0.12806"
"449.65200","37.47105","0.12896"
"449.97000","37.49760","0.13000"
"450.28800","37.52415","0.13089"
"450.60600","37.55069","0.13114"
"450.92400","37.57712","0.13243"
"451.24200","37.60361","0.13303"
"451.56000","37.63016","0.13436"
"451.87800","37.65664","0.13538"
"452.19600","37.68313","0.13663"
"452.51400","37.70967","0.13783"
"452.83200","37.73610","0.13888"
"453.15000","37.76265","0.13995"
"453.46800","37.78913","0.14169"
"453.78600","37.81568","0.14309"
"454.10400","37.84211","0.14477"
"454.42200","37.86860","0.14551"
"454.74000","37.89520","0.14742"
"455.05800","37.92157","0.14901"
"455.37600","37.94812","0.15003"
"455.69400","37.97460","0.15291"
"456.01200","38.00115","0.15457"
"456.33000","38.02764","0.15567"
"456.64800","38.05412","0.15717"
"456.96600","38.08061","0.15851"
"457.28400","38.10710","0.15910"
"457.60200","38.13364","0.16180"
"457.92000","38.16013","0.16251"
"458.23800","38.18662","0.16353"
"458.55600","38.21310","0.16373"
"458.87400","38.23959","0.16453"
"459.19200","38.26620","0.16531"
"459.51000","38.29263","0.16622"
"459.82800","38.31905","0.16707"
"460.14600","38.34566","0.16790"
"460.46400","38.37209","0.16913"
"460.78200","38.39869","0.16824"
"461.10000","38.42506","0.16865"
"461.41800","38.45160","0.16841"
"461.73600","38.47815","0.16933"
"462.05400","38.50458","0.16936"
"462.37200","38.53119","-0.00194"
"462.69000","38.55761","0.01177"
"463.00800","38.58410","0.01300"
"463.32600","38.61065","0.01490"
"463.64400","38.63713","0.01257"
"463.96200","38.66362","0.01210"
"464.28000","38.69011","0.01450"
"464.59800","38.71665","0.01265"
"464.91600","38.74320","0.01333"
"465.23400","38.76963","0.01276"
"465.55200","38.79611","0.01391"
"465.87000","38.82254","0.01332"
"466.18800","38.84914","0.01316"
"466.50600","38.87569","0.01319"
"466.82400","38.90212","0.01288"
"467.14200","38.92860","0.01323"
"467.46000","38.95503","0.01500"
"467.77800","38.98170","0.01370"
"468.09600","39.00813","0.01410"
"468.41400","39.03461","0.01365"
"468.73200","39.06116","0.01332"
"469.05000","39.08759","0.01473"
"469.36800","39.11419","0.01403"
"469.68600","39.14062","0.01419"
"470.00400","39.16711","0.01475"
"470.32200","39.19359","0.01335"
"470.64000","39.22014","0.01483"
"470.95800","39.24668","0.01475"
"471.02600","39.25231","0.01444"