File: Force_trajectories/161223/Specimen_RawData_4.csv
End date,"12/23/2016"
Specimen label,"22CG_79"
Maximum Load,"0.00485",N

Time,Extension,Load
(s),(mm),(N)
"0.00000","0.00000","-0.00082"
"0.20400","0.01453","-0.00045"
"0.40800","0.03432","0.00007"
"0.61200","0.05124","0.00019"
"0.81600","0.06828","0.00063"
"1.02000","0.08514","0.00090"
"1.22400","0.10218","0.00119"
"1.42800","0.11922","0.00116"
"1.63200","0.13620","0.00080"
"1.83600","0.15324","0.00117"
"2.04000","0.17022","0.00125"
"2.24400","0.18720","0.00111"
"2.44800","0.20424","0.00144"
"2.65200","0.22110","0.00149"
"2.85600","0.23826","0.00192"
"3.06000","0.25524","0.00136"
"3.26400","0.27216","0.00168"
"3.46800","0.28920","0.00183"
"3.67200","0.30618","0.00146"
"3.87600","0.32316","0.00156"
"4.08000","0.34020","0.00164"
"4.28400","0.35724","0.00155"
"4.48800","0.37422","0.00166"
"4.69200","0.39126","0.00206"
"4.89600","0.40818","0.00180"
"5.10000","0.42516","0.00182"
"5.30400","0.44220","0.00212"
"5.50800","0.45924","0.00174"
"5.71200","0.47622","0.00178"
"5.91600","0.49320","0.00222"
"6.12000","0.51018","0.00189"
"6.32400","0.52722","0.00173"
"6.52800","0.54420","0.00191"
"6.73200","0.56124","0.00236"
"6.93600","0.57816","0.00178"
"7.14000","0.59526","0.00192"
"7.34400","0.61224","0.00196"
"7.54800","0.62917","0.00205"
"7.75200","0.64621","0.00205"
"7.95600","0.66319","0.00182"
"8.16000","0.68023","0.00237"
"8.36400","0.69721","0.00249"
"8.56800","0.71413","0.00234"
"8.77200","0.73123","0.00240"
"8.97600","0.74821","0.00213"
"9.18000","0.76513","0.00185"
"9.38400","0.78229","0.00229"
"9.58800","0.79921","0.00212"
"9.79200","0.81619","0.00227"
"9.99600","0.83323","0.00224"
"10.20000","0.85015","0.00243"
"10.40400","0.86719","0.00225"
"10.60800","0.88423","0.00228"
"10.81200","0.90115","0.00231"
"11.01600","0.91825","0.00243"
"11.22000","0.93523","0.00220"
"11.42400","0.95215","0.00272"
"11.62800","0.96925","0.00273"
"11.83200","0.98617","0.00239"
"12.03600","1.00327","0.00211"
"12.24000","1.02019","0.00195"
"12.44400","1.03717","0.00247"
"12.64800","1.05421","0.00219"
"12.85200","1.07119","0.00229"
"13.05600","1.08823","0.00224"
"13.26000","1.10521","0.00242"
"13.46400","1.12219","0.00237"
"13.66800","1.13923","0.00242"
"13.87200","1.15621","0.00198"
"14.07600","1.17319","0.00240"
"14.28000","1.19023","0.00243"
"14.48400","1.20715","0.00212"
"14.68800","1.22425","0.00240"
"14.89200","1.24123","0.00246"
"15.09600","1.25821","0.00230"
"15.30000","1.27519","0.00247"
"15.50400","1.29223","0.00209"
"15.70800","1.30915","0.00226"
"15.91200","1.32625","0.00253"
"16.11600","1.34311","0.00233"
"16.32000","1.36021","0.00244"
"16.52400","1.37719","0.00263"
"16.72800","1.39417","0.00263"
"16.93200","1.41121","0.00246"
"17.13600","1.42825","0.00288"
"17.34000","1.44523","0.00246"
"17.54400","1.46221","0.00283"
"17.74800","1.47919","0.00288"
"17.95200","1.49623","0.00254"
"18.15600","1.51315","0.00204"
"18.36000","1.53019","0.00246"
"18.56400","1.54723","0.00245"
"18.76800","1.56421","0.00241"
"18.97200","1.58125","0.00233"
"19.17600","1.59823","0.00203"
"19.38000","1.61521","0.00230"
"19.58400","1.63225","0.00263"
"19.78800","1.64929","0.00257"
"19.99200","1.66615","0.00209"
"20.19600","1.68319","0.00247"
"20.40000","1.70018","0.00232"
"20.60400","1.71716","0.00249"
"20.80800","1.73426","0.00258"
"21.01200","1.75118","0.00276"
"21.21600","1.76828","0.00278"
"21.42000","1.78520","0.00239"
"21.62400","1.80218","0.00270"
"21.82800","1.81922","0.00257"
"22.03200","1.83620","0.00251"
"22.23600","1.85324","0.00287"
"22.44000","1.87022","0.00263"
"22.64400","1.88714","0.00258"
"22.84800","1.90424","0.00275"
"23.05200","1.92116","0.00267"
"23.25600","1.93820","0.00270"
"23.46000","1.95518","0.00295"
"23.66400","1.97222","0.00240"
"23.86800","1.98920","0.00279"
"24.07200","2.00624","0.00244"
"24.27600","2.02322","0.00261"
"24.48000","2.04026","0.00263"
"24.68400","2.05718","0.00239"
"24.88800","2.07422","0.00227"
"25.09200","2.09126","0.00268"
"25.29600","2.10818","0.00260"
"25.50000","2.12528","0.00290"
"25.70400","2.14220","0.00285"
"25.90800","2.15918","0.00292"
"26.11200","2.17622","0.00264"
"26.31600","2.19314","0.00246"
"26.52000","2.21018","0.00242"
"26.72400","2.22722","0.00223"
"26.92800","2.24414","0.00281"
"27.13200","2.26124","0.00251"
"27.33600","2.27822","0.00256"
"27.54000","2.29520","0.00235"
"27.74400","2.31224","0.00240"
"27.94800","2.32922","0.00284"
"28.15200","2.34620","0.00274"
"28.35600","2.36324","0.00262"
"28.56000","2.38022","0.00274"
"28.76400","2.39720","0.00252"
"28.96800","2.41418","0.00264"
"29.17200","2.43122","0.00244"
"29.37600","2.44820","0.00247"
"29.58000","2.46518","0.00263"
"29.78400","2.48222","0.00277"
"29.98800","2.49920","0.00257"
"30.19200","2.51618","0.00258"
"30.39600","2.53322","0.00305"
"30.60000","2.55020","0.00291"
"30.80400","2.56718","0.00296"
"31.00800","2.58422","0.00291"
"31.21200","2.60114","0.00252"
"31.41600","2.61824","0.00273"
"31.62000","2.63516","0.00287"
"31.82400","2.65226","0.00248"
"32.02800","2.66924","0.00303"
"32.23200","2.68616","0.00302"
"32.43600","2.70326","0.00317"
"32.64000","2.72024","0.00290"
"32.84400","2.73716","0.00281"
"33.04800","2.75420","0.00248"
"33.25200","2.77119","0.00290"
"33.45600","2.78823","0.00298"
"33.66000","2.80526","0.00292"
"33.86400","2.82219","0.00285"
"34.06800","2.83917","0.00266"
"34.27200","2.85621","0.00301"
"34.47600","2.87313","0.00267"
"34.68000","2.89023","0.00275"
"34.88400","2.90721","0.00310"
"35.08800","2.92419","0.00294"
"35.29200","2.94123","0.00281"
"35.49600","2.95821","0.00303"
"35.70000","2.97525","0.00287"
"35.90400","2.99223","0.00262"
"36.10800","3.00915","0.00307"
"36.31200","3.02625","0.00295"
"36.51600","3.04317","0.00270"
"36.72000","3.06021","0.00270"
"36.92400","3.07725","0.00289"
"37.12800","3.09417","0.00294"
"37.33200","3.11121","0.00284"
"37.53600","3.12819","0.00289"
"37.74000","3.14517","0.00260"
"37.94400","3.16227","0.00289"
"38.14800","3.17919","0.00284"
"38.35200","3.19623","0.00294"
"38.55600","3.21321","0.00306"
"38.76000","3.23019","0.00263"
"38.96400","3.24723","0.00285"
"39.16800","3.26421","0.00326"
"39.37200","3.28113","0.00323"
"39.57600","3.29823","0.00286"
"39.78000","3.31521","0.00277"
"39.98400","3.33219","0.00313"
"40.18800","3.34923","0.00336"
"40.39200","3.36615","0.00264"
"40.59600","3.38325","0.00288"
"40.80000","3.40017","0.00298"
"41.00400","3.41727","0.00297"
"41.20800","3.43425","0.00303"
"41.41200","3.45117","0.00302"
"41.61600","3.46821","0.00320"
"41.82000","3.48525","0.00303"
"42.02400","3.50217","0.00318"
"42.22800","3.51921","0.00300"
"42.43200","3.53619","0.00279"
"42.63600","3.55323","0.00310"
"42.84000","3.57027","0.00312"
"43.04400","3.58713","0.00306"
"43.24800","3.60423","0.00310"
"43.45200","3.62121","0.00312"
"43.65600","3.63813","0.00315"
"43.86000","3.65523","0.00321"
"44.06400","3.67215","0.00303"
"44.26800","3.68919","0.00291"
"44.47200","3.70629","0.00329"
"44.67600","3.72315","0.00322"
"44.88000","3.74025","0.00300"
"45.08400","3.75723","0.00305"
"45.28800","3.77421","0.00317"
"45.49200","3.79125","0.00305"
"45.69600","3.80817","0.00316"
"45.90000","3.82521","0.00323"
"46.10400","3.84220","0.00314"
"46.30800","3.85918","0.00324"
"46.51200","3.87622","0.00296"
"46.71600","3.89320","0.00305"
"46.92000","3.91018","0.00299"
"47.12400","3.92722","0.00309"
"47.32800","3.94420","0.00325"
"47.53200","3.96118","0.00316"
"47.73600","3.97822","0.00307"
"47.94000","3.99520","0.00358"
"48.14400","4.01218","0.00298"
"48.34800","4.02922","0.00345"
"48.55200","4.04620","0.00307"
"48.75600","4.06324","0.00310"
"48.96000","4.08022","0.00314"
"49.16400","4.09720","0.00304"
"49.36800","4.11424","0.00286"
"49.57200","4.13116","0.00312"
"49.77600","4.14826","0.00318"
"49.98000","4.16512","0.00339"
"50.18400","4.18222","0.00305"
"50.38800","4.19920","0.00336"
"50.59200","4.21612","0.00306"
"50.79600","4.23322","0.00328"
"51.00000","4.25020","0.00297"
"51.20400","4.26724","0.00349"
"51.40800","4.28422","0.00325"
"51.61200","4.30114","0.00320"
"51.81600","4.31824","0.00340"
"52.02000","4.33522","0.00346"
"52.22400","4.35220","0.00333"
"52.42800","4.36924","0.00311"
"52.63200","4.38622","0.00329"
"52.83600","4.40314","0.00342"
"53.04000","4.42024","0.00293"
"53.24400","4.43716","0.00286"
"53.44800","4.45420","0.00324"
"53.65200","4.47124","0.00318"
"53.85600","4.48816","0.00330"
"54.06000","4.50526","0.00298"
"54.26400","4.52218","0.00349"
"54.46800","4.53916","0.00286"
"54.67200","4.55626","0.00325"
"54.87600","4.57312","0.00322"
"55.08000","4.59022","0.00299"
"55.28400","4.60720","0.00332"
"55.48800","4.62418","0.00307"
"55.69200","4.64122","0.00294"
"55.89600","4.65820","0.00307"
"56.10000","4.67524","0.00362"
"56.30400","4.69222","0.00353"
"56.50800","4.70920","0.00335"
"56.71200","4.72624","0.00345"
"56.91600","4.74316","0.00301"
"57.12000","4.76020","0.00350"
"57.32400","4.77724","0.00372"
"57.52800","4.79422","0.00328"
"57.73200","4.81120","0.00353"
"57.93600","4.82824","0.00360"
"58.14000","4.84516","0.00361"
"58.34400","4.86220","0.00372"
"58.54800","4.87918","0.00339"
"58.75200","4.89622","0.00337"
"58.95600","4.91320","0.00323"
"59.16000","4.93013","0.00308"
"59.36400","4.94723","0.00322"
"59.56800","4.96421","0.00313"
"59.77200","4.98113","0.00358"
"59.97600","4.99829","0.00346"
"60.18000","5.01515","0.00326"
"60.38400","5.03225","0.00303"
"60.58800","5.04923","0.00328"
"60.79200","5.06615","0.00332"
"60.99600","5.08325","0.00337"
"61.20000","5.10017","0.00347"
"61.40400","5.11721","0.00337"
"61.60800","5.13419","0.00328"
"61.81200","5.15117","0.00322"
"62.01600","5.16827","0.00320"
"62.22000","5.18525","0.00347"
"62.42400","5.20217","0.00345"
"62.62800","5.21921","0.00305"
"62.83200","5.23625","0.00337"
"63.03600","5.25317","0.00346"
"63.24000","5.27021","0.00345"
"63.44400","5.28713","0.00345"
"63.64800","5.30423","0.00331"
"63.85200","5.32127","0.00327"
"64.05600","5.33819","0.00355"
"64.26000","5.35529","0.00376"
"64.46400","5.37221","0.00340"
"64.66800","5.38919","0.00331"
"64.87200","5.40629","0.00368"
"65.07600","5.42315","0.00350"
"65.28000","5.44031","0.00344"
"65.48400","5.45717","0.00352"
"65.68800","5.47415","0.00350"
"65.89200","5.49119","0.00329"
"66.09600","5.50817","0.00338"
"66.30000","5.52515","0.00362"
"66.50400","5.54225","0.00373"
"66.70800","5.55911","0.00365"
"66.91200","5.57621","0.00368"
"67.11600","5.59319","0.00349"
"67.32000","5.61017","0.00354"
"67.52400","5.62721","0.00356"
"67.72800","5.64419","0.00347"
"67.93200","5.66117","0.00368"
"68.13600","5.67827","0.00343"
"68.34000","5.69513","0.00332"
"68.54400","5.71223","0.00359"
"68.74800","5.72921","0.00328"
"68.95200","5.74619","0.00333"
"69.15600","5.76323","0.00338"
"69.36000","5.78015","0.00328"
"69.56400","5.79719","0.00327"
"69.76800","5.81423","0.00339"
"69.97200","5.83115","0.00313"
"70.17600","5.84825","0.00313"
"70.38000","5.86517","0.00328"
"70.58400","5.88221","0.00339"
"70.78800","5.89925","0.00347"
"70.99200","5.91617","0.00355"
"71.19600","5.93321","0.00370"
"71.40000","5.95019","0.00355"
"71.60400","5.96723","0.00381"
"71.80800","5.98422","0.00365"
"72.01200","6.00125","0.00357"
"72.21600","6.01817","0.00352"
"72.42000","6.03522","0.00320"
"72.62400","6.05220","0.00395"
"72.82800","6.06918","0.00320"
"73.03200","6.08622","0.00350"
"73.23600","6.10314","0.00338"
"73.44000","6.12018","0.00322"
"73.64400","6.13722","0.00323"
"73.84800","6.15426","0.00357"
"74.05200","6.17118","0.00338"
"74.25600","6.18822","0.00333"
"74.46000","6.20526","0.00350"
"74.66400","6.22212","0.00347"
"74.86800","6.23922","0.00327"
"75.07200","6.25620","0.00333"
"75.27600","6.27318","0.00301"
"75.48000","6.29022","0.00382"
"75.68400","6.30720","0.00356"
"75.88800","6.32418","0.00359"
"76.09200","6.34122","0.00346"
"76.29600","6.35820","0.00366"
"76.50000","6.37518","0.00315"
"76.70400","6.39222","0.00363"
"76.90800","6.40920","0.00341"
"77.11200","6.42618","0.00348"
"77.31600","6.44328","0.00330"
"77.52000","6.46014","0.00330"
"77.72400","6.47724","0.00369"
"77.92800","6.49422","0.00328"
"78.13200","6.51120","0.00348"
"78.33600","6.52824","0.00330"
"78.54000","6.54516","0.00351"
"78.74400","6.56220","0.00343"
"78.94800","6.57918","0.00348"
"79.15200","6.59616","0.00317"
"79.35600","6.61320","0.00375"
"79.56000","6.63018","0.00332"
"79.76400","6.64722","0.00339"
"79.96800","6.66426","0.00311"
"80.17200","6.68118","0.00317"
"80.37600","6.69816","0.00319"
"80.58000","6.71520","0.00328"
"80.78400","6.73224","0.00323"
"80.98800","6.74916","0.00309"
"81.19200","6.76620","0.00348"
"81.39600","6.78318","0.00342"
"81.60000","6.80022","0.00329"
"81.80400","6.81714","0.00303"
"82.00800","6.83418","0.00310"
"82.21200","6.85122","0.00311"
"82.41600","6.86820","0.00309"
"82.62000","6.88518","0.00347"
"82.82400","6.90216","0.00303"
"83.02800","6.91920","0.00368"
"83.23200","6.93624","0.00299"
"83.43600","6.95316","0.00289"
"83.64000","6.97020","0.00321"
"83.84400","6.98718","0.00311"
"84.04800","7.00422","0.00329"
"84.25200","7.02120","0.00294"
"84.45600","7.03818","0.00314"
"84.66000","7.05528","0.00321"
"84.86400","7.07221","0.00333"
"85.06800","7.08919","0.00305"
"85.27200","7.10623","0.00324"
"85.47600","7.12321","0.00297"
"85.68000","7.14019","0.00315"
"85.88400","7.15723","0.00307"
"86.08800","7.17415","0.00338"
"86.29200","7.19125","0.00314"
"86.49600","7.20823","0.00314"
"86.70000","7.22515","0.00325"
"86.90400","7.24225","0.00312"
"87.10800","7.25917","0.00342"
"87.31200","7.27621","0.00322"
"87.51600","7.29319","0.00338"
"87.72000","7.31017","0.00310"
"87.92400","7.32727","0.00342"
"88.12800","7.34425","0.00329"
"88.33200","7.36117","0.00310"
"88.53600","7.37827","0.00335"
"88.74000","7.39513","0.00326"
"88.94400","7.41223","0.00360"
"89.14800","7.42921","0.00326"
"89.35200","7.44619","0.00364"
"89.55600","7.46323","0.00311"
"89.76000","7.48021","0.00303"
"89.96400","7.49725","0.00310"
"90.16800","7.51423","0.00306"
"90.37200","7.53121","0.00284"
"90.57600","7.54825","0.00335"
"90.78000","7.56517","0.00321"
"90.98400","7.58221","0.00338"
"91.18800","7.59919","0.00303"
"91.39200","7.61623","0.00315"
"91.59600","7.63321","0.00314"
"91.80000","7.65019","0.00315"
"92.00400","7.66717","0.00275"
"92.20800","7.68421","0.00334"
"92.41200","7.70125","0.00292"
"92.61600","7.71817","0.00291"
"92.82000","7.73527","0.00330"
"93.02400","7.75213","0.00267"
"93.22800","7.76923","0.00314"
"93.43200","7.78621","0.00314"
"93.63600","7.80313","0.00321"
"93.84000","7.82023","0.00262"
"94.04400","7.83721","0.00301"
"94.24800","7.85419","0.00346"
"94.45200","7.87123","0.00318"
"94.65600","7.88815","0.00317"
"94.86000","7.90519","0.00301"
"95.06400","7.92223","0.00321"
"95.26800","7.93921","0.00319"
"95.47200","7.95619","0.00296"
"95.67600","7.97323","0.00292"
"95.88000","7.99021","0.00312"
"96.08400","8.00725","0.00326"
"96.28800","8.02417","0.00300"
"96.49200","8.04121","0.00346"
"96.69600","8.05825","0.00339"
"96.90000","8.07517","0.00341"
"97.10400","8.09221","0.00328"
"97.30800","8.10919","0.00325"
"97.51200","8.12617","0.00284"
"97.71600","8.14327","0.00319"
"97.92000","8.16013","0.00324"
"98.12400","8.17723","0.00315"
"98.32800","8.19422","0.00320"
"98.53200","8.21119","0.00303"
"98.73600","8.22824","0.00321"
"98.94000","8.24522","0.00323"
"99.14400","8.26226","0.00311"
"99.34800","8.27924","0.00357"
"99.55200","8.29616","0.00319"
"99.75600","8.31326","0.00300"
"99.96000","8.33018","0.00305"
"100.16400","8.34716","0.00314"
"100.36800","8.36420","0.00311"
"100.57200","8.38124","0.00309"
"100.77600","8.39822","0.00344"
"100.98000","8.41526","0.00313"
"101.18400","8.43218","0.00309"
"101.38800","8.44922","0.00316"
"101.59200","8.46626","0.00309"
"101.79600","8.48318","0.00353"
"102.00000","8.50022","0.00307"
"102.20400","8.51714","0.00296"
"102.40800","8.53424","0.00351"
"102.61200","8.55122","0.00310"
"102.81600","8.56814","0.00334"
"103.02000","8.58524","0.00322"
"103.22400","8.60222","0.00328"
"103.42800","8.61920","0.00339"
"103.63200","8.63624","0.00357"
"103.83600","8.65316","0.00350"
"104.04000","8.67026","0.00348"
"104.24400","8.68718","0.00309"
"104.44800","8.70422","0.00277"
"104.65200","8.72120","0.00346"
"104.85600","8.73818","0.00323"
"105.06000","8.75522","0.00304"
"105.26400","8.77220","0.00315"
"105.46800","8.78918","0.00290"
"105.67200","8.80622","0.00328"
"105.87600","8.82320","0.00317"
"106.08000","8.84018","0.00347"
"106.28400","8.85716","0.00355"
"106.48800","8.87414","0.00315"
"106.69200","8.89118","0.00311"
"106.89600","8.90828","0.00346"
"107.10000","8.92514","0.00313"
"107.30400","8.94224","0.00320"
"107.50800","8.95922","0.00298"
"107.71200","8.97620","0.00340"
"107.91600","8.99324","0.00347"
"108.12000","9.01016","0.00338"
"108.32400","9.02726","0.00323"
"108.52800","9.04418","0.00355"
"108.73200","9.06116","0.00345"
"108.93600","9.07820","0.00314"
"109.14000","9.09518","0.00355"
"109.34400","9.11222","0.00292"
"109.54800","9.12920","0.00319"
"109.75200","9.14612","0.00333"
"109.95600","9.16322","0.00353"
"110.16000","9.18021","0.00342"
"110.36400","9.19718","0.00313"
"110.56800","9.21422","0.00322"
"110.77200","9.23120","0.00322"
"110.97600","9.24824","0.00326"
"111.18000","9.26528","0.00337"
"111.38400","9.28215","0.00306"
"111.58800","9.29925","0.00317"
"111.79200","9.31623","0.00364"
"111.99600","9.33315","0.00324"
"112.20000","9.35025","0.00326"
"112.40400","9.36717","0.00322"
"112.60800","9.38421","0.00319"
"112.81200","9.40125","0.00302"
"113.01600","9.41811","0.00353"
"113.22000","9.43521","0.00298"
"113.42400","9.45219","0.00363"
"113.62800","9.46923","0.00323"
"113.83200","9.48627","0.00352"
"114.03600","9.50319","0.00324"
"114.24000","9.52017","0.00357"
"114.44400","9.53721","0.00331"
"114.64800","9.55419","0.00359"
"114.85200","9.57117","0.00346"
"115.05600","9.58821","0.00371"
"115.26000","9.60519","0.00336"
"115.46400","9.62223","0.00328"
"115.66800","9.63915","0.00327"
"115.87200","9.65625","0.00301"
"116.07600","9.67323","0.00292"
"116.28000","9.69015","0.00349"
"116.48400","9.70725","0.00326"
"116.68800","9.72417","0.00336"
"116.89200","9.74121","0.00345"
"117.09600","9.75825","0.00329"
"117.30000","9.77517","0.00316"
"117.50400","9.79221","0.00313"
"117.70800","9.80919","0.00332"
"117.91200","9.82617","0.00319"
"118.11600","9.84321","0.00313"
"118.32000","9.86013","0.00350"
"118.52400","9.87723","0.00326"
"118.72800","9.89421","0.00347"
"118.93200","9.91119","0.00321"
"119.13600","9.92823","0.00342"
"119.34000","9.94515","0.00362"
"119.54400","9.96219","0.00343"
"119.74800","9.97923","0.00360"
"119.95200","9.99621","0.00306"
"120.15600","10.01319","0.00345"
"120.36000","10.03023","0.00348"
"120.56400","10.04715","0.00314"
"120.76800","10.06419","0.00332"
"120.97200","10.08123","0.00321"
"121.17600","10.09821","0.00331"
"121.38000","10.11525","0.00276"
"121.58400","10.13217","0.00369"
"121.78800","10.14921","0.00337"
"121.99200","10.16625","0.00325"
"122.19600","10.18312","0.00337"
"122.40000","10.20027","0.00337"
"122.60400","10.21719","0.00352"
"122.80800","10.23423","0.00347"
"123.01200","10.25127","0.00340"
"123.21600","10.26819","0.00352"
"123.42000","10.28523","0.00323"
"123.62400","10.30221","0.00312"
"123.82800","10.31919","0.00323"
"124.03200","10.33618","0.00351"
"124.23600","10.35322","0.00343"
"124.44000","10.37020","0.00344"
"124.64400","10.38718","0.00351"
"124.84800","10.40421","0.00311"
"125.05200","10.42120","0.00339"
"125.25600","10.43824","0.00304"
"125.46000","10.45516","0.00333"
"125.66400","10.47220","0.00367"
"125.86800","10.48912","0.00335"
"126.07200","10.50616","0.00320"
"126.27600","10.52326","0.00335"
"126.48000","10.54018","0.00353"
"126.68400","10.55722","0.00327"
"126.88800","10.57420","0.00348"
"127.09200","10.59124","0.00356"
"127.29600","10.60828","0.00344"
"127.50000","10.62520","0.00328"
"127.70400","10.64230","0.00356"
"127.90800","10.65916","0.00296"
"128.11200","10.67620","0.00345"
"128.31600","10.69318","0.00354"
"128.52000","10.71016","0.00371"
"128.72400","10.72726","0.00325"
"128.92800","10.74418","0.00388"
"129.13200","10.76116","0.00329"
"129.33600","10.77826","0.00346"
"129.54000","10.79524","0.00322"
"129.74400","10.81222","0.00349"
"129.94800","10.82920","0.00362"
"130.15200","10.84612","0.00386"
"130.35600","10.86322","0.00314"
"130.56000","10.88020","0.00376"
"130.76400","10.89718","0.00324"
"130.96800","10.91422","0.00408"
"131.17200","10.93120","0.00341"
"131.37600","10.94818","0.00384"
"131.58000","10.96528","0.00347"
"131.78400","10.98214","0.00364"
"131.98800","10.99924","0.00387"
"132.19200","11.01622","0.00343"
"132.39600","11.03314","0.00305"
"132.60000","11.05024","0.00348"
"132.80400","11.06716","0.00288"
"133.00800","11.08420","0.00373"
"133.21200","11.10124","0.00324"
"133.41600","11.11822","0.00360"
"133.62000","11.13520","0.00351"
"133.82400","11.15218","0.00334"
"134.02800","11.16922","0.00320"
"134.23200","11.18620","0.00336"
"134.43600","11.20318","0.00354"
"134.64000","11.22022","0.00352"
"134.84400","11.23720","0.00342"
"135.04800","11.25418","0.00337"
"135.25200","11.27122","0.00304"
"135.45600","11.28826","0.00367"
"135.66000","11.30519","0.00326"
"135.86400","11.32222","0.00364"
"136.06800","11.33914","0.00358"
"136.27200","11.35625","0.00394"
"136.47600","11.37322","0.00308"
"136.68000","11.39015","0.00373"
"136.88400","11.40731","0.00384"
"137.08800","11.42423","0.00354"
"137.29200","11.44121","0.00339"
"137.49600","11.45825","0.00334"
"137.70000","11.47517","0.00313"
"137.90400","11.49221","0.00370"
"138.10800","11.50925","0.00375"
"138.31200","11.52617","0.00367"
"138.51600","11.54321","0.00352"
"138.72000","11.56019","0.00390"
"138.92400","11.57717","0.00347"
"139.12800","11.59421","0.00404"
"139.33200","11.61119","0.00345"
"139.53600","11.62823","0.00337"
"139.74000","11.64527","0.00325"
"139.94400","11.66219","0.00342"
"140.14800","11.67923","0.00323"
"140.35200","11.69621","0.00363"
"140.55600","11.71313","0.00343"
"140.76000","11.73023","0.00365"
"140.96400","11.74715","0.00371"
"141.16800","11.76425","0.00347"
"141.37200","11.78117","0.00288"
"141.57600","11.79815","0.00344"
"141.78000","11.81525","0.00336"
"141.98400","11.83223","0.00392"
"142.18800","11.84927","0.00357"
"142.39200","11.86625","0.00350"
"142.59600","11.88317","0.00367"
"142.80000","11.90027","0.00381"
"143.00400","11.91719","0.00340"
"143.20800","11.93417","0.00342"
"143.41200","11.95121","0.00380"
"143.61600","11.96819","0.00357"
"143.82000","11.98523","0.00340"
"144.02400","12.00221","0.00348"
"144.22800","12.01919","0.00320"
"144.43200","12.03617","0.00372"
"144.63600","12.05321","0.00344"
"144.84000","12.07019","0.00348"
"145.04400","12.08723","0.00366"
"145.24800","12.10415","0.00345"
"145.45200","12.12119","0.00340"
"145.65600","12.13823","0.00366"
"145.86000","12.15515","0.00328"
"146.06400","12.17225","0.00349"
"146.26800","12.18923","0.00349"
"146.47200","12.20621","0.00296"
"146.67600","12.22325","0.00349"
"146.88000","12.24017","0.00329"
"147.08400","12.25727","0.00320"
"147.28800","12.27419","0.00297"
"147.49200","12.29117","0.00313"
"147.69600","12.30821","0.00320"
"147.90000","12.32519","0.00291"
"148.10400","12.34223","0.00322"
"148.30800","12.35921","0.00338"
"148.51200","12.37619","0.00291"
"148.71600","12.39323","0.00349"
"148.92000","12.41021","0.00339"
"149.12400","12.42714","0.00300"
"149.32800","12.44423","0.00282"
"149.53200","12.46122","0.00291"
"149.73600","12.47820","0.00267"
"149.94000","12.49523","0.00299"
"150.14400","12.51216","0.00335"
"150.34800","12.52925","0.00315"
"150.55200","12.54624","0.00295"
"150.75600","12.56316","0.00313"
"150.96000","12.58026","0.00314"
"151.16400","12.59718","0.00301"
"151.36800","12.61422","0.00313"
"151.57200","12.63120","0.00267"
"151.77600","12.64812","0.00338"
"151.98000","12.66522","0.00275"
"152.18400","12.68220","0.00310"
"152.38800","12.69924","0.00290"
"152.59200","12.71622","0.00316"
"152.79600","12.73320","0.00311"
"153.00000","12.75024","0.00280"
"153.20400","12.76722","0.00310"
"153.40800","12.78420","0.00315"
"153.61200","12.80124","0.00332"
"153.81600","12.81816","0.00310"
"154.02000","12.83520","0.00304"
"154.22400","12.85224","0.00314"
"154.42800","12.86916","0.00330"
"154.63200","12.88626","0.00310"
"154.83600","12.90324","0.00319"
"155.04000","12.92016","0.00321"
"155.24400","12.93726","0.00299"
"155.44800","12.95418","0.00330"
"155.65200","12.97116","0.00296"
"155.85600","12.98826","0.00304"
"156.06000","13.00512","0.00316"
"156.26400","13.02222","0.00293"
"156.46800","13.03920","0.00328"
"156.67200","13.05618","0.00295"
"156.87600","13.07322","0.00341"
"157.08000","13.09020","0.00349"
"157.28400","13.10718","0.00350"
"157.48800","13.12422","0.00288"
"157.69200","13.14120","0.00308"
"157.89600","13.15818","0.00313"
"158.10000","13.17522","0.00353"
"158.30400","13.19220","0.00318"
"158.50800","13.20918","0.00279"
"158.71200","13.22622","0.00293"
"158.91600","13.24326","0.00266"
"159.12000","13.26018","0.00242"
"159.32400","13.27716","0.00308"
"159.52800","13.29420","0.00314"
"159.73200","13.31124","0.00312"
"159.93600","13.32822","0.00298"
"160.14000","13.34526","0.00286"
"160.34400","13.36212","0.00294"
"160.54800","13.37922","0.00345"
"160.75200","13.39614","0.00311"
"160.95600","13.41318","0.00297"
"161.16000","13.43022","0.00282"
"161.36400","13.44714","0.00357"
"161.56800","13.46424","0.00340"
"161.77200","13.48123","0.00359"
"161.97600","13.49814","0.00289"
"162.18000","13.51525","0.00308"
"162.38400","13.53216","0.00290"
"162.58800","13.54921","0.00342"
"162.79200","13.56625","0.00298"
"162.99600","13.58323","0.00325"
"163.20000","13.60027","0.00267"
"163.40400","13.61725","0.00320"
"163.60800","13.63417","0.00291"
"163.81200","13.65121","0.00331"
"164.01600","13.66819","0.00296"
"164.22000","13.68517","0.00294"
"164.42400","13.70227","0.00309"
"164.62800","13.71919","0.00319"
"164.83200","13.73617","0.00282"
"165.03600","13.75327","0.00318"
"165.24000","13.77013","0.00321"
"165.44400","13.78729","0.00288"
"165.64800","13.80415","0.00297"
"165.85200","13.82125","0.00329"
"166.05600","13.83829","0.00339"
"166.26000","13.85515","0.00305"
"166.46400","13.87219","0.00263"
"166.66800","13.88923","0.00332"
"166.87200","13.90615","0.00340"
"167.07600","13.92319","0.00327"
"167.28000","13.94017","0.00279"
"167.48400","13.95721","0.00345"
"167.68800","13.97419","0.00311"
"167.89200","13.99123","0.00326"
"168.09600","14.00821","0.00335"
"168.30000","14.02525","0.00347"
"168.50400","14.04217","0.00316"
"168.70800","14.05921","0.00282"
"168.91200","14.07619","0.00320"
"169.11600","14.09317","0.00330"
"169.32000","14.11027","0.00327"
"169.52400","14.12713","0.00307"
"169.72800","14.14423","0.00319"
"169.93200","14.16121","0.00309"
"170.13600","14.17819","0.00411"
"170.34000","14.19523","0.00455"
"170.54400","14.21221","0.00432"
"170.74800","14.22925","0.00432"
"170.95200","14.24623","0.00464"
"171.15600","14.26315","0.00414"
"171.36000","14.28019","0.00342"
"171.56400","14.29717","0.00333"
"171.76800","14.31421","0.00329"
"171.97200","14.33125","0.00322"
"172.17600","14.34817","0.00317"
"172.38000","14.36527","0.00319"
"172.58400","14.38219","0.00318"
"172.78800","14.39917","0.00310"
"172.99200","14.41621","0.00337"
"173.19600","14.43313","0.00327"
"173.40000","14.45017","0.00315"
"173.60400","14.46727","0.00326"
"173.80800","14.48413","0.00344"
"174.01200","14.50123","0.00328"
"174.21600","14.51821","0.00319"
"174.42000","14.53519","0.00323"
"174.62400","14.55223","0.00309"
"174.82800","14.56921","0.00301"
"175.03200","14.58619","0.00330"
"175.23600","14.60324","0.00287"
"175.44000","14.62016","0.00322"
"175.64400","14.63726","0.00308"
"175.84800","14.65418","0.00315"
"176.05200","14.67122","0.00341"
"176.25600","14.68826","0.00342"
"176.46000","14.70518","0.00306"
"176.66400","14.72222","0.00308"
"176.86800","14.73920","0.00331"
"177.07200","14.75624","0.00293"
"177.27600","14.77322","0.00295"
"177.48000","14.79020","0.00277"
"177.68400","14.80718","0.00320"
"177.88800","14.82422","0.00317"
"178.09200","14.84120","0.00295"
"178.29600","14.85818","0.00339"
"178.50000","14.87522","0.00307"
"178.70400","14.89220","0.00366"
"178.90800","14.90924","0.00303"
"179.11200","14.92616","0.00337"
"179.31600","14.94320","0.00310"
"179.52000","14.96018","0.00299"
"179.72400","14.97716","0.00319"
"179.92800","14.99426","0.00324"
"180.13200","15.01124","0.00327"
"180.33600","15.02822","0.00305"
"180.54000","15.04520","0.00300"
"180.74400","15.06218","0.00315"
"180.94800","15.07928","0.00319"
"181.15200","15.09620","0.00287"
"181.35600","15.11318","0.00338"
"181.56000","15.13022","0.00314"
"181.76400","15.14720","0.00300"
"181.96800","15.16418","0.00310"
"182.17200","15.18122","0.00310"
"182.37600","15.19814","0.00332"
"182.58000","15.21518","0.00336"
"182.78400","15.23222","0.00333"
"182.98800","15.24914","0.00326"
"183.19200","15.26618","0.00348"
"183.39600","15.28322","0.00323"
"183.60000","15.30014","0.00385"
"183.80400","15.31724","0.00330"
"184.00800","15.33416","0.00326"
"184.21200","15.35120","0.00323"
"184.41600","15.36818","0.00330"
"184.62000","15.38510","0.00362"
"184.82400","15.40226","0.00351"
"185.02800","15.41918","0.00319"
"185.23200","15.43622","0.00356"
"185.43600","15.45320","0.00349"
"185.64000","15.47018","0.00321"
"185.84400","15.48728","0.00290"
"186.04800","15.50414","0.00350"
"186.25200","15.52118","0.00373"
"186.45600","15.53822","0.00347"
"186.66000","15.55520","0.00357"
"186.86400","15.57218","0.00340"
"187.06800","15.58922","0.00311"
"187.27200","15.60614","0.00337"
"187.47600","15.62324","0.00319"
"187.68000","15.64022","0.00326"
"187.88400","15.65720","0.00332"
"188.08800","15.67424","0.00293"
"188.29200","15.69116","0.00357"
"188.49600","15.70820","0.00330"
"188.70000","15.72524","0.00320"
"188.90400","15.74210","0.00359"
"189.10800","15.75926","0.00345"
"189.31200","15.77619","0.00313"
"189.51600","15.79317","0.00318"
"189.72000","15.81021","0.00342"
"189.92400","15.82719","0.00290"
"190.12800","15.84423","0.00331"
"190.33200","15.86121","0.00302"
"190.53600","15.87819","0.00309"
"190.74000","15.89517","0.00346"
"190.94400","15.91221","0.00282"
"191.14800","15.92925","0.00312"
"191.35200","15.94623","0.00276"
"191.55600","15.96321","0.00326"
"191.76000","15.98025","0.00280"
"191.96400","15.99723","0.00333"
"192.16800","16.01415","0.00269"
"192.37200","16.03119","0.00296"
"192.57600","16.04817","0.00345"
"192.78000","16.06521","0.00339"
"192.98400","16.08225","0.00338"
"193.18800","16.09917","0.00322"
"193.39200","16.11627","0.00376"
"193.59600","16.13325","0.00312"
"193.80000","16.15017","0.00320"
"194.00400","16.16727","0.00325"
"194.20800","16.18419","0.00293"
"194.41200","16.20123","0.00312"
"194.61600","16.21815","0.00297"
"194.82000","16.23513","0.00301"
"195.02400","16.25223","0.00315"
"195.22800","16.26915","0.00294"
"195.43200","16.28619","0.00340"
"195.63600","16.30323","0.00318"
"195.84000","16.32015","0.00292"
"196.04400","16.33725","0.00326"
"196.24800","16.35423","0.00310"
"196.45200","16.37121","0.00320"
"196.65600","16.38819","0.00313"
"196.86000","16.40517","0.00311"
"197.06400","16.42215","0.00341"
"197.26800","16.43925","0.00366"
"197.47200","16.45617","0.00295"
"197.67600","16.47327","0.00317"
"197.88000","16.49025","0.00333"
"198.08400","16.50717","0.00357"
"198.28800","16.52427","0.00342"
"198.49200","16.54119","0.00314"
"198.69600","16.55817","0.00332"
"198.90000","16.57521","0.00336"
"199.10400","16.59213","0.00318"
"199.30800","16.60923","0.00358"
"199.51200","16.62621","0.00326"
"199.71600","16.64319","0.00370"
"199.92000","16.66023","0.00305"
"200.12400","16.67715","0.00342"
"200.32800","16.69419","0.00348"
"200.53200","16.71123","0.00322"
"200.73600","16.72821","0.00338"
"200.94000","16.74520","0.00350"
"201.14400","16.76217","0.00337"
"201.34800","16.77921","0.00339"
"201.55200","16.79620","0.00341"
"201.75600","16.81318","0.00342"
"201.96000","16.83022","0.00320"
"202.16400","16.84725","0.00327"
"202.36800","16.86411","0.00342"
"202.57200","16.88122","0.00371"
"202.77600","16.89820","0.00322"
"202.98000","16.91524","0.00317"
"203.18400","16.93221","0.00314"
"203.38800","16.94920","0.00283"
"203.59200","16.96624","0.00349"
"203.79600","16.98316","0.00312"
"204.00000","17.00020","0.00316"
"204.20400","17.01724","0.00302"
"204.40800","17.03416","0.00352"
"204.61200","17.05120","0.00321"
"204.81600","17.06824","0.00371"
"205.02000","17.08516","0.00314"
"205.22400","17.10226","0.00319"
"205.42800","17.11912","0.00338"
"205.63200","17.13622","0.00341"
"205.83600","17.15326","0.00352"
"206.04000","17.17024","0.00323"
"206.24400","17.18722","0.00334"
"206.44800","17.20426","0.00328"
"206.65200","17.22118","0.00327"
"206.85600","17.23822","0.00351"
"207.06000","17.25520","0.00296"
"207.26400","17.27218","0.00263"
"207.46800","17.28922","0.00303"
"207.67200","17.30614","0.00337"
"207.87600","17.32318","0.00314"
"208.08000","17.34022","0.00300"
"208.28400","17.35720","0.00358"
"208.48800","17.37424","0.00350"
"208.69200","17.39122","0.00309"
"208.89600","17.40820","0.00318"
"209.10000","17.42524","0.00286"
"209.30400","17.44216","0.00296"
"209.50800","17.45926","0.00311"
"209.71200","17.47618","0.00303"
"209.91600","17.49322","0.00333"
"210.12000","17.51020","0.00331"
"210.32400","17.52718","0.00312"
"210.52800","17.54422","0.00326"
"210.73200","17.56120","0.00326"
"210.93600","17.57818","0.00310"
"211.14000","17.59522","0.00327"
"211.34400","17.61226","0.00338"
"211.54800","17.62918","0.00306"
"211.75200","17.64616","0.00285"
"211.95600","17.66314","0.00346"
"212.16000","17.68024","0.00333"
"212.36400","17.69722","0.00353"
"212.56800","17.71420","0.00353"
"212.77200","17.73124","0.00320"
"212.97600","17.74822","0.00347"
"213.18000","17.76520","0.00356"
"213.38400","17.78225","0.00335"
"213.58800","17.79917","0.00341"
"213.79200","17.81627","0.00348"
"213.99600","17.83319","0.00361"
"214.20000","17.85016","0.00308"
"214.40400","17.86721","0.00350"
"214.60800","17.88419","0.00295"
"214.81200","17.90122","0.00345"
"215.01600","17.91821","0.00328"
"215.22000","17.93513","0.00336"
"215.42400","17.95223","0.00338"
"215.62800","17.96921","0.00338"
"215.83200","17.98619","0.00355"
"216.03600","18.00323","0.00343"
"216.24000","18.02021","0.00338"
"216.44400","18.03719","0.00344"
"216.64800","18.05429","0.00369"
"216.85200","18.07121","0.00324"
"217.05600","18.08825","0.00369"
"217.26000","18.10523","0.00355"
"217.46400","18.12215","0.00361"
"217.66800","18.13931","0.00339"
"217.87200","18.15611","0.00341"
"218.07600","18.17321","0.00348"
"218.28000","18.19019","0.00325"
"218.48400","18.20717","0.00329"
"218.68800","18.22427","0.00320"
"218.89200","18.24125","0.00361"
"219.09600","18.25823","0.00305"
"219.30000","18.27521","0.00327"
"219.50400","18.29219","0.00336"
"219.70800","18.30923","0.00329"
"219.91200","18.32621","0.00314"
"220.11600","18.34319","0.00285"
"220.32000","18.36017","0.00346"
"220.52400","18.37715","0.00305"
"220.72800","18.39425","0.00301"
"220.93200","18.41117","0.00321"
"221.13600","18.42821","0.00327"
"221.34000","18.44519","0.00323"
"221.54400","18.46223","0.00318"
"221.74800","18.47915","0.00337"
"221.95200","18.49619","0.00310"
"222.15600","18.51317","0.00294"
"222.36000","18.53027","0.00330"
"222.56400","18.54719","0.00325"
"222.76800","18.56411","0.00283"
"222.97200","18.58127","0.00316"
"223.17600","18.59819","0.00324"
"223.38000","18.61517","0.00295"
"223.58400","18.63221","0.00326"
"223.78800","18.64919","0.00329"
"223.99200","18.66617","0.00374"
"224.19600","18.68321","0.00319"
"224.40000","18.70019","0.00315"
"224.60400","18.71723","0.00307"
"224.80800","18.73415","0.00313"
"225.01200","18.75119","0.00301"
"225.21600","18.76823","0.00326"
"225.42000","18.78521","0.00318"
"225.62400","18.80219","0.00301"
"225.82800","18.81923","0.00339"
"226.03200","18.83621","0.00332"
"226.23600","18.85320","0.00298"
"226.44000","18.87024","0.00324"
"226.64400","18.88716","0.00342"
"226.84800","18.90419","0.00321"
"227.05200","18.92118","0.00315"
"227.25600","18.93822","0.00329"
"227.46000","18.95519","0.00355"
"227.66400","18.97218","0.00303"
"227.86800","18.98921","0.00315"
"228.07200","19.00620","0.00398"
"228.27600","19.02324","0.00299"
"228.48000","19.04022","0.00319"
"228.68400","19.05720","0.00328"
"228.88800","19.07424","0.00331"
"229.09200","19.09116","0.00349"
"229.29600","19.10820","0.00350"
"229.50000","19.12524","0.00349"
"229.70400","19.14222","0.00331"
"229.90800","19.15920","0.00361"
"230.11200","19.17624","0.00351"
"230.31600","19.19322","0.00321"
"230.52000","19.21020","0.00336"
"230.72400","19.22724","0.00318"
"230.92800","19.24416","0.00354"
"231.13200","19.26120","0.00350"
"231.33600","19.27812","0.00298"
"231.54000","19.29522","0.00291"
"231.74400","19.31226","0.00318"
"231.94800","19.32918","0.00356"
"232.15200","19.34628","0.00356"
"232.35600","19.36320","0.00300"
"232.56000","19.38018","0.00341"
"232.76400","19.39722","0.00326"
"232.96800","19.41420","0.00312"
"233.17200","19.43124","0.00352"
"233.37600","19.44822","0.00351"
"233.58000","19.46520","0.00334"
"233.78400","19.48224","0.00337"
"233.98800","19.49916","0.00313"
"234.19200","19.51626","0.00339"
"234.39600","19.53324","0.00344"
"234.60000","19.55022","0.00340"
"234.80400","19.56726","0.00354"
"235.00800","19.58424","0.00376"
"235.21200","19.60116","0.00335"
"235.41600","19.61820","0.00368"
"235.62000","19.63518","0.00296"
"235.82400","19.65222","0.00341"
"236.02800","19.66926","0.00337"
"236.23200","19.68618","0.00353"
"236.43600","19.70322","0.00392"
"236.64000","19.72020","0.00308"
"236.84400","19.73718","0.00363"
"237.04800","19.75422","0.00340"
"237.25200","19.77120","0.00344"
"237.45600","19.78824","0.00334"
"237.66000","19.80516","0.00286"
"237.86400","19.82214","0.00360"
"238.06800","19.83924","0.00341"
"238.27200","19.85610","0.00322"
"238.47600","19.87320","0.00343"
"238.68000","19.89024","0.00380"
"238.88400","19.90717","0.00332"
"239.08800","19.92426","0.00337"
"239.29200","19.94124","0.00365"
"239.49600","19.95816","0.00358"
"239.70000","19.97520","0.00326"
"239.90400","19.99218","0.00312"
"240.10800","20.00923","0.00362"
"240.31200","20.02626","0.00330"
"240.51600","20.04318","0.00334"
"240.72000","20.06017","0.00352"
"240.92400","20.07721","0.00360"
"241.12800","20.09419","0.00311"
"241.33200","20.11128","0.00333"
"241.53600","20.12815","0.00340"
"241.74000","20.14513","0.00364"
"241.94400","20.16222","0.00355"
"242.14800","20.17915","0.00355"
"242.35200","20.19631","0.00324"
"242.55600","20.21323","0.00323"
"242.76000","20.23021","0.00318"
"242.96400","20.24725","0.00354"
"243.16800","20.26417","0.00334"
"243.37200","20.28121","0.00342"
"243.57600","20.29825","0.00351"
"243.78000","20.31517","0.00353"
"243.98400","20.33215","0.00344"
"244.18800","20.34919","0.00342"
"244.39200","20.36617","0.00350"
"244.59600","20.38327","0.00330"
"244.80000","20.40019","0.00337"
"245.00400","20.41723","0.00389"
"245.20800","20.43421","0.00335"
"245.41200","20.45113","0.00373"
"245.61600","20.46823","0.00378"
"245.82000","20.48521","0.00347"
"246.02400","20.50219","0.00321"
"246.22800","20.51923","0.00352"
"246.43200","20.53615","0.00339"
"246.63600","20.55325","0.00376"
"246.84000","20.57017","0.00343"
"247.04400","20.58715","0.00335"
"247.24800","20.60419","0.00349"
"247.45200","20.62117","0.00344"
"247.65600","20.63827","0.00299"
"247.86000","20.65525","0.00323"
"248.06400","20.67217","0.00326"
"248.26800","20.68927","0.00327"
"248.47200","20.70613","0.00344"
"248.67600","20.72317","0.00319"
"248.88000","20.74021","0.00304"
"249.08400","20.75725","0.00305"
"249.28800","20.77417","0.00342"
"249.49200","20.79121","0.00348"
"249.69600","20.80813","0.00326"
"249.90000","20.82523","0.00320"
"250.10400","20.84227","0.00361"
"250.30800","20.85919","0.00341"
"250.51200","20.87623","0.00331"
"250.71600","20.89315","0.00328"
"250.92000","20.91019","0.00334"
"251.12400","20.92723","0.00372"
"251.32800","20.94409","0.00323"
"251.53200","20.96132","0.00366"
"251.73600","20.97817","0.00331"
"251.94000","20.99521","0.00329"
"252.14400","21.01225","0.00351"
"252.34800","21.02917","0.00374"
"252.55200","21.04622","0.00340"
"252.75600","21.06319","0.00312"
"252.96000","21.08023","0.00327"
"253.16400","21.09715","0.00359"
"253.36800","21.11420","0.00326"
"253.57200","21.13124","0.00346"
"253.77600","21.14821","0.00314"
"253.98000","21.16525","0.00346"
"254.18400","21.18224","0.00344"
"254.38800","21.19921","0.00318"
"254.59200","21.21620","0.00332"
"254.79600","21.23318","0.00332"
"255.00000","21.25016","0.00330"
"255.20400","21.26720","0.00348"
"255.40800","21.28424","0.00349"
"255.61200","21.30116","0.00368"
"255.81600","21.31820","0.00320"
"256.02000","21.33518","0.00352"
"256.22400","21.35222","0.00352"
"256.42800","21.36926","0.00350"
"256.63200","21.38618","0.00334"
"256.83600","21.40327","0.00366"
"257.04000","21.42020","0.00323"
"257.24400","21.43712","0.00365"
"257.44800","21.45422","0.00362"
"257.65200","21.47120","0.00365"
"257.85600","21.48824","0.00329"
"258.06000","21.50522","0.00330"
"258.26400","21.52220","0.00335"
"258.46800","21.53924","0.00390"
"258.67200","21.55622","0.00330"
"258.87600","21.57320","0.00400"
"259.08000","21.59018","0.00295"
"259.28400","21.60716","0.00347"
"259.48800","21.62420","0.00351"
"259.69200","21.64124","0.00333"
"259.89600","21.65816","0.00389"
"260.10000","21.67520","0.00317"
"260.30400","21.69224","0.00351"
"260.50800","21.70916","0.00380"
"260.71200","21.72626","0.00348"
"260.91600","21.74312","0.00330"
"261.12000","21.76022","0.00328"
"261.32400","21.77720","0.00335"
"261.52800","21.79412","0.00366"
"261.73200","21.81128","0.00352"
"261.93600","21.82820","0.00324"
"262.14000","21.84518","0.00336"
"262.34400","21.86222","0.00321"
"262.54800","21.87920","0.00314"
"262.75200","21.89618","0.00343"
"262.95600","21.91322","0.00342"
"263.16000","21.93020","0.00346"
"263.36400","21.94718","0.00355"
"263.56800","21.96422","0.00373"
"263.77200","21.98120","0.00373"
"263.97600","21.99824","0.00368"
"264.18000","22.01522","0.00375"
"264.38400","22.03221","0.00345"
"264.58800","22.04924","0.00318"
"264.79200","22.06616","0.00310"
"264.99600","22.08320","0.00398"
"265.20000","22.10018","0.00388"
"265.40400","22.11723","0.00360"
"265.60800","22.13420","0.00340"
"265.81200","22.15112","0.00329"
"266.01600","22.16829","0.00339"
"266.22000","22.18521","0.00356"
"266.42400","22.20219","0.00332"
"266.62800","22.21922","0.00359"
"266.83200","22.23615","0.00376"
"267.03600","22.25325","0.00340"
"267.24000","22.27023","0.00343"
"267.44400","22.28715","0.00340"
"267.64800","22.30425","0.00399"
"267.85200","22.32122","0.00305"
"268.05600","22.33821","0.00319"
"268.26000","22.35525","0.00345"
"268.46400","22.37217","0.00336"
"268.66800","22.38921","0.00341"
"268.87200","22.40625","0.00320"
"269.07600","22.42317","0.00328"
"269.28000","22.44015","0.00329"
"269.48400","22.45724","0.00346"
"269.68800","22.47417","0.00334"
"269.89200","22.49127","0.00350"
"270.09600","22.50813","0.00357"
"270.30000","22.52523","0.00333"
"270.50400","22.54221","0.00315"
"270.70800","22.55913","0.00336"
"270.91200","22.57623","0.00366"
"271.11600","22.59315","0.00302"
"271.32000","22.61019","0.00319"
"271.52400","22.62723","0.00356"
"271.72800","22.64421","0.00341"
"271.93200","22.66125","0.00324"
"272.13600","22.67817","0.00378"
"272.34000","22.69521","0.00348"
"272.54400","22.71225","0.00323"
"272.74800","22.72917","0.00303"
"272.95200","22.74621","0.00303"
"273.15600","22.76325","0.00375"
"273.36000","22.78017","0.00326"
"273.56400","22.79721","0.00337"
"273.76800","22.81425","0.00317"
"273.97200","22.83117","0.00313"
"274.17600","22.84821","0.00327"
"274.38000","22.86513","0.00328"
"274.58400","22.88223","0.00292"
"274.78800","22.89927","0.00330"
"274.99200","22.91613","0.00341"
"275.19600","22.93323","0.00349"
"275.40000","22.95021","0.00324"
"275.60400","22.96719","0.00324"
"275.80800","22.98423","0.00302"
"276.01200","23.00121","0.00363"
"276.21600","23.01825","0.00308"
"276.42000","23.03523","0.00341"
"276.62400","23.05215","0.00326"
"276.82800","23.06925","0.00283"
"277.03200","23.08618","0.00307"
"277.23600","23.10328","0.00300"
"277.44000","23.12020","0.00298"
"277.64400","23.13723","0.00290"
"277.84800","23.15421","0.00282"
"278.05200","23.17125","0.00348"
"278.25600","23.18817","0.00292"
"278.46000","23.20522","0.00327"
"278.66400","23.22219","0.00297"
"278.86800","23.23918","0.00313"
"279.07200","23.25622","0.00303"
"279.27600","23.27319","0.00316"
"279.48000","23.29024","0.00317"
"279.68400","23.30721","0.00260"
"279.88800","23.32414","0.00333"
"280.09200","23.34124","0.00302"
"280.29600","23.35816","0.00293"
"280.50000","23.37519","0.00292"
"280.70400","23.39218","0.00279"
"280.90800","23.40916","0.00313"
"281.11200","23.42626","0.00325"
"281.31600","23.44318","0.00298"
"281.52000","23.46022","0.00246"
"281.72400","23.47720","0.00297"
"281.92800","23.49418","0.00291"
"282.13200","23.51122","0.00268"
"282.33600","23.52820","0.00266"
"282.54000","23.54518","0.00333"
"282.74400","23.56222","0.00298"
"282.94800","23.57920","0.00273"
"283.15200","23.59618","0.00305"
"283.35600","23.61322","0.00287"
"283.56000","23.63014","0.00283"
"283.76400","23.64718","0.00277"
"283.96800","23.66422","0.00301"
"284.17200","23.68120","0.00289"
"284.37600","23.69824","0.00273"
"284.58000","23.71516","0.00320"
"284.78400","23.73214","0.00282"
"284.98800","23.74924","0.00317"
"285.19200","23.76610","0.00309"
"285.39600","23.78326","0.00276"
"285.60000","23.80018","0.00272"
"285.80400","23.81716","0.00300"
"286.00800","23.83420","0.00341"
"286.21200","23.85118","0.00317"
"286.41600","23.86822","0.00276"
"286.62000","23.88520","0.00314"
"286.82400","23.90218","0.00305"
"287.02800","23.91916","0.00294"
"287.23200","23.93620","0.00299"
"287.43600","23.95324","0.00276"
"287.64000","23.97022","0.00334"
"287.84400","23.98720","0.00318"
"288.04800","24.00424","0.00350"
"288.25200","24.02116","0.00298"
"288.45600","24.03820","0.00350"
"288.66000","24.05524","0.00303"
"288.86400","24.07222","0.00323"
"289.06800","24.08920","0.00323"
"289.27200","24.10624","0.00318"
"289.47600","24.12316","0.00296"
"289.68000","24.14020","0.00321"
"289.88400","24.15718","0.00324"
"290.08800","24.17416","0.00316"
"290.29200","24.19126","0.00340"
"290.49600","24.20819","0.00314"
"290.70000","24.22528","0.00289"
"290.90400","24.24226","0.00315"
"291.10800","24.25913","0.00336"
"291.31200","24.27628","0.00359"
"291.51600","24.29314","0.00330"
"291.72000","24.31018","0.00322"
"291.92400","24.32723","0.00290"
"292.12800","24.34420","0.00290"
"292.33200","24.36125","0.00349"
"292.53600","24.37823","0.00306"
"292.74000","24.39515","0.00356"
"292.94400","24.41225","0.00319"
"293.14800","24.42928","0.00320"
"293.35200","24.44621","0.00313"
"293.55600","24.46325","0.00336"
"293.76000","24.48017","0.00301"
"293.96400","24.49715","0.00344"
"294.16800","24.51424","0.00303"
"294.37200","24.53111","0.00318"
"294.57600","24.54827","0.00331"
"294.78000","24.56519","0.00310"
"294.98400","24.58217","0.00321"
"295.18800","24.59927","0.00345"
"295.39200","24.61613","0.00287"
"295.59600","24.63323","0.00310"
"295.80000","24.65027","0.00309"
"296.00400","24.66713","0.00331"
"296.20800","24.68423","0.00310"
"296.41200","24.70121","0.00319"
"296.61600","24.71819","0.00293"
"296.82000","24.73523","0.00321"
"297.02400","24.75221","0.00314"
"297.22800","24.76919","0.00308"
"297.43200","24.78623","0.00299"
"297.63600","24.80315","0.00312"
"297.84000","24.82013","0.00342"
"298.04400","24.83717","0.00283"
"298.24800","24.85421","0.00297"
"298.45200","24.87125","0.00340"
"298.65600","24.88817","0.00291"
"298.86000","24.90521","0.00268"
"299.06400","24.92225","0.00290"
"299.26800","24.93917","0.00261"
"299.47200","24.95627","0.00290"
"299.67600","24.97319","0.00304"
"299.88000","24.99023","0.00275"
"300.08400","25.00721","0.00298"
"300.28800","25.02419","0.00284"
"300.49200","25.04123","0.00289"
"300.69600","25.05815","0.00317"
"300.90000","25.07525","0.00294"
"301.10400","25.09223","0.00320"
"301.30800","25.10915","0.00289"
"301.51200","25.12626","0.00239"
"301.71600","25.14323","0.00233"
"301.92000","25.16021","0.00302"
"302.12400","25.17719","0.00301"
"302.32800","25.19417","0.00341"
"302.53200","25.21122","0.00333"
"302.73600","25.22825","0.00280"
"302.94000","25.24517","0.00291"
"303.14400","25.26221","0.00316"
"303.34800","25.27919","0.00300"
"303.55200","25.29617","0.00322"
"303.75600","25.31322","0.00303"
"303.96000","25.33019","0.00257"
"304.16400","25.34717","0.00297"
"304.36800","25.36422","0.00317"
"304.57200","25.38107","0.00272"
"304.77600","25.39824","0.00245"
"304.98000","25.41522","0.00328"
"305.18400","25.43220","0.00269"
"305.38000","25.44852","0.00295"