File: Force_trajectories/161223/Specimen_RawData_7.csv
End date,"12/23/2016"
Specimen label,"24DG_92"
Maximum Load,"0.21653",N

Time,Extension,Load
(s),(mm),(N)
"0.00000","0.00000","-0.00011"
"0.20400","0.01447","0.00016"
"0.40800","0.03426","0.00059"
"0.61200","0.05118","0.00099"
"0.81600","0.06822","0.00114"
"1.02000","0.08526","0.00115"
"1.22400","0.10212","0.00126"
"1.42800","0.11922","0.00127"
"1.63200","0.13620","0.00164"
"1.83600","0.15318","0.00203"
"2.04000","0.17022","0.00199"
"2.24400","0.18720","0.00169"
"2.44800","0.20424","0.00194"
"2.65200","0.22122","0.00186"
"2.85600","0.23814","0.00209"
"3.06000","0.25524","0.00243"
"3.26400","0.27216","0.00236"
"3.46800","0.28920","0.00236"
"3.67200","0.30618","0.00271"
"3.87600","0.32316","0.00223"
"4.08000","0.34020","0.00240"
"4.28400","0.35718","0.00280"
"4.48800","0.37416","0.00277"
"4.69200","0.39114","0.00273"
"4.89600","0.40818","0.00302"
"5.10000","0.42516","0.00308"
"5.30400","0.44226","0.00296"
"5.50800","0.45918","0.00351"
"5.71200","0.47616","0.00324"
"5.91600","0.49320","0.00305"
"6.12000","0.51012","0.00228"
"6.32400","0.52722","0.00266"
"6.52800","0.54414","0.00237"
"6.73200","0.56118","0.00297"
"6.93600","0.57810","0.00264"
"7.14000","0.59515","0.00297"
"7.34400","0.61219","0.00295"
"7.54800","0.62917","0.00316"
"7.75200","0.64621","0.00263"
"7.95600","0.66319","0.00322"
"8.16000","0.68011","0.00325"
"8.36400","0.69721","0.00308"
"8.56800","0.71419","0.00271"
"8.77200","0.73117","0.00298"
"8.97600","0.74821","0.00336"
"9.18000","0.76519","0.00330"
"9.38400","0.78217","0.00305"
"9.58800","0.79921","0.00295"
"9.79200","0.81619","0.00263"
"9.99600","0.83323","0.00337"
"10.20000","0.85021","0.00322"
"10.40400","0.86719","0.00312"
"10.60800","0.88423","0.00353"
"10.81200","0.90115","0.00303"
"11.01600","0.91813","0.00311"
"11.22000","0.93523","0.00329"
"11.42400","0.95209","0.00312"
"11.62800","0.96925","0.00345"
"11.83200","0.98617","0.00301"
"12.03600","1.00315","0.00298"
"12.24000","1.02019","0.00344"
"12.44400","1.03717","0.00352"
"12.64800","1.05421","0.00311"
"12.85200","1.07119","0.00332"
"13.05600","1.08817","0.00329"
"13.26000","1.10515","0.00328"
"13.46400","1.12219","0.00330"
"13.66800","1.13923","0.00339"
"13.87200","1.15615","0.00331"
"14.07600","1.17319","0.00348"
"14.28000","1.19017","0.00383"
"14.48400","1.20721","0.00317"
"14.68800","1.22413","0.00366"
"14.89200","1.24117","0.00344"
"15.09600","1.25821","0.00375"
"15.30000","1.27519","0.00352"
"15.50400","1.29223","0.00353"
"15.70800","1.30915","0.00352"
"15.91200","1.32619","0.00344"
"16.11600","1.34317","0.00340"
"16.32000","1.36009","0.00340"
"16.52400","1.37719","0.00348"
"16.72800","1.39417","0.00354"
"16.93200","1.41121","0.00389"
"17.13600","1.42819","0.00329"
"17.34000","1.44511","0.00379"
"17.54400","1.46221","0.00388"
"17.74800","1.47913","0.00357"
"17.95200","1.49617","0.00356"
"18.15600","1.51321","0.00383"
"18.36000","1.53019","0.00354"
"18.56400","1.54717","0.00371"
"18.76800","1.56415","0.00348"
"18.97200","1.58113","0.00364"
"19.17600","1.59823","0.00371"
"19.38000","1.61521","0.00379"
"19.58400","1.63213","0.00418"
"19.78800","1.64917","0.00360"
"19.99200","1.66615","0.00397"
"20.19600","1.68314","0.00380"
"20.40000","1.70024","0.00391"
"20.60400","1.71710","0.00364"
"20.80800","1.73420","0.00413"
"21.01200","1.75112","0.00424"
"21.21600","1.76816","0.00381"
"21.42000","1.78526","0.00408"
"21.62400","1.80218","0.00383"
"21.82800","1.81916","0.00414"
"22.03200","1.83620","0.00440"
"22.23600","1.85318","0.00431"
"22.44000","1.87022","0.00409"
"22.64400","1.88720","0.00406"
"22.84800","1.90418","0.00428"
"23.05200","1.92122","0.00415"
"23.25600","1.93820","0.00441"
"23.46000","1.95518","0.00424"
"23.66400","1.97222","0.00386"
"23.86800","1.98914","0.00389"
"24.07200","2.00612","0.00416"
"24.27600","2.02316","0.00379"
"24.48000","2.04020","0.00415"
"24.68400","2.05724","0.00430"
"24.88800","2.07416","0.00429"
"25.09200","2.09120","0.00416"
"25.29600","2.10824","0.00392"
"25.50000","2.12516","0.00448"
"25.70400","2.14220","0.00431"
"25.90800","2.15918","0.00444"
"26.11200","2.17622","0.00420"
"26.31600","2.19320","0.00424"
"26.52000","2.21012","0.00397"
"26.72400","2.22722","0.00403"
"26.92800","2.24414","0.00431"
"27.13200","2.26124","0.00401"
"27.33600","2.27822","0.00406"
"27.54000","2.29520","0.00415"
"27.74400","2.31224","0.00394"
"27.94800","2.32916","0.00405"
"28.15200","2.34620","0.00418"
"28.35600","2.36318","0.00402"
"28.56000","2.38016","0.00404"
"28.76400","2.39714","0.00413"
"28.96800","2.41424","0.00455"
"29.17200","2.43116","0.00427"
"29.37600","2.44820","0.00439"
"29.58000","2.46518","0.00458"
"29.78400","2.48216","0.00410"
"29.98800","2.49920","0.00408"
"30.19200","2.51612","0.00442"
"30.39600","2.53316","0.00430"
"30.60000","2.55026","0.00451"
"30.80400","2.56712","0.00430"
"31.00800","2.58428","0.00420"
"31.21200","2.60120","0.00430"
"31.41600","2.61818","0.00454"
"31.62000","2.63522","0.00442"
"31.82400","2.65220","0.00483"
"32.02800","2.66918","0.00457"
"32.23200","2.68622","0.00456"
"32.43600","2.70314","0.00433"
"32.64000","2.72018","0.00454"
"32.84400","2.73716","0.00420"
"33.04800","2.75420","0.00409"
"33.25200","2.77119","0.00440"
"33.45600","2.78817","0.00429"
"33.66000","2.80515","0.00452"
"33.86400","2.82219","0.00437"
"34.06800","2.83911","0.00406"
"34.27200","2.85615","0.00453"
"34.47600","2.87319","0.00424"
"34.68000","2.89017","0.00443"
"34.88400","2.90721","0.00476"
"35.08800","2.92413","0.00451"
"35.29200","2.94123","0.00421"
"35.49600","2.95821","0.00467"
"35.70000","2.97513","0.00422"
"35.90400","2.99223","0.00452"
"36.10800","3.00915","0.00430"
"36.31200","3.02619","0.00468"
"36.51600","3.04317","0.00462"
"36.72000","3.06015","0.00466"
"36.92400","3.07725","0.00468"
"37.12800","3.09417","0.00450"
"37.33200","3.11115","0.00468"
"37.53600","3.12819","0.00486"
"37.74000","3.14517","0.00458"
"37.94400","3.16221","0.00434"
"38.14800","3.17919","0.00434"
"38.35200","3.19617","0.00451"
"38.55600","3.21315","0.00436"
"38.76000","3.23019","0.00418"
"38.96400","3.24717","0.00476"
"39.16800","3.26421","0.00403"
"39.37200","3.28113","0.00468"
"39.57600","3.29817","0.00460"
"39.78000","3.31521","0.00408"
"39.98400","3.33213","0.00449"
"40.18800","3.34923","0.00462"
"40.39200","3.36615","0.00450"
"40.59600","3.38319","0.00466"
"40.80000","3.40023","0.00471"
"41.00400","3.41715","0.00485"
"41.20800","3.43425","0.00459"
"41.41200","3.45117","0.00474"
"41.61600","3.46815","0.00439"
"41.82000","3.48519","0.00473"
"42.02400","3.50217","0.00496"
"42.22800","3.51921","0.00471"
"42.43200","3.53619","0.00485"
"42.63600","3.55317","0.00507"
"42.84000","3.57021","0.00494"
"43.04400","3.58719","0.00498"
"43.24800","3.60417","0.00474"
"43.45200","3.62121","0.00490"
"43.65600","3.63813","0.00466"
"43.86000","3.65517","0.00497"
"44.06400","3.67221","0.00482"
"44.26800","3.68907","0.00471"
"44.47200","3.70623","0.00463"
"44.67600","3.72321","0.00449"
"44.88000","3.74013","0.00481"
"45.08400","3.75723","0.00456"
"45.28800","3.77415","0.00494"
"45.49200","3.79119","0.00476"
"45.69600","3.80817","0.00488"
"45.90000","3.82515","0.00521"
"46.10400","3.84220","0.00505"
"46.30800","3.85912","0.00477"
"46.51200","3.87622","0.00501"
"46.71600","3.89326","0.00495"
"46.92000","3.91018","0.00439"
"47.12400","3.92722","0.00514"
"47.32800","3.94420","0.00512"
"47.53200","3.96118","0.00485"
"47.73600","3.97816","0.00510"
"47.94000","3.99520","0.00483"
"48.14400","4.01218","0.00435"
"48.34800","4.02922","0.00450"
"48.55200","4.04614","0.00489"
"48.75600","4.06324","0.00512"
"48.96000","4.08022","0.00474"
"49.16400","4.09714","0.00438"
"49.36800","4.11424","0.00509"
"49.57200","4.13116","0.00500"
"49.77600","4.14820","0.00504"
"49.98000","4.16518","0.00527"
"50.18400","4.18210","0.00472"
"50.38800","4.19920","0.00453"
"50.59200","4.21618","0.00475"
"50.79600","4.23316","0.00493"
"51.00000","4.25020","0.00487"
"51.20400","4.26712","0.00449"
"51.40800","4.28422","0.00488"
"51.61200","4.30120","0.00506"
"51.81600","4.31818","0.00489"
"52.02000","4.33522","0.00485"
"52.22400","4.35220","0.00449"
"52.42800","4.36918","0.00467"
"52.63200","4.38616","0.00526"
"52.83600","4.40314","0.00485"
"53.04000","4.42024","0.00493"
"53.24400","4.43722","0.00485"
"53.44800","4.45414","0.00475"
"53.65200","4.47118","0.00475"
"53.85600","4.48816","0.00489"
"54.06000","4.50514","0.00480"
"54.26400","4.52224","0.00486"
"54.46800","4.53910","0.00482"
"54.67200","4.55620","0.00467"
"54.87600","4.57318","0.00470"
"55.08000","4.59016","0.00494"
"55.28400","4.60726","0.00472"
"55.48800","4.62412","0.00477"
"55.69200","4.64122","0.00517"
"55.89600","4.65820","0.00540"
"56.10000","4.67512","0.00504"
"56.30400","4.69216","0.00519"
"56.50800","4.70920","0.00500"
"56.71200","4.72618","0.00513"
"56.91600","4.74316","0.00500"
"57.12000","4.76020","0.00502"
"57.32400","4.77712","0.00490"
"57.52800","4.79416","0.00483"
"57.73200","4.81114","0.00468"
"57.93600","4.82818","0.00492"
"58.14000","4.84516","0.00514"
"58.34400","4.86220","0.00500"
"58.54800","4.87918","0.00505"
"58.75200","4.89616","0.00565"
"58.95600","4.91320","0.00494"
"59.16000","4.93013","0.00473"
"59.36400","4.94711","0.00464"
"59.56800","4.96421","0.00546"
"59.77200","4.98119","0.00477"
"59.97600","4.99823","0.00516"
"60.18000","5.01521","0.00502"
"60.38400","5.03213","0.00500"
"60.58800","5.04929","0.00536"
"60.79200","5.06615","0.00512"
"60.99600","5.08319","0.00533"
"61.20000","5.10017","0.00506"
"61.40400","5.11715","0.00477"
"61.60800","5.13419","0.00540"
"61.81200","5.15117","0.00518"
"62.01600","5.16815","0.00537"
"62.22000","5.18525","0.00518"
"62.42400","5.20223","0.00511"
"62.62800","5.21921","0.00523"
"62.83200","5.23619","0.00518"
"63.03600","5.25317","0.00511"
"63.24000","5.27015","0.00542"
"63.44400","5.28725","0.00529"
"63.64800","5.30417","0.00525"
"63.85200","5.32121","0.00516"
"64.05600","5.33819","0.00543"
"64.26000","5.35517","0.00539"
"64.46400","5.37227","0.00525"
"64.66800","5.38913","0.00531"
"64.87200","5.40623","0.00530"
"65.07600","5.42315","0.00535"
"65.28000","5.44019","0.00507"
"65.48400","5.45717","0.00548"
"65.68800","5.47421","0.00538"
"65.89200","5.49119","0.00510"
"66.09600","5.50823","0.00530"
"66.30000","5.52515","0.00521"
"66.50400","5.54219","0.00492"
"66.70800","5.55923","0.00482"
"66.91200","5.57615","0.00531"
"67.11600","5.59313","0.00524"
"67.32000","5.61017","0.00534"
"67.52400","5.62721","0.00574"
"67.72800","5.64419","0.00529"
"67.93200","5.66117","0.00529"
"68.13600","5.67821","0.00563"
"68.34000","5.69519","0.00576"
"68.54400","5.71211","0.00501"
"68.74800","5.72921","0.00588"
"68.95200","5.74619","0.00553"
"69.15600","5.76317","0.00567"
"69.36000","5.78021","0.00530"
"69.56400","5.79707","0.00545"
"69.76800","5.81423","0.00567"
"69.97200","5.83121","0.00578"
"70.17600","5.84819","0.00535"
"70.38000","5.86517","0.00581"
"70.58400","5.88215","0.00550"
"70.78800","5.89919","0.00579"
"70.99200","5.91617","0.00568"
"71.19600","5.93315","0.00560"
"71.40000","5.95019","0.00547"
"71.60400","5.96717","0.00562"
"71.80800","5.98416","0.00567"
"72.01200","6.00120","0.00568"
"72.21600","6.01812","0.00580"
"72.42000","6.03522","0.00575"
"72.62400","6.05226","0.00569"
"72.82800","6.06912","0.00589"
"73.03200","6.08622","0.00581"
"73.23600","6.10314","0.00522"
"73.44000","6.12018","0.00582"
"73.64400","6.13722","0.00581"
"73.84800","6.15414","0.00607"
"74.05200","6.17124","0.00568"
"74.25600","6.18822","0.00619"
"74.46000","6.20514","0.00535"
"74.66400","6.22218","0.00568"
"74.86800","6.23916","0.00538"
"75.07200","6.25620","0.00599"
"75.27600","6.27324","0.00536"
"75.48000","6.29016","0.00557"
"75.68400","6.30726","0.00560"
"75.88800","6.32418","0.00581"
"76.09200","6.34122","0.00556"
"76.29600","6.35814","0.00602"
"76.50000","6.37518","0.00579"
"76.70400","6.39216","0.00577"
"76.90800","6.40920","0.00557"
"77.11200","6.42612","0.00622"
"77.31600","6.44316","0.00589"
"77.52000","6.46020","0.00583"
"77.72400","6.47718","0.00554"
"77.92800","6.49422","0.00564"
"78.13200","6.51114","0.00581"
"78.33600","6.52824","0.00600"
"78.54000","6.54522","0.00570"
"78.74400","6.56214","0.00592"
"78.94800","6.57918","0.00573"
"79.15200","6.59616","0.00567"
"79.35600","6.61320","0.00563"
"79.56000","6.63024","0.00584"
"79.76400","6.64716","0.00546"
"79.96800","6.66420","0.00548"
"80.17200","6.68112","0.00562"
"80.37600","6.69816","0.00573"
"80.58000","6.71514","0.00561"
"80.78400","6.73218","0.00545"
"80.98800","6.74922","0.00587"
"81.19200","6.76620","0.00574"
"81.39600","6.78318","0.00560"
"81.60000","6.80022","0.00553"
"81.80400","6.81720","0.00593"
"82.00800","6.83412","0.00544"
"82.21200","6.85116","0.00529"
"82.41600","6.86814","0.00562"
"82.62000","6.88518","0.00606"
"82.82400","6.90216","0.00541"
"83.02800","6.91914","0.00584"
"83.23200","6.93618","0.00600"
"83.43600","6.95316","0.00577"
"83.64000","6.97014","0.00567"
"83.84400","6.98724","0.00600"
"84.04800","7.00416","0.00563"
"84.25200","7.02126","0.00556"
"84.45600","7.03818","0.00543"
"84.66000","7.05516","0.00589"
"84.86400","7.07221","0.00608"
"85.06800","7.08913","0.00603"
"85.27200","7.10623","0.00597"
"85.47600","7.12321","0.00598"
"85.68000","7.14019","0.00554"
"85.88400","7.15723","0.00590"
"86.08800","7.17421","0.00598"
"86.29200","7.19113","0.00576"
"86.49600","7.20823","0.00584"
"86.70000","7.22515","0.00542"
"86.90400","7.24225","0.00570"
"87.10800","7.25923","0.00549"
"87.31200","7.27615","0.00600"
"87.51600","7.29325","0.00577"
"87.72000","7.31023","0.00581"
"87.92400","7.32709","0.00555"
"88.12800","7.34425","0.00589"
"88.33200","7.36117","0.00587"
"88.53600","7.37821","0.00596"
"88.74000","7.39519","0.00567"
"88.94400","7.41211","0.00603"
"89.14800","7.42921","0.00596"
"89.35200","7.44613","0.00615"
"89.55600","7.46317","0.00543"
"89.76000","7.48021","0.00600"
"89.96400","7.49719","0.00612"
"90.16800","7.51423","0.00600"
"90.37200","7.53121","0.00637"
"90.57600","7.54813","0.00614"
"90.78000","7.56511","0.00571"
"90.98400","7.58221","0.00585"
"91.18800","7.59919","0.00610"
"91.39200","7.61623","0.00597"
"91.59600","7.63315","0.00572"
"91.80000","7.65025","0.00569"
"92.00400","7.66717","0.00637"
"92.20800","7.68415","0.00562"
"92.41200","7.70119","0.00564"
"92.61600","7.71817","0.00589"
"92.82000","7.73521","0.00634"
"93.02400","7.75219","0.00611"
"93.22800","7.76911","0.00601"
"93.43200","7.78627","0.00646"
"93.63600","7.80313","0.00618"
"93.84000","7.82017","0.00595"
"94.04400","7.83715","0.00612"
"94.24800","7.85413","0.00605"
"94.45200","7.87117","0.00555"
"94.65600","7.88821","0.00626"
"94.86000","7.90513","0.00661"
"95.06400","7.92223","0.00601"
"95.26800","7.93915","0.00610"
"95.47200","7.95619","0.00628"
"95.67600","7.97323","0.00627"
"95.88000","7.99015","0.00637"
"96.08400","8.00719","0.00574"
"96.28800","8.02417","0.00618"
"96.49200","8.04115","0.00612"
"96.69600","8.05819","0.00590"
"96.90000","8.07517","0.00614"
"97.10400","8.09215","0.00623"
"97.30800","8.10925","0.00645"
"97.51200","8.12611","0.00625"
"97.71600","8.14321","0.00661"
"97.92000","8.16020","0.00634"
"98.12400","8.17718","0.00650"
"98.32800","8.19422","0.00684"
"98.53200","8.21114","0.00655"
"98.73600","8.22818","0.00642"
"98.94000","8.24522","0.00635"
"99.14400","8.26214","0.00659"
"99.34800","8.27918","0.00654"
"99.55200","8.29616","0.00623"
"99.75600","8.31314","0.00661"
"99.96000","8.33024","0.00647"
"100.16400","8.34716","0.00677"
"100.36800","8.36420","0.00697"
"100.57200","8.38112","0.00678"
"100.77600","8.39810","0.00700"
"100.98000","8.41514","0.00691"
"101.18400","8.43224","0.00715"
"101.38800","8.44916","0.00689"
"101.59200","8.46620","0.00655"
"101.79600","8.48318","0.00702"
"102.00000","8.50016","0.00698"
"102.20400","8.51714","0.00708"
"102.40800","8.53418","0.00677"
"102.61200","8.55116","0.00715"
"102.81600","8.56814","0.00692"
"103.02000","8.58518","0.00686"
"103.22400","8.60222","0.00682"
"103.42800","8.61914","0.00707"
"103.63200","8.63624","0.00689"
"103.83600","8.65316","0.00693"
"104.04000","8.67014","0.00706"
"104.24400","8.68718","0.00720"
"104.44800","8.70416","0.00744"
"104.65200","8.72120","0.00692"
"104.85600","8.73824","0.00697"
"105.06000","8.75516","0.00673"
"105.26400","8.77220","0.00643"
"105.46800","8.78924","0.00721"
"105.67200","8.80616","0.00694"
"105.87600","8.82320","0.00687"
"106.08000","8.84018","0.00701"
"106.28400","8.85710","0.00718"
"106.48800","8.87426","0.00733"
"106.69200","8.89106","0.00710"
"106.89600","8.90822","0.00720"
"107.10000","8.92520","0.00756"
"107.30400","8.94218","0.00729"
"107.50800","8.95922","0.00713"
"107.71200","8.97620","0.00722"
"107.91600","8.99318","0.00708"
"108.12000","9.01016","0.00753"
"108.32400","9.02714","0.00729"
"108.52800","9.04418","0.00720"
"108.73200","9.06116","0.00727"
"108.93600","9.07820","0.00686"
"109.14000","9.09518","0.00724"
"109.34400","9.11222","0.00714"
"109.54800","9.12920","0.00690"
"109.75200","9.14618","0.00713"
"109.95600","9.16316","0.00713"
"110.16000","9.18014","0.00692"
"110.36400","9.19713","0.00723"
"110.56800","9.21416","0.00716"
"110.77200","9.23120","0.00727"
"110.97600","9.24819","0.00707"
"111.18000","9.26517","0.00750"
"111.38400","9.28221","0.00728"
"111.58800","9.29919","0.00735"
"111.79200","9.31623","0.00723"
"111.99600","9.33321","0.00702"
"112.20000","9.35025","0.00704"
"112.40400","9.36723","0.00697"
"112.60800","9.38409","0.00709"
"112.81200","9.40125","0.00716"
"113.01600","9.41817","0.00735"
"113.22000","9.43521","0.00726"
"113.42400","9.45219","0.00744"
"113.62800","9.46917","0.00685"
"113.83200","9.48621","0.00710"
"114.03600","9.50319","0.00668"
"114.24000","9.52017","0.00733"
"114.44400","9.53715","0.00741"
"114.64800","9.55419","0.00671"
"114.85200","9.57117","0.00672"
"115.05600","9.58821","0.00716"
"115.26000","9.60513","0.00719"
"115.46400","9.62217","0.00732"
"115.66800","9.63921","0.00716"
"115.87200","9.65613","0.00717"
"116.07600","9.67317","0.00750"
"116.28000","9.69015","0.00704"
"116.48400","9.70719","0.00742"
"116.68800","9.72423","0.00699"
"116.89200","9.74109","0.00685"
"117.09600","9.75825","0.00675"
"117.30000","9.77517","0.00685"
"117.50400","9.79215","0.00673"
"117.70800","9.80919","0.00712"
"117.91200","9.82617","0.00669"
"118.11600","9.84321","0.00693"
"118.32000","9.86019","0.00728"
"118.52400","9.87717","0.00733"
"118.72800","9.89421","0.00678"
"118.93200","9.91113","0.00737"
"119.13600","9.92817","0.00764"
"119.34000","9.94521","0.00691"
"119.54400","9.96219","0.00761"
"119.74800","9.97917","0.00729"
"119.95200","9.99621","0.00737"
"120.15600","10.01313","0.00701"
"120.36000","10.03017","0.00754"
"120.56400","10.04715","0.00723"
"120.76800","10.06419","0.00761"
"120.97200","10.08117","0.00738"
"121.17600","10.09815","0.00716"
"121.38000","10.11519","0.00722"
"121.58400","10.13223","0.00749"
"121.78800","10.14909","0.00770"
"121.99200","10.16625","0.00734"
"122.19600","10.18317","0.00762"
"122.40000","10.20021","0.00760"
"122.60400","10.21719","0.00799"
"122.80800","10.23417","0.00766"
"123.01200","10.25115","0.00792"
"123.21600","10.26819","0.00753"
"123.42000","10.28512","0.00757"
"123.62400","10.30221","0.00701"
"123.82800","10.31919","0.00739"
"124.03200","10.33618","0.00741"
"124.23600","10.35322","0.00751"
"124.44000","10.37020","0.00744"
"124.64400","10.38718","0.00750"
"124.84800","10.40421","0.00758"
"125.05200","10.42114","0.00778"
"125.25600","10.43818","0.00735"
"125.46000","10.45516","0.00753"
"125.66400","10.47214","0.00733"
"125.86800","10.48924","0.00733"
"126.07200","10.50610","0.00754"
"126.27600","10.52320","0.00779"
"126.48000","10.54024","0.00772"
"126.68400","10.55716","0.00736"
"126.88800","10.57420","0.00769"
"127.09200","10.59124","0.00776"
"127.29600","10.60822","0.00763"
"127.50000","10.62520","0.00786"
"127.70400","10.64218","0.00769"
"127.90800","10.65922","0.00819"
"128.11200","10.67620","0.00754"
"128.31600","10.69318","0.00782"
"128.52000","10.71028","0.00805"
"128.72400","10.72714","0.00823"
"128.92800","10.74418","0.00822"
"129.13200","10.76116","0.00759"
"129.33600","10.77814","0.00763"
"129.54000","10.79518","0.00815"
"129.74400","10.81216","0.00767"
"129.94800","10.82914","0.00834"
"130.15200","10.84624","0.00804"
"130.35600","10.86310","0.00806"
"130.56000","10.88020","0.00805"
"130.76400","10.89718","0.00788"
"130.96800","10.91416","0.00789"
"131.17200","10.93120","0.00816"
"131.37600","10.94818","0.00804"
"131.58000","10.96516","0.00828"
"131.78400","10.98220","0.00828"
"131.98800","10.99912","0.00821"
"132.19200","11.01622","0.00809"
"132.39600","11.03314","0.00795"
"132.60000","11.05018","0.00849"
"132.80400","11.06722","0.00821"
"133.00800","11.08420","0.00838"
"133.21200","11.10124","0.00827"
"133.41600","11.11816","0.00868"
"133.62000","11.13520","0.00866"
"133.82400","11.15218","0.00864"
"134.02800","11.16922","0.00833"
"134.23200","11.18620","0.00855"
"134.43600","11.20324","0.00877"
"134.64000","11.22016","0.00872"
"134.84400","11.23720","0.00880"
"135.04800","11.25424","0.00813"
"135.25200","11.27116","0.00854"
"135.45600","11.28820","0.00847"
"135.66000","11.30519","0.00846"
"135.86400","11.32216","0.00868"
"136.06800","11.33914","0.00851"
"136.27200","11.35612","0.00898"
"136.47600","11.37322","0.00834"
"136.68000","11.39015","0.00851"
"136.88400","11.40718","0.00863"
"137.08800","11.42417","0.00878"
"137.29200","11.44109","0.00858"
"137.49600","11.45825","0.00832"
"137.70000","11.47517","0.00846"
"137.90400","11.49215","0.00852"
"138.10800","11.50919","0.00899"
"138.31200","11.52617","0.00874"
"138.51600","11.54321","0.00862"
"138.72000","11.56025","0.00904"
"138.92400","11.57717","0.00851"
"139.12800","11.59421","0.00874"
"139.33200","11.61125","0.00899"
"139.53600","11.62817","0.00885"
"139.74000","11.64521","0.00892"
"139.94400","11.66219","0.00894"
"140.14800","11.67923","0.00924"
"140.35200","11.69627","0.00943"
"140.55600","11.71313","0.00880"
"140.76000","11.73017","0.00892"
"140.96400","11.74721","0.00912"
"141.16800","11.76413","0.00892"
"141.37200","11.78123","0.00950"
"141.57600","11.79815","0.00955"
"141.78000","11.81519","0.00902"
"141.98400","11.83223","0.00943"
"142.18800","11.84915","0.00928"
"142.39200","11.86619","0.00931"
"142.59600","11.88317","0.00903"
"142.80000","11.90021","0.00934"
"143.00400","11.91719","0.00997"
"143.20800","11.93417","0.00976"
"143.41200","11.95121","0.00919"
"143.61600","11.96819","0.00932"
"143.82000","11.98511","0.00931"
"144.02400","12.00221","0.00956"
"144.22800","12.01919","0.00950"
"144.43200","12.03617","0.01008"
"144.63600","12.05321","0.00964"
"144.84000","12.07013","0.00954"
"145.04400","12.08717","0.00976"
"145.24800","12.10421","0.00907"
"145.45200","12.12113","0.00974"
"145.65600","12.13823","0.00962"
"145.86000","12.15515","0.01000"
"146.06400","12.17219","0.00951"
"146.26800","12.18917","0.00980"
"146.47200","12.20615","0.01023"
"146.67600","12.22325","0.00965"
"146.88000","12.24011","0.01007"
"147.08400","12.25715","0.00997"
"147.28800","12.27419","0.00985"
"147.49200","12.29117","0.00953"
"147.69600","12.30821","0.01003"
"147.90000","12.32525","0.01012"
"148.10400","12.34212","0.01007"
"148.30800","12.35921","0.01006"
"148.51200","12.37619","0.01027"
"148.71600","12.39311","0.01030"
"148.92000","12.41021","0.01028"
"149.12400","12.42714","0.01035"
"149.32800","12.44417","0.01026"
"149.53200","12.46127","0.01013"
"149.73600","12.47813","0.01036"
"149.94000","12.49523","0.01018"
"150.14400","12.51216","0.01048"
"150.34800","12.52914","0.01061"
"150.55200","12.54624","0.01085"
"150.75600","12.56316","0.01063"
"150.96000","12.58020","0.01061"
"151.16400","12.59724","0.01114"
"151.36800","12.61410","0.01114"
"151.57200","12.63114","0.01081"
"151.77600","12.64824","0.01085"
"151.98000","12.66522","0.01054"
"152.18400","12.68220","0.01114"
"152.38800","12.69918","0.01114"
"152.59200","12.71622","0.01144"
"152.79600","12.73320","0.01117"
"153.00000","12.75018","0.01094"
"153.20400","12.76716","0.01104"
"153.40800","12.78414","0.01166"
"153.61200","12.80118","0.01147"
"153.81600","12.81822","0.01179"
"154.02000","12.83514","0.01143"
"154.22400","12.85218","0.01115"
"154.42800","12.86922","0.01165"
"154.63200","12.88614","0.01180"
"154.83600","12.90324","0.01171"
"155.04000","12.92016","0.01155"
"155.24400","12.93720","0.01177"
"155.44800","12.95418","0.01176"
"155.65200","12.97110","0.01133"
"155.85600","12.98826","0.01181"
"156.06000","13.00518","0.01210"
"156.26400","13.02222","0.01188"
"156.46800","13.03920","0.01196"
"156.67200","13.05618","0.01201"
"156.87600","13.07322","0.01194"
"157.08000","13.09020","0.01232"
"157.28400","13.10718","0.01273"
"157.48800","13.12422","0.01214"
"157.69200","13.14114","0.01212"
"157.89600","13.15818","0.01209"
"158.10000","13.17522","0.01265"
"158.30400","13.19220","0.01260"
"158.50800","13.20918","0.01321"
"158.71200","13.22622","0.01237"
"158.91600","13.24314","0.01235"
"159.12000","13.26018","0.01268"
"159.32400","13.27716","0.01239"
"159.52800","13.29420","0.01282"
"159.73200","13.31124","0.01312"
"159.93600","13.32810","0.01294"
"160.14000","13.34520","0.01285"
"160.34400","13.36218","0.01323"
"160.54800","13.37916","0.01325"
"160.75200","13.39626","0.01289"
"160.95600","13.41318","0.01334"
"161.16000","13.43022","0.01308"
"161.36400","13.44720","0.01366"
"161.56800","13.46412","0.01295"
"161.77200","13.48123","0.01343"
"161.97600","13.49814","0.01332"
"162.18000","13.51519","0.01351"
"162.38400","13.53216","0.01330"
"162.58800","13.54921","0.01375"
"162.79200","13.56618","0.01345"
"162.99600","13.58323","0.01365"
"163.20000","13.60015","0.01387"
"163.40400","13.61719","0.01384"
"163.60800","13.63423","0.01401"
"163.81200","13.65115","0.01366"
"164.01600","13.66819","0.01448"
"164.22000","13.68511","0.01391"
"164.42400","13.70221","0.01434"
"164.62800","13.71919","0.01431"
"164.83200","13.73611","0.01456"
"165.03600","13.75321","0.01503"
"165.24000","13.77019","0.01424"
"165.44400","13.78723","0.01452"
"165.64800","13.80421","0.01455"
"165.85200","13.82113","0.01440"
"166.05600","13.83829","0.01513"
"166.26000","13.85515","0.01488"
"166.46400","13.87219","0.01504"
"166.66800","13.88923","0.01480"
"166.87200","13.90615","0.01559"
"167.07600","13.92319","0.01531"
"167.28000","13.94023","0.01596"
"167.48400","13.95715","0.01557"
"167.68800","13.97419","0.01590"
"167.89200","13.99123","0.01569"
"168.09600","14.00815","0.01568"
"168.30000","14.02519","0.01591"
"168.50400","14.04211","0.01623"
"168.70800","14.05915","0.01625"
"168.91200","14.07619","0.01632"
"169.11600","14.09311","0.01604"
"169.32000","14.11021","0.01576"
"169.52400","14.12719","0.01581"
"169.72800","14.14417","0.01616"
"169.93200","14.16121","0.01630"
"170.13600","14.17813","0.01638"
"170.34000","14.19523","0.01654"
"170.54400","14.21215","0.01734"
"170.74800","14.22913","0.01698"
"170.95200","14.24623","0.01719"
"171.15600","14.26315","0.01677"
"171.36000","14.28025","0.01702"
"171.56400","14.29723","0.01762"
"171.76800","14.31415","0.01756"
"171.97200","14.33119","0.01740"
"172.17600","14.34817","0.01745"
"172.38000","14.36515","0.01751"
"172.58400","14.38219","0.01780"
"172.78800","14.39917","0.01785"
"172.99200","14.41615","0.01834"
"173.19600","14.43325","0.01803"
"173.40000","14.45011","0.01857"
"173.60400","14.46721","0.01836"
"173.80800","14.48425","0.01872"
"174.01200","14.50111","0.01906"
"174.21600","14.51828","0.01907"
"174.42000","14.53513","0.01911"
"174.62400","14.55218","0.01861"
"174.82800","14.56921","0.01943"
"175.03200","14.58614","0.01930"
"175.23600","14.60324","0.01989"
"175.44000","14.62016","0.01917"
"175.64400","14.63720","0.01997"
"175.84800","14.65423","0.01984"
"176.05200","14.67116","0.01988"
"176.25600","14.68820","0.02002"
"176.46000","14.70518","0.01955"
"176.66400","14.72216","0.02010"
"176.86800","14.73914","0.02013"
"177.07200","14.75618","0.02045"
"177.27600","14.77316","0.02072"
"177.48000","14.79020","0.02072"
"177.68400","14.80718","0.02087"
"177.88800","14.82422","0.02092"
"178.09200","14.84126","0.02080"
"178.29600","14.85818","0.02106"
"178.50000","14.87522","0.02109"
"178.70400","14.89220","0.02176"
"178.90800","14.90918","0.02142"
"179.11200","14.92616","0.02191"
"179.31600","14.94314","0.02186"
"179.52000","14.96018","0.02207"
"179.72400","14.97716","0.02276"
"179.92800","14.99414","0.02253"
"180.13200","15.01118","0.02257"
"180.33600","15.02810","0.02252"
"180.54000","15.04520","0.02266"
"180.74400","15.06224","0.02219"
"180.94800","15.07916","0.02345"
"181.15200","15.09620","0.02356"
"181.35600","15.11318","0.02330"
"181.56000","15.13022","0.02429"
"181.76400","15.14720","0.02398"
"181.96800","15.16418","0.02419"
"182.17200","15.18122","0.02483"
"182.37600","15.19820","0.02416"
"182.58000","15.21512","0.02480"
"182.78400","15.23216","0.02499"
"182.98800","15.24920","0.02505"
"183.19200","15.26612","0.02523"
"183.39600","15.28322","0.02552"
"183.60000","15.30014","0.02558"
"183.80400","15.31718","0.02573"
"184.00800","15.33422","0.02580"
"184.21200","15.35120","0.02593"
"184.41600","15.36824","0.02656"
"184.62000","15.38516","0.02664"
"184.82400","15.40220","0.02683"
"185.02800","15.41924","0.02745"
"185.23200","15.43610","0.02636"
"185.43600","15.45320","0.02715"
"185.64000","15.47018","0.02740"
"185.84400","15.48722","0.02734"
"186.04800","15.50420","0.02817"
"186.25200","15.52118","0.02760"
"186.45600","15.53816","0.02822"
"186.66000","15.55515","0.02807"
"186.86400","15.57212","0.02845"
"187.06800","15.58917","0.02859"
"187.27200","15.60620","0.02866"
"187.47600","15.62319","0.02864"
"187.68000","15.64016","0.02902"
"187.88400","15.65714","0.02889"
"188.08800","15.67418","0.02871"
"188.29200","15.69122","0.02899"
"188.49600","15.70815","0.02933"
"188.70000","15.72518","0.02905"
"188.90400","15.74217","0.02908"
"189.10800","15.75921","0.02900"
"189.31200","15.77619","0.02886"
"189.51600","15.79311","0.02941"
"189.72000","15.81027","0.02873"
"189.92400","15.82713","0.02877"
"190.12800","15.84417","0.02789"
"190.33200","15.86121","0.02779"
"190.53600","15.87819","0.02699"
"190.74000","15.89523","0.02740"
"190.94400","15.91221","0.02722"
"191.14800","15.92913","0.02746"
"191.35200","15.94623","0.02748"
"191.55600","15.96321","0.02690"
"191.76000","15.98019","0.02768"
"191.96400","15.99717","0.02804"
"192.16800","16.01415","0.02737"
"192.37200","16.03113","0.02699"
"192.57600","16.04823","0.02693"
"192.78000","16.06515","0.02730"
"192.98400","16.08219","0.02731"
"193.18800","16.09917","0.02712"
"193.39200","16.11615","0.02703"
"193.59600","16.13325","0.02712"
"193.80000","16.15017","0.02739"
"194.00400","16.16721","0.02741"
"194.20800","16.18419","0.02731"
"194.41200","16.20111","0.02737"
"194.61600","16.21821","0.02746"
"194.82000","16.23519","0.02766"
"195.02400","16.25217","0.02822"
"195.22800","16.26921","0.02832"
"195.43200","16.28619","0.02855"
"195.63600","16.30323","0.02858"
"195.84000","16.32021","0.02865"
"196.04400","16.33719","0.02876"
"196.24800","16.35417","0.02903"
"196.45200","16.37115","0.02856"
"196.65600","16.38819","0.02848"
"196.86000","16.40517","0.02904"
"197.06400","16.42221","0.02905"
"197.26800","16.43919","0.02944"
"197.47200","16.45623","0.02973"
"197.67600","16.47315","0.02997"
"197.88000","16.49025","0.02978"
"198.08400","16.50717","0.03041"
"198.28800","16.52421","0.03028"
"198.49200","16.54119","0.03045"
"198.69600","16.55811","0.03055"
"198.90000","16.57521","0.03086"
"199.10400","16.59219","0.03099"
"199.30800","16.60917","0.03173"
"199.51200","16.62621","0.03154"
"199.71600","16.64313","0.03144"
"199.92000","16.66023","0.03167"
"200.12400","16.67721","0.03207"
"200.32800","16.69413","0.03187"
"200.53200","16.71123","0.03191"
"200.73600","16.72816","0.03227"
"200.94000","16.74513","0.03238"
"201.14400","16.76223","0.03214"
"201.34800","16.77921","0.03217"
"201.55200","16.79620","0.03272"
"201.75600","16.81324","0.03289"
"201.96000","16.83016","0.03267"
"202.16400","16.84719","0.03291"
"202.36800","16.86418","0.03354"
"202.57200","16.88116","0.03346"
"202.77600","16.89820","0.03330"
"202.98000","16.91518","0.03466"
"203.18400","16.93221","0.03390"
"203.38800","16.94920","0.03407"
"203.59400","16.96636","0.03479"
"203.79800","16.98339","0.03501"
"204.00200","17.00032","0.03598"
"204.20600","17.01736","0.03499"
"204.41000","17.03440","0.03575"
"204.61600","17.05144","0.03559"
"204.82000","17.06854","0.03642"
"205.02400","17.08546","0.03633"
"205.22800","17.10256","0.03671"
"205.43200","17.11954","0.03671"
"205.63600","17.13652","0.03738"
"205.84000","17.15350","0.03761"
"206.04400","17.17054","0.03737"
"206.24800","17.18746","0.03768"
"206.45200","17.20450","0.03774"
"206.65600","17.22154","0.03868"
"206.86000","17.23852","0.03778"
"207.06400","17.25556","0.03960"
"207.26800","17.27248","0.03854"
"207.47200","17.28952","0.03976"
"207.67600","17.30656","0.03948"
"207.88000","17.32342","0.03968"
"208.08400","17.34052","0.03996"
"208.28800","17.35750","0.04053"
"208.49200","17.37454","0.04052"
"208.69600","17.39152","0.04177"
"208.90000","17.40850","0.04173"
"209.10400","17.42554","0.04322"
"209.30800","17.44246","0.04240"
"209.51200","17.45950","0.04369"
"209.71600","17.47648","0.04360"
"209.92000","17.49352","0.04405"
"210.12400","17.51056","0.04528"
"210.32800","17.52754","0.04477"
"210.53200","17.54452","0.04535"
"210.73600","17.56150","0.04502"
"210.94000","17.57854","0.04631"
"211.14400","17.59546","0.04606"
"211.34800","17.61250","0.04709"
"211.55200","17.62948","0.04731"
"211.75600","17.64652","0.04766"
"211.96000","17.66356","0.04750"
"212.16400","17.68048","0.04777"
"212.36800","17.69752","0.04784"
"212.57200","17.71450","0.04874"
"212.77600","17.73148","0.04875"
"212.98000","17.74858","0.04949"
"213.18400","17.76550","0.04893"
"213.38800","17.78254","0.04958"
"213.59200","17.79952","0.05036"
"213.79600","17.81650","0.05005"
"214.00000","17.83354","0.05043"
"214.20400","17.85046","0.05100"
"214.40800","17.86756","0.05081"
"214.61200","17.88454","0.05080"
"214.81600","17.90153","0.05128"
"215.02000","17.91856","0.05143"
"215.22400","17.93548","0.05210"
"215.42800","17.95247","0.05258"
"215.63200","17.96951","0.05229"
"215.83600","17.98649","0.05326"
"216.04000","18.00352","0.05345"
"216.24400","18.02057","0.05362"
"216.44800","18.03749","0.05410"
"216.65200","18.05459","0.05436"
"216.85600","18.07157","0.05516"
"217.06000","18.08843","0.05574"
"217.26400","18.10559","0.05548"
"217.46800","18.12245","0.05670"
"217.67200","18.13949","0.05739"
"217.87600","18.15653","0.05669"
"218.08000","18.17345","0.05749"
"218.28400","18.19055","0.05835"
"218.48800","18.20747","0.05920"
"218.69200","18.22451","0.05968"
"218.89600","18.24155","0.05999"
"219.10000","18.25853","0.06073"
"219.30400","18.27557","0.06077"
"219.50800","18.29255","0.06156"
"219.71200","18.30953","0.06246"
"219.91600","18.32651","0.06238"
"220.12000","18.34355","0.06381"
"220.32400","18.36053","0.06475"
"220.52800","18.37751","0.06430"
"220.73200","18.39449","0.06565"
"220.93600","18.41153","0.06602"
"221.14000","18.42851","0.06629"
"221.34400","18.44549","0.06721"
"221.54800","18.46253","0.06813"
"221.75200","18.47951","0.06926"
"221.95600","18.49649","0.07006"
"222.16000","18.51353","0.07063"
"222.36400","18.53045","0.07096"
"222.56800","18.54755","0.07189"
"222.77200","18.56447","0.07307"
"222.97600","18.58151","0.07381"
"223.18000","18.59849","0.07416"
"223.38400","18.61547","0.07515"
"223.58800","18.63251","0.07535"
"223.79200","18.64955","0.07602"
"223.99600","18.66647","0.07664"
"224.20000","18.68351","0.07727"
"224.40400","18.70049","0.07742"
"224.60800","18.71753","0.07770"
"224.81200","18.73451","0.07797"
"225.01600","18.75149","0.07839"
"225.22000","18.76853","0.07918"
"225.42400","18.78551","0.07997"
"225.62800","18.80249","0.08051"
"225.83200","18.81953","0.08098"
"226.03600","18.83651","0.08201"
"226.24000","18.85349","0.08207"
"226.44400","18.87053","0.08284"
"226.64800","18.88745","0.08410"
"226.85200","18.90455","0.08513"
"227.05600","18.92153","0.08599"
"227.26000","18.93845","0.08602"
"227.46400","18.95555","0.08814"
"227.66800","18.97248","0.08804"
"227.87200","18.98952","0.08949"
"228.07600","19.00655","0.09034"
"228.28000","19.02347","0.09201"
"228.48400","19.04046","0.09193"
"228.68800","19.05750","0.09339"
"228.89200","19.07448","0.09402"
"229.09600","19.09157","0.09460"
"229.30000","19.10856","0.09567"
"229.50400","19.12554","0.09660"
"229.70800","19.14252","0.09729"
"229.91200","19.15950","0.09830"
"230.11600","19.17653","0.09910"
"230.32000","19.19358","0.09978"
"230.52400","19.21050","0.10117"
"230.72800","19.22748","0.10109"
"230.93200","19.24446","0.10220"
"231.13600","19.26150","0.10264"
"231.34000","19.27854","0.10307"
"231.54400","19.29546","0.10224"
"231.74800","19.31250","0.10130"
"231.95200","19.32948","0.10178"
"232.15600","19.34652","0.10240"
"232.36000","19.36356","0.10335"
"232.56400","19.38048","0.10327"
"232.76800","19.39758","0.10424"
"232.97200","19.41450","0.10447"
"233.17600","19.43148","0.10554"
"233.38000","19.44858","0.10510"
"233.58400","19.46550","0.10580"
"233.78800","19.48254","0.10623"
"233.99200","19.49952","0.10710"
"234.19600","19.51650","0.10774"
"234.40000","19.53354","0.10818"
"234.60400","19.55058","0.10904"
"234.80800","19.56750","0.10900"
"235.01200","19.58448","0.10994"
"235.21600","19.60146","0.11001"
"235.42000","19.61844","0.11099"
"235.62400","19.63554","0.11185"
"235.82800","19.65240","0.11253"
"236.03200","19.66956","0.11283"
"236.23600","19.68648","0.11378"
"236.44000","19.70346","0.11476"
"236.64400","19.72056","0.11590"
"236.84800","19.73748","0.11649"
"237.05200","19.75452","0.11820"
"237.25600","19.77150","0.11875"
"237.46000","19.78848","0.11991"
"237.66400","19.80552","0.12057"
"237.86800","19.82250","0.12094"
"238.07200","19.83954","0.12170"
"238.27600","19.85652","0.12266"
"238.48000","19.87350","0.12263"
"238.68400","19.89054","0.12328"
"238.88800","19.90752","0.12288"
"239.09200","19.92450","0.12317"
"239.29600","19.94148","0.12383"
"239.50000","19.95852","0.12431"
"239.70400","19.97550","0.12473"
"239.90800","19.99254","0.12412"
"240.11200","20.00952","0.12493"
"240.31600","20.02650","0.12495"
"240.52000","20.04354","0.12446"
"240.72400","20.06046","0.12524"
"240.92800","20.07756","0.12603"
"241.13200","20.09449","0.12677"
"241.33600","20.11152","0.12791"
"241.54000","20.12856","0.12872"
"241.74400","20.14542","0.12855"
"241.94800","20.16259","0.12950"
"242.15200","20.17951","0.13041"
"242.35600","20.19649","0.13250"
"242.56000","20.21353","0.13348"
"242.76400","20.23050","0.13411"
"242.96800","20.24755","0.13612"
"243.17200","20.26453","0.13658"
"243.37600","20.28151","0.13768"
"243.58000","20.29848","0.13850"
"243.78400","20.31546","0.14040"
"243.98800","20.33251","0.14161"
"244.19200","20.34955","0.14297"
"244.39600","20.36647","0.14178"
"244.60000","20.38350","0.14322"
"244.80400","20.40055","0.14485"
"245.00800","20.41747","0.14630"
"245.21200","20.43457","0.14794"
"245.41600","20.45149","0.14936"
"245.62000","20.46853","0.15037"
"245.82400","20.48557","0.15143"
"246.02800","20.50249","0.15157"
"246.23200","20.51959","0.15123"
"246.43600","20.53651","0.15187"
"246.64000","20.55349","0.15097"
"246.84400","20.57059","0.15273"
"247.04800","20.58751","0.15323"
"247.25200","20.60455","0.15478"
"247.45600","20.62153","0.15629"
"247.66000","20.63851","0.15749"
"247.86400","20.65555","0.15794"
"248.06800","20.67247","0.15951"
"248.27200","20.68951","0.16092"
"248.47600","20.70655","0.16245"
"248.68000","20.72353","0.16360"
"248.88400","20.74051","0.16568"
"249.08800","20.75749","0.16668"
"249.29200","20.77447","0.16861"
"249.49600","20.79151","0.17052"
"249.70000","20.80849","0.17226"
"249.90400","20.82553","0.17434"
"250.10800","20.84251","0.17547"
"250.31200","20.85949","0.17784"
"250.51600","20.87653","0.17844"
"250.72000","20.89351","0.18068"
"250.92400","20.91043","0.18136"
"251.12800","20.92759","0.18230"
"251.33200","20.94451","0.18390"
"251.53600","20.96149","0.18479"
"251.74000","20.97853","0.18551"
"251.94400","20.99545","0.18622"
"252.14800","21.01249","0.18721"
"252.35200","21.02953","0.18822"
"252.55600","21.04645","0.18938"
"252.76000","21.06355","0.19049"
"252.96400","21.08053","0.19160"
"253.16800","21.09751","0.19315"
"253.37200","21.11455","0.19404"
"253.57600","21.13148","0.19526"
"253.78000","21.14851","0.19694"
"253.98400","21.16556","0.19768"
"254.18800","21.18248","0.19824"
"254.39200","21.19951","0.18938"
"254.59600","21.21650","0.18946"
"254.80000","21.23354","0.19167"
"255.00400","21.25058","0.19310"
"255.20800","21.26744","0.19496"
"255.41200","21.28454","0.19588"
"255.61600","21.30152","0.19839"
"255.82000","21.31850","0.19861"
"256.02400","21.33554","0.19850"
"256.22800","21.35252","0.19938"
"256.43200","21.36955","0.20052"
"256.63600","21.38648","0.20122"
"256.84000","21.40346","0.20015"
"257.04400","21.42056","0.20116"
"257.24800","21.43748","0.20170"
"257.45200","21.45452","0.20334"
"257.65600","21.47156","0.20464"
"257.86000","21.48848","0.20583"
"258.06400","21.50558","0.20744"
"258.26800","21.52250","0.20831"
"258.47200","21.53954","0.20984"
"258.67600","21.55646","0.21126"
"258.88000","21.57350","0.21212"
"259.08400","21.59054","0.21332"
"259.28800","21.60758","0.21478"
"259.49200","21.62444","0.21508"
"259.69600","21.64154","0.21600"
"259.90000","21.65852","0.21646"
"260.10400","21.67550","-0.01876"
"260.30800","21.69254","0.00844"
"260.51200","21.70946","0.00755"
"260.71600","21.72650","0.00525"
"260.92000","21.74354","0.00955"
"261.12400","21.76046","0.00813"
"261.32800","21.77756","0.00806"
"261.53200","21.79454","0.00813"
"261.73600","21.81152","0.00698"
"261.94000","21.82856","0.00914"
"262.14400","21.84548","0.00769"
"262.34800","21.86252","0.00772"
"262.55200","21.87956","0.00927"
"262.75600","21.89654","0.00794"
"262.96000","21.91346","0.00930"
"263.16400","21.93050","0.00755"
"263.36800","21.94748","0.00898"
"263.57200","21.96452","0.00871"
"263.77600","21.98150","0.00801"
"263.98000","21.99848","0.00914"
"264.18400","22.01552","0.00779"
"264.38800","22.03250","0.00918"
"264.59200","22.04954","0.00776"
"264.79600","22.06652","0.00837"
"265.00000","22.08350","0.00865"
"265.20400","22.10048","0.00835"
"265.40800","22.11752","0.00869"
"265.61200","22.13457","0.00821"
"265.81600","22.15149","0.00880"
"266.02000","22.16852","0.00874"
"266.22400","22.18556","0.00899"
"266.42800","22.20243","0.00873"
"266.63200","22.21952","0.00857"
"266.83600","22.23656","0.00916"
"267.04000","22.25348","0.00821"
"267.24400","22.27052","0.00902"
"267.44800","22.28751","0.00886"
"267.65200","22.30449","0.00938"
"267.85600","22.32153","0.00929"
"268.06000","22.33851","0.00883"
"268.26400","22.35554","0.00933"
"268.46800","22.37253","0.00855"
"268.67200","22.38945","0.00895"
"268.87600","22.40654","0.00878"
"269.08000","22.42353","0.00936"
"269.28400","22.44051","0.00916"
"269.48800","22.45755","0.00931"
"269.69200","22.47447","0.00927"
"269.89600","22.49151","0.00944"
"270.10000","22.50855","0.00958"
"270.30400","22.52547","0.00955"
"270.50800","22.54257","0.00930"
"270.71200","22.55949","0.00925"
"270.91600","22.57653","0.00953"
"271.12000","22.59357","0.00975"
"271.32400","22.61049","0.00990"
"271.52800","22.62747","0.00960"
"271.73200","22.64451","0.00966"
"271.93600","22.66155","0.01001"
"272.14000","22.67853","0.00969"
"272.34400","22.69551","0.00948"
"272.54800","22.71249","0.00985"
"272.75200","22.72953","0.00991"
"272.95600","22.74645","0.01038"
"273.16000","22.76355","0.00959"
"273.36400","22.78053","0.01007"
"273.56800","22.79751","0.01019"
"273.77200","22.81449","0.01063"
"273.97600","22.83153","0.01071"
"274.18000","22.84851","0.01076"
"274.38400","22.86555","0.01028"
"274.58800","22.88247","0.01065"
"274.79200","22.89957","0.01011"
"274.99600","22.91649","0.01044"
"275.20000","22.93353","0.01134"
"275.40400","22.95057","0.01087"
"275.60800","22.96749","0.01091"
"275.81200","22.98459","0.01060"
"276.01600","23.00151","0.01111"
"276.22000","23.01843","0.01095"
"276.42400","23.03553","0.01093"
"276.62800","23.05251","0.01079"
"276.83200","23.06949","0.01120"
"277.03600","23.08659","0.01095"
"277.24000","23.10345","0.01169"
"277.44400","23.12055","0.01081"
"277.64800","23.13753","0.01097"
"277.85200","23.15451","0.01137"
"278.05600","23.17149","0.01135"
"278.26000","23.18853","0.01177"
"278.46400","23.20546","0.01117"
"278.66800","23.22256","0.01137"
"278.87200","23.23948","0.01124"
"279.07600","23.25651","0.01170"
"279.28000","23.27349","0.01132"
"279.48400","23.29048","0.01179"
"279.68800","23.30758","0.01210"
"279.89200","23.32449","0.01220"
"280.09600","23.34154","0.01201"
"280.30000","23.35858","0.01202"
"280.50400","23.37550","0.01261"
"280.70800","23.39248","0.01201"
"280.91200","23.40952","0.01247"
"281.11600","23.42650","0.01208"
"281.32000","23.44353","0.01240"
"281.52400","23.46052","0.01258"
"281.72800","23.47750","0.01255"
"281.93200","23.49453","0.01272"
"282.13600","23.51146","0.01250"
"282.34000","23.52850","0.01281"
"282.54400","23.54554","0.01281"
"282.74800","23.56252","0.01287"
"282.95200","23.57956","0.01284"
"283.15600","23.59654","0.01351"
"283.36000","23.61352","0.01319"
"283.56400","23.63056","0.01340"
"283.76800","23.64748","0.01364"
"283.97200","23.66458","0.01328"
"284.17600","23.68150","0.01340"
"284.38000","23.69854","0.01336"
"284.58400","23.71552","0.01350"
"284.78800","23.73244","0.01305"
"284.99200","23.74960","0.01325"
"285.19600","23.76652","0.01275"
"285.40000","23.78350","0.01256"
"285.60400","23.80054","0.01279"
"285.80800","23.81752","0.01279"
"286.01200","23.83456","0.01306"
"286.21600","23.85154","0.01306"
"286.42000","23.86852","0.01281"
"286.62400","23.88550","0.01283"
"286.82800","23.90248","0.01239"
"287.03200","23.91952","0.01295"
"287.23600","23.93656","0.01310"
"287.44000","23.95354","0.01274"
"287.64400","23.97052","0.01320"
"287.84800","23.98750","0.01299"
"288.05200","24.00448","0.01323"
"288.25600","24.02152","0.01292"
"288.46000","24.03850","0.01312"
"288.66400","24.05554","0.01327"
"288.86800","24.07258","0.01265"
"289.07200","24.08944","0.01303"
"289.27600","24.10654","0.01328"
"289.48000","24.12358","0.01278"
"289.68400","24.14050","0.01366"
"289.88800","24.15754","0.01307"
"290.09200","24.17452","0.01357"
"290.29600","24.19150","0.01331"
"290.50000","24.20854","0.01364"
"290.70400","24.22546","0.01411"
"290.90800","24.24256","0.01376"
"291.11200","24.25948","0.01389"
"291.31600","24.27653","0.01390"
"291.52000","24.29350","0.01366"
"291.72400","24.31054","0.01328"
"291.92800","24.32752","0.01385"
"292.13200","24.34450","0.01349"
"292.33600","24.36148","0.01393"
"292.54000","24.37852","0.01431"
"292.74400","24.39557","0.01354"
"292.94800","24.41249","0.01397"
"293.15200","24.42952","0.01375"
"293.35600","24.44645","0.01424"
"293.56000","24.46354","0.01413"
"293.76400","24.48052","0.01413"
"293.96800","24.49745","0.01423"
"294.17200","24.51455","0.01419"
"294.37600","24.53152","0.01427"
"294.58000","24.54851","0.01400"
"294.78400","24.56555","0.01401"
"294.98800","24.58247","0.01432"
"295.19200","24.59957","0.01450"
"295.39600","24.61649","0.01384"
"295.60000","24.63346","0.01465"
"295.80400","24.65051","0.01399"
"296.00800","24.66749","0.01430"
"296.21200","24.68447","0.01433"
"296.41600","24.70156","0.01399"
"296.62000","24.71849","0.01392"
"296.82400","24.73553","0.01429"
"297.02800","24.75251","0.01460"
"297.23200","24.76949","0.01460"
"297.43600","24.78653","0.01457"
"297.64000","24.80345","0.01526"
"297.84400","24.82049","0.01478"
"298.04800","24.83753","0.01471"
"298.25200","24.85445","0.01446"
"298.45600","24.87155","0.01444"
"298.66000","24.88853","0.01445"
"298.86400","24.90551","0.01476"
"299.06800","24.92255","0.01481"
"299.27200","24.93953","0.01489"
"299.47600","24.95657","0.01504"
"299.68000","24.97349","0.01531"
"299.88400","24.99047","0.01494"
"300.08800","25.00757","0.01549"
"300.29200","25.02449","0.01519"
"300.49600","25.04153","0.01551"
"300.70000","25.05851","0.01586"
"300.90400","25.07549","0.01593"
"301.10800","25.09253","0.01579"
"301.31200","25.10957","0.01610"
"301.51600","25.12649","0.01607"
"301.72000","25.14353","0.01610"
"301.92400","25.16045","0.01628"
"302.12800","25.17755","0.01616"
"302.33200","25.19459","0.01660"
"302.53600","25.21145","0.01656"
"302.74000","25.22855","0.01615"
"302.94400","25.24559","0.01661"
"303.14800","25.26245","0.01641"
"303.35200","25.27961","0.01625"
"303.38200","25.28212","0.01617"