File: Force_trajectories/161223/Specimen_RawData_6.csv
End date,"12/23/2016"
Specimen label,"22BG_75"
Maximum Load,"0.92771",N

Time,Extension,Load
(s),(mm),(N)
"0.00000","0.00006","-0.00051"
"0.34200","0.02840","0.00020"
"0.68400","0.05716","0.00054"
"1.02600","0.08580","0.00065"
"1.36800","0.11420","0.00063"
"1.71000","0.14266","0.00122"
"2.05200","0.17130","0.00070"
"2.39400","0.19964","0.00098"
"2.73600","0.22822","0.00107"
"3.07800","0.25674","0.00133"
"3.42000","0.28514","0.00168"
"3.76200","0.31366","0.00169"
"4.10400","0.34224","0.00158"
"4.44600","0.37064","0.00158"
"4.78800","0.39915","0.00178"
"5.13000","0.42767","0.00166"
"5.47200","0.45613","0.00167"
"5.81400","0.48471","0.00182"
"6.15600","0.51317","0.00191"
"6.49800","0.54169","0.00237"
"6.84000","0.57015","0.00258"
"7.18200","0.59861","0.00259"
"7.52400","0.62719","0.00234"
"7.86600","0.65565","0.00255"
"8.20800","0.68417","0.00258"
"8.55000","0.71269","0.00273"
"8.89200","0.74115","0.00254"
"9.23400","0.76967","0.00210"
"9.57600","0.79825","0.00251"
"9.91800","0.82665","0.00231"
"10.26000","0.85517","0.00282"
"10.60200","0.88369","0.00327"
"10.94400","0.91215","0.00292"
"11.28600","0.94067","0.00285"
"11.62800","0.96919","0.00277"
"11.97000","0.99759","0.00323"
"12.31200","1.02617","0.00376"
"12.65400","1.05469","0.00324"
"12.99600","1.08315","0.00313"
"13.33800","1.11161","0.00312"
"13.68000","1.14019","0.00365"
"14.02200","1.16871","0.00335"
"14.36400","1.19723","0.00335"
"14.70600","1.22563","0.00342"
"15.04800","1.25415","0.00340"
"15.39000","1.28272","0.00315"
"15.73200","1.31112","0.00297"
"16.07400","1.33970","0.00333"
"16.41600","1.36822","0.00360"
"16.75800","1.39668","0.00377"
"17.10000","1.42520","0.00358"
"17.44200","1.45366","0.00370"
"17.78400","1.48212","0.00373"
"18.12600","1.51076","0.00414"
"18.46800","1.53910","0.00367"
"18.81000","1.56768","0.00420"
"19.15200","1.59614","0.00383"
"19.49400","1.62466","0.00397"
"19.83600","1.65324","0.00433"
"20.17800","1.68164","0.00409"
"20.52000","1.71016","0.00412"
"20.86200","1.73874","0.00408"
"21.20400","1.76714","0.00460"
"21.54600","1.79572","0.00452"
"21.88800","1.82418","0.00415"
"22.23000","1.85258","0.00418"
"22.57200","1.88122","0.00447"
"22.91400","1.90962","0.00440"
"23.25600","1.93814","0.00472"
"23.59800","1.96672","0.00458"
"23.94000","1.99518","0.00534"
"24.28200","2.02370","0.00501"
"24.62400","2.05222","0.00507"
"24.96600","2.08068","0.00492"
"25.30800","2.10926","0.00520"
"25.65000","2.13772","0.00516"
"25.99200","2.16612","0.00566"
"26.33400","2.19469","0.00555"
"26.67600","2.22315","0.00513"
"27.01800","2.25161","0.00484"
"27.36000","2.28019","0.00511"
"27.70200","2.30865","0.00546"
"28.04400","2.33723","0.00530"
"28.38600","2.36569","0.00538"
"28.72800","2.39415","0.00509"
"29.07000","2.42267","0.00566"
"29.41200","2.45119","0.00488"
"29.75400","2.47971","0.00542"
"30.09600","2.50817","0.00597"
"30.43800","2.53669","0.00575"
"30.78000","2.56515","0.00574"
"31.12200","2.59367","0.00571"
"31.46400","2.62219","0.00606"
"31.80600","2.65065","0.00631"
"32.14800","2.67917","0.00580"
"32.49000","2.70763","0.00607"
"32.83200","2.73621","0.00597"
"33.17400","2.76473","0.00584"
"33.51600","2.79313","0.00586"
"33.85800","2.82165","0.00660"
"34.20000","2.85023","0.00659"
"34.54200","2.87863","0.00599"
"34.88400","2.90721","0.00616"
"35.22600","2.93567","0.00571"
"35.56800","2.96413","0.00665"
"35.91000","2.99271","0.00665"
"36.25200","3.02117","0.00617"
"36.59400","3.04968","0.00627"
"36.93600","3.07820","0.00614"
"37.27800","3.10660","0.00641"
"37.62000","3.13524","0.00644"
"37.96200","3.16370","0.00653"
"38.30400","3.19216","0.00640"
"38.64600","3.22068","0.00665"
"38.98800","3.24914","0.00626"
"39.33000","3.27766","0.00687"
"39.67200","3.30618","0.00676"
"40.01400","3.33464","0.00669"
"40.35600","3.36316","0.00698"
"40.69800","3.39168","0.00656"
"41.04000","3.42014","0.00739"
"41.38200","3.44866","0.00678"
"41.72400","3.47718","0.00692"
"42.06600","3.50564","0.00739"
"42.40800","3.53422","0.00712"
"42.75000","3.56262","0.00749"
"43.09200","3.59120","0.00723"
"43.43400","3.61966","0.00727"
"43.77600","3.64812","0.00747"
"44.11800","3.67670","0.00747"
"44.46000","3.70516","0.00713"
"44.80200","3.73368","0.00784"
"45.14400","3.76220","0.00724"
"45.48600","3.79066","0.00749"
"45.82800","3.81918","0.00797"
"46.17000","3.84764","0.00747"
"46.51200","3.87616","0.00760"
"46.85400","3.90468","0.00733"
"47.19600","3.93319","0.00758"
"47.53800","3.96165","0.00780"
"47.88000","3.99023","0.00797"
"48.22200","4.01869","0.00785"
"48.56400","4.04715","0.00826"
"48.90600","4.07573","0.00795"
"49.24800","4.10419","0.00798"
"49.59000","4.13271","0.00780"
"49.93200","4.16117","0.00765"
"50.27400","4.18969","0.00813"
"50.61600","4.21815","0.00800"
"50.95800","4.24673","0.00814"
"51.30000","4.27513","0.00836"
"51.64200","4.30365","0.00842"
"51.98400","4.33223","0.00802"
"52.32600","4.36063","0.00832"
"52.66800","4.38921","0.00812"
"53.01000","4.41767","0.00834"
"53.35200","4.44619","0.00831"
"53.69400","4.47471","0.00847"
"54.03600","4.50317","0.00803"
"54.37800","4.53163","0.00839"
"54.72000","4.56021","0.00888"
"55.06200","4.58861","0.00868"
"55.40400","4.61719","0.00858"
"55.74600","4.64565","0.00864"
"56.08800","4.67417","0.00862"
"56.43000","4.70269","0.00905"
"56.77200","4.73121","0.00879"
"57.11400","4.75967","0.00901"
"57.45600","4.78819","0.00895"
"57.79800","4.81664","0.00894"
"58.14000","4.84522","0.00828"
"58.48200","4.87368","0.00891"
"58.82400","4.90208","0.00923"
"59.16600","4.93072","0.00959"
"59.50800","4.95918","0.00934"
"59.85000","4.98764","0.00929"
"60.19200","5.01622","0.00914"
"60.53400","5.04468","0.00952"
"60.87600","5.07314","0.00929"
"61.21800","5.10166","0.00970"
"61.56000","5.13012","0.00958"
"61.90200","5.15876","0.00945"
"62.24400","5.18716","0.00981"
"62.58600","5.21562","0.00961"
"62.92800","5.24420","0.01013"
"63.27000","5.27272","0.00954"
"63.61200","5.30118","0.00961"
"63.95400","5.32970","0.00963"
"64.29600","5.35816","0.00942"
"64.63800","5.38668","0.00953"
"64.98000","5.41520","0.00958"
"65.32200","5.44366","0.00962"
"65.66400","5.47218","0.00962"
"66.00600","5.50070","0.01028"
"66.34800","5.52916","0.00985"
"66.69000","5.55768","0.01013"
"67.03200","5.58620","0.01022"
"67.37400","5.61466","0.01047"
"67.71600","5.64318","0.01022"
"68.05800","5.67169","0.01066"
"68.40000","5.70015","0.01102"
"68.74200","5.72873","0.01038"
"69.08400","5.75713","0.01007"
"69.42600","5.78565","0.01066"
"69.76800","5.81417","0.01058"
"70.11000","5.84257","0.01013"
"70.45200","5.87121","0.00990"
"70.79400","5.89973","0.00972"
"71.13600","5.92819","0.01046"
"71.47800","5.95671","0.01027"
"71.82000","5.98517","0.01046"
"72.16200","6.01363","0.01030"
"72.50400","6.04215","0.01058"
"72.84600","6.07061","0.01105"
"73.18800","6.09919","0.01036"
"73.53000","6.12771","0.01039"
"73.87200","6.15617","0.01061"
"74.21400","6.18469","0.01077"
"74.55600","6.21321","0.01086"
"74.89800","6.24161","0.01061"
"75.24000","6.27019","0.01072"
"75.58200","6.29865","0.01060"
"75.92400","6.32717","0.01084"
"76.26600","6.35569","0.01083"
"76.60800","6.38415","0.01093"
"76.95000","6.41273","0.01148"
"77.29200","6.44125","0.01152"
"77.63400","6.46965","0.01068"
"77.97600","6.49823","0.01047"
"78.31800","6.52663","0.01048"
"78.66000","6.55514","0.00969"
"79.00200","6.58372","0.01007"
"79.34400","6.61212","0.01039"
"79.68600","6.64070","0.01072"
"80.02800","6.66916","0.01024"
"80.37000","6.69762","0.01080"
"80.71200","6.72620","0.01085"
"81.05400","6.75472","0.01091"
"81.39600","6.78318","0.01123"
"81.73800","6.81170","0.01141"
"82.08000","6.84016","0.01110"
"82.42200","6.86868","0.01102"
"82.76400","6.89714","0.01107"
"83.10600","6.92566","0.01096"
"83.44800","6.95412","0.01124"
"83.79000","6.98270","0.01163"
"84.13200","7.01116","0.01117"
"84.47400","7.03968","0.01106"
"84.81600","7.06820","0.01150"
"85.15800","7.09666","0.01161"
"85.50000","7.12518","0.01176"
"85.84200","7.15370","0.01126"
"86.18400","7.18216","0.01168"
"86.52600","7.21068","0.01172"
"86.86800","7.23920","0.01163"
"87.21000","7.26766","0.01181"
"87.55200","7.29624","0.01200"
"87.89400","7.32464","0.01131"
"88.23600","7.35316","0.01141"
"88.57800","7.38168","0.01138"
"88.92000","7.41014","0.01144"
"89.26200","7.43871","0.01131"
"89.60400","7.46712","0.01110"
"89.94600","7.49563","0.01155"
"90.28800","7.52421","0.01152"
"90.63000","7.55267","0.01149"
"90.97200","7.58113","0.01133"
"91.31400","7.60971","0.01097"
"91.65600","7.63811","0.01060"
"91.99800","7.66669","0.01054"
"92.34000","7.69521","0.01054"
"92.68200","7.72361","0.01092"
"93.02400","7.75219","0.01079"
"93.36600","7.78065","0.01133"
"93.70800","7.80911","0.01089"
"94.05000","7.83775","0.01157"
"94.39200","7.86609","0.01187"
"94.73400","7.89473","0.01138"
"95.07600","7.92319","0.01171"
"95.41800","7.95159","0.01176"
"95.76000","7.98023","0.01191"
"96.10200","8.00869","0.01212"
"96.44400","8.03715","0.01245"
"96.78600","8.06573","0.01255"
"97.12800","8.09419","0.01232"
"97.47000","8.12265","0.01210"
"97.81200","8.15117","0.01286"
"98.15400","8.17963","0.01298"
"98.49600","8.20821","0.01272"
"98.83800","8.23673","0.01294"
"99.18000","8.26519","0.01303"
"99.52200","8.29365","0.01312"
"99.86400","8.32216","0.01314"
"100.20600","8.35068","0.01252"
"100.54800","8.37920","0.01231"
"100.89000","8.40766","0.01266"
"101.23200","8.43624","0.01281"
"101.57400","8.46464","0.01303"
"101.91600","8.49316","0.01242"
"102.25800","8.52168","0.01284"
"102.60000","8.55020","0.01279"
"102.94200","8.57860","0.01354"
"103.28400","8.60718","0.01349"
"103.62600","8.63570","0.01344"
"103.96800","8.66410","0.01316"
"104.31000","8.69268","0.01301"
"104.65200","8.72114","0.01311"
"104.99400","8.74972","0.01296"
"105.33600","8.77818","0.01407"
"105.67800","8.80670","0.01361"
"106.02000","8.83516","0.01419"
"106.36200","8.86374","0.01354"
"106.70400","8.89214","0.01365"
"107.04600","8.92066","0.01355"
"107.38800","8.94918","0.01360"
"107.73000","8.97764","0.01375"
"108.07200","9.00616","0.01328"
"108.41400","9.03468","0.01395"
"108.75600","9.06314","0.01356"
"109.09800","9.09172","0.01373"
"109.44000","9.12012","0.01417"
"109.78200","9.14870","0.01331"
"110.12400","9.17722","0.01347"
"110.46600","9.20562","0.01380"
"110.80800","9.23425","0.01404"
"111.15000","9.26271","0.01368"
"111.49200","9.29111","0.01331"
"111.83400","9.31969","0.01352"
"112.17600","9.34815","0.01320"
"112.51800","9.37667","0.01319"
"112.86000","9.40519","0.01294"
"113.20200","9.43359","0.01323"
"113.54400","9.46223","0.01266"
"113.88600","9.49069","0.01337"
"114.22800","9.51915","0.01302"
"114.57000","9.54773","0.01316"
"114.91200","9.57613","0.01315"
"115.25400","9.60465","0.01278"
"115.59600","9.63317","0.01308"
"115.93800","9.66169","0.01276"
"116.28000","9.69021","0.01165"
"116.62200","9.71873","0.01187"
"116.96400","9.74713","0.01162"
"117.30600","9.77565","0.01200"
"117.64800","9.80423","0.01237"
"117.99000","9.83263","0.01242"
"118.33200","9.86121","0.01189"
"118.67400","9.88967","0.01188"
"119.01600","9.91813","0.01229"
"119.35800","9.94665","0.01244"
"119.70000","9.97517","0.01232"
"120.04200","10.00369","0.01250"
"120.38400","10.03221","0.01208"
"120.72600","10.06066","0.01238"
"121.06800","10.08918","0.01253"
"121.41000","10.11764","0.01213"
"121.75200","10.14616","0.01190"
"122.09400","10.17468","0.01241"
"122.43600","10.20320","0.01267"
"122.77800","10.23166","0.01262"
"123.12000","10.26018","0.01275"
"123.46200","10.28870","0.01241"
"123.80400","10.31716","0.01240"
"124.14600","10.34574","0.01288"
"124.48800","10.37420","0.01257"
"124.83000","10.40266","0.01250"
"125.17200","10.43118","0.01245"
"125.51400","10.45964","0.01309"
"125.85600","10.48816","0.01335"
"126.19800","10.51668","0.01313"
"126.54000","10.54508","0.01318"
"126.88200","10.57372","0.01326"
"127.22400","10.60218","0.01310"
"127.56600","10.63064","0.01255"
"127.90800","10.65916","0.01281"
"128.25000","10.68762","0.01293"
"128.59200","10.71620","0.01295"
"128.93400","10.74472","0.01360"
"129.27600","10.77318","0.01370"
"129.61800","10.80176","0.01332"
"129.96000","10.83016","0.01322"
"130.30200","10.85868","0.01364"
"130.64400","10.88720","0.01325"
"130.98600","10.91566","0.01360"
"131.32800","10.94418","0.01334"
"131.67000","10.97269","0.01381"
"132.01200","11.00109","0.01352"
"132.35400","11.02973","0.01396"
"132.69600","11.05819","0.01394"
"133.03800","11.08665","0.01379"
"133.38000","11.11523","0.01407"
"133.72200","11.14369","0.01491"
"134.06400","11.17221","0.01460"
"134.40600","11.20067","0.01465"
"134.74800","11.22913","0.01531"
"135.09000","11.25771","0.01448"
"135.43200","11.28617","0.01476"
"135.77400","11.31463","0.01526"
"136.11600","11.34315","0.01559"
"136.45800","11.37167","0.01560"
"136.80000","11.40013","0.01581"
"137.14200","11.42871","0.01568"
"137.48400","11.45717","0.01573"
"137.82600","11.48569","0.01584"
"138.16800","11.51421","0.01613"
"138.51000","11.54267","0.01655"
"138.85200","11.57119","0.01677"
"139.19400","11.59971","0.01694"
"139.53600","11.62817","0.01690"
"139.87800","11.65669","0.01758"
"140.22000","11.68515","0.01782"
"140.56200","11.71361","0.01796"
"140.90400","11.74219","0.01848"
"141.24600","11.77065","0.01869"
"141.58800","11.79917","0.01838"
"141.93000","11.82769","0.01891"
"142.27200","11.85614","0.01926"
"142.61400","11.88461","0.01982"
"142.95600","11.91324","0.02010"
"143.29800","11.94164","0.02061"
"143.64000","11.97016","0.02114"
"143.98200","11.99874","0.02086"
"144.32400","12.02720","0.02109"
"144.66600","12.05572","0.02148"
"145.00800","12.08418","0.02129"
"145.35000","12.11264","0.02227"
"145.69200","12.14122","0.02187"
"146.03400","12.16962","0.02281"
"146.37600","12.19820","0.02292"
"146.71800","12.22672","0.02342"
"147.06000","12.25512","0.02383"
"147.40200","12.28376","0.02386"
"147.74400","12.31216","0.02374"
"148.08600","12.34068","0.02488"
"148.42800","12.36920","0.02519"
"148.77000","12.39772","0.02513"
"149.11200","12.42618","0.02588"
"149.45400","12.45470","0.02602"
"149.79600","12.48316","0.02649"
"150.13800","12.51168","0.02652"
"150.48000","12.54020","0.02762"
"150.82200","12.56860","0.02744"
"151.16400","12.59718","0.02789"
"151.50600","12.62564","0.02879"
"151.84800","12.65416","0.02900"
"152.19000","12.68268","0.02971"
"152.53200","12.71119","0.02985"
"152.87400","12.73972","0.03012"
"153.21600","12.76817","0.03063"
"153.55800","12.79658","0.03051"
"153.90000","12.82521","0.03102"
"154.24200","12.85373","0.03217"
"154.58400","12.88213","0.03202"
"154.92600","12.91071","0.03289"
"155.26800","12.93917","0.03303"
"155.61000","12.96769","0.03367"
"155.95200","12.99621","0.03428"
"156.29400","13.02467","0.03456"
"156.63600","13.05319","0.03595"
"156.97800","13.08165","0.03651"
"157.32000","13.11017","0.03639"
"157.66200","13.13869","0.03703"
"158.00400","13.16721","0.03808"
"158.34600","13.19567","0.03864"
"158.68800","13.22419","0.03988"
"159.03000","13.25271","0.04033"
"159.37200","13.28117","0.04084"
"159.71400","13.30969","0.04167"
"160.05600","13.33815","0.04339"
"160.39800","13.36661","0.04402"
"160.74000","13.39525","0.04473"
"161.08200","13.42365","0.04628"
"161.42400","13.45217","0.04619"
"161.76600","13.48069","0.04648"
"162.10800","13.50915","0.04819"
"162.45000","13.53773","0.04905"
"162.79200","13.56618","0.04926"
"163.13400","13.59465","0.05032"
"163.47600","13.62322","0.05119"
"163.81800","13.65162","0.05152"
"164.16000","13.68015","0.05284"
"164.50200","13.70872","0.05371"
"164.84400","13.73712","0.05441"
"165.18600","13.76570","0.05531"
"165.52800","13.79422","0.05652"
"165.87000","13.82268","0.05749"
"166.21200","13.85126","0.05871"
"166.55400","13.87966","0.05986"
"166.89600","13.90818","0.06116"
"167.23800","13.93670","0.06266"
"167.58000","13.96516","0.06397"
"167.92200","13.99368","0.06545"
"168.26400","14.02220","0.06775"
"168.60600","14.05060","0.06868"
"168.94800","14.07912","0.06981"
"169.29000","14.10770","0.07004"
"169.63200","14.13610","0.07181"
"169.97400","14.16474","0.07368"
"170.31600","14.19320","0.07455"
"170.65800","14.22166","0.07601"
"171.00000","14.25018","0.07704"
"171.34200","14.27864","0.07776"
"171.68400","14.30722","0.07914"
"172.02600","14.33568","0.08013"
"172.36800","14.36420","0.08169"
"172.71000","14.39266","0.08297"
"173.05200","14.42118","0.08500"
"173.39400","14.44964","0.08647"
"173.73600","14.47822","0.08799"
"174.07800","14.50668","0.09045"
"174.42000","14.53513","0.09206"
"174.76200","14.56365","0.09363"
"175.10400","14.59217","0.09533"
"175.44600","14.62069","0.09720"
"175.78800","14.64921","0.09861"
"176.13000","14.67761","0.09968"
"176.47200","14.70619","0.10051"
"176.81400","14.73471","0.10155"
"177.15600","14.76311","0.10216"
"177.49800","14.79169","0.10348"
"177.84000","14.82021","0.10470"
"178.18200","14.84867","0.10510"
"178.52400","14.87719","0.10641"
"178.86600","14.90565","0.10730"
"179.20800","14.93411","0.10852"
"179.55000","14.96275","0.10964"
"179.89200","14.99115","0.11084"
"180.23400","15.01973","0.11213"
"180.57600","15.04825","0.11359"
"180.91800","15.07665","0.11485"
"181.26000","15.10523","0.11598"
"181.60200","15.13363","0.11501"
"181.94400","15.16215","0.10889"
"182.28600","15.19067","0.10952"
"182.62800","15.21913","0.11025"
"182.97000","15.24765","0.11158"
"183.31200","15.27617","0.11360"
"183.65400","15.30463","0.11501"
"183.99600","15.33321","0.11706"
"184.33800","15.36166","0.11794"
"184.68000","15.39018","0.11969"
"185.02200","15.41871","0.12135"
"185.36400","15.44710","0.12312"
"185.70600","15.47562","0.12461"
"186.04800","15.50420","0.12538"
"186.39000","15.53266","0.12652"
"186.73200","15.56118","0.12815"
"187.07400","15.58970","0.12933"
"187.41600","15.61816","0.13051"
"187.75800","15.64668","0.13286"
"188.10000","15.67520","0.13448"
"188.44200","15.70366","0.13719"
"188.78400","15.73218","0.13912"
"189.12600","15.76064","0.14154"
"189.46800","15.78922","0.14445"
"189.81000","15.81774","0.14711"
"190.15200","15.84614","0.15009"
"190.49400","15.87472","0.15214"
"190.83600","15.90318","0.15387"
"191.17800","15.93170","0.15564"
"191.52000","15.96022","0.15750"
"191.86200","15.98868","0.15924"
"192.20400","16.01714","0.16069"
"192.54600","16.04566","0.16309"
"192.88800","16.07418","0.16495"
"193.23000","16.10270","0.16878"
"193.57200","16.13116","0.17161"
"193.91400","16.15962","0.17379"
"194.25600","16.18814","0.17649"
"194.59800","16.21671","0.17870"
"194.94000","16.24512","0.18083"
"195.28200","16.27369","0.18234"
"195.62400","16.30221","0.18402"
"195.96600","16.33061","0.18529"
"196.30800","16.35919","0.18735"
"196.65000","16.38771","0.18932"
"196.99200","16.41617","0.19079"
"197.33400","16.44469","0.19272"
"197.67600","16.47315","0.19461"
"198.01800","16.50167","0.19775"
"198.36000","16.53025","0.19934"
"198.70200","16.55865","0.20168"
"199.04400","16.58723","0.20356"
"199.38600","16.61569","0.20519"
"199.72800","16.64415","0.20727"
"200.07000","16.67273","0.20982"
"200.41200","16.70113","0.21170"
"200.75400","16.72965","0.21358"
"201.09600","16.75823","0.21518"
"201.43800","16.78669","0.21672"
"201.78000","16.81515","0.21777"
"202.12200","16.84373","0.21951"
"202.46400","16.87213","0.22096"
"202.80600","16.90071","0.22261"
"203.14800","16.92917","0.22529"
"203.49000","16.95769","0.22750"
"203.83200","16.98621","0.22969"
"204.17400","17.01467","0.23217"
"204.51600","17.04319","0.23397"
"204.85800","17.07165","0.23593"
"205.20000","17.10011","0.23783"
"205.54200","17.12868","0.24072"
"205.88400","17.15720","0.24356"
"206.22600","17.18566","0.24633"
"206.56800","17.21424","0.24873"
"206.91000","17.24264","0.25201"
"207.25200","17.27116","0.25423"
"207.59400","17.29968","0.25722"
"207.93600","17.32814","0.26014"
"208.27800","17.35672","0.26289"
"208.62000","17.38518","0.26580"
"208.96200","17.41364","0.26986"
"209.30400","17.44222","0.27387"
"209.64600","17.47068","0.27651"
"209.98800","17.49920","0.27894"
"210.33000","17.52766","0.28112"
"210.67200","17.55618","0.28371"
"211.01400","17.58470","0.28527"
"211.35600","17.61316","0.14186"
"211.69800","17.64168","0.04099"
"212.04000","17.67014","0.05252"
"212.38200","17.69866","0.05635"
"212.72400","17.72712","0.04690"
"213.06600","17.75576","0.06011"
"213.40800","17.78422","0.05723"
"213.75000","17.81262","0.06037"
"214.09200","17.84120","0.06642"
"214.43400","17.86966","0.07176"
"214.77600","17.89812","0.07399"
"215.11800","17.92669","0.07222"
"215.46000","17.95516","0.08050"
"215.80200","17.98362","0.07986"
"216.14400","18.01225","0.08242"
"216.48600","18.04066","0.08261"
"216.82800","18.06923","0.09481"
"217.17000","18.09769","0.09574"
"217.51200","18.12609","0.09710"
"217.85400","18.15473","0.09888"
"218.19600","18.18319","0.10272"
"218.53800","18.21171","0.10735"
"218.88000","18.24023","0.10721"
"219.22200","18.26863","0.10927"
"219.56400","18.29715","0.11180"
"219.90600","18.32573","0.11685"
"220.24800","18.35413","0.12366"
"220.59000","18.38271","0.12462"
"220.93200","18.41117","0.12635"
"221.27400","18.43963","0.12884"
"221.61600","18.46821","0.13236"
"221.95800","18.49667","0.14159"
"222.30000","18.52513","0.15156"
"222.64200","18.55371","0.15502"
"222.98400","18.58211","0.15651"
"223.32600","18.61075","0.15883"
"223.66800","18.63921","0.16321"
"224.01000","18.66761","0.16915"
"224.35200","18.69625","0.17622"
"224.69400","18.72465","0.18283"
"225.03600","18.75317","0.18762"
"225.37800","18.78169","0.19330"
"225.72000","18.81015","0.19695"
"226.06200","18.83867","0.20008"
"226.40400","18.86719","0.20361"
"226.74600","18.89565","0.20692"
"227.08800","18.92422","0.21070"
"227.43000","18.95268","0.21463"
"227.77200","18.98120","0.21042"
"228.11400","19.00972","0.21184"
"228.45600","19.03818","0.21244"
"228.79800","19.06664","0.20714"
"229.14000","19.09516","0.20766"
"229.48200","19.12368","0.21103"
"229.82400","19.15220","0.21520"
"230.16600","19.18066","0.21864"
"230.50800","19.20918","0.22148"
"230.85000","19.23764","0.22377"
"231.19200","19.26622","0.22721"
"231.53400","19.29462","0.23158"
"231.87600","19.32314","0.23531"
"232.21800","19.35172","0.23909"
"232.56000","19.38018","0.24352"
"232.90200","19.40870","0.24837"
"233.24400","19.43716","0.25370"
"233.58600","19.46568","0.25802"
"233.92800","19.49420","0.26371"
"234.27000","19.52266","0.27065"
"234.61200","19.55118","0.27614"
"234.95400","19.57970","0.28195"
"235.29600","19.60816","0.28796"
"235.63800","19.63667","0.29576"
"235.98000","19.66514","0.30462"
"236.32200","19.69366","0.31007"
"236.66400","19.72223","0.31404"
"237.00600","19.75070","0.31759"
"237.34800","19.77915","0.32143"
"237.69000","19.80773","0.32540"
"238.03200","19.83619","0.32842"
"238.37400","19.86471","0.33144"
"238.71600","19.89317","0.33505"
"239.05800","19.92163","0.33839"
"239.40000","19.95021","0.34312"
"239.74200","19.97867","0.34920"
"240.08400","20.00713","0.35661"
"240.42600","20.03571","0.36290"
"240.76800","20.06411","0.36995"
"241.11000","20.09269","0.37817"
"241.45200","20.12121","0.38394"
"241.79400","20.14961","0.38625"
"242.13600","20.17825","0.38955"
"242.47800","20.20671","0.39338"
"242.82000","20.23517","0.39938"
"243.16200","20.26375","0.40669"
"243.50400","20.29215","0.41100"
"243.84600","20.32067","0.41520"
"244.18800","20.34919","0.41844"
"244.53000","20.37765","0.42264"
"244.87200","20.40623","0.42730"
"245.21400","20.43475","0.43370"
"245.55600","20.46315","0.43924"
"245.89800","20.49167","0.44451"
"246.24000","20.52019","0.44978"
"246.58200","20.54865","0.45608"
"246.92400","20.57723","0.46216"
"247.26600","20.60568","0.46660"
"247.60800","20.63414","0.47293"
"247.95000","20.66267","0.47983"
"248.29200","20.69118","0.48733"
"248.63400","20.71964","0.49083"
"248.97600","20.74822","0.49675"
"249.31800","20.77662","0.50317"
"249.66000","20.80520","0.51135"
"250.00200","20.83372","0.51853"
"250.34400","20.86212","0.52272"
"250.68600","20.89070","0.49114"
"251.02800","20.91922","0.48403"
"251.37000","20.94768","0.48776"
"251.71200","20.97620","0.49230"
"252.05400","21.00466","0.49688"
"252.39600","21.03318","0.50384"
"252.73800","21.06170","0.50694"
"253.08000","21.09016","0.51242"
"253.42200","21.11868","0.51980"
"253.76400","21.14720","0.52409"
"254.10600","21.17566","0.52783"
"254.44800","21.20418","0.53115"
"254.79000","21.23264","0.53468"
"255.13200","21.26116","0.53883"
"255.47400","21.28974","0.54272"
"255.81600","21.31814","0.54728"
"256.15800","21.34672","0.55260"
"256.50000","21.37523","0.55908"
"256.84200","21.40364","0.56550"
"257.18400","21.43222","0.56985"
"257.52600","21.46067","0.57633"
"257.86800","21.48913","0.58474"
"258.21000","21.51771","0.59002"
"258.55200","21.54618","0.59514"
"258.89400","21.57463","0.60032"
"259.23600","21.60315","0.60688"
"259.57800","21.63161","0.61203"
"259.92000","21.66025","0.61585"
"260.26200","21.68865","0.62011"
"260.60400","21.71717","0.62493"
"260.94600","21.74569","0.63012"
"261.28800","21.77415","0.63429"
"261.63000","21.80267","0.63810"
"261.97200","21.83119","0.64296"
"262.31400","21.85965","0.64741"
"262.65600","21.88817","0.65505"
"262.99800","21.91669","0.66295"
"263.34000","21.94515","0.66875"
"263.68200","21.97367","0.67294"
"264.02400","22.00219","0.68001"
"264.36600","22.03065","0.68787"
"264.70800","22.05923","0.41526"
"265.05000","22.08769","0.42539"
"265.39200","22.11615","0.43497"
"265.73400","22.14467","0.43374"
"266.07600","22.17313","0.44829"
"266.41800","22.20171","0.45376"
"266.76000","22.23017","0.45770"
"267.10200","22.25869","0.46507"
"267.44400","22.28720","0.47183"
"267.78600","22.31566","0.48110"
"268.12800","22.34413","0.49068"
"268.47000","22.37271","0.49258"
"268.81200","22.40122","0.50201"
"269.15400","22.42962","0.50876"
"269.49600","22.45820","0.51900"
"269.83800","22.48660","0.52399"
"270.18000","22.51525","0.52826"
"270.52200","22.54370","0.53255"
"270.86400","22.57216","0.53857"
"271.20600","22.60068","0.54388"
"271.54800","22.62920","0.54927"
"271.89000","22.65760","0.55630"
"272.23200","22.68618","0.56563"
"272.57400","22.71464","0.57016"
"272.91600","22.74316","0.57904"
"273.25800","22.77174","0.58678"
"273.60000","22.80020","0.59520"
"273.94200","22.82872","0.60092"
"274.28400","22.85724","0.60836"
"274.62600","22.88558","0.61522"
"274.96800","22.91422","0.61841"
"275.31000","22.94274","0.62374"
"275.65200","22.97114","0.63005"
"275.99400","22.99972","0.63389"
"276.33600","23.02818","0.63911"
"276.67800","23.05664","0.64415"
"277.02000","23.08522","0.64934"
"277.36200","23.11368","0.65627"
"277.70400","23.14220","0.66576"
"278.04600","23.17066","0.67119"
"278.38800","23.19906","0.67641"
"278.73000","23.22770","0.68525"
"279.07200","23.25616","0.69247"
"279.41400","23.28468","0.69814"
"279.75600","23.31326","0.70248"
"280.09800","23.34166","0.70834"
"280.44000","23.37017","0.71669"
"280.78200","23.39863","0.72081"
"281.12400","23.42715","0.72595"
"281.46600","23.45567","0.72981"
"281.80800","23.48413","0.73334"
"282.15000","23.51265","0.73731"
"282.49200","23.54117","0.74038"
"282.83400","23.56969","0.74483"
"283.17600","23.59815","0.74882"
"283.51800","23.62667","0.75295"
"283.86000","23.65519","0.75871"
"284.20200","23.68365","0.76435"
"284.54400","23.71217","0.77020"
"284.88600","23.74063","0.77575"
"285.22800","23.76921","0.78179"
"285.57000","23.79767","0.79140"
"285.91200","23.82619","0.79800"
"286.25400","23.85465","0.80351"
"286.59600","23.88317","0.80972"
"286.93800","23.91163","0.81812"
"287.28000","23.94020","0.82533"
"287.62200","23.96873","0.83176"
"287.96400","23.99719","0.83648"
"288.30600","24.02571","0.84009"
"288.64800","24.05417","0.84292"
"288.99000","24.08262","0.84569"
"289.33200","24.11121","0.85023"
"289.67400","24.13960","0.85491"
"290.01600","24.16818","0.85923"
"290.35800","24.19670","0.86436"
"290.70000","24.22516","0.87124"
"291.04200","24.25368","0.87540"
"291.38400","24.28214","0.87953"
"291.72600","24.31060","0.87929"
"292.06800","24.33924","0.88497"
"292.41000","24.36758","0.89218"
"292.75200","24.39616","0.89773"
"293.09400","24.42468","0.90152"
"293.43600","24.45314","0.90579"
"293.77800","24.48172","0.91160"
"294.12000","24.51024","0.91725"
"294.46200","24.53864","0.92203"
"294.80400","24.56722","0.92570"
"295.14600","24.59562","0.32497"
"295.48800","24.62420","0.32973"
"295.83000","24.65272","0.32614"
"296.17200","24.68112","0.31513"
"296.51400","24.70976","0.32000"
"296.85600","24.73816","0.32271"
"297.19800","24.76662","0.33162"
"297.54000","24.79514","0.33333"
"297.88200","24.82366","0.33842"
"298.22400","24.85212","0.34988"
"298.56600","24.88076","0.35611"
"298.90800","24.90915","0.36149"
"299.25000","24.93767","0.37131"
"299.59200","24.96614","0.38253"
"299.93400","24.99466","0.38469"
"300.27600","25.02318","0.38991"
"300.61800","25.05169","0.39808"
"300.96000","25.08015","0.40188"
"301.30200","25.10867","0.40957"
"301.64400","25.13713","0.41565"
"301.98600","25.16566","0.41953"
"302.32800","25.19423","0.42711"
"302.67000","25.22269","0.43311"
"303.01200","25.25115","0.44000"
"303.35400","25.27967","0.44480"
"303.69600","25.30813","0.44777"
"304.03800","25.33665","0.45252"
"304.38000","25.36529","0.45586"
"304.72200","25.39363","0.46152"
"305.06400","25.42215","0.46590"
"305.40600","25.45073","0.47227"
"305.74800","25.47919","0.47803"
"306.09000","25.50771","0.48489"
"306.43200","25.53617","0.48985"
"306.77400","25.56457","0.49673"
"307.11600","25.59321","0.50160"
"307.45800","25.62167","0.50567"
"307.80000","25.65019","0.50992"
"308.14200","25.67877","0.51531"
"308.48400","25.70711","0.52037"
"308.82600","25.73569","0.52439"
"309.16800","25.76415","0.52688"
"309.51000","25.79261","0.53004"
"309.85200","25.82119","0.53162"
"310.19400","25.84970","0.53208"
"310.53600","25.87817","0.53376"
"310.87800","25.90668","0.53617"
"311.22000","25.93514","0.54000"
"311.56200","25.96373","0.54412"
"311.90400","25.99219","0.54749"
"312.24600","26.02064","0.24959"
"312.58800","26.04922","0.23419"
"312.93000","26.07768","0.23522"
"313.27200","26.10620","0.23337"
"313.61400","26.13466","0.23586"
"313.95600","26.16318","0.24145"
"314.29800","26.19170","0.23689"
"314.64000","26.22016","0.23941"
"314.98200","26.24862","0.24333"
"315.32400","26.27720","0.24077"
"315.66600","26.30566","0.24787"
"316.00800","26.33412","0.24938"
"316.35000","26.36270","0.24477"
"316.69200","26.39116","0.24960"
"317.03400","26.41968","0.25130"
"317.37600","26.44820","0.25039"
"317.71800","26.47666","0.25408"
"318.06000","26.50524","0.25645"
"318.40200","26.53370","0.25561"
"318.74400","26.56216","0.25862"
"319.08600","26.59068","0.26223"
"319.42800","26.61914","0.26181"
"319.77000","26.64772","0.26219"
"320.11200","26.67618","0.26780"
"320.45400","26.70470","0.26776"
"320.79600","26.73316","0.26752"
"321.13800","26.76162","0.27134"
"321.48000","26.79014","0.27447"
"321.82200","26.81871","0.27508"
"322.16400","26.84724","0.27596"
"322.50600","26.87563","0.27816"
"322.84800","26.90415","0.27920"
"323.19000","26.93273","0.27996"
"323.53200","26.96113","0.28149"
"323.87400","26.98965","0.28356"
"324.21600","27.01817","0.28598"
"324.55800","27.04663","0.28652"
"324.90000","27.07521","0.28756"
"325.24200","27.10367","0.29119"
"325.58400","27.13213","0.29356"
"325.92600","27.16071","0.29502"
"326.26800","27.18911","0.29635"
"326.61000","27.21769","0.29867"
"326.95200","27.24621","0.30192"
"327.29400","27.27467","0.30387"
"327.63600","27.30325","0.30549"
"327.97800","27.33165","0.30614"
"328.32000","27.36011","0.30793"
"328.66200","27.38869","0.01815"
"329.00400","27.41715","0.01708"
"329.34600","27.44567","0.01831"
"329.68800","27.47419","0.02129"
"330.03000","27.50259","0.02192"
"330.37200","27.53117","0.02142"
"330.71400","27.55969","0.02063"
"331.05600","27.58821","0.02155"
"331.39800","27.61672","0.02270"
"331.74000","27.64519","0.02317"
"332.08200","27.67371","0.02336"
"332.42400","27.70216","0.02410"
"332.76600","27.73062","0.02524"
"333.10800","27.75920","0.02499"
"333.45000","27.78772","0.02506"
"333.79200","27.81612","0.02589"
"334.13400","27.84464","0.02661"
"334.47600","27.87316","0.02687"
"334.81800","27.90162","0.02750"
"335.16000","27.93014","0.02775"
"335.50200","27.95866","0.02878"
"335.84400","27.98718","0.02828"
"336.18600","28.01564","0.02748"
"336.52800","28.04416","0.02789"
"336.87000","28.07268","0.02819"
"337.21200","28.10120","0.02930"
"337.55400","28.12966","0.02932"
"337.89600","28.15818","0.03001"
"338.23800","28.18670","0.03100"
"338.58000","28.21516","0.03089"
"338.92200","28.24368","0.02648"
"339.26400","28.27220","0.02667"
"339.60600","28.30072","0.02189"
"339.94800","28.32918","0.02075"
"340.29000","28.35770","0.02130"
"340.63200","28.38610","0.02246"
"340.97400","28.41474","0.02521"
"341.31600","28.44314","0.02523"
"341.65800","28.47166","0.02685"
"342.00000","28.50018","0.02729"
"342.34200","28.52864","0.02803"
"342.68400","28.55722","0.02844"
"343.02600","28.58568","0.02967"
"343.36800","28.61413","0.03037"
"343.71000","28.64271","0.03010"
"344.05200","28.67112","0.03096"
"344.39400","28.69969","0.03136"
"344.73600","28.72821","0.03166"
"345.07800","28.75661","0.03257"
"345.42000","28.78519","0.03236"
"345.76200","28.81365","0.03273"
"346.10400","28.84217","0.03350"
"346.44600","28.87075","0.03269"
"346.78800","28.89915","0.03293"
"347.13000","28.92767","0.03397"
"347.47200","28.95619","0.03457"
"347.81400","28.98465","0.03535"
"348.15600","29.01323","0.03591"
"348.49800","29.04169","0.03678"
"348.84000","29.07015","0.03717"
"349.18200","29.09867","0.03783"
"349.52400","29.12713","0.03914"
"349.86600","29.15565","0.03891"
"350.20800","29.18417","0.03979"
"350.55000","29.21263","0.04043"
"350.89200","29.24121","0.04153"
"351.23400","29.26967","0.04214"
"351.57600","29.29813","0.04308"
"351.91800","29.32671","0.04289"
"352.26000","29.35517","0.04450"
"352.60200","29.38363","0.04457"
"352.94400","29.41221","0.04555"
"353.28600","29.44067","0.04597"
"353.62800","29.46913","0.04703"
"353.97000","29.49771","0.04812"
"354.31200","29.52617","0.04875"
"354.65400","29.55468","0.04933"
"354.99600","29.58315","0.04960"
"355.33800","29.61160","0.04980"
"355.68000","29.64018","0.05053"
"356.02200","29.66870","0.05080"
"356.36400","29.69716","0.05171"
"356.70600","29.72568","0.05259"
"357.04800","29.75420","0.05345"
"357.39000","29.78266","0.05398"
"357.73200","29.81118","0.05502"
"358.07400","29.83970","0.05511"
"358.41600","29.86816","0.05561"
"358.75800","29.89668","0.05634"
"359.10000","29.92514","0.05664"
"359.44200","29.95366","0.05668"
"359.78400","29.98224","0.05789"
"360.12600","30.01064","0.05908"
"360.46800","30.03922","0.06028"
"360.81000","30.06768","0.06297"
"361.15200","30.09614","0.06398"
"361.49400","30.12472","0.06466"
"361.83600","30.15318","0.06609"
"362.17800","30.18164","0.06695"
"362.52000","30.21016","0.06956"
"362.86200","30.23862","0.06997"
"363.20400","30.26720","0.07155"
"363.54600","30.29565","0.07312"
"363.88800","30.32411","0.07404"
"364.23000","30.35270","0.07513"
"364.57200","30.38116","0.07573"
"364.91400","30.40968","0.07626"
"365.25600","30.43826","0.07748"
"365.59800","30.46665","0.06067"
"365.94000","30.49523","0.06424"
"366.28200","30.52369","0.05793"
"366.62400","30.55209","0.05896"
"366.96600","30.58067","0.06133"
"367.30800","30.60913","0.06260"
"367.65000","30.63759","0.06348"
"367.99200","30.66617","0.05912"
"368.33400","30.69469","0.05994"
"368.67600","30.72315","0.06288"
"369.01800","30.75167","0.06438"
"369.36000","30.78013","0.06508"
"369.70200","30.80877","0.06603"
"370.04400","30.83723","0.06810"
"370.38600","30.86563","0.06794"
"370.72800","30.89415","0.06934"
"371.07000","30.92267","0.02525"
"371.41200","30.95119","0.01585"
"371.75400","30.97971","0.03023"
"372.09600","31.00817","0.01737"
"372.43800","31.03669","0.02412"
"372.78000","31.06515","0.02475"
"373.12200","31.09367","0.02115"
"373.46400","31.12218","0.02400"
"373.80600","31.15071","0.02095"
"374.14800","31.17917","0.02220"
"374.49000","31.20774","0.02533"
"374.83200","31.23621","0.02490"
"375.17400","31.26466","0.02402"
"375.51600","31.29318","0.02642"
"375.85800","31.32170","0.02713"
"376.20000","31.35016","0.02774"
"376.54200","31.37868","0.02875"
"376.88400","31.40714","0.03001"
"377.22600","31.43560","0.03078"
"377.56800","31.46424","0.03069"
"377.91000","31.49264","0.03233"
"378.25200","31.52122","0.03215"
"378.59400","31.54968","0.03334"
"378.93600","31.57814","0.03372"
"379.27800","31.60666","0.03409"
"379.62000","31.63518","0.03446"
"379.96200","31.66370","0.03406"
"380.30400","31.69222","0.03443"
"380.64600","31.72062","0.03131"
"380.98800","31.74920","0.03221"
"381.33000","31.77772","0.03230"
"381.67200","31.80612","0.03269"
"382.01400","31.83470","0.03250"
"382.35600","31.86322","0.03280"
"382.69800","31.89168","0.03290"
"383.04000","31.92025","0.03330"
"383.38200","31.94866","0.03417"
"383.72400","31.97712","0.03449"
"384.06600","32.00563","0.03470"
"384.40800","32.03416","0.03546"
"384.75000","32.06274","0.03601"
"385.09200","32.09119","0.03720"
"385.43400","32.11959","0.03766"
"385.77600","32.14817","0.03847"
"386.11800","32.17669","0.03943"
"386.46000","32.20515","0.03941"
"386.80200","32.23373","0.04020"
"387.14400","32.26213","0.04021"
"387.48600","32.29065","0.04084"
"387.82800","32.31917","0.04041"
"388.17000","32.34763","0.04096"
"388.51200","32.37621","0.04208"
"388.85400","32.40467","0.04188"
"389.19600","32.43319","0.04252"
"389.53800","32.46171","0.04280"
"389.88000","32.49017","0.04376"
"390.22200","32.51869","0.04384"
"390.56400","32.54715","0.04475"
"390.90600","32.57567","0.04592"
"391.24800","32.60419","0.04690"
"391.59000","32.63271","0.04730"
"391.93200","32.66117","0.04814"
"392.27400","32.68963","0.04903"
"392.61600","32.71815","0.04969"
"392.95800","32.74667","0.05064"
"393.30000","32.77518","0.05132"
"393.64200","32.80377","0.05219"
"393.98400","32.83216","0.05284"
"394.32600","32.86068","0.05313"
"394.66800","32.88914","0.05355"
"395.01000","32.91766","0.05417"
"395.35200","32.94624","0.05507"
"395.69400","32.97459","0.04567"
"396.03600","33.00316","0.03493"
"396.37800","33.03168","0.03341"
"396.72000","33.06015","0.03298"
"397.06200","33.08872","0.03218"
"397.40400","33.11718","0.01549"
"397.74600","33.14558","0.01075"
"398.08800","33.17422","0.01525"
"398.43000","33.20268","0.01243"
"398.77200","33.23120","0.01456"
"399.11400","33.25966","0.01528"
"399.45600","33.28812","0.01288"
"399.79800","33.31664","0.01630"
"400.14000","33.34516","0.01363"
"400.48200","33.37362","0.01455"
"400.82400","33.40220","0.01493"
"401.16600","33.43066","0.01299"
"401.50800","33.45912","0.01300"
"401.85000","33.48770","0.01297"
"402.19200","33.51610","0.01113"
"402.53400","33.54468","0.01248"
"402.87600","33.57326","0.00710"
"403.21800","33.60160","0.00739"
"403.56000","33.63024","0.00653"
"403.90200","33.65870","0.00808"
"404.24400","33.68716","0.00835"
"404.58600","33.71568","0.00644"
"404.92800","33.74420","0.01023"
"405.27000","33.77266","0.00723"
"405.61200","33.80117","0.00867"
"405.95400","33.82957","0.00894"
"406.29600","33.85815","0.00769"
"406.63800","33.88673","0.00943"
"406.98000","33.91513","0.00921"
"407.32200","33.94371","0.00840"
"407.66400","33.97218","0.00972"
"408.00600","34.00069","0.01019"
"408.34800","34.02921","0.00836"
"408.69000","34.05767","0.01072"
"409.03200","34.08613","0.00975"
"409.37400","34.11465","0.00832"
"409.71600","34.14317","0.01101"
"410.05800","34.17169","0.00966"
"410.40000","34.20015","0.00954"
"410.74200","34.22861","0.01115"
"411.08400","34.25719","0.01014"
"411.42600","34.28577","0.01028"
"411.76800","34.31411","0.01201"
"412.11000","34.34269","0.01097"
"412.45200","34.37121","0.01090"
"412.79400","34.39967","0.01183"
"413.13600","34.42819","0.01158"
"413.47800","34.45665","0.01135"
"413.82000","34.48517","0.01253"
"414.16200","34.51369","0.01259"
"414.50400","34.54215","0.01249"
"414.84600","34.57073","0.01303"
"415.18800","34.59919","0.01322"
"415.53000","34.62765","0.01338"
"415.87200","34.65623","0.01328"
"416.21400","34.68468","0.01302"
"416.55600","34.71315","0.01361"
"416.89800","34.74173","0.01347"
"417.24000","34.77012","0.01419"
"417.58200","34.79865","0.01484"
"417.92400","34.82722","0.01441"
"418.26600","34.85562","0.01478"
"418.60800","34.88420","0.01497"
"418.95000","34.91267","0.01452"
"419.29200","34.94112","0.01522"
"419.63400","34.96964","0.01564"
"419.97600","34.99816","0.01580"
"420.31800","35.02668","0.01641"
"420.66000","35.05520","0.01578"
"421.00200","35.08360","0.01636"
"421.34400","35.11224","0.01714"
"421.68600","35.14070","0.01742"
"422.02800","35.16916","0.01754"
"422.37000","35.19774","0.01762"
"422.71200","35.22620","0.01775"
"423.05400","35.25466","0.01821"
"423.39600","35.28324","0.01843"
"423.73800","35.31170","0.01894"
"424.08000","35.34022","0.01885"
"424.42200","35.36862","0.01807"
"424.76400","35.39714","0.01875"
"425.10600","35.42566","0.01899"
"425.44800","35.45418","0.01923"
"425.79000","35.48270","0.01896"
"426.13200","35.51122","0.01970"
"426.47400","35.53968","0.01974"
"426.81600","35.56814","0.01998"
"427.15800","35.59671","0.02002"
"427.50000","35.62518","0.02062"
"427.84200","35.65364","0.02079"
"428.18400","35.68215","0.01956"
"428.52600","35.71067","0.01998"
"428.86800","35.73914","0.02025"
"429.21000","35.76771","0.02076"
"429.55200","35.79611","0.02144"
"429.89400","35.82470","0.02085"
"430.23600","35.85321","0.02148"
"430.57800","35.88167","0.02143"
"430.92000","35.91019","0.02135"
"431.26200","35.93865","0.02257"
"431.60400","35.96717","0.02243"
"431.94600","35.99569","0.02233"
"432.28800","36.02415","0.02301"
"432.63000","36.05267","0.02332"
"432.97200","36.08119","0.02348"
"433.31400","36.10959","0.02362"
"433.65600","36.13817","0.02446"
"433.99800","36.16663","0.02415"
"434.34000","36.19509","0.02456"
"434.68200","36.22367","0.02516"
"435.02400","36.25219","0.02529"
"435.36600","36.28065","0.02498"
"435.70800","36.30923","0.02575"
"436.05000","36.33762","0.02559"
"436.39200","36.36621","0.02627"
"436.73400","36.39473","0.02625"
"437.07600","36.42313","0.02655"
"437.41800","36.45171","0.02707"
"437.76000","36.48017","0.02753"
"438.10200","36.50868","0.02781"
"438.44400","36.53720","0.02814"
"438.78600","36.56561","0.02877"
"439.12800","36.59418","0.02895"
"439.47000","36.62264","0.02901"
"439.81200","36.65110","0.02931"
"440.15400","36.67974","0.02908"
"440.49600","36.70820","0.02992"
"440.83800","36.73666","0.03023"
"441.18000","36.76524","0.03050"
"441.52200","36.79364","0.03084"
"441.86400","36.82216","0.03078"
"442.20600","36.85062","0.03118"
"442.54800","36.87914","0.03171"
"442.89000","36.90766","0.03202"
"443.23200","36.93618","0.03213"
"443.57400","36.96470","0.03248"
"443.91600","36.99316","0.03256"
"444.25800","37.02168","0.03298"
"444.60000","37.05014","0.03299"
"444.94200","37.07866","0.03324"
"445.28400","37.10723","0.03323"
"445.62600","37.13570","0.03343"
"445.96800","37.16416","0.03420"
"446.31000","37.19268","0.03480"
"446.65200","37.22120","0.03458"
"446.99400","37.24972","0.03531"
"447.33600","37.27811","0.03524"
"447.67800","37.30670","0.03624"
"448.02000","37.33516","0.03626"
"448.36200","37.36367","0.03667"
"448.70400","37.39220","0.03689"
"449.04600","37.42065","0.03718"
"449.38800","37.44912","0.03615"
"449.73000","37.47770","0.03705"
"450.07200","37.50615","0.03756"
"450.41400","37.53467","0.03771"
"450.75600","37.56325","0.03881"
"451.09800","37.59165","0.03931"
"451.44000","37.62017","0.03951"
"451.78200","37.64869","0.03947"
"452.12400","37.67715","0.03940"
"452.46600","37.70567","0.04024"
"452.80800","37.73419","0.03988"
"453.15000","37.76265","0.04104"
"453.49200","37.79123","0.04195"
"453.83400","37.81963","0.04255"
"454.17600","37.84821","0.04308"
"454.51800","37.87679","0.04357"
"454.86000","37.90507","0.04487"
"455.20200","37.93371","0.04448"
"455.54400","37.96217","0.04528"
"455.88600","37.99063","0.04557"
"456.22800","38.01921","0.04607"
"456.57000","38.04767","0.04642"
"456.91200","38.07619","0.04718"
"457.25400","38.10464","0.04738"
"457.59600","38.13311","0.04745"
"457.93800","38.16175","0.04840"
"458.28000","38.19020","0.04836"
"458.62200","38.21861","0.04881"
"458.96400","38.24725","0.04928"
"459.30600","38.27570","0.04902"
"459.64800","38.30416","0.04959"
"459.99000","38.33269","0.05026"
"460.33200","38.36115","0.05066"
"460.67400","38.38972","0.05079"
"461.01600","38.41819","0.05131"
"461.35800","38.44664","0.05204"
"461.70000","38.47516","0.05261"
"462.04200","38.50362","0.05244"
"462.38400","38.53214","0.05345"
"462.72600","38.56066","0.05424"
"463.06800","38.58918","0.05510"
"463.41000","38.61758","0.05493"
"463.75200","38.64622","0.05629"
"464.09400","38.67468","0.05649"
"464.43600","38.70320","0.05750"
"464.77800","38.73166","0.05746"
"465.12000","38.76018","0.05896"
"465.46200","38.78864","0.06021"
"465.80400","38.81716","0.06037"
"466.14600","38.84562","0.06087"
"466.48800","38.87420","0.06161"
"466.83000","38.90272","0.06199"
"467.17200","38.93118","0.06303"
"467.51400","38.95970","0.06401"
"467.85600","38.98816","0.06476"
"468.19800","39.01667","0.06627"
"468.54000","39.04520","0.06702"
"468.88200","39.07366","0.06701"
"469.22400","39.10217","0.06804"
"469.56600","39.13075","0.06854"
"469.90800","39.15910","0.06971"
"470.25000","39.18773","0.06110"
"470.59200","39.21613","0.06458"
"470.93400","39.24465","0.06531"
"471.27600","39.27317","0.06513"
"471.61800","39.30169","0.06587"
"471.96000","39.33015","0.06810"
"472.30200","39.35873","0.06988"
"472.64400","39.38713","0.07021"
"472.98600","39.41565","0.07115"
"473.32800","39.44423","0.07218"
"473.67000","39.47263","0.07218"
"474.01200","39.50127","0.07380"
"474.35400","39.52967","0.07339"
"474.69600","39.55819","0.07432"
"475.03800","39.58671","0.07507"
"475.38000","39.61517","0.07595"
"475.72200","39.64368","0.07540"
"476.06400","39.67215","0.07556"
"476.40600","39.70061","0.07660"
"476.74800","39.72919","0.07692"
"477.09000","39.75771","0.07748"
"477.43200","39.78617","0.07768"
"477.77400","39.81469","0.07844"
"478.11600","39.84314","0.07870"
"478.45800","39.87167","0.07963"
"478.80000","39.90019","0.07992"
"479.14200","39.92865","0.08072"
"479.48400","39.95723","0.08072"
"479.82600","39.98569","0.08150"
"480.16800","40.01414","0.08199"
"480.51000","40.04266","0.08291"
"480.85200","40.07118","0.08372"
"481.19400","40.09970","0.08442"
"481.53600","40.12816","0.08494"
"481.87800","40.15668","0.08538"
"482.22000","40.18514","0.08723"
"482.56200","40.21366","0.08789"
"482.90400","40.24212","0.08815"
"483.24600","40.27070","0.08914"
"483.58800","40.29916","0.09015"
"483.93000","40.32763","0.09097"
"484.27200","40.35620","0.09242"
"484.61400","40.38466","0.09304"
"484.95600","40.41312","0.09394"
"485.29800","40.44164","0.09517"
"485.64000","40.47021","0.09534"
"485.98200","40.49868","0.09618"
"486.32400","40.52719","0.09648"
"486.66600","40.55566","0.09736"
"487.00800","40.58412","0.09841"
"487.35000","40.61270","0.09910"
"487.69200","40.64116","0.09862"
"488.03400","40.66974","0.09877"
"488.37600","40.69820","0.09922"
"488.71800","40.72666","0.09951"
"489.06000","40.75524","0.10007"
"489.40200","40.78370","0.10062"
"489.74400","40.81216","0.10078"
"490.08600","40.84073","0.10134"
"490.42800","40.86908","0.10213"
"490.77000","40.89771","0.10292"
"491.11200","40.92617","0.10271"
"491.45400","40.95457","0.10351"
"491.79600","40.98322","0.10371"
"492.13800","41.01167","0.10484"
"492.48000","41.04019","0.10485"
"492.82200","41.06878","0.10551"
"493.16400","41.09717","0.10602"
"493.50600","41.12569","0.10638"
"493.84800","41.15415","0.10699"
"494.19000","41.18261","0.10733"
"494.53200","41.21125","0.10767"
"494.87400","41.23971","0.10840"
"495.21600","41.26811","0.10900"
"495.55800","41.29669","0.10946"
"495.90000","41.32521","0.10951"
"496.24200","41.35367","0.11023"
"496.58400","41.38219","0.11063"
"496.92600","41.41065","0.11134"
"497.26800","41.43916","0.11131"
"497.61000","41.46769","0.11185"
"497.95200","41.49615","0.11270"
"498.29400","41.52473","0.11348"
"498.63600","41.55319","0.11402"
"498.97800","41.58165","0.11436"
"499.32000","41.61023","0.11439"
"499.66200","41.63869","0.11478"
"500.00400","41.66715","0.11523"
"500.34600","41.69567","0.11572"
"500.68800","41.72419","0.11657"
"501.03000","41.75270","0.11754"
"501.37200","41.78117","0.11790"
"501.71400","41.80963","0.00853"
"502.05600","41.83814","0.00511"
"502.39800","41.86672","0.00480"
"502.74000","41.89512","0.00629"
"503.08200","41.92364","0.00511"
"503.42400","41.95216","0.00492"
"503.76600","41.98068","0.00541"
"504.10800","42.00920","0.00584"
"504.45000","42.03766","0.00489"
"504.79200","42.06618","0.00532"
"505.13400","42.09470","0.00556"
"505.47600","42.12316","0.00521"
"505.81800","42.15168","0.00515"
"506.16000","42.18026","0.00565"
"506.50200","42.20854","0.00597"
"506.84400","42.23724","0.00477"
"507.18600","42.26569","0.00512"
"507.52800","42.29416","0.00536"
"507.87000","42.32274","0.00478"
"507.97200","42.33117","0.00491"