File: Force_trajectories/170107_1/Specimen_RawData_7.csv
End date,"1/7/2017"
Specimen label,"17CT_33"
Maximum Load,"0.18647",N

Time,Extension,Load
(s),(mm),(N)
"0.00000","0.00000","-0.00042"
"0.18600","0.01238","0.00026"
"0.37200","0.03115","-0.00015"
"0.55800","0.04682","0.00014"
"0.74400","0.06224","0.00034"
"0.93000","0.07773","0.00056"
"1.11600","0.09321","0.00068"
"1.30200","0.10876","0.00101"
"1.48800","0.12418","0.00120"
"1.67400","0.13973","0.00081"
"1.86000","0.15521","0.00089"
"2.04600","0.17070","0.00162"
"2.23200","0.18630","0.00155"
"2.41800","0.20173","0.00229"
"2.60400","0.21716","0.00123"
"2.79000","0.23270","0.00161"
"2.97600","0.24825","0.00205"
"3.16200","0.26361","0.00275"
"3.34800","0.27928","0.00246"
"3.53400","0.29476","0.00280"
"3.72000","0.31019","0.00200"
"3.90600","0.32567","0.00232"
"4.09200","0.34128","0.00270"
"4.27800","0.35664","0.00315"
"4.46400","0.37213","0.00330"
"4.65000","0.38768","0.00282"
"4.83600","0.40316","0.00352"
"5.02200","0.41871","0.00366"
"5.20800","0.43419","0.00298"
"5.39400","0.44968","0.00340"
"5.58000","0.46522","0.00404"
"5.76600","0.48071","0.00392"
"5.95200","0.49625","0.00408"
"6.13800","0.51174","0.00430"
"6.32400","0.52722","0.00473"
"6.51000","0.54271","0.00467"
"6.69600","0.55825","0.00471"
"6.88200","0.57368","0.00508"
"7.06800","0.58923","0.00579"
"7.25400","0.60471","0.00477"
"7.44000","0.62014","0.00523"
"7.62600","0.63568","0.00517"
"7.81200","0.65123","0.00545"
"7.99800","0.66665","0.00568"
"8.18400","0.68226","0.00624"
"8.37000","0.69774","0.00600"
"8.55600","0.71323","0.00639"
"8.74200","0.72871","0.00606"
"8.92800","0.74420","0.00693"
"9.11400","0.75969","0.00692"
"9.30000","0.77517","0.00662"
"9.48600","0.79072","0.00691"
"9.67200","0.80620","0.00671"
"9.85800","0.82175","0.00743"
"10.04400","0.83717","0.00755"
"10.23000","0.85266","0.00777"
"10.41600","0.86826","0.00854"
"10.60200","0.88369","0.00806"
"10.78800","0.89923","0.00793"
"10.97400","0.91472","0.00810"
"11.16000","0.93015","0.00817"
"11.34600","0.94569","0.00834"
"11.53200","0.96124","0.00852"
"11.71800","0.97666","0.00825"
"11.90400","0.99227","0.00899"
"12.09000","1.00775","0.00933"
"12.27600","1.02318","0.00935"
"12.46200","1.03872","0.00915"
"12.64800","1.05421","0.00981"
"12.83400","1.06969","0.00955"
"13.02000","1.08524","0.00981"
"13.20600","1.10079","0.00971"
"13.39200","1.11609","0.00978"
"13.57800","1.13176","0.01003"
"13.76400","1.14718","0.01043"
"13.95000","1.16267","0.01025"
"14.13600","1.17827","0.01057"
"14.32200","1.19370","0.01045"
"14.50800","1.20918","0.01104"
"14.69400","1.22473","0.01086"
"14.88000","1.24021","0.01092"
"15.06600","1.25570","0.01131"
"15.25200","1.27119","0.01128"
"15.43800","1.28667","0.01146"
"15.62400","1.30216","0.01135"
"15.81000","1.31770","0.01170"
"15.99600","1.33319","0.01190"
"16.18200","1.34867","0.01212"
"16.36800","1.36422","0.01198"
"16.55400","1.37964","0.01257"
"16.74000","1.39525","0.01262"
"16.92600","1.41079","0.01199"
"17.11200","1.42616","0.01267"
"17.29800","1.44176","0.01275"
"17.48400","1.45719","0.01284"
"17.67000","1.47262","0.01291"
"17.85600","1.48822","0.01328"
"18.04200","1.50377","0.01383"
"18.22800","1.51919","0.01375"
"18.41400","1.53474","0.01329"
"18.60000","1.55022","0.01420"
"18.78600","1.56571","0.01410"
"18.97200","1.58119","0.01436"
"19.15800","1.59674","0.01467"
"19.34400","1.61222","0.01425"
"19.53000","1.62771","0.01480"
"19.71600","1.64320","0.01468"
"19.90200","1.65868","0.01450"
"20.08800","1.67417","0.01537"
"20.27400","1.68965","0.01565"
"20.46000","1.70520","0.01571"
"20.64600","1.72074","0.01586"
"20.83200","1.73617","0.01568"
"21.01800","1.75171","0.01621"
"21.20400","1.76726","0.01628"
"21.39000","1.78262","0.01594"
"21.57600","1.79823","0.01684"
"21.76200","1.81378","0.01658"
"21.94800","1.82914","0.01724"
"22.13400","1.84469","0.01748"
"22.32000","1.86017","0.01745"
"22.50600","1.87566","0.01733"
"22.69200","1.89120","0.01745"
"22.87800","1.90669","0.01780"
"23.06400","1.92217","0.01803"
"23.25000","1.93772","0.01846"
"23.43600","1.95326","0.01827"
"23.62200","1.96875","0.01835"
"23.80800","1.98424","0.01883"
"23.99400","1.99966","0.01850"
"24.18000","2.01521","0.01881"
"24.36600","2.03069","0.01915"
"24.55200","2.04618","0.01908"
"24.73800","2.06172","0.01936"
"24.92400","2.07727","0.01967"
"25.11000","2.09263","0.01999"
"25.29600","2.10818","0.02000"
"25.48200","2.12378","0.02026"
"25.66800","2.13921","0.02064"
"25.85400","2.15475","0.02078"
"26.04000","2.17024","0.02111"
"26.22600","2.18573","0.02114"
"26.41200","2.20121","0.02159"
"26.59800","2.21676","0.02172"
"26.78400","2.23218","0.02178"
"26.97000","2.24773","0.02186"
"27.15600","2.26321","0.02202"
"27.34200","2.27870","0.02222"
"27.52800","2.29424","0.02260"
"27.71400","2.30973","0.02293"
"27.90000","2.32521","0.02266"
"28.08600","2.34076","0.02334"
"28.27200","2.35619","0.02362"
"28.45800","2.37167","0.02353"
"28.64400","2.38722","0.02359"
"28.83000","2.40276","0.02408"
"29.01600","2.41813","0.02412"
"29.20200","2.43379","0.02475"
"29.38800","2.44922","0.02396"
"29.57400","2.46470","0.02479"
"29.76000","2.48019","0.02470"
"29.94600","2.49567","0.02445"
"30.13200","2.51122","0.02462"
"30.31800","2.52671","0.02470"
"30.50400","2.54219","0.02448"
"30.69000","2.55768","0.02478"
"30.87600","2.57322","0.02527"
"31.06200","2.58871","0.02546"
"31.24800","2.60425","0.02531"
"31.43400","2.61974","0.02581"
"31.62000","2.63522","0.02626"
"31.80600","2.65071","0.02588"
"31.99200","2.66619","0.02622"
"32.17800","2.68168","0.02616"
"32.36400","2.69723","0.02636"
"32.55000","2.71265","0.02629"
"32.73600","2.72814","0.02498"
"32.92200","2.74368","0.02387"
"33.10800","2.75923","0.02414"
"33.29400","2.77465","0.02460"
"33.48000","2.79020","0.02411"
"33.66600","2.80574","0.02502"
"33.85200","2.82117","0.02476"
"34.03800","2.83671","0.02532"
"34.22400","2.85226","0.02554"
"34.41000","2.86769","0.02572"
"34.59600","2.88317","0.02598"
"34.78200","2.89872","0.02629"
"34.96800","2.91420","0.02674"
"35.15400","2.92969","0.02709"
"35.34000","2.94517","0.02765"
"35.52600","2.96078","0.02728"
"35.71200","2.97620","0.02752"
"35.89800","2.99169","0.02773"
"36.08400","3.00723","0.02814"
"36.27000","3.02278","0.02834"
"36.45600","3.03820","0.02886"
"36.64200","3.05369","0.02856"
"36.82800","3.06924","0.02889"
"37.01400","3.08460","0.02911"
"37.20000","3.10021","0.02932"
"37.38600","3.11575","0.02948"
"37.57200","3.13118","0.02985"
"37.75800","3.14672","0.02966"
"37.94400","3.16227","0.02835"
"38.13000","3.17769","0.02817"
"38.31600","3.19318","0.02250"
"38.50200","3.20872","0.02265"
"38.68800","3.22421","0.02301"
"38.87400","3.23970","0.02356"
"39.06000","3.25524","0.02276"
"39.24600","3.27067","0.02326"
"39.43200","3.28621","0.02295"
"39.61800","3.30170","0.02322"
"39.80400","3.31718","0.02387"
"39.99000","3.33273","0.02423"
"40.17600","3.34821","0.02450"
"40.36200","3.36370","0.02530"
"40.54800","3.37930","0.02469"
"40.73400","3.39467","0.02532"
"40.92000","3.41022","0.02524"
"41.10600","3.42576","0.02557"
"41.29200","3.44119","0.02633"
"41.47800","3.45673","0.02618"
"41.66400","3.47222","0.02620"
"41.85000","3.48770","0.02652"
"42.03600","3.50325","0.02676"
"42.22200","3.51873","0.02696"
"42.40800","3.53422","0.02702"
"42.59400","3.54970","0.02708"
"42.78000","3.56519","0.02728"
"42.96600","3.58068","0.02752"
"43.15200","3.59628","0.02807"
"43.33800","3.61165","0.02803"
"43.52400","3.62713","0.02784"
"43.71000","3.64280","0.02842"
"43.89600","3.65828","0.02849"
"44.08200","3.67365","0.02831"
"44.26800","3.68925","0.02912"
"44.45400","3.70474","0.02805"
"44.64000","3.72010","0.02845"
"44.82600","3.73577","0.02855"
"45.01200","3.75120","0.02917"
"45.19800","3.76668","0.02925"
"45.38400","3.78229","0.02929"
"45.57000","3.79765","0.02871"
"45.75600","3.81314","0.02946"
"45.94200","3.82874","0.02962"
"46.12800","3.84423","0.03019"
"46.31400","3.85971","0.03107"
"46.50000","3.87526","0.03103"
"46.68600","3.89068","0.03125"
"46.87200","3.90623","0.03145"
"47.05800","3.92177","0.03205"
"47.24400","3.93720","0.03244"
"47.43000","3.95275","0.03230"
"47.61600","3.96823","0.03306"
"47.80200","3.98360","0.03327"
"47.98800","3.99926","0.03278"
"48.17400","4.01475","0.03258"
"48.36000","4.03011","0.03300"
"48.54600","4.04578","0.03364"
"48.73200","4.06126","0.03360"
"48.91800","4.07669","0.03392"
"49.10400","4.09229","0.03407"
"49.29000","4.10772","0.03478"
"49.47600","4.12321","0.03482"
"49.66200","4.13875","0.03494"
"49.84800","4.15424","0.03545"
"50.03400","4.16972","0.03521"
"50.22000","4.18521","0.03661"
"50.40600","4.20069","0.03716"
"50.59200","4.21624","0.03687"
"50.77800","4.23172","0.03746"
"50.96400","4.24715","0.03739"
"51.15000","4.26275","0.03784"
"51.33600","4.27818","0.03793"
"51.52200","4.29367","0.03891"
"51.70800","4.30927","0.03900"
"51.89400","4.32476","0.03975"
"52.08000","4.34012","0.04033"
"52.26600","4.35573","0.04025"
"52.45200","4.37127","0.04074"
"52.63800","4.38664","0.04145"
"52.82400","4.40224","0.04169"
"53.01000","4.41773","0.04196"
"53.19600","4.43315","0.04307"
"53.38200","4.44876","0.04310"
"53.56800","4.46419","0.04362"
"53.75400","4.47973","0.04445"
"53.94000","4.49522","0.04482"
"54.12600","4.51070","0.04498"
"54.31200","4.52619","0.04582"
"54.49800","4.54173","0.04569"
"54.68400","4.55722","0.04643"
"54.87000","4.57270","0.04691"
"55.05600","4.58825","0.04741"
"55.24200","4.60367","0.04811"
"55.42800","4.61916","0.04865"
"55.61400","4.63471","0.04839"
"55.80000","4.65019","0.04938"
"55.98600","4.66568","0.04966"
"56.17200","4.68122","0.05012"
"56.35800","4.69671","0.05043"
"56.54400","4.71225","0.05059"
"56.73000","4.72774","0.05066"
"56.91600","4.74322","0.05068"
"57.10200","4.75877","0.05141"
"57.28800","4.77419","0.05181"
"57.47400","4.78968","0.05224"
"57.66000","4.80522","0.05278"
"57.84600","4.82071","0.05315"
"58.03200","4.83620","0.05337"
"58.21800","4.85174","0.05364"
"58.40400","4.86717","0.05392"
"58.59000","4.88265","0.05455"
"58.77600","4.89826","0.05486"
"58.96200","4.91368","0.05518"
"59.14800","4.92917","0.05553"
"59.33400","4.94477","0.05594"
"59.52000","4.96020","0.05630"
"59.70600","4.97568","0.05671"
"59.89200","4.99123","0.05687"
"60.07800","5.00672","0.05784"
"60.26400","5.02220","0.05773"
"60.45000","5.03769","0.05829"
"60.63600","5.05317","0.05880"
"60.82200","5.06872","0.05856"
"61.00800","5.08420","0.05914"
"61.19400","5.09969","0.05970"
"61.38000","5.11523","0.06010"
"61.56600","5.13072","0.06006"
"61.75200","5.14620","0.06029"
"61.93800","5.16175","0.06072"
"62.12400","5.17724","0.06119"
"62.31000","5.19272","0.06189"
"62.49600","5.20821","0.06181"
"62.68200","5.22369","0.06195"
"62.86800","5.23912","0.06219"
"63.05400","5.25472","0.06240"
"63.24000","5.27027","0.06262"
"63.42600","5.28563","0.06306"
"63.61200","5.30118","0.06304"
"63.79800","5.31672","0.06299"
"63.98400","5.33221","0.06338"
"64.17000","5.34770","0.06359"
"64.35600","5.36324","0.06394"
"64.54200","5.37873","0.06425"
"64.72800","5.39415","0.06437"
"64.91400","5.40970","0.06449"
"65.10000","5.42524","0.06469"
"65.28600","5.44067","0.06516"
"65.47200","5.45615","0.06488"
"65.65800","5.47164","0.06520"
"65.84400","5.48724","0.06608"
"66.03000","5.50267","0.06600"
"66.21600","5.51821","0.06648"
"66.40200","5.53370","0.06694"
"66.58800","5.54919","0.06692"
"66.77400","5.56467","0.06731"
"66.96000","5.58022","0.06726"
"67.14600","5.59564","0.06836"
"67.33200","5.61119","0.06810"
"67.51800","5.62673","0.06897"
"67.70400","5.64222","0.06914"
"67.89000","5.65770","0.06952"
"68.07600","5.67325","0.07038"
"68.26200","5.68867","0.07072"
"68.44800","5.70422","0.07061"
"68.63400","5.71971","0.07130"
"68.82000","5.73519","0.07134"
"69.00600","5.75068","0.07165"
"69.19200","5.76616","0.07229"
"69.37800","5.78171","0.07324"
"69.56400","5.79725","0.07368"
"69.75000","5.81274","0.07393"
"69.93600","5.82816","0.07410"
"70.12200","5.84371","0.07469"
"70.30800","5.85920","0.07453"
"70.49400","5.87468","0.07563"
"70.68000","5.89029","0.07621"
"70.86600","5.90571","0.07701"
"71.05200","5.92120","0.07801"
"71.23800","5.93674","0.07949"
"71.42400","5.95217","0.08020"
"71.61000","5.96765","0.08000"
"71.79600","5.98326","0.08042"
"71.98200","5.99868","0.08123"
"72.16800","6.01423","0.08254"
"72.35400","6.02972","0.08358"
"72.54000","6.04520","0.08448"
"72.72600","6.06069","0.08556"
"72.91200","6.07623","0.08590"
"73.09800","6.09166","0.08748"
"73.28400","6.10720","0.08883"
"73.47000","6.12269","0.09041"
"73.65600","6.13811","0.09201"
"73.84200","6.15372","0.09310"
"74.02800","6.16926","0.09436"
"74.21400","6.18469","0.09577"
"74.40000","6.20029","0.09780"
"74.58600","6.21572","0.09900"
"74.77200","6.23120","0.10090"
"74.95800","6.24675","0.10229"
"75.14400","6.26224","0.10399"
"75.33000","6.27766","0.10359"
"75.51600","6.29321","0.10516"
"75.70200","6.30869","0.10636"
"75.88800","6.32424","0.10780"
"76.07400","6.33972","0.10850"
"76.26000","6.35521","0.10814"
"76.44600","6.37075","0.10987"
"76.63200","6.38624","0.11118"
"76.81800","6.40167","0.11301"
"77.00400","6.41727","0.11240"
"77.19000","6.43276","0.11353"
"77.37600","6.44818","0.11525"
"77.56200","6.46373","0.11731"
"77.74800","6.47921","0.11794"
"77.93400","6.49464","0.11903"
"78.12000","6.51024","0.12127"
"78.30600","6.52573","0.12030"
"78.49200","6.54109","0.10246"
"78.67800","6.55670","0.10447"
"78.86400","6.57225","0.10598"
"79.05000","6.58767","0.10704"
"79.23600","6.60322","0.10916"
"79.42200","6.61876","0.10776"
"79.60800","6.63419","0.10455"
"79.79400","6.64973","0.10509"
"79.98000","6.66522","0.10505"
"80.16600","6.68070","0.10547"
"80.35200","6.69619","0.10573"
"80.53800","6.71167","0.10582"
"80.72400","6.72722","0.10642"
"80.91000","6.74271","0.10761"
"81.09600","6.75813","0.10888"
"81.28200","6.77368","0.10902"
"81.46800","6.78922","0.11140"
"81.65400","6.80465","0.11197"
"81.84000","6.82019","0.11347"
"82.02600","6.83574","0.11421"
"82.21200","6.85116","0.11492"
"82.39800","6.86677","0.11607"
"82.58400","6.88225","0.11719"
"82.77000","6.89768","0.11846"
"82.95600","6.91322","0.11975"
"83.14200","6.92871","0.12096"
"83.32800","6.94414","0.12097"
"83.51400","6.95968","0.12256"
"83.70000","6.97523","0.12396"
"83.88600","6.99065","0.12473"
"84.07200","7.00620","0.12572"
"84.25800","7.02162","0.12598"
"84.44400","7.03723","0.12760"
"84.63000","7.05271","0.12868"
"84.81600","7.06820","0.12887"
"85.00200","7.08374","0.13024"
"85.18800","7.09923","0.13059"
"85.37400","7.11472","0.13202"
"85.56000","7.13020","0.13287"
"85.74600","7.14575","0.13326"
"85.93200","7.16117","0.13377"
"86.11800","7.17672","0.13400"
"86.30400","7.19220","0.13460"
"86.49000","7.20763","0.13472"
"86.67600","7.22323","0.13547"
"86.86200","7.23878","0.13613"
"87.04800","7.25420","0.13691"
"87.23400","7.26975","0.13781"
"87.42000","7.28524","0.13886"
"87.60600","7.30066","0.13991"
"87.79200","7.31627","0.14142"
"87.97800","7.33169","0.14198"
"88.16400","7.34718","0.14365"
"88.35000","7.36278","0.14422"
"88.53600","7.37815","0.14558"
"88.72200","7.39363","0.14711"
"88.90800","7.40924","0.14892"
"89.09400","7.42472","0.15001"
"89.28000","7.44015","0.15107"
"89.46600","7.45575","0.15276"
"89.65200","7.47118","0.15360"
"89.83800","7.48667","0.15495"
"90.02400","7.50221","0.15611"
"90.21000","7.51770","0.15671"
"90.39600","7.53318","0.15805"
"90.58200","7.54873","0.15941"
"90.76800","7.56415","0.16095"
"90.95400","7.57970","0.16122"
"91.14000","7.59524","0.16171"
"91.32600","7.61073","0.16251"
"91.51200","7.62621","0.16375"
"91.69800","7.64170","0.16505"
"91.88400","7.65719","0.16603"
"92.07000","7.67279","0.16670"
"92.25600","7.68828","0.16814"
"92.44200","7.70370","0.16832"
"92.62800","7.71925","0.16907"
"92.81400","7.73473","0.16973"
"93.00000","7.75022","0.17079"
"93.18600","7.76576","0.17135"
"93.37200","7.78119","0.17225"
"93.55800","7.79667","0.17259"
"93.74400","7.81216","0.17288"
"93.93000","7.82771","0.17368"
"94.11600","7.84319","0.17375"
"94.30200","7.85874","0.17465"
"94.48800","7.87422","0.17510"
"94.67400","7.88971","0.17532"
"94.86000","7.90525","0.17645"
"95.04600","7.92068","0.17718"
"95.23200","7.93622","0.17769"
"95.41800","7.95171","0.17857"
"95.60400","7.96713","0.17966"
"95.79000","7.98274","0.17989"
"95.97600","7.99823","0.18165"
"96.16200","8.01365","0.18243"
"96.34800","8.02920","0.18300"
"96.53400","8.04474","0.18423"
"96.72000","8.06017","0.18445"
"96.90600","8.07565","0.18570"
"97.09200","8.09126","0.18569"
"97.27800","8.10668","0.14591"
"97.46400","8.12217","0.13897"
"97.65000","8.13777","0.13787"
"97.83600","8.15320","0.13780"
"98.02200","8.16875","0.13802"
"98.20800","8.18423","0.13900"
"98.39400","8.19966","0.13963"
"98.58000","8.21526","0.14015"
"98.76600","8.23075","0.14076"
"98.95200","8.24617","0.14126"
"99.13800","8.26172","0.14282"
"99.32400","8.27720","0.14317"
"99.51000","8.29269","0.14169"
"99.69600","8.30823","-0.00664"
"99.88200","8.32372","0.00552"
"100.06800","8.33920","-0.00131"
"100.25400","8.35475","-0.00204"
"100.44000","8.37018","-0.00272"
"100.62600","8.38566","-0.00176"
"100.81200","8.40127","-0.00291"
"100.99800","8.41669","-0.00156"
"101.18400","8.43218","-0.00260"
"101.37000","8.44772","-0.00445"
"101.55600","8.46321","-0.00239"
"101.74200","8.47869","-0.00302"
"101.92800","8.49424","-0.00355"
"102.11400","8.50961","-0.00331"
"102.30000","8.52521","-0.00325"
"102.48600","8.54070","-0.00386"
"102.67200","8.55618","-0.00252"
"102.85800","8.57173","-0.00342"
"103.04400","8.58721","-0.00319"
"103.23000","8.60264","-0.00309"
"103.41600","8.61824","-0.00392"
"103.60200","8.63367","-0.00417"
"103.78800","8.64915","-0.00320"
"103.97400","8.66476","-0.00310"
"104.16000","8.68024","-0.00350"
"104.34600","8.69561","-0.00381"
"104.53200","8.71128","-0.00230"
"104.71800","8.72670","-0.00299"
"104.90400","8.74213","-0.00315"
"105.09000","8.75773","-0.00326"
"105.27600","8.77322","-0.00342"
"105.46200","8.78870","-0.00338"
"105.64800","8.80425","-0.00147"
"105.83400","8.81967","-0.00325"
"106.02000","8.83522","-0.00329"
"106.20600","8.85076","-0.00359"
"106.39200","8.86619","-0.00263"
"106.57800","8.88173","-0.00337"
"106.76400","8.89722","-0.00310"
"106.95000","8.91271","-0.00346"
"107.13600","8.92825","-0.00375"
"107.32200","8.94374","-0.00364"
"107.50800","8.95916","-0.00307"
"107.69400","8.97477","-0.00343"
"107.88000","8.99019","-0.00335"
"108.06600","9.00562","-0.00356"
"108.25200","9.02128","-0.00290"
"108.43800","9.03677","-0.00339"
"108.62400","9.05214","-0.00289"
"108.81000","9.06774","-0.00298"
"108.99600","9.08323","-0.00346"
"109.18200","9.09865","-0.00372"
"109.36800","9.11420","-0.00352"
"109.55400","9.12968","-0.00380"
"109.74000","9.14517","-0.00271"
"109.92600","9.16071","-0.00311"
"110.11200","9.17620","-0.00349"
"110.29800","9.19168","-0.00350"
"110.48400","9.20723","-0.00350"
"110.67000","9.22265","-0.00350"
"110.85600","9.23820","-0.00353"
"111.04200","9.25375","-0.00362"
"111.22800","9.26917","-0.00381"
"111.41400","9.28472","-0.00329"
"111.60000","9.30020","-0.00362"
"111.78600","9.31569","-0.00322"
"111.97200","9.33123","-0.00337"
"112.15800","9.34672","-0.00328"
"112.34400","9.36214","-0.00382"
"112.53000","9.37769","-0.00338"
"112.71600","9.39329","-0.00292"
"112.90200","9.40866","-0.00338"
"113.08800","9.42421","-0.00339"
"113.27400","9.43975","-0.00306"
"113.46000","9.45518","-0.00354"
"113.64600","9.47078","-0.00302"
"113.83200","9.48621","-0.00315"
"114.01800","9.50169","-0.00331"
"114.20400","9.51724","-0.00333"
"114.39000","9.53266","-0.00273"
"114.57600","9.54821","-0.00295"
"114.76200","9.56369","-0.00356"
"114.94800","9.57918","-0.00352"
"115.13400","9.59467","-0.00383"
"115.32000","9.61021","-0.00368"
"115.50600","9.62570","-0.00249"
"115.69200","9.64118","-0.00292"
"115.87800","9.65673","-0.00340"
"116.06400","9.67221","-0.00352"
"116.25000","9.68770","-0.00286"
"116.43600","9.70324","-0.00289"
"116.62200","9.71867","-0.00322"
"116.80800","9.73421","-0.00321"
"116.99400","9.74970","-0.00346"
"117.18000","9.76519","-0.00306"
"117.36600","9.78073","-0.00369"
"117.55200","9.79622","-0.00298"
"117.73800","9.81170","-0.00360"
"117.92400","9.82725","-0.00292"
"118.11000","9.84273","-0.00323"
"118.29600","9.85822","-0.00311"
"118.48200","9.87376","-0.00353"
"118.66800","9.88919","-0.00361"
"118.85400","9.90467","-0.00282"
"119.04000","9.92022","-0.00308"
"119.22600","9.93570","-0.00290"
"119.41200","9.95113","-0.00288"
"119.59800","9.96667","-0.00335"
"119.78400","9.98216","-0.00351"
"119.97000","9.99765","-0.00298"
"120.15600","10.01325","-0.00332"
"120.34200","10.02874","-0.00273"
"120.52800","10.04416","-0.00316"
"120.71400","10.05971","-0.00261"
"120.90000","10.07519","-0.00271"
"121.08600","10.09068","-0.00326"
"121.27200","10.10623","-0.00250"
"121.45800","10.12171","-0.00270"
"121.64400","10.13720","-0.00330"
"121.83000","10.15268","-0.00289"
"122.01600","10.16817","-0.00311"
"122.20200","10.18377","-0.00318"
"122.38800","10.19920","-0.00297"
"122.57400","10.21468","-0.00288"
"122.76000","10.23017","-0.00374"
"122.94600","10.24571","-0.00342"
"123.13200","10.26120","-0.00323"
"123.31800","10.27674","-0.00294"
"123.50400","10.29223","-0.00317"
"123.69000","10.30766","-0.00325"
"123.87600","10.32320","-0.00328"
"124.06200","10.33875","-0.00256"
"124.24800","10.35417","-0.00237"
"124.43400","10.36966","-0.00343"
"124.62000","10.38526","-0.00366"
"124.80600","10.40069","-0.00352"
"124.99200","10.41617","-0.00362"
"125.17800","10.43172","-0.00277"
"125.36400","10.44720","-0.00287"
"125.55000","10.46269","-0.00301"
"125.73600","10.47818","-0.00373"
"125.92200","10.49372","-0.00278"
"126.10800","10.50921","-0.00324"
"126.29400","10.52469","-0.00291"
"126.48000","10.54018","-0.00358"
"126.66600","10.55578","-0.00289"
"126.85200","10.57121","-0.00289"
"127.03800","10.58669","-0.00287"
"127.22400","10.60224","-0.00320"
"127.41000","10.61767","-0.00324"
"127.59600","10.63321","-0.00290"
"127.78200","10.64876","-0.00276"
"127.96800","10.66418","-0.00288"
"128.15400","10.67973","-0.00320"
"128.34000","10.69521","-0.00293"
"128.52600","10.71070","-0.00272"
"128.71200","10.72624","-0.00297"
"128.89800","10.74173","-0.00314"
"129.08400","10.75715","-0.00321"
"129.27000","10.77276","-0.00277"
"129.45600","10.78813","-0.00277"
"129.64200","10.80367","-0.00314"
"129.82800","10.81922","-0.00310"
"130.01400","10.83470","-0.00312"
"130.20000","10.85019","-0.00272"
"130.38600","10.86573","-0.00278"
"130.57200","10.88122","-0.00362"
"130.75800","10.89670","-0.00325"
"130.94400","10.91225","-0.00304"
"131.13000","10.92773","-0.00265"
"131.31600","10.94316","-0.00269"
"131.50200","10.95876","-0.00254"
"131.68800","10.97419","-0.00275"
"131.87400","10.98968","-0.00276"
"132.06000","11.00522","-0.00268"
"132.24600","11.02065","-0.00330"
"132.43200","11.03625","-0.00275"
"132.61800","11.05174","-0.00258"
"132.80400","11.06722","-0.00259"
"132.99000","11.08271","-0.00360"
"133.17600","11.09825","-0.00250"
"133.36200","11.11368","-0.00266"
"133.54800","11.12928","-0.00309"
"133.73400","11.14471","-0.00241"
"133.92000","11.16014","-0.00208"
"134.10600","11.17574","-0.00319"
"134.29200","11.19123","-0.00241"
"134.47800","11.20671","-0.00263"
"134.66400","11.22220","-0.00223"
"134.85000","11.23768","-0.00268"
"135.03600","11.25317","-0.00257"
"135.22200","11.26871","-0.00244"
"135.40800","11.28420","-0.00285"
"135.59400","11.29968","-0.00208"
"135.78000","11.31523","-0.00264"
"135.96600","11.33071","-0.00262"
"136.15200","11.34620","-0.00295"
"136.33800","11.36174","-0.00266"
"136.52400","11.37723","-0.00253"
"136.71000","11.39272","-0.00228"
"136.89600","11.40820","-0.00253"
"137.08200","11.42363","-0.00244"
"137.26800","11.43923","-0.00254"
"137.45400","11.45472","-0.00229"
"137.64000","11.47014","-0.00257"
"137.82600","11.48575","-0.00302"
"138.01200","11.50123","-0.00228"
"138.19800","11.51666","-0.00286"
"138.38400","11.53227","-0.00253"
"138.57000","11.54775","-0.00233"
"138.75600","11.56318","-0.00204"
"138.94200","11.57872","-0.00175"
"139.12800","11.59427","-0.00265"
"139.31400","11.60963","-0.00244"
"139.50000","11.62524","-0.00238"
"139.68600","11.64072","-0.00175"
"139.87200","11.65621","-0.00316"
"140.05800","11.67169","-0.00221"
"140.24400","11.68718","-0.00223"
"140.43000","11.70273","-0.00212"
"140.61600","11.71821","-0.00213"
"140.80200","11.73370","-0.00252"
"140.98800","11.74924","-0.00192"
"141.17400","11.76473","-0.00254"
"141.36000","11.78021","-0.00230"
"141.54600","11.79576","-0.00152"
"141.73200","11.81124","-0.00240"
"141.91800","11.82673","-0.00193"
"142.10400","11.84221","-0.00200"
"142.29000","11.85776","-0.00206"
"142.47600","11.87319","-0.00227"
"142.66200","11.88873","-0.00230"
"142.84800","11.90422","-0.00225"
"143.03400","11.91964","-0.00143"
"143.22000","11.93525","-0.00231"
"143.40600","11.95073","-0.00171"
"143.59200","11.96622","-0.00259"
"143.77800","11.98176","-0.00185"
"143.96400","11.99725","-0.00211"
"144.15000","12.01273","-0.00156"
"144.33600","12.02828","-0.00215"
"144.52200","12.04364","-0.00167"
"144.70800","12.05919","-0.00177"
"144.89400","12.07474","-0.00216"
"145.08000","12.09010","-0.00146"
"145.26600","12.10571","-0.00251"
"145.45200","12.12125","-0.00222"
"145.63800","12.13668","-0.00247"
"145.82400","12.15222","-0.00223"
"146.01000","12.16771","-0.00203"
"146.19600","12.18319","-0.00167"
"146.38200","12.19874","-0.00162"
"146.56800","12.21422","-0.00149"
"146.75400","12.22971","-0.00208"
"146.94000","12.24520","-0.00138"
"147.12600","12.26074","-0.00215"
"147.31200","12.27617","-0.00185"
"147.49800","12.29177","-0.00194"
"147.68400","12.30720","-0.00181"
"147.87000","12.32262","-0.00170"
"148.05600","12.33829","-0.00219"
"148.24200","12.35371","-0.00195"
"148.42800","12.36920","-0.00182"
"148.61400","12.38474","-0.00177"
"148.80000","12.40023","-0.00210"
"148.98600","12.41566","-0.00172"
"149.17200","12.43126","-0.00084"
"149.35800","12.44674","-0.00150"
"149.54400","12.46217","-0.00161"
"149.73000","12.47772","-0.00151"
"149.91600","12.49320","-0.00148"
"150.10200","12.50869","-0.00153"
"150.28800","12.52423","-0.00199"
"150.47400","12.53972","-0.00162"
"150.66000","12.55520","-0.00175"
"150.84600","12.57069","-0.00110"
"151.03200","12.58623","-0.00138"
"151.21800","12.60172","-0.00113"
"151.40400","12.61721","-0.00091"
"151.59000","12.63269","-0.00180"
"151.77600","12.64818","-0.00160"
"151.96200","12.66372","-0.00071"
"152.14800","12.67915","-0.00091"
"152.33400","12.69475","-0.00108"
"152.52000","12.71018","-0.00084"
"152.70600","12.72566","-0.00145"
"152.89200","12.74127","-0.00123"
"153.07800","12.75669","-0.00162"
"153.26400","12.77212","-0.00156"
"153.45000","12.78772","-0.00094"
"153.63600","12.80321","-0.00096"
"153.82200","12.81870","-0.00140"
"154.00800","12.83418","-0.00149"
"154.19400","12.84979","-0.00078"
"154.38000","12.86515","-0.00126"
"154.56600","12.88070","-0.00138"
"154.75200","12.89624","-0.00108"
"154.93800","12.91167","-0.00088"
"155.12400","12.92721","-0.00138"
"155.31000","12.94270","-0.00154"
"155.49600","12.95819","-0.00079"
"155.68200","12.97373","-0.00054"
"155.86800","12.98916","-0.00152"
"156.05400","13.00470","-0.00071"
"156.24000","13.02025","-0.00111"
"156.42600","13.03567","-0.00086"
"156.61200","13.05122","-0.00105"
"156.79800","13.06676","-0.00090"
"156.98400","13.08219","-0.00130"
"157.17000","13.09767","-0.00133"
"157.35600","13.11322","-0.00079"
"157.54200","13.12864","-0.00166"
"157.72800","13.14419","-0.00105"
"157.91400","13.15974","-0.00128"
"158.10000","13.17516","-0.00091"
"158.28600","13.19071","-0.00082"
"158.47200","13.20625","-0.00114"
"158.65800","13.22174","-0.00120"
"158.84400","13.23722","-0.00092"
"159.03000","13.25277","-0.00066"
"159.21600","13.26819","-0.00124"
"159.40200","13.28374","-0.00044"
"159.58800","13.29923","-0.00091"
"159.77400","13.31471","-0.00081"
"159.96000","13.33020","-0.00058"
"160.14600","13.34568","-0.00120"
"160.33200","13.36117","-0.00071"
"160.51800","13.37671","-0.00071"
"160.70400","13.39214","-0.00107"
"160.89000","13.40768","-0.00072"
"161.07600","13.42323","-0.00082"
"161.26200","13.43871","-0.00056"
"161.44800","13.45420","-0.00070"
"161.63400","13.46975","-0.00045"
"161.82000","13.48517","-0.00083"
"162.00600","13.50072","-0.00048"
"162.19200","13.51620","-0.00031"
"162.37800","13.53169","-0.00077"
"162.56400","13.54723","-0.00109"
"162.75000","13.56272","-0.00052"
"162.93600","13.57814","-0.00029"
"163.12200","13.59375","-0.00075"
"163.30800","13.60923","-0.00091"
"163.49400","13.62466","-0.00082"
"163.68000","13.64032","-0.00045"
"163.86600","13.65569","-0.00054"
"164.05200","13.67112","-0.00070"
"164.23800","13.68678","-0.00050"
"164.42400","13.70221","-0.00035"
"164.61000","13.71763","-0.00029"
"164.79600","13.73324","0.00007"
"164.98200","13.74872","0.00003"
"165.16800","13.76415","-0.00073"
"165.35400","13.77975","-0.00035"
"165.54000","13.79524","0.00036"
"165.72600","13.81067","0.00000"
"165.91200","13.82621","-0.00033"
"166.09800","13.84170","-0.00023"
"166.28400","13.85718","-0.00114"
"166.47000","13.87273","-0.00024"
"166.65600","13.88821","-0.00050"
"166.84200","13.90370","-0.00005"
"167.02800","13.91924","-0.00029"
"167.21400","13.93467","0.00009"
"167.40000","13.95021","0.00015"
"167.58600","13.96576","0.00003"
"167.77200","13.98112","-0.00006"
"167.95800","13.99673","-0.00022"
"168.14400","14.01221","-0.00042"
"168.33000","14.02764","0.00044"
"168.51600","14.04325","0.00000"
"168.70200","14.05873","0.00002"
"168.88800","14.07416","0.00051"
"169.07400","14.08970","-0.00035"
"169.26000","14.10525","0.00022"
"169.44600","14.12067","0.00015"
"169.63200","14.13622","0.00038"
"169.81800","14.15176","-0.00034"
"170.00400","14.16719","0.00028"
"170.19000","14.18267","0.00036"
"170.37600","14.19816","-0.00010"
"170.56200","14.21371","0.00003"
"170.74800","14.22919","0.00016"
"170.93400","14.24468","-0.00004"
"171.12000","14.26022","0.00021"
"171.30600","14.27577","0.00020"
"171.49200","14.29119","-0.00019"
"171.67800","14.30674","0.00003"
"171.86400","14.32228","0.00027"
"172.05000","14.33765","-0.00010"
"172.23600","14.35326","0.00043"
"172.42200","14.36874","0.00018"
"172.60800","14.38417","0.00003"
"172.79400","14.39971","-0.00017"
"172.98000","14.41526","0.00051"
"173.16600","14.43062","0.00014"
"173.35200","14.44623","0.00019"
"173.53800","14.46171","-0.00007"
"173.72400","14.47720","0.00066"
"173.91000","14.49274","0.00008"
"174.09600","14.50823","0.00005"
"174.28200","14.52372","0.00033"
"174.46800","14.53926","0.00061"
"174.65400","14.55475","0.00026"
"174.84000","14.57023","0.00028"
"175.02600","14.58572","0.00018"
"175.21200","14.60120","0.00012"
"175.39800","14.61669","0.00049"
"175.58400","14.63223","0.00058"
"175.77000","14.64766","0.00058"
"175.95600","14.66320","0.00024"
"176.14200","14.67875","0.00018"
"176.32800","14.69423","0.00004"
"176.51400","14.70966","0.00002"
"176.70000","14.72521","0.00037"
"176.88600","14.74069","0.00044"
"177.07200","14.75618","0.00089"
"177.25800","14.77172","0.00057"
"177.44400","14.78721","0.00048"
"177.63000","14.80269","0.00036"
"177.81600","14.81824","0.00059"
"178.00200","14.83372","0.00038"
"178.18800","14.84927","0.00081"
"178.37400","14.86475","0.00013"
"178.56000","14.88018","0.00098"
"178.74600","14.89573","0.00076"
"178.93200","14.91121","0.00128"
"179.11800","14.92664","0.00022"
"179.30400","14.94230","0.00087"
"179.49000","14.95767","0.00046"
"179.67600","14.97315","0.00043"
"179.86200","14.98870","0.00083"
"180.04800","15.00418","0.00057"
"180.23400","15.01967","0.00086"
"180.42000","15.03521","0.00083"
"180.60600","15.05070","0.00081"
"180.79200","15.06619","0.00091"
"180.97800","15.08167","0.00102"
"181.16400","15.09722","0.00097"
"181.35000","15.11270","0.00107"
"181.53600","15.12819","0.00122"
"181.72200","15.14367","0.00135"
"181.90800","15.15922","0.00118"
"182.09400","15.17476","0.00130"
"182.28000","15.19019","0.00078"
"182.46600","15.20573","0.00102"
"182.65200","15.22122","0.00120"
"182.83800","15.23665","0.00101"
"183.02400","15.25225","0.00113"
"183.21000","15.26774","0.00115"
"183.39600","15.28316","0.00088"
"183.58200","15.29871","0.00128"
"183.76800","15.31419","0.00152"
"183.95400","15.32962","0.00105"
"184.14000","15.34522","0.00127"
"184.32600","15.36077","0.00144"
"184.51200","15.37619","0.00144"
"184.69800","15.39174","0.00095"
"184.88400","15.40722","0.00193"
"185.07000","15.42271","0.00095"
"185.25600","15.43820","0.00157"
"185.44200","15.45374","0.00103"
"185.62800","15.46923","0.00189"
"185.81400","15.48471","0.00160"
"186.00000","15.50020","0.00143"
"186.18600","15.51568","0.00162"
"186.37200","15.53123","0.00142"
"186.55800","15.54665","0.00197"
"186.74400","15.56220","0.00219"
"186.93000","15.57774","0.00173"
"187.11600","15.59323","0.00197"
"187.30200","15.60872","0.00122"
"187.48800","15.62420","0.00172"
"187.67400","15.63968","0.00149"
"187.86000","15.65523","0.00199"
"188.04600","15.67072","0.00187"
"188.23200","15.68620","0.00195"
"188.41800","15.70169","0.00197"
"188.60400","15.71723","0.00172"
"188.79000","15.73272","0.00258"
"188.97600","15.74820","0.00202"
"189.16200","15.76369","0.00138"
"189.34800","15.77917","0.00181"
"189.53400","15.79472","0.00162"
"189.72000","15.81021","0.00193"
"189.90600","15.82569","0.00197"
"190.09200","15.84124","0.00167"
"190.27800","15.85672","0.00192"
"190.46400","15.87221","0.00132"
"190.65000","15.88775","0.00107"
"190.83600","15.90318","0.00209"
"191.02200","15.91866","0.00199"
"191.20800","15.93427","0.00206"
"191.39400","15.94969","0.00197"
"191.58000","15.96524","0.00166"
"191.76600","15.98073","0.00205"
"191.95200","15.99615","0.00230"
"192.13800","16.01170","0.00224"
"192.32400","16.02724","0.00180"
"192.51000","16.04267","0.00248"
"192.69600","16.05821","0.00217"
"192.88200","16.07376","0.00276"
"193.06800","16.08918","0.00250"
"193.25400","16.10473","0.00236"
"193.44000","16.12021","0.00215"
"193.62600","16.13564","0.00252"
"193.81200","16.15125","0.00234"
"193.99800","16.16673","0.00212"
"194.18400","16.18210","0.00237"
"194.37000","16.19776","0.00222"
"194.55600","16.21319","0.00240"
"194.74200","16.22861","0.00300"
"194.92800","16.24422","0.00298"
"195.11400","16.25970","0.00299"
"195.30000","16.27519","0.00284"
"195.48600","16.29073","0.00348"
"195.67200","16.30622","0.00260"
"195.85800","16.32170","0.00349"
"196.04400","16.33719","0.00260"
"196.23000","16.35274","0.00286"
"196.41600","16.36816","0.00326"
"196.60200","16.38371","0.00296"
"196.78800","16.39913","0.00307"
"196.97400","16.41474","0.00315"
"197.16000","16.43022","0.00308"
"197.34600","16.44565","0.00325"
"197.53200","16.46125","0.00323"
"197.71800","16.47674","0.00307"
"197.90400","16.49217","0.00284"
"198.09000","16.50777","0.00291"
"198.27600","16.52320","0.00309"
"198.46200","16.53862","0.00364"
"198.64800","16.55423","0.00392"
"198.83400","16.56971","0.00374"
"199.02000","16.58514","0.00388"
"199.20600","16.60074","0.00364"
"199.39200","16.61623","0.00469"
"199.57800","16.63165","0.00393"
"199.76400","16.64720","0.00365"
"199.95000","16.66274","0.00378"
"200.13600","16.67823","0.00370"
"200.32200","16.69371","0.00421"
"200.50800","16.70920","0.00356"
"200.69400","16.72469","0.00379"
"200.88000","16.74023","0.00415"
"201.06600","16.75566","0.00427"
"201.25200","16.77120","0.00436"
"201.43800","16.78675","0.00395"
"201.62400","16.80217","0.00373"
"201.81000","16.81772","0.00439"
"201.99600","16.83327","0.00407"
"202.18200","16.84869","0.00449"
"202.36800","16.86423","0.00481"
"202.55400","16.87978","0.00437"
"202.74000","16.89521","0.00463"
"202.92600","16.91075","0.00441"
"203.11200","16.92618","0.00425"
"203.29800","16.94166","0.00443"
"203.48400","16.95721","0.00437"
"203.67000","16.97269","0.00409"
"203.85600","16.98818","0.00491"
"204.04200","17.00373","0.00481"
"204.22800","17.01921","0.00468"
"204.41400","17.03469","0.00494"
"204.60000","17.05024","0.00511"
"204.78600","17.06567","0.00477"
"204.97200","17.08121","0.00405"
"205.15800","17.09670","0.00487"
"205.34400","17.11218","0.00485"
"205.53000","17.12767","0.00511"
"205.71600","17.14321","0.00477"
"205.90200","17.15870","0.00489"
"206.08800","17.17418","0.00533"
"206.27400","17.18973","0.00471"
"206.46000","17.20522","0.00542"
"206.64600","17.22070","0.00547"
"206.83200","17.23625","0.00522"
"207.01800","17.25167","0.00501"
"207.20400","17.26722","0.00554"
"207.39000","17.28270","0.00544"
"207.57600","17.29819","0.00466"
"207.76200","17.31373","0.00555"
"207.94800","17.32922","0.00559"
"208.13400","17.34470","0.00539"
"208.32000","17.36025","0.00523"
"208.50600","17.37574","0.00516"
"208.69200","17.39116","0.00510"
"208.87800","17.40676","0.00527"
"209.06400","17.42219","0.00568"
"209.25000","17.43768","0.00521"
"209.43600","17.45328","0.00557"
"209.62200","17.46871","0.00610"
"209.80800","17.48413","0.00577"
"209.99400","17.49974","0.00595"
"210.18000","17.51522","0.00599"
"210.36600","17.53065","0.00631"
"210.55200","17.54620","0.00655"
"210.73800","17.56174","0.00545"
"210.92400","17.57717","0.00577"
"211.11000","17.59265","0.00583"
"211.29600","17.60820","0.00580"
"211.48200","17.62368","0.00609"
"211.66800","17.63917","0.00590"
"211.85400","17.65471","0.00638"
"212.04000","17.67020","0.00617"
"212.22600","17.68574","0.00602"
"212.41200","17.70117","0.00620"
"212.59800","17.71671","0.00636"
"212.78400","17.73226","0.00596"
"212.97000","17.74768","0.00650"
"213.15600","17.76323","0.00612"
"213.34200","17.77872","0.00613"
"213.52800","17.79414","0.00697"
"213.71400","17.80969","0.00684"
"213.90000","17.82523","0.00655"
"214.08600","17.84072","0.00639"
"214.27200","17.85620","0.00698"
"214.45800","17.87175","0.00677"
"214.64400","17.88717","0.00665"
"214.83000","17.90272","0.00647"
"215.01600","17.91826","0.00670"
"215.20200","17.93369","0.00686"
"215.38800","17.94918","0.00695"
"215.57400","17.96466","0.00686"
"215.76000","17.98015","0.00734"
"215.94600","17.99569","0.00682"
"216.13200","18.01124","0.00699"
"216.31800","18.02672","0.00727"
"216.50400","18.04221","0.00673"
"216.69000","18.05770","0.00725"
"216.87600","18.07324","0.00724"
"217.06200","18.08879","0.00772"
"217.24800","18.10421","0.00796"
"217.43400","18.11970","0.00723"
"217.62000","18.13524","0.00778"
"217.80600","18.15067","0.00758"
"217.99200","18.16615","0.00718"
"218.17800","18.18176","0.00720"
"218.36400","18.19712","0.00805"
"218.55000","18.21273","0.00747"
"218.73600","18.22821","0.00805"
"218.92200","18.24370","0.00755"
"219.10800","18.25918","0.00776"
"219.29400","18.27467","0.00778"
"219.48000","18.29016","0.00753"
"219.66600","18.30570","0.00813"
"219.85200","18.32119","0.00825"
"220.03800","18.33667","0.00764"
"220.22400","18.35222","0.00823"
"220.41000","18.36770","0.00834"
"220.59600","18.38319","0.00806"
"220.78200","18.39879","0.00875"
"220.96800","18.41422","0.00865"
"221.15400","18.42971","0.00836"
"221.34000","18.44525","0.00818"
"221.52600","18.46068","0.00848"
"221.71200","18.47616","0.00845"
"221.89800","18.49171","0.00856"
"222.08400","18.50719","0.00866"
"222.27000","18.52268","0.00854"
"222.45600","18.53822","0.00870"
"222.64200","18.55371","0.00850"
"222.82800","18.56925","0.00909"
"223.01400","18.58474","0.00891"
"223.20000","18.60017","0.00853"
"223.38600","18.61571","0.00877"
"223.57200","18.63126","0.00885"
"223.75800","18.64668","0.00890"
"223.94400","18.66223","0.00891"
"224.13000","18.67771","0.00873"
"224.31600","18.69314","0.00879"
"224.50200","18.70874","0.00911"
"224.68800","18.72423","0.00858"
"224.87400","18.73959","0.00910"
"225.06000","18.75526","0.00898"
"225.24600","18.77074","0.00955"
"225.43200","18.78611","0.00934"
"225.61800","18.80172","0.00931"
"225.80400","18.81726","0.00903"
"225.99000","18.83269","0.00942"
"226.17600","18.84823","0.00955"
"226.36200","18.86366","0.00969"
"226.54800","18.87920","0.00929"
"226.73400","18.89469","0.00981"
"226.92000","18.91017","0.00979"
"227.10600","18.92572","0.00979"
"227.29200","18.94127","0.00932"
"227.47800","18.95669","0.00940"
"227.66400","18.97218","0.00984"
"227.85000","18.98772","0.00969"
"228.03600","19.00321","0.00960"
"228.22200","19.01875","0.00964"
"228.40800","19.03424","0.00987"
"228.59400","19.04960","0.00927"
"228.78000","19.06521","0.00927"
"228.96600","19.08075","0.00954"
"229.15200","19.09618","0.01002"
"229.33800","19.11172","0.00997"
"229.52400","19.12727","0.00986"
"229.71000","19.14269","0.01046"
"229.89600","19.15818","0.01029"
"230.08200","19.17373","0.00992"
"230.26800","19.18921","0.01015"
"230.45400","19.20470","0.01036"
"230.64000","19.22018","0.01046"
"230.82600","19.23567","0.01025"
"231.01200","19.25121","0.01085"
"231.19800","19.26670","0.01025"
"231.38400","19.28218","0.01041"
"231.57000","19.29773","0.01055"
"231.75600","19.31315","0.01089"
"231.94200","19.32870","0.01068"
"232.12800","19.34431","0.01049"
"232.31400","19.35967","0.01075"
"232.50000","19.37522","0.01058"
"232.68600","19.39070","0.01060"
"232.87200","19.40619","0.01108"
"233.05800","19.42173","0.01147"
"233.24400","19.43728","0.01090"
"233.43000","19.45264","0.01121"
"233.61600","19.46825","0.01127"
"233.80200","19.48374","0.01141"
"233.98800","19.49916","0.01183"
"234.17400","19.51476","0.01160"
"234.36000","19.53019","0.01117"
"234.54600","19.54573","0.01169"
"234.73200","19.56122","0.01157"
"234.91800","19.57671","0.01171"
"235.10400","19.59219","0.01190"
"235.29000","19.60768","0.01130"
"235.47600","19.62322","0.01197"
"235.66200","19.63871","0.01189"
"235.84800","19.65425","0.01228"
"236.03400","19.66968","0.01212"
"236.22000","19.68516","0.01192"
"236.40600","19.70077","0.01217"
"236.59200","19.71619","0.01185"
"236.77800","19.73168","0.01243"
"236.96400","19.74722","0.01211"
"237.15000","19.76265","0.01250"
"237.33600","19.77820","0.01225"
"237.52200","19.79368","0.01248"
"237.70800","19.80917","0.01267"
"237.89400","19.82466","0.01247"
"238.08000","19.84020","0.01246"
"238.26600","19.85569","0.01281"
"238.45200","19.87123","0.01252"
"238.63800","19.88672","0.01264"
"238.82400","19.90220","0.01340"
"239.01000","19.91775","0.01304"
"239.19600","19.93323","0.01305"
"239.38200","19.94866","0.01332"
"239.56800","19.96426","0.01346"
"239.75400","19.97969","0.01312"
"239.94000","19.99512","0.01300"
"240.12600","20.01072","0.01346"
"240.31200","20.02626","0.01331"
"240.49800","20.04169","0.01345"
"240.68400","20.05724","0.01350"
"240.87000","20.07272","0.01382"
"241.05600","20.08821","0.01364"
"241.24200","20.10369","0.01370"
"241.42800","20.11918","0.01368"
"241.61400","20.13466","0.01411"
"241.80000","20.15021","0.01378"
"241.98600","20.16570","0.01435"
"242.17200","20.18124","0.01429"
"242.35800","20.19678","0.01372"
"242.54400","20.21215","0.01372"
"242.73000","20.22776","0.01417"
"242.91600","20.24324","0.01425"
"243.10200","20.25867","0.01407"
"243.28800","20.27421","0.01467"
"243.47400","20.28976","0.01471"
"243.66000","20.30512","0.01460"
"243.84600","20.32067","0.01491"
"244.03200","20.33627","0.01488"
"244.21800","20.35164","0.01471"
"244.40400","20.36724","0.01466"
"244.59000","20.38273","0.01503"
"244.77600","20.39816","0.01527"
"244.96200","20.41370","0.01572"
"245.14800","20.42925","0.01528"
"245.33400","20.44467","0.01534"
"245.52000","20.46016","0.01568"
"245.70600","20.47570","0.01591"
"245.89200","20.49125","0.01512"
"246.07800","20.50667","0.01583"
"246.26400","20.52222","0.01580"
"246.45000","20.53770","0.01561"
"246.63600","20.55319","0.01564"
"246.82200","20.56874","0.01593"
"247.00800","20.58416","0.01619"
"247.19400","20.59970","0.01621"
"247.38000","20.61519","0.01589"
"247.56600","20.63068","0.01612"
"247.75200","20.64622","0.01606"
"247.93800","20.66165","0.01651"
"248.12400","20.67725","0.01616"
"248.31000","20.69268","0.01668"
"248.49600","20.70822","0.01650"
"248.68200","20.72377","0.01688"
"248.86800","20.73925","0.01707"
"249.05400","20.75468","0.01709"
"249.24000","20.77023","0.01691"
"249.42600","20.78565","0.01715"
"249.61200","20.80120","0.01698"
"249.79800","20.81674","0.01753"
"249.98400","20.83211","0.01747"
"250.17000","20.84765","0.01769"
"250.35600","20.86320","0.01781"
"250.54200","20.87875","0.01775"
"250.72800","20.89417","0.01711"
"250.91400","20.90972","0.01788"
"251.10000","20.92520","0.01819"
"251.28600","20.94062","0.01800"
"251.47200","20.95629","0.01820"
"251.65800","20.97172","0.01828"
"251.84400","20.98720","0.01784"
"252.03000","21.00275","0.01805"
"252.21600","21.01811","0.01836"
"252.40200","21.03372","0.01865"
"252.58800","21.04926","0.01857"
"252.77400","21.06475","0.01881"
"252.96000","21.08023","0.01890"
"253.14600","21.09572","0.01850"
"253.33200","21.11121","0.01928"
"253.51800","21.12675","0.01921"
"253.70400","21.14223","0.01941"
"253.89000","21.15766","0.01880"
"254.07600","21.17327","0.01962"
"254.26200","21.18869","0.01979"
"254.44800","21.20412","0.01907"
"254.63400","21.21978","0.01967"
"254.82000","21.23521","0.01956"
"255.00600","21.25064","0.01912"
"255.19200","21.26624","0.01984"
"255.37800","21.28173","0.02014"
"255.56400","21.29715","0.01986"
"255.75000","21.31269","0.01988"
"255.93600","21.32818","0.01999"
"256.12200","21.34373","0.02038"
"256.30800","21.35921","0.02021"
"256.49400","21.37470","0.02027"
"256.68000","21.39018","0.02028"
"256.86600","21.40567","0.02092"
"257.05200","21.42115","0.02092"
"257.23800","21.43670","0.02115"
"257.42400","21.45219","0.02121"
"257.61000","21.46767","0.02095"
"257.79600","21.48322","0.02080"
"257.98200","21.49876","0.02101"
"258.16800","21.51413","0.02093"
"258.35400","21.52979","0.02115"
"258.54000","21.54522","0.02104"
"258.72600","21.56064","0.02079"
"258.91200","21.57625","0.02064"
"259.09800","21.59179","0.02107"
"259.28400","21.60710","0.02152"
"259.47000","21.62277","0.02162"
"259.65600","21.63819","0.02192"
"259.84200","21.65361","0.02195"
"260.02800","21.66922","0.02167"
"260.21400","21.68471","0.02233"
"260.40000","21.70019","0.02251"
"260.58600","21.71574","0.02252"
"260.77200","21.73116","0.02280"
"260.95800","21.74671","0.02230"
"261.14400","21.76219","0.02318"
"261.33000","21.77768","0.02312"
"261.51600","21.79323","0.02320"
"261.70200","21.80871","0.02347"
"261.88800","21.82420","0.02371"
"262.07400","21.83968","0.02370"
"262.26000","21.85523","0.02381"
"262.44600","21.87071","0.02398"
"262.63200","21.88620","0.02400"
"262.81800","21.90168","0.02417"
"263.00400","21.91717","0.02459"
"263.19000","21.93271","0.02456"
"263.37600","21.94820","0.02514"
"263.56200","21.96369","0.02467"
"263.74800","21.97929","0.02502"
"263.93400","21.99471","0.02542"
"264.12000","22.01020","0.02520"
"264.30600","22.02575","0.02492"
"264.49200","22.04117","0.02490"
"264.67800","22.05672","0.02567"
"264.86400","22.07220","0.02563"
"265.05000","22.08763","0.02550"
"265.23600","22.10317","0.02603"
"265.42200","22.11872","0.02652"
"265.60800","22.13415","0.02622"
"265.79400","22.14969","0.02599"
"265.98000","22.16529","0.02669"
"266.16600","22.18072","0.02644"
"266.35200","22.19621","0.02684"
"266.53800","22.21175","0.02707"
"266.72400","22.22724","0.02707"
"266.91000","22.24266","0.02675"
"267.09600","22.25821","0.02795"
"267.28200","22.27363","0.02755"
"267.46800","22.28924","0.02756"
"267.65400","22.30473","0.02806"
"267.84000","22.32015","0.02795"
"268.02600","22.33576","0.02812"
"268.21200","22.35118","0.02815"
"268.39800","22.36666","0.02787"
"268.58400","22.38221","0.02796"
"268.77000","22.39776","0.02866"
"268.95600","22.41318","0.02828"
"269.14200","22.42873","0.02878"
"269.32800","22.44421","0.02865"
"269.51400","22.45964","0.02858"
"269.70000","22.47524","0.02922"
"269.88600","22.49073","0.02923"
"270.07200","22.50616","0.02934"
"270.25800","22.52176","0.02991"
"270.44400","22.53724","0.02977"
"270.63000","22.55267","0.02952"
"270.81600","22.56822","0.03032"
"271.00200","22.58376","0.02999"
"271.18800","22.59919","0.03046"
"271.37400","22.61468","0.03103"
"271.46600","22.62245","0.03084"