File: Force_trajectories/170107_1/Specimen_RawData_8.csv
End date,"1/7/2017"
Specimen label,"17CT_36"
Maximum Load,"0.72786",N

Time,Extension,Load
(s),(mm),(N)
"0.00000","0.00000","-0.00430"
"0.24600","0.01895","-0.00392"
"0.49200","0.04131","-0.00336"
"0.73800","0.06164","-0.00242"
"0.98400","0.08227","-0.00222"
"1.23000","0.10272","-0.00134"
"1.47600","0.12317","-0.00115"
"1.72200","0.14373","-0.00101"
"1.96800","0.16418","-0.00053"
"2.21400","0.18475","-0.00017"
"2.46000","0.20508","0.00040"
"2.70600","0.22571","0.00045"
"2.95200","0.24615","0.00114"
"3.19800","0.26672","0.00144"
"3.44400","0.28723","0.00157"
"3.69000","0.30774","0.00205"
"3.93600","0.32824","0.00201"
"4.18200","0.34869","0.00255"
"4.42800","0.36920","0.00250"
"4.67400","0.38971","0.00257"
"4.92000","0.41022","0.00267"
"5.16600","0.43066","0.00203"
"5.41200","0.45123","0.00294"
"5.65800","0.47168","0.00357"
"5.90400","0.49219","0.00294"
"6.15000","0.51264","0.00334"
"6.39600","0.53326","0.00374"
"6.64200","0.55371","0.00360"
"6.88800","0.57422","0.00356"
"7.13400","0.59473","0.00394"
"7.38000","0.61523","0.00437"
"7.62600","0.63568","0.00411"
"7.87200","0.65613","0.00536"
"8.11800","0.67676","0.00488"
"8.36400","0.69721","0.00496"
"8.61000","0.71771","0.00500"
"8.85600","0.73816","0.00522"
"9.10200","0.75873","0.00598"
"9.34800","0.77918","0.00552"
"9.59400","0.79974","0.00548"
"9.84000","0.82025","0.00586"
"10.08600","0.84070","0.00612"
"10.33200","0.86121","0.00653"
"10.57800","0.88172","0.00663"
"10.82400","0.90228","0.00642"
"11.07000","0.92261","0.00676"
"11.31600","0.94318","0.00645"
"11.56200","0.96375","0.00691"
"11.80800","0.98426","0.00702"
"12.05400","1.00470","0.00773"
"12.30000","1.02521","0.00735"
"12.54600","1.04572","0.00750"
"12.79200","1.06623","0.00811"
"13.03800","1.08667","0.00792"
"13.28400","1.10718","0.00792"
"13.53000","1.12769","0.00806"
"13.77600","1.14814","0.00839"
"14.02200","1.16871","0.00828"
"14.26800","1.18915","0.00878"
"14.51400","1.20972","0.00897"
"14.76000","1.23017","0.00925"
"15.00600","1.25074","0.00926"
"15.25200","1.27119","0.00931"
"15.49800","1.29169","0.00942"
"15.74400","1.31226","0.00993"
"15.99000","1.33271","0.00954"
"16.23600","1.35322","0.01004"
"16.48200","1.37366","0.01000"
"16.72800","1.39423","0.01013"
"16.97400","1.41468","0.01066"
"17.22000","1.43519","0.01036"
"17.46600","1.45564","0.01102"
"17.71200","1.47620","0.01112"
"17.95800","1.49665","0.01123"
"18.20400","1.51722","0.01158"
"18.45000","1.53773","0.01141"
"18.69600","1.55817","0.01195"
"18.94200","1.57874","0.01194"
"19.18800","1.59919","0.01210"
"19.43400","1.61976","0.01238"
"19.68000","1.64009","0.01265"
"19.92600","1.66071","0.01259"
"20.17200","1.68122","0.01277"
"20.41800","1.70173","0.01349"
"20.66400","1.72218","0.01318"
"20.91000","1.74275","0.01380"
"21.15600","1.76325","0.01428"
"21.40200","1.78370","0.01482"
"21.64800","1.80415","0.01500"
"21.89400","1.82466","0.01535"
"22.14000","1.84522","0.01513"
"22.38600","1.86567","0.01512"
"22.63200","1.88624","0.01609"
"22.87800","1.90669","0.01568"
"23.12400","1.92720","0.01668"
"23.37000","1.94764","0.01650"
"23.61600","1.96827","0.01664"
"23.86200","1.98872","0.01675"
"24.10800","2.00923","0.01718"
"24.35400","2.02974","0.01744"
"24.60000","2.05018","0.01782"
"24.84600","2.07069","0.01827"
"25.09200","2.09114","0.01813"
"25.33800","2.11177","0.01864"
"25.58400","2.13215","0.01895"
"25.83000","2.15272","0.01920"
"26.07600","2.17317","0.01962"
"26.32200","2.19374","0.02005"
"26.56800","2.21419","0.02006"
"26.81400","2.23469","0.02066"
"27.06000","2.25520","0.02067"
"27.30600","2.27571","0.02137"
"27.55200","2.29628","0.02190"
"27.79800","2.31667","0.02251"
"28.04400","2.33717","0.02246"
"28.29000","2.35762","0.02285"
"28.53600","2.37819","0.02340"
"28.78200","2.39870","0.02448"
"29.02800","2.41926","0.02465"
"29.27400","2.43971","0.02773"
"29.52000","2.46022","0.02471"
"29.76600","2.48073","0.02469"
"30.01200","2.50118","0.02559"
"30.25800","2.52168","0.02629"
"30.50400","2.54219","0.02677"
"30.75000","2.56270","0.02722"
"30.99600","2.58315","0.02785"
"31.24200","2.60371","0.02841"
"31.48800","2.62416","0.02897"
"31.73400","2.64473","0.02939"
"31.98000","2.66518","0.02989"
"32.22600","2.68581","0.03031"
"32.47200","2.70619","0.03065"
"32.71800","2.72670","0.03101"
"32.96400","2.74721","0.03205"
"33.21000","2.76772","0.03222"
"33.45600","2.78823","0.03260"
"33.70200","2.80861","0.03292"
"33.94800","2.82924","0.03393"
"34.19400","2.84963","0.03462"
"34.44000","2.87020","0.03477"
"34.68600","2.89064","0.03614"
"34.93200","2.91121","0.03650"
"35.17800","2.93172","0.03741"
"35.42400","2.95223","0.03778"
"35.67000","2.97268","0.03859"
"35.91600","2.99318","0.03997"
"36.16200","3.01369","0.04066"
"36.40800","3.03420","0.04106"
"36.65400","3.05477","0.04140"
"36.90000","3.07510","0.04279"
"37.14600","3.09572","0.04359"
"37.39200","3.11623","0.04466"
"37.63800","3.13674","0.04533"
"37.88400","3.15719","0.04600"
"38.13000","3.17769","0.04717"
"38.37600","3.19826","0.04758"
"38.62200","3.21871","0.04884"
"38.86800","3.23922","0.04901"
"39.11400","3.25967","0.04962"
"39.36000","3.28023","0.05071"
"39.60600","3.30068","0.05152"
"39.85200","3.32125","0.05230"
"40.09800","3.34170","0.05301"
"40.34400","3.36220","0.05371"
"40.59000","3.38265","0.05433"
"40.83600","3.40328","0.05414"
"41.08200","3.42367","0.05519"
"41.32800","3.44424","0.05628"
"41.57400","3.46474","0.05639"
"41.82000","3.48525","0.05719"
"42.06600","3.50570","0.05712"
"42.31200","3.52609","0.05795"
"42.55800","3.54677","0.05854"
"42.80400","3.56716","0.05869"
"43.05000","3.58773","0.05957"
"43.29600","3.60812","0.05970"
"43.54200","3.62875","0.06008"
"43.78800","3.64919","0.06056"
"44.03400","3.66976","0.06111"
"44.28000","3.69021","0.05916"
"44.52600","3.71072","0.05894"
"44.77200","3.73123","0.05939"
"45.01800","3.75167","0.05936"
"45.26400","3.77224","0.05928"
"45.51000","3.79263","0.05942"
"45.75600","3.81320","0.05998"
"46.00200","3.83371","0.06012"
"46.24800","3.85421","0.06068"
"46.49400","3.87472","0.06146"
"46.74000","3.89523","0.06170"
"46.98600","3.91574","0.06198"
"47.23200","3.93618","0.06243"
"47.47800","3.95669","0.06269"
"47.72400","3.97720","0.06295"
"47.97000","3.99777","0.06352"
"48.21600","4.01816","0.06350"
"48.46200","4.03872","0.06389"
"48.70800","4.05911","0.06492"
"48.95400","4.07968","0.06504"
"49.20000","4.10019","0.06556"
"49.44600","4.12075","0.06630"
"49.69200","4.14120","0.06630"
"49.93800","4.16171","0.06712"
"50.18400","4.18222","0.06772"
"50.43000","4.20273","0.06852"
"50.67600","4.22323","0.06897"
"50.92200","4.24362","0.06957"
"51.16800","4.26425","0.07050"
"51.41400","4.28470","0.07146"
"51.66000","4.30515","0.07217"
"51.90600","4.32565","0.07302"
"52.15200","4.34622","0.07379"
"52.39800","4.36667","0.07476"
"52.64400","4.38724","0.07514"
"52.89000","4.40774","0.07681"
"53.13600","4.42819","0.07703"
"53.38200","4.44870","0.07795"
"53.62800","4.46915","0.07909"
"53.87400","4.48972","0.08019"
"54.12000","4.51010","0.08143"
"54.36600","4.53073","0.08229"
"54.61200","4.55124","0.08317"
"54.85800","4.57175","0.08516"
"55.10400","4.59219","0.08637"
"55.35000","4.61270","0.08831"
"55.59600","4.63321","0.08936"
"55.84200","4.65372","0.09030"
"56.08800","4.67417","0.09213"
"56.33400","4.69467","0.09294"
"56.58000","4.71524","0.09549"
"56.82600","4.73569","0.09693"
"57.07200","4.75626","0.09892"
"57.31800","4.77671","0.09967"
"57.56400","4.79715","0.10289"
"57.81000","4.81766","0.10398"
"58.05600","4.83829","0.10649"
"58.30200","4.85868","0.10795"
"58.54800","4.87924","0.10997"
"58.79400","4.89975","0.11117"
"59.04000","4.92020","0.11259"
"59.28600","4.94071","0.11397"
"59.53200","4.96116","0.11576"
"59.77800","4.98172","0.11695"
"60.02400","5.00217","0.11827"
"60.27000","5.02274","0.11985"
"60.51600","5.04319","0.12097"
"60.76200","5.06376","0.12268"
"61.00800","5.08414","0.12398"
"61.25400","5.10471","0.12481"
"61.50000","5.12522","0.12606"
"61.74600","5.14573","0.12522"
"61.99200","5.16623","0.12458"
"62.23800","5.18668","0.12588"
"62.48400","5.20725","0.12741"
"62.73000","5.22758","0.12811"
"62.97600","5.24821","0.12945"
"63.22200","5.26865","0.13059"
"63.46800","5.28922","0.13211"
"63.71400","5.30973","0.13332"
"63.96000","5.33024","0.13460"
"64.20600","5.35074","0.13519"
"64.45200","5.37119","0.13509"
"64.69800","5.39170","0.13563"
"64.94400","5.41221","0.13711"
"65.19000","5.43272","0.13795"
"65.43600","5.45316","0.13882"
"65.68200","5.47373","0.14007"
"65.92800","5.49418","0.14127"
"66.17400","5.51469","0.14297"
"66.42000","5.53514","0.14435"
"66.66600","5.55576","0.14625"
"66.91200","5.57615","0.14746"
"67.15800","5.59672","0.14958"
"67.40400","5.61723","0.15097"
"67.65000","5.63767","0.15283"
"67.89600","5.65824","0.15400"
"68.14200","5.67863","0.15571"
"68.38800","5.69926","0.15696"
"68.63400","5.71965","0.15856"
"68.88000","5.74015","0.16041"
"69.12600","5.76066","0.16136"
"69.37200","5.78123","0.16309"
"69.61800","5.80168","0.16458"
"69.86400","5.82219","0.16576"
"70.11000","5.84275","0.16727"
"70.35600","5.86320","0.16858"
"70.60200","5.88371","0.16938"
"70.84800","5.90416","0.16998"
"71.09400","5.92472","0.17066"
"71.34000","5.94511","0.17192"
"71.58600","5.96574","0.17262"
"71.83200","5.98619","0.17326"
"72.07800","6.00676","0.17439"
"72.32400","6.02720","0.17514"
"72.57000","6.04771","0.17595"
"72.81600","6.06822","0.17699"
"73.06200","6.08867","0.17815"
"73.30800","6.10918","0.17948"
"73.55400","6.12974","0.18042"
"73.80000","6.15025","0.18252"
"74.04600","6.17064","0.18402"
"74.29200","6.19121","0.18601"
"74.53800","6.21165","0.18737"
"74.78400","6.23222","0.18889"
"75.03000","6.25273","0.19039"
"75.27600","6.27324","0.19192"
"75.52200","6.29368","0.19362"
"75.76800","6.31419","0.19561"
"76.01400","6.33470","0.19673"
"76.26000","6.35521","0.19843"
"76.50600","6.37572","0.20116"
"76.75200","6.39616","0.20370"
"76.99800","6.41673","0.20596"
"77.24400","6.43718","0.20732"
"77.49000","6.45769","0.20954"
"77.73600","6.47814","0.21162"
"77.98200","6.49876","0.21317"
"78.22800","6.51915","0.21494"
"78.47400","6.53966","0.21634"
"78.72000","6.56023","0.21893"
"78.96600","6.58068","0.22035"
"79.21200","6.60124","0.22298"
"79.45800","6.62169","0.22525"
"79.70400","6.64226","0.22731"
"79.95000","6.66265","0.22960"
"80.19600","6.68321","0.23207"
"80.44200","6.70372","0.23365"
"80.68800","6.72423","0.23616"
"80.93400","6.74468","0.21486"
"81.18000","6.76519","0.21812"
"81.42600","6.78569","0.22189"
"81.67200","6.80614","0.22433"
"81.91800","6.82665","0.22773"
"82.16400","6.84722","0.23098"
"82.41000","6.86772","0.23350"
"82.65600","6.88817","0.23766"
"82.90200","6.90874","0.23996"
"83.14800","6.92919","0.24537"
"83.39400","6.94970","0.24945"
"83.64000","6.97014","0.25332"
"83.88600","6.99077","0.25773"
"84.13200","7.01116","0.26100"
"84.37800","7.03173","0.26358"
"84.62400","7.05224","0.26602"
"84.87000","7.07274","0.26891"
"85.11600","7.09325","0.27110"
"85.36200","7.11364","0.27286"
"85.60800","7.13427","0.27406"
"85.85400","7.15465","0.27508"
"86.10000","7.17522","0.27690"
"86.34600","7.19567","0.27828"
"86.59200","7.21624","0.27903"
"86.83800","7.23669","0.28031"
"87.08400","7.25725","0.28087"
"87.33000","7.27770","0.28149"
"87.57600","7.29821","0.28221"
"87.82200","7.31872","0.28304"
"88.06800","7.33917","0.28386"
"88.31400","7.35973","0.28529"
"88.56000","7.38012","0.28639"
"88.80600","7.40075","0.28786"
"89.05200","7.42120","0.28954"
"89.29800","7.44176","0.29127"
"89.54400","7.46215","0.29329"
"89.79000","7.48272","0.29580"
"90.03600","7.50329","0.29713"
"90.28200","7.52374","0.30022"
"90.52800","7.54418","0.30341"
"90.77400","7.56469","0.30758"
"91.02000","7.58520","0.30989"
"91.26600","7.60565","0.31383"
"91.51200","7.62621","0.31702"
"91.75800","7.64666","0.32000"
"92.00400","7.66723","0.32289"
"92.25000","7.68768","0.32588"
"92.49600","7.70825","0.32884"
"92.74200","7.72869","0.33143"
"92.98800","7.74920","0.33089"
"93.23400","7.76971","0.33314"
"93.48000","7.79022","0.33574"
"93.72600","7.81073","0.33858"
"93.97200","7.83111","0.34068"
"94.21800","7.85174","0.34251"
"94.46400","7.87213","0.34489"
"94.71000","7.89270","0.34659"
"94.95600","7.91314","0.34934"
"95.20200","7.93377","0.35321"
"95.44800","7.95416","0.35489"
"95.69400","7.97473","0.35732"
"95.94000","7.99524","0.35964"
"96.18600","8.01568","0.36104"
"96.43200","8.03625","0.36302"
"96.67800","8.05670","0.36518"
"96.92400","8.07727","0.36728"
"97.17000","8.09760","0.36911"
"97.41600","8.11822","0.37082"
"97.66200","8.13867","0.36249"
"97.90800","8.15930","0.36292"
"98.15400","8.17969","0.36522"
"98.40000","8.20019","0.36739"
"98.64600","8.22070","0.36926"
"98.89200","8.24121","0.37188"
"99.13800","8.26166","0.37403"
"99.38400","8.28217","0.37546"
"99.63000","8.30273","0.37683"
"99.87600","8.32318","0.37298"
"100.12200","8.34375","0.37492"
"100.36800","8.36414","0.37715"
"100.61400","8.38470","0.37997"
"100.86000","8.40515","0.38247"
"101.10600","8.42578","0.38564"
"101.35200","8.44617","0.38891"
"101.59800","8.46668","0.39275"
"101.84400","8.48724","0.39638"
"102.09000","8.50775","0.39886"
"102.33600","8.52820","0.34324"
"102.58200","8.54865","0.27612"
"102.82800","8.56927","0.27806"
"103.07400","8.58972","0.27842"
"103.32000","8.61023","0.27961"
"103.56600","8.63068","0.28251"
"103.81200","8.65125","0.28347"
"104.05800","8.67163","0.28364"
"104.30400","8.69220","0.28520"
"104.55000","8.71271","0.29021"
"104.79600","8.73322","0.29357"
"105.04200","8.75373","0.29312"
"105.28800","8.77417","0.29630"
"105.53400","8.79474","0.30543"
"105.78000","8.81513","0.31277"
"106.02600","8.83570","0.31387"
"106.27200","8.85620","0.28758"
"106.51800","8.87671","0.28760"
"106.76400","8.89716","0.29041"
"107.01000","8.91773","0.19170"
"107.25600","8.93818","0.20107"
"107.50200","8.95868","0.19821"
"107.74800","8.97919","0.19848"
"107.99400","8.99970","0.20804"
"108.24000","9.02027","0.20446"
"108.48600","9.04066","0.20864"
"108.73200","9.06122","0.21752"
"108.97800","9.08167","0.21668"
"109.22400","9.10218","0.21811"
"109.47000","9.12269","0.22889"
"109.71600","9.14325","0.22994"
"109.96200","9.16370","0.23319"
"110.20800","9.18421","0.24428"
"110.45400","9.20472","0.24637"
"110.70000","9.22523","0.24947"
"110.94600","9.24573","0.25540"
"111.19200","9.26612","0.25814"
"111.43800","9.28675","0.26278"
"111.68400","9.30720","0.26542"
"111.93000","9.32771","0.26753"
"112.17600","9.34815","0.27259"
"112.42200","9.36872","0.27331"
"112.66800","9.38917","0.27505"
"112.91400","9.40968","0.27868"
"113.16000","9.43019","0.27993"
"113.40600","9.45069","0.28063"
"113.65200","9.47120","0.28167"
"113.89800","9.49165","0.28250"
"114.14400","9.51222","0.28466"
"114.39000","9.53260","0.28565"
"114.63600","9.55317","0.17112"
"114.88200","9.57368","0.17351"
"115.12800","9.59425","0.17769"
"115.37400","9.61469","0.17329"
"115.62000","9.63520","0.17473"
"115.86600","9.65577","0.17827"
"116.11200","9.67622","0.17802"
"116.35800","9.69667","0.18026"
"116.60400","9.71717","0.18529"
"116.85000","9.73768","0.18489"
"117.09600","9.75819","0.18762"
"117.34200","9.77870","0.19160"
"117.58800","9.79914","0.19158"
"117.83400","9.81971","0.19368"
"118.08000","9.84016","0.19929"
"118.32600","9.86079","0.19866"
"118.57200","9.88124","0.20097"
"118.81800","9.90168","0.20656"
"119.06400","9.92225","0.20877"
"119.31000","9.94270","0.21082"
"119.55600","9.96321","0.21435"
"119.80200","9.98360","0.21806"
"120.04800","10.00422","0.22044"
"120.29400","10.02467","0.22371"
"120.54000","10.04524","0.22819"
"120.78600","10.06569","0.23021"
"121.03200","10.08626","0.23218"
"121.27800","10.10664","0.23898"
"121.52400","10.12721","0.24323"
"121.77000","10.14778","0.24730"
"122.01600","10.16817","0.25396"
"122.26200","10.18867","0.26099"
"122.50800","10.20918","0.26396"
"122.75400","10.22975","0.26627"
"123.00000","10.25014","0.27098"
"123.24600","10.27071","0.27353"
"123.49200","10.29121","0.27504"
"123.73800","10.31178","0.27707"
"123.98400","10.33217","0.27900"
"124.23000","10.35268","0.28072"
"124.47600","10.37318","0.28169"
"124.72200","10.39369","0.28341"
"124.96800","10.41420","0.28491"
"125.21400","10.43471","0.28694"
"125.46000","10.45522","0.28799"
"125.70600","10.47566","0.29067"
"125.95200","10.49617","0.29497"
"126.19800","10.51668","0.29936"
"126.44400","10.53719","0.30318"
"126.69000","10.55764","0.30796"
"126.93600","10.57826","0.31308"
"127.18200","10.59865","0.31770"
"127.42800","10.61922","0.32061"
"127.67400","10.63973","0.32426"
"127.92000","10.66018","0.32718"
"128.16600","10.68074","0.33137"
"128.41200","10.70119","0.33540"
"128.65800","10.72176","0.33800"
"128.90400","10.74221","0.34044"
"129.15000","10.76271","0.34315"
"129.39600","10.78316","0.34642"
"129.64200","10.80373","0.35014"
"129.88800","10.82412","0.35313"
"130.13400","10.84474","0.35607"
"130.38000","10.86519","0.35938"
"130.62600","10.88570","0.36203"
"130.87200","10.90621","0.36498"
"131.11800","10.92666","0.36779"
"131.36400","10.94728","0.36977"
"131.61000","10.96761","0.37231"
"131.85600","10.98824","0.37489"
"132.10200","11.00869","0.37734"
"132.34800","11.02920","0.37977"
"132.59400","11.04970","0.35970"
"132.84000","11.07021","0.35830"
"133.08600","11.09072","0.35942"
"133.33200","11.11123","0.36108"
"133.57800","11.13167","0.36361"
"133.82400","11.15218","0.36625"
"134.07000","11.17275","0.36832"
"134.31600","11.19314","0.37080"
"134.56200","11.21371","0.37367"
"134.80800","11.23415","0.37554"
"135.05400","11.25472","0.37807"
"135.30000","11.27517","0.38106"
"135.54600","11.29574","0.38395"
"135.79200","11.31618","0.38705"
"136.03800","11.33669","0.39078"
"136.28400","11.35720","0.39428"
"136.53000","11.37771","0.39805"
"136.77600","11.39822","0.40110"
"137.02200","11.41860","0.40391"
"137.26800","11.43923","0.40732"
"137.51400","11.45968","0.41107"
"137.76000","11.48019","0.41488"
"138.00600","11.50064","0.41732"
"138.25200","11.52126","0.41957"
"138.49800","11.54165","0.42135"
"138.74400","11.56222","0.42335"
"138.99000","11.58273","0.41899"
"139.23600","11.60324","0.41327"
"139.48200","11.62368","0.41454"
"139.72800","11.64419","0.41666"
"139.97400","11.66470","0.41900"
"140.22000","11.68509","0.42206"
"140.46600","11.70572","0.42433"
"140.71200","11.72616","0.42685"
"140.95800","11.74673","0.42980"
"141.20400","11.76724","0.43307"
"141.45000","11.78775","0.43642"
"141.69600","11.80825","0.43931"
"141.94200","11.82870","0.44233"
"142.18800","11.84915","0.44566"
"142.43400","11.86972","0.45127"
"142.68000","11.89022","0.45464"
"142.92600","11.91061","0.45942"
"143.17200","11.93118","0.46326"
"143.41800","11.95169","0.46468"
"143.66400","11.97220","0.40687"
"143.91000","11.99270","0.40610"
"144.15600","12.01327","0.41036"
"144.40200","12.03372","0.41404"
"144.64800","12.05423","0.41831"
"144.89400","12.07474","0.42239"
"145.14000","12.09518","0.42606"
"145.38600","12.11569","0.42909"
"145.63200","12.13614","0.43288"
"145.87800","12.15671","0.43620"
"146.12400","12.17721","0.44031"
"146.37000","12.19772","0.44497"
"146.61600","12.21817","0.45009"
"146.86200","12.23874","0.45692"
"147.10800","12.25919","0.46339"
"147.35400","12.27969","0.46789"
"147.60000","12.30020","0.47162"
"147.84600","12.32065","0.47562"
"148.09200","12.34122","0.47832"
"148.33800","12.36167","0.48101"
"148.58400","12.38223","0.48367"
"148.83000","12.40262","0.48541"
"149.07600","12.42319","0.48700"
"149.32200","12.44370","0.48956"
"149.56800","12.46426","0.49145"
"149.81400","12.48465","0.49383"
"150.06000","12.50522","0.49559"
"150.30600","12.52573","0.49759"
"150.55200","12.54624","0.50101"
"150.79800","12.56668","0.50298"
"151.04400","12.58719","0.50688"
"151.29000","12.60776","0.51036"
"151.53600","12.62821","0.51523"
"151.78200","12.64872","0.51968"
"152.02800","12.66916","0.52267"
"152.27400","12.68967","0.52564"
"152.52000","12.71012","0.52983"
"152.76600","12.73075","0.51048"
"153.01200","12.75119","0.51194"
"153.25800","12.77170","0.51408"
"153.50400","12.79221","0.51785"
"153.75000","12.81272","0.52257"
"153.99600","12.83322","0.52476"
"154.24200","12.85367","0.52828"
"154.48800","12.87424","0.53136"
"154.73400","12.89469","0.53480"
"154.98000","12.91520","0.53721"
"155.22600","12.93565","0.54001"
"155.47200","12.95621","0.54323"
"155.71800","12.97666","0.54545"
"155.96400","12.99723","0.54905"
"156.21000","13.01774","0.55297"
"156.45600","13.03818","0.55642"
"156.70200","13.05875","0.56101"
"156.94800","13.07920","0.56401"
"157.19400","13.09977","0.56675"
"157.44000","13.12016","0.57013"
"157.68600","13.14066","0.57179"
"157.93200","13.16117","0.57484"
"158.17800","13.18174","0.57645"
"158.42400","13.20213","0.57815"
"158.67000","13.22269","0.57939"
"158.91600","13.24326","0.58097"
"159.16200","13.26371","0.58203"
"159.40800","13.28422","0.58354"
"159.65400","13.30473","0.58468"
"159.90000","13.32523","0.58632"
"160.14600","13.34568","0.58804"
"160.39200","13.36619","0.59028"
"160.63800","13.38664","0.59342"
"160.88400","13.40720","0.59582"
"161.13000","13.42771","0.59923"
"161.37600","13.44828","0.60367"
"161.62200","13.46873","0.60680"
"161.86800","13.48918","0.61100"
"162.11400","13.50974","0.61486"
"162.36000","13.53025","0.61959"
"162.60600","13.55070","0.62276"
"162.85200","13.57115","0.62626"
"163.09800","13.59172","0.62826"
"163.34400","13.61216","0.62996"
"163.59000","13.63273","0.63261"
"163.83600","13.65312","0.63412"
"164.08200","13.67375","0.63528"
"164.32800","13.69419","0.63628"
"164.57400","13.71476","0.63792"
"164.82000","13.73521","0.63998"
"165.06600","13.75572","0.64120"
"165.31200","13.77623","0.62928"
"165.55800","13.79667","0.62941"
"165.80400","13.81724","0.63154"
"166.05000","13.83763","0.63312"
"166.29600","13.85820","0.63157"
"166.54200","13.87871","0.58587"
"166.78800","13.89921","0.58542"
"167.03400","13.91966","0.58621"
"167.28000","13.94023","0.58725"
"167.52600","13.96074","0.58931"
"167.77200","13.98124","0.59146"
"168.01800","14.00169","0.59374"
"168.26400","14.02220","0.59730"
"168.51000","14.04271","0.60007"
"168.75600","14.06322","0.60311"
"169.00200","14.08372","0.60795"
"169.24800","14.10417","0.61068"
"169.49400","14.12468","0.61712"
"169.74000","14.14519","0.62068"
"169.98600","14.16576","0.62494"
"170.23200","14.18620","0.62772"
"170.47800","14.20671","0.62988"
"170.72400","14.22722","0.63306"
"170.97000","14.24767","0.63582"
"171.21600","14.26823","0.63927"
"171.46200","14.28862","0.64087"
"171.70800","14.30925","0.64410"
"171.95400","14.32970","0.64709"
"172.20000","14.35027","0.64983"
"172.44600","14.37071","0.65224"
"172.69200","14.39122","0.65720"
"172.93800","14.41167","0.66066"
"173.18400","14.43224","0.66446"
"173.43000","14.45274","0.66812"
"173.67600","14.47319","0.67169"
"173.92200","14.49370","0.67448"
"174.16800","14.51415","0.67784"
"174.41400","14.53477","0.68093"
"174.66000","14.55511","0.68254"
"174.90600","14.57567","0.68448"
"175.15200","14.59618","0.68623"
"175.39800","14.61675","0.68777"
"175.64400","14.63720","0.68937"
"175.89000","14.65776","0.69067"
"176.13600","14.67821","0.69215"
"176.38200","14.69866","0.69372"
"176.62800","14.71917","0.69604"
"176.87400","14.73967","0.69796"
"177.12000","14.76024","0.69990"
"177.36600","14.78069","0.70232"
"177.61200","14.80120","0.70452"
"177.85800","14.82165","0.70758"
"178.10400","14.84221","0.71131"
"178.35000","14.86266","0.71470"
"178.59600","14.88329","0.71876"
"178.84200","14.90368","0.72208"
"179.08800","14.92418","0.72519"
"179.33400","14.94469","0.66918"
"179.58000","14.96526","0.62179"
"179.82600","14.98571","0.62172"
"180.07200","15.00616","0.62394"
"180.31800","15.02672","0.62662"
"180.56400","15.04717","0.62757"
"180.81000","15.06768","0.63069"
"181.05600","15.08813","0.63242"
"181.30200","15.10870","0.63330"
"181.54800","15.12914","0.61652"
"181.79400","15.14977","0.55874"
"182.04000","15.17028","0.56035"
"182.28600","15.19073","0.56188"
"182.53200","15.21124","0.56361"
"182.77800","15.23168","0.56427"
"183.02400","15.25225","0.56680"
"183.27000","15.27264","0.56755"
"183.51600","15.29327","0.56997"
"183.76200","15.31365","0.57227"
"184.00800","15.33422","0.57383"
"184.25400","15.35467","0.57560"
"184.50000","15.37524","0.57722"
"184.74600","15.39574","0.57922"
"184.99200","15.41619","0.58107"
"185.23800","15.43670","0.58263"
"185.48400","15.45721","0.58426"
"185.73000","15.47772","0.58523"
"185.97600","15.49817","0.58672"
"186.22200","15.51873","0.58807"
"186.46800","15.53918","0.58973"
"186.71400","15.55969","0.59070"
"186.96000","15.58014","0.59038"
"187.20600","15.60076","0.59160"
"187.45200","15.62121","0.59239"
"187.69800","15.64172","0.59453"
"187.94400","15.66223","0.59829"
"188.19000","15.68273","0.60129"
"188.43600","15.70324","0.60473"
"188.68200","15.72363","0.60709"
"188.92800","15.74420","0.60994"
"189.17400","15.76465","0.61303"
"189.42000","15.78521","0.61694"
"189.66600","15.80566","0.62033"
"189.91200","15.82623","0.62314"
"190.15800","15.84668","0.62603"
"190.40400","15.86718","0.62856"
"190.65000","15.88769","0.63059"
"190.89600","15.90820","0.63290"
"191.14200","15.92871","0.63479"
"191.38800","15.94922","0.63620"
"191.63400","15.96972","0.63812"
"191.88000","15.99011","0.63884"
"192.12600","16.01068","0.64134"
"192.37200","16.03119","0.64301"
"192.61800","16.05176","0.64388"
"192.86400","16.07220","0.64541"
"193.11000","16.09271","0.64756"
"193.35600","16.11322","0.65028"
"193.60200","16.13367","0.65153"
"193.84800","16.15417","0.65309"
"194.09400","16.17468","0.65576"
"194.34000","16.19519","0.65754"
"194.58600","16.21564","0.65873"
"194.83200","16.23621","0.66141"
"195.07800","16.25671","0.66340"
"195.32400","16.27716","0.66589"
"195.57000","16.29767","0.66741"
"195.81600","16.31830","0.66024"
"196.06200","16.33863","0.66273"
"196.30800","16.35919","0.66431"
"196.55400","16.37970","0.66690"
"196.80000","16.40015","0.66743"
"197.04600","16.42072","0.61674"
"197.29200","16.44116","0.61882"
"197.53800","16.46173","0.61889"
"197.78400","16.48218","0.62087"
"198.03000","16.50275","0.62168"
"198.27600","16.52320","0.62410"
"198.52200","16.54370","0.62619"
"198.76800","16.56415","0.62772"
"199.01400","16.58472","0.62986"
"199.26000","16.60523","0.63087"
"199.50600","16.62574","0.63242"
"199.75200","16.64624","0.63513"
"199.99800","16.66669","0.63672"
"200.24400","16.68726","0.63878"
"200.49000","16.70765","0.63981"
"200.73600","16.72821","0.64130"
"200.98200","16.74866","0.64393"
"201.22800","16.76929","0.64599"
"201.47400","16.78968","0.64787"
"201.72000","16.81019","0.64953"
"201.96600","16.83069","0.65161"
"202.21200","16.85120","0.65389"
"202.45800","16.87171","0.65649"
"202.70400","16.89222","0.65783"
"202.95000","16.91278","0.66065"
"203.19600","16.93311","0.66327"
"203.44200","16.95374","0.66573"
"203.68800","16.97419","0.66879"
"203.93400","16.99470","0.67156"
"204.18000","17.01520","0.67355"
"204.42600","17.03577","0.67549"
"204.67200","17.05616","0.67699"
"204.91800","17.07673","0.67902"
"205.16400","17.09723","0.68125"
"205.41000","17.11774","0.68250"
"205.65600","17.13825","0.68317"
"205.90200","17.15870","0.68448"
"206.14800","17.17921","0.68530"
"206.39400","17.19965","0.68651"
"206.64000","17.22022","0.68694"
"206.88600","17.24061","0.68823"
"207.13200","17.26130","0.68877"
"207.37800","17.28169","0.69027"
"207.62400","17.30219","0.69142"
"207.87000","17.32276","0.69251"
"208.11600","17.34321","0.69405"
"208.36200","17.36372","0.69546"
"208.60800","17.38417","0.69706"
"208.85400","17.40473","0.69786"
"209.10000","17.42512","0.69890"
"209.34600","17.44569","0.69893"
"209.59200","17.46614","0.61961"
"209.83800","17.48670","0.57285"
"210.08400","17.50721","0.57380"
"210.33000","17.52772","0.57350"
"210.57600","17.54823","0.57372"
"210.82200","17.56874","0.57400"
"211.06800","17.58918","0.57398"
"211.31400","17.60969","0.57519"
"211.56000","17.63020","0.57557"
"211.80600","17.65065","0.57707"
"212.05200","17.67122","0.57780"
"212.29800","17.69166","0.57813"
"212.54400","17.71217","0.57953"
"212.79000","17.73262","0.57991"
"213.03600","17.75331","0.58136"
"213.28200","17.77363","0.58177"
"213.52800","17.79420","0.58307"
"213.77400","17.81471","0.58430"
"214.02000","17.83522","0.58505"
"214.26600","17.85573","0.58588"
"214.51200","17.87611","0.58694"
"214.75800","17.89674","0.58843"
"215.00400","17.91713","0.58951"
"215.25000","17.93770","0.59093"
"215.49600","17.95815","0.59216"
"215.74200","17.97871","0.59362"
"215.98800","17.99916","0.59547"
"216.23400","18.01973","0.59763"
"216.48000","18.04018","0.60067"
"216.72600","18.06068","0.60259"
"216.97200","18.08119","0.60539"
"217.21800","18.10170","0.31438"
"217.46400","18.12221","0.31677"
"217.71000","18.14260","0.30673"
"217.95600","18.16322","0.30774"
"218.20200","18.18373","0.30835"
"218.44800","18.20430","0.31761"
"218.69400","18.22469","0.31039"
"218.94000","18.24525","0.31273"
"219.18600","18.26576","0.31515"
"219.43200","18.28621","0.32405"
"219.67800","18.30666","0.31867"
"219.92400","18.32717","0.31962"
"220.17000","18.34773","0.32150"
"220.41600","18.36818","0.33068"
"220.66200","18.38875","0.32676"
"220.90800","18.40914","0.32882"
"221.15400","18.42971","0.33110"
"221.40000","18.45021","0.33880"
"221.64600","18.47072","0.33660"
"221.89200","18.49117","0.33723"
"222.13800","18.51168","0.33867"
"222.38400","18.53218","0.34406"
"222.63000","18.55275","0.34539"
"222.87600","18.57320","0.34402"
"223.12200","18.59365","0.34595"
"223.36800","18.61427","0.35034"
"223.61400","18.63472","0.35548"
"223.86000","18.65517","0.35404"
"224.10600","18.67562","0.35500"
"224.35200","18.69625","0.35723"
"224.59800","18.71663","0.36136"
"224.84400","18.73726","0.36272"
"225.09000","18.75771","0.36234"
"225.33600","18.77822","0.36351"
"225.58200","18.79873","0.36609"
"225.82800","18.81917","0.36934"
"226.07400","18.83980","0.37055"
"226.32000","18.86013","0.37047"
"226.56600","18.88070","0.37182"
"226.81200","18.90121","0.37381"
"227.05800","18.92177","0.37694"
"227.30400","18.94216","0.37729"
"227.55000","18.96273","0.37732"
"227.79600","18.98324","0.37900"
"228.04200","19.00368","0.38224"
"228.28800","19.02413","0.38562"
"228.53400","19.04464","0.38692"
"228.78000","19.06521","0.38758"
"229.02600","19.08566","0.38885"
"229.27200","19.10622","0.39234"
"229.51800","19.12661","0.39524"
"229.76400","19.14718","0.39774"
"230.01000","19.16769","0.39780"
"230.25600","19.18826","0.39975"
"230.50200","19.20870","0.40160"
"230.74800","19.22921","0.40403"
"230.99400","19.24972","0.40787"
"231.24000","19.27023","0.41050"
"231.48600","19.29073","0.41241"
"231.73200","19.31112","0.41463"
"231.97800","19.33175","0.41744"
"232.22400","19.35220","0.41926"
"232.47000","19.37271","0.42121"
"232.71600","19.39315","0.42314"
"232.96200","19.41372","0.42388"
"233.20800","19.43417","0.42501"
"233.45400","19.45474","0.42734"
"233.70000","19.47524","0.42930"
"233.94600","19.49569","0.43147"
"234.19200","19.51620","0.43314"
"234.43800","19.53665","0.43341"
"234.68400","19.55722","0.43513"
"234.93000","19.57754","0.43706"
"235.17600","19.59817","0.43947"
"235.42200","19.61868","0.44289"
"235.66800","19.63925","0.44489"
"235.91400","19.65964","0.44641"
"236.16000","19.68026","0.44817"
"236.40600","19.70071","0.45044"
"236.65200","19.72122","0.45385"
"236.89800","19.74173","0.45735"
"237.14400","19.76217","0.46089"
"237.39000","19.78274","0.46391"
"237.63600","19.80319","0.46580"
"237.88200","19.82376","0.46865"
"238.12800","19.84420","0.46990"
"238.37400","19.86477","0.47332"
"238.62000","19.88516","0.47592"
"238.86600","19.90579","0.47813"
"239.11200","19.92618","0.48011"
"239.35800","19.94669","0.48143"
"239.60400","19.96719","0.48280"
"239.85000","19.98770","0.48352"
"240.09600","20.00821","0.48526"
"240.34200","20.02865","0.48635"
"240.58800","20.04922","0.48734"
"240.83400","20.06967","0.48853"
"241.08000","20.09018","0.49026"
"241.32600","20.11063","0.49105"
"241.57200","20.13126","0.49288"
"241.81800","20.15164","0.49380"
"242.06400","20.17221","0.49451"
"242.31000","20.19272","0.49660"
"242.55600","20.21323","0.49788"
"242.80200","20.23367","0.49995"
"243.04800","20.25418","0.50172"
"243.29400","20.27475","0.50319"
"243.54000","20.29514","0.50575"
"243.78600","20.31565","0.50756"
"244.03200","20.33615","0.51001"
"244.27800","20.35672","0.51145"
"244.52400","20.37723","0.51378"
"244.77000","20.39774","0.51627"
"245.01600","20.41824","0.51886"
"245.26200","20.43869","0.52056"
"245.50800","20.45914","0.52143"
"245.75400","20.47971","0.48258"
"246.00000","20.50022","0.47982"
"246.24600","20.52073","0.48073"
"246.49200","20.54123","0.48129"
"246.73800","20.56162","0.48172"
"246.98400","20.58219","0.48263"
"247.23000","20.60264","0.48350"
"247.47600","20.62326","0.48452"
"247.72200","20.64365","0.48542"
"247.96800","20.66422","0.48632"
"248.21400","20.68473","0.48712"
"248.46000","20.70524","0.48800"
"248.70600","20.72574","0.48883"
"248.95200","20.74613","0.48919"
"249.19800","20.76676","0.41947"
"249.44400","20.78715","0.41750"
"249.69000","20.80778","0.41769"
"249.93600","20.82816","0.41825"
"250.18200","20.84873","0.42022"
"250.42800","20.86918","0.42098"
"250.67400","20.88969","0.42168"
"250.92000","20.91025","0.42262"
"251.16600","20.93070","0.42438"
"251.41200","20.95121","0.42607"
"251.65800","20.97172","0.42860"
"251.90400","20.99223","0.43061"
"252.15000","21.01261","0.43195"
"252.39600","21.03318","0.43349"
"252.64200","21.05369","0.43550"
"252.88800","21.07425","0.43839"
"253.13400","21.09464","0.44038"
"253.38000","21.11521","0.44217"
"253.62600","21.13566","0.44439"
"253.87200","21.15617","0.44738"
"254.11800","21.17668","0.45038"
"254.36400","21.19718","0.45407"
"254.61000","21.21775","0.45822"
"254.85600","21.23814","0.46082"
"255.10200","21.25871","0.46468"
"255.34800","21.27915","0.46661"
"255.59400","21.29966","0.46938"
"255.84000","21.32017","0.47183"
"256.08600","21.34074","0.47378"
"256.33200","21.36119","0.47577"
"256.57800","21.38175","0.47791"
"256.82400","21.40220","0.47882"
"257.07000","21.42277","0.47997"
"257.31600","21.44322","0.48116"
"257.56200","21.46367","0.48206"
"257.80800","21.48423","0.48281"
"258.05400","21.50468","0.48413"
"258.30000","21.52519","0.48499"
"258.54600","21.54570","0.48608"
"258.79200","21.56620","0.48699"
"259.03800","21.58665","0.48817"
"259.28400","21.60722","0.48773"
"259.53000","21.62773","0.07125"
"259.77600","21.64818","0.06639"
"260.02200","21.66868","0.06686"
"260.26800","21.68913","0.06198"
"260.51400","21.70976","0.06386"
"260.76000","21.73015","0.06296"
"261.00600","21.75072","0.06530"
"261.25200","21.77122","0.06801"
"261.49800","21.79173","0.06801"
"261.74400","21.81224","0.06781"
"261.99000","21.83274","0.06748"
"262.23600","21.85325","0.06745"
"262.48200","21.87370","0.07058"
"262.72800","21.89415","0.07202"
"262.97400","21.91466","0.07356"
"263.22000","21.93523","0.07250"
"263.46600","21.95567","0.07307"
"263.71200","21.97624","0.07634"
"263.95800","21.99669","0.07776"
"264.20400","22.01720","0.08029"
"264.45000","22.03770","0.08019"
"264.69600","22.05821","0.08070"
"264.94200","22.07866","0.08552"
"265.18800","22.09923","0.08517"
"265.43400","22.11973","0.09035"
"265.68000","22.14024","0.08963"
"265.92600","22.16069","0.09389"
"266.17200","22.18114","0.09429"
"266.41800","22.20177","0.09915"
"266.66400","22.22216","0.09776"
"266.91000","22.24272","0.10572"
"267.15600","22.26311","0.10261"
"267.40200","22.28374","0.10903"
"267.64800","22.30412","0.10749"
"267.89400","22.32475","0.11173"
"268.14000","22.34520","0.11208"
"268.38600","22.36571","0.11544"
"268.63200","22.38622","0.11643"
"268.87800","22.40666","0.11874"
"269.12400","22.42723","0.12098"
"269.37000","22.44762","0.12036"
"269.61600","22.46819","0.12482"
"269.86200","22.48870","0.12424"
"270.10800","22.50927","0.12681"
"270.35400","22.52971","0.12788"
"270.60000","22.55022","0.13084"
"270.84600","22.57073","0.13062"
"271.09200","22.59118","0.13270"
"271.33800","22.61168","0.13404"
"271.58400","22.63219","0.13498"
"271.83000","22.65276","0.13703"
"272.07600","22.67315","0.13741"
"272.32200","22.69372","0.13949"
"272.56800","22.71416","0.14024"
"272.81400","22.73473","0.14219"
"273.06000","22.75518","0.14408"
"273.30600","22.77575","0.14549"
"273.55200","22.79619","0.14829"
"273.79800","22.81670","0.14860"
"274.04400","22.83727","0.15095"
"274.29000","22.85772","0.15155"
"274.53600","22.87823","0.15416"
"274.78200","22.89867","0.15543"
"275.02800","22.91924","0.15606"
"275.27400","22.93969","0.15802"
"275.52000","22.96020","0.15815"
"275.76600","22.98065","0.16026"
"276.01200","23.00127","0.16120"
"276.25800","23.02166","0.16217"
"276.50400","23.04223","0.16382"
"276.75000","23.06274","0.16490"
"276.99600","23.08319","0.16640"
"277.24200","23.10375","0.08039"
"277.48800","23.12420","0.10087"
"277.73400","23.14477","0.08139"
"277.98000","23.16516","0.09686"
"278.22600","23.18572","0.08422"
"278.47200","23.20617","0.09388"
"278.71800","23.22668","0.08959"
"278.96400","23.24713","0.09296"
"279.21000","23.26776","0.09511"
"279.45600","23.28820","0.09738"
"279.70200","23.30871","0.10247"
"279.94800","23.32916","0.10199"
"280.19400","23.34966","0.10800"
"280.44000","23.37023","0.10914"
"280.68600","23.39062","0.11221"
"280.93200","23.41125","0.11154"
"281.17800","23.43170","0.11480"
"281.42400","23.45220","0.11348"
"281.67000","23.47265","0.11807"
"281.91600","23.49328","0.11854"
"282.16200","23.51373","0.12197"
"282.40800","23.53424","0.12268"
"282.65400","23.55474","0.12296"
"282.90000","23.57519","0.12680"
"283.14600","23.59570","0.12434"
"283.39200","23.61615","0.13182"
"283.63800","23.63671","0.12735"
"283.88400","23.65716","0.13517"
"284.13000","23.67773","0.13029"
"284.37600","23.69818","0.13662"
"284.62200","23.71875","0.13409"
"284.86800","23.73920","0.13858"
"285.11400","23.75970","0.13719"
"285.36000","23.78021","0.14111"
"285.60600","23.80066","0.13863"
"285.85200","23.82123","0.14517"
"286.09800","23.84167","0.14333"
"286.34400","23.86224","0.14537"
"286.59000","23.88263","0.14900"
"286.83600","23.90320","0.14666"
"287.08200","23.92370","0.15351"
"287.32800","23.94427","0.15013"
"287.57400","23.96466","0.15485"
"287.82000","23.98523","0.15437"
"288.06600","24.00574","0.15633"
"288.31200","24.02619","0.15715"
"288.55800","24.04669","0.15904"
"288.80400","24.06720","0.16029"
"289.05000","24.08777","0.16087"
"289.29600","24.10822","0.16407"
"289.54200","24.12872","0.16247"
"289.78800","24.14911","0.16608"
"290.03400","24.16974","0.16570"
"290.28000","24.19019","0.16709"
"290.52600","24.21075","0.16807"
"290.77200","24.23120","0.16827"
"291.01800","24.25171","0.16953"
"291.26400","24.27222","0.16950"
"291.51000","24.29273","0.17075"
"291.75600","24.31324","0.17079"
"292.00200","24.33362","0.17167"
"292.24800","24.35425","0.17270"
"292.49400","24.37470","0.17247"
"292.74000","24.39520","0.17371"
"292.98600","24.41566","0.17283"
"293.23200","24.43622","0.17442"
"293.47800","24.45673","0.17439"
"293.72400","24.47724","0.17495"
"293.97000","24.49769","0.17556"
"294.21600","24.51819","0.17575"
"294.46200","24.53870","0.17656"
"294.70800","24.55921","0.17699"
"294.95400","24.57972","0.17783"
"295.20000","24.60016","0.17765"
"295.44600","24.62073","0.17879"
"295.69200","24.64118","0.17954"
"295.93800","24.66175","0.17904"
"296.18400","24.68213","0.18056"
"296.43000","24.70270","0.18098"
"296.67600","24.72321","0.18142"
"296.92200","24.74372","0.18192"
"297.16800","24.76417","0.18198"
"297.41400","24.78467","0.18298"
"297.66000","24.80518","0.18365"
"297.90600","24.82569","0.18380"
"298.15200","24.84620","0.18506"
"298.39800","24.86665","0.18510"
"298.64400","24.88716","0.18570"
"298.89000","24.90760","0.18581"
"299.13600","24.92823","0.18661"
"299.38200","24.94868","0.18742"
"299.62800","24.96924","0.18718"
"299.87400","24.98975","0.18849"
"300.12000","25.01020","0.18878"
"300.36600","25.03071","0.18910"
"300.61200","25.05116","0.18884"
"300.85800","25.07173","0.19004"
"301.10400","25.09217","0.19058"
"301.35000","25.11274","0.19033"
"301.59600","25.13319","0.19118"
"301.84200","25.15376","0.19135"
"302.08800","25.17420","0.19168"
"302.33400","25.19471","0.19161"
"302.58000","25.21522","0.19189"
"302.82600","25.23567","0.19268"
"303.07200","25.25617","0.19277"
"303.31800","25.27668","0.19347"
"303.56400","25.29725","0.19418"
"303.81000","25.31764","0.19461"
"304.05600","25.33821","0.19524"
"304.30200","25.35872","0.19545"
"304.54800","25.37922","0.19543"
"304.79400","25.39973","0.19609"
"305.04000","25.42024","0.19527"
"305.28600","25.44069","0.19514"
"305.53200","25.46119","0.19445"
"305.77800","25.48164","0.19462"
"306.02400","25.50221","0.19493"
"306.27000","25.52278","0.19585"
"306.51600","25.54317","0.19561"
"306.76200","25.56373","0.19584"
"307.00800","25.58412","0.19618"
"307.25400","25.60475","0.19753"
"307.50000","25.62519","0.19752"
"307.74600","25.64577","0.19731"
"307.99200","25.66621","0.19503"
"308.23800","25.68672","0.19403"
"308.48400","25.70717","0.19415"
"308.73000","25.72773","0.19324"
"308.97600","25.74818","0.19336"
"309.22200","25.76863","0.19332"
"309.46800","25.78926","0.19374"
"309.71400","25.80971","0.19349"
"309.96000","25.83021","0.19434"
"310.20600","25.85066","0.19422"
"310.45200","25.87123","0.19489"
"310.69800","25.89168","0.19441"
"310.94400","25.91224","0.19402"
"311.19000","25.93269","0.19556"
"311.43600","25.95320","0.19499"
"311.68200","25.97371","0.19529"
"311.92800","25.99416","0.19580"
"312.17400","26.01478","0.19635"
"312.42000","26.03518","0.19684"
"312.66600","26.05574","0.19634"
"312.91200","26.07619","0.19657"
"313.15800","26.09676","0.19645"
"313.40400","26.11721","0.19670"
"313.65000","26.13771","0.19757"
"313.89600","26.15822","0.19757"
"314.14200","26.17873","0.19799"
"314.38800","26.19917","0.19844"
"314.63400","26.21968","0.19838"
"314.88000","26.24025","0.19891"
"315.12600","26.26070","0.19964"
"315.37200","26.28127","0.19866"
"315.61800","26.30166","0.19820"
"315.86400","26.32216","0.19865"
"316.11000","26.34261","0.19971"
"316.35600","26.36324","0.19932"
"316.60200","26.38369","0.19960"
"316.84800","26.40419","0.19988"
"317.09400","26.42470","0.20025"
"317.34000","26.44521","0.20022"
"317.58600","26.46572","0.20125"
"317.83200","26.48616","0.20171"
"318.07800","26.50673","0.20088"
"318.32400","26.52718","0.20066"
"318.57000","26.54775","0.20076"
"318.81600","26.56814","0.20210"
"319.06200","26.58877","0.20201"
"319.30800","26.60915","0.20252"
"319.55400","26.62972","0.20291"
"319.80000","26.65023","0.20302"
"320.04600","26.67073","0.20306"
"320.29200","26.69124","0.20279"
"320.53800","26.71169","0.20361"
"320.78400","26.73226","0.20409"
"321.03000","26.75265","0.20392"
"321.27600","26.77316","0.20477"
"321.52200","26.79366","0.20487"
"321.76800","26.81423","0.20514"
"322.01400","26.83468","0.20552"
"322.26000","26.85525","0.20600"
"322.50600","26.87575","0.20604"
"322.75200","26.89620","0.20703"
"322.99800","26.91665","0.20660"
"323.24400","26.93716","0.20756"
"323.49000","26.95773","0.20773"
"323.73600","26.97817","0.20793"
"323.98200","26.99868","0.20792"
"324.22800","27.01919","0.20849"
"324.47400","27.03970","0.20903"
"324.72000","27.06015","0.20879"
"324.96600","27.08077","0.20934"
"325.21200","27.10122","0.20979"
"325.45800","27.12173","0.21033"
"325.70400","27.14224","0.21002"
"325.95000","27.16268","0.21070"
"326.19600","27.18319","0.21019"
"326.44200","27.20364","0.21063"
"326.68800","27.22421","0.21137"
"326.93400","27.24466","0.21150"
"327.18000","27.26522","0.21149"
"327.42600","27.28567","0.21207"
"327.67200","27.30624","0.21202"
"327.91800","27.32669","0.21216"
"328.16400","27.34720","0.21323"
"328.41000","27.36770","0.21259"
"328.65600","27.38821","0.21333"
"328.90200","27.40872","0.21319"
"329.14800","27.42916","0.21365"
"329.39400","27.44973","0.21377"
"329.64000","27.47012","0.21436"
"329.88600","27.49075","0.21440"
"330.13200","27.51120","0.21452"
"330.37800","27.53176","0.21510"
"330.62400","27.55215","0.21485"
"330.87000","27.57272","0.21569"
"331.11600","27.59323","0.21616"
"331.36200","27.61368","0.21656"
"331.60800","27.63418","0.21631"
"331.85400","27.65475","0.21669"
"332.10000","27.67526","0.21711"
"332.34600","27.69565","0.21756"
"332.59200","27.71622","0.21753"
"332.83800","27.73667","0.21811"
"333.08400","27.75723","0.21821"
"333.33000","27.77774","0.21814"
"333.57600","27.79825","0.21889"
"333.82200","27.81870","0.21965"
"334.06800","27.83920","0.21918"
"334.31400","27.85971","0.21947"
"334.56000","27.88022","0.21946"
"334.80600","27.90073","0.21996"
"335.05200","27.92117","0.21999"
"335.29800","27.94174","0.22036"
"335.54400","27.96219","0.22077"
"335.79000","27.98270","0.22137"
"336.03600","28.00309","0.22109"
"336.28200","28.02377","0.22114"
"336.52800","28.04416","0.22124"
"336.77400","28.06467","0.22188"
"337.02000","28.08518","0.22222"
"337.26600","28.10569","0.22220"
"337.51200","28.12625","0.22222"
"337.75800","28.14670","0.22329"
"338.00400","28.16727","0.22342"
"338.25000","28.18765","0.22426"
"338.49600","28.20822","0.22373"
"338.74200","28.22867","0.22406"
"338.98800","28.24924","0.22457"
"339.23400","28.26969","0.22497"
"339.48000","28.29020","0.22532"
"339.72600","28.31071","0.22519"
"339.97200","28.33121","0.22557"
"340.21800","28.35166","0.22615"
"340.46400","28.37223","0.22683"
"340.71000","28.39274","0.22666"
"340.95600","28.41318","0.22620"
"341.20200","28.43369","0.22691"
"341.44800","28.45414","0.22659"
"341.69400","28.47470","0.22696"
"341.94000","28.49510","0.22750"
"342.18600","28.51578","0.22788"
"342.43200","28.53617","0.22781"
"342.67800","28.55674","0.22831"
"342.92400","28.57724","0.22724"
"343.17000","28.59769","0.22745"
"343.41600","28.61820","0.22822"
"343.66200","28.63865","0.22815"
"343.90800","28.65922","0.22777"
"344.15400","28.67966","0.22826"
"344.40000","28.70017","0.22885"
"344.64600","28.72062","0.22910"
"344.89200","28.74125","0.22915"
"345.13800","28.76170","0.22942"
"345.38400","28.78220","0.22954"
"345.63000","28.80271","0.23042"
"345.87600","28.82322","0.23047"
"346.12200","28.84373","0.23043"
"346.36800","28.86417","0.23082"
"346.61400","28.88474","0.23088"
"346.86000","28.90513","0.23021"
"347.10600","28.92570","0.23055"
"347.35200","28.94615","0.23073"
"347.59800","28.96678","0.23110"
"347.84400","28.98722","0.23039"
"348.09000","29.00779","0.23157"
"348.33600","29.02824","0.23215"
"348.58200","29.04874","0.23237"
"348.82800","29.06919","0.23255"
"349.07400","29.08964","0.23290"
"349.32000","29.11021","0.23308"
"349.56600","29.13066","0.23314"
"349.81200","29.15116","0.23345"
"350.05800","29.17161","0.23401"
"350.30400","29.19218","0.23357"
"350.55000","29.21269","0.23378"
"350.79600","29.23326","0.23473"
"351.04200","29.25370","0.23413"
"351.28800","29.27421","0.23462"
"351.53400","29.29472","0.23499"
"351.78000","29.31523","0.23534"
"352.02600","29.33567","0.23612"
"352.27200","29.35612","0.23580"
"352.51800","29.37675","0.23533"
"352.76400","29.39720","0.23593"
"353.01000","29.41771","0.23697"
"353.25600","29.43815","0.23704"
"353.50200","29.45872","0.23562"
"353.74800","29.47917","0.23647"
"353.99400","29.49974","0.23637"
"354.24000","29.52019","0.23734"
"354.48600","29.54070","0.23686"
"354.73200","29.56120","0.23801"
"354.97800","29.58171","0.23842"
"355.22400","29.60222","0.23773"
"355.47000","29.62260","0.23763"
"355.71600","29.64323","0.23741"
"355.96200","29.66368","0.23729"
"356.20800","29.68425","0.23764"
"356.45400","29.70470","0.23781"
"356.70000","29.72520","0.23754"
"356.94600","29.74571","-0.00512"
"357.19200","29.76622","-0.00806"
"357.43800","29.78667","-0.00300"
"357.68400","29.80717","-0.00354"
"357.93000","29.82768","-0.00301"
"358.17600","29.84819","-0.00198"
"358.42200","29.86876","-0.00009"
"358.66800","29.88915","-0.00225"
"358.91400","29.90971","-0.00462"
"359.16000","29.93016","-0.00400"
"359.40600","29.95073","-0.00283"
"359.65200","29.97118","-0.00101"
"359.89800","29.99169","-0.00359"
"360.14400","30.01219","-0.00370"
"360.39000","30.03270","-0.00342"
"360.63600","30.05321","-0.00023"
"360.88200","30.07366","-0.00328"
"361.12800","30.09423","-0.00407"
"361.37400","30.11467","-0.00373"
"361.62000","30.13524","-0.00052"
"361.86600","30.15569","-0.00276"
"362.11200","30.17620","-0.00424"
"362.35800","30.19664","-0.00348"
"362.60400","30.21715","-0.00133"
"362.72400","30.22720","-0.00119"