File: Force_trajectories/170107_1/Specimen_RawData_2.csv
End date,"1/7/2017"
Specimen label,"18CT_NT1"
Maximum Load,"0.01610",N

Time,Extension,Load
(s),(mm),(N)
"0.00000","0.00000","0.00005"
"0.42000","0.03528","-0.00016"
"0.84000","0.07019","-0.00062"
"1.26000","0.10523","-0.00005"
"1.68000","0.14021","-0.00001"
"2.10000","0.17524","0.00039"
"2.52000","0.21022","0.00057"
"2.94000","0.24520","0.00054"
"3.36000","0.28023","0.00066"
"3.78000","0.31521","0.00043"
"4.20000","0.35019","0.00090"
"4.62000","0.38516","0.00086"
"5.04000","0.42014","0.00092"
"5.46000","0.45518","0.00042"
"5.88000","0.49021","0.00074"
"6.30000","0.52513","0.00099"
"6.72000","0.56017","0.00096"
"7.14000","0.59515","0.00134"
"7.56000","0.63018","0.00093"
"7.98000","0.66516","0.00077"
"8.40000","0.70014","0.00130"
"8.82000","0.73523","0.00116"
"9.24000","0.77021","0.00146"
"9.66000","0.80519","0.00077"
"10.08000","0.84016","0.00143"
"10.50000","0.87514","0.00169"
"10.92000","0.91018","0.00126"
"11.34000","0.94521","0.00151"
"11.76000","0.98019","0.00144"
"12.18000","1.01517","0.00167"
"12.60000","1.05014","0.00086"
"13.02000","1.08518","0.00054"
"13.44000","1.12022","0.00021"
"13.86000","1.15519","0.00023"
"14.28000","1.19017","0.00045"
"14.70000","1.22521","0.00018"
"15.12000","1.26018","0.00044"
"15.54000","1.29522","0.00064"
"15.96000","1.33014","0.00025"
"16.38000","1.36511","0.00019"
"16.80000","1.40021","-0.00032"
"17.22000","1.43519","-0.00007"
"17.64000","1.47016","0.00046"
"18.06000","1.50514","0.00053"
"18.48000","1.54018","0.00047"
"18.90000","1.57522","0.00039"
"19.32000","1.61019","0.00005"
"19.74000","1.64517","-0.00011"
"20.16000","1.68021","0.00008"
"20.58000","1.71524","0.00071"
"21.00000","1.75022","0.00021"
"21.42000","1.78514","0.00024"
"21.84000","1.82011","-0.00029"
"22.26000","1.85515","0.00051"
"22.68000","1.89019","0.00043"
"23.10000","1.92522","0.00027"
"23.52000","1.96014","0.00046"
"23.94000","1.99512","0.00029"
"24.36000","2.03021","0.00044"
"24.78000","2.06519","0.00043"
"25.20000","2.10017","0.00088"
"25.62000","2.13514","0.00067"
"26.04000","2.17024","0.00085"
"26.46000","2.20522","0.00112"
"26.88000","2.24019","0.00058"
"27.30000","2.27517","0.00042"
"27.72000","2.31015","0.00060"
"28.14000","2.34518","0.00075"
"28.56000","2.38022","0.00051"
"28.98000","2.41520","0.00016"
"29.40000","2.45012","0.00057"
"29.82000","2.48515","0.00092"
"30.24000","2.52025","0.00113"
"30.66000","2.55523","0.00059"
"31.08000","2.59014","0.00101"
"31.50000","2.62518","0.00039"
"31.92000","2.66022","0.00093"
"32.34000","2.69519","0.00068"
"32.76000","2.73017","0.00119"
"33.18000","2.76509","0.00086"
"33.60000","2.80012","0.00173"
"34.02000","2.83522","0.00057"
"34.44000","2.87020","0.00104"
"34.86000","2.90517","0.00109"
"35.28000","2.94015","0.00122"
"35.70000","2.97519","0.00114"
"36.12000","3.01022","0.00144"
"36.54000","3.04520","0.00097"
"36.96000","3.08018","0.00064"
"37.38000","3.11515","0.00142"
"37.80000","3.15025","0.00083"
"38.22000","3.18523","0.00108"
"38.64000","3.22014","0.00142"
"39.06000","3.25512","0.00107"
"39.48000","3.29016","0.00106"
"39.90000","3.32520","0.00143"
"40.32000","3.36023","0.00125"
"40.74000","3.39515","0.00077"
"41.16000","3.43019","0.00102"
"41.58000","3.46516","0.00122"
"42.00000","3.50020","0.00114"
"42.42000","3.53518","0.00119"
"42.84000","3.57015","0.00098"
"43.26000","3.60525","0.00157"
"43.68000","3.64023","0.00145"
"44.10000","3.67520","0.00097"
"44.52000","3.71018","0.00120"
"44.94000","3.74516","0.00150"
"45.36000","3.78019","0.00155"
"45.78000","3.81517","0.00111"
"46.20000","3.85015","0.00135"
"46.62000","3.88512","0.00115"
"47.04000","3.92016","0.00135"
"47.46000","3.95520","0.00153"
"47.88000","3.99023","0.00138"
"48.30000","4.02515","0.00159"
"48.72000","4.06019","0.00101"
"49.14000","4.09516","0.00172"
"49.56000","4.13020","0.00153"
"49.98000","4.16518","0.00153"
"50.40000","4.20009","0.00153"
"50.82000","4.23513","0.00190"
"51.24000","4.27017","0.00152"
"51.66000","4.30521","0.00142"
"52.08000","4.34018","0.00158"
"52.50000","4.37510","0.00208"
"52.92000","4.41020","0.00171"
"53.34000","4.44523","0.00179"
"53.76000","4.48021","0.00150"
"54.18000","4.51525","0.00124"
"54.60000","4.55016","0.00154"
"55.02000","4.58520","0.00219"
"55.44000","4.62018","0.00186"
"55.86000","4.65515","0.00152"
"56.28000","4.69013","0.00165"
"56.70000","4.72517","0.00175"
"57.12000","4.76020","0.00201"
"57.54000","4.79518","0.00183"
"57.96000","4.83010","0.00189"
"58.38000","4.86519","0.00163"
"58.80000","4.90017","0.00173"
"59.22000","4.93515","0.00181"
"59.64000","4.97018","0.00185"
"60.06000","5.00516","0.00214"
"60.48000","5.04020","0.00157"
"60.90000","5.07523","0.00183"
"61.32000","5.11021","0.00196"
"61.74000","5.14519","0.00241"
"62.16000","5.18011","0.00151"
"62.58000","5.21520","0.00190"
"63.00000","5.25018","0.00193"
"63.42000","5.28516","0.00241"
"63.84000","5.32013","0.00158"
"64.26000","5.35517","0.00206"
"64.68000","5.39021","0.00257"
"65.10000","5.42518","0.00195"
"65.52000","5.46022","0.00201"
"65.94000","5.49520","0.00239"
"66.36000","5.53023","0.00212"
"66.78000","5.56521","0.00194"
"67.20000","5.60019","0.00208"
"67.62000","5.63510","0.00193"
"68.04000","5.67014","0.00206"
"68.46000","5.70518","0.00238"
"68.88000","5.74021","0.00217"
"69.30000","5.77519","0.00155"
"69.72000","5.81011","0.00172"
"70.14000","5.84520","0.00259"
"70.56000","5.88018","0.00247"
"70.98000","5.91522","0.00224"
"71.40000","5.95014","0.00191"
"71.82000","5.98511","0.00201"
"72.24000","6.02021","0.00220"
"72.66000","6.05518","0.00225"
"73.08000","6.09016","0.00291"
"73.50000","6.12514","0.00253"
"73.92000","6.16017","0.00230"
"74.34000","6.19515","0.00273"
"74.76000","6.23019","0.00252"
"75.18000","6.26511","0.00215"
"75.60000","6.30014","0.00262"
"76.02000","6.33518","0.00222"
"76.44000","6.37022","0.00210"
"76.86000","6.40519","0.00231"
"77.28000","6.44017","0.00252"
"77.70000","6.47521","0.00187"
"78.12000","6.51018","0.00180"
"78.54000","6.54522","0.00216"
"78.96000","6.58014","0.00212"
"79.38000","6.61511","0.00241"
"79.80000","6.65015","0.00202"
"80.22000","6.68525","0.00163"
"80.64000","6.72016","0.00253"
"81.06000","6.75508","0.00199"
"81.48000","6.79018","0.00172"
"81.90000","6.82521","0.00103"
"82.32000","6.86019","0.00153"
"82.74000","6.89517","0.00161"
"83.16000","6.93020","0.00154"
"83.58000","6.96524","0.00207"
"84.00000","7.00022","0.00193"
"84.42000","7.03525","0.00177"
"84.84000","7.07011","0.00178"
"85.26000","7.10515","0.00246"
"85.68000","7.14025","0.00190"
"86.10000","7.17516","0.00206"
"86.52000","7.21014","0.00185"
"86.94000","7.24506","0.00176"
"87.36000","7.28015","0.00184"
"87.78000","7.31519","0.00214"
"88.20000","7.35023","0.00238"
"88.62000","7.38520","0.00193"
"89.04000","7.42012","0.00233"
"89.46000","7.45522","0.00173"
"89.88000","7.49019","0.00241"
"90.30000","7.52517","0.00185"
"90.72000","7.56015","0.00203"
"91.14000","7.59518","0.00207"
"91.56000","7.63022","0.00272"
"91.98000","7.66526","0.00234"
"92.40000","7.70018","0.00255"
"92.82000","7.73515","0.00233"
"93.24000","7.77013","0.00216"
"93.66000","7.80517","0.00220"
"94.08000","7.84020","0.00211"
"94.50000","7.87518","0.00259"
"94.92000","7.91021","0.00258"
"95.34000","7.94519","0.00225"
"95.76000","7.98023","0.00251"
"96.18000","8.01515","0.00240"
"96.60000","8.05012","0.00258"
"97.02000","8.08522","0.00241"
"97.44000","8.12020","0.00268"
"97.86000","8.15517","0.00262"
"98.28000","8.19015","0.00294"
"98.70000","8.22519","0.00268"
"99.12000","8.26022","0.00267"
"99.54000","8.29514","0.00267"
"99.96000","8.33018","0.00225"
"100.38000","8.36515","0.00194"
"100.80000","8.40013","0.00229"
"101.22000","8.43517","0.00250"
"101.64000","8.47020","0.00149"
"102.06000","8.50512","0.00144"
"102.48000","8.54010","0.00087"
"102.90000","8.57519","0.00128"
"103.32000","8.61017","0.00109"
"103.74000","8.64515","0.00156"
"104.16000","8.68013","0.00091"
"104.58000","8.71522","0.00146"
"105.00000","8.75020","0.00116"
"105.42000","8.78523","0.00156"
"105.84000","8.82021","0.00131"
"106.26000","8.85519","0.00165"
"106.68000","8.89023","0.00170"
"107.10000","8.92520","0.00099"
"107.52000","8.96018","0.00082"
"107.94000","8.99516","0.00082"
"108.36000","9.03019","0.00159"
"108.78000","9.06523","0.00088"
"109.20000","9.10021","0.00148"
"109.62000","9.13518","0.00130"
"110.04000","9.17016","0.00081"
"110.46000","9.20520","0.00139"
"110.88000","9.24017","0.00103"
"111.30000","9.27521","0.00118"
"111.72000","9.31013","0.00115"
"112.14000","9.34522","0.00148"
"112.56000","9.38020","0.00132"
"112.98000","9.41524","0.00095"
"113.40000","9.45015","0.00123"
"113.82000","9.48519","0.00143"
"114.24000","9.52017","0.00111"
"114.66000","9.55520","0.00127"
"115.08000","9.59018","0.00180"
"115.50000","9.62516","0.00143"
"115.92000","9.66019","0.00172"
"116.34000","9.69523","0.00224"
"116.76000","9.73021","0.00203"
"117.18000","9.76519","0.00189"
"117.60000","9.80016","0.00194"
"118.02000","9.83520","0.00172"
"118.44000","9.87024","0.00209"
"118.86000","9.90515","0.00241"
"119.28000","9.94013","0.00245"
"119.70000","9.97517","0.00215"
"120.12000","10.01020","0.00226"
"120.54000","10.04518","0.00235"
"120.96000","10.08016","0.00242"
"121.38000","10.11507","0.00274"
"121.80000","10.15023","0.00237"
"122.22000","10.18521","0.00213"
"122.64000","10.22024","0.00207"
"123.06000","10.25516","0.00253"
"123.48000","10.29020","0.00224"
"123.90000","10.32523","0.00283"
"124.32000","10.36021","0.00241"
"124.74000","10.39519","0.00187"
"125.16000","10.43011","0.00233"
"125.58000","10.46514","0.00203"
"126.00000","10.50024","0.00212"
"126.42000","10.53515","0.00258"
"126.84000","10.57013","0.00275"
"127.26000","10.60517","0.00266"
"127.68000","10.64020","0.00275"
"128.10000","10.67518","0.00279"
"128.52000","10.71016","0.00367"
"128.94000","10.74514","0.00263"
"129.36000","10.78017","0.00244"
"129.78000","10.81521","0.00296"
"130.20000","10.85025","0.00290"
"130.62000","10.88516","0.00347"
"131.04000","10.92014","0.00390"
"131.46000","10.95518","0.00375"
"131.88000","10.99015","0.00358"
"132.30000","11.02513","0.00455"
"132.72000","11.06011","0.00434"
"133.14000","11.09520","0.00426"
"133.56000","11.13024","0.00126"
"133.98000","11.16516","0.00185"
"134.40000","11.20019","0.00201"
"134.82000","11.23517","0.00236"
"135.24000","11.27021","0.00188"
"135.66000","11.30524","0.00181"
"136.08000","11.34022","0.00241"
"136.50000","11.37508","0.00193"
"136.92000","11.41012","0.00221"
"137.34000","11.44521","0.00243"
"137.76000","11.48019","0.00233"
"138.18000","11.51517","0.00227"
"138.60000","11.55014","0.00261"
"139.02000","11.58518","0.00294"
"139.44000","11.62022","0.00297"
"139.86000","11.65525","0.00299"
"140.28000","11.69017","0.00238"
"140.70000","11.72515","0.00256"
"141.12000","11.76024","0.00338"
"141.54000","11.79522","0.00334"
"141.96000","11.83020","0.00360"
"142.38000","11.86517","0.00303"
"142.80000","11.90021","0.00331"
"143.22000","11.93519","0.00332"
"143.64000","11.97016","0.00374"
"144.06000","12.00508","0.00395"
"144.48000","12.04012","0.00302"
"144.90000","12.07515","0.00345"
"145.32000","12.11019","0.00365"
"145.74000","12.14517","0.00412"
"146.16000","12.18014","0.00403"
"146.58000","12.21518","0.00434"
"147.00000","12.25022","0.00416"
"147.42000","12.28525","0.00423"
"147.84000","12.32017","0.00423"
"148.26000","12.35515","0.00448"
"148.68000","12.39019","0.00473"
"149.10000","12.42522","0.00475"
"149.52000","12.46014","0.00545"
"149.94000","12.49512","0.00331"
"150.36000","12.53015","0.00276"
"150.78000","12.56525","0.00324"
"151.20000","12.60017","0.00289"
"151.62000","12.63520","0.00362"
"152.04000","12.67018","0.00344"
"152.46000","12.70516","0.00408"
"152.88000","12.74019","0.00483"
"153.30000","12.77517","0.00343"
"153.72000","12.81015","0.00213"
"154.14000","12.84518","0.00118"
"154.56000","12.88016","0.00053"
"154.98000","12.91520","0.00051"
"155.40000","12.95017","0.00071"
"155.82000","12.98515","0.00087"
"156.24000","13.02019","0.00048"
"156.66000","13.05516","0.00138"
"157.08000","13.09020","0.00123"
"157.50000","13.12512","0.00211"
"157.92000","13.16016","0.00148"
"158.34000","13.19525","0.00169"
"158.76000","13.23023","0.00177"
"159.18000","13.26515","0.00187"
"159.60000","13.30012","0.00188"
"160.02000","13.33516","0.00179"
"160.44000","13.37020","0.00156"
"160.86000","13.40517","0.00078"
"161.28000","13.44015","0.00133"
"161.70000","13.47519","0.00129"
"162.12000","13.51016","0.00123"
"162.54000","13.54520","0.00149"
"162.96000","13.58018","0.00151"
"163.38000","13.61515","0.00131"
"163.80000","13.65019","0.00133"
"164.22000","13.68517","0.00150"
"164.64000","13.72020","0.00148"
"165.06000","13.75518","0.00165"
"165.48000","13.79016","0.00150"
"165.90000","13.82519","0.00211"
"166.32000","13.86017","0.00213"
"166.74000","13.89521","0.00163"
"167.16000","13.93013","0.00195"
"167.58000","13.96516","0.00212"
"168.00000","14.00020","0.00180"
"168.42000","14.03524","0.00229"
"168.84000","14.07015","0.00217"
"169.26000","14.10513","0.00228"
"169.68000","14.14016","0.00262"
"170.10000","14.17520","0.00187"
"170.52000","14.21018","0.00226"
"170.94000","14.24516","0.00236"
"171.36000","14.28013","0.00216"
"171.78000","14.31523","0.00283"
"172.20000","14.35021","0.00256"
"172.62000","14.38518","0.00281"
"173.04000","14.42016","0.00226"
"173.46000","14.45520","0.00220"
"173.88000","14.49017","0.00285"
"174.30000","14.52521","0.00275"
"174.72000","14.56013","0.00274"
"175.14000","14.59516","0.00306"
"175.56000","14.63026","0.00322"
"175.98000","14.66524","0.00273"
"176.40000","14.70021","0.00245"
"176.82000","14.73513","0.00320"
"177.24000","14.77017","0.00335"
"177.66000","14.80520","0.00317"
"178.08000","14.84018","0.00302"
"178.50000","14.87516","0.00308"
"178.92000","14.91013","0.00339"
"179.34000","14.94517","0.00297"
"179.76000","14.98021","0.00371"
"180.18000","15.01518","0.00396"
"180.60000","15.05010","0.00403"
"181.02000","15.08520","0.00400"
"181.44000","15.12024","0.00333"
"181.86000","15.15521","0.00457"
"182.28000","15.19013","0.00398"
"182.70000","15.22511","0.00391"
"183.12000","15.26014","0.00400"
"183.54000","15.29518","0.00433"
"183.96000","15.33016","0.00412"
"184.38000","15.36513","0.00431"
"184.80000","15.40017","0.00431"
"185.22000","15.43527","0.00439"
"185.64000","15.47018","0.00427"
"186.06000","15.50516","0.00387"
"186.48000","15.54020","0.00500"
"186.90000","15.57523","0.00447"
"187.32000","15.61021","0.00411"
"187.74000","15.64519","0.00428"
"188.16000","15.68010","0.00424"
"188.58000","15.71514","0.00476"
"189.00000","15.75018","0.00512"
"189.42000","15.78521","0.00484"
"189.84000","15.82019","0.00528"
"190.26000","15.85517","0.00526"
"190.68000","15.89020","0.00528"
"191.10000","15.92518","0.00571"
"191.52000","15.96022","0.00564"
"191.94000","15.99520","0.00528"
"192.36000","16.03017","0.00549"
"192.78000","16.06521","0.00583"
"193.20000","16.10024","0.00595"
"193.62000","16.13516","0.00654"
"194.04000","16.17014","0.00607"
"194.46000","16.20518","0.00633"
"194.88000","16.24015","0.00621"
"195.30000","16.27519","0.00674"
"195.72000","16.31010","0.00630"
"196.14000","16.34514","0.00650"
"196.56000","16.38018","0.00643"
"196.98000","16.41522","0.00716"
"197.40000","16.45013","0.00680"
"197.82000","16.48511","0.00729"
"198.24000","16.52021","0.00704"
"198.66000","16.55524","0.00753"
"199.08000","16.59022","0.00761"
"199.50000","16.62514","0.00733"
"199.92000","16.66017","0.00756"
"200.34000","16.69521","0.00690"
"200.76000","16.73019","0.00713"
"201.18000","16.76516","0.00810"
"201.60000","16.80014","0.00690"
"202.02000","16.83518","0.00784"
"202.44000","16.87021","0.00833"
"202.86000","16.90519","0.00888"
"203.28000","16.94017","0.00836"
"203.70000","16.97520","0.00858"
"204.12000","17.01024","0.00865"
"204.54000","17.04522","0.00847"
"204.96000","17.08019","0.00838"
"205.38000","17.11511","0.00845"
"205.80000","17.15009","0.00906"
"206.22000","17.18518","0.00887"
"206.64000","17.22016","0.00901"
"207.06000","17.25520","0.00927"
"207.48000","17.29012","0.00914"
"207.90000","17.32521","0.00915"
"208.32000","17.36019","0.00848"
"208.74000","17.39523","0.00936"
"209.16000","17.43014","0.00968"
"209.58000","17.46512","0.00989"
"210.00000","17.50028","0.00997"
"210.42000","17.53519","0.01024"
"210.84000","17.57017","0.01035"
"211.26000","17.60515","0.01097"
"211.68000","17.64018","0.01157"
"212.10000","17.67516","0.01119"
"212.52000","17.71020","0.01035"
"212.94000","17.74517","0.01073"
"213.36000","17.78021","0.01047"
"213.78000","17.81519","0.01073"
"214.20000","17.85016","0.01115"
"214.62000","17.88514","0.01122"
"215.04000","17.92018","0.01157"
"215.46000","17.95522","0.01214"
"215.88000","17.99025","0.01103"
"216.30000","18.02523","0.00507"
"216.72000","18.06015","0.00471"
"217.14000","18.09518","0.00509"
"217.56000","18.13016","0.00564"
"217.98000","18.16520","0.00617"
"218.40000","18.20017","0.00682"
"218.82000","18.23509","0.00683"
"219.24000","18.27019","0.00670"
"219.66000","18.30522","0.00740"
"220.08000","18.34020","0.00785"
"220.50000","18.37518","0.00730"
"220.92000","18.41015","0.00777"
"221.34000","18.44519","0.00810"
"221.76000","18.48029","0.00921"
"222.18000","18.51521","0.00911"
"222.60000","18.55018","0.00902"
"223.02000","18.58516","0.00920"
"223.44000","18.62020","0.00946"
"223.86000","18.65511","0.00972"
"224.28000","18.69015","0.00930"
"224.70000","18.72512","0.01019"
"225.12000","18.76016","0.01005"
"225.54000","18.79526","0.01035"
"225.96000","18.83024","0.01030"
"226.38000","18.86515","0.01068"
"226.80000","18.90013","0.01145"
"227.22000","18.93523","0.01120"
"227.64000","18.97026","0.01112"
"228.06000","19.00518","0.01221"
"228.48000","19.04016","0.01235"
"228.90000","19.07519","0.01216"
"229.32000","19.11017","0.01216"
"229.74000","19.14521","0.01294"
"230.16000","19.18012","0.01247"
"230.58000","19.21516","0.01270"
"231.00000","19.25014","0.01310"
"231.42000","19.28517","0.01267"
"231.84000","19.32021","0.01430"
"232.26000","19.35519","0.01428"
"232.68000","19.39022","0.01471"
"233.10000","19.42520","0.01465"
"233.52000","19.46024","0.01488"
"233.94000","19.49515","0.01532"
"234.36000","19.53013","0.01576"
"234.78000","19.56517","0.01569"
"235.20000","19.60020","0.01064"
"235.62000","19.63518","0.01111"
"236.04000","19.67010","0.01194"
"236.46000","19.70514","0.01128"
"236.88000","19.74023","0.01139"
"237.30000","19.77521","0.01175"
"237.72000","19.81018","0.01162"
"238.14000","19.84510","0.01161"
"238.56000","19.88020","0.00312"
"238.98000","19.91524","0.00256"
"239.40000","19.95021","0.00382"
"239.82000","19.98513","0.00296"
"240.24000","20.02011","0.00422"
"240.66000","20.05520","0.00380"
"241.08000","20.09018","0.00404"
"241.50000","20.12522","0.00355"
"241.92000","20.16014","0.00463"
"242.34000","20.19517","0.00357"
"242.76000","20.23021","0.00435"
"243.18000","20.26524","0.00463"
"243.60000","20.30016","0.00458"
"244.02000","20.33514","0.00473"
"244.44000","20.37023","0.00492"
"244.86000","20.40521","0.00460"
"245.28000","20.44013","0.00516"
"245.70000","20.47511","0.00491"
"246.12000","20.51014","0.00453"
"246.54000","20.54512","0.00459"
"246.96000","20.58015","0.00492"
"247.38000","20.61519","0.00503"
"247.80000","20.65017","0.00462"
"248.22000","20.68521","0.00523"
"248.64000","20.72018","0.00496"
"249.06000","20.75516","0.00502"
"249.48000","20.79014","0.00549"
"249.90000","20.82523","0.00530"
"250.32000","20.86021","0.00480"
"250.74000","20.89519","0.00523"
"251.16000","20.93016","0.00529"
"251.58000","20.96514","0.00568"
"252.00000","21.00018","0.00547"
"252.42000","21.03521","0.00607"
"252.84000","21.07013","0.00520"
"253.26000","21.10511","0.00571"
"253.68000","21.14014","0.00580"
"254.10000","21.17524","0.00627"
"254.52000","21.21016","0.00554"
"254.94000","21.24513","0.00586"
"255.36000","21.28017","0.00610"
"255.78000","21.31521","0.00610"
"256.20000","21.35024","0.00679"
"256.62000","21.38522","0.00625"
"257.04000","21.42014","0.00624"
"257.46000","21.45518","0.00672"
"257.88000","21.49021","0.00606"
"258.30000","21.52519","0.00682"
"258.72000","21.56023","0.00557"
"259.14000","21.59508","0.00518"
"259.56000","21.63018","0.00599"
"259.98000","21.66521","0.00563"
"260.40000","21.70019","0.00637"
"260.82000","21.73517","0.00652"
"261.24000","21.77015","0.00636"
"261.66000","21.80524","0.00693"
"262.08000","21.84022","0.00648"
"262.50000","21.87519","0.00718"
"262.92000","21.91011","0.00724"
"263.34000","21.94515","0.00697"
"263.76000","21.98018","0.00694"
"264.18000","22.01516","0.00672"
"264.60000","22.05014","0.00730"
"265.02000","22.08518","0.00615"
"265.44000","22.12016","0.00696"
"265.86000","22.15519","0.00734"
"266.28000","22.19017","0.00740"
"266.70000","22.22515","0.00691"
"267.12000","22.26018","0.00690"
"267.54000","22.29522","0.00751"
"267.96000","22.33025","0.00686"
"268.38000","22.36517","0.00788"
"268.80000","22.40015","0.00840"
"269.22000","22.43519","0.00740"
"269.64000","22.47022","0.00820"
"270.06000","22.50520","0.00815"
"270.48000","22.54018","0.00832"
"270.90000","22.57515","0.00829"
"271.32000","22.61025","0.00853"
"271.74000","22.64517","0.00887"
"272.16000","22.68014","0.00835"
"272.58000","22.71512","0.00849"
"273.00000","22.75022","0.00798"
"273.42000","22.78519","0.00860"
"273.84000","22.82023","0.00919"
"274.26000","22.85515","0.00929"
"274.68000","22.89012","0.00930"
"275.10000","22.92522","0.00935"
"275.52000","22.96020","0.00945"
"275.94000","22.99517","0.00901"
"276.36000","23.03009","0.00907"
"276.78000","23.06519","0.00961"
"277.20000","23.10023","0.00891"
"277.62000","23.13520","0.00919"
"278.04000","23.17018","0.00927"
"278.46000","23.20515","0.00977"
"278.88000","23.24025","0.00957"
"279.30000","23.27523","0.00483"
"279.72000","23.31021","0.00404"
"280.14000","23.34512","0.00517"
"280.56000","23.38016","0.00475"
"280.98000","23.41520","0.00434"
"281.40000","23.45023","0.00422"
"281.82000","23.48515","0.00466"
"282.24000","23.52019","0.00542"
"282.66000","23.55516","0.00510"
"283.08000","23.59014","0.00471"
"283.50000","23.62518","0.00513"
"283.92000","23.66015","0.00539"
"284.34000","23.69519","0.00610"
"284.76000","23.73017","0.00583"
"285.18000","23.76526","0.00581"
"285.60000","23.80018","0.00630"
"286.02000","23.83516","0.00638"
"286.44000","23.87019","0.00583"
"286.86000","23.90517","0.00556"
"287.28000","23.94015","0.00582"
"287.70000","23.97512","0.00654"
"288.12000","24.01016","0.00587"
"288.54000","24.04520","0.00672"
"288.96000","24.08017","0.00668"
"289.38000","24.11515","0.00654"
"289.80000","24.15019","0.00714"
"290.22000","24.18522","0.00657"
"290.64000","24.22020","0.00710"
"291.06000","24.25518","0.00680"
"291.48000","24.29016","0.00691"
"291.90000","24.32513","0.00758"
"292.32000","24.36017","0.00724"
"292.74000","24.39515","0.00705"
"293.16000","24.43018","0.00771"
"293.58000","24.46510","0.00756"
"294.00000","24.50019","0.00805"
"294.42000","24.53523","0.00792"
"294.84000","24.57021","0.00743"
"295.26000","24.60513","0.00799"
"295.68000","24.64017","0.00796"
"296.10000","24.67526","0.00837"
"296.52000","24.71024","0.00790"
"296.94000","24.74516","0.00873"
"297.36000","24.78013","0.00897"
"297.78000","24.81517","0.00990"
"298.20000","24.85020","0.00924"
"298.62000","24.88524","0.00963"
"299.04000","24.92016","0.00896"
"299.46000","24.95520","0.00966"
"299.88000","24.99011","0.00931"
"300.30000","25.02521","0.00944"
"300.72000","25.06019","0.01004"
"301.14000","25.09516","0.00982"
"301.56000","25.13020","0.00963"
"301.98000","25.16523","0.00933"
"302.40000","25.20021","0.00978"
"302.82000","25.23519","0.00998"
"303.24000","25.27016","0.01048"
"303.66000","25.30520","0.00994"
"304.08000","25.34018","0.01056"
"304.50000","25.37516","0.01067"
"304.92000","25.41013","0.01132"
"305.34000","25.44517","0.01076"
"305.76000","25.48021","0.01118"
"306.18000","25.51518","0.01096"
"306.60000","25.55016","0.01136"
"307.02000","25.58520","0.01098"
"307.44000","25.62017","0.01158"
"307.86000","25.65521","0.01177"
"308.28000","25.69019","0.01198"
"308.70000","25.72510","0.01176"
"309.12000","25.76014","0.01179"
"309.54000","25.79518","0.01204"
"309.96000","25.83015","0.01194"
"310.38000","25.86513","0.01132"
"310.80000","25.90005","0.01171"
"311.22000","25.93521","0.01163"
"311.64000","25.97024","0.01119"
"312.06000","26.00522","0.01095"
"312.48000","26.04020","0.01140"
"312.90000","26.07517","0.01128"
"313.32000","26.11027","0.01071"
"313.74000","26.14524","0.00970"
"314.16000","26.18016","0.01014"
"314.58000","26.21514","0.01036"
"315.00000","26.25018","0.01073"
"315.42000","26.28521","0.01029"
"315.84000","26.32019","0.01056"
"316.26000","26.35511","0.01145"
"316.68000","26.39014","0.01122"
"317.10000","26.42512","0.01112"
"317.52000","26.46016","0.01184"
"317.94000","26.49519","0.01208"
"318.36000","26.53017","0.01255"
"318.78000","26.56521","0.01225"
"319.20000","26.60018","0.01290"
"319.62000","26.63522","0.01297"
"320.04000","26.67020","0.01303"
"320.46000","26.70512","0.01311"
"320.88000","26.74015","0.01370"
"321.30000","26.77519","0.01364"
"321.72000","26.81017","0.01370"
"322.14000","26.84508","0.01394"
"322.56000","26.88018","0.01239"
"322.98000","26.91521","0.01144"
"323.40000","26.95019","0.01128"
"323.82000","26.98517","0.01039"
"324.24000","27.02015","0.01060"
"324.66000","27.05518","0.01084"
"325.08000","27.09022","0.01079"
"325.50000","27.12520","0.01134"
"325.92000","27.16011","0.01153"
"326.34000","27.19515","0.01123"
"326.76000","27.23025","0.01173"
"327.18000","27.26522","0.01155"
"327.60000","27.30014","0.01209"
"328.02000","27.33512","0.01203"
"328.44000","27.37016","0.01178"
"328.86000","27.40519","0.01140"
"329.28000","27.44023","0.01223"
"329.70000","27.47514","0.01155"
"330.12000","27.51012","0.01163"
"330.54000","27.54522","0.01150"
"330.96000","27.58020","0.01160"
"331.38000","27.61517","0.01164"
"331.80000","27.65015","0.01136"
"332.22000","27.68513","0.01048"
"332.64000","27.72016","0.01105"
"333.06000","27.75520","0.01110"
"333.48000","27.79012","0.01152"
"333.90000","27.82515","0.01111"
"334.32000","27.86019","0.01204"
"334.74000","27.89517","0.01212"
"335.16000","27.93020","0.01236"
"335.58000","27.96512","0.01265"
"336.00000","28.00016","0.01261"
"336.42000","28.03519","0.01290"
"336.84000","28.07023","0.01306"
"337.26000","28.10514","0.01245"
"337.68000","28.14012","0.01245"
"338.10000","28.17516","0.01209"
"338.52000","28.21020","0.01263"
"338.94000","28.24517","0.01254"
"339.36000","28.28009","0.01169"
"339.78000","28.31513","0.01140"
"340.20000","28.35022","0.01221"
"340.62000","28.38520","0.01177"
"341.04000","28.42018","0.00892"
"341.46000","28.45515","0.00948"
"341.88000","28.49019","0.00891"
"342.30000","28.52523","0.00896"
"342.72000","28.56021","0.00876"
"343.14000","28.59512","0.01042"
"343.56000","28.63016","0.00971"
"343.98000","28.66520","0.01090"
"344.40000","28.70017","0.01046"
"344.82000","28.73515","0.01145"
"345.24000","28.77007","0.01188"
"345.66000","28.80516","0.01207"
"346.08000","28.84020","0.01257"
"346.50000","28.87518","0.01219"
"346.92000","28.91021","0.01249"
"347.34000","28.94513","0.01322"
"347.76000","28.98022","0.01354"
"348.18000","29.01520","0.01363"
"348.60000","29.05018","0.01420"
"349.02000","29.08516","0.01396"
"349.44000","29.12019","0.01472"
"349.86000","29.15523","0.01318"
"350.28000","29.19021","0.01238"
"350.70000","29.22513","0.01470"
"351.12000","29.26016","0.01357"
"351.54000","29.29520","0.01464"
"351.96000","29.33023","0.01412"
"352.38000","29.36515","0.01170"
"352.80000","29.40019","0.01235"
"353.22000","29.43522","0.01329"
"353.64000","29.47020","0.01318"
"354.06000","29.50524","0.01181"
"354.48000","29.54016","0.01055"
"354.90000","29.57513","0.01067"
"355.32000","29.61017","0.01033"
"355.74000","29.64521","0.01008"
"356.16000","29.68018","0.01018"
"356.58000","29.71510","0.01014"
"357.00000","29.75014","0.01076"
"357.42000","29.78523","0.01056"
"357.84000","29.82015","0.01111"
"358.26000","29.85519","0.01084"
"358.68000","29.89017","0.01140"
"359.10000","29.92514","0.01222"
"359.52000","29.96018","0.01219"
"359.94000","29.99521","0.01234"
"360.36000","30.03013","0.01224"
"360.78000","30.06517","0.01206"
"361.20000","30.10021","0.01184"
"361.62000","30.13518","0.01203"
"362.04000","30.17016","0.01236"
"362.46000","30.20514","0.01206"
"362.88000","30.24023","0.01214"
"363.30000","30.27521","0.01217"
"363.72000","30.31025","0.01210"
"364.14000","30.34522","0.01185"
"364.56000","30.38020","0.01140"
"364.98000","30.41524","0.01180"
"365.40000","30.45021","0.01139"
"365.82000","30.48519","0.01128"
"366.24000","30.52017","0.01185"
"366.66000","30.55520","0.01148"
"367.08000","30.59018","0.00990"
"367.50000","30.62522","0.00426"
"367.92000","30.66013","0.00301"
"368.34000","30.69517","0.00398"
"368.76000","30.73014","0.00397"
"369.18000","30.76518","0.00410"
"369.60000","30.80016","0.00511"
"370.02000","30.83514","0.00443"
"370.44000","30.87017","0.00549"
"370.86000","30.90521","0.00437"
"371.28000","30.94025","0.00522"
"371.70000","30.97516","0.00556"
"372.12000","31.01014","0.00611"
"372.54000","31.04518","0.00659"
"372.96000","31.08022","0.00629"
"373.38000","31.11519","0.00594"
"373.80000","31.15011","0.00663"
"374.22000","31.18515","0.00693"
"374.64000","31.22024","0.00627"
"375.06000","31.25521","0.00677"
"375.48000","31.29019","0.00695"
"375.90000","31.32517","0.00690"
"376.32000","31.36021","0.00723"
"376.74000","31.39524","0.00720"
"377.16000","31.43022","0.00783"
"377.58000","31.46514","0.00793"
"378.00000","31.50012","0.00768"
"378.42000","31.53521","0.00815"
"378.84000","31.57019","0.00781"
"379.26000","31.60517","0.00788"
"379.68000","31.64008","0.00779"
"380.10000","31.67524","0.00764"
"380.52000","31.71021","0.00768"
"380.94000","31.74525","0.00815"
"381.36000","31.78017","0.00773"
"381.78000","31.81520","0.00768"
"382.20000","31.85024","0.00643"
"382.62000","31.88522","0.00710"
"383.04000","31.92019","0.00730"
"383.46000","31.95511","0.00811"
"383.88000","31.99015","0.00807"
"384.30000","32.02525","0.00805"
"384.72000","32.06023","0.00835"
"385.14000","32.09514","0.00790"
"385.56000","32.13018","0.00805"
"385.98000","32.16515","0.00768"
"386.40000","32.20019","0.00919"
"386.82000","32.23517","0.00706"
"387.24000","32.27015","0.00651"
"387.66000","32.30518","0.00594"
"388.08000","32.34022","0.00694"
"388.50000","32.37526","0.00672"
"388.92000","32.41017","0.00712"
"389.34000","32.44515","0.00684"
"389.76000","32.48013","0.00763"
"390.18000","32.51516","0.00753"
"390.60000","32.55014","0.00811"
"391.02000","32.58511","0.00772"
"391.44000","32.62021","0.00826"
"391.86000","32.65525","0.00780"
"392.28000","32.69017","0.00821"
"392.70000","32.72514","0.00815"
"393.12000","32.76018","0.00813"
"393.54000","32.79522","0.00798"
"393.96000","32.83025","0.00829"
"394.38000","32.86523","0.00874"
"394.80000","32.90015","0.00850"
"395.22000","32.93512","0.00907"
"395.64000","32.97016","0.00875"
"396.06000","33.00514","0.00882"
"396.48000","33.04017","0.00853"
"396.90000","33.07509","0.00786"
"397.32000","33.11019","0.00777"
"397.74000","33.14522","0.00746"
"398.16000","33.18026","0.00753"
"398.58000","33.21518","0.00835"
"399.00000","33.25015","0.00847"
"399.42000","33.28519","0.00895"
"399.84000","33.32017","0.00946"
"400.26000","33.35521","0.01010"
"400.68000","33.39013","0.01036"
"401.10000","33.42516","0.01009"
"401.52000","33.46014","0.00868"
"401.94000","33.49517","0.00822"
"402.36000","33.53009","0.00974"
"402.78000","33.56519","0.00947"
"403.20000","33.60016","0.00999"
"403.62000","33.63520","0.00994"
"404.04000","33.67018","0.00895"
"404.46000","33.70515","0.00828"
"404.88000","33.74019","0.00783"
"405.30000","33.77523","0.00614"
"405.72000","33.81026","0.00731"
"406.14000","33.84518","0.00695"
"406.56000","33.88015","0.00694"
"406.98000","33.91513","0.00762"
"407.40000","33.95017","0.00779"
"407.82000","33.98515","0.00772"
"408.24000","34.02013","0.00783"
"408.66000","34.05516","0.00726"
"409.08000","34.09020","0.00828"
"409.50000","34.12518","0.00835"
"409.92000","34.16021","0.00902"
"410.34000","34.19513","0.00892"
"410.76000","34.23022","0.00956"
"411.18000","34.26526","0.00987"
"411.60000","34.30018","0.00935"
"412.02000","34.33516","0.00954"
"412.44000","34.37013","0.00976"
"412.86000","34.40523","0.00663"
"413.28000","34.44014","0.00746"
"413.70000","34.47518","0.00670"
"414.12000","34.51010","0.00762"
"414.54000","34.54519","0.00837"
"414.96000","34.58017","0.00817"
"415.38000","34.61521","0.00918"
"415.80000","34.65019","0.00898"
"416.22000","34.68510","0.00918"
"416.64000","34.72020","0.00780"
"417.06000","34.75524","0.00892"
"417.48000","34.79015","0.00760"
"417.90000","34.82513","0.00748"
"418.32000","34.86017","0.00766"
"418.74000","34.89515","0.00804"
"419.16000","34.93018","0.00813"
"419.58000","34.96516","0.00795"
"420.00000","35.00019","0.00543"
"420.42000","35.03517","0.00608"
"420.84000","35.07021","0.00623"
"421.26000","35.10518","0.00547"
"421.68000","35.14016","0.00683"
"422.10000","35.17520","0.00697"
"422.52000","35.21017","0.00714"
"422.94000","35.24521","0.00738"
"423.36000","35.28019","0.00722"
"423.78000","35.31517","0.00733"
"424.20000","35.35020","0.00750"
"424.62000","35.38518","0.00774"
"425.04000","35.42016","0.00758"
"425.46000","35.45507","0.00664"
"425.88000","35.49011","0.00719"
"426.30000","35.52521","0.00790"
"426.72000","35.56018","0.00834"
"427.14000","35.59516","0.00840"
"427.56000","35.63014","0.00832"
"427.98000","35.66517","0.00897"
"428.40000","35.70027","0.00755"
"428.82000","35.73524","0.00733"
"429.24000","35.77016","0.00804"
"429.66000","35.80514","0.00759"
"430.08000","35.84018","0.00830"
"430.50000","35.87516","0.00894"
"430.92000","35.91019","0.00884"
"431.34000","35.94511","0.00995"
"431.76000","35.98021","0.00938"
"432.18000","36.01518","0.01030"
"432.60000","36.05022","0.01102"
"433.02000","36.08520","0.01052"
"433.44000","36.12011","0.01135"
"433.86000","36.15527","0.01228"
"434.28000","36.19025","0.01041"
"434.70000","36.22522","0.01076"
"435.12000","36.26014","0.01053"
"435.54000","36.29517","0.01191"
"435.96000","36.33021","0.01252"
"436.38000","36.36525","0.01257"
"436.80000","36.40017","0.01218"
"437.22000","36.43520","0.01326"
"437.64000","36.47012","-0.00121"
"438.06000","36.50515","0.00293"
"438.48000","36.54013","0.00103"
"438.90000","36.57511","0.00006"
"439.32000","36.61015","0.00260"
"439.74000","36.64518","0.00036"
"440.16000","36.68022","0.00112"
"440.58000","36.71514","0.00338"
"441.00000","36.75011","0.00161"
"441.42000","36.78515","0.00351"
"441.84000","36.82019","0.00221"
"442.26000","36.85516","0.00238"
"442.68000","36.89014","0.00469"
"443.10000","36.92518","0.00255"
"443.52000","36.96027","0.00361"
"443.94000","36.99519","0.00368"
"444.36000","37.03017","0.00320"
"444.78000","37.06514","0.00491"
"445.20000","37.10024","0.00329"
"445.62000","37.13522","0.00414"
"446.04000","37.17026","0.00440"
"446.46000","37.20517","0.00406"
"446.88000","37.24015","0.00372"
"447.30000","37.27519","0.00294"
"447.72000","37.31017","0.00296"
"448.14000","37.34520","0.00479"
"448.56000","37.38012","0.00310"
"448.98000","37.41515","0.00547"
"449.40000","37.45019","0.00404"
"449.82000","37.48523","0.00574"
"450.24000","37.52015","0.00544"
"450.66000","37.55512","0.00561"
"451.08000","37.59022","0.00528"
"451.50000","37.62525","0.00522"
"451.92000","37.66017","0.00656"
"452.34000","37.69515","0.00600"
"452.76000","37.73018","0.00279"
"453.18000","37.76516","0.00379"
"453.60000","37.80020","0.00280"
"454.02000","37.83518","0.00479"
"454.44000","37.87016","0.00429"
"454.86000","37.90519","0.00476"
"455.28000","37.94017","0.00446"
"455.70000","37.97514","0.00567"
"456.12000","38.01012","0.00482"
"456.54000","38.04516","0.00507"
"456.96000","38.08019","0.00554"
"457.38000","38.11523","0.00503"
"457.80000","38.15021","0.00612"
"458.22000","38.18518","0.00614"
"458.64000","38.22016","0.00651"
"459.06000","38.25520","0.00655"
"459.48000","38.29017","0.00689"
"459.90000","38.32515","0.00718"
"460.32000","38.36019","0.00689"
"460.74000","38.39522","0.00746"
"461.16000","38.43014","0.00720"
"461.58000","38.46518","0.00729"
"462.00000","38.50016","0.00735"
"462.42000","38.53519","0.00756"
"462.84000","38.57023","0.00833"
"463.26000","38.60521","0.00853"
"463.68000","38.64012","0.00801"
"464.10000","38.67516","0.00826"
"464.52000","38.71020","0.00820"
"464.94000","38.74517","0.00858"
"465.36000","38.78021","0.00825"
"465.78000","38.81512","0.00885"
"466.20000","38.85022","0.00907"
"466.62000","38.88520","0.00818"
"467.04000","38.92023","0.00740"
"467.46000","38.95515","0.00789"
"467.88000","38.99013","0.00746"
"468.30000","39.02523","0.00641"
"468.72000","39.06020","0.00649"
"469.14000","39.09518","0.00643"
"469.56000","39.13010","0.00656"
"469.98000","39.16513","0.00090"
"470.40000","39.20017","0.00216"
"470.82000","39.23521","0.00111"
"471.24000","39.27018","0.00133"
"471.66000","39.30516","0.00121"
"472.08000","39.34020","0.00157"
"472.50000","39.37517","0.00095"
"472.92000","39.41015","0.00097"
"473.34000","39.44513","0.00079"
"473.76000","39.48022","0.00124"
"474.18000","39.51520","0.00070"
"474.60000","39.55024","0.00150"
"475.02000","39.58521","0.00098"
"475.44000","39.62013","0.00108"
"475.86000","39.65516","0.00240"
"476.28000","39.69014","0.00199"
"476.70000","39.72519","0.00226"
"477.12000","39.76016","0.00165"
"477.54000","39.79514","0.00163"
"477.96000","39.83023","0.00185"
"478.38000","39.86515","0.00099"
"478.80000","39.90019","0.00036"
"479.22000","39.93522","0.00100"
"479.64000","39.97026","0.00085"
"480.06000","40.00524","0.00045"
"480.48000","40.04021","0.00040"
"480.90000","40.07513","-0.00013"
"481.32000","40.11011","0.00059"
"481.74000","40.14520","-0.00011"
"482.16000","40.18012","-0.00016"
"482.58000","40.21516","0.00055"
"483.00000","40.25013","0.00093"
"483.42000","40.28517","0.00033"
"483.84000","40.32020","0.00081"
"484.26000","40.35525","0.00090"
"484.68000","40.39016","0.00082"
"485.10000","40.42514","0.00119"
"485.52000","40.46023","0.00112"
"485.94000","40.49527","0.00021"
"486.36000","40.53019","0.00099"
"486.78000","40.56510","0.00098"
"487.20000","40.60020","0.00038"
"487.62000","40.63518","0.00072"
"488.04000","40.67022","0.00062"
"488.46000","40.70513","0.00093"
"488.88000","40.74017","0.00026"
"489.30000","40.77515","0.00050"
"489.72000","40.81018","0.00072"
"490.14000","40.84522","0.00045"
"490.56000","40.88013","0.00054"
"490.98000","40.91517","0.00095"
"491.40000","40.95021","0.00040"
"491.82000","40.98525","0.00096"
"492.24000","41.02016","0.00038"
"492.66000","41.05514","0.00070"
"493.08000","41.09018","0.00099"
"493.50000","41.12522","0.00123"
"493.92000","41.16013","0.00104"
"494.34000","41.19511","0.00130"
"494.76000","41.23014","0.00085"
"495.18000","41.26524","0.00080"
"495.60000","41.30016","0.00058"
"496.02000","41.33514","0.00123"
"496.44000","41.37017","0.00060"
"496.86000","41.40521","0.00072"
"497.28000","41.44025","0.00113"
"497.70000","41.47522","0.00062"
"498.12000","41.51014","0.00082"
"498.54000","41.54517","0.00124"
"498.96000","41.58021","0.00124"
"499.38000","41.61518","0.00095"
"499.80000","41.65017","0.00103"
"500.22000","41.68515","0.00161"
"500.64000","41.72018","0.00141"
"501.06000","41.75522","0.00174"
"501.48000","41.79020","0.00082"
"501.90000","41.82511","0.00090"
"502.32000","41.86008","0.00108"
"502.74000","41.89524","0.00096"
"503.16000","41.93022","0.00101"
"503.58000","41.96519","0.00145"
"504.00000","42.00011","0.00115"
"504.42000","42.03521","0.00068"
"504.84000","42.07019","0.00087"
"505.26000","42.10522","0.00057"
"505.68000","42.14014","0.00087"
"506.10000","42.17511","0.00084"
"506.52000","42.21015","0.00116"
"506.94000","42.24519","0.00065"
"507.36000","42.28023","0.00085"
"507.78000","42.31515","0.00063"
"508.20000","42.35019","0.00053"
"508.62000","42.38516","0.00054"
"509.04000","42.42020","0.00103"
"509.46000","42.45517","0.00094"
"509.88000","42.49015","0.00057"
"510.30000","42.52519","0.00081"
"510.72000","42.56016","0.00113"
"511.14000","42.59514","0.00100"
"511.56000","42.63012","0.00156"
"511.98000","42.66515","0.00121"
"512.40000","42.70019","0.00060"
"512.82000","42.73523","0.00102"
"513.24000","42.77014","0.00130"
"513.66000","42.80518","0.00145"
"514.08000","42.84021","0.00112"
"514.50000","42.87519","0.00099"
"514.92000","42.91023","0.00061"
"515.34000","42.94515","0.00120"
"515.76000","42.98019","0.00084"
"516.18000","43.01522","0.00135"
"516.60000","43.05014","0.00139"
"517.02000","43.08518","0.00081"
"517.44000","43.12015","0.00136"
"517.86000","43.15519","0.00145"
"518.28000","43.19016","0.00132"
"518.70000","43.22520","0.00131"
"519.12000","43.26018","0.00092"
"519.54000","43.29515","0.00100"
"519.96000","43.33019","0.00082"
"520.38000","43.36517","0.00031"
"520.80000","43.40021","0.00093"
"521.22000","43.43512","0.00025"
"521.64000","43.47015","0.00032"
"522.06000","43.50519","0.00098"
"522.48000","43.54023","0.00049"
"522.90000","43.57509","0.00023"
"523.32000","43.61019","0.00099"
"523.74000","43.64511","0.00093"
"524.16000","43.68020","0.00087"
"524.58000","43.71518","0.00034"
"525.00000","43.75015","0.00030"
"525.42000","43.78519","0.00062"
"525.84000","43.82016","0.00094"
"526.26000","43.85520","0.00024"
"526.68000","43.89018","0.00075"
"527.10000","43.92516","0.00070"
"527.52000","43.96014","0.00021"
"527.94000","43.99517","0.00025"
"528.36000","44.03014","0.00055"
"528.78000","44.06512","0.00085"
"529.20000","44.10016","0.00043"
"529.62000","44.13519","0.00028"
"530.04000","44.17017","0.00022"
"530.46000","44.20521","0.00100"
"530.88000","44.24019","0.00042"
"531.30000","44.27523","0.00036"
"531.72000","44.31020","-0.00008"
"532.14000","44.34524","0.00068"
"532.56000","44.38016","0.00024"
"532.98000","44.41513","0.00058"
"533.40000","44.45023","0.00047"
"533.82000","44.48515","0.00060"
"534.24000","44.52018","0.00060"
"534.66000","44.55510","0.00081"
"535.08000","44.59020","0.00032"
"535.50000","44.62523","0.00064"
"535.92000","44.66027","0.00069"
"536.34000","44.69518","0.00046"
"536.76000","44.73016","-0.00036"
"537.18000","44.76520","0.00032"
"537.60000","44.80018","0.00001"
"538.02000","44.83516","0.00019"
"538.44000","44.87013","0.00001"
"538.86000","44.90517","0.00000"
"539.28000","44.94021","0.00042"
"539.70000","44.97519","0.00012"
"540.12000","45.01016","0.00014"
"540.54000","45.04514","0.00008"
"540.96000","45.08017","0.00036"
"541.38000","45.11521","0.00085"
"541.80000","45.15019","0.00050"
"542.22000","45.18510","-0.00002"
"542.64000","45.22020","0.00083"
"543.06000","45.25524","0.00015"
"543.48000","45.29021","0.00042"
"543.90000","45.32513","0.00053"
"544.32000","45.36011","0.00063"
"544.74000","45.39520","0.00077"
"545.16000","45.43024","-0.00018"
"545.58000","45.46516","0.00054"
"546.00000","45.50013","0.00045"
"546.42000","45.53511","0.00096"
"546.84000","45.57021","0.00030"
"547.26000","45.60519","0.00111"
"547.68000","45.64016","0.00081"
"548.10000","45.67514","0.00075"
"548.52000","45.71017","0.00113"
"548.94000","45.74521","0.00032"
"549.36000","45.78019","0.00108"
"549.78000","45.81517","0.00080"
"550.20000","45.85014","0.00112"
"550.62000","45.88518","0.00080"
"551.04000","45.92015","0.00125"
"551.46000","45.95519","0.00076"
"551.88000","45.99011","0.00086"
"552.30000","46.02520","0.00151"
"552.72000","46.06024","0.00057"
"553.14000","46.09522","0.00099"
"553.56000","46.13013","0.00130"
"553.98000","46.16518","0.00091"
"554.40000","46.20021","0.00134"
"554.82000","46.23525","0.00126"
"555.24000","46.27016","0.00205"
"555.66000","46.30514","0.00064"
"556.08000","46.34018","0.00041"
"556.50000","46.37521","0.00125"
"556.92000","46.41019","0.00085"
"557.34000","46.44511","0.00053"
"557.76000","46.48014","0.00055"
"558.18000","46.51518","0.00079"
"558.60000","46.55016","0.00052"
"559.02000","46.58519","0.00044"
"559.44000","46.62017","0.00083"
"559.86000","46.65520","0.00108"
"560.28000","46.69019","0.00019"
"560.70000","46.72522","0.00026"
"561.12000","46.76020","0.00024"
"561.54000","46.79518","0.00053"
"561.96000","46.83022","0.00034"
"562.38000","46.86519","-0.00002"
"562.80000","46.90017","-0.00003"
"563.22000","46.93508","-0.00072"
"563.64000","46.97012","-0.00043"
"564.06000","47.00521","-0.00036"
"564.48000","47.04019","0.00023"
"564.90000","47.07517","-0.00069"
"565.32000","47.11021","0.00011"
"565.74000","47.14512","0.00037"
"566.16000","47.18022","-0.00055"
"566.58000","47.21526","-0.00061"
"567.00000","47.25011","0.00032"
"567.42000","47.28515","0.00023"
"567.84000","47.32018","0.00027"
"568.26000","47.35516","0.00006"
"568.68000","47.39020","-0.00035"
"569.10000","47.42511","-0.00014"
"569.52000","47.46016","-0.00017"
"569.94000","47.49519","-0.00039"
"570.36000","47.53023","0.00025"
"570.78000","47.56521","-0.00019"
"571.20000","47.60012","-0.00051"
"571.62000","47.63522","0.00035"
"572.04000","47.67019","0.00003"
"572.46000","47.70517","0.00053"
"572.88000","47.74015","0.00016"
"573.30000","47.77519","0.00012"
"573.72000","47.81022","0.00000"
"574.14000","47.84520","0.00111"
"574.56000","47.88011","0.00068"
"574.98000","47.91515","0.00027"
"575.40000","47.95013","0.00027"
"575.82000","47.98516","0.00096"
"576.24000","48.02020","0.00137"
"576.66000","48.05518","0.00092"
"577.08000","48.09022","0.00178"
"577.50000","48.12519","0.00125"
"577.92000","48.16023","0.00012"
"578.34000","48.19521","-0.00044"
"578.76000","48.23012","-0.00012"
"579.18000","48.26516","-0.00019"
"579.60000","48.30019","0.00017"
"580.02000","48.33512","0.00046"
"580.44000","48.37009","0.00038"
"580.86000","48.40512","0.00012"
"581.28000","48.44022","0.00005"
"581.70000","48.47520","0.00020"
"582.12000","48.51017","0.00055"
"582.54000","48.54515","-0.00017"
"582.96000","48.58019","0.00072"
"583.38000","48.61522","0.00078"
"583.80000","48.65020","0.00035"
"584.22000","48.68518","0.00056"
"584.64000","48.72016","0.00078"
"585.06000","48.75520","0.00081"
"585.48000","48.79017","0.00112"
"585.90000","48.82521","0.00091"
"586.32000","48.86007","0.00101"
"586.74000","48.89516","0.00080"
"587.16000","48.93014","0.00082"
"587.58000","48.96523","0.00120"
"588.00000","49.00016","0.00172"
"588.42000","49.03513","0.00093"
"588.84000","49.07023","0.00202"
"589.26000","49.10514","0.00161"
"589.68000","49.14018","0.00093"
"590.10000","49.17510","0.00082"
"590.52000","49.21014","0.00141"
"590.94000","49.24517","0.00193"
"591.36000","49.28015","0.00189"
"591.78000","49.31512","0.00230"
"592.20000","49.35017","0.00243"
"592.62000","49.38520","0.00271"
"593.04000","49.42018","0.00329"
"593.46000","49.45521","0.00366"
"593.88000","49.49013","0.00268"
"594.30000","49.52517","0.00322"
"594.72000","49.56020","0.00340"
"595.14000","49.59524","0.00359"
"595.56000","49.63016","0.00486"
"595.98000","49.66513","0.00217"
"596.40000","49.70017","0.00355"
"596.82000","49.73520","0.00432"
"597.24000","49.77018","0.00396"
"597.66000","49.80510","0.00434"
"598.08000","49.84014","0.00469"
"598.50000","49.87523","0.00579"
"598.92000","49.91015","0.00468"
"599.34000","49.94512","0.00482"
"599.76000","49.98016","0.00428"
"600.18000","50.01521","0.00516"
"600.60000","50.05024","0.00549"
"601.02000","50.08522","0.00645"
"601.44000","50.12019","0.00697"
"601.86000","50.15511","0.00544"
"602.28000","50.19020","0.00576"
"602.70000","50.22518","0.00537"
"603.12000","50.26016","0.00681"
"603.54000","50.29507","0.00614"
"603.96000","50.33011","0.00604"
"604.38000","50.36521","0.00588"
"604.80000","50.40024","0.00050"
"605.22000","50.43516","0.00047"
"605.64000","50.47014","0.00018"
"606.06000","50.50518","-0.00010"
"606.48000","50.54021","0.00032"
"606.90000","50.57525","0.00022"
"607.32000","50.61016","0.00059"
"607.74000","50.64521","-0.00005"
"608.16000","50.68018","0.00025"
"608.58000","50.71521","0.00008"
"609.00000","50.75013","0.00052"
"609.42000","50.78517","0.00025"
"609.84000","50.82015","0.00026"
"610.26000","50.85519","0.00059"
"610.68000","50.89016","-0.00029"
"611.10000","50.92520","0.00014"
"611.52000","50.96017","0.00048"
"611.94000","50.99521","-0.00010"
"612.36000","51.03019","0.00023"
"612.78000","51.06522","-0.00038"
"613.20000","51.10014","-0.00027"
"613.62000","51.13518","0.00014"
"614.04000","51.17022","-0.00035"
"614.46000","51.20513","0.00004"
"614.88000","51.24010","-0.00007"
"615.30000","51.27514","0.00030"
"615.72000","51.31025","-0.00014"
"616.14000","51.34516","0.00037"
"616.56000","51.38020","0.00038"
"616.98000","51.41512","-0.00002"
"617.40000","51.45015","0.00066"
"617.82000","51.48519","0.00054"
"618.24000","51.52023","0.00043"
"618.66000","51.55514","0.00032"
"619.08000","51.59011","0.00061"
"619.50000","51.62521","-0.00012"
"619.92000","51.66019","0.00032"
"620.34000","51.69516","-0.00040"
"620.76000","51.73008","0.00032"
"621.18000","51.76518","0.00034"
"621.60000","51.80027","0.00004"
"622.02000","51.83525","0.00029"
"622.44000","51.87017","0.00010"
"622.86000","51.90514","0.00078"
"623.28000","51.94025","0.00047"
"623.70000","51.97522","0.00019"
"624.12000","52.01020","0.00051"
"624.54000","52.04517","0.00019"
"624.96000","52.08015","-0.00017"
"625.38000","52.11519","0.00059"
"625.80000","52.15023","0.00030"
"626.22000","52.18514","-0.00015"
"626.22800","52.18586","0.00011"