File: Force_trajectories/170107_1/Specimen_RawData_4.csv
End date,"1/7/2017"
Specimen label,"18DT_44"
Maximum Load,"0.20391",N

Time,Extension,Load
(s),(mm),(N)
"0.00000","0.00000","0.00027"
"0.33000","0.02732","0.00030"
"0.66000","0.05531","0.00056"
"0.99000","0.08281","0.00077"
"1.32000","0.11025","0.00096"
"1.65000","0.13776","0.00082"
"1.98000","0.16526","0.00129"
"2.31000","0.19270","0.00139"
"2.64000","0.22020","0.00132"
"2.97000","0.24771","0.00107"
"3.30000","0.27521","0.00168"
"3.63000","0.30271","0.00200"
"3.96000","0.33022","0.00180"
"4.29000","0.35778","0.00177"
"4.62000","0.38522","0.00231"
"4.95000","0.41273","0.00203"
"5.28000","0.44023","0.00210"
"5.61000","0.46767","0.00191"
"5.94000","0.49524","0.00211"
"6.27000","0.52274","0.00199"
"6.60000","0.55024","0.00268"
"6.93000","0.57775","0.00263"
"7.26000","0.60519","0.00225"
"7.59000","0.63281","0.00228"
"7.92000","0.66020","0.00246"
"8.25000","0.68764","0.00254"
"8.58000","0.71520","0.00274"
"8.91000","0.74265","0.00249"
"9.24000","0.77027","0.00276"
"9.57000","0.79777","0.00279"
"9.90000","0.82522","0.00259"
"10.23000","0.85272","0.00315"
"10.56000","0.88022","0.00268"
"10.89000","0.90778","0.00278"
"11.22000","0.93523","0.00277"
"11.55000","0.96267","0.00307"
"11.88000","0.99023","0.00321"
"12.21000","1.01768","0.00277"
"12.54000","1.04524","0.00274"
"12.87000","1.07274","0.00300"
"13.20000","1.10019","0.00344"
"13.53000","1.12775","0.00339"
"13.86000","1.15525","0.00308"
"14.19000","1.18270","0.00305"
"14.52000","1.21020","0.00344"
"14.85000","1.23764","0.00325"
"15.18000","1.26527","0.00358"
"15.51000","1.29277","0.00349"
"15.84000","1.32021","0.00345"
"16.17000","1.34778","0.00305"
"16.50000","1.37522","0.00322"
"16.83000","1.40272","0.00307"
"17.16000","1.43029","0.00326"
"17.49000","1.45773","0.00347"
"17.82000","1.48529","0.00353"
"18.15000","1.51274","0.00334"
"18.48000","1.54024","0.00366"
"18.81000","1.56774","0.00425"
"19.14000","1.59518","0.00367"
"19.47000","1.62275","0.00392"
"19.80000","1.65025","0.00373"
"20.13000","1.67775","0.00390"
"20.46000","1.70526","0.00384"
"20.79000","1.73270","0.00385"
"21.12000","1.76014","0.00428"
"21.45000","1.78771","0.00420"
"21.78000","1.81515","0.00415"
"22.11000","1.84271","0.00343"
"22.44000","1.87022","0.00437"
"22.77000","1.89772","0.00432"
"23.10000","1.92522","0.00425"
"23.43000","1.95267","0.00415"
"23.76000","1.98023","0.00385"
"24.09000","2.00779","0.00418"
"24.42000","2.03524","0.00413"
"24.75000","2.06274","0.00434"
"25.08000","2.09024","0.00471"
"25.41000","2.11775","0.00432"
"25.74000","2.14525","0.00409"
"26.07000","2.17269","0.00448"
"26.40000","2.20025","0.00399"
"26.73000","2.22770","0.00471"
"27.06000","2.25520","0.00451"
"27.39000","2.28276","0.00471"
"27.72000","2.31015","0.00477"
"28.05000","2.33771","0.00467"
"28.38000","2.36521","0.00393"
"28.71000","2.39272","0.00423"
"29.04000","2.42022","0.00513"
"29.37000","2.44772","0.00513"
"29.70000","2.47523","0.00498"
"30.03000","2.50273","0.00459"
"30.36000","2.53017","0.00463"
"30.69000","2.55774","0.00462"
"31.02000","2.58518","0.00508"
"31.35000","2.61268","0.00488"
"31.68000","2.64025","0.00487"
"32.01000","2.66763","0.00501"
"32.34000","2.69525","0.00456"
"32.67000","2.72276","0.00425"
"33.00000","2.75020","0.00491"
"33.33000","2.77776","0.00457"
"33.66000","2.80515","0.00500"
"33.99000","2.83277","0.00488"
"34.32000","2.86021","0.00478"
"34.65000","2.88766","0.00491"
"34.98000","2.91534","0.00519"
"35.31000","2.94272","0.00498"
"35.64000","2.97022","0.00541"
"35.97000","2.99779","0.00530"
"36.30000","3.02517","0.00467"
"36.63000","3.05273","0.00558"
"36.96000","3.08018","0.00487"
"37.29000","3.10774","0.00459"
"37.62000","3.13524","0.00521"
"37.95000","3.16263","0.00522"
"38.28000","3.19025","0.00498"
"38.61000","3.21769","0.00494"
"38.94000","3.24514","0.00540"
"39.27000","3.27276","0.00520"
"39.60000","3.30020","0.00554"
"39.93000","3.32771","0.00527"
"40.26000","3.35527","0.00519"
"40.59000","3.38265","0.00558"
"40.92000","3.41028","0.00549"
"41.25000","3.43772","0.00563"
"41.58000","3.46522","0.00568"
"41.91000","3.49279","0.00549"
"42.24000","3.52017","0.00566"
"42.57000","3.54779","0.00565"
"42.90000","3.57523","0.00553"
"43.23000","3.60268","0.00555"
"43.56000","3.63018","0.00569"
"43.89000","3.65768","0.00552"
"44.22000","3.68525","0.00525"
"44.55000","3.71275","0.00553"
"44.88000","3.74019","0.00534"
"45.21000","3.76776","0.00570"
"45.54000","3.79520","0.00537"
"45.87000","3.82276","0.00520"
"46.20000","3.85027","0.00563"
"46.53000","3.87765","0.00588"
"46.86000","3.90521","0.00558"
"47.19000","3.93272","0.00621"
"47.52000","3.96016","0.00580"
"47.85000","3.98772","0.00538"
"48.18000","4.01523","0.00579"
"48.51000","4.04273","0.00539"
"48.84000","4.07023","0.00606"
"49.17000","4.09768","0.00602"
"49.50000","4.12524","0.00615"
"49.83000","4.15268","0.00562"
"50.16000","4.18024","0.00597"
"50.49000","4.20781","0.00575"
"50.82000","4.23513","0.00614"
"51.15000","4.26275","0.00545"
"51.48000","4.29026","0.00589"
"51.81000","4.31770","0.00599"
"52.14000","4.34520","0.00613"
"52.47000","4.37271","0.00619"
"52.80000","4.40027","0.00581"
"53.13000","4.42771","0.00617"
"53.46000","4.45522","0.00592"
"53.79000","4.48272","0.00559"
"54.12000","4.51016","0.00654"
"54.45000","4.53773","0.00629"
"54.78000","4.56529","0.00590"
"55.11000","4.59267","0.00596"
"55.44000","4.62024","0.00591"
"55.77000","4.64774","0.00627"
"56.10000","4.67524","0.00629"
"56.43000","4.70275","0.00618"
"56.76000","4.73019","0.00679"
"57.09000","4.75775","0.00665"
"57.42000","4.78520","0.00619"
"57.75000","4.81270","0.00601"
"58.08000","4.84026","0.00635"
"58.41000","4.86770","0.00613"
"58.74000","4.89521","0.00612"
"59.07000","4.92271","0.00646"
"59.40000","4.95021","0.00689"
"59.73000","4.97766","0.00687"
"60.06000","5.00522","0.00652"
"60.39000","5.03272","0.00672"
"60.72000","5.06023","0.00689"
"61.05000","5.08767","0.00637"
"61.38000","5.11529","0.00654"
"61.71000","5.14268","0.00702"
"62.04000","5.17024","0.00681"
"62.37000","5.19774","0.00678"
"62.70000","5.22519","0.00709"
"63.03000","5.25275","0.00656"
"63.36000","5.28025","0.00650"
"63.69000","5.30776","0.00645"
"64.02000","5.33520","0.00689"
"64.35000","5.36270","0.00657"
"64.68000","5.39026","0.00687"
"65.01000","5.41777","0.00720"
"65.34000","5.44521","0.00737"
"65.67000","5.47277","0.00670"
"66.00000","5.50016","0.00648"
"66.33000","5.52772","0.00739"
"66.66000","5.55522","0.00730"
"66.99000","5.58267","0.00689"
"67.32000","5.61023","0.00720"
"67.65000","5.63767","0.00695"
"67.98000","5.66524","0.00731"
"68.31000","5.69274","0.00706"
"68.64000","5.72012","0.00664"
"68.97000","5.74775","0.00731"
"69.30000","5.77519","0.00742"
"69.63000","5.80275","0.00713"
"69.96000","5.83026","0.00743"
"70.29000","5.85776","0.00687"
"70.62000","5.88526","0.00661"
"70.95000","5.91277","0.00660"
"71.28000","5.94021","0.00673"
"71.61000","5.96777","0.00691"
"71.94000","5.99522","0.00689"
"72.27000","6.02272","0.00650"
"72.60000","6.05022","0.00696"
"72.93000","6.07767","0.00699"
"73.26000","6.10529","0.00675"
"73.59000","6.13273","0.00703"
"73.92000","6.16024","0.00706"
"74.25000","6.18768","0.00741"
"74.58000","6.21524","0.00707"
"74.91000","6.24274","0.00729"
"75.24000","6.27025","0.00713"
"75.57000","6.29769","0.00724"
"75.90000","6.32525","0.00746"
"76.23000","6.35270","0.00767"
"76.56000","6.38020","0.00718"
"76.89000","6.40770","0.00755"
"77.22000","6.43521","0.00724"
"77.55000","6.46277","0.00723"
"77.88000","6.49021","0.00766"
"78.21000","6.51772","0.00671"
"78.54000","6.54522","0.00761"
"78.87000","6.57266","0.00754"
"79.20000","6.60023","0.00792"
"79.53000","6.62773","0.00713"
"79.86000","6.65517","0.00666"
"80.19000","6.68280","0.00758"
"80.52000","6.71024","0.00740"
"80.85000","6.73768","0.00691"
"81.18000","6.76525","0.00700"
"81.51000","6.79275","0.00710"
"81.84000","6.82025","0.00742"
"82.17000","6.84775","0.00707"
"82.50000","6.87520","0.00676"
"82.83000","6.90270","0.00708"
"83.16000","6.93015","0.00728"
"83.49000","6.95777","0.00714"
"83.82000","6.98527","0.00714"
"84.15000","7.01265","0.00755"
"84.48000","7.04028","0.00722"
"84.81000","7.06766","0.00741"
"85.14000","7.09522","0.00718"
"85.47000","7.12273","0.00735"
"85.80000","7.15017","0.00710"
"86.13000","7.17773","0.00723"
"86.46000","7.20518","0.00756"
"86.79000","7.23274","0.00719"
"87.12000","7.26018","0.00765"
"87.45000","7.28763","0.00787"
"87.78000","7.31525","0.00749"
"88.11000","7.34275","0.00730"
"88.44000","7.37020","0.00765"
"88.77000","7.39776","0.00714"
"89.10000","7.42520","0.00777"
"89.43000","7.45265","0.00755"
"89.76000","7.48021","0.00736"
"90.09000","7.50771","0.00706"
"90.42000","7.53521","0.00759"
"90.75000","7.56272","0.00781"
"91.08000","7.59028","0.00717"
"91.41000","7.61772","0.00757"
"91.74000","7.64511","0.00785"
"92.07000","7.67279","0.00736"
"92.40000","7.70023","0.00814"
"92.73000","7.72774","0.00725"
"93.06000","7.75524","0.00785"
"93.39000","7.78274","0.00771"
"93.72000","7.81025","0.00739"
"94.05000","7.83769","0.00788"
"94.38000","7.86519","0.00782"
"94.71000","7.89276","0.00728"
"95.04000","7.92014","0.00789"
"95.37000","7.94776","0.00745"
"95.70000","7.97527","0.00775"
"96.03000","8.00265","0.00738"
"96.36000","8.03027","0.00781"
"96.69000","8.05772","0.00770"
"97.02000","8.08522","0.00767"
"97.35000","8.11272","0.00816"
"97.68000","8.14023","0.00787"
"98.01000","8.16767","0.00824"
"98.34000","8.19523","0.00786"
"98.67000","8.22268","0.00813"
"99.00000","8.25030","0.00797"
"99.33000","8.27768","0.00798"
"99.66000","8.30524","0.00782"
"99.99000","8.33281","0.00740"
"100.32000","8.36013","0.00859"
"100.65000","8.38775","0.00770"
"100.98000","8.41526","0.00820"
"101.31000","8.44276","0.00778"
"101.64000","8.47026","0.00814"
"101.97000","8.49771","0.00826"
"102.30000","8.52527","0.00751"
"102.63000","8.55271","0.00805"
"102.96000","8.58016","0.00782"
"103.29000","8.60778","0.00807"
"103.62000","8.63522","0.00840"
"103.95000","8.66273","0.00825"
"104.28000","8.69023","0.00799"
"104.61000","8.71767","0.00805"
"104.94000","8.74518","0.00855"
"105.27000","8.77268","0.00842"
"105.60000","8.80018","0.00853"
"105.93000","8.82775","0.00841"
"106.26000","8.85519","0.00789"
"106.59000","8.88275","0.00877"
"106.92000","8.91020","0.00771"
"107.25000","8.93764","0.00876"
"107.58000","8.96526","0.00861"
"107.91000","8.99270","0.00898"
"108.24000","9.02027","0.00819"
"108.57000","9.04777","0.00821"
"108.90000","9.07521","0.00800"
"109.23000","9.10278","0.00814"
"109.56000","9.13016","0.00867"
"109.89000","9.15772","0.00844"
"110.22000","9.18529","0.00877"
"110.55000","9.21267","0.00873"
"110.88000","9.24023","0.00748"
"111.21000","9.26768","0.00844"
"111.54000","9.29518","0.00800"
"111.87000","9.32274","0.00814"
"112.20000","9.35025","0.00856"
"112.53000","9.37775","0.00864"
"112.86000","9.40519","0.00824"
"113.19000","9.43270","0.00845"
"113.52000","9.46026","0.00838"
"113.85000","9.48770","0.00859"
"114.18000","9.51527","0.00910"
"114.51000","9.54271","0.00894"
"114.84000","9.57021","0.00881"
"115.17000","9.59772","0.00857"
"115.50000","9.62522","0.00905"
"115.83000","9.65272","0.00909"
"116.16000","9.68022","0.00894"
"116.49000","9.70767","0.00866"
"116.82000","9.73529","0.00909"
"117.15000","9.76273","0.00889"
"117.48000","9.79024","0.00935"
"117.81000","9.81774","0.00907"
"118.14000","9.84512","0.00916"
"118.47000","9.87275","0.00932"
"118.80000","9.90025","0.00912"
"119.13000","9.92769","0.00985"
"119.46000","9.95526","0.00760"
"119.79000","9.98276","0.00793"
"120.12000","10.01020","0.00812"
"120.45000","10.03771","0.00796"
"120.78000","10.06521","0.00813"
"121.11000","10.09277","0.00807"
"121.44000","10.12022","0.00782"
"121.77000","10.14772","0.00800"
"122.10000","10.17528","0.00844"
"122.43000","10.20267","0.00876"
"122.76000","10.23023","0.00865"
"123.09000","10.25773","0.00842"
"123.42000","10.28517","0.00843"
"123.75000","10.31268","0.00838"
"124.08000","10.34024","0.00863"
"124.41000","10.36774","0.00872"
"124.74000","10.39525","0.00881"
"125.07000","10.42269","0.00880"
"125.40000","10.45025","0.00833"
"125.73000","10.47776","0.00897"
"126.06000","10.50520","0.00896"
"126.39000","10.53276","0.00865"
"126.72000","10.56021","0.00855"
"127.05000","10.58777","0.00945"
"127.38000","10.61527","0.00866"
"127.71000","10.64272","0.00952"
"128.04000","10.67022","0.00917"
"128.37000","10.69766","0.00936"
"128.70000","10.72529","0.00929"
"129.03000","10.75273","0.00993"
"129.36000","10.78017","0.01090"
"129.69000","10.80774","0.01051"
"130.02000","10.83518","0.01034"
"130.35000","10.86274","0.01034"
"130.68000","10.89024","0.01104"
"131.01000","10.91769","0.01086"
"131.34000","10.94519","0.01103"
"131.67000","10.97269","0.01103"
"132.00000","11.00026","0.01037"
"132.33000","11.02776","0.01110"
"132.66000","11.05514","0.01072"
"132.99000","11.08277","0.01046"
"133.32000","11.11021","0.01002"
"133.65000","11.13765","0.00980"
"133.98000","11.16522","0.01104"
"134.31000","11.19266","0.01103"
"134.64000","11.22022","0.01095"
"134.97000","11.24773","0.01092"
"135.30000","11.27517","0.01124"
"135.63000","11.30273","0.01095"
"135.96000","11.33018","0.01166"
"136.29000","11.35774","0.01150"
"136.62000","11.38524","0.01244"
"136.95000","11.41269","0.01208"
"137.28000","11.44031","0.01223"
"137.61000","11.46775","0.01224"
"137.94000","11.49525","0.01261"
"138.27000","11.52270","0.01194"
"138.60000","11.55020","0.01275"
"138.93000","11.57771","0.01235"
"139.26000","11.60527","0.01236"
"139.59000","11.63271","0.01381"
"139.92000","11.66021","0.01269"
"140.25000","11.68766","0.01300"
"140.58000","11.71522","0.01321"
"140.91000","11.74278","0.01300"
"141.24000","11.77017","0.01363"
"141.57000","11.79773","0.01334"
"141.90000","11.82517","0.01359"
"142.23000","11.85268","0.01439"
"142.56000","11.88018","0.01436"
"142.89000","11.90768","0.01426"
"143.22000","11.93519","0.01326"
"143.55000","11.96269","0.01294"
"143.88000","11.99019","0.01293"
"144.21000","12.01782","0.01369"
"144.54000","12.04514","0.01370"
"144.87000","12.07270","0.01361"
"145.20000","12.10027","0.01382"
"145.53000","12.12771","0.01228"
"145.86000","12.15527","0.01191"
"146.19000","12.18271","0.01219"
"146.52000","12.21022","0.00769"
"146.85000","12.23772","0.00886"
"147.18000","12.26516","0.00783"
"147.51000","12.29279","0.00810"
"147.84000","12.32023","0.00885"
"148.17000","12.34773","0.00862"
"148.50000","12.37524","0.00767"
"148.83000","12.40262","0.00869"
"149.16000","12.43018","0.00843"
"149.49000","12.45775","0.00797"
"149.82000","12.48519","0.00725"
"150.15000","12.51275","0.00657"
"150.48000","12.54026","0.00772"
"150.81000","12.56776","0.00822"
"151.14000","12.59526","0.00725"
"151.47000","12.62265","0.00764"
"151.80000","12.65021","0.00794"
"152.13000","12.67771","0.00800"
"152.46000","12.70522","0.00841"
"152.79000","12.73278","0.00793"
"153.12000","12.76016","0.00830"
"153.45000","12.78772","0.00807"
"153.78000","12.81523","0.00837"
"154.11000","12.84267","0.00794"
"154.44000","12.87024","0.00834"
"154.77000","12.89774","0.00813"
"155.10000","12.92524","0.00875"
"155.43000","12.95275","0.00780"
"155.76000","12.98019","0.00858"
"156.09000","13.00775","0.00850"
"156.42000","13.03525","0.00832"
"156.75000","13.06270","0.00847"
"157.08000","13.09026","0.00861"
"157.41000","13.11770","0.00833"
"157.74000","13.14527","0.00869"
"158.07000","13.17271","0.00846"
"158.40000","13.20015","0.00849"
"158.73000","13.22778","0.00954"
"159.06000","13.25516","0.00905"
"159.39000","13.28278","0.00921"
"159.72000","13.31023","0.00979"
"160.05000","13.33767","0.00946"
"160.38000","13.36523","0.00885"
"160.71000","13.39274","0.00934"
"161.04000","13.42024","0.00950"
"161.37000","13.44774","0.00938"
"161.70000","13.47513","0.00915"
"162.03000","13.50269","0.00970"
"162.36000","13.53019","0.00970"
"162.69000","13.55770","0.00994"
"163.02000","13.58526","0.00940"
"163.35000","13.61264","0.01008"
"163.68000","13.64026","0.00926"
"164.01000","13.66771","0.00964"
"164.34000","13.69515","0.01010"
"164.67000","13.72271","0.00956"
"165.00000","13.75022","0.01014"
"165.33000","13.77772","0.01038"
"165.66000","13.80522","0.00963"
"165.99000","13.83273","0.00907"
"166.32000","13.86023","0.00940"
"166.65000","13.88767","0.00999"
"166.98000","13.91518","0.00926"
"167.31000","13.94274","0.00974"
"167.64000","13.97018","0.00973"
"167.97000","13.99775","0.00964"
"168.30000","14.02525","0.00948"
"168.63000","14.05269","0.01003"
"168.96000","14.08020","0.00951"
"169.29000","14.10770","0.00982"
"169.62000","14.13526","0.00983"
"169.95000","14.16277","0.00959"
"170.28000","14.19015","0.00961"
"170.61000","14.21777","0.00966"
"170.94000","14.24516","0.00982"
"171.27000","14.27272","0.01001"
"171.60000","14.30022","0.01025"
"171.93000","14.32767","0.01061"
"172.26000","14.35523","0.01023"
"172.59000","14.38273","0.01036"
"172.92000","14.41023","0.01050"
"173.25000","14.43768","0.01112"
"173.58000","14.46518","0.01077"
"173.91000","14.49274","0.01083"
"174.24000","14.52025","0.01035"
"174.57000","14.54769","0.01123"
"174.90000","14.57525","0.01103"
"175.23000","14.60270","0.01142"
"175.56000","14.63014","0.01091"
"175.89000","14.65776","0.01112"
"176.22000","14.68521","0.01107"
"176.55000","14.71271","0.01088"
"176.88000","14.74027","0.01149"
"177.21000","14.76772","0.01163"
"177.54000","14.79522","0.01188"
"177.87000","14.82266","0.01164"
"178.20000","14.85023","0.01191"
"178.53000","14.87773","0.01217"
"178.86000","14.90517","0.01172"
"179.19000","14.93273","0.01208"
"179.52000","14.96018","0.01226"
"179.85000","14.98768","0.01209"
"180.18000","15.01524","0.01227"
"180.51000","15.04269","0.01255"
"180.84000","15.07025","0.01269"
"181.17000","15.09769","0.01241"
"181.50000","15.12526","0.01329"
"181.83000","15.15270","0.01280"
"182.16000","15.18014","0.01314"
"182.49000","15.20777","0.01308"
"182.82000","15.23527","0.01341"
"183.15000","15.26277","0.01312"
"183.48000","15.29028","0.01368"
"183.81000","15.31772","0.01414"
"184.14000","15.34516","0.01320"
"184.47000","15.37273","0.01364"
"184.80000","15.40023","0.01362"
"185.13000","15.42773","0.01377"
"185.46000","15.45524","0.01336"
"185.79000","15.48274","0.01368"
"186.12000","15.51024","0.01413"
"186.45000","15.53763","0.01349"
"186.78000","15.56525","0.01422"
"187.11000","15.59269","0.01400"
"187.44000","15.62013","0.01418"
"187.77000","15.64776","0.01454"
"188.10000","15.67526","0.01545"
"188.43000","15.70276","0.01474"
"188.76000","15.73021","0.01502"
"189.09000","15.75771","0.01460"
"189.42000","15.78521","0.01508"
"189.75000","15.81272","0.01515"
"190.08000","15.84028","0.01548"
"190.41000","15.86772","0.01533"
"190.74000","15.89517","0.01524"
"191.07000","15.92273","0.01524"
"191.40000","15.95017","0.01557"
"191.73000","15.97768","0.01575"
"192.06000","16.00524","0.01602"
"192.39000","16.03274","0.01685"
"192.72000","16.06019","0.01627"
"193.05000","16.08769","0.01662"
"193.38000","16.11519","0.01631"
"193.71000","16.14270","0.01679"
"194.04000","16.17020","0.01624"
"194.37000","16.19776","0.01653"
"194.70000","16.22527","0.01711"
"195.03000","16.25271","0.01714"
"195.36000","16.28027","0.01721"
"195.69000","16.30771","0.01798"
"196.02000","16.33522","0.01774"
"196.35000","16.36272","0.01808"
"196.68000","16.39016","0.01787"
"197.01000","16.41773","0.01841"
"197.34000","16.44517","0.01782"
"197.67000","16.47267","0.01871"
"198.00000","16.50030","0.01840"
"198.33000","16.52768","0.01883"
"198.66000","16.55530","0.01886"
"198.99000","16.58275","0.01930"
"199.32000","16.61019","0.01958"
"199.65000","16.63769","0.01972"
"199.98000","16.66520","0.01967"
"200.31000","16.69270","0.01963"
"200.64000","16.72020","0.02005"
"200.97000","16.74771","0.02019"
"201.30000","16.77521","0.02051"
"201.63000","16.80271","0.02040"
"201.96000","16.83016","0.02038"
"202.29000","16.85772","0.02108"
"202.62000","16.88516","0.02117"
"202.95000","16.91278","0.02109"
"203.28000","16.94029","0.02133"
"203.61000","16.96773","0.02112"
"203.94000","16.99523","0.02177"
"204.27000","17.02268","0.02193"
"204.60000","17.05024","0.02159"
"204.93000","17.07780","0.02202"
"205.26000","17.10519","0.02239"
"205.59000","17.13275","0.02247"
"205.92000","17.16019","0.02271"
"206.25000","17.18770","0.02288"
"206.58000","17.21526","0.02312"
"206.91000","17.24270","0.02307"
"207.24000","17.27027","0.02314"
"207.57000","17.29777","0.02306"
"207.90000","17.32521","0.02342"
"208.23000","17.35271","0.02380"
"208.56000","17.38016","0.02440"
"208.89000","17.40778","0.02428"
"209.22000","17.43522","0.02437"
"209.55000","17.46267","0.02449"
"209.88000","17.49023","0.02496"
"210.21000","17.51768","0.02554"
"210.54000","17.54518","0.02548"
"210.87000","17.57274","0.02520"
"211.20000","17.60018","0.02587"
"211.53000","17.62775","0.02623"
"211.86000","17.65525","0.02649"
"212.19000","17.68275","0.02693"
"212.52000","17.71026","0.02689"
"212.85000","17.73764","0.02726"
"213.18000","17.76526","0.02782"
"213.51000","17.79277","0.02826"
"213.84000","17.82021","0.02802"
"214.17000","17.84777","0.02808"
"214.50000","17.87528","0.02875"
"214.83000","17.90272","0.02913"
"215.16000","17.93022","0.02947"
"215.49000","17.95773","0.02978"
"215.82000","17.98523","0.02995"
"216.15000","18.01267","0.03054"
"216.48000","18.04024","0.03068"
"216.81000","18.06780","0.03129"
"217.14000","18.09518","0.03099"
"217.47000","18.12275","0.03110"
"217.80000","18.15025","0.03162"
"218.13000","18.17769","0.03094"
"218.46000","18.20520","0.03133"
"218.79000","18.23270","0.03027"
"219.12000","18.26020","0.03053"
"219.45000","18.28770","0.03078"
"219.78000","18.31515","0.03139"
"220.11000","18.34271","0.03136"
"220.44000","18.37016","0.03156"
"220.77000","18.39772","0.02883"
"221.10000","18.42528","0.00726"
"221.43000","18.45267","0.00798"
"221.76000","18.48023","0.00720"
"222.09000","18.50773","0.00751"
"222.42000","18.53523","0.00774"
"222.75000","18.56268","0.00847"
"223.08000","18.59018","0.00783"
"223.41000","18.61774","0.00846"
"223.74000","18.64531","0.00809"
"224.07000","18.67275","0.00921"
"224.40000","18.70025","0.00831"
"224.73000","18.72770","0.00860"
"225.06000","18.75520","0.00904"
"225.39000","18.78276","0.00942"
"225.72000","18.81015","0.00939"
"226.05000","18.83771","0.01006"
"226.38000","18.86521","0.01006"
"226.71000","18.89272","0.01004"
"227.04000","18.92028","0.01145"
"227.37000","18.94766","0.01093"
"227.70000","18.97522","0.01091"
"228.03000","19.00273","0.01136"
"228.36000","19.03017","0.01206"
"228.69000","19.05779","0.00902"
"229.02000","19.08524","0.00926"
"229.35000","19.11268","0.00913"
"229.68000","19.14024","0.00948"
"230.01000","19.16769","0.00885"
"230.34000","19.19525","0.00948"
"230.67000","19.22269","0.00859"
"231.00000","19.25020","0.00915"
"231.33000","19.27776","0.00890"
"231.66000","19.30514","0.00947"
"231.99000","19.33277","0.00836"
"232.32000","19.36021","0.00936"
"232.65000","19.38765","0.00958"
"232.98000","19.41522","0.00987"
"233.31000","19.44272","0.00942"
"233.64000","19.47022","0.00953"
"233.97000","19.49773","0.00961"
"234.30000","19.52523","0.00933"
"234.63000","19.55273","0.00936"
"234.96000","19.58024","0.00916"
"235.29000","19.60774","0.00989"
"235.62000","19.63524","0.00992"
"235.95000","19.66269","0.00977"
"236.28000","19.69025","0.00971"
"236.61000","19.71775","0.00911"
"236.94000","19.74520","0.00968"
"237.27000","19.77270","0.00992"
"237.60000","19.80020","0.00916"
"237.93000","19.82771","0.01008"
"238.26000","19.85521","0.01012"
"238.59000","19.88265","0.01016"
"238.92000","19.91022","0.00957"
"239.25000","19.93766","0.01021"
"239.58000","19.96522","0.00972"
"239.91000","19.99272","0.00987"
"240.24000","20.02017","0.01041"
"240.57000","20.04773","0.01064"
"240.90000","20.07523","0.01011"
"241.23000","20.10274","0.01091"
"241.56000","20.13024","0.01052"
"241.89000","20.15774","0.01035"
"242.22000","20.18525","0.01094"
"242.55000","20.21275","0.01056"
"242.88000","20.24019","0.01140"
"243.21000","20.26776","0.01053"
"243.54000","20.29520","0.01038"
"243.87000","20.32270","0.01093"
"244.20000","20.35026","0.01068"
"244.53000","20.37765","0.01155"
"244.86000","20.40521","0.01074"
"245.19000","20.43271","0.01099"
"245.52000","20.46022","0.01141"
"245.85000","20.48772","0.01113"
"246.18000","20.51516","0.01074"
"246.51000","20.54273","0.01088"
"246.84000","20.57023","0.01161"
"247.17000","20.59767","0.01101"
"247.50000","20.62530","0.01150"
"247.83000","20.65268","0.01197"
"248.16000","20.68024","0.01186"
"248.49000","20.70774","0.01137"
"248.82000","20.73513","0.01185"
"249.15000","20.76269","0.01198"
"249.48000","20.79020","0.01140"
"249.81000","20.81776","0.01218"
"250.14000","20.84526","0.01148"
"250.47000","20.87271","0.01183"
"250.80000","20.90027","0.01182"
"251.13000","20.92771","0.01218"
"251.46000","20.95515","0.01256"
"251.79000","20.98272","0.01248"
"252.12000","21.01022","0.01201"
"252.45000","21.03772","0.01183"
"252.78000","21.06529","0.01182"
"253.11000","21.09267","0.01223"
"253.44000","21.12017","0.01229"
"253.77000","21.14768","0.01304"
"254.10000","21.17530","0.01203"
"254.43000","21.20274","0.01242"
"254.76000","21.23013","0.01231"
"255.09000","21.25775","0.01252"
"255.42000","21.28519","0.01302"
"255.75000","21.31276","0.01231"
"256.08000","21.34026","0.01287"
"256.41000","21.36770","0.01263"
"256.74000","21.39521","0.01325"
"257.07000","21.42265","0.01274"
"257.40000","21.45021","0.01325"
"257.73000","21.47772","0.01334"
"258.06000","21.50516","0.01372"
"258.39000","21.53272","0.01321"
"258.72000","21.56023","0.01378"
"259.05000","21.58773","0.01369"
"259.38000","21.61523","0.01306"
"259.71000","21.64267","0.01349"
"260.04000","21.67018","0.01298"
"260.37000","21.69774","0.01294"
"260.70000","21.72524","0.01340"
"261.03000","21.75275","0.01355"
"261.36000","21.78019","0.01334"
"261.69000","21.80769","0.01354"
"262.02000","21.83526","0.01360"
"262.35000","21.86264","0.01318"
"262.68000","21.89026","0.01325"
"263.01000","21.91777","0.01303"
"263.34000","21.94521","0.01286"
"263.67000","21.97271","0.01376"
"264.00000","22.00022","0.01371"
"264.33000","22.02772","0.01357"
"264.66000","22.05522","0.01353"
"264.99000","22.08273","0.01364"
"265.32000","22.11029","0.01391"
"265.65000","22.13767","0.01373"
"265.98000","22.16518","0.01339"
"266.31000","22.19274","0.01363"
"266.64000","22.22018","0.01380"
"266.97000","22.24774","0.01429"
"267.30000","22.27525","0.01426"
"267.63000","22.30269","0.01432"
"267.96000","22.33019","0.01396"
"268.29000","22.35770","0.01431"
"268.62000","22.38526","0.01379"
"268.95000","22.41270","0.01424"
"269.28000","22.44027","0.01383"
"269.61000","22.46777","0.01428"
"269.94000","22.49515","0.01408"
"270.27000","22.52266","0.01434"
"270.60000","22.55028","0.01448"
"270.93000","22.57766","0.01455"
"271.26000","22.60523","0.01443"
"271.59000","22.63273","0.01425"
"271.92000","22.66023","0.01470"
"272.25000","22.68774","0.01440"
"272.58000","22.71512","0.01474"
"272.91000","22.74280","0.01431"
"273.24000","22.77024","0.01425"
"273.57000","22.79769","0.01392"
"273.90000","22.82525","0.01454"
"274.23000","22.85270","0.01397"
"274.56000","22.88026","0.01402"
"274.89000","22.90770","0.01411"
"275.22000","22.93521","0.01423"
"275.55000","22.96277","0.01388"
"275.88000","22.99021","0.01464"
"276.21000","23.01771","0.01379"
"276.54000","23.04522","0.01422"
"276.87000","23.07260","0.01434"
"277.20000","23.10028","0.01440"
"277.53000","23.12767","0.01464"
"277.86000","23.15517","0.01496"
"278.19000","23.18274","0.01486"
"278.52000","23.21018","0.01452"
"278.85000","23.23774","0.01427"
"279.18000","23.26518","0.01414"
"279.51000","23.29275","0.01472"
"279.84000","23.32025","0.01452"
"280.17000","23.34769","0.01385"
"280.50000","23.37526","0.01456"
"280.83000","23.40276","0.01447"
"281.16000","23.43014","0.01385"
"281.49000","23.45776","0.01421"
"281.82000","23.48521","0.01461"
"282.15000","23.51271","0.01489"
"282.48000","23.54028","0.01457"
"282.81000","23.56772","0.01452"
"283.14000","23.59522","0.01404"
"283.47000","23.62266","0.01472"
"283.80000","23.65017","0.01506"
"284.13000","23.67773","0.01477"
"284.46000","23.70518","0.01496"
"284.79000","23.73274","0.01491"
"285.12000","23.76024","0.01520"
"285.45000","23.78762","0.01414"
"285.78000","23.81525","0.01456"
"286.11000","23.84275","0.01502"
"286.44000","23.87025","0.01501"
"286.77000","23.89770","0.01473"
"287.10000","23.92520","0.01532"
"287.43000","23.95270","0.01537"
"287.76000","23.98027","0.01530"
"288.09000","24.00771","0.01521"
"288.42000","24.03527","0.01559"
"288.75000","24.06266","0.01536"
"289.08000","24.09022","0.01535"
"289.41000","24.11778","0.01493"
"289.74000","24.14517","0.01514"
"290.07000","24.17273","0.01491"
"290.40000","24.20023","0.01505"
"290.73000","24.22774","0.01420"
"291.06000","24.25524","0.01516"
"291.39000","24.28268","0.01513"
"291.72000","24.31025","0.01441"
"292.05000","24.33769","0.01491"
"292.38000","24.36519","0.01494"
"292.71000","24.39275","0.01461"
"293.04000","24.42020","0.01494"
"293.37000","24.44770","0.01508"
"293.70000","24.47527","0.01459"
"294.03000","24.50265","0.01543"
"294.36000","24.53021","0.01518"
"294.69000","24.55771","0.01508"
"295.02000","24.58522","0.01505"
"295.35000","24.61272","0.01542"
"295.68000","24.64017","0.01552"
"296.01000","24.66773","0.01509"
"296.34000","24.69523","0.01496"
"296.67000","24.72268","0.01435"
"297.00000","24.75030","0.01478"
"297.33000","24.77768","0.01456"
"297.66000","24.80524","0.01540"
"297.99000","24.83280","0.01516"
"298.32000","24.86019","0.01493"
"298.65000","24.88769","0.01564"
"298.98000","24.91520","0.01584"
"299.31000","24.94270","0.01571"
"299.64000","24.97026","0.01533"
"299.97000","24.99770","0.01518"
"300.30000","25.02527","0.01579"
"300.63000","25.05271","0.01534"
"300.96000","25.08022","0.01583"
"301.29000","25.10778","0.01557"
"301.62000","25.13522","0.01587"
"301.95000","25.16273","0.01520"
"302.28000","25.19017","0.01534"
"302.61000","25.21767","0.01603"
"302.94000","25.24523","0.01613"
"303.27000","25.27274","0.01637"
"303.60000","25.30024","0.01585"
"303.93000","25.32774","0.01600"
"304.26000","25.35519","0.01608"
"304.59000","25.38275","0.01591"
"304.92000","25.41019","0.01599"
"305.25000","25.43764","0.01545"
"305.58000","25.46526","0.01581"
"305.91000","25.49270","0.01617"
"306.24000","25.52021","0.01590"
"306.57000","25.54771","0.01553"
"306.90000","25.57515","0.01647"
"307.23000","25.60272","0.01650"
"307.56000","25.63016","0.01563"
"307.89000","25.65772","0.01625"
"308.22000","25.68522","0.01650"
"308.55000","25.71273","0.01632"
"308.88000","25.74017","0.01662"
"309.21000","25.76774","0.01581"
"309.54000","25.79524","0.01608"
"309.87000","25.82274","0.01626"
"310.20000","25.85018","0.01641"
"310.53000","25.87775","0.01634"
"310.86000","25.90525","0.01676"
"311.19000","25.93275","0.01650"
"311.52000","25.96025","0.01595"
"311.85000","25.98764","0.01658"
"312.18000","26.01520","0.01644"
"312.51000","26.04271","0.01566"
"312.84000","26.07021","0.01690"
"313.17000","26.09771","0.01670"
"313.50000","26.12522","0.01648"
"313.83000","26.15272","0.01668"
"314.16000","26.18022","0.01693"
"314.49000","26.20767","0.01651"
"314.82000","26.23523","0.01669"
"315.15000","26.26273","0.01711"
"315.48000","26.29017","0.01771"
"315.81000","26.31780","0.01694"
"316.14000","26.34518","0.01687"
"316.47000","26.37275","0.01724"
"316.80000","26.40025","0.01722"
"317.13000","26.42769","0.01716"
"317.46000","26.45520","0.01743"
"317.79000","26.48270","0.01763"
"318.12000","26.51026","0.01660"
"318.45000","26.53777","0.01689"
"318.78000","26.56521","0.01659"
"319.11000","26.59277","0.01698"
"319.44000","26.62021","0.01688"
"319.77000","26.64772","0.01678"
"320.10000","26.67528","0.01629"
"320.43000","26.70267","0.01632"
"320.76000","26.73023","0.01671"
"321.09000","26.75773","0.01700"
"321.42000","26.78523","0.01704"
"321.75000","26.81274","0.01737"
"322.08000","26.84012","0.01676"
"322.41000","26.86774","0.01731"
"322.74000","26.89524","0.01710"
"323.07000","26.92269","0.01750"
"323.40000","26.95025","0.01762"
"323.73000","26.97770","0.01773"
"324.06000","27.00520","0.01766"
"324.39000","27.03276","0.01765"
"324.72000","27.06020","0.01753"
"325.05000","27.08777","0.01753"
"325.38000","27.11515","0.01743"
"325.71000","27.14277","0.01743"
"326.04000","27.17022","0.01768"
"326.37000","27.19766","0.01747"
"326.70000","27.22528","0.01719"
"327.03000","27.25273","0.01606"
"327.36000","27.28017","0.01602"
"327.69000","27.30773","0.01586"
"328.02000","27.33518","0.01592"
"328.35000","27.36274","0.01561"
"328.68000","27.39024","0.01603"
"329.01000","27.41769","0.01645"
"329.34000","27.44525","0.01588"
"329.67000","27.47269","0.01617"
"330.00000","27.50026","0.01590"
"330.33000","27.52770","0.01643"
"330.66000","27.55514","0.01591"
"330.99000","27.58277","0.01602"
"331.32000","27.61021","0.01645"
"331.65000","27.63771","0.01645"
"331.98000","27.66522","0.01654"
"332.31000","27.69266","0.01615"
"332.64000","27.72022","0.01653"
"332.97000","27.74772","0.01666"
"333.30000","27.77523","0.01651"
"333.63000","27.80273","0.01636"
"333.96000","27.83017","0.01681"
"334.29000","27.85774","0.01626"
"334.62000","27.88524","0.01666"
"334.95000","27.91269","0.01669"
"335.28000","27.94025","0.01666"
"335.61000","27.96769","0.01687"
"335.94000","27.99519","0.01707"
"336.27000","28.02270","0.01702"
"336.60000","28.05020","0.01654"
"336.93000","28.07776","0.01693"
"337.26000","28.10521","0.01696"
"337.59000","28.13271","0.01707"
"337.92000","28.16027","0.01687"
"338.25000","28.18765","0.01686"
"338.58000","28.21522","0.01730"
"338.91000","28.24278","0.01710"
"339.24000","28.27017","0.01665"
"339.57000","28.29773","0.01724"
"339.90000","28.32523","0.01787"
"340.23000","28.35274","0.01655"
"340.56000","28.38024","0.01759"
"340.89000","28.40762","0.01773"
"341.22000","28.43524","0.01777"
"341.55000","28.46275","0.01746"
"341.88000","28.49019","0.01813"
"342.21000","28.51775","0.01813"
"342.54000","28.54514","0.01794"
"342.87000","28.57270","0.01794"
"343.20000","28.60020","0.01739"
"343.53000","28.62771","0.01784"
"343.86000","28.65527","0.01790"
"344.19000","28.68271","0.01787"
"344.52000","28.71022","0.01810"
"344.85000","28.73772","0.01842"
"345.18000","28.76516","0.01898"
"345.51000","28.79273","0.01859"
"345.84000","28.82023","0.01794"
"346.17000","28.84773","0.01811"
"346.50000","28.87530","0.01833"
"346.83000","28.90268","0.01840"
"347.16000","28.93024","0.01865"
"347.49000","28.95774","0.01866"
"347.82000","28.98519","0.01885"
"348.15000","29.01275","0.01889"
"348.48000","29.04020","0.01872"
"348.81000","29.06770","0.01874"
"349.14000","29.09526","0.01918"
"349.47000","29.12271","0.01876"
"349.80000","29.15027","0.01908"
"350.13000","29.17777","0.01937"
"350.46000","29.20521","0.01931"
"350.79000","29.23278","0.01970"
"351.12000","29.26016","0.01948"
"351.45000","29.28773","0.01951"
"351.78000","29.31523","0.01974"
"352.11000","29.34273","0.02003"
"352.44000","29.37024","0.01940"
"352.77000","29.39768","0.01982"
"353.10000","29.42524","0.02039"
"353.43000","29.45274","0.01973"
"353.76000","29.48019","0.02058"
"354.09000","29.50775","0.02066"
"354.42000","29.53525","0.02073"
"354.75000","29.56276","0.02064"
"355.08000","29.59026","0.02017"
"355.41000","29.61770","0.02061"
"355.74000","29.64526","0.02078"
"356.07000","29.67271","0.02080"
"356.40000","29.70021","0.02085"
"356.73000","29.72778","0.02077"
"357.06000","29.75516","0.02120"
"357.39000","29.78272","0.02083"
"357.72000","29.81022","0.02142"
"358.05000","29.83767","0.02133"
"358.38000","29.86523","0.02154"
"358.71000","29.89273","0.02135"
"359.04000","29.92024","0.02122"
"359.37000","29.94774","0.02146"
"359.70000","29.97519","0.02191"
"360.03000","30.00275","0.02190"
"360.36000","30.03025","0.02198"
"360.69000","30.05769","0.02198"
"361.02000","30.08526","0.02193"
"361.35000","30.11264","0.02205"
"361.68000","30.14020","0.02198"
"362.01000","30.16771","0.02262"
"362.34000","30.19521","0.02261"
"362.67000","30.22271","0.02216"
"363.00000","30.25022","0.02268"
"363.33000","30.27772","0.02228"
"363.66000","30.30522","0.02261"
"363.99000","30.33267","0.02327"
"364.32000","30.36023","0.02295"
"364.65000","30.38773","0.02301"
"364.98000","30.41518","0.02308"
"365.31000","30.44274","0.02322"
"365.64000","30.47018","0.02334"
"365.97000","30.49768","0.02316"
"366.30000","30.52525","0.02346"
"366.63000","30.55269","0.02406"
"366.96000","30.58020","0.02387"
"367.29000","30.60770","0.02422"
"367.62000","30.63526","0.02397"
"367.95000","30.66276","0.02422"
"368.28000","30.69015","0.02460"
"368.61000","30.71777","0.02461"
"368.94000","30.74521","0.02431"
"369.27000","30.77272","0.02511"
"369.60000","30.80028","0.02487"
"369.93000","30.82766","0.02525"
"370.26000","30.85523","0.02525"
"370.59000","30.88273","0.02497"
"370.92000","30.91023","0.02517"
"371.25000","30.93773","0.02576"
"371.58000","30.96518","0.02559"
"371.91000","30.99268","0.02589"
"372.24000","31.02025","0.02606"
"372.57000","31.04769","0.02613"
"372.90000","31.07525","0.02632"
"373.23000","31.10270","0.02655"
"373.56000","31.13020","0.02699"
"373.89000","31.15770","0.02689"
"374.22000","31.18521","0.02731"
"374.55000","31.21277","0.02771"
"374.88000","31.24027","0.02731"
"375.21000","31.26771","0.02670"
"375.54000","31.29528","0.02766"
"375.87000","31.32266","0.02821"
"376.20000","31.35028","0.02738"
"376.53000","31.37773","0.02774"
"376.86000","31.40523","0.02817"
"377.19000","31.43273","0.02736"
"377.52000","31.46024","0.02746"
"377.85000","31.48768","0.02801"
"378.18000","31.51524","0.02816"
"378.51000","31.54274","0.02863"
"378.84000","31.57025","0.02848"
"379.17000","31.59769","0.02907"
"379.50000","31.62526","0.02880"
"379.83000","31.65276","0.02922"
"380.16000","31.68014","0.02917"
"380.49000","31.70776","0.02943"
"380.82000","31.73521","0.02992"
"381.15000","31.76271","0.03020"
"381.48000","31.79021","0.03017"
"381.81000","31.81771","0.03065"
"382.14000","31.84522","0.03032"
"382.47000","31.87272","0.03080"
"382.80000","31.90023","0.03088"
"383.13000","31.92773","0.03121"
"383.46000","31.95517","0.03165"
"383.79000","31.98273","0.03176"
"384.12000","32.01030","0.03237"
"384.45000","32.03768","0.03266"
"384.78000","32.06525","0.03265"
"385.11000","32.09275","0.03231"
"385.44000","32.12019","0.03307"
"385.77000","32.14775","0.03333"
"386.10000","32.17520","0.03324"
"386.43000","32.20276","0.03365"
"386.76000","32.23021","0.03354"
"387.09000","32.25771","0.03363"
"387.42000","32.28521","0.03455"
"387.75000","32.31271","0.03446"
"388.08000","32.34022","0.03504"
"388.41000","32.36772","0.03525"
"388.74000","32.39516","0.03579"
"389.07000","32.42279","0.03634"
"389.40000","32.45023","0.03634"
"389.73000","32.47773","0.03622"
"390.06000","32.50524","0.03650"
"390.39000","32.53274","0.03684"
"390.72000","32.56025","0.03744"
"391.05000","32.58768","0.03736"
"391.38000","32.61519","0.03847"
"391.71000","32.64275","0.03873"
"392.04000","32.67020","0.03852"
"392.37000","32.69776","0.03881"
"392.70000","32.72526","0.03927"
"393.03000","32.75270","0.03903"
"393.36000","32.78021","0.04000"
"393.69000","32.80771","0.04040"
"394.02000","32.83522","0.04037"
"394.35000","32.86278","0.04097"
"394.68000","32.89016","0.04073"
"395.01000","32.91779","0.04112"
"395.34000","32.94517","0.04163"
"395.67000","32.97267","0.04172"
"396.00000","33.00023","0.04220"
"396.33000","33.02768","0.04329"
"396.66000","33.05530","0.04324"
"396.99000","33.08274","0.04411"
"397.32000","33.11019","0.04498"
"397.65000","33.13769","0.04458"
"397.98000","33.16520","0.04503"
"398.31000","33.19276","0.04587"
"398.64000","33.22020","0.04676"
"398.97000","33.24770","0.04654"
"399.30000","33.27521","0.04675"
"399.63000","33.30271","0.04707"
"399.96000","33.33021","0.04797"
"400.29000","33.35772","0.04849"
"400.62000","33.38516","0.04872"
"400.95000","33.41278","0.04954"
"401.28000","33.44022","0.04969"
"401.61000","33.46773","0.05060"
"401.94000","33.49523","0.05039"
"402.27000","33.52262","0.05170"
"402.60000","33.55024","0.05262"
"402.93000","33.57780","0.05302"
"403.26000","33.60518","0.05316"
"403.59000","33.63275","0.05379"
"403.92000","33.66019","0.05518"
"404.25000","33.68776","0.05515"
"404.58000","33.71519","0.05663"
"404.91000","33.74270","0.05674"
"405.24000","33.77026","0.05692"
"405.57000","33.79771","0.05771"
"405.90000","33.82521","0.05782"
"406.23000","33.85278","0.05898"
"406.56000","33.88015","0.05997"
"406.89000","33.90772","0.06012"
"407.22000","33.93528","0.06060"
"407.55000","33.96273","0.06136"
"407.88000","33.99023","0.06212"
"408.21000","34.01773","0.06223"
"408.54000","34.04517","0.06346"
"408.87000","34.07268","0.06368"
"409.20000","34.10018","0.06429"
"409.53000","34.12775","0.06463"
"409.86000","34.15519","0.06555"
"410.19000","34.18269","0.06579"
"410.52000","34.21031","0.06596"
"410.85000","34.23764","0.06707"
"411.18000","34.26520","0.06710"
"411.51000","34.29277","0.06705"
"411.84000","34.32021","0.06813"
"412.17000","34.34771","0.06807"
"412.50000","34.37521","0.06907"
"412.83000","34.40277","0.06938"
"413.16000","34.43022","0.06961"
"413.49000","34.45766","0.07031"
"413.82000","34.48529","0.07050"
"414.15000","34.51267","0.07075"
"414.48000","34.54017","0.07137"
"414.81000","34.56774","0.07173"
"415.14000","34.59512","0.07193"
"415.47000","34.62275","0.07229"
"415.80000","34.65025","0.07290"
"416.13000","34.67775","0.07317"
"416.46000","34.70525","0.07295"
"416.79000","34.73264","0.07362"
"417.12000","34.76020","0.07358"
"417.45000","34.78770","0.07404"
"417.78000","34.81515","0.07427"
"418.11000","34.84277","0.07466"
"418.44000","34.87021","0.07517"
"418.77000","34.89772","0.07522"
"419.10000","34.92528","0.07539"
"419.43000","34.95266","0.07595"
"419.76000","34.98022","0.07611"
"420.09000","35.00772","0.07633"
"420.42000","35.03523","0.07703"
"420.75000","35.06279","0.07746"
"421.08000","35.09018","0.07786"
"421.41000","35.11780","0.07834"
"421.74000","35.14519","0.07853"
"422.07000","35.17269","0.07870"
"422.40000","35.20025","0.07928"
"422.73000","35.22770","0.07944"
"423.06000","35.25526","0.07995"
"423.39000","35.28276","0.08048"
"423.72000","35.31026","0.08108"
"424.05000","35.33770","0.08148"
"424.38000","35.36521","0.08194"
"424.71000","35.39271","0.08245"
"425.04000","35.42028","0.08288"
"425.37000","35.44766","0.08397"
"425.70000","35.47522","0.08384"
"426.03000","35.50272","0.08506"
"426.36000","35.53017","0.08561"
"426.69000","35.55773","0.08646"
"427.02000","35.58524","0.08712"
"427.35000","35.61268","0.08769"
"427.68000","35.64024","0.08809"
"428.01000","35.66768","0.08950"
"428.34000","35.69525","0.09008"
"428.67000","35.72275","0.09094"
"429.00000","35.75019","0.09175"
"429.33000","35.77782","0.09272"
"429.66000","35.80514","0.09303"
"429.99000","35.83276","0.09440"
"430.32000","35.86027","0.09593"
"430.65000","35.88771","0.09663"
"430.98000","35.91521","0.09730"
"431.31000","35.94272","0.09855"
"431.64000","35.97028","0.09976"
"431.97000","35.99772","0.10051"
"432.30000","36.02523","0.10212"
"432.63000","36.05273","0.10333"
"432.96000","36.08017","0.10514"
"433.29000","36.10774","0.10601"
"433.62000","36.13530","0.10774"
"433.95000","36.16268","0.10902"
"434.28000","36.19025","0.11115"
"434.61000","36.21775","0.11201"
"434.94000","36.24519","0.11397"
"435.27000","36.27270","0.11506"
"435.60000","36.30014","0.11619"
"435.93000","36.32776","0.11818"
"436.26000","36.35521","0.11930"
"436.59000","36.38271","0.12047"
"436.92000","36.41027","0.12165"
"437.25000","36.43765","0.12286"
"437.58000","36.46522","0.12310"
"437.91000","36.49272","0.12527"
"438.24000","36.52016","0.12598"
"438.57000","36.54773","0.12706"
"438.90000","36.57523","0.12837"
"439.23000","36.60273","0.12903"
"439.56000","36.63023","0.13047"
"439.89000","36.65768","0.13186"
"440.22000","36.68524","0.13274"
"440.55000","36.71275","0.13382"
"440.88000","36.74019","0.13455"
"441.21000","36.76781","0.13544"
"441.54000","36.79520","0.13671"
"441.87000","36.82276","0.13725"
"442.20000","36.85026","0.13859"
"442.53000","36.87771","0.13946"
"442.86000","36.90515","0.14062"
"443.19000","36.93271","0.14166"
"443.52000","36.96021","0.14283"
"443.85000","36.98778","0.14357"
"444.18000","37.01516","0.14506"
"444.51000","37.04279","0.14521"
"444.84000","37.07023","0.14641"
"445.17000","37.09767","0.14653"
"445.50000","37.12529","0.14778"
"445.83000","37.15268","0.14863"
"446.16000","37.18024","0.14942"
"446.49000","37.20768","0.15006"
"446.82000","37.23525","0.15127"
"447.15000","37.26269","0.15163"
"447.48000","37.29019","0.15309"
"447.81000","37.31776","0.15468"
"448.14000","37.34520","0.15576"
"448.47000","37.37265","0.15696"
"448.80000","37.40027","0.15762"
"449.13000","37.42771","0.15872"
"449.46000","37.45527","0.15961"
"449.79000","37.48272","0.16103"
"450.12000","37.51022","0.16210"
"450.45000","37.53772","0.16324"
"450.78000","37.56522","0.16485"
"451.11000","37.59273","0.16553"
"451.44000","37.62023","0.16653"
"451.77000","37.64774","0.16722"
"452.10000","37.67524","0.16842"
"452.43000","37.70274","0.16948"
"452.76000","37.73018","0.17009"
"453.09000","37.75775","0.17141"
"453.42000","37.78519","0.17221"
"453.75000","37.81276","0.17330"
"454.08000","37.84026","0.17418"
"454.41000","37.86770","0.17531"
"454.74000","37.89526","0.17627"
"455.07000","37.92265","0.17669"
"455.40000","37.95015","0.17752"
"455.73000","37.97771","0.17870"
"456.06000","38.00510","0.17925"
"456.39000","38.03278","0.17994"
"456.72000","38.06016","0.18061"
"457.05000","38.08767","0.18008"
"457.38000","38.11523","0.18058"
"457.71000","38.14273","0.18243"
"458.04000","38.17024","0.18324"
"458.37000","38.19774","0.18391"
"458.70000","38.22524","0.18481"
"459.03000","38.25280","0.18448"
"459.36000","38.28019","0.18493"
"459.69000","38.30769","0.18608"
"460.02000","38.33525","0.18620"
"460.35000","38.36270","0.18661"
"460.68000","38.39026","0.18737"
"461.01000","38.41776","0.18800"
"461.34000","38.44521","0.18829"
"461.67000","38.47271","0.18902"
"462.00000","38.50022","0.18999"
"462.33000","38.52778","0.19028"
"462.66000","38.55528","0.19115"
"462.99000","38.58266","0.19238"
"463.32000","38.61029","0.19257"
"463.65000","38.63767","0.19302"
"463.98000","38.66518","0.19444"
"464.31000","38.69273","0.19561"
"464.64000","38.72018","0.19602"
"464.97000","38.74774","0.19739"
"465.30000","38.77519","0.19792"
"465.63000","38.80269","0.19894"
"465.96000","38.83020","0.19994"
"466.29000","38.85764","0.20130"
"466.62000","38.88526","0.20130"
"466.95000","38.91276","0.20214"
"467.28000","38.94020","0.20337"
"467.61000","38.96777","0.20354"
"467.94000","38.99521","0.20275"
"468.27000","39.02271","0.01093"
"468.60000","39.05022","0.01289"
"468.93000","39.07772","0.00871"
"469.26000","39.10522","0.00533"
"469.59000","39.13272","0.00777"
"469.92000","39.16023","0.00887"
"470.25000","39.18773","0.00737"
"470.58000","39.21512","0.00708"
"470.91000","39.24274","0.00749"
"471.24000","39.27024","0.00673"
"471.57000","39.29768","0.00762"
"471.90000","39.32525","0.00690"
"472.23000","39.35269","0.00814"
"472.56000","39.38025","0.00678"
"472.89000","39.40770","0.00700"
"473.22000","39.43520","0.00640"
"473.55000","39.46277","0.00724"
"473.88000","39.49015","0.00673"
"474.21000","39.51777","0.00758"
"474.54000","39.54528","0.00613"
"474.87000","39.57266","0.00682"
"475.20000","39.60022","0.00707"
"475.53000","39.62772","0.00805"
"475.86000","39.65523","0.00674"
"476.19000","39.68279","0.00657"
"476.52000","39.71024","0.00668"
"476.85000","39.73774","0.00772"
"477.18000","39.76524","0.00666"
"477.51000","39.79269","0.00744"
"477.84000","39.82025","0.00715"
"478.17000","39.84769","0.00696"
"478.50000","39.87519","0.00706"
"478.83000","39.90276","0.00724"
"479.16000","39.93014","0.00796"
"479.49000","39.95776","0.00717"
"479.82000","39.98526","0.00609"
"480.15000","40.01271","0.00674"
"480.48000","40.04021","0.00686"
"480.81000","40.06772","0.00762"
"481.14000","40.09516","0.00684"
"481.47000","40.12272","0.00755"
"481.80000","40.15023","0.00763"
"482.13000","40.17778","0.00703"
"482.46000","40.20517","0.00787"
"482.79000","40.23273","0.00711"
"483.12000","40.26024","0.00753"
"483.45000","40.28762","0.00677"
"483.78000","40.31524","0.00150"
"484.11000","40.34275","0.00762"
"484.44000","40.37025","0.00671"
"484.77000","40.39770","0.00807"
"485.10000","40.42520","0.00707"
"485.43000","40.45270","0.00721"
"485.76000","40.48020","0.00702"
"486.09000","40.50765","0.00746"
"486.42000","40.53527","0.00705"
"486.75000","40.56271","0.00745"
"487.08000","40.59022","0.00688"
"487.41000","40.61777","0.00699"
"487.74000","40.64516","0.00759"
"488.07000","40.67272","0.00733"
"488.40000","40.70017","0.00788"
"488.73000","40.72773","0.00741"
"489.06000","40.75524","0.00773"
"489.39000","40.78268","0.00775"
"489.72000","40.81024","0.00789"
"490.05000","40.83775","0.00767"
"490.38000","40.86519","0.00780"
"490.71000","40.89275","0.00752"
"490.80200","40.90041","0.00805"