File: Force_trajectories/170107_1/Specimen_RawData_1.csv
End date,"1/7/2017"
Specimen label,"18CT_45"
Maximum Load,"0.05629",N

Time,Extension,Load
(s),(mm),(N)
"0.00000","0.00000","-0.00041"
"0.42600","0.03569","0.00045"
"0.85200","0.07121","0.00065"
"1.27800","0.10666","0.00120"
"1.70400","0.14212","0.00162"
"2.13000","0.17763","0.00180"
"2.55600","0.21309","0.00175"
"2.98200","0.24866","0.00156"
"3.40800","0.28412","0.00175"
"3.83400","0.31958","0.00214"
"4.26000","0.35515","0.00267"
"4.68600","0.39066","0.00284"
"5.11200","0.42612","0.00294"
"5.53800","0.46163","0.00258"
"5.96400","0.49709","0.00301"
"6.39000","0.53261","0.00318"
"6.81600","0.56812","0.00300"
"7.24200","0.60364","0.00374"
"7.66800","0.63909","0.00403"
"8.09400","0.67461","0.00353"
"8.52000","0.71012","0.00389"
"8.94600","0.74570","0.00354"
"9.37200","0.78115","0.00447"
"9.79800","0.81661","0.00410"
"10.22400","0.85212","0.00421"
"10.65000","0.88764","0.00440"
"11.07600","0.92321","0.00452"
"11.50200","0.95873","0.00457"
"11.92800","0.99412","0.00454"
"12.35400","1.02958","0.00473"
"12.78000","1.06515","0.00417"
"13.20600","1.10067","0.00443"
"13.63200","1.13618","0.00446"
"14.05800","1.17164","0.00479"
"14.48400","1.20709","0.00496"
"14.91000","1.24267","0.00484"
"15.33600","1.27812","0.00482"
"15.76200","1.31358","0.00497"
"16.18800","1.34909","0.00550"
"16.61400","1.38461","0.00558"
"17.04000","1.42012","0.00548"
"17.46600","1.45564","0.00600"
"17.89200","1.49115","0.00548"
"18.31800","1.52661","0.00605"
"18.74400","1.56212","0.00637"
"19.17000","1.59764","0.00650"
"19.59600","1.63315","0.00672"
"20.02200","1.66867","0.00686"
"20.44800","1.70412","0.00672"
"20.87400","1.73964","0.00709"
"21.30000","1.77515","0.00710"
"21.72600","1.81067","0.00635"
"22.15200","1.84612","0.00680"
"22.57800","1.88158","0.00698"
"23.00400","1.91715","0.00715"
"23.43000","1.95273","0.00754"
"23.85600","1.98818","0.00732"
"24.28200","2.02364","0.00768"
"24.70800","2.05909","0.00779"
"25.13400","2.09461","0.00818"
"25.56000","2.13012","0.00792"
"25.98600","2.16564","0.00770"
"26.41200","2.20109","0.00860"
"26.83800","2.23667","0.00862"
"27.26400","2.27212","0.00886"
"27.69000","2.30770","0.00875"
"28.11600","2.34315","0.00915"
"28.54200","2.37855","0.00907"
"28.96800","2.41412","0.00926"
"29.39400","2.44964","0.00966"
"29.82000","2.48509","0.00968"
"30.24600","2.52067","0.01003"
"30.67200","2.55606","0.01009"
"31.09800","2.59158","0.01039"
"31.52400","2.62715","0.01027"
"31.95000","2.66267","0.01076"
"32.37600","2.69812","0.01092"
"32.80200","2.73358","0.01085"
"33.22800","2.76915","0.01093"
"33.65400","2.80467","0.01158"
"34.08000","2.84012","0.01094"
"34.50600","2.87564","0.01186"
"34.93200","2.91109","0.01216"
"35.35800","2.94667","0.01198"
"35.78400","2.98212","0.01258"
"36.21000","3.01770","0.01214"
"36.63600","3.05309","0.01285"
"37.06200","3.08861","0.01262"
"37.48800","3.12418","0.01240"
"37.91400","3.15958","0.01248"
"38.34000","3.19509","0.01286"
"38.76600","3.23061","0.01370"
"39.19200","3.26612","0.01333"
"39.61800","3.30170","0.01358"
"40.04400","3.33721","0.01376"
"40.47000","3.37261","0.01388"
"40.89600","3.40812","0.01368"
"41.32200","3.44364","0.01335"
"41.74800","3.47915","0.01345"
"42.17400","3.51461","0.01380"
"42.60000","3.55012","0.01415"
"43.02600","3.58558","0.01380"
"43.45200","3.62109","0.01364"
"43.87800","3.65661","0.01411"
"44.30400","3.69218","0.01414"
"44.73000","3.72764","0.01316"
"45.15600","3.76309","0.01372"
"45.58200","3.79861","0.01433"
"46.00800","3.83412","0.01443"
"46.43400","3.86964","0.01504"
"46.86000","3.90509","0.01469"
"47.28600","3.94061","0.01455"
"47.71200","3.97612","0.01446"
"48.13800","4.01164","0.01517"
"48.56400","4.04715","0.01533"
"48.99000","4.08255","0.01596"
"49.41600","4.11812","0.01543"
"49.84200","4.15364","0.01599"
"50.26800","4.18915","0.01637"
"50.69400","4.22461","0.01610"
"51.12000","4.26006","0.01622"
"51.54600","4.29570","0.01653"
"51.97200","4.33121","0.01732"
"52.39800","4.36673","0.01732"
"52.82400","4.40218","0.01757"
"53.25000","4.43758","0.01724"
"53.67600","4.47315","0.01789"
"54.10200","4.50867","0.01788"
"54.52800","4.54418","0.01758"
"54.95400","4.57958","0.01845"
"55.38000","4.61509","0.01857"
"55.80600","4.65067","0.01839"
"56.23200","4.68612","0.01385"
"56.65800","4.72164","0.01409"
"57.08400","4.75703","0.01346"
"57.51000","4.79261","0.01299"
"57.93600","4.82818","0.01315"
"58.36200","4.86364","0.01420"
"58.78800","4.89909","0.01336"
"59.21400","4.93455","0.01394"
"59.64000","4.97006","0.01394"
"60.06600","5.00570","0.01425"
"60.49200","5.04109","0.01509"
"60.91800","5.07661","0.01510"
"61.34400","5.11212","0.01482"
"61.77000","5.14764","0.01003"
"62.19600","5.18315","0.01010"
"62.62200","5.21867","0.01067"
"63.04800","5.25412","0.01073"
"63.47400","5.28958","0.01058"
"63.90000","5.32515","0.01099"
"64.32600","5.36067","0.01012"
"64.75200","5.39618","0.01094"
"65.17800","5.43158","0.01051"
"65.60400","5.46710","0.00953"
"66.03000","5.50267","0.01050"
"66.45600","5.53818","0.00971"
"66.88200","5.57364","0.00982"
"67.30800","5.60916","0.00959"
"67.73400","5.64461","0.00957"
"68.16000","5.68019","0.01048"
"68.58600","5.71564","0.01044"
"69.01200","5.75115","0.01082"
"69.43800","5.78655","0.01067"
"69.86400","5.82213","0.01115"
"70.29000","5.85764","0.01113"
"70.71600","5.89316","0.01215"
"71.14200","5.92861","0.01178"
"71.56800","5.96407","0.01126"
"71.99400","5.99958","0.01189"
"72.42000","6.03516","0.01168"
"72.84600","6.07067","0.01241"
"73.27200","6.10613","0.01200"
"73.69800","6.14152","0.01260"
"74.12400","6.17716","0.01267"
"74.55000","6.21267","0.01289"
"74.97600","6.24819","0.01288"
"75.40200","6.28364","0.01355"
"75.82800","6.31910","0.01385"
"76.25400","6.35461","0.01357"
"76.68000","6.39013","0.01383"
"77.10600","6.42564","0.01425"
"77.53200","6.46116","0.01459"
"77.95800","6.49661","0.01521"
"78.38400","6.53213","0.01443"
"78.81000","6.56764","0.01481"
"79.23600","6.60316","0.01484"
"79.66200","6.63861","0.01491"
"80.08800","6.67419","0.01607"
"80.51400","6.70964","0.01574"
"80.94000","6.74516","0.01584"
"81.36600","6.78067","0.01583"
"81.79200","6.81613","0.01650"
"82.21800","6.85164","0.01647"
"82.64400","6.88716","0.01618"
"83.07000","6.92267","0.01713"
"83.49600","6.95807","0.01738"
"83.92200","6.99358","0.01721"
"84.34800","7.02910","0.01759"
"84.77400","7.06467","0.01704"
"85.20000","7.10013","0.01768"
"85.62600","7.13558","0.01818"
"86.05200","7.17116","0.01816"
"86.47800","7.20667","0.01768"
"86.90400","7.24213","0.01834"
"87.33000","7.27770","0.01824"
"87.75600","7.31310","0.01870"
"88.18200","7.34861","0.01886"
"88.60800","7.38413","0.01925"
"89.03400","7.41958","0.01953"
"89.46000","7.45510","0.01921"
"89.88600","7.49055","0.01978"
"90.31200","7.52613","0.01968"
"90.73800","7.56164","0.01965"
"91.16400","7.59716","0.01178"
"91.59000","7.63267","0.01326"
"92.01600","7.66807","0.01303"
"92.44200","7.70364","0.01302"
"92.86800","7.73922","0.01379"
"93.29400","7.77467","0.01375"
"93.72000","7.81013","0.01384"
"94.14600","7.84564","0.01459"
"94.57200","7.88116","0.01491"
"94.99800","7.91661","0.01536"
"95.42400","7.95219","0.01492"
"95.85000","7.98758","0.01584"
"96.27600","8.02310","0.01582"
"96.70200","8.05861","0.01577"
"97.12800","8.09413","0.01523"
"97.55400","8.12964","0.01569"
"97.98000","8.16516","0.01549"
"98.40600","8.20061","0.01596"
"98.83200","8.23619","0.01584"
"99.25800","8.27158","0.01631"
"99.68400","8.30716","0.01621"
"100.11000","8.34255","0.01668"
"100.53600","8.37813","0.01638"
"100.96200","8.41364","0.01753"
"101.38800","8.44916","0.01775"
"101.81400","8.48461","0.01721"
"102.24000","8.52007","0.01758"
"102.66600","8.55564","0.01779"
"103.09200","8.59116","0.01828"
"103.51800","8.62661","0.01771"
"103.94400","8.66213","0.01830"
"104.37000","8.69764","0.01810"
"104.79600","8.73316","0.01788"
"105.22200","8.76867","0.01851"
"105.64800","8.80419","0.01847"
"106.07400","8.83964","0.01839"
"106.50000","8.87516","0.01835"
"106.92600","8.91067","0.01814"
"107.35200","8.94613","0.01516"
"107.77800","8.98170","0.01563"
"108.20400","9.01710","0.01600"
"108.63000","9.05255","0.01595"
"109.05600","9.08813","0.01565"
"109.48200","9.12364","0.00719"
"109.90800","9.15910","0.00768"
"110.33400","9.19455","0.00773"
"110.76000","9.23013","0.00833"
"111.18600","9.26564","0.00830"
"111.61200","9.30110","0.00828"
"112.03800","9.33661","0.00879"
"112.46400","9.37201","0.00937"
"112.89000","9.40764","0.00891"
"113.31600","9.44316","0.00930"
"113.74200","9.47861","0.00937"
"114.16800","9.51413","0.00988"
"114.59400","9.54958","0.01063"
"115.02000","9.58510","0.01020"
"115.44600","9.62067","0.01045"
"115.87200","9.65613","0.01126"
"116.29800","9.69158","0.01120"
"116.72400","9.72704","0.01163"
"117.15000","9.76267","0.01111"
"117.57600","9.79819","0.01191"
"118.00200","9.83364","0.01221"
"118.42800","9.86910","0.01253"
"118.85400","9.90461","0.01251"
"119.28000","9.94019","0.01259"
"119.70600","9.97570","0.01301"
"120.13200","10.01116","0.01297"
"120.55800","10.04661","0.01330"
"120.98400","10.08213","0.01339"
"121.41000","10.11764","0.01375"
"121.83600","10.15316","0.01432"
"122.26200","10.18861","0.01418"
"122.68800","10.22407","0.01414"
"123.11400","10.25959","0.01440"
"123.54000","10.29516","0.01462"
"123.96600","10.33061","0.01453"
"124.39200","10.36613","0.01382"
"124.81800","10.40158","0.01392"
"125.24400","10.43710","0.01487"
"125.67000","10.47268","0.01424"
"126.09600","10.50819","0.01464"
"126.52200","10.54359","0.01508"
"126.94800","10.57910","0.01536"
"127.37400","10.61455","0.01526"
"127.80000","10.65013","0.01422"
"128.22600","10.68565","0.01455"
"128.65200","10.72110","0.01400"
"129.07800","10.75662","0.01454"
"129.50400","10.79213","0.01408"
"129.93000","10.82759","0.01333"
"130.35600","10.86316","0.01357"
"130.78200","10.89862","0.01329"
"131.20800","10.93413","0.01369"
"131.63400","10.96964","0.01342"
"132.06000","11.00516","0.01335"
"132.48600","11.04062","0.01373"
"132.91200","11.07607","0.01400"
"133.33800","11.11165","0.01380"
"133.76400","11.14716","0.01391"
"134.19000","11.18268","0.01390"
"134.61600","11.21819","0.01213"
"135.04200","11.25359","0.01258"
"135.46800","11.28916","0.01264"
"135.89400","11.32468","0.01327"
"136.32000","11.36019","0.01379"
"136.74600","11.39565","0.01354"
"137.17200","11.43110","0.01374"
"137.59800","11.46668","0.01400"
"138.02400","11.50213","0.01388"
"138.45000","11.53765","0.01454"
"138.87600","11.57310","0.01454"
"139.30200","11.60862","0.01510"
"139.72800","11.64413","0.01418"
"140.15400","11.67959","0.01530"
"140.58000","11.71510","0.01546"
"141.00600","11.75062","0.01591"
"141.43200","11.78613","0.01480"
"141.85800","11.82165","0.01515"
"142.28400","11.85716","0.01529"
"142.71000","11.89262","0.01509"
"143.13600","11.92807","0.01523"
"143.56200","11.96365","0.01587"
"143.98800","11.99916","0.01569"
"144.41400","12.03468","0.01561"
"144.84000","12.07013","0.01575"
"145.26600","12.10559","0.01553"
"145.69200","12.14110","0.01629"
"146.11800","12.17668","0.01667"
"146.54400","12.21213","0.01664"
"146.97000","12.24759","0.01644"
"147.39600","12.28316","0.01688"
"147.82200","12.31862","0.01675"
"148.24800","12.35419","0.01751"
"148.67400","12.38971","0.01759"
"149.10000","12.42510","0.01740"
"149.52600","12.46062","0.01793"
"149.95200","12.49619","0.01754"
"150.37800","12.53165","0.01793"
"150.80400","12.56716","0.01766"
"151.23000","12.60256","0.01704"
"151.65600","12.63807","0.01681"
"152.08200","12.67365","0.01709"
"152.50800","12.70916","0.01689"
"152.93400","12.74456","0.01599"
"153.36000","12.78007","0.01652"
"153.78600","12.81559","0.01685"
"154.21200","12.85116","0.01673"
"154.63800","12.88668","0.01423"
"155.06400","12.92207","0.01490"
"155.49000","12.95753","0.01514"
"155.91600","12.99316","0.01536"
"156.34200","13.02862","0.01656"
"156.76800","13.06413","0.01636"
"157.19400","13.09959","0.01658"
"157.62000","13.13510","0.01628"
"158.04600","13.17062","0.01710"
"158.47200","13.20613","0.01729"
"158.89800","13.24165","0.01710"
"159.32400","13.27710","0.01727"
"159.75000","13.31256","0.01731"
"160.17600","13.34819","0.01645"
"160.60200","13.38371","0.01670"
"161.02800","13.41916","0.01668"
"161.45400","13.45462","0.01688"
"161.88000","13.49013","0.01711"
"162.30600","13.52571","0.01659"
"162.73200","13.56116","0.01688"
"163.15800","13.59662","0.01681"
"163.58400","13.63207","0.01781"
"164.01000","13.66765","0.01766"
"164.43600","13.70316","0.01745"
"164.86200","13.73862","0.01713"
"165.28800","13.77407","0.01769"
"165.71400","13.80959","0.01762"
"166.14000","13.84510","0.01796"
"166.56600","13.88062","0.01771"
"166.99200","13.91613","0.01477"
"167.41800","13.95159","0.01422"
"167.84400","13.98710","0.01453"
"168.27000","14.02262","0.01459"
"168.69600","14.05813","0.01501"
"169.12200","14.09365","0.01548"
"169.54800","14.12904","0.01540"
"169.97400","14.16462","0.01597"
"170.40000","14.20013","0.01573"
"170.82600","14.23565","0.01640"
"171.25200","14.27110","0.01665"
"171.67800","14.30662","0.01647"
"172.10400","14.34213","0.01667"
"172.53000","14.37765","0.01671"
"172.95600","14.41317","0.01512"
"173.38200","14.44868","0.01617"
"173.80800","14.48407","0.01504"
"174.23400","14.51971","0.01563"
"174.66000","14.55516","0.01506"
"175.08600","14.59068","0.01496"
"175.51200","14.62608","0.01533"
"175.93800","14.66159","0.01556"
"176.36400","14.69716","0.01539"
"176.79000","14.73262","0.01481"
"177.21600","14.76820","0.01553"
"177.64200","14.80359","0.01547"
"178.06800","14.83911","0.01439"
"178.49400","14.87462","0.01441"
"178.92000","14.91013","0.01441"
"179.34600","14.94559","0.01483"
"179.77200","14.98105","0.01457"
"180.19800","15.01662","0.01516"
"180.62400","15.05213","0.01519"
"181.05000","15.08759","0.01512"
"181.47600","15.12317","0.01519"
"181.90200","15.15856","0.01503"
"182.32800","15.19414","0.01550"
"182.75400","15.22971","0.01565"
"183.18000","15.26517","0.01614"
"183.60600","15.30062","0.01618"
"184.03200","15.33614","0.01618"
"184.45800","15.37165","0.01600"
"184.88400","15.40717","0.01599"
"185.31000","15.44268","0.01606"
"185.73600","15.47814","0.01649"
"186.16200","15.51353","0.01655"
"186.58800","15.54917","0.01646"
"187.01400","15.58468","0.01627"
"187.44000","15.62020","0.01647"
"187.86600","15.65565","0.01688"
"188.29200","15.69110","0.01462"
"188.71800","15.72668","0.01459"
"189.14400","15.76214","0.01461"
"189.57000","15.79765","0.01460"
"189.99600","15.83311","0.01499"
"190.42200","15.86862","0.01504"
"190.84800","15.90413","0.01543"
"191.27400","15.93965","0.01569"
"191.70000","15.97510","0.01604"
"192.12600","16.01056","0.01601"
"192.55200","16.04608","0.01572"
"192.97800","16.08165","0.01622"
"193.40400","16.11716","0.01633"
"193.83000","16.15262","0.01655"
"194.25600","16.18808","0.01638"
"194.68200","16.22365","0.01725"
"195.10800","16.25911","0.01624"
"195.53400","16.29468","0.01681"
"195.96000","16.33008","0.01708"
"196.38600","16.36559","0.01563"
"196.81200","16.40117","0.01570"
"197.23800","16.43662","0.01569"
"197.66400","16.47214","0.01567"
"198.09000","16.50759","0.01672"
"198.51600","16.54311","0.01738"
"198.94200","16.57868","0.01761"
"199.36800","16.61414","0.01808"
"199.79400","16.64965","0.01796"
"200.22000","16.68511","0.01778"
"200.64600","16.72062","0.01597"
"201.07200","16.75614","0.01324"
"201.49800","16.79171","0.01295"
"201.92400","16.82717","0.01302"
"202.35000","16.86262","0.01376"
"202.77600","16.89814","0.01358"
"203.20200","16.93371","0.01387"
"203.62800","16.96917","0.01369"
"204.05400","17.00462","0.01381"
"204.48000","17.04014","0.01458"
"204.90600","17.07559","0.01451"
"205.33200","17.11117","0.01502"
"205.75800","17.14662","0.01432"
"206.18400","17.18214","0.01444"
"206.61000","17.21759","0.01515"
"207.03600","17.25317","0.01430"
"207.46200","17.28862","0.01477"
"207.88800","17.32414","0.01504"
"208.31400","17.35959","0.01446"
"208.74000","17.39511","0.01499"
"209.16600","17.43062","0.01476"
"209.59200","17.46614","0.01548"
"210.01800","17.50165","0.01556"
"210.44400","17.53711","0.01559"
"210.87000","17.57262","0.01592"
"211.29600","17.60814","0.01611"
"211.72200","17.64365","0.01567"
"212.14800","17.67917","0.01606"
"212.57400","17.71456","0.01661"
"213.00000","17.75014","0.01679"
"213.42600","17.78565","0.01628"
"213.85200","17.82117","0.01631"
"214.27800","17.85662","0.01658"
"214.70400","17.89214","0.01692"
"215.13000","17.92765","0.01664"
"215.55600","17.96317","0.01708"
"215.98200","17.99868","0.01718"
"216.40800","18.03414","0.01713"
"216.83400","18.06959","0.01786"
"217.26000","18.10517","0.01772"
"217.68600","18.14062","0.01813"
"218.11200","18.17614","0.01816"
"218.53800","18.21159","0.01778"
"218.96400","18.24711","0.01772"
"219.39000","18.28268","0.01808"
"219.81600","18.31814","0.01855"
"220.24200","18.35359","0.01846"
"220.66800","18.38905","0.01868"
"221.09400","18.42462","0.01875"
"221.52000","18.46014","0.01856"
"221.94600","18.49565","0.01882"
"222.37200","18.53111","0.01898"
"222.79800","18.56656","0.01947"
"223.22400","18.60214","0.01947"
"223.65000","18.63765","0.01993"
"224.07600","18.67311","0.01929"
"224.50200","18.70862","0.01859"
"224.92800","18.74408","0.01900"
"225.35400","18.77959","0.01931"
"225.78000","18.81517","0.01934"
"226.20600","18.85068","0.01951"
"226.63200","18.88614","0.01960"
"227.05800","18.92159","0.01924"
"227.48400","18.95717","0.01974"
"227.91000","18.99268","0.01991"
"228.33600","19.02820","0.02013"
"228.76200","19.06365","0.02041"
"229.18800","19.09911","0.02058"
"229.61400","19.13462","0.02030"
"230.04000","19.17020","0.02084"
"230.46600","19.20565","0.02089"
"230.89200","19.24111","0.00910"
"231.31800","19.27662","0.00786"
"231.74400","19.31214","0.00791"
"232.17000","19.34759","0.00755"
"232.59600","19.38311","0.00944"
"233.02200","19.41856","0.00766"
"233.44800","19.45414","0.00892"
"233.87400","19.48965","0.00777"
"234.30000","19.52517","0.00966"
"234.72600","19.56062","0.00849"
"235.15200","19.59608","0.00969"
"235.57800","19.63159","0.00801"
"236.00400","19.66717","0.00891"
"236.43000","19.70263","0.00897"
"236.85600","19.73808","0.00941"
"237.28200","19.77353","0.00947"
"237.70800","19.80911","0.00947"
"238.13400","19.84462","0.00961"
"238.56000","19.88014","0.00994"
"238.98600","19.91560","0.01055"
"239.41200","19.95111","0.01057"
"239.83800","19.98662","0.01092"
"240.26400","20.02214","0.01161"
"240.69000","20.05771","0.01065"
"241.11600","20.09311","0.01107"
"241.54200","20.12862","0.01085"
"241.96800","20.16414","0.01140"
"242.39400","20.19965","0.01162"
"242.82000","20.23517","0.01076"
"243.24600","20.27063","0.01123"
"243.67200","20.30614","0.01189"
"244.09800","20.34165","0.01209"
"244.52400","20.37717","0.01111"
"244.95000","20.41268","0.01218"
"245.37600","20.44808","0.01215"
"245.80200","20.48359","0.01252"
"246.22800","20.51917","0.01248"
"246.65400","20.55468","0.01318"
"247.08000","20.59008","0.01249"
"247.50600","20.62559","0.01308"
"247.93200","20.66111","0.01344"
"248.35800","20.69662","0.01306"
"248.78400","20.73214","0.01306"
"249.21000","20.76760","0.01369"
"249.63600","20.80311","0.01340"
"250.06200","20.83862","0.01340"
"250.48800","20.87414","0.01381"
"250.91400","20.90966","0.01432"
"251.34000","20.94511","0.01413"
"251.76600","20.98063","0.01394"
"252.19200","21.01614","0.01435"
"252.61800","21.05160","0.01428"
"253.04400","21.08717","0.01420"
"253.47000","21.12263","0.01465"
"253.89600","21.15814","0.01489"
"254.32200","21.19365","0.01519"
"254.74800","21.22917","0.01499"
"255.17400","21.26456","0.01536"
"255.60000","21.30008","0.01571"
"256.02600","21.33565","0.01572"
"256.45200","21.37117","0.01583"
"256.87800","21.40668","0.01576"
"257.30400","21.44214","0.01561"
"257.73000","21.47759","0.01529"
"258.15600","21.51317","0.01579"
"258.58200","21.54863","0.01582"
"259.00800","21.58414","0.01604"
"259.43400","21.61960","0.01598"
"259.86000","21.65517","0.01604"
"260.28600","21.69063","0.01618"
"260.71200","21.72614","0.01649"
"261.13800","21.76160","0.01633"
"261.56400","21.79705","0.01671"
"261.99000","21.83257","0.01712"
"262.41600","21.86814","0.01725"
"262.84200","21.90366","0.01691"
"263.26800","21.93917","0.01676"
"263.69400","21.97457","0.01712"
"264.12000","22.01014","0.01728"
"264.54600","22.04565","0.01777"
"264.97200","22.08111","0.01767"
"265.39800","22.11663","0.01770"
"265.82400","22.15214","0.01777"
"266.25000","22.18766","0.01805"
"266.67600","22.22317","0.01774"
"267.10200","22.25863","0.01752"
"267.52800","22.29414","0.01620"
"267.95400","22.32954","0.01433"
"268.38000","22.36511","0.01353"
"268.80600","22.40068","0.01397"
"269.23200","22.43620","0.01521"
"269.65800","22.47166","0.01524"
"270.08400","22.50711","0.01506"
"270.51000","22.54268","0.01537"
"270.93600","22.57814","0.01551"
"271.36200","22.61372","0.01543"
"271.78800","22.64911","0.01560"
"272.21400","22.68463","0.01568"
"272.64000","22.72014","0.01518"
"273.06600","22.75566","0.01607"
"273.49200","22.79105","0.01593"
"273.91800","22.82651","0.01646"
"274.34400","22.86208","0.01651"
"274.77000","22.89766","0.01654"
"275.19600","22.93311","0.01635"
"275.62200","22.96857","0.01657"
"276.04800","23.00402","0.01685"
"276.47400","23.03966","0.01717"
"276.90000","23.07517","0.01717"
"277.32600","23.11063","0.01744"
"277.75200","23.14608","0.01769"
"278.17800","23.18160","0.01734"
"278.60400","23.21705","0.01722"
"279.03000","23.25269","0.01722"
"279.45600","23.28814","0.01753"
"279.88200","23.32360","0.01677"
"280.30800","23.35905","0.01725"
"280.73400","23.39463","0.01713"
"281.16000","23.43014","0.01754"
"281.58600","23.46566","0.01785"
"282.01200","23.50111","0.01742"
"282.43800","23.53657","0.01755"
"282.86400","23.57220","0.01813"
"283.29000","23.60766","0.01840"
"283.71600","23.64317","0.01871"
"284.14200","23.67863","0.01842"
"284.56800","23.71414","0.01847"
"284.99400","23.74966","0.01854"
"285.42000","23.78517","0.01911"
"285.84600","23.82063","0.01835"
"286.27200","23.85608","0.01941"
"286.69800","23.89160","0.01903"
"287.12400","23.92711","0.01882"
"287.55000","23.96263","0.01931"
"287.97600","23.99814","0.01921"
"288.40200","24.03360","0.01935"
"288.82800","24.06911","0.01940"
"289.25400","24.10463","0.01923"
"289.68000","24.14020","0.01935"
"290.10600","24.17560","0.01870"
"290.53200","24.21111","0.01966"
"290.95800","24.24663","0.01986"
"291.38400","24.28214","0.01950"
"291.81000","24.31766","0.01995"
"292.23600","24.35305","0.01840"
"292.66200","24.38857","0.01659"
"293.08800","24.42414","0.01652"
"293.51400","24.45966","0.01647"
"293.94000","24.49512","0.01674"
"294.36600","24.53057","0.01682"
"294.79200","24.56614","0.01741"
"295.21800","24.60160","0.01777"
"295.64400","24.63711","0.01748"
"296.07000","24.67269","0.01716"
"296.49600","24.70808","0.01665"
"296.92200","24.74366","0.01650"
"297.34800","24.77917","0.01676"
"297.77400","24.81469","0.01675"
"298.20000","24.85015","0.01687"
"298.62600","24.88560","0.01729"
"299.05200","24.92111","0.01738"
"299.47800","24.95669","0.01785"
"299.90400","24.99214","0.01772"
"300.33000","25.02760","0.01747"
"300.75600","25.06312","0.01782"
"301.18200","25.09863","0.01797"
"301.60800","25.13414","0.01831"
"302.03400","25.16966","0.01873"
"302.46000","25.20505","0.01885"
"302.88600","25.24063","0.01899"
"303.31200","25.27614","0.01829"
"303.73800","25.31160","0.01882"
"304.16400","25.34717","0.01873"
"304.59000","25.38263","0.01922"
"305.01600","25.41808","0.01983"
"305.44200","25.45366","0.01957"
"305.86800","25.48912","0.02038"
"306.29400","25.52463","0.02089"
"306.72000","25.56009","0.02054"
"307.14600","25.59566","0.02047"
"307.57200","25.63117","0.02095"
"307.99800","25.66663","0.02108"
"308.42400","25.70209","0.02154"
"308.85000","25.73760","0.02056"
"309.27600","25.77318","0.01869"
"309.70200","25.80869","0.01897"
"310.12800","25.84421","0.01860"
"310.55400","25.87960","0.01784"
"310.98000","25.91518","0.01817"
"311.40600","25.95063","0.01801"
"311.83200","25.98615","0.01869"
"312.25800","26.02160","0.01885"
"312.68400","26.05712","0.01803"
"313.11000","26.09263","0.01857"
"313.53600","26.12815","0.01833"
"313.96200","26.16366","0.01827"
"314.38800","26.19917","0.01823"
"314.81400","26.23451","0.01904"
"315.24000","26.27009","0.01910"
"315.66600","26.30566","0.01937"
"316.09200","26.34118","0.01855"
"316.51800","26.37657","0.01792"
"316.94400","26.41203","0.01783"
"317.37000","26.44760","0.01755"
"317.79600","26.48318","0.01747"
"318.22200","26.51863","0.01775"
"318.64800","26.55408","0.01811"
"319.07400","26.58954","0.01819"
"319.50000","26.62512","0.01861"
"319.92600","26.66063","0.01896"
"320.35200","26.69621","0.01875"
"320.77800","26.73160","0.01847"
"321.20400","26.76712","0.01814"
"321.63000","26.80257","0.01903"
"322.05600","26.83821","0.01884"
"322.48200","26.87366","0.01886"
"322.90800","26.90912","0.01924"
"323.33400","26.94457","0.01962"
"323.76000","26.98015","0.02028"
"324.18600","27.01566","0.02036"
"324.61200","27.05112","0.02037"
"325.03800","27.08657","0.02129"
"325.46400","27.12209","0.02107"
"325.89000","27.15772","0.02137"
"326.31600","27.19318","0.02185"
"326.74200","27.22863","0.02220"
"327.16800","27.26409","0.02322"
"327.59400","27.29960","0.02296"
"328.02000","27.33518","0.02288"
"328.44600","27.37069","0.02342"
"328.87200","27.40609","0.02369"
"329.29800","27.44160","0.02405"
"329.72400","27.47706","0.02437"
"330.15000","27.51263","0.02470"
"330.57600","27.54815","0.02472"
"331.00200","27.58360","0.02498"
"331.42800","27.61912","0.02545"
"331.85400","27.65457","0.02510"
"332.28000","27.69015","0.02611"
"332.70600","27.72566","0.02588"
"333.13200","27.76112","0.02627"
"333.55800","27.79663","0.02690"
"333.98400","27.83215","0.02667"
"334.41000","27.86766","0.02659"
"334.83600","27.90312","0.02702"
"335.26200","27.93857","0.02712"
"335.68800","27.97409","0.02771"
"336.11400","28.00960","0.02777"
"336.54000","28.04518","0.02793"
"336.96600","28.08063","0.02810"
"337.39200","28.11609","0.02865"
"337.81800","28.15166","0.02088"
"338.24400","28.18718","0.02050"
"338.67000","28.22269","0.02077"
"339.09600","28.25815","0.02137"
"339.52200","28.29360","0.02212"
"339.94800","28.32918","0.02199"
"340.37400","28.36463","0.02342"
"340.80000","28.40015","0.02372"
"341.22600","28.43560","0.01571"
"341.65200","28.47106","0.01381"
"342.07800","28.50663","0.01449"
"342.50400","28.54215","0.01448"
"342.93000","28.57761","0.01497"
"343.35600","28.61306","0.01527"
"343.78200","28.64857","0.01547"
"344.20800","28.68415","0.01578"
"344.63400","28.71960","0.01611"
"345.06000","28.75512","0.01565"
"345.48600","28.79057","0.01670"
"345.91200","28.82615","0.01646"
"346.33800","28.86166","0.01685"
"346.76400","28.89712","0.01753"
"347.19000","28.93263","0.01773"
"347.61600","28.96815","0.01808"
"348.04200","29.00366","0.01837"
"348.46800","29.03918","0.01829"
"348.89400","29.07470","0.01852"
"349.32000","29.11015","0.01904"
"349.74600","29.14561","0.01890"
"350.17200","29.18118","0.01957"
"350.59800","29.21663","0.01914"
"351.02400","29.25221","0.01987"
"351.45000","29.28760","0.01977"
"351.87600","29.32312","0.02039"
"352.30200","29.35863","0.02078"
"352.72800","29.39421","0.02101"
"353.15400","29.42966","0.02142"
"353.58000","29.46506","0.01984"
"354.00600","29.50063","0.01706"
"354.43200","29.53615","0.01565"
"354.85800","29.57161","0.01587"
"355.28400","29.60712","0.01598"
"355.71000","29.64257","0.01642"
"356.13600","29.67809","0.01630"
"356.56200","29.71360","0.01717"
"356.98800","29.74912","0.01699"
"357.41400","29.78464","0.01740"
"357.84000","29.82003","0.01715"
"358.26600","29.85561","0.01750"
"358.69200","29.89112","0.01792"
"359.11800","29.92669","0.01751"
"359.54400","29.96209","0.01801"
"359.97000","29.99760","0.01859"
"360.39600","30.03312","0.01822"
"360.82200","30.06863","0.01807"
"361.24800","30.10409","0.01803"
"361.67400","30.13961","0.01768"
"362.10000","30.17506","0.01814"
"362.52600","30.21063","0.01768"
"362.95200","30.24615","0.01796"
"363.37800","30.28161","0.01806"
"363.80400","30.31712","0.01776"
"364.23000","30.35264","0.01810"
"364.65600","30.38815","0.01823"
"365.08200","30.42367","0.01745"
"365.50800","30.45918","0.01531"
"365.93400","30.49463","0.01498"
"366.36000","30.53015","0.01420"
"366.78600","30.56566","0.01435"
"367.21200","30.60118","0.01469"
"367.63800","30.63664","0.01425"
"368.06400","30.67209","0.01492"
"368.49000","30.70761","0.01485"
"368.91600","30.74318","0.01533"
"369.34200","30.77864","0.01485"
"369.76800","30.81409","0.01519"
"370.19400","30.84961","0.01482"
"370.62000","30.88512","0.01559"
"371.04600","30.92070","0.01541"
"371.47200","30.95615","0.01555"
"371.89800","30.99155","0.01508"
"372.32400","31.02712","0.01483"
"372.75000","31.06258","0.01575"
"373.17600","31.09815","0.01579"
"373.60200","31.13361","0.01579"
"374.02800","31.16912","0.01550"
"374.45400","31.20458","0.01674"
"374.88000","31.24009","0.01462"
"375.30600","31.27560","0.01457"
"375.73200","31.31112","0.01524"
"376.15800","31.34657","0.01504"
"376.58400","31.38215","0.01540"
"377.01000","31.41766","0.01568"
"377.43600","31.45318","0.01563"
"377.86200","31.48863","0.01551"
"378.28800","31.52415","0.01599"
"378.71400","31.55967","0.01578"
"379.14000","31.59518","0.01548"
"379.56600","31.63070","0.01555"
"379.99200","31.66609","0.01571"
"380.41800","31.70160","0.01555"
"380.84400","31.73712","0.01548"
"381.27000","31.77264","0.01541"
"381.69600","31.80809","0.01603"
"382.12200","31.84361","0.01591"
"382.54800","31.87906","0.01556"
"382.97400","31.91464","0.01605"
"383.40000","31.95015","0.01606"
"383.82600","31.98561","0.01554"
"384.25200","32.02112","0.01602"
"384.67800","32.05658","0.01558"
"385.10400","32.09209","0.01524"
"385.53000","32.12767","0.01579"
"385.95600","32.16312","0.01634"
"386.38200","32.19857","0.01629"
"386.80800","32.23409","0.01568"
"387.23400","32.26966","0.01675"
"387.66000","32.30512","0.01674"
"388.08600","32.34063","0.01711"
"388.51200","32.37609","0.01679"
"388.93800","32.41161","0.01654"
"389.36400","32.44718","0.01734"
"389.79000","32.48264","0.01659"
"390.21600","32.51815","0.01602"
"390.64200","32.55360","0.01645"
"391.06800","32.58912","0.01658"
"391.49400","32.62469","0.01677"
"391.92000","32.66015","0.01670"
"392.34600","32.69561","0.01702"
"392.77200","32.73112","0.01707"
"393.19800","32.76670","0.01695"
"393.62400","32.80221","0.01722"
"394.05000","32.83767","0.01705"
"394.47600","32.87312","0.01732"
"394.90200","32.90858","0.01764"
"395.32800","32.94409","0.01789"
"395.75400","32.97967","0.01727"
"396.18000","33.01512","0.01759"
"396.60600","33.05058","0.01716"
"397.03200","33.08615","0.01742"
"397.45800","33.12161","0.01756"
"397.88400","33.15706","0.01750"
"398.31000","33.19264","0.01763"
"398.73600","33.22803","0.01748"
"399.16200","33.26361","0.01738"
"399.58800","33.29912","0.01697"
"400.01400","33.33470","0.01714"
"400.44000","33.37015","0.01766"
"400.86600","33.40554","0.01752"
"401.29200","33.44118","0.01805"
"401.71800","33.47663","0.01788"
"402.14400","33.51221","0.01826"
"402.57000","33.54755","0.01842"
"402.99600","33.58312","0.01789"
"403.42200","33.61864","0.01815"
"403.84800","33.65415","0.01850"
"404.27400","33.68967","0.01884"
"404.70000","33.72512","0.01891"
"405.12600","33.76058","0.01876"
"405.55200","33.79615","0.01910"
"405.97800","33.83167","0.02005"
"406.40400","33.86718","0.01989"
"406.83000","33.90264","0.01932"
"407.25600","33.93809","0.01991"
"407.68200","33.97361","0.02066"
"408.10800","34.00919","0.02017"
"408.53400","34.04464","0.01986"
"408.96000","34.08009","0.02030"
"409.38600","34.11561","0.02006"
"409.81200","34.15118","0.01927"
"410.23800","34.18664","0.01982"
"410.66400","34.22209","0.02018"
"411.09000","34.25761","0.01987"
"411.51600","34.29306","0.01994"
"411.94200","34.32864","0.02018"
"412.36800","34.36415","0.02000"
"412.79400","34.39961","0.01984"
"413.22000","34.43512","0.01978"
"413.64600","34.47064","0.02006"
"414.07200","34.50615","0.02015"
"414.49800","34.54161","0.02064"
"414.92400","34.57713","0.02052"
"415.35000","34.61258","0.02084"
"415.77600","34.64809","0.02164"
"416.20200","34.68361","0.02126"
"416.62800","34.71912","0.02188"
"417.05400","34.75458","0.02179"
"417.48000","34.79015","0.02199"
"417.90600","34.82561","0.02183"
"418.33200","34.86118","0.02250"
"418.75800","34.89664","0.02241"
"419.18400","34.93209","0.02290"
"419.61000","34.96767","0.02304"
"420.03600","35.00312","0.02294"
"420.46200","35.03864","0.02375"
"420.88800","35.07410","0.02351"
"421.31400","35.10961","0.02330"
"421.74000","35.14519","0.02373"
"422.16600","35.18070","0.02294"
"422.59200","35.21622","0.02353"
"423.01800","35.25155","0.02309"
"423.44400","35.28712","0.02350"
"423.87000","35.32264","0.02274"
"424.29600","35.35815","0.02285"
"424.72200","35.39361","0.02290"
"425.14800","35.42907","0.02286"
"425.57400","35.46464","0.02279"
"426.00000","35.50010","0.02212"
"426.42600","35.53561","0.02256"
"426.85200","35.57113","0.02199"
"427.27800","35.60652","0.02137"
"427.70400","35.64209","0.01955"
"428.13000","35.67767","0.01579"
"428.55600","35.71312","0.01370"
"428.98200","35.74858","0.01479"
"429.40800","35.78403","0.01515"
"429.83400","35.81961","0.01533"
"430.26000","35.85519","0.01567"
"430.68600","35.89064","0.01578"
"431.11200","35.92616","0.01526"
"431.53800","35.96161","0.01589"
"431.96400","35.99718","0.01653"
"432.39000","36.03270","0.01713"
"432.81600","36.06821","0.01689"
"433.24200","36.10361","0.01702"
"433.66800","36.13913","0.01701"
"434.09400","36.17464","0.01794"
"434.52000","36.21016","0.01759"
"434.94600","36.24567","0.01730"
"435.37200","36.28113","0.01723"
"435.79800","36.31658","0.01750"
"436.22400","36.35215","0.01782"
"436.65000","36.38767","0.01798"
"437.07600","36.42313","0.01822"
"437.50200","36.45858","0.01832"
"437.92800","36.49409","0.01786"
"438.35400","36.52967","0.01810"
"438.78000","36.56512","0.01822"
"439.20600","36.60064","0.01817"
"439.63200","36.63604","0.01869"
"440.05800","36.67161","0.01865"
"440.48400","36.70713","0.01871"
"440.91000","36.74264","0.01871"
"441.33600","36.77816","0.01911"
"441.76200","36.81355","0.01881"
"442.18800","36.84912","0.01885"
"442.61400","36.88464","0.01906"
"443.04000","36.92015","0.01921"
"443.46600","36.95561","0.01911"
"443.89200","36.99113","0.01971"
"444.31800","37.02670","0.02000"
"444.74400","37.06216","0.01994"
"445.17000","37.09767","0.02002"
"445.59600","37.13313","0.02063"
"446.02200","37.16864","0.02004"
"446.44800","37.20416","0.02119"
"446.87400","37.23967","0.02141"
"447.30000","37.27513","0.02149"
"447.72600","37.31058","0.02178"
"448.15200","37.34616","0.02213"
"448.57800","37.38161","0.02196"
"449.00400","37.41713","0.02008"
"449.43000","37.45264","0.02058"
"449.85600","37.48809","0.01982"
"450.28200","37.52361","0.02027"
"450.70800","37.55919","0.01942"
"451.13400","37.59464","0.01990"
"451.56000","37.63016","0.02020"
"451.98600","37.66555","0.02084"
"452.41200","37.70113","0.02063"
"452.83800","37.73664","0.02042"
"453.26400","37.77216","0.02051"
"453.69000","37.80755","0.02007"
"454.11600","37.84313","0.02008"
"454.54200","37.87864","0.01988"
"454.96800","37.91410","0.01988"
"455.39400","37.94967","0.01913"
"455.82000","37.98507","0.01960"
"456.24600","38.02065","0.01886"
"456.67200","38.05622","0.01918"
"457.09800","38.09167","0.01899"
"457.52400","38.12719","0.01927"
"457.95000","38.16258","0.01978"
"458.37600","38.19816","0.02020"
"458.80200","38.23361","0.02011"
"459.22800","38.26913","0.01991"
"459.65400","38.30464","0.01992"
"460.08000","38.34010","0.01943"
"460.50600","38.37561","0.01922"
"460.93200","38.41119","0.01893"
"461.35800","38.44670","0.01981"
"461.78400","38.48210","0.01966"
"462.21000","38.51761","0.02054"
"462.63600","38.55313","0.02014"
"463.06200","38.58870","0.02138"
"463.48800","38.62416","0.02108"
"463.91400","38.65961","0.02050"
"464.34000","38.69513","0.02040"
"464.76600","38.73064","0.02035"
"465.19200","38.76610","0.02078"
"465.61800","38.80161","0.02067"
"466.04400","38.83707","0.02042"
"466.47000","38.87259","0.02037"
"466.89600","38.90810","0.02041"
"467.32200","38.94361","0.01983"
"467.74800","38.97907","0.02032"
"468.17400","39.01458","0.02082"
"468.60000","39.05010","0.01998"
"469.02600","39.08562","0.01996"
"469.45200","39.12113","0.02030"
"469.87800","39.15664","0.02009"
"470.30400","39.19210","0.01924"
"470.73000","39.22761","0.01952"
"471.15600","39.26313","0.01794"
"471.58200","39.29864","0.01705"
"472.00800","39.33410","0.01590"
"472.43400","39.36961","0.01595"
"472.86000","39.40513","0.01702"
"473.28600","39.44064","0.01660"
"473.71200","39.47616","0.01754"
"474.13800","39.51167","0.01773"
"474.56400","39.54713","0.01737"
"474.99000","39.58265","0.01756"
"475.41600","39.61822","0.01719"
"475.84200","39.65361","0.01658"
"476.26800","39.68907","0.01617"
"476.69400","39.72464","0.01638"
"477.12000","39.76016","0.01623"
"477.54600","39.79567","0.01628"
"477.97200","39.83119","0.01688"
"478.39800","39.86653","0.01747"
"478.82400","39.90210","0.01678"
"479.25000","39.93761","0.01726"
"479.67600","39.97319","0.01796"
"480.10200","40.00858","0.01744"
"480.52800","40.04410","0.01736"
"480.95400","40.07962","0.01734"
"481.38000","40.11519","0.01784"
"481.80600","40.15064","0.01706"
"482.23200","40.18610","0.01799"
"482.65800","40.22155","0.01778"
"483.08400","40.25713","0.01808"
"483.51000","40.29265","0.01819"
"483.93600","40.32816","0.01876"
"484.36200","40.36362","0.01845"
"484.78800","40.39907","0.01869"
"485.21400","40.43464","0.01856"
"485.64000","40.47021","0.01855"
"486.06600","40.50567","0.01726"
"486.49200","40.54113","0.01690"
"486.91800","40.57658","0.01686"
"487.34400","40.61222","0.01738"
"487.77000","40.64767","0.01714"
"488.19600","40.68319","0.01638"
"488.62200","40.71858","0.01713"
"489.04800","40.75410","0.01683"
"489.47400","40.78968","0.01711"
"489.90000","40.82519","0.01700"
"490.32600","40.86058","0.01740"
"490.75200","40.89610","0.01797"
"491.17800","40.93161","0.01781"
"491.60400","40.96713","0.01769"
"492.03000","41.00265","0.01850"
"492.45600","41.03810","0.01820"
"492.88200","41.07362","0.01844"
"493.30800","41.10913","0.01877"
"493.73400","41.14464","0.01813"
"494.16000","41.18016","0.01830"
"494.58600","41.21561","0.01796"
"495.01200","41.25107","0.01827"
"495.43800","41.28665","0.01789"
"495.86400","41.32210","0.01817"
"496.29000","41.35762","0.01854"
"496.71600","41.39307","0.01864"
"497.14200","41.42859","0.01924"
"497.56800","41.46410","0.01979"
"497.99400","41.49968","0.01950"
"498.42000","41.53519","0.01960"
"498.84600","41.57058","0.01949"
"499.27200","41.60616","0.01962"
"499.69800","41.64167","0.02000"
"500.12400","41.67719","0.02000"
"500.55000","41.71264","0.01952"
"500.97600","41.74810","0.01903"
"501.40200","41.78368","0.01873"
"501.82800","41.81913","0.01882"
"502.25400","41.85470","0.01978"
"502.68000","41.89016","0.02075"
"503.10600","41.92561","0.01854"
"503.53200","41.96113","0.01891"
"503.95800","41.99665","0.01952"
"504.38400","42.03216","0.02023"
"504.81000","42.06756","0.02043"
"505.23600","42.10307","0.02076"
"505.66200","42.13865","0.02119"
"506.08800","42.17416","0.02135"
"506.51400","42.20962","0.02080"
"506.94000","42.24507","0.02150"
"507.36600","42.28059","0.02126"
"507.79200","42.31616","0.02213"
"508.21800","42.35162","0.02235"
"508.64400","42.38713","0.02205"
"509.07000","42.42258","0.02276"
"509.49600","42.45810","0.02241"
"509.92200","42.49362","0.02287"
"510.34800","42.52907","0.02322"
"510.77400","42.56459","0.02308"
"511.20000","42.60010","0.02300"
"511.62600","42.63562","0.02314"
"512.05200","42.67113","0.02383"
"512.47800","42.70665","0.02417"
"512.90400","42.74210","0.02421"
"513.33000","42.77762","0.02446"
"513.75600","42.81313","0.02416"
"514.18200","42.84870","0.02490"
"514.60800","42.88416","0.02528"
"515.03400","42.91961","0.02628"
"515.46000","42.95514","0.02655"
"515.88600","42.99065","0.02650"
"516.31200","43.02617","0.02692"
"516.73800","43.06168","0.02688"
"517.16400","43.09707","0.02721"
"517.59000","43.13259","0.02710"
"518.01600","43.16816","0.02470"
"518.44200","43.20361","0.02436"
"518.86800","43.23913","0.02494"
"519.29400","43.27453","0.02381"
"519.72000","43.31010","0.01988"
"520.14600","43.34562","0.01906"
"520.57200","43.38113","0.01983"
"520.99800","43.41665","0.01901"
"521.42400","43.45204","0.01927"
"521.85000","43.48762","0.02008"
"522.27600","43.52319","0.02033"
"522.70200","43.55870","0.02054"
"523.12800","43.59404","0.02011"
"523.55400","43.62956","0.02026"
"523.98000","43.66513","0.02141"
"524.40600","43.70065","0.02148"
"524.83200","43.73616","0.02198"
"525.25800","43.77162","0.02224"
"525.68400","43.80707","0.02355"
"526.11000","43.84265","0.02358"
"526.53600","43.87816","0.02392"
"526.96200","43.91361","0.02446"
"527.38800","43.94913","0.02411"
"527.81400","43.98458","0.02327"
"528.24000","44.02016","0.02402"
"528.66600","44.05562","0.02396"
"529.09200","44.09114","0.02438"
"529.51800","44.12659","0.02439"
"529.94400","44.16211","0.02340"
"530.37000","44.19768","0.02245"
"530.79600","44.23320","0.02194"
"531.22200","44.26865","0.02173"
"531.64800","44.30410","0.02255"
"532.07400","44.33956","0.02324"
"532.50000","44.37519","0.02294"
"532.92600","44.41064","0.02352"
"533.35200","44.44604","0.02376"
"533.77800","44.48162","0.02429"
"534.20400","44.51713","0.02519"
"534.63000","44.55265","0.02520"
"535.05600","44.58817","0.02288"
"535.48200","44.62356","0.02201"
"535.90800","44.65907","0.02200"
"536.33400","44.69459","0.02253"
"536.76000","44.73016","0.02286"
"537.18600","44.76562","0.02351"
"537.61200","44.80113","0.02406"
"538.03800","44.83659","0.02331"
"538.46400","44.87217","0.02407"
"538.89000","44.90768","0.02526"
"539.31600","44.94319","0.02578"
"539.74200","44.97859","0.02602"
"540.16800","45.01410","0.02624"
"540.59400","45.04968","0.02720"
"541.02000","45.08514","0.02667"
"541.44600","45.12064","0.02695"
"541.87200","45.15605","0.02751"
"542.29800","45.19162","0.02811"
"542.72400","45.22719","0.02846"
"543.15000","45.26271","0.02893"
"543.57600","45.29817","0.02978"
"544.00200","45.33362","0.03007"
"544.42800","45.36914","0.03159"
"544.85400","45.40465","0.03172"
"545.28000","45.44016","0.03184"
"545.70600","45.47562","0.03230"
"546.13200","45.51107","0.03246"
"546.55800","45.54665","0.03230"
"546.98400","45.58217","0.03406"
"547.41000","45.61762","0.03409"
"547.83600","45.65308","0.03468"
"548.26200","45.68859","0.03547"
"548.68800","45.72411","0.03613"
"549.11400","45.75962","0.03679"
"549.54000","45.79520","0.03760"
"549.96600","45.83059","0.03911"
"550.39200","45.86610","0.03955"
"550.81800","45.90168","0.04056"
"551.24400","45.93714","0.04135"
"551.67000","45.97265","0.04233"
"552.09600","46.00810","0.04288"
"552.52200","46.04362","0.04399"
"552.94800","46.07914","0.04593"
"553.37400","46.11465","0.04653"
"553.80000","46.15011","0.04756"
"554.22600","46.18562","0.04840"
"554.65200","46.22113","0.04912"
"555.07800","46.25665","0.04873"
"555.50400","46.29222","0.04476"
"555.93000","46.32762","0.04587"
"556.35600","46.36314","0.04841"
"556.78200","46.39865","0.04980"
"557.20800","46.43417","0.04820"
"557.63400","46.46962","0.04885"
"558.06000","46.50514","0.04866"
"558.48600","46.54059","0.04856"
"558.91200","46.57611","0.04225"
"559.33800","46.61162","0.03078"
"559.76400","46.64714","0.02935"
"560.19000","46.68253","0.03038"
"560.61600","46.71817","0.03095"
"561.04200","46.75362","0.03132"
"561.46800","46.78914","0.03178"
"561.89400","46.82459","0.03112"
"562.32000","46.86005","0.03139"
"562.74600","46.89562","0.03163"
"563.17200","46.93113","0.03248"
"563.59800","46.96665","0.03331"
"564.02400","47.00210","0.03361"
"564.45000","47.03756","0.03441"
"564.87600","47.07320","0.03411"
"565.30200","47.10865","0.03487"
"565.72800","47.14417","0.03417"
"566.15400","47.17962","0.03483"
"566.58000","47.21507","0.03445"
"567.00600","47.25065","0.03447"
"567.43200","47.28611","0.03499"
"567.85800","47.32162","0.03585"
"568.28400","47.35714","0.03573"
"568.71000","47.39259","0.03637"
"569.13600","47.42817","0.03616"
"569.56200","47.46368","0.03621"
"569.98800","47.49908","0.03519"
"570.41400","47.53459","0.03477"
"570.84000","47.57011","0.03204"
"571.26600","47.60568","0.03041"
"571.69200","47.64114","0.02915"
"572.11800","47.67665","0.02954"
"572.54400","47.71205","0.02985"
"572.97000","47.74756","0.03052"
"573.39600","47.78314","0.03070"
"573.82200","47.81865","0.03145"
"574.24800","47.85411","0.03180"
"574.67400","47.88962","0.03250"
"575.10000","47.92508","0.03250"
"575.52600","47.96066","0.03339"
"575.95200","47.99611","0.03306"
"576.37800","48.03157","0.03320"
"576.80400","48.06708","0.03323"
"577.23000","48.10265","0.03201"
"577.65600","48.13816","0.03151"
"578.08200","48.17368","0.03206"
"578.50800","48.20908","0.03310"
"578.93400","48.24465","0.03500"
"579.36000","48.28011","0.03579"
"579.78600","48.31562","0.03678"
"580.21200","48.35114","0.03688"
"580.63800","48.38660","0.03669"
"581.06400","48.42216","0.03755"
"581.49000","48.45763","0.03889"
"581.91600","48.49314","0.03955"
"582.34200","48.52865","0.03894"
"582.76800","48.56411","0.03972"
"583.19400","48.59962","0.03965"
"583.62000","48.63514","0.04049"
"584.04600","48.67065","0.04186"
"584.47200","48.70617","0.04324"
"584.89800","48.74162","0.04409"
"585.32400","48.77720","0.04425"
"585.75000","48.81265","0.04528"
"586.17600","48.84817","0.04651"
"586.60200","48.88363","0.04780"
"587.02800","48.91908","0.04895"
"587.45400","48.95459","0.04977"
"587.88000","48.99011","0.05092"
"588.30600","49.02562","0.05163"
"588.73200","49.06108","0.05278"
"589.15800","49.09653","0.05438"
"589.58400","49.13217","0.05509"
"590.01000","49.16763","0.05531"
"590.43600","49.20314","0.05617"
"590.86200","49.23860","0.01258"
"591.28800","49.27411","0.01231"
"591.71400","49.30968","0.01597"
"592.14000","49.34514","0.01650"
"592.56600","49.38059","0.01704"
"592.99200","49.41611","0.01707"
"593.41800","49.45163","0.01818"
"593.84400","49.48720","0.01797"
"594.27000","49.52265","0.01906"
"594.69600","49.55811","0.01914"
"595.12200","49.59363","0.01989"
"595.54800","49.62914","0.02064"
"595.97400","49.66466","0.02066"
"596.40000","49.70017","0.02153"
"596.82600","49.73563","0.02206"
"597.25200","49.77108","0.02233"
"597.67800","49.80665","0.02296"
"598.10400","49.84217","0.02370"
"598.53000","49.87769","0.02423"
"598.95600","49.91308","0.02483"
"599.38200","49.94865","0.02520"
"599.80800","49.98411","0.02588"
"600.23400","50.01968","0.02656"
"600.66000","50.05514","0.02706"
"601.08600","50.09053","0.02730"
"601.51200","50.12611","0.02147"
"601.93800","50.16162","0.02190"
"602.36400","50.19714","0.02180"
"602.79000","50.23265","0.02131"
"603.21600","50.26805","0.02242"
"603.64200","50.30362","0.02260"
"604.06800","50.33914","0.02358"
"604.49400","50.37466","0.02300"
"604.92000","50.41011","0.02207"
"605.34600","50.44557","0.02165"
"605.77200","50.48114","0.02254"
"606.19800","50.51665","0.02258"
"606.62400","50.55217","0.02305"
"607.05000","50.58762","0.02289"
"607.47600","50.62308","0.02380"
"607.90200","50.65866","0.02416"
"608.32800","50.69417","0.02425"
"608.75400","50.72968","0.02293"
"609.18000","50.76514","0.02352"
"609.60600","50.80059","0.02415"
"610.03200","50.83617","0.02348"
"610.45800","50.87169","0.02433"
"610.88400","50.90714","0.02428"
"611.31000","50.94260","0.02466"
"611.73600","50.97811","0.02477"
"612.16200","51.01368","0.02513"
"612.58800","51.04914","0.02399"
"613.01400","51.08465","0.02446"
"613.44000","51.12011","0.02499"
"613.86600","51.15557","0.02514"
"614.29200","51.19114","0.02547"
"614.71800","51.22660","0.02564"
"615.14400","51.26212","0.02596"
"615.57000","51.29757","0.02638"
"615.99600","51.33308","0.02666"
"616.42200","51.36866","0.02708"
"616.84800","51.40417","0.02690"
"617.27400","51.43957","0.02767"
"617.70000","51.47514","0.02778"
"618.12600","51.51065","0.02766"
"618.55200","51.54617","0.02527"
"618.97800","51.58169","0.02588"
"619.40400","51.61708","0.02601"
"619.83000","51.65260","0.02693"
"620.25600","51.68817","0.02711"
"620.68200","51.72363","0.02753"
"621.10800","51.75914","0.02758"
"621.53400","51.79460","0.02852"
"621.96000","51.83011","0.02867"
"622.38600","51.86563","0.02931"
"622.81200","51.90120","0.02956"
"623.23800","51.93666","0.03028"
"623.66400","51.97211","0.03051"
"624.09000","52.00769","0.03139"
"624.51600","52.04314","0.03166"
"624.94200","52.07872","0.03194"
"625.36800","52.11411","0.03258"
"625.79400","52.14963","0.03342"
"626.22000","52.18514","0.03369"
"626.64600","52.22065","0.03392"
"627.07200","52.25611","0.03416"
"627.49800","52.29156","0.03453"
"627.92400","52.32708","0.00861"
"628.35000","52.36266","0.01458"
"628.77600","52.39811","0.00839"
"629.20200","52.43363","0.01332"
"629.62800","52.46908","0.01201"
"630.05400","52.50460","0.01317"
"630.48000","52.54012","0.01285"
"630.90600","52.57563","0.01380"
"631.33200","52.61114","0.01640"
"631.75800","52.64660","0.01309"
"632.18400","52.68205","0.01711"
"632.61000","52.71769","0.01509"
"633.03600","52.75314","0.01791"
"633.46200","52.78860","0.01539"
"633.88800","52.82411","0.01854"
"634.31400","52.85963","0.01709"
"634.74000","52.89514","0.01952"
"635.16600","52.93066","0.01819"
"635.59200","52.96611","0.02044"
"636.01800","53.00163","0.01956"
"636.44400","53.03714","0.02142"
"636.87000","53.07272","0.02094"
"637.15800","53.09664","0.02161"