File: Force_trajectories/170107_1/Specimen_RawData_3.csv
End date,"1/7/2017"
Specimen label,"18_CTNT2"
Maximum Load,"0.07079",N

Time,Extension,Load
(s),(mm),(N)
"0.00000","0.00006","-0.00038"
"0.18600","0.01220","-0.00038"
"0.37200","0.03103","-0.00053"
"0.55800","0.04670","-0.00030"
"0.74400","0.06224","0.00002"
"0.93000","0.07773","-0.00005"
"1.11600","0.09321","0.00005"
"1.30200","0.10870","0.00003"
"1.48800","0.12418","-0.00021"
"1.67400","0.13967","0.00004"
"1.86000","0.15515","0.00052"
"2.04600","0.17064","0.00006"
"2.23200","0.18618","0.00048"
"2.41800","0.20167","0.00048"
"2.60400","0.21710","0.00005"
"2.79000","0.23270","0.00017"
"2.97600","0.24819","-0.00002"
"3.16200","0.26367","-0.00004"
"3.34800","0.27922","0.00048"
"3.53400","0.29470","0.00024"
"3.72000","0.31013","0.00011"
"3.90600","0.32567","0.00064"
"4.09200","0.34122","0.00014"
"4.27800","0.35658","0.00012"
"4.46400","0.37213","0.00018"
"4.65000","0.38768","0.00028"
"4.83600","0.40310","0.00043"
"5.02200","0.41871","0.00003"
"5.20800","0.43413","0.00040"
"5.39400","0.44962","0.00016"
"5.58000","0.46516","0.00007"
"5.76600","0.48065","0.00038"
"5.95200","0.49619","0.00007"
"6.13800","0.51168","0.00025"
"6.32400","0.52716","-0.00037"
"6.51000","0.54271","0.00050"
"6.69600","0.55820","0.00065"
"6.88200","0.57368","0.00101"
"7.06800","0.58917","0.00094"
"7.25400","0.60465","0.00046"
"7.44000","0.62014","0.00025"
"7.62600","0.63562","0.00026"
"7.81200","0.65123","0.00035"
"7.99800","0.66665","0.00010"
"8.18400","0.68214","0.00085"
"8.37000","0.69768","0.00025"
"8.55600","0.71317","0.00054"
"8.74200","0.72866","0.00006"
"8.92800","0.74420","0.00033"
"9.11400","0.75963","0.00077"
"9.30000","0.77517","0.00038"
"9.48600","0.79072","0.00031"
"9.67200","0.80614","0.00029"
"9.85800","0.82169","0.00100"
"10.04400","0.83717","0.00052"
"10.23000","0.85260","0.00042"
"10.41600","0.86820","0.00045"
"10.60200","0.88363","0.00049"
"10.78800","0.89912","0.00059"
"10.97400","0.91472","0.00047"
"11.16000","0.93021","0.00059"
"11.34600","0.94557","0.00062"
"11.53200","0.96124","0.00042"
"11.71800","0.97666","0.00079"
"11.90400","0.99209","0.00050"
"12.09000","1.00769","0.00049"
"12.27600","1.02318","0.00054"
"12.46200","1.03866","0.00035"
"12.64800","1.05421","0.00043"
"12.83400","1.06963","0.00043"
"13.02000","1.08512","0.00017"
"13.20600","1.10067","0.00046"
"13.39200","1.11615","0.00017"
"13.57800","1.13164","0.00076"
"13.76400","1.14718","0.00020"
"13.95000","1.16267","0.00030"
"14.13600","1.17815","0.00074"
"14.32200","1.19370","0.00057"
"14.50800","1.20912","0.00039"
"14.69400","1.22467","0.00076"
"14.88000","1.24015","0.00002"
"15.06600","1.25558","0.00089"
"15.25200","1.27125","0.00034"
"15.43800","1.28667","0.00039"
"15.62400","1.30210","0.00028"
"15.81000","1.31770","0.00021"
"15.99600","1.33319","0.00025"
"16.18200","1.34861","0.00103"
"16.36800","1.36416","0.00081"
"16.55400","1.37970","0.00120"
"16.74000","1.39513","0.00017"
"16.92600","1.41067","0.00004"
"17.11200","1.42616","0.00026"
"17.29800","1.44165","0.00041"
"17.48400","1.45719","0.00061"
"17.67000","1.47262","0.00070"
"17.85600","1.48816","0.00076"
"18.04200","1.50365","0.00055"
"18.22800","1.51913","0.00027"
"18.41400","1.53468","0.00037"
"18.60000","1.55022","0.00063"
"18.78600","1.56565","0.00052"
"18.97200","1.58125","0.00074"
"19.15800","1.59668","0.00016"
"19.34400","1.61211","0.00077"
"19.53000","1.62765","0.00076"
"19.71600","1.64320","0.00070"
"19.90200","1.65862","0.00074"
"20.08800","1.67417","-0.00028"
"20.27400","1.68971","0.00076"
"20.46000","1.70508","0.00061"
"20.64600","1.72074","0.00118"
"20.83200","1.73617","0.00050"
"21.01800","1.75165","0.00032"
"21.20400","1.76720","0.00072"
"21.39000","1.78262","0.00032"
"21.57600","1.79817","0.00089"
"21.76200","1.81366","0.00120"
"21.94800","1.82914","0.00062"
"22.13400","1.84463","0.00039"
"22.32000","1.86017","0.00075"
"22.50600","1.87566","0.00080"
"22.69200","1.89114","0.00079"
"22.87800","1.90669","0.00127"
"23.06400","1.92211","0.00014"
"23.25000","1.93766","0.00104"
"23.43600","1.95320","0.00051"
"23.62200","1.96863","0.00031"
"23.80800","1.98418","0.00073"
"23.99400","1.99966","0.00082"
"24.18000","2.01515","0.00041"
"24.36600","2.03069","0.00090"
"24.55200","2.04618","0.00106"
"24.73800","2.06166","0.00030"
"24.92400","2.07721","0.00100"
"25.11000","2.09263","0.00070"
"25.29600","2.10818","0.00034"
"25.48200","2.12372","0.00108"
"25.66800","2.13915","0.00026"
"25.85400","2.15464","0.00068"
"26.04000","2.17018","0.00110"
"26.22600","2.18567","0.00048"
"26.41200","2.20115","0.00110"
"26.59800","2.21670","0.00023"
"26.78400","2.23218","0.00070"
"26.97000","2.24761","0.00099"
"27.15600","2.26321","0.00043"
"27.34200","2.27870","0.00080"
"27.52800","2.29412","0.00063"
"27.71400","2.30967","0.00078"
"27.90000","2.32516","0.00067"
"28.08600","2.34064","0.00047"
"28.27200","2.35619","0.00061"
"28.45800","2.37161","0.00136"
"28.64400","2.38722","0.00070"
"28.83000","2.40270","0.00072"
"29.01600","2.41813","0.00030"
"29.20200","2.43373","0.00066"
"29.38800","2.44916","0.00085"
"29.57400","2.46464","0.00035"
"29.76000","2.48013","0.00093"
"29.94600","2.49567","0.00121"
"30.13200","2.51110","0.00060"
"30.31800","2.52665","0.00050"
"30.50400","2.54219","0.00104"
"30.69000","2.55756","0.00117"
"30.87600","2.57316","0.00077"
"31.06200","2.58871","0.00067"
"31.24800","2.60413","0.00071"
"31.43400","2.61968","0.00073"
"31.62000","2.63522","0.00067"
"31.80600","2.65065","0.00128"
"31.99200","2.66613","0.00049"
"32.17800","2.68168","0.00077"
"32.36400","2.69717","0.00086"
"32.55000","2.71265","0.00082"
"32.73600","2.72814","0.00085"
"32.92200","2.74368","0.00117"
"33.10800","2.75917","0.00089"
"33.29400","2.77465","0.00046"
"33.48000","2.79020","0.00107"
"33.66600","2.80574","0.00084"
"33.85200","2.82117","0.00051"
"34.03800","2.83665","0.00093"
"34.22400","2.85220","0.00061"
"34.41000","2.86763","0.00103"
"34.59600","2.88317","0.00099"
"34.78200","2.89872","0.00097"
"34.96800","2.91414","0.00103"
"35.15400","2.92969","0.00125"
"35.34000","2.94523","0.00153"
"35.52600","2.96066","0.00081"
"35.71200","2.97620","0.00130"
"35.89800","2.99169","0.00064"
"36.08400","3.00717","0.00063"
"36.27000","3.02272","0.00116"
"36.45600","3.03809","0.00153"
"36.64200","3.05369","0.00098"
"36.82800","3.06918","0.00082"
"37.01400","3.08466","0.00099"
"37.20000","3.10015","0.00126"
"37.38600","3.11569","0.00100"
"37.57200","3.13118","0.00062"
"37.75800","3.14666","0.00137"
"37.94400","3.16221","0.00058"
"38.13000","3.17769","0.00079"
"38.31600","3.19312","0.00117"
"38.50200","3.20872","0.00071"
"38.68800","3.22415","0.00152"
"38.87400","3.23964","0.00111"
"39.06000","3.25524","0.00122"
"39.24600","3.27061","0.00120"
"39.43200","3.28621","0.00130"
"39.61800","3.30170","0.00171"
"39.80400","3.31718","0.00164"
"39.99000","3.33267","0.00088"
"40.17600","3.34815","0.00126"
"40.36200","3.36364","0.00126"
"40.54800","3.37918","0.00113"
"40.73400","3.39467","0.00097"
"40.92000","3.41010","0.00106"
"41.10600","3.42570","0.00147"
"41.29200","3.44119","0.00150"
"41.47800","3.45661","0.00136"
"41.66400","3.47222","0.00126"
"41.85000","3.48770","0.00128"
"42.03600","3.50319","0.00169"
"42.22200","3.51873","0.00123"
"42.40800","3.53422","0.00121"
"42.59400","3.54970","0.00087"
"42.78000","3.56519","0.00130"
"42.96600","3.58068","0.00109"
"43.15200","3.59610","0.00124"
"43.33800","3.61165","0.00089"
"43.52400","3.62713","0.00145"
"43.71000","3.64268","0.00156"
"43.89600","3.65816","0.00164"
"44.08200","3.67365","0.00086"
"44.26800","3.68919","0.00117"
"44.45400","3.70468","0.00123"
"44.64000","3.72010","0.00141"
"44.82600","3.73577","0.00103"
"45.01200","3.75120","0.00085"
"45.19800","3.76662","0.00161"
"45.38400","3.78217","0.00139"
"45.57000","3.79765","0.00158"
"45.75600","3.81314","0.00126"
"45.94200","3.82874","0.00171"
"46.12800","3.84423","0.00125"
"46.31400","3.85959","0.00153"
"46.50000","3.87520","0.00118"
"46.68600","3.89068","0.00123"
"46.87200","3.90617","0.00165"
"47.05800","3.92165","0.00119"
"47.24400","3.93714","0.00172"
"47.43000","3.95269","0.00132"
"47.61600","3.96817","0.00119"
"47.80200","3.98360","0.00147"
"47.98800","3.99920","0.00117"
"48.17400","4.01469","0.00139"
"48.36000","4.03011","0.00178"
"48.54600","4.04566","0.00143"
"48.73200","4.06120","0.00193"
"48.91800","4.07669","0.00176"
"49.10400","4.09218","0.00122"
"49.29000","4.10772","0.00155"
"49.47600","4.12309","0.00146"
"49.66200","4.13869","0.00151"
"49.84800","4.15418","0.00194"
"50.03400","4.16966","0.00148"
"50.22000","4.18521","0.00187"
"50.40600","4.20069","0.00112"
"50.59200","4.21612","0.00181"
"50.77800","4.23172","0.00106"
"50.96400","4.24721","0.00161"
"51.15000","4.26269","0.00173"
"51.33600","4.27818","0.00173"
"51.52200","4.29361","0.00199"
"51.70800","4.30915","0.00168"
"51.89400","4.32470","0.00171"
"52.08000","4.34012","0.00154"
"52.26600","4.35567","0.00170"
"52.45200","4.37121","0.00177"
"52.63800","4.38664","0.00169"
"52.82400","4.40218","0.00195"
"53.01000","4.41767","0.00171"
"53.19600","4.43315","0.00194"
"53.38200","4.44870","0.00158"
"53.56800","4.46419","0.00191"
"53.75400","4.47967","0.00167"
"53.94000","4.49516","0.00176"
"54.12600","4.51070","0.00181"
"54.31200","4.52613","0.00196"
"54.49800","4.54173","0.00218"
"54.68400","4.55722","0.00146"
"54.87000","4.57264","0.00197"
"55.05600","4.58825","0.00235"
"55.24200","4.60367","0.00271"
"55.42800","4.61916","0.00272"
"55.61400","4.63471","0.00211"
"55.80000","4.65013","0.00184"
"55.98600","4.66562","0.00185"
"56.17200","4.68116","0.00201"
"56.35800","4.69665","0.00166"
"56.54400","4.71213","0.00222"
"56.73000","4.72768","0.00153"
"56.91600","4.74316","0.00174"
"57.10200","4.75865","0.00126"
"57.28800","4.77419","0.00193"
"57.47400","4.78968","0.00097"
"57.66000","4.80517","0.00176"
"57.84600","4.82065","0.00197"
"58.03200","4.83614","0.00207"
"58.21800","4.85168","0.00130"
"58.40400","4.86717","0.00207"
"58.59000","4.88265","0.00249"
"58.77600","4.89814","0.00148"
"58.96200","4.91368","0.00185"
"59.14800","4.92917","0.00172"
"59.33400","4.94471","0.00186"
"59.52000","4.96014","0.00185"
"59.70600","4.97563","0.00179"
"59.89200","4.99123","0.00211"
"60.07800","5.00666","0.00198"
"60.26400","5.02208","0.00201"
"60.45000","5.03769","0.00216"
"60.63600","5.05317","0.00224"
"60.82200","5.06866","0.00206"
"61.00800","5.08420","0.00204"
"61.19400","5.09975","0.00217"
"61.38000","5.11511","0.00201"
"61.56600","5.13066","0.00199"
"61.75200","5.14620","0.00250"
"61.93800","5.16169","0.00168"
"62.12400","5.17718","0.00259"
"62.31000","5.19266","0.00222"
"62.49600","5.20815","0.00249"
"62.68200","5.22369","0.00203"
"62.86800","5.23912","0.00206"
"63.05400","5.25466","0.00209"
"63.24000","5.27021","0.00191"
"63.42600","5.28563","0.00182"
"63.61200","5.30118","0.00216"
"63.79800","5.31666","0.00172"
"63.98400","5.33215","0.00232"
"64.17000","5.34770","0.00183"
"64.35600","5.36318","0.00245"
"64.54200","5.37861","0.00239"
"64.72800","5.39409","0.00208"
"64.91400","5.40976","0.00197"
"65.10000","5.42512","0.00193"
"65.28600","5.44067","0.00211"
"65.47200","5.45621","0.00214"
"65.65800","5.47164","0.00206"
"65.84400","5.48718","0.00251"
"66.03000","5.50267","0.00281"
"66.21600","5.51816","0.00249"
"66.40200","5.53364","0.00215"
"66.58800","5.54913","0.00199"
"66.77400","5.56467","0.00108"
"66.96000","5.58016","0.00147"
"67.14600","5.59564","0.00096"
"67.33200","5.61113","0.00172"
"67.51800","5.62673","0.00196"
"67.70400","5.64216","0.00143"
"67.89000","5.65764","0.00146"
"68.07600","5.67325","0.00176"
"68.26200","5.68862","0.00085"
"68.44800","5.70416","0.00201"
"68.63400","5.71965","0.00164"
"68.82000","5.73513","0.00200"
"69.00600","5.75062","0.00258"
"69.19200","5.76616","0.00212"
"69.37800","5.78165","0.00142"
"69.56400","5.79719","0.00161"
"69.75000","5.81268","0.00212"
"69.93600","5.82810","0.00179"
"70.12200","5.84371","0.00191"
"70.30800","5.85920","0.00167"
"70.49400","5.87462","0.00221"
"70.68000","5.89023","0.00239"
"70.86600","5.90565","0.00191"
"71.05200","5.92108","0.00225"
"71.23800","5.93674","0.00160"
"71.42400","5.95217","0.00145"
"71.61000","5.96759","0.00234"
"71.79600","5.98326","0.00176"
"71.98200","5.99868","0.00209"
"72.16800","6.01411","0.00261"
"72.35400","6.02972","0.00212"
"72.54000","6.04520","0.00208"
"72.72600","6.06057","0.00209"
"72.91200","6.07617","0.00235"
"73.09800","6.09160","0.00242"
"73.28400","6.10714","0.00277"
"73.47000","6.12275","0.00271"
"73.65600","6.13817","0.00202"
"73.84200","6.15366","0.00194"
"74.02800","6.16920","0.00235"
"74.21400","6.18463","0.00268"
"74.40000","6.20017","0.00231"
"74.58600","6.21572","0.00244"
"74.77200","6.23109","0.00213"
"74.95800","6.24675","0.00248"
"75.14400","6.26224","0.00257"
"75.33000","6.27760","0.00240"
"75.51600","6.29321","0.00265"
"75.70200","6.30869","0.00228"
"75.88800","6.32412","0.00209"
"76.07400","6.33972","0.00281"
"76.26000","6.35521","0.00228"
"76.44600","6.37063","0.00285"
"76.63200","6.38618","0.00255"
"76.81800","6.40173","0.00283"
"77.00400","6.41721","0.00253"
"77.19000","6.43264","0.00254"
"77.37600","6.44812","0.00280"
"77.56200","6.46367","0.00271"
"77.74800","6.47921","0.00244"
"77.93400","6.49464","0.00304"
"78.12000","6.51018","0.00267"
"78.30600","6.52567","0.00288"
"78.49200","6.54109","0.00259"
"78.67800","6.55670","0.00278"
"78.86400","6.57219","0.00180"
"79.05000","6.58761","0.00135"
"79.23600","6.60322","0.00125"
"79.42200","6.61870","0.00143"
"79.60800","6.63413","0.00067"
"79.79400","6.64973","0.00070"
"79.98000","6.66522","0.00123"
"80.16600","6.68058","0.00187"
"80.35200","6.69625","0.00155"
"80.53800","6.71167","0.00131"
"80.72400","6.72710","0.00135"
"80.91000","6.74271","0.00221"
"81.09600","6.75819","0.00135"
"81.28200","6.77362","0.00120"
"81.46800","6.78922","0.00134"
"81.65400","6.80465","0.00184"
"81.84000","6.82013","0.00150"
"82.02600","6.83568","0.00136"
"82.21200","6.85116","0.00147"
"82.39800","6.86671","0.00114"
"82.58400","6.88219","0.00199"
"82.77000","6.89762","0.00189"
"82.95600","6.91317","0.00134"
"83.14200","6.92871","0.00206"
"83.32800","6.94420","0.00199"
"83.51400","6.95962","0.00166"
"83.70000","6.97523","0.00141"
"83.88600","6.99059","0.00205"
"84.07200","7.00614","0.00189"
"84.25800","7.02168","0.00150"
"84.44400","7.03717","0.00212"
"84.63000","7.05265","0.00202"
"84.81600","7.06820","0.00187"
"85.00200","7.08368","0.00212"
"85.18800","7.09923","0.00193"
"85.37400","7.11466","0.00174"
"85.56000","7.13014","0.00256"
"85.74600","7.14575","0.00235"
"85.93200","7.16117","0.00186"
"86.11800","7.17660","0.00234"
"86.30400","7.19226","0.00211"
"86.49000","7.20763","0.00219"
"86.67600","7.22311","0.00221"
"86.86200","7.23866","0.00247"
"87.04800","7.25415","0.00227"
"87.23400","7.26963","0.00243"
"87.42000","7.28518","0.00284"
"87.60600","7.30072","0.00324"
"87.79200","7.31615","0.00284"
"87.97800","7.33163","0.00306"
"88.16400","7.34718","0.00246"
"88.35000","7.36266","0.00284"
"88.53600","7.37815","0.00303"
"88.72200","7.39363","0.00318"
"88.90800","7.40918","0.00322"
"89.09400","7.42466","0.00262"
"89.28000","7.44015","0.00262"
"89.46600","7.45570","0.00303"
"89.65200","7.47118","0.00305"
"89.83800","7.48661","0.00361"
"90.02400","7.50221","0.00354"
"90.21000","7.51764","0.00313"
"90.39600","7.53306","0.00340"
"90.58200","7.54867","0.00300"
"90.76800","7.56421","0.00320"
"90.95400","7.57964","0.00294"
"91.14000","7.59518","0.00361"
"91.32600","7.61073","0.00383"
"91.51200","7.62610","0.00352"
"91.69800","7.64164","0.00319"
"91.88400","7.65719","0.00411"
"92.07000","7.67267","0.00357"
"92.25600","7.68816","0.00350"
"92.44200","7.70364","0.00376"
"92.62800","7.71919","0.00332"
"92.81400","7.73467","0.00364"
"93.00000","7.75016","0.00316"
"93.18600","7.76570","0.00370"
"93.37200","7.78119","0.00339"
"93.55800","7.79667","0.00378"
"93.74400","7.81222","0.00405"
"93.93000","7.82771","0.00352"
"94.11600","7.84313","0.00389"
"94.30200","7.85868","0.00356"
"94.48800","7.87410","0.00423"
"94.67400","7.88965","0.00425"
"94.86000","7.90519","0.00398"
"95.04600","7.92068","0.00401"
"95.23200","7.93616","0.00387"
"95.41800","7.95171","0.00422"
"95.60400","7.96719","0.00397"
"95.79000","7.98268","0.00468"
"95.97600","7.99817","0.00406"
"96.16200","8.01365","0.00464"
"96.34800","8.02914","0.00433"
"96.53400","8.04468","0.00445"
"96.72000","8.06011","0.00412"
"96.90600","8.07565","0.00433"
"97.09200","8.09120","0.00404"
"97.27800","8.10668","0.00367"
"97.46400","8.12217","0.00485"
"97.65000","8.13771","0.00477"
"97.83600","8.15314","0.00443"
"98.02200","8.16863","0.00479"
"98.20800","8.18417","0.00436"
"98.39400","8.19966","0.00390"
"98.58000","8.21520","0.00411"
"98.76600","8.23069","0.00409"
"98.95200","8.24611","0.00471"
"99.13800","8.26166","0.00405"
"99.32400","8.27720","0.00447"
"99.51000","8.29263","0.00493"
"99.69600","8.30817","0.00468"
"99.88200","8.32366","0.00495"
"100.06800","8.33915","0.00474"
"100.25400","8.35469","0.00429"
"100.44000","8.37018","0.00468"
"100.62600","8.38566","0.00442"
"100.81200","8.40121","0.00482"
"100.99800","8.41669","0.00508"
"101.18400","8.43206","0.00512"
"101.37000","8.44772","0.00472"
"101.55600","8.46315","0.00542"
"101.74200","8.47857","0.00523"
"101.92800","8.49418","0.00492"
"102.11400","8.50966","0.00500"
"102.30000","8.52515","0.00568"
"102.48600","8.54070","0.00574"
"102.67200","8.55618","0.00572"
"102.85800","8.57167","0.00546"
"103.04400","8.58715","0.00539"
"103.23000","8.60270","0.00563"
"103.41600","8.61818","0.00541"
"103.60200","8.63367","0.00526"
"103.78800","8.64915","0.00595"
"103.97400","8.66470","0.00619"
"104.16000","8.68018","0.00503"
"104.34600","8.69561","0.00548"
"104.53200","8.71122","0.00551"
"104.71800","8.72670","0.00567"
"104.90400","8.74213","0.00527"
"105.09000","8.75773","0.00527"
"105.27600","8.77316","0.00651"
"105.46200","8.78858","0.00555"
"105.64800","8.80419","0.00555"
"105.83400","8.81967","0.00597"
"106.02000","8.83516","0.00556"
"106.20600","8.85070","0.00612"
"106.39200","8.86619","0.00568"
"106.57800","8.88162","0.00589"
"106.76400","8.89716","0.00598"
"106.95000","8.91277","0.00572"
"107.13600","8.92813","0.00654"
"107.32200","8.94362","0.00491"
"107.50800","8.95910","0.00524"
"107.69400","8.97465","0.00493"
"107.88000","8.99019","0.00473"
"108.06600","9.00562","0.00559"
"108.25200","9.02116","0.00542"
"108.43800","9.03671","0.00485"
"108.62400","9.05214","0.00533"
"108.81000","9.06768","0.00508"
"108.99600","9.08323","0.00581"
"109.18200","9.09865","0.00528"
"109.36800","9.11414","0.00570"
"109.55400","9.12968","0.00557"
"109.74000","9.14511","0.00627"
"109.92600","9.16071","0.00531"
"110.11200","9.17620","0.00557"
"110.29800","9.19162","0.00593"
"110.48400","9.20723","0.00599"
"110.67000","9.22272","0.00597"
"110.85600","9.23814","0.00568"
"111.04200","9.25369","0.00623"
"111.22800","9.26917","0.00611"
"111.41400","9.28466","0.00607"
"111.60000","9.30020","0.00647"
"111.78600","9.31563","0.00624"
"111.97200","9.33117","0.00681"
"112.15800","9.34666","0.00602"
"112.34400","9.36214","0.00636"
"112.53000","9.37763","0.00642"
"112.71600","9.39318","0.00716"
"112.90200","9.40866","0.00682"
"113.08800","9.42421","0.00619"
"113.27400","9.43969","0.00694"
"113.46000","9.45518","0.00731"
"113.64600","9.47066","0.00740"
"113.83200","9.48621","0.00743"
"114.01800","9.50163","0.00725"
"114.20400","9.51718","0.00736"
"114.39000","9.53272","0.00755"
"114.57600","9.54815","0.00767"
"114.76200","9.56369","0.00728"
"114.94800","9.57918","0.00755"
"115.13400","9.59461","0.00770"
"115.32000","9.61021","0.00823"
"115.50600","9.62570","0.00873"
"115.69200","9.64112","0.00839"
"115.87800","9.65673","0.00802"
"116.06400","9.67215","0.00803"
"116.25000","9.68764","0.00790"
"116.43600","9.70324","0.00758"
"116.62200","9.71867","0.00870"
"116.80800","9.73409","0.00831"
"116.99400","9.74970","0.00836"
"117.18000","9.76519","0.00825"
"117.36600","9.78061","0.00911"
"117.55200","9.79616","0.00891"
"117.73800","9.81164","0.00859"
"117.92400","9.82719","0.00856"
"118.11000","9.84267","0.00844"
"118.29600","9.85822","0.00855"
"118.48200","9.87364","0.00913"
"118.66800","9.88919","0.00952"
"118.85400","9.90467","0.00900"
"119.04000","9.92016","0.00911"
"119.22600","9.93570","0.00905"
"119.41200","9.95113","0.00939"
"119.59800","9.96667","0.00931"
"119.78400","9.98216","0.00977"
"119.97000","9.99759","0.00958"
"120.15600","10.01319","0.00904"
"120.34200","10.02862","0.00993"
"120.52800","10.04410","0.01003"
"120.71400","10.05971","0.00956"
"120.90000","10.07519","0.01002"
"121.08600","10.09062","0.01009"
"121.27200","10.10616","0.00965"
"121.45800","10.12171","0.01034"
"121.64400","10.13714","0.01032"
"121.83000","10.15268","0.01065"
"122.01600","10.16817","0.01029"
"122.20200","10.18365","0.01034"
"122.38800","10.19914","0.01053"
"122.57400","10.21462","0.01085"
"122.76000","10.23011","0.01128"
"122.94600","10.24571","0.01106"
"123.13200","10.26120","0.01103"
"123.31800","10.27668","0.01162"
"123.50400","10.29217","0.01143"
"123.69000","10.30766","0.01197"
"123.87600","10.32320","0.01138"
"124.06200","10.33875","0.01165"
"124.24800","10.35411","0.01202"
"124.43400","10.36960","0.01178"
"124.62000","10.38520","0.01194"
"124.80600","10.40063","0.01181"
"124.99200","10.41611","0.01210"
"125.17800","10.43172","0.01212"
"125.36400","10.44708","0.01257"
"125.55000","10.46269","0.01240"
"125.73600","10.47818","0.01184"
"125.92200","10.49366","0.01185"
"126.10800","10.50915","0.01188"
"126.29400","10.52463","0.01189"
"126.48000","10.54012","0.01238"
"126.66600","10.55566","0.01221"
"126.85200","10.57115","0.01219"
"127.03800","10.58663","0.01321"
"127.22400","10.60218","0.01327"
"127.41000","10.61767","0.01296"
"127.59600","10.63315","0.01321"
"127.78200","10.64870","0.01331"
"127.96800","10.66412","0.01368"
"128.15400","10.67961","0.01385"
"128.34000","10.69521","0.01356"
"128.52600","10.71070","0.01333"
"128.71200","10.72618","0.01419"
"128.89800","10.74173","0.01397"
"129.08400","10.75715","0.01429"
"129.27000","10.77264","0.01443"
"129.45600","10.78818","0.01447"
"129.64200","10.80367","0.01467"
"129.82800","10.81916","0.01458"
"130.01400","10.83470","0.01433"
"130.20000","10.85013","0.01479"
"130.38600","10.86567","0.01500"
"130.57200","10.88122","0.01512"
"130.75800","10.89658","0.01432"
"130.94400","10.91219","0.01437"
"131.13000","10.92767","0.01466"
"131.31600","10.94310","0.01423"
"131.50200","10.95876","0.01532"
"131.68800","10.97419","0.01492"
"131.87400","10.98962","0.01512"
"132.06000","11.00522","0.01499"
"132.24600","11.02065","0.01518"
"132.43200","11.03607","0.01552"
"132.61800","11.05174","0.01540"
"132.80400","11.06716","0.01580"
"132.99000","11.08259","0.01612"
"133.17600","11.09819","0.01621"
"133.36200","11.11368","0.01595"
"133.54800","11.12916","0.01591"
"133.73400","11.14471","0.01636"
"133.92000","11.16014","0.01609"
"134.10600","11.17568","0.01631"
"134.29200","11.19123","0.01692"
"134.47800","11.20665","0.01689"
"134.66400","11.22214","0.01735"
"134.85000","11.23774","0.01720"
"135.03600","11.25317","0.01741"
"135.22200","11.26865","0.01741"
"135.40800","11.28420","0.01791"
"135.59400","11.29956","0.01768"
"135.78000","11.31523","0.01753"
"135.96600","11.33071","0.01746"
"136.15200","11.34608","0.01753"
"136.33800","11.36168","0.01792"
"136.52400","11.37723","0.01787"
"136.71000","11.39266","0.01808"
"136.89600","11.40820","0.01830"
"137.08200","11.42369","0.01837"
"137.26800","11.43911","0.01848"
"137.45400","11.45466","0.01849"
"137.64000","11.47014","0.01895"
"137.82600","11.48563","0.01903"
"138.01200","11.50117","0.01867"
"138.19800","11.51666","0.01871"
"138.38400","11.53214","0.01955"
"138.57000","11.54769","0.01935"
"138.75600","11.56312","0.01939"
"138.94200","11.57866","0.01951"
"139.12800","11.59421","0.01991"
"139.31400","11.60957","0.01997"
"139.50000","11.62518","0.01923"
"139.68600","11.64066","0.01983"
"139.87200","11.65609","0.01966"
"140.05800","11.67169","0.02019"
"140.24400","11.68724","0.01988"
"140.43000","11.70260","0.02038"
"140.61600","11.71821","0.02021"
"140.80200","11.73363","0.02033"
"140.98800","11.74912","0.02082"
"141.17400","11.76473","0.02056"
"141.36000","11.78015","0.02059"
"141.54600","11.79570","0.02068"
"141.73200","11.81118","0.02116"
"141.91800","11.82667","0.02116"
"142.10400","11.84215","0.02105"
"142.29000","11.85770","0.02125"
"142.47600","11.87319","0.02176"
"142.66200","11.88867","0.02143"
"142.84800","11.90422","0.02178"
"143.03400","11.91964","0.02178"
"143.22000","11.93513","0.02204"
"143.40600","11.95073","0.02245"
"143.59200","11.96616","0.02231"
"143.77800","11.98164","0.02202"
"143.96400","11.99719","0.02202"
"144.15000","12.01267","0.02282"
"144.33600","12.02822","0.02263"
"144.52200","12.04370","0.02246"
"144.70800","12.05913","0.02342"
"144.89400","12.07462","0.02275"
"145.08000","12.09010","0.02320"
"145.26600","12.10565","0.02352"
"145.45200","12.12119","0.02340"
"145.63800","12.13662","0.02355"
"145.82400","12.15210","0.02380"
"146.01000","12.16771","0.02399"
"146.19600","12.18319","0.02397"
"146.38200","12.19862","0.02401"
"146.56800","12.21422","0.02422"
"146.75400","12.22965","0.02480"
"146.94000","12.24514","0.02447"
"147.12600","12.26074","0.02457"
"147.31200","12.27617","0.02533"
"147.49800","12.29165","0.02499"
"147.68400","12.30720","0.02510"
"147.87000","12.32268","0.02559"
"148.05600","12.33817","0.02531"
"148.24200","12.35365","0.02573"
"148.42800","12.36920","0.02646"
"148.61400","12.38463","0.02642"
"148.80000","12.40017","0.02645"
"148.98600","12.41566","0.02651"
"149.17200","12.43114","0.02671"
"149.35800","12.44669","0.02640"
"149.54400","12.46217","0.02684"
"149.73000","12.47772","0.02759"
"149.91600","12.49320","0.02711"
"150.10200","12.50863","0.02781"
"150.28800","12.52417","0.02830"
"150.47400","12.53972","0.02783"
"150.66000","12.55509","0.02860"
"150.84600","12.57069","0.02834"
"151.03200","12.58623","0.02871"
"151.21800","12.60160","0.02883"
"151.40400","12.61721","0.02908"
"151.59000","12.63269","0.02932"
"151.77600","12.64812","0.02977"
"151.96200","12.66366","0.02995"
"152.14800","12.67921","0.03001"
"152.33400","12.69463","0.02948"
"152.52000","12.71012","0.03058"
"152.70600","12.72566","0.03038"
"152.89200","12.74121","0.03086"
"153.07800","12.75663","0.03081"
"153.26400","12.77218","0.03112"
"153.45000","12.78767","0.03167"
"153.63600","12.80315","0.03205"
"153.82200","12.81864","0.03239"
"154.00800","12.83418","0.03165"
"154.19400","12.84967","0.03225"
"154.38000","12.86515","0.03317"
"154.56600","12.88064","0.03326"
"154.75200","12.89618","0.03352"
"154.93800","12.91161","0.03346"
"155.12400","12.92715","0.03344"
"155.31000","12.94264","0.03406"
"155.49600","12.95813","0.03404"
"155.68200","12.97367","0.03422"
"155.86800","12.98922","0.03490"
"156.05400","13.00464","0.03508"
"156.24000","13.02019","0.03541"
"156.42600","13.03567","0.03576"
"156.61200","13.05116","0.03645"
"156.79800","13.06670","0.03624"
"156.98400","13.08213","0.03641"
"157.17000","13.09767","0.03707"
"157.35600","13.11316","0.03737"
"157.54200","13.12871","0.03783"
"157.72800","13.14413","0.03791"
"157.91400","13.15968","0.03827"
"158.10000","13.17516","0.03815"
"158.28600","13.19065","0.03798"
"158.47200","13.20619","0.03800"
"158.65800","13.22162","0.03836"
"158.84400","13.23710","0.03854"
"159.03000","13.25271","0.03826"
"159.21600","13.26813","0.03858"
"159.40200","13.28368","0.03907"
"159.58800","13.29923","0.03853"
"159.77400","13.31465","0.03932"
"159.96000","13.33014","0.03992"
"160.14600","13.34568","0.03995"
"160.33200","13.36117","0.04019"
"160.51800","13.37665","0.04088"
"160.70400","13.39220","0.04123"
"160.89000","13.40762","0.04096"
"161.07600","13.42323","0.04134"
"161.26200","13.43865","0.04210"
"161.44800","13.45408","0.04245"
"161.63400","13.46975","0.04305"
"161.82000","13.48517","0.04306"
"162.00600","13.50060","0.04381"
"162.19200","13.51620","0.04379"
"162.37800","13.53169","0.04444"
"162.56400","13.54711","0.04472"
"162.75000","13.56266","0.04545"
"162.93600","13.57814","0.04572"
"163.12200","13.59363","0.04601"
"163.30800","13.60917","0.04646"
"163.49400","13.62460","0.04731"
"163.68000","13.64015","0.04777"
"163.86600","13.65563","0.04738"
"164.05200","13.67118","0.04741"
"164.23800","13.68666","0.04815"
"164.42400","13.70221","0.04874"
"164.61000","13.71763","0.04993"
"164.79600","13.73324","0.04987"
"164.98200","13.74872","0.05057"
"165.16800","13.76409","0.05057"
"165.35400","13.77969","0.05106"
"165.54000","13.79518","0.05133"
"165.72600","13.81061","0.05181"
"165.91200","13.82621","0.05196"
"166.09800","13.84175","0.05225"
"166.28400","13.85706","0.05268"
"166.47000","13.87273","0.05364"
"166.65600","13.88821","0.05358"
"166.84200","13.90364","0.05392"
"167.02800","13.91924","0.05420"
"167.21400","13.93467","0.05384"
"167.40000","13.95015","0.05428"
"167.58600","13.96570","0.05492"
"167.77200","13.98112","0.05519"
"167.95800","13.99667","0.05566"
"168.14400","14.01216","0.05617"
"168.33000","14.02764","0.05618"
"168.51600","14.04319","0.05637"
"168.70200","14.05867","0.05679"
"168.88800","14.07416","0.05747"
"169.07400","14.08964","0.05768"
"169.26000","14.10519","0.05829"
"169.44600","14.12067","0.05846"
"169.63200","14.13616","0.05898"
"169.81800","14.15170","0.05909"
"170.00400","14.16713","0.01751"
"170.19000","14.18267","0.02065"
"170.37600","14.19816","0.01980"
"170.56200","14.21365","0.01936"
"170.74800","14.22919","0.02088"
"170.93400","14.24468","0.01889"
"171.12000","14.26010","0.02098"
"171.30600","14.27571","0.01958"
"171.49200","14.29119","0.01992"
"171.67800","14.30668","0.02000"
"171.86400","14.32222","0.01992"
"172.05000","14.33765","0.02062"
"172.23600","14.35320","0.01866"
"172.42200","14.36868","0.02012"
"172.60800","14.38411","0.01937"
"172.79400","14.39965","0.01973"
"172.98000","14.41520","0.01980"
"173.16600","14.43062","0.02049"
"173.35200","14.44617","0.02072"
"173.53800","14.46165","0.01999"
"173.72400","14.47720","0.02128"
"173.91000","14.49262","0.02070"
"174.09600","14.50817","0.02105"
"174.28200","14.52359","0.02075"
"174.46800","14.53920","0.02152"
"174.65400","14.55469","0.02122"
"174.84000","14.57011","0.02120"
"175.02600","14.58572","0.02192"
"175.21200","14.60114","0.02147"
"175.39800","14.61663","0.02226"
"175.58400","14.63223","0.02207"
"175.77000","14.64772","0.02241"
"175.95600","14.66308","0.02249"
"176.14200","14.67869","0.02245"
"176.32800","14.69417","0.02336"
"176.51400","14.70960","0.02327"
"176.70000","14.72521","0.02336"
"176.88600","14.74069","0.02317"
"177.07200","14.75612","0.02380"
"177.25800","14.77172","0.02364"
"177.44400","14.78721","0.02379"
"177.63000","14.80263","0.02428"
"177.81600","14.81818","0.02444"
"178.00200","14.83366","0.02378"
"178.18800","14.84915","0.02436"
"178.37400","14.86463","0.02501"
"178.56000","14.88018","0.02441"
"178.74600","14.89567","0.02487"
"178.93200","14.91115","0.02532"
"179.11800","14.92664","0.02557"
"179.30400","14.94218","0.02572"
"179.49000","14.95767","0.02578"
"179.67600","14.97315","0.02604"
"179.86200","14.98870","0.02661"
"180.04800","15.00418","0.02676"
"180.23400","15.01961","0.02673"
"180.42000","15.03521","0.02779"
"180.60600","15.05064","0.02665"
"180.79200","15.06613","0.02767"
"180.97800","15.08167","0.02735"
"181.16400","15.09716","0.02782"
"181.35000","15.11264","0.02825"
"181.53600","15.12819","0.02747"
"181.72200","15.14367","0.02800"
"181.90800","15.15916","0.02798"
"182.09400","15.17470","0.02887"
"182.28000","15.19019","0.02882"
"182.46600","15.20568","0.02925"
"182.65200","15.22116","0.02957"
"182.83800","15.23665","0.02922"
"183.02400","15.25219","0.02984"
"183.21000","15.26768","0.03095"
"183.39600","15.28316","0.03073"
"183.58200","15.29865","0.03072"
"183.76800","15.31419","0.03194"
"183.95400","15.32962","0.03182"
"184.14000","15.34516","0.03239"
"184.32600","15.36071","0.03240"
"184.51200","15.37613","0.03276"
"184.69800","15.39168","0.03316"
"184.88400","15.40722","0.03355"
"185.07000","15.42259","0.03308"
"185.25600","15.43814","0.03422"
"185.44200","15.45374","0.03420"
"185.62800","15.46911","0.03492"
"185.81400","15.48471","0.03460"
"186.00000","15.50020","0.03477"
"186.18600","15.51562","0.03552"
"186.37200","15.53117","0.03580"
"186.55800","15.54671","0.03635"
"186.74400","15.56220","0.03582"
"186.93000","15.57763","0.03695"
"187.11600","15.59317","0.03728"
"187.30200","15.60860","0.03786"
"187.48800","15.62420","0.03835"
"187.67400","15.63968","0.03891"
"187.86000","15.65511","0.03923"
"188.04600","15.67072","0.03922"
"188.23200","15.68614","0.03988"
"188.41800","15.70163","0.04017"
"188.60400","15.71723","0.04145"
"188.79000","15.73266","0.04109"
"188.97600","15.74814","0.04203"
"189.16200","15.76369","0.04249"
"189.34800","15.77917","0.04269"
"189.53400","15.79460","0.04302"
"189.72000","15.81021","0.04396"
"189.90600","15.82563","0.04396"
"190.09200","15.84118","0.04445"
"190.27800","15.85666","0.04575"
"190.46400","15.87215","0.04517"
"190.65000","15.88775","0.04645"
"190.83600","15.90318","0.04690"
"191.02200","15.91860","0.04736"
"191.20800","15.93421","0.04735"
"191.39400","15.94969","0.04839"
"191.58000","15.96506","0.04846"
"191.76600","15.98073","0.04989"
"191.95200","15.99621","0.04999"
"192.13800","16.01158","0.05005"
"192.32400","16.02724","0.05051"
"192.51000","16.04267","0.05102"
"192.69600","16.05815","0.05186"
"192.88200","16.07370","0.05173"
"193.06800","16.08918","0.05272"
"193.25400","16.10467","0.05337"
"193.44000","16.12016","0.05344"
"193.62600","16.13564","0.05460"
"193.81200","16.15113","0.05476"
"193.99800","16.16667","0.05459"
"194.18400","16.18216","0.05565"
"194.37000","16.19770","0.05642"
"194.55600","16.21319","0.05640"
"194.74200","16.22867","0.05696"
"194.92800","16.24416","0.05717"
"195.11400","16.25970","0.05810"
"195.30000","16.27519","0.05842"
"195.48600","16.29067","0.05824"
"195.67200","16.30622","0.05874"
"195.85800","16.32159","0.05958"
"196.04400","16.33719","0.05976"
"196.23000","16.35274","0.06047"
"196.41600","16.36810","0.06072"
"196.60200","16.38365","0.06108"
"196.78800","16.39913","0.06085"
"196.97400","16.41462","0.06136"
"197.16000","16.43016","0.06221"
"197.34600","16.44571","0.06239"
"197.53200","16.46113","0.06288"
"197.71800","16.47668","0.06317"
"197.90400","16.49217","0.06338"
"198.09000","16.50765","0.06367"
"198.27600","16.52314","0.06400"
"198.46200","16.53862","0.06428"
"198.64800","16.55417","0.06472"
"198.83400","16.56965","0.06490"
"199.02000","16.58514","0.06505"
"199.20600","16.60068","0.06526"
"199.39200","16.61623","0.06561"
"199.57800","16.63171","0.06584"
"199.76400","16.64720","0.06600"
"199.95000","16.66269","0.06619"
"200.13600","16.67811","0.06676"
"200.32200","16.69366","0.06662"
"200.50800","16.70920","0.06692"
"200.69400","16.72463","0.06710"
"200.88000","16.74017","0.06760"
"201.06600","16.75572","0.06780"
"201.25200","16.77108","0.06805"
"201.43800","16.78675","0.06820"
"201.62400","16.80217","0.06706"
"201.81000","16.81766","0.06414"
"201.99600","16.83320","0.06385"
"202.18200","16.84863","0.06434"
"202.36800","16.86418","0.06405"
"202.55400","16.87966","0.06451"
"202.74000","16.89521","0.06487"
"202.92600","16.91063","0.06493"
"203.11200","16.92618","0.06264"
"203.29800","16.94166","0.06279"
"203.48400","16.95715","0.06286"
"203.67000","16.97269","0.06317"
"203.85600","16.98812","0.06325"
"204.04200","17.00366","0.06345"
"204.22800","17.01915","0.06397"
"204.41400","17.03464","0.06405"
"204.60000","17.05012","0.06419"
"204.78600","17.06567","0.06441"
"204.97200","17.08115","0.06474"
"205.15800","17.09664","0.06511"
"205.34400","17.11218","0.06497"
"205.53000","17.12767","0.06554"
"205.71600","17.14321","0.06565"
"205.90200","17.15870","0.06597"
"206.08800","17.17413","0.06588"
"206.27400","17.18973","0.06619"
"206.46000","17.20515","0.06639"
"206.64600","17.22064","0.06662"
"206.83200","17.23619","0.06643"
"207.01800","17.25161","0.06641"
"207.20400","17.26716","0.06676"
"207.39000","17.28270","0.06707"
"207.57600","17.29819","0.06720"
"207.76200","17.31361","0.06732"
"207.94800","17.32922","0.06802"
"208.13400","17.34470","0.06758"
"208.32000","17.36019","0.06797"
"208.50600","17.37568","0.06841"
"208.69200","17.39116","0.06901"
"208.87800","17.40665","0.06879"
"209.06400","17.42219","0.06918"
"209.25000","17.43762","0.06901"
"209.43600","17.45316","0.06957"
"209.62200","17.46865","0.06978"
"209.80800","17.48413","0.07006"
"209.99400","17.49974","0.07002"
"210.18000","17.51522","0.07003"
"210.36600","17.53065","0.07050"
"210.55200","17.54620","0.06052"
"210.73800","17.56168","0.00643"
"210.92400","17.57711","-0.00169"
"211.11000","17.59265","0.00036"
"211.29600","17.60820","0.00222"
"211.48200","17.62356","0.00136"
"211.66800","17.63917","0.00035"
"211.85400","17.65471","0.00059"
"212.04000","17.67014","0.00139"
"212.22600","17.68562","-0.00004"
"212.41200","17.70123","-0.00027"
"212.59800","17.71666","0.00025"
"212.78400","17.73214","0.00094"
"212.97000","17.74768","0.00029"
"213.15600","17.76317","-0.00078"
"213.34200","17.77866","-0.00087"
"213.52800","17.79414","0.00037"
"213.71400","17.80969","0.00054"
"213.90000","17.82517","0.00017"
"214.08600","17.84066","-0.00008"
"214.27200","17.85620","0.00044"
"214.45800","17.87169","0.00050"
"214.64400","17.88717","0.00045"
"214.83000","17.90266","-0.00016"
"215.01600","17.91821","0.00159"
"215.20200","17.93363","0.00081"
"215.38800","17.94918","0.00012"
"215.57400","17.96472","0.00001"
"215.76000","17.98009","0.00049"
"215.94600","17.99569","0.00061"
"216.13200","18.01118","0.00025"
"216.31800","18.02660","0.00060"
"216.50400","18.04221","0.00092"
"216.69000","18.05770","0.00040"
"216.87600","18.07318","0.00030"
"217.06200","18.08867","-0.00008"
"217.24800","18.10415","0.00075"
"217.43400","18.11964","0.00042"
"217.62000","18.13524","0.00092"
"217.80600","18.15067","0.00134"
"217.99200","18.16615","0.00064"
"218.17800","18.18170","0.00069"
"218.36400","18.19718","0.00080"
"218.55000","18.21267","0.00093"
"218.73600","18.22821","0.00117"
"218.92200","18.24364","0.00044"
"219.10800","18.25912","0.00076"
"219.29400","18.27467","0.00096"
"219.48000","18.29016","0.00101"
"219.66600","18.30570","0.00038"
"219.85200","18.32119","0.00111"
"220.03800","18.33661","0.00094"
"220.22400","18.35222","0.00029"
"220.41000","18.36770","0.00068"
"220.59600","18.38319","0.00064"
"220.78200","18.39873","0.00117"
"220.96800","18.41422","0.00083"
"221.15400","18.42964","0.00096"
"221.34000","18.44525","0.00081"
"221.52600","18.46068","0.00091"
"221.71200","18.47610","0.00173"
"221.89800","18.49171","0.00106"
"222.08400","18.50719","0.00059"
"222.27000","18.52256","0.00098"
"222.45600","18.53822","0.00140"
"222.64200","18.55371","0.00125"
"222.82800","18.56913","0.00178"
"223.01400","18.58468","0.00093"
"223.20000","18.60017","0.00128"
"223.38600","18.61565","0.00082"
"223.57200","18.63120","0.00097"
"223.75800","18.64668","0.00118"
"223.94400","18.66217","0.00170"
"224.13000","18.67771","0.00145"
"224.31600","18.69314","0.00083"
"224.50200","18.70868","0.00124"
"224.68800","18.72417","0.00158"
"224.87400","18.73959","0.00107"
"225.06000","18.75520","0.00147"
"225.24600","18.77074","0.00163"
"225.43200","18.78611","0.00091"
"225.61800","18.80177","0.00138"
"225.80400","18.81714","0.00150"
"225.99000","18.83257","0.00171"
"226.17600","18.84817","0.00112"
"226.36200","18.86372","0.00115"
"226.54800","18.87908","0.00172"
"226.73400","18.89469","0.00160"
"226.92000","18.91017","0.00116"
"227.10600","18.92560","0.00167"
"227.29200","18.94120","0.00130"
"227.47800","18.95669","0.00180"
"227.66400","18.97218","0.00181"
"227.85000","18.98766","0.00164"
"228.03600","19.00315","0.00136"
"228.22200","19.01869","0.00190"
"228.40800","19.03412","0.00195"
"228.59400","19.04960","0.00184"
"228.78000","19.06515","0.00145"
"228.96600","19.08069","0.00186"
"229.15200","19.09612","0.00205"
"229.33800","19.11167","0.00148"
"229.52400","19.12721","0.00163"
"229.71000","19.14264","0.00176"
"229.89600","19.15818","0.00151"
"230.08200","19.17367","0.00221"
"230.26800","19.18909","0.00217"
"230.45400","19.20470","0.00174"
"230.64000","19.22018","0.00216"
"230.82600","19.23567","0.00161"
"231.01200","19.25121","0.00178"
"231.19800","19.26664","0.00211"
"231.38400","19.28213","0.00211"
"231.57000","19.29773","0.00230"
"231.75600","19.31315","0.00197"
"231.94200","19.32864","0.00223"
"232.12800","19.34419","0.00249"
"232.31400","19.35961","0.00224"
"232.50000","19.37516","0.00169"
"232.68600","19.39064","0.00166"
"232.87200","19.40613","0.00248"
"233.05800","19.42167","0.00209"
"233.24400","19.43722","0.00195"
"233.43000","19.45264","0.00225"
"233.61600","19.46819","0.00223"
"233.80200","19.48368","0.00214"
"233.98800","19.49916","0.00192"
"234.17400","19.51465","0.00243"
"234.36000","19.53019","0.00281"
"234.54600","19.54568","0.00280"
"234.73200","19.56116","0.00210"
"234.91800","19.57665","0.00232"
"235.10400","19.59213","0.00251"
"235.29000","19.60768","0.00234"
"235.47600","19.62322","0.00299"
"235.66200","19.63865","0.00318"
"235.84800","19.65425","0.00271"
"236.03400","19.66968","0.00270"
"236.22000","19.68511","0.00291"
"236.40600","19.70071","0.00273"
"236.59200","19.71614","0.00250"
"236.77800","19.73156","0.00315"
"236.96400","19.74717","0.00282"
"237.15000","19.76265","0.00358"
"237.33600","19.77808","0.00325"
"237.52200","19.79374","0.00265"
"237.70800","19.80917","0.00249"
"237.89400","19.82466","0.00297"
"238.08000","19.84020","0.00282"
"238.26600","19.85574","0.00314"
"238.45200","19.87117","0.00314"
"238.63800","19.88665","0.00286"
"238.82400","19.90214","0.00265"
"239.01000","19.91763","0.00329"
"239.19600","19.93317","0.00326"
"239.38200","19.94866","0.00304"
"239.56800","19.96420","0.00344"
"239.75400","19.97969","0.00291"
"239.94000","19.99517","0.00335"
"240.12600","20.01066","0.00310"
"240.31200","20.02620","0.00383"
"240.49800","20.04163","0.00377"
"240.68400","20.05718","0.00315"
"240.87000","20.07272","0.00362"
"241.05600","20.08809","0.00333"
"241.24200","20.10363","0.00315"
"241.42800","20.11918","0.00344"
"241.61400","20.13460","0.00328"
"241.80000","20.15015","0.00399"
"241.98600","20.16575","0.00391"
"242.17200","20.18112","0.00367"
"242.35800","20.19666","0.00341"
"242.54400","20.21221","0.00304"
"242.73000","20.22764","0.00309"
"242.91600","20.24318","0.00389"
"243.10200","20.25867","0.00406"
"243.28800","20.27415","0.00405"
"243.47400","20.28970","0.00415"
"243.66000","20.30512","0.00407"
"243.84600","20.32073","0.00379"
"244.03200","20.33615","0.00420"
"244.21800","20.35170","0.00437"
"244.40400","20.36719","0.00419"
"244.59000","20.38267","0.00446"
"244.77600","20.39816","0.00456"
"244.96200","20.41364","0.00413"
"245.14800","20.42919","0.00413"
"245.33400","20.44461","0.00476"
"245.52000","20.46016","0.00449"
"245.70600","20.47570","0.00374"
"245.89200","20.49119","0.00405"
"246.07800","20.50667","0.00420"
"246.26400","20.52222","0.00419"
"246.45000","20.53765","0.00431"
"246.63600","20.55319","0.00450"
"246.82200","20.56868","0.00541"
"247.00800","20.58416","0.00438"
"247.19400","20.59965","0.00456"
"247.38000","20.61513","0.00413"
"247.56600","20.63062","0.00473"
"247.75200","20.64616","0.00498"
"247.93800","20.66165","0.00455"
"248.12400","20.67713","0.00460"
"248.31000","20.69268","0.00517"
"248.49600","20.70816","0.00485"
"248.68200","20.72365","0.00544"
"248.86800","20.73925","0.00541"
"249.05400","20.75462","0.00458"
"249.24000","20.77017","0.00503"
"249.42600","20.78571","0.00511"
"249.61200","20.80114","0.00487"
"249.79800","20.81662","0.00562"
"249.98400","20.83217","0.00525"
"250.17000","20.84765","0.00527"
"250.35600","20.86320","0.00568"
"250.54200","20.87868","0.00580"
"250.72800","20.89417","0.00597"
"250.91400","20.90972","0.00577"
"251.10000","20.92520","0.00584"
"251.28600","20.94062","0.00558"
"251.47200","20.95629","0.00495"
"251.65800","20.97166","0.00519"
"251.84400","20.98708","0.00560"
"252.03000","21.00269","0.00551"
"252.21600","21.01817","0.00552"
"252.40200","21.03360","0.00578"
"252.58800","21.04921","0.00594"
"252.77400","21.06475","0.00525"
"252.96000","21.08012","0.00525"
"253.14600","21.09572","0.00513"
"253.33200","21.11121","0.00594"
"253.51800","21.12663","0.00564"
"253.70400","21.14218","0.00526"
"253.89000","21.15766","0.00489"
"254.07600","21.17315","0.00500"
"254.26200","21.18869","0.00591"
"254.44800","21.20412","0.00505"
"254.63400","21.21967","0.00546"
"254.82000","21.23521","0.00570"
"255.00600","21.25064","0.00468"
"255.19200","21.26618","0.00466"
"255.37800","21.28167","0.00450"
"255.56400","21.29715","0.00565"
"255.75000","21.31269","0.00584"
"255.93600","21.32818","0.00499"
"256.12200","21.34361","0.00552"
"256.30800","21.35915","0.00631"
"256.49400","21.37470","0.00550"
"256.68000","21.39013","0.00572"
"256.86600","21.40567","0.00584"
"257.05200","21.42121","0.00610"
"257.23800","21.43664","0.00556"
"257.42400","21.45219","0.00626"
"257.61000","21.46773","0.00603"
"257.79600","21.48315","0.00621"
"257.98200","21.49864","0.00619"
"258.16800","21.51413","0.00631"
"258.35400","21.52961","0.00684"
"258.54000","21.54516","0.00681"
"258.72600","21.56064","0.00546"
"258.91200","21.57619","0.00687"
"259.09800","21.59173","0.00652"
"259.28400","21.60710","0.00671"
"259.47000","21.62265","0.00668"
"259.65600","21.63819","0.00637"
"259.84200","21.65368","0.00699"
"260.02800","21.66922","0.00720"
"260.21400","21.68471","0.00627"
"260.40000","21.70013","0.00692"
"260.58600","21.71568","0.00733"
"260.77200","21.73122","0.00681"
"260.95800","21.74659","0.00681"
"261.14400","21.76219","0.00650"
"261.33000","21.77768","0.00764"
"261.51600","21.79317","0.00711"
"261.70200","21.80871","0.00691"
"261.88800","21.82414","0.00758"
"262.07400","21.83968","0.00751"
"262.26000","21.85517","0.00775"
"262.44600","21.87065","0.00746"
"262.63200","21.88614","0.00769"
"262.81800","21.90168","0.00775"
"263.00400","21.91717","0.00733"
"263.19000","21.93259","0.00785"
"263.37600","21.94820","0.00717"
"263.56200","21.96369","0.00763"
"263.74800","21.97917","0.00768"
"263.93400","21.99466","0.00807"
"264.12000","22.01020","0.00814"
"264.30600","22.02563","0.00819"
"264.49200","22.04117","0.00865"
"264.67800","22.05666","0.00822"
"264.86400","22.07214","0.00828"
"265.05000","22.08769","0.00832"
"265.23600","22.10317","0.00848"
"265.42200","22.11866","0.00850"
"265.60800","22.13415","0.00831"
"265.79400","22.14969","0.00819"
"265.98000","22.16518","0.00822"
"266.16600","22.18066","0.00835"
"266.35200","22.19615","0.00835"
"266.53800","22.21175","0.00834"
"266.72400","22.22712","0.00823"
"266.91000","22.24260","0.00891"
"267.09600","22.25821","0.00854"
"267.28200","22.27363","0.00845"
"267.46800","22.28918","0.00874"
"267.65400","22.30466","0.00894"
"267.84000","22.32015","0.00874"
"268.02600","22.33563","0.00865"
"268.21200","22.35118","0.00863"
"268.39800","22.36666","0.00908"
"268.58400","22.38215","0.00893"
"268.77000","22.39770","0.00943"
"268.95600","22.41312","0.00933"
"269.14200","22.42867","0.00119"
"269.32800","22.44415","0.00093"
"269.51400","22.45964","0.00088"
"269.70000","22.47518","0.00037"
"269.88600","22.49073","0.00091"
"270.07200","22.50616","0.00236"
"270.25800","22.52170","0.00056"
"270.44400","22.53719","-0.00024"
"270.63000","22.55261","0.00145"
"270.81600","22.56816","0.00133"
"271.00200","22.58370","0.00000"
"271.18800","22.59913","0.00088"
"271.37400","22.61468","0.00190"
"271.56000","22.63022","0.00010"
"271.74600","22.64565","0.00063"
"271.93200","22.66119","0.00195"
"272.11800","22.67674","0.00065"
"272.30400","22.69216","0.00018"
"272.49000","22.70765","0.00147"
"272.67600","22.72319","0.00025"
"272.86200","22.73862","0.00018"
"273.04800","22.75416","0.00107"
"273.23400","22.76965","0.00180"
"273.42000","22.78519","0.00025"
"273.60600","22.80068","0.00101"
"273.79200","22.81616","0.00123"
"273.97800","22.83165","0.00043"
"274.16400","22.84720","0.00055"
"274.35000","22.86262","0.00159"
"274.53600","22.87816","0.00010"
"274.72200","22.89371","0.00086"
"274.90800","22.90920","0.00196"
"274.92000","22.91021","0.00179"