File: Force_trajectories/170107_1/Specimen_RawData_10.csv
End date,"1/7/2017"
Specimen label,"18AT_47/49"
Maximum Load,"0.18800",N

Time,Extension,Load
(s),(mm),(N)
"0.00000","0.00000","-0.00070"
"0.19200","0.01309","-0.00130"
"0.38400","0.03217","-0.00071"
"0.57600","0.04825","-0.00075"
"0.76800","0.06421","-0.00056"
"0.96000","0.08024","-0.00063"
"1.15200","0.09626","-0.00070"
"1.34400","0.11217","-0.00048"
"1.53600","0.12825","-0.00038"
"1.72800","0.14421","-0.00041"
"1.92000","0.16018","-0.00031"
"2.11200","0.17620","-0.00039"
"2.30400","0.19222","-0.00039"
"2.49600","0.20813","0.00005"
"2.68800","0.22421","-0.00053"
"2.88000","0.24023","-0.00018"
"3.07200","0.25614","-0.00019"
"3.26400","0.27222","-0.00023"
"3.45600","0.28819","-0.00017"
"3.64800","0.30415","-0.00038"
"3.84000","0.32023","-0.00031"
"4.03200","0.33620","-0.00072"
"4.22400","0.35216","-0.00043"
"4.41600","0.36824","-0.00087"
"4.60800","0.38415","-0.00059"
"4.80000","0.40023","-0.00083"
"4.99200","0.41619","-0.00083"
"5.18400","0.43216","-0.00055"
"5.37600","0.44818","-0.00029"
"5.56800","0.46421","-0.00058"
"5.76000","0.48017","-0.00103"
"5.95200","0.49619","-0.00029"
"6.14400","0.51216","-0.00024"
"6.33600","0.52818","-0.00024"
"6.52800","0.54420","-0.00040"
"6.72000","0.56023","-0.00087"
"6.91200","0.57619","-0.00003"
"7.10400","0.59222","-0.00045"
"7.29600","0.60818","-0.00064"
"7.48800","0.62420","0.00000"
"7.68000","0.64017","-0.00051"
"7.87200","0.65619","-0.00031"
"8.06400","0.67221","-0.00073"
"8.25600","0.68818","-0.00081"
"8.44800","0.70420","-0.00009"
"8.64000","0.72022","-0.00045"
"8.83200","0.73613","-0.00020"
"9.02400","0.75221","0.00012"
"9.21600","0.76824","-0.00030"
"9.40800","0.78414","-0.00019"
"9.60000","0.80022","-0.00064"
"9.79200","0.81625","-0.00067"
"9.98400","0.83215","-0.00021"
"10.17600","0.84823","-0.00029"
"10.36800","0.86420","-0.00041"
"10.56000","0.88010","-0.00012"
"10.75200","0.89625","-0.00017"
"10.94400","0.91215","0.00032"
"11.13600","0.92817","-0.00032"
"11.32800","0.94426","0.00005"
"11.52000","0.96016","-0.00026"
"11.71200","0.97612","-0.00033"
"11.90400","0.99227","-0.00019"
"12.09600","1.00817","0.00032"
"12.28800","1.02419","-0.00001"
"12.48000","1.04028","-0.00034"
"12.67200","1.05612","-0.00027"
"12.86400","1.07215","-0.00035"
"13.05600","1.08823","-0.00032"
"13.24800","1.10413","0.00073"
"13.44000","1.12022","0.00026"
"13.63200","1.13618","0.00014"
"13.82400","1.15214","-0.00013"
"14.01600","1.16817","0.00061"
"14.20800","1.18419","0.00018"
"14.40000","1.20016","-0.00014"
"14.59200","1.21624","-0.00020"
"14.78400","1.23220","0.00011"
"14.97600","1.24817","0.00062"
"15.16800","1.26425","-0.00009"
"15.36000","1.28021","0.00045"
"15.55200","1.29618","0.00076"
"15.74400","1.31214","0.00005"
"15.93600","1.32816","0.00026"
"16.12800","1.34419","0.00061"
"16.32000","1.36021","0.00033"
"16.51200","1.37618","0.00014"
"16.70400","1.39220","0.00040"
"16.89600","1.40816","0.00050"
"17.08800","1.42419","0.00052"
"17.28000","1.44021","0.00044"
"17.47200","1.45617","0.00076"
"17.66400","1.47220","0.00076"
"17.85600","1.48822","0.00063"
"18.04800","1.50413","0.00091"
"18.24000","1.52021","0.00055"
"18.43200","1.53623","0.00121"
"18.62400","1.55214","0.00071"
"18.81600","1.56828","0.00063"
"19.00800","1.58412","0.00034"
"19.20000","1.60015","0.00096"
"19.39200","1.61617","0.00021"
"19.58400","1.63213","0.00092"
"19.77600","1.64822","0.00093"
"19.96800","1.66424","0.00076"
"20.16000","1.68015","0.00064"
"20.35200","1.69617","0.00073"
"20.54400","1.71219","0.00071"
"20.73600","1.72816","0.00075"
"20.92800","1.74418","0.00085"
"21.12000","1.76020","0.00052"
"21.31200","1.77611","0.00084"
"21.50400","1.79219","0.00059"
"21.69600","1.80821","0.00109"
"21.88800","1.82418","0.00123"
"22.08000","1.84026","0.00064"
"22.27200","1.85617","0.00024"
"22.46400","1.87219","-0.00010"
"22.65600","1.88827","-0.00004"
"22.84800","1.90418","0.00059"
"23.04000","1.92020","0.00008"
"23.23200","1.93628","0.00074"
"23.42400","1.95213","0.00025"
"23.61600","1.96821","0.00069"
"23.80800","1.98424","0.00027"
"24.00000","2.00014","0.00025"
"24.19200","2.01622","0.00021"
"24.38400","2.03225","0.00033"
"24.57600","2.04815","0.00055"
"24.76800","2.06417","0.00036"
"24.96000","2.08020","0.00105"
"25.15200","2.09616","0.00089"
"25.34400","2.11224","0.00116"
"25.53600","2.12821","0.00053"
"25.72800","2.14411","0.00056"
"25.92000","2.16020","0.00014"
"26.11200","2.17622","0.00021"
"26.30400","2.19218","0.00005"
"26.49600","2.20821","0.00093"
"26.68800","2.22417","0.00017"
"26.88000","2.24019","0.00085"
"27.07200","2.25622","0.00046"
"27.26400","2.27218","0.00062"
"27.45600","2.28821","0.00071"
"27.64800","2.30417","0.00096"
"27.84000","2.32019","0.00065"
"28.03200","2.33622","0.00031"
"28.22400","2.35218","0.00072"
"28.41600","2.36820","0.00103"
"28.60800","2.38423","0.00111"
"28.80000","2.40013","0.00035"
"28.99200","2.41621","0.00099"
"29.18400","2.43218","0.00084"
"29.37600","2.44814","0.00135"
"29.56800","2.46429","0.00100"
"29.76000","2.48019","0.00139"
"29.95200","2.49615","0.00066"
"30.14400","2.51224","0.00093"
"30.33600","2.52814","0.00105"
"30.52800","2.54416","0.00120"
"30.72000","2.56019","0.00073"
"30.91200","2.57621","0.00108"
"31.10400","2.59218","0.00082"
"31.29600","2.60820","0.00136"
"31.48800","2.62416","0.00159"
"31.68000","2.64019","0.00126"
"31.87200","2.65621","0.00148"
"32.06400","2.67211","0.00172"
"32.25600","2.68826","0.00076"
"32.44800","2.70422","0.00153"
"32.64000","2.72012","0.00140"
"32.83200","2.73621","0.00129"
"33.02400","2.75223","0.00111"
"33.21600","2.76814","0.00125"
"33.40800","2.78422","0.00168"
"33.60000","2.80018","0.00082"
"33.79200","2.81615","0.00116"
"33.98400","2.83223","0.00135"
"34.17600","2.84819","0.00146"
"34.36800","2.86422","0.00181"
"34.56000","2.88018","0.00138"
"34.75200","2.89620","0.00130"
"34.94400","2.91223","0.00152"
"35.13600","2.92825","0.00143"
"35.32800","2.94416","0.00187"
"35.52000","2.96018","0.00200"
"35.71200","2.97626","0.00156"
"35.90400","2.99217","0.00143"
"36.09600","3.00819","0.00170"
"36.28800","3.02421","0.00168"
"36.48000","3.04018","0.00192"
"36.67200","3.05620","0.00187"
"36.86400","3.07217","0.00180"
"37.05600","3.08825","0.00190"
"37.24800","3.10421","0.00151"
"37.44000","3.12018","0.00178"
"37.63200","3.13620","0.00159"
"37.82400","3.15216","0.00162"
"38.01600","3.16813","0.00188"
"38.20800","3.18421","0.00188"
"38.40000","3.20017","0.00185"
"38.59200","3.21614","0.00150"
"38.78400","3.23222","0.00208"
"38.97600","3.24819","0.00165"
"39.16800","3.26415","0.00153"
"39.36000","3.28023","0.00185"
"39.55200","3.29614","0.00185"
"39.74400","3.31222","0.00178"
"39.93600","3.32824","0.00191"
"40.12800","3.34409","0.00219"
"40.32000","3.36023","0.00229"
"40.51200","3.37620","0.00216"
"40.70400","3.39216","0.00256"
"40.89600","3.40824","0.00178"
"41.08800","3.42421","0.00266"
"41.28000","3.44017","0.00133"
"41.47200","3.45625","0.00211"
"41.66400","3.47216","0.00181"
"41.85600","3.48818","0.00205"
"42.04800","3.50420","0.00248"
"42.24000","3.52023","0.00220"
"42.43200","3.53619","0.00190"
"42.62400","3.55222","0.00247"
"42.81600","3.56812","0.00233"
"43.00800","3.58420","0.00219"
"43.20000","3.60017","0.00203"
"43.39200","3.61613","0.00213"
"43.58400","3.63221","0.00217"
"43.77600","3.64824","0.00230"
"43.96800","3.66414","0.00187"
"44.16000","3.68022","0.00142"
"44.35200","3.69619","0.00170"
"44.54400","3.71221","0.00157"
"44.73600","3.72824","0.00197"
"44.92800","3.74420","0.00239"
"45.12000","3.76016","0.00206"
"45.31200","3.77625","0.00184"
"45.50400","3.79215","0.00201"
"45.69600","3.80823","0.00171"
"45.88800","3.82420","0.00138"
"46.08000","3.84010","0.00192"
"46.27200","3.85625","0.00193"
"46.46400","3.87221","0.00176"
"46.65600","3.88817","0.00210"
"46.84800","3.90420","0.00128"
"47.04000","3.92016","0.00192"
"47.23200","3.93618","0.00176"
"47.42400","3.95221","0.00215"
"47.61600","3.96817","0.00239"
"47.80800","3.98425","0.00199"
"48.00000","4.00022","0.00224"
"48.19200","4.01618","0.00225"
"48.38400","4.03221","0.00156"
"48.57600","4.04823","0.00188"
"48.76800","4.06419","0.00243"
"48.96000","4.08016","0.00221"
"49.15200","4.09618","0.00192"
"49.34400","4.11214","0.00226"
"49.53600","4.12817","0.00262"
"49.72800","4.14419","0.00195"
"49.92000","4.16016","0.00192"
"50.11200","4.17618","0.00203"
"50.30400","4.19220","0.00272"
"50.49600","4.20823","0.00231"
"50.68800","4.22419","0.00224"
"50.88000","4.24015","0.00212"
"51.07200","4.25624","0.00234"
"51.26400","4.27214","0.00177"
"51.45600","4.28817","0.00226"
"51.64800","4.30425","0.00235"
"51.84000","4.32009","0.00284"
"52.03200","4.33618","0.00215"
"52.22400","4.35226","0.00228"
"52.41600","4.36816","0.00217"
"52.60800","4.38419","0.00249"
"52.80000","4.40021","0.00178"
"52.99200","4.41617","0.00207"
"53.18400","4.43220","0.00205"
"53.37600","4.44822","0.00203"
"53.56800","4.46419","0.00222"
"53.76000","4.48021","0.00220"
"53.95200","4.49623","0.00201"
"54.14400","4.51214","0.00230"
"54.33600","4.52822","0.00201"
"54.52800","4.54424","0.00159"
"54.72000","4.56015","0.00230"
"54.91200","4.57623","0.00221"
"55.10400","4.59219","0.00214"
"55.29600","4.60816","0.00121"
"55.48800","4.62418","0.00156"
"55.68000","4.64015","0.00108"
"55.87200","4.65617","0.00180"
"56.06400","4.67225","0.00090"
"56.25600","4.68816","0.00131"
"56.44800","4.70424","0.00147"
"56.64000","4.72020","0.00187"
"56.83200","4.73617","0.00182"
"57.02400","4.75219","0.00162"
"57.21600","4.76822","0.00145"
"57.40800","4.78418","0.00187"
"57.60000","4.80020","0.00178"
"57.79200","4.81623","0.00129"
"57.98400","4.83219","0.00169"
"58.17600","4.84821","0.00117"
"58.36800","4.86418","0.00175"
"58.56000","4.88020","0.00162"
"58.75200","4.89616","0.00163"
"58.94400","4.91219","0.00139"
"59.13600","4.92821","0.00199"
"59.32800","4.94418","0.00116"
"59.52000","4.96020","0.00202"
"59.71200","4.97628","0.00190"
"59.90400","4.99213","0.00120"
"60.09600","5.00815","0.00198"
"60.28800","5.02423","0.00189"
"60.48000","5.04014","0.00151"
"60.67200","5.05622","0.00137"
"60.86400","5.07219","0.00158"
"61.05600","5.08815","0.00163"
"61.24800","5.10423","0.00208"
"61.44000","5.12026","0.00174"
"61.63200","5.13616","0.00148"
"61.82400","5.15224","0.00157"
"62.01600","5.16821","0.00153"
"62.20800","5.18411","0.00158"
"62.40000","5.20025","0.00135"
"62.59200","5.21622","0.00160"
"62.78400","5.23212","0.00139"
"62.97600","5.24827","0.00175"
"63.16800","5.26417","0.00154"
"63.36000","5.28013","0.00112"
"63.55200","5.29622","0.00104"
"63.74400","5.31218","0.00137"
"63.93600","5.32814","0.00135"
"64.12800","5.34423","0.00118"
"64.32000","5.36013","0.00092"
"64.51200","5.37616","0.00157"
"64.70400","5.39224","0.00142"
"64.89600","5.40820","0.00137"
"65.08800","5.42423","0.00127"
"65.28000","5.44025","0.00082"
"65.47200","5.45621","0.00130"
"65.66400","5.47218","0.00116"
"65.85600","5.48820","0.00130"
"66.04800","5.50416","0.00095"
"66.24000","5.52019","0.00118"
"66.43200","5.53615","0.00113"
"66.62400","5.55218","0.00131"
"66.81600","5.56820","0.00153"
"67.00800","5.58416","0.00101"
"67.20000","5.60019","0.00194"
"67.39200","5.61621","0.00165"
"67.58400","5.63217","0.00161"
"67.77600","5.64826","0.00141"
"67.96800","5.66422","0.00190"
"68.16000","5.68024","0.00164"
"68.35200","5.69621","0.00144"
"68.54400","5.71217","0.00172"
"68.73600","5.72820","0.00193"
"68.92800","5.74422","0.00138"
"69.12000","5.76018","0.00088"
"69.31200","5.77621","0.00109"
"69.50400","5.79223","0.00191"
"69.69600","5.80814","0.00152"
"69.88800","5.82422","0.00194"
"70.08000","5.84018","0.00146"
"70.27200","5.85615","0.00157"
"70.46400","5.87223","0.00179"
"70.65600","5.88819","0.00131"
"70.84800","5.90410","0.00164"
"71.04000","5.92018","0.00199"
"71.23200","5.93620","0.00224"
"71.42400","5.95223","0.00201"
"71.61600","5.96825","0.00145"
"71.80800","5.98410","0.00127"
"72.00000","6.00018","0.00128"
"72.19200","6.01620","0.00140"
"72.38400","6.03217","0.00154"
"72.57600","6.04819","0.00177"
"72.76800","6.06421","0.00169"
"72.96000","6.08018","0.00178"
"73.15200","6.09620","0.00182"
"73.34400","6.11222","0.00180"
"73.53600","6.12807","0.00119"
"73.72800","6.14427","0.00142"
"73.92000","6.16017","0.00157"
"74.11200","6.17614","0.00180"
"74.30400","6.19222","0.00185"
"74.49600","6.20819","0.00128"
"74.68800","6.22421","0.00178"
"74.88000","6.24023","0.00171"
"75.07200","6.25614","0.00204"
"75.26400","6.27222","0.00183"
"75.45600","6.28824","0.00160"
"75.64800","6.30415","0.00241"
"75.84000","6.32023","0.00200"
"76.03200","6.33620","0.00198"
"76.22400","6.35216","0.00243"
"76.41600","6.36818","0.00221"
"76.60800","6.38421","0.00190"
"76.80000","6.40011","0.00229"
"76.99200","6.41619","0.00231"
"77.18400","6.43216","0.00277"
"77.37600","6.44818","0.00139"
"77.56800","6.46415","0.00212"
"77.76000","6.48017","0.00217"
"77.95200","6.49619","0.00209"
"78.14400","6.51222","0.00261"
"78.33600","6.52812","0.00188"
"78.52800","6.54426","0.00216"
"78.72000","6.56023","0.00201"
"78.91200","6.57619","0.00275"
"79.10400","6.59222","0.00258"
"79.29600","6.60818","0.00198"
"79.48800","6.62420","0.00253"
"79.68000","6.64023","0.00243"
"79.87200","6.65619","0.00176"
"80.06400","6.67221","0.00235"
"80.25600","6.68818","0.00258"
"80.44800","6.70420","0.00283"
"80.64000","6.72022","0.00215"
"80.83200","6.73619","0.00282"
"81.02400","6.75215","0.00256"
"81.21600","6.76824","0.00252"
"81.40800","6.78420","0.00276"
"81.60000","6.80010","0.00258"
"81.79200","6.81619","0.00279"
"81.98400","6.83221","0.00278"
"82.17600","6.84817","0.00217"
"82.36800","6.86420","0.00205"
"82.56000","6.88016","0.00201"
"82.75200","6.89618","0.00247"
"82.94400","6.91227","0.00233"
"83.13600","6.92817","0.00165"
"83.32800","6.94426","0.00199"
"83.52000","6.96022","0.00216"
"83.71200","6.97612","0.00265"
"83.90400","6.99221","0.00267"
"84.09600","7.00823","0.00154"
"84.28800","7.02413","0.00196"
"84.48000","7.04022","0.00185"
"84.67200","7.05618","0.00258"
"84.86400","7.07214","0.00184"
"85.05600","7.08823","0.00175"
"85.24800","7.10419","0.00195"
"85.44000","7.12016","0.00292"
"85.63200","7.13624","0.00214"
"85.82400","7.15214","0.00228"
"86.01600","7.16823","0.00225"
"86.20800","7.18419","0.00212"
"86.40000","7.20021","0.00289"
"86.59200","7.21618","0.00229"
"86.78400","7.23226","0.00278"
"86.97600","7.24817","0.00238"
"87.16800","7.26419","0.00257"
"87.36000","7.28021","0.00209"
"87.55200","7.29618","0.00218"
"87.74400","7.31220","0.00256"
"87.93600","7.32816","0.00237"
"88.12800","7.34419","0.00266"
"88.32000","7.36021","0.00266"
"88.51200","7.37617","0.00211"
"88.70400","7.39226","0.00280"
"88.89600","7.40816","0.00292"
"89.08800","7.42419","0.00257"
"89.28000","7.44021","0.00243"
"89.47200","7.45623","0.00253"
"89.66400","7.47214","0.00316"
"89.85600","7.48822","0.00255"
"90.04800","7.50418","0.00281"
"90.24000","7.52015","0.00262"
"90.43200","7.53623","0.00251"
"90.62400","7.55214","0.00334"
"90.81600","7.56822","0.00225"
"91.00800","7.58424","0.00268"
"91.20000","7.60015","0.00313"
"91.39200","7.61617","0.00320"
"91.58400","7.63225","0.00322"
"91.77600","7.64816","0.00299"
"91.96800","7.66424","0.00319"
"92.16000","7.68021","0.00313"
"92.35200","7.69611","0.00285"
"92.54400","7.71225","0.00267"
"92.73600","7.72822","0.00294"
"92.92800","7.74412","0.00268"
"93.12000","7.76026","0.00268"
"93.31200","7.77623","0.00270"
"93.50400","7.79219","0.00250"
"93.69600","7.80821","0.00259"
"93.88800","7.82418","0.00309"
"94.08000","7.84020","0.00345"
"94.27200","7.85622","0.00296"
"94.46400","7.87213","0.00313"
"94.65600","7.88821","0.00310"
"94.84800","7.90424","0.00340"
"95.04000","7.92014","0.00354"
"95.23200","7.93616","0.00277"
"95.42400","7.95219","0.00315"
"95.61600","7.96815","0.00309"
"95.80800","7.98423","0.00368"
"96.00000","8.00020","0.00333"
"96.19200","8.01616","0.00338"
"96.38400","8.03219","0.00359"
"96.57600","8.04815","0.00301"
"96.76800","8.06417","0.00365"
"96.96000","8.08026","0.00259"
"97.15200","8.09610","0.00313"
"97.34400","8.11224","0.00302"
"97.53600","8.12821","0.00296"
"97.72800","8.14411","0.00371"
"97.92000","8.16025","0.00312"
"98.11200","8.17622","0.00361"
"98.30400","8.19218","0.00347"
"98.49600","8.20821","0.00383"
"98.68800","8.22417","0.00382"
"98.88000","8.24019","0.00340"
"99.07200","8.25628","0.00339"
"99.26400","8.27218","0.00281"
"99.45600","8.28820","0.00337"
"99.64800","8.30417","0.00338"
"99.84000","8.32019","0.00349"
"100.03200","8.33622","0.00348"
"100.22400","8.35224","0.00342"
"100.41600","8.36814","0.00359"
"100.60800","8.38423","0.00334"
"100.80000","8.40019","0.00348"
"100.99200","8.41615","0.00364"
"101.18400","8.43224","0.00367"
"101.37600","8.44820","0.00422"
"101.56800","8.46416","0.00391"
"101.76000","8.48019","0.00383"
"101.95200","8.49615","0.00350"
"102.14400","8.51218","0.00348"
"102.33600","8.52820","0.00426"
"102.52800","8.54416","0.00376"
"102.72000","8.56019","0.00443"
"102.91200","8.57615","0.00346"
"103.10400","8.59217","0.00395"
"103.29600","8.60820","0.00393"
"103.48800","8.62416","0.00385"
"103.68000","8.64013","0.00454"
"103.87200","8.65627","0.00408"
"104.06400","8.67217","0.00413"
"104.25600","8.68820","0.00423"
"104.44800","8.70428","0.00463"
"104.64000","8.72018","0.00409"
"104.83200","8.73621","0.00413"
"105.02400","8.75223","0.00452"
"105.21600","8.76814","0.00431"
"105.40800","8.78422","0.00410"
"105.60000","8.80024","0.00425"
"105.79200","8.81615","0.00472"
"105.98400","8.83223","0.00445"
"106.17600","8.84819","0.00451"
"106.36800","8.86416","0.00408"
"106.56000","8.88018","0.00459"
"106.75200","8.89620","0.00429"
"106.94400","8.91217","0.00365"
"107.13600","8.92819","0.00353"
"107.32800","8.94416","0.00380"
"107.52000","8.96018","0.00452"
"107.71200","8.97620","0.00414"
"107.90400","8.99217","0.00411"
"108.09600","9.00819","0.00460"
"108.28800","9.02421","0.00483"
"108.48000","9.04018","0.00405"
"108.67200","9.05620","0.00386"
"108.86400","9.07222","0.00442"
"109.05600","9.08819","0.00455"
"109.24800","9.10415","0.00455"
"109.44000","9.12018","0.00466"
"109.63200","9.13620","0.00463"
"109.82400","9.15216","0.00428"
"110.01600","9.16819","0.00486"
"110.20800","9.18415","0.00490"
"110.40000","9.20023","0.00448"
"110.59200","9.21620","0.00479"
"110.78400","9.23216","0.00475"
"110.97600","9.24819","0.00531"
"111.16800","9.26415","0.00529"
"111.36000","9.28023","0.00508"
"111.55200","9.29614","0.00544"
"111.74400","9.31216","0.00502"
"111.93600","9.32824","0.00513"
"112.12800","9.34415","0.00495"
"112.32000","9.36023","0.00534"
"112.51200","9.37619","0.00551"
"112.70400","9.39216","0.00553"
"112.89600","9.40818","0.00599"
"113.08800","9.42421","0.00620"
"113.28000","9.44017","0.00535"
"113.47200","9.45625","0.00487"
"113.66400","9.47222","0.00548"
"113.85600","9.48812","0.00568"
"114.04800","9.50420","0.00549"
"114.24000","9.52023","0.00495"
"114.43200","9.53613","0.00602"
"114.62400","9.55222","0.00540"
"114.81600","9.56818","0.00568"
"115.00800","9.58414","0.00570"
"115.20000","9.60023","0.00570"
"115.39200","9.61619","0.00528"
"115.58400","9.63215","0.00572"
"115.77600","9.64818","0.00549"
"115.96800","9.66414","0.00577"
"116.16000","9.68017","0.00596"
"116.35200","9.69625","0.00583"
"116.54400","9.71215","0.00550"
"116.73600","9.72818","0.00649"
"116.92800","9.74420","0.00611"
"117.12000","9.76016","0.00613"
"117.31200","9.77613","0.00551"
"117.50400","9.79221","0.00574"
"117.69600","9.80817","0.00644"
"117.88800","9.82420","0.00607"
"118.08000","9.84016","0.00657"
"118.27200","9.85618","0.00618"
"118.46400","9.87221","0.00679"
"118.65600","9.88817","0.00708"
"118.84800","9.90426","0.00623"
"119.04000","9.92022","0.00709"
"119.23200","9.93618","0.00666"
"119.42400","9.95221","0.00685"
"119.61600","9.96817","0.00678"
"119.80800","9.98419","0.00746"
"120.00000","10.00022","0.00723"
"120.19200","10.01618","0.00725"
"120.38400","10.03221","0.00745"
"120.57600","10.04817","0.00736"
"120.76800","10.06413","0.00772"
"120.96000","10.08022","0.00742"
"121.15200","10.09618","0.00747"
"121.34400","10.11214","0.00700"
"121.53600","10.12823","0.00749"
"121.72800","10.14425","0.00771"
"121.92000","10.16015","0.00763"
"122.11200","10.17624","0.00770"
"122.30400","10.19220","0.00748"
"122.49600","10.20811","0.00825"
"122.68800","10.22425","0.00745"
"122.88000","10.24015","0.00816"
"123.07200","10.25618","0.00790"
"123.26400","10.27220","0.00781"
"123.45600","10.28822","0.00764"
"123.64800","10.30419","0.00800"
"123.84000","10.32021","0.00833"
"124.03200","10.33618","0.00749"
"124.22400","10.35220","0.00818"
"124.41600","10.36822","0.00820"
"124.60800","10.38413","0.00858"
"124.80000","10.40021","0.00851"
"124.99200","10.41623","0.00832"
"125.18400","10.43208","0.00857"
"125.37600","10.44822","0.00866"
"125.56800","10.46418","0.00876"
"125.76000","10.48015","0.00894"
"125.95200","10.49623","0.00885"
"126.14400","10.51220","0.00869"
"126.33600","10.52822","0.00937"
"126.52800","10.54424","0.00921"
"126.72000","10.56021","0.00898"
"126.91200","10.57623","0.00844"
"127.10400","10.59219","0.00906"
"127.29600","10.60816","0.00910"
"127.48800","10.62418","0.00853"
"127.68000","10.64020","0.00917"
"127.87200","10.65617","0.00853"
"128.06400","10.67213","0.00938"
"128.25600","10.68822","0.00911"
"128.44800","10.70418","0.00897"
"128.64000","10.72014","0.00996"
"128.83200","10.73617","0.00944"
"129.02400","10.75219","0.00956"
"129.21600","10.76821","0.00985"
"129.40800","10.78424","0.01039"
"129.60000","10.80020","0.00990"
"129.79200","10.81623","0.01008"
"129.98400","10.83219","0.01095"
"130.17600","10.84827","0.01015"
"130.36800","10.86424","0.01056"
"130.56000","10.88020","0.01049"
"130.75200","10.89622","0.01087"
"130.94400","10.91219","0.00994"
"131.13600","10.92815","0.01088"
"131.32800","10.94423","0.01022"
"131.52000","10.96020","0.01065"
"131.71200","10.97622","0.01092"
"131.90400","10.99225","0.01087"
"132.09600","11.00815","0.01091"
"132.28800","11.02423","0.01102"
"132.48000","11.04020","0.01035"
"132.67200","11.05616","0.01118"
"132.86400","11.07224","0.01116"
"133.05600","11.08815","0.01065"
"133.24800","11.10411","0.01085"
"133.44000","11.12020","0.01069"
"133.63200","11.13622","0.01164"
"133.82400","11.15218","0.01113"
"134.01600","11.16821","0.01059"
"134.20800","11.18417","0.01064"
"134.40000","11.20013","0.01071"
"134.59200","11.21622","0.01097"
"134.78400","11.23218","0.01119"
"134.97600","11.24815","0.01103"
"135.16800","11.26423","0.00760"
"135.36000","11.28013","0.00708"
"135.55200","11.29622","0.00834"
"135.74400","11.31224","0.00789"
"135.93600","11.32814","0.00838"
"136.12800","11.34423","0.00906"
"136.32000","11.36025","0.00864"
"136.51200","11.37615","0.00828"
"136.70400","11.39218","0.00702"
"136.89600","11.40820","0.00536"
"137.08800","11.42417","0.00541"
"137.28000","11.44019","0.00533"
"137.47200","11.45615","0.00520"
"137.66400","11.47218","0.00623"
"137.85600","11.48820","0.00548"
"138.04800","11.50416","0.00475"
"138.24000","11.52019","0.00492"
"138.43200","11.53621","0.00475"
"138.62400","11.55212","0.00534"
"138.81600","11.56820","0.00565"
"139.00800","11.58422","0.00505"
"139.20000","11.60019","0.00574"
"139.39200","11.61621","0.00603"
"139.58400","11.63217","0.00505"
"139.77600","11.64820","0.00635"
"139.96800","11.66422","0.00523"
"140.16000","11.68013","0.00542"
"140.35200","11.69621","0.00608"
"140.54400","11.71217","0.00592"
"140.73600","11.72820","0.00627"
"140.92800","11.74422","0.00632"
"141.12000","11.76018","0.00635"
"141.31200","11.77615","0.00710"
"141.50400","11.79223","0.00720"
"141.69600","11.80814","0.00639"
"141.88800","11.82422","0.00732"
"142.08000","11.84024","0.00703"
"142.27200","11.85614","0.00722"
"142.46400","11.87217","0.00751"
"142.65600","11.88819","0.00763"
"142.84800","11.90416","0.00793"
"143.04000","11.92018","0.00763"
"143.23200","11.93620","0.00835"
"143.42400","11.95217","0.00840"
"143.61600","11.96819","0.00909"
"143.80800","11.98421","0.00873"
"144.00000","12.00012","0.00944"
"144.19200","12.01626","0.00951"
"144.38400","12.03223","0.00952"
"144.57600","12.04813","0.00982"
"144.76800","12.06427","0.01024"
"144.96000","12.08024","0.00996"
"145.15200","12.09614","0.01037"
"145.34400","12.11222","0.01056"
"145.53600","12.12819","0.01036"
"145.72800","12.14415","0.01085"
"145.92000","12.16023","0.01094"
"146.11200","12.17614","0.01114"
"146.30400","12.19222","0.01125"
"146.49600","12.20819","0.01136"
"146.68800","12.22415","0.01141"
"146.88000","12.24017","0.01129"
"147.07200","12.25620","0.01210"
"147.26400","12.27216","0.01224"
"147.45600","12.28819","0.01192"
"147.64800","12.30421","0.01197"
"147.84000","12.32017","0.01233"
"148.03200","12.33619","0.01243"
"148.22400","12.35216","0.01274"
"148.41600","12.36818","0.01268"
"148.60800","12.38421","0.01303"
"148.80000","12.40017","0.01291"
"148.99200","12.41625","0.01339"
"149.18400","12.43216","0.01330"
"149.37600","12.44818","0.01359"
"149.56800","12.46426","0.01424"
"149.76000","12.48017","0.01416"
"149.95200","12.49619","0.01445"
"150.14400","12.51222","0.01433"
"150.33600","12.52818","0.01444"
"150.52800","12.54414","0.01439"
"150.72000","12.56023","0.01485"
"150.91200","12.57613","0.01499"
"151.10400","12.59215","0.01532"
"151.29600","12.60824","0.01489"
"151.48800","12.62420","0.01550"
"151.68000","12.64023","0.01546"
"151.87200","12.65625","0.01559"
"152.06400","12.67215","0.01541"
"152.25600","12.68818","0.01567"
"152.44800","12.70420","0.01581"
"152.64000","12.72016","0.01581"
"152.83200","12.73625","0.01595"
"153.02400","12.75215","0.01622"
"153.21600","12.76817","0.01651"
"153.40800","12.78420","0.01653"
"153.60000","12.80010","0.01669"
"153.79200","12.81619","0.01720"
"153.98400","12.83215","0.01713"
"154.17600","12.84817","0.01719"
"154.36800","12.86420","0.01735"
"154.56000","12.88016","0.01798"
"154.75200","12.89618","0.01746"
"154.94400","12.91221","0.01787"
"155.13600","12.92817","0.01828"
"155.32800","12.94414","0.01835"
"155.52000","12.96022","0.01860"
"155.71200","12.97618","0.01854"
"155.90400","12.99215","0.01914"
"156.09600","13.00823","0.01881"
"156.28800","13.02419","0.01910"
"156.48000","13.04016","0.01950"
"156.67200","13.05624","0.01969"
"156.86400","13.07215","0.02007"
"157.05600","13.08817","0.01970"
"157.24800","13.10425","0.02020"
"157.44000","13.12016","0.02065"
"157.63200","13.13624","0.02056"
"157.82400","13.15220","0.02054"
"158.01600","13.16811","0.02082"
"158.20800","13.18425","0.02133"
"158.40000","13.20021","0.02126"
"158.59200","13.21618","0.02151"
"158.78400","13.23220","0.02160"
"158.97600","13.24817","0.02241"
"159.16800","13.26413","0.02240"
"159.36000","13.28021","0.02249"
"159.55200","13.29611","0.02234"
"159.74400","13.31220","0.02221"
"159.93600","13.32822","0.02302"
"160.12800","13.34419","0.02299"
"160.32000","13.36021","0.02329"
"160.51200","13.37617","0.02372"
"160.70400","13.39220","0.02403"
"160.89600","13.40810","0.02397"
"161.08800","13.42419","0.02450"
"161.28000","13.44021","0.02436"
"161.47200","13.45617","0.02483"
"161.66400","13.47220","0.02473"
"161.85600","13.48822","0.02535"
"162.04800","13.50418","0.02578"
"162.24000","13.52021","0.02655"
"162.43200","13.53623","0.02594"
"162.62400","13.55225","0.02714"
"162.81600","13.56816","0.02715"
"163.00800","13.58424","0.02742"
"163.20000","13.60015","0.02783"
"163.39200","13.61617","0.02784"
"163.58400","13.63219","0.02809"
"163.77600","13.64816","0.02853"
"163.96800","13.66412","0.02904"
"164.16000","13.68020","0.02941"
"164.35200","13.69617","0.02941"
"164.54400","13.71225","0.03020"
"164.73600","13.72822","0.03062"
"164.92800","13.74418","0.03058"
"165.12000","13.76026","0.03106"
"165.31200","13.77623","0.03184"
"165.50400","13.79213","0.03167"
"165.69600","13.80821","0.03186"
"165.88800","13.82424","0.03290"
"166.08000","13.84014","0.03270"
"166.27200","13.85616","0.03273"
"166.46400","13.87225","0.03322"
"166.65600","13.88809","0.03335"
"166.84800","13.90424","0.03380"
"167.04000","13.92020","0.03452"
"167.23200","13.93616","0.03467"
"167.42400","13.95225","0.03480"
"167.61600","13.96815","0.03564"
"167.80800","13.98417","0.03514"
"168.00000","14.00026","0.03620"
"168.19200","14.01616","0.03687"
"168.38400","14.03219","0.03686"
"168.57600","14.04821","0.03718"
"168.76800","14.06417","0.03754"
"168.96000","14.08014","0.03770"
"169.15200","14.09622","0.03835"
"169.34400","14.11218","0.03827"
"169.53600","14.12815","0.03846"
"169.72800","14.14423","0.03890"
"169.92000","14.16020","0.03938"
"170.11200","14.17616","0.03954"
"170.30400","14.19218","0.03967"
"170.49600","14.20815","0.03979"
"170.68800","14.22417","0.04074"
"170.88000","14.24019","0.04108"
"171.07200","14.25616","0.04098"
"171.26400","14.27218","0.04131"
"171.45600","14.28815","0.04209"
"171.64800","14.30423","0.04202"
"171.84000","14.32013","0.04279"
"172.03200","14.33616","0.04318"
"172.22400","14.35218","0.04368"
"172.41600","14.36814","0.04374"
"172.60800","14.38423","0.04383"
"172.80000","14.40019","0.04484"
"172.99200","14.41615","0.04488"
"173.18400","14.43224","0.04551"
"173.37600","14.44820","0.04610"
"173.56800","14.46411","0.04682"
"173.76000","14.48025","0.04703"
"173.95200","14.49615","0.04752"
"174.14400","14.51206","0.04741"
"174.33600","14.52826","0.04806"
"174.52800","14.54422","0.04908"
"174.72000","14.56013","0.04979"
"174.91200","14.57621","0.05078"
"175.10400","14.59223","0.05022"
"175.29600","14.60820","0.05123"
"175.48800","14.62422","0.05138"
"175.68000","14.64019","0.05219"
"175.87200","14.65615","0.05301"
"176.06400","14.67223","0.05363"
"176.25600","14.68814","0.05372"
"176.44800","14.70416","0.05405"
"176.64000","14.72024","0.05450"
"176.83200","14.73609","0.05569"
"177.02400","14.75223","0.05586"
"177.21600","14.76820","0.05714"
"177.40800","14.78416","0.05725"
"177.60000","14.80018","0.05810"
"177.79200","14.81627","0.05813"
"177.98400","14.83217","0.05886"
"178.17600","14.84819","0.05937"
"178.36800","14.86416","0.05980"
"178.56000","14.88018","0.06051"
"178.75200","14.89620","0.06057"
"178.94400","14.91217","0.06051"
"179.13600","14.92819","0.06184"
"179.32800","14.94416","0.06177"
"179.52000","14.96012","0.06255"
"179.71200","14.97620","0.06274"
"179.90400","14.99223","0.06319"
"180.09600","15.00819","0.06335"
"180.28800","15.02421","0.06360"
"180.48000","15.04018","0.06401"
"180.67200","15.05620","0.06481"
"180.86400","15.07222","0.06497"
"181.05600","15.08819","0.06542"
"181.24800","15.10421","0.06602"
"181.44000","15.12024","0.06630"
"181.63200","15.13614","0.06636"
"181.82400","15.15222","0.06682"
"182.01600","15.16819","0.06704"
"182.20800","15.18415","0.06759"
"182.40000","15.20017","0.06778"
"182.59200","15.21620","0.06779"
"182.78400","15.23216","0.06832"
"182.97600","15.24819","0.06896"
"183.16800","15.26421","0.06893"
"183.36000","15.28017","0.06917"
"183.55200","15.29620","0.06947"
"183.74400","15.31216","0.06974"
"183.93600","15.32818","0.07015"
"184.12800","15.34421","0.07060"
"184.32000","15.36017","0.07091"
"184.51200","15.37619","0.07072"
"184.70400","15.39222","0.07125"
"184.89600","15.40812","0.07175"
"185.08800","15.42421","0.07182"
"185.28000","15.44023","0.07216"
"185.47200","15.45613","0.07279"
"185.66400","15.47228","0.07293"
"185.85600","15.48818","0.07341"
"186.04800","15.50414","0.07402"
"186.24000","15.52023","0.07442"
"186.43200","15.53619","0.07441"
"186.62400","15.55222","0.07520"
"186.81600","15.56818","0.07586"
"187.00800","15.58414","0.07628"
"187.20000","15.60017","0.07690"
"187.39200","15.61625","0.07746"
"187.58400","15.63215","0.07798"
"187.77600","15.64824","0.07879"
"187.96800","15.66420","0.07885"
"188.16000","15.68016","0.07948"
"188.35200","15.69625","0.08038"
"188.54400","15.71221","0.08103"
"188.73600","15.72817","0.08177"
"188.92800","15.74420","0.08221"
"189.12000","15.76016","0.08302"
"189.31200","15.77619","0.08404"
"189.50400","15.79221","0.08425"
"189.69600","15.80817","0.08507"
"189.88800","15.82414","0.08589"
"190.08000","15.84016","0.08650"
"190.27200","15.85612","0.08721"
"190.46400","15.87227","0.08784"
"190.65600","15.88823","0.08860"
"190.84800","15.90420","0.08960"
"191.04000","15.92022","0.09055"
"191.23200","15.93618","0.09156"
"191.42400","15.95221","0.09212"
"191.61600","15.96817","0.09311"
"191.80800","15.98419","0.09442"
"192.00000","16.00016","0.09517"
"192.19200","16.01624","0.09577"
"192.38400","16.03214","0.09619"
"192.57600","16.04823","0.09769"
"192.76800","16.06419","0.09887"
"192.96000","16.08016","0.09977"
"193.15200","16.09624","0.10121"
"193.34400","16.11214","0.10152"
"193.53600","16.12817","0.10322"
"193.72800","16.14419","0.10430"
"193.92000","16.16015","0.10647"
"194.11200","16.17618","0.10808"
"194.30400","16.19220","0.10902"
"194.49600","16.20816","0.10944"
"194.68800","16.22419","0.11090"
"194.88000","16.24021","0.11194"
"195.07200","16.25612","0.11339"
"195.26400","16.27220","0.11461"
"195.45600","16.28822","0.11526"
"195.64800","16.30413","0.11675"
"195.84000","16.32021","0.11779"
"196.03200","16.33624","0.11784"
"196.22400","16.35214","0.11918"
"196.41600","16.36822","0.12005"
"196.60800","16.38418","0.12091"
"196.80000","16.40015","0.12197"
"196.99200","16.41623","0.12380"
"197.18400","16.43220","0.12456"
"197.37600","16.44816","0.12503"
"197.56800","16.46424","0.12613"
"197.76000","16.48015","0.12777"
"197.95200","16.49617","0.12820"
"198.14400","16.51220","0.12907"
"198.33600","16.52816","0.13025"
"198.52800","16.54418","0.13078"
"198.72000","16.56027","0.13246"
"198.91200","16.57611","0.13265"
"199.10400","16.59219","0.13485"
"199.29600","16.60822","0.13512"
"199.48800","16.62418","0.13664"
"199.68000","16.64021","0.13745"
"199.87200","16.65617","0.13834"
"200.06400","16.67219","0.13922"
"200.25600","16.68822","0.13954"
"200.44800","16.70418","0.14095"
"200.64000","16.72020","0.14234"
"200.83200","16.73623","0.14292"
"201.02400","16.75219","0.14323"
"201.21600","16.76827","0.14323"
"201.40800","16.78418","0.14406"
"201.60000","16.80020","0.14514"
"201.79200","16.81623","0.14597"
"201.98400","16.83219","0.14730"
"202.17600","16.84815","0.14728"
"202.36800","16.86418","0.14891"
"202.56000","16.88014","0.15013"
"202.75200","16.89622","0.15074"
"202.94400","16.91219","0.15132"
"203.13600","16.92821","0.15327"
"203.32800","16.94417","0.15436"
"203.52000","16.96026","0.15597"
"203.71200","16.97616","0.15651"
"203.90400","16.99219","0.15807"
"204.09600","17.00821","0.15906"
"204.28800","17.02411","0.15972"
"204.48000","17.04020","0.16031"
"204.67200","17.05616","0.16180"
"204.86400","17.07212","0.16248"
"205.05600","17.08821","0.16375"
"205.24800","17.10417","0.16393"
"205.44000","17.12019","0.16560"
"205.63200","17.13628","0.16586"
"205.82400","17.15218","0.16658"
"206.01600","17.16821","0.16784"
"206.20800","17.18417","0.16845"
"206.40000","17.20013","0.16840"
"206.59200","17.21622","0.16947"
"206.78400","17.23218","0.17080"
"206.97600","17.24814","0.17186"
"207.16800","17.26417","0.17300"
"207.36000","17.28019","0.17433"
"207.55200","17.29616","0.17467"
"207.74400","17.31218","0.17537"
"207.93600","17.32820","0.17627"
"208.12800","17.34417","0.17705"
"208.32000","17.36025","0.17778"
"208.51200","17.37615","0.17824"
"208.70400","17.39218","0.17865"
"208.89600","17.40826","0.17911"
"209.08800","17.42416","0.17986"
"209.28000","17.44019","0.18031"
"209.47200","17.45621","0.18065"
"209.66400","17.47212","0.18132"
"209.85600","17.48826","0.18195"
"210.04800","17.50422","0.18249"
"210.24000","17.52013","0.18310"
"210.43200","17.53615","0.18406"
"210.62400","17.55218","0.18479"
"210.81600","17.56820","0.18548"
"211.00800","17.58428","0.18637"
"211.20000","17.60018","0.18767"
"211.39200","17.61621","0.08573"
"211.58400","17.63223","0.07876"
"211.77600","17.64820","0.07713"
"211.96800","17.66422","0.08054"
"212.16000","17.68018","0.07833"
"212.35200","17.69615","0.08192"
"212.54400","17.71217","0.08015"
"212.73600","17.72820","0.08330"
"212.92800","17.74416","0.08389"
"213.12000","17.76018","0.08435"
"213.31200","17.77614","0.08644"
"213.50400","17.79217","0.08549"
"213.69600","17.80819","0.08960"
"213.88800","17.82416","0.02293"
"214.08000","17.84024","0.01589"
"214.27200","17.85620","0.01356"
"214.46400","17.87217","0.01514"
"214.65600","17.88825","0.00846"
"214.84800","17.90421","0.01920"
"215.04000","17.92012","0.01807"
"215.23200","17.93620","0.01284"
"215.42400","17.95217","0.02512"
"215.61600","17.96819","0.01482"
"215.80800","17.98421","0.01296"
"216.00000","18.00018","0.02312"
"216.19200","18.01620","0.01410"
"216.38400","18.03222","0.01693"
"216.57600","18.04813","0.02362"
"216.76800","18.06421","0.01469"
"216.96000","18.08023","0.01944"
"217.15200","18.09614","0.02157"
"217.34400","18.11222","0.01539"
"217.53600","18.12825","0.02284"
"217.72800","18.14409","0.01998"
"217.92000","18.16023","0.01807"
"218.11200","18.17626","0.02309"
"218.30400","18.19210","0.01882"
"218.49600","18.20824","0.02057"
"218.68800","18.22421","0.02269"
"218.88000","18.24017","0.01955"
"219.07200","18.25626","0.02345"
"219.26400","18.27216","0.02232"
"219.45600","18.28818","0.02160"
"219.64800","18.30421","0.02414"
"219.84000","18.32011","0.02182"
"220.03200","18.33619","0.02431"
"220.22400","18.35222","0.02401"
"220.41600","18.36818","0.02380"
"220.60800","18.38420","0.02548"
"220.80000","18.40023","0.02487"
"220.99200","18.41619","0.02604"
"221.18400","18.43216","0.02529"
"221.37600","18.44818","0.02579"
"221.56800","18.46414","0.02700"
"221.76000","18.48017","0.02662"
"221.95200","18.49619","0.02811"
"222.14400","18.51221","0.02806"
"222.33600","18.52824","0.02807"
"222.52800","18.54420","0.02980"
"222.72000","18.56022","0.02860"
"222.91200","18.57625","0.02987"
"223.10400","18.59221","0.03061"
"223.29600","18.60824","0.03024"
"223.48800","18.62414","0.03145"
"223.68000","18.64022","0.03103"
"223.87200","18.65619","0.03276"
"224.06400","18.67215","0.03283"
"224.25600","18.68818","0.03362"
"224.44800","18.70420","0.03403"
"224.64000","18.72016","0.03363"
"224.83200","18.73625","0.03551"
"225.02400","18.75221","0.03490"
"225.21600","18.76811","0.03617"
"225.40800","18.78426","0.03629"
"225.60000","18.80022","0.03663"
"225.79200","18.81606","0.03717"
"225.98400","18.83221","0.03759"
"226.17600","18.84817","0.03871"
"226.36800","18.86414","0.03826"
"226.56000","18.88022","0.03928"
"226.75200","18.89624","0.03961"
"226.94400","18.91215","0.04005"
"227.13600","18.92829","0.04092"
"227.32800","18.94419","0.04104"
"227.52000","18.96016","0.04177"
"227.71200","18.97618","0.04214"
"227.90400","18.99215","0.04283"
"228.09600","19.00817","0.04378"
"228.28800","19.02419","0.04401"
"228.48000","19.04016","0.04453"
"228.67200","19.05624","0.04544"
"228.86400","19.07226","0.04669"
"229.05600","19.08817","0.04676"
"229.24800","19.10419","0.04777"
"229.44000","19.12021","0.04816"
"229.63200","19.13612","0.04934"
"229.82400","19.15220","0.05013"
"230.01600","19.16823","0.05089"
"230.20800","19.18419","0.05150"
"230.40000","19.20021","0.05215"
"230.59200","19.21618","0.05359"
"230.78400","19.23220","0.05404"
"230.97600","19.24816","0.05455"
"231.16800","19.26419","0.05559"
"231.36000","19.28021","0.05593"
"231.55200","19.29618","0.05729"
"231.74400","19.31214","0.05767"
"231.93600","19.32822","0.05814"
"232.12800","19.34419","0.05951"
"232.32000","19.36015","0.06012"
"232.51200","19.37623","0.06132"
"232.70400","19.39214","0.06153"
"232.89600","19.40816","0.06247"
"233.08800","19.42418","0.06345"
"233.28000","19.44015","0.06372"
"233.47200","19.45623","0.06448"
"233.66400","19.47219","0.06494"
"233.85600","19.48816","0.06527"
"234.04800","19.50424","0.06572"
"234.24000","19.52021","0.06651"
"234.43200","19.53611","0.06674"
"234.62400","19.55219","0.06708"
"234.81600","19.56816","0.06760"
"235.00800","19.58418","0.06840"
"235.20000","19.60026","0.06853"
"235.39200","19.61617","0.06912"
"235.58400","19.63213","0.06911"
"235.77600","19.64822","0.06965"
"235.96800","19.66418","0.07044"
"236.16000","19.68014","0.07074"
"236.35200","19.69623","0.07109"
"236.54400","19.71213","0.07103"
"236.73600","19.72821","0.06492"
"236.92800","19.74424","0.06739"
"237.12000","19.76014","0.06436"
"237.31200","19.77623","0.06699"
"237.50400","19.79219","0.06749"
"237.69600","19.80815","0.06566"
"237.88800","19.82424","0.06851"
"238.08000","19.84014","0.06662"
"238.27200","19.85622","0.06825"
"238.46400","19.87225","0.06841"
"238.65600","19.88815","0.06818"
"238.84800","19.90417","0.07024"
"239.04000","19.92026","0.06918"
"239.23200","19.93616","0.06957"
"239.42400","19.95225","0.07077"
"239.61600","19.96821","0.06990"
"239.80800","19.98417","0.07133"
"240.00000","20.00020","0.07071"
"240.19200","20.01622","0.07127"
"240.38400","20.03218","0.07238"
"240.57600","20.04821","0.07147"
"240.76800","20.06423","0.07320"
"240.96000","20.08014","0.07306"
"241.15200","20.09622","0.07336"
"241.34400","20.11218","0.07429"
"241.53600","20.12821","0.07398"
"241.72800","20.14423","0.07527"
"241.92000","20.16019","0.07474"
"242.11200","20.17622","0.07552"
"242.30400","20.19218","0.07666"
"242.49600","20.20820","0.07646"
"242.68800","20.22423","0.07766"
"242.88000","20.24013","0.07796"
"243.07200","20.25621","0.07870"
"243.26400","20.27224","0.07994"
"243.45600","20.28820","0.07950"
"243.64800","20.30416","0.08232"
"243.84000","20.32025","0.08129"
"244.03200","20.33615","0.08316"
"244.22400","20.35224","0.08386"
"244.41600","20.36820","0.08372"
"244.60800","20.38410","0.08574"
"244.80000","20.40025","0.08569"
"244.99200","20.41621","0.08683"
"245.18400","20.43212","0.08746"
"245.37600","20.44820","0.08808"
"245.56800","20.46416","0.09059"
"245.76000","20.48013","0.08973"
"245.95200","20.49627","0.09257"
"246.14400","20.51217","0.09234"
"246.33600","20.52820","0.09479"
"246.52800","20.54428","0.09572"
"246.72000","20.56019","0.09612"
"246.91200","20.57621","0.09848"
"247.10400","20.59223","0.09913"
"247.29600","20.60820","0.10168"
"247.48800","20.62422","0.10246"
"247.68000","20.64018","0.10328"
"247.87200","20.65615","0.10619"
"248.06400","20.67223","0.10748"
"248.25600","20.68825","0.10983"
"248.44800","20.70416","0.10983"
"248.64000","20.72024","0.11097"
"248.83200","20.73615","0.11343"
"249.02400","20.75211","0.11444"
"249.21600","20.76819","0.11597"
"249.40800","20.78416","0.11690"
"249.60000","20.80018","0.11787"
"249.79200","20.81626","0.11949"
"249.98400","20.83217","0.12050"
"250.17600","20.84819","0.12154"
"250.36800","20.86421","0.12283"
"250.56000","20.88012","0.12471"
"250.75200","20.89614","0.12589"
"250.94400","20.91223","0.12708"
"251.13600","20.92819","0.12780"
"251.32800","20.94421","0.12903"
"251.52000","20.96018","0.13021"
"251.71200","20.97620","0.13115"
"251.90400","20.99216","0.13252"
"252.09600","21.00819","0.13308"
"252.28800","21.02421","0.13454"
"252.48000","21.04024","0.13560"
"252.67200","21.05614","0.13704"
"252.86400","21.07222","0.13747"
"253.05600","21.08819","0.13859"
"253.24800","21.10415","0.13933"
"253.44000","21.12017","0.14062"
"253.63200","21.13614","0.14210"
"253.82400","21.15222","0.14248"
"254.01600","21.16818","0.14329"
"254.20800","21.18415","0.14421"
"254.40000","21.20023","0.14544"
"254.59200","21.21620","0.14601"
"254.78400","21.23222","0.14666"
"254.97600","21.24818","0.14774"
"255.16800","21.26427","0.14912"
"255.36000","21.28017","0.14956"
"255.55200","21.29620","0.15044"
"255.74400","21.31216","0.15220"
"255.93600","21.32812","0.15307"
"256.12800","21.34420","0.15464"
"256.32000","21.36017","0.04593"
"256.51200","21.37613","0.07181"
"256.70400","21.39222","0.04677"
"256.89600","21.40824","0.04723"
"257.08800","21.42420","0.06655"
"257.28000","21.44023","0.05457"
"257.47200","21.45613","0.05489"
"257.66400","21.47222","0.06620"
"257.85600","21.48824","0.05481"
"258.04800","21.50414","0.05905"
"258.24000","21.52017","0.06679"
"258.43200","21.53619","0.05364"
"258.62400","21.55215","0.05927"
"258.81600","21.56818","0.06746"
"259.00800","21.58426","0.05671"
"259.20000","21.60016","0.05744"
"259.39200","21.61619","0.06831"
"259.58400","21.63221","0.06173"
"259.77600","21.64818","0.05535"
"259.96800","21.66420","0.06948"
"260.16000","21.68016","0.06471"
"260.35200","21.69619","0.05671"
"260.54400","21.71221","0.07125"
"260.73600","21.72811","0.06599"
"260.92800","21.74426","0.05978"
"261.12000","21.76022","0.07243"
"261.31200","21.77612","0.06621"
"261.50400","21.79221","0.06458"
"261.69600","21.80823","0.07208"
"261.88800","21.82414","0.06688"
"262.08000","21.84022","0.06662"
"262.27200","21.85618","0.07345"
"262.46400","21.87215","0.06802"
"262.65600","21.88823","0.06632"
"262.84800","21.90413","0.07636"
"263.04000","21.92016","0.06884"
"263.23200","21.93618","0.06721"
"263.42400","21.95215","0.07923"
"263.61600","21.96823","0.06886"
"263.80800","21.98419","0.06909"
"264.00000","22.00016","0.07993"
"264.19200","22.01624","0.06983"
"264.38400","22.03221","0.07004"
"264.57600","22.04817","0.08195"
"264.76800","22.06419","0.07034"
"264.96000","22.08015","0.07143"
"265.15200","22.09624","0.08217"
"265.34400","22.11220","0.07129"
"265.53600","22.12817","0.07355"
"265.72800","22.14425","0.08048"
"265.92000","22.16021","0.07212"
"266.11200","22.17618","0.07678"
"266.30400","22.19226","0.07953"
"266.49600","22.20817","0.07310"
"266.68800","22.22413","0.08148"
"266.88000","22.24021","0.07843"
"267.07200","22.25617","0.07513"
"267.26400","22.27214","0.08593"
"267.45600","22.28828","0.07702"
"267.64800","22.30419","0.07614"
"267.84000","22.32021","0.09001"
"268.03200","22.33617","0.07665"
"268.22400","22.35214","0.07850"
"268.41600","22.36822","0.08925"
"268.60800","22.38424","0.07764"
"268.80000","22.40015","0.08192"
"268.99200","22.41617","0.08748"
"269.18400","22.43220","0.07866"
"269.37600","22.44810","0.08613"
"269.56800","22.46424","0.08408"
"269.76000","22.48027","0.08002"
"269.95200","22.49611","0.09118"
"270.14400","22.51225","0.08205"
"270.33600","22.52822","0.08135"
"270.52800","22.54418","0.09389"
"270.72000","22.56021","0.08123"
"270.91200","22.57617","0.08387"
"271.10400","22.59213","0.09192"
"271.29600","22.60822","0.08152"
"271.48800","22.62418","0.08725"
"271.68000","22.64026","0.08920"
"271.87200","22.65623","0.08251"
"272.06400","22.67213","0.09194"
"272.25600","22.68827","0.08675"
"272.44800","22.70424","0.08411"
"272.64000","22.72020","0.09626"
"272.83200","22.73617","0.08549"
"273.02400","22.75219","0.08695"
"273.21600","22.76815","0.09657"
"273.40800","22.78418","0.08551"
"273.60000","22.80020","0.09126"
"273.79200","22.81622","0.09435"
"273.98400","22.83219","0.08641"
"274.17600","22.84821","0.09550"
"274.36800","22.86423","0.09109"
"274.56000","22.88020","0.08821"
"274.75200","22.89616","0.09984"
"274.94400","22.91225","0.08858"
"275.13600","22.92815","0.09019"
"275.32800","22.94411","0.10073"
"275.52000","22.96020","0.08922"
"275.71200","22.97616","0.09543"
"275.90400","22.99218","0.09768"
"276.09600","23.00821","0.09032"
"276.28800","23.02411","0.10073"
"276.48000","23.04020","0.09428"
"276.67200","23.05622","0.09214"
"276.86400","23.07212","0.10481"
"277.05600","23.08827","0.09271"
"277.24800","23.10417","0.09655"
"277.44000","23.12008","0.00094"
"277.63200","23.13628","0.00282"
"277.82400","23.15224","0.00079"
"278.01600","23.16809","0.00275"
"278.20800","23.18429","0.00101"
"278.40000","23.20019","0.00347"
"278.59200","23.21616","0.00209"
"278.78400","23.23224","0.00269"
"278.97600","23.24821","0.00201"
"279.16800","23.26417","0.00196"
"279.36000","23.28025","0.00222"
"279.55200","23.29616","0.00128"
"279.74400","23.31218","0.00200"
"279.93600","23.32820","0.00128"
"280.12800","23.34417","0.00118"
"280.32000","23.36025","0.00146"
"280.35400","23.36306","0.00234"