File: Force_trajectories/170107_1/Specimen_RawData_9.csv
End date,"1/7/2017"
Specimen label,"18AT_41"
Maximum Load,"0.04672",N

Time,Extension,Load
(s),(mm),(N)
"0.00000","0.00000","-0.00032"
"0.34200","0.02834","0.00331"
"0.68400","0.05722","0.00589"
"1.02600","0.08574","0.00707"
"1.36800","0.11414","0.00784"
"1.71000","0.14272","0.00898"
"2.05200","0.17118","0.00927"
"2.39400","0.19970","0.00914"
"2.73600","0.22822","0.00952"
"3.07800","0.25668","0.01040"
"3.42000","0.28520","0.01054"
"3.76200","0.31366","0.01050"
"4.10400","0.34218","0.01081"
"4.44600","0.37070","0.01090"
"4.78800","0.39915","0.01089"
"5.13000","0.42767","0.01096"
"5.47200","0.45619","0.01101"
"5.81400","0.48471","0.01132"
"6.15600","0.51317","0.01125"
"6.49800","0.54169","0.01099"
"6.84000","0.57015","0.01141"
"7.18200","0.59867","0.01155"
"7.52400","0.62719","0.01141"
"7.86600","0.65559","0.01131"
"8.20800","0.68417","0.01120"
"8.55000","0.71269","0.01141"
"8.89200","0.74109","0.01170"
"9.23400","0.76973","0.01159"
"9.57600","0.79819","0.01156"
"9.91800","0.82665","0.01141"
"10.26000","0.85523","0.01131"
"10.60200","0.88369","0.01183"
"10.94400","0.91221","0.01228"
"11.28600","0.94073","0.01162"
"11.62800","0.96919","0.01191"
"11.97000","0.99771","0.01186"
"12.31200","1.02623","0.01154"
"12.65400","1.05463","0.01166"
"12.99600","1.08321","0.01188"
"13.33800","1.11167","0.01173"
"13.68000","1.14013","0.01186"
"14.02200","1.16871","0.01172"
"14.36400","1.19717","0.01192"
"14.70600","1.22569","0.01214"
"15.04800","1.25426","0.01156"
"15.39000","1.28261","0.01199"
"15.73200","1.31124","0.01174"
"16.07400","1.33970","0.01204"
"16.41600","1.36810","0.01183"
"16.75800","1.39674","0.01198"
"17.10000","1.42508","0.01205"
"17.44200","1.45366","0.01182"
"17.78400","1.48218","0.01143"
"18.12600","1.51064","0.01188"
"18.46800","1.53922","0.01188"
"18.81000","1.56768","0.01178"
"19.15200","1.59614","0.01188"
"19.49400","1.62472","0.01176"
"19.83600","1.65318","0.01194"
"20.17800","1.68170","0.01205"
"20.52000","1.71022","0.01217"
"20.86200","1.73862","0.01236"
"21.20400","1.76720","0.01182"
"21.54600","1.79572","0.01205"
"21.88800","1.82418","0.01178"
"22.23000","1.85264","0.01240"
"22.57200","1.88116","0.01207"
"22.91400","1.90962","0.01214"
"23.25600","1.93820","0.01228"
"23.59800","1.96672","0.01162"
"23.94000","1.99512","0.01239"
"24.28200","2.02370","0.01215"
"24.62400","2.05222","0.01227"
"24.96600","2.08068","0.01238"
"25.30800","2.10920","0.01254"
"25.65000","2.13772","0.01227"
"25.99200","2.16617","0.01203"
"26.33400","2.19469","0.01241"
"26.67600","2.22315","0.01232"
"27.01800","2.25167","0.01220"
"27.36000","2.28019","0.01249"
"27.70200","2.30871","0.01280"
"28.04400","2.33723","0.01271"
"28.38600","2.36569","0.01261"
"28.72800","2.39421","0.01239"
"29.07000","2.42273","0.01249"
"29.41200","2.45113","0.01232"
"29.75400","2.47971","0.01297"
"30.09600","2.50829","0.01280"
"30.43800","2.53663","0.01275"
"30.78000","2.56521","0.01339"
"31.12200","2.59367","0.01329"
"31.46400","2.62213","0.01351"
"31.80600","2.65071","0.01379"
"32.14800","2.67917","0.01349"
"32.49000","2.70769","0.01339"
"32.83200","2.73621","0.01419"
"33.17400","2.76461","0.01378"
"33.51600","2.79319","0.01357"
"33.85800","2.82171","0.01384"
"34.20000","2.85011","0.01352"
"34.54200","2.87875","0.01401"
"34.88400","2.90721","0.01399"
"35.22600","2.93567","0.01412"
"35.56800","2.96425","0.01377"
"35.91000","2.99265","0.01402"
"36.25200","3.02122","0.01437"
"36.59400","3.04968","0.01432"
"36.93600","3.07808","0.01414"
"37.27800","3.10672","0.01424"
"37.62000","3.13518","0.01422"
"37.96200","3.16364","0.01423"
"38.30400","3.19222","0.01441"
"38.64600","3.22068","0.01475"
"38.98800","3.24920","0.01448"
"39.33000","3.27766","0.01478"
"39.67200","3.30618","0.01418"
"40.01400","3.33470","0.01488"
"40.35600","3.36316","0.01534"
"40.69800","3.39168","0.01509"
"41.04000","3.42020","0.01449"
"41.38200","3.44866","0.01470"
"41.72400","3.47718","0.01495"
"42.06600","3.50570","0.01416"
"42.40800","3.53422","0.01492"
"42.75000","3.56268","0.01511"
"43.09200","3.59120","0.01514"
"43.43400","3.61966","0.01538"
"43.77600","3.64818","0.01462"
"44.11800","3.67670","0.01553"
"44.46000","3.70516","0.01455"
"44.80200","3.73368","0.01487"
"45.14400","3.76220","0.01519"
"45.48600","3.79060","0.01524"
"45.82800","3.81918","0.01526"
"46.17000","3.84770","0.01521"
"46.51200","3.87622","0.01484"
"46.85400","3.90468","0.01518"
"47.19600","3.93314","0.01464"
"47.53800","3.96165","0.01480"
"47.88000","3.99017","0.01490"
"48.22200","4.01869","0.01559"
"48.56400","4.04721","0.01514"
"48.90600","4.07573","0.01529"
"49.24800","4.10413","0.01507"
"49.59000","4.13271","0.01519"
"49.93200","4.16117","0.01503"
"50.27400","4.18969","0.01537"
"50.61600","4.21821","0.01541"
"50.95800","4.24661","0.01525"
"51.30000","4.27519","0.01516"
"51.64200","4.30371","0.01526"
"51.98400","4.33211","0.01564"
"52.32600","4.36075","0.01502"
"52.66800","4.38915","0.01538"
"53.01000","4.41767","0.01527"
"53.35200","4.44625","0.01505"
"53.69400","4.47465","0.01513"
"54.03600","4.50323","0.01497"
"54.37800","4.53169","0.01524"
"54.72000","4.56009","0.01497"
"55.06200","4.58873","0.01500"
"55.40400","4.61719","0.01505"
"55.74600","4.64565","0.01477"
"56.08800","4.67417","0.01510"
"56.43000","4.70263","0.01516"
"56.77200","4.73115","0.01471"
"57.11400","4.75967","0.01555"
"57.45600","4.78819","0.01490"
"57.79800","4.81664","0.01510"
"58.14000","4.84522","0.01498"
"58.48200","4.87362","0.01495"
"58.82400","4.90220","0.01530"
"59.16600","4.93072","0.01496"
"59.50800","4.95906","0.01466"
"59.85000","4.98770","0.01429"
"60.19200","5.01616","0.01473"
"60.53400","5.04468","0.01474"
"60.87600","5.07320","0.01540"
"61.21800","5.10172","0.01509"
"61.56000","5.13018","0.01545"
"61.90200","5.15864","0.01478"
"62.24400","5.18716","0.01514"
"62.58600","5.21568","0.01479"
"62.92800","5.24420","0.01527"
"63.27000","5.27266","0.01509"
"63.61200","5.30124","0.01516"
"63.95400","5.32976","0.01559"
"64.29600","5.35816","0.01463"
"64.63800","5.38674","0.01491"
"64.98000","5.41520","0.01518"
"65.32200","5.44360","0.01507"
"65.66400","5.47224","0.01508"
"66.00600","5.50064","0.01475"
"66.34800","5.52916","0.01513"
"66.69000","5.55774","0.01542"
"67.03200","5.58614","0.01471"
"67.37400","5.61472","0.01509"
"67.71600","5.64324","0.01517"
"68.05800","5.67164","0.01506"
"68.40000","5.70021","0.01552"
"68.74200","5.72867","0.01560"
"69.08400","5.75713","0.01487"
"69.42600","5.78571","0.01554"
"69.76800","5.81411","0.01566"
"70.11000","5.84275","0.01533"
"70.45200","5.87121","0.01518"
"70.79400","5.89967","0.01539"
"71.13600","5.92825","0.01598"
"71.47800","5.95671","0.01536"
"71.82000","5.98517","0.01522"
"72.16200","6.01369","0.01562"
"72.50400","6.04215","0.01550"
"72.84600","6.07073","0.01488"
"73.18800","6.09919","0.01511"
"73.53000","6.12759","0.01519"
"73.87200","6.15617","0.01442"
"74.21400","6.18469","0.01510"
"74.55600","6.21315","0.01537"
"74.89800","6.24173","0.01509"
"75.24000","6.27019","0.01552"
"75.58200","6.29871","0.01551"
"75.92400","6.32717","0.01570"
"76.26600","6.35569","0.01501"
"76.60800","6.38421","0.01480"
"76.95000","6.41267","0.01573"
"77.29200","6.44119","0.01534"
"77.63400","6.46971","0.01503"
"77.97600","6.49817","0.01517"
"78.31800","6.52663","0.01528"
"78.66000","6.55520","0.01482"
"79.00200","6.58366","0.01476"
"79.34400","6.61212","0.01467"
"79.68600","6.64064","0.01505"
"80.02800","6.66916","0.01524"
"80.37000","6.69768","0.01479"
"80.71200","6.72620","0.01526"
"81.05400","6.75466","0.01545"
"81.39600","6.78318","0.01538"
"81.73800","6.81176","0.01490"
"82.08000","6.84016","0.01514"
"82.42200","6.86868","0.01555"
"82.76400","6.89720","0.01542"
"83.10600","6.92566","0.01585"
"83.44800","6.95424","0.01582"
"83.79000","6.98270","0.01552"
"84.13200","7.01116","0.01572"
"84.47400","7.03968","0.01521"
"84.81600","7.06814","0.01520"
"85.15800","7.09672","0.01570"
"85.50000","7.12524","0.01624"
"85.84200","7.15364","0.01593"
"86.18400","7.18222","0.01522"
"86.52600","7.21062","0.01482"
"86.86800","7.23914","0.01486"
"87.21000","7.26778","0.01557"
"87.55200","7.29618","0.01543"
"87.89400","7.32470","0.01600"
"88.23600","7.35316","0.01548"
"88.57800","7.38162","0.01528"
"88.92000","7.41025","0.01542"
"89.26200","7.43871","0.01523"
"89.60400","7.46717","0.01559"
"89.94600","7.49575","0.01534"
"90.28800","7.52415","0.01581"
"90.63000","7.55267","0.01549"
"90.97200","7.58113","0.01551"
"91.31400","7.60965","0.01487"
"91.65600","7.63823","0.01521"
"91.99800","7.66675","0.01437"
"92.34000","7.69515","0.01550"
"92.68200","7.72373","0.01503"
"93.02400","7.75219","0.01536"
"93.36600","7.78071","0.01497"
"93.70800","7.80917","0.01547"
"94.05000","7.83769","0.01510"
"94.39200","7.86621","0.01498"
"94.73400","7.89467","0.01613"
"95.07600","7.92313","0.01610"
"95.41800","7.95171","0.01550"
"95.76000","7.98017","0.01523"
"96.10200","8.00869","0.01587"
"96.44400","8.03721","0.01580"
"96.78600","8.06573","0.01576"
"97.12800","8.09419","0.01580"
"97.47000","8.12265","0.01584"
"97.81200","8.15117","0.01564"
"98.15400","8.17963","0.01575"
"98.49600","8.20815","0.01570"
"98.83800","8.23667","0.01544"
"99.18000","8.26519","0.01595"
"99.52200","8.29370","0.01558"
"99.86400","8.32216","0.01588"
"100.20600","8.35068","0.01591"
"100.54800","8.37920","0.01607"
"100.89000","8.40760","0.01595"
"101.23200","8.43618","0.01528"
"101.57400","8.46470","0.01535"
"101.91600","8.49316","0.01541"
"102.25800","8.52174","0.01586"
"102.60000","8.55008","0.01609"
"102.94200","8.57872","0.01559"
"103.28400","8.60718","0.01554"
"103.62600","8.63564","0.01624"
"103.96800","8.66422","0.01549"
"104.31000","8.69268","0.01613"
"104.65200","8.72114","0.01616"
"104.99400","8.74972","0.01575"
"105.33600","8.77812","0.01581"
"105.67800","8.80664","0.01586"
"106.02000","8.83522","0.01595"
"106.36200","8.86362","0.01623"
"106.70400","8.89220","0.01624"
"107.04600","8.92072","0.01601"
"107.38800","8.94918","0.01591"
"107.73000","8.97770","0.01596"
"108.07200","9.00616","0.01640"
"108.41400","9.03462","0.01584"
"108.75600","9.06320","0.01615"
"109.09800","9.09166","0.01693"
"109.44000","9.12024","0.01626"
"109.78200","9.14864","0.01700"
"110.12400","9.17710","0.01580"
"110.46600","9.20573","0.01628"
"110.80800","9.23419","0.01647"
"111.15000","9.26265","0.01643"
"111.49200","9.29117","0.01685"
"111.83400","9.31963","0.01618"
"112.17600","9.34815","0.01640"
"112.51800","9.37673","0.01658"
"112.86000","9.40513","0.01699"
"113.20200","9.43371","0.01628"
"113.54400","9.46217","0.01621"
"113.88600","9.49069","0.01658"
"114.22800","9.51921","0.01694"
"114.57000","9.54767","0.01702"
"114.91200","9.57619","0.01683"
"115.25400","9.60465","0.01675"
"115.59600","9.63317","0.01678"
"115.93800","9.66163","0.01707"
"116.28000","9.69015","0.01687"
"116.62200","9.71867","0.01677"
"116.96400","9.74713","0.01669"
"117.30600","9.77571","0.01674"
"117.64800","9.80417","0.01638"
"117.99000","9.83269","0.01639"
"118.33200","9.86127","0.01631"
"118.67400","9.88961","0.01710"
"119.01600","9.91819","0.01665"
"119.35800","9.94671","0.01716"
"119.70000","9.97517","0.01683"
"120.04200","10.00369","0.01690"
"120.38400","10.03215","0.01656"
"120.72600","10.06066","0.01637"
"121.06800","10.08924","0.01740"
"121.41000","10.11764","0.01668"
"121.75200","10.14622","0.01760"
"122.09400","10.17468","0.01685"
"122.43600","10.20314","0.01759"
"122.77800","10.23172","0.01709"
"123.12000","10.26018","0.01744"
"123.46200","10.28870","0.01687"
"123.80400","10.31716","0.01735"
"124.14600","10.34568","0.01666"
"124.48800","10.37420","0.01706"
"124.83000","10.40272","0.01738"
"125.17200","10.43112","0.01784"
"125.51400","10.45970","0.01739"
"125.85600","10.48822","0.01663"
"126.19800","10.51662","0.01723"
"126.54000","10.54520","0.01755"
"126.88200","10.57366","0.01759"
"127.22400","10.60218","0.01791"
"127.56600","10.63070","0.01789"
"127.90800","10.65916","0.01766"
"128.25000","10.68768","0.01803"
"128.59200","10.71626","0.01833"
"128.93400","10.74466","0.01816"
"129.27600","10.77318","0.01841"
"129.61800","10.80164","0.01841"
"129.96000","10.83016","0.01893"
"130.30200","10.85874","0.01859"
"130.64400","10.88720","0.01854"
"130.98600","10.91572","0.01866"
"131.32800","10.94418","0.01906"
"131.67000","10.97263","0.01898"
"132.01200","11.00121","0.01881"
"132.35400","11.02973","0.01913"
"132.69600","11.05819","0.01882"
"133.03800","11.08671","0.01973"
"133.38000","11.11517","0.01966"
"133.72200","11.14363","0.01936"
"134.06400","11.17215","0.01907"
"134.40600","11.20067","0.01936"
"134.74800","11.22913","0.01982"
"135.09000","11.25771","0.01986"
"135.43200","11.28617","0.02009"
"135.77400","11.31469","0.01968"
"136.11600","11.34321","0.01982"
"136.45800","11.37161","0.02130"
"136.80000","11.40019","0.02036"
"137.14200","11.42871","0.01972"
"137.48400","11.45717","0.01993"
"137.82600","11.48575","0.02038"
"138.16800","11.51415","0.01975"
"138.51000","11.54261","0.02037"
"138.85200","11.57125","0.02023"
"139.19400","11.59965","0.01992"
"139.53600","11.62817","0.02101"
"139.87800","11.65675","0.02090"
"140.22000","11.68515","0.02015"
"140.56200","11.71373","0.02059"
"140.90400","11.74213","0.02143"
"141.24600","11.77065","0.02091"
"141.58800","11.79922","0.02155"
"141.93000","11.82762","0.02138"
"142.27200","11.85614","0.02144"
"142.61400","11.88472","0.02126"
"142.95600","11.91318","0.02225"
"143.29800","11.94170","0.02197"
"143.64000","11.97022","0.02198"
"143.98200","11.99856","0.02119"
"144.32400","12.02714","0.02134"
"144.66600","12.05572","0.02179"
"145.00800","12.08418","0.02192"
"145.35000","12.11270","0.02201"
"145.69200","12.14110","0.02133"
"146.03400","12.16968","0.02193"
"146.37600","12.19820","0.02143"
"146.71800","12.22660","0.02185"
"147.06000","12.25524","0.02213"
"147.40200","12.28370","0.02209"
"147.74400","12.31216","0.02177"
"148.08600","12.34074","0.02188"
"148.42800","12.36914","0.02226"
"148.77000","12.39760","0.02260"
"149.11200","12.42618","0.02299"
"149.45400","12.45470","0.02229"
"149.79600","12.48316","0.02252"
"150.13800","12.51168","0.02264"
"150.48000","12.54020","0.02281"
"150.82200","12.56866","0.02351"
"151.16400","12.59718","0.02314"
"151.50600","12.62570","0.02217"
"151.84800","12.65421","0.02294"
"152.19000","12.68268","0.02313"
"152.53200","12.71114","0.02335"
"152.87400","12.73972","0.02356"
"153.21600","12.76824","0.02253"
"153.55800","12.79663","0.02361"
"153.90000","12.82521","0.02338"
"154.24200","12.85361","0.02358"
"154.58400","12.88219","0.02378"
"154.92600","12.91071","0.02403"
"155.26800","12.93911","0.02408"
"155.61000","12.96775","0.02363"
"155.95200","12.99621","0.02403"
"156.29400","13.02467","0.02429"
"156.63600","13.05319","0.02430"
"156.97800","13.08165","0.02428"
"157.32000","13.11017","0.02422"
"157.66200","13.13875","0.02475"
"158.00400","13.16715","0.02523"
"158.34600","13.19567","0.02467"
"158.68800","13.22419","0.02481"
"159.03000","13.25265","0.02425"
"159.37200","13.28123","0.02482"
"159.71400","13.30963","0.02453"
"160.05600","13.33815","0.02432"
"160.39800","13.36667","0.02470"
"160.74000","13.39513","0.02440"
"161.08200","13.42371","0.02482"
"161.42400","13.45223","0.02525"
"161.76600","13.48057","0.02504"
"162.10800","13.50921","0.02538"
"162.45000","13.53773","0.02578"
"162.79200","13.56612","0.02533"
"163.13400","13.59471","0.02592"
"163.47600","13.62316","0.02576"
"163.81800","13.65168","0.02588"
"164.16000","13.68020","0.02625"
"164.50200","13.70866","0.02649"
"164.84400","13.73724","0.02661"
"165.18600","13.76564","0.02680"
"165.52800","13.79416","0.02675"
"165.87000","13.82274","0.02637"
"166.21200","13.85120","0.02697"
"166.55400","13.87966","0.02615"
"166.89600","13.90818","0.02654"
"167.23800","13.93664","0.02637"
"167.58000","13.96516","0.02681"
"167.92200","13.99368","0.02690"
"168.26400","14.02220","0.02688"
"168.60600","14.05066","0.02753"
"168.94800","14.07918","0.02679"
"169.29000","14.10764","0.02720"
"169.63200","14.13622","0.02741"
"169.97400","14.16474","0.02734"
"170.31600","14.19320","0.02800"
"170.65800","14.22172","0.02776"
"171.00000","14.25018","0.02808"
"171.34200","14.27870","0.02794"
"171.68400","14.30722","0.02826"
"172.02600","14.33568","0.02811"
"172.36800","14.36414","0.02824"
"172.71000","14.39272","0.02837"
"173.05200","14.42112","0.02825"
"173.39400","14.44970","0.02899"
"173.73600","14.47822","0.02898"
"174.07800","14.50662","0.02843"
"174.42000","14.53519","0.02869"
"174.76200","14.56371","0.02866"
"175.10400","14.59217","0.02878"
"175.44600","14.62069","0.02899"
"175.78800","14.64915","0.02912"
"176.13000","14.67767","0.02969"
"176.47200","14.70625","0.02921"
"176.81400","14.73465","0.02935"
"177.15600","14.76317","0.02931"
"177.49800","14.79163","0.02936"
"177.84000","14.82009","0.02907"
"178.18200","14.84873","0.02945"
"178.52400","14.87713","0.02955"
"178.86600","14.90565","0.02966"
"179.20800","14.93423","0.02943"
"179.55000","14.96263","0.02986"
"179.89200","14.99121","0.03000"
"180.23400","15.01967","0.03001"
"180.57600","15.04813","0.02992"
"180.91800","15.07671","0.03022"
"181.26000","15.10517","0.03034"
"181.60200","15.13369","0.03030"
"181.94400","15.16221","0.03060"
"182.28600","15.19061","0.03091"
"182.62800","15.21919","0.03124"
"182.97000","15.24765","0.03039"
"183.31200","15.27611","0.03087"
"183.65400","15.30469","0.03084"
"183.99600","15.33321","0.03101"
"184.33800","15.36166","0.03140"
"184.68000","15.39025","0.03109"
"185.02200","15.41871","0.03038"
"185.36400","15.44716","0.03109"
"185.70600","15.47569","0.03112"
"186.04800","15.50420","0.03102"
"186.39000","15.53266","0.03079"
"186.73200","15.56118","0.03142"
"187.07400","15.58964","0.03143"
"187.41600","15.61816","0.03185"
"187.75800","15.64674","0.03208"
"188.10000","15.67514","0.03192"
"188.44200","15.70372","0.03257"
"188.78400","15.73218","0.03266"
"189.12600","15.76070","0.03230"
"189.46800","15.78922","0.03242"
"189.81000","15.81768","0.03250"
"190.15200","15.84614","0.03328"
"190.49400","15.87472","0.03292"
"190.83600","15.90318","0.03378"
"191.17800","15.93170","0.03340"
"191.52000","15.96028","0.03418"
"191.86200","15.98862","0.03407"
"192.20400","16.01720","0.03410"
"192.54600","16.04566","0.03453"
"192.88800","16.07418","0.03447"
"193.23000","16.10270","0.03457"
"193.57200","16.13116","0.02906"
"193.91400","16.15968","0.02901"
"194.25600","16.18826","0.03010"
"194.59800","16.21659","0.03012"
"194.94000","16.24524","0.03027"
"195.28200","16.27375","0.03062"
"195.62400","16.30215","0.03103"
"195.96600","16.33073","0.03126"
"196.30800","16.35919","0.03116"
"196.65000","16.38765","0.03194"
"196.99200","16.41623","0.03215"
"197.33400","16.44457","0.03281"
"197.67600","16.47321","0.03307"
"198.01800","16.50173","0.03312"
"198.36000","16.53007","0.03297"
"198.70200","16.55871","0.03305"
"199.04400","16.58723","0.03325"
"199.38600","16.61563","0.03379"
"199.72800","16.64421","0.03417"
"200.07000","16.67267","0.03448"
"200.41200","16.70119","0.03463"
"200.75400","16.72971","0.03479"
"201.09600","16.75811","0.03490"
"201.43800","16.78669","0.03606"
"201.78000","16.81521","0.03549"
"202.12200","16.84367","0.03615"
"202.46400","16.87219","0.03626"
"202.80600","16.90071","0.03641"
"203.14800","16.92917","0.03677"
"203.49000","16.95769","0.03720"
"203.83200","16.98621","0.03753"
"204.17400","17.01467","0.03773"
"204.51600","17.04319","0.03787"
"204.85800","17.07170","0.03734"
"205.20000","17.10016","0.03784"
"205.54200","17.12868","0.03819"
"205.88400","17.15709","0.03790"
"206.22600","17.18566","0.03834"
"206.56800","17.21418","0.03860"
"206.91000","17.24264","0.03953"
"207.25200","17.27122","0.03931"
"207.59400","17.29968","0.03853"
"207.93600","17.32820","0.03858"
"208.27800","17.35666","0.03912"
"208.62000","17.38518","0.03861"
"208.96200","17.41370","0.03904"
"209.30400","17.44222","0.03923"
"209.64600","17.47062","0.03925"
"209.98800","17.49914","0.03930"
"210.33000","17.52772","0.03948"
"210.67200","17.55612","0.04022"
"211.01400","17.58470","0.03985"
"211.35600","17.61310","0.04021"
"211.69800","17.64162","0.03974"
"212.04000","17.67020","0.02232"
"212.38200","17.69866","0.02141"
"212.72400","17.72718","0.02422"
"213.06600","17.75576","0.02333"
"213.40800","17.78410","0.02396"
"213.75000","17.81274","0.02394"
"214.09200","17.84120","0.02426"
"214.43400","17.86966","0.02477"
"214.77600","17.89824","0.02534"
"215.11800","17.92664","0.02622"
"215.46000","17.95516","0.02599"
"215.80200","17.98373","0.02657"
"216.14400","18.01208","0.02703"
"216.48600","18.04071","0.02633"
"216.82800","18.06923","0.02696"
"217.17000","18.09763","0.02751"
"217.51200","18.12621","0.02708"
"217.85400","18.15467","0.02778"
"218.19600","18.18319","0.02801"
"218.53800","18.21165","0.02811"
"218.88000","18.24017","0.02858"
"219.22200","18.26875","0.02872"
"219.56400","18.29715","0.02888"
"219.90600","18.32567","0.02921"
"220.24800","18.35419","0.02944"
"220.59000","18.38271","0.02932"
"220.93200","18.41111","0.02979"
"221.27400","18.43975","0.02966"
"221.61600","18.46821","0.03055"
"221.95800","18.49667","0.02979"
"222.30000","18.52519","0.03013"
"222.64200","18.55371","0.03086"
"222.98400","18.58223","0.03039"
"223.32600","18.61075","0.03037"
"223.66800","18.63915","0.03094"
"224.01000","18.66767","0.03128"
"224.35200","18.69619","0.03080"
"224.69400","18.72465","0.03121"
"225.03600","18.75323","0.03095"
"225.37800","18.78169","0.03083"
"225.72000","18.81015","0.03100"
"226.06200","18.83867","0.03129"
"226.40400","18.86719","0.03181"
"226.74600","18.89565","0.03179"
"227.08800","18.92422","0.03222"
"227.43000","18.95268","0.03257"
"227.77200","18.98120","0.03264"
"228.11600","19.00990","0.02620"
"228.45800","19.03830","0.02661"
"228.80000","19.06682","0.02666"
"229.14200","19.09534","0.02694"
"229.48400","19.12380","0.02700"
"229.82600","19.15238","0.02723"
"230.16800","19.18084","0.02756"
"230.51000","19.20936","0.02812"
"230.85200","19.23788","0.02739"
"231.19600","19.26640","0.02862"
"231.53800","19.29504","0.02765"
"231.88000","19.32356","0.02840"
"232.22200","19.35202","0.02852"
"232.56400","19.38054","0.02857"
"232.90600","19.40900","0.02859"
"233.24800","19.43752","0.02887"
"233.59000","19.46604","0.02846"
"233.93200","19.49450","0.02943"
"234.27400","19.52302","0.02898"
"234.61600","19.55154","0.02945"
"234.95800","19.57994","0.02924"
"235.30000","19.60851","0.03011"
"235.64200","19.63703","0.03005"
"235.98400","19.66549","0.03034"
"236.32600","19.69402","0.03014"
"236.66800","19.72253","0.03054"
"237.01000","19.75099","0.03075"
"237.35200","19.77951","0.03137"
"237.69400","19.80797","0.03191"
"238.03600","19.83655","0.03193"
"238.37800","19.86501","0.03220"
"238.72000","19.89353","0.03280"
"239.06200","19.92205","0.03253"
"239.40400","19.95051","0.03272"
"239.74600","19.97897","0.03289"
"240.08800","20.00755","0.03253"
"240.43000","20.03601","0.03318"
"240.77200","20.06453","0.03361"
"241.11400","20.09299","0.03370"
"241.45600","20.12151","0.03383"
"241.79800","20.15003","0.03409"
"242.14000","20.17855","0.03373"
"242.48200","20.20701","0.03408"
"242.82400","20.23553","0.03483"
"243.16600","20.26405","0.03412"
"243.50800","20.29245","0.03370"
"243.85000","20.32103","0.03424"
"244.19200","20.34949","0.03509"
"244.53400","20.37801","0.03508"
"244.87600","20.40653","0.03536"
"245.21800","20.43499","0.03570"
"245.56000","20.46351","0.03624"
"245.90200","20.49203","0.03683"
"246.24400","20.52048","0.03696"
"246.58600","20.54906","0.03744"
"246.92800","20.57758","0.03714"
"247.27000","20.60592","0.03715"
"247.61200","20.63456","0.03738"
"247.95400","20.66302","0.03805"
"248.29600","20.69148","0.03784"
"248.63800","20.72006","0.03825"
"248.98000","20.74846","0.03921"
"249.32200","20.77698","0.03989"
"249.66400","20.80556","0.04106"
"250.00600","20.83396","0.04178"
"250.34800","20.86260","0.04167"
"250.69000","20.89100","0.04148"
"251.03200","20.91946","0.04179"
"251.37400","20.94804","0.04238"
"251.71600","20.97650","0.04370"
"252.05800","21.00502","0.04399"
"252.40000","21.03354","0.04451"
"252.74200","21.06194","0.04432"
"253.08400","21.09046","0.04198"
"253.42600","21.11904","0.04288"
"253.76800","21.14750","0.04343"
"254.11000","21.17602","0.04318"
"254.45200","21.20448","0.04333"
"254.79400","21.23300","0.04496"
"255.13600","21.26152","0.04536"
"255.47800","21.28998","0.04613"
"255.82000","21.31855","0.04632"
"256.16200","21.34701","0.04561"
"256.50400","21.37547","0.04591"
"256.84600","21.40399","0.04585"
"257.18800","21.43258","0.04584"
"257.53000","21.46097","0.04551"
"257.87200","21.48950","0.03565"
"258.21400","21.51801","0.03490"
"258.55600","21.54647","0.03579"
"258.89800","21.57499","0.03584"
"259.24000","21.60351","0.03652"
"259.58200","21.63203","0.03585"
"259.92400","21.66049","0.03628"
"260.26600","21.68901","0.03644"
"260.60800","21.71753","0.03746"
"260.95000","21.74599","0.03794"
"261.29200","21.77445","0.03773"
"261.63400","21.80297","0.03853"
"261.97600","21.83155","0.03872"
"262.31800","21.86001","0.03891"
"262.66000","21.88853","0.03934"
"263.00200","21.91705","0.03820"
"263.34400","21.94545","0.03851"
"263.68600","21.97403","0.03876"
"264.02800","22.00243","0.03872"
"264.37000","22.03101","0.03904"
"264.71200","22.05959","0.03918"
"265.05400","22.08793","0.03906"
"265.39600","22.11657","0.03885"
"265.73800","22.14503","0.02782"
"266.08000","22.17349","0.02856"
"266.42200","22.20207","0.02947"
"266.76400","22.23047","0.02958"
"267.10600","22.25898","0.03024"
"267.44800","22.28757","0.03075"
"267.79000","22.31596","0.03125"
"268.13200","22.34455","0.03136"
"268.47400","22.37300","0.02591"
"268.81600","22.40146","0.02332"
"269.15800","22.43004","0.02363"
"269.50000","22.45850","0.02410"
"269.84200","22.48696","0.02381"
"270.18400","22.51554","0.02428"
"270.52600","22.54400","0.02391"
"270.86800","22.57252","0.02481"
"271.21000","22.60104","0.02448"
"271.55200","22.62944","0.02495"
"271.89400","22.65802","0.02506"
"272.23600","22.68648","0.02528"
"272.57800","22.71500","0.02503"
"272.92000","22.74352","0.02490"
"273.26200","22.77204","0.02520"
"273.60400","22.80050","0.02532"
"273.94600","22.82902","0.02645"
"274.28800","22.85748","0.02564"
"274.63000","22.88606","0.02553"
"274.97200","22.91452","0.02613"
"275.31400","22.94298","0.02661"
"275.65600","22.97150","0.02660"
"275.99800","22.99996","0.02713"
"276.34000","23.02848","0.02674"
"276.68200","23.05705","0.02706"
"277.02400","23.08551","0.02737"
"277.36600","23.11404","0.02758"
"277.70800","23.14249","0.02715"
"278.05200","23.17114","0.02719"
"278.39400","23.19971","0.02780"
"278.73600","23.22823","0.02778"
"279.07800","23.25664","0.02745"
"279.42000","23.28515","0.02718"
"279.76200","23.31373","0.02851"
"280.10400","23.34213","0.02801"
"280.44600","23.37071","0.02783"
"280.78800","23.39923","0.02837"
"281.13000","23.42763","0.02820"
"281.47200","23.45615","0.02881"
"281.81400","23.48467","0.02794"
"282.15600","23.51319","0.02864"
"282.49800","23.54171","0.02777"
"282.84000","23.57011","0.02792"
"283.18200","23.59869","0.02808"
"283.52400","23.62721","0.02776"
"283.86600","23.65567","0.02870"
"284.20800","23.68425","0.02790"
"284.55000","23.71265","0.02834"
"284.89200","23.74111","0.02840"
"285.23400","23.76969","0.02864"
"285.57600","23.79821","0.02837"
"285.91800","23.82673","0.02800"
"286.26000","23.85518","0.02819"
"286.60200","23.88358","0.02914"
"286.94400","23.91223","0.02848"
"287.28600","23.94069","0.02899"
"287.62800","23.96914","0.02917"
"287.97000","23.99772","0.02885"
"288.31200","24.02612","0.02940"
"288.65400","24.05470","0.02917"
"288.99600","24.08316","0.02939"
"289.33800","24.11163","0.02960"
"289.68000","24.14014","0.02972"
"290.02200","24.16872","0.02973"
"290.36400","24.19712","0.02964"
"290.70600","24.22564","0.02955"
"291.04800","24.25416","0.02953"
"291.39000","24.28268","0.02980"
"291.73200","24.31120","0.03005"
"292.07400","24.33966","0.03025"
"292.41600","24.36818","0.03010"
"292.75800","24.39670","0.02974"
"293.10000","24.42516","0.03058"
"293.44200","24.45374","0.03055"
"293.78400","24.48226","0.03054"
"294.12600","24.51066","0.03050"
"294.46800","24.53924","0.03111"
"294.81000","24.56770","0.03108"
"295.15200","24.59610","0.03139"
"295.49400","24.62468","0.03102"
"295.83600","24.65320","0.03069"
"296.17800","24.68166","0.03099"
"296.52000","24.71018","0.03132"
"296.86200","24.73864","0.03152"
"297.20400","24.76715","0.03164"
"297.54600","24.79568","0.03114"
"297.88800","24.82413","0.03158"
"298.23000","24.85271","0.03173"
"298.57200","24.88118","0.03253"
"298.91400","24.90969","0.03313"
"299.25600","24.93815","0.03307"
"299.59800","24.96667","0.03326"
"299.94000","24.99513","0.03414"
"300.28200","25.02377","0.03380"
"300.62400","25.05211","0.03401"
"300.96600","25.08069","0.03451"
"301.30800","25.10921","0.03468"
"301.65000","25.13761","0.03420"
"301.99200","25.16625","0.03431"
"302.33400","25.19465","0.03387"
"302.67600","25.22317","0.03395"
"303.01800","25.25175","0.03353"
"303.36000","25.28015","0.03126"
"303.70200","25.30867","0.03109"
"304.04400","25.33719","0.03025"
"304.38600","25.36565","0.02966"
"304.72800","25.39417","0.03173"
"305.07000","25.42269","0.03096"
"305.41200","25.45115","0.03152"
"305.75400","25.47967","0.02936"
"306.09600","25.50819","0.02774"
"306.43800","25.53665","0.02761"
"306.78000","25.56523","0.02703"
"307.12400","25.59387","0.02712"
"307.46600","25.62239","0.02805"
"307.80800","25.65085","0.02733"
"308.15000","25.67931","0.02885"
"308.49200","25.70788","0.02867"
"308.83400","25.73641","0.02913"
"309.17600","25.76481","0.02927"
"309.51800","25.79338","0.02974"
"309.86000","25.82184","0.02969"
"310.20200","25.85030","0.02970"
"310.54400","25.87888","0.03007"
"310.88600","25.90734","0.03001"
"311.22800","25.93586","0.03064"
"311.57000","25.96432","0.03013"
"311.91200","25.99284","0.03009"
"312.25400","26.02130","0.03032"
"312.59600","26.04988","0.03031"
"312.93800","26.07834","0.03058"
"313.28000","26.10680","0.03067"
"313.62200","26.13532","0.03060"
"313.96400","26.16384","0.03013"
"314.30600","26.19236","0.03066"
"314.64800","26.22088","0.03040"
"314.99000","26.24928","0.03066"
"315.33200","26.27786","0.03051"
"315.67400","26.30632","0.03061"
"316.01600","26.33484","0.03037"
"316.35800","26.36342","0.03043"
"316.70000","26.39182","0.03066"
"317.04200","26.42034","0.03086"
"317.38400","26.44885","0.03085"
"317.72600","26.47732","0.03083"
"318.06800","26.50590","0.03115"
"318.41000","26.53429","0.03174"
"318.75200","26.56282","0.03069"
"319.09400","26.59139","0.03120"
"319.43600","26.61979","0.03139"
"319.77800","26.64838","0.03127"
"320.12000","26.67690","0.03118"
"320.46200","26.70529","0.03016"
"320.80400","26.73388","0.03092"
"321.14600","26.76233","0.03068"
"321.48800","26.79085","0.03097"
"321.83000","26.81937","0.03142"
"322.17200","26.84783","0.03160"
"322.51400","26.87635","0.03101"
"322.85600","26.90487","0.03109"
"323.19800","26.93327","0.03097"
"323.54000","26.96185","0.03154"
"323.88200","26.99037","0.03126"
"324.22400","27.01883","0.03146"
"324.56600","27.04735","0.03177"
"324.90800","27.07587","0.03175"
"325.25000","27.10433","0.03206"
"325.59200","27.13285","0.03182"
"325.93400","27.16131","0.03078"
"326.27600","27.18989","0.03023"
"326.61800","27.21841","0.03012"
"326.96000","27.24681","0.03046"
"327.30200","27.27539","0.03031"
"327.64400","27.30385","0.03176"
"327.98600","27.33231","0.03091"
"328.32800","27.36089","0.03116"
"328.67000","27.38935","0.03143"
"329.01200","27.41787","0.03166"
"329.35400","27.44633","0.03166"
"329.69600","27.47484","0.03205"
"330.03800","27.50336","0.03211"
"330.38000","27.53189","0.03223"
"330.72200","27.56028","0.01861"
"331.06400","27.58887","0.02259"
"331.40600","27.61732","0.01445"
"331.74800","27.64585","0.01924"
"332.09000","27.67436","0.01585"
"332.43200","27.70288","0.01898"
"332.77400","27.73129","0.01618"
"333.11600","27.75986","0.01740"
"333.45800","27.78832","0.01616"
"333.80000","27.81684","0.01840"
"334.14200","27.84542","0.01713"
"334.48400","27.87382","0.01816"
"334.82600","27.90234","0.01790"
"335.16800","27.93086","0.01871"
"335.51000","27.95932","0.01801"
"335.85200","27.98790","0.01916"
"336.19400","28.01636","0.01871"
"336.53600","28.04482","0.01900"
"336.87800","28.07340","0.01891"
"337.22000","28.10186","0.01905"
"337.56200","28.13038","0.01988"
"337.90400","28.15884","0.01941"
"338.24600","28.18730","0.02001"
"338.58800","28.21588","0.01951"
"338.93000","28.24434","0.02065"
"339.27200","28.27280","0.02055"
"339.61400","28.30137","0.01999"
"339.95600","28.32984","0.02055"
"340.29800","28.35830","0.02110"
"340.64000","28.38681","0.02092"
"340.98200","28.41528","0.02146"
"341.32400","28.44391","0.02118"
"341.66600","28.47238","0.02153"
"342.00800","28.50077","0.02175"
"342.35000","28.52935","0.02226"
"342.69200","28.55787","0.02223"
"343.03400","28.58633","0.02230"
"343.37600","28.61485","0.02249"
"343.71800","28.64331","0.02213"
"344.06000","28.67189","0.02204"
"344.40200","28.70035","0.02264"
"344.74400","28.72875","0.02225"
"345.08600","28.75739","0.02292"
"345.42800","28.78585","0.02212"
"345.77000","28.81431","0.02223"
"346.11200","28.84289","0.02296"
"346.45400","28.87135","0.02241"
"346.79600","28.89981","0.02235"
"347.13800","28.92833","0.02206"
"347.48000","28.95685","0.02199"
"347.82200","28.98537","0.02191"
"348.16400","29.01383","0.02235"
"348.50600","29.04235","0.02205"
"348.84800","29.07081","0.02252"
"349.19000","29.09933","0.02189"
"349.53200","29.12785","0.02177"
"349.87400","29.15637","0.02231"
"350.21600","29.18489","0.02230"
"350.55800","29.21334","0.02227"
"350.90000","29.24181","0.02222"
"351.24200","29.27039","0.02211"
"351.58400","29.29885","0.02192"
"351.92600","29.32743","0.02225"
"352.26800","29.35576","0.02201"
"352.61000","29.38434","0.02211"
"352.95200","29.41286","0.02201"
"353.29400","29.44127","0.02195"
"353.63600","29.46990","0.02280"
"353.97800","29.49830","0.02203"
"354.32000","29.52682","0.02225"
"354.66200","29.55540","0.02270"
"355.00400","29.58386","0.02267"
"355.34600","29.61232","0.02293"
"355.68800","29.64090","0.02237"
"356.03000","29.66930","0.02240"
"356.37200","29.69782","0.02265"
"356.71400","29.72634","0.02284"
"357.05600","29.75480","0.02262"
"357.39800","29.78338","0.02261"
"357.74000","29.81184","0.02254"
"358.08200","29.84030","0.02300"
"358.42400","29.86888","0.02237"
"358.76600","29.89728","0.02171"
"359.10800","29.92586","0.02278"
"359.45000","29.95438","0.02244"
"359.79200","29.98278","0.02256"
"360.13400","30.01142","0.02235"
"360.47600","30.03988","0.02199"
"360.81800","30.06834","0.02254"
"361.16000","30.09686","0.02244"
"361.50200","30.12531","0.02291"
"361.84400","30.15384","0.02264"
"362.18600","30.18236","0.02248"
"362.52800","30.21082","0.02239"
"362.87000","30.23939","0.02229"
"363.21200","30.26780","0.02269"
"363.55400","30.29631","0.02238"
"363.89600","30.32490","0.02213"
"364.23800","30.35335","0.02271"
"364.58000","30.38187","0.02268"
"364.92200","30.41039","0.02271"
"365.26400","30.43885","0.02307"
"365.60600","30.46731","0.02303"
"365.94800","30.49583","0.02265"
"366.29000","30.52435","0.02266"
"366.63200","30.55281","0.02212"
"366.97400","30.58133","0.02239"
"367.31600","30.60979","0.02257"
"367.65800","30.63837","0.02314"
"368.00000","30.66689","0.02246"
"368.34200","30.69529","0.02285"
"368.68400","30.72387","0.02275"
"369.02600","30.75239","0.02302"
"369.36800","30.78085","0.02301"
"369.71000","30.80937","0.02331"
"370.05200","30.83783","0.02386"
"370.39400","30.86635","0.02318"
"370.73600","30.89487","0.02364"
"371.07800","30.92333","0.02334"
"371.42000","30.95185","0.02351"
"371.76200","30.98037","0.02387"
"372.10400","31.00883","0.02379"
"372.44600","31.03741","0.02315"
"372.78800","31.06587","0.02416"
"373.13000","31.09438","0.02419"
"373.47200","31.12290","0.02417"
"373.81400","31.15131","0.02379"
"374.15600","31.17982","0.02401"
"374.49800","31.20840","0.02485"
"374.84000","31.23680","0.02425"
"375.18200","31.26538","0.02408"
"375.52400","31.29384","0.02437"
"375.86600","31.32224","0.02413"
"376.20800","31.35088","0.02452"
"376.55000","31.37934","0.02474"
"376.89200","31.40780","0.02494"
"377.23400","31.43632","0.02494"
"377.57600","31.46478","0.02453"
"377.91800","31.49336","0.02423"
"378.26000","31.52194","0.02500"
"378.60200","31.55034","0.02429"
"378.94400","31.57886","0.02457"
"379.28600","31.60732","0.02493"
"379.62800","31.63584","0.02478"
"379.97000","31.66436","0.02489"
"380.31200","31.69282","0.02490"
"380.65400","31.72133","0.02508"
"380.99600","31.74986","0.02484"
"381.33800","31.77832","0.02477"
"381.68000","31.80689","0.02534"
"382.02200","31.83541","0.02525"
"382.36400","31.86376","0.02520"
"382.70600","31.89239","0.02562"
"383.04800","31.92085","0.02480"
"383.39000","31.94932","0.02507"
"383.73200","31.97783","0.02489"
"384.07400","32.00635","0.02530"
"384.41600","32.03481","0.02586"
"384.75800","32.06333","0.02540"
"385.10000","32.09185","0.02479"
"385.44200","32.12031","0.02547"
"385.78400","32.14889","0.02536"
"386.12600","32.17735","0.02578"
"386.46800","32.20587","0.02593"
"386.81000","32.23439","0.02601"
"387.15200","32.26279","0.02595"
"387.49400","32.29137","0.02607"
"387.83600","32.31983","0.02651"
"388.17800","32.34829","0.02634"
"388.52000","32.37687","0.02414"
"388.86200","32.40533","0.02523"
"389.20400","32.43385","0.02487"
"389.54600","32.46236","0.02459"
"389.88800","32.49083","0.02490"
"390.23000","32.51935","0.02408"
"390.57200","32.54787","0.02405"
"390.91400","32.57632","0.02453"
"391.25600","32.60491","0.02424"
"391.59800","32.63330","0.02488"
"391.94000","32.66183","0.02438"
"392.28200","32.69041","0.02434"
"392.62400","32.71880","0.02351"
"392.96600","32.74738","0.02456"
"393.30800","32.77591","0.02464"
"393.65000","32.80436","0.01865"
"393.99200","32.83288","0.02015"
"394.33400","32.86134","0.01856"
"394.67600","32.88980","0.01905"
"395.01800","32.91838","0.01969"
"395.36000","32.94678","0.01832"
"395.70200","32.97536","0.02084"
"396.04400","33.00382","0.01823"
"396.38600","33.03228","0.02048"
"396.72800","33.06092","0.01949"
"397.07000","33.08932","0.01882"
"397.41200","33.11778","0.02021"
"397.75400","33.14636","0.01960"
"398.09600","33.17488","0.02027"
"398.43800","33.20334","0.02008"
"398.78000","33.23186","0.02019"
"399.12200","33.26032","0.02063"
"399.46400","33.28884","0.02044"
"399.80600","33.31730","0.02048"
"400.14800","33.34582","0.02027"
"400.49000","33.37434","0.02015"
"400.83200","33.40285","0.02012"
"401.17400","33.43132","0.02002"
"401.51600","33.45984","0.02101"
"401.85800","33.48835","0.02105"
"402.20000","33.51682","0.02080"
"402.54200","33.54533","0.02117"
"402.88400","33.57380","0.02120"
"403.22600","33.60238","0.02129"
"403.56800","33.63089","0.02144"
"403.91000","33.65929","0.02159"
"404.25200","33.68787","0.02166"
"404.59400","33.71639","0.02075"
"404.93600","33.74479","0.02117"
"405.27800","33.77337","0.02175"
"405.62000","33.80183","0.02196"
"405.96200","33.83035","0.02128"
"406.30400","33.85887","0.02192"
"406.64600","33.88733","0.02209"
"406.98800","33.91585","0.02217"
"407.33000","33.94437","0.02210"
"407.67200","33.97277","0.02238"
"408.01400","34.00135","0.02248"
"408.35600","34.02993","0.02173"
"408.69800","34.05833","0.02253"
"409.04000","34.08685","0.02204"
"409.38200","34.11531","0.02221"
"409.72400","34.14377","0.02226"
"410.06600","34.17235","0.02253"
"410.40800","34.20081","0.02205"
"410.75000","34.22939","0.02168"
"411.09200","34.25791","0.02197"
"411.43400","34.28631","0.02223"
"411.77600","34.31488","0.02195"
"412.11800","34.34335","0.02272"
"412.46000","34.37181","0.02236"
"412.80200","34.40044","0.02196"
"413.14400","34.42879","0.02252"
"413.48600","34.45731","0.02267"
"413.82800","34.48589","0.02279"
"414.17000","34.51429","0.02230"
"414.51200","34.54287","0.02291"
"414.85400","34.57138","0.02305"
"415.19600","34.59978","0.02293"
"415.53800","34.62843","0.02257"
"415.88000","34.65682","0.02302"
"416.22200","34.68534","0.02262"
"416.56400","34.71386","0.02314"
"416.90600","34.74232","0.02294"
"417.24800","34.77084","0.02309"
"417.59000","34.79936","0.02266"
"417.93200","34.82782","0.02297"
"418.27400","34.85628","0.02301"
"418.61600","34.88486","0.02338"
"418.95800","34.91326","0.02328"
"419.30000","34.94190","0.02311"
"419.64200","34.97036","0.02310"
"419.98400","34.99882","0.02299"
"420.32600","35.02734","0.02321"
"420.66800","35.05586","0.02395"
"421.01000","35.08432","0.02410"
"421.35200","35.11284","0.02414"
"421.69400","35.14136","0.02347"
"422.03600","35.16988","0.02363"
"422.37800","35.19834","0.02376"
"422.72000","35.22680","0.02394"
"423.06200","35.25532","0.02400"
"423.40400","35.28390","0.02353"
"423.74600","35.31236","0.02336"
"424.08800","35.34087","0.02457"
"424.43000","35.36940","0.02371"
"424.77200","35.39785","0.02408"
"425.11400","35.42638","0.02406"
"425.45600","35.45478","0.02462"
"425.79800","35.48335","0.02438"
"426.14000","35.51188","0.02456"
"426.48200","35.54034","0.02437"
"426.82400","35.56891","0.02456"
"427.16600","35.59731","0.02414"
"427.50800","35.62584","0.02490"
"427.85000","35.65435","0.02491"
"428.19200","35.68281","0.02490"
"428.53400","35.71127","0.02518"
"428.87600","35.73991","0.02502"
"429.21800","35.76825","0.02508"
"429.56000","35.79689","0.02493"
"429.90200","35.82541","0.02496"
"430.24400","35.85375","0.02548"
"430.58600","35.88239","0.02521"
"430.92800","35.91079","0.02560"
"431.27000","35.93931","0.02572"
"431.61200","35.96789","0.02602"
"431.95400","35.99635","0.02544"
"432.29600","36.02487","0.02589"
"432.63800","36.05333","0.02619"
"432.98000","36.08173","0.02627"
"433.32200","36.11043","0.02630"
"433.66400","36.13889","0.02664"
"434.00600","36.16735","0.02641"
"434.34800","36.19587","0.02631"
"434.69000","36.22432","0.02674"
"435.03200","36.25278","0.02669"
"435.37400","36.28136","0.02656"
"435.71600","36.30982","0.02689"
"436.05800","36.33834","0.02699"
"436.40000","36.36686","0.02695"
"436.74200","36.39532","0.02717"
"437.08400","36.42384","0.02727"
"437.42600","36.45237","0.02710"
"437.76800","36.48076","0.02779"
"438.11000","36.50934","0.02714"
"438.45200","36.53786","0.02713"
"438.79400","36.56632","0.02771"
"439.13600","36.59490","0.02707"
"439.47800","36.62330","0.02740"
"439.82000","36.65182","0.02741"
"440.16200","36.68034","0.02756"
"440.50400","36.70880","0.02718"
"440.84600","36.73738","0.02382"
"441.18800","36.76590","0.02558"
"441.53000","36.79430","0.02388"
"441.87200","36.82282","0.02447"
"442.21400","36.85134","0.02583"
"442.55600","36.87980","0.02400"
"442.89800","36.90832","0.02524"
"443.24000","36.93684","0.02507"
"443.58200","36.96529","0.02497"
"443.92400","36.99393","0.02497"
"444.26600","37.02228","0.02538"
"444.60800","37.05085","0.02605"
"444.95000","37.07938","0.02487"
"445.29200","37.10778","0.02571"
"445.63400","37.13635","0.02592"
"445.97600","37.16488","0.02545"
"446.31800","37.19328","0.02590"
"446.66000","37.22185","0.02574"
"447.00200","37.25031","0.02609"
"447.34400","37.27884","0.02660"
"447.68600","37.30741","0.02650"
"448.02800","37.33575","0.02640"
"448.37000","37.36440","0.02611"
"448.71200","37.39285","0.02650"
"449.05400","37.42131","0.02646"
"449.39600","37.44989","0.02656"
"449.73800","37.47835","0.02661"
"450.08000","37.50687","0.02681"
"450.42200","37.53533","0.02659"
"450.76400","37.56379","0.02660"
"451.10600","37.59237","0.02654"
"451.44800","37.62089","0.02696"
"451.79000","37.64935","0.02682"
"452.13200","37.67787","0.02729"
"452.47400","37.70633","0.02707"
"452.81600","37.73485","0.02704"
"453.15800","37.76337","0.02730"
"453.50000","37.79183","0.02727"
"453.84200","37.82041","0.02781"
"454.18400","37.84887","0.02794"
"454.52600","37.87733","0.02805"
"454.86800","37.90585","0.02836"
"455.21000","37.93437","0.02812"
"455.55200","37.96283","0.02807"
"455.89400","37.99141","0.02822"
"456.23600","38.01987","0.02769"
"456.57800","38.04833","0.02801"
"456.92000","38.07684","0.02817"
"457.26200","38.10537","0.02809"
"457.60400","38.13388","0.02842"
"457.94600","38.16234","0.02848"
"458.28800","38.19080","0.02869"
"458.63000","38.21938","0.02822"
"458.97200","38.24790","0.02938"
"459.31400","38.27636","0.02934"
"459.65600","38.30488","0.02892"
"459.99800","38.33334","0.02923"
"460.34000","38.36180","0.02915"
"460.68200","38.39032","0.02937"
"461.02400","38.41884","0.02953"
"461.36600","38.44724","0.02957"
"461.70800","38.47588","0.02963"
"462.05000","38.50434","0.03020"
"462.39200","38.53286","0.02972"
"462.73400","38.56144","0.03001"
"463.07600","38.58978","0.03016"
"463.41800","38.61836","0.03005"
"463.76000","38.64688","0.03024"
"464.10200","38.67528","0.03042"
"464.44400","38.70392","0.03012"
"464.78600","38.73232","0.03054"
"465.12800","38.76084","0.03080"
"465.47000","38.78942","0.03047"
"465.81200","38.81781","0.03086"
"466.15400","38.84640","0.03068"
"466.49600","38.87486","0.03025"
"466.83800","38.90326","0.03036"
"467.18000","38.93190","0.03099"
"467.52200","38.96036","0.03067"
"467.86400","38.98887","0.03079"
"468.20600","39.01733","0.03102"
"468.54800","39.04580","0.03146"
"468.89000","39.07437","0.03124"
"469.23200","39.10289","0.03119"
"469.57400","39.13129","0.03126"
"469.91600","39.15987","0.03115"
"470.25800","39.18839","0.03149"
"470.60000","39.21685","0.03164"
"470.94200","39.24537","0.03142"
"471.28400","39.27389","0.03191"
"471.62600","39.30235","0.03190"
"471.96800","39.33087","0.03187"
"472.31000","39.35933","0.02822"
"472.65200","39.38785","0.02760"
"472.99400","39.41637","0.03027"
"473.33600","39.44483","0.02689"
"473.67800","39.47335","0.02931"
"474.02000","39.50181","0.02852"
"474.36200","39.53033","0.02813"
"474.70400","39.55890","0.02908"
"475.04600","39.58736","0.02823"
"475.38800","39.61583","0.02868"
"475.73000","39.64434","0.02908"
"476.07200","39.67287","0.02889"
"476.41400","39.70133","0.02932"
"476.75600","39.72990","0.02913"
"477.09800","39.75837","0.02921"
"477.44000","39.78689","0.02959"
"477.78200","39.81535","0.02994"
"478.12400","39.84380","0.03017"
"478.46600","39.87233","0.02951"
"478.80800","39.90084","0.02944"
"479.15000","39.92936","0.02991"
"479.49200","39.95782","0.02960"
"479.83400","39.98634","0.02992"
"480.17600","40.01480","0.03043"
"480.51800","40.04338","0.03025"
"480.86000","40.07178","0.03075"
"481.20200","40.10036","0.03079"
"481.54400","40.12888","0.03042"
"481.88600","40.15728","0.03061"
"482.22800","40.18592","0.03117"
"482.57000","40.21432","0.03122"
"482.91200","40.24284","0.03097"
"483.25400","40.27136","0.03166"
"483.59600","40.29982","0.03138"
"483.93800","40.32834","0.03123"
"484.28000","40.35686","0.03129"
"484.62200","40.38526","0.03126"
"484.96400","40.41389","0.03128"
"485.30600","40.44236","0.03191"
"485.64800","40.47081","0.03197"
"485.99000","40.49940","0.03193"
"486.33200","40.52786","0.03179"
"486.67400","40.55631","0.03186"
"487.01600","40.58484","0.03210"
"487.35800","40.61336","0.03265"
"487.70000","40.64193","0.03274"
"488.04200","40.67039","0.03213"
"488.38400","40.69880","0.03251"
"488.72600","40.72738","0.03243"
"489.06800","40.75583","0.03280"
"489.41000","40.78429","0.03239"
"489.75200","40.81287","0.03278"
"490.09400","40.84133","0.03262"
"490.43600","40.86985","0.03242"
"490.77800","40.89843","0.03246"
"491.12000","40.92677","0.03325"
"491.46200","40.95535","0.03313"
"491.80400","40.98387","0.03282"
"492.14600","41.01233","0.03354"
"492.48800","41.04085","0.03332"
"492.83000","41.06931","0.03376"
"493.17200","41.09783","0.03349"
"493.51400","41.12635","0.03385"
"493.85600","41.15487","0.03378"
"494.19800","41.18339","0.03465"
"494.54000","41.21191","0.03449"
"494.88200","41.24031","0.03389"
"495.22400","41.26883","0.03405"
"495.56600","41.29741","0.03450"
"495.90800","41.32581","0.03472"
"496.25000","41.35439","0.03456"
"496.59200","41.38291","0.03459"
"496.93400","41.41130","0.03487"
"497.27600","41.43983","0.03437"
"497.61800","41.46835","0.03461"
"497.96000","41.49681","0.03433"
"498.30200","41.52539","0.03493"
"498.64400","41.55379","0.03536"
"498.98600","41.58231","0.03518"
"499.32800","41.61088","0.03509"
"499.67000","41.63928","0.03565"
"500.01200","41.66786","0.03526"
"500.35400","41.69638","0.03529"
"500.69600","41.72478","0.03592"
"501.03800","41.75342","0.03572"
"501.38000","41.78182","0.03550"
"501.72200","41.81034","0.03648"
"502.06400","41.83886","0.03579"
"502.40600","41.86732","0.03557"
"502.74800","41.89584","0.03585"
"503.09000","41.92436","0.03668"
"503.43200","41.95282","0.03651"
"503.77400","41.98134","0.03661"
"504.11600","42.00986","0.03718"
"504.45800","42.03832","0.03658"
"504.80000","42.06689","0.03692"
"505.14200","42.09530","0.03682"
"505.48400","42.12387","0.03718"
"505.82600","42.15233","0.03748"
"505.87400","42.15635","0.03784"