File: Force_trajectories/170107_1/Specimen_RawData_6.csv
End date,"1/7/2017"
Specimen label,"18DT_47"
Maximum Load,"0.09977",N

Time,Extension,Load
(s),(mm),(N)
"0.00000","0.00000","-0.00002"
"0.26400","0.02081","-0.00012"
"0.52800","0.04430","0.00006"
"0.79200","0.06613","-0.00010"
"1.05600","0.08819","-0.00019"
"1.32000","0.11013","0.00070"
"1.58400","0.13219","0.00022"
"1.84800","0.15420","-0.00007"
"2.11200","0.17626","0.00018"
"2.37600","0.19814","0.00043"
"2.64000","0.22020","0.00068"
"2.90400","0.24209","0.00017"
"3.16800","0.26415","0.00046"
"3.43200","0.28615","0.00047"
"3.69600","0.30816","0.00028"
"3.96000","0.33016","0.00017"
"4.22400","0.35222","0.00059"
"4.48800","0.37416","0.00017"
"4.75200","0.39623","0.00027"
"5.01600","0.41811","0.00038"
"5.28000","0.44023","0.00116"
"5.54400","0.46217","0.00153"
"5.80800","0.48424","0.00076"
"6.07200","0.50618","0.00138"
"6.33600","0.52824","0.00080"
"6.60000","0.55018","0.00121"
"6.86400","0.57225","0.00162"
"7.12800","0.59419","0.00148"
"7.39200","0.61619","0.00159"
"7.65600","0.63819","0.00139"
"7.92000","0.66020","0.00216"
"8.18400","0.68220","0.00144"
"8.44800","0.70420","0.00164"
"8.71200","0.72620","0.00130"
"8.97600","0.74821","0.00171"
"9.24000","0.77021","0.00139"
"9.50400","0.79215","0.00157"
"9.76800","0.81421","0.00171"
"10.03200","0.83616","0.00138"
"10.29600","0.85822","0.00188"
"10.56000","0.88022","0.00217"
"10.82400","0.90216","0.00149"
"11.08800","0.92417","0.00199"
"11.35200","0.94623","0.00202"
"11.61600","0.96817","0.00206"
"11.88000","0.99023","0.00182"
"12.14400","1.01224","0.00195"
"12.40800","1.03424","0.00234"
"12.67200","1.05618","0.00170"
"12.93600","1.07818","0.00206"
"13.20000","1.10019","0.00227"
"13.46400","1.12219","0.00243"
"13.72800","1.14419","0.00230"
"13.99200","1.16625","0.00159"
"14.25600","1.18814","0.00245"
"14.52000","1.21020","0.00181"
"14.78400","1.23208","0.00284"
"15.04800","1.25420","0.00230"
"15.31200","1.27615","0.00235"
"15.57600","1.29821","0.00231"
"15.84000","1.32009","0.00282"
"16.10400","1.34222","0.00293"
"16.36800","1.36416","0.00239"
"16.63200","1.38622","0.00295"
"16.89600","1.40816","0.00281"
"17.16000","1.43017","0.00321"
"17.42400","1.45217","0.00273"
"17.68800","1.47417","0.00275"
"17.95200","1.49611","0.00342"
"18.21600","1.51824","0.00315"
"18.48000","1.54018","0.00329"
"18.74400","1.56224","0.00241"
"19.00800","1.58418","0.00282"
"19.27200","1.60625","0.00325"
"19.53600","1.62819","0.00321"
"19.80000","1.65025","0.00365"
"20.06400","1.67219","0.00307"
"20.32800","1.69426","0.00267"
"20.59200","1.71620","0.00319"
"20.85600","1.73820","0.00289"
"21.12000","1.76014","0.00343"
"21.38400","1.78221","0.00432"
"21.64800","1.80421","0.00361"
"21.91200","1.82627","0.00319"
"22.17600","1.84815","0.00327"
"22.44000","1.87022","0.00361"
"22.70400","1.89216","0.00354"
"22.96800","1.91422","0.00318"
"23.23200","1.93622","0.00346"
"23.49600","1.95823","0.00308"
"23.76000","1.98017","0.00340"
"24.02400","2.00217","0.00419"
"24.28800","2.02417","0.00374"
"24.55200","2.04618","0.00331"
"24.81600","2.06824","0.00375"
"25.08000","2.09024","0.00356"
"25.34400","2.11224","0.00399"
"25.60800","2.13413","0.00425"
"25.87200","2.15619","0.00360"
"26.13600","2.17813","0.00361"
"26.40000","2.20020","0.00356"
"26.66400","2.22220","0.00377"
"26.92800","2.24426","0.00378"
"27.19200","2.26620","0.00386"
"27.45600","2.28815","0.00358"
"27.72000","2.31015","0.00354"
"27.98400","2.33221","0.00383"
"28.24800","2.35415","0.00430"
"28.51200","2.37616","0.00407"
"28.77600","2.39816","0.00348"
"29.04000","2.42016","0.00422"
"29.30400","2.44216","0.00420"
"29.56800","2.46423","0.00399"
"29.83200","2.48623","0.00414"
"30.09600","2.50829","0.00355"
"30.36000","2.53011","0.00399"
"30.62400","2.55218","0.00426"
"30.88800","2.57412","0.00467"
"31.15200","2.59618","0.00442"
"31.41600","2.61818","0.00432"
"31.68000","2.64025","0.00442"
"31.94400","2.66213","0.00411"
"32.20800","2.68419","0.00442"
"32.47200","2.70619","0.00409"
"32.73600","2.72820","0.00431"
"33.00000","2.75014","0.00483"
"33.26400","2.77226","0.00476"
"33.52800","2.79420","0.00470"
"33.79200","2.81621","0.00422"
"34.05600","2.83815","0.00477"
"34.32000","2.86021","0.00434"
"34.58400","2.88215","0.00451"
"34.84800","2.90422","0.00491"
"35.11200","2.92616","0.00389"
"35.37600","2.94822","0.00468"
"35.64000","2.97016","0.00508"
"35.90400","2.99223","0.00499"
"36.16800","3.01417","0.00458"
"36.43200","3.03617","0.00574"
"36.69600","3.05823","0.00475"
"36.96000","3.08024","0.00523"
"37.22400","3.10218","0.00486"
"37.48800","3.12418","0.00501"
"37.75200","3.14618","0.00500"
"38.01600","3.16819","0.00518"
"38.28000","3.19025","0.00551"
"38.54400","3.21219","0.00497"
"38.80800","3.23419","0.00505"
"39.07200","3.25620","0.00496"
"39.33600","3.27820","0.00514"
"39.60000","3.30020","0.00495"
"39.86400","3.32221","0.00545"
"40.12800","3.34415","0.00374"
"40.39200","3.36621","0.00469"
"40.65600","3.38815","0.00456"
"40.92000","3.41016","0.00439"
"41.18400","3.43216","0.00399"
"41.44800","3.45422","0.00395"
"41.71200","3.47616","0.00397"
"41.97600","3.49823","0.00417"
"42.24000","3.52011","0.00432"
"42.50400","3.54223","0.00446"
"42.76800","3.56417","0.00494"
"43.03200","3.58624","0.00552"
"43.29600","3.60824","0.00557"
"43.56000","3.63018","0.00489"
"43.82400","3.65212","0.00429"
"44.08800","3.67419","0.00477"
"44.35200","3.69619","0.00497"
"44.61600","3.71819","0.00446"
"44.88000","3.74019","0.00443"
"45.14400","3.76220","0.00464"
"45.40800","3.78414","0.00455"
"45.67200","3.80614","0.00485"
"45.93600","3.82814","0.00444"
"46.20000","3.85021","0.00517"
"46.46400","3.87215","0.00462"
"46.72800","3.89421","0.00492"
"46.99200","3.91615","0.00486"
"47.25600","3.93822","0.00464"
"47.52000","3.96022","0.00538"
"47.78400","3.98222","0.00515"
"48.04800","4.00416","0.00508"
"48.31200","4.02623","0.00516"
"48.57600","4.04817","0.00555"
"48.84000","4.07023","0.00560"
"49.10400","4.09218","0.00595"
"49.36800","4.11424","0.00523"
"49.63200","4.13624","0.00561"
"49.89600","4.15824","0.00588"
"50.16000","4.18018","0.00558"
"50.42400","4.20219","0.00553"
"50.68800","4.22413","0.00521"
"50.95200","4.24619","0.00577"
"51.21600","4.26820","0.00576"
"51.48000","4.29014","0.00569"
"51.74400","4.31220","0.00492"
"52.00800","4.33420","0.00534"
"52.27200","4.35621","0.00584"
"52.53600","4.37821","0.00572"
"52.80000","4.40021","0.00552"
"53.06400","4.42221","0.00581"
"53.32800","4.44422","0.00606"
"53.59200","4.46616","0.00622"
"53.85600","4.48816","0.00546"
"54.12000","4.51016","0.00586"
"54.38400","4.53217","0.00639"
"54.64800","4.55423","0.00632"
"54.91200","4.57623","0.00584"
"55.17600","4.59823","0.00621"
"55.44000","4.62024","0.00679"
"55.70400","4.64218","0.00660"
"55.96800","4.66424","0.00625"
"56.23200","4.68618","0.00639"
"56.49600","4.70819","0.00671"
"56.76000","4.73013","0.00618"
"57.02400","4.75225","0.00611"
"57.28800","4.77413","0.00675"
"57.55200","4.79620","0.00620"
"57.81600","4.81814","0.00678"
"58.08000","4.84026","0.00690"
"58.34400","4.86214","0.00672"
"58.60800","4.88421","0.00664"
"58.87200","4.90609","0.00645"
"59.13600","4.92821","0.00694"
"59.40000","4.95015","0.00662"
"59.66400","4.97222","0.00675"
"59.92800","4.99416","0.00712"
"60.19200","5.01616","0.00726"
"60.45600","5.03816","0.00633"
"60.72000","5.06017","0.00732"
"60.98400","5.08211","0.00768"
"61.24800","5.10423","0.00792"
"61.51200","5.12618","0.00776"
"61.77600","5.14824","0.00764"
"62.04000","5.17018","0.00758"
"62.30400","5.19224","0.00777"
"62.56800","5.21419","0.00743"
"62.83200","5.23625","0.00748"
"63.09600","5.25819","0.00721"
"63.36000","5.28019","0.00766"
"63.62400","5.30214","0.00736"
"63.88800","5.32420","0.00768"
"64.15200","5.34614","0.00713"
"64.41600","5.36820","0.00734"
"64.68000","5.39021","0.00727"
"64.94400","5.41221","0.00790"
"65.20800","5.43421","0.00785"
"65.47200","5.45621","0.00727"
"65.73600","5.47816","0.00790"
"66.00000","5.50022","0.00740"
"66.26400","5.52222","0.00773"
"66.52800","5.54422","0.00841"
"66.79200","5.56617","0.00694"
"67.05600","5.58817","0.00764"
"67.32000","5.61017","0.00749"
"67.58400","5.63217","0.00736"
"67.84800","5.65424","0.00767"
"68.11200","5.67618","0.00767"
"68.37600","5.69824","0.00789"
"68.64000","5.72018","0.00783"
"68.90400","5.74225","0.00771"
"69.16800","5.76419","0.00807"
"69.43200","5.78625","0.00828"
"69.69600","5.80819","0.00780"
"69.96000","5.83026","0.00823"
"70.22400","5.85214","0.00838"
"70.48800","5.87414","0.00768"
"70.75200","5.89614","0.00815"
"71.01600","5.91821","0.00851"
"71.28000","5.94015","0.00770"
"71.54400","5.96221","0.00767"
"71.80800","5.98410","0.00714"
"72.07200","6.00622","0.00702"
"72.33600","6.02816","0.00711"
"72.60000","6.05022","0.00677"
"72.86400","6.07217","0.00742"
"73.12800","6.09423","0.00719"
"73.39200","6.11611","0.00694"
"73.65600","6.13817","0.00798"
"73.92000","6.16012","0.00802"
"74.18400","6.18218","0.00772"
"74.44800","6.20418","0.00749"
"74.71200","6.22624","0.00804"
"74.97600","6.24813","0.00844"
"75.24000","6.27019","0.00795"
"75.50400","6.29219","0.00718"
"75.76800","6.31425","0.00815"
"76.03200","6.33614","0.00833"
"76.29600","6.35820","0.00860"
"76.56000","6.38020","0.00885"
"76.82400","6.40220","0.00817"
"77.08800","6.42415","0.00798"
"77.35200","6.44621","0.00782"
"77.61600","6.46821","0.00742"
"77.88000","6.49021","0.00742"
"78.14400","6.51222","0.00735"
"78.40800","6.53422","0.00778"
"78.67200","6.55616","0.00692"
"78.93600","6.57816","0.00751"
"79.20000","6.60017","0.00764"
"79.46400","6.62223","0.00691"
"79.72800","6.64417","0.00760"
"79.99200","6.66617","0.00703"
"80.25600","6.68818","0.00656"
"80.52000","6.71018","0.00685"
"80.78400","6.73218","0.00744"
"81.04800","6.75418","0.00676"
"81.31200","6.77625","0.00738"
"81.57600","6.79819","0.00672"
"81.84000","6.82019","0.00759"
"82.10400","6.84219","0.00763"
"82.36800","6.86414","0.00754"
"82.63200","6.88620","0.00726"
"82.89600","6.90826","0.00716"
"83.16000","6.93020","0.00731"
"83.42400","6.95221","0.00704"
"83.68800","6.97415","0.00781"
"83.95200","6.99621","0.00782"
"84.21600","7.01816","0.00813"
"84.48000","7.04022","0.00816"
"84.74400","7.06216","0.00808"
"85.00800","7.08422","0.00854"
"85.27200","7.10617","0.00846"
"85.53600","7.12823","0.00794"
"85.80000","7.15017","0.00804"
"86.06400","7.17223","0.00850"
"86.32800","7.19418","0.00878"
"86.59200","7.21618","0.00841"
"86.85600","7.23812","0.00844"
"87.12000","7.26018","0.00892"
"87.38400","7.28213","0.00892"
"87.64800","7.30419","0.00873"
"87.91200","7.32619","0.00888"
"88.17600","7.34819","0.00839"
"88.44000","7.37014","0.00859"
"88.70400","7.39220","0.00894"
"88.96800","7.41414","0.00943"
"89.23200","7.43620","0.00902"
"89.49600","7.45815","0.00840"
"89.76000","7.48015","0.00849"
"90.02400","7.50209","0.00909"
"90.28800","7.52421","0.00930"
"90.55200","7.54616","0.00888"
"90.81600","7.56828","0.00882"
"91.08000","7.59022","0.00951"
"91.34400","7.61222","0.00917"
"91.60800","7.63417","0.00941"
"91.87200","7.65623","0.00999"
"92.13600","7.67823","0.00948"
"92.40000","7.70023","0.00964"
"92.66400","7.72224","0.00993"
"92.92800","7.74418","0.00962"
"93.19200","7.76618","0.00987"
"93.45600","7.78819","0.00982"
"93.72000","7.81019","0.00975"
"93.98400","7.83219","0.00972"
"94.24800","7.85425","0.00841"
"94.51200","7.87619","0.00810"
"94.77600","7.89820","0.00805"
"95.04000","7.92020","0.00827"
"95.30400","7.94220","0.00808"
"95.56800","7.96420","0.00804"
"95.83200","7.98627","0.00822"
"96.09600","8.00821","0.00925"
"96.36000","8.03021","0.00826"
"96.62400","8.05216","0.00869"
"96.88800","8.07422","0.00901"
"97.15200","8.09616","0.00888"
"97.41600","8.11822","0.00953"
"97.68000","8.14017","0.00929"
"97.94400","8.16223","0.00917"
"98.20800","8.18417","0.00908"
"98.47200","8.20617","0.00942"
"98.73600","8.22818","0.00964"
"99.00000","8.25024","0.00791"
"99.26400","8.27218","0.00768"
"99.52800","8.29418","0.00800"
"99.79200","8.31607","0.00872"
"100.05600","8.33819","0.00764"
"100.32000","8.36007","0.00825"
"100.58400","8.38219","0.00797"
"100.84800","8.40414","0.00850"
"101.11200","8.42626","0.00846"
"101.37600","8.44820","0.00824"
"101.64000","8.47020","0.00922"
"101.90400","8.49215","0.00826"
"102.16800","8.51421","0.00859"
"102.43200","8.53615","0.00825"
"102.69600","8.55821","0.00837"
"102.96000","8.58016","0.00820"
"103.22400","8.60216","0.00889"
"103.48800","8.62416","0.00892"
"103.75200","8.64616","0.00880"
"104.01600","8.66817","0.00829"
"104.28000","8.69023","0.00890"
"104.54400","8.71217","0.00901"
"104.80800","8.73417","0.00899"
"105.07200","8.75618","0.00885"
"105.33600","8.77824","0.00849"
"105.60000","8.80024","0.00837"
"105.86400","8.82224","0.00777"
"106.12800","8.84419","0.00824"
"106.39200","8.86619","0.00839"
"106.65600","8.88813","0.00919"
"106.92000","8.91020","0.00876"
"107.18400","8.93220","0.00870"
"107.44800","8.95426","0.00908"
"107.71200","8.97620","0.00918"
"107.97600","8.99821","0.00890"
"108.24000","9.02021","0.00844"
"108.50400","9.04221","0.00813"
"108.76800","9.06421","0.00859"
"109.03200","9.08622","0.00831"
"109.29600","9.10822","0.00832"
"109.56000","9.13016","0.00889"
"109.82400","9.15222","0.00870"
"110.08800","9.17417","0.00870"
"110.35200","9.19617","0.00876"
"110.61600","9.21817","0.00929"
"110.88000","9.24023","0.00909"
"111.14400","9.26218","0.00945"
"111.40800","9.28418","0.00899"
"111.67200","9.30612","0.00881"
"111.93600","9.32824","0.00974"
"112.20000","9.35019","0.00953"
"112.46400","9.37225","0.00935"
"112.72800","9.39413","0.00951"
"112.99200","9.41619","0.00987"
"113.25600","9.43814","0.00974"
"113.52000","9.46020","0.00974"
"113.78400","9.48220","0.00966"
"114.04800","9.50426","0.00979"
"114.31200","9.52615","0.00933"
"114.57600","9.54821","0.01012"
"114.84000","9.57015","0.00941"
"115.10400","9.59215","0.00988"
"115.36800","9.61416","0.00954"
"115.63200","9.63622","0.00972"
"115.89600","9.65816","0.01008"
"116.16000","9.68022","0.01006"
"116.42400","9.70217","0.00968"
"116.68800","9.72417","0.00971"
"116.95200","9.74611","0.01034"
"117.21600","9.76823","0.01039"
"117.48000","9.79018","0.01006"
"117.74400","9.81218","0.01021"
"118.00800","9.83412","0.01045"
"118.27200","9.85618","0.01024"
"118.53600","9.87819","0.01070"
"118.80000","9.90019","0.01039"
"119.06400","9.92219","0.01067"
"119.32800","9.94419","0.01075"
"119.59200","9.96620","0.01111"
"119.85600","9.98820","0.01098"
"120.12000","10.01020","0.01086"
"120.38400","10.03221","0.01073"
"120.64800","10.05421","0.01101"
"120.91200","10.07621","0.01114"
"121.17600","10.09821","0.01103"
"121.44000","10.12022","0.01159"
"121.70400","10.14222","0.01111"
"121.96800","10.16416","0.01167"
"122.23200","10.18622","0.01148"
"122.49600","10.20823","0.01188"
"122.76000","10.23017","0.01165"
"123.02400","10.25217","0.01228"
"123.28800","10.27417","0.01156"
"123.55200","10.29612","0.01151"
"123.81600","10.31818","0.01187"
"124.08000","10.34024","0.01242"
"124.34400","10.36224","0.01189"
"124.60800","10.38419","0.01235"
"124.87200","10.40619","0.01186"
"125.13600","10.42819","0.01214"
"125.40000","10.45019","0.01208"
"125.66400","10.47214","0.01252"
"125.92800","10.49420","0.01265"
"126.19200","10.51614","0.01276"
"126.45600","10.53820","0.01251"
"126.72000","10.56015","0.01269"
"126.98400","10.58221","0.01290"
"127.24800","10.60421","0.01316"
"127.51200","10.62621","0.01307"
"127.77600","10.64810","0.01341"
"128.04000","10.67022","0.01300"
"128.30400","10.69210","0.01334"
"128.56800","10.71422","0.01347"
"128.83200","10.73623","0.01387"
"129.09600","10.75823","0.01344"
"129.36000","10.78017","0.01357"
"129.62400","10.80217","0.01410"
"129.88800","10.82412","0.01416"
"130.15200","10.84618","0.01440"
"130.41600","10.86818","0.01380"
"130.68000","10.89024","0.01376"
"130.94400","10.91219","0.01405"
"131.20800","10.93419","0.01382"
"131.47200","10.95619","0.01414"
"131.73600","10.97820","0.01399"
"132.00000","11.00014","0.01415"
"132.26400","11.02226","0.01447"
"132.52800","11.04420","0.01360"
"132.79200","11.06621","0.01431"
"133.05600","11.08815","0.01282"
"133.32000","11.11021","0.01362"
"133.58400","11.13221","0.01343"
"133.84800","11.15427","0.01339"
"134.11200","11.17622","0.01429"
"134.37600","11.19822","0.01435"
"134.64000","11.22016","0.01358"
"134.90400","11.24223","0.01377"
"135.16800","11.26423","0.01411"
"135.43200","11.28623","0.01419"
"135.69600","11.30823","0.01418"
"135.96000","11.33018","0.01420"
"136.22400","11.35218","0.01447"
"136.48800","11.37418","0.01432"
"136.75200","11.39618","0.01415"
"137.01600","11.41813","0.01440"
"137.28000","11.44025","0.01480"
"137.54400","11.46219","0.01395"
"137.80800","11.48419","0.01465"
"138.07200","11.50614","0.01444"
"138.33600","11.52820","0.01443"
"138.60000","11.55014","0.01432"
"138.86400","11.57220","0.01456"
"139.12800","11.59415","0.01484"
"139.39200","11.61615","0.01473"
"139.65600","11.63815","0.01472"
"139.92000","11.66021","0.01459"
"140.18400","11.68222","0.01507"
"140.44800","11.70416","0.01501"
"140.71200","11.72616","0.01522"
"140.97600","11.74822","0.01514"
"141.24000","11.77017","0.01533"
"141.50400","11.79223","0.01545"
"141.76800","11.81417","0.01565"
"142.03200","11.83623","0.01585"
"142.29600","11.85812","0.01547"
"142.56000","11.88018","0.01607"
"142.82400","11.90206","0.01590"
"143.08800","11.92418","0.01611"
"143.35200","11.94613","0.01596"
"143.61600","11.96819","0.01612"
"143.88000","11.99019","0.01577"
"144.14400","12.01225","0.01627"
"144.40800","12.03420","0.01681"
"144.67200","12.05626","0.01599"
"144.93600","12.07814","0.01587"
"145.20000","12.10020","0.01658"
"145.46400","12.12215","0.01631"
"145.72800","12.14421","0.01650"
"145.99200","12.16615","0.01649"
"146.25600","12.18816","0.01593"
"146.52000","12.21022","0.01643"
"146.78400","12.23222","0.01660"
"147.04800","12.25416","0.01669"
"147.31200","12.27623","0.01694"
"147.57600","12.29817","0.01758"
"147.84000","12.32017","0.01727"
"148.10400","12.34217","0.01721"
"148.36800","12.36424","0.01713"
"148.63200","12.38618","0.01753"
"148.89600","12.40824","0.01782"
"149.16000","12.43018","0.01783"
"149.42400","12.45219","0.01802"
"149.68800","12.47419","0.01792"
"149.95200","12.49619","0.01849"
"150.21600","12.51819","0.01838"
"150.48000","12.54026","0.01858"
"150.74400","12.56220","0.01880"
"151.00800","12.58420","0.01864"
"151.27200","12.60614","0.01820"
"151.53600","12.62821","0.01820"
"151.80000","12.65021","0.01840"
"152.06400","12.67221","0.01914"
"152.32800","12.69422","0.01886"
"152.59200","12.71616","0.01891"
"152.85600","12.73822","0.01899"
"153.12000","12.76016","0.01869"
"153.38400","12.78223","0.01901"
"153.64800","12.80417","0.01932"
"153.91200","12.82623","0.01952"
"154.17600","12.84811","0.01958"
"154.44000","12.87024","0.02012"
"154.70400","12.89212","0.01967"
"154.96800","12.91424","0.01919"
"155.23200","12.93618","0.02008"
"155.49600","12.95825","0.01979"
"155.76000","12.98013","0.02000"
"156.02400","13.00219","0.02005"
"156.28800","13.02413","0.02043"
"156.55200","13.04620","0.02053"
"156.81600","13.06820","0.02111"
"157.08000","13.09026","0.02033"
"157.34400","13.11214","0.02080"
"157.60800","13.13421","0.02132"
"157.87200","13.15621","0.02179"
"158.13600","13.17821","0.02110"
"158.40000","13.20015","0.02196"
"158.66400","13.22222","0.02216"
"158.92800","13.24416","0.02222"
"159.19200","13.26616","0.02293"
"159.45600","13.28811","0.02321"
"159.72000","13.31023","0.02341"
"159.98400","13.33217","0.02336"
"160.24800","13.35423","0.02367"
"160.51200","13.37617","0.02344"
"160.77600","13.39824","0.02370"
"161.04000","13.42018","0.02367"
"161.30400","13.44224","0.02428"
"161.56800","13.46419","0.02443"
"161.83200","13.48619","0.02517"
"162.09600","13.50819","0.02534"
"162.36000","13.53019","0.02532"
"162.62400","13.55214","0.02566"
"162.88800","13.57420","0.02619"
"163.15200","13.59620","0.02644"
"163.41600","13.61820","0.02624"
"163.68000","13.64021","0.02660"
"163.94400","13.66221","0.02534"
"164.20800","13.68415","0.02549"
"164.47200","13.70621","0.02617"
"164.73600","13.72822","0.02647"
"165.00000","13.75016","0.02655"
"165.26400","13.77216","0.02719"
"165.52800","13.79416","0.02761"
"165.79200","13.81623","0.02822"
"166.05600","13.83817","0.02867"
"166.32000","13.86017","0.02815"
"166.58400","13.88217","0.02866"
"166.84800","13.90418","0.02879"
"167.11200","13.92618","0.02919"
"167.37600","13.94824","0.02900"
"167.64000","13.97018","0.02960"
"167.90400","13.99219","0.03014"
"168.16800","14.01419","0.03077"
"168.43200","14.03619","0.03060"
"168.69600","14.05813","0.03061"
"168.96000","14.08020","0.03122"
"169.22400","14.10214","0.03171"
"169.48800","14.12426","0.03204"
"169.75200","14.14614","0.03171"
"170.01600","14.16827","0.03160"
"170.28000","14.19015","0.03147"
"170.54400","14.21221","0.03266"
"170.80800","14.23415","0.03276"
"171.07200","14.25616","0.03345"
"171.33600","14.27810","0.03403"
"171.60000","14.30022","0.03395"
"171.86400","14.32216","0.03442"
"172.12800","14.34423","0.03520"
"172.39200","14.36617","0.03537"
"172.65600","14.38817","0.03603"
"172.92000","14.41018","0.03606"
"173.18400","14.43218","0.03708"
"173.44800","14.45418","0.03753"
"173.71200","14.47624","0.03750"
"173.97600","14.49819","0.03829"
"174.24000","14.52019","0.03903"
"174.50400","14.54219","0.03941"
"174.76800","14.56425","0.04008"
"175.03200","14.58614","0.04002"
"175.29600","14.60820","0.04135"
"175.56000","14.63014","0.04130"
"175.82400","14.65220","0.03981"
"176.08800","14.67415","0.03800"
"176.35200","14.69621","0.03837"
"176.61600","14.71821","0.04108"
"176.88000","14.74021","0.04013"
"177.14400","14.76222","0.04191"
"177.40800","14.78422","0.04157"
"177.67200","14.80622","0.04256"
"177.93600","14.82822","0.04222"
"178.20000","14.85023","0.04357"
"178.46400","14.87223","0.04436"
"178.72800","14.89417","0.04390"
"178.99200","14.91611","0.04605"
"179.25600","14.93818","0.04606"
"179.52000","14.96018","0.04451"
"179.78400","14.98224","0.04564"
"180.04800","15.00418","0.04533"
"180.31200","15.02625","0.04682"
"180.57600","15.04819","0.04699"
"180.84000","15.07025","0.04755"
"181.10400","15.09219","0.04789"
"181.36800","15.11420","0.04839"
"181.63200","15.13620","0.04838"
"181.89600","15.15820","0.04916"
"182.16000","15.18014","0.05050"
"182.42400","15.20221","0.05044"
"182.68800","15.22415","0.05167"
"182.95200","15.24621","0.05209"
"183.21600","15.26821","0.05276"
"183.48000","15.29022","0.05333"
"183.74400","15.31216","0.05363"
"184.00800","15.33416","0.05453"
"184.27200","15.35616","0.05496"
"184.53600","15.37823","0.05612"
"184.80000","15.40017","0.05644"
"185.06400","15.42223","0.05679"
"185.32800","15.44411","0.05692"
"185.59200","15.46618","0.05803"
"185.85600","15.48812","0.05820"
"186.12000","15.51018","0.05885"
"186.38400","15.53212","0.05943"
"186.64800","15.55425","0.05958"
"186.91200","15.57619","0.06047"
"187.17600","15.59819","0.06036"
"187.44000","15.62013","0.06023"
"187.70400","15.64220","0.06101"
"187.96800","15.66420","0.06122"
"188.23200","15.68620","0.06137"
"188.49600","15.70815","0.06192"
"188.76000","15.73021","0.06291"
"189.02400","15.75215","0.06289"
"189.28800","15.77415","0.06287"
"189.55200","15.79621","0.06343"
"189.81600","15.81822","0.06261"
"190.08000","15.84016","0.06273"
"190.34400","15.86222","0.06284"
"190.60800","15.88416","0.06096"
"190.87200","15.90617","0.06119"
"191.13600","15.92817","0.06257"
"191.40000","15.95023","0.06257"
"191.66400","15.97224","0.06410"
"191.92800","15.99418","0.06315"
"192.19200","16.01612","0.06468"
"192.45600","16.03812","0.06417"
"192.72000","16.06013","0.06545"
"192.98400","16.08219","0.06550"
"193.24800","16.10425","0.06662"
"193.51200","16.12619","0.00975"
"193.77600","16.14820","0.01000"
"194.04000","16.17020","0.00822"
"194.30400","16.19220","0.00978"
"194.56800","16.21414","0.00847"
"194.83200","16.23621","0.01013"
"195.09600","16.25821","0.00926"
"195.36000","16.28021","0.01136"
"195.62400","16.30209","0.00988"
"195.88800","16.32422","0.01157"
"196.15200","16.34616","0.01023"
"196.41600","16.36828","0.01205"
"196.68000","16.39016","0.01153"
"196.94400","16.41223","0.01251"
"197.20800","16.43411","0.01225"
"197.47200","16.45623","0.01268"
"197.73600","16.47818","0.01215"
"198.00000","16.50024","0.01311"
"198.26400","16.52218","0.01282"
"198.52800","16.54418","0.01326"
"198.79200","16.56613","0.01325"
"199.05600","16.58819","0.01422"
"199.32000","16.61019","0.01386"
"199.58400","16.63225","0.01431"
"199.84800","16.65420","0.01409"
"200.11200","16.67626","0.01468"
"200.37600","16.69814","0.01492"
"200.64000","16.72020","0.01503"
"200.90400","16.74215","0.01526"
"201.16800","16.76421","0.01580"
"201.43200","16.78609","0.01615"
"201.69600","16.80821","0.01627"
"201.96000","16.83016","0.01625"
"202.22400","16.85222","0.01681"
"202.48800","16.87416","0.01672"
"202.75200","16.89622","0.01748"
"203.01600","16.91817","0.01716"
"203.28000","16.94023","0.01806"
"203.54400","16.96217","0.01825"
"203.80800","16.98423","0.01822"
"204.07200","17.00618","0.01860"
"204.33600","17.02824","0.01831"
"204.60000","17.05018","0.01868"
"204.86400","17.07218","0.01930"
"205.12800","17.09418","0.01950"
"205.39200","17.11619","0.01942"
"205.65600","17.13819","0.02007"
"205.92000","17.16019","0.01992"
"206.18400","17.18220","0.02015"
"206.44800","17.20420","0.02070"
"206.71200","17.22620","0.02054"
"206.97600","17.24820","0.02117"
"207.24000","17.27015","0.02058"
"207.50400","17.29215","0.02134"
"207.76800","17.31421","0.02115"
"208.03200","17.33621","0.02137"
"208.29600","17.35822","0.02153"
"208.56000","17.38016","0.02193"
"208.82400","17.40222","0.02150"
"209.08800","17.42422","0.02224"
"209.35200","17.44617","0.02184"
"209.61600","17.46817","0.02228"
"209.88000","17.49023","0.02221"
"210.14400","17.51217","0.02286"
"210.40800","17.53424","0.02239"
"210.67200","17.55618","0.02304"
"210.93600","17.57824","0.02283"
"211.20000","17.60018","0.02343"
"211.46400","17.62219","0.02351"
"211.72800","17.64413","0.02368"
"211.99200","17.66619","0.02357"
"212.25600","17.68814","0.02358"
"212.52000","17.71026","0.02449"
"212.78400","17.73214","0.02423"
"213.04800","17.75426","0.02407"
"213.31200","17.77614","0.02394"
"213.57600","17.79821","0.02335"
"213.84000","17.82009","0.02365"
"214.10400","17.84221","0.02393"
"214.36800","17.86416","0.02389"
"214.63200","17.88622","0.02406"
"214.89600","17.90816","0.02391"
"215.16000","17.93016","0.02455"
"215.42400","17.95217","0.02434"
"215.68800","17.97417","0.02264"
"215.95200","17.99617","0.02348"
"216.21600","18.01823","0.02316"
"216.48000","18.04018","0.02355"
"216.74400","18.06224","0.02398"
"217.00800","18.08418","0.02413"
"217.27200","18.10618","0.02394"
"217.53600","18.12819","0.02436"
"217.80000","18.15025","0.02379"
"218.06400","18.17213","0.02502"
"218.32800","18.19419","0.02480"
"218.59200","18.21620","0.02539"
"218.85600","18.23820","0.02506"
"219.12000","18.26020","0.02537"
"219.38400","18.28226","0.02547"
"219.64800","18.30421","0.02600"
"219.91200","18.32621","0.02598"
"220.17600","18.34809","0.02590"
"220.44000","18.37021","0.02612"
"220.70400","18.39222","0.02618"
"220.96800","18.41422","0.02668"
"221.23200","18.43622","0.02693"
"221.49600","18.45823","0.02706"
"221.76000","18.48017","0.02702"
"222.02400","18.50217","0.02824"
"222.28800","18.52417","0.02796"
"222.55200","18.54618","0.02844"
"222.81600","18.56824","0.02771"
"223.08000","18.59018","0.02819"
"223.34400","18.61224","0.02799"
"223.60800","18.63412","0.02809"
"223.87200","18.65619","0.02672"
"224.13600","18.67819","0.02711"
"224.40000","18.70019","0.02726"
"224.66400","18.72214","0.02821"
"224.92800","18.74420","0.02769"
"225.19200","18.76614","0.02802"
"225.45600","18.78814","0.02808"
"225.72000","18.81015","0.02892"
"225.98400","18.83221","0.02905"
"226.24800","18.85415","0.02937"
"226.51200","18.87621","0.02930"
"226.77600","18.89810","0.02972"
"227.04000","18.92016","0.02847"
"227.30400","18.94216","0.02971"
"227.56800","18.96422","0.03032"
"227.83200","18.98617","0.03013"
"228.09600","19.00823","0.03052"
"228.36000","19.03011","0.03076"
"228.62400","19.05217","0.03113"
"228.88800","19.07418","0.03125"
"229.15200","19.09618","0.03178"
"229.41600","19.11818","0.03230"
"229.68000","19.14024","0.03175"
"229.94400","19.16219","0.03266"
"230.20800","19.18425","0.03180"
"230.47200","19.20619","0.03154"
"230.73600","19.22819","0.03199"
"231.00000","19.25020","0.03170"
"231.26400","19.27220","0.03165"
"231.52800","19.29420","0.03177"
"231.79200","19.31620","0.03171"
"232.05600","19.33815","0.03063"
"232.32000","19.36021","0.02972"
"232.58400","19.38221","0.03064"
"232.84800","19.40421","0.03072"
"233.11200","19.42616","0.03130"
"233.37600","19.44822","0.03155"
"233.64000","19.47016","0.03273"
"233.90400","19.49223","0.03312"
"234.16800","19.51423","0.03332"
"234.43200","19.53623","0.03447"
"234.69600","19.55823","0.03459"
"234.96000","19.58017","0.03494"
"235.22400","19.60212","0.03585"
"235.48800","19.62418","0.03596"
"235.75200","19.64618","0.03627"
"236.01600","19.66825","0.03615"
"236.28000","19.69025","0.03717"
"236.54400","19.71219","0.03757"
"236.80800","19.73419","0.03754"
"237.07200","19.75614","0.03847"
"237.33600","19.77820","0.03770"
"237.60000","19.80014","0.03782"
"237.86400","19.82220","0.03832"
"238.12800","19.84415","0.03892"
"238.39200","19.86621","0.03878"
"238.65600","19.88809","0.03981"
"238.92000","19.91022","0.03988"
"239.18400","19.93216","0.04039"
"239.44800","19.95422","0.04021"
"239.71200","19.97616","0.04076"
"239.97600","19.99822","0.04166"
"240.24000","20.02011","0.04126"
"240.50400","20.04217","0.04106"
"240.76800","20.06417","0.04037"
"241.03200","20.08624","0.04163"
"241.29600","20.10818","0.04117"
"241.56000","20.13018","0.04262"
"241.82400","20.15212","0.04268"
"242.08800","20.17418","0.04235"
"242.35200","20.19619","0.04307"
"242.61600","20.21819","0.04316"
"242.88000","20.24019","0.04390"
"243.14400","20.26219","0.04504"
"243.40800","20.28414","0.04519"
"243.67200","20.30620","0.04530"
"243.93600","20.32820","0.04271"
"244.20000","20.35026","0.04396"
"244.46400","20.37221","0.04365"
"244.72800","20.39421","0.04460"
"244.99200","20.41615","0.04429"
"245.25600","20.43821","0.04421"
"245.52000","20.46016","0.04402"
"245.78400","20.48222","0.04487"
"246.04800","20.50416","0.04532"
"246.31200","20.52622","0.04631"
"246.57600","20.54817","0.04643"
"246.84000","20.57023","0.04756"
"247.10400","20.59217","0.04803"
"247.36800","20.61423","0.04864"
"247.63200","20.63618","0.04944"
"247.89600","20.65818","0.03701"
"248.16000","20.68012","0.03239"
"248.42400","20.70218","0.03050"
"248.68800","20.72419","0.02954"
"248.95200","20.74619","0.02826"
"249.21600","20.76819","0.02832"
"249.48000","20.79020","0.02877"
"249.74400","20.81220","0.02919"
"250.00800","20.83414","0.02980"
"250.27200","20.85620","0.02941"
"250.53600","20.87815","0.03014"
"250.80000","20.90021","0.03028"
"251.06400","20.92215","0.03027"
"251.32800","20.94415","0.03016"
"251.59200","20.96610","0.03005"
"251.85600","20.98816","0.03088"
"252.12000","21.01016","0.02989"
"252.38400","21.03222","0.03088"
"252.64800","21.05417","0.03137"
"252.91200","21.07623","0.03168"
"253.17600","21.09817","0.03283"
"253.44000","21.12024","0.03326"
"253.70400","21.14218","0.03385"
"253.96800","21.16424","0.03351"
"254.23200","21.18618","0.03428"
"254.49600","21.20819","0.03482"
"254.76000","21.23013","0.03554"
"255.02400","21.25225","0.03594"
"255.28800","21.27413","0.03613"
"255.55200","21.29626","0.03599"
"255.81600","21.31814","0.03603"
"256.08000","21.34026","0.03686"
"256.34400","21.36214","0.03637"
"256.60800","21.38420","0.03657"
"256.87200","21.40615","0.03635"
"257.13600","21.42821","0.03642"
"257.40000","21.45015","0.03696"
"257.66400","21.47227","0.03735"
"257.92800","21.49416","0.03826"
"258.19200","21.51616","0.03901"
"258.45600","21.53816","0.03936"
"258.72000","21.56017","0.04018"
"258.98400","21.58217","0.04093"
"259.24800","21.60423","0.04086"
"259.51200","21.62617","0.04135"
"259.77600","21.64818","0.04184"
"260.04000","21.67018","0.04293"
"260.30400","21.69218","0.04267"
"260.56800","21.71418","0.04275"
"260.83200","21.73625","0.04339"
"261.09600","21.75813","0.04413"
"261.36000","21.78019","0.04484"
"261.62400","21.80219","0.04394"
"261.88800","21.82425","0.04379"
"262.15200","21.84620","0.04403"
"262.41600","21.86826","0.04275"
"262.68000","21.89020","0.04178"
"262.94400","21.91227","0.03960"
"263.20800","21.93415","0.03998"
"263.47200","21.95621","0.03872"
"263.73600","21.97821","0.04110"
"264.00000","22.00022","0.03939"
"264.26400","22.02222","0.04179"
"264.52800","22.04416","0.04089"
"264.79200","22.06616","0.04273"
"265.05600","22.08810","0.04226"
"265.32000","22.11017","0.04432"
"265.58400","22.13217","0.04493"
"265.84800","22.15423","0.04547"
"266.11200","22.17618","0.04584"
"266.37600","22.19824","0.04699"
"266.64000","22.22018","0.04777"
"266.90400","22.24224","0.04902"
"267.16800","22.26419","0.04925"
"267.43200","22.28619","0.05096"
"267.69600","22.30813","0.05109"
"267.96000","22.33019","0.05259"
"268.22400","22.35214","0.05319"
"268.48800","22.37420","0.05355"
"268.75200","22.39614","0.05440"
"269.01600","22.41827","0.05485"
"269.28000","22.44015","0.05551"
"269.54400","22.46221","0.05621"
"269.80800","22.48415","0.05684"
"270.07200","22.50621","0.05747"
"270.33600","22.52822","0.05816"
"270.60000","22.55022","0.05859"
"270.86400","22.57216","0.05908"
"271.12800","22.59417","0.05901"
"271.39200","22.61611","0.05981"
"271.65600","22.63823","0.06069"
"271.92000","22.66017","0.06186"
"272.18400","22.68223","0.06228"
"272.44800","22.70418","0.06293"
"272.71200","22.72624","0.06384"
"272.97600","22.74812","0.06386"
"273.24000","22.77019","0.06461"
"273.50400","22.79219","0.06499"
"273.76800","22.81419","0.06527"
"274.03200","22.83613","0.06591"
"274.29600","22.85820","0.06639"
"274.56000","22.88020","0.06707"
"274.82400","22.90220","0.06741"
"275.08800","22.92414","0.06773"
"275.35200","22.94615","0.06877"
"275.61600","22.96821","0.06904"
"275.88000","22.99021","0.06937"
"276.14400","23.01215","0.07056"
"276.40800","23.03416","0.07094"
"276.67200","23.05622","0.07158"
"276.93600","23.07822","0.07217"
"277.20000","23.10023","0.07211"
"277.46400","23.12223","0.07293"
"277.72800","23.14417","0.07420"
"277.99200","23.16617","0.07491"
"278.25600","23.18817","0.07624"
"278.52000","23.21012","0.07758"
"278.78400","23.23218","0.07920"
"279.04800","23.25418","0.07935"
"279.31200","23.27618","0.08057"
"279.57600","23.29819","0.08209"
"279.84000","23.32019","0.08356"
"280.10400","23.34219","0.08506"
"280.36800","23.36419","0.08698"
"280.63200","23.38620","0.08868"
"280.89600","23.40826","0.09034"
"281.16000","23.43014","0.09230"
"281.42400","23.45220","0.09544"
"281.68800","23.47409","0.09672"
"281.95200","23.49627","0.09914"
"282.21600","23.51821","0.04061"
"282.48000","23.54021","0.04387"
"282.74400","23.56216","0.03971"
"283.00800","23.58422","0.04139"
"283.27200","23.60616","0.04315"
"283.53600","23.62822","0.00531"
"283.80000","23.65017","0.01060"
"284.06400","23.67217","-0.00048"
"284.32800","23.69417","0.01309"
"284.59200","23.71618","-0.00133"
"284.85600","23.73812","0.00713"
"285.12000","23.76024","-0.00092"
"285.38400","23.78218","0.00697"
"285.64800","23.80419","-0.00047"
"285.91200","23.82619","0.00481"
"286.17600","23.84819","0.00237"
"286.44000","23.87013","0.00559"
"286.70400","23.89220","0.00277"
"286.96800","23.91414","0.00374"
"287.23200","23.93626","0.00351"
"287.49600","23.95820","0.00544"
"287.76000","23.98021","0.00403"
"288.02400","24.00215","0.00358"
"288.28800","24.02421","0.00552"
"288.55200","24.04621","0.00504"
"288.81600","24.06828","0.00474"
"289.08000","24.09016","0.00351"
"289.34400","24.11222","0.00480"
"289.60800","24.13416","0.00574"
"289.87200","24.15623","0.00498"
"290.13600","24.17823","0.00368"
"290.40000","24.20017","0.00519"
"290.66400","24.22218","0.00567"
"290.92800","24.24418","0.00501"
"291.19200","24.26612","0.00450"
"291.45600","24.28818","0.00498"
"291.72000","24.31025","0.00620"
"291.98400","24.33219","0.00468"
"292.24800","24.35425","0.00417"
"292.51200","24.37619","0.00557"
"292.77600","24.39826","0.00526"
"293.04000","24.42020","0.00448"
"293.30400","24.44220","0.00521"
"293.56800","24.46420","0.00558"
"293.83200","24.48620","0.00543"
"294.09600","24.50815","0.00543"
"294.36000","24.53021","0.00548"
"294.62400","24.55215","0.00562"
"294.88800","24.57421","0.00591"
"295.15200","24.59622","0.00462"
"295.41600","24.61822","0.00607"
"295.68000","24.64017","0.00597"
"295.94400","24.66222","0.00575"
"296.20800","24.68417","0.00493"
"296.47200","24.70623","0.00661"
"296.73600","24.72818","0.00619"
"297.00000","24.75018","0.00579"
"297.26400","24.77212","0.00497"
"297.52800","24.79418","0.00751"
"297.79200","24.81612","0.00478"
"298.05600","24.83825","0.00642"
"298.32000","24.86019","0.00503"
"298.58400","24.88219","0.00788"
"298.84800","24.90413","0.00560"
"299.11200","24.92620","0.00653"
"299.37600","24.94814","0.00530"
"299.64000","24.97020","0.00797"
"299.90400","24.99220","0.00572"
"300.16800","25.01421","0.00698"
"300.43200","25.03621","0.00673"
"300.69600","25.05821","0.00780"
"300.96000","25.08010","0.00602"
"301.22400","25.10216","0.00749"
"301.48800","25.12410","0.00695"
"301.75200","25.14622","0.00845"
"302.01600","25.16816","0.00599"
"302.28000","25.19023","0.00810"
"302.54400","25.21223","0.00673"
"302.80800","25.23423","0.00771"
"303.07200","25.25617","0.00676"
"303.33600","25.27818","0.00871"
"303.60000","25.30018","0.00681"
"303.86400","25.32218","0.00782"
"304.12800","25.34413","0.00716"
"304.39200","25.36619","0.00856"
"304.65600","25.38819","0.00737"
"304.92000","25.41019","0.00793"
"305.18400","25.43226","0.00752"
"305.44800","25.45426","0.00900"
"305.71200","25.47620","0.00722"
"305.97600","25.49820","0.00891"
"306.24000","25.52021","0.00842"
"306.50400","25.54215","0.00889"
"306.76800","25.56427","0.00833"
"307.03200","25.58621","0.00921"
"307.29600","25.60822","0.00863"
"307.56000","25.63016","0.00898"
"307.82400","25.65222","0.00838"
"308.08800","25.67416","0.00970"
"308.35200","25.69623","0.00807"
"308.61600","25.71823","0.00944"
"308.88000","25.74023","0.00905"
"309.14400","25.76212","0.00962"
"309.40800","25.78418","0.00891"
"309.67200","25.80612","0.01000"
"309.93600","25.82824","0.00874"
"310.20000","25.85018","0.00990"
"310.46400","25.87225","0.00934"
"310.72800","25.89413","0.00980"
"310.99200","25.91619","0.00951"
"311.25600","25.93814","0.00969"
"311.52000","25.96020","0.01009"
"311.78400","25.98214","0.01023"
"312.04800","26.00420","0.01033"
"312.31200","26.02614","0.01048"
"312.57600","26.04815","0.00996"
"312.84000","26.07015","0.01048"
"313.10400","26.09221","0.01054"
"313.36800","26.11415","0.01036"
"313.63200","26.13622","0.01032"
"313.89600","26.15816","0.01096"
"314.16000","26.18016","0.01103"
"314.42400","26.20211","0.01052"
"314.68800","26.22423","0.01116"
"314.95200","26.24611","0.01033"
"315.21600","26.26823","0.01085"
"315.48000","26.29017","0.01070"
"315.74400","26.31218","0.01117"
"316.00800","26.33418","0.01109"
"316.27200","26.35624","0.01119"
"316.53600","26.37819","0.01057"
"316.80000","26.40025","0.01146"
"317.06400","26.42213","0.01085"
"317.32800","26.44419","0.01156"
"317.59200","26.46619","0.01108"
"317.85600","26.48820","0.01151"
"318.12000","26.51020","0.01126"
"318.38400","26.53221","0.01129"
"318.64800","26.55420","0.01086"
"318.91200","26.57615","0.01162"
"319.17600","26.59821","0.01155"
"319.44000","26.62021","0.01231"
"319.70400","26.64221","0.01151"
"319.96800","26.66422","0.01193"
"320.23200","26.68622","0.01218"
"320.49600","26.70823","0.01195"
"320.76000","26.73017","0.01209"
"321.02400","26.75217","0.01258"
"321.28800","26.77417","0.01250"
"321.55200","26.79617","0.01249"
"321.81600","26.81818","0.01274"
"322.08000","26.84018","0.01244"
"322.34400","26.86218","0.01219"
"322.60800","26.88418","0.01251"
"322.87200","26.90625","0.01292"
"323.13600","26.92813","0.01303"
"323.40000","26.95019","0.01284"
"323.66400","26.97214","0.01277"
"323.92800","26.99420","0.01338"
"324.19200","27.01608","0.01290"
"324.45600","27.03820","0.01343"
"324.72000","27.06015","0.01291"
"324.98400","27.08227","0.01343"
"325.24800","27.10415","0.01340"
"325.51200","27.12621","0.01318"
"325.77600","27.14816","0.01353"
"326.04000","27.17016","0.01358"
"326.30400","27.19216","0.01304"
"326.56800","27.21422","0.01382"
"326.83200","27.23617","0.01382"
"327.09600","27.25817","0.01389"
"327.36000","27.28017","0.01347"
"327.62400","27.30217","0.01370"
"327.88800","27.32412","0.01387"
"328.15200","27.34624","0.01393"
"328.41600","27.36818","0.01397"
"328.68000","27.39024","0.01416"
"328.94400","27.41219","0.01446"
"329.20800","27.43419","0.01361"
"329.47200","27.45619","0.01381"
"329.73600","27.47825","0.01369"
"330.00000","27.50019","0.01419"
"330.26400","27.52220","0.01421"
"330.52800","27.54414","0.01425"
"330.79200","27.56621","0.01412"
"331.05600","27.58815","0.01452"
"331.32000","27.61021","0.01430"
"331.58400","27.63221","0.01424"
"331.84800","27.65421","0.01454"
"332.11200","27.67616","0.01462"
"332.37600","27.69822","0.01499"
"332.64000","27.72016","0.01486"
"332.90400","27.74223","0.01481"
"333.16800","27.76423","0.01503"
"333.43200","27.78623","0.01483"
"333.69600","27.80817","0.01544"
"333.96000","27.83017","0.01519"
"334.22400","27.85224","0.01514"
"334.48800","27.87418","0.01509"
"334.75200","27.89618","0.01540"
"335.01600","27.91818","0.01545"
"335.28000","27.94019","0.01534"
"335.54400","27.96213","0.01586"
"335.80800","27.98425","0.01545"
"336.07200","28.00620","0.01552"
"336.33600","28.02820","0.01584"
"336.60000","28.05020","0.01540"
"336.86400","28.07220","0.01613"
"337.12800","28.09415","0.01651"
"337.39200","28.11615","0.01649"
"337.65600","28.13815","0.01655"
"337.92000","28.16021","0.01679"
"338.18400","28.18216","0.01631"
"338.44800","28.20422","0.01641"
"338.71200","28.22616","0.01647"
"338.97600","28.24822","0.01674"
"339.24000","28.27017","0.01629"
"339.50400","28.29217","0.01660"
"339.76800","28.31417","0.01649"
"340.03200","28.33624","0.01628"
"340.29600","28.35812","0.01669"
"340.56000","28.38018","0.01667"
"340.82400","28.40212","0.01708"
"341.08800","28.42418","0.01732"
"341.35200","28.44619","0.01669"
"341.61600","28.46825","0.01693"
"341.88000","28.49019","0.01724"
"342.14400","28.51220","0.01734"
"342.40800","28.53420","0.01774"
"342.67200","28.55620","0.01752"
"342.93600","28.57814","0.01771"
"343.20000","28.60026","0.01727"
"343.46400","28.62215","0.01754"
"343.72800","28.64421","0.01756"
"343.99200","28.66615","0.01795"
"344.25600","28.68822","0.01784"
"344.52000","28.71016","0.01813"
"344.78400","28.73222","0.01795"
"345.04800","28.75416","0.01850"
"345.31200","28.77616","0.01779"
"345.57600","28.79817","0.01859"
"345.84000","28.82017","0.01797"
"346.10400","28.84223","0.01778"
"346.36800","28.86424","0.01819"
"346.63200","28.88624","0.01790"
"346.89600","28.90818","0.01682"
"347.16000","28.93012","0.01710"
"347.42400","28.95225","0.01731"
"347.68800","28.97419","0.01728"
"347.95200","28.99613","0.01772"
"348.21600","29.01825","0.01765"
"348.48000","29.04026","0.01733"
"348.74400","29.06220","0.01757"
"349.00800","29.08414","0.01766"
"349.27200","29.10620","0.01834"
"349.53600","29.12820","0.01838"
"349.80000","29.15021","0.01879"
"350.06400","29.17215","0.01807"
"350.32800","29.19421","0.01901"
"350.59200","29.21609","0.01896"
"350.85600","29.23822","0.01929"
"351.12000","29.26016","0.01848"
"351.38400","29.28222","0.01898"
"351.64800","29.30417","0.01933"
"351.91200","29.32623","0.01948"
"352.17600","29.34811","0.01914"
"352.44000","29.37024","0.01977"
"352.70400","29.39212","0.01966"
"352.96800","29.41424","0.02020"
"353.23200","29.43618","0.02021"
"353.49600","29.45818","0.02019"
"353.76000","29.48013","0.02060"
"354.02400","29.50219","0.02052"
"354.28800","29.52413","0.02073"
"354.55200","29.54619","0.02098"
"354.81600","29.56814","0.02034"
"355.08000","29.59020","0.02063"
"355.34400","29.61220","0.02077"
"355.60800","29.63414","0.02075"
"355.87200","29.65615","0.02119"
"356.13600","29.67827","0.02154"
"356.40000","29.70021","0.02132"
"356.66400","29.72221","0.02177"
"356.92800","29.74416","0.02167"
"357.19200","29.76622","0.02130"
"357.45600","29.78816","0.02174"
"357.72000","29.81029","0.02160"
"357.98400","29.83223","0.02165"
"358.24800","29.85423","0.02210"
"358.51200","29.87617","0.02217"
"358.77600","29.89823","0.02235"
"359.04000","29.92018","0.02266"
"359.30400","29.94224","0.02272"
"359.56800","29.96418","0.02258"
"359.83200","29.98618","0.02326"
"360.09600","30.00813","0.02327"
"360.36000","30.03013","0.02368"
"360.62400","30.05213","0.02346"
"360.88800","30.07419","0.02329"
"361.15200","30.09620","0.02397"
"361.41600","30.11820","0.02453"
"361.68000","30.14020","0.02402"
"361.94400","30.16215","0.02340"
"362.20800","30.18421","0.02355"
"362.47200","30.20615","0.02355"
"362.73600","30.22821","0.01791"
"363.00000","30.25016","0.02338"
"363.26400","30.27216","0.01913"
"363.52800","30.29416","0.02143"
"363.79200","30.31623","0.02173"
"364.05600","30.33817","0.02062"
"364.32000","30.36017","0.02257"
"364.58400","30.38223","0.02111"
"364.84800","30.40423","0.02283"
"365.11200","30.42618","0.02180"
"365.37600","30.44824","0.02270"
"365.64000","30.47018","0.02110"
"365.90400","30.49218","0.02217"
"366.16800","30.51419","0.02107"
"366.43200","30.53619","0.02068"
"366.69600","30.55813","0.02133"
"366.96000","30.58020","0.02170"
"367.22400","30.60214","0.02167"
"367.48800","30.62420","0.02192"
"367.75200","30.64614","0.02179"
"368.01600","30.66821","0.02147"
"368.28000","30.69015","0.02196"
"368.54400","30.71221","0.02145"
"368.80800","30.73409","0.02247"
"369.07200","30.75622","0.01962"
"369.33600","30.77816","0.02043"
"369.60000","30.80022","0.01968"
"369.86400","30.82216","0.02064"
"370.12800","30.84417","0.02017"
"370.39200","30.86617","0.02133"
"370.65600","30.88817","0.02108"
"370.92000","30.91011","0.02098"
"371.18400","30.93224","0.02162"
"371.44800","30.95424","0.02165"
"371.71200","30.97624","0.02226"
"371.97600","30.99818","0.02192"
"372.24000","31.02025","0.02232"
"372.50400","31.04219","0.02218"
"372.76800","31.06425","0.02254"
"373.03200","31.08613","0.02278"
"373.29600","31.10819","0.02278"
"373.56000","31.13008","0.02357"
"373.82400","31.15220","0.02346"
"374.08800","31.17414","0.02367"
"374.35200","31.19621","0.02347"
"374.61600","31.21821","0.02434"
"374.88000","31.24021","0.02457"
"375.14400","31.26215","0.02511"
"375.40800","31.28415","0.02494"
"375.67200","31.30622","0.02511"
"375.93600","31.32822","0.02500"
"376.20000","31.35022","0.02466"
"376.46400","31.37216","0.02534"
"376.72800","31.39417","0.02546"
"376.99200","31.41617","0.02615"
"377.25600","31.43817","0.02590"
"377.52000","31.46018","0.02601"
"377.78400","31.48224","0.02579"
"378.04800","31.50418","0.02655"
"378.31200","31.52624","0.02666"
"378.57600","31.54819","0.02664"
"378.84000","31.57025","0.02700"
"379.10400","31.59213","0.02716"
"379.36800","31.61425","0.02732"
"379.63200","31.63614","0.02780"
"379.89600","31.65820","0.02882"
"380.16000","31.68014","0.02847"
"380.42400","31.70220","0.02885"
"380.68800","31.72415","0.02579"
"380.95200","31.74621","0.02678"
"381.21600","31.76821","0.02786"
"381.48000","31.79015","0.02688"
"381.74400","31.81210","0.02693"
"382.00800","31.83422","0.02577"
"382.27200","31.85616","0.02791"
"382.53600","31.87823","0.02714"
"382.80000","31.90017","0.02857"
"383.06400","31.92217","0.02533"
"383.32800","31.94411","0.02353"
"383.59200","31.96624","0.01742"
"383.85600","31.98818","0.00053"
"384.12000","32.01024","0.00613"
"384.38400","32.03218","0.00498"
"384.64800","32.05424","-0.00042"
"384.91200","32.07613","-0.00055"
"385.17600","32.09819","0.00072"
"385.44000","32.12013","0.00074"
"385.70400","32.14225","-0.00109"
"385.96800","32.16420","-0.00097"
"386.23200","32.18620","0.00357"
"386.49600","32.20814","-0.00013"
"386.76000","32.23021","0.00327"
"387.02400","32.25221","-0.00037"
"387.28800","32.27421","0.00411"
"387.55200","32.29615","-0.00091"
"387.81600","32.31821","-0.00159"
"388.08000","32.34016","0.00036"
"388.34400","32.36216","0.00009"
"388.60800","32.38416","0.00084"
"388.87200","32.40623","-0.00107"
"389.13600","32.42823","0.00318"
"389.40000","32.45023","0.00096"
"389.66400","32.47218","-0.00059"
"389.92800","32.49417","-0.00011"
"390.19200","32.51618","-0.00038"
"390.31800","32.52664","0.00240"