File: Force_trajectories/170107_1/Specimen_RawData_5.csv
End date,"1/7/2017"
Specimen label,"DT18_41"
Maximum Load,"0.02543",N

Time,Extension,Load
(s),(mm),(N)
"0.00000","0.00000","-0.00006"
"0.34800","0.02900","0.00041"
"0.69600","0.05824","0.00018"
"1.04400","0.08723","0.00051"
"1.39200","0.11617","0.00053"
"1.74000","0.14529","0.00033"
"2.08800","0.17423","0.00048"
"2.43600","0.20316","0.00053"
"2.78400","0.23222","0.00082"
"3.13200","0.26122","0.00070"
"3.48000","0.29022","0.00097"
"3.82800","0.31928","0.00023"
"4.17600","0.34815","0.00086"
"4.52400","0.37727","0.00075"
"4.87200","0.40627","0.00057"
"5.22000","0.43515","0.00110"
"5.56800","0.46421","0.00077"
"5.91600","0.49326","0.00095"
"6.26400","0.52220","0.00127"
"6.61200","0.55126","0.00118"
"6.96000","0.58026","0.00111"
"7.30800","0.60920","0.00191"
"7.65600","0.63825","0.00128"
"8.00400","0.66725","0.00096"
"8.35200","0.69613","0.00183"
"8.70000","0.72531","0.00107"
"9.04800","0.75424","0.00168"
"9.39600","0.78318","0.00149"
"9.74400","0.81224","0.00108"
"10.09200","0.84118","0.00122"
"10.44000","0.87024","0.00113"
"10.78800","0.89923","0.00116"
"11.13600","0.92823","0.00095"
"11.48400","0.95723","0.00122"
"11.83200","0.98623","0.00108"
"12.18000","1.01523","0.00205"
"12.52800","1.04422","0.00104"
"12.87600","1.07322","0.00147"
"13.22400","1.10222","0.00151"
"13.57200","1.13122","0.00180"
"13.92000","1.16022","0.00159"
"14.26800","1.18915","0.00113"
"14.61600","1.21821","0.00174"
"14.96400","1.24721","0.00121"
"15.31200","1.27621","0.00144"
"15.66000","1.30521","0.00109"
"16.00800","1.33420","0.00186"
"16.35600","1.36326","0.00105"
"16.70400","1.39226","0.00138"
"17.05200","1.42114","0.00201"
"17.40000","1.45020","0.00117"
"17.74800","1.47931","0.00151"
"18.09600","1.50813","0.00154"
"18.44400","1.53731","0.00206"
"18.79200","1.56625","0.00172"
"19.14000","1.59518","0.00212"
"19.48800","1.62430","0.00183"
"19.83600","1.65324","0.00182"
"20.18400","1.68224","0.00190"
"20.53200","1.71124","0.00242"
"20.88000","1.74017","0.00185"
"21.22800","1.76923","0.00214"
"21.57600","1.79817","0.00233"
"21.92400","1.82723","0.00207"
"22.27200","1.85623","0.00198"
"22.62000","1.88522","0.00186"
"22.96800","1.91422","0.00253"
"23.31600","1.94322","0.00253"
"23.66400","1.97228","0.00229"
"24.01200","2.00116","0.00282"
"24.36000","2.03021","0.00262"
"24.70800","2.05927","0.00293"
"25.05600","2.08821","0.00204"
"25.40400","2.11721","0.00240"
"25.75200","2.14621","0.00276"
"26.10000","2.17520","0.00263"
"26.44800","2.20426","0.00294"
"26.79600","2.23320","0.00273"
"27.14400","2.26220","0.00255"
"27.49200","2.29125","0.00289"
"27.84000","2.32019","0.00303"
"28.18800","2.34925","0.00280"
"28.53600","2.37825","0.00272"
"28.88400","2.40713","0.00349"
"29.23200","2.43624","0.00277"
"29.58000","2.46524","0.00368"
"29.92800","2.49424","0.00339"
"30.27600","2.52324","0.00313"
"30.62400","2.55224","0.00320"
"30.97200","2.58117","0.00336"
"31.32000","2.61023","0.00323"
"31.67000","2.63941","0.00340"
"32.01800","2.66835","0.00372"
"32.36600","2.69740","0.00384"
"32.71400","2.72634","0.00341"
"33.06200","2.75534","0.00360"
"33.41000","2.78446","0.00371"
"33.75800","2.81334","0.00372"
"34.10600","2.84239","0.00369"
"34.45400","2.87145","0.00419"
"34.80200","2.90039","0.00353"
"35.15000","2.92939","0.00450"
"35.49800","2.95839","0.00385"
"35.84600","2.98738","0.00421"
"36.19400","3.01638","0.00406"
"36.54200","3.04544","0.00473"
"36.89000","3.07438","0.00363"
"37.23800","3.10338","0.00437"
"37.58600","3.13243","0.00358"
"37.93400","3.16143","0.00430"
"38.28200","3.19043","0.00464"
"38.63000","3.21937","0.00451"
"38.97800","3.24843","0.00472"
"39.32600","3.27736","0.00570"
"39.67400","3.30630","0.00491"
"40.02200","3.33536","0.00513"
"40.37000","3.36442","0.00521"
"40.71800","3.39336","0.00442"
"41.06600","3.42241","0.00565"
"41.41400","3.45147","0.00577"
"41.76200","3.48035","0.00484"
"42.11000","3.50947","0.00571"
"42.45800","3.53840","0.00541"
"42.80600","3.56734","0.00539"
"43.15400","3.59640","0.00557"
"43.50200","3.62540","0.00560"
"43.85000","3.65434","0.00554"
"44.19800","3.68339","0.00617"
"44.54600","3.71239","0.00601"
"44.89400","3.74139","0.00565"
"45.24200","3.77039","0.00639"
"45.59000","3.79939","0.00579"
"45.93800","3.82838","0.00636"
"46.28600","3.85744","0.00574"
"46.63400","3.88632","0.00552"
"46.98200","3.91538","0.00567"
"47.33000","3.94438","0.00611"
"47.67800","3.97337","0.00638"
"48.02600","4.00243","0.00581"
"48.37400","4.03137","0.00644"
"48.72200","4.06037","0.00648"
"49.07000","4.08943","0.00639"
"49.41800","4.11836","0.00715"
"49.76600","4.14742","0.00637"
"50.11400","4.17636","0.00669"
"50.46200","4.20542","0.00697"
"50.81000","4.23441","0.00724"
"51.15800","4.26341","0.00691"
"51.50600","4.29235","0.00689"
"51.85400","4.32141","0.00673"
"52.20200","4.35041","0.00656"
"52.55000","4.37934","0.00735"
"52.89800","4.40846","0.00692"
"53.24600","4.43740","0.00723"
"53.59400","4.46640","0.00698"
"53.94200","4.49546","0.00704"
"54.29000","4.52439","0.00725"
"54.63800","4.55333","0.00763"
"54.98600","4.58239","0.00720"
"55.33400","4.61139","0.00753"
"55.68200","4.64039","0.00741"
"56.03000","4.66938","0.00757"
"56.37800","4.69838","0.00811"
"56.72600","4.72738","0.00743"
"57.07400","4.75644","0.00766"
"57.42200","4.78532","0.00780"
"57.77000","4.81443","0.00762"
"58.11800","4.84343","0.00804"
"58.46600","4.87231","0.00825"
"58.81400","4.90143","0.00801"
"59.16200","4.93042","0.00811"
"59.51000","4.95936","0.00810"
"59.85800","4.98842","0.00780"
"60.20600","5.01736","0.00812"
"60.55400","5.04642","0.00847"
"60.90200","5.07541","0.00871"
"61.25000","5.10441","0.00822"
"61.59800","5.13335","0.00826"
"61.94600","5.16241","0.00883"
"62.29400","5.19135","0.00857"
"62.64200","5.22040","0.00919"
"62.99000","5.24940","0.00848"
"63.33800","5.27834","0.00870"
"63.68600","5.30746","0.00875"
"64.03400","5.33639","0.00868"
"64.38200","5.36533","0.00903"
"64.73000","5.39439","0.00847"
"65.07800","5.42339","0.00875"
"65.42600","5.45233","0.00886"
"65.77400","5.48139","0.00857"
"66.12200","5.51038","0.00857"
"66.47000","5.53938","0.00895"
"66.81800","5.56844","0.00887"
"67.16600","5.59738","0.00919"
"67.51400","5.62637","0.00902"
"67.86200","5.65543","0.00898"
"68.21000","5.68437","0.00895"
"68.55800","5.71349","0.00914"
"68.90600","5.74243","0.00955"
"69.25400","5.77136","0.00971"
"69.60200","5.80036","0.00838"
"69.95000","5.82936","0.00877"
"70.29800","5.85836","0.00935"
"70.64600","5.88742","0.00883"
"70.99400","5.91641","0.00872"
"71.34200","5.94541","0.00875"
"71.69000","5.97441","0.00845"
"72.03800","6.00341","0.00855"
"72.38600","6.03240","0.00924"
"72.73400","6.06140","0.00948"
"73.08200","6.09034","0.00885"
"73.43000","6.11946","0.00871"
"73.77800","6.14840","0.00925"
"74.12600","6.17740","0.00894"
"74.47400","6.20633","0.00849"
"74.82200","6.23539","0.00877"
"75.17000","6.26433","0.00881"
"75.51800","6.29345","0.00916"
"75.86600","6.32244","0.00959"
"76.21400","6.35132","0.00957"
"76.56200","6.38044","0.00916"
"76.91000","6.40944","0.00977"
"77.25800","6.43838","0.00915"
"77.60600","6.46749","0.00978"
"77.95400","6.49637","0.00972"
"78.30200","6.52537","0.00982"
"78.65000","6.55443","0.00931"
"78.99800","6.58337","0.00948"
"79.34600","6.61242","0.00940"
"79.69400","6.64136","0.00983"
"80.04200","6.67036","0.00960"
"80.39000","6.69936","0.00965"
"80.73800","6.72848","0.00946"
"81.08600","6.75735","0.00944"
"81.43400","6.78641","0.00997"
"81.78200","6.81541","0.00938"
"82.13000","6.84435","0.00997"
"82.47800","6.87340","0.00957"
"82.82600","6.90240","0.00961"
"83.17400","6.93134","0.00950"
"83.52200","6.96046","0.00954"
"83.87000","6.98940","0.00995"
"84.21800","7.01839","0.00952"
"84.56600","7.04739","0.00910"
"84.91400","7.07639","0.00982"
"85.26200","7.10539","0.00906"
"85.61000","7.13445","0.00899"
"85.95800","7.16332","0.00937"
"86.30600","7.19238","0.00865"
"86.65400","7.22144","0.00802"
"87.00200","7.25032","0.00842"
"87.35000","7.27944","0.00821"
"87.69800","7.30837","0.00874"
"88.04600","7.33737","0.00853"
"88.39400","7.36643","0.00919"
"88.74200","7.39543","0.00828"
"89.09000","7.42437","0.00828"
"89.43800","7.45336","0.00849"
"89.78600","7.48236","0.00894"
"90.13400","7.51136","0.00892"
"90.48200","7.54042","0.00789"
"90.83000","7.56936","0.00901"
"91.17800","7.59835","0.00886"
"91.52600","7.62741","0.00929"
"91.87400","7.65635","0.00882"
"92.22200","7.68541","0.00934"
"92.57000","7.71440","0.00891"
"92.91800","7.74334","0.00920"
"93.26600","7.77240","0.00812"
"93.61400","7.80140","0.00917"
"93.96200","7.83040","0.00903"
"94.31000","7.85945","0.00904"
"94.65800","7.88839","0.00977"
"95.00600","7.91739","0.00959"
"95.35400","7.94645","0.00904"
"95.70200","7.97533","0.00926"
"96.05000","8.00438","0.00924"
"96.39800","8.03338","0.00922"
"96.74600","8.06238","0.00957"
"97.09400","8.09144","0.00896"
"97.44200","8.12037","0.00951"
"97.79000","8.14931","0.00950"
"98.13800","8.17843","0.01002"
"98.48600","8.20743","0.00925"
"98.83400","8.23637","0.00909"
"99.18200","8.26542","0.00973"
"99.53000","8.29442","0.00979"
"99.87800","8.32336","0.00976"
"100.22600","8.35236","0.00944"
"100.57400","8.38142","0.01020"
"100.92200","8.41035","0.00977"
"101.27000","8.43947","0.01001"
"101.61800","8.46835","0.01022"
"101.96600","8.49741","0.00984"
"102.31400","8.52641","0.01022"
"102.66200","8.55534","0.00941"
"103.01000","8.58440","0.00985"
"103.35800","8.61340","0.00942"
"103.70600","8.64234","0.01037"
"104.05400","8.67140","0.01059"
"104.40200","8.70039","0.01004"
"104.75000","8.72933","0.01011"
"105.09800","8.75839","0.00995"
"105.44600","8.78745","0.01017"
"105.79400","8.81633","0.01003"
"106.14200","8.84544","0.01039"
"106.49000","8.87444","0.01035"
"106.83800","8.90338","0.01038"
"107.18600","8.93238","0.01048"
"107.53400","8.96138","0.01016"
"107.88200","8.99037","0.01004"
"108.23000","9.01937","0.00988"
"108.57800","9.04843","0.01001"
"108.92600","9.07737","0.01015"
"109.27400","9.10642","0.01004"
"109.62200","9.13536","0.00930"
"109.97000","9.16442","0.00961"
"110.31800","9.19348","0.01081"
"110.66600","9.22230","0.01097"
"111.01400","9.25147","0.01020"
"111.36200","9.28041","0.01077"
"111.71000","9.30935","0.01018"
"112.05800","9.33841","0.00992"
"112.40600","9.36735","0.01038"
"112.75400","9.39640","0.01053"
"113.10200","9.42540","0.00980"
"113.45000","9.45440","0.01049"
"113.79800","9.48334","0.01021"
"114.14600","9.51240","0.01059"
"114.49400","9.54139","0.00995"
"114.84200","9.57039","0.01018"
"115.19000","9.59945","0.01022"
"115.53800","9.62839","0.01047"
"115.88600","9.65738","0.01069"
"116.23400","9.68644","0.01068"
"116.58200","9.71532","0.01060"
"116.93000","9.74444","0.01094"
"117.27800","9.77338","0.01097"
"117.62600","9.80237","0.01049"
"117.97400","9.83143","0.01065"
"118.32200","9.86043","0.01111"
"118.67000","9.88937","0.01064"
"119.01800","9.91843","0.01124"
"119.36600","9.94736","0.01124"
"119.71400","9.97642","0.01072"
"120.06200","10.00548","0.01052"
"120.41000","10.03430","0.01150"
"120.75800","10.06342","0.01035"
"121.10600","10.09241","0.01037"
"121.45400","10.12135","0.01071"
"121.80200","10.15047","0.01014"
"122.15000","10.17941","0.01068"
"122.49800","10.20840","0.01089"
"122.84600","10.23746","0.01040"
"123.19400","10.26640","0.01048"
"123.54200","10.29540","0.01074"
"123.89000","10.32440","0.01015"
"124.23800","10.35339","0.01091"
"124.58600","10.38239","0.01105"
"124.93400","10.41145","0.01083"
"125.28200","10.44033","0.01111"
"125.63000","10.46939","0.01111"
"125.97800","10.49838","0.01153"
"126.32600","10.52732","0.01145"
"126.67400","10.55638","0.01160"
"127.02200","10.58544","0.01169"
"127.37000","10.61438","0.01150"
"127.71800","10.64337","0.01144"
"128.06600","10.67243","0.01174"
"128.41400","10.70131","0.01229"
"128.76200","10.73043","0.01082"
"129.11000","10.75943","0.01182"
"129.45800","10.78836","0.01164"
"129.80600","10.81748","0.01164"
"130.15400","10.84642","0.01188"
"130.50200","10.87536","0.01203"
"130.85000","10.90436","0.01195"
"131.19800","10.93341","0.01187"
"131.54600","10.96241","0.01202"
"131.89400","10.99135","0.01241"
"132.24200","11.02035","0.01254"
"132.59000","11.04941","0.01245"
"132.93800","11.07840","0.01259"
"133.28600","11.10734","0.01280"
"133.63400","11.13640","0.01288"
"133.98200","11.16546","0.01264"
"134.33000","11.19433","0.01277"
"134.67800","11.22345","0.01317"
"135.02600","11.25239","0.01323"
"135.37400","11.28133","0.01339"
"135.72200","11.31045","0.01315"
"136.07000","11.33938","0.01340"
"136.41800","11.36838","0.01254"
"136.76600","11.39738","0.01236"
"137.11400","11.42638","0.01197"
"137.46200","11.45538","0.01225"
"137.81000","11.48443","0.01213"
"138.15800","11.51337","0.01277"
"138.50600","11.54237","0.01287"
"138.85400","11.57143","0.01277"
"139.20200","11.60031","0.01281"
"139.55000","11.62942","0.01244"
"139.89800","11.65842","0.01292"
"140.24600","11.68742","0.01328"
"140.59400","11.71642","0.01366"
"140.94200","11.74541","0.01360"
"141.29000","11.77441","0.01382"
"141.63800","11.80341","0.01381"
"141.98600","11.83241","0.01372"
"142.33400","11.86141","0.01388"
"142.68200","11.89040","0.01403"
"143.03000","11.91940","0.01416"
"143.37800","11.94834","0.01437"
"143.72600","11.97740","0.01459"
"144.07400","12.00640","0.01460"
"144.42200","12.03545","0.01500"
"144.77000","12.06445","0.01494"
"145.11800","12.09333","0.01500"
"145.46600","12.12245","0.01510"
"145.81400","12.15138","0.01489"
"146.16200","12.18038","0.01545"
"146.51000","12.20944","0.01541"
"146.85800","12.23838","0.01580"
"147.20600","12.26732","0.01604"
"147.55400","12.29643","0.01619"
"147.90200","12.32537","0.01565"
"148.25000","12.35437","0.01631"
"148.59800","12.38343","0.01653"
"148.94600","12.41237","0.01674"
"149.29400","12.44142","0.01624"
"149.64200","12.47042","0.01701"
"149.99000","12.49930","0.01654"
"150.33800","12.52842","0.01609"
"150.68600","12.55742","0.01632"
"151.03400","12.58641","0.01633"
"151.38200","12.61541","0.01641"
"151.73000","12.64441","0.01694"
"152.07800","12.67341","0.01684"
"152.42600","12.70241","0.01649"
"152.77400","12.73146","0.01665"
"153.12200","12.76034","0.01692"
"153.47000","12.78940","0.01724"
"153.81800","12.81840","0.01668"
"154.16600","12.84739","0.01696"
"154.51400","12.87639","0.01687"
"154.86200","12.90533","0.01717"
"155.21000","12.93445","0.01690"
"155.55800","12.96345","0.01746"
"155.90600","12.99239","0.01498"
"156.25400","13.02144","0.01188"
"156.60200","13.05044","0.01225"
"156.95000","13.07938","0.01250"
"157.29800","13.10838","0.01260"
"157.64600","13.13744","0.01200"
"157.99400","13.16637","0.01321"
"158.34200","13.19537","0.01260"
"158.69000","13.22443","0.01278"
"159.03800","13.25343","0.01293"
"159.38600","13.28242","0.01304"
"159.73400","13.31142","0.01250"
"160.08200","13.34042","0.01328"
"160.43000","13.36936","0.01365"
"160.77800","13.39836","0.01298"
"161.12600","13.42735","0.01384"
"161.47400","13.45641","0.01392"
"161.82200","13.48535","0.01361"
"162.17000","13.51441","0.01402"
"162.51800","13.54341","0.01436"
"162.86600","13.57234","0.01457"
"163.21400","13.60140","0.01466"
"163.56200","13.63040","0.01472"
"163.91000","13.65934","0.01536"
"164.25800","13.68839","0.01530"
"164.60600","13.71739","0.01563"
"164.95400","13.74633","0.01603"
"165.30200","13.77545","0.01621"
"165.65000","13.80439","0.01613"
"165.99800","13.83345","0.01620"
"166.34600","13.86238","0.01646"
"166.69400","13.89138","0.01703"
"167.04200","13.92038","0.01667"
"167.39000","13.94938","0.01653"
"167.73800","13.97837","0.01683"
"168.08600","14.00737","0.01725"
"168.43400","14.03643","0.01780"
"168.78200","14.06537","0.01728"
"169.13000","14.09443","0.01799"
"169.47800","14.12336","0.01759"
"169.82600","14.15236","0.01825"
"170.17400","14.18148","0.01804"
"170.52200","14.21042","0.01905"
"170.87000","14.23936","0.01843"
"171.21800","14.26841","0.01798"
"171.56600","14.29741","0.01861"
"171.91400","14.32635","0.01889"
"172.26200","14.35541","0.01919"
"172.61000","14.38441","0.01882"
"172.95800","14.41340","0.01876"
"173.30600","14.44240","0.01970"
"173.65400","14.47134","0.01995"
"174.00200","14.50046","0.01990"
"174.35000","14.52940","0.01641"
"174.69800","14.55833","0.01204"
"175.04600","14.58745","0.01139"
"175.39400","14.61639","0.01056"
"175.74200","14.64539","0.01070"
"176.09000","14.67445","0.01031"
"176.43800","14.70338","0.01062"
"176.78600","14.73238","0.01088"
"177.13400","14.76138","0.01086"
"177.48200","14.79038","0.01099"
"177.83000","14.81931","0.01160"
"178.17800","14.84843","0.01049"
"178.52600","14.87737","0.01130"
"178.87400","14.90643","0.01143"
"179.22200","14.93543","0.01178"
"179.57000","14.96430","0.01150"
"179.91800","14.99342","0.01183"
"180.26600","15.02242","0.01191"
"180.61400","15.05136","0.01176"
"180.96200","15.08041","0.01204"
"181.31000","15.10941","0.01230"
"181.65800","15.13835","0.01184"
"182.00800","15.16759","0.01176"
"182.35600","15.19659","0.01233"
"182.70400","15.22552","0.01154"
"183.05400","15.25482","0.01261"
"183.40200","15.28370","0.01240"
"183.75000","15.31276","0.01220"
"184.09800","15.34170","0.01223"
"184.44600","15.37069","0.01245"
"184.79400","15.39975","0.01208"
"185.14200","15.42869","0.01232"
"185.49000","15.45769","0.01207"
"185.83800","15.48668","0.01245"
"186.18600","15.51574","0.01275"
"186.53400","15.54468","0.01264"
"186.88200","15.57374","0.01278"
"187.23000","15.60274","0.01278"
"187.57800","15.63173","0.01307"
"187.92600","15.66073","0.01277"
"188.27400","15.68973","0.01297"
"188.62200","15.71873","0.01245"
"188.97000","15.74773","0.01299"
"189.31800","15.77672","0.01329"
"189.66600","15.80578","0.01315"
"190.01400","15.83472","0.01337"
"190.36200","15.86372","0.01337"
"190.71000","15.89272","0.01344"
"191.05800","15.92177","0.01389"
"191.40600","15.95071","0.01364"
"191.75400","15.97977","0.01356"
"192.10200","16.00877","0.01298"
"192.45000","16.03765","0.01365"
"192.79800","16.06670","0.01408"
"193.14600","16.09570","0.01385"
"193.49400","16.12470","0.01411"
"193.84200","16.15376","0.01420"
"194.19000","16.18270","0.01427"
"194.53800","16.21169","0.01466"
"194.88600","16.24069","0.01434"
"195.23400","16.26975","0.01428"
"195.58200","16.29875","0.01453"
"195.93000","16.32774","0.01468"
"196.27800","16.35674","0.01435"
"196.62600","16.38574","0.01452"
"196.97400","16.41474","0.01485"
"197.32200","16.44368","0.01477"
"197.67000","16.47279","0.01496"
"198.01800","16.50179","0.01501"
"198.36600","16.53073","0.01490"
"198.71400","16.55979","0.01499"
"199.06200","16.58873","0.01531"
"199.41000","16.61766","0.01553"
"199.75800","16.64678","0.01518"
"200.10600","16.67572","0.01539"
"200.45400","16.70472","0.01523"
"200.80200","16.73372","0.01519"
"201.15000","16.76271","0.01543"
"201.49800","16.79171","0.01571"
"201.84600","16.82083","0.01544"
"202.19400","16.84971","0.01573"
"202.54200","16.87877","0.01607"
"202.89000","16.90776","0.01593"
"203.23800","16.93670","0.01613"
"203.58600","16.96576","0.01608"
"203.93400","16.99475","0.01595"
"204.28200","17.02369","0.01636"
"204.63000","17.05275","0.01666"
"204.97800","17.08175","0.01674"
"205.32600","17.11069","0.01658"
"205.67400","17.13975","0.01699"
"206.02200","17.16874","0.01671"
"206.37000","17.19774","0.01671"
"206.71800","17.22680","0.01716"
"207.06600","17.25568","0.01727"
"207.41400","17.28468","0.01699"
"207.76200","17.31373","0.01720"
"208.11000","17.34267","0.01667"
"208.45800","17.37173","0.01740"
"208.80600","17.40079","0.01770"
"209.15400","17.42966","0.01719"
"209.50200","17.45878","0.01726"
"209.85000","17.48772","0.01678"
"210.19800","17.51672","0.01681"
"210.54600","17.54572","0.01727"
"210.89400","17.57471","0.01682"
"211.24200","17.60371","0.01669"
"211.59000","17.63271","0.01711"
"211.93800","17.66171","0.01712"
"212.28600","17.69071","0.01756"
"212.63400","17.71971","0.01764"
"212.98200","17.74870","0.01779"
"213.33000","17.77776","0.01776"
"213.67800","17.80676","0.01861"
"214.02600","17.83564","0.01783"
"214.37400","17.86475","0.01837"
"214.72200","17.89375","0.01860"
"215.07000","17.92269","0.01860"
"215.41800","17.95175","0.01847"
"215.76600","17.98075","0.01878"
"216.11400","18.00968","0.01928"
"216.46200","18.03874","0.01893"
"216.81000","18.06774","0.01782"
"217.15800","18.09668","0.01843"
"217.50600","18.12580","0.01896"
"217.85400","18.15473","0.01861"
"218.20200","18.18373","0.01838"
"218.55000","18.21273","0.01936"
"218.89800","18.24173","0.01868"
"219.24600","18.27073","0.01957"
"219.59400","18.29972","0.01937"
"219.94200","18.32872","0.02003"
"220.29000","18.35772","0.01952"
"220.63800","18.38678","0.01971"
"220.98600","18.41571","0.02030"
"221.33400","18.44477","0.02017"
"221.68200","18.47377","0.02027"
"222.03000","18.50271","0.02075"
"222.37800","18.53176","0.02062"
"222.72600","18.56070","0.02052"
"223.07400","18.58976","0.02127"
"223.42200","18.61882","0.02132"
"223.77000","18.64770","0.02175"
"224.11800","18.67670","0.02130"
"224.46600","18.70569","0.02189"
"224.81400","18.73475","0.02114"
"225.16200","18.76369","0.02041"
"225.51000","18.79275","0.01962"
"225.85800","18.82168","0.01869"
"226.20600","18.85074","0.01885"
"226.55400","18.87974","0.01908"
"226.90200","18.90862","0.01953"
"227.25000","18.93780","0.01915"
"227.59800","18.96673","0.01991"
"227.94600","18.99573","0.01987"
"228.29400","19.02473","0.02052"
"228.64200","19.05367","0.02030"
"228.99000","19.08267","0.02064"
"229.33800","19.11172","0.02039"
"229.68600","19.14072","0.02100"
"230.03400","19.16972","0.02133"
"230.38200","19.19872","0.02157"
"230.73000","19.22766","0.02126"
"231.07800","19.25665","0.02096"
"231.42600","19.28577","0.02060"
"231.77400","19.31471","0.02126"
"232.12200","19.34377","0.02095"
"232.47000","19.37276","0.02137"
"232.81800","19.40170","0.02144"
"233.16600","19.43076","0.02206"
"233.51400","19.45970","0.02212"
"233.86200","19.48876","0.02269"
"234.21000","19.51776","0.02313"
"234.55800","19.54675","0.02261"
"234.90600","19.57569","0.02297"
"235.25400","19.60469","0.02312"
"235.60200","19.63369","0.02385"
"235.95000","19.66269","0.02357"
"236.29800","19.69174","0.02374"
"236.64600","19.72068","0.02464"
"236.99400","19.74968","0.02407"
"237.34200","19.77874","0.02375"
"237.69000","19.80767","0.02366"
"238.03800","19.83673","0.02288"
"238.38600","19.86573","0.02287"
"238.73400","19.89473","0.01958"
"239.08200","19.92373","0.02010"
"239.43000","19.95278","0.02066"
"239.77800","19.98172","0.02012"
"240.12600","20.01072","0.01991"
"240.47400","20.03972","0.02036"
"240.82200","20.06872","0.01997"
"241.17000","20.09777","0.02051"
"241.51800","20.12665","0.02086"
"241.86600","20.15571","0.02153"
"242.21400","20.18471","0.02176"
"242.56200","20.21371","0.02198"
"242.91000","20.24276","0.02275"
"243.25800","20.27170","0.02302"
"243.60600","20.30070","0.02311"
"243.95400","20.32969","0.02279"
"244.30200","20.35875","0.02313"
"244.65000","20.38775","0.02350"
"244.99800","20.41675","0.02337"
"245.34600","20.44581","0.02399"
"245.69400","20.47469","0.02075"
"246.04200","20.50374","0.02166"
"246.39000","20.53268","0.02094"
"246.73800","20.56174","0.02160"
"247.08600","20.59074","0.02198"
"247.43400","20.61974","0.02172"
"247.78200","20.64879","0.02208"
"248.13000","20.67773","0.02122"
"248.47800","20.70667","0.02195"
"248.82600","20.73573","0.02221"
"249.17400","20.76479","0.02283"
"249.52200","20.79366","0.02315"
"249.87000","20.82272","0.02344"
"250.21800","20.85178","0.02317"
"250.56600","20.88066","0.02362"
"250.91400","20.90977","0.02378"
"251.26200","20.93877","0.02403"
"251.61000","20.96771","0.02424"
"251.95800","20.99677","0.02474"
"252.30600","21.02571","0.02508"
"252.65400","21.05470","0.01603"
"253.00200","21.08376","0.01547"
"253.35000","21.11276","0.01906"
"253.69800","21.14176","0.01736"
"254.04600","21.17075","0.01602"
"254.39400","21.19969","0.01706"
"254.74200","21.22869","0.01842"
"255.09000","21.25781","0.01843"
"255.43800","21.28669","0.01760"
"255.78600","21.31575","0.01886"
"256.13400","21.34474","0.01903"
"256.48200","21.37368","0.01948"
"256.83000","21.40274","0.01946"
"257.17800","21.43174","0.01994"
"257.52600","21.46074","0.01938"
"257.87400","21.48979","0.01943"
"258.22200","21.51873","0.02017"
"258.57000","21.54773","0.02041"
"258.91800","21.57673","0.01986"
"259.26600","21.60573","0.02052"
"259.61400","21.63472","0.02000"
"259.96200","21.66378","0.01973"
"260.31000","21.69272","0.01975"
"260.65800","21.72172","0.01796"
"261.00600","21.75072","0.01786"
"261.35400","21.77965","0.01825"
"261.70200","21.80871","0.01771"
"262.05000","21.83777","0.01766"
"262.39800","21.86671","0.01861"
"262.74600","21.89570","0.01942"
"263.09400","21.92476","0.01936"
"263.44200","21.95370","0.01890"
"263.79000","21.98276","0.01900"
"264.13800","22.01175","0.01929"
"264.48600","22.04070","0.01947"
"264.83400","22.06975","0.01979"
"265.18200","22.09875","0.01979"
"265.53000","22.12769","0.01976"
"265.87800","22.15674","0.02026"
"266.22600","22.18568","0.02042"
"266.57400","22.21480","0.02005"
"266.92200","22.24374","0.02044"
"267.27000","22.27268","0.02024"
"267.61800","22.30173","0.02027"
"267.96600","22.33073","0.02029"
"268.31400","22.35967","0.02056"
"268.66200","22.38873","0.02103"
"269.01000","22.41773","0.01940"
"269.35800","22.44673","0.01993"
"269.70600","22.47572","0.02014"
"270.05400","22.50472","0.01971"
"270.40200","22.53372","0.02000"
"270.75000","22.56272","0.02077"
"271.09800","22.59171","0.02098"
"271.44600","22.62077","0.02059"
"271.79400","22.64971","0.02173"
"272.14200","22.67871","0.02196"
"272.49000","22.70777","0.02163"
"272.83800","22.73676","0.02154"
"273.18600","22.76564","0.02249"
"273.53400","22.79476","0.02266"
"273.88200","22.82382","0.02274"
"274.23000","22.85264","0.02299"
"274.57800","22.88175","0.02285"
"274.92600","22.91075","0.02341"
"275.27400","22.93969","0.02273"
"275.62200","22.96875","0.01692"
"275.97000","22.99769","0.01644"
"276.31800","23.02668","0.01706"
"276.66600","23.05574","0.01612"
"277.01400","23.08474","0.01619"
"277.36200","23.11374","0.01687"
"277.71000","23.14273","0.01752"
"278.05800","23.17173","0.01738"
"278.40600","23.20073","0.01786"
"278.75400","23.22979","0.01779"
"279.10200","23.25867","0.01802"
"279.45000","23.28772","0.01805"
"279.79800","23.31672","0.01910"
"280.14600","23.34566","0.01884"
"280.49400","23.37472","0.01864"
"280.84200","23.40377","0.01949"
"281.19000","23.43271","0.01983"
"281.53800","23.46171","0.01945"
"281.88600","23.49071","0.01922"
"282.23400","23.51965","0.02036"
"282.58200","23.54871","0.02052"
"282.93000","23.57776","0.02005"
"283.27800","23.60676","0.02064"
"283.62600","23.63582","0.02066"
"283.97400","23.66464","0.01969"
"284.32200","23.69376","0.01968"
"284.67000","23.72275","0.02009"
"285.01800","23.75169","0.01991"
"285.36600","23.78081","0.02050"
"285.71400","23.80975","0.01986"
"286.06200","23.83868","0.02057"
"286.41000","23.86774","0.02072"
"286.75800","23.89668","0.02010"
"287.10600","23.92568","0.02087"
"287.45400","23.95474","0.02076"
"287.80200","23.98374","0.02099"
"288.15000","24.01273","0.02114"
"288.49800","24.04179","0.02090"
"288.84600","24.07073","0.02072"
"289.19400","24.09967","0.02107"
"289.54200","24.12878","0.02160"
"289.89000","24.15766","0.02171"
"290.23800","24.18678","0.02144"
"290.58600","24.21578","0.01879"
"290.93400","24.24471","0.01551"
"291.28200","24.27371","0.01525"
"291.63000","24.30271","0.01412"
"291.97800","24.33165","0.01421"
"292.32600","24.36077","0.01463"
"292.67400","24.38976","0.01508"
"293.02200","24.41870","0.01504"
"293.37000","24.44776","0.01506"
"293.71800","24.47670","0.01507"
"294.06600","24.50570","0.01575"
"294.41400","24.53475","0.01547"
"294.76200","24.56369","0.01570"
"295.11000","24.59281","0.01638"
"295.45800","24.62169","0.01604"
"295.80600","24.65069","0.01601"
"296.15400","24.67974","0.01630"
"296.50200","24.70874","0.01671"
"296.85000","24.73774","0.01584"
"297.19800","24.76674","0.01603"
"297.54600","24.79574","0.01649"
"297.89400","24.82474","0.01600"
"298.24200","24.85373","0.01660"
"298.59000","24.88273","0.01643"
"298.93800","24.91167","0.01653"
"299.28600","24.94078","0.01673"
"299.63400","24.96972","0.01681"
"299.98200","24.99872","0.01666"
"300.33000","25.02772","0.01704"
"300.67800","25.05666","0.01713"
"301.02600","25.08571","0.01722"
"301.37400","25.11477","0.01707"
"301.72200","25.14371","0.01729"
"302.07000","25.17271","0.01773"
"302.41800","25.20177","0.01736"
"302.76600","25.23070","0.01797"
"303.11400","25.25976","0.01806"
"303.46200","25.28876","0.01776"
"303.81000","25.31770","0.01802"
"304.15800","25.34676","0.01803"
"304.50600","25.37576","0.01823"
"304.85400","25.40469","0.01880"
"305.20200","25.43375","0.01927"
"305.55000","25.46269","0.01892"
"305.89800","25.49174","0.01892"
"306.24600","25.52074","0.01952"
"306.59400","25.54968","0.01947"
"306.94200","25.57868","0.01977"
"307.29000","25.60774","0.01962"
"307.63800","25.63667","0.01942"
"307.98600","25.66573","0.01965"
"308.33400","25.69479","0.01952"
"308.68200","25.72367","0.01943"
"309.03000","25.75279","0.01987"
"309.37800","25.78178","0.01463"
"309.72600","25.81067","0.01489"
"310.07400","25.83972","0.01523"
"310.42200","25.86872","0.01497"
"310.77000","25.89771","0.01552"
"311.11800","25.92677","0.01626"
"311.46600","25.95572","0.01607"
"311.81400","25.98471","0.01633"
"312.16200","26.01371","0.01580"
"312.51000","26.04271","0.01647"
"312.85800","26.07176","0.01656"
"313.20600","26.10076","0.01651"
"313.55400","26.12970","0.01625"
"313.90200","26.15876","0.01713"
"314.25000","26.18776","0.01701"
"314.59800","26.21669","0.01698"
"314.94600","26.24575","0.01766"
"315.29400","26.27475","0.01742"
"315.64200","26.30375","0.01735"
"315.99000","26.33274","0.01753"
"316.33800","26.36174","0.01802"
"316.68600","26.39074","0.01763"
"317.03400","26.41974","0.01642"
"317.38200","26.44874","0.01749"
"317.73000","26.47773","0.01719"
"318.07800","26.50679","0.01752"
"318.42600","26.53567","0.01727"
"318.77400","26.56473","0.01768"
"319.12200","26.59373","0.01739"
"319.47000","26.62267","0.01778"
"319.81800","26.65178","0.01771"
"320.16600","26.68072","0.01855"
"320.51400","26.70966","0.01757"
"320.86200","26.73878","0.01811"
"321.21000","26.76777","0.01806"
"321.55800","26.79671","0.01855"
"321.90600","26.82571","0.01808"
"322.25400","26.85471","0.01804"
"322.60200","26.88371","0.01862"
"322.95000","26.91276","0.01840"
"323.29800","26.94170","0.01881"
"323.64600","26.97070","0.01901"
"323.99400","26.99976","0.01917"
"324.34200","27.02869","0.01910"
"324.69000","27.05775","0.01892"
"325.03800","27.08675","0.01922"
"325.38600","27.11569","0.01763"
"325.73400","27.14469","0.01834"
"326.08200","27.17375","0.01903"
"326.43000","27.20268","0.01861"
"326.77800","27.23174","0.01875"
"327.12600","27.26080","0.01897"
"327.47400","27.28968","0.01913"
"327.82200","27.31879","0.01786"
"328.17000","27.34767","0.01815"
"328.51800","27.37673","0.01840"
"328.86600","27.40573","0.01838"
"329.21400","27.43467","0.01759"
"329.56200","27.46378","0.01782"
"329.91000","27.49272","0.01786"
"330.25800","27.52166","0.01786"
"330.60600","27.55072","0.01772"
"330.95400","27.57978","0.01827"
"331.30200","27.60877","0.01804"
"331.65000","27.63771","0.01831"
"331.99800","27.66677","0.01894"
"332.34600","27.69571","0.01876"
"332.69400","27.72471","0.01855"
"333.04200","27.75370","0.01875"
"333.39000","27.78264","0.01893"
"333.73800","27.81176","0.01795"
"334.08600","27.84076","0.01875"
"334.43400","27.86975","0.01842"
"334.78200","27.89875","0.01831"
"335.13000","27.92769","0.01772"
"335.47800","27.95675","0.01853"
"335.82600","27.98575","0.01785"
"336.17400","28.01474","0.01863"
"336.52200","28.04368","0.01794"
"336.87000","28.07274","0.01814"
"337.21800","28.10168","0.01677"
"337.56600","28.13074","0.01748"
"337.91400","28.15973","0.01753"
"338.26200","28.18873","0.01763"
"338.61000","28.21779","0.01793"
"338.95800","28.24673","0.01796"
"339.30600","28.27573","0.01778"
"339.65400","28.30473","0.01690"
"340.00200","28.33372","0.01211"
"340.35000","28.36272","0.01200"
"340.69800","28.39172","0.01354"
"341.04600","28.42072","0.01181"
"341.39400","28.44971","0.01254"
"341.74200","28.47877","0.01358"
"342.09000","28.50771","0.01352"
"342.43800","28.53671","0.01244"
"342.78600","28.56577","0.01347"
"343.13400","28.59464","0.01335"
"343.48200","28.62376","0.01355"
"343.83000","28.65276","0.01336"
"344.17800","28.68170","0.01353"
"344.52600","28.71076","0.01380"
"344.87400","28.73969","0.01338"
"345.22200","28.76869","0.01374"
"345.57000","28.79781","0.01322"
"345.91800","28.82669","0.01447"
"346.26600","28.85568","0.01383"
"346.61400","28.88474","0.01404"
"346.96200","28.91374","0.01372"
"347.31000","28.94274","0.01421"
"347.65800","28.97180","0.01441"
"348.00600","29.00068","0.01453"
"348.35400","29.02973","0.01370"
"348.70200","29.05879","0.01433"
"349.05000","29.08773","0.01392"
"349.39800","29.11673","0.01454"
"349.74600","29.14572","0.01451"
"350.09400","29.17472","0.01452"
"350.44200","29.20372","0.01474"
"350.79000","29.23272","0.01462"
"351.13800","29.26171","0.01483"
"351.48600","29.29071","0.01490"
"351.83400","29.31971","0.01517"
"352.18200","29.34871","0.01548"
"352.53000","29.37777","0.01487"
"352.87800","29.40664","0.01531"
"353.22600","29.43570","0.01517"
"353.57400","29.46476","0.01522"
"353.92200","29.49364","0.01494"
"354.27000","29.52276","0.01528"
"354.61800","29.55176","0.01568"
"354.96600","29.58069","0.01571"
"355.31400","29.60975","0.01572"
"355.66200","29.63875","0.01591"
"356.01000","29.66769","0.01574"
"356.35800","29.69668","0.01567"
"356.70600","29.72574","0.01602"
"357.05400","29.75474","0.01582"
"357.40200","29.78380","0.01586"
"357.75000","29.81268","0.01614"
"358.09800","29.84167","0.01622"
"358.44600","29.87073","0.01597"
"358.79400","29.89961","0.01583"
"359.14200","29.92873","0.01654"
"359.49000","29.95773","0.01633"
"359.83800","29.98672","0.01648"
"360.18600","30.01572","0.01662"
"360.53400","30.04478","0.01641"
"360.88200","30.07366","0.01664"
"361.23000","30.10271","0.01639"
"361.57800","30.13177","0.01692"
"361.92600","30.16071","0.01695"
"362.27400","30.18977","0.01700"
"362.62200","30.21871","0.01708"
"362.97000","30.24770","0.01702"
"363.31800","30.27676","0.01709"
"363.66600","30.30570","0.01714"
"364.01400","30.33476","0.01744"
"364.36200","30.36370","0.01698"
"364.71000","30.39269","0.01737"
"365.05800","30.42169","0.01782"
"365.40600","30.45075","0.01765"
"365.75400","30.47969","0.01752"
"366.10200","30.50875","0.01765"
"366.45000","30.53774","0.01796"
"366.79800","30.56668","0.01776"
"367.14600","30.59574","0.01750"
"367.49400","30.62474","0.01835"
"367.84200","30.65368","0.01785"
"368.19000","30.68274","0.01807"
"368.53800","30.71173","0.01788"
"368.88600","30.74073","0.01832"
"369.23400","30.76973","0.01861"
"369.58200","30.79873","0.01877"
"369.93000","30.82772","0.01907"
"370.27800","30.85678","0.01817"
"370.62600","30.88572","0.01862"
"370.97400","30.91466","0.01870"
"371.32200","30.94371","0.01866"
"371.67000","30.97265","0.01835"
"372.01800","31.00177","0.01821"
"372.36600","31.03077","0.01918"
"372.71400","31.05971","0.01910"
"373.06200","31.08877","0.01856"
"373.41000","31.11776","0.01880"
"373.75800","31.14670","0.01857"
"374.10600","31.17576","0.01870"
"374.45400","31.20475","0.01895"
"374.80200","31.23369","0.01888"
"375.15000","31.26275","0.01865"
"375.49800","31.29175","0.01927"
"375.84600","31.32069","0.01899"
"376.19400","31.34980","0.01931"
"376.54200","31.37868","0.01913"
"376.89000","31.40774","0.01884"
"377.23800","31.43674","0.01933"
"377.58600","31.46568","0.01936"
"377.93400","31.49473","0.01918"
"378.28200","31.52373","0.01915"
"378.63000","31.55267","0.01971"
"378.97800","31.58179","0.01939"
"379.32600","31.61072","0.01937"
"379.67400","31.63967","0.01955"
"380.02200","31.66872","0.01962"
"380.37000","31.69778","0.01974"
"380.71800","31.72672","0.01983"
"381.06600","31.75578","0.01983"
"381.41400","31.78471","0.01997"
"381.76200","31.81371","0.02018"
"382.11000","31.84277","0.02037"
"382.45800","31.87165","0.02053"
"382.80600","31.90076","0.02074"
"383.15400","31.92976","0.02055"
"383.50200","31.95876","0.02011"
"383.85000","31.98770","0.02092"
"384.19800","32.01669","0.02065"
"384.54600","32.04576","0.02014"
"384.89400","32.07475","0.01921"
"385.24200","32.10375","0.02029"
"385.59000","32.13269","0.02022"
"385.93800","32.16175","0.01938"
"386.28600","32.19069","0.02006"
"386.63400","32.21974","0.01978"
"386.98200","32.24880","0.02009"
"387.33000","32.27768","0.02035"
"387.67800","32.30674","0.02040"
"388.02600","32.33573","0.02013"
"388.37400","32.36473","0.01868"
"388.72200","32.39373","0.01734"
"389.07000","32.42273","0.01802"
"389.41800","32.45173","0.01796"
"389.76600","32.48079","0.01841"
"390.11400","32.50978","0.01815"
"390.46200","32.53866","0.01825"
"390.81000","32.56772","0.01830"
"391.15800","32.59671","0.01844"
"391.50600","32.62565","0.01854"
"391.85400","32.65477","0.01889"
"392.20200","32.68371","0.01884"
"392.55000","32.71276","0.01898"
"392.89800","32.74176","0.01900"
"393.24600","32.77070","0.01873"
"393.59400","32.79976","0.01952"
"393.94200","32.82870","0.01904"
"394.29000","32.85770","0.01947"
"394.63800","32.88675","0.01922"
"394.98600","32.91575","0.01947"
"395.33400","32.94469","0.01999"
"395.68200","32.97375","0.01975"
"396.03000","33.00275","0.01856"
"396.37800","33.03168","0.01810"
"396.72600","33.06074","0.01872"
"397.07400","33.08962","0.01897"
"397.42200","33.11868","0.01907"
"397.77000","33.14773","0.01849"
"398.11800","33.17673","0.01887"
"398.46600","33.20567","0.01861"
"398.81400","33.23473","0.01924"
"399.16200","33.26373","0.01965"
"399.51000","33.29272","0.01962"
"399.85800","33.32178","0.01916"
"400.20600","33.35072","0.01903"
"400.55400","33.37972","0.01925"
"400.90200","33.40878","0.01914"
"401.25000","33.43765","0.01873"
"401.59800","33.46677","0.01903"
"401.94600","33.49577","0.01918"
"402.29400","33.52465","0.01912"
"402.64200","33.55376","0.01922"
"402.99000","33.58277","0.01937"
"403.33800","33.61170","0.01968"
"403.68600","33.64076","0.01922"
"404.03400","33.66976","0.01960"
"404.38200","33.69870","0.01954"
"404.73000","33.72775","0.01956"
"405.07800","33.75669","0.01976"
"405.42600","33.78569","0.01939"
"405.77400","33.81475","0.01962"
"406.12200","33.84369","0.01939"
"406.47000","33.87274","0.01971"
"406.81800","33.90174","0.01993"
"407.16600","33.93068","0.02028"
"407.51400","33.95974","0.02006"
"407.86200","33.98874","0.01961"
"408.21000","34.01773","0.02046"
"408.55800","34.04673","0.02027"
"408.90600","34.07573","0.02033"
"409.25400","34.10467","0.02081"
"409.60200","34.13372","0.02083"
"409.95000","34.16272","0.02096"
"410.29800","34.19166","0.02035"
"410.64600","34.22078","0.02065"
"410.99400","34.24966","0.02087"
"411.34200","34.27877","0.02130"
"411.69000","34.30777","0.02143"
"412.03800","34.33665","0.02114"
"412.38600","34.36577","0.02145"
"412.73400","34.39477","0.02214"
"413.08200","34.42371","0.02150"
"413.43000","34.45276","0.02151"
"413.77800","34.48176","0.02201"
"414.12600","34.51070","0.02192"
"414.47400","34.53976","0.02166"
"414.82200","34.56875","0.02178"
"415.17000","34.59769","0.02087"
"415.51800","34.62675","0.02203"
"415.86600","34.65569","0.02207"
"416.21400","34.68474","0.02221"
"416.56200","34.71374","0.02201"
"416.91000","34.74268","0.02199"
"417.25800","34.77174","0.02173"
"417.60600","34.80080","0.02194"
"417.95400","34.82968","0.02187"
"418.30200","34.85873","0.02199"
"418.65000","34.88779","0.02172"
"418.99800","34.91667","0.02054"
"419.34600","34.94579","0.01954"
"419.69400","34.97478","0.01837"
"420.04200","35.00366","0.01762"
"420.39000","35.03278","0.01761"
"420.73800","35.06172","0.01810"
"421.08600","35.09066","0.01822"
"421.43400","35.11977","0.01730"
"421.78200","35.14871","0.01815"
"422.13000","35.17771","0.01801"
"422.47800","35.20671","0.01839"
"422.82600","35.23571","0.01811"
"423.17400","35.26476","0.01780"
"423.52200","35.29376","0.01765"
"423.87000","35.32270","0.01805"
"424.21800","35.35170","0.01796"
"424.56600","35.38076","0.01842"
"424.91400","35.40963","0.01868"
"425.26200","35.43875","0.01833"
"425.61000","35.46775","0.01798"
"425.95800","35.49675","0.01822"
"426.30600","35.52574","0.01863"
"426.65400","35.55474","0.01825"
"427.00200","35.58368","0.01915"
"427.35000","35.61274","0.01884"
"427.69800","35.64174","0.01883"
"428.04600","35.67068","0.01875"
"428.39400","35.69973","0.01866"
"428.74200","35.72873","0.01872"
"429.09000","35.75773","0.01895"
"429.43800","35.78679","0.01922"
"429.78600","35.81566","0.01918"
"430.13400","35.84478","0.01946"
"430.48200","35.87378","0.01947"
"430.83000","35.90272","0.01913"
"431.17800","35.93178","0.01923"
"431.52600","35.96072","0.01943"
"431.87400","35.98971","0.01966"
"432.22200","36.01877","0.01998"
"432.57000","36.04771","0.01979"
"432.91800","36.07671","0.01975"
"433.26600","36.10571","0.01998"
"433.61400","36.13476","0.01977"
"433.96200","36.16376","0.02046"
"434.31000","36.19276","0.01931"
"434.65800","36.22169","0.01954"
"435.00600","36.25069","0.01985"
"435.35400","36.27969","0.01936"
"435.70200","36.30869","0.02038"
"436.05000","36.33775","0.01996"
"436.39800","36.36674","0.02017"
"436.74600","36.39574","0.02010"
"437.09400","36.42474","0.02021"
"437.44200","36.45374","0.02030"
"437.79000","36.48273","0.02042"
"438.13800","36.51180","0.02054"
"438.48600","36.54073","0.02027"
"438.83400","36.56973","0.02074"
"439.18200","36.59879","0.02097"
"439.53000","36.62767","0.02086"
"439.87800","36.65672","0.02103"
"440.22600","36.68572","0.02078"
"440.57400","36.71466","0.02051"
"440.92200","36.74378","0.01928"
"441.27000","36.77272","0.01977"
"441.61800","36.80172","0.01983"
"441.96600","36.83077","0.01971"
"442.31400","36.85971","0.02028"
"442.66200","36.88865","0.02060"
"443.01000","36.91771","0.02008"
"443.35800","36.94670","0.02045"
"443.70600","36.97570","0.02003"
"444.05400","37.00476","0.02046"
"444.40200","37.03376","0.02035"
"444.75000","37.06269","0.02090"
"445.09800","37.09175","0.02086"
"445.44600","37.12069","0.02096"
"445.79400","37.14975","0.02130"
"446.14200","37.17881","0.02143"
"446.49000","37.20768","0.02110"
"446.83800","37.23674","0.02104"
"447.18600","37.26574","0.02086"
"447.53400","37.29468","0.02104"
"447.88200","37.32373","0.02159"
"448.23000","37.35279","0.02101"
"448.57800","37.38167","0.02140"
"448.92600","37.41079","0.02140"
"449.27400","37.43973","0.02152"
"449.62200","37.46867","0.02171"
"449.97000","37.49772","0.02157"
"450.31800","37.52672","0.02121"
"450.66600","37.55572","0.02047"
"451.01400","37.58472","0.02036"
"451.36200","37.61372","0.01576"
"451.71000","37.64277","0.01387"
"452.05800","37.67171","0.01652"
"452.40600","37.70071","0.01454"
"452.75400","37.72971","0.01434"
"453.10200","37.75876","0.01593"
"453.45000","37.78776","0.01495"
"453.79800","37.81676","0.01551"
"454.14600","37.84576","0.01561"
"454.49400","37.87463","0.01605"
"454.84200","37.90376","0.01526"
"455.19000","37.93275","0.01572"
"455.53800","37.96169","0.01534"
"455.88600","37.99075","0.01589"
"456.23400","38.01969","0.01593"
"456.58200","38.04874","0.01586"
"456.93000","38.07774","0.01541"
"457.27800","38.10674","0.01561"
"457.62600","38.13574","0.01587"
"457.97400","38.16479","0.01584"
"458.32200","38.19367","0.01605"
"458.67000","38.22273","0.01589"
"459.01800","38.25173","0.01599"
"459.36600","38.28067","0.01661"
"459.71400","38.30973","0.01662"
"460.06200","38.33873","0.01685"
"460.41000","38.36772","0.01631"
"460.75800","38.39672","0.01648"
"461.10600","38.42572","0.01667"
"461.45400","38.45472","0.01664"
"461.80200","38.48377","0.01677"
"462.15000","38.51277","0.01667"
"462.49800","38.54171","0.01696"
"462.84600","38.57071","0.01675"
"463.19400","38.59970","0.01749"
"463.54200","38.62870","0.01709"
"463.89000","38.65782","0.01689"
"464.23800","38.68664","0.01722"
"464.58600","38.71576","0.01750"
"464.93400","38.74475","0.01766"
"465.28200","38.77369","0.01762"
"465.63000","38.80275","0.01733"
"465.97800","38.83169","0.01694"
"466.32600","38.86069","0.01734"
"466.67400","38.88974","0.01708"
"467.02200","38.91874","0.01690"
"467.37000","38.94774","0.01678"
"467.71800","38.97674","0.01753"
"468.06600","39.00568","0.01700"
"468.41400","39.03473","0.01702"
"468.76200","39.06379","0.01745"
"469.11000","39.09267","0.01720"
"469.45800","39.12173","0.01718"
"469.80600","39.15079","0.01769"
"470.15400","39.17966","0.01750"
"470.50200","39.20872","0.01798"
"470.85000","39.23778","0.01759"
"471.19800","39.26665","0.01768"
"471.54600","39.29577","0.01788"
"471.89400","39.32477","0.01772"
"472.24200","39.35371","0.01757"
"472.59000","39.38271","0.01459"
"472.93800","39.41177","0.01563"
"473.28600","39.44070","0.01494"
"473.63400","39.46976","0.01405"
"473.98200","39.49870","0.01490"
"474.33000","39.52770","0.01469"
"474.67800","39.55676","0.01430"
"475.02600","39.58569","0.01486"
"475.37400","39.61475","0.01484"
"475.72200","39.64368","0.01501"
"476.07000","39.67269","0.01525"
"476.41800","39.70169","0.01510"
"476.76600","39.73080","0.01531"
"477.11400","39.75968","0.01488"
"477.46200","39.78867","0.01532"
"477.81000","39.81773","0.01567"
"478.15800","39.84673","0.01513"
"478.50600","39.87574","0.01585"
"478.85400","39.90473","0.01539"
"479.20200","39.93373","0.01595"
"479.55000","39.96272","0.01602"
"479.89800","39.99172","0.01509"
"480.24600","40.02072","0.01448"
"480.59400","40.04972","0.01499"
"480.94200","40.07872","0.01501"
"481.29000","40.10771","0.01508"
"481.63800","40.13677","0.01495"
"481.98600","40.16565","0.01578"
"482.33400","40.19471","0.01519"
"482.68200","40.22377","0.01515"
"483.03000","40.25264","0.01531"
"483.37800","40.28176","0.01477"
"483.72600","40.31076","0.01503"
"484.07400","40.33970","0.01542"
"484.42200","40.36881","0.01596"
"484.77000","40.39775","0.01522"
"485.11800","40.42669","0.01531"
"485.46600","40.45569","0.01541"
"485.81400","40.48469","0.01553"
"486.16200","40.51375","0.01594"
"486.51000","40.54268","0.01628"
"486.85800","40.57168","0.01591"
"487.20600","40.60068","0.01612"
"487.55400","40.62973","0.01616"
"487.90200","40.65873","0.01580"
"488.25000","40.68779","0.01604"
"488.59800","40.71673","0.01603"
"488.94600","40.74567","0.01576"
"489.29400","40.77473","0.01613"
"489.64200","40.80372","0.01615"
"489.99000","40.83273","0.01602"
"490.33800","40.86172","0.01628"
"490.68600","40.89078","0.01594"
"491.03400","40.91971","0.01619"
"491.38200","40.94877","0.01624"
"491.73000","40.97771","0.01580"
"492.07800","41.00671","0.01540"
"492.42600","41.03577","0.01580"
"492.77400","41.06464","0.01564"
"493.12200","41.09377","0.01578"
"493.47000","41.12270","0.01614"
"493.81800","41.15164","0.01587"
"494.16600","41.18076","0.01608"
"494.51400","41.20976","0.01554"
"494.86200","41.23870","0.01562"
"495.21000","41.26781","0.01587"
"495.55800","41.29675","0.01593"
"495.90600","41.32569","0.01582"
"496.25400","41.35474","0.01607"
"496.60200","41.38374","0.01601"
"496.95000","41.41268","0.01563"
"497.29800","41.44180","0.01568"
"497.64600","41.47074","0.01602"
"497.99400","41.49968","0.01612"
"498.34200","41.52874","0.01621"
"498.69000","41.55767","0.01567"
"499.03800","41.58673","0.01472"
"499.38600","41.61578","0.01517"
"499.73400","41.64473","0.01365"
"500.08200","41.67373","0.01482"
"500.43000","41.70272","0.01456"
"500.77800","41.73166","0.01450"
"501.12600","41.76071","0.01462"
"501.47400","41.78971","0.01449"
"501.82200","41.81871","0.01431"
"502.17000","41.84777","0.01454"
"502.51800","41.87671","0.01445"
"502.86600","41.90571","0.01491"
"503.21400","41.93476","0.01452"
"503.56200","41.96370","0.01506"
"503.91000","41.99276","0.01519"
"504.25800","42.02176","0.01476"
"504.60600","42.05070","0.01528"
"504.95400","42.07969","0.01529"
"505.30200","42.10869","0.01493"
"505.65000","42.13769","0.01522"
"505.99800","42.16669","0.01501"
"506.34600","42.19580","0.01514"
"506.69400","42.22468","0.01529"
"507.04200","42.25374","0.01519"
"507.39000","42.28274","0.01544"
"507.73800","42.31168","0.01557"
"508.08600","42.34080","0.01577"
"508.43400","42.36974","0.01572"
"508.78200","42.39867","0.01524"
"509.13000","42.42773","0.01497"
"509.47800","42.45673","0.01553"
"509.82600","42.48573","0.01481"
"510.17400","42.51472","0.01528"
"510.52200","42.54372","0.01528"
"510.87000","42.57277","0.01502"
"511.21800","42.60177","0.01478"
"511.56600","42.63065","0.01506"
"511.91400","42.65971","0.01545"
"512.26200","42.68871","0.01543"
"512.61000","42.71771","0.01540"
"512.95800","42.74677","0.01552"
"513.30600","42.77571","0.01575"
"513.65400","42.80476","0.01554"
"514.00200","42.83376","0.01627"
"514.35000","42.86276","0.01567"
"514.69800","42.89175","0.01552"
"515.04600","42.92075","0.01578"
"515.39400","42.94975","0.01564"
"515.74200","42.97875","0.01560"
"515.92000","42.99352","0.01598"