File: Force_trajectories/161216/Specimen_RawData_6.csv
End date,"12/16/2016"
Specimen label,"15BT_19"
Maximum Load,"0.60469",N

Time,Extension,Load
(s),(mm),(N)
"0.00000","0.00000","-0.00005"
"0.25200","0.01973","0.00021"
"0.50400","0.04227","0.00086"
"0.75600","0.06320","0.00082"
"1.00800","0.08418","0.00051"
"1.26000","0.10529","0.00069"
"1.51200","0.12616","0.00091"
"1.76400","0.14720","0.00126"
"2.01600","0.16819","0.00088"
"2.26800","0.18917","0.00049"
"2.52000","0.21016","0.00131"
"2.77200","0.23121","0.00099"
"3.02400","0.25219","0.00101"
"3.27600","0.27318","0.00124"
"3.52800","0.29422","0.00079"
"3.78000","0.31515","0.00171"
"4.03200","0.33620","0.00210"
"4.28400","0.35712","0.00113"
"4.53600","0.37817","0.00147"
"4.78800","0.39915","0.00168"
"5.04000","0.42020","0.00165"
"5.29200","0.44119","0.00134"
"5.54400","0.46223","0.00151"
"5.79600","0.48316","0.00121"
"6.04800","0.50415","0.00151"
"6.30000","0.52513","0.00155"
"6.55200","0.54618","0.00154"
"6.80400","0.56716","0.00186"
"7.05600","0.58815","0.00210"
"7.30800","0.60920","0.00179"
"7.56000","0.63018","0.00124"
"7.81200","0.65117","0.00284"
"8.06400","0.67215","0.00182"
"8.31600","0.69320","0.00200"
"8.56800","0.71419","0.00155"
"8.82000","0.73517","0.00242"
"9.07200","0.75616","0.00218"
"9.32400","0.77726","0.00206"
"9.57600","0.79819","0.00233"
"9.82800","0.81918","0.00251"
"10.08000","0.84022","0.00178"
"10.33200","0.86115","0.00168"
"10.58400","0.88219","0.00193"
"10.83600","0.90318","0.00183"
"11.08800","0.92417","0.00228"
"11.34000","0.94521","0.00211"
"11.59200","0.96626","0.00212"
"11.84400","0.98713","0.00240"
"12.09600","1.00823","0.00238"
"12.34800","1.02910","0.00257"
"12.60000","1.05020","0.00303"
"12.85200","1.07113","0.00205"
"13.10400","1.09218","0.00197"
"13.35600","1.11316","0.00244"
"13.60800","1.13421","0.00244"
"13.86000","1.15519","0.00252"
"14.11200","1.17618","0.00207"
"14.36400","1.19723","0.00209"
"14.61600","1.21821","0.00178"
"14.86800","1.23920","0.00207"
"15.12000","1.26012","0.00250"
"15.37200","1.28123","0.00232"
"15.62400","1.30216","0.00250"
"15.87600","1.32320","0.00226"
"16.12800","1.34413","0.00262"
"16.38000","1.36517","0.00247"
"16.63200","1.38616","0.00255"
"16.88400","1.40721","0.00281"
"17.13600","1.42813","0.00275"
"17.38800","1.44924","0.00255"
"17.64000","1.47016","0.00282"
"17.89200","1.49121","0.00249"
"18.14400","1.51226","0.00282"
"18.39600","1.53318","0.00276"
"18.64800","1.55423","0.00279"
"18.90000","1.57516","0.00292"
"19.15200","1.59620","0.00242"
"19.40400","1.61713","0.00292"
"19.65600","1.63823","0.00263"
"19.90800","1.65922","0.00297"
"20.16000","1.68021","0.00293"
"20.41200","1.70113","0.00319"
"20.66400","1.72218","0.00304"
"20.91600","1.74316","0.00329"
"21.16800","1.76421","0.00289"
"21.42000","1.78514","0.00286"
"21.67200","1.80618","0.00319"
"21.92400","1.82717","0.00262"
"22.17600","1.84815","0.00319"
"22.42800","1.86920","0.00288"
"22.68000","1.89019","0.00315"
"22.93200","1.91123","0.00315"
"23.18400","1.93216","0.00323"
"23.43600","1.95320","0.00312"
"23.68800","1.97413","0.00301"
"23.94000","1.99524","0.00302"
"24.19200","2.01616","0.00276"
"24.44400","2.03715","0.00330"
"24.69600","2.05814","0.00313"
"24.94800","2.07924","0.00257"
"25.20000","2.10017","0.00258"
"25.45200","2.12121","0.00299"
"25.70400","2.14220","0.00303"
"25.95600","2.16319","0.00307"
"26.20800","2.18417","0.00334"
"26.46000","2.20522","0.00311"
"26.71200","2.22614","0.00331"
"26.96400","2.24713","0.00360"
"27.21600","2.26818","0.00342"
"27.46800","2.28916","0.00320"
"27.72000","2.31021","0.00340"
"27.97200","2.33113","0.00353"
"28.22400","2.35224","0.00358"
"28.47600","2.37317","0.00314"
"28.72800","2.39421","0.00307"
"28.98000","2.41520","0.00351"
"29.23200","2.43618","0.00379"
"29.48400","2.45717","0.00357"
"29.73600","2.47816","0.00337"
"29.98800","2.49914","0.00383"
"30.24000","2.52019","0.00319"
"30.49200","2.54117","0.00336"
"30.74400","2.56216","0.00341"
"30.99600","2.58321","0.00363"
"31.24800","2.60413","0.00335"
"31.50000","2.62518","0.00334"
"31.75200","2.64611","0.00342"
"32.00400","2.66715","0.00324"
"32.25600","2.68820","0.00338"
"32.50800","2.70918","0.00308"
"32.76000","2.73017","0.00331"
"33.01200","2.75122","0.00376"
"33.26400","2.77214","0.00385"
"33.51600","2.79319","0.00376"
"33.76800","2.81417","0.00388"
"34.02000","2.83516","0.00369"
"34.27200","2.85621","0.00390"
"34.52400","2.87719","0.00334"
"34.77600","2.89824","0.00391"
"35.02800","2.91916","0.00389"
"35.28000","2.94021","0.00403"
"35.53200","2.96114","0.00430"
"35.78400","2.98218","0.00368"
"36.03600","3.00311","0.00411"
"36.28800","3.02421","0.00361"
"36.54000","3.04514","0.00383"
"36.79200","3.06619","0.00416"
"37.04400","3.08717","0.00355"
"37.29600","3.10822","0.00373"
"37.54800","3.12914","0.00377"
"37.80000","3.15013","0.00380"
"38.05200","3.17118","0.00416"
"38.30400","3.19222","0.00330"
"38.55600","3.21321","0.00387"
"38.80800","3.23419","0.00409"
"39.06000","3.25524","0.00442"
"39.31200","3.27617","0.00383"
"39.56400","3.29721","0.00418"
"39.81600","3.31808","0.00372"
"40.06800","3.33919","0.00381"
"40.32000","3.36017","0.00414"
"40.57200","3.38122","0.00417"
"40.82400","3.40220","0.00397"
"41.07600","3.42319","0.00450"
"41.32800","3.44418","0.00425"
"41.58000","3.46522","0.00447"
"41.83200","3.48615","0.00401"
"42.08400","3.50719","0.00416"
"42.33600","3.52818","0.00444"
"42.58800","3.54917","0.00398"
"42.84000","3.57015","0.00411"
"43.09200","3.59120","0.00410"
"43.34400","3.61224","0.00446"
"43.59600","3.63317","0.00431"
"43.84800","3.65416","0.00406"
"44.10000","3.67508","0.00435"
"44.35200","3.69619","0.00416"
"44.60400","3.71718","0.00435"
"44.85600","3.73822","0.00399"
"45.10800","3.75915","0.00434"
"45.36000","3.78025","0.00483"
"45.61200","3.80118","0.00442"
"45.86400","3.82217","0.00436"
"46.11600","3.84321","0.00416"
"46.36800","3.86414","0.00456"
"46.62000","3.88518","0.00416"
"46.87200","3.90617","0.00457"
"47.12400","3.92722","0.00388"
"47.37600","3.94814","0.00458"
"47.62800","3.96925","0.00432"
"47.88000","3.99017","0.00434"
"48.13200","4.01116","0.00434"
"48.38400","4.03209","0.00438"
"48.63600","4.05325","0.00477"
"48.88800","4.07418","0.00476"
"49.14000","4.09516","0.00400"
"49.39200","4.11609","0.00469"
"49.64400","4.13720","0.00461"
"49.89600","4.15818","0.00454"
"50.14800","4.17917","0.00469"
"50.40000","4.20021","0.00427"
"50.65200","4.22114","0.00426"
"50.90400","4.24219","0.00425"
"51.15600","4.26317","0.00420"
"51.40800","4.28422","0.00485"
"51.66000","4.30515","0.00459"
"51.91200","4.32619","0.00439"
"52.16400","4.34712","0.00424"
"52.41600","4.36816","0.00472"
"52.66800","4.38915","0.00473"
"52.92000","4.41026","0.00447"
"53.17200","4.43118","0.00472"
"53.42400","4.45223","0.00488"
"53.67600","4.47315","0.00521"
"53.92800","4.49420","0.00520"
"54.18000","4.51513","0.00505"
"54.43200","4.53623","0.00542"
"54.68400","4.55722","0.00510"
"54.93600","4.57820","0.00517"
"55.18800","4.59925","0.00511"
"55.44000","4.62012","0.00532"
"55.69200","4.64122","0.00524"
"55.94400","4.66221","0.00500"
"56.19600","4.68319","0.00559"
"56.44800","4.70412","0.00534"
"56.70000","4.72517","0.00564"
"56.95200","4.74615","0.00520"
"57.20400","4.76726","0.00559"
"57.45600","4.78819","0.00513"
"57.70800","4.80917","0.00581"
"57.96000","4.83016","0.00560"
"58.21200","4.85120","0.00600"
"58.46400","4.87219","0.00637"
"58.71600","4.89312","0.00585"
"58.96800","4.91422","0.00618"
"59.22000","4.93515","0.00580"
"59.47200","4.95619","0.00590"
"59.72400","4.97718","0.00649"
"59.97600","4.99817","0.00630"
"60.22800","5.01909","0.00668"
"60.48000","5.04020","0.00655"
"60.73200","5.06118","0.00661"
"60.98400","5.08223","0.00640"
"61.23600","5.10316","0.00626"
"61.48800","5.12420","0.00660"
"61.74000","5.14519","0.00682"
"61.99200","5.16617","0.00666"
"62.24400","5.18716","0.00717"
"62.49600","5.20815","0.00704"
"62.74800","5.22919","0.00674"
"63.00000","5.25012","0.00702"
"63.25200","5.27122","0.00695"
"63.50400","5.29215","0.00700"
"63.75600","5.31320","0.00723"
"64.00800","5.33418","0.00770"
"64.26000","5.35523","0.00771"
"64.51200","5.37616","0.00761"
"64.76400","5.39720","0.00776"
"65.01600","5.41813","0.00757"
"65.26800","5.43923","0.00765"
"65.52000","5.46022","0.00807"
"65.77200","5.48121","0.00814"
"66.02400","5.50219","0.00817"
"66.27600","5.52318","0.00825"
"66.52800","5.54416","0.00835"
"66.78000","5.56515","0.00857"
"67.03200","5.58626","0.00892"
"67.28400","5.60718","0.00885"
"67.53600","5.62823","0.00952"
"67.78800","5.64915","0.00954"
"68.04000","5.67014","0.00960"
"68.29200","5.69119","0.00958"
"68.54400","5.71223","0.01004"
"68.79600","5.73316","0.01035"
"69.04800","5.75420","0.01062"
"69.30000","5.77519","0.01036"
"69.55200","5.79618","0.01076"
"69.80400","5.81710","0.01059"
"70.05600","5.83821","0.01079"
"70.30800","5.85925","0.01139"
"70.56000","5.88018","0.01058"
"70.81200","5.90123","0.01055"
"71.06400","5.92215","0.01160"
"71.31600","5.94320","0.01175"
"71.56800","5.96419","0.01163"
"71.82000","5.98523","0.01259"
"72.07200","6.00616","0.01260"
"72.32400","6.02720","0.01322"
"72.57600","6.04813","0.01357"
"72.82800","6.06918","0.01401"
"73.08000","6.09010","0.01406"
"73.33200","6.11121","0.01413"
"73.58400","6.13225","0.01448"
"73.83600","6.15318","0.01511"
"74.08800","6.17417","0.01570"
"74.34000","6.19515","0.01620"
"74.59200","6.21620","0.01673"
"74.84400","6.23718","0.01675"
"75.09600","6.25823","0.01725"
"75.34800","6.27910","0.01779"
"75.60000","6.30020","0.01835"
"75.85200","6.32113","0.01908"
"76.10400","6.34217","0.01918"
"76.35600","6.36316","0.01990"
"76.60800","6.38427","0.02050"
"76.86000","6.40519","0.02080"
"77.11200","6.42618","0.02158"
"77.36400","6.44711","0.02187"
"77.61600","6.46821","0.02215"
"77.86800","6.48920","0.02276"
"78.12000","6.51018","0.02396"
"78.37200","6.53117","0.02423"
"78.62400","6.55216","0.02426"
"78.87600","6.57320","0.02528"
"79.12800","6.59413","0.02581"
"79.38000","6.61517","0.02543"
"79.63200","6.63616","0.02655"
"79.88400","6.65721","0.02701"
"80.13600","6.67819","0.02830"
"80.38800","6.69918","0.02890"
"80.64000","6.72016","0.02980"
"80.89200","6.74121","0.03128"
"81.14400","6.76214","0.03212"
"81.39600","6.78324","0.03333"
"81.64800","6.80423","0.03446"
"81.90000","6.82521","0.03520"
"82.15200","6.84620","0.03593"
"82.40400","6.86719","0.03756"
"82.65600","6.88817","0.03824"
"82.90800","6.90910","0.03895"
"83.16000","6.93020","0.03968"
"83.41200","6.95113","0.04037"
"83.66400","6.97218","0.04157"
"83.91600","6.99316","0.04244"
"84.16800","7.01421","0.04288"
"84.42000","7.03519","0.04314"
"84.67200","7.05624","0.04406"
"84.92400","7.07717","0.04501"
"85.17600","7.09821","0.04623"
"85.42800","7.11914","0.04703"
"85.68000","7.14019","0.04781"
"85.93200","7.16117","0.04827"
"86.18400","7.18222","0.04982"
"86.43600","7.20326","0.05066"
"86.68800","7.22419","0.05154"
"86.94000","7.24518","0.05252"
"87.19200","7.26616","0.05362"
"87.44400","7.28721","0.05448"
"87.69600","7.30814","0.05562"
"87.94800","7.32918","0.05766"
"88.20000","7.35011","0.05801"
"88.45200","7.37121","0.05843"
"88.70400","7.39214","0.06049"
"88.95600","7.41319","0.06117"
"89.20800","7.43417","0.06164"
"89.46000","7.45516","0.06253"
"89.71200","7.47620","0.06350"
"89.96400","7.49719","0.06479"
"90.21600","7.51818","0.06562"
"90.46800","7.53916","0.06634"
"90.72000","7.56021","0.06759"
"90.97200","7.58119","0.06837"
"91.22400","7.60224","0.06934"
"91.47600","7.62311","0.07034"
"91.72800","7.64421","0.07082"
"91.98000","7.66520","0.07225"
"92.23200","7.68624","0.07389"
"92.48400","7.70717","0.07526"
"92.73600","7.72822","0.07644"
"92.98800","7.74920","0.07844"
"93.24000","7.77025","0.07875"
"93.49200","7.79111","0.06358"
"93.74400","7.81210","0.06370"
"93.99600","7.83315","0.06627"
"94.24800","7.85419","0.06740"
"94.50000","7.87524","0.06870"
"94.75200","7.89616","0.06971"
"95.00400","7.91721","0.07175"
"95.25600","7.93814","0.07287"
"95.50800","7.95918","0.07520"
"95.76000","7.98017","0.07696"
"96.01200","8.00121","0.07759"
"96.26400","8.02220","0.07884"
"96.51600","8.04325","0.08065"
"96.76800","8.06411","0.08285"
"97.02000","8.08522","0.08481"
"97.27200","8.10620","0.08579"
"97.52400","8.12719","0.08630"
"97.77600","8.14818","0.08738"
"98.02800","8.16916","0.08813"
"98.28000","8.19021","0.08937"
"98.53200","8.21114","0.08993"
"98.78400","8.23218","0.09069"
"99.03600","8.25317","0.09096"
"99.28800","8.27421","0.09212"
"99.54000","8.29514","0.09251"
"99.79200","8.31619","0.09330"
"100.04400","8.33711","0.09383"
"100.29600","8.35822","0.09461"
"100.54800","8.37920","0.09534"
"100.80000","8.40019","0.09554"
"101.05200","8.42118","0.09648"
"101.30400","8.44216","0.09730"
"101.55600","8.46321","0.09790"
"101.80800","8.48413","0.09855"
"102.06000","8.50518","0.09873"
"102.31200","8.52617","0.09972"
"102.56400","8.54727","0.10027"
"102.81600","8.56820","0.10080"
"103.06800","8.58924","0.10134"
"103.32000","8.61011","0.10178"
"103.57200","8.63122","0.10292"
"103.82400","8.65214","0.10323"
"104.07600","8.67319","0.10349"
"104.32800","8.69418","0.10426"
"104.58000","8.71528","0.10544"
"104.83200","8.73615","0.10571"
"105.08400","8.75719","0.10618"
"105.33600","8.77818","0.10737"
"105.58800","8.79922","0.10780"
"105.84000","8.82021","0.10880"
"106.09200","8.84114","0.10888"
"106.34400","8.86218","0.11005"
"106.59600","8.88323","0.11099"
"106.84800","8.90422","0.11161"
"107.10000","8.92514","0.11272"
"107.35200","8.94619","0.11310"
"107.60400","8.96717","0.11376"
"107.85600","8.98816","0.11448"
"108.10800","9.00909","0.11488"
"108.36000","9.03019","0.11602"
"108.61200","9.05118","0.11744"
"108.86400","9.07222","0.11739"
"109.11600","9.09315","0.11866"
"109.36800","9.11420","0.11829"
"109.62000","9.13518","0.12007"
"109.87200","9.15623","0.12110"
"110.12400","9.17722","0.12164"
"110.37600","9.19820","0.12251"
"110.62800","9.21919","0.12364"
"110.88000","9.24017","0.12390"
"111.13200","9.26122","0.12474"
"111.38400","9.28215","0.12554"
"111.63600","9.30319","0.12740"
"111.88800","9.32418","0.12795"
"112.14000","9.34516","0.12893"
"112.39200","9.36615","0.13043"
"112.64400","9.38726","0.13302"
"112.89600","9.40818","0.13449"
"113.14800","9.42917","0.13531"
"113.40000","9.45021","0.13722"
"113.65200","9.47120","0.13860"
"113.90400","9.49225","0.14050"
"114.15600","9.51317","0.14164"
"114.40800","9.53422","0.14258"
"114.66000","9.55515","0.14395"
"114.91200","9.57619","0.14503"
"115.16400","9.59712","0.14588"
"115.41600","9.61822","0.14717"
"115.66800","9.63909","0.14865"
"115.92000","9.66019","0.14971"
"116.17200","9.68118","0.15030"
"116.42400","9.70217","0.15160"
"116.67600","9.72315","0.15318"
"116.92800","9.74420","0.15311"
"117.18000","9.76519","0.15508"
"117.43200","9.78617","0.15652"
"117.68400","9.80716","0.15924"
"117.93600","9.82820","0.15970"
"118.18800","9.84919","0.16137"
"118.44000","9.87018","0.16305"
"118.69200","9.89122","0.16402"
"118.94400","9.91215","0.16578"
"119.19600","9.93319","0.16742"
"119.44800","9.95412","0.16874"
"119.70000","9.97517","0.16998"
"119.95200","9.99615","0.17075"
"120.20400","10.01720","0.17158"
"120.45600","10.03812","0.17248"
"120.70800","10.05917","0.17403"
"120.96000","10.08016","0.17534"
"121.21200","10.10120","0.17551"
"121.46400","10.12219","0.17684"
"121.71600","10.14318","0.17784"
"121.96800","10.16422","0.17933"
"122.22000","10.18521","0.18051"
"122.47200","10.20619","0.18229"
"122.72400","10.22712","0.18328"
"122.97600","10.24823","0.18445"
"123.22800","10.26921","0.18580"
"123.48000","10.29020","0.18774"
"123.73200","10.31112","0.18956"
"123.98400","10.33217","0.19079"
"124.23600","10.35316","0.19266"
"124.48800","10.37420","0.19394"
"124.74000","10.39519","0.19498"
"124.99200","10.41623","0.19639"
"125.24400","10.43722","0.19835"
"125.49600","10.45815","0.20014"
"125.74800","10.47919","0.20146"
"126.00000","10.50018","0.20304"
"126.25200","10.52122","0.20466"
"126.50400","10.54215","0.20605"
"126.75600","10.56314","0.20732"
"127.00800","10.58412","0.20848"
"127.26000","10.60523","0.20960"
"127.51200","10.62615","0.21103"
"127.76400","10.64720","0.21280"
"128.01600","10.66819","0.21426"
"128.26800","10.68923","0.21676"
"128.52000","10.71016","0.21851"
"128.77200","10.73114","0.22043"
"129.02400","10.75213","0.22231"
"129.27600","10.77324","0.22401"
"129.52800","10.79422","0.22605"
"129.78000","10.81521","0.22761"
"130.03200","10.83613","0.22944"
"130.28400","10.85718","0.23117"
"130.53600","10.87823","0.23308"
"130.78800","10.89909","0.23561"
"131.04000","10.92026","0.23801"
"131.29200","10.94113","0.24091"
"131.54400","10.96223","0.24265"
"131.79600","10.98316","0.21050"
"132.04800","11.00420","0.30302"
"132.30000","11.02513","0.29677"
"132.55200","11.04618","0.29962"
"132.80400","11.06716","0.29852"
"133.05600","11.08815","0.30000"
"133.30800","11.10919","0.30191"
"133.56000","11.13018","0.30248"
"133.81200","11.15123","0.30426"
"134.06400","11.17215","0.30674"
"134.31600","11.19320","0.30904"
"134.56800","11.21418","0.31056"
"134.82000","11.23517","0.31275"
"135.07200","11.25616","0.30952"
"135.32400","11.27720","0.31147"
"135.57600","11.29813","0.31357"
"135.82800","11.31917","0.31583"
"136.08000","11.34016","0.31812"
"136.33200","11.36121","0.31996"
"136.58400","11.38213","0.32201"
"136.83600","11.40312","0.32425"
"137.08800","11.42411","0.32654"
"137.34000","11.44521","0.32902"
"137.59200","11.46626","0.33145"
"137.84400","11.48724","0.33528"
"138.09600","11.50823","0.34004"
"138.34800","11.52915","0.34430"
"138.60000","11.55020","0.34801"
"138.85200","11.57113","0.35104"
"139.10400","11.59223","0.35390"
"139.35600","11.61316","0.35761"
"139.60800","11.63421","0.36130"
"139.86000","11.65513","0.36606"
"140.11200","11.67624","0.36977"
"140.36400","11.69716","0.37398"
"140.61600","11.71821","0.37612"
"140.86800","11.73920","0.37858"
"141.12000","11.76012","0.38154"
"141.37200","11.78117","0.38489"
"141.62400","11.80221","0.38892"
"141.87600","11.82320","0.39311"
"142.12800","11.84419","0.39607"
"142.38000","11.86523","0.39977"
"142.63200","11.88622","0.40264"
"142.88400","11.90721","0.40566"
"143.13600","11.92813","0.40760"
"143.38800","11.94918","0.41029"
"143.64000","11.97016","0.41198"
"143.89200","11.99127","0.41433"
"144.14400","12.01219","0.41659"
"144.39600","12.03318","0.41917"
"144.64800","12.05417","0.42285"
"144.90000","12.07521","0.42682"
"145.15200","12.09614","0.42977"
"145.40400","12.11719","0.43225"
"145.65600","12.13823","0.39952"
"145.90800","12.15922","0.40079"
"146.16000","12.18020","0.40252"
"146.41200","12.20113","0.40455"
"146.66400","12.22224","0.40744"
"146.91600","12.24316","0.40906"
"147.16800","12.26415","0.41064"
"147.42000","12.28513","0.41244"
"147.67200","12.30618","0.41438"
"147.92400","12.32717","0.41620"
"148.17600","12.34821","0.41889"
"148.42800","12.36920","0.42165"
"148.68000","12.39025","0.42555"
"148.93200","12.41123","0.42835"
"149.18400","12.43216","0.43222"
"149.43600","12.45314","0.43478"
"149.68800","12.47419","0.43854"
"149.94000","12.49523","0.44246"
"150.19200","12.51616","0.44605"
"150.44400","12.53721","0.44946"
"150.69600","12.55813","0.45211"
"150.94800","12.57924","0.45464"
"151.20000","12.60011","0.45697"
"151.45200","12.62115","0.46007"
"151.70400","12.64214","0.46509"
"151.95600","12.66318","0.46887"
"152.20800","12.68417","0.47267"
"152.46000","12.70516","0.47555"
"152.71200","12.72620","0.47822"
"152.96400","12.74719","0.48069"
"153.21600","12.76824","0.48407"
"153.46800","12.78916","0.39592"
"153.72000","12.81015","0.38321"
"153.97200","12.83119","0.37761"
"154.22400","12.85218","0.37937"
"154.47600","12.87316","0.36946"
"154.72800","12.89421","0.37065"
"154.98000","12.91514","0.37085"
"155.23200","12.93618","0.37527"
"155.48400","12.95711","0.37764"
"155.73600","12.97816","0.37958"
"155.98800","12.99914","0.38141"
"156.24000","13.02025","0.38314"
"156.49200","13.04117","0.38834"
"156.74400","13.06222","0.39243"
"156.99600","13.08321","0.39799"
"157.24800","13.10419","0.39913"
"157.50000","13.12518","0.40238"
"157.75200","13.14610","0.40429"
"158.00400","13.16715","0.40779"
"158.25600","13.18820","0.40904"
"158.50800","13.20924","0.41066"
"158.76000","13.23011","0.41263"
"159.01200","13.25115","0.41393"
"159.26400","13.27214","0.41804"
"159.51600","13.29319","0.42150"
"159.76800","13.31417","0.42391"
"160.02000","13.33522","0.42689"
"160.27200","13.35614","0.42953"
"160.52400","13.37719","0.43303"
"160.77600","13.39818","0.43691"
"161.02800","13.41916","0.43932"
"161.28000","13.44021","0.44279"
"161.53200","13.46120","0.44693"
"161.78400","13.48218","0.44879"
"162.03600","13.50317","0.45263"
"162.28800","13.52415","0.45369"
"162.54000","13.54514","0.45566"
"162.79200","13.56618","0.45912"
"163.04400","13.58717","0.46117"
"163.29600","13.60828","0.46448"
"163.54800","13.62914","0.46779"
"163.80000","13.65019","0.46996"
"164.05200","13.67118","0.47226"
"164.30400","13.69222","0.47497"
"164.55600","13.71321","0.47701"
"164.80800","13.73419","0.47983"
"165.06000","13.75518","0.48345"
"165.31200","13.77623","0.48686"
"165.56400","13.79721","0.49079"
"165.81600","13.81814","0.49510"
"166.06800","13.83918","0.49060"
"166.32000","13.86017","0.49386"
"166.57200","13.88128","0.49147"
"166.82400","13.90208","0.49426"
"167.07600","13.92319","0.49835"
"167.32800","13.94412","0.50068"
"167.58000","13.96522","0.50329"
"167.83200","13.98615","0.50371"
"168.08400","14.00719","0.36724"
"168.33600","14.02818","0.36301"
"168.58800","14.04922","0.36164"
"168.84000","14.07015","0.36019"
"169.09200","14.09120","0.35947"
"169.34400","14.11218","0.36011"
"169.59600","14.13323","0.35968"
"169.84800","14.15422","0.36237"
"170.10000","14.17514","0.36393"
"170.35200","14.19625","0.36474"
"170.60400","14.21717","0.36691"
"170.85600","14.23822","0.36906"
"171.10800","14.25915","0.37133"
"171.36000","14.28019","0.37041"
"171.61200","14.30112","0.36988"
"171.86400","14.32216","0.37131"
"172.11600","14.34309","0.37218"
"172.36800","14.36420","0.37356"
"172.62000","14.38518","0.37512"
"172.87200","14.40623","0.37690"
"173.12400","14.42716","0.37831"
"173.37600","14.44820","0.37950"
"173.62800","14.46919","0.38154"
"173.88000","14.49017","0.38325"
"174.13200","14.51122","0.13718"
"174.38400","14.53215","0.13860"
"174.63600","14.55319","0.14468"
"174.88800","14.57418","0.14796"
"175.14000","14.59516","0.14902"
"175.39200","14.61615","0.15089"
"175.64400","14.63720","0.15230"
"175.89600","14.65812","0.15593"
"176.14800","14.67923","0.15805"
"176.40000","14.70015","0.16022"
"176.65200","14.72120","0.16099"
"176.90400","14.74219","0.16400"
"177.15600","14.76317","0.16769"
"177.40800","14.78416","0.17138"
"177.66000","14.80514","0.17184"
"177.91200","14.82625","0.17236"
"178.16400","14.84718","0.17322"
"178.41600","14.86816","0.17555"
"178.66800","14.88909","0.17741"
"178.92000","14.91020","0.17809"
"179.17200","14.93118","0.17859"
"179.42400","14.95223","0.01487"
"179.67600","14.97315","0.03072"
"179.92800","14.99420","0.02091"
"180.18000","15.01518","0.03141"
"180.43200","15.03617","0.02869"
"180.68400","15.05722","0.02232"
"180.93600","15.07820","0.02631"
"181.18800","15.09919","0.02660"
"181.44000","15.12018","0.02596"
"181.69200","15.14116","0.03719"
"181.94400","15.16221","0.03196"
"182.19600","15.18325","0.03310"
"182.44800","15.20412","0.03557"
"182.70000","15.22523","0.03170"
"182.95200","15.24615","0.03818"
"183.20400","15.26720","0.03706"
"183.45600","15.28813","0.04328"
"183.70800","15.30923","0.04168"
"183.96000","15.33016","0.04112"
"184.21200","15.35120","0.04408"
"184.46400","15.37213","0.04176"
"184.71600","15.39317","0.04524"
"184.96800","15.41422","0.04771"
"185.22000","15.43521","0.05058"
"185.47200","15.45619","0.05070"
"185.72400","15.47718","0.04887"
"185.97600","15.49822","0.05192"
"186.22800","15.51921","0.05228"
"186.48000","15.54020","0.05608"
"186.73200","15.56112","0.05674"
"186.98400","15.58217","0.05861"
"187.23600","15.60316","0.05894"
"187.48800","15.62420","0.05800"
"187.74000","15.64513","0.06032"
"187.99200","15.66623","0.06257"
"188.24400","15.68710","0.06582"
"188.49600","15.70820","0.06535"
"188.74800","15.72919","0.06575"
"189.00000","15.75018","0.06539"
"189.25200","15.77122","0.06692"
"189.50400","15.79221","0.06828"
"189.75600","15.81319","0.07040"
"190.00800","15.83412","0.07115"
"190.26000","15.85517","0.07214"
"190.51200","15.87615","0.07292"
"190.76400","15.89720","0.07420"
"191.01600","15.91813","0.07774"
"191.26800","15.93917","0.08154"
"191.52000","15.96016","0.08340"
"191.77200","15.98120","0.08396"
"192.02400","16.00219","0.08496"
"192.27600","16.02318","0.08670"
"192.52800","16.04410","0.08928"
"192.78000","16.06515","0.09043"
"193.03200","16.08619","0.09142"
"193.28400","16.10718","0.09133"
"193.53600","16.12823","0.09258"
"193.78800","16.14915","0.09360"
"194.04000","16.17020","0.09455"
"194.29200","16.19118","0.09572"
"194.54400","16.21223","0.09637"
"194.79600","16.23310","0.09704"
"195.04800","16.25420","0.09763"
"195.30000","16.27519","0.09852"
"195.55200","16.29623","0.09897"
"195.80400","16.31716","0.09914"
"196.05600","16.33821","0.09999"
"196.30800","16.35913","0.10034"
"196.56000","16.38018","0.10107"
"196.81200","16.40117","0.10175"
"197.06400","16.42215","0.10261"
"197.31600","16.44314","0.10352"
"197.56800","16.46418","0.10426"
"197.82000","16.48517","0.10549"
"198.07200","16.50616","0.10399"
"198.32400","16.52720","0.10492"
"198.57600","16.54813","0.10591"
"198.82800","16.56918","0.10708"
"199.08000","16.59010","0.10743"
"199.33200","16.61115","0.10801"
"199.58400","16.63213","0.10855"
"199.83600","16.65324","0.10880"
"200.08800","16.67422","0.10993"
"200.34000","16.69521","0.10903"
"200.59200","16.71620","0.10882"
"200.84400","16.73712","0.10857"
"201.09600","16.75817","0.11015"
"201.34800","16.77915","0.10915"
"201.60000","16.80026","0.10934"
"201.85200","16.82119","0.11066"
"202.10400","16.84217","0.11155"
"202.35600","16.86316","0.11220"
"202.60800","16.88421","0.11338"
"202.86000","16.90513","0.11375"
"203.11200","16.92612","0.11453"
"203.36400","16.94710","0.11648"
"203.61600","16.96821","0.11773"
"203.86800","16.98914","0.11841"
"204.12000","17.01024","0.11964"
"204.37200","17.03117","0.12139"
"204.62400","17.05221","0.12244"
"204.87600","17.07320","0.12462"
"205.12800","17.09413","0.12669"
"205.38000","17.11511","0.12852"
"205.63200","17.13616","0.13091"
"205.88400","17.15720","0.13237"
"206.13600","17.17819","0.13388"
"206.38800","17.19924","0.13683"
"206.64000","17.22016","0.13788"
"206.89200","17.24121","0.13827"
"207.14400","17.26213","0.14029"
"207.39600","17.28318","0.14147"
"207.64800","17.30417","0.14304"
"207.90000","17.32521","0.14420"
"208.15200","17.34614","0.14607"
"208.40400","17.36724","0.14625"
"208.65600","17.38817","0.14759"
"208.90800","17.40922","0.14954"
"209.16000","17.43020","0.15110"
"209.41200","17.45119","0.15136"
"209.66400","17.47218","0.15196"
"209.91600","17.49322","0.15366"
"210.16800","17.51421","0.15588"
"210.42000","17.53513","0.15743"
"210.67200","17.55618","0.15635"
"210.92400","17.57717","0.15806"
"211.17600","17.59815","0.15909"
"211.42800","17.61920","0.16116"
"211.68000","17.64018","0.16224"
"211.93200","17.66111","0.16355"
"212.18400","17.68222","0.16611"
"212.43600","17.70314","0.16695"
"212.68800","17.72419","0.16850"
"212.94000","17.74523","0.16925"
"213.19200","17.76616","0.17032"
"213.44400","17.78715","0.17190"
"213.69600","17.80813","0.17250"
"213.94800","17.82918","0.17423"
"214.20000","17.85016","0.17481"
"214.45200","17.87121","0.17557"
"214.70400","17.89214","0.17680"
"214.95600","17.91324","0.17775"
"215.20800","17.93417","0.17867"
"215.46000","17.95522","0.18024"
"215.71200","17.97614","0.18157"
"215.96400","17.99719","0.18322"
"216.21600","18.01817","0.18414"
"216.46800","18.03922","0.18643"
"216.72000","18.06021","0.18698"
"216.97200","18.08119","0.18810"
"217.22400","18.10218","0.18985"
"217.47600","18.12317","0.19101"
"217.72800","18.14421","0.19238"
"217.98000","18.16514","0.19427"
"218.23200","18.18618","0.19578"
"218.48400","18.20711","0.19719"
"218.73600","18.22821","0.19876"
"218.98800","18.24914","0.20083"
"219.24000","18.27019","0.20174"
"219.49200","18.29111","0.20237"
"219.74400","18.31216","0.20383"
"219.99600","18.33315","0.20363"
"220.24800","18.35419","0.20480"
"220.50000","18.37518","0.20604"
"220.75200","18.39622","0.20710"
"221.00400","18.41721","0.20826"
"221.25600","18.43820","0.20900"
"221.50800","18.45918","0.21015"
"221.76000","18.48011","0.21102"
"222.01200","18.50115","0.21207"
"222.26400","18.52220","0.21377"
"222.51600","18.54319","0.21531"
"222.76800","18.56411","0.21654"
"223.02000","18.58516","0.21746"
"223.27200","18.60614","0.21960"
"223.52400","18.62719","0.22138"
"223.77600","18.64812","0.22209"
"224.02800","18.66922","0.22406"
"224.28000","18.69021","0.22481"
"224.53200","18.71119","0.22666"
"224.78400","18.73218","0.22766"
"225.03600","18.75323","0.22839"
"225.28800","18.77421","0.23025"
"225.54000","18.79520","0.23170"
"225.79200","18.81618","0.23315"
"226.04400","18.83711","0.23517"
"226.29600","18.85822","0.23693"
"226.54800","18.87914","0.23849"
"226.80000","18.90019","0.24061"
"227.05200","18.92118","0.24187"
"227.30400","18.94216","0.24408"
"227.55600","18.96315","0.24558"
"227.80800","18.98419","0.24647"
"228.06000","19.00518","0.24781"
"228.31200","19.02617","0.25008"
"228.56400","19.04715","0.25215"
"228.81600","19.06820","0.25409"
"229.06800","19.08918","0.25519"
"229.32000","19.11017","0.25809"
"229.57200","19.13122","0.26035"
"229.82400","19.15214","0.26292"
"230.07600","19.17319","0.26494"
"230.32800","19.19417","0.26703"
"230.58000","19.21522","0.26886"
"230.83200","19.23615","0.26979"
"231.08400","19.25713","0.27148"
"231.33600","19.27812","0.27346"
"231.58800","19.29922","0.27619"
"231.84000","19.32021","0.27808"
"232.09200","19.34126","0.28086"
"232.34400","19.36218","0.28442"
"232.59600","19.38317","0.28688"
"232.84800","19.40421","0.29030"
"233.10000","19.42520","0.29334"
"233.35200","19.44619","0.29598"
"233.60400","19.46717","0.29796"
"233.85600","19.48822","0.29995"
"234.10800","19.50909","0.30148"
"234.36000","19.53019","0.30303"
"234.61200","19.55112","0.30482"
"234.86400","19.57222","0.30666"
"235.11600","19.59315","0.30824"
"235.36800","19.61419","0.31046"
"235.62000","19.63512","0.31173"
"235.87200","19.65617","0.31407"
"236.12400","19.67715","0.31498"
"236.37600","19.69820","0.31663"
"236.62800","19.71918","0.31798"
"236.88000","19.74017","0.31961"
"237.13200","19.76122","0.32115"
"237.38400","19.78214","0.32290"
"237.63600","19.80319","0.32430"
"237.88800","19.82418","0.32498"
"238.14000","19.84522","0.32689"
"238.39200","19.86615","0.32948"
"238.64400","19.88719","0.33061"
"238.89600","19.90818","0.33304"
"239.14800","19.92917","0.33656"
"239.40000","19.95015","0.34007"
"239.65200","19.97120","0.34317"
"239.90400","19.99213","0.34604"
"240.15600","20.01317","0.34879"
"240.40800","20.03416","0.35191"
"240.66000","20.05520","0.35410"
"240.91200","20.07619","0.35609"
"241.16400","20.09718","0.35799"
"241.41600","20.11822","0.36060"
"241.66800","20.13921","0.36340"
"241.92000","20.16019","0.36715"
"242.17200","20.18112","0.36926"
"242.42400","20.20217","0.37232"
"242.67600","20.22309","0.37458"
"242.92800","20.24420","0.37629"
"243.18000","20.26518","0.37817"
"243.43200","20.28617","0.37987"
"243.68400","20.30716","0.38240"
"243.93600","20.32820","0.38539"
"244.18800","20.34913","0.38740"
"244.44000","20.37017","0.39064"
"244.69200","20.39116","0.39288"
"244.94400","20.41221","0.39589"
"245.19600","20.43319","0.39823"
"245.44800","20.45412","0.40072"
"245.70000","20.47522","0.40273"
"245.95200","20.49615","0.40491"
"246.20400","20.51720","0.40681"
"246.45600","20.53812","0.40854"
"246.70800","20.55917","0.41038"
"246.96000","20.58015","0.41177"
"247.21200","20.60120","0.41357"
"247.46400","20.62219","0.41533"
"247.71600","20.64323","0.41679"
"247.96800","20.66416","0.41954"
"248.22000","20.68521","0.42162"
"248.47200","20.70613","0.42510"
"248.72400","20.72712","0.42771"
"248.97600","20.74817","0.43048"
"249.22800","20.76921","0.43312"
"249.48000","20.79020","0.43573"
"249.73200","20.81118","0.43886"
"249.98400","20.83217","0.44100"
"250.23600","20.85321","0.44529"
"250.48800","20.87420","0.44819"
"250.74000","20.89513","0.45068"
"250.99200","20.91623","0.45310"
"251.24400","20.93716","0.45525"
"251.49600","20.95821","0.45823"
"251.74800","20.97913","0.46078"
"252.00000","21.00024","0.45990"
"252.25200","21.02122","0.46246"
"252.50400","21.04221","0.46628"
"252.75600","21.06319","0.46759"
"253.00800","21.08418","0.47115"
"253.26000","21.10523","0.47461"
"253.51200","21.12615","0.47685"
"253.76400","21.14720","0.47885"
"254.01600","21.16813","0.48089"
"254.26800","21.18923","0.48319"
"254.52000","21.21016","0.48640"
"254.77200","21.23114","0.42407"
"255.02400","21.25213","0.29336"
"255.27600","21.27318","0.29738"
"255.52800","21.29422","0.30141"
"255.78000","21.31521","0.29979"
"256.03200","21.33619","0.30804"
"256.28400","21.35718","0.30691"
"256.53600","21.37823","0.31097"
"256.78800","21.39915","0.32021"
"257.04000","21.42020","0.31908"
"257.29200","21.44118","0.32096"
"257.54400","21.46223","0.32575"
"257.79600","21.48315","0.33088"
"258.04800","21.50420","0.33651"
"258.30000","21.52519","0.34017"
"258.55200","21.54623","0.34885"
"258.80400","21.56716","0.34412"
"259.05600","21.58815","0.34980"
"259.30800","21.60913","0.35612"
"259.56000","21.63024","0.36773"
"259.81200","21.65111","0.36647"
"260.06400","21.67221","0.37054"
"260.31600","21.69320","0.37550"
"260.56800","21.71418","0.38202"
"260.82000","21.73517","0.38320"
"261.07200","21.75615","0.38586"
"261.32400","21.77720","0.38935"
"261.57600","21.79813","0.39727"
"261.82800","21.81923","0.39879"
"262.08000","21.84010","0.40356"
"262.33200","21.86121","0.40550"
"262.58400","21.88213","0.40897"
"262.83600","21.90318","0.40947"
"263.08800","21.92416","0.41137"
"263.34000","21.94515","0.41352"
"263.59200","21.96614","0.41814"
"263.84400","21.98724","0.42022"
"264.09600","22.00817","0.42035"
"264.34800","22.02915","0.42335"
"264.60000","22.05014","0.42821"
"264.85200","22.07113","0.43382"
"265.10400","22.09217","0.43437"
"265.35600","22.11316","0.43612"
"265.60800","22.13420","0.43987"
"265.86000","22.15513","0.44492"
"266.11200","22.17618","0.44909"
"266.36400","22.19710","0.44943"
"266.61600","22.21821","0.45143"
"266.86800","22.23914","0.45392"
"267.12000","22.26018","0.45661"
"267.37200","22.28117","0.46010"
"267.62400","22.30221","0.46192"
"267.87600","22.32320","0.46398"
"268.12800","22.34419","0.46763"
"268.38000","22.36523","0.47116"
"268.63200","22.38616","0.47452"
"268.88400","22.40714","0.47509"
"269.13600","22.42819","0.47546"
"269.38800","22.44918","0.47688"
"269.64000","22.47016","0.47927"
"269.89200","22.49127","0.48144"
"270.14400","22.51213","0.48355"
"270.39600","22.53324","0.48482"
"270.64800","22.55411","0.48874"
"270.90000","22.57521","0.49236"
"271.15200","22.59614","0.49634"
"271.40400","22.61712","0.50045"
"271.65600","22.63817","0.50321"
"271.90800","22.65922","0.50564"
"272.16000","22.68014","0.50753"
"272.41200","22.70119","0.50993"
"272.66400","22.72218","0.50353"
"272.91600","22.74316","0.50707"
"273.16800","22.76421","0.51073"
"273.42000","22.78514","0.51277"
"273.67200","22.80624","0.51428"
"273.92400","22.82717","0.51575"
"274.17600","22.84821","0.51863"
"274.42800","22.86908","0.52071"
"274.68000","22.89018","0.52110"
"274.93200","22.91117","0.52219"
"275.18400","22.93222","0.52431"
"275.43600","22.95314","0.52672"
"275.68800","22.97419","0.52838"
"275.94000","22.99517","0.53067"
"276.19200","23.01622","0.53254"
"276.44400","23.03721","0.53448"
"276.69600","23.05819","0.53624"
"276.94800","23.07924","0.53739"
"277.20000","23.10023","0.54035"
"277.45200","23.12115","0.54347"
"277.70400","23.14214","0.54651"
"277.95600","23.16324","0.54868"
"278.20800","23.18417","0.55102"
"278.46000","23.20522","0.55333"
"278.71200","23.22608","0.55486"
"278.96400","23.24719","0.55713"
"279.21600","23.26818","0.56015"
"279.46800","23.28916","0.56303"
"279.72000","23.31014","0.56457"
"279.97200","23.33119","0.56760"
"280.22400","23.35218","0.57046"
"280.47600","23.37322","0.57280"
"280.72800","23.39415","0.57540"
"280.98000","23.41514","0.57823"
"281.23200","23.43624","0.58056"
"281.48400","23.45717","0.58236"
"281.73600","23.47821","0.58479"
"281.98800","23.49908","0.58702"
"282.24000","23.52024","0.58874"
"282.49200","23.54117","0.59096"
"282.74400","23.56216","0.59382"
"282.99600","23.58315","0.59585"
"283.24800","23.60419","0.59807"
"283.50000","23.62518","0.60071"
"283.75200","23.64616","0.60252"
"284.00400","23.66715","0.60371"
"284.25600","23.68819","0.39862"
"284.50800","23.70924","0.39040"
"284.76000","23.73023","0.38614"
"285.01200","23.75115","0.38481"
"285.26400","23.77214","0.38818"
"285.51600","23.79318","0.39197"
"285.76800","23.81411","0.39427"
"286.02000","23.83522","0.39614"
"286.27200","23.85608","0.39731"
"286.52400","23.87725","0.39538"
"286.77600","23.89817","0.39526"
"287.02800","23.91916","0.39864"
"287.28000","23.94015","0.40349"
"287.53200","23.96119","0.40472"
"287.78400","23.98218","0.40339"
"288.03600","24.00316","0.40440"
"288.28800","24.02415","0.40684"
"288.54000","24.04520","0.40777"
"288.79200","24.06618","0.40838"
"289.04400","24.08717","0.41002"
"289.29600","24.10822","0.41208"
"289.54800","24.12914","0.41277"
"289.80000","24.15019","0.41226"
"290.05200","24.17112","0.41225"
"290.30400","24.19216","0.25367"
"290.55600","24.21315","0.24402"
"290.80800","24.23419","0.25470"
"291.06000","24.25518","0.24117"
"291.31200","24.27622","0.24105"
"291.56400","24.29715","0.23858"
"291.81600","24.31820","0.24854"
"292.06800","24.33912","0.24853"
"292.32000","24.36017","0.24706"
"292.57200","24.38121","0.24450"
"292.82400","24.40220","0.25164"
"293.07600","24.42324","0.25094"
"293.32800","24.44417","0.25112"
"293.58000","24.46522","0.25088"
"293.83200","24.48615","0.25353"
"294.08400","24.50719","0.25820"
"294.33600","24.52812","0.25490"
"294.58800","24.54916","0.25607"
"294.84000","24.57015","0.26131"
"295.09200","24.59120","0.26065"
"295.34400","24.61218","0.25992"
"295.59600","24.63323","0.26091"
"295.84800","24.65416","0.26631"
"296.10000","24.67514","0.26945"
"296.35200","24.69619","0.26650"
"296.60400","24.71723","0.26647"
"296.85600","24.73816","0.27373"
"297.10800","24.75920","0.27373"
"297.36000","24.78025","0.27339"
"297.61200","24.80118","0.27750"
"297.86400","24.82222","0.27817"
"298.11600","24.84309","0.28018"
"298.36800","24.86419","0.28445"
"298.62000","24.88518","0.28896"
"298.87200","24.90623","0.29158"
"299.12400","24.92721","0.29144"
"299.37600","24.94820","0.29407"
"299.62800","24.96919","0.29947"
"299.88000","24.99023","0.29937"
"300.13200","25.01110","0.29912"
"300.38400","25.03214","0.30325"
"300.63600","25.05319","0.30385"
"300.88800","25.07417","0.30524"
"301.14000","25.09522","0.30879"
"301.39200","25.11621","0.30852"
"301.64400","25.13725","0.30958"
"301.89600","25.15818","0.31317"
"302.14800","25.17916","0.31394"
"302.40000","25.20009","0.31496"
"302.65200","25.22120","0.31558"
"302.90400","25.24219","0.31717"
"303.15600","25.26323","0.31786"
"303.40800","25.28416","0.31936"
"303.66000","25.30520","0.32055"
"303.91200","25.32619","0.32053"
"304.16400","25.34717","0.32313"
"304.41600","25.36822","0.32388"
"304.66800","25.38921","0.32517"
"304.92000","25.41019","0.32629"
"305.17200","25.43118","0.32737"
"305.42400","25.45217","0.32809"
"305.67600","25.47315","0.33212"
"305.92800","25.49426","0.33224"
"306.18000","25.51518","0.33346"
"306.43200","25.53617","0.33924"
"306.68400","25.55709","0.33991"
"306.93600","25.57826","0.34144"
"307.18800","25.59919","0.34625"
"307.44000","25.62024","0.34396"
"307.69200","25.64110","0.34678"
"307.94400","25.66227","0.35011"
"308.19600","25.68319","0.35048"
"308.44800","25.70418","0.35293"
"308.70000","25.72516","0.35472"
"308.95200","25.74615","0.35771"
"309.20400","25.76726","0.35959"
"309.45600","25.78818","0.36223"
"309.70800","25.80923","0.36678"
"309.96000","25.83015","0.36718"
"310.21200","25.85126","0.36933"
"310.46400","25.87213","0.37341"
"310.71600","25.89317","0.37363"
"310.96800","25.91416","0.37605"
"311.22000","25.93527","0.37723"
"311.47200","25.95619","0.37939"
"311.72400","25.97717","0.38034"
"311.97600","25.99816","0.38207"
"312.22800","26.01921","0.38626"
"312.48000","26.04013","0.38646"
"312.73200","26.06118","0.38974"
"312.98400","26.08223","0.39274"
"313.23600","26.10315","0.39503"
"313.48800","26.12426","0.39709"
"313.74000","26.14513","0.39838"
"313.99200","26.16623","0.40208"
"314.24400","26.18716","0.40249"
"314.49600","26.20820","0.40437"
"314.74800","26.22913","0.40573"
"315.00000","26.25018","0.40838"
"315.25200","26.27116","0.40882"
"315.50400","26.29221","0.41012"
"315.75600","26.31319","0.41175"
"316.00800","26.33418","0.41336"
"316.26000","26.35517","0.41409"
"316.51200","26.37621","0.41514"
"316.76400","26.39720","0.41802"
"317.01600","26.41812","0.41925"
"317.26800","26.43923","0.42131"
"317.52000","26.46021","0.42268"
"317.77200","26.48120","0.42726"
"318.02400","26.50213","0.42759"
"318.27600","26.52317","0.43071"
"318.52800","26.54410","0.43217"
"318.78000","26.56521","0.43500"
"319.03200","26.58613","0.43569"
"319.28400","26.60724","0.43887"
"319.53600","26.62817","0.34001"
"319.78800","26.64921","0.33051"
"320.04000","26.67020","0.33087"
"320.29200","26.69118","0.10677"
"320.54400","26.71217","0.10122"
"320.79600","26.73322","0.10996"
"321.04800","26.75414","0.09936"
"321.30000","26.77513","0.10538"
"321.55200","26.79623","0.10494"
"321.80400","26.81710","0.10978"
"322.05600","26.83821","0.10960"
"322.30800","26.85913","0.11369"
"322.56000","26.88024","0.11243"
"322.81200","26.90116","0.12399"
"323.06400","26.92215","0.12326"
"323.31600","26.94314","0.14289"
"323.56800","26.96424","0.12807"
"323.82000","26.98517","0.13256"
"324.07200","27.00621","0.12179"
"324.32400","27.02720","0.11635"
"324.57600","27.04819","0.11981"
"324.82800","27.06917","0.13128"
"325.08000","27.09016","0.14006"
"325.33200","27.11121","0.14311"
"325.58400","27.13213","0.14630"
"325.83600","27.15318","0.13703"
"326.08800","27.17410","0.13332"
"326.34000","27.19515","0.13663"
"326.59200","27.21620","0.13998"
"326.84400","27.23724","0.14704"
"327.09600","27.25811","0.15334"
"327.34800","27.27921","0.15910"
"327.60000","27.30014","0.15402"
"327.85200","27.32125","0.15123"
"328.10400","27.34217","0.15386"
"328.35600","27.36316","0.16336"
"328.60800","27.38420","0.16925"
"328.86000","27.40519","0.16645"
"329.11200","27.42624","0.16339"
"329.36400","27.44716","0.16795"
"329.61600","27.46821","0.17218"
"329.86800","27.48920","0.17622"
"330.12000","27.51024","0.17513"
"330.37200","27.53111","0.17621"
"330.62400","27.55215","0.17855"
"330.87600","27.57314","0.18678"
"331.12800","27.59418","0.18714"
"331.38000","27.61511","0.18582"
"331.63200","27.63622","0.18430"
"331.88400","27.65726","0.18826"
"332.13600","27.67819","0.19129"
"332.38800","27.69917","0.19109"
"332.64000","27.72016","0.18873"
"332.89200","27.74115","0.19334"
"333.14400","27.76213","0.19623"
"333.39600","27.78318","0.19418"
"333.64800","27.80410","0.19630"
"333.90000","27.82521","0.20225"
"334.15200","27.84614","0.20323"
"334.40400","27.86718","0.20232"
"334.65600","27.88811","0.20429"
"334.90800","27.90922","0.20505"
"335.16000","27.93020","0.20382"
"335.41200","27.95119","0.20279"
"335.66400","27.97218","0.20498"
"335.91600","27.99322","0.20726"
"336.16800","28.01421","0.20671"
"336.42000","28.03519","0.20870"
"336.67200","28.05618","0.21079"
"336.92400","28.07717","0.21023"
"337.17600","28.09821","0.20867"
"337.42800","28.11914","0.21005"
"337.68000","28.14018","0.20925"
"337.93200","28.16111","0.20829"
"338.18400","28.18221","0.21166"
"338.43600","28.20314","0.21235"
"338.68800","28.22419","0.21258"
"338.94000","28.24511","0.21411"
"339.19200","28.26622","0.21458"
"339.44400","28.28714","0.21223"
"339.69600","28.30819","0.21233"
"339.94800","28.32918","0.21328"
"340.20000","28.35022","0.21306"
"340.45200","28.37121","0.21459"
"340.70400","28.39220","0.21647"
"340.95600","28.41318","0.21767"
"341.20800","28.43417","0.21532"
"341.46000","28.45521","0.21667"
"341.71200","28.47614","0.21579"
"341.96400","28.49718","0.21458"
"342.21600","28.51817","0.21748"
"342.46800","28.53922","0.21910"
"342.72000","28.56014","0.21989"
"342.97200","28.58119","0.22024"
"343.22400","28.60217","0.22110"
"343.47600","28.62316","0.21828"
"343.72800","28.64409","0.21852"
"343.98000","28.66520","0.22050"
"344.23200","28.68618","0.21973"
"344.48400","28.70717","0.22267"
"344.73600","28.72821","0.22321"
"344.98800","28.74920","0.22221"
"345.24000","28.77018","0.21986"
"345.49200","28.79117","0.22028"
"345.74400","28.81216","0.21915"
"345.99600","28.83314","0.21899"
"346.24800","28.85419","0.22243"
"346.50000","28.87512","0.22071"
"346.75200","28.89616","0.22015"
"347.00400","28.91715","-0.00261"
"347.25600","28.93819","-0.00974"
"347.50800","28.95918","0.00417"
"347.76000","28.98017","-0.00178"
"348.01200","29.00115","-0.00191"
"348.26400","29.02220","0.00118"
"348.51600","29.04318","-0.00134"
"348.76800","29.06417","0.00031"
"349.02000","29.08521","-0.00152"
"349.27200","29.10614","-0.00010"
"349.52400","29.12725","-0.00019"
"349.77600","29.14812","-0.00104"
"350.02800","29.16922","-0.00015"
"350.28000","29.19021","-0.00108"
"350.53200","29.21119","-0.00070"
"350.78400","29.23218","-0.00080"
"351.03600","29.25317","-0.00049"
"351.28800","29.27415","-0.00105"
"351.54000","29.29520","-0.00101"
"351.79200","29.31618","-0.00085"
"352.04400","29.33717","-0.00051"
"352.29600","29.35816","-0.00052"
"352.54800","29.37920","-0.00037"
"352.80000","29.40019","-0.00091"
"353.05200","29.42117","-0.00073"
"353.30400","29.44222","-0.00026"
"353.55600","29.46315","-0.00102"
"353.80800","29.48419","-0.00075"
"354.06000","29.50512","-0.00096"
"354.31200","29.52622","-0.00064"
"354.56400","29.54715","-0.00082"
"354.81600","29.56825","-0.00040"
"355.06800","29.58912","-0.00070"
"355.32000","29.61017","-0.00052"
"355.57200","29.63122","-0.00063"
"355.82400","29.65220","-0.00080"
"356.07600","29.67319","-0.00054"
"356.32800","29.69417","-0.00069"
"356.58000","29.71516","-0.00065"
"356.83200","29.73621","-0.00090"
"357.08400","29.75719","-0.00070"
"357.33600","29.77818","-0.00027"
"357.58800","29.79922","-0.00084"
"357.84000","29.82015","-0.00076"
"358.09200","29.84120","-0.00071"
"358.34400","29.86212","-0.00083"
"358.59600","29.88317","-0.00090"
"358.84800","29.90415","-0.00077"
"359.10000","29.92520","-0.00038"
"359.35200","29.94619","-0.00106"
"359.60400","29.96717","-0.00093"
"359.85600","29.98822","-0.00041"
"360.10800","30.00914","-0.00070"
"360.36000","30.03013","-0.00083"
"360.61200","30.05118","-0.00085"
"360.86400","30.07222","-0.00086"
"361.11600","30.09321","-0.00027"
"361.36800","30.11426","-0.00038"
"361.62000","30.13512","-0.00033"
"361.87200","30.15617","-0.00080"
"362.12400","30.17709","-0.00091"
"362.37600","30.19814","-0.00059"
"362.62800","30.21913","-0.00084"
"362.88000","30.24023","-0.00052"
"363.13200","30.26116","-0.00040"
"363.38400","30.28221","-0.00051"
"363.63600","30.30319","-0.00101"
"363.88800","30.32424","-0.00062"
"364.14000","30.34522","-0.00022"
"364.39200","30.36615","-0.00071"
"364.64400","30.38719","-0.00101"
"364.89600","30.40818","-0.00052"
"365.14800","30.42923","-0.00041"
"365.40000","30.45015","-0.00033"
"365.65200","30.47120","-0.00008"
"365.90400","30.49218","-0.00067"
"366.15600","30.51323","-0.00090"
"366.40800","30.53415","-0.00058"
"366.66000","30.55514","-0.00055"
"366.91200","30.57613","-0.00063"
"367.16400","30.59723","-0.00041"
"367.41600","30.61816","-0.00076"
"367.66800","30.63921","-0.00075"
"367.92000","30.66019","-0.00054"
"368.17200","30.68118","-0.00055"
"368.42400","30.70217","-0.00030"
"368.67600","30.72315","-0.00054"
"368.92800","30.74420","-0.00082"
"369.18000","30.76512","-0.00068"
"369.43200","30.78617","-0.00094"
"369.68400","30.80715","-0.00059"
"369.93600","30.82820","-0.00074"
"370.18800","30.84919","-0.00077"
"370.44000","30.87017","-0.00102"
"370.69200","30.89116","-0.00036"
"370.94400","30.91221","-0.00107"
"371.19600","30.93319","-0.00023"
"371.44800","30.95424","-0.00071"
"371.70000","30.97516","-0.00061"
"371.95200","30.99621","-0.00042"
"372.20400","31.01726","-0.00101"
"372.45600","31.03818","-0.00069"
"372.70800","31.05917","-0.00073"
"372.96000","31.08015","-0.00086"
"373.07800","31.09002","-0.00083"