File: Force_trajectories/161216/Specimen_RawData_7.csv
End date,"12/16/2016"
Specimen label,"15AG_19"
Maximum Load,"0.22100",N

Time,Extension,Load
(s),(mm),(N)
"0.00000","0.00000","-0.00063"
"0.33600","0.02786","0.00005"
"0.67200","0.05620","0.00018"
"1.00800","0.08430","0.00014"
"1.34400","0.11222","0.00050"
"1.68000","0.14021","0.00093"
"2.01600","0.16819","0.00099"
"2.35200","0.19617","0.00149"
"2.68800","0.22427","0.00163"
"3.02400","0.25219","0.00157"
"3.36000","0.28023","0.00182"
"3.69600","0.30816","0.00193"
"4.03200","0.33614","0.00159"
"4.36800","0.36424","0.00209"
"4.70400","0.39222","0.00160"
"5.04000","0.42020","0.00193"
"5.37600","0.44824","0.00204"
"5.71200","0.47616","0.00183"
"6.04800","0.50415","0.00175"
"6.38400","0.53219","0.00219"
"6.72000","0.56017","0.00231"
"7.05600","0.58821","0.00246"
"7.39200","0.61619","0.00219"
"7.72800","0.64417","0.00284"
"8.06400","0.67221","0.00273"
"8.40000","0.70020","0.00255"
"8.73600","0.72818","0.00262"
"9.07200","0.75628","0.00237"
"9.40800","0.78414","0.00278"
"9.74400","0.81218","0.00267"
"10.08000","0.84022","0.00278"
"10.41600","0.86808","0.00250"
"10.75200","0.89625","0.00324"
"11.08800","0.92423","0.00253"
"11.42400","0.95221","0.00269"
"11.76000","0.98019","0.00303"
"12.09600","1.00817","0.00309"
"12.43200","1.03621","0.00318"
"12.76800","1.06419","0.00302"
"13.10400","1.09218","0.00347"
"13.44000","1.12022","0.00327"
"13.77600","1.14820","0.00315"
"14.11200","1.17618","0.00292"
"14.44800","1.20416","0.00355"
"14.78400","1.23214","0.00304"
"15.12000","1.26024","0.00316"
"15.45600","1.28823","0.00336"
"15.79200","1.31621","0.00312"
"16.12800","1.34425","0.00278"
"16.46400","1.37223","0.00309"
"16.80000","1.40015","0.00349"
"17.13600","1.42825","0.00404"
"17.47200","1.45617","0.00334"
"17.80800","1.48422","0.00351"
"18.14400","1.51226","0.00366"
"18.48000","1.54018","0.00357"
"18.81600","1.56822","0.00319"
"19.15200","1.59620","0.00318"
"19.48800","1.62418","0.00363"
"19.82400","1.65222","0.00342"
"20.16000","1.68015","0.00410"
"20.49600","1.70825","0.00321"
"20.83200","1.73617","0.00385"
"21.16800","1.76415","0.00366"
"21.50400","1.79225","0.00365"
"21.84000","1.82017","0.00410"
"22.17600","1.84815","0.00430"
"22.51200","1.87620","0.00409"
"22.84800","1.90424","0.00355"
"23.18400","1.93222","0.00407"
"23.52000","1.96020","0.00428"
"23.85600","1.98818","0.00372"
"24.19200","2.01622","0.00357"
"24.52800","2.04420","0.00394"
"24.86400","2.07225","0.00422"
"25.20000","2.10023","0.00440"
"25.53600","2.12815","0.00356"
"25.87200","2.15625","0.00401"
"26.20800","2.18423","0.00399"
"26.54400","2.21215","0.00396"
"26.88000","2.24025","0.00341"
"27.21600","2.26818","0.00390"
"27.55200","2.29616","0.00353"
"27.88800","2.32426","0.00427"
"28.22400","2.35212","0.00425"
"28.56000","2.38022","0.00473"
"28.89600","2.40820","0.00400"
"29.23200","2.43618","0.00381"
"29.56800","2.46423","0.00403"
"29.90400","2.49221","0.00380"
"30.24000","2.52019","0.00362"
"30.57600","2.54823","0.00385"
"30.91200","2.57621","0.00340"
"31.24800","2.60419","0.00416"
"31.58400","2.63217","0.00428"
"31.92000","2.66022","0.00399"
"32.25600","2.68820","0.00432"
"32.59200","2.71618","0.00405"
"32.92800","2.74416","0.00407"
"33.26400","2.77220","0.00427"
"33.60000","2.80018","0.00380"
"33.93600","2.82816","0.00444"
"34.27200","2.85621","0.00421"
"34.60800","2.88419","0.00446"
"34.94400","2.91229","0.00390"
"35.28000","2.94015","0.00415"
"35.61600","2.96825","0.00469"
"35.95200","2.99623","0.00441"
"36.28800","3.02415","0.00404"
"36.62400","3.05220","0.00436"
"36.96000","3.08018","0.00434"
"37.29600","3.10816","0.00417"
"37.63200","3.13626","0.00443"
"37.96800","3.16418","0.00459"
"38.30400","3.19216","0.00402"
"38.64000","3.22026","0.00411"
"38.97600","3.24819","0.00459"
"39.31200","3.27617","0.00459"
"39.64800","3.30421","0.00416"
"39.98400","3.33219","0.00441"
"40.32000","3.36023","0.00440"
"40.65600","3.38821","0.00446"
"40.99200","3.41619","0.00413"
"41.32800","3.44418","0.00403"
"41.66400","3.47216","0.00438"
"42.00000","3.50026","0.00414"
"42.33600","3.52824","0.00425"
"42.67200","3.55622","0.00422"
"43.00800","3.58420","0.00480"
"43.34400","3.61213","0.00484"
"43.68000","3.64023","0.00429"
"44.01600","3.66827","0.00467"
"44.35200","3.69613","0.00414"
"44.68800","3.72423","0.00478"
"45.02400","3.75215","0.00426"
"45.36000","3.78013","0.00454"
"45.69600","3.80823","0.00451"
"46.03200","3.83616","0.00391"
"46.36800","3.86420","0.00487"
"46.70400","3.89224","0.00443"
"47.04000","3.92010","0.00401"
"47.37600","3.94820","0.00442"
"47.71200","3.97618","0.00460"
"48.04800","4.00422","0.00429"
"48.38400","4.03227","0.00488"
"48.72000","4.06019","0.00475"
"49.05600","4.08817","0.00415"
"49.39200","4.11621","0.00456"
"49.72800","4.14419","0.00453"
"50.06400","4.17217","0.00435"
"50.40000","4.20021","0.00469"
"50.73600","4.22820","0.00460"
"51.07200","4.25618","0.00482"
"51.40800","4.28416","0.00441"
"51.74400","4.31220","0.00431"
"52.08000","4.34024","0.00496"
"52.41600","4.36816","0.00463"
"52.75200","4.39620","0.00483"
"53.08800","4.42419","0.00452"
"53.42400","4.45217","0.00442"
"53.76000","4.48021","0.00459"
"54.09600","4.50813","0.00453"
"54.43200","4.53623","0.00453"
"54.76800","4.56421","0.00482"
"55.10400","4.59213","0.00448"
"55.44000","4.62024","0.00490"
"55.77600","4.64822","0.00428"
"56.11200","4.67620","0.00516"
"56.44800","4.70424","0.00455"
"56.78400","4.73216","0.00491"
"57.12000","4.76020","0.00424"
"57.45600","4.78819","0.00434"
"57.79200","4.81617","0.00463"
"58.12800","4.84421","0.00442"
"58.46400","4.87219","0.00488"
"58.80000","4.90017","0.00468"
"59.13600","4.92821","0.00452"
"59.47200","4.95619","0.00494"
"59.80800","4.98412","0.00470"
"60.14400","5.01222","0.00542"
"60.48000","5.04014","0.00465"
"60.81600","5.06824","0.00495"
"61.15200","5.09622","0.00482"
"61.48800","5.12420","0.00451"
"61.82400","5.15224","0.00465"
"62.16000","5.18017","0.00451"
"62.49600","5.20821","0.00505"
"62.83200","5.23619","0.00493"
"63.16800","5.26417","0.00493"
"63.50400","5.29221","0.00490"
"63.84000","5.32019","0.00530"
"64.17600","5.34817","0.00475"
"64.51200","5.37621","0.00506"
"64.84800","5.40420","0.00442"
"65.18400","5.43218","0.00395"
"65.52000","5.46022","0.00432"
"65.85600","5.48820","0.00497"
"66.19200","5.51624","0.00464"
"66.52800","5.54416","0.00430"
"66.86400","5.57221","0.00445"
"67.20000","5.60025","0.00406"
"67.53600","5.62817","0.00477"
"67.87200","5.65621","0.00448"
"68.20800","5.68425","0.00419"
"68.54400","5.71217","0.00441"
"68.88000","5.74021","0.00439"
"69.21600","5.76826","0.00472"
"69.55200","5.79618","0.00472"
"69.88800","5.82422","0.00495"
"70.22400","5.85220","0.00446"
"70.56000","5.88018","0.00454"
"70.89600","5.90816","0.00469"
"71.23200","5.93614","0.00468"
"71.56800","5.96425","0.00441"
"71.90400","5.99223","0.00467"
"72.24000","6.02021","0.00475"
"72.57600","6.04819","0.00460"
"72.91200","6.07611","0.00444"
"73.24800","6.10421","0.00489"
"73.58400","6.13219","0.00420"
"73.92000","6.16017","0.00471"
"74.25600","6.18822","0.00462"
"74.59200","6.21620","0.00437"
"74.92800","6.24418","0.00426"
"75.26400","6.27222","0.00455"
"75.60000","6.30014","0.00412"
"75.93600","6.32818","0.00397"
"76.27200","6.35623","0.00428"
"76.60800","6.38421","0.00466"
"76.94400","6.41219","0.00422"
"77.28000","6.44023","0.00407"
"77.61600","6.46821","0.00432"
"77.95200","6.49625","0.00433"
"78.28800","6.52417","0.00455"
"78.62400","6.55222","0.00430"
"78.96000","6.58020","0.00461"
"79.29600","6.60818","0.00442"
"79.63200","6.63622","0.00452"
"79.96800","6.66420","0.00523"
"80.30400","6.69218","0.00491"
"80.64000","6.72016","0.00459"
"80.97600","6.74821","0.00470"
"81.31200","6.77619","0.00492"
"81.64800","6.80423","0.00456"
"81.98400","6.83221","0.00539"
"82.32000","6.86019","0.00551"
"82.65600","6.88817","0.00495"
"82.99200","6.91621","0.00532"
"83.32800","6.94420","0.00521"
"83.66400","6.97212","0.00535"
"84.00000","7.00022","0.00521"
"84.33600","7.02820","0.00507"
"84.67200","7.05618","0.00549"
"85.00800","7.08422","0.00528"
"85.34400","7.11220","0.00507"
"85.68000","7.14019","0.00497"
"86.01600","7.16823","0.00528"
"86.35200","7.19615","0.00526"
"86.68800","7.22425","0.00478"
"87.02400","7.25223","0.00536"
"87.36000","7.28015","0.00511"
"87.69600","7.30819","0.00473"
"88.03200","7.33618","0.00501"
"88.36800","7.36416","0.00524"
"88.70400","7.39220","0.00531"
"89.04000","7.42018","0.00501"
"89.37600","7.44822","0.00502"
"89.71200","7.47620","0.00531"
"90.04800","7.50418","0.00501"
"90.38400","7.53217","0.00483"
"90.72000","7.56021","0.00510"
"91.05600","7.58819","0.00517"
"91.39200","7.61617","0.00471"
"91.72800","7.64421","0.00510"
"92.06400","7.67219","0.00551"
"92.40000","7.70018","0.00555"
"92.73600","7.72822","0.00531"
"93.07200","7.75620","0.00502"
"93.40800","7.78418","0.00490"
"93.74400","7.81222","0.00526"
"94.08000","7.84020","0.00543"
"94.41600","7.86812","0.00507"
"94.75200","7.89622","0.00482"
"95.08800","7.92421","0.00493"
"95.42400","7.95219","0.00576"
"95.76000","7.98023","0.00520"
"96.09600","8.00815","0.00501"
"96.43200","8.03613","0.00540"
"96.76800","8.06423","0.00463"
"97.10400","8.09215","0.00514"
"97.44000","8.12020","0.00501"
"97.77600","8.14818","0.00549"
"98.11200","8.17616","0.00531"
"98.44800","8.20420","0.00590"
"98.78400","8.23218","0.00504"
"99.12000","8.26016","0.00544"
"99.45600","8.28820","0.00554"
"99.79200","8.31619","0.00530"
"100.12800","8.34423","0.00558"
"100.46400","8.37221","0.00557"
"100.80000","8.40013","0.00530"
"101.13600","8.42829","0.00504"
"101.47200","8.45615","0.00547"
"101.80800","8.48419","0.00533"
"102.14400","8.51224","0.00560"
"102.48000","8.54016","0.00546"
"102.81600","8.56820","0.00555"
"103.15200","8.59624","0.00555"
"103.48800","8.62416","0.00571"
"103.82400","8.65220","0.00530"
"104.16000","8.68013","0.00572"
"104.49600","8.70823","0.00571"
"104.83200","8.73621","0.00588"
"105.16800","8.76413","0.00575"
"105.50400","8.79223","0.00556"
"105.84000","8.82021","0.00596"
"106.17600","8.84819","0.00597"
"106.51200","8.87623","0.00606"
"106.84800","8.90416","0.00632"
"107.18400","8.93220","0.00629"
"107.52000","8.96024","0.00563"
"107.85600","8.98816","0.00599"
"108.19200","9.01620","0.00634"
"108.52800","9.04418","0.00588"
"108.86400","9.07222","0.00616"
"109.20000","9.10021","0.00615"
"109.53600","9.12819","0.00642"
"109.87200","9.15617","0.00618"
"110.20800","9.18421","0.00691"
"110.54400","9.21219","0.00606"
"110.88000","9.24017","0.00650"
"111.21600","9.26822","0.00598"
"111.55200","9.29614","0.00601"
"111.88800","9.32418","0.00620"
"112.22400","9.35216","0.00609"
"112.56000","9.38020","0.00650"
"112.89600","9.40824","0.00653"
"113.23200","9.43616","0.00634"
"113.56800","9.46420","0.00634"
"113.90400","9.49219","0.00661"
"114.24000","9.52017","0.00652"
"114.57600","9.54821","0.00703"
"114.91200","9.57619","0.00691"
"115.24800","9.60423","0.00622"
"115.58400","9.63221","0.00650"
"115.92000","9.66014","0.00598"
"116.25600","9.68824","0.00622"
"116.59200","9.71616","0.00629"
"116.92800","9.74420","0.00679"
"117.26400","9.77224","0.00637"
"117.60000","9.80016","0.00662"
"117.93600","9.82820","0.00679"
"118.27200","9.85624","0.00654"
"118.60800","9.88417","0.00636"
"118.94400","9.91221","0.00647"
"119.28000","9.94025","0.00690"
"119.61600","9.96817","0.00727"
"119.95200","9.99615","0.00683"
"120.28800","10.02419","0.00694"
"120.62400","10.05218","0.00725"
"120.96000","10.08022","0.00764"
"121.29600","10.10814","0.00731"
"121.63200","10.13624","0.00694"
"121.96800","10.16422","0.00724"
"122.30400","10.19214","0.00685"
"122.64000","10.22018","0.00746"
"122.97600","10.24817","0.00691"
"123.31200","10.27627","0.00746"
"123.64800","10.30419","0.00762"
"123.98400","10.33217","0.00781"
"124.32000","10.36021","0.00763"
"124.65600","10.38819","0.00793"
"124.99200","10.41617","0.00800"
"125.32800","10.44422","0.00775"
"125.66400","10.47220","0.00796"
"126.00000","10.50024","0.00786"
"126.33600","10.52828","0.00810"
"126.67200","10.55614","0.00831"
"127.00800","10.58418","0.00828"
"127.34400","10.61222","0.00851"
"127.68000","10.64015","0.00855"
"128.01600","10.66819","0.00846"
"128.35200","10.69623","0.00860"
"128.68800","10.72415","0.00857"
"129.02400","10.75225","0.00857"
"129.36000","10.78017","0.00880"
"129.69600","10.80827","0.00862"
"130.03200","10.83619","0.00884"
"130.36800","10.86418","0.00903"
"130.70400","10.89222","0.00924"
"131.04000","10.92020","0.00909"
"131.37600","10.94824","0.00992"
"131.71200","10.97622","0.00931"
"132.04800","11.00420","0.00954"
"132.38400","11.03224","0.00954"
"132.72000","11.06017","0.00962"
"133.05600","11.08821","0.00947"
"133.39200","11.11619","0.00962"
"133.72800","11.14417","0.00963"
"134.06400","11.17221","0.00979"
"134.40000","11.20019","0.01020"
"134.73600","11.22818","0.00984"
"135.07200","11.25622","0.00966"
"135.40800","11.28420","0.00998"
"135.74400","11.31218","0.01044"
"136.08000","11.34022","0.00993"
"136.41600","11.36814","0.00985"
"136.75200","11.39618","0.01020"
"137.08800","11.42423","0.01008"
"137.42400","11.45215","0.01049"
"137.76000","11.48025","0.01059"
"138.09600","11.50823","0.01081"
"138.43200","11.53621","0.01028"
"138.76800","11.56425","0.01089"
"139.10400","11.59217","0.01077"
"139.44000","11.62022","0.01082"
"139.77600","11.64820","0.01144"
"140.11200","11.67618","0.01076"
"140.44800","11.70422","0.01106"
"140.78400","11.73220","0.01128"
"141.12000","11.76018","0.01175"
"141.45600","11.78816","0.01167"
"141.79200","11.81615","0.01146"
"142.12800","11.84419","0.01197"
"142.46400","11.87223","0.01170"
"142.80000","11.90021","0.01233"
"143.13600","11.92825","0.01197"
"143.47200","11.95617","0.01228"
"143.80800","11.98421","0.01265"
"144.14400","12.01219","0.01249"
"144.48000","12.04018","0.01266"
"144.81600","12.06822","0.01188"
"145.15200","12.09626","0.01230"
"145.48800","12.12412","0.01197"
"145.82400","12.15222","0.01177"
"146.16000","12.18014","0.01216"
"146.49600","12.20819","0.01216"
"146.83200","12.23623","0.01251"
"147.16800","12.26415","0.01229"
"147.50400","12.29219","0.01240"
"147.84000","12.32023","0.01253"
"148.17600","12.34815","0.01259"
"148.51200","12.37625","0.01270"
"148.84800","12.40418","0.01285"
"149.18400","12.43216","0.01308"
"149.52000","12.46020","0.01339"
"149.85600","12.48818","0.01332"
"150.19200","12.51622","0.01312"
"150.52800","12.54420","0.01325"
"150.86400","12.57218","0.01308"
"151.20000","12.60023","0.01316"
"151.53600","12.62821","0.01298"
"151.87200","12.65619","0.01313"
"152.20800","12.68423","0.01356"
"152.54400","12.71215","0.01328"
"152.88000","12.74019","0.01389"
"153.21600","12.76817","0.01331"
"153.55200","12.79616","0.01350"
"153.88800","12.82420","0.01341"
"154.22400","12.85218","0.01386"
"154.56000","12.88016","0.01379"
"154.89600","12.90826","0.01402"
"155.23200","12.93612","0.01401"
"155.56800","12.96422","0.01399"
"155.90400","12.99221","0.01404"
"156.24000","13.02019","0.01429"
"156.57600","13.04823","0.01453"
"156.91200","13.07615","0.01440"
"157.24800","13.10419","0.01475"
"157.58400","13.13223","0.01451"
"157.92000","13.16016","0.01436"
"158.25600","13.18826","0.01408"
"158.59200","13.21618","0.01460"
"158.92800","13.24410","0.01471"
"159.26400","13.27220","0.01450"
"159.60000","13.30024","0.01468"
"159.93600","13.32822","0.01512"
"160.27200","13.35620","0.01479"
"160.60800","13.38419","0.01500"
"160.94400","13.41217","0.01532"
"161.28000","13.44021","0.01558"
"161.61600","13.46819","0.01494"
"161.95200","13.49623","0.01538"
"162.28800","13.52421","0.01545"
"162.62400","13.55220","0.01550"
"162.96000","13.58024","0.01553"
"163.29600","13.60810","0.01564"
"163.63200","13.63626","0.01557"
"163.96800","13.66424","0.01548"
"164.30400","13.69216","0.01599"
"164.64000","13.72026","0.01568"
"164.97600","13.74819","0.01632"
"165.31200","13.77617","0.01601"
"165.64800","13.80421","0.01636"
"165.98400","13.83219","0.01664"
"166.32000","13.86023","0.01628"
"166.65600","13.88821","0.01722"
"166.99200","13.91613","0.01650"
"167.32800","13.94424","0.01725"
"167.66400","13.97222","0.01633"
"168.00000","14.00020","0.01680"
"168.33600","14.02824","0.01724"
"168.67200","14.05616","0.01722"
"169.00800","14.08420","0.01712"
"169.34400","14.11224","0.01726"
"169.68000","14.14016","0.01731"
"170.01600","14.16821","0.01714"
"170.35200","14.19619","0.01718"
"170.68800","14.22423","0.01699"
"171.02400","14.25221","0.01719"
"171.36000","14.28013","0.01749"
"171.69600","14.30817","0.01729"
"172.03200","14.33622","0.01709"
"172.36800","14.36420","0.01734"
"172.70400","14.39224","0.01786"
"173.04000","14.42016","0.01758"
"173.37600","14.44820","0.01762"
"173.71200","14.47624","0.01776"
"174.04800","14.50410","0.01775"
"174.38400","14.53226","0.01801"
"174.72000","14.56019","0.01794"
"175.05600","14.58817","0.01781"
"175.39200","14.61621","0.01795"
"175.72800","14.64419","0.01809"
"176.06400","14.67217","0.01830"
"176.40000","14.70027","0.01811"
"176.73600","14.72814","0.01821"
"177.07200","14.75624","0.01801"
"177.40800","14.78422","0.01893"
"177.74400","14.81214","0.01899"
"178.08000","14.84018","0.01864"
"178.41600","14.86816","0.01887"
"178.75200","14.89620","0.01873"
"179.08800","14.92424","0.01724"
"179.42400","14.95217","0.01759"
"179.76000","14.98021","0.01771"
"180.09600","15.00825","0.01771"
"180.43200","15.03617","0.01808"
"180.76800","15.06421","0.01756"
"181.10400","15.09219","0.01777"
"181.44000","15.12024","0.01743"
"181.77600","15.14822","0.01789"
"182.11200","15.17614","0.01819"
"182.44800","15.20424","0.01809"
"182.78400","15.23216","0.01815"
"183.12000","15.26014","0.01797"
"183.45600","15.28824","0.01825"
"183.79200","15.31617","0.01833"
"184.12800","15.34421","0.01795"
"184.46400","15.37219","0.01767"
"184.80000","15.40011","0.01789"
"185.13600","15.42821","0.01787"
"185.47200","15.45619","0.01776"
"185.80800","15.48417","0.01780"
"186.14400","15.51222","0.01811"
"186.48000","15.54020","0.01812"
"186.81600","15.56818","0.01826"
"187.15200","15.59622","0.01887"
"187.48800","15.62420","0.01860"
"187.82400","15.65218","0.01936"
"188.16000","15.68022","0.01875"
"188.49600","15.70815","0.01880"
"188.83200","15.73619","0.01910"
"189.16800","15.76423","0.01945"
"189.50400","15.79221","0.01952"
"189.84000","15.82025","0.01934"
"190.17600","15.84811","0.01980"
"190.51200","15.87621","0.02001"
"190.84800","15.90413","0.01999"
"191.18400","15.93218","0.02013"
"191.52000","15.96022","0.02023"
"191.85600","15.98814","0.02041"
"192.19200","16.01624","0.02046"
"192.52800","16.04422","0.02004"
"192.86400","16.07214","0.01963"
"193.20000","16.10024","0.02022"
"193.53600","16.12823","0.02058"
"193.87200","16.15621","0.02011"
"194.20800","16.18419","0.02031"
"194.54400","16.21217","0.02009"
"194.88000","16.24021","0.02046"
"195.21600","16.26825","0.02006"
"195.55200","16.29618","0.01967"
"195.88800","16.32422","0.01988"
"196.22400","16.35220","0.01932"
"196.56000","16.38018","0.01974"
"196.89600","16.40822","0.01974"
"197.23200","16.43614","0.01947"
"197.56800","16.46418","0.01973"
"197.90400","16.49223","0.02029"
"198.24000","16.52015","0.02017"
"198.57600","16.54819","0.02035"
"198.91200","16.57617","0.02071"
"199.24800","16.60415","0.02139"
"199.58400","16.63219","0.02178"
"199.92000","16.66017","0.02150"
"200.25600","16.68822","0.02152"
"200.59200","16.71620","0.02136"
"200.92800","16.74418","0.02153"
"201.26400","16.77222","0.02142"
"201.60000","16.80020","0.02213"
"201.93600","16.82818","0.02234"
"202.27200","16.85622","0.02105"
"202.60800","16.88415","0.02191"
"202.94400","16.91219","0.02258"
"203.28000","16.94023","0.02281"
"203.61600","16.96815","0.02278"
"203.95200","16.99619","0.02359"
"204.28800","17.02417","0.02398"
"204.62400","17.05215","0.02434"
"204.96000","17.08026","0.02475"
"205.29600","17.10818","0.02558"
"205.63200","17.13622","0.02532"
"205.96800","17.16426","0.02656"
"206.30400","17.19212","0.02659"
"206.64000","17.22022","0.02667"
"206.97600","17.24820","0.02716"
"207.31200","17.27618","0.02774"
"207.64800","17.30423","0.02853"
"207.98400","17.33221","0.02882"
"208.32000","17.36019","0.02978"
"208.65600","17.38823","0.02969"
"208.99200","17.41615","0.03065"
"209.32800","17.44425","0.03127"
"209.66400","17.47218","0.03183"
"210.00000","17.50016","0.03258"
"210.33600","17.52814","0.03364"
"210.67200","17.55612","0.03454"
"211.00800","17.58422","0.03493"
"211.34400","17.61220","0.03499"
"211.68000","17.64018","0.03630"
"212.01600","17.66822","0.03661"
"212.35200","17.69615","0.03721"
"212.68800","17.72419","0.03766"
"213.02400","17.75223","0.03737"
"213.36000","17.78015","0.03763"
"213.69600","17.80825","0.03674"
"214.03200","17.83623","0.03609"
"214.36800","17.86416","0.03616"
"214.70400","17.89220","0.03693"
"215.04000","17.92018","0.03847"
"215.37600","17.94822","0.03878"
"215.71200","17.97626","0.04036"
"216.04800","18.00412","0.04020"
"216.38400","18.03217","0.04088"
"216.72000","18.06021","0.04182"
"217.05600","18.08813","0.04217"
"217.39200","18.11623","0.04362"
"217.72800","18.14421","0.04354"
"218.06400","18.17213","0.04458"
"218.40000","18.20017","0.04530"
"218.73600","18.22816","0.04633"
"219.07200","18.25620","0.04695"
"219.40800","18.28418","0.04727"
"219.74400","18.31216","0.04827"
"220.08000","18.34020","0.04895"
"220.41600","18.36818","0.04935"
"220.75200","18.39622","0.05009"
"221.08800","18.42420","0.05090"
"221.42400","18.45213","0.05156"
"221.76000","18.48023","0.05237"
"222.09600","18.50821","0.05254"
"222.43200","18.53619","0.05380"
"222.76800","18.56417","0.05403"
"223.10400","18.59215","0.05501"
"223.44000","18.62020","0.05536"
"223.77600","18.64824","0.05548"
"224.11200","18.67610","0.05611"
"224.44800","18.70420","0.05670"
"224.78400","18.73224","0.05719"
"225.12000","18.76016","0.05717"
"225.45600","18.78820","0.05756"
"225.79200","18.81618","0.05800"
"226.12800","18.84417","0.05821"
"226.46400","18.87221","0.05855"
"226.80000","18.90013","0.05904"
"227.13600","18.92823","0.06019"
"227.47200","18.95621","0.06124"
"227.80800","18.98419","0.06233"
"228.14400","19.01217","0.06304"
"228.48000","19.04022","0.06363"
"228.81600","19.06820","0.06424"
"229.15200","19.09618","0.06536"
"229.48800","19.12422","0.06650"
"229.82400","19.15220","0.06786"
"230.16000","19.18024","0.06846"
"230.49600","19.20816","0.06965"
"230.83200","19.23621","0.06856"
"231.16800","19.26419","0.06935"
"231.50400","19.29223","0.07081"
"231.84000","19.32021","0.07214"
"232.17600","19.34813","0.07271"
"232.51200","19.37623","0.07393"
"232.84800","19.40428","0.07547"
"233.18400","19.43214","0.07747"
"233.52000","19.46024","0.07880"
"233.85600","19.48816","0.08050"
"234.19200","19.51620","0.08231"
"234.52800","19.54424","0.08380"
"234.86400","19.57210","0.08514"
"235.20000","19.60020","0.08739"
"235.53600","19.62818","0.08853"
"235.87200","19.65617","0.08978"
"236.20800","19.68421","0.09098"
"236.54400","19.71219","0.09172"
"236.88000","19.74017","0.09269"
"237.21600","19.76821","0.09349"
"237.55200","19.79613","0.09421"
"237.88800","19.82424","0.09568"
"238.22400","19.85222","0.09672"
"238.56000","19.88014","0.09705"
"238.89600","19.90824","0.08959"
"239.23200","19.93622","0.07256"
"239.56800","19.96420","0.06879"
"239.90400","19.99218","0.07013"
"240.24000","20.02017","0.07116"
"240.57600","20.04821","0.07080"
"240.91200","20.07619","0.07265"
"241.24800","20.10417","0.07352"
"241.58400","20.13221","0.07576"
"241.92000","20.16014","0.07713"
"242.25600","20.18823","0.07767"
"242.59200","20.21622","0.08038"
"242.92800","20.24414","0.08340"
"243.26400","20.27224","0.08476"
"243.60000","20.30022","0.08631"
"243.93600","20.32814","0.08745"
"244.27200","20.35624","0.08914"
"244.60800","20.38416","0.09039"
"244.94400","20.41221","0.09159"
"245.28000","20.44025","0.09196"
"245.61600","20.46817","0.09278"
"245.95200","20.49621","0.09397"
"246.28800","20.52419","0.09548"
"246.62400","20.55217","0.09658"
"246.96000","20.58022","0.09758"
"247.29600","20.60820","0.09834"
"247.63200","20.63618","0.09968"
"247.96800","20.66422","0.10044"
"248.30400","20.69220","0.10044"
"248.64000","20.72024","0.10180"
"248.97600","20.74822","0.10275"
"249.31200","20.77615","0.10353"
"249.64800","20.80419","0.10448"
"249.98400","20.83217","0.10539"
"250.32000","20.86021","0.10575"
"250.65600","20.88825","0.10633"
"250.99200","20.91617","0.10700"
"251.32800","20.94421","0.10773"
"251.66400","20.97214","0.10851"
"252.00000","21.00018","0.10909"
"252.33600","21.02822","0.10989"
"252.67200","21.05614","0.11083"
"253.00800","21.08424","0.11263"
"253.34400","21.11216","0.11332"
"253.68000","21.14008","0.11497"
"254.01600","21.16825","0.11595"
"254.35200","21.19617","0.11716"
"254.68800","21.22421","0.11836"
"255.02400","21.25219","0.12015"
"255.36000","21.28023","0.12243"
"255.69600","21.30815","0.12385"
"256.03200","21.33619","0.12610"
"256.36800","21.36418","0.12740"
"256.70400","21.39222","0.12923"
"257.04000","21.42026","0.13218"
"257.37600","21.44818","0.13352"
"257.71200","21.47616","0.13537"
"258.04800","21.50414","0.13757"
"258.38400","21.53225","0.13929"
"258.72000","21.56023","0.14053"
"259.05600","21.58809","0.14283"
"259.39200","21.61619","0.14429"
"259.72800","21.64417","0.14634"
"260.06400","21.67221","0.14804"
"260.40000","21.70019","0.15008"
"260.73600","21.72817","0.15013"
"261.07200","21.75621","0.15098"
"261.40800","21.78419","0.15159"
"261.74400","21.81218","0.15232"
"262.08000","21.84022","0.15463"
"262.41600","21.86820","0.15580"
"262.75200","21.89618","0.15769"
"263.08800","21.92422","0.15907"
"263.42400","21.95215","0.16147"
"263.76000","21.98018","0.16248"
"264.09600","22.00823","0.16425"
"264.43200","22.03615","0.16548"
"264.76800","22.06425","0.16676"
"265.10400","22.09223","0.16829"
"265.44000","22.12016","0.16963"
"265.77600","22.14819","0.17092"
"266.11200","22.17618","0.17193"
"266.44800","22.20428","0.17312"
"266.78400","22.23226","0.17457"
"267.12000","22.26012","0.17591"
"267.45600","22.28822","0.17793"
"267.79200","22.31620","0.17911"
"268.12800","22.34419","0.18054"
"268.46400","22.37223","0.18255"
"268.80000","22.40021","0.18441"
"269.13600","22.42819","0.18579"
"269.47200","22.45617","0.18717"
"269.80800","22.48415","0.18777"
"270.14400","22.51225","0.19013"
"270.48000","22.54018","0.19165"
"270.81600","22.56822","0.19352"
"271.15200","22.59620","0.19507"
"271.48800","22.62418","0.19663"
"271.82400","22.65216","0.19869"
"272.16000","22.68020","0.20002"
"272.49600","22.70812","0.20189"
"272.83200","22.73623","0.20343"
"273.16800","22.76421","0.20449"
"273.50400","22.79219","0.20617"
"273.84000","22.82017","0.20710"
"274.17600","22.84815","0.20823"
"274.51200","22.87619","0.20927"
"274.84800","22.90429","0.21035"
"275.18400","22.93210","0.21079"
"275.52000","22.96026","0.21159"
"275.85600","22.98824","0.21194"
"276.19200","23.01616","0.21223"
"276.52800","23.04426","0.21254"
"276.86400","23.07218","0.21348"
"277.20000","23.10016","0.21487"
"277.53600","23.12821","0.21595"
"277.87200","23.15613","0.21757"
"278.20800","23.18423","0.21937"
"278.54400","23.21221","0.01018"
"278.88000","23.24019","0.00852"
"279.21600","23.26823","0.00403"
"279.55200","23.29616","0.00436"
"279.88800","23.32420","0.00418"
"280.22400","23.35218","0.00596"
"280.56000","23.38022","0.00347"
"280.89600","23.40826","0.00546"
"281.23200","23.43618","0.00235"
"281.56800","23.46416","0.00604"
"281.90400","23.49220","0.00329"
"282.24000","23.52019","0.00539"
"282.57600","23.54823","0.00300"
"282.91200","23.57621","0.00478"
"283.24800","23.60419","0.00411"
"283.58400","23.63223","0.00521"
"283.92000","23.66021","0.00413"
"284.25600","23.68819","0.00487"
"284.59200","23.71624","0.00460"
"284.92800","23.74416","0.00459"
"285.26400","23.77220","0.00441"
"285.60000","23.80024","0.00449"
"285.93600","23.82816","0.00484"
"286.27200","23.85626","0.00545"
"286.60800","23.88418","0.00502"
"286.94400","23.91223","0.00547"
"287.28000","23.94020","0.00474"
"287.61600","23.96819","0.00568"
"287.95200","23.99617","0.00531"
"288.28800","24.02421","0.00558"
"288.62400","24.05219","0.00589"
"288.96000","24.08017","0.00595"
"289.29600","24.10816","0.00556"
"289.63200","24.13620","0.00629"
"289.96800","24.16418","0.00556"
"290.30400","24.19216","0.00606"
"290.64000","24.22020","0.00587"
"290.97600","24.24824","0.00637"
"291.31200","24.27616","0.00628"
"291.64800","24.30427","0.00611"
"291.98400","24.33219","0.00674"
"292.32000","24.36017","0.00677"
"292.65600","24.38821","0.00661"
"292.99200","24.41607","0.00684"
"293.32800","24.44423","0.00684"
"293.66400","24.47227","0.00669"
"294.00000","24.50019","0.00716"
"294.33600","24.52818","0.00724"
"294.67200","24.55616","0.00742"
"295.00800","24.58420","0.00734"
"295.34400","24.61218","0.00751"
"295.68000","24.64017","0.00765"
"296.01600","24.66820","0.00779"
"296.35200","24.69625","0.00815"
"296.68800","24.72411","0.00813"
"297.02400","24.75221","0.00820"
"297.36000","24.78013","0.00806"
"297.69600","24.80817","0.00853"
"298.03200","24.83621","0.00843"
"298.36800","24.86419","0.00891"
"298.70400","24.89218","0.00889"
"299.04000","24.92016","0.00891"
"299.37600","24.94820","0.00924"
"299.71200","24.97618","0.00927"
"300.04800","25.00416","0.00925"
"300.38400","25.03220","0.00946"
"300.72000","25.06019","0.00927"
"301.05600","25.08811","0.00957"
"301.39200","25.11621","0.00979"
"301.72800","25.14419","0.00969"
"302.06400","25.17211","0.00984"
"302.40000","25.20021","0.00978"
"302.73600","25.22820","0.01020"
"303.07200","25.25617","0.01020"
"303.40800","25.28428","0.01035"
"303.74400","25.31214","0.01064"
"304.08000","25.34024","0.01036"
"304.41600","25.36822","0.01071"
"304.75200","25.39620","0.01088"
"305.08800","25.42418","0.01087"
"305.42400","25.45223","0.01103"
"305.76000","25.48021","0.01134"
"306.09600","25.50819","0.01138"
"306.43200","25.53617","0.01152"
"306.76800","25.56421","0.01152"
"307.10400","25.59219","0.01174"
"307.44000","25.62017","0.01185"
"307.77600","25.64821","0.01223"
"308.11200","25.67614","0.01234"
"308.44800","25.70418","0.01212"
"308.78400","25.73222","0.01235"
"309.12000","25.76020","0.01291"
"309.45600","25.78818","0.01262"
"309.79200","25.81623","0.01320"
"310.12800","25.84414","0.01248"
"310.46400","25.87219","0.01283"
"310.80000","25.90017","0.01271"
"311.13600","25.92827","0.01329"
"311.47200","25.95625","0.01322"
"311.80800","25.98417","0.01335"
"312.14400","26.01228","0.01366"
"312.48000","26.04020","0.01390"
"312.81600","26.06817","0.01385"
"313.15200","26.09628","0.01406"
"313.48800","26.12420","0.01427"
"313.82400","26.15218","0.01451"
"314.16000","26.18028","0.01455"
"314.49600","26.20814","0.01405"
"314.83200","26.23619","0.01449"
"315.16800","26.26417","0.01449"
"315.50400","26.29221","0.01477"
"315.84000","26.32019","0.01367"
"316.17600","26.34823","0.01428"
"316.51200","26.37615","0.01374"
"316.84800","26.40419","0.01370"
"317.18400","26.43217","0.01358"
"317.52000","26.46021","0.01377"
"317.85600","26.48820","0.01369"
"318.19200","26.51618","0.01429"
"318.52800","26.54416","0.01407"
"318.86400","26.57220","0.01417"
"319.20000","26.60024","0.01431"
"319.53600","26.62828","0.01380"
"319.87200","26.65615","0.01391"
"320.20800","26.68419","0.01407"
"320.54400","26.71217","0.01369"
"320.88000","26.74015","0.01383"
"321.21600","26.76819","0.01419"
"321.55200","26.79617","0.01408"
"321.88800","26.82421","0.01451"
"322.22400","26.85220","0.01474"
"322.56000","26.88012","0.01497"
"322.89600","26.90816","0.01506"
"323.23200","26.93620","0.01529"
"323.56800","26.96418","0.01560"
"323.90400","26.99222","0.01611"
"324.24000","27.02020","0.01610"
"324.57600","27.04813","0.01604"
"324.91200","27.07623","0.01615"
"325.24800","27.10415","0.01618"
"325.58400","27.13219","0.01654"
"325.92000","27.16023","0.01672"
"326.25600","27.18816","0.01712"
"326.59200","27.21620","0.01708"
"326.92800","27.24418","0.01635"
"327.26400","27.27222","0.01658"
"327.60000","27.30020","0.01685"
"327.93600","27.32818","0.01731"
"328.27200","27.35622","0.01732"
"328.60800","27.38420","0.01720"
"328.94400","27.41219","0.01741"
"329.28000","27.44023","0.01752"
"329.61600","27.46815","0.01789"
"329.95200","27.49625","0.01819"
"330.28800","27.52423","0.01854"
"330.62400","27.55215","0.01924"
"330.96000","27.58020","0.01867"
"331.29600","27.60824","0.01865"
"331.63200","27.63622","0.01911"
"331.96800","27.66420","0.01947"
"332.30400","27.69218","0.01962"
"332.64000","27.72022","0.01899"
"332.97600","27.74826","0.01977"
"333.31200","27.77618","0.01374"
"333.64800","27.80417","0.01245"
"333.98400","27.83221","0.01153"
"334.32000","27.86013","0.01301"
"334.65600","27.88823","0.01275"
"334.99200","27.91621","0.01243"
"335.32800","27.94419","0.01382"
"335.66400","27.97224","0.01293"
"336.00000","28.00016","0.01441"
"336.33600","28.02826","0.01330"
"336.67200","28.05624","0.01439"
"337.00800","28.08416","0.01435"
"337.34400","28.11220","0.01495"
"337.68000","28.14018","0.01508"
"338.01600","28.16817","0.01513"
"338.35200","28.19621","0.01518"
"338.68800","28.22419","0.01472"
"339.02400","28.25223","0.01589"
"339.36000","28.28021","0.01506"
"339.69600","28.30819","0.01578"
"340.03200","28.33617","0.01548"
"340.36800","28.36415","0.01479"
"340.70400","28.39220","0.01513"
"341.04000","28.42024","0.01477"
"341.37600","28.44816","0.01554"
"341.71200","28.47620","0.01496"
"342.04800","28.50418","0.01530"
"342.38400","28.53216","0.01524"
"342.72000","28.56021","0.01539"
"343.05600","28.58818","0.01467"
"343.39200","28.61623","0.01483"
"343.72800","28.64427","0.01451"
"344.06400","28.67219","0.01498"
"344.40000","28.70023","0.01492"
"344.73600","28.72821","0.01534"
"345.07200","28.75613","0.01528"
"345.40800","28.78424","0.01549"
"345.74400","28.81222","0.01555"
"346.08000","28.84020","0.01626"
"346.41600","28.86818","0.01664"
"346.75200","28.89616","0.01680"
"347.08800","28.92426","0.01693"
"347.42400","28.95218","0.01742"
"347.76000","28.98017","0.01739"
"348.09600","29.00821","0.01785"
"348.43200","29.03619","0.01808"
"348.76800","29.06423","0.01813"
"349.10400","29.09221","0.01818"
"349.44000","29.12019","0.01839"
"349.77600","29.14824","0.01881"
"350.11200","29.17616","0.01871"
"350.44800","29.20414","0.01916"
"350.78400","29.23218","0.01893"
"351.12000","29.26016","0.01898"
"351.45600","29.28820","0.01936"
"351.79200","29.31624","0.01898"
"352.12800","29.34417","0.01936"
"352.46400","29.37221","0.01941"
"352.80000","29.40019","0.02036"
"353.13600","29.42817","0.02005"
"353.47200","29.45627","0.02111"
"353.80800","29.48407","0.02084"
"354.14400","29.51223","0.02139"
"354.48000","29.54021","0.02179"
"354.81600","29.56814","0.02139"
"355.15200","29.59624","0.02200"
"355.48800","29.62416","0.02185"
"355.82400","29.65220","0.02222"
"356.16000","29.68018","0.02331"
"356.49600","29.70817","0.02335"
"356.83200","29.73621","0.02357"
"357.16800","29.76425","0.02404"
"357.50400","29.79223","0.02409"
"357.84000","29.82021","0.02474"
"358.17600","29.84819","0.02496"
"358.51200","29.87617","0.02477"
"358.84800","29.90421","0.02486"
"359.18400","29.93214","0.02500"
"359.52000","29.96018","0.02548"
"359.85600","29.98822","0.02610"
"360.19200","30.01614","0.02550"
"360.52800","30.04424","0.02652"
"360.86400","30.07222","0.02666"
"361.20000","30.10015","0.02701"
"361.53600","30.12825","0.02750"
"361.87200","30.15611","0.02776"
"362.20800","30.18421","0.02799"
"362.54400","30.21225","0.02821"
"362.88000","30.24017","0.02847"
"363.21600","30.26822","0.02847"
"363.55200","30.29613","0.02876"
"363.88800","30.32418","0.02887"
"364.22400","30.35222","0.02897"
"364.56000","30.38014","0.02909"
"364.89600","30.40818","0.02922"
"365.23200","30.43622","0.02938"
"365.56800","30.46414","0.02998"
"365.90400","30.49218","0.03025"
"366.24000","30.52017","0.03001"
"366.57600","30.54821","0.03015"
"366.91200","30.57625","0.03075"
"367.24800","30.60417","0.03098"
"367.58400","30.63221","0.03037"
"367.92000","30.66019","0.02519"
"368.25600","30.68818","0.02347"
"368.59200","30.71622","0.02600"
"368.92800","30.74420","0.02414"
"369.26400","30.77224","0.02663"
"369.60000","30.80016","0.02529"
"369.93600","30.82814","0.02705"
"370.27200","30.85625","0.02700"
"370.60800","30.88422","0.02788"
"370.94400","30.91221","0.02847"
"371.28000","30.94025","0.02895"
"371.61600","30.96817","0.03023"
"371.95200","30.99615","0.03024"
"372.28800","31.02419","0.03164"
"372.62400","31.05217","0.03145"
"372.96000","31.08022","0.03232"
"373.29600","31.10819","0.03320"
"373.63200","31.13618","0.03396"
"373.96800","31.16422","0.03450"
"374.30400","31.19220","0.03446"
"374.64000","31.22024","0.03440"
"374.97600","31.24822","0.03538"
"375.31200","31.27620","0.03596"
"375.64800","31.30418","0.03620"
"375.98400","31.33216","0.03780"
"376.32000","31.36015","0.03836"
"376.65600","31.38819","0.03880"
"376.99200","31.41623","0.03874"
"377.32800","31.44415","0.03876"
"377.66400","31.47219","0.03989"
"378.00000","31.50018","0.04080"
"378.33600","31.52822","0.04046"
"378.67200","31.55620","0.04141"
"379.00800","31.58418","0.04228"
"379.34400","31.61222","0.04280"
"379.68000","31.64014","0.04285"
"380.01600","31.66818","0.04357"
"380.35200","31.69622","0.04398"
"380.68800","31.72415","0.04433"
"381.02400","31.75225","0.04525"
"381.36000","31.78017","0.04539"
"381.69600","31.80815","0.04499"
"382.03200","31.83619","0.04519"
"382.36800","31.86417","0.04637"
"382.70400","31.89215","0.04630"
"383.04000","31.92025","0.04646"
"383.37600","31.94812","0.04567"
"383.71200","31.97622","0.04600"
"384.04800","32.00420","0.04683"
"384.38400","32.03218","0.04725"
"384.72000","32.06017","0.04796"
"385.05600","32.08820","0.04798"
"385.39200","32.11618","0.04780"
"385.72800","32.14423","0.04861"
"386.06400","32.17215","0.04933"
"386.40000","32.20025","0.04990"
"386.73600","32.22823","0.04957"
"387.07200","32.25621","0.05047"
"387.40800","32.28426","0.05127"
"387.74400","32.31212","0.05158"
"388.08000","32.34016","0.05228"
"388.41600","32.36826","0.05322"
"388.75200","32.39612","0.05365"
"389.08800","32.42422","0.05403"
"389.42400","32.45214","0.05401"
"389.76000","32.48018","0.05534"
"390.09600","32.50823","0.05636"
"390.43200","32.53621","0.05671"
"390.76800","32.56425","0.05737"
"391.10400","32.59217","0.05798"
"391.44000","32.62015","0.05861"
"391.77600","32.64819","0.05916"
"392.11200","32.67624","0.05951"
"392.44800","32.70415","0.06053"
"392.78400","32.73220","0.06163"
"393.12000","32.76018","0.06193"
"393.45600","32.78816","0.06290"
"393.79200","32.81620","0.06408"
"394.12800","32.84418","0.06449"
"394.46400","32.87223","0.06545"
"394.80000","32.90021","0.06658"
"395.13600","32.92819","0.06750"
"395.47200","32.95623","0.06796"
"395.80800","32.98415","0.06688"
"396.14400","33.01219","0.06716"
"396.48000","33.04023","0.06759"
"396.81600","33.06815","0.06872"
"397.15200","33.09620","0.07003"
"397.48800","33.12412","0.07080"
"397.82400","33.15210","0.07181"
"398.16000","33.18020","0.07230"
"398.49600","33.20818","0.07306"
"398.83200","33.23623","0.07488"
"399.16800","33.26421","0.07562"
"399.50400","33.29213","0.07705"
"399.84000","33.32023","0.07851"
"400.17600","33.34821","0.07875"
"400.51200","33.37619","0.08051"
"400.84800","33.40423","0.08152"
"401.18400","33.43216","0.08215"
"401.52000","33.46020","0.08382"
"401.85600","33.48824","0.08499"
"402.19200","33.51610","0.08590"
"402.52800","33.54426","0.08771"
"402.86400","33.57218","0.08840"
"403.20000","33.60016","0.08928"
"403.53600","33.62820","0.09030"
"403.87200","33.65619","0.09161"
"404.20800","33.68417","0.09256"
"404.54400","33.71227","0.09334"
"404.88000","33.74013","0.09417"
"405.21600","33.76817","0.09546"
"405.55200","33.79622","0.09627"
"405.88800","33.82420","0.09707"
"406.22400","33.85223","0.09758"
"406.56000","33.88021","0.09844"
"406.89600","33.90820","0.09900"
"407.23200","33.93618","0.09969"
"407.56800","33.96416","0.10046"
"407.90400","33.99220","0.10048"
"408.24000","34.02019","0.10100"
"408.57600","34.04816","0.10151"
"408.91200","34.07621","0.10236"
"409.24800","34.10413","0.10271"
"409.58400","34.13223","0.10318"
"409.92000","34.16021","0.10383"
"410.25600","34.18819","0.10420"
"410.59200","34.21623","0.10487"
"410.92800","34.24422","0.10502"
"411.26400","34.27220","0.10543"
"411.60000","34.30024","0.10553"
"411.93600","34.32822","0.10521"
"412.27200","34.35620","0.02924"
"412.60800","34.38424","0.03972"
"412.94400","34.41216","0.03266"
"413.28000","34.44027","0.03299"
"413.61600","34.46825","0.04145"
"413.95200","34.49617","0.04079"
"414.28800","34.52421","0.03391"
"414.62400","34.55219","0.04584"
"414.96000","34.58017","0.04209"
"415.29600","34.60822","0.04303"
"415.63200","34.63614","0.04168"
"415.96800","34.66423","0.04924"
"416.30400","34.69222","0.04348"
"416.64000","34.72020","0.04656"
"416.97600","34.74818","0.04757"
"417.31200","34.77616","0.05036"
"417.64800","34.80420","0.04767"
"417.98400","34.83224","0.04946"
"418.32000","34.86017","0.05305"
"418.65600","34.88821","0.05195"
"418.99200","34.91613","0.05472"
"419.32800","34.94417","0.05211"
"419.66400","34.97221","0.05765"
"420.00000","35.00019","0.05374"
"420.33600","35.02818","0.05954"
"420.67200","35.05622","0.05548"
"421.00800","35.08414","0.06066"
"421.34400","35.11218","0.05687"
"421.68000","35.14016","0.06027"
"422.01600","35.16814","0.05921"
"422.35200","35.19624","0.05995"
"422.68800","35.22417","0.06111"
"423.02400","35.25215","0.06080"
"423.36000","35.28019","0.06401"
"423.69600","35.30817","0.06159"
"424.03200","35.33621","0.06643"
"424.36800","35.36419","0.06410"
"424.70400","35.39218","0.06694"
"425.04000","35.42016","0.06649"
"425.37600","35.44820","0.06852"
"425.71200","35.47618","0.06977"
"426.04800","35.50422","0.06929"
"426.38400","35.53220","0.07237"
"426.72000","35.56018","0.07116"
"427.05600","35.58817","0.07414"
"427.39200","35.61621","0.07235"
"427.72800","35.64425","0.07473"
"428.06400","35.67217","0.07530"
"428.40000","35.70021","0.07285"
"428.73600","35.72820","0.07518"
"429.07200","35.75618","0.07482"
"429.40800","35.78421","0.07764"
"429.74400","35.81219","0.07745"
"430.08000","35.84018","0.07786"
"430.41600","35.86822","0.07777"
"430.75200","35.89614","0.07824"
"431.08800","35.92418","0.07892"
"431.42400","35.95222","0.07903"
"431.76000","35.98021","0.08088"
"432.09600","36.00825","0.08174"
"432.43200","36.03617","0.08221"
"432.76800","36.06415","0.08382"
"433.10400","36.09225","0.08471"
"433.44000","36.12017","0.08598"
"433.77600","36.14821","0.08566"
"434.11200","36.17625","0.08724"
"434.44800","36.20412","0.08784"
"434.78400","36.23216","0.08869"
"435.12000","36.26020","0.08385"
"435.45600","36.28818","0.07238"
"435.79200","36.31622","0.07239"
"436.12800","36.34420","0.07341"
"436.46400","36.37218","0.07491"
"436.80000","36.40023","0.07567"
"437.13600","36.42815","0.07827"
"437.47200","36.45619","0.07867"
"437.80800","36.48417","0.08097"
"438.14400","36.51221","0.08222"
"438.48000","36.54020","0.08353"
"438.81600","36.56818","0.08593"
"439.15200","36.59622","0.08631"
"439.48800","36.62426","0.08814"
"439.82400","36.65218","0.08786"
"440.16000","36.68022","0.08936"
"440.49600","36.70814","0.08247"
"440.83200","36.73618","0.07951"
"441.16800","36.76423","0.08141"
"441.50400","36.79215","0.08154"
"441.84000","36.82025","0.08289"
"442.17600","36.84823","0.08528"
"442.51200","36.87609","0.08694"
"442.84800","36.90419","0.08840"
"443.18400","36.93217","0.08967"
"443.52000","36.96016","0.09068"
"443.85600","36.98826","0.09036"
"444.19200","37.01618","0.09165"
"444.52800","37.04422","0.09244"
"444.86400","37.07220","0.09364"
"445.20000","37.10018","0.09445"
"445.53600","37.12817","0.09563"
"445.87200","37.15620","0.09596"
"446.20800","37.18419","0.09632"
"446.54400","37.21223","0.09696"
"446.88000","37.24015","0.09849"
"447.21600","37.26819","0.09835"
"447.55200","37.29623","0.09874"
"447.88800","37.32421","0.09967"
"448.22400","37.35220","0.10009"
"448.56000","37.38018","0.10095"
"448.89600","37.40822","0.10145"
"449.23200","37.43620","0.10230"
"449.56800","37.46412","0.10320"
"449.90400","37.49222","0.10347"
"450.24000","37.52020","0.10434"
"450.57600","37.54813","0.10495"
"450.91200","37.57623","0.10586"
"451.24800","37.60415","0.10612"
"451.58400","37.63219","0.10656"
"451.92000","37.66023","0.10688"
"452.25600","37.68816","0.10715"
"452.59200","37.71619","0.10771"
"452.92800","37.74417","0.10831"
"453.26400","37.77222","0.10880"
"453.60000","37.80020","0.10919"
"453.93600","37.82818","0.10926"
"454.27200","37.85610","0.10988"
"454.60800","37.88426","0.11015"
"454.94400","37.91219","0.11096"
"455.28000","37.94017","0.11215"
"455.61600","37.96827","0.11162"
"455.95200","37.99613","0.11331"
"456.28800","38.02423","0.11367"
"456.62400","38.05221","0.11406"
"456.96000","38.08019","0.11623"
"457.29600","38.10823","0.11667"
"457.63200","38.13615","0.11810"
"457.96800","38.16420","0.11146"
"458.30400","38.19218","0.11131"
"458.64000","38.22016","0.11263"
"458.97600","38.24820","0.11375"
"459.31200","38.27618","0.11405"
"459.64800","38.30423","0.11583"
"459.98400","38.33221","0.11651"
"460.32000","38.36007","0.11798"
"460.65600","38.38823","0.12062"
"460.99200","38.41621","0.12039"
"461.32800","38.44419","0.12287"
"461.66400","38.47223","0.12389"
"462.00000","38.50016","0.12444"
"462.33600","38.52814","0.12685"
"462.67200","38.55624","0.12776"
"463.00800","38.58416","0.12861"
"463.34400","38.61220","0.13165"
"463.68000","38.64018","0.13260"
"464.01600","38.66816","0.13279"
"464.35200","38.69621","0.13482"
"464.68800","38.72419","0.13627"
"465.02400","38.75223","0.13731"
"465.36000","38.78021","0.13969"
"465.69600","38.80813","0.13950"
"466.03200","38.83624","0.14129"
"466.36800","38.86422","0.14290"
"466.70400","38.89214","0.14400"
"467.04000","38.92017","0.14536"
"467.37600","38.94822","0.14755"
"467.71200","38.97620","0.14799"
"468.04800","39.00424","0.14953"
"468.38400","39.03216","0.15019"
"468.72000","39.06020","0.15115"
"469.05600","39.08825","0.15039"
"469.39200","39.11622","0.15191"
"469.72800","39.14420","0.14935"
"470.06400","39.17213","0.14997"
"470.40000","39.20023","0.15169"
"470.73600","39.22827","0.15214"
"471.07200","39.25613","0.15293"
"471.40800","39.28423","0.15339"
"471.74400","39.31221","0.12693"
"472.08000","39.34014","0.12676"
"472.41600","39.36824","0.12768"
"472.75200","39.39621","0.13172"
"473.08800","39.42420","0.13196"
"473.42400","39.45218","0.13521"
"473.76000","39.48016","0.13861"
"474.09600","39.50820","0.13700"
"474.43200","39.53625","0.14055"
"474.76800","39.56417","0.14330"
"475.10400","39.59221","0.14377"
"475.44000","39.62019","0.14562"
"475.77600","39.64823","0.14945"
"476.11200","39.67615","0.14932"
"476.44800","39.70420","0.15162"
"476.78400","39.73223","0.15278"
"477.12000","39.76022","0.15358"
"477.45600","39.78820","0.15195"
"477.79200","39.81618","0.15297"
"478.12800","39.84410","0.15404"
"478.46400","39.87221","0.15668"
"478.80000","39.90019","0.15780"
"479.13600","39.92817","0.15914"
"479.47200","39.95620","0.16108"
"479.80800","39.98419","0.16137"
"480.14400","40.01217","0.15949"
"480.48000","40.04015","0.16013"
"480.81600","40.06820","0.16167"
"481.15200","40.09618","0.14676"
"481.48800","40.12421","0.15069"
"481.82400","40.15214","0.15055"
"482.16000","40.18024","0.15240"
"482.49600","40.20822","0.15554"
"482.83200","40.23621","0.15515"
"483.16800","40.26424","0.15703"
"483.50400","40.29222","0.15969"
"483.84000","40.32014","0.16029"
"484.17600","40.34819","0.16159"
"484.51200","40.37617","0.16379"
"484.84800","40.40421","0.16416"
"485.18400","40.43219","0.16536"
"485.52000","40.46018","0.16730"
"485.85600","40.48816","0.16660"
"486.19200","40.51614","0.16863"
"486.52800","40.54418","0.16945"
"486.86400","40.57222","0.17034"
"487.20000","40.60020","0.17145"
"487.53600","40.62824","0.17281"
"487.87200","40.65617","0.17326"
"488.20800","40.68415","0.16406"
"488.54400","40.71219","0.16237"
"488.88000","40.74017","0.15414"
"489.21600","40.76821","0.13751"
"489.55200","40.79620","0.13552"
"489.88800","40.82417","0.13452"
"490.22400","40.85221","0.13571"
"490.56000","40.88020","0.13355"
"490.89600","40.90818","0.13510"
"491.23200","40.93622","0.13840"
"491.56800","40.96414","0.14011"
"491.90400","40.99218","0.14220"
"492.24000","41.02022","0.14424"
"492.57600","41.04815","0.14553"
"492.91200","41.07625","0.14721"
"493.24800","41.10417","0.14888"
"493.58400","41.13214","0.14998"
"493.92000","41.16019","0.15208"
"494.25600","41.18817","0.15406"
"494.59200","41.21621","0.15508"
"494.92800","41.24420","0.15696"
"495.26400","41.27218","0.15838"
"495.60000","41.30022","0.15955"
"495.93600","41.32820","0.16114"
"496.27200","41.35624","0.16172"
"496.60800","41.38422","0.16317"
"496.94400","41.41214","0.16404"
"497.28000","41.44019","0.16522"
"497.61600","41.46822","0.16550"
"497.95200","41.49615","0.16641"
"498.28800","41.52419","0.16719"
"498.62400","41.55217","0.16788"
"498.96000","41.58015","0.16919"
"499.29600","41.60825","0.17026"
"499.63200","41.63612","0.17027"
"499.96800","41.66421","0.17211"
"500.30400","41.69226","0.17317"
"500.64000","41.72018","0.17342"
"500.71200","41.72622","0.17442"