File: Force_trajectories/161216/Specimen_RawData_3.csv
End date,"12/16/2016"
Specimen label,"6DG_Unk"
Maximum Load,"0.12815",N

Time,Extension,Load
(s),(mm),(N)
"0.00000","0.00000","0.00001"
"0.24000","0.01842","0.00071"
"0.48000","0.04024","0.00084"
"0.72000","0.06027","0.00020"
"0.96000","0.08018","0.00070"
"1.20000","0.10021","0.00073"
"1.44000","0.12024","0.00013"
"1.68000","0.14021","0.00037"
"1.92000","0.16024","0.00062"
"2.16000","0.18015","0.00075"
"2.40000","0.20018","0.00045"
"2.64000","0.22015","0.00045"
"2.88000","0.24023","0.00050"
"3.12000","0.26020","0.00025"
"3.36000","0.28017","0.00049"
"3.60000","0.30020","0.00021"
"3.84000","0.32017","0.00063"
"4.08000","0.34026","0.00028"
"4.32000","0.36017","0.00065"
"4.56000","0.38020","0.00075"
"4.80000","0.40017","0.00116"
"5.04000","0.42020","0.00063"
"5.28000","0.44011","0.00041"
"5.52000","0.46014","0.00044"
"5.76000","0.48017","0.00078"
"6.00000","0.50020","0.00104"
"6.24000","0.52023","0.00085"
"6.48000","0.54020","0.00075"
"6.72000","0.56017","0.00079"
"6.96000","0.58008","0.00024"
"7.20000","0.60023","0.00077"
"7.44000","0.62020","0.00086"
"7.68000","0.64023","0.00079"
"7.92000","0.66020","0.00132"
"8.16000","0.68017","0.00117"
"8.40000","0.70020","0.00102"
"8.64000","0.72022","0.00078"
"8.88000","0.74025","0.00088"
"9.12000","0.76010","0.00094"
"9.36000","0.78025","0.00112"
"9.60000","0.80016","0.00116"
"9.84000","0.82019","0.00113"
"10.08000","0.84016","0.00126"
"10.32000","0.86019","0.00118"
"10.56000","0.88022","0.00135"
"10.80000","0.90019","0.00103"
"11.04000","0.92022","0.00141"
"11.28000","0.94013","0.00139"
"11.52000","0.96022","0.00117"
"11.76000","0.98019","0.00147"
"12.00000","1.00022","0.00122"
"12.24000","1.02019","0.00137"
"12.48000","1.04022","0.00160"
"12.72000","1.06019","0.00131"
"12.96000","1.08022","0.00125"
"13.20000","1.10019","0.00168"
"13.44000","1.12010","0.00108"
"13.68000","1.14019","0.00161"
"13.92000","1.16016","0.00106"
"14.16000","1.18019","0.00149"
"14.40000","1.20022","0.00164"
"14.64000","1.22024","0.00182"
"14.88000","1.24021","0.00167"
"15.12000","1.26018","0.00168"
"15.36000","1.28015","0.00179"
"15.60000","1.30012","0.00158"
"15.84000","1.32021","0.00188"
"16.08000","1.34018","0.00195"
"16.32000","1.36021","0.00164"
"16.56000","1.38018","0.00145"
"16.80000","1.40021","0.00190"
"17.04000","1.42018","0.00178"
"17.28000","1.44021","0.00156"
"17.52000","1.46024","0.00166"
"17.76000","1.48015","0.00162"
"18.00000","1.50018","0.00192"
"18.24000","1.52015","0.00197"
"18.48000","1.54018","0.00188"
"18.72000","1.56015","0.00194"
"18.96000","1.58018","0.00182"
"19.20000","1.60021","0.00220"
"19.44000","1.62024","0.00203"
"19.68000","1.64027","0.00158"
"19.92000","1.66012","0.00174"
"20.16000","1.68015","0.00214"
"20.40000","1.70018","0.00216"
"20.64000","1.72020","0.00233"
"20.88000","1.74017","0.00231"
"21.12000","1.76020","0.00216"
"21.36000","1.78017","0.00176"
"21.60000","1.80014","0.00207"
"21.84000","1.82023","0.00210"
"22.08000","1.84014","0.00224"
"22.32000","1.86017","0.00192"
"22.56000","1.88020","0.00245"
"22.80000","1.90017","0.00254"
"23.04000","1.92014","0.00276"
"23.28000","1.94023","0.00265"
"23.52000","1.96020","0.00235"
"23.76000","1.98017","0.00242"
"24.00000","2.00026","0.00215"
"24.24000","2.02017","0.00217"
"24.48000","2.04020","0.00269"
"24.72000","2.06017","0.00238"
"24.96000","2.08026","0.00262"
"25.20000","2.10017","0.00278"
"25.44000","2.12026","0.00257"
"25.68000","2.14023","0.00203"
"25.92000","2.16014","0.00251"
"26.16000","2.18023","0.00264"
"26.40000","2.20014","0.00205"
"26.64000","2.22022","0.00276"
"26.88000","2.24013","0.00223"
"27.12000","2.26016","0.00234"
"27.36000","2.28013","0.00266"
"27.60000","2.30016","0.00258"
"27.84000","2.32019","0.00275"
"28.08000","2.34016","0.00232"
"28.32000","2.36019","0.00272"
"28.56000","2.38016","0.00274"
"28.80000","2.40019","0.00292"
"29.04000","2.42016","0.00296"
"29.28000","2.44025","0.00311"
"29.52000","2.46016","0.00316"
"29.76000","2.48019","0.00271"
"30.00000","2.50022","0.00312"
"30.24000","2.52019","0.00331"
"30.48000","2.54022","0.00304"
"30.72000","2.56019","0.00271"
"30.96000","2.58022","0.00292"
"31.20000","2.60019","0.00320"
"31.44000","2.62022","0.00295"
"31.68000","2.64013","0.00316"
"31.92000","2.66022","0.00352"
"32.16000","2.68025","0.00299"
"32.40000","2.70021","0.00310"
"32.64000","2.72018","0.00274"
"32.88000","2.74021","0.00297"
"33.12000","2.76018","0.00318"
"33.36000","2.78009","0.00326"
"33.60000","2.80024","0.00306"
"33.84000","2.82015","0.00348"
"34.08000","2.84024","0.00346"
"34.32000","2.86021","0.00324"
"34.56000","2.88018","0.00319"
"34.80000","2.90021","0.00335"
"35.04000","2.92018","0.00311"
"35.28000","2.94021","0.00362"
"35.52000","2.96006","0.00345"
"35.76000","2.98021","0.00377"
"36.00000","3.00012","0.00375"
"36.24000","3.02021","0.00349"
"36.48000","3.04024","0.00329"
"36.72000","3.06021","0.00404"
"36.96000","3.08018","0.00366"
"37.20000","3.10021","0.00352"
"37.44000","3.12018","0.00383"
"37.68000","3.14015","0.00420"
"37.92000","3.16018","0.00336"
"38.16000","3.18021","0.00343"
"38.40000","3.20023","0.00364"
"38.64000","3.22014","0.00375"
"38.88000","3.24017","0.00371"
"39.12000","3.26020","0.00411"
"39.36000","3.28017","0.00376"
"39.60000","3.30026","0.00342"
"39.84000","3.32017","0.00421"
"40.08000","3.34020","0.00412"
"40.32000","3.36011","0.00358"
"40.56000","3.38020","0.00397"
"40.80000","3.40017","0.00374"
"41.04000","3.42020","0.00438"
"41.28000","3.44017","0.00414"
"41.52000","3.46020","0.00395"
"41.76000","3.48023","0.00395"
"42.00000","3.50014","0.00395"
"42.24000","3.52023","0.00396"
"42.48000","3.54020","0.00442"
"42.72000","3.56023","0.00415"
"42.96000","3.58020","0.00421"
"43.20000","3.60023","0.00446"
"43.44000","3.62020","0.00444"
"43.68000","3.64017","0.00402"
"43.92000","3.66020","0.00396"
"44.16000","3.68011","0.00406"
"44.40000","3.70019","0.00457"
"44.64000","3.72022","0.00417"
"44.88000","3.74019","0.00473"
"45.12000","3.76022","0.00415"
"45.36000","3.78019","0.00391"
"45.60000","3.80016","0.00412"
"45.84000","3.82019","0.00420"
"46.08000","3.84022","0.00425"
"46.32000","3.86013","0.00519"
"46.56000","3.88016","0.00490"
"46.80000","3.90019","0.00439"
"47.04000","3.92022","0.00461"
"47.28000","3.94019","0.00425"
"47.52000","3.96022","0.00492"
"47.76000","3.98019","0.00449"
"48.00000","4.00016","0.00491"
"48.24000","4.02019","0.00488"
"48.48000","4.04016","0.00481"
"48.72000","4.06019","0.00485"
"48.96000","4.08022","0.00463"
"49.20000","4.10019","0.00461"
"49.44000","4.12016","0.00498"
"49.68000","4.14031","0.00475"
"49.92000","4.16016","0.00442"
"50.16000","4.18018","0.00473"
"50.40000","4.20021","0.00441"
"50.64000","4.22018","0.00456"
"50.88000","4.24021","0.00445"
"51.12000","4.26012","0.00513"
"51.36000","4.28021","0.00498"
"51.60000","4.30024","0.00520"
"51.84000","4.32021","0.00511"
"52.08000","4.34018","0.00537"
"52.32000","4.36015","0.00507"
"52.56000","4.38024","0.00486"
"52.80000","4.40021","0.00530"
"53.04000","4.42024","0.00516"
"53.28000","4.44015","0.00537"
"53.52000","4.46018","0.00462"
"53.76000","4.48015","0.00527"
"54.00000","4.50018","0.00526"
"54.24000","4.52015","0.00512"
"54.48000","4.54024","0.00546"
"54.72000","4.56021","0.00556"
"54.96000","4.58018","0.00531"
"55.20000","4.60021","0.00559"
"55.44000","4.62018","0.00487"
"55.68000","4.64021","0.00554"
"55.92000","4.66018","0.00494"
"56.16000","4.68021","0.00569"
"56.40000","4.70017","0.00568"
"56.64000","4.72014","0.00520"
"56.88000","4.74017","0.00547"
"57.12000","4.76020","0.00526"
"57.36000","4.78023","0.00591"
"57.60000","4.80020","0.00560"
"57.84000","4.82023","0.00540"
"58.08000","4.84014","0.00523"
"58.32000","4.86023","0.00556"
"58.56000","4.88020","0.00553"
"58.80000","4.90023","0.00538"
"59.04000","4.92020","0.00526"
"59.28000","4.94017","0.00557"
"59.52000","4.96020","0.00549"
"59.76000","4.98011","0.00553"
"60.00000","5.00026","0.00619"
"60.24000","5.02017","0.00577"
"60.48000","5.04020","0.00569"
"60.72000","5.06017","0.00577"
"60.96000","5.08014","0.00596"
"61.20000","5.10017","0.00608"
"61.44000","5.12020","0.00592"
"61.68000","5.14023","0.00597"
"61.92000","5.16020","0.00590"
"62.16000","5.18028","0.00619"
"62.40000","5.20019","0.00571"
"62.64000","5.22016","0.00560"
"62.88000","5.24019","0.00618"
"63.12000","5.26022","0.00592"
"63.36000","5.28019","0.00565"
"63.60000","5.30022","0.00563"
"63.84000","5.32019","0.00589"
"64.08000","5.34016","0.00586"
"64.32000","5.36025","0.00603"
"64.56000","5.38016","0.00600"
"64.80000","5.40019","0.00558"
"65.04000","5.42016","0.00593"
"65.28000","5.44019","0.00591"
"65.52000","5.46016","0.00592"
"65.76000","5.48025","0.00546"
"66.00000","5.50022","0.00645"
"66.24000","5.52013","0.00581"
"66.48000","5.54022","0.00601"
"66.72000","5.56013","0.00638"
"66.96000","5.58022","0.00625"
"67.20000","5.60013","0.00617"
"67.44000","5.62022","0.00635"
"67.68000","5.64019","0.00603"
"67.92000","5.66022","0.00596"
"68.16000","5.68024","0.00558"
"68.40000","5.70015","0.00582"
"68.64000","5.72018","0.00561"
"68.88000","5.74015","0.00604"
"69.12000","5.76018","0.00629"
"69.36000","5.78009","0.00640"
"69.60000","5.80024","0.00576"
"69.84000","5.82015","0.00579"
"70.08000","5.84018","0.00585"
"70.32000","5.86027","0.00616"
"70.56000","5.88018","0.00614"
"70.80000","5.90021","0.00579"
"71.04000","5.92012","0.00604"
"71.28000","5.94015","0.00587"
"71.52000","5.96018","0.00626"
"71.76000","5.98021","0.00624"
"72.00000","6.00018","0.00590"
"72.24000","6.02021","0.00527"
"72.48000","6.04018","0.00573"
"72.72000","6.06015","0.00625"
"72.96000","6.08024","0.00657"
"73.20000","6.10021","0.00581"
"73.44000","6.12018","0.00601"
"73.68000","6.14015","0.00623"
"73.92000","6.16017","0.00574"
"74.16000","6.18014","0.00573"
"74.40000","6.20017","0.00598"
"74.64000","6.22020","0.00630"
"74.88000","6.24017","0.00642"
"75.12000","6.26026","0.00601"
"75.36000","6.28017","0.00624"
"75.60000","6.30020","0.00639"
"75.84000","6.32011","0.00598"
"76.08000","6.34020","0.00641"
"76.32000","6.36017","0.00640"
"76.56000","6.38020","0.00668"
"76.80000","6.40023","0.00677"
"77.04000","6.42020","0.00593"
"77.28000","6.44023","0.00648"
"77.52000","6.46020","0.00696"
"77.76000","6.48023","0.00628"
"78.00000","6.50014","0.00664"
"78.24000","6.52023","0.00672"
"78.48000","6.54014","0.00594"
"78.72000","6.56017","0.00616"
"78.96000","6.58020","0.00667"
"79.20000","6.60017","0.00630"
"79.44000","6.62020","0.00674"
"79.68000","6.64017","0.00602"
"79.92000","6.66019","0.00634"
"80.16000","6.68016","0.00640"
"80.40000","6.70019","0.00629"
"80.64000","6.72022","0.00683"
"80.88000","6.74019","0.00610"
"81.12000","6.76022","0.00652"
"81.36000","6.78019","0.00625"
"81.60000","6.80016","0.00668"
"81.84000","6.82019","0.00671"
"82.08000","6.84022","0.00609"
"82.32000","6.86019","0.00663"
"82.56000","6.88022","0.00678"
"82.80000","6.90019","0.00700"
"83.04000","6.92022","0.00675"
"83.28000","6.94019","0.00681"
"83.52000","6.96022","0.00676"
"83.76000","6.98019","0.00641"
"84.00000","7.00016","0.00695"
"84.24000","7.02019","0.00676"
"84.48000","7.04010","0.00643"
"84.72000","7.06019","0.00663"
"84.96000","7.08016","0.00681"
"85.20000","7.10025","0.00667"
"85.44000","7.12022","0.00677"
"85.68000","7.14025","0.00653"
"85.92000","7.16016","0.00713"
"86.16000","7.18018","0.00727"
"86.40000","7.20027","0.00706"
"86.64000","7.22012","0.00675"
"86.88000","7.24021","0.00709"
"87.12000","7.26018","0.00715"
"87.36000","7.28021","0.00747"
"87.60000","7.30018","0.00737"
"87.84000","7.32021","0.00711"
"88.08000","7.34018","0.00662"
"88.32000","7.36015","0.00678"
"88.56000","7.38024","0.00726"
"88.80000","7.40009","0.00666"
"89.04000","7.42018","0.00649"
"89.28000","7.44021","0.00743"
"89.52000","7.46024","0.00720"
"89.76000","7.48021","0.00729"
"90.00000","7.50018","0.00703"
"90.24000","7.52021","0.00694"
"90.48000","7.54018","0.00683"
"90.72000","7.56021","0.00691"
"90.96000","7.58012","0.00749"
"91.20000","7.60021","0.00744"
"91.44000","7.62018","0.00716"
"91.68000","7.64021","0.00691"
"91.92000","7.66012","0.00726"
"92.16000","7.68021","0.00752"
"92.40000","7.70023","0.00737"
"92.64000","7.72020","0.00718"
"92.88000","7.74017","0.00704"
"93.12000","7.76014","0.00780"
"93.36000","7.78017","0.00752"
"93.60000","7.80020","0.00768"
"93.84000","7.82023","0.00739"
"94.08000","7.84014","0.00795"
"94.32000","7.86023","0.00772"
"94.56000","7.88020","0.00792"
"94.80000","7.90017","0.00771"
"95.04000","7.92020","0.00757"
"95.28000","7.94017","0.00764"
"95.52000","7.96026","0.00762"
"95.76000","7.98017","0.00818"
"96.00000","8.00026","0.00770"
"96.24000","8.02017","0.00791"
"96.48000","8.04020","0.00771"
"96.72000","8.06017","0.00786"
"96.96000","8.08020","0.00795"
"97.20000","8.10017","0.00760"
"97.44000","8.12020","0.00759"
"97.68000","8.14017","0.00817"
"97.92000","8.16013","0.00740"
"98.16000","8.18028","0.00806"
"98.40000","8.20013","0.00783"
"98.64000","8.22022","0.00798"
"98.88000","8.24025","0.00841"
"99.12000","8.26022","0.00787"
"99.36000","8.28019","0.00831"
"99.60000","8.30016","0.00846"
"99.84000","8.32019","0.00784"
"100.08000","8.34016","0.00863"
"100.32000","8.36019","0.00879"
"100.56000","8.38016","0.00839"
"100.80000","8.40025","0.00823"
"101.04000","8.42022","0.00831"
"101.28000","8.44025","0.00829"
"101.52000","8.46016","0.00894"
"101.76000","8.48019","0.00842"
"102.00000","8.50022","0.00885"
"102.24000","8.52013","0.00874"
"102.48000","8.54022","0.00885"
"102.72000","8.56019","0.00870"
"102.96000","8.58028","0.00846"
"103.20000","8.60019","0.00862"
"103.44000","8.62016","0.00872"
"103.68000","8.64019","0.00893"
"103.92000","8.66022","0.00832"
"104.16000","8.68024","0.00911"
"104.40000","8.70015","0.00879"
"104.64000","8.72024","0.00899"
"104.88000","8.74015","0.00888"
"105.12000","8.76018","0.00890"
"105.36000","8.78021","0.00934"
"105.60000","8.80018","0.00910"
"105.84000","8.82021","0.00920"
"106.08000","8.84018","0.00939"
"106.32000","8.86015","0.00931"
"106.56000","8.88012","0.00927"
"106.80000","8.90021","0.00962"
"107.04000","8.92018","0.00941"
"107.28000","8.94021","0.00945"
"107.52000","8.96018","0.00961"
"107.76000","8.98021","0.00935"
"108.00000","9.00018","0.00941"
"108.24000","9.02021","0.00943"
"108.48000","9.04018","0.00953"
"108.72000","9.06021","0.00989"
"108.96000","9.08024","0.00983"
"109.20000","9.10015","0.00944"
"109.44000","9.12018","0.00940"
"109.68000","9.14021","0.00960"
"109.92000","9.16023","0.00969"
"110.16000","9.18014","0.00969"
"110.40000","9.20017","0.00967"
"110.64000","9.22020","0.00976"
"110.88000","9.24017","0.00986"
"111.12000","9.26020","0.01038"
"111.36000","9.28017","0.00994"
"111.60000","9.30020","0.00957"
"111.84000","9.32017","0.01000"
"112.08000","9.34020","0.00991"
"112.32000","9.36017","0.00993"
"112.56000","9.38014","0.01027"
"112.80000","9.40023","0.00997"
"113.04000","9.42014","0.01006"
"113.28000","9.44023","0.01001"
"113.52000","9.46014","0.01074"
"113.76000","9.48017","0.01048"
"114.00000","9.50014","0.01026"
"114.24000","9.52023","0.01076"
"114.48000","9.54020","0.01046"
"114.72000","9.56017","0.01045"
"114.96000","9.58026","0.00995"
"115.20000","9.60011","0.01062"
"115.44000","9.62020","0.01028"
"115.68000","9.64017","0.01019"
"115.92000","9.66019","0.01087"
"116.16000","9.68022","0.01095"
"116.40000","9.70019","0.01047"
"116.64000","9.72016","0.01128"
"116.88000","9.74019","0.01042"
"117.12000","9.76022","0.01044"
"117.36000","9.78013","0.01050"
"117.60000","9.80016","0.01038"
"117.84000","9.82013","0.01071"
"118.08000","9.84022","0.01076"
"118.32000","9.86013","0.01037"
"118.56000","9.88028","0.01080"
"118.80000","9.90019","0.01043"
"119.04000","9.92022","0.01111"
"119.28000","9.94025","0.01100"
"119.52000","9.96016","0.01050"
"119.76000","9.98025","0.00998"
"120.00000","10.00010","0.00995"
"120.24000","10.02019","0.01051"
"120.48000","10.04016","0.01010"
"120.72000","10.06025","0.00975"
"120.96000","10.08016","0.01037"
"121.20000","10.10019","0.00987"
"121.44000","10.12027","0.01018"
"121.68000","10.14019","0.00996"
"121.92000","10.16022","0.01008"
"122.16000","10.18018","0.01069"
"122.40000","10.20015","0.01030"
"122.64000","10.22012","0.01007"
"122.88000","10.24021","0.01045"
"123.12000","10.26018","0.01025"
"123.36000","10.28021","0.01028"
"123.60000","10.30018","0.01053"
"123.84000","10.32015","0.00997"
"124.08000","10.34024","0.01083"
"124.32000","10.36015","0.01073"
"124.56000","10.38024","0.01050"
"124.80000","10.40015","0.01098"
"125.04000","10.42018","0.01097"
"125.28000","10.44021","0.01089"
"125.52000","10.46018","0.01086"
"125.76000","10.48015","0.01094"
"126.00000","10.50024","0.01081"
"126.24000","10.52021","0.01123"
"126.48000","10.54018","0.01145"
"126.72000","10.56021","0.01109"
"126.96000","10.58012","0.01127"
"127.20000","10.60021","0.01112"
"127.44000","10.62018","0.01126"
"127.68000","10.64020","0.01128"
"127.92000","10.66018","0.01159"
"128.16000","10.68020","0.01136"
"128.40000","10.70017","0.01145"
"128.64000","10.72014","0.01158"
"128.88000","10.74023","0.01124"
"129.12000","10.76014","0.01163"
"129.36000","10.78023","0.01131"
"129.60000","10.80014","0.01152"
"129.84000","10.82017","0.01178"
"130.08000","10.84014","0.01221"
"130.32000","10.86023","0.01189"
"130.56000","10.88020","0.01158"
"130.80000","10.90017","0.01174"
"131.04000","10.92020","0.01189"
"131.28000","10.94017","0.01203"
"131.52000","10.96020","0.01230"
"131.76000","10.98017","0.01198"
"132.00000","11.00020","0.01228"
"132.24000","11.02017","0.01220"
"132.48000","11.04026","0.01230"
"132.72000","11.06017","0.01186"
"132.96000","11.08014","0.01191"
"133.20000","11.10023","0.01231"
"133.44000","11.12014","0.01294"
"133.68000","11.14023","0.01194"
"133.92000","11.16019","0.01223"
"134.16000","11.18022","0.01214"
"134.40000","11.20013","0.01175"
"134.64000","11.22016","0.01278"
"134.88000","11.24019","0.01239"
"135.12000","11.26016","0.01255"
"135.36000","11.28019","0.01173"
"135.60000","11.30010","0.01199"
"135.84000","11.32019","0.01238"
"136.08000","11.34016","0.01199"
"136.32000","11.36025","0.01217"
"136.56000","11.38022","0.01192"
"136.80000","11.40025","0.01217"
"137.04000","11.42022","0.01240"
"137.28000","11.44013","0.01181"
"137.52000","11.46022","0.01204"
"137.76000","11.48019","0.01196"
"138.00000","11.50016","0.01191"
"138.24000","11.52013","0.01230"
"138.48000","11.54022","0.01200"
"138.72000","11.56019","0.01223"
"138.96000","11.58016","0.01229"
"139.20000","11.60025","0.01270"
"139.44000","11.62022","0.01220"
"139.68000","11.64025","0.01237"
"139.92000","11.66016","0.01198"
"140.16000","11.68018","0.01243"
"140.40000","11.70015","0.01284"
"140.64000","11.72024","0.01265"
"140.88000","11.74021","0.01248"
"141.12000","11.76018","0.01302"
"141.36000","11.78021","0.01238"
"141.60000","11.80012","0.01229"
"141.84000","11.82021","0.01279"
"142.08000","11.84018","0.01236"
"142.32000","11.86015","0.01242"
"142.56000","11.88012","0.01260"
"142.80000","11.90021","0.01270"
"143.04000","11.92012","0.01224"
"143.28000","11.94021","0.01256"
"143.52000","11.96024","0.01307"
"143.76000","11.98021","0.01304"
"144.00000","12.00024","0.01265"
"144.24000","12.02021","0.01322"
"144.48000","12.04018","0.01321"
"144.72000","12.06021","0.01281"
"144.96000","12.08024","0.01285"
"145.20000","12.10020","0.01311"
"145.44000","12.12018","0.01308"
"145.68000","12.14020","0.01283"
"145.92000","12.16018","0.01316"
"146.16000","12.18020","0.01334"
"146.40000","12.20017","0.01376"
"146.64000","12.22020","0.01386"
"146.88000","12.24017","0.01393"
"147.12000","12.26020","0.01411"
"147.36000","12.28017","0.01339"
"147.60000","12.30020","0.01367"
"147.84000","12.32017","0.01360"
"148.08000","12.34014","0.01365"
"148.32000","12.36023","0.01361"
"148.56000","12.38020","0.01289"
"148.80000","12.40023","0.01314"
"149.04000","12.42014","0.01361"
"149.28000","12.44023","0.01387"
"149.52000","12.46020","0.01345"
"149.76000","12.48023","0.01407"
"150.00000","12.50020","0.01339"
"150.24000","12.52023","0.01371"
"150.48000","12.54020","0.01356"
"150.72000","12.56017","0.01345"
"150.96000","12.58020","0.01374"
"151.20000","12.60011","0.01383"
"151.44000","12.62019","0.01366"
"151.68000","12.64023","0.01433"
"151.92000","12.66025","0.01411"
"152.16000","12.68016","0.01411"
"152.40000","12.70019","0.01423"
"152.64000","12.72022","0.01424"
"152.88000","12.74019","0.01446"
"153.12000","12.76022","0.01469"
"153.36000","12.78007","0.01481"
"153.60000","12.80022","0.01453"
"153.84000","12.82019","0.01457"
"154.08000","12.84022","0.01462"
"154.32000","12.86019","0.01494"
"154.56000","12.88022","0.01405"
"154.80000","12.90019","0.01455"
"155.04000","12.92016","0.01454"
"155.28000","12.94025","0.01474"
"155.52000","12.96016","0.01483"
"155.76000","12.98019","0.01495"
"156.00000","13.00016","0.01502"
"156.24000","13.02019","0.01542"
"156.48000","13.04016","0.01450"
"156.72000","13.06019","0.01498"
"156.96000","13.08022","0.01490"
"157.20000","13.10019","0.01475"
"157.44000","13.12022","0.01499"
"157.68000","13.14012","0.01504"
"157.92000","13.16021","0.01498"
"158.16000","13.18018","0.01540"
"158.40000","13.20021","0.01541"
"158.64000","13.22018","0.01532"
"158.88000","13.24021","0.01479"
"159.12000","13.26018","0.01510"
"159.36000","13.28021","0.01466"
"159.60000","13.30024","0.01514"
"159.84000","13.32015","0.01533"
"160.08000","13.34024","0.01480"
"160.32000","13.36021","0.01551"
"160.56000","13.38018","0.01520"
"160.80000","13.40015","0.01539"
"161.04000","13.42024","0.01564"
"161.28000","13.44021","0.01548"
"161.52000","13.46018","0.01565"
"161.76000","13.48021","0.01512"
"162.00000","13.50012","0.01563"
"162.24000","13.52021","0.01550"
"162.48000","13.54018","0.01545"
"162.72000","13.56027","0.01560"
"162.96000","13.58018","0.01519"
"163.20000","13.60021","0.01573"
"163.44000","13.62018","0.01530"
"163.68000","13.64015","0.01539"
"163.92000","13.66017","0.01547"
"164.16000","13.68015","0.01564"
"164.40000","13.70023","0.01580"
"164.64000","13.72014","0.01494"
"164.88000","13.74023","0.01598"
"165.12000","13.76014","0.01586"
"165.36000","13.78017","0.01576"
"165.60000","13.80020","0.01573"
"165.84000","13.82017","0.01605"
"166.08000","13.84020","0.01549"
"166.32000","13.86017","0.01580"
"166.56000","13.88020","0.01584"
"166.80000","13.90017","0.01578"
"167.04000","13.92020","0.01635"
"167.28000","13.94023","0.01615"
"167.52000","13.96020","0.01629"
"167.76000","13.98023","0.01593"
"168.00000","14.00020","0.01626"
"168.24000","14.02017","0.01613"
"168.48000","14.04020","0.01608"
"168.72000","14.06023","0.01657"
"168.96000","14.08014","0.01673"
"169.20000","14.10023","0.01619"
"169.44000","14.12014","0.01575"
"169.68000","14.14022","0.01650"
"169.92000","14.16026","0.01608"
"170.16000","14.18022","0.01692"
"170.40000","14.20019","0.01689"
"170.64000","14.22022","0.01686"
"170.88000","14.24019","0.01668"
"171.12000","14.26010","0.01657"
"171.36000","14.28025","0.01674"
"171.60000","14.30016","0.01708"
"171.84000","14.32025","0.01696"
"172.08000","14.34022","0.01691"
"172.32000","14.36019","0.01716"
"172.56000","14.38022","0.01692"
"172.80000","14.40019","0.01669"
"173.04000","14.42022","0.01736"
"173.28000","14.44013","0.01710"
"173.52000","14.46016","0.01719"
"173.76000","14.48013","0.01755"
"174.00000","14.50016","0.01664"
"174.24000","14.52025","0.01773"
"174.48000","14.54022","0.01767"
"174.72000","14.56019","0.01728"
"174.96000","14.58016","0.01733"
"175.20000","14.60019","0.01719"
"175.44000","14.62021","0.01685"
"175.68000","14.64019","0.01748"
"175.92000","14.66021","0.01791"
"176.16000","14.68018","0.01799"
"176.40000","14.70015","0.01792"
"176.64000","14.72018","0.01791"
"176.88000","14.74015","0.01802"
"177.12000","14.76018","0.01765"
"177.36000","14.78021","0.01731"
"177.60000","14.80018","0.01835"
"177.84000","14.82021","0.01834"
"178.08000","14.84012","0.01835"
"178.32000","14.86015","0.01824"
"178.56000","14.88018","0.01809"
"178.80000","14.90027","0.01801"
"179.04000","14.92018","0.01811"
"179.28000","14.94015","0.01807"
"179.52000","14.96024","0.01824"
"179.76000","14.98015","0.01780"
"180.00000","15.00024","0.01798"
"180.24000","15.02015","0.01842"
"180.48000","15.04024","0.01829"
"180.72000","15.06021","0.01873"
"180.96000","15.08018","0.01845"
"181.20000","15.10015","0.01880"
"181.44000","15.12018","0.01833"
"181.68000","15.14026","0.01873"
"181.92000","15.16012","0.01903"
"182.16000","15.18020","0.01835"
"182.40000","15.20017","0.01893"
"182.64000","15.22020","0.01923"
"182.88000","15.24017","0.01896"
"183.12000","15.26020","0.01917"
"183.36000","15.28017","0.01889"
"183.60000","15.30020","0.01917"
"183.84000","15.32023","0.01906"
"184.08000","15.34014","0.01901"
"184.32000","15.36017","0.01934"
"184.56000","15.38014","0.01937"
"184.80000","15.40023","0.01917"
"185.04000","15.42020","0.01987"
"185.28000","15.44029","0.01980"
"185.52000","15.46020","0.01950"
"185.76000","15.48017","0.01942"
"186.00000","15.50020","0.01880"
"186.24000","15.52017","0.01931"
"186.48000","15.54020","0.01931"
"186.72000","15.56017","0.01902"
"186.96000","15.58020","0.01913"
"187.20000","15.60017","0.01887"
"187.44000","15.62025","0.01878"
"187.68000","15.64016","0.01831"
"187.92000","15.66019","0.01781"
"188.16000","15.68022","0.01823"
"188.40000","15.70013","0.01840"
"188.64000","15.72028","0.01800"
"188.88000","15.74007","0.01790"
"189.12000","15.76022","0.01781"
"189.36000","15.78013","0.01795"
"189.60000","15.80022","0.01808"
"189.84000","15.82019","0.01781"
"190.08000","15.84016","0.01759"
"190.32000","15.86025","0.01773"
"190.56000","15.88016","0.01810"
"190.80000","15.90025","0.01801"
"191.04000","15.92016","0.01786"
"191.28000","15.94019","0.01804"
"191.52000","15.96016","0.01712"
"191.76000","15.98019","0.01691"
"192.00000","16.00016","0.01715"
"192.24000","16.02019","0.01737"
"192.48000","16.04021","0.01723"
"192.72000","16.06019","0.01734"
"192.96000","16.08022","0.01760"
"193.20000","16.10019","0.01651"
"193.44000","16.12027","0.01702"
"193.68000","16.14018","0.01685"
"193.92000","16.16021","0.01693"
"194.16000","16.18012","0.01701"
"194.40000","16.20015","0.01704"
"194.64000","16.22018","0.01648"
"194.88000","16.24021","0.01640"
"195.12000","16.26024","0.01666"
"195.36000","16.28015","0.01721"
"195.60000","16.30024","0.01640"
"195.84000","16.32015","0.01656"
"196.08000","16.34024","0.01638"
"196.32000","16.36015","0.01629"
"196.56000","16.38024","0.01585"
"196.80000","16.40021","0.01593"
"197.04000","16.42024","0.01585"
"197.28000","16.44021","0.01613"
"197.52000","16.46012","0.01597"
"197.76000","16.48027","0.01591"
"198.00000","16.50018","0.01549"
"198.24000","16.52021","0.01585"
"198.48000","16.54012","0.01552"
"198.72000","16.56021","0.01524"
"198.96000","16.58018","0.01546"
"199.20000","16.60020","0.01598"
"199.44000","16.62017","0.01520"
"199.68000","16.64014","0.01525"
"199.92000","16.66023","0.01556"
"200.16000","16.68014","0.01551"
"200.40000","16.70017","0.01564"
"200.64000","16.72020","0.01614"
"200.88000","16.74023","0.01600"
"201.12000","16.76020","0.01610"
"201.36000","16.78017","0.01626"
"201.60000","16.80014","0.01651"
"201.84000","16.82011","0.01663"
"202.08000","16.84026","0.01623"
"202.32000","16.86017","0.01706"
"202.56000","16.88014","0.01722"
"202.80000","16.90017","0.01677"
"203.04000","16.92020","0.01638"
"203.28000","16.94017","0.01659"
"203.52000","16.96020","0.01691"
"203.76000","16.98023","0.01724"
"204.00000","17.00020","0.01713"
"204.24000","17.02023","0.01706"
"204.48000","17.04014","0.01755"
"204.72000","17.06017","0.01772"
"204.96000","17.08014","0.01787"
"205.20000","17.10022","0.01807"
"205.44000","17.12019","0.01856"
"205.68000","17.14022","0.01800"
"205.92000","17.16025","0.01856"
"206.16000","17.18016","0.01852"
"206.40000","17.20019","0.01871"
"206.64000","17.22016","0.01895"
"206.88000","17.24019","0.01880"
"207.12000","17.26016","0.01888"
"207.36000","17.28025","0.01956"
"207.60000","17.30016","0.01891"
"207.84000","17.32019","0.01909"
"208.08000","17.34022","0.01911"
"208.32000","17.36013","0.01952"
"208.56000","17.38022","0.01942"
"208.80000","17.40013","0.01918"
"209.04000","17.42022","0.01926"
"209.28000","17.44013","0.01947"
"209.52000","17.46022","0.01932"
"209.76000","17.48019","0.02000"
"210.00000","17.50022","0.01946"
"210.24000","17.52025","0.01971"
"210.48000","17.54016","0.02001"
"210.72000","17.56019","0.02025"
"210.96000","17.58022","0.02091"
"211.20000","17.60024","0.02052"
"211.44000","17.62016","0.02046"
"211.68000","17.64018","0.02076"
"211.92000","17.66015","0.02096"
"212.16000","17.68018","0.02122"
"212.40000","17.70021","0.02133"
"212.64000","17.72018","0.02143"
"212.88000","17.74027","0.02138"
"213.12000","17.76018","0.02177"
"213.36000","17.78021","0.02208"
"213.60000","17.80012","0.02249"
"213.84000","17.82027","0.02178"
"214.08000","17.84018","0.02182"
"214.32000","17.86021","0.02247"
"214.56000","17.88018","0.02234"
"214.80000","17.90015","0.02268"
"215.04000","17.92018","0.02281"
"215.28000","17.94021","0.02330"
"215.52000","17.96024","0.02332"
"215.76000","17.98015","0.02360"
"216.00000","18.00024","0.02336"
"216.24000","18.02021","0.02355"
"216.48000","18.04024","0.02405"
"216.72000","18.06015","0.02383"
"216.96000","18.08018","0.02426"
"217.20000","18.10027","0.02472"
"217.44000","18.12017","0.02444"
"217.68000","18.14020","0.02451"
"217.92000","18.16011","0.02489"
"218.16000","18.18026","0.02486"
"218.40000","18.20023","0.02540"
"218.64000","18.22020","0.02544"
"218.88000","18.24017","0.02556"
"219.12000","18.26014","0.02592"
"219.36000","18.28017","0.02597"
"219.60000","18.30014","0.02578"
"219.84000","18.32023","0.02618"
"220.08000","18.34014","0.02678"
"220.32000","18.36023","0.02685"
"220.56000","18.38020","0.02650"
"220.80000","18.40023","0.02669"
"221.04000","18.42020","0.02722"
"221.28000","18.44023","0.02738"
"221.52000","18.46020","0.02754"
"221.76000","18.48017","0.02758"
"222.00000","18.50020","0.02806"
"222.24000","18.52011","0.02818"
"222.48000","18.54020","0.02809"
"222.72000","18.56017","0.02840"
"222.96000","18.58019","0.02847"
"223.20000","18.60017","0.02897"
"223.44000","18.62025","0.02891"
"223.68000","18.64016","0.02887"
"223.92000","18.66019","0.02905"
"224.16000","18.68022","0.02966"
"224.40000","18.70013","0.02971"
"224.64000","18.72022","0.02971"
"224.88000","18.74013","0.03052"
"225.12000","18.76016","0.03049"
"225.36000","18.78013","0.03081"
"225.60000","18.80022","0.03095"
"225.84000","18.82019","0.03153"
"226.08000","18.84016","0.03164"
"226.32000","18.86025","0.03228"
"226.56000","18.88010","0.03237"
"226.80000","18.90019","0.03206"
"227.04000","18.92016","0.03350"
"227.28000","18.94019","0.03326"
"227.52000","18.96016","0.03299"
"227.76000","18.98025","0.03306"
"228.00000","19.00022","0.03360"
"228.24000","19.02019","0.03365"
"228.48000","19.04016","0.03399"
"228.72000","19.06013","0.03449"
"228.96000","19.08022","0.03517"
"229.20000","19.10019","0.03598"
"229.44000","19.12016","0.03584"
"229.68000","19.14018","0.03670"
"229.92000","19.16021","0.03725"
"230.16000","19.18024","0.03756"
"230.40000","19.20021","0.03838"
"230.64000","19.22018","0.03849"
"230.88000","19.24015","0.03864"
"231.12000","19.26018","0.03832"
"231.36000","19.28015","0.03985"
"231.60000","19.30024","0.03986"
"231.84000","19.32015","0.03984"
"232.08000","19.34024","0.04105"
"232.32000","19.36015","0.04170"
"232.56000","19.38018","0.04168"
"232.80000","19.40021","0.04180"
"233.04000","19.42018","0.04199"
"233.28000","19.44027","0.04227"
"233.52000","19.46012","0.04261"
"233.76000","19.48021","0.04288"
"234.00000","19.50018","0.04348"
"234.24000","19.52021","0.04348"
"234.48000","19.54024","0.04436"
"234.72000","19.56021","0.04429"
"234.96000","19.58024","0.04487"
"235.20000","19.60020","0.04533"
"235.44000","19.62017","0.04531"
"235.68000","19.64014","0.04597"
"235.92000","19.66023","0.04611"
"236.16000","19.68020","0.04696"
"236.40000","19.70023","0.04749"
"236.64000","19.72026","0.04780"
"236.88000","19.74017","0.04838"
"237.12000","19.76020","0.04870"
"237.36000","19.78017","0.04906"
"237.60000","19.80020","0.04968"
"237.84000","19.82017","0.04999"
"238.08000","19.84014","0.05046"
"238.32000","19.86011","0.05076"
"238.56000","19.88020","0.05114"
"238.80000","19.90023","0.05238"
"239.04000","19.92020","0.05260"
"239.28000","19.94017","0.05433"
"239.52000","19.96020","0.05449"
"239.76000","19.98023","0.05445"
"240.00000","20.00014","0.05532"
"240.24000","20.02017","0.05622"
"240.48000","20.04014","0.05672"
"240.72000","20.06022","0.05725"
"240.96000","20.08019","0.05831"
"241.20000","20.10016","0.05934"
"241.44000","20.12019","0.05978"
"241.68000","20.14016","0.06072"
"241.92000","20.16025","0.06199"
"242.16000","20.18011","0.06307"
"242.40000","20.20025","0.06395"
"242.64000","20.22016","0.06465"
"242.88000","20.24019","0.06569"
"243.12000","20.26016","0.06605"
"243.36000","20.28025","0.06713"
"243.60000","20.30016","0.06790"
"243.84000","20.32019","0.06823"
"244.08000","20.34022","0.06911"
"244.32000","20.36013","0.06976"
"244.56000","20.38022","0.07044"
"244.80000","20.40019","0.07106"
"245.04000","20.42016","0.07164"
"245.28000","20.44013","0.07281"
"245.52000","20.46016","0.07305"
"245.76000","20.48013","0.07414"
"246.00000","20.50022","0.07380"
"246.24000","20.52024","0.07419"
"246.48000","20.54015","0.07483"
"246.72000","20.56019","0.07518"
"246.96000","20.58015","0.07642"
"247.20000","20.60019","0.07552"
"247.44000","20.62015","0.07597"
"247.68000","20.64024","0.07686"
"247.92000","20.66015","0.07669"
"248.16000","20.68018","0.07812"
"248.40000","20.70027","0.07847"
"248.64000","20.72012","0.08015"
"248.88000","20.74021","0.08158"
"249.12000","20.76018","0.08207"
"249.36000","20.78021","0.08244"
"249.60000","20.80018","0.08378"
"249.84000","20.82021","0.08505"
"250.08000","20.84012","0.08666"
"250.32000","20.86015","0.08793"
"250.56000","20.88024","0.08885"
"250.80000","20.90015","0.09062"
"251.04000","20.92018","0.09068"
"251.28000","20.94021","0.09172"
"251.52000","20.96018","0.09273"
"251.76000","20.98021","0.09315"
"252.00000","21.00024","0.09441"
"252.24000","21.02020","0.09461"
"252.48000","21.04018","0.09551"
"252.72000","21.06015","0.09617"
"252.96000","21.08017","0.09702"
"253.20000","21.10020","0.09764"
"253.44000","21.12011","0.09841"
"253.68000","21.14021","0.09894"
"253.92000","21.16017","0.10010"
"254.16000","21.18026","0.10040"
"254.40000","21.20017","0.10133"
"254.64000","21.22014","0.10194"
"254.88000","21.24017","0.10267"
"255.12000","21.26020","0.10370"
"255.36000","21.28023","0.10429"
"255.60000","21.30020","0.10518"
"255.84000","21.32023","0.10594"
"256.08000","21.34014","0.10666"
"256.32000","21.36023","0.10741"
"256.56000","21.38014","0.10791"
"256.80000","21.40023","0.10876"
"257.04000","21.42020","0.10945"
"257.28000","21.44017","0.11021"
"257.52000","21.46020","0.11072"
"257.76000","21.48017","0.11153"
"258.00000","21.50020","0.11254"
"258.24000","21.52017","0.11359"
"258.48000","21.54025","0.11453"
"258.72000","21.56017","0.11522"
"258.96000","21.58013","0.11720"
"259.20000","21.60022","0.11796"
"259.44000","21.62020","0.11877"
"259.68000","21.64022","0.11977"
"259.92000","21.66013","0.12053"
"260.16000","21.68022","0.12222"
"260.40000","21.70019","0.12351"
"260.64000","21.72016","0.12437"
"260.88000","21.74013","0.12538"
"261.12000","21.76022","0.12618"
"261.36000","21.78019","0.12802"
"261.60000","21.80022","0.12784"
"261.84000","21.82019","0.12526"
"262.08000","21.84016","0.12189"
"262.32000","21.86025","-0.00035"
"262.56000","21.88016","0.00540"
"262.80000","21.90025","0.00511"
"263.04000","21.92016","0.00431"
"263.28000","21.94019","0.00476"
"263.52000","21.96010","0.00628"
"263.76000","21.98018","0.00602"
"264.00000","22.00022","0.00448"
"264.24000","22.02019","0.00383"
"264.48000","22.04022","0.00595"
"264.72000","22.06013","0.00529"
"264.96000","22.08022","0.00436"
"265.20000","22.10018","0.00465"
"265.44000","22.12021","0.00508"
"265.68000","22.14018","0.00567"
"265.92000","22.16015","0.00496"
"266.16000","22.18024","0.00413"
"266.40000","22.20015","0.00501"
"266.64000","22.22024","0.00556"
"266.88000","22.24021","0.00517"
"267.12000","22.26018","0.00498"
"267.36000","22.28015","0.00538"
"267.60000","22.30018","0.00569"
"267.84000","22.32021","0.00520"
"268.08000","22.34018","0.00487"
"268.32000","22.36021","0.00584"
"268.56000","22.38018","0.00523"
"268.80000","22.40021","0.00547"
"269.04000","22.42018","0.00531"
"269.28000","22.44015","0.00560"
"269.52000","22.46012","0.00551"
"269.76000","22.48021","0.00504"
"270.00000","22.50024","0.00507"
"270.24000","22.52015","0.00556"
"270.48000","22.54018","0.00549"
"270.72000","22.56009","0.00555"
"270.96000","22.58023","0.00544"
"271.20000","22.60015","0.00548"
"271.44000","22.62017","0.00536"
"271.68000","22.64020","0.00543"
"271.92000","22.66023","0.00572"
"272.16000","22.68014","0.00523"
"272.40000","22.70017","0.00520"
"272.64000","22.72026","0.00551"
"272.88000","22.74017","0.00549"
"273.12000","22.76020","0.00554"
"273.36000","22.78011","0.00576"
"273.60000","22.80020","0.00543"
"273.84000","22.82017","0.00554"
"274.08000","22.84020","0.00582"
"274.32000","22.86017","0.00526"
"274.56000","22.88020","0.00559"
"274.80000","22.90023","0.00574"
"275.04000","22.92014","0.00581"
"275.28000","22.94023","0.00584"
"275.52000","22.96014","0.00578"
"275.76000","22.98017","0.00592"
"276.00000","23.00014","0.00535"
"276.24000","23.02017","0.00564"
"276.48000","23.04020","0.00553"
"276.72000","23.06022","0.00631"
"276.96000","23.08026","0.00601"
"277.20000","23.10016","0.00559"
"277.44000","23.12025","0.00566"
"277.68000","23.14016","0.00560"
"277.92000","23.16019","0.00609"
"278.16000","23.18010","0.00605"
"278.40000","23.20025","0.00621"
"278.64000","23.22022","0.00571"
"278.88000","23.24025","0.00559"
"279.12000","23.26022","0.00610"
"279.36000","23.28019","0.00604"
"279.60000","23.30022","0.00595"
"279.84000","23.32019","0.00593"
"280.08000","23.34016","0.00603"
"280.32000","23.36013","0.00581"
"280.56000","23.38022","0.00622"
"280.80000","23.40013","0.00648"
"281.04000","23.42022","0.00618"
"281.28000","23.44019","0.00586"
"281.52000","23.46016","0.00636"
"281.76000","23.48025","0.00613"
"282.00000","23.50016","0.00615"
"282.24000","23.52019","0.00582"
"282.48000","23.54009","0.00611"
"282.72000","23.56025","0.00592"
"282.96000","23.58016","0.00574"
"283.20000","23.60024","0.00604"
"283.44000","23.62021","0.00611"
"283.68000","23.64018","0.00615"
"283.92000","23.66021","0.00613"
"284.16000","23.68018","0.00573"
"284.40000","23.70027","0.00522"
"284.64000","23.72012","0.00514"
"284.88000","23.74021","0.00472"
"285.12000","23.76018","0.00473"
"285.36000","23.78021","0.00517"
"285.60000","23.80018","0.00535"
"285.84000","23.82015","0.00509"
"286.08000","23.84018","0.00505"
"286.32000","23.86021","0.00489"
"286.56000","23.88018","0.00491"
"286.80000","23.90015","0.00461"
"287.04000","23.92018","0.00498"
"287.28000","23.94020","0.00453"
"287.52000","23.96024","0.00492"
"287.76000","23.98021","0.00530"
"288.00000","24.00018","0.00468"
"288.24000","24.02021","0.00481"
"288.48000","24.04017","0.00456"
"288.72000","24.06021","0.00484"
"288.96000","24.08017","0.00518"
"289.20000","24.10020","0.00503"
"289.44000","24.12017","0.00522"
"289.68000","24.14020","0.00483"
"289.92000","24.16023","0.00526"
"290.16000","24.18020","0.00521"
"290.40000","24.20017","0.00549"
"290.64000","24.22020","0.00518"
"290.88000","24.24023","0.00504"
"291.12000","24.26008","0.00497"
"291.36000","24.28017","0.00510"
"291.60000","24.30020","0.00509"
"291.84000","24.32023","0.00515"
"292.08000","24.34020","0.00509"
"292.32000","24.36023","0.00562"
"292.56000","24.38020","0.00495"
"292.80000","24.40017","0.00519"
"293.04000","24.42020","0.00510"
"293.28000","24.44011","0.00470"
"293.52000","24.46020","0.00521"
"293.76000","24.48017","0.00516"
"294.00000","24.50019","0.00466"
"294.24000","24.52017","0.00539"
"294.48000","24.54020","0.00459"
"294.72000","24.56022","0.00507"
"294.96000","24.58014","0.00535"
"295.20000","24.60023","0.00504"
"295.44000","24.62013","0.00434"
"295.68000","24.64022","0.00473"
"295.92000","24.66019","0.00463"
"296.16000","24.68016","0.00437"
"296.40000","24.70019","0.00412"
"296.64000","24.72016","0.00430"
"296.88000","24.74019","0.00454"
"297.12000","24.76022","0.00463"
"297.36000","24.78019","0.00434"
"297.60000","24.80016","0.00412"
"297.84000","24.82019","0.00438"
"298.08000","24.84016","0.00425"
"298.32000","24.86019","0.00478"
"298.56000","24.88016","0.00434"
"298.80000","24.90025","0.00459"
"299.04000","24.92022","0.00451"
"299.28000","24.94019","0.00452"
"299.52000","24.96022","0.00439"
"299.76000","24.98019","0.00416"
"300.00000","25.00022","0.00436"
"300.24000","25.02013","0.00434"
"300.48000","25.04022","0.00448"
"300.72000","25.06019","0.00453"
"300.96000","25.08022","0.00470"
"301.20000","25.10019","0.00425"
"301.44000","25.12015","0.00443"
"301.68000","25.14018","0.00438"
"301.92000","25.16015","0.00406"
"302.16000","25.18024","0.00448"
"302.40000","25.20015","0.00420"
"302.64000","25.22024","0.00429"
"302.88000","25.24015","0.00426"
"303.12000","25.26024","0.00449"
"303.36000","25.28027","0.00440"
"303.60000","25.30018","0.00419"
"303.84000","25.32021","0.00402"
"304.08000","25.34018","0.00407"
"304.32000","25.36021","0.00432"
"304.56000","25.38018","0.00470"
"304.80000","25.40021","0.00442"
"305.04000","25.42018","0.00466"
"305.28000","25.44021","0.00491"
"305.52000","25.46024","0.00478"
"305.76000","25.48015","0.00426"
"306.00000","25.50018","0.00454"
"306.24000","25.52015","0.00425"
"306.48000","25.54024","0.00479"
"306.72000","25.56020","0.00477"
"306.96000","25.58023","0.00489"
"307.20000","25.60008","0.00434"
"307.44000","25.62017","0.00440"
"307.68000","25.64021","0.00460"
"307.92000","25.66023","0.00511"
"308.16000","25.68020","0.00461"
"308.40000","25.70017","0.00421"
"308.64000","25.72020","0.00427"
"308.88000","25.74011","0.00462"
"309.12000","25.76026","0.00451"
"309.36000","25.78017","0.00461"
"309.60000","25.80026","0.00442"
"309.84000","25.82017","0.00480"
"310.08000","25.84020","0.00504"
"310.32000","25.86023","0.00448"
"310.56000","25.88014","0.00458"
"310.80000","25.90023","0.00459"
"311.04000","25.92014","0.00452"
"311.28000","25.94023","0.00467"
"311.52000","25.96020","0.00474"
"311.76000","25.98017","0.00460"
"312.00000","26.00014","0.00460"
"312.24000","26.02017","0.00474"
"312.48000","26.04020","0.00469"
"312.72000","26.06022","0.00452"
"312.96000","26.08019","0.00430"
"313.20000","26.10017","0.00454"
"313.44000","26.12019","0.00517"
"313.68000","26.14017","0.00439"
"313.92000","26.16019","0.00476"
"314.16000","26.18016","0.00480"
"314.40000","26.20019","0.00484"
"314.64000","26.22010","0.00468"
"314.88000","26.24013","0.00429"
"315.12000","26.26022","0.00546"
"315.36000","26.28013","0.00521"
"315.60000","26.30022","0.00476"
"315.84000","26.32019","0.00471"
"316.08000","26.34016","0.00523"
"316.32000","26.36019","0.00488"
"316.56000","26.38022","0.00516"
"316.80000","26.40013","0.00487"
"317.04000","26.42016","0.00446"
"317.28000","26.44019","0.00470"
"317.52000","26.46016","0.00466"
"317.76000","26.48025","0.00456"
"318.00000","26.50016","0.00435"
"318.24000","26.52025","0.00428"
"318.48000","26.54016","0.00505"
"318.72000","26.56024","0.00457"
"318.96000","26.58015","0.00448"
"319.20000","26.60013","0.00527"
"319.44000","26.62027","0.00432"
"319.68000","26.64013","0.00464"
"319.92000","26.66021","0.00459"
"320.16000","26.68018","0.00426"
"320.40000","26.70015","0.00454"
"320.64000","26.72012","0.00501"
"320.88000","26.74021","0.00430"
"321.12000","26.76018","0.00458"
"321.36000","26.78021","0.00454"
"321.60000","26.80018","0.00460"
"321.84000","26.82015","0.00467"
"322.08000","26.84018","0.00457"
"322.32000","26.86021","0.00447"
"322.56000","26.88018","0.00450"
"322.80000","26.90021","0.00472"
"323.04000","26.92024","0.00487"
"323.28000","26.94021","0.00519"
"323.52000","26.96018","0.00470"
"323.76000","26.98027","0.00464"
"324.00000","27.00018","0.00494"
"324.24000","27.02020","0.00463"
"324.48000","27.04018","0.00433"
"324.72000","27.06020","0.00506"
"324.96000","27.08018","0.00461"
"325.20000","27.10027","0.00480"
"325.44000","27.12017","0.00468"
"325.68000","27.14026","0.00482"
"325.92000","27.16023","0.00486"
"326.16000","27.18020","0.00415"
"326.40000","27.20023","0.00510"
"326.64000","27.22014","0.00452"
"326.88000","27.24023","0.00401"
"327.12000","27.26020","0.00475"
"327.36000","27.28023","0.00506"
"327.60000","27.30014","0.00462"
"327.84000","27.32023","0.00468"
"328.08000","27.34020","0.00439"
"328.32000","27.36023","0.00469"
"328.56000","27.38020","0.00445"
"328.80000","27.40017","0.00525"
"329.04000","27.42026","0.00447"
"329.28000","27.44011","0.00401"
"329.52000","27.46020","0.00455"
"329.76000","27.48017","0.00408"
"330.00000","27.50019","0.00469"
"330.24000","27.52023","0.00429"
"330.48000","27.54020","0.00479"
"330.72000","27.56023","0.00476"
"330.96000","27.58014","0.00420"
"331.20000","27.60023","0.00425"
"331.44000","27.62013","0.00392"
"331.68000","27.64016","0.00474"
"331.92000","27.66019","0.00443"
"332.16000","27.68022","0.00455"
"332.40000","27.70019","0.00455"
"332.64000","27.72016","0.00476"
"332.88000","27.74019","0.00452"
"333.12000","27.76016","0.00429"
"333.36000","27.78019","0.00430"
"333.60000","27.80010","0.00447"
"333.84000","27.82019","0.00463"
"334.08000","27.84016","0.00448"
"334.32000","27.86019","0.00415"
"334.56000","27.88016","0.00460"
"334.80000","27.90019","0.00440"
"335.04000","27.92022","0.00454"
"335.28000","27.94013","0.00436"
"335.52000","27.96028","0.00477"
"335.76000","27.98019","0.00454"
"336.00000","28.00022","0.00438"
"336.24000","28.02018","0.00460"
"336.48000","28.04016","0.00403"
"336.72000","28.06019","0.00451"
"336.96000","28.08021","0.00465"
"337.20000","28.10018","0.00496"
"337.44000","28.12015","0.00460"
"337.68000","28.14025","0.00403"
"337.92000","28.16015","0.00439"
"338.16000","28.18018","0.00448"
"338.40000","28.20015","0.00451"
"338.64000","28.22018","0.00441"
"338.88000","28.24015","0.00372"
"339.12000","28.26018","0.00434"
"339.36000","28.28021","0.00409"
"339.60000","28.30012","0.00425"
"339.84000","28.32021","0.00436"
"340.08000","28.34018","0.00466"
"340.32000","28.36021","0.00445"
"340.56000","28.38018","0.00415"
"340.80000","28.40021","0.00493"
"341.04000","28.42012","0.00422"
"341.28000","28.44021","0.00451"
"341.52000","28.46024","0.00477"
"341.76000","28.48021","0.00488"
"342.00000","28.50018","0.00459"
"342.24000","28.52009","0.00433"
"342.48000","28.54017","0.00411"
"342.72000","28.56014","0.00409"
"342.96000","28.58023","0.00413"
"343.20000","28.60014","0.00443"
"343.44000","28.62023","0.00430"
"343.68000","28.64020","0.00437"
"343.92000","28.66011","0.00416"
"344.16000","28.68020","0.00411"
"344.40000","28.70017","0.00419"
"344.64000","28.72020","0.00447"
"344.88000","28.74011","0.00421"
"345.12000","28.76020","0.00495"
"345.36000","28.78017","0.00395"
"345.60000","28.80026","0.00435"
"345.84000","28.82017","0.00507"
"346.08000","28.84020","0.00385"
"346.32000","28.86023","0.00436"
"346.56000","28.88020","0.00420"
"346.80000","28.90017","0.00385"
"347.04000","28.92014","0.00426"
"347.28000","28.94023","0.00443"
"347.52000","28.96014","0.00446"
"347.76000","28.98022","0.00453"
"348.00000","29.00019","0.00387"
"348.24000","29.02016","0.00433"
"348.48000","29.04020","0.00454"
"348.72000","29.06017","0.00421"
"348.96000","29.08019","0.00460"
"349.20000","29.10016","0.00508"
"349.44000","29.12019","0.00448"
"349.68000","29.14016","0.00453"
"349.92000","29.16019","0.00441"
"350.16000","29.18016","0.00494"
"350.40000","29.20019","0.00445"
"350.64000","29.22022","0.00419"
"350.88000","29.24019","0.00497"
"351.12000","29.26016","0.00466"
"351.36000","29.28013","0.00477"
"351.60000","29.30022","0.00419"
"351.84000","29.32019","0.00438"
"352.08000","29.34022","0.00466"
"352.32000","29.36019","0.00432"
"352.56000","29.38016","0.00455"
"352.80000","29.40019","0.00439"
"353.04000","29.42022","0.00453"
"353.28000","29.44025","0.00360"
"353.52000","29.46016","0.00440"
"353.76000","29.48019","0.00434"
"354.00000","29.50015","0.00463"
"354.24000","29.52019","0.00458"
"354.48000","29.54021","0.00467"
"354.72000","29.56019","0.00444"
"354.96000","29.58016","0.00425"
"355.20000","29.60018","0.00429"
"355.44000","29.62021","0.00439"
"355.62400","29.63546","0.00467"