File: Force_trajectories/161216/Specimen_RawData_5.csv
End date,"12/16/2016"
Specimen label,"15BT_21"
Maximum Load,"0.21588",N

Time,Extension,Load
(s),(mm),(N)
"0.00000","0.00000","0.00002"
"0.19200","0.01220","0.00020"
"0.38400","0.03205","-0.00035"
"0.57600","0.04831","0.00012"
"0.76800","0.06421","-0.00003"
"0.96000","0.08018","0.00007"
"1.15200","0.09626","0.00010"
"1.34400","0.11217","-0.00008"
"1.53600","0.12819","0.00019"
"1.72800","0.14421","0.00065"
"1.92000","0.16018","0.00022"
"2.11200","0.17620","0.00053"
"2.30400","0.19222","0.00077"
"2.49600","0.20819","0.00013"
"2.68800","0.22415","0.00013"
"2.88000","0.24023","0.00021"
"3.07200","0.25614","0.00028"
"3.26400","0.27222","0.00037"
"3.45600","0.28819","0.00034"
"3.64800","0.30415","0.00022"
"3.84000","0.32023","0.00058"
"4.03200","0.33614","0.00039"
"4.22400","0.35216","0.00061"
"4.41600","0.36818","0.00071"
"4.60800","0.38415","0.00050"
"4.80000","0.40017","0.00077"
"4.99200","0.41619","0.00048"
"5.18400","0.43216","0.00055"
"5.37600","0.44818","0.00073"
"5.56800","0.46415","0.00045"
"5.76000","0.48017","0.00041"
"5.95200","0.49619","0.00050"
"6.14400","0.51216","0.00076"
"6.33600","0.52818","0.00068"
"6.52800","0.54414","0.00080"
"6.72000","0.56011","0.00100"
"6.91200","0.57619","0.00064"
"7.10400","0.59222","0.00076"
"7.29600","0.60812","0.00051"
"7.48800","0.62414","0.00077"
"7.68000","0.64023","0.00076"
"7.87200","0.65613","0.00055"
"8.06400","0.67221","0.00067"
"8.25600","0.68818","0.00067"
"8.44800","0.70408","0.00079"
"8.64000","0.72022","0.00043"
"8.83200","0.73619","0.00111"
"9.02400","0.75215","0.00106"
"9.21600","0.76818","0.00073"
"9.40800","0.78420","0.00054"
"9.60000","0.80016","0.00063"
"9.79200","0.81625","0.00040"
"9.98400","0.83215","0.00071"
"10.17600","0.84817","0.00053"
"10.36800","0.86420","0.00064"
"10.56000","0.88010","0.00056"
"10.75200","0.89619","0.00079"
"10.94400","0.91221","0.00088"
"11.13600","0.92817","0.00031"
"11.32800","0.94414","0.00062"
"11.52000","0.96016","0.00100"
"11.71200","0.97618","0.00048"
"11.90400","0.99221","0.00079"
"12.09600","1.00817","0.00063"
"12.28800","1.02413","0.00072"
"12.48000","1.04016","0.00068"
"12.67200","1.05612","0.00051"
"12.86400","1.07215","0.00070"
"13.05600","1.08817","0.00052"
"13.24800","1.10413","0.00064"
"13.44000","1.12022","0.00120"
"13.63200","1.13618","0.00074"
"13.82400","1.15208","0.00075"
"14.01600","1.16817","0.00068"
"14.20800","1.18419","0.00054"
"14.40000","1.20016","0.00059"
"14.59200","1.21618","0.00111"
"14.78400","1.23214","0.00110"
"14.97600","1.24817","0.00061"
"15.16800","1.26419","0.00078"
"15.36000","1.28009","0.00045"
"15.55200","1.29612","0.00096"
"15.74400","1.31220","0.00053"
"15.93600","1.32810","0.00065"
"16.12800","1.34419","0.00082"
"16.32000","1.36015","0.00073"
"16.51200","1.37612","0.00102"
"16.70400","1.39220","0.00060"
"16.89600","1.40822","0.00061"
"17.08800","1.42407","0.00103"
"17.28000","1.44015","0.00066"
"17.47200","1.45611","0.00093"
"17.66400","1.47214","0.00048"
"17.85600","1.48816","0.00069"
"18.04800","1.50413","0.00056"
"18.24000","1.52015","0.00083"
"18.43200","1.53617","0.00097"
"18.62400","1.55214","0.00072"
"18.81600","1.56822","0.00026"
"19.00800","1.58418","0.00054"
"19.20000","1.60015","0.00084"
"19.39200","1.61617","0.00094"
"19.58400","1.63213","0.00053"
"19.77600","1.64816","0.00091"
"19.96800","1.66424","0.00107"
"20.16000","1.68015","0.00072"
"20.35200","1.69617","0.00079"
"20.54400","1.71213","0.00109"
"20.73600","1.72816","0.00049"
"20.92800","1.74418","0.00059"
"21.12000","1.76020","0.00076"
"21.31200","1.77611","0.00058"
"21.50400","1.79219","0.00037"
"21.69600","1.80821","0.00040"
"21.88800","1.82412","0.00070"
"22.08000","1.84020","0.00043"
"22.27200","1.85617","0.00018"
"22.46400","1.87207","0.00021"
"22.65600","1.88815","0.00040"
"22.84800","1.90418","0.00006"
"23.04000","1.92014","0.00023"
"23.23200","1.93616","0.00037"
"23.42400","1.95213","0.00067"
"23.61600","1.96815","0.00079"
"23.80800","1.98418","0.00037"
"24.00000","2.00014","0.00016"
"24.19200","2.01622","0.00037"
"24.38400","2.03219","0.00050"
"24.57600","2.04815","0.00034"
"24.76800","2.06423","-0.00004"
"24.96000","2.08014","0.00041"
"25.15200","2.09616","0.00020"
"25.34400","2.11213","0.00008"
"25.53600","2.12815","0.00058"
"25.72800","2.14417","0.00018"
"25.92000","2.16014","0.00047"
"26.11200","2.17616","0.00068"
"26.30400","2.19218","0.00057"
"26.49600","2.20815","0.00030"
"26.68800","2.22417","0.00037"
"26.88000","2.24013","0.00020"
"27.07200","2.25616","0.00042"
"27.26400","2.27212","0.00033"
"27.45600","2.28821","0.00064"
"27.64800","2.30411","0.00059"
"27.84000","2.32013","0.00041"
"28.03200","2.33622","0.00060"
"28.22400","2.35218","0.00038"
"28.41600","2.36814","0.00034"
"28.60800","2.38417","-0.00009"
"28.80000","2.40013","0.00022"
"28.99200","2.41615","-0.00009"
"29.18400","2.43224","0.00058"
"29.37600","2.44814","0.00054"
"29.56800","2.46423","-0.00013"
"29.76000","2.48013","0.00017"
"29.95200","2.49609","0.00034"
"30.14400","2.51218","-0.00002"
"30.33600","2.52820","0.00042"
"30.52800","2.54410","0.00034"
"30.72000","2.56019","0.00001"
"30.91200","2.57615","0.00023"
"31.10400","2.59212","0.00038"
"31.29600","2.60820","0.00040"
"31.48800","2.62416","0.00010"
"31.68000","2.64019","0.00029"
"31.87200","2.65621","-0.00057"
"32.06400","2.67211","0.00023"
"32.25600","2.68820","0.00052"
"32.44800","2.70416","0.00035"
"32.64000","2.72012","0.00014"
"32.83200","2.73615","0.00030"
"33.02400","2.75217","0.00031"
"33.21600","2.76814","0.00004"
"33.40800","2.78416","0.00009"
"33.60000","2.80018","0.00009"
"33.79200","2.81615","0.00072"
"33.98400","2.83217","0.00002"
"34.17600","2.84819","0.00023"
"34.36800","2.86416","-0.00001"
"34.56000","2.88018","-0.00017"
"34.75200","2.89615","0.00033"
"34.94400","2.91211","0.00017"
"35.13600","2.92813","0.00035"
"35.32800","2.94416","-0.00018"
"35.52000","2.96018","0.00041"
"35.71200","2.97614","0.00039"
"35.90400","2.99211","0.00035"
"36.09600","3.00819","0.00008"
"36.28800","3.02415","0.00022"
"36.48000","3.04018","0.00022"
"36.67200","3.05614","0.00049"
"36.86400","3.07211","0.00016"
"37.05600","3.08819","0.00026"
"37.24800","3.10415","0.00045"
"37.44000","3.12012","0.00078"
"37.63200","3.13614","0.00056"
"37.82400","3.15216","0.00057"
"38.01600","3.16813","0.00035"
"38.20800","3.18421","0.00029"
"38.40000","3.20012","0.00017"
"38.59200","3.21608","0.00030"
"38.78400","3.23222","0.00069"
"38.97600","3.24819","0.00001"
"39.16800","3.26415","0.00010"
"39.36000","3.28023","0.00011"
"39.55200","3.29620","0.00039"
"39.74400","3.31210","0.00030"
"39.93600","3.32818","0.00035"
"40.12800","3.34415","0.00084"
"40.32000","3.36017","0.00016"
"40.51200","3.37620","0.00019"
"40.70400","3.39210","0.00040"
"40.89600","3.40812","0.00053"
"41.08800","3.42421","0.00047"
"41.28000","3.44011","0.00049"
"41.47200","3.45619","0.00038"
"41.66400","3.47216","0.00025"
"41.85600","3.48818","0.00062"
"42.04800","3.50420","0.00058"
"42.24000","3.52017","0.00114"
"42.43200","3.53613","0.00097"
"42.62400","3.55216","0.00022"
"42.81600","3.56812","0.00041"
"43.00800","3.58414","0.00081"
"43.20000","3.60017","0.00077"
"43.39200","3.61613","0.00045"
"43.58400","3.63221","0.00052"
"43.77600","3.64818","0.00064"
"43.96800","3.66414","0.00054"
"44.16000","3.68022","0.00022"
"44.35200","3.69619","0.00002"
"44.54400","3.71215","0.00040"
"44.73600","3.72818","0.00066"
"44.92800","3.74414","0.00054"
"45.12000","3.76016","0.00066"
"45.31200","3.77619","0.00041"
"45.50400","3.79215","0.00049"
"45.69600","3.80817","0.00046"
"45.88800","3.82420","0.00032"
"46.08000","3.84010","0.00017"
"46.27200","3.85619","0.00026"
"46.46400","3.87221","0.00044"
"46.65600","3.88817","0.00049"
"46.84800","3.90420","0.00080"
"47.04000","3.92016","0.00070"
"47.23200","3.93612","0.00021"
"47.42400","3.95215","0.00038"
"47.61600","3.96817","0.00032"
"47.80800","3.98414","0.00048"
"48.00000","4.00016","0.00071"
"48.19200","4.01612","0.00027"
"48.38400","4.03221","0.00098"
"48.57600","4.04817","0.00056"
"48.76800","4.06413","0.00068"
"48.96000","4.08016","0.00040"
"49.15200","4.09618","0.00027"
"49.34400","4.11214","0.00057"
"49.53600","4.12823","0.00042"
"49.72800","4.14419","0.00024"
"49.92000","4.16010","0.00050"
"50.11200","4.17624","0.00016"
"50.30400","4.19214","0.00062"
"50.49600","4.20811","0.00045"
"50.68800","4.22425","0.00050"
"50.88000","4.24009","0.00075"
"51.07200","4.25618","-0.00001"
"51.26400","4.27220","0.00070"
"51.45600","4.28811","0.00061"
"51.64800","4.30419","0.00079"
"51.84000","4.32021","0.00064"
"52.03200","4.33612","0.00080"
"52.22400","4.35220","0.00048"
"52.41600","4.36822","0.00134"
"52.60800","4.38413","0.00097"
"52.80000","4.40015","0.00038"
"52.99200","4.41617","0.00070"
"53.18400","4.43220","0.00069"
"53.37600","4.44816","0.00075"
"53.56800","4.46413","0.00090"
"53.76000","4.48015","0.00071"
"53.95200","4.49617","0.00073"
"54.14400","4.51214","0.00090"
"54.33600","4.52816","0.00039"
"54.52800","4.54418","0.00041"
"54.72000","4.56015","0.00075"
"54.91200","4.57617","0.00062"
"55.10400","4.59219","0.00061"
"55.29600","4.60816","0.00058"
"55.48800","4.62418","0.00110"
"55.68000","4.64015","0.00050"
"55.87200","4.65617","0.00066"
"56.06400","4.67213","0.00051"
"56.25600","4.68816","0.00075"
"56.44800","4.70418","0.00059"
"56.64000","4.72020","0.00076"
"56.83200","4.73617","0.00068"
"57.02400","4.75219","0.00036"
"57.21600","4.76822","0.00068"
"57.40800","4.78412","0.00098"
"57.60000","4.80020","0.00107"
"57.79200","4.81611","0.00124"
"57.98400","4.83213","0.00067"
"58.17600","4.84815","0.00069"
"58.36800","4.86412","0.00083"
"58.56000","4.88020","0.00070"
"58.75200","4.89616","0.00082"
"58.94400","4.91213","0.00064"
"59.13600","4.92815","0.00071"
"59.32800","4.94418","0.00104"
"59.52000","4.96014","0.00087"
"59.71200","4.97622","0.00088"
"59.90400","4.99219","0.00115"
"60.09600","5.00809","0.00100"
"60.28800","5.02417","0.00066"
"60.48000","5.04020","0.00064"
"60.67200","5.05616","0.00043"
"60.86400","5.07219","0.00110"
"61.05600","5.08815","0.00062"
"61.24800","5.10411","0.00066"
"61.44000","5.12020","0.00048"
"61.63200","5.13616","0.00067"
"61.82400","5.15212","0.00113"
"62.01600","5.16821","0.00084"
"62.20800","5.18417","0.00127"
"62.40000","5.20014","0.00099"
"62.59200","5.21622","0.00087"
"62.78400","5.23212","0.00105"
"62.97600","5.24815","0.00093"
"63.16800","5.26417","0.00122"
"63.36000","5.28013","0.00109"
"63.55200","5.29616","0.00111"
"63.74400","5.31224","0.00138"
"63.93600","5.32814","0.00121"
"64.12800","5.34417","0.00116"
"64.32000","5.36013","0.00078"
"64.51200","5.37616","0.00102"
"64.70400","5.39224","0.00078"
"64.89600","5.40814","0.00099"
"65.08800","5.42417","0.00072"
"65.28000","5.44013","0.00107"
"65.47200","5.45615","0.00111"
"65.66400","5.47224","0.00110"
"65.85600","5.48820","0.00122"
"66.04800","5.50416","0.00076"
"66.24000","5.52019","0.00106"
"66.43200","5.53615","0.00091"
"66.62400","5.55218","0.00066"
"66.81600","5.56814","0.00073"
"67.00800","5.58410","0.00113"
"67.20000","5.60019","0.00082"
"67.39200","5.61615","0.00124"
"67.58400","5.63211","0.00053"
"67.77600","5.64820","0.00127"
"67.96800","5.66422","0.00124"
"68.16000","5.68013","0.00078"
"68.35200","5.69615","0.00074"
"68.54400","5.71223","0.00109"
"68.73600","5.72808","0.00097"
"68.92800","5.74422","0.00141"
"69.12000","5.76018","0.00118"
"69.31200","5.77615","0.00131"
"69.50400","5.79217","0.00123"
"69.69600","5.80814","0.00072"
"69.88800","5.82416","0.00108"
"70.08000","5.84018","0.00101"
"70.27200","5.85615","0.00119"
"70.46400","5.87217","0.00142"
"70.65600","5.88819","0.00098"
"70.84800","5.90416","0.00098"
"71.04000","5.92018","0.00082"
"71.23200","5.93614","0.00124"
"71.42400","5.95211","0.00127"
"71.61600","5.96819","0.00165"
"71.80800","5.98416","0.00140"
"72.00000","6.00018","0.00119"
"72.19200","6.01620","0.00126"
"72.38400","6.03217","0.00136"
"72.57600","6.04819","0.00161"
"72.76800","6.06415","0.00137"
"72.96000","6.08012","0.00120"
"73.15200","6.09620","0.00164"
"73.34400","6.11216","0.00150"
"73.53600","6.12813","0.00143"
"73.72800","6.14421","0.00071"
"73.92000","6.16017","0.00123"
"74.11200","6.17608","0.00142"
"74.30400","6.19216","0.00155"
"74.49600","6.20819","0.00155"
"74.68800","6.22415","0.00170"
"74.88000","6.24017","0.00131"
"75.07200","6.25614","0.00140"
"75.26400","6.27216","0.00215"
"75.45600","6.28824","0.00171"
"75.64800","6.30415","0.00161"
"75.84000","6.32017","0.00166"
"76.03200","6.33620","0.00121"
"76.22400","6.35210","0.00146"
"76.41600","6.36818","0.00093"
"76.60800","6.38421","0.00196"
"76.80000","6.40017","0.00191"
"76.99200","6.41613","0.00157"
"77.18400","6.43216","0.00124"
"77.37600","6.44812","0.00167"
"77.56800","6.46421","0.00195"
"77.76000","6.48017","0.00162"
"77.95200","6.49619","0.00178"
"78.14400","6.51216","0.00149"
"78.33600","6.52812","0.00234"
"78.52800","6.54420","0.00167"
"78.72000","6.56017","0.00163"
"78.91200","6.57613","0.00143"
"79.10400","6.59222","0.00175"
"79.29600","6.60812","0.00179"
"79.48800","6.62408","0.00198"
"79.68000","6.64023","0.00187"
"79.87200","6.65613","0.00180"
"80.06400","6.67215","0.00157"
"80.25600","6.68818","0.00228"
"80.44800","6.70414","0.00188"
"80.64000","6.72016","0.00192"
"80.83200","6.73619","0.00218"
"81.02400","6.75215","0.00199"
"81.21600","6.76818","0.00166"
"81.40800","6.78414","0.00191"
"81.60000","6.80016","0.00201"
"81.79200","6.81619","0.00209"
"81.98400","6.83221","0.00223"
"82.17600","6.84811","0.00258"
"82.36800","6.86420","0.00184"
"82.56000","6.88022","0.00230"
"82.75200","6.89612","0.00221"
"82.94400","6.91221","0.00192"
"83.13600","6.92817","0.00225"
"83.32800","6.94414","0.00224"
"83.52000","6.96016","0.00211"
"83.71200","6.97612","0.00211"
"83.90400","6.99215","0.00237"
"84.09600","7.00817","0.00187"
"84.28800","7.02413","0.00259"
"84.48000","7.04016","0.00190"
"84.67200","7.05618","0.00184"
"84.86400","7.07214","0.00198"
"85.05600","7.08817","0.00258"
"85.24800","7.10419","0.00215"
"85.44000","7.12016","0.00270"
"85.63200","7.13618","0.00250"
"85.82400","7.15214","0.00246"
"86.01600","7.16817","0.00260"
"86.20800","7.18413","0.00231"
"86.40000","7.20015","0.00265"
"86.59200","7.21618","0.00262"
"86.78400","7.23214","0.00242"
"86.97600","7.24817","0.00300"
"87.16800","7.26413","0.00264"
"87.36000","7.28015","0.00248"
"87.55200","7.29618","0.00255"
"87.74400","7.31220","0.00197"
"87.93600","7.32810","0.00228"
"88.12800","7.34419","0.00209"
"88.32000","7.36015","0.00253"
"88.51200","7.37612","0.00242"
"88.70400","7.39214","0.00238"
"88.89600","7.40816","0.00288"
"89.08800","7.42413","0.00246"
"89.28000","7.44021","0.00238"
"89.47200","7.45617","0.00261"
"89.66400","7.47214","0.00245"
"89.85600","7.48822","0.00272"
"90.04800","7.50418","0.00248"
"90.24000","7.52009","0.00323"
"90.43200","7.53623","0.00331"
"90.62400","7.55214","0.00277"
"90.81600","7.56810","0.00288"
"91.00800","7.58424","0.00251"
"91.20000","7.60015","0.00268"
"91.39200","7.61617","0.00320"
"91.58400","7.63219","0.00305"
"91.77600","7.64816","0.00325"
"91.96800","7.66412","0.00309"
"92.16000","7.68021","0.00287"
"92.35200","7.69611","0.00258"
"92.54400","7.71213","0.00276"
"92.73600","7.72822","0.00309"
"92.92800","7.74412","0.00275"
"93.12000","7.76014","0.00308"
"93.31200","7.77617","0.00296"
"93.50400","7.79213","0.00246"
"93.69600","7.80816","0.00266"
"93.88800","7.82418","0.00253"
"94.08000","7.84014","0.00240"
"94.27200","7.85616","0.00270"
"94.46400","7.87213","0.00279"
"94.65600","7.88815","0.00337"
"94.84800","7.90418","0.00303"
"95.04000","7.92014","0.00272"
"95.23200","7.93616","0.00328"
"95.42400","7.95213","0.00276"
"95.61600","7.96815","0.00328"
"95.80800","7.98417","0.00318"
"96.00000","8.00020","0.00325"
"96.19200","8.01616","0.00297"
"96.38400","8.03219","0.00314"
"96.57600","8.04809","0.00332"
"96.76800","8.06411","0.00324"
"96.96000","8.08020","0.00320"
"97.15200","8.09610","0.00300"
"97.34400","8.11212","0.00342"
"97.53600","8.12815","0.00371"
"97.72800","8.14411","0.00354"
"97.92000","8.16020","0.00307"
"98.11200","8.17622","0.00307"
"98.30400","8.19212","0.00378"
"98.49600","8.20821","0.00358"
"98.68800","8.22411","0.00339"
"98.88000","8.24013","0.00319"
"99.07200","8.25622","0.00371"
"99.26400","8.27218","0.00396"
"99.45600","8.28814","0.00338"
"99.64800","8.30417","0.00359"
"99.84000","8.32013","0.00346"
"100.03200","8.33616","0.00371"
"100.22400","8.35218","0.00335"
"100.41600","8.36814","0.00375"
"100.60800","8.38417","0.00363"
"100.80000","8.40019","0.00360"
"100.99200","8.41609","0.00399"
"101.18400","8.43218","0.00369"
"101.37600","8.44820","0.00369"
"101.56800","8.46411","0.00360"
"101.76000","8.48019","0.00350"
"101.95200","8.49615","0.00410"
"102.14400","8.51218","0.00410"
"102.33600","8.52820","0.00433"
"102.52800","8.54416","0.00457"
"102.72000","8.56013","0.00435"
"102.91200","8.57621","0.00435"
"103.10400","8.59211","0.00418"
"103.29600","8.60814","0.00435"
"103.48800","8.62422","0.00416"
"103.68000","8.64013","0.00490"
"103.87200","8.65621","0.00496"
"104.06400","8.67217","0.00463"
"104.25600","8.68814","0.00506"
"104.44800","8.70422","0.00460"
"104.64000","8.72018","0.00436"
"104.83200","8.73615","0.00448"
"105.02400","8.75217","0.00447"
"105.21600","8.76814","0.00469"
"105.40800","8.78410","0.00509"
"105.60000","8.80018","0.00504"
"105.79200","8.81615","0.00463"
"105.98400","8.83217","0.00574"
"106.17600","8.84819","0.00512"
"106.36800","8.86416","0.00497"
"106.56000","8.88018","0.00489"
"106.75200","8.89620","0.00497"
"106.94400","8.91217","0.00476"
"107.13600","8.92813","0.00465"
"107.32800","8.94416","0.00516"
"107.52000","8.96018","0.00555"
"107.71200","8.97614","0.00478"
"107.90400","8.99211","0.00541"
"108.09600","9.00819","0.00577"
"108.28800","9.02421","0.00555"
"108.48000","9.04018","0.00559"
"108.67200","9.05620","0.00532"
"108.86400","9.07216","0.00586"
"109.05600","9.08819","0.00571"
"109.24800","9.10421","0.00559"
"109.44000","9.12018","0.00559"
"109.63200","9.13614","0.00589"
"109.82400","9.15216","0.00538"
"110.01600","9.16819","0.00582"
"110.20800","9.18415","0.00550"
"110.40000","9.20017","0.00590"
"110.59200","9.21614","0.00548"
"110.78400","9.23216","0.00549"
"110.97600","9.24824","0.00643"
"111.16800","9.26415","0.00608"
"111.36000","9.28017","0.00627"
"111.55200","9.29620","0.00614"
"111.74400","9.31210","0.00666"
"111.93600","9.32818","0.00721"
"112.12800","9.34415","0.00625"
"112.32000","9.36017","0.00638"
"112.51200","9.37613","0.00656"
"112.70400","9.39216","0.00612"
"112.89600","9.40812","0.00679"
"113.08800","9.42421","0.00656"
"113.28000","9.44017","0.00618"
"113.47200","9.45613","0.00644"
"113.66400","9.47216","0.00688"
"113.85600","9.48818","0.00607"
"114.04800","9.50420","0.00517"
"114.24000","9.52017","0.00500"
"114.43200","9.53613","0.00600"
"114.62400","9.55216","0.00562"
"114.81600","9.56818","0.00607"
"115.00800","9.58414","0.00612"
"115.20000","9.60017","0.00601"
"115.39200","9.61619","0.00672"
"115.58400","9.63215","0.00666"
"115.77600","9.64818","0.00670"
"115.96800","9.66414","0.00660"
"116.16000","9.68010","0.00694"
"116.35200","9.69619","0.00718"
"116.54400","9.71215","0.00704"
"116.73600","9.72818","0.00731"
"116.92800","9.74420","0.00773"
"117.12000","9.76010","0.00722"
"117.31200","9.77619","0.00755"
"117.50400","9.79215","0.00783"
"117.69600","9.80817","0.00770"
"117.88800","9.82420","0.00812"
"118.08000","9.84016","0.00776"
"118.27200","9.85612","0.00785"
"118.46400","9.87215","0.00770"
"118.65600","9.88811","0.00819"
"118.84800","9.90420","0.00842"
"119.04000","9.92022","0.00842"
"119.23200","9.93612","0.00840"
"119.42400","9.95215","0.00875"
"119.61600","9.96823","0.00879"
"119.80800","9.98413","0.00865"
"120.00000","10.00016","0.00835"
"120.19200","10.01618","0.00503"
"120.38400","10.03209","0.00494"
"120.57600","10.04823","0.00545"
"120.76800","10.06419","0.00552"
"120.96000","10.08010","0.00527"
"121.15200","10.09618","0.00577"
"121.34400","10.11214","0.00564"
"121.53600","10.12817","0.00547"
"121.72800","10.14419","0.00606"
"121.92000","10.16015","0.00589"
"122.11200","10.17618","0.00603"
"122.30400","10.19220","0.00691"
"122.49600","10.20811","0.00637"
"122.68800","10.22413","0.00683"
"122.88000","10.24015","0.00686"
"123.07200","10.25612","0.00673"
"123.26400","10.27220","0.00732"
"123.45600","10.28822","0.00716"
"123.64800","10.30413","0.00736"
"123.84000","10.32015","0.00744"
"124.03200","10.33618","0.00736"
"124.22400","10.35214","0.00765"
"124.41600","10.36816","0.00774"
"124.60800","10.38419","0.00787"
"124.80000","10.40015","0.00785"
"124.99200","10.41617","0.00765"
"125.18400","10.43214","0.00773"
"125.37600","10.44822","0.00785"
"125.56800","10.46418","0.00767"
"125.76000","10.48009","0.00782"
"125.95200","10.49623","0.00667"
"126.14400","10.51220","0.00578"
"126.33600","10.52816","0.00650"
"126.52800","10.54418","0.00593"
"126.72000","10.56015","0.00614"
"126.91200","10.57611","0.00654"
"127.10400","10.59219","0.00633"
"127.29600","10.60810","0.00589"
"127.48800","10.62418","0.00587"
"127.68000","10.64020","0.00632"
"127.87200","10.65617","0.00675"
"128.06400","10.67219","0.00670"
"128.25600","10.68822","0.00630"
"128.44800","10.70418","0.00720"
"128.64000","10.72020","0.00711"
"128.83200","10.73617","0.00689"
"129.02400","10.75213","0.00677"
"129.21600","10.76816","0.00704"
"129.40800","10.78418","0.00735"
"129.60000","10.80014","0.00694"
"129.79200","10.81617","0.00694"
"129.98400","10.83213","0.00692"
"130.17600","10.84815","0.00691"
"130.36800","10.86418","0.00681"
"130.56000","10.88014","0.00678"
"130.75200","10.89616","0.00684"
"130.94400","10.91219","0.00693"
"131.13600","10.92809","0.00693"
"131.32800","10.94423","0.00664"
"131.52000","10.96014","0.00746"
"131.71200","10.97610","0.00724"
"131.90400","10.99219","0.00714"
"132.09600","11.00815","0.00749"
"132.28800","11.02417","0.00760"
"132.48000","11.04020","0.00781"
"132.67200","11.05616","0.00783"
"132.86400","11.07218","0.00755"
"133.05600","11.08815","0.00729"
"133.24800","11.10411","0.00853"
"133.44000","11.12020","0.00838"
"133.63200","11.13622","0.00849"
"133.82400","11.15212","0.00866"
"134.01600","11.16821","0.00859"
"134.20800","11.18423","0.00898"
"134.40000","11.20013","0.00884"
"134.59200","11.21616","0.00876"
"134.78400","11.23218","0.00915"
"134.97600","11.24809","0.01008"
"135.16800","11.26417","0.00931"
"135.36000","11.28007","0.00908"
"135.55200","11.29616","0.00944"
"135.74400","11.31224","0.01009"
"135.93600","11.32814","0.00996"
"136.12800","11.34417","0.01000"
"136.32000","11.36019","0.01004"
"136.51200","11.37615","0.01047"
"136.70400","11.39218","0.01067"
"136.89600","11.40820","0.01074"
"137.08800","11.42417","0.00890"
"137.28000","11.44013","0.00976"
"137.47200","11.45615","0.00967"
"137.66400","11.47218","0.00938"
"137.85600","11.48814","0.00986"
"138.04800","11.50416","0.01031"
"138.24000","11.52013","0.01004"
"138.43200","11.53621","0.00938"
"138.62400","11.55212","0.00902"
"138.81600","11.56820","0.00978"
"139.00800","11.58416","0.00993"
"139.20000","11.60013","0.00982"
"139.39200","11.61621","0.00997"
"139.58400","11.63211","0.01024"
"139.77600","11.64814","0.01050"
"139.96800","11.66416","0.01034"
"140.16000","11.68007","0.01058"
"140.35200","11.69615","0.01088"
"140.54400","11.71217","0.01132"
"140.73600","11.72814","0.01142"
"140.92800","11.74416","0.01139"
"141.12000","11.76018","0.01140"
"141.31200","11.77609","0.01175"
"141.50400","11.79223","0.01194"
"141.69600","11.80814","0.01238"
"141.88800","11.82410","0.01237"
"142.08000","11.84024","0.01264"
"142.27200","11.85620","0.01214"
"142.46400","11.87211","0.01245"
"142.65600","11.88819","0.01264"
"142.84800","11.90422","0.01318"
"143.04000","11.92012","0.01294"
"143.23200","11.93620","0.01326"
"143.42400","11.95217","0.01320"
"143.61600","11.96813","0.01316"
"143.80800","11.98421","0.01348"
"144.00000","12.00012","0.01359"
"144.19200","12.01614","0.01387"
"144.38400","12.03223","0.01389"
"144.57600","12.04813","0.01412"
"144.76800","12.06415","0.01460"
"144.96000","12.08024","0.01439"
"145.15200","12.09614","0.01516"
"145.34400","12.11210","0.01508"
"145.53600","12.12819","0.01552"
"145.72800","12.14415","0.01575"
"145.92000","12.16018","0.01548"
"146.11200","12.17614","0.01564"
"146.30400","12.19216","0.01641"
"146.49600","12.20819","0.01628"
"146.68800","12.22415","0.01631"
"146.88000","12.24017","0.01614"
"147.07200","12.25620","0.01692"
"147.26400","12.27222","0.01654"
"147.45600","12.28824","0.01658"
"147.64800","12.30415","0.01705"
"147.84000","12.32017","0.01695"
"148.03200","12.33619","0.01698"
"148.22400","12.35210","0.01785"
"148.41600","12.36812","0.01792"
"148.60800","12.38421","0.01822"
"148.80000","12.40011","0.01829"
"148.99200","12.41619","0.01856"
"149.18400","12.43222","0.01858"
"149.37600","12.44812","0.01876"
"149.56800","12.46420","0.01872"
"149.76000","12.48023","0.01893"
"149.95200","12.49607","0.01892"
"150.14400","12.51222","0.01925"
"150.33600","12.52818","0.01927"
"150.52800","12.54408","0.02000"
"150.72000","12.56023","0.02030"
"150.91200","12.57613","0.02063"
"151.10400","12.59215","0.02095"
"151.29600","12.60818","0.02084"
"151.48800","12.62414","0.02147"
"151.68000","12.64017","0.02152"
"151.87200","12.65625","0.02210"
"152.06400","12.67215","0.02185"
"152.25600","12.68818","0.02222"
"152.44800","12.70420","0.02210"
"152.64000","12.72010","0.02248"
"152.83200","12.73619","0.02312"
"153.02400","12.75215","0.02230"
"153.21600","12.76812","0.02161"
"153.40800","12.78420","0.02276"
"153.60000","12.80016","0.02285"
"153.79200","12.81619","0.02307"
"153.98400","12.83215","0.02355"
"154.17600","12.84817","0.02361"
"154.36800","12.86414","0.02429"
"154.56000","12.88016","0.02429"
"154.75200","12.89612","0.02477"
"154.94400","12.91221","0.02540"
"155.13600","12.92823","0.02561"
"155.32800","12.94414","0.02552"
"155.52000","12.96016","0.02602"
"155.71200","12.97618","0.02617"
"155.90400","12.99215","0.02641"
"156.09600","13.00817","0.02726"
"156.28800","13.02419","0.02762"
"156.48000","13.04016","0.02791"
"156.67200","13.05618","0.02801"
"156.86400","13.07215","0.02881"
"157.05600","13.08811","0.02908"
"157.24800","13.10419","0.02926"
"157.44000","13.12016","0.02955"
"157.63200","13.13612","0.02972"
"157.82400","13.15220","0.02981"
"158.01600","13.16811","0.03027"
"158.20800","13.18419","0.03121"
"158.40000","13.20015","0.03169"
"158.59200","13.21612","0.03271"
"158.78400","13.23220","0.03335"
"158.97600","13.24811","0.03403"
"159.16800","13.26413","0.03457"
"159.36000","13.28015","0.03525"
"159.55200","13.29611","0.03510"
"159.74400","13.31220","0.03559"
"159.93600","13.32822","0.03610"
"160.12800","13.34413","0.03673"
"160.32000","13.36021","0.03771"
"160.51200","13.37617","0.03849"
"160.70400","13.39214","0.03848"
"160.89600","13.40816","0.03912"
"161.08800","13.42419","0.03955"
"161.28000","13.44009","0.04028"
"161.47200","13.45617","0.04075"
"161.66400","13.47220","0.04031"
"161.85600","13.48816","0.04101"
"162.04800","13.50418","0.04201"
"162.24000","13.52015","0.04174"
"162.43200","13.53617","0.04095"
"162.62400","13.55225","0.04136"
"162.81600","13.56816","0.04171"
"163.00800","13.58418","0.04235"
"163.20000","13.60021","0.04269"
"163.39200","13.61611","0.04320"
"163.58400","13.63219","0.04336"
"163.77600","13.64822","0.04414"
"163.96800","13.66412","0.04450"
"164.16000","13.68020","0.04514"
"164.35200","13.69617","0.04562"
"164.54400","13.71213","0.04642"
"164.73600","13.72816","0.04688"
"164.92800","13.74418","0.04672"
"165.12000","13.76020","0.04810"
"165.31200","13.77617","0.04849"
"165.50400","13.79213","0.04763"
"165.69600","13.80815","0.04801"
"165.88800","13.82418","0.04836"
"166.08000","13.84014","0.04951"
"166.27200","13.85616","0.05088"
"166.46400","13.87219","0.05082"
"166.65600","13.88815","0.05043"
"166.84800","13.90418","0.05052"
"167.04000","13.92020","0.05171"
"167.23200","13.93616","0.05194"
"167.42400","13.95213","0.05377"
"167.61600","13.96815","0.05321"
"167.80800","13.98417","0.05480"
"168.00000","14.00020","0.05589"
"168.19200","14.01616","0.05616"
"168.38400","14.03219","0.05680"
"168.57600","14.04821","0.05767"
"168.76800","14.06411","0.05847"
"168.96000","14.08020","0.05993"
"169.15200","14.09616","0.06038"
"169.34400","14.11212","0.06145"
"169.53600","14.12821","0.06179"
"169.72800","14.14411","0.06284"
"169.92000","14.16020","0.06334"
"170.11200","14.17616","0.06302"
"170.30400","14.19212","0.06388"
"170.49600","14.20815","0.06478"
"170.68800","14.22417","0.06602"
"170.88000","14.24013","0.06634"
"171.07200","14.25616","0.06696"
"171.26400","14.27224","0.06746"
"171.45600","14.28808","0.06778"
"171.64800","14.30423","0.06841"
"171.84000","14.32019","0.06896"
"172.03200","14.33609","0.06953"
"172.22400","14.35224","0.07016"
"172.41600","14.36814","0.07115"
"172.60800","14.38411","0.07187"
"172.80000","14.40019","0.07227"
"172.99200","14.41615","0.07365"
"173.18400","14.43212","0.07440"
"173.37600","14.44820","0.07506"
"173.56800","14.46411","0.07589"
"173.76000","14.48013","0.07698"
"173.95200","14.49615","0.07828"
"174.14400","14.51212","0.07892"
"174.33600","14.52814","0.08011"
"174.52800","14.54416","0.08097"
"174.72000","14.56019","0.08223"
"174.91200","14.57621","0.08316"
"175.10400","14.59223","0.08415"
"175.29600","14.60814","0.08571"
"175.48800","14.62416","0.08610"
"175.68000","14.64019","0.08783"
"175.87200","14.65609","0.08803"
"176.06400","14.67217","0.08899"
"176.25600","14.68814","0.09012"
"176.44800","14.70416","0.09063"
"176.64000","14.72018","0.09134"
"176.83200","14.73615","0.09215"
"177.02400","14.75223","0.09250"
"177.21600","14.76820","0.09307"
"177.40800","14.78410","0.09387"
"177.60000","14.80018","0.09450"
"177.79200","14.81614","0.09483"
"177.98400","14.83217","0.09536"
"178.17600","14.84819","0.09597"
"178.36800","14.86410","0.09644"
"178.56000","14.88012","0.09698"
"178.75200","14.89620","0.09739"
"178.94400","14.91211","0.09844"
"179.13600","14.92813","0.09876"
"179.32800","14.94422","0.09946"
"179.52000","14.96012","0.09954"
"179.71200","14.97620","0.10039"
"179.90400","14.99217","0.10104"
"180.09600","15.00813","0.10144"
"180.28800","15.02421","0.10254"
"180.48000","15.04012","0.10321"
"180.67200","15.05608","0.10350"
"180.86400","15.07217","0.10405"
"181.05600","15.08813","0.10429"
"181.24800","15.10415","0.10465"
"181.44000","15.12018","0.10469"
"181.63200","15.13614","0.10488"
"181.82400","15.15216","0.10549"
"182.01600","15.16819","0.10619"
"182.20800","15.18415","0.10659"
"182.40000","15.20017","0.10715"
"182.59200","15.21614","0.10800"
"182.78400","15.23210","0.10856"
"182.97600","15.24819","0.10963"
"183.16800","15.26415","0.11037"
"183.36000","15.28011","0.11069"
"183.55200","15.29620","0.11221"
"183.74400","15.31216","0.11290"
"183.93600","15.32812","0.11391"
"184.12800","15.34421","0.11402"
"184.32000","15.36011","0.11483"
"184.51200","15.37619","0.11598"
"184.70400","15.39216","0.11686"
"184.89600","15.40812","0.11751"
"185.08800","15.42415","0.11931"
"185.28000","15.44023","0.11958"
"185.47200","15.45607","0.12020"
"185.66400","15.47222","0.12147"
"185.85600","15.48818","0.12236"
"186.04800","15.50414","0.12326"
"186.24000","15.52023","0.12408"
"186.43200","15.53619","0.12479"
"186.62400","15.55210","0.12701"
"186.81600","15.56818","0.12788"
"187.00800","15.58414","0.12905"
"187.20000","15.60017","0.13037"
"187.39200","15.61625","0.13116"
"187.58400","15.63215","0.13291"
"187.77600","15.64824","0.13442"
"187.96800","15.66420","0.13562"
"188.16000","15.68016","0.13681"
"188.35200","15.69619","0.13779"
"188.54400","15.71215","0.13909"
"188.73600","15.72811","0.14045"
"188.92800","15.74414","0.14196"
"189.12000","15.76010","0.14282"
"189.31200","15.77613","0.14377"
"189.50400","15.79221","0.14497"
"189.69600","15.80817","0.14580"
"189.88800","15.82414","0.14674"
"190.08000","15.84022","0.14693"
"190.27200","15.85612","0.14824"
"190.46400","15.87221","0.14959"
"190.65600","15.88817","0.15002"
"190.84800","15.90413","0.15068"
"191.04000","15.92022","0.15220"
"191.23200","15.93612","0.15322"
"191.42400","15.95215","0.15405"
"191.61600","15.96823","0.15479"
"191.80800","15.98407","0.15608"
"192.00000","16.00016","0.15752"
"192.19200","16.01624","0.15854"
"192.38400","16.03214","0.15943"
"192.57600","16.04817","0.16085"
"192.76800","16.06413","0.16227"
"192.96000","16.08010","0.16306"
"193.15200","16.09618","0.10721"
"193.34400","16.11220","0.10522"
"193.53600","16.12811","0.10476"
"193.72800","16.14419","0.10626"
"193.92000","16.16015","0.10486"
"194.11200","16.17612","0.10626"
"194.30400","16.19220","0.10513"
"194.49600","16.20816","0.10717"
"194.68800","16.22407","0.10638"
"194.88000","16.24021","0.10858"
"195.07200","16.25612","0.10761"
"195.26400","16.27214","0.11011"
"195.45600","16.28816","0.10934"
"195.64800","16.30413","0.11163"
"195.84000","16.32015","0.11029"
"196.03200","16.33624","0.11236"
"196.22400","16.35208","0.11208"
"196.41600","16.36816","0.11360"
"196.60800","16.38424","0.11192"
"196.80000","16.40009","0.11451"
"196.99200","16.41617","0.11452"
"197.18400","16.43220","0.11584"
"197.37600","16.44810","0.11577"
"197.56800","16.46412","0.11721"
"197.76000","16.48015","0.11634"
"197.95200","16.49617","0.11794"
"198.14400","16.51220","0.11877"
"198.33600","16.52816","0.11982"
"198.52800","16.54418","0.12049"
"198.72000","16.56015","0.12164"
"198.91200","16.57611","0.12198"
"199.10400","16.59213","0.12253"
"199.29600","16.60816","0.12276"
"199.48800","16.62412","0.12368"
"199.68000","16.64021","0.12355"
"199.87200","16.65611","0.12298"
"200.06400","16.67213","0.12349"
"200.25600","16.68815","0.12429"
"200.44800","16.70412","0.12475"
"200.64000","16.72020","0.12604"
"200.83200","16.73617","0.12670"
"201.02400","16.75213","0.12733"
"201.21600","16.76815","0.12772"
"201.40800","16.78418","0.12920"
"201.60000","16.80008","0.12956"
"201.79200","16.81623","0.13134"
"201.98400","16.83213","0.13244"
"202.17600","16.84809","0.13346"
"202.36800","16.86423","0.13395"
"202.56000","16.88020","0.13453"
"202.75200","16.89616","0.13516"
"202.94400","16.91219","0.13647"
"203.13600","16.92815","0.13753"
"203.32800","16.94411","0.13834"
"203.52000","16.96020","0.13998"
"203.71200","16.97610","0.14109"
"203.90400","16.99213","0.14210"
"204.09600","17.00821","0.14239"
"204.28800","17.02405","0.14351"
"204.48000","17.04020","0.14406"
"204.67200","17.05622","0.14462"
"204.86400","17.07212","0.14567"
"205.05600","17.08821","0.14653"
"205.24800","17.10417","0.14697"
"205.44000","17.12019","0.14742"
"205.63200","17.13616","0.14836"
"205.82400","17.15212","0.14861"
"206.01600","17.16815","0.14932"
"206.20800","17.18417","0.15017"
"206.40000","17.20013","0.15089"
"206.59200","17.21616","0.15154"
"206.78400","17.23218","0.15262"
"206.97600","17.24814","0.15360"
"207.16800","17.26417","0.15394"
"207.36000","17.28019","0.15453"
"207.55200","17.29616","0.15537"
"207.74400","17.31218","0.15659"
"207.93600","17.32814","0.15723"
"208.12800","17.34417","0.15801"
"208.32000","17.36013","0.15915"
"208.51200","17.37615","0.15932"
"208.70400","17.39212","0.16036"
"208.89600","17.40820","0.16130"
"209.08800","17.42410","0.16244"
"209.28000","17.44013","0.16321"
"209.47200","17.45621","0.16369"
"209.66400","17.47218","0.16434"
"209.85600","17.48820","0.16525"
"210.04800","17.50416","0.16615"
"210.24000","17.52013","0.16746"
"210.43200","17.53621","0.16806"
"210.62400","17.55211","0.16895"
"210.81600","17.56808","0.16946"
"211.00800","17.58422","0.17027"
"211.20000","17.60012","0.17144"
"211.39200","17.61621","0.17196"
"211.58400","17.63223","0.17280"
"211.77600","17.64808","0.17286"
"211.96800","17.66416","0.17374"
"212.16000","17.68018","0.17399"
"212.35200","17.69615","0.17435"
"212.54400","17.71217","0.17245"
"212.73600","17.72820","0.17374"
"212.92800","17.74410","0.17408"
"213.12000","17.76018","0.17462"
"213.31200","17.77614","0.17528"
"213.50400","17.79211","0.17556"
"213.69600","17.80819","0.17627"
"213.88800","17.82416","0.17666"
"214.08000","17.84012","0.17743"
"214.27200","17.85620","0.17748"
"214.46400","17.87217","0.17872"
"214.65600","17.88819","0.17814"
"214.84800","17.90421","0.17961"
"215.04000","17.92012","0.18023"
"215.23200","17.93620","0.18125"
"215.42400","17.95223","0.18222"
"215.61600","17.96813","0.18245"
"215.80800","17.98421","0.18301"
"216.00000","18.00024","0.18354"
"216.19200","18.01614","0.18548"
"216.38400","18.03217","0.18571"
"216.57600","18.04819","0.18693"
"216.76800","18.06409","0.18728"
"216.96000","18.08012","0.18822"
"217.15200","18.09614","0.18936"
"217.34400","18.11216","0.19002"
"217.53600","18.12819","0.19049"
"217.72800","18.14415","0.19118"
"217.92000","18.16017","0.19140"
"218.11200","18.17620","0.19169"
"218.30400","18.19210","0.19110"
"218.49600","18.20824","0.13796"
"218.68800","18.22415","0.13585"
"218.88000","18.24017","0.13750"
"219.07200","18.25614","0.13420"
"219.26400","18.27216","0.14123"
"219.45600","18.28818","0.13441"
"219.64800","18.30415","0.13959"
"219.84000","18.32017","0.13474"
"220.03200","18.33619","0.13910"
"220.22400","18.35216","0.13574"
"220.41600","18.36812","0.14098"
"220.60800","18.38420","0.13806"
"220.80000","18.40017","0.14152"
"220.99200","18.41613","0.13835"
"221.18400","18.43222","0.14204"
"221.37600","18.44818","0.13962"
"221.56800","18.46414","0.14243"
"221.76000","18.48017","0.14025"
"221.95200","18.49619","0.14376"
"222.14400","18.51215","0.14211"
"222.33600","18.52818","0.14536"
"222.52800","18.54414","0.14361"
"222.72000","18.56017","0.14627"
"222.91200","18.57625","0.14464"
"223.10400","18.59209","0.14696"
"223.29600","18.60818","0.14575"
"223.48800","18.62420","0.14864"
"223.68000","18.64010","0.14720"
"223.87200","18.65619","0.14684"
"224.06400","18.67221","0.14648"
"224.25600","18.68812","0.14800"
"224.44800","18.70420","0.14804"
"224.64000","18.72016","0.14894"
"224.83200","18.73607","0.14905"
"225.02400","18.75215","0.15014"
"225.21600","18.76818","0.14940"
"225.40800","18.78414","0.15069"
"225.60000","18.80016","0.15016"
"225.79200","18.81612","0.15212"
"225.98400","18.83221","0.15160"
"226.17600","18.84817","0.15289"
"226.36800","18.86414","0.15275"
"226.56000","18.88016","0.15341"
"226.75200","18.89618","0.15383"
"226.94400","18.91209","0.15459"
"227.13600","18.92811","0.15439"
"227.32800","18.94419","0.15687"
"227.52000","18.96016","0.15679"
"227.71200","18.97612","0.15883"
"227.90400","18.99215","0.15806"
"228.09600","19.00817","0.15911"
"228.28800","19.02419","0.15956"
"228.48000","19.04016","0.16048"
"228.67200","19.05624","0.16158"
"228.86400","19.07214","0.16226"
"229.05600","19.08817","0.16286"
"229.24800","19.10419","0.16350"
"229.44000","19.12016","0.16455"
"229.63200","19.13612","0.16444"
"229.82400","19.15220","0.16468"
"230.01600","19.16817","0.16600"
"230.20800","19.18413","0.16638"
"230.40000","19.20015","0.16736"
"230.59200","19.21612","0.16791"
"230.78400","19.23220","0.16941"
"230.97600","19.24822","0.16931"
"231.16800","19.26413","0.16832"
"231.36000","19.28015","0.16876"
"231.55200","19.29618","0.16924"
"231.74400","19.31208","0.16955"
"231.93600","19.32822","0.17070"
"232.12800","19.34419","0.17063"
"232.32000","19.36009","0.17190"
"232.51200","19.37617","0.17257"
"232.70400","19.39214","0.17257"
"232.89600","19.40816","0.17316"
"233.08800","19.42418","0.17329"
"233.28000","19.44021","0.17414"
"233.47200","19.45617","0.17476"
"233.66400","19.47219","0.17540"
"233.85600","19.48822","0.17511"
"234.04800","19.50418","0.17592"
"234.24000","19.52015","0.17605"
"234.43200","19.53611","0.17660"
"234.62400","19.55219","0.17691"
"234.81600","19.56816","0.17753"
"235.00800","19.58412","0.17761"
"235.20000","19.60015","0.17832"
"235.39200","19.61611","0.17856"
"235.58400","19.63213","0.17893"
"235.77600","19.64822","0.17979"
"235.96800","19.66418","0.18041"
"236.16000","19.68014","0.18053"
"236.35200","19.69617","0.18156"
"236.54400","19.71207","0.18216"
"236.73600","19.72815","0.18304"
"236.92800","19.74424","0.18169"
"237.12000","19.76008","0.18178"
"237.31200","19.77623","0.18135"
"237.50400","19.79213","0.18299"
"237.69600","19.80809","0.18393"
"237.88800","19.82418","0.18390"
"238.08000","19.84020","0.18467"
"238.27200","19.85616","0.18416"
"238.46400","19.87219","0.18610"
"238.65600","19.88815","0.18623"
"238.84800","19.90417","0.18694"
"239.04000","19.92020","0.18752"
"239.23200","19.93616","0.18820"
"239.42400","19.95218","0.18903"
"239.61600","19.96815","0.18841"
"239.80800","19.98411","0.19009"
"240.00000","20.00020","0.18979"
"240.19200","20.01616","0.19013"
"240.38400","20.03218","0.18997"
"240.57600","20.04815","0.19041"
"240.76800","20.06417","0.19096"
"240.96000","20.08014","0.19014"
"241.15200","20.09622","0.19123"
"241.34400","20.11218","0.19120"
"241.53600","20.12815","0.19216"
"241.72800","20.14417","0.19228"
"241.92000","20.16019","0.19265"
"242.11200","20.17616","0.19354"
"242.30400","20.19218","0.19380"
"242.49600","20.20815","0.19370"
"242.68800","20.22417","0.19427"
"242.88000","20.24013","0.19459"
"243.07200","20.25610","0.19550"
"243.26400","20.27224","0.19571"
"243.45600","20.28814","0.19564"
"243.64800","20.30416","0.19640"
"243.84000","20.32019","0.19682"
"244.03200","20.33610","0.19741"
"244.22400","20.35217","0.19773"
"244.41600","20.36820","0.19789"
"244.60800","20.38410","0.19867"
"244.80000","20.40019","0.19913"
"244.99200","20.41615","0.19920"
"245.18400","20.43212","0.19919"
"245.37600","20.44820","0.20022"
"245.56800","20.46422","0.20056"
"245.76000","20.48013","0.20052"
"245.95200","20.49621","0.20096"
"246.14400","20.51217","0.20138"
"246.33600","20.52814","0.20186"
"246.52800","20.54416","0.20231"
"246.72000","20.56013","0.20284"
"246.91200","20.57615","0.20303"
"247.10400","20.59217","0.20332"
"247.29600","20.60807","0.20392"
"247.48800","20.62416","0.20400"
"247.68000","20.64018","0.20439"
"247.87200","20.65615","0.20470"
"248.06400","20.67217","0.20527"
"248.25600","20.68819","0.20508"
"248.44800","20.70416","0.20563"
"248.64000","20.72012","0.20616"
"248.83200","20.73621","0.20626"
"249.02400","20.75217","0.20652"
"249.21600","20.76813","0.20689"
"249.40800","20.78416","0.20720"
"249.60000","20.80018","0.20749"
"249.79200","20.81614","0.20812"
"249.98400","20.83217","0.20796"
"250.17600","20.84813","0.20820"
"250.36800","20.86415","0.20854"
"250.56000","20.88012","0.20870"
"250.75200","20.89620","0.20898"
"250.94400","20.91217","0.20937"
"251.13600","20.92813","0.20991"
"251.32800","20.94421","0.21039"
"251.52000","20.96012","0.21027"
"251.71200","20.97614","0.21085"
"251.90400","20.99216","0.21127"
"252.09600","21.00813","0.21130"
"252.28800","21.02415","0.21168"
"252.48000","21.04018","0.21216"
"252.67200","21.05608","0.21230"
"252.86400","21.07222","0.21287"
"253.05600","21.08819","0.21321"
"253.24800","21.10409","0.21366"
"253.44000","21.12024","0.21385"
"253.63200","21.13614","0.21424"
"253.82400","21.15210","0.21432"
"254.01600","21.16818","0.21557"
"254.20800","21.18421","0.21538"
"254.40000","21.20011","0.01435"
"254.59200","21.21620","0.01002"
"254.78400","21.23210","0.00562"
"254.97600","21.24813","0.00000"
"255.16800","21.26421","-0.00097"
"255.36000","21.28011","-0.00110"
"255.55200","21.29614","-0.00086"
"255.74400","21.31222","0.00129"
"255.93600","21.32812","0.00302"
"256.12800","21.34414","0.00139"
"256.32000","21.36023","0.00131"
"256.51200","21.37607","0.00071"
"256.70400","21.39215","0.00221"
"256.89600","21.40818","0.00444"
"257.08800","21.42414","0.00378"
"257.28000","21.44017","0.00095"
"257.47200","21.45619","0.00008"
"257.66400","21.47216","0.00100"
"257.85600","21.48818","0.00251"
"258.04800","21.50414","0.00360"
"258.24000","21.52017","0.00306"
"258.43200","21.53619","0.00120"
"258.62400","21.55215","0.00069"
"258.81600","21.56818","0.00275"
"259.00800","21.58414","0.00277"
"259.20000","21.60016","0.00234"
"259.39200","21.61619","0.00209"
"259.58400","21.63215","0.00073"
"259.77600","21.64812","0.00146"
"259.96800","21.66420","0.00346"
"260.16000","21.68010","0.00309"
"260.35200","21.69619","0.00148"
"260.54400","21.71215","0.00214"
"260.73600","21.72811","0.00175"
"260.92800","21.74420","0.00278"
"261.12000","21.76022","0.00317"
"261.31200","21.77612","0.00165"
"261.50400","21.79221","0.00239"
"261.69600","21.80823","0.00288"
"261.88800","21.82408","0.00331"
"262.08000","21.84022","0.00385"
"262.27200","21.85624","0.00301"
"262.46400","21.87209","0.00242"
"262.65600","21.88817","0.00383"
"262.84800","21.90413","0.00344"
"263.04000","21.92016","0.00369"
"263.23200","21.93618","0.00327"
"263.42400","21.95215","0.00395"
"263.61600","21.96817","0.00443"
"263.80800","21.98419","0.00448"
"264.00000","22.00016","0.00458"
"264.19200","22.01618","0.00375"
"264.38400","22.03221","0.00332"
"264.57600","22.04811","0.00478"
"264.76800","22.06419","0.00534"
"264.96000","22.08015","0.00411"
"265.15200","22.09606","0.00377"
"265.34400","22.11220","0.00451"
"265.53600","22.12817","0.00553"
"265.72800","22.14413","0.00557"
"265.92000","22.16021","0.00501"
"266.11200","22.17612","0.00439"
"266.30400","22.19214","0.00008"
"266.49600","22.20823","0.00089"
"266.68800","22.22413","0.00035"
"266.88000","22.24015","0.00060"
"267.07200","22.25624","0.00007"
"267.26400","22.27214","0.00000"
"267.45600","22.28816","0.00007"
"267.64800","22.30412","0.00005"
"267.84000","22.32009","0.00029"
"268.03200","22.33611","0.00031"
"268.22400","22.35214","0.00030"
"268.41600","22.36816","-0.00046"
"268.60800","22.38413","0.00005"
"268.80000","22.40015","-0.00031"
"268.99200","22.41617","-0.00008"
"269.18400","22.43220","0.00037"
"269.37600","22.44816","0.00014"
"269.56800","22.46418","0.00036"
"269.76000","22.48014","-0.00034"
"269.95200","22.49611","0.00009"
"270.14400","22.51219","-0.00001"
"270.33600","22.52816","-0.00003"
"270.52800","22.54418","0.00029"
"270.72000","22.56015","-0.00006"
"270.91200","22.57611","0.00005"
"271.10400","22.59213","-0.00043"
"271.29600","22.60822","-0.00002"
"271.48800","22.62418","0.00016"
"271.68000","22.64020","-0.00021"
"271.87200","22.65617","0.00057"
"272.06400","22.67213","0.00004"
"272.25600","22.68821","-0.00012"
"272.44800","22.70418","-0.00042"
"272.64000","22.72014","0.00020"
"272.83200","22.73623","0.00022"
"273.02400","22.75213","0.00004"
"273.21600","22.76809","0.00001"
"273.40800","22.78418","-0.00014"
"273.60000","22.80014","-0.00020"
"273.79200","22.81616","0.00041"
"273.98400","22.83219","0.00024"
"274.17600","22.84809","0.00040"
"274.36800","22.86412","-0.00039"
"274.56000","22.88020","0.00006"
"274.75200","22.89616","0.00034"
"274.94400","22.91213","0.00042"
"275.13600","22.92815","0.00005"
"275.32800","22.94411","0.00015"
"275.52000","22.96020","0.00014"
"275.71200","22.97616","0.00020"
"275.90400","22.99212","0.00078"
"276.09600","23.00821","0.00042"
"276.28800","23.02417","0.00002"
"276.48000","23.04014","0.00042"
"276.67200","23.05622","0.00026"
"276.86400","23.07218","0.00012"
"277.05600","23.08815","0.00027"
"277.24800","23.10417","0.00015"
"277.44000","23.12013","0.00043"
"277.63200","23.13616","0.00020"
"277.82400","23.15218","0.00025"
"278.01600","23.16815","-0.00010"
"278.20800","23.18417","0.00045"
"278.40000","23.20019","0.00053"
"278.59200","23.21616","0.00022"
"278.78400","23.23218","0.00034"
"278.97600","23.24821","0.00029"
"279.16800","23.26417","-0.00008"
"279.36000","23.28019","0.00062"
"279.55200","23.29616","0.00033"
"279.74400","23.31218","0.00017"
"279.93600","23.32820","0.00070"
"280.12800","23.34417","-0.00011"
"280.32000","23.36019","0.00023"
"280.51200","23.37609","0.00031"
"280.70400","23.39211","0.00032"
"280.89600","23.40820","0.00056"
"281.08800","23.42416","0.00025"
"281.28000","23.44019","0.00044"
"281.47200","23.45615","0.00068"
"281.66400","23.47211","0.00029"
"281.85600","23.48814","0.00082"
"282.04800","23.50416","0.00030"
"282.24000","23.52012","0.00048"
"282.43200","23.53621","0.00064"
"282.62400","23.55217","0.00060"
"282.81600","23.56814","0.00095"
"283.00800","23.58416","0.00052"
"283.20000","23.60018","0.00043"
"283.39200","23.61615","0.00093"
"283.58400","23.63217","0.00084"
"283.62800","23.63576","0.00065"