File: Force_trajectories/161216/Specimen_RawData_2.csv
End date,"12/16/2016"
Specimen label,"6DG_45"
Maximum Load,"0.00540",N

Time,Extension,Load
(s),(mm),(N)
"0.00000","0.00000","-0.00002"
"0.29400","0.02386","-0.00013"
"0.58800","0.04921","0.00088"
"0.88200","0.07372","0.00089"
"1.17600","0.09823","0.00037"
"1.47000","0.12269","0.00063"
"1.76400","0.14720","0.00072"
"2.05800","0.17166","0.00055"
"2.35200","0.19617","0.00094"
"2.64600","0.22062","0.00029"
"2.94000","0.24520","0.00055"
"3.23400","0.26965","0.00042"
"3.52800","0.29422","0.00026"
"3.82200","0.31868","0.00073"
"4.11600","0.34319","0.00039"
"4.41000","0.36765","0.00050"
"4.70400","0.39216","0.00067"
"4.99800","0.41667","0.00082"
"5.29200","0.44119","0.00048"
"5.58600","0.46570","0.00125"
"5.88000","0.49015","0.00047"
"6.17400","0.51467","0.00068"
"6.46800","0.53912","0.00057"
"6.76200","0.56370","0.00082"
"7.05600","0.58821","0.00054"
"7.35000","0.61260","0.00041"
"7.64400","0.63718","0.00101"
"7.93800","0.66163","0.00063"
"8.23200","0.68620","0.00060"
"8.52600","0.71066","0.00076"
"8.82000","0.73523","0.00084"
"9.11400","0.75969","0.00053"
"9.40800","0.78426","0.00051"
"9.70200","0.80865","0.00035"
"9.99600","0.83323","0.00020"
"10.29000","0.85768","0.00083"
"10.58400","0.88219","0.00069"
"10.87800","0.90671","0.00014"
"11.17200","0.93122","0.00016"
"11.46600","0.95574","0.00064"
"11.76000","0.98013","0.00084"
"12.05400","1.00464","0.00039"
"12.34800","1.02916","0.00044"
"12.64200","1.05373","0.00055"
"12.93600","1.07812","0.00056"
"13.23000","1.10264","0.00050"
"13.52400","1.12715","0.00092"
"13.81800","1.15167","0.00069"
"14.11200","1.17618","0.00093"
"14.40600","1.20069","0.00052"
"14.70000","1.22521","0.00124"
"14.99400","1.24966","0.00035"
"15.28800","1.27417","0.00077"
"15.58200","1.29863","0.00044"
"15.87600","1.32320","0.00082"
"16.17000","1.34766","0.00057"
"16.46400","1.37223","0.00108"
"16.75800","1.39668","0.00082"
"17.05200","1.42120","0.00082"
"17.34600","1.44571","0.00064"
"17.64000","1.47016","0.00113"
"17.93400","1.49468","0.00008"
"18.22800","1.51907","0.00033"
"18.52200","1.54371","0.00089"
"18.81600","1.56810","0.00018"
"19.11000","1.59267","0.00086"
"19.40400","1.61713","0.00079"
"19.69800","1.64170","0.00084"
"19.99200","1.66621","0.00061"
"20.28600","1.69067","0.00090"
"20.58000","1.71518","0.00009"
"20.87400","1.73970","0.00097"
"21.16800","1.76421","0.00042"
"21.46200","1.78872","0.00068"
"21.75600","1.81324","0.00048"
"22.05000","1.83769","0.00104"
"22.34400","1.86220","0.00088"
"22.63800","1.88666","0.00059"
"22.93200","1.91117","0.00082"
"23.22600","1.93569","0.00066"
"23.52000","1.96014","0.00076"
"23.81400","1.98471","0.00135"
"24.10800","2.00917","0.00066"
"24.40200","2.03368","0.00052"
"24.69600","2.05808","0.00083"
"24.99000","2.08271","0.00059"
"25.28400","2.10710","0.00084"
"25.57800","2.13168","0.00119"
"25.87200","2.15613","0.00044"
"26.16600","2.18064","0.00058"
"26.46000","2.20516","0.00050"
"26.75400","2.22967","0.00022"
"27.04800","2.25424","0.00033"
"27.34200","2.27864","0.00078"
"27.63600","2.30315","0.00116"
"27.93000","2.32761","0.00071"
"28.22400","2.35218","0.00118"
"28.51800","2.37669","0.00074"
"28.81200","2.40121","0.00094"
"29.10600","2.42566","0.00082"
"29.40000","2.45017","0.00065"
"29.69400","2.47469","0.00096"
"29.98800","2.49914","0.00070"
"30.28200","2.52372","0.00050"
"30.57600","2.54817","0.00087"
"30.87000","2.57268","0.00041"
"31.16400","2.59708","0.00136"
"31.45800","2.62171","0.00109"
"31.75200","2.64616","0.00095"
"32.04600","2.67074","0.00073"
"32.34000","2.69519","0.00151"
"32.63400","2.71971","0.00086"
"32.92800","2.74416","0.00095"
"33.22200","2.76861","0.00072"
"33.51600","2.79325","0.00033"
"33.81000","2.81764","0.00114"
"34.10400","2.84222","0.00091"
"34.39800","2.86667","0.00042"
"34.69200","2.89124","0.00085"
"34.98600","2.91570","0.00070"
"35.28000","2.94021","0.00106"
"35.57400","2.96466","0.00063"
"35.86800","2.98918","0.00046"
"36.16200","3.01369","0.00066"
"36.45600","3.03815","0.00059"
"36.75000","3.06272","0.00088"
"37.04400","3.08717","0.00057"
"37.33800","3.11169","0.00034"
"37.63200","3.13608","0.00091"
"37.92600","3.16065","0.00065"
"38.22000","3.18511","0.00059"
"38.51400","3.20968","0.00045"
"38.80800","3.23419","0.00099"
"39.10200","3.25871","0.00072"
"39.39600","3.28322","0.00084"
"39.69000","3.30768","0.00091"
"39.98400","3.33225","0.00118"
"40.27800","3.35670","0.00049"
"40.57200","3.38116","0.00099"
"40.86600","3.40561","0.00163"
"41.16000","3.43019","0.00082"
"41.45400","3.45464","0.00081"
"41.74800","3.47921","0.00093"
"42.04200","3.50367","0.00071"
"42.33600","3.52818","0.00075"
"42.63000","3.55269","0.00060"
"42.92400","3.57721","0.00172"
"43.21800","3.60172","0.00128"
"43.51200","3.62618","0.00042"
"43.80600","3.65069","0.00164"
"44.10000","3.67514","0.00151"
"44.39400","3.69972","0.00243"
"44.68800","3.72417","0.00111"
"44.98200","3.74868","0.00075"
"45.27600","3.77314","0.00050"
"45.57000","3.79771","0.00126"
"45.86400","3.82223","0.00097"
"46.15800","3.84668","0.00075"
"46.45200","3.87125","0.00158"
"46.74600","3.89571","0.00037"
"47.04000","3.92022","0.00131"
"47.33400","3.94467","0.00154"
"47.62800","3.96925","0.00130"
"47.92200","3.99370","0.00152"
"48.21600","4.01822","0.00097"
"48.51000","4.04273","0.00107"
"48.80400","4.06712","0.00165"
"49.09800","4.09164","0.00114"
"49.39200","4.11615","0.00136"
"49.68600","4.14066","0.00057"
"49.98000","4.16512","0.00098"
"50.27400","4.18969","0.00105"
"50.56800","4.21409","0.00096"
"50.86200","4.23872","0.00105"
"51.15600","4.26317","0.00096"
"51.45000","4.28775","0.00076"
"51.74400","4.31220","0.00094"
"52.03800","4.33671","0.00152"
"52.33200","4.36117","0.00111"
"52.62600","4.38568","0.00116"
"52.92000","4.41020","0.00095"
"53.21400","4.43459","0.00090"
"53.50800","4.45922","0.00087"
"53.80200","4.48368","0.00084"
"54.09600","4.50825","0.00063"
"54.39000","4.53264","0.00110"
"54.68400","4.55716","0.00098"
"54.97800","4.58167","0.00130"
"55.27200","4.60613","0.00103"
"55.56600","4.63070","0.00082"
"55.86000","4.65515","0.00049"
"56.15400","4.67973","0.00056"
"56.44800","4.70418","0.00053"
"56.74200","4.72869","0.00075"
"57.03600","4.75315","0.00038"
"57.33000","4.77772","0.00099"
"57.62400","4.80218","0.00108"
"57.91800","4.82669","0.00106"
"58.21200","4.85120","0.00086"
"58.50600","4.87572","0.00070"
"58.80000","4.90023","0.00089"
"59.09400","4.92462","0.00127"
"59.38800","4.94920","0.00067"
"59.68200","4.97359","0.00083"
"59.97600","4.99817","0.00101"
"60.27000","5.02262","0.00050"
"60.56400","5.04719","0.00079"
"60.85800","5.07165","0.00083"
"61.15200","5.09616","0.00065"
"61.44600","5.12067","0.00079"
"61.74000","5.14513","0.00053"
"62.03400","5.16970","0.00067"
"62.32800","5.19416","0.00091"
"62.62200","5.21873","0.00084"
"62.91600","5.24318","0.00032"
"63.21000","5.26770","0.00097"
"63.50400","5.29209","0.00019"
"63.79800","5.31672","0.00105"
"64.09200","5.34112","0.00096"
"64.38600","5.36569","0.00065"
"64.68000","5.39021","0.00112"
"64.97400","5.41466","0.00059"
"65.26800","5.43923","0.00088"
"65.56200","5.46369","0.00033"
"65.85600","5.48820","0.00079"
"66.15000","5.51265","0.00090"
"66.44400","5.53717","0.00091"
"66.73800","5.56168","0.00073"
"67.03200","5.58620","0.00071"
"67.32600","5.61071","0.00133"
"67.62000","5.63516","0.00093"
"67.91400","5.65968","0.00077"
"68.20800","5.68413","0.00100"
"68.50200","5.70870","0.00033"
"68.79600","5.73316","0.00125"
"69.09000","5.75773","0.00112"
"69.38400","5.78219","0.00123"
"69.67800","5.80670","0.00109"
"69.97200","5.83115","0.00094"
"70.26600","5.85573","0.00122"
"70.56000","5.88024","0.00116"
"70.85400","5.90469","0.00086"
"71.14800","5.92915","0.00092"
"71.44200","5.95366","0.00090"
"71.73600","5.97818","0.00124"
"72.03000","6.00263","0.00060"
"72.32400","6.02720","0.00103"
"72.61800","6.05160","0.00122"
"72.91200","6.07623","0.00099"
"73.20600","6.10068","0.00130"
"73.50000","6.12520","0.00077"
"73.79400","6.14965","0.00072"
"74.08800","6.17417","0.00105"
"74.38200","6.19862","0.00119"
"74.67600","6.22313","0.00118"
"74.97000","6.24771","0.00092"
"75.26400","6.27216","0.00084"
"75.55800","6.29673","0.00082"
"75.85200","6.32113","0.00084"
"76.14600","6.34570","0.00051"
"76.44000","6.37016","0.00054"
"76.73400","6.39467","0.00095"
"77.02800","6.41912","0.00087"
"77.32200","6.44370","0.00098"
"77.61600","6.46821","0.00105"
"77.91000","6.49266","0.00101"
"78.20400","6.51718","0.00103"
"78.49800","6.54163","0.00131"
"78.79200","6.56615","0.00112"
"79.08600","6.59060","0.00086"
"79.38000","6.61523","0.00085"
"79.67400","6.63969","0.00070"
"79.96800","6.66420","0.00082"
"80.26200","6.68866","0.00094"
"80.55600","6.71323","0.00045"
"80.85000","6.73768","0.00101"
"81.14400","6.76214","0.00144"
"81.43800","6.78671","0.00114"
"81.73200","6.81116","0.00124"
"82.02600","6.83574","0.00083"
"82.32000","6.86013","0.00143"
"82.61400","6.88470","0.00127"
"82.90800","6.90922","0.00124"
"83.20200","6.93373","0.00111"
"83.49600","6.95819","0.00132"
"83.79000","6.98270","0.00139"
"84.08400","7.00721","0.00135"
"84.37800","7.03167","0.00125"
"84.67200","7.05624","0.00172"
"84.96600","7.08064","0.00126"
"85.26000","7.10521","0.00113"
"85.55400","7.12960","0.00138"
"85.84800","7.15418","0.00123"
"86.14200","7.17869","0.00082"
"86.43600","7.20320","0.00173"
"86.73000","7.22766","0.00160"
"87.02400","7.25217","0.00128"
"87.31800","7.27668","0.00173"
"87.61200","7.30120","0.00117"
"87.90600","7.32571","0.00110"
"88.20000","7.35017","0.00174"
"88.49400","7.37474","0.00155"
"88.78800","7.39913","0.00170"
"89.08200","7.42371","0.00186"
"89.37600","7.44816","0.00154"
"89.67000","7.47268","0.00154"
"89.96400","7.49719","0.00191"
"90.25800","7.52170","0.00195"
"90.55200","7.54622","0.00123"
"90.84600","7.57061","0.00172"
"91.14000","7.59518","0.00142"
"91.43400","7.61958","0.00144"
"91.72800","7.64415","0.00186"
"92.02200","7.66867","0.00151"
"92.31600","7.69318","0.00182"
"92.61000","7.71769","0.00146"
"92.90400","7.74221","0.00155"
"93.19800","7.76672","0.00138"
"93.49200","7.79117","0.00141"
"93.78600","7.81569","0.00155"
"94.08000","7.84020","0.00182"
"94.37400","7.86471","0.00147"
"94.66800","7.88917","0.00163"
"94.96200","7.91368","0.00159"
"95.25600","7.93814","0.00165"
"95.55000","7.96271","0.00156"
"95.84400","7.98710","0.00157"
"96.13800","8.01168","0.00171"
"96.43200","8.03619","0.00164"
"96.72600","8.06065","0.00204"
"97.02000","8.08516","0.00157"
"97.31400","8.10967","0.00232"
"97.60800","8.13419","0.00145"
"97.90200","8.15864","0.00187"
"98.19600","8.18321","0.00150"
"98.49000","8.20767","0.00132"
"98.78400","8.23218","0.00193"
"99.07800","8.25669","0.00194"
"99.37200","8.28121","0.00176"
"99.66600","8.30566","0.00188"
"99.96000","8.33012","0.00172"
"100.25400","8.35469","0.00178"
"100.54800","8.37914","0.00224"
"100.84200","8.40378","0.00111"
"101.13600","8.42817","0.00145"
"101.43000","8.45269","0.00235"
"101.72400","8.47714","0.00117"
"102.01800","8.50171","0.00151"
"102.31200","8.52617","0.00172"
"102.60600","8.55068","0.00148"
"102.90000","8.57519","0.00170"
"103.19400","8.59965","0.00199"
"103.48800","8.62422","0.00203"
"103.78200","8.64868","0.00214"
"104.07600","8.67319","0.00169"
"104.37000","8.69758","0.00144"
"104.66400","8.72222","0.00115"
"104.95800","8.74661","0.00166"
"105.25200","8.77118","0.00176"
"105.54600","8.79570","0.00192"
"105.84000","8.82021","0.00207"
"106.13400","8.84473","0.00202"
"106.42800","8.86918","0.00188"
"106.72200","8.89375","0.00161"
"107.01600","8.91821","0.00204"
"107.31000","8.94272","0.00208"
"107.60400","8.96717","0.00197"
"107.89800","8.99169","0.00173"
"108.19200","9.01614","0.00176"
"108.48600","9.04066","0.00177"
"108.78000","9.06511","0.00165"
"109.07400","9.08968","0.00157"
"109.36800","9.11420","0.00175"
"109.66200","9.13859","0.00139"
"109.95600","9.16316","0.00181"
"110.25000","9.18762","0.00183"
"110.54400","9.21219","0.00158"
"110.83800","9.23665","0.00133"
"111.13200","9.26122","0.00182"
"111.42600","9.28567","0.00126"
"111.72000","9.31025","0.00185"
"112.01400","9.33470","0.00181"
"112.30800","9.35921","0.00143"
"112.60200","9.38367","0.00176"
"112.89600","9.40812","0.00240"
"113.19000","9.43270","0.00217"
"113.48400","9.45715","0.00191"
"113.77800","9.48172","0.00227"
"114.07200","9.50618","0.00231"
"114.36600","9.53069","0.00218"
"114.66000","9.55515","0.00190"
"114.95400","9.57966","0.00127"
"115.24800","9.60417","0.00151"
"115.54200","9.62869","0.00143"
"115.83600","9.65320","0.00172"
"116.13000","9.67765","0.00159"
"116.42400","9.70217","0.00207"
"116.71800","9.72668","0.00184"
"117.01200","9.75119","0.00205"
"117.30600","9.77559","0.00182"
"117.60000","9.80022","0.00163"
"117.89400","9.82468","0.00207"
"118.18800","9.84925","0.00185"
"118.48200","9.87370","0.00158"
"118.77600","9.89822","0.00163"
"119.07000","9.92273","0.00169"
"119.36400","9.94718","0.00153"
"119.65800","9.97170","0.00163"
"119.95200","9.99615","0.00159"
"120.24600","10.02072","0.00146"
"120.54000","10.04512","0.00150"
"120.83400","10.06975","0.00142"
"121.12800","10.09421","0.00194"
"121.42200","10.11866","0.00208"
"121.71600","10.14311","0.00164"
"122.01000","10.16763","0.00117"
"122.30400","10.19220","0.00180"
"122.59800","10.21666","0.00167"
"122.89200","10.24117","0.00230"
"123.18600","10.26562","0.00201"
"123.48000","10.29020","0.00197"
"123.77400","10.31471","0.00178"
"124.06800","10.33922","0.00173"
"124.36200","10.36368","0.00180"
"124.65600","10.38819","0.00184"
"124.95000","10.41271","0.00185"
"125.24400","10.43722","0.00194"
"125.53800","10.46173","0.00157"
"125.83200","10.48613","0.00151"
"126.12600","10.51070","0.00174"
"126.42000","10.53522","0.00159"
"126.71400","10.55973","0.00170"
"127.00800","10.58412","0.00149"
"127.30200","10.60870","0.00170"
"127.59600","10.63315","0.00167"
"127.89000","10.65766","0.00179"
"128.18400","10.68224","0.00152"
"128.47800","10.70669","0.00179"
"128.77200","10.73127","0.00167"
"129.06600","10.75566","0.00158"
"129.36000","10.78023","0.00147"
"129.65400","10.80463","0.00151"
"129.94800","10.82920","0.00145"
"130.24200","10.85365","0.00175"
"130.53600","10.87823","0.00207"
"130.83000","10.90268","0.00171"
"131.12400","10.92726","0.00175"
"131.41800","10.95171","0.00223"
"131.71200","10.97616","0.00218"
"132.00600","11.00068","0.00210"
"132.30000","11.02513","0.00226"
"132.59400","11.04964","0.00141"
"132.88800","11.07410","0.00254"
"133.18200","11.09867","0.00186"
"133.47600","11.12313","0.00186"
"133.77000","11.14770","0.00219"
"134.06400","11.17215","0.00200"
"134.35800","11.19667","0.00196"
"134.65200","11.22118","0.00188"
"134.94600","11.24563","0.00198"
"135.24000","11.27021","0.00227"
"135.53400","11.29466","0.00216"
"135.82800","11.31923","0.00234"
"136.12200","11.34363","0.00247"
"136.41600","11.36820","0.00203"
"136.71000","11.39272","0.00249"
"137.00400","11.41723","0.00235"
"137.29800","11.44168","0.00262"
"137.59200","11.46620","0.00230"
"137.88600","11.49071","0.00209"
"138.18000","11.51517","0.00210"
"138.47400","11.53968","0.00213"
"138.76800","11.56413","0.00214"
"139.06200","11.58871","0.00164"
"139.35600","11.61310","0.00225"
"139.65000","11.63773","0.00226"
"139.94400","11.66213","0.00206"
"140.23800","11.68670","0.00272"
"140.53200","11.71116","0.00236"
"140.82600","11.73567","0.00224"
"141.12000","11.76018","0.00237"
"141.41400","11.78464","0.00231"
"141.70800","11.80921","0.00245"
"142.00200","11.83366","0.00204"
"142.29600","11.85824","0.00206"
"142.59000","11.88269","0.00284"
"142.88400","11.90721","0.00234"
"143.17800","11.93166","0.00237"
"143.47200","11.95617","0.00285"
"143.76600","11.98069","0.00236"
"144.06000","12.00514","0.00268"
"144.35400","12.02971","0.00213"
"144.64800","12.05417","0.00206"
"144.94200","12.07868","0.00252"
"145.23600","12.10314","0.00221"
"145.53000","12.12771","0.00297"
"145.82400","12.15210","0.00287"
"146.11800","12.17668","0.00255"
"146.41200","12.20113","0.00237"
"146.70600","12.22570","0.00234"
"147.00000","12.25016","0.00242"
"147.29400","12.27467","0.00256"
"147.58800","12.29919","0.00275"
"147.88200","12.32364","0.00244"
"148.17600","12.34821","0.00283"
"148.47000","12.37267","0.00279"
"148.76400","12.39718","0.00223"
"149.05800","12.42163","0.00247"
"149.35200","12.44621","0.00242"
"149.64600","12.47066","0.00197"
"149.94000","12.49518","0.00268"
"150.23400","12.51969","0.00273"
"150.52800","12.54420","0.00222"
"150.82200","12.56872","0.00251"
"151.11600","12.59317","0.00303"
"151.41000","12.61768","0.00300"
"151.70400","12.64214","0.00243"
"151.99800","12.66671","0.00282"
"152.29200","12.69116","0.00271"
"152.58600","12.71568","0.00271"
"152.88000","12.74019","0.00291"
"153.17400","12.76471","0.00255"
"153.46800","12.78922","0.00279"
"153.76200","12.81367","0.00216"
"154.05600","12.83825","0.00300"
"154.35000","12.86264","0.00264"
"154.64400","12.88722","0.00301"
"154.93800","12.91161","0.00278"
"155.23200","12.93624","0.00242"
"155.52600","12.96064","0.00334"
"155.82000","12.98521","0.00278"
"156.11400","13.00966","0.00323"
"156.40800","13.03424","0.00277"
"156.70200","13.05869","0.00288"
"156.99600","13.08321","0.00290"
"157.29000","13.10772","0.00299"
"157.58400","13.13211","0.00297"
"157.87800","13.15669","0.00326"
"158.17200","13.18108","0.00298"
"158.46600","13.20571","0.00307"
"158.76000","13.23017","0.00317"
"159.05400","13.25468","0.00344"
"159.34800","13.27920","0.00336"
"159.64200","13.30371","0.00341"
"159.93600","13.32822","0.00258"
"160.23000","13.35268","0.00305"
"160.52400","13.37719","0.00325"
"160.81800","13.40164","0.00277"
"161.11200","13.42616","0.00333"
"161.40600","13.45067","0.00305"
"161.70000","13.47525","0.00349"
"161.99400","13.49970","0.00337"
"162.28800","13.52421","0.00292"
"162.58200","13.54867","0.00332"
"162.87600","13.57318","0.00294"
"163.17000","13.59770","0.00330"
"163.46400","13.62215","0.00333"
"163.75800","13.64666","0.00350"
"164.05200","13.67112","0.00301"
"164.34600","13.69569","0.00306"
"164.64000","13.72014","0.00297"
"164.93400","13.74472","0.00333"
"165.22800","13.76917","0.00338"
"165.52200","13.79368","0.00227"
"165.81600","13.81814","0.00270"
"166.11000","13.84271","0.00297"
"166.40400","13.86723","0.00274"
"166.69800","13.89168","0.00298"
"166.99200","13.91619","0.00279"
"167.28600","13.94071","0.00276"
"167.58000","13.96522","0.00344"
"167.87400","13.98967","0.00289"
"168.16800","14.01419","0.00300"
"168.46200","14.03864","0.00316"
"168.75600","14.06316","0.00271"
"169.05000","14.08767","0.00289"
"169.34400","14.11218","0.00332"
"169.63800","14.13670","0.00390"
"169.93200","14.16121","0.00314"
"170.22600","14.18572","0.00366"
"170.52000","14.21012","0.00348"
"170.81400","14.23469","0.00316"
"171.10800","14.25915","0.00332"
"171.40200","14.28372","0.00329"
"171.69600","14.30817","0.00294"
"171.99000","14.33275","0.00345"
"172.28400","14.35720","0.00318"
"172.57800","14.38171","0.00369"
"172.87200","14.40623","0.00344"
"173.16600","14.43062","0.00318"
"173.46000","14.45520","0.00329"
"173.75400","14.47965","0.00337"
"174.04800","14.50422","0.00337"
"174.34200","14.52862","0.00335"
"174.63600","14.55319","0.00401"
"174.93000","14.57770","0.00336"
"175.22400","14.60222","0.00387"
"175.51800","14.62667","0.00386"
"175.81200","14.65119","0.00338"
"176.10600","14.67570","0.00387"
"176.40000","14.70015","0.00396"
"176.69400","14.72467","0.00404"
"176.98800","14.74918","0.00343"
"177.28200","14.77370","0.00381"
"177.57600","14.79815","0.00336"
"177.87000","14.82266","0.00347"
"178.16400","14.84718","0.00340"
"178.45800","14.87169","0.00380"
"178.75200","14.89620","0.00337"
"179.04600","14.92066","0.00315"
"179.34000","14.94523","0.00392"
"179.63400","14.96969","0.00403"
"179.92800","14.99420","0.00357"
"180.22200","15.01865","0.00328"
"180.51600","15.04323","0.00385"
"180.81000","15.06762","0.00330"
"181.10400","15.09219","0.00338"
"181.39800","15.11665","0.00425"
"181.69200","15.14116","0.00441"
"181.98600","15.16568","0.00426"
"182.28000","15.19019","0.00443"
"182.57400","15.21470","0.00406"
"182.86800","15.23916","0.00357"
"183.16200","15.26361","0.00347"
"183.45600","15.28813","0.00408"
"183.75000","15.31270","0.00378"
"184.04400","15.33715","0.00425"
"184.33800","15.36172","0.00401"
"184.63200","15.38618","0.00387"
"184.92600","15.41069","0.00420"
"185.22000","15.43521","0.00434"
"185.51400","15.45966","0.00425"
"185.80800","15.48423","0.00419"
"186.10200","15.50863","0.00411"
"186.39600","15.53314","0.00440"
"186.69000","15.55766","0.00408"
"186.98400","15.58223","0.00391"
"187.27800","15.60668","0.00308"
"187.57200","15.63120","0.00382"
"187.86600","15.65565","0.00210"
"188.16000","15.68016","0.00317"
"188.45400","15.70468","0.00221"
"188.74800","15.72913","0.00289"
"189.04200","15.75371","0.00247"
"189.33600","15.77816","0.00303"
"189.63000","15.80273","0.00250"
"189.92400","15.82719","0.00316"
"190.21800","15.85170","0.00262"
"190.51200","15.87615","0.00324"
"190.80600","15.90067","0.00236"
"191.10000","15.92518","0.00317"
"191.39400","15.94969","0.00231"
"191.68800","15.97421","0.00315"
"191.98200","15.99872","0.00293"
"192.27600","16.02318","0.00267"
"192.57000","16.04763","0.00328"
"192.86400","16.07220","0.00305"
"193.15800","16.09672","0.00259"
"193.45200","16.12117","0.00268"
"193.74600","16.14562","0.00262"
"194.04000","16.17014","0.00304"
"194.33400","16.19465","0.00270"
"194.62800","16.21917","0.00290"
"194.92200","16.24368","0.00279"
"195.21600","16.26819","0.00293"
"195.51000","16.29271","0.00289"
"195.80400","16.31716","0.00306"
"196.09800","16.34173","0.00302"
"196.39200","16.36619","0.00272"
"196.68600","16.39070","0.00289"
"196.98000","16.41516","0.00291"
"197.27400","16.43973","0.00307"
"197.56800","16.46418","0.00255"
"197.86200","16.48864","0.00296"
"198.15600","16.51321","0.00290"
"198.45000","16.53766","0.00274"
"198.74400","16.56218","0.00324"
"199.03800","16.58663","0.00267"
"199.33200","16.61115","0.00265"
"199.62600","16.63560","0.00266"
"199.92000","16.66017","0.00334"
"200.21400","16.68463","0.00286"
"200.50800","16.70920","0.00330"
"200.80200","16.73372","0.00332"
"201.09600","16.75817","0.00346"
"201.39000","16.78274","0.00280"
"201.68400","16.80720","0.00350"
"201.97800","16.83171","0.00312"
"202.27200","16.85610","0.00323"
"202.56600","16.88068","0.00318"
"202.86000","16.90525","0.00320"
"203.15400","16.92970","0.00355"
"203.44800","16.95416","0.00301"
"203.74200","16.97867","0.00326"
"204.03600","17.00319","0.00359"
"204.33000","17.02764","0.00344"
"204.62400","17.05221","0.00347"
"204.91800","17.07667","0.00360"
"205.21200","17.10118","0.00343"
"205.50600","17.12564","0.00395"
"205.80000","17.15027","0.00345"
"206.09400","17.17466","0.00381"
"206.38800","17.19924","0.00342"
"206.68200","17.22363","0.00387"
"206.97600","17.24820","0.00370"
"207.27000","17.27266","0.00358"
"207.56400","17.29717","0.00416"
"207.85800","17.32169","0.00351"
"208.15200","17.34614","0.00337"
"208.44600","17.37071","0.00381"
"208.74000","17.39517","0.00388"
"209.03400","17.41974","0.00406"
"209.32800","17.44419","0.00406"
"209.62200","17.46871","0.00390"
"209.91600","17.49316","0.00391"
"210.21000","17.51768","0.00385"
"210.50400","17.54219","0.00351"
"210.79800","17.56664","0.00387"
"211.09200","17.59122","0.00376"
"211.38600","17.61567","0.00400"
"211.68000","17.64018","0.00414"
"211.97400","17.66458","0.00348"
"212.26800","17.68921","0.00365"
"212.56200","17.71367","0.00348"
"212.85600","17.73824","0.00364"
"213.15000","17.76269","0.00400"
"213.44400","17.78721","0.00397"
"213.73800","17.81166","0.00390"
"214.03200","17.83617","0.00398"
"214.32600","17.86075","0.00328"
"214.62000","17.88514","0.00377"
"214.91400","17.90972","0.00342"
"215.20800","17.93411","0.00350"
"215.50200","17.95874","0.00319"
"215.79600","17.98320","0.00365"
"216.09000","18.00771","0.00356"
"216.38400","18.03217","0.00314"
"216.67800","18.05668","0.00324"
"216.97200","18.08113","0.00358"
"217.26600","18.10565","0.00325"
"217.56000","18.13022","0.00303"
"217.85400","18.15467","0.00288"
"218.14800","18.17919","0.00303"
"218.44200","18.20358","0.00304"
"218.73600","18.22821","0.00324"
"219.03000","18.25267","0.00311"
"219.32400","18.27712","0.00302"
"219.61800","18.30164","0.00337"
"219.91200","18.32621","0.00334"
"220.20600","18.35072","0.00321"
"220.50000","18.37518","0.00333"
"220.79400","18.39969","0.00335"
"221.08800","18.42420","0.00372"
"221.38200","18.44872","0.00335"
"221.67600","18.47311","0.00321"
"221.97000","18.49775","0.00341"
"222.26400","18.52220","0.00319"
"222.55800","18.54665","0.00343"
"222.85200","18.57117","0.00367"
"223.14600","18.59574","0.00357"
"223.44000","18.62020","0.00372"
"223.73400","18.64465","0.00379"
"224.02800","18.66922","0.00387"
"224.32200","18.69368","0.00344"
"224.61600","18.71819","0.00393"
"224.91000","18.74258","0.00400"
"225.20400","18.76722","0.00408"
"225.49800","18.79167","0.00365"
"225.79200","18.81624","0.00374"
"226.08600","18.84070","0.00371"
"226.38000","18.86521","0.00442"
"226.67400","18.88972","0.00449"
"226.96800","18.91412","0.00423"
"227.26200","18.93869","0.00403"
"227.55600","18.96315","0.00393"
"227.85000","18.98766","0.00407"
"228.14400","19.01217","0.00457"
"228.43800","19.03669","0.00430"
"228.73200","19.06114","0.00422"
"229.02600","19.08566","0.00433"
"229.32000","19.11017","0.00436"
"229.61400","19.13462","0.00429"
"229.90800","19.15914","0.00421"
"230.20200","19.18359","0.00437"
"230.49600","19.20816","0.00431"
"230.79000","19.23262","0.00442"
"231.08400","19.25719","0.00365"
"231.37800","19.28165","0.00381"
"231.67200","19.30622","0.00319"
"231.96600","19.33067","0.00307"
"232.26000","19.35519","0.00345"
"232.55400","19.37970","0.00305"
"232.84800","19.40421","0.00335"
"233.14200","19.42873","0.00321"
"233.43600","19.45312","0.00346"
"233.73000","19.47770","0.00307"
"234.02400","19.50215","0.00364"
"234.31800","19.52666","0.00361"
"234.61200","19.55112","0.00322"
"234.90600","19.57575","0.00309"
"235.20000","19.60015","0.00336"
"235.49400","19.62466","0.00295"
"235.78800","19.64917","0.00281"
"236.08200","19.67369","0.00290"
"236.37600","19.69820","0.00297"
"236.67000","19.72265","0.00329"
"236.96400","19.74717","0.00341"
"237.25800","19.77162","0.00343"
"237.55200","19.79619","0.00349"
"237.84600","19.82065","0.00307"
"238.14000","19.84516","0.00322"
"238.43400","19.86968","0.00309"
"238.72800","19.89419","0.00373"
"239.02200","19.91870","0.00346"
"239.31600","19.94316","0.00316"
"239.61000","19.96773","0.00326"
"239.90400","19.99213","0.00332"
"240.19800","20.01670","0.00346"
"240.49200","20.04109","0.00385"
"240.78600","20.06573","0.00397"
"241.08000","20.09012","0.00378"
"241.37400","20.11469","0.00364"
"241.66800","20.13915","0.00356"
"241.96200","20.16366","0.00307"
"242.25600","20.18818","0.00350"
"242.55000","20.21263","0.00384"
"242.84400","20.23720","0.00360"
"243.13800","20.26166","0.00349"
"243.43200","20.28617","0.00376"
"243.72600","20.31068","0.00387"
"244.02000","20.33520","0.00459"
"244.31400","20.35971","0.00386"
"244.60800","20.38423","0.00357"
"244.90200","20.40862","0.00423"
"245.19600","20.43319","0.00411"
"245.49000","20.45771","0.00348"
"245.78400","20.48222","0.00419"
"246.07800","20.50673","0.00404"
"246.37200","20.53113","0.00451"
"246.66600","20.55564","0.00426"
"246.96000","20.58015","0.00419"
"247.25400","20.60467","0.00442"
"247.54800","20.62918","0.00441"
"247.84200","20.65370","0.00455"
"248.13600","20.67821","0.00437"
"248.43000","20.70260","0.00429"
"248.72400","20.72718","0.00399"
"249.01800","20.75163","0.00451"
"249.31200","20.77621","0.00438"
"249.60600","20.80066","0.00437"
"249.90000","20.82517","0.00491"
"250.19400","20.84963","0.00456"
"250.48800","20.87420","0.00515"
"250.78200","20.89871","0.00486"
"251.07600","20.92329","0.00436"
"251.37000","20.94768","0.00469"
"251.66400","20.97219","0.00507"
"251.95800","20.99665","0.00451"
"252.25200","21.02116","0.00458"
"252.54600","21.04568","0.00518"
"252.84000","21.07013","0.00480"
"253.13400","21.09464","0.00355"
"253.42800","21.11910","0.00317"
"253.72200","21.14367","0.00221"
"254.01600","21.16818","0.00287"
"254.31000","21.19270","0.00240"
"254.60400","21.21715","0.00375"
"254.89800","21.24161","0.00234"
"255.19200","21.26618","0.00249"
"255.48600","21.29063","0.00234"
"255.78000","21.31515","0.00305"
"256.07400","21.33960","0.00216"
"256.36800","21.36423","0.00216"
"256.66200","21.38869","0.00248"
"256.95600","21.41320","0.00238"
"257.25000","21.43766","0.00222"
"257.54400","21.46217","0.00273"
"257.83800","21.48668","0.00324"
"258.13200","21.51120","0.00216"
"258.42600","21.53571","0.00285"
"258.72000","21.56017","0.00258"
"259.01400","21.58474","0.00279"
"259.30800","21.60913","0.00204"
"259.60200","21.63371","0.00315"
"259.89600","21.65810","0.00253"
"260.19000","21.68273","0.00288"
"260.48400","21.70713","0.00234"
"260.77800","21.73170","0.00262"
"261.07200","21.75621","0.00272"
"261.36600","21.78067","0.00246"
"261.66000","21.80524","0.00229"
"261.95400","21.82970","0.00223"
"262.24800","21.85421","0.00235"
"262.54200","21.87867","0.00234"
"262.83600","21.90318","0.00300"
"263.13000","21.92763","0.00289"
"263.42400","21.95215","0.00264"
"263.71800","21.97666","0.00311"
"264.01200","22.00117","0.00279"
"264.30600","22.02569","0.00331"
"264.60000","22.05014","0.00315"
"264.89400","22.07471","0.00304"
"265.18800","22.09917","0.00259"
"265.48200","22.12368","0.00294"
"265.77600","22.14808","0.00320"
"266.07000","22.17271","0.00318"
"266.36400","22.19710","0.00292"
"266.65800","22.22174","0.00307"
"266.95200","22.24619","0.00266"
"267.24600","22.27071","0.00249"
"267.54000","22.29516","0.00284"
"267.83400","22.31961","0.00314"
"268.12800","22.34419","0.00340"
"268.42200","22.36864","0.00306"
"268.71600","22.39321","0.00360"
"269.01000","22.41767","0.00284"
"269.30400","22.44224","0.00347"
"269.59800","22.46670","0.00330"
"269.89200","22.49121","0.00311"
"270.18600","22.51566","0.00308"
"270.48000","22.54018","0.00314"
"270.77400","22.56469","0.00324"
"271.06800","22.58920","0.00311"
"271.36200","22.61372","0.00312"
"271.65600","22.63817","0.00303"
"271.95000","22.66268","0.00312"
"272.24400","22.68714","0.00343"
"272.53800","22.71171","0.00387"
"272.83200","22.73617","0.00342"
"273.12600","22.76068","0.00313"
"273.42000","22.78519","0.00234"
"273.71400","22.80971","0.00256"
"274.00800","22.83422","0.00274"
"274.30200","22.85868","0.00262"
"274.59600","22.88319","0.00292"
"274.89000","22.90764","0.00252"
"275.18400","22.93222","0.00278"
"275.47800","22.95661","0.00314"
"275.77200","22.98118","0.00242"
"276.06600","23.00570","0.00337"
"276.36000","23.03015","0.00299"
"276.65400","23.05466","0.00240"
"276.94800","23.07918","0.00296"
"277.24200","23.10369","0.00327"
"277.53600","23.12815","0.00346"
"277.83000","23.15272","0.00322"
"278.12400","23.17723","0.00344"
"278.41800","23.20163","0.00390"
"278.71200","23.22608","0.00347"
"279.00600","23.25071","0.00324"
"279.30000","23.27517","0.00410"
"279.59400","23.29968","0.00366"
"279.88800","23.32420","0.00378"
"280.18200","23.34871","0.00416"
"280.47600","23.37322","0.00363"
"280.77000","23.39768","0.00366"
"281.06400","23.42219","0.00396"
"281.35800","23.44670","0.00384"
"281.65200","23.47122","0.00333"
"281.94600","23.49567","0.00331"
"282.24000","23.52024","0.00425"
"282.53400","23.54464","0.00358"
"282.82800","23.56915","0.00421"
"283.12200","23.59367","0.00417"
"283.41600","23.61818","0.00452"
"283.71000","23.64269","0.00409"
"284.00400","23.66715","0.00436"
"284.29800","23.69166","0.00409"
"284.59200","23.71618","0.00438"
"284.88600","23.74069","0.00381"
"285.18000","23.76508","0.00426"
"285.47400","23.78972","0.00389"
"285.76800","23.81417","0.00415"
"286.06200","23.83868","0.00433"
"286.35600","23.86320","0.00347"
"286.65000","23.88771","0.00315"
"286.94400","23.91216","0.00345"
"287.23800","23.93668","0.00344"
"287.53200","23.96119","0.00340"
"287.82600","23.98565","0.00359"
"288.12000","24.01016","0.00396"
"288.41400","24.03461","0.00366"
"288.70800","24.05919","0.00361"
"289.00200","24.08364","0.00327"
"289.29600","24.10816","0.00354"
"289.59000","24.13267","0.00375"
"289.88400","24.15713","0.00360"
"290.17800","24.18164","0.00375"
"290.47200","24.20615","0.00382"
"290.76600","24.23067","0.00364"
"291.06000","24.25512","0.00398"
"291.35400","24.27969","0.00318"
"291.64800","24.30409","0.00399"
"291.94200","24.32872","0.00381"
"292.23600","24.35317","0.00359"
"292.53000","24.37775","0.00437"
"292.82400","24.40220","0.00424"
"293.11800","24.42671","0.00370"
"293.41200","24.45123","0.00373"
"293.70600","24.47562","0.00368"
"294.00000","24.50019","0.00349"
"294.29400","24.52465","0.00386"
"294.58800","24.54922","0.00359"
"294.88200","24.57362","0.00415"
"295.17600","24.59819","0.00163"
"295.47000","24.62271","0.00174"
"295.76400","24.64722","0.00138"
"296.05800","24.67167","0.00029"
"296.35200","24.69619","0.00012"
"296.64600","24.72070","0.00069"
"296.94000","24.74516","0.00199"
"297.23400","24.76973","0.00036"
"297.52800","24.79418","0.00098"
"297.82200","24.81870","0.00104"
"298.11600","24.84315","0.00192"
"298.41000","24.86772","0.00079"
"298.70400","24.89218","0.00076"
"298.99800","24.91669","0.00116"
"299.29200","24.94120","0.00118"
"299.58600","24.96566","0.00067"
"299.88000","24.99023","0.00068"
"300.17400","25.01463","0.00097"
"300.46800","25.03920","0.00088"
"300.76200","25.06359","0.00082"
"301.05600","25.08817","0.00094"
"301.35000","25.11262","0.00083"
"301.64400","25.13720","0.00182"
"301.93800","25.16165","0.00140"
"302.23200","25.18616","0.00090"
"302.52600","25.21068","0.00078"
"302.82000","25.23519","0.00151"
"303.11400","25.25970","0.00142"
"303.40800","25.28416","0.00083"
"303.70200","25.30867","0.00183"
"303.99600","25.33313","0.00132"
"304.29000","25.35770","0.00102"
"304.58400","25.38215","0.00064"
"304.87800","25.40672","0.00100"
"305.17200","25.43124","0.00137"
"305.46600","25.45569","0.00148"
"305.76000","25.48021","0.00126"
"306.05400","25.50466","0.00112"
"306.34800","25.52924","0.00131"
"306.64200","25.55363","0.00178"
"306.93600","25.57820","0.00104"
"307.23000","25.60272","0.00168"
"307.52400","25.62723","0.00189"
"307.81800","25.65162","0.00159"
"308.11200","25.67620","0.00132"
"308.40600","25.70071","0.00130"
"308.70000","25.72510","0.00188"
"308.99400","25.74968","0.00186"
"309.28800","25.77419","0.00137"
"309.58200","25.79871","0.00150"
"309.87600","25.82316","0.00179"
"310.17000","25.84773","0.00170"
"310.46400","25.87213","0.00100"
"310.75800","25.89670","0.00112"
"311.05200","25.92115","0.00134"
"311.34600","25.94573","0.00148"
"311.64000","25.97018","0.00138"
"311.93400","25.99469","0.00175"
"312.22800","26.01915","0.00157"
"312.52200","26.04366","0.00143"
"312.81600","26.06817","0.00135"
"313.11000","26.09263","0.00125"
"313.40400","26.11721","0.00149"
"313.69800","26.14160","0.00145"
"313.99200","26.16617","0.00144"
"314.28600","26.19069","0.00116"
"314.58000","26.21520","0.00162"
"314.87400","26.23965","0.00162"
"315.16800","26.26417","0.00193"
"315.46200","26.28868","0.00099"
"315.75600","26.31313","0.00188"
"316.05000","26.33771","0.00130"
"316.34400","26.36216","0.00179"
"316.63800","26.38668","0.00171"
"316.93200","26.41113","0.00147"
"317.22600","26.43570","0.00185"
"317.52000","26.46016","0.00157"
"317.81400","26.48473","0.00158"
"318.10800","26.50918","0.00134"
"318.40200","26.53370","0.00142"
"318.69600","26.55821","0.00157"
"318.99000","26.58267","0.00171"
"319.28400","26.60718","0.00152"
"319.57800","26.63163","0.00189"
"319.87200","26.65621","0.00103"
"320.16600","26.68060","0.00184"
"320.46000","26.70523","0.00112"
"320.75400","26.72963","0.00139"
"321.04800","26.75420","0.00128"
"321.34200","26.77866","0.00124"
"321.63600","26.80317","0.00154"
"321.93000","26.82768","0.00177"
"322.22400","26.85220","0.00184"
"322.51800","26.87671","0.00175"
"322.81200","26.90116","0.00160"
"323.10600","26.92574","0.00161"
"323.40000","26.95013","0.00140"
"323.69400","26.97464","0.00173"
"323.98800","26.99916","0.00180"
"324.28200","27.02367","0.00172"
"324.57600","27.04819","0.00160"
"324.87000","27.07264","0.00150"
"325.16400","27.09721","0.00151"
"325.45800","27.12161","0.00129"
"325.75200","27.14618","0.00154"
"326.04600","27.17064","0.00182"
"326.34000","27.19521","0.00196"
"326.63400","27.21960","0.00176"
"326.92800","27.24418","0.00193"
"327.22200","27.26869","0.00143"
"327.51600","27.29314","0.00202"
"327.81000","27.31766","0.00206"
"328.10400","27.34217","0.00200"
"328.39800","27.36669","0.00189"
"328.69200","27.39114","0.00146"
"328.98600","27.41571","0.00144"
"329.28000","27.44017","0.00122"
"329.57400","27.46468","0.00174"
"329.86800","27.48914","0.00167"
"330.16200","27.51371","0.00180"
"330.45600","27.53822","0.00178"
"330.75000","27.56268","0.00152"
"331.04400","27.58719","0.00122"
"331.33800","27.61170","0.00160"
"331.63200","27.63622","0.00215"
"331.92600","27.66067","0.00160"
"332.22000","27.68513","0.00174"
"332.51400","27.70964","0.00157"
"332.80800","27.73421","0.00183"
"333.10200","27.75867","0.00130"
"333.39600","27.78324","0.00177"
"333.69000","27.80769","0.00231"
"333.98400","27.83221","0.00175"
"334.27800","27.85672","0.00169"
"334.57200","27.88117","0.00157"
"334.86600","27.90569","0.00184"
"335.16000","27.93014","0.00176"
"335.45400","27.95472","0.00164"
"335.74800","27.97911","0.00181"
"336.04200","28.00368","0.00196"
"336.33600","28.02814","0.00198"
"336.63000","28.05265","0.00210"
"336.92400","28.07710","0.00197"
"337.21800","28.10168","0.00194"
"337.51200","28.12619","0.00185"
"337.80600","28.15065","0.00211"
"338.10000","28.17516","0.00222"
"338.39400","28.19961","0.00205"
"338.68800","28.22419","0.00210"
"338.98200","28.24864","0.00245"
"339.27600","28.27316","0.00171"
"339.57000","28.29761","0.00197"
"339.86400","28.32218","0.00179"
"340.15800","28.34669","0.00202"
"340.45200","28.37121","0.00212"
"340.74600","28.39573","0.00177"
"341.04000","28.42018","0.00188"
"341.33400","28.44469","0.00144"
"341.62800","28.46921","0.00227"
"341.92200","28.49372","0.00200"
"342.21600","28.51811","0.00185"
"342.51000","28.54269","0.00201"
"342.80400","28.56714","0.00199"
"343.09800","28.59171","0.00187"
"343.39200","28.61617","0.00151"
"343.68600","28.64068","0.00195"
"343.98000","28.66520","0.00202"
"344.27400","28.68965","0.00208"
"344.56800","28.71422","0.00178"
"344.86200","28.73862","0.00232"
"345.15600","28.76319","0.00217"
"345.45000","28.78765","0.00186"
"345.74400","28.81222","0.00187"
"346.03800","28.83667","0.00199"
"346.33200","28.86119","0.00229"
"346.62600","28.88570","0.00258"
"346.92000","28.91021","0.00227"
"347.21400","28.93473","0.00242"
"347.50800","28.95918","0.00238"
"347.80200","28.98369","0.00250"
"348.09600","29.00815","0.00214"
"348.39000","29.03272","0.00211"
"348.68400","29.05717","0.00245"
"348.97800","29.08175","0.00242"
"349.27200","29.10614","0.00213"
"349.56600","29.13066","0.00222"
"349.86000","29.15517","0.00271"
"350.15400","29.17969","0.00212"
"350.44800","29.20420","0.00225"
"350.74200","29.22865","0.00237"
"351.03600","29.25317","0.00231"
"351.33000","29.27756","0.00192"
"351.62400","29.30219","0.00234"
"351.91800","29.32659","0.00187"
"352.21200","29.35116","0.00235"
"352.50600","29.37567","0.00189"
"352.80000","29.40025","0.00251"
"353.09400","29.42470","0.00213"
"353.38800","29.44922","0.00174"
"353.68200","29.47379","0.00188"
"353.97600","29.49818","0.00239"
"354.27000","29.52270","0.00233"
"354.56400","29.54715","0.00239"
"354.85800","29.57173","0.00179"
"355.15200","29.59612","0.00184"
"355.44600","29.62069","0.00206"
"355.74000","29.64515","0.00183"
"356.03400","29.66972","0.00203"
"356.32800","29.69423","0.00259"
"356.62200","29.71869","0.00212"
"356.91600","29.74320","0.00291"
"357.21000","29.76765","0.00195"
"357.50400","29.79217","0.00229"
"357.79800","29.81662","0.00223"
"358.09200","29.84120","0.00210"
"358.38600","29.86565","0.00225"
"358.68000","29.89022","0.00207"
"358.97400","29.91468","0.00194"
"359.26800","29.93925","0.00233"
"359.56200","29.96370","0.00152"
"359.85600","29.98816","0.00173"
"360.15000","30.01273","0.00216"
"360.44400","30.03713","0.00235"
"360.73800","30.06170","0.00233"
"361.03200","30.08615","0.00231"
"361.32600","30.11067","0.00195"
"361.62000","30.13506","0.00221"
"361.91400","30.15969","0.00278"
"362.20800","30.18409","0.00233"
"362.50200","30.20866","0.00228"
"362.79600","30.23318","0.00215"
"363.09000","30.25763","0.00239"
"363.38400","30.28221","0.00235"
"363.67800","30.30666","0.00233"
"363.97200","30.33117","0.00202"
"364.26600","30.35563","0.00242"
"364.56000","30.38026","0.00237"
"364.85400","30.40465","0.00231"
"365.14800","30.42923","0.00250"
"365.44200","30.45374","0.00268"
"365.73600","30.47819","0.00267"
"366.03000","30.50265","0.00282"
"366.32400","30.52716","0.00258"
"366.61800","30.55173","0.00330"
"366.91200","30.57613","0.00255"
"367.20600","30.60070","0.00299"
"367.50000","30.62515","0.00261"
"367.79400","30.64973","0.00271"
"368.08800","30.67418","0.00271"
"368.38200","30.69870","0.00290"
"368.67600","30.72321","0.00205"
"368.97000","30.74767","0.00270"
"369.26400","30.77218","0.00254"
"369.55800","30.79663","0.00242"
"369.85200","30.82121","0.00243"
"370.14600","30.84566","0.00261"
"370.44000","30.87017","0.00248"
"370.73400","30.89469","0.00333"
"371.02800","30.91920","0.00295"
"371.32200","30.94366","0.00263"
"371.61600","30.96817","0.00267"
"371.91000","30.99268","0.00251"
"372.20400","31.01719","0.00242"
"372.49800","31.04165","0.00215"
"372.79200","31.06610","0.00250"
"373.08600","31.09068","0.00232"
"373.38000","31.11513","0.00207"
"373.67400","31.13970","0.00240"
"373.96800","31.16416","0.00214"
"374.26200","31.18867","0.00208"
"374.55600","31.21313","0.00214"
"374.85000","31.23764","0.00215"
"375.14400","31.26221","0.00210"
"375.43800","31.28666","0.00240"
"375.73200","31.31118","0.00235"
"376.02600","31.33563","0.00249"
"376.32000","31.36021","0.00239"
"376.61400","31.38466","0.00224"
"376.90800","31.40923","0.00261"
"377.20200","31.43369","0.00228"
"377.49600","31.45820","0.00216"
"377.79000","31.48266","0.00241"
"378.08400","31.50723","0.00215"
"378.37800","31.53168","0.00198"
"378.67200","31.55620","0.00209"
"378.96600","31.58077","0.00212"
"379.26000","31.60517","0.00240"
"379.55400","31.62968","0.00249"
"379.84800","31.65413","0.00215"
"380.14200","31.67871","0.00188"
"380.43600","31.70310","0.00194"
"380.73000","31.72774","0.00244"
"381.02400","31.75213","0.00239"
"381.31800","31.77670","0.00191"
"381.61200","31.80122","0.00260"
"381.90600","31.82567","0.00246"
"382.20000","31.85018","0.00193"
"382.49400","31.87464","0.00245"
"382.78800","31.89921","0.00262"
"383.08200","31.92366","0.00244"
"383.37600","31.94824","0.00180"
"383.67000","31.97269","0.00201"
"383.96400","31.99720","0.00131"
"384.25800","32.02166","0.00208"
"384.55200","32.04617","0.00133"
"384.84600","32.07069","0.00183"
"385.14000","32.09520","0.00145"
"385.43400","32.11971","0.00207"
"385.72800","32.14411","0.00200"
"386.02200","32.16868","0.00186"
"386.31600","32.19313","0.00215"
"386.61000","32.21771","0.00199"
"386.90400","32.24210","0.00190"
"387.19800","32.26668","0.00181"
"387.49200","32.29119","0.00182"
"387.78600","32.31570","0.00147"
"388.08000","32.34016","0.00169"
"388.37400","32.36461","0.00187"
"388.66800","32.38919","0.00181"
"388.96200","32.41370","0.00136"
"389.25600","32.43821","0.00171"
"389.55000","32.46267","0.00198"
"389.84400","32.48724","0.00162"
"390.13800","32.51169","0.00224"
"390.43200","32.53621","0.00146"
"390.72600","32.56066","0.00185"
"391.02000","32.58517","0.00171"
"391.31400","32.60969","0.00146"
"391.60800","32.63420","0.00189"
"391.90200","32.65871","0.00168"
"392.19600","32.68317","0.00198"
"392.49000","32.70774","0.00177"
"392.78400","32.73214","0.00191"
"393.07800","32.75671","0.00159"
"393.37200","32.78117","0.00161"
"393.66600","32.80568","0.00187"
"393.96000","32.83019","0.00134"
"394.25400","32.85471","0.00161"
"394.54800","32.87922","0.00146"
"394.84200","32.90368","0.00211"
"395.13600","32.92825","0.00184"
"395.43000","32.95264","0.00175"
"395.72400","32.97721","0.00176"
"396.01800","33.00161","0.00151"
"396.31200","33.02618","0.00167"
"396.60600","33.05064","0.00227"
"396.90000","33.07515","0.00230"
"397.19400","33.09966","0.00158"
"397.48800","33.12418","0.00197"
"397.78200","33.14869","0.00202"
"398.07600","33.17308","0.00149"
"398.37000","33.19766","0.00223"
"398.66400","33.22211","0.00208"
"398.95800","33.24669","0.00195"
"399.25200","33.27108","0.00192"
"399.54600","33.29571","0.00219"
"399.84000","33.32017","0.00190"
"400.13400","33.34462","0.00195"
"400.42800","33.36914","0.00228"
"400.72200","33.39371","0.00203"
"401.01600","33.41822","0.00198"
"401.31000","33.44268","0.00221"
"401.60400","33.46725","0.00234"
"401.89800","33.49165","0.00205"
"402.19200","33.51622","0.00238"
"402.48600","33.54067","0.00222"
"402.78000","33.56519","0.00272"
"403.07400","33.58964","0.00231"
"403.36800","33.61415","0.00265"
"403.66200","33.63867","0.00252"
"403.95600","33.66318","0.00272"
"404.25000","33.68776","0.00238"
"404.54400","33.71215","0.00165"
"404.83800","33.73672","0.00207"
"405.13200","33.76118","0.00210"
"405.42600","33.78569","0.00162"
"405.72000","33.81014","0.00171"
"406.01400","33.83472","0.00202"
"406.30800","33.85917","0.00170"
"406.60200","33.88374","0.00209"
"406.89600","33.90820","0.00259"
"407.19000","33.93271","0.00195"
"407.48400","33.95723","0.00238"
"407.77800","33.98162","0.00225"
"408.07200","34.00620","0.00268"
"408.36600","34.03065","0.00259"
"408.66000","34.05516","0.00280"
"408.95400","34.07962","0.00246"
"409.24800","34.10419","0.00217"
"409.54200","34.12864","0.00203"
"409.83600","34.15316","0.00267"
"410.13000","34.17767","0.00252"
"410.42400","34.20213","0.00240"
"410.71800","34.22670","0.00230"
"411.01200","34.25109","0.00197"
"411.30600","34.27567","0.00235"
"411.60000","34.30018","0.00275"
"411.89400","34.32469","0.00235"
"412.18800","34.34915","0.00235"
"412.48200","34.37372","0.00248"
"412.77600","34.39817","0.00206"
"413.07000","34.42269","0.00249"
"413.36400","34.44720","0.00209"
"413.65800","34.47171","0.00229"
"413.95200","34.49623","0.00263"
"414.24600","34.52062","0.00208"
"414.54000","34.54519","0.00247"
"414.83400","34.56965","0.00221"
"415.12800","34.59416","0.00217"
"415.42200","34.61868","0.00280"
"415.71600","34.64325","0.00252"
"416.01000","34.66764","0.00199"
"416.30400","34.69216","0.00207"
"416.59800","34.71667","0.00182"
"416.89200","34.74118","0.00186"
"417.18600","34.76570","0.00237"
"417.48000","34.79015","0.00178"
"417.77400","34.81467","0.00155"
"418.06800","34.83918","0.00184"
"418.36200","34.86370","0.00234"
"418.65600","34.88815","0.00212"
"418.95000","34.91272","0.00241"
"419.24400","34.93718","0.00261"
"419.53800","34.96175","0.00238"
"419.83200","34.98621","0.00246"
"420.12600","35.01072","0.00242"
"420.42000","35.03523","0.00232"
"420.71400","35.05969","0.00219"
"421.00800","35.08420","0.00285"
"421.30200","35.10865","0.00242"
"421.59600","35.13323","0.00225"
"421.89000","35.15762","0.00210"
"422.18400","35.18219","0.00239"
"422.47800","35.20665","0.00261"
"422.77200","35.23116","0.00248"
"423.06600","35.25567","0.00212"
"423.36000","35.28013","0.00213"
"423.65400","35.30464","0.00226"
"423.94800","35.32910","0.00288"
"424.24200","35.35367","0.00221"
"424.53600","35.37812","0.00235"
"424.83000","35.40269","0.00294"
"425.12400","35.42721","0.00247"
"425.41800","35.45173","0.00266"
"425.71200","35.47618","0.00260"
"426.00600","35.50069","0.00289"
"426.30000","35.52515","0.00207"
"426.59400","35.54966","0.00253"
"426.88800","35.57418","0.00263"
"427.18200","35.59863","0.00207"
"427.47600","35.62320","0.00262"
"427.77000","35.64766","0.00261"
"428.06400","35.67223","0.00276"
"428.35800","35.69668","0.00312"
"428.65200","35.72126","0.00229"
"428.94600","35.74565","0.00299"
"429.24000","35.77016","0.00288"
"429.53400","35.79468","0.00290"
"429.82800","35.81919","0.00276"
"430.12200","35.84377","0.00268"
"430.41600","35.86816","0.00286"
"430.71000","35.89273","0.00297"
"431.00400","35.91719","0.00318"
"431.29800","35.94170","0.00314"
"431.59200","35.96621","0.00258"
"431.88600","35.99073","0.00278"
"432.18000","36.01512","0.00308"
"432.47400","36.03970","0.00303"
"432.76800","36.06421","0.00252"
"433.06200","36.08867","0.00307"
"433.35600","36.11318","0.00313"
"433.65000","36.13763","0.00284"
"433.72200","36.14361","0.00302"