File: Force_trajectories/161216/Specimen_RawData_1.csv
End date,"12/16/2016"
Specimen label,"6DG_44"
Maximum Load,"0.70196",N

Time,Extension,Load
(s),(mm),(N)
"0.00000","0.00000","0.00003"
"0.49200","0.04125","0.00202"
"0.98400","0.08227","0.00323"
"1.47600","0.12323","0.00423"
"1.96800","0.16424","0.00469"
"2.46000","0.20526","0.00451"
"2.95200","0.24621","0.00561"
"3.44400","0.28717","0.00626"
"3.93600","0.32818","0.00601"
"4.42800","0.36914","0.00631"
"4.92000","0.41016","0.00647"
"5.41200","0.45117","0.00660"
"5.90400","0.49219","0.00691"
"6.39600","0.53314","0.00725"
"6.88800","0.57422","0.00726"
"7.38000","0.61523","0.00724"
"7.87200","0.65619","0.00709"
"8.36400","0.69721","0.00703"
"8.85600","0.73816","0.00710"
"9.34800","0.77924","0.00749"
"9.84000","0.82019","0.00759"
"10.33200","0.86121","0.00788"
"10.82400","0.90216","0.00782"
"11.31600","0.94318","0.00813"
"11.80800","0.98420","0.00837"
"12.30000","1.02521","0.00848"
"12.79200","1.06623","0.00821"
"13.28400","1.10718","0.00856"
"13.77600","1.14826","0.00859"
"14.26800","1.18915","0.00874"
"14.76000","1.23017","0.00841"
"15.25200","1.27119","0.00896"
"15.74400","1.31220","0.00855"
"16.23600","1.35316","0.00850"
"16.72800","1.39417","0.00888"
"17.22000","1.43519","0.00903"
"17.71200","1.47620","0.00923"
"18.20400","1.51722","0.00903"
"18.69600","1.55817","0.00929"
"19.18800","1.59925","0.00950"
"19.68000","1.64021","0.00947"
"20.17200","1.68122","0.00961"
"20.66400","1.72218","0.00938"
"21.15600","1.76313","0.00951"
"21.64800","1.80415","0.00937"
"22.14000","1.84516","0.00960"
"22.63200","1.88618","0.00973"
"23.12400","1.92720","0.00987"
"23.61600","1.96815","0.00957"
"24.10800","2.00917","0.00971"
"24.60000","2.05024","0.00972"
"25.09200","2.09120","0.00996"
"25.58400","2.13221","0.01038"
"26.07600","2.17317","0.00976"
"26.56800","2.21419","0.00996"
"27.06000","2.25514","0.01017"
"27.55200","2.29622","0.00995"
"28.04400","2.33711","0.01005"
"28.53600","2.37813","0.01025"
"29.02800","2.41920","0.01052"
"29.52000","2.46022","0.01040"
"30.01200","2.50124","0.01013"
"30.50400","2.54225","0.01025"
"30.99600","2.58321","0.01050"
"31.48800","2.62416","0.01060"
"31.98000","2.66518","0.01050"
"32.47200","2.70613","0.01093"
"32.96400","2.74715","0.01046"
"33.45600","2.78817","0.01092"
"33.94800","2.82912","0.01059"
"34.44000","2.87014","0.01037"
"34.93200","2.91121","0.01035"
"35.42400","2.95223","0.01083"
"35.91600","2.99324","0.01070"
"36.40800","3.03420","0.01059"
"36.90000","3.07522","0.01045"
"37.39200","3.11617","0.01080"
"37.88400","3.15719","0.01089"
"38.37600","3.19820","0.01088"
"38.86800","3.23916","0.01066"
"39.36000","3.28011","0.01086"
"39.85200","3.32113","0.01092"
"40.34400","3.36220","0.01099"
"40.83600","3.40316","0.01112"
"41.32800","3.44424","0.01105"
"41.82000","3.48519","0.01107"
"42.31200","3.52621","0.01078"
"42.80400","3.56722","0.01079"
"43.29600","3.60818","0.01072"
"43.78800","3.64919","0.01111"
"44.28000","3.69015","0.01084"
"44.77200","3.73117","0.01114"
"45.26400","3.77212","0.01114"
"45.75600","3.81314","0.01116"
"46.24800","3.85415","0.01129"
"46.74000","3.89523","0.01100"
"47.23200","3.93618","0.01122"
"47.72400","3.97720","0.01124"
"48.21600","4.01822","0.01150"
"48.70800","4.05917","0.01118"
"49.20000","4.10019","0.01129"
"49.69200","4.14120","0.01148"
"50.18400","4.18216","0.01156"
"50.67600","4.22317","0.01133"
"51.16800","4.26419","0.01135"
"51.66000","4.30515","0.01155"
"52.15200","4.34616","0.01159"
"52.64400","4.38724","0.01111"
"53.13600","4.42819","0.01099"
"53.62800","4.46921","0.01079"
"54.12000","4.51022","0.01093"
"54.61200","4.55118","0.01107"
"55.10400","4.59213","0.01068"
"55.59600","4.63315","0.01093"
"56.08800","4.67417","0.01043"
"56.58000","4.71518","0.01081"
"57.07200","4.75614","0.01112"
"57.56400","4.79721","0.01094"
"58.05600","4.83817","0.01129"
"58.54800","4.87924","0.01110"
"59.04000","4.92026","0.01157"
"59.53200","4.96122","0.01099"
"60.02400","5.00223","0.01137"
"60.51600","5.04325","0.01128"
"61.00800","5.08420","0.01130"
"61.50000","5.12516","0.01163"
"61.99200","5.16617","0.01129"
"62.48400","5.20713","0.01192"
"62.97600","5.24815","0.01181"
"63.46800","5.28916","0.01189"
"63.96000","5.33018","0.01167"
"64.45200","5.37119","0.01200"
"64.94400","5.41227","0.01154"
"65.43600","5.45322","0.01167"
"65.92800","5.49424","0.01209"
"66.42000","5.53520","0.01185"
"66.91200","5.57615","0.01204"
"67.40400","5.61717","0.01216"
"67.89600","5.65812","0.01233"
"68.38800","5.69914","0.01207"
"68.88000","5.74021","0.01223"
"69.37200","5.78117","0.01297"
"69.86400","5.82219","0.01245"
"70.35600","5.86320","0.01201"
"70.84800","5.90416","0.01256"
"71.34000","5.94517","0.01227"
"71.83200","5.98619","0.01234"
"72.32400","6.02720","0.01258"
"72.81600","6.06816","0.01230"
"73.30800","6.10918","0.01256"
"73.80000","6.15013","0.01251"
"74.29200","6.19121","0.01299"
"74.78400","6.23222","0.01234"
"75.27600","6.27312","0.01233"
"75.76800","6.31419","0.01197"
"76.26000","6.35521","0.01209"
"76.75200","6.39616","0.01247"
"77.24400","6.43724","0.01166"
"77.73600","6.47820","0.01201"
"78.22800","6.51921","0.01228"
"78.72000","6.56011","0.01234"
"79.21200","6.60124","0.01274"
"79.70400","6.64220","0.01199"
"80.19600","6.68315","0.01279"
"80.68800","6.72411","0.01253"
"81.18000","6.76519","0.01256"
"81.67200","6.80620","0.01250"
"82.16400","6.84722","0.01263"
"82.65600","6.88823","0.01223"
"83.14800","6.92919","0.01201"
"83.64000","6.97020","0.01188"
"84.13200","7.01116","0.01211"
"84.62400","7.05218","0.01212"
"85.11600","7.09319","0.01226"
"85.60800","7.13415","0.01265"
"86.10000","7.17516","0.01226"
"86.59200","7.21618","0.01239"
"87.08400","7.25719","0.01250"
"87.57600","7.29821","0.01246"
"88.06800","7.33923","0.01271"
"88.56000","7.38024","0.01248"
"89.05200","7.42120","0.01252"
"89.54400","7.46221","0.01280"
"90.03600","7.50317","0.01253"
"90.52800","7.54418","0.01221"
"91.02000","7.58514","0.01248"
"91.51200","7.62616","0.01261"
"92.00400","7.66723","0.01294"
"92.49600","7.70819","0.01265"
"92.98800","7.74920","0.01249"
"93.48000","7.79016","0.01262"
"93.97200","7.83123","0.01349"
"94.46400","7.87219","0.01276"
"94.95600","7.91320","0.01289"
"95.44800","7.95416","0.01279"
"95.94000","7.99512","0.01299"
"96.43200","8.03619","0.01379"
"96.92400","8.07715","0.01319"
"97.41600","8.11816","0.01337"
"97.90800","8.15918","0.01277"
"98.40000","8.20019","0.01261"
"98.89200","8.24121","0.01339"
"99.38400","8.28217","0.01257"
"99.87600","8.32324","0.01345"
"100.36800","8.36420","0.01325"
"100.86000","8.40521","0.01268"
"101.35200","8.44617","0.01328"
"101.84400","8.48718","0.01280"
"102.33600","8.52814","0.01314"
"102.82800","8.56916","0.01318"
"103.32000","8.61017","0.01330"
"103.81200","8.65119","0.01348"
"104.30400","8.69220","0.01316"
"104.79600","8.73322","0.01315"
"105.28800","8.77423","0.01354"
"105.78000","8.81519","0.01352"
"106.27200","8.85620","0.01385"
"106.76400","8.89722","0.01369"
"107.25600","8.93818","0.01304"
"107.74800","8.97913","0.01310"
"108.24000","9.02015","0.01307"
"108.73200","9.06116","0.01357"
"109.22400","9.10224","0.01313"
"109.71600","9.14313","0.01337"
"110.20800","9.18421","0.01350"
"110.70000","9.22523","0.01333"
"111.19200","9.26618","0.01397"
"111.68400","9.30720","0.01321"
"112.17600","9.34821","0.01389"
"112.66800","9.38923","0.01372"
"113.16000","9.43012","0.01373"
"113.65200","9.47120","0.01376"
"114.14400","9.51210","0.01364"
"114.63600","9.55317","0.01378"
"115.12800","9.59419","0.01359"
"115.62000","9.63520","0.01374"
"116.11200","9.67622","0.01415"
"116.60400","9.71723","0.01362"
"117.09600","9.75825","0.01312"
"117.58800","9.79926","0.01340"
"118.08000","9.84022","0.01315"
"118.57200","9.88118","0.01355"
"119.06400","9.92219","0.01343"
"119.55600","9.96315","0.01364"
"120.04800","10.00416","0.01377"
"120.54000","10.04518","0.01354"
"121.03200","10.08620","0.01311"
"121.52400","10.12721","0.01362"
"122.01600","10.16823","0.01365"
"122.50800","10.20924","0.01353"
"123.00000","10.25020","0.01416"
"123.49200","10.29121","0.01367"
"123.98400","10.33217","0.01350"
"124.47600","10.37318","0.01425"
"124.96800","10.41414","0.01432"
"125.46000","10.45516","0.01404"
"125.95200","10.49617","0.01351"
"126.44400","10.53719","0.01347"
"126.93600","10.57814","0.01344"
"127.42800","10.61922","0.01384"
"127.92000","10.66018","0.01366"
"128.41200","10.70125","0.01348"
"128.90400","10.74221","0.01393"
"129.39600","10.78322","0.01340"
"129.88800","10.82418","0.01378"
"130.38000","10.86513","0.01404"
"130.87200","10.90621","0.01404"
"131.36400","10.94717","0.01421"
"131.85600","10.98812","0.01362"
"132.34800","11.02920","0.01437"
"132.84000","11.07021","0.01411"
"133.33200","11.11123","0.01363"
"133.82400","11.15218","0.01394"
"134.31600","11.19320","0.01380"
"134.80800","11.23415","0.01380"
"135.30000","11.27523","0.01406"
"135.79200","11.31618","0.01385"
"136.28400","11.35720","0.01415"
"136.77600","11.39810","0.01405"
"137.26800","11.43917","0.01428"
"137.76000","11.48019","0.01408"
"138.25200","11.52114","0.01411"
"138.74400","11.56222","0.01433"
"139.23600","11.60324","0.01502"
"139.72800","11.64419","0.01429"
"140.22000","11.68521","0.01484"
"140.71200","11.72616","0.01467"
"141.20400","11.76724","0.01487"
"141.69600","11.80819","0.01494"
"142.18800","11.84915","0.01498"
"142.68000","11.89017","0.01546"
"143.17200","11.93118","0.01481"
"143.66400","11.97220","0.01461"
"144.15600","12.01315","0.01493"
"144.64800","12.05417","0.01496"
"145.14000","12.09518","0.01495"
"145.63200","12.13626","0.01516"
"146.12400","12.17715","0.01552"
"146.61600","12.21823","0.01517"
"147.10800","12.25919","0.01517"
"147.60000","12.30014","0.01562"
"148.09200","12.34116","0.01482"
"148.58400","12.38217","0.01496"
"149.07600","12.42313","0.01505"
"149.56800","12.46420","0.01558"
"150.06000","12.50522","0.01568"
"150.55200","12.54624","0.01544"
"151.04400","12.58719","0.01623"
"151.53600","12.62821","0.01568"
"152.02800","12.66928","0.01552"
"152.52000","12.71024","0.01621"
"153.01200","12.75113","0.01573"
"153.50400","12.79215","0.01621"
"153.99600","12.83311","0.01629"
"154.48800","12.87412","0.01607"
"154.98000","12.91514","0.01555"
"155.47200","12.95615","0.01597"
"155.96400","12.99723","0.01595"
"156.45600","13.03824","0.01625"
"156.94800","13.07920","0.01649"
"157.44000","13.12022","0.01650"
"157.93200","13.16123","0.01691"
"158.42400","13.20225","0.01608"
"158.91600","13.24314","0.01662"
"159.40800","13.28416","0.01661"
"159.90000","13.32511","0.01659"
"160.39200","13.36619","0.01661"
"160.88400","13.40720","0.01649"
"161.37600","13.44816","0.01721"
"161.86800","13.48918","0.01580"
"162.36000","13.53019","0.01569"
"162.85200","13.57121","0.01507"
"163.34400","13.61216","0.01526"
"163.83600","13.65318","0.01532"
"164.32800","13.69419","0.01562"
"164.82000","13.73515","0.01558"
"165.31200","13.77617","0.01577"
"165.80400","13.81718","0.01562"
"166.29600","13.85820","0.01629"
"166.78800","13.89915","0.01600"
"167.28000","13.94023","0.01609"
"167.77200","13.98118","0.01571"
"168.26400","14.02220","0.01603"
"168.75600","14.06322","0.01604"
"169.24800","14.10423","0.01635"
"169.74000","14.14519","0.01620"
"170.23200","14.18614","0.01606"
"170.72400","14.22716","0.01632"
"171.21600","14.26817","0.01649"
"171.70800","14.30913","0.01619"
"172.20000","14.35021","0.01659"
"172.69200","14.39122","0.01740"
"173.18400","14.43218","0.01679"
"173.67600","14.47319","0.01683"
"174.16800","14.51421","0.01693"
"174.66000","14.55516","0.01710"
"175.15200","14.59618","0.01680"
"175.64400","14.63720","0.01693"
"176.13600","14.67821","0.01716"
"176.62800","14.71917","0.01720"
"177.12000","14.76012","0.01690"
"177.61200","14.80120","0.01689"
"178.10400","14.84215","0.01765"
"178.59600","14.88317","0.01735"
"179.08800","14.92424","0.01673"
"179.58000","14.96520","0.01746"
"180.07200","15.00622","0.01748"
"180.56400","15.04723","0.01722"
"181.05600","15.08825","0.01736"
"181.54800","15.12920","0.01773"
"182.04000","15.17016","0.01727"
"182.53200","15.21117","0.01760"
"183.02400","15.25207","0.01740"
"183.51600","15.29321","0.01778"
"184.00800","15.33416","0.01808"
"184.50000","15.37518","0.01757"
"184.99200","15.41619","0.01778"
"185.48400","15.45721","0.01764"
"185.97600","15.49817","0.01764"
"186.46800","15.53918","0.01801"
"186.96000","15.58020","0.01789"
"187.45200","15.62115","0.01769"
"187.94400","15.66217","0.01845"
"188.43600","15.70318","0.01831"
"188.92800","15.74414","0.01854"
"189.42000","15.78515","0.01869"
"189.91200","15.82617","0.01899"
"190.40400","15.86724","0.01881"
"190.89600","15.90820","0.01862"
"191.38800","15.94922","0.01850"
"191.88000","15.99017","0.01885"
"192.37200","16.03119","0.01882"
"192.86400","16.07220","0.01956"
"193.35600","16.11316","0.01951"
"193.84800","16.15411","0.01939"
"194.34000","16.19519","0.01969"
"194.83200","16.23621","0.01922"
"195.32400","16.27716","0.01960"
"195.81600","16.31812","0.02006"
"196.30800","16.35919","0.01860"
"196.80000","16.40021","0.01894"
"197.29200","16.44116","0.01947"
"197.78400","16.48218","0.01873"
"198.27600","16.52320","0.01900"
"198.76800","16.56421","0.01922"
"199.26000","16.60511","0.01952"
"199.75200","16.64618","0.02017"
"200.24400","16.68708","0.01923"
"200.73600","16.72816","0.02007"
"201.22800","16.76923","0.02058"
"201.72000","16.81019","0.02018"
"202.21200","16.85120","0.02094"
"202.70400","16.89222","0.02094"
"203.19600","16.93323","0.02140"
"203.68800","16.97419","0.02168"
"204.18000","17.01526","0.02167"
"204.67200","17.05616","0.02150"
"205.16400","17.09718","0.02180"
"205.65600","17.13813","0.02100"
"206.14800","17.17915","0.02178"
"206.64000","17.22016","0.02187"
"207.13200","17.26118","0.02191"
"207.62400","17.30219","0.02181"
"208.11600","17.34321","0.02264"
"208.60800","17.38423","0.02212"
"209.10000","17.42518","0.02268"
"209.59200","17.46620","0.02300"
"210.08400","17.50721","0.02294"
"210.57600","17.54817","0.02296"
"211.06800","17.58918","0.02372"
"211.56000","17.63014","0.02322"
"212.05200","17.67122","0.02327"
"212.54400","17.71223","0.02340"
"213.03600","17.75313","0.02367"
"213.52800","17.79420","0.02372"
"214.02000","17.83528","0.02441"
"214.51200","17.87623","0.02418"
"215.00400","17.91719","0.02399"
"215.49600","17.95820","0.02493"
"215.98800","17.99922","0.02483"
"216.48000","18.04012","0.02471"
"216.97200","18.08119","0.02573"
"217.46400","18.12215","0.02618"
"217.95600","18.16316","0.02555"
"218.44800","18.20418","0.02628"
"218.94000","18.24519","0.02601"
"219.43200","18.28621","0.02680"
"219.92400","18.32717","0.02730"
"220.41600","18.36824","0.02733"
"220.90800","18.40914","0.02749"
"221.40000","18.45021","0.02795"
"221.89200","18.49117","0.02795"
"222.38400","18.53218","0.02809"
"222.87600","18.57314","0.02842"
"223.36800","18.61416","0.02867"
"223.86000","18.65511","0.02911"
"224.35200","18.69625","0.02916"
"224.84400","18.73720","0.02942"
"225.33600","18.77822","0.02964"
"225.82800","18.81917","0.03011"
"226.32000","18.86019","0.03067"
"226.81200","18.90121","0.03071"
"227.30400","18.94222","0.03074"
"227.79600","18.98318","0.03124"
"228.28800","19.02419","0.03096"
"228.78000","19.06515","0.03148"
"229.27200","19.10616","0.03158"
"229.76400","19.14718","0.03169"
"230.25600","19.18820","0.03204"
"230.74800","19.22921","0.03211"
"231.24000","19.27023","0.03202"
"231.73200","19.31124","0.03220"
"232.22400","19.35220","0.03277"
"232.71600","19.39321","0.03338"
"233.20800","19.43423","0.03388"
"233.70000","19.47518","0.03447"
"234.19200","19.51620","0.03532"
"234.68400","19.55716","0.03514"
"235.17600","19.59817","0.03554"
"235.66800","19.63913","0.03597"
"236.16000","19.68020","0.03671"
"236.65200","19.72122","0.03729"
"237.14400","19.76224","0.03706"
"237.63600","19.80319","0.03887"
"238.12800","19.84426","0.03957"
"238.62000","19.88522","0.04045"
"239.11200","19.92612","0.04038"
"239.60400","19.96719","0.04187"
"240.09600","20.00815","0.04310"
"240.58800","20.04910","0.04395"
"241.08000","20.09018","0.04494"
"241.57200","20.13119","0.04648"
"242.06400","20.17221","0.04788"
"242.55600","20.21323","0.04884"
"243.04800","20.25418","0.05037"
"243.54000","20.29520","0.05111"
"244.03200","20.33621","0.05199"
"244.52400","20.37717","0.05323"
"245.01600","20.41819","0.05356"
"245.50800","20.45914","0.05473"
"246.00000","20.50016","0.05623"
"246.49200","20.54117","0.05742"
"246.98400","20.58219","0.05805"
"247.47600","20.62314","0.05880"
"247.96800","20.66422","0.06046"
"248.46000","20.70524","0.06253"
"248.95200","20.74619","0.06398"
"249.44400","20.78720","0.06647"
"249.93600","20.82822","0.06788"
"250.42800","20.86924","0.06959"
"250.92000","20.91013","0.07102"
"251.41200","20.95115","0.07249"
"251.90400","20.99211","0.07467"
"252.39600","21.03318","0.07618"
"252.88800","21.07419","0.07806"
"253.38000","21.11521","0.07874"
"253.87200","21.15617","0.07856"
"254.36400","21.19718","0.08006"
"254.85600","21.23826","0.08178"
"255.34800","21.27921","0.08429"
"255.84000","21.32023","0.08655"
"256.33200","21.36112","0.08860"
"256.82400","21.40214","0.09150"
"257.31600","21.44316","0.09399"
"257.80800","21.48417","0.09533"
"258.30000","21.52519","0.09841"
"258.79200","21.56620","0.09923"
"259.28400","21.60722","0.10092"
"259.77600","21.64818","0.10311"
"260.26800","21.68919","0.10403"
"260.76000","21.73021","0.10609"
"261.25200","21.77122","0.10700"
"261.74400","21.81218","0.10885"
"262.23600","21.85319","0.11072"
"262.72800","21.89421","0.11287"
"263.22000","21.93517","0.11457"
"263.71200","21.97618","0.11636"
"264.20400","22.01714","0.11896"
"264.69600","22.05815","0.12081"
"265.18800","22.09923","0.12295"
"265.68000","22.14024","0.12583"
"266.17200","22.18120","0.12855"
"266.66400","22.22222","0.13056"
"267.15600","22.26323","0.13350"
"267.64800","22.30425","0.13596"
"268.14000","22.34514","0.13833"
"268.63200","22.38616","0.14062"
"269.12400","22.42711","0.14205"
"269.61600","22.46813","0.09755"
"270.10800","22.50914","0.09820"
"270.60000","22.55022","0.10331"
"271.09200","22.59124","0.09806"
"271.58400","22.63219","0.10601"
"272.07600","22.67321","0.10686"
"272.56800","22.71416","0.10852"
"273.06000","22.75518","0.10881"
"273.55200","22.79619","0.11292"
"274.04400","22.83721","0.11460"
"274.53600","22.87811","0.11455"
"275.02800","22.91912","0.11796"
"275.52000","22.96020","0.11997"
"276.01200","23.00121","0.12246"
"276.50400","23.04223","0.12392"
"276.99600","23.08319","0.12594"
"277.48800","23.12420","0.12819"
"277.98000","23.16522","0.13020"
"278.47200","23.20623","0.13288"
"278.96400","23.24719","0.13623"
"279.45600","23.28814","0.13673"
"279.94800","23.32916","0.13867"
"280.44000","23.37017","0.09690"
"280.93200","23.41119","0.10027"
"281.42400","23.45215","0.10233"
"281.91600","23.49316","0.10371"
"282.40800","23.53418","0.10574"
"282.90000","23.57525","0.10686"
"283.39200","23.61621","0.10899"
"283.88400","23.65716","0.10616"
"284.37600","23.69824","0.10711"
"284.86800","23.73920","0.10756"
"285.36000","23.78015","0.10767"
"285.85200","23.82123","0.10984"
"286.34400","23.86212","0.11200"
"286.83600","23.90320","0.11435"
"287.32800","23.94415","0.11525"
"287.82000","23.98523","0.11636"
"288.31200","24.02624","0.11762"
"288.80400","24.06720","0.11679"
"289.29600","24.10822","0.11887"
"289.78800","24.14917","0.12160"
"290.28000","24.19019","0.12037"
"290.77200","24.23114","0.12113"
"291.26400","24.27222","0.12421"
"291.75600","24.31317","0.12708"
"292.24800","24.35413","0.12849"
"292.74000","24.39520","0.13000"
"293.23200","24.43616","0.13214"
"293.72400","24.47718","0.13595"
"294.21600","24.51819","0.13870"
"294.70800","24.55921","0.14365"
"295.20000","24.60016","0.14865"
"295.69200","24.64118","0.15284"
"296.18400","24.68219","0.15708"
"296.67600","24.72321","0.16051"
"297.16800","24.76417","0.16417"
"297.66000","24.80512","0.16767"
"298.15200","24.84614","0.17353"
"298.64400","24.88721","0.17946"
"299.13600","24.92817","0.18417"
"299.62800","24.96924","0.18786"
"300.12000","25.01020","0.18954"
"300.61200","25.05122","0.19323"
"301.10400","25.09223","0.19642"
"301.59600","25.13319","0.20128"
"302.08800","25.17420","0.20518"
"302.58000","25.21516","0.20762"
"303.07200","25.25617","0.21045"
"303.56400","25.29713","0.21458"
"304.05600","25.33815","0.21792"
"304.54800","25.37916","0.22038"
"305.04000","25.42024","0.22343"
"305.53200","25.46119","0.22731"
"306.02400","25.50221","0.20116"
"306.51600","25.54323","0.20470"
"307.00800","25.58418","0.20228"
"307.50000","25.62519","0.20447"
"307.99200","25.66621","0.20325"
"308.48400","25.70717","0.20592"
"308.97600","25.74813","0.21153"
"309.46800","25.78914","0.21363"
"309.96000","25.83015","0.21826"
"310.45200","25.87117","0.22164"
"310.94400","25.91224","0.22437"
"311.43600","25.95320","0.22845"
"311.92800","25.99422","0.23120"
"312.42000","26.03523","0.23557"
"312.91200","26.07619","0.23893"
"313.40400","26.11714","0.24316"
"313.89600","26.15822","0.24798"
"314.38800","26.19917","0.25256"
"314.88000","26.24019","0.25760"
"315.37200","26.28115","0.26251"
"315.86400","26.32216","0.26769"
"316.35600","26.36318","0.27387"
"316.84800","26.40425","0.28096"
"317.34000","26.44521","0.28433"
"317.83200","26.48623","0.29008"
"318.32400","26.52718","0.29650"
"318.81600","26.56820","0.30019"
"319.30800","26.60921","0.30704"
"319.80000","26.65017","0.31251"
"320.29200","26.69118","0.31563"
"320.78400","26.73208","0.31924"
"321.27600","26.77316","0.32486"
"321.76800","26.81417","0.32854"
"322.26000","26.85525","0.33261"
"322.75200","26.89620","0.33657"
"323.24400","26.93722","0.33871"
"323.73600","26.97817","0.34167"
"324.22800","27.01919","0.34556"
"324.72000","27.06027","0.34954"
"325.21200","27.10122","0.35436"
"325.70400","27.14218","0.35866"
"326.19600","27.18313","0.36390"
"326.68800","27.22415","0.36740"
"327.18000","27.26517","0.37266"
"327.67200","27.30618","0.37980"
"328.16400","27.34720","0.38514"
"328.65600","27.38821","0.38965"
"329.14800","27.42923","0.39269"
"329.64000","27.47018","0.39720"
"330.13200","27.51120","0.40299"
"330.62400","27.55221","0.40889"
"331.11600","27.59317","0.41388"
"331.60800","27.63418","0.41781"
"332.10000","27.67514","0.42142"
"332.59200","27.71622","0.42276"
"333.08400","27.75717","0.42561"
"333.57600","27.79813","0.42915"
"334.06800","27.83920","0.43345"
"334.56000","27.88028","0.43663"
"335.05200","27.92124","0.44331"
"335.54400","27.96225","0.44693"
"336.03600","28.00320","0.45345"
"336.52800","28.04416","0.45975"
"337.02000","28.08518","0.46476"
"337.51200","28.12619","0.46878"
"338.00400","28.16715","0.47400"
"338.49600","28.20816","0.48105"
"338.98800","28.24912","0.48954"
"339.48000","28.29020","0.49361"
"339.97200","28.33121","0.49832"
"340.46400","28.37223","0.50430"
"340.95600","28.41318","0.51226"
"341.44800","28.45420","0.51726"
"341.94000","28.49521","0.52356"
"342.43200","28.53617","0.52858"
"342.92400","28.57719","0.53213"
"343.41600","28.61814","0.53560"
"343.90800","28.65916","0.53995"
"344.40000","28.70017","0.54620"
"344.89200","28.74113","0.55215"
"345.38400","28.78220","0.55710"
"345.87600","28.82322","0.53241"
"346.36800","28.86424","0.53299"
"346.86000","28.90519","0.53607"
"347.35200","28.94621","0.54229"
"347.84400","28.98716","0.54979"
"348.33600","29.02818","0.55703"
"348.82800","29.06919","0.56339"
"349.32000","29.11009","0.56902"
"349.81200","29.15116","0.57525"
"350.30400","29.19218","0.58767"
"350.79600","29.23314","0.59633"
"351.28800","29.27421","0.60191"
"351.78000","29.31517","0.60822"
"352.27200","29.35624","0.61565"
"352.76400","29.39720","0.62120"
"353.25600","29.43822","0.62776"
"353.74800","29.47917","0.63402"
"354.24000","29.52019","0.63867"
"354.73200","29.56114","0.64289"
"355.22400","29.60216","0.64860"
"355.71600","29.64318","0.65503"
"356.20800","29.68419","0.66451"
"356.70000","29.72520","0.67141"
"357.19200","29.76622","0.67498"
"357.68400","29.80717","0.68411"
"358.17600","29.84819","0.69623"
"358.66800","29.88915","0.70183"
"359.16000","29.93016","0.64541"
"359.65200","29.97118","0.65202"
"360.14400","30.01219","0.65837"
"360.63600","30.05315","0.66530"
"361.12800","30.09417","0.67466"
"361.62000","30.13518","0.67858"
"362.11200","30.17620","0.47386"
"362.60400","30.21721","0.48580"
"363.09600","30.25823","0.47797"
"363.58800","30.29924","0.48258"
"364.08000","30.34014","0.49258"
"364.57200","30.38116","0.49594"
"365.06400","30.42223","0.50821"
"365.55600","30.46319","0.52070"
"366.04800","30.50420","0.53210"
"366.54000","30.54516","0.53731"
"367.03200","30.58617","0.54613"
"367.52400","30.62719","0.55522"
"368.01600","30.66814","0.56069"
"368.50800","30.70916","0.56677"
"369.00000","30.75024","0.57105"
"369.49200","30.79119","0.58413"
"369.98400","30.83221","0.59435"
"370.47600","30.87322","0.60174"
"370.96800","30.91418","0.61005"
"371.46000","30.95513","0.61801"
"371.95200","30.99615","0.62376"
"372.44400","31.03711","0.62834"
"372.93600","31.07818","0.60276"
"373.42800","31.11914","0.60645"
"373.92000","31.16021","0.61163"
"374.41200","31.20123","0.61465"
"374.90400","31.24218","0.61824"
"375.39600","31.28320","0.62131"
"375.88800","31.32421","0.62547"
"376.38000","31.36523","0.63131"
"376.87200","31.40613","0.63476"
"377.36400","31.44720","0.63766"
"377.85600","31.48816","0.64109"
"378.34800","31.52917","0.64486"
"378.84000","31.57019","0.64871"
"379.33200","31.61115","0.65252"
"379.82400","31.65216","0.65745"
"380.31600","31.69324","0.66370"
"380.80800","31.73425","0.66885"
"381.30000","31.77521","0.67201"
"381.79200","31.81616","0.67402"
"382.28400","31.85718","0.56729"
"382.77600","31.89813","0.37954"
"383.26800","31.93915","0.38645"
"383.76000","31.98016","0.36976"
"384.25200","32.02118","0.38510"
"384.74400","32.06219","0.38092"
"385.23600","32.10315","0.38565"
"385.72800","32.14423","0.39255"
"386.22000","32.18524","0.38707"
"386.71200","32.22620","0.39167"
"387.20400","32.26721","0.39514"
"387.69600","32.30817","0.39014"
"388.18800","32.34919","0.39905"
"388.68000","32.39014","0.39692"
"389.17200","32.43122","0.39605"
"389.66400","32.47211","0.40915"
"390.15600","32.51313","0.40759"
"390.64800","32.55415","0.41321"
"391.14000","32.59522","0.41308"
"391.63200","32.63624","0.41524"
"392.12400","32.67713","0.42189"
"392.61600","32.71821","0.41882"
"393.10800","32.75922","0.42372"
"393.60000","32.80024","0.42291"
"394.09200","32.84119","0.42448"
"394.58400","32.88215","0.42719"
"395.07600","32.92316","0.42623"
"395.56800","32.96412","0.43078"
"396.06000","33.00514","0.42811"
"396.55200","33.04615","0.43345"
"397.04400","33.08723","0.43394"
"397.53600","33.12824","0.43832"
"398.02800","33.16926","0.44216"
"398.52000","33.21021","0.44368"
"399.01200","33.25117","0.44847"
"399.50400","33.29219","0.44876"
"399.99600","33.33320","0.45617"
"400.48800","33.37416","0.45665"
"400.98000","33.41511","0.46287"
"401.47200","33.45619","0.46354"
"401.96400","33.49714","0.46856"
"402.45600","33.53816","0.46880"
"402.94800","33.57918","0.47591"
"403.44000","33.62019","0.47676"
"403.93200","33.66127","0.48496"
"404.42400","33.70216","0.48493"
"404.91600","33.74324","0.33260"
"405.40800","33.78419","0.32884"
"405.90000","33.82515","0.32649"
"406.39200","33.86617","0.32553"
"406.88400","33.90712","0.32688"
"407.37600","33.94820","0.32752"
"407.86800","33.98921","0.32388"
"408.36000","34.03023","0.32561"
"408.85200","34.07124","0.32958"
"409.34400","34.11214","0.32820"
"409.83600","34.15322","0.32909"
"410.32800","34.19423","0.33260"
"410.82000","34.23519","0.33427"
"411.31200","34.27614","0.33318"
"411.80400","34.31716","0.33543"
"412.29600","34.35817","0.33749"
"412.78800","34.39913","0.33702"
"413.28000","34.44014","0.33768"
"413.77200","34.48116","0.34058"
"414.26400","34.52224","0.34115"
"414.75600","34.56319","0.34121"
"415.24800","34.60415","0.34275"
"415.74000","34.64516","0.34348"
"416.23200","34.68618","0.34304"
"416.72400","34.72726","0.34478"
"417.21600","34.76815","0.34559"
"417.70800","34.80917","0.34543"
"418.20000","34.85019","0.34722"
"418.69200","34.89120","0.35010"
"419.18400","34.93216","0.34952"
"419.67600","34.97317","0.35014"
"420.16800","35.01419","0.35175"
"420.66000","35.05520","0.35212"
"421.15200","35.09622","0.35325"
"421.64400","35.13717","0.35339"
"422.13600","35.17825","0.35463"
"422.62800","35.21920","0.35771"
"423.12000","35.26016","0.35940"
"423.61200","35.30117","0.35889"
"424.10400","35.34213","0.36038"
"424.59600","35.38314","0.36170"
"425.08800","35.42416","0.35821"
"425.58000","35.46518","0.35847"
"426.07200","35.50619","0.35726"
"426.56400","35.54721","0.00057"
"427.05600","35.58822","0.00904"
"427.54800","35.62924","0.01268"
"428.04000","35.67025","0.01115"
"428.53200","35.71115","0.01184"
"429.02400","35.75217","0.01154"
"429.51600","35.79312","0.01174"
"430.00800","35.83414","0.01105"
"430.50000","35.87516","0.01142"
"430.99200","35.91617","0.01118"
"431.48400","35.95719","0.01210"
"431.97600","35.99820","0.01134"
"432.46800","36.03922","0.01163"
"432.96000","36.08023","0.01156"
"433.45200","36.12119","0.01189"
"433.94400","36.16220","0.01153"
"434.43600","36.20316","0.01170"
"434.92800","36.24412","0.01110"
"435.42000","36.28513","0.01143"
"435.91200","36.32621","0.01176"
"436.40400","36.36716","0.01112"
"436.89600","36.40818","0.01161"
"437.38800","36.44920","0.01196"
"437.88000","36.49021","0.01144"
"438.37200","36.53117","0.01147"
"438.86400","36.57224","0.01123"
"439.35600","36.61320","0.01173"
"439.84800","36.65421","0.01114"
"440.34000","36.69517","0.01131"
"440.83200","36.73618","0.01141"
"441.32400","36.77708","0.01163"
"441.81600","36.81821","0.01132"
"442.30800","36.85917","0.01153"
"442.80000","36.90018","0.01128"
"443.29200","36.94120","0.01148"
"443.78400","36.98222","0.01153"
"444.27600","37.02324","0.01146"
"444.76800","37.06419","0.01138"
"445.26000","37.10521","0.01113"
"445.75200","37.14616","0.01152"
"446.24400","37.18718","0.01152"
"446.73600","37.22813","0.01112"
"447.22800","37.26909","0.01111"
"447.72000","37.31017","0.01150"
"448.21200","37.35118","0.01163"
"448.70400","37.39225","0.01144"
"449.19600","37.43321","0.01166"
"449.68800","37.47423","0.01160"
"450.18000","37.51518","0.01151"
"450.67200","37.55620","0.01138"
"451.16400","37.59721","0.01143"
"451.65600","37.63817","0.01110"
"452.14800","37.67912","0.01125"
"452.64000","37.72014","0.01092"
"453.13200","37.76122","0.01136"
"453.62400","37.80217","0.01150"
"454.11600","37.84313","0.01151"
"454.60800","37.88420","0.01105"
"455.10000","37.92522","0.01163"
"455.59200","37.96617","0.01151"
"456.08400","38.00719","0.01158"
"456.57600","38.04820","0.01139"
"457.06800","38.08922","0.01149"
"457.56000","38.13018","0.01102"
"458.05200","38.17120","0.01156"
"458.54400","38.21209","0.01144"
"459.03600","38.25317","0.01148"
"459.52800","38.29424","0.01111"
"460.02000","38.33520","0.01138"
"460.51200","38.37621","0.01114"
"461.00400","38.41717","0.01135"
"461.49600","38.45818","0.01162"
"461.98800","38.49914","0.01129"
"462.48000","38.54021","0.01107"
"462.97200","38.58117","0.01091"
"463.46400","38.62218","0.01133"
"463.95600","38.66314","0.01116"
"464.44800","38.70415","0.01142"
"464.94000","38.74517","0.01084"
"465.43200","38.78613","0.01130"
"465.92400","38.82720","0.01115"
"466.41600","38.86822","0.01116"
"466.90800","38.90923","0.01130"
"467.40000","38.95025","0.01146"
"467.89200","38.99121","0.01157"
"468.38400","39.03216","0.01119"
"468.87600","39.07318","0.01127"
"469.36800","39.11419","0.01099"
"469.86000","39.15515","0.01104"
"470.35200","39.19616","0.01081"
"470.84400","39.23718","0.01156"
"471.33600","39.27819","0.01130"
"471.82800","39.31921","0.01122"
"472.32000","39.36023","0.01157"
"472.81200","39.40125","0.01131"
"473.30400","39.44220","0.01131"
"473.79600","39.48322","0.01145"
"474.28800","39.52417","0.01191"
"474.78000","39.56512","0.01116"
"475.27200","39.60614","0.01118"
"475.76400","39.64709","0.01118"
"476.25600","39.68811","0.01127"
"476.74800","39.72919","0.01159"
"477.24000","39.77020","0.01132"
"477.73200","39.81121","0.01118"
"478.22400","39.85217","0.01131"
"478.71600","39.89319","0.01100"
"479.20800","39.93420","0.01133"
"479.70000","39.97522","0.01135"
"480.19200","40.01624","0.01113"
"480.68400","40.05719","0.01109"
"481.17600","40.09809","0.01086"
"481.66800","40.13916","0.01094"
"482.16000","40.18018","0.01150"
"482.65200","40.22120","0.01166"
"483.14400","40.26221","0.01143"
"483.63600","40.30317","0.01083"
"484.12800","40.34424","0.01191"
"484.62000","40.38520","0.01106"
"485.11200","40.42621","0.01147"
"485.60400","40.46717","0.01144"
"486.09600","40.50819","0.01193"
"486.58800","40.54920","0.01137"
"487.08000","40.59010","0.01115"
"487.57200","40.63118","0.01154"
"488.06400","40.67219","0.01189"
"488.55600","40.71314","0.01122"
"489.04800","40.75422","0.01168"
"489.54000","40.79517","0.01150"
"490.03200","40.83625","0.01137"
"490.52400","40.87720","0.01183"
"491.01600","40.91822","0.01160"
"491.50800","40.95924","0.01130"
"492.00000","41.00013","0.01157"
"492.49200","41.04115","0.01165"
"492.98400","41.08211","0.01170"
"493.47600","41.12318","0.01175"
"493.96800","41.16414","0.01164"
"494.46000","41.20521","0.01174"
"494.95200","41.24623","0.01160"
"495.44400","41.28724","0.01174"
"495.93600","41.32820","0.01157"
"496.42800","41.36921","0.01127"
"496.92000","41.41023","0.01175"
"497.41200","41.45119","0.01120"
"497.90400","41.49220","0.01138"
"498.39600","41.53315","0.01191"
"498.88800","41.57411","0.01180"
"499.38000","41.61513","0.01157"
"499.87200","41.65620","0.01168"
"500.36400","41.69722","0.01222"
"500.85600","41.73824","0.01206"
"501.34800","41.77919","0.01189"
"501.84000","41.82021","0.01193"
"502.33200","41.86122","0.01216"
"502.82400","41.90218","0.01214"
"503.31600","41.94325","0.01216"
"503.80800","41.98415","0.01243"
"504.30000","42.02511","0.01201"
"504.79200","42.06612","0.01246"
"505.28400","42.10720","0.01250"
"505.77600","42.14816","0.01217"
"506.26800","42.18917","0.01217"
"506.76000","42.23019","0.01277"
"507.25200","42.27120","0.01282"
"507.74400","42.31222","0.01242"
"508.23600","42.35323","0.01285"
"508.72800","42.39418","0.01285"
"509.22000","42.43514","0.01241"
"509.71200","42.47622","0.01300"
"510.20400","42.51711","0.01259"
"510.69600","42.55813","0.01316"
"511.18800","42.59920","0.01281"
"511.68000","42.64016","0.01291"
"512.17200","42.68118","0.01349"
"512.66400","42.72219","0.01305"
"513.15600","42.76321","0.01331"
"513.64800","42.80416","0.01317"
"514.14000","42.84524","0.01369"
"514.63200","42.88614","0.01378"
"515.12400","42.92721","0.01381"
"515.61600","42.96817","0.01392"
"516.10800","43.00912","0.01378"
"516.60000","43.05014","0.01400"
"517.09200","43.09116","0.01431"
"517.58400","43.13223","0.01393"
"518.07600","43.17319","0.01461"
"518.56800","43.21420","0.01433"
"519.06000","43.25522","0.01443"
"519.55200","43.29617","0.01430"
"520.04400","43.33719","0.01491"
"520.53600","43.37820","0.01518"
"521.02800","43.41922","0.01526"
"521.52000","43.46012","0.01558"
"522.01200","43.50119","0.01521"
"522.50400","43.54214","0.01530"
"522.99600","43.58316","0.01529"
"523.48800","43.62418","0.01534"
"523.98000","43.66525","0.01595"
"524.47200","43.70621","0.01580"
"524.96400","43.74717","0.01644"
"525.45600","43.78824","0.01630"
"525.94800","43.82925","0.01630"
"526.44000","43.87015","0.01631"
"526.93200","43.91117","0.01614"
"527.42400","43.95212","0.01706"
"527.91600","43.99314","0.01705"
"528.40800","44.03416","0.01716"
"528.90000","44.07523","0.01656"
"529.39200","44.11619","0.01675"
"529.88400","44.15720","0.01695"
"530.37600","44.19822","0.01712"
"530.86800","44.23917","0.01760"
"531.36000","44.28025","0.01693"
"531.85200","44.32127","0.01729"
"532.34400","44.36216","0.01707"
"532.83600","44.40312","0.01616"
"533.32800","44.44413","0.01666"
"533.82000","44.48515","0.01599"
"534.31200","44.52622","0.01647"
"534.80400","44.56723","0.01676"
"535.29600","44.60820","0.01699"
"535.78800","44.64921","0.01658"
"536.28000","44.69017","0.01722"
"536.77200","44.73124","0.01662"
"537.26400","44.77220","0.01749"
"537.75600","44.81315","0.01714"
"538.24800","44.85417","0.01738"
"538.74000","44.89512","0.01699"
"539.23200","44.93620","0.01698"
"539.72400","44.97715","0.01706"
"540.21600","45.01811","0.01715"
"540.70800","45.05918","0.01648"
"541.20000","45.10020","0.01502"
"541.69200","45.14122","0.01536"
"542.18400","45.18217","0.01522"
"542.67600","45.22325","0.01456"
"543.16800","45.26421","0.01394"
"543.66000","45.30516","0.01427"
"544.15200","45.34618","0.01446"
"544.64400","45.38713","0.01415"
"545.13600","45.42815","0.01415"
"545.62800","45.46917","0.01458"
"546.12000","45.51023","0.01393"
"546.61200","45.55125","0.01439"
"547.10400","45.59221","0.01370"
"547.59600","45.63317","0.01459"
"548.08800","45.67418","0.01452"
"548.58000","45.71520","0.01459"
"549.07200","45.75615","0.01416"
"549.56400","45.79723","0.01444"
"550.05600","45.83818","0.01412"
"550.54800","45.87914","0.01426"
"551.04000","45.92015","0.01410"
"551.53200","45.96117","0.01440"
"552.02400","46.00219","0.01451"
"552.51600","46.04320","0.01417"
"553.00800","46.08422","0.01463"
"553.50000","46.12517","0.01455"
"553.99200","46.16618","0.01458"
"554.48400","46.20720","0.01458"
"554.97600","46.24816","0.01461"
"555.46800","46.28918","0.01504"
"555.96000","46.33013","0.01523"
"556.45200","46.37115","0.01494"
"556.94400","46.41217","0.01466"
"557.43600","46.45318","0.01537"
"557.92800","46.49414","0.01550"
"558.42000","46.53521","0.01525"
"558.91200","46.57623","0.01534"
"559.40400","46.61718","0.01494"
"559.89600","46.65820","0.01538"
"560.38800","46.69921","0.01480"
"560.88000","46.74017","0.01483"
"561.37200","46.78119","0.01524"
"561.86400","46.82214","0.01509"
"562.35600","46.86316","0.01512"
"562.84800","46.90417","0.01507"
"563.34000","46.94518","0.01605"
"563.83200","46.98620","0.01520"
"564.32400","47.02721","0.01517"
"564.81600","47.06823","0.01501"
"565.30800","47.10919","0.01533"
"565.80000","47.15020","0.01501"
"566.29200","47.19122","0.01542"
"566.78400","47.23217","0.01470"
"567.27600","47.27313","0.01495"
"567.76800","47.31415","0.01501"
"568.26000","47.35510","0.01506"
"568.75200","47.39618","0.01463"
"569.24400","47.43726","0.01513"
"569.73600","47.47821","0.01448"
"570.22800","47.51923","0.01439"
"570.72000","47.56018","0.01469"
"571.21200","47.60120","0.01465"
"571.70400","47.64222","0.01356"
"572.19600","47.68317","0.01359"
"572.68800","47.72419","0.01378"
"573.18000","47.76520","0.01347"
"573.67200","47.80616","0.01363"
"574.16400","47.84718","0.01377"
"574.65600","47.88819","0.01356"
"575.14800","47.92921","0.01380"
"575.64000","47.97022","0.01349"
"576.13200","48.01117","0.01373"
"576.62400","48.05213","0.01405"
"577.11600","48.09320","0.01377"
"577.60800","48.13422","0.01384"
"578.10000","48.17517","0.01355"
"578.59200","48.21619","0.01394"
"579.08400","48.25709","0.01322"
"579.57600","48.29816","0.01368"
"580.06800","48.33912","0.01338"
"580.56000","48.38020","0.01293"
"581.05200","48.42121","0.01297"
"581.54400","48.46223","0.01306"
"582.03600","48.50318","0.01246"
"582.52800","48.54420","0.01324"
"583.02000","48.58521","0.01315"
"583.51200","48.62617","0.01322"
"584.00400","48.66719","0.01319"
"584.49600","48.70814","0.01334"
"584.98800","48.74910","0.01324"
"585.48000","48.79011","0.01300"
"585.97200","48.83113","0.01368"
"586.46400","48.87220","0.01329"
"586.95600","48.91316","0.01318"
"587.44800","48.95424","0.01359"
"587.94000","48.99519","0.01350"
"588.43200","49.03621","0.01355"
"588.92400","49.07716","0.01330"
"589.41600","49.11818","0.01349"
"589.90800","49.15919","0.01362"
"590.40000","49.20015","0.01379"
"590.89200","49.24122","0.01369"
"591.38400","49.28218","0.01344"
"591.87600","49.32314","0.01355"
"592.36800","49.36415","0.01366"
"592.86000","49.40523","0.01364"
"593.35200","49.44624","0.01377"
"593.84400","49.48720","0.01401"
"594.33600","49.52821","0.01356"
"594.82800","49.56923","0.01335"
"595.32000","49.61018","0.01286"
"595.81200","49.65120","0.01328"
"596.30400","49.69209","0.01337"
"596.79600","49.73311","0.01346"
"597.28800","49.77412","0.01345"
"597.78000","49.81521","0.01312"
"598.27200","49.85616","0.01303"
"598.76400","49.89717","0.01299"
"599.25600","49.93819","0.01354"
"599.74800","49.97915","0.01321"
"600.24000","50.02022","0.01374"
"600.73200","50.06118","0.01389"
"601.22400","50.10219","0.01331"
"601.71600","50.14315","0.01304"
"602.20800","50.18411","0.01321"
"602.70000","50.22518","0.01337"
"603.19200","50.26614","0.01329"
"603.68400","50.30721","0.01340"
"604.17600","50.34823","0.01315"
"604.66800","50.38919","0.01353"
"605.16000","50.43020","0.01333"
"605.65200","50.47122","0.01352"
"606.14400","50.51223","0.01354"
"606.63600","50.55319","0.01340"
"607.12800","50.59420","0.01300"
"607.62000","50.63515","0.01192"
"608.11200","50.67617","0.01176"
"608.60400","50.71719","0.01069"
"609.09600","50.75814","0.01157"
"609.58800","50.79916","0.01116"
"610.08000","50.84023","0.01391"
"610.57200","50.88125","0.01044"
"611.06400","50.92215","0.01120"
"611.55600","50.96322","0.01098"
"612.04800","51.00418","0.01162"
"612.54000","51.04519","0.01158"
"613.03200","51.08615","0.01064"
"613.52400","51.12717","0.01124"
"614.01600","51.16819","-0.23686"
"614.50800","51.20914","-0.25895"
"615.00000","51.25022","-0.26078"
"615.49200","51.29117","-0.25814"
"615.98400","51.33219","-0.25859"
"616.47600","51.37320","-0.25855"
"616.96800","51.41422","-0.25917"
"617.46000","51.45517","-0.25876"
"617.95200","51.49619","-0.25872"
"618.44400","51.53720","-0.19690"
"618.93600","51.57816","0.03664"
"619.42800","51.61911","0.00860"
"619.92000","51.66019","-0.00719"
"620.41200","51.70115","0.01248"
"620.90400","51.74222","0.02047"
"621.39600","51.78323","0.01024"
"621.88800","51.82425","0.00982"
"622.38000","51.86520","0.01220"
"622.87200","51.90622","0.00729"
"623.36400","51.94718","0.00918"
"623.85600","51.98820","0.00929"
"624.34800","52.02915","0.01216"
"624.84000","52.07017","0.01378"
"625.33200","52.11119","0.00681"
"625.82400","52.15220","0.01253"
"626.31600","52.19316","0.01375"
"626.80800","52.23417","0.00859"
"627.30000","52.27519","0.01106"
"627.79200","52.31620","0.00997"
"628.28400","52.35716","0.01307"
"628.77600","52.39824","0.01116"
"629.26800","52.43919","0.00718"
"629.76000","52.48014","0.01302"
"630.25200","52.52116","0.01217"
"630.74400","52.56211","0.00866"
"631.23600","52.60319","0.01045"
"631.72800","52.64415","0.01106"
"632.22000","52.68516","0.01266"
"632.71200","52.72623","0.00999"
"633.20400","52.76719","0.00876"
"633.69600","52.80820","0.01333"
"634.18800","52.84922","0.01111"
"634.68000","52.89024","0.00880"
"635.17200","52.93120","0.01036"
"635.66400","52.97221","0.01223"
"636.15600","53.01317","0.01119"
"636.64800","53.05412","0.00956"
"637.14000","53.09520","0.01021"
"637.63200","53.13615","0.01235"
"638.12400","53.17717","0.01087"
"638.61600","53.21819","0.00883"
"639.10800","53.25927","0.01090"
"639.60000","53.30016","0.01223"
"640.09200","53.34117","0.01034"
"640.58400","53.38219","0.00967"
"641.07600","53.42320","0.01132"
"641.56800","53.46416","0.01148"
"642.06000","53.50518","0.01043"
"642.55200","53.54619","0.00886"
"643.04400","53.58715","0.01151"
"643.53600","53.62816","0.01233"
"644.02800","53.66918","0.00901"
"644.52000","53.71019","0.01021"
"645.01200","53.75127","0.01115"
"645.50400","53.79222","0.01117"
"645.99600","53.83324","0.01066"
"646.48800","53.87420","0.00899"
"646.98000","53.91515","0.01156"
"647.47200","53.95617","0.01128"
"647.96400","53.99712","0.00868"
"648.45600","54.03814","0.01094"
"648.94800","54.07915","0.01118"
"649.44000","54.12017","0.01083"
"649.93200","54.16118","0.01051"
"650.42400","54.20220","0.00942"
"650.91600","54.24321","0.01179"
"651.40800","54.28417","0.01135"
"651.90000","54.32524","0.00882"
"652.39200","54.36620","0.01098"
"652.88400","54.40716","0.01135"
"653.37600","54.44818","0.01052"
"653.86800","54.48913","0.00967"
"654.36000","54.53015","0.01026"
"654.85200","54.57116","0.01164"
"655.34400","54.61218","0.01040"
"655.83600","54.65319","0.00965"
"656.32800","54.69421","0.01093"
"656.82000","54.73523","0.01164"
"657.31200","54.77618","0.00992"
"657.80400","54.81720","0.01061"
"658.29600","54.85815","0.01137"
"658.78800","54.89917","0.01120"
"659.28000","54.94013","0.01040"
"659.77200","54.98120","0.00986"
"660.26400","55.02216","0.01111"
"660.75600","55.06311","0.01148"
"661.24800","55.10419","0.00954"
"661.74000","55.14514","0.01117"
"662.23200","55.18622","0.01061"
"662.72400","55.22717","0.01075"
"663.21600","55.26825","0.01075"
"663.70800","55.30920","0.00990"
"664.20000","55.35016","0.01128"
"664.69200","55.39112","0.01123"
"665.18400","55.43213","0.00929"
"665.67600","55.47315","0.01134"
"666.16800","55.51416","0.01138"
"666.66000","55.55524","0.01089"
"667.15200","55.59620","0.01086"
"667.64400","55.63721","0.01027"
"668.13600","55.67817","0.01183"
"668.62800","55.71924","0.01110"
"669.12000","55.76026","0.00950"
"669.61200","55.80116","0.01085"
"670.10400","55.84217","0.01092"
"670.59600","55.88313","0.01062"
"671.08800","55.92414","0.01063"
"671.58000","55.96516","0.01033"
"672.07200","56.00611","0.01079"
"672.56400","56.04725","0.01044"
"673.05600","56.08820","0.00996"
"673.54800","56.12922","0.01084"
"674.04000","56.17023","0.01079"
"674.53200","56.21119","0.01062"
"675.02400","56.25220","0.01017"
"675.51600","56.29316","0.01077"
"676.00800","56.33418","0.01129"
"676.50000","56.37519","0.01100"
"676.99200","56.41621","0.01000"
"677.48400","56.45716","0.01147"
"677.97600","56.49812","0.01100"
"678.46800","56.53914","0.01061"
"678.96000","56.58021","0.01054"
"679.45200","56.62123","0.01117"
"679.94400","56.66218","0.01086"
"680.43600","56.70326","0.01125"
"680.92800","56.74422","0.00984"
"681.42000","56.78518","0.01071"
"681.91200","56.82619","0.01143"
"682.40400","56.86715","0.01033"
"682.89600","56.90816","0.01110"
"683.38800","56.94911","0.01057"
"683.88000","56.99019","0.01053"
"684.37200","57.03121","0.01071"
"684.86400","57.07216","0.01044"
"685.35600","57.11317","0.01115"
"685.84800","57.15419","0.01110"
"686.34000","57.19527","0.01056"
"686.83200","57.23616","0.01091"
"687.32400","57.27718","0.01124"
"687.81600","57.31813","0.01051"
"688.30800","57.35915","0.01100"
"688.80000","57.40017","0.01040"
"689.29200","57.44118","0.01073"
"689.78400","57.48220","0.01096"
"690.27600","57.52316","0.01067"
"690.76800","57.56423","0.01069"
"691.26000","57.60519","0.01078"
"691.75200","57.64620","0.01056"
"692.24400","57.68721","0.01100"
"692.73600","57.72817","0.01032"
"693.22800","57.76912","0.01105"
"693.72000","57.81014","0.01111"
"694.21200","57.85115","0.01043"
"694.70400","57.89217","0.01087"
"695.19600","57.93312","0.01150"
"695.68800","57.97421","0.01067"
"696.18000","58.01522","0.01109"
"696.67200","58.05618","0.01091"
"697.16400","58.09725","0.01118"
"697.65600","58.13821","0.01056"
"698.14800","58.17922","0.01037"
"698.64000","58.22012","0.01095"
"699.13200","58.26119","0.01084"
"699.62400","58.30215","0.01028"
"700.11600","58.34317","0.01073"
"700.60800","58.38418","0.01038"
"701.10000","58.42520","0.01068"
"701.59200","58.46621","0.01102"
"702.08400","58.50723","0.01017"
"702.57600","58.54819","0.01065"
"703.06800","58.58914","0.01069"
"703.56000","58.63022","0.01040"
"704.05200","58.67117","0.01102"
"704.54400","58.71218","0.01049"
"705.03600","58.75314","0.01060"
"705.52800","58.79416","0.01088"
"706.02000","58.83511","0.01022"
"706.51200","58.87619","0.01127"
"707.00400","58.91726","0.01088"
"707.49600","58.95816","0.01007"
"707.98800","58.99923","0.01092"
"708.48000","59.04019","0.01070"
"708.97200","59.08115","0.01124"
"709.46400","59.12222","0.01092"
"709.95600","59.16318","0.01040"
"710.44800","59.20414","0.01084"
"710.94000","59.24516","0.01103"
"711.43200","59.28617","0.01078"
"711.92400","59.32719","0.01084"
"712.41600","59.36814","0.01058"
"712.90800","59.40916","0.01082"
"713.40000","59.45023","0.01092"
"713.89200","59.49119","0.01078"
"714.38400","59.53220","0.01079"
"714.87600","59.57322","0.01079"
"715.36800","59.61423","0.01041"
"715.86000","59.65519","0.01095"
"716.35200","59.69614","0.01067"
"716.84400","59.73710","0.01044"
"717.33600","59.77817","0.01073"
"717.82800","59.81919","0.01015"
"718.32000","59.86020","0.01092"
"718.81200","59.90122","0.01112"
"719.30400","59.94217","0.01086"
"719.79600","59.98319","0.01052"
"720.28800","60.02420","0.01073"
"720.78000","60.06522","0.01053"
"721.27200","60.10618","0.01032"
"721.76400","60.14720","0.01032"
"722.25600","60.18815","0.01056"
"722.74800","60.22911","0.01067"
"723.24000","60.27012","0.01062"
"723.73200","60.31114","0.01130"
"724.22400","60.35222","0.01066"
"724.71600","60.39323","0.01082"
"725.20800","60.43425","0.01087"
"725.70000","60.47520","0.01042"
"726.19200","60.51622","0.01096"
"726.68400","60.55717","0.01114"
"727.17600","60.59819","0.01048"
"727.66800","60.63920","0.01080"
"728.16000","60.68016","0.01026"
"728.65200","60.72117","0.01092"
"729.14400","60.76213","0.01092"
"729.63600","60.80315","0.01014"
"730.12800","60.84416","0.01066"
"730.62000","60.88523","0.01084"
"731.11200","60.92619","0.01073"
"731.60400","60.96721","0.01081"
"732.09600","61.00822","0.01074"
"732.58800","61.04918","0.01016"
"733.08000","61.09014","0.01106"
"733.57200","61.13115","0.01052"
"733.58400","61.13217","0.01061"